File: Data/compression 24/AutoHeating-12-24-reverse-1-3_09202024_165556.csv
Time (sec),S:Load (lbs),S:HL1 (DIM),S:LVDT (in),S:Position (in),Ch:Position (mm),Ch:Load (N),Ch:Stress (MPa),Ch:Strain (mm/mm),Ch:HL1 (DIM),Set Point (),Cycles ()
0.110000,0.072983,-238.907181,-0.010408,-0.005863,-0.148929,0.324644,0.016538,-1.489288,-238.907181,-0.148668,0.000000
0.480000,0.010429,-238.996155,-0.010386,-0.005821,-0.147862,0.046392,0.002363,-1.478618,-238.996155,-0.147194,0.000000
0.850000,-0.023460,-238.907181,-0.010274,-0.005599,-0.142208,-0.104357,-0.005316,-1.422076,-238.907181,-0.141037,0.000000
1.220000,0.000748,-238.951675,-0.010050,-0.005362,-0.136189,0.003326,0.000169,-1.361892,-238.951675,-0.134880,0.000000
1.590000,0.034256,-238.996155,-0.009796,-0.005115,-0.129928,0.152378,0.007763,-1.299279,-238.996155,-0.128705,0.000000
1.960000,0.027184,-239.040634,-0.009554,-0.004876,-0.123849,0.120918,0.006160,-1.238486,-239.040634,-0.122548,0.000000
2.330000,-0.006699,-239.040634,-0.009300,-0.004628,-0.117561,-0.029797,-0.001518,-1.175611,-239.040634,-0.116373,0.000000
2.700000,-0.004837,-239.085114,-0.009067,-0.004391,-0.111542,-0.021516,-0.001096,-1.115424,-239.085114,-0.110216,0.000000
3.070000,0.052132,-239.085114,-0.008800,-0.004148,-0.105359,0.231893,0.011813,-1.053594,-239.085114,-0.104058,0.000000
3.440000,0.026436,-239.129593,-0.008558,-0.003908,-0.099271,0.117593,0.005990,-0.992714,-239.129593,-0.097884,0.000000
3.810000,0.028305,-239.263031,-0.008304,-0.003662,-0.093010,0.125907,0.006414,-0.930100,-239.263031,-0.091727,0.000000
4.180000,0.013779,-239.263031,-0.008045,-0.003423,-0.086957,0.061291,0.003122,-0.869568,-239.263031,-0.085552,0.000000
4.550000,-0.016014,-239.307510,-0.007791,-0.003174,-0.080617,-0.071234,-0.003629,-0.806171,-239.307510,-0.079395,0.000000
4.920000,-0.048782,-239.218552,-0.007558,-0.002931,-0.074451,-0.216995,-0.011054,-0.744512,-239.218552,-0.073237,0.000000
5.290000,0.016754,-239.352005,-0.007299,-0.002687,-0.068251,0.074526,0.003797,-0.682507,-239.352005,-0.067063,0.000000
5.660000,0.045059,-239.352005,-0.007054,-0.002451,-0.062258,0.200433,0.010211,-0.622581,-239.352005,-0.060905,0.000000
6.030000,0.044685,-239.440964,-0.006808,-0.002202,-0.055936,0.198770,0.010126,-0.559362,-239.440964,-0.054748,0.000000
6.400000,0.016754,-239.396484,-0.006566,-0.001965,-0.049917,0.074526,0.003797,-0.499175,-239.396484,-0.048573,0.000000
6.770000,0.005211,-239.440964,-0.006295,-0.001716,-0.043578,0.023179,0.001181,-0.435781,-239.440964,-0.042416,0.000000
7.140000,0.042450,-239.485443,-0.006066,-0.001479,-0.037568,0.188827,0.009619,-0.375681,-239.485443,-0.036242,0.000000
7.510000,0.041710,-239.529922,-0.005812,-0.001235,-0.031359,0.185535,0.009452,-0.313590,-239.529922,-0.030084,0.000000
7.880001,0.050644,-239.618881,-0.005562,-0.000988,-0.025098,0.225275,0.011476,-0.250976,-239.618881,-0.023927,0.000000
8.250000,0.042824,-239.663361,-0.005295,-0.000754,-0.019140,0.190490,0.009704,-0.191398,-239.663361,-0.017752,0.000000
8.620001,0.012665,-239.574402,-0.005049,-0.000510,-0.012948,0.056336,0.002870,-0.129477,-239.574402,-0.011595,0.000000
8.990001,-0.017876,-239.618881,-0.004807,-0.000261,-0.006617,-0.079515,-0.004051,-0.066168,-239.618881,-0.005420,0.000000
9.360001,0.003349,-239.707840,-0.004544,-0.000016,-0.000408,0.014898,0.000759,-0.004076,-239.707840,0.000737,0.000000
9.730000,0.114319,-239.752319,-0.004376,-0.000000,-0.000000,0.508516,0.025905,-0.000000,-239.752319,0.000191,0.000000
10.100000,0.115433,-239.752319,-0.004363,-0.000000,-0.000009,0.513470,0.026157,-0.000087,-239.752319,0.000191,0.000000
10.470000,0.125862,-239.796814,-0.004372,-0.000000,-0.000009,0.559863,0.028521,-0.000087,-239.796814,0.000685,0.000000
10.840000,0.093842,-239.752319,-0.004372,-0.000000,-0.000000,0.417428,0.021265,-0.000000,-239.752319,0.001301,0.000000
11.210001,0.154907,-239.796814,-0.004368,0.000034,0.000867,0.689062,0.035102,0.008671,-239.796814,0.001916,0.000000
11.580001,0.206665,-239.885773,-0.004320,0.000066,0.001665,0.919292,0.046831,0.016650,-239.885773,0.002532,0.000000
11.950001,0.205551,-239.930252,-0.004324,0.000075,0.001899,0.914337,0.046579,0.018993,-239.930252,0.003157,0.000000
12.320001,0.296410,-239.930252,-0.004277,0.000110,0.002792,1.318496,0.067167,0.027925,-239.930252,0.003772,0.000000
12.690001,0.415939,-239.930252,-0.004243,0.000136,0.003443,1.850191,0.094253,0.034427,-239.930252,0.004388,0.000000
13.060000,0.479248,-239.974731,-0.004238,0.000154,0.003911,2.131802,0.108599,0.039109,-239.974731,0.005004,0.000000
13.430000,0.688889,-240.063690,-0.004208,0.000188,0.004778,3.064329,0.156104,0.047784,-240.063690,0.005619,0.000000
13.800000,0.751450,-240.152649,-0.004182,0.000203,0.005160,3.342615,0.170281,0.051599,-240.152649,0.006235,0.000000
14.170001,0.891830,-240.108170,-0.004165,0.000233,0.005923,3.967060,0.202092,0.059230,-240.108170,0.006851,0.000000
14.540001,0.956627,-240.152649,-0.004139,0.000252,0.006400,4.255289,0.216775,0.063999,-240.152649,0.007467,0.000000
14.910001,1.156593,-240.108170,-0.004117,0.000275,0.006990,5.144784,0.262088,0.069896,-240.108170,0.008091,0.000000
15.280001,1.366982,-240.197128,-0.004096,0.000301,0.007658,6.080637,0.309762,0.076576,-240.197128,0.008707,0.000000
15.650001,1.556145,-240.241623,-0.004074,0.000331,0.008412,6.922077,0.352627,0.084119,-240.241623,0.009323,0.000000
16.020000,1.565079,-240.286102,-0.004066,0.000339,0.008603,6.961818,0.354652,0.086027,-240.286102,0.009938,0.000000
16.390001,1.764305,-240.286102,-0.004018,0.000373,0.009479,7.848021,0.399797,0.094785,-240.286102,0.010554,0.000000
16.760000,1.908409,-240.330582,-0.004001,0.000398,0.010120,8.489028,0.432452,0.101204,-240.330582,0.011170,0.000000
17.130001,2.064804,-240.375061,-0.003980,0.000419,0.010650,9.184708,0.467891,0.106496,-240.375061,0.011785,0.000000
17.500000,2.201836,-240.464020,-0.003954,0.000451,0.011447,9.794254,0.498943,0.114474,-240.464020,0.012401,0.000000
17.870001,2.302750,-240.464020,-0.003928,0.000472,0.011985,10.243142,0.521811,0.119849,-240.464020,0.013017,0.000000
18.240002,2.439789,-240.508499,-0.003893,0.000493,0.012531,10.852723,0.552864,0.125314,-240.508499,0.013642,0.000000
18.610001,2.535110,-240.464020,-0.003859,0.000516,0.013104,11.276734,0.574464,0.131037,-240.464020,0.014257,0.000000
18.980001,2.671776,-240.508499,-0.003850,0.000545,0.013849,11.884652,0.605433,0.138493,-240.508499,0.014873,0.000000
19.350000,2.752205,-240.552979,-0.003833,0.000571,0.014491,12.242419,0.623659,0.144912,-240.552979,0.015489,0.000000
19.720001,2.848274,-240.730911,-0.003803,0.000594,0.015081,12.669757,0.645428,0.150809,-240.730911,0.016104,0.000000
20.090000,2.872482,-240.641953,-0.003773,0.000616,0.015636,12.777439,0.650914,0.156358,-240.641953,0.016720,0.000000
20.460001,2.970787,-240.641953,-0.003751,0.000639,0.016243,13.214721,0.673190,0.162429,-240.641953,0.017336,0.000000
20.830002,3.040047,-240.730911,-0.003729,0.000662,0.016816,13.522803,0.688884,0.168155,-240.730911,0.017951,0.000000
21.200001,3.132767,-240.686432,-0.003712,0.000686,0.017431,13.935243,0.709895,0.174310,-240.686432,0.018567,0.000000
21.570002,3.276505,-240.775391,-0.003686,0.000717,0.018212,14.574620,0.742467,0.182118,-240.775391,0.019192,0.000000
21.940001,3.304062,-240.819870,-0.003656,0.000740,0.018784,14.697202,0.748711,0.187841,-240.819870,0.019807,0.000000
22.310001,3.378906,-240.775391,-0.003639,0.000762,0.019348,15.030126,0.765671,0.193476,-240.775391,0.020423,0.000000
22.680000,3.321190,-240.775391,-0.003622,0.000779,0.019799,14.773391,0.752592,0.197988,-240.775391,0.021039,0.000000
23.050001,3.537910,-240.864349,-0.003591,0.000810,0.020571,15.737411,0.801702,0.205705,-240.864349,0.021655,0.000000
23.420002,3.613129,-240.953308,-0.003566,0.000840,0.021325,16.071999,0.818747,0.213249,-240.953308,0.022270,0.000000
23.790001,3.616852,-241.042267,-0.003535,0.000864,0.021958,16.088560,0.819590,0.219581,-241.042267,0.022886,0.000000
24.160002,3.698776,-241.042267,-0.003523,0.000889,0.022583,16.452978,0.838155,0.225826,-241.042267,0.023502,0.000000
24.530001,3.754631,-240.953308,-0.003488,0.000911,0.023129,16.701433,0.850812,0.231287,-240.953308,0.024117,0.000000
24.900002,3.892036,-240.997787,-0.003466,0.000936,0.023771,17.312643,0.881948,0.237707,-240.997787,0.024742,0.000000
25.270000,3.928528,-241.042267,-0.003432,0.000962,0.024430,17.474964,0.890217,0.244296,-241.042267,0.025358,0.000000
25.640001,3.938957,-241.086761,-0.003415,0.000987,0.025072,17.521357,0.892580,0.250715,-241.086761,0.025973,0.000000
26.010002,3.930023,-241.131241,-0.003402,0.001004,0.025514,17.481617,0.890556,0.255136,-241.131241,0.026589,0.000000
26.380001,4.087906,-241.220200,-0.003354,0.001030,0.026173,18.183914,0.926333,0.261729,-241.220200,0.027205,0.000000
26.750002,4.156052,-241.175720,-0.003350,0.001051,0.026702,18.487041,0.941775,0.267017,-241.175720,0.027820,0.000000
27.120001,4.342979,-241.264679,-0.003311,0.001087,0.027604,19.318537,0.984133,0.276036,-241.264679,0.028436,0.000000
27.490002,4.257332,-241.220200,-0.003303,0.001105,0.028072,18.937557,0.964725,0.280718,-241.220200,0.029052,0.000000
27.860001,4.270744,-241.353638,-0.003272,0.001127,0.028636,18.997219,0.967764,0.286358,-241.353638,0.029668,0.000000
28.230001,4.382080,-241.353638,-0.003234,0.001151,0.029234,19.492466,0.992994,0.292342,-241.353638,0.030292,0.000000
28.600002,4.455063,-241.353638,-0.003225,0.001170,0.029711,19.817110,1.009532,0.297110,-241.353638,0.030908,0.000000
28.970001,4.763016,-241.398117,-0.003199,0.001204,0.030578,21.186953,1.079315,0.305782,-241.398117,0.031524,0.000000
29.340002,4.754456,-241.442596,-0.003169,0.001229,0.031220,21.148874,1.077375,0.312201,-241.442596,0.032139,0.000000
29.710001,4.753708,-241.487076,-0.003160,0.001252,0.031792,21.145548,1.077206,0.317924,-241.487076,0.032755,0.000000
30.080002,4.871002,-241.531570,-0.003117,0.001277,0.032426,21.667299,1.103785,0.324256,-241.531570,0.033371,0.000000
30.450001,4.874725,-241.487076,-0.003104,0.001294,0.032868,21.683861,1.104629,0.328676,-241.487076,0.033986,0.000000
30.820002,5.082138,-241.620529,-0.003074,0.001321,0.033561,22.606480,1.151629,0.335614,-241.620529,0.034602,0.000000
31.190001,5.066498,-241.620529,-0.003070,0.001347,0.034212,22.536907,1.148085,0.342120,-241.620529,0.035218,0.000000
31.560001,5.247101,-241.665009,-0.003035,0.001374,0.034888,23.340271,1.189010,0.348884,-241.665009,0.035842,0.000000
31.930002,5.341682,-241.620529,-0.003005,0.001397,0.035496,23.760990,1.210443,0.354955,-241.620529,0.036458,0.000000
32.300003,5.328651,-241.709488,-0.002979,0.001416,0.035955,23.703026,1.207490,0.359550,-241.709488,0.037074,0.000000
32.670002,5.512604,-241.709488,-0.002949,0.001441,0.036606,24.521286,1.249174,0.366056,-241.709488,0.037690,0.000000
33.040001,5.636604,-241.798447,-0.002932,0.001469,0.037316,25.072868,1.277273,0.373164,-241.798447,0.038305,0.000000
33.410000,5.702141,-241.798447,-0.002910,0.001490,0.037837,25.364389,1.292124,0.378368,-241.798447,0.038921,0.000000
33.780003,5.959450,-241.842926,-0.002897,0.001521,0.038643,26.508957,1.350431,0.386434,-241.842926,0.039537,0.000000
34.150002,5.916252,-241.842926,-0.002867,0.001541,0.039138,26.316803,1.340642,0.391377,-241.842926,0.040152,0.000000
34.520000,6.106911,-241.842926,-0.002837,0.001565,0.039745,27.164896,1.383846,0.397448,-241.842926,0.040768,0.000000
34.890003,6.280060,-241.931900,-0.002807,0.001595,0.040508,27.935101,1.423082,0.405078,-241.931900,0.041393,0.000000
35.260002,6.205963,-241.976379,-0.002798,0.001613,0.040959,27.605503,1.406291,0.409590,-241.976379,0.042008,0.000000
35.630001,6.344482,-242.065338,-0.002755,0.001637,0.041592,28.221668,1.437680,0.415922,-242.065338,0.042624,0.000000
36.000000,6.594345,-242.065338,-0.002733,0.001664,0.042277,29.333113,1.494300,0.422773,-242.065338,0.043240,0.000000
36.370003,6.602539,-241.976379,-0.002703,0.001684,0.042780,29.369560,1.496157,0.427803,-241.976379,0.043856,0.000000
36.740002,6.761169,-242.109818,-0.002695,0.001711,0.043457,30.075184,1.532103,0.434566,-242.109818,0.044471,0.000000
37.110001,6.889633,-242.109818,-0.002652,0.001735,0.044081,30.646620,1.561213,0.440808,-242.109818,0.045087,0.000000
37.480003,6.960388,-242.154297,-0.002643,0.001754,0.044558,30.961353,1.577246,0.445581,-242.154297,0.045703,0.000000
37.850002,7.216209,-242.198776,-0.002621,0.001783,0.045278,32.099304,1.635216,0.452776,-242.198776,0.046327,0.000000
38.220001,7.290306,-242.198776,-0.002591,0.001805,0.045850,32.428902,1.652007,0.458502,-242.198776,0.046943,0.000000
38.590000,7.506287,-242.198776,-0.002574,0.001830,0.046483,33.389629,1.700949,0.464831,-242.198776,0.047559,0.000000
38.960003,7.648529,-242.287735,-0.002557,0.001854,0.047090,34.022358,1.733181,0.470901,-242.287735,0.048174,0.000000
39.330002,7.590813,-242.332214,-0.002527,0.001872,0.047559,33.765621,1.720103,0.475587,-242.332214,0.048790,0.000000
39.700001,7.651886,-242.376709,-0.002509,0.001892,0.048061,34.037289,1.733942,0.480614,-242.376709,0.049406,0.000000
40.070004,8.118095,-242.376709,-0.002470,0.001927,0.048938,36.111092,1.839587,0.489376,-242.376709,0.050022,0.000000
40.440002,8.158310,-242.376709,-0.002445,0.001949,0.049510,36.289974,1.848699,0.495098,-242.376709,0.050637,0.000000
40.810001,8.541481,-242.421188,-0.002440,0.001982,0.050343,37.994404,1.935527,0.503425,-242.421188,0.051253,0.000000
41.180000,8.473335,-242.510147,-0.002406,0.002000,0.050793,37.691277,1.920085,0.507933,-242.510147,0.051877,0.000000
41.550003,8.638298,-242.554626,-0.002402,0.002023,0.051374,38.425068,1.957466,0.513743,-242.554626,0.052493,0.000000
41.920002,8.888161,-242.599106,-0.002358,0.002047,0.051999,39.536514,2.014086,0.519988,-242.599106,0.053109,0.000000
42.290001,9.145096,-242.554626,-0.002333,0.002071,0.052615,40.679417,2.072308,0.526146,-242.554626,0.053725,0.000000
42.660004,9.116051,-242.599106,-0.002337,0.002089,0.053057,40.550220,2.065727,0.530567,-242.599106,0.054340,0.000000
43.030003,9.498474,-242.643585,-0.002285,0.002119,0.053828,42.251324,2.152385,0.538284,-242.643585,0.054956,0.000000
43.400002,9.647057,-242.732544,-0.002276,0.002143,0.054444,42.912251,2.186054,0.544442,-242.732544,0.055572,0.000000
43.770000,9.890213,-242.688065,-0.002238,0.002167,0.055051,43.993866,2.241154,0.550513,-242.688065,0.056188,0.000000
44.140003,10.300194,-242.777023,-0.002229,0.002193,0.055711,45.817551,2.334057,0.557106,-242.777023,0.056803,0.000000
44.510002,10.655067,-242.732544,-0.002199,0.002225,0.056508,47.396107,2.414473,0.565085,-242.732544,0.057427,0.000000
44.880001,10.714272,-242.865997,-0.002169,0.002249,0.057133,47.659462,2.427889,0.571326,-242.865997,0.058043,0.000000
45.250004,10.666611,-242.865997,-0.002151,0.002270,0.057653,47.447453,2.417089,0.576530,-242.865997,0.058659,0.000000
45.620003,11.042336,-242.910477,-0.002121,0.002294,0.058278,49.118763,2.502229,0.582775,-242.910477,0.059275,0.000000
45.990002,11.233360,-242.910477,-0.002095,0.002314,0.058781,49.968483,2.545516,0.587806,-242.910477,0.059891,0.000000
46.360001,11.704414,-242.910477,-0.002078,0.002345,0.059552,52.063835,2.652258,0.595523,-242.910477,0.060506,0.000000
46.730003,11.928581,-242.954956,-0.002061,0.002370,0.060203,53.060978,2.703055,0.602025,-242.954956,0.061122,0.000000
47.100002,12.110298,-242.999435,-0.002039,0.002392,0.060758,53.869297,2.744233,0.607578,-242.999435,0.061738,0.000000
47.470001,12.332603,-243.043915,-0.002013,0.002415,0.061330,54.858158,2.794608,0.613301,-243.043915,0.062353,0.000000
47.840004,12.455856,-243.043915,-0.001988,0.002434,0.061833,55.406418,2.822537,0.618331,-243.043915,0.062978,0.000000
48.210003,13.003616,-243.043915,-0.001979,0.002459,0.062466,57.842976,2.946662,0.624663,-243.043915,0.063593,0.000000
48.580002,13.551010,-243.088394,-0.001940,0.002491,0.063281,60.277905,3.070703,0.632812,-243.088394,0.064209,0.000000
48.950001,13.679100,-243.177353,-0.001923,0.002513,0.063828,60.847675,3.099728,0.638277,-243.177353,0.064825,0.000000
49.320004,13.820602,-243.177353,-0.001901,0.002534,0.064374,61.477112,3.131793,0.643739,-243.177353,0.065441,0.000000
49.690002,14.467789,-243.177353,-0.001884,0.002559,0.064990,64.355942,3.278448,0.649897,-243.177353,0.066057,0.000000
50.060001,14.705360,-243.177353,-0.001845,0.002579,0.065510,65.412712,3.332282,0.655101,-243.177353,0.066672,0.000000
50.430004,15.669434,-243.266327,-0.001832,0.002614,0.066403,69.701118,3.550744,0.664033,-243.266327,0.067288,0.000000
50.800003,15.652679,-243.310806,-0.001819,0.002637,0.066984,69.626595,3.546948,0.669843,-243.310806,0.067904,0.000000
51.170002,15.713745,-243.399765,-0.001785,0.002656,0.067453,69.898232,3.560786,0.674529,-243.399765,0.068528,0.000000
51.540001,16.281616,-243.310806,-0.001772,0.002680,0.068060,72.424248,3.689467,0.680596,-243.310806,0.069144,0.000000
51.910004,16.355713,-243.399765,-0.001768,0.002700,0.068580,72.753845,3.706258,0.685800,-243.399765,0.069759,0.000000
52.280003,17.689926,-243.399765,-0.001729,0.002733,0.069421,78.688721,4.008595,0.694214,-243.399765,0.070375,0.000000
52.650002,17.826218,-243.444244,-0.001707,0.002754,0.069941,79.294975,4.039479,0.699415,-243.444244,0.070991,0.000000
53.020004,18.251091,-243.488724,-0.001681,0.002778,0.070566,81.184906,4.135756,0.705660,-243.488724,0.071607,0.000000
53.390003,18.451057,-243.577682,-0.001656,0.002800,0.071121,82.074402,4.181069,0.711212,-243.577682,0.072223,0.000000
53.760002,18.999191,-243.577682,-0.001638,0.002825,0.071754,84.512627,4.305278,0.717540,-243.577682,0.072838,0.000000
54.130001,19.640411,-243.577682,-0.001625,0.002851,0.072413,87.364914,4.450581,0.724134,-243.577682,0.073454,0.000000
54.500004,20.323715,-243.666656,-0.001608,0.002875,0.073020,90.404404,4.605420,0.730205,-243.666656,0.074078,0.000000
54.870003,20.950050,-243.711136,-0.001582,0.002901,0.073697,93.190475,4.747349,0.736968,-243.711136,0.074694,0.000000
55.240002,21.722717,-243.666656,-0.001548,0.002927,0.074347,96.627472,4.922438,0.743471,-243.666656,0.075310,0.000000
55.610004,21.622925,-243.666656,-0.001544,0.002942,0.074737,96.183571,4.899825,0.747373,-243.666656,0.075925,0.000000
55.980003,23.020813,-243.755615,-0.001513,0.002976,0.075587,102.401688,5.216590,0.755874,-243.755615,0.076541,0.000000
56.350002,23.342911,-243.889053,-0.001500,0.002998,0.076142,103.834450,5.289579,0.761422,-243.889053,0.077157,0.000000
56.720001,23.652725,-243.844574,-0.001470,0.003017,0.076628,105.212578,5.359784,0.766279,-243.844574,0.077773,0.000000
57.090004,24.178520,-243.889053,-0.001470,0.003039,0.077192,107.551430,5.478931,0.771918,-243.889053,0.078389,0.000000
57.460003,25.314629,-243.889053,-0.001431,0.003068,0.077937,112.605095,5.736377,0.779374,-243.889053,0.079004,0.000000
57.830002,25.886215,-243.933533,-0.001427,0.003090,0.078475,115.147636,5.865900,0.784753,-243.933533,0.079629,0.000000
58.200005,27.546257,-244.066986,-0.001418,0.003124,0.079351,122.531868,6.242071,0.793511,-244.066986,0.080244,0.000000
58.570004,27.035362,-244.022491,-0.001388,0.003134,0.079602,120.259300,6.126301,0.796024,-244.022491,0.080860,0.000000
58.940002,27.786064,-244.022491,-0.001358,0.003165,0.080383,123.598587,6.296412,0.803832,-244.022491,0.081476,0.000000
59.310001,29.264008,-244.022491,-0.001345,0.003188,0.080981,130.172806,6.631319,0.809812,-244.022491,0.082091,0.000000
59.680004,30.129402,-244.022491,-0.001341,0.003214,0.081641,134.022278,6.827420,0.816406,-244.022491,0.082707,0.000000
60.050003,30.817917,-244.066986,-0.001324,0.003237,0.082222,137.084946,6.983440,0.822215,-244.066986,0.083323,0.000000
60.420002,31.403664,-244.200424,-0.001289,0.003261,0.082820,139.690475,7.116172,0.828199,-244.200424,0.083939,0.000000
60.790005,32.755371,-244.200424,-0.001272,0.003288,0.083505,145.703171,7.422473,0.835050,-244.200424,0.084563,0.000000
61.160004,33.721306,-244.155945,-0.001259,0.003309,0.084060,149.999863,7.641357,0.840602,-244.155945,0.085179,0.000000
61.530003,34.786293,-244.200424,-0.001255,0.003336,0.084737,154.737152,7.882687,0.847366,-244.200424,0.085794,0.000000
61.900002,35.261810,-244.289383,-0.001233,0.003354,0.085196,156.852371,7.990440,0.851961,-244.289383,0.086410,0.000000
62.270004,36.789284,-244.333862,-0.001224,0.003387,0.086037,163.646912,8.336571,0.860375,-244.333862,0.087026,0.000000
62.640003,37.504242,-244.333862,-0.001190,0.003408,0.086575,166.827194,8.498582,0.865749,-244.333862,0.087642,0.000000
63.010002,38.445595,-244.289383,-0.001194,0.003431,0.087139,171.014542,8.711896,0.871389,-244.289383,0.088257,0.000000
63.380005,39.725815,-244.333862,-0.001168,0.003453,0.087702,176.709244,9.001999,0.877025,-244.333862,0.088873,0.000000
63.750004,40.715202,-244.467300,-0.001151,0.003475,0.088266,181.110260,9.226196,0.882660,-244.467300,0.089489,0.000000
64.120003,42.265022,-244.511795,-0.001130,0.003503,0.088977,188.004211,9.577391,0.889772,-244.511795,0.090113,0.000000
64.490005,43.518051,-244.467300,-0.001125,0.003531,0.089688,193.577957,9.861331,0.896884,-244.467300,0.090729,0.000000
64.860001,44.344345,-244.511795,-0.001117,0.003552,0.090218,197.253494,10.048573,0.902175,-244.511795,0.091345,0.000000
65.230003,45.199684,-244.511795,-0.001086,0.003568,0.090633,201.058243,10.242394,0.906335,-244.511795,0.091960,0.000000
65.600006,47.154640,-244.600754,-0.001082,0.003600,0.091440,209.754318,10.685394,0.914400,-244.600754,0.092576,0.000000
65.970001,49.069756,-244.689713,-0.001056,0.003630,0.092212,218.273178,11.119366,0.922122,-244.689713,0.093192,0.000000
66.340004,50.026009,-244.689713,-0.001039,0.003653,0.092793,222.526794,11.336056,0.927931,-244.689713,0.093808,0.000000
66.710007,51.140892,-244.645233,-0.001039,0.003676,0.093365,227.486053,11.588692,0.933654,-244.645233,0.094423,0.000000
67.080002,51.999207,-244.645233,-0.001026,0.003693,0.093808,231.304016,11.783189,0.938079,-244.645233,0.095039,0.000000
67.450005,53.724411,-244.778671,-0.001009,0.003722,0.094527,238.978119,12.174126,0.945274,-244.778671,0.095664,0.000000
67.820000,55.648834,-244.778671,-0.000996,0.003752,0.095291,247.538376,12.610207,0.952908,-244.778671,0.096279,0.000000
68.190002,57.112999,-244.734192,-0.000983,0.003777,0.095941,254.051300,12.941991,0.959410,-244.734192,0.096895,0.000000
68.560005,58.335869,-244.867630,-0.000979,0.003796,0.096427,259.490906,13.219096,0.964266,-244.867630,0.097511,0.000000
68.930000,60.103149,-244.867630,-0.000961,0.003822,0.097086,267.352173,13.619569,0.970860,-244.867630,0.098126,0.000000
69.300003,60.903008,-244.912109,-0.000957,0.003840,0.097528,270.910095,13.800818,0.975280,-244.912109,0.098742,0.000000
69.670006,63.674202,-245.001083,-0.000936,0.003875,0.098413,283.237000,14.428781,0.984126,-245.001083,0.099358,0.000000
70.040001,64.872490,-244.956604,-0.000927,0.003894,0.098916,288.567261,14.700316,0.989156,-244.956604,0.099974,0.000000
70.410004,66.465874,-245.001083,-0.000918,0.003909,0.099297,295.654968,15.061382,0.992971,-245.001083,0.100546,0.000000
70.780006,65.490257,-245.045563,-0.000905,0.003909,0.099280,291.315216,14.840305,0.992801,-245.045563,294.500488,0.000000
71.150002,64.716469,-245.045563,-0.000897,0.003909,0.099297,287.873230,14.664962,0.992971,-245.045563,294.500488,0.000000
71.520004,66.353416,-245.134521,-0.000880,0.003865,0.098179,295.154724,15.035899,0.981787,-245.134521,294.500488,0.000000
71.890007,65.780708,-245.134521,-0.000875,0.003885,0.098682,292.607208,14.906121,0.986817,-245.134521,294.500488,0.000000
72.260002,65.305565,-245.090042,-0.000875,0.003913,0.099384,290.493652,14.798452,0.993838,-245.090042,294.500488,0.000000
72.630005,65.062035,-245.179001,-0.000888,0.003926,0.099722,289.410370,14.743267,0.997221,-245.179001,294.500488,0.000000
73.000000,65.114906,-245.267960,-0.000875,0.003934,0.099913,289.645569,14.755248,0.999129,-245.267960,294.500488,0.000000
73.370003,65.067986,-245.223480,-0.000871,0.003934,0.099913,289.436859,14.744617,0.999129,-245.223480,294.500488,0.000000
73.740005,65.565483,-245.267960,-0.000862,0.003942,0.100121,291.649841,14.857351,1.001211,-245.267960,294.500488,0.000000
74.110001,65.336845,-245.312439,-0.000884,0.003942,0.100121,290.632812,14.805541,1.001211,-245.312439,294.500488,0.000000
74.480003,65.159966,-245.356934,-0.000862,0.003942,0.100121,289.846008,14.765460,1.001211,-245.356934,294.500488,0.000000
74.850006,64.961861,-245.445892,-0.000880,0.003942,0.100121,288.964783,14.720568,1.001211,-245.445892,294.500488,0.000000
75.220001,64.761909,-245.401413,-0.000867,0.003942,0.100121,288.075348,14.675258,1.001211,-245.401413,294.500488,0.000000
75.590004,64.624123,-245.445892,-0.000858,0.003942,0.100121,287.462463,14.644036,1.001211,-245.445892,294.500488,0.000000
75.960007,64.443901,-245.445892,-0.000862,0.003942,0.100121,286.660797,14.603196,1.001211,-245.445892,294.500488,0.000000
76.330002,64.298302,-245.534851,-0.000867,0.003942,0.100121,286.013123,14.570204,1.001211,-245.534851,294.500488,0.000000
76.700005,66.577965,-245.579330,-0.000854,0.003782,0.096071,296.153564,15.086782,0.960712,-245.579330,294.500488,0.000000
77.070007,66.391411,-245.579330,-0.000841,0.003783,0.096080,295.323730,15.044509,0.960799,-245.579330,294.500488,0.000000
77.440002,66.247292,-245.623810,-0.000832,0.003783,0.096080,294.682678,15.011850,0.960799,-245.623810,294.500488,0.000000
77.810005,66.087914,-245.623810,-0.000836,0.003783,0.096080,293.973724,14.975735,0.960799,-245.623810,294.500488,0.000000
78.180000,65.922966,-245.712769,-0.000849,0.003788,0.096227,293.239990,14.938358,0.962272,-245.712769,294.500488,0.000000
78.550003,65.830238,-245.757248,-0.000836,0.003796,0.096409,292.827515,14.917345,0.964092,-245.757248,294.500488,0.000000
78.920006,65.723366,-245.712769,-0.000828,0.003825,0.097164,292.352142,14.893127,0.971639,-245.712769,294.500488,0.000000
79.290001,65.571068,-245.757248,-0.000845,0.003893,0.098881,291.674683,14.858616,0.988811,-245.757248,294.500488,0.000000
79.660004,65.468666,-245.757248,-0.000845,0.003924,0.099670,291.219177,14.835411,0.996703,-245.757248,294.500488,0.000000
80.030006,65.350990,-245.846222,-0.000841,0.003933,0.099895,290.695709,14.808746,0.998955,-245.846222,294.500488,0.000000
80.400002,65.273918,-245.890701,-0.000841,0.003934,0.099922,290.352875,14.791282,0.999216,-245.890701,294.500488,0.000000
80.770004,65.243385,-245.890701,-0.000841,0.003941,0.100095,290.217072,14.784363,1.000950,-245.890701,294.500488,0.000000
81.140007,65.252693,-245.935181,-0.000841,0.003951,0.100347,290.258484,14.786471,1.003466,-245.935181,294.500488,0.000000
81.510002,65.164070,-245.935181,-0.000841,0.003951,0.100355,289.864258,14.766389,1.003554,-245.935181,294.500488,0.000000
81.880005,65.067986,-246.024139,-0.000836,0.003951,0.100355,289.436859,14.744617,1.003554,-246.024139,294.500488,0.000000
82.250008,65.124962,-246.068619,-0.000841,0.003959,0.100546,289.690308,14.757527,1.005461,-246.068619,294.500488,0.000000
82.620003,65.124962,-246.068619,-0.000832,0.003960,0.100581,289.690308,14.757527,1.005806,-246.068619,294.500488,0.000000
82.990005,65.097404,-246.068619,-0.000832,0.003962,0.100624,289.567719,14.751283,1.006241,-246.068619,294.500488,0.000000
83.360001,65.051613,-246.113098,-0.000849,0.003962,0.100624,289.364014,14.740906,1.006241,-246.113098,294.500488,0.000000
83.730003,65.288811,-246.157578,-0.000849,0.003966,0.100746,290.419128,14.794656,1.007456,-246.157578,294.500488,0.000000
84.100006,65.292900,-246.202057,-0.000841,0.003966,0.100746,290.437317,14.795583,1.007456,-246.202057,294.500488,0.000000
84.470001,65.257164,-246.246552,-0.000836,0.003966,0.100746,290.278351,14.787484,1.007456,-246.246552,294.500488,0.000000
84.840004,65.228111,-246.202057,-0.000832,0.003966,0.100746,290.149139,14.780901,1.007456,-246.202057,294.500488,0.000000
85.210007,65.185661,-246.246552,-0.000836,0.003966,0.100746,289.960297,14.771281,1.007456,-246.246552,294.500488,0.000000
85.580002,65.115288,-246.379990,-0.000841,0.003966,0.100746,289.647278,14.755335,1.007456,-246.379990,294.500488,0.000000
85.950005,65.051231,-246.379990,-0.000841,0.003966,0.100746,289.362335,14.740820,1.007456,-246.379990,294.500488,0.000000
86.320007,65.004311,-246.379990,-0.000845,0.003966,0.100746,289.153625,14.730187,1.007456,-246.379990,294.500488,0.000000
86.690002,64.992027,-246.468948,-0.000836,0.003967,0.100754,289.098969,14.727404,1.007543,-246.468948,294.500488,0.000000
87.060005,64.956276,-246.468948,-0.000836,0.003967,0.100763,288.939941,14.719302,1.007630,-246.468948,294.500488,0.000000
87.430008,65.262001,-246.557907,-0.000828,0.003972,0.100884,290.299866,14.788581,1.008841,-246.557907,294.500488,0.000000
87.800003,65.276894,-246.513428,-0.000841,0.003972,0.100884,290.366119,14.791956,1.008841,-246.513428,294.500488,0.000000
88.170006,65.269447,-246.513428,-0.000823,0.003972,0.100884,290.333008,14.790268,1.008841,-246.513428,294.500488,0.000000
88.540001,65.245247,-246.513428,-0.000845,0.003972,0.100884,290.225342,14.784784,1.008841,-246.513428,294.500488,0.000000
88.910004,65.213219,-246.557907,-0.000849,0.003972,0.100884,290.082886,14.777527,1.008841,-246.557907,294.500488,0.000000
89.280006,65.170403,-246.602386,-0.000841,0.003972,0.100884,289.892426,14.767824,1.008841,-246.602386,294.500488,0.000000
89.650002,65.133537,-246.646881,-0.000832,0.003972,0.100884,289.728455,14.759470,1.008841,-246.646881,294.500488,0.000000
90.020004,65.151772,-246.735840,-0.000836,0.003974,0.100928,289.809540,14.763602,1.009276,-246.735840,294.500488,0.000000
90.390007,65.137260,-246.780319,-0.000828,0.003974,0.100928,289.744995,14.760314,1.009276,-246.780319,294.500488,0.000000
90.760002,65.136879,-246.735840,-0.000849,0.003974,0.100928,289.743317,14.760228,1.009276,-246.735840,294.500488,0.000000
91.130005,65.098534,-246.780319,-0.000849,0.003974,0.100936,289.572754,14.751538,1.009363,-246.780319,294.500488,0.000000
91.500008,65.081032,-246.869278,-0.000845,0.003974,0.100936,289.494873,14.747572,1.009363,-246.869278,294.500488,0.000000
91.870003,65.060539,-246.913757,-0.000828,0.003974,0.100936,289.403748,14.742929,1.009363,-246.913757,294.500488,0.000000
92.240005,65.108208,-246.869278,-0.000841,0.003976,0.100979,289.615784,14.753730,1.009795,-246.869278,294.500488,0.000000
92.610001,65.122734,-246.958237,-0.000832,0.003976,0.100988,289.680389,14.757022,1.009882,-246.958237,294.500488,0.000000
92.980003,65.102989,-247.002716,-0.000849,0.003976,0.100988,289.592560,14.752548,1.009882,-247.002716,294.500488,0.000000
93.350006,65.082512,-247.002716,-0.000832,0.003976,0.100988,289.501465,14.747909,1.009882,-247.002716,294.500488,0.000000
93.720001,65.054588,-247.091690,-0.000836,0.003976,0.100988,289.377258,14.741581,1.009882,-247.091690,294.500488,0.000000
94.090004,65.043419,-247.047195,-0.000828,0.003976,0.100988,289.327576,14.739050,1.009882,-247.047195,294.500488,0.000000
94.460007,65.016975,-247.091690,-0.000836,0.003976,0.100988,289.209961,14.733057,1.009882,-247.091690,294.500488,0.000000
94.830002,64.991661,-247.091690,-0.000845,0.003976,0.100988,289.097351,14.727321,1.009882,-247.091690,294.500488,0.000000
95.200005,64.971550,-247.136169,-0.000836,0.003976,0.100988,289.007874,14.722764,1.009882,-247.136169,294.500488,0.000000
95.570007,64.936180,-247.180649,-0.000836,0.003976,0.100988,288.850555,14.714748,1.009882,-247.180649,294.500488,0.000000
95.940002,65.187523,-247.180649,-0.000823,0.003980,0.101101,289.968597,14.771704,1.011010,-247.180649,294.500488,0.000000
96.310005,65.224022,-247.225128,-0.000828,0.003980,0.101101,290.130951,14.779975,1.011010,-247.225128,294.500488,0.000000
96.680008,65.213966,-247.314087,-0.000841,0.003980,0.101101,290.086212,14.777697,1.011010,-247.314087,294.500488,0.000000
97.050003,65.194969,-247.403046,-0.000849,0.003980,0.101101,290.001709,14.773392,1.011010,-247.403046,294.500488,0.000000
97.420006,65.178215,-247.314087,-0.000832,0.003980,0.101101,289.927185,14.769595,1.011010,-247.314087,294.500488,0.000000
97.790001,65.162575,-247.358566,-0.000828,0.003980,0.101101,289.857605,14.766050,1.011010,-247.358566,294.500488,0.000000
98.160004,65.137627,-247.403046,-0.000841,0.003980,0.101101,289.746643,14.760398,1.011010,-247.403046,294.500488,0.000000
98.530006,65.108574,-247.447525,-0.000836,0.003980,0.101101,289.617401,14.753814,1.011010,-247.447525,294.500488,0.000000
98.900002,65.082512,-247.492004,-0.000836,0.003980,0.101101,289.501465,14.747909,1.011010,-247.492004,294.500488,0.000000
99.270004,65.059059,-247.492004,-0.000828,0.003980,0.101101,289.397156,14.742594,1.011010,-247.492004,294.500488,0.000000
99.640007,65.057945,-247.447525,-0.000832,0.003980,0.101101,289.392181,14.742341,1.011010,-247.447525,294.500488,0.000000
100.010002,65.028526,-247.580978,-0.000828,0.003981,0.101118,289.261322,14.735675,1.011184,-247.580978,294.500488,0.000000
100.380005,65.017723,-247.580978,-0.000823,0.003981,0.101118,289.213287,14.733227,1.011184,-247.580978,294.500488,0.000000
100.750008,65.011757,-247.669937,-0.000845,0.003981,0.101118,289.186737,14.731875,1.011184,-247.669937,294.500488,0.000000
101.120003,64.992393,-247.669937,-0.000823,0.003981,0.101118,289.100616,14.727487,1.011184,-247.669937,294.500488,0.000000
101.490005,64.987938,-247.625458,-0.000845,0.003981,0.101127,289.080780,14.726477,1.011271,-247.625458,294.500488,0.000000
101.860008,64.964851,-247.714417,-0.000836,0.003981,0.101127,288.978088,14.721246,1.011271,-247.714417,294.500488,0.000000
102.230003,64.999474,-247.758896,-0.000836,0.003982,0.101153,289.132111,14.729092,1.011532,-247.758896,294.500488,0.000000
102.600006,64.996498,-247.803375,-0.000832,0.003982,0.101153,289.118866,14.728416,1.011532,-247.803375,294.500488,0.000000
102.970001,64.986443,-247.847855,-0.000828,0.003982,0.101153,289.074127,14.726138,1.011532,-247.847855,294.500488,0.000000
103.340004,64.975639,-247.892334,-0.000841,0.003982,0.101153,289.026093,14.723690,1.011532,-247.892334,294.500488,0.000000
103.710007,64.963722,-247.892334,-0.000836,0.003982,0.101153,288.973083,14.720990,1.011532,-247.892334,294.500488,0.000000
104.080002,64.944359,-247.936829,-0.000854,0.003983,0.101162,288.886932,14.716602,1.011619,-247.936829,294.500488,0.000000
104.450005,64.927605,-247.936829,-0.000823,0.003983,0.101162,288.812408,14.712806,1.011619,-247.936829,294.500488,0.000000
104.820007,64.931328,-247.981308,-0.000828,0.003983,0.101162,288.828979,14.713649,1.011619,-247.981308,294.500488,0.000000
105.190002,64.923515,-247.936829,-0.000841,0.003983,0.101162,288.794220,14.711879,1.011619,-247.936829,294.500488,0.000000
105.560005,65.426216,-248.025787,-0.000836,0.003991,0.101378,291.030334,14.825793,1.013784,-248.025787,294.500488,0.000000
105.930008,65.564369,-248.070267,-0.000841,0.003991,0.101370,291.644867,14.857099,1.013697,-248.070267,294.500488,0.000000
106.300003,65.586342,-248.159225,-0.000832,0.003991,0.101370,291.742615,14.862078,1.013697,-248.159225,294.500488,0.000000
106.670006,65.588936,-248.114746,-0.000815,0.003991,0.101370,291.754150,14.862665,1.013697,-248.114746,294.500488,0.000000
107.040009,65.585960,-248.159225,-0.000819,0.003991,0.101370,291.740936,14.861991,1.013697,-248.159225,294.500488,0.000000
107.410004,65.593788,-248.159225,-0.000828,0.003991,0.101370,291.775757,14.863765,1.013697,-248.159225,294.500488,0.000000
107.780006,65.570702,-248.248184,-0.000832,0.003991,0.101370,291.673035,14.858533,1.013697,-248.248184,294.500488,0.000000
108.150002,65.580757,-248.203705,-0.000828,0.003991,0.101370,291.717773,14.860812,1.013697,-248.203705,294.500488,0.000000
108.520004,65.563622,-248.292664,-0.000841,0.003991,0.101370,291.641541,14.856929,1.013697,-248.292664,294.500488,0.000000
108.890007,65.571815,-248.292664,-0.000823,0.003991,0.101370,291.678009,14.858786,1.013697,-248.292664,294.500488,0.000000
109.260002,65.556175,-248.381638,-0.000836,0.003991,0.101370,291.608429,14.855242,1.013697,-248.381638,294.500488,0.000000
109.630005,65.547615,-248.337143,-0.000828,0.003991,0.101370,291.570343,14.853302,1.013697,-248.337143,294.500488,0.000000
110.000008,65.543510,-248.470596,-0.000832,0.003991,0.101370,291.552094,14.852372,1.013697,-248.470596,294.500488,0.000000
110.370003,65.517067,-248.381638,-0.000828,0.003991,0.101370,291.434479,14.846379,1.013697,-248.381638,294.500488,0.000000
110.740005,65.491386,-248.470596,-0.000823,0.003991,0.101370,291.320251,14.840561,1.013697,-248.470596,294.500488,0.000000
111.110008,65.482063,-248.515076,-0.000832,0.003991,0.101370,291.278778,14.838448,1.013697,-248.515076,294.500488,0.000000
111.480003,65.483192,-248.604034,-0.000823,0.003991,0.101370,291.283783,14.838703,1.013697,-248.604034,294.500488,0.000000
111.850006,65.458244,-248.604034,-0.000828,0.003991,0.101370,291.172821,14.833050,1.013697,-248.604034,294.500488,0.000000
112.220009,65.437752,-248.604034,-0.000819,0.003991,0.101370,291.081665,14.828406,1.013697,-248.604034,294.500488,0.000000
112.590004,65.407967,-248.604034,-0.000828,0.003991,0.101370,290.949158,14.821657,1.013697,-248.604034,294.500488,0.000000
112.960007,65.378548,-248.648514,-0.000832,0.003991,0.101370,290.818298,14.814991,1.013697,-248.648514,294.500488,0.000000
113.330002,65.362907,-248.737473,-0.000823,0.003991,0.101370,290.748718,14.811446,1.013697,-248.737473,294.500488,0.000000
113.700005,65.364403,-248.737473,-0.000823,0.003991,0.101370,290.755371,14.811786,1.013697,-248.737473,294.500488,0.000000
114.070007,65.348396,-248.781952,-0.000823,0.003991,0.101370,290.684174,14.808158,1.013697,-248.781952,294.500488,0.000000
114.440002,65.318596,-248.737473,-0.000819,0.003991,0.101370,290.551636,14.801406,1.013697,-248.737473,294.500488,0.000000
114.810005,65.309669,-248.826447,-0.000832,0.003991,0.101370,290.511932,14.799383,1.013697,-248.826447,294.500488,0.000000
115.180008,65.286201,-248.870926,-0.000819,0.003991,0.101370,290.407532,14.794065,1.013697,-248.870926,294.500488,0.000000
115.550003,65.293282,-248.915405,-0.000832,0.003991,0.101370,290.439026,14.795669,1.013697,-248.915405,294.500488,0.000000
115.920006,65.275032,-248.915405,-0.000823,0.003991,0.101370,290.357849,14.791533,1.013697,-248.915405,294.500488,0.000000
116.290009,65.262749,-248.915405,-0.000819,0.003991,0.101370,290.303192,14.788750,1.013697,-248.915405,294.500488,0.000000
116.660004,65.244118,-248.959885,-0.000832,0.003991,0.101370,290.220337,14.784528,1.013697,-248.959885,294.500488,0.000000
117.030006,65.224022,-249.048843,-0.000828,0.003991,0.101370,290.130951,14.779975,1.013697,-249.048843,294.500488,0.000000
117.400009,65.216576,-249.093323,-0.000832,0.003991,0.101370,290.097809,14.778287,1.013697,-249.093323,294.500488,0.000000
117.770004,65.205772,-249.004364,-0.000823,0.003991,0.101370,290.049774,14.775839,1.013697,-249.004364,294.500488,0.000000
118.140007,65.168526,-249.093323,-0.000828,0.003991,0.101370,289.884094,14.767399,1.013697,-249.093323,294.500488,0.000000
118.510002,65.162575,-249.093323,-0.000819,0.003991,0.101378,289.857605,14.766050,1.013784,-249.093323,294.500488,0.000000
118.880005,65.129066,-249.093323,-0.000845,0.003991,0.101378,289.708557,14.758457,1.013784,-249.093323,294.500488,0.000000
119.250008,65.110069,-249.182281,-0.000819,0.003991,0.101378,289.624054,14.754152,1.013784,-249.182281,294.500488,0.000000
119.620003,65.113792,-249.271255,-0.000832,0.003991,0.101378,289.640625,14.754995,1.013784,-249.271255,294.500488,0.000000
119.990005,65.075066,-249.137802,-0.000823,0.003991,0.101378,289.468353,14.746221,1.013784,-249.137802,294.500488,0.000000
120.360008,65.749809,-249.226776,-0.000832,0.003999,0.101578,292.469757,14.899120,1.015779,-249.226776,294.500488,0.000000
120.730003,65.754646,-249.315735,-0.000836,0.003999,0.101578,292.491272,14.900216,1.015779,-249.315735,294.500488,0.000000
121.100006,65.771400,-249.360214,-0.000828,0.003999,0.101578,292.565796,14.904013,1.015779,-249.360214,294.500488,0.000000
121.470009,65.787041,-249.404694,-0.000819,0.003999,0.101578,292.635376,14.907557,1.015779,-249.404694,294.500488,0.000000
121.840004,65.788902,-249.360214,-0.000815,0.003999,0.101578,292.643646,14.907978,1.015779,-249.360214,294.500488,0.000000
122.210007,65.773262,-249.404694,-0.000828,0.003999,0.101578,292.574097,14.904434,1.015779,-249.404694,294.500488,0.000000
122.580009,65.781090,-249.493652,-0.000845,0.003999,0.101578,292.608887,14.906208,1.015779,-249.493652,294.500488,0.000000
122.950005,65.781090,-249.493652,-0.000832,0.003999,0.101578,292.608887,14.906208,1.015779,-249.493652,294.500488,0.000000
123.320007,65.786293,-249.493652,-0.000811,0.003999,0.101578,292.632050,14.907387,1.015779,-249.493652,294.500488,0.000000
123.690002,65.781090,-249.538132,-0.000819,0.003999,0.101578,292.608887,14.906208,1.015779,-249.538132,294.500488,0.000000
124.060005,65.744591,-249.582611,-0.000823,0.003999,0.101578,292.446533,14.897937,1.015779,-249.582611,294.500488,0.000000
124.430008,65.756889,-249.671585,-0.000819,0.003999,0.101578,292.501251,14.900724,1.015779,-249.671585,294.500488,0.000000
124.800003,65.762093,-249.671585,-0.000828,0.003999,0.101578,292.524384,14.901904,1.015779,-249.671585,294.500488,0.000000
125.170006,65.750175,-249.671585,-0.000819,0.003999,0.101578,292.471375,14.899202,1.015779,-249.671585,294.500488,0.000000
125.540009,65.673103,-249.716064,-0.000828,0.003999,0.101578,292.128540,14.881738,1.015779,-249.716064,294.500488,0.000000
125.910004,65.681664,-249.716064,-0.000828,0.003999,0.101578,292.166626,14.883677,1.015779,-249.716064,294.500488,0.000000
126.280006,65.667137,-249.849503,-0.000819,0.003999,0.101578,292.102020,14.880386,1.015779,-249.849503,294.500488,0.000000
126.650009,65.661934,-249.805023,-0.000819,0.003999,0.101578,292.078857,14.879207,1.015779,-249.805023,294.500488,0.000000
127.020004,65.650383,-249.805023,-0.000815,0.003999,0.101578,292.027496,14.876590,1.015779,-249.805023,294.500488,0.000000
127.390007,65.623207,-249.760544,-0.000832,0.003999,0.101578,291.906616,14.870431,1.015779,-249.760544,294.500488,0.000000
127.760010,65.608299,-249.893982,-0.000832,0.003999,0.101578,291.840302,14.867053,1.015779,-249.893982,294.500488,0.000000
128.130005,65.599739,-249.938461,-0.000832,0.003999,0.101578,291.802216,14.865113,1.015779,-249.938461,294.500488,0.000000
128.500000,65.600487,-250.027420,-0.000828,0.003999,0.101578,291.805542,14.865283,1.015779,-250.027420,294.500488,0.000000
128.870010,65.589317,-249.982941,-0.000819,0.003999,0.101578,291.755859,14.862752,1.015779,-249.982941,294.500488,0.000000
129.240005,65.574791,-250.027420,-0.000823,0.003999,0.101578,291.691223,14.859460,1.015779,-250.027420,294.500488,0.000000
129.610001,65.564369,-250.027420,-0.000819,0.003999,0.101578,291.644867,14.857099,1.015779,-250.027420,294.500488,0.000000
129.980011,65.562126,-250.116394,-0.000823,0.003999,0.101578,291.634888,14.856590,1.015779,-250.116394,294.500488,0.000000
130.350006,65.550957,-250.205353,-0.000823,0.003999,0.101578,291.585205,14.854059,1.015779,-250.205353,294.500488,0.000000
130.720001,65.531593,-250.160873,-0.000815,0.003999,0.101578,291.499084,14.849671,1.015779,-250.160873,294.500488,0.000000
131.090012,65.534950,-250.116394,-0.000815,0.003999,0.101578,291.514008,14.850431,1.015779,-250.116394,1681.640991,0.000000
131.460007,65.429192,-250.205353,-0.000819,0.003989,0.101309,291.043579,14.826467,1.013091,-250.205353,0.101101,0.000000
131.830002,65.356575,-250.249832,-0.000819,0.003965,0.100719,290.720551,14.810012,1.007195,-250.249832,0.100485,0.000000
132.200012,65.357704,-250.338791,-0.000815,0.003944,0.100182,290.725586,14.810267,1.001816,-250.338791,0.099870,0.000000
132.570007,65.320091,-250.383270,-0.000802,0.003920,0.099575,290.558289,14.801744,0.995749,-250.383270,0.099254,0.000000
132.940002,65.275398,-250.294312,-0.000802,0.003903,0.099132,290.359467,14.791616,0.991325,-250.294312,0.098629,0.000000
133.310013,65.306313,-250.383270,-0.000802,0.003876,0.098439,290.496979,14.798622,0.984387,-250.383270,0.098014,0.000000
133.680008,65.273537,-250.338791,-0.000819,0.003855,0.097918,290.351196,14.791195,0.979183,-250.338791,0.097398,0.000000
134.050003,65.242256,-250.427750,-0.000811,0.003830,0.097285,290.212036,14.784107,0.972854,-250.427750,0.096782,0.000000
134.420013,65.182304,-250.472229,-0.000798,0.003801,0.096539,289.945374,14.770521,0.965394,-250.472229,0.096167,0.000000
134.790009,65.075066,-250.472229,-0.000802,0.003783,0.096080,289.468353,14.746221,0.960799,-250.472229,0.095551,0.000000
135.160004,64.796898,-250.516724,-0.000815,0.003760,0.095516,288.230988,14.683187,0.955160,-250.516724,0.094935,0.000000
135.530014,63.921837,-250.605682,-0.000802,0.003737,0.094926,284.338531,14.484896,0.949263,-250.605682,0.094319,0.000000
135.900009,62.915680,-250.605682,-0.000793,0.003715,0.094363,279.862915,14.256897,0.943627,-250.605682,0.093704,0.000000
136.270004,61.752762,-250.605682,-0.000789,0.003693,0.093790,274.690002,13.993376,0.937905,-250.605682,0.093079,0.000000
136.639999,60.074852,-250.650162,-0.000789,0.003670,0.093209,267.226288,13.613155,0.932095,-250.650162,0.092463,0.000000
137.010010,58.596901,-250.650162,-0.000780,0.003647,0.092646,260.652039,13.278248,0.926455,-250.650162,0.091848,0.000000
137.380005,56.717911,-250.739120,-0.000776,0.003623,0.092030,252.293869,12.852462,0.920297,-250.739120,0.091232,0.000000
137.750000,54.988617,-250.828079,-0.000785,0.003604,0.091544,244.601578,12.460599,0.915441,-250.828079,0.090616,0.000000
138.120010,52.694427,-250.783600,-0.000785,0.003581,0.090946,234.396515,11.940728,0.909457,-250.783600,0.090001,0.000000
138.490005,50.752876,-250.783600,-0.000776,0.003560,0.090426,225.760071,11.500766,0.904257,-250.783600,0.089385,0.000000
138.860001,48.109779,-250.828079,-0.000789,0.003532,0.089714,214.002991,10.901832,0.897145,-250.828079,0.088769,0.000000
139.230011,45.709839,-250.872559,-0.000785,0.003513,0.089237,203.327515,10.357998,0.892372,-250.872559,0.088145,0.000000
139.600006,42.248634,-250.917038,-0.000785,0.003482,0.088448,187.931305,9.573677,0.884481,-250.917038,0.087529,0.000000
139.970001,40.398689,-250.917038,-0.000772,0.003467,0.088058,179.702347,9.154474,0.880579,-250.917038,0.086913,0.000000
140.340012,37.428650,-250.961533,-0.000780,0.003438,0.087321,166.490952,8.481453,0.873209,-250.961533,0.086297,0.000000
140.710007,34.539040,-250.961533,-0.000776,0.003411,0.086636,153.637314,7.826658,0.866359,-250.961533,0.085682,0.000000
141.080002,32.044510,-251.050491,-0.000785,0.003390,0.086107,142.541092,7.261390,0.861067,-251.050491,0.085066,0.000000
141.450012,28.952332,-251.094971,-0.000776,0.003361,0.085361,128.786407,6.560692,0.853607,-251.094971,0.084450,0.000000
141.820007,26.220978,-251.139450,-0.000785,0.003336,0.084728,116.636734,5.941758,0.847279,-251.139450,0.083835,0.000000
142.190002,23.767418,-251.094971,-0.000767,0.003316,0.084225,105.722755,5.385774,0.842249,-251.094971,0.083219,0.000000
142.560013,20.926964,-251.094971,-0.000780,0.003289,0.083531,93.087784,4.742118,0.835311,-251.094971,0.082594,0.000000
142.930008,19.144043,-251.094971,-0.000767,0.003272,0.083097,85.156960,4.338102,0.830974,-251.094971,0.081979,0.000000
143.300003,15.652306,-251.317368,-0.000772,0.003240,0.082291,69.624931,3.546863,0.822908,-251.317368,0.081363,0.000000
143.670013,13.444138,-251.272888,-0.000780,0.003221,0.081823,59.802509,3.046485,0.818226,-251.272888,0.080747,0.000000
144.040009,10.040283,-251.228409,-0.000789,0.003189,0.080999,44.661411,2.275161,0.809986,-251.228409,0.080132,0.000000
144.410004,8.014946,-251.272888,-0.000776,0.003172,0.080574,35.652260,1.816213,0.805740,-251.272888,0.079516,0.000000
144.780014,5.154755,-251.317368,-0.000789,0.003143,0.079837,22.929493,1.168084,0.798367,-251.317368,0.078900,0.000000
145.150009,2.449097,-251.406342,-0.000789,0.003121,0.079264,10.894126,0.554973,0.792644,-251.406342,0.078284,0.000000
145.520004,0.367905,-251.406342,-0.000772,0.003098,0.078692,1.636522,0.083368,0.786921,-251.406342,0.077669,0.000000
145.889999,-0.695587,-251.406342,-0.000785,0.003067,0.077903,-3.094126,-0.157622,0.779026,-251.406342,0.077044,0.000000
146.260010,-0.155647,-251.406342,-0.000789,0.003052,0.077521,-0.692354,-0.035270,0.775211,-251.406342,0.076428,0.000000
146.630005,-0.013405,-251.495300,-0.000836,0.003025,0.076836,-0.059628,-0.003038,0.768360,-251.495300,0.075813,0.000000
147.000000,0.018250,-251.584259,-0.000862,0.002997,0.076134,0.081178,0.004135,0.761335,-251.584259,0.075197,0.000000
147.370010,0.006706,-251.495300,-0.000901,0.002975,0.075553,0.029831,0.001520,0.755526,-251.495300,0.074581,0.000000
147.740005,0.055855,-251.495300,-0.000927,0.002948,0.074867,0.248455,0.012657,0.748675,-251.495300,0.073966,0.000000
148.110001,-0.012291,-251.584259,-0.000970,0.002927,0.074356,-0.054673,-0.002785,0.743558,-251.584259,0.073350,0.000000
148.480011,-0.025322,-251.584259,-0.001013,0.002895,0.073532,-0.112638,-0.005738,0.735318,-251.584259,0.072734,0.000000
148.850006,-0.003723,-251.628738,-0.001039,0.002876,0.073055,-0.016561,-0.000844,0.730549,-251.628738,0.072119,0.000000
149.220001,0.016014,-251.673218,-0.001056,0.002851,0.072422,0.071234,0.003629,0.724221,-251.673218,0.071494,0.000000
149.590012,-0.004837,-251.717697,-0.001078,0.002833,0.071953,-0.021516,-0.001096,0.719535,-251.717697,0.070878,0.000000
149.960007,0.004097,-251.762177,-0.001104,0.002803,0.071208,0.018224,0.000928,0.712079,-251.762177,0.070262,0.000000
150.200012,0.026810,-251.806671,-0.001117,0.002803,0.071208,0.119255,0.006075,0.712079,-251.806671,0.071078,0.000000