File: Data/compression 24/AutoHeating-12-24-reverse-1-5_09202024_170222.csv
Time (sec),S:Load (lbs),S:HL1 (DIM),S:LVDT (in),S:Position (in),Ch:Position (mm),Ch:Load (N),Ch:Stress (MPa),Ch:Strain (mm/mm),Ch:HL1 (DIM),Set Point (),Cycles ()
0.110000,0.010803,-270.666595,-0.010438,-0.005387,-0.136831,0.048055,0.002448,-1.368311,-270.666595,-0.136666,0.000000
0.470000,-0.026436,-270.622101,-0.010421,-0.005349,-0.135877,-0.117593,-0.005990,-1.358770,-270.622101,-0.135400,0.000000
0.830000,-0.003723,-270.711060,-0.010352,-0.005140,-0.130544,-0.016561,-0.000844,-1.305437,-270.711060,-0.129416,0.000000
1.190000,0.035751,-270.755554,-0.010123,-0.004910,-0.124716,0.159030,0.008101,-1.247161,-270.755554,-0.123415,0.000000
1.550000,0.029419,-270.755554,-0.009869,-0.004667,-0.118550,0.130862,0.006666,-1.185501,-270.755554,-0.117414,0.000000
1.910000,0.015640,-270.800018,-0.009636,-0.004430,-0.112514,0.069571,0.003544,-1.125139,-270.800018,-0.111413,0.000000
2.270000,0.001488,-270.800018,-0.009395,-0.004195,-0.106565,0.006618,0.000337,-1.065649,-270.800018,-0.105429,0.000000
2.630000,-0.036865,-270.844513,-0.009145,-0.003958,-0.100529,-0.163985,-0.008354,-1.005291,-270.844513,-0.099428,0.000000
2.990000,-0.012657,-270.800018,-0.008908,-0.003716,-0.094381,-0.056302,-0.002868,-0.943805,-270.800018,-0.093426,0.000000
3.350000,0.033142,-270.844513,-0.008679,-0.003487,-0.088579,0.147423,0.007510,-0.885787,-270.844513,-0.087425,0.000000
3.710000,0.052505,-270.933472,-0.008412,-0.003258,-0.082751,0.233556,0.011898,-0.827507,-270.933472,-0.081424,0.000000
4.070000,0.010803,-270.888977,-0.008157,-0.003010,-0.076455,0.048055,0.002448,-0.764549,-270.888977,-0.075440,0.000000
4.430000,0.005585,-270.977966,-0.007925,-0.002781,-0.070644,0.024842,0.001266,-0.706443,-270.977966,-0.069439,0.000000
4.790000,-0.045799,-271.022430,-0.007696,-0.002543,-0.064582,-0.203725,-0.010378,-0.645824,-271.022430,-0.063438,0.000000
5.150000,-0.037239,-270.933472,-0.007442,-0.002303,-0.058494,-0.165648,-0.008438,-0.584944,-270.933472,-0.057437,0.000000
5.510000,0.021225,-271.066925,-0.007200,-0.002067,-0.052493,0.094413,0.004810,-0.524935,-271.066925,-0.051435,0.000000
5.870000,0.048035,-271.066925,-0.006963,-0.001835,-0.046605,0.213669,0.010885,-0.466049,-271.066925,-0.045451,0.000000
6.230000,0.045433,-271.111389,-0.006709,-0.001602,-0.040682,0.202096,0.010295,-0.406816,-271.111389,-0.039450,0.000000
6.590000,0.027557,-271.200348,-0.006467,-0.001362,-0.034585,0.122581,0.006245,-0.345852,-271.200348,-0.033449,0.000000
6.950000,-0.007820,-271.155884,-0.006239,-0.001125,-0.028584,-0.034786,-0.001772,-0.285839,-271.155884,-0.027448,0.000000
7.310000,-0.021599,-271.244843,-0.005997,-0.000889,-0.022591,-0.096076,-0.004894,-0.225913,-271.244843,-0.021447,0.000000
7.670001,0.018990,-271.289307,-0.005747,-0.000652,-0.016556,0.084470,0.004303,-0.165555,-271.289307,-0.015463,0.000000
8.030001,0.050270,-271.244843,-0.005493,-0.000413,-0.010502,0.223612,0.011391,-0.105023,-271.244843,-0.009461,0.000000
8.390000,0.046921,-271.333801,-0.005269,-0.000182,-0.004614,0.208714,0.010632,-0.046138,-271.333801,-0.003461,0.000000
8.750000,0.052132,-271.289307,-0.005010,0.000050,0.001275,0.231893,0.011813,0.012748,-271.289307,0.002541,0.000000
9.110001,0.020851,-271.378296,-0.004760,0.000291,0.007388,0.092750,0.004725,0.073885,-271.378296,0.008525,0.000000
9.470000,0.002983,-271.333801,-0.004523,0.000528,0.013407,0.013269,0.000676,0.134072,-271.333801,0.014526,0.000000
9.830001,0.048035,-271.378296,-0.004281,0.000764,0.019399,0.213669,0.010885,0.193995,-271.378296,0.020527,0.000000
10.190001,0.075592,-271.422760,-0.004074,-0.000002,-0.000052,0.336250,0.017129,-0.000519,-271.422760,0.000156,0.000000
10.550000,0.058838,-271.467255,-0.004087,-0.000002,-0.000061,0.261724,0.013333,-0.000606,-271.467255,0.000156,0.000000
10.910001,0.082664,-271.511719,-0.004083,-0.000002,-0.000052,0.367710,0.018732,-0.000519,-271.511719,0.000598,0.000000
11.270000,0.083412,-271.511719,-0.004092,-0.000002,-0.000043,0.371036,0.018901,-0.000431,-271.511719,0.001197,0.000000
11.630000,0.112457,-271.511719,-0.004057,0.000039,0.000989,0.500235,0.025483,0.009886,-271.511719,0.001795,0.000000
11.990001,0.075966,-271.600677,-0.004049,0.000059,0.001500,0.337913,0.017214,0.015003,-271.600677,0.002402,0.000000
12.350000,0.072983,-271.511719,-0.004031,0.000079,0.001995,0.324644,0.016538,0.019946,-271.511719,0.003001,0.000000
12.710001,0.112083,-271.645172,-0.004005,0.000105,0.002671,0.498572,0.025398,0.026710,-271.645172,0.003599,0.000000
13.070001,0.119904,-271.689636,-0.003984,0.000120,0.003044,0.533358,0.027171,0.030442,-271.689636,0.004197,0.000000
13.430000,0.117668,-271.689636,-0.003932,0.000155,0.003929,0.523414,0.026664,0.039287,-271.689636,0.004796,0.000000
13.790001,0.126236,-271.734131,-0.003915,0.000177,0.004501,0.561526,0.028605,0.045010,-271.734131,0.005394,0.000000
14.150001,0.107246,-271.734131,-0.003906,0.000200,0.005091,0.477056,0.024302,0.050907,-271.734131,0.006001,0.000000
14.510000,0.115067,-271.778625,-0.003880,0.000226,0.005741,0.511841,0.026074,0.057413,-271.778625,0.006600,0.000000
14.870001,0.118790,-271.823090,-0.003867,0.000246,0.006244,0.528403,0.026918,0.062439,-271.823090,0.007198,0.000000
15.230000,0.134056,-271.689636,-0.003824,0.000269,0.006842,0.596311,0.030378,0.068423,-271.689636,0.007797,0.000000
15.590001,0.135170,-271.867584,-0.003803,0.000296,0.007528,0.601266,0.030630,0.075278,-271.867584,0.008395,0.000000
15.950001,0.115807,-271.867584,-0.003781,0.000318,0.008074,0.515133,0.026242,0.080739,-271.867584,0.009002,0.000000
16.310001,0.094955,-271.867584,-0.003760,0.000336,0.008533,0.422383,0.021517,0.085334,-271.867584,0.009600,0.000000
16.670000,0.115067,-271.956543,-0.003760,0.000357,0.009063,0.511841,0.026074,0.090626,-271.956543,0.010199,0.000000
17.030001,0.149696,-271.912048,-0.003717,0.000388,0.009843,0.665883,0.033922,0.098430,-271.912048,0.010797,0.000000
17.390001,0.160492,-272.001007,-0.003678,0.000415,0.010537,0.713904,0.036368,0.105368,-272.001007,0.011396,0.000000
17.750000,0.160492,-272.001007,-0.003665,0.000434,0.011022,0.713904,0.036368,0.110224,-272.001007,0.012003,0.000000
18.110001,0.132935,-272.045502,-0.003639,0.000456,0.011578,0.591322,0.030123,0.115776,-272.045502,0.012601,0.000000
18.470001,0.188049,-272.089966,-0.003617,0.000481,0.012228,0.836485,0.042613,0.122279,-272.089966,0.013199,0.000000
18.830002,0.167938,-272.045502,-0.003600,0.000499,0.012679,0.747027,0.038055,0.126790,-272.045502,0.013798,0.000000
19.190001,0.215607,-272.134460,-0.003553,0.000532,0.013503,0.959066,0.048857,0.135030,-272.134460,0.014396,0.000000
19.550001,0.204803,-272.134460,-0.003535,0.000557,0.014136,0.911011,0.046409,0.141358,-272.134460,0.015003,0.000000
19.910002,0.201828,-272.134460,-0.003514,0.000578,0.014674,0.897776,0.045735,0.146737,-272.134460,0.015601,0.000000
20.270000,0.210388,-272.223419,-0.003497,0.000603,0.015324,0.935853,0.047675,0.153239,-272.223419,0.016200,0.000000
20.630001,0.266617,-272.178925,-0.003466,0.000624,0.015853,1.185971,0.060416,0.158530,-272.178925,0.016798,0.000000
20.990002,0.256935,-272.267914,-0.003445,0.000650,0.016512,1.142905,0.058222,0.165120,-272.267914,0.017397,0.000000
21.350000,0.286354,-272.267914,-0.003415,0.000673,0.017085,1.273767,0.064889,0.170846,-272.267914,0.017995,0.000000
21.710001,0.252838,-272.267914,-0.003393,0.000697,0.017691,1.124680,0.057294,0.176914,-272.267914,0.018602,0.000000
22.070002,0.250237,-272.401337,-0.003372,0.000714,0.018134,1.113108,0.056704,0.181338,-272.401337,0.019200,0.000000
22.430000,0.321358,-272.401337,-0.003341,0.000739,0.018758,1.429471,0.072821,0.187583,-272.401337,0.019799,0.000000
22.790001,0.362694,-272.445831,-0.003320,0.000759,0.019278,1.613343,0.082188,0.192784,-272.445831,0.020397,0.000000
23.150002,0.349655,-272.401337,-0.003307,0.000788,0.020016,1.555344,0.079233,0.200157,-272.401337,0.020996,0.000000
23.510000,0.383919,-272.401337,-0.003290,0.000812,0.020623,1.707756,0.086997,0.206228,-272.401337,0.021603,0.000000
23.870001,0.370140,-272.490295,-0.003251,0.000836,0.021239,1.646465,0.083875,0.212386,-272.490295,0.022201,0.000000
24.230001,0.405518,-272.490295,-0.003229,0.000858,0.021785,1.803832,0.091892,0.217847,-272.490295,0.022799,0.000000
24.590002,0.493019,-272.490295,-0.003208,0.000882,0.022401,2.193058,0.111720,0.224005,-272.490295,0.023398,0.000000
24.950001,0.546272,-272.579254,-0.003186,0.000909,0.023094,2.429940,0.123787,0.230943,-272.579254,0.023996,0.000000
25.310001,0.589096,-272.534790,-0.003152,0.000935,0.023745,2.620430,0.133491,0.237449,-272.534790,0.024603,0.000000
25.670002,0.631172,-272.623749,-0.003130,0.000957,0.024300,2.807594,0.143026,0.242998,-272.623749,0.025202,0.000000
26.030001,0.699692,-272.623749,-0.003122,0.000980,0.024889,3.112385,0.158552,0.248895,-272.623749,0.025800,0.000000
26.390001,0.719795,-272.623749,-0.003091,0.000996,0.025297,3.201809,0.163108,0.252971,-272.623749,0.026399,0.000000
26.750002,0.843796,-272.712708,-0.003078,0.001021,0.025922,3.753391,0.191207,0.259216,-272.712708,0.026997,0.000000
27.110001,0.945084,-272.668243,-0.003048,0.001050,0.026676,4.203942,0.214159,0.266759,-272.668243,0.027604,0.000000
27.470001,1.003174,-272.801666,-0.003022,0.001073,0.027266,4.462340,0.227322,0.272656,-272.801666,0.028202,0.000000
27.830002,1.053818,-272.712708,-0.002992,0.001098,0.027881,4.687615,0.238799,0.278814,-272.712708,0.028801,0.000000
28.190001,1.199409,-272.757202,-0.002971,0.001124,0.028549,5.335240,0.271790,0.285491,-272.757202,0.029399,0.000000
28.550001,1.251915,-272.846161,-0.002953,0.001140,0.028948,5.568796,0.283688,0.289480,-272.846161,0.029998,0.000000
28.910002,1.416878,-272.890625,-0.002923,0.001173,0.029789,6.302587,0.321069,0.297894,-272.890625,0.030605,0.000000
29.270000,1.492470,-272.890625,-0.002897,0.001192,0.030275,6.638837,0.338198,0.302750,-272.890625,0.031203,0.000000
29.630001,1.619446,-272.846161,-0.002884,0.001218,0.030943,7.203655,0.366972,0.309427,-272.846161,0.031801,0.000000
29.990002,1.758347,-272.935120,-0.002850,0.001241,0.031524,7.821516,0.398447,0.315236,-272.935120,0.032400,0.000000
30.350002,1.819038,-273.024078,-0.002850,0.001253,0.031827,8.091487,0.412200,0.318272,-273.024078,0.032998,0.000000
30.710001,2.138161,-272.979584,-0.002811,0.001288,0.032712,9.511014,0.484514,0.327117,-272.979584,0.033596,0.000000
31.070002,2.247643,-273.068573,-0.002772,0.001312,0.033319,9.998013,0.509323,0.333188,-273.068573,0.034203,0.000000
31.430002,2.350044,-273.024078,-0.002759,0.001335,0.033900,10.453519,0.532528,0.338998,-273.024078,0.034802,0.000000
31.790001,2.462128,-273.068573,-0.002729,0.001356,0.034455,10.952091,0.557926,0.344550,-273.068573,0.035400,0.000000
32.150002,2.730980,-273.201996,-0.002721,0.001381,0.035088,12.148005,0.618849,0.350879,-273.201996,0.035999,0.000000
32.510002,2.833382,-273.068573,-0.002699,0.001397,0.035496,12.603511,0.642053,0.354955,-273.068573,0.036597,0.000000
32.870003,3.169266,-273.113037,-0.002677,0.001431,0.036354,14.097598,0.718166,0.363543,-273.113037,0.037204,0.000000
33.230003,3.244858,-273.246490,-0.002660,0.001451,0.036849,14.433848,0.735295,0.368486,-273.246490,0.037802,0.000000
33.590000,3.426949,-273.201996,-0.002630,0.001475,0.037464,15.243829,0.776558,0.374644,-273.201996,0.038401,0.000000
33.950001,3.659302,-273.290955,-0.002617,0.001501,0.038132,16.277388,0.829210,0.381321,-273.290955,0.038999,0.000000
34.310001,3.735641,-273.246490,-0.002596,0.001518,0.038548,16.616962,0.846508,0.385484,-273.246490,0.039598,0.000000
34.670002,3.977684,-273.379913,-0.002570,0.001546,0.039268,17.693623,0.901356,0.392679,-273.379913,0.040205,0.000000
35.030003,4.173553,-273.379913,-0.002552,0.001571,0.039892,18.564894,0.945741,0.398924,-273.379913,0.040803,0.000000
35.390003,4.269623,-273.335449,-0.002531,0.001593,0.040465,18.992231,0.967510,0.404647,-273.335449,0.041401,0.000000
35.750000,4.376869,-273.379913,-0.002527,0.001612,0.040942,19.469286,0.991813,0.409420,-273.379913,0.042000,0.000000
36.110001,4.687798,-273.424408,-0.002479,0.001644,0.041757,20.852365,1.062270,0.417569,-273.424408,0.042598,0.000000
36.470001,4.839729,-273.468872,-0.002462,0.001666,0.042321,21.528191,1.096698,0.423208,-273.468872,0.043205,0.000000
36.830002,4.978249,-273.468872,-0.002449,0.001688,0.042876,22.144356,1.128087,0.428757,-273.468872,0.043804,0.000000
37.190002,5.057564,-273.468872,-0.002419,0.001713,0.043509,22.497168,1.146060,0.435089,-273.468872,0.044402,0.000000
37.550003,5.109322,-273.602325,-0.002423,0.001731,0.043968,22.727398,1.157789,0.439684,-273.602325,0.045001,0.000000
37.910004,5.329025,-273.557861,-0.002389,0.001755,0.044584,23.704689,1.207574,0.445842,-273.557861,0.045599,0.000000
38.270000,5.360306,-273.557861,-0.002354,0.001775,0.045096,23.843830,1.214663,0.450959,-273.557861,0.046197,0.000000
38.630001,5.750923,-273.691284,-0.002350,0.001809,0.045937,25.581385,1.303178,0.459369,-273.691284,0.046804,0.000000
38.990002,5.810127,-273.602325,-0.002315,0.001830,0.046492,25.844736,1.316594,0.464921,-273.602325,0.047403,0.000000
39.350002,5.863007,-273.602325,-0.002302,0.001851,0.047021,26.079956,1.328576,0.470213,-273.602325,0.048001,0.000000
39.710003,6.074883,-273.646820,-0.002281,0.001876,0.047645,27.022427,1.376588,0.476454,-273.646820,0.048600,0.000000
40.070004,6.179153,-273.691284,-0.002255,0.001898,0.048201,27.486248,1.400216,0.482006,-273.691284,0.049198,0.000000
40.430000,6.589500,-273.780243,-0.002238,0.001925,0.048894,29.311562,1.493202,0.488944,-273.780243,0.049805,0.000000
40.790001,6.635307,-273.735779,-0.002216,0.001951,0.049545,29.515322,1.503582,0.495447,-273.735779,0.050403,0.000000
41.150002,6.582802,-273.824738,-0.002199,0.001972,0.050082,29.281765,1.491684,0.500825,-273.824738,0.051001,0.000000
41.510002,6.823723,-273.869202,-0.002173,0.001997,0.050724,30.353436,1.546278,0.507240,-273.869202,0.051600,0.000000
41.870003,7.050125,-273.869202,-0.002143,0.002022,0.051366,31.360523,1.597581,0.513659,-273.869202,0.052198,0.000000
42.230003,6.951820,-273.913696,-0.002130,0.002036,0.051713,30.923241,1.575305,0.517126,-273.913696,0.052805,0.000000
42.590000,7.364037,-273.913696,-0.002100,0.002067,0.052510,32.756870,1.668715,0.525105,-273.913696,0.053404,0.000000
42.950001,7.456017,-273.913696,-0.002074,0.002089,0.053057,33.166019,1.689558,0.530570,-273.913696,0.054002,0.000000
43.310001,7.555435,-273.958191,-0.002074,0.002110,0.053603,33.608253,1.712086,0.536032,-273.958191,0.054601,0.000000
43.670002,7.882011,-274.002655,-0.002031,0.002136,0.054245,35.060936,1.786089,0.542451,-274.002655,0.055199,0.000000
44.030003,7.823921,-274.047150,-0.002031,0.002154,0.054705,34.802540,1.772926,0.547046,-274.047150,0.055806,0.000000
44.390003,8.328857,-274.002655,-0.001992,0.002184,0.055468,37.048607,1.887346,0.554680,-274.002655,0.056404,0.000000
44.750004,8.465889,-274.091614,-0.001975,0.002208,0.056092,37.658154,1.918398,0.560921,-274.091614,0.057003,0.000000
45.110001,8.548180,-274.047150,-0.001944,0.002229,0.056621,38.024200,1.937045,0.566213,-274.047150,0.057601,0.000000
45.470001,8.688568,-274.136108,-0.001927,0.002251,0.057185,38.648682,1.968858,0.571848,-274.136108,0.058200,0.000000
45.830002,8.968216,-274.180573,-0.001910,0.002272,0.057714,39.892616,2.032227,0.577140,-274.180573,0.058798,0.000000
46.190002,9.352509,-274.180573,-0.001893,0.002298,0.058382,41.602036,2.119309,0.583816,-274.180573,0.059405,0.000000
46.550003,9.703285,-274.269531,-0.001854,0.002329,0.059154,43.162369,2.198796,0.591537,-274.269531,0.060003,0.000000
46.910004,9.806061,-274.269531,-0.001854,0.002352,0.059743,43.619537,2.222085,0.597434,-274.269531,0.060602,0.000000
47.270000,9.818718,-274.180573,-0.001815,0.002370,0.060194,43.675838,2.224953,0.601942,-274.180573,0.061200,0.000000
47.630001,10.165771,-274.314026,-0.001802,0.002392,0.060758,45.219608,2.303597,0.607578,-274.314026,0.061799,0.000000
47.990002,10.503510,-274.314026,-0.001785,0.002415,0.061339,46.721943,2.380129,0.613391,-274.314026,0.062406,0.000000
48.350002,11.171173,-274.402985,-0.001755,0.002446,0.062120,49.691860,2.531424,0.621196,-274.402985,0.063004,0.000000
48.710003,11.169312,-274.447479,-0.001738,0.002465,0.062623,49.683578,2.531002,0.626226,-274.447479,0.063603,0.000000
49.070004,11.507423,-274.402985,-0.001712,0.002490,0.063255,51.187576,2.607620,0.632554,-274.402985,0.064201,0.000000
49.430004,11.830643,-274.491943,-0.001703,0.002516,0.063906,52.625328,2.680862,0.639061,-274.491943,0.064799,0.000000
49.790001,11.624725,-274.491943,-0.001673,0.002531,0.064296,51.709362,2.634200,0.642963,-274.491943,0.065406,0.000000
50.150002,12.716148,-274.536438,-0.001651,0.002565,0.065163,56.564255,2.881520,0.651634,-274.536438,0.066005,0.000000
50.510002,12.768654,-274.536438,-0.001643,0.002586,0.065675,56.797810,2.893418,0.656751,-274.536438,0.066603,0.000000
50.870003,13.122032,-274.669861,-0.001604,0.002611,0.066308,58.369713,2.973495,0.663083,-274.669861,0.067202,0.000000
51.230003,13.551010,-274.536438,-0.001578,0.002633,0.066889,60.277905,3.070703,0.668893,-274.536438,0.067800,0.000000
51.590004,13.640373,-274.580902,-0.001578,0.002652,0.067349,60.675411,3.090953,0.673488,-274.580902,0.068407,0.000000
51.950001,14.202660,-274.625397,-0.001556,0.002674,0.067930,63.176586,3.218369,0.679298,-274.625397,0.069005,0.000000
52.310001,15.053902,-274.669861,-0.001535,0.002705,0.068719,66.963097,3.411263,0.687189,-274.669861,0.069603,0.000000
52.670002,15.138802,-274.758820,-0.001496,0.002729,0.069326,67.340752,3.430501,0.693260,-274.758820,0.070202,0.000000
53.030003,15.410263,-274.714355,-0.001487,0.002748,0.069812,68.548271,3.492015,0.698116,-274.714355,0.070800,0.000000
53.390003,16.156494,-274.714355,-0.001470,0.002775,0.070497,71.867676,3.661114,0.704967,-274.714355,0.071399,0.000000
53.750004,16.141602,-274.758820,-0.001444,0.002790,0.070870,71.801430,3.657739,0.708699,-274.758820,0.072006,0.000000
54.110004,17.175308,-274.803314,-0.001427,0.002819,0.071598,76.399590,3.891981,0.715981,-274.803314,0.072604,0.000000
54.470001,17.513054,-274.847809,-0.001397,0.002844,0.072249,77.901955,3.968515,0.722487,-274.847809,0.073203,0.000000
54.830002,18.080917,-274.892273,-0.001393,0.002869,0.072865,80.427940,4.097194,0.728645,-274.892273,0.073801,0.000000
55.190002,18.366158,-274.847809,-0.001354,0.002888,0.073350,81.696747,4.161830,0.733501,-274.847809,0.074399,0.000000
55.550003,19.150375,-274.847809,-0.001358,0.002915,0.074044,85.185127,4.339537,0.740439,-274.847809,0.075006,0.000000
55.910004,19.966988,-274.892273,-0.001337,0.002938,0.074616,88.817596,4.524584,0.746162,-274.892273,0.075605,0.000000
56.270004,20.654755,-274.936768,-0.001311,0.002965,0.075319,91.876938,4.680434,0.753187,-274.936768,0.076203,0.000000
56.630001,21.020798,-275.025726,-0.001285,0.002986,0.075848,93.505180,4.763381,0.758478,-275.025726,0.076802,0.000000
56.990002,21.686226,-275.025726,-0.001272,0.003009,0.076429,96.465149,4.914169,0.764288,-275.025726,0.077400,0.000000
57.350002,22.477890,-275.070190,-0.001246,0.003034,0.077070,99.986649,5.093563,0.770703,-275.070190,0.078007,0.000000
57.710003,22.823082,-275.114685,-0.001237,0.003056,0.077626,101.522141,5.171784,0.776255,-275.114685,0.078605,0.000000
58.070004,24.105164,-275.070190,-0.001220,0.003084,0.078328,107.225121,5.462308,0.783280,-275.070190,0.079204,0.000000
58.430004,24.569511,-275.159149,-0.001186,0.003104,0.078831,109.290642,5.567531,0.788310,-275.159149,0.079802,0.000000
58.790001,25.191368,-275.159149,-0.001186,0.003126,0.079412,112.056801,5.708446,0.794120,-275.159149,0.080401,0.000000
59.150002,26.222099,-275.203644,-0.001177,0.003152,0.080054,116.641724,5.942012,0.800536,-275.203644,0.081008,0.000000
59.510002,26.764275,-275.159149,-0.001155,0.003169,0.080496,119.053436,6.064871,0.804960,-275.159149,0.081606,0.000000
59.870003,27.875435,-275.248138,-0.001134,0.003197,0.081198,123.996124,6.316664,0.811985,-275.248138,0.082205,0.000000
60.230003,28.892006,-275.292603,-0.001108,0.003220,0.081797,128.518066,6.547022,0.817969,-275.292603,0.082803,0.000000
60.590004,29.905609,-275.337097,-0.001091,0.003247,0.082482,133.026794,6.776708,0.824819,-275.337097,0.083401,0.000000
60.950005,30.330856,-275.292603,-0.001091,0.003264,0.082916,134.918381,6.873070,0.829157,-275.292603,0.084000,0.000000
61.310001,31.850510,-275.426056,-0.001074,0.003293,0.083653,141.678146,7.217429,0.836526,-275.426056,0.084607,0.000000
61.670002,32.984756,-275.381561,-0.001061,0.003317,0.084242,146.723526,7.474452,0.842423,-275.381561,0.085205,0.000000
62.030003,34.182304,-275.426056,-0.001043,0.003343,0.084910,152.050491,7.745821,0.849103,-275.426056,0.085804,0.000000
62.390003,34.981415,-275.426056,-0.001022,0.003365,0.085465,155.605103,7.926902,0.854652,-275.426056,0.086402,0.000000
62.750004,35.765633,-275.470520,-0.001009,0.003385,0.085977,159.093475,8.104609,0.859769,-275.470520,0.087000,0.000000
63.110004,37.588394,-275.515015,-0.000992,0.003416,0.086766,167.201523,8.517652,0.867661,-275.515015,0.087607,0.000000
63.470001,37.977524,-275.470520,-0.000974,0.003432,0.087174,168.932465,8.605830,0.871737,-275.470520,0.088205,0.000000
63.830002,39.531059,-275.515015,-0.000957,0.003457,0.087815,175.842941,8.957866,0.878152,-275.515015,0.088804,0.000000
64.190002,41.079018,-275.648468,-0.000949,0.003485,0.088509,182.728592,9.308639,0.885090,-275.648468,0.089402,0.000000
64.550003,42.062080,-275.515015,-0.000927,0.003504,0.088995,187.101471,9.531404,0.889950,-275.515015,0.090001,0.000000
64.910004,43.543747,-275.648468,-0.000927,0.003531,0.089680,193.692261,9.867154,0.896801,-275.648468,0.090608,0.000000
65.270004,44.820610,-275.603973,-0.000910,0.003551,0.090191,199.372025,10.156496,0.901914,-275.603973,0.091206,0.000000
65.630005,46.020393,-275.737427,-0.000892,0.003574,0.090773,204.708939,10.428370,0.907728,-275.737427,0.091805,0.000000
65.990005,47.854706,-275.692932,-0.000884,0.003602,0.091492,212.868362,10.844031,0.914923,-275.692932,0.092403,0.000000
66.350006,49.153168,-275.692932,-0.000871,0.003623,0.092021,218.644211,11.138267,0.920214,-275.692932,0.093001,0.000000
66.710007,50.031967,-275.826385,-0.000849,0.003640,0.092455,222.553299,11.337405,0.924551,-275.826385,0.093608,0.000000
67.070000,52.311256,-275.781891,-0.000841,0.003670,0.093209,232.692093,11.853900,0.932095,-275.781891,0.094207,0.000000
67.430000,52.752892,-275.826385,-0.000836,0.003681,0.093496,234.656586,11.953976,0.934956,-275.826385,0.094805,0.000000
67.790001,55.424660,-275.915344,-0.000819,0.003719,0.094458,246.541199,12.559407,0.944585,-275.915344,0.095404,0.000000
68.150002,57.301048,-275.870850,-0.000819,0.003743,0.095083,254.887787,12.984603,0.950826,-275.870850,0.096002,0.000000
68.510002,58.606216,-275.915344,-0.000798,0.003763,0.095568,260.693481,13.280358,0.955682,-275.915344,0.096600,0.000000
68.870003,60.296783,-275.959808,-0.000789,0.003787,0.096184,268.213501,13.663446,0.961840,-275.959808,0.097207,0.000000
69.230003,61.509598,-275.915344,-0.000759,0.003805,0.096653,273.608368,13.938273,0.966526,-275.915344,0.097806,0.000000
69.590004,63.679420,-276.004303,-0.000763,0.003830,0.097285,283.260223,14.429963,0.972854,-276.004303,0.098404,0.000000
69.950005,64.839729,-275.959808,-0.000737,0.003847,0.097710,288.421509,14.692893,0.977105,-275.959808,0.099003,0.000000
70.310005,66.023125,-276.093262,-0.000733,0.003860,0.098040,293.685516,14.961054,0.980401,-276.093262,0.017210,0.000000
70.670006,65.362541,-276.048767,-0.000733,0.003860,0.098031,290.747101,14.811363,0.980314,-276.048767,294.500488,0.000000
71.030006,64.833397,-276.137756,-0.000724,0.003860,0.098031,288.393341,14.691458,0.980314,-276.137756,294.500488,0.000000
71.390007,64.393257,-276.137756,-0.000724,0.003860,0.098031,286.435516,14.591721,0.980314,-276.137756,294.500488,0.000000
71.750000,65.603096,-276.137756,-0.000686,0.003680,0.093478,291.817139,14.865874,0.934782,-276.137756,294.500488,0.000000
72.110001,65.344658,-276.226715,-0.000677,0.003837,0.097467,290.667542,14.807311,0.974675,-276.226715,294.500488,0.000000
72.470001,65.100395,-276.182220,-0.000677,0.003847,0.097710,289.581024,14.751961,0.977105,-276.182220,294.500488,0.000000
72.830002,65.362541,-276.226715,-0.000686,0.003869,0.098274,290.747101,14.811363,0.982740,-276.226715,294.500488,0.000000
73.190002,65.437752,-276.271179,-0.000681,0.003876,0.098439,291.081665,14.828406,0.984391,-276.271179,294.500488,0.000000
73.550003,65.268700,-276.315674,-0.000686,0.003876,0.098439,290.329681,14.790098,0.984391,-276.315674,294.500488,0.000000
73.910004,65.254173,-276.360138,-0.000690,0.003878,0.098508,290.265045,14.786807,0.985083,-276.360138,294.500488,0.000000
74.270004,65.329765,-276.360138,-0.000690,0.003883,0.098630,290.601318,14.803937,0.986298,-276.360138,294.500488,0.000000
74.630005,65.297371,-276.360138,-0.000681,0.003883,0.098630,290.457214,14.796596,0.986298,-276.360138,294.500488,0.000000
74.990005,65.194969,-276.449097,-0.000690,0.003884,0.098656,290.001709,14.773392,0.986556,-276.449097,294.500488,0.000000
75.350006,65.359184,-276.404633,-0.000686,0.003887,0.098742,290.732178,14.810603,0.987422,-276.404633,294.500488,0.000000
75.710007,65.302589,-276.449097,-0.000686,0.003887,0.098742,290.480438,14.797779,0.987422,-276.449097,294.500488,0.000000
76.070007,65.214333,-276.493591,-0.000690,0.003889,0.098768,290.087830,14.777779,0.987683,-276.493591,294.500488,0.000000
76.430000,65.208382,-276.493591,-0.000690,0.003890,0.098794,290.061371,14.776431,0.987945,-276.493591,294.500488,0.000000
76.790001,65.211357,-276.538086,-0.000694,0.003890,0.098812,290.074615,14.777104,0.988119,-276.538086,294.500488,0.000000
77.150002,65.273537,-276.582550,-0.000690,0.003895,0.098925,290.351196,14.791195,0.989247,-276.582550,294.500488,0.000000
77.510002,65.515587,-276.582550,-0.000668,0.003895,0.098933,291.427887,14.846044,0.989334,-276.582550,294.500488,0.000000
77.870003,65.483940,-276.627045,-0.000681,0.003895,0.098933,291.287109,14.838873,0.989334,-276.627045,294.500488,0.000000
78.230003,65.393074,-276.627045,-0.000681,0.003895,0.098933,290.882935,14.818282,0.989334,-276.627045,294.500488,0.000000
78.590004,65.341316,-276.716003,-0.000677,0.003895,0.098933,290.652679,14.806554,0.989334,-276.716003,294.500488,0.000000
78.950005,65.286568,-276.716003,-0.000694,0.003896,0.098959,290.409149,14.794147,0.989591,-276.716003,294.500488,0.000000
79.310005,65.235191,-276.760468,-0.000681,0.003896,0.098959,290.180634,14.782506,0.989591,-276.760468,294.500488,0.000000
79.670006,65.199440,-276.804962,-0.000686,0.003896,0.098959,290.021606,14.774405,0.989591,-276.804962,294.500488,0.000000
80.030006,65.200188,-276.716003,-0.000686,0.003897,0.098977,290.024933,14.774573,0.989765,-276.716003,294.500488,0.000000
80.390007,65.150658,-276.804962,-0.000677,0.003897,0.098985,289.804596,14.763350,0.989852,-276.804962,294.500488,0.000000
80.750008,65.597511,-276.849426,-0.000673,0.003901,0.099098,291.792297,14.864609,0.990980,-276.849426,294.500488,0.000000
81.110001,65.573677,-276.849426,-0.000686,0.003901,0.099098,291.686279,14.859208,0.990980,-276.849426,294.500488,0.000000
81.470001,65.520424,-276.938416,-0.000694,0.003901,0.099098,291.449402,14.847140,0.990980,-276.938416,294.500488,0.000000
81.830002,65.488777,-276.938416,-0.000694,0.003901,0.099098,291.308624,14.839969,0.990980,-276.938416,294.500488,0.000000
82.190002,65.388985,-276.982880,-0.000690,0.003901,0.099098,290.864716,14.817355,0.990980,-276.982880,294.500488,0.000000
82.550003,65.336098,-277.027374,-0.000686,0.003901,0.099098,290.629486,14.805371,0.990980,-277.027374,294.500488,0.000000
82.910004,65.302589,-277.071838,-0.000686,0.003901,0.099098,290.480438,14.797779,0.990980,-277.071838,294.500488,0.000000
83.270004,65.267586,-277.027374,-0.000677,0.003901,0.099098,290.324707,14.789846,0.990980,-277.027374,294.500488,0.000000
83.630005,65.228493,-277.071838,-0.000681,0.003901,0.099098,290.150818,14.780988,0.990980,-277.071838,294.500488,0.000000
83.990005,65.178215,-277.071838,-0.000677,0.003901,0.099098,289.927185,14.769595,0.990980,-277.071838,294.500488,0.000000
84.350006,65.108955,-277.160797,-0.000681,0.003901,0.099098,289.619110,14.753900,0.990980,-277.160797,294.500488,0.000000
84.710007,65.062782,-277.160797,-0.000677,0.003901,0.099098,289.413696,14.743437,0.990980,-277.160797,294.500488,0.000000
85.070007,65.025917,-277.205292,-0.000681,0.003901,0.099098,289.249725,14.735084,0.990980,-277.205292,294.500488,0.000000
85.430000,65.001335,-277.205292,-0.000677,0.003901,0.099098,289.140381,14.729513,0.990980,-277.205292,294.500488,0.000000
85.790001,64.967827,-277.249756,-0.000664,0.003901,0.099098,288.991333,14.721920,0.990980,-277.249756,294.500488,0.000000
86.150002,64.938774,-277.249756,-0.000681,0.003902,0.099107,288.862091,14.715337,0.991067,-277.249756,294.500488,0.000000
86.510002,64.900429,-277.294250,-0.000668,0.003902,0.099107,288.691528,14.706648,0.991067,-277.294250,294.500488,0.000000
86.870003,64.847923,-277.338715,-0.000677,0.003902,0.099107,288.457977,14.694750,0.991067,-277.338715,294.500488,0.000000
87.230003,64.804359,-277.338715,-0.000677,0.003902,0.099107,288.264191,14.684877,0.991067,-277.338715,294.500488,0.000000
87.590004,64.779411,-277.427704,-0.000668,0.003902,0.099107,288.153198,14.679225,0.991067,-277.427704,294.500488,0.000000
87.950005,64.754082,-277.383209,-0.000677,0.003902,0.099107,288.040527,14.673485,0.991067,-277.383209,294.500488,0.000000
88.310005,64.711266,-277.472168,-0.000681,0.003902,0.099107,287.850098,14.663782,0.991067,-277.472168,294.500488,0.000000
88.670006,64.690041,-277.472168,-0.000668,0.003902,0.099107,287.755676,14.658973,0.991067,-277.472168,294.500488,0.000000
89.030006,64.676262,-277.427704,-0.000668,0.003902,0.099107,287.694366,14.655850,0.991067,-277.427704,294.500488,0.000000
89.390007,64.633064,-277.561127,-0.000673,0.003902,0.099107,287.502228,14.646062,0.991067,-277.561127,294.500488,0.000000
89.750008,66.675896,-277.561127,-0.000668,0.003852,0.097849,296.589203,15.108974,0.978490,-277.561127,294.500488,0.000000
90.110001,66.587273,-277.516663,-0.000664,0.003833,0.097355,296.194977,15.088892,0.973547,-277.516663,294.500488,0.000000
90.470001,66.573494,-277.650085,-0.000664,0.003833,0.097346,296.133698,15.085770,0.973464,-277.650085,294.500488,0.000000
90.830002,66.488594,-277.516663,-0.000664,0.003833,0.097346,295.756042,15.066530,0.973464,-277.516663,294.500488,0.000000
91.190002,66.408165,-277.694580,-0.000655,0.003833,0.097355,295.398285,15.048306,0.973547,-277.694580,294.500488,0.000000
91.550003,66.420448,-277.650085,-0.000664,0.003833,0.097363,295.452911,15.051089,0.973634,-277.650085,294.500488,0.000000
91.910004,66.392891,-277.694580,-0.000655,0.003833,0.097363,295.330322,15.044844,0.973634,-277.694580,294.500488,0.000000
92.270004,66.360497,-277.783539,-0.000660,0.003833,0.097363,295.186218,15.037503,0.973634,-277.783539,294.500488,0.000000
92.630005,66.320656,-277.739044,-0.000655,0.003833,0.097363,295.009003,15.028476,0.973634,-277.739044,294.500488,0.000000
92.990005,66.300911,-277.828033,-0.000660,0.003833,0.097363,294.921173,15.024001,0.973634,-277.828033,294.500488,0.000000
93.350006,66.264046,-277.828033,-0.000668,0.003833,0.097363,294.757202,15.015647,0.973634,-277.828033,294.500488,0.000000
93.710007,66.243568,-277.783539,-0.000660,0.003833,0.097363,294.666107,15.011007,0.973634,-277.783539,294.500488,0.000000
94.070007,66.194786,-277.872498,-0.000664,0.003833,0.097363,294.449127,14.999953,0.973634,-277.872498,294.500488,0.000000
94.430008,66.165367,-277.872498,-0.000655,0.003833,0.097363,294.318237,14.993286,0.973634,-277.872498,294.500488,0.000000
94.790001,66.150475,-277.872498,-0.000668,0.003833,0.097363,294.252014,14.989912,0.973634,-277.872498,294.500488,0.000000
95.150002,66.117714,-277.961456,-0.000668,0.003833,0.097363,294.106293,14.982488,0.973634,-277.961456,294.500488,0.000000
95.510002,66.085686,-277.961456,-0.000668,0.003833,0.097363,293.963806,14.975231,0.973634,-277.961456,294.500488,0.000000
95.870003,66.059624,-278.005951,-0.000660,0.003833,0.097363,293.847870,14.969324,0.973634,-278.005951,294.500488,0.000000
96.230003,66.030571,-278.050415,-0.000651,0.003833,0.097363,293.718658,14.962741,0.973634,-278.050415,294.500488,0.000000
96.590004,66.008598,-278.139374,-0.000655,0.003833,0.097363,293.620911,14.957763,0.973634,-278.139374,294.500488,0.000000
96.950005,65.990364,-278.139374,-0.000660,0.003833,0.097363,293.539795,14.953630,0.973634,-278.139374,294.500488,0.000000
97.310005,65.938225,-278.094910,-0.000647,0.003834,0.097372,293.307861,14.941815,0.973721,-278.094910,294.500488,0.000000
97.670006,65.935616,-278.183868,-0.000655,0.003834,0.097372,293.296265,14.941224,0.973721,-278.183868,294.500488,0.000000
98.030006,65.932640,-278.139374,-0.000668,0.003834,0.097381,293.283020,14.940550,0.973808,-278.139374,294.500488,0.000000
98.390007,65.841789,-278.139374,-0.000642,0.003834,0.097390,292.878906,14.919962,0.973895,-278.139374,294.500488,0.000000
98.750008,65.845512,-278.228363,-0.000655,0.003837,0.097459,292.895477,14.920807,0.974588,-278.228363,294.500488,0.000000
99.110008,65.857430,-278.228363,-0.000655,0.003844,0.097650,292.948486,14.923507,0.976495,-278.228363,294.500488,0.000000
99.470001,65.846245,-278.317322,-0.000655,0.003844,0.097650,292.898712,14.920972,0.976495,-278.317322,294.500488,0.000000
99.830002,65.809761,-278.272827,-0.000673,0.003845,0.097658,292.736450,14.912705,0.976582,-278.272827,294.500488,0.000000
100.190002,65.783699,-278.317322,-0.000647,0.003854,0.097893,292.620514,14.906799,0.978925,-278.317322,294.500488,0.000000
100.550003,65.763588,-278.361786,-0.000655,0.003857,0.097970,292.531036,14.902242,0.979705,-278.361786,294.500488,0.000000
100.910004,65.761726,-278.317322,-0.000651,0.003876,0.098439,292.522766,14.901820,0.984391,-278.317322,294.500488,0.000000
101.270004,65.671608,-278.361786,-0.000651,0.003879,0.098526,292.121887,14.881399,0.985257,-278.361786,294.500488,0.000000
101.630005,65.666389,-278.406281,-0.000664,0.003882,0.098595,292.098694,14.880217,0.985950,-278.406281,294.500488,0.000000
101.990005,65.653740,-278.450745,-0.000651,0.003882,0.098595,292.042419,14.877350,0.985950,-278.450745,294.500488,0.000000
102.350006,65.620598,-278.495239,-0.000668,0.003883,0.098621,291.894989,14.869841,0.986211,-278.495239,294.500488,0.000000
102.710007,65.606438,-278.495239,-0.000651,0.003884,0.098647,291.832001,14.866632,0.986469,-278.495239,294.500488,0.000000
103.070007,65.590431,-278.584198,-0.000647,0.003884,0.098656,291.760803,14.863005,0.986556,-278.584198,294.500488,0.000000
103.430008,65.583351,-278.539703,-0.000668,0.003887,0.098734,291.729309,14.861400,0.987339,-278.539703,294.500488,0.000000
103.790009,65.566978,-278.584198,-0.000647,0.003887,0.098742,291.656494,14.857690,0.987422,-278.584198,294.500488,0.000000
104.150002,65.538292,-278.628693,-0.000677,0.003889,0.098768,291.528870,14.851189,0.987683,-278.628693,294.500488,0.000000
104.510002,65.537560,-278.584198,-0.000647,0.003889,0.098768,291.525635,14.851024,0.987683,-278.584198,294.500488,0.000000
104.870003,65.521172,-278.673157,-0.000651,0.003889,0.098777,291.452728,14.847310,0.987771,-278.673157,294.500488,0.000000
105.230003,65.518562,-278.673157,-0.000660,0.003890,0.098803,291.441132,14.846719,0.988032,-278.673157,294.500488,0.000000
105.590004,65.491386,-278.717651,-0.000655,0.003890,0.098803,291.320251,14.840561,0.988032,-278.717651,294.500488,0.000000
105.950005,65.485420,-278.806610,-0.000664,0.003891,0.098821,291.293701,14.839208,0.988206,-278.806610,294.500488,0.000000
106.310005,65.495110,-278.673157,-0.000664,0.003894,0.098907,291.336792,14.841404,0.989073,-278.673157,294.500488,0.000000
106.670006,65.484673,-278.717651,-0.000651,0.003896,0.098959,291.290375,14.839039,0.989591,-278.717651,294.500488,0.000000
107.030006,65.454140,-278.806610,-0.000660,0.003896,0.098959,291.154541,14.832120,0.989591,-278.806610,294.500488,0.000000
107.390007,65.410210,-278.895569,-0.000651,0.003896,0.098959,290.959137,14.822165,0.989591,-278.895569,294.500488,0.000000
107.750008,65.402016,-278.895569,-0.000668,0.003897,0.098977,290.922699,14.820309,0.989765,-278.895569,294.500488,0.000000
108.110008,65.384880,-278.895569,-0.000638,0.003897,0.098977,290.846466,14.816426,0.989765,-278.895569,294.500488,0.000000
108.470009,65.361046,-278.984528,-0.000647,0.003898,0.099011,290.740448,14.811025,0.990113,-278.984528,294.500488,0.000000
108.830002,65.405357,-278.940033,-0.000668,0.003905,0.099176,290.937561,14.821066,0.991760,-278.940033,294.500488,0.000000
109.190002,65.400520,-279.028992,-0.000651,0.003905,0.099176,290.916046,14.819970,0.991760,-279.028992,294.500488,0.000000
109.550003,65.385628,-279.073486,-0.000664,0.003905,0.099176,290.849792,14.816595,0.991760,-279.073486,294.500488,0.000000
109.910004,65.377068,-279.028992,-0.000647,0.003905,0.099176,290.811707,14.814655,0.991760,-279.028992,294.500488,0.000000
110.270004,65.358070,-279.117981,-0.000647,0.003906,0.099202,290.727203,14.810350,0.992021,-279.117981,294.500488,0.000000
110.630005,65.324928,-279.028992,-0.000660,0.003906,0.099202,290.579803,14.802840,0.992021,-279.028992,294.500488,0.000000
110.990005,65.324928,-279.117981,-0.000647,0.003906,0.099202,290.579803,14.802840,0.992021,-279.117981,294.500488,0.000000
111.350006,65.302589,-279.117981,-0.000668,0.003906,0.099202,290.480438,14.797779,0.992021,-279.117981,294.500488,0.000000
111.710007,65.345406,-279.117981,-0.000651,0.003911,0.099349,290.670868,14.807481,0.993493,-279.117981,294.500488,0.000000
112.070007,65.348763,-279.206940,-0.000655,0.003911,0.099349,290.685822,14.808242,0.993493,-279.206940,294.500488,0.000000
112.430008,65.332756,-279.206940,-0.000651,0.003911,0.099349,290.614624,14.804614,0.993493,-279.206940,294.500488,0.000000
112.790009,65.338341,-279.206940,-0.000655,0.003911,0.099349,290.639465,14.805880,0.993493,-279.206940,294.500488,0.000000
113.150009,65.323814,-279.295898,-0.000642,0.003911,0.099349,290.574829,14.802588,0.993493,-279.295898,294.500488,0.000000
113.510002,65.317848,-279.340363,-0.000642,0.003911,0.099349,290.548309,14.801236,0.993493,-279.340363,294.500488,0.000000
113.870003,65.308922,-279.340363,-0.000642,0.003911,0.099349,290.508606,14.799213,0.993493,-279.340363,294.500488,0.000000
114.230003,65.283592,-279.384857,-0.000655,0.003911,0.099349,290.395935,14.793474,0.993493,-279.384857,294.500488,0.000000
114.590004,65.280617,-279.429321,-0.000655,0.003911,0.099349,290.382690,14.792799,0.993493,-279.429321,294.500488,0.000000
114.950005,65.257530,-279.429321,-0.000660,0.003911,0.099349,290.279999,14.787567,0.993493,-279.429321,294.500488,0.000000
115.310005,65.516335,-279.340363,-0.000655,0.003919,0.099540,291.431213,14.846213,0.995401,-279.340363,294.500488,0.000000
115.670006,65.551338,-279.518311,-0.000655,0.003919,0.099540,291.586914,14.854146,0.995401,-279.518311,294.500488,0.000000
116.030006,65.580376,-279.518311,-0.000655,0.003919,0.099540,291.716095,14.860725,0.995401,-279.518311,294.500488,0.000000
116.390007,65.547981,-279.473816,-0.000642,0.003919,0.099540,291.571991,14.853385,0.995401,-279.473816,294.500488,0.000000
116.750008,65.556923,-279.518311,-0.000655,0.003919,0.099540,291.611755,14.855412,0.995401,-279.518311,294.500488,0.000000
117.110008,65.546486,-279.562775,-0.000673,0.003919,0.099540,291.565338,14.853046,0.995401,-279.562775,294.500488,0.000000
117.470009,65.556175,-279.651733,-0.000655,0.003919,0.099540,291.608429,14.855242,0.995401,-279.651733,294.500488,0.000000
117.830002,65.541649,-279.607269,-0.000651,0.003919,0.099540,291.543823,14.851950,0.995401,-279.607269,294.500488,0.000000
118.190002,65.538673,-279.651733,-0.000647,0.003919,0.099540,291.530579,14.851276,0.995401,-279.651733,294.500488,0.000000
118.550003,65.520058,-279.696228,-0.000660,0.003919,0.099540,291.447784,14.847057,0.995401,-279.696228,294.500488,0.000000
118.910004,65.526390,-279.696228,-0.000660,0.003919,0.099540,291.475952,14.848493,0.995401,-279.696228,294.500488,0.000000
119.270004,65.492500,-279.785187,-0.000647,0.003919,0.099540,291.325195,14.840813,0.995401,-279.785187,294.500488,0.000000
119.630005,65.502174,-279.740692,-0.000660,0.003919,0.099540,291.368225,14.843005,0.995401,-279.740692,294.500488,0.000000
119.990005,65.498085,-279.785187,-0.000651,0.003919,0.099540,291.350037,14.842078,0.995401,-279.785187,294.500488,0.000000
120.350006,65.493980,-279.829651,-0.000660,0.003919,0.099540,291.331787,14.841148,0.995401,-279.829651,294.500488,0.000000
120.710007,65.484306,-279.785187,-0.000651,0.003919,0.099540,291.288757,14.838956,0.995401,-279.785187,294.500488,0.000000
121.070007,65.453392,-279.874146,-0.000660,0.003919,0.099540,291.151215,14.831951,0.995401,-279.874146,294.500488,0.000000
121.430008,65.454887,-279.874146,-0.000660,0.003919,0.099540,291.157867,14.832290,0.995401,-279.874146,294.500488,0.000000
121.790009,65.439995,-279.918640,-0.000642,0.003919,0.099540,291.091644,14.828915,0.995401,-279.918640,294.500488,0.000000
122.150009,65.455254,-279.918640,-0.000664,0.003919,0.099540,291.159515,14.832372,0.995401,-279.918640,294.500488,0.000000
122.510002,65.426216,-279.963104,-0.000651,0.003919,0.099540,291.030334,14.825793,0.995401,-279.963104,294.500488,0.000000
122.870003,65.429939,-280.007599,-0.000655,0.003920,0.099557,291.046906,14.826636,0.995575,-280.007599,294.500488,0.000000
123.230003,65.420250,-280.052063,-0.000660,0.003920,0.099557,291.003815,14.824440,0.995575,-280.052063,294.500488,0.000000
123.590004,65.419884,-280.052063,-0.000647,0.003920,0.099557,291.002167,14.824358,0.995575,-280.052063,294.500488,0.000000
123.950005,65.429192,-280.052063,-0.000655,0.003920,0.099557,291.043579,14.826467,0.995575,-280.052063,294.500488,0.000000
124.310005,65.395683,-280.096558,-0.000642,0.003920,0.099566,290.894531,14.818873,0.995662,-280.096558,294.500488,0.000000
124.670006,65.390846,-280.096558,-0.000655,0.003920,0.099566,290.873016,14.817778,0.995662,-280.096558,294.500488,0.000000
125.030006,65.395302,-280.141022,-0.000664,0.003920,0.099566,290.892822,14.818788,0.995662,-280.141022,294.500488,0.000000
125.390007,65.378181,-280.229980,-0.000651,0.003920,0.099566,290.816681,14.814908,0.995662,-280.229980,294.500488,0.000000
125.750008,65.381157,-280.141022,-0.000651,0.003920,0.099566,290.829926,14.815581,0.995662,-280.141022,294.500488,0.000000
126.110008,65.356575,-280.274475,-0.000651,0.003920,0.099566,290.720551,14.810012,0.995662,-280.274475,294.500488,0.000000
126.470009,65.356209,-280.318939,-0.000660,0.003920,0.099566,290.718933,14.809928,0.995662,-280.318939,294.500488,0.000000
126.830009,65.352486,-280.274475,-0.000664,0.003920,0.099566,290.702362,14.809085,0.995662,-280.274475,294.500488,0.000000
127.190002,65.331627,-280.318939,-0.000642,0.003920,0.099566,290.609589,14.804358,0.995662,-280.318939,294.500488,0.000000
127.550003,65.315987,-280.363434,-0.000647,0.003920,0.099566,290.540009,14.800814,0.995662,-280.363434,294.500488,0.000000
127.910004,65.337212,-280.363434,-0.000647,0.003920,0.099566,290.634430,14.805623,0.995662,-280.363434,294.500488,0.000000
128.270004,65.319710,-280.452393,-0.000647,0.003920,0.099566,290.556580,14.801658,0.995662,-280.452393,294.500488,0.000000
128.630005,65.302208,-280.452393,-0.000647,0.003920,0.099566,290.478729,14.797691,0.995662,-280.452393,294.500488,0.000000
128.990005,65.310402,-280.452393,-0.000660,0.003920,0.099566,290.515167,14.799548,0.995662,-280.452393,294.500488,0.000000
129.350006,65.300346,-280.541351,-0.000655,0.003920,0.099566,290.470459,14.797271,0.995662,-280.541351,294.500488,0.000000
129.710007,65.288811,-280.541351,-0.000647,0.003920,0.099566,290.419128,14.794656,0.995662,-280.541351,294.500488,0.000000
130.070007,65.429939,-280.630310,-0.000651,0.003924,0.099662,291.046906,14.826636,0.996616,-280.630310,294.500488,0.000000
130.430008,65.480583,-280.585846,-0.000660,0.003924,0.099662,291.272186,14.838112,0.996616,-280.585846,294.500488,0.000000
130.790009,65.498451,-280.585846,-0.000651,0.003924,0.099662,291.351654,14.842161,0.996616,-280.585846,1681.640991,0.000000
131.150009,65.418388,-280.674805,-0.000655,0.003913,0.099384,290.995514,14.824019,0.993842,-280.674805,0.099185,0.000000
131.510010,65.364403,-280.630310,-0.000647,0.003896,0.098959,290.755371,14.811786,0.989591,-280.630310,0.098586,0.000000
131.870010,65.269081,-280.719269,-0.000660,0.003879,0.098517,290.331360,14.790185,0.985170,-280.719269,0.097979,0.000000
132.230011,65.310036,-280.719269,-0.000655,0.003849,0.097771,290.513550,14.799465,0.977710,-280.719269,0.097381,0.000000
132.590012,65.277641,-280.719269,-0.000642,0.003827,0.097207,290.369446,14.792125,0.972075,-280.719269,0.096782,0.000000
132.950012,65.244865,-280.763763,-0.000660,0.003804,0.096626,290.223663,14.784698,0.966265,-280.763763,0.096184,0.000000
133.310013,65.200935,-280.808258,-0.000655,0.003783,0.096080,290.028259,14.774743,0.960799,-280.808258,0.095586,0.000000
133.670013,65.197212,-280.852722,-0.000638,0.003763,0.095577,290.011688,14.773900,0.955769,-280.852722,0.094979,0.000000
134.029999,65.167793,-280.808258,-0.000660,0.003734,0.094831,289.880829,14.767234,0.948313,-280.808258,0.094380,0.000000
134.389999,65.108208,-280.808258,-0.000634,0.003717,0.094406,289.615784,14.753730,0.944063,-280.808258,0.093782,0.000000
134.750000,64.666954,-280.852722,-0.000651,0.003693,0.093799,287.652985,14.653742,0.937992,-280.852722,0.093183,0.000000
135.110001,63.760216,-280.897217,-0.000625,0.003667,0.093149,283.619598,14.448272,0.931489,-280.897217,0.092585,0.000000
135.470001,62.754066,-280.986176,-0.000625,0.003646,0.092611,279.144043,14.220275,0.926111,-280.986176,0.091978,0.000000
135.830002,61.753136,-280.941681,-0.000621,0.003628,0.092143,274.691681,13.993461,0.921429,-280.941681,0.091380,0.000000
136.190002,60.475899,-281.030640,-0.000621,0.003605,0.091579,269.010223,13.704034,0.915793,-281.030640,0.090781,0.000000
136.550003,58.768944,-281.119598,-0.000625,0.003582,0.090981,261.417328,13.317233,0.909809,-281.119598,0.090183,0.000000
136.910004,56.822548,-281.075134,-0.000612,0.003554,0.090278,252.759323,12.876173,0.902785,-281.075134,0.089585,0.000000
137.270004,55.327477,-281.119598,-0.000621,0.003535,0.089801,246.108902,12.537386,0.898012,-281.119598,0.088978,0.000000
137.630005,53.169205,-281.119598,-0.000617,0.003513,0.089238,236.508438,12.048314,0.892376,-281.119598,0.088379,0.000000
137.990005,51.082802,-281.208588,-0.000629,0.003492,0.088708,227.227646,11.575529,0.887085,-281.208588,0.087781,0.000000
138.350006,48.911865,-281.164093,-0.000617,0.003472,0.088180,217.570847,11.083587,0.881797,-281.164093,0.087182,0.000000
138.710007,46.339149,-281.164093,-0.000617,0.003448,0.087573,206.126831,10.500601,0.875726,-281.164093,0.086584,0.000000
139.070007,42.995239,-281.253052,-0.000621,0.003417,0.086783,191.252380,9.742861,0.867835,-281.253052,0.085986,0.000000
139.430008,40.814629,-281.253052,-0.000629,0.003398,0.086315,181.552536,9.248727,0.863149,-281.253052,0.085379,0.000000
139.790009,38.153656,-281.253052,-0.000625,0.003374,0.085691,169.715942,8.645741,0.856908,-281.253052,0.084780,0.000000
140.150009,35.465126,-281.342010,-0.000621,0.003348,0.085049,157.756760,8.036512,0.850489,-281.342010,0.084182,0.000000
140.510010,33.215996,-281.342010,-0.000629,0.003328,0.084537,147.752121,7.526852,0.845371,-281.342010,0.083583,0.000000
140.870010,31.574203,-281.386505,-0.000621,0.003314,0.084182,140.449066,7.154817,0.841817,-281.386505,0.082985,0.000000
141.230011,27.880272,-281.386505,-0.000629,0.003281,0.083349,124.017647,6.317760,0.833491,-281.386505,0.082378,0.000000
141.590012,25.392082,-281.430969,-0.000621,0.003260,0.082794,112.949623,5.753928,0.827942,-281.430969,0.081779,0.000000
141.950012,23.661293,-281.475464,-0.000612,0.003246,0.082447,105.250687,5.361726,0.824471,-281.475464,0.081181,0.000000
142.310013,20.132317,-281.430969,-0.000617,0.003211,0.081563,89.553017,4.562048,0.815626,-281.430969,0.080583,0.000000
142.670013,17.741318,-281.519928,-0.000621,0.003192,0.081077,78.917320,4.020240,0.810770,-281.519928,0.079984,0.000000
143.030014,14.470398,-281.475464,-0.000629,0.003161,0.080288,64.367546,3.279039,0.802878,-281.475464,0.079377,0.000000
143.389999,11.898415,-281.519928,-0.000608,0.003138,0.079698,52.926792,2.696219,0.796982,-281.519928,0.078779,0.000000
143.750000,9.995964,-281.519928,-0.000621,0.003123,0.079325,44.464268,2.265118,0.793253,-281.519928,0.078180,0.000000
144.110001,6.892990,-281.519928,-0.000629,0.003092,0.078545,30.661551,1.561974,0.785449,-281.519928,0.077582,0.000000
144.470001,4.269249,-281.653381,-0.000608,0.003068,0.077938,18.990568,0.967426,0.779378,-281.653381,0.076984,0.000000
144.830002,2.121033,-281.653381,-0.000617,0.003047,0.077400,9.434825,0.480633,0.774000,-281.653381,0.076377,0.000000
145.190002,-0.053619,-281.653381,-0.000608,0.003024,0.076810,-0.238511,-0.012150,0.768103,-281.653381,0.075778,0.000000
145.550003,-0.522064,-281.697876,-0.000629,0.003000,0.076194,-2.322258,-0.118301,0.761945,-281.697876,0.075180,0.000000
145.910004,-0.064789,-281.742340,-0.000634,0.002979,0.075666,-0.288195,-0.014681,0.756657,-281.742340,0.074581,0.000000
146.270004,-0.044685,-281.786835,-0.000642,0.002951,0.074963,-0.198770,-0.010126,0.749633,-281.786835,0.073983,0.000000
146.630005,-0.030159,-281.786835,-0.000660,0.002934,0.074521,-0.134154,-0.006834,0.745208,-281.786835,0.073385,0.000000
146.990005,-0.031281,-281.742340,-0.000703,0.002906,0.073818,-0.139143,-0.007088,0.738183,-281.742340,0.072778,0.000000
147.350006,-0.010422,-281.786835,-0.000742,0.002879,0.073133,-0.046358,-0.002362,0.731333,-281.786835,0.072179,0.000000
147.710007,-0.012291,-281.831299,-0.000767,0.002862,0.072691,-0.054673,-0.002785,0.726908,-281.831299,0.071581,0.000000
148.070007,-0.030533,-281.920258,-0.000789,0.002837,0.072058,-0.135817,-0.006919,0.720580,-281.920258,0.070983,0.000000
148.430008,-0.030533,-281.964752,-0.000823,0.002810,0.071373,-0.135817,-0.006919,0.713729,-281.964752,0.070384,0.000000
148.790009,-0.013405,-281.964752,-0.000849,0.002781,0.070644,-0.059628,-0.003038,0.706443,-281.964752,0.069777,0.000000
149.150009,-0.013031,-281.964752,-0.000875,0.002756,0.070002,-0.057965,-0.002953,0.700024,-281.964752,0.069179,0.000000
149.510010,-0.021599,-281.964752,-0.000888,0.002742,0.069647,-0.096076,-0.004894,0.696470,-281.964752,0.068580,0.000000
149.870010,-0.013405,-282.098206,-0.000931,0.002715,0.068953,-0.059628,-0.003038,0.689532,-282.098206,0.067982,0.000000
150.100006,0.026810,-282.053711,-0.000923,0.002715,0.068962,0.119255,0.006075,0.689619,-282.053711,0.068823,0.000000