File: Data/compression 24/AutoHeating-12-24-reverse-1-1_09202024_164919.csv
Time (sec),S:Load (lbs),S:HL1 (DIM),S:LVDT (in),S:Position (in),Ch:Position (mm),Ch:Load (N),Ch:Stress (MPa),Ch:Strain (mm/mm),Ch:HL1 (DIM),Set Point (),Cycles ()
0.110000,-0.029785,-200.875977,-0.006191,-0.006197,-0.157393,-0.132491,-0.006749,-1.573930,-200.875977,-0.157098,0.000000
0.490000,-0.014893,-200.964935,-0.006178,-0.006153,-0.156292,-0.066245,-0.003375,-1.562916,-200.964935,-0.155485,0.000000
0.870000,-0.033142,-200.920456,-0.006092,-0.005918,-0.150325,-0.147423,-0.007510,-1.503250,-200.920456,-0.149154,0.000000
1.250000,0.037239,-200.964935,-0.005851,-0.005676,-0.144159,0.165648,0.008438,-1.441591,-200.964935,-0.142823,0.000000
1.630000,0.051758,-201.009415,-0.005588,-0.005426,-0.137828,0.230230,0.011728,-1.378281,-201.009415,-0.136493,0.000000
2.010000,0.057716,-201.098373,-0.005351,-0.005177,-0.131489,0.256735,0.013079,-1.314888,-201.098373,-0.130162,0.000000
2.390000,0.036865,-201.098373,-0.005088,-0.004930,-0.125210,0.163985,0.008354,-1.252100,-201.098373,-0.123831,0.000000
2.770000,0.046547,-201.142868,-0.004825,-0.004672,-0.118680,0.207051,0.010548,-1.186799,-201.142868,-0.117501,0.000000
3.150000,0.161240,-201.142868,-0.004665,-0.000001,-0.000035,0.717230,0.036537,-0.000348,-201.142868,0.000130,0.000000
3.530000,0.091232,-201.231827,-0.004674,-0.000002,-0.000044,0.405822,0.020674,-0.000435,-201.231827,0.000208,0.000000
3.910000,0.137779,-201.276306,-0.004682,-0.000002,-0.000044,0.612873,0.031221,-0.000435,-201.276306,0.000841,0.000000
4.290000,0.090858,-201.276306,-0.004682,0.000010,0.000251,0.404159,0.020589,0.002513,-201.276306,0.001474,0.000000
4.670000,0.152672,-201.365265,-0.004635,0.000041,0.001049,0.679118,0.034596,0.010492,-201.365265,0.002107,0.000000
5.050000,0.233475,-201.409744,-0.004618,0.000065,0.001656,1.038548,0.052906,0.016563,-201.409744,0.002740,0.000000
5.430000,0.364555,-201.498703,-0.004600,0.000087,0.002220,1.621623,0.082609,0.022198,-201.498703,0.003373,0.000000
5.810000,0.469566,-201.498703,-0.004566,0.000123,0.003130,2.088735,0.106405,0.031305,-201.498703,0.004007,0.000000
6.190000,0.552231,-201.543182,-0.004540,0.000147,0.003746,2.456445,0.125137,0.037463,-201.543182,0.004640,0.000000
6.570000,0.621490,-201.543182,-0.004510,0.000165,0.004189,2.764528,0.140832,0.041887,-201.543182,0.005273,0.000000
6.950000,0.802094,-201.632156,-0.004488,0.000188,0.004787,3.567890,0.181757,0.047871,-201.632156,0.005906,0.000000
7.330000,0.966309,-201.676636,-0.004480,0.000213,0.005411,4.298355,0.218969,0.054113,-201.676636,0.006539,0.000000
7.710001,1.134995,-201.676636,-0.004454,0.000244,0.006200,5.048707,0.257193,0.062004,-201.676636,0.007172,0.000000
8.090000,1.175583,-201.632156,-0.004419,0.000262,0.006660,5.229254,0.266391,0.066603,-201.632156,0.007805,0.000000
8.470000,1.402359,-201.721115,-0.004393,0.000294,0.007476,6.238004,0.317779,0.074755,-201.721115,0.008438,0.000000
8.850000,1.560616,-201.810074,-0.004368,0.000322,0.008178,6.941965,0.353641,0.081780,-201.810074,0.009071,0.000000
9.230000,1.633224,-201.854553,-0.004355,0.000337,0.008560,7.264946,0.370094,0.085595,-201.854553,0.009704,0.000000
9.610001,1.875641,-201.899033,-0.004329,0.000371,0.009418,8.343267,0.425026,0.094180,-201.899033,0.010337,0.000000
9.990001,1.912880,-201.854553,-0.004299,0.000385,0.009774,8.508915,0.433465,0.097737,-201.854553,0.010971,0.000000
10.370001,2.030174,-201.899033,-0.004281,0.000409,0.010398,9.030666,0.460044,0.103979,-201.899033,0.011612,0.000000
10.750001,2.205193,-202.032486,-0.004260,0.000442,0.011231,9.809186,0.499704,0.112305,-202.032486,0.012245,0.000000
11.130000,2.297539,-201.987991,-0.004221,0.000460,0.011690,10.219963,0.520630,0.116900,-201.987991,0.012878,0.000000
11.510000,2.492661,-202.076965,-0.004186,0.000495,0.012583,11.087908,0.564845,0.125833,-202.076965,0.013511,0.000000
11.890000,2.480743,-202.121445,-0.004174,0.000509,0.012930,11.034898,0.562144,0.129303,-202.121445,0.014145,0.000000
12.270000,2.636398,-202.121445,-0.004126,0.000542,0.013771,11.727285,0.597416,0.137713,-202.121445,0.014777,0.000000
12.650001,2.780136,-202.254883,-0.004122,0.000571,0.014509,12.366663,0.629988,0.145086,-202.254883,0.015411,0.000000
13.030001,2.782738,-202.299362,-0.004100,0.000587,0.014916,12.378236,0.630577,0.149163,-202.299362,0.016044,0.000000
13.410001,2.898178,-202.254883,-0.004083,0.000614,0.015601,12.891740,0.656737,0.156013,-202.254883,0.016677,0.000000
13.790001,2.968925,-202.254883,-0.004040,0.000638,0.016200,13.206440,0.672768,0.161997,-202.254883,0.017310,0.000000
14.170001,3.028503,-202.343842,-0.004023,0.000662,0.016816,13.471456,0.686269,0.168155,-202.343842,0.017943,0.000000
14.550001,3.121223,-202.477295,-0.003992,0.000687,0.017440,13.883895,0.707279,0.174397,-202.477295,0.018576,0.000000
14.930000,3.202034,-202.477295,-0.003971,0.000714,0.018125,14.243359,0.725591,0.181251,-202.477295,0.019209,0.000000
15.310000,3.132767,-202.477295,-0.003945,0.000731,0.018558,13.935243,0.709895,0.185585,-202.477295,0.019842,0.000000
15.690001,3.337204,-202.477295,-0.003902,0.000763,0.019382,14.844625,0.756221,0.193824,-202.477295,0.020475,0.000000
16.070002,3.361038,-202.566254,-0.003880,0.000785,0.019946,14.950644,0.761622,0.199460,-202.566254,0.021108,0.000000
16.450001,3.311134,-202.655212,-0.003867,0.000799,0.020302,14.728662,0.750314,0.203018,-202.655212,0.021741,0.000000
16.830000,3.556534,-202.699692,-0.003833,0.000839,0.021316,15.820252,0.805922,0.213161,-202.699692,0.022374,0.000000
17.210001,3.522270,-202.655212,-0.003811,0.000857,0.021759,15.667840,0.798158,0.217586,-202.655212,0.023007,0.000000
17.590000,3.636963,-202.744171,-0.003781,0.000891,0.022634,16.178019,0.824148,0.226344,-202.744171,0.023640,0.000000
17.970001,3.571800,-202.833130,-0.003755,0.000907,0.023042,15.888161,0.809381,0.230421,-202.833130,0.024274,0.000000
18.350000,3.558762,-202.833130,-0.003747,0.000925,0.023485,15.830162,0.806427,0.234845,-202.833130,0.024907,0.000000
18.730001,3.760590,-202.833130,-0.003704,0.000957,0.024308,16.727938,0.852162,0.243081,-202.833130,0.025540,0.000000
19.110001,3.860756,-202.877625,-0.003678,0.000984,0.024994,17.173500,0.874860,0.249936,-202.877625,0.026173,0.000000
19.490002,3.990715,-202.877625,-0.003656,0.001014,0.025757,17.751587,0.904309,0.257566,-202.877625,0.026806,0.000000
19.870001,3.879379,-202.966583,-0.003635,0.001028,0.026121,17.256340,0.879080,0.261207,-202.966583,0.027439,0.000000
20.250002,3.987366,-203.055542,-0.003622,0.001060,0.026927,17.736689,0.903550,0.269273,-203.055542,0.028072,0.000000
20.630001,4.097961,-203.055542,-0.003583,0.001083,0.027517,18.228643,0.928611,0.275169,-203.055542,0.028705,0.000000
21.010000,4.232018,-203.011063,-0.003548,0.001109,0.028168,18.824955,0.958989,0.281676,-203.011063,0.029338,0.000000
21.390001,4.267014,-203.100021,-0.003518,0.001141,0.028991,18.980625,0.966919,0.289912,-203.100021,0.029980,0.000000
21.770000,4.289360,-203.188980,-0.003484,0.001167,0.029642,19.080027,0.971983,0.296418,-203.188980,0.030613,0.000000
22.150002,4.429741,-203.233459,-0.003471,0.001195,0.030344,19.704472,1.003794,0.303443,-203.233459,0.031246,0.000000
22.530001,4.253983,-203.188980,-0.003458,0.001203,0.030544,18.922659,0.963966,0.305437,-203.188980,0.031879,0.000000
22.910002,4.574600,-203.277939,-0.003419,0.001242,0.031541,20.348839,1.036619,0.315410,-203.277939,0.032512,0.000000
23.290001,4.662849,-203.322433,-0.003389,0.001268,0.032217,20.741390,1.056617,0.322174,-203.322433,0.033145,0.000000
23.670002,4.678864,-203.411392,-0.003376,0.001293,0.032851,20.812624,1.060246,0.328506,-203.411392,0.033778,0.000000
24.050001,4.758179,-203.366913,-0.003346,0.001317,0.033440,21.165436,1.078219,0.334403,-203.366913,0.034412,0.000000
24.430000,4.822227,-203.411392,-0.003307,0.001340,0.034030,21.450338,1.092732,0.340300,-203.411392,0.035044,0.000000
24.810001,4.888878,-203.455872,-0.003303,0.001361,0.034559,21.746815,1.107836,0.345587,-203.455872,0.035678,0.000000
25.190001,5.132782,-203.500351,-0.003255,0.001393,0.035374,22.831755,1.163105,0.353740,-203.500351,0.036311,0.000000
25.570002,5.129807,-203.589310,-0.003234,0.001417,0.035981,22.818520,1.162431,0.359811,-203.589310,0.036944,0.000000
25.950001,5.051231,-203.589310,-0.003225,0.001436,0.036484,22.469000,1.144625,0.364841,-203.589310,0.037577,0.000000
26.330002,5.206512,-203.678268,-0.003195,0.001459,0.037056,23.159723,1.179813,0.370564,-203.678268,0.038210,0.000000
26.710001,5.352852,-203.678268,-0.003169,0.001486,0.037733,23.810675,1.212974,0.377328,-203.678268,0.038843,0.000000
27.090002,5.670860,-203.767242,-0.003126,0.001521,0.038626,25.225246,1.285035,0.386260,-203.767242,0.039476,0.000000
27.470001,5.588196,-203.767242,-0.003109,0.001545,0.039242,24.857536,1.266303,0.392418,-203.767242,0.040109,0.000000
27.850000,5.546120,-203.767242,-0.003104,0.001565,0.039745,24.670372,1.256769,0.397448,-203.767242,0.040742,0.000000
28.230001,5.705864,-203.811722,-0.003057,0.001588,0.040334,25.380951,1.292967,0.403345,-203.811722,0.041375,0.000000
28.610001,5.819069,-203.811722,-0.003044,0.001612,0.040933,25.884512,1.318620,0.409329,-203.811722,0.042008,0.000000
28.990002,6.083076,-203.945160,-0.003009,0.001642,0.041696,27.058876,1.378445,0.416963,-203.945160,0.042641,0.000000
29.370001,5.927055,-203.945160,-0.002992,0.001656,0.042052,26.364859,1.343090,0.420517,-203.945160,0.043275,0.000000
29.750002,6.280060,-203.945160,-0.002962,0.001692,0.042988,27.935101,1.423082,0.429885,-203.945160,0.043907,0.000000
30.130001,6.381721,-203.989639,-0.002945,0.001720,0.043691,28.387316,1.446119,0.436909,-203.989639,0.044541,0.000000
30.510002,6.279694,-204.078598,-0.002915,0.001735,0.044064,27.933472,1.422999,0.440637,-204.078598,0.045174,0.000000
30.890001,6.674034,-204.123077,-0.002871,0.001768,0.044896,29.687586,1.512358,0.448960,-204.123077,0.045807,0.000000
31.270002,6.541840,-204.167572,-0.002867,0.001783,0.045295,29.099556,1.482402,0.452950,-204.167572,0.046440,0.000000
31.650002,6.539230,-204.167572,-0.002841,0.001806,0.045868,29.087950,1.481811,0.458676,-204.167572,0.047073,0.000000
32.030003,6.970070,-204.167572,-0.002815,0.001840,0.046735,31.004419,1.579440,0.467347,-204.167572,0.047706,0.000000
32.410000,6.927994,-204.301010,-0.002785,0.001859,0.047220,30.817255,1.569906,0.472203,-204.301010,0.048348,0.000000
32.790001,7.262383,-204.345490,-0.002742,0.001889,0.047992,32.304691,1.645679,0.479921,-204.345490,0.048981,0.000000
33.170002,7.103752,-204.345490,-0.002733,0.001907,0.048443,31.599068,1.609733,0.484432,-204.345490,0.049614,0.000000
33.550003,7.459366,-204.345490,-0.002708,0.001938,0.049232,33.180916,1.690316,0.492324,-204.345490,0.050247,0.000000
33.930000,7.673111,-204.345490,-0.002690,0.001965,0.049900,34.131702,1.738752,0.499001,-204.345490,0.050880,0.000000
34.310001,7.644066,-204.523407,-0.002660,0.001985,0.050429,34.002502,1.732170,0.504292,-204.523407,0.051513,0.000000
34.690002,7.730080,-204.523407,-0.002630,0.002009,0.051019,34.385113,1.751661,0.510189,-204.523407,0.052146,0.000000
35.070004,7.919617,-204.523407,-0.002608,0.002032,0.051617,35.228214,1.794611,0.516173,-204.523407,0.052779,0.000000
35.450001,8.132240,-204.523407,-0.002591,0.002060,0.052328,36.174011,1.842792,0.523284,-204.523407,0.053412,0.000000
35.830002,8.377640,-204.612381,-0.002561,0.002085,0.052970,37.265602,1.898400,0.529700,-204.612381,0.054045,0.000000
36.210003,8.522865,-204.612381,-0.002544,0.002111,0.053621,37.911598,1.931309,0.536206,-204.612381,0.054678,0.000000
36.590000,8.488228,-204.701340,-0.002518,0.002133,0.054175,37.757523,1.923460,0.541755,-204.701340,0.055312,0.000000
36.970001,8.910126,-204.656860,-0.002483,0.002162,0.054904,39.634220,2.019063,0.549041,-204.656860,0.055945,0.000000
37.350002,8.979759,-204.701340,-0.002466,0.002184,0.055468,39.943962,2.034842,0.554676,-204.701340,0.056578,0.000000
37.730003,8.823364,-204.790298,-0.002440,0.002198,0.055823,39.248283,1.999403,0.558234,-204.790298,0.057211,0.000000
38.110001,9.494011,-204.879257,-0.002419,0.002237,0.056821,42.231468,2.151374,0.568207,-204.879257,0.057844,0.000000
38.490002,9.431076,-204.879257,-0.002402,0.002255,0.057280,41.951523,2.137112,0.572802,-204.879257,0.058477,0.000000
38.870003,9.810898,-204.879257,-0.002376,0.002284,0.058017,43.641052,2.223181,0.580171,-204.879257,0.059110,0.000000
39.250000,9.759140,-204.923737,-0.002337,0.002306,0.058564,43.410824,2.211453,0.585637,-204.923737,0.059743,0.000000
39.630001,10.004532,-204.968216,-0.002324,0.002329,0.059145,44.502380,2.267059,0.591447,-204.968216,0.060376,0.000000
40.010002,10.219765,-205.101669,-0.002302,0.002354,0.059787,45.459785,2.315832,0.597866,-205.101669,0.061009,0.000000
40.390003,10.637566,-205.057190,-0.002268,0.002382,0.060506,47.318256,2.410507,0.605061,-205.057190,0.061642,0.000000
40.770000,11.082550,-205.057190,-0.002251,0.002412,0.061261,49.297646,2.511342,0.612608,-205.057190,0.062276,0.000000
41.150002,11.065796,-205.146149,-0.002229,0.002432,0.061781,49.223118,2.507545,0.617812,-205.146149,0.062908,0.000000
41.530003,10.996529,-205.190628,-0.002195,0.002449,0.062215,48.915001,2.491849,0.622146,-205.190628,0.063542,0.000000
41.910004,11.561050,-205.235107,-0.002169,0.002481,0.063030,51.426121,2.619771,0.630299,-205.235107,0.064175,0.000000
42.290001,11.890228,-205.235107,-0.002143,0.002507,0.063680,52.890377,2.694364,0.636805,-205.235107,0.064808,0.000000
42.670002,12.225731,-205.279587,-0.002121,0.002538,0.064470,54.382767,2.770390,0.644696,-205.279587,0.065441,0.000000
43.050003,12.364258,-205.324066,-0.002100,0.002564,0.065120,54.998966,2.801781,0.651199,-205.324066,0.066082,0.000000
43.430000,12.761581,-205.368546,-0.002082,0.002590,0.065788,56.766350,2.891816,0.657875,-205.368546,0.066716,0.000000
43.810001,12.644279,-205.413025,-0.002057,0.002606,0.066204,56.244564,2.865235,0.662039,-205.413025,0.067349,0.000000
44.190002,13.247154,-205.413025,-0.002026,0.002636,0.066950,58.926285,3.001848,0.669499,-205.413025,0.067982,0.000000
44.570004,13.656387,-205.501999,-0.002018,0.002663,0.067644,60.746643,3.094582,0.676436,-205.501999,0.068615,0.000000
44.950001,14.074562,-205.546478,-0.001983,0.002690,0.068320,62.606777,3.189341,0.683200,-205.546478,0.069248,0.000000
45.330002,14.098770,-205.590958,-0.001953,0.002711,0.068849,62.714462,3.194827,0.688491,-205.590958,0.069881,0.000000
45.710003,14.479706,-205.679916,-0.001936,0.002732,0.069395,64.408951,3.281148,0.693953,-205.679916,0.070514,0.000000
46.090004,14.847984,-205.590958,-0.001923,0.002755,0.069985,66.047134,3.364601,0.699850,-205.590958,0.071147,0.000000
46.470001,15.652306,-205.679916,-0.001884,0.002788,0.070826,69.624931,3.546863,0.708264,-205.679916,0.071780,0.000000
46.850002,15.815033,-205.724396,-0.001880,0.002813,0.071442,70.348778,3.583738,0.714422,-205.724396,0.072413,0.000000
47.230003,15.982971,-205.813354,-0.001845,0.002832,0.071945,71.095810,3.621793,0.719448,-205.813354,0.073046,0.000000
47.610001,16.645424,-205.813354,-0.001828,0.002859,0.072630,74.042542,3.771907,0.726302,-205.813354,0.073679,0.000000
47.990002,16.916885,-205.813354,-0.001815,0.002881,0.073185,75.250061,3.833421,0.731851,-205.813354,0.074313,0.000000
48.370003,18.257050,-205.902328,-0.001772,0.002917,0.074104,81.211411,4.137106,0.741045,-205.902328,0.074945,0.000000
48.750004,18.153534,-205.946808,-0.001738,0.002939,0.074659,80.750954,4.113650,0.746593,-205.946808,0.075579,0.000000
49.130001,18.214600,-205.946808,-0.001733,0.002959,0.075162,81.022583,4.127487,0.751623,-205.946808,0.076212,0.000000
49.510002,18.947426,-205.991287,-0.001707,0.002985,0.075830,84.282356,4.293548,0.758300,-205.991287,0.076845,0.000000
49.890003,18.973495,-205.991287,-0.001690,0.003004,0.076290,84.398323,4.299455,0.762899,-205.991287,0.077478,0.000000
50.270004,20.446602,-206.035767,-0.001656,0.003039,0.077201,90.951027,4.633266,0.772005,-206.035767,0.078111,0.000000
50.650002,20.375847,-206.035767,-0.001647,0.003058,0.077677,90.636292,4.617233,0.776774,-206.035767,0.078744,0.000000
51.030003,21.174957,-206.124725,-0.001621,0.003085,0.078371,94.190918,4.798314,0.783712,-206.124725,0.079377,0.000000
51.410004,21.978539,-206.213684,-0.001604,0.003116,0.079134,97.765419,4.980408,0.791342,-206.213684,0.080010,0.000000
51.790001,21.966621,-206.169205,-0.001565,0.003131,0.079524,97.712410,4.977708,0.795244,-206.169205,0.080643,0.000000
52.170002,23.327644,-206.213684,-0.001552,0.003164,0.080375,103.766548,5.286120,0.803745,-206.213684,0.081276,0.000000
52.550003,23.236786,-206.347137,-0.001535,0.003182,0.080817,103.362389,5.265531,0.808166,-206.347137,0.081909,0.000000
52.930004,23.431168,-206.391617,-0.001513,0.003202,0.081337,104.227036,5.309578,0.813370,-206.391617,0.082543,0.000000
53.310001,25.251694,-206.391617,-0.001496,0.003235,0.082178,112.325142,5.722116,0.821784,-206.391617,0.083176,0.000000
53.690002,25.027901,-206.436096,-0.001475,0.003253,0.082629,111.329666,5.671403,0.826292,-206.436096,0.083809,0.000000
54.070004,26.940407,-206.480576,-0.001444,0.003287,0.083479,119.836914,6.104784,0.834789,-206.480576,0.084450,0.000000
54.450001,26.644371,-206.525055,-0.001431,0.003301,0.083852,118.520081,6.037701,0.838521,-206.525055,0.085083,0.000000
54.830002,27.985283,-206.569534,-0.001410,0.003335,0.084702,124.484756,6.341556,0.847018,-206.569534,0.085717,0.000000
55.210003,27.797981,-206.525055,-0.001406,0.003350,0.085101,123.651596,6.299113,0.851007,-206.525055,0.086350,0.000000
55.590004,29.263260,-206.569534,-0.001371,0.003382,0.085907,130.169479,6.631149,0.859073,-206.569534,0.086983,0.000000
55.970001,29.976730,-206.658493,-0.001358,0.003401,0.086393,133.343155,6.792824,0.863929,-206.658493,0.087616,0.000000
56.350002,31.139275,-206.747467,-0.001337,0.003432,0.087173,138.514404,7.056261,0.871733,-206.747467,0.088249,0.000000
56.730003,31.124382,-206.702972,-0.001341,0.003444,0.087477,138.448166,7.052886,0.874769,-206.702972,0.088882,0.000000
57.110004,33.139290,-206.747467,-0.001306,0.003483,0.088457,147.410919,7.509470,0.884568,-206.747467,0.089515,0.000000
57.490002,33.102425,-206.791946,-0.001281,0.003502,0.088960,147.246933,7.501117,0.889598,-206.791946,0.090148,0.000000
57.870003,34.329391,-206.880905,-0.001281,0.003522,0.089463,152.704758,7.779151,0.894628,-206.880905,0.090781,0.000000
58.250004,35.655037,-206.925385,-0.001255,0.003554,0.090269,158.601532,8.079547,0.902694,-206.925385,0.091414,0.000000
58.630001,36.241150,-206.925385,-0.001229,0.003579,0.090903,161.208679,8.212362,0.909026,-206.925385,0.092047,0.000000
59.010002,37.184746,-206.969864,-0.001220,0.003596,0.091345,165.406006,8.426184,0.913447,-206.969864,0.092680,0.000000
59.390003,39.178429,-207.014343,-0.001194,0.003632,0.092255,174.274353,8.877959,0.922553,-207.014343,0.093314,0.000000
59.770004,39.903061,-207.058823,-0.001181,0.003653,0.092793,177.497681,9.042163,0.927931,-207.058823,0.093946,0.000000
60.150002,41.483040,-207.103302,-0.001177,0.003682,0.093530,184.525772,9.400191,0.935301,-207.103302,0.094580,0.000000
60.530003,42.044945,-207.103302,-0.001151,0.003702,0.094042,187.025253,9.527521,0.940418,-207.103302,0.095213,0.000000
60.910004,42.413971,-207.147797,-0.001134,0.003720,0.094493,188.666763,9.611143,0.944929,-207.147797,0.095846,0.000000
61.290005,44.117577,-207.192276,-0.001108,0.003752,0.095291,196.244781,9.997186,0.952908,-207.192276,0.096479,0.000000
61.670002,45.819313,-207.281235,-0.001104,0.003778,0.095958,203.814484,10.382805,0.959584,-207.281235,0.097112,0.000000
62.050003,47.079422,-207.325714,-0.001095,0.003805,0.096652,209.419724,10.668349,0.966522,-207.325714,0.097745,0.000000
62.430004,48.200264,-207.325714,-0.001091,0.003825,0.097155,214.405487,10.922337,0.971552,-207.325714,0.098378,0.000000
62.810001,49.258919,-207.325714,-0.001065,0.003849,0.097754,219.114609,11.162230,0.977536,-207.325714,0.099011,0.000000
63.190002,50.959175,-207.370193,-0.001048,0.003877,0.098465,226.677734,11.547515,0.984648,-207.370193,0.099644,0.000000
63.570004,52.494461,-207.503632,-0.001035,0.003904,0.099150,233.507019,11.895415,0.991499,-207.503632,0.100277,0.000000
63.950005,54.464317,-207.459152,-0.001018,0.003934,0.099913,242.269379,12.341790,0.999129,-207.459152,0.100910,0.000000
64.330002,55.564674,-207.459152,-0.001013,0.003958,0.100537,247.164017,12.591135,1.005374,-207.459152,0.101543,0.000000
64.710007,56.669502,-207.503632,-0.000987,0.003979,0.101075,252.078537,12.841493,1.010752,-207.503632,0.102177,0.000000
65.090004,57.933708,-207.592606,-0.000966,0.004001,0.101621,257.701996,13.127966,1.016214,-207.592606,0.102818,0.000000
65.470001,59.446289,-207.681564,-0.000966,0.004026,0.102272,264.430298,13.470722,1.022720,-207.681564,0.103451,0.000000
65.850006,61.493217,-207.637085,-0.000940,0.004058,0.103061,273.535492,13.934563,1.030612,-207.637085,0.104084,0.000000
66.230003,63.040794,-207.637085,-0.000931,0.004083,0.103711,280.419464,14.285248,1.037114,-207.637085,0.104717,0.000000
66.610001,64.251747,-207.681564,-0.000927,0.004103,0.104223,285.806030,14.559654,1.042231,-207.681564,0.105351,0.000000
66.990005,66.200005,-207.815002,-0.000918,0.004131,0.104917,294.472321,15.001135,1.049169,-207.815002,0.105983,0.000000
67.370003,65.277260,-207.903961,-0.000905,0.004122,0.104691,290.367767,14.792039,1.046913,-207.903961,290.518494,0.000000
67.750000,64.459541,-207.903961,-0.000905,0.004122,0.104700,286.730347,14.606741,1.047000,-207.903961,294.500488,0.000000
68.130005,66.209312,-207.903961,-0.000862,0.004075,0.103503,294.513733,15.003245,1.035033,-207.903961,294.500488,0.000000
68.510002,65.560265,-207.948441,-0.000884,0.004105,0.104275,291.626617,14.856169,1.042750,-207.948441,294.500488,0.000000
68.890007,65.155128,-208.037415,-0.000862,0.004133,0.104969,289.824493,14.764363,1.049688,-208.037415,294.500488,0.000000
69.270004,65.028526,-208.037415,-0.000862,0.004146,0.105307,289.261322,14.735675,1.053071,-208.037415,294.500488,0.000000
69.650002,65.153633,-207.992920,-0.000871,0.004152,0.105472,289.817841,14.764025,1.054718,-207.992920,294.500488,0.000000
70.030006,64.977501,-208.037415,-0.000875,0.004153,0.105498,289.034363,14.724113,1.054979,-208.037415,294.500488,0.000000
70.410004,65.451164,-208.126373,-0.000875,0.004162,0.105715,291.141327,14.831446,1.057148,-208.126373,294.500488,0.000000
70.790001,65.252693,-208.215332,-0.000867,0.004162,0.105715,290.258484,14.786471,1.057148,-208.215332,294.500488,0.000000
71.170006,65.009895,-208.215332,-0.000871,0.004162,0.105715,289.178467,14.731453,1.057148,-208.215332,294.500488,0.000000
71.550003,64.803230,-208.215332,-0.000862,0.004162,0.105715,288.259155,14.684622,1.057148,-208.215332,294.500488,0.000000
71.930000,65.865242,-208.259811,-0.000858,0.004171,0.105940,292.983215,14.925277,1.059403,-208.259811,294.500488,0.000000
72.310005,65.651878,-208.393250,-0.000845,0.004171,0.105940,292.034149,14.876927,1.059403,-208.393250,294.500488,0.000000
72.690002,65.464577,-208.437744,-0.000862,0.004171,0.105949,291.200989,14.834485,1.059491,-208.437744,294.500488,0.000000
73.070000,65.264229,-208.393250,-0.000858,0.004171,0.105949,290.309784,14.789085,1.059491,-208.393250,294.500488,0.000000
73.450005,65.070229,-208.393250,-0.000854,0.004171,0.105949,289.446838,14.745125,1.059491,-208.393250,294.500488,0.000000
73.830002,64.923134,-208.482224,-0.000849,0.004171,0.105949,288.792511,14.711793,1.059491,-208.482224,294.500488,0.000000
74.210007,66.341881,-208.526703,-0.000849,0.004192,0.106469,295.103424,15.033285,1.064691,-208.526703,294.500488,0.000000
74.590004,66.230171,-208.615662,-0.000854,0.004182,0.106226,294.606506,15.007971,1.062265,-208.615662,294.500488,0.000000
74.970001,66.068184,-208.615662,-0.000854,0.004182,0.106226,293.885956,14.971265,1.062265,-208.615662,294.500488,0.000000
75.350006,65.870461,-208.571182,-0.000854,0.004182,0.106226,293.006439,14.926459,1.062265,-208.571182,294.500488,0.000000
75.730003,65.774757,-208.660141,-0.000841,0.004182,0.106226,292.580719,14.904774,1.062265,-208.660141,294.500488,0.000000
76.110001,65.644798,-208.749100,-0.000845,0.004182,0.106226,292.002655,14.875324,1.062265,-208.749100,294.500488,0.000000
76.490005,65.536812,-208.793579,-0.000854,0.004182,0.106226,291.522308,14.850854,1.062265,-208.793579,294.500488,0.000000
76.870003,65.404243,-208.749100,-0.000845,0.004182,0.106226,290.932617,14.820813,1.062265,-208.749100,294.500488,0.000000
77.250000,65.295509,-208.838058,-0.000832,0.004182,0.106226,290.448944,14.796174,1.062265,-208.838058,294.500488,0.000000
77.630005,65.195351,-208.927032,-0.000849,0.004182,0.106235,290.003418,14.773478,1.062352,-208.927032,294.500488,0.000000
78.010002,65.075066,-208.971512,-0.000854,0.004182,0.106235,289.468353,14.746221,1.062352,-208.971512,294.500488,0.000000
78.390007,64.985329,-209.015991,-0.000836,0.004182,0.106235,289.069183,14.725885,1.062352,-209.015991,294.500488,0.000000
78.770004,64.877342,-208.927032,-0.000836,0.004183,0.106244,288.588837,14.701416,1.062439,-208.927032,294.500488,0.000000
79.150002,64.780891,-209.015991,-0.000836,0.004183,0.106253,288.159790,14.679560,1.062526,-209.015991,294.500488,0.000000
79.530006,66.097969,-209.104950,-0.000841,0.004196,0.106573,294.018463,14.978013,1.065732,-209.104950,294.500488,0.000000
79.910004,66.011208,-209.149429,-0.000828,0.004195,0.106564,293.632507,14.958353,1.065645,-209.149429,294.500488,0.000000
80.290001,65.870461,-209.104950,-0.000828,0.004195,0.106564,293.006439,14.926459,1.065645,-209.104950,294.500488,0.000000
80.670006,65.839546,-209.193909,-0.000836,0.004195,0.106564,292.868927,14.919454,1.065645,-209.193909,294.500488,0.000000
81.050003,65.766563,-209.193909,-0.000832,0.004195,0.106564,292.544281,14.902917,1.065645,-209.193909,294.500488,0.000000
81.430000,65.658943,-209.238388,-0.000836,0.004195,0.106564,292.065552,14.878530,1.065645,-209.238388,294.500488,0.000000
81.810005,65.580376,-209.282867,-0.000832,0.004195,0.106564,291.716095,14.860725,1.065645,-209.282867,294.500488,0.000000
82.190002,65.526390,-209.282867,-0.000832,0.004195,0.106564,291.475952,14.848493,1.065645,-209.282867,294.500488,0.000000
82.570007,65.448189,-209.416321,-0.000836,0.004195,0.106564,291.128082,14.830771,1.065645,-209.416321,294.500488,0.000000
82.950005,65.361794,-209.460800,-0.000841,0.004196,0.106573,290.743774,14.811193,1.065732,-209.460800,294.500488,0.000000
83.330002,65.295509,-209.505280,-0.000832,0.004196,0.106573,290.448944,14.796174,1.065732,-209.505280,294.500488,0.000000
83.710007,65.240395,-209.460800,-0.000832,0.004196,0.106573,290.203766,14.783685,1.065732,-209.460800,294.500488,0.000000
84.090004,65.184914,-209.505280,-0.000828,0.004196,0.106573,289.956970,14.771112,1.065732,-209.505280,294.500488,0.000000
84.470001,65.094810,-209.505280,-0.000841,0.004196,0.106573,289.556183,14.750695,1.065732,-209.505280,294.500488,0.000000
84.850006,65.034111,-209.638718,-0.000832,0.004196,0.106573,289.286163,14.736940,1.065732,-209.638718,294.500488,0.000000
85.230003,64.998726,-209.683197,-0.000841,0.004196,0.106573,289.128784,14.728922,1.065732,-209.683197,294.500488,0.000000
85.610001,64.957024,-209.727692,-0.000836,0.004196,0.106573,288.943268,14.719472,1.065732,-209.727692,294.500488,0.000000
85.990005,65.887581,-209.727692,-0.000828,0.004213,0.106998,293.082611,14.930339,1.069982,-209.727692,294.500488,0.000000
86.370003,65.867104,-209.772171,-0.000823,0.004210,0.106929,292.991516,14.925699,1.069290,-209.772171,294.500488,0.000000
86.750008,65.846245,-209.816650,-0.000819,0.004210,0.106929,292.898712,14.920972,1.069290,-209.816650,294.500488,0.000000
87.130005,65.851830,-209.816650,-0.000836,0.004210,0.106929,292.923553,14.922237,1.069290,-209.816650,294.500488,0.000000
87.510002,65.827629,-209.861130,-0.000828,0.004210,0.106929,292.815918,14.916754,1.069290,-209.861130,294.500488,0.000000
87.890007,65.783318,-209.905609,-0.000828,0.004210,0.106929,292.618805,14.906713,1.069290,-209.905609,294.500488,0.000000
88.270004,65.759483,-209.950089,-0.000823,0.004210,0.106929,292.512787,14.901312,1.069290,-209.950089,294.500488,0.000000
88.650002,65.650017,-210.039047,-0.000832,0.004210,0.106929,292.025848,14.876507,1.069290,-210.039047,294.500488,0.000000
89.030006,65.599739,-210.039047,-0.000823,0.004210,0.106929,291.802216,14.865113,1.069290,-210.039047,294.500488,0.000000
89.410004,65.581871,-210.083527,-0.000832,0.004210,0.106929,291.722717,14.861064,1.069290,-210.083527,294.500488,0.000000
89.790001,65.566597,-210.128006,-0.000828,0.004210,0.106929,291.654785,14.857604,1.069290,-210.128006,294.500488,0.000000
90.170006,65.518929,-210.216980,-0.000828,0.004210,0.106929,291.442749,14.846802,1.069290,-210.216980,294.500488,0.000000
90.550003,65.488777,-210.216980,-0.000828,0.004210,0.106929,291.308624,14.839969,1.069290,-210.216980,294.500488,0.000000
90.930008,65.416908,-210.172501,-0.000815,0.004210,0.106929,290.988953,14.823683,1.069290,-210.172501,294.500488,0.000000
91.310005,65.356956,-210.172501,-0.000823,0.004210,0.106929,290.722260,14.810098,1.069290,-210.172501,294.500488,0.000000
91.690002,65.324928,-210.305939,-0.000836,0.004210,0.106929,290.579803,14.802840,1.069290,-210.305939,294.500488,0.000000
92.070007,65.298485,-210.350418,-0.000823,0.004210,0.106929,290.462158,14.796848,1.069290,-210.350418,294.500488,0.000000
92.450005,65.264229,-210.394897,-0.000832,0.004210,0.106929,290.309784,14.789085,1.069290,-210.394897,294.500488,0.000000
92.830002,65.235558,-210.483856,-0.000823,0.004210,0.106938,290.182251,14.782589,1.069377,-210.483856,294.500488,0.000000
93.210007,65.211723,-210.394897,-0.000836,0.004211,0.106963,290.076233,14.777188,1.069634,-210.394897,294.500488,0.000000
93.590004,65.188271,-210.528336,-0.000811,0.004211,0.106963,289.971924,14.771873,1.069634,-210.528336,294.500488,0.000000
93.970001,65.134270,-210.572815,-0.000823,0.004211,0.106963,289.731689,14.759637,1.069634,-210.572815,294.500488,0.000000
94.350006,65.108574,-210.528336,-0.000832,0.004211,0.106963,289.617401,14.753814,1.069634,-210.528336,294.500488,0.000000
94.730003,65.065010,-210.572815,-0.000828,0.004211,0.106963,289.423615,14.743942,1.069634,-210.572815,294.500488,0.000000
95.110008,65.426582,-210.617310,-0.000815,0.004219,0.107154,291.031982,14.825875,1.071542,-210.617310,294.500488,0.000000
95.490005,65.583351,-210.661789,-0.000811,0.004218,0.107146,291.729309,14.861400,1.071458,-210.661789,294.500488,0.000000
95.870003,65.591179,-210.750748,-0.000815,0.004218,0.107146,291.764130,14.863173,1.071458,-210.750748,294.500488,0.000000
96.250008,65.603096,-210.750748,-0.000823,0.004218,0.107146,291.817139,14.865874,1.071458,-210.750748,294.500488,0.000000
96.630005,65.602348,-210.795227,-0.000832,0.004218,0.107146,291.813812,14.865705,1.071458,-210.795227,294.500488,0.000000
97.010002,65.585960,-210.750748,-0.000823,0.004218,0.107146,291.740936,14.861991,1.071458,-210.750748,294.500488,0.000000
97.390007,65.559517,-210.928665,-0.000819,0.004218,0.107146,291.623291,14.855999,1.071458,-210.928665,294.500488,0.000000
97.770004,65.555794,-210.928665,-0.000815,0.004218,0.107146,291.606720,14.855155,1.071458,-210.928665,294.500488,0.000000
98.150002,65.527870,-210.928665,-0.000828,0.004218,0.107146,291.482513,14.848827,1.071458,-210.928665,294.500488,0.000000
98.530006,65.504417,-210.928665,-0.000819,0.004218,0.107146,291.378204,14.843513,1.071458,-210.928665,294.500488,0.000000
98.910004,65.484673,-211.017639,-0.000811,0.004218,0.107146,291.290375,14.839039,1.071458,-211.017639,294.500488,0.000000
99.290001,65.451912,-211.062119,-0.000823,0.004218,0.107146,291.144653,14.831614,1.071458,-211.062119,294.500488,0.000000
99.670006,65.410576,-211.106598,-0.000806,0.004218,0.107146,290.960785,14.822248,1.071458,-211.106598,294.500488,0.000000
100.050003,65.389351,-211.151077,-0.000828,0.004218,0.107146,290.866364,14.817439,1.071458,-211.151077,294.500488,0.000000
100.430008,65.354713,-211.106598,-0.000806,0.004219,0.107154,290.712280,14.809589,1.071542,-211.106598,294.500488,0.000000
100.810005,65.328651,-211.195557,-0.000811,0.004219,0.107154,290.596344,14.803684,1.071542,-211.195557,294.500488,0.000000
101.190002,65.316734,-211.240036,-0.000823,0.004219,0.107154,290.543335,14.800983,1.071542,-211.240036,294.500488,0.000000
101.570007,65.283592,-211.328995,-0.000823,0.004219,0.107154,290.395935,14.793474,1.071542,-211.328995,294.500488,0.000000
101.950005,65.255669,-211.328995,-0.000823,0.004219,0.107154,290.271698,14.787147,1.071542,-211.328995,294.500488,0.000000
102.330002,65.257530,-211.373474,-0.000815,0.004219,0.107154,290.279999,14.787567,1.071542,-211.373474,294.500488,0.000000
102.710007,65.243385,-211.373474,-0.000811,0.004219,0.107172,290.217072,14.784363,1.071716,-211.373474,294.500488,0.000000
103.090004,65.237801,-211.462448,-0.000815,0.004220,0.107180,290.192230,14.783097,1.071803,-211.462448,294.500488,0.000000
103.470001,65.208000,-211.462448,-0.000819,0.004220,0.107180,290.059662,14.776343,1.071803,-211.462448,294.500488,0.000000
103.850006,65.193108,-211.551407,-0.000815,0.004220,0.107189,289.993439,14.772969,1.071890,-211.551407,294.500488,0.000000
104.230003,65.208000,-211.640366,-0.000811,0.004220,0.107198,290.059662,14.776343,1.071977,-211.640366,294.500488,0.000000
104.610008,65.186409,-211.595886,-0.000815,0.004220,0.107198,289.963623,14.771451,1.071977,-211.595886,294.500488,0.000000
104.990005,65.198326,-211.640366,-0.000823,0.004221,0.107215,290.016632,14.774152,1.072151,-211.640366,294.500488,0.000000
105.370003,65.211357,-211.684845,-0.000823,0.004221,0.107224,290.074615,14.777104,1.072238,-211.684845,294.500488,0.000000
105.750008,65.202797,-211.684845,-0.000819,0.004222,0.107250,290.036530,14.775166,1.072499,-211.684845,294.500488,0.000000
106.130005,65.262001,-211.773804,-0.000806,0.004223,0.107258,290.299866,14.788581,1.072582,-211.773804,294.500488,0.000000
106.510002,65.262749,-211.818283,-0.000811,0.004223,0.107258,290.303192,14.788750,1.072582,-211.818283,294.500488,0.000000
106.890007,65.253059,-211.907257,-0.000811,0.004223,0.107258,290.260101,14.786554,1.072582,-211.907257,294.500488,0.000000
107.270004,65.241142,-211.862762,-0.000819,0.004223,0.107258,290.207092,14.783854,1.072582,-211.862762,294.500488,0.000000
107.650002,65.236671,-211.907257,-0.000815,0.004223,0.107258,290.187195,14.782842,1.072582,-211.907257,294.500488,0.000000
108.030006,65.251945,-211.907257,-0.000815,0.004224,0.107284,290.255157,14.786302,1.072844,-211.907257,294.500488,0.000000
108.410004,65.282845,-212.040695,-0.000815,0.004224,0.107293,290.392609,14.793304,1.072931,-212.040695,294.500488,0.000000
108.790009,65.278389,-212.085175,-0.000819,0.004224,0.107302,290.372772,14.792295,1.073018,-212.085175,294.500488,0.000000
109.170006,65.273918,-212.040695,-0.000815,0.004224,0.107302,290.352875,14.791282,1.073018,-212.040695,294.500488,0.000000
109.550003,65.274284,-212.040695,-0.000823,0.004224,0.107302,290.354523,14.791364,1.073018,-212.040695,294.500488,0.000000
109.930008,65.261620,-212.129654,-0.000811,0.004224,0.107302,290.298187,14.788494,1.073018,-212.129654,294.500488,0.000000
110.310005,65.258278,-212.174133,-0.000815,0.004224,0.107302,290.283325,14.787737,1.073018,-212.174133,294.500488,0.000000
110.690002,65.244118,-212.218613,-0.000823,0.004224,0.107302,290.220337,14.784528,1.073018,-212.218613,294.500488,0.000000
111.070007,65.238533,-212.263092,-0.000802,0.004224,0.107302,290.195496,14.783262,1.073018,-212.263092,294.500488,0.000000
111.450005,65.222160,-212.263092,-0.000823,0.004224,0.107302,290.122650,14.779552,1.073018,-212.263092,294.500488,0.000000
111.830002,65.204277,-212.352066,-0.000823,0.004224,0.107302,290.043121,14.775500,1.073018,-212.352066,294.500488,0.000000
112.210007,65.201668,-212.307587,-0.000811,0.004224,0.107302,290.031494,14.774909,1.073018,-212.307587,294.500488,0.000000
112.590004,65.166298,-212.441025,-0.000819,0.004224,0.107302,289.874176,14.766894,1.073018,-212.441025,294.500488,0.000000
112.970009,65.156990,-212.396545,-0.000823,0.004224,0.107302,289.832764,14.764785,1.073018,-212.396545,294.500488,0.000000
113.350006,65.159599,-212.441025,-0.000806,0.004225,0.107310,289.844360,14.765376,1.073105,-212.441025,294.500488,0.000000
113.730003,65.133537,-212.529984,-0.000815,0.004225,0.107310,289.728455,14.759470,1.073105,-212.529984,294.500488,0.000000
114.110008,65.110451,-212.529984,-0.000819,0.004225,0.107310,289.625763,14.754239,1.073105,-212.529984,294.500488,0.000000
114.490005,65.122734,-212.574463,-0.000802,0.004226,0.107337,289.680389,14.757022,1.073366,-212.574463,294.500488,0.000000
114.870003,65.118629,-212.618942,-0.000819,0.004226,0.107337,289.662140,14.756093,1.073366,-212.618942,294.500488,0.000000
115.250008,65.113045,-212.663422,-0.000811,0.004226,0.107337,289.637299,14.754827,1.073366,-212.663422,294.500488,0.000000
115.630005,65.081764,-212.663422,-0.000811,0.004226,0.107337,289.498138,14.747739,1.073366,-212.663422,294.500488,0.000000
116.010002,65.090340,-212.752396,-0.000815,0.004226,0.107337,289.536285,14.749682,1.073366,-212.752396,294.500488,0.000000
116.390007,65.076180,-212.796875,-0.000823,0.004226,0.107337,289.473297,14.746473,1.073366,-212.796875,294.500488,0.000000
116.770004,65.082512,-212.752396,-0.000815,0.004227,0.107371,289.501465,14.747909,1.073710,-212.752396,294.500488,0.000000
117.150009,65.119377,-212.841354,-0.000806,0.004228,0.107380,289.665466,14.756262,1.073797,-212.841354,294.500488,0.000000
117.530006,65.105598,-212.885834,-0.000811,0.004228,0.107380,289.604156,14.753139,1.073797,-212.885834,294.500488,0.000000
117.910004,65.123100,-212.885834,-0.000815,0.004228,0.107380,289.682007,14.757106,1.073797,-212.885834,294.500488,0.000000
118.290009,65.116768,-212.974792,-0.000815,0.004228,0.107380,289.653839,14.755671,1.073797,-212.974792,294.500488,0.000000
118.670006,65.112312,-212.974792,-0.000823,0.004228,0.107380,289.634033,14.754661,1.073797,-212.974792,294.500488,0.000000
119.050003,65.095543,-212.974792,-0.000815,0.004228,0.107380,289.559448,14.750860,1.073797,-212.974792,294.500488,0.000000
119.430008,65.075813,-213.108231,-0.000819,0.004229,0.107406,289.471680,14.746390,1.074059,-213.108231,294.500488,0.000000
119.810005,65.164803,-213.108231,-0.000815,0.004229,0.107423,289.867523,14.766556,1.074233,-213.108231,294.500488,0.000000
120.190002,65.173378,-213.152710,-0.000806,0.004229,0.107423,289.905670,14.768499,1.074233,-213.152710,294.500488,0.000000
120.570007,65.184166,-213.152710,-0.000802,0.004229,0.107423,289.953644,14.770943,1.074233,-213.152710,294.500488,0.000000
120.950005,65.172997,-213.197205,-0.000811,0.004229,0.107423,289.903961,14.768412,1.074233,-213.197205,294.500488,0.000000
121.330009,65.170021,-213.241684,-0.000811,0.004229,0.107423,289.890747,14.767738,1.074233,-213.241684,294.500488,0.000000
121.710007,65.157738,-213.286163,-0.000815,0.004229,0.107423,289.836090,14.764955,1.074233,-213.286163,294.500488,0.000000
122.090004,65.145073,-213.330643,-0.000811,0.004230,0.107432,289.779755,14.762084,1.074320,-213.330643,294.500488,0.000000
122.470009,65.126076,-213.330643,-0.000806,0.004230,0.107432,289.695251,14.757779,1.074320,-213.330643,294.500488,0.000000
122.850006,65.122353,-213.419601,-0.000802,0.004230,0.107432,289.678680,14.756936,1.074320,-213.419601,294.500488,0.000000
123.230003,65.109322,-213.508560,-0.000811,0.004230,0.107432,289.620728,14.753983,1.074320,-213.508560,294.500488,0.000000
123.610008,65.091454,-213.508560,-0.000811,0.004230,0.107432,289.541260,14.749934,1.074320,-213.508560,294.500488,0.000000
123.990005,65.092201,-213.464081,-0.000815,0.004230,0.107432,289.544586,14.750103,1.074320,-213.464081,294.500488,0.000000
124.370003,65.076180,-213.553040,-0.000798,0.004230,0.107432,289.473297,14.746473,1.074320,-213.553040,294.500488,0.000000
124.750008,65.075066,-213.553040,-0.000798,0.004230,0.107432,289.468353,14.746221,1.074320,-213.553040,294.500488,0.000000
125.130005,65.059425,-213.597534,-0.000815,0.004230,0.107432,289.398773,14.742677,1.074320,-213.597534,294.500488,0.000000
125.510010,65.046394,-213.686493,-0.000815,0.004230,0.107432,289.340820,14.739723,1.074320,-213.686493,294.500488,0.000000
125.890007,65.039696,-213.730972,-0.000806,0.004230,0.107432,289.311005,14.738206,1.074320,-213.730972,294.500488,0.000000
126.270004,65.037453,-213.686493,-0.000819,0.004230,0.107432,289.301025,14.737697,1.074320,-213.686493,294.500488,0.000000
126.650009,65.033730,-213.775452,-0.000811,0.004230,0.107441,289.284485,14.736854,1.074407,-213.775452,294.500488,0.000000
127.030006,65.017357,-213.819931,-0.000798,0.004230,0.107441,289.211639,14.733144,1.074407,-213.819931,294.500488,0.000000
127.410004,65.016228,-213.908890,-0.000806,0.004230,0.107449,289.206635,14.732888,1.074490,-213.908890,294.500488,0.000000
127.790009,65.089592,-213.908890,-0.000815,0.004222,0.107250,289.532959,14.749513,1.072499,-213.908890,0.107397,0.000000
128.170013,65.046761,-213.908890,-0.000798,0.004213,0.107016,289.342438,14.739807,1.070156,-213.908890,0.106764,0.000000
128.550003,64.988304,-213.997849,-0.000806,0.004192,0.106478,289.082428,14.726561,1.064778,-213.997849,0.106131,0.000000
128.930008,64.974159,-214.042343,-0.000789,0.004170,0.105914,289.019501,14.723354,1.059142,-214.042343,0.105498,0.000000
129.310013,64.930214,-214.086823,-0.000802,0.004148,0.105359,288.824005,14.713397,1.053594,-214.086823,0.104865,0.000000
129.690002,64.895592,-214.042343,-0.000785,0.004126,0.104795,288.670013,14.705551,1.047954,-214.042343,0.104232,0.000000
130.070007,64.881065,-214.086823,-0.000789,0.004102,0.104180,288.605408,14.702259,1.041796,-214.086823,0.103599,0.000000
130.450012,64.851265,-214.131302,-0.000785,0.004074,0.103477,288.472839,14.695507,1.034771,-214.131302,0.102966,0.000000
130.830002,64.804726,-214.131302,-0.000802,0.004047,0.102801,288.265808,14.684960,1.028008,-214.131302,0.102333,0.000000
131.210007,64.806221,-214.264740,-0.000785,0.004025,0.102228,288.272461,14.685300,1.022285,-214.264740,0.101699,0.000000
131.590012,64.706413,-214.264740,-0.000780,0.004006,0.101752,287.828491,14.662683,1.017516,-214.264740,0.101058,0.000000
131.970001,64.274467,-214.264740,-0.000789,0.003982,0.101136,285.907104,14.564802,1.011358,-214.264740,0.100425,0.000000
132.350006,63.240761,-214.309219,-0.000767,0.003957,0.100520,281.308960,14.330561,1.005200,-214.309219,0.099791,0.000000
132.730011,61.939316,-214.398178,-0.000767,0.003931,0.099835,275.519836,14.035649,0.998349,-214.398178,0.099159,0.000000
133.110001,60.738419,-214.442657,-0.000772,0.003911,0.099341,270.177979,13.763522,0.993406,-214.442657,0.098525,0.000000
133.490005,59.067955,-214.442657,-0.000767,0.003885,0.098690,262.747375,13.384990,0.986904,-214.442657,0.097893,0.000000
133.870010,57.642517,-214.442657,-0.000750,0.003867,0.098222,256.406708,13.061981,0.982218,-214.442657,0.097259,0.000000
134.250000,55.363594,-214.576111,-0.000780,0.003840,0.097528,246.269562,12.545569,0.975280,-214.576111,0.096626,0.000000
134.630005,54.197327,-214.576111,-0.000776,0.003828,0.097233,241.081757,12.281290,0.972332,-214.576111,0.095993,0.000000
135.010010,50.959915,-214.620590,-0.000763,0.003792,0.096314,226.681030,11.547682,0.963138,-214.620590,0.095360,0.000000
135.389999,48.783028,-214.576111,-0.000767,0.003773,0.095837,216.997742,11.054393,0.958369,-214.576111,0.094727,0.000000
135.770004,45.927673,-214.620590,-0.000772,0.003745,0.095134,204.296494,10.407359,0.951345,-214.620590,0.094094,0.000000
136.150009,42.834007,-214.709549,-0.000767,0.003717,0.094415,190.535187,9.706325,0.944150,-214.709549,0.093461,0.000000
136.530014,40.501465,-214.709549,-0.000759,0.003695,0.093860,180.159515,9.177763,0.938597,-214.709549,0.092828,0.000000
136.910004,37.347099,-214.754028,-0.000763,0.003667,0.093131,166.128189,8.462975,0.931311,-214.754028,0.092195,0.000000
137.290009,34.405724,-214.798508,-0.000767,0.003639,0.092429,153.044296,7.796449,0.924290,-214.798508,0.091562,0.000000
137.670013,32.139465,-214.887482,-0.000767,0.003621,0.091978,142.963486,7.282907,0.919779,-214.887482,0.090929,0.000000
138.050003,29.230125,-214.842987,-0.000755,0.003594,0.091293,130.022095,6.623641,0.912928,-214.842987,0.090295,0.000000
138.430008,26.461159,-214.976440,-0.000767,0.003568,0.090625,117.705116,5.996184,0.906251,-214.976440,0.089662,0.000000
138.810013,23.684380,-214.976440,-0.000767,0.003543,0.089983,105.353378,5.366957,0.899832,-214.976440,0.089029,0.000000
139.190002,21.514565,-214.976440,-0.000780,0.003522,0.089463,95.701561,4.875270,0.894628,-214.976440,0.088396,0.000000
139.570007,19.203621,-215.020920,-0.000759,0.003505,0.089021,85.421974,4.351603,0.890207,-215.020920,0.087763,0.000000
139.950012,16.074577,-215.109879,-0.000763,0.003469,0.088101,71.503288,3.642551,0.881014,-215.109879,0.087130,0.000000
140.330002,13.494034,-215.198837,-0.000772,0.003453,0.087711,60.024460,3.057792,0.877112,-215.198837,0.086497,0.000000
140.710007,10.389938,-215.154358,-0.000763,0.003423,0.086957,46.216755,2.354394,0.869568,-215.154358,0.085864,0.000000
141.090012,7.819824,-215.109879,-0.000767,0.003395,0.086228,34.784317,1.771997,0.862282,-215.109879,0.085231,0.000000
141.470001,4.485970,-215.198837,-0.000772,0.003367,0.085534,19.954590,1.016535,0.855345,-215.198837,0.084598,0.000000
141.850006,2.157524,-215.243317,-0.000789,0.003345,0.084971,9.597147,0.488902,0.849709,-215.243317,0.083965,0.000000
142.230011,-0.073730,-215.332291,-0.000780,0.003317,0.084260,-0.327969,-0.016708,0.842597,-215.332291,0.083332,0.000000
142.610001,-0.529510,-215.332291,-0.000819,0.003293,0.083653,-2.355380,-0.119989,0.836526,-215.332291,0.082690,0.000000
142.990005,0.027557,-215.376770,-0.000849,0.003273,0.083123,0.122581,0.006245,0.831235,-215.376770,0.082057,0.000000
143.370010,0.030907,-215.376770,-0.000880,0.003246,0.082438,0.137480,0.007004,0.824384,-215.376770,0.081424,0.000000
143.750000,0.012665,-215.465729,-0.000918,0.003220,0.081788,0.056336,0.002870,0.817878,-215.465729,0.080791,0.000000
144.130005,0.035004,-215.510208,-0.000949,0.003200,0.081276,0.155704,0.007932,0.812765,-215.510208,0.080158,0.000000
144.510010,0.046173,-215.510208,-0.000983,0.003167,0.080444,0.205388,0.010463,0.804438,-215.510208,0.079524,0.000000
144.889999,-0.005959,-215.510208,-0.001018,0.003146,0.079898,-0.026505,-0.001350,0.798976,-215.510208,0.078892,0.000000
145.270004,0.001862,-215.510208,-0.001052,0.003123,0.079316,0.008281,0.000422,0.793163,-215.510208,0.078258,0.000000
145.650009,-0.025696,-215.643646,-0.001082,0.003108,0.078943,-0.114301,-0.005823,0.789434,-215.643646,0.077625,0.000000
146.030014,0.004845,-215.688126,-0.001130,0.003067,0.077894,0.021550,0.001098,0.778943,-215.688126,0.076992,0.000000
146.410004,0.006706,-215.688126,-0.001160,0.003043,0.077287,0.029831,0.001520,0.772872,-215.688126,0.076359,0.000000
146.790009,0.007820,-215.688126,-0.001177,0.003020,0.076715,0.034786,0.001772,0.767149,-215.688126,0.075726,0.000000
147.170013,0.018250,-215.777100,-0.001220,0.002990,0.075934,0.081178,0.004135,0.759341,-215.777100,0.075093,0.000000
147.550003,0.010056,-215.821579,-0.001246,0.002970,0.075431,0.044729,0.002279,0.754311,-215.821579,0.074460,0.000000
147.930008,0.000374,-215.866058,-0.001268,0.002951,0.074945,0.001663,0.000085,0.749455,-215.866058,0.073827,0.000000
148.310013,0.000748,-215.866058,-0.001302,0.002921,0.074200,0.003326,0.000169,0.741998,-215.866058,0.073194,0.000000
148.690002,0.005585,-215.910538,-0.001311,0.002896,0.073567,0.024842,0.001266,0.735666,-215.910538,0.072561,0.000000
149.070007,0.053253,-215.999496,-0.001350,0.002869,0.072864,0.236882,0.012067,0.728642,-215.999496,0.071928,0.000000
149.450012,0.027557,-215.999496,-0.001371,0.002849,0.072352,0.122581,0.006245,0.723524,-215.999496,0.071295,0.000000
149.830002,0.035004,-216.043976,-0.001397,0.002824,0.071737,0.155704,0.007932,0.717370,-216.043976,0.070661,0.000000
150.210007,0.021599,-216.043976,-0.001427,0.002795,0.071000,0.096076,0.004894,0.709997,-216.043976,0.070029,0.000000
150.590012,0.017876,-216.043976,-0.001457,0.002770,0.070366,0.079515,0.004051,0.703665,-216.043976,0.069395,0.000000
150.970001,0.068146,-216.132935,-0.001487,0.002743,0.069664,0.303127,0.015442,0.696640,-216.132935,0.068762,0.000000
151.350006,0.062935,-216.221909,-0.001513,0.002723,0.069170,0.279948,0.014261,0.691697,-216.221909,0.068129,0.000000
151.730011,0.037613,-216.221909,-0.001518,0.002696,0.068476,0.167311,0.008523,0.684759,-216.221909,0.067496,0.000000
152.110001,0.027557,-216.266388,-0.001561,0.002669,0.067800,0.122581,0.006245,0.677996,-216.266388,0.066863,0.000000
152.490005,0.035378,-216.266388,-0.001591,0.002644,0.067149,0.157367,0.008017,0.671493,-216.266388,0.066230,0.000000
152.870010,0.042076,-216.310867,-0.001613,0.002616,0.066438,0.187164,0.009535,0.664382,-216.310867,0.065597,0.000000
153.250000,0.024574,-216.399826,-0.001651,0.002598,0.065996,0.109312,0.005569,0.659957,-216.399826,0.064964,0.000000
153.630005,0.032028,-216.399826,-0.001664,0.002576,0.065432,0.142469,0.007258,0.654321,-216.399826,0.064322,0.000000
154.010010,0.016014,-216.488785,-0.001681,0.002549,0.064747,0.071234,0.003629,0.647471,-216.488785,0.063689,0.000000
154.390015,0.039101,-216.444305,-0.001720,0.002517,0.063941,0.173928,0.008860,0.639405,-216.444305,0.063056,0.000000
154.770004,0.020851,-216.577744,-0.001738,0.002492,0.063290,0.092750,0.004725,0.632899,-216.577744,0.062423,0.000000
155.000000,0.040962,-216.622238,-0.001759,0.002490,0.063255,0.182209,0.009282,0.632554,-216.622238,0.063169,0.000000