File: Data/compression 24/AutoHeating-12-24-reverse-1-4_09202024_165903.csv
Time (sec),S:Load (lbs),S:HL1 (DIM),S:LVDT (in),S:Position (in),Ch:Position (mm),Ch:Load (N),Ch:Stress (MPa),Ch:Strain (mm/mm),Ch:HL1 (DIM),Set Point (),Cycles ()
0.110000,0.006332,-254.875854,-0.013620,-0.009148,-0.232356,0.028168,0.001435,-2.323558,-254.875854,-0.232148,0.000000
0.510000,-0.002235,-254.831375,-0.013603,-0.009077,-0.230552,-0.009944,-0.000507,-2.305520,-254.831375,-0.230101,0.000000
0.910000,-0.016014,-254.964813,-0.013478,-0.008836,-0.224430,-0.071234,-0.003629,-2.244295,-254.964813,-0.223441,0.000000
1.310000,-0.010796,-254.875854,-0.013215,-0.008573,-0.217761,-0.048021,-0.002446,-2.177605,-254.875854,-0.216763,0.000000
1.710000,0.024208,-254.964813,-0.012939,-0.008309,-0.211048,0.107683,0.005486,-2.110480,-254.964813,-0.210103,0.000000
2.110000,0.043198,-255.053772,-0.012654,-0.008049,-0.204440,0.192153,0.009789,-2.044400,-255.053772,-0.203443,0.000000
2.510000,0.011543,-254.964813,-0.012409,-0.007790,-0.197875,0.051347,0.002616,-1.978751,-254.964813,-0.196782,0.000000
2.910000,-0.039841,-255.009293,-0.012124,-0.007528,-0.191206,-0.177220,-0.009028,-1.912061,-255.009293,-0.190122,0.000000
3.310000,-0.067772,-255.142731,-0.011861,-0.007265,-0.184520,-0.301465,-0.015357,-1.845197,-255.142731,-0.183444,0.000000
3.710000,-0.000000,-255.187210,-0.011598,-0.007006,-0.177955,-0.000000,-0.000000,-1.779548,-255.187210,-0.176784,0.000000
4.110000,0.005211,-255.187210,-0.011322,-0.006741,-0.171234,0.023179,0.001181,-1.712340,-255.187210,-0.170124,0.000000
4.510000,0.007446,-255.142731,-0.011059,-0.006478,-0.164530,0.033123,0.001687,-1.645301,-255.142731,-0.163464,0.000000
4.910000,-0.003349,-255.231705,-0.010796,-0.006215,-0.157852,-0.014898,-0.000759,-1.578524,-255.231705,-0.156803,0.000000
5.310000,-0.006332,-255.276184,-0.010524,-0.005953,-0.151201,-0.028168,-0.001435,-1.512009,-255.276184,-0.150126,0.000000
5.710000,0.011917,-255.276184,-0.010257,-0.005699,-0.144749,0.053010,0.002700,-1.447488,-255.276184,-0.143465,0.000000
6.110000,0.020851,-255.320663,-0.009998,-0.005443,-0.138262,0.092750,0.004725,-1.382618,-255.320663,-0.136805,0.000000
6.510000,0.033516,-255.365143,-0.009718,-0.005174,-0.131419,0.149086,0.007595,-1.314195,-255.365143,-0.130145,0.000000
6.910000,0.020111,-255.365143,-0.009459,-0.004908,-0.124655,0.089459,0.004557,-1.246551,-255.365143,-0.123467,0.000000
7.310000,-0.013405,-255.409622,-0.009175,-0.004642,-0.117908,-0.059628,-0.003038,-1.179082,-255.409622,-0.116807,0.000000
7.710001,0.002983,-255.409622,-0.008895,-0.004375,-0.111118,0.013269,0.000676,-1.111177,-255.409622,-0.110147,0.000000
8.110001,0.027184,-255.498581,-0.008636,-0.004111,-0.104423,0.120918,0.006160,-1.044226,-255.498581,-0.103486,0.000000
8.510000,0.047668,-255.543060,-0.008356,-0.003851,-0.097823,0.212040,0.010802,-0.978233,-255.543060,-0.096826,0.000000
8.910001,-0.000000,-255.454102,-0.008106,-0.003592,-0.091232,-0.000000,-0.000000,-0.912322,-255.454102,-0.090148,0.000000
9.310000,-0.018242,-255.587540,-0.007834,-0.003330,-0.084589,-0.081144,-0.004134,-0.845894,-255.587540,-0.083488,0.000000
9.710000,-0.045059,-255.632019,-0.007562,-0.003068,-0.077938,-0.200433,-0.010211,-0.779378,-255.632019,-0.076828,0.000000
10.110001,0.032028,-255.632019,-0.007286,-0.002808,-0.071312,0.142469,0.007258,-0.713120,-255.632019,-0.070167,0.000000
10.510000,0.011917,-255.676514,-0.007028,-0.002543,-0.064591,0.053010,0.002700,-0.645911,-255.676514,-0.063507,0.000000
10.910001,0.035751,-255.720993,-0.006743,-0.002279,-0.057896,0.159030,0.008101,-0.578960,-255.720993,-0.056829,0.000000
11.310000,0.025322,-255.765472,-0.006476,-0.002019,-0.051279,0.112638,0.005738,-0.512793,-255.765472,-0.050169,0.000000
11.710001,0.011169,-255.809952,-0.006226,-0.001756,-0.044602,0.049684,0.002531,-0.446016,-255.809952,-0.043509,0.000000
12.110001,0.022713,-255.809952,-0.005937,-0.001502,-0.038141,0.101031,0.005147,-0.381408,-255.809952,-0.036849,0.000000
12.510000,0.033890,-255.898911,-0.005674,-0.001245,-0.031610,0.150749,0.007680,-0.316103,-255.898911,-0.030188,0.000000
12.910001,0.064049,-255.898911,-0.005398,-0.000979,-0.024855,0.284903,0.014514,-0.248546,-255.898911,-0.023511,0.000000
13.310000,0.077827,-255.898911,-0.005131,-0.000711,-0.018047,0.346194,0.017636,-0.180471,-255.898911,-0.016850,0.000000
13.710001,0.111710,-255.943390,-0.005027,0.000013,0.000338,0.496909,0.025314,0.003380,-255.943390,0.000546,0.000000
14.110001,0.079689,-255.943390,-0.005027,0.000013,0.000338,0.354474,0.018058,0.003380,-255.943390,0.000824,0.000000
14.510000,0.103889,-255.943390,-0.005027,0.000014,0.000347,0.462123,0.023542,0.003467,-255.943390,0.001492,0.000000
14.910001,0.132195,-256.032349,-0.005010,0.000045,0.001145,0.588031,0.029956,0.011446,-256.032349,0.002159,0.000000
15.310000,0.129585,-256.076843,-0.004971,0.000076,0.001942,0.576424,0.029364,0.019424,-256.076843,0.002818,0.000000
15.710001,0.133682,-256.032349,-0.004954,0.000102,0.002584,0.594648,0.030293,0.025843,-256.032349,0.003486,0.000000
16.110001,0.136292,-256.121307,-0.004911,0.000128,0.003252,0.606255,0.030884,0.032520,-256.121307,0.004154,0.000000
16.510000,0.170547,-256.165802,-0.004907,0.000158,0.004015,0.758633,0.038647,0.040150,-256.165802,0.004822,0.000000
16.910002,0.187675,-256.165802,-0.004876,0.000174,0.004414,0.834822,0.042528,0.044139,-256.165802,0.005489,0.000000
17.310001,0.189537,-256.165802,-0.004842,0.000208,0.005273,0.843103,0.042950,0.052727,-256.165802,0.006157,0.000000
17.710001,0.179482,-256.299225,-0.004825,0.000235,0.005958,0.798374,0.040671,0.059578,-256.299225,0.006825,0.000000
18.110001,0.203316,-256.299225,-0.004799,0.000262,0.006652,0.904394,0.046072,0.066516,-256.299225,0.007493,0.000000
18.510000,0.264755,-256.299225,-0.004773,0.000285,0.007241,1.177690,0.059994,0.072413,-256.299225,0.008160,0.000000
18.910002,0.283005,-256.388214,-0.004747,0.000311,0.007900,1.258868,0.064130,0.079002,-256.388214,0.008820,0.000000
19.310001,0.275932,-256.388214,-0.004708,0.000341,0.008663,1.227408,0.062527,0.086632,-256.388214,0.009487,0.000000
19.710001,0.267365,-256.432678,-0.004691,0.000364,0.009253,1.189297,0.060586,0.092529,-256.432678,0.010155,0.000000
20.110001,0.274811,-256.432678,-0.004669,0.000387,0.009826,1.222420,0.062273,0.098256,-256.432678,0.010823,0.000000
20.510000,0.327690,-256.477173,-0.004644,0.000412,0.010476,1.457639,0.074256,0.104758,-256.477173,0.011491,0.000000
20.910002,0.367531,-256.477173,-0.004618,0.000441,0.011196,1.634859,0.083284,0.111957,-256.477173,0.012158,0.000000
21.310001,0.388382,-256.477173,-0.004575,0.000472,0.011994,1.727609,0.088009,0.119936,-256.477173,0.012826,0.000000
21.710001,0.401047,-256.521637,-0.004557,0.000495,0.012575,1.783945,0.090878,0.125746,-256.521637,0.013494,0.000000
22.110001,0.425247,-256.566132,-0.004540,0.000520,0.013216,1.891594,0.096362,0.132165,-256.566132,0.014153,0.000000
22.510000,0.469193,-256.655090,-0.004518,0.000543,0.013789,2.087073,0.106321,0.137888,-256.655090,0.014821,0.000000
22.910002,0.531380,-256.655090,-0.004484,0.000571,0.014491,2.363695,0.120412,0.144912,-256.655090,0.015489,0.000000
23.310001,0.580154,-256.744049,-0.004441,0.000601,0.015272,2.580656,0.131465,0.152717,-256.744049,0.016156,0.000000
23.710001,0.587608,-256.744049,-0.004424,0.000625,0.015879,2.613812,0.133154,0.158788,-256.744049,0.016824,0.000000
24.110001,0.628197,-256.788544,-0.004402,0.000651,0.016538,2.794358,0.142351,0.165377,-256.788544,0.017492,0.000000
24.510000,0.640480,-256.788544,-0.004381,0.000667,0.016954,2.848998,0.145135,0.169541,-256.788544,0.018160,0.000000
24.910002,0.753685,-256.877502,-0.004350,0.000708,0.017986,3.352558,0.170787,0.179862,-256.877502,0.018827,0.000000
25.310001,0.795761,-256.877502,-0.004324,0.000729,0.018524,3.539722,0.180322,0.185237,-256.877502,0.019487,0.000000
25.710001,0.854225,-256.921967,-0.004307,0.000757,0.019226,3.799783,0.193570,0.192261,-256.921967,0.020154,0.000000
26.110001,0.973007,-256.921967,-0.004255,0.000784,0.019920,4.328152,0.220487,0.199199,-256.921967,0.020822,0.000000
26.510002,0.991631,-256.921967,-0.004247,0.000798,0.020276,4.410993,0.224707,0.202757,-256.921967,0.021489,0.000000
26.910002,1.228828,-256.966461,-0.004208,0.000839,0.021299,5.466102,0.278457,0.212987,-256.966461,0.022158,0.000000
27.310001,1.309631,-257.010925,-0.004195,0.000865,0.021967,5.825531,0.296767,0.219668,-257.010925,0.022825,0.000000
27.710001,1.428795,-257.099884,-0.004165,0.000888,0.022556,6.355597,0.323770,0.225565,-257.099884,0.023493,0.000000
28.110001,1.635460,-257.099884,-0.004135,0.000916,0.023259,7.274889,0.370601,0.232589,-257.099884,0.024161,0.000000
28.510002,1.705841,-257.099884,-0.004113,0.000933,0.023701,7.587960,0.386549,0.237010,-257.099884,0.024820,0.000000
28.910002,2.008209,-257.188873,-0.004066,0.000973,0.024716,8.932961,0.455067,0.247157,-257.188873,0.025487,0.000000
29.310001,2.056618,-257.188873,-0.004053,0.000994,0.025254,9.148293,0.466036,0.252536,-257.188873,0.026156,0.000000
29.710001,2.213753,-257.233337,-0.004036,0.001016,0.025817,9.847264,0.501644,0.258171,-257.233337,0.026823,0.000000
30.110001,2.369034,-257.233337,-0.004023,0.001043,0.026494,10.537989,0.536831,0.264935,-257.233337,0.027491,0.000000
30.510002,2.469574,-257.277832,-0.003997,0.001064,0.027023,10.985213,0.559613,0.270226,-257.277832,0.028158,0.000000
30.910002,2.751465,-257.366791,-0.003941,0.001104,0.028037,12.239127,0.623491,0.280374,-257.366791,0.028827,0.000000
31.310001,2.840088,-257.322296,-0.003936,0.001125,0.028584,12.633342,0.643573,0.285835,-257.322296,0.029494,0.000000
31.710001,2.961853,-257.411255,-0.003893,0.001151,0.029225,13.174980,0.671166,0.292254,-257.411255,0.030153,0.000000
32.110001,3.130539,-257.411255,-0.003876,0.001178,0.029911,13.925333,0.709390,0.299105,-257.411255,0.030821,0.000000
32.510002,3.241875,-257.411255,-0.003846,0.001201,0.030500,14.420579,0.734619,0.305002,-257.411255,0.031489,0.000000
32.910000,3.347260,-257.411255,-0.003833,0.001230,0.031246,14.889354,0.758500,0.312458,-257.411255,0.032156,0.000000
33.310001,3.478706,-257.500214,-0.003794,0.001257,0.031931,15.474059,0.788286,0.319309,-257.500214,0.032825,0.000000
33.710003,3.578125,-257.544708,-0.003777,0.001280,0.032504,15.916295,0.810815,0.325035,-257.544708,0.033492,0.000000
34.110001,3.767662,-257.544708,-0.003747,0.001309,0.033240,16.759398,0.853764,0.332405,-257.544708,0.034160,0.000000
34.510002,3.859642,-257.678162,-0.003721,0.001333,0.033856,17.168545,0.874607,0.338563,-257.678162,0.034827,0.000000
34.910000,3.957573,-257.678162,-0.003686,0.001361,0.034559,17.604164,0.896799,0.345587,-257.678162,0.035496,0.000000
35.310001,4.047318,-257.678162,-0.003665,0.001388,0.035244,18.003366,0.917135,0.352438,-257.678162,0.036154,0.000000
35.710003,4.164246,-257.767120,-0.003648,0.001412,0.035860,18.523489,0.943632,0.358596,-257.767120,0.036822,0.000000
36.110001,4.244675,-257.767120,-0.003617,0.001436,0.036484,18.881256,0.961857,0.364841,-257.767120,0.037490,0.000000
36.510002,4.449104,-257.811584,-0.003600,0.001468,0.037299,19.790604,1.008181,0.372994,-257.811584,0.038158,0.000000
36.910000,4.522835,-257.856079,-0.003570,0.001495,0.037967,20.118574,1.024889,0.379670,-257.856079,0.038825,0.000000
37.310001,4.509056,-257.811584,-0.003540,0.001516,0.038504,20.057283,1.021767,0.385045,-257.811584,0.039493,0.000000
37.710003,4.716843,-257.900543,-0.003505,0.001547,0.039294,20.981564,1.068852,0.392936,-257.900543,0.040161,0.000000
38.110001,4.680351,-257.945038,-0.003492,0.001565,0.039745,20.819242,1.060583,0.397448,-257.945038,0.040829,0.000000
38.510002,4.956276,-257.989502,-0.003466,0.001601,0.040664,22.046616,1.123108,0.406642,-257.989502,0.041488,0.000000
38.910004,5.014366,-257.945038,-0.003441,0.001625,0.041263,22.305016,1.136272,0.412625,-257.945038,0.042156,0.000000
39.310001,5.041176,-257.989502,-0.003436,0.001648,0.041861,22.424271,1.142347,0.418609,-257.989502,0.042823,0.000000
39.710003,5.248962,-258.078491,-0.003385,0.001675,0.042555,23.348551,1.189432,0.425547,-258.078491,0.043491,0.000000
40.110001,5.274284,-258.122955,-0.003363,0.001699,0.043162,23.461189,1.195170,0.431618,-258.122955,0.044159,0.000000
40.510002,5.506271,-258.167450,-0.003333,0.001733,0.044020,24.493118,1.247739,0.440202,-258.167450,0.044827,0.000000
40.910004,5.457863,-258.211914,-0.003307,0.001754,0.044558,24.277786,1.236769,0.445581,-258.211914,0.045494,0.000000
41.310001,5.507759,-258.211914,-0.003285,0.001777,0.045139,24.499737,1.248076,0.451390,-258.211914,0.046162,0.000000
41.710003,5.784805,-258.256409,-0.003255,0.001809,0.045946,25.732100,1.310856,0.459456,-258.256409,0.046821,0.000000
42.110001,5.684265,-258.256409,-0.003247,0.001826,0.046370,25.284874,1.288073,0.463703,-258.256409,0.047489,0.000000
42.510002,6.023499,-258.300873,-0.003203,0.001864,0.047333,26.793859,1.364944,0.473331,-258.300873,0.048157,0.000000
42.910004,6.029831,-258.256409,-0.003195,0.001888,0.047949,26.822027,1.366379,0.479486,-258.256409,0.048825,0.000000
43.310001,6.041374,-258.345367,-0.003165,0.001909,0.048478,26.873375,1.368995,0.484777,-258.345367,0.049492,0.000000
43.710003,6.169472,-258.389832,-0.003134,0.001932,0.049076,27.443180,1.398022,0.490761,-258.389832,0.050160,0.000000
44.110001,6.379860,-258.389832,-0.003104,0.001958,0.049744,28.379034,1.445697,0.497437,-258.389832,0.050828,0.000000
44.510002,6.595833,-258.434326,-0.003083,0.001994,0.050646,29.339729,1.494637,0.506457,-258.434326,0.051496,0.000000
44.910004,6.618919,-258.478821,-0.003044,0.002016,0.051210,29.442425,1.499869,0.512096,-258.478821,0.052155,0.000000
45.310001,6.782021,-258.567780,-0.003035,0.002045,0.051938,30.167934,1.536828,0.519378,-258.567780,0.052822,0.000000
45.710003,6.739944,-258.567780,-0.002997,0.002065,0.052441,29.980770,1.527293,0.524409,-258.567780,0.053490,0.000000
46.110001,7.090347,-258.612244,-0.002966,0.002096,0.053230,31.539440,1.606696,0.532300,-258.612244,0.054158,0.000000
46.510002,7.147690,-258.656738,-0.002958,0.002124,0.053950,31.794512,1.619690,0.539499,-258.656738,0.054826,0.000000
46.910004,7.199448,-258.701202,-0.002910,0.002149,0.054592,32.024742,1.631418,0.545918,-258.701202,0.055494,0.000000
47.310001,7.438889,-258.701202,-0.002893,0.002178,0.055311,33.089828,1.685676,0.553113,-258.701202,0.056161,0.000000
47.710003,7.270203,-258.790161,-0.002863,0.002192,0.055667,32.339478,1.647451,0.556671,-258.790161,0.056829,0.000000
48.110001,7.871208,-258.701202,-0.002833,0.002232,0.056699,35.012882,1.783641,0.566989,-258.701202,0.057497,0.000000
48.510002,7.723007,-258.790161,-0.002798,0.002253,0.057228,34.353653,1.750058,0.572280,-258.790161,0.058156,0.000000
48.910004,7.842911,-258.834656,-0.002772,0.002280,0.057922,34.887009,1.777229,0.579218,-258.834656,0.058824,0.000000
49.310001,7.997070,-258.834656,-0.002777,0.002305,0.058546,35.572746,1.812162,0.585463,-258.834656,0.059491,0.000000
49.710003,8.060745,-258.923615,-0.002738,0.002328,0.059136,35.855984,1.826591,0.591360,-258.923615,0.060159,0.000000
50.110001,8.489723,-258.968109,-0.002716,0.002359,0.059925,37.764175,1.923799,0.599251,-258.968109,0.060827,0.000000
50.510002,8.423813,-258.968109,-0.002682,0.002385,0.060575,37.470989,1.908863,0.605754,-258.968109,0.061495,0.000000
50.910004,8.566803,-259.012573,-0.002647,0.002411,0.061252,38.107044,1.941265,0.612521,-259.012573,0.062163,0.000000
51.310001,8.750008,-259.012573,-0.002630,0.002435,0.061859,38.921978,1.982780,0.618592,-259.012573,0.062830,0.000000
51.710003,8.732506,-259.057068,-0.002600,0.002456,0.062371,38.844128,1.978814,0.623705,-259.057068,0.063489,0.000000
52.110001,9.332024,-259.057068,-0.002574,0.002495,0.063385,41.510914,2.114667,0.633853,-259.057068,0.064157,0.000000
52.510002,9.202438,-259.146027,-0.002548,0.002515,0.063871,40.934490,2.085302,0.638709,-259.146027,0.064825,0.000000
52.910004,9.446716,-259.146027,-0.002531,0.002541,0.064548,42.021091,2.140656,0.645476,-259.146027,0.065493,0.000000
53.310001,9.753181,-259.190491,-0.002496,0.002572,0.065319,43.384319,2.210103,0.653193,-259.190491,0.066160,0.000000
53.710003,9.616150,-259.190491,-0.002475,0.002590,0.065796,42.774773,2.179051,0.657962,-259.190491,0.066828,0.000000
54.110004,10.183640,-259.279449,-0.002449,0.002623,0.066611,45.299091,2.307646,0.666115,-259.279449,0.067496,0.000000
54.510002,10.214180,-259.279449,-0.002419,0.002647,0.067244,45.434940,2.314566,0.672443,-259.279449,0.068164,0.000000
54.910004,10.190720,-259.323944,-0.002397,0.002669,0.067791,45.330585,2.309250,0.677909,-259.323944,0.068823,0.000000
55.310001,10.450638,-259.368439,-0.002371,0.002692,0.068381,46.486759,2.368148,0.683806,-259.368439,0.069491,0.000000
55.710003,10.975677,-259.412903,-0.002345,0.002725,0.069213,48.822250,2.487124,0.692132,-259.412903,0.070158,0.000000
56.110004,11.240433,-259.412903,-0.002328,0.002754,0.069959,49.999943,2.547118,0.699589,-259.412903,0.070826,0.000000
56.510002,11.359596,-259.457397,-0.002294,0.002780,0.070601,50.530006,2.574121,0.706008,-259.457397,0.071494,0.000000
56.910004,11.421783,-259.501862,-0.002268,0.002802,0.071182,50.806629,2.588213,0.711818,-259.501862,0.072162,0.000000
57.310001,11.797134,-259.546356,-0.002259,0.002831,0.071902,52.476276,2.673269,0.719016,-259.546356,0.072829,0.000000
57.710003,12.129288,-259.590820,-0.002216,0.002857,0.072561,53.953766,2.748536,0.725606,-259.590820,0.073497,0.000000
58.110004,12.290527,-259.590820,-0.002195,0.002884,0.073254,54.670998,2.785073,0.732544,-259.590820,0.074156,0.000000
58.510002,12.469269,-259.590820,-0.002169,0.002911,0.073939,55.466076,2.825577,0.739394,-259.590820,0.074824,0.000000
58.910004,12.882973,-259.635315,-0.002130,0.002940,0.074668,57.306324,2.919323,0.746680,-259.635315,0.075492,0.000000
59.310001,13.020378,-259.679779,-0.002104,0.002963,0.075266,57.917534,2.950460,0.752664,-259.679779,0.076160,0.000000
59.710003,13.528664,-259.724274,-0.002100,0.002991,0.075978,60.178501,3.065639,0.759776,-259.724274,0.076827,0.000000
60.110004,13.652290,-259.724274,-0.002087,0.003016,0.076610,60.728420,3.093653,0.766104,-259.724274,0.077495,0.000000
60.510002,13.948326,-259.813232,-0.002052,0.003041,0.077244,62.045254,3.160736,0.772436,-259.813232,0.078163,0.000000
60.910004,14.295380,-259.768768,-0.002026,0.003068,0.077929,63.589024,3.239379,0.779287,-259.768768,0.078831,0.000000
61.310001,14.499809,-259.857727,-0.001996,0.003089,0.078467,64.498375,3.285704,0.784666,-259.857727,0.079498,0.000000
61.710003,15.225197,-259.902191,-0.001970,0.003122,0.079290,67.725060,3.450079,0.792901,-259.902191,0.080158,0.000000
62.110004,15.318657,-259.946686,-0.001949,0.003146,0.079897,68.140793,3.471257,0.798972,-259.946686,0.080825,0.000000
62.510002,15.654915,-259.902191,-0.001932,0.003171,0.080539,69.636536,3.547455,0.805392,-259.902191,0.081493,0.000000
62.910004,15.870888,-260.124603,-0.001910,0.003193,0.081094,70.597237,3.596395,0.810940,-260.124603,0.082161,0.000000
63.310001,16.330765,-260.035645,-0.001871,0.003218,0.081727,72.642868,3.700604,0.817272,-260.035645,0.082829,0.000000
63.710003,17.270264,-260.035645,-0.001845,0.003255,0.082672,76.821968,3.913498,0.826723,-260.035645,0.083496,0.000000
64.110001,17.282921,-260.035645,-0.001807,0.003277,0.083236,76.878273,3.916366,0.832363,-260.035645,0.084164,0.000000
64.510002,17.562950,-260.080109,-0.001798,0.003301,0.083852,78.123901,3.979821,0.838517,-260.080109,0.084832,0.000000
64.910004,18.031021,-260.169098,-0.001772,0.003325,0.084468,80.205986,4.085888,0.844675,-260.169098,0.085491,0.000000
65.310005,18.315140,-260.169098,-0.001768,0.003347,0.085014,81.469810,4.150270,0.850140,-260.169098,0.086159,0.000000
65.710007,19.582695,-260.213562,-0.001725,0.003383,0.085925,87.108177,4.437502,0.859247,-260.213562,0.086827,0.000000
66.110001,19.382362,-260.258057,-0.001703,0.003401,0.086393,86.217056,4.392106,0.863929,-260.258057,0.087494,0.000000
66.510002,20.235840,-260.258057,-0.001677,0.003435,0.087243,90.013512,4.585507,0.872426,-260.258057,0.088162,0.000000
66.910004,20.784714,-260.302521,-0.001656,0.003461,0.087919,92.455025,4.709884,0.879193,-260.302521,0.088830,0.000000
67.310005,20.968292,-260.302521,-0.001638,0.003481,0.088422,93.271622,4.751483,0.884223,-260.302521,0.089498,0.000000
67.710007,22.133072,-260.391479,-0.001613,0.003515,0.089289,98.452820,5.015426,0.892895,-260.391479,0.090165,0.000000
68.110001,22.491669,-260.391479,-0.001582,0.003540,0.089914,100.047935,5.096685,0.899140,-260.391479,0.090824,0.000000
68.510002,22.836113,-260.480438,-0.001574,0.003564,0.090521,101.580101,5.174737,0.905207,-260.480438,0.091492,0.000000
68.910004,23.289291,-260.480438,-0.001552,0.003585,0.091067,103.595940,5.277429,0.910672,-260.480438,0.092160,0.000000
69.310005,24.251503,-260.524933,-0.001526,0.003613,0.091778,107.876076,5.495469,0.917784,-260.524933,0.092828,0.000000
69.710007,25.425591,-260.524933,-0.001509,0.003647,0.092646,113.098679,5.761521,0.926455,-260.524933,0.093496,0.000000
70.110001,25.721626,-260.658386,-0.001487,0.003670,0.093209,114.415504,5.828604,0.932091,-260.658386,0.094163,0.000000
70.510002,26.487602,-260.569397,-0.001462,0.003698,0.093920,117.822739,6.002176,0.939203,-260.569397,0.094831,0.000000
70.910004,26.942635,-260.658386,-0.001431,0.003719,0.094458,119.846825,6.105288,0.944581,-260.658386,0.095499,0.000000
71.310005,27.721642,-260.702850,-0.001414,0.003749,0.095221,123.312019,6.281814,0.952211,-260.702850,0.096158,0.000000
71.710007,29.167564,-260.658386,-0.001397,0.003778,0.095950,129.743805,6.609465,0.959497,-260.658386,0.096826,0.000000
72.110001,29.633774,-260.791809,-0.001371,0.003801,0.096557,131.817612,6.715109,0.965568,-260.791809,0.097493,0.000000
72.510002,30.377777,-260.747345,-0.001341,0.003827,0.097207,135.127106,6.883703,0.972071,-260.747345,0.098161,0.000000
72.910004,31.287483,-260.791809,-0.001332,0.003852,0.097849,139.173676,7.089845,0.978490,-260.791809,0.098829,0.000000
73.310005,32.963898,-260.836304,-0.001311,0.003885,0.098690,146.630737,7.469726,0.986900,-260.836304,0.099497,0.000000
73.710007,33.161255,-260.880768,-0.001289,0.003906,0.099202,147.508621,7.514448,0.992017,-260.880768,0.100164,0.000000
74.110001,33.949944,-260.880768,-0.001272,0.003930,0.099818,151.016891,7.693167,0.998175,-260.880768,0.100832,0.000000
74.510002,35.375015,-260.925262,-0.001250,0.003960,0.100581,157.355927,8.016093,1.005806,-260.925262,0.101500,0.000000
74.910004,35.907135,-260.969727,-0.001233,0.003980,0.101101,159.722916,8.136673,1.011010,-260.969727,0.102159,0.000000
75.310005,37.074150,-260.969727,-0.001224,0.004007,0.101786,164.914062,8.401123,1.017860,-260.969727,0.102827,0.000000
75.710007,38.445595,-260.969727,-0.001194,0.004040,0.102619,171.014542,8.711896,1.026187,-260.969727,0.103495,0.000000
76.110001,39.283058,-261.058716,-0.001190,0.004062,0.103182,174.739777,8.901669,1.031823,-261.058716,0.104162,0.000000
76.510002,40.040466,-261.103180,-0.001151,0.004088,0.103841,178.108887,9.073299,1.038412,-261.103180,0.104830,0.000000
76.910004,41.244347,-261.103180,-0.001155,0.004107,0.104310,183.464020,9.346102,1.043098,-261.103180,0.105498,0.000000
77.310005,43.410812,-261.147675,-0.001147,0.004144,0.105255,193.100937,9.837031,1.052549,-261.147675,0.106166,0.000000
77.710007,44.438560,-261.147675,-0.001125,0.004168,0.105871,197.672592,10.069922,1.058707,-261.147675,0.106833,0.000000
78.110001,45.411568,-261.192139,-0.001095,0.004191,0.106460,202.000748,10.290409,1.064604,-261.192139,0.107493,0.000000
78.510002,46.857491,-261.236633,-0.001091,0.004220,0.107180,208.432526,10.618059,1.071803,-261.236633,0.108160,0.000000
78.910004,47.723259,-261.281097,-0.001078,0.004241,0.107709,212.283661,10.814245,1.077094,-261.281097,0.108828,0.000000
79.310005,49.921371,-261.325592,-0.001061,0.004275,0.108577,222.061356,11.312345,1.085765,-261.325592,0.109496,0.000000
79.710007,51.201584,-261.325592,-0.001035,0.004299,0.109192,227.756027,11.602445,1.091923,-261.325592,0.110164,0.000000
80.110001,52.303062,-261.325592,-0.001030,0.004322,0.109791,232.655640,11.852044,1.097907,-261.325592,0.110831,0.000000
80.510002,54.457985,-261.370056,-0.001022,0.004356,0.110632,242.241211,12.340356,1.106317,-261.370056,0.111499,0.000000
80.910004,54.921585,-261.370056,-0.001005,0.004371,0.111031,244.303406,12.445409,1.110307,-261.370056,0.112167,0.000000
81.310005,57.293602,-261.370056,-0.000970,0.004406,0.111906,254.854675,12.982916,1.119065,-261.370056,0.112826,0.000000
81.710007,58.913422,-261.503510,-0.000966,0.004432,0.112575,262.059998,13.349973,1.125745,-261.503510,0.113493,0.000000
82.110001,60.400307,-261.459045,-0.000970,0.004457,0.113216,268.673981,13.686905,1.132161,-261.459045,0.114162,0.000000
82.510002,62.131088,-261.548004,-0.000940,0.004485,0.113910,276.372894,14.079106,1.139098,-261.548004,0.114829,0.000000
82.910004,62.955894,-261.548004,-0.000927,0.004507,0.114474,280.041809,14.266010,1.144738,-261.548004,0.115497,0.000000
83.310005,65.587456,-261.592468,-0.000914,0.004536,0.115211,291.747589,14.862329,1.152107,-261.592468,0.116165,0.000000
83.710007,65.954247,-261.636963,-0.000901,0.004540,0.115315,293.379150,14.945446,1.153148,-261.636963,0.020233,0.000000
84.110001,65.032249,-261.636963,-0.000897,0.004540,0.115315,289.277893,14.736519,1.153148,-261.636963,294.500488,0.000000
84.510002,66.866554,-261.725922,-0.000892,0.004445,0.112895,297.437286,15.152178,1.128951,-261.725922,294.500488,0.000000
84.910004,66.083824,-261.681427,-0.000880,0.004423,0.112349,293.955536,14.974809,1.123489,-261.681427,294.500488,0.000000
85.310005,65.536430,-261.725922,-0.000867,0.004508,0.114491,291.520599,14.850768,1.144908,-261.725922,294.500488,0.000000
85.710007,65.203529,-261.770386,-0.000871,0.004551,0.115592,290.039795,14.775331,1.155922,-261.770386,294.500488,0.000000
86.110001,65.232216,-261.814880,-0.000875,0.004562,0.115887,290.167389,14.781832,1.158870,-261.814880,294.500488,0.000000
86.510002,65.384132,-261.814880,-0.000884,0.004568,0.116035,290.843140,14.816257,1.160347,-261.814880,294.500488,0.000000
86.910004,65.208382,-261.903839,-0.000871,0.004569,0.116052,290.061371,14.776431,1.160521,-261.903839,294.500488,0.000000
87.310005,65.134651,-261.903839,-0.000871,0.004571,0.116113,289.733398,14.759723,1.161126,-261.903839,294.500488,0.000000
87.710007,65.114540,-261.903839,-0.000867,0.004573,0.116165,289.643951,14.755165,1.161649,-261.903839,294.500488,0.000000
88.110001,65.121239,-261.948334,-0.000880,0.004576,0.116234,289.673737,14.756683,1.162341,-261.948334,294.500488,0.000000
88.510002,65.194221,-262.037292,-0.000867,0.004579,0.116303,289.998383,14.773222,1.163034,-262.037292,294.500488,0.000000
88.910004,65.100395,-261.992798,-0.000875,0.004579,0.116312,289.581024,14.751961,1.163121,-261.992798,294.500488,0.000000
89.310005,65.220299,-262.081757,-0.000854,0.004582,0.116390,290.114380,14.779131,1.163901,-262.081757,294.500488,0.000000
89.710007,65.112312,-262.126251,-0.000871,0.004582,0.116390,289.634033,14.754661,1.163901,-262.126251,294.500488,0.000000
90.110001,65.458977,-262.126251,-0.000871,0.004588,0.116529,291.176056,14.833217,1.165290,-262.126251,294.500488,0.000000
90.510002,65.362160,-262.215210,-0.000862,0.004588,0.116529,290.745422,14.811277,1.165290,-262.215210,294.500488,0.000000
90.910004,65.255669,-262.259674,-0.000849,0.004588,0.116538,290.271698,14.787147,1.165377,-262.259674,294.500488,0.000000
91.310005,65.194221,-262.259674,-0.000849,0.004589,0.116555,289.998383,14.773222,1.165551,-262.259674,294.500488,0.000000
91.710007,65.167046,-262.259674,-0.000867,0.004590,0.116581,289.877502,14.767064,1.165808,-262.259674,294.500488,0.000000
92.110001,65.324181,-262.259674,-0.000867,0.004594,0.116694,290.576477,14.802671,1.166936,-262.259674,294.500488,0.000000
92.510002,65.353600,-262.304169,-0.000858,0.004594,0.116694,290.707336,14.809338,1.166936,-262.304169,294.500488,0.000000
92.910004,65.291039,-262.393127,-0.000845,0.004594,0.116694,290.429047,14.795160,1.166936,-262.393127,294.500488,0.000000
93.310005,65.234444,-262.393127,-0.000854,0.004594,0.116694,290.177307,14.782336,1.166936,-262.393127,294.500488,0.000000
93.710007,65.186775,-262.437622,-0.000845,0.004594,0.116694,289.965271,14.771534,1.166936,-262.437622,294.500488,0.000000
94.110008,65.554680,-262.482086,-0.000849,0.004600,0.116841,291.601776,14.854903,1.168412,-262.482086,294.500488,0.000000
94.510002,65.558784,-262.482086,-0.000849,0.004600,0.116841,291.620026,14.855833,1.168412,-262.482086,294.500488,0.000000
94.910004,65.487282,-262.526581,-0.000845,0.004600,0.116841,291.301971,14.839630,1.168412,-262.526581,294.500488,0.000000
95.310005,65.421379,-262.571045,-0.000841,0.004600,0.116841,291.008820,14.824697,1.168412,-262.571045,294.500488,0.000000
95.710007,65.337959,-262.615540,-0.000849,0.004600,0.116841,290.637756,14.805793,1.168412,-262.615540,294.500488,0.000000
96.110008,65.283974,-262.615540,-0.000841,0.004600,0.116841,290.397614,14.793560,1.168412,-262.615540,294.500488,0.000000
96.510002,65.234444,-262.704498,-0.000841,0.004600,0.116850,290.177307,14.782336,1.168499,-262.704498,294.500488,0.000000
96.910004,65.270561,-262.704498,-0.000845,0.004602,0.116902,290.337952,14.790521,1.169018,-262.704498,294.500488,0.000000
97.310005,65.256416,-262.704498,-0.000862,0.004602,0.116902,290.275024,14.787314,1.169018,-262.704498,294.500488,0.000000
97.710007,65.221779,-262.793457,-0.000832,0.004602,0.116902,290.120972,14.779467,1.169018,-262.793457,294.500488,0.000000
98.110008,65.396049,-262.748993,-0.000845,0.004607,0.117006,290.896149,14.818957,1.170059,-262.748993,294.500488,0.000000
98.510002,65.437752,-262.837952,-0.000854,0.004607,0.117006,291.081665,14.828406,1.170059,-262.837952,294.500488,0.000000
98.910004,65.409828,-262.837952,-0.000854,0.004607,0.117006,290.957458,14.822079,1.170059,-262.837952,294.500488,0.000000
99.310005,65.367378,-262.837952,-0.000841,0.004607,0.117006,290.768616,14.812459,1.170059,-262.837952,294.500488,0.000000
99.710007,65.334984,-262.882416,-0.000841,0.004607,0.117006,290.624512,14.805119,1.170059,-262.882416,294.500488,0.000000
100.110008,65.280617,-262.971375,-0.000845,0.004607,0.117006,290.382690,14.792799,1.170059,-262.971375,294.500488,0.000000
100.510002,65.225883,-262.971375,-0.000849,0.004607,0.117006,290.139221,14.780396,1.170059,-262.971375,294.500488,0.000000
100.910004,65.201668,-262.971375,-0.000854,0.004607,0.117006,290.031494,14.774909,1.170059,-262.971375,294.500488,0.000000
101.310005,65.142845,-263.060333,-0.000845,0.004607,0.117006,289.769836,14.761580,1.170059,-263.060333,294.500488,0.000000
101.710007,65.120872,-263.060333,-0.000836,0.004608,0.117032,289.672119,14.756600,1.170320,-263.060333,294.500488,0.000000
102.110008,65.325676,-263.104828,-0.000836,0.004613,0.117179,290.583130,14.803010,1.171792,-263.104828,294.500488,0.000000
102.510002,65.539040,-263.193787,-0.000836,0.004613,0.117171,291.532196,14.851358,1.171705,-263.193787,294.500488,0.000000
102.910004,65.540154,-263.149292,-0.000836,0.004613,0.117171,291.537170,14.851611,1.171705,-263.149292,294.500488,0.000000
103.310005,65.532707,-263.193787,-0.000845,0.004613,0.117171,291.504028,14.849923,1.171705,-263.193787,294.500488,0.000000
103.710007,65.504036,-263.282745,-0.000836,0.004613,0.117171,291.376495,14.843427,1.171705,-263.282745,294.500488,0.000000
104.110008,65.480202,-263.282745,-0.000841,0.004613,0.117171,291.270477,14.838026,1.171705,-263.282745,294.500488,0.000000
104.510002,65.428825,-263.238281,-0.000854,0.004613,0.117171,291.041962,14.826384,1.171705,-263.238281,294.500488,0.000000
104.910004,65.389351,-263.327240,-0.000836,0.004613,0.117171,290.866364,14.817439,1.171705,-263.327240,294.500488,0.000000
105.310005,65.352486,-263.371704,-0.000858,0.004613,0.117171,290.702362,14.809085,1.171705,-263.371704,294.500488,0.000000
105.710007,65.306313,-263.416199,-0.000841,0.004613,0.117171,290.496979,14.798622,1.171705,-263.416199,294.500488,0.000000
106.110008,65.274666,-263.416199,-0.000836,0.004613,0.117171,290.356201,14.791451,1.171705,-263.416199,294.500488,0.000000
106.510002,65.250450,-263.460663,-0.000845,0.004613,0.117179,290.248505,14.785963,1.171792,-263.460663,294.500488,0.000000
106.910004,65.205391,-263.505157,-0.000828,0.004613,0.117179,290.048065,14.775753,1.171792,-263.505157,294.500488,0.000000
107.310005,65.224388,-263.549622,-0.000836,0.004615,0.117214,290.132568,14.780058,1.172140,-263.549622,294.500488,0.000000
107.710007,65.237801,-263.594116,-0.000845,0.004615,0.117214,290.192230,14.783097,1.172140,-263.594116,294.500488,0.000000
108.110008,65.204277,-263.549622,-0.000849,0.004615,0.117214,290.043121,14.775500,1.172140,-263.549622,294.500488,0.000000
108.510002,65.154762,-263.594116,-0.000836,0.004615,0.117214,289.822845,14.764280,1.172140,-263.594116,294.500488,0.000000
108.910004,65.138374,-263.727570,-0.000841,0.004615,0.117214,289.749969,14.760567,1.172140,-263.727570,294.500488,0.000000
109.310005,65.125710,-263.683075,-0.000841,0.004615,0.117231,289.693634,14.757697,1.172314,-263.683075,294.500488,0.000000
109.710007,65.097404,-263.727570,-0.000849,0.004615,0.117231,289.567719,14.751283,1.172314,-263.727570,294.500488,0.000000
110.110008,65.081764,-263.727570,-0.000841,0.004615,0.117231,289.498138,14.747739,1.172314,-263.727570,294.500488,0.000000
110.510002,65.057198,-263.772034,-0.000832,0.004615,0.117231,289.388855,14.742171,1.172314,-263.772034,294.500488,0.000000
110.910004,65.036339,-263.816528,-0.000841,0.004615,0.117231,289.296082,14.737446,1.172314,-263.816528,294.500488,0.000000
111.310005,65.011024,-263.905487,-0.000828,0.004615,0.117231,289.183472,14.731709,1.172314,-263.905487,294.500488,0.000000
111.710007,64.995003,-263.860992,-0.000836,0.004615,0.117231,289.112213,14.728079,1.172314,-263.860992,294.500488,0.000000
112.110008,64.965218,-263.949951,-0.000828,0.004615,0.117231,288.979706,14.721329,1.172314,-263.949951,294.500488,0.000000
112.510002,64.955162,-263.949951,-0.000828,0.004616,0.117249,288.934998,14.719049,1.172489,-263.949951,294.500488,0.000000
112.910004,64.942497,-264.038940,-0.000832,0.004616,0.117249,288.878662,14.716180,1.172489,-264.038940,294.500488,0.000000
113.310005,64.912712,-264.038940,-0.000845,0.004616,0.117249,288.746155,14.709432,1.172489,-264.038940,294.500488,0.000000
113.710007,64.879951,-264.038940,-0.000845,0.004616,0.117258,288.600433,14.702006,1.172576,-264.038940,294.500488,0.000000
114.110008,64.945854,-264.127899,-0.000845,0.004618,0.117292,288.893585,14.716941,1.172920,-264.127899,294.500488,0.000000
114.510002,64.945488,-264.127899,-0.000836,0.004618,0.117292,288.891968,14.716858,1.172920,-264.127899,294.500488,0.000000
114.910004,64.923134,-264.172363,-0.000841,0.004618,0.117292,288.792511,14.711793,1.172920,-264.172363,294.500488,0.000000
115.310005,64.924629,-264.172363,-0.000841,0.004618,0.117292,288.799164,14.712132,1.172920,-264.172363,294.500488,0.000000
115.710007,64.900047,-264.216858,-0.000828,0.004618,0.117292,288.689819,14.706561,1.172920,-264.216858,294.500488,0.000000
116.110008,64.861702,-264.216858,-0.000836,0.004618,0.117292,288.519257,14.697871,1.172920,-264.216858,294.500488,0.000000
116.510002,64.838982,-264.261322,-0.000828,0.004618,0.117292,288.418182,14.692723,1.172920,-264.261322,294.500488,0.000000
116.910004,64.836372,-264.305817,-0.000828,0.004618,0.117292,288.406586,14.692132,1.172920,-264.305817,294.500488,0.000000
117.310005,64.794670,-264.394775,-0.000836,0.004618,0.117292,288.221100,14.682682,1.172920,-264.394775,294.500488,0.000000
117.710007,64.775673,-264.394775,-0.000832,0.004618,0.117292,288.136597,14.678377,1.172920,-264.394775,294.500488,0.000000
118.110008,64.756691,-264.439240,-0.000845,0.004618,0.117292,288.052155,14.674076,1.172920,-264.439240,294.500488,0.000000
118.510002,64.735085,-264.439240,-0.000828,0.004618,0.117292,287.956024,14.669180,1.172920,-264.439240,294.500488,0.000000
118.910004,66.014931,-264.483734,-0.000828,0.004624,0.117448,293.649078,14.959198,1.174483,-264.483734,294.500488,0.000000
119.310005,65.993340,-264.572693,-0.000832,0.004623,0.117431,293.553040,14.954304,1.174309,-264.572693,294.500488,0.000000
119.710007,65.947533,-264.483734,-0.000819,0.004623,0.117431,293.349274,14.943925,1.174309,-264.483734,294.500488,0.000000
120.110008,65.872322,-264.528229,-0.000819,0.004623,0.117431,293.014709,14.926882,1.174309,-264.528229,294.500488,0.000000
120.510002,65.889076,-264.661652,-0.000823,0.004623,0.117431,293.089264,14.930678,1.174309,-264.661652,294.500488,0.000000
120.910004,65.847374,-264.617187,-0.000828,0.004623,0.117431,292.903748,14.921227,1.174309,-264.617187,294.500488,0.000000
121.310005,65.857430,-264.661652,-0.000828,0.004623,0.117431,292.948486,14.923507,1.174309,-264.661652,294.500488,0.000000
121.710007,65.832848,-264.706146,-0.000828,0.004623,0.117431,292.839142,14.917937,1.174309,-264.706146,294.500488,0.000000
122.110008,65.776985,-264.706146,-0.000819,0.004623,0.117431,292.590637,14.905278,1.174309,-264.706146,294.500488,0.000000
122.510002,65.770287,-264.750610,-0.000819,0.004623,0.117431,292.560852,14.903760,1.174309,-264.750610,294.500488,0.000000
122.910004,65.741249,-264.750610,-0.000823,0.004623,0.117431,292.431671,14.897180,1.174309,-264.750610,294.500488,0.000000
123.310005,65.683525,-264.706146,-0.000823,0.004623,0.117431,292.174927,14.884100,1.174309,-264.706146,294.500488,0.000000
123.710007,65.661552,-264.884064,-0.000815,0.004623,0.117431,292.077179,14.879121,1.174309,-264.884064,294.500488,0.000000
124.110008,65.638466,-264.839569,-0.000815,0.004623,0.117431,291.974487,14.873889,1.174309,-264.839569,294.500488,0.000000
124.510002,65.610542,-264.928558,-0.000823,0.004623,0.117431,291.850281,14.867561,1.174309,-264.928558,294.500488,0.000000
124.910004,65.599739,-264.928558,-0.000815,0.004623,0.117431,291.802216,14.865113,1.174309,-264.928558,294.500488,0.000000
125.310005,65.575157,-264.973022,-0.000828,0.004623,0.117431,291.692871,14.859543,1.174309,-264.973022,294.500488,0.000000
125.710007,65.555061,-265.061981,-0.000823,0.004623,0.117431,291.603485,14.854989,1.174309,-265.061981,294.500488,0.000000
126.110008,65.542030,-265.106476,-0.000823,0.004623,0.117431,291.545502,14.852036,1.174309,-265.106476,294.500488,0.000000
126.510010,65.532341,-265.106476,-0.000819,0.004623,0.117431,291.502411,14.849841,1.174309,-265.106476,294.500488,0.000000
126.910004,65.511482,-265.150940,-0.000823,0.004623,0.117431,291.409637,14.845114,1.174309,-265.150940,294.500488,0.000000
127.310005,65.485802,-265.150940,-0.000832,0.004623,0.117431,291.295380,14.839295,1.174309,-265.150940,294.500488,0.000000
127.710007,65.459724,-265.150940,-0.000823,0.004623,0.117431,291.179382,14.833385,1.174309,-265.150940,294.500488,0.000000
128.110001,65.434410,-265.195435,-0.000828,0.004623,0.117431,291.066803,14.827649,1.174309,-265.195435,294.500488,0.000000
128.510010,65.393074,-265.239899,-0.000823,0.004623,0.117431,290.882935,14.818282,1.174309,-265.239899,294.500488,0.000000
128.910004,65.375938,-265.239899,-0.000815,0.004623,0.117431,290.806702,14.814400,1.174309,-265.239899,294.500488,0.000000
129.310013,65.371849,-265.284393,-0.000815,0.004623,0.117431,290.788513,14.813473,1.174309,-265.284393,294.500488,0.000000
129.710007,65.333488,-265.328888,-0.000815,0.004623,0.117431,290.617859,14.804780,1.174309,-265.328888,294.500488,0.000000
130.110001,65.313759,-265.328888,-0.000815,0.004623,0.117431,290.530121,14.800309,1.174309,-265.328888,294.500488,0.000000
130.510010,65.309669,-265.373352,-0.000823,0.004623,0.117431,290.511932,14.799383,1.174309,-265.373352,294.500488,0.000000
130.910004,65.288445,-265.417847,-0.000823,0.004623,0.117431,290.417511,14.794573,1.174309,-265.417847,294.500488,0.000000
131.310013,65.263481,-265.417847,-0.000819,0.004623,0.117431,290.306458,14.788917,1.174309,-265.417847,294.500488,0.000000
131.710007,65.271309,-265.462311,-0.000819,0.004623,0.117431,290.341278,14.790690,1.174309,-265.462311,294.500488,0.000000
132.110001,65.253441,-265.462311,-0.000819,0.004623,0.117431,290.261810,14.786641,1.174309,-265.462311,294.500488,0.000000
132.510010,65.230354,-265.595764,-0.000819,0.004623,0.117431,290.159119,14.781409,1.174309,-265.595764,294.500488,0.000000
132.910004,65.210243,-265.595764,-0.000828,0.004623,0.117431,290.069641,14.776852,1.174309,-265.595764,294.500488,0.000000
133.310013,65.197945,-265.595764,-0.000819,0.004623,0.117431,290.014954,14.774065,1.174309,-265.595764,294.500488,0.000000
133.710007,65.165184,-265.640228,-0.000815,0.004624,0.117440,289.869202,14.766642,1.174396,-265.640228,294.500488,0.000000
134.110001,65.152153,-265.684723,-0.000823,0.004624,0.117440,289.811249,14.763689,1.174396,-265.684723,294.500488,0.000000
134.510010,65.143959,-265.729187,-0.000823,0.004624,0.117440,289.774811,14.761832,1.174396,-265.729187,294.500488,0.000000
134.910004,65.130928,-265.773682,-0.000811,0.004624,0.117440,289.716827,14.758880,1.174396,-265.773682,294.500488,0.000000
135.310013,65.104485,-265.818176,-0.000832,0.004624,0.117440,289.599213,14.752887,1.174396,-265.818176,294.500488,0.000000
135.710007,65.099648,-265.818176,-0.000823,0.004624,0.117448,289.577698,14.751791,1.174483,-265.818176,294.500488,0.000000
136.110001,65.092949,-265.862640,-0.000828,0.004624,0.117448,289.547913,14.750273,1.174483,-265.862640,294.500488,0.000000
136.510010,65.092201,-265.862640,-0.000819,0.004624,0.117448,289.544586,14.750103,1.174483,-265.862640,294.500488,0.000000
136.910004,65.052727,-265.907135,-0.000815,0.004624,0.117448,289.368988,14.741158,1.174483,-265.907135,294.500488,0.000000
137.310013,65.048256,-265.951599,-0.000832,0.004624,0.117448,289.349091,14.740146,1.174483,-265.951599,294.500488,0.000000
137.710007,65.029259,-265.996094,-0.000811,0.004624,0.117448,289.264587,14.735841,1.174483,-265.996094,294.500488,0.000000
138.110001,65.019218,-266.129517,-0.000819,0.004624,0.117448,289.219940,14.733565,1.174483,-266.129517,294.500488,0.000000
138.510010,65.011024,-266.040558,-0.000823,0.004624,0.117448,289.183472,14.731709,1.174483,-266.040558,294.500488,0.000000
138.910004,64.997612,-266.040558,-0.000832,0.004624,0.117448,289.123810,14.728669,1.174483,-266.040558,294.500488,0.000000
139.310013,64.989418,-266.129517,-0.000832,0.004624,0.117448,289.087372,14.726813,1.174483,-266.129517,294.500488,0.000000
139.710007,64.969688,-266.174011,-0.000832,0.004624,0.117448,288.999603,14.722342,1.174483,-266.174011,294.500488,0.000000
140.110001,64.971550,-266.129517,-0.000806,0.004624,0.117448,289.007874,14.722764,1.174483,-266.129517,294.500488,0.000000
140.510010,66.411888,-266.262970,-0.000815,0.004628,0.117544,295.414825,15.049149,1.175437,-266.262970,294.500488,0.000000
140.910004,66.386192,-266.262970,-0.000828,0.004628,0.117544,295.300537,15.043326,1.175437,-266.262970,294.500488,0.000000
141.310013,66.371666,-266.262970,-0.000815,0.004628,0.117544,295.235901,15.040034,1.175437,-266.262970,294.500488,0.000000
141.710007,66.350822,-266.262970,-0.000811,0.004628,0.117544,295.143188,15.035312,1.175437,-266.262970,294.500488,0.000000
142.110001,66.350441,-266.351929,-0.000811,0.004628,0.117544,295.141510,15.035225,1.175437,-266.351929,294.500488,0.000000
142.510010,66.326607,-266.351929,-0.000823,0.004628,0.117544,295.035492,15.029824,1.175437,-266.351929,294.500488,0.000000
142.910004,66.297935,-266.396423,-0.000819,0.004628,0.117544,294.907959,15.023327,1.175437,-266.396423,294.500488,0.000000
143.310013,66.296822,-266.351929,-0.000806,0.004628,0.117544,294.902985,15.023074,1.175437,-266.351929,294.500488,0.000000
143.710007,66.284157,-266.396423,-0.000823,0.004628,0.117544,294.846649,15.020205,1.175437,-266.396423,294.500488,0.000000
144.110001,66.269646,-266.529846,-0.000815,0.004628,0.117544,294.782104,15.016916,1.175437,-266.529846,1681.640991,0.000000
144.510010,66.137077,-266.529846,-0.000832,0.004625,0.117466,294.192413,14.986876,1.174657,-266.529846,0.117249,0.000000
144.910004,66.162392,-266.529846,-0.000806,0.004602,0.116902,294.305023,14.992613,1.169018,-266.529846,0.116581,0.000000
145.310013,66.107658,-266.574341,-0.000802,0.004577,0.116252,294.061554,14.980209,1.162515,-266.574341,0.115913,0.000000
145.710007,66.093880,-266.663300,-0.000802,0.004560,0.115818,294.000275,14.977087,1.158178,-266.663300,0.115246,0.000000
146.110001,66.057762,-266.618835,-0.000806,0.004528,0.115011,293.839600,14.968904,1.150112,-266.618835,0.114578,0.000000
146.510010,66.023125,-266.707794,-0.000789,0.004505,0.114430,293.685516,14.961054,1.144302,-266.707794,0.113910,0.000000
146.910004,66.018288,-266.707794,-0.000793,0.004478,0.113736,293.664001,14.959958,1.137365,-266.707794,0.113242,0.000000
147.310013,65.939720,-266.707794,-0.000802,0.004448,0.112990,293.314514,14.942155,1.129905,-266.707794,0.112575,0.000000
147.710007,65.861153,-266.841217,-0.000802,0.004428,0.112462,292.965027,14.924351,1.124617,-266.841217,0.111915,0.000000
148.110001,65.393074,-266.796753,-0.000802,0.004402,0.111811,290.882935,14.818282,1.118111,-266.796753,0.111248,0.000000
148.510010,64.672905,-266.841217,-0.000798,0.004379,0.111239,287.679443,14.655089,1.112388,-266.841217,0.110580,0.000000
148.910004,63.403862,-266.841217,-0.000793,0.004351,0.110528,282.034454,14.367520,1.105276,-266.841217,0.109912,0.000000
149.310013,61.979538,-266.885712,-0.000772,0.004327,0.109904,275.698761,14.044765,1.099035,-266.885712,0.109244,0.000000
149.710007,60.540688,-266.974670,-0.000767,0.004304,0.109322,269.298431,13.718716,1.093222,-266.974670,0.108577,0.000000
150.110001,58.936508,-266.930176,-0.000780,0.004282,0.108759,262.162689,13.355204,1.087586,-266.930176,0.107909,0.000000
150.510010,56.975594,-266.974670,-0.000785,0.004257,0.108125,253.440094,12.910854,1.081254,-266.974670,0.107241,0.000000
150.910004,54.541397,-267.019135,-0.000767,0.004231,0.107458,242.612244,12.359257,1.074577,-267.019135,0.106582,0.000000
151.310013,52.535049,-267.019135,-0.000789,0.004209,0.106903,233.687576,11.904613,1.069028,-267.019135,0.105914,0.000000
151.710007,50.075157,-267.108124,-0.000780,0.004187,0.106348,222.745422,11.347193,1.063476,-267.108124,0.105246,0.000000
152.110001,46.920792,-267.152588,-0.000772,0.004154,0.105524,208.714111,10.632403,1.055240,-267.152588,0.104579,0.000000
152.510010,44.126511,-267.152588,-0.000767,0.004130,0.104899,196.284515,9.999210,1.048995,-267.152588,0.103911,0.000000
152.910004,41.085716,-267.152588,-0.000785,0.004100,0.104145,182.758392,9.310156,1.041448,-267.152588,0.103243,0.000000
153.310013,38.879410,-267.197083,-0.000780,0.004080,0.103633,172.944260,8.810200,1.036335,-267.197083,0.102575,0.000000
153.710007,36.266846,-267.197083,-0.000772,0.004060,0.103122,161.322983,8.218184,1.031217,-267.197083,0.101908,0.000000
154.110001,32.513329,-267.286041,-0.000780,0.004024,0.102220,144.626511,7.367626,1.022198,-267.286041,0.101249,0.000000
154.510010,29.943214,-267.286041,-0.000772,0.004000,0.101604,133.194077,6.785230,1.016040,-267.286041,0.100581,0.000000
154.910004,26.694641,-267.375000,-0.000776,0.003969,0.100806,118.743690,6.049092,1.008061,-267.375000,0.099913,0.000000
155.310013,24.136436,-267.330505,-0.000767,0.003946,0.100225,107.364235,5.469395,1.002252,-267.330505,0.099245,0.000000
155.710007,21.562973,-267.375000,-0.000772,0.003924,0.099679,95.916893,4.886240,0.996786,-267.375000,0.098577,0.000000
156.110001,18.308807,-267.419464,-0.000772,0.003894,0.098898,81.441643,4.148835,0.988982,-267.419464,0.097910,0.000000
156.510010,15.832161,-267.463959,-0.000772,0.003872,0.098352,70.424973,3.587619,0.983520,-267.463959,0.097242,0.000000
156.910004,12.550072,-267.463959,-0.000776,0.003842,0.097580,55.825508,2.843887,0.975799,-267.463959,0.096574,0.000000
157.310013,10.995789,-267.508453,-0.000767,0.003824,0.097129,48.911709,2.491681,0.971291,-267.508453,0.095906,0.000000
157.710007,7.341324,-267.463959,-0.000767,0.003788,0.096227,32.655838,1.663568,0.962272,-267.463959,0.095247,0.000000
158.110001,4.516510,-267.597412,-0.000776,0.003767,0.095689,20.090441,1.023456,0.956893,-267.597412,0.094580,0.000000
158.510010,1.598221,-267.641876,-0.000780,0.003735,0.094866,7.109241,0.362162,0.948657,-267.641876,0.093912,0.000000
158.910004,-0.428970,-267.597412,-0.000785,0.003716,0.094389,-1.908155,-0.097206,0.943888,-267.597412,0.093244,0.000000
159.310013,-0.150436,-267.686371,-0.000789,0.003686,0.093634,-0.669175,-0.034089,0.936341,-267.686371,0.092576,0.000000
159.710007,0.012291,-267.686371,-0.000789,0.003658,0.092914,0.054673,0.002785,0.929143,-267.686371,0.091908,0.000000
160.110001,0.004097,-267.730835,-0.000841,0.003630,0.092203,0.018224,0.000928,0.922031,-267.730835,0.091241,0.000000
160.510010,0.001122,-267.775330,-0.000888,0.003598,0.091388,0.004989,0.000254,0.913882,-267.775330,0.090573,0.000000
160.910004,0.001122,-267.819794,-0.000927,0.003580,0.090920,0.004989,0.000254,0.909196,-267.819794,0.089914,0.000000
161.310013,0.001862,-267.819794,-0.000957,0.003558,0.090373,0.008281,0.000422,0.903735,-267.819794,0.089246,0.000000
161.710007,-0.000740,-267.864288,-0.001005,0.003524,0.089515,-0.003292,-0.000168,0.895150,-267.864288,0.088578,0.000000
162.110001,0.015266,-267.864288,-0.001035,0.003499,0.088882,0.067908,0.003459,0.888818,-267.864288,0.087911,0.000000
162.510010,0.016014,-267.953247,-0.001078,0.003470,0.088136,0.071234,0.003629,0.881358,-267.953247,0.087243,0.000000
162.910004,-0.023834,-267.953247,-0.001112,0.003449,0.087598,-0.106020,-0.005401,0.875984,-267.953247,0.086575,0.000000
163.310013,-0.032768,-268.042206,-0.001130,0.003421,0.086896,-0.145760,-0.007425,0.868959,-268.042206,0.085907,0.000000
163.710007,0.001862,-268.042206,-0.001160,0.003390,0.086107,0.008281,0.000422,0.861067,-268.042206,0.085240,0.000000
164.110001,0.002235,-268.086700,-0.001199,0.003367,0.085526,0.009944,0.000507,0.855258,-268.086700,0.084580,0.000000
164.510010,0.003349,-268.086700,-0.001233,0.003334,0.084693,0.014898,0.000759,0.846931,-268.086700,0.083913,0.000000
164.910004,0.010056,-268.086700,-0.001263,0.003314,0.084181,0.044729,0.002279,0.841814,-268.086700,0.083245,0.000000
165.300003,0.037987,-268.086700,-0.001272,0.003298,0.083765,0.168974,0.008608,0.837650,-268.086700,0.083670,0.000000