File: Data/compression 24/AutoHeating-12-24-reverse-1-2_09202024_165247.csv
Time (sec),S:Load (lbs),S:HL1 (DIM),S:LVDT (in),S:Position (in),Ch:Position (mm),Ch:Load (N),Ch:Stress (MPa),Ch:Strain (mm/mm),Ch:HL1 (DIM),Set Point (),Cycles ()
0.110000,0.005211,-221.604095,-0.009136,-0.004475,-0.113659,0.023179,0.001181,-1.136585,-221.604095,-0.113650,0.000000
0.480000,0.009682,-221.604095,-0.009127,-0.004433,-0.112601,0.043066,0.002194,-1.126006,-221.604095,-0.112071,0.000000
0.850000,0.020851,-221.648575,-0.009041,-0.004224,-0.107285,0.092750,0.004725,-1.072847,-221.648575,-0.105897,0.000000
1.220000,0.037987,-221.648575,-0.008791,-0.003979,-0.101058,0.168974,0.008608,-1.010578,-221.648575,-0.099740,0.000000
1.590000,0.027184,-221.782028,-0.008554,-0.003739,-0.094970,0.120918,0.006160,-0.949698,-221.782028,-0.093582,0.000000
1.960000,0.016754,-221.782028,-0.008291,-0.003492,-0.088700,0.074526,0.003797,-0.886998,-221.782028,-0.087408,0.000000
2.330000,0.002235,-221.826508,-0.008041,-0.003256,-0.082708,0.009944,0.000507,-0.827075,-221.826508,-0.081250,0.000000
2.700000,-0.010056,-221.782028,-0.007778,-0.003003,-0.076272,-0.044729,-0.002279,-0.762724,-221.782028,-0.075093,0.000000
3.070000,-0.035744,-221.870987,-0.007549,-0.002760,-0.070115,-0.158996,-0.008100,-0.701152,-221.870987,-0.068918,0.000000
3.440000,0.018250,-221.870987,-0.007299,-0.002521,-0.064036,0.081178,0.004135,-0.640359,-221.870987,-0.062761,0.000000
3.810000,0.042450,-221.959946,-0.007036,-0.002282,-0.057974,0.188827,0.009619,-0.579740,-221.959946,-0.056586,0.000000
4.180000,0.052132,-222.004425,-0.006786,-0.002038,-0.051765,0.231893,0.011813,-0.517649,-222.004425,-0.050429,0.000000
4.550000,0.026810,-222.048904,-0.006541,-0.001796,-0.045625,0.119255,0.006075,-0.456246,-222.048904,-0.044272,0.000000
4.920000,0.010429,-222.048904,-0.006282,-0.001546,-0.039259,0.046392,0.002363,-0.392592,-222.048904,-0.038097,0.000000
5.290000,0.028305,-222.048904,-0.006066,-0.001310,-0.033276,0.125907,0.006414,-0.332757,-222.048904,-0.031940,0.000000
5.660000,0.031281,-222.093384,-0.005799,-0.001065,-0.027049,0.139143,0.007088,-0.270488,-222.093384,-0.025765,0.000000
6.030000,0.038727,-222.226837,-0.005532,-0.000819,-0.020805,0.172265,0.008776,-0.208048,-222.226837,-0.019608,0.000000
6.400000,0.053619,-222.226837,-0.005299,-0.000585,-0.014864,0.238511,0.012150,-0.148644,-222.226837,-0.013451,0.000000
6.770000,0.016014,-222.226837,-0.005044,-0.000343,-0.008716,0.071234,0.003629,-0.087159,-222.226837,-0.007276,0.000000
7.140000,-0.006699,-222.271317,-0.004799,-0.000089,-0.002263,-0.029797,-0.001518,-0.022634,-222.271317,-0.001119,0.000000
7.510000,0.064423,-222.315796,-0.004549,0.000155,0.003928,0.286566,0.014598,0.039283,-222.315796,0.005056,0.000000
7.880001,0.062187,-222.360275,-0.004510,-0.000000,-0.000009,0.276622,0.014092,-0.000087,-222.360275,0.000217,0.000000
8.250000,0.119904,-222.315796,-0.004493,-0.000000,-0.000009,0.533358,0.027171,-0.000087,-222.315796,0.000477,0.000000
8.620001,0.133308,-222.404755,-0.004501,0.000010,0.000252,0.592985,0.030208,0.002517,-222.404755,0.001093,0.000000
8.990001,0.212250,-222.404755,-0.004493,0.000027,0.000694,0.944134,0.048096,0.006938,-222.404755,0.001717,0.000000
9.360001,0.297157,-222.449234,-0.004475,0.000054,0.001361,1.321822,0.067337,0.013614,-222.449234,0.002333,0.000000
9.730000,0.397324,-222.449234,-0.004445,0.000072,0.001839,1.767384,0.090035,0.018387,-222.449234,0.002948,0.000000
10.100000,0.489670,-222.493713,-0.004406,0.000102,0.002602,2.178160,0.110961,0.026017,-222.493713,0.003564,0.000000
10.470000,0.604736,-222.493713,-0.004376,0.000124,0.003157,2.690001,0.137035,0.031566,-222.493713,0.004180,0.000000
10.840000,0.779747,-222.582672,-0.004363,0.000151,0.003842,3.468488,0.176693,0.038417,-222.582672,0.004796,0.000000
11.210001,0.898163,-222.627167,-0.004359,0.000171,0.004336,3.995228,0.203527,0.043360,-222.627167,0.005412,0.000000
11.580001,1.091797,-222.627167,-0.004333,0.000200,0.005091,4.856555,0.247405,0.050907,-222.627167,0.006027,0.000000
11.950001,1.161057,-222.760605,-0.004307,0.000216,0.005490,5.164638,0.263099,0.054896,-222.760605,0.006652,0.000000
12.320001,1.299210,-222.716125,-0.004290,0.000245,0.006218,5.779173,0.294405,0.062182,-222.716125,0.007267,0.000000
12.690001,1.496941,-222.760605,-0.004243,0.000271,0.006877,6.658724,0.339212,0.068772,-222.760605,0.007883,0.000000
13.060000,1.645515,-222.805084,-0.004230,0.000291,0.007398,7.319618,0.372879,0.073976,-222.805084,0.008499,0.000000
13.430000,1.832817,-222.894043,-0.004212,0.000320,0.008117,8.152778,0.415322,0.081171,-222.894043,0.009114,0.000000
13.800000,1.872292,-222.894043,-0.004182,0.000335,0.008508,8.328369,0.424267,0.085077,-222.894043,0.009730,0.000000
14.170001,2.081566,-222.849564,-0.004148,0.000369,0.009384,9.259268,0.471690,0.093835,-222.849564,0.010346,0.000000
14.540001,2.048050,-222.938522,-0.004143,0.000384,0.009756,9.110181,0.464095,0.097563,-222.938522,0.010962,0.000000
14.910001,2.315414,-222.938522,-0.004105,0.000415,0.010545,10.299478,0.524680,0.105455,-222.938522,0.011578,0.000000
15.280001,2.427498,-223.071976,-0.004092,0.000437,0.011100,10.798050,0.550079,0.111003,-223.071976,0.012202,0.000000
15.650001,2.576447,-223.071976,-0.004061,0.000466,0.011846,11.460607,0.583831,0.118463,-223.071976,0.012818,0.000000
16.020000,2.512398,-223.071976,-0.004040,0.000484,0.012288,11.175703,0.569317,0.122884,-223.071976,0.013433,0.000000
16.390001,2.761887,-223.116455,-0.004014,0.000515,0.013069,12.285485,0.625852,0.130692,-223.116455,0.014049,0.000000
16.760000,2.791306,-223.160934,-0.003992,0.000533,0.013529,12.416348,0.632519,0.135287,-223.160934,0.014665,0.000000
17.130001,2.857590,-223.205414,-0.003971,0.000555,0.014092,12.711194,0.647539,0.140923,-223.205414,0.015280,0.000000
17.500000,2.964455,-223.249893,-0.003932,0.000582,0.014786,13.186553,0.671755,0.147861,-223.249893,0.015896,0.000000
17.870001,3.030739,-223.249893,-0.003923,0.000607,0.015419,13.481400,0.686775,0.154193,-223.249893,0.016512,0.000000
18.240002,3.104095,-223.294373,-0.003885,0.000628,0.015948,13.807706,0.703398,0.159484,-223.294373,0.017128,0.000000
18.610001,3.254539,-223.294373,-0.003872,0.000658,0.016703,14.476914,0.737489,0.167027,-223.294373,0.017752,0.000000
18.980001,3.284325,-223.383331,-0.003833,0.000682,0.017319,14.609406,0.744239,0.173185,-223.383331,0.018368,0.000000
19.350000,3.430672,-223.427811,-0.003807,0.000712,0.018082,15.260390,0.777401,0.180816,-223.427811,0.018984,0.000000
19.720001,3.329758,-223.427811,-0.003786,0.000733,0.018619,14.811502,0.754534,0.186194,-223.427811,0.019599,0.000000
20.090000,3.384865,-223.472305,-0.003751,0.000751,0.019088,15.056631,0.767021,0.190876,-223.472305,0.020215,0.000000
20.460001,3.483917,-223.472305,-0.003738,0.000778,0.019773,15.497238,0.789467,0.197727,-223.472305,0.020831,0.000000
20.830002,3.587807,-223.516785,-0.003717,0.000803,0.020397,15.959361,0.813009,0.203972,-223.516785,0.021446,0.000000
21.200001,3.587807,-223.605743,-0.003695,0.000825,0.020952,15.959361,0.813009,0.209520,-223.605743,0.022062,0.000000
21.570002,3.723724,-223.650223,-0.003673,0.000853,0.021655,16.563953,0.843808,0.216545,-223.650223,0.022678,0.000000
21.940001,3.745697,-223.694702,-0.003626,0.000872,0.022140,16.661692,0.848787,0.221401,-223.694702,0.023302,0.000000
22.310001,3.830597,-223.650223,-0.003604,0.000898,0.022799,17.039347,0.868026,0.227995,-223.650223,0.023918,0.000000
22.680000,3.852936,-223.650223,-0.003591,0.000921,0.023389,17.138714,0.873088,0.233891,-223.650223,0.024534,0.000000
23.050001,4.063705,-223.739182,-0.003561,0.000954,0.024222,18.076265,0.920849,0.242218,-223.739182,0.025149,0.000000
23.420002,4.068916,-223.828140,-0.003540,0.000980,0.024881,18.099443,0.922030,0.248808,-223.828140,0.025765,0.000000
23.790001,4.038750,-223.783661,-0.003505,0.001000,0.025410,17.965256,0.915194,0.254099,-223.783661,0.026381,0.000000
24.160002,4.182487,-223.783661,-0.003479,0.001028,0.026112,18.604633,0.947765,0.261124,-223.783661,0.026997,0.000000
24.530001,4.217865,-223.872620,-0.003458,0.001050,0.026676,18.762001,0.955782,0.266759,-223.872620,0.027612,0.000000
24.900002,4.328087,-223.961594,-0.003432,0.001075,0.027300,19.252293,0.980758,0.273004,-223.961594,0.028228,0.000000
25.270000,4.352661,-224.006073,-0.003415,0.001098,0.027899,19.361603,0.986327,0.278988,-224.006073,0.028853,0.000000
25.640001,4.367561,-224.006073,-0.003389,0.001123,0.028514,19.427883,0.989704,0.285143,-224.006073,0.029468,0.000000
26.010002,4.474426,-224.050552,-0.003354,0.001146,0.029113,19.903242,1.013919,0.291127,-224.050552,0.030084,0.000000
26.380001,4.484108,-224.006073,-0.003333,0.001164,0.029564,19.946308,1.016113,0.295638,-224.006073,0.030700,0.000000
26.750002,4.562683,-224.095032,-0.003316,0.001186,0.030119,20.295828,1.033919,0.301187,-224.095032,0.031315,0.000000
27.120001,4.826691,-224.139511,-0.003281,0.001221,0.031012,21.470192,1.093744,0.310119,-224.139511,0.031931,0.000000
27.490002,4.714233,-224.228470,-0.003247,0.001240,0.031498,20.969957,1.068261,0.314975,-224.228470,0.032547,0.000000
27.860001,4.739182,-224.228470,-0.003238,0.001263,0.032087,21.080933,1.073914,0.320872,-224.228470,0.033163,0.000000
28.230001,4.919411,-224.228470,-0.003199,0.001288,0.032720,21.882631,1.114754,0.327204,-224.228470,0.033778,0.000000
28.600002,4.880318,-224.228470,-0.003212,0.001306,0.033180,21.708736,1.105896,0.331799,-224.228470,0.034403,0.000000
28.970001,5.204651,-224.317429,-0.003169,0.001338,0.033995,23.151443,1.179391,0.339952,-224.317429,0.035019,0.000000
29.340002,5.229973,-224.361923,-0.003147,0.001367,0.034715,23.264082,1.185129,0.347151,-224.361923,0.035634,0.000000
29.710001,5.212471,-224.450882,-0.003109,0.001387,0.035235,23.186230,1.181163,0.352355,-224.450882,0.036250,0.000000
30.080002,5.342430,-224.361923,-0.003091,0.001414,0.035903,23.764317,1.210612,0.359031,-224.361923,0.036866,0.000000
30.450001,5.418022,-224.361923,-0.003061,0.001431,0.036346,24.100567,1.227741,0.363456,-224.361923,0.037481,0.000000
30.820002,5.662300,-224.495361,-0.003035,0.001462,0.037135,25.187168,1.283095,0.371347,-224.495361,0.038097,0.000000
31.190001,5.669373,-224.539841,-0.003014,0.001482,0.037646,25.218628,1.284698,0.376465,-224.539841,0.038713,0.000000
31.560001,5.822792,-224.584320,-0.002992,0.001511,0.038392,25.901073,1.319464,0.383921,-224.584320,0.039329,0.000000
31.930002,5.916252,-224.584320,-0.002962,0.001534,0.038973,26.316803,1.340642,0.389731,-224.584320,0.039953,0.000000
32.300003,5.849602,-224.539841,-0.002945,0.001551,0.039407,26.020329,1.325539,0.394068,-224.539841,0.040569,0.000000
32.670002,6.007858,-224.628799,-0.002932,0.001576,0.040023,26.724289,1.361400,0.400226,-224.628799,0.041185,0.000000
33.040001,6.261818,-224.762253,-0.002897,0.001608,0.040838,27.853958,1.418948,0.408375,-224.762253,0.041800,0.000000
33.410000,6.279320,-224.717758,-0.002884,0.001628,0.041358,27.931808,1.422914,0.413579,-224.717758,0.042416,0.000000
33.780003,6.559341,-224.717758,-0.002846,0.001658,0.042104,29.177408,1.486368,0.421039,-224.717758,0.043032,0.000000
34.150002,6.462524,-224.762253,-0.002824,0.001677,0.042590,28.746744,1.464429,0.425895,-224.762253,0.043647,0.000000
34.520000,6.789841,-224.806732,-0.002802,0.001706,0.043326,30.202721,1.538600,0.433264,-224.806732,0.044263,0.000000
34.890003,6.866180,-224.851212,-0.002777,0.001730,0.043934,30.542295,1.555899,0.439335,-224.851212,0.044888,0.000000
35.260002,6.605888,-224.895691,-0.002759,0.001744,0.044289,29.384459,1.496916,0.442893,-224.895691,0.045504,0.000000
35.630001,6.981613,-224.940170,-0.002716,0.001772,0.045018,31.055767,1.582056,0.450175,-224.940170,0.046119,0.000000
36.000000,7.274666,-224.940170,-0.002695,0.001803,0.045790,32.359329,1.648463,0.457897,-224.940170,0.046735,0.000000
36.370003,7.243019,-225.073608,-0.002669,0.001820,0.046240,32.218559,1.641292,0.462404,-225.073608,0.047351,0.000000
36.740002,7.370369,-225.073608,-0.002673,0.001841,0.046761,32.785038,1.670150,0.467609,-225.073608,0.047966,0.000000
37.110001,7.543152,-225.073608,-0.002621,0.001870,0.047506,33.553616,1.709303,0.475065,-225.073608,0.048582,0.000000
37.480003,7.593796,-225.073608,-0.002604,0.001889,0.047984,33.778893,1.720779,0.479838,-225.073608,0.049198,0.000000
37.850002,7.840675,-225.118088,-0.002587,0.001919,0.048738,34.877068,1.776722,0.487381,-225.118088,0.049813,0.000000
38.220001,8.041756,-225.162567,-0.002570,0.001942,0.049319,35.771515,1.822288,0.493191,-225.162567,0.050438,0.000000
38.590000,8.232414,-225.207062,-0.002552,0.001967,0.049961,36.619606,1.865492,0.499610,-225.207062,0.051054,0.000000
38.960003,8.341141,-225.251541,-0.002509,0.001989,0.050525,37.103249,1.890129,0.505246,-225.251541,0.051669,0.000000
39.330002,8.467377,-225.251541,-0.002483,0.002014,0.051149,37.664772,1.918735,0.511491,-225.251541,0.052285,0.000000
39.700001,8.315453,-225.296021,-0.002462,0.002027,0.051478,36.988979,1.884308,0.514784,-225.296021,0.052901,0.000000
40.070004,9.033760,-225.296021,-0.002423,0.002066,0.052484,40.184174,2.047079,0.524844,-225.296021,0.053517,0.000000
40.440002,8.903801,-225.384979,-0.002419,0.002084,0.052927,39.606083,2.017630,0.529268,-225.384979,0.054132,0.000000
40.810001,9.237076,-225.429459,-0.002393,0.002118,0.053794,41.088566,2.093151,0.537940,-225.429459,0.054748,0.000000
41.180000,9.174141,-225.473938,-0.002367,0.002133,0.054184,40.808617,2.078890,0.541842,-225.473938,0.055364,0.000000
41.550003,9.329796,-225.473938,-0.002350,0.002157,0.054800,41.501003,2.114162,0.548000,-225.473938,0.055988,0.000000
41.920002,9.759514,-225.518417,-0.002328,0.002183,0.055442,43.412487,2.211538,0.554419,-225.518417,0.056604,0.000000
42.290001,10.030602,-225.562897,-0.002302,0.002209,0.056110,44.618343,2.272967,0.561096,-225.562897,0.057220,0.000000
42.660004,10.383232,-225.607391,-0.002285,0.002236,0.056795,46.186924,2.352874,0.567946,-225.607391,0.057835,0.000000
43.030003,10.328499,-225.651871,-0.002259,0.002256,0.057306,45.943459,2.340471,0.573063,-225.651871,0.058451,0.000000
43.400002,10.502396,-225.696350,-0.002238,0.002278,0.057870,46.716988,2.379877,0.578699,-225.696350,0.059067,0.000000
43.770000,10.978287,-225.651871,-0.002195,0.002306,0.058572,48.833858,2.487715,0.585724,-225.651871,0.059682,0.000000
44.140003,10.731400,-225.696350,-0.002199,0.002319,0.058911,47.735649,2.431770,0.589108,-225.696350,0.060298,0.000000
44.510002,11.748352,-225.740829,-0.002147,0.002364,0.060038,52.259281,2.662215,0.600379,-225.740829,0.060914,0.000000
44.880001,11.660103,-225.874268,-0.002134,0.002385,0.060584,51.866730,2.642217,0.605844,-225.874268,0.061538,0.000000
45.250004,11.841446,-225.918747,-0.002108,0.002408,0.061174,52.673382,2.683310,0.611741,-225.918747,0.062154,0.000000
45.620003,12.008270,-225.829788,-0.002095,0.002429,0.061686,53.415455,2.721113,0.616858,-225.829788,0.062770,0.000000
45.990002,12.368721,-225.829788,-0.002061,0.002450,0.062241,55.018818,2.802792,0.622407,-225.829788,0.063386,0.000000
46.360001,13.014046,-225.874268,-0.002044,0.002483,0.063073,57.889366,2.949025,0.630734,-225.874268,0.064001,0.000000
46.730003,13.240074,-226.007706,-0.002026,0.002508,0.063707,58.894791,3.000244,0.637066,-226.007706,0.064617,0.000000
47.100002,13.235977,-226.007706,-0.002001,0.002530,0.064253,58.876568,2.999315,0.642528,-226.007706,0.065233,0.000000
47.470001,13.581917,-226.052200,-0.001966,0.002555,0.064903,60.415382,3.077706,0.649030,-226.052200,0.065848,0.000000
47.840004,13.877953,-226.052200,-0.001944,0.002573,0.065363,61.732216,3.144789,0.653629,-226.052200,0.066464,0.000000
48.210003,14.375443,-226.141159,-0.001932,0.002598,0.065979,63.945164,3.257522,0.659787,-226.141159,0.067089,0.000000
48.580002,14.818565,-226.185638,-0.001910,0.002627,0.066724,65.916267,3.357935,0.667243,-226.185638,0.067704,0.000000
48.950001,15.085182,-226.274597,-0.001901,0.002650,0.067314,67.102242,3.418351,0.673140,-226.274597,0.068320,0.000000
49.320004,15.244560,-226.274597,-0.001876,0.002669,0.067800,67.811188,3.454467,0.677996,-226.274597,0.068936,0.000000
49.690002,15.829185,-226.274597,-0.001837,0.002696,0.068476,70.411736,3.586945,0.684763,-226.274597,0.069552,0.000000
50.060001,16.012390,-226.274597,-0.001824,0.002715,0.068962,71.226669,3.628459,0.689619,-226.274597,0.070167,0.000000
50.430004,17.241966,-226.363556,-0.001794,0.002753,0.069916,76.696098,3.907085,0.699157,-226.363556,0.070783,0.000000
50.800003,17.238243,-226.452515,-0.001781,0.002774,0.070454,76.679535,3.906242,0.704535,-226.452515,0.071399,0.000000
51.170002,17.506348,-226.408035,-0.001746,0.002797,0.071043,77.872124,3.966995,0.710432,-226.408035,0.072014,0.000000
51.540001,17.744293,-226.452515,-0.001729,0.002814,0.071477,78.930557,4.020915,0.714766,-226.452515,0.072639,0.000000
51.910004,18.381050,-226.408035,-0.001716,0.002839,0.072110,81.762993,4.165205,0.721098,-226.408035,0.073255,0.000000
52.280003,19.230431,-226.497009,-0.001690,0.002869,0.072873,85.541229,4.357678,0.728729,-226.497009,0.073870,0.000000
52.650002,19.686592,-226.585968,-0.001669,0.002894,0.073506,87.570335,4.461046,0.735061,-226.585968,0.074486,0.000000
53.020004,20.332657,-226.585968,-0.001630,0.002920,0.074174,90.444176,4.607446,0.741737,-226.585968,0.075102,0.000000
53.390003,20.844292,-226.585968,-0.001625,0.002944,0.074790,92.720039,4.723384,0.747895,-226.585968,0.075718,0.000000
53.760002,20.812645,-226.674927,-0.001604,0.002961,0.075215,92.579269,4.716213,0.752146,-226.674927,0.076333,0.000000
54.130001,22.054504,-226.674927,-0.001591,0.002993,0.076012,98.103333,4.997622,0.760124,-226.674927,0.076949,0.000000
54.500004,22.128235,-226.763885,-0.001561,0.003010,0.076446,98.431305,5.014329,0.764458,-226.763885,0.077565,0.000000
54.870003,22.735947,-226.852844,-0.001561,0.003037,0.077131,101.134544,5.152039,0.771312,-226.852844,0.078189,0.000000
55.240002,23.785667,-226.808365,-0.001539,0.003065,0.077859,105.803932,5.389909,0.778595,-226.808365,0.078805,0.000000
55.610004,23.532822,-226.763885,-0.001518,0.003078,0.078172,104.679222,5.332613,0.781717,-226.763885,0.079421,0.000000
55.980003,25.231590,-226.852844,-0.001492,0.003115,0.079117,112.235718,5.717560,0.791172,-226.852844,0.080036,0.000000
56.350002,25.414795,-226.941818,-0.001470,0.003132,0.079542,113.050652,5.759075,0.795418,-226.941818,0.080652,0.000000
56.720001,26.169220,-226.941818,-0.001453,0.003158,0.080210,116.406502,5.930030,0.802099,-226.941818,0.081268,0.000000
57.090004,26.789597,-226.986298,-0.001431,0.003183,0.080860,119.166077,6.070610,0.808601,-226.986298,0.081884,0.000000
57.460003,27.524658,-226.986298,-0.001406,0.003203,0.081354,122.435791,6.237176,0.813544,-226.986298,0.082499,0.000000
57.830002,28.230675,-226.986298,-0.001393,0.003230,0.082039,125.576309,6.397162,0.820395,-226.986298,0.083115,0.000000
58.200005,29.864273,-227.030777,-0.001388,0.003259,0.082768,132.842926,6.767341,0.827681,-227.030777,0.083739,0.000000
58.570004,29.587601,-227.164215,-0.001350,0.003272,0.083106,131.612228,6.704647,0.831061,-227.164215,0.084355,0.000000
58.940002,31.119911,-227.119736,-0.001337,0.003305,0.083956,138.428284,7.051873,0.839562,-227.119736,0.084971,0.000000
59.310001,31.752571,-227.164215,-0.001328,0.003326,0.084468,141.242493,7.195236,0.844679,-227.164215,0.085587,0.000000
59.680004,32.772125,-227.208694,-0.001319,0.003351,0.085109,145.777695,7.426270,0.851094,-227.208694,0.086202,0.000000
60.050003,33.158653,-227.208694,-0.001302,0.003371,0.085612,147.497055,7.513858,0.856124,-227.208694,0.086818,0.000000
60.420002,34.639946,-227.342148,-0.001285,0.003399,0.086324,154.086182,7.849524,0.863236,-227.342148,0.087434,0.000000
60.790005,35.504601,-227.297653,-0.001250,0.003424,0.086966,157.932358,8.045457,0.869655,-227.297653,0.088050,0.000000
61.160004,36.443352,-227.342148,-0.001237,0.003445,0.087503,162.108124,8.258182,0.875030,-227.342148,0.088674,0.000000
61.530003,37.680740,-227.386627,-0.001220,0.003472,0.088197,167.612305,8.538577,0.881968,-227.386627,0.089289,0.000000
61.900002,38.117538,-227.431107,-0.001207,0.003491,0.088682,169.555283,8.637557,0.886824,-227.431107,0.089905,0.000000
62.270004,40.177872,-227.475586,-0.001186,0.003525,0.089532,178.720093,9.104436,0.895324,-227.475586,0.090521,0.000000
62.640003,40.612061,-227.475586,-0.001173,0.003545,0.090044,180.651474,9.202825,0.900442,-227.475586,0.091137,0.000000
63.010002,41.573151,-227.520065,-0.001164,0.003568,0.090634,184.926605,9.420610,0.906339,-227.520065,0.091753,0.000000
63.380005,42.529778,-227.564545,-0.001143,0.003591,0.091206,189.181900,9.637385,0.912061,-227.564545,0.092368,0.000000
63.750004,43.752274,-227.564545,-0.001130,0.003611,0.091727,194.619827,9.914407,0.917266,-227.564545,0.092984,0.000000
64.120003,45.380287,-227.653503,-0.001108,0.003639,0.092429,201.861603,10.283320,0.924290,-227.653503,0.093600,0.000000
64.490005,46.346970,-227.697983,-0.001112,0.003664,0.093071,206.161621,10.502373,0.930706,-227.697983,0.094224,0.000000
64.860001,47.859169,-227.697983,-0.001082,0.003689,0.093695,212.888214,10.845042,0.936951,-227.697983,0.094840,0.000000
65.230003,49.305092,-227.742462,-0.001069,0.003712,0.094293,219.320007,11.172693,0.942935,-227.742462,0.095455,0.000000
65.600006,50.559242,-227.742462,-0.001065,0.003737,0.094918,224.898743,11.456888,0.949180,-227.742462,0.096071,0.000000
65.970001,52.514946,-227.875916,-0.001065,0.003769,0.095725,233.598145,11.900057,0.957245,-227.875916,0.096687,0.000000
66.340004,53.476784,-227.831436,-0.001022,0.003791,0.096279,237.876617,12.118012,0.962794,-227.831436,0.097303,0.000000
66.710007,54.718269,-227.875916,-0.001026,0.003816,0.096921,243.399017,12.399337,0.969213,-227.875916,0.097919,0.000000
67.080002,55.334549,-227.875916,-0.001005,0.003827,0.097216,246.140366,12.538988,0.972162,-227.875916,0.098534,0.000000
67.450005,57.403076,-227.920395,-0.000996,0.003862,0.098101,255.341629,13.007723,0.981007,-227.920395,0.099150,0.000000
67.820000,59.410538,-227.964874,-0.000987,0.003889,0.098777,264.271271,13.462620,0.987771,-227.964874,0.099774,0.000000
68.190002,60.992378,-227.964874,-0.000979,0.003914,0.099427,271.307648,13.821071,0.994273,-227.964874,0.100390,0.000000
68.560005,61.938202,-228.053833,-0.000961,0.003933,0.099905,275.514893,14.035398,0.999046,-228.053833,0.101006,0.000000
68.930000,63.979179,-228.098312,-0.000931,0.003961,0.100615,284.593597,14.497890,1.006154,-228.098312,0.101621,0.000000
69.300003,65.129799,-228.098312,-0.000944,0.003982,0.101145,289.711823,14.758624,1.011445,-228.098312,0.102237,0.000000
69.670006,66.066689,-228.098312,-0.000940,0.003990,0.101335,293.879303,14.970926,1.013353,-228.098312,0.101552,0.000000
70.040001,65.204659,-228.231766,-0.000914,0.003989,0.101327,290.044800,14.775586,1.013266,-228.231766,294.500488,0.000000
70.410004,66.377251,-228.231766,-0.000905,0.003994,0.101439,295.260742,15.041300,1.014393,-228.231766,294.500488,0.000000
70.780006,65.720390,-228.231766,-0.000892,0.003994,0.101439,292.338898,14.892453,1.014393,-228.231766,294.500488,0.000000
71.150002,65.193108,-228.276245,-0.000901,0.003998,0.101561,289.993439,14.772969,1.015608,-228.276245,294.500488,0.000000
71.520004,65.993706,-228.320724,-0.000914,0.004015,0.101986,293.554657,14.954388,1.019859,-228.320724,294.500488,0.000000
71.890007,65.547981,-228.409683,-0.000880,0.004015,0.101986,291.571991,14.853385,1.019859,-228.409683,294.500488,0.000000
72.260002,65.184166,-228.365204,-0.000897,0.004015,0.101986,289.953644,14.770943,1.019859,-228.365204,294.500488,0.000000
72.630005,64.863182,-228.409683,-0.000884,0.004015,0.101986,288.525848,14.698207,1.019859,-228.409683,294.500488,0.000000
73.000000,64.552254,-228.409683,-0.000884,0.004016,0.101995,287.142761,14.627750,1.019946,-228.409683,294.500488,0.000000
73.370003,66.905647,-228.498642,-0.000858,0.003861,0.098057,297.611176,15.161036,0.980572,-228.498642,294.500488,0.000000
73.740005,66.400337,-228.498642,-0.000854,0.003848,0.097736,295.363464,15.046532,0.977362,-228.498642,294.500488,0.000000
74.110001,66.147865,-228.587601,-0.000867,0.003848,0.097736,294.240387,14.989321,0.977362,-228.587601,294.500488,0.000000
74.480003,65.905830,-228.543121,-0.000854,0.003849,0.097762,293.163788,14.934474,0.977623,-228.543121,294.500488,0.000000
74.850006,65.670494,-228.587601,-0.000862,0.003886,0.098708,292.116943,14.881146,0.987078,-228.587601,294.500488,0.000000
75.220001,65.508141,-228.676575,-0.000871,0.003973,0.100919,291.394775,14.844357,1.009189,-228.676575,294.500488,0.000000
75.590004,65.361046,-228.721054,-0.000858,0.004008,0.101803,290.740448,14.811025,1.018035,-228.721054,294.500488,0.000000
75.960007,65.226616,-228.765533,-0.000867,0.004009,0.101838,290.142487,14.780562,1.018383,-228.765533,294.500488,0.000000
76.330002,65.046761,-228.721054,-0.000858,0.004009,0.101838,289.342438,14.739807,1.018383,-228.721054,294.500488,0.000000
76.700005,65.213966,-228.721054,-0.000849,0.004034,0.102471,290.086212,14.777697,1.024715,-228.721054,294.500488,0.000000
77.070007,65.232216,-228.765533,-0.000871,0.004043,0.102680,290.167389,14.781832,1.026797,-228.765533,294.500488,0.000000
77.440002,65.553566,-228.854492,-0.000862,0.004043,0.102680,291.596832,14.854650,1.026797,-228.854492,294.500488,0.000000
77.810005,65.492500,-228.854492,-0.000858,0.004043,0.102680,291.325195,14.840813,1.026797,-228.854492,294.500488,0.000000
78.180000,65.349129,-228.898972,-0.000854,0.004043,0.102680,290.687439,14.808324,1.026797,-228.898972,294.500488,0.000000
78.550003,65.263863,-228.898972,-0.000849,0.004043,0.102680,290.308167,14.789002,1.026797,-228.898972,294.500488,0.000000
78.920006,65.259392,-228.943451,-0.000849,0.004045,0.102740,290.288269,14.787990,1.027402,-228.943451,294.500488,0.000000
79.290001,65.242638,-229.032410,-0.000862,0.004045,0.102749,290.213745,14.784193,1.027489,-229.032410,294.500488,0.000000
79.660004,65.202049,-229.032410,-0.000854,0.004046,0.102766,290.033203,14.774996,1.027663,-229.032410,294.500488,0.000000
80.030006,65.192741,-229.076904,-0.000858,0.004047,0.102792,289.991791,14.772886,1.027925,-229.076904,294.500488,0.000000
80.400002,65.222893,-229.121384,-0.000845,0.004048,0.102827,290.125916,14.779719,1.028269,-229.121384,294.500488,0.000000
80.770004,65.174858,-229.076904,-0.000854,0.004049,0.102844,289.912262,14.768834,1.028443,-229.076904,294.500488,0.000000
81.140007,65.307426,-229.121384,-0.000858,0.004051,0.102897,290.501953,14.798875,1.028965,-229.121384,294.500488,0.000000
81.510002,65.281731,-229.210342,-0.000862,0.004051,0.102897,290.387634,14.793052,1.028965,-229.210342,294.500488,0.000000
81.880005,65.243004,-229.299301,-0.000849,0.004053,0.102948,290.215363,14.784276,1.029484,-229.299301,294.500488,0.000000
82.250008,65.303703,-229.210342,-0.000854,0.004053,0.102948,290.485382,14.798031,1.029484,-229.210342,294.500488,0.000000
82.620003,65.273170,-229.254822,-0.000841,0.004053,0.102948,290.349548,14.791112,1.029484,-229.254822,294.500488,0.000000
82.990005,65.230354,-229.343781,-0.000849,0.004053,0.102957,290.159119,14.781409,1.029571,-229.343781,294.500488,0.000000
83.360001,65.176353,-229.388260,-0.000867,0.004053,0.102957,289.918915,14.769173,1.029571,-229.388260,294.500488,0.000000
83.730003,65.136131,-229.477234,-0.000849,0.004054,0.102983,289.739990,14.760058,1.029832,-229.477234,294.500488,0.000000
84.100006,65.101509,-229.432739,-0.000849,0.004054,0.102983,289.585968,14.752213,1.029832,-229.432739,294.500488,0.000000
84.470001,65.117516,-229.477234,-0.000849,0.004056,0.103018,289.657166,14.755840,1.030177,-229.477234,294.500488,0.000000
84.840004,65.113792,-229.477234,-0.000858,0.004056,0.103018,289.640625,14.754995,1.030177,-229.477234,294.500488,0.000000
85.210007,65.116035,-229.566193,-0.000867,0.004059,0.103087,289.650604,14.755505,1.030873,-229.566193,294.500488,0.000000
85.580002,65.228111,-229.566193,-0.000836,0.004059,0.103087,290.149139,14.780901,1.030873,-229.566193,294.500488,0.000000
85.950005,65.213585,-229.655151,-0.000836,0.004059,0.103087,290.084503,14.777609,1.030873,-229.655151,294.500488,0.000000
86.320007,65.162209,-229.610672,-0.000858,0.004059,0.103087,289.855988,14.765968,1.030873,-229.610672,294.500488,0.000000
86.690002,65.111565,-229.699631,-0.000858,0.004059,0.103087,289.630707,14.754492,1.030873,-229.699631,294.500488,0.000000
87.060005,65.090340,-229.699631,-0.000845,0.004059,0.103096,289.536285,14.749682,1.030956,-229.699631,294.500488,0.000000
87.430008,65.066124,-229.788589,-0.000849,0.004060,0.103122,289.428589,14.744194,1.031217,-229.788589,294.500488,0.000000
87.800003,65.114174,-229.788589,-0.000845,0.004061,0.103148,289.642303,14.755083,1.031479,-229.788589,294.500488,0.000000
88.170006,65.108208,-229.788589,-0.000845,0.004061,0.103148,289.615784,14.753730,1.031479,-229.788589,294.500488,0.000000
88.540001,65.086983,-229.788589,-0.000862,0.004061,0.103157,289.521362,14.748921,1.031566,-229.788589,294.500488,0.000000
88.910004,65.068367,-229.922043,-0.000858,0.004062,0.103165,289.438538,14.744702,1.031653,-229.922043,294.500488,0.000000
89.280006,65.222160,-229.922043,-0.000854,0.004064,0.103217,290.122650,14.779552,1.032171,-229.922043,294.500488,0.000000
89.650002,65.218437,-230.055481,-0.000841,0.004064,0.103217,290.106110,14.778709,1.032171,-230.055481,294.500488,0.000000
90.020004,65.191628,-230.011002,-0.000836,0.004064,0.103217,289.986847,14.772635,1.032171,-230.011002,294.500488,0.000000
90.390007,65.168159,-230.011002,-0.000845,0.004064,0.103217,289.882446,14.767316,1.032171,-230.011002,294.500488,0.000000
90.760002,65.126457,-230.011002,-0.000854,0.004064,0.103226,289.696960,14.757866,1.032258,-230.011002,294.500488,0.000000
91.130005,65.111931,-230.144440,-0.000845,0.004065,0.103243,289.632324,14.754575,1.032432,-230.144440,294.500488,0.000000
91.500008,65.239281,-230.144440,-0.000841,0.004067,0.103295,290.198822,14.783432,1.032951,-230.144440,294.500488,0.000000
91.870003,65.257896,-230.188919,-0.000845,0.004067,0.103295,290.281616,14.787651,1.032951,-230.188919,294.500488,0.000000
92.240005,65.248589,-230.144440,-0.000823,0.004067,0.103295,290.240204,14.785542,1.032951,-230.144440,294.500488,0.000000
92.610001,65.199074,-230.277878,-0.000849,0.004067,0.103295,290.019958,14.774321,1.032951,-230.277878,294.500488,0.000000
92.980003,65.183800,-230.277878,-0.000854,0.004067,0.103295,289.952026,14.770861,1.032951,-230.277878,294.500488,0.000000
93.350006,65.174126,-230.277878,-0.000858,0.004067,0.103304,289.908997,14.768668,1.033038,-230.277878,294.500488,0.000000
93.720001,65.139854,-230.277878,-0.000845,0.004067,0.103304,289.756531,14.760902,1.033038,-230.277878,294.500488,0.000000
94.090004,65.091087,-230.322357,-0.000858,0.004067,0.103304,289.539612,14.749851,1.033038,-230.322357,294.500488,0.000000
94.460007,65.092201,-230.322357,-0.000845,0.004068,0.103339,289.544586,14.750103,1.033386,-230.322357,294.500488,0.000000
94.830002,65.111931,-230.455811,-0.000854,0.004068,0.103339,289.632324,14.754575,1.033386,-230.455811,294.500488,0.000000
95.200005,65.092201,-230.455811,-0.000845,0.004068,0.103339,289.544586,14.750103,1.033386,-230.455811,294.500488,0.000000
95.570007,65.063530,-230.500290,-0.000849,0.004068,0.103339,289.417023,14.743607,1.033386,-230.500290,294.500488,0.000000
95.940002,65.034111,-230.500290,-0.000845,0.004068,0.103339,289.286163,14.736940,1.033386,-230.500290,294.500488,0.000000
96.310005,65.019218,-230.500290,-0.000849,0.004068,0.103339,289.219940,14.733565,1.033386,-230.500290,294.500488,0.000000
96.680008,65.535316,-230.589249,-0.000841,0.004075,0.103495,291.515656,14.850515,1.034945,-230.589249,294.500488,0.000000
97.050003,65.547234,-230.633728,-0.000849,0.004075,0.103495,291.568665,14.853215,1.034945,-230.633728,294.500488,0.000000
97.420006,65.559517,-230.678207,-0.000845,0.004075,0.103495,291.623291,14.855999,1.034945,-230.678207,294.500488,0.000000
97.790001,65.528618,-230.589249,-0.000828,0.004075,0.103495,291.485840,14.848997,1.034945,-230.589249,294.500488,0.000000
98.160004,65.541649,-230.722687,-0.000849,0.004075,0.103495,291.543823,14.851950,1.034945,-230.722687,294.500488,0.000000
98.530006,65.514473,-230.767181,-0.000841,0.004075,0.103495,291.422943,14.845792,1.034945,-230.767181,294.500488,0.000000
98.900002,65.488777,-230.856140,-0.000841,0.004075,0.103495,291.308624,14.839969,1.034945,-230.856140,294.500488,0.000000
99.270004,65.476112,-230.856140,-0.000828,0.004075,0.103495,291.252289,14.837099,1.034945,-230.856140,294.500488,0.000000
99.640007,65.420631,-230.811661,-0.000845,0.004075,0.103495,291.005493,14.824528,1.034945,-230.811661,294.500488,0.000000
100.010002,65.403130,-230.856140,-0.000841,0.004075,0.103495,290.927643,14.820561,1.034945,-230.856140,294.500488,0.000000
100.380005,65.398659,-230.945099,-0.000832,0.004075,0.103495,290.907776,14.819548,1.034945,-230.945099,294.500488,0.000000
100.750008,65.343544,-231.034058,-0.000845,0.004075,0.103503,290.662598,14.807058,1.035033,-231.034058,294.500488,0.000000
101.120003,65.327904,-230.989578,-0.000841,0.004075,0.103503,290.593018,14.803514,1.035033,-230.989578,294.500488,0.000000
101.490005,65.321571,-230.989578,-0.000832,0.004075,0.103503,290.564850,14.802079,1.035033,-230.989578,294.500488,0.000000
101.860008,65.297752,-231.034058,-0.000841,0.004075,0.103503,290.458923,14.796682,1.035033,-231.034058,294.500488,0.000000
102.230003,65.293282,-231.034058,-0.000845,0.004075,0.103503,290.439026,14.795669,1.035033,-231.034058,294.500488,0.000000
102.600006,65.276527,-231.123016,-0.000836,0.004075,0.103503,290.364502,14.791872,1.035033,-231.123016,294.500488,0.000000
102.970001,65.245247,-231.167496,-0.000849,0.004075,0.103503,290.225342,14.784784,1.035033,-231.167496,294.500488,0.000000
103.340004,65.230354,-231.211990,-0.000819,0.004075,0.103503,290.159119,14.781409,1.035033,-231.211990,294.500488,0.000000
103.710007,65.226616,-231.167496,-0.000836,0.004075,0.103503,290.142487,14.780562,1.035033,-231.167496,294.500488,0.000000
104.080002,65.195717,-231.211990,-0.000836,0.004075,0.103503,290.005035,14.773561,1.035033,-231.211990,294.500488,0.000000
104.450005,65.155495,-231.345428,-0.000845,0.004075,0.103503,289.826111,14.764446,1.035033,-231.345428,294.500488,0.000000
104.820007,65.143959,-231.389908,-0.000823,0.004075,0.103512,289.774811,14.761832,1.035120,-231.389908,294.500488,0.000000
105.190002,65.111183,-231.300949,-0.000832,0.004075,0.103512,289.628998,14.754405,1.035120,-231.300949,294.500488,0.000000
105.560005,65.087730,-231.389908,-0.000845,0.004075,0.103512,289.524689,14.749090,1.035120,-231.389908,294.500488,0.000000
105.930008,65.061668,-231.389908,-0.000828,0.004075,0.103512,289.408752,14.743185,1.035120,-231.389908,294.500488,0.000000
106.300003,65.690605,-231.434387,-0.000854,0.004083,0.103720,292.206390,14.885704,1.037201,-231.434387,294.500488,0.000000
106.670006,65.758003,-231.523346,-0.000841,0.004082,0.103694,292.506195,14.900976,1.036940,-231.523346,294.500488,0.000000
107.040009,65.749062,-231.523346,-0.000823,0.004082,0.103694,292.466431,14.898951,1.036940,-231.523346,294.500488,0.000000
107.410004,65.686134,-231.567825,-0.000819,0.004082,0.103694,292.186523,14.884691,1.036940,-231.567825,294.500488,0.000000
107.780006,65.681297,-231.567825,-0.000841,0.004082,0.103694,292.165009,14.883595,1.036940,-231.567825,294.500488,0.000000
108.150002,65.666389,-231.656799,-0.000845,0.004082,0.103694,292.098694,14.880217,1.036940,-231.656799,294.500488,0.000000
108.520004,65.644798,-231.701279,-0.000836,0.004082,0.103694,292.002655,14.875324,1.036940,-231.701279,294.500488,0.000000
108.890007,65.618736,-231.701279,-0.000841,0.004082,0.103694,291.886719,14.869418,1.036940,-231.701279,294.500488,0.000000
109.260002,65.612770,-231.745758,-0.000828,0.004082,0.103694,291.860168,14.868067,1.036940,-231.745758,294.500488,0.000000
109.630005,65.585594,-231.745758,-0.000823,0.004082,0.103694,291.739288,14.861908,1.036940,-231.745758,294.500488,0.000000
110.000008,65.589317,-231.834717,-0.000845,0.004082,0.103694,291.755859,14.862752,1.036940,-231.834717,294.500488,0.000000
110.370003,65.587456,-231.790237,-0.000828,0.004082,0.103694,291.747589,14.862329,1.036940,-231.790237,294.500488,0.000000
110.740005,65.574043,-231.879196,-0.000832,0.004082,0.103694,291.687927,14.859290,1.036940,-231.879196,294.500488,0.000000
111.110008,65.571068,-231.923676,-0.000832,0.004082,0.103694,291.674683,14.858616,1.036940,-231.923676,294.500488,0.000000
111.480003,65.560265,-231.879196,-0.000836,0.004082,0.103694,291.626617,14.856169,1.036940,-231.879196,294.500488,0.000000
111.850006,65.544624,-231.923676,-0.000836,0.004082,0.103694,291.557037,14.852624,1.036940,-231.923676,294.500488,0.000000
112.220009,65.521919,-232.012634,-0.000849,0.004082,0.103694,291.456055,14.847479,1.036940,-232.012634,294.500488,0.000000
112.590004,65.507759,-232.057129,-0.000841,0.004082,0.103694,291.393066,14.844271,1.036940,-232.057129,294.500488,0.000000
112.960007,65.481697,-232.101608,-0.000828,0.004082,0.103694,291.277130,14.838365,1.036940,-232.101608,294.500488,0.000000
113.330002,65.463081,-232.057129,-0.000841,0.004082,0.103694,291.194336,14.834146,1.036940,-232.057129,294.500488,0.000000
113.700005,65.456749,-232.190567,-0.000832,0.004082,0.103694,291.166168,14.832711,1.036940,-232.190567,294.500488,0.000000
114.070007,65.402748,-232.190567,-0.000836,0.004082,0.103694,290.925964,14.820475,1.036940,-232.190567,294.500488,0.000000
114.440002,65.384132,-232.235046,-0.000828,0.004082,0.103694,290.843140,14.816257,1.036940,-232.235046,294.500488,0.000000
114.810005,65.355843,-232.190567,-0.000828,0.004082,0.103694,290.717316,14.809846,1.036940,-232.190567,294.500488,0.000000
115.180008,65.358437,-232.279526,-0.000828,0.004083,0.103703,290.728851,14.810433,1.037027,-232.279526,294.500488,0.000000
115.550003,65.324928,-232.324005,-0.000832,0.004083,0.103703,290.579803,14.802840,1.037027,-232.324005,294.500488,0.000000
115.920006,65.327171,-232.368484,-0.000845,0.004083,0.103703,290.589783,14.803349,1.037027,-232.368484,294.500488,0.000000
116.290009,65.313011,-232.368484,-0.000836,0.004083,0.103703,290.526794,14.800140,1.037027,-232.368484,294.500488,0.000000
116.660004,65.291420,-232.457443,-0.000832,0.004083,0.103703,290.430756,14.795248,1.037027,-232.457443,294.500488,0.000000
117.030006,65.267586,-232.457443,-0.000819,0.004083,0.103703,290.324707,14.789846,1.037027,-232.457443,294.500488,0.000000
117.400009,65.268700,-232.457443,-0.000828,0.004083,0.103703,290.329681,14.790098,1.037027,-232.457443,294.500488,0.000000
117.770004,65.253441,-232.546417,-0.000845,0.004083,0.103703,290.261810,14.786641,1.037027,-232.546417,294.500488,0.000000
118.140007,65.241142,-232.590897,-0.000845,0.004083,0.103703,290.207092,14.783854,1.037027,-232.590897,294.500488,0.000000
118.510002,65.233696,-232.501938,-0.000828,0.004083,0.103703,290.173981,14.782166,1.037027,-232.501938,294.500488,0.000000
118.880005,65.201302,-232.546417,-0.000836,0.004083,0.103703,290.029877,14.774826,1.037027,-232.546417,294.500488,0.000000
119.250008,65.168159,-232.590897,-0.000841,0.004083,0.103703,289.882446,14.767316,1.037027,-232.590897,294.500488,0.000000
119.620003,65.140236,-232.635376,-0.000845,0.004083,0.103703,289.758240,14.760988,1.037027,-232.635376,294.500488,0.000000
119.990005,65.107094,-232.679855,-0.000832,0.004083,0.103703,289.610809,14.753479,1.037027,-232.679855,294.500488,0.000000
120.360008,65.090340,-232.768814,-0.000832,0.004083,0.103703,289.536285,14.749682,1.037027,-232.768814,294.500488,0.000000
120.730003,65.076927,-232.768814,-0.000832,0.004083,0.103703,289.476624,14.746643,1.037027,-232.768814,294.500488,0.000000
121.100006,65.079170,-232.768814,-0.000828,0.004083,0.103703,289.486603,14.747151,1.037027,-232.768814,294.500488,0.000000
121.470009,65.055336,-232.813293,-0.000836,0.004083,0.103703,289.380585,14.741750,1.037027,-232.813293,294.500488,0.000000
121.840004,65.041557,-232.857773,-0.000841,0.004083,0.103703,289.319305,14.738627,1.037027,-232.857773,294.500488,0.000000
122.210007,65.026665,-232.902252,-0.000832,0.004083,0.103703,289.253052,14.735253,1.037027,-232.902252,294.500488,0.000000
122.580009,65.007301,-232.991226,-0.000823,0.004083,0.103703,289.166931,14.730865,1.037027,-232.991226,294.500488,0.000000
122.950005,64.993141,-232.946747,-0.000828,0.004083,0.103703,289.103943,14.727656,1.037027,-232.946747,294.500488,0.000000
123.320007,64.982719,-232.946747,-0.000832,0.004083,0.103703,289.057587,14.725295,1.037027,-232.946747,294.500488,0.000000
123.690002,64.963722,-233.035706,-0.000841,0.004083,0.103703,288.973083,14.720990,1.037027,-233.035706,294.500488,0.000000
124.060005,64.966331,-233.080185,-0.000828,0.004083,0.103703,288.984680,14.721581,1.037027,-233.080185,294.500488,0.000000
124.430008,64.952187,-233.124664,-0.000828,0.004083,0.103703,288.921753,14.718376,1.037027,-233.124664,294.500488,0.000000
124.800003,64.927986,-233.124664,-0.000832,0.004083,0.103703,288.814117,14.712892,1.037027,-233.124664,294.500488,0.000000
125.170006,64.907127,-233.169144,-0.000823,0.004083,0.103703,288.721313,14.708166,1.037027,-233.169144,294.500488,0.000000
125.540009,64.878456,-233.213623,-0.000828,0.004083,0.103703,288.593781,14.701669,1.037027,-233.213623,294.500488,0.000000
125.910004,64.844200,-233.258102,-0.000832,0.004083,0.103703,288.441406,14.693906,1.037027,-233.258102,294.500488,0.000000
126.280006,64.838982,-233.213623,-0.000823,0.004083,0.103703,288.418182,14.692723,1.037027,-233.213623,294.500488,0.000000
126.650009,64.824455,-233.302582,-0.000832,0.004083,0.103703,288.353577,14.689431,1.037027,-233.302582,294.500488,0.000000
127.020004,64.812538,-233.302582,-0.000836,0.004083,0.103703,288.300568,14.686730,1.037027,-233.302582,294.500488,0.000000
127.390007,64.789085,-233.302582,-0.000836,0.004083,0.103703,288.196259,14.681417,1.037027,-233.302582,294.500488,0.000000
127.760010,64.772697,-233.480515,-0.000832,0.004083,0.103703,288.123352,14.677703,1.037027,-233.480515,294.500488,0.000000
128.130005,64.765633,-233.436035,-0.000819,0.004083,0.103703,288.091919,14.676103,1.037027,-233.436035,294.500488,0.000000
128.500000,64.744408,-233.480515,-0.000823,0.004083,0.103703,287.997498,14.671292,1.037027,-233.480515,294.500488,0.000000
128.870010,64.748131,-233.436035,-0.000832,0.004083,0.103703,288.014069,14.672136,1.037027,-233.436035,294.500488,0.000000
129.240005,64.732857,-233.569473,-0.000832,0.004083,0.103703,287.946136,14.668674,1.037027,-233.569473,294.500488,0.000000
129.610001,65.859291,-233.569473,-0.000828,0.004096,0.104041,292.956757,14.923928,1.040411,-233.569473,294.500488,0.000000
129.980011,65.874550,-233.613953,-0.000828,0.004096,0.104041,293.024628,14.927386,1.040411,-233.613953,294.500488,0.000000
130.350006,65.933006,-233.569473,-0.000819,0.004090,0.103893,293.284668,14.940633,1.038935,-233.569473,0.103954,0.000000
130.720001,65.898384,-233.658432,-0.000832,0.004078,0.103590,293.130646,14.932788,1.035903,-233.658432,0.103339,0.000000
131.090012,65.844383,-233.658432,-0.000815,0.004060,0.103122,292.890442,14.920550,1.031217,-233.658432,0.102723,0.000000
131.460007,65.753151,-233.747391,-0.000806,0.004039,0.102593,292.484619,14.899878,1.025930,-233.747391,0.102107,0.000000
131.830002,65.760979,-233.791885,-0.000811,0.004012,0.101908,292.519440,14.901651,1.019075,-233.791885,0.101492,0.000000
132.200012,65.688744,-233.791885,-0.000802,0.003991,0.101370,292.198120,14.885282,1.013701,-233.791885,0.100876,0.000000
132.570007,65.728203,-233.836365,-0.000806,0.003970,0.100841,292.373657,14.894223,1.008410,-233.836365,0.100260,0.000000
132.940002,65.667137,-233.836365,-0.000815,0.003945,0.100208,292.102020,14.880386,1.002081,-233.836365,0.099644,0.000000
133.310013,65.677559,-233.925323,-0.000819,0.003922,0.099618,292.148376,14.882748,0.996181,-233.925323,0.099020,0.000000
133.680008,65.565849,-233.925323,-0.000815,0.003893,0.098881,291.651459,14.857434,0.988811,-233.925323,0.098404,0.000000
134.050003,65.439247,-234.014282,-0.000823,0.003870,0.098309,291.088318,14.828745,0.983089,-234.014282,0.097788,0.000000
134.420013,65.079536,-233.969803,-0.000819,0.003852,0.097832,289.488251,14.747233,0.978316,-233.969803,0.097173,0.000000
134.790009,64.178764,-234.014282,-0.000798,0.003827,0.097216,285.481415,14.543116,0.972162,-234.014282,0.096557,0.000000
135.160004,63.111923,-234.103241,-0.000798,0.003806,0.096670,280.735870,14.301367,0.966696,-234.103241,0.095941,0.000000
135.530014,61.798935,-234.103241,-0.000802,0.003783,0.096097,274.895386,14.003839,0.960974,-234.103241,0.095326,0.000000
135.900009,60.268860,-234.147720,-0.000780,0.003757,0.095421,268.089264,13.657119,0.954210,-234.147720,0.094710,0.000000
136.270004,58.928688,-234.147720,-0.000789,0.003738,0.094952,262.127899,13.353432,0.949524,-234.147720,0.094094,0.000000
136.639999,56.894417,-234.192200,-0.000789,0.003715,0.094371,253.079010,12.892459,0.943714,-234.192200,0.093469,0.000000
137.010010,55.388542,-234.281174,-0.000798,0.003695,0.093843,246.380539,12.551223,0.938427,-234.281174,0.092854,0.000000
137.380005,53.195267,-234.370132,-0.000780,0.003674,0.093314,236.624359,12.054220,0.933136,-234.370132,0.092238,0.000000
137.750000,51.328194,-234.325653,-0.000780,0.003654,0.092819,228.319214,11.631135,0.928192,-234.325653,0.091622,0.000000
138.120010,47.584732,-234.281174,-0.000793,0.003618,0.091900,211.667465,10.782854,0.918999,-234.281174,0.091007,0.000000
138.490005,45.603714,-234.370132,-0.000785,0.003602,0.091492,202.855453,10.333950,0.914923,-234.370132,0.090391,0.000000
138.860001,42.770699,-234.459091,-0.000798,0.003576,0.090842,190.253571,9.691978,0.908420,-234.459091,0.089775,0.000000
139.230011,40.429970,-234.459091,-0.000780,0.003554,0.090261,179.841492,9.161563,0.902610,-234.459091,0.089160,0.000000
139.600006,37.433861,-234.503571,-0.000780,0.003527,0.089593,166.514130,8.482635,0.895930,-234.503571,0.088544,0.000000
139.970001,34.407585,-234.503571,-0.000785,0.003498,0.088847,153.052582,7.796870,0.888474,-234.503571,0.087919,0.000000
140.340012,31.638626,-234.503571,-0.000789,0.003472,0.088188,140.735641,7.169415,0.881881,-234.503571,0.087304,0.000000
140.710007,29.052872,-234.503571,-0.000789,0.003449,0.087607,129.233627,6.583475,0.876071,-234.503571,0.086688,0.000000
141.080002,26.466377,-234.681503,-0.000780,0.003425,0.086983,117.728325,5.997367,0.869829,-234.681503,0.086072,0.000000
141.450012,24.391144,-234.681503,-0.000793,0.003409,0.086601,108.497223,5.527112,0.866010,-234.681503,0.085456,0.000000
141.820007,21.005531,-234.637024,-0.000785,0.003377,0.085769,93.437271,4.759922,0.857687,-234.637024,0.084841,0.000000
142.190002,18.717300,-234.637024,-0.000776,0.003358,0.085283,83.258713,4.241401,0.852831,-234.637024,0.084225,0.000000
142.560013,15.676880,-234.725983,-0.000785,0.003330,0.084589,69.734245,3.552432,0.845894,-234.725983,0.083609,0.000000
142.930008,14.052223,-234.814941,-0.000793,0.003315,0.084207,62.507412,3.184279,0.842075,-234.814941,0.082994,0.000000
143.300003,10.272636,-234.770462,-0.000789,0.003279,0.083297,45.694969,2.327813,0.832972,-234.770462,0.082369,0.000000
143.670013,7.547249,-234.814941,-0.000802,0.003256,0.082699,33.571838,1.710231,0.826988,-234.814941,0.081753,0.000000
144.040009,5.584099,-234.814941,-0.000789,0.003235,0.082178,24.839312,1.265375,0.821784,-234.814941,0.081138,0.000000
144.410004,2.625603,-234.903900,-0.000789,0.003207,0.081467,11.679264,0.594970,0.814672,-234.903900,0.080522,0.000000
144.780014,0.774910,-234.992859,-0.000793,0.003188,0.080982,3.446972,0.175597,0.809816,-234.992859,0.079906,0.000000
145.150009,-1.156960,-235.037338,-0.000793,0.003163,0.080348,-5.146413,-0.262171,0.803484,-235.037338,0.079291,0.000000
145.520004,-0.088623,-234.948380,-0.000836,0.003135,0.079629,-0.394215,-0.020082,0.796285,-234.948380,0.078675,0.000000
145.889999,-0.008934,-234.948380,-0.000854,0.003112,0.079056,-0.039741,-0.002024,0.790562,-234.948380,0.078059,0.000000
146.260010,0.027557,-235.081833,-0.000910,0.003082,0.078284,0.122581,0.006245,0.782845,-235.081833,0.077434,0.000000
146.630005,0.052132,-235.081833,-0.000923,0.003083,0.078302,0.231893,0.011813,0.783019,-235.081833,0.076819,0.000000
147.000000,0.010056,-235.126312,-0.000970,0.003043,0.077296,0.044729,0.002279,0.772959,-235.126312,0.076203,0.000000
147.370010,-0.020103,-235.126312,-0.000983,0.003014,0.076559,-0.089425,-0.004556,0.765586,-235.126312,0.075587,0.000000
147.740005,0.010056,-235.126312,-0.001018,0.002990,0.075934,0.044729,0.002279,0.759345,-235.126312,0.074972,0.000000
148.110001,0.004097,-235.170792,-0.001061,0.002962,0.075232,0.018224,0.000928,0.752320,-235.170792,0.074356,0.000000
148.480011,-0.012657,-235.259750,-0.001086,0.002943,0.074746,-0.056302,-0.002868,0.747464,-235.259750,0.073740,0.000000
148.850006,-0.024574,-235.304230,-0.001108,0.002928,0.074373,-0.109312,-0.005569,0.743732,-235.304230,0.073125,0.000000
149.220001,-0.021973,-235.304230,-0.001147,0.002892,0.073463,-0.097739,-0.004979,0.734625,-235.304230,0.072509,0.000000
149.590012,0.004097,-235.304230,-0.001181,0.002867,0.072821,0.018224,0.000928,0.728210,-235.304230,0.071884,0.000000
149.960007,-0.005959,-235.304230,-0.001203,0.002844,0.072240,-0.026505,-0.001350,0.722400,-235.304230,0.071268,0.000000
150.330002,0.020485,-235.393188,-0.001233,0.002817,0.071555,0.091121,0.004642,0.715550,-235.393188,0.070653,0.000000
150.700012,0.033142,-235.482162,-0.001246,0.002809,0.071355,0.147423,0.007510,0.713555,-235.482162,0.071243,0.000000