File: Data/Sima compression/P1-15-2_10302024_170502.csv
Time (sec),S:Load (lbs),S:HL1 (DIM),S:LVDT (in),S:Position (in),Ch:Position (mm),Ch:Load (N),Ch:Stress (MPa),Ch:Strain (mm/mm),Ch:HL1 (DIM),Set Point (),Cycles ()
0.210000,-0.011169,-1293.239136,-0.008063,-0.005069,-0.128758,-0.049684,-0.002531,-1.287576,-1293.239136,-0.128602,0.000000
0.510000,-0.005959,-1293.283691,-0.008075,-0.005023,-0.127587,-0.026505,-0.001350,-1.275873,-1293.283691,-0.127023,0.000000
0.810000,-0.036491,-1293.239136,-0.007994,-0.004853,-0.123268,-0.162322,-0.008269,-1.232680,-1293.239136,-0.122028,0.000000
1.110000,-0.003349,-1293.239136,-0.007825,-0.004654,-0.118220,-0.014898,-0.000759,-1.182204,-1293.239136,-0.117032,0.000000
1.410000,-0.081551,-1293.239136,-0.007614,-0.004456,-0.113173,-0.362755,-0.018480,-1.131729,-1293.239136,-0.112019,0.000000
1.710000,0.010429,-1293.283691,-0.007394,-0.004264,-0.108309,0.046392,0.002363,-1.083086,-1293.283691,-0.107025,0.000000
2.010000,-0.026436,-1293.194702,-0.007196,-0.004066,-0.103287,-0.117593,-0.005990,-1.032868,-1293.194702,-0.102030,0.000000
2.310000,0.047661,-1293.283691,-0.006989,-0.003864,-0.098136,0.212006,0.010800,-0.981363,-1293.283691,-0.097034,0.000000
2.610000,0.010056,-1293.239136,-0.006799,-0.003673,-0.093296,0.044729,0.002279,-0.932961,-1293.239136,-0.092040,0.000000
2.910000,0.001862,-1293.283691,-0.006584,-0.003476,-0.088283,0.008281,0.000422,-0.882834,-1293.283691,-0.087044,0.000000
3.210000,-0.012291,-1293.283691,-0.006381,-0.003277,-0.083237,-0.054673,-0.002785,-0.832374,-1293.283691,-0.082031,0.000000
3.510000,-0.068886,-1293.283691,-0.006178,-0.003075,-0.078111,-0.306419,-0.015610,-0.781111,-1293.283691,-0.077036,0.000000
3.810000,0.028671,-1293.328125,-0.005984,-0.002880,-0.073159,0.127536,0.006497,-0.731590,-1293.328125,-0.072040,0.000000
4.110000,0.000374,-1293.328125,-0.005773,-0.002686,-0.068225,0.001663,0.000085,-0.682250,-1293.328125,-0.067046,0.000000
4.410000,0.047661,-1293.283691,-0.005583,-0.002490,-0.063247,0.212006,0.010800,-0.632471,-1293.283691,-0.062051,0.000000
4.710000,-0.002975,-1293.328125,-0.005376,-0.002296,-0.058330,-0.013236,-0.000674,-0.583298,-1293.328125,-0.057055,0.000000
5.010000,-0.004097,-1293.283691,-0.005182,-0.002101,-0.053370,-0.018224,-0.000928,-0.533700,-1293.283691,-0.052042,0.000000
5.310000,-0.031654,-1293.328125,-0.004984,-0.001900,-0.048253,-0.140806,-0.007173,-0.482529,-1293.328125,-0.047048,0.000000
5.610000,-0.018250,-1293.328125,-0.004760,-0.001699,-0.043163,-0.081178,-0.004135,-0.431629,-1293.328125,-0.042052,0.000000
5.910000,-0.035751,-1293.328125,-0.004579,-0.001505,-0.038237,-0.159030,-0.008101,-0.382365,-1293.328125,-0.037057,0.000000
6.210001,0.031654,-1293.283691,-0.004355,-0.001306,-0.033180,0.140806,0.007173,-0.331799,-1293.283691,-0.032061,0.000000
6.510000,0.022339,-1293.328125,-0.004174,-0.001107,-0.028125,0.099368,0.005062,-0.281248,-1293.328125,-0.027067,0.000000
6.810000,0.013031,-1293.328125,-0.003954,-0.000913,-0.023182,0.057965,0.002953,-0.231817,-1293.328125,-0.022072,0.000000
7.110000,0.019737,-1293.372559,-0.003751,-0.000715,-0.018151,0.087796,0.004473,-0.181508,-1293.372559,-0.017059,0.000000
7.410000,-0.044685,-1293.372559,-0.003557,-0.000520,-0.013217,-0.198770,-0.010126,-0.132169,-1293.372559,-0.012063,0.000000
7.710001,0.010429,-1293.328125,-0.003372,-0.000326,-0.008283,0.046392,0.002363,-0.082829,-1293.328125,-0.007069,0.000000
8.010000,-0.027557,-1293.328125,-0.003143,-0.000126,-0.003191,-0.122581,-0.006245,-0.031914,-1293.328125,-0.002073,0.000000
8.310000,0.089745,-1293.417114,-0.003009,-0.000009,-0.000226,0.399204,0.020336,-0.002256,-1293.417114,0.000009,0.000000
8.610001,0.084160,-1293.417114,-0.003005,-0.000009,-0.000226,0.374362,0.019071,-0.002256,-1293.417114,0.000009,0.000000
8.910001,0.146339,-1293.417114,-0.003001,-0.000009,-0.000226,0.650950,0.033161,-0.002256,-1293.417114,0.000242,0.000000
9.210000,0.146713,-1293.372559,-0.003001,-0.000007,-0.000174,0.652613,0.033246,-0.001741,-1293.372559,0.000746,0.000000
9.510000,0.231613,-1293.328125,-0.002997,0.000014,0.000356,1.030267,0.052484,0.003558,-1293.328125,0.001249,0.000000
9.810000,0.448708,-1293.372559,-0.002975,0.000031,0.000798,1.995951,0.101679,0.007979,-1293.372559,0.001743,0.000000
10.110001,0.715698,-1293.328125,-0.002966,0.000048,0.001223,3.183585,0.162180,0.012233,-1293.328125,0.002247,0.000000
10.410001,1.101852,-1293.417114,-0.002958,0.000071,0.001796,4.901284,0.249683,0.017956,-1293.417114,0.002749,0.000000
10.710000,1.574760,-1293.328125,-0.002936,0.000091,0.002315,7.004884,0.356846,0.023148,-1293.328125,0.003243,0.000000
11.010000,2.007835,-1293.283691,-0.002902,0.000108,0.002749,8.931298,0.454982,0.027493,-1293.283691,0.003747,0.000000
11.310000,2.642731,-1293.328125,-0.002897,0.000129,0.003269,11.755453,0.598851,0.032686,-1293.328125,0.004250,0.000000
11.610001,3.273895,-1293.283691,-0.002884,0.000150,0.003799,14.563013,0.741875,0.037985,-1293.283691,0.004743,0.000000
11.910001,3.721489,-1293.283691,-0.002893,0.000163,0.004145,16.554010,0.843301,0.041452,-1293.283691,0.005246,0.000000
12.210001,4.465492,-1293.328125,-0.002859,0.000183,0.004657,19.863503,1.011895,0.046569,-1293.328125,0.005750,0.000000
12.510000,5.611282,-1293.283691,-0.002828,0.000212,0.005385,24.960230,1.271535,0.053851,-1293.283691,0.006244,0.000000
12.810000,6.192924,-1293.283691,-0.002833,0.000229,0.005827,27.547504,1.403337,0.058272,-1293.283691,0.006746,0.000000
13.110001,7.013634,-1293.328125,-0.002828,0.000248,0.006297,31.198200,1.589312,0.062966,-1293.328125,0.007250,0.000000
13.410001,7.846634,-1293.372559,-0.002811,0.000267,0.006790,34.903572,1.778073,0.067901,-1293.372559,0.007744,0.000000
13.710001,8.770859,-1293.328125,-0.002790,0.000288,0.007311,39.014729,1.987505,0.073109,-1293.328125,0.008247,0.000000
14.010000,9.441505,-1293.328125,-0.002777,0.000303,0.007702,41.997913,2.139476,0.077015,-1293.328125,0.008751,0.000000
14.310000,10.646873,-1293.328125,-0.002772,0.000329,0.008360,47.359657,2.412616,0.083601,-1293.328125,0.009244,0.000000
14.610001,11.454178,-1293.328125,-0.002746,0.000348,0.008837,50.950729,2.595554,0.088370,-1293.328125,0.009747,0.000000
14.910001,12.168388,-1293.372559,-0.002746,0.000365,0.009279,54.127693,2.757396,0.092790,-1293.372559,0.010242,0.000000
15.210001,12.945900,-1293.372559,-0.002725,0.000385,0.009774,57.586239,2.933583,0.097741,-1293.372559,0.010745,0.000000
15.510001,13.977745,-1293.328125,-0.002712,0.000405,0.010286,62.176117,3.167402,0.102858,-1293.328125,0.011247,0.000000
15.810000,14.465179,-1293.372559,-0.002703,0.000420,0.010658,64.344330,3.277857,0.106583,-1293.372559,0.011742,0.000000
16.110001,15.344727,-1293.328125,-0.002682,0.000437,0.011100,68.256752,3.477165,0.111003,-1293.328125,0.012245,0.000000
16.410000,16.788788,-1293.283691,-0.002677,0.000465,0.011803,74.680260,3.804394,0.118028,-1293.283691,0.012748,0.000000
16.710001,17.594223,-1293.328125,-0.002660,0.000485,0.012331,78.263016,3.986908,0.123312,-1293.328125,0.013243,0.000000
17.010000,18.136772,-1293.328125,-0.002643,0.000499,0.012687,80.676392,4.109851,0.126870,-1293.328125,0.013745,0.000000
17.310001,18.770554,-1293.372559,-0.002639,0.000519,0.013191,83.495590,4.253468,0.131911,-1293.372559,0.014248,0.000000
17.610001,20.245148,-1293.283691,-0.002613,0.000544,0.013824,90.054916,4.587616,0.138240,-1293.283691,0.014743,0.000000
17.910002,20.622360,-1293.328125,-0.002591,0.000558,0.014162,91.732841,4.673094,0.141616,-1293.328125,0.015246,0.000000
18.210001,21.585686,-1293.283691,-0.002587,0.000579,0.014717,96.017929,4.891387,0.147172,-1293.283691,0.015748,0.000000
18.510000,22.308464,-1293.328125,-0.002570,0.000598,0.015202,99.233002,5.055170,0.152017,-1293.328125,0.016243,0.000000
18.810001,23.233063,-1293.328125,-0.002544,0.000620,0.015748,103.345825,5.264687,0.157482,-1293.328125,0.016746,0.000000
19.110001,23.434891,-1293.283691,-0.002548,0.000633,0.016078,104.243599,5.310422,0.160782,-1293.283691,0.017249,0.000000
19.410002,25.001083,-1293.328125,-0.002522,0.000664,0.016867,111.210373,5.665327,0.168670,-1293.328125,0.017744,0.000000
19.710001,25.071838,-1293.283691,-0.002505,0.000673,0.017084,111.525108,5.681360,0.170835,-1293.283691,0.018246,0.000000
20.010000,25.564484,-1293.372559,-0.002496,0.000691,0.017544,113.716499,5.792995,0.175437,-1293.372559,0.018749,0.000000
20.310001,26.679001,-1293.372559,-0.002483,0.000715,0.018169,118.674126,6.045548,0.181690,-1293.372559,0.019244,0.000000
20.610001,27.736534,-1293.328125,-0.002453,0.000739,0.018775,123.378265,6.285188,0.187746,-1293.328125,0.019747,0.000000
20.910002,28.221367,-1293.328125,-0.002453,0.000759,0.019279,125.534912,6.395053,0.192787,-1293.328125,0.020249,0.000000
21.210001,28.527084,-1293.283691,-0.002445,0.000774,0.019651,126.894806,6.464330,0.196512,-1293.283691,0.020744,0.000000
21.510000,29.576797,-1293.328125,-0.002419,0.000799,0.020284,131.564163,6.702198,0.202840,-1293.328125,0.021247,0.000000
21.810001,29.848633,-1293.328125,-0.002410,0.000813,0.020656,132.773346,6.763797,0.206564,-1293.328125,0.021750,0.000000
22.110001,31.131454,-1293.328125,-0.002384,0.000842,0.021394,138.479630,7.054489,0.213937,-1293.328125,0.022245,0.000000
22.410002,31.493774,-1293.283691,-0.002367,0.000860,0.021854,140.091309,7.136591,0.218540,-1293.283691,0.022747,0.000000
22.710001,31.769699,-1293.328125,-0.002350,0.000877,0.022279,141.318680,7.199117,0.222794,-1293.328125,0.023250,0.000000
23.010000,32.043396,-1293.328125,-0.002341,0.000894,0.022696,142.536148,7.261137,0.226957,-1293.328125,0.023745,0.000000
23.310001,32.956451,-1293.372559,-0.002324,0.000916,0.023268,146.597610,7.468039,0.232680,-1293.372559,0.024248,0.000000
23.610001,32.916611,-1293.283691,-0.002302,0.000929,0.023606,146.420395,7.459011,0.236056,-1293.283691,0.024750,0.000000
23.910002,33.359360,-1293.328125,-0.002285,0.000946,0.024039,148.389847,7.559339,0.240386,-1293.328125,0.025245,0.000000
24.210001,35.122169,-1293.372559,-0.002264,0.000979,0.024871,156.231216,7.958797,0.248713,-1293.372559,0.025748,0.000000
24.510000,35.207069,-1293.328125,-0.002246,0.000997,0.025322,156.608871,7.978036,0.253225,-1293.328125,0.026251,0.000000
24.810001,35.492310,-1293.328125,-0.002238,0.001015,0.025774,157.877686,8.042672,0.257736,-1293.328125,0.026746,0.000000
25.110001,35.935432,-1293.372559,-0.002220,0.001033,0.026234,159.848785,8.143085,0.262339,-1293.372559,0.027248,0.000000
25.410002,36.287323,-1293.417114,-0.002195,0.001049,0.026650,161.414078,8.222825,0.266502,-1293.417114,0.027751,0.000000
25.710001,36.860031,-1293.328125,-0.002182,0.001071,0.027204,163.961609,8.352603,0.272043,-1293.328125,0.028246,0.000000
26.010002,37.863579,-1293.328125,-0.002160,0.001096,0.027846,168.425613,8.580009,0.278462,-1293.328125,0.028749,0.000000
26.310001,38.259407,-1293.328125,-0.002143,0.001114,0.028306,170.186340,8.669706,0.283065,-1293.328125,0.029251,0.000000
26.610001,38.479111,-1293.372559,-0.002121,0.001130,0.028714,171.163635,8.719491,0.287137,-1293.372559,0.029746,0.000000
26.910002,38.915901,-1293.328125,-0.002113,0.001152,0.029260,173.106567,8.818469,0.292603,-1293.328125,0.030249,0.000000
27.210001,39.693039,-1293.372559,-0.002104,0.001172,0.029763,176.563461,8.994572,0.297629,-1293.372559,0.030752,0.000000
27.510002,39.449509,-1293.417114,-0.002091,0.001182,0.030023,175.480179,8.939386,0.300233,-1293.417114,0.031247,0.000000
27.810001,39.747780,-1293.328125,-0.002070,0.001198,0.030440,176.806961,9.006975,0.304396,-1293.328125,0.031749,0.000000
28.110001,42.078461,-1293.372559,-0.002039,0.001235,0.031377,187.174347,9.535115,0.313768,-1293.372559,0.032243,0.000000
28.410002,41.929886,-1293.372559,-0.002035,0.001250,0.031749,186.513443,9.501449,0.317492,-1293.372559,0.032747,0.000000
28.710001,42.447113,-1293.328125,-0.002013,0.001270,0.032252,188.814194,9.618653,0.322518,-1293.328125,0.033250,0.000000
29.010002,42.915924,-1293.417114,-0.001996,0.001289,0.032738,190.899567,9.724887,0.327378,-1293.417114,0.033743,0.000000
29.310001,43.486404,-1293.328125,-0.001970,0.001307,0.033197,193.437195,9.854160,0.331966,-1293.328125,0.034247,0.000000
29.610001,43.510605,-1293.372559,-0.001966,0.001320,0.033518,193.544830,9.859644,0.335175,-1293.372559,0.034750,0.000000
29.910002,43.376923,-1293.372559,-0.001932,0.001339,0.034022,192.950195,9.829351,0.340217,-1293.372559,0.035243,0.000000
30.210001,45.065262,-1293.328125,-0.001919,0.001365,0.034671,200.460297,10.211934,0.346712,-1293.328125,0.035748,0.000000
30.510002,45.939964,-1293.372559,-0.001901,0.001386,0.035201,204.351166,10.410145,0.352010,-1293.372559,0.036250,0.000000
30.810001,46.349945,-1293.417114,-0.001884,0.001405,0.035695,206.174850,10.503048,0.356946,-1293.417114,0.036744,0.000000
31.110001,47.332260,-1293.372559,-0.001858,0.001428,0.036259,210.544403,10.725643,0.362593,-1293.372559,0.037248,0.000000
31.410002,47.595901,-1293.372559,-0.001858,0.001446,0.036736,211.717148,10.785385,0.367362,-1293.372559,0.037751,0.000000
31.710001,48.301552,-1293.417114,-0.001850,0.001466,0.037230,214.856033,10.945288,0.372297,-1293.417114,0.038244,0.000000
32.010002,49.201942,-1293.372559,-0.001815,0.001487,0.037776,218.861176,11.149319,0.377763,-1293.372559,0.038748,0.000000
32.310001,49.705765,-1293.506104,-0.001807,0.001506,0.038253,221.102280,11.263488,0.382532,-1293.506104,0.039251,0.000000
32.610001,50.219643,-1293.372559,-0.001794,0.001527,0.038774,223.388123,11.379933,0.387740,-1293.372559,0.039744,0.000000
32.910000,50.936081,-1293.372559,-0.001763,0.001545,0.039233,226.574997,11.542281,0.392327,-1293.372559,0.040249,0.000000
33.210003,51.495018,-1293.372559,-0.001755,0.001562,0.039675,229.061279,11.668938,0.396748,-1293.372559,0.040751,0.000000
33.510002,52.037560,-1293.417114,-0.001733,0.001580,0.040135,231.474625,11.791880,0.401350,-1293.417114,0.041245,0.000000
33.810001,53.512901,-1293.461548,-0.001729,0.001607,0.040828,238.037277,12.126197,0.408284,-1293.461548,0.041747,0.000000
34.110001,53.893463,-1293.417114,-0.001712,0.001626,0.041298,239.730103,12.212433,0.412977,-1293.417114,0.042252,0.000000
34.410000,54.294884,-1293.461548,-0.001690,0.001644,0.041747,241.515701,12.303397,0.417474,-1293.461548,0.042745,0.000000
34.710003,55.337158,-1293.417114,-0.001673,0.001665,0.042294,246.151978,12.539579,0.422939,-1293.417114,0.043248,0.000000
35.010002,56.101639,-1293.372559,-0.001651,0.001685,0.042798,249.552551,12.712813,0.427981,-1293.372559,0.043752,0.000000
35.310001,56.795738,-1293.372559,-0.001647,0.001701,0.043205,252.640060,12.870099,0.432053,-1293.372559,0.044245,0.000000
35.610001,57.603783,-1293.417114,-0.001625,0.001723,0.043752,256.234436,13.053204,0.437519,-1293.417114,0.044748,0.000000
35.910000,58.567856,-1293.461548,-0.001613,0.001743,0.044280,260.522827,13.271666,0.442802,-1293.461548,0.045252,0.000000
36.210003,59.272385,-1293.372559,-0.001604,0.001762,0.044748,263.656738,13.431314,0.447481,-1293.372559,0.045746,0.000000
36.510002,59.792221,-1293.417114,-0.001600,0.001778,0.045164,265.969086,13.549111,0.451644,-1293.417114,0.046248,0.000000
36.810001,61.034454,-1293.461548,-0.001556,0.001801,0.045737,271.494812,13.830605,0.457367,-1293.461548,0.046753,0.000000
37.110001,61.403473,-1293.372559,-0.001548,0.001815,0.046102,273.136292,13.914226,0.461015,-1293.372559,0.047246,0.000000
37.410004,61.984001,-1293.417114,-0.001522,0.001833,0.046569,275.718597,14.045775,0.465693,-1293.417114,0.047749,0.000000
37.710003,63.929649,-1293.461548,-0.001513,0.001861,0.047281,284.373291,14.486665,0.472809,-1293.461548,0.048253,0.000000
38.010002,64.640877,-1293.506104,-0.001518,0.001880,0.047758,287.536987,14.647833,0.477578,-1293.506104,0.048746,0.000000
38.310001,65.247841,-1293.506104,-0.001492,0.001897,0.048183,290.236877,14.785373,0.481832,-1293.506104,0.049249,0.000000
38.610001,65.891304,-1293.461548,-0.001487,0.001912,0.048574,293.099152,14.931184,0.485738,-1293.461548,0.049753,0.000000
38.910004,65.468285,-1293.461548,-0.001457,0.001913,0.048600,291.217468,14.835325,0.485996,-1293.461548,0.008549,0.000000
39.210003,66.276344,-1293.461548,-0.001436,0.001896,0.048165,294.811890,15.018434,0.481651,-1293.461548,294.500488,0.000000
39.510002,65.227745,-1293.372559,-0.001440,0.001924,0.048877,290.147491,14.780818,0.488766,-1293.372559,294.500488,0.000000
39.810001,65.209114,-1293.506104,-0.001431,0.001942,0.049328,290.064636,14.776596,0.493278,-1293.506104,294.500488,0.000000
40.110001,65.523781,-1293.461548,-0.001427,0.001954,0.049631,291.464325,14.847900,0.496306,-1293.461548,294.500488,0.000000
40.410004,65.035973,-1293.417114,-0.001410,0.001958,0.049726,289.294464,14.737362,0.497259,-1293.417114,294.500488,0.000000
40.710003,65.849602,-1293.417114,-0.001410,0.001969,0.050021,292.913666,14.921733,0.500212,-1293.417114,294.500488,0.000000
41.010002,64.999474,-1293.506104,-0.001401,0.001974,0.050135,289.132111,14.729092,0.501347,-1293.506104,294.500488,0.000000
41.310001,65.304070,-1293.506104,-0.001393,0.001982,0.050351,290.487000,14.798114,0.503512,-1293.506104,294.500488,0.000000
41.610001,65.169655,-1293.506104,-0.001380,0.001989,0.050524,289.889099,14.767654,0.505238,-1293.506104,294.500488,0.000000
41.910004,65.359932,-1293.506104,-0.001388,0.001998,0.050758,290.735504,14.810773,0.507585,-1293.506104,294.500488,0.000000
42.210003,65.250084,-1293.506104,-0.001367,0.002002,0.050863,290.246857,14.785880,0.508629,-1293.506104,294.500488,0.000000
42.510002,65.495110,-1293.461548,-0.001354,0.002012,0.051096,291.336792,14.841404,0.510961,-1293.461548,294.500488,0.000000
42.810001,65.352486,-1293.506104,-0.001350,0.002017,0.051226,290.702362,14.809085,0.512263,-1293.506104,294.500488,0.000000
43.110001,65.152519,-1293.506104,-0.001354,0.002020,0.051305,289.812866,14.763772,0.513050,-1293.506104,294.500488,0.000000
43.410004,65.033363,-1293.461548,-0.001358,0.002025,0.051435,289.282837,14.736771,0.514352,-1293.461548,294.500488,0.000000
43.710003,64.939522,-1293.506104,-0.001345,0.002029,0.051531,288.865417,14.715506,0.515306,-1293.506104,294.500488,0.000000
44.010002,65.041557,-1293.550537,-0.001332,0.002034,0.051670,289.319305,14.738627,0.516699,-1293.550537,294.500488,0.000000
44.310001,65.137627,-1293.550537,-0.001332,0.002043,0.051903,289.746643,14.760398,0.519030,-1293.550537,294.500488,0.000000
44.610001,65.184166,-1293.461548,-0.001324,0.002044,0.051929,289.953644,14.770943,0.519288,-1293.461548,294.500488,0.000000
44.910004,65.384514,-1293.506104,-0.001328,0.002051,0.052103,290.844849,14.816342,0.521029,-1293.506104,294.500488,0.000000
45.210003,65.385994,-1293.506104,-0.001306,0.002056,0.052233,290.851440,14.816678,0.522331,-1293.506104,294.500488,0.000000
45.510002,65.316734,-1293.506104,-0.001315,0.002061,0.052338,290.543335,14.800983,0.523375,-1293.506104,294.500488,0.000000
45.810001,65.270561,-1293.550537,-0.001302,0.002064,0.052424,290.337952,14.790521,0.524238,-1293.550537,294.500488,0.000000
46.110001,65.259758,-1293.506104,-0.001293,0.002068,0.052519,290.289886,14.788073,0.525192,-1293.506104,294.500488,0.000000
46.410004,65.151405,-1293.550537,-0.001302,0.002070,0.052580,289.807922,14.763519,0.525798,-1293.550537,294.500488,0.000000
46.710003,65.744972,-1293.506104,-0.001293,0.002079,0.052814,292.448242,14.898024,0.528144,-1293.506104,294.500488,0.000000
47.010002,65.359566,-1293.506104,-0.001285,0.002078,0.052787,290.733856,14.810689,0.527872,-1293.506104,294.500488,0.000000
47.310001,65.369606,-1293.550537,-0.001281,0.002084,0.052936,290.778534,14.812964,0.529355,-1293.550537,294.500488,0.000000
47.610001,65.158104,-1293.550537,-0.001276,0.002084,0.052936,289.837708,14.765038,0.529355,-1293.550537,294.500488,0.000000
47.910004,64.916801,-1293.506104,-0.001276,0.002086,0.052987,288.764343,14.710358,0.529870,-1293.506104,294.500488,0.000000
48.210003,64.919792,-1293.550537,-0.001272,0.002090,0.053075,288.777649,14.711036,0.530748,-1293.550537,294.500488,0.000000
48.510002,65.919609,-1293.550537,-0.001259,0.002097,0.053266,293.225067,14.937597,0.532656,-1293.550537,294.500488,0.000000
48.810001,65.561760,-1293.461548,-0.001246,0.002097,0.053273,291.633270,14.856507,0.532732,-1293.461548,294.500488,0.000000
49.110001,65.181572,-1293.506104,-0.001263,0.002098,0.053282,289.942108,14.770355,0.532822,-1293.506104,294.500488,0.000000
49.410004,65.493980,-1293.550537,-0.001259,0.002107,0.053524,291.331787,14.841148,0.535245,-1293.550537,294.500488,0.000000
49.710003,65.263115,-1293.550537,-0.001246,0.002108,0.053552,290.304840,14.788833,0.535517,-1293.550537,294.500488,0.000000
50.010002,65.247841,-1293.461548,-0.001250,0.002112,0.053647,290.236877,14.785373,0.536471,-1293.461548,294.500488,0.000000
50.310001,65.160713,-1293.506104,-0.001246,0.002114,0.053699,289.849335,14.765629,0.536986,-1293.506104,294.500488,0.000000
50.610001,65.190880,-1293.506104,-0.001233,0.002118,0.053785,289.983521,14.772465,0.537849,-1293.506104,294.500488,0.000000
50.910004,65.142845,-1293.461548,-0.001242,0.002120,0.053845,289.769836,14.761580,0.538454,-1293.461548,294.500488,0.000000
51.210003,65.123482,-1293.550537,-0.001233,0.002127,0.054029,289.683716,14.757192,0.540286,-1293.550537,294.500488,0.000000
51.510002,65.479836,-1293.550537,-0.001233,0.002128,0.054054,291.268860,14.837942,0.540544,-1293.550537,294.500488,0.000000
51.810001,65.272423,-1293.506104,-0.001229,0.002129,0.054071,290.346252,14.790943,0.540710,-1293.506104,294.500488,0.000000
52.110001,65.251198,-1293.506104,-0.001233,0.002131,0.054132,290.251831,14.786133,0.541316,-1293.506104,294.500488,0.000000
52.410004,65.214714,-1293.550537,-0.001224,0.002134,0.054201,290.089539,14.777865,0.542012,-1293.550537,294.500488,0.000000
52.710003,65.193474,-1293.550537,-0.001224,0.002138,0.054306,289.995056,14.773052,0.543057,-1293.550537,294.500488,0.000000
53.010002,65.232582,-1293.506104,-0.001220,0.002140,0.054357,290.169006,14.781914,0.543571,-1293.506104,294.500488,0.000000
53.310001,65.129066,-1293.550537,-0.001224,0.002141,0.054375,289.708557,14.758457,0.543753,-1293.550537,294.500488,0.000000
53.610004,65.185661,-1293.506104,-0.001212,0.002144,0.054462,289.960297,14.771281,0.544616,-1293.506104,294.500488,0.000000
53.910004,65.138741,-1293.506104,-0.001212,0.002146,0.054513,289.751587,14.760650,0.545131,-1293.506104,294.500488,0.000000
54.210003,65.101875,-1293.550537,-0.001212,0.002148,0.054566,289.587616,14.752295,0.545661,-1293.550537,294.500488,0.000000
54.510002,65.246361,-1293.639526,-0.001199,0.002151,0.054643,290.230316,14.785036,0.546433,-1293.639526,294.500488,0.000000
54.810001,65.098900,-1293.550537,-0.001203,0.002152,0.054661,289.574371,14.751621,0.546615,-1293.550537,294.500488,0.000000
55.110004,65.342430,-1293.594971,-0.001190,0.002157,0.054783,290.657654,14.806807,0.547826,-1293.594971,294.500488,0.000000
55.410004,65.200188,-1293.594971,-0.001203,0.002157,0.054792,290.024933,14.774573,0.547917,-1293.594971,294.500488,0.000000
55.710003,65.079536,-1293.594971,-0.001199,0.002159,0.054834,289.488251,14.747233,0.548340,-1293.594971,294.500488,0.000000
56.010002,65.045647,-1293.550537,-0.001203,0.002161,0.054878,289.337494,14.739554,0.548779,-1293.550537,294.500488,0.000000
56.310001,64.987938,-1293.594971,-0.001186,0.002162,0.054913,289.080780,14.726477,0.549128,-1293.594971,294.500488,0.000000
56.610004,65.059059,-1293.594971,-0.001207,0.002165,0.054990,289.397156,14.742594,0.549900,-1293.594971,294.500488,0.000000
56.910004,65.030754,-1293.550537,-0.001186,0.002167,0.055034,289.271240,14.736180,0.550339,-1293.550537,294.500488,0.000000
57.210003,65.189751,-1293.594971,-0.001190,0.002171,0.055147,289.978485,14.772208,0.551474,-1293.594971,294.500488,0.000000
57.510002,65.171883,-1293.594971,-0.001186,0.002171,0.055147,289.899017,14.768160,0.551474,-1293.594971,294.500488,0.000000
57.810001,65.075066,-1293.594971,-0.001181,0.002174,0.055225,289.468353,14.746221,0.552246,-1293.594971,294.500488,0.000000
58.110004,65.113792,-1293.550537,-0.001186,0.002175,0.055243,289.640625,14.754995,0.552428,-1293.550537,294.500488,0.000000
58.410004,65.384880,-1293.550537,-0.001194,0.002180,0.055364,290.846466,14.816426,0.553639,-1293.550537,294.500488,0.000000
58.710003,65.285088,-1293.594971,-0.001177,0.002180,0.055364,290.402588,14.793813,0.553639,-1293.594971,294.500488,0.000000
59.010002,65.247475,-1293.639526,-0.001173,0.002182,0.055415,290.235260,14.785289,0.554154,-1293.639526,294.500488,0.000000
59.310001,65.237801,-1293.550537,-0.001155,0.002183,0.055459,290.192230,14.783097,0.554593,-1293.550537,294.500488,0.000000
59.610004,65.240028,-1293.550537,-0.001173,0.002185,0.055502,290.202148,14.783602,0.555017,-1293.550537,294.500488,0.000000
59.910004,65.345787,-1293.594971,-0.001168,0.002189,0.055590,290.672577,14.807567,0.555895,-1293.594971,294.500488,0.000000
60.210003,65.285454,-1293.550537,-0.001168,0.002189,0.055597,290.404205,14.793895,0.555971,-1293.550537,294.500488,0.000000
60.510002,65.268700,-1293.639526,-0.001173,0.002191,0.055641,290.329681,14.790098,0.556410,-1293.639526,294.500488,0.000000
60.810001,65.239662,-1293.550537,-0.001155,0.002192,0.055667,290.200500,14.783519,0.556667,-1293.550537,294.500488,0.000000
61.110004,65.174858,-1293.639526,-0.001155,0.002193,0.055692,289.912262,14.768834,0.556925,-1293.639526,294.500488,0.000000
61.410004,65.194603,-1293.550537,-0.001168,0.002195,0.055755,290.000092,14.773308,0.557545,-1293.550537,294.500488,0.000000
61.710003,65.130928,-1293.639526,-0.001160,0.002196,0.055771,289.716827,14.758880,0.557712,-1293.639526,294.500488,0.000000
62.010002,65.174492,-1293.594971,-0.001168,0.002198,0.055823,289.910614,14.768751,0.558227,-1293.594971,294.500488,0.000000
62.310001,65.139854,-1293.594971,-0.001143,0.002200,0.055876,289.756531,14.760902,0.558756,-1293.594971,294.500488,0.000000
62.610004,65.321571,-1293.594971,-0.001155,0.002202,0.055936,290.564850,14.802079,0.559362,-1293.594971,294.500488,0.000000
62.910004,65.240395,-1293.639526,-0.001164,0.002203,0.055953,290.203766,14.783685,0.559529,-1293.639526,294.500488,0.000000
63.210003,65.196083,-1293.639526,-0.001155,0.002204,0.055979,290.006653,14.773643,0.559786,-1293.639526,294.500488,0.000000
63.510002,65.152885,-1293.639526,-0.001143,0.002205,0.056006,289.814514,14.763855,0.560058,-1293.639526,294.500488,0.000000
63.810001,65.273918,-1293.594971,-0.001155,0.002208,0.056074,290.352875,14.791282,0.560740,-1293.594971,294.500488,0.000000
64.110001,65.187523,-1293.639526,-0.001151,0.002208,0.056092,289.968597,14.771704,0.560921,-1293.639526,294.500488,0.000000
64.410004,65.138741,-1293.594971,-0.001147,0.002210,0.056136,289.751587,14.760650,0.561360,-1293.594971,294.500488,0.000000
64.710007,65.098152,-1293.594971,-0.001151,0.002210,0.056136,289.571045,14.751452,0.561360,-1293.594971,294.500488,0.000000
65.010002,65.062401,-1293.683960,-0.001155,0.002212,0.056178,289.412018,14.743351,0.561784,-1293.683960,294.500488,0.000000
65.310005,65.009163,-1293.639526,-0.001143,0.002212,0.056188,289.175201,14.731286,0.561875,-1293.639526,294.500488,0.000000
65.610001,64.955162,-1293.594971,-0.001138,0.002213,0.056204,288.934998,14.719049,0.562042,-1293.594971,294.500488,0.000000
65.910004,64.907127,-1293.683960,-0.001138,0.002217,0.056309,288.721313,14.708166,0.563086,-1293.683960,294.500488,0.000000
66.210007,65.344658,-1293.683960,-0.001134,0.002220,0.056395,290.667542,14.807311,0.563949,-1293.683960,294.500488,0.000000
66.510002,65.293282,-1293.728516,-0.001143,0.002220,0.056395,290.439026,14.795669,0.563949,-1293.728516,294.500488,0.000000
66.810005,65.195351,-1293.639526,-0.001130,0.002220,0.056395,290.003418,14.773478,0.563949,-1293.639526,294.500488,0.000000
67.110001,65.180077,-1293.683960,-0.001138,0.002222,0.056448,289.935455,14.770016,0.564479,-1293.683960,294.500488,0.000000
67.410004,65.121239,-1293.639526,-0.001125,0.002223,0.056457,289.673737,14.756683,0.564570,-1293.639526,294.500488,0.000000
67.710007,65.053474,-1293.639526,-0.001134,0.002225,0.056508,289.372314,14.741328,0.565085,-1293.639526,294.500488,0.000000
68.010002,65.383766,-1293.639526,-0.001134,0.002228,0.056604,290.841522,14.816174,0.566039,-1293.639526,294.500488,0.000000
68.310005,65.323433,-1293.772949,-0.001134,0.002228,0.056604,290.573151,14.802502,0.566039,-1293.772949,294.500488,0.000000
68.610001,65.240776,-1293.728516,-0.001130,0.002229,0.056613,290.205475,14.783772,0.566129,-1293.728516,294.500488,0.000000
68.910004,65.251198,-1293.639526,-0.001125,0.002231,0.056655,290.251831,14.786133,0.566553,-1293.639526,294.500488,0.000000
69.210007,65.241142,-1293.728516,-0.001130,0.002232,0.056690,290.207092,14.783854,0.566902,-1293.728516,294.500488,0.000000
69.510002,65.323433,-1293.639526,-0.001125,0.002235,0.056760,290.573151,14.802502,0.567598,-1293.639526,294.500488,0.000000
69.810005,65.336098,-1293.728516,-0.001112,0.002235,0.056769,290.629486,14.805371,0.567689,-1293.728516,294.500488,0.000000
70.110001,65.314507,-1293.683960,-0.001130,0.002236,0.056795,290.533447,14.800479,0.567946,-1293.683960,294.500488,0.000000
70.410004,65.367012,-1293.683960,-0.001121,0.002238,0.056839,290.766998,14.812377,0.568385,-1293.683960,294.500488,0.000000
70.710007,65.305931,-1293.683960,-0.001117,0.002238,0.056855,290.495300,14.798535,0.568552,-1293.683960,294.500488,0.000000
71.010002,65.328651,-1293.683960,-0.001125,0.002240,0.056890,290.596344,14.803684,0.568900,-1293.683960,294.500488,0.000000
71.310005,65.314873,-1293.683960,-0.001117,0.002241,0.056916,290.535065,14.800561,0.569157,-1293.683960,294.500488,0.000000
71.610001,65.323067,-1293.728516,-0.001121,0.002242,0.056951,290.571503,14.802419,0.569506,-1293.728516,294.500488,0.000000
71.910004,65.356575,-1293.728516,-0.001117,0.002243,0.056976,290.720551,14.810012,0.569763,-1293.728516,294.500488,0.000000
72.210007,65.342064,-1293.772949,-0.001117,0.002245,0.057011,290.656006,14.806724,0.570111,-1293.772949,294.500488,0.000000
72.510002,65.334984,-1293.728516,-0.001104,0.002246,0.057046,290.624512,14.805119,0.570459,-1293.728516,294.500488,0.000000
72.810005,65.336479,-1293.728516,-0.001104,0.002247,0.057072,290.631165,14.805458,0.570717,-1293.728516,294.500488,0.000000
73.110001,65.314125,-1293.728516,-0.001112,0.002248,0.057090,290.531738,14.800392,0.570898,-1293.728516,294.500488,0.000000
73.410004,65.333122,-1293.772949,-0.001117,0.002249,0.057125,290.616241,14.804697,0.571247,-1293.772949,294.500488,0.000000
73.710007,65.340202,-1293.772949,-0.001099,0.002250,0.057141,290.647736,14.806301,0.571413,-1293.772949,294.500488,0.000000
74.010002,65.296257,-1293.728516,-0.001104,0.002250,0.057150,290.452271,14.796344,0.571504,-1293.728516,294.500488,0.000000
74.310005,65.325294,-1293.772949,-0.001091,0.002252,0.057211,290.581421,14.802923,0.572110,-1293.772949,294.500488,0.000000
74.610001,65.321205,-1293.772949,-0.001117,0.002253,0.057220,290.563232,14.801996,0.572200,-1293.772949,294.500488,0.000000
74.910004,65.276527,-1293.728516,-0.001091,0.002253,0.057237,290.364502,14.791872,0.572367,-1293.728516,294.500488,0.000000
75.210007,65.280617,-1293.728516,-0.001104,0.002254,0.057255,290.382690,14.792799,0.572549,-1293.728516,294.500488,0.000000
75.510002,65.324928,-1293.772949,-0.001104,0.002255,0.057288,290.579803,14.802840,0.572882,-1293.772949,294.500488,0.000000
75.810005,65.259758,-1293.772949,-0.001099,0.002256,0.057297,290.289886,14.788073,0.572973,-1293.772949,294.500488,0.000000
76.110001,65.253426,-1293.728516,-0.001099,0.002257,0.057323,290.261719,14.786638,0.573230,-1293.728516,294.500488,0.000000
76.410004,65.191246,-1293.728516,-0.001087,0.002257,0.057323,289.985138,14.772547,0.573230,-1293.728516,294.500488,0.000000
76.710007,65.228111,-1293.772949,-0.001099,0.002259,0.057367,290.149139,14.780901,0.573669,-1293.772949,294.500488,0.000000
77.010002,65.175606,-1293.728516,-0.001095,0.002259,0.057367,289.915588,14.769003,0.573669,-1293.728516,294.500488,0.000000
77.310005,65.091820,-1293.772949,-0.001095,0.002259,0.057367,289.542877,14.750017,0.573669,-1293.772949,294.500488,0.000000
77.610001,65.303703,-1293.772949,-0.001087,0.002263,0.057479,290.485382,14.798031,0.574789,-1293.772949,294.500488,0.000000
77.910004,65.282112,-1293.728516,-0.001095,0.002263,0.057479,290.389343,14.793138,0.574789,-1293.728516,294.500488,0.000000
78.210007,65.234810,-1293.728516,-0.001087,0.002263,0.057479,290.178925,14.782419,0.574789,-1293.728516,294.500488,0.000000
78.510002,65.160713,-1293.772949,-0.001091,0.002263,0.057488,289.849335,14.765629,0.574880,-1293.772949,294.500488,0.000000
78.810005,65.209496,-1293.772949,-0.001078,0.002265,0.057532,290.066315,14.776683,0.575319,-1293.772949,294.500488,0.000000
79.110001,65.152153,-1293.683960,-0.001078,0.002265,0.057541,289.811249,14.763689,0.575410,-1293.683960,294.500488,0.000000
79.410004,65.108574,-1293.683960,-0.001091,0.002266,0.057567,289.617401,14.753814,0.575667,-1293.683960,294.500488,0.000000
79.710007,65.179329,-1293.772949,-0.001074,0.002268,0.057602,289.932129,14.769847,0.576016,-1293.772949,294.500488,0.000000
80.010002,65.164070,-1293.683960,-0.001078,0.002269,0.057636,289.864258,14.766389,0.576364,-1293.683960,294.500488,0.000000
80.310005,65.180824,-1293.772949,-0.001091,0.002270,0.057653,289.938782,14.770185,0.576530,-1293.772949,294.500488,0.000000
80.610001,65.146187,-1293.683960,-0.001074,0.002271,0.057688,289.784698,14.762337,0.576879,-1293.683960,294.500488,0.000000
80.910004,65.340569,-1293.728516,-0.001069,0.002273,0.057739,290.649353,14.806384,0.577393,-1293.728516,294.500488,0.000000
81.210007,65.316734,-1293.728516,-0.001078,0.002273,0.057739,290.543335,14.800983,0.577393,-1293.728516,294.500488,0.000000
81.510002,65.275780,-1293.728516,-0.001069,0.002273,0.057739,290.361176,14.791703,0.577393,-1293.728516,294.500488,0.000000
81.810005,65.216576,-1293.772949,-0.001087,0.002274,0.057748,290.097809,14.778287,0.577484,-1293.772949,294.500488,0.000000
82.110001,65.205772,-1293.728516,-0.001078,0.002275,0.057774,290.049774,14.775839,0.577742,-1293.728516,294.500488,0.000000
82.410004,65.199440,-1293.772949,-0.001078,0.002275,0.057792,290.021606,14.774405,0.577923,-1293.772949,294.500488,0.000000
82.710007,65.142097,-1293.728516,-0.001061,0.002276,0.057809,289.766510,14.761411,0.578090,-1293.728516,294.500488,0.000000
83.010002,65.179329,-1293.683960,-0.001069,0.002277,0.057844,289.932129,14.769847,0.578438,-1293.683960,294.500488,0.000000
83.310005,65.198692,-1293.728516,-0.001069,0.002278,0.057870,290.018280,14.774235,0.578695,-1293.728516,294.500488,0.000000
83.610001,65.188637,-1293.772949,-0.001056,0.002279,0.057879,289.973541,14.771956,0.578786,-1293.772949,294.500488,0.000000
83.910004,65.162575,-1293.772949,-0.001069,0.002280,0.057904,289.857605,14.766050,0.579044,-1293.772949,294.500488,0.000000
84.210007,65.184166,-1293.728516,-0.001082,0.002281,0.057930,289.953644,14.770943,0.579301,-1293.728516,294.500488,0.000000
84.510002,65.195351,-1293.683960,-0.001074,0.002281,0.057939,290.003418,14.773478,0.579392,-1293.683960,294.500488,0.000000
84.810005,65.191612,-1293.728516,-0.001074,0.002283,0.057991,289.986786,14.772631,0.579906,-1293.728516,294.500488,0.000000
85.110001,65.229973,-1293.772949,-0.001074,0.002283,0.057991,290.157410,14.781323,0.579906,-1293.772949,294.500488,0.000000
85.410004,65.192360,-1293.772949,-0.001069,0.002283,0.057991,289.990112,14.772799,0.579906,-1293.772949,294.500488,0.000000
85.710007,65.179329,-1293.683960,-0.001052,0.002284,0.058018,289.932129,14.769847,0.580179,-1293.683960,294.500488,0.000000
86.010002,65.161461,-1293.728516,-0.001069,0.002284,0.058025,289.852661,14.765799,0.580255,-1293.728516,294.500488,0.000000
86.310005,65.188637,-1293.683960,-0.001056,0.002286,0.058060,289.973541,14.771956,0.580603,-1293.683960,294.500488,0.000000
86.610001,65.165932,-1293.772949,-0.001056,0.002286,0.058060,289.872528,14.766811,0.580603,-1293.772949,294.500488,0.000000
86.910004,65.118263,-1293.728516,-0.001069,0.002287,0.058078,289.660492,14.756009,0.580785,-1293.728516,294.500488,0.000000
87.210007,65.127205,-1293.728516,-0.001061,0.002288,0.058104,289.700287,14.758035,0.581042,-1293.728516,294.500488,0.000000
87.510002,65.144707,-1293.728516,-0.001069,0.002289,0.058148,289.778137,14.762002,0.581481,-1293.728516,294.500488,0.000000
87.810005,65.162209,-1293.683960,-0.001061,0.002289,0.058148,289.855988,14.765968,0.581481,-1293.683960,294.500488,0.000000
88.110001,65.122734,-1293.772949,-0.001065,0.002289,0.058148,289.680389,14.757022,0.581481,-1293.772949,294.500488,0.000000
88.410004,65.151772,-1293.817383,-0.001061,0.002291,0.058181,289.809540,14.763602,0.581814,-1293.817383,294.500488,0.000000
88.710007,65.111183,-1293.772949,-0.001056,0.002291,0.058181,289.628998,14.754405,0.581814,-1293.772949,294.500488,0.000000
89.010002,65.067253,-1293.728516,-0.001061,0.002291,0.058181,289.433594,14.744451,0.581814,-1293.728516,294.500488,0.000000
89.310005,65.150291,-1293.683960,-0.001048,0.002293,0.058243,289.802979,14.763268,0.582435,-1293.683960,294.500488,0.000000
89.610001,65.112679,-1293.772949,-0.001043,0.002293,0.058243,289.635651,14.754745,0.582435,-1293.772949,294.500488,0.000000
89.910004,65.103371,-1293.772949,-0.001048,0.002294,0.058260,289.594269,14.752634,0.582601,-1293.772949,294.500488,0.000000
90.210007,65.091454,-1293.772949,-0.001052,0.002294,0.058269,289.541260,14.749934,0.582692,-1293.772949,294.500488,0.000000
90.510002,65.071342,-1293.817383,-0.001056,0.002295,0.058295,289.451782,14.745378,0.582950,-1293.817383,294.500488,0.000000
90.810005,65.086983,-1293.728516,-0.001056,0.002296,0.058312,289.521362,14.748921,0.583116,-1293.728516,294.500488,0.000000
91.110001,65.152885,-1293.728516,-0.001061,0.002297,0.058346,289.814514,14.763855,0.583464,-1293.728516,294.500488,0.000000
91.410004,65.124962,-1293.772949,-0.001039,0.002297,0.058346,289.690308,14.757527,0.583464,-1293.772949,294.500488,0.000000
91.710007,65.102989,-1293.772949,-0.001039,0.002297,0.058356,289.592560,14.752548,0.583555,-1293.772949,294.500488,0.000000
92.010002,65.053474,-1293.683960,-0.001043,0.002297,0.058356,289.372314,14.741328,0.583555,-1293.683960,294.500488,0.000000
92.310005,65.091820,-1293.772949,-0.001052,0.002299,0.058407,289.542877,14.750017,0.584070,-1293.772949,294.500488,0.000000
92.610001,65.094429,-1293.772949,-0.001039,0.002299,0.058407,289.554474,14.750608,0.584070,-1293.772949,294.500488,0.000000
92.910004,65.076561,-1293.772949,-0.001039,0.002300,0.058416,289.475006,14.746559,0.584161,-1293.772949,294.500488,0.000000
93.210007,65.104118,-1293.772949,-0.001052,0.002301,0.058451,289.597595,14.752804,0.584509,-1293.772949,294.500488,0.000000
93.510002,65.097404,-1293.817383,-0.001039,0.002301,0.058451,289.567719,14.751283,0.584509,-1293.817383,294.500488,0.000000
93.810005,65.060539,-1293.817383,-0.001048,0.002301,0.058451,289.403748,14.742929,0.584509,-1293.817383,294.500488,0.000000
94.110008,65.257896,-1293.817383,-0.001056,0.002305,0.058546,290.281616,14.787651,0.585463,-1293.817383,294.500488,0.000000
94.410004,65.279503,-1293.772949,-0.001039,0.002305,0.058546,290.377716,14.792547,0.585463,-1293.772949,294.500488,0.000000
94.710007,65.262367,-1293.728516,-0.001048,0.002305,0.058546,290.301514,14.788664,0.585463,-1293.728516,294.500488,0.000000
95.010002,65.222160,-1293.817383,-0.001039,0.002305,0.058546,290.122650,14.779552,0.585463,-1293.817383,294.500488,0.000000
95.310005,65.182304,-1293.772949,-0.001035,0.002305,0.058555,289.945374,14.770521,0.585554,-1293.772949,294.500488,0.000000
95.610008,65.184166,-1293.817383,-0.001043,0.002306,0.058572,289.953644,14.770943,0.585720,-1293.817383,294.500488,0.000000
95.910004,65.195717,-1293.817383,-0.001043,0.002307,0.058598,290.005035,14.773561,0.585977,-1293.817383,294.500488,0.000000
96.210007,65.196831,-1293.817383,-0.001039,0.002307,0.058607,290.009979,14.773812,0.586068,-1293.817383,294.500488,0.000000
96.510002,65.151024,-1293.772949,-0.001035,0.002308,0.058625,289.806213,14.763433,0.586250,-1293.772949,294.500488,0.000000
96.810005,65.199074,-1293.861938,-0.001048,0.002309,0.058651,290.019958,14.774321,0.586507,-1293.861938,294.500488,0.000000
97.110008,65.252312,-1293.817383,-0.001035,0.002310,0.058676,290.256775,14.786386,0.586765,-1293.817383,294.500488,0.000000
97.410004,65.244118,-1293.728516,-0.001048,0.002310,0.058686,290.220337,14.784528,0.586856,-1293.728516,294.500488,0.000000
97.710007,65.209496,-1293.728516,-0.001018,0.002310,0.058686,290.066315,14.776683,0.586856,-1293.728516,294.500488,0.000000
98.010002,65.187523,-1293.772949,-0.001039,0.002311,0.058702,289.968597,14.771704,0.587022,-1293.772949,294.500488,0.000000
98.310005,65.236305,-1293.772949,-0.001022,0.002313,0.058746,290.185577,14.782759,0.587461,-1293.772949,294.500488,0.000000
98.610008,65.250832,-1293.772949,-0.001030,0.002313,0.058746,290.250183,14.786049,0.587461,-1293.772949,294.500488,0.000000
98.910004,65.230339,-1293.772949,-0.001030,0.002313,0.058746,290.159027,14.781406,0.587461,-1293.772949,294.500488,0.000000
99.210007,65.190880,-1293.772949,-0.001022,0.002313,0.058746,289.983521,14.772465,0.587461,-1293.772949,1681.640991,0.000000
99.510002,65.120125,-1293.861938,-0.001022,0.002305,0.058537,289.668793,14.756431,0.585372,-1293.861938,0.058686,0.000000
99.810005,65.024422,-1293.817383,-0.001035,0.002299,0.058390,289.243073,14.734745,0.583903,-1293.817383,0.058190,0.000000
100.110008,64.939522,-1293.817383,-0.001018,0.002280,0.057913,288.865417,14.715506,0.579134,-1293.817383,0.057688,0.000000
100.410004,64.779030,-1293.772949,-0.001013,0.002266,0.057549,288.151520,14.679137,0.575486,-1293.772949,0.057185,0.000000
100.710007,64.719078,-1293.772949,-0.001005,0.002247,0.057063,287.884827,14.665552,0.570626,-1293.772949,0.056690,0.000000
101.010002,64.707161,-1293.817383,-0.001013,0.002228,0.056586,287.831818,14.662852,0.565857,-1293.817383,0.056188,0.000000
101.310005,64.588753,-1293.817383,-0.001013,0.002209,0.056101,287.305115,14.636021,0.561012,-1293.817383,0.055692,0.000000
101.610008,64.512779,-1293.772949,-0.001013,0.002190,0.055632,286.967163,14.618804,0.556319,-1293.772949,0.055190,0.000000
101.910004,64.417824,-1293.817383,-0.001009,0.002171,0.055147,286.544800,14.597287,0.551474,-1293.817383,0.054687,0.000000
102.210007,64.338890,-1293.728516,-0.001005,0.002155,0.054739,286.193665,14.579401,0.547387,-1293.728516,0.054192,0.000000
102.510002,64.334419,-1293.728516,-0.001013,0.002140,0.054366,286.173798,14.578388,0.543662,-1293.728516,0.053689,0.000000
102.810005,64.167595,-1293.817383,-0.001009,0.002113,0.053680,285.431732,14.540585,0.536804,-1293.817383,0.053187,0.000000
103.110008,64.018639,-1293.772949,-0.001005,0.002096,0.053238,284.769135,14.506831,0.532383,-1293.772949,0.052692,0.000000
103.410004,63.707344,-1293.817383,-0.001005,0.002076,0.052727,283.384430,14.436291,0.527266,-1293.817383,0.052189,0.000000
103.710007,63.195702,-1293.817383,-0.000996,0.002059,0.052303,281.108521,14.320351,0.523027,-1293.817383,0.051687,0.000000
104.010002,62.490059,-1293.817383,-0.001009,0.002039,0.051791,277.969666,14.160450,0.517910,-1293.817383,0.051191,0.000000
104.310005,61.709564,-1293.861938,-0.000987,0.002023,0.051384,274.497864,13.983586,0.513837,-1293.861938,0.050689,0.000000
104.610008,60.994980,-1293.772949,-0.001005,0.002009,0.051028,271.319214,13.821660,0.510280,-1293.772949,0.050186,0.000000
104.910004,59.744186,-1293.817383,-0.001005,0.001988,0.050490,265.755402,13.538226,0.504905,-1293.817383,0.049693,0.000000
105.210007,58.466576,-1293.817383,-0.000987,0.001967,0.049970,260.072327,13.248715,0.499697,-1293.817383,0.049188,0.000000
105.510002,57.848434,-1293.817383,-0.000992,0.001959,0.049770,257.322693,13.108643,0.497699,-1293.817383,0.048686,0.000000
105.810005,56.128075,-1293.772949,-0.001000,0.001937,0.049188,249.670151,12.718803,0.491885,-1293.772949,0.048192,0.000000
106.110008,54.271423,-1293.772949,-0.001005,0.001914,0.048616,241.411346,12.298080,0.486162,-1293.772949,0.047688,0.000000
106.410004,52.424088,-1293.817383,-0.000992,0.001893,0.048079,233.193985,11.879468,0.480788,-1293.817383,0.047186,0.000000
106.710007,51.045189,-1293.861938,-0.000992,0.001880,0.047749,227.060333,11.567005,0.477487,-1293.861938,0.046692,0.000000
107.010002,48.412514,-1293.817383,-0.001000,0.001854,0.047081,215.349609,10.970432,0.470811,-1293.817383,0.046188,0.000000
107.310005,46.765137,-1293.728516,-0.001005,0.001838,0.046674,208.021713,10.597131,0.466738,-1293.728516,0.045685,0.000000
107.610008,44.371529,-1293.772949,-0.001009,0.001813,0.046058,197.374420,10.054732,0.460576,-1293.772949,0.045192,0.000000
107.910004,42.436684,-1293.817383,-0.001013,0.001796,0.045625,188.767792,9.616290,0.456246,-1293.817383,0.044687,0.000000
108.210007,40.033394,-1293.817383,-0.001009,0.001774,0.045061,178.077423,9.071697,0.450614,-1293.817383,0.044185,0.000000
108.510002,38.445595,-1293.817383,-0.001018,0.001760,0.044697,171.014542,8.711896,0.446966,-1293.817383,0.043691,0.000000
108.810005,35.790207,-1293.772949,-0.001009,0.001732,0.043994,159.202789,8.110177,0.439941,-1293.772949,0.043187,0.000000
109.110008,34.338699,-1293.817383,-0.001035,0.001719,0.043656,152.746170,7.781260,0.436565,-1293.817383,0.042685,0.000000
109.410004,32.756859,-1293.772949,-0.001039,0.001700,0.043180,145.709778,7.422810,0.431796,-1293.772949,0.042191,0.000000
109.710007,31.550003,-1293.861938,-0.001035,0.001682,0.042719,140.341415,7.149333,0.427194,-1293.861938,0.041687,0.000000
110.010002,28.793701,-1293.817383,-0.001035,0.001663,0.042252,128.080780,6.524746,0.422515,-1293.817383,0.041184,0.000000
110.310005,26.960884,-1293.728516,-0.001048,0.001646,0.041817,119.928001,6.109424,0.418170,-1293.728516,0.040691,0.000000
110.610008,24.709145,-1293.861938,-0.001043,0.001625,0.041270,109.911766,5.599172,0.412705,-1293.861938,0.040186,0.000000
110.910004,22.200478,-1293.772949,-0.001043,0.001600,0.040630,98.752655,5.030700,0.406301,-1293.772949,0.039684,0.000000
111.210007,20.568741,-1293.861938,-0.001043,0.001584,0.040239,91.494331,4.660943,0.402395,-1293.861938,0.039190,0.000000
111.510002,18.376579,-1293.728516,-0.001069,0.001561,0.039658,81.743111,4.164193,0.396581,-1293.728516,0.038686,0.000000
111.810005,16.589195,-1293.817383,-0.001056,0.001542,0.039155,73.792427,3.759165,0.391555,-1293.817383,0.038184,0.000000
112.110008,14.312881,-1293.772949,-0.001056,0.001522,0.038660,63.666878,3.243345,0.386604,-1293.772949,0.037690,0.000000
112.410004,12.821526,-1293.817383,-0.001078,0.001507,0.038279,57.032993,2.905399,0.382789,-1293.817383,0.037186,0.000000
112.710007,11.251610,-1293.772949,-0.001074,0.001486,0.037751,50.049660,2.549651,0.377505,-1293.772949,0.036683,0.000000
113.010002,8.728409,-1293.861938,-0.001091,0.001465,0.037213,38.825901,1.977886,0.372131,-1293.861938,0.036190,0.000000
113.310005,7.006561,-1293.772949,-0.001082,0.001448,0.036788,31.166740,1.587709,0.367877,-1293.772949,0.035686,0.000000
113.610008,5.389717,-1293.772949,-0.001091,0.001429,0.036302,23.974659,1.221327,0.363017,-1293.772949,0.035183,0.000000
113.910004,3.197563,-1293.728516,-0.001095,0.001408,0.035755,14.223472,0.724578,0.357551,-1293.728516,0.034689,0.000000
114.210007,1.824623,-1293.772949,-0.001108,0.001393,0.035383,8.116329,0.413465,0.353827,-1293.772949,0.034185,0.000000
114.510002,0.214859,-1293.861938,-0.001099,0.001376,0.034957,0.955741,0.048688,0.349573,-1293.861938,0.033692,0.000000
114.810005,-2.461384,-1293.817383,-0.001125,0.001345,0.034159,-10.948782,-0.557758,0.341594,-1293.817383,0.033189,0.000000
115.110008,-3.623558,-1293.817383,-0.001125,0.001328,0.033726,-16.118391,-0.821110,0.337264,-1293.817383,0.032686,0.000000
115.410004,-0.290451,-1293.817383,-0.001181,0.001308,0.033215,-1.291991,-0.065817,0.332147,-1293.817383,0.032191,0.000000
115.710007,-0.103149,-1293.728516,-0.001203,0.001289,0.032747,-0.458832,-0.023374,0.327469,-1293.728516,0.031689,0.000000
116.010002,-0.079315,-1293.772949,-0.001242,0.001271,0.032296,-0.352812,-0.017973,0.322958,-1293.772949,0.031186,0.000000
116.310005,-0.045799,-1293.772949,-0.001255,0.001254,0.031854,-0.203725,-0.010378,0.318537,-1293.772949,0.030691,0.000000
116.610008,-0.040962,-1293.772949,-0.001289,0.001228,0.031186,-0.182209,-0.009282,0.311860,-1293.772949,0.030188,0.000000
116.910004,-0.034630,-1293.772949,-0.001315,0.001213,0.030803,-0.154041,-0.007847,0.308030,-1293.772949,0.029686,0.000000
117.210007,0.001114,-1293.817383,-0.001345,0.001192,0.030275,0.004955,0.000252,0.302746,-1293.817383,0.029191,0.000000
117.510002,0.009682,-1293.772949,-0.001362,0.001172,0.029763,0.043066,0.002194,0.297629,-1293.772949,0.028688,0.000000
117.810005,0.004097,-1293.728516,-0.001410,0.001150,0.029216,0.018224,0.000928,0.292164,-1293.728516,0.028185,0.000000
118.110008,0.016388,-1293.728516,-0.001436,0.001128,0.028653,0.072897,0.003714,0.286532,-1293.728516,0.027690,0.000000
118.410004,-0.001114,-1293.772949,-0.001453,0.001105,0.028055,-0.004955,-0.000252,0.280552,-1293.772949,0.027188,0.000000
118.710007,-0.016388,-1293.817383,-0.001466,0.001088,0.027646,-0.072897,-0.003714,0.276464,-1293.817383,0.026685,0.000000
119.010002,-0.006332,-1293.861938,-0.001492,0.001076,0.027318,-0.028168,-0.001435,0.273179,-1293.861938,0.026190,0.000000
119.310005,0.009682,-1293.772949,-0.001513,0.001054,0.026780,0.043066,0.002194,0.267804,-1293.772949,0.025687,0.000000
119.610008,0.025696,-1293.728516,-0.001535,0.001031,0.026190,0.114301,0.005823,0.261900,-1293.728516,0.025185,0.000000
119.910004,0.017128,-1293.728516,-0.001565,0.001008,0.025601,0.076189,0.003881,0.256010,-1293.728516,0.024690,0.000000
120.210007,0.005959,-1293.772949,-0.001587,0.000997,0.025315,0.026505,0.001350,0.253149,-1293.772949,0.025157,0.000000
120.300003,0.009308,-1293.728516,-0.001574,0.000997,0.025322,0.041403,0.002109,0.253225,-1293.728516,0.025157,0.000000