File: Data/Sima compression/P1-11-2_10302024_163052.csv
Time (sec),S:Load (lbs),S:HL1 (DIM),S:LVDT (in),S:Position (in),Ch:Position (mm),Ch:Load (N),Ch:Stress (MPa),Ch:Strain (mm/mm),Ch:HL1 (DIM),Set Point (),Cycles ()
0.210000,0.024948,-1291.459961,-0.011507,-0.005739,-0.145771,0.110975,0.005653,-1.457714,-1291.459961,-0.145555,0.000000
0.780000,0.037613,-1291.459961,-0.011456,-0.005518,-0.140168,0.167311,0.008523,-1.401683,-1291.459961,-0.139016,0.000000
1.350000,0.052879,-1291.415405,-0.011089,-0.005148,-0.130751,0.235219,0.011983,-1.307515,-1291.415405,-0.129528,0.000000
1.920000,-0.000000,-1291.370972,-0.010718,-0.004773,-0.121238,-0.000000,-0.000000,-1.212378,-1291.370972,-0.120024,0.000000
2.490000,0.019737,-1291.415405,-0.010335,-0.004389,-0.111482,0.087796,0.004473,-1.114818,-1291.415405,-0.110536,0.000000
3.060000,0.039474,-1291.415405,-0.009977,-0.004019,-0.102071,0.175591,0.008945,-1.020710,-1291.415405,-0.101031,0.000000
3.630000,0.068886,-1291.415405,-0.009830,0.000029,0.000728,0.306419,0.015610,0.007282,-1291.415405,0.000849,0.000000
4.200000,0.110596,-1291.459961,-0.009826,0.000029,0.000728,0.491954,0.025061,0.007282,-1291.459961,0.001596,0.000000
4.770000,0.043564,-1291.459961,-0.009835,0.000059,0.001500,0.193782,0.009872,0.015003,-1291.459961,0.002550,0.000000
5.340000,0.074104,-1291.415405,-0.009804,0.000099,0.002524,0.329632,0.016792,0.025238,-1291.415405,0.003494,0.000000
5.910000,0.095329,-1291.459961,-0.009766,0.000141,0.003590,0.424046,0.021602,0.035896,-1291.459961,0.004448,0.000000
6.480000,0.068146,-1291.459961,-0.009727,0.000175,0.004457,0.303127,0.015442,0.044571,-1291.459961,0.005394,0.000000
7.050000,0.078201,-1291.415405,-0.009666,0.000218,0.005532,0.347857,0.017721,0.055320,-1291.415405,0.006348,0.000000
7.620000,0.078941,-1291.459961,-0.009649,0.000245,0.006218,0.351149,0.017888,0.062178,-1291.459961,0.007302,0.000000
8.190001,0.084526,-1291.415405,-0.009623,0.000280,0.007102,0.375991,0.019154,0.071020,-1291.415405,0.008247,0.000000
8.760000,0.017876,-1291.459961,-0.009602,0.000314,0.007986,0.079515,0.004051,0.079861,-1291.459961,0.009200,0.000000
9.330001,0.042450,-1291.459961,-0.009554,0.000356,0.009053,0.188827,0.009619,0.090535,-1291.459961,0.010147,0.000000
9.900001,0.048782,-1291.504395,-0.009507,0.000395,0.010033,0.216995,0.011054,0.100330,-1291.504395,0.011100,0.000000
10.470000,0.025696,-1291.415405,-0.009464,0.000433,0.011005,0.114301,0.005823,0.110050,-1291.415405,0.012045,0.000000
11.040001,0.048035,-1291.459961,-0.009438,0.000469,0.011906,0.213669,0.010885,0.119058,-1291.459961,0.012999,0.000000
11.610001,0.076706,-1291.459961,-0.009412,0.000504,0.012799,0.341205,0.017382,0.127990,-1291.459961,0.013945,0.000000
12.180000,0.003349,-1291.459961,-0.009347,0.000548,0.013910,0.014898,0.000759,0.139102,-1291.459961,0.014899,0.000000
12.750001,0.032768,-1291.459961,-0.009309,0.000588,0.014925,0.145760,0.007425,0.149246,-1291.459961,0.015853,0.000000
13.320001,0.067024,-1291.504395,-0.009274,0.000619,0.015732,0.298139,0.015188,0.157315,-1291.504395,0.016797,0.000000
13.890000,0.021599,-1291.548950,-0.009231,0.000665,0.016893,0.096076,0.004894,0.168927,-1291.548950,0.017751,0.000000
14.460001,-0.011169,-1291.548950,-0.009192,0.000698,0.017735,-0.049684,-0.002531,0.177345,-1291.548950,0.018697,0.000000
15.030001,0.037979,-1291.548950,-0.009171,0.000731,0.018575,0.168940,0.008606,0.185748,-1291.548950,0.019651,0.000000
15.600000,0.047661,-1291.548950,-0.009132,0.000764,0.019417,0.212006,0.010800,0.194165,-1291.548950,0.020596,0.000000
16.170000,-0.013031,-1291.548950,-0.009084,0.000807,0.020510,-0.057965,-0.002953,0.205096,-1291.548950,0.021550,0.000000
16.740002,0.021599,-1291.415405,-0.009046,0.000848,0.021550,0.096076,0.004894,0.215497,-1291.415405,0.022496,0.000000
17.310001,0.080063,-1291.548950,-0.009011,0.000878,0.022296,0.356137,0.018143,0.222961,-1291.548950,0.023450,0.000000
17.880001,0.015266,-1291.593384,-0.008977,0.000927,0.023545,0.067908,0.003459,0.235451,-1291.593384,0.024394,0.000000
18.450001,0.013405,-1291.593384,-0.008916,0.000961,0.024403,0.059628,0.003038,0.244035,-1291.593384,0.025348,0.000000
19.020000,0.075966,-1291.593384,-0.008912,0.000992,0.025201,0.337913,0.017214,0.252013,-1291.593384,0.026302,0.000000
19.590000,0.091606,-1291.504395,-0.008856,0.001038,0.026372,0.407484,0.020758,0.263716,-1291.504395,0.027248,0.000000
20.160002,0.074104,-1291.548950,-0.008804,0.001074,0.027283,0.329632,0.016792,0.272830,-1291.548950,0.028202,0.000000
20.730001,0.081177,-1291.504395,-0.008774,0.001109,0.028167,0.361092,0.018395,0.281672,-1291.504395,0.029147,0.000000
21.300001,0.101654,-1291.504395,-0.008757,0.001141,0.028991,0.452180,0.023035,0.289908,-1291.504395,0.030101,0.000000
21.870001,0.067772,-1291.593384,-0.008692,0.001188,0.030170,0.301465,0.015357,0.301702,-1291.593384,0.031047,0.000000
22.440001,0.077827,-1291.548950,-0.008666,0.001226,0.031150,0.346194,0.017636,0.311497,-1291.548950,0.032001,0.000000
23.010000,0.103889,-1291.548950,-0.008623,0.001256,0.031896,0.462123,0.023542,0.318961,-1291.548950,0.032945,0.000000
23.580002,0.084900,-1291.504395,-0.008589,0.001302,0.033075,0.377654,0.019239,0.330754,-1291.504395,0.033899,0.000000
24.150002,0.066658,-1291.548950,-0.008541,0.001335,0.033908,0.296510,0.015105,0.339081,-1291.548950,0.034853,0.000000
24.720001,0.092720,-1291.593384,-0.008507,0.001373,0.034871,0.412439,0.021011,0.348710,-1291.593384,0.035799,0.000000
25.290001,0.119904,-1291.548950,-0.008464,0.001415,0.035937,0.533358,0.027171,0.359368,-1291.548950,0.036753,0.000000
25.860001,0.075966,-1291.548950,-0.008429,0.001448,0.036788,0.337913,0.017214,0.367877,-1291.548950,0.037698,0.000000
26.430000,0.113205,-1291.548950,-0.008386,0.001485,0.037707,0.503561,0.025653,0.377066,-1291.548950,0.038651,0.000000
27.000002,0.103149,-1291.593384,-0.008382,0.001515,0.038486,0.458832,0.023374,0.384863,-1291.593384,0.039598,0.000000
27.570002,0.103889,-1291.593384,-0.008326,0.001561,0.039658,0.462123,0.023542,0.396581,-1291.593384,0.040551,0.000000
28.140001,0.090111,-1291.637817,-0.008287,0.001596,0.040533,0.400833,0.020419,0.405332,-1291.637817,0.041496,0.000000
28.710001,0.097565,-1291.548950,-0.008248,0.001632,0.041445,0.433989,0.022108,0.414446,-1291.548950,0.042450,0.000000
29.280001,0.088623,-1291.548950,-0.008222,0.001659,0.042129,0.394215,0.020082,0.421289,-1291.548950,0.043404,0.000000
29.850002,0.036491,-1291.593384,-0.008188,0.001704,0.043283,0.162322,0.008269,0.432825,-1291.593384,0.044350,0.000000
30.420002,0.064423,-1291.682373,-0.008157,0.001736,0.044099,0.286566,0.014598,0.440986,-1291.682373,0.045304,0.000000
30.990002,0.067024,-1291.682373,-0.008093,0.001774,0.045052,0.298139,0.015188,0.450524,-1291.682373,0.046248,0.000000
31.560001,0.037613,-1291.548950,-0.008054,0.001817,0.046153,0.167311,0.008523,0.461530,-1291.548950,0.047202,0.000000
32.130001,0.042824,-1291.637817,-0.008032,0.001855,0.047116,0.190490,0.009704,0.471159,-1291.637817,0.048148,0.000000
32.700001,0.087135,-1291.593384,-0.007989,0.001894,0.048095,0.387597,0.019745,0.480954,-1291.593384,0.049102,0.000000
33.270000,0.060326,-1291.637817,-0.007950,0.001937,0.049198,0.268342,0.013670,0.491976,-1291.637817,0.050047,0.000000
33.840000,0.024200,-1291.726807,-0.007916,0.001970,0.050030,0.107649,0.005484,0.500303,-1291.726807,0.051001,0.000000
34.410000,0.062187,-1291.726807,-0.007877,0.002004,0.050905,0.276622,0.014092,0.509053,-1291.726807,0.051954,0.000000
34.980003,0.029045,-1291.637817,-0.007834,0.002040,0.051808,0.129199,0.006582,0.518076,-1291.637817,0.052901,0.000000
35.550003,0.004097,-1291.593384,-0.007787,0.002084,0.052943,0.018224,0.000928,0.529431,-1291.593384,0.053855,0.000000
36.120003,0.020477,-1291.726807,-0.007765,0.002113,0.053680,0.091088,0.004640,0.536804,-1291.726807,0.054799,0.000000
36.690002,0.066284,-1291.726807,-0.007726,0.002153,0.054687,0.294847,0.015020,0.546872,-1291.726807,0.055753,0.000000
37.260002,0.044685,-1291.682373,-0.007662,0.002194,0.055718,0.198770,0.010126,0.557182,-1291.682373,0.056699,0.000000
37.830002,-0.025696,-1291.726807,-0.007640,0.002228,0.056604,-0.114301,-0.005823,0.566039,-1291.726807,0.057653,0.000000
38.400002,0.047661,-1291.726807,-0.007614,0.002264,0.057497,0.212006,0.010800,0.574971,-1291.726807,0.058598,0.000000
38.970001,0.043564,-1291.682373,-0.007537,0.002315,0.058789,0.193782,0.009872,0.587885,-1291.682373,0.059552,0.000000
39.540001,0.017502,-1291.682373,-0.007519,0.002345,0.059561,0.077852,0.003966,0.595606,-1291.682373,0.060498,0.000000
40.110001,0.099792,-1291.726807,-0.007468,0.002383,0.060523,0.443899,0.022613,0.605235,-1291.726807,0.061452,0.000000
40.680000,0.088623,-1291.771240,-0.007446,0.002410,0.061208,0.394215,0.020082,0.612078,-1291.771240,0.062405,0.000000
41.250004,0.070381,-1291.726807,-0.007381,0.002459,0.062448,0.313071,0.015949,0.624477,-1291.726807,0.063350,0.000000
41.820004,0.071869,-1291.682373,-0.007351,0.002497,0.063436,0.319689,0.016286,0.634364,-1291.682373,0.064304,0.000000
42.390003,0.097931,-1291.726807,-0.007312,0.002528,0.064201,0.435618,0.022191,0.642009,-1291.726807,0.065250,0.000000
42.960003,0.087883,-1291.771240,-0.007256,0.002570,0.065285,0.390923,0.019915,0.652849,-1291.771240,0.066204,0.000000
43.530003,0.060326,-1291.726807,-0.007222,0.002605,0.066178,0.268342,0.013670,0.661781,-1291.726807,0.067149,0.000000
44.100002,0.080063,-1291.637817,-0.007183,0.002643,0.067139,0.356137,0.018143,0.671395,-1291.637817,0.068102,0.000000
44.670002,0.108360,-1291.726807,-0.007148,0.002685,0.068207,0.482011,0.024555,0.682068,-1291.726807,0.069049,0.000000
45.240002,0.063301,-1291.726807,-0.007114,0.002720,0.069100,0.281577,0.014344,0.691001,-1291.726807,0.070002,0.000000
45.810001,0.082291,-1291.726807,-0.007088,0.002760,0.070114,0.366047,0.018647,0.701144,-1291.726807,0.070956,0.000000
46.380001,0.121017,-1291.815796,-0.007045,0.002786,0.070775,0.538313,0.027423,0.707745,-1291.815796,0.071901,0.000000
46.950001,0.073357,-1291.771240,-0.006989,0.002833,0.071961,0.326307,0.016623,0.719615,-1291.771240,0.072855,0.000000
47.520000,0.082664,-1291.726807,-0.006972,0.002871,0.072915,0.367710,0.018732,0.729152,-1291.726807,0.073801,0.000000
48.090004,0.067024,-1291.682373,-0.006929,0.002899,0.073627,0.298139,0.015188,0.736268,-1291.682373,0.074755,0.000000
48.660004,0.100540,-1291.726807,-0.006873,0.002945,0.074806,0.447225,0.022783,0.748062,-1291.726807,0.075699,0.000000
49.230003,0.065910,-1291.771240,-0.006834,0.002978,0.075639,0.293184,0.014935,0.756389,-1291.771240,0.076653,0.000000
49.800003,0.102776,-1291.771240,-0.006804,0.003020,0.076706,0.457169,0.023289,0.767062,-1291.771240,0.077599,0.000000
50.370003,0.084900,-1291.726807,-0.006782,0.003049,0.077451,0.377654,0.019239,0.774511,-1291.726807,0.078553,0.000000
50.940002,0.037239,-1291.682373,-0.006739,0.003089,0.078449,0.165648,0.008438,0.784488,-1291.682373,0.079507,0.000000
51.510002,0.043938,-1291.771240,-0.006700,0.003116,0.079151,0.195445,0.009956,0.791512,-1291.771240,0.080452,0.000000
52.080002,0.082291,-1291.771240,-0.006679,0.003163,0.080347,0.366047,0.018647,0.803473,-1291.771240,0.081406,0.000000
52.650002,0.061440,-1291.726807,-0.006622,0.003198,0.081224,0.273297,0.013922,0.812238,-1291.726807,0.082352,0.000000
53.220001,0.049156,-1291.726807,-0.006584,0.003239,0.082282,0.218658,0.011139,0.822821,-1291.726807,0.083306,0.000000
53.790001,0.071121,-1291.771240,-0.006554,0.003275,0.083184,0.316363,0.016116,0.831844,-1291.771240,0.084250,0.000000
54.360004,0.068520,-1291.771240,-0.006523,0.003311,0.084111,0.304790,0.015527,0.841110,-1291.771240,0.085204,0.000000
54.930004,0.021225,-1291.815796,-0.006493,0.003354,0.085196,0.094413,0.004810,0.851965,-1291.815796,0.086150,0.000000
55.500004,0.072609,-1291.815796,-0.006446,0.003393,0.086185,0.322981,0.016453,0.861851,-1291.815796,0.087104,0.000000
56.070004,0.088623,-1291.815796,-0.006420,0.003425,0.086983,0.394215,0.020082,0.869829,-1291.815796,0.088049,0.000000
56.640003,0.068146,-1291.815796,-0.006351,0.003470,0.088127,0.303127,0.015442,0.881275,-1291.815796,0.089003,0.000000
57.210003,0.013031,-1291.682373,-0.006325,0.003500,0.088891,0.057965,0.002953,0.888905,-1291.682373,0.089956,0.000000
57.780003,0.052505,-1291.815796,-0.006303,0.003534,0.089766,0.233556,0.011898,0.897656,-1291.815796,0.090903,0.000000
58.350002,0.054741,-1291.860229,-0.006265,0.003581,0.090963,0.243500,0.012404,0.909631,-1291.860229,0.091856,0.000000
58.920002,-0.020111,-1291.815796,-0.006226,0.003614,0.091787,-0.089459,-0.004557,0.917867,-1291.815796,0.092801,0.000000
59.490002,0.057343,-1291.771240,-0.006161,0.003653,0.092775,0.255072,0.012994,0.927753,-1291.771240,0.093755,0.000000
60.060001,0.077080,-1291.771240,-0.006161,0.003682,0.093529,0.342868,0.017467,0.935293,-1291.771240,0.094701,0.000000
60.630001,0.041702,-1291.771240,-0.006101,0.003731,0.094778,0.185501,0.009450,0.947783,-1291.771240,0.095655,0.000000
61.200005,0.052505,-1291.860229,-0.006084,0.003768,0.095706,0.233556,0.011898,0.957064,-1291.860229,0.096600,0.000000
61.770004,0.111336,-1291.860229,-0.006036,0.003798,0.096469,0.495246,0.025229,0.964694,-1291.860229,0.097553,0.000000
62.340004,0.088997,-1291.860229,-0.005928,0.003839,0.097519,0.395878,0.020167,0.975186,-1291.860229,0.098507,0.000000
62.910004,0.067398,-1291.771240,-0.005933,0.003876,0.098447,0.299802,0.015273,0.984466,-1291.771240,0.099453,0.000000
63.480003,0.093468,-1291.815796,-0.005894,0.003914,0.099426,0.415765,0.021180,0.994262,-1291.815796,0.100407,0.000000
64.050003,0.106499,-1291.860229,-0.005881,0.003955,0.100450,0.473730,0.024133,1.004496,-1291.860229,0.101352,0.000000
64.620003,0.078941,-1291.904785,-0.005821,0.003991,0.101378,0.351149,0.017888,1.013777,-1291.904785,0.102306,0.000000
65.190002,0.111710,-1291.904785,-0.005777,0.004028,0.102315,0.496909,0.025314,1.023148,-1291.904785,0.103252,0.000000
65.760002,0.122887,-1291.815796,-0.005756,0.004064,0.103225,0.546627,0.027847,1.032247,-1291.815796,0.104206,0.000000
66.330002,0.094208,-1291.815796,-0.005717,0.004104,0.104241,0.419057,0.021348,1.042405,-1291.815796,0.105150,0.000000
66.900002,0.065910,-1291.815796,-0.005691,0.004145,0.105281,0.293184,0.014935,1.052806,-1291.815796,0.106104,0.000000
67.470001,0.129959,-1291.949219,-0.005657,0.004177,0.106104,0.578087,0.029449,1.061042,-1291.949219,0.107058,0.000000
68.040001,0.115433,-1291.815796,-0.005596,0.004215,0.107067,0.513470,0.026157,1.070671,-1291.815796,0.108004,0.000000
68.610001,0.089371,-1291.860229,-0.005558,0.004252,0.108004,0.397541,0.020252,1.080042,-1291.860229,0.108958,0.000000
69.180000,0.097931,-1291.860229,-0.005523,0.004290,0.108958,0.435618,0.022191,1.089580,-1291.860229,0.109903,0.000000
69.750000,0.110222,-1291.860229,-0.005493,0.004326,0.109868,0.490291,0.024977,1.098679,-1291.860229,0.110857,0.000000
70.320000,0.087883,-1291.904785,-0.005454,0.004364,0.110840,0.390923,0.019915,1.108399,-1291.904785,0.111803,0.000000
70.890007,0.099052,-1291.904785,-0.005415,0.004402,0.111819,0.440607,0.022446,1.118194,-1291.904785,0.112757,0.000000
71.460007,0.108734,-1291.904785,-0.005381,0.004434,0.112635,0.483674,0.024640,1.126354,-1291.904785,0.113701,0.000000
72.030006,0.088249,-1291.904785,-0.005346,0.004470,0.113536,0.392552,0.019998,1.135363,-1291.904785,0.114655,0.000000
72.600006,0.062561,-1291.904785,-0.005290,0.004507,0.114482,0.278285,0.014177,1.144825,-1291.904785,0.115609,0.000000
73.170006,0.074478,-1291.904785,-0.005264,0.004542,0.115358,0.331295,0.016877,1.153575,-1291.904785,0.116555,0.000000
73.740005,0.070007,-1291.993652,-0.005226,0.004586,0.116476,0.311408,0.015864,1.164764,-1291.993652,0.117509,0.000000
74.310005,0.042076,-1291.949219,-0.005174,0.004624,0.117439,0.187164,0.009535,1.174392,-1291.949219,0.118454,0.000000
74.880005,0.080803,-1291.860229,-0.005148,0.004659,0.118332,0.359429,0.018310,1.183325,-1291.860229,0.119407,0.000000
75.450005,0.095329,-1291.904785,-0.005096,0.004693,0.119209,0.424046,0.021602,1.192091,-1291.904785,0.120354,0.000000
76.020004,0.082664,-1291.904785,-0.005053,0.004739,0.120361,0.367710,0.018732,1.203612,-1291.904785,0.121307,0.000000
76.590004,0.032768,-1291.949219,-0.005036,0.004775,0.121289,0.145760,0.007425,1.212892,-1291.949219,0.122252,0.000000
77.160004,0.094208,-1291.949219,-0.004984,0.004806,0.122070,0.419057,0.021348,1.220704,-1291.949219,0.123206,0.000000
77.730003,0.056976,-1291.904785,-0.004963,0.004855,0.123319,0.253443,0.012911,1.233194,-1291.904785,0.124152,0.000000
78.300003,0.002975,-1291.949219,-0.004898,0.004885,0.124092,0.013236,0.000674,1.240916,-1291.949219,0.125106,0.000000
78.870003,0.058090,-1292.038208,-0.004889,0.004923,0.125036,0.258398,0.013163,1.250363,-1292.038208,0.126060,0.000000
79.440002,0.037239,-1291.993652,-0.004825,0.004958,0.125939,0.165648,0.008438,1.259386,-1291.993652,0.127004,0.000000
80.010002,0.006706,-1291.949219,-0.004781,0.004999,0.126979,0.029831,0.001520,1.269787,-1291.949219,0.127958,0.000000
80.580002,0.027931,-1291.993652,-0.004751,0.005037,0.127942,0.124244,0.006329,1.279416,-1291.993652,0.128904,0.000000
81.150002,0.087509,-1291.949219,-0.004717,0.005070,0.128774,0.389260,0.019830,1.287742,-1291.949219,0.129858,0.000000
81.720001,0.077080,-1291.904785,-0.004656,0.005115,0.129928,0.342868,0.017467,1.299279,-1291.904785,0.130803,0.000000
82.290001,0.025696,-1292.038208,-0.004635,0.005150,0.130812,0.114301,0.005823,1.308120,-1292.038208,0.131757,0.000000
82.860001,0.083786,-1291.993652,-0.004583,0.005184,0.131680,0.372699,0.018986,1.316795,-1291.993652,0.132703,0.000000
83.430000,0.099426,-1291.949219,-0.004566,0.005219,0.132555,0.442270,0.022530,1.325546,-1291.949219,0.133657,0.000000
84.000008,0.092720,-1291.993652,-0.004527,0.005264,0.133717,0.412439,0.021011,1.337173,-1291.993652,0.134611,0.000000
84.570007,0.100914,-1291.993652,-0.004471,0.005303,0.134697,0.448888,0.022867,1.346968,-1291.993652,0.135555,0.000000
85.140007,0.103889,-1291.993652,-0.004454,0.005330,0.135390,0.462123,0.023542,1.353902,-1291.993652,0.136509,0.000000
85.710007,0.065536,-1291.993652,-0.004393,0.005377,0.136588,0.291521,0.014851,1.365878,-1291.993652,0.137455,0.000000
86.280006,0.062187,-1291.949219,-0.004359,0.005409,0.137395,0.276622,0.014092,1.373947,-1291.949219,0.138409,0.000000
86.850006,0.107986,-1291.949219,-0.004329,0.005444,0.138288,0.480348,0.024470,1.382879,-1291.949219,0.139354,0.000000
87.420006,0.117294,-1291.993652,-0.004290,0.005488,0.139407,0.521751,0.026579,1.394068,-1291.993652,0.140308,0.000000
87.990005,0.070007,-1292.082642,-0.004247,0.005524,0.140308,0.311408,0.015864,1.403076,-1292.082642,0.141254,0.000000
88.560005,0.103523,-1292.082642,-0.004204,0.005565,0.141357,0.460494,0.023459,1.413567,-1292.082642,0.142208,0.000000
89.130005,0.138519,-1291.993652,-0.004195,0.005593,0.142052,0.616165,0.031389,1.420516,-1291.993652,0.143161,0.000000
89.700005,0.093842,-1292.038208,-0.004139,0.005637,0.143187,0.417428,0.021265,1.431871,-1292.038208,0.144106,0.000000
90.270004,0.094955,-1291.993652,-0.004096,0.005675,0.144141,0.422383,0.021517,1.441409,-1291.993652,0.145060,0.000000
90.840004,0.110222,-1292.038208,-0.004074,0.005701,0.144799,0.490291,0.024977,1.447995,-1292.038208,0.146006,0.000000
91.410004,0.120277,-1292.127197,-0.004027,0.005748,0.146006,0.535021,0.027255,1.460061,-1292.127197,0.146960,0.000000
91.980003,0.090111,-1292.082642,-0.003992,0.005782,0.146855,0.400833,0.020419,1.468554,-1292.082642,0.147905,0.000000
92.550003,0.097931,-1292.082642,-0.003936,0.005822,0.147879,0.435618,0.022191,1.478789,-1292.082642,0.148858,0.000000
93.120003,0.099426,-1292.038208,-0.003936,0.005853,0.148677,0.442270,0.022530,1.486767,-1292.038208,0.149805,0.000000
93.690002,0.061066,-1292.038208,-0.003872,0.005895,0.149726,0.271634,0.013838,1.497259,-1292.038208,0.150758,0.000000
94.260002,0.056976,-1292.127197,-0.003846,0.005931,0.150637,0.253443,0.012911,1.506373,-1292.127197,0.151703,0.000000
94.830002,0.102028,-1292.082642,-0.003803,0.005964,0.151487,0.453843,0.023120,1.514866,-1292.082642,0.152657,0.000000
95.400002,0.065910,-1292.082642,-0.003768,0.006007,0.152580,0.293184,0.014935,1.525797,-1292.082642,0.153611,0.000000
95.970001,0.063675,-1291.949219,-0.003708,0.006042,0.153473,0.283240,0.014429,1.534729,-1291.949219,0.154557,0.000000
96.540001,0.103149,-1291.993652,-0.003686,0.006079,0.154401,0.458832,0.023374,1.544010,-1291.993652,0.155511,0.000000
97.110008,0.078201,-1292.082642,-0.003643,0.006125,0.155580,0.347857,0.017721,1.555804,-1292.082642,0.156455,0.000000
97.680008,0.038353,-1292.082642,-0.003617,0.006162,0.156508,0.170603,0.008691,1.565084,-1292.082642,0.157409,0.000000
98.250008,0.087509,-1292.082642,-0.003561,0.006195,0.157349,0.389260,0.019830,1.573487,-1292.082642,0.158355,0.000000
98.820007,0.072983,-1292.038208,-0.003544,0.006232,0.158295,0.324644,0.016538,1.582949,-1292.038208,0.159309,0.000000
99.390007,0.021973,-1291.993652,-0.003505,0.006275,0.159396,0.097739,0.004979,1.593956,-1291.993652,0.160254,0.000000
99.960007,0.026070,-1292.082642,-0.003466,0.006297,0.159933,0.115964,0.005907,1.599330,-1292.082642,0.161208,0.000000
100.530006,0.109108,-1291.993652,-0.003432,0.006344,0.161131,0.485336,0.024724,1.611305,-1291.993652,0.162162,0.000000
101.100006,0.106499,-1292.082642,-0.003376,0.006386,0.162196,0.473730,0.024133,1.621964,-1292.082642,0.163108,0.000000
101.670006,0.096443,-1292.127197,-0.003359,0.006420,0.163081,0.429001,0.021854,1.630805,-1292.127197,0.164062,0.000000
102.240005,0.269226,-1291.993652,-0.003320,0.006455,0.163957,1.197577,0.061007,1.639571,-1291.993652,0.165006,0.000000
102.810005,0.547760,-1292.038208,-0.003298,0.006502,0.165155,2.436558,0.124124,1.651546,-1292.038208,0.165960,0.000000
103.380005,0.841187,-1292.082642,-0.003247,0.006536,0.166004,3.741785,0.190616,1.660040,-1292.082642,0.166906,0.000000
103.950005,1.331978,-1292.082642,-0.003212,0.006570,0.166888,5.924933,0.301831,1.668881,-1292.082642,0.167860,0.000000
104.520004,1.806007,-1292.082642,-0.003191,0.006598,0.167600,8.033522,0.409247,1.675997,-1292.082642,0.168805,0.000000
105.090004,2.656876,-1292.082642,-0.003156,0.006644,0.168770,11.818373,0.602057,1.687700,-1292.082642,0.169759,0.000000
105.660004,3.283951,-1292.038208,-0.003134,0.006678,0.169628,14.607742,0.744154,1.696284,-1292.038208,0.170712,0.000000
106.230003,4.186958,-1292.038208,-0.003109,0.006718,0.170635,18.624521,0.948778,1.706352,-1292.038208,0.171659,0.000000
106.800003,5.245239,-1292.127197,-0.003061,0.006758,0.171659,23.331989,1.188588,1.716586,-1292.127197,0.172612,0.000000
107.370003,6.008972,-1292.171631,-0.003048,0.006794,0.172559,26.729242,1.361652,1.725594,-1292.171631,0.173557,0.000000
107.940002,6.970444,-1292.127197,-0.003009,0.006831,0.173497,31.006083,1.579525,1.734966,-1292.127197,0.174511,0.000000
108.510002,8.037659,-1292.127197,-0.002984,0.006871,0.174529,35.753292,1.821360,1.745291,-1292.127197,0.175457,0.000000
109.080002,8.777939,-1292.082642,-0.002962,0.006909,0.175492,39.046223,1.989109,1.754920,-1292.082642,0.176411,0.000000
109.650002,9.680565,-1292.127197,-0.002932,0.006949,0.176514,43.061302,2.193647,1.765139,-1292.127197,0.177356,0.000000
110.220009,10.252159,-1292.171631,-0.002897,0.006980,0.177286,45.603882,2.323173,1.772860,-1292.171631,0.178309,0.000000
110.790009,11.172661,-1292.127197,-0.002863,0.007021,0.178344,49.698479,2.531761,1.783442,-1292.127197,0.179263,0.000000
111.360008,11.393852,-1292.127197,-0.002846,0.007051,0.179107,50.682384,2.581884,1.791073,-1292.127197,0.180209,0.000000
111.930008,12.118858,-1292.038208,-0.002820,0.007091,0.180122,53.907375,2.746173,1.801216,-1292.038208,0.181163,0.000000
112.500008,13.092987,-1292.171631,-0.002768,0.007134,0.181198,58.240517,2.966913,1.811981,-1292.171631,0.182108,0.000000
113.070007,13.200607,-1292.082642,-0.002751,0.007168,0.182056,58.719234,2.991300,1.820565,-1292.082642,0.183062,0.000000
113.640007,13.969177,-1292.127197,-0.002708,0.007211,0.183150,62.138004,3.165461,1.831496,-1292.127197,0.184008,0.000000
114.210007,13.841454,-1292.127197,-0.002665,0.007238,0.183843,61.569859,3.136518,1.838429,-1292.127197,0.184962,0.000000
114.780006,14.242500,-1292.171631,-0.002647,0.007276,0.184806,63.353806,3.227397,1.848058,-1292.171631,0.185906,0.000000
115.350006,14.354210,-1292.038208,-0.002613,0.007308,0.185629,63.850716,3.252710,1.856294,-1292.038208,0.186860,0.000000
115.920006,15.023369,-1292.127197,-0.002574,0.007349,0.186669,66.827286,3.404344,1.866695,-1292.127197,0.187806,0.000000
116.490005,15.537613,-1292.171631,-0.002548,0.007391,0.187737,69.114754,3.520874,1.877368,-1292.171631,0.188760,0.000000
117.060005,15.647835,-1292.127197,-0.002501,0.007430,0.188725,69.605049,3.545850,1.887255,-1292.127197,0.189714,0.000000
117.630005,15.386055,-1292.038208,-0.002462,0.007456,0.189375,68.440590,3.486530,1.893749,-1292.038208,0.190659,0.000000
118.200005,15.906265,-1292.038208,-0.002453,0.007498,0.190442,70.754601,3.604411,1.904423,-1292.038208,0.191613,0.000000
118.770004,16.400772,-1292.127197,-0.002414,0.007544,0.191605,72.954277,3.716468,1.916050,-1292.127197,0.192559,0.000000
119.340004,16.580254,-1292.127197,-0.002354,0.007583,0.192601,73.752655,3.757139,1.926012,-1292.127197,0.193513,0.000000
119.910004,16.208626,-1292.082642,-0.002345,0.007610,0.193296,72.099571,3.672927,1.932961,-1292.082642,0.194457,0.000000
120.480003,17.352554,-1292.171631,-0.002302,0.007657,0.194483,77.188019,3.932145,1.944830,-1292.171631,0.195411,0.000000
121.050003,17.126526,-1292.038208,-0.002268,0.007692,0.195376,76.182594,3.880926,1.953763,-1292.038208,0.196357,0.000000
121.620003,17.427773,-1292.127197,-0.002242,0.007725,0.196209,77.522606,3.949190,1.962090,-1292.127197,0.197311,0.000000
122.190002,17.462410,-1292.127197,-0.002216,0.007760,0.197111,77.676682,3.957039,1.971113,-1292.127197,0.198265,0.000000
122.760002,17.950584,-1292.127197,-0.002182,0.007802,0.198170,79.848190,4.067660,1.981695,-1292.127197,0.199210,0.000000
123.330009,18.519203,-1292.127197,-0.002134,0.007842,0.199184,82.377533,4.196512,1.991839,-1292.127197,0.200163,0.000000
123.900009,18.423126,-1292.082642,-0.002121,0.007872,0.199938,81.950157,4.174740,1.999378,-1292.082642,0.201110,0.000000
124.470009,19.294853,-1292.038208,-0.002074,0.007921,0.201205,85.827797,4.372276,2.012050,-1292.038208,0.202063,0.000000
125.040009,18.849495,-1292.127197,-0.002052,0.007949,0.201898,83.846741,4.271357,2.018984,-1292.127197,0.203008,0.000000
125.610008,19.261711,-1292.127197,-0.002022,0.007986,0.202843,85.680367,4.364766,2.028431,-1292.127197,0.203962,0.000000
126.180008,20.099548,-1292.127197,-0.001983,0.008028,0.203910,89.407257,4.554623,2.039105,-1292.127197,0.204908,0.000000
126.750008,20.507668,-1292.082642,-0.001953,0.008066,0.204881,91.222664,4.647104,2.048809,-1292.082642,0.205862,0.000000
127.320007,20.689011,-1292.127197,-0.001927,0.008104,0.205836,92.029312,4.688197,2.058362,-1292.127197,0.206816,0.000000
127.890007,20.549004,-1292.082642,-0.001910,0.008134,0.206599,91.406532,4.656471,2.065993,-1292.082642,0.207760,0.000000
128.460007,21.602074,-1292.127197,-0.001867,0.008181,0.207804,96.090820,4.895100,2.078044,-1292.127197,0.208714,0.000000
129.029999,22.117432,-1292.171631,-0.001832,0.008218,0.208749,98.383247,5.011881,2.087491,-1292.171631,0.209660,0.000000
129.600006,22.050034,-1292.038208,-0.001807,0.008249,0.209521,98.083450,4.996609,2.095212,-1292.038208,0.210614,0.000000
130.170013,23.167900,-1292.082642,-0.001776,0.008296,0.210710,103.055969,5.249921,2.107096,-1292.082642,0.211559,0.000000
130.740005,22.999214,-1292.082642,-0.001742,0.008325,0.211464,102.305611,5.211697,2.114636,-1292.082642,0.212513,0.000000
131.310013,23.681396,-1292.127197,-0.001720,0.008365,0.212478,105.340111,5.366281,2.124779,-1292.127197,0.213459,0.000000
131.880005,24.364326,-1292.171631,-0.001681,0.008402,0.213415,108.377937,5.521035,2.134151,-1292.171631,0.214413,0.000000
132.450012,24.758675,-1292.127197,-0.001651,0.008439,0.214360,110.132088,5.610396,2.143598,-1292.127197,0.215357,0.000000
133.020004,25.496346,-1292.082642,-0.001638,0.008480,0.215383,113.413406,5.777555,2.153832,-1292.082642,0.216311,0.000000
133.590012,25.418144,-1292.082642,-0.001600,0.008508,0.216095,113.065552,5.759834,2.160948,-1292.082642,0.217265,0.000000
134.160004,26.467117,-1292.171631,-0.001574,0.008551,0.217195,117.731621,5.997535,2.171954,-1292.171631,0.218211,0.000000
134.730011,26.852524,-1292.127197,-0.001544,0.008587,0.218116,119.445992,6.084869,2.181159,-1292.127197,0.219165,0.000000
135.300003,27.748451,-1292.171631,-0.001500,0.008625,0.219077,123.431274,6.287889,2.190773,-1292.171631,0.220110,0.000000
135.870010,28.320786,-1292.082642,-0.001487,0.008660,0.219963,125.977142,6.417582,2.199630,-1292.082642,0.221064,0.000000
136.440002,29.266243,-1292.127197,-0.001457,0.008699,0.220942,130.182755,6.631826,2.209425,-1292.127197,0.222010,0.000000
137.010010,30.101471,-1292.082642,-0.001440,0.008734,0.221854,133.898026,6.821091,2.218539,-1292.082642,0.222964,0.000000
137.580002,30.687218,-1292.127197,-0.001418,0.008766,0.222652,136.503555,6.953823,2.226517,-1292.127197,0.223908,0.000000
138.150009,32.135002,-1292.171631,-0.001397,0.008812,0.223822,142.943634,7.281895,2.238220,-1292.171631,0.224862,0.000000
138.720001,32.764305,-1292.171631,-0.001354,0.008845,0.224671,145.742905,7.424498,2.246714,-1292.171631,0.225816,0.000000
139.290009,34.394928,-1292.127197,-0.001337,0.008886,0.225704,152.996277,7.794003,2.257039,-1292.127197,0.226762,0.000000
139.860001,35.977509,-1292.038208,-0.001293,0.008929,0.226788,160.035950,8.152619,2.267879,-1292.038208,0.227716,0.000000
140.430008,36.707359,-1292.038208,-0.001276,0.008964,0.227681,163.282486,8.318007,2.276811,-1292.038208,0.228661,0.000000
141.000000,37.624138,-1292.216064,-0.001272,0.008998,0.228549,167.360519,8.525751,2.285486,-1292.216064,0.229614,0.000000
141.570007,39.043251,-1292.171631,-0.001220,0.009035,0.229493,173.673050,8.847327,2.294933,-1292.171631,0.230561,0.000000
142.139999,40.835854,-1292.171631,-0.001199,0.009077,0.230552,181.646942,9.253537,2.305516,-1292.171631,0.231514,0.000000
142.710007,41.663269,-1292.038208,-0.001168,0.009112,0.231436,185.327484,9.441031,2.314357,-1292.038208,0.232459,0.000000
143.280014,43.741104,-1291.993652,-0.001168,0.009147,0.232329,194.570145,9.911876,2.323290,-1291.993652,0.233413,0.000000
143.850006,45.845757,-1292.127197,-0.001147,0.009186,0.233318,203.932114,10.388797,2.333176,-1292.127197,0.234367,0.000000
144.420013,47.357216,-1292.260620,-0.001138,0.009223,0.234264,210.655411,10.731298,2.342638,-1292.260620,0.235313,0.000000
144.990005,49.042198,-1292.127197,-0.001112,0.009256,0.235095,218.150589,11.113121,2.350950,-1292.127197,0.236267,0.000000
145.560013,52.469887,-1292.216064,-0.001082,0.009305,0.236353,233.397720,11.889846,2.363531,-1292.216064,0.237211,0.000000
146.130005,53.999222,-1292.082642,-0.001074,0.009337,0.237160,240.200531,12.236398,2.371600,-1292.082642,0.238165,0.000000
146.700012,56.448311,-1292.127197,-0.001048,0.009376,0.238149,251.094620,12.791369,2.381486,-1292.127197,0.239111,0.000000
147.270004,57.676399,-1292.171631,-0.001030,0.009402,0.238798,256.557434,13.069658,2.387981,-1292.171631,0.240065,0.000000
147.840012,61.153236,-1292.171631,-0.001030,0.009450,0.240040,272.023193,13.857521,2.400396,-1292.171631,0.241010,0.000000
148.410004,63.472755,-1292.171631,-0.000996,0.009483,0.240880,282.340912,14.383132,2.408798,-1292.171631,0.241964,0.000000
148.980011,65.960197,-1292.171631,-0.000979,0.009519,0.241791,293.405609,14.946795,2.417912,-1292.171631,0.242918,0.000000
149.550003,65.302956,-1292.082642,-0.000966,0.009515,0.241687,290.482056,14.797861,2.416867,-1292.082642,294.500488,0.000000
150.120010,65.000587,-1292.171631,-0.000979,0.009528,0.241999,289.137054,14.729344,2.419986,-1292.171631,294.500488,0.000000
150.690002,65.179710,-1292.260620,-0.000953,0.009544,0.242415,289.933838,14.769934,2.424150,-1292.260620,294.500488,0.000000
151.260010,65.348763,-1292.216064,-0.000949,0.009543,0.242398,290.685822,14.808242,2.423983,-1292.216064,294.500488,0.000000
151.830002,65.663780,-1292.171631,-0.000953,0.009553,0.242641,292.087097,14.879625,2.426405,-1292.171631,294.500488,0.000000
152.400009,65.363655,-1292.127197,-0.000940,0.009553,0.242641,290.752045,14.811616,2.426405,-1292.127197,294.500488,0.000000
152.970001,65.247475,-1292.127197,-0.000944,0.009556,0.242727,290.235260,14.785289,2.427268,-1292.127197,294.500488,0.000000
153.540009,65.167793,-1292.216064,-0.000944,0.009558,0.242780,289.880829,14.767234,2.427798,-1292.216064,294.500488,0.000000
154.110001,65.120491,-1292.260620,-0.000927,0.009561,0.242840,289.670410,14.756514,2.428404,-1292.260620,294.500488,0.000000
154.680008,65.189018,-1292.127197,-0.000923,0.009564,0.242918,289.975250,14.772042,2.429176,-1292.127197,294.500488,0.000000
155.250000,65.135765,-1292.171631,-0.000923,0.009565,0.242961,289.738342,14.759975,2.429615,-1292.171631,294.500488,0.000000
155.820007,65.144325,-1292.171631,-0.000927,0.009568,0.243022,289.776428,14.761915,2.430221,-1292.171631,294.500488,0.000000
156.390015,65.127937,-1292.171631,-0.000918,0.009571,0.243092,289.703522,14.758202,2.430917,-1292.171631,294.500488,0.000000
156.960007,65.218803,-1292.171631,-0.000918,0.009573,0.243143,290.107727,14.778792,2.431432,-1292.171631,294.500488,0.000000
157.530014,65.174858,-1292.171631,-0.000914,0.009574,0.243178,289.912262,14.768834,2.431780,-1292.171631,294.500488,0.000000
158.100006,65.247841,-1292.260620,-0.000914,0.009576,0.243222,290.236877,14.785373,2.432219,-1292.260620,294.500488,0.000000
158.670013,65.297371,-1292.216064,-0.000927,0.009578,0.243282,290.457214,14.796596,2.432825,-1292.216064,294.500488,0.000000
159.240005,65.289925,-1292.127197,-0.000931,0.009579,0.243308,290.424103,14.794909,2.433082,-1292.127197,294.500488,0.000000
159.810013,65.263115,-1292.260620,-0.000936,0.009580,0.243326,290.304840,14.788833,2.433264,-1292.260620,294.500488,0.000000
160.380005,65.238167,-1292.216064,-0.000918,0.009581,0.243352,290.193848,14.783179,2.433521,-1292.216064,294.500488,0.000000
160.950012,65.206886,-1292.127197,-0.000918,0.009582,0.243378,290.054718,14.776092,2.433778,-1292.127197,294.500488,0.000000
161.520004,65.215080,-1292.171631,-0.000905,0.009583,0.243413,290.091156,14.777948,2.434127,-1292.171631,294.500488,0.000000
162.090012,65.257896,-1292.127197,-0.000923,0.009584,0.243438,290.281616,14.787651,2.434384,-1292.127197,294.500488,0.000000
162.660004,65.210243,-1292.216064,-0.000918,0.009585,0.243455,290.069641,14.776852,2.434551,-1292.216064,294.500488,0.000000
163.230011,65.176720,-1292.260620,-0.000923,0.009585,0.243455,289.920532,14.769256,2.434551,-1292.260620,294.500488,0.000000
163.800003,65.193474,-1292.216064,-0.000914,0.009586,0.243490,289.995056,14.773052,2.434899,-1292.216064,294.500488,0.000000
164.370010,65.155495,-1292.171631,-0.000914,0.009586,0.243490,289.826111,14.764446,2.434899,-1292.171631,294.500488,0.000000
164.940002,65.298866,-1292.171631,-0.000927,0.009589,0.243559,290.463867,14.796934,2.435595,-1292.171631,294.500488,0.000000
165.510010,65.262001,-1292.216064,-0.000918,0.009589,0.243559,290.299866,14.788581,2.435595,-1292.216064,294.500488,0.000000
166.080002,65.219917,-1292.260620,-0.000923,0.009589,0.243559,290.112671,14.779044,2.435595,-1292.260620,294.500488,0.000000
166.650009,65.167046,-1292.260620,-0.000914,0.009589,0.243569,289.877502,14.767064,2.435686,-1292.260620,294.500488,0.000000
167.220001,65.158485,-1292.260620,-0.000918,0.009590,0.243594,289.839417,14.765123,2.435943,-1292.260620,294.500488,0.000000
167.790009,65.116020,-1292.171631,-0.000918,0.009590,0.243594,289.650513,14.755501,2.435943,-1292.171631,294.500488,0.000000
168.360001,65.200935,-1292.260620,-0.000905,0.009592,0.243646,290.028259,14.774743,2.436458,-1292.260620,294.500488,0.000000
168.930008,65.191246,-1292.216064,-0.000905,0.009592,0.243646,289.985138,14.772547,2.436458,-1292.216064,294.500488,0.000000
169.500015,65.158104,-1292.216064,-0.000918,0.009592,0.243646,289.837708,14.765038,2.436458,-1292.216064,294.500488,0.000000
170.070007,65.186028,-1292.305054,-0.000914,0.009594,0.243681,289.961945,14.771365,2.436806,-1292.305054,294.500488,0.000000
170.640015,65.140984,-1292.260620,-0.000914,0.009594,0.243681,289.761566,14.761158,2.436806,-1292.260620,294.500488,0.000000
171.210007,65.128319,-1292.216064,-0.000910,0.009594,0.243690,289.705231,14.758287,2.436897,-1292.216064,294.500488,0.000000
171.780014,65.392326,-1292.305054,-0.000910,0.009598,0.243785,290.879608,14.818112,2.437851,-1292.305054,294.500488,0.000000
172.350006,65.383385,-1292.349609,-0.000910,0.009598,0.243785,290.839813,14.816087,2.437851,-1292.349609,294.500488,0.000000
172.920013,65.357704,-1292.305054,-0.000910,0.009598,0.243785,290.725586,14.810267,2.437851,-1292.305054,294.500488,0.000000
173.490005,65.329018,-1292.260620,-0.000905,0.009598,0.243785,290.597992,14.803767,2.437851,-1292.260620,294.500488,0.000000
174.060013,65.298119,-1292.260620,-0.000892,0.009598,0.243785,290.460541,14.796765,2.437851,-1292.260620,294.500488,0.000000
174.630005,65.269814,-1292.305054,-0.000901,0.009598,0.243785,290.334625,14.790351,2.437851,-1292.305054,294.500488,0.000000
175.200012,65.245247,-1292.349609,-0.000914,0.009598,0.243785,290.225342,14.784784,2.437851,-1292.349609,294.500488,0.000000
175.770004,65.193855,-1292.349609,-0.000905,0.009598,0.243785,289.996765,14.773139,2.437851,-1292.349609,294.500488,0.000000
176.340012,65.135017,-1292.260620,-0.000914,0.009598,0.243785,289.735016,14.759806,2.437851,-1292.260620,294.500488,0.000000
176.910004,65.101875,-1292.260620,-0.000905,0.009598,0.243785,289.587616,14.752295,2.437851,-1292.260620,294.500488,0.000000
177.480011,65.388969,-1292.305054,-0.000905,0.009602,0.243899,290.864655,14.817352,2.438986,-1292.305054,294.500488,0.000000
178.050003,65.389351,-1292.260620,-0.000918,0.009602,0.243899,290.866364,14.817439,2.438986,-1292.260620,294.500488,0.000000
178.620010,65.390465,-1292.305054,-0.000901,0.009602,0.243899,290.871307,14.817692,2.438986,-1292.305054,294.500488,0.000000
179.190002,65.368126,-1292.305054,-0.000897,0.009602,0.243899,290.771942,14.812629,2.438986,-1292.305054,294.500488,0.000000
179.760010,65.328651,-1292.260620,-0.000892,0.009602,0.243899,290.596344,14.803684,2.438986,-1292.260620,294.500488,0.000000
180.330002,65.304451,-1292.349609,-0.000901,0.009602,0.243899,290.488708,14.798200,2.438986,-1292.349609,294.500488,0.000000
180.900009,65.289177,-1292.260620,-0.000905,0.009602,0.243899,290.420776,14.794740,2.438986,-1292.260620,294.500488,0.000000
181.470001,65.262749,-1292.394043,-0.000905,0.009602,0.243899,290.303192,14.788750,2.438986,-1292.394043,294.500488,0.000000
182.040009,65.228859,-1292.349609,-0.000897,0.009602,0.243899,290.152466,14.781071,2.438986,-1292.349609,294.500488,0.000000
182.610016,65.210976,-1292.260620,-0.000905,0.009602,0.243899,290.072906,14.777019,2.438986,-1292.260620,294.500488,0.000000
183.180008,65.174858,-1292.394043,-0.000918,0.009602,0.243899,289.912262,14.768834,2.438986,-1292.394043,294.500488,0.000000
183.750015,65.152519,-1292.260620,-0.000905,0.009603,0.243924,289.812866,14.763772,2.439244,-1292.260620,294.500488,0.000000
184.320007,65.144325,-1292.349609,-0.000918,0.009603,0.243924,289.776428,14.761915,2.439244,-1292.349609,294.500488,0.000000
184.890015,65.383018,-1292.438477,-0.000897,0.009608,0.244036,290.838196,14.816004,2.440364,-1292.438477,294.500488,0.000000
185.460007,65.457863,-1292.305054,-0.000897,0.009608,0.244036,291.171112,14.832964,2.440364,-1292.305054,294.500488,0.000000
186.030014,65.478722,-1292.349609,-0.000901,0.009608,0.244036,291.263885,14.837690,2.440364,-1292.349609,294.500488,0.000000
186.600006,65.455254,-1292.394043,-0.000910,0.009608,0.244036,291.159515,14.832372,2.440364,-1292.394043,294.500488,0.000000
187.170013,65.435890,-1292.394043,-0.000910,0.009608,0.244036,291.073364,14.827985,2.440364,-1292.394043,294.500488,0.000000
187.740005,65.406105,-1292.438477,-0.000910,0.009608,0.244036,290.940887,14.821236,2.440364,-1292.438477,294.500488,0.000000
188.310013,65.374458,-1292.394043,-0.000897,0.009608,0.244036,290.800110,14.814064,2.440364,-1292.394043,294.500488,0.000000
188.880005,65.348015,-1292.394043,-0.000905,0.009608,0.244036,290.682495,14.808072,2.440364,-1292.394043,294.500488,0.000000
189.450012,65.328285,-1292.394043,-0.000910,0.009608,0.244036,290.594727,14.803600,2.440364,-1292.394043,294.500488,0.000000
190.020004,65.307793,-1292.394043,-0.000897,0.009608,0.244036,290.503571,14.798957,2.440364,-1292.394043,294.500488,0.000000
190.590012,65.293282,-1292.394043,-0.000897,0.009608,0.244036,290.439026,14.795669,2.440364,-1292.394043,294.500488,0.000000
191.160004,65.289177,-1292.438477,-0.000910,0.009608,0.244036,290.420776,14.794740,2.440364,-1292.438477,294.500488,0.000000
191.730011,65.251564,-1292.438477,-0.000897,0.009608,0.244036,290.253448,14.786216,2.440364,-1292.438477,294.500488,0.000000
192.300003,65.231468,-1292.438477,-0.000905,0.009608,0.244036,290.164062,14.781662,2.440364,-1292.438477,294.500488,0.000000
192.870010,65.208382,-1292.438477,-0.000892,0.009608,0.244036,290.061371,14.776431,2.440364,-1292.438477,294.500488,0.000000
193.440002,65.185295,-1292.483032,-0.000910,0.009608,0.244036,289.958679,14.771199,2.440364,-1292.483032,294.500488,0.000000
194.010010,65.159966,-1292.483032,-0.000901,0.009608,0.244036,289.846008,14.765460,2.440364,-1292.483032,294.500488,0.000000
194.580002,65.121620,-1292.483032,-0.000897,0.009608,0.244045,289.675446,14.756769,2.440455,-1292.483032,294.500488,0.000000
195.150009,65.129066,-1292.394043,-0.000910,0.009609,0.244062,289.708557,14.758457,2.440621,-1292.394043,294.500488,0.000000
195.720016,65.766930,-1292.394043,-0.000905,0.009615,0.244227,292.545929,14.903000,2.442272,-1292.394043,294.500488,0.000000
196.290009,65.779961,-1292.483032,-0.000914,0.009615,0.244227,292.603882,14.905951,2.442272,-1292.483032,294.500488,0.000000
196.860016,65.800819,-1292.527466,-0.000910,0.009615,0.244227,292.696655,14.910679,2.442272,-1292.527466,294.500488,0.000000
197.430008,65.750557,-1292.483032,-0.000897,0.009615,0.244227,292.473083,14.899289,2.442272,-1292.483032,294.500488,0.000000
198.000015,65.784431,-1292.438477,-0.000910,0.009615,0.244227,292.623779,14.906965,2.442272,-1292.438477,294.500488,0.000000
198.570007,65.748314,-1292.394043,-0.000905,0.009615,0.244227,292.463104,14.898781,2.442272,-1292.394043,294.500488,0.000000
199.140015,65.755394,-1292.483032,-0.000905,0.009615,0.244227,292.494598,14.900386,2.442272,-1292.483032,294.500488,0.000000
199.710007,65.768791,-1292.571899,-0.000892,0.009615,0.244227,292.554199,14.903420,2.442272,-1292.571899,294.500488,0.000000
200.280014,65.756508,-1292.483032,-0.000897,0.009615,0.244227,292.499542,14.900638,2.442272,-1292.483032,294.500488,0.000000
200.850006,65.683891,-1292.483032,-0.000905,0.009615,0.244227,292.176544,14.884183,2.442272,-1292.483032,294.500488,0.000000
201.420013,65.663048,-1292.394043,-0.000897,0.009615,0.244227,292.083832,14.879459,2.442272,-1292.394043,294.500488,0.000000
201.990005,65.633995,-1292.438477,-0.000892,0.009615,0.244227,291.954590,14.872875,2.442272,-1292.438477,294.500488,0.000000
202.560013,65.612770,-1292.483032,-0.000892,0.009615,0.244227,291.860168,14.868067,2.442272,-1292.483032,294.500488,0.000000
203.130005,65.600853,-1292.438477,-0.000888,0.009615,0.244227,291.807159,14.865366,2.442272,-1292.438477,294.500488,0.000000
203.700012,65.587456,-1292.438477,-0.000884,0.009615,0.244227,291.747589,14.862329,2.442272,-1292.438477,294.500488,0.000000
204.270004,65.584465,-1292.438477,-0.000910,0.009615,0.244227,291.734283,14.861651,2.442272,-1292.438477,294.500488,0.000000
204.840012,65.576653,-1292.438477,-0.000914,0.009615,0.244227,291.699524,14.859881,2.442272,-1292.438477,294.500488,0.000000
205.410004,65.550591,-1292.527466,-0.000901,0.009615,0.244227,291.583588,14.853976,2.442272,-1292.527466,294.500488,0.000000
205.980011,65.533089,-1292.483032,-0.000884,0.009615,0.244227,291.505737,14.850011,2.442272,-1292.483032,294.500488,0.000000
206.550003,65.522285,-1292.527466,-0.000897,0.009615,0.244227,291.457672,14.847562,2.442272,-1292.527466,294.500488,0.000000
207.120010,65.509254,-1292.483032,-0.000888,0.009615,0.244227,291.399719,14.844608,2.442272,-1292.483032,294.500488,0.000000
207.690002,65.489891,-1292.483032,-0.000897,0.009615,0.244227,291.313599,14.840221,2.442272,-1292.483032,294.500488,0.000000
208.260010,65.472389,-1292.527466,-0.000892,0.009615,0.244227,291.235718,14.836256,2.442272,-1292.527466,294.500488,0.000000
208.830017,65.428825,-1292.527466,-0.000897,0.009615,0.244227,291.041962,14.826384,2.442272,-1292.527466,294.500488,0.000000
209.400009,65.406853,-1292.527466,-0.000905,0.009615,0.244227,290.944214,14.821404,2.442272,-1292.527466,294.500488,0.000000
209.970016,65.379662,-1292.483032,-0.000901,0.009611,0.244124,290.823273,14.815243,2.441242,-1292.483032,0.244080,0.000000
210.540009,65.288429,-1292.438477,-0.000884,0.009587,0.243499,290.417450,14.794570,2.434989,-1292.438477,0.243127,0.000000
211.110016,65.228111,-1292.438477,-0.000892,0.009555,0.242684,290.149139,14.780901,2.426844,-1292.438477,0.242180,0.000000
211.680008,65.172249,-1292.483032,-0.000880,0.009520,0.241799,289.900635,14.768242,2.417988,-1292.483032,0.241226,0.000000
212.250015,65.136879,-1292.483032,-0.000875,0.009481,0.240810,289.743317,14.760228,2.408102,-1292.483032,0.240282,0.000000
212.820007,65.086617,-1292.483032,-0.000875,0.009454,0.240142,289.519745,14.748837,2.401425,-1292.483032,0.239328,0.000000
213.390015,65.022942,-1292.438477,-0.000867,0.009405,0.238886,289.236481,14.734409,2.388859,-1292.438477,0.238382,0.000000
213.960007,64.878075,-1292.394043,-0.000880,0.009375,0.238130,288.592102,14.701582,2.381305,-1292.394043,0.237428,0.000000
214.530014,63.938957,-1292.483032,-0.000880,0.009345,0.237367,284.414673,14.488775,2.373674,-1292.483032,0.236474,0.000000
215.100006,62.333290,-1292.483032,-0.000858,0.009311,0.236509,277.272308,14.124926,2.365090,-1292.483032,0.235529,0.000000
215.670013,59.909142,-1292.527466,-0.000849,0.009272,0.235520,266.489166,13.575605,2.355204,-1292.527466,0.234576,0.000000
216.240005,56.564865,-1292.483032,-0.000828,0.009230,0.234455,251.613083,12.817781,2.344546,-1292.483032,0.233629,0.000000
216.810013,53.986557,-1292.438477,-0.000828,0.009205,0.233813,240.144196,12.233528,2.338126,-1292.438477,0.232676,0.000000
217.380005,49.448456,-1292.438477,-0.000845,0.009159,0.232650,219.957718,11.205180,2.326499,-1292.438477,0.231731,0.000000
217.950012,45.409332,-1292.483032,-0.000824,0.009121,0.231661,201.990799,10.289902,2.316613,-1292.483032,0.230777,0.000000
218.520004,41.566818,-1292.527466,-0.000836,0.009088,0.230829,184.898437,9.419175,2.308286,-1292.527466,0.229831,0.000000
219.090012,37.092766,-1292.483032,-0.000836,0.009047,0.229805,164.996857,8.405341,2.298052,-1292.483032,0.228877,0.000000
219.660004,33.791313,-1292.438477,-0.000828,0.009014,0.228956,150.311264,7.657221,2.289559,-1292.438477,0.227932,0.000000
220.230011,29.221931,-1292.438477,-0.000849,0.008974,0.227942,129.985641,6.621785,2.279415,-1292.438477,0.226979,0.000000
220.800003,25.235306,-1292.438477,-0.000832,0.008932,0.226883,112.252243,5.718402,2.268833,-1292.438477,0.226025,0.000000
221.370010,21.609146,-1292.527466,-0.000836,0.008902,0.226111,96.122284,4.896702,2.261111,-1292.527466,0.225079,0.000000
221.940018,17.282921,-1292.527466,-0.000836,0.008862,0.225106,76.878273,3.916366,2.251059,-1292.527466,0.224125,0.000000
222.510010,13.599411,-1292.438477,-0.000836,0.008830,0.224281,60.493202,3.081671,2.242808,-1292.438477,0.223180,0.000000
223.080017,9.481720,-1292.438477,-0.000819,0.008791,0.223292,42.176796,2.148589,2.232922,-1292.438477,0.222226,0.000000
223.650009,5.530479,-1292.438477,-0.000828,0.008753,0.222322,24.600801,1.253224,2.223217,-1292.438477,0.221280,0.000000
224.220016,1.848831,-1292.438477,-0.000832,0.008716,0.221385,8.224011,0.418951,2.213846,-1292.438477,0.220326,0.000000
224.790009,-1.308144,-1292.483032,-0.000836,0.008678,0.220431,-5.818913,-0.296430,2.204308,-1292.483032,0.219382,0.000000
225.360016,-0.090858,-1292.483032,-0.000832,0.008643,0.219521,-0.404159,-0.020589,2.195209,-1292.483032,0.218428,0.000000
225.930008,0.001488,-1292.483032,-0.000828,0.008616,0.218835,0.006618,0.000337,2.188351,-1292.483032,0.217474,0.000000
226.500015,-0.007820,-1292.483032,-0.000824,0.008572,0.217725,-0.034786,-0.001772,2.177253,-1292.483032,0.216528,0.000000
227.070007,-0.066658,-1292.483032,-0.000841,0.008527,0.216581,-0.296510,-0.015105,2.165808,-1292.483032,0.215574,0.000000
227.640015,-0.057343,-1292.527466,-0.000862,0.008490,0.215635,-0.255072,-0.012994,2.156346,-1292.527466,0.214629,0.000000
228.210007,-0.047661,-1292.527466,-0.000828,0.008455,0.214750,-0.212006,-0.010800,2.147504,-1292.527466,0.213675,0.000000
228.780014,-0.082664,-1292.527466,-0.000836,0.008416,0.213762,-0.367710,-0.018732,2.137618,-1292.527466,0.212729,0.000000
229.350006,-0.065536,-1292.394043,-0.000845,0.008374,0.212704,-0.291521,-0.014851,2.127035,-1292.394043,0.211775,0.000000
229.920013,-0.047661,-1292.438477,-0.000849,0.008343,0.211906,-0.212006,-0.010800,2.119057,-1292.438477,0.210831,0.000000
230.490005,-0.058838,-1292.483032,-0.000841,0.008312,0.211126,-0.261724,-0.013333,2.111260,-1292.483032,0.209877,0.000000
231.060013,-0.096443,-1292.571899,-0.000841,0.008266,0.209947,-0.429001,-0.021854,2.099466,-1292.571899,0.208923,0.000000
231.630005,-0.057343,-1292.527466,-0.000841,0.008234,0.209149,-0.255072,-0.012994,2.091488,-1292.527466,0.207977,0.000000
232.200012,-0.073357,-1292.483032,-0.000841,0.008190,0.208038,-0.326307,-0.016623,2.080375,-1292.483032,0.207023,0.000000
232.770004,-0.086021,-1292.438477,-0.000854,0.008153,0.207076,-0.382642,-0.019493,2.070761,-1292.438477,0.206078,0.000000
233.340012,-0.077454,-1292.483032,-0.000845,0.008123,0.206330,-0.344531,-0.017551,2.063298,-1292.483032,0.205125,0.000000
233.910004,-0.114319,-1292.483032,-0.000862,0.008081,0.205262,-0.508516,-0.025905,2.052624,-1292.483032,0.204178,0.000000
234.480011,-0.112457,-1292.527466,-0.000875,0.008055,0.204587,-0.500235,-0.025483,2.045872,-1292.527466,0.203225,0.000000
235.050018,-0.046173,-1292.483032,-0.000914,0.008006,0.203364,-0.205388,-0.010463,2.033639,-1292.483032,0.203269,0.000000
235.200012,-0.045433,-1292.438477,-0.000923,0.008007,0.203373,-0.202096,-0.010295,2.033730,-1292.438477,0.203269,0.000000