File: Data/Sima compression/P1-17-1_10302024_172533.csv
Time (sec),S:Load (lbs),S:HL1 (DIM),S:LVDT (in),S:Position (in),Ch:Position (mm),Ch:Load (N),Ch:Stress (MPa),Ch:Strain (mm/mm),Ch:HL1 (DIM),Set Point (),Cycles ()
0.210000,0.003723,-1293.950806,-0.004691,-0.004684,-0.118974,0.016561,0.000844,-1.189744,-1293.950806,-0.118793,0.000000
0.500000,-0.012291,-1293.950806,-0.004691,-0.004622,-0.117404,-0.054673,-0.002785,-1.174044,-1293.950806,-0.116849,0.000000
0.790000,0.001114,-1293.906372,-0.004622,-0.004444,-0.112887,0.004955,0.000252,-1.128868,-1293.906372,-0.112010,0.000000
1.080000,0.005211,-1293.950806,-0.004419,-0.004263,-0.108290,0.023179,0.001181,-1.082904,-1293.950806,-0.107188,0.000000
1.370000,0.042076,-1293.906372,-0.004243,-0.004069,-0.103364,0.187164,0.009535,-1.033640,-1293.906372,-0.102350,0.000000
1.660000,0.014526,-1293.950806,-0.004057,-0.003884,-0.098663,0.064617,0.003292,-0.986631,-1293.950806,-0.097511,0.000000
1.950000,0.019363,-1293.950806,-0.003854,-0.003692,-0.093781,0.086133,0.004388,-0.937806,-1293.950806,-0.092689,0.000000
2.240000,0.021973,-1293.950806,-0.003648,-0.003500,-0.088898,0.097739,0.004979,-0.888981,-1293.950806,-0.087849,0.000000
2.530000,0.005211,-1293.950806,-0.003454,-0.003310,-0.084069,0.023179,0.001181,-0.840686,-1293.950806,-0.083027,0.000000
2.820000,0.153419,-1293.906372,-0.003294,-0.000000,-0.000000,0.682444,0.034765,-0.000000,-1293.906372,0.000226,0.000000
3.110000,0.132935,-1293.950806,-0.003294,-0.000000,-0.000000,0.591322,0.030123,-0.000000,-1293.950806,0.000226,0.000000
3.400000,0.236084,-1293.950806,-0.003285,-0.000000,-0.000000,1.050154,0.053497,-0.000000,-1293.950806,0.000400,0.000000
3.690000,0.148575,-1293.906372,-0.003303,0.000005,0.000121,0.660894,0.033668,0.001211,-1293.906372,0.000884,0.000000
3.980000,0.286354,-1293.950806,-0.003281,0.000019,0.000477,1.273767,0.064889,0.004769,-1293.950806,0.001370,0.000000
4.270000,0.539192,-1293.950806,-0.003285,0.000039,0.000980,2.398447,0.122183,0.009795,-1293.950806,0.001847,0.000000
4.560000,0.889969,-1293.950806,-0.003272,0.000056,0.001423,3.958779,0.201670,0.014231,-1293.950806,0.002333,0.000000
4.850000,1.203133,-1293.950806,-0.003251,0.000069,0.001761,5.351801,0.272634,0.017607,-1293.950806,0.002819,0.000000
5.140000,1.299950,-1293.950806,-0.003251,0.000077,0.001968,5.782465,0.294573,0.019681,-1293.950806,0.003305,0.000000
5.430000,2.345573,-1293.950806,-0.003208,0.000115,0.002914,10.433632,0.531515,0.029144,-1293.950806,0.003782,0.000000
5.720000,2.829659,-1293.861938,-0.003199,0.000133,0.003382,12.586949,0.641210,0.033822,-1293.861938,0.004266,0.000000
6.010000,3.421730,-1293.861938,-0.003191,0.000149,0.003782,15.220615,0.775375,0.037819,-1293.861938,0.004752,0.000000
6.300000,4.081573,-1293.995361,-0.003165,0.000169,0.004285,18.155746,0.924898,0.042845,-1293.995361,0.005238,0.000000
6.590000,4.776421,-1293.861938,-0.003156,0.000187,0.004743,21.246580,1.082352,0.047432,-1293.861938,0.005715,0.000000
6.880000,5.331627,-1293.995361,-0.003143,0.000199,0.005057,23.716261,1.208164,0.050566,-1293.995361,0.006201,0.000000
7.170001,6.580566,-1293.861938,-0.003126,0.000227,0.005767,29.271822,1.491178,0.057667,-1293.861938,0.006687,0.000000
7.460001,6.957031,-1293.950806,-0.003117,0.000239,0.006071,30.946421,1.576486,0.060710,-1293.950806,0.007164,0.000000
7.750000,8.041382,-1293.906372,-0.003104,0.000264,0.006704,35.769852,1.822203,0.067038,-1293.906372,0.007649,0.000000
8.040000,8.840126,-1293.861938,-0.003096,0.000281,0.007137,39.322845,2.003201,0.071368,-1293.861938,0.008134,0.000000
8.330000,10.030968,-1293.950806,-0.003070,0.000306,0.007762,44.619972,2.273050,0.077621,-1293.950806,0.008620,0.000000
8.620001,10.292747,-1293.906372,-0.003070,0.000315,0.007997,45.784428,2.332370,0.079967,-1293.906372,0.009097,0.000000
8.910001,11.111221,-1293.906372,-0.003061,0.000332,0.008439,49.425182,2.517839,0.084388,-1293.906372,0.009583,0.000000
9.200001,12.754128,-1293.995361,-0.003040,0.000361,0.009167,56.733192,2.890127,0.091670,-1293.995361,0.010069,0.000000
9.490001,13.608353,-1293.906372,-0.003009,0.000379,0.009626,60.532974,3.083697,0.096257,-1293.906372,0.010554,0.000000
9.780001,14.303574,-1293.950806,-0.003005,0.000395,0.010025,63.625473,3.241236,0.100254,-1293.950806,0.011031,0.000000
10.070001,15.382332,-1293.861938,-0.002988,0.000419,0.010642,68.424026,3.485686,0.106416,-1293.861938,0.011517,0.000000
10.360001,16.282730,-1293.950806,-0.002975,0.000434,0.011031,72.429199,3.689719,0.110307,-1293.950806,0.012003,0.000000
10.650001,16.977203,-1293.950806,-0.002975,0.000452,0.011474,75.518372,3.847089,0.114743,-1293.950806,0.012489,0.000000
10.940001,18.294662,-1293.906372,-0.002975,0.000474,0.012028,81.378723,4.145630,0.120284,-1293.906372,0.012966,0.000000
11.230000,19.592377,-1293.950806,-0.002953,0.000497,0.012626,87.151245,4.439696,0.126264,-1293.950806,0.013452,0.000000
11.520000,20.129341,-1293.772949,-0.002936,0.000511,0.012991,89.539780,4.561374,0.129913,-1293.772949,0.013936,0.000000
11.810000,20.993240,-1293.861938,-0.002910,0.000531,0.013494,93.382599,4.757136,0.134939,-1293.861938,0.014422,0.000000
12.100000,21.593880,-1293.906372,-0.002906,0.000545,0.013833,96.054375,4.893243,0.138330,-1293.906372,0.014899,0.000000
12.390000,22.721054,-1293.861938,-0.002897,0.000566,0.014370,101.068298,5.148664,0.143705,-1293.861938,0.015385,0.000000
12.680000,23.350731,-1293.995361,-0.002880,0.000581,0.014769,103.869240,5.291351,0.147687,-1293.995361,0.015871,0.000000
12.970000,24.756813,-1293.861938,-0.002863,0.000609,0.015480,110.123802,5.609974,0.154802,-1293.861938,0.016348,0.000000
13.260000,25.594650,-1293.861938,-0.002846,0.000627,0.015931,113.850693,5.799830,0.159314,-1293.861938,0.016834,0.000000
13.550000,26.058624,-1293.950806,-0.002846,0.000644,0.016364,115.914551,5.904969,0.163644,-1293.950806,0.017318,0.000000
13.840001,26.857361,-1293.817383,-0.002824,0.000662,0.016816,119.467506,6.085965,0.168155,-1293.817383,0.017804,0.000000
14.130001,27.613655,-1293.950806,-0.002802,0.000680,0.017276,122.831673,6.257344,0.172758,-1293.950806,0.018281,0.000000
14.420001,28.125290,-1293.906372,-0.002798,0.000697,0.017709,125.107536,6.373281,0.177088,-1293.906372,0.018767,0.000000
14.710001,28.521126,-1293.906372,-0.002777,0.000710,0.018039,126.868301,6.462979,0.180388,-1293.906372,0.019253,0.000000
15.000001,30.328621,-1293.995361,-0.002764,0.000742,0.018837,134.908447,6.872564,0.188367,-1293.995361,0.019739,0.000000
15.290001,30.655937,-1293.906372,-0.002742,0.000757,0.019218,136.364426,6.946734,0.192182,-1293.906372,0.020216,0.000000
15.580001,31.356369,-1293.950806,-0.002729,0.000776,0.019704,139.480103,7.105454,0.197042,-1293.950806,0.020700,0.000000
15.870001,31.846039,-1293.950806,-0.002712,0.000794,0.020172,141.658249,7.216415,0.201720,-1293.950806,0.021186,0.000000
16.160000,33.091995,-1293.906372,-0.002690,0.000820,0.020823,147.200546,7.498753,0.208230,-1293.906372,0.021672,0.000000
16.450001,33.480751,-1293.906372,-0.002669,0.000835,0.021204,148.929825,7.586846,0.212045,-1293.906372,0.022149,0.000000
16.740002,32.944160,-1293.861938,-0.002665,0.000840,0.021335,146.542938,7.465253,0.213347,-1293.861938,0.022635,0.000000
17.030001,34.762459,-1293.861938,-0.002656,0.000873,0.022175,154.631134,7.877286,0.221749,-1293.861938,0.023121,0.000000
17.320002,35.176163,-1293.906372,-0.002643,0.000892,0.022644,156.471390,7.971032,0.226443,-1293.906372,0.023606,0.000000
17.610001,35.944740,-1293.906372,-0.002613,0.000910,0.023121,159.890198,8.145195,0.231212,-1293.906372,0.024083,0.000000
17.900002,36.502930,-1293.906372,-0.002600,0.000930,0.023615,162.373138,8.271682,0.236147,-1293.906372,0.024569,0.000000
18.190001,37.258842,-1293.861938,-0.002570,0.000950,0.024126,165.735611,8.442974,0.241264,-1293.861938,0.025054,0.000000
18.480001,37.316193,-1293.906372,-0.002557,0.000963,0.024464,165.990707,8.455970,0.244640,-1293.906372,0.025531,0.000000
18.770000,38.489532,-1293.950806,-0.002548,0.000989,0.025132,171.209991,8.721852,0.251317,-1293.950806,0.026017,0.000000
19.060001,38.591934,-1293.817383,-0.002514,0.001008,0.025601,171.665497,8.745057,0.256010,-1293.817383,0.026503,0.000000
19.350000,39.069321,-1293.906372,-0.002505,0.001022,0.025948,173.789017,8.853234,0.259477,-1293.906372,0.026988,0.000000
19.640001,39.781670,-1293.861938,-0.002483,0.001043,0.026494,176.957703,9.014655,0.264943,-1293.861938,0.027465,0.000000
19.930000,40.603867,-1293.906372,-0.002475,0.001065,0.027057,180.615021,9.200968,0.270575,-1293.906372,0.027951,0.000000
20.220001,40.999695,-1293.995361,-0.002458,0.001084,0.027525,182.375748,9.290664,0.275253,-1293.995361,0.028437,0.000000
20.510000,40.692116,-1293.906372,-0.002436,0.001092,0.027743,181.007568,9.220965,0.277433,-1293.906372,0.028923,0.000000
20.800001,42.398331,-1293.950806,-0.002419,0.001124,0.028558,188.597198,9.607599,0.285578,-1293.950806,0.029400,0.000000
21.090000,42.339119,-1293.861938,-0.002402,0.001137,0.028888,188.333801,9.594182,0.288878,-1293.861938,0.029886,0.000000
21.380001,42.941620,-1293.950806,-0.002376,0.001161,0.029477,191.013870,9.730710,0.294768,-1293.950806,0.030370,0.000000
21.670000,43.111046,-1293.950806,-0.002350,0.001174,0.029823,191.767502,9.769103,0.298235,-1293.950806,0.030856,0.000000
21.960001,44.138428,-1293.906372,-0.002350,0.001198,0.030440,196.337540,10.001910,0.304396,-1293.906372,0.031333,0.000000
22.250002,44.562927,-1293.950806,-0.002320,0.001216,0.030882,198.225800,10.098104,0.308817,-1293.950806,0.031819,0.000000
22.540001,44.240829,-1293.906372,-0.002298,0.001229,0.031221,196.793045,10.025116,0.312208,-1293.906372,0.032305,0.000000
22.830002,45.775002,-1293.950806,-0.002281,0.001255,0.031888,203.617371,10.372764,0.318885,-1293.950806,0.032789,0.000000
23.120001,45.957840,-1293.950806,-0.002259,0.001271,0.032296,204.430679,10.414195,0.322958,-1293.950806,0.033268,0.000000
23.410002,46.598320,-1293.861938,-0.002255,0.001291,0.032782,207.279678,10.559330,0.327817,-1293.861938,0.033752,0.000000
23.700001,46.912598,-1293.950806,-0.002233,0.001310,0.033268,208.677658,10.630547,0.332677,-1293.950806,0.034238,0.000000
23.990002,47.678574,-1293.950806,-0.002195,0.001327,0.033717,212.084885,10.804119,0.337174,-1293.950806,0.034715,0.000000
24.280001,48.029343,-1293.950806,-0.002186,0.001344,0.034126,213.645187,10.883605,0.341261,-1293.950806,0.035201,0.000000
24.570002,48.697754,-1293.906372,-0.002164,0.001366,0.034689,216.618423,11.035069,0.346893,-1293.906372,0.035687,0.000000
24.860001,49.766090,-1293.861938,-0.002134,0.001388,0.035245,221.370621,11.277158,0.352449,-1293.861938,0.036171,0.000000
25.150002,50.070320,-1293.995361,-0.002130,0.001404,0.035669,222.723907,11.346096,0.356688,-1293.995361,0.036650,0.000000
25.440001,50.344383,-1293.861938,-0.002091,0.001422,0.036111,223.943008,11.408200,0.361109,-1293.861938,0.037134,0.000000
25.730001,50.902946,-1293.861938,-0.002100,0.001438,0.036527,226.427612,11.534772,0.365273,-1293.861938,0.037620,0.000000
26.020000,51.537468,-1294.039795,-0.002078,0.001457,0.036997,229.250107,11.678556,0.369966,-1294.039795,0.038106,0.000000
26.310001,51.769829,-1293.906372,-0.002061,0.001470,0.037343,230.283707,11.731211,0.373433,-1293.906372,0.038583,0.000000
26.600000,52.727943,-1293.950806,-0.002039,0.001499,0.038072,234.545609,11.948323,0.380715,-1293.950806,0.039069,0.000000
26.890001,53.851387,-1293.906372,-0.002018,0.001518,0.038565,239.542938,12.202899,0.385651,-1293.906372,0.039554,0.000000
27.180002,54.391701,-1293.995361,-0.002001,0.001536,0.039025,241.946365,12.325336,0.390253,-1293.995361,0.040040,0.000000
27.470001,54.950630,-1293.950806,-0.001970,0.001554,0.039467,244.432617,12.451990,0.394674,-1293.950806,0.040517,0.000000
27.760002,55.481262,-1293.995361,-0.001953,0.001571,0.039909,246.792984,12.572234,0.399094,-1293.995361,0.041003,0.000000
28.050001,55.827194,-1293.995361,-0.001949,0.001586,0.040274,248.331757,12.650622,0.402743,-1293.995361,0.041489,0.000000
28.340002,55.959763,-1293.906372,-0.001927,0.001599,0.040604,248.921463,12.680664,0.406044,-1293.906372,0.041974,0.000000
28.630001,57.622032,-1293.906372,-0.001923,0.001630,0.041402,256.315613,13.057339,0.414022,-1293.906372,0.042451,0.000000
28.920002,58.238678,-1293.995361,-0.001884,0.001649,0.041879,259.058563,13.197073,0.418791,-1293.995361,0.042936,0.000000
29.210001,59.358406,-1293.906372,-0.001867,0.001669,0.042382,264.039368,13.450808,0.423817,-1293.906372,0.043422,0.000000
29.500002,59.337555,-1293.906372,-0.001867,0.001680,0.042677,263.946625,13.446082,0.426770,-1293.906372,0.043899,0.000000
29.790001,60.829651,-1293.906372,-0.001819,0.001707,0.043370,270.583801,13.784196,0.433704,-1293.906372,0.044385,0.000000
30.080002,61.046371,-1293.906372,-0.001828,0.001721,0.043708,271.547821,13.833305,0.437080,-1293.906372,0.044871,0.000000
30.370001,62.059967,-1293.950806,-0.001798,0.001744,0.044298,276.056519,14.062989,0.442984,-1293.950806,0.045357,0.000000
30.660002,63.055321,-1293.861938,-0.001768,0.001764,0.044810,280.484070,14.288540,0.448101,-1293.861938,0.045834,0.000000
30.950001,63.699150,-1293.950806,-0.001759,0.001784,0.045313,283.347961,14.434433,0.453128,-1293.950806,0.046318,0.000000
31.240002,64.423409,-1293.906372,-0.001738,0.001803,0.045808,286.569641,14.598553,0.458078,-1293.906372,0.046804,0.000000
31.530001,65.520790,-1293.906372,-0.001729,0.001823,0.046292,291.451019,14.847223,0.462923,-1293.906372,0.047290,0.000000
31.820002,66.014183,-1293.906372,-0.001716,0.001838,0.046674,293.645752,14.959028,0.466738,-1293.906372,0.047767,0.000000
32.110001,65.811241,-1293.950806,-0.001677,0.001839,0.046709,292.743011,14.913040,0.467086,-1293.950806,0.008221,0.000000
32.400002,65.064644,-1293.950806,-0.001686,0.001857,0.047169,289.421997,14.743859,0.471689,-1293.950806,294.500488,0.000000
32.690002,65.004311,-1293.995361,-0.001669,0.001856,0.047151,289.153625,14.730187,0.471507,-1293.995361,294.500488,0.000000
32.980003,65.573677,-1293.861938,-0.001664,0.001868,0.047446,291.686279,14.859208,0.474459,-1293.861938,294.500488,0.000000
33.270000,65.274666,-1293.906372,-0.001638,0.001878,0.047690,290.356201,14.791451,0.476897,-1293.906372,294.500488,0.000000
33.560001,65.341682,-1293.906372,-0.001630,0.001889,0.047976,290.654327,14.806637,0.479758,-1293.906372,294.500488,0.000000
33.850002,65.423241,-1293.950806,-0.001634,0.001896,0.048167,291.017120,14.825118,0.481666,-1293.950806,294.500488,0.000000
34.140003,64.990532,-1293.906372,-0.001608,0.001903,0.048339,289.092316,14.727065,0.483392,-1293.906372,294.500488,0.000000
34.430000,65.084373,-1293.906372,-0.001613,0.001910,0.048521,289.509766,14.748329,0.485208,-1293.906372,294.500488,0.000000
34.720001,65.319344,-1293.950806,-0.001604,0.001920,0.048756,290.554962,14.801575,0.487555,-1293.950806,294.500488,0.000000
35.010002,65.119377,-1293.861938,-0.001574,0.001926,0.048930,289.665466,14.756262,0.489296,-1293.861938,294.500488,0.000000
35.300003,65.492500,-1293.906372,-0.001574,0.001935,0.049155,291.325195,14.840813,0.491552,-1293.906372,294.500488,0.000000
35.590000,65.556175,-1293.906372,-0.001574,0.001943,0.049354,291.608429,14.855242,0.493535,-1293.906372,294.500488,0.000000
35.880001,65.035973,-1293.861938,-0.001561,0.001947,0.049458,289.294464,14.737362,0.494580,-1293.861938,294.500488,0.000000
36.170002,65.359932,-1293.906372,-0.001548,0.001953,0.049597,290.735504,14.810773,0.495973,-1293.906372,294.500488,0.000000
36.460003,65.721504,-1293.906372,-0.001539,0.001962,0.049823,292.343842,14.892705,0.498228,-1293.906372,294.500488,0.000000
36.750000,65.103371,-1293.861938,-0.001535,0.001962,0.049823,289.594269,14.752634,0.498228,-1293.861938,294.500488,0.000000
37.040001,65.493248,-1293.950806,-0.001522,0.001971,0.050074,291.328522,14.840981,0.500742,-1293.950806,294.500488,0.000000
37.330002,65.200935,-1293.906372,-0.001531,0.001974,0.050151,290.028259,14.774743,0.501514,-1293.906372,294.500488,0.000000
37.620003,65.149544,-1293.950806,-0.001513,0.001979,0.050274,289.799652,14.763098,0.502740,-1293.950806,294.500488,0.000000
37.910004,65.345787,-1293.906372,-0.001500,0.001987,0.050472,290.672577,14.807567,0.504723,-1293.906372,294.500488,0.000000
38.200001,65.325676,-1293.906372,-0.001492,0.001996,0.050690,290.583130,14.803010,0.506903,-1293.906372,294.500488,0.000000
38.490002,65.337212,-1293.906372,-0.001492,0.001996,0.050698,290.634430,14.805623,0.506979,-1293.906372,294.500488,0.000000
38.780003,65.531227,-1293.772949,-0.001492,0.002003,0.050881,291.497467,14.849588,0.508811,-1293.772949,294.500488,0.000000
39.070004,65.205391,-1293.906372,-0.001470,0.002005,0.050923,290.048065,14.775753,0.509235,-1293.906372,294.500488,0.000000
39.360001,65.507011,-1293.817383,-0.001457,0.002012,0.051098,291.389740,14.844101,0.510976,-1293.817383,294.500488,0.000000
39.650002,65.183052,-1293.950806,-0.001462,0.002014,0.051149,289.948700,14.770691,0.511491,-1293.950806,294.500488,0.000000
39.940002,65.411324,-1293.861938,-0.001449,0.002020,0.051305,290.964111,14.822417,0.513050,-1293.861938,294.500488,0.000000
40.230003,65.210243,-1293.906372,-0.001444,0.002022,0.051366,290.069641,14.776852,0.513656,-1293.906372,294.500488,0.000000
40.520000,65.217690,-1293.817383,-0.001444,0.002027,0.051479,290.102783,14.778540,0.514791,-1293.817383,294.500488,0.000000
40.810001,65.605324,-1293.906372,-0.001449,0.002036,0.051705,291.827057,14.866379,0.517047,-1293.906372,294.500488,0.000000
41.100002,65.323433,-1293.861938,-0.001431,0.002036,0.051712,290.573151,14.802502,0.517123,-1293.861938,294.500488,0.000000
41.390003,65.134270,-1293.861938,-0.001423,0.002041,0.051835,289.731689,14.759637,0.518349,-1293.861938,294.500488,0.000000
41.680000,65.333488,-1293.817383,-0.001423,0.002048,0.052007,290.617859,14.804780,0.520075,-1293.817383,294.500488,0.000000
41.970001,65.307793,-1293.906372,-0.001414,0.002048,0.052007,290.503571,14.798957,0.520075,-1293.906372,294.500488,0.000000
42.260002,65.159966,-1293.906372,-0.001418,0.002051,0.052086,289.846008,14.765460,0.520862,-1293.906372,294.500488,0.000000
42.550003,65.097786,-1293.906372,-0.001414,0.002054,0.052163,289.569427,14.751369,0.521634,-1293.906372,294.500488,0.000000
42.840000,65.242638,-1293.995361,-0.001397,0.002058,0.052285,290.213745,14.784193,0.522845,-1293.995361,294.500488,0.000000
43.130001,64.987190,-1293.906372,-0.001401,0.002059,0.052294,289.077454,14.726308,0.522936,-1293.906372,294.500488,0.000000
43.420002,65.768791,-1293.995361,-0.001397,0.002069,0.052554,292.554199,14.903420,0.525540,-1293.995361,294.500488,0.000000
43.710003,65.440742,-1293.817383,-0.001375,0.002069,0.052563,291.094971,14.829084,0.525631,-1293.817383,294.500488,0.000000
44.000004,65.100761,-1293.906372,-0.001397,0.002069,0.052563,289.582642,14.752044,0.525631,-1293.906372,294.500488,0.000000
44.290001,65.497337,-1293.950806,-0.001367,0.002077,0.052754,291.346710,14.841908,0.527539,-1293.950806,294.500488,0.000000
44.580002,65.182686,-1293.817383,-0.001375,0.002077,0.052754,289.947083,14.770608,0.527539,-1293.817383,294.500488,0.000000
44.870003,64.864311,-1293.906372,-0.001367,0.002077,0.052754,288.530853,14.698462,0.527539,-1293.906372,294.500488,0.000000
45.160004,65.857414,-1293.906372,-0.001367,0.002083,0.052919,292.948395,14.923503,0.529189,-1293.906372,294.500488,0.000000
45.450001,65.527870,-1293.906372,-0.001375,0.002083,0.052919,291.482513,14.848827,0.529189,-1293.906372,294.500488,0.000000
45.740002,65.186409,-1293.906372,-0.001362,0.002084,0.052926,289.963623,14.771451,0.529265,-1293.906372,294.500488,0.000000
46.030003,65.324562,-1293.906372,-0.001367,0.002094,0.053178,290.578156,14.802757,0.531778,-1293.906372,294.500488,0.000000
46.320004,65.072838,-1293.817383,-0.001358,0.002094,0.053187,289.458435,14.745716,0.531869,-1293.817383,294.500488,0.000000
46.610001,64.916801,-1293.861938,-0.001358,0.002096,0.053231,288.764343,14.710358,0.532308,-1293.861938,294.500488,0.000000
46.900002,65.815346,-1293.950806,-0.001345,0.002107,0.053526,292.761292,14.913971,0.535260,-1293.950806,294.500488,0.000000
47.190002,65.593040,-1293.906372,-0.001345,0.002107,0.053526,291.772430,14.863595,0.535260,-1293.906372,294.500488,0.000000
47.480003,65.357323,-1293.817383,-0.001345,0.002107,0.053526,290.723877,14.810181,0.535260,-1293.817383,294.500488,0.000000
47.770000,65.090340,-1293.995361,-0.001319,0.002107,0.053526,289.536285,14.749682,0.535260,-1293.995361,294.500488,0.000000
48.060001,65.111931,-1293.861938,-0.001324,0.002114,0.053708,289.632324,14.754575,0.537077,-1293.861938,294.500488,0.000000
48.350002,65.151772,-1293.906372,-0.001332,0.002115,0.053717,289.809540,14.763602,0.537167,-1293.906372,294.500488,0.000000
48.640003,65.072838,-1293.950806,-0.001332,0.002117,0.053759,289.458435,14.745716,0.537591,-1293.950806,294.500488,0.000000
48.930004,65.753151,-1293.817383,-0.001324,0.002125,0.053976,292.484619,14.899878,0.539756,-1293.817383,294.500488,0.000000
49.220001,65.536430,-1293.950806,-0.001311,0.002125,0.053976,291.520599,14.850768,0.539756,-1293.950806,294.500488,0.000000
49.510002,65.301476,-1293.950806,-0.001306,0.002125,0.053985,290.475464,14.797526,0.539847,-1293.950806,294.500488,0.000000
49.800003,65.053841,-1293.950806,-0.001328,0.002125,0.053985,289.373932,14.741411,0.539847,-1293.950806,294.500488,0.000000
50.090004,65.752037,-1293.906372,-0.001315,0.002135,0.054236,292.479675,14.899625,0.542360,-1293.906372,294.500488,0.000000
50.380001,65.567711,-1293.906372,-0.001302,0.002136,0.054245,291.659760,14.857855,0.542451,-1293.906372,294.500488,0.000000
50.670002,65.344292,-1293.906372,-0.001319,0.002136,0.054245,290.665924,14.807228,0.542451,-1293.906372,294.500488,0.000000
50.960003,65.145073,-1293.995361,-0.001298,0.002136,0.054245,289.779755,14.762084,0.542451,-1293.995361,294.500488,0.000000
51.250004,65.491005,-1293.906372,-0.001298,0.002142,0.054419,291.318542,14.840473,0.544192,-1293.906372,294.500488,0.000000
51.540001,65.330879,-1293.950806,-0.001298,0.002143,0.054427,290.606262,14.804189,0.544268,-1293.950806,294.500488,0.000000
51.830002,65.135017,-1293.861938,-0.001289,0.002143,0.054436,289.735016,14.759806,0.544359,-1293.861938,294.500488,0.000000
52.120003,65.264229,-1293.906372,-0.001289,0.002148,0.054566,290.309784,14.789085,0.545661,-1293.906372,294.500488,0.000000
52.410004,65.179329,-1293.995361,-0.001281,0.002148,0.054566,289.932129,14.769847,0.545661,-1293.995361,294.500488,0.000000
52.700001,65.395683,-1293.906372,-0.001293,0.002154,0.054713,290.894531,14.818873,0.547129,-1293.906372,294.500488,0.000000
52.990002,65.300728,-1293.995361,-0.001276,0.002154,0.054713,290.472137,14.797357,0.547129,-1293.995361,294.500488,0.000000
53.280003,65.113045,-1293.861938,-0.001272,0.002155,0.054748,289.637299,14.754827,0.547477,-1293.861938,294.500488,0.000000
53.570004,65.087349,-1293.950806,-0.001272,0.002158,0.054801,289.522980,14.749004,0.548007,-1293.950806,294.500488,0.000000
53.860004,65.301094,-1293.906372,-0.001268,0.002161,0.054896,290.473785,14.797440,0.548961,-1293.906372,294.500488,0.000000
54.150002,65.203529,-1293.906372,-0.001263,0.002163,0.054931,290.039795,14.775331,0.549309,-1293.906372,294.500488,0.000000
54.440002,65.107094,-1293.906372,-0.001276,0.002164,0.054957,289.610809,14.753479,0.549567,-1293.906372,294.500488,0.000000
54.730003,65.119759,-1293.861938,-0.001250,0.002166,0.055008,289.667145,14.756349,0.550081,-1293.861938,294.500488,0.000000
55.020004,65.193474,-1293.950806,-0.001272,0.002169,0.055094,289.995056,14.773052,0.550944,-1293.950806,294.500488,0.000000
55.310001,65.195351,-1293.861938,-0.001259,0.002171,0.055138,290.003418,14.773478,0.551383,-1293.861938,294.500488,0.000000
55.600002,65.232948,-1293.906372,-0.001250,0.002173,0.055199,290.170654,14.781998,0.551989,-1293.906372,294.500488,0.000000
55.890003,65.146568,-1293.950806,-0.001259,0.002175,0.055234,289.786407,14.762424,0.552337,-1293.950806,294.500488,0.000000
56.180004,65.244118,-1293.861938,-0.001246,0.002177,0.055294,290.220337,14.784528,0.552943,-1293.861938,294.500488,0.000000
56.470001,65.160713,-1293.995361,-0.001255,0.002179,0.055347,289.849335,14.765629,0.553473,-1293.995361,294.500488,0.000000
56.760002,65.162209,-1293.906372,-0.001246,0.002180,0.055373,289.855988,14.765968,0.553730,-1293.906372,294.500488,0.000000
57.050003,65.078423,-1293.906372,-0.001246,0.002181,0.055390,289.483276,14.746982,0.553897,-1293.906372,294.500488,0.000000
57.340004,65.292152,-1293.995361,-0.001229,0.002185,0.055503,290.433990,14.795413,0.555032,-1293.995361,294.500488,0.000000
57.630001,65.167793,-1293.906372,-0.001233,0.002185,0.055503,289.880829,14.767234,0.555032,-1293.906372,294.500488,0.000000
57.920002,65.084007,-1293.906372,-0.001229,0.002193,0.055694,289.508118,14.748247,0.556940,-1293.906372,294.500488,0.000000
58.210003,65.625053,-1293.995361,-0.001237,0.002194,0.055720,291.914825,14.870851,0.557197,-1293.995361,294.500488,0.000000
58.500004,65.514473,-1293.906372,-0.001229,0.002194,0.055720,291.422943,14.845792,0.557197,-1293.906372,294.500488,0.000000
58.790001,65.331261,-1293.995361,-0.001224,0.002194,0.055720,290.607971,14.804276,0.557197,-1293.995361,294.500488,0.000000
59.080002,65.207253,-1293.950806,-0.001212,0.002194,0.055720,290.056335,14.776175,0.557197,-1293.950806,294.500488,0.000000
59.370003,65.014000,-1293.950806,-0.001212,0.002194,0.055720,289.196716,14.732384,0.557197,-1293.950806,294.500488,0.000000
59.660004,64.829308,-1293.995361,-0.001207,0.002194,0.055720,288.375153,14.690531,0.557197,-1293.995361,294.500488,0.000000
59.950005,64.680351,-1293.906372,-0.001224,0.002194,0.055720,287.712585,14.656777,0.557197,-1293.906372,294.500488,0.000000
60.240002,64.489693,-1293.995361,-0.001220,0.002194,0.055720,286.864471,14.613573,0.557197,-1293.995361,294.500488,0.000000
60.530003,66.403313,-1293.950806,-0.001194,0.002027,0.051487,295.376678,15.047206,0.514867,-1293.950806,294.500488,0.000000
60.820004,66.208565,-1293.906372,-0.001190,0.002027,0.051496,294.510406,15.003076,0.514958,-1293.906372,294.500488,0.000000
61.110004,66.005257,-1294.039795,-0.001177,0.002027,0.051496,293.606049,14.957005,0.514958,-1294.039795,294.500488,0.000000
61.400002,65.820930,-1293.950806,-0.001194,0.002047,0.051982,292.786133,14.915236,0.519817,-1293.950806,294.500488,0.000000
61.690002,65.607933,-1293.995361,-0.001194,0.002090,0.053091,291.838654,14.866970,0.530915,-1293.995361,294.500488,0.000000
61.980003,65.454140,-1293.995361,-0.001186,0.002124,0.053950,291.154541,14.832120,0.539499,-1293.995361,294.500488,0.000000
62.270004,65.330513,-1293.950806,-0.001190,0.002184,0.055485,290.604645,14.804106,0.554850,-1293.950806,294.500488,0.000000
62.560001,65.240776,-1293.950806,-0.001203,0.002195,0.055745,290.205475,14.783772,0.557454,-1293.950806,294.500488,0.000000
62.850002,65.361046,-1293.950806,-0.001190,0.002210,0.056136,290.740448,14.811025,0.561360,-1293.950806,294.500488,0.000000
63.140003,65.342430,-1293.995361,-0.001194,0.002213,0.056206,290.657654,14.806807,0.562057,-1293.995361,294.500488,0.000000
63.430004,65.287315,-1293.906372,-0.001186,0.002215,0.056266,290.412476,14.794317,0.562662,-1293.906372,294.500488,0.000000
63.720001,65.289925,-1293.950806,-0.001190,0.002217,0.056309,290.424103,14.794909,0.563086,-1293.950806,294.500488,0.000000
64.010002,65.241524,-1294.039795,-0.001181,0.002218,0.056343,290.208801,14.783940,0.563435,-1294.039795,294.500488,0.000000
64.300003,65.282845,-1293.950806,-0.001186,0.002221,0.056404,290.392609,14.793304,0.564040,-1293.950806,294.500488,0.000000
64.590004,65.227745,-1294.039795,-0.001199,0.002222,0.056439,290.147491,14.780818,0.564388,-1294.039795,294.500488,0.000000
64.880005,65.183052,-1293.950806,-0.001186,0.002223,0.056465,289.948700,14.770691,0.564646,-1293.950806,294.500488,0.000000
65.170006,65.498085,-1294.039795,-0.001177,0.002228,0.056595,291.350037,14.842078,0.565948,-1294.039795,294.500488,0.000000
65.460007,65.419884,-1293.950806,-0.001168,0.002228,0.056595,291.002167,14.824358,0.565948,-1293.950806,294.500488,0.000000
65.750000,65.338341,-1293.950806,-0.001173,0.002229,0.056622,290.639465,14.805880,0.566220,-1293.950806,294.500488,0.000000
66.040001,65.302956,-1294.039795,-0.001186,0.002230,0.056648,290.482056,14.797861,0.566478,-1294.039795,294.500488,0.000000
66.330002,65.240395,-1293.950806,-0.001168,0.002231,0.056657,290.203766,14.783685,0.566568,-1293.950806,294.500488,0.000000
66.620003,65.231087,-1294.039795,-0.001177,0.002233,0.056708,290.162354,14.781575,0.567083,-1294.039795,294.500488,0.000000
66.910004,65.158485,-1294.039795,-0.001168,0.002233,0.056725,289.839417,14.765123,0.567250,-1294.039795,294.500488,0.000000
67.200005,65.078423,-1293.995361,-0.001168,0.002233,0.056725,289.483276,14.746982,0.567250,-1293.995361,294.500488,0.000000
67.490005,64.983833,-1293.995361,-0.001168,0.002234,0.056743,289.062531,14.725547,0.567431,-1293.995361,294.500488,0.000000
67.780006,64.964104,-1293.995361,-0.001160,0.002236,0.056786,288.974762,14.721076,0.567855,-1293.995361,294.500488,0.000000
68.070000,64.900795,-1294.039795,-0.001151,0.002236,0.056795,288.693146,14.706731,0.567946,-1294.039795,294.500488,0.000000
68.360001,64.878456,-1293.995361,-0.001160,0.002238,0.056839,288.593781,14.701669,0.568385,-1293.995361,294.500488,0.000000
68.650002,64.807701,-1293.995361,-0.001160,0.002238,0.056848,288.279053,14.685635,0.568476,-1293.995361,294.500488,0.000000
68.940002,65.672356,-1294.039795,-0.001160,0.002251,0.057185,292.125214,14.881569,0.571852,-1294.039795,294.500488,0.000000
69.230003,65.755013,-1294.084351,-0.001155,0.002250,0.057159,292.492889,14.900299,0.571595,-1294.084351,294.500488,0.000000
69.520004,65.658195,-1294.039795,-0.001155,0.002250,0.057159,292.062225,14.878360,0.571595,-1294.039795,294.500488,0.000000
69.810005,65.561012,-1294.039795,-0.001151,0.002250,0.057159,291.629944,14.856339,0.571595,-1294.039795,294.500488,0.000000
70.100006,65.456001,-1293.950806,-0.001155,0.002250,0.057159,291.162842,14.832541,0.571595,-1293.950806,294.500488,0.000000
70.390007,65.323067,-1293.950806,-0.001143,0.002251,0.057167,290.571503,14.802419,0.571671,-1293.950806,294.500488,0.000000
70.680000,65.237053,-1293.995361,-0.001143,0.002251,0.057167,290.188904,14.782928,0.571671,-1293.995361,294.500488,0.000000
70.970001,65.099648,-1293.950806,-0.001147,0.002251,0.057167,289.577698,14.751791,0.571671,-1293.950806,294.500488,0.000000
71.260002,65.523033,-1293.995361,-0.001138,0.002258,0.057350,291.460999,14.847732,0.573502,-1293.995361,294.500488,0.000000
71.550003,65.470894,-1293.995361,-0.001134,0.002258,0.057350,291.229095,14.835917,0.573502,-1293.995361,294.500488,0.000000
71.840004,65.358070,-1294.039795,-0.001143,0.002258,0.057350,290.727203,14.810350,0.573502,-1294.039795,294.500488,0.000000
72.130005,65.263481,-1294.039795,-0.001134,0.002258,0.057350,290.306458,14.788917,0.573502,-1294.039795,294.500488,0.000000
72.420006,65.133904,-1293.995361,-0.001138,0.002258,0.057358,289.730072,14.759553,0.573578,-1293.995361,294.500488,0.000000
72.710007,65.279503,-1294.039795,-0.001134,0.002262,0.057446,290.377716,14.792547,0.574456,-1294.039795,294.500488,0.000000
73.000000,65.223274,-1294.039795,-0.001125,0.002262,0.057446,290.127625,14.779805,0.574456,-1294.039795,294.500488,0.000000
73.290001,65.118263,-1293.995361,-0.001130,0.002262,0.057455,289.660492,14.756009,0.574547,-1293.995361,294.500488,0.000000
73.580002,65.089592,-1294.039795,-0.001121,0.002265,0.057523,289.532959,14.749513,0.575228,-1294.039795,294.500488,0.000000
73.870003,65.108574,-1293.995361,-0.001117,0.002265,0.057523,289.617401,14.753814,0.575228,-1293.995361,294.500488,0.000000
74.160004,65.117149,-1294.084351,-0.001130,0.002266,0.057567,289.655548,14.755756,0.575667,-1294.084351,294.500488,0.000000
74.450005,65.043785,-1294.039795,-0.001138,0.002266,0.057567,289.329193,14.739132,0.575667,-1294.039795,294.500488,0.000000
74.740005,65.065010,-1294.039795,-0.001130,0.002272,0.057697,289.423615,14.743942,0.576969,-1294.039795,294.500488,0.000000
75.030006,65.257530,-1294.039795,-0.001112,0.002272,0.057697,290.279999,14.787567,0.576969,-1294.039795,294.500488,0.000000
75.320007,65.201302,-1293.995361,-0.001117,0.002272,0.057697,290.029877,14.774826,0.576969,-1293.995361,294.500488,0.000000
75.610001,65.092201,-1294.039795,-0.001121,0.002272,0.057697,289.544586,14.750103,0.576969,-1294.039795,294.500488,0.000000
75.900002,65.030006,-1293.995361,-0.001121,0.002273,0.057732,289.267914,14.736011,0.577318,-1293.995361,294.500488,0.000000
76.190002,65.306679,-1293.950806,-0.001112,0.002280,0.057904,290.498627,14.798705,0.579044,-1293.950806,294.500488,0.000000
76.480003,65.504784,-1294.039795,-0.001112,0.002280,0.057904,291.379822,14.843596,0.579044,-1294.039795,294.500488,0.000000
76.770004,65.425468,-1293.906372,-0.001099,0.002280,0.057904,291.027008,14.825624,0.579044,-1293.906372,294.500488,0.000000
77.060005,65.324928,-1293.995361,-0.001125,0.002280,0.057904,290.579803,14.802840,0.579044,-1293.995361,294.500488,0.000000
77.350006,65.242638,-1293.995361,-0.001108,0.002280,0.057904,290.213745,14.784193,0.579044,-1293.995361,294.500488,0.000000
77.640007,65.133904,-1293.995361,-0.001117,0.002280,0.057904,289.730072,14.759553,0.579044,-1293.995361,294.500488,0.000000
77.930000,65.104118,-1294.039795,-0.001099,0.002281,0.057948,289.597595,14.752804,0.579483,-1294.039795,294.500488,0.000000
78.220001,65.051613,-1294.039795,-0.001108,0.002284,0.058009,289.364014,14.740906,0.580088,-1294.039795,294.500488,0.000000
78.510002,65.142464,-1294.039795,-0.001099,0.002285,0.058027,289.768158,14.761494,0.580270,-1294.039795,294.500488,0.000000
78.800003,65.093681,-1294.039795,-0.001087,0.002286,0.058053,289.551147,14.750440,0.580527,-1294.039795,294.500488,0.000000
79.090004,65.402016,-1293.995361,-0.001091,0.002290,0.058156,290.922699,14.820309,0.581557,-1293.995361,294.500488,0.000000
79.380005,65.341316,-1294.039795,-0.001091,0.002290,0.058156,290.652679,14.806554,0.581557,-1294.039795,294.500488,0.000000
79.670006,65.286568,-1294.039795,-0.001095,0.002290,0.058156,290.409149,14.794147,0.581557,-1294.039795,294.500488,0.000000
79.960007,65.199806,-1294.039795,-0.001091,0.002290,0.058165,290.023224,14.774487,0.581648,-1294.039795,294.500488,0.000000
80.250000,65.234810,-1294.039795,-0.001099,0.002292,0.058225,290.178925,14.782419,0.582253,-1294.039795,294.500488,0.000000
80.540001,65.229973,-1293.995361,-0.001095,0.002293,0.058243,290.157410,14.781323,0.582435,-1293.995361,294.500488,0.000000
80.830002,65.181938,-1294.084351,-0.001095,0.002293,0.058251,289.943756,14.770438,0.582510,-1294.084351,294.500488,0.000000
81.120003,65.116402,-1293.995361,-0.001087,0.002295,0.058286,289.652222,14.755588,0.582859,-1293.995361,294.500488,0.000000
81.410004,65.340202,-1294.039795,-0.001091,0.002298,0.058381,290.647736,14.806301,0.583812,-1294.039795,294.500488,0.000000
81.700005,65.355843,-1294.039795,-0.001082,0.002298,0.058381,290.717316,14.809846,0.583812,-1294.039795,294.500488,0.000000
81.990005,65.299614,-1294.039795,-0.001078,0.002298,0.058381,290.467194,14.797104,0.583812,-1294.039795,294.500488,0.000000
82.280006,65.243752,-1293.995361,-0.001082,0.002299,0.058390,290.218689,14.784445,0.583903,-1293.995361,294.500488,0.000000
82.570007,65.167046,-1294.039795,-0.001074,0.002299,0.058399,289.877502,14.767064,0.583994,-1294.039795,294.500488,0.000000
82.860001,65.254555,-1294.039795,-0.001095,0.002302,0.058469,290.266754,14.786894,0.584691,-1294.039795,294.500488,0.000000
83.150002,65.223640,-1294.128784,-0.001087,0.002302,0.058469,290.129242,14.779888,0.584691,-1294.128784,294.500488,0.000000
83.440002,65.156242,-1293.995361,-0.001074,0.002303,0.058486,289.829437,14.764615,0.584857,-1293.995361,294.500488,0.000000
83.730003,65.177101,-1294.039795,-0.001069,0.002305,0.058546,289.922211,14.769342,0.585463,-1294.039795,294.500488,0.000000
84.020004,65.231087,-1294.039795,-0.001078,0.002306,0.058564,290.162354,14.781575,0.585644,-1294.039795,294.500488,0.000000
84.310005,65.202797,-1294.084351,-0.001078,0.002306,0.058572,290.036530,14.775166,0.585720,-1294.084351,294.500488,0.000000
84.600006,65.183052,-1294.039795,-0.001074,0.002307,0.058590,289.948700,14.770691,0.585902,-1294.039795,294.500488,0.000000
84.890007,65.174858,-1294.039795,-0.001061,0.002308,0.058625,289.912262,14.768834,0.586250,-1294.039795,294.500488,0.000000
85.180000,65.160347,-1294.039795,-0.001074,0.002309,0.058642,289.847687,14.765546,0.586416,-1294.039795,294.500488,0.000000
85.470001,65.133904,-1294.039795,-0.001061,0.002310,0.058676,289.730072,14.759553,0.586765,-1294.039795,294.500488,0.000000
85.760002,65.132042,-1293.995361,-0.001065,0.002311,0.058695,289.721802,14.759132,0.586946,-1293.995361,294.500488,0.000000
86.050003,65.142464,-1294.173218,-0.001069,0.002311,0.058711,289.768158,14.761494,0.587113,-1294.173218,294.500488,0.000000
86.340004,65.139854,-1294.084351,-0.001061,0.002313,0.058746,289.756531,14.760902,0.587461,-1294.084351,294.500488,0.000000
86.630005,65.139488,-1294.084351,-0.001065,0.002313,0.058755,289.754913,14.760818,0.587552,-1294.084351,294.500488,0.000000
86.920006,65.170021,-1294.039795,-0.001052,0.002315,0.058798,289.890747,14.767738,0.587976,-1294.039795,294.500488,0.000000
87.210007,65.162209,-1293.995361,-0.001052,0.002315,0.058807,289.855988,14.765968,0.588067,-1293.995361,294.500488,0.000000
87.500008,65.135017,-1294.039795,-0.001069,0.002316,0.058825,289.735016,14.759806,0.588248,-1294.039795,294.500488,0.000000
87.790001,65.102623,-1294.039795,-0.001065,0.002317,0.058841,289.590942,14.752465,0.588415,-1294.039795,294.500488,0.000000
88.080002,65.086235,-1294.039795,-0.001056,0.002317,0.058858,289.518036,14.748752,0.588581,-1294.039795,294.500488,0.000000
88.370003,65.271675,-1294.084351,-0.001052,0.002321,0.058954,290.342926,14.790773,0.589535,-1294.084351,294.500488,0.000000
88.660004,65.283592,-1294.084351,-0.001043,0.002321,0.058954,290.395935,14.793474,0.589535,-1294.084351,294.500488,0.000000
88.950005,65.222893,-1294.039795,-0.001056,0.002321,0.058954,290.125916,14.779719,0.589535,-1294.039795,294.500488,0.000000
89.240005,65.223640,-1294.084351,-0.001069,0.002323,0.058997,290.129242,14.779888,0.589974,-1294.084351,294.500488,0.000000
89.530006,65.224388,-1294.039795,-0.001061,0.002323,0.059007,290.132568,14.780058,0.590065,-1294.039795,294.500488,0.000000
89.820007,65.222160,-1294.084351,-0.001052,0.002324,0.059032,290.122650,14.779552,0.590322,-1294.084351,294.500488,0.000000
90.110001,65.185661,-1294.084351,-0.001061,0.002324,0.059032,289.960297,14.771281,0.590322,-1294.084351,294.500488,0.000000
90.400002,65.307426,-1294.039795,-0.001065,0.002328,0.059119,290.501953,14.798875,0.591185,-1294.039795,294.500488,0.000000
90.690002,65.301094,-1294.039795,-0.001039,0.002328,0.059119,290.473785,14.797440,0.591185,-1294.039795,294.500488,0.000000
90.980003,65.269066,-1294.039795,-0.001048,0.002328,0.059119,290.331299,14.790182,0.591185,-1294.039795,294.500488,0.000000
91.270004,65.210976,-1294.084351,-0.001035,0.002328,0.059119,290.072906,14.777019,0.591185,-1294.084351,294.500488,0.000000
91.560005,65.272423,-1294.039795,-0.001056,0.002330,0.059188,290.346252,14.790943,0.591882,-1294.039795,294.500488,0.000000
91.850006,65.281364,-1294.084351,-0.001052,0.002331,0.059197,290.386017,14.792969,0.591973,-1294.084351,294.500488,0.000000
92.140007,65.275398,-1294.039795,-0.001022,0.002331,0.059214,290.359467,14.791616,0.592139,-1294.039795,294.500488,0.000000
92.430008,65.262001,-1294.084351,-0.001039,0.002332,0.059232,290.299866,14.788581,0.592321,-1294.084351,294.500488,0.000000
92.720001,65.218437,-1294.039795,-0.001035,0.002326,0.059076,290.106110,14.778709,0.590762,-1294.039795,0.059232,0.000000
93.010002,65.103371,-1293.995361,-0.001030,0.002321,0.058963,289.594269,14.752634,0.589626,-1293.995361,0.058798,0.000000
93.300003,64.963356,-1294.084351,-0.001035,0.002306,0.058564,288.971436,14.720907,0.585644,-1294.084351,0.058313,0.000000
93.590004,64.805092,-1294.039795,-0.001022,0.002297,0.058339,288.267456,14.685044,0.583389,-1294.039795,0.057827,0.000000
93.880005,64.677376,-1293.995361,-0.001018,0.002282,0.057974,287.699341,14.656103,0.579740,-1293.995361,0.057341,0.000000
94.170006,64.555229,-1294.039795,-0.001026,0.002262,0.057446,287.156006,14.628424,0.574456,-1294.039795,0.056864,0.000000
94.460007,64.416344,-1293.995361,-0.001030,0.002241,0.056934,286.538208,14.596952,0.569339,-1293.995361,0.056378,0.000000
94.750008,64.345589,-1294.084351,-0.001026,0.002223,0.056457,286.223480,14.580919,0.564570,-1294.084351,0.055892,0.000000
95.040001,64.252495,-1294.039795,-0.001026,0.002201,0.055901,285.809357,14.559824,0.559014,-1294.039795,0.055408,0.000000
95.330002,64.140038,-1293.995361,-0.001043,0.002181,0.055408,285.309143,14.534341,0.554078,-1293.995361,0.054931,0.000000
95.620003,64.027214,-1294.084351,-0.001030,0.002165,0.054991,284.807281,14.508774,0.549915,-1294.084351,0.054445,0.000000
95.910004,63.929283,-1294.039795,-0.001026,0.002147,0.054522,284.371643,14.486583,0.545222,-1294.039795,0.053959,0.000000
96.200005,63.742714,-1294.039795,-0.001043,0.002128,0.054045,283.541748,14.444305,0.540453,-1294.039795,0.053473,0.000000
96.490005,63.648506,-1294.039795,-0.001018,0.002111,0.053621,283.122681,14.422957,0.536214,-1294.039795,0.052996,0.000000
96.780006,62.994995,-1293.995361,-0.001013,0.002087,0.053022,280.215729,14.274870,0.530218,-1293.995361,0.052510,0.000000
97.070007,62.496384,-1294.039795,-0.000996,0.002074,0.052684,277.997803,14.161883,0.526842,-1294.039795,0.052026,0.000000
97.360008,61.768028,-1293.995361,-0.001005,0.002055,0.052207,274.757904,13.996835,0.522073,-1293.995361,0.051549,0.000000
97.650002,60.815125,-1294.039795,-0.001018,0.002038,0.051756,270.519196,13.780904,0.517562,-1294.039795,0.051063,0.000000
97.940002,59.889778,-1294.084351,-0.001013,0.002022,0.051358,266.403046,13.571218,0.513580,-1294.084351,0.050577,0.000000
98.230003,58.617386,-1293.995361,-0.001005,0.002003,0.050881,260.743164,13.282889,0.508811,-1293.995361,0.050091,0.000000
98.520004,57.522980,-1293.995361,-0.001018,0.001989,0.050516,255.875000,13.034894,0.505162,-1293.995361,0.049614,0.000000
98.810005,56.121368,-1294.039795,-0.001005,0.001968,0.049995,249.640320,12.717283,0.499954,-1294.039795,0.049128,0.000000
99.100006,54.723114,-1293.950806,-0.001009,0.001952,0.049572,243.420563,12.400435,0.495715,-1293.950806,0.048643,0.000000
99.390007,53.573601,-1294.084351,-0.001022,0.001935,0.049155,238.307281,12.139952,0.491552,-1294.084351,0.048157,0.000000
99.680008,51.555336,-1293.995361,-0.001005,0.001915,0.048651,229.329590,11.682606,0.486510,-1293.995361,0.047681,0.000000
99.970001,49.920998,-1294.084351,-0.001013,0.001899,0.048244,222.059692,11.312260,0.482438,-1294.084351,0.047195,0.000000
100.260002,47.599998,-1294.084351,-0.001013,0.001876,0.047646,211.735367,10.786314,0.476458,-1294.084351,0.046709,0.000000
100.550003,45.971985,-1293.995361,-0.001018,0.001860,0.047255,204.493607,10.417400,0.472552,-1293.995361,0.046223,0.000000
100.840004,43.652107,-1294.084351,-0.001018,0.001838,0.046674,194.174271,9.891709,0.466738,-1294.084351,0.045746,0.000000
101.130005,42.335396,-1293.995361,-0.001013,0.001826,0.046371,188.317245,9.593338,0.463710,-1293.995361,0.045261,0.000000
101.420006,40.437790,-1293.995361,-0.001026,0.001806,0.045868,179.876266,9.163335,0.458684,-1293.995361,0.044775,0.000000
101.710007,38.078438,-1294.084351,-0.001018,0.001780,0.045217,169.381348,8.628696,0.452174,-1294.084351,0.044289,0.000000
102.000008,36.672729,-1293.995361,-0.001026,0.001767,0.044880,163.128448,8.310159,0.448798,-1293.995361,0.043812,0.000000
102.290009,34.641068,-1294.039795,-0.001043,0.001747,0.044376,154.091171,7.849778,0.443756,-1294.039795,0.043326,0.000000
102.580002,33.002998,-1293.950806,-0.001039,0.001729,0.043926,146.804672,7.478587,0.439260,-1293.950806,0.042840,0.000000
102.870003,30.740089,-1294.084351,-0.001052,0.001709,0.043396,136.738754,6.965804,0.433961,-1294.084351,0.042364,0.000000
103.160004,29.535835,-1293.950806,-0.001043,0.001696,0.043066,131.381958,6.692916,0.430660,-1293.950806,0.041879,0.000000
103.450005,27.604340,-1293.995361,-0.001061,0.001675,0.042554,122.790237,6.255233,0.425543,-1293.995361,0.041393,0.000000
103.740005,25.682159,-1294.039795,-0.001061,0.001657,0.042096,114.239952,5.819661,0.420956,-1294.039795,0.040907,0.000000
104.030006,22.776535,-1293.995361,-0.001065,0.001629,0.041367,101.315086,5.161237,0.413674,-1293.995361,0.040430,0.000000
104.320007,21.027870,-1294.039795,-0.001078,0.001613,0.040977,93.536636,4.764984,0.409768,-1294.039795,0.039944,0.000000
104.610008,19.552902,-1294.039795,-0.001074,0.001600,0.040630,86.975655,4.430751,0.406301,-1294.039795,0.039458,0.000000
104.900002,17.055405,-1294.039795,-0.001095,0.001574,0.039979,75.866226,3.864810,0.399791,-1294.039795,0.038974,0.000000
105.190002,15.374886,-1293.995361,-0.001091,0.001557,0.039554,68.390907,3.483999,0.395537,-1293.995361,0.038497,0.000000
105.480003,14.038071,-1294.039795,-0.001091,0.001541,0.039139,62.444458,3.181072,0.391388,-1294.039795,0.038011,0.000000
105.770004,11.600891,-1294.039795,-0.001108,0.001519,0.038592,51.603340,2.628800,0.385923,-1294.039795,0.037525,0.000000
106.060005,9.442993,-1293.995361,-0.001117,0.001497,0.038028,42.004532,2.139813,0.380276,-1293.995361,0.037039,0.000000
106.350006,8.152725,-1293.995361,-0.001121,0.001484,0.037699,36.265133,1.847434,0.376991,-1293.995361,0.036562,0.000000
106.640007,5.991104,-1294.084351,-0.001125,0.001457,0.037013,26.649761,1.357604,0.370132,-1294.084351,0.036076,0.000000
106.930008,4.576454,-1293.950806,-0.001134,0.001444,0.036683,20.357084,1.037039,0.366832,-1293.950806,0.035592,0.000000
107.220009,2.318764,-1294.039795,-0.001143,0.001422,0.036129,10.314376,0.525439,0.361291,-1294.039795,0.035106,0.000000
107.510002,0.653885,-1294.084351,-0.001164,0.001404,0.035652,2.908625,0.148172,0.356522,-1294.084351,0.034629,0.000000
107.800003,-1.350967,-1293.995361,-0.001160,0.001378,0.035001,-6.009403,-0.306134,0.350012,-1293.995361,0.034143,0.000000
108.090004,-2.544792,-1294.084351,-0.001177,0.001365,0.034664,-11.319801,-0.576658,0.346636,-1294.084351,0.033657,0.000000
108.380005,-3.596001,-1293.995361,-0.001177,0.001350,0.034282,-15.995810,-0.814865,0.342821,-1293.995361,0.033180,0.000000
108.670006,-0.035751,-1293.995361,-0.001250,0.001330,0.033787,-0.159030,-0.008101,0.337870,-1293.995361,0.032694,0.000000
108.960007,-0.050644,-1293.995361,-0.001259,0.001319,0.033501,-0.225275,-0.011476,0.335009,-1293.995361,0.032209,0.000000
109.250008,-0.028297,-1293.950806,-0.001315,0.001285,0.032642,-0.125873,-0.006412,0.326424,-1293.950806,0.031723,0.000000
109.540009,-0.031281,-1294.039795,-0.001341,0.001267,0.032191,-0.139143,-0.007088,0.321913,-1294.039795,0.031247,0.000000
109.830002,-0.039841,-1294.084351,-0.001375,0.001245,0.031619,-0.177220,-0.009028,0.316190,-1294.084351,0.030761,0.000000
110.120003,-0.040215,-1293.906372,-0.001406,0.001231,0.031256,-0.178883,-0.009113,0.312557,-1293.906372,0.030275,0.000000
110.410004,-0.002609,-1294.084351,-0.001440,0.001210,0.030744,-0.011607,-0.000591,0.307439,-1294.084351,0.029790,0.000000
110.700005,-0.009682,-1294.039795,-0.001462,0.001193,0.030302,-0.043066,-0.002194,0.303019,-1294.039795,0.029312,0.000000
110.990005,-0.008934,-1294.039795,-0.001505,0.001176,0.029858,-0.039741,-0.002024,0.298583,-1294.039795,0.028827,0.000000
111.280006,0.015640,-1294.039795,-0.001539,0.001151,0.029235,0.069571,0.003544,0.292345,-1294.039795,0.028341,0.000000
111.570007,-0.001114,-1294.039795,-0.001578,0.001136,0.028853,-0.004955,-0.000252,0.288530,-1294.039795,0.027855,0.000000
111.860008,0.010056,-1294.039795,-0.001604,0.001114,0.028306,0.044729,0.002279,0.283065,-1294.039795,0.027378,0.000000
112.150002,-0.032021,-1293.995361,-0.001638,0.001090,0.027683,-0.142435,-0.007256,0.276827,-1293.995361,0.026892,0.000000
112.440002,0.026436,-1294.084351,-0.001677,0.001076,0.027335,0.117593,0.005990,0.273345,-1294.084351,0.026408,0.000000
112.730003,0.002609,-1294.039795,-0.001694,0.001066,0.027076,0.011607,0.000591,0.270756,-1294.039795,0.025922,0.000000
113.020004,-0.021225,-1294.039795,-0.001746,0.001044,0.026511,-0.094413,-0.004810,0.265109,-1294.039795,0.025445,0.000000
113.310005,-0.021225,-1293.995361,-0.001772,0.001022,0.025964,-0.094413,-0.004810,0.259644,-1293.995361,0.024959,0.000000
113.600006,0.005211,-1293.995361,-0.001807,0.001010,0.025653,0.023179,0.001181,0.256525,-1293.995361,0.024473,0.000000
113.890007,0.004471,-1293.995361,-0.001832,0.000983,0.024959,0.019887,0.001013,0.249591,-1293.995361,0.023996,0.000000
114.180008,-0.019363,-1293.995361,-0.001880,0.000957,0.024308,-0.086133,-0.004388,0.243081,-1293.995361,0.023510,0.000000
114.470009,-0.012657,-1293.995361,-0.001901,0.000948,0.024075,-0.056302,-0.002868,0.240750,-1293.995361,0.023026,0.000000
114.760002,0.008934,-1294.039795,-0.001914,0.000941,0.023892,0.039741,0.002024,0.238918,-1294.039795,0.023831,0.000000
114.800003,0.009308,-1293.995361,-0.001927,0.000941,0.023901,0.041403,0.002109,0.239009,-1293.995361,0.023831,0.000000