File: Data/Sima compression/P1-15-1re_10302024_171049.csv
Time (sec),S:Load (lbs),S:HL1 (DIM),S:LVDT (in),S:Position (in),Ch:Position (mm),Ch:Load (N),Ch:Stress (MPa),Ch:Strain (mm/mm),Ch:HL1 (DIM),Set Point (),Cycles ()
0.210000,-0.003349,-1294.084351,-0.007148,-0.004126,-0.104805,-0.014898,-0.000759,-1.048053,-1294.084351,-0.104605,0.000000
0.520000,-0.027557,-1293.995361,-0.007127,-0.004058,-0.103079,-0.122581,-0.006245,-1.030793,-1293.995361,-0.102489,0.000000
0.830000,0.029419,-1294.039795,-0.007041,-0.003874,-0.098388,0.130862,0.006666,-0.983876,-1294.039795,-0.097320,0.000000
1.140000,0.003723,-1293.995361,-0.006825,-0.003674,-0.093322,0.016561,0.000844,-0.933219,-1293.995361,-0.092152,0.000000
1.450000,0.002235,-1294.039795,-0.006631,-0.003483,-0.088458,0.009944,0.000507,-0.884575,-1294.039795,-0.086983,0.000000
1.760000,-0.028671,-1294.039795,-0.006403,-0.003266,-0.082951,-0.127536,-0.006497,-0.829513,-1294.039795,-0.081832,0.000000
2.070000,-0.032021,-1294.039795,-0.006200,-0.003057,-0.077652,-0.142435,-0.007256,-0.776524,-1294.039795,-0.076664,0.000000
2.380000,0.036118,-1294.084351,-0.006010,-0.002858,-0.072596,0.160659,0.008184,-0.725958,-1294.084351,-0.071495,0.000000
2.690000,-0.020477,-1293.995361,-0.005790,-0.002658,-0.067506,-0.091088,-0.004640,-0.675059,-1293.995361,-0.066326,0.000000
3.000000,0.057343,-1294.039795,-0.005579,-0.002458,-0.062424,0.255072,0.012994,-0.624235,-1294.039795,-0.061158,0.000000
3.310000,0.008194,-1294.084351,-0.005372,-0.002251,-0.057169,0.036449,0.001857,-0.571686,-1294.084351,-0.056006,0.000000
3.620000,0.006332,-1294.039795,-0.005144,-0.002043,-0.051886,0.028168,0.001435,-0.518864,-1294.039795,-0.050837,0.000000
3.930000,0.007072,-1294.039795,-0.004967,-0.001848,-0.046934,0.031460,0.001603,-0.469342,-1294.039795,-0.045669,0.000000
4.240000,-0.081177,-1294.039795,-0.004743,-0.001638,-0.041601,-0.361092,-0.018395,-0.416005,-1294.039795,-0.040500,0.000000
4.550000,0.027184,-1294.084351,-0.004536,-0.001445,-0.036701,0.120918,0.006160,-0.367014,-1294.084351,-0.035348,0.000000
4.860000,0.006332,-1293.995361,-0.004324,-0.001234,-0.031342,0.028168,0.001435,-0.313420,-1293.995361,-0.030179,0.000000
5.170000,0.052879,-1293.995361,-0.004113,-0.001027,-0.026095,0.235219,0.011983,-0.260946,-1293.995361,-0.025011,0.000000
5.480000,0.023087,-1294.039795,-0.003915,-0.000823,-0.020909,0.102694,0.005231,-0.209093,-1294.039795,-0.019842,0.000000
5.790000,-0.020851,-1293.995361,-0.003708,-0.000622,-0.015801,-0.092750,-0.004725,-0.158012,-1293.995361,-0.014691,0.000000
6.100000,-0.010056,-1294.084351,-0.003484,-0.000424,-0.010772,-0.044729,-0.002279,-0.107718,-1294.084351,-0.009523,0.000000
6.410000,-0.052505,-1293.995361,-0.003294,-0.000213,-0.005420,-0.233556,-0.011898,-0.054200,-1293.995361,-0.004354,0.000000
6.720000,0.076706,-1294.039795,-0.003147,-0.000009,-0.000218,0.341205,0.017382,-0.002180,-1294.039795,0.000008,0.000000
7.030000,0.073730,-1294.084351,-0.003152,-0.000009,-0.000218,0.327969,0.016708,-0.002180,-1294.084351,0.000008,0.000000
7.340000,0.105751,-1293.950806,-0.003143,-0.000009,-0.000218,0.470404,0.023964,-0.002180,-1293.950806,0.000347,0.000000
7.650001,0.113571,-1293.995361,-0.003143,0.000000,0.000008,0.505190,0.025736,0.000076,-1293.995361,0.000858,0.000000
7.960001,0.247253,-1294.039795,-0.003134,0.000020,0.000510,1.099838,0.056028,0.005102,-1294.039795,0.001378,0.000000
8.270000,0.290451,-1294.084351,-0.003117,0.000031,0.000798,1.291991,0.065817,0.007979,-1294.084351,0.001889,0.000000
8.580001,0.353012,-1294.039795,-0.003100,0.000050,0.001275,1.570276,0.079994,0.012748,-1294.039795,0.002410,0.000000
8.890000,0.500099,-1293.995361,-0.003070,0.000082,0.002073,2.224552,0.113324,0.020726,-1293.995361,0.002931,0.000000
9.200001,0.595055,-1294.039795,-0.003057,0.000100,0.002540,2.646935,0.134841,0.025404,-1294.039795,0.003443,0.000000
9.510000,0.713837,-1293.995361,-0.003044,0.000116,0.002948,3.175304,0.161758,0.029477,-1293.995361,0.003962,0.000000
9.820001,0.986046,-1293.995361,-0.003040,0.000142,0.003599,4.386151,0.223441,0.035987,-1293.995361,0.004474,0.000000
10.130000,1.094406,-1294.084351,-0.002997,0.000154,0.003911,4.868162,0.247996,0.039106,-1294.084351,0.004995,0.000000
10.440001,1.365120,-1293.906372,-0.003001,0.000174,0.004422,6.072357,0.309341,0.044223,-1293.906372,0.005506,0.000000
10.750001,1.873405,-1294.084351,-0.002962,0.000203,0.005160,8.333323,0.424520,0.051596,-1294.084351,0.006027,0.000000
11.060000,2.231255,-1294.039795,-0.002940,0.000223,0.005662,9.925116,0.505610,0.056622,-1294.039795,0.006546,0.000000
11.370001,2.566391,-1293.995361,-0.002932,0.000238,0.006035,11.415877,0.581553,0.060346,-1293.995361,0.007058,0.000000
11.680000,3.313744,-1293.995361,-0.002902,0.000262,0.006667,14.740268,0.750905,0.066675,-1293.995361,0.007579,0.000000
11.990001,3.743088,-1293.995361,-0.002889,0.000279,0.007084,16.650085,0.848196,0.070838,-1293.995361,0.008091,0.000000
12.300000,4.356758,-1293.995361,-0.002884,0.000297,0.007553,19.379827,0.987256,0.075531,-1293.995361,0.008611,0.000000
12.610001,5.340935,-1293.995361,-0.002871,0.000327,0.008307,23.757664,1.210273,0.083071,-1293.995361,0.009131,0.000000
12.920001,5.925194,-1293.950806,-0.002833,0.000343,0.008723,26.356579,1.342668,0.087234,-1293.950806,0.009642,0.000000
13.230000,6.628975,-1294.084351,-0.002837,0.000363,0.009226,29.487154,1.502147,0.092261,-1294.084351,0.010163,0.000000
13.540001,7.526016,-1293.950806,-0.002802,0.000386,0.009798,33.477394,1.705420,0.097983,-1293.950806,0.010675,0.000000
13.850000,8.364227,-1294.039795,-0.002798,0.000407,0.010328,37.205940,1.895361,0.103282,-1294.039795,0.011196,0.000000
14.160001,9.009552,-1293.995361,-0.002781,0.000422,0.010719,40.076488,2.041594,0.107188,-1293.995361,0.011707,0.000000
14.470000,10.169495,-1293.995361,-0.002764,0.000447,0.011352,45.236172,2.304440,0.113517,-1293.995361,0.012227,0.000000
14.780001,10.843483,-1294.039795,-0.002751,0.000467,0.011854,48.234222,2.457168,0.118543,-1294.039795,0.012748,0.000000
15.090001,11.540565,-1294.039795,-0.002742,0.000485,0.012315,51.334999,2.615129,0.123145,-1294.039795,0.013259,0.000000
15.400001,12.485275,-1294.084351,-0.002721,0.000508,0.012903,55.537277,2.829204,0.129035,-1294.084351,0.013780,0.000000
15.710001,13.166344,-1294.039795,-0.002721,0.000525,0.013329,58.566822,2.983536,0.133289,-1294.039795,0.014292,0.000000
16.020000,13.590477,-1293.995361,-0.002703,0.000538,0.013657,60.453461,3.079646,0.136574,-1293.995361,0.014811,0.000000
16.330000,14.449165,-1294.039795,-0.002695,0.000556,0.014127,64.273094,3.274228,0.141267,-1294.039795,0.015323,0.000000
16.640001,15.979988,-1293.995361,-0.002656,0.000587,0.014906,71.082535,3.621117,0.149064,-1293.995361,0.015844,0.000000
16.950001,16.643188,-1294.084351,-0.002656,0.000606,0.015383,74.032600,3.771400,0.153833,-1294.084351,0.016364,0.000000
17.260000,17.167488,-1293.995361,-0.002630,0.000622,0.015809,76.364799,3.890208,0.158087,-1293.995361,0.016876,0.000000
17.570002,18.470795,-1293.950806,-0.002608,0.000650,0.016502,82.162201,4.185542,0.165021,-1293.950806,0.017395,0.000000
17.880001,18.948174,-1293.995361,-0.002591,0.000664,0.016867,84.285683,4.293717,0.168670,-1293.995361,0.017907,0.000000
18.190001,19.340652,-1293.950806,-0.002583,0.000679,0.017249,86.031517,4.382655,0.172485,-1293.950806,0.018428,0.000000
18.500000,20.722527,-1294.084351,-0.002570,0.000707,0.017960,92.178398,4.695792,0.179601,-1294.084351,0.018949,0.000000
18.810001,21.338806,-1294.039795,-0.002557,0.000728,0.018479,94.919754,4.835443,0.184794,-1294.039795,0.019460,0.000000
19.120001,21.977051,-1294.039795,-0.002535,0.000746,0.018956,97.758804,4.980071,0.189563,-1294.039795,0.019980,0.000000
19.430000,22.837975,-1294.084351,-0.002501,0.000769,0.019521,101.588387,5.175159,0.195210,-1294.084351,0.020491,0.000000
19.740002,23.647514,-1293.950806,-0.002501,0.000788,0.020015,105.189400,5.358603,0.200145,-1293.950806,0.021012,0.000000
20.050001,24.059357,-1294.039795,-0.002488,0.000803,0.020405,107.021362,5.451928,0.204051,-1294.039795,0.021524,0.000000
20.360001,23.790878,-1294.039795,-0.002479,0.000815,0.020700,105.827110,5.391090,0.207003,-1294.039795,0.022045,0.000000
20.670000,25.868340,-1294.039795,-0.002436,0.000851,0.021610,115.068123,5.861850,0.216102,-1294.039795,0.022564,0.000000
20.980001,26.296944,-1294.084351,-0.002432,0.000869,0.022070,116.974648,5.958973,0.220705,-1294.084351,0.023076,0.000000
21.290001,26.643623,-1294.039795,-0.002406,0.000888,0.022564,118.516754,6.037531,0.225640,-1294.039795,0.023597,0.000000
21.600000,27.777496,-1294.084351,-0.002393,0.000914,0.023224,123.560478,6.294470,0.232241,-1294.084351,0.024108,0.000000
21.910002,27.976715,-1293.950806,-0.002367,0.000930,0.023622,124.446648,6.339614,0.236223,-1293.950806,0.024629,0.000000
22.220001,28.012833,-1293.995361,-0.002345,0.000948,0.024090,124.607300,6.347798,0.240901,-1293.995361,0.025148,0.000000
22.530001,29.238312,-1294.039795,-0.002324,0.000974,0.024750,130.058502,6.625496,0.247502,-1294.039795,0.025660,0.000000
22.840000,29.575684,-1294.084351,-0.002298,0.000996,0.025288,131.559204,6.701945,0.252876,-1294.084351,0.026181,0.000000
23.150002,29.753677,-1294.039795,-0.002289,0.001012,0.025704,132.350967,6.742280,0.257040,-1294.039795,0.026693,0.000000
23.460001,30.303673,-1293.995361,-0.002268,0.001034,0.026276,134.797470,6.866910,0.262763,-1293.995361,0.027213,0.000000
23.770000,30.355057,-1294.039795,-0.002242,0.001050,0.026658,135.026031,6.878554,0.266578,-1294.039795,0.027725,0.000000
24.080002,30.689819,-1294.039795,-0.002225,0.001068,0.027126,136.515137,6.954412,0.271256,-1294.039795,0.028244,0.000000
24.390001,32.144684,-1293.995361,-0.002186,0.001098,0.027889,142.986694,7.284090,0.278886,-1293.995361,0.028765,0.000000
24.700001,32.104836,-1294.084351,-0.002169,0.001117,0.028384,142.809448,7.275060,0.283837,-1294.084351,0.029277,0.000000
25.010002,32.454124,-1293.995361,-0.002147,0.001137,0.028877,144.363159,7.354210,0.288772,-1293.995361,0.029798,0.000000
25.320002,32.754623,-1293.995361,-0.002121,0.001158,0.029407,145.699844,7.422304,0.294071,-1293.995361,0.030309,0.000000
25.630001,32.631744,-1294.039795,-0.002113,0.001170,0.029719,145.153244,7.394459,0.297190,-1294.039795,0.030829,0.000000
25.940001,33.223068,-1293.950806,-0.002074,0.001193,0.030291,147.783585,7.528455,0.302913,-1293.950806,0.031340,0.000000
26.250002,33.988670,-1294.039795,-0.002061,0.001217,0.030924,151.189163,7.701942,0.309241,-1294.039795,0.031861,0.000000
26.560001,34.104477,-1294.039795,-0.002044,0.001238,0.031445,151.704285,7.728185,0.314449,-1294.039795,0.032382,0.000000
26.870001,34.450409,-1294.039795,-0.002013,0.001258,0.031948,153.243073,7.806574,0.319475,-1294.039795,0.032894,0.000000
27.180002,34.705116,-1293.995361,-0.002001,0.001279,0.032477,154.376068,7.864292,0.324774,-1293.995361,0.033413,0.000000
27.490002,35.068550,-1293.995361,-0.001962,0.001296,0.032910,155.992706,7.946647,0.329104,-1293.995361,0.033925,0.000000
27.800001,35.149353,-1293.995361,-0.001953,0.001311,0.033310,156.352127,7.964957,0.333101,-1293.995361,0.034446,0.000000
28.110001,36.766197,-1293.995361,-0.001919,0.001346,0.034176,163.544220,8.331339,0.341761,-1293.995361,0.034966,0.000000
28.420002,36.574051,-1294.084351,-0.001897,0.001362,0.034592,162.689499,8.287798,0.345924,-1294.084351,0.035478,0.000000
28.730001,36.402016,-1294.039795,-0.001871,0.001378,0.035001,161.924255,8.248815,0.350012,-1294.039795,0.035997,0.000000
29.040001,36.714806,-1294.039795,-0.001850,0.001398,0.035520,163.315613,8.319695,0.355205,-1294.039795,0.036509,0.000000
29.350002,37.429390,-1293.995361,-0.001815,0.001421,0.036085,166.494247,8.481621,0.360852,-1293.995361,0.037030,0.000000
29.660002,37.450241,-1293.995361,-0.001811,0.001438,0.036518,166.586990,8.486345,0.365182,-1293.995361,0.037542,0.000000
29.970001,37.096115,-1293.995361,-0.001781,0.001448,0.036779,165.011765,8.406099,0.367786,-1293.995361,0.038062,0.000000
30.280001,38.413940,-1294.039795,-0.001755,0.001479,0.037558,170.873734,8.704723,0.375583,-1294.039795,0.038582,0.000000
30.590002,38.839561,-1293.906372,-0.001720,0.001500,0.038088,172.766998,8.801170,0.380882,-1293.906372,0.039093,0.000000
30.900002,38.834724,-1294.039795,-0.001716,0.001518,0.038556,172.745483,8.800075,0.385560,-1294.039795,0.039614,0.000000
31.210001,39.842361,-1293.950806,-0.001677,0.001545,0.039233,177.227676,9.028408,0.392327,-1293.950806,0.040126,0.000000
31.520002,39.371315,-1293.995361,-0.001660,0.001554,0.039467,175.132355,8.921667,0.394674,-1293.995361,0.040647,0.000000
31.830002,40.065414,-1293.995361,-0.001647,0.001582,0.040186,178.219864,9.078953,0.401865,-1293.995361,0.041166,0.000000
32.140003,40.979218,-1294.039795,-0.001630,0.001604,0.040742,182.284668,9.286023,0.407421,-1294.039795,0.041678,0.000000
32.450001,41.210831,-1294.039795,-0.001613,0.001623,0.041227,183.314926,9.338509,0.412266,-1294.039795,0.042199,0.000000
32.760002,41.197800,-1293.906372,-0.001582,0.001641,0.041670,183.256958,9.335555,0.416702,-1293.906372,0.042710,0.000000
33.070000,41.956322,-1294.039795,-0.001561,0.001661,0.042199,186.631042,9.507439,0.421986,-1294.039795,0.043231,0.000000
33.380001,42.246025,-1293.995361,-0.001535,0.001679,0.042659,187.919708,9.573086,0.426588,-1293.995361,0.043743,0.000000
33.690002,42.609467,-1294.039795,-0.001509,0.001700,0.043169,189.536377,9.655442,0.431690,-1294.039795,0.044262,0.000000
34.000000,43.951118,-1293.995361,-0.001500,0.001729,0.043906,195.504333,9.959466,0.439063,-1293.995361,0.044783,0.000000
34.310001,44.033043,-1293.995361,-0.001462,0.001746,0.044341,195.868759,9.978030,0.443408,-1293.995361,0.045295,0.000000
34.620003,44.520477,-1294.084351,-0.001462,0.001765,0.044834,198.036972,10.088484,0.448344,-1294.084351,0.045815,0.000000
34.930000,44.982964,-1293.950806,-0.001427,0.001787,0.045399,200.094208,10.193285,0.453991,-1293.950806,0.046327,0.000000
35.240002,45.563492,-1294.039795,-0.001406,0.001806,0.045884,202.676529,10.324835,0.458835,-1294.039795,0.046846,0.000000
35.550003,45.695686,-1294.084351,-0.001388,0.001821,0.046257,203.264572,10.354791,0.462575,-1294.084351,0.047367,0.000000
35.860001,47.020592,-1293.995361,-0.001354,0.001849,0.046977,209.158035,10.655019,0.469766,-1293.995361,0.047879,0.000000
36.170002,47.309921,-1293.995361,-0.001350,0.001866,0.047384,210.445038,10.720581,0.473839,-1293.995361,0.048400,0.000000
36.480003,48.034927,-1293.950806,-0.001319,0.001889,0.047983,213.670029,10.884871,0.479834,-1293.950806,0.048911,0.000000
36.790001,48.594604,-1294.084351,-0.001306,0.001909,0.048486,216.159592,11.011695,0.484860,-1294.084351,0.049431,0.000000
37.100002,48.916336,-1293.950806,-0.001298,0.001928,0.048980,217.590729,11.084600,0.489796,-1293.950806,0.049942,0.000000
37.410004,49.385155,-1294.039795,-0.001268,0.001946,0.049440,219.676132,11.190837,0.494398,-1294.039795,0.050463,0.000000
37.720001,49.397072,-1294.084351,-0.001263,0.001965,0.049917,219.729156,11.193537,0.499167,-1294.084351,0.050984,0.000000
38.030003,50.966988,-1293.995361,-0.001229,0.001988,0.050507,226.712479,11.549284,0.505072,-1293.995361,0.051496,0.000000
38.340000,51.366173,-1294.039795,-0.001207,0.002007,0.050966,228.488144,11.639741,0.509659,-1294.039795,0.052015,0.000000
38.650002,51.671890,-1293.950806,-0.001194,0.002026,0.051461,229.848053,11.709018,0.514609,-1293.950806,0.052527,0.000000
38.960003,52.861252,-1294.039795,-0.001177,0.002050,0.052068,235.138596,11.978531,0.520680,-1294.039795,0.053048,0.000000
39.270000,53.045204,-1293.995361,-0.001151,0.002066,0.052484,235.956848,12.020215,0.524844,-1293.995361,0.053559,0.000000
39.580002,52.999771,-1294.039795,-0.001130,0.002078,0.052787,235.754761,12.009920,0.527872,-1294.039795,0.054080,0.000000
39.890003,54.637466,-1293.995361,-0.001112,0.002109,0.053568,243.039597,12.381027,0.535684,-1293.995361,0.054599,0.000000
40.200001,55.319283,-1293.950806,-0.001091,0.002130,0.054106,246.072464,12.535528,0.541058,-1293.950806,0.055111,0.000000
40.510002,55.710274,-1294.039795,-0.001069,0.002148,0.054565,247.811676,12.624128,0.545646,-1294.039795,0.055632,0.000000
40.820004,56.669128,-1293.995361,-0.001052,0.002170,0.055120,252.076874,12.841408,0.551202,-1293.995361,0.056144,0.000000
41.130001,57.289879,-1294.039795,-0.001026,0.002189,0.055588,254.838104,12.982072,0.555880,-1294.039795,0.056664,0.000000
41.440002,57.534149,-1293.995361,-0.001026,0.002203,0.055962,255.924683,13.037425,0.559619,-1293.995361,0.057184,0.000000
41.750004,58.740639,-1293.950806,-0.001005,0.002228,0.056595,261.291412,13.310820,0.565948,-1293.950806,0.057695,0.000000
42.060001,59.864090,-1293.995361,-0.000983,0.002253,0.057219,266.288757,13.565397,0.572185,-1293.995361,0.058216,0.000000
42.370003,60.341469,-1293.995361,-0.000953,0.002272,0.057714,268.412262,13.673573,0.577136,-1293.995361,0.058728,0.000000
42.680000,60.996468,-1293.950806,-0.000944,0.002291,0.058181,271.325836,13.821998,0.581814,-1293.950806,0.059249,0.000000
42.990002,62.283020,-1294.084351,-0.000931,0.002316,0.058814,277.048706,14.113534,0.588142,-1294.084351,0.059760,0.000000
43.300003,62.502716,-1294.039795,-0.000901,0.002330,0.059187,278.025970,14.163318,0.591867,-1294.039795,0.060280,0.000000
43.610001,63.823524,-1294.039795,-0.000875,0.002359,0.059924,283.901215,14.462617,0.599240,-1294.039795,0.060801,0.000000
43.920002,64.647957,-1294.039795,-0.000875,0.002378,0.060401,287.568481,14.649437,0.604009,-1294.039795,0.061312,0.000000
44.230003,65.163322,-1294.039795,-0.000849,0.002396,0.060852,289.860931,14.766220,0.608520,-1294.039795,0.061833,0.000000
44.540001,65.675331,-1294.128784,-0.000836,0.002414,0.061303,292.138458,14.882242,0.613032,-1294.128784,0.062345,0.000000
44.850002,66.341881,-1294.039795,-0.000819,0.002425,0.061598,295.103424,15.033285,0.615984,-1294.039795,0.061780,0.000000
45.160004,64.915688,-1293.995361,-0.000798,0.002423,0.061555,288.759399,14.710105,0.615545,-1293.995361,288.714661,0.000000
45.470001,65.426216,-1293.995361,-0.000798,0.002436,0.061866,291.030334,14.825793,0.618664,-1293.995361,294.500488,0.000000
45.780003,67.033379,-1294.039795,-0.000763,0.002417,0.061382,298.179352,15.189981,0.613819,-1294.039795,294.500488,0.000000
46.090004,65.550957,-1293.995361,-0.000746,0.002404,0.061052,291.585205,14.854059,0.610519,-1293.995361,294.500488,0.000000
46.400002,65.195717,-1294.039795,-0.000755,0.002477,0.062917,290.005035,14.773561,0.629171,-1294.039795,294.500488,0.000000
46.710003,65.163322,-1294.039795,-0.000737,0.002485,0.063124,289.860931,14.766220,0.631245,-1294.039795,294.500488,0.000000
47.020000,65.857048,-1294.039795,-0.000733,0.002495,0.063385,292.946777,14.923420,0.633849,-1294.039795,294.500488,0.000000
47.330002,65.025536,-1293.995361,-0.000711,0.002495,0.063385,289.248016,14.734997,0.633849,-1293.995361,294.500488,0.000000
47.640003,66.201118,-1294.039795,-0.000694,0.002475,0.062873,294.477295,15.001388,0.628732,-1294.039795,294.500488,0.000000
47.950001,65.330147,-1294.039795,-0.000711,0.002502,0.063550,290.602997,14.804023,0.635499,-1294.039795,294.500488,0.000000
48.260002,65.269447,-1294.128784,-0.000698,0.002521,0.064036,290.333008,14.790268,0.640359,-1294.128784,294.500488,0.000000
48.570004,65.226616,-1294.039795,-0.000681,0.002529,0.064243,290.142487,14.780562,0.642433,-1294.039795,294.500488,0.000000
48.880001,65.230339,-1293.950806,-0.000673,0.002534,0.064373,290.159027,14.781406,0.643735,-1293.950806,294.500488,0.000000
49.190002,65.240776,-1294.084351,-0.000677,0.002542,0.064555,290.205475,14.783772,0.645552,-1294.084351,294.500488,0.000000
49.500004,65.190132,-1294.039795,-0.000660,0.002546,0.064676,289.980194,14.772295,0.646763,-1294.039795,294.500488,0.000000
49.810001,65.197212,-1294.039795,-0.000673,0.002553,0.064841,290.011688,14.773900,0.648413,-1294.039795,294.500488,0.000000
50.120003,65.184914,-1293.995361,-0.000642,0.002559,0.065006,289.956970,14.771112,0.650063,-1293.995361,294.500488,0.000000
50.430004,65.324928,-1294.039795,-0.000629,0.002565,0.065162,290.579803,14.802840,0.651623,-1294.039795,294.500488,0.000000
50.740002,65.056816,-1294.039795,-0.000642,0.002567,0.065206,289.387177,14.742085,0.652062,-1294.039795,294.500488,0.000000
51.050003,65.082146,-1294.039795,-0.000634,0.002572,0.065327,289.499847,14.747825,0.653273,-1294.039795,294.500488,0.000000
51.360001,65.242256,-1294.039795,-0.000621,0.002578,0.065474,290.212036,14.784107,0.654741,-1294.039795,294.500488,0.000000
51.670002,65.247108,-1294.039795,-0.000625,0.002582,0.065588,290.233643,14.785206,0.655877,-1294.039795,294.500488,0.000000
51.980003,65.100761,-1294.084351,-0.000612,0.002586,0.065674,289.582642,14.752044,0.656740,-1294.084351,294.500488,0.000000
52.290001,65.238914,-1294.128784,-0.000599,0.002591,0.065813,290.197174,14.783349,0.658133,-1294.128784,294.500488,0.000000
52.600002,64.881065,-1294.039795,-0.000604,0.002593,0.065856,288.605408,14.702259,0.658557,-1294.039795,294.500488,0.000000
52.910004,65.670113,-1294.084351,-0.000595,0.002599,0.066004,292.115265,14.881061,0.660040,-1294.084351,294.500488,0.000000
53.220001,65.211357,-1293.995361,-0.000599,0.002603,0.066116,290.074615,14.777104,0.661161,-1293.995361,294.500488,0.000000
53.530003,65.290672,-1294.084351,-0.000578,0.002606,0.066204,290.427429,14.795078,0.662039,-1294.084351,294.500488,0.000000
53.840004,65.196831,-1294.084351,-0.000591,0.002609,0.066272,290.009979,14.773812,0.662720,-1294.084351,294.500488,0.000000
54.150002,65.326042,-1294.084351,-0.000569,0.002614,0.066395,290.584747,14.803092,0.663946,-1294.084351,294.500488,0.000000
54.460003,65.095177,-1294.128784,-0.000586,0.002615,0.066420,289.557800,14.750778,0.664204,-1294.128784,294.500488,0.000000
54.770004,65.561760,-1294.084351,-0.000582,0.002622,0.066602,291.633270,14.856507,0.666020,-1294.084351,294.500488,0.000000
55.080002,65.302956,-1294.128784,-0.000582,0.002623,0.066620,290.482056,14.797861,0.666202,-1294.128784,294.500488,0.000000
55.390003,65.397545,-1293.995361,-0.000569,0.002627,0.066723,290.902802,14.819296,0.667232,-1293.995361,294.500488,0.000000
55.700001,65.337212,-1294.084351,-0.000565,0.002630,0.066802,290.634430,14.805623,0.668019,-1294.084351,294.500488,0.000000
56.010002,65.251198,-1294.084351,-0.000565,0.002631,0.066837,290.251831,14.786133,0.668367,-1294.084351,294.500488,0.000000
56.320004,65.604576,-1294.039795,-0.000573,0.002639,0.067018,291.823730,14.866209,0.670184,-1294.039795,294.500488,0.000000
56.630001,65.470528,-1294.128784,-0.000560,0.002639,0.067018,291.227448,14.835834,0.670184,-1294.128784,294.500488,0.000000
56.940002,65.275032,-1294.039795,-0.000556,0.002641,0.067079,290.357849,14.791533,0.670789,-1294.039795,294.500488,0.000000
57.250004,65.248970,-1293.995361,-0.000548,0.002643,0.067123,290.241913,14.785628,0.671228,-1293.995361,294.500488,0.000000
57.560001,65.317482,-1294.084351,-0.000552,0.002646,0.067218,290.546661,14.801153,0.672182,-1294.084351,294.500488,0.000000
57.870003,65.238914,-1294.039795,-0.000543,0.002647,0.067227,290.197174,14.783349,0.672273,-1294.039795,294.500488,0.000000
58.180004,65.317482,-1294.084351,-0.000552,0.002652,0.067348,290.546661,14.801153,0.673484,-1294.084351,294.500488,0.000000
58.490002,65.280617,-1294.039795,-0.000548,0.002652,0.067348,290.382690,14.792799,0.673484,-1294.039795,294.500488,0.000000
58.800003,65.372597,-1294.039795,-0.000530,0.002656,0.067460,290.791840,14.813643,0.674605,-1294.039795,294.500488,0.000000
59.110004,65.306313,-1294.084351,-0.000539,0.002656,0.067460,290.496979,14.798622,0.674605,-1294.084351,294.500488,0.000000
59.420002,65.308540,-1294.039795,-0.000530,0.002659,0.067530,290.506897,14.799127,0.675301,-1294.039795,294.500488,0.000000
59.730003,65.255669,-1294.084351,-0.000526,0.002660,0.067574,290.271698,14.787147,0.675740,-1294.084351,294.500488,0.000000
60.040005,65.205772,-1294.084351,-0.000530,0.002661,0.067600,290.049774,14.775839,0.675997,-1294.084351,294.500488,0.000000
60.350002,65.247475,-1294.084351,-0.000526,0.002664,0.067660,290.235260,14.785289,0.676603,-1294.084351,294.500488,0.000000
60.660004,65.260506,-1294.084351,-0.000530,0.002666,0.067721,290.293213,14.788242,0.677209,-1294.084351,294.500488,0.000000
60.970001,65.329018,-1294.128784,-0.000522,0.002668,0.067765,290.597992,14.803767,0.677648,-1294.128784,294.500488,0.000000
61.280003,65.249702,-1294.128784,-0.000517,0.002668,0.067772,290.245178,14.785793,0.677723,-1294.128784,294.500488,0.000000
61.590004,65.281731,-1294.084351,-0.000535,0.002671,0.067842,290.387634,14.793052,0.678420,-1294.084351,294.500488,0.000000
61.900002,65.209114,-1294.084351,-0.000522,0.002672,0.067860,290.064636,14.776596,0.678601,-1294.084351,294.500488,0.000000
62.210003,65.440361,-1294.084351,-0.000513,0.002675,0.067956,291.093262,14.828998,0.679555,-1294.084351,294.500488,0.000000
62.520004,65.333870,-1294.039795,-0.000509,0.002676,0.067963,290.619568,14.804866,0.679631,-1294.039795,294.500488,0.000000
62.830002,65.301094,-1294.128784,-0.000517,0.002678,0.068016,290.473785,14.797440,0.680161,-1294.128784,294.500488,0.000000
63.140003,65.317116,-1294.084351,-0.000509,0.002679,0.068042,290.545044,14.801069,0.680418,-1294.084351,294.500488,0.000000
63.450005,65.309654,-1294.128784,-0.000513,0.002680,0.068077,290.511841,14.799379,0.680766,-1294.128784,294.500488,0.000000
63.760002,65.318977,-1294.128784,-0.000522,0.002682,0.068111,290.553314,14.801492,0.681115,-1294.128784,294.500488,0.000000
64.070000,65.258278,-1294.039795,-0.000500,0.002682,0.068121,290.283325,14.787737,0.681205,-1294.039795,294.500488,0.000000
64.380005,65.377800,-1294.128784,-0.000513,0.002685,0.068198,290.814972,14.814821,0.681978,-1294.128784,294.500488,0.000000
64.690002,65.320457,-1294.084351,-0.000496,0.002685,0.068207,290.559906,14.801826,0.682068,-1294.084351,294.500488,0.000000
65.000000,65.260139,-1294.128784,-0.000509,0.002686,0.068216,290.291595,14.788159,0.682159,-1294.128784,294.500488,0.000000
65.310005,65.249336,-1294.084351,-0.000500,0.002688,0.068267,290.243530,14.785711,0.682674,-1294.084351,294.500488,0.000000
65.620003,65.276146,-1294.039795,-0.000483,0.002689,0.068293,290.362793,14.791786,0.682931,-1294.039795,294.500488,0.000000
65.930000,65.193108,-1294.084351,-0.000504,0.002689,0.068302,289.993439,14.772969,0.683022,-1294.084351,294.500488,0.000000
66.240005,65.321205,-1294.039795,-0.000504,0.002692,0.068389,290.563232,14.801996,0.683885,-1294.039795,294.500488,0.000000
66.550003,65.301476,-1294.128784,-0.000496,0.002692,0.068389,290.475464,14.797526,0.683885,-1294.128784,294.500488,0.000000
66.860001,65.244499,-1294.084351,-0.000500,0.002692,0.068389,290.222015,14.784615,0.683885,-1294.084351,294.500488,0.000000
67.170006,65.145439,-1293.995361,-0.000483,0.002693,0.068407,289.781372,14.762168,0.684067,-1293.995361,294.500488,0.000000
67.480003,65.120872,-1294.128784,-0.000496,0.002694,0.068440,289.672119,14.756600,0.684400,-1294.128784,294.500488,0.000000
67.790001,65.074318,-1294.084351,-0.000492,0.002695,0.068449,289.465027,14.746051,0.684491,-1294.084351,294.500488,0.000000
68.100006,65.043785,-1294.084351,-0.000487,0.002696,0.068467,289.329193,14.739132,0.684672,-1294.084351,294.500488,0.000000
68.410004,65.030006,-1294.084351,-0.000487,0.002697,0.068493,289.267914,14.736011,0.684930,-1294.084351,294.500488,0.000000
68.720001,64.999855,-1294.084351,-0.000479,0.002697,0.068510,289.133789,14.729177,0.685096,-1294.084351,294.500488,0.000000
69.030006,64.926857,-1294.084351,-0.000492,0.002697,0.068510,288.809082,14.712636,0.685096,-1294.084351,294.500488,0.000000
69.340004,64.945107,-1294.084351,-0.000479,0.002699,0.068554,288.890259,14.716771,0.685535,-1294.084351,294.500488,0.000000
69.650002,64.938408,-1294.128784,-0.000483,0.002699,0.068563,288.860474,14.715253,0.685626,-1294.128784,294.500488,0.000000
69.960007,64.876595,-1294.084351,-0.000487,0.002699,0.068563,288.585510,14.701246,0.685626,-1294.084351,294.500488,0.000000
70.270004,65.272789,-1294.039795,-0.000479,0.002711,0.068849,290.347870,14.791025,0.688488,-1294.039795,294.500488,0.000000
70.580002,65.592293,-1294.039795,-0.000466,0.002708,0.068796,291.769104,14.863425,0.687958,-1294.039795,294.500488,0.000000
70.890007,65.559151,-1294.039795,-0.000470,0.002708,0.068796,291.621674,14.855916,0.687958,-1294.039795,294.500488,0.000000
71.200005,65.501808,-1294.128784,-0.000479,0.002708,0.068796,291.366608,14.842922,0.687958,-1294.128784,294.500488,0.000000
71.510002,65.410194,-1294.039795,-0.000479,0.002708,0.068796,290.959076,14.822162,0.687958,-1294.039795,294.500488,0.000000
71.820000,65.334236,-1294.128784,-0.000466,0.002708,0.068796,290.621185,14.804950,0.687958,-1294.128784,294.500488,0.000000
72.130005,65.272423,-1294.084351,-0.000479,0.002708,0.068796,290.346252,14.790943,0.687958,-1294.084351,294.500488,0.000000
72.440002,65.197945,-1294.039795,-0.000470,0.002708,0.068796,290.014954,14.774065,0.687958,-1294.039795,294.500488,0.000000
72.750000,65.110817,-1294.084351,-0.000479,0.002709,0.068805,289.627380,14.754322,0.688048,-1294.084351,294.500488,0.000000
73.060005,65.044167,-1294.084351,-0.000470,0.002709,0.068805,289.330902,14.739220,0.688048,-1294.084351,294.500488,0.000000
73.370003,64.969307,-1294.128784,-0.000466,0.002709,0.068805,288.997925,14.722256,0.688048,-1294.128784,294.500488,0.000000
73.680000,65.113792,-1294.039795,-0.000466,0.002713,0.068900,289.640625,14.754995,0.689002,-1294.039795,294.500488,0.000000
73.990005,65.097404,-1294.084351,-0.000461,0.002713,0.068900,289.567719,14.751283,0.689002,-1294.084351,294.500488,0.000000
74.300003,65.057198,-1294.084351,-0.000479,0.002713,0.068900,289.388855,14.742171,0.689002,-1294.084351,294.500488,0.000000
74.610001,65.016609,-1294.084351,-0.000479,0.002713,0.068900,289.208313,14.732974,0.689002,-1294.084351,294.500488,0.000000
74.920006,65.078423,-1294.128784,-0.000474,0.002715,0.068961,289.483276,14.746982,0.689608,-1294.128784,294.500488,0.000000
75.230003,65.048256,-1294.039795,-0.000466,0.002715,0.068961,289.349091,14.740146,0.689608,-1294.039795,294.500488,0.000000
75.540001,65.021080,-1294.039795,-0.000466,0.002715,0.068970,289.228210,14.733988,0.689699,-1294.039795,294.500488,0.000000
75.850006,65.000587,-1294.039795,-0.000457,0.002719,0.069074,289.137054,14.729344,0.690743,-1294.039795,294.500488,0.000000
76.160004,65.312263,-1293.995361,-0.000474,0.002720,0.069091,290.523468,14.799971,0.690910,-1293.995361,294.500488,0.000000
76.470001,65.295891,-1294.128784,-0.000461,0.002720,0.069091,290.450623,14.796261,0.690910,-1294.128784,294.500488,0.000000
76.780006,65.260887,-1294.039795,-0.000453,0.002720,0.069091,290.294922,14.788328,0.690910,-1294.039795,294.500488,0.000000
77.090004,65.228111,-1294.039795,-0.000461,0.002720,0.069091,290.149139,14.780901,0.690910,-1294.039795,294.500488,0.000000
77.400002,65.151024,-1294.084351,-0.000461,0.002720,0.069091,289.806213,14.763433,0.690910,-1294.084351,294.500488,0.000000
77.710007,65.138741,-1294.084351,-0.000466,0.002721,0.069117,289.751587,14.760650,0.691167,-1294.084351,294.500488,0.000000
78.020004,65.095543,-1294.039795,-0.000461,0.002721,0.069126,289.559448,14.750860,0.691258,-1294.039795,294.500488,0.000000
78.330002,65.183800,-1294.084351,-0.000474,0.002723,0.069170,289.952026,14.770861,0.691697,-1294.084351,294.500488,0.000000
78.640007,65.149910,-1294.084351,-0.000466,0.002723,0.069170,289.801270,14.763181,0.691697,-1294.084351,294.500488,0.000000
78.950005,65.135765,-1294.128784,-0.000457,0.002724,0.069177,289.738342,14.759975,0.691773,-1294.128784,294.500488,0.000000
79.260002,65.124214,-1294.084351,-0.000466,0.002724,0.069195,289.686981,14.757359,0.691954,-1294.084351,294.500488,0.000000
79.570007,65.089592,-1294.084351,-0.000466,0.002725,0.069205,289.532959,14.749513,0.692045,-1294.084351,294.500488,0.000000
79.880005,65.552071,-1294.128784,-0.000444,0.002730,0.069342,291.590179,14.854312,0.693423,-1294.128784,294.500488,0.000000
80.190002,65.558037,-1294.084351,-0.000444,0.002730,0.069342,291.616699,14.855663,0.693423,-1294.084351,294.500488,0.000000
80.500008,65.532341,-1294.084351,-0.000461,0.002730,0.069342,291.502411,14.849841,0.693423,-1294.084351,294.500488,0.000000
80.810005,65.489891,-1294.084351,-0.000444,0.002730,0.069342,291.313599,14.840221,0.693423,-1294.084351,294.500488,0.000000
81.120003,65.422859,-1294.173218,-0.000444,0.002730,0.069342,291.015411,14.825032,0.693423,-1294.173218,294.500488,0.000000
81.430000,65.388969,-1294.039795,-0.000435,0.002730,0.069342,290.864655,14.817352,0.693423,-1294.039795,294.500488,0.000000
81.740005,65.322319,-1294.084351,-0.000448,0.002730,0.069342,290.568176,14.802249,0.693423,-1294.084351,294.500488,0.000000
82.050003,65.299980,-1294.128784,-0.000453,0.002730,0.069351,290.468811,14.797187,0.693514,-1294.128784,294.500488,0.000000
82.360001,65.265724,-1294.084351,-0.000448,0.002730,0.069351,290.316437,14.789425,0.693514,-1294.084351,294.500488,0.000000
82.670006,65.237801,-1294.128784,-0.000461,0.002731,0.069368,290.192230,14.783097,0.693680,-1294.128784,294.500488,0.000000
82.980003,65.205025,-1294.039795,-0.000457,0.002731,0.069368,290.046448,14.775670,0.693680,-1294.039795,294.500488,0.000000
83.290001,65.775124,-1294.128784,-0.000444,0.002738,0.069551,292.582367,14.904856,0.695512,-1294.128784,294.500488,0.000000
83.600006,65.786293,-1294.084351,-0.000448,0.002738,0.069551,292.632050,14.907387,0.695512,-1294.084351,294.500488,0.000000
83.910004,65.761345,-1294.039795,-0.000431,0.002738,0.069551,292.521057,14.901734,0.695512,-1294.039795,294.500488,0.000000
84.220001,65.746086,-1294.128784,-0.000457,0.002738,0.069551,292.453186,14.898275,0.695512,-1294.128784,294.500488,0.000000
84.530006,65.687614,-1294.084351,-0.000453,0.002738,0.069551,292.193115,14.885026,0.695512,-1294.084351,294.500488,0.000000
84.840004,65.648521,-1294.084351,-0.000444,0.002738,0.069551,292.019196,14.876167,0.695512,-1294.084351,294.500488,0.000000
85.150002,65.607567,-1294.173218,-0.000444,0.002738,0.069551,291.837036,14.866887,0.695512,-1294.173218,294.500488,0.000000
85.460007,65.566963,-1294.128784,-0.000461,0.002738,0.069551,291.656433,14.857686,0.695512,-1294.128784,294.500488,0.000000
85.770004,65.541649,-1294.128784,-0.000444,0.002738,0.069551,291.543823,14.851950,0.695512,-1294.128784,294.500488,0.000000
86.080002,65.498833,-1294.084351,-0.000435,0.002738,0.069551,291.353363,14.842247,0.695512,-1294.084351,294.500488,0.000000
86.390007,65.453773,-1294.217773,-0.000444,0.002738,0.069551,291.152924,14.832037,0.695512,-1294.217773,294.500488,0.000000
86.700005,65.405357,-1294.128784,-0.000457,0.002738,0.069551,290.937561,14.821066,0.695512,-1294.128784,294.500488,0.000000
87.010002,65.352119,-1294.173218,-0.000435,0.002738,0.069551,290.700745,14.809002,0.695512,-1294.173218,294.500488,0.000000
87.320007,65.291039,-1294.173218,-0.000444,0.002738,0.069551,290.429047,14.795160,0.695512,-1294.173218,294.500488,0.000000
87.630005,65.263481,-1294.084351,-0.000444,0.002738,0.069551,290.306458,14.788917,0.695512,-1294.084351,294.500488,0.000000
87.940002,65.238914,-1294.217773,-0.000440,0.002738,0.069551,290.197174,14.783349,0.695512,-1294.217773,294.500488,0.000000
88.250008,65.178963,-1294.128784,-0.000448,0.002738,0.069551,289.930511,14.769765,0.695512,-1294.128784,294.500488,0.000000
88.560005,65.139854,-1294.128784,-0.000440,0.002738,0.069551,289.756531,14.760902,0.695512,-1294.128784,294.500488,0.000000
88.870003,65.698418,-1294.128784,-0.000448,0.002746,0.069759,292.241150,14.887474,0.697586,-1294.128784,294.500488,0.000000
89.180008,65.759117,-1294.173218,-0.000431,0.002746,0.069750,292.511169,14.901229,0.697496,-1294.173218,294.500488,0.000000
89.490005,65.752785,-1294.217773,-0.000440,0.002746,0.069750,292.483002,14.899794,0.697496,-1294.217773,294.500488,0.000000
89.800003,65.733421,-1294.173218,-0.000431,0.002746,0.069750,292.396851,14.895406,0.697496,-1294.173218,294.500488,0.000000
90.110001,65.661186,-1294.128784,-0.000444,0.002746,0.069750,292.075531,14.879038,0.697496,-1294.128784,294.500488,0.000000
90.420006,65.627296,-1294.217773,-0.000444,0.002746,0.069750,291.924805,14.871358,0.697496,-1294.217773,294.500488,0.000000
90.730003,65.594521,-1294.128784,-0.000427,0.002746,0.069750,291.778992,14.863931,0.697496,-1294.128784,294.500488,0.000000
91.040001,65.585594,-1294.217773,-0.000427,0.002746,0.069750,291.739288,14.861908,0.697496,-1294.217773,294.500488,0.000000
91.350006,65.537560,-1294.128784,-0.000440,0.002746,0.069750,291.525635,14.851024,0.697496,-1294.128784,294.500488,0.000000
91.660004,65.513725,-1294.217773,-0.000431,0.002746,0.069759,291.419617,14.845622,0.697586,-1294.217773,294.500488,0.000000
91.970001,65.486534,-1294.217773,-0.000444,0.002746,0.069759,291.298645,14.839460,0.697586,-1294.217773,294.500488,0.000000
92.280006,65.420998,-1294.084351,-0.000423,0.002746,0.069759,291.007141,14.824610,0.697586,-1294.084351,294.500488,0.000000
92.590004,65.383018,-1294.217773,-0.000435,0.002746,0.069759,290.838196,14.816004,0.697586,-1294.217773,294.500488,0.000000
92.900002,65.364021,-1294.128784,-0.000440,0.002747,0.069768,290.753693,14.811699,0.697677,-1294.128784,294.500488,0.000000
93.210007,65.326424,-1294.217773,-0.000444,0.002747,0.069768,290.586456,14.803180,0.697677,-1294.217773,294.500488,0.000000
93.520004,65.291420,-1294.173218,-0.000435,0.002747,0.069768,290.430756,14.795248,0.697677,-1294.173218,294.500488,0.000000
93.830002,65.265724,-1294.128784,-0.000440,0.002747,0.069768,290.316437,14.789425,0.697677,-1294.128784,294.500488,0.000000
94.140007,65.254921,-1294.262207,-0.000440,0.002748,0.069803,290.268372,14.786977,0.698025,-1294.262207,294.500488,0.000000
94.450005,65.277641,-1294.173218,-0.000423,0.002748,0.069812,290.369446,14.792125,0.698116,-1294.173218,294.500488,0.000000
94.760002,65.278755,-1294.217773,-0.000427,0.002749,0.069819,290.374420,14.792377,0.698192,-1294.217773,294.500488,0.000000
95.070007,65.271309,-1294.173218,-0.000431,0.002749,0.069819,290.341278,14.790690,0.698192,-1294.173218,294.500488,0.000000
95.380005,65.272423,-1294.217773,-0.000418,0.002751,0.069880,290.346252,14.790943,0.698798,-1294.217773,294.500488,0.000000
95.690002,65.366264,-1294.262207,-0.000431,0.002751,0.069880,290.763672,14.812207,0.698798,-1294.262207,294.500488,0.000000
96.000008,65.367744,-1294.173218,-0.000431,0.002751,0.069880,290.770264,14.812542,0.698798,-1294.173218,294.500488,0.000000
96.310005,65.354713,-1294.217773,-0.000410,0.002752,0.069889,290.712280,14.809589,0.698888,-1294.217773,294.500488,0.000000
96.620003,65.331627,-1294.173218,-0.000431,0.002752,0.069889,290.609589,14.804358,0.698888,-1294.173218,294.500488,0.000000
96.930008,65.346901,-1294.173218,-0.000423,0.002753,0.069924,290.677521,14.807819,0.699237,-1294.173218,294.500488,0.000000
97.240005,65.362541,-1294.262207,-0.000418,0.002753,0.069924,290.747101,14.811363,0.699237,-1294.262207,294.500488,0.000000
97.550003,65.346519,-1294.217773,-0.000418,0.002753,0.069924,290.675842,14.807734,0.699237,-1294.217773,294.500488,0.000000
97.860008,65.345406,-1294.262207,-0.000431,0.002753,0.069924,290.670868,14.807481,0.699237,-1294.262207,294.500488,0.000000
98.170006,65.317848,-1294.173218,-0.000427,0.002753,0.069924,290.548309,14.801236,0.699237,-1294.173218,294.500488,0.000000
98.480003,65.321953,-1294.128784,-0.000427,0.002755,0.069968,290.566559,14.802166,0.699676,-1294.128784,294.500488,0.000000
98.790001,65.473137,-1294.217773,-0.000418,0.002756,0.070002,291.239044,14.836425,0.700024,-1294.217773,294.500488,0.000000
99.100006,65.479469,-1294.173218,-0.000418,0.002756,0.070002,291.267212,14.837860,0.700024,-1294.173218,294.500488,0.000000
99.410004,65.491753,-1294.217773,-0.000423,0.002756,0.070002,291.321869,14.840643,0.700024,-1294.217773,294.500488,0.000000
99.720001,65.453773,-1294.217773,-0.000418,0.002756,0.070002,291.152924,14.832037,0.700024,-1294.217773,294.500488,0.000000
100.030006,65.433662,-1294.173218,-0.000427,0.002756,0.070002,291.063477,14.827479,0.700024,-1294.173218,294.500488,0.000000
100.340004,65.420631,-1294.217773,-0.000427,0.002756,0.070010,291.005493,14.824528,0.700100,-1294.217773,294.500488,0.000000
100.650002,65.408333,-1294.173218,-0.000418,0.002757,0.070019,290.950806,14.821740,0.700190,-1294.173218,294.500488,0.000000
100.960007,65.394936,-1294.173218,-0.000418,0.002757,0.070028,290.891205,14.818705,0.700281,-1294.173218,294.500488,0.000000
101.270004,65.374077,-1294.217773,-0.000418,0.002757,0.070028,290.798431,14.813977,0.700281,-1294.217773,294.500488,0.000000
101.580002,65.379295,-1294.128784,-0.000427,0.002757,0.070036,290.821625,14.815161,0.700357,-1294.128784,294.500488,0.000000
101.890007,65.350624,-1294.217773,-0.000418,0.002757,0.070036,290.694092,14.808662,0.700357,-1294.217773,294.500488,0.000000
102.200005,65.358818,-1294.173218,-0.000410,0.002758,0.070045,290.730530,14.810520,0.700448,-1294.173218,294.500488,0.000000
102.510002,65.355461,-1294.217773,-0.000431,0.002758,0.070054,290.715607,14.809759,0.700539,-1294.217773,294.500488,0.000000
102.820007,65.337959,-1294.173218,-0.000418,0.002758,0.070054,290.637756,14.805793,0.700539,-1294.173218,294.500488,0.000000
103.130005,65.320457,-1294.217773,-0.000423,0.002758,0.070054,290.559906,14.801826,0.700539,-1294.217773,294.500488,0.000000
103.440002,65.323433,-1294.173218,-0.000423,0.002759,0.070071,290.573151,14.802502,0.700705,-1294.173218,294.500488,0.000000
103.750008,65.340935,-1294.173218,-0.000418,0.002759,0.070089,290.651001,14.806468,0.700887,-1294.173218,294.500488,0.000000
104.060005,65.348763,-1294.306763,-0.000423,0.002759,0.070089,290.685822,14.808242,0.700887,-1294.306763,294.500488,0.000000
104.370003,65.335350,-1294.217773,-0.000410,0.002759,0.070089,290.626160,14.805202,0.700887,-1294.217773,294.500488,0.000000
104.680008,65.333870,-1294.173218,-0.000401,0.002759,0.070089,290.619568,14.804866,0.700887,-1294.173218,294.500488,0.000000
104.990005,65.313759,-1294.262207,-0.000427,0.002760,0.070105,290.530121,14.800309,0.701053,-1294.262207,294.500488,0.000000
105.300003,65.306313,-1294.128784,-0.000423,0.002760,0.070105,290.496979,14.798622,0.701053,-1294.128784,294.500488,0.000000
105.610008,65.326424,-1294.262207,-0.000410,0.002755,0.069968,290.586456,14.803180,0.699676,-1294.262207,0.070045,0.000000
105.920006,65.285835,-1294.128784,-0.000418,0.002747,0.069777,290.405914,14.793983,0.697768,-1294.128784,0.069525,0.000000
106.230003,65.208000,-1294.173218,-0.000405,0.002734,0.069447,290.059662,14.776343,0.694468,-1294.173218,0.069005,0.000000
106.540009,65.116402,-1294.262207,-0.000414,0.002719,0.069056,289.652222,14.755588,0.690562,-1294.262207,0.068493,0.000000
106.850006,65.052345,-1294.173218,-0.000410,0.002694,0.068440,289.367279,14.741073,0.684400,-1294.173218,0.067972,0.000000
107.160004,65.017342,-1294.217773,-0.000397,0.002675,0.067946,289.211578,14.733141,0.679464,-1294.217773,0.067460,0.000000
107.470009,64.980110,-1294.173218,-0.000397,0.002657,0.067495,289.045959,14.724703,0.674953,-1294.173218,0.066940,0.000000
107.780006,64.972298,-1294.217773,-0.000401,0.002638,0.067009,289.011200,14.722934,0.670093,-1294.217773,0.066420,0.000000
108.090004,64.903404,-1294.217773,-0.000392,0.002612,0.066351,288.704773,14.707321,0.663507,-1294.217773,0.065909,0.000000
108.400002,64.884789,-1294.173218,-0.000410,0.002597,0.065960,288.621948,14.703104,0.659601,-1294.173218,0.065388,0.000000
108.710007,64.877708,-1294.173218,-0.000397,0.002582,0.065579,288.590454,14.701499,0.655786,-1294.173218,0.064876,0.000000
109.020004,64.809196,-1294.217773,-0.000392,0.002560,0.065015,288.285706,14.685973,0.650154,-1294.217773,0.064355,0.000000
109.330002,64.637535,-1294.217773,-0.000392,0.002534,0.064373,287.522125,14.647076,0.643735,-1294.217773,0.063845,0.000000
109.640007,64.422676,-1294.217773,-0.000392,0.002518,0.063957,286.566376,14.598387,0.639572,-1294.217773,0.063324,0.000000
109.950005,63.692451,-1294.173218,-0.000388,0.002497,0.063429,283.318176,14.432916,0.634288,-1294.173218,0.062804,0.000000
110.260002,62.882538,-1294.306763,-0.000384,0.002479,0.062959,279.715485,14.249387,0.629595,-1294.306763,0.062292,0.000000
110.570007,62.046562,-1294.217773,-0.000384,0.002462,0.062543,275.996887,14.059952,0.625431,-1294.217773,0.061771,0.000000
110.880005,60.896675,-1294.262207,-0.000375,0.002441,0.061989,270.881927,13.799384,0.619890,-1294.262207,0.061261,0.000000
111.190002,59.734131,-1294.262207,-0.000384,0.002422,0.061520,265.710693,13.535948,0.615197,-1294.262207,0.060740,0.000000
111.500008,58.532112,-1294.128784,-0.000384,0.002406,0.061112,260.363831,13.263566,0.611124,-1294.128784,0.060219,0.000000
111.810005,57.022888,-1294.217773,-0.000388,0.002386,0.060610,253.650482,12.921572,0.606098,-1294.217773,0.059707,0.000000
112.120003,55.026970,-1294.173218,-0.000388,0.002361,0.059977,244.772186,12.469290,0.599770,-1294.173218,0.059187,0.000000
112.430008,53.765373,-1294.173218,-0.000375,0.002347,0.059612,239.160324,12.183408,0.596121,-1294.173218,0.058676,0.000000
112.740005,52.026016,-1294.173218,-0.000379,0.002329,0.059144,231.423279,11.789264,0.591443,-1294.173218,0.058156,0.000000
113.050003,50.036057,-1294.173218,-0.000375,0.002310,0.058676,222.571503,11.338332,0.586765,-1294.173218,0.057644,0.000000
113.360008,47.899757,-1294.306763,-0.000379,0.002289,0.058147,213.068756,10.854239,0.581466,-1294.306763,0.057123,0.000000
113.670006,45.951134,-1294.173218,-0.000379,0.002274,0.057748,204.400848,10.412676,0.577484,-1294.173218,0.056602,0.000000
113.980003,43.690086,-1294.217773,-0.000379,0.002251,0.057184,194.343216,9.900314,0.571837,-1294.217773,0.056092,0.000000
114.290009,41.139336,-1294.262207,-0.000384,0.002227,0.056560,182.996902,9.322307,0.565600,-1294.262207,0.055571,0.000000
114.600006,38.877548,-1294.173218,-0.000388,0.002207,0.056048,172.935974,8.809778,0.560482,-1294.173218,0.055060,0.000000
114.910004,37.209320,-1294.306763,-0.000392,0.002190,0.055632,165.515320,8.431752,0.556319,-1294.306763,0.054539,0.000000
115.220009,35.400703,-1294.173218,-0.000392,0.002174,0.055216,157.470200,8.021914,0.552156,-1294.173218,0.054027,0.000000
115.530006,32.424706,-1294.217773,-0.000388,0.002144,0.054469,144.232300,7.347543,0.544692,-1294.217773,0.053508,0.000000
115.840004,30.904678,-1294.173218,-0.000392,0.002132,0.054148,137.470871,7.003100,0.541482,-1294.173218,0.052987,0.000000
116.150009,28.238121,-1294.262207,-0.000397,0.002107,0.053508,125.609436,6.398849,0.535078,-1294.262207,0.052475,0.000000
116.460007,26.492439,-1294.306763,-0.000405,0.002088,0.053029,117.844254,6.003273,0.530294,-1294.306763,0.051954,0.000000
116.770004,25.219299,-1294.173218,-0.000418,0.002074,0.052675,112.181046,5.714775,0.526751,-1294.173218,0.051443,0.000000
117.080002,22.925858,-1294.128784,-0.000392,0.002057,0.052241,101.979309,5.195074,0.522406,-1294.128784,0.050923,0.000000
117.390007,19.661263,-1294.217773,-0.000410,0.002023,0.051382,87.457664,4.455306,0.513822,-1294.217773,0.050403,0.000000
117.700005,17.610237,-1294.217773,-0.000410,0.002006,0.050949,78.334244,3.990537,0.509492,-1294.217773,0.049891,0.000000
118.010002,14.974213,-1294.306763,-0.000418,0.001977,0.050212,66.608627,3.393205,0.502119,-1294.306763,0.049370,0.000000
118.320007,13.147354,-1294.128784,-0.000423,0.001964,0.049882,58.482353,2.979233,0.498819,-1294.128784,0.048858,0.000000
118.630005,11.516365,-1294.351196,-0.000431,0.001948,0.049491,51.227348,2.609646,0.494913,-1294.351196,0.048339,0.000000
118.940002,8.615211,-1294.217773,-0.000448,0.001919,0.048754,38.322376,1.952235,0.487540,-1294.217773,0.047827,0.000000
119.250008,6.340012,-1294.128784,-0.000440,0.001897,0.048182,28.201780,1.436667,0.481817,-1294.128784,0.047307,0.000000
119.560005,4.500870,-1294.173218,-0.000466,0.001878,0.047697,20.020868,1.019912,0.476972,-1294.173218,0.046786,0.000000
119.870003,2.644592,-1294.262207,-0.000461,0.001858,0.047193,11.763734,0.599273,0.471931,-1294.262207,0.046274,0.000000
120.180008,1.097755,-1294.262207,-0.000461,0.001841,0.046751,4.883060,0.248755,0.467510,-1294.262207,0.045755,0.000000
120.490005,-0.139267,-1294.217773,-0.000470,0.001823,0.046309,-0.619490,-0.031558,0.463089,-1294.217773,0.045243,0.000000
120.800003,-0.869865,-1294.217773,-0.000474,0.001806,0.045867,-3.869355,-0.197114,0.458669,-1294.217773,0.044722,0.000000
121.110008,-1.654449,-1294.262207,-0.000522,0.001782,0.045269,-7.359359,-0.374904,0.452689,-1294.262207,0.044202,0.000000
121.420006,-0.191025,-1294.173218,-0.000548,0.001762,0.044757,-0.849721,-0.043287,0.447571,-1294.173218,0.043690,0.000000
121.730003,-0.014893,-1294.306763,-0.000582,0.001742,0.044245,-0.066245,-0.003375,0.442454,-1294.306763,0.043169,0.000000
122.040009,0.035004,-1294.173218,-0.000617,0.001717,0.043604,0.155704,0.007932,0.436035,-1294.173218,0.042659,0.000000
122.350006,0.013405,-1294.217773,-0.000638,0.001700,0.043187,0.059628,0.003038,0.431872,-1294.217773,0.042138,0.000000
122.660004,0.031281,-1294.217773,-0.000668,0.001677,0.042606,0.139143,0.007088,0.426058,-1294.217773,0.041626,0.000000
122.970009,0.026070,-1294.173218,-0.000686,0.001662,0.042224,0.115964,0.005907,0.422243,-1294.173218,0.041105,0.000000
123.280006,0.017502,-1294.262207,-0.000733,0.001639,0.041635,0.077852,0.003966,0.416354,-1294.262207,0.040585,0.000000
123.590004,0.018616,-1294.217773,-0.000772,0.001620,0.041149,0.082807,0.004218,0.411494,-1294.217773,0.040074,0.000000
123.900009,0.028297,-1294.217773,-0.000802,0.001592,0.040447,0.125873,0.006412,0.404469,-1294.217773,0.039554,0.000000
124.210007,-0.003349,-1294.262207,-0.000845,0.001576,0.040021,-0.014898,-0.000759,0.400215,-1294.262207,0.039042,0.000000
124.520004,0.000748,-1294.217773,-0.000875,0.001565,0.039754,0.003326,0.000169,0.397535,-1294.217773,0.038521,0.000000
124.830009,-0.021973,-1294.262207,-0.000910,0.001537,0.039042,-0.097739,-0.004979,0.390419,-1294.262207,0.038009,0.000000
125.140007,-0.019737,-1294.217773,-0.000931,0.001520,0.038617,-0.087796,-0.004473,0.386165,-1294.217773,0.037490,0.000000
125.450005,-0.005585,-1294.173218,-0.000979,0.001502,0.038140,-0.024842,-0.001266,0.381396,-1294.173218,0.036969,0.000000
125.600006,0.038353,-1294.173218,-0.000987,0.001494,0.037949,0.170603,0.008691,0.379489,-1294.173218,0.037844,0.000000