File: Data/Sima compression/P1-17-3_10302024_173106.csv
Time (sec),S:Load (lbs),S:HL1 (DIM),S:LVDT (in),S:Position (in),Ch:Position (mm),Ch:Load (N),Ch:Stress (MPa),Ch:Strain (mm/mm),Ch:HL1 (DIM),Set Point (),Cycles ()
0.210000,0.007072,-1293.995361,-0.006752,-0.003484,-0.088500,0.031460,0.001603,-0.884999,-1293.995361,-0.088300,0.000000
0.530000,-0.001488,-1294.084351,-0.006752,-0.003408,-0.086574,-0.006618,-0.000337,-0.865742,-1294.084351,-0.085994,0.000000
0.850000,-0.004471,-1294.084351,-0.006635,-0.003215,-0.081666,-0.019887,-0.001013,-0.816659,-1294.084351,-0.080670,0.000000
1.170000,-0.048035,-1294.084351,-0.006420,-0.003008,-0.076411,-0.213669,-0.010885,-0.764110,-1294.084351,-0.075327,0.000000
1.490000,-0.030533,-1293.950806,-0.006217,-0.002799,-0.071103,-0.135817,-0.006919,-0.711030,-1293.950806,-0.070002,0.000000
1.810000,0.009682,-1294.039795,-0.006002,-0.002591,-0.065822,0.043066,0.002194,-0.658224,-1294.039795,-0.064678,0.000000
2.130000,0.002975,-1294.039795,-0.005795,-0.002383,-0.060540,0.013236,0.000674,-0.605402,-1294.039795,-0.059335,0.000000
2.450000,0.050270,-1294.084351,-0.005579,-0.002180,-0.055364,0.223612,0.011391,-0.553639,-1294.084351,-0.054010,0.000000
2.770000,0.007446,-1294.084351,-0.005342,-0.001958,-0.049726,0.033123,0.001687,-0.497259,-1294.084351,-0.048686,0.000000
3.090000,-0.025322,-1293.995361,-0.005126,-0.001750,-0.044445,-0.112638,-0.005738,-0.444453,-1293.995361,-0.043343,0.000000
3.410000,-0.015640,-1294.039795,-0.004932,-0.001547,-0.039302,-0.069571,-0.003544,-0.393023,-1294.039795,-0.038019,0.000000
3.730000,-0.031654,-1293.995361,-0.004704,-0.001333,-0.033857,-0.140806,-0.007173,-0.338566,-1293.995361,-0.032677,0.000000
4.050000,0.013405,-1294.039795,-0.004497,-0.001123,-0.028523,0.059628,0.003038,-0.285230,-1294.039795,-0.027353,0.000000
4.370000,0.053993,-1294.039795,-0.004273,-0.000920,-0.023363,0.240174,0.012235,-0.233634,-1294.039795,-0.022027,0.000000
4.690000,0.020111,-1293.950806,-0.004057,-0.000701,-0.017804,0.089459,0.004557,-0.178041,-1293.950806,-0.016685,0.000000
5.010000,0.025696,-1293.861938,-0.003854,-0.000493,-0.012522,0.114301,0.005823,-0.125219,-1293.861938,-0.011361,0.000000
5.330000,0.036865,-1293.995361,-0.003630,-0.000286,-0.007258,0.163985,0.008354,-0.072579,-1293.995361,-0.006036,0.000000
5.650000,0.019737,-1294.039795,-0.003419,-0.000073,-0.001856,0.087796,0.004473,-0.018561,-1294.039795,-0.000693,0.000000
5.970000,0.084900,-1293.995361,-0.003359,-0.000005,-0.000121,0.377654,0.019239,-0.001211,-1293.995361,0.000130,0.000000
6.290000,0.071869,-1294.039795,-0.003354,-0.000005,-0.000121,0.319689,0.016286,-0.001211,-1294.039795,0.000216,0.000000
6.610000,0.075218,-1294.039795,-0.003385,-0.000003,-0.000070,0.334587,0.017045,-0.000696,-1294.039795,0.000746,0.000000
6.930000,0.083038,-1293.995361,-0.003359,0.000014,0.000356,0.369373,0.018817,0.003558,-1293.995361,0.001284,0.000000
7.250000,0.226776,-1293.995361,-0.003350,0.000038,0.000972,1.008751,0.051388,0.009720,-1293.995361,0.001812,0.000000
7.570000,0.379448,-1294.084351,-0.003328,0.000058,0.001475,1.687869,0.085984,0.014746,-1294.084351,0.002350,0.000000
7.890000,0.672874,-1293.995361,-0.003303,0.000077,0.001951,2.993095,0.152476,0.019515,-1293.995361,0.002880,0.000000
8.210000,1.053070,-1293.995361,-0.003285,0.000096,0.002428,4.684289,0.238629,0.024284,-1293.995361,0.003417,0.000000
8.530001,1.525238,-1294.039795,-0.003281,0.000116,0.002940,6.784598,0.345624,0.029401,-1294.039795,0.003945,0.000000
8.850000,1.952347,-1294.039795,-0.003264,0.000129,0.003270,8.684472,0.442408,0.032701,-1294.039795,0.004483,0.000000
9.170000,3.176338,-1294.039795,-0.003242,0.000167,0.004250,14.129058,0.719769,0.042497,-1294.039795,0.005013,0.000000
9.490001,3.642548,-1294.084351,-0.003225,0.000183,0.004648,16.202862,0.825413,0.046479,-1294.084351,0.005550,0.000000
9.810000,4.493050,-1293.995361,-0.003212,0.000205,0.005203,19.986082,1.018140,0.052035,-1293.995361,0.006079,0.000000
10.130000,5.277634,-1293.950806,-0.003195,0.000224,0.005680,23.476088,1.195929,0.056804,-1293.950806,0.006618,0.000000
10.450001,5.992218,-1293.995361,-0.003199,0.000242,0.006148,26.654716,1.357856,0.061482,-1293.995361,0.007146,0.000000
10.770000,6.617805,-1293.995361,-0.003169,0.000255,0.006487,29.437469,1.499616,0.064873,-1293.995361,0.007683,0.000000
11.090000,8.059631,-1294.039795,-0.003173,0.000285,0.007232,35.851032,1.826339,0.072322,-1294.039795,0.008213,0.000000
11.410001,8.981255,-1293.906372,-0.003147,0.000307,0.007788,39.950615,2.035181,0.077878,-1293.906372,0.008751,0.000000
11.730000,9.952026,-1293.906372,-0.003143,0.000328,0.008334,44.268826,2.255162,0.083343,-1293.906372,0.009279,0.000000
12.050000,10.818161,-1293.995361,-0.003117,0.000350,0.008898,48.121582,2.451430,0.088975,-1293.995361,0.009817,0.000000
12.370001,11.850006,-1293.995361,-0.003104,0.000367,0.009332,52.711460,2.685250,0.093320,-1293.995361,0.010346,0.000000
12.690001,12.527351,-1294.039795,-0.003100,0.000382,0.009704,55.724442,2.838738,0.097045,-1294.039795,0.010884,0.000000
13.010000,14.023918,-1293.950806,-0.003083,0.000410,0.010424,62.381504,3.177865,0.104236,-1293.950806,0.011412,0.000000
13.330001,15.196518,-1293.950806,-0.003065,0.000434,0.011031,67.597488,3.443580,0.110307,-1293.950806,0.011950,0.000000
13.650001,15.953926,-1293.995361,-0.003053,0.000451,0.011465,70.966606,3.615211,0.114652,-1293.995361,0.012480,0.000000
13.970000,17.379738,-1294.039795,-0.003048,0.000477,0.012124,77.308937,3.938305,0.121238,-1294.039795,0.013017,0.000000
14.290001,17.928986,-1293.995361,-0.003027,0.000494,0.012540,79.752113,4.062766,0.125401,-1293.995361,0.013545,0.000000
14.610001,18.858803,-1294.039795,-0.003031,0.000511,0.012973,83.888145,4.273466,0.129731,-1294.039795,0.014084,0.000000
14.930000,20.223923,-1293.950806,-0.002992,0.000539,0.013685,89.960503,4.582806,0.136847,-1293.950806,0.014613,0.000000
15.250001,21.276245,-1293.950806,-0.002979,0.000559,0.014205,94.641464,4.821266,0.142055,-1293.950806,0.015150,0.000000
15.570001,22.120415,-1293.995361,-0.002988,0.000581,0.014752,98.396523,5.012558,0.147520,-1293.995361,0.015680,0.000000
15.890000,23.148537,-1293.995361,-0.002958,0.000601,0.015264,102.969833,5.245533,0.152637,-1293.995361,0.016218,0.000000
16.210001,24.149101,-1294.084351,-0.002945,0.000623,0.015818,107.420570,5.472265,0.158178,-1294.084351,0.016746,0.000000
16.530001,24.687180,-1293.995361,-0.002923,0.000638,0.016199,109.814056,5.594195,0.161994,-1293.995361,0.017283,0.000000
16.850000,26.072029,-1293.950806,-0.002932,0.000666,0.016920,115.974174,5.908006,0.169200,-1293.950806,0.017813,0.000000
17.170000,26.840607,-1293.950806,-0.002906,0.000684,0.017371,119.392982,6.082168,0.173712,-1293.950806,0.018351,0.000000
17.490002,27.668022,-1294.039795,-0.002884,0.000708,0.017978,123.073509,6.269663,0.179783,-1294.039795,0.018879,0.000000
17.810001,27.863144,-1293.995361,-0.002880,0.000719,0.018272,123.941452,6.313879,0.182720,-1293.995361,0.019417,0.000000
18.130001,28.731514,-1293.950806,-0.002863,0.000745,0.018932,127.804153,6.510654,0.189320,-1293.950806,0.019946,0.000000
18.450001,29.596535,-1293.950806,-0.002863,0.000763,0.019383,131.651962,6.706670,0.193832,-1293.950806,0.020484,0.000000
18.770000,30.879730,-1293.950806,-0.002846,0.000791,0.020086,137.359894,6.997447,0.200857,-1293.950806,0.021012,0.000000
19.090000,31.250618,-1294.084351,-0.002837,0.000806,0.020484,139.009689,7.081491,0.204839,-1294.084351,0.021551,0.000000
19.410002,32.173355,-1293.995361,-0.002811,0.000831,0.021117,143.114227,7.290586,0.211167,-1293.995361,0.022080,0.000000
19.730001,33.080452,-1293.995361,-0.002790,0.000855,0.021707,147.149200,7.496137,0.217071,-1293.995361,0.022617,0.000000
20.050001,33.618530,-1293.950806,-0.002764,0.000874,0.022192,149.542694,7.618068,0.221916,-1293.950806,0.023147,0.000000
20.370001,34.028137,-1293.950806,-0.002764,0.000891,0.022635,151.364716,7.710886,0.226352,-1293.950806,0.023684,0.000000
20.690001,33.877701,-1294.039795,-0.002746,0.000909,0.023077,150.695541,7.676797,0.230773,-1294.039795,0.024213,0.000000
21.010000,35.320648,-1293.995361,-0.002742,0.000932,0.023666,157.114090,8.003774,0.236662,-1293.995361,0.024750,0.000000
21.330002,36.224396,-1293.995361,-0.002716,0.000959,0.024369,161.134155,8.208566,0.243687,-1293.995361,0.025280,0.000000
21.650002,36.455261,-1293.995361,-0.002708,0.000973,0.024724,162.161102,8.260880,0.247244,-1293.995361,0.025818,0.000000
21.970001,37.563446,-1293.906372,-0.002682,0.001002,0.025445,167.090546,8.511998,0.254451,-1293.906372,0.026346,0.000000
22.290001,37.600685,-1293.995361,-0.002677,0.001017,0.025834,167.256195,8.520437,0.258342,-1293.995361,0.026883,0.000000
22.610001,37.366463,-1294.039795,-0.002665,0.001033,0.026234,166.214325,8.467361,0.262339,-1294.039795,0.027413,0.000000
22.930000,38.734558,-1293.950806,-0.002647,0.001057,0.026841,172.299927,8.777376,0.268410,-1293.950806,0.027951,0.000000
23.250002,39.632347,-1293.995361,-0.002626,0.001085,0.027560,176.293488,8.980819,0.275601,-1293.995361,0.028479,0.000000
23.570002,40.092598,-1293.995361,-0.002613,0.001104,0.028029,178.340790,9.085113,0.280294,-1293.995361,0.029018,0.000000
23.890001,40.836227,-1293.995361,-0.002604,0.001128,0.028644,181.648605,9.253621,0.286441,-1293.995361,0.029546,0.000000
24.210001,41.117371,-1293.995361,-0.002583,0.001145,0.029095,182.899200,9.317329,0.290952,-1293.995361,0.030084,0.000000
24.530001,41.722473,-1294.039795,-0.002587,0.001170,0.029728,185.590836,9.454448,0.297281,-1294.039795,0.030614,0.000000
24.850000,42.356247,-1293.995361,-0.002544,0.001190,0.030214,188.410004,9.598063,0.302141,-1293.995361,0.031151,0.000000
25.170002,42.447113,-1293.950806,-0.002539,0.001206,0.030639,188.814194,9.618653,0.306395,-1293.950806,0.031680,0.000000
25.490002,42.954277,-1293.906372,-0.002531,0.001228,0.031203,191.070160,9.733578,0.312027,-1293.906372,0.032217,0.000000
25.810001,43.922447,-1294.039795,-0.002522,0.001254,0.031845,195.376801,9.952969,0.318446,-1294.039795,0.032747,0.000000
26.130001,44.425896,-1293.995361,-0.002505,0.001272,0.032305,197.616257,10.067052,0.323048,-1293.995361,0.033284,0.000000
26.450001,44.649323,-1293.950806,-0.002479,0.001294,0.032868,198.610107,10.117681,0.328680,-1293.950806,0.033822,0.000000
26.770000,45.603714,-1293.861938,-0.002466,0.001314,0.033371,202.855453,10.333950,0.333707,-1293.861938,0.034350,0.000000
27.090002,45.986885,-1293.950806,-0.002449,0.001335,0.033917,204.559875,10.420777,0.339172,-1293.950806,0.034889,0.000000
27.410002,46.566292,-1293.950806,-0.002445,0.001356,0.034455,207.137207,10.552073,0.344547,-1293.950806,0.035418,0.000000
27.730001,47.103630,-1293.995361,-0.002440,0.001377,0.034966,209.527405,10.673836,0.349664,-1293.995361,0.035955,0.000000
28.050001,47.958221,-1294.039795,-0.002427,0.001400,0.035548,213.328827,10.867488,0.355477,-1294.039795,0.036485,0.000000
28.370001,47.785439,-1293.950806,-0.002406,0.001416,0.035973,212.560242,10.828336,0.359732,-1293.950806,0.037022,0.000000
28.690001,49.191895,-1293.950806,-0.002384,0.001441,0.036614,218.816483,11.147042,0.366136,-1293.950806,0.037551,0.000000
29.010002,49.426483,-1293.995361,-0.002367,0.001460,0.037083,219.859970,11.200201,0.370829,-1293.995361,0.038088,0.000000
29.330002,49.946693,-1293.950806,-0.002367,0.001481,0.037611,222.173996,11.318082,0.376113,-1293.950806,0.038618,0.000000
29.650002,50.716011,-1294.084351,-0.002341,0.001503,0.038176,225.596085,11.492413,0.381760,-1294.084351,0.039155,0.000000
29.970001,50.498917,-1294.039795,-0.002328,0.001513,0.038418,224.630402,11.443218,0.384182,-1294.039795,0.039684,0.000000
30.290001,50.788254,-1294.039795,-0.002320,0.001531,0.038878,225.917435,11.508782,0.388784,-1294.039795,0.040221,0.000000
30.610001,53.438431,-1293.995361,-0.002307,0.001570,0.039867,237.706009,12.109322,0.398671,-1293.995361,0.040751,0.000000
30.930002,53.347565,-1293.950806,-0.002294,0.001586,0.040291,237.301819,12.088731,0.402910,-1293.950806,0.041289,0.000000
31.250002,53.792923,-1294.084351,-0.002285,0.001606,0.040786,239.282867,12.189651,0.407860,-1294.084351,0.041817,0.000000
31.570002,54.574539,-1294.084351,-0.002259,0.001628,0.041340,242.759674,12.366768,0.413401,-1294.084351,0.042356,0.000000
31.890001,54.786789,-1293.995361,-0.002242,0.001642,0.041705,243.703812,12.414864,0.417050,-1293.995361,0.042884,0.000000
32.210003,55.057129,-1294.039795,-0.002238,0.001662,0.042217,244.906342,12.476124,0.422167,-1294.039795,0.043422,0.000000
32.530003,56.485924,-1293.995361,-0.002238,0.001689,0.042901,251.261932,12.799893,0.429010,-1293.995361,0.043952,0.000000
32.850002,57.450371,-1294.039795,-0.002220,0.001712,0.043473,255.552017,13.018440,0.434733,-1294.039795,0.044489,0.000000
33.170002,57.947487,-1294.039795,-0.002199,0.001729,0.043917,257.763306,13.131088,0.439169,-1294.039795,0.045018,0.000000
33.490002,59.101471,-1293.995361,-0.002190,0.001755,0.044575,262.896484,13.392585,0.445755,-1293.995361,0.045555,0.000000
33.810001,59.482033,-1293.995361,-0.002182,0.001771,0.044983,264.589294,13.478822,0.449827,-1293.995361,0.046085,0.000000
34.130001,59.913612,-1293.995361,-0.002182,0.001790,0.045460,266.509064,13.576619,0.454596,-1293.995361,0.046622,0.000000
34.450001,61.571045,-1294.084351,-0.002169,0.001816,0.046127,273.881683,13.952198,0.461273,-1294.084351,0.047151,0.000000
34.770000,62.382072,-1294.084351,-0.002147,0.001837,0.046657,277.489319,14.135980,0.466572,-1294.084351,0.047688,0.000000
35.090000,63.137611,-1294.039795,-0.002130,0.001858,0.047204,280.850128,14.307187,0.472037,-1294.039795,0.048218,0.000000
35.410000,64.216377,-1294.039795,-0.002117,0.001879,0.047732,285.648712,14.551640,0.477321,-1294.039795,0.048756,0.000000
35.730003,64.703804,-1293.995361,-0.002108,0.001894,0.048104,287.816895,14.662092,0.481045,-1293.995361,0.049284,0.000000
36.050003,65.183052,-1293.995361,-0.002108,0.001913,0.048600,289.948700,14.770691,0.485996,-1293.995361,0.049823,0.000000
36.370003,65.219170,-1294.039795,-0.002095,0.001917,0.048686,290.109344,14.778874,0.486859,-1294.039795,0.008566,0.000000
36.690002,65.996681,-1293.995361,-0.002082,0.001899,0.048227,293.567902,14.955062,0.482271,-1293.995361,294.500488,0.000000
37.010002,65.480949,-1293.950806,-0.002065,0.001944,0.049388,291.273804,14.838195,0.493883,-1293.950806,294.500488,0.000000
37.330002,65.402748,-1293.995361,-0.002074,0.001954,0.049640,290.925964,14.820475,0.496397,-1293.995361,294.500488,0.000000
37.650002,65.189384,-1294.039795,-0.002065,0.001964,0.049874,289.976868,14.772126,0.498743,-1294.039795,294.500488,0.000000
37.970001,65.184914,-1294.084351,-0.002061,0.001975,0.050160,289.956970,14.771112,0.501605,-1294.084351,294.500488,0.000000
38.290001,65.228111,-1294.084351,-0.002057,0.001983,0.050368,290.149139,14.780901,0.503679,-1294.084351,294.500488,0.000000
38.610001,65.126076,-1293.995361,-0.002035,0.001992,0.050586,289.695251,14.757779,0.505859,-1293.995361,294.500488,0.000000
38.930000,65.033363,-1293.995361,-0.002039,0.001998,0.050749,289.282837,14.736771,0.507494,-1293.995361,294.500488,0.000000
39.250000,66.105049,-1294.039795,-0.002013,0.001984,0.050395,294.049957,14.979618,0.503951,-1294.039795,294.500488,0.000000
39.570004,65.279503,-1294.084351,-0.002009,0.002011,0.051079,290.377716,14.792547,0.510794,-1294.084351,294.500488,0.000000
39.890003,65.160347,-1294.084351,-0.002018,0.002022,0.051356,289.847687,14.765546,0.513565,-1294.084351,294.500488,0.000000
40.210003,65.301094,-1294.084351,-0.002018,0.002030,0.051574,290.473785,14.797440,0.515745,-1294.084351,294.500488,0.000000
40.530003,65.091072,-1294.084351,-0.002005,0.002035,0.051696,289.539551,14.749847,0.516956,-1294.084351,294.500488,0.000000
40.850002,65.471642,-1294.039795,-0.002005,0.002047,0.051991,291.232422,14.836086,0.519908,-1294.039795,294.500488,0.000000
41.170002,65.090340,-1293.995361,-0.002001,0.002048,0.052017,289.536285,14.749682,0.520166,-1293.995361,294.500488,0.000000
41.490002,65.502556,-1294.084351,-0.001996,0.002057,0.052259,291.369934,14.843092,0.522588,-1294.084351,294.500488,0.000000
41.810001,65.563988,-1294.039795,-0.001988,0.002066,0.052475,291.643188,14.857012,0.524753,-1294.039795,294.500488,0.000000
42.130001,65.168159,-1293.995361,-0.001979,0.002066,0.052484,289.882446,14.767316,0.524844,-1293.995361,294.500488,0.000000
42.450001,65.511482,-1293.995361,-0.001970,0.002076,0.052719,291.409637,14.845114,0.527190,-1293.995361,294.500488,0.000000
42.770000,65.241142,-1294.039795,-0.001975,0.002078,0.052789,290.207092,14.783854,0.527887,-1294.039795,294.500488,0.000000
43.090000,65.099648,-1294.084351,-0.001966,0.002082,0.052884,289.577698,14.751791,0.528841,-1294.084351,294.500488,0.000000
43.410004,65.153633,-1294.128784,-0.001957,0.002088,0.053040,289.817841,14.764025,0.530400,-1294.128784,294.500488,0.000000
43.730003,65.111565,-1293.995361,-0.001953,0.002094,0.053178,289.630707,14.754492,0.531778,-1293.995361,294.500488,0.000000
44.050003,65.130180,-1293.995361,-0.001949,0.002098,0.053291,289.713501,14.758710,0.532913,-1293.995361,294.500488,0.000000
44.370003,65.279503,-1294.084351,-0.001957,0.002104,0.053438,290.377716,14.792547,0.534382,-1294.084351,294.500488,0.000000
44.690002,65.123482,-1294.128784,-0.001953,0.002107,0.053524,289.683716,14.757192,0.535245,-1294.128784,294.500488,0.000000
45.010002,65.113426,-1294.084351,-0.001957,0.002112,0.053655,289.638977,14.754913,0.536547,-1294.084351,294.500488,0.000000
45.330002,65.288429,-1293.995361,-0.001944,0.002117,0.053768,290.417450,14.794570,0.537682,-1293.995361,294.500488,0.000000
45.650002,64.927986,-1294.039795,-0.001944,0.002118,0.053803,288.814117,14.712892,0.538030,-1294.039795,294.500488,0.000000
45.970001,65.648888,-1294.039795,-0.001940,0.002123,0.053915,292.020844,14.876251,0.539151,-1294.039795,294.500488,0.000000
46.290001,65.209862,-1294.084351,-0.001940,0.002124,0.053941,290.067963,14.776766,0.539408,-1294.084351,294.500488,0.000000
46.610001,65.808266,-1294.084351,-0.001936,0.002137,0.054280,292.729797,14.912367,0.542799,-1294.084351,294.500488,0.000000
46.930004,65.432549,-1294.084351,-0.001923,0.002137,0.054280,291.058502,14.827228,0.542799,-1294.084351,294.500488,0.000000
47.250004,65.051979,-1294.039795,-0.001932,0.002137,0.054280,289.365662,14.740989,0.542799,-1294.039795,294.500488,0.000000
47.570004,64.697853,-1294.039795,-0.001940,0.002137,0.054280,287.790436,14.660743,0.542799,-1294.039795,294.500488,0.000000
47.890003,66.084572,-1294.039795,-0.001919,0.002144,0.054453,293.958862,14.974978,0.544525,-1294.039795,294.500488,0.000000
48.210003,65.626183,-1294.039795,-0.001901,0.002144,0.054453,291.919830,14.871106,0.544525,-1294.039795,294.500488,0.000000
48.530003,65.251945,-1294.128784,-0.001914,0.002144,0.054453,290.255157,14.786302,0.544525,-1294.128784,294.500488,0.000000
48.850002,65.022560,-1294.039795,-0.001901,0.002158,0.054817,289.234802,14.734323,0.548174,-1294.039795,294.500488,0.000000
49.170002,65.325294,-1293.995361,-0.001914,0.002160,0.054869,290.581421,14.802923,0.548689,-1293.995361,294.500488,0.000000
49.490002,65.085869,-1294.039795,-0.001910,0.002162,0.054904,289.516418,14.748669,0.549037,-1294.039795,294.500488,0.000000
49.810001,64.923515,-1294.084351,-0.001901,0.002163,0.054939,288.794220,14.711879,0.549385,-1294.084351,294.500488,0.000000
50.130001,64.854256,-1294.084351,-0.001901,0.002166,0.055017,288.486145,14.696184,0.550172,-1294.084351,294.500488,0.000000
50.450001,65.005058,-1294.039795,-0.001897,0.002170,0.055113,289.156952,14.730357,0.551126,-1294.039795,294.500488,0.000000
50.770004,65.598991,-1294.039795,-0.001897,0.002179,0.055355,291.798889,14.864944,0.553548,-1294.039795,294.500488,0.000000
51.090004,65.395683,-1294.084351,-0.001897,0.002179,0.055355,290.894531,14.818873,0.553548,-1294.084351,294.500488,0.000000
51.410004,65.171883,-1294.128784,-0.001906,0.002182,0.055415,289.899017,14.768160,0.554154,-1294.128784,294.500488,0.000000
51.730003,65.134651,-1294.084351,-0.001893,0.002182,0.055434,289.733398,14.759723,0.554336,-1294.084351,294.500488,0.000000
52.050003,65.449669,-1294.039795,-0.001888,0.002189,0.055590,291.134674,14.831106,0.555895,-1294.039795,294.500488,0.000000
52.370003,65.236305,-1294.039795,-0.001880,0.002189,0.055590,290.185577,14.782759,0.555895,-1294.039795,294.500488,0.000000
52.690002,65.515587,-1294.039795,-0.001897,0.002195,0.055755,291.427887,14.846044,0.557545,-1294.039795,294.500488,0.000000
53.010002,65.340202,-1294.084351,-0.001884,0.002195,0.055755,290.647736,14.806301,0.557545,-1294.084351,294.500488,0.000000
53.330002,65.129799,-1294.084351,-0.001888,0.002196,0.055789,289.711823,14.758624,0.557894,-1294.084351,294.500488,0.000000
53.650002,65.115654,-1294.084351,-0.001863,0.002198,0.055841,289.648895,14.755418,0.558408,-1294.084351,294.500488,0.000000
53.970001,65.173378,-1294.039795,-0.001880,0.002203,0.055945,289.905670,14.768499,0.559453,-1294.039795,294.500488,0.000000
54.290001,65.059807,-1294.039795,-0.001876,0.002203,0.055953,289.400482,14.742763,0.559529,-1294.039795,294.500488,0.000000
54.610004,65.205025,-1294.084351,-0.001876,0.002210,0.056144,290.046448,14.775670,0.561436,-1294.084351,294.500488,0.000000
54.930004,65.342796,-1294.084351,-0.001871,0.002210,0.056144,290.659271,14.806889,0.561436,-1294.084351,294.500488,0.000000
55.250004,65.172997,-1294.084351,-0.001871,0.002210,0.056144,289.903961,14.768412,0.561436,-1294.084351,294.500488,0.000000
55.570004,65.125710,-1294.039795,-0.001867,0.002213,0.056222,289.693634,14.757697,0.562223,-1294.039795,294.500488,0.000000
55.890003,65.224754,-1294.084351,-0.001858,0.002217,0.056300,290.134186,14.780140,0.562996,-1294.084351,294.500488,0.000000
56.210003,65.111183,-1294.039795,-0.001867,0.002218,0.056327,289.628998,14.754405,0.563268,-1294.039795,294.500488,0.000000
56.530003,65.106712,-1294.128784,-0.001871,0.002220,0.056387,289.609131,14.753392,0.563874,-1294.128784,294.500488,0.000000
56.850002,65.125710,-1294.084351,-0.001858,0.002222,0.056439,289.693634,14.757697,0.564388,-1294.084351,294.500488,0.000000
57.170002,65.135765,-1294.039795,-0.001854,0.002224,0.056499,289.738342,14.759975,0.564994,-1294.039795,294.500488,0.000000
57.490002,65.183434,-1293.995361,-0.001863,0.002227,0.056569,289.950378,14.770777,0.565690,-1293.995361,294.500488,0.000000
57.810001,65.242256,-1294.084351,-0.001854,0.002230,0.056630,290.212036,14.784107,0.566296,-1294.084351,294.500488,0.000000
58.130001,65.118263,-1294.039795,-0.001867,0.002231,0.056655,289.660492,14.756009,0.566553,-1294.039795,294.500488,0.000000
58.450005,65.180824,-1294.084351,-0.001850,0.002233,0.056716,289.938782,14.770185,0.567159,-1294.084351,294.500488,0.000000
58.770004,65.099266,-1294.084351,-0.001854,0.002234,0.056751,289.575989,14.751705,0.567507,-1294.084351,294.500488,0.000000
59.090004,65.279503,-1294.039795,-0.001841,0.002239,0.056864,290.377716,14.792547,0.568643,-1294.039795,294.500488,0.000000
59.410004,65.228111,-1293.995361,-0.001845,0.002239,0.056864,290.149139,14.780901,0.568643,-1293.995361,294.500488,0.000000
59.730003,65.073204,-1294.084351,-0.001841,0.002239,0.056864,289.460083,14.745798,0.568643,-1294.084351,294.500488,0.000000
60.050003,65.062401,-1294.084351,-0.001850,0.002241,0.056925,289.412018,14.743351,0.569248,-1294.084351,294.500488,0.000000
60.370003,65.459724,-1294.128784,-0.001837,0.002247,0.057081,291.179382,14.833385,0.570808,-1294.128784,294.500488,0.000000
60.690002,65.366631,-1294.039795,-0.001832,0.002247,0.057081,290.765289,14.812291,0.570808,-1294.039795,294.500488,0.000000
61.010002,65.232948,-1294.039795,-0.001837,0.002247,0.057081,290.170654,14.781998,0.570808,-1294.039795,294.500488,0.000000
61.330002,65.206886,-1294.039795,-0.001845,0.002249,0.057132,290.054718,14.776092,0.571322,-1294.039795,294.500488,0.000000
61.650002,65.186028,-1294.128784,-0.001841,0.002251,0.057176,289.961945,14.771365,0.571761,-1294.128784,294.500488,0.000000
61.970001,65.218803,-1294.039795,-0.001819,0.002253,0.057228,290.107727,14.778792,0.572276,-1294.039795,294.500488,0.000000
62.290005,65.117149,-1294.084351,-0.001850,0.002254,0.057262,289.655548,14.755756,0.572624,-1294.084351,294.500488,0.000000
62.610004,65.720757,-1294.084351,-0.001828,0.002261,0.057418,292.340515,14.892536,0.574184,-1294.084351,294.500488,0.000000
62.930004,65.573677,-1294.084351,-0.001824,0.002261,0.057418,291.686279,14.859208,0.574184,-1294.084351,294.500488,0.000000
63.250004,65.450798,-1294.084351,-0.001837,0.002261,0.057418,291.139679,14.831363,0.574184,-1294.084351,294.500488,0.000000
63.570004,65.283226,-1294.039795,-0.001828,0.002261,0.057418,290.394287,14.793390,0.574184,-1294.039795,294.500488,0.000000
63.890003,65.124596,-1294.173218,-0.001832,0.002261,0.057418,289.688660,14.757444,0.574184,-1294.173218,294.500488,0.000000
64.210007,64.970055,-1293.995361,-0.001832,0.002261,0.057427,289.001251,14.722425,0.574275,-1293.995361,294.500488,0.000000
64.530006,66.181007,-1294.039795,-0.001815,0.002268,0.057618,294.387817,14.996830,0.576182,-1294.039795,294.500488,0.000000
64.850006,65.975456,-1294.128784,-0.001815,0.002267,0.057583,293.473480,14.950252,0.575834,-1294.128784,294.500488,0.000000
65.170006,65.800453,-1294.128784,-0.001828,0.002267,0.057583,292.695038,14.910596,0.575834,-1294.128784,294.500488,0.000000
65.490005,65.600853,-1294.084351,-0.001811,0.002267,0.057583,291.807159,14.865366,0.575834,-1294.084351,294.500488,0.000000
65.810005,65.438881,-1294.039795,-0.001815,0.002267,0.057583,291.086670,14.828663,0.575834,-1294.039795,294.500488,0.000000
66.130005,65.269447,-1294.039795,-0.001819,0.002267,0.057583,290.333008,14.790268,0.575834,-1294.039795,294.500488,0.000000
66.450005,65.089958,-1294.084351,-0.001815,0.002267,0.057583,289.534607,14.749595,0.575834,-1294.084351,294.500488,0.000000
66.770004,64.963722,-1294.084351,-0.001832,0.002267,0.057592,288.973083,14.720990,0.575925,-1294.084351,294.500488,0.000000
67.090004,64.981606,-1294.039795,-0.001807,0.002287,0.058095,289.052612,14.725042,0.580951,-1294.039795,294.500488,0.000000
67.410004,66.062599,-1294.084351,-0.001802,0.002277,0.057827,293.861115,14.969999,0.578271,-1294.084351,294.500488,0.000000
67.730003,65.912163,-1294.039795,-0.001811,0.002277,0.057827,293.191956,14.935909,0.578271,-1294.039795,294.500488,0.000000
68.050003,65.754280,-1294.039795,-0.001819,0.002277,0.057827,292.489655,14.900133,0.578271,-1294.039795,294.500488,0.000000
68.370003,65.563988,-1294.084351,-0.001807,0.002277,0.057827,291.643188,14.857012,0.578271,-1294.084351,294.500488,0.000000
68.690002,65.400520,-1294.173218,-0.001811,0.002277,0.057827,290.916046,14.819970,0.578271,-1294.173218,294.500488,0.000000
69.010002,65.257896,-1294.084351,-0.001798,0.002277,0.057827,290.281616,14.787651,0.578271,-1294.084351,294.500488,0.000000
69.330002,65.422493,-1294.039795,-0.001815,0.002288,0.058113,291.013794,14.824948,0.581133,-1294.039795,294.500488,0.000000
69.650002,65.359184,-1293.995361,-0.001811,0.002288,0.058113,290.732178,14.810603,0.581133,-1293.995361,294.500488,0.000000
69.970001,65.276146,-1294.039795,-0.001811,0.002288,0.058113,290.362793,14.791786,0.581133,-1294.039795,294.500488,0.000000
70.290001,65.215446,-1293.995361,-0.001811,0.002289,0.058148,290.092804,14.778031,0.581481,-1293.995361,294.500488,0.000000
70.610001,65.111565,-1294.039795,-0.001802,0.002290,0.058156,289.630707,14.754492,0.581557,-1294.039795,294.500488,0.000000
70.930000,65.020699,-1294.039795,-0.001811,0.002290,0.058174,289.226501,14.733901,0.581738,-1294.039795,294.500488,0.000000
71.250000,64.983086,-1293.995361,-0.001794,0.002291,0.058200,289.059204,14.725378,0.581996,-1293.995361,294.500488,0.000000
71.570000,64.890373,-1293.995361,-0.001798,0.002291,0.058200,288.646790,14.704370,0.581996,-1293.995361,294.500488,0.000000
71.890007,64.939888,-1294.128784,-0.001802,0.002294,0.058260,288.867035,14.715590,0.582601,-1294.128784,294.500488,0.000000
72.210007,64.869148,-1294.039795,-0.001802,0.002294,0.058260,288.552368,14.699559,0.582601,-1294.039795,294.500488,0.000000
72.530006,64.818871,-1294.039795,-0.001811,0.002295,0.058286,288.328735,14.688166,0.582859,-1294.039795,294.500488,0.000000
72.850006,64.896706,-1293.995361,-0.001794,0.002297,0.058346,288.674957,14.705804,0.583464,-1293.995361,294.500488,0.000000
73.170006,64.925377,-1294.039795,-0.001807,0.002303,0.058486,288.802490,14.712301,0.584857,-1294.039795,294.500488,0.000000
73.490005,65.548729,-1294.039795,-0.001802,0.002306,0.058572,291.575317,14.853555,0.585720,-1294.039795,294.500488,0.000000
73.810005,65.488396,-1294.084351,-0.001789,0.002306,0.058572,291.306946,14.839883,0.585720,-1294.084351,294.500488,0.000000
74.130005,65.369606,-1294.084351,-0.001785,0.002306,0.058572,290.778534,14.812964,0.585720,-1294.084351,294.500488,0.000000
74.450005,65.298119,-1293.950806,-0.001789,0.002306,0.058572,290.460541,14.796765,0.585720,-1293.950806,294.500488,0.000000
74.770004,65.200188,-1293.995361,-0.001789,0.002306,0.058572,290.024933,14.774573,0.585720,-1293.995361,294.500488,0.000000
75.090004,65.078789,-1293.995361,-0.001807,0.002306,0.058581,289.484924,14.747064,0.585811,-1293.995361,294.500488,0.000000
75.410004,65.000221,-1294.084351,-0.001781,0.002307,0.058598,289.135437,14.729260,0.585977,-1294.084351,294.500488,0.000000
75.730003,65.184914,-1294.128784,-0.001794,0.002310,0.058686,289.956970,14.771112,0.586856,-1294.128784,294.500488,0.000000
76.050003,65.126076,-1294.039795,-0.001772,0.002311,0.058693,289.695251,14.757779,0.586931,-1294.039795,294.500488,0.000000
76.370003,65.110069,-1293.995361,-0.001776,0.002312,0.058720,289.624054,14.754152,0.587204,-1293.995361,294.500488,0.000000
76.690002,65.040062,-1293.995361,-0.001794,0.002312,0.058728,289.312653,14.738289,0.587279,-1293.995361,294.500488,0.000000
77.010002,64.969688,-1294.039795,-0.001781,0.002312,0.058728,288.999603,14.722342,0.587279,-1294.039795,294.500488,0.000000
77.330002,64.954414,-1294.039795,-0.001802,0.002314,0.058781,288.931671,14.718881,0.587809,-1294.039795,294.500488,0.000000
77.650002,64.967827,-1293.995361,-0.001798,0.002315,0.058807,288.991333,14.721920,0.588067,-1293.995361,294.500488,0.000000
77.970001,65.213966,-1293.995361,-0.001789,0.002320,0.058919,290.086212,14.777697,0.589187,-1293.995361,294.500488,0.000000
78.290001,65.232201,-1293.950806,-0.001776,0.002320,0.058919,290.167328,14.781828,0.589187,-1293.950806,294.500488,0.000000
78.610001,65.178963,-1294.084351,-0.001781,0.002320,0.058919,289.930511,14.769765,0.589187,-1294.084351,294.500488,0.000000
78.930000,65.164436,-1294.084351,-0.001785,0.002321,0.058946,289.865875,14.766473,0.589460,-1294.084351,294.500488,0.000000
79.250000,65.070595,-1293.995361,-0.001798,0.002321,0.058946,289.448456,14.745208,0.589460,-1293.995361,294.500488,0.000000
79.570007,65.101128,-1293.950806,-0.001785,0.002323,0.059007,289.584290,14.752126,0.590065,-1293.950806,294.500488,0.000000
79.890007,65.077675,-1294.039795,-0.001789,0.002323,0.059007,289.479950,14.746812,0.590065,-1294.039795,294.500488,0.000000
80.210007,64.994637,-1294.039795,-0.001798,0.002323,0.059007,289.110596,14.727995,0.590065,-1294.039795,294.500488,0.000000
80.530006,64.913078,-1293.995361,-0.001781,0.002323,0.059014,288.747803,14.709514,0.590141,-1293.995361,294.500488,0.000000
80.850006,65.286201,-1293.950806,-0.001785,0.002329,0.059153,290.407532,14.794065,0.591534,-1293.950806,294.500488,0.000000
81.170006,65.256035,-1294.039795,-0.001785,0.002329,0.059153,290.273346,14.787229,0.591534,-1294.039795,294.500488,0.000000
81.490005,65.185661,-1293.995361,-0.001763,0.002329,0.059153,289.960297,14.771281,0.591534,-1293.995361,294.500488,0.000000
81.810005,65.088844,-1294.039795,-0.001789,0.002329,0.059153,289.529633,14.749343,0.591534,-1294.039795,294.500488,0.000000
82.130005,65.024055,-1294.084351,-0.001772,0.002329,0.059162,289.241455,14.734662,0.591624,-1294.084351,294.500488,0.000000
82.450005,65.337959,-1293.995361,-0.001776,0.002336,0.059327,290.637756,14.805793,0.593275,-1293.995361,294.500488,0.000000
82.770004,65.394936,-1294.039795,-0.001785,0.002335,0.059318,290.891205,14.818705,0.593184,-1294.039795,294.500488,0.000000
83.090004,65.345406,-1293.995361,-0.001772,0.002335,0.059318,290.670868,14.807481,0.593184,-1293.995361,294.500488,0.000000
83.410004,65.283592,-1294.039795,-0.001763,0.002335,0.059318,290.395935,14.793474,0.593184,-1294.039795,294.500488,0.000000
83.730003,65.237053,-1294.039795,-0.001772,0.002335,0.059318,290.188904,14.782928,0.593184,-1294.039795,294.500488,0.000000
84.050003,65.138374,-1294.039795,-0.001763,0.002336,0.059327,289.749969,14.760567,0.593275,-1294.039795,294.500488,0.000000
84.370003,65.050865,-1294.039795,-0.001759,0.002336,0.059327,289.360687,14.740736,0.593275,-1294.039795,294.500488,0.000000
84.690002,65.070976,-1293.906372,-0.001763,0.002338,0.059388,289.450165,14.745294,0.593880,-1293.906372,294.500488,0.000000
85.010002,65.033363,-1293.906372,-0.001781,0.002338,0.059396,289.282837,14.736771,0.593956,-1293.906372,294.500488,0.000000
85.330002,65.083626,-1294.084351,-0.001768,0.002340,0.059449,289.506439,14.748160,0.594486,-1294.084351,294.500488,0.000000
85.650002,65.065392,-1294.084351,-0.001772,0.002341,0.059458,289.425323,14.744028,0.594577,-1294.084351,294.500488,0.000000
85.970001,65.077675,-1293.995361,-0.001768,0.002344,0.059526,289.479950,14.746812,0.595258,-1293.995361,294.500488,0.000000
86.290001,65.197212,-1294.039795,-0.001768,0.002344,0.059544,290.011688,14.773900,0.595440,-1294.039795,294.500488,0.000000
86.610001,65.154015,-1294.084351,-0.001759,0.002344,0.059544,289.819519,14.764111,0.595440,-1294.084351,294.500488,0.000000
86.930008,65.140984,-1294.084351,-0.001768,0.002346,0.059579,289.761566,14.761158,0.595788,-1294.084351,294.500488,0.000000
87.250008,65.130928,-1294.084351,-0.001759,0.002346,0.059595,289.716827,14.758880,0.595954,-1294.084351,294.500488,0.000000
87.570007,65.087730,-1294.084351,-0.001750,0.002347,0.059605,289.524689,14.749090,0.596045,-1294.084351,294.500488,0.000000
87.890007,65.100014,-1294.039795,-0.001755,0.002348,0.059630,289.579315,14.751874,0.596303,-1294.039795,294.500488,0.000000
88.210007,65.060921,-1294.039795,-0.001755,0.002348,0.059630,289.405426,14.743015,0.596303,-1294.039795,294.500488,0.000000
88.530006,65.156990,-1293.995361,-0.001759,0.002350,0.059691,289.832764,14.764785,0.596908,-1293.995361,294.500488,0.000000
88.850006,65.106346,-1294.084351,-0.001772,0.002350,0.059700,289.607483,14.753309,0.596999,-1294.084351,294.500488,0.000000
89.170006,65.089592,-1294.084351,-0.001755,0.002351,0.059717,289.532959,14.749513,0.597166,-1294.084351,294.500488,0.000000
89.490005,65.244118,-1294.039795,-0.001759,0.002355,0.059812,290.220337,14.784528,0.598119,-1294.039795,294.500488,0.000000
89.810005,65.305199,-1294.084351,-0.001759,0.002355,0.059812,290.492035,14.798369,0.598119,-1294.084351,294.500488,0.000000
90.130005,65.245979,-1294.039795,-0.001759,0.002355,0.059812,290.228607,14.784950,0.598119,-1294.039795,294.500488,0.000000
90.450005,65.205772,-1293.995361,-0.001746,0.002355,0.059821,290.049774,14.775839,0.598210,-1293.995361,294.500488,0.000000
90.770004,65.167046,-1294.084351,-0.001763,0.002357,0.059874,289.877502,14.767064,0.598740,-1294.084351,294.500488,0.000000
91.090004,65.225883,-1294.084351,-0.001746,0.002357,0.059874,290.139221,14.780396,0.598740,-1294.084351,294.500488,0.000000
91.410004,65.195717,-1294.039795,-0.001746,0.002358,0.059891,290.005035,14.773561,0.598907,-1294.039795,294.500488,0.000000
91.730003,65.179710,-1294.039795,-0.001746,0.002359,0.059907,289.933838,14.769934,0.599073,-1294.039795,294.500488,0.000000
92.050003,65.144325,-1294.084351,-0.001759,0.002359,0.059925,289.776428,14.761915,0.599255,-1294.084351,294.500488,0.000000
92.370003,65.114159,-1294.128784,-0.001738,0.002360,0.059935,289.642242,14.755079,0.599346,-1294.128784,294.500488,0.000000
92.690002,65.081398,-1293.995361,-0.001750,0.002360,0.059942,289.496521,14.747656,0.599421,-1293.995361,294.500488,0.000000
93.010002,65.063148,-1294.039795,-0.001738,0.002361,0.059969,289.415344,14.743520,0.599694,-1294.039795,294.500488,0.000000
93.330002,65.100395,-1293.995361,-0.001750,0.002362,0.060003,289.581024,14.751961,0.600027,-1293.995361,294.500488,0.000000
93.650002,65.170021,-1294.084351,-0.001750,0.002364,0.060038,289.890747,14.767738,0.600375,-1294.084351,294.500488,0.000000
93.970001,65.151405,-1294.173218,-0.001738,0.002364,0.060047,289.807922,14.763519,0.600466,-1294.173218,294.500488,0.000000
94.290001,65.107841,-1294.039795,-0.001742,0.002364,0.060047,289.614136,14.753648,0.600466,-1294.039795,294.500488,0.000000
94.610008,65.050117,-1294.084351,-0.001759,0.002364,0.060056,289.357361,14.740567,0.600557,-1294.084351,294.500488,0.000000
94.930008,65.037086,-1293.995361,-0.001750,0.002365,0.060072,289.299408,14.737615,0.600723,-1293.995361,294.500488,0.000000
95.250008,65.008034,-1294.084351,-0.001750,0.002365,0.060081,289.170166,14.731030,0.600814,-1294.084351,294.500488,0.000000
95.570007,64.959633,-1294.128784,-0.001746,0.002366,0.060091,288.954865,14.720063,0.600905,-1294.128784,294.500488,0.000000
95.890007,65.104851,-1294.084351,-0.001750,0.002369,0.060160,289.600830,14.752970,0.601601,-1294.084351,294.500488,0.000000
96.210007,65.087730,-1294.084351,-0.001738,0.002369,0.060168,289.524689,14.749090,0.601677,-1294.084351,294.500488,0.000000
96.530006,65.059425,-1293.995361,-0.001746,0.002369,0.060177,289.398773,14.742677,0.601768,-1293.995361,294.500488,0.000000
96.850006,65.058678,-1293.995361,-0.001742,0.002369,0.060168,289.395447,14.742507,0.601677,-1293.995361,0.060212,0.000000
97.170006,64.985695,-1294.084351,-0.001733,0.002359,0.059925,289.070801,14.725968,0.599255,-1294.084351,0.059751,0.000000
97.490005,64.903770,-1294.084351,-0.001725,0.002348,0.059648,288.706390,14.707405,0.596484,-1294.084351,0.059223,0.000000
97.810005,64.711632,-1294.039795,-0.001712,0.002330,0.059188,287.851715,14.663866,0.591882,-1294.039795,0.058686,0.000000
98.130005,64.582787,-1294.084351,-0.001712,0.002309,0.058642,287.278595,14.634668,0.586416,-1294.084351,0.058156,0.000000
98.450005,64.472191,-1294.039795,-0.001725,0.002291,0.058183,286.786621,14.609607,0.581829,-1294.039795,0.057618,0.000000
98.770004,64.369041,-1294.084351,-0.001742,0.002266,0.057567,286.327789,14.586234,0.575667,-1294.084351,0.057090,0.000000
99.090004,64.316551,-1294.084351,-0.001725,0.002245,0.057029,286.094299,14.574339,0.570293,-1294.084351,0.056552,0.000000
99.410004,64.210045,-1294.084351,-0.001720,0.002223,0.056474,285.620544,14.550204,0.564737,-1294.084351,0.056022,0.000000
99.730003,64.149727,-1294.128784,-0.001729,0.002204,0.055971,285.352234,14.536535,0.559710,-1294.128784,0.055485,0.000000
100.050003,64.011940,-1294.039795,-0.001720,0.002185,0.055494,284.739319,14.505313,0.554941,-1294.039795,0.054957,0.000000
100.370003,63.892036,-1294.084351,-0.001720,0.002168,0.055060,284.205963,14.478143,0.550596,-1294.084351,0.054418,0.000000
100.690002,63.637703,-1294.128784,-0.001716,0.002142,0.054410,283.074646,14.420510,0.544101,-1294.128784,0.053889,0.000000
101.010002,63.347633,-1294.084351,-0.001725,0.002127,0.054029,281.784332,14.354778,0.540286,-1294.084351,0.053352,0.000000
101.330002,62.531387,-1294.039795,-0.001716,0.002106,0.053491,278.153503,14.169815,0.534912,-1294.039795,0.052822,0.000000
101.650002,61.654083,-1294.084351,-0.001707,0.002089,0.053066,274.251068,13.971015,0.530657,-1294.084351,0.052285,0.000000
101.970001,60.403656,-1293.995361,-0.001703,0.002064,0.052424,268.688873,13.687664,0.524238,-1293.995361,0.051756,0.000000
102.290009,59.322281,-1294.128784,-0.001712,0.002047,0.051982,263.878693,13.442620,0.519817,-1294.128784,0.051219,0.000000
102.610008,57.999245,-1294.039795,-0.001703,0.002027,0.051487,257.993530,13.142817,0.514867,-1294.039795,0.050689,0.000000
102.930008,56.719032,-1294.084351,-0.001690,0.002008,0.051010,252.298859,12.852716,0.510098,-1294.084351,0.050151,0.000000
103.250008,55.143890,-1294.039795,-0.001703,0.001988,0.050507,245.292282,12.495784,0.505072,-1294.039795,0.049623,0.000000
103.570007,53.522957,-1294.084351,-0.001707,0.001969,0.050021,238.082001,12.128476,0.500212,-1294.084351,0.049086,0.000000
103.890007,51.731468,-1294.084351,-0.001703,0.001949,0.049509,230.113068,11.722518,0.495095,-1294.084351,0.048556,0.000000
104.210007,49.697571,-1294.084351,-0.001703,0.001930,0.049016,221.065842,11.261631,0.490159,-1294.084351,0.048018,0.000000
104.530006,47.834969,-1294.084351,-0.001712,0.001910,0.048521,212.780563,10.839560,0.485208,-1294.084351,0.047490,0.000000
104.850006,45.297623,-1294.039795,-0.001703,0.001887,0.047941,201.493896,10.264587,0.479410,-1294.039795,0.046951,0.000000
105.170006,43.142326,-1294.039795,-0.001725,0.001866,0.047394,191.906647,9.776191,0.473945,-1294.039795,0.046422,0.000000
105.490005,41.045876,-1294.173218,-0.001716,0.001846,0.046890,182.581177,9.301128,0.468903,-1294.173218,0.045885,0.000000
105.810005,39.217896,-1294.128784,-0.001720,0.001829,0.046457,174.449905,8.886903,0.464573,-1294.128784,0.045357,0.000000
106.130005,36.839554,-1294.084351,-0.001725,0.001805,0.045850,163.870514,8.347962,0.458502,-1294.084351,0.044818,0.000000
106.450005,35.082329,-1294.039795,-0.001720,0.001787,0.045399,156.053986,7.949769,0.453991,-1294.039795,0.044289,0.000000
106.770004,32.638443,-1294.084351,-0.001750,0.001763,0.044775,145.183044,7.395977,0.447753,-1294.084351,0.043752,0.000000
107.090004,31.008202,-1294.084351,-0.001742,0.001746,0.044341,137.931366,7.026559,0.443408,-1294.084351,0.043222,0.000000
107.410004,28.925148,-1294.084351,-0.001746,0.001724,0.043787,128.665482,6.554532,0.437867,-1294.084351,0.042685,0.000000
107.730003,26.540100,-1294.084351,-0.001742,0.001701,0.043196,118.056259,6.014072,0.431962,-1294.084351,0.042156,0.000000
108.050003,23.978554,-1294.039795,-0.001750,0.001678,0.042624,106.661934,5.433618,0.426240,-1294.039795,0.041619,0.000000
108.370003,22.214249,-1294.084351,-0.001763,0.001661,0.042182,98.813911,5.033821,0.421819,-1294.084351,0.041089,0.000000
108.690002,19.570778,-1294.128784,-0.001759,0.001634,0.041505,87.055168,4.434802,0.415052,-1294.128784,0.040551,0.000000
109.010002,18.005325,-1294.084351,-0.001768,0.001618,0.041089,80.091690,4.080065,0.410888,-1294.084351,0.040023,0.000000
109.330002,16.107346,-1294.084351,-0.001759,0.001599,0.040621,71.649048,3.649976,0.406210,-1294.084351,0.039486,0.000000
109.650002,14.142334,-1294.039795,-0.001763,0.001581,0.040170,62.908245,3.204699,0.401698,-1294.039795,0.038956,0.000000
109.970009,11.259430,-1294.084351,-0.001781,0.001553,0.039442,50.084446,2.551423,0.394416,-1294.084351,0.038418,0.000000
110.290009,9.882019,-1294.128784,-0.001772,0.001536,0.039025,43.957417,2.239298,0.390253,-1294.128784,0.037890,0.000000
110.610008,7.094437,-1294.084351,-0.001789,0.001508,0.038314,31.557631,1.607622,0.383137,-1294.084351,0.037351,0.000000
110.930008,5.840286,-1294.084351,-0.001785,0.001493,0.037916,25.978891,1.323428,0.379156,-1294.084351,0.036822,0.000000
111.250008,3.682022,-1294.039795,-0.001781,0.001469,0.037308,16.378452,0.834358,0.373085,-1294.039795,0.036285,0.000000
111.570007,1.358040,-1294.084351,-0.001807,0.001446,0.036727,6.040863,0.307736,0.367271,-1294.084351,0.035755,0.000000
111.890007,-0.420410,-1294.084351,-0.001811,0.001425,0.036190,-1.870078,-0.095266,0.361897,-1294.084351,0.035218,0.000000
112.210007,-1.866329,-1294.128784,-0.001815,0.001406,0.035720,-8.301847,-0.422916,0.357203,-1294.128784,0.034689,0.000000
112.530006,-3.464924,-1294.084351,-0.001819,0.001386,0.035192,-15.412751,-0.785163,0.351920,-1294.084351,0.034152,0.000000
112.850006,-0.072243,-1294.039795,-0.001871,0.001368,0.034741,-0.321352,-0.016370,0.347408,-1294.039795,0.033622,0.000000
113.170006,-0.038353,-1294.084351,-0.001876,0.001338,0.033996,-0.170603,-0.008691,0.339959,-1294.084351,0.033085,0.000000
113.490005,-0.035004,-1294.128784,-0.001884,0.001320,0.033527,-0.155704,-0.007932,0.335266,-1294.128784,0.032556,0.000000
113.810005,-0.054741,-1294.128784,-0.001906,0.001296,0.032929,-0.243500,-0.012404,0.329286,-1294.128784,0.032019,0.000000
114.130005,-0.051384,-1294.084351,-0.001914,0.001279,0.032487,-0.228567,-0.011644,0.324865,-1294.084351,0.031489,0.000000
114.450005,-0.010429,-1294.084351,-0.001919,0.001256,0.031905,-0.046392,-0.002363,0.319052,-1294.084351,0.030951,0.000000
114.770004,-0.019737,-1294.084351,-0.001940,0.001236,0.031403,-0.087796,-0.004473,0.314025,-1294.084351,0.030414,0.000000
115.090004,-0.020111,-1294.128784,-0.001953,0.001223,0.031072,-0.089459,-0.004557,0.310725,-1294.128784,0.029884,0.000000
115.410004,-0.005959,-1294.084351,-0.001962,0.001198,0.030423,-0.026505,-0.001350,0.304230,-1294.084351,0.029347,0.000000
115.730003,-0.029045,-1294.039795,-0.001975,0.001172,0.029772,-0.129199,-0.006582,0.297720,-1294.039795,0.028818,0.000000
116.050003,-0.029419,-1294.039795,-0.001966,0.001151,0.029235,-0.130862,-0.006666,0.292345,-1294.039795,0.028281,0.000000
116.370003,-0.007072,-1293.995361,-0.001988,0.001130,0.028714,-0.031460,-0.001603,0.287137,-1293.995361,0.027751,0.000000
116.690002,-0.027184,-1294.039795,-0.002001,0.001114,0.028297,-0.120918,-0.006160,0.282974,-1294.039795,0.027213,0.000000
117.010002,-0.007072,-1294.084351,-0.001996,0.001098,0.027899,-0.031460,-0.001603,0.278992,-1294.084351,0.026685,0.000000
117.330002,-0.037239,-1294.039795,-0.002013,0.001071,0.027204,-0.165648,-0.008438,0.272043,-1294.039795,0.026148,0.000000
117.650009,-0.014893,-1293.995361,-0.002031,0.001048,0.026615,-0.066245,-0.003375,0.266154,-1293.995361,0.025618,0.000000
117.970009,-0.022713,-1294.084351,-0.002048,0.001022,0.025948,-0.101031,-0.005147,0.259477,-1294.084351,0.025080,0.000000
118.290009,-0.013031,-1294.084351,-0.002044,0.001008,0.025601,-0.057965,-0.002953,0.256010,-1294.084351,0.024552,0.000000
118.610008,0.005211,-1294.084351,-0.002061,0.000990,0.025150,0.023179,0.001181,0.251499,-1294.084351,0.024013,0.000000
118.930008,0.008568,-1294.039795,-0.002065,0.000971,0.024655,0.038112,0.001941,0.246548,-1294.039795,0.023485,0.000000
119.250008,0.002975,-1294.039795,-0.002087,0.000948,0.024075,0.013236,0.000674,0.240750,-1294.039795,0.022947,0.000000
119.570007,-0.044685,-1293.995361,-0.002113,0.000923,0.023450,-0.198770,-0.010126,0.234497,-1293.995361,0.022417,0.000000
119.890007,-0.053619,-1294.084351,-0.002126,0.000902,0.022921,-0.238511,-0.012150,0.229213,-1294.084351,0.021880,0.000000
120.210007,-0.062187,-1294.039795,-0.002143,0.000881,0.022384,-0.276622,-0.014092,0.223839,-1294.039795,0.021351,0.000000
120.530006,-0.048782,-1294.039795,-0.002156,0.000866,0.021984,-0.216995,-0.011054,0.219842,-1294.039795,0.020814,0.000000
120.850006,-0.038727,-1293.995361,-0.002186,0.000846,0.021482,-0.172265,-0.008776,0.214815,-1293.995361,0.020284,0.000000
121.170006,-0.033516,-1294.039795,-0.002203,0.000821,0.020849,-0.149086,-0.007595,0.208487,-1294.039795,0.019747,0.000000
121.490005,-0.051384,-1294.039795,-0.002238,0.000792,0.020111,-0.228567,-0.011644,0.201114,-1294.039795,0.019218,0.000000
121.810005,-0.052132,-1294.128784,-0.002251,0.000773,0.019642,-0.231893,-0.011813,0.196421,-1294.128784,0.018681,0.000000
122.130005,-0.035378,-1294.084351,-0.002272,0.000751,0.019070,-0.157367,-0.008017,0.190698,-1294.084351,0.018151,0.000000
122.450005,-0.040215,-1294.039795,-0.002281,0.000735,0.018663,-0.178883,-0.009113,0.186626,-1294.039795,0.017613,0.000000
122.770004,-0.032768,-1293.995361,-0.002307,0.000717,0.018220,-0.145760,-0.007425,0.182205,-1293.995361,0.017085,0.000000
123.090004,-0.059952,-1294.128784,-0.002350,0.000691,0.017544,-0.266679,-0.013585,0.175437,-1294.128784,0.016546,0.000000
123.410004,-0.083038,-1294.084351,-0.002358,0.000671,0.017041,-0.369373,-0.018817,0.170411,-1294.084351,0.016018,0.000000
123.730003,-0.071121,-1294.039795,-0.002376,0.000649,0.016478,-0.316363,-0.016116,0.164779,-1294.039795,0.015480,0.000000
124.050003,-0.048035,-1294.039795,-0.002393,0.000626,0.015897,-0.213669,-0.010885,0.158966,-1294.039795,0.014950,0.000000
124.370003,-0.045799,-1294.039795,-0.002423,0.000609,0.015462,-0.203725,-0.010378,0.154621,-1294.039795,0.014413,0.000000
124.690002,-0.053993,-1294.084351,-0.002432,0.000588,0.014943,-0.240174,-0.012235,0.149428,-1294.084351,0.013885,0.000000
125.010002,-0.048409,-1294.084351,-0.002466,0.000570,0.014483,-0.215332,-0.010970,0.144825,-1294.084351,0.013347,0.000000
125.330009,-0.071495,-1294.173218,-0.002492,0.000541,0.013736,-0.318026,-0.016201,0.137361,-1294.173218,0.012817,0.000000
125.650009,-0.063675,-1293.995361,-0.002505,0.000524,0.013303,-0.283240,-0.014429,0.133031,-1293.995361,0.012280,0.000000
125.970009,-0.032394,-1293.995361,-0.002522,0.000495,0.012584,-0.144098,-0.007341,0.125840,-1293.995361,0.011751,0.000000
126.290009,-0.032394,-1294.084351,-0.002552,0.000484,0.012289,-0.144098,-0.007341,0.122888,-1294.084351,0.011214,0.000000
126.610008,-0.043938,-1294.084351,-0.002565,0.000463,0.011759,-0.195445,-0.009956,0.117589,-1294.084351,0.010684,0.000000
126.930008,-0.040962,-1294.039795,-0.002587,0.000438,0.011126,-0.182209,-0.009282,0.111261,-1294.039795,0.010147,0.000000
127.250008,0.016388,-1294.084351,-0.002604,0.000430,0.010919,0.072897,0.003714,0.109187,-1294.084351,0.010788,0.000000
127.300003,-0.000748,-1294.039795,-0.002617,0.000430,0.010919,-0.003326,-0.000169,0.109187,-1294.039795,0.010788,0.000000