File: Data/Sima compression/P1-11-1_10302024_162707.csv
Time (sec),S:Load (lbs),S:HL1 (DIM),S:LVDT (in),S:Position (in),Ch:Position (mm),Ch:Load (N),Ch:Stress (MPa),Ch:Strain (mm/mm),Ch:HL1 (DIM),Set Point (),Cycles ()
0.210000,0.047295,-1289.814087,-0.005700,-0.005684,-0.144385,0.210377,0.010717,-1.443847,-1289.814087,-0.144168,0.000000
0.620000,0.088997,-1289.903076,-0.005708,0.000032,0.000825,0.395878,0.020167,0.008251,-1289.903076,0.000851,0.000000
1.030000,0.076706,-1289.858643,-0.005713,0.000032,0.000825,0.341205,0.017382,0.008251,-1289.858643,0.000851,0.000000
1.440000,0.113205,-1289.814087,-0.005717,0.000033,0.000833,0.503561,0.025653,0.008327,-1289.814087,0.001475,0.000000
1.850000,0.068520,-1289.858643,-0.005713,0.000056,0.001432,0.304790,0.015527,0.014322,-1289.858643,0.002160,0.000000
2.260000,0.090111,-1289.858643,-0.005704,0.000076,0.001935,0.400833,0.020419,0.019348,-1289.858643,0.002845,0.000000
2.670000,0.103149,-1289.947632,-0.005708,0.000102,0.002602,0.458832,0.023374,0.026025,-1289.947632,0.003531,0.000000
3.080000,0.137032,-1289.903076,-0.005713,0.000120,0.003045,0.609547,0.031052,0.030446,-1289.903076,0.004215,0.000000
3.490000,0.119156,-1289.858643,-0.005683,0.000161,0.004085,0.530032,0.027001,0.040847,-1289.858643,0.004892,0.000000
3.900000,0.090111,-1289.903076,-0.005661,0.000183,0.004658,0.400833,0.020419,0.046584,-1289.903076,0.005577,0.000000
4.310000,0.100166,-1289.858643,-0.005639,0.000212,0.005394,0.445562,0.022698,0.053942,-1289.858643,0.006262,0.000000
4.720000,0.106499,-1289.947632,-0.005627,0.000233,0.005906,0.473730,0.024133,0.059060,-1289.947632,0.006948,0.000000
5.130000,0.140381,-1289.858643,-0.005601,0.000257,0.006531,0.624445,0.031811,0.065312,-1289.858643,0.007632,0.000000
5.540000,0.107613,-1289.903076,-0.005562,0.000292,0.007424,0.478685,0.024385,0.074244,-1289.903076,0.008309,0.000000
5.950000,0.072983,-1289.992065,-0.005562,0.000315,0.007997,0.324644,0.016538,0.079967,-1289.992065,0.008994,0.000000
6.360000,0.114319,-1289.947632,-0.005527,0.000346,0.008795,0.508516,0.025905,0.087946,-1289.947632,0.009679,0.000000
6.770000,0.125488,-1289.903076,-0.005493,0.000364,0.009253,0.558200,0.028436,0.092533,-1289.903076,0.010365,0.000000
7.180000,0.121765,-1289.947632,-0.005493,0.000384,0.009765,0.541638,0.027592,0.097650,-1289.947632,0.011049,0.000000
7.590000,0.113571,-1289.947632,-0.005445,0.000419,0.010651,0.505190,0.025736,0.106507,-1289.947632,0.011726,0.000000
8.000000,0.093094,-1289.947632,-0.005433,0.000436,0.011084,0.414102,0.021095,0.110837,-1289.947632,0.012411,0.000000
8.410001,0.112831,-1289.858643,-0.005385,0.000482,0.012246,0.501898,0.025568,0.122464,-1289.858643,0.013096,0.000000
8.820001,0.129959,-1289.992065,-0.005364,0.000500,0.012688,0.578087,0.029449,0.126885,-1289.992065,0.013782,0.000000
9.230000,0.101288,-1289.947632,-0.005346,0.000530,0.013452,0.450551,0.022952,0.134515,-1289.947632,0.014466,0.000000
9.640000,0.058838,-1289.903076,-0.005303,0.000557,0.014154,0.261724,0.013333,0.141540,-1289.903076,0.015143,0.000000
10.050000,0.064423,-1289.947632,-0.005307,0.000572,0.014536,0.286566,0.014598,0.145355,-1289.947632,0.015827,0.000000
10.460000,0.088249,-1289.903076,-0.005264,0.000595,0.015108,0.392552,0.019998,0.151078,-1289.903076,0.016513,0.000000
10.870001,0.100914,-1289.947632,-0.005226,0.000628,0.015950,0.448888,0.022867,0.159495,-1289.947632,0.017197,0.000000
11.280001,0.098679,-1289.947632,-0.005191,0.000665,0.016885,0.438944,0.022361,0.168852,-1289.947632,0.017883,0.000000
11.690001,0.081177,-1289.992065,-0.005187,0.000680,0.017267,0.361092,0.018395,0.172667,-1289.992065,0.018560,0.000000
12.100000,0.084526,-1289.947632,-0.005165,0.000713,0.018118,0.375991,0.019154,0.181175,-1289.947632,0.019244,0.000000
12.510000,0.093842,-1289.947632,-0.005148,0.000740,0.018793,0.417428,0.021265,0.187928,-1289.947632,0.019930,0.000000
12.920001,0.090111,-1289.947632,-0.005092,0.000770,0.019557,0.400833,0.020419,0.195573,-1289.947632,0.020614,0.000000
13.330001,0.083412,-1289.992065,-0.005070,0.000801,0.020355,0.371036,0.018901,0.203552,-1289.992065,0.021300,0.000000
13.740001,0.032021,-1289.947632,-0.005053,0.000825,0.020944,0.142435,0.007256,0.209441,-1289.947632,0.021977,0.000000
14.150001,0.083412,-1289.947632,-0.005006,0.000854,0.021681,0.371036,0.018901,0.216814,-1289.947632,0.022661,0.000000
14.560000,0.116928,-1289.947632,-0.005001,0.000877,0.022279,0.520122,0.026496,0.222794,-1289.947632,0.023347,0.000000
14.970000,0.075966,-1289.992065,-0.004954,0.000908,0.023061,0.337913,0.017214,0.230606,-1289.992065,0.024031,0.000000
15.380001,0.027931,-1289.992065,-0.004919,0.000936,0.023780,0.124244,0.006329,0.237797,-1289.992065,0.024717,0.000000
15.790001,0.026070,-1289.903076,-0.004894,0.000959,0.024370,0.115964,0.005907,0.243702,-1289.903076,0.025394,0.000000
16.200001,0.083786,-1289.947632,-0.004872,0.000983,0.024977,0.372699,0.018986,0.249773,-1289.947632,0.026078,0.000000
16.610001,0.093842,-1289.947632,-0.004855,0.001012,0.025715,0.417428,0.021265,0.257146,-1289.947632,0.026764,0.000000
17.020000,0.068886,-1289.903076,-0.004820,0.001046,0.026573,0.306419,0.015610,0.265730,-1289.903076,0.027448,0.000000
17.430000,-0.001488,-1290.036499,-0.004794,0.001068,0.027136,-0.006618,-0.000337,0.271362,-1290.036499,0.028134,0.000000
17.840000,0.020477,-1289.903076,-0.004773,0.001093,0.027769,0.091088,0.004640,0.277690,-1289.903076,0.028811,0.000000
18.250000,0.066658,-1289.947632,-0.004743,0.001118,0.028394,0.296510,0.015105,0.283943,-1289.947632,0.029495,0.000000
18.660002,0.085648,-1289.947632,-0.004725,0.001139,0.028923,0.380979,0.019408,0.289227,-1289.947632,0.030181,0.000000
19.070002,0.076340,-1289.992065,-0.004652,0.001184,0.030067,0.339576,0.017299,0.300672,-1289.992065,0.030865,0.000000
19.480001,0.042824,-1290.036499,-0.004656,0.001204,0.030588,0.190490,0.009704,0.305880,-1290.036499,0.031551,0.000000
19.890001,0.116928,-1289.947632,-0.004622,0.001235,0.031377,0.520122,0.026496,0.313768,-1289.947632,0.032226,0.000000
20.300001,0.143738,-1290.036499,-0.004605,0.001253,0.031837,0.639378,0.032571,0.318370,-1290.036499,0.032912,0.000000
20.710001,0.129959,-1289.992065,-0.004596,0.001276,0.032400,0.578087,0.029449,0.324002,-1289.992065,0.033598,0.000000
21.120001,0.116928,-1289.947632,-0.004540,0.001312,0.033337,0.520122,0.026496,0.333374,-1289.947632,0.034282,0.000000
21.530001,0.099052,-1290.036499,-0.004510,0.001338,0.033979,0.440607,0.022446,0.339793,-1290.036499,0.034968,0.000000
21.940001,0.125114,-1289.947632,-0.004484,0.001367,0.034715,0.556537,0.028351,0.347151,-1289.947632,0.035643,0.000000
22.350000,0.132195,-1289.947632,-0.004475,0.001387,0.035227,0.588031,0.029956,0.352268,-1289.947632,0.036329,0.000000
22.760000,0.132568,-1290.036499,-0.004454,0.001421,0.036103,0.589693,0.030040,0.361034,-1290.036499,0.037013,0.000000
23.170002,0.110596,-1289.992065,-0.004402,0.001450,0.036822,0.491954,0.025061,0.368225,-1289.992065,0.037699,0.000000
23.580002,0.102028,-1289.947632,-0.004398,0.001474,0.037439,0.453843,0.023120,0.374387,-1289.947632,0.038383,0.000000
23.990002,0.114693,-1289.992065,-0.004350,0.001498,0.038055,0.510179,0.025990,0.380548,-1289.992065,0.039060,0.000000
24.400002,0.161613,-1290.036499,-0.004324,0.001518,0.038567,0.718893,0.036622,0.385666,-1290.036499,0.039746,0.000000
24.810001,0.124001,-1289.992065,-0.004294,0.001560,0.039616,0.551582,0.028099,0.396157,-1289.992065,0.040430,0.000000
25.220001,0.104637,-1290.036499,-0.004260,0.001584,0.040223,0.465449,0.023711,0.402228,-1290.036499,0.041116,0.000000
25.630001,0.111336,-1290.036499,-0.004238,0.001613,0.040968,0.495246,0.025229,0.409677,-1290.036499,0.041800,0.000000
26.040001,0.121017,-1290.081055,-0.004208,0.001631,0.041437,0.538313,0.027423,0.414370,-1290.081055,0.042486,0.000000
26.450001,0.157143,-1289.992065,-0.004191,0.001659,0.042149,0.699005,0.035609,0.421486,-1289.992065,0.043163,0.000000
26.860001,0.106499,-1290.036499,-0.004165,0.001692,0.042980,0.473730,0.024133,0.429798,-1290.036499,0.043847,0.000000
27.270000,0.112083,-1290.081055,-0.004130,0.001714,0.043544,0.498572,0.025398,0.435445,-1290.081055,0.044533,0.000000
27.680002,0.126976,-1290.081055,-0.004096,0.001745,0.044324,0.564817,0.028773,0.443241,-1290.081055,0.045217,0.000000
28.090002,0.141129,-1290.036499,-0.004092,0.001764,0.044810,0.627771,0.031980,0.448101,-1290.036499,0.045903,0.000000
28.500002,0.148575,-1290.081055,-0.004053,0.001789,0.045452,0.660894,0.033668,0.454520,-1290.081055,0.046580,0.000000
28.910002,0.121391,-1290.081055,-0.004027,0.001822,0.046285,0.539975,0.027508,0.462847,-1290.081055,0.047264,0.000000
29.320002,0.125488,-1290.036499,-0.004005,0.001844,0.046848,0.558200,0.028436,0.468479,-1290.036499,0.047950,0.000000
29.730001,0.138519,-1290.036499,-0.003967,0.001880,0.047741,0.616165,0.031389,0.477412,-1290.036499,0.048634,0.000000
30.140001,0.159744,-1290.036499,-0.003954,0.001898,0.048201,0.710578,0.036199,0.482014,-1290.036499,0.049320,0.000000
30.550001,0.147087,-1290.036499,-0.003941,0.001921,0.048799,0.654276,0.033330,0.487994,-1290.036499,0.049997,0.000000
30.960001,0.103889,-1290.081055,-0.003902,0.001956,0.049684,0.462123,0.023542,0.496836,-1290.081055,0.050681,0.000000
31.370001,0.102028,-1290.081055,-0.003880,0.001970,0.050048,0.453843,0.023120,0.500484,-1290.081055,0.051367,0.000000
31.780001,0.139267,-1290.081055,-0.003854,0.001993,0.050630,0.619490,0.031558,0.506298,-1290.081055,0.052051,0.000000
32.190002,0.166824,-1290.081055,-0.003824,0.002026,0.051462,0.742072,0.037803,0.514625,-1290.081055,0.052737,0.000000
32.600002,0.160492,-1290.036499,-0.003786,0.002065,0.052451,0.713904,0.036368,0.524511,-1290.036499,0.053412,0.000000
33.010002,0.155281,-1290.081055,-0.003760,0.002089,0.053066,0.690725,0.035187,0.530657,-1290.081055,0.054098,0.000000
33.420002,0.185814,-1290.036499,-0.003742,0.002114,0.053691,0.826542,0.042106,0.536910,-1290.036499,0.054784,0.000000
33.830002,0.209274,-1290.170044,-0.003717,0.002138,0.054315,0.930899,0.047422,0.543148,-1290.170044,0.055468,0.000000
34.240002,0.236084,-1290.125488,-0.003686,0.002175,0.055234,1.050154,0.053497,0.552337,-1290.125488,0.056154,0.000000
34.650002,0.281883,-1290.125488,-0.003652,0.002200,0.055868,1.253879,0.063876,0.558681,-1290.125488,0.056829,0.000000
35.060001,0.253212,-1290.170044,-0.003635,0.002224,0.056492,1.126343,0.057379,0.564918,-1290.170044,0.057515,0.000000
35.470001,0.323219,-1290.125488,-0.003591,0.002252,0.057194,1.437751,0.073243,0.571943,-1290.125488,0.058200,0.000000
35.880001,0.374603,-1290.125488,-0.003583,0.002272,0.057715,1.666319,0.084886,0.577151,-1290.125488,0.058885,0.000000
36.290001,0.409607,-1290.125488,-0.003540,0.002311,0.058711,1.822023,0.092818,0.587113,-1290.125488,0.059570,0.000000
36.700001,0.418549,-1290.081055,-0.003514,0.002337,0.059371,1.861797,0.094844,0.593714,-1290.081055,0.060246,0.000000
37.110001,0.445358,-1290.214478,-0.003510,0.002358,0.059883,1.981053,0.100920,0.598831,-1290.214478,0.060932,0.000000
37.520000,0.548134,-1290.125488,-0.003471,0.002382,0.060490,2.438221,0.124209,0.604902,-1290.125488,0.061617,0.000000
37.930000,0.625961,-1290.170044,-0.003454,0.002411,0.061227,2.784415,0.141845,0.612275,-1290.170044,0.062302,0.000000
38.340000,0.725006,-1290.125488,-0.003415,0.002445,0.062103,3.224988,0.164289,0.621026,-1290.125488,0.062987,0.000000
38.750000,0.714958,-1290.214478,-0.003385,0.002467,0.062666,3.180293,0.162012,0.626657,-1290.214478,0.063663,0.000000
39.160004,0.839699,-1290.214478,-0.003363,0.002493,0.063317,3.735167,0.190278,0.633168,-1290.214478,0.064349,0.000000
39.570004,1.019554,-1290.214478,-0.003320,0.002516,0.063907,4.535203,0.231034,0.639072,-1290.214478,0.065034,0.000000
39.980003,1.174835,-1290.214478,-0.003311,0.002539,0.064479,5.225928,0.266221,0.644795,-1290.214478,0.065719,0.000000
40.390003,1.531570,-1290.170044,-0.003264,0.002583,0.065598,6.812766,0.347059,0.655983,-1290.170044,0.066404,0.000000
40.800003,1.715889,-1290.125488,-0.003242,0.002603,0.066127,7.632655,0.388826,0.661267,-1290.125488,0.067080,0.000000
41.210003,2.169815,-1290.214478,-0.003221,0.002635,0.066941,9.651819,0.491687,0.669412,-1290.214478,0.067766,0.000000
41.620003,2.364937,-1290.170044,-0.003212,0.002653,0.067376,10.519764,0.535902,0.673757,-1290.170044,0.068451,0.000000
42.030003,2.856468,-1290.214478,-0.003186,0.002685,0.068199,12.706205,0.647285,0.681993,-1290.214478,0.069136,0.000000
42.440002,3.225121,-1290.170044,-0.003156,0.002711,0.068867,14.346053,0.730823,0.688669,-1290.170044,0.069821,0.000000
42.850002,3.600471,-1290.170044,-0.003134,0.002737,0.069509,16.015697,0.815878,0.695088,-1290.170044,0.070497,0.000000
43.260002,4.214882,-1290.258911,-0.003104,0.002766,0.070263,18.748732,0.955106,0.702628,-1290.258911,0.071183,0.000000
43.670002,4.545547,-1290.214478,-0.003091,0.002786,0.070767,20.219604,1.030036,0.707669,-1290.214478,0.071868,0.000000
44.080002,5.323441,-1290.303467,-0.003070,0.002820,0.071616,23.679846,1.206309,0.716163,-1290.303467,0.072553,0.000000
44.490002,5.821671,-1290.214478,-0.003040,0.002848,0.072335,25.896084,1.319209,0.723354,-1290.214478,0.073238,0.000000
44.900002,6.374641,-1290.214478,-0.003009,0.002873,0.072977,28.355822,1.444514,0.729773,-1290.214478,0.073914,0.000000
45.310001,6.933945,-1290.258911,-0.003001,0.002900,0.073654,30.843727,1.571254,0.736541,-1290.258911,0.074599,0.000000
45.720001,7.270943,-1290.214478,-0.002975,0.002917,0.074087,32.342770,1.647619,0.740870,-1290.214478,0.075285,0.000000
46.130001,8.401466,-1290.347900,-0.002940,0.002958,0.075129,37.371590,1.903800,0.751287,-1290.347900,0.075970,0.000000
46.540001,8.738091,-1290.258911,-0.002910,0.002982,0.075752,38.868969,1.980080,0.757524,-1290.258911,0.076655,0.000000
46.950001,9.365913,-1290.258911,-0.002889,0.003011,0.076490,41.661663,2.122346,0.764897,-1290.258911,0.077331,0.000000
47.360001,9.688759,-1290.258911,-0.002863,0.003030,0.076959,43.097752,2.195504,0.769590,-1290.258911,0.078016,0.000000
47.770000,10.383232,-1290.170044,-0.002850,0.003058,0.077678,46.186924,2.352874,0.776782,-1290.170044,0.078702,0.000000
48.180004,11.087761,-1290.303467,-0.002811,0.003091,0.078502,49.320824,2.512523,0.785017,-1290.303467,0.079386,0.000000
48.590004,11.286240,-1290.214478,-0.002794,0.003112,0.079048,50.203701,2.557498,0.790483,-1290.214478,0.080072,0.000000
49.000004,11.990395,-1290.214478,-0.002759,0.003144,0.079846,53.335937,2.717062,0.798461,-1290.214478,0.080748,0.000000
49.410004,11.984810,-1290.303467,-0.002755,0.003162,0.080314,53.311096,2.715797,0.803140,-1290.303467,0.081433,0.000000
49.820004,12.538895,-1290.214478,-0.002725,0.003184,0.080886,55.775787,2.841354,0.808862,-1290.214478,0.082119,0.000000
50.230003,13.169327,-1290.258911,-0.002677,0.003220,0.081779,58.580090,2.984212,0.817795,-1290.258911,0.082803,0.000000
50.640003,13.348434,-1290.258911,-0.002647,0.003243,0.082370,59.376801,3.024798,0.823699,-1290.258911,0.083489,0.000000
51.050003,14.168404,-1290.258911,-0.002608,0.003278,0.083263,63.024208,3.210606,0.832631,-1290.258911,0.084165,0.000000
51.460003,14.117012,-1290.392334,-0.002608,0.003299,0.083792,62.795605,3.198961,0.837915,-1290.392334,0.084850,0.000000
51.870003,14.351608,-1290.214478,-0.002561,0.003320,0.084330,63.839142,3.252121,0.843305,-1290.214478,0.085536,0.000000
52.280003,15.064697,-1290.303467,-0.002531,0.003355,0.085215,67.011124,3.413709,0.852146,-1290.303467,0.086220,0.000000
52.690002,14.674828,-1290.258911,-0.002501,0.003369,0.085570,65.276894,3.325363,0.855704,-1290.258911,0.086906,0.000000
53.100002,15.000648,-1290.347900,-0.002471,0.003398,0.086308,66.726219,3.399195,0.863077,-1290.347900,0.087582,0.000000
53.510002,15.450104,-1290.303467,-0.002436,0.003424,0.086966,68.725494,3.501044,0.869663,-1290.303467,0.088267,0.000000
53.920002,16.036591,-1290.258911,-0.002406,0.003462,0.087929,71.334320,3.633943,0.879292,-1290.258911,0.088953,0.000000
54.330002,16.106598,-1290.392334,-0.002384,0.003489,0.088632,71.645729,3.649807,0.886316,-1290.392334,0.089637,0.000000
54.740002,16.178841,-1290.214478,-0.002345,0.003513,0.089230,71.967079,3.666178,0.892297,-1290.214478,0.090323,0.000000
55.150002,15.994141,-1290.347900,-0.002320,0.003536,0.089802,71.145493,3.624324,0.898019,-1290.347900,0.090998,0.000000
55.560001,16.684517,-1290.347900,-0.002285,0.003567,0.090600,74.216438,3.780766,0.905998,-1290.347900,0.091684,0.000000
55.970001,17.126526,-1290.347900,-0.002233,0.003599,0.091407,76.182594,3.880926,0.914067,-1290.347900,0.092370,0.000000
56.380001,16.978691,-1290.347900,-0.002212,0.003623,0.092014,75.524986,3.847426,0.920138,-1290.347900,0.093054,0.000000
56.790001,17.111259,-1290.347900,-0.002173,0.003648,0.092647,76.114685,3.877467,0.926467,-1290.347900,0.093740,0.000000
57.200005,17.186478,-1290.347900,-0.002147,0.003673,0.093289,76.449272,3.894511,0.932886,-1290.347900,0.094415,0.000000
57.610004,17.500389,-1290.347900,-0.002121,0.003697,0.093912,77.845619,3.965645,0.939123,-1290.347900,0.095101,0.000000
58.020004,17.924149,-1290.392334,-0.002078,0.003735,0.094875,79.730598,4.061670,0.948752,-1290.392334,0.095785,0.000000
58.430004,17.812813,-1290.436890,-0.002044,0.003756,0.095404,79.235352,4.036441,0.954036,-1290.436890,0.096471,0.000000
58.840004,18.009422,-1290.303467,-0.002031,0.003780,0.096011,80.109909,4.080994,0.960107,-1290.303467,0.097157,0.000000
59.250004,18.376579,-1290.392334,-0.001992,0.003809,0.096740,81.743111,4.164193,0.967404,-1290.392334,0.097832,0.000000
59.660004,18.945564,-1290.392334,-0.001949,0.003842,0.097581,84.274078,4.293127,0.975806,-1290.392334,0.098518,0.000000
60.070004,18.729218,-1290.392334,-0.001914,0.003865,0.098171,83.311722,4.244102,0.981711,-1290.392334,0.099202,0.000000
60.480003,18.904602,-1290.347900,-0.001876,0.003890,0.098813,84.091873,4.283844,0.988130,-1290.347900,0.099888,0.000000
60.890003,19.129517,-1290.303467,-0.001854,0.003915,0.099446,85.092339,4.334810,0.994458,-1290.303467,0.100572,0.000000
61.300003,19.108665,-1290.436890,-0.001828,0.003938,0.100018,84.999588,4.330085,1.000181,-1290.436890,0.101249,0.000000
61.710003,20.229881,-1290.392334,-0.001781,0.003981,0.101111,89.987007,4.584157,1.011112,-1290.392334,0.101935,0.000000
62.120003,19.847076,-1290.347900,-0.001729,0.004003,0.101683,88.284203,4.497412,1.016835,-1290.347900,0.102619,0.000000
62.530003,20.263763,-1290.436890,-0.001725,0.004031,0.102394,90.137718,4.591834,1.023935,-1290.436890,0.103305,0.000000
62.940002,20.027679,-1290.392334,-0.001681,0.004050,0.102880,89.087570,4.538337,1.028795,-1290.392334,0.103989,0.000000
63.350002,20.037735,-1290.481323,-0.001664,0.004075,0.103496,89.132294,4.540616,1.034957,-1290.481323,0.104666,0.000000
63.760002,21.095642,-1290.481323,-0.001643,0.004109,0.104363,93.838104,4.780341,1.043632,-1290.481323,0.105352,0.000000
64.170006,21.139214,-1290.436890,-0.001574,0.004135,0.105022,94.031921,4.790215,1.050218,-1290.436890,0.106036,0.000000
64.580002,21.648247,-1290.481323,-0.001556,0.004164,0.105776,96.296211,4.905563,1.057757,-1290.481323,0.106722,0.000000
64.990005,21.404716,-1290.392334,-0.001518,0.004184,0.106271,95.212936,4.850379,1.062708,-1290.392334,0.107406,0.000000
65.400002,22.238831,-1290.481323,-0.001492,0.004217,0.107120,98.923256,5.039391,1.071201,-1290.481323,0.108083,0.000000
65.810005,22.505447,-1290.436890,-0.001453,0.004246,0.107848,100.109230,5.099807,1.078483,-1290.436890,0.108769,0.000000
66.220001,22.660728,-1290.481323,-0.001431,0.004271,0.108490,100.799957,5.134994,1.084902,-1290.481323,0.109453,0.000000
66.630005,22.704666,-1290.436890,-0.001393,0.004295,0.109097,100.995399,5.144951,1.090973,-1290.436890,0.110139,0.000000
67.040001,22.764244,-1290.436890,-0.001367,0.004315,0.109609,101.260414,5.158452,1.096090,-1290.436890,0.110823,0.000000
67.450005,24.181496,-1290.570312,-0.001328,0.004356,0.110651,107.564667,5.479605,1.106506,-1290.570312,0.111500,0.000000
67.860001,23.940941,-1290.436890,-0.001311,0.004380,0.111249,106.494621,5.425095,1.112487,-1290.436890,0.112184,0.000000
68.270004,24.524452,-1290.481323,-0.001259,0.004411,0.112028,109.090210,5.557320,1.120283,-1290.481323,0.112870,0.000000
68.680000,24.351669,-1290.481323,-0.001237,0.004428,0.112480,108.321632,5.518167,1.124795,-1290.481323,0.113556,0.000000
69.090004,24.917679,-1290.436890,-0.001207,0.004457,0.113217,110.839371,5.646427,1.132168,-1290.436890,0.114240,0.000000
69.500000,25.760353,-1290.570312,-0.001168,0.004489,0.114024,114.587776,5.837379,1.140237,-1290.570312,0.114917,0.000000
69.910004,25.684761,-1290.481323,-0.001134,0.004511,0.114570,114.251526,5.820250,1.145703,-1290.481323,0.115601,0.000000
70.320000,26.409775,-1290.525879,-0.001104,0.004542,0.115368,117.476547,5.984540,1.153681,-1290.525879,0.116287,0.000000
70.730003,25.956596,-1290.570312,-0.001091,0.004558,0.115775,115.460709,5.881849,1.157754,-1290.570312,0.116971,0.000000
71.140007,27.433426,-1290.525879,-0.001052,0.004597,0.116755,122.029976,6.216503,1.167549,-1290.525879,0.117657,0.000000
71.550003,27.815109,-1290.570312,-0.001026,0.004622,0.117406,123.727783,6.302994,1.174059,-1290.570312,0.118334,0.000000
71.960007,27.811752,-1290.525879,-0.001000,0.004642,0.117909,123.712852,6.302233,1.179086,-1290.525879,0.119018,0.000000
72.370003,28.731514,-1290.525879,-0.000957,0.004677,0.118785,127.804153,6.510654,1.187851,-1290.525879,0.119704,0.000000
72.780006,28.902061,-1290.525879,-0.000953,0.004696,0.119288,128.562790,6.549301,1.192878,-1290.525879,0.120388,0.000000
73.190002,29.405136,-1290.525879,-0.000901,0.004723,0.119955,130.800583,6.663299,1.199554,-1290.525879,0.121074,0.000000
73.600006,30.511086,-1290.614746,-0.000905,0.004752,0.120709,135.720093,6.913911,1.207094,-1290.614746,0.121751,0.000000
74.010002,30.129028,-1290.525879,-0.000875,0.004767,0.121091,134.020615,6.827335,1.210909,-1290.525879,0.122435,0.000000
74.420006,30.619812,-1290.570312,-0.000836,0.004790,0.121672,136.203720,6.938549,1.216723,-1290.570312,0.123121,0.000000
74.830002,31.924232,-1290.570312,-0.000819,0.004823,0.122496,142.006073,7.234134,1.224959,-1290.570312,0.123805,0.000000
75.240005,33.474792,-1290.570312,-0.000776,0.004861,0.123477,148.903320,7.585496,1.234769,-1290.570312,0.124491,0.000000
75.650002,33.834877,-1290.570312,-0.000767,0.004888,0.124152,150.505051,7.667092,1.241521,-1290.570312,0.125168,0.000000
76.060005,34.400887,-1290.525879,-0.000729,0.004912,0.124759,153.022781,7.795352,1.247592,-1290.525879,0.125852,0.000000
76.470001,35.016792,-1290.570312,-0.000711,0.004937,0.125401,155.762466,7.934919,1.254011,-1290.570312,0.126538,0.000000
76.880005,35.752594,-1290.570312,-0.000686,0.004963,0.126052,159.035477,8.101654,1.260521,-1290.570312,0.127222,0.000000
77.290001,37.442055,-1290.570312,-0.000642,0.004996,0.126911,166.550583,8.484490,1.269106,-1290.570312,0.127908,0.000000
77.700005,37.775322,-1290.570312,-0.000642,0.005021,0.127527,168.033020,8.560011,1.275267,-1290.570312,0.128585,0.000000
78.110001,38.580391,-1290.525879,-0.000608,0.005046,0.128160,171.614151,8.742441,1.281596,-1290.525879,0.129269,0.000000
78.520004,39.262955,-1290.570312,-0.000599,0.005072,0.128836,174.650345,8.897113,1.288363,-1290.570312,0.129955,0.000000
78.930000,40.392357,-1290.614746,-0.000582,0.005095,0.129425,179.674179,9.153039,1.294252,-1290.614746,0.130639,0.000000
79.340004,42.046440,-1290.570312,-0.000535,0.005133,0.130371,187.031906,9.527859,1.303715,-1290.570312,0.131325,0.000000
79.750000,42.766602,-1290.614746,-0.000526,0.005155,0.130926,190.235352,9.691051,1.309256,-1290.614746,0.132000,0.000000
80.160004,43.738121,-1290.570312,-0.000509,0.005179,0.131542,194.556885,9.911200,1.315418,-1290.570312,0.132686,0.000000
80.570007,45.155746,-1290.703735,-0.000492,0.005207,0.132261,200.862793,10.232438,1.322609,-1290.703735,0.133371,0.000000
80.980003,46.880577,-1290.614746,-0.000474,0.005239,0.133068,208.535217,10.623290,1.330678,-1290.614746,0.134056,0.000000
81.390007,47.729584,-1290.659302,-0.000461,0.005262,0.133658,212.311798,10.815679,1.336583,-1290.659302,0.134742,0.000000
81.800003,49.081299,-1290.659302,-0.000444,0.005289,0.134333,218.324524,11.121982,1.343335,-1290.659302,0.135417,0.000000
82.210007,50.382736,-1290.614746,-0.000418,0.005313,0.134959,224.113602,11.416891,1.349588,-1290.614746,0.136103,0.000000
82.620003,51.542305,-1290.659302,-0.000418,0.005336,0.135522,229.271622,11.679654,1.355219,-1290.659302,0.136788,0.000000
83.030006,54.600227,-1290.614746,-0.000397,0.005378,0.136597,242.873947,12.372588,1.365969,-1290.614746,0.137473,0.000000
83.440002,55.587387,-1290.659302,-0.000358,0.005401,0.137178,247.265045,12.596282,1.371782,-1290.659302,0.138158,0.000000
83.850006,57.364723,-1290.570312,-0.000354,0.005429,0.137890,255.171036,12.999032,1.378898,-1290.570312,0.138834,0.000000
84.260002,58.338104,-1290.614746,-0.000332,0.005449,0.138392,259.500854,13.219603,1.383924,-1290.614746,0.139520,0.000000
84.670006,59.275742,-1290.659302,-0.000345,0.005467,0.138860,263.671661,13.432075,1.388602,-1290.659302,0.140205,0.000000
85.080002,62.172424,-1290.659302,-0.000332,0.005504,0.139806,276.556763,14.088472,1.398064,-1290.659302,0.140890,0.000000
85.490005,64.125893,-1290.748291,-0.000315,0.005531,0.140500,285.246216,14.531135,1.404998,-1290.748291,0.141575,0.000000
85.900002,66.264427,-1290.614746,-0.000293,0.005554,0.141063,294.758881,15.015734,1.410630,-1290.614746,0.141254,0.000000
86.310005,65.179329,-1290.614746,-0.000272,0.005553,0.141046,289.932129,14.769847,1.410464,-1290.614746,294.500488,0.000000
86.720001,65.418388,-1290.703735,-0.000280,0.005567,0.141393,290.995514,14.824019,1.413931,-1290.703735,294.500488,0.000000
87.130005,65.030006,-1290.614746,-0.000263,0.005570,0.141479,289.267914,14.736011,1.414794,-1290.614746,294.500488,0.000000
87.540001,64.964851,-1290.748291,-0.000285,0.005577,0.141644,288.978088,14.721246,1.416444,-1290.748291,294.500488,0.000000
87.950005,65.121986,-1290.659302,-0.000263,0.005581,0.141766,289.677063,14.756853,1.417655,-1290.659302,294.500488,0.000000
88.360001,64.882179,-1290.748291,-0.000241,0.005583,0.141800,288.610352,14.702512,1.418003,-1290.748291,294.500488,0.000000
88.770004,65.094063,-1290.748291,-0.000250,0.005588,0.141940,289.552856,14.750525,1.419396,-1290.748291,294.500488,0.000000
89.180008,64.882545,-1290.703735,-0.000263,0.005589,0.141965,288.611969,14.702596,1.419654,-1290.703735,294.500488,0.000000
89.590004,65.384514,-1290.792725,-0.000254,0.005597,0.142174,290.844849,14.816342,1.421743,-1290.792725,294.500488,0.000000
90.000008,65.223640,-1290.659302,-0.000259,0.005597,0.142174,290.129242,14.779888,1.421743,-1290.659302,294.500488,0.000000
90.410004,64.974159,-1290.748291,-0.000250,0.005598,0.142191,289.019501,14.723354,1.421909,-1290.748291,294.500488,0.000000
90.820007,65.424721,-1290.703735,-0.000250,0.005605,0.142356,291.023682,14.825454,1.423560,-1290.703735,294.500488,0.000000
91.230003,65.291786,-1290.748291,-0.000233,0.005605,0.142365,290.432373,14.795330,1.423650,-1290.748291,294.500488,0.000000
91.640007,65.328651,-1290.659302,-0.000241,0.005610,0.142486,290.596344,14.803684,1.424862,-1290.659302,294.500488,0.000000
92.050003,65.365150,-1290.748291,-0.000237,0.005610,0.142486,290.758698,14.811954,1.424862,-1290.748291,294.500488,0.000000
92.460007,65.254921,-1290.792725,-0.000241,0.005610,0.142486,290.268372,14.786977,1.424862,-1290.792725,294.500488,0.000000
92.870003,65.167412,-1290.748291,-0.000237,0.005611,0.142521,289.879120,14.767146,1.425210,-1290.748291,294.500488,0.000000
93.280006,65.272423,-1290.748291,-0.000224,0.005613,0.142582,290.346252,14.790943,1.425815,-1290.748291,294.500488,0.000000
93.690002,65.249336,-1290.748291,-0.000237,0.005614,0.142607,290.243530,14.785711,1.426073,-1290.748291,294.500488,0.000000
94.100006,65.168907,-1290.703735,-0.000241,0.005615,0.142633,289.885773,14.767486,1.426330,-1290.703735,294.500488,0.000000
94.510002,65.253426,-1290.792725,-0.000233,0.005618,0.142686,290.261719,14.786638,1.426860,-1290.792725,294.500488,0.000000
94.920006,65.216576,-1290.748291,-0.000233,0.005618,0.142686,290.097809,14.778287,1.426860,-1290.748291,294.500488,0.000000
95.330002,65.198692,-1290.748291,-0.000233,0.005620,0.142747,290.018280,14.774235,1.427466,-1290.748291,294.500488,0.000000
95.740005,65.194221,-1290.703735,-0.000237,0.005620,0.142747,289.998383,14.773222,1.427466,-1290.703735,294.500488,0.000000
96.150002,65.112679,-1290.748291,-0.000237,0.005620,0.142747,289.635651,14.754745,1.427466,-1290.748291,294.500488,0.000000
96.560005,65.260887,-1290.837158,-0.000233,0.005623,0.142815,290.294922,14.788328,1.428147,-1290.837158,294.500488,0.000000
96.970001,65.240028,-1290.748291,-0.000224,0.005624,0.142842,290.202148,14.783602,1.428419,-1290.748291,294.500488,0.000000
97.380005,65.248222,-1290.748291,-0.000224,0.005624,0.142850,290.238586,14.785459,1.428495,-1290.748291,294.500488,0.000000
97.790001,65.217308,-1290.748291,-0.000220,0.005625,0.142868,290.101074,14.778454,1.428677,-1290.748291,294.500488,0.000000
98.200005,65.208382,-1290.703735,-0.000216,0.005625,0.142884,290.061371,14.776431,1.428843,-1290.703735,294.500488,0.000000
98.610008,65.191246,-1290.792725,-0.000233,0.005626,0.142893,289.985138,14.772547,1.428934,-1290.792725,294.500488,0.000000
99.020004,65.228477,-1290.748291,-0.000237,0.005627,0.142928,290.150757,14.780985,1.429282,-1290.748291,294.500488,0.000000
99.430008,65.201302,-1290.837158,-0.000220,0.005627,0.142937,290.029877,14.774826,1.429373,-1290.837158,294.500488,0.000000
99.840004,65.237801,-1290.792725,-0.000220,0.005629,0.142972,290.192230,14.783097,1.429721,-1290.792725,294.500488,0.000000
100.250008,65.267586,-1290.792725,-0.000211,0.005630,0.143007,290.324707,14.789846,1.430070,-1290.792725,294.500488,0.000000
100.660004,65.262367,-1290.881714,-0.000216,0.005630,0.143015,290.301514,14.788664,1.430145,-1290.881714,294.500488,0.000000
101.070007,65.259758,-1290.748291,-0.000229,0.005631,0.143024,290.289886,14.788073,1.430236,-1290.748291,294.500488,0.000000
101.480003,65.229225,-1290.792725,-0.000220,0.005631,0.143024,290.154083,14.781154,1.430236,-1290.792725,294.500488,0.000000
101.890007,65.199440,-1290.792725,-0.000216,0.005632,0.143049,290.021606,14.774405,1.430493,-1290.792725,294.500488,0.000000
102.300003,65.280251,-1290.792725,-0.000220,0.005633,0.143084,290.381042,14.792717,1.430842,-1290.792725,294.500488,0.000000
102.710007,65.269447,-1290.837158,-0.000224,0.005634,0.143093,290.333008,14.790268,1.430933,-1290.837158,294.500488,0.000000
103.120003,65.283226,-1290.792725,-0.000224,0.005634,0.143110,290.394287,14.793390,1.431099,-1290.792725,294.500488,0.000000
103.530006,65.259392,-1290.837158,-0.000216,0.005634,0.143110,290.288269,14.787990,1.431099,-1290.837158,294.500488,0.000000
103.940002,65.275780,-1290.748291,-0.000216,0.005636,0.143145,290.361176,14.791703,1.431447,-1290.748291,294.500488,0.000000
104.350006,65.304451,-1290.792725,-0.000211,0.005636,0.143163,290.488708,14.798200,1.431629,-1290.792725,294.500488,0.000000
104.760002,65.295509,-1290.837158,-0.000220,0.005637,0.143170,290.448944,14.796174,1.431705,-1290.837158,294.500488,0.000000
105.170006,65.291420,-1290.792725,-0.000207,0.005637,0.143170,290.430756,14.795248,1.431705,-1290.792725,294.500488,0.000000
105.580002,65.269814,-1290.881714,-0.000211,0.005637,0.143180,290.334625,14.790351,1.431795,-1290.881714,294.500488,0.000000
105.990005,65.263115,-1290.881714,-0.000224,0.005637,0.143189,290.304840,14.788833,1.431886,-1290.881714,294.500488,0.000000
106.400002,65.258278,-1290.881714,-0.000220,0.005638,0.143198,290.283325,14.787737,1.431977,-1290.881714,294.500488,0.000000
106.810005,65.287315,-1290.926147,-0.000207,0.005639,0.143231,290.412476,14.794317,1.432310,-1290.926147,294.500488,0.000000
107.220009,65.302208,-1290.881714,-0.000224,0.005639,0.143231,290.478729,14.797691,1.432310,-1290.881714,294.500488,0.000000
107.630005,65.288811,-1290.837158,-0.000211,0.005640,0.143249,290.419128,14.794656,1.432492,-1290.837158,294.500488,0.000000
108.040009,65.286568,-1290.881714,-0.000220,0.005640,0.143249,290.409149,14.794147,1.432492,-1290.881714,294.500488,0.000000
108.450005,65.280617,-1290.881714,-0.000207,0.005641,0.143275,290.382690,14.792799,1.432749,-1290.881714,294.500488,0.000000
108.860008,65.305565,-1290.926147,-0.000224,0.005641,0.143284,290.493652,14.798452,1.432840,-1290.926147,294.500488,0.000000
109.270004,65.296257,-1290.926147,-0.000216,0.005641,0.143284,290.452271,14.796344,1.432840,-1290.926147,294.500488,0.000000
109.680008,65.280251,-1290.881714,-0.000216,0.005641,0.143284,290.381042,14.792717,1.432840,-1290.881714,294.500488,0.000000
110.090004,65.267952,-1290.881714,-0.000211,0.005641,0.143293,290.326355,14.789929,1.432931,-1290.881714,294.500488,0.000000
110.500008,65.263115,-1290.881714,-0.000194,0.005642,0.143310,290.304840,14.788833,1.433097,-1290.881714,294.500488,0.000000
110.910004,65.272057,-1290.881714,-0.000220,0.005642,0.143319,290.344604,14.790859,1.433188,-1290.881714,294.500488,0.000000
111.320007,65.262367,-1290.837158,-0.000207,0.005642,0.143319,290.301514,14.788664,1.433188,-1290.837158,294.500488,0.000000
111.730003,65.251945,-1290.926147,-0.000220,0.005643,0.143326,290.255157,14.786302,1.433264,-1290.926147,294.500488,0.000000
112.140007,65.255302,-1290.926147,-0.000207,0.005643,0.143335,290.270081,14.787063,1.433355,-1290.926147,294.500488,0.000000
112.550003,65.240028,-1290.970703,-0.000211,0.005643,0.143345,290.202148,14.783602,1.433446,-1290.970703,294.500488,0.000000
112.960007,65.267204,-1290.881714,-0.000216,0.005644,0.143361,290.323029,14.789760,1.433612,-1290.881714,294.500488,0.000000
113.370003,65.269066,-1290.926147,-0.000211,0.005644,0.143361,290.331299,14.790182,1.433612,-1290.926147,294.500488,0.000000
113.780006,65.267204,-1290.970703,-0.000216,0.005645,0.143379,290.323029,14.789760,1.433794,-1290.970703,294.500488,0.000000
114.190002,65.273537,-1290.881714,-0.000194,0.005645,0.143388,290.351196,14.791195,1.433885,-1290.881714,294.500488,0.000000
114.600006,65.275032,-1291.015137,-0.000198,0.005646,0.143396,290.357849,14.791533,1.433960,-1291.015137,294.500488,0.000000
115.010002,65.285454,-1290.926147,-0.000203,0.005646,0.143405,290.404205,14.793895,1.434051,-1290.926147,294.500488,0.000000
115.420006,65.267952,-1290.970703,-0.000220,0.005646,0.143414,290.326355,14.789929,1.434142,-1290.970703,294.500488,0.000000
115.830002,65.291786,-1291.015137,-0.000211,0.005647,0.143422,290.432373,14.795330,1.434218,-1291.015137,294.500488,0.000000
116.240005,65.284706,-1290.926147,-0.000203,0.005647,0.143422,290.400879,14.793726,1.434218,-1290.926147,294.500488,0.000000
116.650009,65.264977,-1291.104126,-0.000211,0.005647,0.143422,290.313110,14.789255,1.434218,-1291.104126,294.500488,0.000000
117.060005,65.263481,-1290.926147,-0.000207,0.005647,0.143422,290.306458,14.788917,1.434218,-1290.926147,294.500488,0.000000
117.470009,65.247108,-1291.015137,-0.000211,0.005647,0.143431,290.233643,14.785206,1.434309,-1291.015137,294.500488,0.000000
117.880005,65.235191,-1291.015137,-0.000211,0.005647,0.143431,290.180634,14.782506,1.434309,-1291.015137,294.500488,0.000000
118.290009,65.231834,-1291.015137,-0.000220,0.005647,0.143431,290.165680,14.781745,1.434309,-1291.015137,294.500488,0.000000
118.700005,65.206520,-1291.059570,-0.000207,0.005647,0.143440,290.053101,14.776009,1.434399,-1291.059570,294.500488,0.000000
119.110008,65.295143,-1291.015137,-0.000216,0.005650,0.143517,290.447296,14.796091,1.435172,-1291.015137,294.500488,0.000000
119.520004,65.345406,-1291.059570,-0.000203,0.005650,0.143517,290.670868,14.807481,1.435172,-1291.059570,294.500488,0.000000
119.930008,65.368492,-1291.015137,-0.000207,0.005650,0.143517,290.773590,14.812712,1.435172,-1291.015137,294.500488,0.000000
120.340004,65.371483,-1291.015137,-0.000207,0.005650,0.143517,290.786865,14.813390,1.435172,-1291.015137,294.500488,0.000000
120.750008,65.355461,-1291.059570,-0.000207,0.005650,0.143517,290.715607,14.809759,1.435172,-1291.059570,294.500488,0.000000
121.160004,65.342064,-1291.059570,-0.000207,0.005650,0.143517,290.656006,14.806724,1.435172,-1291.059570,294.500488,0.000000
121.570007,65.340935,-1291.104126,-0.000198,0.005650,0.143517,290.651001,14.806468,1.435172,-1291.104126,294.500488,0.000000
121.980003,65.317482,-1291.059570,-0.000207,0.005650,0.143517,290.546661,14.801153,1.435172,-1291.059570,294.500488,0.000000
122.390007,65.314873,-1291.104126,-0.000194,0.005650,0.143517,290.535065,14.800561,1.435172,-1291.104126,294.500488,0.000000
122.800003,65.304817,-1291.104126,-0.000207,0.005650,0.143517,290.490326,14.798283,1.435172,-1291.104126,294.500488,0.000000
123.210007,65.299980,-1291.059570,-0.000216,0.005651,0.143526,290.468811,14.797187,1.435262,-1291.059570,294.500488,0.000000
123.620003,65.282478,-1291.104126,-0.000194,0.005651,0.143526,290.390961,14.793221,1.435262,-1291.104126,294.500488,0.000000
124.030006,65.274666,-1291.059570,-0.000194,0.005651,0.143526,290.356201,14.791451,1.435262,-1291.059570,294.500488,0.000000
124.440002,65.262001,-1291.015137,-0.000203,0.005651,0.143526,290.299866,14.788581,1.435262,-1291.015137,294.500488,0.000000
124.850006,65.251945,-1291.104126,-0.000216,0.005651,0.143526,290.255157,14.786302,1.435262,-1291.104126,294.500488,0.000000
125.260002,65.231834,-1291.015137,-0.000198,0.005651,0.143526,290.165680,14.781745,1.435262,-1291.015137,294.500488,0.000000
125.670006,65.219170,-1291.059570,-0.000203,0.005651,0.143535,290.109344,14.778874,1.435353,-1291.059570,294.500488,0.000000
126.080009,65.194969,-1291.104126,-0.000203,0.005651,0.143535,290.001709,14.773392,1.435353,-1291.104126,294.500488,0.000000
126.490005,65.206886,-1291.059570,-0.000203,0.005652,0.143561,290.054718,14.776092,1.435611,-1291.059570,294.500488,0.000000
126.900009,65.206139,-1291.104126,-0.000207,0.005652,0.143561,290.051392,14.775923,1.435611,-1291.104126,294.500488,0.000000
127.310005,65.197212,-1291.059570,-0.000198,0.005652,0.143561,290.011688,14.773900,1.435611,-1291.059570,294.500488,0.000000
127.720009,65.191246,-1291.104126,-0.000207,0.005652,0.143561,289.985138,14.772547,1.435611,-1291.104126,294.500488,0.000000
128.130005,65.177467,-1291.148560,-0.000211,0.005652,0.143561,289.923859,14.769425,1.435611,-1291.148560,294.500488,0.000000
128.540009,65.161827,-1291.104126,-0.000190,0.005652,0.143561,289.854279,14.765881,1.435611,-1291.104126,294.500488,0.000000
128.950012,65.151405,-1291.104126,-0.000207,0.005652,0.143570,289.807922,14.763519,1.435701,-1291.104126,294.500488,0.000000
129.360001,65.177467,-1291.015137,-0.000194,0.005654,0.143605,289.923859,14.769425,1.436050,-1291.015137,294.500488,0.000000
129.770004,65.215446,-1291.104126,-0.000198,0.005654,0.143605,290.092804,14.778031,1.436050,-1291.104126,294.500488,0.000000
130.180008,65.214333,-1291.148560,-0.000207,0.005654,0.143605,290.087830,14.777779,1.436050,-1291.148560,294.500488,0.000000
130.590012,65.222527,-1291.148560,-0.000207,0.005654,0.143605,290.124298,14.779635,1.436050,-1291.148560,294.500488,0.000000
131.000000,65.216576,-1291.192993,-0.000211,0.005654,0.143605,290.097809,14.778287,1.436050,-1291.192993,294.500488,0.000000
131.410004,65.224388,-1291.104126,-0.000198,0.005654,0.143605,290.132568,14.780058,1.436050,-1291.104126,294.500488,0.000000
131.820007,65.207634,-1291.104126,-0.000216,0.005654,0.143613,290.058044,14.776261,1.436125,-1291.104126,294.500488,0.000000
132.230011,65.189384,-1291.104126,-0.000203,0.005654,0.143613,289.976868,14.772126,1.436125,-1291.104126,294.500488,0.000000
132.639999,65.206520,-1291.104126,-0.000185,0.005655,0.143640,290.053101,14.776009,1.436398,-1291.104126,294.500488,0.000000
133.050003,65.231468,-1291.192993,-0.000203,0.005655,0.143640,290.164062,14.781662,1.436398,-1291.192993,294.500488,0.000000
133.460007,65.228859,-1291.059570,-0.000190,0.005655,0.143647,290.152466,14.781071,1.436474,-1291.059570,294.500488,0.000000
133.870010,65.243752,-1291.148560,-0.000207,0.005655,0.143647,290.218689,14.784445,1.436474,-1291.148560,294.500488,0.000000
134.279999,65.238533,-1291.059570,-0.000207,0.005655,0.143647,290.195496,14.783262,1.436474,-1291.059570,294.500488,0.000000
134.690002,65.219917,-1291.148560,-0.000207,0.005655,0.143647,290.112671,14.779044,1.436474,-1291.148560,294.500488,0.000000
135.100006,65.209496,-1291.192993,-0.000211,0.005655,0.143647,290.066315,14.776683,1.436474,-1291.192993,294.500488,0.000000
135.510010,65.211723,-1291.148560,-0.000207,0.005655,0.143647,290.076233,14.777188,1.436474,-1291.148560,294.500488,0.000000
135.920013,65.211723,-1291.192993,-0.000207,0.005655,0.143647,290.076233,14.777188,1.436474,-1291.192993,294.500488,0.000000
136.330002,65.191246,-1291.104126,-0.000198,0.005655,0.143647,289.985138,14.772547,1.436474,-1291.104126,294.500488,0.000000
136.740005,65.163322,-1291.148560,-0.000203,0.005655,0.143647,289.860931,14.766220,1.436474,-1291.148560,294.500488,0.000000
137.150009,65.156990,-1291.148560,-0.000211,0.005655,0.143647,289.832764,14.764785,1.436474,-1291.148560,294.500488,0.000000
137.560013,65.139854,-1291.148560,-0.000194,0.005655,0.143647,289.756531,14.760902,1.436474,-1291.148560,294.500488,0.000000
137.970001,65.135017,-1291.148560,-0.000211,0.005655,0.143647,289.735016,14.759806,1.436474,-1291.148560,294.500488,0.000000
138.380005,65.128319,-1291.148560,-0.000207,0.005655,0.143647,289.705231,14.758287,1.436474,-1291.148560,294.500488,0.000000
138.790009,65.302589,-1291.104126,-0.000198,0.005660,0.143752,290.480438,14.797779,1.437518,-1291.104126,294.500488,0.000000
139.200012,65.368492,-1291.148560,-0.000198,0.005660,0.143752,290.773590,14.812712,1.437518,-1291.148560,294.500488,0.000000
139.610001,65.405357,-1291.104126,-0.000185,0.005660,0.143752,290.937561,14.821066,1.437518,-1291.104126,294.500488,0.000000
140.020004,65.419136,-1291.148560,-0.000198,0.005660,0.143752,290.998840,14.824188,1.437518,-1291.148560,294.500488,0.000000
140.430008,65.426582,-1291.148560,-0.000194,0.005660,0.143752,291.031982,14.825875,1.437518,-1291.148560,294.500488,0.000000
140.840012,65.416527,-1291.192993,-0.000211,0.005660,0.143752,290.987244,14.823597,1.437518,-1291.192993,294.500488,0.000000
141.250000,65.404243,-1291.192993,-0.000194,0.005660,0.143752,290.932617,14.820813,1.437518,-1291.192993,294.500488,0.000000
141.660004,65.420631,-1291.148560,-0.000207,0.005660,0.143752,291.005493,14.824528,1.437518,-1291.148560,294.500488,0.000000
142.070007,65.400520,-1291.237549,-0.000203,0.005660,0.143752,290.916046,14.819970,1.437518,-1291.237549,294.500488,0.000000
142.480011,65.393822,-1291.192993,-0.000211,0.005660,0.143752,290.886261,14.818452,1.437518,-1291.192993,294.500488,0.000000
142.889999,65.374077,-1291.237549,-0.000203,0.005660,0.143752,290.798431,14.813977,1.437518,-1291.237549,294.500488,0.000000
143.300003,65.367744,-1291.148560,-0.000194,0.005660,0.143752,290.770264,14.812542,1.437518,-1291.148560,294.500488,0.000000
143.710007,65.356209,-1291.148560,-0.000207,0.005660,0.143752,290.718933,14.809928,1.437518,-1291.148560,294.500488,0.000000
144.120010,65.346153,-1291.192993,-0.000203,0.005660,0.143752,290.674194,14.807650,1.437518,-1291.192993,294.500488,0.000000
144.530014,65.332008,-1291.148560,-0.000203,0.005660,0.143752,290.611298,14.804445,1.437518,-1291.148560,294.500488,0.000000
144.940002,65.323814,-1291.237549,-0.000203,0.005660,0.143752,290.574829,14.802588,1.437518,-1291.237549,294.500488,0.000000
145.350006,65.326790,-1291.192993,-0.000207,0.005660,0.143752,290.588074,14.803262,1.437518,-1291.192993,294.500488,0.000000
145.760010,65.326424,-1291.192993,-0.000190,0.005660,0.143752,290.586456,14.803180,1.437518,-1291.192993,294.500488,0.000000
146.170013,65.306679,-1291.192993,-0.000194,0.005660,0.143752,290.498627,14.798705,1.437518,-1291.192993,294.500488,0.000000
146.580002,65.297752,-1291.237549,-0.000207,0.005660,0.143752,290.458923,14.796682,1.437518,-1291.237549,1681.640991,0.000000
146.990005,65.161827,-1291.237549,-0.000198,0.005646,0.143414,289.854279,14.765881,1.434142,-1291.237549,0.143180,0.000000
147.400009,65.206886,-1291.192993,-0.000194,0.005623,0.142824,290.054718,14.776092,1.428238,-1291.192993,0.142503,0.000000
147.810013,65.132408,-1291.104126,-0.000172,0.005603,0.142304,289.723419,14.759214,1.423045,-1291.104126,0.141818,0.000000
148.220001,65.099648,-1291.237549,-0.000190,0.005581,0.141758,289.577698,14.751791,1.417579,-1291.237549,0.141133,0.000000
148.630005,65.043785,-1291.192993,-0.000185,0.005552,0.141012,289.329193,14.739132,1.410116,-1291.192993,0.140448,0.000000
149.040009,65.067253,-1291.237549,-0.000181,0.005528,0.140423,289.433594,14.744451,1.404226,-1291.237549,0.139763,0.000000
149.450012,65.032249,-1291.192993,-0.000185,0.005509,0.139918,289.277893,14.736519,1.399185,-1291.192993,0.139086,0.000000
149.860001,64.980492,-1291.281982,-0.000181,0.005471,0.138956,289.047668,14.724790,1.389556,-1291.281982,0.138401,0.000000
150.270004,64.958138,-1291.237549,-0.000177,0.005449,0.138411,288.948212,14.719725,1.384106,-1291.237549,0.137716,0.000000
150.680008,64.762276,-1291.192993,-0.000177,0.005421,0.137681,288.076996,14.675342,1.376809,-1291.192993,0.137031,0.000000
151.090012,64.410378,-1291.237549,-0.000185,0.005401,0.137196,286.511658,14.595600,1.371964,-1291.237549,0.136346,0.000000
151.500000,63.412422,-1291.148560,-0.000164,0.005382,0.136701,282.072540,14.369460,1.367013,-1291.148560,0.135669,0.000000
151.910004,61.512207,-1291.281982,-0.000151,0.005346,0.135791,273.619965,13.938866,1.357914,-1291.281982,0.134984,0.000000
152.320007,60.198479,-1291.148560,-0.000147,0.005323,0.135210,267.776215,13.641170,1.352101,-1291.148560,0.134299,0.000000
152.730011,57.369560,-1291.148560,-0.000134,0.005290,0.134377,255.192551,13.000128,1.343774,-1291.148560,0.133614,0.000000
153.140015,55.703941,-1291.237549,-0.000155,0.005272,0.133900,247.783508,12.622694,1.339005,-1291.237549,0.132929,0.000000
153.550003,52.953972,-1291.148560,-0.000134,0.005242,0.133147,235.551025,11.999541,1.331465,-1291.148560,0.132253,0.000000
153.960007,50.351089,-1291.192993,-0.000151,0.005218,0.132530,223.972839,11.409719,1.325304,-1291.192993,0.131567,0.000000
154.370010,48.412514,-1291.237549,-0.000160,0.005200,0.132088,215.349609,10.970432,1.320883,-1291.237549,0.130882,0.000000
154.780014,44.224815,-1291.237549,-0.000147,0.005162,0.131125,196.721802,10.021486,1.311254,-1291.237549,0.130197,0.000000
155.190002,41.618950,-1291.192993,-0.000151,0.005139,0.130527,185.130341,9.430989,1.305274,-1291.192993,0.129512,0.000000
155.600006,38.392349,-1291.148560,-0.000142,0.005110,0.129790,170.777695,8.699831,1.297901,-1291.148560,0.128836,0.000000
156.010010,35.813293,-1291.237549,-0.000142,0.005086,0.129183,159.305481,8.115408,1.291830,-1291.237549,0.128150,0.000000
156.420013,33.518738,-1291.192993,-0.000142,0.005063,0.128593,149.098785,7.595455,1.285926,-1291.192993,0.127466,0.000000
156.830002,29.835602,-1291.237549,-0.000142,0.005030,0.127760,132.715378,6.760844,1.277599,-1291.237549,0.126780,0.000000
157.240005,27.258781,-1291.237549,-0.000142,0.005004,0.127110,121.253113,6.176928,1.271104,-1291.237549,0.126096,0.000000
157.650009,24.260811,-1291.237549,-0.000134,0.004977,0.126425,107.917473,5.497579,1.264246,-1291.237549,0.125419,0.000000
158.060013,20.986542,-1291.192993,-0.000151,0.004945,0.125610,93.352798,4.755618,1.256101,-1291.192993,0.124733,0.000000
158.470001,17.899200,-1291.192993,-0.000138,0.004920,0.124968,79.619621,4.056016,1.249681,-1291.192993,0.124049,0.000000
158.880005,15.757317,-1291.192993,-0.000147,0.004901,0.124473,70.092049,3.570659,1.244731,-1291.192993,0.123363,0.000000
159.290009,13.414719,-1291.192993,-0.000147,0.004880,0.123945,59.671650,3.039819,1.239447,-1291.192993,0.122679,0.000000
159.700012,9.424744,-1291.237549,-0.000155,0.004841,0.122973,41.923355,2.135678,1.229728,-1291.237549,0.122002,0.000000
160.110001,6.633812,-1291.192993,-0.000147,0.004815,0.122298,29.508669,1.503243,1.222975,-1291.192993,0.121316,0.000000
160.520004,3.830223,-1291.192993,-0.000151,0.004788,0.121603,17.037683,0.867941,1.216026,-1291.192993,0.120632,0.000000
160.930008,1.925537,-1291.281982,-0.000142,0.004769,0.121144,8.565217,0.436333,1.211439,-1291.281982,0.119946,0.000000
161.340012,-1.015087,-1291.237549,-0.000147,0.004734,0.120251,-4.515333,-0.230022,1.202507,-1291.237549,0.119262,0.000000
161.750015,-0.321732,-1291.281982,-0.000138,0.004710,0.119634,-1.431134,-0.072905,1.196345,-1291.281982,0.118585,0.000000
162.160004,-0.106873,-1291.237549,-0.000147,0.004685,0.118993,-0.475393,-0.024218,1.189926,-1291.237549,0.117899,0.000000
162.570007,-0.106873,-1291.192993,-0.000155,0.004654,0.118213,-0.475393,-0.024218,1.182129,-1291.192993,0.117215,0.000000
162.980011,-0.095703,-1291.326538,-0.000164,0.004629,0.117579,-0.425709,-0.021687,1.175785,-1291.326538,0.116529,0.000000
163.390015,-0.122513,-1291.237549,-0.000168,0.004602,0.116903,-0.544964,-0.027762,1.169033,-1291.237549,0.115845,0.000000
163.800003,-0.110970,-1291.281982,-0.000194,0.004576,0.116227,-0.493617,-0.025146,1.162266,-1291.281982,0.115168,0.000000
164.210007,-0.103149,-1291.281982,-0.000233,0.004551,0.115585,-0.458832,-0.023374,1.155846,-1291.281982,0.114482,0.000000
164.620010,-0.082664,-1291.237549,-0.000263,0.004518,0.114752,-0.367710,-0.018732,1.147520,-1291.237549,0.113798,0.000000
165.030014,-0.113571,-1291.281982,-0.000302,0.004495,0.114180,-0.505190,-0.025736,1.141797,-1291.281982,0.113112,0.000000
165.440002,-0.109474,-1291.281982,-0.000332,0.004462,0.113347,-0.486965,-0.024807,1.133470,-1291.281982,0.112428,0.000000
165.850006,-0.087509,-1291.326538,-0.000362,0.004436,0.112663,-0.389260,-0.019830,1.126627,-1291.326538,0.111751,0.000000
166.260010,-0.118416,-1291.237549,-0.000384,0.004412,0.112056,-0.526740,-0.026833,1.120556,-1291.237549,0.111067,0.000000
166.670013,-0.056229,-1291.281982,-0.000405,0.004399,0.111726,-0.250117,-0.012742,1.117256,-1291.281982,0.111630,0.000000
166.700012,-0.064423,-1291.370972,-0.000423,0.004399,0.111726,-0.286566,-0.014598,1.117256,-1291.370972,0.111630,0.000000