File: Data/Sima compression/P1-17-2_10302024_172819.csv
Time (sec),S:Load (lbs),S:HL1 (DIM),S:LVDT (in),S:Position (in),Ch:Position (mm),Ch:Load (N),Ch:Stress (MPa),Ch:Strain (mm/mm),Ch:HL1 (DIM),Set Point (),Cycles ()
0.110000,-0.005585,-1294.084351,-0.006976,-0.003706,-0.094136,-0.024842,-0.001266,-0.941364,-1294.084351,-0.093946,0.000000
0.400000,-0.002975,-1294.039795,-0.006967,-0.003705,-0.094111,-0.013236,-0.000674,-0.941107,-1294.039795,-0.093722,0.000000
0.690000,-0.017502,-1294.084351,-0.006950,-0.003542,-0.089965,-0.077852,-0.003966,-0.899654,-1294.084351,-0.088900,0.000000
0.980000,0.020477,-1294.084351,-0.006756,-0.003357,-0.085274,0.091088,0.004640,-0.852737,-1294.084351,-0.084059,0.000000
1.270000,-0.029793,-1294.084351,-0.006562,-0.003164,-0.080375,-0.132525,-0.006751,-0.803745,-1294.084351,-0.079221,0.000000
1.560000,0.009682,-1294.039795,-0.006377,-0.002973,-0.075518,0.043066,0.002194,-0.755177,-1294.039795,-0.074399,0.000000
1.850000,-0.081924,-1294.084351,-0.006174,-0.002784,-0.070705,-0.364418,-0.018564,-0.707049,-1294.084351,-0.069560,0.000000
2.140000,0.035378,-1294.084351,-0.005997,-0.002598,-0.065987,0.157367,0.008017,-0.659874,-1294.084351,-0.064738,0.000000
2.430000,-0.013405,-1294.084351,-0.005773,-0.002406,-0.061105,-0.059628,-0.003038,-0.611049,-1294.084351,-0.059900,0.000000
2.720000,0.047295,-1294.084351,-0.005583,-0.002216,-0.056283,0.210377,0.010717,-0.562829,-1294.084351,-0.055078,0.000000
3.010000,-0.001862,-1294.173218,-0.005402,-0.002028,-0.051512,-0.008281,-0.000422,-0.515124,-1294.173218,-0.050238,0.000000
3.300000,0.026810,-1294.084351,-0.005200,-0.001833,-0.046569,0.119255,0.006075,-0.465693,-1294.084351,-0.045416,0.000000
3.590000,-0.055855,-1294.084351,-0.005014,-0.001643,-0.041740,-0.248455,-0.012657,-0.417398,-1294.084351,-0.040577,0.000000
3.880000,0.012291,-1294.084351,-0.004799,-0.001453,-0.036900,0.054673,0.002785,-0.368997,-1294.084351,-0.035738,0.000000
4.170000,-0.051018,-1294.128784,-0.004592,-0.001257,-0.031922,-0.226938,-0.011561,-0.319218,-1294.128784,-0.030917,0.000000
4.460000,0.053246,-1294.084351,-0.004424,-0.001074,-0.027291,0.236848,0.012066,-0.272906,-1294.084351,-0.026078,0.000000
4.750000,-0.003723,-1294.039795,-0.004217,-0.000881,-0.022375,-0.016561,-0.000844,-0.223748,-1294.039795,-0.021256,0.000000
5.040000,0.037239,-1294.084351,-0.004027,-0.000696,-0.017683,0.165648,0.008438,-0.176830,-1294.084351,-0.016416,0.000000
5.330000,-0.004837,-1294.039795,-0.003820,-0.000503,-0.012773,-0.021516,-0.001096,-0.127733,-1294.039795,-0.011594,0.000000
5.620000,0.028671,-1294.084351,-0.003622,-0.000309,-0.007857,0.127536,0.006497,-0.078574,-1294.084351,-0.006755,0.000000
5.910000,-0.039101,-1294.173218,-0.003432,-0.000121,-0.003070,-0.173928,-0.008860,-0.030703,-1294.173218,-0.001933,0.000000
6.200000,0.203316,-1294.084351,-0.003311,-0.000003,-0.000070,0.904394,0.046072,-0.000696,-1294.084351,0.000114,0.000000
6.490000,0.193260,-1294.084351,-0.003307,-0.000003,-0.000077,0.859664,0.043793,-0.000772,-1294.084351,0.000114,0.000000
6.780000,0.168686,-1294.084351,-0.003316,-0.000003,-0.000077,0.750352,0.038225,-0.000772,-1294.084351,0.000435,0.000000
7.070000,0.163475,-1294.084351,-0.003328,-0.000002,-0.000051,0.727173,0.037044,-0.000515,-1294.084351,0.000911,0.000000
7.360000,0.233849,-1294.128784,-0.003307,0.000019,0.000477,1.040210,0.052991,0.004769,-1294.128784,0.001396,0.000000
7.650001,0.404022,-1294.039795,-0.003285,0.000036,0.000919,1.797181,0.091553,0.009190,-1294.039795,0.001882,0.000000
7.940001,0.738411,-1294.039795,-0.003272,0.000055,0.001405,3.284616,0.167326,0.014050,-1294.039795,0.002368,0.000000
8.230000,1.161057,-1294.039795,-0.003272,0.000074,0.001891,5.164638,0.263099,0.018909,-1294.039795,0.002845,0.000000
8.520000,1.525986,-1294.039795,-0.003247,0.000088,0.002247,6.787923,0.345793,0.022467,-1294.039795,0.003331,0.000000
8.810000,1.851067,-1294.128784,-0.003225,0.000110,0.002784,8.233955,0.419458,0.027842,-1294.128784,0.003817,0.000000
9.100000,2.841202,-1294.084351,-0.003199,0.000136,0.003443,12.638297,0.643826,0.034427,-1294.084351,0.004294,0.000000
9.390000,3.308899,-1294.128784,-0.003208,0.000151,0.003833,14.718718,0.749807,0.038333,-1294.128784,0.004778,0.000000
9.680000,3.942680,-1294.084351,-0.003191,0.000169,0.004285,17.537918,0.893424,0.042845,-1294.084351,0.005264,0.000000
9.970000,4.829300,-1293.950806,-0.003173,0.000189,0.004805,21.481798,1.094335,0.048053,-1293.950806,0.005750,0.000000
10.260000,5.390839,-1294.128784,-0.003165,0.000203,0.005169,23.979649,1.221581,0.051687,-1294.128784,0.006227,0.000000
10.550000,5.888329,-1294.039795,-0.003156,0.000216,0.005499,26.192593,1.334314,0.054987,-1294.039795,0.006713,0.000000
10.840000,7.338341,-1294.084351,-0.003143,0.000246,0.006236,32.642570,1.662892,0.062360,-1294.084351,0.007199,0.000000
11.130000,7.963554,-1294.039795,-0.003126,0.000264,0.006704,35.423660,1.804567,0.067038,-1294.039795,0.007683,0.000000
11.420000,8.911987,-1293.995361,-0.003117,0.000285,0.007241,39.642498,2.019485,0.072413,-1293.995361,0.008160,0.000000
11.710001,9.558800,-1294.128784,-0.003100,0.000299,0.007597,42.519665,2.166055,0.075970,-1294.128784,0.008646,0.000000
12.000001,11.041588,-1293.995361,-0.003074,0.000324,0.008230,49.115437,2.502059,0.082299,-1293.995361,0.009132,0.000000
12.290001,11.635895,-1294.084351,-0.003074,0.000340,0.008630,51.759045,2.636731,0.086296,-1294.084351,0.009618,0.000000
12.580001,12.006775,-1294.084351,-0.003057,0.000352,0.008932,53.408802,2.720774,0.089324,-1294.084351,0.010095,0.000000
12.870001,13.745010,-1293.995361,-0.003053,0.000379,0.009627,61.140862,3.114664,0.096273,-1293.995361,0.010581,0.000000
13.160001,14.522896,-1294.084351,-0.003040,0.000397,0.010086,64.601067,3.290935,0.100860,-1294.084351,0.011066,0.000000
13.450001,15.309349,-1294.039795,-0.003031,0.000415,0.010537,68.099388,3.469148,0.105371,-1294.039795,0.011551,0.000000
13.740001,16.769051,-1294.039795,-0.003005,0.000438,0.011126,74.592461,3.799921,0.111261,-1294.039795,0.012028,0.000000
14.030001,16.999550,-1294.084351,-0.003009,0.000451,0.011447,75.617775,3.852153,0.114470,-1294.084351,0.012514,0.000000
14.320001,18.198959,-1293.995361,-0.002997,0.000469,0.011924,80.953011,4.123943,0.119239,-1293.995361,0.013000,0.000000
14.610001,19.645256,-1294.084351,-0.002971,0.000494,0.012549,87.386467,4.451678,0.125492,-1294.084351,0.013486,0.000000
14.900001,20.684174,-1293.950806,-0.002966,0.000516,0.013112,92.007797,4.687101,0.131124,-1293.950806,0.013963,0.000000
15.190001,21.170120,-1294.084351,-0.002949,0.000531,0.013494,94.169395,4.797218,0.134939,-1294.084351,0.014448,0.000000
15.480000,22.247765,-1293.995361,-0.002928,0.000552,0.014024,98.962997,5.041415,0.140238,-1293.995361,0.014934,0.000000
15.770000,23.126564,-1293.995361,-0.002923,0.000570,0.014475,102.872093,5.240554,0.144750,-1293.995361,0.015411,0.000000
16.060001,23.772629,-1294.084351,-0.002928,0.000585,0.014856,105.745934,5.386955,0.148565,-1294.084351,0.015897,0.000000
16.350000,24.361351,-1293.950806,-0.002893,0.000600,0.015229,108.364700,5.520361,0.152289,-1293.950806,0.016383,0.000000
16.640001,25.997925,-1294.039795,-0.002880,0.000628,0.015948,115.644547,5.891214,0.159480,-1294.039795,0.016869,0.000000
16.930000,26.545319,-1293.950806,-0.002876,0.000645,0.016383,118.079475,6.015255,0.163825,-1293.950806,0.017345,0.000000
17.220001,27.434540,-1293.906372,-0.002850,0.000666,0.016920,122.034927,6.216756,0.169200,-1293.906372,0.017830,0.000000
17.510000,27.848991,-1294.084351,-0.002854,0.000681,0.017285,123.878502,6.310671,0.172849,-1294.084351,0.018316,0.000000
17.800001,28.809715,-1294.039795,-0.002820,0.000702,0.017839,128.152008,6.528375,0.178390,-1294.039795,0.018802,0.000000
18.090000,29.066277,-1294.084351,-0.002824,0.000714,0.018125,129.293259,6.586512,0.181251,-1294.084351,0.019279,0.000000
18.380001,29.800224,-1294.084351,-0.002811,0.000733,0.018620,132.558014,6.752827,0.186202,-1294.084351,0.019765,0.000000
18.670000,31.195129,-1293.950806,-0.002794,0.000760,0.019295,138.762863,7.068917,0.192954,-1293.950806,0.020251,0.000000
18.960001,31.566017,-1294.039795,-0.002777,0.000774,0.019660,140.412659,7.152962,0.196603,-1294.039795,0.020735,0.000000
19.250000,32.471992,-1293.995361,-0.002755,0.000795,0.020198,144.442642,7.358259,0.201977,-1293.995361,0.021212,0.000000
19.540001,33.107635,-1294.039795,-0.002738,0.000813,0.020658,147.270111,7.502297,0.206580,-1294.039795,0.021698,0.000000
19.830002,34.003189,-1294.084351,-0.002729,0.000834,0.021177,151.253738,7.705233,0.211772,-1294.084351,0.022184,0.000000
20.120001,34.498444,-1294.039795,-0.002716,0.000852,0.021628,153.456741,7.817459,0.216284,-1294.039795,0.022670,0.000000
20.410002,34.545364,-1294.084351,-0.002721,0.000868,0.022037,153.665451,7.828091,0.220372,-1294.084351,0.023147,0.000000
20.700001,35.815529,-1294.084351,-0.002690,0.000890,0.022609,159.315430,8.115915,0.226094,-1294.084351,0.023633,0.000000
20.990002,36.440742,-1294.039795,-0.002677,0.000910,0.023103,162.096512,8.257590,0.231030,-1294.039795,0.024117,0.000000
21.280001,36.934135,-1294.084351,-0.002673,0.000926,0.023510,164.291245,8.369395,0.235103,-1294.084351,0.024594,0.000000
21.570002,37.773087,-1294.039795,-0.002647,0.000948,0.024083,168.023087,8.559505,0.240825,-1294.039795,0.025080,0.000000
21.860001,38.299622,-1294.084351,-0.002630,0.000965,0.024517,170.365219,8.678818,0.245170,-1294.084351,0.025566,0.000000
22.150002,38.444847,-1294.039795,-0.002617,0.000979,0.024864,171.011215,8.711727,0.248637,-1294.039795,0.026052,0.000000
22.440001,39.546700,-1294.039795,-0.002604,0.001008,0.025601,175.912506,8.961410,0.256010,-1294.039795,0.026529,0.000000
22.730001,39.759323,-1294.039795,-0.002600,0.001024,0.026017,176.858307,9.009592,0.260174,-1294.039795,0.027015,0.000000
23.020000,40.422150,-1293.950806,-0.002561,0.001043,0.026494,179.806702,9.159790,0.264943,-1293.950806,0.027500,0.000000
23.310001,40.945702,-1293.995361,-0.002557,0.001060,0.026927,182.135574,9.278429,0.269273,-1293.995361,0.027986,0.000000
23.600000,41.766037,-1294.039795,-0.002535,0.001084,0.027534,185.784607,9.464319,0.275344,-1294.039795,0.028462,0.000000
23.890001,42.380829,-1294.039795,-0.002527,0.001101,0.027960,188.519348,9.603633,0.279598,-1294.039795,0.028948,0.000000
24.180000,41.989090,-1294.039795,-0.002522,0.001109,0.028176,186.776794,9.514864,0.281763,-1294.039795,0.029434,0.000000
24.470001,43.674446,-1294.039795,-0.002488,0.001142,0.029000,194.273636,9.896770,0.289999,-1294.039795,0.029920,0.000000
24.760000,43.639816,-1293.995361,-0.002466,0.001155,0.029347,194.119598,9.888924,0.293466,-1293.995361,0.030397,0.000000
25.050001,44.459038,-1294.039795,-0.002449,0.001178,0.029920,197.763672,10.074562,0.299204,-1294.039795,0.030882,0.000000
25.340002,44.600914,-1293.995361,-0.002449,0.001192,0.030267,198.394775,10.106711,0.302670,-1293.995361,0.031368,0.000000
25.630001,45.527374,-1294.084351,-0.002432,0.001216,0.030874,202.515869,10.316650,0.308741,-1294.084351,0.031854,0.000000
25.920002,46.155937,-1293.995361,-0.002414,0.001233,0.031307,205.311859,10.459085,0.313071,-1293.995361,0.032331,0.000000
26.210001,46.222969,-1294.039795,-0.002406,0.001250,0.031758,205.610031,10.474275,0.317583,-1294.039795,0.032817,0.000000
26.500002,47.663300,-1293.995361,-0.002389,0.001273,0.032340,212.016953,10.800658,0.323397,-1293.995361,0.033303,0.000000
26.790001,47.795494,-1293.861938,-0.002358,0.001290,0.032756,212.604980,10.830614,0.327560,-1293.861938,0.033779,0.000000
27.080002,48.600937,-1293.995361,-0.002350,0.001311,0.033293,216.187759,11.013129,0.332934,-1293.995361,0.034264,0.000000
27.370001,48.940170,-1294.039795,-0.002328,0.001328,0.033736,217.696747,11.090001,0.337355,-1294.039795,0.034750,0.000000
27.660002,49.586983,-1293.995361,-0.002324,0.001347,0.034203,220.573914,11.236570,0.342033,-1293.995361,0.035236,0.000000
27.950001,49.977600,-1293.995361,-0.002307,0.001362,0.034603,222.311462,11.325087,0.346030,-1293.995361,0.035713,0.000000
28.240002,51.025826,-1293.995361,-0.002294,0.001387,0.035236,226.974213,11.562617,0.352359,-1293.995361,0.036199,0.000000
28.530001,51.681572,-1293.995361,-0.002264,0.001404,0.035661,229.891113,11.711212,0.356613,-1293.995361,0.036685,0.000000
28.820002,52.024155,-1293.950806,-0.002246,0.001423,0.036155,231.414993,11.788841,0.361548,-1293.950806,0.037169,0.000000
29.110001,52.604683,-1293.950806,-0.002238,0.001440,0.036588,233.997314,11.920391,0.365878,-1293.950806,0.037646,0.000000
29.400002,53.299530,-1294.039795,-0.002233,0.001458,0.037031,237.088150,12.077847,0.370314,-1294.039795,0.038132,0.000000
29.690001,53.714355,-1293.950806,-0.002203,0.001473,0.037404,238.933380,12.171847,0.374038,-1293.950806,0.038618,0.000000
29.980001,54.030128,-1293.950806,-0.002203,0.001487,0.037776,240.338013,12.243402,0.377763,-1293.950806,0.039104,0.000000
30.270002,56.530609,-1293.995361,-0.002190,0.001526,0.038757,251.460709,12.810019,0.387573,-1293.995361,0.039581,0.000000
30.560001,56.626678,-1293.950806,-0.002173,0.001539,0.039095,251.888046,12.831789,0.390949,-1293.950806,0.040067,0.000000
30.850002,57.095871,-1293.995361,-0.002164,0.001558,0.039572,253.975113,12.938109,0.395718,-1293.995361,0.040551,0.000000
31.140001,57.452232,-1293.995361,-0.002151,0.001572,0.039937,255.560287,13.018862,0.399367,-1293.995361,0.041037,0.000000
31.430002,58.517212,-1293.950806,-0.002130,0.001592,0.040448,260.297546,13.260190,0.404484,-1293.950806,0.041514,0.000000
31.720001,58.749207,-1293.950806,-0.002104,0.001610,0.040890,261.329529,13.312760,0.408905,-1293.950806,0.042000,0.000000
32.010002,59.285423,-1293.950806,-0.002095,0.001622,0.041193,263.714722,13.434269,0.411933,-1293.950806,0.042486,0.000000
32.300003,60.800232,-1293.995361,-0.002082,0.001649,0.041896,270.452942,13.777530,0.418958,-1293.995361,0.042963,0.000000
32.590000,61.647751,-1293.950806,-0.002065,0.001669,0.042391,274.222900,13.969580,0.423908,-1293.950806,0.043449,0.000000
32.880001,62.574585,-1293.950806,-0.002061,0.001688,0.042884,278.345642,14.179604,0.428844,-1293.950806,0.043934,0.000000
33.170002,63.585197,-1293.950806,-0.002031,0.001709,0.043414,282.841095,14.408612,0.434143,-1293.950806,0.044420,0.000000
33.460003,64.282280,-1293.906372,-0.002035,0.001726,0.043831,285.941864,14.566572,0.438306,-1293.906372,0.044896,0.000000
33.750000,64.738075,-1293.950806,-0.002013,0.001740,0.044203,287.969330,14.669857,0.442030,-1293.950806,0.045382,0.000000
34.040001,66.128883,-1293.906372,-0.001983,0.001768,0.044896,294.155975,14.985019,0.448964,-1293.906372,0.045868,0.000000
34.330002,65.095543,-1294.039795,-0.002001,0.001760,0.044697,289.559448,14.750860,0.446966,-1294.039795,0.007864,0.000000
34.620003,66.595467,-1294.039795,-0.001957,0.001705,0.043310,296.231445,15.090748,0.433098,-1294.039795,294.500488,0.000000
34.910000,65.453026,-1293.950806,-0.001966,0.001733,0.044029,291.149597,14.831867,0.440289,-1293.950806,294.500488,0.000000
35.200001,65.106712,-1293.995361,-0.001953,0.001791,0.045487,289.609131,14.753392,0.454869,-1293.995361,294.500488,0.000000
35.490002,65.106712,-1294.084351,-0.001957,0.001800,0.045720,289.609131,14.753392,0.457200,-1294.084351,294.500488,0.000000
35.780003,65.321205,-1293.995361,-0.001940,0.001812,0.046015,290.563232,14.801996,0.460152,-1293.995361,294.500488,0.000000
36.070004,65.221031,-1293.995361,-0.001944,0.001817,0.046162,290.117645,14.779297,0.461621,-1293.995361,294.500488,0.000000
36.360001,65.362907,-1293.995361,-0.001936,0.001828,0.046422,290.748718,14.811446,0.464225,-1293.995361,294.500488,0.000000
36.650002,65.602348,-1294.084351,-0.001923,0.001836,0.046639,291.813812,14.865705,0.466390,-1294.084351,294.500488,0.000000
36.940002,65.059425,-1293.995361,-0.001910,0.001838,0.046683,289.398773,14.742677,0.466829,-1293.995361,294.500488,0.000000
37.230003,65.129799,-1294.039795,-0.001901,0.001844,0.046848,289.711823,14.758624,0.468479,-1294.039795,294.500488,0.000000
37.520000,65.028145,-1294.039795,-0.001897,0.001849,0.046960,289.259644,14.735588,0.469599,-1294.039795,294.500488,0.000000
37.810001,65.011024,-1293.950806,-0.001910,0.001855,0.047125,289.183472,14.731709,0.471250,-1293.950806,294.500488,0.000000
38.100002,65.481331,-1294.039795,-0.001893,0.001868,0.047437,291.275513,14.838282,0.474368,-1294.039795,294.500488,0.000000
38.390003,65.135384,-1293.995361,-0.001888,0.001866,0.047385,289.736664,14.759890,0.473854,-1293.995361,294.500488,0.000000
38.680000,64.632683,-1293.950806,-0.001876,0.001866,0.047394,287.500519,14.645975,0.473945,-1293.950806,294.500488,0.000000
38.970001,65.906197,-1294.039795,-0.001876,0.001878,0.047690,293.165405,14.934558,0.476897,-1294.039795,294.500488,0.000000
39.260002,65.333122,-1293.950806,-0.001876,0.001878,0.047697,290.616241,14.804697,0.476972,-1293.950806,294.500488,0.000000
39.550003,65.272057,-1293.950806,-0.001867,0.001886,0.047915,290.344604,14.790859,0.479153,-1293.950806,294.500488,0.000000
39.840000,65.934502,-1294.039795,-0.001867,0.001897,0.048192,293.291321,14.940971,0.481923,-1294.039795,294.500488,0.000000
40.130001,65.538292,-1293.995361,-0.001858,0.001897,0.048192,291.528870,14.851189,0.481923,-1293.995361,294.500488,0.000000
40.420002,65.122353,-1294.084351,-0.001863,0.001898,0.048209,289.678680,14.756936,0.482090,-1294.084351,294.500488,0.000000
40.710003,66.205223,-1293.995361,-0.001837,0.001908,0.048460,294.495544,15.002318,0.484603,-1293.995361,294.500488,0.000000
41.000004,65.718147,-1294.039795,-0.001850,0.001907,0.048444,292.328918,14.891945,0.484436,-1294.039795,294.500488,0.000000
41.290001,65.255669,-1294.039795,-0.001828,0.001907,0.048444,290.271698,14.787147,0.484436,-1294.039795,294.500488,0.000000
41.580002,65.358818,-1294.039795,-0.001845,0.001916,0.048678,290.730530,14.810520,0.486783,-1294.039795,294.500488,0.000000
41.870003,65.266090,-1294.084351,-0.001845,0.001921,0.048790,290.318085,14.789508,0.487903,-1294.084351,294.500488,0.000000
42.160004,65.269814,-1294.084351,-0.001837,0.001925,0.048886,290.334625,14.790351,0.488857,-1294.084351,294.500488,0.000000
42.450001,65.101875,-1294.039795,-0.001841,0.001926,0.048930,289.587616,14.752295,0.489296,-1294.039795,294.500488,0.000000
42.740002,65.219917,-1294.084351,-0.001811,0.001930,0.049025,290.112671,14.779044,0.490250,-1294.084351,294.500488,0.000000
43.030003,65.265724,-1293.995361,-0.001811,0.001934,0.049128,290.316437,14.789425,0.491279,-1293.995361,294.500488,0.000000
43.320004,65.176720,-1294.084351,-0.001832,0.001937,0.049198,289.920532,14.769256,0.491976,-1294.084351,294.500488,0.000000
43.610001,65.372215,-1294.039795,-0.001828,0.001942,0.049319,290.790131,14.813556,0.493187,-1294.039795,294.500488,0.000000
43.900002,65.167046,-1294.039795,-0.001807,0.001943,0.049363,289.877502,14.767064,0.493626,-1294.039795,294.500488,0.000000
44.190002,65.136879,-1294.084351,-0.001807,0.001949,0.049493,289.743317,14.760228,0.494928,-1294.084351,294.500488,0.000000
44.480003,65.355843,-1293.950806,-0.001802,0.001951,0.049553,290.717316,14.809846,0.495534,-1293.950806,294.500488,0.000000
44.770000,65.170769,-1294.084351,-0.001815,0.001952,0.049588,289.894043,14.767907,0.495882,-1294.084351,294.500488,0.000000
45.060001,65.378181,-1293.995361,-0.001798,0.001957,0.049709,290.816681,14.814908,0.497093,-1293.995361,294.500488,0.000000
45.350002,65.245979,-1293.995361,-0.001802,0.001959,0.049753,290.228607,14.784950,0.497532,-1293.995361,294.500488,0.000000
45.640003,65.085487,-1294.039795,-0.001785,0.001959,0.049770,289.514709,14.748582,0.497699,-1294.039795,294.500488,0.000000
45.930000,65.759865,-1294.039795,-0.001794,0.001968,0.049995,292.514496,14.901399,0.499954,-1294.039795,294.500488,0.000000
46.220001,65.549843,-1294.084351,-0.001785,0.001968,0.049995,291.580261,14.853807,0.499954,-1294.084351,294.500488,0.000000
46.510002,65.282112,-1294.084351,-0.001785,0.001968,0.049995,290.389343,14.793138,0.499954,-1294.084351,294.500488,0.000000
46.800003,65.038200,-1294.039795,-0.001794,0.001968,0.049995,289.304352,14.737866,0.499954,-1294.039795,294.500488,0.000000
47.090004,64.792442,-1293.995361,-0.001763,0.001968,0.049995,288.211182,14.682177,0.499954,-1293.995361,294.500488,0.000000
47.380001,66.523964,-1294.039795,-0.001781,0.001966,0.049944,295.913361,15.074546,0.499440,-1294.039795,294.500488,0.000000
47.670002,66.162025,-1293.995361,-0.001772,0.001964,0.049892,294.303375,14.992530,0.498925,-1293.995361,294.500488,0.000000
47.960003,65.849236,-1293.950806,-0.001768,0.001964,0.049892,292.912018,14.921650,0.498925,-1293.950806,294.500488,0.000000
48.250004,65.594521,-1293.950806,-0.001763,0.001964,0.049892,291.778992,14.863931,0.498925,-1293.950806,294.500488,0.000000
48.540001,65.336098,-1294.084351,-0.001759,0.001974,0.050144,290.629486,14.805371,0.501438,-1294.084351,294.500488,0.000000
48.830002,65.158485,-1294.039795,-0.001763,0.001982,0.050351,289.839417,14.765123,0.503512,-1294.039795,294.500488,0.000000
49.120003,65.009163,-1294.039795,-0.001772,0.001984,0.050404,289.175201,14.731286,0.504042,-1294.039795,294.500488,0.000000
49.410004,65.484306,-1294.039795,-0.001772,0.001992,0.050603,291.288757,14.838956,0.506025,-1294.039795,294.500488,0.000000
49.700001,65.301476,-1294.039795,-0.001772,0.001992,0.050603,290.475464,14.797526,0.506025,-1294.039795,294.500488,0.000000
49.990002,65.174492,-1294.084351,-0.001763,0.001994,0.050637,289.910614,14.768751,0.506374,-1294.084351,294.500488,0.000000
50.280003,65.166664,-1293.995361,-0.001746,0.001995,0.050681,289.875793,14.766976,0.506813,-1293.995361,294.500488,0.000000
50.570004,65.056816,-1294.084351,-0.001763,0.001997,0.050716,289.387177,14.742085,0.507161,-1294.084351,294.500488,0.000000
50.860001,64.990166,-1294.084351,-0.001746,0.001998,0.050751,289.090698,14.726981,0.507509,-1294.084351,294.500488,0.000000
51.150002,65.289925,-1293.950806,-0.001750,0.002004,0.050898,290.424103,14.794909,0.508978,-1293.950806,294.500488,0.000000
51.440002,65.185295,-1293.995361,-0.001746,0.002004,0.050898,289.958679,14.771199,0.508978,-1293.995361,294.500488,0.000000
51.730003,65.027779,-1293.995361,-0.001742,0.002004,0.050898,289.257996,14.735505,0.508978,-1293.995361,294.500488,0.000000
52.020004,64.852760,-1294.039795,-0.001742,0.002004,0.050907,288.479492,14.695846,0.509068,-1294.039795,294.500488,0.000000
52.310001,66.103554,-1294.039795,-0.001733,0.002014,0.051149,294.043304,14.979279,0.511491,-1294.039795,294.500488,0.000000
52.600002,65.871193,-1293.950806,-0.001733,0.002013,0.051140,293.009705,14.926626,0.511400,-1293.950806,294.500488,0.000000
52.890003,65.667519,-1294.084351,-0.001738,0.002013,0.051140,292.103699,14.880472,0.511400,-1294.084351,294.500488,0.000000
53.180004,65.473885,-1293.995361,-0.001738,0.002013,0.051140,291.242371,14.836595,0.511400,-1293.995361,294.500488,0.000000
53.470001,65.270195,-1293.950806,-0.001725,0.002013,0.051140,290.336334,14.790438,0.511400,-1293.950806,294.500488,0.000000
53.760002,65.043037,-1293.995361,-0.001712,0.002014,0.051149,289.325867,14.738962,0.511491,-1293.995361,294.500488,0.000000
54.050003,66.020897,-1293.995361,-0.001738,0.002028,0.051514,293.675629,14.960549,0.515139,-1293.995361,294.500488,0.000000
54.340004,65.839546,-1294.084351,-0.001738,0.002024,0.051419,292.868927,14.919454,0.514186,-1294.084351,294.500488,0.000000
54.630001,65.616875,-1293.995361,-0.001707,0.002024,0.051419,291.878448,14.868996,0.514186,-1293.995361,294.500488,0.000000
54.920002,65.452278,-1294.039795,-0.001729,0.002024,0.051419,291.146271,14.831698,0.514186,-1294.039795,294.500488,0.000000
55.210003,65.257530,-1293.950806,-0.001707,0.002025,0.051426,290.279999,14.787567,0.514261,-1293.950806,294.500488,0.000000
55.500004,65.077293,-1294.039795,-0.001733,0.002028,0.051514,289.478271,14.746725,0.515139,-1294.039795,294.500488,0.000000
55.790001,65.446693,-1294.084351,-0.001738,0.002033,0.051635,291.121429,14.830433,0.516351,-1294.084351,294.500488,0.000000
56.080002,65.318230,-1294.039795,-0.001712,0.002033,0.051635,290.549988,14.801322,0.516351,-1294.039795,294.500488,0.000000
56.370003,65.200554,-1294.039795,-0.001729,0.002033,0.051644,290.026550,14.774657,0.516441,-1294.039795,294.500488,0.000000
56.660004,65.191612,-1294.039795,-0.001733,0.002036,0.051705,289.986786,14.772631,0.517047,-1294.039795,294.500488,0.000000
56.950005,65.272057,-1294.039795,-0.001720,0.002041,0.051842,290.344604,14.790859,0.518425,-1294.039795,294.500488,0.000000
57.240002,65.394936,-1294.084351,-0.001725,0.002041,0.051842,290.891205,14.818705,0.518425,-1294.084351,294.500488,0.000000
57.530003,65.292152,-1293.995361,-0.001712,0.002041,0.051842,290.433990,14.795413,0.518425,-1293.995361,294.500488,0.000000
57.820004,65.219917,-1294.084351,-0.001712,0.002042,0.051870,290.112671,14.779044,0.518697,-1294.084351,294.500488,0.000000
58.110004,65.111931,-1294.084351,-0.001716,0.002044,0.051921,289.632324,14.754575,0.519212,-1294.084351,294.500488,0.000000
58.400002,65.053841,-1294.039795,-0.001720,0.002044,0.051921,289.373932,14.741411,0.519212,-1294.039795,294.500488,0.000000
58.690002,65.553200,-1294.039795,-0.001707,0.002051,0.052103,291.595184,14.854568,0.521029,-1294.039795,294.500488,0.000000
58.980003,65.493248,-1294.039795,-0.001712,0.002051,0.052103,291.328522,14.840981,0.521029,-1294.039795,294.500488,0.000000
59.270004,65.353981,-1294.039795,-0.001712,0.002051,0.052103,290.709015,14.809423,0.521029,-1294.039795,294.500488,0.000000
59.560001,65.241524,-1294.039795,-0.001712,0.002052,0.052112,290.208801,14.783940,0.521119,-1294.039795,294.500488,0.000000
59.850002,65.143211,-1294.084351,-0.001694,0.002053,0.052138,289.771484,14.761663,0.521377,-1294.084351,294.500488,0.000000
60.140003,65.140602,-1294.084351,-0.001712,0.002054,0.052182,289.759857,14.761071,0.521816,-1294.084351,294.500488,0.000000
60.430004,65.249336,-1294.039795,-0.001694,0.002057,0.052251,290.243530,14.785711,0.522512,-1294.039795,294.500488,0.000000
60.720001,65.200188,-1294.039795,-0.001712,0.002057,0.052251,290.024933,14.774573,0.522512,-1294.039795,294.500488,0.000000
61.010002,65.347267,-1294.084351,-0.001694,0.002061,0.052354,290.679169,14.807902,0.523542,-1294.084351,294.500488,0.000000
61.300003,65.306679,-1294.084351,-0.001690,0.002061,0.052354,290.498627,14.798705,0.523542,-1294.084351,294.500488,0.000000
61.590004,65.275032,-1294.084351,-0.001699,0.002062,0.052381,290.357849,14.791533,0.523814,-1294.084351,294.500488,0.000000
61.880001,65.236671,-1294.084351,-0.001690,0.002063,0.052407,290.187195,14.782842,0.524072,-1294.084351,294.500488,0.000000
62.170002,65.208748,-1294.039795,-0.001694,0.002065,0.052442,290.062988,14.776513,0.524420,-1294.039795,294.500488,0.000000
62.460003,65.201668,-1294.128784,-0.001694,0.002066,0.052468,290.031494,14.774909,0.524677,-1294.128784,294.500488,0.000000
62.750004,65.121986,-1294.039795,-0.001681,0.002066,0.052477,289.677063,14.756853,0.524768,-1294.039795,294.500488,0.000000
63.040005,65.157738,-1294.128784,-0.001694,0.002068,0.052528,289.836090,14.764955,0.525283,-1294.128784,294.500488,0.000000
63.330002,65.199074,-1294.084351,-0.001690,0.002070,0.052580,290.019958,14.774321,0.525798,-1294.084351,294.500488,0.000000
63.620003,65.130547,-1294.128784,-0.001686,0.002071,0.052605,289.715149,14.758793,0.526055,-1294.128784,294.500488,0.000000
63.910004,65.153633,-1294.084351,-0.001690,0.002072,0.052640,289.817841,14.764025,0.526403,-1294.084351,294.500488,0.000000
64.200005,65.081764,-1294.084351,-0.001690,0.002073,0.052649,289.498138,14.747739,0.526494,-1294.084351,294.500488,0.000000
64.490005,65.440361,-1294.128784,-0.001673,0.002078,0.052780,291.093262,14.828998,0.527796,-1294.128784,294.500488,0.000000
64.780006,65.364021,-1294.084351,-0.001673,0.002078,0.052780,290.753693,14.811699,0.527796,-1294.084351,294.500488,0.000000
65.070000,65.268333,-1294.084351,-0.001686,0.002078,0.052780,290.328033,14.790016,0.527796,-1294.084351,294.500488,0.000000
65.360001,65.170769,-1294.128784,-0.001673,0.002078,0.052780,289.894043,14.767907,0.527796,-1294.128784,294.500488,0.000000
65.650002,65.397545,-1294.039795,-0.001677,0.002082,0.052893,290.902802,14.819296,0.528931,-1294.039795,294.500488,0.000000
65.940002,65.333488,-1294.128784,-0.001686,0.002082,0.052893,290.617859,14.804780,0.528931,-1294.128784,294.500488,0.000000
66.230003,65.227745,-1294.173218,-0.001677,0.002082,0.052893,290.147491,14.780818,0.528931,-1294.173218,294.500488,0.000000
66.520004,65.187523,-1294.039795,-0.001677,0.002089,0.053049,289.968597,14.771704,0.530491,-1294.039795,294.500488,0.000000
66.810005,65.527122,-1294.128784,-0.001673,0.002089,0.053057,291.479187,14.848658,0.530567,-1294.128784,294.500488,0.000000
67.100006,65.463829,-1294.084351,-0.001669,0.002089,0.053057,291.197662,14.834315,0.530567,-1294.084351,294.500488,0.000000
67.389999,65.340569,-1294.128784,-0.001664,0.002089,0.053057,290.649353,14.806384,0.530567,-1294.128784,294.500488,0.000000
67.680000,65.269066,-1294.084351,-0.001669,0.002089,0.053057,290.331299,14.790182,0.530567,-1294.084351,294.500488,0.000000
67.970001,65.154015,-1294.128784,-0.001660,0.002089,0.053057,289.819519,14.764111,0.530567,-1294.128784,294.500488,0.000000
68.260002,65.223274,-1294.128784,-0.001673,0.002091,0.053117,290.127625,14.779805,0.531172,-1294.128784,294.500488,0.000000
68.550003,65.291420,-1294.084351,-0.001656,0.002094,0.053196,290.430756,14.795248,0.531959,-1294.084351,294.500488,0.000000
68.840004,65.263115,-1294.128784,-0.001664,0.002094,0.053196,290.304840,14.788833,0.531959,-1294.128784,294.500488,0.000000
69.130005,65.211723,-1294.128784,-0.001660,0.002095,0.053205,290.076233,14.777188,0.532050,-1294.128784,294.500488,0.000000
69.420006,65.122734,-1294.084351,-0.001660,0.002095,0.053205,289.680389,14.757022,0.532050,-1294.084351,294.500488,0.000000
69.710007,65.311150,-1294.128784,-0.001664,0.002099,0.053308,290.518494,14.799718,0.533080,-1294.128784,294.500488,0.000000
70.000000,65.276894,-1294.128784,-0.001660,0.002099,0.053308,290.366119,14.791956,0.533080,-1294.128784,294.500488,0.000000
70.290001,65.179710,-1294.084351,-0.001660,0.002099,0.053308,289.933838,14.769934,0.533080,-1294.084351,294.500488,0.000000
70.580002,65.139854,-1294.128784,-0.001656,0.002103,0.053422,289.756531,14.760902,0.534215,-1294.128784,294.500488,0.000000
70.870003,65.371849,-1294.217773,-0.001656,0.002104,0.053431,290.788513,14.813473,0.534306,-1294.217773,294.500488,0.000000
71.160004,65.323433,-1294.217773,-0.001647,0.002104,0.053431,290.573151,14.802502,0.534306,-1294.217773,294.500488,0.000000
71.450005,65.218437,-1294.217773,-0.001638,0.002104,0.053438,290.106110,14.778709,0.534382,-1294.217773,294.500488,0.000000
71.740005,65.291786,-1294.173218,-0.001656,0.002106,0.053491,290.432373,14.795330,0.534912,-1294.173218,294.500488,0.000000
72.030006,65.228477,-1294.173218,-0.001643,0.002106,0.053491,290.150757,14.780985,0.534912,-1294.173218,294.500488,0.000000
72.320000,65.215828,-1294.128784,-0.001634,0.002107,0.053526,290.094482,14.778117,0.535260,-1294.128784,294.500488,0.000000
72.610001,65.131660,-1294.173218,-0.001643,0.002108,0.053534,289.720093,14.759045,0.535336,-1294.173218,294.500488,0.000000
72.900002,65.123848,-1294.173218,-0.001647,0.002109,0.053568,289.685333,14.757275,0.535684,-1294.173218,294.500488,0.000000
73.190002,65.174492,-1294.217773,-0.001647,0.002110,0.053594,289.910614,14.768751,0.535941,-1294.217773,294.500488,0.000000
73.480003,65.095924,-1294.217773,-0.001638,0.002110,0.053603,289.561127,14.750948,0.536032,-1294.217773,294.500488,0.000000
73.770004,65.036705,-1294.084351,-0.001643,0.002110,0.053603,289.297699,14.737528,0.536032,-1294.084351,294.500488,0.000000
74.060005,64.961861,-1294.262207,-0.001651,0.002111,0.053612,288.964783,14.720568,0.536123,-1294.262207,294.500488,0.000000
74.350006,64.942131,-1294.173218,-0.001651,0.002112,0.053638,288.877014,14.716098,0.536380,-1294.173218,294.500488,0.000000
74.640007,65.436272,-1294.128784,-0.001643,0.002120,0.053838,291.075073,14.828072,0.538379,-1294.128784,294.500488,0.000000
74.930000,65.401634,-1294.217773,-0.001630,0.002118,0.053794,290.920990,14.820223,0.537940,-1294.217773,294.500488,0.000000
75.220001,65.318977,-1294.128784,-0.001643,0.002118,0.053794,290.553314,14.801492,0.537940,-1294.128784,294.500488,0.000000
75.510002,65.283974,-1294.173218,-0.001651,0.002118,0.053803,290.397614,14.793560,0.538030,-1294.173218,294.500488,0.000000
75.800003,65.224388,-1294.217773,-0.001634,0.002118,0.053803,290.132568,14.780058,0.538030,-1294.217773,294.500488,0.000000
76.090004,65.175606,-1294.262207,-0.001638,0.002120,0.053838,289.915588,14.769003,0.538379,-1294.262207,294.500488,0.000000
76.380005,65.133904,-1294.217773,-0.001630,0.002121,0.053864,289.730072,14.759553,0.538636,-1294.217773,294.500488,0.000000
76.670006,65.115288,-1294.173218,-0.001634,0.002121,0.053873,289.647278,14.755335,0.538727,-1294.173218,294.500488,0.000000
76.960007,65.077675,-1294.217773,-0.001647,0.002122,0.053889,289.479950,14.746812,0.538893,-1294.217773,294.500488,0.000000
77.250000,65.011391,-1294.173218,-0.001617,0.002122,0.053889,289.185120,14.731791,0.538893,-1294.173218,294.500488,0.000000
77.540001,64.980492,-1294.262207,-0.001647,0.002122,0.053908,289.047668,14.724790,0.539075,-1294.262207,294.500488,0.000000
77.830002,64.932076,-1294.173218,-0.001643,0.002123,0.053924,288.832306,14.713819,0.539242,-1294.173218,294.500488,0.000000
78.120003,64.931709,-1294.128784,-0.001630,0.002124,0.053950,288.830658,14.713736,0.539499,-1294.128784,294.500488,0.000000
78.410004,64.902657,-1294.217773,-0.001643,0.002126,0.054003,288.701447,14.707152,0.540029,-1294.217773,294.500488,0.000000
78.700005,65.029259,-1294.217773,-0.001634,0.002127,0.054029,289.264587,14.735841,0.540286,-1294.217773,294.500488,0.000000
78.990005,65.001717,-1294.173218,-0.001630,0.002127,0.054029,289.142090,14.729600,0.540286,-1294.173218,294.500488,0.000000
79.280006,64.917931,-1294.217773,-0.001621,0.002127,0.054029,288.769379,14.710613,0.540286,-1294.217773,294.500488,0.000000
79.570007,65.561012,-1294.217773,-0.001634,0.002136,0.054263,291.629944,14.856339,0.542633,-1294.217773,294.500488,0.000000
79.860001,65.571068,-1294.217773,-0.001625,0.002136,0.054245,291.674683,14.858616,0.542451,-1294.217773,294.500488,0.000000
80.150002,65.549843,-1294.173218,-0.001621,0.002136,0.054245,291.580261,14.853807,0.542451,-1294.173218,294.500488,0.000000
80.440002,65.489525,-1294.173218,-0.001630,0.002136,0.054245,291.311951,14.840138,0.542451,-1294.173218,294.500488,0.000000
80.730003,65.406471,-1294.217773,-0.001625,0.002136,0.054245,290.942505,14.821319,0.542451,-1294.217773,294.500488,0.000000
81.020004,65.336098,-1294.128784,-0.001621,0.002136,0.054245,290.629486,14.805371,0.542451,-1294.128784,294.500488,0.000000
81.310005,65.295143,-1294.128784,-0.001625,0.002136,0.054254,290.447296,14.796091,0.542542,-1294.128784,294.500488,0.000000
81.600006,65.232948,-1294.128784,-0.001613,0.002136,0.054263,290.170654,14.781998,0.542633,-1294.128784,294.500488,0.000000
81.890007,65.186028,-1294.173218,-0.001621,0.002138,0.054297,289.961945,14.771365,0.542966,-1294.173218,294.500488,0.000000
82.180000,65.275780,-1294.217773,-0.001613,0.002142,0.054410,290.361176,14.791703,0.544101,-1294.217773,294.500488,0.000000
82.470001,65.439995,-1294.128784,-0.001613,0.002142,0.054410,291.091644,14.828915,0.544101,-1294.128784,294.500488,0.000000
82.760002,65.409081,-1294.128784,-0.001630,0.002142,0.054410,290.954132,14.821909,0.544101,-1294.128784,294.500488,0.000000
83.050003,65.339821,-1294.217773,-0.001604,0.002142,0.054410,290.646027,14.806215,0.544101,-1294.217773,294.500488,0.000000
83.340004,65.298485,-1294.128784,-0.001613,0.002142,0.054410,290.462158,14.796848,0.544101,-1294.128784,294.500488,0.000000
83.630005,65.233330,-1294.262207,-0.001621,0.002142,0.054410,290.172333,14.782084,0.544101,-1294.262207,294.500488,0.000000
83.920006,65.293282,-1294.128784,-0.001613,0.002146,0.054515,290.439026,14.795669,0.545146,-1294.128784,294.500488,0.000000
84.210007,65.380409,-1294.173218,-0.001621,0.002146,0.054515,290.826599,14.815413,0.545146,-1294.173218,294.500488,0.000000
84.500008,65.351738,-1294.217773,-0.001613,0.002146,0.054515,290.699036,14.808915,0.545146,-1294.217773,294.500488,0.000000
84.790001,65.295143,-1294.173218,-0.001608,0.002146,0.054515,290.447296,14.796091,0.545146,-1294.173218,294.500488,0.000000
85.080002,65.253059,-1294.217773,-0.001608,0.002147,0.054522,290.260101,14.786554,0.545222,-1294.217773,294.500488,0.000000
85.370003,65.208748,-1294.128784,-0.001595,0.002148,0.054549,290.062988,14.776513,0.545494,-1294.128784,294.500488,0.000000
85.660004,65.161461,-1294.173218,-0.001604,0.002148,0.054549,289.852661,14.765799,0.545494,-1294.173218,294.500488,0.000000
85.950005,65.292534,-1294.173218,-0.001608,0.002150,0.054618,290.435699,14.795500,0.546175,-1294.173218,294.500488,0.000000
86.240005,65.274666,-1294.128784,-0.001617,0.002150,0.054618,290.356201,14.791451,0.546175,-1294.128784,294.500488,0.000000
86.530006,65.219917,-1294.173218,-0.001604,0.002150,0.054618,290.112671,14.779044,0.546175,-1294.173218,294.500488,0.000000
86.820007,65.213219,-1294.173218,-0.001604,0.002152,0.054652,290.082886,14.777527,0.546524,-1294.173218,294.500488,0.000000
87.110001,65.190132,-1294.173218,-0.001625,0.002152,0.054652,289.980194,14.772295,0.546524,-1294.173218,294.500488,0.000000
87.400002,65.197212,-1294.217773,-0.001604,0.002152,0.054671,290.011688,14.773900,0.546705,-1294.217773,294.500488,0.000000
87.690002,65.159218,-1294.217773,-0.001591,0.002152,0.054671,289.842682,14.765290,0.546705,-1294.217773,294.500488,0.000000
87.980003,65.097038,-1294.217773,-0.001613,0.002152,0.054671,289.566101,14.751200,0.546705,-1294.217773,294.500488,0.000000
88.270004,65.343178,-1294.173218,-0.001595,0.002158,0.054801,290.660980,14.806976,0.548007,-1294.173218,294.500488,0.000000
88.560005,65.377800,-1294.217773,-0.001608,0.002158,0.054801,290.814972,14.814821,0.548007,-1294.217773,294.500488,0.000000
88.850006,65.344658,-1294.217773,-0.001591,0.002158,0.054801,290.667542,14.807311,0.548007,-1294.217773,294.500488,0.000000
89.140007,65.302589,-1294.173218,-0.001608,0.002158,0.054801,290.480438,14.797779,0.548007,-1294.173218,294.500488,0.000000
89.430008,65.260887,-1294.173218,-0.001587,0.002158,0.054801,290.294922,14.788328,0.548007,-1294.173218,294.500488,0.000000
89.720001,65.188271,-1294.173218,-0.001591,0.002158,0.054801,289.971924,14.771873,0.548007,-1294.173218,294.500488,0.000000
90.010002,65.158852,-1294.128784,-0.001600,0.002158,0.054808,289.841034,14.765207,0.548083,-1294.128784,294.500488,0.000000
90.300003,65.107094,-1294.262207,-0.001613,0.002159,0.054836,289.610809,14.753479,0.548356,-1294.262207,294.500488,0.000000
90.590004,65.121986,-1294.173218,-0.001600,0.002160,0.054852,289.677063,14.756853,0.548522,-1294.173218,294.500488,0.000000
90.880005,65.102623,-1294.262207,-0.001595,0.002160,0.054870,289.590942,14.752465,0.548704,-1294.262207,294.500488,0.000000
91.170006,65.059059,-1294.173218,-0.001608,0.002160,0.054870,289.397156,14.742594,0.548704,-1294.173218,294.500488,0.000000
91.460007,65.030006,-1294.173218,-0.001591,0.002160,0.054870,289.267914,14.736011,0.548704,-1294.173218,294.500488,0.000000
91.750008,64.995384,-1294.217773,-0.001591,0.002161,0.054878,289.113922,14.728165,0.548779,-1294.217773,294.500488,0.000000
92.040001,65.130928,-1294.128784,-0.001587,0.002164,0.054957,289.716827,14.758880,0.549567,-1294.128784,294.500488,0.000000
92.330002,65.118629,-1294.128784,-0.001600,0.002164,0.054957,289.662140,14.756093,0.549567,-1294.128784,294.500488,0.000000
92.620003,65.085487,-1294.173218,-0.001578,0.002164,0.054957,289.514709,14.748582,0.549567,-1294.173218,294.500488,0.000000
92.910004,65.019218,-1294.084351,-0.001604,0.002164,0.054966,289.219940,14.733565,0.549658,-1294.084351,294.500488,0.000000
93.200005,65.041176,-1294.173218,-0.001600,0.002165,0.054982,289.317596,14.738542,0.549824,-1294.173218,294.500488,0.000000
93.490005,64.996498,-1294.084351,-0.001587,0.002165,0.054999,289.118866,14.728416,0.549991,-1294.084351,294.500488,0.000000
93.780006,65.027031,-1294.217773,-0.001595,0.002166,0.055017,289.254669,14.735335,0.550172,-1294.217773,294.500488,0.000000
94.070007,65.005806,-1294.128784,-0.001595,0.002166,0.055017,289.160278,14.730526,0.550172,-1294.128784,294.500488,0.000000
94.360008,65.118629,-1294.173218,-0.001600,0.002170,0.055113,289.662140,14.756093,0.551126,-1294.173218,294.500488,0.000000
94.650002,65.176720,-1294.173218,-0.001587,0.002170,0.055113,289.920532,14.769256,0.551126,-1294.173218,1681.640991,0.000000
94.940002,65.089211,-1294.173218,-0.001578,0.002163,0.054931,289.531281,14.749426,0.549309,-1294.173218,0.055017,0.000000
95.230003,64.919044,-1294.173218,-0.001591,0.002155,0.054748,288.774323,14.710866,0.547477,-1294.173218,0.054531,0.000000
95.520004,64.844566,-1294.217773,-0.001574,0.002142,0.054401,288.443024,14.693989,0.544011,-1294.217773,0.054045,0.000000
95.810005,64.705299,-1294.128784,-0.001578,0.002128,0.054054,287.823547,14.662431,0.540544,-1294.128784,0.053561,0.000000
96.100006,64.610725,-1294.173218,-0.001578,0.002104,0.053447,287.402863,14.641000,0.534473,-1294.173218,0.053084,0.000000
96.390007,64.495277,-1294.173218,-0.001561,0.002090,0.053075,286.889313,14.614839,0.530748,-1294.173218,0.052598,0.000000
96.680008,64.433846,-1294.173218,-0.001574,0.002070,0.052572,286.616058,14.600918,0.525722,-1294.173218,0.052112,0.000000
96.970001,64.354530,-1294.217773,-0.001569,0.002052,0.052129,286.263245,14.582945,0.521286,-1294.217773,0.051635,0.000000
97.260002,64.309471,-1294.173218,-0.001569,0.002036,0.051712,286.062805,14.572735,0.517123,-1294.173218,0.051149,0.000000
97.550003,64.181374,-1294.217773,-0.001578,0.002016,0.051219,285.493011,14.543708,0.512187,-1294.217773,0.050663,0.000000
97.840004,64.169090,-1294.128784,-0.001565,0.002001,0.050837,285.438354,14.540924,0.508372,-1294.128784,0.050179,0.000000
98.130005,64.023109,-1294.173218,-0.001565,0.001979,0.050274,284.789001,14.507844,0.502740,-1294.173218,0.049702,0.000000
98.420006,63.929283,-1294.262207,-0.001574,0.001965,0.049918,284.371643,14.486583,0.499182,-1294.262207,0.049216,0.000000
98.710007,63.647392,-1294.128784,-0.001574,0.001944,0.049388,283.117737,14.422705,0.493883,-1294.128784,0.048730,0.000000
99.000008,63.218788,-1294.173218,-0.001565,0.001929,0.048999,281.211212,14.325583,0.489992,-1294.173218,0.048244,0.000000
99.290001,62.721298,-1294.217773,-0.001548,0.001914,0.048609,278.998260,14.212850,0.486086,-1294.217773,0.047767,0.000000
99.580002,61.695045,-1294.128784,-0.001556,0.001890,0.048018,274.433258,13.980297,0.480182,-1294.128784,0.047281,0.000000
99.870003,60.874336,-1294.173218,-0.001556,0.001873,0.047585,270.782562,13.794322,0.475852,-1294.173218,0.046796,0.000000
100.160004,59.703224,-1294.128784,-0.001548,0.001854,0.047090,265.573212,13.528944,0.470901,-1294.128784,0.046310,0.000000
100.450005,59.037422,-1294.217773,-0.001556,0.001841,0.046769,262.611572,13.378071,0.467692,-1294.217773,0.045834,0.000000
100.740005,57.716614,-1294.217773,-0.001552,0.001823,0.046310,256.736328,13.078772,0.463105,-1294.217773,0.045348,0.000000
101.030006,56.397301,-1294.128784,-0.001535,0.001804,0.045824,250.867722,12.779811,0.458245,-1294.128784,0.044862,0.000000
101.320007,54.993828,-1294.217773,-0.001561,0.001788,0.045426,244.624771,12.461780,0.454263,-1294.217773,0.044376,0.000000
101.610008,53.177765,-1294.173218,-0.001552,0.001766,0.044853,236.546509,12.050254,0.448525,-1294.173218,0.043899,0.000000
101.900002,51.811157,-1294.217773,-0.001574,0.001749,0.044429,230.467545,11.740576,0.444286,-1294.217773,0.043414,0.000000
102.190002,49.845406,-1294.173218,-0.001548,0.001729,0.043908,221.723434,11.295130,0.439078,-1294.173218,0.042928,0.000000
102.480003,48.237877,-1294.217773,-0.001535,0.001713,0.043517,214.572800,10.930859,0.435172,-1294.217773,0.042451,0.000000
102.770004,46.694389,-1294.128784,-0.001561,0.001699,0.043154,207.707016,10.581100,0.431539,-1294.128784,0.041965,0.000000
103.060005,44.641129,-1294.173218,-0.001565,0.001680,0.042677,198.573654,10.115825,0.426770,-1294.173218,0.041479,0.000000
103.350006,42.146233,-1294.128784,-0.001582,0.001655,0.042035,187.475800,9.550472,0.420350,-1294.128784,0.040993,0.000000
103.640007,39.852043,-1294.217773,-0.001578,0.001634,0.041498,177.270737,9.030602,0.414976,-1294.217773,0.040517,0.000000
103.930008,38.339096,-1294.084351,-0.001574,0.001618,0.041107,170.540817,8.687763,0.411070,-1294.084351,0.040032,0.000000
104.220001,35.881439,-1294.217773,-0.001582,0.001594,0.040482,159.608612,8.130850,0.404817,-1294.217773,0.039546,0.000000
104.510002,34.583717,-1294.173218,-0.001582,0.001581,0.040162,153.836060,7.836782,0.401623,-1294.173218,0.039060,0.000000
104.800003,33.018639,-1294.173218,-0.001574,0.001565,0.039763,146.874237,7.482130,0.397626,-1294.173218,0.038583,0.000000
105.090004,30.824623,-1294.262207,-0.001587,0.001545,0.039251,137.114777,6.984960,0.392509,-1294.262207,0.038097,0.000000
105.380005,29.515732,-1294.128784,-0.001600,0.001533,0.038948,131.292526,6.688361,0.389481,-1294.128784,0.037611,0.000000
105.670006,26.838371,-1294.173218,-0.001591,0.001505,0.038237,119.383041,6.081662,0.382365,-1294.173218,0.037127,0.000000
105.960007,25.039444,-1294.128784,-0.001587,0.001487,0.037776,111.381012,5.674019,0.377763,-1294.128784,0.036650,0.000000
106.250008,22.606361,-1294.217773,-0.001604,0.001464,0.037187,100.558121,5.122675,0.371873,-1294.217773,0.036164,0.000000
106.540009,20.970154,-1294.173218,-0.001613,0.001447,0.036753,93.279900,4.751905,0.367528,-1294.173218,0.035678,0.000000
106.830002,19.089676,-1294.173218,-0.001613,0.001427,0.036250,84.915123,4.325782,0.362502,-1294.173218,0.035192,0.000000
107.120003,16.545250,-1294.173218,-0.001621,0.001404,0.035669,73.596947,3.749207,0.356688,-1294.173218,0.034715,0.000000
107.410004,14.653976,-1294.128784,-0.001617,0.001386,0.035210,65.184143,3.320639,0.352101,-1294.128784,0.034229,0.000000
107.700005,13.206192,-1294.084351,-0.001634,0.001372,0.034854,58.744076,2.992566,0.348543,-1294.084351,0.033745,0.000000
107.990005,10.863968,-1294.262207,-0.001630,0.001348,0.034247,48.325344,2.461810,0.342472,-1294.262207,0.033268,0.000000
108.280006,10.048843,-1294.173218,-0.001638,0.001340,0.034038,44.699490,2.277101,0.340383,-1294.173218,0.032782,0.000000
108.570007,7.695450,-1294.128784,-0.001647,0.001315,0.033405,34.231071,1.743814,0.334055,-1294.128784,0.032296,0.000000
108.860008,5.592659,-1294.173218,-0.001638,0.001295,0.032886,24.877390,1.267315,0.328862,-1294.173218,0.031810,0.000000
109.150002,4.046944,-1294.084351,-0.001643,0.001277,0.032443,18.001705,0.917051,0.324426,-1294.084351,0.031333,0.000000
109.440002,1.667854,-1294.173218,-0.001647,0.001252,0.031810,7.418986,0.377941,0.318098,-1294.173218,0.030847,0.000000
109.730003,0.336624,-1294.128784,-0.001660,0.001237,0.031419,1.497379,0.076280,0.314192,-1294.128784,0.030362,0.000000
110.020004,-1.868565,-1294.262207,-0.001673,0.001212,0.030795,-8.311790,-0.423423,0.307954,-1294.262207,0.029876,0.000000
110.310005,-2.990894,-1294.217773,-0.001673,0.001199,0.030458,-13.304162,-0.677746,0.304578,-1294.217773,0.029400,0.000000
110.600006,-4.031303,-1294.173218,-0.001681,0.001186,0.030128,-17.932133,-0.913506,0.301278,-1294.173218,0.028914,0.000000
110.890007,-0.024574,-1294.173218,-0.001755,0.001160,0.029460,-0.109312,-0.005569,0.294601,-1294.173218,0.028428,0.000000
111.180008,-0.038727,-1294.173218,-0.001776,0.001139,0.028930,-0.172265,-0.008776,0.289302,-1294.173218,0.027942,0.000000
111.470009,-0.036118,-1294.173218,-0.001794,0.001120,0.028446,-0.160659,-0.008184,0.284458,-1294.173218,0.027465,0.000000
111.760002,-0.036865,-1294.262207,-0.001811,0.001096,0.027830,-0.163985,-0.008354,0.278296,-1294.262207,0.026980,0.000000
112.050003,-0.039474,-1294.128784,-0.001832,0.001083,0.027518,-0.175591,-0.008945,0.275177,-1294.128784,0.026494,0.000000
112.340004,-0.034256,-1294.217773,-0.001858,0.001065,0.027057,-0.152378,-0.007763,0.270575,-1294.217773,0.026008,0.000000
112.630005,-0.026436,-1294.084351,-0.001863,0.001054,0.026762,-0.117593,-0.005990,0.267622,-1294.084351,0.025531,0.000000
112.920006,-0.010796,-1294.128784,-0.001906,0.001031,0.026182,-0.048021,-0.002446,0.261824,-1294.128784,0.025045,0.000000
113.210007,-0.022713,-1294.217773,-0.001927,0.001008,0.025601,-0.101031,-0.005147,0.256010,-1294.217773,0.024559,0.000000
113.500008,-0.021599,-1294.128784,-0.001949,0.000988,0.025089,-0.096076,-0.004894,0.250893,-1294.128784,0.024083,0.000000
113.790009,-0.029793,-1294.262207,-0.001962,0.000969,0.024603,-0.132525,-0.006751,0.246033,-1294.262207,0.023598,0.000000
114.080002,-0.007072,-1294.173218,-0.001983,0.000955,0.024248,-0.031460,-0.001603,0.242476,-1294.173218,0.023112,0.000000
114.370003,-0.016388,-1294.128784,-0.001996,0.000942,0.023919,-0.072897,-0.003714,0.239190,-1294.128784,0.022626,0.000000
114.660004,-0.012291,-1294.262207,-0.002018,0.000923,0.023442,-0.054673,-0.002785,0.234421,-1294.262207,0.022149,0.000000
114.800003,0.010796,-1294.173218,-0.002031,0.000917,0.023294,0.048021,0.002446,0.232938,-1294.173218,0.023224,0.000000