File: Data/Sima compression/P1-15-3_10302024_170745.csv
Time (sec),S:Load (lbs),S:HL1 (DIM),S:LVDT (in),S:Position (in),Ch:Position (mm),Ch:Load (N),Ch:Stress (MPa),Ch:Strain (mm/mm),Ch:HL1 (DIM),Set Point (),Cycles ()
0.110000,-0.004471,-1293.861938,-0.007791,-0.004782,-0.121472,-0.019887,-0.001013,-1.214724,-1293.861938,-0.121273,0.000000
0.440000,0.010429,-1293.817383,-0.007800,-0.004767,-0.121074,0.046392,0.002363,-1.210742,-1293.817383,-0.120405,0.000000
0.770000,-0.066658,-1293.817383,-0.007726,-0.004567,-0.115992,-0.296510,-0.015105,-1.159919,-1293.817383,-0.114908,0.000000
1.100000,-0.005211,-1293.728516,-0.007502,-0.004345,-0.110354,-0.023179,-0.001181,-1.103539,-1293.728516,-0.109409,0.000000
1.430000,0.033142,-1293.817383,-0.007269,-0.004139,-0.105134,0.147423,0.007510,-1.051338,-1293.817383,-0.103929,0.000000
1.760000,-0.007072,-1293.861938,-0.007049,-0.003914,-0.099410,-0.031460,-0.001603,-0.994095,-1293.861938,-0.098430,0.000000
2.090000,-0.006706,-1293.772949,-0.006847,-0.003701,-0.094017,-0.029831,-0.001520,-0.940168,-1293.772949,-0.092931,0.000000
2.420000,-0.002975,-1293.817383,-0.006627,-0.003496,-0.088804,-0.013236,-0.000674,-0.888042,-1293.817383,-0.087434,0.000000
2.750000,-0.008934,-1293.772949,-0.006390,-0.003270,-0.083063,-0.039741,-0.002024,-0.830633,-1293.772949,-0.081935,0.000000
3.080000,-0.101654,-1293.817383,-0.006178,-0.003054,-0.077565,-0.452180,-0.023035,-0.775646,-1293.817383,-0.076437,0.000000
3.410000,0.012657,-1293.772949,-0.005963,-0.002835,-0.071998,0.056302,0.002868,-0.719978,-1293.772949,-0.070940,0.000000
3.740000,0.039474,-1293.861938,-0.005730,-0.002621,-0.066569,0.175591,0.008945,-0.665687,-1293.861938,-0.065441,0.000000
4.070000,0.012291,-1293.817383,-0.005510,-0.002404,-0.061053,0.054673,0.002785,-0.610534,-1293.817383,-0.059942,0.000000
4.400000,0.010429,-1293.772949,-0.005277,-0.002185,-0.055494,0.046392,0.002363,-0.554941,-1293.772949,-0.054445,0.000000
4.730000,0.012657,-1293.861938,-0.005057,-0.001978,-0.050247,0.056302,0.002868,-0.502468,-1293.861938,-0.048946,0.000000
5.060000,-0.007072,-1293.772949,-0.004825,-0.001752,-0.044506,-0.031460,-0.001603,-0.445058,-1293.772949,-0.043448,0.000000
5.390000,-0.054741,-1293.861938,-0.004605,-0.001536,-0.039025,-0.243500,-0.012404,-0.390253,-1293.861938,-0.037950,0.000000
5.720000,0.016014,-1293.772949,-0.004385,-0.001325,-0.033649,0.071234,0.003629,-0.336492,-1293.772949,-0.032452,0.000000
6.050000,0.016388,-1293.772949,-0.004165,-0.001101,-0.027960,0.072897,0.003714,-0.279598,-1293.772949,-0.026953,0.000000
6.380000,0.022339,-1293.772949,-0.003945,-0.000891,-0.022626,0.099368,0.005062,-0.226261,-1293.772949,-0.021456,0.000000
6.710001,-0.001114,-1293.817383,-0.003729,-0.000672,-0.017067,-0.004955,-0.000252,-0.170668,-1293.817383,-0.015957,0.000000
7.040000,0.019737,-1293.772949,-0.003505,-0.000459,-0.011647,0.087796,0.004473,-0.116469,-1293.772949,-0.010458,0.000000
7.370000,-0.056229,-1293.817383,-0.003281,-0.000239,-0.006071,-0.250117,-0.012742,-0.060710,-1293.817383,-0.004961,0.000000
7.700000,0.071121,-1293.728516,-0.003048,-0.000020,-0.000503,0.316363,0.016116,-0.005026,-1293.728516,0.000537,0.000000
8.030001,0.065910,-1293.817383,-0.003022,0.000004,0.000095,0.293184,0.014935,0.000954,-1293.817383,0.000329,0.000000
8.360001,0.182838,-1293.817383,-0.003027,0.000004,0.000095,0.813306,0.041432,0.000954,-1293.817383,0.000424,0.000000
8.690001,0.150063,-1293.772949,-0.003031,0.000004,0.000095,0.667512,0.034005,0.000954,-1293.772949,0.000980,0.000000
9.020000,0.229752,-1293.772949,-0.003018,0.000023,0.000580,1.021986,0.052062,0.005798,-1293.772949,0.001526,0.000000
9.350000,0.513504,-1293.817383,-0.003005,0.000048,0.001222,2.284180,0.116362,0.012218,-1293.817383,0.002080,0.000000
9.680000,0.688515,-1293.817383,-0.002984,0.000062,0.001578,3.062666,0.156020,0.015775,-1293.817383,0.002627,0.000000
10.010000,1.290268,-1293.772949,-0.002962,0.000092,0.002333,5.739398,0.292379,0.023330,-1293.772949,0.003173,0.000000
10.340000,1.793716,-1293.817383,-0.002958,0.000112,0.002852,7.978849,0.406462,0.028523,-1293.817383,0.003729,0.000000
10.670000,2.274452,-1293.728516,-0.002932,0.000131,0.003338,10.117269,0.515398,0.033383,-1293.728516,0.004275,0.000000
11.000001,3.038933,-1293.861938,-0.002910,0.000155,0.003929,13.517848,0.688632,0.039287,-1293.861938,0.004830,0.000000
11.330001,3.778091,-1293.817383,-0.002902,0.000176,0.004483,16.805790,0.856128,0.044828,-1293.817383,0.005376,0.000000
11.660001,4.451340,-1293.817383,-0.002889,0.000195,0.004951,19.800549,1.008688,0.049506,-1293.817383,0.005932,0.000000
11.990001,5.484673,-1293.728516,-0.002863,0.000220,0.005585,24.397041,1.242845,0.055850,-1293.728516,0.006478,0.000000
12.320001,6.340012,-1293.772949,-0.002846,0.000243,0.006174,28.201780,1.436667,0.061739,-1293.772949,0.007025,0.000000
12.650001,6.977516,-1293.817383,-0.002824,0.000263,0.006669,31.037542,1.581128,0.066690,-1293.817383,0.007579,0.000000
12.980000,7.965416,-1293.861938,-0.002828,0.000286,0.007258,35.431938,1.804989,0.072579,-1293.861938,0.008125,0.000000
13.310000,9.122383,-1293.817383,-0.002820,0.000310,0.007865,40.578388,2.067162,0.078650,-1293.817383,0.008681,0.000000
13.640000,9.683922,-1293.772949,-0.002798,0.000323,0.008212,43.076237,2.194408,0.082117,-1293.772949,0.009226,0.000000
13.970000,10.927643,-1293.728516,-0.002777,0.000348,0.008845,48.608582,2.476239,0.088445,-1293.728516,0.009782,0.000000
14.300001,11.763992,-1293.817383,-0.002764,0.000370,0.009391,52.328850,2.665759,0.093911,-1293.817383,0.010328,0.000000
14.630001,12.747429,-1293.861938,-0.002751,0.000393,0.009972,56.703396,2.888609,0.099724,-1293.861938,0.010875,0.000000
14.960001,13.820229,-1293.817383,-0.002729,0.000417,0.010589,61.475449,3.131709,0.105886,-1293.817383,0.011429,0.000000
15.290001,14.633865,-1293.772949,-0.002729,0.000436,0.011075,65.094681,3.316081,0.110746,-1293.772949,0.011975,0.000000
15.620001,15.169334,-1293.772949,-0.002712,0.000451,0.011447,67.476570,3.437420,0.114470,-1293.772949,0.012531,0.000000
15.950001,16.534828,-1293.817383,-0.002686,0.000478,0.012131,73.550591,3.746845,0.121313,-1293.817383,0.013078,0.000000
16.280001,17.443787,-1293.817383,-0.002686,0.000499,0.012687,77.593842,3.952818,0.126870,-1293.817383,0.013632,0.000000
16.610001,18.206032,-1293.817383,-0.002669,0.000519,0.013190,80.984474,4.125546,0.131896,-1293.817383,0.014178,0.000000
16.940001,19.181648,-1293.817383,-0.002656,0.000543,0.013797,85.324234,4.346623,0.137967,-1293.817383,0.014725,0.000000
17.270000,20.251106,-1293.817383,-0.002647,0.000566,0.014378,90.081421,4.588966,0.143781,-1293.817383,0.015280,0.000000
17.600000,20.504318,-1293.861938,-0.002643,0.000579,0.014716,91.207764,4.646345,0.147157,-1293.861938,0.015827,0.000000
17.930000,21.639679,-1293.817383,-0.002621,0.000607,0.015411,96.258102,4.903622,0.154106,-1293.817383,0.016381,0.000000
18.260000,22.797012,-1293.861938,-0.002604,0.000633,0.016069,101.406174,5.165877,0.160691,-1293.861938,0.016928,0.000000
18.590000,23.233810,-1293.817383,-0.002591,0.000651,0.016529,103.349152,5.264857,0.165294,-1293.817383,0.017483,0.000000
18.920000,24.150215,-1293.772949,-0.002578,0.000671,0.017049,107.425522,5.472517,0.170487,-1293.772949,0.018030,0.000000
19.250000,24.862190,-1293.906372,-0.002544,0.000692,0.017586,110.592545,5.633852,0.175861,-1293.906372,0.018575,0.000000
19.580002,25.056946,-1293.861938,-0.002535,0.000706,0.017942,111.458862,5.677985,0.179419,-1293.861938,0.019130,0.000000
19.910002,26.445145,-1293.772949,-0.002509,0.000738,0.018740,117.633881,5.992555,0.187398,-1293.772949,0.019677,0.000000
20.240002,27.204041,-1293.817383,-0.002518,0.000761,0.019330,121.009613,6.164524,0.193302,-1293.817383,0.020233,0.000000
20.570002,27.662804,-1293.817383,-0.002492,0.000780,0.019824,123.050293,6.268481,0.198238,-1293.817383,0.020778,0.000000
20.900002,28.161041,-1293.861938,-0.002483,0.000802,0.020363,125.266571,6.381383,0.203627,-1293.861938,0.021333,0.000000
21.230001,29.098671,-1293.861938,-0.002466,0.000826,0.020986,129.437347,6.593853,0.209865,-1293.861938,0.021880,0.000000
21.560001,28.759445,-1293.772949,-0.002453,0.000835,0.021203,127.928398,6.516984,0.212030,-1293.772949,0.022426,0.000000
21.890001,30.473473,-1293.817383,-0.002427,0.000872,0.022140,135.552780,6.905388,0.221401,-1293.817383,0.022980,0.000000
22.220001,30.491348,-1293.817383,-0.002423,0.000890,0.022617,135.632294,6.909438,0.226170,-1293.817383,0.023527,0.000000
22.550001,30.965752,-1293.817383,-0.002397,0.000911,0.023129,137.742538,7.016940,0.231287,-1293.817383,0.024083,0.000000
22.880001,31.630432,-1293.861938,-0.002363,0.000932,0.023683,140.699188,7.167558,0.236828,-1293.861938,0.024629,0.000000
23.210001,31.553726,-1293.772949,-0.002367,0.000945,0.024004,140.357986,7.150177,0.240038,-1293.772949,0.025176,0.000000
23.540001,32.482796,-1293.683960,-0.002350,0.000975,0.024776,144.490692,7.360707,0.247759,-1293.683960,0.025730,0.000000
23.870001,33.414101,-1293.861938,-0.002333,0.000999,0.025383,148.633347,7.571743,0.253830,-1293.861938,0.026276,0.000000
24.200001,33.620018,-1293.817383,-0.002324,0.001020,0.025904,149.549316,7.618405,0.259038,-1293.817383,0.026832,0.000000
24.530001,33.775673,-1293.772949,-0.002311,0.001040,0.026425,150.241699,7.653677,0.264246,-1293.772949,0.027378,0.000000
24.860001,34.446686,-1293.861938,-0.002298,0.001064,0.027014,153.226517,7.805731,0.270136,-1293.861938,0.027933,0.000000
25.190001,34.507385,-1293.817383,-0.002281,0.001084,0.027542,153.496521,7.819485,0.275419,-1293.817383,0.028479,0.000000
25.520000,34.892792,-1293.861938,-0.002259,0.001103,0.028020,155.210892,7.906820,0.280203,-1293.861938,0.029026,0.000000
25.850000,35.948090,-1293.772949,-0.002229,0.001130,0.028696,159.905090,8.145953,0.286956,-1293.772949,0.029581,0.000000
26.180000,36.034859,-1293.817383,-0.002225,0.001150,0.029207,160.291061,8.165615,0.292073,-1293.817383,0.030126,0.000000
26.510002,36.286209,-1293.772949,-0.002216,0.001170,0.029711,161.409119,8.222572,0.297114,-1293.772949,0.030682,0.000000
26.840002,36.804550,-1293.772949,-0.002203,0.001190,0.030214,163.714813,8.340031,0.302141,-1293.772949,0.031228,0.000000
27.170002,36.575539,-1293.772949,-0.002177,0.001206,0.030638,162.696121,8.288136,0.306380,-1293.772949,0.031784,0.000000
27.500002,37.604408,-1293.861938,-0.002173,0.001234,0.031340,167.272766,8.521281,0.313404,-1293.861938,0.032329,0.000000
27.830002,38.435165,-1293.861938,-0.002160,0.001258,0.031966,170.968155,8.709533,0.319657,-1293.861938,0.032876,0.000000
28.160002,38.519699,-1293.817383,-0.002139,0.001277,0.032424,171.344177,8.728688,0.324244,-1293.817383,0.033431,0.000000
28.490002,38.916275,-1293.728516,-0.002121,0.001300,0.033015,173.108231,8.818554,0.330149,-1293.728516,0.033978,0.000000
28.820002,39.651711,-1293.772949,-0.002108,0.001323,0.033596,176.379623,8.985207,0.335962,-1293.772949,0.034532,0.000000
29.150002,39.500526,-1293.906372,-0.002095,0.001339,0.034013,175.707123,8.950947,0.340126,-1293.906372,0.035078,0.000000
29.480001,40.095947,-1293.772949,-0.002082,0.001367,0.034723,178.355682,9.085872,0.347226,-1293.772949,0.035634,0.000000
29.810001,40.880539,-1293.772949,-0.002065,0.001387,0.035234,181.845718,9.263663,0.352343,-1293.772949,0.036181,0.000000
30.140001,41.167641,-1293.817383,-0.002061,0.001406,0.035711,183.122818,9.328721,0.357112,-1293.817383,0.036727,0.000000
30.470001,42.032661,-1293.817383,-0.002035,0.001433,0.036388,186.970612,9.524737,0.363880,-1293.817383,0.037281,0.000000
30.800001,42.232254,-1293.861938,-0.002018,0.001451,0.036848,187.858444,9.569965,0.368482,-1293.861938,0.037828,0.000000
31.130001,42.276566,-1293.772949,-0.002013,0.001467,0.037255,188.055557,9.580007,0.372555,-1293.772949,0.038383,0.000000
31.460001,43.457726,-1293.728516,-0.001988,0.001498,0.038044,193.309616,9.847662,0.380443,-1293.728516,0.038930,0.000000
31.790001,43.876648,-1293.728516,-0.001970,0.001518,0.038565,195.173080,9.942590,0.385651,-1293.728516,0.039484,0.000000
32.120003,43.942184,-1293.861938,-0.001962,0.001535,0.038998,195.464600,9.957441,0.389980,-1293.861938,0.040031,0.000000
32.450001,44.896202,-1293.817383,-0.001966,0.001562,0.039666,199.708282,10.173625,0.396657,-1293.817383,0.040577,0.000000
32.780003,45.410820,-1293.817383,-0.001953,0.001581,0.040170,201.997421,10.290239,0.401698,-1293.817383,0.041133,0.000000
33.110001,45.475990,-1293.728516,-0.001936,0.001600,0.040629,202.287308,10.305007,0.406286,-1293.728516,0.041678,0.000000
33.440002,46.870148,-1293.772949,-0.001914,0.001628,0.041349,208.488831,10.620928,0.413492,-1293.772949,0.042233,0.000000
33.770000,47.207893,-1293.772949,-0.001897,0.001647,0.041843,209.991196,10.697462,0.418428,-1293.772949,0.042780,0.000000
34.100002,47.668892,-1293.861938,-0.001893,0.001666,0.042320,212.041824,10.801926,0.423197,-1293.861938,0.043326,0.000000
34.430000,48.368950,-1293.861938,-0.001880,0.001692,0.042971,215.155838,10.960561,0.429707,-1293.861938,0.043881,0.000000
34.760002,49.118538,-1293.772949,-0.001876,0.001709,0.043413,218.490173,11.130420,0.434127,-1293.772949,0.044427,0.000000
35.090000,49.276794,-1293.772949,-0.001837,0.001725,0.043820,219.194122,11.166281,0.438200,-1293.772949,0.044983,0.000000
35.420002,50.678406,-1293.772949,-0.001850,0.001756,0.044592,225.428802,11.483891,0.445921,-1293.772949,0.045529,0.000000
35.750000,51.197121,-1293.772949,-0.001837,0.001776,0.045113,227.736160,11.601433,0.451129,-1293.772949,0.046083,0.000000
36.080002,51.906113,-1293.772949,-0.001819,0.001794,0.045564,230.889923,11.762093,0.455641,-1293.772949,0.046630,0.000000
36.410000,53.235115,-1293.728516,-0.001802,0.001821,0.046257,236.801620,12.063250,0.462575,-1293.728516,0.047176,0.000000
36.740002,53.479019,-1293.728516,-0.001798,0.001837,0.046665,237.886551,12.118519,0.466647,-1293.728516,0.047732,0.000000
37.070004,53.837608,-1293.817383,-0.001789,0.001855,0.047107,239.481644,12.199777,0.471068,-1293.817383,0.048279,0.000000
37.400002,55.403809,-1293.906372,-0.001772,0.001884,0.047862,246.448456,12.554683,0.478623,-1293.906372,0.048833,0.000000
37.730003,56.174995,-1293.861938,-0.001755,0.001905,0.048391,249.878860,12.729436,0.483906,-1293.861938,0.049379,0.000000
38.060001,56.819939,-1293.772949,-0.001755,0.001927,0.048946,252.747711,12.875582,0.489463,-1293.772949,0.049935,0.000000
38.390003,58.008553,-1293.817383,-0.001742,0.001952,0.049579,258.034943,13.144926,0.495791,-1293.817383,0.050481,0.000000
38.720001,58.688507,-1293.817383,-0.001712,0.001971,0.050073,261.059509,13.299006,0.500726,-1293.817383,0.051026,0.000000
39.050003,58.258789,-1293.817383,-0.001712,0.001980,0.050282,259.148041,13.201631,0.502816,-1293.817383,0.051582,0.000000
39.380001,60.355988,-1293.772949,-0.001712,0.002014,0.051157,268.476837,13.676863,0.511566,-1293.772949,0.052129,0.000000
39.710003,61.256386,-1293.772949,-0.001694,0.002036,0.051712,272.482025,13.880896,0.517123,-1293.772949,0.052684,0.000000
40.040001,61.862984,-1293.861938,-0.001673,0.002055,0.052189,275.180298,14.018353,0.521892,-1293.861938,0.053229,0.000000
40.370003,63.021057,-1293.817383,-0.001677,0.002080,0.052831,280.331665,14.280776,0.528311,-1293.817383,0.053785,0.000000
40.700001,63.903954,-1293.906372,-0.001664,0.002102,0.053385,284.258972,14.480844,0.533852,-1293.906372,0.054331,0.000000
41.030003,63.532707,-1293.772949,-0.001651,0.002109,0.053568,282.607605,14.396717,0.535684,-1293.772949,0.054878,0.000000
41.360001,65.713310,-1293.817383,-0.001643,0.002142,0.054401,292.307404,14.890849,0.544011,-1293.817383,0.055432,0.000000
41.690002,65.110435,-1293.817383,-0.001630,0.002142,0.054401,289.625671,14.754235,0.544011,-1293.817383,0.009565,0.000000
42.020000,66.121437,-1293.861938,-0.001595,0.002109,0.053577,294.122833,14.983332,0.535775,-1293.861938,294.500488,0.000000
42.350002,65.298866,-1293.861938,-0.001608,0.002170,0.055120,290.463867,14.796934,0.551202,-1293.861938,294.500488,0.000000
42.680000,65.143578,-1293.861938,-0.001600,0.002180,0.055371,289.773102,14.761745,0.553715,-1293.861938,294.500488,0.000000
43.010002,65.201302,-1293.861938,-0.001591,0.002191,0.055641,290.029877,14.774826,0.556410,-1293.861938,294.500488,0.000000
43.340000,65.350243,-1293.772949,-0.001591,0.002203,0.055944,290.692383,14.808577,0.559438,-1293.772949,294.500488,0.000000
43.670002,65.194221,-1293.861938,-0.001574,0.002210,0.056127,289.998383,14.773222,0.561270,-1293.861938,294.500488,0.000000
44.000004,65.033363,-1293.906372,-0.001569,0.002225,0.056508,289.282837,14.736771,0.565085,-1293.906372,294.500488,0.000000
44.330002,65.052345,-1293.817383,-0.001574,0.002225,0.056525,289.367279,14.741073,0.565251,-1293.817383,294.500488,0.000000
44.660004,65.479088,-1293.817383,-0.001548,0.002238,0.056846,291.265533,14.837773,0.568461,-1293.817383,294.500488,0.000000
44.990002,65.067253,-1293.861938,-0.001539,0.002245,0.057020,289.433594,14.744451,0.570202,-1293.861938,294.500488,0.000000
45.320004,65.251198,-1293.906372,-0.001539,0.002256,0.057297,290.251831,14.786133,0.572973,-1293.906372,294.500488,0.000000
45.650002,65.320457,-1293.950806,-0.001548,0.002261,0.057437,290.559906,14.801826,0.574365,-1293.950806,294.500488,0.000000
45.980003,65.298119,-1293.861938,-0.001526,0.002268,0.057618,290.460541,14.796765,0.576182,-1293.861938,294.500488,0.000000
46.310001,65.228859,-1293.772949,-0.001531,0.002278,0.057853,290.152466,14.781071,0.578529,-1293.772949,294.500488,0.000000
46.640003,65.469032,-1293.906372,-0.001531,0.002284,0.058025,291.220795,14.835495,0.580255,-1293.906372,294.500488,0.000000
46.970001,65.402016,-1293.906372,-0.001509,0.002291,0.058200,290.922699,14.820309,0.581996,-1293.906372,294.500488,0.000000
47.300003,65.203529,-1293.861938,-0.001509,0.002293,0.058251,290.039795,14.775331,0.582510,-1293.861938,294.500488,0.000000
47.630001,65.411690,-1293.861938,-0.001518,0.002302,0.058468,290.965729,14.822501,0.584675,-1293.861938,294.500488,0.000000
47.960003,65.193108,-1293.861938,-0.001492,0.002306,0.058563,289.993439,14.772969,0.585629,-1293.861938,294.500488,0.000000
48.290001,65.145439,-1293.861938,-0.001496,0.002310,0.058684,289.781372,14.762168,0.586840,-1293.861938,294.500488,0.000000
48.620003,65.162209,-1293.817383,-0.001513,0.002317,0.058858,289.855988,14.765968,0.588581,-1293.817383,294.500488,0.000000
48.950001,65.221413,-1293.817383,-0.001509,0.002321,0.058954,290.119324,14.779383,0.589535,-1293.817383,294.500488,0.000000
49.280003,65.206139,-1293.817383,-0.001475,0.002326,0.059075,290.051392,14.775923,0.590746,-1293.817383,294.500488,0.000000
49.610001,65.231468,-1293.817383,-0.001475,0.002332,0.059223,290.164062,14.781662,0.592230,-1293.817383,294.500488,0.000000
49.940002,65.191612,-1293.861938,-0.001479,0.002336,0.059344,289.986786,14.772631,0.593441,-1293.861938,294.500488,0.000000
50.270004,65.170021,-1293.906372,-0.001483,0.002339,0.059421,289.890747,14.767738,0.594213,-1293.906372,294.500488,0.000000
50.600002,65.074699,-1293.906372,-0.001483,0.002344,0.059526,289.466705,14.746138,0.595258,-1293.906372,294.500488,0.000000
50.930004,65.284706,-1293.861938,-0.001475,0.002349,0.059673,290.400879,14.793726,0.596727,-1293.861938,294.500488,0.000000
51.260002,65.041557,-1293.772949,-0.001462,0.002351,0.059726,289.319305,14.738627,0.597256,-1293.772949,294.500488,0.000000
51.590004,65.213966,-1293.817383,-0.001457,0.002356,0.059847,290.086212,14.777697,0.598468,-1293.817383,294.500488,0.000000
51.920002,65.131294,-1293.906372,-0.001475,0.002360,0.059951,289.718475,14.758963,0.599512,-1293.906372,294.500488,0.000000
52.250004,64.986076,-1293.817383,-0.001470,0.002362,0.060003,289.072510,14.726055,0.600027,-1293.817383,294.500488,0.000000
52.580002,65.556923,-1293.817383,-0.001466,0.002372,0.060237,291.611755,14.855412,0.602374,-1293.817383,294.500488,0.000000
52.910004,65.268333,-1293.817383,-0.001436,0.002372,0.060237,290.328033,14.790016,0.602374,-1293.817383,294.500488,0.000000
53.240002,65.373344,-1293.861938,-0.001462,0.002377,0.060368,290.795166,14.813812,0.603676,-1293.861938,294.500488,0.000000
53.570004,65.229607,-1293.950806,-0.001453,0.002380,0.060445,290.155792,14.781240,0.604448,-1293.950806,294.500488,0.000000
53.900002,65.492119,-1293.861938,-0.001444,0.002387,0.060619,291.323486,14.840726,0.606189,-1293.861938,294.500488,0.000000
54.230003,65.338341,-1293.817383,-0.001436,0.002387,0.060619,290.639465,14.805880,0.606189,-1293.817383,294.500488,0.000000
54.560001,65.389351,-1293.861938,-0.001436,0.002391,0.060731,290.866364,14.817439,0.607309,-1293.861938,294.500488,0.000000
54.890003,65.302208,-1293.861938,-0.001436,0.002393,0.060784,290.478729,14.797691,0.607839,-1293.861938,294.500488,0.000000
55.220001,65.298866,-1293.906372,-0.001440,0.002396,0.060870,290.463867,14.796934,0.608702,-1293.906372,294.500488,0.000000
55.550003,65.204277,-1293.772949,-0.001431,0.002398,0.060905,290.043121,14.775500,0.609050,-1293.772949,294.500488,0.000000
55.880001,65.552452,-1293.817383,-0.001431,0.002405,0.061096,291.591858,14.854398,0.610958,-1293.817383,294.500488,0.000000
56.210003,65.421745,-1293.861938,-0.001427,0.002405,0.061096,291.010468,14.824780,0.610958,-1293.861938,294.500488,0.000000
56.540001,65.218803,-1293.906372,-0.001431,0.002406,0.061122,290.107727,14.778792,0.611215,-1293.906372,294.500488,0.000000
56.870003,65.390465,-1293.861938,-0.001431,0.002411,0.061252,290.871307,14.817692,0.612517,-1293.861938,294.500488,0.000000
57.200005,65.272789,-1293.817383,-0.001436,0.002414,0.061312,290.347870,14.791025,0.613123,-1293.817383,294.500488,0.000000
57.530003,65.295509,-1293.861938,-0.001414,0.002417,0.061382,290.448944,14.796174,0.613819,-1293.861938,294.500488,0.000000
57.860004,65.245613,-1293.861938,-0.001418,0.002418,0.061417,290.226990,14.784867,0.614167,-1293.861938,294.500488,0.000000
58.190002,65.365883,-1293.861938,-0.001418,0.002422,0.061529,290.761963,14.812121,0.615288,-1293.861938,294.500488,0.000000
58.520004,65.227745,-1293.861938,-0.001436,0.002423,0.061538,290.147491,14.780818,0.615378,-1293.861938,294.500488,0.000000
58.850002,65.286568,-1293.772949,-0.001418,0.002426,0.061624,290.409149,14.794147,0.616241,-1293.772949,294.500488,0.000000
59.180004,65.238167,-1293.817383,-0.001410,0.002429,0.061685,290.193848,14.783179,0.616847,-1293.817383,294.500488,0.000000
59.510002,65.186775,-1293.861938,-0.001410,0.002430,0.061720,289.965271,14.771534,0.617195,-1293.861938,294.500488,0.000000
59.840004,65.328285,-1293.861938,-0.001406,0.002434,0.061815,290.594727,14.803600,0.618149,-1293.861938,294.500488,0.000000
60.170002,65.260139,-1293.861938,-0.001414,0.002435,0.061859,290.291595,14.788159,0.618588,-1293.861938,294.500488,0.000000
60.500004,65.217690,-1293.817383,-0.001418,0.002437,0.061903,290.102783,14.778540,0.619027,-1293.817383,294.500488,0.000000
60.830002,65.226616,-1293.817383,-0.001397,0.002439,0.061945,290.142487,14.780562,0.619451,-1293.817383,294.500488,0.000000
61.160004,65.188637,-1293.861938,-0.001380,0.002441,0.061998,289.973541,14.771956,0.619981,-1293.861938,294.500488,0.000000
61.490002,65.165932,-1293.906372,-0.001414,0.002443,0.062050,289.872528,14.766811,0.620496,-1293.906372,294.500488,0.000000
61.820004,65.110817,-1293.772949,-0.001410,0.002444,0.062075,289.627380,14.754322,0.620753,-1293.772949,294.500488,0.000000
62.150002,65.500313,-1293.817383,-0.001397,0.002449,0.062215,291.359955,14.842584,0.622146,-1293.817383,294.500488,0.000000
62.480003,65.334236,-1293.817383,-0.001401,0.002449,0.062215,290.621185,14.804950,0.622146,-1293.817383,294.500488,0.000000
62.810001,65.211723,-1293.861938,-0.001397,0.002451,0.062266,290.076233,14.777188,0.622661,-1293.861938,294.500488,0.000000
63.140003,65.291420,-1293.906372,-0.001397,0.002453,0.062301,290.430756,14.795248,0.623009,-1293.906372,294.500488,0.000000
63.470001,65.335732,-1293.861938,-0.001393,0.002457,0.062405,290.627838,14.805288,0.624053,-1293.861938,294.500488,0.000000
63.800003,65.342064,-1293.817383,-0.001393,0.002457,0.062414,290.656006,14.806724,0.624144,-1293.817383,294.500488,0.000000
64.130005,65.269447,-1293.772949,-0.001393,0.002458,0.062440,290.333008,14.790268,0.624402,-1293.772949,294.500488,0.000000
64.460007,65.243385,-1293.861938,-0.001393,0.002460,0.062483,290.217072,14.784363,0.624826,-1293.861938,294.500488,0.000000
64.790001,65.266090,-1293.906372,-0.001397,0.002462,0.062536,290.318085,14.789508,0.625355,-1293.906372,294.500488,0.000000
65.120003,65.296257,-1293.861938,-0.001393,0.002464,0.062578,290.452271,14.796344,0.625779,-1293.861938,294.500488,0.000000
65.450005,65.305199,-1293.817383,-0.001384,0.002466,0.062648,290.492035,14.798369,0.626476,-1293.817383,294.500488,0.000000
65.780006,65.286201,-1293.861938,-0.001375,0.002467,0.062657,290.407532,14.794065,0.626567,-1293.861938,294.500488,0.000000
66.110001,65.194603,-1293.950806,-0.001393,0.002467,0.062673,290.000092,14.773308,0.626733,-1293.950806,294.500488,0.000000
66.440002,65.111565,-1293.861938,-0.001384,0.002468,0.062691,289.630707,14.754492,0.626915,-1293.861938,294.500488,0.000000
66.770004,65.099648,-1293.817383,-0.001384,0.002471,0.062752,289.577698,14.751791,0.627520,-1293.817383,294.500488,0.000000
67.100006,65.048256,-1293.861938,-0.001371,0.002471,0.062761,289.349091,14.740146,0.627611,-1293.861938,294.500488,0.000000
67.430000,65.114540,-1293.817383,-0.001393,0.002473,0.062813,289.643951,14.755165,0.628126,-1293.817383,294.500488,0.000000
67.760002,65.040810,-1293.861938,-0.001380,0.002474,0.062847,289.315979,14.738459,0.628474,-1293.861938,294.500488,0.000000
68.090004,65.215446,-1293.861938,-0.001388,0.002477,0.062917,290.092804,14.778031,0.629171,-1293.861938,294.500488,0.000000
68.420006,65.270195,-1293.817383,-0.001380,0.002479,0.062959,290.336334,14.790438,0.629595,-1293.817383,294.500488,0.000000
68.750000,65.190498,-1293.906372,-0.001384,0.002479,0.062978,289.981812,14.772378,0.629776,-1293.906372,294.500488,0.000000
69.080002,65.349510,-1293.817383,-0.001375,0.002482,0.063047,290.689148,14.808411,0.630473,-1293.817383,294.500488,0.000000
69.410004,65.262367,-1293.861938,-0.001358,0.002482,0.063055,290.301514,14.788664,0.630548,-1293.861938,294.500488,0.000000
69.740005,65.202049,-1293.950806,-0.001380,0.002484,0.063090,290.033203,14.774996,0.630897,-1293.950806,294.500488,0.000000
70.070000,65.164803,-1293.817383,-0.001380,0.002484,0.063090,289.867523,14.766556,0.630897,-1293.817383,294.500488,0.000000
70.400002,65.075432,-1293.861938,-0.001375,0.002485,0.063108,289.469971,14.746304,0.631078,-1293.861938,294.500488,0.000000
70.730003,65.096657,-1293.906372,-0.001362,0.002487,0.063159,289.564392,14.751113,0.631593,-1293.906372,294.500488,0.000000
71.060005,65.034477,-1293.906372,-0.001375,0.002487,0.063159,289.287811,14.737023,0.631593,-1293.906372,294.500488,0.000000
71.390007,65.069481,-1293.906372,-0.001371,0.002489,0.063220,289.443512,14.744955,0.632199,-1293.906372,294.500488,0.000000
71.720001,65.069847,-1293.861938,-0.001375,0.002490,0.063255,289.445129,14.745038,0.632547,-1293.861938,294.500488,0.000000
72.050003,65.057198,-1293.906372,-0.001371,0.002492,0.063308,289.388855,14.742171,0.633077,-1293.906372,294.500488,0.000000
72.380005,65.067253,-1293.861938,-0.001371,0.002492,0.063308,289.433594,14.744451,0.633077,-1293.861938,294.500488,0.000000
72.710007,65.038200,-1293.906372,-0.001350,0.002493,0.063333,289.304352,14.737866,0.633334,-1293.906372,294.500488,0.000000
73.040001,65.575905,-1293.861938,-0.001375,0.002500,0.063506,291.696198,14.859713,0.635060,-1293.861938,294.500488,0.000000
73.370003,65.550591,-1293.906372,-0.001362,0.002500,0.063506,291.583588,14.853976,0.635060,-1293.906372,294.500488,0.000000
73.700005,65.486916,-1293.906372,-0.001358,0.002500,0.063506,291.300354,14.839547,0.635060,-1293.906372,294.500488,0.000000
74.030006,65.363655,-1293.861938,-0.001358,0.002500,0.063506,290.752045,14.811616,0.635060,-1293.861938,294.500488,0.000000
74.360001,65.278755,-1293.861938,-0.001367,0.002501,0.063515,290.374420,14.792377,0.635151,-1293.861938,294.500488,0.000000
74.690002,65.220665,-1293.950806,-0.001367,0.002503,0.063567,290.115997,14.779214,0.635666,-1293.950806,294.500488,0.000000
75.020004,65.423607,-1293.861938,-0.001362,0.002505,0.063620,291.018738,14.825201,0.636195,-1293.861938,294.500488,0.000000
75.350006,65.346901,-1293.906372,-0.001345,0.002505,0.063629,290.677521,14.807819,0.636286,-1293.906372,294.500488,0.000000
75.680000,65.290291,-1293.861938,-0.001358,0.002505,0.063636,290.425720,14.794991,0.636362,-1293.861938,294.500488,0.000000
76.010002,65.308540,-1293.950806,-0.001362,0.002507,0.063680,290.506897,14.799127,0.636801,-1293.950806,294.500488,0.000000
76.340004,65.278008,-1293.950806,-0.001345,0.002507,0.063689,290.371094,14.792209,0.636892,-1293.950806,294.500488,0.000000
76.670006,65.253426,-1293.861938,-0.001358,0.002509,0.063741,290.261719,14.786638,0.637407,-1293.861938,294.500488,0.000000
77.000000,65.267586,-1293.861938,-0.001345,0.002509,0.063741,290.324707,14.789846,0.637407,-1293.861938,294.500488,0.000000
77.330002,65.202797,-1293.906372,-0.001358,0.002510,0.063750,290.036530,14.775166,0.637497,-1293.906372,294.500488,0.000000
77.660004,65.231834,-1293.906372,-0.001358,0.002514,0.063853,290.165680,14.781745,0.638527,-1293.906372,294.500488,0.000000
77.990005,65.465691,-1293.906372,-0.001362,0.002514,0.063862,291.205933,14.834738,0.638618,-1293.906372,294.500488,0.000000
78.320007,65.409081,-1293.906372,-0.001358,0.002514,0.063862,290.954132,14.821909,0.638618,-1293.906372,294.500488,0.000000
78.650002,65.321571,-1293.906372,-0.001341,0.002515,0.063880,290.564850,14.802079,0.638799,-1293.906372,294.500488,0.000000
78.980003,65.317848,-1293.906372,-0.001358,0.002516,0.063897,290.548309,14.801236,0.638966,-1293.906372,294.500488,0.000000
79.310005,65.283592,-1293.950806,-0.001354,0.002517,0.063922,290.395935,14.793474,0.639223,-1293.950806,294.500488,0.000000
79.640007,65.297005,-1293.950806,-0.001345,0.002517,0.063941,290.455597,14.796514,0.639405,-1293.950806,294.500488,0.000000
79.970001,65.393822,-1293.861938,-0.001350,0.002520,0.064010,290.886261,14.818452,0.640101,-1293.861938,294.500488,0.000000
80.300003,65.403877,-1293.906372,-0.001345,0.002520,0.064010,290.930969,14.820731,0.640101,-1293.906372,294.500488,0.000000
80.630005,65.346901,-1293.950806,-0.001341,0.002520,0.064018,290.677521,14.807819,0.640177,-1293.950806,294.500488,0.000000
80.960007,65.332756,-1293.995361,-0.001345,0.002521,0.064043,290.614624,14.804614,0.640435,-1293.995361,294.500488,0.000000
81.290001,65.314873,-1293.950806,-0.001362,0.002522,0.064053,290.535065,14.800561,0.640525,-1293.950806,294.500488,0.000000
81.620003,65.270561,-1293.861938,-0.001337,0.002522,0.064053,290.337952,14.790521,0.640525,-1293.861938,294.500488,0.000000
81.950005,65.248970,-1293.906372,-0.001345,0.002522,0.064071,290.241913,14.785628,0.640707,-1293.906372,294.500488,0.000000
82.280006,65.340569,-1293.950806,-0.001328,0.002526,0.064157,290.649353,14.806384,0.641570,-1293.950806,294.500488,0.000000
82.610001,65.363289,-1293.906372,-0.001345,0.002526,0.064157,290.750427,14.811533,0.641570,-1293.906372,294.500488,0.000000
82.940002,65.321205,-1293.906372,-0.001354,0.002526,0.064157,290.563232,14.801996,0.641570,-1293.906372,294.500488,0.000000
83.270004,65.279869,-1293.906372,-0.001332,0.002526,0.064166,290.379364,14.792629,0.641661,-1293.906372,294.500488,0.000000
83.600006,65.266472,-1293.906372,-0.001332,0.002527,0.064192,290.319763,14.789594,0.641918,-1293.906372,294.500488,0.000000
83.930000,65.269447,-1293.906372,-0.001341,0.002528,0.064201,290.333008,14.790268,0.642009,-1293.906372,294.500488,0.000000
84.260002,65.241524,-1293.995361,-0.001341,0.002528,0.064208,290.208801,14.783940,0.642085,-1293.995361,294.500488,0.000000
84.590004,65.242638,-1293.861938,-0.001345,0.002530,0.064261,290.213745,14.784193,0.642615,-1293.861938,294.500488,0.000000
84.920006,65.327904,-1293.906372,-0.001341,0.002531,0.064296,290.593018,14.803514,0.642963,-1293.906372,294.500488,0.000000
85.250008,65.362907,-1293.950806,-0.001319,0.002532,0.064313,290.748718,14.811446,0.643129,-1293.950806,294.500488,0.000000
85.580002,65.352486,-1293.950806,-0.001341,0.002532,0.064313,290.702362,14.809085,0.643129,-1293.950806,294.500488,0.000000
85.910004,65.301842,-1293.950806,-0.001332,0.002532,0.064322,290.477112,14.797609,0.643220,-1293.950806,294.500488,0.000000
86.240005,65.272423,-1293.906372,-0.001337,0.002533,0.064330,290.346252,14.790943,0.643296,-1293.906372,294.500488,0.000000
86.570007,65.228111,-1293.906372,-0.001350,0.002534,0.064364,290.149139,14.780901,0.643644,-1293.906372,294.500488,0.000000
86.900002,65.404243,-1293.861938,-0.001328,0.002537,0.064443,290.932617,14.820813,0.644431,-1293.861938,294.500488,0.000000
87.230003,65.407967,-1293.950806,-0.001328,0.002537,0.064443,290.949158,14.821657,0.644431,-1293.950806,294.500488,0.000000
87.560005,65.373711,-1293.950806,-0.001337,0.002537,0.064443,290.796783,14.813894,0.644431,-1293.950806,294.500488,0.000000
87.890007,65.333870,-1293.861938,-0.001345,0.002537,0.064443,290.619568,14.804866,0.644431,-1293.861938,294.500488,0.000000
88.220001,65.293282,-1293.906372,-0.001328,0.002537,0.064452,290.439026,14.795669,0.644522,-1293.906372,294.500488,0.000000
88.550003,65.301842,-1293.950806,-0.001324,0.002539,0.064495,290.477112,14.797609,0.644946,-1293.950806,294.500488,0.000000
88.880005,65.327156,-1293.950806,-0.001328,0.002540,0.064504,290.589691,14.803345,0.645037,-1293.950806,294.500488,0.000000
89.210007,65.298119,-1293.906372,-0.001341,0.002540,0.064513,290.460541,14.796765,0.645128,-1293.906372,294.500488,0.000000
89.540001,65.289558,-1293.861938,-0.001341,0.002540,0.064522,290.422455,14.794826,0.645219,-1293.861938,294.500488,0.000000
89.870003,65.294762,-1293.906372,-0.001341,0.002541,0.064529,290.445618,14.796005,0.645294,-1293.906372,294.500488,0.000000
90.200005,65.260139,-1293.995361,-0.001315,0.002541,0.064548,290.291595,14.788159,0.645476,-1293.995361,294.500488,0.000000
90.530006,65.241142,-1293.906372,-0.001341,0.002542,0.064564,290.207092,14.783854,0.645643,-1293.906372,294.500488,0.000000
90.860001,65.237053,-1294.039795,-0.001328,0.002542,0.064573,290.188904,14.782928,0.645733,-1294.039795,294.500488,0.000000
91.190002,65.226250,-1293.906372,-0.001345,0.002543,0.064582,290.140839,14.780479,0.645824,-1293.906372,294.500488,0.000000
91.520004,65.208382,-1293.861938,-0.001337,0.002543,0.064599,290.061371,14.776431,0.645991,-1293.861938,294.500488,0.000000
91.850006,65.219917,-1293.906372,-0.001315,0.002544,0.064617,290.112671,14.779044,0.646172,-1293.906372,294.500488,0.000000
92.180008,65.204659,-1293.995361,-0.001332,0.002544,0.064625,290.044800,14.775586,0.646248,-1293.995361,294.500488,0.000000
92.510002,65.305931,-1294.084351,-0.001324,0.002547,0.064704,290.495300,14.798535,0.647035,-1294.084351,294.500488,0.000000
92.840004,65.362160,-1293.861938,-0.001324,0.002547,0.064704,290.745422,14.811277,0.647035,-1293.861938,294.500488,0.000000
93.170006,65.329765,-1293.906372,-0.001328,0.002547,0.064704,290.601318,14.803937,0.647035,-1293.906372,294.500488,0.000000
93.500008,65.308540,-1293.950806,-0.001324,0.002547,0.064704,290.506897,14.799127,0.647035,-1293.950806,294.500488,0.000000
93.830002,65.283592,-1293.950806,-0.001324,0.002547,0.064704,290.395935,14.793474,0.647035,-1293.950806,294.500488,0.000000
94.160004,65.231468,-1293.995361,-0.001315,0.002548,0.064713,290.164062,14.781662,0.647126,-1293.995361,294.500488,0.000000
94.490005,65.198326,-1293.950806,-0.001324,0.002548,0.064720,290.016632,14.774152,0.647202,-1293.950806,294.500488,0.000000
94.820007,65.178581,-1293.906372,-0.001319,0.002548,0.064729,289.928802,14.769677,0.647293,-1293.906372,294.500488,0.000000
95.150002,65.170387,-1293.950806,-0.001324,0.002549,0.064755,289.892365,14.767821,0.647550,-1293.950806,294.500488,0.000000
95.480003,65.286201,-1293.995361,-0.001332,0.002552,0.064825,290.407532,14.794065,0.648247,-1293.995361,294.500488,0.000000
95.810005,65.323067,-1293.995361,-0.001332,0.002552,0.064825,290.571503,14.802419,0.648247,-1293.995361,294.500488,0.000000
96.140007,65.320839,-1293.906372,-0.001337,0.002552,0.064825,290.561615,14.801914,0.648247,-1293.906372,294.500488,0.000000
96.470001,65.299232,-1293.906372,-0.001311,0.002552,0.064825,290.465485,14.797018,0.648247,-1293.906372,294.500488,0.000000
96.800003,65.263863,-1293.906372,-0.001332,0.002552,0.064825,290.308167,14.789002,0.648247,-1293.906372,294.500488,0.000000
97.130005,65.216942,-1293.995361,-0.001328,0.002552,0.064825,290.099457,14.778370,0.648247,-1293.995361,294.500488,0.000000
97.460007,65.168907,-1293.995361,-0.001337,0.002553,0.064834,289.885773,14.767486,0.648337,-1293.995361,294.500488,0.000000
97.790001,65.260887,-1293.950806,-0.001315,0.002555,0.064894,290.294922,14.788328,0.648943,-1293.950806,294.500488,0.000000
98.120003,65.251198,-1293.950806,-0.001319,0.002555,0.064894,290.251831,14.786133,0.648943,-1293.950806,294.500488,0.000000
98.450005,65.231087,-1293.950806,-0.001324,0.002555,0.064894,290.162354,14.781575,0.648943,-1293.950806,294.500488,0.000000
98.780006,65.200935,-1293.950806,-0.001315,0.002555,0.064903,290.028259,14.774743,0.649034,-1293.950806,294.500488,0.000000
99.110008,65.223640,-1293.995361,-0.001319,0.002556,0.064920,290.129242,14.779888,0.649200,-1293.995361,294.500488,0.000000
99.440002,65.212105,-1293.950806,-0.001311,0.002557,0.064946,290.077942,14.777274,0.649458,-1293.950806,294.500488,0.000000
99.770004,65.219917,-1293.995361,-0.001319,0.002557,0.064946,290.112671,14.779044,0.649458,-1293.995361,294.500488,0.000000
100.100006,65.212837,-1293.995361,-0.001324,0.002557,0.064955,290.081177,14.777440,0.649549,-1293.995361,294.500488,0.000000
100.430008,65.174858,-1294.039795,-0.001324,0.002558,0.064964,289.912262,14.768834,0.649639,-1294.039795,294.500488,0.000000
100.760002,65.193474,-1293.995361,-0.001315,0.002558,0.064981,289.995056,14.773052,0.649806,-1293.995361,294.500488,0.000000
101.090004,65.187523,-1293.906372,-0.001315,0.002559,0.065006,289.968597,14.771704,0.650063,-1293.906372,294.500488,0.000000
101.420006,65.222527,-1293.906372,-0.001315,0.002560,0.065015,290.124298,14.779635,0.650154,-1293.906372,294.500488,0.000000
101.750008,65.213966,-1293.906372,-0.001319,0.002560,0.065015,290.086212,14.777697,0.650154,-1293.906372,294.500488,0.000000
102.080002,65.226250,-1293.995361,-0.001306,0.002561,0.065041,290.140839,14.780479,0.650411,-1293.995361,1681.640991,0.000000
102.410004,65.252693,-1293.950806,-0.001319,0.002550,0.064764,290.258484,14.786471,0.647641,-1293.950806,0.064685,0.000000
102.740005,65.140236,-1293.995361,-0.001306,0.002535,0.064383,289.758240,14.760988,0.643826,-1293.995361,0.064139,0.000000
103.070007,65.037453,-1293.950806,-0.001306,0.002517,0.063922,289.301025,14.737697,0.639223,-1293.950806,0.063585,0.000000
103.400002,64.948463,-1293.995361,-0.001293,0.002502,0.063541,288.905182,14.717532,0.635408,-1293.995361,0.063038,0.000000
103.730003,64.927986,-1293.950806,-0.001298,0.002485,0.063124,288.814117,14.712892,0.631245,-1293.950806,0.062483,0.000000
104.060005,64.811806,-1293.995361,-0.001293,0.002460,0.062475,288.297302,14.686565,0.624750,-1293.995361,0.061938,0.000000
104.390007,64.778282,-1293.995361,-0.001293,0.002434,0.061824,288.148193,14.678968,0.618240,-1293.995361,0.061391,0.000000
104.720001,64.711632,-1293.995361,-0.001298,0.002415,0.061330,287.851715,14.663866,0.613304,-1293.995361,0.060835,0.000000
105.050003,64.639763,-1293.950806,-0.001298,0.002390,0.060714,287.532013,14.647580,0.607143,-1293.950806,0.060289,0.000000
105.380005,64.583534,-1293.950806,-0.001293,0.002371,0.060228,287.281921,14.634837,0.602283,-1293.950806,0.059735,0.000000
105.710007,64.399590,-1293.950806,-0.001306,0.002349,0.059673,286.463684,14.593156,0.596727,-1293.950806,0.059188,0.000000
106.040009,64.249138,-1293.950806,-0.001306,0.002327,0.059109,285.794434,14.559063,0.591095,-1293.950806,0.058642,0.000000
106.370003,63.775856,-1293.950806,-0.001293,0.002310,0.058667,283.689178,14.451816,0.586674,-1293.950806,0.058086,0.000000
106.700005,63.147667,-1293.906372,-0.001276,0.002291,0.058190,280.894836,14.309465,0.581905,-1293.906372,0.057539,0.000000
107.030006,62.261421,-1293.995361,-0.001285,0.002272,0.057714,276.952637,14.108640,0.577136,-1293.995361,0.056985,0.000000
107.360008,61.114883,-1293.950806,-0.001285,0.002249,0.057132,271.852570,13.848830,0.571322,-1293.950806,0.056439,0.000000
107.690002,60.161987,-1293.950806,-0.001293,0.002234,0.056742,267.613892,13.632901,0.567416,-1293.950806,0.055883,0.000000
108.020004,58.713455,-1293.906372,-0.001289,0.002212,0.056195,261.170502,13.304660,0.561951,-1293.906372,0.055337,0.000000
108.350006,57.436592,-1293.950806,-0.001272,0.002194,0.055736,255.490723,13.015318,0.557364,-1293.950806,0.054790,0.000000
108.680008,55.758682,-1293.950806,-0.001289,0.002173,0.055199,248.027008,12.635098,0.551989,-1293.950806,0.054236,0.000000
109.010002,54.177956,-1293.995361,-0.001289,0.002156,0.054757,240.995590,12.276900,0.547568,-1293.995361,0.053689,0.000000
109.340004,52.044640,-1293.950806,-0.001298,0.002128,0.054054,231.506119,11.793484,0.540544,-1293.950806,0.053134,0.000000
109.670006,49.881523,-1293.906372,-0.001285,0.002109,0.053568,221.884094,11.303314,0.535684,-1293.906372,0.052589,0.000000
110.000008,47.475624,-1293.906372,-0.001302,0.002086,0.052996,211.182129,10.758130,0.529961,-1293.906372,0.052033,0.000000
110.330002,45.588440,-1293.950806,-0.001293,0.002066,0.052484,202.787506,10.330488,0.524844,-1293.950806,0.051487,0.000000
110.660004,42.960983,-1293.995361,-0.001289,0.002044,0.051929,191.099991,9.735098,0.519288,-1293.995361,0.050940,0.000000
110.990005,41.136734,-1293.906372,-0.001319,0.002028,0.051503,182.985336,9.321717,0.515033,-1293.906372,0.050386,0.000000
111.320007,38.411713,-1293.906372,-0.001293,0.002003,0.050880,170.863831,8.704219,0.508796,-1293.906372,0.049839,0.000000
111.650002,36.412811,-1293.906372,-0.001306,0.001983,0.050368,161.972275,8.251261,0.503679,-1293.906372,0.049284,0.000000
111.980003,34.538292,-1293.950806,-0.001302,0.001963,0.049865,153.634003,7.826489,0.498652,-1293.950806,0.048737,0.000000
112.310005,32.182289,-1294.039795,-0.001306,0.001941,0.049293,143.153976,7.292611,0.492930,-1294.039795,0.048183,0.000000
112.640007,29.254700,-1293.906372,-0.001319,0.001913,0.048590,130.131409,6.629210,0.485905,-1293.906372,0.047637,0.000000
112.970009,27.860535,-1293.906372,-0.001319,0.001899,0.048244,123.929848,6.313287,0.482438,-1293.906372,0.047090,0.000000
113.300003,24.757187,-1293.861938,-0.001319,0.001871,0.047516,110.125465,5.610059,0.475156,-1293.861938,0.046535,0.000000
113.630005,23.061028,-1293.861938,-0.001315,0.001855,0.047116,102.580574,5.225704,0.471159,-1293.861938,0.045988,0.000000
113.960007,20.012413,-1293.906372,-0.001324,0.001826,0.046370,89.019661,4.534878,0.463695,-1293.906372,0.045434,0.000000
114.290009,18.005699,-1293.906372,-0.001337,0.001804,0.045824,80.093353,4.080150,0.458245,-1293.906372,0.044887,0.000000
114.620003,15.645226,-1293.861938,-0.001341,0.001784,0.045320,69.593437,3.545259,0.453203,-1293.861938,0.044332,0.000000
114.950005,13.364822,-1293.950806,-0.001350,0.001761,0.044731,59.449699,3.028512,0.447314,-1293.950806,0.043785,0.000000
115.280006,11.246391,-1293.906372,-0.001354,0.001741,0.044220,50.026447,2.548469,0.442197,-1293.906372,0.043240,0.000000
115.610008,9.326813,-1293.950806,-0.001354,0.001719,0.043655,41.487736,2.113486,0.436550,-1293.950806,0.042685,0.000000
115.940002,7.572563,-1293.906372,-0.001354,0.001705,0.043301,33.684444,1.715967,0.433007,-1293.906372,0.042138,0.000000
116.270004,5.146187,-1293.906372,-0.001354,0.001676,0.042580,22.891382,1.166143,0.425801,-1293.906372,0.041582,0.000000
116.600006,3.170006,-1293.861938,-0.001371,0.001657,0.042087,14.100890,0.718334,0.420865,-1293.861938,0.041037,0.000000
116.930008,1.766533,-1293.950806,-0.001380,0.001640,0.041661,7.857931,0.400302,0.416611,-1293.950806,0.040482,0.000000
117.260002,-0.617020,-1293.995361,-0.001375,0.001612,0.040933,-2.744641,-0.139819,0.409329,-1293.995361,0.039935,0.000000
117.590004,-1.737492,-1293.950806,-0.001388,0.001597,0.040559,-7.728749,-0.393721,0.405589,-1293.950806,0.039389,0.000000
117.920006,-0.552597,-1293.950806,-0.001410,0.001571,0.039909,-2.458074,-0.125220,0.399094,-1293.950806,0.038835,0.000000
118.250008,-0.204803,-1293.906372,-0.001410,0.001548,0.039328,-0.911011,-0.046409,0.393281,-1293.906372,0.038288,0.000000
118.580002,-0.099426,-1293.906372,-0.001440,0.001529,0.038825,-0.442270,-0.022530,0.388255,-1293.906372,0.037732,0.000000
118.910004,-0.074844,-1293.995361,-0.001457,0.001502,0.038140,-0.332924,-0.016960,0.381396,-1293.995361,0.037186,0.000000
119.240005,-0.062561,-1293.995361,-0.001466,0.001483,0.037663,-0.278285,-0.014177,0.376627,-1293.995361,0.036639,0.000000
119.570007,-0.074844,-1293.906372,-0.001479,0.001462,0.037143,-0.332924,-0.016960,0.371434,-1293.906372,0.036085,0.000000
119.900009,-0.035378,-1293.861938,-0.001500,0.001445,0.036700,-0.157367,-0.008017,0.366999,-1293.861938,0.035539,0.000000
120.230003,-0.064049,-1293.950806,-0.001509,0.001421,0.036102,-0.284903,-0.014514,0.361018,-1293.950806,0.034983,0.000000
120.560005,-0.052879,-1293.950806,-0.001518,0.001406,0.035711,-0.235219,-0.011983,0.357112,-1293.950806,0.034436,0.000000
120.890007,-0.040215,-1294.039795,-0.001556,0.001371,0.034827,-0.178883,-0.009113,0.348271,-1294.039795,0.033882,0.000000
121.220009,-0.045799,-1294.039795,-0.001569,0.001351,0.034324,-0.203725,-0.010378,0.343245,-1294.039795,0.033336,0.000000
121.550003,-0.034630,-1293.906372,-0.001587,0.001331,0.033804,-0.154041,-0.007847,0.338037,-1293.906372,0.032789,0.000000
121.880005,-0.030907,-1293.817383,-0.001595,0.001312,0.033327,-0.137480,-0.007004,0.333268,-1293.817383,0.032234,0.000000
122.210007,-0.024948,-1293.950806,-0.001604,0.001293,0.032833,-0.110975,-0.005653,0.328332,-1293.950806,0.031689,0.000000
122.540009,-0.024948,-1293.995361,-0.001630,0.001271,0.032278,-0.110975,-0.005653,0.322776,-1293.995361,0.031133,0.000000
122.870003,-0.022713,-1293.906372,-0.001643,0.001248,0.031705,-0.101031,-0.005147,0.317053,-1293.906372,0.030586,0.000000
123.200005,-0.032768,-1293.861938,-0.001673,0.001226,0.031133,-0.145760,-0.007425,0.311330,-1293.861938,0.030031,0.000000
123.530006,0.022713,-1293.906372,-0.001699,0.001197,0.030405,0.101031,0.005147,0.304048,-1293.906372,0.029486,0.000000
123.860008,0.026810,-1293.995361,-0.001712,0.001183,0.030049,0.119255,0.006075,0.300490,-1293.995361,0.028939,0.000000
124.190002,0.001114,-1293.995361,-0.001720,0.001158,0.029424,0.004955,0.000252,0.294238,-1293.995361,0.028384,0.000000
124.520004,-0.002609,-1293.995361,-0.001755,0.001132,0.028749,-0.011607,-0.000591,0.287485,-1293.995361,0.027837,0.000000
124.850006,-0.017502,-1293.906372,-0.001768,0.001110,0.028193,-0.077852,-0.003966,0.281929,-1293.906372,0.027283,0.000000
125.180008,-0.033142,-1293.906372,-0.001768,0.001095,0.027820,-0.147423,-0.007510,0.278205,-1293.906372,0.026736,0.000000
125.510010,0.017502,-1294.039795,-0.001802,0.001079,0.027395,0.077852,0.003966,0.273951,-1294.039795,0.026181,0.000000
125.840004,0.014526,-1294.039795,-0.001815,0.001057,0.026849,0.064617,0.003292,0.268485,-1294.039795,0.025634,0.000000
126.170006,0.014526,-1293.995361,-0.001841,0.001027,0.026095,0.064617,0.003292,0.260946,-1293.995361,0.025088,0.000000
126.500008,0.012657,-1293.861938,-0.001867,0.001006,0.025557,0.056302,0.002868,0.255571,-1293.861938,0.024534,0.000000
126.830009,-0.011169,-1293.950806,-0.001880,0.000980,0.024889,-0.049684,-0.002531,0.248895,-1293.950806,0.023987,0.000000
127.160004,-0.006706,-1293.995361,-0.001888,0.000959,0.024360,-0.029831,-0.001520,0.243596,-1293.995361,0.023432,0.000000
127.490005,0.002235,-1294.039795,-0.001910,0.000952,0.024178,0.009944,0.000507,0.241779,-1294.039795,0.022885,0.000000
127.820007,-0.004471,-1293.995361,-0.001940,0.000918,0.023329,-0.019887,-0.001013,0.233286,-1293.995361,0.022331,0.000000
128.150009,0.001862,-1293.995361,-0.001936,0.000895,0.022721,0.008281,0.000422,0.227215,-1293.995361,0.021784,0.000000
128.480011,-0.013031,-1293.906372,-0.001936,0.000876,0.022245,-0.057965,-0.002953,0.222446,-1293.906372,0.021238,0.000000
128.810013,-0.007446,-1293.950806,-0.001966,0.000851,0.021610,-0.033123,-0.001687,0.216102,-1293.950806,0.020682,0.000000
129.139999,-0.032021,-1293.995361,-0.001988,0.000830,0.021091,-0.142435,-0.007256,0.210909,-1293.995361,0.020137,0.000000
129.470001,-0.029045,-1293.995361,-0.002009,0.000807,0.020501,-0.129199,-0.006582,0.205005,-1293.995361,0.019582,0.000000
129.800003,-0.032394,-1293.950806,-0.002022,0.000792,0.020119,-0.144098,-0.007341,0.201190,-1293.950806,0.019035,0.000000
130.130005,-0.014519,-1293.950806,-0.002052,0.000771,0.019582,-0.064583,-0.003290,0.195815,-1293.950806,0.018479,0.000000
130.460007,-0.032768,-1293.995361,-0.002070,0.000750,0.019053,-0.145760,-0.007425,0.190532,-1293.995361,0.017934,0.000000
130.790009,-0.010796,-1294.039795,-0.002091,0.000722,0.018351,-0.048021,-0.002446,0.183507,-1294.039795,0.017388,0.000000
131.120010,-0.034256,-1294.039795,-0.002091,0.000705,0.017907,-0.152378,-0.007763,0.179071,-1294.039795,0.016832,0.000000
131.450012,-0.027931,-1293.906372,-0.002126,0.000685,0.017388,-0.124244,-0.006329,0.173878,-1293.906372,0.016286,0.000000
131.779999,-0.018250,-1293.861938,-0.002147,0.000664,0.016858,-0.081178,-0.004135,0.168579,-1293.861938,0.015732,0.000000
132.110001,-0.019737,-1293.995361,-0.002160,0.000643,0.016330,-0.087796,-0.004473,0.163296,-1293.995361,0.015185,0.000000
132.440002,-0.016754,-1294.128784,-0.002182,0.000625,0.015878,-0.074526,-0.003797,0.158784,-1294.128784,0.014638,0.000000
132.700012,0.005211,-1293.995361,-0.002195,0.000607,0.015411,0.023179,0.001181,0.154106,-1293.995361,0.015280,0.000000