File: Data/Sima compression/P1-11-3_10302024_163558.csv
Time (sec),S:Load (lbs),S:HL1 (DIM),S:LVDT (in),S:Position (in),Ch:Position (mm),Ch:Load (N),Ch:Stress (MPa),Ch:Strain (mm/mm),Ch:HL1 (DIM),Set Point (),Cycles ()
0.210000,-0.023834,-1292.749878,-0.012935,-0.003319,-0.084294,-0.106020,-0.005401,-0.842942,-1292.749878,-0.084078,0.000000
0.580000,-0.052879,-1292.794312,-0.012956,-0.003218,-0.081728,-0.235219,-0.011983,-0.817280,-1292.794312,-0.080921,0.000000
0.950000,-0.016754,-1292.794312,-0.012762,-0.002988,-0.075883,-0.074526,-0.003797,-0.758826,-1292.794312,-0.074747,0.000000
1.320000,-0.010056,-1292.838867,-0.012516,-0.002747,-0.069769,-0.044729,-0.002279,-0.697692,-1292.838867,-0.068590,0.000000
1.690000,0.007446,-1292.749878,-0.012262,-0.002502,-0.063551,0.033123,0.001687,-0.635514,-1292.749878,-0.062433,0.000000
2.060000,0.005959,-1292.705444,-0.012008,-0.002258,-0.057359,0.026505,0.001350,-0.573593,-1292.705444,-0.056257,0.000000
2.430000,-0.035378,-1292.794312,-0.011766,-0.002020,-0.051314,-0.157367,-0.008017,-0.513141,-1292.794312,-0.050100,0.000000
2.800000,0.027931,-1292.749878,-0.011512,-0.001784,-0.045304,0.124244,0.006329,-0.453037,-1292.749878,-0.043926,0.000000
3.170000,0.051018,-1292.838867,-0.011283,-0.001539,-0.039078,0.226938,0.011561,-0.390783,-1292.838867,-0.037769,0.000000
3.540000,0.030159,-1292.749878,-0.011003,-0.001292,-0.032826,0.134154,0.006834,-0.328256,-1292.749878,-0.031611,0.000000
3.910000,-0.010056,-1292.749878,-0.010770,-0.001053,-0.026736,-0.044729,-0.002279,-0.267365,-1292.749878,-0.025436,0.000000
4.280000,-0.039101,-1292.794312,-0.010524,-0.000809,-0.020544,-0.173928,-0.008860,-0.205444,-1292.794312,-0.019279,0.000000
4.650000,-0.094208,-1292.838867,-0.010266,-0.000566,-0.014387,-0.419057,-0.021348,-0.143871,-1292.838867,-0.013105,0.000000
5.020000,0.000374,-1292.838867,-0.009998,-0.000319,-0.008100,0.001663,0.000085,-0.080997,-1292.838867,-0.006948,0.000000
5.390000,-0.003723,-1292.749878,-0.009744,-0.000074,-0.001891,-0.016561,-0.000844,-0.018909,-1292.749878,-0.000790,0.000000
5.760000,0.037239,-1292.749878,-0.009494,0.000168,0.004266,0.165648,0.008438,0.042663,-1292.749878,0.005385,0.000000
6.130000,0.008934,-1292.749878,-0.009270,0.000408,0.010372,0.039741,0.002024,0.103721,-1292.749878,0.011542,0.000000
6.500000,-0.019363,-1292.705444,-0.009007,0.000649,0.016495,-0.086133,-0.004388,0.164946,-1292.705444,0.017716,0.000000
6.870000,0.014893,-1292.838867,-0.008778,0.000888,0.022556,0.066245,0.003375,0.225565,-1292.838867,0.023874,0.000000
7.240000,0.046173,-1292.838867,-0.008507,0.001130,0.028696,0.205388,0.010463,0.286956,-1292.838867,0.030031,0.000000
7.610000,0.040588,-1292.749878,-0.008274,0.001378,0.034992,0.180546,0.009197,0.349921,-1292.749878,0.036206,0.000000
7.980000,0.031654,-1292.749878,-0.007994,0.001629,0.041384,0.140806,0.007173,0.413840,-1292.749878,0.042364,0.000000
8.350000,-0.007072,-1292.749878,-0.007769,0.001859,0.047211,-0.031460,-0.001603,0.472113,-1292.749878,0.048537,0.000000
8.720000,-0.041336,-1292.749878,-0.007506,0.002106,0.053490,-0.183872,-0.009367,0.534896,-1292.749878,0.054695,0.000000
9.090000,-0.041702,-1292.749878,-0.007261,0.002350,0.059700,-0.185501,-0.009450,0.596999,-1292.749878,0.060852,0.000000
9.460000,0.010796,-1292.705444,-0.006993,0.002595,0.065909,0.048021,0.002446,0.659086,-1292.705444,0.067027,0.000000
9.830001,0.064423,-1292.794312,-0.006760,0.002836,0.072022,0.286566,0.014598,0.720220,-1292.794312,0.073185,0.000000
10.200001,0.036118,-1292.749878,-0.006506,0.003077,0.078154,0.160659,0.008184,0.781535,-1292.749878,0.079342,0.000000
10.570001,0.008934,-1292.749878,-0.006260,0.003317,0.084241,0.039741,0.002024,0.842412,-1292.749878,0.085516,0.000000
10.940001,0.026436,-1292.794312,-0.006019,0.003559,0.090398,0.117593,0.005990,0.903984,-1292.794312,0.091673,0.000000
11.310000,0.064423,-1292.749878,-0.005764,0.003800,0.096522,0.286566,0.014598,0.965224,-1292.749878,0.097849,0.000000
11.680000,0.037613,-1292.749878,-0.005501,0.004047,0.102783,0.167311,0.008523,1.027826,-1292.749878,0.104006,0.000000
12.050000,0.039841,-1292.705444,-0.005260,0.004294,0.109063,0.177220,0.009028,1.090625,-1292.705444,0.110163,0.000000
12.420001,-0.003349,-1292.749878,-0.005023,0.004524,0.114915,-0.014898,-0.000759,1.149155,-1292.749878,0.116337,0.000000
12.790001,-0.029419,-1292.794312,-0.004764,0.004773,0.121229,-0.130862,-0.006666,1.212287,-1292.794312,0.122496,0.000000
13.160001,-0.061440,-1292.838867,-0.004514,0.005018,0.127446,-0.273297,-0.013922,1.274465,-1292.838867,0.128670,0.000000
13.530001,0.020111,-1292.749878,-0.004268,0.005264,0.133717,0.089459,0.004557,1.337173,-1292.749878,0.134827,0.000000
13.900001,0.031654,-1292.794312,-0.004014,0.005510,0.139944,0.140806,0.007173,1.399442,-1292.794312,0.140984,0.000000
14.270000,0.064423,-1292.794312,-0.003773,0.005749,0.146023,0.286566,0.014598,1.460228,-1292.794312,0.147160,0.000000
14.640000,0.010429,-1292.794312,-0.003518,0.005986,0.152041,0.046392,0.002363,1.520407,-1292.794312,0.153317,0.000000
15.010001,0.032394,-1292.794312,-0.003281,0.006229,0.158225,0.144098,0.007341,1.582253,-1292.794312,0.159491,0.000000
15.380001,0.132935,-1292.749878,-0.003027,0.006468,0.164278,0.591322,0.030123,1.642781,-1292.749878,0.165562,0.000000
15.750001,0.105751,-1292.794312,-0.003014,-0.000003,-0.000079,0.470404,0.023964,-0.000787,-1292.794312,0.000173,0.000000
16.120001,0.105385,-1292.838867,-0.003027,-0.000003,-0.000079,0.468775,0.023881,-0.000787,-1292.838867,0.000545,0.000000
16.490002,0.129585,-1292.794312,-0.003014,0.000012,0.000312,0.576424,0.029364,0.003119,-1292.794312,0.001161,0.000000
16.860001,0.169800,-1292.749878,-0.003001,0.000041,0.001040,0.755307,0.038477,0.010401,-1292.749878,0.001786,0.000000
17.230001,0.254333,-1292.794312,-0.002975,0.000061,0.001543,1.131332,0.057633,0.015427,-1292.794312,0.002401,0.000000
17.600000,0.336624,-1292.794312,-0.002949,0.000083,0.002115,1.497379,0.076280,0.021150,-1292.794312,0.003017,0.000000
17.970001,0.531372,-1292.794312,-0.002932,0.000109,0.002766,2.363661,0.120411,0.027660,-1292.794312,0.003633,0.000000
18.340000,0.764854,-1292.838867,-0.002906,0.000128,0.003252,3.402242,0.173318,0.032520,-1292.838867,0.004248,0.000000
18.710001,0.991631,-1292.794312,-0.002897,0.000147,0.003736,4.410993,0.224707,0.037364,-1292.794312,0.004864,0.000000
19.080002,1.437729,-1292.794312,-0.002867,0.000178,0.004527,6.395338,0.325794,0.045267,-1292.794312,0.005481,0.000000
19.450001,1.823509,-1292.749878,-0.002863,0.000204,0.005176,8.111374,0.413213,0.051762,-1292.749878,0.006095,0.000000
19.820002,2.271469,-1292.794312,-0.002846,0.000227,0.005767,10.103999,0.514722,0.057667,-1292.794312,0.006720,0.000000
20.190001,2.757790,-1292.794312,-0.002824,0.000252,0.006390,12.267261,0.624924,0.063904,-1292.794312,0.007337,0.000000
20.560001,3.094414,-1292.794312,-0.002815,0.000269,0.006825,13.764640,0.701204,0.068249,-1292.794312,0.007951,0.000000
20.930000,3.826126,-1292.794312,-0.002777,0.000301,0.007639,17.019459,0.867013,0.076394,-1292.794312,0.008567,0.000000
21.300001,4.313560,-1292.883301,-0.002755,0.000325,0.008256,19.187675,0.977467,0.082556,-1292.883301,0.009184,0.000000
21.670000,4.757431,-1292.749878,-0.002746,0.000347,0.008810,21.162109,1.078049,0.088097,-1292.749878,0.009798,0.000000
22.040001,5.383018,-1292.794312,-0.002729,0.000370,0.009409,23.944862,1.219809,0.094092,-1292.794312,0.010415,0.000000
22.410002,5.849968,-1292.927856,-0.002721,0.000394,0.009998,26.021957,1.325622,0.099982,-1292.927856,0.011031,0.000000
22.780001,6.659882,-1292.838867,-0.002682,0.000426,0.010814,29.624634,1.509151,0.108142,-1292.838867,0.011645,0.000000
23.150002,6.969696,-1292.794312,-0.002665,0.000449,0.011394,31.002756,1.579356,0.113940,-1292.794312,0.012271,0.000000
23.520000,7.376701,-1292.794312,-0.002677,0.000468,0.011880,32.813206,1.671584,0.118800,-1292.794312,0.012887,0.000000
23.890001,8.065216,-1292.838867,-0.002639,0.000496,0.012608,35.875874,1.827604,0.126082,-1292.838867,0.013501,0.000000
24.260000,8.032448,-1292.838867,-0.002626,0.000511,0.012973,35.730114,1.820179,0.129731,-1292.838867,0.014118,0.000000
24.630001,9.065407,-1292.838867,-0.002604,0.000547,0.013892,40.324944,2.054250,0.138921,-1292.838867,0.014734,0.000000
25.000002,9.122749,-1292.838867,-0.002587,0.000567,0.014395,40.580017,2.067245,0.143947,-1292.838867,0.015349,0.000000
25.370001,9.465332,-1292.794312,-0.002574,0.000590,0.014985,42.103901,2.144875,0.149852,-1292.794312,0.015965,0.000000
25.740002,9.869362,-1292.794312,-0.002557,0.000616,0.015635,43.901115,2.236429,0.156346,-1292.794312,0.016581,0.000000
26.110001,9.872337,-1292.794312,-0.002544,0.000635,0.016121,43.914349,2.237103,0.161206,-1292.794312,0.017197,0.000000
26.480001,10.000435,-1292.883301,-0.002539,0.000652,0.016555,44.484158,2.266131,0.165551,-1292.883301,0.017821,0.000000
26.850000,10.578728,-1292.838867,-0.002509,0.000686,0.017430,47.056530,2.397174,0.174302,-1292.838867,0.018437,0.000000
27.220001,10.728798,-1292.794312,-0.002505,0.000712,0.018090,47.724075,2.431180,0.180903,-1292.794312,0.019052,0.000000
27.590002,11.134682,-1292.838867,-0.002475,0.000741,0.018818,49.529537,2.523155,0.188185,-1292.838867,0.019668,0.000000
27.960001,11.097816,-1292.883301,-0.002462,0.000761,0.019321,49.365555,2.514801,0.193211,-1292.883301,0.020284,0.000000
28.330002,11.002861,-1292.883301,-0.002449,0.000778,0.019763,48.943169,2.493284,0.197632,-1292.883301,0.020899,0.000000
28.700001,11.577057,-1292.838867,-0.002432,0.000808,0.020517,51.497322,2.623399,0.205172,-1292.838867,0.021515,0.000000
29.070002,11.637756,-1292.838867,-0.002414,0.000833,0.021152,51.767326,2.637153,0.211515,-1292.838867,0.022131,0.000000
29.440001,11.534241,-1292.794312,-0.002397,0.000849,0.021575,51.306866,2.613696,0.215754,-1292.794312,0.022747,0.000000
29.810001,11.918152,-1292.749878,-0.002384,0.000877,0.022270,53.014587,2.700692,0.222703,-1292.749878,0.023371,0.000000
30.180002,12.134132,-1292.838867,-0.002380,0.000902,0.022920,53.975315,2.749634,0.229198,-1292.838867,0.023987,0.000000
30.550001,12.321808,-1292.838867,-0.002358,0.000928,0.023562,54.810139,2.792161,0.235617,-1292.838867,0.024602,0.000000
30.920002,12.384361,-1292.749878,-0.002341,0.000954,0.024220,55.088390,2.806336,0.242203,-1292.749878,0.025218,0.000000
31.290001,12.414528,-1292.794312,-0.002333,0.000975,0.024767,55.222580,2.813172,0.247668,-1292.794312,0.025834,0.000000
31.660002,12.316216,-1292.749878,-0.002311,0.000992,0.025192,54.785263,2.790894,0.251923,-1292.749878,0.026450,0.000000
32.030003,12.855415,-1292.838867,-0.002302,0.001025,0.026042,57.183743,2.913079,0.260416,-1292.838867,0.027065,0.000000
32.400002,13.163742,-1292.794312,-0.002294,0.001054,0.026779,58.555248,2.982947,0.267789,-1292.794312,0.027681,0.000000
32.770000,13.157410,-1292.838867,-0.002246,0.001078,0.027369,58.527081,2.981512,0.273693,-1292.838867,0.028297,0.000000
33.140003,12.999153,-1292.749878,-0.002229,0.001098,0.027898,57.823120,2.945650,0.278977,-1292.749878,0.028921,0.000000
33.510002,13.139160,-1292.749878,-0.002229,0.001119,0.028435,58.445904,2.977376,0.284352,-1292.749878,0.029537,0.000000
33.880001,13.384186,-1292.838867,-0.002216,0.001144,0.029060,59.535831,3.032900,0.290604,-1292.838867,0.030152,0.000000
34.250000,13.817253,-1292.838867,-0.002195,0.001172,0.029763,61.462212,3.131034,0.297629,-1292.838867,0.030768,0.000000
34.620003,14.033974,-1292.838867,-0.002173,0.001200,0.030473,62.426231,3.180144,0.304729,-1292.838867,0.031384,0.000000
34.990002,13.893585,-1292.749878,-0.002151,0.001222,0.031029,61.801754,3.148331,0.310286,-1292.749878,0.032001,0.000000
35.360001,13.971786,-1292.749878,-0.002134,0.001243,0.031566,62.149609,3.166052,0.315660,-1292.749878,0.032615,0.000000
35.730003,14.262238,-1292.794312,-0.002121,0.001266,0.032156,63.441601,3.231869,0.321565,-1292.794312,0.033231,0.000000
36.100002,14.570190,-1292.838867,-0.002130,0.001294,0.032859,64.811447,3.301652,0.328589,-1292.838867,0.033848,0.000000
36.470001,14.735153,-1292.794312,-0.002082,0.001319,0.033492,65.545235,3.339034,0.334918,-1292.794312,0.034471,0.000000
36.840000,14.874420,-1292.838867,-0.002078,0.001341,0.034064,66.164726,3.370592,0.340641,-1292.838867,0.035087,0.000000
37.210003,14.903465,-1292.794312,-0.002061,0.001363,0.034627,66.293922,3.377173,0.346272,-1292.794312,0.035704,0.000000
37.580002,15.375633,-1292.749878,-0.002035,0.001391,0.035330,68.394234,3.484168,0.353297,-1292.749878,0.036318,0.000000
37.950001,15.488457,-1292.794312,-0.002018,0.001411,0.035841,68.896095,3.509735,0.358414,-1292.794312,0.036935,0.000000
38.320004,16.252571,-1292.838867,-0.002005,0.001448,0.036769,72.295044,3.682885,0.367695,-1292.838867,0.037551,0.000000
38.690002,15.963608,-1292.749878,-0.001983,0.001467,0.037265,71.009674,3.617405,0.372646,-1292.749878,0.038165,0.000000
39.060001,16.122238,-1292.838867,-0.001944,0.001491,0.037872,71.715294,3.653351,0.378717,-1292.838867,0.038782,0.000000
39.430000,16.371727,-1292.794312,-0.001953,0.001516,0.038504,72.825081,3.709887,0.385045,-1292.794312,0.039398,0.000000
39.800003,16.203789,-1292.838867,-0.001944,0.001533,0.038928,72.078049,3.671831,0.389284,-1292.838867,0.040021,0.000000
40.170002,16.708725,-1292.883301,-0.001927,0.001561,0.039649,74.324120,3.786251,0.396490,-1292.883301,0.040638,0.000000
40.540001,17.146637,-1292.838867,-0.001897,0.001587,0.040317,76.272049,3.885484,0.403167,-1292.838867,0.041254,0.000000
40.910004,17.104553,-1292.794312,-0.001871,0.001610,0.040906,76.084854,3.875947,0.409056,-1292.794312,0.041869,0.000000
41.280003,17.596458,-1292.749878,-0.001863,0.001637,0.041591,78.272957,3.987414,0.415915,-1292.749878,0.042485,0.000000
41.650002,17.107162,-1292.794312,-0.001850,0.001651,0.041929,76.096458,3.876539,0.419291,-1292.794312,0.043101,0.000000
42.020000,17.496666,-1292.883301,-0.001837,0.001681,0.042692,77.829056,3.964801,0.426921,-1292.883301,0.043716,0.000000
42.390003,18.208641,-1292.838867,-0.001802,0.001710,0.043429,80.996078,4.126137,0.434294,-1292.838867,0.044332,0.000000
42.760002,18.201935,-1292.883301,-0.001802,0.001732,0.044002,80.966248,4.124618,0.440017,-1292.883301,0.044948,0.000000
43.130001,18.099533,-1292.838867,-0.001776,0.001753,0.044532,80.510742,4.101413,0.445316,-1292.838867,0.045572,0.000000
43.500004,18.556808,-1292.749878,-0.001772,0.001777,0.045139,82.544807,4.205033,0.451387,-1292.749878,0.046188,0.000000
43.870003,19.211815,-1292.838867,-0.001759,0.001807,0.045893,85.458420,4.353460,0.458926,-1292.838867,0.046804,0.000000
44.240002,19.527588,-1292.838867,-0.001729,0.001834,0.046595,86.863052,4.425014,0.465951,-1292.838867,0.047419,0.000000
44.610001,19.328735,-1292.838867,-0.001712,0.001855,0.047107,85.978508,4.379954,0.471068,-1292.838867,0.048035,0.000000
44.980003,19.445290,-1292.838867,-0.001712,0.001877,0.047670,86.496971,4.406365,0.476700,-1292.838867,0.048651,0.000000
45.350002,19.949852,-1292.794312,-0.001699,0.001903,0.048339,88.741371,4.520701,0.483392,-1292.794312,0.049266,0.000000
45.720001,19.840378,-1292.794312,-0.001681,0.001920,0.048772,88.254410,4.495894,0.487722,-1292.794312,0.049882,0.000000
46.090004,20.746735,-1292.838867,-0.001669,0.001951,0.049561,92.286087,4.701277,0.495609,-1292.838867,0.050507,0.000000
46.460003,20.878181,-1292.838867,-0.001643,0.001975,0.050159,92.870789,4.731063,0.501589,-1292.838867,0.051122,0.000000
46.830002,20.840942,-1292.794312,-0.001638,0.001996,0.050705,92.705139,4.722625,0.507055,-1292.794312,0.051738,0.000000
47.200001,21.378273,-1292.749878,-0.001608,0.002021,0.051338,95.095306,4.844386,0.513383,-1292.749878,0.052354,0.000000
47.570004,21.562599,-1292.838867,-0.001600,0.002045,0.051938,95.915230,4.886155,0.519378,-1292.838867,0.052969,0.000000
47.940002,22.498741,-1292.883301,-0.001587,0.002073,0.052657,100.079399,5.098288,0.526570,-1292.883301,0.053585,0.000000
48.310001,22.546783,-1292.838867,-0.001561,0.002096,0.053238,100.293098,5.109174,0.532383,-1292.838867,0.054201,0.000000
48.680004,22.947083,-1292.794312,-0.001552,0.002121,0.053871,102.073723,5.199883,0.538712,-1292.794312,0.054816,0.000000
49.050003,23.622940,-1292.838867,-0.001544,0.002150,0.054618,105.080086,5.353034,0.546175,-1292.838867,0.055432,0.000000
49.420002,23.260620,-1292.838867,-0.001518,0.002168,0.055069,103.468407,5.270932,0.550687,-1292.838867,0.056057,0.000000
49.790001,23.444572,-1292.838867,-0.001518,0.002184,0.055476,104.286667,5.312616,0.554760,-1292.838867,0.056672,0.000000
50.160004,24.300285,-1292.883301,-0.001496,0.002214,0.056239,108.093071,5.506523,0.562390,-1292.883301,0.057288,0.000000
50.530003,24.667442,-1292.838867,-0.001496,0.002237,0.056811,109.726265,5.589723,0.568113,-1292.838867,0.057904,0.000000
50.900002,24.903900,-1292.794312,-0.001475,0.002255,0.057272,110.778084,5.643304,0.572715,-1292.794312,0.058519,0.000000
51.270004,26.169594,-1292.838867,-0.001462,0.002288,0.058112,116.408165,5.930115,0.581118,-1292.838867,0.059135,0.000000
51.640003,26.003143,-1292.794312,-0.001444,0.002303,0.058502,115.667755,5.892397,0.585024,-1292.794312,0.059751,0.000000
52.010002,27.223778,-1292.927856,-0.001440,0.002335,0.059317,121.097412,6.168996,0.593169,-1292.927856,0.060368,0.000000
52.380001,27.803192,-1292.883301,-0.001418,0.002360,0.059951,123.674774,6.300293,0.599512,-1292.883301,0.060982,0.000000
52.750004,27.990868,-1292.883301,-0.001401,0.002378,0.060401,124.509598,6.342821,0.604009,-1292.883301,0.061607,0.000000
53.120003,29.106491,-1292.794312,-0.001397,0.002409,0.061191,129.472137,6.595625,0.611912,-1292.794312,0.062222,0.000000
53.490002,29.569351,-1292.794312,-0.001375,0.002428,0.061676,131.531036,6.700511,0.616756,-1292.794312,0.062838,0.000000
53.860004,31.000381,-1292.794312,-0.001384,0.002461,0.062508,137.896591,7.024787,0.625083,-1292.794312,0.063455,0.000000
54.230003,31.399193,-1292.883301,-0.001345,0.002483,0.063064,139.670578,7.115159,0.630639,-1292.883301,0.064069,0.000000
54.600002,31.878807,-1292.883301,-0.001337,0.002503,0.063576,141.804016,7.223841,0.635756,-1292.883301,0.064685,0.000000
54.970001,32.857399,-1292.838867,-0.001311,0.002528,0.064218,146.157013,7.445593,0.642176,-1292.838867,0.065302,0.000000
55.340004,33.678108,-1292.838867,-0.001324,0.002554,0.064859,149.807709,7.631568,0.648595,-1292.838867,0.065918,0.000000
55.710003,35.245796,-1292.883301,-0.001306,0.002584,0.065632,156.781128,7.986812,0.656316,-1292.883301,0.066532,0.000000
56.080002,35.805473,-1292.883301,-0.001298,0.002605,0.066177,159.270706,8.113636,0.661766,-1292.883301,0.067158,0.000000
56.450005,36.645920,-1292.883301,-0.001276,0.002629,0.066776,163.009186,8.304084,0.667761,-1292.883301,0.067772,0.000000
56.820004,37.477425,-1292.927856,-0.001246,0.002650,0.067305,166.707916,8.492505,0.673045,-1292.927856,0.068389,0.000000
57.190002,38.423996,-1292.838867,-0.001259,0.002672,0.067877,170.918472,8.707002,0.678768,-1292.838867,0.069005,0.000000
57.560001,40.206169,-1292.883301,-0.001233,0.002701,0.068614,178.845978,9.110847,0.686141,-1292.883301,0.069621,0.000000
57.930004,41.367226,-1292.838867,-0.001224,0.002725,0.069212,184.010605,9.373947,0.692121,-1292.838867,0.070236,0.000000
58.300003,42.264648,-1292.883301,-0.001207,0.002747,0.069784,188.002548,9.577307,0.697844,-1292.883301,0.070852,0.000000
58.670002,43.656204,-1292.883301,-0.001194,0.002773,0.070444,194.192490,9.892637,0.704445,-1292.883301,0.071468,0.000000
59.040001,44.709274,-1292.838867,-0.001177,0.002792,0.070929,198.876785,10.131267,0.709289,-1292.838867,0.072083,0.000000
59.410004,45.705742,-1292.838867,-0.001177,0.002812,0.071433,203.309296,10.357069,0.714331,-1292.838867,0.072708,0.000000
59.780003,48.461670,-1292.838867,-0.001168,0.002849,0.072369,215.568268,10.981572,0.723687,-1292.838867,0.073322,0.000000
60.150002,49.588097,-1292.883301,-0.001160,0.002873,0.072976,220.578873,11.236823,0.729758,-1292.883301,0.073939,0.000000
60.520004,51.053757,-1292.927856,-0.001130,0.002898,0.073601,227.098450,11.568947,0.736011,-1292.927856,0.074555,0.000000
60.890003,52.650856,-1292.838867,-0.001112,0.002919,0.074155,234.202698,11.930854,0.741552,-1292.838867,0.075171,0.000000
61.260002,53.439545,-1292.883301,-0.001125,0.002935,0.074555,237.710968,12.109573,0.745549,-1292.883301,0.075786,0.000000
61.630001,56.116531,-1292.838867,-0.001112,0.002972,0.075483,249.618805,12.716187,0.754829,-1292.838867,0.076402,0.000000
62.000004,57.748268,-1292.883301,-0.001108,0.002995,0.076072,256.877136,13.085944,0.760718,-1292.883301,0.077018,0.000000
62.370003,59.118973,-1292.927856,-0.001082,0.003014,0.076567,262.974335,13.396551,0.765669,-1292.927856,0.077633,0.000000
62.740002,61.200157,-1292.883301,-0.001069,0.003041,0.077244,272.231903,13.868154,0.772436,-1292.883301,0.078258,0.000000
63.110004,62.296051,-1292.883301,-0.001078,0.003060,0.077728,277.106689,14.116487,0.777281,-1292.883301,0.078874,0.000000
63.480003,64.771950,-1292.794312,-0.001061,0.003090,0.078491,288.120026,14.677533,0.784912,-1292.794312,0.079489,0.000000
63.850002,66.029091,-1292.972290,-0.001048,0.003100,0.078735,293.712067,14.962405,0.787349,-1292.972290,0.078977,0.000000
64.220001,65.302589,-1292.972290,-0.001030,0.003099,0.078726,290.480438,14.797779,0.787258,-1292.972290,294.500488,0.000000
64.590004,65.525261,-1292.927856,-0.001030,0.003113,0.079065,291.470917,14.848237,0.790649,-1292.927856,294.500488,0.000000
64.960007,65.152153,-1292.883301,-0.001026,0.003115,0.079116,289.811249,14.763689,0.791164,-1292.883301,294.500488,0.000000
65.330002,65.215828,-1292.883301,-0.001013,0.003119,0.079221,290.094482,14.778117,0.792209,-1292.883301,294.500488,0.000000
65.700005,65.117897,-1292.927856,-0.001030,0.003121,0.079281,289.658875,14.755926,0.792814,-1292.927856,294.500488,0.000000
66.070000,65.175606,-1292.927856,-0.001026,0.003125,0.079368,289.915588,14.769003,0.793677,-1292.927856,294.500488,0.000000
66.440002,65.286949,-1292.927856,-0.001022,0.003129,0.079480,290.410858,14.794234,0.794798,-1292.927856,294.500488,0.000000
66.810005,65.155128,-1292.927856,-0.001013,0.003129,0.079480,289.824493,14.764363,0.794798,-1292.927856,294.500488,0.000000
67.180000,65.077293,-1292.883301,-0.001013,0.003131,0.079524,289.478271,14.746725,0.795237,-1292.883301,294.500488,0.000000
67.550003,64.997978,-1292.972290,-0.001022,0.003132,0.079558,289.125458,14.728752,0.795585,-1292.972290,294.500488,0.000000
67.920006,65.507759,-1292.972290,-0.001030,0.003139,0.079724,291.393066,14.844271,0.797235,-1292.972290,294.500488,0.000000
68.290001,65.366631,-1293.016724,-0.001013,0.003139,0.079724,290.765289,14.812291,0.797235,-1293.016724,294.500488,0.000000
68.660004,65.263863,-1292.972290,-0.001009,0.003139,0.079724,290.308167,14.789002,0.797235,-1292.972290,294.500488,0.000000
69.030006,65.214333,-1292.838867,-0.001013,0.003140,0.079767,290.087830,14.777779,0.797674,-1292.838867,294.500488,0.000000
69.400002,65.217690,-1292.883301,-0.001026,0.003142,0.079810,290.102783,14.778540,0.798098,-1292.883301,294.500488,0.000000
69.770004,65.149910,-1292.972290,-0.001009,0.003142,0.079810,289.801270,14.763181,0.798098,-1292.972290,294.500488,0.000000
70.140007,65.052345,-1292.972290,-0.001009,0.003142,0.079819,289.367279,14.741073,0.798189,-1292.972290,294.500488,0.000000
70.510002,65.502174,-1293.061279,-0.001013,0.003149,0.079984,291.368225,14.843005,0.799839,-1293.061279,294.500488,0.000000
70.880005,65.501060,-1292.972290,-0.001005,0.003149,0.079984,291.363281,14.842752,0.799839,-1292.972290,294.500488,0.000000
71.250000,65.393822,-1292.972290,-0.001009,0.003149,0.079984,290.886261,14.818452,0.799839,-1292.972290,294.500488,0.000000
71.620003,65.319710,-1292.927856,-0.001000,0.003149,0.079984,290.556580,14.801658,0.799839,-1292.927856,294.500488,0.000000
71.990005,65.256416,-1292.927856,-0.001009,0.003149,0.079984,290.275024,14.787314,0.799839,-1292.927856,294.500488,0.000000
72.360001,65.192360,-1293.016724,-0.000996,0.003149,0.079991,289.990112,14.772799,0.799915,-1293.016724,294.500488,0.000000
72.730003,65.097038,-1293.016724,-0.001009,0.003149,0.079991,289.566101,14.751200,0.799915,-1293.016724,294.500488,0.000000
73.100006,65.696922,-1292.927856,-0.000992,0.003157,0.080182,292.234497,14.887135,0.801822,-1292.927856,294.500488,0.000000
73.470001,65.692085,-1292.972290,-0.000996,0.003157,0.080182,292.212982,14.886039,0.801822,-1292.972290,294.500488,0.000000
73.840004,65.614265,-1293.061279,-0.001000,0.003157,0.080182,291.866821,14.868405,0.801822,-1293.061279,294.500488,0.000000
74.210007,65.584465,-1293.016724,-0.001000,0.003157,0.080182,291.734283,14.861651,0.801822,-1293.016724,294.500488,0.000000
74.580002,65.536812,-1293.061279,-0.000992,0.003157,0.080182,291.522308,14.850854,0.801822,-1293.061279,294.500488,0.000000
74.950005,65.490257,-1292.927856,-0.000983,0.003157,0.080182,291.315216,14.840305,0.801822,-1292.927856,294.500488,0.000000
75.320007,65.396431,-1292.927856,-0.001000,0.003157,0.080182,290.897858,14.819043,0.801822,-1292.927856,294.500488,0.000000
75.690002,65.342796,-1292.972290,-0.000992,0.003157,0.080182,290.659271,14.806889,0.801822,-1292.972290,294.500488,0.000000
76.060005,65.301094,-1292.927856,-0.001005,0.003157,0.080182,290.473785,14.797440,0.801822,-1292.927856,294.500488,0.000000
76.430000,65.252312,-1293.016724,-0.000992,0.003157,0.080182,290.256775,14.786386,0.801822,-1293.016724,294.500488,0.000000
76.800003,65.195351,-1292.972290,-0.000987,0.003157,0.080182,290.003418,14.773478,0.801822,-1292.972290,294.500488,0.000000
77.170006,65.129799,-1292.972290,-0.000979,0.003157,0.080182,289.711823,14.758624,0.801822,-1292.972290,294.500488,0.000000
77.540001,65.075432,-1293.016724,-0.001005,0.003157,0.080182,289.469971,14.746304,0.801822,-1293.016724,294.500488,0.000000
77.910004,65.015862,-1292.972290,-0.001005,0.003157,0.080191,289.204987,14.732804,0.801913,-1292.972290,294.500488,0.000000
78.280006,64.978249,-1293.016724,-0.000987,0.003157,0.080191,289.037689,14.724281,0.801913,-1293.016724,294.500488,0.000000
78.650002,64.948830,-1292.972290,-0.001009,0.003157,0.080191,288.906830,14.717615,0.801913,-1292.972290,294.500488,0.000000
79.020004,64.881813,-1292.883301,-0.001000,0.003157,0.080191,288.608704,14.702429,0.801913,-1292.883301,294.500488,0.000000
79.390007,64.832283,-1293.016724,-0.001000,0.003157,0.080200,288.388397,14.691205,0.802004,-1293.016724,294.500488,0.000000
79.760002,64.795036,-1293.016724,-0.000996,0.003157,0.080200,288.222717,14.682765,0.802004,-1293.016724,294.500488,0.000000
80.130005,64.755577,-1292.927856,-0.001005,0.003157,0.080200,288.047180,14.673823,0.802004,-1292.927856,294.500488,0.000000
80.500008,64.715721,-1293.016724,-0.001005,0.003157,0.080200,287.869904,14.664792,0.802004,-1293.016724,294.500488,0.000000
80.870003,64.679985,-1292.883301,-0.000983,0.003159,0.080244,287.710937,14.656693,0.802443,-1292.883301,294.500488,0.000000
81.240005,66.306877,-1292.972290,-0.001005,0.003165,0.080391,294.947723,15.025352,0.803912,-1292.972290,294.500488,0.000000
81.610001,66.262566,-1292.927856,-0.001005,0.003165,0.080382,294.750610,15.015312,0.803821,-1292.927856,294.500488,0.000000
81.980003,66.210808,-1293.016724,-0.000992,0.003165,0.080382,294.520386,15.003584,0.803821,-1293.016724,294.500488,0.000000
82.350006,66.148613,-1293.061279,-0.000979,0.003164,0.080373,294.243713,14.989491,0.803730,-1293.061279,294.500488,0.000000
82.720001,66.112495,-1293.016724,-0.000992,0.003164,0.080373,294.083069,14.981305,0.803730,-1293.016724,294.500488,0.000000
83.090004,66.051048,-1292.927856,-0.000992,0.003164,0.080373,293.809723,14.967381,0.803730,-1292.927856,294.500488,0.000000
83.460007,66.027229,-1292.972290,-0.000987,0.003164,0.080373,293.703796,14.961985,0.803730,-1292.972290,294.500488,0.000000
83.830002,65.952003,-1293.016724,-0.000992,0.003164,0.080373,293.369171,14.944938,0.803730,-1293.016724,294.500488,0.000000
84.200005,65.955727,-1293.016724,-0.000996,0.003164,0.080373,293.385712,14.945782,0.803730,-1293.016724,294.500488,0.000000
84.570007,65.845512,-1292.972290,-0.000987,0.003164,0.080373,292.895477,14.920807,0.803730,-1292.972290,294.500488,0.000000
84.940002,65.824287,-1292.927856,-0.000979,0.003164,0.080373,292.801056,14.915997,0.803730,-1292.927856,294.500488,0.000000
85.310005,65.841408,-1293.016724,-0.000987,0.003164,0.080373,292.877197,14.919876,0.803730,-1293.016724,294.500488,0.000000
85.680000,65.784813,-1293.061279,-0.000979,0.003164,0.080373,292.625458,14.907052,0.803730,-1293.061279,294.500488,0.000000
86.050003,65.772148,-1293.016724,-0.001000,0.003164,0.080373,292.569122,14.904181,0.803730,-1293.016724,294.500488,0.000000
86.420006,65.749062,-1293.016724,-0.000992,0.003164,0.080373,292.466431,14.898951,0.803730,-1293.016724,294.500488,0.000000
86.790001,65.674965,-1292.972290,-0.000992,0.003164,0.080373,292.136841,14.882160,0.803730,-1292.972290,294.500488,0.000000
87.160004,65.626930,-1292.927856,-0.000979,0.003164,0.080373,291.923157,14.871275,0.803730,-1292.927856,294.500488,0.000000
87.530006,65.593040,-1292.972290,-0.000992,0.003164,0.080373,291.772430,14.863595,0.803730,-1292.972290,294.500488,0.000000
87.900002,65.571434,-1293.061279,-0.000987,0.003164,0.080373,291.676300,14.858700,0.803730,-1293.061279,294.500488,0.000000
88.270004,65.552452,-1293.061279,-0.000983,0.003164,0.080373,291.591858,14.854398,0.803730,-1293.061279,294.500488,0.000000
88.640007,65.521919,-1292.972290,-0.000979,0.003164,0.080373,291.456055,14.847479,0.803730,-1292.972290,294.500488,0.000000
89.010002,65.505150,-1293.016724,-0.000979,0.003164,0.080373,291.381470,14.843679,0.803730,-1293.016724,294.500488,0.000000
89.380005,65.472389,-1293.016724,-0.000983,0.003164,0.080373,291.235718,14.836256,0.803730,-1293.016724,294.500488,0.000000
89.750008,65.416908,-1293.016724,-0.000987,0.003164,0.080373,290.988953,14.823683,0.803730,-1293.016724,294.500488,0.000000
90.120003,65.379662,-1293.016724,-0.000987,0.003164,0.080373,290.823273,14.815243,0.803730,-1293.016724,294.500488,0.000000
90.490005,65.363289,-1293.016724,-0.000983,0.003164,0.080373,290.750427,14.811533,0.803730,-1293.016724,294.500488,0.000000
90.860001,65.337212,-1292.883301,-0.000987,0.003164,0.080373,290.634430,14.805623,0.803730,-1292.883301,294.500488,0.000000
91.230003,65.310036,-1292.972290,-0.000987,0.003164,0.080373,290.513550,14.799465,0.803730,-1292.972290,294.500488,0.000000
91.600006,65.295891,-1292.972290,-0.001000,0.003164,0.080373,290.450623,14.796261,0.803730,-1292.972290,294.500488,0.000000
91.970001,65.277641,-1293.016724,-0.000992,0.003164,0.080373,290.369446,14.792125,0.803730,-1293.016724,294.500488,0.000000
92.340004,65.250084,-1293.105713,-0.000983,0.003164,0.080373,290.246857,14.785880,0.803730,-1293.105713,294.500488,0.000000
92.710007,65.225883,-1293.016724,-0.000983,0.003164,0.080373,290.139221,14.780396,0.803730,-1293.016724,294.500488,0.000000
93.080002,65.200188,-1293.016724,-0.000987,0.003164,0.080373,290.024933,14.774573,0.803730,-1293.016724,294.500488,0.000000
93.450005,65.176720,-1293.016724,-0.001000,0.003164,0.080373,289.920532,14.769256,0.803730,-1293.016724,294.500488,0.000000
93.820007,65.145073,-1293.016724,-0.000970,0.003164,0.080373,289.779755,14.762084,0.803730,-1293.016724,294.500488,0.000000
94.190002,65.093315,-1293.016724,-0.000966,0.003164,0.080373,289.549530,14.750356,0.803730,-1293.016724,294.500488,0.000000
94.560005,65.080284,-1293.016724,-0.000970,0.003164,0.080373,289.491577,14.747403,0.803730,-1293.016724,294.500488,0.000000
94.930008,65.074318,-1293.016724,-0.000983,0.003164,0.080373,289.465027,14.746051,0.803730,-1293.016724,294.500488,0.000000
95.300003,65.042671,-1292.972290,-0.000987,0.003164,0.080373,289.324249,14.738880,0.803730,-1292.972290,294.500488,0.000000
95.670006,65.026283,-1292.972290,-0.000987,0.003164,0.080373,289.251343,14.735167,0.803730,-1292.972290,294.500488,0.000000
96.040001,65.003578,-1293.061279,-0.000987,0.003165,0.080382,289.150360,14.730021,0.803821,-1293.061279,294.500488,0.000000
96.410004,65.676826,-1293.061279,-0.000979,0.003178,0.080729,292.145111,14.882582,0.807288,-1293.061279,294.500488,0.000000
96.780006,65.679802,-1293.016724,-0.000970,0.003176,0.080677,292.158356,14.883256,0.806773,-1293.016724,294.500488,0.000000
97.150002,65.644417,-1293.016724,-0.000983,0.003176,0.080677,292.000946,14.875237,0.806773,-1293.016724,294.500488,0.000000
97.520004,65.635490,-1293.016724,-0.000983,0.003176,0.080677,291.961243,14.873215,0.806773,-1293.016724,294.500488,0.000000
97.890007,65.612770,-1293.016724,-0.000970,0.003176,0.080677,291.860168,14.868067,0.806773,-1293.016724,294.500488,0.000000
98.260002,65.593407,-1293.061279,-0.000979,0.003176,0.080677,291.774048,14.863678,0.806773,-1293.061279,294.500488,0.000000
98.630005,65.581871,-1293.061279,-0.000983,0.003176,0.080677,291.722717,14.861064,0.806773,-1293.061279,294.500488,0.000000
99.000008,65.573677,-1292.972290,-0.000979,0.003176,0.080677,291.686279,14.859208,0.806773,-1292.972290,294.500488,0.000000
99.370003,65.566597,-1293.061279,-0.000979,0.003176,0.080677,291.654785,14.857604,0.806773,-1293.061279,294.500488,0.000000
99.740005,65.552071,-1293.061279,-0.000983,0.003176,0.080677,291.590179,14.854312,0.806773,-1293.061279,294.500488,0.000000
100.110008,65.525642,-1293.016724,-0.000979,0.003176,0.080677,291.472626,14.848323,0.806773,-1293.016724,294.500488,0.000000
100.480003,65.521919,-1292.972290,-0.000983,0.003176,0.080677,291.456055,14.847479,0.806773,-1292.972290,294.500488,0.000000
100.850006,65.509621,-1293.016724,-0.000970,0.003176,0.080677,291.401337,14.844692,0.806773,-1293.016724,294.500488,0.000000
101.220001,65.486916,-1293.061279,-0.000983,0.003176,0.080677,291.300354,14.839547,0.806773,-1293.061279,294.500488,0.000000
101.590004,65.460838,-1293.105713,-0.000979,0.003176,0.080677,291.184357,14.833637,0.806773,-1293.105713,294.500488,0.000000
101.960007,65.454140,-1293.105713,-0.000987,0.003176,0.080677,291.154541,14.832120,0.806773,-1293.105713,294.500488,0.000000
102.330002,65.425102,-1293.105713,-0.000974,0.003176,0.080677,291.025391,14.825541,0.806773,-1293.105713,294.500488,0.000000
102.700005,65.406853,-1293.016724,-0.000979,0.003176,0.080677,290.944214,14.821404,0.806773,-1293.016724,294.500488,0.000000
103.070007,65.383766,-1293.105713,-0.000957,0.003176,0.080677,290.841522,14.816174,0.806773,-1293.105713,294.500488,0.000000
103.440002,65.355461,-1293.105713,-0.000974,0.003176,0.080677,290.715607,14.809759,0.806773,-1293.105713,294.500488,0.000000
103.810005,65.343178,-1293.194702,-0.000974,0.003176,0.080677,290.660980,14.806976,0.806773,-1293.194702,294.500488,0.000000
104.180008,65.339821,-1293.105713,-0.000979,0.003176,0.080677,290.646027,14.806215,0.806773,-1293.105713,294.500488,0.000000
104.550003,65.325676,-1293.016724,-0.000966,0.003176,0.080677,290.583130,14.803010,0.806773,-1293.016724,294.500488,0.000000
104.920006,65.320839,-1293.105713,-0.000992,0.003176,0.080677,290.561615,14.801914,0.806773,-1293.105713,294.500488,0.000000
105.290009,65.307793,-1293.061279,-0.000983,0.003176,0.080677,290.503571,14.798957,0.806773,-1293.061279,294.500488,0.000000
105.660004,65.280983,-1293.105713,-0.000966,0.003176,0.080677,290.384308,14.792882,0.806773,-1293.105713,294.500488,0.000000
106.030006,65.272423,-1293.061279,-0.000974,0.003176,0.080677,290.346252,14.790943,0.806773,-1293.061279,294.500488,0.000000
106.400002,65.269066,-1293.061279,-0.000970,0.003176,0.080677,290.331299,14.790182,0.806773,-1293.061279,294.500488,0.000000
106.770004,65.266090,-1293.061279,-0.000996,0.003177,0.080703,290.318085,14.789508,0.807030,-1293.061279,294.500488,0.000000
107.140007,65.257164,-1293.061279,-0.000987,0.003177,0.080703,290.278351,14.787484,0.807030,-1293.061279,294.500488,0.000000
107.510002,65.258644,-1293.061279,-0.000987,0.003177,0.080703,290.284943,14.787820,0.807030,-1293.061279,294.500488,0.000000
107.880005,65.250832,-1293.061279,-0.000979,0.003177,0.080703,290.250183,14.786049,0.807030,-1293.061279,294.500488,0.000000
108.250008,65.234810,-1293.105713,-0.000974,0.003177,0.080703,290.178925,14.782419,0.807030,-1293.105713,294.500488,0.000000
108.620003,65.220299,-1293.016724,-0.000966,0.003177,0.080703,290.114380,14.779131,0.807030,-1293.016724,294.500488,0.000000
108.990005,65.225136,-1293.016724,-0.000979,0.003177,0.080703,290.135895,14.780228,0.807030,-1293.016724,294.500488,0.000000
109.360008,65.195351,-1293.061279,-0.000987,0.003177,0.080703,290.003418,14.773478,0.807030,-1293.061279,294.500488,0.000000
109.730003,65.187523,-1293.105713,-0.000974,0.003177,0.080703,289.968597,14.771704,0.807030,-1293.105713,294.500488,0.000000
110.100006,65.170021,-1293.105713,-0.000974,0.003177,0.080703,289.890747,14.767738,0.807030,-1293.105713,294.500488,0.000000
110.470009,65.157738,-1293.105713,-0.000979,0.003178,0.080712,289.836090,14.764955,0.807121,-1293.105713,294.500488,0.000000
110.840004,65.133156,-1293.016724,-0.000987,0.003178,0.080712,289.726746,14.759384,0.807121,-1293.016724,294.500488,0.000000
111.210007,65.127571,-1293.061279,-0.000979,0.003178,0.080712,289.701904,14.758119,0.807121,-1293.061279,294.500488,0.000000
111.580002,65.110435,-1293.105713,-0.000983,0.003178,0.080712,289.625671,14.754235,0.807121,-1293.105713,294.500488,0.000000
111.950005,65.098152,-1293.061279,-0.000970,0.003178,0.080712,289.571045,14.751452,0.807121,-1293.061279,294.500488,0.000000
112.320007,65.086983,-1293.061279,-0.000970,0.003178,0.080712,289.521362,14.748921,0.807121,-1293.061279,294.500488,0.000000
112.690002,65.085121,-1293.061279,-0.000979,0.003178,0.080712,289.513092,14.748499,0.807121,-1293.061279,294.500488,0.000000
113.060005,65.050117,-1293.016724,-0.000987,0.003178,0.080712,289.357361,14.740567,0.807121,-1293.016724,294.500488,0.000000
113.430008,65.051979,-1293.150269,-0.000983,0.003178,0.080712,289.365662,14.740989,0.807121,-1293.150269,294.500488,0.000000
113.800003,65.051231,-1293.061279,-0.000970,0.003178,0.080712,289.362335,14.740820,0.807121,-1293.061279,294.500488,0.000000
114.170006,65.037834,-1292.972290,-0.000966,0.003178,0.080712,289.302734,14.737784,0.807121,-1292.972290,294.500488,0.000000
114.540009,65.095543,-1293.061279,-0.000966,0.003179,0.080756,289.559448,14.750860,0.807560,-1293.061279,294.500488,0.000000
114.910004,65.119011,-1293.061279,-0.000979,0.003180,0.080773,289.663818,14.756179,0.807727,-1293.061279,294.500488,0.000000
115.280006,65.145821,-1293.194702,-0.000966,0.003181,0.080789,289.783081,14.762254,0.807893,-1293.194702,294.500488,0.000000
115.650009,65.184166,-1293.105713,-0.000974,0.003181,0.080789,289.953644,14.770943,0.807893,-1293.105713,294.500488,0.000000
116.020004,65.177467,-1293.105713,-0.000979,0.003181,0.080789,289.923859,14.769425,0.807893,-1293.105713,294.500488,0.000000
116.390007,65.191246,-1293.061279,-0.000983,0.003181,0.080789,289.985138,14.772547,0.807893,-1293.061279,294.500488,0.000000
116.760002,65.190880,-1293.061279,-0.000974,0.003181,0.080789,289.983521,14.772465,0.807893,-1293.061279,294.500488,0.000000
117.130005,65.189018,-1293.061279,-0.000992,0.003181,0.080789,289.975250,14.772042,0.807893,-1293.061279,294.500488,0.000000
117.500008,65.167046,-1293.150269,-0.000974,0.003181,0.080789,289.877502,14.767064,0.807893,-1293.150269,294.500488,0.000000
117.870003,65.172997,-1293.150269,-0.000966,0.003181,0.080789,289.903961,14.768412,0.807893,-1293.150269,294.500488,0.000000
118.240005,65.168526,-1293.061279,-0.000966,0.003181,0.080789,289.884094,14.767399,0.807893,-1293.061279,294.500488,0.000000
118.610008,65.167793,-1293.061279,-0.000983,0.003181,0.080789,289.880829,14.767234,0.807893,-1293.061279,294.500488,0.000000
118.980003,65.153267,-1293.194702,-0.000974,0.003181,0.080789,289.816193,14.763942,0.807893,-1293.194702,294.500488,0.000000
119.350006,65.139122,-1293.194702,-0.000983,0.003181,0.080789,289.753296,14.760736,0.807893,-1293.194702,294.500488,0.000000
119.720009,65.141350,-1293.150269,-0.000970,0.003181,0.080789,289.763184,14.761241,0.807893,-1293.150269,294.500488,0.000000
120.090004,65.130928,-1293.105713,-0.000974,0.003181,0.080789,289.716827,14.758880,0.807893,-1293.105713,294.500488,0.000000
120.460007,65.114540,-1293.150269,-0.000970,0.003181,0.080798,289.643951,14.755165,0.807984,-1293.150269,294.500488,0.000000
120.830009,65.117149,-1293.150269,-0.000987,0.003181,0.080798,289.655548,14.755756,0.807984,-1293.150269,294.500488,0.000000
121.200005,65.111183,-1293.150269,-0.000970,0.003181,0.080808,289.628998,14.754405,0.808075,-1293.150269,294.500488,0.000000
121.570007,65.111183,-1293.194702,-0.000983,0.003181,0.080808,289.628998,14.754405,0.808075,-1293.194702,294.500488,0.000000
121.940002,65.099648,-1293.061279,-0.000970,0.003182,0.080817,289.577698,14.751791,0.808166,-1293.061279,294.500488,0.000000
122.310005,65.088478,-1293.061279,-0.000961,0.003182,0.080817,289.528015,14.749260,0.808166,-1293.061279,294.500488,0.000000
122.680008,65.113792,-1293.150269,-0.000966,0.003182,0.080824,289.640625,14.754995,0.808242,-1293.150269,294.500488,0.000000
123.050003,65.111183,-1293.150269,-0.000979,0.003182,0.080824,289.628998,14.754405,0.808242,-1293.150269,294.500488,0.000000
123.420006,65.113792,-1293.150269,-0.000979,0.003182,0.080824,289.640625,14.754995,0.808242,-1293.150269,294.500488,0.000000
123.790009,65.120491,-1293.150269,-0.000979,0.003182,0.080833,289.670410,14.756514,0.808332,-1293.150269,294.500488,0.000000
124.160004,65.127937,-1293.194702,-0.000983,0.003182,0.080833,289.703522,14.758202,0.808332,-1293.194702,294.500488,0.000000
124.530006,65.070976,-1293.150269,-0.000987,0.003174,0.080617,289.450165,14.745294,0.806167,-1293.150269,0.080798,0.000000
124.900009,65.052345,-1293.239136,-0.000979,0.003166,0.080426,289.367279,14.741073,0.804260,-1293.239136,0.080175,0.000000
125.270004,64.996117,-1293.105713,-0.000966,0.003152,0.080061,289.117157,14.728331,0.800611,-1293.105713,0.079558,0.000000
125.640007,64.983086,-1293.150269,-0.000957,0.003123,0.079333,289.059204,14.725378,0.793329,-1293.150269,0.078942,0.000000
126.010010,64.938026,-1293.061279,-0.000966,0.003105,0.078865,288.858765,14.715167,0.788651,-1293.061279,0.078328,0.000000
126.380005,64.928352,-1293.150269,-0.000966,0.003078,0.078188,288.815735,14.712975,0.781884,-1293.150269,0.077711,0.000000
126.750008,64.896324,-1293.194702,-0.000970,0.003053,0.077546,288.673279,14.705717,0.775464,-1293.194702,0.077095,0.000000
127.120003,64.921654,-1293.194702,-0.000957,0.003036,0.077121,288.785950,14.711456,0.771210,-1293.194702,0.076481,0.000000
127.490005,64.884041,-1293.194702,-0.000953,0.003012,0.076497,288.618622,14.702934,0.764973,-1293.194702,0.075864,0.000000
127.860008,64.845314,-1293.105713,-0.000957,0.002996,0.076090,288.446350,14.694159,0.760900,-1293.105713,0.075248,0.000000
128.230011,64.771217,-1293.194702,-0.000949,0.002958,0.075144,288.116760,14.677368,0.751438,-1293.194702,0.074625,0.000000
128.600006,64.686317,-1293.194702,-0.000953,0.002939,0.074641,287.739105,14.658129,0.746412,-1293.194702,0.074008,0.000000
128.970001,63.922203,-1293.194702,-0.000949,0.002913,0.073992,284.340149,14.484979,0.739917,-1293.194702,0.073392,0.000000
129.340012,63.302940,-1293.150269,-0.000940,0.002899,0.073643,281.585541,14.344651,0.736435,-1293.150269,0.072777,0.000000
129.710007,62.067039,-1293.194702,-0.000923,0.002873,0.072985,276.087982,14.064592,0.729849,-1293.194702,0.072161,0.000000
130.080002,60.912315,-1293.105713,-0.000931,0.002855,0.072508,270.951508,13.802928,0.725080,-1293.105713,0.071545,0.000000
130.450012,59.355797,-1293.194702,-0.000927,0.002830,0.071875,264.027771,13.450215,0.718752,-1293.194702,0.070929,0.000000
130.820007,57.564690,-1293.194702,-0.000918,0.002808,0.071329,256.060516,13.044345,0.713286,-1293.194702,0.070314,0.000000
131.190002,55.689049,-1293.194702,-0.000914,0.002786,0.070765,247.717255,12.619319,0.707654,-1293.194702,0.069698,0.000000
131.560013,53.169945,-1293.061279,-0.000918,0.002758,0.070045,236.511734,12.048481,0.700448,-1293.061279,0.069074,0.000000
131.930008,51.214989,-1293.150269,-0.000923,0.002741,0.069621,227.815643,11.605482,0.696209,-1293.150269,0.068458,0.000000
132.300003,47.820442,-1293.194702,-0.000927,0.002707,0.068761,212.715958,10.836267,0.687609,-1293.194702,0.067842,0.000000
132.670013,45.526627,-1293.194702,-0.000931,0.002686,0.068233,202.512543,10.316481,0.682326,-1293.194702,0.067227,0.000000
133.040009,43.316597,-1293.194702,-0.000910,0.002669,0.067781,192.681839,9.815681,0.677814,-1293.194702,0.066611,0.000000
133.410004,40.434433,-1293.194702,-0.000927,0.002639,0.067037,179.861343,9.162573,0.670365,-1293.194702,0.065995,0.000000
133.779999,37.217140,-1293.194702,-0.000923,0.002613,0.066376,165.550110,8.433525,0.663765,-1293.194702,0.065379,0.000000
134.150009,34.497330,-1293.150269,-0.000918,0.002586,0.065692,153.451782,7.817207,0.656922,-1293.150269,0.064764,0.000000
134.520004,31.785339,-1293.239136,-0.000914,0.002564,0.065127,141.388245,7.202661,0.651274,-1293.239136,0.064139,0.000000
134.889999,29.062553,-1293.105713,-0.000914,0.002539,0.064486,129.276688,6.585669,0.644855,-1293.105713,0.063524,0.000000
135.260010,26.797783,-1293.150269,-0.000910,0.002519,0.063983,119.202492,6.072464,0.639829,-1293.150269,0.062908,0.000000
135.630005,23.860138,-1293.150269,-0.000910,0.002493,0.063315,106.135193,5.406785,0.633152,-1293.150269,0.062292,0.000000
136.000000,20.857323,-1293.194702,-0.000927,0.002465,0.062622,92.778008,4.726337,0.626218,-1293.194702,0.061676,0.000000
136.370010,18.366898,-1293.194702,-0.000931,0.002442,0.062024,81.700043,4.161999,0.620238,-1293.194702,0.061061,0.000000
136.740005,15.265411,-1293.194702,-0.000927,0.002414,0.061312,67.903938,3.459192,0.613123,-1293.194702,0.060445,0.000000
137.110001,13.546165,-1293.150269,-0.000918,0.002401,0.060975,60.256355,3.069605,0.609747,-1293.150269,0.059829,0.000000
137.480011,10.564949,-1293.194702,-0.000918,0.002371,0.060219,46.995239,2.394052,0.602192,-1293.194702,0.059214,0.000000
137.850006,7.948662,-1293.239136,-0.000931,0.002347,0.059621,35.357414,1.801192,0.596212,-1293.239136,0.058589,0.000000
138.220001,5.081764,-1293.194702,-0.000905,0.002320,0.058928,22.604816,1.151544,0.589278,-1293.194702,0.057974,0.000000
138.590012,3.375931,-1293.194702,-0.000923,0.002303,0.058493,15.016891,0.764997,0.584933,-1293.194702,0.057358,0.000000
138.960007,1.192337,-1293.150269,-0.000914,0.002282,0.057974,5.303780,0.270187,0.579740,-1293.150269,0.056742,0.000000
139.330002,-1.049347,-1293.150269,-0.000918,0.002251,0.057184,-4.667728,-0.237785,0.571837,-1293.150269,0.056125,0.000000
139.700012,-0.088997,-1293.194702,-0.000931,0.002230,0.056646,-0.395878,-0.020167,0.566463,-1293.194702,0.055511,0.000000
140.070007,-0.037979,-1293.194702,-0.000910,0.002203,0.055953,-0.168940,-0.008606,0.559529,-1293.194702,0.054895,0.000000
140.440002,-0.020851,-1293.194702,-0.000918,0.002180,0.055381,-0.092750,-0.004725,0.553806,-1293.194702,0.054278,0.000000
140.810013,0.011543,-1293.194702,-0.000914,0.002157,0.054799,0.051347,0.002616,0.547992,-1293.194702,0.053664,0.000000
141.180008,0.002235,-1293.194702,-0.000931,0.002134,0.054210,0.009944,0.000507,0.542103,-1293.194702,0.053038,0.000000
141.550003,-0.001862,-1293.150269,-0.000927,0.002110,0.053603,-0.008281,-0.000422,0.536032,-1293.150269,0.052422,0.000000
141.920013,-0.031654,-1293.194702,-0.000914,0.002087,0.053013,-0.140806,-0.007173,0.530128,-1293.194702,0.051808,0.000000
142.290009,-0.034256,-1293.239136,-0.000914,0.002056,0.052215,-0.152378,-0.007763,0.522149,-1293.239136,0.051191,0.000000
142.660004,-0.036491,-1293.194702,-0.000918,0.002032,0.051608,-0.162322,-0.008269,0.516078,-1293.194702,0.050575,0.000000
143.030014,-0.024948,-1293.194702,-0.000914,0.002009,0.051036,-0.110975,-0.005653,0.510355,-1293.194702,0.049961,0.000000
143.400009,-0.029045,-1293.239136,-0.000936,0.001984,0.050403,-0.129199,-0.006582,0.504027,-1293.239136,0.049344,0.000000
143.770004,-0.033516,-1293.194702,-0.000931,0.001959,0.049752,-0.149086,-0.007595,0.497517,-1293.194702,0.048728,0.000000
144.139999,-0.034630,-1293.194702,-0.000931,0.001931,0.049049,-0.154041,-0.007847,0.490492,-1293.194702,0.048114,0.000000
144.510010,-0.005585,-1293.194702,-0.000931,0.001905,0.048391,-0.024842,-0.001266,0.483906,-1293.194702,0.047488,0.000000
144.880005,-0.003723,-1293.194702,-0.000914,0.001891,0.048026,-0.016561,-0.000844,0.480258,-1293.194702,0.046872,0.000000
145.250000,-0.036491,-1293.239136,-0.000931,0.001864,0.047349,-0.162322,-0.008269,0.473490,-1293.239136,0.046257,0.000000
145.620010,-0.042076,-1293.239136,-0.000944,0.001840,0.046743,-0.187164,-0.009535,0.467435,-1293.239136,0.045641,0.000000
145.990005,-0.042824,-1293.283691,-0.000936,0.001811,0.046006,-0.190490,-0.009704,0.460062,-1293.283691,0.045025,0.000000
146.360001,-0.035751,-1293.194702,-0.000940,0.001794,0.045555,-0.159030,-0.008101,0.455550,-1293.194702,0.044410,0.000000
146.730011,-0.033882,-1293.194702,-0.000936,0.001775,0.045095,-0.150715,-0.007678,0.450948,-1293.194702,0.043794,0.000000
147.100006,-0.053246,-1293.194702,-0.000944,0.001744,0.044306,-0.236848,-0.012066,0.443060,-1293.194702,0.043178,0.000000
147.470001,-0.029419,-1293.239136,-0.000949,0.001714,0.043534,-0.130862,-0.006666,0.435339,-1293.239136,0.042563,0.000000
147.840012,-0.018250,-1293.239136,-0.000970,0.001687,0.042840,-0.081178,-0.004135,0.428405,-1293.239136,0.041938,0.000000
148.210007,-0.037613,-1293.194702,-0.000983,0.001663,0.042250,-0.167311,-0.008523,0.422500,-1293.194702,0.041322,0.000000
148.580002,-0.052505,-1293.150269,-0.000992,0.001644,0.041747,-0.233556,-0.011898,0.417474,-1293.150269,0.040707,0.000000
148.950012,-0.045799,-1293.150269,-0.001005,0.001622,0.041192,-0.203725,-0.010378,0.411918,-1293.150269,0.040091,0.000000
149.320007,-0.056229,-1293.194702,-0.001043,0.001597,0.040568,-0.250117,-0.012742,0.405680,-1293.194702,0.039475,0.000000
149.600006,0.001862,-1293.194702,-0.001056,0.001587,0.040308,0.008281,0.000422,0.403076,-1293.194702,0.040221,0.000000