File: Data/Sima compression/P1-15-1_10302024_170229.csv
Time (sec),S:Load (lbs),S:HL1 (DIM),S:LVDT (in),S:Position (in),Ch:Position (mm),Ch:Load (N),Ch:Stress (MPa),Ch:Strain (mm/mm),Ch:HL1 (DIM),Set Point (),Cycles ()
0.110000,-0.005585,-1293.639526,-0.004186,-0.004262,-0.108246,-0.024842,-0.001266,-1.082465,-1293.639526,-0.108134,0.000000
0.290000,-0.004837,-1293.639526,-0.004178,-0.004262,-0.108246,-0.021516,-0.001096,-1.082465,-1293.639526,-0.108134,0.000000
0.470000,0.026070,-1293.683960,-0.004178,-0.004228,-0.107388,0.115964,0.005907,-1.073881,-1293.683960,-0.106729,0.000000
0.650000,0.015266,-1293.639526,-0.004174,-0.004117,-0.104569,0.067908,0.003459,-1.045691,-1293.639526,-0.103729,0.000000
0.830000,0.030159,-1293.594971,-0.004156,-0.004004,-0.101690,0.134154,0.006834,-1.016895,-1293.594971,-0.100728,0.000000
1.010000,0.000374,-1293.639526,-0.004061,-0.003894,-0.098898,0.001663,0.000085,-0.988978,-1293.639526,-0.097727,0.000000
1.190000,0.001488,-1293.683960,-0.003936,-0.003780,-0.096018,0.006618,0.000337,-0.960182,-1293.683960,-0.094743,0.000000
1.370000,-0.021973,-1293.683960,-0.003829,-0.003664,-0.093071,-0.097739,-0.004979,-0.930706,-1293.683960,-0.091743,0.000000
1.550000,-0.007820,-1293.594971,-0.003686,-0.003542,-0.089975,-0.034786,-0.001772,-0.899745,-1293.594971,-0.088742,0.000000
1.730000,-0.028671,-1293.594971,-0.003553,-0.003421,-0.086904,-0.127536,-0.006497,-0.869042,-1293.594971,-0.085741,0.000000
1.910000,-0.005585,-1293.683960,-0.003445,-0.003300,-0.083808,-0.024842,-0.001266,-0.838082,-1293.683960,-0.082741,0.000000
2.090000,-0.024948,-1293.639526,-0.003341,-0.003186,-0.080920,-0.110975,-0.005653,-0.809195,-1293.639526,-0.079740,0.000000
2.270000,-0.010056,-1293.728516,-0.003229,-0.003076,-0.078137,-0.044729,-0.002279,-0.781369,-1293.728516,-0.076739,0.000000
2.450000,0.049156,-1293.594971,-0.003096,-0.002955,-0.075057,0.218658,0.011139,-0.750575,-1293.594971,-0.073739,0.000000
2.630000,0.158630,-1293.594971,-0.003001,-0.000001,-0.000018,0.705623,0.035946,-0.000182,-1293.594971,0.000182,0.000000
2.810000,0.150436,-1293.594971,-0.003005,-0.000001,-0.000026,0.669175,0.034089,-0.000257,-1293.594971,0.000182,0.000000
2.990000,0.091606,-1293.683960,-0.003014,-0.000001,-0.000035,0.407484,0.020758,-0.000348,-1293.683960,0.000182,0.000000
3.170000,0.182465,-1293.639526,-0.003014,-0.000001,-0.000026,0.811643,0.041347,-0.000257,-1293.639526,0.000329,0.000000
3.350000,0.162727,-1293.594971,-0.003014,-0.000001,-0.000026,0.723847,0.036875,-0.000257,-1293.594971,0.000633,0.000000
3.530000,0.155655,-1293.594971,-0.003001,-0.000001,-0.000026,0.692388,0.035272,-0.000257,-1293.594971,0.000936,0.000000
3.710000,0.135918,-1293.639526,-0.003005,-0.000001,-0.000026,0.604592,0.030799,-0.000257,-1293.639526,0.001231,0.000000
3.890000,0.126236,-1293.639526,-0.003009,0.000003,0.000086,0.561526,0.028605,0.000863,-1293.639526,0.001535,0.000000
4.070000,0.338112,-1293.683960,-0.002992,0.000031,0.000798,1.503997,0.076617,0.007979,-1293.683960,0.001829,0.000000
4.250000,0.482964,-1293.683960,-0.002979,0.000043,0.001084,2.148329,0.109441,0.010840,-1293.683960,0.002133,0.000000
4.430000,0.600639,-1293.683960,-0.002962,0.000053,0.001335,2.671777,0.136107,0.013353,-1293.683960,0.002436,0.000000
4.610000,1.058655,-1293.594971,-0.002945,0.000078,0.001977,4.709132,0.239895,0.019772,-1293.594971,0.002731,0.000000
4.790000,1.192337,-1293.683960,-0.002936,0.000084,0.002124,5.303780,0.270187,0.021241,-1293.683960,0.003035,0.000000
4.970000,1.336075,-1293.683960,-0.002936,0.000093,0.002359,5.943158,0.302759,0.023587,-1293.683960,0.003329,0.000000
5.150000,1.651100,-1293.594971,-0.002932,0.000104,0.002654,7.344460,0.374145,0.026540,-1293.594971,0.003633,0.000000
5.330000,1.868568,-1293.594971,-0.002910,0.000114,0.002887,8.311808,0.423424,0.028871,-1293.594971,0.003936,0.000000
5.510000,2.325836,-1293.683960,-0.002915,0.000127,0.003234,10.345836,0.527042,0.032338,-1293.683960,0.004232,0.000000
5.690000,2.790932,-1293.683960,-0.002889,0.000143,0.003624,12.414684,0.632434,0.036244,-1293.683960,0.004536,0.000000
5.870000,3.216927,-1293.683960,-0.002871,0.000156,0.003954,14.309604,0.728966,0.039545,-1293.683960,0.004830,0.000000
6.050000,3.397896,-1293.639526,-0.002876,0.000161,0.004101,15.114595,0.769974,0.041013,-1293.639526,0.005134,0.000000
6.230000,3.768410,-1293.639526,-0.002863,0.000172,0.004371,16.762724,0.853934,0.043708,-1293.639526,0.005429,0.000000
6.410000,4.088280,-1293.594971,-0.002863,0.000181,0.004596,18.185577,0.926417,0.045964,-1293.594971,0.005732,0.000000
6.590000,5.018837,-1293.728516,-0.002846,0.000203,0.005169,22.324902,1.137285,0.051687,-1293.728516,0.006036,0.000000
6.770000,5.409454,-1293.683960,-0.002824,0.000215,0.005464,24.062454,1.225800,0.054639,-1293.683960,0.006330,0.000000
6.950000,5.651871,-1293.728516,-0.002837,0.000224,0.005688,25.140776,1.280732,0.056879,-1293.728516,0.006634,0.000000
7.130000,6.170586,-1293.639526,-0.002828,0.000236,0.005983,27.448135,1.398275,0.059832,-1293.639526,0.006929,0.000000
7.310000,6.569023,-1293.639526,-0.002824,0.000245,0.006227,29.220474,1.488562,0.062269,-1293.639526,0.007232,0.000000
7.490000,7.096672,-1293.772949,-0.002807,0.000258,0.006548,31.567574,1.608129,0.065479,-1293.772949,0.007536,0.000000
7.670001,7.803062,-1293.639526,-0.002794,0.000274,0.006963,34.709755,1.768199,0.069627,-1293.639526,0.007830,0.000000
7.850000,8.357155,-1293.639526,-0.002790,0.000286,0.007267,37.174480,1.893758,0.072670,-1293.639526,0.008134,0.000000
8.030001,8.464401,-1293.550537,-0.002777,0.000291,0.007397,37.651539,1.918061,0.073972,-1293.550537,0.008430,0.000000
8.210000,8.950714,-1293.728516,-0.002768,0.000301,0.007649,39.814766,2.028261,0.076485,-1293.728516,0.008733,0.000000
8.390000,9.519333,-1293.683960,-0.002755,0.000315,0.007995,42.344109,2.157112,0.079952,-1293.683960,0.009037,0.000000
8.570001,9.922234,-1293.728516,-0.002772,0.000330,0.008377,44.136299,2.248410,0.083767,-1293.728516,0.009331,0.000000
8.750000,10.729912,-1293.639526,-0.002751,0.000339,0.008611,47.729031,2.431433,0.086114,-1293.639526,0.009635,0.000000
8.930000,11.024460,-1293.594971,-0.002738,0.000350,0.008888,49.039246,2.498178,0.088884,-1293.594971,0.009930,0.000000
9.110001,11.661591,-1293.639526,-0.002729,0.000363,0.009218,51.873344,2.642554,0.092185,-1293.639526,0.010233,0.000000
9.290001,12.014595,-1293.639526,-0.002721,0.000372,0.009444,53.443588,2.722546,0.094441,-1293.639526,0.010537,0.000000
9.470000,12.762321,-1293.639526,-0.002721,0.000388,0.009851,56.769642,2.891984,0.098513,-1293.639526,0.010831,0.000000
9.650001,13.532013,-1293.683960,-0.002695,0.000403,0.010224,60.193401,3.066398,0.102238,-1293.683960,0.011135,0.000000
9.830001,13.891724,-1293.594971,-0.002708,0.000412,0.010475,61.793472,3.147910,0.104751,-1293.594971,0.011430,0.000000
10.010000,13.935669,-1293.550537,-0.002695,0.000418,0.010614,61.988953,3.157868,0.106144,-1293.550537,0.011733,0.000000
10.190001,14.546730,-1293.683960,-0.002686,0.000431,0.010944,64.707085,3.296336,0.109444,-1293.683960,0.012036,0.000000
10.370001,14.769409,-1293.728516,-0.002695,0.000437,0.011109,65.697617,3.346796,0.111094,-1293.728516,0.012331,0.000000
10.550000,16.142349,-1293.683960,-0.002647,0.000461,0.011698,71.804756,3.657909,0.116984,-1293.683960,0.012635,0.000000
10.730000,16.337471,-1293.594971,-0.002643,0.000468,0.011898,72.672699,3.702124,0.118982,-1293.594971,0.012929,0.000000
10.910001,16.609673,-1293.639526,-0.002643,0.000476,0.012089,73.883514,3.763806,0.120890,-1293.639526,0.013234,0.000000
11.090000,17.158920,-1293.683960,-0.002630,0.000490,0.012445,76.326691,3.888267,0.124447,-1293.683960,0.013536,0.000000
11.270000,17.689178,-1293.772949,-0.002621,0.000502,0.012748,78.685394,4.008425,0.127475,-1293.772949,0.013832,0.000000
11.450001,18.175873,-1293.639526,-0.002630,0.000513,0.013034,80.850319,4.118712,0.130337,-1293.639526,0.014136,0.000000
11.630000,18.973495,-1293.639526,-0.002613,0.000529,0.013441,84.398323,4.299455,0.134409,-1293.639526,0.014430,0.000000
11.810000,19.482903,-1293.594971,-0.002587,0.000541,0.013736,86.664276,4.414889,0.137361,-1293.594971,0.014734,0.000000
11.990001,19.530563,-1293.683960,-0.002570,0.000549,0.013936,86.876282,4.425689,0.139360,-1293.683960,0.015037,0.000000
12.170001,19.856758,-1293.683960,-0.002583,0.000557,0.014136,88.327271,4.499606,0.141358,-1293.683960,0.015332,0.000000
12.350000,20.390747,-1293.594971,-0.002583,0.000572,0.014525,90.702576,4.620609,0.145249,-1293.594971,0.015636,0.000000
12.530001,21.290398,-1293.594971,-0.002544,0.000587,0.014916,94.704422,4.824473,0.149155,-1293.594971,0.015930,0.000000
12.710001,21.657928,-1293.594971,-0.002557,0.000596,0.015150,96.339279,4.907757,0.151502,-1293.594971,0.016234,0.000000
12.890000,22.174034,-1293.639526,-0.002539,0.000611,0.015515,98.635033,5.024708,0.155150,-1293.639526,0.016537,0.000000
13.070001,22.305855,-1293.639526,-0.002535,0.000619,0.015732,99.221397,5.054579,0.157315,-1293.639526,0.016832,0.000000
13.250001,22.665565,-1293.683960,-0.002535,0.000629,0.015965,100.821472,5.136091,0.159647,-1293.683960,0.017136,0.000000
13.430000,22.708015,-1293.683960,-0.002509,0.000634,0.016113,101.010300,5.145710,0.161131,-1293.683960,0.017430,0.000000
13.610001,23.418129,-1293.683960,-0.002514,0.000650,0.016511,104.169037,5.306624,0.165112,-1293.683960,0.017735,0.000000
13.790001,24.277199,-1293.683960,-0.002496,0.000666,0.016928,107.990372,5.501292,0.169276,-1293.683960,0.018037,0.000000
13.970000,24.135696,-1293.728516,-0.002483,0.000671,0.017032,107.360939,5.469227,0.170320,-1293.728516,0.018333,0.000000
14.150001,24.677864,-1293.728516,-0.002483,0.000685,0.017388,109.772621,5.592084,0.173878,-1293.728516,0.018637,0.000000
14.330001,25.300476,-1293.550537,-0.002458,0.000700,0.017778,112.542137,5.733170,0.177784,-1293.550537,0.018931,0.000000
14.510000,25.851585,-1293.594971,-0.002449,0.000714,0.018142,114.993591,5.858053,0.181418,-1293.594971,0.019235,0.000000
14.690001,26.665962,-1293.728516,-0.002436,0.000732,0.018602,118.616127,6.042593,0.186020,-1293.728516,0.019530,0.000000
14.870001,26.711395,-1293.728516,-0.002419,0.000739,0.018767,118.818222,6.052888,0.187670,-1293.728516,0.019833,0.000000
15.050001,26.920296,-1293.728516,-0.002423,0.000752,0.019096,119.747459,6.100226,0.190956,-1293.728516,0.020137,0.000000
15.230000,27.162712,-1293.639526,-0.002419,0.000760,0.019304,120.825775,6.155159,0.193045,-1293.639526,0.020431,0.000000
15.410001,26.947479,-1293.683960,-0.002389,0.000764,0.019400,119.868378,6.106386,0.193999,-1293.683960,0.020735,0.000000
15.590001,27.195854,-1293.683960,-0.002384,0.000776,0.019721,120.973198,6.162669,0.197208,-1293.683960,0.021030,0.000000
15.770000,28.462288,-1293.728516,-0.002371,0.000797,0.020240,126.606583,6.449646,0.202401,-1293.728516,0.021333,0.000000
15.950001,28.916580,-1293.594971,-0.002358,0.000810,0.020579,128.627380,6.552591,0.205792,-1293.594971,0.021637,0.000000
16.130001,28.555756,-1293.639526,-0.002350,0.000813,0.020640,127.022346,6.470827,0.206398,-1293.639526,0.021931,0.000000
16.310001,29.956245,-1293.639526,-0.002337,0.000839,0.021307,133.252029,6.788182,0.213074,-1293.639526,0.022235,0.000000
16.490002,30.266060,-1293.639526,-0.002320,0.000851,0.021619,134.630157,6.858387,0.216193,-1293.639526,0.022531,0.000000
16.670000,30.105194,-1293.728516,-0.002302,0.000859,0.021828,133.914597,6.821935,0.218282,-1293.728516,0.022834,0.000000
16.850000,30.147278,-1293.683960,-0.002311,0.000869,0.022061,134.101791,6.831471,0.220614,-1293.683960,0.023138,0.000000
17.030001,30.075409,-1293.683960,-0.002294,0.000876,0.022261,133.782104,6.815185,0.222612,-1293.683960,0.023432,0.000000
17.210001,30.548317,-1293.639526,-0.002272,0.000890,0.022617,135.885696,6.922348,0.226170,-1293.639526,0.023736,0.000000
17.390001,30.839890,-1293.683960,-0.002268,0.000903,0.022938,137.182678,6.988419,0.229380,-1293.683960,0.024031,0.000000
17.570002,30.703224,-1293.639526,-0.002264,0.000904,0.022973,136.574768,6.957450,0.229728,-1293.639526,0.024334,0.000000
17.750000,31.494514,-1293.683960,-0.002255,0.000923,0.023441,140.094604,7.136759,0.234406,-1293.683960,0.024638,0.000000
17.930000,32.170746,-1293.639526,-0.002220,0.000939,0.023857,143.102631,7.289995,0.238569,-1293.639526,0.024932,0.000000
18.110001,32.458588,-1293.594971,-0.002220,0.000951,0.024161,144.383011,7.355221,0.241613,-1293.594971,0.025236,0.000000
18.290001,33.349678,-1293.594971,-0.002199,0.000972,0.024681,148.346771,7.557145,0.246805,-1293.594971,0.025531,0.000000
18.470001,33.596931,-1293.639526,-0.002169,0.000983,0.024967,149.446609,7.613173,0.249667,-1293.639526,0.025834,0.000000
18.650002,33.512405,-1293.683960,-0.002160,0.000993,0.025227,149.070618,7.594019,0.252271,-1293.683960,0.026138,0.000000
18.830002,33.392876,-1293.639526,-0.002164,0.001001,0.025427,148.538925,7.566934,0.254269,-1293.639526,0.026432,0.000000
19.010000,33.590973,-1293.594971,-0.002147,0.001013,0.025739,149.420105,7.611823,0.257388,-1293.594971,0.026736,0.000000
19.190001,33.392876,-1293.594971,-0.002139,0.001018,0.025869,148.538925,7.566934,0.258690,-1293.594971,0.027032,0.000000
19.370001,33.792053,-1293.594971,-0.002130,0.001032,0.026216,150.314560,7.657389,0.262157,-1293.594971,0.027335,0.000000
19.550001,34.126076,-1293.639526,-0.002117,0.001046,0.026562,151.800369,7.733079,0.265624,-1293.639526,0.027639,0.000000
19.730001,34.774002,-1293.639526,-0.002104,0.001060,0.026927,154.682480,7.879901,0.269273,-1293.639526,0.027933,0.000000
19.910002,34.783310,-1293.550537,-0.002091,0.001068,0.027127,154.723892,7.882011,0.271271,-1293.550537,0.028237,0.000000
20.090000,34.715164,-1293.594971,-0.002065,0.001078,0.027378,154.420761,7.866569,0.273784,-1293.594971,0.028532,0.000000
20.270000,35.783134,-1293.639526,-0.002057,0.001098,0.027881,159.171326,8.108574,0.278811,-1293.639526,0.028835,0.000000
20.450001,35.885536,-1293.639526,-0.002048,0.001108,0.028149,159.626831,8.131779,0.281490,-1293.639526,0.029139,0.000000
20.630001,35.748131,-1293.639526,-0.002031,0.001118,0.028402,159.015625,8.100642,0.284019,-1293.639526,0.029433,0.000000
20.810001,35.827820,-1293.506104,-0.002005,0.001128,0.028644,159.370102,8.118700,0.286441,-1293.506104,0.029737,0.000000
20.990002,36.026665,-1293.594971,-0.002001,0.001139,0.028921,160.254608,8.163759,0.289211,-1293.594971,0.030032,0.000000
21.170000,36.173752,-1293.594971,-0.001988,0.001149,0.029191,160.908890,8.197089,0.291906,-1293.594971,0.030335,0.000000
21.350000,36.788162,-1293.683960,-0.001983,0.001164,0.029572,163.641922,8.336317,0.295721,-1293.683960,0.030638,0.000000
21.530001,36.789284,-1293.594971,-0.001970,0.001173,0.029798,163.646912,8.336571,0.297977,-1293.594971,0.030933,0.000000
21.710001,36.691719,-1293.594971,-0.001962,0.001182,0.030014,163.212921,8.314463,0.300142,-1293.594971,0.031237,0.000000
21.890001,36.873810,-1293.550537,-0.001940,0.001191,0.030240,164.022903,8.355724,0.302398,-1293.550537,0.031531,0.000000
22.070002,36.937485,-1293.683960,-0.001919,0.001200,0.030482,164.306137,8.370153,0.304820,-1293.683960,0.031836,0.000000
22.250002,39.261093,-1293.639526,-0.001901,0.001234,0.031340,174.642059,8.896690,0.313404,-1293.639526,0.032131,0.000000
22.430000,38.753922,-1293.639526,-0.001897,0.001240,0.031498,172.386047,8.781764,0.314979,-1293.639526,0.032434,0.000000
22.610001,38.507034,-1293.550537,-0.001880,0.001248,0.031705,171.287842,8.725819,0.317053,-1293.550537,0.032738,0.000000
22.790001,38.330528,-1293.639526,-0.001863,0.001256,0.031896,170.502701,8.685822,0.318961,-1293.639526,0.033032,0.000000
22.970001,38.550606,-1293.683960,-0.001841,0.001267,0.032182,171.481659,8.735692,0.321822,-1293.683960,0.033336,0.000000
23.150002,38.772163,-1293.683960,-0.001854,0.001279,0.032494,172.467194,8.785898,0.324941,-1293.683960,0.033631,0.000000
23.330002,39.619316,-1293.639526,-0.001832,0.001297,0.032945,176.235519,8.977865,0.329452,-1293.639526,0.033934,0.000000
23.510000,39.634949,-1293.683960,-0.001819,0.001304,0.033119,176.305054,8.981408,0.331193,-1293.683960,0.034238,0.000000
23.690001,39.625641,-1293.550537,-0.001794,0.001314,0.033380,176.263657,8.979299,0.333797,-1293.550537,0.034532,0.000000
23.870001,39.641281,-1293.594971,-0.001776,0.001325,0.033648,176.333221,8.982843,0.336477,-1293.594971,0.034836,0.000000
24.050001,40.968422,-1293.639526,-0.001763,0.001347,0.034220,182.236649,9.283577,0.342200,-1293.639526,0.035131,0.000000
24.230001,40.899529,-1293.639526,-0.001759,0.001354,0.034403,181.930191,9.267965,0.344032,-1293.639526,0.035434,0.000000
24.410002,41.167641,-1293.550537,-0.001729,0.001367,0.034732,183.122818,9.328721,0.347317,-1293.550537,0.035738,0.000000
24.590002,41.251045,-1293.506104,-0.001720,0.001377,0.034983,183.493820,9.347620,0.349830,-1293.506104,0.036032,0.000000
24.770000,41.292381,-1293.594971,-0.001712,0.001388,0.035253,183.677689,9.356987,0.352525,-1293.594971,0.036337,0.000000
24.950001,41.392921,-1293.639526,-0.001694,0.001398,0.035520,184.124908,9.379770,0.355205,-1293.639526,0.036632,0.000000
25.130001,42.121658,-1293.639526,-0.001677,0.001416,0.035964,187.366501,9.544904,0.359641,-1293.639526,0.036935,0.000000
25.310001,42.207672,-1293.594971,-0.001681,0.001426,0.036223,187.749100,9.564395,0.362230,-1293.594971,0.037239,0.000000
25.490002,42.000633,-1293.594971,-0.001660,0.001431,0.036346,186.828140,9.517480,0.363456,-1293.594971,0.037533,0.000000
25.670002,42.110855,-1293.594971,-0.001638,0.001443,0.036648,187.318436,9.542457,0.366484,-1293.594971,0.037837,0.000000
25.850000,42.912949,-1293.683960,-0.001625,0.001461,0.037116,190.886322,9.724214,0.371162,-1293.683960,0.038132,0.000000
26.030001,43.746689,-1293.594971,-0.001608,0.001478,0.037533,194.594986,9.913141,0.375325,-1293.594971,0.038435,0.000000
26.210001,43.474113,-1293.639526,-0.001600,0.001483,0.037672,193.382507,9.851375,0.376718,-1293.639526,0.038739,0.000000
26.390001,43.686737,-1293.594971,-0.001578,0.001496,0.037993,194.328308,9.899556,0.379928,-1293.594971,0.039033,0.000000
26.570002,43.823029,-1293.639526,-0.001565,0.001507,0.038279,194.934570,9.930441,0.382789,-1293.639526,0.039337,0.000000
26.750002,43.800308,-1293.683960,-0.001565,0.001517,0.038521,194.833496,9.925291,0.385211,-1293.683960,0.039632,0.000000
26.930002,44.399086,-1293.639526,-0.001539,0.001530,0.038869,197.496994,10.060976,0.388694,-1293.639526,0.039935,0.000000
27.110001,44.846680,-1293.594971,-0.001531,0.001544,0.039224,199.487991,10.162403,0.392236,-1293.594971,0.040239,0.000000
27.290001,45.156494,-1293.594971,-0.001505,0.001555,0.039502,200.866119,10.232608,0.395022,-1293.594971,0.040533,0.000000
27.470001,44.920410,-1293.594971,-0.001500,0.001562,0.039684,199.815964,10.179110,0.396839,-1293.594971,0.040838,0.000000
27.650002,45.216446,-1293.683960,-0.001496,0.001574,0.039987,201.132797,10.246193,0.399867,-1293.683960,0.041133,0.000000
27.830002,46.262062,-1293.639526,-0.001483,0.001595,0.040526,205.783936,10.483133,0.405256,-1293.639526,0.041436,0.000000
28.010002,46.660507,-1293.594971,-0.001462,0.001606,0.040785,207.556305,10.573421,0.407845,-1293.594971,0.041740,0.000000
28.190001,46.860840,-1293.594971,-0.001444,0.001618,0.041105,208.447433,10.618818,0.411055,-1293.594971,0.042034,0.000000
28.370001,46.927498,-1293.639526,-0.001427,0.001628,0.041349,208.743942,10.633923,0.413492,-1293.639526,0.042338,0.000000
28.550001,46.915955,-1293.639526,-0.001414,0.001636,0.041566,208.692596,10.631308,0.415657,-1293.639526,0.042633,0.000000
28.730001,47.136024,-1293.594971,-0.001410,0.001650,0.041921,209.671509,10.681176,0.419215,-1293.594971,0.042936,0.000000
28.910002,47.869598,-1293.639526,-0.001397,0.001662,0.042224,212.934601,10.847406,0.422243,-1293.639526,0.043240,0.000000
29.090002,48.405441,-1293.594971,-0.001375,0.001676,0.042580,215.318161,10.968829,0.425801,-1293.594971,0.043534,0.000000
29.270000,48.535027,-1293.639526,-0.001362,0.001686,0.042824,215.894577,10.998195,0.428238,-1293.639526,0.043838,0.000000
29.450001,48.492203,-1293.594971,-0.001350,0.001695,0.043049,215.704086,10.988490,0.430494,-1293.594971,0.044133,0.000000
29.630001,48.500771,-1293.639526,-0.001341,0.001702,0.043231,215.742203,10.990432,0.432311,-1293.639526,0.044436,0.000000
29.810001,49.021347,-1293.728516,-0.001328,0.001715,0.043561,218.057846,11.108397,0.435611,-1293.728516,0.044731,0.000000
29.990002,49.970520,-1293.594971,-0.001311,0.001733,0.044029,222.279968,11.323483,0.440289,-1293.594971,0.045034,0.000000
30.170002,50.215172,-1293.550537,-0.001289,0.001746,0.044341,223.368240,11.378921,0.443408,-1293.550537,0.045339,0.000000
30.350002,50.530197,-1293.639526,-0.001272,0.001757,0.044636,224.769547,11.450307,0.446360,-1293.639526,0.045634,0.000000
30.530001,50.997528,-1293.639526,-0.001268,0.001769,0.044922,226.848328,11.556206,0.449222,-1293.639526,0.045937,0.000000
30.710001,50.869431,-1293.639526,-0.001263,0.001776,0.045113,226.278534,11.527178,0.451129,-1293.639526,0.046232,0.000000
30.890001,51.882286,-1293.594971,-0.001242,0.001794,0.045564,230.783936,11.756694,0.455641,-1293.594971,0.046535,0.000000
31.070002,51.947075,-1293.683960,-0.001220,0.001804,0.045824,231.072128,11.771376,0.458245,-1293.683960,0.046839,0.000000
31.250002,52.050964,-1293.639526,-0.001216,0.001812,0.046015,231.534256,11.794917,0.460152,-1293.639526,0.047134,0.000000
31.430002,52.202896,-1293.639526,-0.001216,0.001822,0.046274,232.210083,11.829346,0.462741,-1293.639526,0.047437,0.000000
31.610001,52.385727,-1293.594971,-0.001203,0.001832,0.046544,233.023346,11.870775,0.465436,-1293.594971,0.047732,0.000000
31.790001,52.672829,-1293.639526,-0.001177,0.001850,0.046995,234.300446,11.935834,0.469948,-1293.639526,0.048035,0.000000
31.970001,53.975388,-1293.639526,-0.001160,0.001862,0.047290,240.094513,12.230997,0.472900,-1293.639526,0.048339,0.000000
32.150002,53.950439,-1293.594971,-0.001168,0.001871,0.047516,239.983536,12.225345,0.475156,-1293.594971,0.048634,0.000000
32.330002,54.466919,-1293.683960,-0.001143,0.001884,0.047844,242.280960,12.342381,0.478441,-1293.683960,0.048937,0.000000
32.510002,54.726089,-1293.639526,-0.001134,0.001895,0.048123,243.433807,12.401109,0.481227,-1293.639526,0.049232,0.000000
32.690002,54.848602,-1293.594971,-0.001125,0.001904,0.048356,243.978775,12.428870,0.483558,-1293.594971,0.049535,0.000000
32.870003,55.521103,-1293.683960,-0.001117,0.001921,0.048798,246.970200,12.581262,0.487979,-1293.683960,0.049839,0.000000
33.050003,56.090836,-1293.683960,-0.001108,0.001932,0.049084,249.504501,12.710365,0.490840,-1293.683960,0.050133,0.000000
33.230003,56.597633,-1293.639526,-0.001099,0.001942,0.049335,251.758850,12.825207,0.493353,-1293.639526,0.050438,0.000000
33.410000,56.679558,-1293.683960,-0.001078,0.001953,0.049596,252.123260,12.843771,0.495957,-1293.683960,0.050733,0.000000
33.590000,56.576408,-1293.594971,-0.001065,0.001957,0.049718,251.664429,12.820397,0.497184,-1293.594971,0.051036,0.000000
33.770000,57.315941,-1293.594971,-0.001039,0.001975,0.050177,254.954041,12.987978,0.501771,-1293.594971,0.051340,0.000000
33.950001,58.445717,-1293.683960,-0.001048,0.001991,0.050568,259.979523,13.243989,0.505677,-1293.683960,0.051634,0.000000
34.130001,58.869476,-1293.728516,-0.001030,0.002003,0.050880,261.864502,13.340014,0.508796,-1293.728516,0.051938,0.000000
34.310001,59.191956,-1293.639526,-0.001026,0.002014,0.051157,263.298981,13.413089,0.511566,-1293.639526,0.052233,0.000000
34.490002,59.415375,-1293.639526,-0.001005,0.002023,0.051382,264.292786,13.463717,0.513822,-1293.639526,0.052536,0.000000
34.670002,59.202751,-1293.639526,-0.000992,0.002030,0.051573,263.346985,13.415535,0.515730,-1293.639526,0.052840,0.000000
34.850002,59.655930,-1293.683960,-0.000983,0.002044,0.051912,265.362823,13.518227,0.519121,-1293.683960,0.053134,0.000000
35.030003,60.654259,-1293.683960,-0.000970,0.002062,0.052363,269.803619,13.744452,0.523633,-1293.683960,0.053438,0.000000
35.210003,61.024399,-1293.683960,-0.000957,0.002068,0.052527,271.450073,13.828327,0.525268,-1293.683960,0.053733,0.000000
35.390003,61.583702,-1293.683960,-0.000953,0.002080,0.052840,273.937988,13.955066,0.528402,-1293.683960,0.054036,0.000000
35.570004,61.334587,-1293.683960,-0.000940,0.002085,0.052970,272.829865,13.898617,0.529704,-1293.683960,0.054340,0.000000
35.750000,62.796890,-1293.683960,-0.000923,0.002107,0.053508,279.334534,14.229979,0.535078,-1293.683960,0.054634,0.000000
35.930000,63.449287,-1293.728516,-0.000927,0.002120,0.053845,282.236511,14.377814,0.538454,-1293.728516,0.054939,0.000000
36.110001,64.373512,-1293.683960,-0.000914,0.002135,0.054227,286.347687,14.587247,0.542269,-1293.683960,0.055234,0.000000
36.290001,64.243935,-1293.639526,-0.000905,0.002143,0.054443,285.771301,14.557883,0.544434,-1293.639526,0.055537,0.000000
36.470001,64.919044,-1293.639526,-0.000884,0.002156,0.054757,288.774323,14.710866,0.547568,-1293.639526,0.055841,0.000000
36.650002,64.834145,-1293.728516,-0.000875,0.002162,0.054920,288.396667,14.691628,0.549203,-1293.728516,0.056135,0.000000
36.830002,65.100395,-1293.772949,-0.000867,0.002172,0.055164,289.581024,14.751961,0.551641,-1293.772949,0.056439,0.000000
37.010002,66.453590,-1293.639526,-0.000854,0.002187,0.055562,295.600342,15.058599,0.555623,-1293.639526,0.056716,0.000000
37.190002,65.535698,-1293.594971,-0.000832,0.002182,0.055424,291.517334,14.850601,0.554245,-1293.594971,0.055667,0.000000
37.370003,64.794670,-1293.639526,-0.000832,0.002182,0.055415,288.221100,14.682682,0.554154,-1293.639526,288.275726,0.000000
37.550003,66.090904,-1293.728516,-0.000819,0.002179,0.055337,293.987030,14.976413,0.553367,-1293.728516,294.500488,0.000000
37.730003,65.324928,-1293.728516,-0.000811,0.002179,0.055346,290.579803,14.802840,0.553458,-1293.728516,294.500488,0.000000
37.910004,65.627663,-1293.639526,-0.000811,0.002212,0.056188,291.926422,14.871441,0.561875,-1293.639526,294.500488,0.000000
38.090000,64.967827,-1293.683960,-0.000802,0.002212,0.056195,288.991333,14.721920,0.561951,-1293.683960,294.500488,0.000000
38.270000,65.399773,-1293.639526,-0.000789,0.002224,0.056499,290.912720,14.819800,0.564994,-1293.639526,294.500488,0.000000
38.450001,65.482445,-1293.683960,-0.000780,0.002232,0.056699,291.280457,14.838534,0.566992,-1293.683960,294.500488,0.000000
38.630001,65.268700,-1293.728516,-0.000763,0.002238,0.056846,290.329681,14.790098,0.568461,-1293.728516,294.500488,0.000000
38.810001,65.250084,-1293.639526,-0.000772,0.002245,0.057020,290.246857,14.785880,0.570202,-1293.639526,294.500488,0.000000
38.990002,65.257896,-1293.639526,-0.000750,0.002247,0.057063,290.281616,14.787651,0.570626,-1293.639526,294.500488,0.000000
39.170002,65.206139,-1293.728516,-0.000750,0.002253,0.057228,290.051392,14.775923,0.572276,-1293.728516,294.500488,0.000000
39.350002,65.073204,-1293.683960,-0.000746,0.002256,0.057314,289.460083,14.745798,0.573139,-1293.683960,294.500488,0.000000
39.530003,65.367012,-1293.728516,-0.000750,0.002265,0.057523,290.766998,14.812377,0.575228,-1293.728516,294.500488,0.000000
39.710003,65.028145,-1293.683960,-0.000724,0.002266,0.057549,289.259644,14.735588,0.575486,-1293.683960,294.500488,0.000000
39.890003,65.056068,-1293.683960,-0.000733,0.002271,0.057695,289.383850,14.741916,0.576954,-1293.683960,294.500488,0.000000
40.070004,64.910851,-1293.683960,-0.000711,0.002278,0.057853,288.737885,14.709009,0.578529,-1293.683960,294.500488,0.000000
40.250004,64.995384,-1293.683960,-0.000716,0.002279,0.057886,289.113922,14.728165,0.578862,-1293.683960,294.500488,0.000000
40.430000,65.014000,-1293.683960,-0.000703,0.002284,0.058016,289.196716,14.732384,0.580164,-1293.683960,294.500488,0.000000
40.610001,65.219551,-1293.683960,-0.000703,0.002291,0.058190,290.111053,14.778962,0.581905,-1293.683960,294.500488,0.000000
40.790001,64.898567,-1293.639526,-0.000703,0.002291,0.058190,288.683258,14.706225,0.581905,-1293.639526,294.500488,0.000000
40.970001,65.339073,-1293.683960,-0.000690,0.002300,0.058416,290.642700,14.806046,0.584161,-1293.683960,294.500488,0.000000
41.150002,64.986443,-1293.728516,-0.000690,0.002300,0.058416,289.074127,14.726138,0.584161,-1293.728516,294.500488,0.000000
41.330002,64.582039,-1293.728516,-0.000681,0.002300,0.058416,287.275269,14.634499,0.584161,-1293.728516,294.500488,0.000000
41.510002,65.159218,-1293.728516,-0.000686,0.002330,0.059188,289.842682,14.765290,0.591882,-1293.728516,294.500488,0.000000
41.690002,66.563072,-1293.639526,-0.000660,0.002232,0.056690,296.087341,15.083408,0.566902,-1293.639526,294.500488,0.000000
41.870003,66.008980,-1293.683960,-0.000660,0.002233,0.056707,293.622620,14.957849,0.567068,-1293.683960,294.500488,0.000000
42.050003,65.541283,-1293.728516,-0.000647,0.002267,0.057574,291.542175,14.851867,0.575743,-1293.728516,294.500488,0.000000
42.230003,65.161079,-1293.639526,-0.000660,0.002295,0.058286,289.850952,14.765712,0.582859,-1293.639526,294.500488,0.000000
42.410004,65.002449,-1293.683960,-0.000651,0.002321,0.058954,289.145325,14.729765,0.589535,-1293.683960,294.500488,0.000000
42.590000,65.113792,-1293.639526,-0.000638,0.002328,0.059128,289.640625,14.754995,0.591276,-1293.639526,294.500488,0.000000
42.770000,65.158852,-1293.639526,-0.000647,0.002333,0.059258,289.841034,14.765207,0.592578,-1293.639526,294.500488,0.000000
42.950001,65.000587,-1293.683960,-0.000629,0.002335,0.059318,289.137054,14.729344,0.593184,-1293.683960,294.500488,0.000000
43.130001,64.942131,-1293.772949,-0.000617,0.002339,0.059421,288.877014,14.716098,0.594213,-1293.772949,294.500488,0.000000
43.310001,65.204659,-1293.683960,-0.000647,0.002345,0.059552,290.044800,14.775586,0.595515,-1293.683960,294.500488,0.000000
43.490002,65.037453,-1293.639526,-0.000629,0.002348,0.059630,289.301025,14.737697,0.596303,-1293.639526,294.500488,0.000000
43.670002,65.046028,-1293.683960,-0.000612,0.002350,0.059682,289.339172,14.739640,0.596817,-1293.683960,294.500488,0.000000
43.850002,65.277260,-1293.728516,-0.000617,0.002364,0.060056,290.367767,14.792039,0.600557,-1293.728516,294.500488,0.000000
44.030003,65.752785,-1293.728516,-0.000612,0.002359,0.059907,292.483002,14.899794,0.599073,-1293.728516,294.500488,0.000000
44.210003,65.415047,-1293.772949,-0.000608,0.002359,0.059916,290.980652,14.823262,0.599164,-1293.772949,294.500488,0.000000
44.390003,65.338707,-1293.683960,-0.000608,0.002371,0.060228,290.641083,14.805963,0.602283,-1293.683960,294.500488,0.000000
44.570004,65.740868,-1293.639526,-0.000604,0.002370,0.060203,292.429993,14.897094,0.602025,-1293.639526,294.500488,0.000000
44.750004,65.469032,-1293.728516,-0.000599,0.002370,0.060203,291.220795,14.835495,0.602025,-1293.728516,294.500488,0.000000
44.930000,65.189751,-1293.728516,-0.000595,0.002370,0.060203,289.978485,14.772208,0.602025,-1293.728516,294.500488,0.000000
45.110001,64.911217,-1293.683960,-0.000599,0.002370,0.060203,288.739502,14.709092,0.602025,-1293.683960,294.500488,0.000000
45.290001,64.653175,-1293.728516,-0.000586,0.002370,0.060203,287.591675,14.650620,0.602025,-1293.728516,294.500488,0.000000
45.470001,66.956657,-1293.683960,-0.000569,0.002307,0.058607,297.838074,15.172596,0.586068,-1293.683960,294.500488,0.000000
45.650002,66.562691,-1293.772949,-0.000565,0.002266,0.057549,296.085632,15.083322,0.575486,-1293.772949,294.500488,0.000000
45.830002,66.264427,-1293.683960,-0.000569,0.002266,0.057558,294.758881,15.015734,0.575577,-1293.683960,294.500488,0.000000
46.010002,65.922218,-1293.728516,-0.000573,0.002266,0.057567,293.236664,14.938189,0.575667,-1293.728516,294.500488,0.000000
46.190002,65.629906,-1293.639526,-0.000573,0.002272,0.057714,291.936401,14.871949,0.577136,-1293.639526,294.500488,0.000000
46.370003,65.369606,-1293.639526,-0.000548,0.002335,0.059309,290.778534,14.812964,0.593093,-1293.639526,294.500488,0.000000
46.550003,65.266472,-1293.728516,-0.000560,0.002383,0.060540,290.319763,14.789594,0.605402,-1293.728516,294.500488,0.000000
46.730003,65.294395,-1293.728516,-0.000565,0.002394,0.060810,290.443970,14.795921,0.608096,-1293.728516,294.500488,0.000000
46.910004,65.224022,-1293.683960,-0.000560,0.002398,0.060905,290.130951,14.779975,0.609050,-1293.683960,294.500488,0.000000
47.090004,65.219917,-1293.728516,-0.000560,0.002400,0.060949,290.112671,14.779044,0.609489,-1293.728516,294.500488,0.000000
47.270000,65.052727,-1293.728516,-0.000539,0.002400,0.060966,289.368988,14.741158,0.609656,-1293.728516,294.500488,0.000000
47.450001,65.282845,-1293.772949,-0.000543,0.002406,0.061105,290.392609,14.793304,0.611049,-1293.772949,294.500488,0.000000
47.630001,65.187523,-1293.772949,-0.000552,0.002408,0.061173,289.968597,14.771704,0.611730,-1293.772949,294.500488,0.000000
47.810001,65.133904,-1293.772949,-0.000548,0.002409,0.061182,289.730072,14.759553,0.611821,-1293.772949,294.500488,0.000000
47.990002,65.303337,-1293.728516,-0.000543,0.002413,0.061287,290.483765,14.797948,0.612865,-1293.728516,294.500488,0.000000
48.170002,65.156242,-1293.728516,-0.000535,0.002413,0.061287,289.829437,14.764615,0.612865,-1293.728516,294.500488,0.000000
48.350002,65.007301,-1293.772949,-0.000535,0.002414,0.061312,289.166931,14.730865,0.613123,-1293.772949,294.500488,0.000000
48.530003,65.173378,-1293.728516,-0.000539,0.002418,0.061417,289.905670,14.768499,0.614167,-1293.728516,294.500488,0.000000
48.710003,65.060539,-1293.772949,-0.000526,0.002420,0.061468,289.403748,14.742929,0.614682,-1293.772949,294.500488,0.000000
48.890003,65.048256,-1293.683960,-0.000530,0.002421,0.061486,289.349091,14.740146,0.614864,-1293.683960,294.500488,0.000000
49.070004,65.491005,-1293.683960,-0.000517,0.002428,0.061668,291.318542,14.840473,0.616681,-1293.683960,294.500488,0.000000
49.250004,65.454140,-1293.772949,-0.000522,0.002428,0.061668,291.154541,14.832120,0.616681,-1293.772949,294.500488,0.000000
49.430004,65.292534,-1293.772949,-0.000530,0.002428,0.061668,290.435699,14.795500,0.616681,-1293.772949,294.500488,0.000000
49.610001,65.165550,-1293.772949,-0.000530,0.002429,0.061694,289.870850,14.766726,0.616938,-1293.772949,294.500488,0.000000
49.790001,65.130928,-1293.683960,-0.000522,0.002431,0.061747,289.716827,14.758880,0.617468,-1293.683960,294.500488,0.000000
49.970001,65.174110,-1293.728516,-0.000517,0.002435,0.061850,289.908936,14.768664,0.618497,-1293.728516,294.500488,0.000000
50.150002,65.227745,-1293.728516,-0.000509,0.002435,0.061859,290.147491,14.780818,0.618588,-1293.728516,294.500488,0.000000
50.330002,65.143959,-1293.772949,-0.000509,0.002436,0.061868,289.774811,14.761832,0.618679,-1293.772949,294.500488,0.000000
50.510002,65.073570,-1293.728516,-0.000509,0.002437,0.061910,289.461700,14.745882,0.619103,-1293.728516,294.500488,0.000000
50.690002,64.970055,-1293.772949,-0.000513,0.002437,0.061910,289.001251,14.722425,0.619103,-1293.772949,294.500488,0.000000
50.870003,65.360680,-1293.728516,-0.000500,0.002446,0.062128,290.738831,14.810942,0.621283,-1293.728516,294.500488,0.000000
51.050003,65.355461,-1293.728516,-0.000504,0.002445,0.062093,290.715607,14.809759,0.620935,-1293.728516,294.500488,0.000000
51.230003,65.236305,-1293.772949,-0.000492,0.002445,0.062093,290.185577,14.782759,0.620935,-1293.772949,294.500488,0.000000
51.410004,65.075813,-1293.772949,-0.000509,0.002445,0.062093,289.471680,14.746390,0.620935,-1293.772949,294.500488,0.000000
51.590004,64.926491,-1293.728516,-0.000513,0.002445,0.062093,288.807465,14.712553,0.620935,-1293.728516,294.500488,0.000000
51.770004,64.781639,-1293.683960,-0.000504,0.002445,0.062093,288.163116,14.679729,0.620935,-1293.683960,294.500488,0.000000
51.950001,64.639397,-1293.817383,-0.000500,0.002445,0.062093,287.530396,14.647496,0.620935,-1293.817383,294.500488,0.000000
52.130001,64.479637,-1293.772949,-0.000483,0.002445,0.062093,286.819763,14.611295,0.620935,-1293.772949,294.500488,0.000000
52.310001,64.376122,-1293.772949,-0.000500,0.002448,0.062189,286.359283,14.587838,0.621889,-1293.772949,294.500488,0.000000
52.490002,66.633446,-1293.772949,-0.000479,0.002411,0.061252,296.400360,15.099355,0.612517,-1293.772949,294.500488,0.000000
52.670002,66.396248,-1293.728516,-0.000470,0.002411,0.061252,295.345276,15.045605,0.612517,-1293.728516,294.500488,0.000000
52.850002,66.221977,-1293.817383,-0.000461,0.002411,0.061252,294.570068,15.006115,0.612517,-1293.817383,294.500488,0.000000
53.030003,66.027962,-1293.772949,-0.000483,0.002411,0.061252,293.707031,14.962150,0.612517,-1293.772949,294.500488,0.000000
53.210003,65.840294,-1293.817383,-0.000479,0.002412,0.061261,292.872253,14.919623,0.612608,-1293.817383,294.500488,0.000000
53.390003,65.732307,-1293.728516,-0.000479,0.002412,0.061268,292.391907,14.895154,0.612684,-1293.728516,294.500488,0.000000
53.570004,65.572929,-1293.728516,-0.000466,0.002430,0.061729,291.682953,14.859038,0.617286,-1293.728516,294.500488,0.000000
53.750004,65.414299,-1293.817383,-0.000474,0.002436,0.061868,290.977325,14.823092,0.618679,-1293.817383,294.500488,0.000000
53.930004,65.258278,-1293.861938,-0.000461,0.002438,0.061919,290.283325,14.787737,0.619194,-1293.861938,294.500488,0.000000
54.110004,65.186775,-1293.861938,-0.000470,0.002450,0.062240,289.965271,14.771534,0.622403,-1293.861938,294.500488,0.000000
54.290001,65.140602,-1293.817383,-0.000474,0.002459,0.062466,289.759857,14.761071,0.624659,-1293.817383,294.500488,0.000000
54.470001,65.062782,-1293.817383,-0.000466,0.002462,0.062526,289.413696,14.743437,0.625265,-1293.817383,294.500488,0.000000
54.650002,65.203163,-1293.817383,-0.000461,0.002467,0.062673,290.038147,14.775248,0.626733,-1293.817383,294.500488,0.000000
54.830002,65.125343,-1293.861938,-0.000466,0.002467,0.062673,289.691986,14.757614,0.626733,-1293.861938,294.500488,0.000000
55.010002,64.995003,-1293.817383,-0.000470,0.002468,0.062682,289.112213,14.728079,0.626824,-1293.817383,294.500488,0.000000
55.190002,65.176720,-1293.772949,-0.000466,0.002472,0.062796,289.920532,14.769256,0.627959,-1293.772949,294.500488,0.000000
55.370003,65.104851,-1293.817383,-0.000470,0.002473,0.062822,289.600830,14.752970,0.628217,-1293.817383,294.500488,0.000000
55.550003,65.104118,-1293.772949,-0.000461,0.002474,0.062831,289.597595,14.752804,0.628308,-1293.772949,294.500488,0.000000
55.730003,65.023674,-1293.861938,-0.000453,0.002474,0.062838,289.239746,14.734575,0.628383,-1293.861938,294.500488,0.000000
55.910004,65.026283,-1293.817383,-0.000466,0.002478,0.062934,289.251343,14.735167,0.629337,-1293.817383,294.500488,0.000000
56.090004,65.162575,-1293.772949,-0.000453,0.002478,0.062952,289.857605,14.766050,0.629519,-1293.772949,294.500488,0.000000
56.270004,65.084373,-1293.728516,-0.000461,0.002478,0.062952,289.509766,14.748329,0.629519,-1293.728516,294.500488,0.000000
56.450005,65.027779,-1293.817383,-0.000448,0.002480,0.062994,289.257996,14.735505,0.629943,-1293.817383,294.500488,0.000000
56.630001,65.087730,-1293.906372,-0.000466,0.002481,0.063022,289.524689,14.749090,0.630215,-1293.906372,294.500488,0.000000
56.810001,65.019951,-1293.861938,-0.000448,0.002482,0.063038,289.223175,14.733731,0.630382,-1293.861938,294.500488,0.000000
56.990002,65.208000,-1293.772949,-0.000457,0.002485,0.063124,290.059662,14.776343,0.631245,-1293.772949,294.500488,0.000000
57.170002,65.181938,-1293.728516,-0.000453,0.002485,0.063124,289.943756,14.770438,0.631245,-1293.728516,294.500488,0.000000
57.350002,65.294762,-1293.772949,-0.000461,0.002488,0.063194,290.445618,14.796005,0.631941,-1293.772949,294.500488,0.000000
57.530003,65.301842,-1293.817383,-0.000457,0.002489,0.063220,290.477112,14.797609,0.632199,-1293.817383,294.500488,0.000000
57.710003,65.263863,-1293.861938,-0.000448,0.002489,0.063220,290.308167,14.789002,0.632199,-1293.861938,294.500488,0.000000
57.890003,65.196465,-1293.906372,-0.000448,0.002489,0.063220,290.008362,14.773730,0.632199,-1293.906372,294.500488,0.000000
58.070004,65.225883,-1293.772949,-0.000444,0.002492,0.063290,290.139221,14.780396,0.632895,-1293.772949,294.500488,0.000000
58.250004,65.298866,-1293.817383,-0.000431,0.002493,0.063333,290.463867,14.796934,0.633334,-1293.817383,294.500488,0.000000
58.430004,65.285454,-1293.817383,-0.000427,0.002494,0.063342,290.404205,14.793895,0.633425,-1293.817383,294.500488,0.000000
58.610004,65.235191,-1293.817383,-0.000444,0.002494,0.063342,290.180634,14.782506,0.633425,-1293.817383,294.500488,0.000000
58.790001,65.188271,-1293.817383,-0.000444,0.002494,0.063359,289.971924,14.771873,0.633591,-1293.817383,294.500488,0.000000
58.970001,65.323433,-1293.906372,-0.000431,0.002497,0.063429,290.573151,14.802502,0.634288,-1293.906372,294.500488,0.000000
59.150002,65.298866,-1293.861938,-0.000423,0.002498,0.063438,290.463867,14.796934,0.634379,-1293.861938,294.500488,0.000000
59.330002,65.281731,-1293.906372,-0.000440,0.002499,0.063471,290.387634,14.793052,0.634712,-1293.906372,294.500488,0.000000
59.510002,65.295143,-1293.906372,-0.000435,0.002500,0.063489,290.447296,14.796091,0.634893,-1293.906372,294.500488,0.000000
59.690002,65.273537,-1293.772949,-0.000435,0.002500,0.063506,290.351196,14.791195,0.635060,-1293.772949,294.500488,0.000000
59.870003,65.293648,-1293.772949,-0.000431,0.002501,0.063533,290.440643,14.795753,0.635332,-1293.772949,294.500488,0.000000
60.050003,65.258644,-1293.817383,-0.000423,0.002502,0.063559,290.284943,14.787820,0.635590,-1293.817383,294.500488,0.000000
60.230003,65.260139,-1293.906372,-0.000427,0.002503,0.063576,290.291595,14.788159,0.635756,-1293.906372,294.500488,0.000000
60.410004,65.233696,-1293.817383,-0.000435,0.002504,0.063594,290.173981,14.782166,0.635938,-1293.817383,294.500488,0.000000
60.590004,65.229607,-1293.817383,-0.000435,0.002504,0.063601,290.155792,14.781240,0.636014,-1293.817383,294.500488,0.000000
60.770004,65.201302,-1293.817383,-0.000427,0.002505,0.063629,290.029877,14.774826,0.636286,-1293.817383,294.500488,0.000000
60.950005,65.174110,-1293.817383,-0.000423,0.002505,0.063629,289.908936,14.768664,0.636286,-1293.817383,294.500488,0.000000
61.130001,65.357704,-1293.817383,-0.000418,0.002509,0.063741,290.725586,14.810267,0.637407,-1293.817383,294.500488,0.000000
61.310001,65.375572,-1293.817383,-0.000418,0.002509,0.063741,290.805084,14.814316,0.637407,-1293.817383,294.500488,0.000000
61.490002,65.352486,-1293.772949,-0.000435,0.002509,0.063741,290.702362,14.809085,0.637407,-1293.772949,294.500488,0.000000
61.670002,65.293648,-1293.817383,-0.000427,0.002509,0.063741,290.440643,14.795753,0.637407,-1293.817383,294.500488,0.000000
61.850002,65.251945,-1293.861938,-0.000418,0.002509,0.063741,290.255157,14.786302,0.637407,-1293.861938,294.500488,0.000000
62.030003,65.201302,-1293.861938,-0.000418,0.002509,0.063741,290.029877,14.774826,0.637407,-1293.861938,294.500488,0.000000
62.210003,65.102989,-1293.817383,-0.000418,0.002510,0.063757,289.592560,14.752548,0.637573,-1293.817383,294.500488,0.000000
62.390003,65.038200,-1293.817383,-0.000414,0.002512,0.063801,289.304352,14.737866,0.638012,-1293.817383,294.500488,0.000000
62.570004,65.306679,-1293.772949,-0.000418,0.002515,0.063888,290.498627,14.798705,0.638875,-1293.772949,294.500488,0.000000
62.750004,65.301842,-1293.817383,-0.000423,0.002515,0.063888,290.477112,14.797609,0.638875,-1293.817383,294.500488,0.000000
62.930004,65.272789,-1293.817383,-0.000418,0.002515,0.063888,290.347870,14.791025,0.638875,-1293.817383,294.500488,0.000000
63.110004,65.204277,-1293.861938,-0.000418,0.002515,0.063888,290.043121,14.775500,0.638875,-1293.861938,294.500488,0.000000
63.290005,65.149910,-1293.817383,-0.000410,0.002516,0.063897,289.801270,14.763181,0.638966,-1293.817383,294.500488,0.000000
63.470001,65.197945,-1293.772949,-0.000427,0.002518,0.063950,290.014954,14.774065,0.639496,-1293.772949,294.500488,0.000000
63.650002,65.197945,-1293.817383,-0.000410,0.002518,0.063957,290.014954,14.774065,0.639572,-1293.817383,294.500488,0.000000
63.830002,65.170769,-1293.817383,-0.000423,0.002518,0.063966,289.894043,14.767907,0.639662,-1293.817383,294.500488,0.000000
64.010002,65.184914,-1293.861938,-0.000414,0.002519,0.063992,289.956970,14.771112,0.639920,-1293.861938,294.500488,0.000000
64.190002,65.158104,-1293.817383,-0.000410,0.002520,0.064001,289.837708,14.765038,0.640011,-1293.817383,294.500488,0.000000
64.370003,65.169273,-1293.817383,-0.000414,0.002521,0.064036,289.887421,14.767569,0.640359,-1293.817383,294.500488,0.000000
64.550003,65.159966,-1293.772949,-0.000410,0.002521,0.064036,289.846008,14.765460,0.640359,-1293.772949,294.500488,0.000000
64.730003,65.109322,-1293.861938,-0.000401,0.002522,0.064053,289.620728,14.753983,0.640525,-1293.861938,294.500488,0.000000
64.910004,65.106712,-1293.861938,-0.000410,0.002523,0.064096,289.609131,14.753392,0.640964,-1293.861938,294.500488,0.000000
65.090004,65.267204,-1293.817383,-0.000418,0.002524,0.064122,290.323029,14.789760,0.641222,-1293.817383,294.500488,0.000000
65.270004,65.243004,-1293.772949,-0.000397,0.002524,0.064122,290.215363,14.784276,0.641222,-1293.772949,294.500488,0.000000
65.450005,65.211357,-1293.817383,-0.000401,0.002524,0.064122,290.074615,14.777104,0.641222,-1293.817383,294.500488,0.000000
65.630005,65.161079,-1293.950806,-0.000397,0.002525,0.064140,289.850952,14.765712,0.641403,-1293.950806,294.500488,0.000000
65.810005,65.149544,-1293.906372,-0.000392,0.002526,0.064157,289.799652,14.763098,0.641570,-1293.906372,294.500488,0.000000
65.990005,65.107841,-1293.772949,-0.000405,0.002526,0.064157,289.614136,14.753648,0.641570,-1293.772949,294.500488,0.000000
66.170006,65.076927,-1293.861938,-0.000388,0.002527,0.064174,289.476624,14.746643,0.641737,-1293.861938,294.500488,0.000000
66.350006,65.069481,-1293.861938,-0.000401,0.002527,0.064183,289.443512,14.744955,0.641827,-1293.861938,294.500488,0.000000
66.530006,65.188271,-1293.817383,-0.000401,0.002530,0.064269,289.971924,14.771873,0.642690,-1293.817383,294.500488,0.000000
66.710007,65.262001,-1293.906372,-0.000401,0.002530,0.064269,290.299866,14.788581,0.642690,-1293.906372,294.500488,0.000000
66.889999,65.246361,-1293.861938,-0.000392,0.002530,0.064269,290.230316,14.785036,0.642690,-1293.861938,294.500488,0.000000
67.070000,65.202415,-1293.906372,-0.000401,0.002530,0.064269,290.034821,14.775078,0.642690,-1293.906372,294.500488,0.000000
67.250000,65.148048,-1293.906372,-0.000401,0.002530,0.064269,289.792999,14.762759,0.642690,-1293.906372,294.500488,0.000000
67.430000,65.111565,-1293.950806,-0.000392,0.002531,0.064278,289.630707,14.754492,0.642781,-1293.950806,294.500488,0.000000
67.610001,65.069481,-1293.906372,-0.000392,0.002531,0.064278,289.443512,14.744955,0.642781,-1293.906372,294.500488,0.000000
67.790001,65.291786,-1293.906372,-0.000388,0.002536,0.064408,290.432373,14.795330,0.644083,-1293.906372,294.500488,0.000000
67.970001,65.359932,-1293.817383,-0.000388,0.002536,0.064408,290.735504,14.810773,0.644083,-1293.817383,294.500488,0.000000
68.150002,65.348015,-1293.861938,-0.000392,0.002536,0.064408,290.682495,14.808072,0.644083,-1293.861938,294.500488,0.000000
68.330002,65.329399,-1293.906372,-0.000401,0.002536,0.064408,290.599670,14.803853,0.644083,-1293.906372,294.500488,0.000000
68.510002,65.283592,-1293.950806,-0.000397,0.002536,0.064408,290.395935,14.793474,0.644083,-1293.950806,294.500488,0.000000
68.690002,65.243004,-1293.861938,-0.000397,0.002536,0.064408,290.215363,14.784276,0.644083,-1293.861938,294.500488,0.000000
68.870003,65.215828,-1293.817383,-0.000401,0.002536,0.064417,290.094482,14.778117,0.644174,-1293.817383,294.500488,0.000000
69.050003,65.164070,-1293.861938,-0.000392,0.002536,0.064417,289.864258,14.766389,0.644174,-1293.861938,294.500488,0.000000
69.230003,65.108955,-1293.950806,-0.000401,0.002536,0.064417,289.619110,14.753900,0.644174,-1293.950806,294.500488,0.000000
69.410004,65.102623,-1293.861938,-0.000384,0.002537,0.064452,289.590942,14.752465,0.644522,-1293.861938,294.500488,0.000000
69.590004,65.108955,-1293.861938,-0.000397,0.002539,0.064478,289.619110,14.753900,0.644780,-1293.861938,294.500488,0.000000
69.770004,65.116402,-1293.861938,-0.000379,0.002539,0.064478,289.652222,14.755588,0.644780,-1293.861938,294.500488,0.000000
69.950005,65.099266,-1293.906372,-0.000379,0.002539,0.064478,289.575989,14.751705,0.644780,-1293.906372,294.500488,0.000000
70.130005,65.088478,-1293.906372,-0.000384,0.002540,0.064504,289.528015,14.749260,0.645037,-1293.906372,294.500488,0.000000
70.310005,65.082146,-1293.950806,-0.000388,0.002540,0.064513,289.499847,14.747825,0.645128,-1293.950806,294.500488,0.000000
70.490005,65.073204,-1293.817383,-0.000384,0.002541,0.064529,289.460083,14.745798,0.645294,-1293.817383,294.500488,0.000000
70.670006,65.076927,-1293.906372,-0.000379,0.002541,0.064548,289.476624,14.746643,0.645476,-1293.906372,294.500488,0.000000
70.850006,65.102623,-1293.906372,-0.000375,0.002542,0.064564,289.590942,14.752465,0.645643,-1293.906372,294.500488,0.000000
71.030006,65.114540,-1293.950806,-0.000388,0.002542,0.064573,289.643951,14.755165,0.645733,-1293.950806,294.500488,0.000000
71.210007,65.095177,-1293.995361,-0.000379,0.002542,0.064573,289.557800,14.750778,0.645733,-1293.995361,294.500488,0.000000
71.390007,65.119377,-1293.906372,-0.000379,0.002544,0.064608,289.665466,14.756262,0.646082,-1293.906372,294.500488,0.000000
71.570000,65.098900,-1293.906372,-0.000379,0.002544,0.064608,289.574371,14.751621,0.646082,-1293.906372,294.500488,0.000000
71.750000,65.076927,-1293.906372,-0.000384,0.002544,0.064608,289.476624,14.746643,0.646082,-1293.906372,294.500488,0.000000
71.930000,65.055336,-1293.950806,-0.000379,0.002544,0.064608,289.380585,14.741750,0.646082,-1293.950806,294.500488,0.000000
72.110001,65.278008,-1293.906372,-0.000384,0.002548,0.064713,290.371094,14.792209,0.647126,-1293.906372,294.500488,0.000000
72.290001,65.291039,-1293.906372,-0.000375,0.002548,0.064713,290.429047,14.795160,0.647126,-1293.906372,294.500488,0.000000
72.470001,65.290672,-1293.861938,-0.000384,0.002548,0.064713,290.427429,14.795078,0.647126,-1293.861938,294.500488,0.000000
72.650002,65.269066,-1293.861938,-0.000371,0.002548,0.064713,290.331299,14.790182,0.647126,-1293.861938,1681.640991,0.000000
72.830002,65.232582,-1293.861938,-0.000362,0.002537,0.064443,290.169006,14.781914,0.644431,-1293.861938,0.064460,0.000000
72.900002,65.220665,-1293.950806,-0.000362,0.002537,0.064443,290.115997,14.779214,0.644431,-1293.950806,0.064460,0.000000