File: Data/Sima compression/P1-21-1_10302024_174639.csv
Time (sec),S:Load (lbs),S:HL1 (DIM),S:LVDT (in),S:Position (in),Ch:Position (mm),Ch:Load (N),Ch:Stress (MPa),Ch:Strain (mm/mm),Ch:HL1 (DIM),Set Point (),Cycles ()
0.210000,-0.013779,-1293.283691,-0.004449,-0.004422,-0.112331,-0.061291,-0.003122,-1.123311,-1293.283691,-0.112124,0.000000
0.480000,0.008568,-1293.239136,-0.004454,-0.004379,-0.111221,0.038112,0.001941,-1.112214,-1293.239136,-0.110719,0.000000
0.750000,0.018250,-1293.283691,-0.004406,-0.004233,-0.107509,0.081178,0.004135,-1.075092,-1293.283691,-0.106227,0.000000
1.020000,-0.018616,-1293.239136,-0.004217,-0.004046,-0.102775,-0.082807,-0.004218,-1.027750,-1293.239136,-0.101717,0.000000
1.290000,0.010796,-1293.239136,-0.004031,-0.003873,-0.098386,0.048021,0.002446,-0.983861,-1293.239136,-0.097225,0.000000
1.560000,0.013031,-1293.150269,-0.003863,-0.003699,-0.093947,0.057965,0.002953,-0.939471,-1293.150269,-0.092733,0.000000
1.830000,0.004471,-1293.239136,-0.003678,-0.003517,-0.089342,0.019887,0.001013,-0.893417,-1293.239136,-0.088223,0.000000
2.100000,0.021225,-1293.239136,-0.003505,-0.003343,-0.084901,0.094413,0.004810,-0.849012,-1293.239136,-0.083731,0.000000
2.370000,0.204063,-1293.239136,-0.003441,0.000032,0.000807,0.907719,0.046241,0.008069,-1293.239136,0.000954,0.000000
2.640000,0.184700,-1293.194702,-0.003445,0.000032,0.000807,0.821587,0.041854,0.008069,-1293.194702,0.000954,0.000000
2.910000,0.159378,-1293.194702,-0.003449,0.000032,0.000807,0.708949,0.036116,0.008069,-1293.194702,0.001353,0.000000
3.180000,0.188049,-1293.194702,-0.003454,0.000036,0.000902,0.836485,0.042613,0.009023,-1293.194702,0.001796,0.000000
3.450000,0.332901,-1293.328125,-0.003441,0.000055,0.001405,1.480818,0.075436,0.014050,-1293.328125,0.002247,0.000000
3.720000,0.594307,-1293.283691,-0.003436,0.000071,0.001803,2.643609,0.134672,0.018031,-1293.283691,0.002696,0.000000
3.990000,0.932793,-1293.283691,-0.003406,0.000086,0.002177,4.149269,0.211374,0.021771,-1293.283691,0.003148,0.000000
4.260000,1.398628,-1293.194702,-0.003402,0.000103,0.002610,6.221409,0.316934,0.026101,-1293.194702,0.003599,0.000000
4.530000,1.800423,-1293.194702,-0.003376,0.000117,0.002975,8.008680,0.407982,0.029749,-1293.194702,0.004050,0.000000
4.800000,2.906738,-1293.239136,-0.003367,0.000148,0.003755,12.929817,0.658676,0.037546,-1293.239136,0.004501,0.000000
5.070000,3.492851,-1293.283691,-0.003341,0.000163,0.004129,15.536979,0.791491,0.041286,-1293.283691,0.004952,0.000000
5.340000,3.991463,-1293.239136,-0.003333,0.000179,0.004536,17.754913,0.904478,0.045358,-1293.239136,0.005403,0.000000
5.610000,4.723175,-1293.150269,-0.003333,0.000194,0.004926,21.009731,1.070287,0.049264,-1293.150269,0.005845,0.000000
5.880000,5.749802,-1293.239136,-0.003324,0.000214,0.005429,25.576395,1.302924,0.054291,-1293.239136,0.006297,0.000000
6.150000,6.328094,-1293.239136,-0.003320,0.000228,0.005785,28.148769,1.433967,0.057848,-1293.239136,0.006748,0.000000
6.420000,6.995392,-1293.283691,-0.003316,0.000241,0.006122,31.117058,1.585178,0.061224,-1293.283691,0.007197,0.000000
6.690001,7.199074,-1293.283691,-0.003281,0.000249,0.006313,32.023079,1.631333,0.063132,-1293.283691,0.007649,0.000000
6.960001,9.550240,-1293.283691,-0.003264,0.000289,0.007353,42.481586,2.164115,0.073533,-1293.283691,0.008100,0.000000
7.230000,9.898407,-1293.194702,-0.003260,0.000301,0.007641,44.030312,2.243011,0.076409,-1293.194702,0.008551,0.000000
7.500000,10.805504,-1293.239136,-0.003251,0.000316,0.008030,48.065281,2.448562,0.080300,-1293.239136,0.009002,0.000000
7.770000,12.242859,-1293.283691,-0.003247,0.000342,0.008690,54.458958,2.774271,0.086901,-1293.283691,0.009453,0.000000
8.040000,13.002129,-1293.283691,-0.003216,0.000356,0.009037,57.836357,2.946325,0.090368,-1293.283691,0.009904,0.000000
8.310000,13.682457,-1293.239136,-0.003212,0.000369,0.009365,60.862610,3.100489,0.093653,-1293.239136,0.010346,0.000000
8.580001,14.098396,-1293.239136,-0.003212,0.000386,0.009817,62.712799,3.194742,0.098165,-1293.239136,0.010798,0.000000
8.850000,16.077179,-1293.328125,-0.003195,0.000410,0.010416,71.514862,3.643141,0.104160,-1293.328125,0.011247,0.000000
9.120001,16.680428,-1293.283691,-0.003182,0.000424,0.010770,74.198250,3.779839,0.107703,-1293.283691,0.011698,0.000000
9.390000,17.664604,-1293.283691,-0.003165,0.000440,0.011170,78.576080,4.002856,0.111700,-1293.283691,0.012150,0.000000
9.660001,18.223160,-1293.283691,-0.003169,0.000451,0.011447,81.060661,4.129427,0.114470,-1293.283691,0.012601,0.000000
9.930000,20.134926,-1293.239136,-0.003165,0.000480,0.012203,89.564621,4.562639,0.122025,-1293.239136,0.013052,0.000000
10.200001,20.899780,-1293.239136,-0.003139,0.000495,0.012575,92.966866,4.735958,0.125749,-1293.239136,0.013503,0.000000
10.470000,21.276245,-1293.328125,-0.003143,0.000506,0.012843,94.641464,4.821266,0.128429,-1293.328125,0.013954,0.000000
10.740001,22.757545,-1293.283691,-0.003113,0.000530,0.013450,101.230621,5.156934,0.134500,-1293.283691,0.014396,0.000000
11.010000,23.824020,-1293.283691,-0.003122,0.000548,0.013927,105.974533,5.398600,0.139269,-1293.283691,0.014847,0.000000
11.280001,24.669678,-1293.239136,-0.003104,0.000563,0.014310,109.736206,5.590229,0.143099,-1293.239136,0.015299,0.000000
11.550000,25.531349,-1293.328125,-0.003091,0.000582,0.014794,113.569115,5.785487,0.147944,-1293.328125,0.015748,0.000000
11.820001,26.735229,-1293.328125,-0.003074,0.000599,0.015211,118.924240,6.058290,0.152107,-1293.328125,0.016199,0.000000
12.090000,27.284851,-1293.328125,-0.003053,0.000613,0.015576,121.369080,6.182836,0.155756,-1293.328125,0.016651,0.000000
12.360001,27.798347,-1293.283691,-0.003065,0.000623,0.015836,123.653229,6.299195,0.158360,-1293.283691,0.017102,0.000000
12.630001,30.148766,-1293.372559,-0.003044,0.000660,0.016755,134.108414,6.831808,0.167550,-1293.372559,0.017553,0.000000
12.900001,30.563957,-1293.283691,-0.003031,0.000671,0.017032,135.955276,6.925892,0.170320,-1293.283691,0.018004,0.000000
13.170001,31.494888,-1293.328125,-0.003022,0.000691,0.017562,140.096268,7.136844,0.175619,-1293.328125,0.018446,0.000000
13.440001,32.272034,-1293.328125,-0.003001,0.000707,0.017951,143.553177,7.312947,0.179510,-1293.328125,0.018897,0.000000
13.710001,33.167587,-1293.283691,-0.002979,0.000724,0.018393,147.536804,7.515883,0.183931,-1293.283691,0.019348,0.000000
13.980000,33.930954,-1293.283691,-0.002984,0.000744,0.018888,150.932419,7.688864,0.188881,-1293.283691,0.019798,0.000000
14.250001,34.575157,-1293.283691,-0.002975,0.000758,0.019261,153.797974,7.834842,0.192606,-1293.283691,0.020249,0.000000
14.520000,36.125343,-1293.372559,-0.002958,0.000783,0.019893,160.693558,8.186120,0.198934,-1293.372559,0.020700,0.000000
14.790001,36.648529,-1293.328125,-0.002940,0.000797,0.020242,163.020798,8.304676,0.202416,-1293.328125,0.021152,0.000000
15.060000,37.121811,-1293.283691,-0.002915,0.000813,0.020658,165.126068,8.411922,0.206580,-1293.283691,0.021603,0.000000
15.330001,37.652443,-1293.283691,-0.002923,0.000827,0.020996,167.486435,8.532166,0.209956,-1293.283691,0.022054,0.000000
15.600000,38.390480,-1293.328125,-0.002910,0.000847,0.021507,170.769379,8.699407,0.215073,-1293.328125,0.022505,0.000000
15.870001,39.414139,-1293.328125,-0.002880,0.000865,0.021968,175.322845,8.931371,0.219675,-1293.328125,0.022947,0.000000
16.140001,39.764542,-1293.283691,-0.002867,0.000877,0.022270,176.881516,9.010774,0.222703,-1293.283691,0.023398,0.000000
16.410000,40.306709,-1293.283691,-0.002863,0.000900,0.022852,179.293198,9.133631,0.228517,-1293.283691,0.023849,0.000000
16.680000,41.755989,-1293.194702,-0.002854,0.000919,0.023345,185.739914,9.462043,0.233452,-1293.194702,0.024299,0.000000
16.950001,42.427002,-1293.283691,-0.002837,0.000936,0.023780,188.724731,9.614096,0.237797,-1293.283691,0.024750,0.000000
17.220001,42.896561,-1293.328125,-0.002828,0.000951,0.024152,190.813431,9.720500,0.241522,-1293.328125,0.025201,0.000000
17.490002,43.998413,-1293.328125,-0.002798,0.000972,0.024699,195.714722,9.970183,0.246987,-1293.328125,0.025653,0.000000
17.760000,44.549149,-1293.283691,-0.002790,0.000989,0.025132,198.164505,10.094981,0.251317,-1293.283691,0.026104,0.000000
18.030001,45.147552,-1293.239136,-0.002777,0.001004,0.025513,200.826340,10.230582,0.255132,-1293.239136,0.026555,0.000000
18.300001,44.909233,-1293.283691,-0.002768,0.001014,0.025748,199.766251,10.176578,0.257479,-1293.283691,0.026997,0.000000
18.570002,46.440430,-1293.283691,-0.002755,0.001042,0.026476,206.577347,10.523551,0.264761,-1293.283691,0.027448,0.000000
18.840000,47.260399,-1293.328125,-0.002738,0.001060,0.026927,210.224747,10.709359,0.269273,-1293.328125,0.027899,0.000000
19.110001,48.069565,-1293.328125,-0.002708,0.001077,0.027360,213.824097,10.892719,0.273602,-1293.328125,0.028349,0.000000
19.380001,48.478424,-1293.283691,-0.002699,0.001094,0.027786,215.642807,10.985368,0.277857,-1293.283691,0.028800,0.000000
19.650002,49.637619,-1293.239136,-0.002677,0.001115,0.028323,220.799164,11.248045,0.283231,-1293.239136,0.029251,0.000000
19.920000,50.070320,-1293.328125,-0.002673,0.001131,0.028739,222.723907,11.346096,0.287395,-1293.328125,0.029702,0.000000
20.190001,49.708748,-1293.328125,-0.002669,0.001137,0.028888,221.115555,11.264164,0.288878,-1293.328125,0.030153,0.000000
20.460001,52.039795,-1293.239136,-0.002652,0.001173,0.029789,231.484573,11.792386,0.297886,-1293.239136,0.030605,0.000000
20.730001,52.045380,-1293.194702,-0.002634,0.001184,0.030067,231.509415,11.793652,0.300672,-1293.194702,0.031056,0.000000
21.000002,53.126755,-1293.239136,-0.002621,0.001204,0.030579,236.319611,12.038694,0.305789,-1293.239136,0.031498,0.000000
21.270000,53.408264,-1293.239136,-0.002604,0.001217,0.030907,237.571823,12.102486,0.309075,-1293.239136,0.031949,0.000000
21.540001,54.611031,-1293.283691,-0.002587,0.001240,0.031498,242.921997,12.375036,0.314979,-1293.283691,0.032400,0.000000
21.810001,55.340881,-1293.283691,-0.002574,0.001258,0.031949,246.168533,12.540423,0.319491,-1293.283691,0.032850,0.000000
22.080002,55.085800,-1293.194702,-0.002557,0.001266,0.032147,245.033875,12.482621,0.321474,-1293.194702,0.033301,0.000000
22.350000,57.231041,-1293.194702,-0.002539,0.001297,0.032945,254.576385,12.968740,0.329452,-1293.194702,0.033752,0.000000
22.620001,57.423187,-1293.283691,-0.002531,0.001307,0.033206,255.431091,13.012280,0.332056,-1293.283691,0.034203,0.000000
22.890001,57.967964,-1293.239136,-0.002518,0.001325,0.033666,257.854370,13.135729,0.336659,-1293.239136,0.034654,0.000000
23.160002,58.636002,-1293.150269,-0.002505,0.001342,0.034091,260.825958,13.287108,0.340913,-1293.150269,0.035106,0.000000
23.430000,59.592255,-1293.194702,-0.002475,0.001363,0.034620,265.079590,13.503798,0.346197,-1293.194702,0.035548,0.000000
23.700001,60.128471,-1293.194702,-0.002462,0.001378,0.034992,267.464813,13.625306,0.349921,-1293.194702,0.035999,0.000000
23.970001,60.675858,-1293.150269,-0.002449,0.001391,0.035339,269.899689,13.749346,0.353388,-1293.150269,0.036450,0.000000
24.240002,62.633797,-1293.239136,-0.002445,0.001421,0.036094,278.609039,14.193021,0.360943,-1293.239136,0.036900,0.000000
24.510000,63.129051,-1293.239136,-0.002432,0.001435,0.036450,280.812042,14.305247,0.364501,-1293.239136,0.037351,0.000000
24.780001,63.396034,-1293.239136,-0.002414,0.001451,0.036866,281.999634,14.365746,0.368664,-1293.239136,0.037802,0.000000
25.050001,64.410759,-1293.194702,-0.002406,0.001469,0.037308,286.513367,14.595687,0.373085,-1293.194702,0.038253,0.000000
25.320002,64.919792,-1293.283691,-0.002393,0.001483,0.037664,288.777649,14.711036,0.376642,-1293.283691,0.038704,0.000000
25.590002,65.721138,-1293.283691,-0.002376,0.001501,0.038123,292.342224,14.892623,0.381230,-1293.283691,0.039155,0.000000
25.860001,65.895409,-1293.239136,-0.002363,0.001504,0.038202,293.117432,14.932113,0.382017,-1293.239136,0.038444,0.000000
26.130001,64.792442,-1293.194702,-0.002354,0.001504,0.038202,288.211182,14.682177,0.382017,-1293.194702,288.274109,0.000000
26.400002,65.862633,-1293.194702,-0.002328,0.001505,0.038227,292.971619,14.924685,0.382274,-1293.194702,294.500488,0.000000
26.670002,65.932640,-1293.239136,-0.002333,0.001537,0.039051,293.283020,14.940550,0.390510,-1293.239136,294.500488,0.000000
26.940001,65.103737,-1293.194702,-0.002315,0.001538,0.039060,289.595886,14.752718,0.390601,-1293.194702,294.500488,0.000000
27.210001,65.488029,-1293.194702,-0.002294,0.001547,0.039293,291.305298,14.839800,0.392933,-1293.194702,294.500488,0.000000
27.480001,66.905281,-1293.150269,-0.002289,0.001572,0.039928,297.609558,15.160954,0.399276,-1293.150269,294.500488,0.000000
27.750002,65.813850,-1293.150269,-0.002272,0.001514,0.038453,292.754639,14.913632,0.384530,-1293.150269,294.500488,0.000000
28.020000,65.062035,-1293.150269,-0.002268,0.001569,0.039849,289.410370,14.743267,0.398489,-1293.150269,294.500488,0.000000
28.290001,65.186409,-1293.194702,-0.002264,0.001577,0.040049,289.963623,14.771451,0.400487,-1293.194702,294.500488,0.000000
28.560001,65.193474,-1293.283691,-0.002255,0.001584,0.040239,289.995056,14.773052,0.402395,-1293.283691,294.500488,0.000000
28.830002,65.251198,-1293.150269,-0.002259,0.001592,0.040447,290.251831,14.786133,0.404469,-1293.150269,294.500488,0.000000
29.100002,65.890556,-1293.194702,-0.002242,0.001605,0.040760,293.095825,14.931014,0.407603,-1293.194702,294.500488,0.000000
29.370001,65.290291,-1293.194702,-0.002242,0.001604,0.040742,290.425720,14.794991,0.407421,-1293.194702,294.500488,0.000000
29.640001,65.986259,-1293.283691,-0.002238,0.001611,0.040924,293.521545,14.952700,0.409238,-1293.283691,294.500488,0.000000
29.910002,65.272789,-1293.194702,-0.002229,0.001612,0.040933,290.347870,14.791025,0.409329,-1293.194702,294.500488,0.000000
30.180002,65.380791,-1293.239136,-0.002203,0.001622,0.041202,290.828278,14.815498,0.412024,-1293.239136,294.500488,0.000000
30.450001,65.543510,-1293.150269,-0.002207,0.001632,0.041454,291.552094,14.852372,0.414537,-1293.150269,294.500488,0.000000
30.720001,65.229225,-1293.194702,-0.002199,0.001632,0.041454,290.154083,14.781154,0.414537,-1293.194702,294.500488,0.000000
30.990002,65.289925,-1293.239136,-0.002195,0.001638,0.041610,290.424103,14.794909,0.416096,-1293.239136,294.500488,0.000000
31.260002,64.804359,-1293.283691,-0.002199,0.001638,0.041610,288.264191,14.684877,0.416096,-1293.283691,294.500488,0.000000
31.530001,64.847923,-1293.194702,-0.002177,0.001644,0.041756,288.457977,14.694750,0.417565,-1293.194702,294.500488,0.000000
31.800001,64.646095,-1293.194702,-0.002169,0.001656,0.042052,287.560181,14.649014,0.420517,-1293.194702,294.500488,0.000000
32.070000,66.331459,-1293.150269,-0.002169,0.001593,0.040456,295.057068,15.030923,0.404560,-1293.150269,294.500488,0.000000
32.340000,65.750923,-1293.194702,-0.002160,0.001605,0.040760,292.474701,14.899372,0.407603,-1293.194702,294.500488,0.000000
32.610001,65.265724,-1293.283691,-0.002164,0.001642,0.041714,290.316437,14.789425,0.417141,-1293.283691,294.500488,0.000000
32.880001,66.558220,-1293.194702,-0.002156,0.001667,0.042338,296.065735,15.082308,0.423378,-1293.194702,294.500488,0.000000
33.150002,65.887215,-1293.239136,-0.002147,0.001656,0.042068,293.080963,14.930256,0.420684,-1293.239136,294.500488,0.000000
33.420002,65.416527,-1293.194702,-0.002130,0.001657,0.042087,290.987244,14.823597,0.420865,-1293.194702,294.500488,0.000000
33.690002,65.642937,-1293.239136,-0.002134,0.001685,0.042789,291.994354,14.874902,0.427890,-1293.239136,294.500488,0.000000
33.960003,65.237053,-1293.283691,-0.002134,0.001685,0.042789,290.188904,14.782928,0.427890,-1293.283691,294.500488,0.000000
34.230003,65.573296,-1293.239136,-0.002130,0.001695,0.043040,291.684601,14.859120,0.430403,-1293.239136,294.500488,0.000000
34.500000,65.226997,-1293.239136,-0.002126,0.001695,0.043049,290.144165,14.780648,0.430494,-1293.239136,294.500488,0.000000
34.770000,65.286568,-1293.194702,-0.002108,0.001701,0.043196,290.409149,14.794147,0.431962,-1293.194702,294.500488,0.000000
35.040001,65.247475,-1293.194702,-0.002113,0.001704,0.043275,290.235260,14.785289,0.432750,-1293.194702,294.500488,0.000000
35.310001,65.392708,-1293.328125,-0.002117,0.001710,0.043422,290.881287,14.818199,0.434218,-1293.328125,294.500488,0.000000
35.580002,65.114906,-1293.283691,-0.002104,0.001710,0.043431,289.645569,14.755248,0.434309,-1293.283691,294.500488,0.000000
35.850002,65.459358,-1293.239136,-0.002104,0.001716,0.043596,291.177765,14.833302,0.435959,-1293.239136,294.500488,0.000000
36.120003,65.094429,-1293.150269,-0.002100,0.001717,0.043613,289.554474,14.750608,0.436126,-1293.150269,294.500488,0.000000
36.390003,65.191246,-1293.239136,-0.002100,0.001721,0.043717,289.985138,14.772547,0.437171,-1293.239136,294.500488,0.000000
36.660000,64.884041,-1293.328125,-0.002095,0.001722,0.043734,288.618622,14.702934,0.437337,-1293.328125,294.500488,0.000000
36.930000,66.036903,-1293.239136,-0.002065,0.001727,0.043873,293.746826,14.964176,0.438730,-1293.239136,294.500488,0.000000
37.200001,65.600105,-1293.194702,-0.002057,0.001727,0.043873,291.803833,14.865196,0.438730,-1293.194702,294.500488,0.000000
37.470001,65.267952,-1293.239136,-0.002070,0.001729,0.043908,290.326355,14.789929,0.439078,-1293.239136,294.500488,0.000000
37.740002,65.825768,-1293.194702,-0.002065,0.001740,0.044194,292.807648,14.916332,0.441939,-1293.194702,294.500488,0.000000
38.010002,65.477974,-1293.283691,-0.002065,0.001740,0.044194,291.260590,14.837522,0.441939,-1293.283691,294.500488,0.000000
38.280003,65.122353,-1293.283691,-0.002048,0.001742,0.044255,289.678680,14.756936,0.442545,-1293.283691,294.500488,0.000000
38.550003,65.306679,-1293.239136,-0.002052,0.001747,0.044376,290.498627,14.798705,0.443756,-1293.239136,294.500488,0.000000
38.820004,65.269814,-1293.239136,-0.002048,0.001751,0.044471,290.334625,14.790351,0.444710,-1293.239136,294.500488,0.000000
39.090000,65.075813,-1293.239136,-0.002052,0.001752,0.044497,289.471680,14.746390,0.444967,-1293.239136,294.500488,0.000000
39.360001,65.091454,-1293.283691,-0.002048,0.001755,0.044566,289.541260,14.749934,0.445664,-1293.283691,294.500488,0.000000
39.630001,64.871376,-1293.283691,-0.002052,0.001755,0.044575,288.562286,14.700065,0.445755,-1293.283691,294.500488,0.000000
39.900002,65.504036,-1293.283691,-0.002035,0.001764,0.044818,291.376495,14.843427,0.448177,-1293.283691,294.500488,0.000000
40.170002,65.270561,-1293.283691,-0.002031,0.001764,0.044818,290.337952,14.790521,0.448177,-1293.283691,294.500488,0.000000
40.440002,65.032249,-1293.283691,-0.002035,0.001765,0.044827,289.277893,14.736519,0.448268,-1293.283691,294.500488,0.000000
40.710003,64.909355,-1293.328125,-0.002031,0.001767,0.044878,288.731232,14.708670,0.448783,-1293.328125,294.500488,0.000000
40.980003,65.306313,-1293.283691,-0.002022,0.001775,0.045087,290.496979,14.798622,0.450872,-1293.283691,294.500488,0.000000
41.250004,65.169273,-1293.283691,-0.002009,0.001775,0.045087,289.887421,14.767569,0.450872,-1293.283691,294.500488,0.000000
41.520000,64.943245,-1293.194702,-0.002018,0.001775,0.045087,288.881989,14.716350,0.450872,-1293.194702,294.500488,0.000000
41.790001,64.984947,-1293.239136,-0.002018,0.001790,0.045478,289.067474,14.725800,0.454778,-1293.239136,294.500488,0.000000
42.060001,66.074135,-1293.328125,-0.002005,0.001787,0.045382,293.912445,14.972612,0.453824,-1293.328125,294.500488,0.000000
42.330002,65.776237,-1293.328125,-0.002013,0.001786,0.045373,292.587311,14.905108,0.453733,-1293.328125,294.500488,0.000000
42.600002,65.477226,-1293.283691,-0.002005,0.001787,0.045382,291.257263,14.837352,0.453824,-1293.283691,294.500488,0.000000
42.870003,65.176720,-1293.328125,-0.001988,0.001787,0.045390,289.920532,14.769256,0.453900,-1293.328125,294.500488,0.000000
43.140003,64.891487,-1293.328125,-0.001996,0.001787,0.045390,288.651764,14.704621,0.453900,-1293.328125,294.500488,0.000000
43.410004,66.309486,-1293.283691,-0.001992,0.001798,0.045676,294.959320,15.025945,0.456761,-1293.283691,294.500488,0.000000
43.680000,65.996681,-1293.372559,-0.001996,0.001798,0.045669,293.567902,14.955062,0.456685,-1293.372559,294.500488,0.000000
43.950001,65.749062,-1293.328125,-0.001988,0.001798,0.045669,292.466431,14.898951,0.456685,-1293.328125,294.500488,0.000000
44.220001,65.457863,-1293.283691,-0.001983,0.001798,0.045676,291.171112,14.832964,0.456761,-1293.283691,294.500488,0.000000
44.490002,65.206886,-1293.239136,-0.001983,0.001799,0.045685,290.054718,14.776092,0.456852,-1293.239136,294.500488,0.000000
44.760002,64.952553,-1293.283691,-0.001983,0.001799,0.045694,288.923370,14.718459,0.456943,-1293.283691,294.500488,0.000000
45.030003,64.676628,-1293.328125,-0.001988,0.001799,0.045694,287.696014,14.655933,0.456943,-1293.328125,294.500488,0.000000
45.300003,66.582436,-1293.328125,-0.001966,0.001767,0.044878,296.173462,15.087796,0.448783,-1293.328125,294.500488,0.000000
45.570004,66.271873,-1293.239136,-0.001953,0.001767,0.044878,294.792023,15.017421,0.448783,-1293.239136,294.500488,0.000000
45.840004,65.989235,-1293.283691,-0.001979,0.001767,0.044878,293.534790,14.953375,0.448783,-1293.283691,294.500488,0.000000
46.110001,65.746452,-1293.283691,-0.001975,0.001768,0.044906,292.454834,14.898359,0.449055,-1293.283691,294.500488,0.000000
46.380001,65.484673,-1293.328125,-0.001970,0.001774,0.045052,291.290375,14.839039,0.450524,-1293.328125,294.500488,0.000000
46.650002,65.333870,-1293.372559,-0.001949,0.001808,0.045929,290.619568,14.804866,0.459289,-1293.372559,294.500488,0.000000
46.920002,65.235191,-1293.283691,-0.001953,0.001820,0.046223,290.180634,14.782506,0.462227,-1293.283691,294.500488,0.000000
47.190002,65.235191,-1293.283691,-0.001957,0.001824,0.046327,290.180634,14.782506,0.463271,-1293.283691,294.500488,0.000000
47.460003,65.211357,-1293.283691,-0.001957,0.001827,0.046397,290.074615,14.777104,0.463968,-1293.283691,294.500488,0.000000
47.730003,65.192741,-1293.328125,-0.001970,0.001830,0.046474,289.991791,14.772886,0.464740,-1293.328125,294.500488,0.000000
48.000004,65.152519,-1293.328125,-0.001966,0.001831,0.046509,289.812866,14.763772,0.465088,-1293.328125,294.500488,0.000000
48.270000,65.295143,-1293.283691,-0.001944,0.001835,0.046604,290.447296,14.796091,0.466042,-1293.283691,294.500488,0.000000
48.540001,65.200188,-1293.239136,-0.001957,0.001836,0.046631,290.024933,14.774573,0.466314,-1293.239136,294.500488,0.000000
48.810001,65.120491,-1293.283691,-0.001962,0.001838,0.046683,289.670410,14.756514,0.466829,-1293.283691,294.500488,0.000000
49.080002,65.254173,-1293.328125,-0.001949,0.001841,0.046769,290.265045,14.786807,0.467692,-1293.328125,294.500488,0.000000
49.350002,65.165184,-1293.283691,-0.001940,0.001841,0.046769,289.869202,14.766642,0.467692,-1293.283691,294.500488,0.000000
49.620003,65.054955,-1293.283691,-0.001949,0.001843,0.046822,289.378876,14.741663,0.468222,-1293.283691,294.500488,0.000000
49.890003,65.191246,-1293.283691,-0.001949,0.001846,0.046890,289.985138,14.772547,0.468903,-1293.283691,294.500488,0.000000
50.160004,65.164070,-1293.283691,-0.001949,0.001849,0.046960,289.864258,14.766389,0.469599,-1293.283691,294.500488,0.000000
50.430004,65.089958,-1293.283691,-0.001944,0.001849,0.046960,289.534607,14.749595,0.469599,-1293.283691,294.500488,0.000000
50.700001,64.953667,-1293.328125,-0.001927,0.001849,0.046960,288.928345,14.718711,0.469599,-1293.328125,294.500488,0.000000
50.970001,66.211922,-1293.283691,-0.001932,0.001856,0.047134,294.525330,15.003836,0.471341,-1293.283691,294.500488,0.000000
51.240002,65.937859,-1293.194702,-0.001919,0.001855,0.047125,293.306244,14.941732,0.471250,-1293.194702,294.500488,0.000000
51.510002,65.753151,-1293.239136,-0.001932,0.001855,0.047125,292.484619,14.899878,0.471250,-1293.239136,294.500488,0.000000
51.780003,65.536812,-1293.283691,-0.001927,0.001855,0.047125,291.522308,14.850854,0.471250,-1293.283691,294.500488,0.000000
52.050003,65.327538,-1293.328125,-0.001919,0.001856,0.047134,290.591400,14.803432,0.471341,-1293.328125,294.500488,0.000000
52.320004,65.154747,-1293.283691,-0.001901,0.001856,0.047151,289.822784,14.764277,0.471507,-1293.283691,294.500488,0.000000
52.590004,64.951805,-1293.283691,-0.001910,0.001856,0.047151,288.920044,14.718289,0.471507,-1293.283691,294.500488,0.000000
52.860001,65.543877,-1293.283691,-0.001919,0.001869,0.047481,291.553711,14.852454,0.474808,-1293.283691,294.500488,0.000000
53.130001,65.397545,-1293.239136,-0.001936,0.001869,0.047481,290.902802,14.819296,0.474808,-1293.239136,294.500488,0.000000
53.400002,65.256035,-1293.328125,-0.001910,0.001869,0.047481,290.273346,14.787229,0.474808,-1293.328125,294.500488,0.000000
53.670002,65.109322,-1293.372559,-0.001914,0.001870,0.047490,289.620728,14.753983,0.474898,-1293.372559,294.500488,0.000000
53.940002,64.972664,-1293.372559,-0.001901,0.001870,0.047490,289.012848,14.723016,0.474898,-1293.372559,294.500488,0.000000
54.210003,65.654854,-1293.239136,-0.001901,0.001881,0.047776,292.047363,14.877603,0.477760,-1293.239136,294.500488,0.000000
54.480003,65.571434,-1293.328125,-0.001919,0.001879,0.047723,291.676300,14.858700,0.477230,-1293.328125,294.500488,0.000000
54.750004,65.415794,-1293.372559,-0.001910,0.001879,0.047723,290.983978,14.823431,0.477230,-1293.372559,294.500488,0.000000
55.020004,65.257164,-1293.283691,-0.001906,0.001879,0.047732,290.278351,14.787484,0.477321,-1293.283691,294.500488,0.000000
55.290001,65.110435,-1293.328125,-0.001897,0.001879,0.047732,289.625671,14.754235,0.477321,-1293.328125,294.500488,0.000000
55.560001,64.975639,-1293.283691,-0.001906,0.001879,0.047732,289.026093,14.723690,0.477321,-1293.283691,294.500488,0.000000
55.830002,64.787971,-1293.283691,-0.001893,0.001879,0.047732,288.191284,14.681164,0.477321,-1293.283691,294.500488,0.000000
56.100002,65.999290,-1293.283691,-0.001888,0.001885,0.047871,293.579498,14.955653,0.478714,-1293.283691,294.500488,0.000000
56.370003,65.852959,-1293.239136,-0.001888,0.001885,0.047871,292.928589,14.922493,0.478714,-1293.239136,294.500488,0.000000
56.640003,65.601967,-1293.372559,-0.001884,0.001885,0.047871,291.812134,14.865618,0.478714,-1293.372559,294.500488,0.000000
56.910004,65.438881,-1293.150269,-0.001876,0.001885,0.047879,291.086670,14.828663,0.478789,-1293.150269,294.500488,0.000000
57.180004,65.252312,-1293.239136,-0.001893,0.001885,0.047879,290.256775,14.786386,0.478789,-1293.239136,294.500488,0.000000
57.450005,65.065758,-1293.283691,-0.001880,0.001885,0.047879,289.426941,14.744112,0.478789,-1293.283691,294.500488,0.000000
57.720001,65.232582,-1293.372559,-0.001888,0.001895,0.048139,290.169006,14.781914,0.481393,-1293.372559,294.500488,0.000000
57.990002,65.169273,-1293.328125,-0.001876,0.001895,0.048139,289.887421,14.767569,0.481393,-1293.328125,294.500488,0.000000
58.260002,65.045280,-1293.283691,-0.001880,0.001896,0.048148,289.335846,14.739471,0.481484,-1293.283691,294.500488,0.000000
58.530003,64.936546,-1293.239136,-0.001876,0.001896,0.048165,288.852173,14.714832,0.481651,-1293.239136,294.500488,0.000000
58.800003,64.940636,-1293.283691,-0.001871,0.001898,0.048218,288.870361,14.715758,0.482180,-1293.283691,294.500488,0.000000
59.070004,64.916069,-1293.283691,-0.001871,0.001899,0.048244,288.761108,14.710192,0.482438,-1293.283691,294.500488,0.000000
59.340004,64.846809,-1293.283691,-0.001863,0.001900,0.048260,288.453003,14.694497,0.482604,-1293.283691,294.500488,0.000000
59.610004,64.985329,-1293.372559,-0.001880,0.001903,0.048348,289.069183,14.725885,0.483482,-1293.372559,294.500488,0.000000
59.880001,64.907127,-1293.328125,-0.001867,0.001904,0.048356,288.721313,14.708166,0.483558,-1293.328125,294.500488,0.000000
60.150002,65.797096,-1293.328125,-0.001880,0.001914,0.048625,292.680115,14.909836,0.486253,-1293.328125,294.500488,0.000000
60.420002,65.765450,-1293.328125,-0.001867,0.001914,0.048625,292.539337,14.902664,0.486253,-1293.328125,294.500488,0.000000
60.690002,65.608299,-1293.328125,-0.001871,0.001914,0.048625,291.840302,14.867053,0.486253,-1293.328125,294.500488,0.000000
60.960003,65.516701,-1293.239136,-0.001850,0.001914,0.048625,291.432831,14.846296,0.486253,-1293.239136,294.500488,0.000000
61.230003,65.383766,-1293.239136,-0.001876,0.001915,0.048634,290.841522,14.816174,0.486344,-1293.239136,294.500488,0.000000
61.500004,65.276894,-1293.239136,-0.001863,0.001915,0.048634,290.366119,14.791956,0.486344,-1293.239136,294.500488,0.000000
61.770004,65.213966,-1293.328125,-0.001867,0.001916,0.048669,290.086212,14.777697,0.486692,-1293.328125,294.500488,0.000000
62.040005,65.093315,-1293.372559,-0.001867,0.001916,0.048669,289.549530,14.750356,0.486692,-1293.372559,294.500488,0.000000
62.310001,65.486916,-1293.283691,-0.001845,0.001922,0.048816,291.300354,14.839547,0.488161,-1293.283691,294.500488,0.000000
62.580002,65.391960,-1293.239136,-0.001858,0.001922,0.048816,290.877960,14.818030,0.488161,-1293.239136,294.500488,0.000000
62.850002,65.293282,-1293.283691,-0.001854,0.001922,0.048816,290.439026,14.795669,0.488161,-1293.283691,294.500488,0.000000
63.120003,65.188271,-1293.283691,-0.001858,0.001922,0.048816,289.971924,14.771873,0.488161,-1293.283691,294.500488,0.000000
63.390003,65.190880,-1293.328125,-0.001850,0.001926,0.048911,289.983521,14.772465,0.489114,-1293.328125,294.500488,0.000000
63.660004,65.230721,-1293.328125,-0.001850,0.001926,0.048911,290.160736,14.781493,0.489114,-1293.328125,294.500488,0.000000
63.930004,65.212105,-1293.239136,-0.001828,0.001927,0.048937,290.077942,14.777274,0.489372,-1293.239136,294.500488,0.000000
64.200005,65.213966,-1293.239136,-0.001850,0.001929,0.048998,290.086212,14.777697,0.489977,-1293.239136,294.500488,0.000000
64.470001,65.221031,-1293.239136,-0.001841,0.001929,0.049007,290.117645,14.779297,0.490068,-1293.239136,294.500488,0.000000
64.740005,65.135765,-1293.328125,-0.001850,0.001929,0.049007,289.738342,14.759975,0.490068,-1293.328125,294.500488,0.000000
65.010002,65.063896,-1293.283691,-0.001832,0.001931,0.049042,289.418671,14.743690,0.490416,-1293.283691,294.500488,0.000000
65.280006,65.221031,-1293.283691,-0.001824,0.001933,0.049102,290.117645,14.779297,0.491022,-1293.283691,294.500488,0.000000
65.550003,65.133156,-1293.194702,-0.001837,0.001933,0.049102,289.726746,14.759384,0.491022,-1293.194702,294.500488,0.000000
65.820000,65.161079,-1293.283691,-0.001832,0.001935,0.049154,289.850952,14.765712,0.491537,-1293.283691,294.500488,0.000000
66.090004,65.100761,-1293.283691,-0.001824,0.001935,0.049154,289.582642,14.752044,0.491537,-1293.283691,294.500488,0.000000
66.360001,65.060921,-1293.283691,-0.001832,0.001937,0.049188,289.405426,14.743015,0.491885,-1293.283691,294.500488,0.000000
66.630005,65.009163,-1293.239136,-0.001828,0.001937,0.049207,289.175201,14.731286,0.492067,-1293.239136,294.500488,0.000000
66.900002,65.727837,-1293.239136,-0.001832,0.001944,0.049379,292.372009,14.894140,0.493793,-1293.239136,294.500488,0.000000
67.170006,65.577400,-1293.283691,-0.001837,0.001944,0.049379,291.702850,14.860051,0.493793,-1293.283691,294.500488,0.000000
67.440002,65.485054,-1293.372559,-0.001828,0.001944,0.049379,291.292053,14.839126,0.493793,-1293.372559,294.500488,0.000000
67.710007,65.333122,-1293.239136,-0.001815,0.001944,0.049379,290.616241,14.804697,0.493793,-1293.239136,294.500488,0.000000
67.980003,65.267204,-1293.283691,-0.001824,0.001944,0.049379,290.323029,14.789760,0.493793,-1293.283691,294.500488,0.000000
68.250000,65.139122,-1293.283691,-0.001811,0.001944,0.049379,289.753296,14.760736,0.493793,-1293.283691,294.500488,0.000000
68.520004,65.037834,-1293.239136,-0.001828,0.001944,0.049379,289.302734,14.737784,0.493793,-1293.239136,294.500488,0.000000
68.790001,64.948082,-1293.283691,-0.001828,0.001944,0.049379,288.903503,14.717445,0.493793,-1293.283691,294.500488,0.000000
69.060005,65.841408,-1293.328125,-0.001815,0.001960,0.049788,292.877197,14.919876,0.497880,-1293.328125,294.500488,0.000000
69.330002,65.843651,-1293.239136,-0.001802,0.001950,0.049519,292.887177,14.920384,0.495185,-1293.239136,294.500488,0.000000
69.600006,65.794487,-1293.283691,-0.001807,0.001950,0.049519,292.668488,14.909244,0.495185,-1293.283691,294.500488,0.000000
69.870003,65.601234,-1293.239136,-0.001811,0.001950,0.049519,291.808868,14.865452,0.495185,-1293.239136,294.500488,0.000000
70.140007,65.515953,-1293.328125,-0.001819,0.001950,0.049519,291.429504,14.846127,0.495185,-1293.328125,294.500488,0.000000
70.410004,65.349510,-1293.328125,-0.001807,0.001950,0.049519,290.689148,14.808411,0.495185,-1293.328125,294.500488,0.000000
70.680000,65.263481,-1293.239136,-0.001807,0.001951,0.049544,290.306458,14.788917,0.495443,-1293.239136,294.500488,0.000000
70.950005,65.180824,-1293.283691,-0.001807,0.001957,0.049718,289.938782,14.770185,0.497184,-1293.283691,294.500488,0.000000
71.220001,65.399025,-1293.283691,-0.001807,0.001959,0.049753,290.909393,14.819631,0.497532,-1293.283691,294.500488,0.000000
71.490005,65.323067,-1293.328125,-0.001811,0.001959,0.049753,290.571503,14.802419,0.497532,-1293.328125,294.500488,0.000000
71.760002,65.259026,-1293.372559,-0.001824,0.001959,0.049753,290.286652,14.787907,0.497532,-1293.372559,294.500488,0.000000
72.030006,65.275780,-1293.194702,-0.001815,0.001961,0.049821,290.361176,14.791703,0.498213,-1293.194702,294.500488,0.000000
72.300003,65.259758,-1293.328125,-0.001798,0.001961,0.049821,290.289886,14.788073,0.498213,-1293.328125,294.500488,0.000000
72.570000,65.203163,-1293.239136,-0.001802,0.001961,0.049821,290.038147,14.775248,0.498213,-1293.239136,294.500488,0.000000
72.840004,65.132790,-1293.283691,-0.001819,0.001963,0.049849,289.725128,14.759300,0.498486,-1293.283691,294.500488,0.000000
73.110001,65.064262,-1293.283691,-0.001807,0.001963,0.049849,289.420288,14.743773,0.498486,-1293.283691,294.500488,0.000000
73.380005,65.077293,-1293.283691,-0.001798,0.001966,0.049935,289.478271,14.746725,0.499349,-1293.283691,294.500488,0.000000
73.650002,65.233696,-1293.239136,-0.001794,0.001967,0.049952,290.173981,14.782166,0.499515,-1293.239136,294.500488,0.000000
73.920006,65.186409,-1293.283691,-0.001785,0.001967,0.049952,289.963623,14.771451,0.499515,-1293.283691,294.500488,0.000000
74.190002,65.129799,-1293.239136,-0.001811,0.001967,0.049961,289.711823,14.758624,0.499606,-1293.239136,294.500488,0.000000
74.460007,65.060539,-1293.328125,-0.001798,0.001967,0.049970,289.403748,14.742929,0.499697,-1293.328125,294.500488,0.000000
74.730003,64.997612,-1293.283691,-0.001794,0.001967,0.049970,289.123810,14.728669,0.499697,-1293.283691,294.500488,0.000000
75.000000,65.593788,-1293.239136,-0.001789,0.001975,0.050177,291.775757,14.863765,0.501771,-1293.239136,294.500488,0.000000
75.270004,65.581490,-1293.194702,-0.001802,0.001975,0.050177,291.721039,14.860978,0.501771,-1293.194702,294.500488,0.000000
75.540001,65.533455,-1293.328125,-0.001794,0.001975,0.050177,291.507355,14.850093,0.501771,-1293.328125,294.500488,0.000000
75.810005,65.473137,-1293.283691,-0.001785,0.001975,0.050177,291.239044,14.836425,0.501771,-1293.283691,294.500488,0.000000
76.080002,65.349129,-1293.239136,-0.001785,0.001975,0.050177,290.687439,14.808324,0.501771,-1293.239136,294.500488,0.000000
76.350006,65.299980,-1293.239136,-0.001776,0.001975,0.050177,290.468811,14.797187,0.501771,-1293.239136,294.500488,0.000000
76.620003,65.226616,-1293.283691,-0.001781,0.001976,0.050186,290.142487,14.780562,0.501862,-1293.283691,294.500488,0.000000
76.890007,65.123100,-1293.283691,-0.001785,0.001976,0.050195,289.682007,14.757106,0.501953,-1293.283691,294.500488,0.000000
77.160004,65.379295,-1293.283691,-0.001789,0.001982,0.050333,290.821625,14.815161,0.503330,-1293.283691,294.500488,0.000000
77.430000,65.454521,-1293.328125,-0.001776,0.001981,0.050325,291.156250,14.832207,0.503255,-1293.328125,294.500488,0.000000
77.700005,65.383385,-1293.328125,-0.001772,0.001981,0.050325,290.839813,14.816087,0.503255,-1293.328125,294.500488,0.000000
77.970001,65.318596,-1293.239136,-0.001794,0.001981,0.050325,290.551636,14.801406,0.503255,-1293.239136,294.500488,0.000000
78.240005,65.263481,-1293.283691,-0.001781,0.001981,0.050325,290.306458,14.788917,0.503255,-1293.283691,294.500488,0.000000
78.510002,65.176720,-1293.328125,-0.001794,0.001982,0.050333,289.920532,14.769256,0.503330,-1293.328125,294.500488,0.000000
78.780006,65.594902,-1293.328125,-0.001785,0.001988,0.050498,291.780701,14.864017,0.504981,-1293.328125,294.500488,0.000000
79.050003,65.592659,-1293.328125,-0.001772,0.001988,0.050498,291.770721,14.863509,0.504981,-1293.328125,294.500488,0.000000
79.320007,65.572929,-1293.328125,-0.001763,0.001988,0.050498,291.682953,14.859038,0.504981,-1293.328125,294.500488,0.000000
79.590004,65.510368,-1293.328125,-0.001772,0.001988,0.050498,291.404663,14.844861,0.504981,-1293.328125,294.500488,0.000000
79.860001,65.436272,-1293.283691,-0.001776,0.001988,0.050498,291.075073,14.828072,0.504981,-1293.283691,294.500488,0.000000
80.130005,65.345039,-1293.328125,-0.001772,0.001988,0.050507,290.669250,14.807397,0.505072,-1293.328125,294.500488,0.000000
80.400002,65.297371,-1293.283691,-0.001785,0.001988,0.050507,290.457214,14.796596,0.505072,-1293.283691,294.500488,0.000000
80.670006,65.242638,-1293.328125,-0.001759,0.001988,0.050507,290.213745,14.784193,0.505072,-1293.328125,294.500488,0.000000
80.940002,65.156242,-1293.328125,-0.001776,0.001989,0.050516,289.829437,14.764615,0.505162,-1293.328125,294.500488,0.000000
81.210007,65.263481,-1293.283691,-0.001768,0.001992,0.050593,290.306458,14.788917,0.505934,-1293.283691,294.500488,0.000000
81.480003,65.237053,-1293.328125,-0.001763,0.001992,0.050593,290.188904,14.782928,0.505934,-1293.328125,294.500488,0.000000
81.750008,65.197945,-1293.328125,-0.001768,0.001992,0.050593,290.014954,14.774065,0.505934,-1293.328125,294.500488,0.000000
82.020004,65.126823,-1293.239136,-0.001772,0.001993,0.050628,289.698578,14.757949,0.506283,-1293.239136,294.500488,0.000000
82.290001,65.180443,-1293.239136,-0.001759,0.001994,0.050637,289.937103,14.770100,0.506374,-1293.239136,294.500488,0.000000
82.560005,65.142464,-1293.283691,-0.001763,0.001994,0.050637,289.768158,14.761494,0.506374,-1293.283691,294.500488,0.000000
82.830002,65.068367,-1293.328125,-0.001763,0.001994,0.050637,289.438538,14.744702,0.506374,-1293.328125,294.500488,0.000000
83.100006,65.391579,-1293.328125,-0.001746,0.001998,0.050758,290.876282,14.817944,0.507585,-1293.328125,294.500488,0.000000
83.370003,65.368126,-1293.283691,-0.001763,0.001998,0.050758,290.771942,14.812629,0.507585,-1293.283691,294.500488,0.000000
83.640007,65.318977,-1293.283691,-0.001768,0.001998,0.050758,290.553314,14.801492,0.507585,-1293.283691,294.500488,0.000000
83.910004,65.263115,-1293.328125,-0.001759,0.001998,0.050758,290.304840,14.788833,0.507585,-1293.328125,294.500488,0.000000
84.180000,65.215080,-1293.372559,-0.001746,0.001998,0.050758,290.091156,14.777948,0.507585,-1293.372559,294.500488,0.000000
84.450005,65.140602,-1293.372559,-0.001755,0.001998,0.050758,289.759857,14.761071,0.507585,-1293.372559,294.500488,0.000000
84.720001,65.064262,-1293.372559,-0.001746,0.001998,0.050758,289.420288,14.743773,0.507585,-1293.372559,294.500488,0.000000
84.990005,65.395683,-1293.328125,-0.001755,0.002004,0.050898,290.894531,14.818873,0.508978,-1293.328125,294.500488,0.000000
85.260002,65.384132,-1293.328125,-0.001755,0.002004,0.050898,290.843140,14.816257,0.508978,-1293.328125,294.500488,0.000000
85.530006,65.348381,-1293.328125,-0.001759,0.002004,0.050898,290.684113,14.808154,0.508978,-1293.328125,294.500488,0.000000
85.800003,65.302589,-1293.372559,-0.001759,0.002004,0.050898,290.480438,14.797779,0.508978,-1293.372559,294.500488,0.000000
86.070007,65.245979,-1293.372559,-0.001750,0.002004,0.050907,290.228607,14.784950,0.509068,-1293.372559,294.500488,0.000000
86.340004,65.225136,-1293.283691,-0.001742,0.002005,0.050923,290.135895,14.780228,0.509235,-1293.283691,1681.640991,0.000000
86.610001,65.133156,-1293.283691,-0.001750,0.001996,0.050698,289.726746,14.759384,0.506979,-1293.283691,0.050784,0.000000
86.880005,64.952934,-1293.328125,-0.001759,0.001991,0.050568,288.925079,14.718545,0.505677,-1293.328125,0.050333,0.000000
87.150002,64.906013,-1293.328125,-0.001733,0.001978,0.050238,288.716370,14.707913,0.502377,-1293.328125,0.049883,0.000000
87.420006,64.748131,-1293.372559,-0.001742,0.001966,0.049935,288.014069,14.672136,0.499349,-1293.372559,0.049432,0.000000
87.690002,64.636406,-1293.328125,-0.001738,0.001947,0.049458,287.517090,14.646819,0.494580,-1293.328125,0.048990,0.000000
87.960007,64.586891,-1293.328125,-0.001742,0.001930,0.049033,287.296844,14.635599,0.490326,-1293.328125,0.048539,0.000000
88.230003,64.480385,-1293.239136,-0.001738,0.001915,0.048634,286.823090,14.611465,0.486344,-1293.239136,0.048088,0.000000
88.500008,64.412621,-1293.417114,-0.001746,0.001899,0.048235,286.521637,14.596108,0.482347,-1293.417114,0.047637,0.000000
88.770004,64.326225,-1293.283691,-0.001720,0.001880,0.047749,286.137329,14.576530,0.477487,-1293.283691,0.047186,0.000000
89.040001,64.247658,-1293.328125,-0.001738,0.001866,0.047402,285.787842,14.558728,0.474020,-1293.328125,0.046734,0.000000
89.310005,64.161644,-1293.283691,-0.001742,0.001846,0.046883,285.405243,14.539236,0.468827,-1293.283691,0.046283,0.000000
89.580002,64.077477,-1293.328125,-0.001720,0.001833,0.046569,285.030853,14.520164,0.465693,-1293.328125,0.045834,0.000000
89.850006,63.956459,-1293.372559,-0.001733,0.001818,0.046180,284.492523,14.492741,0.461803,-1293.372559,0.045382,0.000000
90.120003,63.776970,-1293.328125,-0.001729,0.001792,0.045513,283.694122,14.452068,0.455126,-1293.328125,0.044940,0.000000
90.390007,63.443703,-1293.283691,-0.001729,0.001775,0.045087,282.211670,14.376549,0.450872,-1293.283691,0.044489,0.000000
90.660004,63.024780,-1293.372559,-0.001707,0.001756,0.044610,280.348236,14.281619,0.446103,-1293.372559,0.044038,0.000000
90.930008,62.467712,-1293.328125,-0.001725,0.001746,0.044350,277.870270,14.155386,0.443499,-1293.328125,0.043587,0.000000
91.200005,61.799675,-1293.417114,-0.001725,0.001732,0.043985,274.898682,14.004007,0.439850,-1293.417114,0.043136,0.000000
91.470001,61.075783,-1293.328125,-0.001712,0.001716,0.043587,271.678650,13.839970,0.435869,-1293.328125,0.042685,0.000000
91.740005,60.194382,-1293.328125,-0.001712,0.001700,0.043171,267.757996,13.640243,0.431705,-1293.328125,0.042233,0.000000
92.010002,59.004280,-1293.328125,-0.001703,0.001680,0.042685,262.464142,13.370561,0.426845,-1293.328125,0.041782,0.000000
92.280006,57.887161,-1293.328125,-0.001712,0.001665,0.042294,257.494965,13.117418,0.422939,-1293.328125,0.041333,0.000000
92.550003,56.602852,-1293.328125,-0.001712,0.001648,0.041861,251.782059,12.826389,0.418609,-1293.328125,0.040881,0.000000
92.820007,55.189697,-1293.372559,-0.001720,0.001629,0.041366,245.496033,12.506164,0.413659,-1293.372559,0.040439,0.000000
93.090004,54.099014,-1293.372559,-0.001703,0.001615,0.041012,240.644440,12.259011,0.410116,-1293.372559,0.039988,0.000000
93.360008,52.531700,-1293.372559,-0.001720,0.001597,0.040570,233.672668,11.903853,0.405695,-1293.372559,0.039537,0.000000
93.630005,50.778572,-1293.283691,-0.001729,0.001578,0.040091,225.874374,11.506589,0.400911,-1293.283691,0.039086,0.000000
93.900002,48.774834,-1293.372559,-0.001729,0.001556,0.039528,216.961288,11.052535,0.395279,-1293.372559,0.038635,0.000000
94.170006,46.965851,-1293.328125,-0.001712,0.001539,0.039095,208.914536,10.642613,0.390949,-1293.328125,0.038184,0.000000
94.440002,45.447311,-1293.283691,-0.001707,0.001524,0.038713,202.159744,10.298508,0.387134,-1293.283691,0.037732,0.000000
94.710007,43.979797,-1293.283691,-0.001720,0.001511,0.038374,195.631912,9.965964,0.383743,-1293.283691,0.037283,0.000000
94.980003,42.510788,-1293.283691,-0.001733,0.001497,0.038028,189.097427,9.633082,0.380276,-1293.283691,0.036832,0.000000
95.250008,40.835106,-1293.328125,-0.001742,0.001477,0.037516,181.643616,9.253367,0.375159,-1293.328125,0.036389,0.000000
95.520004,38.264252,-1293.372559,-0.001755,0.001453,0.036909,170.207886,8.670803,0.369088,-1293.372559,0.035938,0.000000
95.790001,36.552826,-1293.372559,-0.001738,0.001435,0.036450,162.595093,8.282990,0.364501,-1293.372559,0.035487,0.000000
96.060005,34.941566,-1293.328125,-0.001746,0.001421,0.036094,155.427856,7.917872,0.360943,-1293.328125,0.035036,0.000000
96.330002,33.096466,-1293.328125,-0.001742,0.001403,0.035625,147.220428,7.499766,0.356249,-1293.328125,0.034585,0.000000
96.600006,31.189919,-1293.283691,-0.001759,0.001383,0.035122,138.739685,7.067737,0.351223,-1293.283691,0.034134,0.000000
96.870003,29.341461,-1293.328125,-0.001759,0.001366,0.034689,130.517334,6.648870,0.346893,-1293.328125,0.033683,0.000000
97.140007,27.660568,-1293.372559,-0.001772,0.001350,0.034290,123.040352,6.267974,0.342896,-1293.372559,0.033231,0.000000
97.410004,25.980423,-1293.372559,-0.001768,0.001332,0.033822,115.566696,5.887248,0.338218,-1293.372559,0.032782,0.000000
97.680008,23.826256,-1293.239136,-0.001776,0.001312,0.033327,105.984482,5.399107,0.333268,-1293.239136,0.032338,0.000000
97.950005,22.083923,-1293.328125,-0.001763,0.001296,0.032920,98.234200,5.004289,0.329195,-1293.328125,0.031888,0.000000
98.220001,20.516609,-1293.328125,-0.001785,0.001280,0.032521,91.262436,4.649130,0.325213,-1293.328125,0.031437,0.000000
98.490005,17.752853,-1293.372559,-0.001785,0.001252,0.031810,78.968636,4.022854,0.318098,-1293.372559,0.030986,0.000000
98.760002,16.294647,-1293.283691,-0.001807,0.001239,0.031480,72.482208,3.692420,0.314797,-1293.283691,0.030535,0.000000
99.030006,15.206573,-1293.328125,-0.001798,0.001228,0.031186,67.642220,3.445859,0.311860,-1293.328125,0.030084,0.000000
99.300003,13.568138,-1293.328125,-0.001807,0.001212,0.030795,60.354092,3.074584,0.307954,-1293.328125,0.029633,0.000000
99.570007,11.530884,-1293.372559,-0.001815,0.001191,0.030258,51.291931,2.612936,0.302580,-1293.372559,0.029182,0.000000
99.840004,10.127411,-1293.461548,-0.001802,0.001177,0.029902,45.048973,2.294904,0.299022,-1293.461548,0.028732,0.000000
100.110008,8.154587,-1293.372559,-0.001824,0.001155,0.029347,36.273415,1.847856,0.293466,-1293.372559,0.028281,0.000000
100.380005,5.764702,-1293.328125,-0.001811,0.001130,0.028697,25.642675,1.306300,0.286971,-1293.328125,0.027839,0.000000
100.650002,4.164986,-1293.372559,-0.001832,0.001113,0.028272,18.526781,0.943799,0.282717,-1293.372559,0.027387,0.000000
100.920006,3.056061,-1293.372559,-0.001837,0.001100,0.027951,13.594037,0.692513,0.279507,-1293.372559,0.026936,0.000000
101.190002,2.084541,-1293.417114,-0.001824,0.001088,0.027639,9.272503,0.472364,0.276388,-1293.417114,0.026485,0.000000
101.460007,0.184700,-1293.372559,-0.001837,0.001068,0.027136,0.821587,0.041854,0.271362,-1293.372559,0.026034,0.000000
101.730003,-0.439026,-1293.283691,-0.001850,0.001061,0.026962,-1.952885,-0.099485,0.269621,-1293.283691,0.025583,0.000000
102.000008,-2.504578,-1293.328125,-0.001867,0.001034,0.026260,-11.140918,-0.567545,0.262596,-1293.328125,0.025132,0.000000
102.270004,-0.141129,-1293.372559,-0.001927,0.001015,0.025783,-0.627771,-0.031980,0.257827,-1293.372559,0.024681,0.000000
102.540009,-0.150810,-1293.417114,-0.001940,0.000992,0.025201,-0.670837,-0.034174,0.252013,-1293.417114,0.024231,0.000000
102.810005,-0.167564,-1293.372559,-0.001962,0.000981,0.024915,-0.745364,-0.037971,0.249152,-1293.372559,0.023787,0.000000
103.080002,-0.137405,-1293.328125,-0.001979,0.000965,0.024508,-0.611210,-0.031137,0.245080,-1293.328125,0.023338,0.000000
103.350006,-0.123253,-1293.283691,-0.002009,0.000943,0.023961,-0.548256,-0.027929,0.239614,-1293.283691,0.022887,0.000000
103.620003,-0.093094,-1293.372559,-0.002048,0.000926,0.023510,-0.414102,-0.021095,0.235103,-1293.372559,0.022435,0.000000
103.890007,-0.113945,-1293.417114,-0.002082,0.000903,0.022938,-0.506853,-0.025820,0.229380,-1293.417114,0.021984,0.000000
104.160004,-0.104637,-1293.417114,-0.002104,0.000886,0.022513,-0.465449,-0.023711,0.225126,-1293.417114,0.021533,0.000000
104.430008,-0.093842,-1293.417114,-0.002113,0.000869,0.022080,-0.417428,-0.021265,0.220796,-1293.417114,0.021082,0.000000
104.700005,-0.086761,-1293.328125,-0.002160,0.000852,0.021647,-0.385934,-0.019660,0.216466,-1293.328125,0.020631,0.000000
104.970001,-0.070747,-1293.372559,-0.002182,0.000837,0.021256,-0.314700,-0.016032,0.212560,-1293.372559,0.020181,0.000000
105.240005,-0.050270,-1293.417114,-0.002229,0.000823,0.020909,-0.223612,-0.011391,0.209093,-1293.417114,0.019730,0.000000
105.510002,-0.074844,-1293.461548,-0.002251,0.000800,0.020328,-0.332924,-0.016960,0.203279,-1293.461548,0.019286,0.000000
105.780006,-0.081924,-1293.372559,-0.002259,0.000784,0.019921,-0.364418,-0.018564,0.199207,-1293.372559,0.018837,0.000000
106.050003,-0.094582,-1293.417114,-0.002307,0.000764,0.019400,-0.420720,-0.021432,0.193999,-1293.417114,0.018386,0.000000
106.300003,-0.010429,-1293.461548,-0.002324,0.000768,0.019495,-0.046392,-0.002363,0.194952,-1293.461548,0.019295,0.000000