File: Data/Sima compression/P1-21-2_10302024_174913.csv
Time (sec),S:Load (lbs),S:HL1 (DIM),S:LVDT (in),S:Position (in),Ch:Position (mm),Ch:Load (N),Ch:Stress (MPa),Ch:Strain (mm/mm),Ch:HL1 (DIM),Set Point (),Cycles ()
0.210000,-0.011917,-1293.417114,-0.008442,-0.004950,-0.125730,-0.053010,-0.002700,-1.257297,-1293.417114,-0.125531,0.000000
0.510000,0.001862,-1293.417114,-0.008438,-0.004883,-0.124039,0.008281,0.000422,-1.240386,-1293.417114,-0.123450,0.000000
0.810000,0.018616,-1293.461548,-0.008334,-0.004711,-0.119660,0.082807,0.004218,-1.196602,-1293.461548,-0.118455,0.000000
1.110000,-0.045799,-1293.417114,-0.008127,-0.004509,-0.114534,-0.203725,-0.010378,-1.145339,-1293.417114,-0.113442,0.000000
1.410000,-0.032394,-1293.461548,-0.007938,-0.004322,-0.109782,-0.144098,-0.007341,-1.097816,-1293.461548,-0.108446,0.000000
1.710000,-0.067772,-1293.372559,-0.007748,-0.004117,-0.104571,-0.301465,-0.015357,-1.045706,-1293.372559,-0.103452,0.000000
2.010000,-0.037613,-1293.417114,-0.007545,-0.003935,-0.099948,-0.167311,-0.008523,-0.999485,-1293.417114,-0.098456,0.000000
2.310000,-0.020111,-1293.417114,-0.007330,-0.003726,-0.094650,-0.089459,-0.004557,-0.946496,-1293.417114,-0.093461,0.000000
2.610000,0.018616,-1293.461548,-0.007123,-0.003525,-0.089532,0.082807,0.004218,-0.895324,-1293.461548,-0.088465,0.000000
2.910000,-0.004097,-1293.461548,-0.006924,-0.003330,-0.084589,-0.018224,-0.000928,-0.845894,-1293.461548,-0.083471,0.000000
3.210000,-0.012657,-1293.461548,-0.006717,-0.003133,-0.079586,-0.056302,-0.002868,-0.795857,-1293.461548,-0.078458,0.000000
3.510000,0.007820,-1293.461548,-0.006506,-0.002934,-0.074520,0.034786,0.001772,-0.745200,-1293.461548,-0.073463,0.000000
3.810000,-0.084900,-1293.461548,-0.006303,-0.002740,-0.069586,-0.377654,-0.019239,-0.695861,-1293.461548,-0.068467,0.000000
4.110000,-0.001862,-1293.461548,-0.006105,-0.002550,-0.064782,-0.008281,-0.000422,-0.647823,-1293.461548,-0.063473,0.000000
4.410000,-0.005211,-1293.506104,-0.005915,-0.002350,-0.059691,-0.023179,-0.001181,-0.596908,-1293.506104,-0.058477,0.000000
4.710000,0.031654,-1293.461548,-0.005730,-0.002160,-0.054852,0.140806,0.007173,-0.548522,-1293.461548,-0.053482,0.000000
5.010000,0.008194,-1293.506104,-0.005506,-0.001953,-0.049597,0.036449,0.001857,-0.495973,-1293.506104,-0.048469,0.000000
5.310000,0.007072,-1293.461548,-0.005325,-0.001763,-0.044792,0.031460,0.001603,-0.447920,-1293.461548,-0.043473,0.000000
5.610000,-0.002235,-1293.461548,-0.005101,-0.001562,-0.039676,-0.009944,-0.000507,-0.396763,-1293.461548,-0.038479,0.000000
5.910000,-0.029793,-1293.506104,-0.004885,-0.001358,-0.034499,-0.132525,-0.006751,-0.344986,-1293.506104,-0.033484,0.000000
6.210001,-0.033516,-1293.417114,-0.004700,-0.001167,-0.029651,-0.149086,-0.007595,-0.296509,-1293.417114,-0.028488,0.000000
6.510000,-0.001488,-1293.506104,-0.004501,-0.000968,-0.024594,-0.006618,-0.000337,-0.245942,-1293.506104,-0.023494,0.000000
6.810000,0.039474,-1293.461548,-0.004294,-0.000777,-0.019737,0.175591,0.008945,-0.197375,-1293.461548,-0.018481,0.000000
7.110000,-0.011917,-1293.417114,-0.004105,-0.000575,-0.014596,-0.053010,-0.002700,-0.145961,-1293.417114,-0.013485,0.000000
7.410000,0.016754,-1293.550537,-0.003885,-0.000386,-0.009817,0.074526,0.003797,-0.098165,-1293.550537,-0.008490,0.000000
7.710001,-0.014893,-1293.506104,-0.003686,-0.000180,-0.004580,-0.066245,-0.003375,-0.045797,-1293.506104,-0.003494,0.000000
8.010000,0.146713,-1293.461548,-0.003492,-0.000002,-0.000061,0.652613,0.033246,-0.000606,-1293.461548,0.001310,0.000000
8.310000,0.085274,-1293.417114,-0.003497,-0.000003,-0.000088,0.379317,0.019323,-0.000878,-1293.417114,0.000138,0.000000
8.610001,0.115067,-1293.506104,-0.003497,-0.000003,-0.000088,0.511841,0.026074,-0.000878,-1293.506104,0.000286,0.000000
8.910001,0.087883,-1293.461548,-0.003505,-0.000003,-0.000088,0.390923,0.019915,-0.000878,-1293.461548,0.000789,0.000000
9.210000,0.115067,-1293.506104,-0.003514,0.000006,0.000165,0.511841,0.026074,0.001650,-1293.506104,0.001291,0.000000
9.510000,0.425621,-1293.461548,-0.003479,0.000039,0.000989,1.893257,0.096447,0.009886,-1293.461548,0.001786,0.000000
9.810000,0.646439,-1293.461548,-0.003462,0.000055,0.001396,2.875503,0.146485,0.013959,-1293.461548,0.002289,0.000000
10.110001,1.140953,-1293.461548,-0.003449,0.000076,0.001942,5.075212,0.258544,0.019424,-1293.461548,0.002792,0.000000
10.410001,1.772491,-1293.417114,-0.003428,0.000094,0.002384,7.884436,0.401652,0.023845,-1293.417114,0.003287,0.000000
10.710000,2.387283,-1293.506104,-0.003419,0.000111,0.002827,10.619166,0.540966,0.028266,-1293.506104,0.003789,0.000000
11.010000,3.041542,-1293.461548,-0.003397,0.000128,0.003252,13.529455,0.689223,0.032520,-1293.461548,0.004292,0.000000
11.310000,4.072639,-1293.417114,-0.003397,0.000154,0.003901,18.116005,0.922873,0.039015,-1293.417114,0.004787,0.000000
11.610001,4.945854,-1293.506104,-0.003372,0.000173,0.004387,22.000257,1.120746,0.043875,-1293.506104,0.005290,0.000000
11.910001,5.791138,-1293.550537,-0.003363,0.000193,0.004908,25.760267,1.312291,0.049083,-1293.550537,0.005792,0.000000
12.210001,6.537369,-1293.506104,-0.003333,0.000207,0.005264,29.079668,1.481389,0.052640,-1293.506104,0.006287,0.000000
12.510000,7.615761,-1293.506104,-0.003333,0.000231,0.005862,33.876595,1.725756,0.058620,-1293.506104,0.006790,0.000000
12.810000,8.273003,-1293.506104,-0.003316,0.000242,0.006148,36.800152,1.874689,0.061482,-1293.506104,0.007293,0.000000
13.110001,9.048653,-1293.506104,-0.003324,0.000257,0.006539,40.250416,2.050454,0.065388,-1293.506104,0.007788,0.000000
13.410001,11.256073,-1293.506104,-0.003298,0.000295,0.007502,50.069515,2.550663,0.075017,-1293.506104,0.008290,0.000000
13.710001,11.821709,-1293.506104,-0.003285,0.000310,0.007883,52.585587,2.678838,0.078832,-1293.506104,0.008793,0.000000
14.010000,12.751892,-1293.506104,-0.003281,0.000330,0.008377,56.723248,2.889620,0.083767,-1293.506104,0.009288,0.000000
14.310000,14.085732,-1293.506104,-0.003260,0.000351,0.008907,62.656464,3.191873,0.089066,-1293.506104,0.009791,0.000000
14.610001,14.969742,-1293.461548,-0.003255,0.000366,0.009296,66.588737,3.392192,0.092957,-1293.461548,0.010293,0.000000
14.910001,15.817635,-1293.506104,-0.003238,0.000381,0.009670,70.360352,3.584327,0.096696,-1293.506104,0.010788,0.000000
15.210001,16.291298,-1293.506104,-0.003229,0.000400,0.010172,72.467316,3.691661,0.101723,-1293.506104,0.011291,0.000000
15.510001,18.362061,-1293.550537,-0.003221,0.000424,0.010779,81.678528,4.160903,0.107794,-1293.550537,0.011794,0.000000
15.810000,19.279587,-1293.506104,-0.003216,0.000443,0.011247,85.759888,4.368817,0.112472,-1293.506104,0.012289,0.000000
16.110001,20.471176,-1293.461548,-0.003186,0.000463,0.011759,91.060341,4.638835,0.117589,-1293.461548,0.012791,0.000000
16.410000,21.996414,-1293.550537,-0.003199,0.000488,0.012401,97.844940,4.984459,0.124008,-1293.550537,0.013285,0.000000
16.710001,22.629448,-1293.506104,-0.003182,0.000504,0.012801,100.660812,5.127906,0.128005,-1293.506104,0.013789,0.000000
17.010000,23.181305,-1293.506104,-0.003165,0.000514,0.013052,103.115593,5.252959,0.130518,-1293.506104,0.014292,0.000000
17.310001,25.141098,-1293.461548,-0.003147,0.000544,0.013824,111.833191,5.697054,0.138240,-1293.461548,0.014785,0.000000
17.610001,26.327103,-1293.461548,-0.003139,0.000566,0.014387,117.108803,5.965806,0.143871,-1293.461548,0.015289,0.000000
17.910002,26.940033,-1293.506104,-0.003117,0.000580,0.014725,119.835251,6.104699,0.147248,-1293.506104,0.015792,0.000000
18.210001,28.554634,-1293.506104,-0.003113,0.000605,0.015367,127.017357,6.470573,0.153667,-1293.506104,0.016286,0.000000
18.510000,29.271454,-1293.506104,-0.003104,0.000621,0.015766,130.205933,6.633007,0.157664,-1293.506104,0.016790,0.000000
18.810001,30.004654,-1293.506104,-0.003091,0.000636,0.016148,133.467361,6.799152,0.161479,-1293.506104,0.017292,0.000000
19.110001,31.740654,-1293.417114,-0.003070,0.000665,0.016893,141.189484,7.192535,0.168927,-1293.417114,0.017786,0.000000
19.410002,32.797073,-1293.506104,-0.003078,0.000683,0.017344,145.888672,7.431923,0.173439,-1293.506104,0.018290,0.000000
19.710001,33.389153,-1293.461548,-0.003057,0.000699,0.017760,148.522369,7.566090,0.177602,-1293.461548,0.018793,0.000000
20.010000,34.437752,-1293.461548,-0.003040,0.000719,0.018272,153.186768,7.803706,0.182720,-1293.461548,0.019286,0.000000
20.310001,35.583168,-1293.417114,-0.003040,0.000743,0.018862,158.281830,8.063261,0.188624,-1293.417114,0.019790,0.000000
20.610001,36.301849,-1293.550537,-0.003022,0.000761,0.019321,161.478683,8.226116,0.193211,-1293.550537,0.020293,0.000000
20.910002,36.917381,-1293.506104,-0.003001,0.000778,0.019772,164.216721,8.365598,0.197723,-1293.506104,0.020787,0.000000
21.210001,38.194618,-1293.417114,-0.002984,0.000797,0.020249,169.898148,8.655025,0.202492,-1293.417114,0.021289,0.000000
21.510000,39.233910,-1293.550537,-0.002966,0.000821,0.020847,174.521149,8.890532,0.208472,-1293.550537,0.021793,0.000000
21.810001,39.945885,-1293.461548,-0.002958,0.000838,0.021273,177.688171,9.051867,0.212726,-1293.461548,0.022287,0.000000
22.110001,40.932297,-1293.506104,-0.002949,0.000862,0.021889,182.075943,9.275392,0.218888,-1293.506104,0.022790,0.000000
22.410002,41.504631,-1293.506104,-0.002923,0.000876,0.022252,184.621826,9.405084,0.222522,-1293.506104,0.023294,0.000000
22.710001,42.019997,-1293.506104,-0.002910,0.000889,0.022591,186.914276,9.521868,0.225913,-1293.506104,0.023787,0.000000
23.010000,44.009583,-1293.417114,-0.002910,0.000923,0.023432,195.764404,9.972714,0.234315,-1293.417114,0.024290,0.000000
23.310001,44.423660,-1293.461548,-0.002893,0.000939,0.023848,197.606308,10.066545,0.238479,-1293.461548,0.024794,0.000000
23.610001,45.471519,-1293.461548,-0.002884,0.000958,0.024325,202.267426,10.303993,0.243248,-1293.461548,0.025288,0.000000
23.910002,45.961563,-1293.506104,-0.002859,0.000973,0.024724,204.447250,10.415039,0.247244,-1293.506104,0.025790,0.000000
24.210001,47.104370,-1293.506104,-0.002850,0.000998,0.025348,209.530701,10.674003,0.253482,-1293.506104,0.026294,0.000000
24.510000,47.294655,-1293.506104,-0.002833,0.001013,0.025739,210.377136,10.717122,0.257388,-1293.506104,0.026788,0.000000
24.810001,47.636116,-1293.461548,-0.002833,0.001024,0.026016,211.896027,10.794498,0.260159,-1293.461548,0.027291,0.000000
25.110001,49.624214,-1293.417114,-0.002802,0.001055,0.026806,220.739532,11.245008,0.268061,-1293.417114,0.027795,0.000000
25.410002,50.534668,-1293.461548,-0.002794,0.001077,0.027344,224.789429,11.451320,0.273436,-1293.461548,0.028288,0.000000
25.710001,51.044441,-1293.417114,-0.002772,0.001093,0.027760,227.057022,11.566835,0.277599,-1293.417114,0.028791,0.000000
26.010002,51.703171,-1293.417114,-0.002781,0.001108,0.028151,229.987183,11.716106,0.281505,-1293.417114,0.029295,0.000000
26.310001,52.744698,-1293.372559,-0.002746,0.001130,0.028714,234.620132,11.952120,0.287137,-1293.372559,0.029789,0.000000
26.610001,53.174042,-1293.461548,-0.002742,0.001145,0.029086,236.529953,12.049410,0.290862,-1293.461548,0.030291,0.000000
26.910002,54.425217,-1293.506104,-0.002734,0.001170,0.029719,242.095459,12.332931,0.297190,-1293.506104,0.030795,0.000000
27.210001,55.417961,-1293.417114,-0.002703,0.001190,0.030231,246.511398,12.557889,0.302307,-1293.417114,0.031289,0.000000
27.510002,56.397301,-1293.417114,-0.002682,0.001213,0.030812,250.867722,12.779811,0.308121,-1293.417114,0.031792,0.000000
27.810001,56.878403,-1293.417114,-0.002682,0.001230,0.031245,253.007767,12.888830,0.312451,-1293.417114,0.032296,0.000000
28.110001,58.004829,-1293.417114,-0.002669,0.001252,0.031810,258.018372,13.144082,0.318098,-1293.417114,0.032789,0.000000
28.410002,58.860542,-1293.372559,-0.002643,0.001271,0.032278,261.824768,13.337989,0.322776,-1293.372559,0.033292,0.000000
28.710001,59.282440,-1293.417114,-0.002634,0.001293,0.032841,263.701477,13.433593,0.328408,-1293.417114,0.033796,0.000000
29.010002,61.003922,-1293.372559,-0.002608,0.001316,0.033422,271.359009,13.823686,0.334221,-1293.372559,0.034290,0.000000
29.310001,61.242607,-1293.417114,-0.002604,0.001332,0.033829,272.420715,13.877773,0.338294,-1293.417114,0.034792,0.000000
29.610001,62.008949,-1293.372559,-0.002591,0.001350,0.034299,275.829590,14.051429,0.342987,-1293.372559,0.035287,0.000000
29.910002,62.571236,-1293.372559,-0.002574,0.001367,0.034715,278.330750,14.178844,0.347151,-1293.372559,0.035790,0.000000
30.210001,63.402367,-1293.461548,-0.002565,0.001383,0.035122,282.027802,14.367182,0.351223,-1293.461548,0.036293,0.000000
30.510002,64.081200,-1293.417114,-0.002544,0.001402,0.035599,285.047424,14.521008,0.355992,-1293.417114,0.036788,0.000000
30.810001,65.756142,-1293.372559,-0.002535,0.001430,0.036311,292.497925,14.900555,0.363108,-1293.372559,0.037290,0.000000
31.110001,65.254173,-1293.461548,-0.002509,0.001426,0.036223,290.265045,14.786807,0.362230,-1293.461548,0.006379,0.000000
31.410002,66.329216,-1293.461548,-0.002492,0.001394,0.035418,295.047089,15.030415,0.354175,-1293.461548,294.500488,0.000000
31.710001,65.304070,-1293.461548,-0.002496,0.001444,0.036667,290.487000,14.798114,0.366665,-1293.461548,294.500488,0.000000
32.010002,65.318230,-1293.417114,-0.002488,0.001459,0.037056,290.549988,14.801322,0.370556,-1293.417114,294.500488,0.000000
32.310001,65.417274,-1293.461548,-0.002475,0.001473,0.037421,290.990570,14.823767,0.374205,-1293.461548,294.500488,0.000000
32.610001,65.271675,-1293.372559,-0.002466,0.001477,0.037525,290.342926,14.790773,0.375250,-1293.372559,294.500488,0.000000
32.910000,65.260506,-1293.417114,-0.002466,0.001486,0.037741,290.293213,14.788242,0.377415,-1293.417114,294.500488,0.000000
33.210003,65.415794,-1293.372559,-0.002453,0.001494,0.037958,290.983978,14.823431,0.379580,-1293.372559,294.500488,0.000000
33.510002,65.354347,-1293.461548,-0.002445,0.001501,0.038132,290.710663,14.809507,0.381321,-1293.461548,294.500488,0.000000
33.810001,65.531975,-1293.417114,-0.002436,0.001509,0.038330,291.500793,14.849758,0.383304,-1293.417114,294.500488,0.000000
34.110001,64.847176,-1293.506104,-0.002432,0.001509,0.038339,288.454651,14.694580,0.383395,-1293.506104,294.500488,0.000000
34.410000,66.404060,-1293.461548,-0.002410,0.001488,0.037802,295.380005,15.047376,0.378020,-1293.461548,294.500488,0.000000
34.710003,65.568840,-1293.506104,-0.002402,0.001490,0.037837,291.664764,14.858112,0.378368,-1293.506104,294.500488,0.000000
35.010002,65.151024,-1293.417114,-0.002397,0.001528,0.038800,289.806213,14.763433,0.387997,-1293.417114,294.500488,0.000000
35.310001,65.306313,-1293.461548,-0.002402,0.001538,0.039060,290.496979,14.798622,0.390601,-1293.461548,294.500488,0.000000
35.610001,65.353981,-1293.461548,-0.002397,0.001545,0.039233,290.709015,14.809423,0.392327,-1293.461548,294.500488,0.000000
35.910000,65.283226,-1293.417114,-0.002384,0.001550,0.039372,290.394287,14.793390,0.393720,-1293.417114,294.500488,0.000000
36.210003,65.304070,-1293.461548,-0.002380,0.001556,0.039528,290.487000,14.798114,0.395279,-1293.461548,294.500488,0.000000
36.510002,65.340935,-1293.417114,-0.002389,0.001562,0.039684,290.651001,14.806468,0.396839,-1293.417114,294.500488,0.000000
36.810001,65.322701,-1293.417114,-0.002367,0.001567,0.039814,290.569885,14.802335,0.398141,-1293.417114,294.500488,0.000000
37.110001,65.183800,-1293.506104,-0.002363,0.001571,0.039900,289.952026,14.770861,0.399004,-1293.506104,294.500488,0.000000
37.410004,65.225136,-1293.417114,-0.002350,0.001576,0.040031,290.135895,14.780228,0.400306,-1293.417114,294.500488,0.000000
37.710003,65.240028,-1293.461548,-0.002345,0.001581,0.040152,290.202148,14.783602,0.401517,-1293.461548,294.500488,0.000000
38.010002,65.229973,-1293.550537,-0.002354,0.001586,0.040274,290.157410,14.781323,0.402743,-1293.550537,294.500488,0.000000
38.310001,65.298119,-1293.461548,-0.002345,0.001591,0.040403,290.460541,14.796765,0.404030,-1293.461548,294.500488,0.000000
38.610001,65.220665,-1293.461548,-0.002337,0.001595,0.040526,290.115997,14.779214,0.405256,-1293.461548,294.500488,0.000000
38.910004,65.232948,-1293.506104,-0.002345,0.001599,0.040612,290.170654,14.781998,0.406119,-1293.506104,294.500488,0.000000
39.210003,65.179329,-1293.506104,-0.002333,0.001603,0.040707,289.932129,14.769847,0.407073,-1293.506104,294.500488,0.000000
39.510002,65.066124,-1293.417114,-0.002333,0.001606,0.040785,289.428589,14.744194,0.407845,-1293.417114,294.500488,0.000000
39.810001,65.349510,-1293.461548,-0.002337,0.001612,0.040950,290.689148,14.808411,0.409495,-1293.461548,294.500488,0.000000
40.110001,65.017342,-1293.372559,-0.002315,0.001612,0.040950,289.211578,14.733141,0.409495,-1293.372559,294.500488,0.000000
40.410004,65.566963,-1293.461548,-0.002315,0.001621,0.041175,291.656433,14.857686,0.411751,-1293.461548,294.500488,0.000000
40.710003,65.228477,-1293.417114,-0.002311,0.001621,0.041184,290.150757,14.780985,0.411842,-1293.417114,294.500488,0.000000
41.010002,65.021080,-1293.417114,-0.002315,0.001623,0.041236,289.228210,14.733988,0.412357,-1293.417114,294.500488,0.000000
41.310001,65.590065,-1293.506104,-0.002302,0.001633,0.041470,291.759186,14.862921,0.414703,-1293.506104,294.500488,0.000000
41.610001,65.305199,-1293.506104,-0.002294,0.001633,0.041479,290.492035,14.798369,0.414794,-1293.506104,294.500488,0.000000
41.910004,65.196083,-1293.417114,-0.002289,0.001636,0.041557,290.006653,14.773643,0.415566,-1293.417114,294.500488,0.000000
42.210003,65.150658,-1293.417114,-0.002289,0.001640,0.041644,289.804596,14.763350,0.416444,-1293.417114,294.500488,0.000000
42.510002,64.967827,-1293.417114,-0.002285,0.001640,0.041661,288.991333,14.721920,0.416611,-1293.417114,294.500488,0.000000
42.810001,64.716850,-1293.461548,-0.002289,0.001641,0.041670,287.874939,14.665048,0.416702,-1293.461548,294.500488,0.000000
43.110001,65.731560,-1293.417114,-0.002289,0.001653,0.041982,292.388580,14.894984,0.419821,-1293.417114,294.500488,0.000000
43.410004,65.448189,-1293.417114,-0.002281,0.001653,0.041982,291.128082,14.830771,0.419821,-1293.417114,294.500488,0.000000
43.710003,65.105598,-1293.417114,-0.002281,0.001653,0.041991,289.604156,14.753139,0.419911,-1293.417114,294.500488,0.000000
44.010002,64.871758,-1293.506104,-0.002268,0.001653,0.041999,288.563995,14.700150,0.419987,-1293.506104,294.500488,0.000000
44.310001,64.872124,-1293.506104,-0.002272,0.001658,0.042112,288.565613,14.700233,0.421123,-1293.506104,294.500488,0.000000
44.610001,64.896324,-1293.461548,-0.002264,0.001661,0.042189,288.673279,14.705717,0.421895,-1293.461548,294.500488,0.000000
44.910004,65.714424,-1293.461548,-0.002268,0.001684,0.042771,292.312347,14.891101,0.427708,-1293.461548,294.500488,0.000000
45.210003,66.154945,-1293.417114,-0.002246,0.001657,0.042094,294.271881,14.990925,0.420941,-1293.417114,294.500488,0.000000
45.510002,65.825401,-1293.417114,-0.002251,0.001657,0.042094,292.806000,14.916249,0.420941,-1293.417114,294.500488,0.000000
45.810001,65.480583,-1293.372559,-0.002259,0.001658,0.042103,291.272186,14.838112,0.421032,-1293.372559,294.500488,0.000000
46.110001,65.165184,-1293.417114,-0.002259,0.001659,0.042138,289.869202,14.766642,0.421380,-1293.417114,294.500488,0.000000
46.410004,65.934135,-1293.461548,-0.002264,0.001681,0.042701,293.289673,14.940889,0.427012,-1293.461548,294.500488,0.000000
46.710003,65.649269,-1293.417114,-0.002255,0.001681,0.042701,292.022522,14.876337,0.427012,-1293.417114,294.500488,0.000000
47.010002,65.335350,-1293.417114,-0.002251,0.001682,0.042719,290.626160,14.805202,0.427194,-1293.417114,294.500488,0.000000
47.310001,65.968391,-1293.417114,-0.002242,0.001695,0.043057,293.442047,14.948651,0.430570,-1293.417114,294.500488,0.000000
47.610001,65.761726,-1293.417114,-0.002251,0.001693,0.043015,292.522766,14.901820,0.430146,-1293.417114,294.500488,0.000000
47.910004,65.493248,-1293.461548,-0.002251,0.001694,0.043022,291.328522,14.840981,0.430221,-1293.461548,294.500488,0.000000
48.210003,65.270561,-1293.417114,-0.002229,0.001695,0.043057,290.337952,14.790521,0.430570,-1293.417114,294.500488,0.000000
48.510002,65.392326,-1293.417114,-0.002229,0.001700,0.043178,290.879608,14.818112,0.431781,-1293.417114,294.500488,0.000000
48.810001,65.285454,-1293.461548,-0.002233,0.001702,0.043231,290.404205,14.793895,0.432311,-1293.461548,294.500488,0.000000
49.110001,65.304817,-1293.417114,-0.002220,0.001705,0.043301,290.490326,14.798283,0.433007,-1293.417114,294.500488,0.000000
49.410004,65.227364,-1293.328125,-0.002233,0.001706,0.043326,290.145813,14.780732,0.433264,-1293.328125,294.500488,0.000000
49.710003,65.218803,-1293.372559,-0.002229,0.001708,0.043378,290.107727,14.778792,0.433779,-1293.372559,294.500488,0.000000
50.010002,65.226250,-1293.417114,-0.002216,0.001710,0.043438,290.140839,14.780479,0.434385,-1293.417114,294.500488,0.000000
50.310001,65.163322,-1293.372559,-0.002212,0.001713,0.043499,289.860931,14.766220,0.434990,-1293.372559,294.500488,0.000000
50.610001,65.087349,-1293.461548,-0.002229,0.001714,0.043543,289.522980,14.749004,0.435429,-1293.461548,294.500488,0.000000
50.910004,65.111183,-1293.372559,-0.002238,0.001716,0.043594,289.628998,14.754405,0.435944,-1293.372559,294.500488,0.000000
51.210003,65.056068,-1293.417114,-0.002225,0.001718,0.043629,289.383850,14.741916,0.436292,-1293.417114,294.500488,0.000000
51.510002,65.689110,-1293.372559,-0.002225,0.001725,0.043803,292.199768,14.885365,0.438033,-1293.372559,294.500488,0.000000
51.810001,65.476479,-1293.372559,-0.002199,0.001725,0.043803,291.253937,14.837182,0.438033,-1293.372559,294.500488,0.000000
52.110001,65.246727,-1293.417114,-0.002212,0.001725,0.043803,290.231934,14.785120,0.438033,-1293.417114,294.500488,0.000000
52.410004,65.315254,-1293.417114,-0.002203,0.001729,0.043924,290.536774,14.800649,0.439245,-1293.417114,294.500488,0.000000
52.710003,65.177101,-1293.417114,-0.002186,0.001729,0.043924,289.922211,14.769342,0.439245,-1293.417114,294.500488,0.000000
53.010002,65.116768,-1293.372559,-0.002212,0.001732,0.043985,289.653839,14.755671,0.439850,-1293.372559,294.500488,0.000000
53.310001,65.187157,-1293.328125,-0.002186,0.001735,0.044071,289.966949,14.771621,0.440713,-1293.328125,294.500488,0.000000
53.610004,65.116020,-1293.461548,-0.002186,0.001735,0.044071,289.650513,14.755501,0.440713,-1293.461548,294.500488,0.000000
53.910004,65.304070,-1293.372559,-0.002203,0.001739,0.044176,290.487000,14.798114,0.441758,-1293.372559,294.500488,0.000000
54.210003,65.187157,-1293.417114,-0.002190,0.001740,0.044185,289.966949,14.771621,0.441849,-1293.417114,294.500488,0.000000
54.510002,65.340935,-1293.417114,-0.002190,0.001744,0.044297,290.651001,14.806468,0.442969,-1293.417114,294.500488,0.000000
54.810001,65.271675,-1293.372559,-0.002195,0.001745,0.044315,290.342926,14.790773,0.443151,-1293.372559,294.500488,0.000000
55.110004,65.280617,-1293.372559,-0.002177,0.001747,0.044376,290.382690,14.792799,0.443756,-1293.372559,294.500488,0.000000
55.410004,65.229607,-1293.372559,-0.002182,0.001749,0.044427,290.155792,14.781240,0.444271,-1293.372559,294.500488,0.000000
55.710003,65.257530,-1293.417114,-0.002186,0.001751,0.044488,290.279999,14.787567,0.444877,-1293.417114,294.500488,0.000000
56.010002,65.265724,-1293.372559,-0.002177,0.001752,0.044497,290.316437,14.789425,0.444967,-1293.372559,294.500488,0.000000
56.310001,65.508507,-1293.417114,-0.002182,0.001756,0.044601,291.396393,14.844440,0.446012,-1293.417114,294.500488,0.000000
56.610004,65.385994,-1293.372559,-0.002173,0.001756,0.044601,290.851440,14.816678,0.446012,-1293.372559,294.500488,0.000000
56.910004,65.252693,-1293.372559,-0.002177,0.001756,0.044610,290.258484,14.786471,0.446103,-1293.372559,294.500488,0.000000
57.210003,65.159599,-1293.417114,-0.002169,0.001758,0.044653,289.844360,14.765376,0.446527,-1293.417114,294.500488,0.000000
57.510002,65.164803,-1293.417114,-0.002182,0.001760,0.044706,289.867523,14.766556,0.447057,-1293.417114,294.500488,0.000000
57.810001,65.310783,-1293.372559,-0.002160,0.001765,0.044827,290.516876,14.799635,0.448268,-1293.372559,294.500488,0.000000
58.110004,65.309654,-1293.417114,-0.002164,0.001765,0.044827,290.511841,14.799379,0.448268,-1293.417114,294.500488,0.000000
58.410004,65.214714,-1293.417114,-0.002151,0.001765,0.044827,290.089539,14.777865,0.448268,-1293.417114,294.500488,0.000000
58.710003,65.112297,-1293.417114,-0.002151,0.001767,0.044878,289.633972,14.754658,0.448783,-1293.417114,294.500488,0.000000
59.010002,65.028893,-1293.417114,-0.002151,0.001767,0.044887,289.262970,14.735758,0.448873,-1293.417114,294.500488,0.000000
59.310001,64.898186,-1293.417114,-0.002156,0.001767,0.044887,288.681549,14.706140,0.448873,-1293.417114,294.500488,0.000000
59.610004,65.616127,-1293.372559,-0.002147,0.001777,0.045148,291.875122,14.868827,0.451477,-1293.372559,294.500488,0.000000
59.910004,65.560646,-1293.417114,-0.002143,0.001777,0.045148,291.628326,14.856255,0.451477,-1293.417114,294.500488,0.000000
60.210003,65.429939,-1293.372559,-0.002156,0.001777,0.045148,291.046906,14.826636,0.451477,-1293.372559,294.500488,0.000000
60.510002,65.304817,-1293.372559,-0.002143,0.001778,0.045157,290.490326,14.798283,0.451568,-1293.372559,294.500488,0.000000
60.810001,65.184166,-1293.372559,-0.002147,0.001778,0.045157,289.953644,14.770943,0.451568,-1293.372559,294.500488,0.000000
61.110004,65.042671,-1293.417114,-0.002143,0.001778,0.045164,289.324249,14.738880,0.451644,-1293.417114,294.500488,0.000000
61.410004,64.905632,-1293.461548,-0.002134,0.001778,0.045173,288.714661,14.707827,0.451735,-1293.461548,294.500488,0.000000
61.710003,64.871376,-1293.372559,-0.002121,0.001782,0.045260,288.562286,14.700065,0.452598,-1293.372559,294.500488,0.000000
62.010002,65.029259,-1293.417114,-0.002143,0.001784,0.045313,289.264587,14.735841,0.453128,-1293.417114,294.500488,0.000000
62.310001,64.942131,-1293.417114,-0.002139,0.001784,0.045313,288.877014,14.716098,0.453128,-1293.417114,294.500488,0.000000
62.610004,64.811424,-1293.417114,-0.002134,0.001784,0.045320,288.295624,14.686479,0.453203,-1293.417114,294.500488,0.000000
62.910004,64.882927,-1293.417114,-0.002126,0.001787,0.045399,288.613678,14.702682,0.453991,-1293.417114,294.500488,0.000000
63.210003,64.798393,-1293.417114,-0.002130,0.001788,0.045408,288.237640,14.683526,0.454081,-1293.417114,294.500488,0.000000
63.510002,66.203728,-1293.506104,-0.002139,0.001801,0.045737,294.488892,15.001980,0.457367,-1293.506104,294.500488,0.000000
63.810001,65.992958,-1293.417114,-0.002130,0.001796,0.045616,293.551331,14.954218,0.456156,-1293.417114,294.500488,0.000000
64.110001,65.830605,-1293.417114,-0.002121,0.001796,0.045616,292.829163,14.917428,0.456156,-1293.417114,294.500488,0.000000
64.410004,65.633629,-1293.506104,-0.002121,0.001796,0.045625,291.952972,14.872792,0.456246,-1293.506104,294.500488,0.000000
64.710007,65.468666,-1293.550537,-0.002121,0.001796,0.045625,291.219177,14.835411,0.456246,-1293.550537,294.500488,0.000000
65.010002,65.296257,-1293.417114,-0.002126,0.001797,0.045634,290.452271,14.796344,0.456337,-1293.417114,294.500488,0.000000
65.310005,65.131660,-1293.417114,-0.002121,0.001798,0.045659,289.720093,14.759045,0.456595,-1293.417114,294.500488,0.000000
65.610001,65.626549,-1293.550537,-0.002104,0.001807,0.045902,291.921478,14.871188,0.459017,-1293.550537,294.500488,0.000000
65.910004,65.559517,-1293.506104,-0.002130,0.001807,0.045902,291.623291,14.855999,0.459017,-1293.506104,294.500488,0.000000
66.210007,65.445946,-1293.506104,-0.002130,0.001807,0.045902,291.118103,14.830263,0.459017,-1293.506104,294.500488,0.000000
66.510002,65.301476,-1293.506104,-0.002117,0.001808,0.045911,290.475464,14.797526,0.459108,-1293.506104,294.500488,0.000000
66.810005,65.246361,-1293.461548,-0.002113,0.001809,0.045955,290.230316,14.785036,0.459547,-1293.461548,294.500488,0.000000
67.110001,65.275780,-1293.417114,-0.002104,0.001812,0.046023,290.361176,14.791703,0.460228,-1293.417114,294.500488,0.000000
67.410004,65.272789,-1293.461548,-0.002121,0.001812,0.046032,290.347870,14.791025,0.460319,-1293.461548,294.500488,0.000000
67.710007,65.237053,-1293.506104,-0.002113,0.001814,0.046067,290.188904,14.782928,0.460667,-1293.506104,294.500488,0.000000
68.010002,65.286568,-1293.461548,-0.002100,0.001816,0.046118,290.409149,14.794147,0.461182,-1293.461548,294.500488,0.000000
68.310005,65.252312,-1293.461548,-0.002117,0.001816,0.046136,290.256775,14.786386,0.461364,-1293.461548,294.500488,0.000000
68.610001,65.340935,-1293.506104,-0.002104,0.001819,0.046214,290.651001,14.806468,0.462136,-1293.506104,294.500488,0.000000
68.910004,65.310036,-1293.461548,-0.002121,0.001819,0.046214,290.513550,14.799465,0.462136,-1293.461548,294.500488,0.000000
69.210007,65.247475,-1293.417114,-0.002100,0.001820,0.046232,290.235260,14.785289,0.462317,-1293.417114,294.500488,0.000000
69.510002,65.222893,-1293.372559,-0.002104,0.001822,0.046274,290.125916,14.779719,0.462741,-1293.372559,294.500488,0.000000
69.810005,65.173378,-1293.417114,-0.002100,0.001822,0.046283,289.905670,14.768499,0.462832,-1293.417114,294.500488,0.000000
70.110001,65.229973,-1293.506104,-0.002095,0.001824,0.046336,290.157410,14.781323,0.463362,-1293.506104,294.500488,0.000000
70.410004,65.165184,-1293.461548,-0.002095,0.001825,0.046344,289.869202,14.766642,0.463438,-1293.461548,294.500488,0.000000
70.710007,65.454887,-1293.417114,-0.002104,0.001829,0.046465,291.157867,14.832290,0.464649,-1293.417114,294.500488,0.000000
71.010002,65.386375,-1293.417114,-0.002100,0.001829,0.046465,290.853119,14.816764,0.464649,-1293.417114,294.500488,0.000000
71.310005,65.306679,-1293.506104,-0.002095,0.001830,0.046474,290.498627,14.798705,0.464740,-1293.506104,294.500488,0.000000
71.610001,65.207253,-1293.461548,-0.002095,0.001830,0.046474,290.056335,14.776175,0.464740,-1293.461548,294.500488,0.000000
71.910004,65.177849,-1293.461548,-0.002087,0.001831,0.046518,289.925537,14.769512,0.465179,-1293.461548,294.500488,0.000000
72.210007,65.118629,-1293.417114,-0.002095,0.001832,0.046535,289.662140,14.756093,0.465345,-1293.417114,294.500488,0.000000
72.510002,65.248970,-1293.417114,-0.002095,0.001834,0.046595,290.241913,14.785628,0.465951,-1293.417114,294.500488,0.000000
72.810005,65.167793,-1293.461548,-0.002091,0.001834,0.046595,289.880829,14.767234,0.465951,-1293.461548,294.500488,0.000000
73.110001,65.119377,-1293.461548,-0.002082,0.001836,0.046630,289.665466,14.756262,0.466299,-1293.461548,294.500488,0.000000
73.410004,65.072090,-1293.417114,-0.002104,0.001836,0.046639,289.455109,14.745546,0.466390,-1293.417114,294.500488,0.000000
73.710007,65.161461,-1293.461548,-0.002095,0.001839,0.046700,289.852661,14.765799,0.466995,-1293.461548,294.500488,0.000000
74.010002,65.086983,-1293.461548,-0.002078,0.001839,0.046700,289.521362,14.748921,0.466995,-1293.461548,294.500488,0.000000
74.310005,65.056450,-1293.461548,-0.002091,0.001840,0.046734,289.385529,14.742002,0.467344,-1293.461548,294.500488,0.000000
74.610001,65.121620,-1293.461548,-0.002087,0.001842,0.046795,289.675446,14.756769,0.467949,-1293.461548,294.500488,0.000000
74.910004,65.102623,-1293.417114,-0.002078,0.001842,0.046795,289.590942,14.752465,0.467949,-1293.417114,294.500488,0.000000
75.210007,65.075432,-1293.417114,-0.002078,0.001843,0.046821,289.469971,14.746304,0.468207,-1293.417114,294.500488,0.000000
75.510002,65.072838,-1293.506104,-0.002082,0.001845,0.046865,289.458435,14.745716,0.468646,-1293.506104,294.500488,0.000000
75.810005,65.228477,-1293.506104,-0.002074,0.001847,0.046908,290.150757,14.780985,0.469085,-1293.506104,294.500488,0.000000
76.110001,65.164803,-1293.417114,-0.002078,0.001847,0.046916,289.867523,14.766556,0.469160,-1293.417114,294.500488,0.000000
76.410004,65.103737,-1293.461548,-0.002070,0.001849,0.046960,289.595886,14.752718,0.469599,-1293.461548,294.500488,0.000000
76.710007,65.154015,-1293.417114,-0.002082,0.001849,0.046960,289.819519,14.764111,0.469599,-1293.417114,294.500488,0.000000
77.010002,65.103371,-1293.417114,-0.002074,0.001851,0.047004,289.594269,14.752634,0.470039,-1293.417114,294.500488,0.000000
77.310005,65.218803,-1293.461548,-0.002078,0.001852,0.047039,290.107727,14.778792,0.470387,-1293.461548,294.500488,0.000000
77.610001,65.158485,-1293.461548,-0.002070,0.001852,0.047039,289.839417,14.765123,0.470387,-1293.461548,294.500488,0.000000
77.910004,65.068733,-1293.461548,-0.002082,0.001852,0.047039,289.440186,14.744785,0.470387,-1293.461548,294.500488,0.000000
78.210007,65.037453,-1293.417114,-0.002087,0.001853,0.047064,289.301025,14.737697,0.470644,-1293.417114,294.500488,0.000000
78.510002,65.056450,-1293.417114,-0.002065,0.001854,0.047099,289.385529,14.742002,0.470992,-1293.417114,294.500488,0.000000
78.810005,65.072456,-1293.372559,-0.002074,0.001856,0.047142,289.456757,14.745629,0.471416,-1293.372559,294.500488,0.000000
79.110001,65.263481,-1293.461548,-0.002074,0.001859,0.047220,290.306458,14.788917,0.472203,-1293.461548,294.500488,0.000000
79.410004,65.243385,-1293.506104,-0.002057,0.001859,0.047220,290.217072,14.784363,0.472203,-1293.506104,294.500488,0.000000
79.710007,65.191246,-1293.372559,-0.002057,0.001859,0.047220,289.985138,14.772547,0.472203,-1293.372559,294.500488,0.000000
80.010002,65.099648,-1293.372559,-0.002065,0.001859,0.047220,289.577698,14.751791,0.472203,-1293.372559,294.500488,0.000000
80.310005,65.146187,-1293.417114,-0.002070,0.001861,0.047272,289.784698,14.762337,0.472718,-1293.417114,294.500488,0.000000
80.610001,65.099266,-1293.417114,-0.002065,0.001861,0.047272,289.575989,14.751705,0.472718,-1293.417114,294.500488,0.000000
80.910004,65.039314,-1293.461548,-0.002061,0.001861,0.047272,289.309326,14.738119,0.472718,-1293.461548,294.500488,0.000000
81.210007,64.957771,-1293.417114,-0.002070,0.001861,0.047281,288.946594,14.719642,0.472809,-1293.417114,294.500488,0.000000
81.510002,65.827629,-1293.417114,-0.002061,0.001871,0.047532,292.815918,14.916754,0.475322,-1293.417114,294.500488,0.000000
81.810005,65.769173,-1293.417114,-0.002061,0.001871,0.047523,292.555878,14.903507,0.475231,-1293.417114,294.500488,0.000000
82.110001,65.758003,-1293.417114,-0.002061,0.001871,0.047523,292.506195,14.900976,0.475231,-1293.417114,294.500488,0.000000
82.410004,65.593788,-1293.417114,-0.002052,0.001871,0.047523,291.775757,14.863765,0.475231,-1293.417114,294.500488,0.000000
82.710007,65.556175,-1293.417114,-0.002048,0.001871,0.047523,291.608429,14.855242,0.475231,-1293.417114,294.500488,0.000000
83.010002,65.482811,-1293.461548,-0.002039,0.001871,0.047523,291.282104,14.838617,0.475231,-1293.461548,294.500488,0.000000
83.310005,65.352852,-1293.461548,-0.002052,0.001871,0.047523,290.704010,14.809168,0.475231,-1293.461548,294.500488,0.000000
83.610001,65.297005,-1293.417114,-0.002048,0.001871,0.047523,290.455597,14.796514,0.475231,-1293.417114,294.500488,0.000000
83.910004,65.207634,-1293.461548,-0.002044,0.001871,0.047532,290.058044,14.776261,0.475322,-1293.461548,294.500488,0.000000
84.210007,65.124596,-1293.461548,-0.002044,0.001871,0.047532,289.688660,14.757444,0.475322,-1293.461548,294.500488,0.000000
84.510002,65.038582,-1293.417114,-0.002057,0.001871,0.047532,289.306061,14.737954,0.475322,-1293.417114,294.500488,0.000000
84.810005,64.976021,-1293.461548,-0.002035,0.001871,0.047532,289.027771,14.723777,0.475322,-1293.461548,294.500488,0.000000
85.110001,64.877708,-1293.461548,-0.002052,0.001871,0.047532,288.590454,14.701499,0.475322,-1293.461548,294.500488,0.000000
85.410004,65.607185,-1293.506104,-0.002048,0.001882,0.047802,291.835327,14.866801,0.478017,-1293.506104,294.500488,0.000000
85.710007,65.591179,-1293.461548,-0.002035,0.001881,0.047774,291.764130,14.863173,0.477745,-1293.461548,294.500488,0.000000
86.010002,65.548347,-1293.417114,-0.002031,0.001881,0.047774,291.573608,14.853468,0.477745,-1293.417114,294.500488,0.000000
86.310005,65.485786,-1293.506104,-0.002026,0.001881,0.047774,291.295319,14.839292,0.477745,-1293.506104,294.500488,0.000000
86.610001,65.385994,-1293.461548,-0.002039,0.001881,0.047774,290.851440,14.816678,0.477745,-1293.461548,294.500488,0.000000
86.910004,65.308174,-1293.417114,-0.002039,0.001881,0.047774,290.505280,14.799045,0.477745,-1293.417114,294.500488,0.000000
87.210007,65.261620,-1293.506104,-0.002039,0.001881,0.047774,290.298187,14.788494,0.477745,-1293.506104,294.500488,0.000000
87.510002,65.171516,-1293.461548,-0.002035,0.001881,0.047774,289.897369,14.768077,0.477745,-1293.461548,294.500488,0.000000
87.810005,65.082512,-1293.506104,-0.002031,0.001881,0.047774,289.501465,14.747909,0.477745,-1293.506104,294.500488,0.000000
88.110001,64.999855,-1293.461548,-0.002031,0.001881,0.047784,289.133789,14.729177,0.477835,-1293.461548,294.500488,0.000000
88.410004,64.941383,-1293.461548,-0.002039,0.001881,0.047784,288.873688,14.715928,0.477835,-1293.461548,294.500488,0.000000
88.710007,64.846809,-1293.461548,-0.002035,0.001881,0.047784,288.453003,14.694497,0.477835,-1293.461548,294.500488,0.000000
89.010002,64.769356,-1293.506104,-0.002026,0.001881,0.047784,288.108490,14.676946,0.477835,-1293.506104,294.500488,0.000000
89.310005,64.702690,-1293.461548,-0.002035,0.001881,0.047784,287.811951,14.661839,0.477835,-1293.461548,294.500488,0.000000
89.610001,65.858543,-1293.417114,-0.002035,0.001895,0.048130,292.953430,14.923759,0.481302,-1293.417114,294.500488,0.000000
89.910004,65.854820,-1293.506104,-0.002039,0.001895,0.048130,292.936859,14.922915,0.481302,-1293.506104,294.500488,0.000000
90.210007,65.830605,-1293.550537,-0.002022,0.001895,0.048130,292.829163,14.917428,0.481302,-1293.550537,294.500488,0.000000
90.510002,65.763954,-1293.461548,-0.002026,0.001895,0.048130,292.532684,14.902325,0.481302,-1293.461548,294.500488,0.000000
90.810005,65.692085,-1293.506104,-0.002031,0.001895,0.048130,292.212982,14.886039,0.481302,-1293.506104,294.500488,0.000000
91.110001,65.611656,-1293.506104,-0.002026,0.001895,0.048130,291.855225,14.867814,0.481302,-1293.506104,294.500488,0.000000
91.410004,65.566963,-1293.417114,-0.002035,0.001895,0.048130,291.656433,14.857686,0.481302,-1293.417114,1681.640991,0.000000
91.710007,65.463081,-1293.550537,-0.002022,0.001889,0.047983,291.194336,14.834146,0.479834,-1293.550537,0.047965,0.000000
92.010002,65.315987,-1293.506104,-0.002013,0.001879,0.047723,290.540009,14.800814,0.477230,-1293.506104,0.047472,0.000000
92.310005,65.187889,-1293.506104,-0.002018,0.001864,0.047341,289.970215,14.771787,0.473415,-1293.506104,0.046969,0.000000
92.610001,65.012138,-1293.550537,-0.002009,0.001849,0.046977,289.188446,14.731961,0.469766,-1293.550537,0.046465,0.000000
92.910004,64.952553,-1293.506104,-0.002005,0.001837,0.046648,288.923370,14.718459,0.466481,-1293.506104,0.045971,0.000000
93.210007,64.856117,-1293.594971,-0.002009,0.001807,0.045902,288.494415,14.696606,0.459017,-1293.594971,0.045469,0.000000
93.510002,64.771217,-1293.550537,-0.002013,0.001789,0.045451,288.116760,14.677368,0.454505,-1293.550537,0.044965,0.000000
93.810005,64.701576,-1293.506104,-0.002005,0.001767,0.044887,287.806976,14.661587,0.448873,-1293.506104,0.044471,0.000000
94.110008,64.617043,-1293.550537,-0.002013,0.001755,0.044575,287.430969,14.642431,0.445755,-1293.550537,0.043968,0.000000
94.410004,64.519493,-1293.550537,-0.001996,0.001737,0.044124,286.997040,14.620327,0.441243,-1293.550537,0.043466,0.000000
94.710007,64.433098,-1293.506104,-0.001992,0.001719,0.043664,286.612732,14.600749,0.436641,-1293.506104,0.042971,0.000000
95.010002,64.199623,-1293.506104,-0.002009,0.001699,0.043145,285.574188,14.547843,0.431448,-1293.506104,0.042468,0.000000
95.310005,64.080467,-1293.506104,-0.001992,0.001679,0.042641,285.044159,14.520842,0.426406,-1293.506104,0.041973,0.000000
95.610008,63.664894,-1293.461548,-0.001988,0.001660,0.042156,283.195587,14.426671,0.421562,-1293.461548,0.041470,0.000000
95.910004,63.011375,-1293.550537,-0.001979,0.001643,0.041722,280.288605,14.278582,0.417217,-1293.550537,0.040968,0.000000
96.210007,62.119171,-1293.506104,-0.001992,0.001623,0.041228,276.319885,14.076406,0.412281,-1293.506104,0.040473,0.000000
96.510002,61.238884,-1293.461548,-0.001988,0.001604,0.040742,272.404175,13.876929,0.407421,-1293.461548,0.039970,0.000000
96.810005,60.247261,-1293.506104,-0.001988,0.001585,0.040265,267.993195,13.652225,0.402652,-1293.506104,0.039467,0.000000
97.110008,58.917145,-1293.506104,-0.001979,0.001563,0.039693,262.076538,13.350816,0.396930,-1293.506104,0.038972,0.000000
97.410004,57.808594,-1293.461548,-0.001996,0.001547,0.039302,257.145477,13.099614,0.393023,-1293.461548,0.038470,0.000000
97.710007,56.726845,-1293.506104,-0.001996,0.001532,0.038903,252.333603,12.854486,0.389027,-1293.506104,0.037967,0.000000
98.010002,55.180389,-1293.506104,-0.001983,0.001514,0.038444,245.454636,12.504055,0.384439,-1293.506104,0.037472,0.000000
98.310005,54.055824,-1293.506104,-0.001983,0.001498,0.038044,240.452316,12.249225,0.380443,-1293.506104,0.036969,0.000000
98.610008,52.195824,-1293.506104,-0.001983,0.001476,0.037499,232.178619,11.827743,0.374992,-1293.506104,0.036467,0.000000
98.910004,50.418114,-1293.506104,-0.001983,0.001458,0.037039,224.270966,11.424908,0.370390,-1293.506104,0.035972,0.000000
99.210007,48.255379,-1293.506104,-0.002009,0.001436,0.036483,214.650650,10.934825,0.364834,-1293.506104,0.035469,0.000000
99.510002,46.158546,-1293.461548,-0.002001,0.001417,0.035999,205.323471,10.459677,0.359989,-1293.461548,0.034966,0.000000
99.810005,44.276573,-1293.461548,-0.002009,0.001398,0.035513,196.952042,10.033215,0.355129,-1293.461548,0.034471,0.000000
100.110008,42.155167,-1293.461548,-0.001992,0.001378,0.035010,187.515549,9.552497,0.350103,-1293.461548,0.033969,0.000000
100.410004,40.165955,-1293.506104,-0.002005,0.001359,0.034515,178.667084,9.101736,0.345152,-1293.506104,0.033466,0.000000
100.710007,38.362183,-1293.506104,-0.002009,0.001340,0.034038,170.643509,8.692995,0.340383,-1293.506104,0.032971,0.000000
101.010002,35.985703,-1293.550537,-0.002001,0.001318,0.033466,160.072403,8.154477,0.334660,-1293.550537,0.032468,0.000000
101.310005,34.254173,-1293.550537,-0.002013,0.001301,0.033041,152.370178,7.762106,0.330406,-1293.550537,0.031966,0.000000
101.610008,32.000198,-1293.506104,-0.002009,0.001277,0.032426,142.343994,7.251348,0.324260,-1293.506104,0.031471,0.000000
101.910004,29.886238,-1293.506104,-0.002026,0.001256,0.031914,132.940628,6.772318,0.319142,-1293.506104,0.030968,0.000000
102.210007,28.384460,-1293.506104,-0.002026,0.001242,0.031549,126.260384,6.432011,0.315494,-1293.506104,0.030465,0.000000
102.510002,26.790337,-1293.550537,-0.002031,0.001225,0.031124,119.169373,6.070777,0.311239,-1293.550537,0.029970,0.000000
102.810005,24.927727,-1293.506104,-0.002031,0.001207,0.030656,110.884064,5.648704,0.306561,-1293.506104,0.029468,0.000000
103.110008,23.049484,-1293.506104,-0.002057,0.001188,0.030170,102.529228,5.223088,0.301702,-1293.506104,0.028965,0.000000
103.410004,20.658478,-1293.506104,-0.002052,0.001164,0.029554,91.893501,4.681278,0.295540,-1293.506104,0.028470,0.000000
103.710007,18.358337,-1293.506104,-0.002052,0.001141,0.028991,81.661964,4.160058,0.289908,-1293.506104,0.027967,0.000000
104.010002,16.134155,-1293.550537,-0.002065,0.001118,0.028409,71.768311,3.656052,0.284094,-1293.550537,0.027465,0.000000
104.310005,14.825638,-1293.506104,-0.002052,0.001104,0.028054,65.947731,3.359538,0.280536,-1293.506104,0.026970,0.000000
104.610008,13.436317,-1293.550537,-0.002061,0.001091,0.027707,59.767727,3.044713,0.277069,-1293.550537,0.026467,0.000000
104.910004,11.381561,-1293.550537,-0.002074,0.001067,0.027092,50.627712,2.579099,0.270923,-1293.550537,0.025964,0.000000
105.210007,9.003593,-1293.506104,-0.002070,0.001045,0.026537,40.049984,2.040243,0.265367,-1293.506104,0.025469,0.000000
105.510002,7.185669,-1293.506104,-0.002087,0.001027,0.026076,31.963451,1.628296,0.260764,-1293.506104,0.024967,0.000000
105.810005,5.975090,-1293.550537,-0.002095,0.001014,0.025765,26.578527,1.353975,0.257645,-1293.550537,0.024464,0.000000
106.110008,3.973587,-1293.506104,-0.002100,0.000992,0.025192,17.675398,0.900428,0.251923,-1293.506104,0.023970,0.000000
106.410004,1.983627,-1293.550537,-0.002091,0.000968,0.024576,8.823615,0.449496,0.245761,-1293.550537,0.023466,0.000000
106.710007,-0.034256,-1293.550537,-0.002104,0.000946,0.024022,-0.152378,-0.007763,0.240220,-1293.550537,0.022964,0.000000
107.010002,-1.539017,-1293.506104,-0.002130,0.000927,0.023545,-6.845888,-0.348746,0.235451,-1293.506104,0.022470,0.000000
107.310005,-0.235710,-1293.550537,-0.002156,0.000904,0.022955,-1.048491,-0.053413,0.229546,-1293.550537,0.021966,0.000000
107.610008,-0.106125,-1293.550537,-0.002177,0.000887,0.022538,-0.472067,-0.024048,0.225383,-1293.550537,0.021463,0.000000
107.910004,-0.077454,-1293.506104,-0.002199,0.000865,0.021958,-0.344531,-0.017551,0.219584,-1293.506104,0.020970,0.000000
108.210007,-0.069260,-1293.550537,-0.002216,0.000846,0.021489,-0.308082,-0.015694,0.214891,-1293.550537,0.020466,0.000000
108.510002,-0.068886,-1293.550537,-0.002255,0.000824,0.020935,-0.306419,-0.015610,0.209350,-1293.550537,0.019972,0.000000
108.810005,-0.071121,-1293.550537,-0.002289,0.000809,0.020544,-0.316363,-0.016116,0.205444,-1293.550537,0.019469,0.000000
109.110008,-0.083412,-1293.550537,-0.002307,0.000785,0.019946,-0.371036,-0.018901,0.199464,-1293.550537,0.018965,0.000000
109.410004,-0.061813,-1293.550537,-0.002328,0.000772,0.019598,-0.274960,-0.014007,0.195982,-1293.550537,0.018472,0.000000
109.710007,-0.058838,-1293.550537,-0.002350,0.000759,0.019286,-0.261724,-0.013333,0.192863,-1293.550537,0.017969,0.000000
110.010002,-0.039841,-1293.506104,-0.002376,0.000733,0.018619,-0.177220,-0.009028,0.186187,-1293.506104,0.017465,0.000000
110.310005,-0.037613,-1293.506104,-0.002380,0.000715,0.018151,-0.167311,-0.008523,0.181508,-1293.506104,0.016971,0.000000
110.610008,-0.054741,-1293.594971,-0.002402,0.000705,0.017916,-0.243500,-0.012404,0.179162,-1293.594971,0.016469,0.000000
110.910004,-0.047295,-1293.594971,-0.002453,0.000664,0.016867,-0.210377,-0.010717,0.168670,-1293.594971,0.015965,0.000000
111.210007,-0.072609,-1293.594971,-0.002471,0.000649,0.016495,-0.322981,-0.016453,0.164946,-1293.594971,0.015471,0.000000
111.510002,-0.054741,-1293.550537,-0.002483,0.000630,0.016000,-0.243500,-0.012404,0.159995,-1293.550537,0.014969,0.000000
111.810005,-0.037239,-1293.639526,-0.002501,0.000612,0.015548,-0.165648,-0.008438,0.155483,-1293.639526,0.014464,0.000000
112.110008,-0.042076,-1293.550537,-0.002531,0.000595,0.015106,-0.187164,-0.009535,0.151063,-1293.550537,0.013971,0.000000
112.410004,-0.042076,-1293.550537,-0.002539,0.000576,0.014622,-0.187164,-0.009535,0.146218,-1293.550537,0.013468,0.000000
112.710007,-0.032394,-1293.550537,-0.002583,0.000558,0.014178,-0.144098,-0.007341,0.141782,-1293.550537,0.012964,0.000000
113.010002,-0.053619,-1293.550537,-0.002596,0.000533,0.013529,-0.238511,-0.012150,0.135287,-1293.550537,0.012470,0.000000
113.310005,-0.050270,-1293.506104,-0.002613,0.000515,0.013087,-0.223612,-0.011391,0.130867,-1293.506104,0.011968,0.000000
113.610008,-0.044312,-1293.594971,-0.002621,0.000494,0.012557,-0.197107,-0.010041,0.125568,-1293.594971,0.011464,0.000000
113.910004,-0.055115,-1293.594971,-0.002639,0.000480,0.012201,-0.245163,-0.012489,0.122010,-1293.594971,0.010970,0.000000
114.210007,-0.059204,-1293.594971,-0.002660,0.000461,0.011698,-0.263353,-0.013416,0.116984,-1293.594971,0.010468,0.000000
114.510002,-0.053993,-1293.550537,-0.002677,0.000447,0.011343,-0.240174,-0.012235,0.113426,-1293.550537,0.009963,0.000000
114.810005,-0.032394,-1293.550537,-0.002708,0.000408,0.010363,-0.144098,-0.007341,0.103630,-1293.550537,0.009470,0.000000
115.110008,-0.058090,-1293.550537,-0.002725,0.000393,0.009982,-0.258398,-0.013163,0.099815,-1293.550537,0.008967,0.000000
115.410004,-0.012291,-1293.550537,-0.002764,0.000368,0.009349,-0.054673,-0.002785,0.093487,-1293.550537,0.008463,0.000000
115.710007,-0.011917,-1293.594971,-0.002764,0.000361,0.009158,-0.053010,-0.002700,0.091579,-1293.594971,0.007969,0.000000
116.010002,-0.028671,-1293.594971,-0.002794,0.000339,0.008602,-0.127536,-0.006497,0.086023,-1293.594971,0.007467,0.000000
116.310005,-0.026810,-1293.550537,-0.002815,0.000319,0.008091,-0.119255,-0.006075,0.080906,-1293.550537,0.006964,0.000000
116.610008,-0.046921,-1293.683960,-0.002824,0.000300,0.007632,-0.208714,-0.010632,0.076319,-1293.683960,0.006469,0.000000
116.910004,-0.010796,-1293.639526,-0.002854,0.000280,0.007102,-0.048021,-0.002446,0.071020,-1293.639526,0.005967,0.000000
117.210007,-0.002235,-1293.506104,-0.002871,0.000260,0.006608,-0.009944,-0.000507,0.066084,-1293.506104,0.005464,0.000000
117.510002,0.015266,-1293.594971,-0.002902,0.000235,0.005967,0.067908,0.003459,0.059665,-1293.594971,0.004969,0.000000
117.810005,-0.000000,-1293.594971,-0.002919,0.000225,0.005706,-0.000000,-0.000000,0.057061,-1293.594971,0.004466,0.000000
118.110008,0.020851,-1293.594971,-0.002936,0.000201,0.005099,0.092750,0.004725,0.050990,-1293.594971,0.003964,0.000000
118.410004,-0.002235,-1293.550537,-0.002962,0.000174,0.004431,-0.009944,-0.000507,0.044314,-1293.550537,0.003468,0.000000
118.710007,-0.009682,-1293.594971,-0.002984,0.000153,0.003885,-0.043066,-0.002194,0.038848,-1293.594971,0.002966,0.000000
119.010002,-0.049156,-1293.550537,-0.003005,0.000140,0.003547,-0.218658,-0.011139,0.035472,-1293.550537,0.002463,0.000000
119.310005,-0.002975,-1293.550537,-0.003018,0.000128,0.003243,-0.013236,-0.000674,0.032429,-1293.550537,0.001968,0.000000
119.610008,0.041702,-1293.594971,-0.003035,0.000105,0.002662,0.185501,0.009450,0.026615,-1293.594971,0.001466,0.000000
119.910004,0.025696,-1293.550537,-0.003044,0.000084,0.002142,0.114301,0.005823,0.021423,-1293.550537,0.000963,0.000000
120.210007,-0.004471,-1293.550537,-0.003070,0.000059,0.001508,-0.019887,-0.001013,0.015079,-1293.550537,0.000468,0.000000
120.510002,0.008934,-1293.550537,-0.003091,0.000043,0.001093,0.039741,0.002024,0.010931,-1293.550537,-0.000035,0.000000
120.810005,-0.042450,-1293.594971,-0.003104,0.000018,0.000468,-0.188827,-0.009619,0.004678,-1293.594971,-0.000530,0.000000
121.110008,-0.007820,-1293.506104,-0.003126,0.000001,0.000017,-0.034786,-0.001772,0.000167,-1293.506104,-0.001023,0.000000
121.200005,-0.007446,-1293.506104,-0.003143,0.000004,0.000112,-0.033123,-0.001687,0.001120,-1293.506104,-0.000009,0.000000