File: Data/Sima compression/P1-21-3_10302024_175207.csv
Time (sec),S:Load (lbs),S:HL1 (DIM),S:LVDT (in),S:Position (in),Ch:Position (mm),Ch:Load (N),Ch:Stress (MPa),Ch:Strain (mm/mm),Ch:HL1 (DIM),Set Point (),Cycles ()
0.210000,-0.004097,-1293.550537,-0.007925,-0.004409,-0.111994,-0.018224,-0.000928,-1.119935,-1293.550537,-0.111794,0.000000
0.490000,0.003349,-1293.461548,-0.007933,-0.004360,-0.110745,0.014898,0.000759,-1.107445,-1293.461548,-0.110095,0.000000
0.770000,0.004845,-1293.461548,-0.007830,-0.004194,-0.106539,0.021550,0.001098,-1.065387,-1293.461548,-0.105429,0.000000
1.050000,-0.084900,-1293.506104,-0.007636,-0.004007,-0.101786,-0.377654,-0.019239,-1.017864,-1293.506104,-0.100763,0.000000
1.330000,0.003723,-1293.506104,-0.007437,-0.003826,-0.097173,0.016561,0.000844,-0.971734,-1293.506104,-0.096097,0.000000
1.610000,0.016388,-1293.506104,-0.007269,-0.003644,-0.092559,0.072897,0.003714,-0.925588,-1293.506104,-0.091432,0.000000
1.890000,-0.009308,-1293.417114,-0.007071,-0.003459,-0.087867,-0.041403,-0.002109,-0.878671,-1293.417114,-0.086766,0.000000
2.170000,0.026070,-1293.461548,-0.006890,-0.003285,-0.083428,0.115964,0.005907,-0.834282,-1293.461548,-0.082100,0.000000
2.450000,-0.024200,-1293.461548,-0.006687,-0.003098,-0.078683,-0.107649,-0.005484,-0.786834,-1293.461548,-0.077434,0.000000
2.730000,0.005959,-1293.506104,-0.006510,-0.002916,-0.074061,0.026505,0.001350,-0.740613,-1293.506104,-0.072770,0.000000
3.010000,-0.082291,-1293.506104,-0.006299,-0.002725,-0.069205,-0.366047,-0.018647,-0.692045,-1293.506104,-0.068104,0.000000
3.290000,0.000748,-1293.461548,-0.006118,-0.002545,-0.064643,0.003326,0.000169,-0.646430,-1293.461548,-0.063438,0.000000
3.570000,0.004471,-1293.506104,-0.005946,-0.002358,-0.059891,0.019887,0.001013,-0.598907,-1293.506104,-0.058772,0.000000
3.850000,0.027184,-1293.417114,-0.005743,-0.002175,-0.055243,0.120918,0.006160,-0.552428,-1293.417114,-0.054106,0.000000
4.130000,0.041702,-1293.506104,-0.005558,-0.001990,-0.050551,0.185501,0.009450,-0.505511,-1293.506104,-0.049441,0.000000
4.410000,0.016014,-1293.506104,-0.005368,-0.001809,-0.045955,0.071234,0.003629,-0.459547,-1293.506104,-0.044775,0.000000
4.690000,0.005211,-1293.417114,-0.005195,-0.001641,-0.041679,0.023179,0.001181,-0.416793,-1293.417114,-0.040109,0.000000
4.970000,-0.035378,-1293.506104,-0.005001,-0.001442,-0.036615,-0.157367,-0.008017,-0.366151,-1293.506104,-0.035443,0.000000
5.250000,-0.005585,-1293.506104,-0.004825,-0.001260,-0.032010,-0.024842,-0.001266,-0.320096,-1293.506104,-0.030779,0.000000
5.530000,-0.050644,-1293.461548,-0.004622,-0.001073,-0.027248,-0.225275,-0.011476,-0.272482,-1293.461548,-0.026113,0.000000
5.810000,0.034630,-1293.461548,-0.004428,-0.000890,-0.022600,0.154041,0.007847,-0.226004,-1293.461548,-0.021465,0.000000
6.090000,0.003349,-1293.417114,-0.004234,-0.000701,-0.017813,0.014898,0.000759,-0.178132,-1293.417114,-0.016799,0.000000
6.370000,0.018250,-1293.506104,-0.004057,-0.000522,-0.013261,0.081178,0.004135,-0.132608,-1293.506104,-0.012133,0.000000
6.650000,0.027184,-1293.550537,-0.003863,-0.000341,-0.008655,0.120918,0.006160,-0.086553,-1293.550537,-0.007467,0.000000
6.930000,0.017876,-1293.550537,-0.003686,-0.000154,-0.003920,0.079515,0.004051,-0.039196,-1293.550537,-0.002801,0.000000
7.210001,0.066284,-1293.372559,-0.003540,0.000002,0.000051,0.294847,0.015020,0.000515,-1293.372559,0.000268,0.000000
7.490000,0.053619,-1293.461548,-0.003531,0.000002,0.000051,0.238511,0.012150,0.000515,-1293.461548,0.000268,0.000000
7.770000,0.135918,-1293.506104,-0.003527,0.000002,0.000051,0.604592,0.030799,0.000515,-1293.506104,0.000486,0.000000
8.050000,0.090485,-1293.506104,-0.003540,0.000007,0.000182,0.402496,0.020504,0.001817,-1293.506104,0.000954,0.000000
8.330000,0.167564,-1293.506104,-0.003527,0.000023,0.000581,0.745364,0.037971,0.005814,-1293.506104,0.001422,0.000000
8.610001,0.370880,-1293.417114,-0.003505,0.000041,0.001031,1.649757,0.084043,0.010310,-1293.417114,0.001889,0.000000
8.890000,0.467331,-1293.372559,-0.003501,0.000049,0.001240,2.078792,0.105899,0.012399,-1293.372559,0.002359,0.000000
9.170000,0.977852,-1293.461548,-0.003479,0.000077,0.001951,4.349702,0.221584,0.019515,-1293.461548,0.002817,0.000000
9.450001,1.403473,-1293.506104,-0.003466,0.000094,0.002384,6.242959,0.318031,0.023845,-1293.506104,0.003287,0.000000
9.730000,1.969849,-1293.461548,-0.003454,0.000112,0.002836,8.762324,0.446374,0.028356,-1293.461548,0.003755,0.000000
10.010000,2.644592,-1293.461548,-0.003445,0.000130,0.003294,11.763734,0.599273,0.032944,-1293.461548,0.004222,0.000000
10.290001,3.414284,-1293.461548,-0.003419,0.000149,0.003780,15.187492,0.773688,0.037804,-1293.461548,0.004692,0.000000
10.570001,4.331062,-1293.506104,-0.003410,0.000169,0.004292,19.265528,0.981433,0.042921,-1293.506104,0.005160,0.000000
10.850000,4.711998,-1293.461548,-0.003419,0.000178,0.004509,20.960014,1.067754,0.045086,-1293.461548,0.005620,0.000000
11.130000,5.877151,-1293.550537,-0.003402,0.000202,0.005143,26.142876,1.331782,0.051429,-1293.550537,0.006088,0.000000
11.410001,6.669937,-1293.461548,-0.003393,0.000220,0.005585,29.669363,1.511429,0.055850,-1293.461548,0.006555,0.000000
11.690001,7.628792,-1293.461548,-0.003372,0.000239,0.006079,33.934563,1.728709,0.060785,-1293.461548,0.007025,0.000000
11.970000,8.529190,-1293.506104,-0.003363,0.000258,0.006548,37.939732,1.932742,0.065479,-1293.506104,0.007493,0.000000
12.250001,9.591194,-1293.461548,-0.003350,0.000276,0.007007,42.663761,2.173396,0.070066,-1293.461548,0.007951,0.000000
12.530001,10.468880,-1293.417114,-0.003346,0.000294,0.007458,46.567902,2.372282,0.074578,-1293.417114,0.008421,0.000000
12.810000,10.751511,-1293.506104,-0.003341,0.000299,0.007605,47.825108,2.436327,0.076046,-1293.506104,0.008888,0.000000
13.090000,12.964523,-1293.417114,-0.003303,0.000337,0.008558,57.669079,2.937803,0.085584,-1293.417114,0.009356,0.000000
13.370001,13.572235,-1293.461548,-0.003316,0.000351,0.008914,60.372318,3.075512,0.089142,-1293.461548,0.009826,0.000000
13.650001,14.313622,-1293.550537,-0.003290,0.000367,0.009314,63.670170,3.243513,0.093139,-1293.550537,0.010284,0.000000
13.930000,15.390900,-1293.417114,-0.003294,0.000385,0.009782,68.462143,3.487628,0.097817,-1293.417114,0.010754,0.000000
14.210001,16.562752,-1293.461548,-0.003264,0.000404,0.010259,73.674797,3.753173,0.102586,-1293.461548,0.011221,0.000000
14.490001,17.550659,-1293.506104,-0.003260,0.000422,0.010710,78.069229,3.977036,0.107097,-1293.506104,0.011689,0.000000
14.770000,17.910744,-1293.550537,-0.003260,0.000428,0.010884,79.670967,4.058633,0.108838,-1293.550537,0.012159,0.000000
15.050001,19.619560,-1293.461548,-0.003251,0.000457,0.011603,87.272163,4.445856,0.116030,-1293.461548,0.012626,0.000000
15.330001,20.818230,-1293.417114,-0.003229,0.000477,0.012115,92.604111,4.717478,0.121147,-1293.417114,0.013087,0.000000
15.610001,21.742455,-1293.506104,-0.003221,0.000494,0.012540,96.715271,4.926911,0.125401,-1293.506104,0.013554,0.000000
15.890000,22.451454,-1293.506104,-0.003212,0.000511,0.012973,99.869057,5.087572,0.129731,-1293.506104,0.014022,0.000000
16.170000,24.175163,-1293.461548,-0.003195,0.000535,0.013580,107.536499,5.478170,0.135802,-1293.461548,0.014492,0.000000
16.450001,24.914322,-1293.417114,-0.003195,0.000550,0.013962,110.824440,5.645666,0.139617,-1293.417114,0.014959,0.000000
16.730001,25.136261,-1293.417114,-0.003195,0.000558,0.014171,111.811676,5.695958,0.141706,-1293.417114,0.015418,0.000000
17.010000,26.945244,-1293.506104,-0.003160,0.000587,0.014908,119.858429,6.105880,0.149079,-1293.506104,0.015887,0.000000
17.290001,28.007622,-1293.461548,-0.003165,0.000605,0.015376,124.584122,6.346618,0.153758,-1293.461548,0.016355,0.000000
17.570002,28.727043,-1293.461548,-0.003152,0.000620,0.015739,127.784271,6.509641,0.157391,-1293.461548,0.016823,0.000000
17.850000,30.245583,-1293.417114,-0.003156,0.000646,0.016399,134.539078,6.853747,0.163992,-1293.417114,0.017292,0.000000
18.130001,30.978783,-1293.372559,-0.003109,0.000659,0.016746,137.800507,7.019892,0.167459,-1293.372559,0.017760,0.000000
18.410002,31.879921,-1293.461548,-0.003113,0.000676,0.017179,141.808975,7.224093,0.171789,-1293.461548,0.018220,0.000000
18.690001,32.130905,-1293.461548,-0.003113,0.000690,0.017535,142.925400,7.280967,0.175347,-1293.461548,0.018688,0.000000
18.970001,34.191238,-1293.417114,-0.003087,0.000720,0.018298,152.090225,7.747846,0.182977,-1293.417114,0.019156,0.000000
19.250000,34.830605,-1293.328125,-0.003087,0.000735,0.018663,154.934265,7.892728,0.186626,-1293.328125,0.019625,0.000000
19.530001,35.533272,-1293.461548,-0.003061,0.000750,0.019044,158.059891,8.051954,0.190441,-1293.461548,0.020093,0.000000
19.810001,36.604958,-1293.461548,-0.003048,0.000774,0.019660,162.826981,8.294802,0.196603,-1293.461548,0.020553,0.000000
20.090000,37.540733,-1293.461548,-0.003044,0.000790,0.020058,166.989517,8.506852,0.200584,-1293.461548,0.021021,0.000000
20.370001,38.183075,-1293.417114,-0.003044,0.000805,0.020440,169.846802,8.652409,0.204399,-1293.417114,0.021489,0.000000
20.650002,39.253647,-1293.417114,-0.003014,0.000829,0.021056,174.608948,8.895004,0.210561,-1293.417114,0.021958,0.000000
20.930000,39.851303,-1293.506104,-0.002988,0.000846,0.021498,177.267456,9.030434,0.214982,-1293.506104,0.022426,0.000000
21.210001,40.678711,-1293.506104,-0.003001,0.000863,0.021915,180.947937,9.217928,0.219145,-1293.506104,0.022894,0.000000
21.490002,41.436119,-1293.417114,-0.002984,0.000880,0.022340,184.317062,9.389559,0.223400,-1293.417114,0.023354,0.000000
21.770000,42.475410,-1293.461548,-0.002958,0.000900,0.022868,188.940063,9.625066,0.228683,-1293.461548,0.023822,0.000000
22.050001,42.767723,-1293.461548,-0.002962,0.000915,0.023233,190.240341,9.691304,0.232332,-1293.461548,0.024290,0.000000
22.330002,43.611893,-1293.506104,-0.002940,0.000931,0.023657,193.995392,9.882596,0.236571,-1293.506104,0.024759,0.000000
22.610001,43.677429,-1293.506104,-0.002928,0.000940,0.023883,194.286911,9.897447,0.238827,-1293.506104,0.025227,0.000000
22.890001,45.547852,-1293.461548,-0.002919,0.000973,0.024724,202.606964,10.321291,0.247244,-1293.461548,0.025687,0.000000
23.170002,46.300423,-1293.461548,-0.002897,0.000990,0.025150,205.954559,10.491826,0.251499,-1293.461548,0.026155,0.000000
23.450001,46.834030,-1293.461548,-0.002880,0.001005,0.025531,208.328171,10.612743,0.255314,-1293.461548,0.026623,0.000000
23.730001,47.949654,-1293.506104,-0.002880,0.001027,0.026095,213.290710,10.865547,0.260946,-1293.506104,0.027092,0.000000
24.010000,48.719353,-1293.461548,-0.002863,0.001046,0.026562,216.714508,11.039964,0.265624,-1293.461548,0.027560,0.000000
24.290001,49.277908,-1293.461548,-0.002859,0.001059,0.026909,219.199081,11.166533,0.269091,-1293.461548,0.028020,0.000000
24.570002,49.204178,-1293.461548,-0.002841,0.001076,0.027335,218.871109,11.149826,0.273345,-1293.461548,0.028488,0.000000
24.850000,51.112961,-1293.506104,-0.002820,0.001100,0.027933,227.361801,11.582362,0.279325,-1293.506104,0.028956,0.000000
25.130001,51.849518,-1293.506104,-0.002824,0.001120,0.028444,230.638168,11.749269,0.284442,-1293.506104,0.029425,0.000000
25.410002,52.424454,-1293.372559,-0.002811,0.001134,0.028791,233.195618,11.879551,0.287909,-1293.372559,0.029893,0.000000
25.690001,53.428375,-1293.461548,-0.002802,0.001157,0.029390,237.661285,12.107042,0.293905,-1293.461548,0.030361,0.000000
25.970001,54.255043,-1293.417114,-0.002772,0.001173,0.029798,241.338486,12.294369,0.297977,-1293.417114,0.030821,0.000000
26.250002,54.787903,-1293.417114,-0.002759,0.001187,0.030144,243.708771,12.415115,0.301444,-1293.417114,0.031289,0.000000
26.530001,54.484047,-1293.506104,-0.002764,0.001196,0.030370,242.357147,12.346262,0.303700,-1293.506104,0.031757,0.000000
26.810001,57.334930,-1293.461548,-0.002755,0.001232,0.031298,255.038513,12.992281,0.312981,-1293.461548,0.032226,0.000000
27.090002,57.585915,-1293.417114,-0.002755,0.001246,0.031645,256.154938,13.049155,0.316447,-1293.417114,0.032694,0.000000
27.370001,58.573814,-1293.461548,-0.002703,0.001266,0.032166,260.549347,13.273016,0.321656,-1293.461548,0.033154,0.000000
27.650002,59.011726,-1293.506104,-0.002725,0.001282,0.032564,262.497284,13.372249,0.325637,-1293.506104,0.033622,0.000000
27.930002,60.380943,-1293.550537,-0.002695,0.001307,0.033189,268.587860,13.682517,0.331890,-1293.550537,0.034090,0.000000
28.210001,60.459511,-1293.506104,-0.002686,0.001315,0.033413,268.937347,13.700321,0.334131,-1293.506104,0.034559,0.000000
28.490002,61.070946,-1293.461548,-0.002673,0.001340,0.034047,271.657135,13.838874,0.340474,-1293.461548,0.035027,0.000000
28.770000,62.895569,-1293.550537,-0.002656,0.001360,0.034550,279.773468,14.252339,0.345500,-1293.550537,0.035495,0.000000
29.050001,63.347633,-1293.550537,-0.002660,0.001378,0.035001,281.784332,14.354778,0.350012,-1293.550537,0.035955,0.000000
29.330002,63.962791,-1293.506104,-0.002639,0.001393,0.035392,284.520721,14.494176,0.353918,-1293.506104,0.036423,0.000000
29.610001,64.727638,-1293.506104,-0.002621,0.001412,0.035869,287.922913,14.667493,0.358687,-1293.506104,0.036892,0.000000
29.890001,65.430305,-1293.461548,-0.002617,0.001429,0.036302,291.048523,14.826719,0.363017,-1293.461548,0.037360,0.000000
30.170002,65.852577,-1293.550537,-0.002591,0.001443,0.036657,292.926880,14.922407,0.366575,-1293.550537,0.037828,0.000000
30.450001,66.465126,-1293.506104,-0.002591,0.001452,0.036874,295.651642,15.061213,0.368740,-1293.506104,0.037090,0.000000
30.730001,65.310783,-1293.506104,-0.002574,0.001452,0.036874,290.516876,14.799635,0.368740,-1293.506104,290.925964,0.000000
31.010002,65.223274,-1293.506104,-0.002574,0.001464,0.037195,290.127625,14.779805,0.371949,-1293.506104,294.500488,0.000000
31.290001,65.298485,-1293.461548,-0.002570,0.001477,0.037516,290.462158,14.796848,0.375159,-1293.461548,294.500488,0.000000
31.570002,65.250084,-1293.461548,-0.002552,0.001483,0.037672,290.246857,14.785880,0.376718,-1293.461548,294.500488,0.000000
31.850002,65.011757,-1293.594971,-0.002557,0.001491,0.037872,289.186737,14.731875,0.378717,-1293.594971,294.500488,0.000000
32.130001,65.190132,-1293.506104,-0.002548,0.001504,0.038200,289.980194,14.772295,0.382002,-1293.506104,294.500488,0.000000
32.410000,65.119011,-1293.461548,-0.002548,0.001508,0.038305,289.663818,14.756179,0.383047,-1293.461548,294.500488,0.000000
32.690002,65.525261,-1293.461548,-0.002518,0.001517,0.038530,291.470917,14.848237,0.385302,-1293.461548,294.500488,0.000000
32.970001,65.171883,-1293.506104,-0.002522,0.001522,0.038670,289.899017,14.768160,0.386695,-1293.506104,294.500488,0.000000
33.250000,65.107460,-1293.506104,-0.002514,0.001528,0.038800,289.612457,14.753561,0.387997,-1293.506104,294.500488,0.000000
33.530003,65.230339,-1293.461548,-0.002531,0.001535,0.038981,290.159027,14.781406,0.389814,-1293.461548,294.500488,0.000000
33.810001,65.048622,-1293.506104,-0.002509,0.001542,0.039155,289.350708,14.740228,0.391555,-1293.506104,294.500488,0.000000
34.090000,65.457497,-1293.461548,-0.002488,0.001550,0.039381,291.169495,14.832880,0.393811,-1293.461548,294.500488,0.000000
34.370003,65.119759,-1293.506104,-0.002492,0.001552,0.039433,289.667145,14.756349,0.394325,-1293.506104,294.500488,0.000000
34.650002,65.224388,-1293.506104,-0.002483,0.001558,0.039579,290.132568,14.780058,0.395794,-1293.506104,294.500488,0.000000
34.930000,65.229225,-1293.506104,-0.002479,0.001564,0.039728,290.154083,14.781154,0.397278,-1293.506104,294.500488,0.000000
35.210003,65.103737,-1293.461548,-0.002471,0.001568,0.039823,289.595886,14.752718,0.398232,-1293.461548,294.500488,0.000000
35.490002,64.893715,-1293.506104,-0.002471,0.001571,0.039900,288.661652,14.705127,0.399004,-1293.506104,294.500488,0.000000
35.770000,65.566963,-1293.461548,-0.002462,0.001582,0.040177,291.656433,14.857686,0.401774,-1293.461548,294.500488,0.000000
36.050003,65.105980,-1293.506104,-0.002466,0.001586,0.040274,289.605865,14.753226,0.402743,-1293.506104,294.500488,0.000000
36.330002,65.123482,-1293.461548,-0.002466,0.001588,0.040342,289.683716,14.757192,0.403424,-1293.461548,294.500488,0.000000
36.610001,65.137993,-1293.461548,-0.002440,0.001595,0.040507,289.748260,14.760480,0.405075,-1293.461548,294.500488,0.000000
36.890003,65.329399,-1293.461548,-0.002445,0.001600,0.040638,290.599670,14.803853,0.406377,-1293.461548,294.500488,0.000000
37.170002,65.248222,-1293.506104,-0.002445,0.001609,0.040880,290.238586,14.785459,0.408799,-1293.506104,294.500488,0.000000
37.450001,65.429558,-1293.461548,-0.002432,0.001608,0.040854,291.045197,14.826550,0.408542,-1293.461548,294.500488,0.000000
37.730003,65.239662,-1293.461548,-0.002449,0.001614,0.041003,290.200500,14.783519,0.410025,-1293.461548,294.500488,0.000000
38.010002,65.130928,-1293.506104,-0.002432,0.001614,0.041003,289.716827,14.758880,0.410025,-1293.506104,294.500488,0.000000
38.290001,65.497337,-1293.506104,-0.002423,0.001622,0.041210,291.346710,14.841908,0.412099,-1293.506104,294.500488,0.000000
38.570004,65.151772,-1293.461548,-0.002423,0.001623,0.041219,289.809540,14.763602,0.412190,-1293.461548,294.500488,0.000000
38.850002,65.184547,-1293.461548,-0.002427,0.001627,0.041331,289.955353,14.771029,0.413311,-1293.461548,294.500488,0.000000
39.130001,65.281731,-1293.417114,-0.002414,0.001632,0.041461,290.387634,14.793052,0.414613,-1293.417114,294.500488,0.000000
39.410004,65.359932,-1293.461548,-0.002410,0.001638,0.041601,290.735504,14.810773,0.416005,-1293.461548,294.500488,0.000000
39.690002,65.176720,-1293.461548,-0.002402,0.001638,0.041610,289.920532,14.769256,0.416096,-1293.461548,294.500488,0.000000
39.970001,65.115288,-1293.506104,-0.002393,0.001642,0.041696,289.647278,14.755335,0.416959,-1293.506104,294.500488,0.000000
40.250004,65.119377,-1293.506104,-0.002397,0.001645,0.041791,289.665466,14.756262,0.417913,-1293.506104,294.500488,0.000000
40.530003,65.125343,-1293.417114,-0.002389,0.001648,0.041869,289.691986,14.757614,0.418685,-1293.417114,294.500488,0.000000
40.810001,65.479836,-1293.461548,-0.002393,0.001655,0.042034,291.268860,14.837942,0.420335,-1293.461548,294.500488,0.000000
41.090000,65.216576,-1293.506104,-0.002384,0.001655,0.042034,290.097809,14.778287,0.420335,-1293.506104,294.500488,0.000000
41.370003,65.324928,-1293.461548,-0.002393,0.001660,0.042173,290.579803,14.802840,0.421728,-1293.461548,294.500488,0.000000
41.650002,65.151024,-1293.461548,-0.002397,0.001662,0.042217,289.806213,14.763433,0.422167,-1293.461548,294.500488,0.000000
41.930000,65.297752,-1293.461548,-0.002384,0.001667,0.042338,290.458923,14.796682,0.423378,-1293.461548,294.500488,0.000000
42.210003,65.200935,-1293.461548,-0.002371,0.001667,0.042338,290.028259,14.774743,0.423378,-1293.461548,294.500488,0.000000
42.490002,65.359932,-1293.550537,-0.002380,0.001673,0.042485,290.735504,14.810773,0.424847,-1293.550537,294.500488,0.000000
42.770000,65.215446,-1293.461548,-0.002376,0.001673,0.042494,290.092804,14.778031,0.424938,-1293.461548,294.500488,0.000000
43.050003,65.044167,-1293.372559,-0.002380,0.001674,0.042529,289.330902,14.739220,0.425286,-1293.372559,294.500488,0.000000
43.330002,65.277641,-1293.417114,-0.002371,0.001679,0.042650,290.369446,14.792125,0.426497,-1293.417114,294.500488,0.000000
43.610001,65.044533,-1293.550537,-0.002367,0.001679,0.042659,289.332520,14.739302,0.426588,-1293.550537,294.500488,0.000000
43.890003,65.076927,-1293.461548,-0.002363,0.001683,0.042745,289.476624,14.746643,0.427451,-1293.461548,294.500488,0.000000
44.170002,64.886650,-1293.506104,-0.002367,0.001683,0.042754,288.630249,14.703525,0.427542,-1293.506104,294.500488,0.000000
44.450001,65.656715,-1293.417114,-0.002358,0.001694,0.043022,292.055664,14.878025,0.430221,-1293.417114,294.500488,0.000000
44.730003,65.491386,-1293.461548,-0.002354,0.001694,0.043022,291.320251,14.840561,0.430221,-1293.461548,294.500488,0.000000
45.010002,65.246727,-1293.506104,-0.002350,0.001694,0.043022,290.231934,14.785120,0.430221,-1293.506104,294.500488,0.000000
45.290001,65.007668,-1293.550537,-0.002358,0.001694,0.043022,289.168549,14.730948,0.430221,-1293.550537,294.500488,0.000000
45.570004,64.776054,-1293.461548,-0.002341,0.001694,0.043022,288.138275,14.678464,0.430221,-1293.461548,294.500488,0.000000
45.850002,64.530663,-1293.417114,-0.002345,0.001694,0.043022,287.046722,14.622857,0.430221,-1293.417114,294.500488,0.000000
46.130001,64.297554,-1293.417114,-0.002345,0.001694,0.043031,286.009796,14.570034,0.430312,-1293.417114,294.500488,0.000000
46.410004,66.368690,-1293.461548,-0.002324,0.001681,0.042701,295.222687,15.039360,0.427012,-1293.461548,294.500488,0.000000
46.690002,66.066322,-1293.550537,-0.002337,0.001681,0.042701,293.877686,14.970842,0.427012,-1293.550537,294.500488,0.000000
46.970001,65.829872,-1293.506104,-0.002333,0.001682,0.042710,292.825897,14.917262,0.427103,-1293.506104,294.500488,0.000000
47.250004,65.516701,-1293.461548,-0.002324,0.001683,0.042754,291.432831,14.846296,0.427542,-1293.461548,294.500488,0.000000
47.530003,65.286568,-1293.461548,-0.002333,0.001695,0.043040,290.409149,14.794147,0.430403,-1293.461548,294.500488,0.000000
47.810001,65.056816,-1293.506104,-0.002324,0.001699,0.043152,289.387177,14.742085,0.431523,-1293.506104,294.500488,0.000000
48.090004,65.827629,-1293.550537,-0.002328,0.001723,0.043759,292.815918,14.916754,0.437594,-1293.550537,294.500488,0.000000
48.370003,65.753899,-1293.506104,-0.002333,0.001723,0.043759,292.487946,14.900046,0.437594,-1293.506104,294.500488,0.000000
48.650002,65.536812,-1293.506104,-0.002333,0.001723,0.043759,291.522308,14.850854,0.437594,-1293.506104,294.500488,0.000000
48.930004,65.324181,-1293.506104,-0.002333,0.001723,0.043769,290.576477,14.802671,0.437685,-1293.506104,294.500488,0.000000
49.210003,65.108955,-1293.550537,-0.002324,0.001725,0.043803,289.619110,14.753900,0.438033,-1293.550537,294.500488,0.000000
49.490002,65.858162,-1293.506104,-0.002337,0.001733,0.044029,292.951721,14.923673,0.440289,-1293.506104,294.500488,0.000000
49.770000,65.668633,-1293.506104,-0.002320,0.001733,0.044029,292.108673,14.880725,0.440289,-1293.506104,294.500488,0.000000
50.050003,65.513725,-1293.417114,-0.002315,0.001733,0.044029,291.419617,14.845622,0.440289,-1293.417114,294.500488,0.000000
50.330002,65.299980,-1293.550537,-0.002315,0.001734,0.044046,290.468811,14.797187,0.440456,-1293.550537,294.500488,0.000000
50.610001,65.119759,-1293.417114,-0.002320,0.001734,0.044046,289.667145,14.756349,0.440456,-1293.417114,294.500488,0.000000
50.890003,65.673103,-1293.461548,-0.002311,0.001742,0.044255,292.128540,14.881738,0.442545,-1293.461548,294.500488,0.000000
51.170002,65.543144,-1293.417114,-0.002311,0.001742,0.044255,291.550476,14.852289,0.442545,-1293.417114,294.500488,0.000000
51.450001,65.361427,-1293.506104,-0.002311,0.001742,0.044255,290.742157,14.811111,0.442545,-1293.506104,294.500488,0.000000
51.730003,65.232201,-1293.506104,-0.002302,0.001743,0.044262,290.167328,14.781828,0.442621,-1293.506104,294.500488,0.000000
52.010002,65.276146,-1293.506104,-0.002307,0.001746,0.044357,290.362793,14.791786,0.443575,-1293.506104,294.500488,0.000000
52.290001,65.163322,-1293.506104,-0.002307,0.001747,0.044367,289.860931,14.766220,0.443665,-1293.506104,294.500488,0.000000
52.570004,65.176720,-1293.417114,-0.002311,0.001750,0.044445,289.920532,14.769256,0.444453,-1293.417114,294.500488,0.000000
52.850002,65.130180,-1293.506104,-0.002294,0.001750,0.044462,289.713501,14.758710,0.444619,-1293.506104,294.500488,0.000000
53.130001,65.245613,-1293.506104,-0.002298,0.001753,0.044522,290.226990,14.784867,0.445225,-1293.506104,294.500488,0.000000
53.410004,65.172249,-1293.550537,-0.002307,0.001754,0.044557,289.900635,14.768242,0.445573,-1293.550537,294.500488,0.000000
53.690002,65.194221,-1293.506104,-0.002302,0.001756,0.044610,289.998383,14.773222,0.446103,-1293.506104,294.500488,0.000000
53.970001,65.097038,-1293.372559,-0.002298,0.001758,0.044653,289.566101,14.751200,0.446527,-1293.372559,294.500488,0.000000
54.250004,65.086983,-1293.372559,-0.002294,0.001758,0.044662,289.521362,14.748921,0.446618,-1293.372559,294.500488,0.000000
54.530003,65.095177,-1293.461548,-0.002294,0.001760,0.044706,289.557800,14.750778,0.447057,-1293.461548,294.500488,0.000000
54.810001,65.248589,-1293.550537,-0.002294,0.001765,0.044827,290.240204,14.785542,0.448268,-1293.550537,294.500488,0.000000
55.090004,65.255302,-1293.461548,-0.002294,0.001764,0.044818,290.270081,14.787063,0.448177,-1293.461548,294.500488,0.000000
55.370003,65.122734,-1293.417114,-0.002285,0.001765,0.044827,289.680389,14.757022,0.448268,-1293.417114,294.500488,0.000000
55.650002,65.245979,-1293.461548,-0.002281,0.001768,0.044913,290.228607,14.784950,0.449131,-1293.461548,294.500488,0.000000
55.930004,65.172249,-1293.461548,-0.002289,0.001768,0.044913,289.900635,14.768242,0.449131,-1293.461548,294.500488,0.000000
56.210003,65.060539,-1293.506104,-0.002281,0.001769,0.044939,289.403748,14.742929,0.449388,-1293.506104,294.500488,0.000000
56.490002,65.095924,-1293.461548,-0.002281,0.001771,0.044983,289.561127,14.750948,0.449827,-1293.461548,294.500488,0.000000
56.770004,65.159966,-1293.417114,-0.002276,0.001773,0.045043,289.846008,14.765460,0.450433,-1293.417114,294.500488,0.000000
57.050003,65.075813,-1293.417114,-0.002276,0.001774,0.045060,289.471680,14.746390,0.450599,-1293.417114,294.500488,0.000000
57.330002,65.049370,-1293.506104,-0.002281,0.001776,0.045104,289.354034,14.740397,0.451038,-1293.506104,294.500488,0.000000
57.610004,65.141350,-1293.506104,-0.002276,0.001777,0.045148,289.763184,14.761241,0.451477,-1293.506104,294.500488,0.000000
57.890003,65.079170,-1293.417114,-0.002272,0.001778,0.045173,289.486603,14.747151,0.451735,-1293.417114,294.500488,0.000000
58.170002,65.020699,-1293.417114,-0.002276,0.001779,0.045183,289.226501,14.733901,0.451826,-1293.417114,294.500488,0.000000
58.450005,65.298485,-1293.461548,-0.002264,0.001784,0.045304,290.462158,14.796848,0.453037,-1293.461548,294.500488,0.000000
58.730003,65.236305,-1293.506104,-0.002268,0.001784,0.045304,290.185577,14.782759,0.453037,-1293.506104,294.500488,0.000000
59.010002,65.089211,-1293.506104,-0.002272,0.001784,0.045304,289.531281,14.749426,0.453037,-1293.506104,294.500488,0.000000
59.290001,65.481331,-1293.506104,-0.002272,0.001789,0.045443,291.275513,14.838282,0.454430,-1293.506104,294.500488,0.000000
59.570004,65.335350,-1293.506104,-0.002268,0.001789,0.045443,290.626160,14.805202,0.454430,-1293.506104,294.500488,0.000000
59.850002,65.238914,-1293.506104,-0.002272,0.001789,0.045443,290.197174,14.783349,0.454430,-1293.506104,294.500488,0.000000
60.130001,65.090706,-1293.506104,-0.002268,0.001790,0.045460,289.537933,14.749764,0.454596,-1293.506104,294.500488,0.000000
60.410004,65.066124,-1293.506104,-0.002255,0.001791,0.045494,289.428589,14.744194,0.454944,-1293.506104,294.500488,0.000000
60.690002,65.301094,-1293.461548,-0.002259,0.001795,0.045590,290.473785,14.797440,0.455898,-1293.461548,294.500488,0.000000
60.970001,65.245247,-1293.417114,-0.002246,0.001795,0.045590,290.225342,14.784784,0.455898,-1293.417114,294.500488,0.000000
61.250004,65.179710,-1293.461548,-0.002259,0.001795,0.045590,289.933838,14.769934,0.455898,-1293.461548,294.500488,0.000000
61.530003,65.406853,-1293.506104,-0.002255,0.001800,0.045711,290.944214,14.821404,0.457109,-1293.506104,294.500488,0.000000
61.810001,65.348381,-1293.506104,-0.002272,0.001800,0.045711,290.684113,14.808154,0.457109,-1293.506104,294.500488,0.000000
62.090004,65.258644,-1293.417114,-0.002264,0.001800,0.045711,290.284943,14.787820,0.457109,-1293.417114,294.500488,0.000000
62.370003,65.146935,-1293.461548,-0.002255,0.001800,0.045711,289.788025,14.762506,0.457109,-1293.461548,294.500488,0.000000
62.650002,65.127571,-1293.506104,-0.002242,0.001802,0.045771,289.701904,14.758119,0.457715,-1293.506104,294.500488,0.000000
62.930004,65.095924,-1293.506104,-0.002251,0.001802,0.045781,289.561127,14.750948,0.457806,-1293.506104,294.500488,0.000000
63.210003,65.259392,-1293.417114,-0.002255,0.001806,0.045885,290.288269,14.787990,0.458850,-1293.417114,294.500488,0.000000
63.490002,65.255669,-1293.461548,-0.002242,0.001806,0.045885,290.271698,14.787147,0.458850,-1293.461548,294.500488,0.000000
63.770004,65.152519,-1293.461548,-0.002242,0.001806,0.045885,289.812866,14.763772,0.458850,-1293.461548,294.500488,0.000000
64.050003,65.038948,-1293.550537,-0.002246,0.001807,0.045893,289.307678,14.738036,0.458926,-1293.550537,294.500488,0.000000
64.330002,65.180824,-1293.550537,-0.002246,0.001810,0.045971,289.938782,14.770185,0.459713,-1293.550537,294.500488,0.000000
64.610001,65.094795,-1293.417114,-0.002255,0.001810,0.045971,289.556122,14.750691,0.459713,-1293.417114,294.500488,0.000000
64.889999,65.044167,-1293.461548,-0.002238,0.001811,0.045997,289.330902,14.739220,0.459971,-1293.461548,294.500488,0.000000
65.170006,64.990532,-1293.506104,-0.002233,0.001811,0.045997,289.092316,14.727065,0.459971,-1293.506104,294.500488,0.000000
65.450005,64.911598,-1293.506104,-0.002242,0.001812,0.046015,288.741211,14.709179,0.460152,-1293.506104,294.500488,0.000000
65.730003,65.553200,-1293.550537,-0.002246,0.001819,0.046214,291.595184,14.854568,0.462136,-1293.550537,294.500488,0.000000
66.010002,65.490257,-1293.506104,-0.002220,0.001819,0.046214,291.315216,14.840305,0.462136,-1293.506104,294.500488,0.000000
66.290001,65.378181,-1293.506104,-0.002242,0.001819,0.046214,290.816681,14.814908,0.462136,-1293.506104,294.500488,0.000000
66.570000,65.275032,-1293.550537,-0.002225,0.001820,0.046223,290.357849,14.791533,0.462227,-1293.550537,294.500488,0.000000
66.850006,65.226997,-1293.506104,-0.002242,0.001821,0.046241,290.144165,14.780648,0.462408,-1293.506104,294.500488,0.000000
67.130005,65.132042,-1293.550537,-0.002238,0.001821,0.046241,289.721802,14.759132,0.462408,-1293.550537,294.500488,0.000000
67.410004,65.039696,-1293.550537,-0.002233,0.001821,0.046248,289.311005,14.738206,0.462484,-1293.550537,294.500488,0.000000
67.690002,64.959251,-1293.506104,-0.002229,0.001821,0.046257,288.953186,14.719976,0.462575,-1293.506104,294.500488,0.000000
67.970001,64.857979,-1293.461548,-0.002242,0.001822,0.046274,288.502686,14.697028,0.462741,-1293.461548,294.500488,0.000000
68.250000,64.831902,-1293.594971,-0.002229,0.001824,0.046318,288.386688,14.691119,0.463180,-1293.594971,294.500488,0.000000
68.530006,65.053093,-1293.639526,-0.002220,0.001826,0.046388,289.370605,14.741241,0.463877,-1293.639526,294.500488,0.000000
68.810005,65.002831,-1293.506104,-0.002229,0.001826,0.046388,289.147034,14.729852,0.463877,-1293.506104,294.500488,0.000000
69.090004,64.920158,-1293.550537,-0.002225,0.001826,0.046388,288.779297,14.711118,0.463877,-1293.550537,294.500488,0.000000
69.370003,64.821846,-1293.461548,-0.002207,0.001826,0.046388,288.341980,14.688841,0.463877,-1293.461548,294.500488,0.000000
69.650002,64.732109,-1293.550537,-0.002229,0.001827,0.046404,287.942810,14.668506,0.464043,-1293.550537,294.500488,0.000000
69.930000,64.935799,-1293.550537,-0.002229,0.001831,0.046509,288.848846,14.714663,0.465088,-1293.550537,294.500488,0.000000
70.210007,64.882179,-1293.461548,-0.002238,0.001831,0.046509,288.610352,14.702512,0.465088,-1293.461548,294.500488,0.000000
70.490005,64.790199,-1293.550537,-0.002225,0.001831,0.046509,288.201202,14.681668,0.465088,-1293.550537,294.500488,0.000000
70.770004,65.999672,-1293.506104,-0.002225,0.001838,0.046683,293.581207,14.955739,0.466829,-1293.506104,294.500488,0.000000
71.050003,65.826515,-1293.550537,-0.002220,0.001838,0.046683,292.810974,14.916502,0.466829,-1293.550537,294.500488,0.000000
71.330002,65.760979,-1293.550537,-0.002212,0.001838,0.046683,292.519440,14.901651,0.466829,-1293.550537,294.500488,0.000000
71.610001,65.605690,-1293.461548,-0.002207,0.001838,0.046683,291.828674,14.866462,0.466829,-1293.461548,294.500488,0.000000
71.890007,65.503288,-1293.550537,-0.002212,0.001838,0.046683,291.373169,14.843257,0.466829,-1293.550537,294.500488,0.000000
72.170006,65.341682,-1293.461548,-0.002207,0.001838,0.046683,290.654327,14.806637,0.466829,-1293.461548,294.500488,0.000000
72.450005,65.247841,-1293.550537,-0.002212,0.001839,0.046709,290.236877,14.785373,0.467086,-1293.550537,294.500488,0.000000
72.730003,65.103737,-1293.594971,-0.002216,0.001839,0.046718,289.595886,14.752718,0.467177,-1293.594971,294.500488,0.000000
73.010002,65.410576,-1293.506104,-0.002207,0.001846,0.046899,290.960785,14.822248,0.468994,-1293.506104,294.500488,0.000000
73.290001,65.346901,-1293.550537,-0.002207,0.001846,0.046899,290.677521,14.807819,0.468994,-1293.550537,294.500488,0.000000
73.570000,65.267586,-1293.594971,-0.002207,0.001846,0.046899,290.324707,14.789846,0.468994,-1293.594971,294.500488,0.000000
73.850006,65.216194,-1293.594971,-0.002212,0.001847,0.046908,290.096130,14.778201,0.469085,-1293.594971,294.500488,0.000000
74.130005,65.124596,-1293.506104,-0.002216,0.001847,0.046916,289.688660,14.757444,0.469160,-1293.506104,294.500488,0.000000
74.410004,65.225136,-1293.550537,-0.002195,0.001850,0.046986,290.135895,14.780228,0.469857,-1293.550537,294.500488,0.000000
74.690002,65.151772,-1293.506104,-0.002220,0.001850,0.046995,289.809540,14.763602,0.469948,-1293.506104,294.500488,0.000000
74.970001,65.077675,-1293.594971,-0.002212,0.001851,0.047004,289.479950,14.746812,0.470039,-1293.594971,294.500488,0.000000
75.250000,65.100395,-1293.639526,-0.002199,0.001852,0.047039,289.581024,14.751961,0.470387,-1293.639526,294.500488,0.000000
75.530006,65.054955,-1293.594971,-0.002207,0.001852,0.047046,289.378876,14.741663,0.470462,-1293.594971,294.500488,0.000000
75.810005,65.258644,-1293.550537,-0.002212,0.001858,0.047202,290.284943,14.787820,0.472022,-1293.550537,294.500488,0.000000
76.090004,65.412071,-1293.550537,-0.002190,0.001858,0.047202,290.967438,14.822587,0.472022,-1293.550537,294.500488,0.000000
76.370003,65.360298,-1293.506104,-0.002186,0.001858,0.047202,290.737122,14.810856,0.472022,-1293.506104,294.500488,0.000000
76.650002,65.303337,-1293.550537,-0.002195,0.001858,0.047202,290.483765,14.797948,0.472022,-1293.550537,294.500488,0.000000
76.930000,65.221413,-1293.594971,-0.002195,0.001858,0.047202,290.119324,14.779383,0.472022,-1293.594971,294.500488,0.000000
77.210007,65.146935,-1293.550537,-0.002203,0.001859,0.047211,289.788025,14.762506,0.472113,-1293.550537,294.500488,0.000000
77.490005,65.439613,-1293.550537,-0.002190,0.001864,0.047341,291.089935,14.828828,0.473415,-1293.550537,294.500488,0.000000
77.770004,65.415794,-1293.550537,-0.002186,0.001864,0.047341,290.983978,14.823431,0.473415,-1293.550537,294.500488,0.000000
78.050003,65.333870,-1293.594971,-0.002199,0.001864,0.047341,290.619568,14.804866,0.473415,-1293.594971,294.500488,0.000000
78.330002,65.284706,-1293.506104,-0.002199,0.001864,0.047341,290.400879,14.793726,0.473415,-1293.506104,294.500488,0.000000
78.610001,65.237801,-1293.506104,-0.002186,0.001864,0.047358,290.192230,14.783097,0.473581,-1293.506104,294.500488,0.000000
78.890007,65.178215,-1293.594971,-0.002195,0.001865,0.047367,289.927185,14.769595,0.473672,-1293.594971,294.500488,0.000000
79.170006,65.142097,-1293.639526,-0.002190,0.001869,0.047472,289.766510,14.761411,0.474717,-1293.639526,294.500488,0.000000
79.450005,65.500313,-1293.594971,-0.002190,0.001871,0.047516,291.359955,14.842584,0.475156,-1293.594971,294.500488,0.000000
79.730003,65.446693,-1293.639526,-0.002195,0.001871,0.047516,291.121429,14.830433,0.475156,-1293.639526,294.500488,0.000000
80.010002,65.373344,-1293.550537,-0.002182,0.001871,0.047516,290.795166,14.813812,0.475156,-1293.550537,294.500488,0.000000
80.290001,65.316368,-1293.594971,-0.002173,0.001871,0.047516,290.541718,14.800900,0.475156,-1293.594971,294.500488,0.000000
80.570007,65.243004,-1293.594971,-0.002177,0.001871,0.047532,290.215363,14.784276,0.475322,-1293.594971,294.500488,0.000000
80.850006,65.232201,-1293.594971,-0.002190,0.001872,0.047558,290.167328,14.781828,0.475580,-1293.594971,294.500488,0.000000
81.130005,65.186775,-1293.506104,-0.002182,0.001873,0.047576,289.965271,14.771534,0.475761,-1293.506104,294.500488,0.000000
81.410004,65.169273,-1293.550537,-0.002186,0.001873,0.047584,289.887421,14.767569,0.475837,-1293.550537,294.500488,0.000000
81.690002,65.094063,-1293.594971,-0.002173,0.001874,0.047602,289.552856,14.750525,0.476019,-1293.594971,294.500488,0.000000
81.970001,65.067986,-1293.594971,-0.002169,0.001874,0.047611,289.436859,14.744617,0.476110,-1293.594971,294.500488,0.000000
82.250008,65.269447,-1293.550537,-0.002195,0.001878,0.047714,290.333008,14.790268,0.477139,-1293.550537,294.500488,0.000000
82.530006,65.297371,-1293.550537,-0.002186,0.001878,0.047714,290.457214,14.796596,0.477139,-1293.550537,294.500488,0.000000
82.810005,65.265724,-1293.550537,-0.002182,0.001878,0.047714,290.316437,14.789425,0.477139,-1293.550537,294.500488,0.000000
83.090004,65.206139,-1293.550537,-0.002186,0.001878,0.047714,290.051392,14.775923,0.477139,-1293.550537,294.500488,0.000000
83.370003,65.129799,-1293.594971,-0.002173,0.001878,0.047714,289.711823,14.758624,0.477139,-1293.594971,294.500488,0.000000
83.650002,65.086617,-1293.594971,-0.002195,0.001881,0.047767,289.519745,14.748837,0.477669,-1293.594971,294.500488,0.000000
83.930000,65.161827,-1293.594971,-0.002182,0.001881,0.047784,289.854279,14.765881,0.477835,-1293.594971,294.500488,0.000000
84.210007,65.109322,-1293.594971,-0.002177,0.001881,0.047784,289.620728,14.753983,0.477835,-1293.594971,294.500488,0.000000
84.490005,65.069115,-1293.594971,-0.002177,0.001882,0.047809,289.441864,14.744872,0.478093,-1293.594971,294.500488,0.000000
84.770004,65.069847,-1293.639526,-0.002164,0.001883,0.047818,289.445129,14.745038,0.478184,-1293.639526,294.500488,0.000000
85.050003,65.110069,-1293.550537,-0.002169,0.001885,0.047870,289.624054,14.754152,0.478698,-1293.550537,294.500488,0.000000
85.330002,65.097404,-1293.550537,-0.002173,0.001885,0.047879,289.567719,14.751283,0.478789,-1293.550537,294.500488,0.000000
85.610001,65.076180,-1293.550537,-0.002186,0.001885,0.047888,289.473297,14.746473,0.478880,-1293.550537,294.500488,0.000000
85.890007,65.067986,-1293.639526,-0.002169,0.001886,0.047914,289.436859,14.744617,0.479137,-1293.639526,294.500488,0.000000
86.170006,65.070595,-1293.594971,-0.002173,0.001887,0.047932,289.448456,14.745208,0.479319,-1293.594971,294.500488,0.000000
86.450005,65.083626,-1293.683960,-0.002177,0.001888,0.047958,289.506439,14.748160,0.479576,-1293.683960,294.500488,0.000000
86.730003,65.207253,-1293.594971,-0.002164,0.001891,0.048027,290.056335,14.776175,0.480273,-1293.594971,294.500488,0.000000
87.010002,65.239662,-1293.639526,-0.002160,0.001891,0.048027,290.200500,14.783519,0.480273,-1293.639526,294.500488,0.000000
87.290001,65.201302,-1293.594971,-0.002164,0.001891,0.048027,290.029877,14.774826,0.480273,-1293.594971,294.500488,0.000000
87.570007,65.156242,-1293.639526,-0.002177,0.001891,0.048044,289.829437,14.764615,0.480439,-1293.639526,294.500488,0.000000
87.850006,65.114540,-1293.594971,-0.002169,0.001891,0.048044,289.643951,14.755165,0.480439,-1293.594971,294.500488,0.000000
88.130005,65.055336,-1293.550537,-0.002169,0.001892,0.048053,289.380585,14.741750,0.480530,-1293.550537,294.500488,0.000000
88.410004,65.059807,-1293.594971,-0.002173,0.001893,0.048079,289.400482,14.742763,0.480788,-1293.594971,294.500488,0.000000
88.690002,65.032616,-1293.594971,-0.002173,0.001893,0.048088,289.279510,14.736601,0.480878,-1293.594971,294.500488,0.000000
88.970001,65.122734,-1293.639526,-0.002151,0.001895,0.048139,289.680389,14.757022,0.481393,-1293.639526,294.500488,0.000000
89.250008,65.092201,-1293.594971,-0.002186,0.001895,0.048139,289.544586,14.750103,0.481393,-1293.594971,294.500488,0.000000
89.530006,65.053093,-1293.550537,-0.002160,0.001895,0.048139,289.370605,14.741241,0.481393,-1293.550537,294.500488,0.000000
89.810005,65.060539,-1293.594971,-0.002164,0.001897,0.048174,289.403748,14.742929,0.481741,-1293.594971,294.500488,0.000000
90.090004,65.024803,-1293.594971,-0.002173,0.001897,0.048183,289.244781,14.734831,0.481832,-1293.594971,294.500488,0.000000
90.370003,64.979744,-1293.639526,-0.002143,0.001897,0.048191,289.044342,14.724620,0.481908,-1293.639526,294.500488,0.000000
90.650002,65.059425,-1293.550537,-0.002164,0.001900,0.048251,289.398773,14.742677,0.482514,-1293.550537,294.500488,0.000000
90.930008,65.083260,-1293.550537,-0.002151,0.001900,0.048251,289.504791,14.748077,0.482514,-1293.550537,1681.640991,0.000000
91.210007,65.026665,-1293.639526,-0.002156,0.001890,0.048009,289.253052,14.735253,0.480091,-1293.639526,0.048251,0.000000
91.490005,64.953300,-1293.683960,-0.002164,0.001888,0.047965,288.926697,14.718629,0.479652,-1293.683960,0.047870,0.000000
91.770004,64.836754,-1293.550537,-0.002139,0.001879,0.047723,288.408295,14.692219,0.477230,-1293.550537,0.047402,0.000000
92.050003,64.710518,-1293.594971,-0.002156,0.001863,0.047316,287.846771,14.663613,0.473157,-1293.594971,0.046942,0.000000
92.330002,64.558586,-1293.550537,-0.002151,0.001847,0.046925,287.170929,14.629185,0.469251,-1293.550537,0.046474,0.000000
92.610001,64.472939,-1293.550537,-0.002134,0.001830,0.046474,286.789948,14.609776,0.464740,-1293.550537,0.046006,0.000000
92.890007,64.412239,-1293.594971,-0.002126,0.001819,0.046206,286.519958,14.596022,0.462060,-1293.594971,0.045538,0.000000
93.170006,64.332558,-1293.550537,-0.002134,0.001799,0.045685,286.165497,14.577966,0.456852,-1293.550537,0.045069,0.000000
93.450005,64.217873,-1293.550537,-0.002130,0.001779,0.045199,285.655365,14.551978,0.451992,-1293.550537,0.044601,0.000000
93.730003,64.127754,-1293.550537,-0.002139,0.001768,0.044896,285.254486,14.531557,0.448964,-1293.550537,0.044141,0.000000
94.010002,64.051781,-1293.594971,-0.002139,0.001751,0.044480,284.916565,14.514340,0.444801,-1293.594971,0.043673,0.000000
94.290001,64.020882,-1293.683960,-0.002151,0.001727,0.043855,284.779114,14.507339,0.438548,-1293.683960,0.043205,0.000000
94.570007,63.863747,-1293.594971,-0.002134,0.001710,0.043431,284.080139,14.471732,0.434309,-1293.594971,0.042736,0.000000
94.850006,63.763939,-1293.550537,-0.002143,0.001688,0.042866,283.636169,14.449115,0.428662,-1293.550537,0.042268,0.000000
95.130005,63.506630,-1293.550537,-0.002130,0.001673,0.042485,282.491608,14.390808,0.424847,-1293.550537,0.041808,0.000000
95.410004,62.916420,-1293.594971,-0.002139,0.001653,0.041982,279.866211,14.257065,0.419821,-1293.594971,0.041340,0.000000
95.690002,62.357491,-1293.594971,-0.002121,0.001642,0.041696,277.379974,14.130409,0.416959,-1293.594971,0.040872,0.000000
95.970001,61.658546,-1293.550537,-0.002126,0.001627,0.041323,274.270905,13.972027,0.413235,-1293.550537,0.040403,0.000000
96.250008,60.446846,-1293.550537,-0.002121,0.001600,0.040638,268.881012,13.697451,0.406377,-1293.550537,0.039935,0.000000
96.530006,59.613106,-1293.550537,-0.002108,0.001586,0.040291,265.172333,13.508523,0.402910,-1293.550537,0.039467,0.000000
96.810005,58.818840,-1293.506104,-0.002121,0.001574,0.039970,261.639282,13.328539,0.399700,-1293.506104,0.039007,0.000000
97.090004,57.429512,-1293.594971,-0.002126,0.001553,0.039458,255.459229,13.013714,0.394583,-1293.594971,0.038539,0.000000
97.370003,56.281494,-1293.594971,-0.002113,0.001537,0.039051,250.352585,12.753569,0.390510,-1293.594971,0.038072,0.000000
97.650002,55.057129,-1293.594971,-0.002104,0.001522,0.038670,244.906342,12.476124,0.386695,-1293.594971,0.037602,0.000000
97.930008,53.387787,-1293.594971,-0.002108,0.001502,0.038140,237.480743,12.097845,0.381396,-1293.594971,0.037134,0.000000
98.210007,52.051712,-1293.594971,-0.002108,0.001486,0.037732,231.537582,11.795087,0.377324,-1293.594971,0.036674,0.000000
98.490005,50.127663,-1293.594971,-0.002126,0.001465,0.037221,222.978973,11.359091,0.372207,-1293.594971,0.036206,0.000000
98.770004,48.338783,-1293.594971,-0.002121,0.001447,0.036753,215.021652,10.953725,0.367528,-1293.594971,0.035738,0.000000
99.050003,45.849846,-1293.550537,-0.002130,0.001422,0.036111,203.950302,10.389724,0.361109,-1293.550537,0.035269,0.000000
99.330002,44.631821,-1293.550537,-0.002121,0.001408,0.035755,198.532257,10.113715,0.357551,-1293.550537,0.034801,0.000000
99.610008,42.927841,-1293.683960,-0.002134,0.001395,0.035443,190.952576,9.727588,0.354433,-1293.683960,0.034341,0.000000
99.890007,40.772926,-1293.683960,-0.002143,0.001374,0.034906,181.367035,9.239277,0.349058,-1293.683960,0.033873,0.000000
100.170006,38.941223,-1293.506104,-0.002143,0.001355,0.034420,173.219208,8.824207,0.344198,-1293.506104,0.033405,0.000000
100.450005,37.342628,-1293.506104,-0.002147,0.001339,0.034013,166.108307,8.461960,0.340126,-1293.506104,0.032936,0.000000
100.730003,35.337776,-1293.506104,-0.002147,0.001320,0.033527,157.190277,8.007654,0.335266,-1293.506104,0.032468,0.000000
101.010002,33.055878,-1293.639526,-0.002147,0.001296,0.032929,147.039886,7.490569,0.329286,-1293.639526,0.032001,0.000000
101.290009,32.026642,-1293.550537,-0.002151,0.001287,0.032694,142.461624,7.257341,0.326939,-1293.550537,0.031540,0.000000
101.570007,30.324524,-1293.594971,-0.002160,0.001269,0.032226,134.890213,6.871635,0.322261,-1293.594971,0.031072,0.000000
101.850006,28.630974,-1293.506104,-0.002160,0.001251,0.031784,127.356934,6.487872,0.317840,-1293.506104,0.030605,0.000000
102.130005,26.961632,-1293.594971,-0.002147,0.001234,0.031340,119.931328,6.109593,0.313404,-1293.594971,0.030135,0.000000
102.410004,24.594086,-1293.639526,-0.002182,0.001209,0.030717,109.399956,5.573100,0.307167,-1293.639526,0.029668,0.000000
102.690002,22.851006,-1293.683960,-0.002177,0.001187,0.030161,101.646347,5.178112,0.301611,-1293.683960,0.029207,0.000000
102.970001,20.605232,-1293.550537,-0.002177,0.001169,0.029684,91.656654,4.669212,0.296842,-1293.550537,0.028739,0.000000
103.250008,19.364861,-1293.550537,-0.002169,0.001155,0.029330,86.139198,4.388140,0.293299,-1293.550537,0.028272,0.000000
103.530006,17.990433,-1293.594971,-0.002182,0.001141,0.028991,80.025444,4.076690,0.289908,-1293.594971,0.027802,0.000000
103.810005,16.093941,-1293.594971,-0.002177,0.001122,0.028497,71.589424,3.646939,0.284972,-1293.594971,0.027335,0.000000
104.090004,14.657326,-1293.550537,-0.002186,0.001106,0.028088,65.199043,3.321398,0.280885,-1293.550537,0.026867,0.000000
104.370003,11.785957,-1293.550537,-0.002199,0.001079,0.027395,52.426556,2.670736,0.273951,-1293.550537,0.026406,0.000000
104.650002,10.396637,-1293.639526,-0.002190,0.001066,0.027074,46.246552,2.355912,0.270741,-1293.639526,0.025939,0.000000
104.930008,8.166870,-1293.550537,-0.002212,0.001041,0.026450,36.328053,1.850639,0.264504,-1293.550537,0.025469,0.000000
105.210007,7.257538,-1293.594971,-0.002220,0.001033,0.026234,32.283142,1.644582,0.262339,-1293.594971,0.025002,0.000000
105.490005,5.540161,-1293.550537,-0.002207,0.001013,0.025722,24.643867,1.255418,0.257221,-1293.550537,0.024534,0.000000
105.770004,3.540146,-1293.594971,-0.002216,0.000991,0.025176,15.747355,0.802208,0.251756,-1293.594971,0.024073,0.000000
106.050003,1.940804,-1293.639526,-0.002225,0.000972,0.024690,8.633125,0.439792,0.246896,-1293.639526,0.023606,0.000000
106.330002,-0.074104,-1293.594971,-0.002225,0.000950,0.024134,-0.329632,-0.016792,0.241340,-1293.594971,0.023138,0.000000
106.610008,-1.242233,-1293.594971,-0.002242,0.000934,0.023736,-5.525730,-0.281494,0.237358,-1293.594971,0.022668,0.000000
106.890007,-0.287468,-1293.550537,-0.002276,0.000913,0.023180,-1.278721,-0.065141,0.231802,-1293.550537,0.022201,0.000000
107.170006,-0.057716,-1293.550537,-0.002298,0.000900,0.022859,-0.256735,-0.013079,0.228593,-1293.550537,0.021733,0.000000
107.450005,-0.052132,-1293.594971,-0.002315,0.000876,0.022261,-0.231893,-0.011813,0.222612,-1293.594971,0.021273,0.000000
107.730003,-0.071121,-1293.594971,-0.002328,0.000858,0.021801,-0.316363,-0.016116,0.218010,-1293.594971,0.020805,0.000000
108.010002,-0.072243,-1293.594971,-0.002354,0.000839,0.021317,-0.321352,-0.016370,0.213165,-1293.594971,0.020335,0.000000
108.290009,-0.076706,-1293.550537,-0.002367,0.000822,0.020874,-0.341205,-0.017382,0.208745,-1293.550537,0.019868,0.000000
108.570007,-0.067024,-1293.594971,-0.002384,0.000802,0.020379,-0.298139,-0.015188,0.203794,-1293.594971,0.019400,0.000000
108.850006,-0.037979,-1293.506104,-0.002384,0.000791,0.020102,-0.168940,-0.008606,0.201023,-1293.506104,0.018940,0.000000
109.130005,-0.035004,-1293.639526,-0.002402,0.000776,0.019703,-0.155704,-0.007932,0.197026,-1293.639526,0.018472,0.000000
109.410004,-0.048782,-1293.639526,-0.002427,0.000758,0.019244,-0.216995,-0.011054,0.192439,-1293.639526,0.018002,0.000000
109.690002,-0.048409,-1293.550537,-0.002440,0.000745,0.018923,-0.215332,-0.010970,0.189230,-1293.550537,0.017535,0.000000
109.970009,-0.065163,-1293.550537,-0.002471,0.000714,0.018125,-0.289858,-0.014766,0.181251,-1293.550537,0.017067,0.000000
110.250008,0.002975,-1293.550537,-0.002479,0.000705,0.017907,0.013236,0.000674,0.179071,-1293.550537,0.017716,0.000000
110.300003,0.001862,-1293.506104,-0.002501,0.000705,0.017907,0.008281,0.000422,0.179071,-1293.506104,0.017716,0.000000