File: Data/Sima compression/P2-11-1_10302024_164035.csv
Time (sec),S:Load (lbs),S:HL1 (DIM),S:LVDT (in),S:Position (in),Ch:Position (mm),Ch:Load (N),Ch:Stress (MPa),Ch:Strain (mm/mm),Ch:HL1 (DIM),Set Point (),Cycles ()
0.210000,-0.000374,-1293.061279,-0.007653,-0.004703,-0.119460,-0.001663,-0.000085,-1.194604,-1293.061279,-0.119522,0.000000
0.560000,-0.014153,-1293.105713,-0.007657,-0.004631,-0.117622,-0.062954,-0.003207,-1.176224,-1293.105713,-0.116815,0.000000
0.910000,-0.017502,-1293.150269,-0.007541,-0.004415,-0.112151,-0.077852,-0.003966,-1.121510,-1293.150269,-0.110972,0.000000
1.260000,0.027931,-1293.194702,-0.007295,-0.004187,-0.106357,0.124244,0.006329,-1.063571,-1293.194702,-0.105143,0.000000
1.610000,0.004471,-1293.105713,-0.007071,-0.003955,-0.100460,0.019887,0.001013,-1.004602,-1293.105713,-0.099316,0.000000
1.960000,0.008568,-1293.105713,-0.006821,-0.003725,-0.094606,0.038112,0.001941,-0.946057,-1293.105713,-0.093488,0.000000
2.310000,0.041702,-1293.061279,-0.006579,-0.003493,-0.088735,0.185501,0.009450,-0.887346,-1293.061279,-0.087660,0.000000
2.660000,0.013405,-1293.105713,-0.006351,-0.003278,-0.083254,0.059628,0.003038,-0.832541,-1293.105713,-0.081832,0.000000
3.010000,0.013405,-1293.150269,-0.006127,-0.003043,-0.077297,0.059628,0.003038,-0.772966,-1293.150269,-0.075987,0.000000
3.360000,-0.066284,-1293.105713,-0.005890,-0.002812,-0.071426,-0.294847,-0.015020,-0.714255,-1293.105713,-0.070160,0.000000
3.710000,0.011917,-1293.105713,-0.005661,-0.002580,-0.065538,0.053010,0.002700,-0.655377,-1293.105713,-0.064331,0.000000
4.060000,0.002975,-1293.061279,-0.005407,-0.002345,-0.059571,0.013236,0.000674,-0.595712,-1293.061279,-0.058504,0.000000
4.410000,0.048035,-1293.150269,-0.005195,-0.002123,-0.053933,0.213669,0.010885,-0.539332,-1293.150269,-0.052677,0.000000
4.760000,0.028297,-1293.105713,-0.004941,-0.001895,-0.048141,0.125873,0.006412,-0.481408,-1293.105713,-0.046831,0.000000
5.110000,0.001862,-1293.105713,-0.004743,-0.001664,-0.042270,0.008281,0.000422,-0.422697,-1293.105713,-0.041003,0.000000
5.460000,-0.084160,-1293.061279,-0.004471,-0.001434,-0.036415,-0.374362,-0.019071,-0.364152,-1293.061279,-0.035175,0.000000
5.810000,0.003349,-1293.061279,-0.004247,-0.001198,-0.030440,0.014898,0.000759,-0.304396,-1293.061279,-0.029348,0.000000
6.160000,0.048409,-1293.105713,-0.003997,-0.000969,-0.024612,0.215332,0.010970,-0.246124,-1293.105713,-0.023519,0.000000
6.510000,0.058090,-1293.150269,-0.003781,-0.000749,-0.019018,0.258398,0.013163,-0.190183,-1293.150269,-0.017692,0.000000
6.860000,0.013779,-1293.150269,-0.003553,-0.000517,-0.013131,0.061291,0.003122,-0.131306,-1293.150269,-0.011847,0.000000
7.210001,-0.022339,-1293.150269,-0.003324,-0.000286,-0.007276,-0.099368,-0.005062,-0.072761,-1293.150269,-0.006019,0.000000
7.560000,0.032394,-1293.105713,-0.003078,-0.000054,-0.001363,0.144098,0.007341,-0.013626,-1293.105713,-0.000192,0.000000
7.910000,0.248001,-1293.105713,-0.003035,-0.000008,-0.000191,1.103164,0.056198,-0.001908,-1293.105713,0.000061,0.000000
8.260000,0.135170,-1293.105713,-0.003040,-0.000008,-0.000191,0.601266,0.030630,-0.001908,-1293.105713,0.000269,0.000000
8.610001,0.106499,-1293.061279,-0.003031,-0.000007,-0.000182,0.473730,0.024133,-0.001817,-1293.061279,0.000858,0.000000
8.960000,0.320984,-1293.150269,-0.003018,0.000022,0.000565,1.427808,0.072736,0.005647,-1293.150269,0.001440,0.000000
9.310000,0.471420,-1293.061279,-0.003018,0.000038,0.000954,2.096982,0.106825,0.009538,-1293.061279,0.002021,0.000000
9.660001,0.793526,-1293.061279,-0.003005,0.000072,0.001839,3.529778,0.179815,0.018395,-1293.061279,0.002602,0.000000
10.010000,1.067223,-1293.150269,-0.002966,0.000093,0.002359,4.747243,0.241836,0.023587,-1293.150269,0.003191,0.000000
10.360001,1.380386,-1293.105713,-0.002949,0.000113,0.002863,6.140265,0.312800,0.028629,-1293.105713,0.003773,0.000000
10.710000,1.884949,-1293.105713,-0.002923,0.000138,0.003512,8.384670,0.427135,0.035124,-1293.105713,0.004354,0.000000
11.060000,2.205559,-1293.150269,-0.002910,0.000154,0.003920,9.810816,0.499787,0.039196,-1293.150269,0.004943,0.000000
11.410001,2.613686,-1293.105713,-0.002906,0.000174,0.004415,11.626254,0.592270,0.044147,-1293.105713,0.005524,0.000000
11.760000,3.383377,-1293.105713,-0.002863,0.000207,0.005247,15.050013,0.766684,0.052474,-1293.105713,0.006106,0.000000
12.110001,3.757240,-1293.061279,-0.002846,0.000227,0.005759,16.713039,0.851403,0.057591,-1293.061279,0.006687,0.000000
12.460001,4.176903,-1293.061279,-0.002820,0.000247,0.006271,18.579792,0.946500,0.062708,-1293.061279,0.007276,0.000000
12.810000,4.920532,-1293.105713,-0.002807,0.000274,0.006955,21.887621,1.115009,0.069551,-1293.105713,0.007857,0.000000
13.160001,5.215446,-1293.061279,-0.002794,0.000291,0.007390,23.199465,1.181837,0.073896,-1293.061279,0.008439,0.000000
13.510000,6.042114,-1293.016724,-0.002759,0.000319,0.008109,26.876667,1.369163,0.081088,-1293.016724,0.009020,0.000000
13.860001,6.483376,-1293.061279,-0.002742,0.000342,0.008690,28.839495,1.469154,0.086901,-1293.061279,0.009609,0.000000
14.210001,6.904160,-1293.105713,-0.002721,0.000363,0.009218,30.711235,1.564505,0.092185,-1293.105713,0.010190,0.000000
14.560000,7.527512,-1293.061279,-0.002708,0.000389,0.009879,33.484043,1.705759,0.098786,-1293.061279,0.010772,0.000000
14.910001,7.889084,-1293.061279,-0.002682,0.000408,0.010365,35.092396,1.787692,0.103646,-1293.061279,0.011353,0.000000
15.260001,8.339279,-1293.061279,-0.002652,0.000429,0.010902,37.094967,1.889708,0.109020,-1293.061279,0.011942,0.000000
15.610001,8.929489,-1293.061279,-0.002613,0.000460,0.011674,39.720352,2.023451,0.116741,-1293.061279,0.012523,0.000000
15.960001,9.135040,-1293.105713,-0.002600,0.000480,0.012193,40.634689,2.070030,0.121934,-1293.105713,0.013105,0.000000
16.310001,9.577423,-1293.016724,-0.002578,0.000504,0.012801,42.602505,2.170275,0.128005,-1293.016724,0.013694,0.000000
16.660000,9.947556,-1293.061279,-0.002548,0.000525,0.013338,44.248936,2.254148,0.133380,-1293.061279,0.014275,0.000000
17.010000,9.859680,-1293.061279,-0.002527,0.000541,0.013747,43.858047,2.234235,0.137467,-1293.061279,0.014856,0.000000
17.360001,10.615967,-1293.150269,-0.002501,0.000574,0.014570,47.222179,2.405612,0.145703,-1293.150269,0.015438,0.000000
17.710001,10.855026,-1293.061279,-0.002479,0.000596,0.015134,48.285568,2.459784,0.151335,-1293.061279,0.016027,0.000000
18.060001,11.018127,-1293.016724,-0.002453,0.000618,0.015706,49.011078,2.496743,0.157058,-1293.016724,0.016608,0.000000
18.410002,11.287354,-1293.061279,-0.002423,0.000642,0.016296,50.208656,2.557751,0.162962,-1293.061279,0.017189,0.000000
18.760000,11.355873,-1292.972290,-0.002384,0.000661,0.016790,50.513447,2.573277,0.167898,-1292.972290,0.017769,0.000000
19.110001,11.451942,-1293.061279,-0.002376,0.000679,0.017241,50.940784,2.595047,0.172410,-1293.061279,0.018360,0.000000
19.460001,12.084229,-1292.972290,-0.002345,0.000710,0.018022,53.753334,2.738325,0.180222,-1292.972290,0.018941,0.000000
19.810001,12.075668,-1293.105713,-0.002302,0.000732,0.018602,53.715256,2.736386,0.186020,-1293.105713,0.019522,0.000000
20.160002,12.155724,-1293.016724,-0.002276,0.000755,0.019167,54.071358,2.754526,0.191667,-1293.016724,0.020111,0.000000
20.510000,12.264458,-1293.061279,-0.002255,0.000778,0.019765,54.555031,2.779166,0.197647,-1293.061279,0.020693,0.000000
20.860001,12.235786,-1293.061279,-0.002238,0.000797,0.020242,54.427498,2.772669,0.202416,-1293.061279,0.021274,0.000000
21.210001,12.226105,-1293.016724,-0.002199,0.000814,0.020684,54.384430,2.770475,0.206837,-1293.016724,0.021854,0.000000
21.560001,12.649864,-1293.016724,-0.002169,0.000840,0.021335,56.269405,2.866500,0.213347,-1293.016724,0.022444,0.000000
21.910002,12.785034,-1293.016724,-0.002151,0.000866,0.022002,56.870674,2.897130,0.220024,-1293.016724,0.023026,0.000000
22.260000,12.699394,-1293.016724,-0.002108,0.000883,0.022426,56.489727,2.877724,0.224263,-1293.016724,0.023607,0.000000
22.610001,13.149963,-1293.016724,-0.002087,0.000912,0.023173,58.493958,2.979824,0.231726,-1293.016724,0.024187,0.000000
22.960001,13.174538,-1293.016724,-0.002044,0.000930,0.023633,58.603271,2.985393,0.236329,-1293.016724,0.024777,0.000000
23.310001,13.349182,-1292.972290,-0.002031,0.000955,0.024248,59.380127,3.024968,0.242476,-1292.972290,0.025359,0.000000
23.660002,13.483238,-1293.016724,-0.001983,0.000980,0.024882,59.976440,3.055346,0.248819,-1293.016724,0.025939,0.000000
24.010000,13.523453,-1293.016724,-0.001983,0.001003,0.025471,60.155323,3.064458,0.254708,-1293.016724,0.026520,0.000000
24.360001,13.459404,-1293.061279,-0.001940,0.001020,0.025896,59.870419,3.049945,0.258963,-1293.061279,0.027110,0.000000
24.710001,13.939392,-1293.061279,-0.001914,0.001050,0.026668,62.005512,3.158711,0.266684,-1293.061279,0.027690,0.000000
25.060001,13.855606,-1293.061279,-0.001884,0.001068,0.027127,61.632812,3.139725,0.271271,-1293.061279,0.028272,0.000000
25.410002,14.366875,-1293.016724,-0.001858,0.001100,0.027943,63.907051,3.255580,0.279431,-1293.016724,0.028862,0.000000
25.760002,14.241013,-1293.061279,-0.001819,0.001121,0.028462,63.347187,3.227059,0.284624,-1293.061279,0.029443,0.000000
26.110001,14.258888,-1293.061279,-0.001789,0.001141,0.028983,63.426704,3.231110,0.289832,-1293.061279,0.030023,0.000000
26.460001,14.386612,-1293.061279,-0.001776,0.001163,0.029530,63.994846,3.260053,0.295298,-1293.061279,0.030605,0.000000
26.810001,14.652115,-1293.016724,-0.001738,0.001186,0.030128,65.175865,3.320217,0.301278,-1293.016724,0.031195,0.000000
27.160002,15.028954,-1293.016724,-0.001703,0.001214,0.030830,66.852127,3.405610,0.308302,-1293.016724,0.031775,0.000000
27.510002,15.006241,-1293.016724,-0.001673,0.001238,0.031437,66.751091,3.400463,0.314373,-1293.016724,0.032356,0.000000
27.860001,15.020760,-1293.061279,-0.001643,0.001258,0.031966,66.815674,3.403753,0.319657,-1293.061279,0.032938,0.000000
28.210001,15.207321,-1293.016724,-0.001613,0.001281,0.032530,67.645546,3.446028,0.325304,-1293.016724,0.033528,0.000000
28.560001,15.065445,-1293.016724,-0.001587,0.001297,0.032938,67.014442,3.413879,0.329377,-1293.016724,0.034108,0.000000
28.910002,15.612091,-1292.972290,-0.001565,0.001324,0.033631,69.446053,3.537750,0.336311,-1292.972290,0.034689,0.000000
29.260002,15.991905,-1293.016724,-0.001531,0.001353,0.034359,71.135544,3.623817,0.343593,-1293.016724,0.035280,0.000000
29.610001,15.831039,-1292.972290,-0.001505,0.001372,0.034854,70.419983,3.587365,0.348543,-1292.972290,0.035860,0.000000
29.960001,15.713745,-1293.016724,-0.001470,0.001391,0.035322,69.898232,3.560786,0.353222,-1293.016724,0.036441,0.000000
30.310001,16.319221,-1293.016724,-0.001457,0.001418,0.036017,72.591522,3.697989,0.360171,-1293.016724,0.037022,0.000000
30.660002,16.359810,-1293.016724,-0.001423,0.001436,0.036467,72.772072,3.707186,0.364667,-1293.016724,0.037613,0.000000
31.010002,17.052055,-1293.016724,-0.001397,0.001470,0.037343,75.851334,3.864051,0.373433,-1293.016724,0.038193,0.000000
31.360001,16.928795,-1293.061279,-0.001354,0.001491,0.037872,75.303040,3.836120,0.378717,-1293.061279,0.038774,0.000000
31.710001,16.751175,-1293.061279,-0.001332,0.001511,0.038383,74.512947,3.795871,0.383834,-1293.061279,0.039355,0.000000
32.060001,17.176796,-1293.061279,-0.001302,0.001537,0.039034,76.406204,3.892318,0.390344,-1293.061279,0.039944,0.000000
32.410000,16.955978,-1293.016724,-0.001285,0.001553,0.039451,75.423958,3.842280,0.394507,-1293.016724,0.040526,0.000000
32.760002,17.075142,-1293.016724,-0.001263,0.001572,0.039937,75.954025,3.869282,0.399367,-1293.016724,0.041107,0.000000
33.110001,17.901436,-1293.016724,-0.001220,0.001606,0.040786,79.629562,4.056523,0.407860,-1293.016724,0.041688,0.000000
33.460003,17.818024,-1293.105713,-0.001199,0.001626,0.041298,79.258530,4.037622,0.412977,-1293.105713,0.042277,0.000000
33.810001,17.891754,-1293.016724,-0.001186,0.001649,0.041879,79.586494,4.054329,0.418791,-1293.016724,0.042859,0.000000
34.160000,18.300613,-1293.105713,-0.001130,0.001675,0.042547,81.405197,4.146978,0.425468,-1293.105713,0.043440,0.000000
34.510002,18.184067,-1293.061279,-0.001117,0.001691,0.042963,80.886772,4.120568,0.429631,-1293.061279,0.044029,0.000000
34.860001,18.773529,-1293.016724,-0.001095,0.001719,0.043666,83.508827,4.254142,0.436656,-1293.016724,0.044610,0.000000
35.210003,18.929924,-1293.105713,-0.001061,0.001743,0.044282,84.204506,4.289582,0.442818,-1293.105713,0.045192,0.000000
35.560001,18.903488,-1293.105713,-0.001039,0.001762,0.044750,84.086914,4.283592,0.447496,-1293.105713,0.045773,0.000000
35.910000,19.396881,-1292.972290,-0.001009,0.001788,0.045408,86.281639,4.395396,0.454081,-1292.972290,0.046362,0.000000
36.260002,19.373795,-1293.016724,-0.000974,0.001806,0.045885,86.178940,4.390164,0.458850,-1293.016724,0.046943,0.000000
36.610001,19.649719,-1293.016724,-0.000957,0.001827,0.046415,87.406319,4.452690,0.464149,-1293.016724,0.047525,0.000000
36.960003,20.347923,-1293.016724,-0.000923,0.001860,0.047255,90.512085,4.610905,0.472552,-1293.016724,0.048106,0.000000
37.310001,20.249245,-1293.016724,-0.000897,0.001882,0.047793,90.073135,4.588545,0.477926,-1293.016724,0.048695,0.000000
37.660004,20.518097,-1293.061279,-0.000875,0.001902,0.048323,91.269051,4.649467,0.483225,-1293.061279,0.049276,0.000000
38.010002,20.684921,-1293.061279,-0.000858,0.001925,0.048904,92.011124,4.687270,0.489039,-1293.061279,0.049858,0.000000
38.360001,20.985046,-1293.105713,-0.000815,0.001948,0.049467,93.346146,4.755280,0.494671,-1293.105713,0.050439,0.000000
38.710003,21.826981,-1293.105713,-0.000789,0.001975,0.050170,97.091255,4.946064,0.501695,-1293.105713,0.051028,0.000000
39.060001,21.838158,-1293.105713,-0.000776,0.001995,0.050672,97.140976,4.948597,0.506722,-1293.105713,0.051609,0.000000
39.410004,22.048920,-1293.105713,-0.000750,0.002017,0.051228,98.078491,4.996356,0.512278,-1293.105713,0.052191,0.000000
39.760002,22.394104,-1293.061279,-0.000737,0.002041,0.051852,99.613953,5.074577,0.518515,-1293.061279,0.052780,0.000000
40.110001,22.531143,-1293.105713,-0.000698,0.002060,0.052321,100.223534,5.105630,0.523209,-1293.105713,0.053361,0.000000
40.460003,22.658493,-1293.105713,-0.000677,0.002077,0.052763,100.790009,5.134488,0.527629,-1293.105713,0.053942,0.000000
40.810001,23.629265,-1293.105713,-0.000647,0.002108,0.053535,105.108223,5.354468,0.535351,-1293.105713,0.054524,0.000000
41.160004,24.007973,-1293.105713,-0.000629,0.002134,0.054194,106.792793,5.440284,0.541936,-1293.105713,0.055113,0.000000
41.510002,24.361351,-1293.061279,-0.000595,0.002158,0.054801,108.364700,5.520361,0.548007,-1293.061279,0.055694,0.000000
41.860001,24.692764,-1293.105713,-0.000578,0.002181,0.055390,109.838898,5.595460,0.553897,-1293.105713,0.056275,0.000000
42.210003,24.766121,-1293.105713,-0.000560,0.002198,0.055824,110.165207,5.612083,0.558242,-1293.105713,0.056855,0.000000
42.560001,24.776176,-1293.105713,-0.000548,0.002217,0.056301,110.209938,5.614362,0.563011,-1293.105713,0.057446,0.000000
42.910004,25.547356,-1293.105713,-0.000517,0.002240,0.056890,113.640312,5.789114,0.568900,-1293.105713,0.058027,0.000000
43.260002,26.359505,-1293.105713,-0.000496,0.002268,0.057602,117.252930,5.973149,0.576016,-1293.105713,0.058608,0.000000
43.610001,26.365829,-1293.061279,-0.000492,0.002284,0.058018,117.281067,5.974582,0.580179,-1293.061279,0.059197,0.000000
43.960003,27.409966,-1293.105713,-0.000466,0.002312,0.058729,121.925613,6.211187,0.587295,-1293.105713,0.059779,0.000000
44.310001,27.648285,-1293.150269,-0.000448,0.002330,0.059188,122.985710,6.265191,0.591882,-1293.150269,0.060360,0.000000
44.660004,28.377388,-1293.150269,-0.000418,0.002355,0.059813,126.228928,6.430408,0.598135,-1293.150269,0.060940,0.000000
45.010002,29.129951,-1293.105713,-0.000384,0.002382,0.060498,129.576492,6.600942,0.604978,-1293.105713,0.061530,0.000000
45.360001,29.599884,-1293.150269,-0.000379,0.002403,0.061035,131.666855,6.707429,0.610352,-1293.150269,0.062112,0.000000
45.710003,29.755913,-1293.061279,-0.000358,0.002418,0.061417,132.360916,6.742786,0.614167,-1293.061279,0.062693,0.000000
46.060001,31.117676,-1293.105713,-0.000332,0.002450,0.062242,138.418335,7.051366,0.622418,-1293.105713,0.063273,0.000000
46.410004,31.742516,-1293.105713,-0.000306,0.002471,0.062770,141.197754,7.192957,0.627702,-1293.105713,0.063863,0.000000
46.760002,32.875275,-1293.194702,-0.000285,0.002500,0.063491,146.236526,7.449644,0.634909,-1293.194702,0.064445,0.000000
47.110001,33.277435,-1293.105713,-0.000263,0.002520,0.064010,148.025421,7.540774,0.640101,-1293.105713,0.065024,0.000000
47.460003,33.800247,-1293.105713,-0.000272,0.002540,0.064505,150.351013,7.659245,0.645052,-1293.105713,0.065606,0.000000
47.810001,34.558769,-1293.061279,-0.000237,0.002560,0.065034,153.725082,7.831129,0.650336,-1293.061279,0.066196,0.000000
48.160004,35.582054,-1293.105713,-0.000229,0.002586,0.065675,158.276886,8.063008,0.656755,-1293.105713,0.066776,0.000000
48.510002,36.990738,-1293.016724,-0.000211,0.002616,0.066439,164.543015,8.382221,0.664385,-1293.016724,0.067358,0.000000
48.860001,37.799530,-1293.061279,-0.000203,0.002638,0.066994,168.140701,8.565495,0.669942,-1293.061279,0.067948,0.000000
49.210003,38.512993,-1293.061279,-0.000172,0.002658,0.067513,171.314346,8.727169,0.675134,-1293.061279,0.068529,0.000000
49.560001,39.437225,-1293.105713,-0.000155,0.002679,0.068052,175.425537,8.936604,0.680524,-1293.105713,0.069109,0.000000
49.910004,40.026688,-1293.150269,-0.000142,0.002698,0.068537,178.047592,9.070177,0.685369,-1293.150269,0.069691,0.000000
50.260002,41.676300,-1293.105713,-0.000138,0.002724,0.069197,185.385437,9.443985,0.691970,-1293.105713,0.070281,0.000000
50.610001,43.272659,-1293.061279,-0.000116,0.002752,0.069907,192.486404,9.805725,0.699070,-1293.061279,0.070861,0.000000
50.960003,43.945908,-1293.105713,-0.000095,0.002772,0.070402,195.481155,9.958285,0.704021,-1293.105713,0.071442,0.000000
51.310001,45.018341,-1293.105713,-0.000108,0.002792,0.070914,200.251587,10.201303,0.709138,-1293.105713,0.072024,0.000000
51.660004,46.540970,-1293.150269,-0.000073,0.002817,0.071547,207.024567,10.546334,0.715466,-1293.150269,0.072614,0.000000
52.010002,47.634628,-1293.061279,-0.000073,0.002837,0.072067,211.889404,10.794161,0.720674,-1293.061279,0.073194,0.000000
52.360001,49.847641,-1293.105713,-0.000039,0.002870,0.072908,221.733383,11.295637,0.729077,-1293.105713,0.073775,0.000000
52.710003,51.042213,-1293.105713,-0.000052,0.002890,0.073403,227.047104,11.566331,0.734027,-1293.105713,0.074366,0.000000
53.060001,52.019691,-1293.105713,-0.000039,0.002910,0.073905,231.395142,11.787831,0.739054,-1293.105713,0.074945,0.000000
53.410004,53.887512,-1293.105713,-0.000030,0.002935,0.074547,239.703629,12.211084,0.745473,-1293.105713,0.075527,0.000000
53.760002,54.777107,-1293.150269,-0.000004,0.002951,0.074955,243.660736,12.412670,0.749545,-1293.150269,0.076108,0.000000
54.110004,55.785492,-1293.194702,-0.000004,0.002971,0.075457,248.146255,12.641172,0.754572,-1293.194702,0.076699,0.000000
54.460003,58.431946,-1293.150269,0.000000,0.003003,0.076264,259.918274,13.240869,0.762641,-1293.150269,0.077278,0.000000
54.810001,59.947128,-1293.150269,0.000013,0.003024,0.076820,266.658142,13.584214,0.768197,-1293.150269,0.077860,0.000000
55.160004,61.347244,-1293.150269,0.000039,0.003047,0.077383,272.886169,13.901484,0.773829,-1293.150269,0.078441,0.000000
55.510002,63.362892,-1293.105713,0.000034,0.003073,0.078042,281.852234,14.358236,0.780415,-1293.105713,0.079030,0.000000
55.860004,64.521721,-1293.150269,0.000060,0.003090,0.078485,287.006958,14.620831,0.784851,-1293.150269,0.079611,0.000000
56.210003,66.374641,-1293.150269,0.000039,0.003106,0.078883,295.249146,15.040709,0.788833,-1293.150269,0.079092,0.000000
56.560001,65.565102,-1293.194702,0.000056,0.003104,0.078848,291.648132,14.857265,0.788484,-1293.194702,291.881683,0.000000
56.910004,65.411324,-1293.194702,0.000065,0.003115,0.079118,290.964111,14.822417,0.791179,-1293.194702,294.500488,0.000000
57.260002,65.211723,-1293.150269,0.000082,0.003116,0.079153,290.076233,14.777188,0.791528,-1293.150269,294.500488,0.000000
57.610004,65.360298,-1293.105713,0.000073,0.003122,0.079309,290.737122,14.810856,0.793087,-1293.105713,294.500488,0.000000
57.960003,65.191612,-1293.105713,0.000086,0.003122,0.079309,289.986786,14.772631,0.793087,-1293.105713,294.500488,0.000000
58.310001,65.292534,-1293.105713,0.000082,0.003127,0.079430,290.435699,14.795500,0.794298,-1293.105713,294.500488,0.000000
58.660004,65.091820,-1293.150269,0.000078,0.003129,0.079465,289.542877,14.750017,0.794646,-1293.150269,294.500488,0.000000
59.010002,65.315620,-1293.194702,0.000091,0.003133,0.079569,290.538391,14.800731,0.795691,-1293.194702,294.500488,0.000000
59.360004,65.219917,-1293.239136,0.000073,0.003133,0.079586,290.112671,14.779044,0.795857,-1293.239136,294.500488,0.000000
59.710003,65.297752,-1293.194702,0.000086,0.003137,0.079681,290.458923,14.796682,0.796811,-1293.194702,294.500488,0.000000
60.060001,65.201668,-1293.150269,0.000091,0.003137,0.079681,290.031494,14.774909,0.796811,-1293.150269,294.500488,0.000000
60.410004,65.236671,-1293.194702,0.000082,0.003140,0.079760,290.187195,14.782842,0.797598,-1293.194702,294.500488,0.000000
60.760002,65.199074,-1293.194702,0.000082,0.003141,0.079786,290.019958,14.774321,0.797856,-1293.194702,294.500488,0.000000
61.110004,65.231834,-1293.194702,0.000091,0.003143,0.079837,290.165680,14.781745,0.798371,-1293.194702,294.500488,0.000000
61.460003,65.221031,-1293.194702,0.000095,0.003145,0.079872,290.117645,14.779297,0.798719,-1293.194702,294.500488,0.000000
61.810001,65.192741,-1293.194702,0.000091,0.003147,0.079942,289.991791,14.772886,0.799415,-1293.194702,294.500488,0.000000
62.160004,65.319710,-1293.239136,0.000095,0.003148,0.079958,290.556580,14.801658,0.799582,-1293.239136,294.500488,0.000000
62.510002,65.256783,-1293.061279,0.000103,0.003148,0.079958,290.276672,14.787398,0.799582,-1293.061279,294.500488,0.000000
62.860004,65.228477,-1293.194702,0.000099,0.003149,0.079993,290.150757,14.780985,0.799930,-1293.194702,294.500488,0.000000
63.210003,65.212837,-1293.150269,0.000095,0.003150,0.080019,290.081177,14.777440,0.800187,-1293.150269,294.500488,0.000000
63.560001,65.208382,-1293.239136,0.000095,0.003152,0.080072,290.061371,14.776431,0.800717,-1293.239136,294.500488,0.000000
63.910004,65.255669,-1293.150269,0.000103,0.003153,0.080081,290.271698,14.787147,0.800808,-1293.150269,294.500488,0.000000
64.260002,65.234444,-1293.150269,0.000099,0.003153,0.080097,290.177307,14.782336,0.800975,-1293.150269,294.500488,0.000000
64.610001,65.198692,-1293.239136,0.000099,0.003154,0.080114,290.018280,14.774235,0.801141,-1293.239136,294.500488,0.000000
64.960007,65.144325,-1293.194702,0.000112,0.003154,0.080114,289.776428,14.761915,0.801141,-1293.194702,294.500488,0.000000
65.310005,65.275780,-1293.194702,0.000091,0.003158,0.080219,290.361176,14.791703,0.802186,-1293.194702,294.500488,0.000000
65.660004,65.358437,-1293.150269,0.000103,0.003158,0.080219,290.728851,14.810433,0.802186,-1293.150269,294.500488,0.000000
66.010002,65.342430,-1293.239136,0.000112,0.003158,0.080219,290.657654,14.806807,0.802186,-1293.239136,294.500488,0.000000
66.360001,65.286568,-1293.194702,0.000091,0.003158,0.080219,290.409149,14.794147,0.802186,-1293.194702,294.500488,0.000000
66.710007,65.243385,-1293.194702,0.000116,0.003159,0.080228,290.217072,14.784363,0.802277,-1293.194702,294.500488,0.000000
67.060005,65.202049,-1293.194702,0.000103,0.003159,0.080228,290.033203,14.774996,0.802277,-1293.194702,294.500488,0.000000
67.410004,65.140236,-1293.194702,0.000108,0.003159,0.080244,289.758240,14.760988,0.802443,-1293.194702,294.500488,0.000000
67.760002,65.120491,-1293.194702,0.000121,0.003160,0.080253,289.670410,14.756514,0.802534,-1293.194702,294.500488,0.000000
68.110001,65.085487,-1293.194702,0.000112,0.003160,0.080262,289.514709,14.748582,0.802625,-1293.194702,294.500488,0.000000
68.460007,65.101509,-1293.194702,0.000103,0.003161,0.080297,289.585968,14.752213,0.802973,-1293.194702,294.500488,0.000000
68.810005,65.102257,-1293.194702,0.000108,0.003162,0.080305,289.589294,14.752382,0.803049,-1293.194702,294.500488,0.000000
69.160004,65.136879,-1293.194702,0.000112,0.003163,0.080340,289.743317,14.760228,0.803397,-1293.194702,294.500488,0.000000
69.510002,65.134651,-1293.150269,0.000116,0.003163,0.080340,289.733398,14.759723,0.803397,-1293.150269,294.500488,0.000000
69.860001,65.109322,-1293.194702,0.000116,0.003163,0.080340,289.620728,14.753983,0.803397,-1293.194702,294.500488,0.000000
70.210007,65.500694,-1293.194702,0.000125,0.003168,0.080479,291.361633,14.842669,0.804790,-1293.194702,294.500488,0.000000
70.560005,65.526756,-1293.194702,0.000121,0.003168,0.080470,291.477570,14.848576,0.804699,-1293.194702,294.500488,0.000000
70.910004,65.519676,-1293.239136,0.000108,0.003168,0.080470,291.446075,14.846972,0.804699,-1293.239136,294.500488,0.000000
71.260002,65.497704,-1293.239136,0.000108,0.003168,0.080470,291.348328,14.841991,0.804699,-1293.239136,294.500488,0.000000
71.610001,65.475746,-1293.239136,0.000121,0.003168,0.080470,291.250671,14.837016,0.804699,-1293.239136,294.500488,0.000000
71.960007,65.412437,-1293.239136,0.000121,0.003168,0.080470,290.969055,14.822670,0.804699,-1293.239136,294.500488,0.000000
72.310005,65.372963,-1293.239136,0.000116,0.003168,0.080470,290.793457,14.813725,0.804699,-1293.239136,294.500488,0.000000
72.660004,65.340569,-1293.239136,0.000112,0.003168,0.080470,290.649353,14.806384,0.804699,-1293.239136,294.500488,0.000000
73.010002,65.320091,-1293.239136,0.000116,0.003168,0.080479,290.558289,14.801744,0.804790,-1293.239136,294.500488,0.000000
73.360001,65.286201,-1293.239136,0.000121,0.003168,0.080479,290.407532,14.794065,0.804790,-1293.239136,294.500488,0.000000
73.710007,65.258278,-1293.283691,0.000108,0.003168,0.080479,290.283325,14.787737,0.804790,-1293.283691,294.500488,0.000000
74.060005,65.203529,-1293.239136,0.000116,0.003169,0.080488,290.039795,14.775331,0.804881,-1293.239136,294.500488,0.000000
74.410004,65.188271,-1293.283691,0.000129,0.003169,0.080488,289.971924,14.771873,0.804881,-1293.283691,294.500488,0.000000
74.760002,65.193855,-1293.283691,0.000116,0.003169,0.080505,289.996765,14.773139,0.805047,-1293.283691,294.500488,0.000000
75.110001,65.216942,-1293.239136,0.000116,0.003171,0.080540,290.099457,14.778370,0.805395,-1293.239136,294.500488,0.000000
75.460007,65.223274,-1293.239136,0.000121,0.003171,0.080540,290.127625,14.779805,0.805395,-1293.239136,294.500488,0.000000
75.810005,65.213219,-1293.239136,0.000112,0.003171,0.080540,290.082886,14.777527,0.805395,-1293.239136,294.500488,0.000000
76.160004,65.188637,-1293.239136,0.000116,0.003171,0.080540,289.973541,14.771956,0.805395,-1293.239136,294.500488,0.000000
76.510002,65.165184,-1293.283691,0.000129,0.003171,0.080540,289.869202,14.766642,0.805395,-1293.283691,294.500488,0.000000
76.860001,65.128685,-1293.283691,0.000116,0.003171,0.080540,289.706848,14.758371,0.805395,-1293.283691,294.500488,0.000000
77.210007,65.102623,-1293.283691,0.000112,0.003171,0.080540,289.590942,14.752465,0.805395,-1293.283691,294.500488,0.000000
77.560005,65.069481,-1293.328125,0.000116,0.003171,0.080540,289.443512,14.744955,0.805395,-1293.328125,294.500488,0.000000
77.910004,65.046394,-1293.283691,0.000112,0.003171,0.080540,289.340820,14.739723,0.805395,-1293.283691,294.500488,0.000000
78.260002,65.032982,-1293.283691,0.000108,0.003172,0.080565,289.281158,14.736685,0.805653,-1293.283691,294.500488,0.000000
78.610001,65.514091,-1293.283691,0.000112,0.003178,0.080714,291.421234,14.845706,0.807136,-1293.283691,294.500488,0.000000
78.960007,65.555428,-1293.239136,0.000112,0.003177,0.080705,291.605103,14.855073,0.807046,-1293.239136,294.500488,0.000000
79.310005,65.561012,-1293.328125,0.000125,0.003177,0.080705,291.629944,14.856339,0.807046,-1293.328125,294.500488,0.000000
79.660004,65.558403,-1293.283691,0.000116,0.003177,0.080705,291.618347,14.855746,0.807046,-1293.283691,294.500488,0.000000
80.010002,65.537178,-1293.283691,0.000121,0.003177,0.080705,291.523926,14.850937,0.807046,-1293.283691,294.500488,0.000000
80.360001,65.520058,-1293.239136,0.000112,0.003177,0.080705,291.447784,14.847057,0.807046,-1293.239136,294.500488,0.000000
80.710007,65.499565,-1293.283691,0.000129,0.003177,0.080705,291.356628,14.842414,0.807046,-1293.283691,294.500488,0.000000
81.060005,65.490639,-1293.283691,0.000121,0.003177,0.080705,291.316925,14.840391,0.807046,-1293.283691,294.500488,0.000000
81.410004,65.471642,-1293.283691,0.000108,0.003177,0.080705,291.232422,14.836086,0.807046,-1293.283691,294.500488,0.000000
81.760002,65.436638,-1293.328125,0.000103,0.003177,0.080705,291.076691,14.828155,0.807046,-1293.328125,294.500488,0.000000
82.110001,65.396049,-1293.328125,0.000116,0.003177,0.080705,290.896149,14.818957,0.807046,-1293.328125,294.500488,0.000000
82.460007,65.378548,-1293.283691,0.000125,0.003177,0.080705,290.818298,14.814991,0.807046,-1293.283691,294.500488,0.000000
82.810005,65.352486,-1293.328125,0.000121,0.003178,0.080714,290.702362,14.809085,0.807136,-1293.328125,294.500488,0.000000
83.160004,65.330513,-1293.328125,0.000103,0.003178,0.080714,290.604645,14.804106,0.807136,-1293.328125,294.500488,0.000000
83.510002,65.309654,-1293.372559,0.000112,0.003178,0.080714,290.511841,14.799379,0.807136,-1293.372559,294.500488,0.000000
83.860001,65.293648,-1293.283691,0.000121,0.003178,0.080714,290.440643,14.795753,0.807136,-1293.283691,294.500488,0.000000
84.210007,65.289177,-1293.283691,0.000125,0.003178,0.080714,290.420776,14.794740,0.807136,-1293.283691,294.500488,0.000000
84.560005,65.260139,-1293.328125,0.000138,0.003178,0.080714,290.291595,14.788159,0.807136,-1293.328125,294.500488,0.000000
84.910004,65.240395,-1293.283691,0.000121,0.003178,0.080714,290.203766,14.783685,0.807136,-1293.283691,294.500488,0.000000
85.260002,65.226250,-1293.283691,0.000103,0.003178,0.080714,290.140839,14.780479,0.807136,-1293.283691,294.500488,0.000000
85.610001,65.203529,-1293.328125,0.000116,0.003178,0.080714,290.039795,14.775331,0.807136,-1293.328125,294.500488,0.000000
85.960007,65.177101,-1293.283691,0.000116,0.003178,0.080714,289.922211,14.769342,0.807136,-1293.283691,294.500488,0.000000
86.310005,65.152885,-1293.239136,0.000121,0.003178,0.080714,289.814514,14.763855,0.807136,-1293.239136,294.500488,0.000000
86.660004,65.123848,-1293.328125,0.000121,0.003178,0.080721,289.685333,14.757275,0.807212,-1293.328125,294.500488,0.000000
87.010002,65.102989,-1293.328125,0.000125,0.003178,0.080730,289.592560,14.752548,0.807303,-1293.328125,294.500488,0.000000
87.360001,65.667137,-1293.239136,0.000108,0.003184,0.080886,292.102020,14.880386,0.808862,-1293.239136,294.500488,0.000000
87.710007,65.663414,-1293.283691,0.000116,0.003184,0.080886,292.085449,14.879542,0.808862,-1293.283691,294.500488,0.000000
88.060005,65.666771,-1293.328125,0.000116,0.003184,0.080886,292.100372,14.880303,0.808862,-1293.328125,294.500488,0.000000
88.410004,65.675697,-1293.283691,0.000112,0.003184,0.080886,292.140106,14.882326,0.808862,-1293.283691,294.500488,0.000000
88.760002,65.661186,-1293.417114,0.000134,0.003184,0.080886,292.075531,14.879038,0.808862,-1293.417114,294.500488,0.000000
89.110001,65.606819,-1293.328125,0.000121,0.003184,0.080886,291.833710,14.866717,0.808862,-1293.328125,294.500488,0.000000
89.460007,65.610909,-1293.283691,0.000116,0.003184,0.080886,291.851898,14.867644,0.808862,-1293.283691,294.500488,0.000000
89.810005,65.603828,-1293.283691,0.000129,0.003184,0.080886,291.820404,14.866040,0.808862,-1293.283691,294.500488,0.000000
90.160004,65.604576,-1293.328125,0.000125,0.003184,0.080886,291.823730,14.866209,0.808862,-1293.328125,294.500488,0.000000
90.510002,65.589317,-1293.283691,0.000121,0.003184,0.080886,291.755859,14.862752,0.808862,-1293.283691,294.500488,0.000000
90.860001,65.580009,-1293.328125,0.000129,0.003184,0.080886,291.714447,14.860642,0.808862,-1293.328125,294.500488,0.000000
91.210007,65.572563,-1293.328125,0.000116,0.003184,0.080886,291.681335,14.858955,0.808862,-1293.328125,294.500488,0.000000
91.560005,65.554680,-1293.417114,0.000112,0.003184,0.080886,291.601776,14.854903,0.808862,-1293.417114,294.500488,0.000000
91.910004,65.545006,-1293.283691,0.000125,0.003184,0.080886,291.558746,14.852711,0.808862,-1293.283691,294.500488,0.000000
92.260002,65.538673,-1293.372559,0.000121,0.003184,0.080886,291.530579,14.851276,0.808862,-1293.372559,294.500488,0.000000
92.610001,65.526756,-1293.417114,0.000125,0.003184,0.080886,291.477570,14.848576,0.808862,-1293.417114,294.500488,0.000000
92.960007,65.493980,-1293.372559,0.000125,0.003184,0.080886,291.331787,14.841148,0.808862,-1293.372559,294.500488,0.000000
93.310005,65.483559,-1293.372559,0.000121,0.003184,0.080886,291.285431,14.838787,0.808862,-1293.372559,294.500488,0.000000
93.660004,65.484673,-1293.328125,0.000121,0.003184,0.080886,291.290375,14.839039,0.808862,-1293.328125,294.500488,0.000000
94.010002,65.446693,-1293.372559,0.000125,0.003184,0.080886,291.121429,14.830433,0.808862,-1293.372559,294.500488,0.000000
94.360008,65.406105,-1293.328125,0.000129,0.003184,0.080886,290.940887,14.821236,0.808862,-1293.328125,294.500488,0.000000
94.710007,65.400887,-1293.372559,0.000121,0.003184,0.080886,290.917664,14.820053,0.808862,-1293.372559,294.500488,0.000000
95.060005,65.380043,-1293.328125,0.000134,0.003184,0.080886,290.824951,14.815329,0.808862,-1293.328125,294.500488,0.000000
95.410004,65.364769,-1293.372559,0.000121,0.003184,0.080886,290.757019,14.811869,0.808862,-1293.372559,294.500488,0.000000
95.760002,65.337959,-1293.328125,0.000134,0.003184,0.080886,290.637756,14.805793,0.808862,-1293.328125,294.500488,0.000000
96.110008,65.330879,-1293.328125,0.000125,0.003184,0.080886,290.606262,14.804189,0.808862,-1293.328125,294.500488,0.000000
96.460007,65.307426,-1293.372559,0.000125,0.003184,0.080886,290.501953,14.798875,0.808862,-1293.372559,294.500488,0.000000
96.810005,65.302208,-1293.372559,0.000116,0.003184,0.080886,290.478729,14.797691,0.808862,-1293.372559,294.500488,0.000000
97.160004,65.293648,-1293.328125,0.000138,0.003184,0.080886,290.440643,14.795753,0.808862,-1293.328125,294.500488,0.000000
97.510002,65.284706,-1293.372559,0.000125,0.003184,0.080886,290.400879,14.793726,0.808862,-1293.372559,294.500488,0.000000
97.860008,65.281731,-1293.372559,0.000134,0.003184,0.080886,290.387634,14.793052,0.808862,-1293.372559,294.500488,0.000000
98.210007,65.266838,-1293.372559,0.000134,0.003184,0.080886,290.321381,14.789678,0.808862,-1293.372559,294.500488,0.000000
98.560005,65.247475,-1293.417114,0.000125,0.003184,0.080886,290.235260,14.785289,0.808862,-1293.417114,294.500488,0.000000
98.910004,65.229607,-1293.417114,0.000138,0.003184,0.080886,290.155792,14.781240,0.808862,-1293.417114,294.500488,0.000000
99.260002,65.220665,-1293.372559,0.000142,0.003184,0.080886,290.115997,14.779214,0.808862,-1293.372559,294.500488,0.000000
99.610008,65.209862,-1293.328125,0.000129,0.003184,0.080886,290.067963,14.776766,0.808862,-1293.328125,294.500488,0.000000
99.960007,65.193108,-1293.372559,0.000134,0.003184,0.080886,289.993439,14.772969,0.808862,-1293.372559,294.500488,0.000000
100.310005,65.177467,-1293.372559,0.000116,0.003184,0.080886,289.923859,14.769425,0.808862,-1293.372559,294.500488,0.000000
100.660004,65.145439,-1293.417114,0.000116,0.003184,0.080886,289.781372,14.762168,0.808862,-1293.417114,294.500488,0.000000
101.010002,65.129433,-1293.417114,0.000129,0.003184,0.080886,289.710175,14.758540,0.808862,-1293.417114,294.500488,0.000000
101.360008,65.164070,-1293.372559,0.000129,0.003187,0.080947,289.864258,14.766389,0.809468,-1293.372559,294.500488,0.000000
101.710007,65.198692,-1293.417114,0.000129,0.003187,0.080947,290.018280,14.774235,0.809468,-1293.417114,294.500488,0.000000
102.060005,65.198692,-1293.417114,0.000129,0.003187,0.080947,290.018280,14.774235,0.809468,-1293.417114,294.500488,0.000000
102.410004,65.192360,-1293.417114,0.000121,0.003187,0.080947,289.990112,14.772799,0.809468,-1293.417114,294.500488,0.000000
102.760002,65.187889,-1293.461548,0.000121,0.003187,0.080947,289.970215,14.771787,0.809468,-1293.461548,294.500488,0.000000
103.110008,65.181190,-1293.461548,0.000138,0.003187,0.080947,289.940430,14.770268,0.809468,-1293.461548,294.500488,0.000000
103.460007,65.183434,-1293.417114,0.000121,0.003188,0.080974,289.950378,14.770777,0.809740,-1293.417114,294.500488,0.000000
103.810005,65.227745,-1293.372559,0.000147,0.003189,0.080991,290.147491,14.780818,0.809907,-1293.372559,294.500488,0.000000
104.160004,65.244118,-1293.417114,0.000121,0.003189,0.080991,290.220337,14.784528,0.809907,-1293.417114,294.500488,0.000000
104.510002,65.244118,-1293.417114,0.000134,0.003189,0.080991,290.220337,14.784528,0.809907,-1293.417114,294.500488,0.000000
104.860008,65.245247,-1293.461548,0.000129,0.003189,0.080991,290.225342,14.784784,0.809907,-1293.461548,294.500488,0.000000
105.210007,65.257164,-1293.417114,0.000125,0.003189,0.080991,290.278351,14.787484,0.809907,-1293.417114,294.500488,0.000000
105.560005,65.246727,-1293.372559,0.000147,0.003189,0.080991,290.231934,14.785120,0.809907,-1293.372559,294.500488,0.000000
105.910004,65.240395,-1293.461548,0.000129,0.003189,0.080991,290.203766,14.783685,0.809907,-1293.461548,294.500488,0.000000
106.260002,65.224754,-1293.506104,0.000138,0.003189,0.080991,290.134186,14.780140,0.809907,-1293.506104,294.500488,0.000000
106.610008,65.222893,-1293.417114,0.000125,0.003189,0.080991,290.125916,14.779719,0.809907,-1293.417114,294.500488,0.000000
106.960007,65.220299,-1293.417114,0.000138,0.003189,0.080991,290.114380,14.779131,0.809907,-1293.417114,294.500488,0.000000
107.310005,65.220665,-1293.461548,0.000125,0.003189,0.080991,290.115997,14.779214,0.809907,-1293.461548,294.500488,0.000000
107.660004,65.199074,-1293.461548,0.000129,0.003189,0.080991,290.019958,14.774321,0.809907,-1293.461548,294.500488,0.000000
108.010002,65.199074,-1293.417114,0.000125,0.003189,0.081000,290.019958,14.774321,0.809998,-1293.417114,294.500488,0.000000
108.360008,65.183052,-1293.417114,0.000138,0.003189,0.081000,289.948700,14.770691,0.809998,-1293.417114,294.500488,0.000000
108.710007,65.186409,-1293.372559,0.000125,0.003189,0.081000,289.963623,14.771451,0.809998,-1293.372559,294.500488,0.000000
109.060005,65.196083,-1293.461548,0.000134,0.003189,0.081000,290.006653,14.773643,0.809998,-1293.461548,294.500488,0.000000
109.410004,65.181938,-1293.461548,0.000134,0.003189,0.081000,289.943756,14.770438,0.809998,-1293.461548,294.500488,0.000000
109.760002,65.167046,-1293.506104,0.000134,0.003189,0.081007,289.877502,14.767064,0.810073,-1293.506104,294.500488,0.000000
110.110008,65.178963,-1293.461548,0.000138,0.003189,0.081007,289.930511,14.769765,0.810073,-1293.461548,294.500488,0.000000
110.460007,65.168159,-1293.461548,0.000129,0.003189,0.081007,289.882446,14.767316,0.810073,-1293.461548,294.500488,0.000000
110.810005,65.148430,-1293.372559,0.000134,0.003189,0.081007,289.794678,14.762845,0.810073,-1293.372559,294.500488,0.000000
111.160004,65.135017,-1293.461548,0.000116,0.003189,0.081007,289.735016,14.759806,0.810073,-1293.461548,294.500488,0.000000
111.510002,65.128685,-1293.372559,0.000138,0.003189,0.081007,289.706848,14.758371,0.810073,-1293.372559,294.500488,0.000000
111.860008,65.147301,-1293.417114,0.000121,0.003191,0.081042,289.789673,14.762589,0.810422,-1293.417114,294.500488,0.000000
112.210007,65.195717,-1293.461548,0.000121,0.003191,0.081042,290.005035,14.773561,0.810422,-1293.461548,294.500488,0.000000
112.560005,65.197578,-1293.461548,0.000125,0.003191,0.081042,290.013306,14.773982,0.810422,-1293.461548,294.500488,0.000000
112.910004,65.218437,-1293.417114,0.000134,0.003191,0.081042,290.106110,14.778709,0.810422,-1293.417114,294.500488,0.000000
113.260002,65.218056,-1293.372559,0.000134,0.003191,0.081042,290.104401,14.778623,0.810422,-1293.372559,294.500488,0.000000
113.610008,65.207253,-1293.461548,0.000129,0.003191,0.081042,290.056335,14.776175,0.810422,-1293.461548,294.500488,0.000000
113.960007,65.201668,-1293.461548,0.000129,0.003191,0.081042,290.031494,14.774909,0.810422,-1293.461548,294.500488,0.000000
114.310005,65.199440,-1293.372559,0.000108,0.003191,0.081042,290.021606,14.774405,0.810422,-1293.372559,294.500488,0.000000
114.660004,65.193855,-1293.506104,0.000125,0.003191,0.081042,289.996765,14.773139,0.810422,-1293.506104,294.500488,0.000000
115.010002,65.189018,-1293.461548,0.000112,0.003191,0.081042,289.975250,14.772042,0.810422,-1293.461548,294.500488,0.000000
115.360008,65.179710,-1293.417114,0.000129,0.003191,0.081042,289.933838,14.769934,0.810422,-1293.417114,294.500488,0.000000
115.710007,65.171135,-1293.372559,0.000134,0.003191,0.081042,289.895691,14.767991,0.810422,-1293.372559,294.500488,0.000000
116.060005,65.154747,-1293.506104,0.000116,0.003191,0.081042,289.822784,14.764277,0.810422,-1293.506104,294.500488,0.000000
116.410004,65.149544,-1293.461548,0.000121,0.003191,0.081042,289.799652,14.763098,0.810422,-1293.461548,294.500488,0.000000
116.760002,65.140984,-1293.461548,0.000121,0.003191,0.081042,289.761566,14.761158,0.810422,-1293.461548,1681.640991,0.000000
117.110008,65.100395,-1293.461548,0.000125,0.003184,0.080870,289.581024,14.751961,0.808696,-1293.461548,0.080809,0.000000
117.460007,65.040062,-1293.461548,0.000116,0.003168,0.080479,289.312653,14.738289,0.804790,-1293.461548,0.080219,0.000000
117.810005,65.012886,-1293.417114,0.000138,0.003151,0.080046,289.191772,14.732131,0.800460,-1293.417114,0.079637,0.000000
118.160004,64.994255,-1293.417114,0.000142,0.003130,0.079490,289.108887,14.727909,0.794904,-1293.417114,0.079057,0.000000
118.510002,64.946220,-1293.461548,0.000160,0.003108,0.078953,288.895203,14.717024,0.789529,-1293.461548,0.078476,0.000000
118.860008,64.910851,-1293.506104,0.000147,0.003085,0.078372,288.737885,14.709009,0.783715,-1293.506104,0.077886,0.000000
119.210007,64.954048,-1293.506104,0.000151,0.003080,0.078232,288.930023,14.718798,0.782323,-1293.506104,0.077306,0.000000
119.560005,64.919792,-1293.461548,0.000147,0.003048,0.077418,288.777649,14.711036,0.774178,-1293.461548,0.076724,0.000000
119.910004,64.872490,-1293.506104,0.000151,0.003031,0.076976,288.567261,14.700316,0.769757,-1293.506104,0.076134,0.000000
120.260002,64.816643,-1293.461548,0.000155,0.002994,0.076039,288.318817,14.687661,0.760385,-1293.461548,0.075553,0.000000
120.610008,64.788719,-1293.506104,0.000151,0.002973,0.075527,288.194611,14.681334,0.755268,-1293.506104,0.074973,0.000000
120.960007,64.770836,-1293.461548,0.000147,0.002960,0.075189,288.115082,14.677281,0.751892,-1293.461548,0.074391,0.000000
121.310005,64.405174,-1293.506104,0.000164,0.002939,0.074652,286.488525,14.594421,0.746518,-1293.506104,0.073801,0.000000
121.660004,63.476097,-1293.461548,0.000164,0.002914,0.074019,282.355774,14.383889,0.740189,-1293.461548,0.073221,0.000000
122.010002,62.433456,-1293.506104,0.000168,0.002890,0.073412,277.717896,14.147624,0.734118,-1293.506104,0.072640,0.000000
122.360008,61.188988,-1293.417114,0.000177,0.002869,0.072882,272.182220,13.865623,0.728819,-1293.417114,0.072058,0.000000
122.710007,60.053627,-1293.417114,0.000185,0.002851,0.072414,267.131866,13.608346,0.724141,-1293.417114,0.071468,0.000000
123.060005,58.174263,-1293.417114,0.000181,0.002826,0.071781,258.772034,13.182477,0.717813,-1293.417114,0.070888,0.000000
123.410004,56.810257,-1293.417114,0.000185,0.002809,0.071339,252.704651,12.873388,0.713392,-1293.417114,0.070307,0.000000
123.760002,54.417770,-1293.461548,0.000185,0.002782,0.070662,242.062332,12.331243,0.706625,-1293.461548,0.069716,0.000000
124.110008,52.587555,-1293.417114,0.000198,0.002760,0.070116,233.921127,11.916511,0.701159,-1293.417114,0.069136,0.000000
124.460007,49.513992,-1293.461548,0.000181,0.002733,0.069430,220.249237,11.220031,0.694301,-1293.461548,0.068555,0.000000
124.810005,47.629044,-1293.372559,0.000177,0.002716,0.068988,211.864563,10.792895,0.689880,-1293.372559,0.067974,0.000000
125.160004,45.348267,-1293.461548,0.000168,0.002697,0.068502,201.719162,10.276064,0.685021,-1293.461548,0.067383,0.000000
125.510010,42.365562,-1293.417114,0.000190,0.002667,0.067748,188.451431,9.600173,0.677481,-1293.417114,0.066803,0.000000
125.860008,39.603676,-1293.461548,0.000185,0.002645,0.067176,176.165955,8.974321,0.671758,-1293.461548,0.066222,0.000000
126.210007,37.546684,-1293.417114,0.000181,0.002625,0.066681,167.015991,8.508200,0.666808,-1293.417114,0.065641,0.000000
126.560005,34.470146,-1293.461548,0.000181,0.002598,0.065996,153.330872,7.811047,0.659965,-1293.461548,0.065052,0.000000
126.910004,31.999084,-1293.461548,0.000177,0.002577,0.065450,142.339035,7.251096,0.654499,-1293.461548,0.064470,0.000000
127.260010,30.272392,-1293.417114,0.000194,0.002559,0.064999,134.658325,6.859822,0.649988,-1293.417114,0.063889,0.000000
127.610008,26.767624,-1293.461548,0.000194,0.002526,0.064159,119.068336,6.065630,0.641585,-1293.461548,0.063308,0.000000
127.960007,24.177025,-1293.461548,0.000185,0.002504,0.063603,107.544777,5.478592,0.636029,-1293.461548,0.062719,0.000000
128.310013,21.995300,-1293.461548,0.000181,0.002484,0.063091,97.839981,4.984206,0.630912,-1293.461548,0.062137,0.000000
128.660004,19.561844,-1293.461548,0.000181,0.002462,0.062528,87.015427,4.432777,0.625280,-1293.461548,0.061556,0.000000
129.010010,17.059875,-1293.372559,0.000181,0.002439,0.061963,75.886116,3.865823,0.619633,-1293.372559,0.060967,0.000000
129.360001,14.531090,-1293.417114,0.000185,0.002417,0.061391,64.637512,3.292792,0.613910,-1293.417114,0.060386,0.000000
129.710007,12.461815,-1293.417114,0.000181,0.002399,0.060940,55.432922,2.823888,0.609398,-1293.417114,0.059804,0.000000
130.060013,10.093903,-1293.372559,0.000185,0.002376,0.060351,44.899921,2.287311,0.603509,-1293.372559,0.059223,0.000000
130.410004,7.052361,-1293.461548,0.000185,0.002347,0.059605,31.370466,1.598088,0.596045,-1293.461548,0.058634,0.000000
130.760010,4.973778,-1293.506104,0.000177,0.002325,0.059067,22.124468,1.127074,0.590671,-1293.506104,0.058053,0.000000
131.110001,3.086594,-1293.461548,0.000194,0.002307,0.058590,13.729855,0.699432,0.585902,-1293.461548,0.057471,0.000000
131.460007,0.665802,-1293.461548,0.000185,0.002280,0.057913,2.961635,0.150873,0.579134,-1293.461548,0.056890,0.000000
131.810013,-0.893322,-1293.417114,0.000181,0.002259,0.057376,-3.973695,-0.202430,0.573760,-1293.417114,0.056301,0.000000
132.160004,-0.304970,-1293.417114,0.000190,0.002232,0.056692,-1.356573,-0.069107,0.566917,-1293.417114,0.055720,0.000000
132.510010,-0.082291,-1293.417114,0.000185,0.002211,0.056162,-0.366047,-0.018647,0.561618,-1293.417114,0.055138,0.000000
132.860001,0.052505,-1293.417114,0.000164,0.002192,0.055685,0.233556,0.011898,0.556849,-1293.417114,0.054557,0.000000
133.210007,-0.024200,-1293.372559,0.000147,0.002166,0.055017,-0.107649,-0.005484,0.550172,-1293.372559,0.053968,0.000000
133.560013,0.028671,-1293.417114,0.000078,0.002141,0.054375,0.127536,0.006497,0.543753,-1293.417114,0.053387,0.000000
133.910004,0.029419,-1293.461548,0.000052,0.002129,0.054080,0.130862,0.006666,0.540801,-1293.461548,0.052805,0.000000
134.260010,0.021973,-1293.417114,-0.000009,0.002094,0.053196,0.097739,0.004979,0.531959,-1293.417114,0.052216,0.000000
134.610001,-0.009682,-1293.372559,-0.000047,0.002063,0.052407,-0.043066,-0.002194,0.524072,-1293.372559,0.051635,0.000000
134.960007,0.003723,-1293.417114,-0.000086,0.002050,0.052068,0.016561,0.000844,0.520680,-1293.417114,0.051054,0.000000
135.310013,0.028671,-1293.372559,-0.000134,0.002026,0.051453,0.127536,0.006497,0.514534,-1293.372559,0.050472,0.000000
135.660004,0.005959,-1293.461548,-0.000185,0.002005,0.050916,0.026505,0.001350,0.509159,-1293.461548,0.049883,0.000000
136.010010,-0.031654,-1293.417114,-0.000224,0.001972,0.050100,-0.140806,-0.007173,0.500999,-1293.417114,0.049302,0.000000
136.360001,0.002235,-1293.461548,-0.000276,0.001955,0.049667,0.009944,0.000507,0.496669,-1293.461548,0.048721,0.000000
136.710007,-0.017128,-1293.461548,-0.000315,0.001936,0.049181,-0.076189,-0.003881,0.491809,-1293.461548,0.048141,0.000000
137.060013,-0.013779,-1293.506104,-0.000345,0.001909,0.048478,-0.061291,-0.003122,0.484784,-1293.506104,0.047550,0.000000
137.410004,-0.017876,-1293.550537,-0.000392,0.001891,0.048036,-0.079515,-0.004051,0.480364,-1293.550537,0.046969,0.000000
137.760010,-0.029793,-1293.417114,-0.000427,0.001868,0.047446,-0.132525,-0.006751,0.474459,-1293.417114,0.046388,0.000000
138.110001,-0.013779,-1293.461548,-0.000466,0.001839,0.046701,-0.061291,-0.003122,0.467011,-1293.461548,0.045799,0.000000
138.460007,-0.030533,-1293.417114,-0.000509,0.001812,0.046015,-0.135817,-0.006919,0.460152,-1293.417114,0.045217,0.000000
138.810013,0.015640,-1293.417114,-0.000543,0.001803,0.045790,0.069571,0.003544,0.457897,-1293.417114,0.044636,0.000000
139.160004,-0.035751,-1293.461548,-0.000573,0.001777,0.045140,-0.159030,-0.008101,0.451402,-1293.461548,0.044056,0.000000
139.510010,-0.033142,-1293.461548,-0.000617,0.001748,0.044403,-0.147423,-0.007510,0.444029,-1293.461548,0.043466,0.000000
139.860001,-0.018616,-1293.461548,-0.000638,0.001725,0.043812,-0.082807,-0.004218,0.438124,-1293.461548,0.042884,0.000000
140.210007,-0.037979,-1293.417114,-0.000668,0.001704,0.043284,-0.168940,-0.008606,0.432841,-1293.417114,0.042305,0.000000
140.560013,0.010429,-1293.372559,-0.000694,0.001693,0.043005,0.046392,0.002363,0.430055,-1293.372559,0.042928,0.000000
140.600006,0.006706,-1293.417114,-0.000690,0.001693,0.043005,0.029831,0.001520,0.430055,-1293.417114,0.042928,0.000000