File: Data/Sima compression/P2-17-1_10302024_173538.csv
Time (sec),S:Load (lbs),S:HL1 (DIM),S:LVDT (in),S:Position (in),Ch:Position (mm),Ch:Load (N),Ch:Stress (MPa),Ch:Strain (mm/mm),Ch:HL1 (DIM),Set Point (),Cycles ()
0.210000,-0.008934,-1293.861938,-0.009231,-0.005826,-0.147992,-0.039741,-0.002024,-1.479924,-1293.861938,-0.147809,0.000000
0.510000,-0.049522,-1293.772949,-0.009218,-0.005764,-0.146397,-0.220287,-0.011222,-1.463967,-1293.772949,-0.145815,0.000000
0.810000,-0.002975,-1293.772949,-0.009132,-0.005588,-0.141947,-0.013236,-0.000674,-1.419472,-1293.772949,-0.140821,0.000000
1.110000,-0.070007,-1293.861938,-0.008933,-0.005394,-0.136995,-0.311408,-0.015864,-1.369950,-1293.861938,-0.135825,0.000000
1.410000,0.013779,-1293.772949,-0.008748,-0.005203,-0.132166,0.061291,0.003122,-1.321655,-1293.772949,-0.130830,0.000000
1.710000,-0.026436,-1293.861938,-0.008541,-0.004999,-0.126971,-0.117593,-0.005990,-1.269711,-1293.861938,-0.125834,0.000000
2.010000,-0.000000,-1293.817383,-0.008326,-0.004806,-0.122061,-0.000000,-0.000000,-1.220613,-1293.817383,-0.120821,0.000000
2.310000,-0.032394,-1293.861938,-0.008123,-0.004610,-0.117093,-0.144098,-0.007341,-1.170925,-1293.861938,-0.115827,0.000000
2.610000,-0.022339,-1293.817383,-0.007929,-0.004407,-0.111942,-0.099368,-0.005062,-1.119421,-1293.817383,-0.110831,0.000000
2.910000,-0.029045,-1293.861938,-0.007713,-0.004214,-0.107041,-0.129199,-0.006582,-1.070414,-1293.861938,-0.105836,0.000000
3.210000,-0.021599,-1293.817383,-0.007519,-0.004012,-0.101917,-0.096076,-0.004894,-1.019166,-1293.817383,-0.100842,0.000000
3.510000,0.011169,-1293.817383,-0.007312,-0.003821,-0.097060,0.049684,0.002531,-0.970598,-1293.817383,-0.095846,0.000000
3.810000,-0.017876,-1293.861938,-0.007105,-0.003622,-0.091996,-0.079515,-0.004051,-0.919957,-1293.861938,-0.090851,0.000000
4.110000,0.022713,-1293.861938,-0.006916,-0.003428,-0.087060,0.101031,0.005147,-0.870602,-1293.861938,-0.085838,0.000000
4.410000,-0.037979,-1293.817383,-0.006700,-0.003227,-0.081970,-0.168940,-0.008606,-0.819702,-1293.817383,-0.080842,0.000000
4.710000,-0.013031,-1293.861938,-0.006506,-0.003038,-0.077157,-0.057965,-0.002953,-0.771574,-1293.861938,-0.075848,0.000000
5.010000,-0.054367,-1293.817383,-0.006295,-0.002834,-0.071980,-0.241837,-0.012320,-0.719796,-1293.817383,-0.070852,0.000000
5.310000,-0.026810,-1293.906372,-0.006101,-0.002648,-0.067262,-0.119255,-0.006075,-0.672621,-1293.906372,-0.065857,0.000000
5.610000,-0.018990,-1293.817383,-0.005911,-0.002443,-0.062042,-0.084470,-0.004303,-0.620420,-1293.817383,-0.060863,0.000000
5.910000,0.026436,-1293.950806,-0.005691,-0.002242,-0.056941,0.117593,0.005990,-0.569415,-1293.950806,-0.055850,0.000000
6.210001,0.013031,-1293.906372,-0.005484,-0.002048,-0.052007,0.057965,0.002953,-0.520075,-1293.906372,-0.050854,0.000000
6.510000,0.005585,-1293.861938,-0.005286,-0.001852,-0.047039,0.024842,0.001266,-0.470387,-1293.861938,-0.045859,0.000000
6.810000,0.015640,-1293.906372,-0.005075,-0.001651,-0.041931,0.069571,0.003544,-0.419306,-1293.906372,-0.040863,0.000000
7.110000,-0.077080,-1293.950806,-0.004876,-0.001455,-0.036969,-0.342868,-0.017467,-0.369693,-1293.950806,-0.035869,0.000000
7.410000,0.005211,-1293.906372,-0.004691,-0.001266,-0.032156,0.023179,0.001181,-0.321565,-1293.906372,-0.030873,0.000000
7.710001,-0.010056,-1293.950806,-0.004480,-0.001066,-0.027074,-0.044729,-0.002279,-0.270741,-1293.950806,-0.025860,0.000000
8.010000,0.033142,-1293.906372,-0.004294,-0.000871,-0.022131,0.147423,0.007510,-0.221310,-1293.906372,-0.020865,0.000000
8.310000,0.000374,-1293.950806,-0.004079,-0.000668,-0.016962,0.001663,0.000085,-0.169624,-1293.950806,-0.015871,0.000000
8.610001,0.013031,-1293.861938,-0.003880,-0.000480,-0.012193,0.057965,0.002953,-0.121934,-1293.861938,-0.010875,0.000000
8.910001,0.004845,-1293.950806,-0.003678,-0.000276,-0.007007,0.021550,0.001098,-0.070066,-1293.950806,-0.005880,0.000000
9.210000,-0.022339,-1293.950806,-0.003454,-0.000076,-0.001942,-0.099368,-0.005062,-0.019424,-1293.950806,-0.000884,0.000000
9.510000,-0.002235,-1293.906372,-0.003272,0.000114,0.002889,-0.009944,-0.000507,0.028886,-1293.906372,0.004110,0.000000
9.810000,0.133308,-1293.906372,-0.003126,-0.000010,-0.000242,0.592985,0.030208,-0.002422,-1293.906372,-0.000035,0.000000
10.110001,0.031654,-1293.950806,-0.003143,-0.000010,-0.000251,0.140806,0.007173,-0.002513,-1293.950806,-0.000035,0.000000
10.410001,0.091606,-1293.861938,-0.003134,-0.000010,-0.000242,0.407484,0.020758,-0.002422,-1293.861938,0.000295,0.000000
10.710000,0.148201,-1293.906372,-0.003152,-0.000003,-0.000068,0.659231,0.033583,-0.000681,-1293.906372,0.000798,0.000000
11.010000,0.187675,-1293.906372,-0.003126,0.000008,0.000209,0.834822,0.042528,0.002089,-1293.906372,0.001293,0.000000
11.310000,0.348541,-1293.861938,-0.003117,0.000026,0.000660,1.550389,0.078981,0.006601,-1293.861938,0.001796,0.000000
11.610001,0.646812,-1293.861938,-0.003109,0.000049,0.001249,2.877165,0.146570,0.012490,-1293.861938,0.002298,0.000000
11.910001,1.038544,-1293.817383,-0.003078,0.000070,0.001786,4.619673,0.235337,0.017865,-1293.817383,0.002793,0.000000
12.210001,1.598595,-1293.906372,-0.003070,0.000092,0.002342,7.110904,0.362247,0.023421,-1293.906372,0.003296,0.000000
12.510000,2.045067,-1293.817383,-0.003061,0.000113,0.002880,9.096911,0.463419,0.028795,-1293.817383,0.003799,0.000000
12.810000,2.719437,-1293.861938,-0.003022,0.000130,0.003314,12.096659,0.616233,0.033141,-1293.861938,0.004294,0.000000
13.110001,3.279854,-1293.861938,-0.003022,0.000145,0.003696,14.589519,0.743226,0.036956,-1293.861938,0.004796,0.000000
13.410001,4.143387,-1293.950806,-0.002992,0.000171,0.004345,18.430706,0.938905,0.043451,-1293.950806,0.005291,0.000000
13.710001,4.997612,-1293.906372,-0.002984,0.000191,0.004840,22.230488,1.132475,0.048401,-1293.906372,0.005794,0.000000
14.010000,5.701393,-1293.906372,-0.002975,0.000210,0.005325,25.361063,1.291954,0.053246,-1293.906372,0.006297,0.000000
14.310000,6.513542,-1293.861938,-0.002958,0.000228,0.005803,28.973682,1.475990,0.058030,-1293.861938,0.006792,0.000000
14.610001,7.477242,-1293.861938,-0.002940,0.000249,0.006322,33.260433,1.694367,0.063223,-1293.861938,0.007294,0.000000
14.910001,8.154961,-1293.772949,-0.002945,0.000264,0.006713,36.275078,1.847941,0.067129,-1293.772949,0.007797,0.000000
15.210001,8.952576,-1293.861938,-0.002919,0.000283,0.007181,39.823044,2.028683,0.071807,-1293.861938,0.008292,0.000000
15.510001,10.386955,-1293.861938,-0.002910,0.000311,0.007892,46.203484,2.353718,0.078923,-1293.861938,0.008795,0.000000
15.810000,11.137657,-1293.861938,-0.002884,0.000330,0.008378,49.542774,2.523829,0.083782,-1293.861938,0.009297,0.000000
16.110001,12.175461,-1293.817383,-0.002884,0.000350,0.008890,54.159153,2.758999,0.088900,-1293.817383,0.009792,0.000000
16.410000,12.858391,-1293.817383,-0.002867,0.000364,0.009246,57.196980,2.913753,0.092457,-1293.817383,0.010295,0.000000
16.710001,14.124084,-1293.817383,-0.002841,0.000388,0.009853,62.827065,3.200563,0.098528,-1293.817383,0.010798,0.000000
17.010000,14.688606,-1293.906372,-0.002846,0.000402,0.010207,65.338181,3.328486,0.102071,-1293.906372,0.011293,0.000000
17.310001,16.048134,-1293.906372,-0.002828,0.000429,0.010893,71.385666,3.636559,0.108929,-1293.906372,0.011795,0.000000
17.610001,16.979813,-1293.817383,-0.002811,0.000447,0.011344,75.529976,3.847681,0.113441,-1293.817383,0.012298,0.000000
17.910002,17.866806,-1293.861938,-0.002807,0.000469,0.011916,79.475525,4.048676,0.119164,-1293.861938,0.012791,0.000000
18.210001,18.420151,-1293.772949,-0.002785,0.000482,0.012237,81.936920,4.174066,0.122373,-1293.772949,0.013296,0.000000
18.510000,19.519020,-1293.861938,-0.002772,0.000506,0.012861,86.824936,4.423073,0.128611,-1293.861938,0.013798,0.000000
18.810001,20.347176,-1293.861938,-0.002755,0.000523,0.013286,90.508759,4.610736,0.132865,-1293.861938,0.014292,0.000000
19.110001,21.268425,-1293.861938,-0.002738,0.000545,0.013833,94.606682,4.819494,0.138330,-1293.861938,0.014796,0.000000
19.410002,22.193024,-1293.772949,-0.002738,0.000564,0.014319,98.719498,5.029011,0.143190,-1293.772949,0.015299,0.000000
19.710001,22.965698,-1293.817383,-0.002703,0.000583,0.014813,102.156525,5.204102,0.148126,-1293.817383,0.015792,0.000000
20.010000,23.775612,-1293.817383,-0.002695,0.000600,0.015247,105.759201,5.387630,0.152471,-1293.817383,0.016296,0.000000
20.310001,24.616425,-1293.817383,-0.002690,0.000623,0.015819,109.499329,5.578162,0.158193,-1293.817383,0.016799,0.000000
20.610001,25.283714,-1293.728516,-0.002660,0.000637,0.016174,112.467575,5.729372,0.161736,-1293.728516,0.017292,0.000000
20.910002,25.973724,-1293.772949,-0.002660,0.000655,0.016643,115.536896,5.885730,0.166429,-1293.772949,0.017797,0.000000
21.210001,26.908379,-1293.772949,-0.002626,0.000677,0.017197,119.694443,6.097526,0.171970,-1293.772949,0.018299,0.000000
21.510000,27.999062,-1293.772949,-0.002634,0.000702,0.017839,124.546043,6.344678,0.178390,-1293.772949,0.018793,0.000000
21.810001,28.956055,-1293.772949,-0.002604,0.000724,0.018395,128.802963,6.561536,0.183946,-1293.772949,0.019297,0.000000
22.110001,29.041702,-1293.772949,-0.002587,0.000737,0.018716,129.183945,6.580944,0.187155,-1293.772949,0.019800,0.000000
22.410002,30.219513,-1293.772949,-0.002565,0.000762,0.019357,134.423111,6.847839,0.193575,-1293.772949,0.020293,0.000000
22.710001,30.642532,-1293.772949,-0.002557,0.000779,0.019781,136.304794,6.943697,0.197814,-1293.772949,0.020797,0.000000
23.010000,30.351334,-1293.772949,-0.002544,0.000785,0.019939,135.009476,6.877710,0.199388,-1293.772949,0.021300,0.000000
23.310001,32.224739,-1293.772949,-0.002522,0.000819,0.020805,143.342804,7.302230,0.208048,-1293.772949,0.021793,0.000000
23.610001,32.866707,-1293.728516,-0.002492,0.000840,0.021342,146.198410,7.447702,0.213423,-1293.728516,0.022298,0.000000
23.910002,33.475166,-1293.772949,-0.002466,0.000861,0.021872,148.904984,7.585581,0.218722,-1293.772949,0.022800,0.000000
24.210001,34.037079,-1293.728516,-0.002466,0.000882,0.022401,151.404495,7.712912,0.224005,-1293.728516,0.023294,0.000000
24.510000,34.327904,-1293.772949,-0.002436,0.000898,0.022809,152.698135,7.778814,0.228093,-1293.772949,0.023798,0.000000
24.810001,34.499191,-1293.772949,-0.002419,0.000911,0.023138,153.460068,7.817628,0.231378,-1293.772949,0.024301,0.000000
25.110001,35.993896,-1293.772949,-0.002410,0.000943,0.023961,160.108841,8.156334,0.239614,-1293.772949,0.024794,0.000000
25.410002,36.054962,-1293.772949,-0.002380,0.000956,0.024282,160.380478,8.170171,0.242824,-1293.772949,0.025298,0.000000
25.710001,36.744598,-1293.772949,-0.002354,0.000980,0.024899,163.448135,8.326445,0.248986,-1293.772949,0.025801,0.000000
26.010002,36.829124,-1293.772949,-0.002350,0.000993,0.025220,163.824127,8.345598,0.252195,-1293.772949,0.026294,0.000000
26.310001,37.799156,-1293.817383,-0.002345,0.001019,0.025878,168.139038,8.565412,0.258781,-1293.817383,0.026799,0.000000
26.610001,38.213608,-1293.728516,-0.002302,0.001035,0.026287,169.982620,8.659328,0.262869,-1293.728516,0.027292,0.000000
26.910002,37.798409,-1293.772949,-0.002285,0.001048,0.026624,168.135712,8.565242,0.266245,-1293.772949,0.027795,0.000000
27.210001,39.515045,-1293.817383,-0.002276,0.001077,0.027362,175.771698,8.954237,0.273618,-1293.817383,0.028299,0.000000
27.510002,39.558243,-1293.817383,-0.002251,0.001094,0.027795,175.963852,8.964026,0.277948,-1293.817383,0.028792,0.000000
27.810001,40.312668,-1293.817383,-0.002229,0.001115,0.028325,179.319702,9.134981,0.283246,-1293.817383,0.029295,0.000000
28.110001,40.626205,-1293.728516,-0.002216,0.001133,0.028767,180.714386,9.206030,0.287667,-1293.728516,0.029798,0.000000
28.410002,41.072311,-1293.772949,-0.002190,0.001151,0.029235,182.698761,9.307118,0.292345,-1293.772949,0.030293,0.000000
28.710001,41.451385,-1293.728516,-0.002160,0.001171,0.029746,184.384964,9.393019,0.297462,-1293.728516,0.030795,0.000000
29.010002,42.636650,-1293.772949,-0.002143,0.001197,0.030405,189.657288,9.661603,0.304048,-1293.772949,0.031298,0.000000
29.310001,42.532013,-1293.772949,-0.002117,0.001209,0.030718,189.191849,9.637893,0.307182,-1293.772949,0.031793,0.000000
29.610001,43.179939,-1293.728516,-0.002108,0.001232,0.031290,192.073959,9.784714,0.312905,-1293.728516,0.032296,0.000000
29.910002,43.536301,-1293.772949,-0.002091,0.001249,0.031733,193.659134,9.865466,0.317326,-1293.772949,0.032798,0.000000
30.210001,44.011070,-1293.772949,-0.002065,0.001267,0.032184,195.771011,9.973051,0.321837,-1293.772949,0.033293,0.000000
30.510002,44.507820,-1293.817383,-0.002048,0.001289,0.032730,197.980667,10.085616,0.327303,-1293.817383,0.033796,0.000000
30.810001,44.138054,-1293.772949,-0.002022,0.001296,0.032921,196.335876,10.001826,0.329210,-1293.772949,0.034299,0.000000
31.110001,46.494797,-1293.728516,-0.001983,0.001333,0.033857,206.819183,10.535872,0.338566,-1293.728516,0.034794,0.000000
31.410002,46.459053,-1293.772949,-0.001979,0.001349,0.034265,206.660187,10.527772,0.342654,-1293.772949,0.035296,0.000000
31.710001,47.082405,-1293.772949,-0.001953,0.001369,0.034768,209.432999,10.669025,0.347680,-1293.772949,0.035799,0.000000
32.010002,47.364662,-1293.728516,-0.001936,0.001387,0.035227,210.688538,10.732985,0.352268,-1293.728516,0.036294,0.000000
32.310001,47.989502,-1293.728516,-0.001901,0.001406,0.035704,213.467972,10.874577,0.357037,-1293.728516,0.036797,0.000000
32.610001,48.240852,-1293.772949,-0.001884,0.001421,0.036103,214.586029,10.931534,0.361034,-1293.772949,0.037299,0.000000
32.910000,49.354248,-1293.772949,-0.001876,0.001446,0.036727,219.538666,11.183832,0.367271,-1293.772949,0.037794,0.000000
33.210003,49.857323,-1293.772949,-0.001850,0.001466,0.037231,221.776443,11.297831,0.372313,-1293.772949,0.038297,0.000000
33.510002,50.285553,-1293.683960,-0.001850,0.001487,0.037776,223.681305,11.394869,0.377763,-1293.683960,0.038800,0.000000
33.810001,50.508598,-1293.728516,-0.001824,0.001500,0.038090,224.673462,11.445412,0.380897,-1293.728516,0.039295,0.000000
34.110001,51.741524,-1293.639526,-0.001802,0.001527,0.038783,230.157791,11.724797,0.387831,-1293.639526,0.039797,0.000000
34.410000,52.177574,-1293.772949,-0.001763,0.001543,0.039199,232.097443,11.823607,0.391994,-1293.772949,0.040300,0.000000
34.710003,52.796455,-1293.772949,-0.001763,0.001565,0.039754,234.850357,11.963848,0.397535,-1293.772949,0.040795,0.000000
35.010002,53.499870,-1293.728516,-0.001750,0.001587,0.040318,237.979309,12.123244,0.403182,-1293.728516,0.041298,0.000000
35.310001,54.084122,-1293.728516,-0.001707,0.001604,0.040742,240.578186,12.255637,0.407421,-1293.728516,0.041800,0.000000
35.610001,54.673218,-1293.817383,-0.001690,0.001625,0.041263,243.198624,12.389128,0.412629,-1293.817383,0.042295,0.000000
35.910000,55.340508,-1293.772949,-0.001669,0.001643,0.041723,246.166870,12.540338,0.417232,-1293.772949,0.042798,0.000000
36.210003,55.623138,-1293.728516,-0.001651,0.001659,0.042130,247.424072,12.604383,0.421304,-1293.728516,0.043301,0.000000
36.510002,56.514595,-1293.683960,-0.001643,0.001679,0.042651,251.389481,12.806390,0.426512,-1293.683960,0.043796,0.000000
36.810001,58.018982,-1293.772949,-0.001608,0.001706,0.043345,258.081329,13.147289,0.433446,-1293.772949,0.044298,0.000000
37.110001,58.509392,-1293.772949,-0.001591,0.001724,0.043796,260.262787,13.258418,0.437958,-1293.772949,0.044801,0.000000
37.410004,59.442932,-1293.728516,-0.001587,0.001746,0.044342,264.415375,13.469961,0.443423,-1293.728516,0.045296,0.000000
37.710003,60.027931,-1293.728516,-0.001565,0.001762,0.044750,267.017578,13.602524,0.447496,-1293.728516,0.045799,0.000000
38.010002,60.897049,-1293.728516,-0.001535,0.001783,0.045296,270.883606,13.799468,0.452961,-1293.728516,0.046301,0.000000
38.310001,61.460449,-1293.817383,-0.001522,0.001799,0.045694,273.389740,13.927137,0.456943,-1293.817383,0.046796,0.000000
38.610001,62.636772,-1293.772949,-0.001505,0.001824,0.046320,278.622284,14.193696,0.463195,-1293.772949,0.047299,0.000000
38.910004,63.595253,-1293.728516,-0.001492,0.001844,0.046848,282.885803,14.410891,0.468479,-1293.728516,0.047802,0.000000
39.210003,63.987373,-1293.772949,-0.001453,0.001861,0.047273,284.630066,14.499746,0.472733,-1293.772949,0.048297,0.000000
39.510002,64.911964,-1293.728516,-0.001444,0.001880,0.047750,288.742828,14.709262,0.477502,-1293.728516,0.048799,0.000000
39.810001,65.607567,-1293.772949,-0.001453,0.001900,0.048253,291.837036,14.866887,0.482529,-1293.772949,0.049293,0.000000
40.110001,66.135582,-1293.728516,-0.001397,0.001915,0.048653,294.185760,14.986537,0.486526,-1293.728516,0.049797,0.000000
40.410004,65.331627,-1293.683960,-0.001388,0.001912,0.048557,290.609589,14.804358,0.485572,-1293.683960,0.008548,0.000000
40.710003,66.003395,-1293.772949,-0.001393,0.001923,0.048843,293.597778,14.956583,0.488433,-1293.772949,294.500488,0.000000
41.010002,64.793556,-1293.728516,-0.001362,0.001931,0.049042,288.216125,14.682429,0.490416,-1293.728516,294.500488,0.000000
41.310001,65.421379,-1293.772949,-0.001354,0.001944,0.049388,291.008820,14.824697,0.493883,-1293.772949,294.500488,0.000000
41.610001,65.498451,-1293.817383,-0.001341,0.001959,0.049762,291.351654,14.842161,0.497623,-1293.817383,294.500488,0.000000
41.910004,65.650749,-1293.728516,-0.001328,0.001971,0.050074,292.029114,14.876672,0.500742,-1293.728516,294.500488,0.000000
42.210003,65.226250,-1293.683960,-0.001319,0.001977,0.050204,290.140839,14.780479,0.502044,-1293.683960,294.500488,0.000000
42.510002,65.047890,-1293.683960,-0.001315,0.001985,0.050412,289.347473,14.740063,0.504118,-1293.683960,294.500488,0.000000
42.810001,65.265724,-1293.728516,-0.001306,0.001993,0.050621,290.316437,14.789425,0.506207,-1293.728516,294.500488,0.000000
43.110001,65.032249,-1293.772949,-0.001281,0.001998,0.050751,289.277893,14.736519,0.507509,-1293.772949,294.500488,0.000000
43.410004,65.216194,-1293.728516,-0.001281,0.002007,0.050976,290.096130,14.778201,0.509765,-1293.728516,294.500488,0.000000
43.710003,65.250832,-1293.728516,-0.001263,0.002014,0.051167,290.250183,14.786049,0.511672,-1293.728516,294.500488,0.000000
44.010002,65.273537,-1293.728516,-0.001250,0.002021,0.051340,290.351196,14.791195,0.513398,-1293.728516,294.500488,0.000000
44.310001,65.239281,-1293.772949,-0.001268,0.002027,0.051496,290.198822,14.783432,0.514958,-1293.772949,294.500488,0.000000
44.610001,65.386375,-1293.772949,-0.001242,0.002035,0.051687,290.853119,14.816764,0.516865,-1293.772949,294.500488,0.000000
44.910004,65.320839,-1293.817383,-0.001237,0.002041,0.051844,290.561615,14.801914,0.518440,-1293.817383,294.500488,0.000000
45.210003,65.499565,-1293.817383,-0.001229,0.002050,0.052077,291.356628,14.842414,0.520771,-1293.817383,294.500488,0.000000
45.510002,65.228859,-1293.772949,-0.001216,0.002051,0.052095,290.152466,14.781071,0.520953,-1293.772949,294.500488,0.000000
45.810001,64.973778,-1293.817383,-0.001216,0.002055,0.052191,289.017792,14.723269,0.521907,-1293.817383,294.500488,0.000000
46.110001,64.789833,-1293.728516,-0.001220,0.002060,0.052321,288.199585,14.681586,0.523209,-1293.728516,294.500488,0.000000
46.410004,65.336845,-1293.772949,-0.001212,0.002068,0.052519,290.632812,14.805541,0.525192,-1293.772949,294.500488,0.000000
46.710003,65.072838,-1293.772949,-0.001190,0.002072,0.052624,289.458435,14.745716,0.526237,-1293.772949,294.500488,0.000000
47.010002,64.994255,-1293.817383,-0.001181,0.002075,0.052710,289.108887,14.727909,0.527100,-1293.817383,294.500488,0.000000
47.310001,65.482811,-1293.772949,-0.001168,0.002084,0.052945,291.282104,14.838617,0.529446,-1293.772949,294.500488,0.000000
47.610001,65.102623,-1293.817383,-0.001168,0.002086,0.052979,289.590942,14.752465,0.529794,-1293.817383,294.500488,0.000000
47.910004,65.380409,-1293.772949,-0.001173,0.002093,0.053161,290.826599,14.815413,0.531611,-1293.772949,294.500488,0.000000
48.210003,65.070976,-1293.772949,-0.001151,0.002094,0.053179,289.450165,14.745294,0.531793,-1293.772949,294.500488,0.000000
48.510002,65.364769,-1293.772949,-0.001151,0.002100,0.053352,290.757019,14.811869,0.533519,-1293.772949,294.500488,0.000000
48.810001,64.999855,-1293.772949,-0.001168,0.002103,0.053422,289.133789,14.729177,0.534215,-1293.772949,294.500488,0.000000
49.110001,65.213219,-1293.772949,-0.001155,0.002107,0.053526,290.082886,14.777527,0.535260,-1293.772949,294.500488,0.000000
49.410004,65.225883,-1293.772949,-0.001155,0.002113,0.053673,290.139221,14.780396,0.536728,-1293.772949,294.500488,0.000000
49.710003,65.610909,-1293.772949,-0.001134,0.002121,0.053864,291.851898,14.867644,0.538636,-1293.772949,294.500488,0.000000
50.010002,65.399025,-1293.817383,-0.001121,0.002121,0.053864,290.909393,14.819631,0.538636,-1293.817383,294.500488,0.000000
50.310001,65.213585,-1293.772949,-0.001130,0.002123,0.053933,290.084503,14.777609,0.539332,-1293.772949,294.500488,0.000000
50.610001,65.067619,-1293.728516,-0.001130,0.002126,0.053994,289.435211,14.744533,0.539938,-1293.728516,294.500488,0.000000
50.910004,65.023674,-1293.772949,-0.001121,0.002130,0.054107,289.239746,14.734575,0.541073,-1293.772949,294.500488,0.000000
51.210003,65.011391,-1293.728516,-0.001121,0.002133,0.054168,289.185120,14.731791,0.541679,-1293.728516,294.500488,0.000000
51.510002,65.031502,-1293.772949,-0.001117,0.002135,0.054228,289.274567,14.736349,0.542285,-1293.772949,294.500488,0.000000
51.810001,65.565483,-1293.817383,-0.001108,0.002143,0.054436,291.649841,14.857351,0.544359,-1293.817383,294.500488,0.000000
52.110001,65.326790,-1293.728516,-0.001108,0.002143,0.054436,290.588074,14.803262,0.544359,-1293.728516,294.500488,0.000000
52.410004,65.031868,-1293.817383,-0.001104,0.002144,0.054445,289.276184,14.736432,0.544450,-1293.817383,294.500488,0.000000
52.710003,64.757439,-1293.861938,-0.001095,0.002144,0.054445,288.055481,14.674245,0.544450,-1293.861938,294.500488,0.000000
53.010002,66.662865,-1293.817383,-0.001078,0.002118,0.053803,296.531219,15.106021,0.538030,-1293.817383,294.500488,0.000000
53.310001,66.240593,-1293.772949,-0.001082,0.002115,0.053726,294.652863,15.010332,0.537258,-1293.772949,294.500488,0.000000
53.610004,65.872322,-1293.817383,-0.001074,0.002115,0.053733,293.014709,14.926882,0.537334,-1293.817383,294.500488,0.000000
53.910004,65.555794,-1293.772949,-0.001087,0.002127,0.054020,291.606720,14.855155,0.540195,-1293.772949,294.500488,0.000000
54.210003,65.269066,-1293.817383,-0.001082,0.002133,0.054185,290.331299,14.790182,0.541846,-1293.817383,294.500488,0.000000
54.510002,65.317116,-1293.817383,-0.001078,0.002160,0.054852,290.545044,14.801069,0.548522,-1293.817383,294.500488,0.000000
54.810001,65.187889,-1293.817383,-0.001078,0.002163,0.054948,289.970215,14.771787,0.549476,-1293.817383,294.500488,0.000000
55.110004,65.197212,-1293.772949,-0.001065,0.002164,0.054973,290.011688,14.773900,0.549733,-1293.772949,294.500488,0.000000
55.410004,65.251945,-1293.817383,-0.001061,0.002168,0.055069,290.255157,14.786302,0.550687,-1293.817383,294.500488,0.000000
55.710003,65.085487,-1293.817383,-0.001061,0.002169,0.055096,289.514709,14.748582,0.550960,-1293.817383,294.500488,0.000000
56.010002,65.371483,-1293.817383,-0.001061,0.002175,0.055234,290.786865,14.813390,0.552337,-1293.817383,294.500488,0.000000
56.310001,65.231468,-1293.817383,-0.001052,0.002175,0.055252,290.164062,14.781662,0.552519,-1293.817383,294.500488,0.000000
56.610004,65.196465,-1293.861938,-0.001061,0.002178,0.055312,290.008362,14.773730,0.553125,-1293.861938,294.500488,0.000000
56.910004,65.168159,-1293.772949,-0.001052,0.002180,0.055364,289.882446,14.767316,0.553639,-1293.772949,294.500488,0.000000
57.210003,65.006172,-1293.861938,-0.001061,0.002180,0.055382,289.161896,14.730610,0.553821,-1293.861938,294.500488,0.000000
57.510002,64.949211,-1293.817383,-0.001048,0.002182,0.055434,288.908508,14.717702,0.554336,-1293.817383,294.500488,0.000000
57.810001,64.801003,-1293.772949,-0.001052,0.002183,0.055452,288.249268,14.684117,0.554517,-1293.772949,294.500488,0.000000
58.110004,64.975273,-1293.817383,-0.001039,0.002187,0.055555,289.024445,14.723607,0.555547,-1293.817383,294.500488,0.000000
58.410004,64.818504,-1293.817383,-0.001030,0.002189,0.055599,288.327118,14.688084,0.555986,-1293.817383,294.500488,0.000000
58.710003,65.772148,-1293.861938,-0.001039,0.002199,0.055850,292.569122,14.904181,0.558499,-1293.861938,294.500488,0.000000
59.010002,65.592293,-1293.817383,-0.001030,0.002199,0.055850,291.769104,14.863425,0.558499,-1293.817383,294.500488,0.000000
59.310001,65.447060,-1293.861938,-0.001030,0.002199,0.055850,291.123047,14.830516,0.558499,-1293.861938,294.500488,0.000000
59.610004,65.245247,-1293.817383,-0.001039,0.002199,0.055850,290.225342,14.784784,0.558499,-1293.817383,294.500488,0.000000
59.910004,65.059425,-1293.817383,-0.001035,0.002199,0.055850,289.398773,14.742677,0.558499,-1293.817383,294.500488,0.000000
60.210003,64.869896,-1293.772949,-0.001030,0.002199,0.055859,288.555695,14.699728,0.558590,-1293.772949,294.500488,0.000000
60.510002,64.696358,-1293.817383,-0.001022,0.002199,0.055859,287.783783,14.660404,0.558590,-1293.817383,294.500488,0.000000
60.810001,64.505333,-1293.817383,-0.001030,0.002199,0.055859,286.934052,14.617118,0.558590,-1293.817383,294.500488,0.000000
61.110004,64.323250,-1293.861938,-0.001022,0.002199,0.055859,286.124115,14.575857,0.558590,-1293.861938,294.500488,0.000000
61.410004,66.747017,-1293.861938,-0.001009,0.002050,0.052070,296.905548,15.125090,0.520696,-1293.861938,294.500488,0.000000
61.710003,66.499763,-1293.772949,-0.000996,0.002050,0.052070,295.805725,15.069061,0.520696,-1293.772949,294.500488,0.000000
62.010002,66.296074,-1293.817383,-0.001013,0.002050,0.052077,294.899658,15.022905,0.520771,-1293.817383,294.500488,0.000000
62.310001,66.080467,-1293.817383,-0.001000,0.002050,0.052077,293.940613,14.974048,0.520771,-1293.817383,294.500488,0.000000
62.610004,65.843651,-1293.817383,-0.000992,0.002052,0.052112,292.887177,14.920384,0.521119,-1293.817383,294.500488,0.000000
62.910004,65.670113,-1293.861938,-0.000992,0.002074,0.052668,292.115265,14.881061,0.526676,-1293.861938,294.500488,0.000000
63.210003,65.494728,-1293.861938,-0.000996,0.002165,0.055001,291.335114,14.841318,0.550006,-1293.861938,294.500488,0.000000
63.510002,65.314125,-1293.817383,-0.000992,0.002182,0.055434,290.531738,14.800392,0.554336,-1293.817383,294.500488,0.000000
63.810001,65.136879,-1293.906372,-0.001005,0.002188,0.055564,289.743317,14.760228,0.555638,-1293.906372,294.500488,0.000000
64.110001,65.188271,-1293.861938,-0.000996,0.002215,0.056266,289.971924,14.771873,0.562662,-1293.861938,294.500488,0.000000
64.410004,65.385628,-1293.817383,-0.001005,0.002225,0.056518,290.849792,14.816595,0.565176,-1293.817383,294.500488,0.000000
64.710007,65.290291,-1293.817383,-0.000987,0.002225,0.056518,290.425720,14.794991,0.565176,-1293.817383,294.500488,0.000000
65.010002,65.143211,-1293.906372,-0.001009,0.002225,0.056518,289.771484,14.761663,0.565176,-1293.906372,294.500488,0.000000
65.310005,65.203911,-1293.861938,-0.000983,0.002229,0.056613,290.041473,14.775417,0.566129,-1293.861938,294.500488,0.000000
65.610001,65.103737,-1293.861938,-0.000983,0.002230,0.056631,289.595886,14.752718,0.566311,-1293.861938,294.500488,0.000000
65.910004,65.300728,-1293.817383,-0.001000,0.002233,0.056717,290.472137,14.797357,0.567174,-1293.817383,294.500488,0.000000
66.210007,65.210243,-1293.817383,-0.000987,0.002233,0.056717,290.069641,14.776852,0.567174,-1293.817383,294.500488,0.000000
66.510002,65.225502,-1293.817383,-0.000974,0.002235,0.056778,290.137512,14.780310,0.567780,-1293.817383,294.500488,0.000000
66.810005,65.218803,-1293.861938,-0.000970,0.002237,0.056813,290.107727,14.778792,0.568128,-1293.861938,294.500488,0.000000
67.110001,65.206139,-1293.817383,-0.000979,0.002238,0.056855,290.051392,14.775923,0.568552,-1293.817383,294.500488,0.000000
67.410004,65.132408,-1293.817383,-0.000983,0.002239,0.056864,289.723419,14.759214,0.568643,-1293.817383,294.500488,0.000000
67.710007,65.502556,-1293.861938,-0.000974,0.002245,0.057013,291.369934,14.843092,0.570126,-1293.861938,294.500488,0.000000
68.010002,65.419136,-1293.861938,-0.000966,0.002245,0.057013,290.998840,14.824188,0.570126,-1293.861938,294.500488,0.000000
68.310005,65.308540,-1293.861938,-0.000966,0.002245,0.057013,290.506897,14.799127,0.570126,-1293.861938,294.500488,0.000000
68.610001,65.267586,-1293.861938,-0.000970,0.002246,0.057046,290.324707,14.789846,0.570459,-1293.861938,294.500488,0.000000
68.910004,65.303703,-1293.817383,-0.000983,0.002248,0.057099,290.485382,14.798031,0.570989,-1293.817383,294.500488,0.000000
69.210007,65.257164,-1293.817383,-0.000961,0.002249,0.057116,290.278351,14.787484,0.571156,-1293.817383,294.500488,0.000000
69.510002,65.209114,-1293.817383,-0.000979,0.002249,0.057134,290.064636,14.776596,0.571337,-1293.817383,294.500488,0.000000
69.810005,65.217690,-1293.772949,-0.000961,0.002251,0.057185,290.102783,14.778540,0.571852,-1293.772949,294.500488,0.000000
70.110001,65.223640,-1293.817383,-0.000961,0.002252,0.057203,290.129242,14.779888,0.572034,-1293.817383,294.500488,0.000000
70.410004,65.284340,-1293.817383,-0.000970,0.002254,0.057264,290.399261,14.793643,0.572639,-1293.817383,294.500488,0.000000
70.710007,65.242638,-1293.817383,-0.000957,0.002255,0.057272,290.213745,14.784193,0.572715,-1293.817383,294.500488,0.000000
71.010002,65.192360,-1293.772949,-0.000957,0.002255,0.057290,289.990112,14.772799,0.572897,-1293.772949,294.500488,0.000000
71.310005,65.291420,-1293.817383,-0.000961,0.002259,0.057385,290.430756,14.795248,0.573851,-1293.817383,294.500488,0.000000
71.610001,65.310783,-1293.728516,-0.000966,0.002259,0.057385,290.516876,14.799635,0.573851,-1293.728516,294.500488,0.000000
71.910004,65.238914,-1293.817383,-0.000961,0.002259,0.057385,290.197174,14.783349,0.573851,-1293.817383,294.500488,0.000000
72.210007,65.209114,-1293.861938,-0.000957,0.002261,0.057420,290.064636,14.776596,0.574199,-1293.861938,294.500488,0.000000
72.510002,65.226997,-1293.817383,-0.000949,0.002262,0.057455,290.144165,14.780648,0.574547,-1293.817383,294.500488,0.000000
72.810005,65.172997,-1293.772949,-0.000949,0.002263,0.057471,289.903961,14.768412,0.574714,-1293.772949,294.500488,0.000000
73.110001,65.143959,-1293.817383,-0.000944,0.002264,0.057506,289.774811,14.761832,0.575062,-1293.817383,294.500488,0.000000
73.410004,65.165550,-1293.817383,-0.000949,0.002265,0.057524,289.870850,14.766726,0.575243,-1293.817383,294.500488,0.000000
73.710007,65.120125,-1293.817383,-0.000953,0.002265,0.057541,289.668793,14.756431,0.575410,-1293.817383,294.500488,0.000000
74.010002,65.284340,-1293.772949,-0.000931,0.002268,0.057611,290.399261,14.793643,0.576106,-1293.772949,294.500488,0.000000
74.310005,65.229973,-1293.772949,-0.000940,0.002268,0.057620,290.157410,14.781323,0.576197,-1293.772949,294.500488,0.000000
74.610001,65.168526,-1293.817383,-0.000944,0.002269,0.057627,289.884094,14.767399,0.576273,-1293.817383,294.500488,0.000000
74.910004,65.133156,-1293.817383,-0.000949,0.002270,0.057645,289.726746,14.759384,0.576455,-1293.817383,294.500488,0.000000
75.210007,65.179329,-1293.772949,-0.000944,0.002271,0.057688,289.932129,14.769847,0.576879,-1293.772949,294.500488,0.000000
75.510002,65.165932,-1293.817383,-0.000931,0.002274,0.057767,289.872528,14.766811,0.577666,-1293.817383,294.500488,0.000000
75.810005,65.293648,-1293.817383,-0.000949,0.002275,0.057776,290.440643,14.795753,0.577757,-1293.817383,294.500488,0.000000
76.110001,65.249702,-1293.817383,-0.000936,0.002275,0.057776,290.245178,14.785793,0.577757,-1293.817383,294.500488,0.000000
76.410004,65.298485,-1293.817383,-0.000936,0.002278,0.057862,290.462158,14.796848,0.578620,-1293.817383,294.500488,0.000000
76.710007,65.352119,-1293.817383,-0.000936,0.002278,0.057862,290.700745,14.809002,0.578620,-1293.817383,294.500488,0.000000
77.010002,65.288811,-1293.817383,-0.000927,0.002278,0.057871,290.419128,14.794656,0.578710,-1293.817383,294.500488,0.000000
77.310005,65.254555,-1293.817383,-0.000927,0.002279,0.057879,290.266754,14.786894,0.578786,-1293.817383,294.500488,0.000000
77.610001,65.265724,-1293.817383,-0.000936,0.002280,0.057923,290.316437,14.789425,0.579225,-1293.817383,294.500488,0.000000
77.910004,65.232201,-1293.817383,-0.000914,0.002281,0.057932,290.167328,14.781828,0.579316,-1293.817383,294.500488,0.000000
78.210007,65.188271,-1293.772949,-0.000923,0.002281,0.057932,289.971924,14.771873,0.579316,-1293.772949,294.500488,0.000000
78.510002,65.300728,-1293.861938,-0.000931,0.002284,0.058009,290.472137,14.797357,0.580088,-1293.861938,294.500488,0.000000
78.810005,65.262749,-1293.817383,-0.000918,0.002284,0.058009,290.303192,14.788750,0.580088,-1293.817383,294.500488,0.000000
79.110001,65.212471,-1293.817383,-0.000931,0.002286,0.058053,290.079559,14.777357,0.580527,-1293.817383,294.500488,0.000000
79.410004,65.278389,-1293.817383,-0.000914,0.002286,0.058062,290.372772,14.792295,0.580618,-1293.817383,294.500488,0.000000
79.710007,65.219917,-1293.817383,-0.000927,0.002286,0.058069,290.112671,14.779044,0.580694,-1293.817383,294.500488,0.000000
80.010002,65.194969,-1293.772949,-0.000910,0.002287,0.058088,290.001709,14.773392,0.580875,-1293.772949,294.500488,0.000000
80.310005,65.151024,-1293.861938,-0.000918,0.002287,0.058088,289.806213,14.763433,0.580875,-1293.861938,294.500488,0.000000
80.610001,65.394569,-1293.772949,-0.000905,0.002291,0.058200,290.889587,14.818621,0.581996,-1293.772949,294.500488,0.000000
80.910004,65.362541,-1293.817383,-0.000897,0.002291,0.058200,290.747101,14.811363,0.581996,-1293.817383,294.500488,0.000000
81.210007,65.299614,-1293.772949,-0.000918,0.002291,0.058200,290.467194,14.797104,0.581996,-1293.772949,294.500488,0.000000
81.510002,65.235939,-1293.772949,-0.000905,0.002292,0.058209,290.183960,14.782675,0.582087,-1293.772949,294.500488,0.000000
81.810005,65.241142,-1293.772949,-0.000918,0.002293,0.058243,290.207092,14.783854,0.582435,-1293.772949,294.500488,0.000000
82.110001,65.216194,-1293.817383,-0.000910,0.002294,0.058260,290.096130,14.778201,0.582601,-1293.817383,294.500488,0.000000
82.410004,65.213966,-1293.817383,-0.000910,0.002294,0.058269,290.086212,14.777697,0.582692,-1293.817383,294.500488,0.000000
82.710007,65.160347,-1293.817383,-0.000918,0.002294,0.058269,289.847687,14.765546,0.582692,-1293.817383,294.500488,0.000000
83.010002,65.547615,-1293.772949,-0.000901,0.002299,0.058383,291.570343,14.853302,0.583828,-1293.772949,294.500488,0.000000
83.310005,65.483559,-1293.817383,-0.000914,0.002299,0.058383,291.285431,14.838787,0.583828,-1293.817383,294.500488,0.000000
83.610001,65.388603,-1293.817383,-0.000901,0.002299,0.058383,290.863037,14.817269,0.583828,-1293.817383,294.500488,0.000000
83.910004,65.297371,-1293.772949,-0.000910,0.002299,0.058383,290.457214,14.796596,0.583828,-1293.772949,294.500488,0.000000
84.210007,65.247841,-1293.817383,-0.000901,0.002299,0.058383,290.236877,14.785373,0.583828,-1293.817383,294.500488,0.000000
84.510002,65.145073,-1293.772949,-0.000888,0.002299,0.058390,289.779755,14.762084,0.583903,-1293.772949,294.500488,0.000000
84.810005,65.075432,-1293.772949,-0.000901,0.002299,0.058390,289.469971,14.746304,0.583903,-1293.772949,294.500488,0.000000
85.110001,64.998726,-1293.861938,-0.000905,0.002299,0.058390,289.128784,14.728922,0.583903,-1293.861938,294.500488,0.000000
85.410004,64.926125,-1293.817383,-0.000897,0.002299,0.058390,288.805817,14.712470,0.583903,-1293.817383,294.500488,0.000000
85.710007,65.600105,-1293.817383,-0.000897,0.002311,0.058704,291.803833,14.865196,0.587037,-1293.817383,294.500488,0.000000
86.010002,65.672722,-1293.772949,-0.000897,0.002309,0.058642,292.126862,14.881652,0.586416,-1293.772949,294.500488,0.000000
86.310005,65.642937,-1293.861938,-0.000897,0.002309,0.058642,291.994354,14.874902,0.586416,-1293.861938,294.500488,0.000000
86.610001,65.583733,-1293.817383,-0.000897,0.002309,0.058642,291.731018,14.861486,0.586416,-1293.817383,294.500488,0.000000
86.910004,65.543510,-1293.817383,-0.000884,0.002309,0.058642,291.552094,14.852372,0.586416,-1293.817383,294.500488,0.000000
87.210007,65.481331,-1293.772949,-0.000892,0.002309,0.058642,291.275513,14.838282,0.586416,-1293.772949,294.500488,0.000000
87.510002,65.400520,-1293.772949,-0.000888,0.002309,0.058642,290.916046,14.819970,0.586416,-1293.772949,294.500488,0.000000
87.810005,65.327904,-1293.772949,-0.000884,0.002309,0.058642,290.593018,14.803514,0.586416,-1293.772949,294.500488,0.000000
88.110001,65.273918,-1293.817383,-0.000880,0.002309,0.058642,290.352875,14.791282,0.586416,-1293.817383,294.500488,0.000000
88.410004,65.203911,-1293.772949,-0.000884,0.002309,0.058642,290.041473,14.775417,0.586416,-1293.772949,294.500488,0.000000
88.710007,65.135765,-1293.817383,-0.000892,0.002309,0.058651,289.738342,14.759975,0.586507,-1293.817383,294.500488,0.000000
89.010002,65.055336,-1293.817383,-0.000880,0.002309,0.058651,289.380585,14.741750,0.586507,-1293.817383,294.500488,0.000000
89.310005,65.008415,-1293.772949,-0.000892,0.002309,0.058651,289.171875,14.731118,0.586507,-1293.772949,294.500488,0.000000
89.610001,64.946220,-1293.772949,-0.000880,0.002309,0.058651,288.895203,14.717024,0.586507,-1293.772949,294.500488,0.000000
89.910004,64.927986,-1293.861938,-0.000871,0.002311,0.058704,288.814117,14.712892,0.587037,-1293.861938,294.500488,0.000000
90.210007,65.093681,-1293.772949,-0.000880,0.002315,0.058799,289.551147,14.750440,0.587991,-1293.772949,294.500488,0.000000
90.510002,65.152153,-1293.772949,-0.000880,0.002315,0.058799,289.811249,14.763689,0.587991,-1293.772949,294.500488,0.000000
90.810005,65.101509,-1293.772949,-0.000888,0.002315,0.058799,289.585968,14.752213,0.587991,-1293.772949,294.500488,0.000000
91.110001,65.066124,-1293.817383,-0.000880,0.002315,0.058799,289.428589,14.744194,0.587991,-1293.817383,294.500488,0.000000
91.410004,65.019218,-1293.861938,-0.000884,0.002315,0.058799,289.219940,14.733565,0.587991,-1293.861938,294.500488,0.000000
91.710007,64.957390,-1293.817383,-0.000871,0.002315,0.058799,288.944916,14.719555,0.587991,-1293.817383,294.500488,0.000000
92.010002,64.899300,-1293.817383,-0.000875,0.002317,0.058841,288.686493,14.706392,0.588415,-1293.817383,294.500488,0.000000
92.310005,64.959251,-1293.772949,-0.000862,0.002317,0.058860,288.953186,14.719976,0.588597,-1293.772949,294.500488,0.000000
92.610001,64.935799,-1293.772949,-0.000875,0.002317,0.058860,288.848846,14.714663,0.588597,-1293.772949,294.500488,0.000000
92.910004,64.970802,-1293.772949,-0.000871,0.002322,0.058972,289.004578,14.722594,0.589717,-1293.772949,294.500488,0.000000
93.210007,65.375206,-1293.772949,-0.000871,0.002324,0.059025,290.803436,14.814233,0.590247,-1293.772949,294.500488,0.000000
93.510002,65.348763,-1293.772949,-0.000854,0.002324,0.059025,290.685822,14.808242,0.590247,-1293.772949,294.500488,0.000000
93.810005,65.320457,-1293.817383,-0.000875,0.002324,0.059025,290.559906,14.801826,0.590247,-1293.817383,294.500488,0.000000
94.110008,65.287697,-1293.772949,-0.000867,0.002324,0.059025,290.414185,14.794403,0.590247,-1293.772949,294.500488,0.000000
94.410004,65.235558,-1293.728516,-0.000862,0.002324,0.059025,290.182251,14.782589,0.590247,-1293.728516,294.500488,0.000000
94.710007,65.195351,-1293.772949,-0.000871,0.002324,0.059025,290.003418,14.773478,0.590247,-1293.772949,294.500488,0.000000
95.010002,65.148048,-1293.817383,-0.000849,0.002324,0.059041,289.792999,14.762759,0.590413,-1293.817383,294.500488,0.000000
95.310005,65.163689,-1293.772949,-0.000858,0.002326,0.059076,289.862549,14.766303,0.590762,-1293.772949,294.500488,0.000000
95.610008,65.184547,-1293.817383,-0.000862,0.002328,0.059137,289.955353,14.771029,0.591367,-1293.817383,294.500488,0.000000
95.910004,65.309654,-1293.772949,-0.000871,0.002329,0.059146,290.511841,14.799379,0.591458,-1293.772949,294.500488,0.000000
96.210007,65.283592,-1293.728516,-0.000867,0.002329,0.059146,290.395935,14.793474,0.591458,-1293.728516,294.500488,0.000000
96.510002,65.248222,-1293.772949,-0.000854,0.002329,0.059153,290.238586,14.785459,0.591534,-1293.772949,294.500488,0.000000
96.810005,65.224022,-1293.728516,-0.000858,0.002329,0.059162,290.130951,14.779975,0.591624,-1293.728516,294.500488,0.000000
97.110008,65.230339,-1293.817383,-0.000862,0.002330,0.059172,290.159027,14.781406,0.591715,-1293.817383,294.500488,0.000000
97.410004,65.173744,-1293.728516,-0.000858,0.002330,0.059188,289.907288,14.768581,0.591882,-1293.728516,294.500488,0.000000
97.710007,65.318596,-1293.817383,-0.000849,0.002333,0.059249,290.551636,14.801406,0.592487,-1293.817383,294.500488,0.000000
98.010002,65.314125,-1293.772949,-0.000854,0.002333,0.059249,290.531738,14.800392,0.592487,-1293.772949,294.500488,0.000000
98.310005,65.295891,-1293.817383,-0.000854,0.002333,0.059267,290.450623,14.796261,0.592669,-1293.817383,294.500488,0.000000
98.610008,65.275032,-1293.772949,-0.000841,0.002333,0.059267,290.357849,14.791533,0.592669,-1293.772949,294.500488,0.000000
98.910004,65.272057,-1293.817383,-0.000858,0.002334,0.059284,290.344604,14.790859,0.592836,-1293.817383,294.500488,0.000000
99.210007,65.314507,-1293.772949,-0.000867,0.002335,0.059318,290.533447,14.800479,0.593184,-1293.772949,294.500488,0.000000
99.510002,65.299980,-1293.817383,-0.000854,0.002335,0.059318,290.468811,14.797187,0.593184,-1293.817383,294.500488,0.000000
99.810005,65.264229,-1293.772949,-0.000862,0.002336,0.059327,290.309784,14.789085,0.593275,-1293.772949,294.500488,0.000000
100.110008,65.296623,-1293.861938,-0.000841,0.002337,0.059353,290.453888,14.796426,0.593532,-1293.861938,294.500488,0.000000
100.410004,65.285454,-1293.772949,-0.000849,0.002337,0.059362,290.404205,14.793895,0.593623,-1293.772949,294.500488,0.000000
100.710007,65.279121,-1293.817383,-0.000858,0.002337,0.059371,290.376038,14.792460,0.593714,-1293.817383,1681.640991,0.000000
101.010002,65.242256,-1293.772949,-0.000845,0.002331,0.059206,290.212036,14.784107,0.592064,-1293.772949,0.059232,0.000000
101.310005,65.088844,-1293.772949,-0.000854,0.002320,0.058937,289.529633,14.749343,0.589369,-1293.772949,0.058729,0.000000
101.610008,65.056816,-1293.817383,-0.000836,0.002302,0.058469,289.387177,14.742085,0.584691,-1293.817383,0.058234,0.000000
101.910004,64.930214,-1293.817383,-0.000841,0.002288,0.058113,288.824005,14.713397,0.581133,-1293.817383,0.057732,0.000000
102.210007,64.855370,-1293.861938,-0.000836,0.002276,0.057818,288.491089,14.696436,0.578181,-1293.861938,0.057229,0.000000
102.510002,64.790581,-1293.772949,-0.000841,0.002258,0.057359,288.202911,14.681756,0.573593,-1293.772949,0.056734,0.000000
102.810005,64.729500,-1293.817383,-0.000836,0.002241,0.056917,287.931183,14.667914,0.569173,-1293.817383,0.056231,0.000000
103.110008,64.669930,-1293.817383,-0.000849,0.002213,0.056215,287.666199,14.654415,0.562148,-1293.817383,0.055738,0.000000
103.410004,64.592476,-1293.861938,-0.000824,0.002194,0.055729,287.321686,14.636864,0.557288,-1293.861938,0.055234,0.000000
103.710007,64.569389,-1293.861938,-0.000832,0.002173,0.055182,287.218994,14.631633,0.551823,-1293.861938,0.054731,0.000000
104.010002,64.476662,-1293.817383,-0.000841,0.002159,0.054826,286.806519,14.610620,0.548265,-1293.817383,0.054238,0.000000
104.310005,64.383568,-1293.817383,-0.000836,0.002144,0.054462,286.392426,14.589524,0.544616,-1293.817383,0.053733,0.000000
104.610008,64.233879,-1293.817383,-0.000824,0.002125,0.053977,285.726562,14.555605,0.539771,-1293.817383,0.053231,0.000000
104.910004,64.105782,-1293.906372,-0.000828,0.002110,0.053587,285.156769,14.526578,0.535865,-1293.906372,0.052737,0.000000
105.210007,63.220284,-1293.817383,-0.000845,0.002085,0.052963,281.217865,14.325921,0.529628,-1293.817383,0.052233,0.000000
105.510002,62.545540,-1293.861938,-0.000819,0.002066,0.052484,278.216461,14.173021,0.524844,-1293.861938,0.051730,0.000000
105.810005,62.051033,-1293.817383,-0.000836,0.002054,0.052165,276.016785,14.060965,0.521649,-1293.817383,0.051237,0.000000
106.110008,60.650162,-1293.817383,-0.000828,0.002029,0.051540,269.785400,13.743523,0.515397,-1293.817383,0.050733,0.000000
106.410004,59.693542,-1293.772949,-0.000828,0.002014,0.051149,265.530151,13.526751,0.511491,-1293.772949,0.050230,0.000000
106.710007,58.478485,-1293.772949,-0.000832,0.001996,0.050690,260.125305,13.251413,0.506903,-1293.772949,0.049737,0.000000
107.010002,56.953995,-1293.861938,-0.000824,0.001973,0.050126,253.344025,12.905959,0.501256,-1293.861938,0.049232,0.000000
107.310005,55.139793,-1293.817383,-0.000832,0.001952,0.049588,245.274048,12.494856,0.495882,-1293.817383,0.048730,0.000000
107.610008,53.846176,-1293.817383,-0.000828,0.001937,0.049198,239.519760,12.201717,0.491976,-1293.817383,0.048236,0.000000
107.910004,52.199547,-1293.861938,-0.000815,0.001916,0.048678,232.195175,11.828587,0.486783,-1293.861938,0.047732,0.000000
108.210007,50.171234,-1293.817383,-0.000832,0.001899,0.048244,223.172791,11.368964,0.482438,-1293.817383,0.047229,0.000000
108.510002,48.299316,-1293.861938,-0.000836,0.001880,0.047759,214.846085,10.944781,0.477593,-1293.861938,0.046736,0.000000
108.810005,46.827698,-1293.861938,-0.000828,0.001866,0.047404,208.300003,10.611308,0.474035,-1293.861938,0.046232,0.000000
109.110008,44.441910,-1293.817383,-0.000832,0.001845,0.046874,197.687485,10.070682,0.468737,-1293.817383,0.045729,0.000000
109.410004,41.934723,-1293.817383,-0.000836,0.001821,0.046250,186.534958,9.502544,0.462499,-1293.817383,0.045236,0.000000
109.710007,40.471672,-1293.772949,-0.000849,0.001808,0.045911,180.026993,9.171012,0.459108,-1293.772949,0.044731,0.000000
110.010002,37.837883,-1293.861938,-0.000845,0.001779,0.045192,168.311310,8.574186,0.451916,-1293.861938,0.044229,0.000000
110.310005,36.369621,-1293.817383,-0.000845,0.001767,0.044880,161.780151,8.241473,0.448798,-1293.817383,0.043735,0.000000
110.610008,34.617607,-1293.861938,-0.000854,0.001750,0.044445,153.986801,7.844462,0.444453,-1293.861938,0.043231,0.000000
110.910004,32.727440,-1293.772949,-0.000862,0.001730,0.043934,145.578918,7.416144,0.439335,-1293.772949,0.042728,0.000000
111.210007,30.387085,-1293.817383,-0.000867,0.001701,0.043205,135.168503,6.885812,0.432053,-1293.817383,0.042235,0.000000
111.510002,28.155457,-1293.817383,-0.000871,0.001686,0.042816,125.241722,6.380117,0.428162,-1293.817383,0.041731,0.000000
111.810005,25.379044,-1293.772949,-0.000880,0.001658,0.042114,112.891624,5.750974,0.421138,-1293.772949,0.041228,0.000000
112.110008,24.188568,-1293.817383,-0.000884,0.001646,0.041809,107.596123,5.481208,0.418095,-1293.817383,0.040735,0.000000
112.410004,22.068657,-1293.817383,-0.000880,0.001626,0.041298,98.166290,5.000829,0.412977,-1293.817383,0.040232,0.000000
112.710007,20.355370,-1293.861938,-0.000892,0.001609,0.040865,90.545204,4.612593,0.408648,-1293.861938,0.039728,0.000000
113.010002,18.190025,-1293.817383,-0.000897,0.001586,0.040283,80.913277,4.121919,0.402834,-1293.817383,0.039234,0.000000
113.310005,15.893974,-1293.861938,-0.000892,0.001565,0.039746,70.699928,3.601626,0.397459,-1293.861938,0.038732,0.000000
113.610008,14.462944,-1293.817383,-0.000905,0.001550,0.039381,64.334389,3.277350,0.393811,-1293.817383,0.038227,0.000000
113.910004,12.205994,-1293.861938,-0.000927,0.001527,0.038792,54.294971,2.765918,0.387921,-1293.861938,0.037734,0.000000
114.210007,10.483772,-1293.861938,-0.000918,0.001510,0.038349,46.634148,2.375657,0.383486,-1293.861938,0.037231,0.000000
114.510002,8.931725,-1293.817383,-0.000927,0.001492,0.037899,39.730293,2.023958,0.378989,-1293.817383,0.036727,0.000000
114.810005,7.026299,-1293.817383,-0.000940,0.001474,0.037448,31.254538,1.592182,0.374478,-1293.817383,0.036234,0.000000
115.110008,4.237968,-1293.861938,-0.000961,0.001444,0.036676,18.851425,0.960337,0.366756,-1293.861938,0.035731,0.000000
115.410004,2.979355,-1293.817383,-0.000944,0.001429,0.036285,13.252832,0.675131,0.362850,-1293.817383,0.035227,0.000000
115.710007,1.572159,-1293.772949,-0.000966,0.001406,0.035722,6.993312,0.356256,0.357218,-1293.772949,0.034733,0.000000
116.010002,-0.167198,-1293.772949,-0.000992,0.001390,0.035315,-0.743735,-0.037888,0.353146,-1293.772949,0.034231,0.000000
116.310005,-1.450390,-1293.817383,-0.000983,0.001375,0.034924,-6.451656,-0.328663,0.349240,-1293.817383,0.033736,0.000000
116.610008,-3.091434,-1293.817383,-0.001000,0.001354,0.034387,-13.751388,-0.700529,0.343865,-1293.817383,0.033233,0.000000
116.910004,-0.127350,-1293.772949,-0.001052,0.001335,0.033917,-0.566480,-0.028858,0.339172,-1293.772949,0.032730,0.000000
117.210007,-0.107986,-1293.817383,-0.001091,0.001313,0.033345,-0.480348,-0.024470,0.333449,-1293.817383,0.032235,0.000000
117.510002,-0.075966,-1293.817383,-0.001108,0.001292,0.032817,-0.337913,-0.017214,0.328166,-1293.817383,0.031733,0.000000
117.810005,-0.045059,-1293.728516,-0.001151,0.001270,0.032261,-0.200433,-0.010211,0.322609,-1293.728516,0.031230,0.000000
118.110008,-0.044312,-1293.817383,-0.001186,0.001253,0.031819,-0.197107,-0.010041,0.318189,-1293.817383,0.030735,0.000000
118.410004,-0.040215,-1293.817383,-0.001212,0.001231,0.031265,-0.178883,-0.009113,0.312647,-1293.817383,0.030232,0.000000
118.710007,-0.016388,-1293.772949,-0.001259,0.001209,0.030700,-0.072897,-0.003714,0.307000,-1293.772949,0.029730,0.000000
119.010002,-0.035004,-1293.861938,-0.001293,0.001189,0.030197,-0.155704,-0.007932,0.301974,-1293.861938,0.029235,0.000000
119.310005,-0.029045,-1293.772949,-0.001324,0.001172,0.029772,-0.129199,-0.006582,0.297720,-1293.772949,0.028732,0.000000
119.610008,0.052879,-1293.772949,-0.001367,0.001149,0.029174,0.235219,0.011983,0.291740,-1293.772949,0.028229,0.000000
119.910004,0.031654,-1293.817383,-0.001393,0.001137,0.028879,0.140806,0.007173,0.288787,-1293.817383,0.027734,0.000000
120.210007,0.026436,-1293.772949,-0.001427,0.001113,0.028272,0.117593,0.005990,0.282717,-1293.772949,0.027232,0.000000
120.510002,0.018616,-1293.728516,-0.001470,0.001094,0.027778,0.082807,0.004218,0.277781,-1293.728516,0.026729,0.000000
120.800003,0.023834,-1293.817383,-0.001509,0.001082,0.027492,0.106020,0.005401,0.274920,-1293.817383,0.027336,0.000000