File: Data/Sima compression/P2-15-2_10302024_171811.csv
Time (sec),S:Load (lbs),S:HL1 (DIM),S:LVDT (in),S:Position (in),Ch:Position (mm),Ch:Load (N),Ch:Stress (MPa),Ch:Strain (mm/mm),Ch:HL1 (DIM),Set Point (),Cycles ()
0.210000,-0.003723,-1293.950806,-0.008852,-0.005640,-0.143248,-0.016561,-0.000844,-1.432477,-1293.950806,-0.143066,0.000000
0.520000,-0.001862,-1294.084351,-0.008856,-0.005571,-0.141496,-0.008281,-0.000422,-1.414960,-1294.084351,-0.141002,0.000000
0.830000,-0.019737,-1293.906372,-0.008765,-0.005395,-0.137030,-0.087796,-0.004473,-1.370299,-1293.906372,-0.135834,0.000000
1.140000,0.026436,-1294.039795,-0.008550,-0.005186,-0.131731,0.117593,0.005990,-1.317310,-1294.039795,-0.130665,0.000000
1.450000,-0.001114,-1293.950806,-0.008343,-0.004988,-0.126693,-0.004955,-0.000252,-1.266925,-1293.950806,-0.125497,0.000000
1.760000,-0.036491,-1293.995361,-0.008119,-0.004781,-0.121438,-0.162322,-0.008269,-1.214376,-1293.995361,-0.120345,0.000000
2.070000,-0.008568,-1293.995361,-0.007938,-0.004589,-0.116573,-0.038112,-0.001941,-1.165733,-1293.995361,-0.115176,0.000000
2.380000,-0.056976,-1293.995361,-0.007722,-0.004376,-0.111161,-0.253443,-0.012911,-1.111609,-1293.995361,-0.110007,0.000000
2.690000,-0.037613,-1293.995361,-0.007493,-0.004170,-0.105906,-0.167311,-0.008523,-1.059059,-1293.995361,-0.104839,0.000000
3.000000,0.020851,-1293.906372,-0.007286,-0.003968,-0.100798,0.092750,0.004725,-1.007978,-1293.906372,-0.099670,0.000000
3.310000,-0.018990,-1293.995361,-0.007075,-0.003766,-0.095664,-0.084470,-0.004303,-0.956640,-1293.995361,-0.094519,0.000000
3.620000,0.016014,-1294.039795,-0.006881,-0.003571,-0.090703,0.071234,0.003629,-0.907027,-1294.039795,-0.089351,0.000000
3.930000,-0.028671,-1293.950806,-0.006666,-0.003365,-0.085483,-0.127536,-0.006497,-0.854826,-1293.950806,-0.084182,0.000000
4.240000,-0.016014,-1294.039795,-0.006459,-0.003154,-0.080114,-0.071234,-0.003629,-0.801141,-1294.039795,-0.079013,0.000000
4.550000,-0.008568,-1293.906372,-0.006252,-0.002953,-0.075015,-0.038112,-0.001941,-0.750151,-1293.906372,-0.073861,0.000000
4.860000,-0.064796,-1293.995361,-0.006028,-0.002748,-0.069795,-0.288229,-0.014683,-0.697950,-1293.995361,-0.068693,0.000000
5.170000,0.017502,-1294.039795,-0.005846,-0.002553,-0.064834,0.077852,0.003966,-0.648337,-1294.039795,-0.063524,0.000000
5.480000,0.007446,-1293.950806,-0.005609,-0.002342,-0.059474,0.033123,0.001687,-0.594743,-1293.950806,-0.058356,0.000000
5.790000,0.033142,-1294.039795,-0.005411,-0.002139,-0.054331,0.147423,0.007510,-0.543314,-1294.039795,-0.053205,0.000000
6.100000,0.000748,-1293.995361,-0.005195,-0.001937,-0.049188,0.003326,0.000169,-0.491885,-1293.995361,-0.048036,0.000000
6.410000,-0.047295,-1293.995361,-0.004993,-0.001732,-0.043985,-0.210377,-0.010717,-0.439850,-1293.995361,-0.042868,0.000000
6.720000,-0.009682,-1293.995361,-0.004790,-0.001534,-0.038956,-0.043066,-0.002194,-0.389557,-1293.995361,-0.037699,0.000000
7.030000,-0.029419,-1293.995361,-0.004583,-0.001330,-0.033787,-0.130862,-0.006666,-0.337870,-1293.995361,-0.032547,0.000000
7.340000,0.021973,-1293.995361,-0.004372,-0.001123,-0.028532,0.097739,0.004979,-0.285321,-1293.995361,-0.027378,0.000000
7.650001,0.036491,-1293.950806,-0.004152,-0.000919,-0.023345,0.162322,0.008269,-0.233452,-1293.950806,-0.022210,0.000000
7.960001,0.025696,-1293.995361,-0.003949,-0.000718,-0.018230,0.114301,0.005823,-0.182296,-1293.995361,-0.017041,0.000000
8.270000,0.027184,-1293.950806,-0.003738,-0.000523,-0.013286,0.120918,0.006160,-0.132865,-1293.950806,-0.011889,0.000000
8.580001,0.010429,-1293.950806,-0.003523,-0.000313,-0.007944,0.046392,0.002363,-0.079437,-1293.950806,-0.006720,0.000000
8.890000,0.053246,-1294.084351,-0.003320,-0.000104,-0.002636,0.236848,0.012066,-0.026358,-1294.084351,-0.001552,0.000000
9.200001,0.080429,-1294.039795,-0.003221,-0.000001,-0.000035,0.357766,0.018225,-0.000348,-1294.039795,0.000209,0.000000
9.510000,0.058090,-1294.039795,-0.003221,-0.000001,-0.000035,0.258398,0.013163,-0.000348,-1294.039795,0.000209,0.000000
9.820001,0.092720,-1294.039795,-0.003229,0.000000,0.000009,0.412439,0.021011,0.000091,-1294.039795,0.000686,0.000000
10.130000,0.110222,-1293.950806,-0.003229,0.000008,0.000191,0.490291,0.024977,0.001908,-1293.950806,0.001205,0.000000
10.440001,0.141129,-1293.995361,-0.003221,0.000019,0.000486,0.627771,0.031980,0.004860,-1293.995361,0.001717,0.000000
10.750001,0.301620,-1293.906372,-0.003191,0.000056,0.001431,1.341675,0.068348,0.014307,-1293.906372,0.002238,0.000000
11.060000,0.450943,-1293.950806,-0.003165,0.000075,0.001908,2.005895,0.102185,0.019076,-1293.950806,0.002749,0.000000
11.370001,0.686279,-1293.995361,-0.003147,0.000092,0.002333,3.052723,0.155513,0.023330,-1293.995361,0.003270,0.000000
11.680000,1.116745,-1293.950806,-0.003126,0.000116,0.002940,4.967530,0.253058,0.029401,-1293.950806,0.003789,0.000000
11.990001,1.426933,-1293.950806,-0.003113,0.000129,0.003287,6.347316,0.323348,0.032868,-1293.950806,0.004301,0.000000
12.300000,1.752754,-1293.950806,-0.003109,0.000143,0.003643,7.796640,0.397180,0.036426,-1293.950806,0.004822,0.000000
12.610001,2.614426,-1294.039795,-0.003083,0.000174,0.004431,11.629546,0.592437,0.044314,-1294.039795,0.005334,0.000000
12.920001,3.142448,-1293.906372,-0.003070,0.000195,0.004943,13.978309,0.712089,0.049431,-1293.906372,0.005854,0.000000
13.230000,3.769897,-1293.995361,-0.003057,0.000214,0.005447,16.769341,0.854271,0.054472,-1293.995361,0.006366,0.000000
13.540001,4.570869,-1293.995361,-0.003044,0.000237,0.006010,20.332243,1.035774,0.060104,-1293.995361,0.006885,0.000000
13.850000,5.191246,-1294.039795,-0.003031,0.000253,0.006436,23.091816,1.176353,0.064358,-1294.039795,0.007406,0.000000
14.160001,5.735657,-1293.995361,-0.003022,0.000268,0.006817,25.513475,1.299718,0.068174,-1293.995361,0.007918,0.000000
14.470000,6.866920,-1293.995361,-0.002992,0.000296,0.007511,30.545588,1.556067,0.075107,-1293.995361,0.008439,0.000000
14.780001,7.693214,-1293.950806,-0.002966,0.000318,0.008083,34.221127,1.743307,0.080830,-1293.950806,0.008951,0.000000
15.090001,8.251030,-1293.995361,-0.002958,0.000333,0.008465,36.702415,1.869710,0.084645,-1293.995361,0.009470,0.000000
15.400001,9.328674,-1293.950806,-0.002953,0.000356,0.009053,41.496017,2.113908,0.090535,-1293.950806,0.009991,0.000000
15.710001,10.123688,-1294.084351,-0.002932,0.000377,0.009565,45.032413,2.294060,0.095652,-1294.084351,0.010502,0.000000
16.020000,10.954826,-1293.950806,-0.002928,0.000395,0.010025,48.729500,2.482399,0.100254,-1293.950806,0.011023,0.000000
16.330000,11.745743,-1293.995361,-0.002902,0.000418,0.010616,52.247673,2.661623,0.106159,-1293.995361,0.011535,0.000000
16.640001,13.165970,-1294.039795,-0.002897,0.000442,0.011231,58.565159,2.983451,0.112305,-1294.039795,0.012054,0.000000
16.950001,13.714851,-1293.950806,-0.002867,0.000460,0.011673,61.006706,3.107830,0.116726,-1293.950806,0.012566,0.000000
17.260000,14.680786,-1293.995361,-0.002863,0.000480,0.012184,65.303398,3.326714,0.121843,-1293.995361,0.013087,0.000000
17.570002,15.451599,-1293.950806,-0.002850,0.000498,0.012645,68.732147,3.501383,0.126446,-1293.950806,0.013607,0.000000
17.880001,15.923393,-1293.995361,-0.002833,0.000513,0.013026,70.830788,3.608292,0.130261,-1293.995361,0.014119,0.000000
18.190001,16.708725,-1293.995361,-0.002820,0.000532,0.013503,74.324120,3.786251,0.135030,-1293.995361,0.014638,0.000000
18.500000,18.036606,-1293.950806,-0.002785,0.000558,0.014162,80.230827,4.087153,0.141616,-1293.950806,0.015150,0.000000
18.810001,18.770920,-1293.995361,-0.002794,0.000580,0.014726,83.497223,4.253551,0.147263,-1293.995361,0.015671,0.000000
19.120001,19.423691,-1293.950806,-0.002772,0.000598,0.015185,86.400894,4.401471,0.151850,-1293.950806,0.016192,0.000000
19.430000,20.336746,-1294.084351,-0.002755,0.000622,0.015810,90.462364,4.608372,0.158103,-1294.084351,0.016703,0.000000
19.740002,20.822693,-1293.995361,-0.002729,0.000636,0.016157,92.623962,4.718490,0.161570,-1293.995361,0.017223,0.000000
20.050001,21.244965,-1293.950806,-0.002721,0.000652,0.016564,94.502319,4.814178,0.165642,-1293.950806,0.017735,0.000000
20.360001,22.909470,-1293.995361,-0.002712,0.000684,0.017371,101.906410,5.191360,0.173712,-1293.995361,0.018255,0.000000
20.670000,23.222267,-1293.861938,-0.002695,0.000701,0.017804,103.297806,5.262241,0.178041,-1293.861938,0.018767,0.000000
20.980001,23.785294,-1294.039795,-0.002673,0.000719,0.018255,105.802269,5.389824,0.182553,-1294.039795,0.019288,0.000000
21.290001,24.804474,-1293.906372,-0.002656,0.000745,0.018932,110.335808,5.620774,0.189320,-1293.906372,0.019807,0.000000
21.600000,25.158974,-1293.950806,-0.002652,0.000761,0.019339,111.912704,5.701105,0.193393,-1293.950806,0.020319,0.000000
21.910002,25.693329,-1293.995361,-0.002617,0.000778,0.019756,114.289635,5.822192,0.197556,-1293.995361,0.020840,0.000000
22.220001,26.909492,-1293.950806,-0.002608,0.000808,0.020519,119.699402,6.097778,0.205187,-1293.950806,0.021351,0.000000
22.530001,27.272560,-1293.950806,-0.002583,0.000823,0.020909,121.314407,6.180050,0.209093,-1293.950806,0.021872,0.000000
22.840000,27.786804,-1293.950806,-0.002565,0.000846,0.021482,123.601875,6.296580,0.214815,-1293.950806,0.022384,0.000000
23.150002,27.802444,-1293.950806,-0.002539,0.000857,0.021768,123.671448,6.300124,0.217677,-1293.950806,0.022903,0.000000
23.460001,28.787743,-1293.995361,-0.002535,0.000884,0.022461,128.054276,6.523396,0.224611,-1293.995361,0.023424,0.000000
23.770000,29.247253,-1293.906372,-0.002505,0.000902,0.022921,130.098282,6.627522,0.229213,-1293.906372,0.023936,0.000000
24.080002,28.782532,-1293.995361,-0.002488,0.000910,0.023112,128.031097,6.522215,0.231121,-1293.995361,0.024456,0.000000
24.390001,30.479057,-1293.950806,-0.002471,0.000944,0.023970,135.577621,6.906653,0.239705,-1293.950806,0.024968,0.000000
24.700001,30.859253,-1293.906372,-0.002440,0.000964,0.024491,137.268814,6.992806,0.244913,-1293.906372,0.025487,0.000000
25.010002,31.168694,-1293.995361,-0.002436,0.000983,0.024959,138.645279,7.062927,0.249591,-1293.995361,0.026008,0.000000
25.320002,31.617027,-1293.950806,-0.002423,0.001005,0.025531,140.639557,7.164521,0.255314,-1293.950806,0.026520,0.000000
25.630001,32.417999,-1293.950806,-0.002397,0.001028,0.026104,144.202469,7.346024,0.261037,-1293.950806,0.027041,0.000000
25.940001,31.864655,-1293.995361,-0.002384,0.001035,0.026278,141.741058,7.220634,0.262778,-1293.995361,0.027553,0.000000
26.250002,33.544060,-1293.950806,-0.002345,0.001071,0.027197,149.211426,7.601192,0.271967,-1293.950806,0.028072,0.000000
26.560001,33.475166,-1293.995361,-0.002333,0.001088,0.027639,148.904984,7.585581,0.276388,-1293.995361,0.028584,0.000000
26.870001,33.895950,-1293.906372,-0.002307,0.001108,0.028134,150.776718,7.680932,0.281339,-1293.906372,0.029104,0.000000
27.180002,33.990158,-1293.995361,-0.002294,0.001125,0.028576,151.195770,7.702280,0.285760,-1293.995361,0.029625,0.000000
27.490002,34.723358,-1293.995361,-0.002268,0.001146,0.029104,154.457214,7.868425,0.291043,-1293.995361,0.030137,0.000000
27.800001,34.870445,-1293.950806,-0.002246,0.001164,0.029572,155.111481,7.901756,0.295721,-1293.950806,0.030656,0.000000
28.110001,35.898193,-1293.995361,-0.002233,0.001192,0.030284,159.683136,8.134646,0.302837,-1293.995361,0.031168,0.000000
28.420002,36.089966,-1293.906372,-0.002190,0.001208,0.030674,160.536179,8.178102,0.306743,-1293.906372,0.031689,0.000000
28.730001,36.460846,-1293.995361,-0.002186,0.001228,0.031203,162.185944,8.262146,0.312027,-1293.995361,0.032209,0.000000
29.040001,36.874557,-1293.950806,-0.002173,0.001250,0.031758,164.026230,8.355894,0.317583,-1293.950806,0.032721,0.000000
29.350002,37.399971,-1293.995361,-0.002134,0.001270,0.032261,166.363373,8.474955,0.322609,-1293.995361,0.033240,0.000000
29.660002,37.592865,-1293.995361,-0.002117,0.001286,0.032668,167.221420,8.518664,0.326682,-1293.995361,0.033752,0.000000
29.970001,38.101898,-1293.950806,-0.002100,0.001310,0.033284,169.485703,8.634013,0.332844,-1293.950806,0.034273,0.000000
30.280001,38.764717,-1294.039795,-0.002070,0.001330,0.033779,172.434067,8.784210,0.337794,-1294.039795,0.034785,0.000000
30.590002,39.017555,-1293.950806,-0.002048,0.001351,0.034308,173.558746,8.841504,0.343078,-1293.950806,0.035306,0.000000
30.900002,39.265556,-1294.039795,-0.002031,0.001367,0.034715,174.661911,8.897702,0.347151,-1294.039795,0.035825,0.000000
31.210001,39.904549,-1293.995361,-0.002018,0.001389,0.035287,177.504303,9.042500,0.352873,-1293.995361,0.036337,0.000000
31.520002,40.192024,-1293.950806,-0.001992,0.001410,0.035808,178.783051,9.107643,0.358081,-1293.950806,0.036857,0.000000
31.830002,39.879227,-1294.039795,-0.001970,0.001419,0.036034,177.391663,9.036761,0.360337,-1294.039795,0.037369,0.000000
32.140003,41.983131,-1293.950806,-0.001932,0.001455,0.036962,186.750290,9.513514,0.369618,-1293.950806,0.037890,0.000000
32.450001,42.131340,-1293.950806,-0.001919,0.001475,0.037455,187.409561,9.547098,0.374553,-1293.950806,0.038409,0.000000
32.760002,42.172668,-1293.950806,-0.001897,0.001492,0.037890,187.593399,9.556463,0.378898,-1293.950806,0.038921,0.000000
33.070000,42.844429,-1293.995361,-0.001876,0.001513,0.038436,190.581543,9.708687,0.384364,-1293.995361,0.039442,0.000000
33.380001,42.904381,-1294.039795,-0.001854,0.001528,0.038809,190.848221,9.722272,0.388088,-1294.039795,0.039953,0.000000
33.690002,42.842194,-1293.995361,-0.001832,0.001544,0.039207,190.571594,9.708180,0.392070,-1293.995361,0.040474,0.000000
34.000000,44.473190,-1293.995361,-0.001798,0.001574,0.039972,197.826630,10.077768,0.399715,-1293.995361,0.040986,0.000000
34.310001,45.016853,-1294.039795,-0.001794,0.001597,0.040570,200.244965,10.200965,0.405695,-1294.039795,0.041505,0.000000
34.620003,45.241020,-1294.039795,-0.001755,0.001614,0.041003,201.242111,10.251761,0.410025,-1294.039795,0.042026,0.000000
34.930000,45.897888,-1294.084351,-0.001729,0.001635,0.041532,204.164001,10.400611,0.415324,-1294.084351,0.042538,0.000000
35.240002,46.100830,-1293.995361,-0.001720,0.001654,0.042017,205.066727,10.446597,0.420169,-1293.995361,0.043058,0.000000
35.550003,46.217751,-1293.995361,-0.001703,0.001670,0.042417,205.586823,10.473092,0.424166,-1293.995361,0.043570,0.000000
35.860001,47.326309,-1294.039795,-0.001673,0.001695,0.043049,210.517944,10.724295,0.430494,-1294.039795,0.044089,0.000000
36.170002,48.179787,-1293.950806,-0.001643,0.001719,0.043666,214.314392,10.917696,0.436656,-1293.950806,0.044601,0.000000
36.480003,48.258728,-1294.084351,-0.001625,0.001736,0.044082,214.665543,10.935584,0.440819,-1294.084351,0.045122,0.000000
36.790001,49.373238,-1293.995361,-0.001608,0.001762,0.044750,219.623123,11.188136,0.447496,-1293.995361,0.045643,0.000000
37.100002,49.505798,-1294.039795,-0.001587,0.001777,0.045148,220.212784,11.218174,0.451477,-1294.039795,0.046155,0.000000
37.410004,50.040901,-1294.039795,-0.001578,0.001794,0.045564,222.593048,11.339430,0.455641,-1294.039795,0.046674,0.000000
37.720001,51.251480,-1293.995361,-0.001548,0.001819,0.046206,227.977966,11.613751,0.462060,-1293.995361,0.047186,0.000000
38.030003,52.222260,-1294.039795,-0.001522,0.001842,0.046787,232.296219,11.833734,0.467874,-1294.039795,0.047706,0.000000
38.340000,52.357430,-1293.950806,-0.001518,0.001858,0.047204,232.897476,11.864363,0.472037,-1293.950806,0.048227,0.000000
38.650002,53.060844,-1294.084351,-0.001487,0.001881,0.047776,236.026428,12.023759,0.477760,-1294.084351,0.048739,0.000000
38.960003,53.513275,-1293.950806,-0.001466,0.001901,0.048288,238.038940,12.126282,0.482877,-1293.950806,0.049258,0.000000
39.270000,54.166046,-1293.950806,-0.001440,0.001918,0.048713,240.942612,12.274201,0.487131,-1293.950806,0.049770,0.000000
39.580002,54.214821,-1294.039795,-0.001427,0.001930,0.049025,241.159561,12.285254,0.490250,-1294.039795,0.050291,0.000000
39.890003,55.674149,-1294.039795,-0.001397,0.001956,0.049684,247.650986,12.615942,0.496836,-1294.039795,0.050802,0.000000
40.200001,56.544762,-1294.039795,-0.001380,0.001980,0.050291,251.523666,12.813226,0.502907,-1294.039795,0.051323,0.000000
40.510002,57.026978,-1293.995361,-0.001362,0.001998,0.050742,253.668671,12.922498,0.507418,-1293.995361,0.051842,0.000000
40.820004,58.137398,-1293.995361,-0.001337,0.002023,0.051393,258.608063,13.174123,0.513928,-1293.995361,0.052354,0.000000
41.130001,58.357094,-1294.039795,-0.001328,0.002037,0.051740,259.585327,13.223907,0.517395,-1294.039795,0.052875,0.000000
41.440002,58.720161,-1293.950806,-0.001302,0.002056,0.052216,261.200317,13.306179,0.522164,-1293.950806,0.053387,0.000000
41.750004,60.493767,-1294.084351,-0.001276,0.002083,0.052901,269.089722,13.708083,0.529007,-1294.084351,0.053908,0.000000
42.060001,61.100365,-1294.039795,-0.001259,0.002105,0.053465,271.787994,13.845540,0.534654,-1294.039795,0.054427,0.000000
42.370003,61.550186,-1293.995361,-0.001237,0.002123,0.053915,273.788910,13.947471,0.539151,-1293.995361,0.054939,0.000000
42.680000,62.699699,-1293.995361,-0.001224,0.002144,0.054462,278.902191,14.207955,0.544616,-1293.995361,0.055459,0.000000
42.990002,63.075424,-1293.950806,-0.001177,0.002163,0.054939,280.573486,14.293096,0.549385,-1293.950806,0.055971,0.000000
43.300003,63.527855,-1294.039795,-0.001186,0.002176,0.055278,282.585999,14.395617,0.552776,-1294.039795,0.056492,0.000000
43.610001,65.334984,-1293.995361,-0.001155,0.002208,0.056085,290.624512,14.805119,0.560846,-1293.995361,0.057004,0.000000
43.920002,65.734169,-1293.995361,-0.001134,0.002225,0.056508,292.400177,14.895576,0.565085,-1293.995361,0.057523,0.000000
44.230003,66.293098,-1294.039795,-0.001134,0.002234,0.056734,294.886444,15.022231,0.567341,-1294.039795,0.056978,0.000000
44.540001,64.934303,-1293.995361,-0.001112,0.002233,0.056717,288.842194,14.714324,0.567174,-1293.995361,289.342438,0.000000
44.850002,65.426964,-1294.039795,-0.001099,0.002243,0.056969,291.033661,14.825962,0.569687,-1294.039795,294.500488,0.000000
45.160004,66.107277,-1293.995361,-0.001078,0.002254,0.057255,294.059845,14.980124,0.572549,-1293.995361,294.500488,0.000000
45.470001,64.913826,-1294.039795,-0.001065,0.002254,0.057255,288.751129,14.709682,0.572549,-1294.039795,294.500488,0.000000
45.780003,66.033180,-1293.950806,-0.001035,0.002226,0.056552,293.730255,14.963333,0.565524,-1293.950806,294.500488,0.000000
46.090004,65.186775,-1293.995361,-0.001039,0.002287,0.058078,289.965271,14.771534,0.580785,-1293.995361,294.500488,0.000000
46.400002,65.263863,-1294.039795,-0.001030,0.002297,0.058348,290.308167,14.789002,0.583479,-1294.039795,294.500488,0.000000
46.710003,65.028526,-1293.950806,-0.001013,0.002304,0.058530,289.261322,14.735675,0.585296,-1293.950806,294.500488,0.000000
47.020000,65.852577,-1294.084351,-0.000992,0.002320,0.058937,292.926880,14.922407,0.589369,-1294.084351,294.500488,0.000000
47.330002,65.088844,-1294.039795,-0.001000,0.002321,0.058946,289.529633,14.749343,0.589460,-1294.039795,294.500488,0.000000
47.640003,65.617607,-1294.039795,-0.000979,0.002334,0.059284,291.881683,14.869163,0.592836,-1294.039795,294.500488,0.000000
47.950001,64.937660,-1293.995361,-0.000970,0.002334,0.059284,288.857147,14.715084,0.592836,-1293.995361,294.500488,0.000000
48.260002,66.402199,-1293.995361,-0.000957,0.002293,0.058253,295.371735,15.046953,0.582526,-1293.995361,294.500488,0.000000
48.570004,65.598244,-1293.950806,-0.000944,0.002299,0.058390,291.795563,14.864775,0.583903,-1293.950806,294.500488,0.000000
48.880001,65.161827,-1294.084351,-0.000949,0.002352,0.059744,289.854279,14.765881,0.597438,-1294.084351,294.500488,0.000000
49.190002,65.167793,-1293.995361,-0.000949,0.002362,0.059995,289.880829,14.767234,0.599951,-1293.995361,294.500488,0.000000
49.500004,65.189384,-1294.039795,-0.000944,0.002369,0.060177,289.976868,14.772126,0.601768,-1294.039795,294.500488,0.000000
49.810001,65.218437,-1293.950806,-0.000918,0.002376,0.060342,290.106110,14.778709,0.603418,-1293.950806,294.500488,0.000000
50.120003,65.151405,-1294.084351,-0.000918,0.002380,0.060446,289.807922,14.763519,0.604463,-1294.084351,294.500488,0.000000
50.430004,65.043037,-1293.995361,-0.000918,0.002384,0.060551,289.325867,14.738962,0.605507,-1293.995361,294.500488,0.000000
50.740002,65.250832,-1293.950806,-0.000918,0.002391,0.060723,290.250183,14.786049,0.607233,-1293.950806,294.500488,0.000000
51.050003,65.266090,-1294.039795,-0.000897,0.002396,0.060870,290.318085,14.789508,0.608702,-1294.039795,294.500488,0.000000
51.360001,65.914391,-1293.995361,-0.000875,0.002409,0.061191,293.201843,14.936415,0.611912,-1293.995361,294.500488,0.000000
51.670002,65.505150,-1293.995361,-0.000892,0.002407,0.061140,291.381470,14.843679,0.611397,-1293.995361,294.500488,0.000000
51.980003,65.283592,-1293.906372,-0.000884,0.002418,0.061409,290.395935,14.793474,0.614092,-1293.906372,294.500488,0.000000
52.290001,65.440361,-1293.950806,-0.000880,0.002415,0.061349,291.093262,14.828998,0.613486,-1293.950806,294.500488,0.000000
52.600002,64.994637,-1294.084351,-0.000871,0.002415,0.061349,289.110596,14.727995,0.613486,-1294.084351,294.500488,0.000000
52.910004,66.144142,-1293.950806,-0.000849,0.002421,0.061505,294.223846,14.988478,0.615045,-1293.950806,294.500488,0.000000
53.220001,65.635857,-1293.995361,-0.000849,0.002421,0.061505,291.962860,14.873298,0.615045,-1293.995361,294.500488,0.000000
53.530003,65.184547,-1293.950806,-0.000858,0.002421,0.061505,289.955353,14.771029,0.615045,-1293.950806,294.500488,0.000000
53.840004,65.555061,-1293.995361,-0.000845,0.002437,0.061903,291.603485,14.854989,0.619027,-1293.995361,294.500488,0.000000
54.150002,65.238167,-1293.995361,-0.000836,0.002437,0.061912,290.193848,14.783179,0.619118,-1293.995361,294.500488,0.000000
54.460003,65.571068,-1293.906372,-0.000836,0.002447,0.062146,291.674683,14.858616,0.621465,-1293.906372,294.500488,0.000000
54.770004,65.330147,-1294.084351,-0.000832,0.002447,0.062146,290.602997,14.804023,0.621465,-1294.084351,294.500488,0.000000
55.080002,65.430687,-1293.995361,-0.000815,0.002452,0.062293,291.050232,14.826806,0.622933,-1293.995361,294.500488,0.000000
55.390003,65.250084,-1293.995361,-0.000811,0.002455,0.062345,290.246857,14.785880,0.623448,-1293.995361,294.500488,0.000000
55.700001,65.362160,-1293.995361,-0.000824,0.002458,0.062440,290.745422,14.811277,0.624402,-1293.995361,294.500488,0.000000
56.010002,65.317482,-1294.084351,-0.000811,0.002461,0.062519,290.546661,14.801153,0.625189,-1294.084351,294.500488,0.000000
56.320004,65.352852,-1294.039795,-0.000824,0.002465,0.062623,290.704010,14.809168,0.626234,-1294.039795,294.500488,0.000000
56.630001,65.334618,-1293.950806,-0.000798,0.002468,0.062675,290.622894,14.805036,0.626748,-1293.950806,294.500488,0.000000
56.940002,65.280251,-1293.995361,-0.000798,0.002471,0.062754,290.381042,14.792717,0.627536,-1293.995361,294.500488,0.000000
57.250004,65.300346,-1293.995361,-0.000789,0.002473,0.062814,290.470459,14.797271,0.628141,-1293.995361,294.500488,0.000000
57.560001,65.493248,-1293.906372,-0.000793,0.002479,0.062961,291.328522,14.840981,0.629610,-1293.906372,294.500488,0.000000
57.870003,65.325676,-1294.039795,-0.000798,0.002479,0.062961,290.583130,14.803010,0.629610,-1294.039795,294.500488,0.000000
58.180004,65.454887,-1293.995361,-0.000785,0.002486,0.063143,291.157867,14.832290,0.631426,-1293.995361,294.500488,0.000000
58.490002,65.457115,-1294.039795,-0.000789,0.002486,0.063143,291.167786,14.832794,0.631426,-1294.039795,294.500488,0.000000
58.800003,65.225502,-1293.995361,-0.000780,0.002486,0.063143,290.137512,14.780310,0.631426,-1293.995361,294.500488,0.000000
59.110004,65.262367,-1293.950806,-0.000767,0.002490,0.063247,290.301514,14.788664,0.632471,-1293.950806,294.500488,0.000000
59.420002,65.405739,-1294.039795,-0.000772,0.002494,0.063359,290.939270,14.821152,0.633591,-1294.039795,294.500488,0.000000
59.730003,65.273918,-1294.039795,-0.000780,0.002495,0.063377,290.352875,14.791282,0.633773,-1294.039795,294.500488,0.000000
60.040005,65.272789,-1293.950806,-0.000767,0.002499,0.063464,290.347870,14.791025,0.634636,-1293.950806,294.500488,0.000000
60.350002,65.224388,-1293.995361,-0.000780,0.002500,0.063508,290.132568,14.780058,0.635075,-1293.995361,294.500488,0.000000
60.660004,65.210976,-1293.995361,-0.000763,0.002502,0.063550,290.072906,14.777019,0.635499,-1293.995361,294.500488,0.000000
60.970001,65.188637,-1294.084351,-0.000759,0.002505,0.063620,289.973541,14.771956,0.636195,-1294.084351,294.500488,0.000000
61.280003,65.158104,-1294.084351,-0.000763,0.002506,0.063654,289.837708,14.765038,0.636544,-1294.084351,294.500488,0.000000
61.590004,65.292534,-1294.084351,-0.000742,0.002510,0.063750,290.435699,14.795500,0.637497,-1294.084351,294.500488,0.000000
61.900002,65.169655,-1293.950806,-0.000746,0.002511,0.063768,289.889099,14.767654,0.637679,-1293.950806,294.500488,0.000000
62.210003,65.182304,-1293.995361,-0.000755,0.002513,0.063828,289.945374,14.770521,0.638285,-1293.995361,294.500488,0.000000
62.520004,65.090706,-1293.995361,-0.000759,0.002514,0.063863,289.537933,14.749764,0.638633,-1293.995361,294.500488,0.000000
62.830002,65.223640,-1293.995361,-0.000737,0.002517,0.063941,290.129242,14.779888,0.639405,-1293.995361,294.500488,0.000000
63.140003,65.106712,-1294.039795,-0.000750,0.002519,0.063984,289.609131,14.753392,0.639844,-1294.039795,294.500488,0.000000
63.450005,65.200188,-1294.039795,-0.000742,0.002521,0.064036,290.024933,14.774573,0.640359,-1294.039795,294.500488,0.000000
63.760002,65.193855,-1294.084351,-0.000742,0.002524,0.064106,289.996765,14.773139,0.641055,-1294.084351,294.500488,0.000000
64.070000,65.106346,-1294.039795,-0.000729,0.002525,0.064124,289.607483,14.753309,0.641237,-1294.039795,294.500488,0.000000
64.380005,65.309288,-1293.995361,-0.000729,0.002528,0.064201,290.510223,14.799295,0.642009,-1293.995361,294.500488,0.000000
64.690002,65.160347,-1294.084351,-0.000724,0.002528,0.064210,289.847687,14.765546,0.642100,-1294.084351,294.500488,0.000000
65.000000,65.650383,-1294.039795,-0.000733,0.002535,0.064401,292.027496,14.876590,0.644007,-1294.039795,294.500488,0.000000
65.310005,65.561012,-1294.084351,-0.000720,0.002535,0.064401,291.629944,14.856339,0.644007,-1294.084351,294.500488,0.000000
65.620003,65.426582,-1294.084351,-0.000729,0.002535,0.064401,291.031982,14.825875,0.644007,-1294.084351,294.500488,0.000000
65.930000,65.304817,-1294.039795,-0.000720,0.002536,0.064410,290.490326,14.798283,0.644098,-1294.039795,294.500488,0.000000
66.240005,65.377068,-1294.084351,-0.000707,0.002540,0.064505,290.811707,14.814655,0.645052,-1294.084351,294.500488,0.000000
66.550003,65.277260,-1294.084351,-0.000716,0.002540,0.064505,290.367767,14.792039,0.645052,-1294.084351,294.500488,0.000000
66.860001,65.184547,-1294.039795,-0.000711,0.002541,0.064531,289.955353,14.771029,0.645309,-1294.039795,294.500488,0.000000
67.170006,65.233696,-1294.128784,-0.000707,0.002543,0.064601,290.173981,14.782166,0.646006,-1294.128784,294.500488,0.000000
67.480003,65.133156,-1294.084351,-0.000703,0.002543,0.064601,289.726746,14.759384,0.646006,-1294.084351,294.500488,0.000000
67.790001,65.050117,-1294.128784,-0.000720,0.002544,0.064626,289.357361,14.740567,0.646263,-1294.128784,294.500488,0.000000
68.100006,65.280617,-1294.084351,-0.000707,0.002549,0.064738,290.382690,14.792799,0.647384,-1294.084351,294.500488,0.000000
68.410004,65.226616,-1294.128784,-0.000711,0.002549,0.064738,290.142487,14.780562,0.647384,-1294.128784,294.500488,0.000000
68.720001,65.174110,-1294.084351,-0.000711,0.002550,0.064773,289.908936,14.768664,0.647732,-1294.084351,294.500488,0.000000
69.030006,65.225502,-1294.084351,-0.000703,0.002552,0.064817,290.137512,14.780310,0.648171,-1294.084351,294.500488,0.000000
69.340004,65.367378,-1294.128784,-0.000716,0.002556,0.064929,290.768616,14.812459,0.649291,-1294.128784,294.500488,0.000000
69.650002,65.402748,-1294.084351,-0.000694,0.002556,0.064929,290.925964,14.820475,0.649291,-1294.084351,294.500488,0.000000
69.960007,65.300728,-1294.039795,-0.000694,0.002556,0.064929,290.472137,14.797357,0.649291,-1294.039795,294.500488,0.000000
70.270004,65.187523,-1294.084351,-0.000703,0.002556,0.064929,289.968597,14.771704,0.649291,-1294.084351,294.500488,0.000000
70.580002,65.086983,-1294.128784,-0.000698,0.002557,0.064955,289.521362,14.748921,0.649549,-1294.128784,294.500488,0.000000
70.890007,65.107841,-1294.128784,-0.000690,0.002560,0.065017,289.614136,14.753648,0.650169,-1294.128784,294.500488,0.000000
71.200005,65.056816,-1294.084351,-0.000690,0.002560,0.065017,289.387177,14.742085,0.650169,-1294.084351,294.500488,0.000000
71.510002,65.107841,-1294.128784,-0.000694,0.002562,0.065085,289.614136,14.753648,0.650851,-1294.128784,294.500488,0.000000
71.820000,65.038582,-1294.039795,-0.000694,0.002562,0.065085,289.306061,14.737954,0.650851,-1294.039795,294.500488,0.000000
72.130005,64.989418,-1294.084351,-0.000677,0.002563,0.065094,289.087372,14.726813,0.650941,-1294.084351,294.500488,0.000000
72.440002,64.894096,-1294.084351,-0.000698,0.002563,0.065103,288.663361,14.705213,0.651032,-1294.084351,294.500488,0.000000
72.750000,65.589684,-1294.039795,-0.000681,0.002572,0.065329,291.757477,14.862835,0.653288,-1294.039795,294.500488,0.000000
73.060005,65.530479,-1294.084351,-0.000677,0.002572,0.065329,291.494141,14.849419,0.653288,-1294.084351,294.500488,0.000000
73.370003,65.444084,-1294.039795,-0.000677,0.002572,0.065329,291.109833,14.829841,0.653288,-1294.039795,294.500488,0.000000
73.680000,65.337212,-1294.039795,-0.000673,0.002572,0.065329,290.634430,14.805623,0.653288,-1294.039795,294.500488,0.000000
73.990005,65.239662,-1294.039795,-0.000673,0.002572,0.065329,290.200500,14.783519,0.653288,-1294.039795,294.500488,0.000000
74.300003,65.166298,-1294.084351,-0.000673,0.002574,0.065389,289.874176,14.766894,0.653894,-1294.084351,294.500488,0.000000
74.610001,65.169273,-1294.128784,-0.000681,0.002575,0.065398,289.887421,14.767569,0.653984,-1294.128784,294.500488,0.000000
74.920006,65.237053,-1294.039795,-0.000673,0.002577,0.065459,290.188904,14.782928,0.654590,-1294.039795,294.500488,0.000000
75.230003,65.203529,-1294.084351,-0.000668,0.002577,0.065459,290.039795,14.775331,0.654590,-1294.084351,294.500488,0.000000
75.540001,65.111183,-1293.995361,-0.000664,0.002577,0.065467,289.628998,14.754405,0.654666,-1293.995361,294.500488,0.000000
75.850006,65.235191,-1294.084351,-0.000655,0.002581,0.065545,290.180634,14.782506,0.655453,-1294.084351,294.500488,0.000000
76.160004,65.196083,-1294.084351,-0.000677,0.002581,0.065545,290.006653,14.773643,0.655453,-1294.084351,294.500488,0.000000
76.470001,65.173378,-1294.084351,-0.000668,0.002581,0.065562,289.905670,14.768499,0.655620,-1294.084351,294.500488,0.000000
76.780006,65.344658,-1294.128784,-0.000673,0.002585,0.065657,290.667542,14.807311,0.656573,-1294.128784,294.500488,0.000000
77.090004,65.324928,-1293.995361,-0.000664,0.002585,0.065657,290.579803,14.802840,0.656573,-1293.995361,294.500488,0.000000
77.400002,65.250084,-1294.039795,-0.000677,0.002585,0.065657,290.246857,14.785880,0.656573,-1294.039795,294.500488,0.000000
77.710007,65.195351,-1294.084351,-0.000664,0.002589,0.065753,290.003418,14.773478,0.657527,-1294.084351,294.500488,0.000000
78.020004,65.571434,-1294.039795,-0.000655,0.002590,0.065788,291.676300,14.858700,0.657875,-1294.039795,294.500488,0.000000
78.330002,65.494728,-1294.128784,-0.000660,0.002590,0.065788,291.335114,14.841318,0.657875,-1294.128784,294.500488,0.000000
78.640007,65.412071,-1294.039795,-0.000655,0.002590,0.065788,290.967438,14.822587,0.657875,-1294.039795,294.500488,0.000000
78.950005,65.315620,-1294.128784,-0.000660,0.002590,0.065788,290.538391,14.800731,0.657875,-1294.128784,294.500488,0.000000
79.260002,65.244499,-1294.128784,-0.000660,0.002590,0.065788,290.222015,14.784615,0.657875,-1294.128784,294.500488,0.000000
79.570007,65.143959,-1294.084351,-0.000651,0.002590,0.065797,289.774811,14.761832,0.657966,-1294.084351,294.500488,0.000000
79.880005,65.544624,-1294.084351,-0.000651,0.002597,0.065953,291.557037,14.852624,0.659526,-1294.084351,294.500488,0.000000
80.190002,65.510002,-1294.084351,-0.000647,0.002597,0.065953,291.403046,14.844778,0.659526,-1294.084351,294.500488,0.000000
80.500008,65.441856,-1293.995361,-0.000634,0.002597,0.065953,291.099915,14.829336,0.659526,-1293.995361,294.500488,0.000000
80.810005,65.350990,-1294.039795,-0.000655,0.002597,0.065953,290.695709,14.808746,0.659526,-1294.039795,294.500488,0.000000
81.120003,65.298485,-1294.084351,-0.000638,0.002597,0.065962,290.462158,14.796848,0.659616,-1294.084351,294.500488,0.000000
81.430000,65.212837,-1294.128784,-0.000660,0.002597,0.065962,290.081177,14.777440,0.659616,-1294.128784,294.500488,0.000000
81.740005,65.170769,-1294.039795,-0.000638,0.002598,0.065978,289.894043,14.767907,0.659783,-1294.039795,294.500488,0.000000
82.050003,65.154015,-1294.084351,-0.000647,0.002599,0.066013,289.819519,14.764111,0.660131,-1294.084351,294.500488,0.000000
82.360001,65.185661,-1294.039795,-0.000638,0.002600,0.066039,289.960297,14.771281,0.660388,-1294.039795,294.500488,0.000000
82.670006,65.487648,-1294.084351,-0.000647,0.002604,0.066143,291.303619,14.839713,0.661433,-1294.084351,294.500488,0.000000
82.980003,65.467552,-1294.039795,-0.000638,0.002604,0.066143,291.214203,14.835159,0.661433,-1294.039795,294.500488,0.000000
83.290001,65.394936,-1293.995361,-0.000629,0.002604,0.066143,290.891205,14.818705,0.661433,-1293.995361,294.500488,0.000000
83.600006,65.320457,-1294.173218,-0.000642,0.002604,0.066143,290.559906,14.801826,0.661433,-1294.173218,294.500488,0.000000
83.910004,65.275780,-1294.039795,-0.000634,0.002604,0.066143,290.361176,14.791703,0.661433,-1294.039795,294.500488,0.000000
84.220001,65.178215,-1294.084351,-0.000625,0.002605,0.066161,289.927185,14.769595,0.661615,-1294.084351,294.500488,0.000000
84.530006,65.194603,-1294.084351,-0.000647,0.002605,0.066178,290.000092,14.773308,0.661781,-1294.084351,294.500488,0.000000
84.840004,65.294395,-1294.084351,-0.000625,0.002610,0.066283,290.443970,14.795921,0.662826,-1294.084351,294.500488,0.000000
85.150002,65.315620,-1294.128784,-0.000629,0.002610,0.066283,290.538391,14.800731,0.662826,-1294.128784,294.500488,0.000000
85.460007,65.279503,-1293.995361,-0.000634,0.002610,0.066283,290.377716,14.792547,0.662826,-1293.995361,294.500488,0.000000
85.770004,65.245247,-1294.084351,-0.000612,0.002610,0.066283,290.225342,14.784784,0.662826,-1294.084351,294.500488,0.000000
86.080002,65.248970,-1294.084351,-0.000634,0.002611,0.066326,290.241913,14.785628,0.663265,-1294.084351,294.500488,0.000000
86.390007,65.224388,-1294.039795,-0.000617,0.002612,0.066334,290.132568,14.780058,0.663341,-1294.039795,294.500488,0.000000
86.700005,65.211723,-1294.039795,-0.000625,0.002612,0.066352,290.076233,14.777188,0.663522,-1294.039795,294.500488,0.000000
87.010002,65.208382,-1294.084351,-0.000617,0.002613,0.066369,290.061371,14.776431,0.663689,-1294.084351,294.500488,0.000000
87.320007,65.357323,-1294.128784,-0.000617,0.002617,0.066464,290.723877,14.810181,0.664643,-1294.128784,294.500488,0.000000
87.630005,65.431801,-1294.084351,-0.000625,0.002617,0.066464,291.055176,14.827059,0.664643,-1294.084351,294.500488,0.000000
87.940002,65.383018,-1294.039795,-0.000617,0.002617,0.066464,290.838196,14.816004,0.664643,-1294.039795,294.500488,0.000000
88.250008,65.346153,-1294.039795,-0.000621,0.002617,0.066464,290.674194,14.807650,0.664643,-1294.039795,294.500488,0.000000
88.560005,65.301476,-1294.084351,-0.000621,0.002617,0.066482,290.475464,14.797526,0.664824,-1294.084351,294.500488,0.000000
88.870003,65.293282,-1294.084351,-0.000629,0.002618,0.066499,290.439026,14.795669,0.664991,-1294.084351,294.500488,0.000000
89.180008,65.286568,-1294.084351,-0.000608,0.002619,0.066525,290.409149,14.794147,0.665248,-1294.084351,294.500488,0.000000
89.490005,65.265724,-1294.084351,-0.000617,0.002619,0.066525,290.316437,14.789425,0.665248,-1294.084351,294.500488,0.000000
89.800003,65.238914,-1294.084351,-0.000625,0.002619,0.066534,290.197174,14.783349,0.665339,-1294.084351,294.500488,0.000000
90.110001,65.337212,-1294.084351,-0.000629,0.002622,0.066594,290.634430,14.805623,0.665945,-1294.084351,294.500488,0.000000
90.420006,65.324181,-1294.128784,-0.000621,0.002622,0.066594,290.576477,14.802671,0.665945,-1294.128784,294.500488,0.000000
90.730003,65.290291,-1294.039795,-0.000612,0.002622,0.066594,290.425720,14.794991,0.665945,-1294.039795,294.500488,0.000000
91.040001,65.274666,-1294.128784,-0.000604,0.002623,0.066620,290.356201,14.791451,0.666202,-1294.128784,294.500488,0.000000
91.350006,65.251198,-1294.039795,-0.000617,0.002623,0.066620,290.251831,14.786133,0.666202,-1294.039795,294.500488,0.000000
91.660004,65.266472,-1294.039795,-0.000604,0.002624,0.066655,290.319763,14.789594,0.666550,-1294.039795,294.500488,0.000000
91.970001,65.266472,-1294.084351,-0.000599,0.002625,0.066673,290.319763,14.789594,0.666732,-1294.084351,294.500488,0.000000
92.280006,65.262001,-1293.995361,-0.000612,0.002625,0.066681,290.299866,14.788581,0.666808,-1293.995361,294.500488,0.000000
92.590004,65.257530,-1294.084351,-0.000604,0.002626,0.066690,290.279999,14.787567,0.666898,-1294.084351,294.500488,0.000000
92.900002,65.246361,-1294.039795,-0.000625,0.002627,0.066716,290.230316,14.785036,0.667156,-1294.039795,294.500488,0.000000
93.210007,65.233330,-1294.084351,-0.000608,0.002627,0.066716,290.172333,14.782084,0.667156,-1294.084351,294.500488,0.000000
93.520004,65.185661,-1294.084351,-0.000621,0.002627,0.066725,289.960297,14.771281,0.667247,-1294.084351,294.500488,0.000000
93.830002,65.174858,-1294.039795,-0.000621,0.002627,0.066734,289.912262,14.768834,0.667338,-1294.039795,294.500488,0.000000
94.140007,65.289925,-1294.128784,-0.000621,0.002630,0.066803,290.424103,14.794909,0.668034,-1294.128784,294.500488,0.000000
94.450005,65.310036,-1294.039795,-0.000621,0.002630,0.066803,290.513550,14.799465,0.668034,-1294.039795,294.500488,0.000000
94.760002,65.285454,-1294.084351,-0.000599,0.002630,0.066803,290.404205,14.793895,0.668034,-1294.084351,294.500488,0.000000
95.070007,65.250450,-1294.084351,-0.000621,0.002630,0.066803,290.248505,14.785963,0.668034,-1294.084351,294.500488,0.000000
95.380005,65.225136,-1294.084351,-0.000612,0.002631,0.066820,290.135895,14.780228,0.668200,-1294.084351,294.500488,0.000000
95.690002,65.201668,-1294.084351,-0.000604,0.002631,0.066837,290.031494,14.774909,0.668367,-1294.084351,294.500488,0.000000
96.000008,65.292534,-1294.084351,-0.000599,0.002633,0.066890,290.435699,14.795500,0.668897,-1294.084351,294.500488,0.000000
96.310005,65.294395,-1294.084351,-0.000604,0.002633,0.066890,290.443970,14.795921,0.668897,-1294.084351,294.500488,0.000000
96.620003,65.271675,-1294.039795,-0.000612,0.002633,0.066890,290.342926,14.790773,0.668897,-1294.039795,294.500488,0.000000
96.930008,65.261253,-1294.084351,-0.000604,0.002634,0.066906,290.296539,14.788412,0.669063,-1294.084351,294.500488,0.000000
97.240005,65.248589,-1294.128784,-0.000604,0.002634,0.066915,290.240204,14.785542,0.669154,-1294.128784,294.500488,0.000000
97.550003,65.227745,-1294.039795,-0.000608,0.002634,0.066915,290.147491,14.780818,0.669154,-1294.039795,294.500488,0.000000
97.860008,65.264610,-1294.128784,-0.000591,0.002636,0.066959,290.311493,14.789172,0.669593,-1294.128784,294.500488,0.000000
98.170006,65.263481,-1294.039795,-0.000595,0.002636,0.066959,290.306458,14.788917,0.669593,-1294.039795,294.500488,0.000000
98.480003,65.236671,-1294.084351,-0.000595,0.002636,0.066959,290.187195,14.782842,0.669593,-1294.084351,294.500488,0.000000
98.790001,65.241142,-1294.039795,-0.000604,0.002638,0.066994,290.207092,14.783854,0.669942,-1294.039795,294.500488,0.000000
99.100006,65.268700,-1294.084351,-0.000599,0.002638,0.067002,290.329681,14.790098,0.670017,-1294.084351,294.500488,0.000000
99.410004,65.247108,-1294.128784,-0.000599,0.002638,0.067011,290.233643,14.785206,0.670108,-1294.128784,294.500488,0.000000
99.720001,65.235558,-1294.084351,-0.000608,0.002638,0.067011,290.182251,14.782589,0.670108,-1294.084351,294.500488,0.000000
100.030006,65.201668,-1294.039795,-0.000595,0.002639,0.067029,290.031494,14.774909,0.670290,-1294.039795,294.500488,0.000000
100.340004,65.192741,-1294.128784,-0.000599,0.002639,0.067037,289.991791,14.772886,0.670365,-1294.128784,294.500488,0.000000
100.650002,65.162209,-1293.995361,-0.000604,0.002639,0.067037,289.855988,14.765968,0.670365,-1293.995361,294.500488,0.000000
100.960007,65.218437,-1294.128784,-0.000591,0.002642,0.067106,290.106110,14.778709,0.671062,-1294.128784,294.500488,0.000000
101.270004,65.288811,-1294.128784,-0.000595,0.002642,0.067106,290.419128,14.794656,0.671062,-1294.128784,294.500488,0.000000
101.580002,65.275398,-1294.084351,-0.000591,0.002642,0.067106,290.359467,14.791616,0.671062,-1294.084351,294.500488,0.000000
101.890007,65.251198,-1294.173218,-0.000595,0.002642,0.067106,290.251831,14.786133,0.671062,-1294.173218,294.500488,0.000000
102.200005,65.234444,-1293.995361,-0.000591,0.002642,0.067115,290.177307,14.782336,0.671153,-1293.995361,294.500488,0.000000
102.510002,65.225883,-1294.128784,-0.000604,0.002643,0.067124,290.139221,14.780396,0.671244,-1294.128784,294.500488,0.000000
102.820007,65.192741,-1294.128784,-0.000586,0.002643,0.067124,289.991791,14.772886,0.671244,-1294.128784,294.500488,0.000000
103.130005,65.153633,-1294.084351,-0.000586,0.002643,0.067132,289.817841,14.764025,0.671319,-1294.084351,294.500488,0.000000
103.440002,65.117897,-1294.084351,-0.000595,0.002643,0.067132,289.658875,14.755926,0.671319,-1294.084351,294.500488,0.000000
103.750008,65.095543,-1294.128784,-0.000595,0.002644,0.067158,289.559448,14.750860,0.671577,-1294.128784,294.500488,0.000000
104.060005,65.100014,-1294.128784,-0.000586,0.002644,0.067158,289.579315,14.751874,0.671577,-1294.128784,294.500488,0.000000
104.370003,65.054588,-1294.084351,-0.000591,0.002644,0.067158,289.377258,14.741581,0.671577,-1294.084351,294.500488,0.000000
104.680008,65.031502,-1294.084351,-0.000578,0.002644,0.067158,289.274567,14.736349,0.671577,-1294.084351,294.500488,0.000000
104.990005,65.679420,-1294.084351,-0.000586,0.002643,0.067124,292.156647,14.883169,0.671244,-1294.084351,0.067253,0.000000
105.300003,65.534950,-1294.039795,-0.000573,0.002635,0.066941,291.514008,14.850431,0.669412,-1294.039795,0.066741,0.000000
105.610008,65.529732,-1294.084351,-0.000578,0.002620,0.066551,291.490814,14.849250,0.665506,-1294.084351,0.066222,0.000000
105.920006,65.349876,-1294.039795,-0.000582,0.002605,0.066178,290.690765,14.808494,0.661781,-1294.039795,0.065710,0.000000
106.230003,65.242256,-1294.128784,-0.000578,0.002584,0.065632,290.212036,14.784107,0.656316,-1294.128784,0.065190,0.000000
106.540009,65.183052,-1294.084351,-0.000591,0.002565,0.065146,289.948700,14.770691,0.651456,-1294.084351,0.064669,0.000000
106.850006,65.168907,-1294.084351,-0.000582,0.002541,0.064531,289.885773,14.767486,0.645309,-1294.084351,0.064157,0.000000
107.160004,65.111183,-1294.128784,-0.000565,0.002522,0.064071,289.628998,14.754405,0.640707,-1294.128784,0.063638,0.000000
107.470009,65.027779,-1294.084351,-0.000569,0.002507,0.063673,289.257996,14.735505,0.636725,-1294.084351,0.063126,0.000000
107.780006,64.983086,-1294.128784,-0.000591,0.002485,0.063126,289.059204,14.725378,0.631260,-1294.128784,0.062605,0.000000
108.090004,64.879936,-1294.084351,-0.000582,0.002465,0.062614,288.600372,14.702003,0.626143,-1294.084351,0.062093,0.000000
108.400002,64.836754,-1294.084351,-0.000565,0.002448,0.062180,288.408295,14.692219,0.621798,-1294.084351,0.061573,0.000000
108.710007,64.579063,-1294.128784,-0.000582,0.002421,0.061495,287.262024,14.633824,0.614955,-1294.128784,0.061053,0.000000
109.020004,64.302773,-1294.039795,-0.000578,0.002408,0.061165,286.033020,14.571217,0.611654,-1294.039795,0.060542,0.000000
109.330002,63.752022,-1294.084351,-0.000569,0.002389,0.060689,283.583160,14.446414,0.606885,-1294.084351,0.060021,0.000000
109.640007,63.181557,-1294.084351,-0.000556,0.002377,0.060377,281.045593,14.317145,0.603766,-1294.084351,0.059509,0.000000
109.950005,62.166466,-1294.084351,-0.000552,0.002354,0.059795,276.530243,14.087122,0.597953,-1294.084351,0.058988,0.000000
110.260002,61.253784,-1294.128784,-0.000569,0.002335,0.059309,272.470428,13.880306,0.593093,-1294.128784,0.058469,0.000000
110.570007,59.846588,-1294.128784,-0.000565,0.002315,0.058790,266.210907,13.561431,0.587900,-1294.128784,0.057957,0.000000
110.880005,58.365662,-1294.039795,-0.000569,0.002295,0.058286,259.623444,13.225848,0.582859,-1294.039795,0.057437,0.000000
111.190002,57.100342,-1294.039795,-0.000573,0.002277,0.057844,253.995010,12.939122,0.578438,-1294.039795,0.056925,0.000000
111.500008,55.928482,-1294.084351,-0.000552,0.002262,0.057462,248.782318,12.673575,0.574623,-1294.084351,0.056404,0.000000
111.810005,54.307175,-1294.084351,-0.000573,0.002243,0.056978,241.570374,12.306182,0.569778,-1294.084351,0.055892,0.000000
112.120003,52.533562,-1294.039795,-0.000569,0.002224,0.056483,233.680954,11.904275,0.564827,-1294.039795,0.055373,0.000000
112.430008,50.635956,-1294.128784,-0.000569,0.002204,0.055989,225.239975,11.474272,0.559892,-1294.128784,0.054852,0.000000
112.740005,48.757706,-1294.039795,-0.000578,0.002185,0.055511,216.885101,11.048654,0.555108,-1294.039795,0.054340,0.000000
113.050003,45.623444,-1294.039795,-0.000586,0.002154,0.054722,202.943207,10.338420,0.547220,-1294.039795,0.053820,0.000000
113.360008,43.996552,-1294.039795,-0.000582,0.002139,0.054324,195.706436,9.969761,0.543238,-1294.039795,0.053308,0.000000
113.670006,42.138412,-1293.995361,-0.000573,0.002123,0.053915,187.441025,9.548700,0.539151,-1293.995361,0.052789,0.000000
113.980003,40.173401,-1294.128784,-0.000586,0.002101,0.053378,178.700211,9.103422,0.533776,-1294.128784,0.052268,0.000000
114.290009,37.130005,-1294.039795,-0.000591,0.002074,0.052675,165.162506,8.413779,0.526751,-1294.039795,0.051756,0.000000
114.600006,35.544815,-1294.039795,-0.000591,0.002058,0.052268,158.111237,8.054570,0.522679,-1294.039795,0.051235,0.000000
114.910004,32.805267,-1294.084351,-0.000599,0.002030,0.051556,145.925110,7.433780,0.515563,-1294.084351,0.050724,0.000000
115.220009,31.377968,-1294.039795,-0.000591,0.002017,0.051235,139.576172,7.110349,0.512354,-1294.039795,0.050204,0.000000
115.530006,29.722397,-1294.084351,-0.000612,0.002000,0.050793,132.211823,6.735192,0.507933,-1294.084351,0.049693,0.000000
115.840004,26.964607,-1293.995361,-0.000608,0.001975,0.050170,119.944565,6.110267,0.501695,-1293.995361,0.049172,0.000000
116.150009,25.054337,-1294.039795,-0.000608,0.001954,0.049640,111.447258,5.677393,0.496397,-1294.039795,0.048651,0.000000
116.460007,23.088585,-1293.995361,-0.000625,0.001936,0.049172,102.703156,5.231948,0.491718,-1293.995361,0.048139,0.000000
116.770004,20.460007,-1294.039795,-0.000629,0.001907,0.048444,91.010658,4.636304,0.484436,-1294.039795,0.047620,0.000000
117.080002,18.534470,-1294.128784,-0.000642,0.001893,0.048079,82.445442,4.199971,0.480788,-1294.128784,0.047108,0.000000
117.390007,17.189827,-1294.039795,-0.000638,0.001878,0.047697,76.464172,3.895270,0.476972,-1294.039795,0.046588,0.000000
117.700005,15.521233,-1293.995361,-0.000642,0.001863,0.047316,69.041893,3.517162,0.473157,-1293.995361,0.046076,0.000000
118.010002,12.912384,-1294.128784,-0.000655,0.001837,0.046648,57.437153,2.925988,0.466481,-1294.128784,0.045555,0.000000
118.320007,10.649483,-1294.039795,-0.000651,0.001813,0.046041,47.371265,2.413207,0.460410,-1294.039795,0.045036,0.000000
118.630005,8.879593,-1294.039795,-0.000668,0.001789,0.045443,39.498402,2.012145,0.454430,-1294.039795,0.044524,0.000000
118.940002,6.828941,-1293.995361,-0.000677,0.001773,0.045036,30.376648,1.547460,0.450357,-1293.995361,0.044003,0.000000
119.250008,5.048996,-1294.173218,-0.000694,0.001752,0.044506,22.459055,1.144119,0.445058,-1294.173218,0.043491,0.000000
119.560005,3.804153,-1294.039795,-0.000681,0.001737,0.044108,16.921721,0.862033,0.441077,-1294.039795,0.042971,0.000000
119.870003,1.656311,-1294.084351,-0.000694,0.001713,0.043501,7.367640,0.375325,0.435006,-1294.084351,0.042451,0.000000
120.180008,-0.116554,-1294.084351,-0.000711,0.001690,0.042919,-0.518459,-0.026412,0.429192,-1294.084351,0.041940,0.000000
120.490005,-1.321548,-1294.039795,-0.000729,0.001673,0.042486,-5.878541,-0.299467,0.424862,-1294.039795,0.041419,0.000000
120.800003,-0.545525,-1294.084351,-0.000772,0.001647,0.041826,-2.426615,-0.123618,0.418261,-1294.084351,0.040907,0.000000
121.110008,-0.221565,-1294.084351,-0.000798,0.001631,0.041428,-0.985571,-0.050207,0.414279,-1294.084351,0.040386,0.000000
121.420006,-0.121765,-1294.084351,-0.000828,0.001616,0.041037,-0.541638,-0.027592,0.410373,-1294.084351,0.039876,0.000000
121.730003,-0.162354,-1294.084351,-0.000854,0.001591,0.040414,-0.722184,-0.036790,0.404136,-1294.084351,0.039355,0.000000
122.040009,-0.058464,-1294.039795,-0.000897,0.001566,0.039788,-0.260061,-0.013248,0.397883,-1294.039795,0.038835,0.000000
122.350006,-0.068146,-1294.039795,-0.000914,0.001549,0.039346,-0.303127,-0.015442,0.393463,-1294.039795,0.038323,0.000000
122.660004,-0.073357,-1294.039795,-0.000953,0.001519,0.038592,-0.326307,-0.016623,0.385923,-1294.039795,0.037802,0.000000
122.970009,-0.051758,-1294.084351,-0.000970,0.001508,0.038306,-0.230230,-0.011728,0.383062,-1294.084351,0.037290,0.000000
123.280006,-0.048782,-1294.084351,-0.001013,0.001492,0.037890,-0.216995,-0.011054,0.378898,-1294.084351,0.036771,0.000000
123.590004,-0.072243,-1293.995361,-0.001022,0.001471,0.037360,-0.321352,-0.016370,0.373599,-1293.995361,0.036250,0.000000
123.900009,-0.057343,-1294.128784,-0.001052,0.001457,0.037013,-0.255072,-0.012994,0.370132,-1294.128784,0.035738,0.000000
124.210007,-0.036118,-1294.084351,-0.001087,0.001432,0.036380,-0.160659,-0.008184,0.363804,-1294.084351,0.035218,0.000000
124.520004,-0.019363,-1294.039795,-0.001104,0.001409,0.035782,-0.086133,-0.004388,0.357824,-1294.039795,0.034706,0.000000
124.830009,-0.027184,-1294.084351,-0.001147,0.001388,0.035262,-0.120918,-0.006160,0.352616,-1294.084351,0.034187,0.000000
125.100006,-0.008568,-1294.128784,-0.001155,0.001387,0.035236,-0.038112,-0.001941,0.352359,-1294.128784,0.035097,0.000000