File: Data/Sima compression/P2-11-2_10302024_164537.csv
Time (sec),S:Load (lbs),S:HL1 (DIM),S:LVDT (in),S:Position (in),Ch:Position (mm),Ch:Load (N),Ch:Stress (MPa),Ch:Strain (mm/mm),Ch:HL1 (DIM),Set Point (),Cycles ()
0.110000,0.026070,-1293.417114,-0.003936,-0.004023,-0.102194,0.115964,0.005907,-1.021937,-1293.417114,-0.101994,0.000000
0.430000,0.020477,-1293.461548,-0.003936,-0.004010,-0.101855,0.091088,0.004640,-1.018546,-1293.461548,-0.101335,0.000000
0.750000,0.049156,-1293.461548,-0.003954,-0.003828,-0.097223,0.218658,0.011139,-0.972234,-1293.461548,-0.095993,0.000000
1.070000,0.006332,-1293.506104,-0.003773,-0.003623,-0.092029,0.028168,0.001435,-0.920290,-1293.506104,-0.090668,0.000000
1.390000,-0.005211,-1293.461548,-0.003544,-0.003407,-0.086539,-0.023179,-0.001181,-0.865394,-1293.461548,-0.085343,0.000000
1.710000,0.032768,-1293.506104,-0.003333,-0.003195,-0.081145,0.145760,0.007425,-0.811451,-1293.506104,-0.080001,0.000000
2.030000,0.141129,-1293.372559,-0.003255,-0.000006,-0.000148,0.627771,0.031980,-0.001484,-1293.372559,0.000086,0.000000
2.350000,0.145973,-1293.506104,-0.003247,-0.000006,-0.000148,0.649321,0.033078,-0.001484,-1293.506104,0.000095,0.000000
2.670000,0.113571,-1293.461548,-0.003247,-0.000006,-0.000148,0.505190,0.025736,-0.001484,-1293.461548,0.000633,0.000000
2.990000,0.122513,-1293.461548,-0.003260,0.000004,0.000104,0.544964,0.027762,0.001045,-1293.461548,0.001161,0.000000
3.310000,0.361946,-1293.372559,-0.003238,0.000032,0.000805,1.610017,0.082018,0.008054,-1293.372559,0.001699,0.000000
3.630000,0.507919,-1293.417114,-0.003229,0.000047,0.001205,2.259338,0.115096,0.012051,-1293.417114,0.002229,0.000000
3.950000,0.832626,-1293.461548,-0.003203,0.000075,0.001917,3.703707,0.188676,0.019167,-1293.461548,0.002766,0.000000
4.270000,1.052696,-1293.506104,-0.003195,0.000091,0.002324,4.682627,0.238544,0.023239,-1293.506104,0.003294,0.000000
4.590000,1.318199,-1293.506104,-0.003165,0.000112,0.002836,5.863643,0.298708,0.028356,-1293.506104,0.003833,0.000000
4.910000,1.693550,-1293.506104,-0.003139,0.000134,0.003399,7.533287,0.383764,0.033988,-1293.506104,0.004362,0.000000
5.230000,2.261787,-1293.417114,-0.003117,0.000158,0.004015,10.060933,0.512528,0.040150,-1293.417114,0.004899,0.000000
5.550000,2.480743,-1293.417114,-0.003122,0.000169,0.004292,11.034898,0.562144,0.042921,-1293.417114,0.005429,0.000000
5.870000,3.034836,-1293.461548,-0.003096,0.000195,0.004943,13.499624,0.687704,0.049431,-1293.461548,0.005967,0.000000
6.190000,3.566208,-1293.461548,-0.003083,0.000217,0.005515,15.863285,0.808114,0.055153,-1293.461548,0.006495,0.000000
6.510000,4.075615,-1293.506104,-0.003065,0.000239,0.006062,18.129240,0.923548,0.060619,-1293.506104,0.007032,0.000000
6.830000,4.471451,-1293.461548,-0.003048,0.000258,0.006555,19.890007,1.013245,0.065554,-1293.461548,0.007562,0.000000
7.150001,5.243004,-1293.461548,-0.003044,0.000283,0.007197,23.322046,1.188082,0.071974,-1293.461548,0.008100,0.000000
7.470000,5.332748,-1293.461548,-0.003027,0.000293,0.007441,23.721251,1.208418,0.074411,-1293.461548,0.008628,0.000000
7.790000,6.045464,-1293.461548,-0.003009,0.000317,0.008048,26.891565,1.369922,0.080482,-1293.461548,0.009166,0.000000
8.110001,6.811066,-1293.506104,-0.002988,0.000346,0.008793,30.297132,1.543410,0.087931,-1293.506104,0.009695,0.000000
8.430000,7.284348,-1293.461548,-0.002958,0.000366,0.009296,32.402397,1.650657,0.092957,-1293.461548,0.010233,0.000000
8.750000,7.734924,-1293.461548,-0.002949,0.000385,0.009782,34.406662,1.752759,0.097817,-1293.461548,0.010761,0.000000
9.070001,8.288269,-1293.461548,-0.002928,0.000408,0.010354,36.868061,1.878149,0.103540,-1293.461548,0.011300,0.000000
9.390000,8.455833,-1293.506104,-0.002936,0.000420,0.010675,37.613426,1.916119,0.106749,-1293.506104,0.011829,0.000000
9.710000,9.387512,-1293.506104,-0.002919,0.000450,0.011430,41.757740,2.127241,0.114304,-1293.506104,0.012366,0.000000
10.030001,9.943832,-1293.461548,-0.002884,0.000475,0.012071,44.232376,2.253305,0.120708,-1293.461548,0.012896,0.000000
10.350000,10.245087,-1293.417114,-0.002867,0.000495,0.012575,45.572422,2.321570,0.125749,-1293.417114,0.013433,0.000000
10.670000,10.550430,-1293.461548,-0.002850,0.000515,0.013078,46.930656,2.390762,0.130776,-1293.461548,0.013962,0.000000
10.990001,11.050522,-1293.506104,-0.002815,0.000535,0.013598,49.155178,2.504084,0.135984,-1293.506104,0.014499,0.000000
11.310000,11.062813,-1293.461548,-0.002807,0.000548,0.013910,49.209850,2.506869,0.139102,-1293.461548,0.015029,0.000000
11.630000,11.435562,-1293.506104,-0.002785,0.000568,0.014422,50.867920,2.591335,0.144220,-1293.506104,0.015567,0.000000
11.950001,12.058167,-1293.461548,-0.002764,0.000593,0.015071,53.637402,2.732420,0.150715,-1293.461548,0.016095,0.000000
12.270000,12.433517,-1293.372559,-0.002751,0.000618,0.015688,55.307049,2.817475,0.156876,-1293.372559,0.016632,0.000000
12.590000,12.574272,-1293.417114,-0.002734,0.000636,0.016165,55.933155,2.849371,0.161645,-1293.417114,0.017162,0.000000
12.910001,13.039368,-1293.461548,-0.002716,0.000661,0.016781,58.002003,2.954763,0.167807,-1293.461548,0.017700,0.000000
13.230000,12.936218,-1293.461548,-0.002690,0.000672,0.017067,57.543171,2.931389,0.170668,-1293.461548,0.018228,0.000000
13.550000,13.321251,-1293.417114,-0.002677,0.000698,0.017725,59.255882,3.018639,0.177254,-1293.417114,0.018767,0.000000
13.870001,13.828796,-1293.372559,-0.002656,0.000721,0.018307,61.513557,3.133650,0.183068,-1293.372559,0.019295,0.000000
14.190001,13.702934,-1293.506104,-0.002656,0.000739,0.018775,60.953697,3.105129,0.187746,-1293.506104,0.019833,0.000000
14.510000,13.985939,-1293.461548,-0.002621,0.000758,0.019261,62.212563,3.169259,0.192606,-1293.461548,0.020363,0.000000
14.830001,14.492363,-1293.461548,-0.002600,0.000784,0.019902,64.465248,3.284016,0.199025,-1293.461548,0.020900,0.000000
15.150001,14.694191,-1293.461548,-0.002587,0.000804,0.020431,65.363029,3.329751,0.204309,-1293.461548,0.021429,0.000000
15.470000,14.553436,-1293.417114,-0.002574,0.000818,0.020770,64.736916,3.297856,0.207700,-1293.417114,0.021966,0.000000
15.790001,15.194656,-1293.506104,-0.002539,0.000847,0.021524,67.589211,3.443158,0.215239,-1293.506104,0.022496,0.000000
16.110001,15.171196,-1293.461548,-0.002522,0.000867,0.022027,67.484848,3.437842,0.220266,-1293.461548,0.023033,0.000000
16.430000,15.219978,-1293.506104,-0.002527,0.000884,0.022461,67.701843,3.448896,0.224611,-1293.506104,0.023562,0.000000
16.750000,15.167473,-1293.461548,-0.002488,0.000903,0.022938,67.468292,3.436999,0.229380,-1293.461548,0.024099,0.000000
17.070002,15.715607,-1293.461548,-0.002458,0.000926,0.023527,69.906509,3.561208,0.235269,-1293.461548,0.024638,0.000000
17.390001,15.610596,-1293.506104,-0.002453,0.000943,0.023952,69.439400,3.537412,0.239523,-1293.506104,0.025167,0.000000
17.710001,16.272675,-1293.506104,-0.002436,0.000973,0.024706,72.384468,3.687441,0.247063,-1293.506104,0.025704,0.000000
18.030001,16.231346,-1293.461548,-0.002406,0.000993,0.025218,72.200630,3.678076,0.252180,-1293.461548,0.026234,0.000000
18.350000,16.306190,-1293.417114,-0.002380,0.001013,0.025739,72.533554,3.695035,0.257388,-1293.417114,0.026771,0.000000
18.670000,16.366890,-1293.372559,-0.002376,0.001032,0.026207,72.803566,3.708790,0.262066,-1293.372559,0.027300,0.000000
18.990002,16.649521,-1293.506104,-0.002358,0.001055,0.026797,74.060768,3.772835,0.267971,-1293.506104,0.027837,0.000000
19.310001,16.583237,-1293.506104,-0.002337,0.001071,0.027204,73.765923,3.757815,0.272043,-1293.506104,0.028367,0.000000
19.630001,17.325371,-1293.506104,-0.002302,0.001103,0.028020,77.067101,3.925985,0.280203,-1293.506104,0.028904,0.000000
19.950001,16.913528,-1293.417114,-0.002285,0.001118,0.028393,75.235130,3.832660,0.283928,-1293.417114,0.029433,0.000000
20.270000,17.175308,-1293.506104,-0.002264,0.001141,0.028974,76.399590,3.891981,0.289741,-1293.506104,0.029970,0.000000
20.590000,17.081467,-1293.372559,-0.002242,0.001157,0.029398,75.982155,3.870716,0.293980,-1293.372559,0.030500,0.000000
20.910002,17.376389,-1293.461548,-0.002225,0.001180,0.029963,77.294037,3.937546,0.299627,-1293.461548,0.031038,0.000000
21.230001,17.397614,-1293.461548,-0.002207,0.001199,0.030447,77.388451,3.942356,0.304472,-1293.461548,0.031566,0.000000
21.550001,17.980751,-1293.461548,-0.002182,0.001225,0.031124,79.982376,4.074496,0.311239,-1293.461548,0.032105,0.000000
21.870001,18.015755,-1293.417114,-0.002169,0.001248,0.031689,80.138077,4.082428,0.316887,-1293.417114,0.032633,0.000000
22.190001,17.961388,-1293.461548,-0.002151,0.001266,0.032166,79.896240,4.070108,0.321656,-1293.461548,0.033171,0.000000
22.510000,18.155022,-1293.506104,-0.002126,0.001287,0.032694,80.757568,4.113986,0.326939,-1293.506104,0.033701,0.000000
22.830002,18.495743,-1293.550537,-0.002113,0.001309,0.033240,82.273170,4.191195,0.332405,-1293.550537,0.034238,0.000000
23.150002,18.458504,-1293.417114,-0.002078,0.001329,0.033752,82.107529,4.182757,0.337522,-1293.417114,0.034767,0.000000
23.470001,18.938118,-1293.417114,-0.002061,0.001354,0.034394,84.240959,4.291439,0.343941,-1293.417114,0.035304,0.000000
23.790001,18.808533,-1293.461548,-0.002044,0.001371,0.034827,83.664536,4.262074,0.348271,-1293.461548,0.035834,0.000000
24.110001,18.948547,-1293.506104,-0.002026,0.001392,0.035357,84.287346,4.293802,0.353570,-1293.506104,0.036371,0.000000
24.430000,18.999557,-1293.506104,-0.001996,0.001411,0.035841,84.514252,4.305361,0.358414,-1293.506104,0.036900,0.000000
24.750002,19.483269,-1293.461548,-0.001979,0.001434,0.036432,86.665909,4.414972,0.364319,-1293.461548,0.037437,0.000000
25.070002,19.462791,-1293.417114,-0.001966,0.001452,0.036892,86.574821,4.410331,0.368921,-1293.417114,0.037967,0.000000
25.390001,20.251106,-1293.506104,-0.001953,0.001482,0.037637,90.081421,4.588966,0.376370,-1293.506104,0.038504,0.000000
25.710001,19.977409,-1293.506104,-0.001927,0.001498,0.038053,88.863953,4.526946,0.380533,-1293.506104,0.039033,0.000000
26.030001,19.917084,-1293.550537,-0.001901,0.001517,0.038521,88.595612,4.513276,0.385211,-1293.550537,0.039572,0.000000
26.350000,20.354622,-1293.417114,-0.001880,0.001538,0.039068,90.541878,4.612423,0.390677,-1293.417114,0.040100,0.000000
26.670002,20.569481,-1293.417114,-0.001863,0.001561,0.039640,91.497620,4.661111,0.396400,-1293.417114,0.040638,0.000000
26.990002,20.570602,-1293.506104,-0.001845,0.001577,0.040049,91.502609,4.661366,0.400487,-1293.506104,0.041168,0.000000
27.310001,21.231934,-1293.550537,-0.001815,0.001605,0.040768,94.444359,4.811225,0.407679,-1293.550537,0.041705,0.000000
27.630001,21.068832,-1293.550537,-0.001798,0.001619,0.041133,93.718849,4.774266,0.411327,-1293.550537,0.042233,0.000000
27.950001,21.643036,-1293.506104,-0.001772,0.001646,0.041817,96.273033,4.904382,0.418170,-1293.506104,0.042771,0.000000
28.270000,21.725327,-1293.506104,-0.001759,0.001665,0.042285,96.639076,4.923029,0.422848,-1293.506104,0.043301,0.000000
28.590002,21.917847,-1293.506104,-0.001759,0.001686,0.042815,97.495453,4.966655,0.428147,-1293.506104,0.043838,0.000000
28.910002,21.861244,-1293.461548,-0.001746,0.001704,0.043273,97.243668,4.953829,0.432735,-1293.461548,0.044367,0.000000
29.230001,22.364319,-1293.594971,-0.001712,0.001729,0.043924,99.481461,5.067827,0.439245,-1293.594971,0.044904,0.000000
29.550001,22.820847,-1293.506104,-0.001686,0.001753,0.044515,101.512192,5.171278,0.445149,-1293.506104,0.045434,0.000000
29.870001,22.899788,-1293.461548,-0.001660,0.001772,0.044999,101.863342,5.189166,0.449994,-1293.461548,0.045971,0.000000
30.190001,23.239395,-1293.550537,-0.001647,0.001797,0.045634,103.373993,5.266122,0.456337,-1293.550537,0.046500,0.000000
30.510002,23.171623,-1293.461548,-0.001630,0.001811,0.046006,103.072525,5.250765,0.460062,-1293.461548,0.047039,0.000000
30.830002,23.576393,-1293.550537,-0.001613,0.001831,0.046509,104.873032,5.342487,0.465088,-1293.550537,0.047567,0.000000
31.150002,24.091011,-1293.461548,-0.001608,0.001855,0.047107,107.162170,5.459101,0.471068,-1293.461548,0.048104,0.000000
31.470001,24.521843,-1293.417114,-0.001578,0.001879,0.047732,109.078606,5.556729,0.477321,-1293.417114,0.048634,0.000000
31.790001,24.607117,-1293.461548,-0.001552,0.001900,0.048251,109.457924,5.576052,0.482514,-1293.461548,0.049172,0.000000
32.110001,24.890862,-1293.550537,-0.001539,0.001921,0.048798,110.720085,5.640350,0.487979,-1293.550537,0.049700,0.000000
32.430000,25.137375,-1293.506104,-0.001505,0.001941,0.049310,111.816628,5.696210,0.493096,-1293.506104,0.050238,0.000000
32.750000,25.234192,-1293.461548,-0.001492,0.001958,0.049735,112.247292,5.718150,0.497350,-1293.461548,0.050768,0.000000
33.070000,25.965157,-1293.417114,-0.001479,0.001981,0.050325,115.498787,5.883789,0.503255,-1293.417114,0.051305,0.000000
33.390003,25.980423,-1293.461548,-0.001466,0.002000,0.050793,115.566696,5.887248,0.507933,-1293.461548,0.051833,0.000000
33.710003,26.693146,-1293.461548,-0.001449,0.002025,0.051443,118.737045,6.048753,0.514428,-1293.461548,0.052371,0.000000
34.030003,26.928116,-1293.550537,-0.001431,0.002044,0.051921,119.782242,6.101998,0.519212,-1293.550537,0.052901,0.000000
34.350002,26.892365,-1293.417114,-0.001393,0.002060,0.052336,119.623215,6.093897,0.523360,-1293.417114,0.053438,0.000000
34.670002,27.418900,-1293.417114,-0.001401,0.002083,0.052917,121.965355,6.213212,0.529174,-1293.417114,0.053967,0.000000
34.990002,28.177055,-1293.417114,-0.001367,0.002109,0.053577,125.337799,6.385012,0.535775,-1293.417114,0.054506,0.000000
35.310001,28.023262,-1293.461548,-0.001358,0.002123,0.053915,124.653694,6.350162,0.539151,-1293.461548,0.055034,0.000000
35.630001,28.506599,-1293.550537,-0.001328,0.002145,0.054487,126.803688,6.459688,0.544873,-1293.550537,0.055571,0.000000
35.950001,28.874130,-1293.461548,-0.001302,0.002167,0.055051,128.438553,6.542971,0.550505,-1293.461548,0.056101,0.000000
36.270000,29.411469,-1293.372559,-0.001289,0.002186,0.055527,130.828751,6.664734,0.555274,-1293.372559,0.056639,0.000000
36.590000,29.992371,-1293.461548,-0.001272,0.002209,0.056118,133.412735,6.796368,0.561179,-1293.461548,0.057167,0.000000
36.910000,29.740273,-1293.461548,-0.001255,0.002224,0.056499,132.291336,6.739242,0.564994,-1293.461548,0.057705,0.000000
37.230003,30.922554,-1293.461548,-0.001237,0.002250,0.057158,137.550385,7.007151,0.571580,-1293.461548,0.058234,0.000000
37.550003,31.474037,-1293.461548,-0.001216,0.002273,0.057739,140.003510,7.132119,0.577393,-1293.461548,0.058772,0.000000
37.870003,31.594688,-1293.461548,-0.001199,0.002290,0.058165,140.540192,7.159459,0.581648,-1293.461548,0.059300,0.000000
38.190002,32.106323,-1293.461548,-0.001190,0.002311,0.058693,142.816055,7.275397,0.586931,-1293.461548,0.059838,0.000000
38.510002,32.617966,-1293.506104,-0.001173,0.002334,0.059274,145.091965,7.391336,0.592745,-1293.506104,0.060368,0.000000
38.830002,33.223442,-1293.506104,-0.001147,0.002355,0.059821,147.785248,7.528540,0.598210,-1293.506104,0.060905,0.000000
39.150002,34.221405,-1293.506104,-0.001130,0.002378,0.060393,152.224411,7.754682,0.603933,-1293.506104,0.061433,0.000000
39.470001,34.658195,-1293.417114,-0.001125,0.002397,0.060896,154.167358,7.853659,0.608959,-1293.417114,0.061972,0.000000
39.790001,35.133339,-1293.417114,-0.001099,0.002417,0.061399,156.280899,7.961329,0.613986,-1293.417114,0.062501,0.000000
40.110001,35.582794,-1293.461548,-0.001082,0.002436,0.061868,158.280167,8.063176,0.618679,-1293.461548,0.063038,0.000000
40.430000,36.556923,-1293.461548,-0.001065,0.002461,0.062510,162.613312,8.283917,0.625098,-1293.461548,0.063567,0.000000
40.750004,36.757256,-1293.506104,-0.001056,0.002478,0.062952,163.504440,8.329312,0.629519,-1293.506104,0.064106,0.000000
41.070004,38.284729,-1293.417114,-0.001035,0.002508,0.063697,170.298981,8.675444,0.636968,-1293.417114,0.064634,0.000000
41.390003,38.512253,-1293.461548,-0.001022,0.002526,0.064148,171.311050,8.727001,0.641479,-1293.461548,0.065171,0.000000
41.710003,39.095383,-1293.417114,-0.000996,0.002545,0.064643,173.904953,8.859140,0.646430,-1293.417114,0.065701,0.000000
42.030003,40.417679,-1293.550537,-0.001000,0.002571,0.065292,179.786819,9.158777,0.652925,-1293.550537,0.066239,0.000000
42.350002,40.248619,-1293.461548,-0.000979,0.002582,0.065571,179.034805,9.120467,0.655710,-1293.461548,0.066767,0.000000
42.670002,41.477821,-1293.461548,-0.000961,0.002606,0.066204,184.502563,9.399009,0.662039,-1293.461548,0.067305,0.000000
42.990002,42.963959,-1293.372559,-0.000949,0.002634,0.066897,191.113235,9.735772,0.668973,-1293.372559,0.067834,0.000000
43.310001,43.635353,-1293.461548,-0.000936,0.002655,0.067427,194.099747,9.887913,0.674271,-1293.461548,0.068372,0.000000
43.630001,44.151459,-1293.461548,-0.000927,0.002673,0.067886,196.395493,10.004864,0.678859,-1293.461548,0.068900,0.000000
43.950001,45.199318,-1293.550537,-0.000914,0.002695,0.068449,201.056610,10.242312,0.684491,-1293.550537,0.069438,0.000000
44.270000,45.753777,-1293.506104,-0.000884,0.002711,0.068858,203.522964,10.367953,0.688578,-1293.506104,0.069968,0.000000
44.590004,47.187408,-1293.461548,-0.000884,0.002736,0.069500,209.900070,10.692820,0.694998,-1293.461548,0.070505,0.000000
44.910004,48.489967,-1293.417114,-0.000871,0.002761,0.070124,215.694153,10.987984,0.701235,-1293.417114,0.071033,0.000000
45.230003,48.794571,-1293.506104,-0.000854,0.002778,0.070566,217.049088,11.057008,0.705656,-1293.506104,0.071572,0.000000
45.550003,49.877426,-1293.461548,-0.000849,0.002796,0.071008,221.865875,11.302386,0.710077,-1293.461548,0.072101,0.000000
45.870003,51.175522,-1293.461548,-0.000832,0.002818,0.071589,227.640091,11.596539,0.715890,-1293.461548,0.072638,0.000000
46.190002,51.938141,-1293.461548,-0.000811,0.002834,0.071989,231.032394,11.769351,0.719887,-1293.461548,0.073168,0.000000
46.510002,53.133453,-1293.506104,-0.000815,0.002856,0.072552,236.349411,12.040213,0.725519,-1293.506104,0.073706,0.000000
46.830002,55.283905,-1293.417114,-0.000806,0.002886,0.073298,245.915085,12.527512,0.732983,-1293.417114,0.074234,0.000000
47.150002,55.851402,-1293.461548,-0.000793,0.002902,0.073713,248.439438,12.656109,0.737131,-1293.461548,0.074771,0.000000
47.470001,56.983040,-1293.461548,-0.000772,0.002921,0.074182,253.473221,12.912541,0.741824,-1293.461548,0.075301,0.000000
47.790001,58.807663,-1293.506104,-0.000772,0.002946,0.074841,261.589539,13.326007,0.748410,-1293.506104,0.075839,0.000000
48.110001,59.733757,-1293.417114,-0.000767,0.002962,0.075241,265.709015,13.535863,0.752407,-1293.417114,0.076367,0.000000
48.430004,60.475151,-1293.506104,-0.000746,0.002977,0.075604,269.006897,13.703865,0.756040,-1293.506104,0.076905,0.000000
48.750004,62.822586,-1293.506104,-0.000742,0.003008,0.076411,279.448822,14.235802,0.764110,-1293.506104,0.077434,0.000000
49.070004,63.648140,-1293.550537,-0.000729,0.003026,0.076853,283.121063,14.422874,0.768530,-1293.550537,0.077972,0.000000
49.390003,65.553200,-1293.461548,-0.000729,0.003050,0.077460,291.595184,14.854568,0.774601,-1293.461548,0.078500,0.000000
49.710003,66.079353,-1293.506104,-0.000711,0.003053,0.077546,293.935638,14.973796,0.775464,-1293.506104,0.013623,0.000000
50.030003,65.275032,-1293.461548,-0.000707,0.003053,0.077539,290.357849,14.791533,0.775389,-1293.461548,294.500488,0.000000
50.350002,66.570885,-1293.506104,-0.000703,0.003051,0.077495,296.122070,15.085177,0.774950,-1293.506104,294.500488,0.000000
50.670002,65.822044,-1293.506104,-0.000694,0.003041,0.077244,292.791077,14.915488,0.772436,-1293.506104,294.500488,0.000000
50.990002,65.294029,-1293.506104,-0.000681,0.003054,0.077581,290.442352,14.795838,0.775813,-1293.506104,294.500488,0.000000
51.310001,65.312263,-1293.417114,-0.000664,0.003076,0.078119,290.523468,14.799971,0.781187,-1293.417114,294.500488,0.000000
51.630001,65.269066,-1293.417114,-0.000668,0.003079,0.078214,290.331299,14.790182,0.782141,-1293.417114,294.500488,0.000000
51.950001,65.306313,-1293.506104,-0.000673,0.003084,0.078337,290.496979,14.798622,0.783367,-1293.506104,294.500488,0.000000
52.270004,65.108574,-1293.594971,-0.000664,0.003084,0.078344,289.617401,14.753814,0.783443,-1293.594971,294.500488,0.000000
52.590004,65.188271,-1293.461548,-0.000673,0.003089,0.078458,289.971924,14.771873,0.784578,-1293.461548,294.500488,0.000000
52.910004,65.028145,-1293.506104,-0.000677,0.003089,0.078467,289.259644,14.735588,0.784669,-1293.506104,294.500488,0.000000
53.230003,65.050484,-1293.461548,-0.000681,0.003095,0.078605,289.359009,14.740650,0.786047,-1293.461548,294.500488,0.000000
53.550003,65.265724,-1293.506104,-0.000677,0.003096,0.078640,290.316437,14.789425,0.786395,-1293.506104,294.500488,0.000000
53.870003,65.220299,-1293.506104,-0.000668,0.003098,0.078700,290.114380,14.779131,0.787001,-1293.506104,294.500488,0.000000
54.190002,65.121986,-1293.506104,-0.000664,0.003098,0.078700,289.677063,14.756853,0.787001,-1293.506104,294.500488,0.000000
54.510002,65.067986,-1293.461548,-0.000655,0.003100,0.078735,289.436859,14.744617,0.787349,-1293.461548,294.500488,0.000000
54.830002,65.048622,-1293.506104,-0.000668,0.003103,0.078805,289.350708,14.740228,0.788045,-1293.506104,294.500488,0.000000
55.150002,65.129433,-1293.594971,-0.000651,0.003104,0.078848,289.710175,14.758540,0.788484,-1293.594971,294.500488,0.000000
55.470001,65.072456,-1293.594971,-0.000655,0.003105,0.078865,289.456757,14.745629,0.788651,-1293.594971,294.500488,0.000000
55.790001,65.119011,-1293.506104,-0.000660,0.003108,0.078935,289.663818,14.756179,0.789347,-1293.506104,294.500488,0.000000
56.110004,65.075813,-1293.461548,-0.000655,0.003108,0.078935,289.471680,14.746390,0.789347,-1293.461548,294.500488,0.000000
56.430004,65.309288,-1293.461548,-0.000668,0.003112,0.079039,290.510223,14.799295,0.790392,-1293.461548,294.500488,0.000000
56.750004,65.253426,-1293.461548,-0.000664,0.003112,0.079039,290.261719,14.786638,0.790392,-1293.461548,294.500488,0.000000
57.070004,65.176353,-1293.594971,-0.000660,0.003112,0.079039,289.918915,14.769173,0.790392,-1293.594971,294.500488,0.000000
57.390003,65.093681,-1293.550537,-0.000673,0.003112,0.079056,289.551147,14.750440,0.790559,-1293.550537,294.500488,0.000000
57.710003,65.215080,-1293.550537,-0.000647,0.003115,0.079116,290.091156,14.777948,0.791164,-1293.550537,294.500488,0.000000
58.030003,65.150291,-1293.550537,-0.000664,0.003115,0.079116,289.802979,14.763268,0.791164,-1293.550537,294.500488,0.000000
58.350002,65.066872,-1293.550537,-0.000651,0.003115,0.079126,289.431915,14.744364,0.791255,-1293.550537,294.500488,0.000000
58.670002,65.448189,-1293.550537,-0.000655,0.003120,0.079256,291.128082,14.830771,0.792557,-1293.550537,294.500488,0.000000
58.990002,65.397911,-1293.594971,-0.000647,0.003120,0.079256,290.904449,14.819378,0.792557,-1293.594971,294.500488,0.000000
59.310001,65.342064,-1293.506104,-0.000638,0.003120,0.079256,290.656006,14.806724,0.792557,-1293.506104,294.500488,0.000000
59.630001,65.285088,-1293.550537,-0.000651,0.003120,0.079256,290.402588,14.793813,0.792557,-1293.550537,294.500488,0.000000
59.950005,65.222893,-1293.506104,-0.000642,0.003121,0.079265,290.125916,14.779719,0.792648,-1293.506104,294.500488,0.000000
60.270004,65.190498,-1293.550537,-0.000651,0.003123,0.079316,289.981812,14.772378,0.793163,-1293.550537,294.500488,0.000000
60.590004,65.209496,-1293.594971,-0.000647,0.003123,0.079316,290.066315,14.776683,0.793163,-1293.594971,294.500488,0.000000
60.910004,65.159966,-1293.506104,-0.000638,0.003123,0.079316,289.846008,14.765460,0.793163,-1293.506104,294.500488,0.000000
61.230003,65.310036,-1293.506104,-0.000638,0.003126,0.079412,290.513550,14.799465,0.794116,-1293.506104,294.500488,0.000000
61.550003,65.351372,-1293.506104,-0.000638,0.003126,0.079412,290.697418,14.808832,0.794116,-1293.506104,294.500488,0.000000
61.870003,65.317116,-1293.550537,-0.000647,0.003126,0.079412,290.545044,14.801069,0.794116,-1293.550537,294.500488,0.000000
62.190002,65.271675,-1293.594971,-0.000638,0.003126,0.079412,290.342926,14.790773,0.794116,-1293.594971,294.500488,0.000000
62.510002,65.238167,-1293.506104,-0.000634,0.003126,0.079412,290.193848,14.783179,0.794116,-1293.506104,294.500488,0.000000
62.830002,65.308922,-1293.506104,-0.000647,0.003129,0.079472,290.508606,14.799213,0.794722,-1293.506104,294.500488,0.000000
63.150002,65.320839,-1293.461548,-0.000634,0.003129,0.079472,290.561615,14.801914,0.794722,-1293.461548,294.500488,0.000000
63.470001,65.288811,-1293.550537,-0.000651,0.003129,0.079472,290.419128,14.794656,0.794722,-1293.550537,294.500488,0.000000
63.790005,65.256783,-1293.550537,-0.000629,0.003129,0.079472,290.276672,14.787398,0.794722,-1293.550537,294.500488,0.000000
64.110001,65.187157,-1293.594971,-0.000625,0.003130,0.079498,289.966949,14.771621,0.794979,-1293.594971,294.500488,0.000000
64.430000,65.261253,-1293.506104,-0.000647,0.003131,0.079524,290.296539,14.788412,0.795237,-1293.506104,294.500488,0.000000
64.750000,65.247108,-1293.417114,-0.000638,0.003131,0.079524,290.233643,14.785206,0.795237,-1293.417114,294.500488,0.000000
65.070000,65.234444,-1293.550537,-0.000634,0.003131,0.079533,290.177307,14.782336,0.795328,-1293.550537,294.500488,0.000000
65.389999,65.302589,-1293.506104,-0.000638,0.003134,0.079593,290.480438,14.797779,0.795933,-1293.506104,294.500488,0.000000
65.710007,65.315987,-1293.594971,-0.000638,0.003134,0.079593,290.540009,14.800814,0.795933,-1293.594971,294.500488,0.000000
66.030006,65.305199,-1293.550537,-0.000625,0.003134,0.079593,290.492035,14.798369,0.795933,-1293.550537,294.500488,0.000000
66.350006,65.279869,-1293.550537,-0.000651,0.003134,0.079593,290.379364,14.792629,0.795933,-1293.550537,294.500488,0.000000
66.670006,65.257164,-1293.506104,-0.000642,0.003134,0.079593,290.278351,14.787484,0.795933,-1293.506104,294.500488,0.000000
66.990005,65.220665,-1293.639526,-0.000629,0.003134,0.079593,290.115997,14.779214,0.795933,-1293.639526,294.500488,0.000000
67.310005,65.216942,-1293.594971,-0.000655,0.003134,0.079611,290.099457,14.778370,0.796115,-1293.594971,294.500488,0.000000
67.630005,65.282845,-1293.594971,-0.000638,0.003136,0.079663,290.392609,14.793304,0.796630,-1293.594971,294.500488,0.000000
67.950005,65.292534,-1293.550537,-0.000638,0.003136,0.079663,290.435699,14.795500,0.796630,-1293.550537,294.500488,0.000000
68.270004,65.290291,-1293.550537,-0.000634,0.003136,0.079663,290.425720,14.794991,0.796630,-1293.550537,294.500488,0.000000
68.590004,65.257896,-1293.550537,-0.000634,0.003136,0.079663,290.281616,14.787651,0.796630,-1293.550537,294.500488,0.000000
68.910004,65.229973,-1293.594971,-0.000629,0.003136,0.079663,290.157410,14.781323,0.796630,-1293.594971,294.500488,0.000000
69.230003,65.211723,-1293.550537,-0.000629,0.003136,0.079663,290.076233,14.777188,0.796630,-1293.550537,294.500488,0.000000
69.550003,65.174858,-1293.506104,-0.000638,0.003136,0.079663,289.912262,14.768834,0.796630,-1293.506104,294.500488,0.000000
69.870003,65.183434,-1293.550537,-0.000642,0.003138,0.079707,289.950378,14.770777,0.797069,-1293.550537,294.500488,0.000000
70.190002,65.212105,-1293.461548,-0.000638,0.003138,0.079707,290.077942,14.777274,0.797069,-1293.461548,294.500488,0.000000
70.510002,65.200554,-1293.550537,-0.000638,0.003138,0.079707,290.026550,14.774657,0.797069,-1293.550537,294.500488,0.000000
70.830002,65.254555,-1293.506104,-0.000634,0.003140,0.079767,290.266754,14.786894,0.797674,-1293.506104,294.500488,0.000000
71.150002,65.307426,-1293.594971,-0.000634,0.003140,0.079767,290.501953,14.798875,0.797674,-1293.594971,294.500488,0.000000
71.470001,65.295891,-1293.506104,-0.000629,0.003140,0.079767,290.450623,14.796261,0.797674,-1293.506104,294.500488,0.000000
71.790001,65.279503,-1293.594971,-0.000642,0.003140,0.079767,290.377716,14.792547,0.797674,-1293.594971,294.500488,0.000000
72.110001,65.261620,-1293.594971,-0.000638,0.003140,0.079767,290.298187,14.788494,0.797674,-1293.594971,294.500488,0.000000
72.430000,65.249336,-1293.550537,-0.000629,0.003140,0.079767,290.243530,14.785711,0.797674,-1293.550537,294.500488,0.000000
72.750000,65.229973,-1293.506104,-0.000642,0.003140,0.079767,290.157410,14.781323,0.797674,-1293.506104,294.500488,0.000000
73.070000,65.210609,-1293.417114,-0.000634,0.003140,0.079767,290.071289,14.776936,0.797674,-1293.417114,294.500488,0.000000
73.390007,65.162941,-1293.550537,-0.000621,0.003140,0.079767,289.859253,14.766133,0.797674,-1293.550537,294.500488,0.000000
73.710007,65.145439,-1293.594971,-0.000625,0.003140,0.079767,289.781372,14.762168,0.797674,-1293.594971,294.500488,0.000000
74.030006,65.114159,-1293.550537,-0.000634,0.003140,0.079767,289.642242,14.755079,0.797674,-1293.550537,294.500488,0.000000
74.350006,65.485420,-1293.550537,-0.000621,0.003146,0.079905,291.293701,14.839208,0.799052,-1293.550537,294.500488,0.000000
74.670006,65.530479,-1293.461548,-0.000629,0.003146,0.079905,291.494141,14.849419,0.799052,-1293.461548,294.500488,0.000000
74.990005,65.531975,-1293.550537,-0.000634,0.003146,0.079905,291.500793,14.849758,0.799052,-1293.550537,294.500488,0.000000
75.310005,65.535316,-1293.550537,-0.000621,0.003146,0.079905,291.515656,14.850515,0.799052,-1293.550537,294.500488,0.000000
75.630005,65.529366,-1293.550537,-0.000642,0.003146,0.079905,291.489166,14.849166,0.799052,-1293.550537,294.500488,0.000000
75.950005,65.504417,-1293.506104,-0.000634,0.003146,0.079905,291.378204,14.843513,0.799052,-1293.506104,294.500488,0.000000
76.270004,65.489143,-1293.550537,-0.000634,0.003146,0.079905,291.310272,14.840053,0.799052,-1293.550537,294.500488,0.000000
76.590004,65.474251,-1293.550537,-0.000638,0.003146,0.079905,291.244019,14.836677,0.799052,-1293.550537,294.500488,0.000000
76.910004,65.445946,-1293.506104,-0.000629,0.003146,0.079905,291.118103,14.830263,0.799052,-1293.506104,294.500488,0.000000
77.230003,65.417656,-1293.550537,-0.000638,0.003146,0.079905,290.992279,14.823853,0.799052,-1293.550537,294.500488,0.000000
77.550003,65.392708,-1293.550537,-0.000629,0.003146,0.079905,290.881287,14.818199,0.799052,-1293.550537,294.500488,0.000000
77.870003,65.372215,-1293.506104,-0.000621,0.003146,0.079905,290.790131,14.813556,0.799052,-1293.506104,294.500488,0.000000
78.190002,65.361427,-1293.550537,-0.000621,0.003146,0.079905,290.742157,14.811111,0.799052,-1293.550537,294.500488,0.000000
78.510002,65.334236,-1293.550537,-0.000621,0.003146,0.079905,290.621185,14.804950,0.799052,-1293.550537,294.500488,0.000000
78.830002,65.311150,-1293.550537,-0.000625,0.003146,0.079905,290.518494,14.799718,0.799052,-1293.550537,294.500488,0.000000
79.150002,65.295509,-1293.506104,-0.000638,0.003146,0.079905,290.448944,14.796174,0.799052,-1293.506104,294.500488,0.000000
79.470001,65.289925,-1293.550537,-0.000612,0.003146,0.079914,290.424103,14.794909,0.799143,-1293.550537,294.500488,0.000000
79.790001,65.288063,-1293.461548,-0.000634,0.003147,0.079932,290.415802,14.794487,0.799324,-1293.461548,294.500488,0.000000
80.110001,65.282845,-1293.550537,-0.000621,0.003147,0.079932,290.392609,14.793304,0.799324,-1293.550537,294.500488,0.000000
80.430000,65.258644,-1293.550537,-0.000629,0.003147,0.079940,290.284943,14.787820,0.799400,-1293.550537,294.500488,0.000000
80.750008,65.245247,-1293.594971,-0.000625,0.003147,0.079940,290.225342,14.784784,0.799400,-1293.594971,294.500488,0.000000
81.070007,65.240395,-1293.506104,-0.000625,0.003147,0.079940,290.203766,14.783685,0.799400,-1293.506104,294.500488,0.000000
81.390007,65.237419,-1293.461548,-0.000634,0.003148,0.079949,290.190521,14.783010,0.799491,-1293.461548,294.500488,0.000000
81.710007,65.233696,-1293.506104,-0.000621,0.003148,0.079958,290.173981,14.782166,0.799582,-1293.506104,294.500488,0.000000
82.030006,65.234062,-1293.594971,-0.000625,0.003149,0.079975,290.175598,14.782249,0.799748,-1293.594971,294.500488,0.000000
82.350006,65.260139,-1293.461548,-0.000642,0.003149,0.079984,290.291595,14.788159,0.799839,-1293.461548,294.500488,0.000000
82.670006,65.260887,-1293.550537,-0.000629,0.003149,0.079984,290.294922,14.788328,0.799839,-1293.550537,294.500488,0.000000
82.990005,65.244499,-1293.639526,-0.000629,0.003149,0.079984,290.222015,14.784615,0.799839,-1293.639526,294.500488,0.000000
83.310005,65.249336,-1293.550537,-0.000629,0.003149,0.079984,290.243530,14.785711,0.799839,-1293.550537,294.500488,0.000000
83.630005,65.257164,-1293.639526,-0.000612,0.003149,0.079993,290.278351,14.787484,0.799930,-1293.639526,294.500488,0.000000
83.950005,65.240028,-1293.639526,-0.000612,0.003149,0.079993,290.202148,14.783602,0.799930,-1293.639526,294.500488,0.000000
84.270004,65.220299,-1293.506104,-0.000625,0.003149,0.079993,290.114380,14.779131,0.799930,-1293.506104,294.500488,0.000000
84.590004,65.218803,-1293.461548,-0.000629,0.003150,0.080010,290.107727,14.778792,0.800097,-1293.461548,294.500488,0.000000
84.910004,65.219170,-1293.506104,-0.000638,0.003150,0.080019,290.109344,14.778874,0.800187,-1293.506104,294.500488,0.000000
85.230003,65.213966,-1293.550537,-0.000638,0.003151,0.080028,290.086212,14.777697,0.800278,-1293.550537,294.500488,0.000000
85.550003,65.223274,-1293.506104,-0.000612,0.003151,0.080035,290.127625,14.779805,0.800354,-1293.506104,294.500488,0.000000
85.870003,65.257896,-1293.550537,-0.000608,0.003152,0.080054,290.281616,14.787651,0.800536,-1293.550537,294.500488,0.000000
86.190002,65.266472,-1293.550537,-0.000625,0.003152,0.080054,290.319763,14.789594,0.800536,-1293.550537,294.500488,0.000000
86.510002,65.262001,-1293.506104,-0.000629,0.003152,0.080063,290.299866,14.788581,0.800626,-1293.506104,294.500488,0.000000
86.830002,65.272789,-1293.550537,-0.000625,0.003152,0.080063,290.347870,14.791025,0.800626,-1293.550537,294.500488,0.000000
87.150002,65.285454,-1293.594971,-0.000629,0.003152,0.080070,290.404205,14.793895,0.800702,-1293.594971,294.500488,0.000000
87.470001,65.285454,-1293.550537,-0.000617,0.003152,0.080070,290.404205,14.793895,0.800702,-1293.550537,294.500488,0.000000
87.790001,65.286201,-1293.506104,-0.000621,0.003153,0.080079,290.407532,14.794065,0.800793,-1293.506104,294.500488,0.000000
88.110001,65.277641,-1293.550537,-0.000612,0.003153,0.080079,290.369446,14.792125,0.800793,-1293.550537,294.500488,0.000000
88.430008,65.282845,-1293.506104,-0.000629,0.003153,0.080088,290.392609,14.793304,0.800884,-1293.506104,294.500488,0.000000
88.750008,65.275032,-1293.550537,-0.000621,0.003153,0.080096,290.357849,14.791533,0.800959,-1293.550537,294.500488,0.000000
89.070007,65.292152,-1293.550537,-0.000625,0.003154,0.080105,290.433990,14.795413,0.801050,-1293.550537,294.500488,0.000000
89.390007,65.308922,-1293.506104,-0.000625,0.003154,0.080114,290.508606,14.799213,0.801141,-1293.506104,294.500488,0.000000
89.710007,65.315620,-1293.594971,-0.000634,0.003154,0.080114,290.538391,14.800731,0.801141,-1293.594971,294.500488,0.000000
90.030006,65.320091,-1293.461548,-0.000617,0.003154,0.080123,290.558289,14.801744,0.801232,-1293.461548,294.500488,0.000000
90.350006,65.310783,-1293.550537,-0.000625,0.003154,0.080123,290.516876,14.799635,0.801232,-1293.550537,294.500488,0.000000
90.670006,65.301094,-1293.550537,-0.000629,0.003154,0.080123,290.473785,14.797440,0.801232,-1293.550537,294.500488,0.000000
90.990005,65.305565,-1293.550537,-0.000612,0.003154,0.080123,290.493652,14.798452,0.801232,-1293.550537,294.500488,0.000000
91.310005,65.304451,-1293.594971,-0.000625,0.003154,0.080123,290.488708,14.798200,0.801232,-1293.594971,294.500488,0.000000
91.630005,65.290291,-1293.550537,-0.000621,0.003154,0.080123,290.425720,14.794991,0.801232,-1293.550537,294.500488,0.000000
91.950005,65.280251,-1293.550537,-0.000625,0.003154,0.080123,290.381042,14.792717,0.801232,-1293.550537,294.500488,0.000000
92.270004,65.288429,-1293.639526,-0.000621,0.003155,0.080140,290.417450,14.794570,0.801399,-1293.639526,294.500488,0.000000
92.590004,65.286949,-1293.550537,-0.000634,0.003155,0.080149,290.410858,14.794234,0.801489,-1293.550537,294.500488,0.000000
92.910004,65.294395,-1293.506104,-0.000621,0.003155,0.080149,290.443970,14.795921,0.801489,-1293.506104,294.500488,0.000000
93.230003,65.285454,-1293.506104,-0.000617,0.003155,0.080149,290.404205,14.793895,0.801489,-1293.506104,294.500488,0.000000
93.550003,65.284340,-1293.550537,-0.000617,0.003155,0.080149,290.399261,14.793643,0.801489,-1293.550537,294.500488,0.000000
93.870003,65.278755,-1293.550537,-0.000612,0.003155,0.080149,290.374420,14.792377,0.801489,-1293.550537,294.500488,0.000000
94.190002,65.275780,-1293.506104,-0.000608,0.003156,0.080166,290.361176,14.791703,0.801656,-1293.506104,294.500488,0.000000
94.510002,65.268700,-1293.550537,-0.000617,0.003156,0.080166,290.329681,14.790098,0.801656,-1293.550537,294.500488,0.000000
94.830002,65.267952,-1293.594971,-0.000625,0.003156,0.080166,290.326355,14.789929,0.801656,-1293.594971,294.500488,0.000000
95.150002,65.290672,-1293.639526,-0.000621,0.003157,0.080191,290.427429,14.795078,0.801913,-1293.639526,294.500488,0.000000
95.470001,65.293648,-1293.594971,-0.000621,0.003157,0.080191,290.440643,14.795753,0.801913,-1293.594971,294.500488,0.000000
95.790001,65.309288,-1293.550537,-0.000612,0.003157,0.080191,290.510223,14.799295,0.801913,-1293.550537,294.500488,0.000000
96.110008,65.305565,-1293.550537,-0.000629,0.003157,0.080191,290.493652,14.798452,0.801913,-1293.550537,294.500488,0.000000
96.430008,65.305199,-1293.594971,-0.000617,0.003157,0.080191,290.492035,14.798369,0.801913,-1293.594971,294.500488,0.000000
96.750008,65.296623,-1293.683960,-0.000621,0.003157,0.080191,290.453888,14.796426,0.801913,-1293.683960,294.500488,0.000000
97.070007,65.293648,-1293.594971,-0.000621,0.003157,0.080191,290.440643,14.795753,0.801913,-1293.594971,294.500488,0.000000
97.390007,65.285454,-1293.594971,-0.000612,0.003157,0.080191,290.404205,14.793895,0.801913,-1293.594971,294.500488,0.000000
97.710007,65.277260,-1293.550537,-0.000629,0.003157,0.080200,290.367767,14.792039,0.802004,-1293.550537,294.500488,0.000000
98.030006,65.268700,-1293.594971,-0.000642,0.003157,0.080200,290.329681,14.790098,0.802004,-1293.594971,294.500488,0.000000
98.350006,65.302956,-1293.683960,-0.000621,0.003159,0.080235,290.482056,14.797861,0.802352,-1293.683960,294.500488,0.000000
98.670006,65.318596,-1293.683960,-0.000621,0.003159,0.080235,290.551636,14.801406,0.802352,-1293.683960,294.500488,0.000000
98.990005,65.337212,-1293.639526,-0.000617,0.003159,0.080244,290.634430,14.805623,0.802443,-1293.639526,294.500488,0.000000
99.310005,65.339073,-1293.639526,-0.000612,0.003159,0.080244,290.642700,14.806046,0.802443,-1293.639526,294.500488,0.000000
99.630005,65.340935,-1293.639526,-0.000621,0.003159,0.080244,290.651001,14.806468,0.802443,-1293.639526,294.500488,0.000000
99.950005,65.336098,-1293.594971,-0.000612,0.003159,0.080244,290.629486,14.805371,0.802443,-1293.594971,294.500488,0.000000
100.270004,65.333870,-1293.683960,-0.000625,0.003159,0.080244,290.619568,14.804866,0.802443,-1293.683960,294.500488,0.000000
100.590004,65.333870,-1293.683960,-0.000621,0.003159,0.080244,290.619568,14.804866,0.802443,-1293.683960,294.500488,0.000000
100.910004,65.324562,-1293.550537,-0.000621,0.003159,0.080244,290.578156,14.802757,0.802443,-1293.550537,294.500488,0.000000
101.230003,65.318977,-1293.594971,-0.000621,0.003159,0.080244,290.553314,14.801492,0.802443,-1293.594971,294.500488,0.000000
101.550003,65.307793,-1293.594971,-0.000625,0.003159,0.080244,290.503571,14.798957,0.802443,-1293.594971,294.500488,0.000000
101.870003,65.304451,-1293.639526,-0.000621,0.003159,0.080244,290.488708,14.798200,0.802443,-1293.639526,294.500488,0.000000
102.190002,65.299614,-1293.639526,-0.000604,0.003159,0.080244,290.467194,14.797104,0.802443,-1293.639526,294.500488,0.000000
102.510002,65.310402,-1293.594971,-0.000617,0.003159,0.080244,290.515167,14.799548,0.802443,-1293.594971,294.500488,0.000000
102.830002,65.296257,-1293.728516,-0.000625,0.003159,0.080244,290.452271,14.796344,0.802443,-1293.728516,294.500488,0.000000
103.150002,65.286949,-1293.683960,-0.000629,0.003160,0.080253,290.410858,14.794234,0.802534,-1293.683960,294.500488,0.000000
103.470001,65.285454,-1293.683960,-0.000612,0.003160,0.080261,290.404205,14.793895,0.802610,-1293.683960,294.500488,0.000000
103.790009,65.284340,-1293.639526,-0.000608,0.003160,0.080261,290.399261,14.793643,0.802610,-1293.639526,294.500488,0.000000
104.110008,65.286568,-1293.639526,-0.000621,0.003160,0.080261,290.409149,14.794147,0.802610,-1293.639526,294.500488,0.000000
104.430008,65.276894,-1293.594971,-0.000625,0.003160,0.080270,290.366119,14.791956,0.802701,-1293.594971,294.500488,0.000000
104.750008,65.270195,-1293.728516,-0.000629,0.003160,0.080270,290.336334,14.790438,0.802701,-1293.728516,294.500488,0.000000
105.070007,65.270927,-1293.728516,-0.000629,0.003160,0.080270,290.339600,14.790604,0.802701,-1293.728516,294.500488,0.000000
105.390007,65.257896,-1293.639526,-0.000617,0.003160,0.080270,290.281616,14.787651,0.802701,-1293.639526,294.500488,0.000000
105.710007,65.275032,-1293.639526,-0.000604,0.003161,0.080279,290.357849,14.791533,0.802791,-1293.639526,294.500488,0.000000
106.030006,65.273170,-1293.550537,-0.000617,0.003161,0.080279,290.349548,14.791112,0.802791,-1293.550537,294.500488,0.000000
106.350006,65.264977,-1293.639526,-0.000621,0.003161,0.080279,290.313110,14.789255,0.802791,-1293.639526,294.500488,0.000000
106.670006,65.265343,-1293.728516,-0.000625,0.003161,0.080287,290.314758,14.789338,0.802867,-1293.728516,294.500488,0.000000
106.990005,65.268333,-1293.639526,-0.000617,0.003161,0.080287,290.328033,14.790016,0.802867,-1293.639526,294.500488,0.000000
107.310005,65.256783,-1293.639526,-0.000612,0.003161,0.080296,290.276672,14.787398,0.802958,-1293.639526,294.500488,0.000000
107.630005,65.263863,-1293.639526,-0.000599,0.003161,0.080296,290.308167,14.789002,0.802958,-1293.639526,294.500488,0.000000
107.950005,65.263863,-1293.639526,-0.000612,0.003161,0.080296,290.308167,14.789002,0.802958,-1293.639526,294.500488,0.000000
108.270004,65.250832,-1293.728516,-0.000617,0.003161,0.080296,290.250183,14.786049,0.802958,-1293.728516,294.500488,0.000000
108.590004,65.259026,-1293.683960,-0.000599,0.003161,0.080296,290.286652,14.787907,0.802958,-1293.683960,294.500488,0.000000
108.910004,65.249702,-1293.683960,-0.000608,0.003162,0.080305,290.245178,14.785793,0.803049,-1293.683960,294.500488,0.000000
109.230003,65.259026,-1293.639526,-0.000608,0.003162,0.080314,290.286652,14.787907,0.803140,-1293.639526,294.500488,0.000000
109.550003,65.251564,-1293.683960,-0.000617,0.003162,0.080314,290.253448,14.786216,0.803140,-1293.683960,294.500488,0.000000
109.870003,65.254921,-1293.728516,-0.000621,0.003162,0.080322,290.268372,14.786977,0.803215,-1293.728516,294.500488,0.000000
110.190002,65.269447,-1293.683960,-0.000608,0.003162,0.080322,290.333008,14.790268,0.803215,-1293.683960,1681.640991,0.000000
110.510002,65.248222,-1293.639526,-0.000608,0.003154,0.080123,290.238586,14.785459,0.801232,-1293.639526,0.079967,0.000000
110.830002,65.077293,-1293.639526,-0.000608,0.003139,0.079724,289.478271,14.746725,0.797235,-1293.639526,0.079437,0.000000
111.150002,65.115654,-1293.639526,-0.000612,0.003124,0.079360,289.648895,14.755418,0.793602,-1293.639526,0.078900,0.000000
111.470009,65.059059,-1293.683960,-0.000617,0.003106,0.078900,289.397156,14.742594,0.788999,-1293.683960,0.078372,0.000000
111.790009,65.043419,-1293.683960,-0.000608,0.003086,0.078379,289.327576,14.739050,0.783791,-1293.683960,0.077833,0.000000
112.110008,65.018471,-1293.683960,-0.000608,0.003063,0.077798,289.216614,14.733397,0.777978,-1293.683960,0.077304,0.000000
112.430008,64.990532,-1293.594971,-0.000608,0.003044,0.077313,289.092316,14.727065,0.773133,-1293.594971,0.076767,0.000000
112.750008,64.986076,-1293.639526,-0.000612,0.003031,0.077000,289.072510,14.726055,0.769999,-1293.639526,0.076237,0.000000
113.070007,64.996117,-1293.594971,-0.000621,0.002998,0.076141,289.117157,14.728331,0.761415,-1293.594971,0.075699,0.000000
113.390007,64.961128,-1293.683960,-0.000604,0.002981,0.075718,288.961517,14.720403,0.757176,-1293.683960,0.075171,0.000000
113.710007,64.904900,-1293.728516,-0.000608,0.002956,0.075092,288.711426,14.707661,0.750923,-1293.728516,0.074634,0.000000
114.030006,64.806587,-1293.639526,-0.000599,0.002938,0.074625,288.274109,14.685383,0.746245,-1293.639526,0.074104,0.000000
114.350006,64.719826,-1293.639526,-0.000612,0.002925,0.074287,287.888153,14.665722,0.742869,-1293.639526,0.073566,0.000000
114.670006,64.280418,-1293.639526,-0.000595,0.002907,0.073836,285.933594,14.566152,0.738357,-1293.639526,0.073038,0.000000
114.990005,63.390450,-1293.683960,-0.000582,0.002887,0.073332,281.974792,14.364482,0.733316,-1293.683960,0.072500,0.000000
115.310005,62.417442,-1293.728516,-0.000586,0.002866,0.072803,277.646637,14.143994,0.728032,-1293.728516,0.071971,0.000000
115.630005,61.339798,-1293.639526,-0.000560,0.002847,0.072317,272.853058,13.899796,0.723172,-1293.639526,0.071433,0.000000
115.950005,59.979523,-1293.639526,-0.000578,0.002827,0.071798,266.802246,13.591554,0.717979,-1293.639526,0.070905,0.000000
116.270004,58.277039,-1293.683960,-0.000560,0.002804,0.071233,259.229218,13.205766,0.712332,-1293.683960,0.070366,0.000000
116.590004,56.614021,-1293.639526,-0.000573,0.002783,0.070696,251.831741,12.828920,0.706958,-1293.639526,0.069837,0.000000
116.910004,54.472878,-1293.639526,-0.000556,0.002758,0.070054,242.307465,12.343730,0.700539,-1293.639526,0.069300,0.000000
117.230003,52.830345,-1293.639526,-0.000556,0.002742,0.069638,235.001114,11.971527,0.696375,-1293.639526,0.068770,0.000000
117.550003,51.200844,-1293.639526,-0.000573,0.002727,0.069265,227.752731,11.602278,0.692651,-1293.639526,0.068233,0.000000
117.870003,49.583626,-1293.728516,-0.000565,0.002706,0.068744,220.558990,11.235810,0.687443,-1293.728516,0.067704,0.000000
118.190002,46.588638,-1293.728516,-0.000565,0.002682,0.068111,207.236618,10.557136,0.681115,-1293.728516,0.067167,0.000000
118.510002,43.667000,-1293.683960,-0.000556,0.002655,0.067444,194.240509,9.895083,0.674438,-1293.683960,0.066637,0.000000
118.830002,41.674812,-1293.683960,-0.000578,0.002638,0.067002,185.378830,9.443648,0.670017,-1293.683960,0.066099,0.000000
119.150009,39.210449,-1293.639526,-0.000573,0.002616,0.066446,174.416794,8.885215,0.664461,-1293.639526,0.065571,0.000000
119.470009,37.324753,-1293.594971,-0.000569,0.002598,0.065995,166.028793,8.457911,0.659949,-1293.594971,0.065034,0.000000
119.790009,35.037643,-1293.683960,-0.000569,0.002575,0.065415,155.855225,7.939644,0.654151,-1293.683960,0.064504,0.000000
120.110008,32.539764,-1293.683960,-0.000565,0.002554,0.064859,144.744095,7.373616,0.648595,-1293.683960,0.063966,0.000000
120.430008,29.759636,-1293.594971,-0.000565,0.002528,0.064208,132.377472,6.743630,0.642085,-1293.594971,0.063438,0.000000
120.750008,27.754410,-1293.639526,-0.000573,0.002509,0.063724,123.457779,6.289239,0.637240,-1293.639526,0.062899,0.000000
121.070007,25.841530,-1293.639526,-0.000573,0.002492,0.063290,114.948868,5.855774,0.632895,-1293.639526,0.062371,0.000000
121.390007,22.810051,-1293.683960,-0.000552,0.002463,0.062552,101.464172,5.168831,0.625522,-1293.683960,0.061833,0.000000
121.710007,21.117241,-1293.683960,-0.000565,0.002449,0.062215,93.934181,4.785235,0.622146,-1293.683960,0.061303,0.000000
122.030006,19.406563,-1293.683960,-0.000565,0.002431,0.061747,86.324699,4.397590,0.617468,-1293.683960,0.060766,0.000000
122.350006,16.568710,-1293.594971,-0.000573,0.002406,0.061122,73.701302,3.754524,0.611215,-1293.594971,0.060237,0.000000
122.670006,14.467789,-1293.594971,-0.000569,0.002389,0.060679,64.355942,3.278448,0.606794,-1293.594971,0.059700,0.000000
122.990005,12.011620,-1293.683960,-0.000560,0.002366,0.060089,53.430351,2.721872,0.600890,-1293.683960,0.059170,0.000000
123.310005,9.644073,-1293.683960,-0.000560,0.002343,0.059500,42.898983,2.185378,0.595001,-1293.683960,0.058633,0.000000
123.630005,7.383026,-1293.639526,-0.000565,0.002322,0.058979,32.841339,1.673018,0.589793,-1293.639526,0.058104,0.000000
123.950005,5.182304,-1293.639526,-0.000560,0.002300,0.058416,23.052042,1.174327,0.584161,-1293.639526,0.057567,0.000000
124.270004,2.975632,-1293.683960,-0.000569,0.002277,0.057835,13.236271,0.674288,0.578347,-1293.683960,0.057037,0.000000
124.590004,1.299583,-1293.683960,-0.000582,0.002259,0.057367,5.780836,0.294490,0.573669,-1293.683960,0.056499,0.000000
124.910004,-0.218208,-1293.728516,-0.000573,0.002240,0.056907,-0.970639,-0.049447,0.569067,-1293.728516,0.055971,0.000000
125.230003,-1.330116,-1293.683960,-0.000565,0.002224,0.056483,-5.916653,-0.301409,0.564827,-1293.683960,0.055432,0.000000
125.550003,-0.792778,-1293.639526,-0.000556,0.002206,0.056032,-3.526453,-0.179646,0.560316,-1293.639526,0.054904,0.000000
125.870003,-0.059578,-1293.594971,-0.000569,0.002183,0.055459,-0.265016,-0.013501,0.554593,-1293.594971,0.054366,0.000000
126.190002,0.122139,-1293.639526,-0.000560,0.002156,0.054773,0.543301,0.027677,0.547735,-1293.639526,0.053836,0.000000
126.510010,0.087509,-1293.772949,-0.000552,0.002139,0.054340,0.389260,0.019830,0.543405,-1293.772949,0.053299,0.000000
126.830009,0.055481,-1293.683960,-0.000552,0.002110,0.053603,0.246792,0.012572,0.536032,-1293.683960,0.052771,0.000000
127.150009,0.033882,-1293.639526,-0.000543,0.002093,0.053169,0.150715,0.007678,0.531687,-1293.639526,0.052233,0.000000
127.470009,0.028297,-1293.594971,-0.000543,0.002075,0.052710,0.125873,0.006412,0.527100,-1293.594971,0.051703,0.000000
127.790009,-0.012291,-1293.683960,-0.000569,0.002051,0.052085,-0.054673,-0.002785,0.520847,-1293.683960,0.051166,0.000000
128.110001,-0.005959,-1293.728516,-0.000604,0.002027,0.051478,-0.026505,-0.001350,0.514776,-1293.728516,0.050637,0.000000
128.430008,-0.030907,-1293.683960,-0.000625,0.002012,0.051105,-0.137480,-0.007004,0.511052,-1293.683960,0.050100,0.000000
128.750000,-0.048782,-1293.683960,-0.000655,0.001984,0.050386,-0.216995,-0.011054,0.503860,-1293.683960,0.049570,0.000000
129.070007,-0.045059,-1293.728516,-0.000681,0.001968,0.049986,-0.200433,-0.010211,0.499864,-1293.728516,0.049033,0.000000
129.389999,-0.017128,-1293.683960,-0.000716,0.001947,0.049466,-0.076189,-0.003881,0.494655,-1293.683960,0.048504,0.000000
129.710007,0.000374,-1293.639526,-0.000737,0.001923,0.048851,0.001663,0.000085,0.488509,-1293.639526,0.048730,0.000000
129.900009,0.018990,-1293.683960,-0.000750,0.001924,0.048858,0.084470,0.004303,0.488585,-1293.683960,0.048730,0.000000