File: Data/Sima compression/P2-17-2_10302024_173830.csv
Time (sec),S:Load (lbs),S:HL1 (DIM),S:LVDT (in),S:Position (in),Ch:Position (mm),Ch:Load (N),Ch:Stress (MPa),Ch:Strain (mm/mm),Ch:HL1 (DIM),Set Point (),Cycles ()
0.210000,-0.008568,-1293.683960,-0.008188,-0.005060,-0.128523,-0.038112,-0.001941,-1.285229,-1293.683960,-0.128314,0.000000
0.500000,-0.014519,-1293.639526,-0.008175,-0.004998,-0.126944,-0.064583,-0.003290,-1.269439,-1293.639526,-0.126388,0.000000
0.790000,-0.008194,-1293.639526,-0.008101,-0.004833,-0.122755,-0.036449,-0.001857,-1.227547,-1293.639526,-0.121568,0.000000
1.080000,-0.006332,-1293.683960,-0.007894,-0.004633,-0.117681,-0.028168,-0.001435,-1.176815,-1293.683960,-0.116728,0.000000
1.370000,-0.023087,-1293.683960,-0.007713,-0.004453,-0.113103,-0.102694,-0.005231,-1.131033,-1293.683960,-0.111906,0.000000
1.660000,-0.036865,-1293.728516,-0.007515,-0.004259,-0.108186,-0.163985,-0.008354,-1.081859,-1293.728516,-0.107067,0.000000
1.950000,-0.007446,-1293.728516,-0.007317,-0.004072,-0.103434,-0.033123,-0.001687,-1.034336,-1293.728516,-0.102245,0.000000
2.240000,0.029045,-1293.594971,-0.007127,-0.003874,-0.098412,0.129199,0.006582,-0.984118,-1293.594971,-0.097407,0.000000
2.530000,0.008568,-1293.639526,-0.006929,-0.003689,-0.093694,0.038112,0.001941,-0.936943,-1293.639526,-0.092566,0.000000
2.820000,0.007446,-1293.594971,-0.006722,-0.003503,-0.088977,0.033123,0.001687,-0.889768,-1293.594971,-0.087746,0.000000
3.110000,-0.008934,-1293.639526,-0.006545,-0.003309,-0.084059,-0.039741,-0.002024,-0.840595,-1293.639526,-0.082906,0.000000
3.400000,-0.008934,-1293.683960,-0.006342,-0.003114,-0.079091,-0.039741,-0.002024,-0.790907,-1293.683960,-0.078084,0.000000
3.690000,-0.060326,-1293.639526,-0.006161,-0.002932,-0.074476,-0.268342,-0.013670,-0.744761,-1293.639526,-0.073245,0.000000
3.980000,0.001488,-1293.728516,-0.005954,-0.002740,-0.069603,0.006618,0.000337,-0.696027,-1293.728516,-0.068423,0.000000
4.270000,-0.004097,-1293.594971,-0.005756,-0.002549,-0.064738,-0.018224,-0.000928,-0.647384,-1293.594971,-0.063585,0.000000
4.560000,0.048409,-1293.639526,-0.005558,-0.002358,-0.059891,0.215332,0.010970,-0.598907,-1293.639526,-0.058763,0.000000
4.850000,0.011917,-1293.683960,-0.005355,-0.002170,-0.055120,0.053010,0.002700,-0.551202,-1293.683960,-0.053924,0.000000
5.140000,-0.005211,-1293.594971,-0.005174,-0.001979,-0.050272,-0.023179,-0.001181,-0.502725,-1293.594971,-0.049084,0.000000
5.430000,-0.031281,-1293.683960,-0.004971,-0.001791,-0.045502,-0.139143,-0.007088,-0.455020,-1293.683960,-0.044262,0.000000
5.720000,-0.029045,-1293.639526,-0.004777,-0.001595,-0.040526,-0.129199,-0.006582,-0.405256,-1293.639526,-0.039423,0.000000
6.010000,-0.036865,-1293.683960,-0.004596,-0.001408,-0.035755,-0.163985,-0.008354,-0.357551,-1293.683960,-0.034602,0.000000
6.300000,0.017502,-1293.639526,-0.004385,-0.001220,-0.030985,0.077852,0.003966,-0.309847,-1293.639526,-0.029763,0.000000
6.590000,0.005585,-1293.639526,-0.004174,-0.001026,-0.026051,0.024842,0.001266,-0.260507,-1293.639526,-0.024941,0.000000
6.880000,0.030907,-1293.594971,-0.004001,-0.000838,-0.021273,0.137480,0.007004,-0.212726,-1293.594971,-0.020102,0.000000
7.170001,-0.013779,-1293.594971,-0.003794,-0.000651,-0.016529,-0.061291,-0.003122,-0.165294,-1293.594971,-0.015280,0.000000
7.460001,-0.004471,-1293.594971,-0.003600,-0.000456,-0.011594,-0.019887,-0.001013,-0.115939,-1293.594971,-0.010440,0.000000
7.750000,-0.021599,-1293.550537,-0.003402,-0.000267,-0.006781,-0.096076,-0.004894,-0.067810,-1293.550537,-0.005602,0.000000
8.040000,0.000748,-1293.550537,-0.003229,-0.000088,-0.002229,0.003326,0.000169,-0.022285,-1293.550537,-0.000780,0.000000
8.330000,0.094208,-1293.639526,-0.003100,-0.000000,-0.000000,0.419057,0.021348,-0.000000,-1293.639526,0.000216,0.000000
8.620001,0.099052,-1293.594971,-0.003100,-0.000000,-0.000000,0.440607,0.022446,-0.000000,-1293.594971,0.000216,0.000000
8.910001,0.087883,-1293.594971,-0.003113,-0.000000,-0.000000,0.390923,0.019915,-0.000000,-1293.594971,0.000572,0.000000
9.200001,0.093468,-1293.639526,-0.003117,0.000005,0.000130,0.415765,0.021180,0.001302,-1293.639526,0.001058,0.000000
9.490001,0.163841,-1293.550537,-0.003100,0.000019,0.000477,0.728802,0.037127,0.004769,-1293.550537,0.001535,0.000000
9.780001,0.235710,-1293.639526,-0.003109,0.000032,0.000824,1.048491,0.053413,0.008236,-1293.639526,0.002021,0.000000
10.070001,0.623726,-1293.594971,-0.003070,0.000065,0.001640,2.774471,0.141338,0.016396,-1293.594971,0.002506,0.000000
10.360001,0.875076,-1293.550537,-0.003040,0.000081,0.002047,3.892534,0.198295,0.020469,-1293.550537,0.002992,0.000000
10.650001,1.298836,-1293.594971,-0.003035,0.000098,0.002498,5.777510,0.294320,0.024980,-1293.594971,0.003468,0.000000
10.940001,1.895752,-1293.550537,-0.003018,0.000120,0.003035,8.432726,0.429584,0.030355,-1293.550537,0.003954,0.000000
11.230000,2.329193,-1293.639526,-0.003001,0.000136,0.003452,10.360768,0.527803,0.034518,-1293.639526,0.004440,0.000000
11.520000,2.897057,-1293.550537,-0.002979,0.000152,0.003850,12.886751,0.656482,0.038500,-1293.550537,0.004917,0.000000
11.810000,3.722977,-1293.639526,-0.002992,0.000176,0.004475,16.560627,0.843639,0.044753,-1293.639526,0.005403,0.000000
12.100000,4.449104,-1293.639526,-0.002971,0.000194,0.004934,19.790604,1.008181,0.049340,-1293.639526,0.005888,0.000000
12.390000,5.075066,-1293.461548,-0.002940,0.000212,0.005394,22.575020,1.150026,0.053942,-1293.461548,0.006374,0.000000
12.680000,5.925560,-1293.639526,-0.002953,0.000232,0.005888,26.358208,1.342751,0.058878,-1293.639526,0.006851,0.000000
12.970000,6.708290,-1293.506104,-0.002915,0.000250,0.006348,29.839964,1.520120,0.063480,-1293.506104,0.007337,0.000000
13.260000,7.472023,-1293.550537,-0.002906,0.000267,0.006773,33.237217,1.693185,0.067734,-1293.550537,0.007823,0.000000
13.550000,8.085693,-1293.594971,-0.002906,0.000282,0.007163,35.966961,1.832244,0.071625,-1293.594971,0.008309,0.000000
13.840001,9.714081,-1293.550537,-0.002880,0.000313,0.007960,43.210388,2.201242,0.079604,-1293.550537,0.008785,0.000000
14.130001,10.314346,-1293.639526,-0.002880,0.000328,0.008334,45.880505,2.337264,0.083343,-1293.639526,0.009270,0.000000
14.420001,11.193886,-1293.594971,-0.002863,0.000348,0.008837,49.792892,2.536571,0.088370,-1293.594971,0.009756,0.000000
14.710001,11.992996,-1293.550537,-0.002863,0.000364,0.009244,53.347511,2.717652,0.092442,-1293.550537,0.010242,0.000000
15.000001,12.917976,-1293.683960,-0.002828,0.000385,0.009782,57.462029,2.927255,0.097817,-1293.683960,0.010719,0.000000
15.290001,14.017960,-1293.594971,-0.002824,0.000405,0.010286,62.355000,3.176515,0.102858,-1293.594971,0.011205,0.000000
15.580001,14.886337,-1293.639526,-0.002815,0.000424,0.010763,66.217735,3.373292,0.107627,-1293.639526,0.011691,0.000000
15.870001,16.141228,-1293.550537,-0.002781,0.000446,0.011326,71.799767,3.657655,0.113259,-1293.550537,0.012175,0.000000
16.160000,16.699043,-1293.550537,-0.002794,0.000462,0.011726,74.281052,3.784057,0.117256,-1293.550537,0.012652,0.000000
16.450001,17.738708,-1293.594971,-0.002768,0.000482,0.012236,78.905716,4.019649,0.122358,-1293.594971,0.013138,0.000000
16.740002,18.635010,-1293.550537,-0.002751,0.000499,0.012679,82.892662,4.222754,0.126794,-1293.550537,0.013624,0.000000
17.030001,19.310120,-1293.550537,-0.002768,0.000517,0.013138,85.895699,4.375736,0.131381,-1293.550537,0.014101,0.000000
17.320002,20.140884,-1293.639526,-0.002742,0.000532,0.013520,89.591125,4.563990,0.135196,-1293.639526,0.014587,0.000000
17.610001,20.981323,-1293.550537,-0.002738,0.000554,0.014075,93.329590,4.754436,0.140753,-1293.550537,0.015073,0.000000
17.900002,22.152069,-1293.639526,-0.002725,0.000574,0.014578,98.537323,5.019731,0.145779,-1293.639526,0.015557,0.000000
18.190001,22.893829,-1293.594971,-0.002695,0.000593,0.015055,101.836838,5.187816,0.150548,-1293.594971,0.016034,0.000000
18.480001,23.504150,-1293.594971,-0.002695,0.000607,0.015420,104.551682,5.326117,0.154197,-1293.594971,0.016520,0.000000
18.770000,24.643234,-1293.639526,-0.002673,0.000630,0.016009,109.618584,5.584237,0.160086,-1293.639526,0.017006,0.000000
19.060001,25.547729,-1293.594971,-0.002669,0.000650,0.016504,113.641975,5.789198,0.165037,-1293.594971,0.017492,0.000000
19.350000,25.909676,-1293.639526,-0.002660,0.000663,0.016850,115.251991,5.871216,0.168504,-1293.639526,0.017969,0.000000
19.640001,26.867416,-1293.550537,-0.002639,0.000683,0.017344,119.512238,6.088243,0.173439,-1293.550537,0.018455,0.000000
19.930000,28.045235,-1293.639526,-0.002621,0.000708,0.017986,124.751434,6.355141,0.179858,-1293.639526,0.018940,0.000000
20.220001,28.962387,-1293.683960,-0.002591,0.000730,0.018532,128.831131,6.562971,0.185324,-1293.683960,0.019426,0.000000
20.510000,29.121758,-1293.594971,-0.002591,0.000742,0.018853,129.540054,6.599084,0.188533,-1293.594971,0.019902,0.000000
20.800001,30.057533,-1293.594971,-0.002574,0.000763,0.019374,133.702591,6.811134,0.193741,-1293.594971,0.020388,0.000000
21.090000,30.744186,-1293.550537,-0.002570,0.000782,0.019868,136.756973,6.966732,0.198677,-1293.550537,0.020874,0.000000
21.380001,30.708069,-1293.639526,-0.002539,0.000790,0.020077,136.596313,6.958548,0.200766,-1293.639526,0.021360,0.000000
21.670000,32.754257,-1293.639526,-0.002531,0.000825,0.020961,145.698212,7.422221,0.209607,-1293.639526,0.021837,0.000000
21.960001,32.712547,-1293.506104,-0.002514,0.000839,0.021298,145.512680,7.412769,0.212984,-1293.506104,0.022322,0.000000
22.250002,33.777908,-1293.550537,-0.002492,0.000862,0.021905,150.251648,7.654183,0.219055,-1293.550537,0.022808,0.000000
22.540001,34.050110,-1293.594971,-0.002479,0.000877,0.022279,151.462448,7.715865,0.222794,-1293.594971,0.023285,0.000000
22.830002,34.837303,-1293.594971,-0.002471,0.000900,0.022852,154.964066,7.894246,0.228517,-1293.594971,0.023771,0.000000
23.120001,35.299789,-1293.639526,-0.002458,0.000914,0.023224,157.021301,7.999046,0.232241,-1293.639526,0.024257,0.000000
23.410002,36.232216,-1293.594971,-0.002445,0.000940,0.023883,161.168945,8.210338,0.238827,-1293.594971,0.024743,0.000000
23.700001,36.939346,-1293.683960,-0.002423,0.000959,0.024352,164.314423,8.370576,0.243520,-1293.683960,0.025220,0.000000
23.990002,36.865616,-1293.594971,-0.002406,0.000972,0.024681,163.986450,8.353868,0.246805,-1293.594971,0.025704,0.000000
24.280001,37.607010,-1293.639526,-0.002406,0.000992,0.025192,167.284332,8.521871,0.251923,-1293.639526,0.026190,0.000000
24.570002,38.051994,-1293.683960,-0.002380,0.001011,0.025678,169.263718,8.622705,0.256782,-1293.683960,0.026676,0.000000
24.860001,38.939735,-1293.639526,-0.002363,0.001030,0.026164,173.212601,8.823870,0.261642,-1293.639526,0.027153,0.000000
25.150002,39.034691,-1293.639526,-0.002345,0.001043,0.026502,173.634979,8.845387,0.265018,-1293.639526,0.027639,0.000000
25.440001,40.395340,-1293.594971,-0.002324,0.001072,0.027239,179.687439,9.153715,0.272391,-1293.594971,0.028125,0.000000
25.730001,40.742760,-1293.594971,-0.002315,0.001089,0.027655,181.232849,9.232441,0.276555,-1293.594971,0.028609,0.000000
26.020000,41.141197,-1293.683960,-0.002307,0.001108,0.028132,183.005188,9.322729,0.281324,-1293.683960,0.029086,0.000000
26.310001,41.673691,-1293.594971,-0.002272,0.001126,0.028593,185.373840,9.443394,0.285926,-1293.594971,0.029572,0.000000
26.600000,41.869186,-1293.639526,-0.002289,0.001138,0.028914,186.243439,9.487694,0.289136,-1293.639526,0.030058,0.000000
26.890001,42.580048,-1293.594971,-0.002255,0.001160,0.029460,189.405518,9.648776,0.294601,-1293.594971,0.030544,0.000000
27.180002,42.724899,-1293.594971,-0.002242,0.001172,0.029772,190.049850,9.681601,0.297720,-1293.594971,0.031021,0.000000
27.470001,44.438927,-1293.683960,-0.002212,0.001205,0.030605,197.674225,10.070004,0.306047,-1293.683960,0.031507,0.000000
27.760002,44.349190,-1293.639526,-0.002203,0.001216,0.030882,197.275055,10.049670,0.308817,-1293.639526,0.031991,0.000000
28.050001,45.106224,-1293.683960,-0.002203,0.001239,0.031480,200.642502,10.221216,0.314797,-1293.683960,0.032468,0.000000
28.340002,45.400024,-1293.639526,-0.002177,0.001256,0.031896,201.949402,10.287792,0.318961,-1293.639526,0.032954,0.000000
28.630001,45.971985,-1293.639526,-0.002169,0.001273,0.032338,204.493607,10.417400,0.323381,-1293.639526,0.033440,0.000000
28.920002,46.930847,-1293.683960,-0.002151,0.001293,0.032833,208.758835,10.634682,0.328332,-1293.683960,0.033926,0.000000
29.210001,46.448250,-1293.594971,-0.002134,0.001300,0.033015,206.612137,10.525324,0.330149,-1293.594971,0.034403,0.000000
29.500002,49.078690,-1293.683960,-0.002113,0.001338,0.033996,218.312912,11.121390,0.339959,-1293.683960,0.034889,0.000000
29.790001,49.004959,-1293.683960,-0.002091,0.001353,0.034368,217.984940,11.104682,0.343684,-1293.683960,0.035374,0.000000
30.080002,49.756409,-1293.594971,-0.002070,0.001373,0.034880,221.327560,11.274963,0.348801,-1293.594971,0.035860,0.000000
30.370001,50.308266,-1293.728516,-0.002078,0.001392,0.035366,223.782349,11.400016,0.353661,-1293.728516,0.036337,0.000000
30.660002,50.440826,-1293.683960,-0.002052,0.001406,0.035713,224.372009,11.430055,0.357128,-1293.683960,0.036822,0.000000
30.950001,51.133812,-1293.683960,-0.002048,0.001423,0.036146,227.454559,11.587088,0.361457,-1293.683960,0.037308,0.000000
31.240002,52.017082,-1293.683960,-0.002013,0.001451,0.036848,231.383545,11.787239,0.368482,-1293.683960,0.037794,0.000000
31.530001,52.765549,-1293.683960,-0.002005,0.001465,0.037221,234.712891,11.956844,0.372207,-1293.683960,0.038271,0.000000
31.820002,53.339752,-1293.728516,-0.001996,0.001484,0.037681,237.267075,12.086960,0.376809,-1293.728516,0.038756,0.000000
32.110001,53.759789,-1293.683960,-0.001970,0.001500,0.038097,239.135483,12.182142,0.380972,-1293.683960,0.039242,0.000000
32.400002,55.024361,-1293.683960,-0.001970,0.001525,0.038739,244.760574,12.468699,0.387392,-1293.683960,0.039728,0.000000
32.690002,55.286140,-1293.728516,-0.001949,0.001541,0.039130,245.925034,12.528019,0.391298,-1293.728516,0.040205,0.000000
32.980003,55.828690,-1293.683960,-0.001927,0.001556,0.039528,248.338409,12.650962,0.395279,-1293.683960,0.040691,0.000000
33.270000,57.146881,-1293.728516,-0.001936,0.001582,0.040179,254.202026,12.949668,0.401789,-1293.728516,0.041177,0.000000
33.560001,58.050262,-1293.639526,-0.001897,0.001602,0.040691,258.220459,13.154377,0.406906,-1293.639526,0.041654,0.000000
33.850002,58.411835,-1293.683960,-0.001897,0.001618,0.041098,259.828827,13.236311,0.410979,-1293.683960,0.042138,0.000000
34.140003,59.381866,-1293.728516,-0.001858,0.001640,0.041654,264.143738,13.456123,0.416535,-1293.728516,0.042624,0.000000
34.430000,59.877495,-1293.683960,-0.001876,0.001654,0.042000,266.348389,13.568435,0.420002,-1293.683960,0.043110,0.000000
34.720001,60.494141,-1293.683960,-0.001845,0.001673,0.042485,269.091370,13.708169,0.424847,-1293.683960,0.043587,0.000000
35.010002,61.685364,-1293.683960,-0.001828,0.001696,0.043066,274.390198,13.978104,0.430660,-1293.683960,0.044073,0.000000
35.300003,63.150276,-1293.683960,-0.001819,0.001719,0.043673,280.906464,14.310058,0.436731,-1293.683960,0.044559,0.000000
35.590000,63.488380,-1293.683960,-0.001802,0.001734,0.044055,282.410431,14.386673,0.440547,-1293.683960,0.045043,0.000000
35.880001,64.342232,-1293.683960,-0.001798,0.001753,0.044532,286.208527,14.580158,0.445316,-1293.683960,0.045520,0.000000
36.170002,64.965218,-1293.683960,-0.001768,0.001768,0.044913,288.979706,14.721329,0.449131,-1293.683960,0.046006,0.000000
36.460003,65.980675,-1293.683960,-0.001755,0.001789,0.045452,293.496704,14.951434,0.454520,-1293.683960,0.046492,0.000000
36.750000,65.876411,-1293.728516,-0.001755,0.001788,0.045417,293.032898,14.927808,0.454172,-1293.728516,0.045685,0.000000
37.040001,64.773445,-1293.772949,-0.001738,0.001800,0.045729,288.126678,14.677873,0.457291,-1293.772949,294.500488,0.000000
37.330002,65.243004,-1293.683960,-0.001725,0.001797,0.045650,290.215363,14.784276,0.456504,-1293.683960,294.500488,0.000000
37.620003,65.155495,-1293.728516,-0.001716,0.001817,0.046145,289.826111,14.764446,0.461454,-1293.728516,294.500488,0.000000
37.910004,65.266472,-1293.728516,-0.001703,0.001824,0.046318,290.319763,14.789594,0.463180,-1293.728516,294.500488,0.000000
38.200001,65.297371,-1293.683960,-0.001707,0.001831,0.046518,290.457214,14.796596,0.465179,-1293.683960,294.500488,0.000000
38.490002,65.443336,-1293.817383,-0.001694,0.001841,0.046760,291.106506,14.829672,0.467601,-1293.817383,294.500488,0.000000
38.780003,65.203529,-1293.728516,-0.001694,0.001844,0.046848,290.039795,14.775331,0.468479,-1293.728516,294.500488,0.000000
39.070004,65.220665,-1293.728516,-0.001699,0.001851,0.047013,290.115997,14.779214,0.470129,-1293.728516,294.500488,0.000000
39.360001,65.151405,-1293.772949,-0.001673,0.001857,0.047169,289.807922,14.763519,0.471689,-1293.772949,294.500488,0.000000
39.650002,65.144707,-1293.683960,-0.001677,0.001862,0.047307,289.778137,14.762002,0.473066,-1293.683960,294.500488,0.000000
39.940002,65.228859,-1293.728516,-0.001656,0.001869,0.047472,290.152466,14.781071,0.474717,-1293.728516,294.500488,0.000000
40.230003,65.209496,-1293.639526,-0.001660,0.001875,0.047628,290.066315,14.776683,0.476276,-1293.639526,294.500488,0.000000
40.520000,65.209114,-1293.772949,-0.001669,0.001880,0.047741,290.064636,14.776596,0.477412,-1293.772949,294.500488,0.000000
40.810001,65.358437,-1293.728516,-0.001651,0.001886,0.047906,290.728851,14.810433,0.479062,-1293.728516,294.500488,0.000000
41.100002,65.700279,-1293.728516,-0.001647,0.001896,0.048157,292.249451,14.887896,0.481575,-1293.728516,294.500488,0.000000
41.390003,65.502174,-1293.772949,-0.001647,0.001896,0.048148,291.368225,14.843005,0.481484,-1293.772949,294.500488,0.000000
41.680000,65.171883,-1293.683960,-0.001638,0.001898,0.048200,289.899017,14.768160,0.481999,-1293.683960,294.500488,0.000000
41.970001,65.515953,-1293.639526,-0.001643,0.001904,0.048365,291.429504,14.846127,0.483649,-1293.639526,294.500488,0.000000
42.260002,65.086617,-1293.772949,-0.001621,0.001904,0.048374,289.519745,14.748837,0.483740,-1293.772949,294.500488,0.000000
42.550003,65.626549,-1293.728516,-0.001634,0.001914,0.048609,291.921478,14.871188,0.486086,-1293.728516,294.500488,0.000000
42.840000,65.270927,-1293.772949,-0.001630,0.001914,0.048609,290.339600,14.790604,0.486086,-1293.772949,294.500488,0.000000
43.130001,65.299980,-1293.728516,-0.001608,0.001920,0.048756,290.468811,14.797187,0.487555,-1293.728516,294.500488,0.000000
43.420002,65.142845,-1293.728516,-0.001617,0.001923,0.048851,289.769836,14.761580,0.488509,-1293.728516,294.500488,0.000000
43.710003,65.335732,-1293.728516,-0.001608,0.001928,0.048972,290.627838,14.805288,0.489720,-1293.728516,294.500488,0.000000
44.000004,65.199074,-1293.728516,-0.001608,0.001928,0.048981,290.019958,14.774321,0.489811,-1293.728516,294.500488,0.000000
44.290001,65.038582,-1293.683960,-0.001613,0.001930,0.049033,289.306061,14.737954,0.490326,-1293.683960,294.500488,0.000000
44.580002,64.992027,-1293.683960,-0.001600,0.001934,0.049120,289.098969,14.727404,0.491204,-1293.683960,294.500488,0.000000
44.870003,65.269814,-1293.728516,-0.001608,0.001940,0.049267,290.334625,14.790351,0.492672,-1293.728516,294.500488,0.000000
45.160004,65.068733,-1293.728516,-0.001587,0.001940,0.049284,289.440186,14.744785,0.492839,-1293.728516,294.500488,0.000000
45.450001,65.311897,-1293.728516,-0.001591,0.001946,0.049423,290.521820,14.799888,0.494232,-1293.728516,294.500488,0.000000
45.740002,65.093681,-1293.728516,-0.001591,0.001947,0.049449,289.551147,14.750440,0.494489,-1293.728516,294.500488,0.000000
46.030003,64.945488,-1293.728516,-0.001587,0.001952,0.049570,288.891968,14.716858,0.495700,-1293.728516,294.500488,0.000000
46.320004,65.823158,-1293.728516,-0.001582,0.001959,0.049753,292.796021,14.915741,0.497532,-1293.728516,294.500488,0.000000
46.610001,65.559898,-1293.772949,-0.001578,0.001959,0.049753,291.625000,14.856086,0.497532,-1293.772949,294.500488,0.000000
46.900002,65.293282,-1293.683960,-0.001574,0.001959,0.049761,290.439026,14.795669,0.497608,-1293.683960,294.500488,0.000000
47.190002,65.031120,-1293.728516,-0.001578,0.001959,0.049761,289.272858,14.736262,0.497608,-1293.728516,294.500488,0.000000
47.480003,65.473503,-1293.683960,-0.001561,0.001967,0.049952,291.240692,14.836508,0.499515,-1293.683960,294.500488,0.000000
47.770000,65.263863,-1293.728516,-0.001574,0.001967,0.049952,290.308167,14.789002,0.499515,-1293.728516,294.500488,0.000000
48.060001,65.046394,-1293.728516,-0.001569,0.001970,0.050030,289.340820,14.739723,0.500303,-1293.728516,294.500488,0.000000
48.350002,65.172249,-1293.728516,-0.001565,0.001971,0.050074,289.900635,14.768242,0.500742,-1293.728516,294.500488,0.000000
48.640003,65.050865,-1293.728516,-0.001561,0.001975,0.050177,289.360687,14.740736,0.501771,-1293.728516,294.500488,0.000000
48.930004,65.336098,-1293.728516,-0.001552,0.001978,0.050247,290.629486,14.805371,0.502468,-1293.728516,294.500488,0.000000
49.220001,65.178215,-1293.683960,-0.001561,0.001978,0.050247,289.927185,14.769595,0.502468,-1293.683960,294.500488,0.000000
49.510002,65.154015,-1293.728516,-0.001556,0.001981,0.050325,289.819519,14.764111,0.503255,-1293.728516,294.500488,0.000000
49.800003,65.216576,-1293.683960,-0.001548,0.001986,0.050438,290.097809,14.778287,0.504375,-1293.683960,294.500488,0.000000
50.090004,65.207634,-1293.683960,-0.001552,0.001986,0.050438,290.058044,14.776261,0.504375,-1293.683960,294.500488,0.000000
50.380001,65.128319,-1293.728516,-0.001535,0.001989,0.050516,289.705231,14.758287,0.505162,-1293.728516,294.500488,0.000000
50.670002,65.200188,-1293.683960,-0.001535,0.001990,0.050559,290.024933,14.774573,0.505586,-1293.683960,294.500488,0.000000
50.960003,65.061287,-1293.728516,-0.001539,0.001991,0.050577,289.407043,14.743098,0.505768,-1293.728516,294.500488,0.000000
51.250004,65.479088,-1293.728516,-0.001535,0.001997,0.050724,291.265533,14.837773,0.507236,-1293.728516,294.500488,0.000000
51.540001,65.310783,-1293.683960,-0.001539,0.001997,0.050724,290.516876,14.799635,0.507236,-1293.683960,294.500488,0.000000
51.830002,65.212471,-1293.683960,-0.001526,0.001998,0.050758,290.079559,14.777357,0.507585,-1293.683960,294.500488,0.000000
52.120003,65.135384,-1293.728516,-0.001526,0.001999,0.050784,289.736664,14.759890,0.507842,-1293.728516,294.500488,0.000000
52.410004,65.193108,-1293.728516,-0.001548,0.002002,0.050854,289.993439,14.772969,0.508538,-1293.728516,294.500488,0.000000
52.700001,65.089211,-1293.594971,-0.001535,0.002003,0.050872,289.531281,14.749426,0.508720,-1293.594971,294.500488,0.000000
52.990002,65.103737,-1293.683960,-0.001531,0.002005,0.050933,289.595886,14.752718,0.509326,-1293.683960,294.500488,0.000000
53.280003,65.025169,-1293.817383,-0.001535,0.002006,0.050940,289.246399,14.734915,0.509401,-1293.817383,294.500488,0.000000
53.570004,65.278389,-1293.683960,-0.001522,0.002010,0.051063,290.372772,14.792295,0.510628,-1293.683960,294.500488,0.000000
53.860004,65.174110,-1293.728516,-0.001526,0.002010,0.051063,289.908936,14.768664,0.510628,-1293.728516,294.500488,0.000000
54.150002,65.047890,-1293.683960,-0.001513,0.002011,0.051070,289.347473,14.740063,0.510703,-1293.683960,294.500488,0.000000
54.440002,65.498451,-1293.728516,-0.001518,0.002018,0.051254,291.351654,14.842161,0.512535,-1293.728516,294.500488,0.000000
54.730003,65.418770,-1293.772949,-0.001509,0.002018,0.051254,290.997223,14.824105,0.512535,-1293.772949,294.500488,0.000000
55.020004,65.305199,-1293.683960,-0.001522,0.002018,0.051254,290.492035,14.798369,0.512535,-1293.683960,294.500488,0.000000
55.310001,65.162941,-1293.683960,-0.001513,0.002018,0.051254,289.859253,14.766133,0.512535,-1293.683960,294.500488,0.000000
55.600002,65.106346,-1293.728516,-0.001505,0.002020,0.051305,289.607483,14.753309,0.513050,-1293.728516,294.500488,0.000000
55.890003,65.479088,-1293.772949,-0.001513,0.002025,0.051444,291.265533,14.837773,0.514443,-1293.772949,294.500488,0.000000
56.180004,65.398659,-1293.728516,-0.001500,0.002025,0.051444,290.907776,14.819548,0.514443,-1293.728516,294.500488,0.000000
56.470001,65.292900,-1293.683960,-0.001496,0.002026,0.051452,290.437317,14.795583,0.514519,-1293.683960,294.500488,0.000000
56.760002,65.163322,-1293.772949,-0.001513,0.002026,0.051470,289.860931,14.766220,0.514700,-1293.772949,294.500488,0.000000
57.050003,65.094795,-1293.772949,-0.001500,0.002027,0.051479,289.556122,14.750691,0.514791,-1293.772949,294.500488,0.000000
57.340004,64.980110,-1293.639526,-0.001505,0.002027,0.051479,289.045959,14.724703,0.514791,-1293.639526,294.500488,0.000000
57.630001,64.848289,-1293.728516,-0.001496,0.002027,0.051479,288.459595,14.694832,0.514791,-1293.728516,294.500488,0.000000
57.920002,65.848106,-1293.683960,-0.001496,0.002033,0.051635,292.907013,14.921394,0.516351,-1293.683960,294.500488,0.000000
58.210003,65.687248,-1293.683960,-0.001509,0.002033,0.051635,292.191467,14.884943,0.516351,-1293.683960,294.500488,0.000000
58.500004,65.552818,-1293.728516,-0.001492,0.002033,0.051635,291.593506,14.854481,0.516351,-1293.728516,294.500488,0.000000
58.790001,65.368874,-1293.683960,-0.001505,0.002033,0.051635,290.775269,14.812799,0.516351,-1293.683960,294.500488,0.000000
59.080002,65.236305,-1293.772949,-0.001479,0.002033,0.051635,290.185577,14.782759,0.516351,-1293.772949,294.500488,0.000000
59.370003,65.071709,-1293.683960,-0.001479,0.002033,0.051635,289.453430,14.745460,0.516351,-1293.683960,294.500488,0.000000
59.660004,65.540535,-1293.728516,-0.001487,0.002043,0.051895,291.538849,14.851697,0.518955,-1293.728516,294.500488,0.000000
59.950005,65.488029,-1293.728516,-0.001487,0.002043,0.051895,291.305298,14.839800,0.518955,-1293.728516,294.500488,0.000000
60.240002,65.363289,-1293.639526,-0.001487,0.002043,0.051895,290.750427,14.811533,0.518955,-1293.639526,294.500488,0.000000
60.530003,65.257896,-1293.728516,-0.001492,0.002043,0.051903,290.281616,14.787651,0.519030,-1293.728516,294.500488,0.000000
60.820004,65.143211,-1293.683960,-0.001483,0.002043,0.051903,289.771484,14.761663,0.519030,-1293.683960,294.500488,0.000000
61.110004,65.272789,-1293.728516,-0.001483,0.002047,0.051991,290.347870,14.791025,0.519908,-1293.728516,294.500488,0.000000
61.400002,65.218056,-1293.772949,-0.001479,0.002047,0.051998,290.104401,14.778623,0.519984,-1293.772949,294.500488,0.000000
61.690002,65.138374,-1293.639526,-0.001483,0.002048,0.052024,289.749969,14.760567,0.520241,-1293.639526,294.500488,0.000000
61.980003,65.115654,-1293.728516,-0.001475,0.002049,0.052033,289.648895,14.755418,0.520332,-1293.728516,294.500488,0.000000
62.270004,65.442604,-1293.683960,-0.001479,0.002054,0.052173,291.103241,14.829506,0.521725,-1293.683960,294.500488,0.000000
62.560001,65.417274,-1293.683960,-0.001470,0.002054,0.052173,290.990570,14.823767,0.521725,-1293.683960,294.500488,0.000000
62.850002,65.342430,-1293.728516,-0.001470,0.002054,0.052173,290.657654,14.806807,0.521725,-1293.728516,294.500488,0.000000
63.140003,65.251945,-1293.728516,-0.001487,0.002054,0.052182,290.255157,14.786302,0.521816,-1293.728516,294.500488,0.000000
63.430004,65.278008,-1293.728516,-0.001483,0.002056,0.052233,290.371094,14.792209,0.522331,-1293.728516,294.500488,0.000000
63.720001,65.251945,-1293.728516,-0.001475,0.002057,0.052242,290.255157,14.786302,0.522421,-1293.728516,294.500488,0.000000
64.010002,65.216576,-1293.639526,-0.001470,0.002058,0.052277,290.097809,14.778287,0.522770,-1293.639526,294.500488,0.000000
64.300003,65.182304,-1293.728516,-0.001470,0.002058,0.052285,289.945374,14.770521,0.522845,-1293.728516,294.500488,0.000000
64.590004,65.109322,-1293.683960,-0.001479,0.002059,0.052294,289.620728,14.753983,0.522936,-1293.683960,294.500488,0.000000
64.880005,65.046028,-1293.728516,-0.001475,0.002059,0.052303,289.339172,14.739640,0.523027,-1293.728516,294.500488,0.000000
65.170006,65.027779,-1293.683960,-0.001475,0.002062,0.052363,289.257996,14.735505,0.523633,-1293.683960,294.500488,0.000000
65.460007,65.052345,-1293.683960,-0.001466,0.002062,0.052363,289.367279,14.741073,0.523633,-1293.683960,294.500488,0.000000
65.750000,64.979362,-1293.728516,-0.001483,0.002062,0.052363,289.042633,14.724534,0.523633,-1293.728516,294.500488,0.000000
66.040001,64.945854,-1293.639526,-0.001457,0.002063,0.052389,288.893585,14.716941,0.523890,-1293.639526,294.500488,0.000000
66.330002,64.934685,-1293.728516,-0.001462,0.002064,0.052415,288.843903,14.714410,0.524147,-1293.728516,294.500488,0.000000
66.620003,65.000587,-1293.683960,-0.001462,0.002066,0.052475,289.137054,14.729344,0.524753,-1293.683960,294.500488,0.000000
66.910004,64.986809,-1293.639526,-0.001453,0.002066,0.052475,289.075775,14.726221,0.524753,-1293.639526,294.500488,0.000000
67.200005,65.014000,-1293.728516,-0.001457,0.002068,0.052528,289.196716,14.732384,0.525283,-1293.728516,294.500488,0.000000
67.490005,65.440361,-1293.639526,-0.001453,0.002074,0.052675,291.093262,14.828998,0.526751,-1293.639526,294.500488,0.000000
67.780006,65.447807,-1293.639526,-0.001457,0.002074,0.052675,291.126373,14.830686,0.526751,-1293.639526,294.500488,0.000000
68.070000,65.399025,-1293.728516,-0.001470,0.002074,0.052675,290.909393,14.819631,0.526751,-1293.728516,294.500488,0.000000
68.360001,65.314873,-1293.639526,-0.001453,0.002074,0.052675,290.535065,14.800561,0.526751,-1293.639526,294.500488,0.000000
68.650002,65.248589,-1293.683960,-0.001470,0.002074,0.052675,290.240204,14.785542,0.526751,-1293.683960,294.500488,0.000000
68.940002,65.203163,-1293.639526,-0.001449,0.002074,0.052684,290.038147,14.775248,0.526842,-1293.639526,294.500488,0.000000
69.230003,65.155128,-1293.728516,-0.001453,0.002075,0.052710,289.824493,14.764363,0.527100,-1293.728516,294.500488,0.000000
69.520004,65.111565,-1293.683960,-0.001457,0.002076,0.052719,289.630707,14.754492,0.527190,-1293.683960,294.500488,0.000000
69.810005,65.116020,-1293.683960,-0.001462,0.002077,0.052761,289.650513,14.755501,0.527614,-1293.683960,294.500488,0.000000
70.100006,65.103371,-1293.639526,-0.001449,0.002077,0.052761,289.594269,14.752634,0.527614,-1293.639526,294.500488,0.000000
70.390007,65.060921,-1293.639526,-0.001449,0.002079,0.052796,289.405426,14.743015,0.527963,-1293.639526,294.500488,0.000000
70.680000,65.045647,-1293.683960,-0.001453,0.002079,0.052796,289.337494,14.739554,0.527963,-1293.683960,294.500488,0.000000
70.970001,64.996498,-1293.772949,-0.001449,0.002079,0.052814,289.118866,14.728416,0.528144,-1293.772949,294.500488,0.000000
71.260002,65.077675,-1293.683960,-0.001449,0.002081,0.052866,289.479950,14.746812,0.528659,-1293.683960,294.500488,0.000000
71.550003,65.036339,-1293.728516,-0.001462,0.002081,0.052866,289.296082,14.737446,0.528659,-1293.728516,294.500488,0.000000
71.840004,65.003578,-1293.728516,-0.001466,0.002082,0.052875,289.150360,14.730021,0.528750,-1293.728516,294.500488,0.000000
72.130005,64.944359,-1293.639526,-0.001449,0.002082,0.052875,288.886932,14.716602,0.528750,-1293.639526,294.500488,0.000000
72.420006,64.880318,-1293.683960,-0.001436,0.002082,0.052875,288.602081,14.702090,0.528750,-1293.683960,294.500488,0.000000
72.710007,65.700279,-1293.594971,-0.001440,0.002093,0.053152,292.249451,14.887896,0.531520,-1293.594971,294.500488,0.000000
73.000000,65.686882,-1293.639526,-0.001444,0.002092,0.053126,292.189850,14.884861,0.531263,-1293.639526,294.500488,0.000000
73.290001,65.641823,-1293.728516,-0.001444,0.002092,0.053126,291.989410,14.874649,0.531263,-1293.728516,294.500488,0.000000
73.580002,65.584846,-1293.639526,-0.001436,0.002092,0.053126,291.735962,14.861739,0.531263,-1293.639526,294.500488,0.000000
73.870003,65.534950,-1293.683960,-0.001427,0.002092,0.053126,291.514008,14.850431,0.531263,-1293.683960,294.500488,0.000000
74.160004,65.467171,-1293.639526,-0.001444,0.002092,0.053126,291.212524,14.835073,0.531263,-1293.639526,294.500488,0.000000
74.450005,65.365517,-1293.772949,-0.001444,0.002092,0.053126,290.760345,14.812038,0.531263,-1293.772949,294.500488,0.000000
74.740005,65.314507,-1293.683960,-0.001444,0.002092,0.053126,290.533447,14.800479,0.531263,-1293.683960,294.500488,0.000000
75.030006,65.253059,-1293.683960,-0.001440,0.002092,0.053126,290.260101,14.786554,0.531263,-1293.683960,294.500488,0.000000
75.320007,65.169655,-1293.683960,-0.001440,0.002092,0.053126,289.889099,14.767654,0.531263,-1293.683960,294.500488,0.000000
75.610001,65.084755,-1293.728516,-0.001423,0.002092,0.053126,289.511444,14.748417,0.531263,-1293.728516,294.500488,0.000000
75.900002,65.032616,-1293.683960,-0.001444,0.002092,0.053143,289.279510,14.736601,0.531430,-1293.683960,294.500488,0.000000
76.190002,64.991661,-1293.728516,-0.001440,0.002092,0.053143,289.097351,14.727321,0.531430,-1293.728516,294.500488,0.000000
76.480003,64.914574,-1293.594971,-0.001440,0.002093,0.053152,288.754456,14.709852,0.531520,-1293.594971,294.500488,0.000000
76.770004,65.263863,-1293.728516,-0.001427,0.002098,0.053300,290.308167,14.789002,0.533004,-1293.728516,294.500488,0.000000
77.060005,65.259392,-1293.683960,-0.001431,0.002098,0.053300,290.288269,14.787990,0.533004,-1293.683960,294.500488,0.000000
77.350006,65.216194,-1293.728516,-0.001431,0.002098,0.053300,290.096130,14.778201,0.533004,-1293.728516,294.500488,0.000000
77.640007,65.149162,-1293.683960,-0.001423,0.002098,0.053300,289.797943,14.763011,0.533004,-1293.683960,294.500488,0.000000
77.930000,65.084755,-1293.639526,-0.001418,0.002098,0.053300,289.511444,14.748417,0.533004,-1293.639526,294.500488,0.000000
78.220001,65.038582,-1293.639526,-0.001423,0.002098,0.053300,289.306061,14.737954,0.533004,-1293.639526,294.500488,0.000000
78.510002,65.026665,-1293.728516,-0.001431,0.002099,0.053326,289.253052,14.735253,0.533261,-1293.728516,294.500488,0.000000
78.800003,65.007301,-1293.639526,-0.001431,0.002100,0.053343,289.166931,14.730865,0.533428,-1293.639526,294.500488,0.000000
79.090004,65.008415,-1293.683960,-0.001427,0.002101,0.053361,289.171875,14.731118,0.533610,-1293.683960,294.500488,0.000000
79.380005,64.989418,-1293.683960,-0.001427,0.002101,0.053378,289.087372,14.726813,0.533776,-1293.683960,294.500488,0.000000
79.670006,65.293648,-1293.683960,-0.001423,0.002106,0.053491,290.440643,14.795753,0.534912,-1293.683960,294.500488,0.000000
79.960007,65.320091,-1293.728516,-0.001436,0.002106,0.053491,290.558289,14.801744,0.534912,-1293.728516,294.500488,0.000000
80.250000,65.295509,-1293.594971,-0.001427,0.002106,0.053491,290.448944,14.796174,0.534912,-1293.594971,294.500488,0.000000
80.540001,65.254173,-1293.772949,-0.001431,0.002106,0.053491,290.265045,14.786807,0.534912,-1293.772949,294.500488,0.000000
80.830002,65.212837,-1293.728516,-0.001423,0.002106,0.053491,290.081177,14.777440,0.534912,-1293.728516,294.500488,0.000000
81.120003,65.146187,-1293.683960,-0.001431,0.002106,0.053491,289.784698,14.762337,0.534912,-1293.683960,294.500488,0.000000
81.410004,65.091072,-1293.728516,-0.001427,0.002106,0.053499,289.539551,14.749847,0.534987,-1293.728516,294.500488,0.000000
81.700005,65.040443,-1293.639526,-0.001414,0.002107,0.053517,289.314331,14.738375,0.535169,-1293.639526,294.500488,0.000000
81.990005,65.081032,-1293.728516,-0.001410,0.002109,0.053577,289.494873,14.747572,0.535775,-1293.728516,294.500488,0.000000
82.280006,65.091072,-1293.683960,-0.001410,0.002110,0.053587,289.539551,14.749847,0.535865,-1293.683960,294.500488,0.000000
82.570007,65.092201,-1293.683960,-0.001418,0.002110,0.053594,289.544586,14.750103,0.535941,-1293.683960,294.500488,0.000000
82.860001,65.113792,-1293.728516,-0.001423,0.002111,0.053620,289.640625,14.754995,0.536198,-1293.728516,294.500488,0.000000
83.150002,65.196831,-1293.594971,-0.001414,0.002113,0.053664,290.009979,14.773812,0.536638,-1293.594971,294.500488,0.000000
83.440002,65.187889,-1293.728516,-0.001423,0.002113,0.053664,289.970215,14.771787,0.536638,-1293.728516,294.500488,0.000000
83.730003,65.176353,-1293.683960,-0.001401,0.002113,0.053673,289.918915,14.769173,0.536728,-1293.683960,294.500488,0.000000
84.020004,65.155128,-1293.683960,-0.001427,0.002114,0.053689,289.824493,14.764363,0.536895,-1293.683960,294.500488,0.000000
84.310005,65.162209,-1293.728516,-0.001410,0.002114,0.053708,289.855988,14.765968,0.537077,-1293.728516,294.500488,0.000000
84.600006,65.143211,-1293.639526,-0.001418,0.002115,0.053715,289.771484,14.761663,0.537152,-1293.639526,294.500488,0.000000
84.890007,65.114159,-1293.683960,-0.001410,0.002115,0.053724,289.642242,14.755079,0.537243,-1293.683960,294.500488,0.000000
85.180000,65.156242,-1293.772949,-0.001423,0.002117,0.053759,289.829437,14.764615,0.537591,-1293.772949,294.500488,0.000000
85.470001,65.152519,-1293.683960,-0.001427,0.002117,0.053759,289.812866,14.763772,0.537591,-1293.683960,294.500488,0.000000
85.760002,65.114159,-1293.772949,-0.001410,0.002117,0.053759,289.642242,14.755079,0.537591,-1293.772949,294.500488,0.000000
86.050003,65.075813,-1293.772949,-0.001423,0.002117,0.053759,289.471680,14.746390,0.537591,-1293.772949,294.500488,0.000000
86.340004,65.196831,-1293.683960,-0.001418,0.002119,0.053829,290.009979,14.773812,0.538288,-1293.683960,294.500488,0.000000
86.630005,65.180824,-1293.772949,-0.001397,0.002119,0.053829,289.938782,14.770185,0.538288,-1293.772949,294.500488,0.000000
86.920006,65.146568,-1293.772949,-0.001401,0.002119,0.053829,289.786407,14.762424,0.538288,-1293.772949,294.500488,0.000000
87.210007,65.112679,-1293.772949,-0.001414,0.002120,0.053845,289.635651,14.754745,0.538454,-1293.772949,294.500488,0.000000
87.500008,65.399025,-1293.728516,-0.001414,0.002124,0.053950,290.909393,14.819631,0.539499,-1293.728516,294.500488,0.000000
87.790001,65.412804,-1293.683960,-0.001414,0.002124,0.053950,290.970673,14.822754,0.539499,-1293.683960,294.500488,0.000000
88.080002,65.402748,-1293.772949,-0.001406,0.002124,0.053950,290.925964,14.820475,0.539499,-1293.772949,294.500488,0.000000
88.370003,65.369987,-1293.728516,-0.001393,0.002124,0.053950,290.780212,14.813051,0.539499,-1293.728516,294.500488,0.000000
88.660004,65.317848,-1293.728516,-0.001406,0.002124,0.053950,290.548309,14.801236,0.539499,-1293.728516,294.500488,0.000000
88.950005,65.291786,-1293.772949,-0.001397,0.002124,0.053950,290.432373,14.795330,0.539499,-1293.772949,294.500488,0.000000
89.240005,65.251198,-1293.772949,-0.001410,0.002124,0.053959,290.251831,14.786133,0.539590,-1293.772949,294.500488,0.000000
89.530006,65.228859,-1293.772949,-0.001401,0.002125,0.053976,290.152466,14.781071,0.539756,-1293.772949,294.500488,0.000000
89.820007,65.219917,-1293.728516,-0.001414,0.002125,0.053985,290.112671,14.779044,0.539847,-1293.728516,294.500488,0.000000
90.110001,65.224388,-1293.772949,-0.001397,0.002126,0.054003,290.132568,14.780058,0.540029,-1293.772949,294.500488,0.000000
90.400002,65.187157,-1293.728516,-0.001401,0.002126,0.054010,289.966949,14.771621,0.540105,-1293.728516,294.500488,0.000000
90.690002,65.182686,-1293.728516,-0.001397,0.002127,0.054020,289.947083,14.770608,0.540195,-1293.728516,294.500488,0.000000
90.980003,65.147301,-1293.772949,-0.001397,0.002127,0.054020,289.789673,14.762589,0.540195,-1293.772949,294.500488,0.000000
91.270004,65.165184,-1293.728516,-0.001393,0.002128,0.054054,289.869202,14.766642,0.540544,-1293.728516,294.500488,0.000000
91.560005,65.167793,-1293.683960,-0.001410,0.002128,0.054063,289.880829,14.767234,0.540634,-1293.683960,294.500488,0.000000
91.850006,65.155495,-1293.772949,-0.001401,0.002129,0.054071,289.826111,14.764446,0.540710,-1293.772949,294.500488,0.000000
92.140007,65.128319,-1293.772949,-0.001393,0.002129,0.054071,289.705231,14.758287,0.540710,-1293.772949,294.500488,0.000000
92.430008,65.137260,-1293.861938,-0.001397,0.002130,0.054106,289.744995,14.760314,0.541058,-1293.861938,294.500488,0.000000
92.720001,65.168159,-1293.772949,-0.001393,0.002131,0.054124,289.882446,14.767316,0.541240,-1293.772949,294.500488,0.000000
93.010002,65.177101,-1293.772949,-0.001393,0.002131,0.054124,289.922211,14.769342,0.541240,-1293.772949,294.500488,0.000000
93.300003,65.136513,-1293.817383,-0.001397,0.002131,0.054124,289.741669,14.760145,0.541240,-1293.817383,294.500488,0.000000
93.590004,65.123100,-1293.772949,-0.001393,0.002132,0.054141,289.682007,14.757106,0.541407,-1293.772949,294.500488,0.000000
93.880005,65.092201,-1293.772949,-0.001397,0.002132,0.054150,289.544586,14.750103,0.541497,-1293.772949,294.500488,0.000000
94.170006,65.106712,-1293.817383,-0.001384,0.002132,0.054159,289.609131,14.753392,0.541588,-1293.817383,294.500488,0.000000
94.460007,65.078789,-1293.772949,-0.001393,0.002133,0.054166,289.484924,14.747064,0.541664,-1293.772949,294.500488,0.000000
94.750008,65.062401,-1293.728516,-0.001401,0.002133,0.054166,289.412018,14.743351,0.541664,-1293.728516,294.500488,0.000000
95.040001,65.030388,-1293.728516,-0.001380,0.002133,0.054175,289.269623,14.736096,0.541755,-1293.728516,294.500488,0.000000
95.330002,65.012886,-1293.772949,-0.001397,0.002133,0.054185,289.191772,14.732131,0.541846,-1293.772949,294.500488,0.000000
95.620003,65.008781,-1293.817383,-0.001388,0.002134,0.054201,289.173492,14.731200,0.542012,-1293.817383,294.500488,0.000000
95.910004,65.013252,-1293.817383,-0.001393,0.002134,0.054210,289.193390,14.732214,0.542103,-1293.817383,294.500488,0.000000
96.200005,65.010643,-1293.817383,-0.001384,0.002135,0.054236,289.181793,14.731623,0.542360,-1293.817383,294.500488,0.000000
96.490005,65.022194,-1293.728516,-0.001388,0.002136,0.054245,289.233154,14.734240,0.542451,-1293.728516,294.500488,0.000000
96.780006,65.036705,-1293.772949,-0.001393,0.002136,0.054254,289.297699,14.737528,0.542542,-1293.772949,294.500488,0.000000
97.070007,65.031120,-1293.817383,-0.001388,0.002136,0.054262,289.272858,14.736262,0.542618,-1293.817383,294.500488,0.000000
97.360008,65.054588,-1293.728516,-0.001380,0.002129,0.054080,289.377258,14.741581,0.540801,-1293.728516,0.054271,0.000000
97.650002,64.980858,-1293.861938,-0.001375,0.002126,0.053994,289.049286,14.724873,0.539938,-1293.861938,0.053838,0.000000
97.940002,64.925743,-1293.772949,-0.001367,0.002114,0.053689,288.804138,14.712383,0.536895,-1293.772949,0.053352,0.000000
98.230003,64.774559,-1293.817383,-0.001380,0.002101,0.053361,288.131622,14.678125,0.533610,-1293.817383,0.052866,0.000000
98.520004,64.680351,-1293.817383,-0.001384,0.002086,0.052979,287.712585,14.656777,0.529794,-1293.817383,0.052389,0.000000
98.810005,64.627098,-1293.728516,-0.001384,0.002068,0.052536,287.475677,14.644710,0.525359,-1293.728516,0.051903,0.000000
99.100006,64.542198,-1293.772949,-0.001384,0.002053,0.052154,287.098022,14.625471,0.521543,-1293.772949,0.051419,0.000000
99.390007,64.486717,-1293.772949,-0.001375,0.002029,0.051531,286.851257,14.612899,0.515306,-1293.772949,0.050933,0.000000
99.680008,64.405907,-1293.728516,-0.001375,0.002005,0.050923,286.491791,14.594586,0.509235,-1293.728516,0.050456,0.000000
99.970001,64.371651,-1293.817383,-0.001384,0.001992,0.050593,286.339417,14.586824,0.505934,-1293.817383,0.049970,0.000000
100.260002,64.299416,-1293.728516,-0.001371,0.001967,0.049961,286.018097,14.570457,0.499606,-1293.728516,0.049484,0.000000
100.550003,64.256966,-1293.728516,-0.001388,0.001952,0.049579,285.829254,14.560837,0.495791,-1293.728516,0.048998,0.000000
100.840004,64.147865,-1293.817383,-0.001362,0.001937,0.049198,285.343964,14.536115,0.491976,-1293.817383,0.048521,0.000000
101.130005,64.003014,-1293.728516,-0.001375,0.001916,0.048660,284.699615,14.503290,0.486601,-1293.728516,0.048036,0.000000
101.420006,63.771019,-1293.817383,-0.001362,0.001900,0.048270,283.667664,14.450719,0.482695,-1293.817383,0.047550,0.000000
101.710007,62.957756,-1293.772949,-0.001362,0.001877,0.047688,280.050079,14.266431,0.476882,-1293.772949,0.047064,0.000000
102.000008,62.415581,-1293.728516,-0.001367,0.001865,0.047360,277.638367,14.143573,0.473596,-1293.728516,0.046588,0.000000
102.290009,61.412041,-1293.817383,-0.001345,0.001844,0.046839,273.174408,13.916168,0.468388,-1293.817383,0.046102,0.000000
102.580002,60.434189,-1293.772949,-0.001362,0.001826,0.046388,268.824707,13.694583,0.463877,-1293.772949,0.045616,0.000000
102.870003,59.620926,-1293.861938,-0.001354,0.001813,0.046058,265.207123,13.510295,0.460576,-1293.861938,0.045131,0.000000
103.160004,58.541046,-1293.817383,-0.001350,0.001795,0.045590,260.403564,13.265591,0.455898,-1293.817383,0.044654,0.000000
103.450005,57.038895,-1293.772949,-0.001367,0.001775,0.045096,253.721680,12.925199,0.450963,-1293.772949,0.044168,0.000000
103.740005,55.587387,-1293.861938,-0.001371,0.001756,0.044610,247.265045,12.596282,0.446103,-1293.861938,0.043682,0.000000
104.030006,54.287437,-1293.728516,-0.001362,0.001741,0.044229,241.482590,12.301709,0.442288,-1293.728516,0.043205,0.000000
104.320007,52.657188,-1293.861938,-0.001358,0.001721,0.043717,234.230865,11.932289,0.437171,-1293.861938,0.042719,0.000000
104.610008,50.714523,-1293.772949,-0.001358,0.001701,0.043205,225.589462,11.492076,0.432053,-1293.772949,0.042233,0.000000
104.900002,49.148697,-1293.772949,-0.001358,0.001685,0.042798,218.624329,11.137254,0.427981,-1293.772949,0.041749,0.000000
105.190002,46.749130,-1293.772949,-0.001358,0.001661,0.042199,207.950516,10.593504,0.421986,-1293.772949,0.041272,0.000000
105.480003,45.324806,-1293.772949,-0.001362,0.001648,0.041852,201.614807,10.270747,0.418519,-1293.772949,0.040786,0.000000
105.770004,42.917419,-1293.817383,-0.001393,0.001624,0.041237,190.906219,9.725226,0.412372,-1293.817383,0.040300,0.000000
106.060005,41.119232,-1293.861938,-0.001388,0.001606,0.040803,182.907486,9.317751,0.408027,-1293.861938,0.039814,0.000000
106.350006,39.214172,-1293.772949,-0.001393,0.001587,0.040309,174.433350,8.886058,0.403091,-1293.772949,0.039337,0.000000
106.640007,37.313957,-1293.861938,-0.001384,0.001570,0.039875,165.980774,8.455463,0.398746,-1293.861938,0.038851,0.000000
106.930008,35.975647,-1293.817383,-0.001393,0.001557,0.039537,160.027664,8.152198,0.395370,-1293.817383,0.038367,0.000000
107.220009,33.831528,-1293.861938,-0.001406,0.001534,0.038974,150.490158,7.666334,0.389738,-1293.861938,0.037881,0.000000
107.510002,32.162186,-1293.817383,-0.001393,0.001518,0.038548,143.064545,7.288055,0.385484,-1293.817383,0.037404,0.000000
107.800003,30.552040,-1293.772949,-0.001388,0.001502,0.038149,135.902267,6.923191,0.381487,-1293.772949,0.036918,0.000000
108.090004,28.812317,-1293.817383,-0.001401,0.001483,0.037664,128.163589,6.528964,0.376642,-1293.817383,0.036432,0.000000
108.380005,25.613640,-1293.772949,-0.001414,0.001452,0.036883,113.935158,5.804134,0.368830,-1293.772949,0.035946,0.000000
108.670006,24.153938,-1293.817383,-0.001406,0.001438,0.036536,107.442085,5.473361,0.365363,-1293.817383,0.035469,0.000000
108.960007,22.773926,-1293.861938,-0.001397,0.001425,0.036199,101.303482,5.160645,0.361987,-1293.861938,0.034985,0.000000
109.250008,20.368401,-1293.817383,-0.001423,0.001400,0.035564,90.603172,4.615546,0.355644,-1293.817383,0.034499,0.000000
109.540009,18.304710,-1293.861938,-0.001423,0.001381,0.035080,81.423416,4.147907,0.350799,-1293.861938,0.034022,0.000000
109.830002,16.771286,-1293.728516,-0.001427,0.001366,0.034689,74.602409,3.800428,0.346893,-1293.728516,0.033536,0.000000
110.120003,15.232643,-1293.861938,-0.001436,0.001351,0.034315,67.758179,3.451766,0.343154,-1293.861938,0.033050,0.000000
110.410004,12.168762,-1293.772949,-0.001449,0.001322,0.033571,54.129356,2.757481,0.335705,-1293.772949,0.032564,0.000000
110.700005,10.819283,-1293.817383,-0.001436,0.001307,0.033198,48.126572,2.451684,0.331981,-1293.817383,0.032087,0.000000
110.990005,8.539619,-1293.817383,-0.001440,0.001284,0.032617,37.986126,1.935105,0.326167,-1293.817383,0.031602,0.000000
111.280006,7.002838,-1293.772949,-0.001462,0.001267,0.032182,31.150179,1.586866,0.321822,-1293.772949,0.031116,0.000000
111.570007,4.843079,-1293.728516,-0.001479,0.001244,0.031602,21.543089,1.097457,0.316024,-1293.728516,0.030630,0.000000
111.860008,3.177452,-1293.772949,-0.001453,0.001228,0.031186,14.134013,0.720021,0.311860,-1293.772949,0.030153,0.000000
112.150002,0.962952,-1293.728516,-0.001470,0.001203,0.030544,4.283423,0.218208,0.305441,-1293.728516,0.029668,0.000000
112.440002,-0.255074,-1293.817383,-0.001475,0.001189,0.030205,-1.134624,-0.057800,0.302050,-1293.817383,0.029182,0.000000
112.730003,-1.415386,-1293.772949,-0.001483,0.001174,0.029823,-6.295952,-0.320731,0.298235,-1293.772949,0.028697,0.000000
113.020004,-3.123833,-1293.906372,-0.001496,0.001154,0.029321,-13.895502,-0.707871,0.293208,-1293.906372,0.028220,0.000000
113.310005,-1.896122,-1293.861938,-0.001544,0.001135,0.028818,-8.434372,-0.429667,0.288182,-1293.861938,0.027734,0.000000
113.600006,-0.103149,-1293.772949,-0.001552,0.001112,0.028237,-0.458832,-0.023374,0.282368,-1293.772949,0.027248,0.000000
113.890007,-0.047661,-1293.772949,-0.001587,0.001094,0.027795,-0.212006,-0.010800,0.277948,-1293.772949,0.026762,0.000000
114.180008,-0.079315,-1293.728516,-0.001617,0.001069,0.027153,-0.352812,-0.017973,0.271528,-1293.728516,0.026285,0.000000
114.470009,-0.047661,-1293.772949,-0.001656,0.001052,0.026727,-0.212006,-0.010800,0.267274,-1293.772949,0.025799,0.000000
114.760002,-0.017128,-1293.817383,-0.001673,0.001036,0.026320,-0.076189,-0.003881,0.263202,-1293.817383,0.025315,0.000000
115.050003,-0.036865,-1293.817383,-0.001690,0.001018,0.025861,-0.163985,-0.008354,0.258614,-1293.817383,0.024838,0.000000
115.340004,-0.004837,-1293.817383,-0.001703,0.001002,0.025445,-0.021516,-0.001096,0.254451,-1293.817383,0.024352,0.000000
115.630005,-0.028297,-1293.817383,-0.001729,0.000984,0.025002,-0.125873,-0.006412,0.250015,-1293.817383,0.023866,0.000000
115.920006,-0.033882,-1293.817383,-0.001768,0.000961,0.024422,-0.150715,-0.007678,0.244217,-1293.817383,0.023380,0.000000
116.210007,-0.036491,-1293.817383,-0.001794,0.000939,0.023849,-0.162322,-0.008269,0.238494,-1293.817383,0.022903,0.000000
116.500008,-0.042076,-1293.772949,-0.001824,0.000918,0.023319,-0.187164,-0.009535,0.233195,-1293.772949,0.022417,0.000000
116.790009,-0.051758,-1293.906372,-0.001828,0.000901,0.022887,-0.230230,-0.011728,0.228865,-1293.906372,0.021933,0.000000
117.080002,-0.026070,-1293.817383,-0.001854,0.000895,0.022738,-0.115964,-0.005907,0.227381,-1293.817383,0.022643,0.000000
117.200005,-0.022339,-1293.817383,-0.001850,0.000895,0.022738,-0.099368,-0.005062,0.227381,-1293.817383,0.022643,0.000000