File: Data/Sima compression/P2-11-1re_10302024_165152.csv
Time (sec),S:Load (lbs),S:HL1 (DIM),S:LVDT (in),S:Position (in),Ch:Position (mm),Ch:Load (N),Ch:Stress (MPa),Ch:Strain (mm/mm),Ch:HL1 (DIM),Set Point (),Cycles ()
0.210000,-0.056976,-1293.950806,-0.007179,-0.004065,-0.103261,-0.253443,-0.012911,-1.032610,-1293.950806,-0.103054,0.000000
0.550000,0.008934,-1293.861938,-0.007179,-0.003976,-0.100998,0.039741,0.002024,-1.009977,-1293.861938,-0.100365,0.000000
0.890000,0.026810,-1293.861938,-0.007058,-0.003777,-0.095943,0.119255,0.006075,-0.959425,-1293.861938,-0.094710,0.000000
1.230000,0.001114,-1293.950806,-0.006825,-0.003551,-0.090193,0.004955,0.000252,-0.901925,-1293.950806,-0.089039,0.000000
1.570000,-0.020111,-1293.861938,-0.006584,-0.003332,-0.084633,-0.089459,-0.004557,-0.846333,-1293.861938,-0.083368,0.000000
1.910000,-0.011543,-1293.906372,-0.006364,-0.003111,-0.079013,-0.051347,-0.002616,-0.790135,-1293.906372,-0.077713,0.000000
2.250000,0.003349,-1293.950806,-0.006148,-0.002888,-0.073351,0.014898,0.000759,-0.733513,-1293.950806,-0.072042,0.000000
2.590000,-0.052132,-1293.861938,-0.005907,-0.002661,-0.067583,-0.231893,-0.011813,-0.675831,-1293.861938,-0.066387,0.000000
2.930000,-0.003349,-1293.950806,-0.005678,-0.002436,-0.061877,-0.014898,-0.000759,-0.618770,-1293.950806,-0.060716,0.000000
3.270000,0.052505,-1293.817383,-0.005433,-0.002215,-0.056257,0.233556,0.011898,-0.562572,-1293.817383,-0.055061,0.000000
3.610000,0.015640,-1293.906372,-0.005208,-0.001990,-0.050551,0.069571,0.003544,-0.505511,-1293.906372,-0.049390,0.000000
3.950000,-0.003349,-1293.950806,-0.004975,-0.001765,-0.044828,-0.014898,-0.000759,-0.448283,-1293.950806,-0.043717,0.000000
4.290000,-0.062561,-1293.906372,-0.004760,-0.001543,-0.039181,-0.278285,-0.014177,-0.391812,-1293.906372,-0.038064,0.000000
4.630000,-0.021973,-1293.950806,-0.004544,-0.001329,-0.033761,-0.097739,-0.004979,-0.337613,-1293.950806,-0.032391,0.000000
4.970000,0.036118,-1293.906372,-0.004299,-0.001101,-0.027978,0.160659,0.008184,-0.279779,-1293.906372,-0.026738,0.000000
5.310000,0.013031,-1293.906372,-0.004066,-0.000872,-0.022142,0.057965,0.002953,-0.221416,-1293.906372,-0.021065,0.000000
5.650000,0.021225,-1293.906372,-0.003846,-0.000655,-0.016625,0.094413,0.004810,-0.166248,-1293.906372,-0.015411,0.000000
5.990000,0.007072,-1293.861938,-0.003617,-0.000432,-0.010972,0.031460,0.001603,-0.109717,-1293.861938,-0.009739,0.000000
6.330000,0.020851,-1293.906372,-0.003389,-0.000210,-0.005326,0.092750,0.004725,-0.053261,-1293.906372,-0.004068,0.000000
6.670001,0.160492,-1293.861938,-0.003165,-0.000023,-0.000590,0.713904,0.036368,-0.005904,-1293.861938,-0.000365,0.000000
7.010000,0.100540,-1293.817383,-0.003173,-0.000000,-0.000000,0.447225,0.022783,-0.000000,-1293.817383,0.000226,0.000000
7.350000,0.147087,-1293.950806,-0.003178,-0.000000,-0.000000,0.654276,0.033330,-0.000000,-1293.950806,0.000521,0.000000
7.690001,0.126976,-1293.861938,-0.003178,-0.000000,-0.000000,0.564817,0.028773,-0.000000,-1293.861938,0.001084,0.000000
8.030001,0.292686,-1293.861938,-0.003156,0.000035,0.000884,1.301934,0.066324,0.008842,-1293.861938,0.001647,0.000000
8.370001,0.490784,-1293.861938,-0.003147,0.000052,0.001310,2.183115,0.111213,0.013096,-1293.861938,0.002219,0.000000
8.710000,0.698944,-1293.906372,-0.003130,0.000066,0.001674,3.109059,0.158383,0.016744,-1293.906372,0.002784,0.000000
9.050000,1.091797,-1293.950806,-0.003087,0.000102,0.002584,4.856555,0.247405,0.025843,-1293.950806,0.003347,0.000000
9.390000,1.319313,-1293.861938,-0.003061,0.000120,0.003045,5.868598,0.298961,0.030446,-1293.861938,0.003920,0.000000
9.730000,1.656311,-1293.906372,-0.003057,0.000140,0.003547,7.367640,0.375325,0.035472,-1293.906372,0.004483,0.000000
10.070001,2.098694,-1293.950806,-0.003035,0.000163,0.004145,9.335457,0.475571,0.041452,-1293.950806,0.005057,0.000000
10.410001,2.445000,-1293.906372,-0.003009,0.000181,0.004605,10.875902,0.554045,0.046055,-1293.906372,0.005620,0.000000
10.750001,2.753693,-1293.906372,-0.003005,0.000199,0.005064,12.249037,0.623996,0.050642,-1293.906372,0.006183,0.000000
11.090000,3.495461,-1293.906372,-0.002975,0.000233,0.005906,15.548585,0.792083,0.059060,-1293.906372,0.006755,0.000000
11.430000,3.823517,-1293.906372,-0.002949,0.000251,0.006374,17.007853,0.866421,0.063738,-1293.906372,0.007320,0.000000
11.770000,4.131104,-1293.906372,-0.002923,0.000268,0.006816,18.376066,0.936121,0.068158,-1293.906372,0.007883,0.000000
12.110001,4.802116,-1293.906372,-0.002915,0.000298,0.007571,21.360880,1.088175,0.075713,-1293.906372,0.008455,0.000000
12.450001,4.929840,-1293.950806,-0.002889,0.000308,0.007823,21.929024,1.117118,0.078226,-1293.950806,0.009019,0.000000
12.790001,5.786293,-1293.906372,-0.002871,0.000344,0.008742,25.738716,1.311193,0.087416,-1293.906372,0.009583,0.000000
13.130001,6.089783,-1293.906372,-0.002850,0.000364,0.009253,27.088707,1.379964,0.092533,-1293.906372,0.010156,0.000000
13.470000,6.305756,-1293.950806,-0.002828,0.000383,0.009739,28.049402,1.428905,0.097393,-1293.950806,0.010719,0.000000
13.810000,6.836761,-1293.861938,-0.002798,0.000408,0.010354,30.411434,1.549232,0.103540,-1293.861938,0.011282,0.000000
14.150001,7.146202,-1293.950806,-0.002781,0.000429,0.010893,31.787895,1.619352,0.108929,-1293.950806,0.011854,0.000000
14.490001,7.479477,-1293.861938,-0.002764,0.000448,0.011386,33.270374,1.694874,0.113865,-1293.861938,0.012419,0.000000
14.830001,7.965050,-1293.906372,-0.002734,0.000477,0.012115,35.430309,1.804906,0.121147,-1293.906372,0.012982,0.000000
15.170001,8.053299,-1293.995361,-0.002703,0.000496,0.012610,35.822865,1.824904,0.126098,-1293.995361,0.013554,0.000000
15.510001,8.307632,-1293.906372,-0.002686,0.000519,0.013182,36.954193,1.882536,0.131820,-1293.906372,0.014119,0.000000
15.850000,8.585419,-1293.995361,-0.002669,0.000545,0.013841,38.189850,1.945484,0.138406,-1293.995361,0.014682,0.000000
16.190001,8.687447,-1294.039795,-0.002630,0.000562,0.014266,38.643692,1.968603,0.142660,-1294.039795,0.015255,0.000000
16.530001,8.773842,-1293.950806,-0.002621,0.000577,0.014664,39.027996,1.988181,0.146642,-1293.950806,0.015818,0.000000
16.870001,9.214355,-1293.950806,-0.002591,0.000606,0.015394,40.987499,2.088003,0.153939,-1293.950806,0.016383,0.000000
17.210001,9.433685,-1293.950806,-0.002548,0.000633,0.016078,41.963127,2.137704,0.160782,-1293.950806,0.016955,0.000000
17.550001,9.349159,-1293.950806,-0.002552,0.000651,0.016529,41.587139,2.118550,0.165294,-1293.950806,0.017518,0.000000
17.890001,9.643700,-1293.950806,-0.002505,0.000676,0.017162,42.897320,2.185293,0.171622,-1293.950806,0.018081,0.000000
18.230001,9.504059,-1293.950806,-0.002501,0.000691,0.017553,42.276165,2.153651,0.175528,-1293.950806,0.018653,0.000000
18.570002,9.976234,-1293.906372,-0.002466,0.000720,0.018299,44.376507,2.260647,0.182992,-1293.906372,0.019218,0.000000
18.910002,10.096504,-1293.906372,-0.002423,0.000740,0.018784,44.911495,2.287900,0.187837,-1293.906372,0.019790,0.000000
19.250000,10.169121,-1293.950806,-0.002402,0.000762,0.019365,45.234509,2.304356,0.193650,-1293.950806,0.020354,0.000000
19.590000,10.459946,-1293.950806,-0.002384,0.000788,0.020016,46.528164,2.370257,0.200160,-1293.950806,0.020917,0.000000
19.930000,10.583199,-1293.950806,-0.002350,0.000813,0.020640,47.076420,2.398187,0.206398,-1293.950806,0.021489,0.000000
20.270000,10.455475,-1293.950806,-0.002324,0.000828,0.021021,46.508274,2.369244,0.210213,-1293.950806,0.022054,0.000000
20.610001,10.772736,-1293.950806,-0.002315,0.000852,0.021628,47.919521,2.441137,0.216284,-1293.950806,0.022617,0.000000
20.950001,10.783905,-1293.950806,-0.002294,0.000873,0.022166,47.969204,2.443668,0.221659,-1293.950806,0.023189,0.000000
21.290001,11.085526,-1293.950806,-0.002242,0.000897,0.022791,49.310879,2.512016,0.227911,-1293.950806,0.023754,0.000000
21.630001,11.056854,-1293.950806,-0.002233,0.000918,0.023319,49.183346,2.505519,0.233195,-1293.950806,0.024317,0.000000
21.970001,11.341347,-1293.950806,-0.002207,0.000941,0.023910,50.448830,2.569986,0.239099,-1293.950806,0.024889,0.000000
22.310001,11.314537,-1293.906372,-0.002190,0.000958,0.024326,50.329575,2.563911,0.243263,-1293.906372,0.025453,0.000000
22.650002,11.616905,-1293.950806,-0.002147,0.000983,0.024976,51.674576,2.632428,0.249758,-1293.950806,0.026017,0.000000
22.990002,11.949806,-1293.995361,-0.002121,0.001010,0.025653,53.155392,2.707865,0.256525,-1293.995361,0.026590,0.000000
23.330002,12.117744,-1293.861938,-0.002091,0.001033,0.026251,53.902420,2.745920,0.262505,-1293.861938,0.027153,0.000000
23.670002,11.835114,-1293.995361,-0.002082,0.001046,0.026562,52.645214,2.681875,0.265624,-1293.995361,0.027716,0.000000
24.010000,12.281219,-1293.950806,-0.002035,0.001076,0.027327,54.629593,2.782964,0.273269,-1293.950806,0.028288,0.000000
24.350000,12.198921,-1293.950806,-0.002035,0.001093,0.027751,54.263512,2.764315,0.277508,-1293.950806,0.028853,0.000000
24.690001,12.814079,-1293.950806,-0.001996,0.001125,0.028584,56.999870,2.903712,0.285835,-1293.950806,0.029416,0.000000
25.030001,12.729179,-1293.861938,-0.001966,0.001144,0.029070,56.622219,2.884473,0.290695,-1293.861938,0.029988,0.000000
25.370001,12.790253,-1293.950806,-0.001932,0.001165,0.029590,56.893887,2.898313,0.295903,-1293.950806,0.030552,0.000000
25.710001,13.066177,-1293.906372,-0.001923,0.001188,0.030179,58.121262,2.960838,0.301792,-1293.906372,0.031116,0.000000
26.050001,13.249382,-1293.861938,-0.001897,0.001210,0.030726,58.936195,3.002353,0.307258,-1293.861938,0.031689,0.000000
26.390001,13.568138,-1293.906372,-0.001876,0.001235,0.031377,60.354092,3.074584,0.313768,-1293.906372,0.032252,0.000000
26.730001,13.659370,-1293.906372,-0.001832,0.001257,0.031931,60.759914,3.095258,0.319309,-1293.906372,0.032824,0.000000
27.070002,13.610214,-1293.861938,-0.001824,0.001277,0.032443,60.541256,3.084119,0.324426,-1293.861938,0.033389,0.000000
27.410002,13.839592,-1293.906372,-0.001798,0.001301,0.033041,61.561581,3.136096,0.330406,-1293.906372,0.033952,0.000000
27.750002,13.960991,-1293.906372,-0.001755,0.001321,0.033545,62.101589,3.163606,0.335448,-1293.906372,0.034524,0.000000
28.090002,14.051102,-1294.039795,-0.001742,0.001340,0.034047,62.502422,3.184025,0.340474,-1294.039795,0.035087,0.000000
28.430002,14.619347,-1293.906372,-0.001716,0.001372,0.034845,65.030098,3.312791,0.348453,-1293.906372,0.035652,0.000000
28.770000,14.337456,-1293.906372,-0.001686,0.001388,0.035243,63.776188,3.248914,0.352434,-1293.906372,0.036224,0.000000
29.110001,14.535934,-1293.861938,-0.001660,0.001411,0.035851,64.659065,3.293890,0.358505,-1293.861938,0.036788,0.000000
29.450001,14.893784,-1293.906372,-0.001630,0.001435,0.036458,66.250854,3.374980,0.364576,-1293.906372,0.037351,0.000000
29.790001,14.711319,-1293.906372,-0.001604,0.001451,0.036866,65.439217,3.333632,0.368664,-1293.906372,0.037923,0.000000
30.130001,14.624184,-1293.861938,-0.001608,0.001467,0.037255,65.051620,3.313887,0.372555,-1293.861938,0.038488,0.000000
30.470001,15.712631,-1293.861938,-0.001569,0.001504,0.038209,69.893272,3.560533,0.382093,-1293.861938,0.039051,0.000000
30.810001,15.409142,-1293.950806,-0.001531,0.001523,0.038688,68.543282,3.491761,0.386877,-1293.950806,0.039623,0.000000
31.150002,15.253494,-1293.906372,-0.001518,0.001541,0.039137,67.850929,3.456491,0.391373,-1293.906372,0.040186,0.000000
31.490002,15.587883,-1293.995361,-0.001496,0.001564,0.039728,69.338364,3.532265,0.397278,-1293.995361,0.040751,0.000000
31.830002,15.587509,-1293.861938,-0.001479,0.001581,0.040161,69.336700,3.532180,0.401608,-1293.861938,0.041323,0.000000
32.170002,15.645226,-1293.906372,-0.001444,0.001601,0.040665,69.593437,3.545259,0.406649,-1293.906372,0.041887,0.000000
32.510002,16.372475,-1293.861938,-0.001401,0.001634,0.041514,72.828407,3.710056,0.415142,-1293.861938,0.042451,0.000000
32.850002,16.327789,-1293.906372,-0.001380,0.001655,0.042035,72.629631,3.699930,0.420350,-1293.906372,0.043024,0.000000
33.190002,16.330025,-1293.950806,-0.001354,0.001674,0.042512,72.639580,3.700436,0.425119,-1293.950806,0.043587,0.000000
33.530003,16.813362,-1293.906372,-0.001341,0.001701,0.043214,74.789574,3.809962,0.432144,-1293.906372,0.044150,0.000000
33.870003,16.748940,-1293.906372,-0.001319,0.001718,0.043638,74.503006,3.795364,0.436383,-1293.906372,0.044722,0.000000
34.210003,17.268028,-1293.950806,-0.001281,0.001747,0.044376,76.812027,3.912991,0.443756,-1293.950806,0.045287,0.000000
34.550003,17.387932,-1293.906372,-0.001259,0.001770,0.044948,77.345383,3.940162,0.449479,-1293.906372,0.045850,0.000000
34.890003,17.325005,-1293.950806,-0.001242,0.001788,0.045408,77.065468,3.925902,0.454081,-1293.950806,0.046422,0.000000
35.230003,17.735359,-1293.906372,-0.001203,0.001813,0.046050,78.890816,4.018890,0.460501,-1293.906372,0.046986,0.000000
35.570004,17.784134,-1293.906372,-0.001186,0.001832,0.046536,79.107780,4.029943,0.465360,-1293.906372,0.047558,0.000000
35.910000,18.171402,-1293.906372,-0.001160,0.001854,0.047090,80.830437,4.117699,0.470901,-1293.906372,0.048123,0.000000
36.250000,18.583992,-1293.995361,-0.001125,0.001880,0.047749,82.665726,4.211193,0.477487,-1293.995361,0.048686,0.000000
36.590000,18.662933,-1293.906372,-0.001104,0.001903,0.048330,83.016876,4.229081,0.483301,-1293.906372,0.049258,0.000000
36.930000,18.820450,-1293.906372,-0.001078,0.001926,0.048930,83.717545,4.264775,0.489296,-1293.906372,0.049823,0.000000
37.270000,19.199524,-1293.950806,-0.001065,0.001948,0.049484,85.403748,4.350675,0.494837,-1293.950806,0.050386,0.000000
37.610001,18.883011,-1293.950806,-0.001035,0.001962,0.049830,83.995827,4.278951,0.498304,-1293.950806,0.050958,0.000000
37.950001,19.409172,-1293.861938,-0.001026,0.001989,0.050533,86.336311,4.398181,0.505329,-1293.861938,0.051522,0.000000
38.290001,20.054489,-1293.950806,-0.000987,0.002014,0.051149,89.206825,4.544412,0.511491,-1293.950806,0.052086,0.000000
38.630001,20.312920,-1293.906372,-0.000949,0.002037,0.051730,90.356377,4.602973,0.517304,-1293.906372,0.052658,0.000000
38.970001,20.687149,-1293.906372,-0.000940,0.002060,0.052312,92.021034,4.687775,0.523118,-1293.906372,0.053222,0.000000
39.310001,20.587730,-1293.906372,-0.000918,0.002076,0.052727,91.578796,4.665246,0.527266,-1293.906372,0.053785,0.000000
39.650002,21.088570,-1293.861938,-0.000910,0.002099,0.053317,93.806641,4.778738,0.533171,-1293.861938,0.054357,0.000000
39.990002,21.959549,-1293.995361,-0.000884,0.002128,0.054045,97.680954,4.976105,0.540453,-1293.995361,0.054922,0.000000
40.330002,21.892891,-1293.861938,-0.000849,0.002145,0.054480,97.384445,4.961000,0.544798,-1293.861938,0.055485,0.000000
40.670002,22.212761,-1293.906372,-0.000819,0.002167,0.055043,98.807297,5.033484,0.550430,-1293.906372,0.056057,0.000000
41.010002,22.846916,-1293.906372,-0.000802,0.002195,0.055745,101.628159,5.177185,0.557454,-1293.906372,0.056621,0.000000
41.350002,23.221893,-1293.861938,-0.000767,0.002216,0.056274,103.296143,5.262156,0.562738,-1293.861938,0.057185,0.000000
41.690002,23.012619,-1293.950806,-0.000755,0.002230,0.056639,102.365242,5.214734,0.566387,-1293.950806,0.057757,0.000000
42.030003,24.005363,-1293.861938,-0.000729,0.002257,0.057315,106.781189,5.439693,0.573154,-1293.861938,0.058321,0.000000
42.370003,24.351295,-1293.861938,-0.000724,0.002278,0.057862,108.319969,5.518083,0.578620,-1293.861938,0.058884,0.000000
42.710003,25.080032,-1293.995361,-0.000694,0.002304,0.058511,111.561554,5.683217,0.585114,-1293.995361,0.059458,0.000000
43.050003,25.463577,-1293.817383,-0.000681,0.002324,0.059041,113.267647,5.770129,0.590413,-1293.817383,0.060021,0.000000
43.390003,25.832596,-1293.950806,-0.000651,0.002343,0.059500,114.909126,5.853750,0.595001,-1293.950806,0.060593,0.000000
43.730003,26.061234,-1293.906372,-0.000634,0.002361,0.059977,115.926155,5.905560,0.599770,-1293.906372,0.061156,0.000000
44.070004,27.029030,-1293.950806,-0.000621,0.002388,0.060663,120.231133,6.124866,0.606628,-1293.950806,0.061721,0.000000
44.410004,27.948784,-1293.950806,-0.000595,0.002413,0.061296,124.322403,6.333285,0.612956,-1293.950806,0.062293,0.000000
44.750004,28.719597,-1293.950806,-0.000578,0.002439,0.061954,127.751144,6.507954,0.619542,-1293.950806,0.062857,0.000000
45.090004,29.398430,-1293.906372,-0.000556,0.002461,0.062519,130.770752,6.661779,0.625189,-1293.906372,0.063420,0.000000
45.430000,29.873955,-1293.950806,-0.000543,0.002480,0.062987,132.885986,6.769535,0.629867,-1293.950806,0.063992,0.000000
45.770000,30.649979,-1293.950806,-0.000530,0.002507,0.063671,136.337921,6.945385,0.636710,-1293.950806,0.064557,0.000000
46.110001,31.506065,-1293.950806,-0.000513,0.002528,0.064218,140.145981,7.139377,0.642176,-1293.950806,0.065120,0.000000
46.450001,32.149147,-1293.861938,-0.000479,0.002549,0.064747,143.006546,7.285101,0.647474,-1293.861938,0.065692,0.000000
46.790001,32.833572,-1293.950806,-0.000474,0.002571,0.065294,146.051025,7.440194,0.652940,-1293.950806,0.066255,0.000000
47.130001,33.605499,-1293.861938,-0.000453,0.002592,0.065841,149.484726,7.615115,0.658405,-1293.861938,0.066820,0.000000
47.470001,34.387482,-1293.906372,-0.000440,0.002610,0.066299,152.963165,7.792315,0.662992,-1293.906372,0.067392,0.000000
47.810001,36.173004,-1293.950806,-0.000427,0.002642,0.067106,160.905563,8.196919,0.671062,-1293.950806,0.067956,0.000000
48.150002,36.752792,-1293.950806,-0.000414,0.002660,0.067574,163.484589,8.328302,0.675740,-1293.950806,0.068520,0.000000
48.490002,37.686699,-1293.995361,-0.000401,0.002683,0.068137,167.638809,8.539928,0.681372,-1293.995361,0.069092,0.000000
48.830002,38.739021,-1293.995361,-0.000371,0.002705,0.068711,172.319778,8.778387,0.687110,-1293.995361,0.069656,0.000000
49.170002,39.511322,-1293.950806,-0.000362,0.002722,0.069144,175.755142,8.953394,0.691440,-1293.950806,0.070219,0.000000
49.510002,40.945328,-1293.950806,-0.000345,0.002750,0.069846,182.133911,9.278344,0.698465,-1293.950806,0.070791,0.000000
49.850002,42.681702,-1293.906372,-0.000328,0.002777,0.070523,189.857697,9.671812,0.705232,-1293.906372,0.071356,0.000000
50.190002,43.382881,-1293.950806,-0.000328,0.002795,0.070982,192.976700,9.830702,0.709819,-1293.950806,0.071919,0.000000
50.530003,44.297424,-1293.906372,-0.000297,0.002814,0.071468,197.044785,10.037940,0.714679,-1293.906372,0.072491,0.000000
50.870003,45.874802,-1293.950806,-0.000297,0.002838,0.072093,204.061310,10.395379,0.720932,-1293.950806,0.073055,0.000000
51.210003,46.479904,-1293.950806,-0.000276,0.002852,0.072431,206.752945,10.532497,0.724308,-1293.950806,0.073619,0.000000
51.550003,47.366898,-1293.772949,-0.000272,0.002869,0.072873,210.698486,10.733492,0.728729,-1293.772949,0.074192,0.000000
51.890003,50.357788,-1293.950806,-0.000250,0.002906,0.073810,224.002625,11.411238,0.738100,-1293.950806,0.074755,0.000000
52.230003,51.341225,-1293.906372,-0.000246,0.002926,0.074322,228.377167,11.634089,0.743217,-1293.906372,0.075327,0.000000
52.570004,52.473610,-1293.861938,-0.000241,0.002946,0.074824,233.414276,11.890691,0.748243,-1293.861938,0.075890,0.000000
52.910004,54.501549,-1293.906372,-0.000224,0.002970,0.075448,242.434998,12.350228,0.754481,-1293.906372,0.076455,0.000000
53.250004,55.649574,-1293.950806,-0.000207,0.002989,0.075908,247.541672,12.610373,0.759083,-1293.950806,0.077027,0.000000
53.590004,56.573059,-1293.950806,-0.000207,0.003011,0.076490,251.649536,12.819638,0.764897,-1293.950806,0.077590,0.000000
53.930004,58.957733,-1293.906372,-0.000203,0.003036,0.077104,262.257080,13.360013,0.771044,-1293.906372,0.078155,0.000000
54.270004,60.774162,-1293.817383,-0.000181,0.003060,0.077711,270.336975,13.771623,0.777115,-1293.817383,0.078727,0.000000
54.610004,62.242805,-1293.906372,-0.000164,0.003079,0.078197,276.869812,14.104422,0.781974,-1293.906372,0.079291,0.000000
54.950001,63.898735,-1293.906372,-0.000164,0.003102,0.078779,284.235779,14.479660,0.787788,-1293.906372,0.079854,0.000000
55.290001,65.439613,-1293.950806,-0.000160,0.003123,0.079316,291.089935,14.828828,0.793163,-1293.950806,0.080426,0.000000
55.630001,65.822044,-1293.861938,-0.000142,0.003124,0.079360,292.791077,14.915488,0.793602,-1293.861938,0.013939,0.000000
55.970001,65.279503,-1293.995361,-0.000147,0.003124,0.079360,290.377716,14.792547,0.793602,-1293.995361,294.500488,0.000000
56.310001,65.938225,-1293.906372,-0.000138,0.003141,0.079777,293.307861,14.941815,0.797765,-1293.906372,294.500488,0.000000
56.650002,65.587456,-1293.906372,-0.000134,0.003139,0.079742,291.747589,14.862329,0.797417,-1293.906372,294.500488,0.000000
56.990002,65.282112,-1293.950806,-0.000142,0.003139,0.079742,290.389343,14.793138,0.797417,-1293.950806,294.500488,0.000000
57.330002,65.010277,-1293.861938,-0.000125,0.003140,0.079758,289.180145,14.731539,0.797583,-1293.861938,294.500488,0.000000
57.670002,64.764137,-1293.861938,-0.000138,0.003140,0.079758,288.085266,14.675763,0.797583,-1293.861938,294.500488,0.000000
58.010002,66.232399,-1293.861938,-0.000116,0.003136,0.079663,294.616425,15.008476,0.796630,-1293.861938,294.500488,0.000000
58.350002,65.918861,-1293.861938,-0.000121,0.003136,0.079663,293.221741,14.937428,0.796630,-1293.861938,294.500488,0.000000
58.690002,65.748314,-1293.950806,-0.000116,0.003136,0.079663,292.463104,14.898781,0.796630,-1293.950806,294.500488,0.000000
59.030003,65.514839,-1293.861938,-0.000103,0.003137,0.079672,291.424561,14.845875,0.796720,-1293.861938,294.500488,0.000000
59.370003,65.346153,-1293.950806,-0.000116,0.003149,0.079993,290.674194,14.807650,0.799930,-1293.950806,294.500488,0.000000
59.710003,65.249336,-1293.861938,-0.000112,0.003153,0.080079,290.243530,14.785711,0.800793,-1293.861938,294.500488,0.000000
60.050003,65.423607,-1293.906372,-0.000112,0.003158,0.080219,291.018738,14.825201,0.802186,-1293.906372,294.500488,0.000000
60.390003,65.343178,-1293.861938,-0.000121,0.003158,0.080219,290.660980,14.806976,0.802186,-1293.861938,294.500488,0.000000
60.730003,65.279121,-1293.817383,-0.000116,0.003159,0.080235,290.376038,14.792460,0.802352,-1293.817383,294.500488,0.000000
61.070004,65.255669,-1293.950806,-0.000121,0.003161,0.080288,290.271698,14.787147,0.802882,-1293.950806,294.500488,0.000000
61.410004,65.241890,-1293.817383,-0.000108,0.003161,0.080296,290.210419,14.784024,0.802958,-1293.817383,294.500488,0.000000
61.750004,65.246361,-1293.906372,-0.000103,0.003162,0.080323,290.230316,14.785036,0.803230,-1293.906372,294.500488,0.000000
62.090004,65.239662,-1293.861938,-0.000099,0.003164,0.080365,290.200500,14.783519,0.803654,-1293.861938,294.500488,0.000000
62.430004,65.210609,-1293.861938,-0.000108,0.003164,0.080365,290.071289,14.776936,0.803654,-1293.861938,294.500488,0.000000
62.770004,65.196083,-1293.906372,-0.000099,0.003165,0.080400,290.006653,14.773643,0.804003,-1293.906372,294.500488,0.000000
63.110004,65.156624,-1293.817383,-0.000103,0.003166,0.080418,289.831146,14.764703,0.804184,-1293.817383,294.500488,0.000000
63.450005,65.311897,-1293.906372,-0.000099,0.003169,0.080487,290.521820,14.799888,0.804865,-1293.906372,294.500488,0.000000
63.790005,65.286201,-1293.950806,-0.000095,0.003169,0.080487,290.407532,14.794065,0.804865,-1293.950806,294.500488,0.000000
64.130005,65.259758,-1293.861938,-0.000099,0.003170,0.080514,290.289886,14.788073,0.805138,-1293.861938,294.500488,0.000000
64.470001,65.230721,-1293.906372,-0.000091,0.003170,0.080521,290.160736,14.781493,0.805214,-1293.906372,294.500488,0.000000
64.810005,65.241890,-1293.861938,-0.000086,0.003171,0.080540,290.210419,14.784024,0.805395,-1293.861938,294.500488,0.000000
65.150002,65.193855,-1293.906372,-0.000099,0.003171,0.080549,289.996765,14.773139,0.805486,-1293.906372,294.500488,0.000000
65.490005,65.263863,-1293.906372,-0.000099,0.003173,0.080582,290.308167,14.789002,0.805819,-1293.906372,294.500488,0.000000
65.830002,65.236305,-1293.817383,-0.000103,0.003173,0.080600,290.185577,14.782759,0.806001,-1293.817383,294.500488,0.000000
66.170006,65.299232,-1293.950806,-0.000095,0.003175,0.080635,290.465485,14.797018,0.806349,-1293.950806,294.500488,0.000000
66.510002,65.302589,-1293.861938,-0.000099,0.003175,0.080635,290.480438,14.797779,0.806349,-1293.861938,294.500488,0.000000
66.850006,65.263481,-1293.906372,-0.000091,0.003175,0.080635,290.306458,14.788917,0.806349,-1293.906372,294.500488,0.000000
67.190002,65.239281,-1293.906372,-0.000086,0.003175,0.080644,290.198822,14.783432,0.806440,-1293.906372,294.500488,0.000000
67.530006,65.206520,-1293.950806,-0.000091,0.003176,0.080661,290.053101,14.776009,0.806607,-1293.950806,294.500488,0.000000
67.870003,65.203163,-1293.950806,-0.000099,0.003176,0.080677,290.038147,14.775248,0.806773,-1293.950806,294.500488,0.000000
68.210007,65.202049,-1293.906372,-0.000099,0.003177,0.080686,290.033203,14.774996,0.806864,-1293.906372,294.500488,0.000000
68.550003,65.175240,-1293.906372,-0.000099,0.003177,0.080686,289.913940,14.768920,0.806864,-1293.906372,294.500488,0.000000
68.890007,65.225136,-1293.861938,-0.000091,0.003178,0.080730,290.135895,14.780228,0.807303,-1293.861938,294.500488,0.000000
69.230003,65.254555,-1293.906372,-0.000099,0.003179,0.080739,290.266754,14.786894,0.807394,-1293.906372,294.500488,0.000000
69.570000,65.239281,-1293.950806,-0.000095,0.003179,0.080739,290.198822,14.783432,0.807394,-1293.950806,294.500488,0.000000
69.910004,65.210609,-1293.906372,-0.000086,0.003179,0.080739,290.071289,14.776936,0.807394,-1293.906372,294.500488,0.000000
70.250000,65.199806,-1293.861938,-0.000095,0.003179,0.080756,290.023224,14.774487,0.807560,-1293.861938,294.500488,0.000000
70.590004,65.218803,-1293.950806,-0.000078,0.003180,0.080773,290.107727,14.778792,0.807727,-1293.950806,294.500488,0.000000
70.930000,65.209862,-1293.906372,-0.000095,0.003180,0.080773,290.067963,14.776766,0.807727,-1293.906372,294.500488,0.000000
71.270004,65.180443,-1293.950806,-0.000091,0.003180,0.080773,289.937103,14.770100,0.807727,-1293.950806,294.500488,0.000000
71.610001,65.159218,-1293.906372,-0.000091,0.003180,0.080782,289.842682,14.765290,0.807818,-1293.906372,294.500488,0.000000
71.950005,65.124214,-1293.995361,-0.000095,0.003180,0.080782,289.686981,14.757359,0.807818,-1293.995361,294.500488,0.000000
72.290001,65.311897,-1293.906372,-0.000082,0.003184,0.080886,290.521820,14.799888,0.808862,-1293.906372,294.500488,0.000000
72.630005,65.373344,-1293.950806,-0.000091,0.003184,0.080886,290.795166,14.813812,0.808862,-1293.950806,294.500488,0.000000
72.970001,65.382652,-1293.950806,-0.000086,0.003184,0.080886,290.836548,14.815921,0.808862,-1293.950806,294.500488,0.000000
73.310005,65.354347,-1293.950806,-0.000095,0.003184,0.080886,290.710663,14.809507,0.808862,-1293.950806,294.500488,0.000000
73.650002,65.346901,-1294.039795,-0.000095,0.003184,0.080886,290.677521,14.807819,0.808862,-1294.039795,294.500488,0.000000
73.990005,65.325294,-1293.950806,-0.000091,0.003184,0.080886,290.581421,14.802923,0.808862,-1293.950806,294.500488,0.000000
74.330002,65.295143,-1293.995361,-0.000095,0.003184,0.080886,290.447296,14.796091,0.808862,-1293.995361,294.500488,0.000000
74.670006,65.285454,-1293.950806,-0.000095,0.003184,0.080886,290.404205,14.793895,0.808862,-1293.950806,294.500488,0.000000
75.010002,65.251198,-1293.906372,-0.000099,0.003184,0.080886,290.251831,14.786133,0.808862,-1293.906372,294.500488,0.000000
75.350006,65.229607,-1293.861938,-0.000091,0.003184,0.080886,290.155792,14.781240,0.808862,-1293.861938,294.500488,0.000000
75.690002,65.210976,-1293.906372,-0.000082,0.003185,0.080903,290.072906,14.777019,0.809029,-1293.906372,294.500488,0.000000
76.030006,65.187889,-1294.039795,-0.000078,0.003185,0.080903,289.970215,14.771787,0.809029,-1294.039795,294.500488,0.000000
76.370003,65.169655,-1293.950806,-0.000086,0.003185,0.080903,289.889099,14.767654,0.809029,-1293.950806,294.500488,0.000000
76.710007,65.152519,-1293.950806,-0.000086,0.003186,0.080912,289.812866,14.763772,0.809120,-1293.950806,294.500488,0.000000
77.050003,65.135384,-1293.995361,-0.000091,0.003186,0.080921,289.736664,14.759890,0.809211,-1293.995361,294.500488,0.000000
77.390007,65.126823,-1293.906372,-0.000082,0.003186,0.080930,289.698578,14.757949,0.809301,-1293.906372,294.500488,0.000000
77.730003,65.161079,-1293.950806,-0.000086,0.003187,0.080956,289.850952,14.765712,0.809559,-1293.950806,294.500488,0.000000
78.070007,65.162941,-1293.950806,-0.000086,0.003187,0.080956,289.859253,14.766133,0.809559,-1293.950806,294.500488,0.000000
78.410004,65.151772,-1293.906372,-0.000095,0.003188,0.080963,289.809540,14.763602,0.809634,-1293.906372,294.500488,0.000000
78.750000,65.179710,-1293.995361,-0.000078,0.003188,0.080982,289.933838,14.769934,0.809816,-1293.995361,294.500488,0.000000
79.090004,65.191612,-1293.950806,-0.000082,0.003188,0.080982,289.986786,14.772631,0.809816,-1293.950806,294.500488,0.000000
79.430000,65.167793,-1293.995361,-0.000082,0.003188,0.080982,289.880829,14.767234,0.809816,-1293.995361,294.500488,0.000000
79.770004,65.139488,-1293.995361,-0.000095,0.003188,0.080982,289.754913,14.760818,0.809816,-1293.995361,294.500488,0.000000
80.110001,65.125710,-1293.995361,-0.000065,0.003188,0.080982,289.693634,14.757697,0.809816,-1293.995361,294.500488,0.000000
80.450005,65.118629,-1293.995361,-0.000095,0.003191,0.081051,289.662140,14.756093,0.810513,-1293.995361,294.500488,0.000000
80.790001,65.561012,-1293.861938,-0.000065,0.003194,0.081121,291.629944,14.856339,0.811209,-1293.861938,294.500488,0.000000
81.130005,65.582603,-1293.950806,-0.000082,0.003194,0.081121,291.725983,14.861231,0.811209,-1293.950806,294.500488,0.000000
81.470001,65.580009,-1293.950806,-0.000086,0.003194,0.081121,291.714447,14.860642,0.811209,-1293.950806,294.500488,0.000000
81.810005,65.572929,-1293.906372,-0.000073,0.003194,0.081121,291.682953,14.859038,0.811209,-1293.906372,294.500488,0.000000
82.150002,65.573677,-1294.039795,-0.000095,0.003194,0.081121,291.686279,14.859208,0.811209,-1294.039795,294.500488,0.000000
82.490005,65.563988,-1293.950806,-0.000073,0.003194,0.081121,291.643188,14.857012,0.811209,-1293.950806,294.500488,0.000000
82.830002,65.564369,-1293.906372,-0.000086,0.003194,0.081121,291.644867,14.857099,0.811209,-1293.906372,294.500488,0.000000
83.170006,65.542015,-1293.995361,-0.000078,0.003194,0.081121,291.545441,14.852034,0.811209,-1293.995361,294.500488,0.000000
83.510002,65.528984,-1293.950806,-0.000082,0.003194,0.081121,291.487488,14.849080,0.811209,-1293.950806,294.500488,0.000000
83.850006,65.519676,-1293.995361,-0.000091,0.003194,0.081121,291.446075,14.846972,0.811209,-1293.995361,294.500488,0.000000
84.190002,65.499565,-1293.950806,-0.000078,0.003194,0.081121,291.356628,14.842414,0.811209,-1293.950806,294.500488,0.000000
84.530006,65.487282,-1293.950806,-0.000069,0.003194,0.081121,291.301971,14.839630,0.811209,-1293.950806,294.500488,0.000000
84.870003,65.459724,-1293.995361,-0.000078,0.003194,0.081121,291.179382,14.833385,0.811209,-1293.995361,294.500488,0.000000
85.210007,65.436272,-1293.995361,-0.000095,0.003194,0.081121,291.075073,14.828072,0.811209,-1293.995361,294.500488,0.000000
85.550003,65.402016,-1293.995361,-0.000073,0.003194,0.081121,290.922699,14.820309,0.811209,-1293.995361,294.500488,0.000000
85.890007,65.390099,-1293.950806,-0.000073,0.003194,0.081121,290.869690,14.817608,0.811209,-1293.950806,294.500488,0.000000
86.230003,65.365150,-1293.950806,-0.000091,0.003194,0.081128,290.758698,14.811954,0.811285,-1293.950806,294.500488,0.000000
86.570007,65.336845,-1293.995361,-0.000073,0.003194,0.081128,290.632812,14.805541,0.811285,-1293.995361,294.500488,0.000000
86.910004,65.334236,-1293.950806,-0.000086,0.003194,0.081128,290.621185,14.804950,0.811285,-1293.950806,294.500488,0.000000
87.250008,65.319344,-1293.995361,-0.000078,0.003194,0.081128,290.554962,14.801575,0.811285,-1293.995361,294.500488,0.000000
87.590004,65.307426,-1293.861938,-0.000086,0.003194,0.081128,290.501953,14.798875,0.811285,-1293.861938,294.500488,0.000000
87.930008,65.301842,-1293.995361,-0.000082,0.003194,0.081128,290.477112,14.797609,0.811285,-1293.995361,294.500488,0.000000
88.270004,65.275398,-1294.084351,-0.000073,0.003195,0.081147,290.359467,14.791616,0.811466,-1294.084351,294.500488,0.000000
88.610001,65.279503,-1294.039795,-0.000078,0.003195,0.081147,290.377716,14.792547,0.811466,-1294.039795,294.500488,0.000000
88.950005,65.266090,-1294.039795,-0.000078,0.003195,0.081147,290.318085,14.789508,0.811466,-1294.039795,294.500488,0.000000
89.290001,65.269814,-1293.995361,-0.000073,0.003195,0.081147,290.334625,14.790351,0.811466,-1293.995361,294.500488,0.000000
89.630005,65.251198,-1293.995361,-0.000086,0.003195,0.081147,290.251831,14.786133,0.811466,-1293.995361,294.500488,0.000000
89.970001,65.237801,-1294.039795,-0.000078,0.003195,0.081147,290.192230,14.783097,0.811466,-1294.039795,294.500488,0.000000
90.310005,65.240776,-1293.950806,-0.000091,0.003195,0.081147,290.205475,14.783772,0.811466,-1293.950806,294.500488,0.000000
90.650002,65.216942,-1294.039795,-0.000082,0.003195,0.081147,290.099457,14.778370,0.811466,-1294.039795,294.500488,0.000000
90.990005,65.209496,-1293.950806,-0.000073,0.003195,0.081147,290.066315,14.776683,0.811466,-1293.950806,294.500488,0.000000
91.330002,65.254921,-1293.995361,-0.000086,0.003197,0.081198,290.268372,14.786977,0.811981,-1293.995361,294.500488,0.000000
91.670006,65.271309,-1294.039795,-0.000078,0.003197,0.081198,290.341278,14.790690,0.811981,-1294.039795,294.500488,0.000000
92.010002,65.275780,-1293.995361,-0.000082,0.003197,0.081198,290.361176,14.791703,0.811981,-1293.995361,294.500488,0.000000
92.350006,65.271309,-1294.039795,-0.000086,0.003197,0.081198,290.341278,14.790690,0.811981,-1294.039795,294.500488,0.000000
92.690002,65.267952,-1293.995361,-0.000073,0.003197,0.081198,290.326355,14.789929,0.811981,-1293.995361,294.500488,0.000000
93.030006,65.278389,-1293.995361,-0.000086,0.003197,0.081198,290.372772,14.792295,0.811981,-1293.995361,294.500488,0.000000
93.370003,65.266090,-1294.039795,-0.000078,0.003197,0.081198,290.318085,14.789508,0.811981,-1294.039795,294.500488,0.000000
93.710007,65.252693,-1293.950806,-0.000073,0.003197,0.081198,290.258484,14.786471,0.811981,-1293.950806,294.500488,0.000000
94.050003,65.239662,-1294.128784,-0.000091,0.003197,0.081198,290.200500,14.783519,0.811981,-1294.128784,294.500488,0.000000
94.390007,65.227745,-1294.039795,-0.000082,0.003197,0.081198,290.147491,14.780818,0.811981,-1294.039795,294.500488,0.000000
94.730003,65.222160,-1294.039795,-0.000073,0.003197,0.081198,290.122650,14.779552,0.811981,-1294.039795,294.500488,0.000000
95.070007,65.220299,-1294.039795,-0.000082,0.003197,0.081198,290.114380,14.779131,0.811981,-1294.039795,294.500488,0.000000
95.410004,65.206139,-1293.950806,-0.000065,0.003197,0.081198,290.051392,14.775923,0.811981,-1293.950806,294.500488,0.000000
95.750008,65.201302,-1294.084351,-0.000082,0.003197,0.081198,290.029877,14.774826,0.811981,-1294.084351,294.500488,0.000000
96.090004,65.178963,-1293.950806,-0.000065,0.003197,0.081216,289.930511,14.769765,0.812163,-1293.950806,294.500488,0.000000
96.430008,65.178215,-1294.084351,-0.000052,0.003198,0.081224,289.927185,14.769595,0.812238,-1294.084351,294.500488,0.000000
96.770004,65.187157,-1294.039795,-0.000065,0.003198,0.081224,289.966949,14.771621,0.812238,-1294.039795,294.500488,0.000000
97.110008,65.177101,-1293.995361,-0.000065,0.003198,0.081224,289.922211,14.769342,0.812238,-1293.995361,294.500488,0.000000
97.450005,65.178963,-1294.039795,-0.000069,0.003198,0.081224,289.930511,14.769765,0.812238,-1294.039795,294.500488,0.000000
97.790001,65.171516,-1293.995361,-0.000060,0.003198,0.081224,289.897369,14.768077,0.812238,-1293.995361,294.500488,0.000000
98.130005,65.159966,-1294.084351,-0.000069,0.003198,0.081224,289.846008,14.765460,0.812238,-1294.084351,294.500488,0.000000
98.470001,65.157738,-1293.995361,-0.000060,0.003198,0.081224,289.836090,14.764955,0.812238,-1293.995361,294.500488,0.000000
98.810005,65.155876,-1294.039795,-0.000065,0.003198,0.081224,289.827820,14.764533,0.812238,-1294.039795,294.500488,0.000000
99.150002,65.455635,-1294.084351,-0.000073,0.003203,0.081354,291.161194,14.832459,0.813540,-1294.084351,294.500488,0.000000
99.490005,65.527122,-1293.950806,-0.000065,0.003203,0.081354,291.479187,14.848658,0.813540,-1293.950806,294.500488,0.000000
99.830002,65.547981,-1294.039795,-0.000060,0.003203,0.081354,291.571991,14.853385,0.813540,-1294.039795,294.500488,0.000000
100.170006,65.550591,-1294.039795,-0.000056,0.003203,0.081354,291.583588,14.853976,0.813540,-1294.039795,294.500488,0.000000
100.510002,65.562508,-1294.039795,-0.000073,0.003203,0.081354,291.636597,14.856677,0.813540,-1294.039795,294.500488,0.000000
100.850006,65.563240,-1294.084351,-0.000060,0.003203,0.081346,291.639862,14.856842,0.813465,-1294.084351,294.500488,0.000000
101.190002,65.574425,-1293.995361,-0.000065,0.003203,0.081346,291.689606,14.859378,0.813465,-1293.995361,294.500488,0.000000
101.530006,65.561012,-1294.039795,-0.000056,0.003203,0.081346,291.629944,14.856339,0.813465,-1294.039795,294.500488,0.000000
101.870003,65.565102,-1294.039795,-0.000056,0.003203,0.081346,291.648132,14.857265,0.813465,-1294.039795,294.500488,0.000000
102.210007,65.551704,-1294.039795,-0.000052,0.003203,0.081346,291.588531,14.854228,0.813465,-1294.039795,294.500488,0.000000
102.550003,65.540154,-1294.084351,-0.000065,0.003203,0.081346,291.537170,14.851611,0.813465,-1294.084351,294.500488,0.000000
102.890007,65.542763,-1293.995361,-0.000060,0.003203,0.081346,291.548767,14.852202,0.813465,-1293.995361,294.500488,0.000000
103.230003,65.521538,-1293.995361,-0.000065,0.003203,0.081346,291.454346,14.847392,0.813465,-1293.995361,294.500488,0.000000
103.570007,65.517067,-1294.039795,-0.000043,0.003203,0.081346,291.434479,14.846379,0.813465,-1294.039795,294.500488,0.000000
103.910004,65.517815,-1294.039795,-0.000060,0.003203,0.081346,291.437805,14.846549,0.813465,-1294.039795,294.500488,0.000000
104.250008,65.507393,-1294.084351,-0.000056,0.003203,0.081346,291.391449,14.844188,0.813465,-1294.084351,294.500488,0.000000
104.590004,65.510368,-1294.128784,-0.000060,0.003203,0.081346,291.404663,14.844861,0.813465,-1294.128784,294.500488,0.000000
104.930008,65.495842,-1294.084351,-0.000069,0.003203,0.081346,291.340057,14.841571,0.813465,-1294.084351,294.500488,0.000000
105.270004,65.483925,-1294.128784,-0.000056,0.003203,0.081346,291.287048,14.838870,0.813465,-1294.128784,294.500488,0.000000
105.610008,65.480202,-1293.950806,-0.000065,0.003203,0.081346,291.270477,14.838026,0.813465,-1293.950806,294.500488,0.000000
105.950005,65.469414,-1294.128784,-0.000065,0.003203,0.081346,291.222504,14.835581,0.813465,-1294.128784,294.500488,0.000000
106.290009,65.448555,-1293.950806,-0.000056,0.003203,0.081346,291.129700,14.830854,0.813465,-1293.950806,294.500488,0.000000
106.630005,65.416908,-1293.995361,-0.000069,0.003203,0.081346,290.988953,14.823683,0.813465,-1293.995361,294.500488,0.000000
106.970009,65.415413,-1293.995361,-0.000056,0.003203,0.081354,290.982300,14.823344,0.813540,-1293.995361,294.500488,0.000000
107.310005,65.389351,-1293.950806,-0.000065,0.003203,0.081354,290.866364,14.817439,0.813540,-1293.950806,294.500488,0.000000
107.650002,65.383385,-1294.128784,-0.000060,0.003203,0.081354,290.839813,14.816087,0.813540,-1294.128784,294.500488,0.000000
107.990005,65.366631,-1293.995361,-0.000060,0.003203,0.081354,290.765289,14.812291,0.813540,-1293.995361,294.500488,0.000000
108.330002,65.354347,-1294.084351,-0.000069,0.003203,0.081354,290.710663,14.809507,0.813540,-1294.084351,294.500488,0.000000
108.670006,65.350243,-1293.995361,-0.000060,0.003203,0.081354,290.692383,14.808577,0.813540,-1293.995361,294.500488,0.000000
109.010002,65.340569,-1293.950806,-0.000073,0.003203,0.081354,290.649353,14.806384,0.813540,-1293.950806,294.500488,0.000000
109.350006,65.326790,-1293.995361,-0.000065,0.003203,0.081354,290.588074,14.803262,0.813540,-1293.995361,294.500488,0.000000
109.690002,65.318977,-1293.995361,-0.000056,0.003203,0.081354,290.553314,14.801492,0.813540,-1293.995361,294.500488,0.000000
110.030006,65.318230,-1293.995361,-0.000065,0.003203,0.081354,290.549988,14.801322,0.813540,-1293.995361,294.500488,0.000000
110.370003,65.291786,-1294.039795,-0.000056,0.003203,0.081354,290.432373,14.795330,0.813540,-1294.039795,294.500488,0.000000
110.710007,65.293648,-1294.039795,-0.000060,0.003203,0.081354,290.440643,14.795753,0.813540,-1294.039795,294.500488,0.000000
111.050003,65.299232,-1294.039795,-0.000065,0.003203,0.081354,290.465485,14.797018,0.813540,-1294.039795,294.500488,0.000000
111.390007,65.279121,-1294.084351,-0.000056,0.003203,0.081354,290.376038,14.792460,0.813540,-1294.084351,294.500488,0.000000
111.730003,65.280617,-1293.950806,-0.000052,0.003203,0.081354,290.382690,14.792799,0.813540,-1293.950806,294.500488,0.000000
112.070007,65.268333,-1293.995361,-0.000056,0.003203,0.081354,290.328033,14.790016,0.813540,-1293.995361,294.500488,0.000000
112.410004,65.256783,-1293.950806,-0.000056,0.003203,0.081354,290.276672,14.787398,0.813540,-1293.950806,294.500488,0.000000
112.750008,65.254555,-1294.084351,-0.000073,0.003203,0.081354,290.266754,14.786894,0.813540,-1294.084351,294.500488,0.000000
113.090004,65.252693,-1293.995361,-0.000060,0.003203,0.081354,290.258484,14.786471,0.813540,-1293.995361,294.500488,0.000000
113.430008,65.231834,-1294.039795,-0.000065,0.003203,0.081354,290.165680,14.781745,0.813540,-1294.039795,294.500488,0.000000
113.770004,65.230721,-1294.039795,-0.000060,0.003203,0.081354,290.160736,14.781493,0.813540,-1294.039795,294.500488,0.000000
114.110008,65.225136,-1294.039795,-0.000065,0.003203,0.081354,290.135895,14.780228,0.813540,-1294.039795,294.500488,0.000000
114.450005,65.219551,-1294.084351,-0.000056,0.003203,0.081363,290.111053,14.778962,0.813631,-1294.084351,294.500488,0.000000
114.790009,65.220665,-1293.950806,-0.000056,0.003204,0.081380,290.115997,14.779214,0.813798,-1293.950806,294.500488,0.000000
115.130005,65.231087,-1293.995361,-0.000073,0.003204,0.081389,290.162354,14.781575,0.813889,-1293.995361,294.500488,0.000000
115.470009,65.237801,-1294.084351,-0.000065,0.003204,0.081389,290.192230,14.783097,0.813889,-1294.084351,294.500488,0.000000
115.810005,65.230339,-1293.995361,-0.000043,0.003204,0.081389,290.159027,14.781406,0.813889,-1293.995361,294.500488,0.000000
116.150009,65.205391,-1294.039795,-0.000073,0.003198,0.081233,290.048065,14.775753,0.812329,-1294.039795,0.081284,0.000000
116.490005,65.147301,-1293.950806,-0.000052,0.003188,0.080963,289.789673,14.762589,0.809634,-1293.950806,0.080721,0.000000
116.830002,65.086617,-1293.950806,-0.000069,0.003175,0.080652,289.519745,14.748837,0.806516,-1293.950806,0.080149,0.000000
117.170006,65.053841,-1294.084351,-0.000060,0.003152,0.080063,289.373932,14.741411,0.800626,-1294.084351,0.079586,0.000000
117.510002,65.019585,-1293.995361,-0.000073,0.003130,0.079490,289.221558,14.733649,0.794904,-1293.995361,0.079021,0.000000
117.850006,65.018471,-1294.084351,-0.000056,0.003115,0.079109,289.216614,14.733397,0.791088,-1294.084351,0.078449,0.000000
118.190002,65.006172,-1293.995361,-0.000043,0.003092,0.078537,289.161896,14.730610,0.785366,-1293.995361,0.077886,0.000000
118.530006,64.968941,-1293.995361,-0.000056,0.003069,0.077946,288.996277,14.722173,0.779461,-1293.995361,0.077313,0.000000
118.870003,64.934303,-1293.995361,-0.000052,0.003049,0.077434,288.842194,14.714324,0.774344,-1293.995361,0.076750,0.000000
119.210007,64.925743,-1294.039795,-0.000065,0.003017,0.076620,288.804138,14.712383,0.766199,-1294.039795,0.076185,0.000000
119.550003,64.871376,-1294.084351,-0.000056,0.002997,0.076134,288.562286,14.700065,0.761339,-1294.084351,0.075613,0.000000
119.890007,64.808815,-1294.039795,-0.000052,0.002982,0.075734,288.283997,14.685887,0.757342,-1294.039795,0.075050,0.000000
120.230003,64.419685,-1294.084351,-0.000060,0.002961,0.075197,286.553070,14.597710,0.751968,-1294.084351,0.074487,0.000000
120.570007,63.785545,-1294.084351,-0.000060,0.002941,0.074711,283.732269,14.454011,0.747108,-1294.084351,0.073913,0.000000
120.910004,62.963715,-1294.084351,-0.000030,0.002922,0.074226,280.076599,14.267782,0.742263,-1294.084351,0.073350,0.000000
121.250008,61.835426,-1294.084351,-0.000017,0.002900,0.073654,275.057709,14.012108,0.736541,-1294.084351,0.072787,0.000000
121.590004,60.569359,-1294.039795,-0.000022,0.002879,0.073115,269.425964,13.725212,0.731151,-1294.039795,0.072214,0.000000
121.930008,58.641586,-1293.995361,-0.000026,0.002853,0.072466,260.850800,13.288374,0.724656,-1293.995361,0.071650,0.000000
122.270004,57.499893,-1294.173218,-0.000022,0.002839,0.072101,255.772293,13.029662,0.721007,-1294.173218,0.071086,0.000000
122.610008,55.430992,-1293.995361,-0.000026,0.002816,0.071519,246.569366,12.560843,0.715194,-1293.995361,0.070514,0.000000
122.950005,53.217979,-1293.950806,-0.000030,0.002790,0.070870,236.725403,12.059366,0.708699,-1293.950806,0.069951,0.000000
123.290009,50.704094,-1294.039795,-0.000026,0.002765,0.070237,225.543076,11.489712,0.702371,-1294.039795,0.069386,0.000000
123.630005,48.631096,-1293.995361,-0.000030,0.002746,0.069760,216.321915,11.019963,0.697602,-1293.995361,0.068814,0.000000
123.970009,47.254807,-1294.084351,-0.000022,0.002735,0.069482,210.199875,10.708092,0.694816,-1294.084351,0.068251,0.000000
124.310005,44.713371,-1293.906372,-0.000039,0.002710,0.068823,198.895004,10.132195,0.688230,-1293.906372,0.067688,0.000000
124.650009,41.570915,-1294.084351,-0.000039,0.002682,0.068111,184.916672,9.420104,0.681115,-1294.084351,0.067115,0.000000
124.990005,38.851479,-1294.039795,-0.000034,0.002658,0.067504,172.820007,8.803870,0.675044,-1294.039795,0.066551,0.000000
125.330009,36.085129,-1294.039795,-0.000056,0.002633,0.066872,160.514664,8.177007,0.668715,-1294.039795,0.065987,0.000000
125.670006,34.001328,-1294.084351,-0.000047,0.002614,0.066386,151.245453,7.704811,0.663855,-1294.084351,0.065415,0.000000
126.010010,31.463982,-1294.039795,-0.000034,0.002590,0.065797,139.958786,7.129840,0.657966,-1294.039795,0.064850,0.000000
126.350006,29.113937,-1294.039795,-0.000056,0.002568,0.065233,129.505264,6.597312,0.652334,-1294.039795,0.064278,0.000000
126.690002,26.372162,-1294.128784,-0.000034,0.002543,0.064599,117.309235,5.976017,0.645991,-1294.128784,0.063715,0.000000
127.030006,24.621643,-1294.039795,-0.000065,0.002524,0.064115,109.522537,5.579344,0.641146,-1294.039795,0.063152,0.000000
127.370003,22.117065,-1294.128784,-0.000043,0.002504,0.063603,98.381622,5.011799,0.636029,-1294.128784,0.062579,0.000000
127.710007,18.662193,-1293.995361,-0.000065,0.002471,0.062770,83.013580,4.228913,0.627702,-1293.995361,0.062015,0.000000
128.050003,17.467247,-1293.995361,-0.000078,0.002463,0.062554,77.698196,3.958135,0.625537,-1293.995361,0.061452,0.000000
128.389999,14.667381,-1294.084351,-0.000082,0.002435,0.061859,65.243767,3.323676,0.618588,-1294.084351,0.060879,0.000000
128.730011,12.960793,-1294.084351,-0.000086,0.002420,0.061468,57.652485,2.936958,0.614682,-1294.084351,0.060316,0.000000
129.070007,10.785393,-1294.039795,-0.000073,0.002400,0.060949,47.975822,2.444005,0.609489,-1294.039795,0.059751,0.000000
129.410004,7.716301,-1294.084351,-0.000069,0.002372,0.060256,34.323822,1.748539,0.602555,-1294.084351,0.059179,0.000000
129.750000,5.079903,-1294.039795,-0.000082,0.002346,0.059595,22.596535,1.151122,0.595954,-1294.039795,0.058616,0.000000
130.090012,3.321938,-1294.128784,-0.000091,0.002329,0.059144,14.776716,0.752762,0.591443,-1294.128784,0.058053,0.000000
130.430008,0.922737,-1294.039795,-0.000091,0.002303,0.058486,4.104540,0.209095,0.584857,-1294.039795,0.057480,0.000000
130.770004,-0.243530,-1294.128784,-0.000103,0.002286,0.058069,-1.083277,-0.055185,0.580694,-1294.128784,0.056916,0.000000
131.110001,-0.418175,-1294.084351,-0.000121,0.002259,0.057367,-1.860134,-0.094760,0.573669,-1294.084351,0.056353,0.000000
131.450012,0.025322,-1294.084351,-0.000168,0.002239,0.056864,0.112638,0.005738,0.568643,-1294.084351,0.055780,0.000000
131.790009,0.103889,-1294.084351,-0.000185,0.002218,0.056343,0.462123,0.023542,0.563435,-1294.084351,0.055216,0.000000
132.130005,0.124748,-1294.039795,-0.000220,0.002194,0.055720,0.554908,0.028268,0.557197,-1294.039795,0.054652,0.000000
132.470001,0.138153,-1294.173218,-0.000246,0.002174,0.055216,0.614536,0.031306,0.552156,-1294.173218,0.054080,0.000000
132.810013,0.105011,-1294.084351,-0.000276,0.002154,0.054713,0.467112,0.023796,0.547129,-1294.084351,0.053517,0.000000
133.150009,0.083786,-1294.084351,-0.000336,0.002123,0.053915,0.372699,0.018986,0.539151,-1294.084351,0.052952,0.000000
133.490005,0.058838,-1294.039795,-0.000358,0.002107,0.053517,0.261724,0.013333,0.535169,-1294.039795,0.052380,0.000000
133.830002,0.051018,-1294.084351,-0.000384,0.002083,0.052901,0.226938,0.011561,0.529007,-1294.084351,0.051817,0.000000
134.170013,0.044685,-1294.039795,-0.000444,0.002055,0.052189,0.198770,0.010126,0.521892,-1294.039795,0.051254,0.000000
134.510010,0.029793,-1294.039795,-0.000470,0.002033,0.051643,0.132525,0.006751,0.516426,-1294.039795,0.050681,0.000000
134.850006,-0.008194,-1294.039795,-0.000517,0.002004,0.050898,-0.036449,-0.001857,0.508978,-1294.039795,0.050117,0.000000
135.190002,-0.014519,-1294.128784,-0.000548,0.001988,0.050498,-0.064583,-0.003290,0.504981,-1294.128784,0.049544,0.000000
135.530014,0.018250,-1294.084351,-0.000595,0.001966,0.049935,0.081178,0.004135,0.499349,-1294.084351,0.048981,0.000000
135.800003,0.063301,-1294.128784,-0.000608,0.001964,0.049883,0.281577,0.014344,0.498834,-1294.128784,0.049744,0.000000