File: Data/Sima compression/P2-15-1_10302024_171522.csv
Time (sec),S:Load (lbs),S:HL1 (DIM),S:LVDT (in),S:Position (in),Ch:Position (mm),Ch:Load (N),Ch:Stress (MPa),Ch:Strain (mm/mm),Ch:HL1 (DIM),Set Point (),Cycles ()
0.210000,-0.020111,-1293.772949,-0.004557,-0.004542,-0.115376,-0.089459,-0.004557,-1.153757,-1293.772949,-0.115168,0.000000
0.510000,0.008194,-1293.861938,-0.004575,-0.004487,-0.113971,0.036449,0.001857,-1.139708,-1293.861938,-0.113226,0.000000
0.810000,-0.013405,-1293.817383,-0.004475,-0.004304,-0.109323,-0.059628,-0.003038,-1.093229,-1293.817383,-0.108230,0.000000
1.110000,0.049156,-1293.817383,-0.004255,-0.004109,-0.104380,0.218658,0.011139,-1.043798,-1293.817383,-0.103217,0.000000
1.410000,0.006332,-1293.861938,-0.004070,-0.003910,-0.099323,0.028168,0.001435,-0.993232,-1293.861938,-0.098223,0.000000
1.710000,0.030533,-1293.772949,-0.003885,-0.003727,-0.094675,0.135817,0.006919,-0.946754,-1293.772949,-0.093226,0.000000
2.010000,-0.000748,-1293.817383,-0.003660,-0.003518,-0.089351,-0.003326,-0.000169,-0.893508,-1293.817383,-0.088232,0.000000
2.310000,-0.014893,-1293.772949,-0.003488,-0.003327,-0.084511,-0.066245,-0.003375,-0.845106,-1293.772949,-0.083236,0.000000
2.610000,-0.021225,-1293.861938,-0.003260,-0.003125,-0.079369,-0.094413,-0.004810,-0.793692,-1293.861938,-0.078241,0.000000
2.910000,0.291199,-1293.817383,-0.003182,0.000014,0.000347,1.295317,0.065987,0.003467,-1293.817383,0.000416,0.000000
3.210000,0.272949,-1293.861938,-0.003178,0.000013,0.000338,1.214139,0.061851,0.003376,-1293.861938,0.000416,0.000000
3.510000,0.247627,-1293.817383,-0.003178,0.000014,0.000347,1.101501,0.056113,0.003467,-1293.817383,0.000833,0.000000
3.810000,0.288589,-1293.861938,-0.003186,0.000020,0.000512,1.283710,0.065395,0.005117,-1293.861938,0.001335,0.000000
4.110000,0.443123,-1293.817383,-0.003173,0.000038,0.000972,1.971109,0.100413,0.009720,-1293.817383,0.001838,0.000000
4.410000,0.685539,-1293.861938,-0.003156,0.000054,0.001370,3.049431,0.155345,0.013701,-1293.861938,0.002333,0.000000
4.710000,1.111534,-1293.817383,-0.003134,0.000077,0.001961,4.944351,0.251877,0.019606,-1293.817383,0.002836,0.000000
5.010000,1.476830,-1293.817383,-0.003122,0.000092,0.002342,6.569266,0.334654,0.023421,-1293.817383,0.003338,0.000000
5.310000,1.875267,-1293.861938,-0.003113,0.000106,0.002696,8.341604,0.424942,0.026964,-1293.861938,0.003833,0.000000
5.610000,2.781998,-1293.817383,-0.003104,0.000139,0.003521,12.374944,0.630410,0.035215,-1293.817383,0.004336,0.000000
5.910000,3.189743,-1293.906372,-0.003074,0.000154,0.003920,14.188685,0.722806,0.039196,-1293.906372,0.004839,0.000000
6.210001,3.672340,-1293.906372,-0.003074,0.000171,0.004336,16.335386,0.832164,0.043360,-1293.906372,0.005334,0.000000
6.510000,4.258827,-1293.861938,-0.003057,0.000188,0.004769,18.944210,0.965064,0.047690,-1293.861938,0.005836,0.000000
6.810000,5.221031,-1293.906372,-0.003022,0.000213,0.005411,23.224306,1.183103,0.054109,-1293.906372,0.006331,0.000000
7.110000,5.469032,-1293.817383,-0.003018,0.000224,0.005689,24.327471,1.239300,0.056895,-1293.817383,0.006834,0.000000
7.410000,6.913841,-1293.817383,-0.003001,0.000258,0.006548,30.754301,1.566699,0.065479,-1293.817383,0.007337,0.000000
7.710001,7.472397,-1293.861938,-0.002988,0.000274,0.006964,33.238880,1.693269,0.069642,-1293.861938,0.007832,0.000000
8.010000,8.188095,-1293.861938,-0.002966,0.000292,0.007423,36.422466,1.855449,0.074229,-1293.861938,0.008334,0.000000
8.310000,8.754852,-1293.861938,-0.002945,0.000309,0.007848,38.943527,1.983878,0.078484,-1293.861938,0.008837,0.000000
8.610001,9.893562,-1293.861938,-0.002932,0.000332,0.008421,44.008762,2.241913,0.084206,-1293.861938,0.009332,0.000000
8.910001,10.437973,-1293.906372,-0.002923,0.000347,0.008820,46.430424,2.365278,0.088203,-1293.906372,0.009835,0.000000
9.210000,11.202080,-1293.861938,-0.002915,0.000366,0.009288,49.829338,2.538428,0.092881,-1293.861938,0.010337,0.000000
9.510000,12.416016,-1293.906372,-0.002893,0.000392,0.009965,55.229195,2.813509,0.099649,-1293.906372,0.010831,0.000000
9.810000,13.097458,-1293.861938,-0.002880,0.000409,0.010381,58.260403,2.967927,0.103812,-1293.861938,0.011335,0.000000
10.110001,13.817253,-1293.906372,-0.002850,0.000429,0.010900,61.462212,3.131034,0.109005,-1293.906372,0.011838,0.000000
10.410001,14.729935,-1293.906372,-0.002833,0.000451,0.011456,65.522018,3.337851,0.114561,-1293.906372,0.012331,0.000000
10.710000,15.460907,-1293.861938,-0.002833,0.000469,0.011916,68.773552,3.503492,0.119164,-1293.861938,0.012835,0.000000
11.010000,15.556229,-1293.861938,-0.002820,0.000477,0.012124,69.197563,3.525092,0.121238,-1293.861938,0.013338,0.000000
11.310000,16.387367,-1293.906372,-0.002802,0.000497,0.012635,72.894653,3.713430,0.126355,-1293.906372,0.013832,0.000000
11.610001,17.880211,-1293.906372,-0.002777,0.000530,0.013450,79.535149,4.051714,0.134500,-1293.906372,0.014336,0.000000
11.910001,18.264496,-1293.906372,-0.002764,0.000546,0.013875,81.244537,4.138794,0.138754,-1293.906372,0.014838,0.000000
12.210001,18.615273,-1293.950806,-0.002742,0.000561,0.014240,82.804871,4.218281,0.142403,-1293.950806,0.015332,0.000000
12.510000,19.741699,-1293.950806,-0.002729,0.000588,0.014934,87.815460,4.473533,0.149337,-1293.950806,0.015836,0.000000
12.810000,20.058212,-1293.906372,-0.002721,0.000602,0.015289,89.223381,4.545256,0.152895,-1293.906372,0.016339,0.000000
13.110001,20.371384,-1293.906372,-0.002690,0.000617,0.015680,90.616440,4.616221,0.156801,-1293.906372,0.016832,0.000000
13.410001,21.678780,-1293.861938,-0.002673,0.000645,0.016390,96.432030,4.912481,0.163901,-1293.861938,0.017336,0.000000
13.710001,21.998650,-1293.906372,-0.002634,0.000663,0.016832,97.854881,4.984965,0.168322,-1293.906372,0.017839,0.000000
14.010000,22.518478,-1293.861938,-0.002621,0.000683,0.017336,100.167198,5.102760,0.173363,-1293.861938,0.018333,0.000000
14.310000,23.173859,-1293.906372,-0.002626,0.000704,0.017890,103.082474,5.251271,0.178904,-1293.906372,0.018837,0.000000
14.610001,23.646767,-1293.861938,-0.002604,0.000724,0.018393,105.186073,5.358434,0.183931,-1293.861938,0.019339,0.000000
14.910001,24.066803,-1293.861938,-0.002565,0.000742,0.018844,107.054489,5.453615,0.188442,-1293.861938,0.019833,0.000000
15.210001,24.064941,-1293.817383,-0.002557,0.000760,0.019304,107.046204,5.453194,0.193045,-1293.817383,0.020337,0.000000
15.510001,25.074074,-1293.861938,-0.002518,0.000781,0.019842,111.535049,5.681867,0.198419,-1293.861938,0.020840,0.000000
15.810000,25.420753,-1293.861938,-0.002501,0.000802,0.020379,113.077156,5.760425,0.203794,-1293.861938,0.021333,0.000000
16.110001,25.527992,-1293.861938,-0.002471,0.000817,0.020761,113.554184,5.784726,0.207609,-1293.861938,0.021837,0.000000
16.410000,26.236992,-1293.861938,-0.002462,0.000839,0.021317,116.707970,5.945387,0.213165,-1293.861938,0.022340,0.000000
16.710001,26.370300,-1293.861938,-0.002436,0.000858,0.021793,117.300957,5.975595,0.217934,-1293.861938,0.022834,0.000000
17.010000,26.400459,-1293.772949,-0.002423,0.000871,0.022114,117.435104,5.982430,0.221144,-1293.772949,0.023338,0.000000
17.310001,27.629662,-1293.861938,-0.002389,0.000900,0.022861,122.902870,6.260971,0.228608,-1293.861938,0.023840,0.000000
17.610001,27.842659,-1293.817383,-0.002367,0.000920,0.023371,123.850334,6.309237,0.233710,-1293.817383,0.024334,0.000000
17.910002,28.056030,-1293.817383,-0.002333,0.000941,0.023910,124.799454,6.357587,0.239099,-1293.817383,0.024838,0.000000
18.210001,28.029221,-1293.906372,-0.002302,0.000956,0.024291,124.680199,6.351512,0.242915,-1293.906372,0.025341,0.000000
18.510000,28.751991,-1293.861938,-0.002298,0.000982,0.024950,127.895248,6.515295,0.249500,-1293.861938,0.025834,0.000000
18.810001,28.645500,-1293.861938,-0.002264,0.000996,0.025306,127.421547,6.491163,0.253058,-1293.861938,0.026338,0.000000
19.110001,28.110023,-1293.906372,-0.002238,0.001010,0.025662,125.039627,6.369823,0.256616,-1293.906372,0.026841,0.000000
19.410002,29.445351,-1293.906372,-0.002225,0.001039,0.026399,130.979462,6.672412,0.263989,-1293.906372,0.027335,0.000000
19.710001,29.559296,-1293.861938,-0.002195,0.001061,0.026953,131.486313,6.698232,0.269530,-1293.861938,0.027837,0.000000
20.010000,29.551476,-1293.861938,-0.002173,0.001077,0.027344,131.451523,6.696460,0.273436,-1293.861938,0.028332,0.000000
20.310001,29.711227,-1293.861938,-0.002143,0.001096,0.027837,132.162140,6.732660,0.278371,-1293.861938,0.028835,0.000000
20.610001,29.711967,-1293.817383,-0.002113,0.001110,0.028185,132.165436,6.732828,0.281854,-1293.817383,0.029337,0.000000
20.910002,29.987900,-1293.861938,-0.002104,0.001129,0.028679,133.392838,6.795355,0.286789,-1293.861938,0.029833,0.000000
21.210001,31.186569,-1293.817383,-0.002065,0.001161,0.029495,138.724792,7.066978,0.294949,-1293.817383,0.030335,0.000000
21.510000,30.853668,-1293.861938,-0.002039,0.001174,0.029823,137.243973,6.991541,0.298235,-1293.861938,0.030838,0.000000
21.810001,31.068527,-1293.861938,-0.002009,0.001194,0.030335,138.199707,7.040229,0.303352,-1293.861938,0.031333,0.000000
22.110001,31.544418,-1293.861938,-0.001979,0.001216,0.030891,140.316574,7.148067,0.308908,-1293.861938,0.031836,0.000000
22.410002,31.802841,-1293.772949,-0.001957,0.001235,0.031377,141.466110,7.206627,0.313768,-1293.772949,0.032338,0.000000
22.710001,31.831886,-1293.817383,-0.001936,0.001251,0.031766,141.595306,7.213209,0.317659,-1293.817383,0.032833,0.000000
23.010000,32.342041,-1293.861938,-0.001910,0.001275,0.032373,143.864578,7.328811,0.323730,-1293.861938,0.033336,0.000000
23.310001,32.797447,-1293.817383,-0.001893,0.001294,0.032877,145.890335,7.432008,0.328771,-1293.817383,0.033838,0.000000
23.610001,32.799683,-1293.861938,-0.001867,0.001313,0.033354,145.900269,7.432515,0.333540,-1293.861938,0.034334,0.000000
23.910002,33.017151,-1293.817383,-0.001850,0.001332,0.033831,146.867615,7.481793,0.338309,-1293.817383,0.034836,0.000000
24.210001,33.168701,-1293.817383,-0.001824,0.001349,0.034264,147.541748,7.516135,0.342639,-1293.817383,0.035339,0.000000
24.510000,33.360474,-1293.817383,-0.001802,0.001365,0.034671,148.394791,7.559591,0.346712,-1293.817383,0.035834,0.000000
24.810001,33.282654,-1293.817383,-0.001759,0.001379,0.035018,148.048645,7.541957,0.350178,-1293.817383,0.036337,0.000000
25.110001,35.485603,-1293.772949,-0.001742,0.001418,0.036016,157.847855,8.041153,0.360155,-1293.772949,0.036839,0.000000
25.410002,35.077110,-1293.728516,-0.001712,0.001433,0.036397,156.030777,7.948587,0.363971,-1293.728516,0.037334,0.000000
25.710001,35.008598,-1293.772949,-0.001703,0.001448,0.036771,155.726028,7.933062,0.367710,-1293.772949,0.037837,0.000000
26.010002,34.923698,-1293.817383,-0.001690,0.001466,0.037248,155.348373,7.913823,0.372479,-1293.817383,0.038339,0.000000
26.310001,35.711639,-1293.772949,-0.001656,0.001487,0.037776,158.853302,8.092373,0.377763,-1293.772949,0.038835,0.000000
26.610001,35.917931,-1293.817383,-0.001630,0.001504,0.038193,159.770935,8.139119,0.381926,-1293.817383,0.039337,0.000000
26.910002,35.499756,-1293.772949,-0.001617,0.001514,0.038444,157.910797,8.044360,0.384439,-1293.772949,0.039840,0.000000
27.210001,37.242088,-1293.772949,-0.001582,0.001549,0.039355,165.661087,8.439178,0.393553,-1293.772949,0.040335,0.000000
27.510002,37.398109,-1293.861938,-0.001552,0.001567,0.039814,166.355103,8.474533,0.398141,-1293.861938,0.040838,0.000000
27.810001,37.352684,-1293.772949,-0.001535,0.001585,0.040256,166.153030,8.464239,0.402561,-1293.772949,0.041340,0.000000
28.110001,38.380798,-1293.728516,-0.001505,0.001611,0.040907,170.726318,8.697214,0.409071,-1293.728516,0.041835,0.000000
28.410002,37.998001,-1293.817383,-0.001492,0.001619,0.041133,169.023544,8.610470,0.411327,-1293.817383,0.042338,0.000000
28.710001,39.146400,-1293.772949,-0.001462,0.001649,0.041896,174.131882,8.870701,0.418958,-1293.772949,0.042840,0.000000
29.010002,39.369820,-1293.861938,-0.001440,0.001668,0.042356,175.125702,8.921329,0.423560,-1293.861938,0.043336,0.000000
29.310001,39.713898,-1293.728516,-0.001427,0.001688,0.042866,176.656235,8.999298,0.428662,-1293.728516,0.043838,0.000000
29.610001,39.745178,-1293.817383,-0.001401,0.001704,0.043283,176.795380,9.006386,0.432825,-1293.817383,0.044341,0.000000
29.910002,40.723022,-1293.817383,-0.001362,0.001728,0.043890,181.145050,9.227968,0.438896,-1293.817383,0.044836,0.000000
30.210001,40.688019,-1293.817383,-0.001350,0.001744,0.044289,180.989349,9.220037,0.442893,-1293.817383,0.045339,0.000000
30.510002,41.106194,-1293.861938,-0.001315,0.001762,0.044748,182.849487,9.314796,0.447481,-1293.861938,0.045841,0.000000
30.810001,42.001007,-1293.817383,-0.001306,0.001787,0.045382,186.829803,9.517565,0.453824,-1293.817383,0.046336,0.000000
31.110001,42.650421,-1293.906372,-0.001285,0.001806,0.045885,189.718552,9.664723,0.458850,-1293.906372,0.046839,0.000000
31.410002,42.683197,-1293.817383,-0.001259,0.001824,0.046318,189.864349,9.672151,0.463180,-1293.817383,0.047341,0.000000
31.710001,43.271912,-1293.772949,-0.001237,0.001845,0.046865,192.483078,9.805555,0.468646,-1293.772949,0.047837,0.000000
32.010002,43.540024,-1293.861938,-0.001224,0.001860,0.047246,193.675705,9.866311,0.472461,-1293.861938,0.048339,0.000000
32.310001,43.629395,-1293.861938,-0.001199,0.001875,0.047628,194.073242,9.886561,0.476276,-1293.861938,0.048842,0.000000
32.610001,44.287750,-1293.861938,-0.001186,0.001897,0.048183,197.001755,10.035748,0.481832,-1293.861938,0.049337,0.000000
32.910000,45.170639,-1293.772949,-0.001160,0.001920,0.048756,200.929031,10.235813,0.487555,-1293.772949,0.049839,0.000000
33.210003,45.865486,-1293.861938,-0.001134,0.001942,0.049328,204.019867,10.393268,0.493278,-1293.861938,0.050333,0.000000
33.510002,46.266159,-1293.906372,-0.001117,0.001958,0.049726,205.802155,10.484061,0.497259,-1293.906372,0.050837,0.000000
33.810001,47.229492,-1293.861938,-0.001095,0.001982,0.050342,210.087280,10.702356,0.503421,-1293.861938,0.051340,0.000000
34.110001,47.564621,-1293.861938,-0.001074,0.001999,0.050777,211.578003,10.778297,0.507766,-1293.861938,0.051833,0.000000
34.410000,47.703522,-1293.817383,-0.001052,0.002014,0.051149,212.195862,10.809772,0.511491,-1293.817383,0.052338,0.000000
34.710003,49.110344,-1293.861938,-0.001026,0.002043,0.051895,218.453720,11.128563,0.518955,-1293.861938,0.052840,0.000000
35.010002,49.246628,-1293.906372,-0.001030,0.002058,0.052277,219.059937,11.159445,0.522770,-1293.906372,0.053334,0.000000
35.310001,50.017067,-1293.861938,-0.000996,0.002080,0.052831,222.487030,11.334029,0.528311,-1293.861938,0.053838,0.000000
35.610001,50.819901,-1293.906372,-0.000983,0.002100,0.053334,226.058212,11.515955,0.533337,-1293.906372,0.054340,0.000000
35.910000,51.321121,-1293.906372,-0.000974,0.002118,0.053794,228.287750,11.629533,0.537940,-1293.906372,0.054834,0.000000
36.210003,51.732964,-1293.906372,-0.000940,0.002137,0.054280,230.119720,11.722857,0.542799,-1293.906372,0.055338,0.000000
36.510002,51.478256,-1293.861938,-0.000927,0.002145,0.054480,228.986725,11.665140,0.544798,-1293.861938,0.055841,0.000000
36.810001,53.438431,-1293.861938,-0.000897,0.002179,0.055346,237.706009,12.109322,0.553458,-1293.861938,0.056334,0.000000
37.110001,54.034966,-1293.861938,-0.000892,0.002197,0.055815,240.359528,12.244498,0.558151,-1293.861938,0.056839,0.000000
37.410004,54.320206,-1293.861938,-0.000862,0.002212,0.056197,241.628342,12.309134,0.561966,-1293.861938,0.057341,0.000000
37.710003,55.502861,-1293.861938,-0.000832,0.002237,0.056811,246.889053,12.577128,0.568113,-1293.861938,0.057835,0.000000
38.010002,56.254677,-1293.906372,-0.000832,0.002255,0.057272,250.233307,12.747492,0.572715,-1293.906372,0.058339,0.000000
38.310001,56.507149,-1293.817383,-0.000815,0.002269,0.057627,251.356354,12.804703,0.576273,-1293.817383,0.058841,0.000000
38.610001,58.081909,-1293.906372,-0.000793,0.002297,0.058356,258.361237,13.161549,0.583555,-1293.906372,0.059335,0.000000
38.910004,58.822563,-1293.861938,-0.000780,0.002316,0.058823,261.655823,13.329384,0.588233,-1293.861938,0.059839,0.000000
39.210003,59.499908,-1293.817383,-0.000759,0.002336,0.059344,264.668823,13.482872,0.593441,-1293.817383,0.060342,0.000000
39.510002,60.183212,-1293.906372,-0.000746,0.002354,0.059795,267.708313,13.637711,0.597953,-1293.906372,0.060835,0.000000
39.810001,61.231812,-1293.817383,-0.000720,0.002379,0.060419,272.372711,13.875327,0.604190,-1293.817383,0.061340,0.000000
40.110001,62.217484,-1293.906372,-0.000716,0.002395,0.060828,276.757202,14.098682,0.608278,-1293.906372,0.061842,0.000000
40.410004,61.816063,-1293.817383,-0.000711,0.002402,0.061019,274.971588,14.007720,0.610186,-1293.817383,0.062336,0.000000
40.710003,64.223076,-1293.861938,-0.000686,0.002437,0.061912,285.678497,14.553158,0.619118,-1293.861938,0.062840,0.000000
41.010002,64.806221,-1293.861938,-0.000655,0.002456,0.062380,288.272461,14.685300,0.623796,-1293.861938,0.063342,0.000000
41.310001,65.490257,-1293.817383,-0.000642,0.002474,0.062831,291.315216,14.840305,0.628308,-1293.817383,0.063836,0.000000
41.610001,66.209312,-1293.817383,-0.000625,0.002492,0.063308,294.513733,15.003245,0.633077,-1293.817383,0.064339,0.000000
41.910004,65.121620,-1293.817383,-0.000629,0.002484,0.063099,289.675446,14.756769,0.630987,-1293.817383,0.011088,0.000000
42.210003,65.621712,-1293.817383,-0.000599,0.002497,0.063412,291.899963,14.870092,0.634121,-1293.817383,294.500488,0.000000
42.510002,64.559334,-1293.861938,-0.000604,0.002504,0.063594,287.174255,14.629354,0.635938,-1293.861938,294.500488,0.000000
42.810001,65.775871,-1293.817383,-0.000569,0.002461,0.062501,292.585693,14.905025,0.625007,-1293.817383,294.500488,0.000000
43.110001,65.062782,-1293.817383,-0.000560,0.002518,0.063950,289.413696,14.743437,0.639496,-1293.817383,294.500488,0.000000
43.410004,64.971169,-1293.906372,-0.000569,0.002528,0.064210,289.006195,14.722678,0.642100,-1293.906372,294.500488,0.000000
43.710003,65.422112,-1293.817383,-0.000565,0.002540,0.064522,291.012085,14.824862,0.645219,-1293.817383,294.500488,0.000000
44.010002,65.490639,-1293.817383,-0.000530,0.002549,0.064738,291.316925,14.840391,0.647384,-1293.817383,294.500488,0.000000
44.310001,64.902290,-1293.817383,-0.000539,0.002549,0.064747,288.699799,14.707069,0.647474,-1293.817383,294.500488,0.000000
44.610001,66.040627,-1293.861938,-0.000522,0.002535,0.064383,293.763367,14.965019,0.643826,-1293.861938,294.500488,0.000000
44.910004,65.372963,-1293.861938,-0.000513,0.002553,0.064850,290.793457,14.813725,0.648504,-1293.861938,294.500488,0.000000
45.210003,65.430687,-1293.817383,-0.000504,0.002572,0.065329,291.050232,14.826806,0.653288,-1293.817383,294.500488,0.000000
45.510002,65.315987,-1293.772949,-0.000504,0.002577,0.065457,290.540009,14.800814,0.654575,-1293.772949,294.500488,0.000000
45.810001,65.669746,-1293.728516,-0.000500,0.002586,0.065675,292.113617,14.880977,0.656755,-1293.728516,294.500488,0.000000
46.110001,65.264610,-1293.817383,-0.000500,0.002587,0.065701,290.311493,14.789172,0.657012,-1293.817383,294.500488,0.000000
46.410004,65.199440,-1293.728516,-0.000474,0.002591,0.065813,290.021606,14.774405,0.658133,-1293.728516,294.500488,0.000000
46.710003,65.239281,-1293.817383,-0.000496,0.002596,0.065934,290.198822,14.783432,0.659344,-1293.817383,294.500488,0.000000
47.010002,65.359184,-1293.817383,-0.000487,0.002601,0.066074,290.732178,14.810603,0.660737,-1293.817383,294.500488,0.000000
47.310001,65.258278,-1293.772949,-0.000487,0.002606,0.066187,290.283325,14.787737,0.661872,-1293.772949,294.500488,0.000000
47.610001,65.215080,-1293.861938,-0.000461,0.002608,0.066255,290.091156,14.777948,0.662553,-1293.861938,294.500488,0.000000
47.910004,65.475746,-1293.772949,-0.000457,0.002614,0.066395,291.250671,14.837016,0.663946,-1293.772949,294.500488,0.000000
48.210003,65.149162,-1293.772949,-0.000466,0.002615,0.066429,289.797943,14.763011,0.664294,-1293.772949,294.500488,0.000000
48.510002,65.199074,-1293.861938,-0.000448,0.002618,0.066508,290.019958,14.774321,0.665082,-1293.861938,294.500488,0.000000
48.810001,65.351372,-1293.861938,-0.000453,0.002623,0.066637,290.697418,14.808832,0.666369,-1293.861938,294.500488,0.000000
49.110001,65.283226,-1293.817383,-0.000435,0.002627,0.066716,290.394287,14.793390,0.667156,-1293.817383,294.500488,0.000000
49.410004,65.307793,-1293.772949,-0.000461,0.002630,0.066811,290.503571,14.798957,0.668110,-1293.772949,294.500488,0.000000
49.710003,65.244499,-1293.728516,-0.000431,0.002631,0.066837,290.222015,14.784615,0.668367,-1293.728516,294.500488,0.000000
50.010002,65.091820,-1293.817383,-0.000435,0.002633,0.066881,289.542877,14.750017,0.668806,-1293.817383,294.500488,0.000000
50.310001,65.069115,-1293.772949,-0.000435,0.002635,0.066941,289.441864,14.744872,0.669412,-1293.772949,294.500488,0.000000
50.610001,65.054955,-1293.861938,-0.000418,0.002638,0.067002,289.378876,14.741663,0.670017,-1293.861938,294.500488,0.000000
50.910004,65.560265,-1293.772949,-0.000418,0.002646,0.067211,291.626617,14.856169,0.672107,-1293.772949,294.500488,0.000000
51.210003,65.427330,-1293.817383,-0.000418,0.002646,0.067211,291.035309,14.826045,0.672107,-1293.817383,294.500488,0.000000
51.510002,65.241524,-1293.861938,-0.000410,0.002646,0.067218,290.208801,14.783940,0.672182,-1293.861938,294.500488,0.000000
51.810001,65.178581,-1293.772949,-0.000414,0.002649,0.067279,289.928802,14.769677,0.672788,-1293.772949,294.500488,0.000000
52.110001,65.060539,-1293.817383,-0.000410,0.002651,0.067339,289.403748,14.742929,0.673393,-1293.817383,294.500488,0.000000
52.410004,65.029640,-1293.817383,-0.000410,0.002652,0.067348,289.266296,14.735928,0.673484,-1293.817383,294.500488,0.000000
52.710003,65.311150,-1293.772949,-0.000405,0.002657,0.067488,290.518494,14.799718,0.674877,-1293.772949,294.500488,0.000000
53.010002,65.174110,-1293.772949,-0.000392,0.002657,0.067488,289.908936,14.768664,0.674877,-1293.772949,294.500488,0.000000
53.310001,65.008034,-1293.861938,-0.000401,0.002657,0.067497,289.170166,14.731030,0.674968,-1293.861938,294.500488,0.000000
53.610004,65.836937,-1293.772949,-0.000388,0.002671,0.067834,292.857330,14.918863,0.678344,-1293.772949,294.500488,0.000000
53.910004,65.808647,-1293.817383,-0.000405,0.002668,0.067774,292.731476,14.912453,0.677738,-1293.817383,294.500488,0.000000
54.210003,65.621330,-1293.728516,-0.000392,0.002668,0.067774,291.898254,14.870006,0.677738,-1293.728516,294.500488,0.000000
54.510002,65.479088,-1293.772949,-0.000392,0.002668,0.067774,291.265533,14.837773,0.677738,-1293.772949,294.500488,0.000000
54.810001,65.310402,-1293.817383,-0.000392,0.002668,0.067774,290.515167,14.799548,0.677738,-1293.817383,294.500488,0.000000
55.110004,65.113045,-1293.861938,-0.000384,0.002671,0.067834,289.637299,14.754827,0.678344,-1293.861938,294.500488,0.000000
55.410004,65.433662,-1293.817383,-0.000392,0.002674,0.067930,291.063477,14.827479,0.679298,-1293.817383,294.500488,0.000000
55.710003,65.305931,-1293.817383,-0.000397,0.002674,0.067930,290.495300,14.798535,0.679298,-1293.817383,294.500488,0.000000
56.010002,65.168526,-1293.861938,-0.000384,0.002674,0.067930,289.884094,14.767399,0.679298,-1293.861938,294.500488,0.000000
56.310001,65.470528,-1293.817383,-0.000379,0.002680,0.068077,291.227448,14.835834,0.680766,-1293.817383,294.500488,0.000000
56.610004,65.404610,-1293.817383,-0.000384,0.002680,0.068077,290.934235,14.820896,0.680766,-1293.817383,294.500488,0.000000
56.910004,65.280251,-1293.861938,-0.000379,0.002680,0.068077,290.381042,14.792717,0.680766,-1293.861938,294.500488,0.000000
57.210003,65.212105,-1293.861938,-0.000371,0.002681,0.068086,290.077942,14.777274,0.680857,-1293.861938,294.500488,0.000000
57.510002,65.080284,-1293.861938,-0.000371,0.002683,0.068137,289.491577,14.747403,0.681372,-1293.861938,294.500488,0.000000
57.810001,65.461586,-1293.861938,-0.000371,0.002686,0.068233,291.187683,14.833807,0.682326,-1293.861938,294.500488,0.000000
58.110004,65.363655,-1293.817383,-0.000371,0.002686,0.068233,290.752045,14.811616,0.682326,-1293.817383,294.500488,0.000000
58.410004,65.263115,-1293.861938,-0.000366,0.002686,0.068233,290.304840,14.788833,0.682326,-1293.861938,294.500488,0.000000
58.710003,65.155495,-1293.861938,-0.000371,0.002687,0.068251,289.826111,14.764446,0.682507,-1293.861938,294.500488,0.000000
59.010002,65.059807,-1293.861938,-0.000366,0.002688,0.068267,289.400482,14.742763,0.682674,-1293.861938,294.500488,0.000000
59.310001,65.318596,-1293.817383,-0.000375,0.002693,0.068398,290.551636,14.801406,0.683976,-1293.817383,294.500488,0.000000
59.610004,65.338707,-1293.817383,-0.000362,0.002693,0.068398,290.641083,14.805963,0.683976,-1293.817383,294.500488,0.000000
59.910004,65.260139,-1293.772949,-0.000366,0.002693,0.068398,290.291595,14.788159,0.683976,-1293.772949,294.500488,0.000000
60.210003,65.170021,-1293.861938,-0.000362,0.002693,0.068398,289.890747,14.767738,0.683976,-1293.861938,294.500488,0.000000
60.510002,65.155495,-1293.817383,-0.000371,0.002695,0.068441,289.826111,14.764446,0.684415,-1293.817383,294.500488,0.000000
60.810001,65.070595,-1293.817383,-0.000349,0.002695,0.068451,289.448456,14.745208,0.684506,-1293.817383,294.500488,0.000000
61.110004,65.215446,-1293.861938,-0.000362,0.002697,0.068511,290.092804,14.778031,0.685111,-1293.861938,294.500488,0.000000
61.410004,65.142464,-1293.861938,-0.000371,0.002697,0.068511,289.768158,14.761494,0.685111,-1293.861938,294.500488,0.000000
61.710003,65.046761,-1293.861938,-0.000358,0.002697,0.068511,289.342438,14.739807,0.685111,-1293.861938,294.500488,0.000000
62.010002,65.563988,-1293.861938,-0.000362,0.002705,0.068719,291.643188,14.857012,0.687186,-1293.861938,294.500488,0.000000
62.310001,65.606438,-1293.817383,-0.000349,0.002705,0.068719,291.832001,14.866632,0.687186,-1293.817383,294.500488,0.000000
62.610004,65.566231,-1293.861938,-0.000358,0.002705,0.068719,291.653168,14.857520,0.687186,-1293.861938,294.500488,0.000000
62.910004,65.500694,-1293.817383,-0.000349,0.002705,0.068719,291.361633,14.842669,0.687186,-1293.817383,294.500488,0.000000
63.210003,65.394188,-1293.906372,-0.000341,0.002705,0.068719,290.887878,14.818535,0.687186,-1293.906372,294.500488,0.000000
63.510002,65.302956,-1293.861938,-0.000366,0.002705,0.068719,290.482056,14.797861,0.687186,-1293.861938,294.500488,0.000000
63.810001,65.240028,-1293.861938,-0.000349,0.002706,0.068728,290.202148,14.783602,0.687276,-1293.861938,294.500488,0.000000
64.110001,65.250832,-1293.950806,-0.000362,0.002708,0.068772,290.250183,14.786049,0.687715,-1293.950806,294.500488,0.000000
64.410004,65.218056,-1293.906372,-0.000354,0.002708,0.068772,290.104401,14.778623,0.687715,-1293.906372,294.500488,0.000000
64.710007,65.188271,-1293.861938,-0.000354,0.002709,0.068814,289.971924,14.771873,0.688139,-1293.861938,294.500488,0.000000
65.010002,65.203911,-1293.861938,-0.000349,0.002710,0.068840,290.041473,14.775417,0.688397,-1293.861938,294.500488,0.000000
65.310005,65.345406,-1293.861938,-0.000358,0.002713,0.068902,290.670868,14.807481,0.689017,-1293.861938,294.500488,0.000000
65.610001,65.310036,-1293.906372,-0.000354,0.002713,0.068902,290.513550,14.799465,0.689017,-1293.906372,294.500488,0.000000
65.910004,65.285454,-1293.861938,-0.000358,0.002713,0.068902,290.404205,14.793895,0.689017,-1293.861938,294.500488,0.000000
66.210007,65.250084,-1293.861938,-0.000345,0.002714,0.068927,290.246857,14.785880,0.689275,-1293.861938,294.500488,0.000000
66.510002,65.228477,-1293.861938,-0.000349,0.002714,0.068944,290.150757,14.780985,0.689441,-1293.861938,294.500488,0.000000
66.810005,65.205025,-1293.906372,-0.000341,0.002714,0.068944,290.046448,14.775670,0.689441,-1293.906372,294.500488,0.000000
67.110001,65.279503,-1293.861938,-0.000345,0.002717,0.069005,290.377716,14.792547,0.690047,-1293.861938,294.500488,0.000000
67.410004,65.270927,-1293.861938,-0.000332,0.002717,0.069005,290.339600,14.790604,0.690047,-1293.861938,294.500488,0.000000
67.710007,65.227745,-1293.861938,-0.000341,0.002717,0.069005,290.147491,14.780818,0.690047,-1293.861938,294.500488,0.000000
68.010002,65.176353,-1293.906372,-0.000349,0.002717,0.069023,289.918915,14.769173,0.690229,-1293.906372,294.500488,0.000000
68.310005,65.183052,-1293.906372,-0.000345,0.002719,0.069074,289.948700,14.770691,0.690743,-1293.906372,294.500488,0.000000
68.610001,65.246361,-1293.906372,-0.000332,0.002719,0.069074,290.230316,14.785036,0.690743,-1293.906372,294.500488,0.000000
68.910004,65.197578,-1293.817383,-0.000354,0.002719,0.069074,290.013306,14.773982,0.690743,-1293.817383,294.500488,0.000000
69.210007,65.336479,-1293.817383,-0.000354,0.002723,0.069161,290.631165,14.805458,0.691606,-1293.817383,294.500488,0.000000
69.510002,65.350624,-1293.817383,-0.000332,0.002723,0.069161,290.694092,14.808662,0.691606,-1293.817383,294.500488,0.000000
69.810005,65.321953,-1293.906372,-0.000341,0.002723,0.069161,290.566559,14.802166,0.691606,-1293.906372,294.500488,0.000000
70.110001,65.288063,-1293.861938,-0.000323,0.002724,0.069179,290.415802,14.794487,0.691788,-1293.861938,294.500488,0.000000
70.410004,65.282112,-1293.817383,-0.000323,0.002724,0.069179,290.389343,14.793138,0.691788,-1293.817383,294.500488,0.000000
70.710007,65.267204,-1293.950806,-0.000332,0.002725,0.069205,290.323029,14.789760,0.692045,-1293.950806,294.500488,0.000000
71.010002,65.270561,-1293.817383,-0.000341,0.002725,0.069214,290.337952,14.790521,0.692136,-1293.817383,294.500488,0.000000
71.310005,65.253807,-1293.861938,-0.000328,0.002726,0.069239,290.263428,14.786724,0.692394,-1293.861938,294.500488,0.000000
71.610001,65.255302,-1293.906372,-0.000341,0.002726,0.069248,290.270081,14.787063,0.692484,-1293.906372,294.500488,0.000000
71.910004,65.241524,-1293.817383,-0.000328,0.002727,0.069256,290.208801,14.783940,0.692560,-1293.817383,294.500488,0.000000
72.210007,65.235558,-1293.950806,-0.000315,0.002727,0.069265,290.182251,14.782589,0.692651,-1293.950806,294.500488,0.000000
72.510002,65.215828,-1293.861938,-0.000328,0.002727,0.069274,290.094482,14.778117,0.692742,-1293.861938,294.500488,0.000000
72.810005,65.183434,-1293.817383,-0.000328,0.002728,0.069283,289.950378,14.770777,0.692833,-1293.817383,294.500488,0.000000
73.110001,65.266090,-1293.861938,-0.000328,0.002730,0.069335,290.318085,14.789508,0.693347,-1293.861938,294.500488,0.000000
73.410004,65.263115,-1293.817383,-0.000323,0.002730,0.069335,290.304840,14.788833,0.693347,-1293.817383,294.500488,0.000000
73.710007,65.229607,-1293.861938,-0.000323,0.002730,0.069344,290.155792,14.781240,0.693438,-1293.861938,294.500488,0.000000
74.010002,65.217690,-1293.861938,-0.000319,0.002730,0.069344,290.102783,14.778540,0.693438,-1293.861938,294.500488,0.000000
74.310005,65.207253,-1293.861938,-0.000319,0.002731,0.069370,290.056335,14.776175,0.693696,-1293.861938,294.500488,0.000000
74.610001,65.192360,-1293.817383,-0.000310,0.002731,0.069370,289.990112,14.772799,0.693696,-1293.817383,294.500488,0.000000
74.910004,65.439613,-1293.861938,-0.000323,0.002735,0.069474,291.089935,14.828828,0.694740,-1293.861938,294.500488,0.000000
75.210007,65.507759,-1293.861938,-0.000315,0.002735,0.069474,291.393066,14.844271,0.694740,-1293.861938,294.500488,0.000000
75.510002,65.465691,-1293.861938,-0.000323,0.002735,0.069474,291.205933,14.834738,0.694740,-1293.861938,294.500488,0.000000
75.810005,65.419136,-1293.906372,-0.000319,0.002735,0.069474,290.998840,14.824188,0.694740,-1293.906372,294.500488,0.000000
76.110001,65.361046,-1293.861938,-0.000328,0.002735,0.069474,290.740448,14.811025,0.694740,-1293.861938,294.500488,0.000000
76.410004,65.324181,-1293.906372,-0.000315,0.002735,0.069474,290.576477,14.802671,0.694740,-1293.906372,294.500488,0.000000
76.710007,65.304451,-1293.950806,-0.000302,0.002735,0.069474,290.488708,14.798200,0.694740,-1293.950806,294.500488,0.000000
77.010002,65.282112,-1293.906372,-0.000323,0.002735,0.069474,290.389343,14.793138,0.694740,-1293.906372,294.500488,0.000000
77.310005,65.218056,-1293.817383,-0.000315,0.002735,0.069474,290.104401,14.778623,0.694740,-1293.817383,294.500488,0.000000
77.610001,65.190880,-1293.861938,-0.000310,0.002735,0.069482,289.983521,14.772465,0.694816,-1293.861938,294.500488,0.000000
77.910004,65.240776,-1293.817383,-0.000310,0.002737,0.069525,290.205475,14.783772,0.695255,-1293.817383,294.500488,0.000000
78.210007,65.217690,-1293.861938,-0.000310,0.002738,0.069535,290.102783,14.778540,0.695346,-1293.861938,294.500488,0.000000
78.510002,65.198692,-1293.906372,-0.000310,0.002738,0.069535,290.018280,14.774235,0.695346,-1293.906372,294.500488,0.000000
78.810005,65.151772,-1293.906372,-0.000306,0.002738,0.069535,289.809540,14.763602,0.695346,-1293.906372,294.500488,0.000000
79.110001,65.333488,-1293.861938,-0.000306,0.002742,0.069647,290.617859,14.804780,0.696466,-1293.861938,294.500488,0.000000
79.410004,65.472023,-1293.906372,-0.000306,0.002742,0.069647,291.234100,14.836172,0.696466,-1293.906372,294.500488,0.000000
79.710007,65.462334,-1293.906372,-0.000315,0.002742,0.069647,291.191010,14.833977,0.696466,-1293.906372,294.500488,0.000000
80.010002,65.423241,-1293.950806,-0.000323,0.002742,0.069647,291.017120,14.825118,0.696466,-1293.950806,294.500488,0.000000
80.310005,65.388969,-1293.995361,-0.000302,0.002742,0.069647,290.864655,14.817352,0.696466,-1293.995361,294.500488,0.000000
80.610001,65.348381,-1293.950806,-0.000302,0.002742,0.069647,290.684113,14.808154,0.696466,-1293.950806,294.500488,0.000000
80.910004,65.328651,-1293.995361,-0.000315,0.002742,0.069647,290.596344,14.803684,0.696466,-1293.995361,294.500488,0.000000
81.210007,65.299232,-1293.950806,-0.000323,0.002742,0.069647,290.465485,14.797018,0.696466,-1293.950806,294.500488,0.000000
81.510002,65.257530,-1293.995361,-0.000315,0.002742,0.069647,290.279999,14.787567,0.696466,-1293.995361,294.500488,0.000000
81.810005,65.245247,-1293.950806,-0.000306,0.002742,0.069647,290.225342,14.784784,0.696466,-1293.950806,294.500488,0.000000
82.110001,65.212837,-1293.995361,-0.000302,0.002742,0.069647,290.081177,14.777440,0.696466,-1293.995361,294.500488,0.000000
82.410004,65.167412,-1293.995361,-0.000310,0.002742,0.069656,289.879120,14.767146,0.696557,-1293.995361,294.500488,0.000000
82.710007,65.265343,-1293.950806,-0.000302,0.002745,0.069716,290.314758,14.789338,0.697163,-1293.950806,294.500488,0.000000
83.010002,65.311150,-1293.995361,-0.000297,0.002745,0.069716,290.518494,14.799718,0.697163,-1293.995361,294.500488,0.000000
83.310005,65.296257,-1293.950806,-0.000302,0.002745,0.069725,290.452271,14.796344,0.697253,-1293.950806,294.500488,0.000000
83.610001,65.270195,-1294.039795,-0.000310,0.002745,0.069725,290.336334,14.790438,0.697253,-1294.039795,294.500488,0.000000
83.910004,65.258278,-1294.039795,-0.000302,0.002745,0.069725,290.283325,14.787737,0.697253,-1294.039795,294.500488,0.000000
84.210007,65.222527,-1293.995361,-0.000297,0.002745,0.069725,290.124298,14.779635,0.697253,-1293.995361,294.500488,0.000000
84.510002,65.162575,-1294.084351,-0.000315,0.002746,0.069742,289.857605,14.766050,0.697420,-1294.084351,294.500488,0.000000
84.810005,65.154015,-1293.950806,-0.000297,0.002746,0.069742,289.819519,14.764111,0.697420,-1293.950806,294.500488,0.000000
85.110001,65.233696,-1293.995361,-0.000319,0.002747,0.069777,290.173981,14.782166,0.697768,-1293.995361,294.500488,0.000000
85.410004,65.218056,-1293.995361,-0.000302,0.002747,0.069777,290.104401,14.778623,0.697768,-1293.995361,294.500488,0.000000
85.710007,65.216942,-1294.039795,-0.000306,0.002747,0.069777,290.099457,14.778370,0.697768,-1294.039795,294.500488,0.000000
86.010002,65.199074,-1294.039795,-0.000293,0.002747,0.069777,290.019958,14.774321,0.697768,-1294.039795,294.500488,0.000000
86.310005,65.177849,-1294.039795,-0.000306,0.002747,0.069777,289.925537,14.769512,0.697768,-1294.039795,294.500488,0.000000
86.610001,65.160713,-1294.084351,-0.000306,0.002747,0.069786,289.849335,14.765629,0.697859,-1294.084351,294.500488,0.000000
86.910004,65.133156,-1294.039795,-0.000302,0.002747,0.069786,289.726746,14.759384,0.697859,-1294.039795,294.500488,0.000000
87.210007,65.153267,-1293.995361,-0.000293,0.002749,0.069828,289.816193,14.763942,0.698283,-1293.995361,294.500488,0.000000
87.510002,65.172630,-1294.039795,-0.000306,0.002749,0.069828,289.902344,14.768330,0.698283,-1294.039795,294.500488,0.000000
87.810005,65.173744,-1293.995361,-0.000306,0.002749,0.069828,289.907288,14.768581,0.698283,-1293.995361,294.500488,0.000000
88.110001,65.138741,-1294.084351,-0.000306,0.002749,0.069828,289.751587,14.760650,0.698283,-1294.084351,294.500488,0.000000
88.410004,65.084007,-1294.084351,-0.000310,0.002751,0.069872,289.508118,14.748247,0.698722,-1294.084351,294.500488,0.000000
88.710007,65.187157,-1294.084351,-0.000285,0.002751,0.069872,289.966949,14.771621,0.698722,-1294.084351,294.500488,0.000000
89.010002,65.177849,-1294.084351,-0.000306,0.002751,0.069872,289.925537,14.769512,0.698722,-1294.084351,294.500488,0.000000
89.310005,65.162575,-1294.084351,-0.000297,0.002751,0.069872,289.857605,14.766050,0.698722,-1294.084351,294.500488,0.000000
89.610001,65.139854,-1293.995361,-0.000297,0.002751,0.069872,289.756531,14.760902,0.698722,-1293.995361,294.500488,0.000000
89.910004,65.113045,-1294.084351,-0.000297,0.002751,0.069872,289.637299,14.754827,0.698722,-1294.084351,294.500488,0.000000
90.210007,65.089592,-1294.084351,-0.000297,0.002751,0.069872,289.532959,14.749513,0.698722,-1294.084351,294.500488,0.000000
90.510002,65.123848,-1294.039795,-0.000297,0.002753,0.069924,289.685333,14.757275,0.699237,-1294.039795,294.500488,0.000000
90.810005,65.168907,-1294.084351,-0.000293,0.002753,0.069924,289.885773,14.767486,0.699237,-1294.084351,294.500488,0.000000
91.110001,65.151772,-1294.084351,-0.000297,0.002753,0.069924,289.809540,14.763602,0.699237,-1294.084351,294.500488,0.000000
91.410004,65.132790,-1293.995361,-0.000297,0.002753,0.069924,289.725128,14.759300,0.699237,-1293.995361,294.500488,0.000000
91.710007,65.110435,-1294.084351,-0.000289,0.002753,0.069924,289.625671,14.754235,0.699237,-1294.084351,294.500488,0.000000
92.010002,65.088097,-1293.995361,-0.000302,0.002753,0.069924,289.526306,14.749174,0.699237,-1293.995361,294.500488,0.000000
92.310005,65.061668,-1294.084351,-0.000302,0.002753,0.069924,289.408752,14.743185,0.699237,-1294.084351,294.500488,0.000000
92.610001,65.044533,-1294.084351,-0.000289,0.002753,0.069924,289.332520,14.739302,0.699237,-1294.084351,294.500488,0.000000
92.910004,65.031868,-1294.039795,-0.000289,0.002753,0.069924,289.276184,14.736432,0.699237,-1294.039795,294.500488,0.000000
93.210007,65.487282,-1293.995361,-0.000297,0.002760,0.070098,291.301971,14.839630,0.700978,-1293.995361,294.500488,0.000000
93.510002,65.563988,-1294.084351,-0.000285,0.002760,0.070098,291.643188,14.857012,0.700978,-1294.084351,294.500488,0.000000
93.810005,65.582603,-1294.084351,-0.000302,0.002760,0.070098,291.725983,14.861231,0.700978,-1294.084351,294.500488,0.000000
94.110008,65.566963,-1294.039795,-0.000302,0.002760,0.070098,291.656433,14.857686,0.700978,-1294.039795,294.500488,0.000000
94.410004,65.557655,-1294.039795,-0.000302,0.002760,0.070098,291.615021,14.855577,0.700978,-1294.039795,294.500488,0.000000
94.710007,65.555794,-1294.039795,-0.000297,0.002760,0.070098,291.606720,14.855155,0.700978,-1294.039795,294.500488,0.000000
95.010002,65.520790,-1293.995361,-0.000289,0.002760,0.070098,291.451019,14.847223,0.700978,-1293.995361,294.500488,0.000000
95.310005,65.513725,-1293.995361,-0.000302,0.002760,0.070098,291.419617,14.845622,0.700978,-1293.995361,294.500488,0.000000
95.610008,65.491005,-1294.039795,-0.000293,0.002760,0.070098,291.318542,14.840473,0.700978,-1294.039795,294.500488,0.000000
95.910004,65.478722,-1294.084351,-0.000293,0.002760,0.070098,291.263885,14.837690,0.700978,-1294.084351,294.500488,0.000000
96.210007,65.451912,-1294.084351,-0.000297,0.002760,0.070098,291.144653,14.831614,0.700978,-1294.084351,294.500488,0.000000
96.510002,65.404991,-1294.084351,-0.000293,0.002760,0.070098,290.935944,14.820983,0.700978,-1294.084351,294.500488,0.000000
96.810005,65.380409,-1294.039795,-0.000289,0.002760,0.070098,290.826599,14.815413,0.700978,-1294.039795,294.500488,0.000000
97.110008,65.352119,-1294.084351,-0.000293,0.002760,0.070098,290.700745,14.809002,0.700978,-1294.084351,294.500488,0.000000
97.410004,65.337593,-1294.084351,-0.000293,0.002760,0.070098,290.636139,14.805711,0.700978,-1294.084351,294.500488,0.000000
97.710007,65.314873,-1294.039795,-0.000293,0.002760,0.070098,290.535065,14.800561,0.700978,-1294.039795,294.500488,0.000000
98.010002,65.288811,-1294.039795,-0.000285,0.002760,0.070098,290.419128,14.794656,0.700978,-1294.039795,294.500488,0.000000
98.310005,65.277260,-1294.084351,-0.000285,0.002760,0.070098,290.367767,14.792039,0.700978,-1294.084351,294.500488,0.000000
98.610008,65.265343,-1294.084351,-0.000293,0.002760,0.070098,290.314758,14.789338,0.700978,-1294.084351,294.500488,0.000000
98.910004,65.231087,-1294.039795,-0.000280,0.002760,0.070098,290.162354,14.781575,0.700978,-1294.039795,294.500488,0.000000
99.210007,65.210609,-1294.039795,-0.000285,0.002760,0.070098,290.071289,14.776936,0.700978,-1294.039795,294.500488,0.000000
99.510002,65.178581,-1294.084351,-0.000293,0.002760,0.070098,289.928802,14.769677,0.700978,-1294.084351,294.500488,0.000000
99.810005,65.163689,-1294.084351,-0.000293,0.002760,0.070098,289.862549,14.766303,0.700978,-1294.084351,294.500488,0.000000
100.110008,65.119377,-1294.084351,-0.000297,0.002760,0.070098,289.665466,14.756262,0.700978,-1294.084351,294.500488,0.000000
100.410004,65.087730,-1294.084351,-0.000289,0.002760,0.070107,289.524689,14.749090,0.701069,-1294.084351,294.500488,0.000000
100.710007,65.073952,-1294.084351,-0.000289,0.002760,0.070107,289.463379,14.745968,0.701069,-1294.084351,294.500488,0.000000
101.010002,65.064644,-1294.084351,-0.000285,0.002761,0.070124,289.421997,14.743859,0.701235,-1294.084351,294.500488,0.000000
101.310005,65.069481,-1294.084351,-0.000276,0.002761,0.070133,289.443512,14.744955,0.701326,-1294.084351,294.500488,0.000000
101.610008,65.063530,-1294.084351,-0.000293,0.002761,0.070133,289.417023,14.743607,0.701326,-1294.084351,294.500488,0.000000
101.910004,65.053093,-1294.039795,-0.000306,0.002761,0.070133,289.370605,14.741241,0.701326,-1294.039795,294.500488,0.000000
102.210007,65.042671,-1294.039795,-0.000293,0.002762,0.070158,289.324249,14.738880,0.701583,-1294.039795,1681.640991,0.000000
102.510002,65.048256,-1294.084351,-0.000297,0.002753,0.069933,289.349091,14.740146,0.699327,-1294.084351,0.069958,0.000000
102.810005,64.946220,-1294.039795,-0.000280,0.002743,0.069665,288.895203,14.717024,0.696648,-1294.039795,0.069456,0.000000
103.110008,64.933571,-1294.039795,-0.000289,0.002728,0.069300,288.838959,14.714157,0.692999,-1294.039795,0.068953,0.000000
103.410004,64.863564,-1294.084351,-0.000276,0.002709,0.068797,288.527527,14.698294,0.687973,-1294.084351,0.068458,0.000000
103.710007,64.771217,-1294.084351,-0.000280,0.002693,0.068407,288.116760,14.677368,0.684067,-1294.084351,0.067956,0.000000
104.010002,64.765999,-1294.084351,-0.000272,0.002673,0.067895,288.093536,14.676186,0.678950,-1294.084351,0.067453,0.000000
104.310005,64.725777,-1294.039795,-0.000276,0.002657,0.067479,287.914642,14.667070,0.674786,-1294.039795,0.066958,0.000000
104.610008,64.709023,-1293.995361,-0.000272,0.002635,0.066932,287.840118,14.663274,0.669321,-1293.995361,0.066455,0.000000
104.910004,64.685188,-1294.039795,-0.000276,0.002616,0.066455,287.734100,14.657873,0.664552,-1294.039795,0.065953,0.000000
105.210007,64.666573,-1294.039795,-0.000289,0.002594,0.065892,287.651276,14.653654,0.658920,-1294.039795,0.065457,0.000000
105.510002,64.579445,-1293.995361,-0.000280,0.002577,0.065450,287.263733,14.633911,0.654499,-1293.995361,0.064955,0.000000
105.810005,64.564171,-1294.084351,-0.000276,0.002562,0.065068,287.195770,14.630450,0.650684,-1294.084351,0.064452,0.000000
106.110008,64.457680,-1294.128784,-0.000267,0.002540,0.064522,286.722076,14.606319,0.645219,-1294.128784,0.063957,0.000000
106.410004,64.214516,-1294.039795,-0.000267,0.002522,0.064071,285.640442,14.551217,0.640707,-1294.039795,0.063455,0.000000
106.710007,63.510353,-1294.084351,-0.000267,0.002500,0.063489,282.508148,14.391651,0.634893,-1294.084351,0.062961,0.000000
107.010002,62.825195,-1294.039795,-0.000263,0.002484,0.063091,279.460419,14.236392,0.630912,-1294.039795,0.062457,0.000000
107.310005,62.155296,-1294.084351,-0.000272,0.002471,0.062752,276.480560,14.084591,0.627520,-1294.084351,0.061954,0.000000
107.610008,60.988655,-1294.039795,-0.000267,0.002449,0.062198,271.291077,13.820227,0.621979,-1294.039795,0.061461,0.000000
107.910004,60.062935,-1293.995361,-0.000259,0.002432,0.061763,267.173279,13.610456,0.617634,-1293.995361,0.060956,0.000000
108.210007,58.894432,-1294.084351,-0.000267,0.002414,0.061321,261.975525,13.345670,0.613214,-1294.084351,0.060454,0.000000
108.510002,57.554634,-1294.084351,-0.000263,0.002396,0.060854,256.015808,13.042067,0.608535,-1294.084351,0.059960,0.000000
108.810005,55.924385,-1294.039795,-0.000267,0.002377,0.060368,248.764084,12.672647,0.603676,-1294.039795,0.059458,0.000000
109.110008,54.809875,-1294.039795,-0.000272,0.002364,0.060038,243.806503,12.420095,0.600375,-1294.039795,0.058954,0.000000
109.410004,52.915245,-1294.084351,-0.000254,0.002341,0.059465,235.378769,11.990767,0.594652,-1294.084351,0.058460,0.000000
109.710007,51.156158,-1294.128784,-0.000263,0.002324,0.059023,227.553955,11.592152,0.590232,-1294.128784,0.057957,0.000000
110.010002,49.773163,-1294.039795,-0.000263,0.002310,0.058676,221.402084,11.278760,0.586765,-1294.039795,0.057453,0.000000
110.310005,46.924515,-1294.039795,-0.000267,0.002284,0.058025,208.730667,10.633246,0.580255,-1294.039795,0.056960,0.000000
110.610008,44.189812,-1294.084351,-0.000263,0.002259,0.057384,196.566101,10.013555,0.573835,-1294.084351,0.056457,0.000000
110.910004,42.862679,-1294.039795,-0.000272,0.002246,0.057037,190.662720,9.712822,0.570369,-1294.039795,0.055953,0.000000
111.210007,40.823936,-1294.039795,-0.000254,0.002224,0.056499,181.593933,9.250836,0.564994,-1294.039795,0.055459,0.000000
111.510002,39.006386,-1294.039795,-0.000267,0.002208,0.056092,173.509064,8.838973,0.560921,-1294.039795,0.054957,0.000000
111.810005,37.143784,-1294.084351,-0.000280,0.002190,0.055632,165.223801,8.416903,0.556319,-1294.084351,0.054453,0.000000
112.110008,35.173561,-1294.084351,-0.000289,0.002170,0.055120,156.459808,7.970443,0.551202,-1294.084351,0.053959,0.000000
112.410004,33.211525,-1294.084351,-0.000293,0.002151,0.054643,147.732239,7.525839,0.546433,-1294.084351,0.053456,0.000000
112.710007,31.134804,-1294.039795,-0.000289,0.002129,0.054089,138.494522,7.055247,0.540892,-1294.039795,0.052952,0.000000
113.010002,29.261024,-1294.084351,-0.000297,0.002113,0.053664,130.159531,6.630643,0.536638,-1294.084351,0.052459,0.000000
113.310005,27.080040,-1294.084351,-0.000306,0.002091,0.053117,120.458031,6.136425,0.531172,-1294.084351,0.051956,0.000000
113.610008,24.932198,-1294.084351,-0.000306,0.002072,0.052631,110.903954,5.649717,0.526312,-1294.084351,0.051452,0.000000
113.910004,22.534866,-1294.039795,-0.000297,0.002047,0.051982,100.240089,5.106473,0.519817,-1294.039795,0.050958,0.000000
114.210007,20.213493,-1294.084351,-0.000297,0.002028,0.051512,89.914108,4.580443,0.515124,-1294.084351,0.050456,0.000000
114.510002,18.864014,-1294.084351,-0.000315,0.002015,0.051175,83.911324,4.274647,0.511748,-1294.084351,0.049952,0.000000
114.810005,15.415848,-1294.039795,-0.000315,0.001984,0.050395,68.573112,3.493281,0.503951,-1294.039795,0.049458,0.000000
115.110008,14.063766,-1294.039795,-0.000341,0.001969,0.050021,62.558758,3.186895,0.500212,-1294.039795,0.048955,0.000000
115.410004,11.807556,-1294.039795,-0.000332,0.001950,0.049528,52.522633,2.675630,0.495276,-1294.039795,0.048451,0.000000
115.710007,9.939369,-1294.039795,-0.000332,0.001930,0.049023,44.212521,2.252293,0.490235,-1294.039795,0.047958,0.000000
116.010002,7.490273,-1294.084351,-0.000362,0.001907,0.048425,33.318398,1.697320,0.484255,-1294.084351,0.047455,0.000000
116.310005,6.189949,-1294.039795,-0.000371,0.001891,0.048035,27.534269,1.402663,0.480349,-1294.039795,0.046951,0.000000
116.610008,3.867462,-1294.084351,-0.000384,0.001866,0.047394,17.203331,0.876379,0.473945,-1294.084351,0.046457,0.000000
116.910004,2.581657,-1294.039795,-0.000375,0.001851,0.047004,11.483786,0.585012,0.470039,-1294.039795,0.045955,0.000000
117.210007,1.201271,-1294.084351,-0.000375,0.001834,0.046588,5.343521,0.272212,0.465875,-1294.084351,0.045451,0.000000
117.510002,-0.909706,-1294.039795,-0.000392,0.001806,0.045885,-4.046575,-0.206142,0.458850,-1294.039795,0.044957,0.000000
117.810005,-2.173538,-1293.995361,-0.000405,0.001784,0.045322,-9.668381,-0.492531,0.453218,-1293.995361,0.044454,0.000000
118.110008,-0.486320,-1293.995361,-0.000444,0.001771,0.044992,-2.163262,-0.110202,0.449918,-1293.995361,0.043950,0.000000
118.410004,-0.182091,-1294.039795,-0.000479,0.001744,0.044306,-0.809980,-0.041262,0.443060,-1294.039795,0.043457,0.000000
118.710007,-0.056602,-1294.039795,-0.000500,0.001736,0.044089,-0.251780,-0.012826,0.440895,-1294.039795,0.042954,0.000000
119.010002,-0.072243,-1294.084351,-0.000526,0.001714,0.043526,-0.321352,-0.016370,0.435263,-1294.084351,0.042451,0.000000
119.310005,-0.059204,-1294.039795,-0.000565,0.001690,0.042928,-0.263353,-0.013416,0.429283,-1294.039795,0.041956,0.000000
119.610008,-0.052132,-1293.995361,-0.000608,0.001672,0.042477,-0.231893,-0.011813,0.424771,-1293.995361,0.041454,0.000000
119.910004,-0.034630,-1294.084351,-0.000638,0.001652,0.041965,-0.154041,-0.007847,0.419654,-1294.084351,0.040959,0.000000
120.210007,-0.052879,-1294.039795,-0.000647,0.001632,0.041445,-0.235219,-0.011983,0.414446,-1294.039795,0.040456,0.000000
120.510002,-0.001114,-1294.084351,-0.000707,0.001611,0.040916,-0.004955,-0.000252,0.409162,-1294.084351,0.039953,0.000000
120.800003,0.037979,-1294.084351,-0.000742,0.001600,0.040638,0.168940,0.008606,0.406377,-1294.084351,0.040482,0.000000