File: Data/Sima compression/P2-11-3_10302024_164828.csv
Time (sec),S:Load (lbs),S:HL1 (DIM),S:LVDT (in),S:Position (in),Ch:Position (mm),Ch:Load (N),Ch:Stress (MPa),Ch:Strain (mm/mm),Ch:HL1 (DIM),Set Point (),Cycles ()
0.210000,0.016754,-1293.683960,-0.008994,-0.005747,-0.145971,0.074526,0.003797,-1.459713,-1293.683960,-0.145790,0.000000
0.570000,-0.011543,-1293.639526,-0.009007,-0.005657,-0.143691,-0.051347,-0.002616,-1.436913,-1293.639526,-0.142859,0.000000
0.930000,-0.002235,-1293.594971,-0.008852,-0.005435,-0.138037,-0.009944,-0.000507,-1.380366,-1293.594971,-0.136874,0.000000
1.290000,0.003723,-1293.728516,-0.008606,-0.005199,-0.132044,0.016561,0.000844,-1.320444,-1293.728516,-0.130874,0.000000
1.650000,0.002975,-1293.728516,-0.008373,-0.004960,-0.125992,0.013236,0.000674,-1.259916,-1293.728516,-0.124873,0.000000
2.010000,0.016014,-1293.683960,-0.008119,-0.004727,-0.120077,0.071234,0.003629,-1.200765,-1293.683960,-0.118871,0.000000
2.370000,0.001114,-1293.683960,-0.007894,-0.004494,-0.114136,0.004955,0.000252,-1.141358,-1293.683960,-0.112870,0.000000
2.730000,-0.011169,-1293.683960,-0.007640,-0.004255,-0.108083,-0.049684,-0.002531,-1.080830,-1293.683960,-0.106885,0.000000
3.090000,0.056229,-1293.683960,-0.007407,-0.004022,-0.102159,0.250117,0.012742,-1.021589,-1293.683960,-0.100884,0.000000
3.450000,0.043564,-1293.639526,-0.007148,-0.003782,-0.096064,0.193782,0.009872,-0.960637,-1293.639526,-0.094883,0.000000
3.810000,0.026810,-1293.594971,-0.006911,-0.003546,-0.090062,0.119255,0.006075,-0.900623,-1293.594971,-0.088883,0.000000
4.170000,-0.000374,-1293.683960,-0.006679,-0.003312,-0.084112,-0.001663,-0.000085,-0.841125,-1293.683960,-0.082882,0.000000
4.530000,0.009682,-1293.639526,-0.006424,-0.003071,-0.077999,0.043066,0.002194,-0.779991,-1293.639526,-0.076897,0.000000
4.890000,-0.007820,-1293.683960,-0.006174,-0.002831,-0.071919,-0.034786,-0.001772,-0.719191,-1293.683960,-0.070896,0.000000
5.250000,0.049522,-1293.594971,-0.005954,-0.002606,-0.066196,0.220287,0.011222,-0.661963,-1293.594971,-0.064894,0.000000
5.610000,0.055115,-1293.594971,-0.005696,-0.002368,-0.060151,0.245163,0.012489,-0.601511,-1293.594971,-0.058893,0.000000
5.970000,0.043564,-1293.683960,-0.005467,-0.002127,-0.054038,0.193782,0.009872,-0.540377,-1293.683960,-0.052893,0.000000
6.330000,-0.011169,-1293.683960,-0.005226,-0.001900,-0.048253,-0.049684,-0.002531,-0.482529,-1293.683960,-0.046908,0.000000
6.690001,-0.032768,-1293.728516,-0.004967,-0.001655,-0.042026,-0.145760,-0.007425,-0.420260,-1293.728516,-0.040907,0.000000
7.050000,-0.045799,-1293.594971,-0.004730,-0.001419,-0.036034,-0.203725,-0.010378,-0.360337,-1293.594971,-0.034906,0.000000
7.410000,0.036865,-1293.639526,-0.004497,-0.001189,-0.030188,0.163985,0.008354,-0.301883,-1293.639526,-0.028904,0.000000
7.770000,0.065910,-1293.594971,-0.004247,-0.000950,-0.024117,0.293184,0.014935,-0.241174,-1293.594971,-0.022921,0.000000
8.130000,0.051018,-1293.639526,-0.004010,-0.000717,-0.018220,0.226938,0.011561,-0.182205,-1293.639526,-0.016920,0.000000
8.490001,0.014893,-1293.594971,-0.003768,-0.000478,-0.012133,0.066245,0.003375,-0.121329,-1293.594971,-0.010919,0.000000
8.850000,-0.001862,-1293.594971,-0.003518,-0.000239,-0.006080,-0.008281,-0.000422,-0.060801,-1293.594971,-0.004917,0.000000
9.210000,0.030533,-1293.683960,-0.003277,-0.000003,-0.000070,0.135817,0.006919,-0.000696,-1293.683960,0.001084,0.000000
9.570001,0.099792,-1293.683960,-0.003260,-0.000001,-0.000018,0.443899,0.022613,-0.000182,-1293.683960,0.000198,0.000000
9.930000,0.163841,-1293.639526,-0.003247,-0.000000,-0.000009,0.728802,0.037127,-0.000091,-1293.639526,0.000442,0.000000
10.290001,0.138893,-1293.639526,-0.003268,-0.000000,-0.000009,0.617827,0.031474,-0.000091,-1293.639526,0.001040,0.000000
10.650001,0.349655,-1293.594971,-0.003255,0.000030,0.000771,1.555344,0.079233,0.007706,-1293.594971,0.001638,0.000000
11.010000,0.556328,-1293.639526,-0.003234,0.000049,0.001240,2.474670,0.126066,0.012399,-1293.639526,0.002236,0.000000
11.370001,0.945457,-1293.594971,-0.003199,0.000078,0.001994,4.205605,0.214244,0.019939,-1293.594971,0.002843,0.000000
11.730000,1.250053,-1293.683960,-0.003182,0.000101,0.002575,5.560515,0.283266,0.025752,-1293.683960,0.003443,0.000000
12.090000,1.568062,-1293.639526,-0.003169,0.000121,0.003078,6.975087,0.355328,0.030779,-1293.639526,0.004041,0.000000
12.450001,2.174652,-1293.550537,-0.003143,0.000147,0.003729,9.673336,0.492783,0.037289,-1293.550537,0.004639,0.000000
12.810000,2.501595,-1293.639526,-0.003156,0.000165,0.004188,11.127648,0.566869,0.041876,-1293.639526,0.005237,0.000000
13.170001,3.098511,-1293.594971,-0.003113,0.000190,0.004830,13.782865,0.702133,0.048295,-1293.594971,0.005844,0.000000
13.530001,3.654839,-1293.639526,-0.003100,0.000215,0.005462,16.257534,0.828198,0.054624,-1293.639526,0.006443,0.000000
13.890000,4.274834,-1293.639526,-0.003078,0.000239,0.006079,19.015409,0.968691,0.060785,-1293.639526,0.007041,0.000000
14.250001,4.731361,-1293.594971,-0.003061,0.000258,0.006565,21.046146,1.072142,0.065645,-1293.594971,0.007639,0.000000
14.610001,5.280243,-1293.683960,-0.003057,0.000281,0.007137,23.487694,1.196520,0.071368,-1293.683960,0.008237,0.000000
14.970000,5.981049,-1293.594971,-0.003040,0.000308,0.007821,26.605032,1.355325,0.078211,-1293.594971,0.008837,0.000000
15.330001,6.662117,-1293.594971,-0.003014,0.000334,0.008472,29.634577,1.509657,0.084721,-1293.594971,0.009444,0.000000
15.690001,7.236687,-1293.639526,-0.002992,0.000357,0.009070,32.190392,1.639857,0.090701,-1293.639526,0.010042,0.000000
16.050001,7.856689,-1293.550537,-0.002984,0.000383,0.009721,34.948299,1.780351,0.097211,-1293.550537,0.010640,0.000000
16.410000,8.366089,-1293.683960,-0.002966,0.000404,0.010259,37.214222,1.895783,0.102586,-1293.683960,0.011238,0.000000
16.770000,8.929123,-1293.594971,-0.002945,0.000426,0.010814,39.718723,2.023368,0.108142,-1293.594971,0.011838,0.000000
17.130001,9.700302,-1293.594971,-0.002928,0.000457,0.011612,43.149097,2.198120,0.116121,-1293.594971,0.012443,0.000000
17.490002,10.006393,-1293.683960,-0.002906,0.000478,0.012131,44.510662,2.267481,0.121313,-1293.683960,0.013043,0.000000
17.850000,10.315460,-1293.639526,-0.002889,0.000500,0.012704,45.885460,2.337517,0.127036,-1293.639526,0.013641,0.000000
18.210001,11.018501,-1293.639526,-0.002880,0.000526,0.013371,49.012741,2.496828,0.133713,-1293.639526,0.014239,0.000000
18.570002,11.037491,-1293.639526,-0.002859,0.000540,0.013719,49.097210,2.501131,0.137195,-1293.639526,0.014837,0.000000
18.930000,11.871979,-1293.639526,-0.002841,0.000573,0.014560,52.809200,2.690229,0.145597,-1293.639526,0.015444,0.000000
19.290001,12.227219,-1293.639526,-0.002841,0.000596,0.015141,54.389385,2.770727,0.151411,-1293.639526,0.016043,0.000000
19.650002,12.511345,-1293.639526,-0.002790,0.000620,0.015748,55.653240,2.835111,0.157482,-1293.639526,0.016641,0.000000
20.010000,12.607788,-1293.728516,-0.002785,0.000638,0.016208,56.082241,2.856966,0.162084,-1293.728516,0.017239,0.000000
20.370001,13.019630,-1293.639526,-0.002764,0.000663,0.016841,57.914207,2.950290,0.168413,-1293.639526,0.017837,0.000000
20.730001,13.135811,-1293.728516,-0.002764,0.000681,0.017309,58.431004,2.976617,0.173091,-1293.728516,0.018445,0.000000
21.090000,13.829170,-1293.639526,-0.002734,0.000713,0.018107,61.515221,3.133735,0.181069,-1293.639526,0.019044,0.000000
21.450001,13.937904,-1293.683960,-0.002716,0.000735,0.018670,61.998894,3.158374,0.186701,-1293.683960,0.019642,0.000000
21.810001,13.837730,-1293.728516,-0.002703,0.000755,0.019165,61.553299,3.135675,0.191652,-1293.728516,0.020240,0.000000
22.170002,14.432411,-1293.728516,-0.002699,0.000783,0.019877,64.198570,3.270431,0.198768,-1293.728516,0.020838,0.000000
22.530001,14.577637,-1293.772949,-0.002682,0.000804,0.020422,64.844566,3.303340,0.204218,-1293.772949,0.021438,0.000000
22.890001,14.836433,-1293.594971,-0.002656,0.000828,0.021029,65.995750,3.361984,0.210289,-1293.594971,0.022045,0.000000
23.250002,15.001396,-1293.639526,-0.002643,0.000852,0.021645,66.729546,3.399365,0.216451,-1293.639526,0.022643,0.000000
23.610001,15.256104,-1293.683960,-0.002634,0.000876,0.022252,67.862541,3.457083,0.222522,-1293.683960,0.023241,0.000000
23.970001,15.472450,-1293.683960,-0.002604,0.000900,0.022850,68.824898,3.506107,0.228502,-1293.683960,0.023839,0.000000
24.330002,15.388290,-1293.728516,-0.002587,0.000919,0.023336,68.450531,3.487036,0.233361,-1293.728516,0.024438,0.000000
24.690001,15.313072,-1293.728516,-0.002578,0.000937,0.023787,68.115944,3.469992,0.237873,-1293.728516,0.025045,0.000000
25.050001,15.946480,-1293.683960,-0.002565,0.000968,0.024594,70.933487,3.613524,0.245942,-1293.683960,0.025643,0.000000
25.410002,16.064148,-1293.683960,-0.002565,0.000991,0.025183,71.456902,3.640188,0.251832,-1293.683960,0.026241,0.000000
25.770000,16.251076,-1293.683960,-0.002531,0.001017,0.025834,72.288399,3.682546,0.258342,-1293.683960,0.026839,0.000000
26.130001,16.343056,-1293.817383,-0.002522,0.001042,0.026476,72.697540,3.703389,0.264761,-1293.817383,0.027439,0.000000
26.490002,16.290176,-1293.683960,-0.002509,0.001061,0.026961,72.462326,3.691407,0.269606,-1293.683960,0.028046,0.000000
26.850000,17.020027,-1293.772949,-0.002501,0.001094,0.027786,75.708862,3.856793,0.277857,-1293.772949,0.028644,0.000000
27.210001,16.719521,-1293.772949,-0.002488,0.001113,0.028270,74.372139,3.788697,0.282701,-1293.772949,0.029242,0.000000
27.570002,16.850227,-1293.728516,-0.002466,0.001137,0.028870,74.953552,3.818316,0.288697,-1293.728516,0.029840,0.000000
27.930002,17.167862,-1293.772949,-0.002440,0.001164,0.029554,76.366463,3.890293,0.295540,-1293.772949,0.030440,0.000000
28.290001,16.715797,-1293.728516,-0.002436,0.001176,0.029858,74.355583,3.787854,0.298583,-1293.728516,0.031045,0.000000
28.650002,17.448257,-1293.728516,-0.002414,0.001208,0.030673,77.613724,3.953831,0.306728,-1293.728516,0.031645,0.000000
29.010002,17.476555,-1293.728516,-0.002397,0.001232,0.031289,77.739601,3.960244,0.312890,-1293.728516,0.032243,0.000000
29.370001,17.596085,-1293.683960,-0.002389,0.001255,0.031870,78.271294,3.987330,0.318703,-1293.683960,0.032841,0.000000
29.730001,17.821747,-1293.728516,-0.002380,0.001279,0.032494,79.275085,4.038465,0.324941,-1293.728516,0.033439,0.000000
30.090002,17.711899,-1293.683960,-0.002363,0.001298,0.032962,78.786461,4.013574,0.329619,-1293.683960,0.034038,0.000000
30.450001,18.332642,-1293.683960,-0.002363,0.001327,0.033699,81.547661,4.154236,0.336992,-1293.683960,0.034645,0.000000
30.810001,18.598145,-1293.683960,-0.002337,0.001354,0.034385,82.728676,4.214400,0.343850,-1293.683960,0.035243,0.000000
31.170002,18.427223,-1293.683960,-0.002333,0.001374,0.034897,81.968384,4.175669,0.348967,-1293.683960,0.035841,0.000000
31.530001,18.310669,-1293.683960,-0.002302,0.001393,0.035374,81.449921,4.149257,0.353736,-1293.683960,0.036439,0.000000
31.890001,18.739273,-1293.683960,-0.002315,0.001419,0.036032,83.356453,4.246380,0.360322,-1293.683960,0.037039,0.000000
32.250000,18.921364,-1293.772949,-0.002289,0.001441,0.036604,84.166428,4.287642,0.366045,-1293.772949,0.037646,0.000000
32.610001,19.308258,-1293.728516,-0.002285,0.001468,0.037299,85.887421,4.375314,0.372994,-1293.728516,0.038244,0.000000
32.970001,19.506729,-1293.728516,-0.002268,0.001493,0.037923,86.770264,4.420288,0.379231,-1293.728516,0.038842,0.000000
33.330002,19.314590,-1293.772949,-0.002259,0.001511,0.038391,85.915588,4.376749,0.383909,-1293.772949,0.039440,0.000000
33.690002,19.590515,-1293.728516,-0.002251,0.001535,0.038981,87.142967,4.439274,0.389814,-1293.728516,0.040040,0.000000
34.050003,19.728668,-1293.683960,-0.002233,0.001556,0.039528,87.757500,4.470580,0.395279,-1293.683960,0.040647,0.000000
34.410000,19.927887,-1293.772949,-0.002229,0.001581,0.040161,88.643669,4.515724,0.401608,-1293.772949,0.041245,0.000000
34.770000,20.365051,-1293.728516,-0.002220,0.001606,0.040785,90.588272,4.614787,0.407845,-1293.728516,0.041843,0.000000
35.130001,20.760139,-1293.817383,-0.002203,0.001632,0.041452,92.345711,4.704315,0.414522,-1293.817383,0.042441,0.000000
35.490002,20.620499,-1293.728516,-0.002182,0.001655,0.042024,91.724556,4.672672,0.420244,-1293.728516,0.043040,0.000000
35.850002,21.087082,-1293.772949,-0.002160,0.001680,0.042666,93.800026,4.778401,0.426664,-1293.772949,0.043647,0.000000
36.210003,21.116867,-1293.728516,-0.002160,0.001699,0.043143,93.932518,4.785151,0.431433,-1293.728516,0.044245,0.000000
36.570004,21.528717,-1293.639526,-0.002151,0.001728,0.043890,95.764519,4.878477,0.438896,-1293.639526,0.044843,0.000000
36.930000,21.873528,-1293.728516,-0.002130,0.001752,0.044513,97.298309,4.956612,0.445134,-1293.728516,0.045441,0.000000
37.290001,22.179245,-1293.728516,-0.002104,0.001775,0.045095,98.658211,5.025888,0.450948,-1293.728516,0.046041,0.000000
37.650002,22.192284,-1293.728516,-0.002087,0.001797,0.045641,98.716209,5.028843,0.456413,-1293.728516,0.046639,0.000000
38.010002,22.227287,-1293.728516,-0.002091,0.001817,0.046162,98.871910,5.036776,0.461621,-1293.728516,0.047246,0.000000
38.370003,23.223007,-1293.772949,-0.002087,0.001847,0.046907,103.301094,5.262408,0.469070,-1293.772949,0.047844,0.000000
38.730003,23.386482,-1293.772949,-0.002074,0.001871,0.047532,104.028267,5.299452,0.475322,-1293.772949,0.048442,0.000000
39.090000,23.480690,-1293.728516,-0.002057,0.001894,0.048114,104.447327,5.320800,0.481136,-1293.728516,0.049042,0.000000
39.450001,23.844498,-1293.772949,-0.002035,0.001920,0.048772,106.065620,5.403241,0.487722,-1293.772949,0.049640,0.000000
39.810001,23.793114,-1293.861938,-0.002031,0.001938,0.049214,105.837059,5.391596,0.492142,-1293.861938,0.050247,0.000000
40.170002,23.872055,-1293.728516,-0.002022,0.001955,0.049647,106.188202,5.409485,0.496472,-1293.728516,0.050845,0.000000
40.530003,24.991035,-1293.817383,-0.002001,0.001988,0.050507,111.165680,5.663050,0.505072,-1293.817383,0.051443,0.000000
40.890003,25.271057,-1293.728516,-0.001992,0.002012,0.051105,112.411278,5.726503,0.511052,-1293.728516,0.052041,0.000000
41.250004,25.510490,-1293.861938,-0.001975,0.002036,0.051721,113.476326,5.780759,0.517213,-1293.861938,0.052640,0.000000
41.610001,25.524269,-1293.728516,-0.001975,0.002053,0.052136,113.537621,5.783882,0.521362,-1293.728516,0.053247,0.000000
41.970001,25.983406,-1293.772949,-0.001953,0.002076,0.052736,115.579964,5.887924,0.527357,-1293.772949,0.053845,0.000000
42.330002,27.003334,-1293.817383,-0.001944,0.002107,0.053515,120.116829,6.119043,0.535154,-1293.817383,0.054443,0.000000
42.690002,27.186913,-1293.772949,-0.001932,0.002130,0.054106,120.933426,6.160643,0.541058,-1293.772949,0.055041,0.000000
43.050003,27.052116,-1293.817383,-0.001923,0.002145,0.054487,120.333824,6.130097,0.544873,-1293.817383,0.055641,0.000000
43.410004,28.041512,-1293.728516,-0.001914,0.002175,0.055250,124.734871,6.354297,0.552504,-1293.728516,0.056248,0.000000
43.770000,28.189713,-1293.817383,-0.001901,0.002197,0.055814,125.394104,6.387880,0.558136,-1293.817383,0.056846,0.000000
44.130001,27.974480,-1293.817383,-0.001884,0.002212,0.056178,124.436699,6.339108,0.561784,-1293.817383,0.057444,0.000000
44.490002,29.280022,-1293.817383,-0.001880,0.002242,0.056951,130.244034,6.634948,0.569506,-1293.817383,0.058042,0.000000
44.850002,29.878418,-1293.772949,-0.001871,0.002269,0.057635,132.905838,6.770546,0.576349,-1293.772949,0.058642,0.000000
45.210003,30.107430,-1293.817383,-0.001858,0.002287,0.058086,133.924530,6.822441,0.580860,-1293.817383,0.059240,0.000000
45.570004,31.361206,-1293.817383,-0.001832,0.002317,0.058849,139.501617,7.106551,0.588491,-1293.817383,0.059847,0.000000
45.930000,31.339615,-1293.906372,-0.001819,0.002332,0.059240,139.405563,7.101658,0.592397,-1293.906372,0.060445,0.000000
46.290001,32.464172,-1293.817383,-0.001815,0.002362,0.059994,144.407852,7.356486,0.599936,-1293.817383,0.061043,0.000000
46.650002,32.835060,-1293.861938,-0.001802,0.002384,0.060549,146.057648,7.440531,0.605492,-1293.861938,0.061642,0.000000
47.010002,33.765244,-1293.817383,-0.001802,0.002409,0.061191,150.195297,7.651314,0.611912,-1293.817383,0.062240,0.000000
47.370003,34.714798,-1293.861938,-0.001772,0.002437,0.061910,154.419128,7.866486,0.619103,-1293.861938,0.062847,0.000000
47.730003,35.100571,-1293.817383,-0.001763,0.002457,0.062405,156.135132,7.953903,0.624053,-1293.817383,0.063445,0.000000
48.090004,35.524330,-1293.817383,-0.001746,0.002481,0.063012,158.020111,8.049929,0.630124,-1293.817383,0.064043,0.000000
48.450001,36.732681,-1293.950806,-0.001733,0.002507,0.063671,163.395126,8.323745,0.636710,-1293.950806,0.064643,0.000000
48.810001,37.474823,-1293.906372,-0.001750,0.002531,0.064287,166.696335,8.491916,0.642872,-1293.906372,0.065241,0.000000
49.170002,38.498474,-1293.906372,-0.001716,0.002559,0.064990,171.249771,8.723879,0.649897,-1293.906372,0.065848,0.000000
49.530003,38.283241,-1293.817383,-0.001712,0.002569,0.065258,170.292358,8.675107,0.652576,-1293.817383,0.066446,0.000000
49.890003,39.758949,-1293.861938,-0.001694,0.002599,0.066013,176.856644,9.009506,0.660131,-1293.861938,0.067044,0.000000
50.250004,41.130775,-1293.906372,-0.001686,0.002626,0.066688,182.958832,9.320367,0.666883,-1293.906372,0.067642,0.000000
50.610001,41.935844,-1293.817383,-0.001681,0.002650,0.067305,186.539948,9.502798,0.673045,-1293.817383,0.068242,0.000000
50.970001,42.462379,-1293.906372,-0.001656,0.002667,0.067739,188.882095,9.622113,0.677390,-1293.906372,0.068849,0.000000
51.330002,43.714294,-1293.906372,-0.001651,0.002694,0.068440,194.450897,9.905801,0.684400,-1293.906372,0.069447,0.000000
51.690002,44.660492,-1293.861938,-0.001634,0.002715,0.068970,198.659790,10.120212,0.689699,-1293.861938,0.070045,0.000000
52.050003,46.587891,-1293.906372,-0.001630,0.002747,0.069784,207.233292,10.556967,0.697844,-1293.906372,0.070643,0.000000
52.410004,46.950211,-1293.817383,-0.001625,0.002764,0.070193,208.844971,10.639070,0.701931,-1293.817383,0.071242,0.000000
52.770004,48.270645,-1293.906372,-0.001600,0.002788,0.070808,214.718552,10.938284,0.708078,-1293.906372,0.071849,0.000000
53.130001,49.554581,-1293.906372,-0.001613,0.002810,0.071380,220.429779,11.229228,0.713801,-1293.906372,0.072447,0.000000
53.490002,50.395027,-1293.950806,-0.001587,0.002829,0.071866,224.168274,11.419676,0.718661,-1293.950806,0.073045,0.000000
53.850002,52.507500,-1293.950806,-0.001578,0.002860,0.072647,233.565018,11.898370,0.726473,-1293.950806,0.073643,0.000000
54.210003,53.914322,-1293.906372,-0.001578,0.002885,0.073280,239.822876,12.217160,0.732801,-1293.906372,0.074243,0.000000
54.570004,55.159157,-1293.950806,-0.001561,0.002908,0.073852,245.360184,12.499244,0.738524,-1293.950806,0.074841,0.000000
54.930004,56.520180,-1293.906372,-0.001561,0.002929,0.074406,251.414322,12.807655,0.744065,-1293.906372,0.075448,0.000000
55.290001,58.009674,-1293.906372,-0.001552,0.002952,0.074980,258.039917,13.145180,0.749803,-1293.906372,0.076046,0.000000
55.650002,59.174828,-1293.995361,-0.001548,0.002972,0.075500,263.222778,13.409207,0.754996,-1293.995361,0.076644,0.000000
56.010002,61.104828,-1293.906372,-0.001535,0.002998,0.076151,271.807861,13.846552,0.761506,-1293.906372,0.077244,0.000000
56.370003,63.046379,-1293.950806,-0.001522,0.003026,0.076870,280.444305,14.286513,0.768697,-1293.950806,0.077842,0.000000
56.730003,64.384682,-1293.950806,-0.001509,0.003047,0.077390,286.397369,14.589777,0.773905,-1293.950806,0.078449,0.000000
57.090004,66.414497,-1293.906372,-0.001483,0.003068,0.077919,295.426453,15.049740,0.779189,-1293.906372,0.079021,0.000000
57.450005,65.451164,-1294.039795,-0.001509,0.003064,0.077816,291.141327,14.831446,0.778159,-1294.039795,291.058502,0.000000
57.810001,65.053841,-1293.906372,-0.001479,0.003071,0.078007,289.373932,14.741411,0.780067,-1293.906372,294.500488,0.000000
58.170002,65.128685,-1293.950806,-0.001470,0.003077,0.078163,289.706848,14.758371,0.781626,-1293.950806,294.500488,0.000000
58.530003,64.967827,-1293.950806,-0.001475,0.003081,0.078249,288.991333,14.721920,0.782489,-1293.950806,294.500488,0.000000
58.890003,65.736031,-1293.950806,-0.001475,0.003091,0.078509,292.408478,14.895997,0.785093,-1293.950806,294.500488,0.000000
59.250004,65.314873,-1293.995361,-0.001487,0.003091,0.078509,290.535065,14.800561,0.785093,-1293.995361,294.500488,0.000000
59.610004,65.060173,-1293.995361,-0.001470,0.003092,0.078544,289.402100,14.742846,0.785441,-1293.995361,294.500488,0.000000
59.970001,65.141716,-1293.995361,-0.001487,0.003097,0.078656,289.764832,14.761324,0.786562,-1293.995361,294.500488,0.000000
60.330002,65.062035,-1293.950806,-0.001475,0.003099,0.078726,289.410370,14.743267,0.787258,-1293.950806,294.500488,0.000000
60.690002,65.084007,-1293.995361,-0.001457,0.003102,0.078779,289.508118,14.748247,0.787788,-1293.995361,294.500488,0.000000
61.050003,65.011391,-1293.950806,-0.001470,0.003103,0.078812,289.185120,14.731791,0.788121,-1293.950806,294.500488,0.000000
61.410004,65.333122,-1293.950806,-0.001453,0.003108,0.078951,290.616241,14.804697,0.789514,-1293.950806,294.500488,0.000000
61.770004,65.225502,-1294.039795,-0.001457,0.003108,0.078951,290.137512,14.780310,0.789514,-1294.039795,294.500488,0.000000
62.130001,65.284706,-1293.995361,-0.001466,0.003112,0.079047,290.400879,14.793726,0.790468,-1293.995361,294.500488,0.000000
62.490002,65.235939,-1293.995361,-0.001453,0.003112,0.079047,290.183960,14.782675,0.790468,-1293.995361,294.500488,0.000000
62.850002,65.208748,-1293.995361,-0.001466,0.003115,0.079116,290.062988,14.776513,0.791164,-1293.995361,294.500488,0.000000
63.210003,65.181190,-1293.906372,-0.001453,0.003115,0.079116,289.940430,14.770268,0.791164,-1293.906372,294.500488,0.000000
63.570004,65.248589,-1294.039795,-0.001466,0.003119,0.079228,290.240204,14.785542,0.792284,-1294.039795,294.500488,0.000000
63.930004,65.345787,-1293.950806,-0.001466,0.003119,0.079228,290.672577,14.807567,0.792284,-1293.950806,294.500488,0.000000
64.290001,65.245247,-1293.950806,-0.001449,0.003119,0.079228,290.225342,14.784784,0.792284,-1293.950806,294.500488,0.000000
64.650002,65.233330,-1293.950806,-0.001457,0.003121,0.079272,290.172333,14.782084,0.792724,-1293.950806,294.500488,0.000000
65.010002,65.238167,-1293.906372,-0.001457,0.003122,0.079298,290.193848,14.783179,0.792981,-1293.906372,294.500488,0.000000
65.370003,65.219170,-1293.995361,-0.001440,0.003123,0.079324,290.109344,14.778874,0.793238,-1293.995361,294.500488,0.000000
65.730003,65.318230,-1293.906372,-0.001453,0.003125,0.079377,290.549988,14.801322,0.793768,-1293.906372,294.500488,0.000000
66.090004,65.281364,-1293.995361,-0.001431,0.003125,0.079377,290.386017,14.792969,0.793768,-1293.995361,294.500488,0.000000
66.450005,65.241524,-1293.950806,-0.001449,0.003126,0.079412,290.208801,14.783940,0.794116,-1293.950806,294.500488,0.000000
66.810005,65.232201,-1293.906372,-0.001444,0.003127,0.079419,290.167328,14.781828,0.794192,-1293.906372,294.500488,0.000000
67.170006,65.264610,-1294.039795,-0.001449,0.003128,0.079446,290.311493,14.789172,0.794465,-1294.039795,294.500488,0.000000
67.530006,65.215828,-1293.906372,-0.001444,0.003128,0.079446,290.094482,14.778117,0.794465,-1293.906372,294.500488,0.000000
67.890007,65.151024,-1293.950806,-0.001444,0.003128,0.079454,289.806213,14.763433,0.794540,-1293.950806,294.500488,0.000000
68.250000,65.199440,-1293.995361,-0.001449,0.003130,0.079498,290.021606,14.774405,0.794979,-1293.995361,294.500488,0.000000
68.610001,65.188637,-1293.950806,-0.001449,0.003130,0.079507,289.973541,14.771956,0.795070,-1293.950806,294.500488,0.000000
68.970001,65.279869,-1293.950806,-0.001449,0.003133,0.079575,290.379364,14.792629,0.795751,-1293.950806,294.500488,0.000000
69.330002,65.289558,-1293.950806,-0.001449,0.003133,0.079575,290.422455,14.794826,0.795751,-1293.950806,294.500488,0.000000
69.690002,65.266838,-1293.950806,-0.001457,0.003133,0.079575,290.321381,14.789678,0.795751,-1293.950806,294.500488,0.000000
70.050003,65.211723,-1293.906372,-0.001440,0.003133,0.079575,290.076233,14.777188,0.795751,-1293.906372,294.500488,0.000000
70.410004,65.267952,-1293.950806,-0.001444,0.003135,0.079619,290.326355,14.789929,0.796191,-1293.950806,294.500488,0.000000
70.770004,65.247108,-1293.995361,-0.001470,0.003135,0.079619,290.233643,14.785206,0.796191,-1293.995361,294.500488,0.000000
71.130005,65.228477,-1293.995361,-0.001449,0.003136,0.079645,290.150757,14.780985,0.796448,-1293.995361,294.500488,0.000000
71.490005,65.232582,-1293.950806,-0.001449,0.003136,0.079645,290.169006,14.781914,0.796448,-1293.950806,294.500488,0.000000
71.850006,65.196465,-1293.995361,-0.001449,0.003136,0.079654,290.008362,14.773730,0.796539,-1293.995361,294.500488,0.000000
72.210007,65.179710,-1293.950806,-0.001436,0.003136,0.079663,289.933838,14.769934,0.796630,-1293.950806,294.500488,0.000000
72.570000,65.135017,-1294.039795,-0.001444,0.003136,0.079663,289.735016,14.759806,0.796630,-1294.039795,294.500488,0.000000
72.930000,65.243752,-1293.950806,-0.001453,0.003139,0.079740,290.218689,14.784445,0.797402,-1293.950806,294.500488,0.000000
73.290001,65.282478,-1293.995361,-0.001449,0.003139,0.079740,290.390961,14.793221,0.797402,-1293.995361,294.500488,0.000000
73.650002,65.278755,-1293.950806,-0.001444,0.003139,0.079740,290.374420,14.792377,0.797402,-1293.950806,294.500488,0.000000
74.010002,65.244499,-1293.906372,-0.001440,0.003139,0.079740,290.222015,14.784615,0.797402,-1293.906372,294.500488,0.000000
74.370003,65.234062,-1293.950806,-0.001449,0.003140,0.079749,290.175598,14.782249,0.797493,-1293.950806,294.500488,0.000000
74.730003,65.205772,-1294.039795,-0.001444,0.003140,0.079749,290.049774,14.775839,0.797493,-1294.039795,294.500488,0.000000
75.090004,65.194969,-1293.950806,-0.001440,0.003141,0.079775,290.001709,14.773392,0.797750,-1293.950806,294.500488,0.000000
75.450005,65.203163,-1293.906372,-0.001444,0.003141,0.079784,290.038147,14.775248,0.797841,-1293.906372,294.500488,0.000000
75.810005,65.192741,-1293.995361,-0.001436,0.003141,0.079793,289.991791,14.772886,0.797932,-1293.995361,294.500488,0.000000
76.170006,65.189751,-1293.950806,-0.001457,0.003141,0.079793,289.978485,14.772208,0.797932,-1293.950806,294.500488,0.000000
76.530006,65.152153,-1293.906372,-0.001427,0.003142,0.079810,289.811249,14.763689,0.798098,-1293.906372,294.500488,0.000000
76.890007,65.180443,-1293.995361,-0.001449,0.003143,0.079845,289.937103,14.770100,0.798446,-1293.995361,294.500488,0.000000
77.250000,65.231834,-1293.950806,-0.001440,0.003144,0.079854,290.165680,14.781745,0.798537,-1293.950806,294.500488,0.000000
77.610001,65.218056,-1293.950806,-0.001436,0.003144,0.079863,290.104401,14.778623,0.798628,-1293.950806,294.500488,0.000000
77.970001,65.239662,-1293.995361,-0.001431,0.003145,0.079870,290.200500,14.783519,0.798704,-1293.995361,294.500488,0.000000
78.330002,65.253807,-1293.950806,-0.001440,0.003145,0.079879,290.263428,14.786724,0.798795,-1293.950806,294.500488,0.000000
78.690002,65.242256,-1293.995361,-0.001427,0.003145,0.079879,290.212036,14.784107,0.798795,-1293.995361,294.500488,0.000000
79.050003,65.226997,-1293.950806,-0.001444,0.003145,0.079889,290.144165,14.780648,0.798885,-1293.950806,294.500488,0.000000
79.410004,65.263863,-1294.084351,-0.001436,0.003147,0.079923,290.308167,14.789002,0.799234,-1294.084351,294.500488,0.000000
79.770004,65.260139,-1293.950806,-0.001440,0.003147,0.079923,290.291595,14.788159,0.799234,-1293.950806,294.500488,0.000000
80.130005,65.254173,-1293.950806,-0.001436,0.003147,0.079923,290.265045,14.786807,0.799234,-1293.950806,294.500488,0.000000
80.490005,65.236305,-1293.950806,-0.001436,0.003147,0.079931,290.185577,14.782759,0.799309,-1293.950806,294.500488,0.000000
80.850006,65.249336,-1293.995361,-0.001444,0.003147,0.079940,290.243530,14.785711,0.799400,-1293.995361,294.500488,0.000000
81.210007,65.227364,-1293.950806,-0.001436,0.003147,0.079940,290.145813,14.780732,0.799400,-1293.950806,294.500488,0.000000
81.570007,65.220665,-1294.039795,-0.001440,0.003148,0.079949,290.115997,14.779214,0.799491,-1294.039795,294.500488,0.000000
81.930000,65.209496,-1293.906372,-0.001440,0.003148,0.079949,290.066315,14.776683,0.799491,-1293.906372,294.500488,0.000000
82.290001,65.190880,-1293.995361,-0.001436,0.003148,0.079958,289.983521,14.772465,0.799582,-1293.995361,294.500488,0.000000
82.650002,65.259026,-1293.950806,-0.001436,0.003149,0.079991,290.286652,14.787907,0.799915,-1293.950806,294.500488,0.000000
83.010002,65.274666,-1293.950806,-0.001431,0.003149,0.079991,290.356201,14.791451,0.799915,-1293.950806,294.500488,0.000000
83.370003,65.257530,-1293.950806,-0.001444,0.003149,0.079991,290.279999,14.787567,0.799915,-1293.950806,294.500488,0.000000
83.730003,65.251564,-1293.950806,-0.001436,0.003149,0.079991,290.253448,14.786216,0.799915,-1293.950806,294.500488,0.000000
84.090004,65.241142,-1293.995361,-0.001444,0.003149,0.079991,290.207092,14.783854,0.799915,-1293.995361,294.500488,0.000000
84.450005,65.205391,-1293.906372,-0.001436,0.003150,0.080001,290.048065,14.775753,0.800006,-1293.906372,294.500488,0.000000
84.810005,65.269814,-1294.039795,-0.001427,0.003151,0.080044,290.334625,14.790351,0.800445,-1294.039795,294.500488,0.000000
85.170006,65.292152,-1293.995361,-0.001449,0.003151,0.080044,290.433990,14.795413,0.800445,-1293.995361,294.500488,0.000000
85.530006,65.290291,-1293.906372,-0.001423,0.003151,0.080044,290.425720,14.794991,0.800445,-1293.906372,294.500488,0.000000
85.890007,65.280251,-1293.995361,-0.001431,0.003151,0.080044,290.381042,14.792717,0.800445,-1293.995361,294.500488,0.000000
86.250008,65.275780,-1293.906372,-0.001431,0.003151,0.080044,290.361176,14.791703,0.800445,-1293.906372,294.500488,0.000000
86.610001,65.267204,-1293.950806,-0.001440,0.003151,0.080044,290.323029,14.789760,0.800445,-1293.950806,294.500488,0.000000
86.970001,65.246727,-1293.906372,-0.001427,0.003152,0.080070,290.231934,14.785120,0.800702,-1293.906372,294.500488,0.000000
87.330002,65.259758,-1293.995361,-0.001449,0.003152,0.080070,290.289886,14.788073,0.800702,-1293.995361,294.500488,0.000000
87.690002,65.247108,-1293.906372,-0.001449,0.003152,0.080070,290.233643,14.785206,0.800702,-1293.906372,294.500488,0.000000
88.050003,65.258644,-1293.950806,-0.001423,0.003153,0.080079,290.284943,14.787820,0.800793,-1293.950806,294.500488,0.000000
88.410004,65.239281,-1293.995361,-0.001440,0.003153,0.080079,290.198822,14.783432,0.800793,-1293.995361,294.500488,0.000000
88.770004,65.245979,-1293.950806,-0.001427,0.003153,0.080079,290.228607,14.784950,0.800793,-1293.950806,294.500488,0.000000
89.130005,65.241142,-1293.995361,-0.001423,0.003153,0.080087,290.207092,14.783854,0.800869,-1293.995361,294.500488,0.000000
89.490005,65.229973,-1293.861938,-0.001436,0.003153,0.080087,290.157410,14.781323,0.800869,-1293.861938,294.500488,0.000000
89.850006,65.225502,-1293.995361,-0.001449,0.003153,0.080096,290.137512,14.780310,0.800959,-1293.995361,294.500488,0.000000
90.210007,65.220665,-1293.950806,-0.001436,0.003153,0.080096,290.115997,14.779214,0.800959,-1293.950806,294.500488,0.000000
90.570007,65.211723,-1293.861938,-0.001440,0.003154,0.080105,290.076233,14.777188,0.801050,-1293.861938,294.500488,0.000000
90.930008,65.221031,-1293.995361,-0.001431,0.003154,0.080114,290.117645,14.779297,0.801141,-1293.995361,294.500488,0.000000
91.290001,65.212837,-1293.950806,-0.001444,0.003154,0.080122,290.081177,14.777440,0.801217,-1293.950806,294.500488,0.000000
91.650002,65.212105,-1293.950806,-0.001431,0.003154,0.080122,290.077942,14.777274,0.801217,-1293.950806,294.500488,0.000000
92.010002,65.216576,-1293.950806,-0.001436,0.003155,0.080131,290.097809,14.778287,0.801308,-1293.950806,294.500488,0.000000
92.370003,65.221779,-1293.861938,-0.001440,0.003155,0.080140,290.120972,14.779467,0.801399,-1293.861938,294.500488,0.000000
92.730003,65.217690,-1294.039795,-0.001436,0.003155,0.080140,290.102783,14.778540,0.801399,-1294.039795,294.500488,0.000000
93.090004,65.234444,-1293.950806,-0.001440,0.003155,0.080149,290.177307,14.782336,0.801489,-1293.950806,294.500488,0.000000
93.450005,65.233330,-1293.950806,-0.001423,0.003156,0.080157,290.172333,14.782084,0.801565,-1293.950806,294.500488,0.000000
93.810005,65.237053,-1293.995361,-0.001440,0.003156,0.080166,290.188904,14.782928,0.801656,-1293.995361,294.500488,0.000000
94.170006,65.243385,-1293.950806,-0.001444,0.003156,0.080166,290.217072,14.784363,0.801656,-1293.950806,294.500488,0.000000
94.530006,65.235191,-1293.995361,-0.001427,0.003156,0.080166,290.180634,14.782506,0.801656,-1293.995361,294.500488,0.000000
94.890007,65.234062,-1293.950806,-0.001436,0.003156,0.080166,290.175598,14.782249,0.801656,-1293.950806,294.500488,0.000000
95.250008,65.210976,-1293.995361,-0.001440,0.003156,0.080175,290.072906,14.777019,0.801747,-1293.995361,294.500488,0.000000
95.610008,65.231834,-1293.950806,-0.001436,0.003157,0.080182,290.165680,14.781745,0.801822,-1293.950806,294.500488,0.000000
95.970001,65.230339,-1293.995361,-0.001436,0.003157,0.080182,290.159027,14.781406,0.801822,-1293.995361,294.500488,0.000000
96.330002,65.224754,-1293.995361,-0.001440,0.003157,0.080182,290.134186,14.780140,0.801822,-1293.995361,294.500488,0.000000
96.690002,65.234810,-1293.995361,-0.001431,0.003157,0.080182,290.178925,14.782419,0.801822,-1293.995361,294.500488,0.000000
97.050003,65.206886,-1293.950806,-0.001449,0.003157,0.080182,290.054718,14.776092,0.801822,-1293.950806,294.500488,0.000000
97.410004,65.203163,-1294.039795,-0.001436,0.003157,0.080182,290.038147,14.775248,0.801822,-1294.039795,294.500488,0.000000
97.770004,65.194969,-1293.995361,-0.001440,0.003157,0.080182,290.001709,14.773392,0.801822,-1293.995361,294.500488,0.000000
98.130005,65.177101,-1293.995361,-0.001449,0.003157,0.080191,289.922211,14.769342,0.801913,-1293.995361,294.500488,0.000000
98.490005,65.152519,-1293.995361,-0.001431,0.003157,0.080191,289.812866,14.763772,0.801913,-1293.995361,294.500488,0.000000
98.850006,65.142845,-1293.950806,-0.001427,0.003157,0.080191,289.769836,14.761580,0.801913,-1293.950806,294.500488,0.000000
99.210007,65.129066,-1294.039795,-0.001427,0.003157,0.080191,289.708557,14.758457,0.801913,-1294.039795,294.500488,0.000000
99.570007,65.117516,-1293.950806,-0.001436,0.003157,0.080200,289.657166,14.755840,0.802004,-1293.950806,294.500488,0.000000
99.930008,65.324562,-1294.084351,-0.001427,0.003161,0.080287,290.578156,14.802757,0.802867,-1294.084351,294.500488,0.000000
100.290009,65.364769,-1293.995361,-0.001431,0.003161,0.080287,290.757019,14.811869,0.802867,-1293.995361,294.500488,0.000000
100.650002,65.375938,-1294.039795,-0.001440,0.003161,0.080287,290.806702,14.814400,0.802867,-1294.039795,294.500488,0.000000
101.010002,65.386742,-1293.995361,-0.001436,0.003161,0.080287,290.854767,14.816847,0.802867,-1293.995361,294.500488,0.000000
101.370003,65.379662,-1293.995361,-0.001444,0.003161,0.080287,290.823273,14.815243,0.802867,-1293.995361,294.500488,0.000000
101.730003,65.379295,-1293.995361,-0.001444,0.003161,0.080287,290.821625,14.815161,0.802867,-1293.995361,294.500488,0.000000
102.090004,65.374077,-1293.950806,-0.001436,0.003161,0.080287,290.798431,14.813977,0.802867,-1293.950806,294.500488,0.000000
102.450005,65.362160,-1293.995361,-0.001440,0.003161,0.080287,290.745422,14.811277,0.802867,-1293.995361,294.500488,0.000000
102.810005,65.350624,-1293.995361,-0.001444,0.003161,0.080287,290.694092,14.808662,0.802867,-1293.995361,294.500488,0.000000
103.170006,65.337593,-1293.995361,-0.001418,0.003161,0.080287,290.636139,14.805711,0.802867,-1293.995361,294.500488,0.000000
103.530006,65.336845,-1294.039795,-0.001427,0.003161,0.080287,290.632812,14.805541,0.802867,-1294.039795,294.500488,0.000000
103.890007,65.315620,-1294.039795,-0.001431,0.003161,0.080287,290.538391,14.800731,0.802867,-1294.039795,294.500488,0.000000
104.250008,65.314507,-1294.084351,-0.001423,0.003161,0.080287,290.533447,14.800479,0.802867,-1294.084351,294.500488,0.000000
104.610008,65.303337,-1293.950806,-0.001423,0.003161,0.080287,290.483765,14.797948,0.802867,-1293.950806,294.500488,0.000000
104.970001,65.292534,-1294.084351,-0.001431,0.003161,0.080287,290.435699,14.795500,0.802867,-1294.084351,294.500488,0.000000
105.330002,65.276527,-1294.039795,-0.001436,0.003161,0.080287,290.364502,14.791872,0.802867,-1294.039795,294.500488,0.000000
105.690002,65.278008,-1293.995361,-0.001427,0.003161,0.080287,290.371094,14.792209,0.802867,-1293.995361,294.500488,0.000000
106.050003,65.269814,-1294.039795,-0.001427,0.003161,0.080287,290.334625,14.790351,0.802867,-1294.039795,294.500488,0.000000
106.410004,65.262367,-1293.995361,-0.001440,0.003161,0.080296,290.301514,14.788664,0.802958,-1293.995361,294.500488,0.000000
106.770004,65.247108,-1294.039795,-0.001427,0.003161,0.080296,290.233643,14.785206,0.802958,-1294.039795,294.500488,0.000000
107.130005,65.237053,-1293.950806,-0.001444,0.003161,0.080296,290.188904,14.782928,0.802958,-1293.950806,294.500488,0.000000
107.490005,65.218056,-1293.950806,-0.001423,0.003161,0.080296,290.104401,14.778623,0.802958,-1293.950806,294.500488,0.000000
107.850006,65.219551,-1294.084351,-0.001427,0.003161,0.080296,290.111053,14.778962,0.802958,-1294.084351,294.500488,0.000000
108.210007,65.189751,-1294.039795,-0.001427,0.003161,0.080296,289.978485,14.772208,0.802958,-1294.039795,294.500488,0.000000
108.570007,65.183800,-1293.950806,-0.001423,0.003161,0.080296,289.952026,14.770861,0.802958,-1293.950806,294.500488,0.000000
108.930008,65.169655,-1294.084351,-0.001440,0.003162,0.080322,289.889099,14.767654,0.803215,-1294.084351,294.500488,0.000000
109.290009,65.178215,-1294.039795,-0.001431,0.003162,0.080322,289.927185,14.769595,0.803215,-1294.039795,294.500488,0.000000
109.650002,65.171135,-1294.039795,-0.001423,0.003162,0.080322,289.895691,14.767991,0.803215,-1294.039795,294.500488,0.000000
110.010002,65.167793,-1293.995361,-0.001436,0.003162,0.080322,289.880829,14.767234,0.803215,-1293.995361,294.500488,0.000000
110.370003,65.144707,-1294.039795,-0.001431,0.003162,0.080322,289.778137,14.762002,0.803215,-1294.039795,294.500488,0.000000
110.730003,65.159218,-1294.039795,-0.001449,0.003163,0.080331,289.842682,14.765290,0.803306,-1294.039795,294.500488,0.000000
111.090004,65.165550,-1293.995361,-0.001431,0.003163,0.080331,289.870850,14.766726,0.803306,-1293.995361,294.500488,0.000000
111.450005,65.146935,-1294.039795,-0.001444,0.003163,0.080331,289.788025,14.762506,0.803306,-1294.039795,294.500488,0.000000
111.810005,65.142097,-1293.995361,-0.001431,0.003163,0.080340,289.766510,14.761411,0.803397,-1293.995361,294.500488,0.000000
112.170006,65.164070,-1293.950806,-0.001423,0.003164,0.080356,289.864258,14.766389,0.803563,-1293.950806,294.500488,0.000000
112.530006,65.157356,-1293.995361,-0.001431,0.003164,0.080356,289.834381,14.764868,0.803563,-1293.995361,294.500488,0.000000
112.890007,65.180824,-1293.995361,-0.001444,0.003164,0.080356,289.938782,14.770185,0.803563,-1293.995361,294.500488,0.000000
113.250008,65.165932,-1293.995361,-0.001436,0.003164,0.080356,289.872528,14.766811,0.803563,-1293.995361,294.500488,0.000000
113.610008,65.154747,-1293.950806,-0.001440,0.003164,0.080356,289.822784,14.764277,0.803563,-1293.950806,294.500488,0.000000
113.970009,65.151772,-1293.995361,-0.001427,0.003164,0.080356,289.809540,14.763602,0.803563,-1293.995361,294.500488,0.000000
114.330002,65.141716,-1294.039795,-0.001436,0.003164,0.080356,289.764832,14.761324,0.803563,-1294.039795,294.500488,0.000000
114.690002,65.133904,-1293.995361,-0.001431,0.003164,0.080365,289.730072,14.759553,0.803654,-1293.995361,294.500488,0.000000
115.050003,65.141716,-1294.039795,-0.001436,0.003164,0.080365,289.764832,14.761324,0.803654,-1294.039795,294.500488,0.000000
115.410004,65.127571,-1293.995361,-0.001427,0.003164,0.080373,289.701904,14.758119,0.803730,-1293.995361,294.500488,0.000000
115.770004,65.165184,-1293.995361,-0.001423,0.003165,0.080391,289.869202,14.766642,0.803912,-1293.995361,294.500488,0.000000
116.130005,65.180443,-1294.039795,-0.001427,0.003165,0.080391,289.937103,14.770100,0.803912,-1294.039795,294.500488,0.000000
116.490005,65.185661,-1293.995361,-0.001444,0.003165,0.080391,289.960297,14.771281,0.803912,-1293.995361,294.500488,0.000000
116.850006,65.188271,-1294.039795,-0.001444,0.003165,0.080391,289.971924,14.771873,0.803912,-1294.039795,294.500488,0.000000
117.210007,65.180824,-1293.950806,-0.001440,0.003165,0.080391,289.938782,14.770185,0.803912,-1293.950806,294.500488,0.000000
117.570007,65.178963,-1293.995361,-0.001431,0.003165,0.080391,289.930511,14.769765,0.803912,-1293.995361,294.500488,0.000000
117.930008,65.167793,-1294.084351,-0.001440,0.003157,0.080191,289.880829,14.767234,0.801913,-1294.084351,0.080312,0.000000
118.290009,65.044533,-1294.084351,-0.001410,0.003149,0.079984,289.332520,14.739302,0.799839,-1294.084351,0.079714,0.000000
118.650009,65.093681,-1294.039795,-0.001423,0.003128,0.079454,289.551147,14.750440,0.794540,-1294.039795,0.079116,0.000000
119.010002,64.997246,-1293.995361,-0.001427,0.003110,0.078995,289.122192,14.728586,0.789953,-1293.995361,0.078509,0.000000
119.370003,64.973412,-1293.950806,-0.001436,0.003092,0.078526,289.016174,14.723186,0.785260,-1293.950806,0.077911,0.000000
119.730003,64.918297,-1294.039795,-0.001431,0.003064,0.077833,288.770996,14.710696,0.778326,-1294.039795,0.077312,0.000000
120.090004,64.891853,-1293.950806,-0.001427,0.003042,0.077269,288.653381,14.704704,0.772694,-1293.950806,0.076714,0.000000
120.450005,64.885902,-1294.084351,-0.001418,0.003027,0.076888,288.626923,14.703356,0.768879,-1294.084351,0.076116,0.000000
120.810005,64.873985,-1293.995361,-0.001440,0.002991,0.075960,288.573914,14.700655,0.759598,-1293.995361,0.075509,0.000000
121.170006,64.826317,-1293.995361,-0.001418,0.002970,0.075448,288.361847,14.689854,0.754481,-1293.995361,0.074911,0.000000
121.530006,64.814034,-1294.039795,-0.001431,0.002957,0.075118,288.307220,14.687070,0.751181,-1294.039795,0.074311,0.000000
121.890007,64.542198,-1293.906372,-0.001423,0.002924,0.074278,287.098022,14.625471,0.742778,-1293.906372,0.073713,0.000000
122.250008,64.064827,-1293.995361,-0.001423,0.002905,0.073792,284.974579,14.517298,0.737918,-1293.995361,0.073115,0.000000
122.610008,63.461952,-1293.950806,-0.001418,0.002892,0.073462,282.292877,14.380684,0.734618,-1293.950806,0.072517,0.000000
122.970009,62.176521,-1293.995361,-0.001410,0.002865,0.072777,276.574982,14.089401,0.727775,-1293.995361,0.071910,0.000000
123.330009,60.865021,-1293.995361,-0.001393,0.002841,0.072152,270.741119,13.792212,0.721522,-1293.995361,0.071312,0.000000
123.690002,59.340904,-1293.950806,-0.001354,0.002818,0.071571,263.961517,13.446841,0.715708,-1293.950806,0.070712,0.000000
124.050003,57.104065,-1293.995361,-0.001358,0.002791,0.070887,254.011566,12.939966,0.708865,-1293.995361,0.070114,0.000000
124.410004,55.405296,-1293.995361,-0.001367,0.002772,0.070401,246.455063,12.555019,0.704006,-1293.995361,0.069516,0.000000
124.770004,52.857155,-1293.906372,-0.001350,0.002744,0.069707,235.120361,11.977603,0.697072,-1293.906372,0.068909,0.000000
125.130005,51.001991,-1293.995361,-0.001354,0.002726,0.069230,226.868195,11.557217,0.692303,-1293.995361,0.068311,0.000000
125.490005,49.416061,-1293.861938,-0.001358,0.002712,0.068884,219.813614,11.197840,0.688836,-1293.861938,0.067712,0.000000
125.850006,46.211792,-1293.995361,-0.001337,0.002679,0.068042,205.560318,10.471742,0.680418,-1293.995361,0.067114,0.000000
126.210007,42.683197,-1293.906372,-0.001354,0.002651,0.067339,189.864349,9.672151,0.673393,-1293.906372,0.066516,0.000000
126.570007,40.508911,-1294.084351,-0.001354,0.002630,0.066793,180.192642,9.179451,0.667928,-1294.084351,0.065909,0.000000
126.930008,37.836769,-1293.950806,-0.001350,0.002606,0.066195,168.306351,8.573935,0.661948,-1293.950806,0.065311,0.000000
127.290009,35.454697,-1293.950806,-0.001350,0.002583,0.065597,157.710373,8.034149,0.655968,-1293.950806,0.064711,0.000000
127.650009,33.004120,-1293.995361,-0.001358,0.002562,0.065067,146.809662,7.478841,0.650669,-1293.995361,0.064113,0.000000
128.010010,30.322662,-1293.950806,-0.001350,0.002535,0.064383,134.881943,6.871213,0.643826,-1293.950806,0.063515,0.000000
128.370010,27.823669,-1294.039795,-0.001350,0.002514,0.063845,123.765862,6.304934,0.638451,-1294.039795,0.062908,0.000000
128.730011,25.112801,-1294.039795,-0.001367,0.002488,0.063185,111.707314,5.690642,0.631850,-1294.039795,0.062310,0.000000
129.090012,21.943909,-1293.995361,-0.001350,0.002457,0.062413,97.611382,4.972560,0.624129,-1293.995361,0.061710,0.000000
129.450012,20.031776,-1293.995361,-0.001341,0.002442,0.062024,89.105789,4.539265,0.620238,-1293.995361,0.061112,0.000000
129.810013,18.318863,-1293.950806,-0.001354,0.002421,0.061503,81.486374,4.151114,0.615030,-1293.950806,0.060514,0.000000
130.170013,15.859718,-1294.039795,-0.001350,0.002403,0.061026,70.547554,3.593864,0.610261,-1294.039795,0.059916,0.000000
130.529999,13.625481,-1293.995361,-0.001362,0.002382,0.060496,60.609165,3.087578,0.604962,-1293.995361,0.059309,0.000000
130.889999,10.360519,-1293.995361,-0.001345,0.002350,0.059698,46.085892,2.347727,0.596984,-1293.995361,0.058710,0.000000
131.250000,7.642197,-1294.084351,-0.001341,0.002325,0.059049,33.994190,1.731747,0.590489,-1294.084351,0.058112,0.000000
131.610001,5.869331,-1293.995361,-0.001354,0.002308,0.058614,26.108089,1.330009,0.586144,-1293.995361,0.057514,0.000000
131.970001,2.917168,-1293.995361,-0.001345,0.002277,0.057835,12.976210,0.661040,0.578347,-1293.995361,0.056916,0.000000
132.330002,1.499916,-1294.084351,-0.001362,0.002262,0.057453,6.671960,0.339886,0.574532,-1294.084351,0.056309,0.000000
132.690002,-0.828529,-1293.950806,-0.001350,0.002234,0.056733,-3.685483,-0.187747,0.567325,-1293.950806,0.055709,0.000000
133.050003,-1.316338,-1294.084351,-0.001354,0.002214,0.056230,-5.855362,-0.298286,0.562299,-1294.084351,0.055111,0.000000
133.410004,-0.008934,-1294.039795,-0.001354,0.002191,0.055641,-0.039741,-0.002024,0.556410,-1294.039795,0.054513,0.000000
133.770004,0.167198,-1294.084351,-0.001337,0.002164,0.054964,0.743735,0.037888,0.549642,-1294.084351,0.053915,0.000000
134.130005,0.130333,-1294.039795,-0.001324,0.002138,0.054306,0.579750,0.029534,0.543057,-1294.039795,0.053308,0.000000
134.490005,0.118042,-1294.039795,-0.001306,0.002117,0.053767,0.525077,0.026749,0.537667,-1294.039795,0.052710,0.000000
134.850006,0.072983,-1294.084351,-0.001250,0.002089,0.053064,0.324644,0.016538,0.530642,-1294.084351,0.052110,0.000000
135.210007,0.079315,-1294.039795,-0.001246,0.002063,0.052397,0.352812,0.017973,0.523966,-1294.039795,0.051512,0.000000
135.570007,0.054741,-1294.128784,-0.001233,0.002038,0.051755,0.243500,0.012404,0.517547,-1294.128784,0.050914,0.000000
135.930008,0.049896,-1294.084351,-0.001220,0.002014,0.051157,0.221950,0.011307,0.511566,-1294.084351,0.050307,0.000000
136.290009,0.008568,-1293.995361,-0.001203,0.001997,0.050724,0.038112,0.001941,0.507236,-1293.995361,0.049709,0.000000
136.650009,0.025322,-1294.128784,-0.001212,0.001970,0.050030,0.112638,0.005738,0.500303,-1294.128784,0.049110,0.000000
137.010010,0.026070,-1293.995361,-0.001203,0.001945,0.049396,0.115964,0.005907,0.493959,-1293.995361,0.048512,0.000000
137.370010,0.001114,-1294.039795,-0.001212,0.001922,0.048824,0.004955,0.000252,0.488236,-1294.039795,0.047914,0.000000
137.730011,0.022339,-1294.128784,-0.001212,0.001900,0.048251,0.099368,0.005062,0.482514,-1294.128784,0.047316,0.000000
138.090012,-0.000748,-1293.995361,-0.001199,0.001880,0.047740,-0.003326,-0.000169,0.477396,-1293.995361,0.046709,0.000000
138.450012,-0.030533,-1294.128784,-0.001203,0.001847,0.046925,-0.135817,-0.006919,0.469251,-1294.128784,0.046109,0.000000
138.810013,-0.010429,-1294.039795,-0.001199,0.001829,0.046456,-0.046392,-0.002363,0.464558,-1294.039795,0.045511,0.000000
139.170013,-0.011917,-1294.039795,-0.001199,0.001808,0.045911,-0.053010,-0.002700,0.459108,-1294.039795,0.044913,0.000000
139.530014,-0.006332,-1294.039795,-0.001203,0.001780,0.045216,-0.028168,-0.001435,0.452159,-1294.039795,0.044315,0.000000
139.889999,-0.022713,-1294.039795,-0.001203,0.001763,0.044783,-0.101031,-0.005147,0.447829,-1294.039795,0.043708,0.000000
140.250000,-0.036118,-1294.084351,-0.001207,0.001736,0.044089,-0.160659,-0.008184,0.440895,-1294.084351,0.043108,0.000000
140.610001,-0.031654,-1293.995361,-0.001220,0.001713,0.043499,-0.140806,-0.007173,0.434990,-1293.995361,0.042510,0.000000
140.970001,-0.045799,-1293.995361,-0.001224,0.001693,0.043005,-0.203725,-0.010378,0.430055,-1293.995361,0.041912,0.000000
141.330002,-0.065163,-1294.084351,-0.001220,0.001665,0.042294,-0.289858,-0.014766,0.422939,-1294.084351,0.041314,0.000000
141.690002,-0.065536,-1293.995361,-0.001229,0.001645,0.041782,-0.291521,-0.014851,0.417822,-1293.995361,0.040707,0.000000
142.050003,-0.062927,-1294.039795,-0.001263,0.001618,0.041105,-0.279914,-0.014260,0.411055,-1294.039795,0.040108,0.000000
142.410004,-0.035378,-1294.084351,-0.001285,0.001590,0.040394,-0.157367,-0.008017,0.403939,-1294.084351,0.039510,0.000000
142.770004,-0.033882,-1294.084351,-0.001302,0.001572,0.039935,-0.150715,-0.007678,0.399352,-1294.084351,0.038912,0.000000
143.130005,-0.013031,-1294.084351,-0.001319,0.001560,0.039623,-0.057965,-0.002953,0.396233,-1294.084351,0.038314,0.000000
143.490005,-0.026810,-1294.084351,-0.001350,0.001523,0.038686,-0.119255,-0.006075,0.386862,-1294.084351,0.037707,0.000000
143.850006,-0.027557,-1294.084351,-0.001362,0.001504,0.038193,-0.122581,-0.006245,0.381926,-1294.084351,0.037107,0.000000
144.210007,-0.011169,-1294.039795,-0.001367,0.001482,0.037637,-0.049684,-0.002531,0.376370,-1294.039795,0.036509,0.000000
144.570007,-0.029045,-1294.084351,-0.001401,0.001457,0.037004,-0.129199,-0.006582,0.370042,-1294.084351,0.035911,0.000000
144.930008,0.026070,-1294.039795,-0.001418,0.001425,0.036206,0.115964,0.005907,0.362063,-1294.039795,0.035313,0.000000
145.290009,0.020477,-1293.995361,-0.001418,0.001402,0.035616,0.091088,0.004640,0.356159,-1293.995361,0.034715,0.000000
145.600006,0.004471,-1294.084351,-0.001453,0.001389,0.035269,0.019887,0.001013,0.352692,-1294.084351,0.035192,0.000000