File: Data/Sima compression/P2-11-3re_10302024_165734.csv
Time (sec),S:Load (lbs),S:HL1 (DIM),S:LVDT (in),S:Position (in),Ch:Position (mm),Ch:Load (N),Ch:Stress (MPa),Ch:Strain (mm/mm),Ch:HL1 (DIM),Set Point (),Cycles ()
0.210000,0.007446,-1293.861938,-0.004523,-0.004519,-0.114785,0.033123,0.001687,-1.147853,-1293.861938,-0.114587,0.000000
0.530000,-0.004471,-1293.950806,-0.004514,-0.004444,-0.112887,-0.019887,-0.001013,-1.128868,-1293.950806,-0.112419,0.000000
0.850000,0.013405,-1293.950806,-0.004415,-0.004259,-0.108169,0.059628,0.003038,-1.081693,-1293.950806,-0.107093,0.000000
1.170000,-0.021225,-1293.950806,-0.004186,-0.004051,-0.102887,-0.094413,-0.004810,-1.028871,-1293.950806,-0.101768,0.000000
1.490000,0.038727,-1293.906372,-0.003992,-0.003849,-0.097771,0.172265,0.008776,-0.977714,-1293.906372,-0.096427,0.000000
1.810000,-0.006332,-1293.906372,-0.003777,-0.003635,-0.092317,-0.028168,-0.001435,-0.923166,-1293.906372,-0.091102,0.000000
2.130000,-0.047295,-1293.906372,-0.003566,-0.003421,-0.086888,-0.210377,-0.010717,-0.868876,-1293.906372,-0.085760,0.000000
2.450000,0.033882,-1293.906372,-0.003346,-0.003217,-0.081710,0.150715,0.007678,-0.817098,-1293.906372,-0.080435,0.000000
2.770000,0.180229,-1293.906372,-0.003229,-0.000006,-0.000148,0.801699,0.040841,-0.001484,-1293.906372,0.000051,0.000000
3.090000,0.153419,-1293.906372,-0.003229,-0.000006,-0.000156,0.682444,0.034765,-0.001559,-1293.906372,0.000051,0.000000
3.410000,0.158630,-1293.950806,-0.003247,-0.000005,-0.000121,0.705623,0.035946,-0.001211,-1293.950806,0.000547,0.000000
3.730000,0.192146,-1293.906372,-0.003247,0.000008,0.000200,0.854709,0.043541,0.001998,-1293.906372,0.001084,0.000000
4.050000,0.320610,-1293.950806,-0.003229,0.000024,0.000607,1.426145,0.072651,0.006071,-1293.950806,0.001612,0.000000
4.370000,0.555580,-1293.906372,-0.003203,0.000055,0.001396,2.471344,0.125896,0.013959,-1293.906372,0.002150,0.000000
4.690000,0.810280,-1293.906372,-0.003165,0.000074,0.001873,3.604305,0.183612,0.018728,-1293.906372,0.002680,0.000000
5.010000,1.033333,-1293.861938,-0.003169,0.000091,0.002324,4.596494,0.234157,0.023239,-1293.861938,0.003217,0.000000
5.330000,1.420227,-1293.861938,-0.003156,0.000115,0.002914,6.317485,0.321828,0.029144,-1293.861938,0.003746,0.000000
5.650000,1.834305,-1293.950806,-0.003122,0.000135,0.003434,8.159395,0.415659,0.034337,-1293.950806,0.004285,0.000000
5.970000,2.181732,-1294.039795,-0.003113,0.000150,0.003808,9.704829,0.494388,0.038076,-1294.039795,0.004813,0.000000
6.290000,2.515007,-1293.906372,-0.003104,0.000176,0.004466,11.187310,0.569909,0.044662,-1293.906372,0.005350,0.000000
6.610000,3.182671,-1293.906372,-0.003074,0.000198,0.005020,14.157226,0.721203,0.050203,-1293.906372,0.005880,0.000000
6.930000,3.527855,-1293.906372,-0.003070,0.000215,0.005455,15.692682,0.799423,0.054548,-1293.906372,0.006418,0.000000
7.250000,4.003746,-1293.950806,-0.003048,0.000235,0.005976,17.809551,0.907262,0.059756,-1293.950806,0.006946,0.000000
7.570000,4.701202,-1293.995361,-0.003027,0.000259,0.006583,20.911993,1.065308,0.065827,-1293.995361,0.007483,0.000000
7.890000,5.159966,-1293.950806,-0.003014,0.000278,0.007051,22.952673,1.169265,0.070505,-1293.950806,0.008013,0.000000
8.210000,5.875290,-1293.861938,-0.002997,0.000302,0.007674,26.134594,1.331360,0.076743,-1293.861938,0.008551,0.000000
8.530001,6.340385,-1293.950806,-0.002966,0.000321,0.008151,28.203444,1.436752,0.081511,-1293.950806,0.009079,0.000000
8.850000,6.803619,-1293.906372,-0.002966,0.000341,0.008672,30.264011,1.541722,0.086720,-1293.906372,0.009617,0.000000
9.170000,7.412071,-1293.906372,-0.002936,0.000364,0.009244,32.970539,1.679599,0.092442,-1293.906372,0.010147,0.000000
9.490001,7.859665,-1293.861938,-0.002928,0.000382,0.009712,34.961536,1.781026,0.097120,-1293.861938,0.010684,0.000000
9.810000,8.300926,-1293.906372,-0.002928,0.000403,0.010233,36.924362,1.881017,0.102328,-1293.906372,0.011212,0.000000
10.130000,9.249359,-1293.861938,-0.002889,0.000430,0.010910,41.143204,2.095935,0.109096,-1293.861938,0.011751,0.000000
10.450001,9.632904,-1293.906372,-0.002880,0.000451,0.011447,42.849297,2.182847,0.114470,-1293.906372,0.012280,0.000000
10.770000,9.901009,-1293.950806,-0.002859,0.000468,0.011898,44.041885,2.243601,0.118982,-1293.950806,0.012817,0.000000
11.090000,10.417122,-1293.817383,-0.002846,0.000489,0.012419,46.337673,2.360554,0.124190,-1293.817383,0.013347,0.000000
11.410001,10.799545,-1293.861938,-0.002820,0.000509,0.012931,48.038776,2.447212,0.129307,-1293.861938,0.013885,0.000000
11.730000,10.877747,-1293.861938,-0.002807,0.000522,0.013268,48.386635,2.464933,0.132683,-1293.861938,0.014413,0.000000
12.050000,11.750961,-1293.950806,-0.002802,0.000553,0.014040,52.270885,2.662806,0.140404,-1293.950806,0.014950,0.000000
12.370001,12.083115,-1293.906372,-0.002781,0.000572,0.014517,53.748379,2.738073,0.145173,-1293.906372,0.015480,0.000000
12.690001,12.404472,-1293.861938,-0.002759,0.000595,0.015106,55.177849,2.810894,0.151063,-1293.861938,0.016018,0.000000
13.010000,12.661034,-1293.906372,-0.002738,0.000615,0.015627,56.319092,2.869031,0.156271,-1293.906372,0.016546,0.000000
13.330001,13.020378,-1293.861938,-0.002725,0.000634,0.016113,57.917534,2.950460,0.161131,-1293.861938,0.017084,0.000000
13.650001,13.070648,-1293.861938,-0.002708,0.000649,0.016485,58.141148,2.961851,0.164855,-1293.861938,0.017613,0.000000
13.970000,13.164482,-1293.950806,-0.002695,0.000664,0.016867,58.558540,2.983114,0.168670,-1293.950806,0.018151,0.000000
14.290001,14.182922,-1293.906372,-0.002665,0.000698,0.017718,63.088791,3.213896,0.177179,-1293.906372,0.018679,0.000000
14.610001,14.206009,-1293.861938,-0.002647,0.000718,0.018246,63.191483,3.219128,0.182462,-1293.861938,0.019218,0.000000
14.930000,14.470024,-1293.950806,-0.002639,0.000739,0.018767,64.365883,3.278954,0.187670,-1293.950806,0.019747,0.000000
15.250001,14.865479,-1293.906372,-0.002621,0.000764,0.019417,66.124954,3.368566,0.194165,-1293.906372,0.020284,0.000000
15.570001,14.893410,-1293.995361,-0.002596,0.000783,0.019886,66.249199,3.374895,0.198858,-1293.995361,0.020814,0.000000
15.890000,14.559387,-1293.861938,-0.002591,0.000791,0.020102,64.763390,3.299204,0.201023,-1293.861938,0.021351,0.000000
16.210001,15.231895,-1293.906372,-0.002557,0.000821,0.020856,67.754852,3.451597,0.208563,-1293.906372,0.021880,0.000000
16.530001,15.564796,-1293.861938,-0.002548,0.000844,0.021429,69.235672,3.527033,0.214286,-1293.861938,0.022417,0.000000
16.850000,15.389038,-1293.861938,-0.002548,0.000858,0.021784,68.453857,3.487206,0.217843,-1293.861938,0.022947,0.000000
17.170000,15.940147,-1293.906372,-0.002518,0.000885,0.022470,70.905319,3.612089,0.224702,-1293.906372,0.023485,0.000000
17.490002,16.075317,-1293.950806,-0.002488,0.000903,0.022938,71.506584,3.642719,0.229380,-1293.950806,0.024013,0.000000
17.810001,15.887268,-1293.906372,-0.002471,0.000917,0.023294,70.670097,3.600106,0.232938,-1293.906372,0.024550,0.000000
18.130001,16.885971,-1293.906372,-0.002445,0.000953,0.024196,75.112549,3.826416,0.241961,-1293.906372,0.025080,0.000000
18.450001,16.732925,-1293.906372,-0.002432,0.000972,0.024681,74.431770,3.791735,0.246805,-1293.906372,0.025618,0.000000
18.770000,16.639465,-1293.950806,-0.002423,0.000989,0.025115,74.016037,3.770557,0.251150,-1293.950806,0.026146,0.000000
19.090000,16.732925,-1293.906372,-0.002397,0.001007,0.025566,74.431770,3.791735,0.255662,-1293.906372,0.026685,0.000000
19.410002,17.253502,-1293.817383,-0.002389,0.001031,0.026190,76.747406,3.909699,0.261900,-1293.817383,0.027213,0.000000
19.730001,16.888206,-1293.861938,-0.002367,0.001044,0.026520,75.122498,3.826922,0.265200,-1293.861938,0.027751,0.000000
20.050001,17.882812,-1293.861938,-0.002358,0.001081,0.027465,79.546722,4.052303,0.274647,-1293.861938,0.028281,0.000000
20.370001,17.570770,-1293.861938,-0.002328,0.001097,0.027855,78.158691,3.981594,0.278553,-1293.861938,0.028818,0.000000
20.690001,17.679871,-1293.906372,-0.002307,0.001118,0.028393,78.643990,4.006316,0.283928,-1293.906372,0.029347,0.000000
21.010000,18.037354,-1293.861938,-0.002298,0.001141,0.028974,80.234154,4.087323,0.289741,-1293.861938,0.029884,0.000000
21.330002,17.778549,-1293.817383,-0.002285,0.001154,0.029312,79.082939,4.028677,0.293117,-1293.817383,0.030414,0.000000
21.650002,17.902550,-1293.861938,-0.002268,0.001172,0.029772,79.634521,4.056776,0.297720,-1293.861938,0.030951,0.000000
21.970001,18.938118,-1293.906372,-0.002233,0.001208,0.030673,84.240959,4.291439,0.306728,-1293.906372,0.031480,0.000000
22.290001,18.609314,-1293.950806,-0.002229,0.001225,0.031116,82.778366,4.216931,0.311164,-1293.950806,0.032017,0.000000
22.610001,18.591064,-1293.906372,-0.002212,0.001243,0.031584,82.697182,4.212796,0.315842,-1293.906372,0.032547,0.000000
22.930000,18.793640,-1293.906372,-0.002177,0.001265,0.032122,83.598289,4.258699,0.321216,-1293.906372,0.033085,0.000000
23.250002,18.909073,-1293.817383,-0.002186,0.001283,0.032589,84.111755,4.284857,0.325895,-1293.817383,0.033613,0.000000
23.570002,18.808159,-1293.861938,-0.002169,0.001298,0.032980,83.662872,4.261990,0.329801,-1293.861938,0.034152,0.000000
23.890001,19.840004,-1293.861938,-0.002143,0.001334,0.033873,88.252747,4.495809,0.338733,-1293.861938,0.034680,0.000000
24.210001,19.345863,-1293.861938,-0.002121,0.001349,0.034264,86.054695,4.383835,0.342639,-1293.861938,0.035218,0.000000
24.530001,19.446037,-1293.861938,-0.002108,0.001368,0.034757,86.500298,4.406535,0.347574,-1293.861938,0.035746,0.000000
24.850000,19.896233,-1293.772949,-0.002104,0.001392,0.035348,88.502861,4.508551,0.353479,-1293.772949,0.036285,0.000000
25.170002,19.934212,-1293.861938,-0.002078,0.001408,0.035764,88.671799,4.517157,0.357642,-1293.861938,0.036813,0.000000
25.490002,19.808350,-1293.950806,-0.002057,0.001422,0.036120,88.111938,4.488636,0.361200,-1293.950806,0.037351,0.000000
25.810001,21.397636,-1293.906372,-0.002035,0.001461,0.037118,95.181442,4.848774,0.371177,-1293.906372,0.037881,0.000000
26.130001,20.749710,-1293.861938,-0.002022,0.001477,0.037507,92.299316,4.701952,0.375068,-1293.861938,0.038418,0.000000
26.450001,20.597038,-1293.817383,-0.002009,0.001494,0.037949,91.620201,4.667356,0.379489,-1293.817383,0.038947,0.000000
26.770000,21.160439,-1293.817383,-0.002005,0.001520,0.038600,94.126335,4.795024,0.385999,-1293.817383,0.039484,0.000000
27.090002,21.074417,-1293.906372,-0.001979,0.001537,0.039042,93.743690,4.775531,0.390419,-1293.906372,0.040014,0.000000
27.410002,20.909088,-1293.906372,-0.001957,0.001551,0.039389,93.008270,4.738067,0.393886,-1293.906372,0.040551,0.000000
27.730001,21.880608,-1293.817383,-0.001944,0.001580,0.040144,97.329803,4.958217,0.401441,-1293.817383,0.041080,0.000000
28.050001,21.835922,-1293.861938,-0.001923,0.001600,0.040647,97.131035,4.948091,0.406467,-1293.861938,0.041617,0.000000
28.370001,21.983009,-1293.772949,-0.001906,0.001620,0.041158,97.785309,4.981421,0.411585,-1293.772949,0.042147,0.000000
28.690001,22.227287,-1293.817383,-0.001893,0.001644,0.041747,98.871910,5.036776,0.417474,-1293.817383,0.042685,0.000000
29.010002,22.413841,-1293.950806,-0.001863,0.001663,0.042242,99.701744,5.079049,0.422425,-1293.950806,0.043213,0.000000
29.330002,22.236595,-1293.772949,-0.001854,0.001677,0.042589,98.913315,5.038884,0.425892,-1293.772949,0.043752,0.000000
29.650002,22.957138,-1293.817383,-0.001845,0.001706,0.043326,102.118454,5.202162,0.433264,-1293.817383,0.044280,0.000000
29.970001,23.123215,-1293.861938,-0.001824,0.001727,0.043855,102.857193,5.239796,0.438548,-1293.861938,0.044818,0.000000
30.290001,23.291527,-1293.906372,-0.001807,0.001745,0.044332,103.605888,5.277935,0.443317,-1293.906372,0.045348,0.000000
30.610001,23.846733,-1293.906372,-0.001802,0.001771,0.044974,106.075569,5.403747,0.449736,-1293.906372,0.045885,0.000000
30.930002,23.725708,-1293.906372,-0.001785,0.001788,0.045408,105.537224,5.376322,0.454081,-1293.906372,0.046413,0.000000
31.250002,23.966637,-1293.817383,-0.001768,0.001807,0.045902,106.608925,5.430917,0.459017,-1293.817383,0.046951,0.000000
31.570002,24.813042,-1293.817383,-0.001750,0.001836,0.046639,110.373924,5.622715,0.466390,-1293.817383,0.047481,0.000000
31.890001,24.669678,-1293.950806,-0.001720,0.001854,0.047090,109.736206,5.590229,0.470901,-1293.950806,0.048018,0.000000
32.210003,24.870758,-1293.861938,-0.001712,0.001875,0.047637,110.630653,5.635795,0.476367,-1293.861938,0.048547,0.000000
32.530003,25.267334,-1293.817383,-0.001681,0.001895,0.048139,112.394714,5.725660,0.481393,-1293.817383,0.049084,0.000000
32.850002,25.525757,-1293.817383,-0.001694,0.001916,0.048660,113.544235,5.784219,0.486601,-1293.817383,0.049614,0.000000
33.170002,25.554062,-1293.861938,-0.001677,0.001932,0.049067,113.670143,5.790633,0.490674,-1293.861938,0.050151,0.000000
33.490002,26.556488,-1293.861938,-0.001656,0.001960,0.049796,118.129158,6.017787,0.497956,-1293.861938,0.050680,0.000000
33.810001,26.480148,-1293.906372,-0.001647,0.001978,0.050230,117.789581,6.000487,0.502301,-1293.906372,0.051219,0.000000
34.130001,27.025673,-1293.906372,-0.001621,0.002001,0.050837,120.216194,6.124105,0.508372,-1293.906372,0.051747,0.000000
34.450001,27.051743,-1293.817383,-0.001604,0.002018,0.051261,120.332161,6.130013,0.512611,-1293.817383,0.052285,0.000000
34.770000,27.107971,-1293.861938,-0.001595,0.002039,0.051799,120.582275,6.142754,0.517986,-1293.861938,0.052814,0.000000
35.090000,27.579765,-1293.817383,-0.001582,0.002057,0.052250,122.680923,6.249664,0.522497,-1293.817383,0.053352,0.000000
35.410000,27.100899,-1293.861938,-0.001569,0.002067,0.052501,120.550819,6.141151,0.525010,-1293.861938,0.053880,0.000000
35.730003,28.544586,-1293.817383,-0.001548,0.002102,0.053387,126.972664,6.468296,0.533867,-1293.817383,0.054418,0.000000
36.050003,28.847321,-1293.772949,-0.001535,0.002122,0.053906,128.319290,6.536896,0.539060,-1293.772949,0.054948,0.000000
36.370003,29.383163,-1293.817383,-0.001509,0.002145,0.054487,130.702835,6.658320,0.544873,-1293.817383,0.055485,0.000000
36.690002,30.101845,-1293.861938,-0.001513,0.002169,0.055085,133.899689,6.821176,0.550854,-1293.861938,0.056013,0.000000
37.010002,29.876556,-1293.817383,-0.001479,0.002184,0.055485,132.897568,6.770124,0.554850,-1293.817383,0.056551,0.000000
37.330002,30.262337,-1293.861938,-0.001475,0.002206,0.056039,134.613602,6.857543,0.560392,-1293.861938,0.057081,0.000000
37.650002,30.767647,-1293.817383,-0.001453,0.002225,0.056508,136.861328,6.972048,0.565085,-1293.817383,0.057618,0.000000
37.970001,31.328812,-1293.817383,-0.001453,0.002247,0.057072,139.357513,7.099210,0.570717,-1293.817383,0.058147,0.000000
38.290001,31.756294,-1293.772949,-0.001431,0.002267,0.057592,141.259048,7.196079,0.575925,-1293.772949,0.058686,0.000000
38.610001,32.291397,-1293.861938,-0.001414,0.002289,0.058147,143.639313,7.317335,0.581466,-1293.861938,0.059214,0.000000
38.930000,33.120293,-1293.861938,-0.001384,0.002312,0.058737,147.326416,7.505166,0.587370,-1293.861938,0.059751,0.000000
39.250000,33.796150,-1293.817383,-0.001384,0.002335,0.059309,150.332779,7.658317,0.593093,-1293.817383,0.060281,0.000000
39.570004,34.464188,-1293.817383,-0.001384,0.002358,0.059891,153.304367,7.809697,0.598907,-1293.817383,0.060819,0.000000
39.890003,34.324173,-1293.817383,-0.001371,0.002374,0.060289,152.681549,7.777969,0.602888,-1293.817383,0.061347,0.000000
40.210003,34.724480,-1293.906372,-0.001337,0.002394,0.060801,154.462204,7.868680,0.608006,-1293.906372,0.061885,0.000000
40.530003,35.711266,-1293.817383,-0.001328,0.002416,0.061373,158.851639,8.092288,0.613728,-1293.817383,0.062414,0.000000
40.850002,36.295517,-1293.772949,-0.001298,0.002437,0.061910,161.450516,8.224681,0.619103,-1293.772949,0.062952,0.000000
41.170002,36.546867,-1293.772949,-0.001298,0.002462,0.062545,162.568588,8.281638,0.625446,-1293.772949,0.063480,0.000000
41.490002,38.300743,-1293.861938,-0.001285,0.002486,0.063152,170.370209,8.679072,0.631517,-1293.861938,0.064018,0.000000
41.810001,38.295532,-1293.817383,-0.001281,0.002503,0.063585,170.347031,8.677892,0.635847,-1293.817383,0.064548,0.000000
42.130001,38.926331,-1293.817383,-0.001259,0.002522,0.064062,173.152969,8.820832,0.640616,-1293.817383,0.065085,0.000000
42.450001,39.737358,-1293.861938,-0.001250,0.002544,0.064608,176.760590,9.004614,0.646082,-1293.861938,0.065613,0.000000
42.770000,39.920189,-1293.772949,-0.001246,0.002562,0.065076,177.573868,9.046044,0.650760,-1293.772949,0.066152,0.000000
43.090000,40.405388,-1293.861938,-0.001224,0.002580,0.065527,179.732147,9.155993,0.655271,-1293.861938,0.066681,0.000000
43.410004,42.713730,-1293.906372,-0.001212,0.002612,0.066343,190.000153,9.679070,0.663432,-1293.906372,0.067218,0.000000
43.730003,43.105835,-1293.861938,-0.001194,0.002631,0.066828,191.744324,9.767921,0.668276,-1293.861938,0.067748,0.000000
44.050003,43.815948,-1293.772949,-0.001190,0.002649,0.067288,194.903076,9.928836,0.672879,-1293.772949,0.068286,0.000000
44.370003,44.720818,-1293.817383,-0.001186,0.002671,0.067843,198.928131,10.133883,0.678435,-1293.817383,0.068814,0.000000
44.690002,45.444710,-1293.817383,-0.001168,0.002692,0.068372,202.148163,10.297918,0.683719,-1293.817383,0.069351,0.000000
45.010002,46.325745,-1293.861938,-0.001160,0.002712,0.068893,206.067200,10.497563,0.688927,-1293.861938,0.069881,0.000000
45.330002,48.155579,-1293.817383,-0.001151,0.002738,0.069535,214.206711,10.912210,0.695346,-1293.817383,0.070419,0.000000
45.650002,48.592369,-1293.817383,-0.001143,0.002754,0.069951,216.149658,11.011189,0.699509,-1293.817383,0.070947,0.000000
45.970001,49.312538,-1293.817383,-0.001108,0.002772,0.070410,219.353119,11.174381,0.704096,-1293.817383,0.071485,0.000000
46.290001,50.671700,-1293.861938,-0.001112,0.002794,0.070973,225.398972,11.482371,0.709728,-1293.861938,0.072014,0.000000
46.610001,51.579918,-1293.906372,-0.001117,0.002814,0.071468,229.438934,11.688176,0.714679,-1293.906372,0.072552,0.000000
46.930004,51.887871,-1293.861938,-0.001091,0.002824,0.071728,230.808777,11.757959,0.717283,-1293.861938,0.073080,0.000000
47.250004,55.142776,-1293.817383,-0.001069,0.002866,0.072787,245.287323,12.495531,0.727866,-1293.817383,0.073619,0.000000
47.570004,55.628349,-1293.817383,-0.001061,0.002881,0.073168,247.447250,12.605564,0.731681,-1293.817383,0.074148,0.000000
47.890003,56.723122,-1293.861938,-0.001065,0.002900,0.073662,252.317047,12.853643,0.736616,-1293.861938,0.074685,0.000000
48.210003,58.237938,-1293.861938,-0.001056,0.002922,0.074217,259.055298,13.196905,0.742172,-1293.861938,0.075215,0.000000
48.530003,59.158066,-1293.906372,-0.001048,0.002939,0.074650,263.148224,13.405409,0.746502,-1293.906372,0.075752,0.000000
48.850002,59.817169,-1293.861938,-0.001035,0.002955,0.075067,266.080048,13.554765,0.750666,-1293.861938,0.076281,0.000000
49.170002,62.525803,-1293.906372,-0.001009,0.002987,0.075874,278.128662,14.168550,0.758735,-1293.906372,0.076818,0.000000
49.490002,63.691338,-1293.861938,-0.001013,0.003005,0.076332,283.313232,14.432663,0.763322,-1293.861938,0.077348,0.000000
49.810001,64.879204,-1293.950806,-0.000996,0.003023,0.076783,288.597107,14.701838,0.767834,-1293.950806,0.077886,0.000000
50.130001,65.962059,-1293.861938,-0.000992,0.003033,0.077035,293.413879,14.947217,0.770347,-1293.861938,0.077260,0.000000
50.450001,65.222527,-1293.861938,-0.000983,0.003033,0.077035,290.124298,14.779635,0.770347,-1293.861938,294.500488,0.000000
50.770004,65.915504,-1293.817383,-0.000970,0.003045,0.077339,293.206818,14.936666,0.773390,-1293.817383,294.500488,0.000000
51.090004,65.307060,-1293.861938,-0.000961,0.003046,0.077365,290.500305,14.798792,0.773648,-1293.861938,294.500488,0.000000
51.410004,65.204659,-1293.861938,-0.000979,0.003053,0.077546,290.044800,14.775586,0.775464,-1293.861938,294.500488,0.000000
51.730003,65.248222,-1293.950806,-0.000961,0.003058,0.077669,290.238586,14.785459,0.776691,-1293.950806,294.500488,0.000000
52.050003,65.209114,-1293.906372,-0.000953,0.003062,0.077772,290.064636,14.776596,0.777720,-1293.906372,294.500488,0.000000
52.370003,64.961861,-1293.861938,-0.000953,0.003063,0.077790,288.964783,14.720568,0.777902,-1293.861938,294.500488,0.000000
52.690002,65.648888,-1293.817383,-0.000961,0.003073,0.078042,292.020844,14.876251,0.780415,-1293.817383,294.500488,0.000000
53.010002,65.467171,-1293.906372,-0.000961,0.003073,0.078042,291.212524,14.835073,0.780415,-1293.906372,294.500488,0.000000
53.330002,65.249336,-1293.906372,-0.000957,0.003073,0.078051,290.243530,14.785711,0.780506,-1293.906372,294.500488,0.000000
53.650002,65.090706,-1293.950806,-0.000970,0.003074,0.078085,289.537933,14.749764,0.780854,-1293.950806,294.500488,0.000000
53.970001,64.907875,-1293.906372,-0.000957,0.003075,0.078093,288.724640,14.708335,0.780930,-1293.906372,294.500488,0.000000
54.290001,65.278755,-1293.861938,-0.000940,0.003081,0.078258,290.374420,14.792377,0.782580,-1293.861938,294.500488,0.000000
54.610004,65.169655,-1293.861938,-0.000949,0.003081,0.078258,289.889099,14.767654,0.782580,-1293.861938,294.500488,0.000000
54.930004,65.011391,-1293.950806,-0.000953,0.003081,0.078258,289.185120,14.731791,0.782580,-1293.950806,294.500488,0.000000
55.250004,65.094795,-1293.950806,-0.000949,0.003084,0.078337,289.556122,14.750691,0.783367,-1293.950806,294.500488,0.000000
55.570004,65.009163,-1293.906372,-0.000931,0.003084,0.078344,289.175201,14.731286,0.783443,-1293.906372,294.500488,0.000000
55.890003,65.314873,-1293.817383,-0.000944,0.003090,0.078474,290.535065,14.800561,0.784745,-1293.817383,294.500488,0.000000
56.210003,65.249336,-1293.906372,-0.000936,0.003090,0.078474,290.243530,14.785711,0.784745,-1293.906372,294.500488,0.000000
56.530003,65.157738,-1293.906372,-0.000949,0.003090,0.078484,289.836090,14.764955,0.784836,-1293.906372,294.500488,0.000000
56.850002,65.249702,-1293.950806,-0.000940,0.003093,0.078570,290.245178,14.785793,0.785699,-1293.950806,294.500488,0.000000
57.170002,65.246361,-1293.950806,-0.000927,0.003093,0.078570,290.230316,14.785036,0.785699,-1293.950806,294.500488,0.000000
57.490002,65.142464,-1293.906372,-0.000931,0.003093,0.078570,289.768158,14.761494,0.785699,-1293.906372,294.500488,0.000000
57.810001,65.230339,-1293.861938,-0.000940,0.003096,0.078630,290.159027,14.781406,0.786304,-1293.861938,294.500488,0.000000
58.130001,65.171883,-1293.995361,-0.000940,0.003096,0.078640,289.899017,14.768160,0.786395,-1293.995361,294.500488,0.000000
58.450005,65.185661,-1293.950806,-0.000931,0.003097,0.078665,289.960297,14.771281,0.786653,-1293.950806,294.500488,0.000000
58.770004,65.246727,-1293.950806,-0.000931,0.003099,0.078726,290.231934,14.785120,0.787258,-1293.950806,294.500488,0.000000
59.090004,65.223640,-1293.861938,-0.000918,0.003099,0.078726,290.129242,14.779888,0.787258,-1293.861938,294.500488,0.000000
59.410004,65.197578,-1293.906372,-0.000931,0.003100,0.078735,290.013306,14.773982,0.787349,-1293.906372,294.500488,0.000000
59.730003,65.282845,-1293.906372,-0.000931,0.003102,0.078795,290.392609,14.793304,0.787955,-1293.906372,294.500488,0.000000
60.050003,65.248222,-1293.995361,-0.000931,0.003102,0.078795,290.238586,14.785459,0.787955,-1293.995361,294.500488,0.000000
60.370003,65.338341,-1293.861938,-0.000918,0.003105,0.078856,290.639465,14.805880,0.788560,-1293.861938,294.500488,0.000000
60.690002,65.317116,-1293.906372,-0.000914,0.003105,0.078856,290.545044,14.801069,0.788560,-1293.906372,294.500488,0.000000
61.010002,65.294029,-1293.906372,-0.000923,0.003105,0.078865,290.442352,14.795838,0.788651,-1293.906372,294.500488,0.000000
61.330002,65.287697,-1293.950806,-0.000931,0.003106,0.078891,290.414185,14.794403,0.788908,-1293.950806,294.500488,0.000000
61.650002,65.294029,-1293.950806,-0.000923,0.003106,0.078900,290.442352,14.795838,0.788999,-1293.950806,294.500488,0.000000
61.970001,65.272789,-1293.906372,-0.000927,0.003107,0.078909,290.347870,14.791025,0.789090,-1293.906372,294.500488,0.000000
62.290005,65.235939,-1293.906372,-0.000927,0.003107,0.078917,290.183960,14.782675,0.789166,-1293.906372,294.500488,0.000000
62.610004,65.210976,-1293.817383,-0.000931,0.003107,0.078926,290.072906,14.777019,0.789257,-1293.817383,294.500488,0.000000
62.930004,65.162941,-1293.906372,-0.000927,0.003107,0.078926,289.859253,14.766133,0.789257,-1293.906372,294.500488,0.000000
63.250004,65.142464,-1293.950806,-0.000923,0.003108,0.078944,289.768158,14.761494,0.789438,-1293.950806,294.500488,0.000000
63.570004,65.276527,-1293.906372,-0.000914,0.003110,0.079004,290.364502,14.791872,0.790044,-1293.906372,294.500488,0.000000
63.890003,65.255669,-1293.906372,-0.000927,0.003110,0.079004,290.271698,14.787147,0.790044,-1293.906372,294.500488,0.000000
64.210007,65.219917,-1293.950806,-0.000927,0.003110,0.079004,290.112671,14.779044,0.790044,-1293.950806,294.500488,0.000000
64.530006,65.194969,-1293.906372,-0.000918,0.003110,0.079004,290.001709,14.773392,0.790044,-1293.906372,294.500488,0.000000
64.850006,65.180077,-1293.906372,-0.000923,0.003111,0.079021,289.935455,14.770016,0.790210,-1293.906372,294.500488,0.000000
65.170006,65.179710,-1293.906372,-0.000914,0.003112,0.079039,289.933838,14.769934,0.790392,-1293.906372,294.500488,0.000000
65.490005,65.246361,-1293.861938,-0.000910,0.003114,0.079100,290.230316,14.785036,0.790998,-1293.861938,294.500488,0.000000
65.810005,65.309654,-1293.861938,-0.000918,0.003114,0.079100,290.511841,14.799379,0.790998,-1293.861938,294.500488,0.000000
66.130005,65.286949,-1293.861938,-0.000927,0.003114,0.079100,290.410858,14.794234,0.790998,-1293.861938,294.500488,0.000000
66.450005,65.259026,-1293.906372,-0.000931,0.003114,0.079100,290.286652,14.787907,0.790998,-1293.906372,294.500488,0.000000
66.770004,65.262367,-1293.861938,-0.000914,0.003114,0.079107,290.301514,14.788664,0.791073,-1293.861938,294.500488,0.000000
67.090004,65.258644,-1293.817383,-0.000910,0.003116,0.079142,290.284943,14.787820,0.791422,-1293.817383,294.500488,0.000000
67.410004,65.280983,-1293.861938,-0.000914,0.003116,0.079151,290.384308,14.792882,0.791512,-1293.861938,294.500488,0.000000
67.730003,65.266838,-1293.950806,-0.000923,0.003116,0.079151,290.321381,14.789678,0.791512,-1293.950806,294.500488,0.000000
68.050003,65.273537,-1293.995361,-0.000914,0.003117,0.079160,290.351196,14.791195,0.791603,-1293.995361,294.500488,0.000000
68.370003,65.257530,-1293.950806,-0.000927,0.003117,0.079160,290.279999,14.787567,0.791603,-1293.950806,294.500488,0.000000
68.690002,65.225883,-1293.906372,-0.000910,0.003117,0.079169,290.139221,14.780396,0.791694,-1293.906372,294.500488,0.000000
69.010002,65.253059,-1293.861938,-0.000914,0.003118,0.079186,290.260101,14.786554,0.791861,-1293.861938,294.500488,0.000000
69.330002,65.232948,-1293.861938,-0.000918,0.003118,0.079195,290.170654,14.781998,0.791951,-1293.861938,294.500488,0.000000
69.650002,65.224754,-1293.906372,-0.000910,0.003118,0.079195,290.134186,14.780140,0.791951,-1293.906372,294.500488,0.000000
69.970001,65.199440,-1293.906372,-0.000918,0.003118,0.079195,290.021606,14.774405,0.791951,-1293.906372,294.500488,0.000000
70.290001,65.200188,-1293.906372,-0.000905,0.003119,0.079230,290.024933,14.774573,0.792300,-1293.906372,294.500488,0.000000
70.610001,65.222160,-1293.861938,-0.000901,0.003119,0.079230,290.122650,14.779552,0.792300,-1293.861938,294.500488,0.000000
70.930000,65.225136,-1293.906372,-0.000918,0.003119,0.079230,290.135895,14.780228,0.792300,-1293.906372,294.500488,0.000000
71.250000,65.207634,-1293.906372,-0.000901,0.003120,0.079238,290.058044,14.776261,0.792375,-1293.906372,294.500488,0.000000
71.570000,65.215080,-1293.906372,-0.000905,0.003121,0.079272,290.091156,14.777948,0.792724,-1293.906372,294.500488,0.000000
71.890007,65.254921,-1293.861938,-0.000927,0.003121,0.079281,290.268372,14.786977,0.792814,-1293.861938,294.500488,0.000000
72.210007,65.255302,-1293.817383,-0.000905,0.003121,0.079281,290.270081,14.787063,0.792814,-1293.817383,294.500488,0.000000
72.530006,65.238533,-1293.906372,-0.000910,0.003121,0.079281,290.195496,14.783262,0.792814,-1293.906372,294.500488,0.000000
72.850006,65.230339,-1293.995361,-0.000910,0.003121,0.079281,290.159027,14.781406,0.792814,-1293.995361,294.500488,0.000000
73.170006,65.207253,-1293.906372,-0.000914,0.003121,0.079281,290.056335,14.776175,0.792814,-1293.906372,294.500488,0.000000
73.490005,65.214333,-1293.950806,-0.000901,0.003123,0.079316,290.087830,14.777779,0.793163,-1293.950806,294.500488,0.000000
73.810005,65.254173,-1293.861938,-0.000905,0.003123,0.079333,290.265045,14.786807,0.793329,-1293.861938,294.500488,0.000000
74.130005,65.266090,-1293.861938,-0.000927,0.003123,0.079333,290.318085,14.789508,0.793329,-1293.861938,294.500488,0.000000
74.450005,65.257164,-1293.950806,-0.000918,0.003124,0.079342,290.278351,14.787484,0.793420,-1293.950806,294.500488,0.000000
74.770004,65.252312,-1293.950806,-0.000910,0.003124,0.079342,290.256775,14.786386,0.793420,-1293.950806,294.500488,0.000000
75.090004,65.245247,-1293.906372,-0.000897,0.003124,0.079351,290.225342,14.784784,0.793511,-1293.906372,294.500488,0.000000
75.410004,65.236671,-1293.906372,-0.000901,0.003124,0.079360,290.187195,14.782842,0.793602,-1293.906372,294.500488,0.000000
75.730003,65.236305,-1293.950806,-0.000905,0.003124,0.079360,290.185577,14.782759,0.793602,-1293.950806,294.500488,0.000000
76.050003,65.207634,-1293.950806,-0.000901,0.003124,0.079360,290.058044,14.776261,0.793602,-1293.950806,294.500488,0.000000
76.370003,65.205391,-1293.950806,-0.000905,0.003124,0.079360,290.048065,14.775753,0.793602,-1293.950806,294.500488,0.000000
76.690002,65.202049,-1293.906372,-0.000910,0.003126,0.079403,290.033203,14.774996,0.794026,-1293.906372,294.500488,0.000000
77.010002,65.261253,-1293.861938,-0.000905,0.003126,0.079412,290.296539,14.788412,0.794116,-1293.861938,294.500488,0.000000
77.330002,65.272423,-1293.906372,-0.000914,0.003126,0.079412,290.346252,14.790943,0.794116,-1293.906372,294.500488,0.000000
77.650002,65.257896,-1293.950806,-0.000918,0.003126,0.079412,290.281616,14.787651,0.794116,-1293.950806,294.500488,0.000000
77.970001,65.256783,-1293.950806,-0.000910,0.003126,0.079412,290.276672,14.787398,0.794116,-1293.950806,294.500488,0.000000
78.290001,65.245613,-1293.995361,-0.000897,0.003126,0.079412,290.226990,14.784867,0.794116,-1293.995361,294.500488,0.000000
78.610001,65.222160,-1293.950806,-0.000901,0.003126,0.079412,290.122650,14.779552,0.794116,-1293.950806,294.500488,0.000000
78.930000,65.202415,-1293.906372,-0.000918,0.003126,0.079412,290.034821,14.775078,0.794116,-1293.906372,294.500488,0.000000
79.250000,65.183434,-1293.906372,-0.000910,0.003127,0.079437,289.950378,14.770777,0.794374,-1293.906372,294.500488,0.000000
79.570007,65.252312,-1293.906372,-0.000897,0.003128,0.079463,290.256775,14.786386,0.794631,-1293.906372,294.500488,0.000000
79.890007,65.260887,-1293.906372,-0.000905,0.003128,0.079463,290.294922,14.788328,0.794631,-1293.906372,294.500488,0.000000
80.210007,65.273537,-1293.861938,-0.000901,0.003128,0.079463,290.351196,14.791195,0.794631,-1293.861938,294.500488,0.000000
80.530006,65.260887,-1293.906372,-0.000918,0.003128,0.079463,290.294922,14.788328,0.794631,-1293.906372,294.500488,0.000000
80.850006,65.245613,-1293.950806,-0.000918,0.003128,0.079463,290.226990,14.784867,0.794631,-1293.950806,294.500488,0.000000
81.170006,65.256783,-1293.950806,-0.000914,0.003129,0.079472,290.276672,14.787398,0.794722,-1293.950806,294.500488,0.000000
81.490005,65.244499,-1293.995361,-0.000892,0.003129,0.079481,290.222015,14.784615,0.794813,-1293.995361,294.500488,0.000000
81.810005,65.247108,-1293.906372,-0.000910,0.003129,0.079481,290.233643,14.785206,0.794813,-1293.906372,294.500488,0.000000
82.130005,65.247475,-1293.906372,-0.000910,0.003130,0.079498,290.235260,14.785289,0.794979,-1293.906372,294.500488,0.000000
82.450005,65.241524,-1293.995361,-0.000910,0.003130,0.079498,290.208801,14.783940,0.794979,-1293.995361,294.500488,0.000000
82.770004,65.251198,-1293.950806,-0.000905,0.003130,0.079507,290.251831,14.786133,0.795070,-1293.950806,294.500488,0.000000
83.090004,65.278008,-1293.950806,-0.000914,0.003131,0.079524,290.371094,14.792209,0.795237,-1293.950806,294.500488,0.000000
83.410004,65.279503,-1293.861938,-0.000905,0.003131,0.079524,290.377716,14.792547,0.795237,-1293.861938,294.500488,0.000000
83.730003,65.270195,-1293.950806,-0.000914,0.003131,0.079524,290.336334,14.790438,0.795237,-1293.950806,294.500488,0.000000
84.050003,65.263115,-1293.906372,-0.000914,0.003131,0.079524,290.304840,14.788833,0.795237,-1293.906372,294.500488,0.000000
84.370003,65.267952,-1293.995361,-0.000914,0.003131,0.079524,290.326355,14.789929,0.795237,-1293.995361,294.500488,0.000000
84.690002,65.243752,-1293.950806,-0.000897,0.003131,0.079524,290.218689,14.784445,0.795237,-1293.950806,294.500488,0.000000
85.010002,65.249702,-1293.906372,-0.000910,0.003131,0.079524,290.245178,14.785793,0.795237,-1293.906372,294.500488,0.000000
85.330002,65.270561,-1293.950806,-0.000897,0.003133,0.079568,290.337952,14.790521,0.795676,-1293.950806,294.500488,0.000000
85.650002,65.281364,-1293.995361,-0.000914,0.003133,0.079568,290.386017,14.792969,0.795676,-1293.995361,294.500488,0.000000
85.970001,65.294029,-1293.950806,-0.000897,0.003133,0.079568,290.442352,14.795838,0.795676,-1293.950806,294.500488,0.000000
86.290001,65.281731,-1293.906372,-0.000897,0.003133,0.079568,290.387634,14.793052,0.795676,-1293.906372,294.500488,0.000000
86.610001,65.274284,-1293.906372,-0.000901,0.003133,0.079568,290.354523,14.791364,0.795676,-1293.906372,294.500488,0.000000
86.930008,65.259026,-1293.950806,-0.000905,0.003133,0.079568,290.286652,14.787907,0.795676,-1293.950806,294.500488,0.000000
87.250008,65.271675,-1293.950806,-0.000905,0.003133,0.079577,290.342926,14.790773,0.795767,-1293.950806,294.500488,0.000000
87.570007,65.269447,-1293.995361,-0.000901,0.003133,0.079586,290.333008,14.790268,0.795857,-1293.995361,294.500488,0.000000
87.890007,65.279503,-1293.950806,-0.000897,0.003133,0.079586,290.377716,14.792547,0.795857,-1293.950806,294.500488,0.000000
88.210007,65.268700,-1293.861938,-0.000892,0.003134,0.079593,290.329681,14.790098,0.795933,-1293.861938,294.500488,0.000000
88.530006,65.270195,-1293.861938,-0.000905,0.003134,0.079593,290.336334,14.790438,0.795933,-1293.861938,294.500488,0.000000
88.850006,65.255669,-1293.906372,-0.000905,0.003134,0.079593,290.271698,14.787147,0.795933,-1293.906372,294.500488,0.000000
89.170006,65.263481,-1293.950806,-0.000888,0.003134,0.079593,290.306458,14.788917,0.795933,-1293.950806,294.500488,0.000000
89.490005,65.258278,-1293.950806,-0.000892,0.003134,0.079593,290.283325,14.787737,0.795933,-1293.950806,294.500488,0.000000
89.810005,65.229225,-1293.950806,-0.000901,0.003134,0.079611,290.154083,14.781154,0.796115,-1293.950806,294.500488,0.000000
90.130005,65.242638,-1293.906372,-0.000914,0.003134,0.079611,290.213745,14.784193,0.796115,-1293.906372,294.500488,0.000000
90.450005,65.246361,-1293.861938,-0.000910,0.003134,0.079611,290.230316,14.785036,0.796115,-1293.861938,294.500488,0.000000
90.770004,65.236305,-1293.995361,-0.000897,0.003134,0.079611,290.185577,14.782759,0.796115,-1293.995361,294.500488,0.000000
91.090004,65.225502,-1293.950806,-0.000884,0.003135,0.079619,290.137512,14.780310,0.796191,-1293.950806,294.500488,0.000000
91.410004,65.239662,-1293.861938,-0.000901,0.003135,0.079619,290.200500,14.783519,0.796191,-1293.861938,294.500488,0.000000
91.730003,65.215446,-1293.906372,-0.000897,0.003135,0.079619,290.092804,14.778031,0.796191,-1293.906372,294.500488,0.000000
92.050003,65.222527,-1293.950806,-0.000888,0.003135,0.079619,290.124298,14.779635,0.796191,-1293.950806,294.500488,0.000000
92.370003,65.215080,-1293.950806,-0.000888,0.003135,0.079619,290.091156,14.777948,0.796191,-1293.950806,294.500488,0.000000
92.690002,65.189384,-1293.906372,-0.000892,0.003135,0.079628,289.976868,14.772126,0.796281,-1293.906372,294.500488,0.000000
93.010002,65.206520,-1293.861938,-0.000901,0.003136,0.079646,290.053101,14.776009,0.796463,-1293.861938,294.500488,0.000000
93.330002,65.226250,-1293.906372,-0.000897,0.003137,0.079672,290.140839,14.780479,0.796720,-1293.906372,294.500488,0.000000
93.650002,65.243752,-1293.950806,-0.000897,0.003137,0.079672,290.218689,14.784445,0.796720,-1293.950806,294.500488,0.000000
93.970001,65.251564,-1293.995361,-0.000910,0.003137,0.079672,290.253448,14.786216,0.796720,-1293.995361,294.500488,0.000000
94.290001,65.257164,-1293.995361,-0.000884,0.003137,0.079672,290.278351,14.787484,0.796720,-1293.995361,294.500488,0.000000
94.610008,65.243752,-1293.906372,-0.000888,0.003137,0.079672,290.218689,14.784445,0.796720,-1293.906372,294.500488,0.000000
94.930008,65.236671,-1293.906372,-0.000901,0.003137,0.079672,290.187195,14.782842,0.796720,-1293.906372,294.500488,0.000000
95.250008,65.244865,-1293.906372,-0.000897,0.003137,0.079672,290.223663,14.784698,0.796720,-1293.906372,294.500488,0.000000
95.570007,65.228859,-1293.906372,-0.000892,0.003137,0.079672,290.152466,14.781071,0.796720,-1293.906372,294.500488,0.000000
95.890007,65.234444,-1293.906372,-0.000897,0.003137,0.079672,290.177307,14.782336,0.796720,-1293.906372,294.500488,0.000000
96.210007,65.244865,-1293.906372,-0.000901,0.003137,0.079689,290.223663,14.784698,0.796887,-1293.906372,294.500488,0.000000
96.530006,65.251564,-1293.906372,-0.000901,0.003137,0.079689,290.253448,14.786216,0.796887,-1293.906372,294.500488,0.000000
96.850006,65.256035,-1293.906372,-0.000901,0.003138,0.079698,290.273346,14.787229,0.796978,-1293.906372,294.500488,0.000000
97.170006,65.257896,-1293.906372,-0.000897,0.003138,0.079698,290.281616,14.787651,0.796978,-1293.906372,294.500488,0.000000
97.490005,65.242256,-1293.995361,-0.000888,0.003138,0.079698,290.212036,14.784107,0.796978,-1293.995361,294.500488,0.000000
97.810005,65.244865,-1293.950806,-0.000901,0.003138,0.079698,290.223663,14.784698,0.796978,-1293.950806,294.500488,0.000000
98.130005,65.232948,-1293.906372,-0.000897,0.003138,0.079698,290.170654,14.781998,0.796978,-1293.906372,294.500488,0.000000
98.450005,65.217308,-1293.950806,-0.000914,0.003138,0.079707,290.101074,14.778454,0.797069,-1293.950806,294.500488,0.000000
98.770004,65.216942,-1293.950806,-0.000897,0.003138,0.079714,290.099457,14.778370,0.797144,-1293.950806,294.500488,0.000000
99.090004,65.222160,-1293.950806,-0.000897,0.003138,0.079714,290.122650,14.779552,0.797144,-1293.950806,294.500488,0.000000
99.410004,65.232582,-1293.906372,-0.000884,0.003138,0.079714,290.169006,14.781914,0.797144,-1293.906372,294.500488,0.000000
99.730003,65.230721,-1293.861938,-0.000892,0.003138,0.079714,290.160736,14.781493,0.797144,-1293.861938,294.500488,0.000000
100.050003,65.227745,-1293.995361,-0.000905,0.003138,0.079714,290.147491,14.780818,0.797144,-1293.995361,294.500488,0.000000
100.370003,65.225883,-1293.950806,-0.000901,0.003138,0.079714,290.139221,14.780396,0.797144,-1293.950806,294.500488,0.000000
100.690002,65.221413,-1293.995361,-0.000892,0.003138,0.079714,290.119324,14.779383,0.797144,-1293.995361,294.500488,0.000000
101.010002,65.200935,-1293.906372,-0.000892,0.003138,0.079714,290.028259,14.774743,0.797144,-1293.906372,294.500488,0.000000
101.330002,65.194969,-1293.906372,-0.000901,0.003138,0.079714,290.001709,14.773392,0.797144,-1293.906372,294.500488,0.000000
101.650002,65.177849,-1293.950806,-0.000897,0.003138,0.079714,289.925537,14.769512,0.797144,-1293.950806,294.500488,0.000000
101.970001,65.178581,-1293.906372,-0.000892,0.003139,0.079724,289.928802,14.769677,0.797235,-1293.906372,294.500488,0.000000
102.290009,65.159966,-1293.995361,-0.000892,0.003139,0.079724,289.846008,14.765460,0.797235,-1293.995361,294.500488,0.000000
102.610008,65.159599,-1293.950806,-0.000897,0.003139,0.079724,289.844360,14.765376,0.797235,-1293.950806,294.500488,0.000000
102.930008,65.143959,-1293.906372,-0.000901,0.003139,0.079724,289.774811,14.761832,0.797235,-1293.906372,294.500488,0.000000
103.250008,65.136513,-1293.950806,-0.000892,0.003139,0.079724,289.741669,14.760145,0.797235,-1293.950806,294.500488,0.000000
103.570007,65.129433,-1293.995361,-0.000918,0.003139,0.079724,289.710175,14.758540,0.797235,-1293.995361,294.500488,0.000000
103.890007,65.145821,-1293.995361,-0.000901,0.003140,0.079758,289.783081,14.762254,0.797583,-1293.995361,294.500488,0.000000
104.210007,65.176353,-1293.950806,-0.000892,0.003140,0.079758,289.918915,14.769173,0.797583,-1293.950806,294.500488,0.000000
104.530006,65.170387,-1293.861938,-0.000901,0.003140,0.079758,289.892365,14.767821,0.797583,-1293.861938,294.500488,0.000000
104.850006,65.168907,-1293.817383,-0.000892,0.003141,0.079784,289.885773,14.767486,0.797841,-1293.817383,294.500488,0.000000
105.170006,65.238167,-1294.039795,-0.000905,0.003141,0.079793,290.193848,14.783179,0.797932,-1294.039795,294.500488,0.000000
105.490005,65.233330,-1293.906372,-0.000892,0.003141,0.079793,290.172333,14.782084,0.797932,-1293.906372,294.500488,0.000000
105.810005,65.245247,-1293.950806,-0.000892,0.003141,0.079793,290.225342,14.784784,0.797932,-1293.950806,294.500488,0.000000
106.130005,65.244499,-1293.906372,-0.000892,0.003141,0.079793,290.222015,14.784615,0.797932,-1293.906372,294.500488,0.000000
106.450005,65.235191,-1293.906372,-0.000892,0.003141,0.079793,290.180634,14.782506,0.797932,-1293.906372,294.500488,0.000000
106.770004,65.238914,-1293.906372,-0.000888,0.003141,0.079793,290.197174,14.783349,0.797932,-1293.906372,294.500488,0.000000
107.090004,65.236305,-1293.906372,-0.000892,0.003141,0.079793,290.185577,14.782759,0.797932,-1293.906372,294.500488,0.000000
107.410004,65.243004,-1293.906372,-0.000888,0.003141,0.079793,290.215363,14.784276,0.797932,-1293.906372,294.500488,0.000000
107.730003,65.243385,-1293.906372,-0.000888,0.003141,0.079793,290.217072,14.784363,0.797932,-1293.906372,294.500488,0.000000
108.050003,65.222893,-1293.906372,-0.000892,0.003141,0.079793,290.125916,14.779719,0.797932,-1293.906372,294.500488,0.000000
108.370003,65.226997,-1293.906372,-0.000897,0.003141,0.079793,290.144165,14.780648,0.797932,-1293.906372,294.500488,0.000000
108.690002,65.189751,-1293.906372,-0.000880,0.003142,0.079819,289.978485,14.772208,0.798189,-1293.906372,294.500488,0.000000
109.010002,65.224754,-1293.906372,-0.000901,0.003142,0.079819,290.134186,14.780140,0.798189,-1293.906372,294.500488,0.000000
109.330002,65.234444,-1293.861938,-0.000884,0.003142,0.079819,290.177307,14.782336,0.798189,-1293.861938,294.500488,0.000000
109.650002,65.229607,-1293.861938,-0.000888,0.003142,0.079819,290.155792,14.781240,0.798189,-1293.861938,294.500488,0.000000
109.970009,65.237801,-1293.861938,-0.000888,0.003142,0.079819,290.192230,14.783097,0.798189,-1293.861938,294.500488,0.000000
110.290009,65.231468,-1293.906372,-0.000892,0.003142,0.079819,290.164062,14.781662,0.798189,-1293.906372,294.500488,0.000000
110.610008,65.238533,-1293.906372,-0.000892,0.003142,0.079819,290.195496,14.783262,0.798189,-1293.906372,1681.640991,0.000000
110.930008,65.222893,-1293.950806,-0.000884,0.003135,0.079637,290.125916,14.779719,0.796372,-1293.950806,0.079637,0.000000
111.250008,65.104485,-1293.906372,-0.000884,0.003126,0.079395,289.599213,14.752887,0.793950,-1293.906372,0.079100,0.000000
111.570007,65.092567,-1293.950806,-0.000888,0.003107,0.078926,289.546204,14.750187,0.789257,-1293.950806,0.078570,0.000000
111.890007,65.011024,-1293.950806,-0.000880,0.003090,0.078493,289.183472,14.731709,0.784927,-1293.950806,0.078032,0.000000
112.210007,64.988304,-1293.950806,-0.000888,0.003074,0.078067,289.082428,14.726561,0.780672,-1293.950806,0.077504,0.000000
112.530006,64.967827,-1293.950806,-0.000892,0.003052,0.077513,288.991333,14.721920,0.775131,-1293.950806,0.076967,0.000000
112.850006,64.944359,-1293.906372,-0.000892,0.003030,0.076967,288.886932,14.716602,0.769666,-1293.906372,0.076437,0.000000
113.170006,64.965584,-1293.861938,-0.000880,0.003014,0.076567,288.981354,14.721412,0.765669,-1293.861938,0.075899,0.000000
113.490005,64.974892,-1293.995361,-0.000888,0.002983,0.075760,289.022766,14.723521,0.757600,-1293.995361,0.075371,0.000000
113.810005,64.906013,-1293.995361,-0.000871,0.002965,0.075310,288.716370,14.707913,0.753103,-1293.995361,0.074832,0.000000
114.130005,64.874733,-1293.995361,-0.000884,0.002948,0.074876,288.577240,14.700825,0.748758,-1293.995361,0.074304,0.000000
114.450005,64.811424,-1293.950806,-0.000880,0.002926,0.074322,288.295624,14.686479,0.743217,-1293.950806,0.073766,0.000000
114.770004,64.649818,-1293.861938,-0.000880,0.002907,0.073827,287.576752,14.649858,0.738266,-1293.861938,0.073238,0.000000
115.090004,64.340004,-1293.950806,-0.000880,0.002893,0.073480,286.198639,14.579654,0.734800,-1293.950806,0.072699,0.000000
115.410004,63.743828,-1293.906372,-0.000867,0.002878,0.073098,283.546722,14.444558,0.730984,-1293.906372,0.072170,0.000000
115.730003,62.584641,-1293.950806,-0.000867,0.002853,0.072466,278.390381,14.181882,0.724656,-1293.950806,0.071633,0.000000
116.050003,61.356186,-1293.906372,-0.000880,0.002829,0.071866,272.925934,13.903511,0.718661,-1293.906372,0.071103,0.000000
116.370003,60.074478,-1293.906372,-0.000867,0.002811,0.071389,267.224640,13.613071,0.713892,-1293.906372,0.070566,0.000000
116.690002,59.024384,-1293.906372,-0.000862,0.002796,0.071026,262.553558,13.375116,0.710258,-1293.906372,0.070037,0.000000
117.010002,57.267159,-1293.950806,-0.000871,0.002773,0.070435,254.737045,12.976923,0.704354,-1293.950806,0.069500,0.000000
117.330002,55.316673,-1293.906372,-0.000862,0.002750,0.069846,246.060852,12.534937,0.698465,-1293.906372,0.068970,0.000000
117.650009,53.018021,-1293.950806,-0.000862,0.002726,0.069230,235.835937,12.014055,0.692303,-1293.950806,0.068432,0.000000
117.970009,51.402298,-1293.906372,-0.000867,0.002710,0.068823,228.648834,11.647927,0.688230,-1293.906372,0.067904,0.000000
118.290009,49.576553,-1293.906372,-0.000871,0.002692,0.068389,220.527527,11.234208,0.683885,-1293.906372,0.067367,0.000000
118.610008,47.624573,-1293.950806,-0.000871,0.002675,0.067956,211.844681,10.791883,0.679555,-1293.950806,0.066837,0.000000
118.930008,44.790451,-1293.906372,-0.000871,0.002647,0.067227,199.237885,10.149661,0.672273,-1293.906372,0.066299,0.000000
119.250008,42.302628,-1293.906372,-0.000871,0.002626,0.066707,188.171478,9.585912,0.667065,-1293.906372,0.065771,0.000000
119.570007,39.827469,-1293.861938,-0.000880,0.002602,0.066099,177.161423,9.025033,0.660994,-1293.861938,0.065232,0.000000
119.890007,37.839371,-1293.906372,-0.000892,0.002585,0.065657,168.317932,8.574524,0.656573,-1293.906372,0.064704,0.000000
120.210007,35.765259,-1293.906372,-0.000897,0.002564,0.065137,159.091812,8.104524,0.651365,-1293.906372,0.064166,0.000000
120.530006,33.571236,-1293.950806,-0.000901,0.002544,0.064608,149.332321,7.607351,0.646082,-1293.950806,0.063636,0.000000
120.850006,31.096451,-1293.950806,-0.000910,0.002521,0.064045,138.323929,7.046556,0.640450,-1293.950806,0.063099,0.000000
121.170006,28.950096,-1293.861938,-0.000897,0.002501,0.063524,128.776459,6.560186,0.635242,-1293.861938,0.062570,0.000000
121.490005,26.156929,-1293.861938,-0.000918,0.002474,0.062847,116.351830,5.927245,0.628474,-1293.861938,0.062033,0.000000
121.810005,24.538971,-1293.995361,-0.000910,0.002460,0.062484,109.154793,5.560610,0.624841,-1293.995361,0.061503,0.000000
122.130005,21.546959,-1293.950806,-0.000923,0.002432,0.061763,95.845657,4.882611,0.617634,-1293.950806,0.060966,0.000000
122.450005,20.125244,-1293.906372,-0.000914,0.002421,0.061495,89.521561,4.560446,0.614955,-1293.906372,0.060437,0.000000
122.770004,17.903297,-1293.861938,-0.000901,0.002398,0.060922,79.637848,4.056945,0.609217,-1293.861938,0.059900,0.000000
123.090004,15.607994,-1293.817383,-0.000910,0.002379,0.060419,69.427826,3.536822,0.604190,-1293.817383,0.059370,0.000000
123.410004,13.486588,-1293.861938,-0.000927,0.002359,0.059925,59.991337,3.056104,0.599255,-1293.861938,0.058832,0.000000
123.730003,10.901207,-1293.995361,-0.000927,0.002336,0.059326,48.490990,2.470249,0.593260,-1293.995361,0.058304,0.000000
124.050003,8.404816,-1293.861938,-0.000931,0.002310,0.058676,37.386486,1.904559,0.586765,-1293.861938,0.057765,0.000000
124.370003,6.827820,-1293.906372,-0.000940,0.002296,0.058321,30.371660,1.547206,0.583207,-1293.906372,0.057237,0.000000
124.690002,4.008591,-1293.861938,-0.000944,0.002267,0.057592,17.831102,0.908360,0.575925,-1293.861938,0.056699,0.000000
125.010002,2.275192,-1293.906372,-0.000940,0.002251,0.057176,10.120561,0.515566,0.571761,-1293.906372,0.056169,0.000000
125.330009,0.093842,-1293.906372,-0.000961,0.002225,0.056518,0.417428,0.021265,0.565176,-1293.906372,0.055632,0.000000
125.650009,-0.891460,-1293.950806,-0.000953,0.002212,0.056188,-3.965414,-0.202008,0.561875,-1293.950806,0.055104,0.000000
125.970009,-1.703606,-1293.906372,-0.000961,0.002195,0.055753,-7.578016,-0.386043,0.557530,-1293.906372,0.054566,0.000000
126.290009,-0.310188,-1293.817383,-0.000987,0.002171,0.055155,-1.379786,-0.070290,0.551550,-1293.817383,0.054036,0.000000
126.610008,-0.131073,-1293.950806,-0.000992,0.002143,0.054427,-0.583042,-0.029702,0.544268,-1293.950806,0.053499,0.000000
126.930008,-0.018250,-1293.950806,-0.001009,0.002123,0.053924,-0.081178,-0.004135,0.539242,-1293.950806,0.052970,0.000000
127.250008,-0.056976,-1293.906372,-0.001030,0.002103,0.053422,-0.253443,-0.012911,0.534215,-1293.906372,0.052433,0.000000
127.570007,-0.031654,-1293.950806,-0.001052,0.002081,0.052857,-0.140806,-0.007173,0.528568,-1293.950806,0.051903,0.000000
127.890007,-0.036491,-1293.861938,-0.001056,0.002066,0.052475,-0.162322,-0.008269,0.524753,-1293.861938,0.051366,0.000000
128.210007,-0.030907,-1293.906372,-0.001065,0.002051,0.052103,-0.137480,-0.007004,0.521029,-1293.906372,0.050837,0.000000
128.529999,-0.028671,-1293.950806,-0.001078,0.002013,0.051123,-0.127536,-0.006497,0.511233,-1293.950806,0.050298,0.000000
128.850006,-0.026070,-1293.995361,-0.001082,0.001995,0.050672,-0.115964,-0.005907,0.506722,-1293.995361,0.049770,0.000000
129.170013,-0.032021,-1293.995361,-0.001099,0.001972,0.050100,-0.142435,-0.007256,0.500999,-1293.995361,0.049232,0.000000
129.490005,-0.045059,-1293.950806,-0.001108,0.001955,0.049649,-0.200433,-0.010211,0.496487,-1293.950806,0.048703,0.000000
129.810013,-0.059952,-1293.906372,-0.001121,0.001938,0.049232,-0.266679,-0.013585,0.492324,-1293.906372,0.048165,0.000000
130.100006,0.026810,-1293.950806,-0.001121,0.001921,0.048798,0.119255,0.006075,0.487979,-1293.950806,0.048677,0.000000