File: Data/Sima compression/P2-17-3_10302024_174124.csv
Time (sec),S:Load (lbs),S:HL1 (DIM),S:LVDT (in),S:Position (in),Ch:Position (mm),Ch:Load (N),Ch:Stress (MPa),Ch:Strain (mm/mm),Ch:HL1 (DIM),Set Point (),Cycles ()
0.210000,0.002609,-1293.772949,-0.007575,-0.004414,-0.112106,0.011607,0.000591,-1.121056,-1293.772949,-0.111950,0.000000
0.510000,-0.056229,-1293.772949,-0.007554,-0.004355,-0.110623,-0.250117,-0.012742,-1.106234,-1293.772949,-0.109956,0.000000
0.810000,0.004097,-1293.861938,-0.007437,-0.004176,-0.106062,0.018224,0.000928,-1.060618,-1293.861938,-0.104960,0.000000
1.110000,-0.020111,-1293.817383,-0.007226,-0.003980,-0.101101,-0.089459,-0.004557,-1.011006,-1293.817383,-0.099965,0.000000
1.410000,0.034256,-1293.772949,-0.007041,-0.003783,-0.096080,0.152378,0.007763,-0.960803,-1293.772949,-0.094971,0.000000
1.710000,0.005211,-1293.728516,-0.006825,-0.003585,-0.091068,0.023179,0.001181,-0.910676,-1293.728516,-0.089975,0.000000
2.010000,0.001114,-1293.772949,-0.006635,-0.003398,-0.086315,0.004955,0.000252,-0.863153,-1293.772949,-0.084980,0.000000
2.310000,-0.031654,-1293.817383,-0.006424,-0.003192,-0.081077,-0.140806,-0.007173,-0.810770,-1293.817383,-0.079967,0.000000
2.610000,-0.032394,-1293.772949,-0.006209,-0.002993,-0.076013,-0.144098,-0.007341,-0.760128,-1293.772949,-0.074971,0.000000
2.910000,-0.059952,-1293.728516,-0.006032,-0.002799,-0.071086,-0.266679,-0.013585,-0.710864,-1293.728516,-0.069977,0.000000
3.210000,0.015266,-1293.728516,-0.005816,-0.002602,-0.066099,0.067908,0.003459,-0.660994,-1293.728516,-0.064981,0.000000
3.510000,0.020851,-1293.728516,-0.005627,-0.002406,-0.061105,0.092750,0.004725,-0.611049,-1293.728516,-0.059986,0.000000
3.810000,0.036491,-1293.728516,-0.005428,-0.002211,-0.056162,0.162322,0.008269,-0.561618,-1293.728516,-0.054991,0.000000
4.110000,0.001862,-1293.817383,-0.005226,-0.002010,-0.051063,0.008281,0.000422,-0.510628,-1293.817383,-0.049979,0.000000
4.410000,-0.062561,-1293.772949,-0.005014,-0.001816,-0.046120,-0.278285,-0.014177,-0.461197,-1293.772949,-0.044983,0.000000
4.710000,0.005959,-1293.683960,-0.004816,-0.001619,-0.041124,0.026505,0.001350,-0.411236,-1293.683960,-0.039988,0.000000
5.010000,-0.052879,-1293.728516,-0.004618,-0.001420,-0.036076,-0.235219,-0.011983,-0.360761,-1293.728516,-0.034992,0.000000
5.310000,0.017502,-1293.772949,-0.004415,-0.001230,-0.031237,0.077852,0.003966,-0.312375,-1293.772949,-0.029998,0.000000
5.610000,0.003723,-1293.728516,-0.004199,-0.001026,-0.026069,0.016561,0.000844,-0.260688,-1293.728516,-0.025002,0.000000
5.910000,0.042824,-1293.683960,-0.004001,-0.000832,-0.021135,0.190490,0.009704,-0.211349,-1293.683960,-0.020007,0.000000
6.210001,-0.002609,-1293.728516,-0.003803,-0.000637,-0.016192,-0.011607,-0.000591,-0.161918,-1293.728516,-0.014994,0.000000
6.510000,0.005211,-1293.639526,-0.003583,-0.000432,-0.010961,0.023179,0.001181,-0.109611,-1293.639526,-0.010000,0.000000
6.810000,0.004471,-1293.728516,-0.003397,-0.000241,-0.006122,0.019887,0.001013,-0.061224,-1293.728516,-0.005004,0.000000
7.110000,0.024200,-1293.728516,-0.003182,-0.000041,-0.001033,0.107649,0.005484,-0.010325,-1293.728516,-0.000009,0.000000
7.410000,0.069260,-1293.728516,-0.003126,-0.000006,-0.000147,0.308082,0.015694,-0.001469,-1293.728516,0.000070,0.000000
7.710001,0.055855,-1293.683960,-0.003134,-0.000006,-0.000147,0.248455,0.012657,-0.001469,-1293.683960,0.000070,0.000000
8.010000,0.159378,-1293.639526,-0.003130,-0.000005,-0.000139,0.708949,0.036116,-0.001393,-1293.639526,0.000547,0.000000
8.310000,0.214859,-1293.639526,-0.003134,0.000007,0.000182,0.955741,0.048688,0.001817,-1293.639526,0.001040,0.000000
8.610001,0.391365,-1293.728516,-0.003130,0.000022,0.000563,1.740879,0.088685,0.005632,-1293.728516,0.001544,0.000000
8.910001,0.497116,-1293.683960,-0.003109,0.000032,0.000807,2.211283,0.112648,0.008069,-1293.683960,0.002047,0.000000
9.210000,1.013222,-1293.639526,-0.003087,0.000062,0.001587,4.507035,0.229599,0.015866,-1293.639526,0.002540,0.000000
9.510000,1.486511,-1293.772949,-0.003074,0.000083,0.002117,6.612332,0.336848,0.021165,-1293.772949,0.003045,0.000000
9.810000,1.981392,-1293.639526,-0.003053,0.000101,0.002559,8.813671,0.448990,0.025586,-1293.639526,0.003547,0.000000
10.110001,2.653152,-1293.639526,-0.003035,0.000125,0.003166,11.801811,0.601213,0.031657,-1293.639526,0.004041,0.000000
10.410001,3.213943,-1293.683960,-0.003040,0.000140,0.003555,14.296334,0.728290,0.035548,-1293.683960,0.004543,0.000000
10.710000,3.770271,-1293.683960,-0.003018,0.000156,0.003954,16.771004,0.854356,0.039545,-1293.683960,0.005048,0.000000
11.010000,4.783127,-1293.683960,-0.002992,0.000181,0.004596,21.276411,1.083872,0.045964,-1293.683960,0.005541,0.000000
11.310000,5.656708,-1293.639526,-0.002988,0.000203,0.005150,25.162292,1.281828,0.051505,-1293.639526,0.006044,0.000000
11.610001,6.348579,-1293.639526,-0.002962,0.000221,0.005620,28.239891,1.438609,0.056198,-1293.639526,0.006548,0.000000
11.910001,7.253441,-1293.683960,-0.002971,0.000243,0.006174,32.264915,1.643653,0.061739,-1293.683960,0.007041,0.000000
12.210001,8.104683,-1293.683960,-0.002945,0.000259,0.006574,36.051430,1.836547,0.065736,-1293.683960,0.007544,0.000000
12.510000,9.006577,-1293.728516,-0.002932,0.000278,0.007060,40.063251,2.040919,0.070596,-1293.728516,0.008048,0.000000
12.810000,10.212318,-1293.683960,-0.002915,0.000304,0.007709,45.426662,2.314144,0.077091,-1293.683960,0.008542,0.000000
13.110001,11.173035,-1293.639526,-0.002915,0.000323,0.008204,49.700142,2.531846,0.082041,-1293.639526,0.009044,0.000000
13.410001,11.749840,-1293.683960,-0.002893,0.000340,0.008637,52.265896,2.662552,0.086371,-1293.683960,0.009549,0.000000
13.710001,12.856529,-1293.683960,-0.002876,0.000361,0.009158,57.188698,2.913331,0.091579,-1293.683960,0.010042,0.000000
14.010000,13.731606,-1293.683960,-0.002863,0.000379,0.009617,61.081230,3.111626,0.096167,-1293.683960,0.010545,0.000000
14.310000,14.772385,-1293.639526,-0.002850,0.000399,0.010137,65.710846,3.347470,0.101375,-1293.639526,0.011049,0.000000
14.610001,15.493675,-1293.683960,-0.002846,0.000414,0.010528,68.919312,3.510917,0.105281,-1293.683960,0.011542,0.000000
14.910001,16.896027,-1293.728516,-0.002841,0.000440,0.011187,75.157280,3.828694,0.111866,-1293.728516,0.012045,0.000000
15.210001,17.447510,-1293.639526,-0.002811,0.000457,0.011595,77.610397,3.953662,0.115954,-1293.639526,0.012549,0.000000
15.510001,18.575058,-1293.683960,-0.002807,0.000480,0.012184,82.625984,4.209168,0.121843,-1293.683960,0.013043,0.000000
15.810000,19.415497,-1293.728516,-0.002781,0.000498,0.012645,86.364441,4.399614,0.126446,-1293.728516,0.013545,0.000000
16.110001,20.264511,-1293.728516,-0.002781,0.000517,0.013129,90.141045,4.592004,0.131290,-1293.728516,0.014050,0.000000
16.410000,20.906853,-1293.683960,-0.002759,0.000531,0.013494,92.998329,4.737560,0.134939,-1293.683960,0.014543,0.000000
16.710001,22.051521,-1293.728516,-0.002772,0.000556,0.014127,98.090065,4.996946,0.141267,-1293.728516,0.015046,0.000000
17.010000,22.668915,-1293.728516,-0.002738,0.000573,0.014543,100.836372,5.136849,0.145431,-1293.728516,0.015550,0.000000
17.310001,23.609161,-1293.639526,-0.002746,0.000592,0.015038,105.018791,5.349913,0.150381,-1293.639526,0.016043,0.000000
17.610001,24.455193,-1293.728516,-0.002712,0.000614,0.015583,108.782127,5.541626,0.155832,-1293.728516,0.016546,0.000000
17.910002,25.163445,-1293.683960,-0.002695,0.000631,0.016034,111.932594,5.702118,0.160343,-1293.683960,0.017050,0.000000
18.210001,26.256729,-1293.728516,-0.002682,0.000656,0.016651,116.795761,5.949860,0.166505,-1293.728516,0.017544,0.000000
18.510000,26.259705,-1293.683960,-0.002682,0.000663,0.016832,116.808998,5.950534,0.168322,-1293.683960,0.018046,0.000000
18.810001,27.768188,-1293.683960,-0.002656,0.000692,0.017588,123.519073,6.292362,0.175876,-1293.683960,0.018551,0.000000
19.110001,28.290627,-1293.728516,-0.002643,0.000710,0.018046,125.842995,6.410748,0.180464,-1293.728516,0.019044,0.000000
19.410002,29.344810,-1293.728516,-0.002630,0.000734,0.018637,130.532242,6.649629,0.186368,-1293.728516,0.019547,0.000000
19.710001,29.539932,-1293.728516,-0.002630,0.000749,0.019018,131.400177,6.693844,0.190183,-1293.728516,0.020051,0.000000
20.010000,30.676041,-1293.683960,-0.002604,0.000773,0.019625,136.453842,6.951290,0.196254,-1293.683960,0.020544,0.000000
20.310001,30.919579,-1293.772949,-0.002596,0.000786,0.019963,137.537155,7.006477,0.199630,-1293.772949,0.021047,0.000000
20.610001,32.302940,-1293.772949,-0.002583,0.000816,0.020726,143.690659,7.319951,0.207261,-1293.772949,0.021542,0.000000
20.910002,32.660042,-1293.728516,-0.002565,0.000831,0.021108,145.279129,7.400871,0.211076,-1293.728516,0.022045,0.000000
21.210001,33.352287,-1293.772949,-0.002548,0.000855,0.021715,148.358383,7.557736,0.217147,-1293.772949,0.022547,0.000000
21.510000,33.641617,-1293.728516,-0.002527,0.000869,0.022070,149.645386,7.623299,0.220705,-1293.728516,0.023042,0.000000
21.810001,34.308167,-1293.728516,-0.002535,0.000892,0.022668,152.610352,7.774342,0.226685,-1293.728516,0.023545,0.000000
22.110001,34.972847,-1293.728516,-0.002509,0.000912,0.023154,155.566986,7.924960,0.231545,-1293.728516,0.024048,0.000000
22.410002,34.622444,-1293.772949,-0.002509,0.000921,0.023398,154.008316,7.845558,0.233982,-1293.772949,0.024543,0.000000
22.710001,36.320839,-1293.728516,-0.002475,0.000953,0.024213,161.563156,8.230420,0.242127,-1293.728516,0.025045,0.000000
23.010000,36.253441,-1293.728516,-0.002462,0.000966,0.024543,161.263351,8.215147,0.245428,-1293.728516,0.025548,0.000000
23.310001,36.963928,-1293.728516,-0.002466,0.000989,0.025124,164.423767,8.376145,0.251241,-1293.728516,0.026043,0.000000
23.610001,37.021271,-1293.683960,-0.002449,0.001004,0.025513,164.678833,8.389139,0.255132,-1293.683960,0.026546,0.000000
23.910002,37.977898,-1293.728516,-0.002423,0.001028,0.026113,168.934128,8.605915,0.261127,-1293.728516,0.027048,0.000000
24.210001,38.043808,-1293.772949,-0.002419,0.001041,0.026441,169.227310,8.620851,0.264413,-1293.772949,0.027543,0.000000
24.510000,39.443550,-1293.683960,-0.002397,0.001072,0.027222,175.453674,8.938037,0.272225,-1293.683960,0.028046,0.000000
24.810001,39.588036,-1293.728516,-0.002397,0.001087,0.027613,176.096375,8.970777,0.276131,-1293.728516,0.028549,0.000000
25.110001,39.794701,-1293.728516,-0.002371,0.001107,0.028116,177.015671,9.017608,0.281157,-1293.728516,0.029044,0.000000
25.410002,40.382675,-1293.728516,-0.002354,0.001125,0.028574,179.631104,9.150845,0.285744,-1293.728516,0.029546,0.000000
25.710001,40.835854,-1293.728516,-0.002350,0.001145,0.029079,181.646942,9.253537,0.290786,-1293.728516,0.030049,0.000000
26.010002,41.101730,-1293.772949,-0.002345,0.001165,0.029581,182.829620,9.313785,0.295812,-1293.772949,0.030544,0.000000
26.310001,41.688583,-1293.772949,-0.002324,0.001183,0.030040,185.440079,9.446768,0.300400,-1293.772949,0.031047,0.000000
26.610001,42.860443,-1293.728516,-0.002307,0.001208,0.030682,190.652771,9.712316,0.306819,-1293.728516,0.031549,0.000000
26.910002,42.762512,-1293.639526,-0.002281,0.001223,0.031056,190.217148,9.690124,0.310558,-1293.639526,0.032044,0.000000
27.210001,43.375809,-1293.728516,-0.002276,0.001242,0.031549,192.945236,9.829099,0.315494,-1293.728516,0.032547,0.000000
27.510002,43.530342,-1293.772949,-0.002276,0.001258,0.031949,193.632629,9.864117,0.319491,-1293.772949,0.033050,0.000000
27.810001,44.440048,-1293.728516,-0.002246,0.001280,0.032503,197.679214,10.070259,0.325032,-1293.728516,0.033545,0.000000
28.110001,44.622513,-1293.683960,-0.002255,0.001294,0.032877,198.490845,10.111606,0.328771,-1293.683960,0.034047,0.000000
28.410002,46.269516,-1293.683960,-0.002220,0.001326,0.033692,205.817093,10.484822,0.336916,-1293.683960,0.034550,0.000000
28.710001,46.367447,-1293.728516,-0.002225,0.001341,0.034073,206.252701,10.507013,0.340731,-1293.728516,0.035045,0.000000
29.010002,46.439690,-1293.728516,-0.002207,0.001360,0.034533,206.574051,10.523384,0.345334,-1293.728516,0.035548,0.000000
29.310001,46.853020,-1293.728516,-0.002199,0.001377,0.034983,208.412643,10.617046,0.349830,-1293.728516,0.036050,0.000000
29.610001,47.637238,-1293.728516,-0.002182,0.001400,0.035548,211.901016,10.794753,0.355477,-1293.728516,0.036545,0.000000
29.910002,48.152969,-1293.728516,-0.002160,0.001419,0.036034,214.195099,10.911619,0.360337,-1293.728516,0.037048,0.000000
30.210001,47.833107,-1293.639526,-0.002160,0.001430,0.036327,212.772293,10.839137,0.363274,-1293.639526,0.037551,0.000000
30.510002,49.492393,-1293.683960,-0.002147,0.001458,0.037039,220.153168,11.215137,0.370390,-1293.683960,0.038046,0.000000
30.810001,49.923607,-1293.728516,-0.002121,0.001479,0.037560,222.071289,11.312851,0.375598,-1293.728516,0.038548,0.000000
31.110001,50.517914,-1293.683960,-0.002117,0.001497,0.038028,224.714905,11.447523,0.380276,-1293.683960,0.039051,0.000000
31.410002,51.115570,-1293.683960,-0.002095,0.001517,0.038530,227.373413,11.582954,0.385302,-1293.683960,0.039546,0.000000
31.710001,51.441025,-1293.728516,-0.002091,0.001535,0.039000,228.821106,11.656702,0.389996,-1293.728516,0.040049,0.000000
32.010002,51.600769,-1293.728516,-0.002082,0.001549,0.039346,229.531677,11.692902,0.393463,-1293.728516,0.040551,0.000000
32.310001,52.867210,-1293.639526,-0.002065,0.001576,0.040040,235.165100,11.979881,0.400396,-1293.639526,0.041045,0.000000
32.610001,53.271233,-1293.683960,-0.002039,0.001597,0.040560,236.962280,12.071433,0.405604,-1293.683960,0.041549,0.000000
32.910000,53.811546,-1293.683960,-0.002044,0.001614,0.041003,239.365707,12.193871,0.410025,-1293.683960,0.042052,0.000000
33.210003,54.667625,-1293.728516,-0.002035,0.001635,0.041531,243.173737,12.387860,0.415309,-1293.728516,0.042545,0.000000
33.510002,54.998665,-1293.683960,-0.002022,0.001652,0.041965,244.646286,12.462875,0.419654,-1293.683960,0.043049,0.000000
33.810001,55.696869,-1293.728516,-0.002005,0.001674,0.042529,247.752045,12.621091,0.425286,-1293.728516,0.043543,0.000000
34.110001,56.173134,-1293.683960,-0.001988,0.001692,0.042980,249.870575,12.729013,0.429798,-1293.683960,0.044046,0.000000
34.410000,57.846947,-1293.683960,-0.001992,0.001719,0.043656,257.316071,13.108305,0.436565,-1293.683960,0.044550,0.000000
34.710003,57.943390,-1293.683960,-0.001992,0.001733,0.044029,257.745056,13.130159,0.440289,-1293.683960,0.045043,0.000000
35.010002,58.680313,-1293.683960,-0.001966,0.001754,0.044541,261.023071,13.297149,0.445406,-1293.683960,0.045546,0.000000
35.310001,59.537888,-1293.683960,-0.001953,0.001775,0.045078,264.837738,13.491478,0.450781,-1293.683960,0.046050,0.000000
35.610001,59.940422,-1293.728516,-0.001940,0.001791,0.045494,266.628326,13.582694,0.454944,-1293.728516,0.046544,0.000000
35.910000,60.358223,-1293.728516,-0.001944,0.001809,0.045955,268.486786,13.677369,0.459547,-1293.728516,0.047046,0.000000
36.210003,61.959053,-1293.683960,-0.001919,0.001835,0.046597,275.607635,14.040122,0.465966,-1293.683960,0.047550,0.000000
36.510002,62.386162,-1293.683960,-0.001906,0.001852,0.047030,277.507507,14.136907,0.470296,-1293.683960,0.048044,0.000000
36.810001,63.209846,-1293.683960,-0.001893,0.001873,0.047576,281.171448,14.323556,0.475761,-1293.683960,0.048547,0.000000
37.110001,63.975075,-1293.728516,-0.001880,0.001893,0.048088,284.575348,14.496960,0.480878,-1293.728516,0.049051,0.000000
37.410004,64.660240,-1293.728516,-0.001880,0.001911,0.048547,287.623108,14.652220,0.485466,-1293.728516,0.049544,0.000000
37.710003,65.513344,-1293.683960,-0.001867,0.001929,0.048998,291.417908,14.845536,0.489977,-1293.683960,0.050047,0.000000
38.010002,65.280983,-1293.728516,-0.001850,0.001940,0.049284,290.384308,14.792882,0.492839,-1293.728516,0.050551,0.000000
38.310001,65.389717,-1293.683960,-0.001841,0.001945,0.049405,290.867981,14.817522,0.494050,-1293.683960,0.008692,0.000000
38.610001,66.285652,-1293.683960,-0.001828,0.001941,0.049302,294.853302,15.020544,0.493020,-1293.683960,294.500488,0.000000
38.910004,65.190498,-1293.639526,-0.001832,0.001964,0.049891,289.981812,14.772378,0.498910,-1293.639526,294.500488,0.000000
39.210003,65.124596,-1293.683960,-0.001819,0.001980,0.050282,289.688660,14.757444,0.502816,-1293.683960,294.500488,0.000000
39.510002,65.215080,-1293.683960,-0.001807,0.001987,0.050472,290.091156,14.777948,0.504723,-1293.683960,294.500488,0.000000
39.810001,65.556175,-1293.772949,-0.001798,0.001998,0.050758,291.608429,14.855242,0.507585,-1293.772949,294.500488,0.000000
40.110001,64.747383,-1293.728516,-0.001802,0.001998,0.050758,288.010742,14.671967,0.507585,-1293.728516,294.500488,0.000000
40.410004,66.618553,-1293.683960,-0.001794,0.001928,0.048981,296.334137,15.095980,0.489811,-1293.683960,294.500488,0.000000
40.710003,65.692467,-1293.683960,-0.001776,0.001930,0.049023,292.214691,14.886127,0.490235,-1293.683960,294.500488,0.000000
41.010002,65.061287,-1293.683960,-0.001772,0.002018,0.051254,289.407043,14.743098,0.512535,-1293.683960,294.500488,0.000000
41.310001,65.081398,-1293.639526,-0.001776,0.002034,0.051652,289.496521,14.747656,0.516517,-1293.639526,294.500488,0.000000
41.610001,65.124596,-1293.683960,-0.001772,0.002036,0.051703,289.688660,14.757444,0.517032,-1293.683960,294.500488,0.000000
41.910004,65.258644,-1293.683960,-0.001772,0.002043,0.051894,290.284943,14.787820,0.518939,-1293.683960,294.500488,0.000000
42.210003,66.366447,-1293.683960,-0.001755,0.002062,0.052363,295.212708,15.038852,0.523633,-1293.683960,294.500488,0.000000
42.510002,65.713310,-1293.728516,-0.001750,0.002051,0.052103,292.307404,14.890849,0.521029,-1293.728516,294.500488,0.000000
42.810001,65.040443,-1293.683960,-0.001763,0.002051,0.052103,289.314331,14.738375,0.521029,-1293.683960,294.500488,0.000000
43.110001,66.935814,-1293.728516,-0.001746,0.002070,0.052580,297.745361,15.167872,0.525798,-1293.728516,294.500488,0.000000
43.410004,66.028709,-1293.683960,-0.001738,0.002038,0.051765,293.710358,14.962319,0.517653,-1293.683960,294.500488,0.000000
43.710003,65.479836,-1293.683960,-0.001738,0.002051,0.052103,291.268860,14.837942,0.521029,-1293.683960,294.500488,0.000000
44.010002,65.078789,-1293.728516,-0.001742,0.002079,0.052796,289.484924,14.747064,0.527963,-1293.728516,294.500488,0.000000
44.310001,65.237801,-1293.683960,-0.001733,0.002083,0.052910,290.192230,14.783097,0.529098,-1293.683960,294.500488,0.000000
44.610001,65.160713,-1293.728516,-0.001738,0.002088,0.053048,289.849335,14.765629,0.530476,-1293.728516,294.500488,0.000000
44.910004,65.308174,-1293.683960,-0.001729,0.002095,0.053222,290.505280,14.799045,0.532217,-1293.683960,294.500488,0.000000
45.210003,65.043419,-1293.728516,-0.001738,0.002097,0.053273,289.327576,14.739050,0.532732,-1293.728516,294.500488,0.000000
45.510002,65.397911,-1293.728516,-0.001720,0.002104,0.053447,290.904449,14.819378,0.534473,-1293.728516,294.500488,0.000000
45.810001,65.058678,-1293.683960,-0.001725,0.002106,0.053499,289.395447,14.742507,0.534987,-1293.683960,294.500488,0.000000
46.110001,65.260887,-1293.683960,-0.001716,0.002112,0.053638,290.294922,14.788328,0.536380,-1293.683960,294.500488,0.000000
46.410004,65.254555,-1293.683960,-0.001716,0.002118,0.053785,290.266754,14.786894,0.537849,-1293.683960,294.500488,0.000000
46.710003,65.147682,-1293.772949,-0.001716,0.002122,0.053898,289.791351,14.762676,0.538984,-1293.772949,294.500488,0.000000
47.010002,65.555061,-1293.728516,-0.001712,0.002125,0.053985,291.603485,14.854989,0.539847,-1293.728516,294.500488,0.000000
47.310001,65.275780,-1293.728516,-0.001703,0.002128,0.054045,290.361176,14.791703,0.540453,-1293.728516,294.500488,0.000000
47.610001,65.222160,-1293.683960,-0.001716,0.002131,0.054124,290.122650,14.779552,0.541240,-1293.683960,294.500488,0.000000
47.910004,65.151405,-1293.728516,-0.001703,0.002133,0.054175,289.807922,14.763519,0.541755,-1293.728516,294.500488,0.000000
48.210003,65.111565,-1293.683960,-0.001716,0.002136,0.054245,289.630707,14.754492,0.542451,-1293.683960,294.500488,0.000000
48.510002,65.129433,-1293.683960,-0.001703,0.002139,0.054322,289.710175,14.758540,0.543223,-1293.683960,294.500488,0.000000
48.810001,65.091820,-1293.728516,-0.001690,0.002145,0.054471,289.542877,14.750017,0.544707,-1293.728516,294.500488,0.000000
49.110001,65.093315,-1293.728516,-0.001699,0.002145,0.054471,289.549530,14.750356,0.544707,-1293.728516,294.500488,0.000000
49.410004,65.173378,-1293.728516,-0.001677,0.002148,0.054566,289.905670,14.768499,0.545661,-1293.728516,294.500488,0.000000
49.710003,65.524513,-1293.683960,-0.001690,0.002155,0.054731,291.467590,14.848067,0.547311,-1293.683960,294.500488,0.000000
50.010002,65.316368,-1293.683960,-0.001686,0.002155,0.054731,290.541718,14.800900,0.547311,-1293.683960,294.500488,0.000000
50.310001,65.235939,-1293.683960,-0.001694,0.002157,0.054792,290.183960,14.782675,0.547917,-1293.683960,294.500488,0.000000
50.610001,65.247108,-1293.728516,-0.001686,0.002160,0.054869,290.233643,14.785206,0.548689,-1293.728516,294.500488,0.000000
50.910004,65.215446,-1293.728516,-0.001681,0.002163,0.054929,290.092804,14.778031,0.549294,-1293.728516,294.500488,0.000000
51.210003,65.228859,-1293.728516,-0.001677,0.002165,0.054999,290.152466,14.781071,0.549991,-1293.728516,294.500488,0.000000
51.510002,65.229225,-1293.728516,-0.001673,0.002168,0.055060,290.154083,14.781154,0.550596,-1293.728516,294.500488,0.000000
51.810001,65.246727,-1293.772949,-0.001673,0.002170,0.055120,290.231934,14.785120,0.551202,-1293.772949,294.500488,0.000000
52.110001,65.225883,-1293.728516,-0.001664,0.002172,0.055181,290.139221,14.780396,0.551807,-1293.728516,294.500488,0.000000
52.410004,65.399773,-1293.728516,-0.001660,0.002178,0.055311,290.912720,14.819800,0.553109,-1293.728516,294.500488,0.000000
52.710003,65.334618,-1293.728516,-0.001673,0.002178,0.055311,290.622894,14.805036,0.553109,-1293.728516,294.500488,0.000000
53.010002,65.257164,-1293.728516,-0.001673,0.002180,0.055364,290.278351,14.787484,0.553639,-1293.728516,294.500488,0.000000
53.310001,65.155876,-1293.639526,-0.001664,0.002182,0.055415,289.827820,14.764533,0.554154,-1293.639526,294.500488,0.000000
53.610004,65.199440,-1293.728516,-0.001669,0.002184,0.055476,290.021606,14.774405,0.554760,-1293.728516,294.500488,0.000000
53.910004,65.087730,-1293.728516,-0.001664,0.002184,0.055476,289.524689,14.749090,0.554760,-1293.728516,294.500488,0.000000
54.210003,64.966331,-1293.728516,-0.001656,0.002186,0.055520,288.984680,14.721581,0.555199,-1293.728516,294.500488,0.000000
54.510002,64.883293,-1293.683960,-0.001669,0.002186,0.055537,288.615295,14.702765,0.555365,-1293.683960,294.500488,0.000000
54.810001,64.775673,-1293.683960,-0.001660,0.002188,0.055564,288.136597,14.678377,0.555638,-1293.683960,294.500488,0.000000
55.110004,64.890373,-1293.772949,-0.001651,0.002191,0.055650,288.646790,14.704370,0.556501,-1293.772949,294.500488,0.000000
55.410004,64.984215,-1293.772949,-0.001651,0.002204,0.055971,289.064240,14.725634,0.559710,-1293.772949,294.500488,0.000000
55.710003,65.867470,-1293.728516,-0.001660,0.002200,0.055876,292.993134,14.925781,0.558756,-1293.728516,294.500488,0.000000
56.010002,65.654106,-1293.728516,-0.001647,0.002200,0.055876,292.044037,14.877433,0.558756,-1293.728516,294.500488,0.000000
56.310001,65.483925,-1293.683960,-0.001638,0.002200,0.055883,291.287048,14.838870,0.558832,-1293.683960,294.500488,0.000000
56.610004,65.253807,-1293.728516,-0.001643,0.002200,0.055883,290.263428,14.786724,0.558832,-1293.728516,294.500488,0.000000
56.910004,65.037453,-1293.683960,-0.001638,0.002201,0.055910,289.301025,14.737697,0.559105,-1293.683960,294.500488,0.000000
57.210003,64.857597,-1293.817383,-0.001638,0.002201,0.055910,288.501007,14.696941,0.559105,-1293.817383,294.500488,0.000000
57.510002,66.238365,-1293.772949,-0.001638,0.002214,0.056231,294.642975,15.009828,0.562314,-1293.772949,294.500488,0.000000
57.810001,66.017540,-1293.817383,-0.001634,0.002213,0.056222,293.660675,14.959788,0.562223,-1293.817383,294.500488,0.000000
58.110004,65.809761,-1293.772949,-0.001647,0.002213,0.056222,292.736450,14.912705,0.562223,-1293.772949,294.500488,0.000000
58.410004,65.594902,-1293.817383,-0.001630,0.002213,0.056222,291.780701,14.864017,0.562223,-1293.817383,294.500488,0.000000
58.710003,65.420631,-1293.772949,-0.001647,0.002213,0.056222,291.005493,14.824528,0.562223,-1293.772949,294.500488,0.000000
59.010002,65.245247,-1293.772949,-0.001634,0.002214,0.056231,290.225342,14.784784,0.562314,-1293.772949,294.500488,0.000000
59.310001,65.048256,-1293.772949,-0.001643,0.002215,0.056257,289.349091,14.740146,0.562572,-1293.772949,294.500488,0.000000
59.610004,66.016045,-1293.817383,-0.001625,0.002224,0.056483,293.654022,14.959450,0.564827,-1293.817383,294.500488,0.000000
59.910004,65.835457,-1293.772949,-0.001643,0.002224,0.056483,292.850739,14.918528,0.564827,-1293.772949,294.500488,0.000000
60.210003,65.635490,-1293.772949,-0.001634,0.002224,0.056483,291.961243,14.873215,0.564827,-1293.772949,294.500488,0.000000
60.510002,65.486168,-1293.772949,-0.001634,0.002224,0.056483,291.297028,14.839377,0.564827,-1293.772949,294.500488,0.000000
60.810001,65.292534,-1293.728516,-0.001643,0.002224,0.056483,290.435699,14.795500,0.564827,-1293.728516,294.500488,0.000000
61.110004,65.131294,-1293.772949,-0.001625,0.002224,0.056483,289.718475,14.758963,0.564827,-1293.772949,294.500488,0.000000
61.410004,65.016609,-1293.817383,-0.001638,0.002230,0.056639,289.208313,14.732974,0.566387,-1293.817383,294.500488,0.000000
61.710003,65.224754,-1293.817383,-0.001625,0.002231,0.056655,290.134186,14.780140,0.566553,-1293.817383,294.500488,0.000000
62.010002,65.102257,-1293.861938,-0.001634,0.002231,0.056655,289.589294,14.752382,0.566553,-1293.861938,294.500488,0.000000
62.310001,65.283974,-1293.772949,-0.001613,0.002235,0.056760,290.397614,14.793560,0.567598,-1293.772949,294.500488,0.000000
62.610004,65.210609,-1293.772949,-0.001625,0.002235,0.056760,290.071289,14.776936,0.567598,-1293.772949,294.500488,0.000000
62.910004,65.080650,-1293.728516,-0.001630,0.002235,0.056760,289.493195,14.747486,0.567598,-1293.728516,294.500488,0.000000
63.210003,64.992393,-1293.861938,-0.001634,0.002235,0.056776,289.100616,14.727487,0.567765,-1293.861938,294.500488,0.000000
63.510002,65.659325,-1293.772949,-0.001625,0.002244,0.057002,292.067261,14.878615,0.570020,-1293.772949,294.500488,0.000000
63.810001,65.594154,-1293.772949,-0.001621,0.002244,0.057002,291.777374,14.863848,0.570020,-1293.772949,294.500488,0.000000
64.110001,65.513344,-1293.772949,-0.001621,0.002244,0.057002,291.417908,14.845536,0.570020,-1293.772949,294.500488,0.000000
64.410004,65.374077,-1293.728516,-0.001621,0.002244,0.057002,290.798431,14.813977,0.570020,-1293.728516,294.500488,0.000000
64.710007,65.287315,-1293.817383,-0.001617,0.002245,0.057011,290.412476,14.794317,0.570111,-1293.817383,294.500488,0.000000
65.010002,65.475365,-1293.772949,-0.001613,0.002249,0.057132,291.248962,14.836929,0.571322,-1293.772949,294.500488,0.000000
65.310005,65.445946,-1293.817383,-0.001617,0.002249,0.057132,291.118103,14.830263,0.571322,-1293.817383,294.500488,0.000000
65.610001,65.349876,-1293.772949,-0.001613,0.002250,0.057141,290.690765,14.808494,0.571413,-1293.772949,294.500488,0.000000
65.910004,65.348381,-1293.683960,-0.001613,0.002252,0.057193,290.684113,14.808154,0.571928,-1293.683960,294.500488,0.000000
66.210007,65.335732,-1293.772949,-0.001617,0.002253,0.057220,290.627838,14.805288,0.572200,-1293.772949,294.500488,0.000000
66.510002,65.301842,-1293.817383,-0.001617,0.002253,0.057228,290.477112,14.797609,0.572276,-1293.817383,294.500488,0.000000
66.810005,65.275398,-1293.772949,-0.001621,0.002254,0.057255,290.359467,14.791616,0.572549,-1293.772949,294.500488,0.000000
67.110001,65.295509,-1293.817383,-0.001600,0.002256,0.057306,290.448944,14.796174,0.573063,-1293.817383,294.500488,0.000000
67.410004,65.280983,-1293.728516,-0.001617,0.002256,0.057306,290.384308,14.792882,0.573063,-1293.728516,294.500488,0.000000
67.710007,65.320457,-1293.772949,-0.001613,0.002259,0.057367,290.559906,14.801826,0.573669,-1293.772949,294.500488,0.000000
68.010002,65.298866,-1293.817383,-0.001604,0.002259,0.057376,290.463867,14.796934,0.573760,-1293.817383,294.500488,0.000000
68.310005,65.253426,-1293.728516,-0.001617,0.002260,0.057393,290.261719,14.786638,0.573926,-1293.728516,294.500488,0.000000
68.610001,65.214714,-1293.728516,-0.001604,0.002260,0.057411,290.089539,14.777865,0.574108,-1293.728516,294.500488,0.000000
68.910004,65.296257,-1293.817383,-0.001604,0.002263,0.057479,290.452271,14.796344,0.574789,-1293.817383,294.500488,0.000000
69.210007,65.289177,-1293.772949,-0.001608,0.002263,0.057479,290.420776,14.794740,0.574789,-1293.772949,294.500488,0.000000
69.510002,65.225136,-1293.817383,-0.001613,0.002263,0.057488,290.135895,14.780228,0.574880,-1293.817383,294.500488,0.000000
69.810005,65.223274,-1293.772949,-0.001595,0.002265,0.057532,290.127625,14.779805,0.575319,-1293.772949,294.500488,0.000000
70.110001,65.210976,-1293.817383,-0.001595,0.002265,0.057541,290.072906,14.777019,0.575410,-1293.817383,294.500488,0.000000
70.410004,65.137260,-1293.728516,-0.001604,0.002265,0.057541,289.744995,14.760314,0.575410,-1293.728516,294.500488,0.000000
70.710007,65.256035,-1293.772949,-0.001604,0.002268,0.057618,290.273346,14.787229,0.576182,-1293.772949,294.500488,0.000000
71.010002,65.217308,-1293.817383,-0.001608,0.002268,0.057618,290.101074,14.778454,0.576182,-1293.817383,294.500488,0.000000
71.310005,65.171883,-1293.728516,-0.001613,0.002269,0.057636,289.899017,14.768160,0.576364,-1293.728516,294.500488,0.000000
71.610001,65.104851,-1293.728516,-0.001600,0.002269,0.057636,289.600830,14.752970,0.576364,-1293.728516,294.500488,0.000000
71.910004,65.153267,-1293.772949,-0.001604,0.002274,0.057757,289.816193,14.763942,0.577575,-1293.772949,294.500488,0.000000
72.210007,65.326790,-1293.772949,-0.001608,0.002274,0.057757,290.588074,14.803262,0.577575,-1293.772949,294.500488,0.000000
72.510002,65.300346,-1293.772949,-0.001608,0.002274,0.057757,290.470459,14.797271,0.577575,-1293.772949,294.500488,0.000000
72.810005,65.234062,-1293.728516,-0.001604,0.002274,0.057757,290.175598,14.782249,0.577575,-1293.728516,294.500488,0.000000
73.110001,65.152519,-1293.817383,-0.001595,0.002274,0.057757,289.812866,14.763772,0.577575,-1293.817383,294.500488,0.000000
73.410004,65.045280,-1293.772949,-0.001600,0.002274,0.057757,289.335846,14.739471,0.577575,-1293.772949,294.500488,0.000000
73.710007,65.003944,-1293.772949,-0.001608,0.002274,0.057765,289.151978,14.730104,0.577651,-1293.772949,294.500488,0.000000
74.010002,64.922401,-1293.683960,-0.001608,0.002274,0.057765,288.789276,14.711626,0.577651,-1293.683960,294.500488,0.000000
74.310005,64.855736,-1293.728516,-0.001604,0.002274,0.057765,288.492706,14.696520,0.577651,-1293.728516,294.500488,0.000000
74.610001,66.022758,-1293.817383,-0.001595,0.002280,0.057904,293.683899,14.960971,0.579044,-1293.817383,294.500488,0.000000
74.910004,65.934868,-1293.772949,-0.001587,0.002280,0.057904,293.292938,14.941054,0.579044,-1293.772949,294.500488,0.000000
75.210007,65.850349,-1293.728516,-0.001595,0.002280,0.057904,292.916992,14.921903,0.579044,-1293.728516,294.500488,0.000000
75.510002,65.756508,-1293.728516,-0.001587,0.002280,0.057904,292.499542,14.900638,0.579044,-1293.728516,294.500488,0.000000
75.810005,65.593407,-1293.728516,-0.001595,0.002280,0.057904,291.774048,14.863678,0.579044,-1293.728516,294.500488,0.000000
76.110001,65.515953,-1293.728516,-0.001582,0.002280,0.057904,291.429504,14.846127,0.579044,-1293.728516,294.500488,0.000000
76.410004,65.399025,-1293.772949,-0.001582,0.002280,0.057904,290.909393,14.819631,0.579044,-1293.772949,294.500488,0.000000
76.710007,65.297752,-1293.683960,-0.001591,0.002280,0.057904,290.458923,14.796682,0.579044,-1293.683960,294.500488,0.000000
77.010002,65.242256,-1293.728516,-0.001578,0.002280,0.057904,290.212036,14.784107,0.579044,-1293.728516,294.500488,0.000000
77.310005,65.122734,-1293.728516,-0.001604,0.002280,0.057904,289.680389,14.757022,0.579044,-1293.728516,294.500488,0.000000
77.610001,65.737511,-1293.728516,-0.001582,0.002294,0.058260,292.415039,14.896333,0.582601,-1293.728516,294.500488,0.000000
77.910004,65.705498,-1293.772949,-0.001587,0.002292,0.058225,292.272644,14.889078,0.582253,-1293.772949,294.500488,0.000000
78.210007,65.645546,-1293.728516,-0.001587,0.002292,0.058225,292.005981,14.875493,0.582253,-1293.728516,294.500488,0.000000
78.510002,65.566231,-1293.772949,-0.001587,0.002292,0.058225,291.653168,14.857520,0.582253,-1293.772949,294.500488,0.000000
78.810005,65.539421,-1293.728516,-0.001587,0.002292,0.058225,291.533905,14.851445,0.582253,-1293.728516,294.500488,0.000000
79.110001,65.456383,-1293.728516,-0.001574,0.002292,0.058225,291.164520,14.832628,0.582253,-1293.728516,294.500488,0.000000
79.410004,65.374077,-1293.772949,-0.001587,0.002292,0.058225,290.798431,14.813977,0.582253,-1293.772949,294.500488,0.000000
79.710007,65.304817,-1293.728516,-0.001591,0.002292,0.058225,290.490326,14.798283,0.582253,-1293.728516,294.500488,0.000000
80.010002,65.226997,-1293.683960,-0.001578,0.002292,0.058225,290.144165,14.780648,0.582253,-1293.683960,294.500488,0.000000
80.310005,65.170769,-1293.772949,-0.001574,0.002292,0.058225,289.894043,14.767907,0.582253,-1293.772949,294.500488,0.000000
80.610001,65.085869,-1293.728516,-0.001582,0.002292,0.058225,289.516418,14.748669,0.582253,-1293.728516,294.500488,0.000000
80.910004,65.024055,-1293.683960,-0.001582,0.002292,0.058225,289.241455,14.734662,0.582253,-1293.683960,294.500488,0.000000
81.210007,64.948830,-1293.728516,-0.001587,0.002292,0.058225,288.906830,14.717615,0.582253,-1293.728516,294.500488,0.000000
81.510002,64.892601,-1293.728516,-0.001582,0.002293,0.058234,288.656708,14.704874,0.582344,-1293.728516,294.500488,0.000000
81.810005,66.300911,-1293.728516,-0.001582,0.002301,0.058451,294.921173,15.024001,0.584509,-1293.728516,294.500488,0.000000
82.110001,66.184731,-1293.772949,-0.001569,0.002299,0.058390,294.404388,14.997675,0.583903,-1293.772949,294.500488,0.000000
82.410004,66.087181,-1293.772949,-0.001561,0.002298,0.058381,293.970459,14.975570,0.583812,-1293.772949,294.500488,0.000000
82.710007,66.000038,-1293.772949,-0.001574,0.002298,0.058381,293.582825,14.955822,0.583812,-1293.772949,294.500488,0.000000
83.010002,65.879021,-1293.683960,-0.001574,0.002298,0.058381,293.044525,14.928400,0.583812,-1293.683960,294.500488,0.000000
83.310005,65.825020,-1293.728516,-0.001578,0.002298,0.058381,292.804321,14.916163,0.583812,-1293.728516,294.500488,0.000000
83.610001,65.773262,-1293.683960,-0.001565,0.002298,0.058381,292.574097,14.904434,0.583812,-1293.683960,294.500488,0.000000
83.910004,65.681664,-1293.728516,-0.001582,0.002298,0.058381,292.166626,14.883677,0.583812,-1293.728516,294.500488,0.000000
84.210007,65.602715,-1293.728516,-0.001565,0.002298,0.058381,291.815460,14.865788,0.583812,-1293.728516,294.500488,0.000000
84.510002,65.539787,-1293.772949,-0.001569,0.002298,0.058381,291.535522,14.851528,0.583812,-1293.772949,294.500488,0.000000
84.810005,65.477608,-1293.728516,-0.001565,0.002298,0.058381,291.258942,14.837438,0.583812,-1293.728516,294.500488,0.000000
85.110001,65.393074,-1293.683960,-0.001556,0.002298,0.058381,290.882935,14.818282,0.583812,-1293.683960,294.500488,0.000000
85.410004,65.293282,-1293.728516,-0.001561,0.002299,0.058407,290.439026,14.795669,0.584070,-1293.728516,294.500488,0.000000
85.710007,65.282478,-1293.683960,-0.001556,0.002308,0.058616,290.390961,14.793221,0.586159,-1293.683960,294.500488,0.000000
86.010002,65.567345,-1293.728516,-0.001552,0.002309,0.058658,291.658112,14.857773,0.586583,-1293.728516,294.500488,0.000000
86.310005,65.526375,-1293.772949,-0.001574,0.002309,0.058658,291.475861,14.848489,0.586583,-1293.772949,294.500488,0.000000
86.610001,65.494728,-1293.728516,-0.001556,0.002309,0.058658,291.335114,14.841318,0.586583,-1293.728516,294.500488,0.000000
86.910004,65.439247,-1293.728516,-0.001561,0.002309,0.058658,291.088318,14.828745,0.586583,-1293.728516,294.500488,0.000000
87.210007,65.381523,-1293.728516,-0.001565,0.002309,0.058658,290.831543,14.815665,0.586583,-1293.728516,294.500488,0.000000
87.510002,65.331261,-1293.728516,-0.001569,0.002310,0.058667,290.607971,14.804276,0.586674,-1293.728516,294.500488,0.000000
87.810005,65.272789,-1293.683960,-0.001561,0.002310,0.058686,290.347870,14.791025,0.586856,-1293.683960,294.500488,0.000000
88.110001,65.272789,-1293.683960,-0.001565,0.002311,0.058693,290.347870,14.791025,0.586931,-1293.683960,294.500488,0.000000
88.410004,65.240028,-1293.728516,-0.001565,0.002311,0.058693,290.202148,14.783602,0.586931,-1293.728516,294.500488,0.000000
88.710007,65.194221,-1293.728516,-0.001565,0.002311,0.058693,289.998383,14.773222,0.586931,-1293.728516,294.500488,0.000000
89.010002,65.146187,-1293.683960,-0.001561,0.002311,0.058702,289.784698,14.762337,0.587022,-1293.683960,294.500488,0.000000
89.310005,65.140984,-1293.728516,-0.001565,0.002312,0.058728,289.761566,14.761158,0.587279,-1293.728516,294.500488,0.000000
89.610001,65.092201,-1293.683960,-0.001561,0.002312,0.058728,289.544586,14.750103,0.587279,-1293.683960,294.500488,0.000000
89.910004,65.079170,-1293.728516,-0.001565,0.002313,0.058754,289.486603,14.747151,0.587537,-1293.728516,294.500488,0.000000
90.210007,65.075066,-1293.683960,-0.001565,0.002313,0.058754,289.468353,14.746221,0.587537,-1293.683960,294.500488,0.000000
90.510002,65.051613,-1293.683960,-0.001556,0.002313,0.058763,289.364014,14.740906,0.587628,-1293.683960,294.500488,0.000000
90.810005,65.011024,-1293.728516,-0.001552,0.002313,0.058763,289.183472,14.731709,0.587628,-1293.728516,294.500488,0.000000
91.110001,65.033363,-1293.683960,-0.001574,0.002315,0.058798,289.282837,14.736771,0.587976,-1293.683960,294.500488,0.000000
91.410004,65.004311,-1293.683960,-0.001552,0.002315,0.058807,289.153625,14.730187,0.588067,-1293.683960,294.500488,0.000000
91.710007,65.023674,-1293.728516,-0.001561,0.002316,0.058823,289.239746,14.734575,0.588233,-1293.728516,294.500488,0.000000
92.010002,65.003197,-1293.772949,-0.001556,0.002316,0.058823,289.148651,14.729935,0.588233,-1293.772949,294.500488,0.000000
92.310005,65.042671,-1293.772949,-0.001552,0.002318,0.058876,289.324249,14.738880,0.588763,-1293.772949,294.500488,0.000000
92.610001,65.038948,-1293.683960,-0.001569,0.002318,0.058876,289.307678,14.738036,0.588763,-1293.683960,294.500488,0.000000
92.910004,65.049751,-1293.683960,-0.001565,0.002319,0.058911,289.355743,14.740485,0.589111,-1293.683960,294.500488,0.000000
93.210007,65.056450,-1293.728516,-0.001556,0.002319,0.058911,289.385529,14.742002,0.589111,-1293.728516,294.500488,0.000000
93.510002,65.031502,-1293.639526,-0.001552,0.002319,0.058911,289.274567,14.736349,0.589111,-1293.639526,294.500488,0.000000
93.810005,65.000587,-1293.772949,-0.001556,0.002319,0.058911,289.137054,14.729344,0.589111,-1293.772949,294.500488,0.000000
94.110008,64.961861,-1293.772949,-0.001544,0.002319,0.058911,288.964783,14.720568,0.589111,-1293.772949,294.500488,0.000000
94.410004,64.914940,-1293.728516,-0.001552,0.002320,0.058919,288.756073,14.709935,0.589187,-1293.728516,294.500488,0.000000
94.710007,64.933189,-1293.728516,-0.001552,0.002321,0.058946,288.837250,14.714071,0.589460,-1293.728516,294.500488,0.000000
95.010002,64.917931,-1293.772949,-0.001548,0.002321,0.058946,288.769379,14.710613,0.589460,-1293.772949,294.500488,0.000000
95.310005,64.867653,-1293.728516,-0.001561,0.002321,0.058954,288.545746,14.699220,0.589535,-1293.728516,294.500488,0.000000
95.610008,66.066322,-1293.728516,-0.001552,0.002328,0.059128,293.877686,14.970842,0.591276,-1293.728516,294.500488,0.000000
95.910004,65.981789,-1293.772949,-0.001548,0.002327,0.059109,293.501648,14.951687,0.591095,-1293.772949,294.500488,0.000000
96.210007,65.854073,-1293.728516,-0.001556,0.002327,0.059109,292.933533,14.922746,0.591095,-1293.728516,294.500488,0.000000
96.510002,65.879768,-1293.817383,-0.001552,0.002327,0.059109,293.047852,14.928569,0.591095,-1293.817383,294.500488,0.000000
96.810005,65.790016,-1293.772949,-0.001552,0.002327,0.059109,292.648621,14.908231,0.591095,-1293.772949,294.500488,0.000000
97.110008,65.758003,-1293.683960,-0.001552,0.002327,0.059109,292.506195,14.900976,0.591095,-1293.683960,294.500488,0.000000
97.410004,65.664909,-1293.639526,-0.001544,0.002327,0.059109,292.092102,14.879881,0.591095,-1293.639526,294.500488,0.000000
97.710007,65.610161,-1293.728516,-0.001548,0.002327,0.059109,291.848572,14.867475,0.591095,-1293.728516,294.500488,0.000000
98.010002,65.576286,-1293.772949,-0.001535,0.002327,0.059109,291.697876,14.859798,0.591095,-1293.772949,294.500488,0.000000
98.310005,65.529366,-1293.772949,-0.001539,0.002327,0.059109,291.489166,14.849166,0.591095,-1293.772949,294.500488,0.000000
98.610008,65.460106,-1293.772949,-0.001539,0.002328,0.059119,291.181091,14.833472,0.591185,-1293.772949,1681.640991,0.000000
98.910004,65.405357,-1293.817383,-0.001544,0.002327,0.059102,290.937561,14.821066,0.591019,-1293.817383,0.059007,0.000000
99.210007,65.280617,-1293.772949,-0.001548,0.002311,0.058711,290.382690,14.792799,0.587113,-1293.772949,0.058502,0.000000
99.510002,65.243004,-1293.772949,-0.001535,0.002297,0.058339,290.215363,14.784276,0.583389,-1293.772949,0.058000,0.000000
99.810005,65.111931,-1293.817383,-0.001531,0.002287,0.058086,289.632324,14.754575,0.580860,-1293.817383,0.057506,0.000000
100.110008,65.038948,-1293.817383,-0.001535,0.002272,0.057714,289.307678,14.738036,0.577136,-1293.817383,0.057002,0.000000
100.410004,64.983467,-1293.817383,-0.001535,0.002249,0.057132,289.060913,14.725465,0.571322,-1293.817383,0.056499,0.000000
100.710007,64.948082,-1293.817383,-0.001539,0.002232,0.056681,288.903503,14.717445,0.566811,-1293.817383,0.056006,0.000000
101.010002,64.869148,-1293.772949,-0.001535,0.002205,0.055997,288.552368,14.699559,0.559968,-1293.772949,0.055502,0.000000
101.310005,64.801750,-1293.817383,-0.001531,0.002185,0.055502,288.252594,14.684287,0.555017,-1293.817383,0.054999,0.000000
101.610008,64.782753,-1293.817383,-0.001526,0.002169,0.055085,288.168091,14.679982,0.550854,-1293.817383,0.054506,0.000000
101.910004,64.688179,-1293.817383,-0.001526,0.002156,0.054773,287.747406,14.658551,0.547735,-1293.817383,0.054001,0.000000
102.210007,64.563057,-1293.817383,-0.001544,0.002139,0.054322,287.190826,14.630198,0.543223,-1293.817383,0.053499,0.000000
102.510002,64.502357,-1293.817383,-0.001531,0.002120,0.053838,286.920807,14.616443,0.538379,-1293.817383,0.053005,0.000000
102.810005,64.346336,-1293.817383,-0.001539,0.002109,0.053568,286.226807,14.581088,0.535684,-1293.817383,0.052501,0.000000
103.110008,63.369225,-1293.817383,-0.001526,0.002076,0.052719,281.880402,14.359672,0.527190,-1293.817383,0.051998,0.000000
103.410004,62.863548,-1293.817383,-0.001522,0.002062,0.052372,279.631042,14.245084,0.523723,-1293.817383,0.051505,0.000000
103.710007,61.689087,-1293.906372,-0.001518,0.002039,0.051799,274.406769,13.978947,0.517986,-1293.906372,0.051001,0.000000
104.010002,61.111908,-1293.817383,-0.001513,0.002025,0.051444,271.839355,13.848156,0.514443,-1293.817383,0.050498,0.000000
104.310005,59.949356,-1293.861938,-0.001518,0.002009,0.051019,266.668060,13.584719,0.510189,-1293.861938,0.050005,0.000000
104.610008,58.567856,-1293.817383,-0.001505,0.001989,0.050524,260.522827,13.271666,0.505238,-1293.817383,0.049500,0.000000
104.910004,57.279823,-1293.861938,-0.001518,0.001970,0.050030,254.793381,12.979793,0.500303,-1293.861938,0.048998,0.000000
105.210007,55.542702,-1293.906372,-0.001522,0.001947,0.049458,247.066284,12.586156,0.494580,-1293.906372,0.048504,0.000000
105.510002,54.401009,-1293.906372,-0.001513,0.001933,0.049102,241.987778,12.327445,0.491022,-1293.906372,0.048002,0.000000
105.810005,52.075920,-1293.861938,-0.001522,0.001908,0.048469,231.645264,11.800572,0.484694,-1293.861938,0.047497,0.000000
106.110008,51.005348,-1293.861938,-0.001535,0.001899,0.048226,226.883118,11.557978,0.482256,-1293.861938,0.047004,0.000000
106.410004,48.747276,-1293.817383,-0.001522,0.001876,0.047653,216.838715,11.046291,0.476533,-1293.817383,0.046501,0.000000
106.710007,46.704071,-1293.950806,-0.001526,0.001853,0.047073,207.750076,10.583294,0.470735,-1293.950806,0.045997,0.000000
107.010002,44.900299,-1293.906372,-0.001539,0.001837,0.046657,199.726501,10.174554,0.466572,-1293.906372,0.045504,0.000000
107.310005,42.301888,-1293.906372,-0.001531,0.001814,0.046076,188.168198,9.585745,0.460758,-1293.906372,0.045001,0.000000
107.610008,40.154037,-1293.906372,-0.001544,0.001792,0.045520,178.614075,9.099035,0.455202,-1293.906372,0.044497,0.000000
107.910004,38.464584,-1293.861938,-0.001552,0.001775,0.045096,171.099014,8.716199,0.450963,-1293.861938,0.044003,0.000000
108.210007,36.860405,-1293.861938,-0.001544,0.001756,0.044610,163.963272,8.352687,0.446103,-1293.861938,0.043501,0.000000
108.510002,35.403313,-1293.861938,-0.001556,0.001745,0.044324,157.481796,8.022505,0.443241,-1293.861938,0.042996,0.000000
108.810005,32.927032,-1293.906372,-0.001548,0.001722,0.043734,146.466751,7.461372,0.437337,-1293.906372,0.042503,0.000000
109.110008,30.276489,-1293.906372,-0.001556,0.001696,0.043075,134.676544,6.860751,0.430751,-1293.906372,0.042000,0.000000
109.410004,28.578094,-1293.861938,-0.001548,0.001679,0.042659,127.121712,6.475889,0.426588,-1293.861938,0.041505,0.000000
109.710007,26.465256,-1293.861938,-0.001561,0.001661,0.042182,117.723335,5.997113,0.421819,-1293.861938,0.041003,0.000000
110.010002,24.129364,-1293.817383,-0.001565,0.001635,0.041531,107.332771,5.467792,0.415309,-1293.817383,0.040500,0.000000
110.310005,22.534866,-1293.861938,-0.001552,0.001621,0.041175,100.240089,5.106473,0.411751,-1293.861938,0.040005,0.000000
110.610008,20.198601,-1293.861938,-0.001565,0.001600,0.040630,89.847862,4.577068,0.406301,-1293.861938,0.039502,0.000000
110.910004,17.640770,-1293.861938,-0.001578,0.001574,0.039979,78.470062,3.997456,0.399791,-1293.861938,0.039000,0.000000
111.210007,16.236931,-1293.772949,-0.001578,0.001560,0.039614,72.225479,3.679341,0.396142,-1293.772949,0.038504,0.000000
111.510002,14.243988,-1293.861938,-0.001569,0.001539,0.039095,63.360424,3.227734,0.390949,-1293.861938,0.038002,0.000000
111.810005,12.419739,-1293.861938,-0.001591,0.001520,0.038609,55.245758,2.814353,0.386090,-1293.861938,0.037499,0.000000
112.110008,10.756348,-1293.817383,-0.001591,0.001504,0.038209,47.846622,2.437423,0.382093,-1293.817383,0.037004,0.000000
112.410004,9.016258,-1293.906372,-0.001604,0.001486,0.037741,40.106319,2.043113,0.377415,-1293.906372,0.036502,0.000000
112.710007,6.320274,-1293.861938,-0.001604,0.001455,0.036969,28.113985,1.432195,0.369693,-1293.861938,0.035999,0.000000
113.010002,4.526558,-1293.906372,-0.001608,0.001437,0.036511,20.135136,1.025733,0.365106,-1293.906372,0.035504,0.000000
113.310005,3.292892,-1293.906372,-0.001608,0.001423,0.036155,14.647517,0.746180,0.361548,-1293.906372,0.035001,0.000000
113.610008,1.692802,-1293.861938,-0.001613,0.001403,0.035634,7.529961,0.383595,0.356340,-1293.861938,0.034499,0.000000
113.910004,0.142616,-1293.861938,-0.001630,0.001386,0.035192,0.634389,0.032317,0.351920,-1293.861938,0.034003,0.000000
114.210007,-1.299206,-1293.906372,-0.001621,0.001366,0.034689,-5.779156,-0.294404,0.346893,-1293.906372,0.033501,0.000000
114.510002,-3.138355,-1293.861938,-0.001638,0.001342,0.034099,-13.960101,-0.711161,0.340989,-1293.861938,0.032998,0.000000
114.810005,-0.266617,-1293.861938,-0.001673,0.001323,0.033596,-1.185971,-0.060416,0.335962,-1293.861938,0.032503,0.000000
115.110008,-0.088249,-1293.906372,-0.001686,0.001305,0.033136,-0.392552,-0.019998,0.331360,-1293.906372,0.032001,0.000000
115.410004,-0.016754,-1293.861938,-0.001699,0.001277,0.032434,-0.074526,-0.003797,0.324335,-1293.861938,0.031498,0.000000
115.710007,-0.000374,-1293.950806,-0.001720,0.001266,0.032147,-0.001663,-0.000085,0.321474,-1293.950806,0.031003,0.000000
116.010002,0.008568,-1293.950806,-0.001733,0.001243,0.031575,0.038112,0.001941,0.315751,-1293.950806,0.030500,0.000000
116.310005,-0.026070,-1293.906372,-0.001742,0.001221,0.031003,-0.115964,-0.005907,0.310028,-1293.906372,0.029998,0.000000
116.610008,-0.039841,-1293.906372,-0.001763,0.001198,0.030421,-0.177220,-0.009028,0.304215,-1293.906372,0.029502,0.000000
116.910004,-0.041336,-1293.995361,-0.001759,0.001183,0.030040,-0.183872,-0.009367,0.300400,-1293.995361,0.029000,0.000000
117.210007,0.011169,-1293.906372,-0.001785,0.001168,0.029677,0.049684,0.002531,0.296766,-1293.906372,0.028497,0.000000
117.510002,0.037613,-1293.906372,-0.001794,0.001148,0.029156,0.167311,0.008523,0.291558,-1293.906372,0.028002,0.000000
117.810005,0.030533,-1293.906372,-0.001807,0.001129,0.028679,0.135817,0.006919,0.286789,-1293.906372,0.027500,0.000000
118.110008,0.009682,-1293.861938,-0.001850,0.001103,0.028020,0.043066,0.002194,0.280203,-1293.861938,0.026997,0.000000
118.410004,0.017502,-1293.950806,-0.001863,0.001085,0.027569,0.077852,0.003966,0.275692,-1293.950806,0.026502,0.000000
118.710007,-0.011543,-1293.950806,-0.001871,0.001060,0.026936,-0.051347,-0.002616,0.269363,-1293.950806,0.025999,0.000000
119.010002,-0.020851,-1293.906372,-0.001901,0.001043,0.026485,-0.092750,-0.004725,0.264852,-1293.906372,0.025497,0.000000
119.300003,0.014893,-1293.817383,-0.001888,0.001035,0.026294,0.066245,0.003375,0.262944,-1293.817383,0.026190,0.000000