File: Data/Sima compression/P2-15-3_10302024_172107.csv
Time (sec),S:Load (lbs),S:HL1 (DIM),S:LVDT (in),S:Position (in),Ch:Position (mm),Ch:Load (N),Ch:Stress (MPa),Ch:Strain (mm/mm),Ch:HL1 (DIM),Set Point (),Cycles ()
0.210000,-0.013405,-1294.128784,-0.007127,-0.003943,-0.100147,-0.059628,-0.003038,-1.001468,-1294.128784,-0.099965,0.000000
0.500000,-0.003349,-1294.128784,-0.007118,-0.003878,-0.098500,-0.014898,-0.000759,-0.984996,-1294.128784,-0.098023,0.000000
0.790000,-0.016754,-1294.039795,-0.007058,-0.003710,-0.094232,-0.074526,-0.003797,-0.942318,-1294.039795,-0.093201,0.000000
1.080000,0.015266,-1294.128784,-0.006885,-0.003532,-0.089705,0.067908,0.003459,-0.897050,-1294.128784,-0.088361,0.000000
1.370000,-0.029045,-1294.084351,-0.006661,-0.003335,-0.084710,-0.129199,-0.006582,-0.847105,-1294.084351,-0.083540,0.000000
1.660000,-0.021225,-1294.128784,-0.006510,-0.003152,-0.080070,-0.094413,-0.004810,-0.800702,-1294.128784,-0.078700,0.000000
1.950000,-0.069260,-1294.173218,-0.006286,-0.002951,-0.074962,-0.308082,-0.015694,-0.749621,-1294.173218,-0.073878,0.000000
2.240000,-0.018990,-1294.039795,-0.006096,-0.002771,-0.070384,-0.084470,-0.004303,-0.703839,-1294.039795,-0.069040,0.000000
2.530000,-0.008568,-1294.128784,-0.005902,-0.002575,-0.065415,-0.038112,-0.001941,-0.654151,-1294.128784,-0.064201,0.000000
2.820000,0.029419,-1294.128784,-0.005713,-0.002387,-0.060636,0.130862,0.006666,-0.606355,-1294.128784,-0.059379,0.000000
3.110000,-0.003723,-1294.128784,-0.005510,-0.002193,-0.055692,-0.016561,-0.000844,-0.556925,-1294.128784,-0.054539,0.000000
3.400000,0.014526,-1294.128784,-0.005320,-0.002011,-0.051079,0.064617,0.003292,-0.510794,-1294.128784,-0.049718,0.000000
3.690000,-0.024948,-1294.128784,-0.005118,-0.001814,-0.046076,-0.110975,-0.005653,-0.460758,-1294.128784,-0.044878,0.000000
3.980000,-0.006706,-1294.128784,-0.004941,-0.001628,-0.041340,-0.029831,-0.001520,-0.413401,-1294.128784,-0.040056,0.000000
4.270000,-0.075592,-1294.173218,-0.004721,-0.001430,-0.036327,-0.336250,-0.017129,-0.363274,-1294.173218,-0.035218,0.000000
4.560000,0.033142,-1294.128784,-0.004540,-0.001249,-0.031723,0.147423,0.007510,-0.317235,-1294.128784,-0.030396,0.000000
4.850000,-0.002235,-1294.173218,-0.004329,-0.001052,-0.026727,-0.009944,-0.000507,-0.267274,-1294.173218,-0.025557,0.000000
5.140000,0.057716,-1294.084351,-0.004139,-0.000866,-0.021984,0.256735,0.013079,-0.219842,-1294.084351,-0.020717,0.000000
5.430000,0.021225,-1294.128784,-0.003941,-0.000671,-0.017041,0.094413,0.004810,-0.170411,-1294.128784,-0.015897,0.000000
5.720000,0.022713,-1294.173218,-0.003755,-0.000489,-0.012419,0.101031,0.005147,-0.124190,-1294.173218,-0.011056,0.000000
6.010000,-0.032021,-1294.084351,-0.003553,-0.000288,-0.007328,-0.142435,-0.007256,-0.073276,-1294.084351,-0.006234,0.000000
6.300000,0.022713,-1294.173218,-0.003359,-0.000103,-0.002610,0.101031,0.005147,-0.026101,-1294.173218,-0.001396,0.000000
6.590000,0.259918,-1294.128784,-0.003195,0.000019,0.000494,1.156174,0.058898,0.004936,-1294.128784,0.000554,0.000000
6.880000,0.242416,-1294.173218,-0.003191,0.000019,0.000486,1.078322,0.054932,0.004860,-1294.173218,0.000554,0.000000
7.170001,0.205551,-1294.084351,-0.003191,0.000019,0.000486,0.914337,0.046579,0.004860,-1294.084351,0.000719,0.000000
7.460001,0.228264,-1294.084351,-0.003182,0.000021,0.000521,1.015368,0.051725,0.005208,-1294.084351,0.001205,0.000000
7.750000,0.303856,-1294.173218,-0.003182,0.000033,0.000849,1.351619,0.068855,0.008493,-1294.173218,0.001682,0.000000
8.040000,0.486694,-1294.039795,-0.003186,0.000051,0.001300,2.164925,0.110287,0.013005,-1294.039795,0.002168,0.000000
8.330000,0.761871,-1294.173218,-0.003169,0.000069,0.001752,3.388973,0.172643,0.017516,-1294.173218,0.002654,0.000000
8.620001,1.134621,-1294.173218,-0.003160,0.000089,0.002263,5.047045,0.257109,0.022634,-1294.173218,0.003138,0.000000
8.910001,1.528961,-1294.084351,-0.003130,0.000104,0.002645,6.801159,0.346468,0.026449,-1294.084351,0.003615,0.000000
9.200001,1.962402,-1294.173218,-0.003109,0.000120,0.003052,8.729201,0.444687,0.030521,-1294.173218,0.004101,0.000000
9.490001,2.140396,-1294.084351,-0.003100,0.000130,0.003296,9.520957,0.485021,0.032959,-1294.084351,0.004587,0.000000
9.780001,3.048615,-1294.128784,-0.003096,0.000161,0.004094,13.560915,0.690826,0.040937,-1294.128784,0.005073,0.000000
10.070001,3.697662,-1294.128784,-0.003061,0.000181,0.004587,16.448023,0.837902,0.045873,-1294.128784,0.005550,0.000000
10.360001,4.163872,-1294.128784,-0.003078,0.000196,0.004969,18.521826,0.943547,0.049688,-1294.128784,0.006036,0.000000
10.650001,5.167786,-1294.128784,-0.003035,0.000223,0.005655,22.987459,1.171037,0.056546,-1294.128784,0.006521,0.000000
10.940001,5.603088,-1294.084351,-0.003031,0.000235,0.005957,24.923782,1.269678,0.059574,-1294.084351,0.006998,0.000000
11.230000,6.155319,-1294.084351,-0.003027,0.000251,0.006365,27.380228,1.394815,0.063647,-1294.084351,0.007483,0.000000
11.520000,7.308556,-1294.173218,-0.003005,0.000276,0.007016,32.510078,1.656142,0.070157,-1294.173218,0.007969,0.000000
11.810000,8.170227,-1294.084351,-0.002988,0.000298,0.007571,36.342983,1.851400,0.075713,-1294.084351,0.008455,0.000000
12.100000,8.741814,-1294.128784,-0.002984,0.000314,0.007988,38.885529,1.980923,0.079876,-1294.128784,0.008932,0.000000
12.390000,9.734192,-1294.039795,-0.002962,0.000334,0.008481,43.299847,2.205800,0.084812,-1294.039795,0.009418,0.000000
12.680000,10.448402,-1294.173218,-0.002949,0.000350,0.008898,46.476814,2.367642,0.088975,-1294.173218,0.009903,0.000000
12.970000,10.871040,-1294.128784,-0.002945,0.000363,0.009228,48.356804,2.463413,0.092276,-1294.128784,0.010389,0.000000
13.260000,11.844421,-1294.128784,-0.002940,0.000386,0.009800,52.686619,2.683984,0.097998,-1294.128784,0.010866,0.000000
13.550000,13.271355,-1294.173218,-0.002915,0.000414,0.010510,59.033936,3.007332,0.105099,-1294.173218,0.011352,0.000000
13.840001,13.869759,-1294.128784,-0.002902,0.000431,0.010935,61.695766,3.142932,0.109353,-1294.128784,0.011838,0.000000
14.130001,14.728073,-1294.084351,-0.002889,0.000449,0.011396,65.513741,3.337429,0.113956,-1294.084351,0.012324,0.000000
14.420001,15.430000,-1294.128784,-0.002876,0.000467,0.011854,68.636070,3.496488,0.118543,-1294.128784,0.012801,0.000000
14.710001,16.370613,-1294.128784,-0.002867,0.000486,0.012349,72.820122,3.709634,0.123494,-1294.128784,0.013285,0.000000
15.000001,16.967522,-1294.128784,-0.002863,0.000502,0.012748,75.475304,3.844895,0.127475,-1294.128784,0.013771,0.000000
15.290001,18.196350,-1294.128784,-0.002824,0.000526,0.013373,80.941406,4.123352,0.133728,-1294.128784,0.014257,0.000000
15.580001,18.839439,-1294.128784,-0.002820,0.000544,0.013815,83.802010,4.269078,0.138149,-1294.128784,0.014734,0.000000
15.870001,19.323151,-1294.173218,-0.002798,0.000561,0.014240,85.953667,4.378689,0.142403,-1294.173218,0.015220,0.000000
16.160000,19.964752,-1294.128784,-0.002794,0.000578,0.014690,88.807655,4.524077,0.146899,-1294.128784,0.015706,0.000000
16.450001,20.951912,-1294.128784,-0.002777,0.000601,0.015255,93.198761,4.747771,0.152546,-1294.128784,0.016183,0.000000
16.740002,21.281090,-1294.128784,-0.002777,0.000615,0.015627,94.663017,4.822364,0.156271,-1294.128784,0.016667,0.000000
17.030001,21.737617,-1294.084351,-0.002746,0.000629,0.015965,96.693748,4.925815,0.159647,-1294.084351,0.017153,0.000000
17.320002,23.276260,-1294.217773,-0.002725,0.000660,0.016772,103.537979,5.274476,0.167716,-1294.217773,0.017639,0.000000
17.610001,23.535431,-1294.173218,-0.002738,0.000675,0.017144,104.690826,5.333205,0.171441,-1294.173218,0.018116,0.000000
17.900002,24.298050,-1294.128784,-0.002725,0.000696,0.017674,108.083122,5.506017,0.176739,-1294.128784,0.018602,0.000000
18.190001,24.945229,-1294.173218,-0.002690,0.000715,0.018151,110.961922,5.652669,0.181508,-1294.173218,0.019088,0.000000
18.480001,25.923454,-1294.128784,-0.002677,0.000738,0.018749,115.313286,5.874339,0.187489,-1294.128784,0.019572,0.000000
18.770000,25.717903,-1294.173218,-0.002665,0.000746,0.018940,114.398949,5.827760,0.189396,-1294.173218,0.020049,0.000000
19.060001,25.943192,-1294.128784,-0.002660,0.000760,0.019304,115.401077,5.878811,0.193045,-1294.128784,0.020535,0.000000
19.350000,27.515717,-1294.173218,-0.002639,0.000792,0.020111,122.396019,6.235150,0.201114,-1294.173218,0.021021,0.000000
19.640001,27.614395,-1294.173218,-0.002613,0.000805,0.020449,122.834961,6.257512,0.204490,-1294.173218,0.021507,0.000000
19.930000,28.476814,-1294.128784,-0.002600,0.000828,0.021030,126.671196,6.452938,0.210304,-1294.128784,0.021984,0.000000
20.220001,28.776947,-1294.217773,-0.002604,0.000847,0.021516,128.006256,6.520949,0.215164,-1294.217773,0.022470,0.000000
20.510000,29.655746,-1294.128784,-0.002565,0.000868,0.022045,131.915344,6.720088,0.220447,-1294.128784,0.022955,0.000000
20.800001,29.686653,-1294.084351,-0.002570,0.000882,0.022391,132.052826,6.727092,0.223914,-1294.084351,0.023441,0.000000
21.090000,29.572701,-1294.173218,-0.002561,0.000894,0.022696,131.545944,6.701270,0.226957,-1294.173218,0.023918,0.000000
21.380001,30.979156,-1294.128784,-0.002531,0.000920,0.023363,137.802170,7.019977,0.233634,-1294.128784,0.024403,0.000000
21.670000,31.502708,-1294.128784,-0.002518,0.000941,0.023908,140.131042,7.138616,0.239084,-1294.128784,0.024889,0.000000
21.960001,31.787949,-1294.128784,-0.002496,0.000959,0.024352,141.399857,7.203252,0.243520,-1294.128784,0.025366,0.000000
22.250002,32.120102,-1294.084351,-0.002475,0.000976,0.024794,142.877350,7.278519,0.247941,-1294.084351,0.025852,0.000000
22.540001,33.000389,-1294.173218,-0.002462,0.001000,0.025401,146.793060,7.477995,0.254012,-1294.173218,0.026337,0.000000
22.830002,32.893524,-1294.128784,-0.002458,0.001012,0.025704,146.317703,7.453779,0.257040,-1294.128784,0.026823,0.000000
23.120001,34.165916,-1294.128784,-0.002436,0.001042,0.026476,151.977585,7.742107,0.264761,-1294.128784,0.027300,0.000000
23.410002,34.286942,-1294.128784,-0.002423,0.001058,0.026883,152.515930,7.769532,0.268834,-1294.128784,0.027786,0.000000
23.700001,34.624306,-1294.128784,-0.002397,0.001079,0.027395,154.016602,7.845980,0.273951,-1294.128784,0.028272,0.000000
23.990002,34.650002,-1294.173218,-0.002397,0.001094,0.027786,154.130905,7.851803,0.277857,-1294.173218,0.028758,0.000000
24.280001,35.054024,-1294.084351,-0.002371,0.001113,0.028281,155.928085,7.943356,0.282807,-1294.084351,0.029235,0.000000
24.570002,35.335167,-1294.128784,-0.002363,0.001127,0.028627,157.178665,8.007063,0.286274,-1294.128784,0.029719,0.000000
24.860001,35.568642,-1294.128784,-0.002345,0.001143,0.029035,158.217224,8.059969,0.290347,-1294.128784,0.030205,0.000000
25.150002,37.131493,-1294.217773,-0.002324,0.001175,0.029849,165.169128,8.414117,0.298492,-1294.217773,0.030691,0.000000
25.440001,36.964294,-1294.217773,-0.002302,0.001189,0.030188,164.425400,8.376229,0.301883,-1294.217773,0.031168,0.000000
25.730001,37.462906,-1294.084351,-0.002289,0.001209,0.030700,166.643326,8.489216,0.307000,-1294.084351,0.031654,0.000000
26.020000,37.630470,-1294.084351,-0.002289,0.001224,0.031089,167.388687,8.527186,0.310891,-1294.084351,0.032140,0.000000
26.310001,38.298508,-1294.173218,-0.002272,0.001247,0.031670,170.360275,8.678566,0.316705,-1294.173218,0.032624,0.000000
26.600000,38.663429,-1294.173218,-0.002259,0.001264,0.032096,171.983521,8.761258,0.320959,-1294.173218,0.033101,0.000000
26.890001,39.238747,-1294.217773,-0.002238,0.001284,0.032624,174.542664,8.891627,0.326243,-1294.217773,0.033587,0.000000
27.180002,40.055359,-1294.084351,-0.002212,0.001305,0.033145,178.175140,9.076674,0.331451,-1294.084351,0.034073,0.000000
27.470001,40.193138,-1294.084351,-0.002199,0.001323,0.033605,178.788010,9.107896,0.336053,-1294.084351,0.034550,0.000000
27.760002,40.626205,-1294.084351,-0.002190,0.001341,0.034073,180.714386,9.206030,0.340731,-1294.084351,0.035036,0.000000
28.050001,41.041779,-1294.084351,-0.002173,0.001358,0.034499,182.562943,9.300200,0.344986,-1294.084351,0.035522,0.000000
28.340002,41.453247,-1294.173218,-0.002169,0.001376,0.034948,184.393250,9.393439,0.349482,-1294.173218,0.036006,0.000000
28.630001,41.672203,-1293.995361,-0.002143,0.001391,0.035331,185.367218,9.443056,0.353312,-1293.995361,0.036483,0.000000
28.920002,41.640175,-1294.128784,-0.002151,0.001412,0.035876,185.224747,9.435799,0.358763,-1294.128784,0.036969,0.000000
29.210001,43.265587,-1294.128784,-0.002117,0.001436,0.036476,192.454941,9.804123,0.364758,-1294.128784,0.037455,0.000000
29.500002,43.618965,-1294.084351,-0.002082,0.001455,0.036960,194.026840,9.884199,0.369603,-1294.084351,0.037941,0.000000
29.790001,43.882607,-1294.173218,-0.002082,0.001472,0.037395,195.199585,9.943941,0.373948,-1294.173218,0.038418,0.000000
30.080002,44.465370,-1294.128784,-0.002061,0.001492,0.037888,197.791840,10.075996,0.378883,-1294.128784,0.038904,0.000000
30.370001,44.595695,-1294.084351,-0.002044,0.001505,0.038235,198.371567,10.105529,0.382350,-1294.084351,0.039389,0.000000
30.660002,44.708153,-1294.084351,-0.002044,0.001521,0.038626,198.871796,10.131013,0.386256,-1294.084351,0.039875,0.000000
30.950001,46.331329,-1294.128784,-0.002044,0.001550,0.039381,206.092041,10.498829,0.393811,-1294.128784,0.040352,0.000000
31.240002,46.866051,-1294.128784,-0.002022,0.001569,0.039858,208.470612,10.619999,0.398580,-1294.128784,0.040838,0.000000
31.530001,47.357582,-1294.039795,-0.002005,0.001588,0.040335,210.657043,10.731381,0.403349,-1294.039795,0.041323,0.000000
31.820002,47.373222,-1294.084351,-0.001979,0.001605,0.040768,210.726624,10.734926,0.407679,-1294.084351,0.041808,0.000000
32.110001,48.539124,-1294.039795,-0.001979,0.001627,0.041331,215.912811,10.999123,0.413311,-1294.039795,0.042286,0.000000
32.400002,47.914284,-1294.039795,-0.001962,0.001637,0.041584,213.133377,10.857532,0.415839,-1294.039795,0.042771,0.000000
32.690002,49.485321,-1294.128784,-0.001949,0.001664,0.042259,220.121704,11.213534,0.422591,-1294.128784,0.043257,0.000000
32.980003,49.891205,-1294.084351,-0.001919,0.001682,0.042728,221.927170,11.305509,0.427284,-1294.084351,0.043734,0.000000
33.270000,50.486633,-1294.128784,-0.001910,0.001703,0.043248,224.575760,11.440434,0.432477,-1294.128784,0.044220,0.000000
33.560001,51.150574,-1294.128784,-0.001901,0.001723,0.043752,227.529114,11.590886,0.437519,-1294.128784,0.044706,0.000000
33.850002,51.837601,-1294.084351,-0.001897,0.001741,0.044220,230.585159,11.746568,0.442197,-1294.084351,0.045190,0.000000
34.140003,52.132515,-1294.128784,-0.001884,0.001756,0.044601,231.897003,11.813396,0.446012,-1294.128784,0.045669,0.000000
34.430000,52.529839,-1294.128784,-0.001871,0.001773,0.045043,233.664398,11.903432,0.450433,-1294.128784,0.046153,0.000000
34.720001,53.776169,-1294.084351,-0.001867,0.001797,0.045650,239.208344,12.185854,0.456504,-1294.084351,0.046639,0.000000
35.010002,54.556290,-1294.128784,-0.001832,0.001819,0.046214,242.678497,12.362632,0.462136,-1294.128784,0.047125,0.000000
35.300003,54.810623,-1294.039795,-0.001837,0.001837,0.046648,243.809830,12.420265,0.466481,-1294.039795,0.047602,0.000000
35.590000,55.668564,-1294.084351,-0.001824,0.001856,0.047134,247.626144,12.614676,0.471341,-1294.084351,0.048088,0.000000
35.880001,55.583664,-1294.039795,-0.001798,0.001874,0.047611,247.248489,12.595439,0.476110,-1294.039795,0.048572,0.000000
36.170002,56.603592,-1294.128784,-0.001789,0.001887,0.047939,251.785355,12.826558,0.479395,-1294.128784,0.049058,0.000000
36.460003,56.977081,-1294.128784,-0.001785,0.001903,0.048339,253.446716,12.911191,0.483392,-1294.128784,0.049535,0.000000
36.750000,58.746971,-1294.128784,-0.001763,0.001931,0.049042,261.319580,13.312254,0.490416,-1294.128784,0.050021,0.000000
37.040001,59.172592,-1294.084351,-0.001768,0.001948,0.049484,263.212830,13.408701,0.494837,-1294.084351,0.050507,0.000000
37.330002,60.293060,-1294.128784,-0.001746,0.001971,0.050056,268.196930,13.662603,0.500560,-1294.128784,0.050993,0.000000
37.620003,60.413338,-1294.128784,-0.001733,0.001981,0.050325,268.731934,13.689858,0.503255,-1294.128784,0.051470,0.000000
37.910004,61.453369,-1294.128784,-0.001725,0.002002,0.050863,273.358246,13.925532,0.508629,-1294.128784,0.051954,0.000000
38.200001,61.772125,-1294.084351,-0.001720,0.002018,0.051261,274.776123,13.997764,0.512611,-1294.084351,0.052440,0.000000
38.490002,62.406273,-1294.128784,-0.001707,0.002034,0.051661,277.596954,14.141464,0.516608,-1294.128784,0.052917,0.000000
38.780003,64.445381,-1294.217773,-0.001690,0.002063,0.052406,286.667358,14.603533,0.524057,-1294.217773,0.053403,0.000000
39.070004,64.968193,-1294.084351,-0.001690,0.002083,0.052917,288.992950,14.722003,0.529174,-1294.084351,0.053889,0.000000
39.360001,65.859276,-1294.084351,-0.001669,0.002100,0.053334,292.956696,14.923925,0.533337,-1294.084351,0.054375,0.000000
39.650002,65.641441,-1294.084351,-0.001656,0.002101,0.053369,291.987701,14.874563,0.533685,-1294.084351,0.009387,0.000000
39.940002,66.563438,-1294.084351,-0.001643,0.002119,0.053811,296.088959,15.083491,0.538106,-1294.084351,294.500488,0.000000
40.230003,65.332375,-1294.128784,-0.001638,0.002102,0.053387,290.612915,14.804527,0.533867,-1294.128784,294.500488,0.000000
40.520000,66.489708,-1294.039795,-0.001634,0.002077,0.052761,295.760986,15.066783,0.527614,-1294.039795,294.500488,0.000000
40.810001,65.431801,-1294.128784,-0.001613,0.002103,0.053412,291.055176,14.827059,0.534124,-1294.128784,294.500488,0.000000
41.100002,65.062782,-1294.084351,-0.001613,0.002145,0.054471,289.413696,14.743437,0.544707,-1294.084351,294.500488,0.000000
41.390003,65.135384,-1294.084351,-0.001625,0.002154,0.054713,289.736664,14.759890,0.547129,-1294.084351,294.500488,0.000000
41.680000,64.779396,-1294.173218,-0.001613,0.002163,0.054929,288.153137,14.679221,0.549294,-1294.173218,294.500488,0.000000
41.970001,65.342430,-1294.128784,-0.001604,0.002172,0.055164,290.657654,14.806807,0.551641,-1294.128784,294.500488,0.000000
42.260002,66.225700,-1294.128784,-0.001600,0.002184,0.055467,294.586639,15.006958,0.554669,-1294.128784,294.500488,0.000000
42.550003,65.340202,-1294.084351,-0.001578,0.002182,0.055434,290.647736,14.806301,0.554336,-1294.084351,294.500488,0.000000
42.840000,65.764702,-1294.128784,-0.001587,0.002198,0.055832,292.536011,14.902494,0.558317,-1294.128784,294.500488,0.000000
43.130001,65.159966,-1294.128784,-0.001574,0.002198,0.055832,289.846008,14.765460,0.558317,-1294.128784,294.500488,0.000000
43.420002,64.523216,-1294.084351,-0.001565,0.002198,0.055832,287.013611,14.621170,0.558317,-1294.084351,294.500488,0.000000
43.710003,68.686714,-1294.084351,-0.001565,0.002241,0.056916,305.533752,15.564632,0.569157,-1294.084351,294.500488,0.000000
44.000004,67.160347,-1294.128784,-0.001539,0.002059,0.052303,298.744141,15.218752,0.523027,-1294.128784,294.500488,0.000000
44.290001,66.149727,-1294.084351,-0.001544,0.002018,0.051261,294.248688,14.989743,0.512611,-1294.084351,294.500488,0.000000
44.580002,65.510368,-1294.128784,-0.001539,0.002080,0.052831,291.404663,14.844861,0.528311,-1294.128784,294.500488,0.000000
44.870003,65.294762,-1294.128784,-0.001535,0.002228,0.056595,290.445618,14.796005,0.565948,-1294.128784,294.500488,0.000000
45.160004,64.934685,-1294.128784,-0.001535,0.002233,0.056725,288.843903,14.714410,0.567250,-1294.128784,294.500488,0.000000
45.450001,65.164803,-1294.173218,-0.001535,0.002240,0.056907,289.867523,14.766556,0.569067,-1294.173218,294.500488,0.000000
45.740002,65.450050,-1294.084351,-0.001539,0.002248,0.057097,291.136353,14.831194,0.570974,-1294.084351,294.500488,0.000000
46.030003,64.951439,-1294.173218,-0.001548,0.002248,0.057106,288.918427,14.718206,0.571065,-1294.173218,294.500488,0.000000
46.320004,64.463631,-1294.084351,-0.001539,0.002248,0.057106,286.748566,14.607668,0.571065,-1294.084351,294.500488,0.000000
46.610001,66.560463,-1294.128784,-0.001522,0.002092,0.053143,296.075714,15.082816,0.531430,-1294.128784,294.500488,0.000000
46.900002,66.012703,-1294.173218,-0.001509,0.002093,0.053152,293.639160,14.958693,0.531520,-1294.173218,294.500488,0.000000
47.190002,65.521538,-1294.128784,-0.001509,0.002142,0.054401,291.454346,14.847392,0.544011,-1294.128784,294.500488,0.000000
47.480003,65.260506,-1294.173218,-0.001518,0.002266,0.057567,290.293213,14.788242,0.575667,-1294.173218,294.500488,0.000000
47.770000,65.245979,-1294.173218,-0.001509,0.002276,0.057809,290.228607,14.784950,0.578090,-1294.173218,294.500488,0.000000
48.060001,65.152153,-1294.128784,-0.001513,0.002279,0.057888,289.811249,14.763689,0.578877,-1294.128784,294.500488,0.000000
48.350002,65.025169,-1294.173218,-0.001496,0.002281,0.057948,289.246399,14.734915,0.579483,-1294.173218,294.500488,0.000000
48.640003,64.886650,-1294.084351,-0.001492,0.002284,0.058025,288.630249,14.703525,0.580255,-1294.084351,294.500488,0.000000
48.930004,65.097786,-1294.262207,-0.001483,0.002291,0.058181,289.569427,14.751369,0.581814,-1294.262207,294.500488,0.000000
49.220001,65.456383,-1294.173218,-0.001479,0.002298,0.058365,291.164520,14.832628,0.583646,-1294.173218,294.500488,0.000000
49.510002,65.179329,-1294.128784,-0.001487,0.002298,0.058372,289.932129,14.769847,0.583722,-1294.128784,294.500488,0.000000
49.800003,65.345039,-1294.217773,-0.001483,0.002304,0.058521,290.669250,14.807397,0.585205,-1294.217773,294.500488,0.000000
50.090004,65.591545,-1294.128784,-0.001492,0.002311,0.058702,291.765778,14.863256,0.587022,-1294.128784,294.500488,0.000000
50.380001,65.373711,-1294.217773,-0.001479,0.002311,0.058693,290.796783,14.813894,0.586931,-1294.217773,294.500488,0.000000
50.670002,65.341682,-1294.128784,-0.001475,0.002316,0.058816,290.654327,14.806637,0.588158,-1294.128784,294.500488,0.000000
50.960003,65.194221,-1294.217773,-0.001492,0.002318,0.058876,289.998383,14.773222,0.588763,-1294.217773,294.500488,0.000000
51.250004,65.167793,-1294.262207,-0.001470,0.002319,0.058902,289.880829,14.767234,0.589020,-1294.262207,294.500488,0.000000
51.540001,65.563622,-1294.128784,-0.001483,0.002326,0.059093,291.641541,14.856929,0.590928,-1294.128784,294.500488,0.000000
51.830002,65.345787,-1294.217773,-0.001479,0.002326,0.059093,290.672577,14.807567,0.590928,-1294.217773,294.500488,0.000000
52.120003,65.183434,-1294.128784,-0.001457,0.002330,0.059179,289.950378,14.770777,0.591791,-1294.128784,294.500488,0.000000
52.410004,65.075066,-1294.217773,-0.001466,0.002331,0.059205,289.468353,14.746221,0.592048,-1294.217773,294.500488,0.000000
52.700001,65.291039,-1294.217773,-0.001457,0.002335,0.059318,290.429047,14.795160,0.593184,-1294.217773,294.500488,0.000000
52.990002,65.241142,-1294.128784,-0.001457,0.002338,0.059379,290.207092,14.783854,0.593789,-1294.128784,294.500488,0.000000
53.280003,65.081398,-1294.262207,-0.001457,0.002339,0.059414,289.496521,14.747656,0.594138,-1294.262207,294.500488,0.000000
53.570004,65.373344,-1294.128784,-0.001449,0.002345,0.059561,290.795166,14.813812,0.595606,-1294.128784,294.500488,0.000000
53.860004,65.231468,-1294.217773,-0.001453,0.002347,0.059605,290.164062,14.781662,0.596045,-1294.217773,294.500488,0.000000
54.150002,65.231834,-1294.217773,-0.001449,0.002348,0.059647,290.165680,14.781745,0.596469,-1294.217773,294.500488,0.000000
54.440002,65.171883,-1294.217773,-0.001440,0.002350,0.059700,289.899017,14.768160,0.596999,-1294.217773,294.500488,0.000000
54.730003,65.155495,-1294.217773,-0.001431,0.002353,0.059770,289.826111,14.764446,0.597695,-1294.217773,294.500488,0.000000
55.020004,65.109703,-1294.128784,-0.001440,0.002355,0.059812,289.622437,14.754069,0.598119,-1294.128784,294.500488,0.000000
55.310001,65.052345,-1294.173218,-0.001444,0.002358,0.059891,289.367279,14.741073,0.598907,-1294.173218,294.500488,0.000000
55.600002,65.038200,-1294.262207,-0.001436,0.002359,0.059925,289.304352,14.737866,0.599255,-1294.262207,294.500488,0.000000
55.890003,65.094429,-1294.128784,-0.001444,0.002362,0.059995,289.554474,14.750608,0.599951,-1294.128784,294.500488,0.000000
56.180004,65.000969,-1294.217773,-0.001444,0.002363,0.060021,289.138763,14.729430,0.600209,-1294.217773,294.500488,0.000000
56.470001,65.221413,-1294.173218,-0.001418,0.002368,0.060142,290.119324,14.779383,0.601420,-1294.173218,294.500488,0.000000
56.760002,65.065392,-1294.173218,-0.001436,0.002368,0.060142,289.425323,14.744028,0.601420,-1294.173218,294.500488,0.000000
57.050003,65.138374,-1294.217773,-0.001431,0.002371,0.060212,289.749969,14.760567,0.602116,-1294.217773,294.500488,0.000000
57.340004,65.246361,-1294.128784,-0.001414,0.002375,0.060315,290.230316,14.785036,0.603146,-1294.128784,294.500488,0.000000
57.630001,65.122734,-1294.217773,-0.001431,0.002375,0.060315,289.680389,14.757022,0.603146,-1294.217773,294.500488,0.000000
57.920002,65.405739,-1294.173218,-0.001431,0.002381,0.060472,290.939270,14.821152,0.604720,-1294.173218,294.500488,0.000000
58.210003,65.331627,-1294.173218,-0.001423,0.002381,0.060472,290.609589,14.804358,0.604720,-1294.173218,294.500488,0.000000
58.500004,65.251198,-1294.217773,-0.001418,0.002382,0.060498,290.251831,14.786133,0.604978,-1294.217773,294.500488,0.000000
58.790001,65.170387,-1294.173218,-0.001414,0.002386,0.060602,289.892365,14.767821,0.606022,-1294.173218,294.500488,0.000000
59.080002,65.382652,-1294.217773,-0.001418,0.002387,0.060628,290.836548,14.815921,0.606280,-1294.217773,294.500488,0.000000
59.370003,65.244865,-1294.217773,-0.001410,0.002387,0.060628,290.223663,14.784698,0.606280,-1294.217773,294.500488,0.000000
59.660004,65.399025,-1294.173218,-0.001418,0.002391,0.060740,290.909393,14.819631,0.607400,-1294.173218,294.500488,0.000000
59.950005,65.274666,-1294.217773,-0.001418,0.002392,0.060749,290.356201,14.791451,0.607491,-1294.217773,294.500488,0.000000
60.240002,65.209862,-1294.217773,-0.001406,0.002393,0.060784,290.067963,14.776766,0.607839,-1294.217773,294.500488,0.000000
60.530003,65.229225,-1294.217773,-0.001414,0.002395,0.060835,290.154083,14.781154,0.608354,-1294.217773,294.500488,0.000000
60.820004,65.561760,-1294.262207,-0.001410,0.002401,0.060991,291.633270,14.856507,0.609913,-1294.262207,294.500488,0.000000
61.110004,65.405739,-1294.173218,-0.001393,0.002400,0.060949,290.939270,14.821152,0.609489,-1294.173218,294.500488,0.000000
61.400002,65.256416,-1294.262207,-0.001410,0.002400,0.060949,290.275024,14.787314,0.609489,-1294.262207,294.500488,0.000000
61.690002,65.080284,-1294.173218,-0.001397,0.002400,0.060949,289.491577,14.747403,0.609489,-1294.173218,294.500488,0.000000
61.980003,64.930580,-1294.173218,-0.001393,0.002400,0.060949,288.825653,14.713479,0.609489,-1294.173218,294.500488,0.000000
62.270004,64.767860,-1294.217773,-0.001384,0.002400,0.060949,288.101837,14.676607,0.609489,-1294.217773,294.500488,0.000000
62.560001,66.175423,-1294.217773,-0.001393,0.002407,0.061131,294.362976,14.995564,0.611306,-1294.217773,294.500488,0.000000
62.850002,65.932274,-1294.262207,-0.001393,0.002406,0.061105,293.281403,14.940467,0.611049,-1294.262207,294.500488,0.000000
63.140003,65.779961,-1294.262207,-0.001401,0.002406,0.061105,292.603882,14.905951,0.611049,-1294.262207,294.500488,0.000000
63.430004,65.569954,-1294.262207,-0.001375,0.002406,0.061105,291.669708,14.858364,0.611049,-1294.262207,294.500488,0.000000
63.720001,65.385246,-1294.217773,-0.001393,0.002406,0.061105,290.848114,14.816508,0.611049,-1294.217773,294.500488,0.000000
64.010002,65.228111,-1294.128784,-0.001393,0.002406,0.061105,290.149139,14.780901,0.611049,-1294.128784,294.500488,0.000000
64.300003,65.072838,-1294.262207,-0.001393,0.002411,0.061235,289.458435,14.745716,0.612351,-1294.262207,294.500488,0.000000
64.590004,64.938408,-1294.173218,-0.001388,0.002411,0.061235,288.860474,14.715253,0.612351,-1294.173218,294.500488,0.000000
64.880005,65.536064,-1294.217773,-0.001384,0.002422,0.061512,291.518982,14.850684,0.615121,-1294.217773,294.500488,0.000000
65.170006,65.471642,-1294.217773,-0.001388,0.002422,0.061512,291.232422,14.836086,0.615121,-1294.217773,294.500488,0.000000
65.460007,65.348381,-1294.173218,-0.001388,0.002422,0.061512,290.684113,14.808154,0.615121,-1294.173218,294.500488,0.000000
65.750000,65.214714,-1294.217773,-0.001388,0.002422,0.061512,290.089539,14.777865,0.615121,-1294.217773,294.500488,0.000000
66.040001,65.101875,-1294.217773,-0.001380,0.002422,0.061521,289.587616,14.752295,0.615212,-1294.217773,294.500488,0.000000
66.330002,65.142845,-1294.173218,-0.001380,0.002425,0.061598,289.769836,14.761580,0.615984,-1294.173218,294.500488,0.000000
66.620003,65.059425,-1294.217773,-0.001384,0.002425,0.061598,289.398773,14.742677,0.615984,-1294.217773,294.500488,0.000000
66.910004,65.489891,-1294.128784,-0.001384,0.002431,0.061754,291.313599,14.840221,0.617543,-1294.128784,294.500488,0.000000
67.200005,65.387856,-1294.173218,-0.001384,0.002431,0.061754,290.859711,14.817100,0.617543,-1294.173218,294.500488,0.000000
67.490005,65.298119,-1294.262207,-0.001375,0.002431,0.061754,290.460541,14.796765,0.617543,-1294.262207,294.500488,0.000000
67.780006,65.200554,-1294.173218,-0.001371,0.002432,0.061763,290.026550,14.774657,0.617634,-1294.173218,294.500488,0.000000
68.070000,65.673103,-1294.217773,-0.001362,0.002439,0.061945,292.128540,14.881738,0.619451,-1294.217773,294.500488,0.000000
68.360001,65.611290,-1294.128784,-0.001367,0.002439,0.061945,291.853607,14.867730,0.619451,-1294.128784,294.500488,0.000000
68.650002,65.545372,-1294.217773,-0.001375,0.002439,0.061945,291.560364,14.852794,0.619451,-1294.217773,294.500488,0.000000
68.940002,65.437019,-1294.217773,-0.001358,0.002439,0.061945,291.078400,14.828240,0.619451,-1294.217773,294.500488,0.000000
69.230003,65.308922,-1294.128784,-0.001362,0.002439,0.061954,290.508606,14.799213,0.619542,-1294.128784,294.500488,0.000000
69.520004,65.384132,-1294.262207,-0.001380,0.002443,0.062040,290.843140,14.816257,0.620405,-1294.262207,294.500488,0.000000
69.810005,65.358818,-1294.217773,-0.001367,0.002443,0.062050,290.730530,14.810520,0.620496,-1294.217773,294.500488,0.000000
70.100006,65.324562,-1294.173218,-0.001380,0.002444,0.062084,290.578156,14.802757,0.620844,-1294.173218,294.500488,0.000000
70.390007,65.282478,-1294.262207,-0.001367,0.002445,0.062101,290.390961,14.793221,0.621010,-1294.262207,294.500488,0.000000
70.680000,65.254555,-1294.217773,-0.001371,0.002446,0.062128,290.266754,14.786894,0.621283,-1294.217773,294.500488,0.000000
70.970001,65.294762,-1294.217773,-0.001358,0.002448,0.062171,290.445618,14.796005,0.621707,-1294.217773,294.500488,0.000000
71.260002,65.260139,-1294.173218,-0.001362,0.002448,0.062180,290.291595,14.788159,0.621798,-1294.173218,294.500488,0.000000
71.550003,65.210243,-1294.262207,-0.001358,0.002448,0.062189,290.069641,14.776852,0.621889,-1294.262207,294.500488,0.000000
71.840004,65.330513,-1294.217773,-0.001354,0.002451,0.062266,290.604645,14.804106,0.622661,-1294.217773,294.500488,0.000000
72.130005,65.273918,-1294.173218,-0.001371,0.002451,0.062266,290.352875,14.791282,0.622661,-1294.173218,294.500488,0.000000
72.420006,65.204277,-1294.262207,-0.001350,0.002452,0.062275,290.043121,14.775500,0.622751,-1294.262207,294.500488,0.000000
72.710007,65.337212,-1294.173218,-0.001354,0.002455,0.062361,290.634430,14.805623,0.623614,-1294.173218,294.500488,0.000000
73.000000,65.320839,-1294.217773,-0.001350,0.002455,0.062361,290.561615,14.801914,0.623614,-1294.217773,294.500488,0.000000
73.290001,65.247475,-1294.262207,-0.001350,0.002455,0.062361,290.235260,14.785289,0.623614,-1294.262207,294.500488,0.000000
73.580002,65.165550,-1294.217773,-0.001350,0.002456,0.062389,289.870850,14.766726,0.623887,-1294.217773,294.500488,0.000000
73.870003,65.168907,-1294.217773,-0.001371,0.002457,0.062405,289.885773,14.767486,0.624053,-1294.217773,294.500488,0.000000
74.160004,65.095543,-1294.173218,-0.001358,0.002458,0.062431,289.559448,14.750860,0.624311,-1294.173218,294.500488,0.000000
74.450005,65.190498,-1294.217773,-0.001350,0.002461,0.062501,289.981812,14.772378,0.625007,-1294.217773,294.500488,0.000000
74.740005,65.193474,-1294.262207,-0.001341,0.002461,0.062501,289.995056,14.773052,0.625007,-1294.262207,294.500488,0.000000
75.030006,65.144707,-1294.128784,-0.001358,0.002461,0.062517,289.778137,14.762002,0.625174,-1294.128784,294.500488,0.000000
75.320007,65.281731,-1294.217773,-0.001345,0.002464,0.062587,290.387634,14.793052,0.625870,-1294.217773,294.500488,0.000000
75.610001,65.236305,-1294.173218,-0.001354,0.002464,0.062587,290.185577,14.782759,0.625870,-1294.173218,294.500488,0.000000
75.900002,65.174492,-1294.217773,-0.001345,0.002464,0.062587,289.910614,14.768751,0.625870,-1294.217773,294.500488,0.000000
76.190002,65.304070,-1294.262207,-0.001341,0.002468,0.062675,290.487000,14.798114,0.626748,-1294.262207,294.500488,0.000000
76.480003,65.282112,-1294.262207,-0.001345,0.002468,0.062675,290.389343,14.793138,0.626748,-1294.262207,294.500488,0.000000
76.770004,65.242256,-1294.217773,-0.001362,0.002468,0.062691,290.212036,14.784107,0.626915,-1294.217773,294.500488,0.000000
77.060005,65.211357,-1294.217773,-0.001350,0.002469,0.062717,290.074615,14.777104,0.627172,-1294.217773,294.500488,0.000000
77.350006,65.163322,-1294.217773,-0.001341,0.002470,0.062735,289.860931,14.766220,0.627354,-1294.217773,294.500488,0.000000
77.640007,65.327904,-1294.262207,-0.001350,0.002472,0.062796,290.593018,14.803514,0.627959,-1294.262207,294.500488,0.000000
77.930000,65.282845,-1294.173218,-0.001350,0.002472,0.062796,290.392609,14.793304,0.627959,-1294.173218,294.500488,0.000000
78.220001,65.269447,-1294.306763,-0.001345,0.002473,0.062822,290.333008,14.790268,0.628217,-1294.306763,294.500488,0.000000
78.510002,65.231087,-1294.217773,-0.001345,0.002474,0.062831,290.162354,14.781575,0.628308,-1294.217773,294.500488,0.000000
78.800003,65.243004,-1294.262207,-0.001337,0.002475,0.062873,290.215363,14.784276,0.628732,-1294.262207,294.500488,0.000000
79.090004,65.230339,-1294.306763,-0.001337,0.002475,0.062873,290.159027,14.781406,0.628732,-1294.306763,294.500488,0.000000
79.380005,65.280983,-1294.217773,-0.001341,0.002477,0.062926,290.384308,14.792882,0.629261,-1294.217773,294.500488,0.000000
79.670006,65.270195,-1294.262207,-0.001341,0.002478,0.062943,290.336334,14.790438,0.629428,-1294.262207,294.500488,0.000000
79.960007,65.298485,-1294.262207,-0.001341,0.002479,0.062978,290.462158,14.796848,0.629776,-1294.262207,294.500488,0.000000
80.250000,65.306313,-1294.262207,-0.001341,0.002480,0.062994,290.496979,14.798622,0.629943,-1294.262207,294.500488,0.000000
80.540001,65.274666,-1294.262207,-0.001332,0.002480,0.062994,290.356201,14.791451,0.629943,-1294.262207,294.500488,0.000000
80.830002,65.240028,-1294.262207,-0.001332,0.002481,0.063012,290.202148,14.783602,0.630124,-1294.262207,294.500488,0.000000
81.120003,65.232948,-1294.217773,-0.001332,0.002481,0.063029,290.170654,14.781998,0.630291,-1294.217773,294.500488,0.000000
81.410004,65.165550,-1294.262207,-0.001332,0.002482,0.063038,289.870850,14.766726,0.630382,-1294.262207,294.500488,0.000000
81.700005,65.164436,-1294.173218,-0.001328,0.002483,0.063064,289.865875,14.766473,0.630639,-1294.173218,294.500488,0.000000
81.990005,65.182686,-1294.306763,-0.001319,0.002484,0.063082,289.947083,14.770608,0.630821,-1294.306763,294.500488,0.000000
82.280006,65.153267,-1294.217773,-0.001324,0.002484,0.063091,289.816193,14.763942,0.630912,-1294.217773,294.500488,0.000000
82.570007,65.110069,-1294.217773,-0.001332,0.002485,0.063117,289.624054,14.754152,0.631169,-1294.217773,294.500488,0.000000
82.860001,65.100014,-1294.262207,-0.001319,0.002485,0.063124,289.579315,14.751874,0.631245,-1294.262207,294.500488,0.000000
83.150002,65.289925,-1294.262207,-0.001319,0.002489,0.063212,290.424103,14.794909,0.632123,-1294.262207,294.500488,0.000000
83.440002,65.288063,-1294.306763,-0.001337,0.002489,0.063212,290.415802,14.794487,0.632123,-1294.306763,294.500488,0.000000
83.730003,65.235558,-1294.217773,-0.001324,0.002489,0.063212,290.182251,14.782589,0.632123,-1294.217773,294.500488,0.000000
84.020004,65.170021,-1294.217773,-0.001332,0.002489,0.063212,289.890747,14.767738,0.632123,-1294.217773,294.500488,0.000000
84.310005,65.124962,-1294.306763,-0.001315,0.002490,0.063247,289.690308,14.757527,0.632471,-1294.306763,294.500488,0.000000
84.600006,65.165932,-1294.217773,-0.001319,0.002490,0.063255,289.872528,14.766811,0.632547,-1294.217773,294.500488,0.000000
84.890007,65.113792,-1294.306763,-0.001337,0.002490,0.063255,289.640625,14.754995,0.632547,-1294.306763,294.500488,0.000000
85.180000,65.100014,-1294.306763,-0.001319,0.002492,0.063308,289.579315,14.751874,0.633077,-1294.306763,294.500488,0.000000
85.470001,65.118629,-1294.262207,-0.001328,0.002492,0.063308,289.662140,14.756093,0.633077,-1294.262207,294.500488,0.000000
85.760002,65.081032,-1294.351196,-0.001324,0.002493,0.063315,289.494873,14.747572,0.633152,-1294.351196,294.500488,0.000000
86.050003,65.085121,-1294.217773,-0.001315,0.002494,0.063350,289.513092,14.748499,0.633501,-1294.217773,294.500488,0.000000
86.340004,65.213585,-1294.351196,-0.001319,0.002496,0.063403,290.084503,14.777609,0.634030,-1294.351196,294.500488,0.000000
86.630005,65.214714,-1294.262207,-0.001315,0.002496,0.063403,290.089539,14.777865,0.634030,-1294.262207,294.500488,0.000000
86.920006,65.156990,-1294.262207,-0.001311,0.002496,0.063403,289.832764,14.764785,0.634030,-1294.262207,294.500488,0.000000
87.210007,65.134651,-1294.306763,-0.001319,0.002497,0.063420,289.733398,14.759723,0.634197,-1294.306763,294.500488,0.000000
87.500008,65.123482,-1294.262207,-0.001324,0.002498,0.063438,289.683716,14.757192,0.634379,-1294.262207,294.500488,0.000000
87.790001,65.086235,-1294.262207,-0.001311,0.002498,0.063438,289.518036,14.748752,0.634379,-1294.262207,294.500488,0.000000
88.080002,65.255669,-1294.217773,-0.001319,0.002501,0.063533,290.271698,14.787147,0.635332,-1294.217773,294.500488,0.000000
88.370003,65.288429,-1294.262207,-0.001315,0.002501,0.063533,290.417450,14.794570,0.635332,-1294.262207,294.500488,0.000000
88.660004,65.250450,-1294.351196,-0.001332,0.002501,0.063533,290.248505,14.785963,0.635332,-1294.351196,294.500488,0.000000
88.950005,65.214333,-1294.217773,-0.001315,0.002502,0.063541,290.087830,14.777779,0.635408,-1294.217773,294.500488,0.000000
89.240005,65.183434,-1294.173218,-0.001311,0.002502,0.063550,289.950378,14.770777,0.635499,-1294.173218,294.500488,0.000000
89.530006,65.175987,-1294.306763,-0.001306,0.002502,0.063550,289.917267,14.769090,0.635499,-1294.306763,294.500488,0.000000
89.820007,65.098900,-1294.306763,-0.001319,0.002502,0.063559,289.574371,14.751621,0.635590,-1294.306763,294.500488,0.000000
90.110001,65.137627,-1294.306763,-0.001324,0.002505,0.063629,289.746643,14.760398,0.636286,-1294.306763,294.500488,0.000000
90.400002,65.223640,-1294.262207,-0.001302,0.002505,0.063629,290.129242,14.779888,0.636286,-1294.262207,294.500488,0.000000
90.690002,65.208382,-1294.262207,-0.001302,0.002505,0.063629,290.061371,14.776431,0.636286,-1294.262207,294.500488,0.000000
90.980003,65.159966,-1294.262207,-0.001315,0.002505,0.063629,289.846008,14.765460,0.636286,-1294.262207,294.500488,0.000000
91.270004,65.120872,-1294.217773,-0.001311,0.002505,0.063636,289.672119,14.756600,0.636362,-1294.217773,294.500488,0.000000
91.560005,65.100014,-1294.306763,-0.001328,0.002506,0.063654,289.579315,14.751874,0.636544,-1294.306763,294.500488,0.000000
91.850006,65.269814,-1294.306763,-0.001311,0.002509,0.063724,290.334625,14.790351,0.637240,-1294.306763,294.500488,0.000000
92.140007,65.260506,-1294.351196,-0.001302,0.002509,0.063724,290.293213,14.788242,0.637240,-1294.351196,294.500488,0.000000
92.430008,65.245247,-1294.306763,-0.001324,0.002509,0.063724,290.225342,14.784784,0.637240,-1294.306763,294.500488,0.000000
92.720001,65.198692,-1294.262207,-0.001306,0.002509,0.063724,290.018280,14.774235,0.637240,-1294.262207,294.500488,0.000000
93.010002,65.130928,-1294.351196,-0.001302,0.002509,0.063732,289.716827,14.758880,0.637316,-1294.351196,294.500488,0.000000
93.300003,65.074318,-1294.217773,-0.001302,0.002509,0.063732,289.465027,14.746051,0.637316,-1294.217773,294.500488,0.000000
93.590004,65.515587,-1294.262207,-0.001306,0.002516,0.063915,291.427887,14.846044,0.639148,-1294.262207,294.500488,0.000000
93.880005,65.552071,-1294.262207,-0.001315,0.002515,0.063880,291.590179,14.854312,0.638799,-1294.262207,294.500488,0.000000
94.170006,65.524513,-1294.217773,-0.001315,0.002515,0.063880,291.467590,14.848067,0.638799,-1294.217773,294.500488,0.000000
94.460007,65.477608,-1294.306763,-0.001311,0.002515,0.063880,291.258942,14.837438,0.638799,-1294.306763,294.500488,0.000000
94.750008,65.410942,-1294.306763,-0.001315,0.002515,0.063880,290.962402,14.822331,0.638799,-1294.306763,294.500488,0.000000
95.040001,65.360680,-1294.217773,-0.001306,0.002515,0.063880,290.738831,14.810942,0.638799,-1294.217773,294.500488,0.000000
95.330002,65.307060,-1294.306763,-0.001302,0.002515,0.063880,290.500305,14.798792,0.638799,-1294.306763,294.500488,0.000000
95.620003,65.279121,-1294.262207,-0.001306,0.002515,0.063880,290.376038,14.792460,0.638799,-1294.262207,294.500488,0.000000
95.910004,65.230721,-1294.262207,-0.001324,0.002515,0.063880,290.160736,14.781493,0.638799,-1294.262207,294.500488,0.000000
96.200005,65.185295,-1294.262207,-0.001293,0.002515,0.063880,289.958679,14.771199,0.638799,-1294.262207,294.500488,0.000000
96.490005,65.119377,-1294.217773,-0.001298,0.002515,0.063880,289.665466,14.756262,0.638799,-1294.217773,294.500488,0.000000
96.780006,65.072456,-1294.351196,-0.001298,0.002515,0.063880,289.456757,14.745629,0.638799,-1294.351196,294.500488,0.000000
97.070007,65.015862,-1294.306763,-0.001302,0.002515,0.063880,289.204987,14.732804,0.638799,-1294.306763,294.500488,0.000000
97.360008,64.986809,-1294.262207,-0.001302,0.002515,0.063880,289.075775,14.726221,0.638799,-1294.262207,294.500488,0.000000
97.650002,64.924629,-1294.306763,-0.001302,0.002515,0.063880,288.799164,14.712132,0.638799,-1294.306763,294.500488,0.000000
97.940002,64.869896,-1294.262207,-0.001315,0.002515,0.063880,288.555695,14.699728,0.638799,-1294.262207,294.500488,0.000000
98.230003,64.811424,-1294.306763,-0.001302,0.002515,0.063880,288.295624,14.686479,0.638799,-1294.306763,294.500488,0.000000
98.520004,64.766365,-1294.306763,-0.001298,0.002515,0.063880,288.095184,14.676268,0.638799,-1294.306763,294.500488,0.000000
98.810005,64.710518,-1294.351196,-0.001276,0.002515,0.063880,287.846771,14.663613,0.638799,-1294.351196,294.500488,0.000000
99.100006,64.683327,-1294.351196,-0.001293,0.002515,0.063888,287.725800,14.657451,0.638875,-1294.351196,294.500488,0.000000
99.390007,64.624870,-1294.262207,-0.001289,0.002515,0.063888,287.465790,14.644205,0.638875,-1294.262207,294.500488,0.000000
99.680008,66.247673,-1294.306763,-0.001306,0.002540,0.064522,294.684357,15.011937,0.645219,-1294.306763,294.500488,0.000000
99.970001,66.341499,-1294.306763,-0.001289,0.002504,0.063594,295.101715,15.033198,0.635938,-1294.306763,294.500488,0.000000
100.260002,66.254738,-1294.306763,-0.001285,0.002504,0.063594,294.715790,15.013538,0.635938,-1294.306763,0.063524,0.000000
100.550003,66.170219,-1294.306763,-0.001281,0.002497,0.063420,294.339844,14.994387,0.634197,-1294.306763,0.063047,0.000000
100.840004,66.049568,-1294.217773,-0.001281,0.002479,0.062961,293.803162,14.967046,0.629610,-1294.217773,0.062561,0.000000
101.130005,65.931145,-1294.262207,-0.001285,0.002463,0.062561,293.276367,14.940211,0.625613,-1294.262207,0.062075,0.000000
101.420006,65.855186,-1294.306763,-0.001285,0.002444,0.062068,292.938507,14.922998,0.620677,-1294.306763,0.061591,0.000000
101.710007,65.797096,-1294.262207,-0.001293,0.002426,0.061617,292.680115,14.909836,0.616166,-1294.262207,0.061112,0.000000
102.000008,65.697304,-1294.306763,-0.001285,0.002406,0.061122,292.236206,14.887222,0.611215,-1294.306763,0.060628,0.000000
102.290009,65.615746,-1294.306763,-0.001285,0.002390,0.060714,291.873413,14.868740,0.607143,-1294.306763,0.060142,0.000000
102.580002,65.562126,-1294.262207,-0.001289,0.002373,0.060263,291.634888,14.856590,0.602631,-1294.262207,0.059656,0.000000
102.870003,65.477608,-1294.262207,-0.001276,0.002355,0.059821,291.258942,14.837438,0.598210,-1294.262207,0.059179,0.000000
103.160004,65.332375,-1294.306763,-0.001285,0.002339,0.059405,290.612915,14.804527,0.594047,-1294.306763,0.058693,0.000000
103.450005,65.210609,-1294.306763,-0.001281,0.002320,0.058937,290.071289,14.776936,0.589369,-1294.306763,0.058209,0.000000
103.740005,64.754082,-1294.262207,-0.001268,0.002299,0.058390,288.040527,14.673485,0.583903,-1294.262207,0.057730,0.000000
104.030006,63.823143,-1294.262207,-0.001272,0.002274,0.057748,283.899506,14.462531,0.577484,-1294.262207,0.057246,0.000000
104.320007,63.407951,-1294.306763,-0.001272,0.002264,0.057506,282.052643,14.368447,0.575062,-1294.306763,0.056760,0.000000
104.610008,62.756302,-1294.262207,-0.001263,0.002249,0.057132,279.153961,14.220781,0.571322,-1294.262207,0.056274,0.000000
104.900002,61.718872,-1294.306763,-0.001263,0.002229,0.056613,274.539246,13.985697,0.566129,-1294.306763,0.055797,0.000000
105.190002,60.981575,-1294.262207,-0.001263,0.002216,0.056292,271.259583,13.818622,0.562920,-1294.262207,0.055311,0.000000
105.480003,59.684601,-1294.306763,-0.001263,0.002196,0.055780,265.490356,13.524724,0.557803,-1294.306763,0.054826,0.000000
105.770004,58.482216,-1294.306763,-0.001276,0.002178,0.055329,260.141876,13.252260,0.553291,-1294.306763,0.054340,0.000000
106.060005,57.168480,-1294.217773,-0.001276,0.002161,0.054895,254.298096,12.954562,0.548946,-1294.217773,0.053864,0.000000
106.350006,55.705803,-1294.217773,-0.001259,0.002143,0.054436,247.791794,12.623115,0.544359,-1294.217773,0.053378,0.000000
106.640007,53.903519,-1294.262207,-0.001263,0.002122,0.053889,239.774826,12.214712,0.538893,-1294.262207,0.052892,0.000000
106.930008,52.449409,-1294.217773,-0.001268,0.002104,0.053429,233.306625,11.885206,0.534291,-1294.217773,0.052406,0.000000
107.220009,50.322784,-1294.351196,-0.001263,0.002084,0.052945,223.846924,11.403306,0.529446,-1294.351196,0.051929,0.000000
107.510002,48.281067,-1294.306763,-0.001250,0.002063,0.052398,214.764908,10.940646,0.523981,-1294.306763,0.051444,0.000000
107.800003,46.494423,-1294.306763,-0.001285,0.002047,0.051989,206.817520,10.535787,0.519893,-1294.306763,0.050958,0.000000
108.090004,44.960625,-1294.351196,-0.001272,0.002032,0.051600,199.994843,10.188223,0.516002,-1294.351196,0.050472,0.000000
108.380005,42.099312,-1294.262207,-0.001285,0.002003,0.050871,187.267090,9.539840,0.508705,-1294.262207,0.049995,0.000000
108.670006,41.011238,-1294.306763,-0.001272,0.001992,0.050593,182.427094,9.293280,0.505934,-1294.306763,0.049509,0.000000
108.960007,38.795250,-1294.306763,-0.001276,0.001971,0.050073,172.569885,8.791129,0.500726,-1294.306763,0.049023,0.000000
109.250008,36.925201,-1294.351196,-0.001302,0.001953,0.049614,164.251495,8.367371,0.496139,-1294.351196,0.048547,0.000000
109.540009,34.774002,-1294.351196,-0.001293,0.001930,0.049016,154.682480,7.879901,0.490159,-1294.351196,0.048062,0.000000
109.830002,33.179131,-1294.306763,-0.001298,0.001915,0.048642,147.588150,7.518498,0.486420,-1294.306763,0.047576,0.000000
110.120003,31.198853,-1294.262207,-0.001306,0.001894,0.048104,138.779434,7.069761,0.481045,-1294.262207,0.047090,0.000000
110.410004,29.331032,-1294.351196,-0.001289,0.001878,0.047714,130.470947,6.646507,0.477139,-1294.351196,0.046613,0.000000
110.700005,27.953255,-1294.306763,-0.001324,0.001863,0.047332,124.342285,6.334298,0.473324,-1294.306763,0.046127,0.000000
110.990005,25.806900,-1294.306763,-0.001315,0.001843,0.046813,114.794823,5.847927,0.468131,-1294.306763,0.045641,0.000000
111.280006,23.148903,-1294.217773,-0.001298,0.001819,0.046206,102.971466,5.245616,0.462060,-1294.217773,0.045157,0.000000
111.570007,20.877060,-1294.306763,-0.001328,0.001797,0.045634,92.865799,4.730809,0.456337,-1294.306763,0.044680,0.000000
111.860008,19.311981,-1294.262207,-0.001315,0.001781,0.045243,85.903984,4.376157,0.452431,-1294.262207,0.044194,0.000000
112.150002,16.908691,-1294.306763,-0.001315,0.001757,0.044636,75.213615,3.831564,0.446360,-1294.306763,0.043708,0.000000
112.440002,15.752846,-1294.306763,-0.001319,0.001745,0.044332,70.072159,3.569646,0.443317,-1294.306763,0.043222,0.000000
112.730003,13.795280,-1294.262207,-0.001332,0.001724,0.043787,61.364471,3.126055,0.437867,-1294.262207,0.042745,0.000000
113.020004,11.889107,-1294.351196,-0.001345,0.001705,0.043301,52.885387,2.694110,0.433007,-1294.351196,0.042259,0.000000
113.310005,9.878670,-1294.306763,-0.001345,0.001684,0.042780,43.942516,2.238539,0.427799,-1294.306763,0.041775,0.000000
113.600006,8.019417,-1294.262207,-0.001350,0.001665,0.042294,35.672146,1.817226,0.422939,-1294.262207,0.041289,0.000000
113.890007,6.326233,-1294.351196,-0.001337,0.001644,0.041766,28.140490,1.433545,0.417656,-1294.351196,0.040812,0.000000
114.180008,4.620399,-1294.306763,-0.001345,0.001628,0.041358,20.552563,1.046998,0.413583,-1294.306763,0.040326,0.000000
114.470009,3.480194,-1294.306763,-0.001354,0.001613,0.040968,15.480677,0.788623,0.409677,-1294.306763,0.039840,0.000000
114.760002,1.793716,-1294.351196,-0.001362,0.001595,0.040526,7.978849,0.406462,0.405256,-1294.351196,0.039363,0.000000
115.050003,0.030533,-1294.306763,-0.001371,0.001574,0.039979,0.135817,0.006919,0.399791,-1294.306763,0.038877,0.000000
115.340004,-2.003735,-1294.306763,-0.001388,0.001548,0.039321,-8.913056,-0.454053,0.393205,-1294.306763,0.038392,0.000000
115.630005,-2.946583,-1294.351196,-0.001384,0.001532,0.038904,-13.107055,-0.667705,0.389042,-1294.351196,0.037906,0.000000
115.920006,-0.261406,-1294.262207,-0.001431,0.001517,0.038523,-1.162792,-0.059235,0.385227,-1294.262207,0.037430,0.000000
116.210007,-0.060699,-1294.306763,-0.001436,0.001495,0.037984,-0.270005,-0.013755,0.379837,-1294.306763,0.036944,0.000000
116.500008,-0.055481,-1294.306763,-0.001453,0.001478,0.037533,-0.246792,-0.012572,0.375325,-1294.306763,0.036458,0.000000
116.790009,-0.066284,-1294.306763,-0.001453,0.001459,0.037056,-0.294847,-0.015020,0.370556,-1294.306763,0.035972,0.000000
117.080002,-0.055855,-1294.262207,-0.001475,0.001439,0.036544,-0.248455,-0.012657,0.365439,-1294.262207,0.035495,0.000000
117.370003,-0.030533,-1294.306763,-0.001496,0.001417,0.035999,-0.135817,-0.006919,0.359989,-1294.306763,0.035010,0.000000
117.660004,-0.037979,-1294.395630,-0.001500,0.001403,0.035643,-0.168940,-0.008606,0.356431,-1294.395630,0.034524,0.000000
117.950005,0.003723,-1294.306763,-0.001522,0.001378,0.035010,0.016561,0.000844,0.350103,-1294.306763,0.034038,0.000000
118.240005,0.013405,-1294.306763,-0.001552,0.001370,0.034801,0.059628,0.003038,0.348014,-1294.306763,0.034689,0.000000
118.300003,0.002235,-1294.262207,-0.001548,0.001370,0.034810,0.009944,0.000507,0.348104,-1294.262207,0.034689,0.000000