File: Data/Sima compression/P2-21-3_10302024_180237.csv
Time (sec),S:Load (lbs),S:HL1 (DIM),S:LVDT (in),S:Position (in),Ch:Position (mm),Ch:Load (N),Ch:Stress (MPa),Ch:Strain (mm/mm),Ch:HL1 (DIM),Set Point (),Cycles ()
0.210000,-0.008194,-1293.417114,-0.008351,-0.004102,-0.104178,-0.036449,-0.001857,-1.041785,-1293.417114,-0.103980,0.000000
0.490000,-0.015640,-1293.417114,-0.008360,-0.004050,-0.102878,-0.069571,-0.003544,-1.028780,-1293.417114,-0.102315,0.000000
0.770000,0.026070,-1293.461548,-0.008313,-0.003890,-0.098802,0.115964,0.005907,-0.988024,-1293.461548,-0.097649,0.000000
1.050000,-0.024200,-1293.461548,-0.008140,-0.003709,-0.094215,-0.107649,-0.005484,-0.942151,-1293.461548,-0.092983,0.000000
1.330000,-0.022713,-1293.461548,-0.007950,-0.003530,-0.089670,-0.101031,-0.005147,-0.896702,-1293.461548,-0.088318,0.000000
1.610000,-0.076340,-1293.506104,-0.007743,-0.003337,-0.084771,-0.339576,-0.017299,-0.847710,-1293.506104,-0.083652,0.000000
1.890000,0.010796,-1293.417114,-0.007562,-0.003159,-0.080244,0.048021,0.002446,-0.802443,-1293.417114,-0.078986,0.000000
2.170000,-0.011917,-1293.372559,-0.007368,-0.002973,-0.075525,-0.053010,-0.002700,-0.755253,-1293.372559,-0.074320,0.000000
2.450000,0.002975,-1293.506104,-0.007170,-0.002788,-0.070826,0.013236,0.000674,-0.708260,-1293.506104,-0.069672,0.000000
2.730000,0.053619,-1293.461548,-0.006989,-0.002603,-0.066116,0.238511,0.012150,-0.661161,-1293.461548,-0.065006,0.000000
3.010000,0.007072,-1293.417114,-0.006821,-0.002422,-0.061512,0.031460,0.001603,-0.615121,-1293.417114,-0.060340,0.000000
3.290000,-0.013031,-1293.461548,-0.006635,-0.002243,-0.056967,-0.057965,-0.002953,-0.569672,-1293.461548,-0.055676,0.000000
3.570000,-0.041702,-1293.372559,-0.006428,-0.002057,-0.052259,-0.185501,-0.009450,-0.522588,-1293.372559,-0.051010,0.000000
3.850000,-0.019363,-1293.461548,-0.006230,-0.001874,-0.047593,-0.086133,-0.004388,-0.475928,-1293.461548,-0.046344,0.000000
4.130000,-0.052505,-1293.550537,-0.006049,-0.001688,-0.042866,-0.233556,-0.011898,-0.428662,-1293.550537,-0.041678,0.000000
4.410000,0.033142,-1293.417114,-0.005877,-0.001506,-0.038253,0.147423,0.007510,-0.382532,-1293.417114,-0.037013,0.000000
4.690000,-0.018990,-1293.417114,-0.005652,-0.001316,-0.033439,-0.084470,-0.004303,-0.334388,-1293.417114,-0.032347,0.000000
4.970000,0.021973,-1293.417114,-0.005476,-0.001136,-0.028861,0.097739,0.004979,-0.288606,-1293.417114,-0.027681,0.000000
5.250000,0.008194,-1293.417114,-0.005290,-0.000952,-0.024169,0.036449,0.001857,-0.241688,-1293.417114,-0.023015,0.000000
5.530000,-0.008194,-1293.417114,-0.005122,-0.000773,-0.019633,-0.036449,-0.001857,-0.196330,-1293.417114,-0.018349,0.000000
5.810000,-0.029793,-1293.506104,-0.004928,-0.000589,-0.014950,-0.132525,-0.006751,-0.149503,-1293.506104,-0.013685,0.000000
6.090000,-0.061440,-1293.461548,-0.004725,-0.000403,-0.010224,-0.273297,-0.013922,-0.102238,-1293.461548,-0.009019,0.000000
6.370000,0.019363,-1293.417114,-0.004553,-0.000226,-0.005748,0.086133,0.004388,-0.057485,-1293.417114,-0.004353,0.000000
6.650000,0.000374,-1293.506104,-0.004359,-0.000037,-0.000945,0.001663,0.000085,-0.009447,-1293.506104,0.000313,0.000000
6.930000,0.079689,-1293.417114,-0.004161,0.000149,0.003773,0.354474,0.018058,0.037728,-1293.417114,0.004978,0.000000
7.210001,0.064049,-1293.550537,-0.004126,-0.000003,-0.000088,0.284903,0.014514,-0.000878,-1293.550537,0.000051,0.000000
7.490000,0.065536,-1293.417114,-0.004122,-0.000003,-0.000088,0.291521,0.014851,-0.000878,-1293.417114,0.000051,0.000000
7.770000,0.073730,-1293.417114,-0.004113,-0.000003,-0.000088,0.327969,0.016708,-0.000878,-1293.417114,0.000494,0.000000
8.050000,0.083412,-1293.417114,-0.004122,-0.000003,-0.000088,0.371036,0.018901,-0.000878,-1293.417114,0.000961,0.000000
8.330000,0.086761,-1293.506104,-0.004096,0.000017,0.000442,0.385934,0.019660,0.004421,-1293.506104,0.001431,0.000000
8.610001,0.151558,-1293.461548,-0.004087,0.000034,0.000866,0.674163,0.034344,0.008660,-1293.461548,0.001889,0.000000
8.890000,0.336998,-1293.417114,-0.004074,0.000057,0.001447,1.499042,0.076365,0.014473,-1293.417114,0.002359,0.000000
9.170000,0.543663,-1293.417114,-0.004066,0.000075,0.001917,2.418334,0.123196,0.019167,-1293.417114,0.002827,0.000000
9.450001,0.765228,-1293.461548,-0.004036,0.000090,0.002289,3.403905,0.173403,0.022891,-1293.461548,0.003294,0.000000
9.730000,0.940987,-1293.506104,-0.004036,0.000099,0.002522,4.185718,0.213231,0.025223,-1293.506104,0.003764,0.000000
10.010000,1.519653,-1293.417114,-0.004010,0.000130,0.003303,6.759756,0.344358,0.033035,-1293.417114,0.004232,0.000000
10.290001,1.927399,-1293.417114,-0.003997,0.000147,0.003746,8.573498,0.436755,0.037455,-1293.417114,0.004692,0.000000
10.570001,2.309456,-1293.372559,-0.003992,0.000161,0.004085,10.272973,0.523330,0.040847,-1293.372559,0.005160,0.000000
10.850000,2.864662,-1293.328125,-0.003980,0.000182,0.004630,12.742654,0.649142,0.046297,-1293.328125,0.005627,0.000000
11.130000,3.695053,-1293.461548,-0.003962,0.000203,0.005169,16.436417,0.837311,0.051687,-1293.461548,0.006097,0.000000
11.410001,4.305374,-1293.461548,-0.003949,0.000219,0.005567,19.151260,0.975612,0.055668,-1293.461548,0.006565,0.000000
11.690001,4.939896,-1293.417114,-0.003945,0.000237,0.006027,21.973753,1.119396,0.060271,-1293.417114,0.007023,0.000000
11.970000,5.866356,-1293.372559,-0.003928,0.000257,0.006539,26.094854,1.329335,0.065388,-1293.372559,0.007493,0.000000
12.250001,6.487099,-1293.328125,-0.003919,0.000274,0.006963,28.856056,1.469998,0.069627,-1293.328125,0.007960,0.000000
12.530001,7.258659,-1293.461548,-0.003915,0.000289,0.007353,32.288128,1.644836,0.073533,-1293.461548,0.008428,0.000000
12.810000,8.217888,-1293.417114,-0.003906,0.000310,0.007883,36.554993,1.862200,0.078832,-1293.417114,0.008898,0.000000
13.090000,8.675163,-1293.506104,-0.003898,0.000326,0.008272,38.589054,1.965820,0.082723,-1293.506104,0.009365,0.000000
13.370001,10.140816,-1293.417114,-0.003867,0.000346,0.008784,45.108601,2.297942,0.087840,-1293.417114,0.009826,0.000000
13.650001,10.386955,-1293.417114,-0.003867,0.000356,0.009035,46.203484,2.353718,0.090353,-1293.417114,0.010293,0.000000
13.930000,11.943474,-1293.417114,-0.003850,0.000381,0.009677,53.127224,2.706430,0.096772,-1293.417114,0.010761,0.000000
14.210001,12.988724,-1293.461548,-0.003850,0.000403,0.010233,57.776730,2.943287,0.102328,-1293.461548,0.011231,0.000000
14.490001,14.059296,-1293.461548,-0.003824,0.000422,0.010710,62.538872,3.185882,0.107097,-1293.461548,0.011698,0.000000
14.770000,14.781700,-1293.417114,-0.003837,0.000434,0.011031,65.752289,3.349581,0.110307,-1293.417114,0.012159,0.000000
15.050001,16.049629,-1293.372559,-0.003807,0.000457,0.011620,71.392319,3.636898,0.116196,-1293.372559,0.012626,0.000000
15.330001,16.964172,-1293.461548,-0.003794,0.000474,0.012036,75.460411,3.844136,0.120360,-1293.461548,0.013094,0.000000
15.610001,17.242706,-1293.461548,-0.003798,0.000484,0.012296,76.699387,3.907253,0.122964,-1293.461548,0.013562,0.000000
15.890000,19.109039,-1293.417114,-0.003764,0.000512,0.013017,85.001251,4.330170,0.130170,-1293.417114,0.014031,0.000000
16.170000,19.907776,-1293.417114,-0.003768,0.000529,0.013441,88.554207,4.511167,0.134409,-1293.417114,0.014490,0.000000
16.450001,21.111656,-1293.417114,-0.003742,0.000550,0.013971,93.909340,4.783970,0.139708,-1293.417114,0.014959,0.000000
16.730001,21.685852,-1293.417114,-0.003742,0.000565,0.014360,96.463486,4.914084,0.143599,-1293.417114,0.015427,0.000000
17.010000,23.122841,-1293.417114,-0.003729,0.000585,0.014872,102.855530,5.239711,0.148716,-1293.417114,0.015895,0.000000
17.290001,23.763695,-1293.506104,-0.003721,0.000600,0.015236,105.706192,5.384930,0.152365,-1293.506104,0.016364,0.000000
17.570002,24.937042,-1293.328125,-0.003704,0.000622,0.015800,110.925507,5.650815,0.157997,-1293.328125,0.016832,0.000000
17.850000,26.131981,-1293.372559,-0.003699,0.000642,0.016311,116.240860,5.921592,0.163114,-1293.372559,0.017292,0.000000
18.130001,26.935562,-1293.372559,-0.003686,0.000661,0.016788,119.815361,6.103685,0.167883,-1293.372559,0.017760,0.000000
18.410002,28.058640,-1293.417114,-0.003669,0.000679,0.017258,124.811066,6.358179,0.172576,-1293.417114,0.018228,0.000000
18.690001,28.791840,-1293.461548,-0.003673,0.000693,0.017613,128.072495,6.524324,0.176134,-1293.461548,0.018697,0.000000
18.970001,29.935394,-1293.417114,-0.003648,0.000715,0.018167,133.159286,6.783457,0.181675,-1293.417114,0.019165,0.000000
19.250000,30.477943,-1293.328125,-0.003639,0.000728,0.018488,135.572662,6.906401,0.184885,-1293.328125,0.019625,0.000000
19.530001,31.477020,-1293.372559,-0.003630,0.000753,0.019114,140.016785,7.132795,0.191137,-1293.372559,0.020093,0.000000
19.810001,32.484657,-1293.372559,-0.003604,0.000766,0.019468,144.498978,7.361129,0.194680,-1293.372559,0.020561,0.000000
20.090000,33.558578,-1293.328125,-0.003609,0.000789,0.020033,149.276016,7.604483,0.200327,-1293.328125,0.021029,0.000000
20.370001,34.386360,-1293.372559,-0.003579,0.000806,0.020484,152.958176,7.792060,0.204839,-1293.372559,0.021498,0.000000
20.650002,35.138184,-1293.372559,-0.003587,0.000820,0.020838,156.302444,7.962426,0.208381,-1293.372559,0.021966,0.000000
20.930000,36.064644,-1293.328125,-0.003557,0.000839,0.021298,160.423553,8.172365,0.212984,-1293.328125,0.022426,0.000000
21.210001,36.741249,-1293.417114,-0.003557,0.000854,0.021680,163.433243,8.325686,0.216799,-1293.417114,0.022894,0.000000
21.490002,36.908813,-1293.417114,-0.003553,0.000867,0.022010,164.178604,8.363656,0.220099,-1293.417114,0.023362,0.000000
21.770000,39.044373,-1293.372559,-0.003540,0.000897,0.022782,173.678040,8.847581,0.227820,-1293.372559,0.023831,0.000000
22.050001,39.808105,-1293.283691,-0.003518,0.000916,0.023267,177.075302,9.020646,0.232665,-1293.283691,0.024299,0.000000
22.330002,40.456032,-1293.417114,-0.003514,0.000933,0.023692,179.957413,9.167468,0.236919,-1293.417114,0.024759,0.000000
22.610001,41.492348,-1293.417114,-0.003501,0.000954,0.024220,184.567184,9.402300,0.242203,-1293.417114,0.025227,0.000000
22.890001,42.184959,-1293.328125,-0.003475,0.000969,0.024611,187.648071,9.559249,0.246109,-1293.328125,0.025695,0.000000
23.170002,42.590843,-1293.417114,-0.003471,0.000983,0.024976,189.453537,9.651223,0.249758,-1293.417114,0.026164,0.000000
23.450001,44.150711,-1293.372559,-0.003466,0.001010,0.025643,196.392166,10.004694,0.256434,-1293.372559,0.026632,0.000000
23.730001,44.674271,-1293.417114,-0.003441,0.001024,0.026016,198.721085,10.123334,0.260159,-1293.417114,0.027091,0.000000
24.010000,45.421249,-1293.328125,-0.003423,0.001044,0.026518,202.043808,10.292602,0.265185,-1293.328125,0.027560,0.000000
24.290001,45.879265,-1293.328125,-0.003415,0.001059,0.026892,204.081161,10.396390,0.268924,-1293.328125,0.028028,0.000000
24.570002,47.066391,-1293.417114,-0.003397,0.001082,0.027490,209.361771,10.665397,0.274904,-1293.417114,0.028496,0.000000
24.850000,47.518822,-1293.283691,-0.003397,0.001095,0.027811,211.374283,10.767919,0.278114,-1293.283691,0.028965,0.000000
25.130001,47.781342,-1293.328125,-0.003380,0.001108,0.028141,212.542023,10.827407,0.281415,-1293.328125,0.029433,0.000000
25.410002,49.545647,-1293.328125,-0.003367,0.001138,0.028895,220.390045,11.227203,0.288954,-1293.328125,0.029893,0.000000
25.690001,50.093407,-1293.372559,-0.003346,0.001156,0.029356,222.826599,11.351328,0.293556,-1293.372559,0.030361,0.000000
25.970001,50.569298,-1293.372559,-0.003337,0.001172,0.029763,224.943466,11.459167,0.297629,-1293.372559,0.030829,0.000000
26.250002,51.290581,-1293.328125,-0.003337,0.001189,0.030205,228.151901,11.622611,0.302050,-1293.328125,0.031298,0.000000
26.530001,52.383499,-1293.372559,-0.003298,0.001212,0.030786,233.013443,11.870271,0.307863,-1293.372559,0.031766,0.000000
26.810001,52.354080,-1293.372559,-0.003281,0.001222,0.031029,232.882584,11.863604,0.310286,-1293.372559,0.032226,0.000000
27.090002,52.792732,-1293.328125,-0.003281,0.001239,0.031471,234.833801,11.963004,0.314706,-1293.328125,0.032694,0.000000
27.370001,54.519798,-1293.328125,-0.003260,0.001267,0.032182,242.516174,12.354363,0.321822,-1293.328125,0.033162,0.000000
27.650002,55.102562,-1293.283691,-0.003260,0.001284,0.032608,245.108444,12.486420,0.326076,-1293.283691,0.033631,0.000000
27.930002,55.707291,-1293.328125,-0.003247,0.001304,0.033119,247.798401,12.623453,0.331193,-1293.328125,0.034099,0.000000
28.210001,56.209999,-1293.283691,-0.003216,0.001320,0.033518,250.034561,12.737368,0.335175,-1293.283691,0.034567,0.000000
28.490002,57.190826,-1293.417114,-0.003203,0.001342,0.034090,254.397507,12.959626,0.340898,-1293.417114,0.035027,0.000000
28.770000,57.029961,-1293.417114,-0.003191,0.001352,0.034334,253.681931,12.923174,0.343335,-1293.417114,0.035495,0.000000
29.050001,57.558731,-1293.372559,-0.003195,0.001371,0.034818,256.034027,13.042995,0.348180,-1293.372559,0.035963,0.000000
29.330002,59.021408,-1293.283691,-0.003169,0.001395,0.035443,262.540344,13.374442,0.354433,-1293.283691,0.036432,0.000000
29.610001,59.372925,-1293.328125,-0.003160,0.001410,0.035825,264.103973,13.454098,0.358248,-1293.328125,0.036900,0.000000
29.890001,60.061073,-1293.372559,-0.003143,0.001430,0.036318,267.165009,13.610034,0.363183,-1293.372559,0.037360,0.000000
30.170002,60.723152,-1293.372559,-0.003139,0.001450,0.036822,270.110077,13.760062,0.368225,-1293.372559,0.037828,0.000000
30.450001,61.450394,-1293.372559,-0.003134,0.001468,0.037281,273.345001,13.924858,0.372812,-1293.372559,0.038296,0.000000
30.730001,61.360283,-1293.328125,-0.003117,0.001479,0.037576,272.944183,13.904439,0.375764,-1293.328125,0.038765,0.000000
31.010002,61.998901,-1293.328125,-0.003109,0.001496,0.038009,275.784882,14.049152,0.380094,-1293.328125,0.039233,0.000000
31.290001,63.676430,-1293.328125,-0.003078,0.001524,0.038704,283.246918,14.429285,0.387043,-1293.328125,0.039693,0.000000
31.570002,64.120308,-1293.417114,-0.003074,0.001539,0.039093,285.221375,14.529869,0.390934,-1293.417114,0.040161,0.000000
31.850002,64.673271,-1293.328125,-0.003070,0.001558,0.039579,287.681091,14.655172,0.395794,-1293.328125,0.040629,0.000000
32.130001,65.213219,-1293.283691,-0.003035,0.001574,0.039970,290.082886,14.777527,0.399700,-1293.283691,0.041098,0.000000
32.410000,66.087914,-1293.328125,-0.003027,0.001594,0.040498,293.973724,14.975735,0.404984,-1293.328125,0.041566,0.000000
32.690002,65.193108,-1293.372559,-0.003014,0.001590,0.040386,289.993439,14.772969,0.403863,-1293.372559,0.007109,0.000000
32.970001,67.475380,-1293.372559,-0.002997,0.001563,0.039701,300.145477,15.290140,0.397005,-1293.372559,294.500488,0.000000
33.250000,65.600105,-1293.417114,-0.002979,0.001463,0.037151,291.803833,14.865196,0.371510,-1293.417114,294.500488,0.000000
33.530003,65.116768,-1293.283691,-0.002984,0.001620,0.041158,289.653839,14.755671,0.411585,-1293.283691,294.500488,0.000000
33.810001,65.483559,-1293.283691,-0.002979,0.001635,0.041540,291.285431,14.838787,0.415400,-1293.283691,294.500488,0.000000
34.090000,65.958336,-1293.372559,-0.002966,0.001647,0.041843,293.397339,14.946372,0.418428,-1293.372559,294.500488,0.000000
34.370003,64.921272,-1293.372559,-0.002971,0.001647,0.041834,288.784241,14.711370,0.418337,-1293.372559,294.500488,0.000000
34.650002,65.394569,-1293.417114,-0.002945,0.001658,0.042103,290.889587,14.818621,0.421032,-1293.417114,294.500488,0.000000
34.930000,64.515388,-1293.283691,-0.002945,0.001674,0.042520,286.978790,14.619396,0.425195,-1293.283691,294.500488,0.000000
35.210003,65.885719,-1293.328125,-0.002915,0.001637,0.041582,293.074310,14.929918,0.415824,-1293.328125,294.500488,0.000000
35.490002,65.129799,-1293.372559,-0.002928,0.001676,0.042580,289.711823,14.758624,0.425801,-1293.372559,294.500488,0.000000
35.770000,65.046028,-1293.372559,-0.002923,0.001688,0.042884,289.339172,14.739640,0.428844,-1293.372559,294.500488,0.000000
36.050003,65.102989,-1293.417114,-0.002928,0.001698,0.043118,289.592560,14.752548,0.431175,-1293.417114,294.500488,0.000000
36.330002,65.681664,-1293.372559,-0.002915,0.001712,0.043473,292.166626,14.883677,0.434733,-1293.372559,294.500488,0.000000
36.610001,65.163322,-1293.328125,-0.002902,0.001712,0.043482,289.860931,14.766220,0.434824,-1293.328125,294.500488,0.000000
36.890003,65.790398,-1293.372559,-0.002884,0.001725,0.043803,292.650299,14.908318,0.438033,-1293.372559,294.500488,0.000000
37.170002,65.179710,-1293.417114,-0.002876,0.001725,0.043803,289.933838,14.769934,0.438033,-1293.417114,294.500488,0.000000
37.450001,64.843819,-1293.372559,-0.002884,0.001744,0.044306,288.439697,14.693819,0.443060,-1293.372559,294.500488,0.000000
37.730003,65.808266,-1293.372559,-0.002880,0.001716,0.043578,292.729797,14.912367,0.435778,-1293.372559,294.500488,0.000000
38.010002,65.148048,-1293.328125,-0.002863,0.001727,0.043855,289.792999,14.762759,0.438548,-1293.328125,294.500488,0.000000
38.290001,64.928352,-1293.372559,-0.002859,0.001745,0.044332,288.815735,14.712975,0.443317,-1293.372559,294.500488,0.000000
38.570004,64.804359,-1293.328125,-0.002867,0.001750,0.044453,288.264191,14.684877,0.444528,-1293.328125,294.500488,0.000000
38.850002,65.619469,-1293.372559,-0.002850,0.001764,0.044809,291.889984,14.869585,0.448086,-1293.372559,294.500488,0.000000
39.130001,65.115654,-1293.372559,-0.002846,0.001764,0.044809,289.648895,14.755418,0.448086,-1293.372559,294.500488,0.000000
39.410004,64.606621,-1293.283691,-0.002850,0.001764,0.044818,287.384613,14.640070,0.448177,-1293.283691,294.500488,0.000000
39.690002,66.148247,-1293.328125,-0.002820,0.001749,0.044427,294.242096,14.989407,0.444271,-1293.328125,294.500488,0.000000
39.970001,65.550957,-1293.372559,-0.002811,0.001750,0.044462,291.585205,14.854059,0.444619,-1293.372559,294.500488,0.000000
40.250004,65.094429,-1293.372559,-0.002837,0.001777,0.045139,289.554474,14.750608,0.451387,-1293.372559,294.500488,0.000000
40.530003,65.266090,-1293.328125,-0.002837,0.001789,0.045434,290.318085,14.789508,0.454339,-1293.328125,294.500488,0.000000
40.810001,65.027031,-1293.328125,-0.002824,0.001793,0.045546,289.254669,14.735335,0.455459,-1293.328125,294.500488,0.000000
41.090000,65.171135,-1293.417114,-0.002824,0.001799,0.045685,289.895691,14.767991,0.456852,-1293.417114,294.500488,0.000000
41.370003,65.170021,-1293.328125,-0.002794,0.001803,0.045797,289.890747,14.767738,0.457972,-1293.328125,294.500488,0.000000
41.650002,65.331261,-1293.417114,-0.002824,0.001810,0.045962,290.607971,14.804276,0.459623,-1293.417114,294.500488,0.000000
41.930000,65.238167,-1293.417114,-0.002802,0.001813,0.046058,290.193848,14.783179,0.460576,-1293.417114,294.500488,0.000000
42.210003,65.259758,-1293.417114,-0.002802,0.001818,0.046179,290.289886,14.788073,0.461787,-1293.417114,294.500488,0.000000
42.490002,65.229973,-1293.372559,-0.002785,0.001822,0.046267,290.157410,14.781323,0.462666,-1293.372559,294.500488,0.000000
42.770000,65.298119,-1293.417114,-0.002794,0.001827,0.046395,290.460541,14.796765,0.463952,-1293.417114,294.500488,0.000000
43.050003,65.108208,-1293.328125,-0.002798,0.001829,0.046448,289.615784,14.753730,0.464482,-1293.328125,294.500488,0.000000
43.330002,65.218437,-1293.372559,-0.002790,0.001832,0.046544,290.106110,14.778709,0.465436,-1293.372559,294.500488,0.000000
43.610001,64.949211,-1293.372559,-0.002785,0.001833,0.046569,288.908508,14.717702,0.465693,-1293.372559,294.500488,0.000000
43.890003,65.441856,-1293.328125,-0.002777,0.001842,0.046778,291.099915,14.829336,0.467783,-1293.328125,294.500488,0.000000
44.170002,65.120125,-1293.328125,-0.002764,0.001842,0.046778,289.668793,14.756431,0.467783,-1293.328125,294.500488,0.000000
44.450001,65.812370,-1293.372559,-0.002777,0.001852,0.047037,292.748047,14.913296,0.470372,-1293.372559,294.500488,0.000000
44.730003,65.469780,-1293.461548,-0.002768,0.001852,0.047037,291.224121,14.835664,0.470372,-1293.461548,294.500488,0.000000
45.010002,65.135765,-1293.328125,-0.002768,0.001852,0.047037,289.738342,14.759975,0.470372,-1293.328125,294.500488,0.000000
45.290001,64.824455,-1293.283691,-0.002755,0.001852,0.047037,288.353577,14.689431,0.470372,-1293.283691,294.500488,0.000000
45.570004,66.022377,-1293.417114,-0.002764,0.001859,0.047211,293.682190,14.960884,0.472113,-1293.417114,294.500488,0.000000
45.850002,65.618736,-1293.328125,-0.002751,0.001859,0.047211,291.886719,14.869418,0.472113,-1293.328125,294.500488,0.000000
46.130001,65.266838,-1293.328125,-0.002751,0.001859,0.047211,290.321381,14.789678,0.472113,-1293.328125,294.500488,0.000000
46.410004,65.582603,-1293.417114,-0.002759,0.001872,0.047558,291.725983,14.861231,0.475580,-1293.417114,294.500488,0.000000
46.690002,65.313759,-1293.328125,-0.002759,0.001872,0.047558,290.530121,14.800309,0.475580,-1293.328125,294.500488,0.000000
46.970001,65.051613,-1293.372559,-0.002738,0.001873,0.047567,289.364014,14.740906,0.475670,-1293.372559,294.500488,0.000000
47.250004,64.793922,-1293.372559,-0.002755,0.001873,0.047575,288.217773,14.682513,0.475746,-1293.372559,294.500488,0.000000
47.530003,65.079170,-1293.372559,-0.002746,0.001880,0.047758,289.486603,14.747151,0.477578,-1293.372559,294.500488,0.000000
47.810001,64.838982,-1293.372559,-0.002734,0.001881,0.047767,288.418182,14.692723,0.477669,-1293.372559,294.500488,0.000000
48.090004,65.670860,-1293.328125,-0.002734,0.001891,0.048044,292.118561,14.881229,0.480439,-1293.328125,294.500488,0.000000
48.370003,65.466057,-1293.328125,-0.002734,0.001892,0.048053,291.207550,14.834821,0.480530,-1293.328125,294.500488,0.000000
48.650002,65.218803,-1293.372559,-0.002721,0.001892,0.048053,290.107727,14.778792,0.480530,-1293.372559,294.500488,0.000000
48.930004,64.970802,-1293.372559,-0.002725,0.001892,0.048061,289.004578,14.722594,0.480606,-1293.372559,294.500488,0.000000
49.210003,65.946419,-1293.372559,-0.002729,0.001901,0.048277,293.344330,14.943672,0.482771,-1293.372559,294.500488,0.000000
49.490002,65.633995,-1293.328125,-0.002729,0.001901,0.048277,291.954590,14.872875,0.482771,-1293.328125,294.500488,0.000000
49.770000,65.328651,-1293.372559,-0.002721,0.001901,0.048277,290.596344,14.803684,0.482771,-1293.372559,294.500488,0.000000
50.050003,65.050117,-1293.372559,-0.002721,0.001901,0.048277,289.357361,14.740567,0.482771,-1293.372559,294.500488,0.000000
50.330002,65.854820,-1293.372559,-0.002716,0.001915,0.048633,292.936859,14.922915,0.486329,-1293.372559,294.500488,0.000000
50.610001,65.653740,-1293.372559,-0.002721,0.001915,0.048633,292.042419,14.877350,0.486329,-1293.372559,294.500488,0.000000
50.890003,65.452660,-1293.328125,-0.002703,0.001915,0.048633,291.147980,14.831784,0.486329,-1293.328125,294.500488,0.000000
51.170002,65.205772,-1293.283691,-0.002712,0.001915,0.048633,290.049774,14.775839,0.486329,-1293.283691,294.500488,0.000000
51.450001,65.029640,-1293.283691,-0.002708,0.001916,0.048668,289.266296,14.735928,0.486677,-1293.283691,294.500488,0.000000
51.730003,64.977135,-1293.461548,-0.002695,0.001922,0.048816,289.032745,14.724030,0.488161,-1293.461548,294.500488,0.000000
52.010002,65.062782,-1293.372559,-0.002695,0.001922,0.048816,289.413696,14.743437,0.488161,-1293.372559,294.500488,0.000000
52.290001,64.891121,-1293.461548,-0.002690,0.001922,0.048824,288.650116,14.704538,0.488236,-1293.461548,294.500488,0.000000
52.570004,65.704384,-1293.283691,-0.002695,0.001932,0.049075,292.267700,14.888826,0.490749,-1293.283691,294.500488,0.000000
52.850002,65.517448,-1293.328125,-0.002686,0.001932,0.049075,291.436157,14.846466,0.490749,-1293.328125,294.500488,0.000000
53.130001,65.293282,-1293.417114,-0.002699,0.001932,0.049075,290.439026,14.795669,0.490749,-1293.417114,294.500488,0.000000
53.410004,65.077675,-1293.372559,-0.002695,0.001932,0.049075,289.479950,14.746812,0.490749,-1293.372559,294.500488,0.000000
53.690002,64.881432,-1293.372559,-0.002708,0.001932,0.049075,288.607025,14.702343,0.490749,-1293.372559,294.500488,0.000000
53.970001,64.680717,-1293.328125,-0.002682,0.001932,0.049084,287.714203,14.656860,0.490840,-1293.328125,294.500488,0.000000
54.250004,64.452827,-1293.328125,-0.002686,0.001932,0.049084,286.700500,14.605219,0.490840,-1293.328125,294.500488,0.000000
54.530003,66.945869,-1293.417114,-0.002677,0.001872,0.047541,297.790100,15.170151,0.475413,-1293.417114,294.500488,0.000000
54.810001,66.567543,-1293.372559,-0.002673,0.001831,0.046518,296.107208,15.084420,0.465179,-1293.372559,294.500488,0.000000
55.090004,66.299431,-1293.328125,-0.002673,0.001832,0.046535,294.914612,15.023666,0.465345,-1293.328125,294.500488,0.000000
55.370003,66.051048,-1293.328125,-0.002677,0.001832,0.046535,293.809723,14.967381,0.465345,-1293.328125,294.500488,0.000000
55.650002,65.835075,-1293.328125,-0.002656,0.001841,0.046751,292.849030,14.918441,0.467510,-1293.328125,294.500488,0.000000
55.930004,65.581490,-1293.417114,-0.002656,0.001884,0.047862,291.721039,14.860978,0.478623,-1293.417114,294.500488,0.000000
56.210003,65.361794,-1293.372559,-0.002656,0.001932,0.049067,290.743774,14.811193,0.490674,-1293.372559,294.500488,0.000000
56.490002,65.260887,-1293.417114,-0.002660,0.001945,0.049396,290.294922,14.788328,0.493959,-1293.417114,294.500488,0.000000
56.770004,65.123848,-1293.328125,-0.002660,0.001951,0.049544,289.685333,14.757275,0.495443,-1293.328125,294.500488,0.000000
57.050003,65.030388,-1293.283691,-0.002656,0.001954,0.049631,289.269623,14.736096,0.496306,-1293.283691,294.500488,0.000000
57.330002,64.942497,-1293.283691,-0.002665,0.001955,0.049665,288.878662,14.716180,0.496654,-1293.283691,294.500488,0.000000
57.610004,65.496590,-1293.372559,-0.002665,0.001963,0.049873,291.343384,14.841740,0.498728,-1293.372559,294.500488,0.000000
57.890003,65.303703,-1293.328125,-0.002677,0.001963,0.049873,290.485382,14.798031,0.498728,-1293.328125,294.500488,0.000000
58.170002,65.137260,-1293.328125,-0.002656,0.001963,0.049873,289.744995,14.760314,0.498728,-1293.328125,294.500488,0.000000
58.450005,64.979744,-1293.328125,-0.002660,0.001963,0.049873,289.044342,14.724620,0.498728,-1293.328125,294.500488,0.000000
58.730003,64.782005,-1293.372559,-0.002656,0.001963,0.049873,288.164764,14.679812,0.498728,-1293.372559,294.500488,0.000000
59.010002,64.633812,-1293.328125,-0.002665,0.001963,0.049873,287.505554,14.646231,0.498728,-1293.328125,294.500488,0.000000
59.290001,64.468102,-1293.372559,-0.002669,0.001963,0.049873,286.768433,14.608681,0.498728,-1293.372559,294.500488,0.000000
59.570004,67.078804,-1293.328125,-0.002652,0.001918,0.048712,298.381409,15.200274,0.487116,-1293.328125,294.500488,0.000000
59.850002,66.673286,-1293.283691,-0.002643,0.001836,0.046639,296.577576,15.108383,0.466390,-1293.283691,294.500488,0.000000
60.130001,66.393272,-1293.328125,-0.002626,0.001837,0.046648,295.332031,15.044930,0.466481,-1293.328125,294.500488,0.000000
60.410004,66.179146,-1293.328125,-0.002643,0.001837,0.046648,294.379547,14.996409,0.466481,-1293.328125,294.500488,0.000000
60.690002,65.987007,-1293.372559,-0.002643,0.001837,0.046648,293.524872,14.952869,0.466481,-1293.372559,294.500488,0.000000
60.970001,65.833961,-1293.372559,-0.002656,0.001842,0.046786,292.844086,14.918188,0.467858,-1293.372559,294.500488,0.000000
61.250004,65.607567,-1293.328125,-0.002630,0.001887,0.047930,291.837036,14.866887,0.479304,-1293.328125,294.500488,0.000000
61.530003,65.447441,-1293.283691,-0.002630,0.001953,0.049605,291.124756,14.830602,0.496048,-1293.283691,294.500488,0.000000
61.810001,65.278008,-1293.283691,-0.002639,0.001960,0.049796,290.371094,14.792209,0.497956,-1293.283691,294.500488,0.000000
62.090004,65.240776,-1293.417114,-0.002643,0.001978,0.050247,290.205475,14.783772,0.502468,-1293.417114,294.500488,0.000000
62.370003,65.175240,-1293.283691,-0.002630,0.001985,0.050412,289.913940,14.768920,0.504118,-1293.283691,294.500488,0.000000
62.650002,65.076180,-1293.239136,-0.002626,0.001985,0.050428,289.473297,14.746473,0.504284,-1293.239136,294.500488,0.000000
62.930004,64.984581,-1293.283691,-0.002639,0.001987,0.050472,289.065857,14.725716,0.504723,-1293.283691,294.500488,0.000000
63.210003,65.576653,-1293.328125,-0.002630,0.001996,0.050698,291.699524,14.859881,0.506979,-1293.328125,294.500488,0.000000
63.490002,65.481331,-1293.283691,-0.002639,0.001996,0.050698,291.275513,14.838282,0.506979,-1293.283691,294.500488,0.000000
63.770004,65.307793,-1293.328125,-0.002647,0.001996,0.050698,290.503571,14.798957,0.506979,-1293.328125,294.500488,0.000000
64.050003,65.210243,-1293.328125,-0.002639,0.001996,0.050698,290.069641,14.776852,0.506979,-1293.328125,294.500488,0.000000
64.330002,65.068733,-1293.239136,-0.002643,0.001996,0.050698,289.440186,14.744785,0.506979,-1293.239136,294.500488,0.000000
64.610001,64.942879,-1293.283691,-0.002634,0.001996,0.050698,288.880341,14.716267,0.506979,-1293.283691,294.500488,0.000000
64.889999,64.789085,-1293.372559,-0.002626,0.001996,0.050698,288.196259,14.681417,0.506979,-1293.372559,294.500488,0.000000
65.170006,64.668816,-1293.283691,-0.002634,0.001996,0.050698,287.661255,14.654162,0.506979,-1293.283691,294.500488,0.000000
65.450005,65.864876,-1293.328125,-0.002647,0.002011,0.051087,292.981598,14.925194,0.510870,-1293.328125,294.500488,0.000000
65.730003,65.786293,-1293.328125,-0.002630,0.002011,0.051087,292.632050,14.907387,0.510870,-1293.328125,294.500488,0.000000
66.010002,65.683525,-1293.328125,-0.002626,0.002011,0.051087,292.174927,14.884100,0.510870,-1293.328125,294.500488,0.000000
66.290001,65.564735,-1293.372559,-0.002626,0.002011,0.051087,291.646515,14.857182,0.510870,-1293.372559,294.500488,0.000000
66.570000,65.435524,-1293.372559,-0.002613,0.002011,0.051087,291.071747,14.827902,0.510870,-1293.372559,294.500488,0.000000
66.850006,65.286949,-1293.328125,-0.002630,0.002012,0.051096,290.410858,14.794234,0.510961,-1293.328125,294.500488,0.000000
67.130005,65.161079,-1293.239136,-0.002630,0.002012,0.051096,289.850952,14.765712,0.510961,-1293.239136,294.500488,0.000000
67.410004,65.148430,-1293.283691,-0.002621,0.002015,0.051191,289.794678,14.762845,0.511915,-1293.283691,294.500488,0.000000
67.690002,65.172630,-1293.239136,-0.002617,0.002016,0.051201,289.902344,14.768330,0.512005,-1293.239136,294.500488,0.000000
67.970001,65.190498,-1293.328125,-0.002617,0.002019,0.051270,289.981812,14.772378,0.512702,-1293.328125,294.500488,0.000000
68.250000,65.226997,-1293.283691,-0.002621,0.002019,0.051278,290.144165,14.780648,0.512778,-1293.283691,294.500488,0.000000
68.530006,65.132408,-1293.328125,-0.002630,0.002019,0.051278,289.723419,14.759214,0.512778,-1293.328125,294.500488,0.000000
68.810005,65.171135,-1293.194702,-0.002608,0.002021,0.051340,289.895691,14.767991,0.513398,-1293.194702,294.500488,0.000000
69.090004,65.087349,-1293.283691,-0.002608,0.002022,0.051347,289.522980,14.749004,0.513474,-1293.283691,294.500488,0.000000
69.370003,65.113426,-1293.372559,-0.002608,0.002023,0.051391,289.638977,14.754913,0.513913,-1293.372559,294.500488,0.000000
69.650002,65.051231,-1293.283691,-0.002613,0.002023,0.051391,289.362335,14.740820,0.513913,-1293.283691,294.500488,0.000000
69.930000,64.988304,-1293.283691,-0.002613,0.002023,0.051391,289.082428,14.726561,0.513913,-1293.283691,294.500488,0.000000
70.210007,65.761345,-1293.283691,-0.002608,0.002033,0.051643,292.521057,14.901734,0.516426,-1293.283691,294.500488,0.000000
70.490005,65.651131,-1293.328125,-0.002604,0.002032,0.051617,292.030823,14.876760,0.516169,-1293.328125,294.500488,0.000000
70.770004,65.527870,-1293.283691,-0.002596,0.002032,0.051617,291.482513,14.848827,0.516169,-1293.283691,294.500488,0.000000
71.050003,65.388969,-1293.328125,-0.002600,0.002032,0.051617,290.864655,14.817352,0.516169,-1293.328125,294.500488,0.000000
71.330002,65.297371,-1293.283691,-0.002608,0.002033,0.051626,290.457214,14.796596,0.516260,-1293.283691,294.500488,0.000000
71.610001,65.194603,-1293.239136,-0.002617,0.002033,0.051626,290.000092,14.773308,0.516260,-1293.239136,294.500488,0.000000
71.890007,65.060173,-1293.328125,-0.002596,0.002033,0.051626,289.402100,14.742846,0.516260,-1293.328125,294.500488,0.000000
72.170006,64.952934,-1293.328125,-0.002613,0.002033,0.051626,288.925079,14.718545,0.516260,-1293.328125,294.500488,0.000000
72.450005,64.830040,-1293.372559,-0.002600,0.002033,0.051626,288.378418,14.690697,0.516260,-1293.372559,294.500488,0.000000
72.730003,64.728767,-1293.239136,-0.002600,0.002033,0.051626,287.927948,14.667748,0.516260,-1293.239136,294.500488,0.000000
73.010002,64.624123,-1293.194702,-0.002596,0.002033,0.051626,287.462463,14.644036,0.516260,-1293.194702,294.500488,0.000000
73.290001,66.410027,-1293.283691,-0.002570,0.002037,0.051738,295.406555,15.048727,0.517380,-1293.283691,294.500488,0.000000
73.570000,66.244682,-1293.239136,-0.002583,0.002037,0.051738,294.671051,15.011259,0.517380,-1293.239136,294.500488,0.000000
73.850006,66.087914,-1293.372559,-0.002574,0.002037,0.051738,293.973724,14.975735,0.517380,-1293.372559,294.500488,0.000000
74.130005,65.939720,-1293.283691,-0.002604,0.002037,0.051738,293.314514,14.942155,0.517380,-1293.283691,294.500488,0.000000
74.410004,65.845512,-1293.239136,-0.002578,0.002037,0.051738,292.895477,14.920807,0.517380,-1293.239136,294.500488,0.000000
74.690002,65.682777,-1293.239136,-0.002591,0.002037,0.051738,292.171600,14.883930,0.517380,-1293.239136,294.500488,0.000000
74.970001,65.564735,-1293.328125,-0.002591,0.002037,0.051738,291.646515,14.857182,0.517380,-1293.328125,294.500488,0.000000
75.250000,65.445198,-1293.328125,-0.002591,0.002037,0.051738,291.114777,14.830093,0.517380,-1293.328125,294.500488,0.000000
75.530006,65.295891,-1293.328125,-0.002578,0.002037,0.051747,290.450623,14.796261,0.517471,-1293.328125,294.500488,0.000000
75.810005,65.181572,-1293.239136,-0.002583,0.002037,0.051747,289.942108,14.770355,0.517471,-1293.239136,294.500488,0.000000
76.090004,65.308922,-1293.239136,-0.002574,0.002055,0.052189,290.508606,14.799213,0.521892,-1293.239136,294.500488,0.000000
76.370003,65.517067,-1293.283691,-0.002596,0.002055,0.052189,291.434479,14.846379,0.521892,-1293.283691,294.500488,0.000000
76.650002,65.415413,-1293.328125,-0.002565,0.002055,0.052189,290.982300,14.823344,0.521892,-1293.328125,294.500488,0.000000
76.930000,65.313393,-1293.328125,-0.002587,0.002055,0.052189,290.528473,14.800226,0.521892,-1293.328125,294.500488,0.000000
77.210007,65.235558,-1293.283691,-0.002587,0.002055,0.052189,290.182251,14.782589,0.521892,-1293.283691,294.500488,0.000000
77.490005,65.127205,-1293.239136,-0.002587,0.002055,0.052198,289.700287,14.758035,0.521982,-1293.239136,294.500488,0.000000
77.770004,65.294395,-1293.239136,-0.002583,0.002059,0.052301,290.443970,14.795921,0.523012,-1293.239136,294.500488,0.000000
78.050003,65.266838,-1293.283691,-0.002570,0.002059,0.052301,290.321381,14.789678,0.523012,-1293.283691,294.500488,0.000000
78.330002,65.193108,-1293.372559,-0.002591,0.002059,0.052301,289.993439,14.772969,0.523012,-1293.372559,294.500488,0.000000
78.610001,65.111565,-1293.328125,-0.002587,0.002060,0.052328,289.630707,14.754492,0.523284,-1293.328125,294.500488,0.000000
78.890007,65.349510,-1293.283691,-0.002587,0.002064,0.052431,290.689148,14.808411,0.524314,-1293.283691,294.500488,0.000000
79.170006,65.309288,-1293.283691,-0.002574,0.002064,0.052431,290.510223,14.799295,0.524314,-1293.283691,294.500488,0.000000
79.450005,65.253426,-1293.328125,-0.002570,0.002064,0.052431,290.261719,14.786638,0.524314,-1293.328125,294.500488,0.000000
79.730003,65.178215,-1293.328125,-0.002574,0.002064,0.052431,289.927185,14.769595,0.524314,-1293.328125,294.500488,0.000000
80.010002,65.085487,-1293.239136,-0.002587,0.002066,0.052475,289.514709,14.748582,0.524753,-1293.239136,294.500488,0.000000
80.290001,65.179710,-1293.239136,-0.002578,0.002067,0.052492,289.933838,14.769934,0.524920,-1293.239136,294.500488,0.000000
80.570007,65.095177,-1293.328125,-0.002578,0.002067,0.052492,289.557800,14.750778,0.524920,-1293.328125,294.500488,0.000000
80.850006,65.352852,-1293.328125,-0.002565,0.002072,0.052631,290.704010,14.809168,0.526312,-1293.328125,294.500488,0.000000
81.130005,65.374077,-1293.328125,-0.002574,0.002072,0.052631,290.798431,14.813977,0.526312,-1293.328125,294.500488,0.000000
81.410004,65.321953,-1293.283691,-0.002557,0.002072,0.052631,290.566559,14.802166,0.526312,-1293.283691,294.500488,0.000000
81.690002,65.258278,-1293.239136,-0.002561,0.002072,0.052631,290.283325,14.787737,0.526312,-1293.239136,294.500488,0.000000
81.970001,65.169273,-1293.283691,-0.002565,0.002072,0.052640,289.887421,14.767569,0.526403,-1293.283691,294.500488,0.000000
82.250008,65.327904,-1293.328125,-0.002565,0.002076,0.052736,290.593018,14.803514,0.527357,-1293.328125,294.500488,0.000000
82.530006,65.328285,-1293.328125,-0.002557,0.002076,0.052736,290.594727,14.803600,0.527357,-1293.328125,294.500488,0.000000
82.810005,65.272057,-1293.239136,-0.002578,0.002076,0.052736,290.344604,14.790859,0.527357,-1293.239136,294.500488,0.000000
83.090004,65.197212,-1293.328125,-0.002561,0.002077,0.052752,290.011688,14.773900,0.527524,-1293.328125,294.500488,0.000000
83.370003,65.183434,-1293.283691,-0.002557,0.002077,0.052761,289.950378,14.770777,0.527614,-1293.283691,294.500488,0.000000
83.650002,65.238167,-1293.328125,-0.002561,0.002080,0.052822,290.193848,14.783179,0.528220,-1293.328125,294.500488,0.000000
83.930000,65.222527,-1293.328125,-0.002565,0.002080,0.052822,290.124298,14.779635,0.528220,-1293.328125,294.500488,0.000000
84.210007,65.136879,-1293.328125,-0.002548,0.002080,0.052831,289.743317,14.760228,0.528311,-1293.328125,294.500488,0.000000
84.490005,65.210976,-1293.283691,-0.002570,0.002082,0.052873,290.072906,14.777019,0.528735,-1293.283691,294.500488,0.000000
84.770004,65.154015,-1293.283691,-0.002561,0.002082,0.052873,289.819519,14.764111,0.528735,-1293.283691,294.500488,0.000000
85.050003,65.103371,-1293.372559,-0.002548,0.002082,0.052892,289.594269,14.752634,0.528916,-1293.372559,294.500488,0.000000
85.330002,65.243752,-1293.283691,-0.002552,0.002086,0.052978,290.218689,14.784445,0.529779,-1293.283691,294.500488,0.000000
85.610001,65.273918,-1293.328125,-0.002552,0.002086,0.052978,290.352875,14.791282,0.529779,-1293.328125,294.500488,0.000000
85.890007,65.222160,-1293.328125,-0.002548,0.002086,0.052978,290.122650,14.779552,0.529779,-1293.328125,294.500488,0.000000
86.170006,65.161461,-1293.283691,-0.002552,0.002086,0.052978,289.852661,14.765799,0.529779,-1293.283691,294.500488,0.000000
86.450005,65.082512,-1293.328125,-0.002557,0.002086,0.052987,289.501465,14.747909,0.529870,-1293.328125,294.500488,0.000000
86.730003,65.344292,-1293.372559,-0.002565,0.002092,0.053126,290.665924,14.807228,0.531263,-1293.372559,294.500488,0.000000
87.010002,65.404610,-1293.328125,-0.002539,0.002092,0.053126,290.934235,14.820896,0.531263,-1293.328125,294.500488,0.000000
87.290001,65.387108,-1293.283691,-0.002552,0.002092,0.053126,290.856384,14.816931,0.531263,-1293.283691,294.500488,0.000000
87.570007,65.330147,-1293.328125,-0.002544,0.002092,0.053126,290.602997,14.804023,0.531263,-1293.328125,294.500488,0.000000
87.850006,65.264610,-1293.372559,-0.002535,0.002092,0.053126,290.311493,14.789172,0.531263,-1293.372559,294.500488,0.000000
88.130005,65.206520,-1293.372559,-0.002535,0.002092,0.053126,290.053101,14.776009,0.531263,-1293.372559,294.500488,0.000000
88.410004,65.100761,-1293.328125,-0.002552,0.002092,0.053126,289.582642,14.752044,0.531263,-1293.328125,294.500488,0.000000
88.690002,65.018837,-1293.328125,-0.002544,0.002092,0.053143,289.218231,14.733479,0.531430,-1293.328125,294.500488,0.000000
88.970001,65.186775,-1293.283691,-0.002535,0.002095,0.053222,289.965271,14.771534,0.532217,-1293.283691,294.500488,0.000000
89.250008,65.157356,-1293.283691,-0.002544,0.002095,0.053222,289.834381,14.764868,0.532217,-1293.283691,294.500488,0.000000
89.530006,65.093315,-1293.328125,-0.002544,0.002095,0.053222,289.549530,14.750356,0.532217,-1293.328125,294.500488,0.000000
89.810005,65.108574,-1293.372559,-0.002531,0.002097,0.053255,289.617401,14.753814,0.532550,-1293.372559,294.500488,0.000000
90.090004,65.088478,-1293.417114,-0.002548,0.002097,0.053264,289.528015,14.749260,0.532641,-1293.417114,294.500488,0.000000
90.370003,65.045647,-1293.328125,-0.002539,0.002097,0.053264,289.337494,14.739554,0.532641,-1293.328125,294.500488,0.000000
90.650002,65.000221,-1293.283691,-0.002539,0.002101,0.053369,289.135437,14.729260,0.533685,-1293.283691,294.500488,0.000000
90.930008,65.393074,-1293.328125,-0.002531,0.002103,0.053412,290.882935,14.818282,0.534124,-1293.328125,294.500488,0.000000
91.210007,65.361794,-1293.417114,-0.002531,0.002103,0.053412,290.743774,14.811193,0.534124,-1293.417114,294.500488,0.000000
91.490005,65.298866,-1293.417114,-0.002535,0.002103,0.053412,290.463867,14.796934,0.534124,-1293.417114,294.500488,0.000000
91.770004,65.257530,-1293.372559,-0.002544,0.002103,0.053412,290.279999,14.787567,0.534124,-1293.372559,294.500488,0.000000
92.050003,65.215080,-1293.328125,-0.002539,0.002104,0.053429,290.091156,14.777948,0.534291,-1293.328125,294.500488,0.000000
92.330002,65.191246,-1293.328125,-0.002527,0.002105,0.053455,289.985138,14.772547,0.534548,-1293.328125,294.500488,0.000000
92.610001,65.208382,-1293.372559,-0.002539,0.002106,0.053481,290.061371,14.776431,0.534806,-1293.372559,294.500488,0.000000
92.890007,65.247475,-1293.328125,-0.002544,0.002107,0.053524,290.235260,14.785289,0.535245,-1293.328125,294.500488,0.000000
93.170006,65.269447,-1293.328125,-0.002539,0.002101,0.053378,290.333008,14.790268,0.533776,-1293.328125,0.053524,0.000000
93.450005,65.097786,-1293.328125,-0.002527,0.002098,0.053299,289.569427,14.751369,0.532989,-1293.328125,0.053091,0.000000
93.730003,65.030754,-1293.328125,-0.002518,0.002086,0.052987,289.271240,14.736180,0.529870,-1293.328125,0.052622,0.000000
94.010002,64.921654,-1293.417114,-0.002518,0.002073,0.052657,288.785950,14.711456,0.526570,-1293.417114,0.052154,0.000000
94.290001,64.788338,-1293.417114,-0.002518,0.002055,0.052206,288.192932,14.681248,0.522058,-1293.417114,0.051687,0.000000
94.570007,64.678490,-1293.328125,-0.002518,0.002038,0.051755,287.704285,14.656355,0.517547,-1293.328125,0.051226,0.000000
94.850006,64.606621,-1293.328125,-0.002505,0.002018,0.051252,287.384613,14.640070,0.512520,-1293.328125,0.050758,0.000000
95.130005,64.563805,-1293.283691,-0.002522,0.001996,0.050705,287.194153,14.630367,0.507055,-1293.283691,0.050289,0.000000
95.410004,64.431236,-1293.328125,-0.002509,0.001980,0.050298,286.604462,14.600327,0.502982,-1293.328125,0.049821,0.000000
95.690002,64.360863,-1293.417114,-0.002505,0.001963,0.049856,286.291412,14.584379,0.498562,-1293.417114,0.049354,0.000000
95.970001,64.255470,-1293.328125,-0.002518,0.001946,0.049423,285.822601,14.560497,0.494232,-1293.328125,0.048884,0.000000
96.250008,64.227913,-1293.328125,-0.002522,0.001931,0.049042,285.700012,14.554254,0.490416,-1293.328125,0.048425,0.000000
96.530006,64.068550,-1293.283691,-0.002496,0.001911,0.048547,284.991150,14.518141,0.485466,-1293.283691,0.047958,0.000000
96.810005,63.962044,-1293.328125,-0.002514,0.001895,0.048121,284.517395,14.494006,0.481212,-1293.328125,0.047488,0.000000
97.090004,63.496208,-1293.372559,-0.002501,0.001873,0.047584,282.445251,14.388447,0.475837,-1293.372559,0.047021,0.000000
97.370003,62.971535,-1293.328125,-0.002488,0.001856,0.047142,280.111389,14.269554,0.471416,-1293.328125,0.046553,0.000000
97.650002,62.450211,-1293.328125,-0.002501,0.001844,0.046839,277.792419,14.151421,0.468388,-1293.328125,0.046092,0.000000
97.930008,61.647377,-1293.372559,-0.002496,0.001829,0.046465,274.221222,13.969495,0.464649,-1293.372559,0.045625,0.000000
98.210007,60.646812,-1293.328125,-0.002492,0.001810,0.045962,269.770508,13.742764,0.459623,-1293.328125,0.045155,0.000000
98.490005,59.826851,-1293.372559,-0.002479,0.001794,0.045564,266.123138,13.556958,0.455641,-1293.372559,0.044687,0.000000
98.770004,59.099609,-1293.372559,-0.002501,0.001781,0.045243,262.888184,13.392162,0.452431,-1293.372559,0.044220,0.000000
99.050003,57.700974,-1293.372559,-0.002496,0.001761,0.044722,256.666748,13.075227,0.447223,-1293.372559,0.043750,0.000000
99.330002,55.898689,-1293.372559,-0.002488,0.001737,0.044115,248.649796,12.666824,0.441152,-1293.372559,0.043292,0.000000
99.610008,54.361168,-1293.372559,-0.002479,0.001717,0.043613,241.810547,12.318418,0.436126,-1293.372559,0.042822,0.000000
99.890007,53.072014,-1293.328125,-0.002483,0.001702,0.043239,236.076111,12.026290,0.432386,-1293.328125,0.042354,0.000000
100.170006,51.870743,-1293.328125,-0.002505,0.001688,0.042866,230.732590,11.754079,0.428662,-1293.328125,0.041887,0.000000
100.450005,50.142189,-1293.328125,-0.002496,0.001670,0.042406,223.043594,11.362382,0.424060,-1293.328125,0.041417,0.000000
100.730003,49.374725,-1293.328125,-0.002505,0.001665,0.042285,219.629745,11.188473,0.422848,-1293.328125,0.040959,0.000000
101.010002,46.759186,-1293.328125,-0.002496,0.001635,0.041531,207.995239,10.595783,0.415309,-1293.328125,0.040491,0.000000
101.290009,44.562187,-1293.372559,-0.002505,0.001612,0.040950,198.222504,10.097937,0.409495,-1293.372559,0.040021,0.000000
101.570007,42.556213,-1293.372559,-0.002514,0.001594,0.040482,189.299484,9.643375,0.404817,-1293.372559,0.039554,0.000000
101.850006,41.063744,-1293.372559,-0.002522,0.001579,0.040109,182.660660,9.305178,0.401093,-1293.372559,0.039086,0.000000
102.130005,38.664177,-1293.328125,-0.002505,0.001554,0.039475,171.986847,8.761428,0.394749,-1293.328125,0.038626,0.000000
102.410004,37.332573,-1293.239136,-0.002514,0.001540,0.039112,166.063583,8.459682,0.391116,-1293.239136,0.038158,0.000000
102.690002,35.944000,-1293.372559,-0.002518,0.001523,0.038677,159.886902,8.145027,0.386771,-1293.372559,0.037688,0.000000
102.970001,34.149536,-1293.372559,-0.002531,0.001506,0.038261,151.904724,7.738396,0.382607,-1293.372559,0.037221,0.000000
103.250008,31.668419,-1293.372559,-0.002518,0.001479,0.037558,140.868164,7.176167,0.375583,-1293.372559,0.036753,0.000000
103.530006,30.016571,-1293.328125,-0.002531,0.001463,0.037169,133.520370,6.801852,0.371692,-1293.328125,0.036284,0.000000
103.810005,28.322647,-1293.328125,-0.002544,0.001444,0.036665,125.985428,6.418004,0.366650,-1293.328125,0.035825,0.000000
104.090004,26.327477,-1293.417114,-0.002535,0.001426,0.036215,117.110466,5.965891,0.362154,-1293.417114,0.035355,0.000000
104.370003,24.875969,-1293.461548,-0.002544,0.001411,0.035841,110.653839,5.636975,0.358414,-1293.461548,0.034888,0.000000
104.650002,23.625168,-1293.417114,-0.002544,0.001399,0.035539,105.089996,5.353539,0.355386,-1293.417114,0.034420,0.000000
104.930008,21.558876,-1293.283691,-0.002557,0.001378,0.034992,95.898666,4.885311,0.349921,-1293.283691,0.033951,0.000000
105.210007,19.608391,-1293.372559,-0.002561,0.001358,0.034489,87.222481,4.443325,0.344895,-1293.372559,0.033492,0.000000
105.490005,17.484001,-1293.328125,-0.002561,0.001336,0.033925,77.772720,3.961931,0.339248,-1293.328125,0.033024,0.000000
105.770004,15.550644,-1293.328125,-0.002561,0.001316,0.033422,69.172722,3.523826,0.334221,-1293.328125,0.032555,0.000000
106.050003,13.953171,-1293.372559,-0.002574,0.001299,0.032989,62.066803,3.161834,0.329891,-1293.372559,0.032087,0.000000
106.330002,12.228714,-1293.328125,-0.002574,0.001282,0.032573,54.396038,2.771066,0.325728,-1293.328125,0.031619,0.000000
106.610008,10.294609,-1293.328125,-0.002583,0.001261,0.032017,45.792709,2.332792,0.320172,-1293.328125,0.031150,0.000000
106.890007,9.267975,-1293.283691,-0.002570,0.001249,0.031731,41.226009,2.100153,0.317310,-1293.283691,0.030691,0.000000
107.170006,6.805107,-1293.417114,-0.002608,0.001222,0.031047,30.270628,1.542059,0.310467,-1293.417114,0.030222,0.000000
107.450005,6.110260,-1293.417114,-0.002596,0.001215,0.030856,27.179794,1.384605,0.308560,-1293.417114,0.029754,0.000000
107.730003,4.907494,-1293.372559,-0.002617,0.001199,0.030447,21.829622,1.112054,0.304472,-1293.372559,0.029286,0.000000
108.010002,1.998894,-1293.328125,-0.002608,0.001165,0.029589,8.891523,0.452956,0.295888,-1293.328125,0.028817,0.000000
108.290009,1.016953,-1293.372559,-0.002608,0.001155,0.029328,4.523631,0.230445,0.293284,-1293.372559,0.028358,0.000000
108.570007,-0.511269,-1293.283691,-0.002617,0.001135,0.028817,-2.274236,-0.115855,0.288167,-1293.283691,0.027889,0.000000
108.850006,-1.197178,-1293.328125,-0.002630,0.001123,0.028523,-5.325313,-0.271284,0.285230,-1293.328125,0.027421,0.000000
109.130005,-0.424873,-1293.372559,-0.002660,0.001097,0.027872,-1.889931,-0.096278,0.278720,-1293.372559,0.026953,0.000000
109.410004,-0.023834,-1293.328125,-0.002682,0.001087,0.027621,-0.106020,-0.005401,0.276206,-1293.328125,0.026485,0.000000
109.690002,-0.059204,-1293.328125,-0.002682,0.001069,0.027144,-0.263353,-0.013416,0.271438,-1293.328125,0.026025,0.000000
109.970009,-0.051018,-1293.417114,-0.002712,0.001043,0.026502,-0.226938,-0.011561,0.265018,-1293.417114,0.025557,0.000000
110.250008,-0.060326,-1293.328125,-0.002734,0.001029,0.026129,-0.268342,-0.013670,0.261294,-1293.328125,0.025088,0.000000
110.530006,-0.046173,-1293.328125,-0.002746,0.001008,0.025609,-0.205388,-0.010463,0.256086,-1293.328125,0.024620,0.000000
110.810005,-0.051384,-1293.328125,-0.002751,0.000994,0.025236,-0.228567,-0.011644,0.252362,-1293.328125,0.024152,0.000000
111.090004,-0.039841,-1293.372559,-0.002759,0.000975,0.024759,-0.177220,-0.009028,0.247593,-1293.372559,0.023683,0.000000
111.370003,-0.031654,-1293.417114,-0.002798,0.000953,0.024195,-0.140806,-0.007173,0.241946,-1293.417114,0.023224,0.000000
111.650002,-0.033516,-1293.372559,-0.002811,0.000939,0.023848,-0.149086,-0.007595,0.238479,-1293.372559,0.022755,0.000000
111.930008,-0.030159,-1293.372559,-0.002837,0.000921,0.023389,-0.134154,-0.006834,0.233891,-1293.372559,0.022287,0.000000
112.210007,-0.037613,-1293.328125,-0.002850,0.000904,0.022955,-0.167311,-0.008523,0.229546,-1293.328125,0.021819,0.000000
112.490005,-0.027184,-1293.372559,-0.002863,0.000880,0.022357,-0.120918,-0.006160,0.223566,-1293.372559,0.021350,0.000000
112.770004,-0.025322,-1293.372559,-0.002880,0.000869,0.022061,-0.112638,-0.005738,0.220614,-1293.372559,0.020891,0.000000
113.050003,0.004471,-1293.372559,-0.002902,0.000843,0.021403,0.019887,0.001013,0.214028,-1293.372559,0.020422,0.000000
113.300003,-0.000748,-1293.328125,-0.002928,0.000836,0.021247,-0.003326,-0.000169,0.212469,-1293.328125,0.021133,0.000000