File: Data/Sima compression/P2-21-1_10302024_175546.csv
Time (sec),S:Load (lbs),S:HL1 (DIM),S:LVDT (in),S:Position (in),Ch:Position (mm),Ch:Load (N),Ch:Stress (MPa),Ch:Strain (mm/mm),Ch:HL1 (DIM),Set Point (),Cycles ()
0.010000,-0.003349,-1293.550537,-0.008442,-0.004909,-0.124682,-0.014898,-0.000759,-1.246820,-1293.550537,-0.124499,0.000000
0.300000,-0.007072,-1293.506104,-0.008446,-0.004909,-0.124682,-0.031460,-0.001603,-1.246820,-1293.506104,-0.124499,0.000000
0.590000,0.014153,-1293.550537,-0.008438,-0.004797,-0.121837,0.062954,0.003207,-1.218373,-1293.550537,-0.121049,0.000000
0.880000,0.017128,-1293.506104,-0.008291,-0.004612,-0.117155,0.076189,0.003881,-1.171546,-1293.506104,-0.116227,0.000000
1.170000,-0.023460,-1293.506104,-0.008093,-0.004423,-0.112349,-0.104357,-0.005316,-1.123493,-1293.506104,-0.111386,0.000000
1.460000,-0.011543,-1293.594971,-0.007916,-0.004235,-0.107562,-0.051347,-0.002616,-1.075622,-1293.594971,-0.106564,0.000000
1.750000,-0.035751,-1293.550537,-0.007722,-0.004044,-0.102705,-0.159030,-0.008101,-1.027054,-1293.550537,-0.101726,0.000000
2.040000,-0.039101,-1293.594971,-0.007549,-0.003865,-0.098162,-0.173928,-0.008860,-0.981620,-1293.594971,-0.096904,0.000000
2.330000,-0.005585,-1293.550537,-0.007317,-0.003670,-0.093210,-0.024842,-0.001266,-0.932099,-1293.550537,-0.092065,0.000000
2.620000,0.026436,-1293.550537,-0.007136,-0.003482,-0.088439,0.117593,0.005990,-0.884394,-1293.550537,-0.087227,0.000000
2.910000,0.001862,-1293.550537,-0.006916,-0.003286,-0.083471,0.008281,0.000422,-0.834706,-1293.550537,-0.082405,0.000000
3.200000,0.021225,-1293.506104,-0.006743,-0.003100,-0.078736,0.094413,0.004810,-0.787364,-1293.506104,-0.077565,0.000000
3.490000,-0.014893,-1293.550537,-0.006528,-0.002903,-0.073724,-0.066245,-0.003375,-0.737237,-1293.550537,-0.072743,0.000000
3.780000,-0.029045,-1293.594971,-0.006342,-0.002716,-0.068988,-0.129199,-0.006582,-0.689880,-1293.594971,-0.067904,0.000000
4.070000,-0.074104,-1293.506104,-0.006148,-0.002526,-0.064159,-0.329632,-0.016792,-0.641585,-1293.506104,-0.063082,0.000000
4.360000,0.020851,-1293.594971,-0.005963,-0.002335,-0.059318,0.092750,0.004725,-0.593184,-1293.594971,-0.058243,0.000000
4.650000,0.011543,-1293.506104,-0.005769,-0.002147,-0.054540,0.051347,0.002616,-0.545403,-1293.506104,-0.053422,0.000000
4.940000,0.048035,-1293.506104,-0.005575,-0.001961,-0.049797,0.213669,0.010885,-0.497971,-1293.506104,-0.048583,0.000000
5.230000,0.020111,-1293.506104,-0.005376,-0.001762,-0.044759,0.089459,0.004557,-0.447587,-1293.506104,-0.043761,0.000000
5.520000,-0.008934,-1293.506104,-0.005187,-0.001581,-0.040153,-0.039741,-0.002024,-0.401532,-1293.506104,-0.038921,0.000000
5.810000,-0.025322,-1293.594971,-0.004975,-0.001384,-0.035166,-0.112638,-0.005738,-0.351662,-1293.594971,-0.034082,0.000000
6.100000,-0.009308,-1293.550537,-0.004781,-0.001197,-0.030405,-0.041403,-0.002109,-0.304048,-1293.550537,-0.029260,0.000000
6.390000,0.021225,-1293.506104,-0.004587,-0.001006,-0.025557,0.094413,0.004810,-0.255571,-1293.506104,-0.024422,0.000000
6.680000,0.062561,-1293.594971,-0.004544,-0.000000,-0.000000,0.278285,0.014177,-0.000000,-1293.594971,0.000226,0.000000
6.970000,0.081924,-1293.506104,-0.004562,-0.000000,-0.000000,0.364418,0.018564,-0.000000,-1293.506104,0.000226,0.000000
7.260000,0.132935,-1293.594971,-0.004557,0.000000,0.000009,0.591322,0.030123,0.000091,-1293.594971,0.000702,0.000000
7.550000,0.156021,-1293.461548,-0.004549,0.000012,0.000303,0.694017,0.035355,0.003028,-1293.461548,0.001188,0.000000
7.840000,0.186188,-1293.594971,-0.004562,0.000023,0.000572,0.828204,0.042191,0.005723,-1293.594971,0.001673,0.000000
8.130000,0.392853,-1293.550537,-0.004531,0.000051,0.001300,1.747496,0.089022,0.013005,-1293.550537,0.002159,0.000000
8.420000,0.541428,-1293.461548,-0.004497,0.000068,0.001717,2.408390,0.122689,0.017168,-1293.461548,0.002636,0.000000
8.710000,0.789055,-1293.594971,-0.004493,0.000085,0.002168,3.509891,0.178802,0.021680,-1293.594971,0.003122,0.000000
9.000000,1.189354,-1293.506104,-0.004475,0.000107,0.002722,5.290511,0.269511,0.027221,-1293.506104,0.003608,0.000000
9.290001,1.548698,-1293.550537,-0.004467,0.000122,0.003096,6.888955,0.350940,0.030960,-1293.550537,0.004092,0.000000
9.580001,1.972458,-1293.594971,-0.004449,0.000139,0.003529,8.773931,0.446965,0.035290,-1293.594971,0.004571,0.000000
9.870001,2.630440,-1293.461548,-0.004441,0.000164,0.004154,11.700781,0.596066,0.041543,-1293.461548,0.005055,0.000000
10.160001,3.033348,-1293.594971,-0.004432,0.000178,0.004509,13.493006,0.687367,0.045086,-1293.594971,0.005541,0.000000
10.450001,3.738991,-1293.506104,-0.004415,0.000199,0.005048,16.631861,0.847267,0.050475,-1293.506104,0.006018,0.000000
10.740001,4.343727,-1293.506104,-0.004402,0.000218,0.005532,19.321863,0.984303,0.055320,-1293.506104,0.006504,0.000000
11.030001,5.200928,-1293.506104,-0.004376,0.000238,0.006036,23.134882,1.178547,0.060362,-1293.506104,0.006990,0.000000
11.320001,5.816460,-1293.506104,-0.004385,0.000254,0.006452,25.872904,1.318029,0.064525,-1293.506104,0.007474,0.000000
11.610001,6.408531,-1293.550537,-0.004376,0.000267,0.006790,28.506571,1.452194,0.067901,-1293.550537,0.007953,0.000000
11.900001,7.870834,-1293.550537,-0.004346,0.000298,0.007570,35.011219,1.783557,0.075698,-1293.550537,0.008437,0.000000
12.190001,8.619308,-1293.506104,-0.004346,0.000314,0.007986,38.340599,1.953163,0.079861,-1293.506104,0.008923,0.000000
12.480000,9.373734,-1293.506104,-0.004316,0.000333,0.008465,41.696449,2.124118,0.084645,-1293.506104,0.009409,0.000000
12.770000,10.295357,-1293.506104,-0.004312,0.000351,0.008914,45.796036,2.332961,0.089142,-1293.506104,0.009886,0.000000
13.060000,11.609825,-1293.550537,-0.004299,0.000375,0.009530,51.643082,2.630824,0.095304,-1293.550537,0.010372,0.000000
13.350000,12.315475,-1293.550537,-0.004286,0.000391,0.009938,54.781971,2.790727,0.099376,-1293.550537,0.010857,0.000000
13.640000,12.899353,-1293.550537,-0.004281,0.000404,0.010259,57.379189,2.923035,0.102586,-1293.550537,0.011343,0.000000
13.930000,14.238777,-1293.594971,-0.004268,0.000428,0.010884,63.337246,3.226553,0.108838,-1293.594971,0.011819,0.000000
14.220000,15.060608,-1293.461548,-0.004260,0.000446,0.011326,66.992928,3.412783,0.113259,-1293.461548,0.012305,0.000000
14.510000,16.276031,-1293.594971,-0.004255,0.000465,0.011819,72.399406,3.688201,0.118195,-1293.594971,0.012791,0.000000
14.800001,17.510445,-1293.506104,-0.004225,0.000487,0.012375,77.890350,3.967923,0.123751,-1293.506104,0.013277,0.000000
15.090001,18.435417,-1293.550537,-0.004221,0.000504,0.012808,82.004829,4.177526,0.128081,-1293.550537,0.013754,0.000000
15.380001,19.269157,-1293.594971,-0.004212,0.000520,0.013208,85.713493,4.366454,0.132078,-1293.594971,0.014239,0.000000
15.670001,20.309196,-1293.550537,-0.004199,0.000542,0.013754,90.339821,4.602129,0.137543,-1293.550537,0.014725,0.000000
15.960001,21.419235,-1293.550537,-0.004178,0.000561,0.014248,95.277519,4.853668,0.142479,-1293.550537,0.015202,0.000000
16.250000,22.312561,-1293.550537,-0.004161,0.000579,0.014699,99.251228,5.056099,0.146990,-1293.550537,0.015688,0.000000
16.540001,23.670227,-1293.550537,-0.004178,0.000603,0.015306,105.290428,5.363750,0.153061,-1293.550537,0.016174,0.000000
16.830000,24.534508,-1293.594971,-0.004161,0.000619,0.015732,109.134941,5.559599,0.157315,-1293.594971,0.016660,0.000000
17.120001,25.565605,-1293.461548,-0.004130,0.000638,0.016218,113.721489,5.793249,0.162175,-1293.461548,0.017136,0.000000
17.410002,26.047455,-1293.550537,-0.004122,0.000651,0.016537,115.864868,5.902437,0.165370,-1293.550537,0.017621,0.000000
17.700001,27.141487,-1293.506104,-0.004109,0.000671,0.017049,120.731361,6.150349,0.170487,-1293.506104,0.018107,0.000000
17.990002,28.053795,-1293.506104,-0.004105,0.000691,0.017553,124.789513,6.357081,0.175528,-1293.506104,0.018593,0.000000
18.280001,29.122879,-1293.506104,-0.004074,0.000712,0.018090,129.545029,6.599339,0.180903,-1293.506104,0.019070,0.000000
18.570002,29.891830,-1293.506104,-0.004066,0.000729,0.018514,132.965500,6.773585,0.185142,-1293.506104,0.019556,0.000000
18.860001,31.531013,-1293.550537,-0.004053,0.000755,0.019174,140.256958,7.145030,0.191743,-1293.550537,0.020042,0.000000
19.150002,32.311874,-1293.506104,-0.004036,0.000773,0.019625,143.730392,7.321975,0.196254,-1293.506104,0.020526,0.000000
19.440001,32.106323,-1293.550537,-0.004027,0.000779,0.019781,142.816055,7.275397,0.197814,-1293.550537,0.021003,0.000000
19.730001,33.853500,-1293.506104,-0.004014,0.000807,0.020493,150.587891,7.671313,0.204929,-1293.506104,0.021489,0.000000
20.020000,34.901726,-1293.550537,-0.003988,0.000829,0.021056,155.250626,7.908844,0.210561,-1293.550537,0.021975,0.000000
20.310001,35.933571,-1293.550537,-0.003984,0.000848,0.021550,159.840500,8.142664,0.215497,-1293.550537,0.022461,0.000000
20.600000,36.768433,-1293.550537,-0.003980,0.000868,0.022054,163.554153,8.331845,0.220538,-1293.550537,0.022938,0.000000
20.890001,37.666222,-1293.461548,-0.003958,0.000888,0.022556,167.547714,8.535288,0.225565,-1293.461548,0.023424,0.000000
21.180000,38.103386,-1293.550537,-0.003945,0.000902,0.022903,169.492325,8.634351,0.229032,-1293.550537,0.023908,0.000000
21.470001,37.942146,-1293.506104,-0.003928,0.000911,0.023129,168.775101,8.597814,0.231287,-1293.506104,0.024385,0.000000
21.760000,39.729904,-1293.550537,-0.003915,0.000941,0.023901,176.727448,9.002925,0.239009,-1293.550537,0.024871,0.000000
22.050001,40.437790,-1293.506104,-0.003898,0.000958,0.024334,179.876266,9.163335,0.243338,-1293.506104,0.025357,0.000000
22.340000,41.351219,-1293.461548,-0.003876,0.000980,0.024897,183.939407,9.370320,0.248970,-1293.461548,0.025843,0.000000
22.630001,42.439293,-1293.594971,-0.003876,0.001002,0.025462,188.779404,9.616881,0.254617,-1293.594971,0.026320,0.000000
22.920002,43.089455,-1293.506104,-0.003850,0.001020,0.025920,191.671463,9.764211,0.259205,-1293.506104,0.026806,0.000000
23.210001,43.059288,-1293.550537,-0.003824,0.001031,0.026181,191.537277,9.757374,0.261809,-1293.550537,0.027291,0.000000
23.500002,44.400574,-1293.550537,-0.003820,0.001057,0.026858,197.503616,10.061314,0.268576,-1293.550537,0.027777,0.000000
23.790001,44.874229,-1293.506104,-0.003807,0.001072,0.027239,199.610535,10.168646,0.272391,-1293.506104,0.028253,0.000000
24.080002,45.515831,-1293.550537,-0.003790,0.001092,0.027734,202.464523,10.314034,0.277342,-1293.550537,0.028739,0.000000
24.370001,46.324249,-1293.461548,-0.003773,0.001113,0.028263,206.060547,10.497225,0.282626,-1293.461548,0.029225,0.000000
24.660002,47.167679,-1293.461548,-0.003755,0.001132,0.028749,209.812317,10.688349,0.287485,-1293.461548,0.029711,0.000000
24.950001,47.951889,-1293.550537,-0.003738,0.001152,0.029251,213.300659,10.866054,0.292512,-1293.550537,0.030188,0.000000
25.240002,47.908325,-1293.461548,-0.003725,0.001165,0.029598,213.106873,10.856182,0.295979,-1293.461548,0.030673,0.000000
25.530001,49.341957,-1293.594971,-0.003734,0.001190,0.030214,219.483994,11.181047,0.302141,-1293.594971,0.031159,0.000000
25.820002,49.954140,-1293.461548,-0.003699,0.001211,0.030768,222.207108,11.319770,0.307682,-1293.461548,0.031645,0.000000
26.110001,50.452370,-1293.506104,-0.003682,0.001226,0.031142,224.423355,11.432670,0.311421,-1293.506104,0.032122,0.000000
26.400002,51.138283,-1293.550537,-0.003665,0.001246,0.031654,227.474442,11.588100,0.316538,-1293.550537,0.032608,0.000000
26.690001,52.119110,-1293.461548,-0.003648,0.001268,0.032217,231.837387,11.810359,0.322170,-1293.461548,0.033094,0.000000
26.980001,52.296364,-1293.550537,-0.003639,0.001281,0.032547,232.625839,11.850526,0.325471,-1293.550537,0.033571,0.000000
27.270000,51.769455,-1293.506104,-0.003609,0.001288,0.032712,230.282043,11.731127,0.327121,-1293.506104,0.034055,0.000000
27.560001,54.040924,-1293.506104,-0.003600,0.001323,0.033605,240.386032,12.245849,0.336053,-1293.506104,0.034541,0.000000
27.850000,54.448303,-1293.550537,-0.003587,0.001341,0.034073,242.198151,12.338161,0.340731,-1293.550537,0.035027,0.000000
28.140001,55.220230,-1293.506104,-0.003557,0.001362,0.034594,245.631851,12.513083,0.345939,-1293.506104,0.035504,0.000000
28.430002,55.781021,-1293.550537,-0.003561,0.001381,0.035087,248.126373,12.640160,0.350875,-1293.550537,0.035990,0.000000
28.720001,56.373093,-1293.506104,-0.003535,0.001398,0.035520,250.760040,12.774325,0.355205,-1293.506104,0.036476,0.000000
29.010002,56.384262,-1293.506104,-0.003523,0.001411,0.035834,250.809723,12.776856,0.358339,-1293.506104,0.036960,0.000000
29.300001,57.579956,-1293.506104,-0.003501,0.001437,0.036502,256.128448,13.047805,0.365015,-1293.506104,0.037437,0.000000
29.590002,57.945625,-1293.506104,-0.003488,0.001450,0.036822,257.755005,13.130666,0.368225,-1293.506104,0.037923,0.000000
29.880001,58.609192,-1293.506104,-0.003466,0.001471,0.037369,260.706696,13.281033,0.373690,-1293.506104,0.038409,0.000000
30.170002,58.962570,-1293.550537,-0.003458,0.001488,0.037793,262.278625,13.361109,0.377929,-1293.550537,0.038895,0.000000
30.460001,59.785515,-1293.506104,-0.003445,0.001506,0.038262,265.939240,13.547591,0.382623,-1293.506104,0.039372,0.000000
30.750002,60.296036,-1293.550537,-0.003419,0.001525,0.038739,268.210175,13.663277,0.387392,-1293.550537,0.039858,0.000000
31.040001,60.510529,-1293.417114,-0.003410,0.001539,0.039095,269.164276,13.711882,0.390949,-1293.417114,0.040342,0.000000
31.330002,62.144867,-1293.550537,-0.003393,0.001567,0.039814,276.434174,14.082229,0.398141,-1293.550537,0.040828,0.000000
31.620001,62.618896,-1293.506104,-0.003363,0.001587,0.040300,278.542755,14.189645,0.403000,-1293.506104,0.041305,0.000000
31.910002,63.124207,-1293.506104,-0.003359,0.001603,0.040707,280.790497,14.304150,0.407073,-1293.506104,0.041791,0.000000
32.200001,63.761711,-1293.506104,-0.003341,0.001620,0.041140,283.626251,14.448610,0.411403,-1293.506104,0.042277,0.000000
32.490002,65.015480,-1293.550537,-0.003316,0.001646,0.041800,289.203308,14.732718,0.418004,-1293.550537,0.042754,0.000000
32.780003,65.331627,-1293.594971,-0.003328,0.001663,0.042242,290.609589,14.804358,0.422425,-1293.594971,0.043240,0.000000
33.070000,65.206520,-1293.461548,-0.003307,0.001672,0.042477,290.053101,14.776009,0.424771,-1293.461548,0.043725,0.000000
33.360001,65.610909,-1293.461548,-0.003277,0.001681,0.042694,291.851898,14.867644,0.426936,-1293.461548,0.007515,0.000000
33.650002,66.294212,-1293.506104,-0.003251,0.001680,0.042668,294.891388,15.022483,0.426679,-1293.506104,294.500488,0.000000
33.940002,65.151772,-1293.417114,-0.003251,0.001705,0.043301,289.809540,14.763602,0.433007,-1293.417114,294.500488,0.000000
34.230003,65.085869,-1293.506104,-0.003251,0.001713,0.043508,289.516418,14.748669,0.435081,-1293.506104,294.500488,0.000000
34.520000,65.098152,-1293.550537,-0.003225,0.001729,0.043908,289.571045,14.751452,0.439078,-1293.550537,294.500488,0.000000
34.810001,65.508507,-1293.461548,-0.003221,0.001740,0.044185,291.396393,14.844440,0.441849,-1293.461548,294.500488,0.000000
35.100002,65.296257,-1293.506104,-0.003212,0.001747,0.044367,290.452271,14.796344,0.443665,-1293.506104,294.500488,0.000000
35.390003,65.575157,-1293.506104,-0.003191,0.001758,0.044653,291.692871,14.859543,0.446527,-1293.506104,294.500488,0.000000
35.680000,65.788155,-1293.506104,-0.003182,0.001765,0.044827,292.640320,14.907809,0.448268,-1293.506104,294.500488,0.000000
35.970001,66.016426,-1293.506104,-0.003160,0.001772,0.045008,293.655731,14.959536,0.450085,-1293.506104,294.500488,0.000000
36.260002,65.021812,-1293.550537,-0.003160,0.001772,0.044999,289.231476,14.734154,0.449994,-1293.550537,294.500488,0.000000
36.550003,65.320457,-1293.506104,-0.003152,0.001785,0.045329,290.559906,14.801826,0.453294,-1293.506104,294.500488,0.000000
36.840000,65.017723,-1293.417114,-0.003160,0.001796,0.045616,289.213287,14.733227,0.456156,-1293.417114,294.500488,0.000000
37.130001,65.135017,-1293.506104,-0.003139,0.001815,0.046092,289.735016,14.759806,0.460925,-1293.506104,294.500488,0.000000
37.420002,65.228477,-1293.506104,-0.003117,0.001811,0.045997,290.150757,14.780985,0.459971,-1293.506104,294.500488,0.000000
37.710003,66.573494,-1293.461548,-0.003104,0.001801,0.045755,296.133698,15.085770,0.457548,-1293.461548,294.500488,0.000000
38.000000,65.621712,-1293.594971,-0.003087,0.001801,0.045737,291.899963,14.870092,0.457367,-1293.594971,294.500488,0.000000
38.290001,64.973412,-1293.506104,-0.003100,0.001827,0.046404,289.016174,14.723186,0.464043,-1293.506104,294.500488,0.000000
38.580002,65.464195,-1293.550537,-0.003096,0.001840,0.046734,291.199280,14.834398,0.467344,-1293.550537,294.500488,0.000000
38.870003,65.972115,-1293.550537,-0.003091,0.001855,0.047116,293.458618,14.949494,0.471159,-1293.550537,294.500488,0.000000
39.160004,65.271309,-1293.550537,-0.003070,0.001854,0.047081,290.341278,14.790690,0.470811,-1293.550537,294.500488,0.000000
39.450001,65.726341,-1293.594971,-0.003091,0.001867,0.047411,292.365356,14.893802,0.474111,-1293.594971,294.500488,0.000000
39.740002,65.100395,-1293.506104,-0.003048,0.001866,0.047393,289.581024,14.751961,0.473929,-1293.506104,294.500488,0.000000
40.030003,65.542397,-1293.461548,-0.003053,0.001877,0.047672,291.547150,14.852119,0.476715,-1293.461548,294.500488,0.000000
40.320004,65.658943,-1293.461548,-0.003048,0.001888,0.047958,292.065552,14.878530,0.479576,-1293.461548,294.500488,0.000000
40.610001,65.380043,-1293.550537,-0.003044,0.001888,0.047949,290.824951,14.815329,0.479486,-1293.550537,294.500488,0.000000
40.900002,65.365150,-1293.550537,-0.003044,0.001894,0.048114,290.758698,14.811954,0.481136,-1293.550537,294.500488,0.000000
41.190002,65.171883,-1293.506104,-0.003018,0.001898,0.048200,289.899017,14.768160,0.481999,-1293.506104,294.500488,0.000000
41.480003,65.181190,-1293.506104,-0.003022,0.001903,0.048330,289.940430,14.770268,0.483301,-1293.506104,294.500488,0.000000
41.770000,65.330879,-1293.594971,-0.003009,0.001910,0.048512,290.606262,14.804189,0.485118,-1293.594971,294.500488,0.000000
42.060001,65.195351,-1293.594971,-0.003009,0.001914,0.048616,290.003418,14.773478,0.486162,-1293.594971,294.500488,0.000000
42.350002,65.126076,-1293.550537,-0.003005,0.001919,0.048737,289.695251,14.757779,0.487373,-1293.550537,294.500488,0.000000
42.640003,64.926491,-1293.506104,-0.003001,0.001925,0.048893,288.807465,14.712553,0.488933,-1293.506104,294.500488,0.000000
42.930000,64.996864,-1293.506104,-0.002988,0.001926,0.048928,289.120483,14.728499,0.489281,-1293.506104,294.500488,0.000000
43.220001,65.648155,-1293.550537,-0.002992,0.001938,0.049223,292.017578,14.876084,0.492233,-1293.550537,294.500488,0.000000
43.510002,65.286568,-1293.550537,-0.002984,0.001938,0.049232,290.409149,14.794147,0.492324,-1293.550537,294.500488,0.000000
43.800003,65.420631,-1293.594971,-0.002975,0.001945,0.049405,291.005493,14.824528,0.494050,-1293.594971,294.500488,0.000000
44.090004,65.056816,-1293.461548,-0.002953,0.001947,0.049466,289.387177,14.742085,0.494655,-1293.461548,294.500488,0.000000
44.380001,65.291420,-1293.506104,-0.002958,0.001952,0.049588,290.430756,14.795248,0.495882,-1293.506104,294.500488,0.000000
44.670002,65.318596,-1293.506104,-0.002966,0.001957,0.049718,290.551636,14.801406,0.497184,-1293.506104,294.500488,0.000000
44.960003,65.391579,-1293.461548,-0.002958,0.001963,0.049865,290.876282,14.817944,0.498652,-1293.461548,294.500488,0.000000
45.250004,65.131660,-1293.594971,-0.002953,0.001964,0.049882,289.720093,14.759045,0.498819,-1293.594971,294.500488,0.000000
45.540001,65.369987,-1293.506104,-0.002949,0.001971,0.050056,290.780212,14.813051,0.500560,-1293.506104,294.500488,0.000000
45.830002,65.305199,-1293.506104,-0.002945,0.001975,0.050168,290.492035,14.798369,0.501680,-1293.506104,294.500488,0.000000
46.120003,65.149910,-1293.594971,-0.002940,0.001979,0.050263,289.801270,14.763181,0.502634,-1293.594971,294.500488,0.000000
46.410004,65.170387,-1293.550537,-0.002932,0.001982,0.050342,289.892365,14.767821,0.503421,-1293.550537,294.500488,0.000000
46.700001,65.451164,-1293.594971,-0.002932,0.001988,0.050498,291.141327,14.831446,0.504981,-1293.594971,294.500488,0.000000
46.990002,65.213585,-1293.550537,-0.002923,0.001988,0.050498,290.084503,14.777609,0.504981,-1293.550537,294.500488,0.000000
47.280003,65.333122,-1293.506104,-0.002928,0.001994,0.050637,290.616241,14.804697,0.506374,-1293.506104,294.500488,0.000000
47.570004,65.156242,-1293.550537,-0.002910,0.001995,0.050672,289.829437,14.764615,0.506722,-1293.550537,294.500488,0.000000
47.860001,65.532341,-1293.461548,-0.002915,0.002002,0.050863,291.502411,14.849841,0.508629,-1293.461548,294.500488,0.000000
48.150002,65.275398,-1293.550537,-0.002906,0.002004,0.050898,290.359467,14.791616,0.508978,-1293.550537,294.500488,0.000000
48.440002,65.275780,-1293.506104,-0.002910,0.002007,0.050975,290.361176,14.791703,0.509750,-1293.506104,294.500488,0.000000
48.730003,65.195351,-1293.550537,-0.002910,0.002010,0.051045,290.003418,14.773478,0.510446,-1293.550537,294.500488,0.000000
49.020000,65.485054,-1293.550537,-0.002893,0.002016,0.051219,291.292053,14.839126,0.512187,-1293.550537,294.500488,0.000000
49.310001,65.267952,-1293.594971,-0.002893,0.002017,0.051244,290.326355,14.789929,0.512444,-1293.594971,294.500488,0.000000
49.600002,65.334618,-1293.594971,-0.002893,0.002022,0.051347,290.622894,14.805036,0.513474,-1293.594971,294.500488,0.000000
49.890003,65.441475,-1293.550537,-0.002884,0.002027,0.051496,291.098206,14.829250,0.514958,-1293.550537,294.500488,0.000000
50.180004,65.362907,-1293.594971,-0.002880,0.002027,0.051496,290.748718,14.811446,0.514958,-1293.594971,294.500488,0.000000
50.470001,65.213219,-1293.594971,-0.002876,0.002029,0.051547,290.082886,14.777527,0.515472,-1293.594971,294.500488,0.000000
50.760002,65.248589,-1293.506104,-0.002876,0.002033,0.051634,290.240204,14.785542,0.516335,-1293.506104,294.500488,0.000000
51.050003,65.193855,-1293.594971,-0.002876,0.002036,0.051712,289.996765,14.773139,0.517123,-1293.594971,294.500488,0.000000
51.340004,65.460838,-1293.506104,-0.002880,0.002041,0.051842,291.184357,14.833637,0.518425,-1293.506104,294.500488,0.000000
51.630001,65.208000,-1293.550537,-0.002863,0.002041,0.051842,290.059662,14.776343,0.518425,-1293.550537,294.500488,0.000000
51.920002,64.961861,-1293.594971,-0.002859,0.002041,0.051842,288.964783,14.720568,0.518425,-1293.594971,294.500488,0.000000
52.210003,65.771782,-1293.550537,-0.002859,0.002053,0.052138,292.567505,14.904099,0.521377,-1293.550537,294.500488,0.000000
52.500004,65.543877,-1293.550537,-0.002871,0.002053,0.052138,291.553711,14.852454,0.521377,-1293.550537,294.500488,0.000000
52.790001,65.293648,-1293.550537,-0.002850,0.002053,0.052138,290.440643,14.795753,0.521377,-1293.550537,294.500488,0.000000
53.080002,65.038200,-1293.594971,-0.002846,0.002053,0.052145,289.304352,14.737866,0.521453,-1293.594971,294.500488,0.000000
53.370003,64.768974,-1293.550537,-0.002846,0.002053,0.052145,288.106781,14.676860,0.521453,-1293.550537,294.500488,0.000000
53.660004,64.514275,-1293.506104,-0.002837,0.002053,0.052145,286.973816,14.619143,0.521453,-1293.506104,294.500488,0.000000
53.950001,64.268135,-1293.639526,-0.002846,0.002053,0.052154,285.878937,14.563368,0.521543,-1293.639526,294.500488,0.000000
54.240002,66.580193,-1293.550537,-0.002811,0.001893,0.048088,296.163483,15.087288,0.480878,-1293.550537,294.500488,0.000000
54.530003,66.229042,-1293.550537,-0.002815,0.001894,0.048104,294.601501,15.007715,0.481045,-1293.550537,294.500488,0.000000
54.820004,65.924446,-1293.550537,-0.002811,0.001898,0.048200,293.246582,14.938693,0.481999,-1293.550537,294.500488,0.000000
55.110004,65.601967,-1293.550537,-0.002798,0.001931,0.049058,291.812134,14.865618,0.490583,-1293.550537,294.500488,0.000000
55.400002,65.426216,-1293.550537,-0.002824,0.002047,0.051998,291.030334,14.825793,0.519984,-1293.550537,294.500488,0.000000
55.690002,65.170387,-1293.550537,-0.002811,0.002050,0.052077,289.892365,14.767821,0.520771,-1293.550537,294.500488,0.000000
55.980003,65.161079,-1293.550537,-0.002811,0.002072,0.052640,289.850952,14.765712,0.526403,-1293.550537,294.500488,0.000000
56.270004,65.287697,-1293.550537,-0.002811,0.002080,0.052831,290.414185,14.794403,0.528311,-1293.550537,294.500488,0.000000
56.560001,65.139122,-1293.506104,-0.002811,0.002080,0.052831,289.753296,14.760736,0.528311,-1293.506104,294.500488,0.000000
56.850002,65.330513,-1293.594971,-0.002815,0.002086,0.052978,290.604645,14.804106,0.529779,-1293.594971,294.500488,0.000000
57.140003,65.186775,-1293.506104,-0.002824,0.002086,0.052978,289.965271,14.771534,0.529779,-1293.506104,294.500488,0.000000
57.430004,65.403877,-1293.461548,-0.002811,0.002092,0.053134,290.930969,14.820731,0.531339,-1293.461548,294.500488,0.000000
57.720001,65.279869,-1293.550537,-0.002807,0.002092,0.053134,290.379364,14.792629,0.531339,-1293.550537,294.500488,0.000000
58.010002,65.098534,-1293.550537,-0.002811,0.002092,0.053143,289.572754,14.751538,0.531430,-1293.550537,294.500488,0.000000
58.300003,65.123100,-1293.550537,-0.002811,0.002096,0.053229,289.682007,14.757106,0.532292,-1293.550537,294.500488,0.000000
58.590004,65.104118,-1293.550537,-0.002794,0.002098,0.053291,289.597595,14.752804,0.532913,-1293.550537,294.500488,0.000000
58.880001,65.292152,-1293.550537,-0.002794,0.002102,0.053394,290.433990,14.795413,0.533943,-1293.550537,294.500488,0.000000
59.170002,65.159966,-1293.594971,-0.002794,0.002102,0.053403,289.846008,14.765460,0.534034,-1293.594971,294.500488,0.000000
59.460003,65.258644,-1293.461548,-0.002794,0.002107,0.053508,290.284943,14.787820,0.535078,-1293.461548,294.500488,0.000000
59.750004,65.149162,-1293.550537,-0.002794,0.002107,0.053508,289.797943,14.763011,0.535078,-1293.550537,294.500488,0.000000
60.040005,65.634377,-1293.550537,-0.002777,0.002115,0.053724,291.956299,14.872962,0.537243,-1293.550537,294.500488,0.000000
60.330002,65.535698,-1293.506104,-0.002781,0.002114,0.053689,291.517334,14.850601,0.536895,-1293.506104,294.500488,0.000000
60.620003,65.320091,-1293.506104,-0.002768,0.002114,0.053689,290.558289,14.801744,0.536895,-1293.506104,294.500488,0.000000
60.910004,65.111565,-1293.550537,-0.002777,0.002114,0.053689,289.630707,14.754492,0.536895,-1293.550537,294.500488,0.000000
61.200005,64.941765,-1293.594971,-0.002777,0.002114,0.053689,288.875397,14.716014,0.536895,-1293.594971,294.500488,0.000000
61.490002,65.824287,-1293.506104,-0.002759,0.002126,0.054001,292.801056,14.915997,0.540014,-1293.506104,294.500488,0.000000
61.780003,65.724113,-1293.506104,-0.002777,0.002126,0.054001,292.355469,14.893297,0.540014,-1293.506104,294.500488,0.000000
62.070004,65.542397,-1293.594971,-0.002755,0.002126,0.054001,291.547150,14.852119,0.540014,-1293.594971,294.500488,0.000000
62.360004,65.344292,-1293.506104,-0.002768,0.002126,0.054001,290.665924,14.807228,0.540014,-1293.506104,294.500488,0.000000
62.650002,65.192360,-1293.594971,-0.002777,0.002126,0.054001,289.990112,14.772799,0.540014,-1293.594971,294.500488,0.000000
62.940002,65.008415,-1293.461548,-0.002768,0.002126,0.054001,289.171875,14.731118,0.540014,-1293.461548,294.500488,0.000000
63.230003,64.827065,-1293.506104,-0.002755,0.002126,0.054001,288.365173,14.690022,0.540014,-1293.506104,294.500488,0.000000
63.520004,64.666954,-1293.550537,-0.002755,0.002126,0.054001,287.652985,14.653742,0.540014,-1293.550537,294.500488,0.000000
63.810001,66.567162,-1293.461548,-0.002759,0.002097,0.053257,296.105530,15.084334,0.532565,-1293.461548,294.500488,0.000000
64.100006,66.287514,-1293.639526,-0.002738,0.002097,0.053257,294.861603,15.020966,0.532565,-1293.639526,294.500488,0.000000
64.389999,66.063347,-1293.550537,-0.002742,0.002097,0.053257,293.864441,14.970169,0.532565,-1293.550537,294.500488,0.000000
64.680000,65.811241,-1293.550537,-0.002738,0.002100,0.053334,292.743011,14.913040,0.533337,-1293.550537,294.500488,0.000000
64.970001,65.619850,-1293.594971,-0.002734,0.002108,0.053534,291.891663,14.869671,0.535336,-1293.594971,294.500488,0.000000
65.260002,65.480202,-1293.506104,-0.002742,0.002119,0.053820,291.270477,14.838026,0.538197,-1293.506104,294.500488,0.000000
65.550003,65.289177,-1293.594971,-0.002746,0.002123,0.053924,290.420776,14.794740,0.539242,-1293.594971,294.500488,0.000000
65.840004,65.148430,-1293.506104,-0.002751,0.002130,0.054097,289.794678,14.762845,0.540967,-1293.506104,294.500488,0.000000
66.130005,65.436272,-1293.506104,-0.002738,0.002147,0.054531,291.075073,14.828072,0.545313,-1293.506104,294.500488,0.000000
66.420006,65.307793,-1293.594971,-0.002742,0.002147,0.054539,290.503571,14.798957,0.545388,-1293.594971,294.500488,0.000000
66.710007,65.346901,-1293.506104,-0.002742,0.002150,0.054608,290.677521,14.807819,0.546085,-1293.506104,294.500488,0.000000
67.000000,65.315254,-1293.639526,-0.002734,0.002152,0.054661,290.536774,14.800649,0.546615,-1293.639526,294.500488,0.000000
67.290001,65.317116,-1293.506104,-0.002734,0.002154,0.054704,290.545044,14.801069,0.547038,-1293.506104,294.500488,0.000000
67.580002,65.260887,-1293.594971,-0.002729,0.002155,0.054739,290.294922,14.788328,0.547387,-1293.594971,294.500488,0.000000
67.870003,65.266090,-1293.550537,-0.002725,0.002157,0.054799,290.318085,14.789508,0.547992,-1293.550537,294.500488,0.000000
68.160004,65.317848,-1293.550537,-0.002742,0.002159,0.054843,290.548309,14.801236,0.548431,-1293.550537,294.500488,0.000000
68.450005,65.303703,-1293.594971,-0.002725,0.002161,0.054878,290.485382,14.798031,0.548779,-1293.594971,294.500488,0.000000
68.740005,65.272057,-1293.506104,-0.002734,0.002162,0.054913,290.344604,14.790859,0.549128,-1293.506104,294.500488,0.000000
69.030006,65.246727,-1293.506104,-0.002734,0.002163,0.054948,290.231934,14.785120,0.549476,-1293.506104,294.500488,0.000000
69.320000,65.351738,-1293.594971,-0.002725,0.002166,0.055016,290.699036,14.808915,0.550157,-1293.594971,294.500488,0.000000
69.610001,65.296623,-1293.550537,-0.002725,0.002167,0.055043,290.453888,14.796426,0.550430,-1293.550537,294.500488,0.000000
69.900002,65.287697,-1293.594971,-0.002729,0.002169,0.055085,290.414185,14.794403,0.550854,-1293.594971,294.500488,0.000000
70.190002,65.259758,-1293.461548,-0.002708,0.002170,0.055120,290.289886,14.788073,0.551202,-1293.461548,294.500488,0.000000
70.480003,65.277260,-1293.550537,-0.002725,0.002171,0.055155,290.367767,14.792039,0.551550,-1293.550537,294.500488,0.000000
70.770004,65.301094,-1293.506104,-0.002699,0.002173,0.055199,290.473785,14.797440,0.551989,-1293.506104,294.500488,0.000000
71.060005,65.247841,-1293.506104,-0.002721,0.002174,0.055208,290.236877,14.785373,0.552080,-1293.506104,294.500488,0.000000
71.350006,65.132408,-1293.594971,-0.002708,0.002174,0.055208,289.723419,14.759214,0.552080,-1293.594971,294.500488,0.000000
71.640007,65.033730,-1293.506104,-0.002712,0.002174,0.055225,289.284485,14.736854,0.552246,-1293.506104,294.500488,0.000000
71.930000,64.949944,-1293.594971,-0.002721,0.002175,0.055250,288.911774,14.717868,0.552504,-1293.594971,294.500488,0.000000
72.220001,64.903404,-1293.506104,-0.002699,0.002176,0.055269,288.704773,14.707321,0.552685,-1293.506104,294.500488,0.000000
72.510002,64.836754,-1293.506104,-0.002703,0.002178,0.055329,288.408295,14.692219,0.553291,-1293.506104,294.500488,0.000000
72.800003,64.912712,-1293.594971,-0.002716,0.002179,0.055355,288.746155,14.709432,0.553548,-1293.594971,294.500488,0.000000
73.090004,64.840477,-1293.550537,-0.002703,0.002180,0.055364,288.424835,14.693062,0.553639,-1293.550537,294.500488,0.000000
73.380005,64.753334,-1293.594971,-0.002703,0.002180,0.055381,288.037201,14.673316,0.553806,-1293.594971,294.500488,0.000000
73.670006,65.917366,-1293.550537,-0.002690,0.002188,0.055571,293.215088,14.937089,0.555713,-1293.550537,294.500488,0.000000
73.960007,65.799706,-1293.550537,-0.002686,0.002188,0.055571,292.691711,14.910426,0.555713,-1293.550537,294.500488,0.000000
74.250000,65.621712,-1293.550537,-0.002690,0.002188,0.055571,291.899963,14.870092,0.555713,-1293.550537,294.500488,0.000000
74.540001,65.498451,-1293.550537,-0.002686,0.002188,0.055571,291.351654,14.842161,0.555713,-1293.550537,294.500488,0.000000
74.830002,65.327156,-1293.594971,-0.002695,0.002188,0.055571,290.589691,14.803345,0.555713,-1293.594971,294.500488,0.000000
75.120003,65.326042,-1293.550537,-0.002690,0.002194,0.055718,290.584747,14.803092,0.557182,-1293.550537,294.500488,0.000000
75.410004,65.259758,-1293.506104,-0.002703,0.002194,0.055727,290.289886,14.788073,0.557273,-1293.506104,294.500488,0.000000
75.700005,65.258278,-1293.550537,-0.002677,0.002195,0.055753,290.283325,14.787737,0.557530,-1293.550537,294.500488,0.000000
75.990005,65.264977,-1293.550537,-0.002677,0.002198,0.055841,290.313110,14.789255,0.558408,-1293.550537,294.500488,0.000000
76.280006,65.279503,-1293.594971,-0.002686,0.002198,0.055841,290.377716,14.792547,0.558408,-1293.594971,294.500488,0.000000
76.570007,65.212837,-1293.550537,-0.002682,0.002199,0.055848,290.081177,14.777440,0.558484,-1293.550537,294.500488,0.000000
76.860001,65.184914,-1293.506104,-0.002686,0.002200,0.055883,289.956970,14.771112,0.558832,-1293.506104,294.500488,0.000000
77.150002,65.210243,-1293.594971,-0.002686,0.002202,0.055927,290.069641,14.776852,0.559271,-1293.594971,294.500488,0.000000
77.440002,65.155876,-1293.550537,-0.002682,0.002202,0.055927,289.827820,14.764533,0.559271,-1293.550537,294.500488,0.000000
77.730003,65.190880,-1293.639526,-0.002686,0.002204,0.055988,289.983521,14.772465,0.559877,-1293.639526,294.500488,0.000000
78.020004,65.173744,-1293.550537,-0.002677,0.002205,0.056006,289.907288,14.768581,0.560058,-1293.550537,294.500488,0.000000
78.310005,65.150658,-1293.506104,-0.002677,0.002206,0.056039,289.804596,14.763350,0.560392,-1293.506104,294.500488,0.000000
78.600006,65.123848,-1293.639526,-0.002669,0.002207,0.056066,289.685333,14.757275,0.560664,-1293.639526,294.500488,0.000000
78.890007,65.129433,-1293.550537,-0.002669,0.002208,0.056092,289.710175,14.758540,0.560921,-1293.550537,294.500488,0.000000
79.180000,65.071709,-1293.506104,-0.002677,0.002211,0.056162,289.453430,14.745460,0.561618,-1293.506104,294.500488,0.000000
79.470001,65.191612,-1293.594971,-0.002673,0.002211,0.056162,289.986786,14.772631,0.561618,-1293.594971,294.500488,0.000000
79.760002,65.132790,-1293.550537,-0.002660,0.002211,0.056169,289.725128,14.759300,0.561694,-1293.550537,294.500488,0.000000
80.050003,65.760979,-1293.550537,-0.002652,0.002219,0.056369,292.519440,14.901651,0.563692,-1293.550537,294.500488,0.000000
80.340004,65.657829,-1293.550537,-0.002669,0.002219,0.056369,292.060608,14.878277,0.563692,-1293.550537,294.500488,0.000000
80.630005,65.579262,-1293.594971,-0.002669,0.002219,0.056369,291.711121,14.860474,0.563692,-1293.594971,294.500488,0.000000
80.920006,65.512230,-1293.461548,-0.002660,0.002219,0.056369,291.412964,14.845284,0.563692,-1293.461548,294.500488,0.000000
81.210007,65.383766,-1293.550537,-0.002660,0.002219,0.056369,290.841522,14.816174,0.563692,-1293.550537,294.500488,0.000000
81.500008,65.286568,-1293.550537,-0.002660,0.002219,0.056369,290.409149,14.794147,0.563692,-1293.550537,294.500488,0.000000
81.790001,65.227745,-1293.506104,-0.002669,0.002220,0.056378,290.147491,14.780818,0.563783,-1293.506104,294.500488,0.000000
82.080002,65.184166,-1293.550537,-0.002669,0.002221,0.056413,289.953644,14.770943,0.564131,-1293.550537,294.500488,0.000000
82.370003,65.140602,-1293.639526,-0.002660,0.002222,0.056439,289.759857,14.761071,0.564388,-1293.639526,294.500488,0.000000
82.660004,65.105598,-1293.550537,-0.002652,0.002223,0.056465,289.604156,14.753139,0.564646,-1293.550537,294.500488,0.000000
82.950005,65.027031,-1293.594971,-0.002639,0.002224,0.056483,289.254669,14.735335,0.564827,-1293.594971,294.500488,0.000000
83.240005,65.008781,-1293.594971,-0.002665,0.002224,0.056490,289.173492,14.731200,0.564903,-1293.594971,294.500488,0.000000
83.530006,64.982719,-1293.550537,-0.002647,0.002226,0.056543,289.057587,14.725295,0.565433,-1293.550537,294.500488,0.000000
83.820007,65.482063,-1293.594971,-0.002639,0.002232,0.056681,291.278778,14.838448,0.566811,-1293.594971,294.500488,0.000000
84.110001,65.441856,-1293.639526,-0.002660,0.002232,0.056681,291.099915,14.829336,0.566811,-1293.639526,294.500488,0.000000
84.400002,65.343925,-1293.594971,-0.002643,0.002232,0.056681,290.664307,14.807145,0.566811,-1293.594971,294.500488,0.000000
84.690002,65.288429,-1293.506104,-0.002639,0.002232,0.056681,290.417450,14.794570,0.566811,-1293.506104,294.500488,0.000000
84.980003,65.193474,-1293.550537,-0.002652,0.002232,0.056681,289.995056,14.773052,0.566811,-1293.550537,294.500488,0.000000
85.270004,65.116768,-1293.550537,-0.002634,0.002233,0.056716,289.653839,14.755671,0.567159,-1293.550537,294.500488,0.000000
85.560005,65.258644,-1293.550537,-0.002647,0.002238,0.056855,290.284943,14.787820,0.568552,-1293.550537,294.500488,0.000000
85.850006,65.466805,-1293.550537,-0.002639,0.002238,0.056855,291.210876,14.834991,0.568552,-1293.550537,294.500488,0.000000
86.140007,65.391212,-1293.594971,-0.002626,0.002238,0.056855,290.874634,14.817861,0.568552,-1293.594971,294.500488,0.000000
86.430000,65.315987,-1293.639526,-0.002647,0.002238,0.056855,290.540009,14.800814,0.568552,-1293.639526,294.500488,0.000000
86.720001,65.267204,-1293.461548,-0.002630,0.002239,0.056881,290.323029,14.789760,0.568809,-1293.461548,294.500488,0.000000
87.010002,65.276527,-1293.594971,-0.002634,0.002241,0.056916,290.364502,14.791872,0.569157,-1293.594971,294.500488,0.000000
87.300003,65.270561,-1293.639526,-0.002626,0.002242,0.056941,290.337952,14.790521,0.569415,-1293.639526,294.500488,0.000000
87.590004,65.278389,-1293.550537,-0.002630,0.002243,0.056967,290.372772,14.792295,0.569672,-1293.550537,294.500488,0.000000
87.880005,65.260139,-1293.594971,-0.002630,0.002243,0.056976,290.291595,14.788159,0.569763,-1293.594971,294.500488,0.000000
88.170006,65.245247,-1293.550537,-0.002639,0.002245,0.057011,290.225342,14.784784,0.570111,-1293.550537,294.500488,0.000000
88.460007,65.235558,-1293.550537,-0.002617,0.002246,0.057037,290.182251,14.782589,0.570369,-1293.550537,294.500488,0.000000
88.750008,65.222527,-1293.594971,-0.002634,0.002246,0.057046,290.124298,14.779635,0.570459,-1293.594971,294.500488,0.000000
89.040001,65.249702,-1293.550537,-0.002630,0.002248,0.057097,290.245178,14.785793,0.570974,-1293.550537,294.500488,0.000000
89.330002,65.241142,-1293.639526,-0.002630,0.002248,0.057106,290.207092,14.783854,0.571065,-1293.639526,294.500488,0.000000
89.620003,65.268333,-1293.550537,-0.002617,0.002250,0.057150,290.328033,14.790016,0.571504,-1293.550537,294.500488,0.000000
89.910004,65.247841,-1293.506104,-0.002634,0.002250,0.057158,290.236877,14.785373,0.571580,-1293.506104,294.500488,0.000000
90.200005,65.231834,-1293.594971,-0.002634,0.002251,0.057176,290.165680,14.781745,0.571761,-1293.594971,294.500488,0.000000
90.490005,65.216576,-1293.594971,-0.002630,0.002252,0.057193,290.097809,14.778287,0.571928,-1293.594971,294.500488,0.000000
90.780006,65.241524,-1293.594971,-0.002630,0.002253,0.057237,290.208801,14.783940,0.572367,-1293.594971,294.500488,0.000000
91.070007,65.210976,-1293.550537,-0.002621,0.002254,0.057246,290.072906,14.777019,0.572458,-1293.550537,294.500488,0.000000
91.360001,65.225883,-1293.594971,-0.002626,0.002255,0.057281,290.139221,14.780396,0.572806,-1293.594971,294.500488,0.000000
91.650002,65.199074,-1293.639526,-0.002630,0.002256,0.057306,290.019958,14.774321,0.573063,-1293.639526,294.500488,0.000000
91.940002,65.244499,-1293.550537,-0.002621,0.002257,0.057332,290.222015,14.784615,0.573321,-1293.550537,294.500488,0.000000
92.230003,65.232201,-1293.594971,-0.002626,0.002258,0.057358,290.167328,14.781828,0.573578,-1293.594971,294.500488,0.000000
92.520004,65.233330,-1293.550537,-0.002621,0.002259,0.057384,290.172333,14.782084,0.573835,-1293.550537,294.500488,0.000000
92.810005,65.328651,-1293.550537,-0.002630,0.002261,0.057437,290.596344,14.803684,0.574365,-1293.550537,294.500488,0.000000
93.100006,65.309288,-1293.639526,-0.002617,0.002262,0.057444,290.510223,14.799295,0.574441,-1293.639526,294.500488,0.000000
93.390007,65.312263,-1293.550537,-0.002613,0.002262,0.057462,290.523468,14.799971,0.574623,-1293.550537,294.500488,0.000000
93.680008,65.275398,-1293.550537,-0.002613,0.002263,0.057479,290.359467,14.791616,0.574789,-1293.550537,294.500488,0.000000
93.970001,65.221031,-1293.550537,-0.002604,0.002254,0.057246,290.117645,14.779297,0.572458,-1293.550537,0.057409,0.000000
94.260002,65.070976,-1293.550537,-0.002604,0.002249,0.057123,289.450165,14.745294,0.571231,-1293.550537,0.056925,0.000000
94.550003,64.975639,-1293.639526,-0.002604,0.002240,0.056890,289.026093,14.723690,0.568900,-1293.639526,0.056439,0.000000
94.840004,64.839348,-1293.594971,-0.002617,0.002231,0.056664,288.419830,14.692806,0.566644,-1293.594971,0.055962,0.000000
95.130005,64.666954,-1293.639526,-0.002596,0.002200,0.055892,287.652985,14.653742,0.558923,-1293.639526,0.055476,0.000000
95.420006,64.543312,-1293.594971,-0.002587,0.002187,0.055555,287.102997,14.625724,0.555547,-1293.594971,0.054990,0.000000
95.710007,64.485222,-1293.594971,-0.002591,0.002171,0.055155,286.844604,14.612560,0.551550,-1293.594971,0.054506,0.000000
96.000008,64.342979,-1293.683960,-0.002600,0.002146,0.054496,286.211853,14.580327,0.544964,-1293.683960,0.054027,0.000000
96.290001,64.254356,-1293.594971,-0.002596,0.002125,0.053985,285.817657,14.560245,0.539847,-1293.594971,0.053543,0.000000
96.580002,64.175407,-1293.639526,-0.002587,0.002115,0.053715,285.466461,14.542355,0.537152,-1293.639526,0.053057,0.000000
96.870003,64.093498,-1293.594971,-0.002600,0.002104,0.053447,285.102112,14.523794,0.534473,-1293.594971,0.052571,0.000000
97.160004,63.993690,-1293.639526,-0.002591,0.002076,0.052719,284.658142,14.501177,0.527190,-1293.639526,0.052094,0.000000
97.450005,63.762459,-1293.594971,-0.002583,0.002057,0.052241,283.629578,14.448780,0.522406,-1293.594971,0.051608,0.000000
97.740005,63.635841,-1293.639526,-0.002587,0.002045,0.051938,283.066345,14.420088,0.519378,-1293.639526,0.051123,0.000000
98.030006,63.016220,-1293.728516,-0.002583,0.002022,0.051356,280.310150,14.279679,0.513565,-1293.728516,0.050637,0.000000
98.320007,62.377228,-1293.594971,-0.002578,0.002000,0.050810,277.467773,14.134882,0.508099,-1293.594971,0.050160,0.000000
98.610008,61.587051,-1293.683960,-0.002591,0.001984,0.050386,273.952881,13.955825,0.503860,-1293.683960,0.049674,0.000000
98.900002,61.073921,-1293.594971,-0.002578,0.001973,0.050126,271.670380,13.839549,0.501256,-1293.594971,0.049188,0.000000
99.190002,59.529694,-1293.594971,-0.002570,0.001945,0.049397,264.801300,13.489621,0.493974,-1293.594971,0.048712,0.000000
99.480003,58.699677,-1293.639526,-0.002557,0.001930,0.049016,261.109192,13.301537,0.490159,-1293.639526,0.048226,0.000000
99.770004,57.633202,-1293.594971,-0.002570,0.001913,0.048590,256.365295,13.059870,0.485905,-1293.594971,0.047741,0.000000
100.060005,56.377563,-1293.594971,-0.002574,0.001897,0.048191,250.779922,12.775338,0.481908,-1293.594971,0.047255,0.000000
100.350006,54.744713,-1293.594971,-0.002574,0.001876,0.047653,243.516647,12.405329,0.476533,-1293.594971,0.046778,0.000000
100.640007,53.276070,-1293.683960,-0.002565,0.001859,0.047229,236.983795,12.072530,0.472294,-1293.683960,0.046292,0.000000
100.930008,51.714714,-1293.683960,-0.002583,0.001843,0.046804,230.038544,11.718721,0.468040,-1293.683960,0.045806,0.000000
101.220001,49.725502,-1293.594971,-0.002570,0.001821,0.046248,221.190079,11.267960,0.462484,-1293.594971,0.045320,0.000000
101.510002,48.259102,-1293.594971,-0.002583,0.001806,0.045885,214.667206,10.935669,0.458850,-1293.594971,0.044843,0.000000
101.800003,46.769234,-1293.683960,-0.002587,0.001788,0.045408,208.039948,10.598060,0.454081,-1293.683960,0.044359,0.000000
102.090004,44.276573,-1293.639526,-0.002596,0.001767,0.044887,196.952042,10.033215,0.448873,-1293.639526,0.043873,0.000000
102.380005,42.731606,-1293.639526,-0.002591,0.001751,0.044480,190.079681,9.683120,0.444801,-1293.639526,0.043387,0.000000
102.670006,40.892830,-1293.639526,-0.002591,0.001732,0.043994,181.900391,9.266448,0.439941,-1293.639526,0.042910,0.000000
102.960007,38.419525,-1293.683960,-0.002596,0.001708,0.043387,170.898590,8.705989,0.433870,-1293.683960,0.042424,0.000000
103.250008,36.580757,-1293.728516,-0.002591,0.001690,0.042927,162.719330,8.289318,0.429268,-1293.728516,0.041938,0.000000
103.540009,34.986252,-1293.639526,-0.002608,0.001672,0.042477,155.626617,7.927998,0.424771,-1293.639526,0.041454,0.000000
103.830002,32.957939,-1293.683960,-0.002604,0.001650,0.041912,146.604233,7.468376,0.419124,-1293.683960,0.040977,0.000000
104.120003,31.820343,-1293.594971,-0.002608,0.001638,0.041601,141.543961,7.210593,0.416005,-1293.594971,0.040491,0.000000
104.410004,29.588715,-1293.728516,-0.002613,0.001613,0.040968,131.617172,6.704899,0.409677,-1293.728516,0.040005,0.000000
104.700005,28.428032,-1293.594971,-0.002613,0.001600,0.040638,126.454201,6.441884,0.406377,-1293.594971,0.039528,0.000000
104.990005,26.086555,-1293.639526,-0.002626,0.001574,0.039979,116.038795,5.911298,0.399791,-1293.639526,0.039042,0.000000
105.280006,24.562057,-1293.639526,-0.002630,0.001560,0.039632,109.257492,5.565842,0.396324,-1293.639526,0.038556,0.000000
105.570007,22.940750,-1293.594971,-0.002630,0.001543,0.039181,102.045555,5.198448,0.391812,-1293.594971,0.038072,0.000000
105.860008,20.617516,-1293.728516,-0.002643,0.001519,0.038574,91.711288,4.671996,0.385741,-1293.728516,0.037595,0.000000
106.150002,19.047600,-1293.683960,-0.002647,0.001502,0.038140,84.727959,4.316247,0.381396,-1293.683960,0.037109,0.000000
106.440002,17.561089,-1293.728516,-0.002660,0.001486,0.037732,78.115623,3.979399,0.377324,-1293.728516,0.036623,0.000000
106.730003,16.230598,-1293.683960,-0.002652,0.001466,0.037239,72.197311,3.677906,0.372388,-1293.683960,0.036137,0.000000
107.020004,13.247147,-1293.639526,-0.002665,0.001438,0.036527,58.926250,3.001846,0.365273,-1293.639526,0.035660,0.000000
107.310005,12.178070,-1293.683960,-0.002682,0.001425,0.036190,54.170761,2.759590,0.361897,-1293.683960,0.035174,0.000000
107.600006,10.951843,-1293.639526,-0.002673,0.001412,0.035869,48.716232,2.481723,0.358687,-1293.639526,0.034689,0.000000
107.890007,8.692291,-1293.639526,-0.002695,0.001386,0.035201,38.665241,1.969701,0.352010,-1293.639526,0.034203,0.000000
108.180008,7.202057,-1293.728516,-0.002695,0.001369,0.034776,32.036350,1.632009,0.347756,-1293.728516,0.033726,0.000000
108.470009,5.955353,-1293.639526,-0.002708,0.001352,0.034334,26.490732,1.349502,0.343335,-1293.639526,0.033240,0.000000
108.760002,4.763390,-1293.728516,-0.002725,0.001340,0.034038,21.188616,1.079399,0.340383,-1293.728516,0.032754,0.000000
109.050003,2.700821,-1293.594971,-0.002721,0.001313,0.033352,12.013851,0.612015,0.333525,-1293.594971,0.032268,0.000000
109.340004,0.961838,-1293.683960,-0.002734,0.001292,0.032815,4.278468,0.217956,0.328150,-1293.683960,0.031792,0.000000
109.630005,-0.611809,-1293.683960,-0.002729,0.001272,0.032303,-2.721461,-0.138638,0.323033,-1293.683960,0.031307,0.000000
109.920006,-1.250053,-1293.683960,-0.002738,0.001259,0.031975,-5.560515,-0.283266,0.319748,-1293.683960,0.030821,0.000000
110.210007,-0.276299,-1293.683960,-0.002772,0.001236,0.031393,-1.229037,-0.062610,0.313934,-1293.683960,0.030344,0.000000
110.500008,-0.083038,-1293.728516,-0.002811,0.001217,0.030917,-0.369373,-0.018817,0.309165,-1293.728516,0.029858,0.000000
110.790009,-0.057716,-1293.728516,-0.002850,0.001192,0.030284,-0.256735,-0.013079,0.302837,-1293.728516,0.029372,0.000000
111.080002,-0.069633,-1293.639526,-0.002846,0.001177,0.029902,-0.309745,-0.015779,0.299022,-1293.639526,0.028886,0.000000
111.370003,0.001488,-1293.683960,-0.002876,0.001163,0.029546,0.006618,0.000337,0.295464,-1293.683960,0.028409,0.000000
111.660004,0.012291,-1293.728516,-0.002902,0.001145,0.029077,0.054673,0.002785,0.290771,-1293.728516,0.027925,0.000000
111.950005,-0.050270,-1293.639526,-0.002923,0.001125,0.028565,-0.223612,-0.011391,0.285654,-1293.639526,0.027439,0.000000
112.240005,-0.133682,-1293.728516,-0.002958,0.001101,0.027976,-0.594648,-0.030293,0.279764,-1293.728516,0.026953,0.000000
112.530006,-0.121765,-1293.683960,-0.002975,0.001084,0.027534,-0.541638,-0.027592,0.275344,-1293.683960,0.026476,0.000000
112.820007,-0.131821,-1293.683960,-0.003001,0.001062,0.026979,-0.586368,-0.029871,0.269787,-1293.683960,0.025990,0.000000
113.110008,-0.118790,-1293.728516,-0.003014,0.001047,0.026597,-0.528403,-0.026918,0.265972,-1293.728516,0.025504,0.000000
113.400009,-0.055481,-1293.550537,-0.003057,0.001030,0.026164,-0.246792,-0.012572,0.261642,-1293.550537,0.025020,0.000000
113.690002,-0.055855,-1293.728516,-0.003074,0.001009,0.025627,-0.248455,-0.012657,0.256268,-1293.728516,0.024543,0.000000
113.980003,-0.040215,-1293.639526,-0.003091,0.000990,0.025157,-0.178883,-0.009113,0.251574,-1293.639526,0.024057,0.000000
114.270004,-0.041336,-1293.594971,-0.003113,0.000975,0.024759,-0.183872,-0.009367,0.247593,-1293.594971,0.023571,0.000000
114.560005,-0.052132,-1293.728516,-0.003134,0.000950,0.024117,-0.231893,-0.011813,0.241174,-1293.728516,0.023085,0.000000
114.700005,-0.037239,-1293.772949,-0.003143,0.000948,0.024092,-0.165648,-0.008438,0.240916,-1293.772949,0.023943,0.000000