File: Data/Sima compression/P2-21-2_10302024_175954.csv
Time (sec),S:Load (lbs),S:HL1 (DIM),S:LVDT (in),S:Position (in),Ch:Position (mm),Ch:Load (N),Ch:Stress (MPa),Ch:Strain (mm/mm),Ch:HL1 (DIM),Set Point (),Cycles ()
0.210000,0.002235,-1293.372559,-0.004967,-0.004949,-0.125713,0.009944,0.000507,-1.257130,-1293.372559,-0.125506,0.000000
0.480000,-0.003349,-1293.417114,-0.004975,-0.004902,-0.124500,-0.014898,-0.000759,-1.245003,-1293.417114,-0.123980,0.000000
0.750000,0.010429,-1293.372559,-0.004937,-0.004745,-0.120528,0.046392,0.002363,-1.205277,-1293.372559,-0.119469,0.000000
1.020000,-0.032021,-1293.417114,-0.004769,-0.004569,-0.116062,-0.142435,-0.007256,-1.160615,-1293.417114,-0.114978,0.000000
1.290000,-0.027557,-1293.417114,-0.004566,-0.004395,-0.111630,-0.122581,-0.006245,-1.116302,-1293.417114,-0.110486,0.000000
1.560000,0.046547,-1293.417114,-0.004406,-0.004231,-0.107467,0.207051,0.010548,-1.074668,-1293.417114,-0.105976,0.000000
1.830000,0.137405,-1293.328125,-0.004286,-0.000008,-0.000191,0.611210,0.031137,-0.001908,-1293.328125,0.000009,0.000000
2.100000,0.135170,-1293.328125,-0.004307,-0.000008,-0.000191,0.601266,0.030630,-0.001908,-1293.328125,0.000009,0.000000
2.370000,0.127350,-1293.417114,-0.004303,-0.000008,-0.000198,0.566480,0.028858,-0.001983,-1293.417114,0.000200,0.000000
2.640000,0.140755,-1293.461548,-0.004303,-0.000008,-0.000191,0.626108,0.031895,-0.001908,-1293.461548,0.000651,0.000000
2.910000,0.123253,-1293.328125,-0.004299,-0.000008,-0.000191,0.548256,0.027929,-0.001908,-1293.328125,0.001102,0.000000
3.180000,0.250977,-1293.417114,-0.004290,0.000020,0.000504,1.116400,0.056872,0.005041,-1293.417114,0.001553,0.000000
3.450000,0.398811,-1293.372559,-0.004264,0.000043,0.001093,1.774001,0.090372,0.010931,-1293.372559,0.002004,0.000000
3.720000,0.560417,-1293.506104,-0.004247,0.000063,0.001605,2.492860,0.126992,0.016048,-1293.506104,0.002456,0.000000
3.990000,0.659843,-1293.461548,-0.004238,0.000077,0.001944,2.935130,0.149523,0.019439,-1293.461548,0.002898,0.000000
4.260000,0.808418,-1293.417114,-0.004221,0.000094,0.002386,3.596024,0.183190,0.023860,-1293.417114,0.003349,0.000000
4.530000,1.101479,-1293.372559,-0.004208,0.000114,0.002905,4.899621,0.249599,0.029053,-1293.372559,0.003799,0.000000
4.800000,1.402351,-1293.417114,-0.004191,0.000131,0.003331,6.237970,0.317777,0.033307,-1293.417114,0.004250,0.000000
5.070000,1.668602,-1293.417114,-0.004182,0.000148,0.003756,7.422312,0.378111,0.037561,-1293.417114,0.004701,0.000000
5.340000,2.017143,-1293.417114,-0.004156,0.000168,0.004275,8.972701,0.457091,0.042754,-1293.417114,0.005152,0.000000
5.610000,2.330681,-1293.461548,-0.004152,0.000180,0.004580,10.367386,0.528140,0.045797,-1293.461548,0.005603,0.000000
5.880000,2.753319,-1293.417114,-0.004139,0.000200,0.005091,12.247374,0.623911,0.050914,-1293.417114,0.006054,0.000000
6.150000,3.219162,-1293.417114,-0.004126,0.000216,0.005490,14.319548,0.729473,0.054896,-1293.417114,0.006505,0.000000
6.420000,3.821655,-1293.506104,-0.004118,0.000236,0.005994,16.999571,0.865999,0.059938,-1293.506104,0.006948,0.000000
6.690001,4.497887,-1293.506104,-0.004105,0.000253,0.006427,20.007599,1.019236,0.064268,-1293.506104,0.007399,0.000000
6.960001,4.628220,-1293.506104,-0.004083,0.000262,0.006643,20.587349,1.048770,0.066432,-1293.506104,0.007848,0.000000
7.230000,5.544998,-1293.461548,-0.004057,0.000281,0.007138,24.665384,1.256515,0.071383,-1293.461548,0.008300,0.000000
7.500000,6.771965,-1293.461548,-0.004061,0.000307,0.007806,30.123205,1.534549,0.078060,-1293.461548,0.008751,0.000000
7.770000,7.295891,-1293.506104,-0.004049,0.000321,0.008153,32.453743,1.653273,0.081527,-1293.506104,0.009202,0.000000
8.040000,8.192940,-1293.506104,-0.004031,0.000341,0.008664,36.444016,1.856547,0.086644,-1293.506104,0.009653,0.000000
8.310000,8.940292,-1293.461548,-0.004036,0.000357,0.009063,39.768406,2.025899,0.090626,-1293.461548,0.010104,0.000000
8.580001,9.935272,-1293.417114,-0.004031,0.000376,0.009558,44.194298,2.251365,0.095576,-1293.417114,0.010555,0.000000
8.850000,10.514679,-1293.417114,-0.004010,0.000390,0.009913,46.771629,2.382660,0.099134,-1293.417114,0.010997,0.000000
9.120001,11.216972,-1293.417114,-0.004010,0.000405,0.010286,49.895584,2.541802,0.102858,-1293.417114,0.011449,0.000000
9.390000,12.681892,-1293.461548,-0.003980,0.000431,0.010937,56.411877,2.873758,0.109368,-1293.461548,0.011900,0.000000
9.660001,13.586006,-1293.506104,-0.003971,0.000447,0.011361,60.433575,3.078633,0.113607,-1293.506104,0.012349,0.000000
9.930000,14.618225,-1293.417114,-0.003958,0.000469,0.011916,65.025116,3.312537,0.119164,-1293.417114,0.012801,0.000000
10.200001,14.931763,-1293.461548,-0.003958,0.000478,0.012133,66.419800,3.383586,0.121329,-1293.461548,0.013252,0.000000
10.470000,16.038078,-1293.506104,-0.003941,0.000497,0.012628,71.340935,3.634281,0.126279,-1293.506104,0.013703,0.000000
10.740001,17.183502,-1293.506104,-0.003936,0.000516,0.013112,76.436035,3.893837,0.131124,-1293.506104,0.014154,0.000000
11.010000,17.791214,-1293.506104,-0.003915,0.000529,0.013426,79.139275,4.031547,0.134258,-1293.506104,0.014605,0.000000
11.280001,19.151863,-1293.461548,-0.003898,0.000552,0.014033,85.191742,4.339874,0.140329,-1293.461548,0.015056,0.000000
11.550000,20.354996,-1293.461548,-0.003898,0.000574,0.014570,90.543541,4.612508,0.145703,-1293.461548,0.015498,0.000000
11.820001,21.003670,-1293.461548,-0.003893,0.000586,0.014891,93.428986,4.759500,0.148913,-1293.461548,0.015950,0.000000
12.090000,22.267876,-1293.550537,-0.003876,0.000609,0.015473,99.052460,5.045973,0.154727,-1293.550537,0.016399,0.000000
12.360001,23.263222,-1293.461548,-0.003859,0.000629,0.015966,103.479980,5.271522,0.159662,-1293.461548,0.016850,0.000000
12.630001,24.115585,-1293.461548,-0.003850,0.000645,0.016392,107.271484,5.464670,0.163916,-1293.461548,0.017302,0.000000
12.900001,24.608604,-1293.417114,-0.003846,0.000657,0.016687,109.464539,5.576389,0.166868,-1293.417114,0.017753,0.000000
13.170001,26.009102,-1293.461548,-0.003842,0.000684,0.017362,115.694260,5.893747,0.173621,-1293.461548,0.018204,0.000000
13.440001,26.887901,-1293.461548,-0.003816,0.000698,0.017736,119.603355,6.092885,0.177360,-1293.461548,0.018655,0.000000
13.710001,27.382782,-1293.461548,-0.003807,0.000711,0.018048,121.804695,6.205027,0.180479,-1293.461548,0.019106,0.000000
13.980000,28.441063,-1293.506104,-0.003798,0.000729,0.018525,126.512169,6.444837,0.185248,-1293.506104,0.019548,0.000000
14.250001,29.466202,-1293.461548,-0.003781,0.000753,0.019114,131.072205,6.677136,0.191137,-1293.461548,0.019999,0.000000
14.520000,30.581833,-1293.461548,-0.003760,0.000769,0.019522,136.034790,6.929942,0.195225,-1293.461548,0.020451,0.000000
14.790001,31.242424,-1293.461548,-0.003764,0.000785,0.019930,138.973236,7.079634,0.199297,-1293.461548,0.020900,0.000000
15.060000,31.326202,-1293.506104,-0.003747,0.000796,0.020216,139.345901,7.098619,0.202159,-1293.506104,0.021351,0.000000
15.330001,33.243179,-1293.417114,-0.003734,0.000823,0.020909,147.873047,7.533012,0.209093,-1293.417114,0.021803,0.000000
15.600000,33.680344,-1293.372559,-0.003742,0.000837,0.021256,149.817657,7.632075,0.212560,-1293.372559,0.022254,0.000000
15.870001,34.358437,-1293.506104,-0.003708,0.000852,0.021647,152.833954,7.785733,0.216466,-1293.506104,0.022705,0.000000
16.140001,35.277451,-1293.461548,-0.003708,0.000870,0.022089,156.921936,7.993985,0.220886,-1293.461548,0.023156,0.000000
16.410000,36.417282,-1293.461548,-0.003695,0.000893,0.022670,161.992157,8.252275,0.226700,-1293.461548,0.023598,0.000000
16.680000,36.550964,-1293.417114,-0.003673,0.000904,0.022956,162.586807,8.282567,0.229561,-1293.417114,0.024049,0.000000
16.950001,37.423431,-1293.417114,-0.003669,0.000917,0.023303,166.467743,8.480270,0.233028,-1293.417114,0.024500,0.000000
17.220001,39.170601,-1293.461548,-0.003648,0.000945,0.024014,174.239532,8.876185,0.240144,-1293.461548,0.024950,0.000000
17.490002,39.463661,-1293.461548,-0.003643,0.000957,0.024317,175.543137,8.942593,0.243172,-1293.461548,0.025401,0.000000
17.760000,40.502205,-1293.550537,-0.003630,0.000980,0.024882,180.162811,9.177931,0.248819,-1293.550537,0.025852,0.000000
18.030001,40.708504,-1293.461548,-0.003609,0.000993,0.025229,181.080475,9.224678,0.252286,-1293.461548,0.026304,0.000000
18.300001,41.487137,-1293.461548,-0.003591,0.001007,0.025584,184.544006,9.401120,0.255844,-1293.461548,0.026755,0.000000
18.570002,42.187195,-1293.461548,-0.003583,0.001024,0.026017,187.658020,9.559755,0.260174,-1293.461548,0.027206,0.000000
18.840000,42.643349,-1293.461548,-0.003561,0.001040,0.026417,189.687088,9.663121,0.264171,-1293.461548,0.027657,0.000000
19.110001,44.437439,-1293.461548,-0.003561,0.001069,0.027162,197.667603,10.069668,0.271619,-1293.461548,0.028099,0.000000
19.380001,44.985199,-1293.417114,-0.003540,0.001086,0.027596,200.104156,10.193791,0.275964,-1293.417114,0.028550,0.000000
19.650002,45.459229,-1293.461548,-0.003531,0.001101,0.027969,202.212753,10.301208,0.279689,-1293.461548,0.029001,0.000000
19.920000,46.126152,-1293.417114,-0.003523,0.001119,0.028428,205.179367,10.452335,0.284276,-1293.417114,0.029451,0.000000
20.190001,46.685081,-1293.506104,-0.003514,0.001138,0.028906,207.665619,10.578991,0.289060,-1293.506104,0.029902,0.000000
20.460001,47.253693,-1293.506104,-0.003484,0.001150,0.029209,210.194916,10.707840,0.292088,-1293.506104,0.030353,0.000000
20.730001,47.743736,-1293.461548,-0.003466,0.001168,0.029660,212.374741,10.818885,0.296600,-1293.461548,0.030805,0.000000
21.000002,49.133804,-1293.417114,-0.003458,0.001192,0.030267,218.558075,11.133880,0.302670,-1293.417114,0.031256,0.000000
21.270000,49.511391,-1293.461548,-0.003449,0.001206,0.030639,220.237671,11.219441,0.306395,-1293.461548,0.031707,0.000000
21.540001,50.235283,-1293.461548,-0.003441,0.001225,0.031109,223.457703,11.383477,0.311088,-1293.461548,0.032149,0.000000
21.810001,50.750267,-1293.506104,-0.003419,0.001242,0.031551,225.748459,11.500175,0.315509,-1293.506104,0.032600,0.000000
22.080002,51.446976,-1293.417114,-0.003406,0.001259,0.031967,228.847580,11.658051,0.319672,-1293.417114,0.033051,0.000000
22.350000,51.972397,-1293.372559,-0.003380,0.001276,0.032409,231.184769,11.777113,0.324093,-1293.372559,0.033501,0.000000
22.620001,52.318703,-1293.417114,-0.003380,0.001290,0.032756,232.725220,11.855588,0.327560,-1293.417114,0.033952,0.000000
22.890001,52.821404,-1293.372559,-0.003367,0.001314,0.033372,234.961334,11.969501,0.333722,-1293.372559,0.034403,0.000000
23.160002,53.805214,-1293.550537,-0.003359,0.001327,0.033693,239.337540,12.192436,0.336931,-1293.550537,0.034854,0.000000
23.430000,54.686989,-1293.417114,-0.003333,0.001350,0.034282,243.259872,12.392249,0.342821,-1293.417114,0.035306,0.000000
23.700001,54.849716,-1293.461548,-0.003324,0.001362,0.034586,243.983719,12.429123,0.345864,-1293.461548,0.035757,0.000000
23.970001,56.261383,-1293.417114,-0.003311,0.001387,0.035236,250.263138,12.749012,0.352359,-1293.417114,0.036199,0.000000
24.240002,56.603592,-1293.417114,-0.003298,0.001403,0.035636,251.785355,12.826558,0.356355,-1293.417114,0.036650,0.000000
24.510000,56.932770,-1293.506104,-0.003277,0.001416,0.035973,253.249603,12.901151,0.359732,-1293.506104,0.037101,0.000000
24.780001,57.942276,-1293.417114,-0.003264,0.001441,0.036606,257.740112,13.129908,0.366060,-1293.417114,0.037552,0.000000
25.050001,58.848625,-1293.372559,-0.003247,0.001460,0.037092,261.771759,13.335289,0.370920,-1293.372559,0.038002,0.000000
25.320002,59.198288,-1293.372559,-0.003238,0.001475,0.037464,263.327148,13.414524,0.374644,-1293.372559,0.038453,0.000000
25.590002,59.536774,-1293.461548,-0.003234,0.001490,0.037838,264.832794,13.491225,0.378384,-1293.461548,0.038904,0.000000
25.860001,60.252846,-1293.461548,-0.003212,0.001510,0.038350,268.018036,13.653490,0.383501,-1293.461548,0.039355,0.000000
26.130001,61.121590,-1293.417114,-0.003208,0.001529,0.038844,271.882416,13.850350,0.388436,-1293.417114,0.039806,0.000000
26.400002,60.634155,-1293.417114,-0.003182,0.001537,0.039043,269.714203,13.739896,0.390435,-1293.417114,0.040258,0.000000
26.670002,61.550560,-1293.372559,-0.003156,0.001559,0.039607,273.790558,13.947556,0.396067,-1293.372559,0.040700,0.000000
26.940001,62.805458,-1293.417114,-0.003156,0.001579,0.040102,279.372620,14.231920,0.401017,-1293.417114,0.041151,0.000000
27.210001,63.212837,-1293.461548,-0.003139,0.001598,0.040586,281.184753,14.324233,0.405862,-1293.461548,0.041602,0.000000
27.480001,63.884224,-1293.461548,-0.003117,0.001614,0.040995,284.171234,14.476372,0.409950,-1293.461548,0.042053,0.000000
27.750002,64.620033,-1293.372559,-0.003109,0.001634,0.041514,287.444275,14.643108,0.415142,-1293.372559,0.042503,0.000000
28.020000,65.179710,-1293.417114,-0.003100,0.001650,0.041914,289.933838,14.769934,0.419139,-1293.417114,0.042954,0.000000
28.290001,64.962608,-1293.417114,-0.003109,0.001659,0.042140,288.968109,14.720737,0.421395,-1293.417114,0.043405,0.000000
28.560001,65.534203,-1293.506104,-0.003087,0.001677,0.042598,291.510681,14.850263,0.425982,-1293.506104,0.043856,0.000000
28.830002,66.393272,-1293.506104,-0.003053,0.001688,0.042868,295.332031,15.044930,0.428677,-1293.506104,0.043102,0.000000
29.100002,65.194221,-1293.417114,-0.003053,0.001688,0.042868,289.998383,14.773222,0.428677,-1293.417114,0.007548,0.000000
29.370001,65.461586,-1293.417114,-0.003035,0.001703,0.043258,291.187683,14.833807,0.432583,-1293.417114,294.500488,0.000000
29.640001,65.127937,-1293.417114,-0.003040,0.001711,0.043466,289.703522,14.758202,0.434657,-1293.417114,294.500488,0.000000
29.910002,65.272789,-1293.550537,-0.003031,0.001722,0.043744,290.347870,14.791025,0.437443,-1293.550537,294.500488,0.000000
30.180002,65.175606,-1293.461548,-0.003009,0.001729,0.043917,289.915588,14.769003,0.439169,-1293.461548,294.500488,0.000000
30.450001,65.196083,-1293.417114,-0.003009,0.001740,0.044194,290.006653,14.773643,0.441939,-1293.417114,294.500488,0.000000
30.720001,65.096657,-1293.417114,-0.003014,0.001745,0.044333,289.564392,14.751113,0.443332,-1293.417114,294.500488,0.000000
30.990002,65.432915,-1293.328125,-0.002988,0.001756,0.044594,291.060150,14.827311,0.445936,-1293.328125,294.500488,0.000000
31.260002,65.097038,-1293.461548,-0.002975,0.001760,0.044706,289.566101,14.751200,0.447057,-1293.461548,294.500488,0.000000
31.530001,65.065758,-1293.506104,-0.002988,0.001767,0.044880,289.426941,14.744112,0.448798,-1293.506104,294.500488,0.000000
31.800001,65.623192,-1293.417114,-0.002971,0.001779,0.045183,291.906525,14.870428,0.451826,-1293.417114,294.500488,0.000000
32.070000,64.982353,-1293.372559,-0.002962,0.001779,0.045183,289.055939,14.725212,0.451826,-1293.372559,294.500488,0.000000
32.340000,64.361229,-1293.461548,-0.002945,0.001779,0.045192,286.293030,14.584463,0.451916,-1293.461548,294.500488,0.000000
32.610001,68.556374,-1293.461548,-0.002923,0.001669,0.042400,304.953979,15.535096,0.423999,-1293.461548,294.500488,0.000000
32.880001,66.707542,-1293.506104,-0.002906,0.001625,0.041263,296.729980,15.116145,0.412629,-1293.506104,294.500488,0.000000
33.150002,65.940468,-1293.461548,-0.002906,0.001618,0.041090,293.317841,14.942324,0.410903,-1293.461548,294.500488,0.000000
33.420002,65.257530,-1293.461548,-0.002919,0.001725,0.043805,290.279999,14.787567,0.438049,-1293.461548,294.500488,0.000000
33.690002,64.881813,-1293.417114,-0.002919,0.001803,0.045808,288.608704,14.702429,0.458078,-1293.417114,294.500488,0.000000
33.960003,65.347649,-1293.372559,-0.002910,0.001821,0.046259,290.680847,14.807989,0.462590,-1293.372559,294.500488,0.000000
34.230003,65.046028,-1293.417114,-0.002906,0.001825,0.046354,289.339172,14.739640,0.463544,-1293.417114,294.500488,0.000000
34.500000,65.203911,-1293.506104,-0.002884,0.001833,0.046562,290.041473,14.775417,0.465618,-1293.506104,294.500488,0.000000
34.770000,65.214333,-1293.417114,-0.002884,0.001838,0.046675,290.087830,14.777779,0.466753,-1293.417114,294.500488,0.000000
35.040001,65.494728,-1293.372559,-0.002902,0.001846,0.046892,291.335114,14.841318,0.468918,-1293.372559,294.500488,0.000000
35.310001,65.088478,-1293.417114,-0.002897,0.001846,0.046892,289.528015,14.749260,0.468918,-1293.417114,294.500488,0.000000
35.580002,65.477974,-1293.506104,-0.002902,0.001856,0.047134,291.260590,14.837522,0.471341,-1293.506104,294.500488,0.000000
35.850002,65.065010,-1293.417114,-0.002867,0.001858,0.047204,289.423615,14.743942,0.472037,-1293.417114,294.500488,0.000000
36.120003,65.108208,-1293.417114,-0.002871,0.001865,0.047378,289.615784,14.753730,0.473778,-1293.417114,294.500488,0.000000
36.390003,65.120491,-1293.461548,-0.002880,0.001867,0.047420,289.670410,14.756514,0.474202,-1293.461548,294.500488,0.000000
36.660000,64.951805,-1293.461548,-0.002871,0.001871,0.047516,288.920044,14.718289,0.475156,-1293.461548,294.500488,0.000000
36.930000,64.934685,-1293.417114,-0.002859,0.001877,0.047664,288.843903,14.714410,0.476639,-1293.417114,294.500488,0.000000
37.200001,64.889626,-1293.461548,-0.002854,0.001878,0.047690,288.643463,14.704200,0.476897,-1293.461548,294.500488,0.000000
37.470001,65.278755,-1293.461548,-0.002846,0.001885,0.047871,290.374420,14.792377,0.478714,-1293.461548,294.500488,0.000000
37.740002,64.906013,-1293.417114,-0.002850,0.001885,0.047880,288.716370,14.707913,0.478804,-1293.417114,294.500488,0.000000
38.010002,65.158852,-1293.372559,-0.002833,0.001892,0.048045,289.841034,14.765207,0.480455,-1293.372559,294.500488,0.000000
38.280003,64.805092,-1293.506104,-0.002824,0.001892,0.048045,288.267456,14.685044,0.480455,-1293.506104,294.500488,0.000000
38.550003,65.477974,-1293.461548,-0.002828,0.001901,0.048297,291.260590,14.837522,0.482968,-1293.461548,294.500488,0.000000
38.820004,65.099648,-1293.417114,-0.002798,0.001901,0.048297,289.577698,14.751791,0.482968,-1293.417114,294.500488,0.000000
39.090000,64.749992,-1293.372559,-0.002820,0.001901,0.048297,288.022339,14.672558,0.482968,-1293.372559,294.500488,0.000000
39.360001,66.266289,-1293.328125,-0.002811,0.001880,0.047741,294.767181,15.016155,0.477412,-1293.328125,294.500488,0.000000
39.630001,65.787041,-1293.506104,-0.002802,0.001880,0.047750,292.635376,14.907557,0.477502,-1293.506104,294.500488,0.000000
39.900002,65.429939,-1293.417114,-0.002794,0.001883,0.047837,291.046906,14.826636,0.478365,-1293.417114,294.500488,0.000000
40.170002,65.167046,-1293.372559,-0.002802,0.001915,0.048634,289.877502,14.767064,0.486344,-1293.372559,294.500488,0.000000
40.440002,65.375206,-1293.372559,-0.002794,0.001923,0.048843,290.803436,14.814233,0.488433,-1293.372559,294.500488,0.000000
40.710003,65.241524,-1293.417114,-0.002802,0.001926,0.048921,290.208801,14.783940,0.489205,-1293.417114,294.500488,0.000000
40.980003,65.008781,-1293.417114,-0.002802,0.001926,0.048930,289.173492,14.731200,0.489296,-1293.417114,294.500488,0.000000
41.250004,64.797279,-1293.461548,-0.002807,0.001928,0.048981,288.232697,14.683273,0.489811,-1293.461548,294.500488,0.000000
41.520000,64.870262,-1293.417114,-0.002777,0.001932,0.049076,288.557343,14.699812,0.490765,-1293.417114,294.500488,0.000000
41.790001,65.849602,-1293.372559,-0.002781,0.001945,0.049416,292.913666,14.921733,0.494156,-1293.372559,294.500488,0.000000
42.060001,65.604958,-1293.417114,-0.002777,0.001945,0.049416,291.825439,14.866296,0.494156,-1293.417114,294.500488,0.000000
42.330002,65.336098,-1293.461548,-0.002790,0.001946,0.049423,290.629486,14.805371,0.494232,-1293.461548,294.500488,0.000000
42.600002,65.056450,-1293.417114,-0.002785,0.001946,0.049423,289.385529,14.742002,0.494232,-1293.417114,294.500488,0.000000
42.870003,64.780525,-1293.417114,-0.002764,0.001946,0.049423,288.158173,14.679477,0.494232,-1293.417114,294.500488,0.000000
43.140003,66.004509,-1293.461548,-0.002772,0.001957,0.049702,293.602722,14.956835,0.497017,-1293.461548,294.500488,0.000000
43.410004,65.652992,-1293.461548,-0.002764,0.001957,0.049702,292.039093,14.877180,0.497017,-1293.461548,294.500488,0.000000
43.680000,65.341316,-1293.506104,-0.002755,0.001957,0.049711,290.652679,14.806554,0.497108,-1293.506104,294.500488,0.000000
43.950001,65.031120,-1293.506104,-0.002764,0.001957,0.049711,289.272858,14.736262,0.497108,-1293.506104,294.500488,0.000000
44.220001,66.149361,-1293.506104,-0.002759,0.001968,0.049988,294.247040,14.989659,0.499879,-1293.506104,294.500488,0.000000
44.490002,65.831734,-1293.417114,-0.002755,0.001967,0.049970,292.834167,14.917685,0.499697,-1293.417114,294.500488,0.000000
44.760002,65.521538,-1293.461548,-0.002755,0.001967,0.049970,291.454346,14.847392,0.499697,-1293.461548,294.500488,0.000000
45.030003,65.226997,-1293.461548,-0.002751,0.001967,0.049970,290.144165,14.780648,0.499697,-1293.461548,294.500488,0.000000
45.300003,65.269447,-1293.417114,-0.002768,0.001976,0.050179,290.333008,14.790268,0.501786,-1293.417114,294.500488,0.000000
45.570004,65.085869,-1293.417114,-0.002746,0.001976,0.050179,289.516418,14.748669,0.501786,-1293.417114,294.500488,0.000000
45.840004,65.029640,-1293.417114,-0.002755,0.001979,0.050256,289.266296,14.735928,0.502558,-1293.417114,294.500488,0.000000
46.110001,65.351738,-1293.417114,-0.002742,0.001984,0.050395,290.699036,14.808915,0.503951,-1293.417114,294.500488,0.000000
46.380001,65.197945,-1293.372559,-0.002751,0.001984,0.050395,290.014954,14.774065,0.503951,-1293.372559,294.500488,0.000000
46.650002,65.095543,-1293.506104,-0.002738,0.001987,0.050481,289.559448,14.750860,0.504814,-1293.506104,294.500488,0.000000
46.920002,65.210243,-1293.461548,-0.002742,0.001990,0.050534,290.069641,14.776852,0.505344,-1293.461548,294.500488,0.000000
47.190002,65.230721,-1293.461548,-0.002729,0.001992,0.050604,290.160736,14.781493,0.506040,-1293.461548,294.500488,0.000000
47.460003,65.243004,-1293.417114,-0.002725,0.001995,0.050665,290.215363,14.784276,0.506646,-1293.417114,294.500488,0.000000
47.730003,65.153633,-1293.372559,-0.002729,0.001996,0.050699,289.817841,14.764025,0.506994,-1293.372559,294.500488,0.000000
48.000004,65.310036,-1293.461548,-0.002738,0.002000,0.050802,290.513550,14.799465,0.508024,-1293.461548,294.500488,0.000000
48.270000,65.197212,-1293.417114,-0.002729,0.002001,0.050828,290.011688,14.773900,0.508281,-1293.417114,294.500488,0.000000
48.540001,65.253807,-1293.417114,-0.002712,0.002004,0.050898,290.263428,14.786724,0.508978,-1293.417114,294.500488,0.000000
48.810001,65.247108,-1293.417114,-0.002716,0.002006,0.050942,290.233643,14.785206,0.509417,-1293.417114,294.500488,0.000000
49.080002,65.217690,-1293.417114,-0.002721,0.002008,0.051011,290.102783,14.778540,0.510113,-1293.417114,294.500488,0.000000
49.350002,65.194603,-1293.461548,-0.002725,0.002009,0.051028,290.000092,14.773308,0.510280,-1293.461548,294.500488,0.000000
49.620003,65.175240,-1293.506104,-0.002716,0.002011,0.051089,289.913940,14.768920,0.510885,-1293.506104,294.500488,0.000000
49.890003,65.165932,-1293.461548,-0.002712,0.002013,0.051142,289.872528,14.766811,0.511415,-1293.461548,294.500488,0.000000
50.160004,65.292900,-1293.417114,-0.002708,0.002016,0.051202,290.437317,14.795583,0.512021,-1293.417114,294.500488,0.000000
50.430004,65.247475,-1293.417114,-0.002708,0.002018,0.051254,290.235260,14.785289,0.512535,-1293.417114,294.500488,0.000000
50.700001,65.305931,-1293.461548,-0.002721,0.002021,0.051323,290.495300,14.798535,0.513232,-1293.461548,294.500488,0.000000
50.970001,65.236671,-1293.461548,-0.002699,0.002021,0.051323,290.187195,14.782842,0.513232,-1293.461548,294.500488,0.000000
51.240002,65.500313,-1293.417114,-0.002695,0.002026,0.051470,291.359955,14.842584,0.514700,-1293.417114,294.500488,0.000000
51.510002,65.456383,-1293.417114,-0.002695,0.002026,0.051470,291.164520,14.832628,0.514700,-1293.417114,294.500488,0.000000
51.780003,65.285835,-1293.461548,-0.002721,0.002026,0.051470,290.405914,14.793983,0.514700,-1293.461548,294.500488,0.000000
52.050003,65.345787,-1293.506104,-0.002695,0.002029,0.051549,290.672577,14.807567,0.515488,-1293.506104,294.500488,0.000000
52.320004,65.260139,-1293.461548,-0.002686,0.002032,0.051600,290.291595,14.788159,0.516002,-1293.461548,294.500488,0.000000
52.590004,65.274284,-1293.372559,-0.002695,0.002032,0.051618,290.354523,14.791364,0.516184,-1293.372559,294.500488,0.000000
52.860001,65.328651,-1293.461548,-0.002695,0.002035,0.051679,290.596344,14.803684,0.516790,-1293.461548,294.500488,0.000000
53.130001,65.293648,-1293.372559,-0.002699,0.002036,0.051721,290.440643,14.795753,0.517213,-1293.372559,294.500488,0.000000
53.400002,65.303337,-1293.506104,-0.002695,0.002038,0.051765,290.483765,14.797948,0.517653,-1293.506104,294.500488,0.000000
53.670002,65.336479,-1293.461548,-0.002703,0.002040,0.051817,290.631165,14.805458,0.518167,-1293.461548,294.500488,0.000000
53.940002,65.292152,-1293.417114,-0.002686,0.002041,0.051852,290.433990,14.795413,0.518515,-1293.417114,294.500488,0.000000
54.210003,65.341316,-1293.461548,-0.002682,0.002043,0.051905,290.652679,14.806554,0.519045,-1293.461548,294.500488,0.000000
54.480003,65.303703,-1293.372559,-0.002690,0.002045,0.051939,290.485382,14.798031,0.519394,-1293.372559,294.500488,0.000000
54.750004,65.341682,-1293.506104,-0.002682,0.002047,0.051982,290.654327,14.806637,0.519817,-1293.506104,294.500488,0.000000
55.020004,65.310402,-1293.506104,-0.002686,0.002048,0.052017,290.515167,14.799548,0.520166,-1293.506104,294.500488,0.000000
55.290001,65.348763,-1293.417114,-0.002656,0.002050,0.052077,290.685822,14.808242,0.520771,-1293.417114,294.500488,0.000000
55.560001,65.319710,-1293.417114,-0.002673,0.002051,0.052095,290.556580,14.801658,0.520953,-1293.417114,294.500488,0.000000
55.830002,65.291786,-1293.417114,-0.002686,0.002052,0.052121,290.432373,14.795330,0.521210,-1293.417114,294.500488,0.000000
56.100002,65.212471,-1293.461548,-0.002673,0.002052,0.052130,290.079559,14.777357,0.521301,-1293.461548,294.500488,0.000000
56.370003,65.114159,-1293.461548,-0.002665,0.002054,0.052165,289.642242,14.755079,0.521649,-1293.461548,294.500488,0.000000
56.640003,65.104118,-1293.417114,-0.002660,0.002055,0.052198,289.597595,14.752804,0.521982,-1293.417114,294.500488,0.000000
56.910004,65.055702,-1293.461548,-0.002665,0.002057,0.052251,289.382202,14.741833,0.522512,-1293.461548,294.500488,0.000000
57.180004,65.038200,-1293.417114,-0.002669,0.002057,0.052260,289.304352,14.737866,0.522603,-1293.417114,294.500488,0.000000
57.450005,64.951805,-1293.417114,-0.002665,0.002057,0.052260,288.920044,14.718289,0.522603,-1293.417114,294.500488,0.000000
57.720001,64.950691,-1293.417114,-0.002669,0.002060,0.052312,288.915100,14.718037,0.523118,-1293.417114,294.500488,0.000000
57.990002,65.002449,-1293.372559,-0.002665,0.002062,0.052381,289.145325,14.729765,0.523814,-1293.372559,294.500488,0.000000
58.260002,64.969688,-1293.417114,-0.002647,0.002062,0.052381,288.999603,14.722342,0.523814,-1293.417114,294.500488,0.000000
58.530003,65.335732,-1293.417114,-0.002656,0.002079,0.052814,290.627838,14.805288,0.528144,-1293.417114,294.500488,0.000000
58.800003,66.132607,-1293.417114,-0.002656,0.002070,0.052589,294.172516,14.985863,0.525888,-1293.417114,294.500488,0.000000
59.070004,65.907326,-1293.417114,-0.002656,0.002070,0.052589,293.170441,14.934813,0.525888,-1293.417114,294.500488,0.000000
59.340004,65.765450,-1293.417114,-0.002656,0.002070,0.052589,292.539337,14.902664,0.525888,-1293.417114,294.500488,0.000000
59.610004,65.598625,-1293.461548,-0.002643,0.002070,0.052589,291.797272,14.864861,0.525888,-1293.461548,294.500488,0.000000
59.880001,65.479469,-1293.372559,-0.002656,0.002070,0.052589,291.267212,14.837860,0.525888,-1293.372559,294.500488,0.000000
60.150002,65.303703,-1293.372559,-0.002652,0.002071,0.052598,290.485382,14.798031,0.525979,-1293.372559,294.500488,0.000000
60.420002,65.160713,-1293.550537,-0.002656,0.002076,0.052719,289.849335,14.765629,0.527190,-1293.550537,294.500488,0.000000
60.690002,65.748695,-1293.417114,-0.002647,0.002081,0.052858,292.464813,14.898868,0.528583,-1293.417114,294.500488,0.000000
60.960003,65.601234,-1293.461548,-0.002639,0.002081,0.052858,291.808868,14.865452,0.528583,-1293.461548,294.500488,0.000000
61.230003,65.504417,-1293.372559,-0.002639,0.002081,0.052858,291.378204,14.843513,0.528583,-1293.372559,294.500488,0.000000
61.500004,65.367744,-1293.417114,-0.002643,0.002081,0.052858,290.770264,14.812542,0.528583,-1293.417114,294.500488,0.000000
61.770004,65.253059,-1293.417114,-0.002634,0.002081,0.052867,290.260101,14.786554,0.528674,-1293.417114,294.500488,0.000000
62.040005,65.119759,-1293.461548,-0.002634,0.002081,0.052867,289.667145,14.756349,0.528674,-1293.461548,294.500488,0.000000
62.310001,65.008781,-1293.417114,-0.002634,0.002081,0.052867,289.173492,14.731200,0.528674,-1293.417114,294.500488,0.000000
62.580002,64.878075,-1293.506104,-0.002643,0.002085,0.052954,288.592102,14.701582,0.529537,-1293.506104,294.500488,0.000000
62.850002,65.660805,-1293.461548,-0.002639,0.002092,0.053126,292.073853,14.878951,0.531263,-1293.461548,294.500488,0.000000
63.120003,65.575539,-1293.461548,-0.002639,0.002092,0.053126,291.694550,14.859629,0.531263,-1293.461548,294.500488,0.000000
63.390003,65.485420,-1293.506104,-0.002626,0.002092,0.053126,291.293701,14.839208,0.531263,-1293.506104,294.500488,0.000000
63.660004,65.369987,-1293.506104,-0.002643,0.002092,0.053126,290.780212,14.813051,0.531263,-1293.506104,294.500488,0.000000
63.930004,65.273170,-1293.417114,-0.002639,0.002092,0.053126,290.349548,14.791112,0.531263,-1293.417114,294.500488,0.000000
64.200005,65.152153,-1293.417114,-0.002621,0.002092,0.053126,289.811249,14.763689,0.531263,-1293.417114,294.500488,0.000000
64.470001,65.031502,-1293.506104,-0.002643,0.002092,0.053126,289.274567,14.736349,0.531263,-1293.506104,294.500488,0.000000
64.740005,64.934303,-1293.461548,-0.002617,0.002092,0.053126,288.842194,14.714324,0.531263,-1293.461548,294.500488,0.000000
65.010002,64.817009,-1293.461548,-0.002613,0.002092,0.053126,288.320465,14.687744,0.531263,-1293.461548,294.500488,0.000000
65.280006,64.716103,-1293.417114,-0.002617,0.002092,0.053126,287.871613,14.664879,0.531263,-1293.417114,294.500488,0.000000
65.550003,64.607368,-1293.417114,-0.002626,0.002092,0.053126,287.387939,14.640239,0.531263,-1293.417114,294.500488,0.000000
65.820000,66.413002,-1293.550537,-0.002617,0.002076,0.052719,295.419800,15.049401,0.527190,-1293.550537,294.500488,0.000000
66.090004,66.270760,-1293.461548,-0.002608,0.002076,0.052719,294.787048,15.017168,0.527190,-1293.461548,294.500488,0.000000
66.360001,66.114723,-1293.461548,-0.002591,0.002076,0.052719,294.092987,14.981810,0.527190,-1293.461548,294.500488,0.000000
66.630005,65.929665,-1293.417114,-0.002630,0.002076,0.052728,293.269806,14.939876,0.527281,-1293.417114,294.500488,0.000000
66.900002,65.840294,-1293.461548,-0.002608,0.002076,0.052737,292.872253,14.919623,0.527372,-1293.461548,294.500488,0.000000
67.170006,65.718147,-1293.461548,-0.002613,0.002076,0.052737,292.328918,14.891945,0.527372,-1293.461548,294.500488,0.000000
67.440002,65.583351,-1293.461548,-0.002604,0.002083,0.052919,291.729309,14.861400,0.529189,-1293.461548,294.500488,0.000000
67.710007,65.498085,-1293.506104,-0.002591,0.002085,0.052963,291.350037,14.842078,0.529628,-1293.506104,294.500488,0.000000
67.980003,65.367378,-1293.372559,-0.002604,0.002093,0.053154,290.768616,14.812459,0.531536,-1293.372559,294.500488,0.000000
68.250000,65.264610,-1293.461548,-0.002613,0.002098,0.053284,290.311493,14.789172,0.532838,-1293.461548,294.500488,0.000000
68.520004,65.206886,-1293.461548,-0.002613,0.002103,0.053412,290.054718,14.776092,0.534124,-1293.461548,294.500488,0.000000
68.790001,65.220299,-1293.506104,-0.002613,0.002109,0.053561,290.114380,14.779131,0.535608,-1293.506104,294.500488,0.000000
69.060005,65.177467,-1293.417114,-0.002600,0.002110,0.053603,289.923859,14.769425,0.536032,-1293.417114,294.500488,0.000000
69.330002,65.174858,-1293.417114,-0.002608,0.002111,0.053630,289.912262,14.768834,0.536304,-1293.417114,294.500488,0.000000
69.600006,65.174492,-1293.461548,-0.002613,0.002113,0.053665,289.910614,14.768751,0.536653,-1293.461548,294.500488,0.000000
69.870003,65.133522,-1293.461548,-0.002613,0.002113,0.053682,289.728363,14.759467,0.536819,-1293.461548,294.500488,0.000000
70.140007,65.310783,-1293.506104,-0.002617,0.002118,0.053794,290.516876,14.799635,0.537940,-1293.506104,294.500488,0.000000
70.410004,65.314873,-1293.461548,-0.002608,0.002118,0.053794,290.535065,14.800561,0.537940,-1293.461548,294.500488,0.000000
70.680000,65.258278,-1293.417114,-0.002613,0.002118,0.053794,290.283325,14.787737,0.537940,-1293.417114,294.500488,0.000000
70.950005,65.178215,-1293.461548,-0.002608,0.002118,0.053803,289.927185,14.769595,0.538030,-1293.461548,294.500488,0.000000
71.220001,65.134270,-1293.506104,-0.002608,0.002120,0.053838,289.731689,14.759637,0.538379,-1293.506104,294.500488,0.000000
71.490005,65.400887,-1293.506104,-0.002600,0.002124,0.053951,290.917664,14.820053,0.539514,-1293.506104,294.500488,0.000000
71.760002,65.361427,-1293.417114,-0.002587,0.002124,0.053951,290.742157,14.811111,0.539514,-1293.417114,294.500488,0.000000
72.030006,65.299980,-1293.417114,-0.002613,0.002124,0.053959,290.468811,14.797187,0.539590,-1293.417114,294.500488,0.000000
72.300003,65.257530,-1293.417114,-0.002596,0.002125,0.053977,290.279999,14.787567,0.539771,-1293.417114,294.500488,0.000000
72.570000,65.209496,-1293.461548,-0.002596,0.002125,0.053986,290.066315,14.776683,0.539862,-1293.461548,294.500488,0.000000
72.840004,65.161461,-1293.506104,-0.002596,0.002126,0.054012,289.852661,14.765799,0.540120,-1293.506104,294.500488,0.000000
73.110001,65.121239,-1293.461548,-0.002604,0.002127,0.054020,289.673737,14.756683,0.540195,-1293.461548,294.500488,0.000000
73.380005,65.249336,-1293.461548,-0.002608,0.002130,0.054098,290.243530,14.785711,0.540983,-1293.461548,294.500488,0.000000
73.650002,65.219917,-1293.372559,-0.002591,0.002130,0.054098,290.112671,14.779044,0.540983,-1293.372559,294.500488,0.000000
73.920006,65.164070,-1293.461548,-0.002596,0.002131,0.054124,289.864258,14.766389,0.541240,-1293.461548,294.500488,0.000000
74.190002,65.218437,-1293.461548,-0.002587,0.002132,0.054159,290.106110,14.778709,0.541588,-1293.461548,294.500488,0.000000
74.460007,65.181190,-1293.461548,-0.002587,0.002132,0.054159,289.940430,14.770268,0.541588,-1293.461548,294.500488,0.000000
74.730003,65.087730,-1293.372559,-0.002591,0.002132,0.054159,289.524689,14.749090,0.541588,-1293.372559,294.500488,0.000000
75.000000,65.017342,-1293.506104,-0.002587,0.002133,0.054168,289.211578,14.733141,0.541679,-1293.506104,294.500488,0.000000
75.270004,64.946602,-1293.506104,-0.002596,0.002133,0.054168,288.896912,14.717111,0.541679,-1293.506104,294.500488,0.000000
75.540001,65.590065,-1293.506104,-0.002583,0.002142,0.054410,291.759186,14.862921,0.544101,-1293.506104,294.500488,0.000000
75.810005,65.578514,-1293.461548,-0.002583,0.002141,0.054393,291.707794,14.860304,0.543935,-1293.461548,294.500488,0.000000
76.080002,65.545372,-1293.417114,-0.002578,0.002141,0.054393,291.560364,14.852794,0.543935,-1293.417114,294.500488,0.000000
76.350006,65.468285,-1293.417114,-0.002574,0.002141,0.054393,291.217468,14.835325,0.543935,-1293.417114,294.500488,0.000000
76.620003,65.355461,-1293.417114,-0.002587,0.002141,0.054393,290.715607,14.809759,0.543935,-1293.417114,294.500488,0.000000
76.890007,65.280983,-1293.506104,-0.002574,0.002141,0.054393,290.384308,14.792882,0.543935,-1293.506104,294.500488,0.000000
77.160004,65.213966,-1293.417114,-0.002583,0.002141,0.054393,290.086212,14.777697,0.543935,-1293.417114,294.500488,0.000000
77.430000,65.109703,-1293.461548,-0.002574,0.002141,0.054393,289.622437,14.754069,0.543935,-1293.461548,294.500488,0.000000
77.700005,65.028893,-1293.461548,-0.002583,0.002141,0.054393,289.262970,14.735758,0.543935,-1293.461548,294.500488,0.000000
77.970001,64.961861,-1293.461548,-0.002583,0.002141,0.054393,288.964783,14.720568,0.543935,-1293.461548,294.500488,0.000000
78.240005,64.879936,-1293.506104,-0.002583,0.002141,0.054393,288.600372,14.702003,0.543935,-1293.506104,294.500488,0.000000
78.510002,64.776802,-1293.461548,-0.002583,0.002141,0.054393,288.141602,14.678634,0.543935,-1293.461548,294.500488,0.000000
78.780006,64.716850,-1293.461548,-0.002574,0.002141,0.054393,287.874939,14.665048,0.543935,-1293.461548,294.500488,0.000000
79.050003,64.631950,-1293.417114,-0.002565,0.002141,0.054393,287.497284,14.645810,0.543935,-1293.417114,294.500488,0.000000
79.320007,66.653923,-1293.461548,-0.002565,0.002087,0.053014,296.491455,15.103994,0.530143,-1293.461548,294.500488,0.000000
79.590004,66.546684,-1293.594971,-0.002557,0.002085,0.052954,296.014435,15.079695,0.529537,-1293.594971,294.500488,0.000000
79.860001,66.406670,-1293.461548,-0.002548,0.002085,0.052970,295.391632,15.047966,0.529704,-1293.461548,294.500488,0.000000
80.130005,66.303154,-1293.461548,-0.002552,0.002085,0.052970,294.931152,15.024509,0.529704,-1293.461548,294.500488,0.000000
80.400002,66.182869,-1293.417114,-0.002557,0.002085,0.052970,294.396118,14.997252,0.529704,-1293.417114,294.500488,0.000000
80.670006,66.091637,-1293.417114,-0.002552,0.002085,0.052970,293.990295,14.976579,0.529704,-1293.417114,294.500488,0.000000
80.940002,65.987007,-1293.461548,-0.002544,0.002085,0.052970,293.524872,14.952869,0.529704,-1293.461548,294.500488,0.000000
81.210007,65.863380,-1293.461548,-0.002544,0.002093,0.053154,292.974945,14.924855,0.531536,-1293.461548,294.500488,0.000000
81.480003,65.820930,-1293.506104,-0.002548,0.002099,0.053326,292.786133,14.915236,0.533261,-1293.506104,294.500488,0.000000
81.750008,65.667519,-1293.461548,-0.002544,0.002115,0.053733,292.103699,14.880472,0.537334,-1293.461548,294.500488,0.000000
82.020004,65.584846,-1293.461548,-0.002548,0.002125,0.053986,291.735962,14.861739,0.539862,-1293.461548,294.500488,0.000000
82.290001,65.526756,-1293.594971,-0.002565,0.002126,0.054012,291.477570,14.848576,0.540120,-1293.594971,294.500488,0.000000
82.560005,65.433296,-1293.461548,-0.002548,0.002131,0.054133,291.061829,14.827397,0.541331,-1293.461548,294.500488,0.000000
82.830002,65.343178,-1293.372559,-0.002561,0.002133,0.054168,290.660980,14.806976,0.541679,-1293.372559,294.500488,0.000000
83.100006,65.267586,-1293.417114,-0.002557,0.002133,0.054168,290.324707,14.789846,0.541679,-1293.417114,294.500488,0.000000
83.370003,65.372215,-1293.461548,-0.002548,0.002156,0.054757,290.790131,14.813556,0.547568,-1293.461548,294.500488,0.000000
83.640007,65.332756,-1293.506104,-0.002544,0.002156,0.054775,290.614624,14.804614,0.547750,-1293.506104,294.500488,0.000000
83.910004,65.396049,-1293.550537,-0.002548,0.002161,0.054896,290.896149,14.818957,0.548961,-1293.550537,294.500488,0.000000
84.180000,65.373344,-1293.417114,-0.002548,0.002161,0.054896,290.795166,14.813812,0.548961,-1293.417114,294.500488,0.000000
84.450005,65.353600,-1293.417114,-0.002552,0.002163,0.054931,290.707336,14.809338,0.549309,-1293.417114,294.500488,0.000000
84.720001,65.353233,-1293.506104,-0.002557,0.002163,0.054948,290.705688,14.809255,0.549476,-1293.506104,294.500488,0.000000
84.990005,65.311516,-1293.461548,-0.002557,0.002164,0.054966,290.520142,14.799801,0.549658,-1293.461548,294.500488,0.000000
85.260002,65.309288,-1293.550537,-0.002561,0.002164,0.054975,290.510223,14.799295,0.549748,-1293.550537,294.500488,0.000000
85.530006,65.262367,-1293.461548,-0.002548,0.002164,0.054975,290.301514,14.788664,0.549748,-1293.461548,294.500488,0.000000
85.800003,65.210609,-1293.417114,-0.002565,0.002164,0.054975,290.071289,14.776936,0.549748,-1293.417114,294.500488,0.000000
86.070007,65.296623,-1293.461548,-0.002570,0.002167,0.055052,290.453888,14.796426,0.550521,-1293.461548,294.500488,0.000000
86.340004,65.264977,-1293.461548,-0.002539,0.002167,0.055052,290.313110,14.789255,0.550521,-1293.461548,294.500488,0.000000
86.610001,65.215828,-1293.506104,-0.002552,0.002167,0.055052,290.094482,14.778117,0.550521,-1293.506104,294.500488,0.000000
86.880005,65.148048,-1293.372559,-0.002548,0.002167,0.055052,289.792999,14.762759,0.550521,-1293.372559,294.500488,0.000000
87.150002,65.135017,-1293.417114,-0.002548,0.002168,0.055078,289.735016,14.759806,0.550778,-1293.417114,294.500488,0.000000
87.420006,65.421745,-1293.461548,-0.002552,0.002176,0.055261,291.010468,14.824780,0.552610,-1293.461548,294.500488,0.000000
87.690002,65.537178,-1293.461548,-0.002557,0.002174,0.055217,291.523926,14.850937,0.552171,-1293.461548,294.500488,0.000000
87.960007,65.477974,-1293.372559,-0.002552,0.002174,0.055217,291.260590,14.837522,0.552171,-1293.372559,294.500488,0.000000
88.230003,65.419518,-1293.417114,-0.002544,0.002174,0.055217,291.000549,14.824275,0.552171,-1293.417114,294.500488,0.000000
88.500008,65.347267,-1293.372559,-0.002561,0.002174,0.055217,290.679169,14.807902,0.552171,-1293.372559,294.500488,0.000000
88.770004,65.285454,-1293.506104,-0.002565,0.002174,0.055217,290.404205,14.793895,0.552171,-1293.506104,294.500488,0.000000
89.040001,65.231834,-1293.461548,-0.002548,0.002174,0.055217,290.165680,14.781745,0.552171,-1293.461548,294.500488,0.000000
89.310005,65.170387,-1293.461548,-0.002552,0.002174,0.055217,289.892365,14.767821,0.552171,-1293.461548,1681.640991,0.000000
89.580002,65.078041,-1293.417114,-0.002544,0.002167,0.055052,289.481598,14.746895,0.550521,-1293.417114,0.055113,0.000000
89.850006,64.975273,-1293.417114,-0.002539,0.002160,0.054861,289.024445,14.723607,0.548613,-1293.417114,0.054661,0.000000
90.120003,64.895576,-1293.417114,-0.002539,0.002147,0.054540,288.669952,14.705547,0.545403,-1293.417114,0.054210,0.000000
90.390007,64.722801,-1293.417114,-0.002518,0.002137,0.054289,287.901398,14.666396,0.542890,-1293.417114,0.053761,0.000000
90.660004,64.639015,-1293.417114,-0.002531,0.002123,0.053933,287.528687,14.647410,0.539332,-1293.417114,0.053309,0.000000
90.930008,64.529167,-1293.417114,-0.002539,0.002099,0.053309,287.040070,14.622519,0.533095,-1293.417114,0.052858,0.000000
91.200005,64.450218,-1293.461548,-0.002522,0.002082,0.052875,286.688904,14.604629,0.528750,-1293.461548,0.052407,0.000000
91.470001,64.382820,-1293.417114,-0.002527,0.002064,0.052433,286.389099,14.589355,0.524329,-1293.417114,0.051956,0.000000
91.740005,64.350807,-1293.461548,-0.002518,0.002044,0.051921,286.246674,14.582101,0.519212,-1293.461548,0.051514,0.000000
92.010002,64.226433,-1293.417114,-0.002531,0.002030,0.051565,285.693451,14.553918,0.515654,-1293.417114,0.051063,0.000000
92.280006,64.163506,-1293.417114,-0.002518,0.002016,0.051202,285.413513,14.539659,0.512021,-1293.417114,0.050612,0.000000
92.550003,64.087166,-1293.372559,-0.002527,0.002001,0.050837,285.073944,14.522360,0.508372,-1293.372559,0.050160,0.000000
92.820007,63.981407,-1293.461548,-0.002509,0.001981,0.050309,284.603516,14.498395,0.503088,-1293.461548,0.049711,0.000000
93.090004,63.887566,-1293.506104,-0.002514,0.001970,0.050030,284.186096,14.477129,0.500303,-1293.506104,0.049260,0.000000
93.360008,63.509987,-1293.417114,-0.002522,0.001949,0.049502,282.506531,14.391569,0.495019,-1293.417114,0.048808,0.000000
93.630005,63.045265,-1293.372559,-0.002505,0.001933,0.049095,280.439331,14.286261,0.490946,-1293.372559,0.048357,0.000000
93.900002,62.102043,-1293.461548,-0.002505,0.001909,0.048488,276.243683,14.072524,0.484875,-1293.461548,0.047906,0.000000
94.170006,61.331978,-1293.417114,-0.002514,0.001892,0.048053,272.818268,13.898025,0.480530,-1293.417114,0.047464,0.000000
94.440002,60.675858,-1293.417114,-0.002501,0.001881,0.047785,269.899689,13.749346,0.477851,-1293.417114,0.047013,0.000000
94.710007,59.981758,-1293.506104,-0.002496,0.001868,0.047446,266.812195,13.592060,0.474459,-1293.506104,0.046562,0.000000
94.980003,59.512939,-1293.417114,-0.002509,0.001858,0.047187,264.726776,13.485825,0.471870,-1293.417114,0.046111,0.000000
95.250008,57.806358,-1293.417114,-0.002505,0.001832,0.046545,257.135529,13.099108,0.465451,-1293.417114,0.045659,0.000000
95.520004,56.538055,-1293.461548,-0.002501,0.001813,0.046050,251.493835,12.811707,0.460501,-1293.461548,0.045210,0.000000
95.790001,55.096230,-1293.461548,-0.002509,0.001795,0.045599,245.080276,12.484984,0.455989,-1293.461548,0.044759,0.000000
96.060005,53.992889,-1293.506104,-0.002509,0.001783,0.045287,240.172363,12.234963,0.452870,-1293.506104,0.044307,0.000000
96.330002,53.916183,-1293.417114,-0.002505,0.001781,0.045236,239.831161,12.217583,0.452356,-1293.417114,0.043856,0.000000
96.600006,50.650101,-1293.461548,-0.002505,0.001740,0.044186,225.302902,11.477476,0.441864,-1293.461548,0.043405,0.000000
96.870003,49.114807,-1293.461548,-0.002501,0.001728,0.043891,218.473572,11.129575,0.438912,-1293.461548,0.042963,0.000000
97.140007,47.945930,-1293.461548,-0.002514,0.001716,0.043587,213.274155,10.864703,0.435869,-1293.461548,0.042512,0.000000
97.410004,45.972733,-1293.461548,-0.002505,0.001696,0.043068,204.496933,10.417570,0.430676,-1293.461548,0.042061,0.000000
97.680008,44.348068,-1293.461548,-0.002501,0.001680,0.042668,197.270065,10.049416,0.426679,-1293.461548,0.041610,0.000000
97.950005,41.759338,-1293.417114,-0.002531,0.001652,0.041965,185.754822,9.462802,0.419654,-1293.417114,0.041158,0.000000
98.220001,40.555458,-1293.461548,-0.002518,0.001642,0.041697,180.399689,9.189998,0.416974,-1293.461548,0.040709,0.000000
98.490005,38.580391,-1293.461548,-0.002531,0.001619,0.041125,171.614151,8.742441,0.411252,-1293.461548,0.040258,0.000000
98.760002,36.960945,-1293.461548,-0.002522,0.001602,0.040700,164.410492,8.375470,0.406997,-1293.461548,0.039806,0.000000
99.030006,35.612961,-1293.461548,-0.002544,0.001592,0.040430,158.414368,8.070012,0.404302,-1293.461548,0.039355,0.000000
99.300003,33.517990,-1293.461548,-0.002531,0.001569,0.039841,149.095459,7.595285,0.398413,-1293.461548,0.038913,0.000000
99.570007,32.040413,-1293.461548,-0.002544,0.001552,0.039425,142.522873,7.260461,0.394250,-1293.461548,0.038462,0.000000
99.840004,29.943214,-1293.594971,-0.002544,0.001531,0.038878,133.194077,6.785230,0.388784,-1293.594971,0.038011,0.000000
100.110008,28.177795,-1293.417114,-0.002548,0.001515,0.038479,125.341095,6.385180,0.384788,-1293.417114,0.037560,0.000000
100.380005,27.235321,-1293.417114,-0.002557,0.001501,0.038132,121.148758,6.171612,0.381321,-1293.417114,0.037109,0.000000
100.650002,25.436020,-1293.417114,-0.002552,0.001486,0.037734,113.145065,5.763885,0.377339,-1293.417114,0.036659,0.000000
100.920006,22.840210,-1293.550537,-0.002557,0.001461,0.037109,101.598328,5.175665,0.371086,-1293.550537,0.036208,0.000000
101.190002,22.760895,-1293.461548,-0.002565,0.001461,0.037109,101.245514,5.157692,0.371086,-1293.461548,0.035757,0.000000
101.460007,19.946129,-1293.506104,-0.002557,0.001432,0.036364,88.724815,4.519857,0.363638,-1293.506104,0.035306,0.000000
101.730003,17.287018,-1293.417114,-0.002587,0.001405,0.035687,76.896492,3.917294,0.356870,-1293.417114,0.034863,0.000000
102.000008,16.416412,-1293.417114,-0.002600,0.001395,0.035436,73.023849,3.720012,0.354357,-1293.417114,0.034412,0.000000
102.270004,15.359993,-1293.506104,-0.002600,0.001383,0.035140,68.324661,3.480624,0.351405,-1293.506104,0.033961,0.000000
102.540009,12.322922,-1293.506104,-0.002596,0.001350,0.034291,54.815094,2.792414,0.342911,-1293.506104,0.033510,0.000000
102.810005,10.946259,-1293.461548,-0.002604,0.001336,0.033944,48.691391,2.480458,0.339445,-1293.461548,0.033059,0.000000
103.080002,10.128159,-1293.417114,-0.002600,0.001324,0.033623,45.052299,2.295074,0.336235,-1293.417114,0.032608,0.000000
103.350006,8.664734,-1293.461548,-0.002613,0.001308,0.033233,38.542660,1.963457,0.332329,-1293.461548,0.032158,0.000000
103.620003,7.142479,-1293.461548,-0.002617,0.001291,0.032791,31.771334,1.618509,0.327908,-1293.461548,0.031707,0.000000
103.890007,5.120865,-1293.461548,-0.002630,0.001269,0.032244,22.778744,1.160405,0.322443,-1293.461548,0.031256,0.000000
104.160004,4.274834,-1293.506104,-0.002630,0.001257,0.031923,19.015409,0.968691,0.319233,-1293.506104,0.030805,0.000000
104.430008,3.195328,-1293.461548,-0.002634,0.001247,0.031663,14.213528,0.724072,0.316629,-1293.461548,0.030362,0.000000
104.700005,0.601379,-1293.506104,-0.002647,0.001216,0.030883,2.675069,0.136275,0.308832,-1293.506104,0.029911,0.000000
104.970001,-0.635269,-1293.461548,-0.002656,0.001199,0.030449,-2.825818,-0.143954,0.304487,-1293.461548,0.029460,0.000000
105.240005,-1.528961,-1293.550537,-0.002669,0.001183,0.030051,-6.801159,-0.346468,0.300506,-1293.550537,0.029009,0.000000
105.510002,-0.262154,-1293.461548,-0.002695,0.001168,0.029669,-1.166118,-0.059405,0.296690,-1293.461548,0.028558,0.000000
105.780006,-0.023460,-1293.417114,-0.002712,0.001142,0.029018,-0.104357,-0.005316,0.290180,-1293.417114,0.028108,0.000000
106.050003,-0.032021,-1293.461548,-0.002734,0.001130,0.028697,-0.142435,-0.007256,0.286971,-1293.461548,0.027657,0.000000
106.320007,-0.027557,-1293.461548,-0.002759,0.001118,0.028402,-0.122581,-0.006245,0.284019,-1293.461548,0.027206,0.000000
106.590004,-0.037613,-1293.550537,-0.002768,0.001097,0.027864,-0.167311,-0.008523,0.278644,-1293.550537,0.026755,0.000000
106.860008,-0.024200,-1293.417114,-0.002798,0.001080,0.027431,-0.107649,-0.005484,0.274314,-1293.417114,0.026313,0.000000
107.130005,-0.029045,-1293.372559,-0.002833,0.001062,0.026980,-0.129199,-0.006582,0.269802,-1293.372559,0.025861,0.000000
107.400002,-0.030533,-1293.506104,-0.002846,0.001046,0.026573,-0.135817,-0.006919,0.265730,-1293.506104,0.025410,0.000000
107.670006,0.019737,-1293.461548,-0.002876,0.001018,0.025852,0.087796,0.004473,0.258523,-1293.461548,0.024959,0.000000
107.940002,0.010056,-1293.506104,-0.002884,0.001007,0.025584,0.044729,0.002279,0.255844,-1293.506104,0.024508,0.000000
108.210007,0.034630,-1293.417114,-0.002906,0.000995,0.025271,0.154041,0.007847,0.252710,-1293.417114,0.024057,0.000000
108.480003,-0.000748,-1293.417114,-0.002919,0.000973,0.024708,-0.003326,-0.000169,0.247078,-1293.417114,0.023607,0.000000
108.750008,0.008934,-1293.461548,-0.002953,0.000950,0.024126,0.039741,0.002024,0.241264,-1293.461548,0.023156,0.000000
109.000008,-0.010429,-1293.417114,-0.002949,0.000948,0.024075,-0.046392,-0.002363,0.240750,-1293.417114,0.023919,0.000000