File: Data/Sima compression/PSFNMP-17-2_10302024_180935.csv
Time (sec),S:Load (lbs),S:HL1 (DIM),S:LVDT (in),S:Position (in),Ch:Position (mm),Ch:Load (N),Ch:Stress (MPa),Ch:Strain (mm/mm),Ch:HL1 (DIM),Set Point (),Cycles ()
0.210000,0.023834,-1293.194702,-0.008157,-0.005194,-0.131923,0.106020,0.005401,-1.319233,-1293.194702,-0.131707,0.000000
0.500000,0.005211,-1293.283691,-0.008157,-0.005142,-0.130605,0.023179,0.001181,-1.306046,-1293.283691,-0.130007,0.000000
0.790000,-0.013779,-1293.239136,-0.008101,-0.004975,-0.126355,-0.061291,-0.003122,-1.263549,-1293.239136,-0.125185,0.000000
1.080000,-0.028671,-1293.239136,-0.007903,-0.004785,-0.121542,-0.127536,-0.006497,-1.215421,-1293.239136,-0.120346,0.000000
1.370000,-0.038727,-1293.239136,-0.007709,-0.004597,-0.116773,-0.172265,-0.008776,-1.167731,-1293.239136,-0.115524,0.000000
1.660000,-0.041702,-1293.105713,-0.007515,-0.004411,-0.112028,-0.185501,-0.009450,-1.120283,-1293.105713,-0.110685,0.000000
1.950000,-0.024948,-1293.283691,-0.007330,-0.004217,-0.107113,-0.110975,-0.005653,-1.071125,-1293.283691,-0.105845,0.000000
2.240000,0.032768,-1293.150269,-0.007092,-0.004022,-0.102160,0.145760,0.007425,-1.021604,-1293.150269,-0.101023,0.000000
2.530000,0.001114,-1293.239136,-0.006924,-0.003833,-0.097364,0.004955,0.000252,-0.973642,-1293.239136,-0.096185,0.000000
2.820000,-0.006706,-1293.239136,-0.006739,-0.003648,-0.092647,-0.029831,-0.001520,-0.926467,-1293.239136,-0.091363,0.000000
3.110000,-0.024574,-1293.150269,-0.006541,-0.003459,-0.087869,-0.109312,-0.005569,-0.878686,-1293.150269,-0.086524,0.000000
3.400000,-0.052132,-1293.194702,-0.006342,-0.003266,-0.082968,-0.231893,-0.011813,-0.829679,-1293.194702,-0.081702,0.000000
3.690000,-0.079689,-1293.150269,-0.006153,-0.003079,-0.078199,-0.354474,-0.018058,-0.781990,-1293.150269,-0.076864,0.000000
3.980000,-0.001488,-1293.194702,-0.005959,-0.002885,-0.073282,-0.006618,-0.000337,-0.732816,-1293.194702,-0.072042,0.000000
4.270000,-0.014153,-1293.239136,-0.005747,-0.002692,-0.068381,-0.062954,-0.003207,-0.683809,-1293.239136,-0.067202,0.000000
4.560000,0.037613,-1293.150269,-0.005553,-0.002503,-0.063577,0.167311,0.008523,-0.635772,-1293.150269,-0.062363,0.000000
4.850000,-0.000748,-1293.239136,-0.005372,-0.002318,-0.058876,-0.003326,-0.000169,-0.588763,-1293.239136,-0.057541,0.000000
5.140000,-0.009682,-1293.194702,-0.005182,-0.002127,-0.054029,-0.043066,-0.002194,-0.540286,-1293.194702,-0.052702,0.000000
5.430000,-0.045799,-1293.194702,-0.004993,-0.001939,-0.049251,-0.203725,-0.010378,-0.492506,-1293.194702,-0.047880,0.000000
5.720000,-0.032768,-1293.194702,-0.004781,-0.001747,-0.044368,-0.145760,-0.007425,-0.443681,-1293.194702,-0.043042,0.000000
6.010000,-0.054741,-1293.150269,-0.004592,-0.001554,-0.039460,-0.243500,-0.012404,-0.394598,-1293.150269,-0.038220,0.000000
6.300000,0.020111,-1293.283691,-0.004402,-0.001368,-0.034742,0.089459,0.004557,-0.347423,-1293.283691,-0.033380,0.000000
6.590000,-0.000748,-1293.150269,-0.004191,-0.001168,-0.029669,-0.003326,-0.000169,-0.296690,-1293.150269,-0.028558,0.000000
6.880000,0.029045,-1293.150269,-0.004010,-0.000984,-0.024985,0.129199,0.006582,-0.249848,-1293.150269,-0.023719,0.000000
7.170001,-0.024200,-1293.239136,-0.003816,-0.000797,-0.020233,-0.107649,-0.005484,-0.202325,-1293.239136,-0.018881,0.000000
7.460001,0.000374,-1293.194702,-0.003617,-0.000611,-0.015507,0.001663,0.000085,-0.155075,-1293.194702,-0.014059,0.000000
7.750000,-0.035378,-1293.239136,-0.003419,-0.000411,-0.010442,-0.157367,-0.008017,-0.104418,-1293.239136,-0.009220,0.000000
8.040000,-0.019363,-1293.150269,-0.003212,-0.000226,-0.005750,-0.086133,-0.004388,-0.057500,-1293.150269,-0.004398,0.000000
8.330000,0.017502,-1293.150269,-0.003022,-0.000031,-0.000790,0.077852,0.003966,-0.007903,-1293.150269,0.000442,0.000000
8.620001,0.141502,-1293.150269,-0.002932,-0.000000,-0.000000,0.629434,0.032065,-0.000000,-1293.150269,0.000157,0.000000
8.910001,0.141502,-1293.150269,-0.002936,-0.000000,-0.000008,0.629434,0.032065,-0.000076,-1293.150269,0.000157,0.000000
9.200001,0.125862,-1293.194702,-0.002945,-0.000000,-0.000008,0.559863,0.028521,-0.000076,-1293.194702,0.000547,0.000000
9.490001,0.136658,-1293.150269,-0.002928,-0.000000,-0.000000,0.607884,0.030967,-0.000000,-1293.150269,0.001023,0.000000
9.780001,0.217834,-1293.194702,-0.002953,0.000023,0.000581,0.968976,0.049362,0.005814,-1293.194702,0.001509,0.000000
10.070001,0.362694,-1293.194702,-0.002906,0.000038,0.000954,1.613343,0.082188,0.009538,-1293.194702,0.001995,0.000000
10.360001,0.619629,-1293.150269,-0.002906,0.000060,0.001535,2.756247,0.140410,0.015352,-1293.150269,0.002481,0.000000
10.650001,1.020302,-1293.239136,-0.002889,0.000079,0.002012,4.538529,0.231204,0.020121,-1293.239136,0.002958,0.000000
10.940001,1.243355,-1293.105713,-0.002880,0.000091,0.002307,5.530718,0.281748,0.023073,-1293.105713,0.003443,0.000000
11.230000,1.870796,-1293.150269,-0.002859,0.000117,0.002975,8.321717,0.423928,0.029749,-1293.150269,0.003929,0.000000
11.520000,2.486702,-1293.194702,-0.002837,0.000139,0.003531,11.061402,0.563495,0.035306,-1293.194702,0.004406,0.000000
11.810000,2.939133,-1293.105713,-0.002824,0.000156,0.003973,13.073915,0.666017,0.039726,-1293.105713,0.004892,0.000000
12.100000,3.559135,-1293.239136,-0.002820,0.000173,0.004389,15.831825,0.806512,0.043890,-1293.239136,0.005378,0.000000
12.390000,4.331062,-1293.150269,-0.002798,0.000196,0.004987,19.265528,0.981433,0.049870,-1293.150269,0.005864,0.000000
12.680000,5.031868,-1293.239136,-0.002777,0.000214,0.005438,22.382866,1.140238,0.054381,-1293.239136,0.006340,0.000000
12.970000,5.619476,-1293.194702,-0.002759,0.000229,0.005811,24.996679,1.273391,0.058106,-1293.194702,0.006825,0.000000
13.260000,6.361984,-1293.194702,-0.002755,0.000249,0.006331,28.299519,1.441646,0.063314,-1293.194702,0.007311,0.000000
13.550000,7.161842,-1293.239136,-0.002738,0.000268,0.006817,31.857466,1.622897,0.068174,-1293.239136,0.007797,0.000000
13.840001,7.752419,-1293.194702,-0.002725,0.000287,0.007294,34.484478,1.756723,0.072942,-1293.194702,0.008274,0.000000
14.130001,8.420830,-1293.239136,-0.002729,0.000303,0.007692,37.457722,1.908187,0.076924,-1293.239136,0.008760,0.000000
14.420001,9.321976,-1293.150269,-0.002695,0.000324,0.008222,41.466217,2.112390,0.082223,-1293.150269,0.009246,0.000000
14.710001,9.917023,-1293.150269,-0.002695,0.000340,0.008630,44.113121,2.247229,0.086296,-1293.150269,0.009730,0.000000
15.000001,10.556389,-1293.239136,-0.002682,0.000356,0.009055,46.957161,2.392112,0.090550,-1293.239136,0.010207,0.000000
15.290001,11.742767,-1293.105713,-0.002656,0.000383,0.009723,52.234436,2.660949,0.097226,-1293.105713,0.010693,0.000000
15.580001,12.251053,-1293.194702,-0.002656,0.000396,0.010051,54.495403,2.776128,0.100512,-1293.194702,0.011179,0.000000
15.870001,13.063568,-1293.150269,-0.002634,0.000416,0.010572,58.109653,2.960247,0.105720,-1293.150269,0.011665,0.000000
16.160000,13.826561,-1293.150269,-0.002634,0.000436,0.011084,61.503616,3.133144,0.110837,-1293.150269,0.012142,0.000000
16.450001,14.863617,-1293.194702,-0.002617,0.000457,0.011612,66.116669,3.368144,0.116121,-1293.194702,0.012628,0.000000
16.740002,15.190933,-1293.150269,-0.002574,0.000471,0.011960,67.572647,3.442315,0.119603,-1293.150269,0.013112,0.000000
17.030001,15.827316,-1293.239136,-0.002578,0.000487,0.012368,70.403419,3.586521,0.123675,-1293.239136,0.013598,0.000000
17.320002,17.130623,-1293.150269,-0.002557,0.000516,0.013096,76.200813,3.881855,0.130957,-1293.150269,0.014075,0.000000
17.610001,17.652313,-1293.150269,-0.002548,0.000531,0.013494,78.521408,4.000071,0.134939,-1293.150269,0.014561,0.000000
17.900002,18.424988,-1293.194702,-0.002535,0.000551,0.014006,81.958443,4.175162,0.140056,-1293.194702,0.015047,0.000000
18.190001,18.719536,-1293.150269,-0.002527,0.000566,0.014370,83.268654,4.241907,0.143705,-1293.150269,0.015524,0.000000
18.480001,18.928810,-1293.239136,-0.002505,0.000577,0.014657,84.199554,4.289330,0.146566,-1293.239136,0.016010,0.000000
18.770000,19.784523,-1293.194702,-0.002492,0.000599,0.015212,88.005951,4.483237,0.152122,-1293.194702,0.016495,0.000000
19.060001,20.344566,-1293.194702,-0.002505,0.000618,0.015697,90.497154,4.610145,0.156967,-1293.194702,0.016981,0.000000
19.350000,21.830338,-1293.239136,-0.002471,0.000647,0.016426,97.106194,4.946825,0.164264,-1293.239136,0.017457,0.000000
19.640001,22.410492,-1293.105713,-0.002449,0.000668,0.016971,99.686844,5.078290,0.169715,-1293.105713,0.017943,0.000000
19.930000,22.904259,-1293.283691,-0.002432,0.000687,0.017441,101.883232,5.190179,0.174408,-1293.283691,0.018429,0.000000
20.220001,23.030495,-1293.105713,-0.002414,0.000699,0.017762,102.444756,5.218785,0.177618,-1293.105713,0.018915,0.000000
20.510000,24.015419,-1293.150269,-0.002393,0.000723,0.018369,106.825920,5.441972,0.183689,-1293.150269,0.019392,0.000000
20.800001,24.317039,-1293.194702,-0.002393,0.000739,0.018758,108.167595,5.510320,0.187579,-1293.194702,0.019877,0.000000
21.090000,24.723297,-1293.194702,-0.002371,0.000761,0.019323,109.974716,5.602379,0.193226,-1293.194702,0.020363,0.000000
21.380001,25.789398,-1293.194702,-0.002358,0.000784,0.019921,114.716972,5.843961,0.199207,-1293.194702,0.020849,0.000000
21.670000,26.036285,-1293.105713,-0.002333,0.000801,0.020354,115.815178,5.899907,0.203537,-1293.105713,0.021326,0.000000
21.960001,26.529678,-1293.105713,-0.002324,0.000816,0.020737,118.009903,6.011711,0.207367,-1293.105713,0.021812,0.000000
22.250002,26.757942,-1293.239136,-0.002320,0.000833,0.021152,119.025269,6.063436,0.211515,-1293.239136,0.022298,0.000000
22.540001,27.489281,-1293.194702,-0.002294,0.000850,0.021603,122.278427,6.229160,0.216027,-1293.194702,0.022782,0.000000
22.830002,27.622963,-1293.194702,-0.002272,0.000867,0.022019,122.873077,6.259453,0.220190,-1293.194702,0.023259,0.000000
23.120001,29.172775,-1293.105713,-0.002259,0.000895,0.022740,129.766983,6.610645,0.227396,-1293.105713,0.023745,0.000000
23.410002,29.759636,-1293.194702,-0.002246,0.000913,0.023198,132.377472,6.743630,0.231984,-1293.194702,0.024231,0.000000
23.700001,30.008011,-1293.150269,-0.002251,0.000932,0.023675,133.482300,6.799912,0.236753,-1293.150269,0.024708,0.000000
23.990002,30.483154,-1293.194702,-0.002212,0.000951,0.024161,135.595840,6.907582,0.241613,-1293.194702,0.025194,0.000000
24.280001,30.811218,-1293.194702,-0.002207,0.000968,0.024578,137.055145,6.981922,0.245776,-1293.194702,0.025680,0.000000
24.570002,31.306839,-1293.150269,-0.002182,0.000985,0.025020,139.259781,7.094231,0.250197,-1293.150269,0.026164,0.000000
24.860001,31.628571,-1293.150269,-0.002182,0.001000,0.025394,140.690903,7.167137,0.253936,-1293.150269,0.026641,0.000000
25.150002,32.852936,-1293.194702,-0.002156,0.001025,0.026026,146.137161,7.444582,0.260265,-1293.194702,0.027127,0.000000
25.440001,33.885895,-1293.150269,-0.002147,0.001049,0.026634,150.731995,7.678653,0.266335,-1293.150269,0.027613,0.000000
25.730001,34.074318,-1293.194702,-0.002126,0.001063,0.026997,151.570129,7.721351,0.269969,-1293.194702,0.028099,0.000000
26.020000,34.469398,-1293.105713,-0.002117,0.001081,0.027466,153.327545,7.810877,0.274662,-1293.105713,0.028576,0.000000
26.310001,35.272980,-1293.194702,-0.002108,0.001102,0.027995,156.902054,7.992971,0.279946,-1293.194702,0.029062,0.000000
26.600000,35.701958,-1293.150269,-0.002070,0.001118,0.028394,158.810242,8.090179,0.283943,-1293.150269,0.029546,0.000000
26.890001,35.332932,-1293.105713,-0.002070,0.001128,0.028646,157.168732,8.006557,0.286456,-1293.105713,0.030032,0.000000
27.180002,37.391411,-1293.194702,-0.002052,0.001159,0.029434,166.325302,8.473015,0.294344,-1293.194702,0.030509,0.000000
27.470001,37.882568,-1293.061279,-0.002031,0.001178,0.029911,168.510086,8.584312,0.299113,-1293.061279,0.030995,0.000000
27.760002,38.435539,-1293.150269,-0.002035,0.001195,0.030362,170.969818,8.709618,0.303624,-1293.150269,0.031481,0.000000
28.050001,38.886108,-1293.150269,-0.002009,0.001212,0.030779,172.974045,8.811718,0.307788,-1293.150269,0.031967,0.000000
28.340002,39.738472,-1293.150269,-0.001983,0.001233,0.031307,176.765549,9.004867,0.313071,-1293.150269,0.032444,0.000000
28.630001,40.224045,-1293.194702,-0.001983,0.001250,0.031758,178.925491,9.114899,0.317583,-1293.194702,0.032929,0.000000
28.920002,41.332596,-1293.150269,-0.001957,0.001273,0.032340,183.856567,9.366100,0.323397,-1293.150269,0.033415,0.000000
29.210001,41.811470,-1293.194702,-0.001944,0.001290,0.032773,185.986710,9.474614,0.327726,-1293.194702,0.033891,0.000000
29.500002,42.959869,-1293.105713,-0.001919,0.001310,0.033284,191.095047,9.734845,0.332844,-1293.105713,0.034377,0.000000
29.790001,43.516937,-1293.105713,-0.001910,0.001327,0.033701,193.572998,9.861078,0.337007,-1293.105713,0.034863,0.000000
30.080002,44.111984,-1293.150269,-0.001906,0.001349,0.034273,196.219910,9.995918,0.342730,-1293.150269,0.035349,0.000000
30.370001,44.743530,-1293.105713,-0.001880,0.001363,0.034620,199.029160,10.139029,0.346197,-1293.105713,0.035826,0.000000
30.660002,45.274902,-1293.194702,-0.001880,0.001377,0.034985,201.392822,10.259439,0.349845,-1293.194702,0.036311,0.000000
30.950001,47.246994,-1293.105713,-0.001858,0.001408,0.035773,210.165131,10.706322,0.357733,-1293.105713,0.036797,0.000000
31.240002,47.852470,-1293.105713,-0.001858,0.001426,0.036224,212.858414,10.843525,0.362245,-1293.105713,0.037283,0.000000
31.530001,48.430389,-1293.105713,-0.001828,0.001442,0.036624,215.429138,10.974483,0.366242,-1293.105713,0.037760,0.000000
31.820002,49.806679,-1293.105713,-0.001824,0.001468,0.037299,221.551178,11.286355,0.372994,-1293.105713,0.038246,0.000000
32.110001,50.583076,-1293.194702,-0.001811,0.001484,0.037681,225.004761,11.462289,0.376809,-1293.194702,0.038732,0.000000
32.400002,51.104767,-1293.150269,-0.001807,0.001499,0.038062,227.325363,11.580505,0.380624,-1293.150269,0.039216,0.000000
32.690002,52.786034,-1293.150269,-0.001807,0.001524,0.038704,234.804001,11.961487,0.387043,-1293.150269,0.039693,0.000000
32.980003,53.799629,-1293.194702,-0.001776,0.001545,0.039243,239.312698,12.191171,0.392433,-1293.194702,0.040179,0.000000
33.270000,54.174980,-1293.061279,-0.001772,0.001559,0.039590,240.982346,12.276226,0.395900,-1293.061279,0.040665,0.000000
33.560001,54.916374,-1293.061279,-0.001759,0.001575,0.039997,244.280228,12.444228,0.399973,-1293.061279,0.041151,0.000000
33.850002,56.668015,-1293.105713,-0.001738,0.001602,0.040700,252.071915,12.841156,0.406997,-1293.105713,0.041628,0.000000
34.140003,56.995705,-1293.061279,-0.001729,0.001615,0.041021,253.529556,12.915412,0.410207,-1293.061279,0.042114,0.000000
34.430000,57.672676,-1293.105713,-0.001729,0.001634,0.041498,256.540863,13.068815,0.414976,-1293.105713,0.042598,0.000000
34.720001,59.387825,-1293.150269,-0.001703,0.001658,0.042105,264.170227,13.457474,0.421047,-1293.150269,0.043075,0.000000
35.010002,60.041336,-1293.150269,-0.001703,0.001672,0.042468,267.077209,13.605560,0.424680,-1293.150269,0.043561,0.000000
35.300003,61.072433,-1293.105713,-0.001669,0.001693,0.043015,271.663757,13.839211,0.430146,-1293.105713,0.044047,0.000000
35.590000,61.975441,-1293.194702,-0.001677,0.001713,0.043510,275.680542,14.043836,0.435096,-1293.194702,0.044533,0.000000
35.880001,63.189369,-1293.061279,-0.001651,0.001731,0.043968,281.080353,14.318916,0.439684,-1293.061279,0.045010,0.000000
36.170002,63.631752,-1293.061279,-0.001651,0.001743,0.044282,283.048157,14.419161,0.442818,-1293.061279,0.045496,0.000000
36.460003,64.447624,-1293.194702,-0.001660,0.001760,0.044715,286.677338,14.604041,0.447147,-1293.194702,0.045980,0.000000
36.750000,66.131859,-1293.061279,-0.001634,0.001778,0.045166,294.169189,14.985694,0.451659,-1293.061279,0.045339,0.000000
37.040001,65.043419,-1293.150269,-0.001621,0.001777,0.045131,289.327576,14.739050,0.451311,-1293.150269,0.007940,0.000000
37.330002,65.245613,-1293.150269,-0.001617,0.001792,0.045522,290.226990,14.784867,0.455217,-1293.150269,294.500488,0.000000
37.620003,64.930214,-1293.150269,-0.001617,0.001806,0.045885,288.824005,14.713397,0.458850,-1293.150269,294.500488,0.000000
37.910004,65.113045,-1293.150269,-0.001595,0.001807,0.045894,289.637299,14.754827,0.458941,-1293.150269,294.500488,0.000000
38.200001,65.188271,-1293.194702,-0.001608,0.001816,0.046129,289.971924,14.771873,0.461288,-1293.194702,294.500488,0.000000
38.490002,65.357704,-1293.194702,-0.001591,0.001825,0.046354,290.725586,14.810267,0.463544,-1293.194702,294.500488,0.000000
38.780003,64.985329,-1293.105713,-0.001569,0.001828,0.046441,289.069183,14.725885,0.464407,-1293.105713,294.500488,0.000000
39.070004,65.180077,-1293.194702,-0.001582,0.001836,0.046641,289.935455,14.770016,0.466405,-1293.194702,294.500488,0.000000
39.360001,65.063530,-1293.150269,-0.001587,0.001842,0.046787,289.417023,14.743607,0.467874,-1293.150269,294.500488,0.000000
39.650002,65.181572,-1293.105713,-0.001582,0.001849,0.046952,289.942108,14.770355,0.469524,-1293.105713,294.500488,0.000000
39.940002,65.183052,-1293.150269,-0.001569,0.001855,0.047117,289.948700,14.770691,0.471174,-1293.150269,294.500488,0.000000
40.230003,65.232582,-1293.150269,-0.001556,0.001862,0.047282,290.169006,14.781914,0.472824,-1293.150269,294.500488,0.000000
40.520000,64.997246,-1293.105713,-0.001569,0.001867,0.047429,289.122192,14.728586,0.474293,-1293.105713,294.500488,0.000000
40.810001,64.965584,-1293.150269,-0.001565,0.001871,0.047516,288.981354,14.721412,0.475156,-1293.150269,294.500488,0.000000
41.100002,65.323433,-1293.150269,-0.001556,0.001878,0.047706,290.573151,14.802502,0.477063,-1293.150269,294.500488,0.000000
41.390003,65.076927,-1293.105713,-0.001552,0.001883,0.047827,289.476624,14.746643,0.478274,-1293.105713,294.500488,0.000000
41.680000,64.923515,-1293.105713,-0.001539,0.001885,0.047890,288.794220,14.711879,0.478895,-1293.105713,294.500488,0.000000
41.970001,64.952553,-1293.105713,-0.001539,0.001890,0.048011,288.923370,14.718459,0.480106,-1293.105713,294.500488,0.000000
42.260002,65.406105,-1293.150269,-0.001531,0.001900,0.048262,290.940887,14.821236,0.482620,-1293.150269,294.500488,0.000000
42.550003,65.040443,-1293.105713,-0.001522,0.001900,0.048271,289.314331,14.738375,0.482710,-1293.105713,294.500488,0.000000
42.840000,65.493248,-1293.150269,-0.001526,0.001910,0.048504,291.328522,14.840981,0.485042,-1293.150269,294.500488,0.000000
43.130001,65.146935,-1293.105713,-0.001500,0.001910,0.048522,289.788025,14.762506,0.485224,-1293.105713,294.500488,0.000000
43.420002,65.095543,-1293.150269,-0.001522,0.001917,0.048695,289.559448,14.750860,0.486949,-1293.150269,294.500488,0.000000
43.710003,65.024422,-1293.105713,-0.001513,0.001919,0.048748,289.243073,14.734745,0.487479,-1293.105713,294.500488,0.000000
44.000004,65.102623,-1293.150269,-0.001522,0.001924,0.048860,289.590942,14.752465,0.488600,-1293.150269,294.500488,0.000000
44.290001,65.094429,-1293.105713,-0.001505,0.001927,0.048955,289.554474,14.750608,0.489553,-1293.105713,294.500488,0.000000
44.580002,65.277641,-1293.105713,-0.001500,0.001935,0.049146,290.369446,14.792125,0.491461,-1293.105713,294.500488,0.000000
44.870003,65.049004,-1293.105713,-0.001505,0.001936,0.049181,289.352417,14.740315,0.491809,-1293.105713,294.500488,0.000000
45.160004,65.181572,-1293.105713,-0.001496,0.001942,0.049328,289.942108,14.770355,0.493278,-1293.105713,294.500488,0.000000
45.450001,65.404610,-1293.105713,-0.001487,0.001950,0.049519,290.934235,14.820896,0.495185,-1293.105713,294.500488,0.000000
45.740002,65.325676,-1293.150269,-0.001500,0.001950,0.049519,290.583130,14.803010,0.495185,-1293.150269,294.500488,0.000000
46.030003,65.007301,-1293.150269,-0.001487,0.001950,0.049537,289.166931,14.730865,0.495367,-1293.150269,294.500488,0.000000
46.320004,64.962242,-1293.105713,-0.001470,0.001954,0.049641,288.966492,14.720654,0.496412,-1293.105713,294.500488,0.000000
46.610001,65.085869,-1293.105713,-0.001487,0.001959,0.049762,289.516418,14.748669,0.497623,-1293.105713,294.500488,0.000000
46.900002,65.028893,-1293.061279,-0.001479,0.001963,0.049867,289.262970,14.735758,0.498667,-1293.061279,294.500488,0.000000
47.190002,64.936546,-1293.150269,-0.001466,0.001964,0.049883,288.852173,14.714832,0.498834,-1293.150269,294.500488,0.000000
47.480003,65.577019,-1293.105713,-0.001457,0.001973,0.050118,291.701141,14.859965,0.501181,-1293.105713,294.500488,0.000000
47.770000,65.292900,-1293.105713,-0.001457,0.001973,0.050118,290.437317,14.795583,0.501181,-1293.105713,294.500488,0.000000
48.060001,64.978249,-1293.150269,-0.001457,0.001973,0.050118,289.037689,14.724281,0.501181,-1293.150269,294.500488,0.000000
48.350002,64.668816,-1293.150269,-0.001453,0.001973,0.050118,287.661255,14.654162,0.501181,-1293.150269,294.500488,0.000000
48.640003,64.330696,-1293.061279,-0.001453,0.001973,0.050118,286.157227,14.577543,0.501181,-1293.061279,294.500488,0.000000
48.930004,66.687447,-1293.105713,-0.001423,0.001890,0.048018,296.640564,15.111591,0.480182,-1293.105713,294.500488,0.000000
49.220001,66.283791,-1293.194702,-0.001449,0.001891,0.048036,294.845032,15.020122,0.480364,-1293.194702,294.500488,0.000000
49.510002,65.933754,-1293.150269,-0.001431,0.001892,0.048062,293.287994,14.940802,0.480621,-1293.150269,294.500488,0.000000
49.800003,65.559517,-1293.061279,-0.001440,0.001936,0.049172,291.623291,14.855999,0.491718,-1293.061279,294.500488,0.000000
50.090004,65.234444,-1293.194702,-0.001427,0.001964,0.049892,290.177307,14.782336,0.498925,-1293.194702,294.500488,0.000000
50.380001,65.098900,-1293.150269,-0.001440,0.001990,0.050542,289.574371,14.751621,0.505420,-1293.150269,294.500488,0.000000
50.670002,64.966331,-1293.150269,-0.001436,0.001994,0.050656,288.984680,14.721581,0.506555,-1293.150269,294.500488,0.000000
50.960003,64.880684,-1293.150269,-0.001440,0.001997,0.050716,288.603699,14.702173,0.507161,-1293.150269,294.500488,0.000000
51.250004,65.516701,-1293.061279,-0.001436,0.002007,0.050967,291.432831,14.846296,0.509674,-1293.061279,294.500488,0.000000
51.540001,65.271675,-1293.105713,-0.001427,0.002007,0.050967,290.342926,14.790773,0.509674,-1293.105713,294.500488,0.000000
51.830002,65.011391,-1293.061279,-0.001423,0.002007,0.050976,289.185120,14.731791,0.509765,-1293.061279,294.500488,0.000000
52.120003,64.750725,-1293.061279,-0.001444,0.002007,0.050984,288.025604,14.672724,0.509840,-1293.061279,294.500488,0.000000
52.410004,65.037834,-1293.105713,-0.001414,0.002014,0.051167,289.302734,14.737784,0.511672,-1293.105713,294.500488,0.000000
52.700001,64.850899,-1293.061279,-0.001423,0.002015,0.051184,288.471191,14.695423,0.511839,-1293.061279,294.500488,0.000000
52.990002,65.434029,-1293.105713,-0.001418,0.002028,0.051514,291.065094,14.827562,0.515139,-1293.105713,294.500488,0.000000
53.280003,65.560265,-1293.105713,-0.001410,0.002027,0.051479,291.626617,14.856169,0.514791,-1293.105713,294.500488,0.000000
53.570004,65.327156,-1293.150269,-0.001427,0.002027,0.051488,290.589691,14.803345,0.514882,-1293.150269,294.500488,0.000000
53.860004,65.097404,-1293.150269,-0.001414,0.002027,0.051488,289.567719,14.751283,0.514882,-1293.150269,294.500488,0.000000
54.150002,64.874733,-1293.105713,-0.001418,0.002027,0.051488,288.577240,14.700825,0.514882,-1293.105713,294.500488,0.000000
54.440002,64.633812,-1293.194702,-0.001401,0.002027,0.051496,287.505554,14.646231,0.514958,-1293.194702,294.500488,0.000000
54.730003,67.213982,-1293.150269,-0.001401,0.002039,0.051782,298.982727,15.230906,0.517819,-1293.150269,294.500488,0.000000
55.020004,66.584663,-1293.105713,-0.001401,0.001943,0.049346,296.183380,15.088301,0.493459,-1293.105713,294.500488,0.000000
55.310001,66.295326,-1293.105713,-0.001384,0.001943,0.049355,294.896332,15.022736,0.493550,-1293.105713,294.500488,0.000000
55.600002,66.010094,-1293.105713,-0.001388,0.001943,0.049355,293.627563,14.958100,0.493550,-1293.105713,294.500488,0.000000
55.890003,65.763954,-1293.239136,-0.001393,0.001952,0.049572,292.532684,14.902325,0.495715,-1293.239136,294.500488,0.000000
56.180004,65.489525,-1293.061279,-0.001380,0.001967,0.049970,291.311951,14.840138,0.499697,-1293.061279,294.500488,0.000000
56.470001,65.279503,-1293.105713,-0.001384,0.002032,0.051600,290.377716,14.792547,0.516002,-1293.105713,294.500488,0.000000
56.760002,65.139854,-1293.105713,-0.001367,0.002043,0.051895,289.756531,14.760902,0.518955,-1293.105713,294.500488,0.000000
57.050003,65.578880,-1293.150269,-0.001393,0.002055,0.052198,291.709442,14.860386,0.521982,-1293.150269,294.500488,0.000000
57.340004,65.391212,-1293.194702,-0.001393,0.002055,0.052198,290.874634,14.817861,0.521982,-1293.194702,294.500488,0.000000
57.630001,65.171883,-1293.194702,-0.001375,0.002055,0.052207,289.899017,14.768160,0.522073,-1293.194702,294.500488,0.000000
57.920002,65.284340,-1293.061279,-0.001384,0.002061,0.052356,290.399261,14.793643,0.523557,-1293.061279,294.500488,0.000000
58.210003,65.186775,-1293.150269,-0.001388,0.002061,0.052356,289.965271,14.771534,0.523557,-1293.150269,294.500488,0.000000
58.500004,65.086617,-1293.061279,-0.001384,0.002065,0.052451,289.519745,14.748837,0.524511,-1293.061279,294.500488,0.000000
58.790001,65.239662,-1293.239136,-0.001367,0.002067,0.052493,290.200500,14.783519,0.524935,-1293.239136,294.500488,0.000000
59.080002,65.046028,-1293.150269,-0.001371,0.002067,0.052493,289.339172,14.739640,0.524935,-1293.150269,294.500488,0.000000
59.370003,65.289177,-1293.061279,-0.001388,0.002073,0.052642,290.420776,14.794740,0.526418,-1293.061279,294.500488,0.000000
59.660004,65.186775,-1293.194702,-0.001371,0.002073,0.052658,289.965271,14.771534,0.526585,-1293.194702,294.500488,0.000000
59.950005,65.217308,-1293.150269,-0.001371,0.002076,0.052728,290.101074,14.778454,0.527281,-1293.150269,294.500488,0.000000
60.240002,65.176720,-1293.239136,-0.001362,0.002077,0.052754,289.920532,14.769256,0.527539,-1293.239136,294.500488,0.000000
60.530003,65.097786,-1293.105713,-0.001367,0.002079,0.052805,289.569427,14.751369,0.528053,-1293.105713,294.500488,0.000000
60.820004,65.136513,-1293.239136,-0.001367,0.002081,0.052849,289.741669,14.760145,0.528492,-1293.239136,294.500488,0.000000
61.110004,65.044533,-1293.150269,-0.001367,0.002082,0.052884,289.332520,14.739302,0.528841,-1293.150269,294.500488,0.000000
61.400002,65.294395,-1293.194702,-0.001358,0.002086,0.052996,290.443970,14.795921,0.529961,-1293.194702,294.500488,0.000000
61.690002,65.176720,-1293.194702,-0.001358,0.002086,0.052996,289.920532,14.769256,0.529961,-1293.194702,294.500488,0.000000
61.980003,65.162209,-1293.150269,-0.001354,0.002090,0.053075,289.855988,14.765968,0.530748,-1293.150269,294.500488,0.000000
62.270004,65.087349,-1293.239136,-0.001362,0.002090,0.053075,289.522980,14.749004,0.530748,-1293.239136,294.500488,0.000000
62.560001,65.309288,-1293.194702,-0.001362,0.002096,0.053249,290.510223,14.799295,0.532489,-1293.194702,294.500488,0.000000
62.850002,65.366631,-1293.105713,-0.001354,0.002096,0.053249,290.765289,14.812291,0.532489,-1293.105713,294.500488,0.000000
63.140003,65.253426,-1293.194702,-0.001350,0.002096,0.053249,290.261719,14.786638,0.532489,-1293.194702,294.500488,0.000000
63.430004,65.089211,-1293.150269,-0.001345,0.002097,0.053257,289.531281,14.749426,0.532565,-1293.150269,294.500488,0.000000
63.720001,64.966331,-1293.150269,-0.001358,0.002098,0.053282,288.984680,14.721581,0.532822,-1293.150269,294.500488,0.000000
64.010002,65.327156,-1293.194702,-0.001350,0.002107,0.053508,290.589691,14.803345,0.535078,-1293.194702,294.500488,0.000000
64.300003,65.460106,-1293.150269,-0.001350,0.002106,0.053500,291.181091,14.833472,0.535002,-1293.150269,294.500488,0.000000
64.590004,65.315620,-1293.194702,-0.001345,0.002106,0.053500,290.538391,14.800731,0.535002,-1293.194702,294.500488,0.000000
64.880005,65.168159,-1293.150269,-0.001345,0.002106,0.053500,289.882446,14.767316,0.535002,-1293.150269,294.500488,0.000000
65.170006,65.428825,-1293.150269,-0.001354,0.002112,0.053647,291.041962,14.826384,0.536471,-1293.150269,294.500488,0.000000
65.460007,65.349510,-1293.194702,-0.001319,0.002112,0.053647,290.689148,14.808411,0.536471,-1293.194702,294.500488,0.000000
65.750000,65.240028,-1293.150269,-0.001345,0.002112,0.053647,290.202148,14.783602,0.536471,-1293.150269,294.500488,0.000000
66.040001,65.217690,-1293.194702,-0.001345,0.002114,0.053691,290.102783,14.778540,0.536910,-1293.194702,294.500488,0.000000
66.330002,65.248222,-1293.150269,-0.001328,0.002117,0.053777,290.238586,14.785459,0.537773,-1293.150269,294.500488,0.000000
66.620003,65.191246,-1293.194702,-0.001341,0.002117,0.053777,289.985138,14.772547,0.537773,-1293.194702,294.500488,0.000000
66.910004,65.110069,-1293.239136,-0.001328,0.002118,0.053803,289.624054,14.754152,0.538030,-1293.239136,294.500488,0.000000
67.200005,65.211357,-1293.194702,-0.001341,0.002121,0.053873,290.074615,14.777104,0.538727,-1293.194702,294.500488,0.000000
67.490005,65.121620,-1293.283691,-0.001332,0.002122,0.053898,289.675446,14.756769,0.538984,-1293.283691,294.500488,0.000000
67.780006,65.215446,-1293.150269,-0.001324,0.002124,0.053959,290.092804,14.778031,0.539590,-1293.150269,294.500488,0.000000
68.070000,65.172997,-1293.239136,-0.001345,0.002125,0.053977,289.903961,14.768412,0.539771,-1293.239136,294.500488,0.000000
68.360001,65.356956,-1293.194702,-0.001324,0.002129,0.054073,290.722260,14.810098,0.540725,-1293.194702,294.500488,0.000000
68.650002,65.275032,-1293.194702,-0.001311,0.002129,0.054073,290.357849,14.791533,0.540725,-1293.194702,294.500488,0.000000
68.940002,65.148430,-1293.194702,-0.001315,0.002129,0.054089,289.794678,14.762845,0.540892,-1293.194702,294.500488,0.000000
69.230003,65.290672,-1293.194702,-0.001328,0.002134,0.054194,290.427429,14.795078,0.541936,-1293.194702,294.500488,0.000000
69.520004,65.267204,-1293.194702,-0.001315,0.002134,0.054194,290.323029,14.789760,0.541936,-1293.194702,294.500488,0.000000
69.810005,65.175987,-1293.239136,-0.001311,0.002134,0.054203,289.917267,14.769090,0.542027,-1293.239136,294.500488,0.000000
70.100006,65.086235,-1293.194702,-0.001319,0.002135,0.054238,289.518036,14.748752,0.542375,-1293.194702,294.500488,0.000000
70.390007,65.011391,-1293.194702,-0.001311,0.002136,0.054245,289.185120,14.731791,0.542451,-1293.194702,294.500488,0.000000
70.680000,65.000969,-1293.150269,-0.001315,0.002137,0.054280,289.138763,14.729430,0.542799,-1293.150269,294.500488,0.000000
70.970001,64.962608,-1293.150269,-0.001324,0.002138,0.054315,288.968109,14.720737,0.543148,-1293.150269,294.500488,0.000000
71.260002,64.861320,-1293.150269,-0.001315,0.002138,0.054315,288.517578,14.697785,0.543148,-1293.150269,294.500488,0.000000
71.550003,64.934303,-1293.194702,-0.001298,0.002141,0.054393,288.842194,14.714324,0.543935,-1293.194702,294.500488,0.000000
71.840004,64.831169,-1293.239136,-0.001319,0.002141,0.054393,288.383453,14.690953,0.543935,-1293.239136,294.500488,0.000000
72.130005,64.928719,-1293.194702,-0.001311,0.002150,0.054601,288.817352,14.713058,0.546009,-1293.194702,294.500488,0.000000
72.420006,65.371849,-1293.194702,-0.001311,0.002150,0.054610,290.788513,14.813473,0.546100,-1293.194702,294.500488,0.000000
72.710007,65.290672,-1293.105713,-0.001311,0.002150,0.054610,290.427429,14.795078,0.546100,-1293.105713,294.500488,0.000000
73.000000,65.180443,-1293.194702,-0.001293,0.002150,0.054610,289.937103,14.770100,0.546100,-1293.194702,294.500488,0.000000
73.290001,65.073204,-1293.239136,-0.001298,0.002150,0.054619,289.460083,14.745798,0.546191,-1293.239136,294.500488,0.000000
73.580002,64.958138,-1293.194702,-0.001306,0.002152,0.054671,288.948212,14.719725,0.546705,-1293.194702,294.500488,0.000000
73.870003,65.521172,-1293.239136,-0.001306,0.002158,0.054810,291.452728,14.847310,0.548098,-1293.239136,294.500488,0.000000
74.160004,65.425102,-1293.239136,-0.001285,0.002158,0.054810,291.025391,14.825541,0.548098,-1293.239136,294.500488,0.000000
74.450005,65.311897,-1293.150269,-0.001298,0.002158,0.054810,290.521820,14.799888,0.548098,-1293.150269,294.500488,0.000000
74.740005,65.208748,-1293.194702,-0.001293,0.002158,0.054810,290.062988,14.776513,0.548098,-1293.194702,294.500488,0.000000
75.030006,65.718529,-1293.194702,-0.001298,0.002165,0.054982,292.330627,14.892032,0.549824,-1293.194702,294.500488,0.000000
75.320007,65.595650,-1293.239136,-0.001293,0.002165,0.054982,291.784027,14.864186,0.549824,-1293.239136,294.500488,0.000000
75.610001,65.516701,-1293.194702,-0.001289,0.002165,0.054982,291.432831,14.846296,0.549824,-1293.194702,294.500488,0.000000
75.900002,65.389717,-1293.150269,-0.001276,0.002165,0.054982,290.867981,14.817522,0.549824,-1293.150269,294.500488,0.000000
76.190002,65.283592,-1293.239136,-0.001302,0.002165,0.054982,290.395935,14.793474,0.549824,-1293.239136,294.500488,0.000000
76.480003,65.146187,-1293.194702,-0.001285,0.002165,0.054982,289.784698,14.762337,0.549824,-1293.194702,294.500488,0.000000
76.770004,65.030754,-1293.194702,-0.001289,0.002165,0.054982,289.271240,14.736180,0.549824,-1293.194702,294.500488,0.000000
77.060005,64.891853,-1293.239136,-0.001293,0.002165,0.054982,288.653381,14.704704,0.549824,-1293.239136,294.500488,0.000000
77.350006,65.788902,-1293.194702,-0.001285,0.002176,0.055269,292.643646,14.907978,0.552685,-1293.194702,294.500488,0.000000
77.640007,65.733055,-1293.194702,-0.001281,0.002176,0.055269,292.395233,14.895324,0.552685,-1293.194702,294.500488,0.000000
77.930000,65.608299,-1293.150269,-0.001281,0.002176,0.055269,291.840302,14.867053,0.552685,-1293.150269,294.500488,0.000000
78.220001,65.535316,-1293.194702,-0.001289,0.002176,0.055269,291.515656,14.850515,0.552685,-1293.194702,294.500488,0.000000
78.510002,65.394569,-1293.239136,-0.001281,0.002176,0.055269,290.889587,14.818621,0.552685,-1293.239136,294.500488,0.000000
78.800003,65.278755,-1293.150269,-0.001276,0.002176,0.055269,290.374420,14.792377,0.552685,-1293.150269,294.500488,0.000000
79.090004,65.151405,-1293.239136,-0.001276,0.002176,0.055269,289.807922,14.763519,0.552685,-1293.239136,294.500488,0.000000
79.380005,65.057564,-1293.105713,-0.001289,0.002177,0.055294,289.390503,14.742254,0.552943,-1293.105713,294.500488,0.000000
79.670006,64.966713,-1293.194702,-0.001285,0.002177,0.055294,288.986359,14.721668,0.552943,-1293.194702,294.500488,0.000000
79.960007,64.959633,-1293.194702,-0.001276,0.002179,0.055347,288.954865,14.720063,0.553473,-1293.194702,294.500488,0.000000
80.250000,65.291786,-1293.194702,-0.001276,0.002186,0.055520,290.432373,14.795330,0.555199,-1293.194702,294.500488,0.000000
80.540001,65.356575,-1293.194702,-0.001276,0.002186,0.055520,290.720551,14.810012,0.555199,-1293.194702,294.500488,0.000000
80.830002,65.295143,-1293.194702,-0.001272,0.002186,0.055520,290.447296,14.796091,0.555199,-1293.194702,294.500488,0.000000
81.120003,65.212105,-1293.150269,-0.001276,0.002186,0.055520,290.077942,14.777274,0.555199,-1293.150269,294.500488,0.000000
81.410004,65.255669,-1293.239136,-0.001259,0.002189,0.055590,290.271698,14.787147,0.555895,-1293.239136,294.500488,0.000000
81.700005,65.220665,-1293.194702,-0.001268,0.002189,0.055599,290.115997,14.779214,0.555986,-1293.194702,294.500488,0.000000
81.990005,65.145073,-1293.239136,-0.001259,0.002189,0.055608,289.779755,14.762084,0.556077,-1293.239136,294.500488,0.000000
82.280006,65.123482,-1293.239136,-0.001276,0.002190,0.055633,289.683716,14.757192,0.556334,-1293.239136,294.500488,0.000000
82.570007,65.060173,-1293.194702,-0.001272,0.002191,0.055650,289.402100,14.742846,0.556501,-1293.194702,294.500488,0.000000
82.860001,65.130180,-1293.194702,-0.001259,0.002195,0.055755,289.713501,14.758710,0.557545,-1293.194702,294.500488,0.000000
83.150002,65.250450,-1293.150269,-0.001268,0.002195,0.055755,290.248505,14.785963,0.557545,-1293.150269,294.500488,0.000000
83.440002,65.190880,-1293.194702,-0.001276,0.002195,0.055755,289.983521,14.772465,0.557545,-1293.194702,294.500488,0.000000
83.730003,65.082146,-1293.194702,-0.001250,0.002195,0.055764,289.499847,14.747825,0.557636,-1293.194702,294.500488,0.000000
84.020004,65.439995,-1293.239136,-0.001272,0.002201,0.055901,291.091644,14.828915,0.559014,-1293.239136,294.500488,0.000000
84.310005,65.402748,-1293.194702,-0.001263,0.002201,0.055901,290.925964,14.820475,0.559014,-1293.194702,294.500488,0.000000
84.600006,65.328285,-1293.150269,-0.001263,0.002201,0.055901,290.594727,14.803600,0.559014,-1293.150269,294.500488,0.000000
84.890007,65.261620,-1293.239136,-0.001276,0.002201,0.055910,290.298187,14.788494,0.559105,-1293.239136,294.500488,0.000000
85.180000,65.231087,-1293.150269,-0.001242,0.002203,0.055945,290.162354,14.781575,0.559453,-1293.150269,294.500488,0.000000
85.470001,65.236305,-1293.194702,-0.001255,0.002204,0.055980,290.185577,14.782759,0.559801,-1293.194702,294.500488,0.000000
85.760002,65.217690,-1293.194702,-0.001259,0.002205,0.056006,290.102783,14.778540,0.560058,-1293.194702,294.500488,0.000000
86.050003,65.183800,-1293.150269,-0.001259,0.002205,0.056015,289.952026,14.770861,0.560149,-1293.150269,294.500488,0.000000
86.340004,65.165184,-1293.239136,-0.001246,0.002207,0.056050,289.869202,14.766642,0.560498,-1293.239136,294.500488,0.000000
86.630005,65.165932,-1293.150269,-0.001263,0.002208,0.056085,289.872528,14.766811,0.560846,-1293.150269,294.500488,0.000000
86.920006,65.184166,-1293.150269,-0.001259,0.002209,0.056101,289.953644,14.770943,0.561012,-1293.150269,294.500488,0.000000
87.210007,65.114540,-1293.150269,-0.001259,0.002209,0.056110,289.643951,14.755165,0.561103,-1293.150269,294.500488,0.000000
87.500008,65.056068,-1293.105713,-0.001237,0.002209,0.056119,289.383850,14.741916,0.561194,-1293.105713,294.500488,0.000000
87.790001,65.013252,-1293.239136,-0.001246,0.002209,0.056119,289.193390,14.732214,0.561194,-1293.239136,294.500488,0.000000
88.080002,65.314507,-1293.150269,-0.001259,0.002215,0.056250,290.533447,14.800479,0.562496,-1293.150269,294.500488,0.000000
88.370003,65.279121,-1293.150269,-0.001242,0.002215,0.056250,290.376038,14.792460,0.562496,-1293.150269,294.500488,0.000000
88.660004,65.209496,-1293.105713,-0.001255,0.002215,0.056250,290.066315,14.776683,0.562496,-1293.105713,294.500488,0.000000
88.950005,65.120491,-1293.194702,-0.001255,0.002215,0.056250,289.670410,14.756514,0.562496,-1293.194702,294.500488,0.000000
89.240005,65.043785,-1293.150269,-0.001242,0.002215,0.056257,289.329193,14.739132,0.562572,-1293.150269,294.500488,0.000000
89.530006,64.983833,-1293.194702,-0.001242,0.002215,0.056257,289.062531,14.725547,0.562572,-1293.194702,294.500488,0.000000
89.820007,64.971169,-1293.194702,-0.001237,0.002217,0.056310,289.006195,14.722678,0.563102,-1293.194702,294.500488,0.000000
90.110001,64.965965,-1293.239136,-0.001242,0.002218,0.056336,288.983032,14.721498,0.563359,-1293.239136,294.500488,0.000000
90.400002,64.911217,-1293.150269,-0.001233,0.002218,0.056336,288.739502,14.709092,0.563359,-1293.150269,294.500488,0.000000
90.690002,64.845680,-1293.239136,-0.001242,0.002218,0.056336,288.447998,14.694242,0.563359,-1293.239136,294.500488,0.000000
90.980003,64.749611,-1293.194702,-0.001237,0.002218,0.056336,288.020660,14.672471,0.563359,-1293.194702,294.500488,0.000000
91.270004,65.564735,-1293.150269,-0.001246,0.002229,0.056613,291.646515,14.857182,0.566129,-1293.150269,294.500488,0.000000
91.560005,65.574425,-1293.194702,-0.001237,0.002227,0.056578,291.689606,14.859378,0.565781,-1293.194702,294.500488,0.000000
91.850006,65.510750,-1293.150269,-0.001233,0.002227,0.056578,291.406372,14.844948,0.565781,-1293.150269,294.500488,0.000000
92.140007,65.406471,-1293.194702,-0.001220,0.002227,0.056578,290.942505,14.821319,0.565781,-1293.194702,294.500488,0.000000
92.430008,65.321571,-1293.150269,-0.001224,0.002227,0.056578,290.564850,14.802079,0.565781,-1293.150269,294.500488,0.000000
92.720001,65.253059,-1293.150269,-0.001246,0.002227,0.056578,290.260101,14.786554,0.565781,-1293.150269,294.500488,0.000000
93.010002,65.173744,-1293.194702,-0.001246,0.002227,0.056578,289.907288,14.768581,0.565781,-1293.194702,294.500488,0.000000
93.300003,65.065758,-1293.150269,-0.001224,0.002227,0.056578,289.426941,14.744112,0.565781,-1293.150269,294.500488,0.000000
93.590004,64.988304,-1293.239136,-0.001242,0.002227,0.056578,289.082428,14.726561,0.565781,-1293.239136,294.500488,0.000000
93.880005,64.871376,-1293.150269,-0.001216,0.002228,0.056587,288.562286,14.700065,0.565872,-1293.150269,294.500488,0.000000
94.170006,64.796165,-1293.194702,-0.001224,0.002228,0.056587,288.227753,14.683022,0.565872,-1293.194702,294.500488,0.000000
94.460007,64.717216,-1293.194702,-0.001220,0.002228,0.056587,287.876556,14.665131,0.565872,-1293.194702,294.500488,0.000000
94.750008,64.629707,-1293.105713,-0.001220,0.002228,0.056587,287.487305,14.645302,0.565872,-1293.105713,294.500488,0.000000
95.040001,64.516502,-1293.239136,-0.001220,0.002228,0.056587,286.983734,14.619649,0.565872,-1293.239136,294.500488,0.000000
95.330002,64.440544,-1293.194702,-0.001224,0.002228,0.056587,286.645844,14.602436,0.565872,-1293.194702,294.500488,0.000000
95.620003,64.353783,-1293.194702,-0.001233,0.002228,0.056587,286.259918,14.582775,0.565872,-1293.194702,294.500488,0.000000
95.910004,64.256599,-1293.239136,-0.001224,0.002228,0.056587,285.827637,14.560754,0.565872,-1293.239136,294.500488,0.000000
96.200005,66.726540,-1293.194702,-0.001203,0.002122,0.053889,296.814484,15.120450,0.538893,-1293.194702,294.500488,0.000000
96.490005,66.589134,-1293.239136,-0.001216,0.002113,0.053682,296.203278,15.089314,0.536819,-1293.239136,294.500488,0.000000
96.780006,66.401085,-1293.194702,-0.001216,0.002114,0.053691,295.366791,15.046700,0.536910,-1293.194702,294.500488,0.000000
97.070007,66.346718,-1293.150269,-0.001212,0.002114,0.053691,295.124939,15.034381,0.536910,-1293.150269,294.500488,0.000000
97.360008,66.238731,-1293.239136,-0.001212,0.002114,0.053691,294.644592,15.009912,0.536910,-1293.239136,1681.640991,0.000000
97.650002,66.177666,-1293.194702,-0.001190,0.002114,0.053691,294.372955,14.996073,0.536910,-1293.194702,0.053422,0.000000
97.940002,66.052544,-1293.239136,-0.001216,0.002108,0.053552,293.816376,14.967720,0.535517,-1293.239136,0.052936,0.000000
98.230003,65.921471,-1293.283691,-0.001190,0.002090,0.053084,293.233337,14.938019,0.530839,-1293.283691,0.052459,0.000000
98.520004,65.774757,-1293.150269,-0.001203,0.002072,0.052633,292.580719,14.904774,0.526327,-1293.150269,0.051974,0.000000
98.810005,65.486168,-1293.194702,-0.001199,0.002054,0.052165,291.297028,14.839377,0.521649,-1293.194702,0.051488,0.000000
99.100006,65.140236,-1293.239136,-0.001203,0.002032,0.051618,289.758240,14.760988,0.516184,-1293.239136,0.051002,0.000000
99.390007,64.836754,-1293.283691,-0.001199,0.002015,0.051184,288.408295,14.692219,0.511839,-1293.283691,0.050525,0.000000
99.680008,63.794472,-1293.105713,-0.001199,0.001990,0.050551,283.771973,14.456034,0.505511,-1293.105713,0.050039,0.000000
99.970001,63.049362,-1293.239136,-0.001212,0.001975,0.050153,280.457581,14.287189,0.501529,-1293.239136,0.049553,0.000000
100.260002,62.308342,-1293.239136,-0.001190,0.001964,0.049892,277.161346,14.119271,0.498925,-1293.239136,0.049069,0.000000
100.550003,61.390442,-1293.105713,-0.001181,0.001945,0.049397,273.078339,13.911273,0.493974,-1293.105713,0.048592,0.000000
100.840004,60.173897,-1293.194702,-0.001194,0.001927,0.048946,267.666870,13.635599,0.489463,-1293.194702,0.048106,0.000000
101.130005,59.127533,-1293.194702,-0.001186,0.001913,0.048592,263.012390,13.398490,0.485920,-1293.194702,0.047620,0.000000
101.420006,57.773956,-1293.150269,-0.001194,0.001893,0.048080,256.991394,13.091765,0.480803,-1293.150269,0.047134,0.000000
101.710007,56.230476,-1293.194702,-0.001203,0.001875,0.047637,250.125656,12.742007,0.476367,-1293.194702,0.046657,0.000000
102.000008,54.494850,-1293.150269,-0.001199,0.001855,0.047117,242.405197,12.348710,0.471174,-1293.150269,0.046171,0.000000
102.290009,52.874283,-1293.283691,-0.001194,0.001837,0.046648,235.196564,11.981483,0.466481,-1293.283691,0.045687,0.000000
102.580002,51.023590,-1293.239136,-0.001186,0.001815,0.046103,226.964264,11.562111,0.461030,-1293.239136,0.045210,0.000000
102.870003,48.867928,-1293.194702,-0.001190,0.001798,0.045678,217.375397,11.073630,0.456776,-1293.194702,0.044724,0.000000
103.160004,46.989677,-1293.283691,-0.001194,0.001780,0.045210,209.020523,10.648013,0.452098,-1293.283691,0.044238,0.000000
103.450005,45.131172,-1293.150269,-0.001194,0.001764,0.044810,200.753479,10.226870,0.448101,-1293.150269,0.043752,0.000000
103.740005,42.092613,-1293.239136,-0.001207,0.001736,0.044099,187.237289,9.538322,0.440986,-1293.239136,0.043275,0.000000
104.030006,40.539444,-1293.194702,-0.001199,0.001723,0.043770,180.328445,9.186369,0.437700,-1293.194702,0.042789,0.000000
104.320007,38.809029,-1293.150269,-0.001203,0.001707,0.043354,172.631180,8.794251,0.433537,-1293.150269,0.042305,0.000000
104.610008,36.266846,-1293.194702,-0.001212,0.001681,0.042686,161.322983,8.218184,0.426860,-1293.194702,0.041819,0.000000
104.900002,34.801559,-1293.194702,-0.001203,0.001673,0.042495,154.805069,7.886146,0.424953,-1293.194702,0.041342,0.000000
105.190002,32.514450,-1293.194702,-0.001207,0.001650,0.041905,144.631500,7.367880,0.419048,-1293.194702,0.040856,0.000000
105.480003,30.689445,-1293.283691,-0.001207,0.001632,0.041445,136.513474,6.954328,0.414446,-1293.283691,0.040370,0.000000
105.770004,27.821434,-1293.194702,-0.001224,0.001607,0.040812,123.755920,6.304427,0.408118,-1293.194702,0.039884,0.000000
106.060005,26.341629,-1293.239136,-0.001220,0.001594,0.040483,117.173416,5.969099,0.404832,-1293.239136,0.039407,0.000000
106.350006,24.608604,-1293.194702,-0.001229,0.001578,0.040074,109.464539,5.576389,0.400745,-1293.194702,0.038922,0.000000
106.640007,21.725700,-1293.239136,-0.001224,0.001550,0.039381,96.640739,4.923114,0.393811,-1293.239136,0.038436,0.000000
106.930008,20.376221,-1293.239136,-0.001233,0.001540,0.039113,90.637955,4.617318,0.391131,-1293.239136,0.037950,0.000000
107.220009,18.023941,-1293.150269,-0.001237,0.001517,0.038532,80.174492,4.084283,0.385317,-1293.150269,0.037473,0.000000
107.510002,15.270622,-1293.194702,-0.001242,0.001491,0.037864,67.927124,3.460372,0.378641,-1293.194702,0.036988,0.000000
107.800003,14.097649,-1293.194702,-0.001229,0.001481,0.037620,62.709473,3.194573,0.376203,-1293.194702,0.036502,0.000000
108.090004,12.594009,-1293.239136,-0.001255,0.001465,0.037213,56.020950,2.853843,0.372131,-1293.239136,0.036025,0.000000
108.380005,10.994293,-1293.150269,-0.001237,0.001444,0.036676,48.905060,2.491343,0.366756,-1293.150269,0.035540,0.000000
108.670006,7.712952,-1293.150269,-0.001255,0.001419,0.036034,34.308922,1.747780,0.360337,-1293.150269,0.035054,0.000000
108.960007,5.940460,-1293.283691,-0.001242,0.001400,0.035557,26.424486,1.346128,0.355568,-1293.283691,0.034568,0.000000
109.250008,4.539223,-1293.194702,-0.001250,0.001385,0.035184,20.191471,1.028603,0.351844,-1293.194702,0.034091,0.000000
109.540009,2.053635,-1293.239136,-0.001263,0.001360,0.034552,9.135023,0.465360,0.345515,-1293.239136,0.033605,0.000000
109.830002,0.957367,-1293.239136,-0.001272,0.001348,0.034231,4.258581,0.216942,0.342306,-1293.239136,0.033119,0.000000
110.120003,-0.705276,-1293.150269,-0.001272,0.001330,0.033787,-3.137227,-0.159818,0.337870,-1293.150269,0.032635,0.000000
110.410004,-2.892216,-1293.239136,-0.001281,0.001308,0.033215,-12.865218,-0.655385,0.332147,-1293.239136,0.032158,0.000000
110.700005,-3.922943,-1293.239136,-0.001276,0.001289,0.032738,-17.450123,-0.888952,0.327378,-1293.239136,0.031672,0.000000
110.990005,-0.264015,-1293.194702,-0.001362,0.001268,0.032209,-1.174398,-0.059827,0.322095,-1293.194702,0.031186,0.000000
111.280006,-0.096443,-1293.239136,-0.001345,0.001252,0.031810,-0.429001,-0.021854,0.318098,-1293.239136,0.030700,0.000000
111.570007,-0.048409,-1293.194702,-0.001371,0.001231,0.031265,-0.215332,-0.010970,0.312647,-1293.194702,0.030223,0.000000
111.860008,-0.060326,-1293.239136,-0.001384,0.001213,0.030805,-0.268342,-0.013670,0.308045,-1293.239136,0.029737,0.000000
112.150002,-0.044685,-1293.194702,-0.001397,0.001204,0.030570,-0.198770,-0.010126,0.305698,-1293.194702,0.029253,0.000000
112.440002,-0.063675,-1293.239136,-0.001431,0.001172,0.029772,-0.283240,-0.014429,0.297720,-1293.239136,0.028767,0.000000
112.730003,-0.058090,-1293.239136,-0.001423,0.001162,0.029512,-0.258398,-0.013163,0.295116,-1293.239136,0.028290,0.000000
113.020004,-0.040215,-1293.239136,-0.001453,0.001139,0.028923,-0.178883,-0.009113,0.289227,-1293.239136,0.027804,0.000000
113.310005,-0.010056,-1293.283691,-0.001475,0.001119,0.028428,-0.044729,-0.002279,0.284276,-1293.283691,0.027318,0.000000
113.600006,0.002609,-1293.194702,-0.001479,0.001097,0.027864,0.011607,0.000591,0.278644,-1293.194702,0.026841,0.000000
113.890007,0.004471,-1293.194702,-0.001513,0.001079,0.027406,0.019887,0.001013,0.274057,-1293.194702,0.026355,0.000000
114.180008,-0.008568,-1293.239136,-0.001531,0.001057,0.026850,-0.038112,-0.001941,0.268500,-1293.239136,0.025871,0.000000
114.470009,-0.017876,-1293.194702,-0.001539,0.001038,0.026355,-0.079515,-0.004051,0.263550,-1293.194702,0.025385,0.000000
114.760002,-0.036118,-1293.328125,-0.001561,0.001021,0.025922,-0.160659,-0.008184,0.259220,-1293.328125,0.024908,0.000000
115.050003,-0.029793,-1293.194702,-0.001565,0.001005,0.025522,-0.132525,-0.006751,0.255223,-1293.194702,0.024422,0.000000
115.340004,0.028671,-1293.239136,-0.001595,0.000979,0.024873,0.127536,0.006497,0.248728,-1293.239136,0.023936,0.000000
115.630005,0.027931,-1293.239136,-0.001613,0.000970,0.024629,0.124244,0.006329,0.246291,-1293.239136,0.023450,0.000000
115.920006,0.031654,-1293.194702,-0.001617,0.000947,0.024057,0.140806,0.007173,0.240568,-1293.194702,0.022973,0.000000
116.210007,0.004097,-1293.194702,-0.001656,0.000923,0.023433,0.018224,0.000928,0.234330,-1293.194702,0.022488,0.000000
116.500008,0.015266,-1293.239136,-0.001673,0.000910,0.023121,0.067908,0.003459,0.231212,-1293.239136,0.022002,0.000000
116.790009,-0.038353,-1293.194702,-0.001699,0.000888,0.022556,-0.170603,-0.008691,0.225565,-1293.194702,0.021516,0.000000
116.900009,-0.023087,-1293.239136,-0.001686,0.000881,0.022384,-0.102694,-0.005231,0.223839,-1293.239136,0.021335,0.000000