File: Data/Sima compression/PSFNMP-17-1_10302024_180642.csv
Time (sec),S:Load (lbs),S:HL1 (DIM),S:LVDT (in),S:Position (in),Ch:Position (mm),Ch:Load (N),Ch:Stress (MPa),Ch:Strain (mm/mm),Ch:HL1 (DIM),Set Point (),Cycles ()
0.210000,-0.012291,-1293.150269,-0.008593,-0.004507,-0.114466,-0.054673,-0.002785,-1.144658,-1293.150269,-0.114284,0.000000
0.510000,-0.001488,-1293.194702,-0.008606,-0.004447,-0.112949,-0.006618,-0.000337,-1.129488,-1293.194702,-0.112410,0.000000
0.810000,-0.019363,-1293.150269,-0.008532,-0.004272,-0.108516,-0.086133,-0.004388,-1.085160,-1293.150269,-0.107397,0.000000
1.110000,0.003349,-1293.194702,-0.008330,-0.004082,-0.103677,0.014898,0.000759,-1.036774,-1293.194702,-0.102403,0.000000
1.410000,-0.038727,-1293.239136,-0.008140,-0.003892,-0.098855,-0.172265,-0.008776,-0.988554,-1293.239136,-0.097408,0.000000
1.710000,-0.021599,-1293.150269,-0.007933,-0.003686,-0.093617,-0.096076,-0.004894,-0.936171,-1293.150269,-0.092412,0.000000
2.010000,-0.049522,-1293.194702,-0.007735,-0.003495,-0.088769,-0.220287,-0.011222,-0.887694,-1293.194702,-0.087417,0.000000
2.310000,-0.035004,-1293.239136,-0.007532,-0.003294,-0.083679,-0.155704,-0.007932,-0.836795,-1293.239136,-0.082421,0.000000
2.610000,0.000374,-1293.194702,-0.007330,-0.003098,-0.078683,0.001663,0.000085,-0.786834,-1293.194702,-0.077427,0.000000
2.910000,-0.029793,-1293.194702,-0.007105,-0.002895,-0.073533,-0.132525,-0.006751,-0.735329,-1293.194702,-0.072414,0.000000
3.210000,0.012657,-1293.194702,-0.006907,-0.002705,-0.068711,0.056302,0.002868,-0.687110,-1293.194702,-0.067418,0.000000
3.510000,-0.037613,-1293.194702,-0.006704,-0.002504,-0.063603,-0.167311,-0.008523,-0.636029,-1293.194702,-0.062424,0.000000
3.810000,-0.015640,-1293.239136,-0.006528,-0.002312,-0.058729,-0.069571,-0.003544,-0.587295,-1293.239136,-0.057429,0.000000
4.110000,-0.069260,-1293.194702,-0.006316,-0.002113,-0.053665,-0.308082,-0.015694,-0.536653,-1293.194702,-0.052433,0.000000
4.410000,-0.023087,-1293.194702,-0.006122,-0.001924,-0.048869,-0.102694,-0.005231,-0.488690,-1293.194702,-0.047438,0.000000
4.710000,-0.012291,-1293.150269,-0.005907,-0.001719,-0.043666,-0.054673,-0.002785,-0.436656,-1293.150269,-0.042426,0.000000
5.010000,0.031654,-1293.194702,-0.005700,-0.001518,-0.038567,0.140806,0.007173,-0.385666,-1293.194702,-0.037430,0.000000
5.310000,0.019363,-1293.194702,-0.005501,-0.001322,-0.033580,0.086133,0.004388,-0.335796,-1293.194702,-0.032435,0.000000
5.610000,0.007820,-1293.194702,-0.005303,-0.001126,-0.028602,0.034786,0.001772,-0.286017,-1293.194702,-0.027439,0.000000
5.910000,0.017128,-1293.150269,-0.005096,-0.000927,-0.023545,0.076189,0.003881,-0.235451,-1293.150269,-0.022444,0.000000
6.210001,-0.055855,-1293.194702,-0.004889,-0.000733,-0.018629,-0.248455,-0.012657,-0.186293,-1293.194702,-0.017450,0.000000
6.510000,0.017128,-1293.194702,-0.004700,-0.000541,-0.013747,0.076189,0.003881,-0.137467,-1293.194702,-0.012437,0.000000
6.810000,-0.013405,-1293.194702,-0.004501,-0.000343,-0.008708,-0.059628,-0.003038,-0.087083,-1293.194702,-0.007441,0.000000
7.110000,0.034256,-1293.194702,-0.004303,-0.000151,-0.003826,0.152378,0.007763,-0.038258,-1293.194702,-0.002447,0.000000
7.410000,0.004471,-1293.239136,-0.004083,0.000053,0.001352,0.019887,0.001013,0.013520,-1293.239136,0.002550,0.000000
7.710001,0.019363,-1293.194702,-0.003906,0.000244,0.006200,0.086133,0.004388,0.061997,-1293.194702,0.007544,0.000000
8.010000,-0.000748,-1293.150269,-0.003686,0.000446,0.011333,-0.003326,-0.000169,0.113335,-1293.150269,0.012540,0.000000
8.310000,-0.017502,-1293.150269,-0.003475,0.000643,0.016330,-0.077852,-0.003966,0.163296,-1293.150269,0.017535,0.000000
8.610001,-0.021599,-1293.194702,-0.003272,0.000839,0.021298,-0.096076,-0.004894,0.212984,-1293.194702,0.022547,0.000000
8.910001,0.042824,-1293.194702,-0.003091,0.001029,0.026137,0.190490,0.009704,0.261370,-1293.194702,0.027542,0.000000
9.210000,0.084526,-1293.194702,-0.002979,-0.000000,-0.000000,0.375991,0.019154,-0.000000,-1293.194702,0.000224,0.000000
9.510000,0.084900,-1293.150269,-0.002975,-0.000000,-0.000000,0.377654,0.019239,-0.000000,-1293.150269,0.000224,0.000000
9.810000,0.102402,-1293.239136,-0.002992,-0.000000,-0.000000,0.455506,0.023205,-0.000000,-1293.239136,0.000606,0.000000
10.110001,0.088623,-1293.239136,-0.002979,0.000003,0.000068,0.394215,0.020082,0.000681,-1293.239136,0.001101,0.000000
10.410001,0.120651,-1293.194702,-0.002992,0.000019,0.000484,0.536684,0.027340,0.004845,-1293.194702,0.001603,0.000000
10.710000,0.198471,-1293.150269,-0.002958,0.000039,0.000989,0.882843,0.044974,0.009886,-1293.150269,0.002106,0.000000
11.010000,0.337746,-1293.150269,-0.002932,0.000064,0.001629,1.502368,0.076534,0.016290,-1293.150269,0.002601,0.000000
11.310000,0.544785,-1293.150269,-0.002906,0.000083,0.002106,2.423323,0.123450,0.021059,-1293.150269,0.003104,0.000000
11.610001,0.850502,-1293.194702,-0.002915,0.000105,0.002662,3.783222,0.192727,0.026615,-1293.194702,0.003606,0.000000
11.910001,1.127541,-1293.150269,-0.002902,0.000118,0.003008,5.015551,0.255504,0.030082,-1293.150269,0.004101,0.000000
12.210001,1.523003,-1293.150269,-0.002880,0.000139,0.003529,6.774654,0.345117,0.035290,-1293.150269,0.004604,0.000000
12.510000,2.325836,-1293.194702,-0.002846,0.000167,0.004241,10.345836,0.527042,0.042406,-1293.194702,0.005107,0.000000
12.810000,2.814766,-1293.150269,-0.002833,0.000187,0.004743,12.520704,0.637835,0.047432,-1293.150269,0.005602,0.000000
13.110001,3.347260,-1293.105713,-0.002811,0.000204,0.005185,14.889354,0.758500,0.051853,-1293.105713,0.006104,0.000000
13.410001,4.076736,-1293.150269,-0.002798,0.000224,0.005697,18.134230,0.923802,0.056970,-1293.150269,0.006607,0.000000
13.710001,4.773445,-1293.194702,-0.002790,0.000243,0.006174,21.233345,1.081678,0.061739,-1293.194702,0.007102,0.000000
14.010000,5.305191,-1293.061279,-0.002777,0.000258,0.006546,23.598669,1.202173,0.065464,-1293.061279,0.007605,0.000000
14.310000,5.873802,-1293.150269,-0.002759,0.000273,0.006937,26.127977,1.331023,0.069370,-1293.150269,0.008107,0.000000
14.610001,7.073959,-1293.194702,-0.002738,0.000302,0.007674,31.466543,1.602982,0.076743,-1293.194702,0.008602,0.000000
14.910001,7.587090,-1293.150269,-0.002725,0.000321,0.008151,33.749062,1.719259,0.081511,-1293.150269,0.009105,0.000000
15.210001,8.310234,-1293.194702,-0.002699,0.000341,0.008663,36.965767,1.883126,0.086629,-1293.194702,0.009608,0.000000
15.510001,9.069504,-1293.150269,-0.002712,0.000360,0.009156,40.343166,2.055179,0.091564,-1293.150269,0.010103,0.000000
15.810000,9.430702,-1293.105713,-0.002677,0.000371,0.009417,41.949860,2.137028,0.094168,-1293.105713,0.010605,0.000000
16.110001,10.267426,-1293.105713,-0.002673,0.000391,0.009921,45.671791,2.326632,0.099210,-1293.105713,0.011108,0.000000
16.410000,11.380821,-1293.150269,-0.002660,0.000417,0.010596,50.624420,2.578931,0.105962,-1293.150269,0.011603,0.000000
16.710001,12.000816,-1293.194702,-0.002643,0.000434,0.011013,53.382298,2.719424,0.110125,-1293.194702,0.012106,0.000000
17.010000,12.688217,-1293.150269,-0.002621,0.000453,0.011499,56.440010,2.875191,0.114985,-1293.150269,0.012608,0.000000
17.310001,13.656387,-1293.061279,-0.002617,0.000472,0.012001,60.746643,3.094582,0.120011,-1293.061279,0.013103,0.000000
17.610001,14.512100,-1293.150269,-0.002604,0.000494,0.012557,64.553047,3.288489,0.125568,-1293.150269,0.013606,0.000000
17.910002,15.084061,-1293.150269,-0.002570,0.000512,0.013008,67.097252,3.418097,0.130079,-1293.150269,0.014109,0.000000
18.210001,15.857857,-1293.150269,-0.002557,0.000534,0.013571,70.539268,3.593442,0.135711,-1293.150269,0.014604,0.000000
18.510000,16.542648,-1293.150269,-0.002539,0.000553,0.014057,73.585373,3.748618,0.140571,-1293.150269,0.015106,0.000000
18.810001,17.184616,-1293.150269,-0.002531,0.000574,0.014578,76.440987,3.894090,0.145779,-1293.150269,0.015609,0.000000
19.110001,17.336548,-1293.105713,-0.002527,0.000587,0.014916,77.116814,3.928518,0.149155,-1293.105713,0.016104,0.000000
19.410002,17.972183,-1293.150269,-0.002496,0.000603,0.015315,79.944267,4.072555,0.153152,-1293.150269,0.016607,0.000000
19.710001,18.885612,-1293.150269,-0.002479,0.000627,0.015913,84.007401,4.279541,0.159132,-1293.150269,0.017109,0.000000
20.010000,19.264320,-1293.150269,-0.002466,0.000645,0.016372,85.691978,4.365357,0.163719,-1293.150269,0.017604,0.000000
20.310001,20.308823,-1293.150269,-0.002440,0.000670,0.017014,90.338158,4.602045,0.170139,-1293.150269,0.018107,0.000000
20.610001,21.303055,-1293.150269,-0.002432,0.000694,0.017621,94.760719,4.827341,0.176210,-1293.150269,0.018610,0.000000
20.910002,21.410301,-1293.150269,-0.002406,0.000711,0.018055,95.237778,4.851644,0.180555,-1293.150269,0.019105,0.000000
21.210001,21.596115,-1293.194702,-0.002393,0.000728,0.018488,96.064316,4.893750,0.184885,-1293.194702,0.019607,0.000000
21.510000,22.947083,-1293.061279,-0.002363,0.000752,0.019112,102.073723,5.199883,0.191122,-1293.061279,0.020110,0.000000
21.810001,22.994003,-1293.105713,-0.002345,0.000768,0.019503,102.282433,5.210516,0.195028,-1293.105713,0.020605,0.000000
22.110001,23.580482,-1293.150269,-0.002341,0.000791,0.020101,104.891228,5.343414,0.201008,-1293.150269,0.021108,0.000000
22.410002,24.007973,-1293.105713,-0.002311,0.000806,0.020475,106.792793,5.440284,0.204748,-1293.105713,0.021610,0.000000
22.710001,24.645470,-1293.150269,-0.002307,0.000830,0.021073,109.628525,5.584743,0.210728,-1293.150269,0.022105,0.000000
23.010000,24.918045,-1293.105713,-0.002264,0.000846,0.021489,110.841003,5.646510,0.214891,-1293.105713,0.022608,0.000000
23.310001,25.839668,-1293.150269,-0.002246,0.000871,0.022122,114.940582,5.855353,0.221220,-1293.150269,0.023101,0.000000
23.610001,26.426903,-1293.105713,-0.002225,0.000890,0.022617,117.552734,5.988422,0.226170,-1293.105713,0.023606,0.000000
23.910002,26.681602,-1293.150269,-0.002207,0.000910,0.023120,118.685692,6.046137,0.231197,-1293.150269,0.024108,0.000000
24.210001,26.241089,-1293.150269,-0.002190,0.000919,0.023345,116.726196,5.946316,0.233452,-1293.150269,0.024602,0.000000
24.510000,27.837822,-1293.239136,-0.002169,0.000949,0.024099,123.828819,6.308141,0.240992,-1293.239136,0.025106,0.000000
24.810001,28.225090,-1293.105713,-0.002160,0.000970,0.024629,125.551468,6.395897,0.246291,-1293.105713,0.025609,0.000000
25.110001,28.451866,-1293.194702,-0.002143,0.000986,0.025045,126.560219,6.447285,0.250454,-1293.194702,0.026102,0.000000
25.410002,29.282623,-1293.239136,-0.002117,0.001004,0.025495,130.255615,6.635538,0.254951,-1293.239136,0.026606,0.000000
25.710001,29.819588,-1293.194702,-0.002082,0.001025,0.026025,132.644150,6.757215,0.260249,-1293.194702,0.027109,0.000000
26.010002,30.697266,-1293.239136,-0.002070,0.001046,0.026571,136.548264,6.956100,0.265715,-1293.239136,0.027602,0.000000
26.310001,30.822014,-1293.194702,-0.002048,0.001060,0.026935,137.103165,6.984368,0.269348,-1293.194702,0.028107,0.000000
26.610001,31.959610,-1293.150269,-0.002031,0.001087,0.027602,142.163452,7.242151,0.276025,-1293.150269,0.028609,0.000000
26.910002,31.829285,-1293.150269,-0.002013,0.001097,0.027872,141.583725,7.212619,0.278720,-1293.150269,0.029103,0.000000
27.210001,33.286377,-1293.150269,-0.001996,0.001126,0.028609,148.065201,7.542801,0.286093,-1293.150269,0.029607,0.000000
27.510002,32.913628,-1293.194702,-0.001979,0.001135,0.028835,146.407135,7.458335,0.288348,-1293.194702,0.030110,0.000000
27.810001,33.437561,-1293.150269,-0.001949,0.001153,0.029294,148.737701,7.577060,0.292936,-1293.150269,0.030603,0.000000
28.110001,35.176910,-1293.105713,-0.001936,0.001183,0.030057,156.474716,7.971202,0.300566,-1293.105713,0.031107,0.000000
28.410002,35.723549,-1293.194702,-0.001914,0.001203,0.030568,158.906281,8.095072,0.305683,-1293.194702,0.031610,0.000000
28.710001,36.282112,-1293.150269,-0.001897,0.001221,0.031019,161.390900,8.221644,0.310195,-1293.150269,0.032103,0.000000
29.010002,37.043610,-1293.194702,-0.001876,0.001241,0.031515,164.778198,8.394201,0.315145,-1293.194702,0.032608,0.000000
29.310001,37.662125,-1293.194702,-0.001867,0.001260,0.031991,167.529495,8.534360,0.319914,-1293.194702,0.033110,0.000000
29.610001,38.195358,-1293.194702,-0.001837,0.001276,0.032399,169.901443,8.655191,0.323987,-1293.194702,0.033604,0.000000
29.910002,39.173958,-1293.150269,-0.001824,0.001298,0.032962,174.254471,8.876946,0.329619,-1293.150269,0.034108,0.000000
30.210001,39.504250,-1293.239136,-0.001811,0.001316,0.033439,175.723679,8.951792,0.334388,-1293.239136,0.034611,0.000000
30.510002,40.699562,-1293.150269,-0.001781,0.001340,0.034038,181.040695,9.222652,0.340383,-1293.150269,0.035104,0.000000
30.810001,41.220886,-1293.105713,-0.001772,0.001356,0.034446,183.359665,9.340787,0.344456,-1293.105713,0.035607,0.000000
31.110001,41.524368,-1293.150269,-0.001746,0.001376,0.034957,184.709610,9.409556,0.349573,-1293.150269,0.036111,0.000000
31.410002,42.141762,-1293.150269,-0.001729,0.001394,0.035399,187.455917,9.549459,0.353994,-1293.150269,0.036604,0.000000
31.710001,42.876457,-1293.239136,-0.001716,0.001411,0.035841,190.724014,9.715944,0.358414,-1293.239136,0.037107,0.000000
32.010002,44.591972,-1293.239136,-0.001686,0.001437,0.036509,198.354996,10.104685,0.365091,-1293.239136,0.037611,0.000000
32.310001,45.494980,-1293.239136,-0.001681,0.001461,0.037107,202.371780,10.309310,0.371071,-1293.239136,0.038105,0.000000
32.610001,45.626801,-1293.194702,-0.001664,0.001474,0.037437,202.958145,10.339181,0.374372,-1293.194702,0.038607,0.000000
32.910000,47.093575,-1293.194702,-0.001647,0.001500,0.038088,209.482681,10.671556,0.380882,-1293.194702,0.039112,0.000000
33.210003,47.549728,-1293.150269,-0.001630,0.001516,0.038504,211.511749,10.774922,0.385045,-1293.150269,0.039605,0.000000
33.510002,47.629417,-1293.105713,-0.001608,0.001528,0.038807,211.866226,10.792980,0.388073,-1293.105713,0.040108,0.000000
33.810001,49.603363,-1293.150269,-0.001595,0.001561,0.039649,220.646774,11.240283,0.396490,-1293.150269,0.040612,0.000000
34.110001,50.352203,-1293.105713,-0.001569,0.001578,0.040082,223.977783,11.409972,0.400820,-1293.105713,0.041105,0.000000
34.410000,51.041466,-1293.150269,-0.001561,0.001597,0.040559,227.043777,11.566162,0.405589,-1293.150269,0.041608,0.000000
34.710003,52.047615,-1293.194702,-0.001544,0.001619,0.041124,231.519348,11.794158,0.411236,-1293.194702,0.042112,0.000000
35.010002,52.977806,-1293.105713,-0.001531,0.001638,0.041608,235.657043,12.004942,0.416081,-1293.105713,0.042606,0.000000
35.310001,53.467476,-1293.194702,-0.001513,0.001654,0.042008,237.835205,12.115903,0.420078,-1293.194702,0.043108,0.000000
35.610001,54.042786,-1293.194702,-0.001513,0.001672,0.042476,240.394318,12.246270,0.424756,-1293.194702,0.043613,0.000000
35.910000,55.897575,-1293.150269,-0.001492,0.001696,0.043074,248.644836,12.666572,0.430736,-1293.150269,0.044106,0.000000
36.210003,56.643806,-1293.194702,-0.001470,0.001714,0.043543,251.964233,12.835670,0.435429,-1293.194702,0.044609,0.000000
36.510002,57.580330,-1293.150269,-0.001453,0.001733,0.044011,256.130096,13.047890,0.440108,-1293.150269,0.045104,0.000000
36.810001,59.089928,-1293.150269,-0.001440,0.001756,0.044592,262.845123,13.389969,0.445921,-1293.150269,0.045606,0.000000
37.110001,59.601936,-1293.194702,-0.001418,0.001769,0.044922,265.122650,13.505991,0.449222,-1293.194702,0.046109,0.000000
37.410004,60.206299,-1293.194702,-0.001414,0.001787,0.045390,267.811005,13.642942,0.453900,-1293.194702,0.046604,0.000000
37.710003,61.699883,-1293.150269,-0.001393,0.001808,0.045911,274.454773,13.981394,0.459108,-1293.150269,0.047107,0.000000
38.010002,62.544052,-1293.150269,-0.001388,0.001826,0.046379,278.209839,14.172685,0.463786,-1293.150269,0.047609,0.000000
38.310001,63.772881,-1293.194702,-0.001367,0.001847,0.046907,283.675934,14.451141,0.469070,-1293.194702,0.048104,0.000000
38.610001,65.017723,-1293.105713,-0.001367,0.001867,0.047419,289.213287,14.733227,0.474187,-1293.105713,0.048607,0.000000
38.910004,65.888695,-1293.150269,-0.001350,0.001876,0.047662,293.087555,14.930592,0.476624,-1293.150269,0.047870,0.000000
39.210003,64.861702,-1293.194702,-0.001345,0.001882,0.047800,288.519257,14.697871,0.478002,-1293.194702,294.500488,0.000000
39.510002,65.227364,-1293.194702,-0.001337,0.001888,0.047949,290.145813,14.780732,0.479486,-1293.194702,294.500488,0.000000
39.810001,64.981224,-1293.194702,-0.001315,0.001899,0.048242,289.050934,14.724956,0.482423,-1293.194702,294.500488,0.000000
40.110001,65.117897,-1293.105713,-0.001324,0.001911,0.048547,289.658875,14.755926,0.485466,-1293.105713,294.500488,0.000000
40.410004,64.903038,-1293.150269,-0.001311,0.001914,0.048625,288.703125,14.707239,0.486253,-1293.150269,294.500488,0.000000
40.710003,65.139488,-1293.150269,-0.001293,0.001924,0.048858,289.754913,14.760818,0.488585,-1293.150269,294.500488,0.000000
41.010002,65.999672,-1293.194702,-0.001293,0.001936,0.049170,293.581207,14.955739,0.491703,-1293.194702,294.500488,0.000000
41.310001,65.186775,-1293.194702,-0.001285,0.001935,0.049154,289.965271,14.771534,0.491537,-1293.194702,294.500488,0.000000
41.610001,65.502174,-1293.150269,-0.001281,0.001948,0.049491,291.368225,14.843005,0.494913,-1293.150269,294.500488,0.000000
41.910004,64.914574,-1293.239136,-0.001268,0.001949,0.049509,288.754456,14.709852,0.495095,-1293.239136,294.500488,0.000000
42.210003,64.873238,-1293.194702,-0.001259,0.001955,0.049665,288.570587,14.700485,0.496654,-1293.194702,294.500488,0.000000
42.510002,65.629524,-1293.150269,-0.001250,0.001968,0.049986,291.934692,14.871863,0.499864,-1293.150269,294.500488,0.000000
42.810001,65.051613,-1293.150269,-0.001237,0.001968,0.049995,289.364014,14.740906,0.499954,-1293.150269,294.500488,0.000000
43.110001,65.568840,-1293.150269,-0.001237,0.001980,0.050282,291.664764,14.858112,0.502816,-1293.150269,294.500488,0.000000
43.410004,65.022194,-1293.150269,-0.001237,0.001980,0.050282,289.233154,14.734240,0.502816,-1293.150269,294.500488,0.000000
43.710003,64.442039,-1293.150269,-0.001229,0.001980,0.050282,286.652496,14.602776,0.502816,-1293.150269,294.500488,0.000000
44.010002,66.220116,-1293.150269,-0.001207,0.001961,0.049812,294.561798,15.005692,0.498122,-1293.150269,294.500488,0.000000
44.310001,65.577766,-1293.150269,-0.001207,0.001961,0.049821,291.704468,14.860134,0.498213,-1293.150269,294.500488,0.000000
44.610001,65.003578,-1293.194702,-0.001194,0.001983,0.050368,289.150360,14.730021,0.503679,-1293.194702,294.500488,0.000000
44.910004,65.464195,-1293.150269,-0.001207,0.002008,0.050992,291.199280,14.834398,0.509916,-1293.150269,294.500488,0.000000
45.210003,65.127571,-1293.194702,-0.001190,0.002010,0.051061,289.701904,14.758119,0.510613,-1293.194702,294.500488,0.000000
45.510002,65.161079,-1293.150269,-0.001194,0.002015,0.051182,289.850952,14.765712,0.511824,-1293.150269,294.500488,0.000000
45.810001,65.176720,-1293.150269,-0.001181,0.002021,0.051331,289.920532,14.769256,0.513307,-1293.150269,294.500488,0.000000
46.110001,65.072838,-1293.194702,-0.001186,0.002025,0.051426,289.458435,14.745716,0.514261,-1293.194702,294.500488,0.000000
46.410004,65.508888,-1293.194702,-0.001168,0.002032,0.051608,291.398102,14.844526,0.516078,-1293.194702,294.500488,0.000000
46.710003,65.046761,-1293.194702,-0.001164,0.002032,0.051608,289.342438,14.739807,0.516078,-1293.194702,294.500488,0.000000
47.010002,64.631203,-1293.194702,-0.001173,0.002032,0.051608,287.493958,14.645640,0.516078,-1293.194702,294.500488,0.000000
47.310001,66.579079,-1293.194702,-0.001147,0.001982,0.050342,296.158539,15.087035,0.503421,-1293.194702,294.500488,0.000000
47.610001,66.041008,-1293.150269,-0.001143,0.001982,0.050342,293.765076,14.965106,0.503421,-1293.150269,294.500488,0.000000
47.910004,65.563988,-1293.239136,-0.001143,0.001983,0.050377,291.643188,14.857012,0.503770,-1293.239136,294.500488,0.000000
48.210003,65.202415,-1293.239136,-0.001134,0.002039,0.051789,290.034821,14.775078,0.517895,-1293.239136,294.500488,0.000000
48.510002,65.568459,-1293.105713,-0.001147,0.002058,0.052285,291.663055,14.858025,0.522845,-1293.105713,294.500488,0.000000
48.810001,65.255669,-1293.061279,-0.001143,0.002058,0.052285,290.271698,14.787147,0.522845,-1293.061279,294.500488,0.000000
49.110001,64.908241,-1293.105713,-0.001130,0.002059,0.052310,288.726288,14.708417,0.523103,-1293.105713,294.500488,0.000000
49.410004,65.321571,-1293.194702,-0.001125,0.002069,0.052545,290.564850,14.802079,0.525449,-1293.194702,294.500488,0.000000
49.710003,65.057198,-1293.194702,-0.001121,0.002070,0.052580,289.388855,14.742171,0.525798,-1293.194702,294.500488,0.000000
50.010002,64.885902,-1293.194702,-0.001121,0.002072,0.052622,288.626923,14.703356,0.526222,-1293.194702,294.500488,0.000000
50.310001,65.785927,-1293.105713,-0.001125,0.002080,0.052822,292.630432,14.907305,0.528220,-1293.105713,294.500488,0.000000
50.610001,65.352486,-1293.194702,-0.001112,0.002080,0.052822,290.702362,14.809085,0.528220,-1293.194702,294.500488,0.000000
50.910004,64.965584,-1293.150269,-0.001099,0.002080,0.052822,288.981354,14.721412,0.528220,-1293.150269,294.500488,0.000000
51.210003,65.343925,-1293.194702,-0.001095,0.002091,0.053117,290.664307,14.807145,0.531172,-1293.194702,294.500488,0.000000
51.510002,65.080284,-1293.105713,-0.001082,0.002091,0.053117,289.491577,14.747403,0.531172,-1293.105713,294.500488,0.000000
51.810001,64.981224,-1293.150269,-0.001082,0.002095,0.053220,289.050934,14.724956,0.532202,-1293.150269,294.500488,0.000000
52.110001,65.355095,-1293.194702,-0.001087,0.002102,0.053385,290.713989,14.809676,0.533852,-1293.194702,294.500488,0.000000
52.410004,65.149910,-1293.239136,-0.001099,0.002102,0.053394,289.801270,14.763181,0.533943,-1293.239136,294.500488,0.000000
52.710003,65.380043,-1293.150269,-0.001069,0.002108,0.053541,290.824951,14.815329,0.535411,-1293.150269,294.500488,0.000000
53.010002,65.137260,-1293.150269,-0.001078,0.002108,0.053550,289.744995,14.760314,0.535502,-1293.150269,294.500488,0.000000
53.310001,65.078423,-1293.150269,-0.001078,0.002112,0.053637,289.483276,14.746982,0.536365,-1293.150269,294.500488,0.000000
53.610004,65.038200,-1293.150269,-0.001069,0.002114,0.053689,289.304352,14.737866,0.536895,-1293.150269,294.500488,0.000000
53.910004,65.109703,-1293.150269,-0.001074,0.002118,0.053794,289.622437,14.754069,0.537940,-1293.150269,294.500488,0.000000
54.210003,64.976753,-1293.150269,-0.001065,0.002119,0.053820,289.031036,14.723943,0.538197,-1293.150269,294.500488,0.000000
54.510002,64.999855,-1293.194702,-0.001065,0.002122,0.053897,289.133789,14.729177,0.538969,-1293.194702,294.500488,0.000000
54.810001,65.172997,-1293.194702,-0.001061,0.002127,0.054018,289.903961,14.768412,0.540180,-1293.194702,294.500488,0.000000
55.110004,64.973778,-1293.194702,-0.001056,0.002128,0.054062,289.017792,14.723269,0.540619,-1293.194702,294.500488,0.000000
55.410004,65.546486,-1293.239136,-0.001043,0.002135,0.054218,291.565338,14.853046,0.542179,-1293.239136,294.500488,0.000000
55.710003,65.271675,-1293.194702,-0.001030,0.002135,0.054227,290.342926,14.790773,0.542269,-1293.194702,294.500488,0.000000
56.010002,65.205391,-1293.194702,-0.001043,0.002141,0.054383,290.048065,14.775753,0.543829,-1293.194702,294.500488,0.000000
56.310001,65.332756,-1293.150269,-0.001039,0.002141,0.054383,290.614624,14.804614,0.543829,-1293.150269,294.500488,0.000000
56.610004,65.243004,-1293.194702,-0.001039,0.002144,0.054453,290.215363,14.784276,0.544525,-1293.194702,294.500488,0.000000
56.910004,65.218056,-1293.150269,-0.001030,0.002146,0.054513,290.104401,14.778623,0.545131,-1293.150269,294.500488,0.000000
57.210003,65.242638,-1293.150269,-0.001030,0.002150,0.054599,290.213745,14.784193,0.545994,-1293.150269,294.500488,0.000000
57.510002,65.160347,-1293.194702,-0.001026,0.002150,0.054608,289.847687,14.765546,0.546085,-1293.194702,294.500488,0.000000
57.810001,65.121239,-1293.194702,-0.001018,0.002155,0.054748,289.673737,14.756683,0.547477,-1293.194702,294.500488,0.000000
58.110004,65.488396,-1293.239136,-0.001022,0.002158,0.054808,291.306946,14.839883,0.548083,-1293.239136,294.500488,0.000000
58.410004,65.282112,-1293.239136,-0.001018,0.002158,0.054808,290.389343,14.793138,0.548083,-1293.239136,294.500488,0.000000
58.710003,65.148048,-1293.150269,-0.001018,0.002161,0.054895,289.792999,14.762759,0.548946,-1293.150269,294.500488,0.000000
59.010002,65.077675,-1293.239136,-0.001022,0.002161,0.054895,289.479950,14.746812,0.548946,-1293.239136,294.500488,0.000000
59.310001,65.145439,-1293.194702,-0.001022,0.002164,0.054973,289.781372,14.762168,0.549733,-1293.194702,294.500488,0.000000
59.610004,65.059059,-1293.194702,-0.001013,0.002167,0.055051,289.397156,14.742594,0.550505,-1293.194702,294.500488,0.000000
59.910004,65.005440,-1293.239136,-0.001009,0.002167,0.055051,289.158630,14.730443,0.550505,-1293.239136,294.500488,0.000000
60.210003,64.993141,-1293.194702,-0.001000,0.002170,0.055120,289.103943,14.727656,0.551202,-1293.194702,294.500488,0.000000
60.510002,64.795036,-1293.239136,-0.001013,0.002172,0.055172,288.222717,14.682765,0.551717,-1293.239136,294.500488,0.000000
60.810001,64.936546,-1293.194702,-0.001000,0.002174,0.055216,288.852173,14.714832,0.552156,-1293.194702,294.500488,0.000000
61.110004,65.488029,-1293.194702,-0.001005,0.002182,0.055423,291.305298,14.839800,0.554230,-1293.194702,294.500488,0.000000
61.410004,65.272423,-1293.194702,-0.001000,0.002180,0.055381,290.346252,14.790943,0.553806,-1293.194702,294.500488,0.000000
61.710003,65.053474,-1293.194702,-0.000992,0.002180,0.055381,289.372314,14.741328,0.553806,-1293.194702,294.500488,0.000000
62.010002,64.838234,-1293.105713,-0.000987,0.002180,0.055381,288.414856,14.692554,0.553806,-1293.105713,294.500488,0.000000
62.310001,65.857048,-1293.194702,-0.000996,0.002189,0.055588,292.946777,14.923420,0.555880,-1293.194702,294.500488,0.000000
62.610004,65.597878,-1293.239136,-0.000992,0.002189,0.055588,291.793945,14.864691,0.555880,-1293.239136,294.500488,0.000000
62.910004,65.365150,-1293.194702,-0.000983,0.002189,0.055588,290.758698,14.811954,0.555880,-1293.194702,294.500488,0.000000
63.210003,65.123482,-1293.194702,-0.000992,0.002189,0.055588,289.683716,14.757192,0.555880,-1293.194702,294.500488,0.000000
63.510002,65.727089,-1293.239136,-0.000983,0.002200,0.055874,292.368683,14.893970,0.558741,-1293.239136,294.500488,0.000000
63.810001,65.572563,-1293.194702,-0.000979,0.002200,0.055874,291.681335,14.858955,0.558741,-1293.194702,294.500488,0.000000
64.110001,65.415413,-1293.194702,-0.000987,0.002200,0.055874,290.982300,14.823344,0.558741,-1293.194702,294.500488,0.000000
64.410004,65.235558,-1293.194702,-0.000961,0.002200,0.055874,290.182251,14.782589,0.558741,-1293.194702,294.500488,0.000000
64.710007,65.028145,-1293.194702,-0.000974,0.002200,0.055874,289.259644,14.735588,0.558741,-1293.194702,294.500488,0.000000
65.010002,64.834511,-1293.194702,-0.000979,0.002200,0.055874,288.398315,14.691710,0.558741,-1293.194702,294.500488,0.000000
65.310005,64.652794,-1293.150269,-0.000970,0.002200,0.055874,287.589996,14.650533,0.558741,-1293.150269,294.500488,0.000000
65.610001,66.372780,-1293.239136,-0.000953,0.002198,0.055823,295.240875,15.040287,0.558227,-1293.239136,294.500488,0.000000
65.910004,66.141167,-1293.150269,-0.000961,0.002198,0.055823,294.210602,14.987803,0.558227,-1293.150269,294.500488,0.000000
66.210007,65.881996,-1293.194702,-0.000944,0.002198,0.055823,293.057770,14.929073,0.558227,-1293.194702,294.500488,0.000000
66.510002,65.733788,-1293.194702,-0.000949,0.002198,0.055823,292.398499,14.895489,0.558227,-1293.194702,294.500488,0.000000
66.810005,65.504417,-1293.194702,-0.000957,0.002198,0.055823,291.378204,14.843513,0.558227,-1293.194702,294.500488,0.000000
67.110001,65.278389,-1293.194702,-0.000940,0.002198,0.055832,290.372772,14.792295,0.558317,-1293.194702,294.500488,0.000000
67.410004,65.057564,-1293.239136,-0.000953,0.002198,0.055832,289.390503,14.742254,0.558317,-1293.239136,294.500488,0.000000
67.710007,65.560646,-1293.194702,-0.000949,0.002223,0.056465,291.628326,14.856255,0.564646,-1293.194702,294.500488,0.000000
68.010002,65.406471,-1293.194702,-0.000949,0.002223,0.056465,290.942505,14.821319,0.564646,-1293.194702,294.500488,0.000000
68.310005,65.259026,-1293.239136,-0.000931,0.002223,0.056465,290.286652,14.787907,0.564646,-1293.239136,294.500488,0.000000
68.610001,65.086617,-1293.239136,-0.000936,0.002223,0.056474,289.519745,14.748837,0.564737,-1293.239136,294.500488,0.000000
68.910004,65.319710,-1293.150269,-0.000944,0.002230,0.056646,290.556580,14.801658,0.566463,-1293.150269,294.500488,0.000000
69.210007,65.295509,-1293.150269,-0.000940,0.002230,0.056646,290.448944,14.796174,0.566463,-1293.150269,294.500488,0.000000
69.510002,65.191994,-1293.239136,-0.000957,0.002230,0.056646,289.988464,14.772717,0.566463,-1293.239136,294.500488,0.000000
69.810005,65.241524,-1293.150269,-0.000918,0.002233,0.056716,290.208801,14.783940,0.567159,-1293.150269,294.500488,0.000000
70.110001,65.159966,-1293.150269,-0.000918,0.002234,0.056742,289.846008,14.765460,0.567416,-1293.150269,294.500488,0.000000
70.410004,65.127205,-1293.194702,-0.000918,0.002236,0.056786,289.700287,14.758035,0.567855,-1293.194702,294.500488,0.000000
70.710007,65.146935,-1293.194702,-0.000940,0.002238,0.056846,289.788025,14.762506,0.568461,-1293.194702,294.500488,0.000000
71.010002,65.072456,-1293.194702,-0.000936,0.002238,0.056846,289.456757,14.745629,0.568461,-1293.194702,294.500488,0.000000
71.310005,65.116768,-1293.150269,-0.000931,0.002241,0.056923,289.653839,14.755671,0.569233,-1293.150269,294.500488,0.000000
71.610001,65.073952,-1293.239136,-0.000923,0.002241,0.056932,289.463379,14.745968,0.569324,-1293.239136,294.500488,0.000000
71.910004,65.127205,-1293.239136,-0.000918,0.002244,0.056993,289.700287,14.758035,0.569929,-1293.239136,294.500488,0.000000
72.210007,65.032616,-1293.194702,-0.000927,0.002244,0.056993,289.279510,14.736601,0.569929,-1293.194702,294.500488,0.000000
72.510002,64.972298,-1293.194702,-0.000923,0.002245,0.057019,289.011200,14.722934,0.570187,-1293.194702,294.500488,0.000000
72.810005,65.238533,-1293.194702,-0.000914,0.002250,0.057141,290.195496,14.783262,0.571413,-1293.194702,294.500488,0.000000
73.110001,65.166298,-1293.194702,-0.000910,0.002250,0.057141,289.874176,14.766894,0.571413,-1293.194702,294.500488,0.000000
73.410004,65.043419,-1293.150269,-0.000914,0.002250,0.057158,289.327576,14.739050,0.571580,-1293.150269,294.500488,0.000000
73.710007,65.016975,-1293.194702,-0.000910,0.002252,0.057193,289.209961,14.733057,0.571928,-1293.194702,294.500488,0.000000
74.010002,65.097404,-1293.239136,-0.000901,0.002256,0.057314,289.567719,14.751283,0.573139,-1293.239136,294.500488,0.000000
74.310005,65.257164,-1293.150269,-0.000918,0.002256,0.057314,290.278351,14.787484,0.573139,-1293.150269,294.500488,0.000000
74.610001,65.152153,-1293.150269,-0.000901,0.002256,0.057314,289.811249,14.763689,0.573139,-1293.150269,294.500488,0.000000
74.910004,65.021812,-1293.194702,-0.000910,0.002258,0.057349,289.231476,14.734154,0.573487,-1293.194702,294.500488,0.000000
75.210007,65.342796,-1293.194702,-0.000901,0.002262,0.057453,290.659271,14.806889,0.574532,-1293.194702,294.500488,0.000000
75.510002,65.274666,-1293.283691,-0.000910,0.002262,0.057453,290.356201,14.791451,0.574532,-1293.283691,294.500488,0.000000
75.810005,65.193855,-1293.239136,-0.000905,0.002263,0.057479,289.996765,14.773139,0.574789,-1293.239136,294.500488,0.000000
76.110001,65.112679,-1293.283691,-0.000892,0.002263,0.057488,289.635651,14.754745,0.574880,-1293.283691,294.500488,0.000000
76.410004,65.488777,-1293.239136,-0.000888,0.002269,0.057635,291.308624,14.839969,0.576349,-1293.239136,294.500488,0.000000
76.710007,65.416908,-1293.283691,-0.000901,0.002269,0.057635,290.988953,14.823683,0.576349,-1293.283691,294.500488,0.000000
77.010002,65.301842,-1293.194702,-0.000892,0.002269,0.057635,290.477112,14.797609,0.576349,-1293.194702,294.500488,0.000000
77.310005,65.232201,-1293.194702,-0.000892,0.002270,0.057661,290.167328,14.781828,0.576606,-1293.194702,294.500488,0.000000
77.610001,65.231087,-1293.194702,-0.000892,0.002271,0.057686,290.162354,14.781575,0.576863,-1293.194702,294.500488,0.000000
77.910004,65.231834,-1293.239136,-0.000901,0.002273,0.057739,290.165680,14.781745,0.577393,-1293.239136,294.500488,0.000000
78.210007,65.195717,-1293.194702,-0.000880,0.002274,0.057765,290.005035,14.773561,0.577651,-1293.194702,294.500488,0.000000
78.510002,65.215828,-1293.239136,-0.000875,0.002276,0.057809,290.094482,14.778117,0.578090,-1293.239136,294.500488,0.000000
78.810005,65.236671,-1293.194702,-0.000880,0.002277,0.057826,290.187195,14.782842,0.578256,-1293.194702,294.500488,0.000000
79.110001,65.132042,-1293.194702,-0.000875,0.002277,0.057826,289.721802,14.759132,0.578256,-1293.194702,294.500488,0.000000
79.410004,65.090340,-1293.239136,-0.000884,0.002278,0.057870,289.536285,14.749682,0.578695,-1293.239136,294.500488,0.000000
79.710007,65.117897,-1293.105713,-0.000901,0.002280,0.057912,289.658875,14.755926,0.579119,-1293.105713,294.500488,0.000000
80.010002,65.116768,-1293.150269,-0.000871,0.002281,0.057939,289.653839,14.755671,0.579392,-1293.150269,294.500488,0.000000
80.310005,65.409828,-1293.194702,-0.000888,0.002285,0.058051,290.957458,14.822079,0.580512,-1293.194702,294.500488,0.000000
80.610001,65.351738,-1293.194702,-0.000884,0.002285,0.058051,290.699036,14.808915,0.580512,-1293.194702,294.500488,0.000000
80.910004,65.268333,-1293.194702,-0.000871,0.002285,0.058051,290.328033,14.790016,0.580512,-1293.194702,294.500488,0.000000
81.210007,65.213219,-1293.194702,-0.000862,0.002286,0.058060,290.082886,14.777527,0.580603,-1293.194702,294.500488,0.000000
81.510002,65.210609,-1293.194702,-0.000862,0.002288,0.058121,290.071289,14.776936,0.581208,-1293.194702,294.500488,0.000000
81.810005,65.197578,-1293.194702,-0.000880,0.002289,0.058137,290.013306,14.773982,0.581375,-1293.194702,294.500488,0.000000
82.110001,65.134651,-1293.150269,-0.000858,0.002290,0.058165,289.733398,14.759723,0.581648,-1293.150269,294.500488,0.000000
82.410004,65.191246,-1293.283691,-0.000880,0.002291,0.058198,289.985138,14.772547,0.581981,-1293.283691,294.500488,0.000000
82.710007,65.178963,-1293.239136,-0.000867,0.002293,0.058242,289.930511,14.769765,0.582420,-1293.239136,294.500488,0.000000
83.010002,65.181572,-1293.283691,-0.000871,0.002293,0.058242,289.942108,14.770355,0.582420,-1293.283691,294.500488,0.000000
83.310005,65.098534,-1293.239136,-0.000862,0.002294,0.058268,289.572754,14.751538,0.582677,-1293.239136,294.500488,0.000000
83.610001,65.067986,-1293.283691,-0.000858,0.002294,0.058277,289.436859,14.744617,0.582768,-1293.283691,294.500488,0.000000
83.910004,65.205391,-1293.194702,-0.000854,0.002298,0.058372,290.048065,14.775753,0.583722,-1293.194702,294.500488,0.000000
84.210007,65.206886,-1293.283691,-0.000858,0.002298,0.058372,290.054718,14.776092,0.583722,-1293.283691,294.500488,0.000000
84.510002,65.113792,-1293.283691,-0.000862,0.002298,0.058372,289.640625,14.754995,0.583722,-1293.283691,294.500488,0.000000
84.810005,65.049004,-1293.194702,-0.000858,0.002298,0.058381,289.352417,14.740315,0.583812,-1293.194702,294.500488,0.000000
85.110001,64.956276,-1293.194702,-0.000862,0.002299,0.058407,288.939941,14.719302,0.584070,-1293.194702,294.500488,0.000000
85.410004,64.926857,-1293.194702,-0.000854,0.002300,0.058416,288.809082,14.712636,0.584161,-1293.194702,294.500488,0.000000
85.710007,65.440742,-1293.194702,-0.000854,0.002307,0.058598,291.094971,14.829084,0.585977,-1293.194702,294.500488,0.000000
86.010002,65.449303,-1293.283691,-0.000854,0.002307,0.058589,291.133026,14.831024,0.585887,-1293.283691,294.500488,0.000000
86.310005,65.345787,-1293.239136,-0.000849,0.002307,0.058589,290.672577,14.807567,0.585887,-1293.239136,294.500488,0.000000
86.610001,65.266838,-1293.239136,-0.000854,0.002307,0.058589,290.321381,14.789678,0.585887,-1293.239136,294.500488,0.000000
86.910004,65.176353,-1293.194702,-0.000841,0.002307,0.058598,289.918915,14.769173,0.585977,-1293.194702,294.500488,0.000000
87.210007,65.084755,-1293.239136,-0.000849,0.002309,0.058642,289.511444,14.748417,0.586416,-1293.239136,294.500488,0.000000
87.510002,65.208382,-1293.194702,-0.000841,0.002310,0.058684,290.061371,14.776431,0.586840,-1293.194702,294.500488,0.000000
87.810005,65.156242,-1293.194702,-0.000845,0.002310,0.058684,289.829437,14.764615,0.586840,-1293.194702,294.500488,0.000000
88.110001,65.116768,-1293.239136,-0.000841,0.002312,0.058719,289.653839,14.755671,0.587189,-1293.239136,294.500488,0.000000
88.410004,65.070229,-1293.194702,-0.000858,0.002312,0.058719,289.446838,14.745125,0.587189,-1293.194702,294.500488,0.000000
88.710007,65.135765,-1293.194702,-0.000836,0.002315,0.058789,289.738342,14.759975,0.587885,-1293.194702,294.500488,0.000000
89.010002,65.126457,-1293.239136,-0.000836,0.002315,0.058789,289.696960,14.757866,0.587885,-1293.239136,294.500488,0.000000
89.310005,65.089958,-1293.194702,-0.000841,0.002315,0.058798,289.534607,14.749595,0.587976,-1293.194702,294.500488,0.000000
89.610001,65.021080,-1293.239136,-0.000832,0.002315,0.058798,289.228210,14.733988,0.587976,-1293.239136,294.500488,0.000000
89.910004,65.070229,-1293.239136,-0.000841,0.002317,0.058858,289.446838,14.745125,0.588581,-1293.239136,294.500488,0.000000
90.210007,65.021080,-1293.194702,-0.000845,0.002317,0.058858,289.228210,14.733988,0.588581,-1293.194702,294.500488,0.000000
90.510002,65.050865,-1293.239136,-0.000841,0.002319,0.058901,289.360687,14.740736,0.589005,-1293.239136,294.500488,0.000000
90.810005,65.112297,-1293.283691,-0.000832,0.002321,0.058954,289.633972,14.754658,0.589535,-1293.283691,294.500488,0.000000
91.110001,65.069847,-1293.239136,-0.000828,0.002321,0.058954,289.445129,14.745038,0.589535,-1293.239136,294.500488,0.000000
91.410004,65.269066,-1293.194702,-0.000832,0.002325,0.059049,290.331299,14.790182,0.590489,-1293.194702,294.500488,0.000000
91.710007,65.262749,-1293.194702,-0.000828,0.002325,0.059049,290.303192,14.788750,0.590489,-1293.194702,294.500488,0.000000
92.010002,65.213585,-1293.239136,-0.000832,0.002325,0.059049,290.084503,14.777609,0.590489,-1293.239136,294.500488,0.000000
92.310005,65.124214,-1293.194702,-0.000828,0.002325,0.059049,289.686981,14.757359,0.590489,-1293.194702,294.500488,0.000000
92.610001,65.091820,-1293.283691,-0.000832,0.002326,0.059075,289.542877,14.750017,0.590746,-1293.283691,294.500488,0.000000
92.910004,65.038582,-1293.194702,-0.000824,0.002326,0.059084,289.306061,14.737954,0.590837,-1293.194702,294.500488,0.000000
93.210007,65.185661,-1293.239136,-0.000832,0.002329,0.059153,289.960297,14.771281,0.591534,-1293.239136,294.500488,0.000000
93.510002,65.145821,-1293.239136,-0.000841,0.002329,0.059153,289.783081,14.762254,0.591534,-1293.239136,294.500488,0.000000
93.810005,65.073570,-1293.194702,-0.000836,0.002329,0.059153,289.461700,14.745882,0.591534,-1293.194702,294.500488,0.000000
94.110008,64.998726,-1293.194702,-0.000819,0.002329,0.059161,289.128784,14.728922,0.591609,-1293.194702,294.500488,0.000000
94.410004,65.472755,-1293.194702,-0.000828,0.002336,0.059335,291.237366,14.836338,0.593350,-1293.194702,294.500488,0.000000
94.710007,65.432549,-1293.239136,-0.000819,0.002335,0.059300,291.058502,14.827228,0.593002,-1293.239136,294.500488,0.000000
95.010002,65.335350,-1293.239136,-0.000811,0.002335,0.059300,290.626160,14.805202,0.593002,-1293.239136,294.500488,0.000000
95.310005,65.273918,-1293.328125,-0.000819,0.002335,0.059300,290.352875,14.791282,0.593002,-1293.328125,294.500488,0.000000
95.610008,65.190498,-1293.239136,-0.000811,0.002335,0.059300,289.981812,14.772378,0.593002,-1293.239136,294.500488,0.000000
95.910004,65.084373,-1293.283691,-0.000815,0.002335,0.059300,289.509766,14.748329,0.593002,-1293.283691,294.500488,0.000000
96.210007,65.007668,-1293.283691,-0.000815,0.002335,0.059300,289.168549,14.730948,0.593002,-1293.283691,294.500488,0.000000
96.510002,64.930580,-1293.150269,-0.000815,0.002335,0.059300,288.825653,14.713479,0.593002,-1293.150269,294.500488,0.000000
96.810005,64.823341,-1293.239136,-0.000824,0.002335,0.059300,288.348633,14.689179,0.593002,-1293.239136,294.500488,0.000000
97.110008,64.755943,-1293.239136,-0.000819,0.002335,0.059300,288.048828,14.673906,0.593002,-1293.239136,294.500488,0.000000
97.410004,64.670677,-1293.239136,-0.000815,0.002335,0.059300,287.669525,14.654585,0.593002,-1293.239136,294.500488,0.000000
97.710007,66.094246,-1293.194702,-0.000815,0.002342,0.059482,294.001892,14.977170,0.594819,-1293.194702,294.500488,0.000000
98.010002,65.955727,-1293.283691,-0.000806,0.002342,0.059482,293.385712,14.945782,0.594819,-1293.283691,294.500488,0.000000
98.310005,65.822792,-1293.194702,-0.000806,0.002342,0.059482,292.794403,14.915658,0.594819,-1293.194702,294.500488,0.000000
98.610008,65.772896,-1293.239136,-0.000802,0.002342,0.059482,292.572449,14.904351,0.594819,-1293.239136,294.500488,0.000000
98.910004,65.664909,-1293.283691,-0.000802,0.002342,0.059482,292.092102,14.879881,0.594819,-1293.283691,294.500488,0.000000
99.210007,65.555794,-1293.239136,-0.000806,0.002342,0.059482,291.606720,14.855155,0.594819,-1293.239136,294.500488,0.000000
99.510002,65.484306,-1293.239136,-0.000815,0.002342,0.059482,291.288757,14.838956,0.594819,-1293.239136,0.059482,0.000000
99.810005,65.321571,-1293.239136,-0.000798,0.002334,0.059282,290.564850,14.802079,0.592821,-1293.239136,0.059075,0.000000
100.110008,65.282845,-1293.239136,-0.000802,0.002319,0.058910,290.392609,14.793304,0.589096,-1293.239136,0.058581,0.000000
100.410004,65.069847,-1293.194702,-0.000802,0.002305,0.058537,289.445129,14.745038,0.585372,-1293.194702,0.058077,0.000000
100.710007,64.979744,-1293.239136,-0.000798,0.002283,0.058000,289.044342,14.724620,0.579997,-1293.239136,0.057574,0.000000
101.010002,64.846428,-1293.239136,-0.000793,0.002266,0.057549,288.451324,14.694410,0.575486,-1293.239136,0.057081,0.000000
101.310005,64.752586,-1293.239136,-0.000802,0.002246,0.057037,288.033875,14.673146,0.570369,-1293.239136,0.056577,0.000000
101.610008,64.660988,-1293.194702,-0.000806,0.002231,0.056664,287.626434,14.652389,0.566644,-1293.194702,0.056074,0.000000
101.910004,64.557838,-1293.239136,-0.000793,0.002210,0.056125,287.167603,14.629016,0.561255,-1293.239136,0.055580,0.000000
102.210007,64.467354,-1293.194702,-0.000789,0.002191,0.055649,286.765106,14.608511,0.556486,-1293.194702,0.055076,0.000000
102.510002,64.298668,-1293.194702,-0.000798,0.002167,0.055041,286.014771,14.570287,0.550415,-1293.194702,0.054574,0.000000
102.810005,64.133705,-1293.283691,-0.000780,0.002146,0.054496,285.280975,14.532906,0.544964,-1293.283691,0.054080,0.000000
103.110008,64.056633,-1293.239136,-0.000789,0.002134,0.054209,284.938141,14.515441,0.542088,-1293.239136,0.053576,0.000000
103.410004,63.697655,-1293.194702,-0.000789,0.002119,0.053820,283.341309,14.434095,0.538197,-1293.194702,0.053073,0.000000
103.710007,63.068352,-1293.150269,-0.000785,0.002097,0.053273,280.542053,14.291492,0.532732,-1293.150269,0.052580,0.000000
104.010002,62.561180,-1293.239136,-0.000772,0.002083,0.052901,278.286041,14.176566,0.529007,-1293.239136,0.052076,0.000000
104.310005,61.408318,-1293.239136,-0.000798,0.002061,0.052354,273.157837,13.915323,0.523542,-1293.239136,0.051573,0.000000
104.610008,60.234222,-1293.239136,-0.000785,0.002039,0.051782,267.935211,13.649270,0.517819,-1293.239136,0.051079,0.000000
104.910004,58.699677,-1293.194702,-0.000767,0.002015,0.051191,261.109192,13.301537,0.511915,-1293.194702,0.050575,0.000000
105.210007,57.707306,-1293.239136,-0.000789,0.002001,0.050836,256.694916,13.076662,0.508357,-1293.239136,0.050073,0.000000
105.510002,56.433418,-1293.194702,-0.000772,0.001985,0.050428,251.028381,12.787995,0.504284,-1293.194702,0.049579,0.000000
105.810005,55.837250,-1293.194702,-0.000780,0.001981,0.050307,248.376495,12.652902,0.503073,-1293.194702,0.049075,0.000000
106.110008,54.014862,-1293.194702,-0.000776,0.001958,0.049743,240.270111,12.239943,0.497426,-1293.194702,0.048572,0.000000
106.410004,51.852493,-1293.150269,-0.000772,0.001931,0.049058,230.651413,11.749943,0.490583,-1293.150269,0.048079,0.000000
106.710007,50.218521,-1293.239136,-0.000772,0.001911,0.048547,223.383133,11.379680,0.485466,-1293.239136,0.047575,0.000000
107.010002,47.642822,-1293.239136,-0.000785,0.001890,0.048018,211.925858,10.796019,0.480182,-1293.239136,0.047072,0.000000
107.310005,45.643555,-1293.239136,-0.000776,0.001872,0.047541,203.032669,10.342978,0.475413,-1293.239136,0.046578,0.000000
107.610008,43.240639,-1293.239136,-0.000793,0.001848,0.046951,192.343964,9.798469,0.469509,-1293.239136,0.046074,0.000000
107.910004,40.750954,-1293.194702,-0.000785,0.001828,0.046439,181.269302,9.234298,0.464391,-1293.194702,0.045572,0.000000
108.210007,39.649849,-1293.194702,-0.000785,0.001816,0.046127,176.371338,8.984784,0.461273,-1293.194702,0.045078,0.000000
108.510002,37.366089,-1293.194702,-0.000793,0.001798,0.045676,166.212662,8.467277,0.456761,-1293.194702,0.044574,0.000000
108.810005,34.214699,-1293.150269,-0.000789,0.001768,0.044904,152.194580,7.753162,0.449040,-1293.150269,0.044080,0.000000
109.110008,32.350975,-1293.283691,-0.000785,0.001753,0.044522,143.904327,7.330836,0.445225,-1293.283691,0.043578,0.000000
109.410004,30.266060,-1293.239136,-0.000798,0.001732,0.043994,134.630157,6.858387,0.439941,-1293.239136,0.043074,0.000000
109.710007,28.073532,-1293.194702,-0.000802,0.001712,0.043490,124.877304,6.361553,0.434900,-1293.194702,0.042580,0.000000
110.010002,26.676392,-1293.150269,-0.000806,0.001702,0.043231,118.662514,6.044957,0.432311,-1293.150269,0.042077,0.000000
110.310005,24.265282,-1293.194702,-0.000802,0.001678,0.042624,107.937363,5.498591,0.426240,-1293.194702,0.041575,0.000000
110.610008,21.908905,-1293.239136,-0.000815,0.001653,0.041999,97.455673,4.964629,0.419987,-1293.239136,0.041080,0.000000
110.910004,19.463905,-1293.194702,-0.000815,0.001633,0.041487,86.579773,4.410584,0.414870,-1293.194702,0.040577,0.000000
111.210007,17.773338,-1293.194702,-0.000824,0.001616,0.041045,79.059761,4.027496,0.410449,-1293.194702,0.040074,0.000000
111.510002,15.865677,-1293.239136,-0.000824,0.001598,0.040577,70.574059,3.595214,0.405771,-1293.239136,0.039579,0.000000
111.810005,13.076973,-1293.150269,-0.000828,0.001575,0.040012,58.169281,2.963284,0.400124,-1293.150269,0.039077,0.000000
112.110008,10.898598,-1293.194702,-0.000845,0.001554,0.039467,48.479385,2.469657,0.394674,-1293.194702,0.038574,0.000000
112.410004,9.643333,-1293.239136,-0.000828,0.001541,0.039146,42.895691,2.185211,0.391464,-1293.239136,0.038079,0.000000
112.710007,6.693398,-1293.150269,-0.000836,0.001513,0.038426,29.773720,1.516746,0.384258,-1293.150269,0.037576,0.000000
113.010002,5.841408,-1293.194702,-0.000832,0.001503,0.038165,25.983879,1.323682,0.381654,-1293.194702,0.037074,0.000000
113.310005,4.777168,-1293.194702,-0.000849,0.001490,0.037853,21.249907,1.082522,0.378535,-1293.194702,0.036579,0.000000
113.610008,0.850128,-1293.105713,-0.000862,0.001453,0.036909,3.781559,0.192642,0.369088,-1293.105713,0.036076,0.000000
113.910004,0.121391,-1293.239136,-0.000854,0.001445,0.036700,0.539975,0.027508,0.366999,-1293.239136,0.035573,0.000000
114.210007,-1.881969,-1293.105713,-0.000862,0.001423,0.036153,-8.371418,-0.426460,0.361533,-1293.105713,0.035078,0.000000
114.510002,-3.213573,-1293.194702,-0.000867,0.001408,0.035755,-14.294688,-0.728206,0.357551,-1293.194702,0.034576,0.000000
114.810005,-0.343330,-1293.150269,-0.000953,0.001384,0.035165,-1.527210,-0.077800,0.351647,-1293.150269,0.034073,0.000000
115.110008,-0.093468,-1293.150269,-0.000961,0.001370,0.034801,-0.415765,-0.021180,0.348014,-1293.150269,0.033578,0.000000
115.410004,-0.048409,-1293.239136,-0.000970,0.001359,0.034523,-0.215332,-0.010970,0.345228,-1293.239136,0.033075,0.000000
115.710007,-0.052132,-1293.194702,-0.001018,0.001326,0.033692,-0.231893,-0.011813,0.336916,-1293.194702,0.032573,0.000000
116.010002,-0.083412,-1293.150269,-0.001039,0.001301,0.033041,-0.371036,-0.018901,0.330406,-1293.150269,0.032078,0.000000
116.310005,-0.068886,-1293.194702,-0.001091,0.001285,0.032641,-0.306419,-0.015610,0.326409,-1293.194702,0.031575,0.000000
116.610008,-0.065163,-1293.239136,-0.001104,0.001267,0.032173,-0.289858,-0.014766,0.321731,-1293.239136,0.031072,0.000000
116.910004,-0.055115,-1293.194702,-0.001138,0.001240,0.031505,-0.245163,-0.012489,0.315055,-1293.194702,0.030577,0.000000
117.210007,-0.051384,-1293.194702,-0.001151,0.001227,0.031175,-0.228567,-0.011644,0.311754,-1293.194702,0.030075,0.000000
117.510002,-0.051018,-1293.105713,-0.001181,0.001206,0.030630,-0.226938,-0.011561,0.306304,-1293.105713,0.029572,0.000000
117.810005,-0.031281,-1293.194702,-0.001203,0.001197,0.030412,-0.139143,-0.007088,0.304124,-1293.194702,0.029077,0.000000
118.110008,-0.042824,-1293.239136,-0.001237,0.001168,0.029668,-0.190490,-0.009704,0.296675,-1293.239136,0.028574,0.000000
118.410004,-0.006706,-1293.150269,-0.001255,0.001153,0.029294,-0.029831,-0.001520,0.292936,-1293.150269,0.028072,0.000000
118.710007,-0.016014,-1293.194702,-0.001293,0.001125,0.028574,-0.071234,-0.003629,0.285744,-1293.194702,0.027577,0.000000
119.010002,-0.000000,-1293.150269,-0.001324,0.001107,0.028123,-0.000000,-0.000000,0.281233,-1293.150269,0.027074,0.000000
119.310005,-0.013405,-1293.239136,-0.001341,0.001094,0.027777,-0.059628,-0.003038,0.277766,-1293.239136,0.026571,0.000000
119.610008,-0.011543,-1293.194702,-0.001375,0.001062,0.026970,-0.051347,-0.002616,0.269696,-1293.194702,0.026076,0.000000
119.900009,-0.013405,-1293.194702,-0.001393,0.001060,0.026927,-0.059628,-0.003038,0.269273,-1293.194702,0.026753,0.000000