File: Data/Sima compression/PSFNMP-17-3_10302024_181226.csv
Time (sec),S:Load (lbs),S:HL1 (DIM),S:LVDT (in),S:Position (in),Ch:Position (mm),Ch:Load (N),Ch:Stress (MPa),Ch:Strain (mm/mm),Ch:HL1 (DIM),Set Point (),Cycles ()
0.210000,-0.006332,-1293.150269,-0.007925,-0.004964,-0.126095,-0.028168,-0.001435,-1.260945,-1293.150269,-0.125895,0.000000
0.510000,-0.000748,-1293.239136,-0.007938,-0.004904,-0.124550,-0.003326,-0.000169,-1.245503,-1293.239136,-0.123831,0.000000
0.810000,-0.000748,-1293.194702,-0.007821,-0.004725,-0.120024,-0.003326,-0.000169,-1.200236,-1293.194702,-0.118835,0.000000
1.110000,-0.087135,-1293.239136,-0.007623,-0.004527,-0.114985,-0.387597,-0.019745,-1.149851,-1293.239136,-0.113822,0.000000
1.410000,0.014526,-1293.194702,-0.007433,-0.004338,-0.110180,0.064617,0.003292,-1.101798,-1293.194702,-0.108828,0.000000
1.710000,-0.029419,-1293.194702,-0.007205,-0.004138,-0.105116,-0.130862,-0.006666,-1.051156,-1293.194702,-0.103832,0.000000
2.010000,0.027184,-1293.194702,-0.007015,-0.003939,-0.100051,0.120918,0.006160,-1.000514,-1293.194702,-0.098837,0.000000
2.310000,0.003723,-1293.194702,-0.006812,-0.003741,-0.095022,0.016561,0.000844,-0.950221,-1293.194702,-0.093841,0.000000
2.610000,-0.013031,-1293.194702,-0.006618,-0.003545,-0.090052,-0.057965,-0.002953,-0.900517,-1293.194702,-0.088847,0.000000
2.910000,-0.017876,-1293.283691,-0.006407,-0.003351,-0.085127,-0.079515,-0.004051,-0.851268,-1293.283691,-0.083834,0.000000
3.210000,-0.036865,-1293.150269,-0.006209,-0.003150,-0.080010,-0.163985,-0.008354,-0.800097,-1293.150269,-0.078839,0.000000
3.510000,0.013779,-1293.194702,-0.006006,-0.002957,-0.075101,0.061291,0.003122,-0.751014,-1293.194702,-0.073843,0.000000
3.810000,-0.006332,-1293.194702,-0.005799,-0.002759,-0.070089,-0.028168,-0.001435,-0.700887,-1293.194702,-0.068849,0.000000
4.110000,0.042824,-1293.239136,-0.005592,-0.002562,-0.065085,0.190490,0.009704,-0.650851,-1293.239136,-0.063853,0.000000
4.410000,-0.000748,-1293.239136,-0.005398,-0.002367,-0.060124,-0.003326,-0.000169,-0.601238,-1293.239136,-0.058858,0.000000
4.710000,0.008568,-1293.150269,-0.005200,-0.002178,-0.055311,0.038112,0.001941,-0.553109,-1293.150269,-0.053862,0.000000
5.010000,-0.038353,-1293.194702,-0.005001,-0.001973,-0.050126,-0.170603,-0.008691,-0.501256,-1293.194702,-0.048851,0.000000
5.310000,-0.037239,-1293.150269,-0.004786,-0.001778,-0.045155,-0.165648,-0.008438,-0.451553,-1293.150269,-0.043855,0.000000
5.610000,-0.038727,-1293.194702,-0.004579,-0.001578,-0.040091,-0.172265,-0.008776,-0.400911,-1293.194702,-0.038860,0.000000
5.910000,0.020111,-1293.194702,-0.004385,-0.001380,-0.035053,0.089459,0.004557,-0.350527,-1293.194702,-0.033864,0.000000
6.210001,0.021973,-1293.150269,-0.004178,-0.001179,-0.029935,0.097739,0.004979,-0.299355,-1293.150269,-0.028870,0.000000
6.510000,0.029793,-1293.194702,-0.003980,-0.000987,-0.025062,0.132525,0.006751,-0.250621,-1293.194702,-0.023874,0.000000
6.810000,0.008568,-1293.194702,-0.003781,-0.000796,-0.020214,0.038112,0.001941,-0.202144,-1293.194702,-0.018861,0.000000
7.110000,-0.042076,-1293.150269,-0.003566,-0.000592,-0.015029,-0.187164,-0.009535,-0.150291,-1293.150269,-0.013866,0.000000
7.410000,0.020477,-1293.150269,-0.003376,-0.000401,-0.010189,0.091088,0.004640,-0.101889,-1293.150269,-0.008872,0.000000
7.710001,-0.034630,-1293.194702,-0.003160,-0.000199,-0.005055,-0.154041,-0.007847,-0.050551,-1293.194702,-0.003876,0.000000
8.010000,0.064796,-1293.194702,-0.002975,0.000004,0.000095,0.288229,0.014683,0.000954,-1293.194702,0.001543,0.000000
8.310000,0.093842,-1293.194702,-0.002932,0.000027,0.000693,0.417428,0.021265,0.006934,-1293.194702,0.000910,0.000000
8.610001,0.127350,-1293.239136,-0.002945,0.000027,0.000693,0.566480,0.028858,0.006934,-1293.239136,0.000970,0.000000
8.910001,0.083786,-1293.194702,-0.002940,0.000028,0.000702,0.372699,0.018986,0.007025,-1293.194702,0.001475,0.000000
9.210000,0.131073,-1293.239136,-0.002936,0.000039,0.000989,0.583042,0.029702,0.009886,-1293.239136,0.001968,0.000000
9.510000,0.197731,-1293.239136,-0.002919,0.000058,0.001466,0.879551,0.044806,0.014655,-1293.239136,0.002471,0.000000
9.810000,0.448708,-1293.194702,-0.002902,0.000083,0.002107,1.995951,0.101679,0.021074,-1293.194702,0.002973,0.000000
10.110001,0.747726,-1293.239136,-0.002876,0.000100,0.002540,3.326053,0.169437,0.025404,-1293.239136,0.003468,0.000000
10.410001,1.104454,-1293.194702,-0.002867,0.000116,0.002957,4.912857,0.250273,0.029568,-1293.194702,0.003971,0.000000
10.710000,1.608650,-1293.239136,-0.002859,0.000142,0.003599,7.155633,0.364525,0.035987,-1293.239136,0.004474,0.000000
11.010000,2.220459,-1293.194702,-0.002850,0.000162,0.004110,9.877095,0.503163,0.041104,-1293.194702,0.004969,0.000000
11.310000,2.618896,-1293.239136,-0.002824,0.000179,0.004543,11.649433,0.593450,0.045434,-1293.239136,0.005471,0.000000
11.610001,3.120110,-1293.239136,-0.002815,0.000193,0.004899,13.878941,0.707027,0.048992,-1293.239136,0.005974,0.000000
11.910001,4.125885,-1293.150269,-0.002798,0.000222,0.005627,18.352854,0.934939,0.056274,-1293.150269,0.006469,0.000000
12.210001,4.484108,-1293.194702,-0.002772,0.000234,0.005932,19.946308,1.016113,0.059317,-1293.194702,0.006972,0.000000
12.510000,5.289177,-1293.194702,-0.002781,0.000253,0.006434,23.527433,1.198545,0.064343,-1293.194702,0.007474,0.000000
12.810000,6.226067,-1293.150269,-0.002746,0.000277,0.007041,27.694927,1.410847,0.070414,-1293.150269,0.007969,0.000000
13.110001,6.727280,-1293.194702,-0.002755,0.000293,0.007449,29.924435,1.524423,0.074487,-1293.194702,0.008472,0.000000
13.410001,7.510384,-1293.194702,-0.002725,0.000313,0.007951,33.407856,1.701877,0.079513,-1293.194702,0.008975,0.000000
13.710001,8.529938,-1293.194702,-0.002712,0.000338,0.008586,37.943058,1.932912,0.085857,-1293.194702,0.009470,0.000000
14.010000,9.136162,-1293.239136,-0.002690,0.000355,0.009010,40.639679,2.070284,0.090096,-1293.239136,0.009972,0.000000
14.310000,9.922607,-1293.194702,-0.002708,0.000372,0.009452,44.137962,2.248495,0.094516,-1293.194702,0.010475,0.000000
14.610001,10.877747,-1293.194702,-0.002682,0.000394,0.010016,48.386635,2.464933,0.100163,-1293.194702,0.010970,0.000000
14.910001,11.461998,-1293.239136,-0.002652,0.000412,0.010468,50.985512,2.597326,0.104675,-1293.239136,0.011473,0.000000
15.210001,12.211952,-1293.283691,-0.002647,0.000431,0.010952,54.321476,2.767268,0.109520,-1293.283691,0.011975,0.000000
15.510001,12.889671,-1293.194702,-0.002634,0.000450,0.011438,57.336121,2.920841,0.114380,-1293.194702,0.012470,0.000000
15.810000,13.782997,-1293.194702,-0.002626,0.000471,0.011959,61.309834,3.123272,0.119588,-1293.194702,0.012973,0.000000
16.110001,14.521034,-1293.194702,-0.002608,0.000488,0.012384,64.592789,3.290513,0.123842,-1293.194702,0.013476,0.000000
16.410000,14.990227,-1293.150269,-0.002596,0.000504,0.012791,66.679855,3.396834,0.127914,-1293.150269,0.013971,0.000000
16.710001,16.302094,-1293.150269,-0.002591,0.000531,0.013476,72.515335,3.694107,0.134757,-1293.150269,0.014473,0.000000
17.010000,16.786179,-1293.194702,-0.002570,0.000548,0.013927,74.668655,3.803802,0.139269,-1293.194702,0.014976,0.000000
17.310001,17.446770,-1293.239136,-0.002561,0.000568,0.014430,77.607109,3.953495,0.144295,-1293.239136,0.015471,0.000000
17.610001,17.800148,-1293.194702,-0.002539,0.000582,0.014794,79.179016,4.033571,0.147944,-1293.194702,0.015974,0.000000
17.910002,18.958969,-1293.239136,-0.002531,0.000608,0.015453,84.333710,4.296164,0.154530,-1293.239136,0.016469,0.000000
18.210001,18.629051,-1293.283691,-0.002514,0.000615,0.015609,82.866158,4.221403,0.156089,-1293.283691,0.016971,0.000000
18.510000,19.780052,-1293.239136,-0.002505,0.000646,0.016416,87.986069,4.482224,0.164158,-1293.239136,0.017474,0.000000
18.810001,21.025269,-1293.194702,-0.002483,0.000671,0.017049,93.525063,4.764394,0.170487,-1293.194702,0.017969,0.000000
19.110001,21.186874,-1293.328125,-0.002466,0.000686,0.017423,94.243927,4.801014,0.174226,-1293.328125,0.018472,0.000000
19.410002,21.838158,-1293.239136,-0.002466,0.000709,0.018002,97.140976,4.948597,0.180025,-1293.239136,0.018974,0.000000
19.710001,22.111107,-1293.283691,-0.002436,0.000725,0.018419,98.355118,5.010448,0.184188,-1293.283691,0.019469,0.000000
20.010000,22.561676,-1293.194702,-0.002432,0.000744,0.018905,100.359344,5.112549,0.189048,-1293.194702,0.019972,0.000000
20.310001,22.796638,-1293.239136,-0.002419,0.000759,0.019286,101.404510,5.165792,0.192863,-1293.239136,0.020475,0.000000
20.610001,24.435829,-1293.283691,-0.002414,0.000789,0.020049,108.695999,5.537238,0.200493,-1293.283691,0.020970,0.000000
20.910002,24.442528,-1293.194702,-0.002397,0.000809,0.020553,108.725792,5.538756,0.205535,-1293.194702,0.021472,0.000000
21.210001,24.730370,-1293.194702,-0.002380,0.000825,0.020961,110.006180,5.603982,0.209607,-1293.194702,0.021975,0.000000
21.510000,24.886772,-1293.328125,-0.002367,0.000840,0.021342,110.701889,5.639423,0.213423,-1293.328125,0.022469,0.000000
21.810001,26.021385,-1293.239136,-0.002350,0.000865,0.021975,115.748901,5.896530,0.219751,-1293.239136,0.022973,0.000000
22.110001,26.126022,-1293.239136,-0.002333,0.000880,0.022357,116.214348,5.920241,0.223566,-1293.239136,0.023475,0.000000
22.410002,26.548294,-1293.239136,-0.002324,0.000903,0.022938,118.092712,6.015929,0.229380,-1293.239136,0.023969,0.000000
22.710001,27.565987,-1293.194702,-0.002320,0.000924,0.023459,122.619629,6.246542,0.234588,-1293.194702,0.024473,0.000000
23.010000,27.803566,-1293.239136,-0.002298,0.000943,0.023961,123.676437,6.300378,0.239614,-1293.239136,0.024976,0.000000
23.310001,28.227325,-1293.283691,-0.002281,0.000961,0.024420,125.561417,6.396403,0.244201,-1293.283691,0.025469,0.000000
23.610001,28.549797,-1293.239136,-0.002276,0.000979,0.024871,126.995842,6.469476,0.248713,-1293.239136,0.025973,0.000000
23.910002,28.860725,-1293.283691,-0.002264,0.000996,0.025306,128.378922,6.539934,0.253058,-1293.283691,0.026476,0.000000
24.210001,29.161606,-1293.239136,-0.002255,0.001016,0.025808,129.717300,6.608114,0.258084,-1293.239136,0.026970,0.000000
24.510000,30.615723,-1293.283691,-0.002229,0.001039,0.026397,136.185532,6.937622,0.263974,-1293.283691,0.027474,0.000000
24.810001,30.838028,-1293.239136,-0.002229,0.001059,0.026902,137.174393,6.987997,0.269015,-1293.239136,0.027976,0.000000
25.110001,31.715332,-1293.194702,-0.002199,0.001080,0.027421,141.076843,7.186797,0.274208,-1293.194702,0.028470,0.000000
25.410002,31.808052,-1293.239136,-0.002195,0.001097,0.027863,141.489288,7.207808,0.278629,-1293.239136,0.028974,0.000000
25.710001,31.808800,-1293.150269,-0.002195,0.001108,0.028132,141.492615,7.207977,0.281324,-1293.150269,0.029477,0.000000
26.010002,33.190300,-1293.239136,-0.002186,0.001135,0.028826,147.637833,7.521029,0.288258,-1293.239136,0.029970,0.000000
26.310001,33.343346,-1293.283691,-0.002173,0.001157,0.029398,148.318604,7.555710,0.293980,-1293.283691,0.030474,0.000000
26.610001,34.425461,-1293.194702,-0.002151,0.001175,0.029849,153.132095,7.800921,0.298492,-1293.194702,0.030977,0.000000
26.910002,35.118820,-1293.239136,-0.002139,0.001198,0.030421,156.216309,7.958038,0.304215,-1293.239136,0.031471,0.000000
27.210001,35.532898,-1293.283691,-0.002121,0.001217,0.030907,158.058228,8.051869,0.309075,-1293.283691,0.031975,0.000000
27.510002,36.014000,-1293.239136,-0.002117,0.001235,0.031368,160.198273,8.160889,0.313677,-1293.239136,0.032477,0.000000
27.810001,36.397919,-1293.283691,-0.002100,0.001251,0.031766,161.906021,8.247887,0.317659,-1293.283691,0.032971,0.000000
28.110001,37.335182,-1293.239136,-0.002091,0.001278,0.032468,166.075180,8.460274,0.324683,-1293.239136,0.033475,0.000000
28.410002,37.675156,-1293.194702,-0.002087,0.001291,0.032789,167.587463,8.537312,0.327893,-1293.194702,0.033978,0.000000
28.710001,38.442245,-1293.239136,-0.002052,0.001313,0.033352,170.999649,8.711137,0.333525,-1293.239136,0.034471,0.000000
29.010002,39.115868,-1293.283691,-0.002052,0.001333,0.033857,173.996063,8.863783,0.338566,-1293.283691,0.034975,0.000000
29.310001,39.978653,-1293.283691,-0.002048,0.001357,0.034471,177.833923,9.059293,0.344713,-1293.283691,0.035478,0.000000
29.610001,40.502579,-1293.150269,-0.002035,0.001373,0.034871,180.164474,9.178016,0.348710,-1293.150269,0.035972,0.000000
29.910002,40.893944,-1293.239136,-0.002026,0.001390,0.035295,181.905350,9.266701,0.352949,-1293.239136,0.036476,0.000000
30.210001,42.098938,-1293.150269,-0.002009,0.001417,0.035997,187.265427,9.539756,0.359974,-1293.150269,0.036978,0.000000
30.510002,42.518234,-1293.194702,-0.001988,0.001432,0.036362,189.130554,9.634769,0.363622,-1293.194702,0.037472,0.000000
30.810001,43.112541,-1293.239136,-0.001992,0.001452,0.036891,191.774155,9.769442,0.368906,-1293.239136,0.037976,0.000000
31.110001,43.796585,-1293.239136,-0.001966,0.001472,0.037395,194.816940,9.924448,0.373948,-1293.239136,0.038470,0.000000
31.410002,45.074570,-1293.194702,-0.001949,0.001496,0.038009,200.501694,10.214044,0.380094,-1293.194702,0.038972,0.000000
31.710001,44.883545,-1293.239136,-0.001949,0.001506,0.038262,199.651978,10.170757,0.382623,-1293.239136,0.039475,0.000000
32.010002,46.238235,-1293.194702,-0.001932,0.001532,0.038912,205.677948,10.477734,0.389117,-1293.194702,0.039970,0.000000
32.310001,47.560898,-1293.194702,-0.001927,0.001558,0.039563,211.561447,10.777453,0.395627,-1293.194702,0.040473,0.000000
32.610001,47.870712,-1293.239136,-0.001914,0.001573,0.039961,212.939560,10.847658,0.399609,-1293.239136,0.040975,0.000000
32.910000,48.519012,-1293.194702,-0.001919,0.001591,0.040412,215.823349,10.994566,0.404121,-1293.194702,0.041470,0.000000
33.210003,49.857323,-1293.194702,-0.001888,0.001616,0.041045,221.776443,11.297831,0.410449,-1293.194702,0.041973,0.000000
33.510002,50.346619,-1293.239136,-0.001897,0.001630,0.041401,223.952942,11.408707,0.414007,-1293.239136,0.042476,0.000000
33.810001,50.895493,-1293.194702,-0.001880,0.001646,0.041808,226.394455,11.533084,0.418079,-1293.194702,0.042971,0.000000
34.110001,52.710442,-1293.194702,-0.001858,0.001674,0.042520,234.467758,11.944357,0.425195,-1293.194702,0.043473,0.000000
34.410000,53.305489,-1293.150269,-0.001863,0.001691,0.042953,237.114655,12.079196,0.429525,-1293.150269,0.043976,0.000000
34.710003,54.081512,-1293.239136,-0.001854,0.001711,0.043448,240.566589,12.255046,0.434476,-1293.239136,0.044471,0.000000
35.010002,55.174797,-1293.239136,-0.001837,0.001731,0.043976,245.429749,12.502788,0.439759,-1293.239136,0.044974,0.000000
35.310001,56.227127,-1293.194702,-0.001815,0.001750,0.044445,250.110748,12.741250,0.444453,-1293.194702,0.045476,0.000000
35.610001,55.855499,-1293.239136,-0.001819,0.001757,0.044627,248.457672,12.657038,0.446269,-1293.239136,0.045971,0.000000
35.910000,57.142418,-1293.194702,-0.001807,0.001779,0.045190,254.182175,12.948657,0.451901,-1293.194702,0.046474,0.000000
36.210003,58.895546,-1293.194702,-0.001798,0.001807,0.045893,261.980469,13.345922,0.458926,-1293.194702,0.046977,0.000000
36.510002,59.314095,-1293.239136,-0.001802,0.001821,0.046257,263.842255,13.440765,0.462575,-1293.239136,0.047472,0.000000
36.810001,60.537338,-1293.150269,-0.001781,0.001843,0.046804,269.283539,13.717957,0.468040,-1293.150269,0.047974,0.000000
37.110001,62.041351,-1293.194702,-0.001768,0.001868,0.047437,275.973724,14.058771,0.474368,-1293.194702,0.048477,0.000000
37.410004,62.926476,-1293.150269,-0.001750,0.001885,0.047870,279.910950,14.259343,0.478698,-1293.150269,0.048972,0.000000
37.710003,63.495094,-1293.194702,-0.001763,0.001900,0.048270,282.440277,14.388194,0.482695,-1293.194702,0.049475,0.000000
38.010002,65.025917,-1293.239136,-0.001742,0.001925,0.048902,289.249725,14.735084,0.489024,-1293.239136,0.049977,0.000000
38.310001,66.040260,-1293.194702,-0.001725,0.001935,0.049154,293.761749,14.964937,0.491537,-1293.194702,0.008648,0.000000
38.610001,64.964470,-1293.239136,-0.001729,0.001935,0.049154,288.976410,14.721160,0.491537,-1293.239136,289.297699,0.000000
38.910004,65.133156,-1293.194702,-0.001729,0.001952,0.049579,289.726746,14.759384,0.495791,-1293.194702,294.500488,0.000000
39.210003,64.980858,-1293.239136,-0.001720,0.001960,0.049796,289.049286,14.724873,0.497956,-1293.239136,294.500488,0.000000
39.510002,64.861702,-1293.239136,-0.001703,0.001968,0.049986,288.519257,14.697871,0.499864,-1293.239136,294.500488,0.000000
39.810001,65.021080,-1293.239136,-0.001712,0.001977,0.050221,289.228210,14.733988,0.502210,-1293.239136,294.500488,0.000000
40.110001,65.589317,-1293.194702,-0.001694,0.001989,0.050533,291.755859,14.862752,0.505329,-1293.194702,294.500488,0.000000
40.410004,64.893715,-1293.194702,-0.001694,0.001989,0.050533,288.661652,14.705127,0.505329,-1293.194702,294.500488,0.000000
40.710003,66.647224,-1293.194702,-0.001664,0.001949,0.049493,296.461670,15.102476,0.494928,-1293.194702,294.500488,0.000000
41.010002,65.746452,-1293.194702,-0.001673,0.001950,0.049526,292.454834,14.898359,0.495261,-1293.194702,294.500488,0.000000
41.310001,65.072838,-1293.194702,-0.001660,0.002005,0.050931,289.458435,14.745716,0.509311,-1293.194702,294.500488,0.000000
41.610001,64.838234,-1293.150269,-0.001660,0.002014,0.051149,288.414856,14.692554,0.511491,-1293.150269,294.500488,0.000000
41.910004,65.205772,-1293.194702,-0.001669,0.002023,0.051382,290.049774,14.775839,0.513822,-1293.194702,294.500488,0.000000
42.210003,64.546303,-1293.194702,-0.001677,0.002023,0.051382,287.116302,14.626401,0.513822,-1293.194702,294.500488,0.000000
42.510002,66.866173,-1293.150269,-0.001634,0.001940,0.049275,297.435577,15.152091,0.492748,-1293.150269,294.500488,0.000000
42.810001,66.104301,-1293.150269,-0.001625,0.001934,0.049111,294.046631,14.979448,0.491113,-1293.150269,294.500488,0.000000
43.110001,65.423241,-1293.239136,-0.001621,0.001978,0.050229,291.017120,14.825118,0.502286,-1293.239136,294.500488,0.000000
43.410004,65.238533,-1293.150269,-0.001621,0.002055,0.052189,290.195496,14.783262,0.521892,-1293.150269,294.500488,0.000000
43.710003,65.086983,-1293.150269,-0.001625,0.002055,0.052198,289.521362,14.748921,0.521982,-1293.150269,294.500488,0.000000
44.010002,65.774010,-1293.194702,-0.001634,0.002068,0.052536,292.577393,14.904604,0.525359,-1293.194702,294.500488,0.000000
44.310001,65.275398,-1293.239136,-0.001634,0.002068,0.052536,290.359467,14.791616,0.525359,-1293.239136,294.500488,0.000000
44.610001,64.849037,-1293.239136,-0.001621,0.002071,0.052615,288.462921,14.695002,0.526146,-1293.239136,294.500488,0.000000
44.910004,64.906761,-1293.194702,-0.001613,0.002078,0.052771,288.719696,14.708082,0.527705,-1293.194702,294.500488,0.000000
45.210003,65.334618,-1293.150269,-0.001613,0.002085,0.052970,290.622894,14.805036,0.529704,-1293.150269,294.500488,0.000000
45.510002,65.127205,-1293.239136,-0.001613,0.002089,0.053057,289.700287,14.758035,0.530567,-1293.239136,294.500488,0.000000
45.810001,65.376686,-1293.105713,-0.001613,0.002097,0.053257,290.810028,14.814569,0.532565,-1293.105713,294.500488,0.000000
46.110001,65.057198,-1293.105713,-0.001595,0.002097,0.053264,289.388855,14.742171,0.532641,-1293.105713,294.500488,0.000000
46.410004,65.155495,-1293.105713,-0.001608,0.002107,0.053508,289.826111,14.764446,0.535078,-1293.105713,294.500488,0.000000
46.710003,65.162575,-1293.150269,-0.001600,0.002107,0.053508,289.857605,14.766050,0.535078,-1293.150269,294.500488,0.000000
47.010002,65.104118,-1293.150269,-0.001582,0.002114,0.053706,289.597595,14.752804,0.537061,-1293.150269,294.500488,0.000000
47.310001,65.098900,-1293.150269,-0.001587,0.002114,0.053706,289.574371,14.751621,0.537061,-1293.150269,294.500488,0.000000
47.610001,64.884789,-1293.194702,-0.001587,0.002126,0.054001,288.621948,14.703104,0.540014,-1293.194702,294.500488,0.000000
47.910004,65.775871,-1293.150269,-0.001578,0.002121,0.053871,292.585693,14.905025,0.538712,-1293.150269,294.500488,0.000000
48.210003,65.280983,-1293.194702,-0.001574,0.002121,0.053871,290.384308,14.792882,0.538712,-1293.194702,294.500488,0.000000
48.510002,65.839912,-1293.150269,-0.001578,0.002136,0.054262,292.870544,14.919538,0.542618,-1293.150269,294.500488,0.000000
48.810001,65.507393,-1293.150269,-0.001578,0.002136,0.054262,291.391449,14.844188,0.542618,-1293.150269,294.500488,0.000000
49.110001,65.144325,-1293.194702,-0.001556,0.002136,0.054262,289.776428,14.761915,0.542618,-1293.194702,294.500488,0.000000
49.410004,64.764885,-1293.150269,-0.001561,0.002136,0.054262,288.088593,14.675933,0.542618,-1293.150269,294.500488,0.000000
49.710003,66.664360,-1293.150269,-0.001556,0.002126,0.054010,296.537872,15.106360,0.540105,-1293.150269,294.500488,0.000000
50.010002,66.073769,-1293.150269,-0.001548,0.002116,0.053750,293.910797,14.972530,0.537501,-1293.150269,294.500488,0.000000
50.310001,65.668251,-1293.150269,-0.001539,0.002117,0.053776,292.106964,14.880638,0.537758,-1293.150269,294.500488,0.000000
50.610001,65.306679,-1293.061279,-0.001552,0.002139,0.054322,290.498627,14.798705,0.543223,-1293.061279,294.500488,0.000000
50.910004,65.072456,-1293.150269,-0.001544,0.002153,0.054687,289.456757,14.745629,0.546872,-1293.150269,294.500488,0.000000
51.210003,64.961494,-1293.150269,-0.001548,0.002158,0.054808,288.963165,14.720485,0.548083,-1293.150269,294.500488,0.000000
51.510002,65.226997,-1293.105713,-0.001552,0.002165,0.054999,290.144165,14.780648,0.549991,-1293.105713,294.500488,0.000000
51.810001,65.076561,-1293.105713,-0.001535,0.002165,0.054999,289.475006,14.746559,0.549991,-1293.105713,294.500488,0.000000
52.110001,65.337593,-1293.105713,-0.001539,0.002173,0.055190,290.636139,14.805711,0.551898,-1293.105713,294.500488,0.000000
52.410004,65.198692,-1293.105713,-0.001544,0.002173,0.055190,290.018280,14.774235,0.551898,-1293.105713,294.500488,0.000000
52.710003,65.070595,-1293.150269,-0.001544,0.002175,0.055250,289.448456,14.745208,0.552504,-1293.150269,294.500488,0.000000
53.010002,65.806404,-1293.194702,-0.001535,0.002185,0.055493,292.721497,14.911944,0.554926,-1293.194702,294.500488,0.000000
53.310001,65.556923,-1293.150269,-0.001535,0.002185,0.055493,291.611755,14.855412,0.554926,-1293.150269,294.500488,0.000000
53.610004,65.279869,-1293.105713,-0.001526,0.002185,0.055493,290.379364,14.792629,0.554926,-1293.105713,294.500488,0.000000
53.910004,65.008415,-1293.105713,-0.001526,0.002186,0.055520,289.171875,14.731118,0.555199,-1293.105713,294.500488,0.000000
54.210003,65.826515,-1293.061279,-0.001509,0.002197,0.055814,292.810974,14.916502,0.558136,-1293.061279,294.500488,0.000000
54.510002,65.640694,-1293.194702,-0.001513,0.002197,0.055814,291.984375,14.874393,0.558136,-1293.194702,294.500488,0.000000
54.810001,65.401634,-1293.150269,-0.001522,0.002197,0.055814,290.920990,14.820223,0.558136,-1293.150269,294.500488,0.000000
55.110004,65.145073,-1293.105713,-0.001522,0.002197,0.055814,289.779755,14.762084,0.558136,-1293.105713,294.500488,0.000000
55.410004,64.882545,-1293.150269,-0.001500,0.002197,0.055814,288.611969,14.702596,0.558136,-1293.150269,294.500488,0.000000
55.710003,65.820183,-1293.105713,-0.001500,0.002211,0.056162,292.782806,14.915067,0.561618,-1293.105713,294.500488,0.000000
56.010002,65.594521,-1293.105713,-0.001505,0.002210,0.056144,291.778992,14.863931,0.561436,-1293.105713,294.500488,0.000000
56.310001,65.356575,-1293.105713,-0.001509,0.002210,0.056144,290.720551,14.810012,0.561436,-1293.105713,294.500488,0.000000
56.610004,65.104118,-1293.150269,-0.001509,0.002210,0.056144,289.597595,14.752804,0.561436,-1293.150269,294.500488,0.000000
56.910004,64.869148,-1293.194702,-0.001487,0.002210,0.056144,288.552368,14.699559,0.561436,-1293.194702,294.500488,0.000000
57.210003,66.003761,-1293.150269,-0.001500,0.002214,0.056239,293.599396,14.956666,0.562390,-1293.150269,294.500488,0.000000
57.510002,65.762459,-1293.150269,-0.001500,0.002214,0.056239,292.526031,14.901986,0.562390,-1293.150269,294.500488,0.000000
57.810001,65.461967,-1293.150269,-0.001492,0.002214,0.056239,291.189362,14.833894,0.562390,-1293.150269,294.500488,0.000000
58.110004,65.153267,-1293.150269,-0.001500,0.002214,0.056239,289.816193,14.763942,0.562390,-1293.150269,294.500488,0.000000
58.410004,65.520424,-1293.150269,-0.001496,0.002229,0.056621,291.449402,14.847140,0.566205,-1293.150269,294.500488,0.000000
58.710003,65.315254,-1293.194702,-0.001492,0.002229,0.056621,290.536774,14.800649,0.566205,-1293.194702,294.500488,0.000000
59.010002,65.140236,-1293.194702,-0.001492,0.002230,0.056646,289.758240,14.760988,0.566463,-1293.194702,294.500488,0.000000
59.310001,65.040443,-1293.150269,-0.001487,0.002231,0.056674,289.314331,14.738375,0.566735,-1293.150269,294.500488,0.000000
59.610004,64.923515,-1293.150269,-0.001487,0.002234,0.056734,288.794220,14.711879,0.567341,-1293.150269,294.500488,0.000000
59.910004,65.023674,-1293.105713,-0.001500,0.002236,0.056795,289.239746,14.734575,0.567946,-1293.105713,294.500488,0.000000
60.210003,65.125710,-1293.194702,-0.001483,0.002241,0.056925,289.693634,14.757697,0.569248,-1293.194702,294.500488,0.000000
60.510002,65.083626,-1293.194702,-0.001487,0.002241,0.056925,289.506439,14.748160,0.569248,-1293.194702,294.500488,0.000000
60.810001,65.193474,-1293.150269,-0.001487,0.002245,0.057011,289.995056,14.773052,0.570111,-1293.150269,294.500488,0.000000
61.110004,65.043785,-1293.194702,-0.001466,0.002245,0.057020,289.329193,14.739132,0.570202,-1293.194702,294.500488,0.000000
61.410004,65.190132,-1293.150269,-0.001479,0.002248,0.057097,289.980194,14.772295,0.570974,-1293.150269,294.500488,0.000000
61.710003,65.081764,-1293.194702,-0.001466,0.002250,0.057150,289.498138,14.747739,0.571504,-1293.194702,294.500488,0.000000
62.010002,65.338707,-1293.105713,-0.001483,0.002257,0.057323,290.641083,14.805963,0.573230,-1293.105713,294.500488,0.000000
62.310001,65.319344,-1293.150269,-0.001483,0.002255,0.057288,290.554962,14.801575,0.572882,-1293.150269,294.500488,0.000000
62.610004,65.164070,-1293.105713,-0.001479,0.002255,0.057288,289.864258,14.766389,0.572882,-1293.105713,294.500488,0.000000
62.910004,64.982719,-1293.105713,-0.001466,0.002255,0.057288,289.057587,14.725295,0.572882,-1293.105713,294.500488,0.000000
63.210003,64.786110,-1293.105713,-0.001449,0.002255,0.057288,288.183014,14.680742,0.572882,-1293.105713,294.500488,0.000000
63.510002,64.606987,-1293.194702,-0.001470,0.002255,0.057288,287.386230,14.640152,0.572882,-1293.194702,294.500488,0.000000
63.810001,66.359001,-1293.105713,-0.001453,0.002243,0.056967,295.179565,15.037165,0.569672,-1293.105713,294.500488,0.000000
64.110001,66.135963,-1293.150269,-0.001444,0.002243,0.056967,294.187469,14.986623,0.569672,-1293.150269,294.500488,0.000000
64.410004,65.856682,-1293.150269,-0.001470,0.002243,0.056967,292.945160,14.923338,0.569672,-1293.150269,294.500488,0.000000
64.710007,65.671242,-1293.105713,-0.001457,0.002243,0.056976,292.120270,14.881316,0.569763,-1293.105713,294.500488,0.000000
65.010002,65.491005,-1293.105713,-0.001449,0.002244,0.056985,291.318542,14.840473,0.569854,-1293.105713,294.500488,0.000000
65.310005,65.302208,-1293.150269,-0.001440,0.002259,0.057384,290.478729,14.797691,0.573835,-1293.150269,294.500488,0.000000
65.610001,65.126823,-1293.150269,-0.001444,0.002266,0.057558,289.698578,14.757949,0.575577,-1293.150269,294.500488,0.000000
65.910004,65.367012,-1293.150269,-0.001453,0.002275,0.057791,290.766998,14.812377,0.577908,-1293.150269,294.500488,0.000000
66.210007,65.246361,-1293.061279,-0.001453,0.002275,0.057791,290.230316,14.785036,0.577908,-1293.061279,294.500488,0.000000
66.510002,65.219551,-1293.105713,-0.001457,0.002278,0.057860,290.111053,14.778962,0.578604,-1293.105713,294.500488,0.000000
66.810005,65.126076,-1293.105713,-0.001453,0.002279,0.057886,289.695251,14.757779,0.578862,-1293.105713,294.500488,0.000000
67.110001,65.153267,-1293.239136,-0.001449,0.002281,0.057939,289.816193,14.763942,0.579392,-1293.239136,294.500488,0.000000
67.410004,65.061287,-1293.061279,-0.001449,0.002282,0.057956,289.407043,14.743098,0.579558,-1293.061279,294.500488,0.000000
67.710007,65.162941,-1293.150269,-0.001457,0.002286,0.058069,289.859253,14.766133,0.580694,-1293.150269,294.500488,0.000000
68.010002,65.172249,-1293.105713,-0.001440,0.002286,0.058069,289.900635,14.768242,0.580694,-1293.105713,294.500488,0.000000
68.310005,65.029259,-1293.105713,-0.001449,0.002286,0.058069,289.264587,14.735841,0.580694,-1293.105713,294.500488,0.000000
68.610001,65.007301,-1293.150269,-0.001436,0.002292,0.058207,289.166931,14.730865,0.582071,-1293.150269,294.500488,0.000000
68.910004,65.219917,-1293.105713,-0.001449,0.002292,0.058216,290.112671,14.779044,0.582162,-1293.105713,294.500488,0.000000
69.210007,65.108208,-1293.150269,-0.001449,0.002292,0.058225,289.615784,14.753730,0.582253,-1293.150269,294.500488,0.000000
69.510002,65.137627,-1293.150269,-0.001436,0.002294,0.058277,289.746643,14.760398,0.582768,-1293.150269,294.500488,0.000000
69.810005,65.136879,-1293.105713,-0.001457,0.002298,0.058365,289.743317,14.760228,0.583646,-1293.105713,294.500488,0.000000
70.110001,65.200935,-1293.150269,-0.001436,0.002298,0.058372,290.028259,14.774743,0.583722,-1293.150269,294.500488,0.000000
70.410004,65.124596,-1293.105713,-0.001436,0.002298,0.058381,289.688660,14.757444,0.583812,-1293.105713,294.500488,0.000000
70.710007,65.054955,-1293.194702,-0.001436,0.002299,0.058407,289.378876,14.741663,0.584070,-1293.194702,294.500488,0.000000
71.010002,65.144707,-1293.061279,-0.001436,0.002302,0.058477,289.778137,14.762002,0.584766,-1293.061279,294.500488,0.000000
71.310005,65.079536,-1293.150269,-0.001431,0.002303,0.058486,289.488251,14.747233,0.584857,-1293.150269,294.500488,0.000000
71.610001,65.307060,-1293.061279,-0.001423,0.002309,0.058642,290.500305,14.798792,0.586416,-1293.061279,294.500488,0.000000
71.910004,65.375572,-1293.105713,-0.001431,0.002309,0.058642,290.805084,14.814316,0.586416,-1293.105713,294.500488,0.000000
72.210007,65.280251,-1293.105713,-0.001423,0.002309,0.058642,290.381042,14.792717,0.586416,-1293.105713,294.500488,0.000000
72.510002,65.209496,-1293.061279,-0.001440,0.002309,0.058658,290.066315,14.776683,0.586583,-1293.061279,294.500488,0.000000
72.810005,65.101875,-1293.061279,-0.001440,0.002313,0.058754,289.587616,14.752295,0.587537,-1293.061279,294.500488,0.000000
73.110001,65.319710,-1293.150269,-0.001436,0.002313,0.058763,290.556580,14.801658,0.587628,-1293.150269,294.500488,0.000000
73.410004,65.228859,-1293.061279,-0.001427,0.002313,0.058763,290.152466,14.781071,0.587628,-1293.061279,294.500488,0.000000
73.710007,65.102623,-1293.061279,-0.001436,0.002314,0.058772,289.590942,14.752465,0.587718,-1293.061279,294.500488,0.000000
74.010002,65.499565,-1293.061279,-0.001427,0.002320,0.058937,291.356628,14.842414,0.589369,-1293.061279,294.500488,0.000000
74.310005,65.443718,-1293.061279,-0.001418,0.002319,0.058902,291.108185,14.829759,0.589020,-1293.061279,294.500488,0.000000
74.610001,65.289177,-1293.150269,-0.001418,0.002319,0.058902,290.420776,14.794740,0.589020,-1293.150269,294.500488,0.000000
74.910004,65.193108,-1293.105713,-0.001431,0.002319,0.058902,289.993439,14.772969,0.589020,-1293.105713,294.500488,0.000000
75.210007,65.042305,-1293.061279,-0.001427,0.002319,0.058902,289.322632,14.738797,0.589020,-1293.061279,294.500488,0.000000
75.510002,64.923134,-1293.061279,-0.001418,0.002319,0.058902,288.792511,14.711793,0.589020,-1293.061279,294.500488,0.000000
75.810005,65.701775,-1293.061279,-0.001423,0.002329,0.059162,292.256104,14.888235,0.591624,-1293.061279,294.500488,0.000000
76.110001,65.605324,-1293.061279,-0.001423,0.002329,0.059162,291.827057,14.866379,0.591624,-1293.061279,294.500488,0.000000
76.410004,65.524147,-1293.061279,-0.001414,0.002329,0.059162,291.465973,14.847984,0.591624,-1293.061279,294.500488,0.000000
76.710007,65.404991,-1293.061279,-0.001418,0.002329,0.059162,290.935944,14.820983,0.591624,-1293.061279,294.500488,0.000000
77.010002,65.295509,-1293.105713,-0.001406,0.002329,0.059162,290.448944,14.796174,0.591624,-1293.105713,294.500488,0.000000
77.310005,65.175240,-1293.061279,-0.001414,0.002329,0.059162,289.913940,14.768920,0.591624,-1293.061279,294.500488,0.000000
77.610001,65.047142,-1293.061279,-0.001397,0.002329,0.059162,289.344147,14.739893,0.591624,-1293.061279,294.500488,0.000000
77.910004,64.933937,-1293.061279,-0.001397,0.002329,0.059162,288.840576,14.714240,0.591624,-1293.061279,294.500488,0.000000
78.210007,65.623573,-1293.016724,-0.001410,0.002345,0.059570,291.908234,14.870514,0.595697,-1293.016724,294.500488,0.000000
78.510002,65.852211,-1293.061279,-0.001406,0.002335,0.059300,292.925262,14.922324,0.593002,-1293.061279,294.500488,0.000000
78.810005,65.744591,-1293.016724,-0.001423,0.002335,0.059300,292.446533,14.897937,0.593002,-1293.016724,294.500488,0.000000
79.110001,65.562874,-1293.016724,-0.001406,0.002335,0.059300,291.638214,14.856759,0.593002,-1293.016724,294.500488,0.000000
79.410004,65.406105,-1293.016724,-0.001397,0.002335,0.059300,290.940887,14.821236,0.593002,-1293.016724,294.500488,0.000000
79.710007,65.287315,-1293.016724,-0.001393,0.002335,0.059300,290.412476,14.794317,0.593002,-1293.016724,294.500488,0.000000
80.010002,65.160713,-1293.061279,-0.001406,0.002335,0.059300,289.849335,14.765629,0.593002,-1293.061279,294.500488,0.000000
80.310005,65.013618,-1293.016724,-0.001401,0.002335,0.059300,289.195007,14.732296,0.593002,-1293.016724,294.500488,0.000000
80.610001,65.750175,-1293.061279,-0.001393,0.002347,0.059612,292.471375,14.899202,0.596121,-1293.061279,294.500488,0.000000
80.910004,65.614265,-1293.105713,-0.001401,0.002347,0.059612,291.866821,14.868405,0.596121,-1293.105713,294.500488,0.000000
81.210007,65.535698,-1292.972290,-0.001393,0.002347,0.059612,291.517334,14.850601,0.596121,-1292.972290,294.500488,0.000000
81.510002,65.394188,-1293.016724,-0.001410,0.002347,0.059612,290.887878,14.818535,0.596121,-1293.016724,294.500488,0.000000
81.810005,65.292152,-1293.016724,-0.001397,0.002347,0.059612,290.433990,14.795413,0.596121,-1293.016724,294.500488,0.000000
82.110001,65.194603,-1293.016724,-0.001401,0.002347,0.059612,290.000092,14.773308,0.596121,-1293.016724,294.500488,0.000000
82.410004,65.049751,-1292.972290,-0.001388,0.002347,0.059612,289.355743,14.740485,0.596121,-1292.972290,294.500488,0.000000
82.710007,64.970802,-1293.105713,-0.001388,0.002347,0.059612,289.004578,14.722594,0.596121,-1293.105713,294.500488,0.000000
83.010002,64.843452,-1293.016724,-0.001384,0.002347,0.059612,288.438080,14.693736,0.596121,-1293.016724,294.500488,0.000000
83.310005,65.852577,-1293.016724,-0.001397,0.002358,0.059898,292.926880,14.922407,0.598982,-1293.016724,294.500488,0.000000
83.610001,65.770287,-1293.016724,-0.001384,0.002358,0.059898,292.560852,14.903760,0.598982,-1293.016724,294.500488,0.000000
83.910004,65.669746,-1293.061279,-0.001384,0.002358,0.059898,292.113617,14.880977,0.598982,-1293.061279,294.500488,0.000000
84.210007,65.570702,-1293.016724,-0.001401,0.002358,0.059898,291.673035,14.858533,0.598982,-1293.016724,294.500488,0.000000
84.510002,65.488777,-1292.927856,-0.001384,0.002358,0.059898,291.308624,14.839969,0.598982,-1292.927856,294.500488,0.000000
84.810005,65.364769,-1292.972290,-0.001384,0.002358,0.059898,290.757019,14.811869,0.598982,-1292.972290,294.500488,0.000000
85.110001,65.277641,-1292.972290,-0.001380,0.002358,0.059898,290.369446,14.792125,0.598982,-1292.972290,294.500488,0.000000
85.410004,65.174858,-1293.016724,-0.001384,0.002358,0.059898,289.912262,14.768834,0.598982,-1293.016724,294.500488,0.000000
85.710007,65.065392,-1293.016724,-0.001393,0.002358,0.059898,289.425323,14.744028,0.598982,-1293.016724,294.500488,0.000000
86.010002,64.977882,-1293.016724,-0.001393,0.002358,0.059898,289.036041,14.724199,0.598982,-1293.016724,294.500488,0.000000
86.310005,64.853508,-1293.061279,-0.001380,0.002358,0.059898,288.482819,14.696015,0.598982,-1293.061279,294.500488,0.000000
86.610001,65.710701,-1292.972290,-0.001393,0.002369,0.060168,292.295807,14.890258,0.601677,-1292.972290,294.500488,0.000000
86.910004,65.673103,-1293.016724,-0.001375,0.002369,0.060168,292.128540,14.881738,0.601677,-1293.016724,294.500488,0.000000
87.210007,65.589684,-1293.016724,-0.001371,0.002369,0.060168,291.757477,14.862835,0.601677,-1293.016724,294.500488,0.000000
87.510002,65.531975,-1292.972290,-0.001380,0.002369,0.060168,291.500793,14.849758,0.601677,-1292.972290,294.500488,0.000000
87.810005,65.447441,-1293.016724,-0.001375,0.002369,0.060168,291.124756,14.830602,0.601677,-1293.016724,294.500488,0.000000
88.110001,65.333122,-1293.061279,-0.001371,0.002369,0.060168,290.616241,14.804697,0.601677,-1293.061279,294.500488,0.000000
88.410004,65.260139,-1293.016724,-0.001375,0.002369,0.060168,290.291595,14.788159,0.601677,-1293.016724,294.500488,0.000000
88.710007,65.178215,-1293.061279,-0.001375,0.002369,0.060177,289.927185,14.769595,0.601768,-1293.061279,294.500488,0.000000
89.010002,65.065010,-1292.972290,-0.001380,0.002369,0.060177,289.423615,14.743942,0.601768,-1292.972290,294.500488,0.000000
89.310005,64.987556,-1293.016724,-0.001375,0.002369,0.060177,289.079102,14.726391,0.601768,-1293.016724,294.500488,0.000000
89.610001,64.900047,-1293.061279,-0.001375,0.002369,0.060177,288.689819,14.706561,0.601768,-1293.061279,294.500488,0.000000
89.910004,64.778664,-1293.016724,-0.001367,0.002369,0.060177,288.149902,14.679055,0.601768,-1293.016724,294.500488,0.000000
90.210007,65.759117,-1293.061279,-0.001362,0.002380,0.060454,292.511169,14.901229,0.604539,-1293.061279,294.500488,0.000000
90.510002,65.677940,-1293.016724,-0.001380,0.002380,0.060454,292.150055,14.882834,0.604539,-1293.016724,294.500488,0.000000
90.810005,65.628792,-1293.016724,-0.001367,0.002380,0.060454,291.931458,14.871696,0.604539,-1293.016724,294.500488,0.000000
91.110001,65.575539,-1292.972290,-0.001358,0.002380,0.060454,291.694550,14.859629,0.604539,-1292.972290,294.500488,0.000000
91.410004,65.498085,-1293.061279,-0.001367,0.002380,0.060454,291.350037,14.842078,0.604539,-1293.061279,294.500488,0.000000
91.710007,65.404243,-1292.972290,-0.001367,0.002380,0.060454,290.932617,14.820813,0.604539,-1292.972290,294.500488,0.000000
92.010002,65.332008,-1293.016724,-0.001358,0.002380,0.060454,290.611298,14.804445,0.604539,-1293.016724,294.500488,0.000000
92.310005,65.257530,-1293.016724,-0.001367,0.002380,0.060454,290.279999,14.787567,0.604539,-1293.016724,294.500488,0.000000
92.610001,65.165932,-1293.016724,-0.001375,0.002380,0.060454,289.872528,14.766811,0.604539,-1293.016724,294.500488,0.000000
92.910004,65.057945,-1293.061279,-0.001367,0.002380,0.060454,289.392181,14.742341,0.604539,-1293.061279,294.500488,0.000000
93.210007,64.994637,-1293.016724,-0.001362,0.002380,0.060454,289.110596,14.727995,0.604539,-1293.016724,294.500488,0.000000
93.510002,64.921654,-1293.016724,-0.001354,0.002380,0.060463,288.785950,14.711456,0.604629,-1293.016724,294.500488,0.000000
93.810005,65.833214,-1293.016724,-0.001358,0.002391,0.060723,292.840759,14.918019,0.607233,-1293.016724,294.500488,0.000000
94.110008,65.781822,-1293.061279,-0.001362,0.002391,0.060723,292.612152,14.906374,0.607233,-1293.061279,294.500488,0.000000
94.410004,65.725227,-1293.061279,-0.001371,0.002391,0.060723,292.360413,14.893550,0.607233,-1293.061279,294.500488,0.000000
94.710007,65.634377,-1293.061279,-0.001358,0.002391,0.060723,291.956299,14.872962,0.607233,-1293.061279,294.500488,0.000000
95.010002,65.567711,-1293.061279,-0.001371,0.002391,0.060723,291.659760,14.857855,0.607233,-1293.061279,294.500488,0.000000
95.310005,65.508141,-1293.105713,-0.001354,0.002391,0.060723,291.394775,14.844357,0.607233,-1293.105713,294.500488,0.000000
95.610008,65.418022,-1293.061279,-0.001350,0.002391,0.060723,290.993896,14.823936,0.607233,-1293.061279,294.500488,0.000000
95.910004,65.325294,-1293.016724,-0.001354,0.002391,0.060723,290.581421,14.802923,0.607233,-1293.016724,294.500488,0.000000
96.210007,65.260139,-1293.016724,-0.001354,0.002391,0.060723,290.291595,14.788159,0.607233,-1293.016724,294.500488,0.000000
96.510002,65.186409,-1293.061279,-0.001358,0.002391,0.060723,289.963623,14.771451,0.607233,-1293.061279,294.500488,0.000000
96.810005,65.089592,-1293.061279,-0.001354,0.002391,0.060731,289.532959,14.749513,0.607309,-1293.061279,294.500488,0.000000
97.110008,65.048622,-1293.061279,-0.001358,0.002392,0.060766,289.350708,14.740228,0.607657,-1293.061279,294.500488,0.000000
97.410004,65.004692,-1293.016724,-0.001354,0.002392,0.060766,289.155304,14.730273,0.607657,-1293.016724,294.500488,0.000000
97.710007,65.054207,-1293.061279,-0.001371,0.002395,0.060826,289.375549,14.741493,0.608263,-1293.061279,294.500488,0.000000
98.010002,65.031502,-1293.105713,-0.001362,0.002395,0.060826,289.274567,14.736349,0.608263,-1293.105713,294.500488,0.000000
98.310005,65.071342,-1293.061279,-0.001375,0.002397,0.060879,289.451782,14.745378,0.608793,-1293.061279,294.500488,0.000000
98.610008,65.110817,-1293.105713,-0.001367,0.002397,0.060887,289.627380,14.754322,0.608868,-1293.105713,294.500488,0.000000
98.910004,65.064262,-1293.016724,-0.001350,0.002397,0.060887,289.420288,14.743773,0.608868,-1293.016724,1681.640991,0.000000
99.210007,64.955528,-1293.061279,-0.001350,0.002388,0.060654,288.936615,14.719133,0.606537,-1293.061279,0.060523,0.000000
99.510002,64.881432,-1293.105713,-0.001345,0.002376,0.060358,288.607025,14.702343,0.603585,-1293.105713,0.060021,0.000000
99.810005,64.767113,-1293.061279,-0.001341,0.002360,0.059942,288.098511,14.676437,0.599421,-1293.061279,0.059526,0.000000
100.110008,64.630821,-1293.061279,-0.001328,0.002346,0.059595,287.492249,14.645554,0.595954,-1293.061279,0.059023,0.000000
100.410004,64.499748,-1293.061279,-0.001332,0.002324,0.059040,286.909210,14.615852,0.590398,-1293.061279,0.058521,0.000000
100.710007,64.401817,-1293.061279,-0.001337,0.002304,0.058521,286.473602,14.593660,0.585205,-1293.061279,0.058025,0.000000
101.010002,64.328453,-1293.105713,-0.001332,0.002284,0.058025,286.147247,14.577036,0.580255,-1293.105713,0.057523,0.000000
101.310005,64.262550,-1293.061279,-0.001345,0.002265,0.057523,285.854095,14.562102,0.575228,-1293.061279,0.057020,0.000000
101.610008,64.161644,-1293.061279,-0.001332,0.002256,0.057314,285.405243,14.539236,0.573139,-1293.061279,0.056525,0.000000
101.910004,64.049187,-1293.061279,-0.001332,0.002226,0.056551,284.904999,14.513753,0.565509,-1293.061279,0.056022,0.000000
102.210007,63.952370,-1293.016724,-0.001341,0.002208,0.056074,284.474335,14.491815,0.560740,-1293.016724,0.055520,0.000000
102.510002,63.827614,-1293.061279,-0.001332,0.002188,0.055571,283.919403,14.463545,0.555713,-1293.061279,0.055025,0.000000
102.810005,63.672340,-1293.016724,-0.001328,0.002172,0.055173,283.228729,14.428358,0.551732,-1293.016724,0.054522,0.000000
103.110008,62.996109,-1293.061279,-0.001319,0.002149,0.054592,280.220703,14.275123,0.545918,-1293.061279,0.054020,0.000000
103.410004,62.294937,-1293.150269,-0.001315,0.002130,0.054106,277.101715,14.116234,0.541058,-1293.150269,0.053524,0.000000
103.710007,61.525238,-1293.061279,-0.001324,0.002118,0.053794,273.677917,13.941818,0.537940,-1293.061279,0.053022,0.000000
104.010002,60.744003,-1293.016724,-0.001324,0.002103,0.053412,270.202820,13.764788,0.534124,-1293.016724,0.052519,0.000000
104.310005,59.772858,-1293.061279,-0.001332,0.002084,0.052943,265.882965,13.544724,0.529431,-1293.061279,0.052024,0.000000
104.610008,58.630791,-1293.061279,-0.001319,0.002067,0.052493,260.802795,13.285927,0.524935,-1293.061279,0.051522,0.000000
104.910004,57.150612,-1292.972290,-0.001319,0.002047,0.051982,254.218613,12.950513,0.519817,-1292.972290,0.051019,0.000000
105.210007,54.922707,-1293.061279,-0.001315,0.002017,0.051244,244.308395,12.445662,0.512444,-1293.061279,0.050524,0.000000
105.510002,53.471199,-1293.061279,-0.001315,0.002003,0.050871,237.851776,12.116747,0.508705,-1293.061279,0.050021,0.000000
105.810005,52.575638,-1293.061279,-0.001315,0.001993,0.050619,233.868118,11.913810,0.506192,-1293.061279,0.049519,0.000000
106.110008,50.973320,-1293.061279,-0.001328,0.001975,0.050168,226.740646,11.550719,0.501680,-1293.061279,0.049023,0.000000
106.410004,48.791962,-1293.061279,-0.001328,0.001955,0.049649,217.037491,11.056417,0.496487,-1293.061279,0.048521,0.000000
106.710007,46.715988,-1293.061279,-0.001332,0.001935,0.049145,207.803101,10.585995,0.491446,-1293.061279,0.048018,0.000000
107.010002,45.099518,-1292.972290,-0.001315,0.001918,0.048728,200.612671,10.219697,0.487283,-1292.972290,0.047523,0.000000
107.310005,42.769211,-1293.061279,-0.001332,0.001896,0.048148,190.246948,9.691642,0.481484,-1293.061279,0.047021,0.000000
107.610008,39.768265,-1293.016724,-0.001332,0.001872,0.047558,176.898071,9.011618,0.475580,-1293.016724,0.046527,0.000000
107.910004,37.865814,-1293.061279,-0.001341,0.001852,0.047037,168.435547,8.580516,0.470372,-1293.061279,0.046023,0.000000
108.210007,35.433846,-1293.105713,-0.001328,0.001832,0.046544,157.617615,8.029424,0.465436,-1293.105713,0.045520,0.000000
108.510002,33.345581,-1293.061279,-0.001341,0.001815,0.046092,148.328552,7.556216,0.460925,-1293.061279,0.045027,0.000000
108.810005,31.092728,-1293.061279,-0.001328,0.001794,0.045564,138.307358,7.045713,0.455641,-1293.061279,0.044522,0.000000
109.110008,29.340340,-1293.061279,-0.001341,0.001778,0.045173,130.512344,6.648616,0.451735,-1293.061279,0.044020,0.000000
109.410004,26.083199,-1293.061279,-0.001341,0.001747,0.044376,116.023865,5.910537,0.443756,-1293.061279,0.043526,0.000000
109.710007,24.380341,-1293.016724,-0.001350,0.001732,0.044003,108.449173,5.524664,0.440032,-1293.016724,0.043022,0.000000
110.010002,22.350166,-1293.061279,-0.001358,0.001714,0.043543,99.418503,5.064620,0.435429,-1293.061279,0.042520,0.000000
110.310005,19.882828,-1293.061279,-0.001341,0.001693,0.043005,88.443237,4.505513,0.430055,-1293.061279,0.042026,0.000000
110.610008,17.917076,-1293.061279,-0.001362,0.001672,0.042476,79.699135,4.060068,0.424756,-1293.061279,0.041522,0.000000
110.910004,15.960258,-1293.016724,-0.001362,0.001656,0.042059,70.994774,3.616646,0.420593,-1293.016724,0.041019,0.000000
111.210007,14.169518,-1293.061279,-0.001358,0.001640,0.041652,63.029163,3.210859,0.416520,-1293.061279,0.040526,0.000000
111.510002,12.239510,-1293.016724,-0.001371,0.001621,0.041175,54.444057,2.773512,0.411751,-1293.016724,0.040021,0.000000
111.810005,9.573692,-1293.105713,-0.001380,0.001595,0.040517,42.585911,2.169430,0.405165,-1293.105713,0.039519,0.000000
112.110008,7.580017,-1293.061279,-0.001375,0.001576,0.040031,33.717602,1.717656,0.400306,-1293.061279,0.039025,0.000000
112.410004,6.033554,-1293.016724,-0.001375,0.001561,0.039658,26.838589,1.367223,0.396581,-1293.016724,0.038521,0.000000
112.710007,3.668617,-1293.105713,-0.001388,0.001537,0.039051,16.318825,0.831321,0.390510,-1293.105713,0.038019,0.000000
113.010002,2.097572,-1293.016724,-0.001384,0.001521,0.038644,9.330468,0.475317,0.386438,-1293.016724,0.037525,0.000000
113.310005,-0.050270,-1293.016724,-0.001393,0.001500,0.038088,-0.223612,-0.011391,0.380882,-1293.016724,0.037021,0.000000
113.610008,-1.206116,-1292.972290,-0.001393,0.001484,0.037681,-5.365071,-0.273310,0.376809,-1292.972290,0.036518,0.000000
113.910004,-3.117874,-1293.016724,-0.001397,0.001465,0.037221,-13.868997,-0.706520,0.372207,-1293.016724,0.036025,0.000000
114.210007,-0.311676,-1293.016724,-0.001449,0.001440,0.036571,-1.386404,-0.070627,0.365712,-1293.016724,0.035520,0.000000
114.510002,-0.189911,-1293.016724,-0.001440,0.001419,0.036032,-0.844766,-0.043034,0.360322,-1293.016724,0.035018,0.000000
114.810005,-0.091972,-1293.016724,-0.001449,0.001402,0.035608,-0.409113,-0.020841,0.356083,-1293.016724,0.034524,0.000000
115.110008,-0.076340,-1293.016724,-0.001479,0.001376,0.034941,-0.339576,-0.017299,0.349406,-1293.016724,0.034020,0.000000
115.410004,-0.070007,-1293.016724,-0.001462,0.001368,0.034741,-0.311408,-0.015864,0.347408,-1293.016724,0.033518,0.000000
115.710007,-0.090485,-1293.016724,-0.001492,0.001345,0.034169,-0.402496,-0.020504,0.341685,-1293.016724,0.033024,0.000000
116.010002,-0.075966,-1293.016724,-0.001496,0.001330,0.033778,-0.337913,-0.017214,0.337779,-1293.016724,0.032520,0.000000
116.310005,-0.077454,-1293.016724,-0.001522,0.001313,0.033362,-0.344531,-0.017551,0.333616,-1293.016724,0.032017,0.000000
116.610008,-0.092720,-1292.972290,-0.001522,0.001281,0.032547,-0.412439,-0.021011,0.325471,-1292.972290,0.031524,0.000000
116.910004,-0.062561,-1293.061279,-0.001531,0.001265,0.032122,-0.278285,-0.014177,0.321216,-1293.061279,0.031019,0.000000
117.210007,-0.046921,-1293.016724,-0.001552,0.001242,0.031540,-0.208714,-0.010632,0.315403,-1293.016724,0.030517,0.000000
117.510002,-0.045799,-1292.927856,-0.001552,0.001227,0.031159,-0.203725,-0.010378,0.311588,-1292.927856,0.030023,0.000000
117.810005,-0.070747,-1293.061279,-0.001565,0.001205,0.030605,-0.314700,-0.016032,0.306047,-1293.061279,0.029521,0.000000
118.110008,-0.037979,-1293.061279,-0.001587,0.001188,0.030170,-0.168940,-0.008606,0.301702,-1293.061279,0.029017,0.000000
118.410004,-0.046921,-1292.972290,-0.001604,0.001168,0.029677,-0.208714,-0.010632,0.296766,-1292.972290,0.028523,0.000000
118.710007,-0.037613,-1293.061279,-0.001613,0.001148,0.029165,-0.167311,-0.008523,0.291649,-1293.061279,0.028020,0.000000
119.010002,-0.004097,-1293.016724,-0.001634,0.001125,0.028565,-0.018224,-0.000928,0.285654,-1293.016724,0.027516,0.000000
119.300003,-0.009682,-1293.061279,-0.001634,0.001117,0.028375,-0.043066,-0.002194,0.283746,-1293.061279,0.028263,0.000000