File: Data/compression 19/AutoNoHeating-17-19-reverse-2-3re_09112024_163621.csv
Time (sec),S:Load (lbs),S:HL1 (DIM),S:LVDT (in),S:Position (in),Ch:Position (mm),Ch:Load (N),Ch:Stress (MPa),Ch:Strain (mm/mm),Ch:HL1 (DIM),Set Point (),Cycles ()
0.110000,-0.070381,-46.882923,-0.006804,-0.006824,-0.173332,-0.313071,-0.015949,-1.733324,-46.882923,-0.173098,0.000000
0.470000,0.007446,-46.882923,-0.006812,-0.006760,-0.171693,0.033123,0.001687,-1.716933,-46.882923,-0.171000,0.000000
0.830000,0.018616,-46.927402,-0.006735,-0.006553,-0.166447,0.082807,0.004218,-1.664466,-46.927402,-0.164998,0.000000
1.190000,-0.024208,-46.971886,-0.006480,-0.006312,-0.160324,-0.107683,-0.005486,-1.603240,-46.971886,-0.158997,0.000000
1.550000,-0.043571,-46.971886,-0.006222,-0.006069,-0.154141,-0.193816,-0.009873,-1.541407,-46.971886,-0.152996,0.000000
1.910000,-0.007446,-47.060844,-0.005993,-0.005832,-0.148131,-0.033123,-0.001687,-1.481308,-47.060844,-0.147012,0.000000
2.270000,0.024948,-47.016365,-0.005764,-0.005603,-0.142312,0.110975,0.005653,-1.423117,-47.016365,-0.141011,0.000000
2.630000,0.040215,-47.060844,-0.005532,-0.005368,-0.136354,0.178883,0.009113,-1.363539,-47.060844,-0.135010,0.000000
2.990000,0.020477,-47.149807,-0.005299,-0.005131,-0.130335,0.091088,0.004640,-1.303353,-47.149807,-0.129008,0.000000
3.350000,-0.001122,-47.105328,-0.005057,-0.004898,-0.124421,-0.004989,-0.000254,-1.244209,-47.105328,-0.123007,0.000000
3.710000,0.089371,-47.238770,-0.004799,0.000006,0.000147,0.397541,0.020252,0.001474,-47.238770,0.001275,0.000000
4.070000,0.072609,-47.194290,-0.004777,0.000002,0.000043,0.322981,0.016453,0.000434,-47.194290,0.000269,0.000000
4.430000,0.113571,-47.238770,-0.004781,0.000002,0.000043,0.505190,0.025736,0.000434,-47.238770,0.000590,0.000000
4.790000,0.113945,-47.283253,-0.004794,0.000002,0.000052,0.506853,0.025820,0.000520,-47.283253,0.001188,0.000000
5.150000,0.252464,-47.327732,-0.004764,0.000028,0.000711,1.123017,0.057209,0.007111,-47.327732,0.001795,0.000000
5.510000,0.520950,-47.327732,-0.004730,0.000057,0.001448,2.317303,0.118049,0.014483,-47.327732,0.002394,0.000000
5.870000,0.706390,-47.327732,-0.004721,0.000071,0.001804,3.142181,0.160070,0.018038,-47.327732,0.002992,0.000000
6.230000,1.045250,-47.416695,-0.004704,0.000101,0.002567,4.649504,0.236857,0.025670,-47.416695,0.003590,0.000000
6.590000,1.391182,-47.461174,-0.004682,0.000124,0.003148,6.188286,0.315246,0.031480,-47.461174,0.004189,0.000000
6.950000,1.886436,-47.461174,-0.004665,0.000148,0.003764,8.391289,0.427473,0.037638,-47.461174,0.004796,0.000000
7.310000,2.378342,-47.550137,-0.004644,0.000170,0.004327,10.579392,0.538940,0.043275,-47.550137,0.005394,0.000000
7.670001,2.866524,-47.505657,-0.004613,0.000197,0.005004,12.750935,0.649564,0.050039,-47.505657,0.005993,0.000000
8.030001,3.382629,-47.594616,-0.004592,0.000224,0.005680,15.046687,0.766515,0.056803,-47.594616,0.006591,0.000000
8.390000,3.966881,-47.639099,-0.004579,0.000248,0.006305,17.645567,0.898908,0.063047,-47.639099,0.007189,0.000000
8.750000,4.243179,-47.639099,-0.004553,0.000266,0.006747,18.874605,0.961518,0.067470,-47.639099,0.007788,0.000000
9.110001,4.875847,-47.639099,-0.004549,0.000289,0.007337,21.688850,1.104883,0.073367,-47.639099,0.008395,0.000000
9.470000,5.440735,-47.683578,-0.004536,0.000312,0.007926,24.201597,1.232888,0.079264,-47.683578,0.008993,0.000000
9.830001,6.098343,-47.728062,-0.004501,0.000338,0.008586,27.126783,1.381904,0.085855,-47.728062,0.009592,0.000000
10.190001,6.501991,-47.772541,-0.004488,0.000361,0.009158,28.922302,1.473372,0.091579,-47.772541,0.010190,0.000000
10.550000,7.049385,-47.817024,-0.004462,0.000385,0.009774,31.357231,1.597414,0.097736,-47.817024,0.010788,0.000000
10.910001,7.639961,-47.861504,-0.004441,0.000410,0.010424,33.984245,1.731240,0.104241,-47.861504,0.011395,0.000000
11.270000,8.034676,-47.861504,-0.004432,0.000427,0.010858,35.740021,1.820684,0.108577,-47.861504,0.011994,0.000000
11.630000,8.831184,-47.950466,-0.004393,0.000460,0.011682,39.283070,2.001175,0.116815,-47.950466,0.012592,0.000000
11.990001,8.849800,-47.905983,-0.004393,0.000477,0.012106,39.365875,2.005394,0.121065,-47.905983,0.013191,0.000000
12.350000,9.470917,-47.905983,-0.004363,0.000495,0.012583,42.128742,2.146140,0.125834,-47.905983,0.013789,0.000000
12.710001,9.537575,-48.039429,-0.004346,0.000508,0.012896,42.425251,2.161245,0.128956,-48.039429,0.014396,0.000000
13.070001,10.949982,-47.994946,-0.004324,0.000549,0.013945,48.707951,2.481301,0.139450,-47.994946,0.014994,0.000000
13.430000,10.888916,-48.128387,-0.004299,0.000567,0.014413,48.436317,2.467464,0.144133,-48.128387,0.015593,0.000000
13.790001,11.425499,-48.083908,-0.004281,0.000590,0.014986,50.823158,2.589055,0.149857,-48.083908,0.016191,0.000000
14.150001,12.200035,-48.128387,-0.004260,0.000622,0.015792,54.268467,2.764568,0.157922,-48.128387,0.016789,0.000000
14.510000,12.569801,-48.172871,-0.004243,0.000642,0.016313,55.913269,2.848358,0.163125,-48.172871,0.017397,0.000000
14.870001,13.070641,-48.217350,-0.004212,0.000666,0.016928,58.141113,2.961849,0.169282,-48.217350,0.017995,0.000000
15.230000,13.531639,-48.261833,-0.004199,0.000689,0.017501,60.191738,3.066313,0.175006,-48.261833,0.018593,0.000000
15.590001,13.905128,-48.261833,-0.004169,0.000714,0.018134,61.853100,3.150947,0.181337,-48.261833,0.019192,0.000000
15.950001,14.316605,-48.306313,-0.004156,0.000733,0.018628,63.683437,3.244189,0.186280,-48.306313,0.019790,0.000000
16.310001,14.668869,-48.439754,-0.004135,0.000759,0.019278,65.250389,3.324013,0.192784,-48.439754,0.020397,0.000000
16.670000,15.349564,-48.395275,-0.004105,0.000782,0.019868,68.278267,3.478261,0.198681,-48.395275,0.020996,0.000000
17.030001,15.638527,-48.439754,-0.004087,0.000806,0.020467,69.563644,3.543741,0.204665,-48.439754,0.021594,0.000000
17.390001,15.952438,-48.395275,-0.004070,0.000827,0.021013,70.959991,3.614874,0.210129,-48.395275,0.022192,0.000000
17.750000,16.442848,-48.439754,-0.004057,0.000850,0.021594,73.141441,3.726003,0.215939,-48.439754,0.022791,0.000000
18.110001,16.769417,-48.573200,-0.004044,0.000878,0.022314,74.594093,3.800004,0.223137,-48.573200,0.023389,0.000000
18.470001,16.948906,-48.573200,-0.004005,0.000893,0.022687,75.392502,3.840677,0.226866,-48.573200,0.023996,0.000000
18.830002,17.990433,-48.617680,-0.003975,0.000928,0.023571,80.025444,4.076690,0.235712,-48.617680,0.024595,0.000000
19.190001,17.979256,-48.573200,-0.003954,0.000947,0.024057,79.975723,4.074157,0.240568,-48.573200,0.025193,0.000000
19.550001,18.359825,-48.617680,-0.003928,0.000970,0.024638,81.668579,4.160396,0.246379,-48.617680,0.025791,0.000000
19.910002,18.532600,-48.795605,-0.003919,0.000990,0.025158,82.437126,4.199547,0.251582,-48.795605,0.026390,0.000000
20.270000,18.644684,-48.706642,-0.003893,0.001011,0.025670,82.935699,4.224946,0.256699,-48.706642,0.026997,0.000000
20.630001,19.069191,-48.706642,-0.003872,0.001032,0.026225,84.823997,4.321141,0.262249,-48.706642,0.027595,0.000000
20.990002,20.172531,-48.795605,-0.003867,0.001068,0.027118,89.731903,4.571161,0.271181,-48.795605,0.028194,0.000000
21.350000,20.361328,-48.840084,-0.003829,0.001092,0.027734,90.571709,4.613943,0.277339,-48.840084,0.028792,0.000000
21.710001,20.688271,-48.929047,-0.003811,0.001116,0.028358,92.026024,4.688029,0.283583,-48.929047,0.029390,0.000000
22.070002,20.558685,-48.840084,-0.003786,0.001133,0.028783,91.449600,4.658665,0.287832,-48.840084,0.029997,0.000000
22.430000,20.979462,-48.929047,-0.003773,0.001156,0.029373,93.321304,4.754014,0.293729,-48.929047,0.030596,0.000000
22.790001,21.714897,-48.973526,-0.003738,0.001185,0.030110,96.592690,4.920666,0.301101,-48.973526,0.031194,0.000000
23.150002,22.037376,-48.973526,-0.003695,0.001213,0.030821,98.027145,4.993741,0.308212,-48.973526,0.031792,0.000000
23.510000,22.263405,-49.018009,-0.003686,0.001237,0.031411,99.032570,5.044960,0.314109,-49.018009,0.032391,0.000000
23.870001,22.271225,-49.018009,-0.003669,0.001256,0.031905,99.067360,5.046731,0.319052,-49.018009,0.032998,0.000000
24.230001,22.066788,-49.106972,-0.003648,0.001276,0.032408,98.157974,5.000406,0.324082,-49.106972,0.033596,0.000000
24.590002,23.180183,-49.106972,-0.003622,0.001305,0.033145,103.110603,5.252705,0.331454,-49.106972,0.034195,0.000000
24.950001,23.271042,-49.151451,-0.003591,0.001327,0.033709,103.514763,5.273293,0.337091,-49.151451,0.034793,0.000000
25.310001,23.725334,-49.240414,-0.003566,0.001355,0.034429,105.535561,5.376238,0.344289,-49.240414,0.035391,0.000000
25.670002,23.730553,-49.195930,-0.003548,0.001373,0.034880,105.558769,5.377420,0.348798,-49.195930,0.035990,0.000000
26.030001,24.111862,-49.284893,-0.003540,0.001401,0.035591,107.254921,5.463826,0.355909,-49.284893,0.036597,0.000000
26.390001,24.235115,-49.284893,-0.003518,0.001420,0.036068,107.803177,5.491755,0.360679,-49.284893,0.037195,0.000000
26.750002,24.976509,-49.329376,-0.003479,0.001449,0.036805,111.101059,5.659758,0.368051,-49.329376,0.037794,0.000000
27.110001,25.020447,-49.418335,-0.003471,0.001470,0.037343,111.296509,5.669714,0.373427,-49.418335,0.038392,0.000000
27.470001,25.189133,-49.329376,-0.003428,0.001489,0.037828,112.046860,5.707939,0.378284,-49.329376,0.038990,0.000000
27.830002,25.506020,-49.418335,-0.003419,0.001517,0.038531,113.456444,5.779747,0.385308,-49.418335,0.039598,0.000000
28.190001,26.061234,-49.418335,-0.003397,0.001542,0.039164,115.926155,5.905560,0.391639,-49.418335,0.040196,0.000000
28.550001,26.317421,-49.507298,-0.003367,0.001564,0.039736,117.065735,5.963613,0.397363,-49.507298,0.040794,0.000000
28.910002,26.541222,-49.507298,-0.003341,0.001589,0.040352,118.061249,6.014327,0.403520,-49.507298,0.041393,0.000000
29.270000,27.081528,-49.551781,-0.003320,0.001616,0.041037,120.464653,6.136762,0.410371,-49.551781,0.041991,0.000000
29.630001,27.306068,-49.596260,-0.003298,0.001642,0.041705,121.463455,6.187644,0.417049,-49.596260,0.042598,0.000000
29.990002,27.297134,-49.596260,-0.003264,0.001661,0.042191,121.423721,6.185619,0.421905,-49.596260,0.043197,0.000000
30.350002,27.595406,-49.685223,-0.003251,0.001686,0.042815,122.750496,6.253208,0.428149,-49.685223,0.043795,0.000000
30.710001,27.886597,-49.729702,-0.003234,0.001707,0.043361,124.045776,6.319193,0.433613,-49.729702,0.044393,0.000000
31.070002,27.864258,-49.685223,-0.003208,0.001727,0.043873,123.946411,6.314131,0.438729,-49.685223,0.044992,0.000000
31.430002,28.626877,-49.818665,-0.003182,0.001754,0.044541,127.338707,6.486943,0.445407,-49.818665,0.045599,0.000000
31.790001,29.142609,-49.818665,-0.003160,0.001779,0.045191,129.632797,6.603809,0.451911,-49.818665,0.046197,0.000000
32.150002,29.469559,-49.863148,-0.003134,0.001805,0.045859,131.087143,6.677897,0.458589,-49.863148,0.046795,0.000000
32.510002,29.566002,-49.863148,-0.003113,0.001825,0.046362,131.516144,6.699752,0.463619,-49.863148,0.047394,0.000000
32.870003,29.985291,-49.863148,-0.003104,0.001850,0.046995,133.381241,6.794764,0.469950,-49.863148,0.047992,0.000000
33.230003,30.098495,-49.952106,-0.003074,0.001868,0.047437,133.884796,6.820416,0.474372,-49.952106,0.048591,0.000000
33.590000,30.681999,-49.996590,-0.003048,0.001894,0.048105,136.480347,6.952641,0.481050,-49.996590,0.049198,0.000000
33.950001,30.324524,-49.996590,-0.003031,0.001906,0.048409,134.890213,6.871635,0.484085,-49.996590,0.049796,0.000000
34.310001,31.077835,-50.041069,-0.003009,0.001934,0.049111,138.241119,7.042338,0.491110,-50.041069,0.050394,0.000000
34.670002,31.960358,-49.996590,-0.002988,0.001963,0.049865,142.166779,7.242321,0.498655,-49.996590,0.050993,0.000000
35.030003,32.165535,-50.085552,-0.002958,0.001988,0.050499,143.079453,7.288815,0.504986,-50.085552,0.051591,0.000000
35.390003,32.149521,-50.130032,-0.002940,0.002003,0.050889,143.008209,7.285185,0.508888,-50.130032,0.052198,0.000000
35.750000,33.005234,-50.130032,-0.002906,0.002035,0.051695,146.814606,7.479093,0.516953,-50.130032,0.052797,0.000000
36.110001,33.665077,-50.174511,-0.002897,0.002063,0.052389,149.749741,7.628615,0.523891,-50.174511,0.053395,0.000000
36.470001,33.789078,-50.174511,-0.002880,0.002081,0.052857,150.301331,7.656714,0.528574,-50.174511,0.053993,0.000000
36.830002,34.234062,-50.307957,-0.002854,0.002105,0.053473,152.280716,7.757549,0.534731,-50.307957,0.054592,0.000000
37.190002,34.506264,-50.263474,-0.002811,0.002126,0.053993,153.491531,7.819232,0.539935,-50.263474,0.055199,0.000000
37.550003,35.148605,-50.307957,-0.002794,0.002155,0.054748,156.348801,7.964788,0.547480,-50.307957,0.055797,0.000000
37.910004,35.619659,-50.352436,-0.002794,0.002180,0.055372,158.444153,8.071530,0.553724,-50.352436,0.056396,0.000000
38.270000,36.094803,-50.396919,-0.002746,0.002201,0.055910,160.557709,8.179199,0.559100,-50.396919,0.056994,0.000000
38.630001,36.311157,-50.441399,-0.002734,0.002221,0.056404,161.520096,8.228226,0.564044,-50.441399,0.057592,0.000000
38.990002,37.013077,-50.441399,-0.002708,0.002245,0.057029,164.642395,8.387283,0.570288,-50.441399,0.058200,0.000000
39.350002,37.720955,-50.485878,-0.002677,0.002270,0.057671,167.791183,8.547690,0.576705,-50.485878,0.058798,0.000000
39.710003,37.785378,-50.485878,-0.002660,0.002290,0.058165,168.077759,8.562289,0.581648,-50.485878,0.059396,0.000000
40.070004,38.393463,-50.530361,-0.002639,0.002317,0.058841,170.782654,8.700083,0.588413,-50.530361,0.059995,0.000000
40.430000,39.027611,-50.619324,-0.002617,0.002338,0.059396,173.603485,8.843782,0.593963,-50.619324,0.060593,0.000000
40.790001,39.628990,-50.574841,-0.002596,0.002368,0.060142,176.278549,8.980058,0.601421,-50.574841,0.061191,0.000000
41.150002,40.262772,-50.708282,-0.002561,0.002389,0.060671,179.097748,9.123674,0.606711,-50.708282,0.061799,0.000000
41.510002,40.299637,-50.663803,-0.002561,0.002407,0.061148,179.261734,9.132029,0.611481,-50.663803,0.062397,0.000000
41.870003,40.863411,-50.663803,-0.002535,0.002431,0.061755,181.769531,9.259781,0.617551,-50.663803,0.062995,0.000000
42.230003,42.005844,-50.752766,-0.002496,0.002461,0.062518,186.851334,9.518661,0.625183,-50.752766,0.063594,0.000000
42.590000,42.713356,-50.752766,-0.002471,0.002486,0.063151,189.998489,9.678985,0.631514,-50.752766,0.064192,0.000000
42.950001,43.646523,-50.841728,-0.002458,0.002511,0.063776,194.149429,9.890444,0.637758,-50.841728,0.064799,0.000000
43.310001,43.400383,-50.886208,-0.002449,0.002526,0.064157,193.054550,9.834667,0.641574,-50.886208,0.065397,0.000000
43.670002,43.927292,-50.797245,-0.002414,0.002555,0.064886,195.398346,9.954066,0.648858,-50.797245,0.065996,0.000000
44.030003,45.024300,-50.930691,-0.002406,0.002581,0.065545,200.278091,10.202652,0.655449,-50.930691,0.066594,0.000000
44.390003,45.674835,-50.886208,-0.002371,0.002602,0.066083,203.171814,10.350065,0.660826,-50.886208,0.067193,0.000000
44.750004,46.711517,-50.975170,-0.002354,0.002632,0.066846,207.783203,10.584981,0.668458,-50.975170,0.067800,0.000000
45.110001,46.535759,-51.019650,-0.002328,0.002646,0.067210,207.001389,10.545154,0.672100,-51.019650,0.068398,0.000000
45.470001,46.944252,-51.019650,-0.002302,0.002671,0.067843,208.818466,10.637720,0.678431,-51.019650,0.068996,0.000000
45.830002,48.071793,-51.064133,-0.002285,0.002697,0.068493,213.834015,10.893224,0.684935,-51.064133,0.069595,0.000000
46.190002,48.952454,-51.108612,-0.002255,0.002722,0.069135,217.751389,11.092784,0.691352,-51.108612,0.070193,0.000000
46.550003,49.283867,-51.197575,-0.002238,0.002742,0.069638,219.225586,11.167884,0.696382,-51.197575,0.070800,0.000000
46.910004,50.498543,-51.153095,-0.002212,0.002772,0.070401,224.628738,11.443134,0.704014,-51.153095,0.071399,0.000000
47.270000,51.023964,-51.197575,-0.002186,0.002795,0.070982,226.965927,11.562196,0.709824,-51.197575,0.071997,0.000000
47.630001,51.527412,-51.242054,-0.002164,0.002817,0.071563,229.205383,11.676278,0.715635,-51.242054,0.072595,0.000000
47.990002,52.140709,-51.242054,-0.002134,0.002841,0.072171,231.933456,11.815253,0.721705,-51.242054,0.073194,0.000000
48.350002,52.843750,-51.286537,-0.002108,0.002861,0.072674,235.060745,11.974565,0.726735,-51.286537,0.073792,0.000000
48.710003,53.339745,-51.331017,-0.002117,0.002886,0.073315,237.267029,12.086959,0.733153,-51.331017,0.074399,0.000000
49.070004,54.152634,-51.375500,-0.002087,0.002906,0.073818,240.882950,12.271162,0.738182,-51.375500,0.074998,0.000000
49.430004,54.887329,-51.419979,-0.002052,0.002930,0.074434,244.151031,12.437647,0.744340,-51.419979,0.075596,0.000000
49.790001,54.988983,-51.419979,-0.002035,0.002945,0.074816,244.603210,12.460681,0.748156,-51.419979,0.076194,0.000000
50.150002,56.647903,-51.464462,-0.002013,0.002977,0.075613,251.982452,12.836598,0.756134,-51.464462,0.076793,0.000000
50.510002,57.924026,-51.508942,-0.001992,0.003008,0.076403,257.658936,13.125772,0.764026,-51.508942,0.077400,0.000000
50.870003,58.904854,-51.553421,-0.001975,0.003032,0.077018,262.021881,13.348031,0.770183,-51.553421,0.077998,0.000000
51.230003,59.238129,-51.508942,-0.001970,0.003053,0.077539,263.504364,13.423553,0.775386,-51.508942,0.078597,0.000000
51.590004,59.935951,-51.597904,-0.001936,0.003078,0.078180,266.608429,13.581681,0.781804,-51.597904,0.079195,0.000000
51.950001,59.951591,-51.597904,-0.001914,0.003096,0.078631,266.678009,13.585225,0.786314,-51.597904,0.079793,0.000000
52.310001,61.241859,-51.597904,-0.001893,0.003119,0.079230,272.417389,13.877604,0.792297,-51.597904,0.080400,0.000000
52.670002,61.944901,-51.642384,-0.001867,0.003144,0.079845,275.544678,14.036915,0.798455,-51.642384,0.080999,0.000000
53.030003,63.262726,-51.731346,-0.001850,0.003172,0.080557,281.406647,14.335539,0.805566,-51.731346,0.081597,0.000000
53.390003,64.064453,-51.775826,-0.001828,0.003194,0.081120,284.972931,14.517212,0.811203,-51.775826,0.082196,0.000000
53.750004,64.561569,-51.775826,-0.001819,0.003214,0.081623,287.184204,14.629861,0.816233,-51.775826,0.082794,0.000000
54.110004,65.530472,-51.820309,-0.001789,0.003240,0.082300,291.494110,14.849417,0.822997,-51.820309,0.083401,0.000000
54.470001,65.253433,-51.864788,-0.001755,0.003247,0.082464,290.261780,14.786639,0.824645,-51.864788,0.014475,0.000000
54.830002,66.347458,-51.864788,-0.001738,0.003174,0.080609,295.128235,15.034550,0.806086,-51.864788,294.500458,0.000000
55.190002,65.105225,-51.864788,-0.001716,0.003276,0.083219,289.602509,14.753055,0.832190,-51.864788,294.500458,0.000000
55.550003,65.076187,-51.953751,-0.001729,0.003289,0.083549,289.473328,14.746475,0.835485,-51.953751,294.500458,0.000000
55.910004,65.834335,-51.953751,-0.001690,0.003296,0.083722,292.845764,14.918274,0.837220,-51.953751,294.500458,0.000000
56.270004,66.092392,-52.042713,-0.001681,0.003323,0.084407,293.993652,14.976750,0.844071,-52.042713,294.500458,0.000000
56.630001,64.522842,-52.042713,-0.001681,0.003321,0.084346,287.011932,14.621084,0.843464,-52.042713,294.500458,0.000000
56.990002,65.830231,-52.042713,-0.001647,0.003264,0.082915,292.827484,14.917343,0.829154,-52.042713,294.500458,0.000000
57.350002,65.238541,-52.131676,-0.001634,0.003355,0.085214,290.195526,14.783265,0.852136,-52.131676,294.500458,0.000000
57.710003,65.026291,-52.131676,-0.001625,0.003367,0.085517,289.251373,14.735168,0.855171,-52.131676,294.500458,0.000000
58.070004,65.531601,-52.131676,-0.001600,0.003383,0.085933,291.499115,14.849672,0.859334,-52.131676,294.500458,0.000000
58.430004,64.452835,-52.176155,-0.001595,0.003384,0.085942,286.700531,14.605221,0.859421,-52.176155,294.500458,0.000000
58.790001,65.997437,-52.176155,-0.001569,0.003325,0.084450,293.571259,14.955233,0.844504,-52.176155,294.500458,0.000000
59.150002,64.939148,-52.309597,-0.001574,0.003401,0.086384,288.863770,14.715422,0.863844,-52.309597,294.500458,0.000000
59.510002,65.251938,-52.309597,-0.001569,0.003422,0.086931,290.255127,14.786300,0.869307,-52.309597,294.500458,0.000000
59.870003,65.509628,-52.265118,-0.001535,0.003434,0.087226,291.401367,14.844694,0.872256,-52.265118,294.500458,0.000000
60.230003,65.229599,-52.398560,-0.001548,0.003444,0.087486,290.155762,14.781239,0.874857,-52.398560,294.500458,0.000000
60.590004,64.917557,-52.398560,-0.001518,0.003453,0.087694,288.767700,14.710528,0.876939,-52.398560,294.500458,0.000000
60.950005,64.998734,-52.443043,-0.001531,0.003459,0.087859,289.128815,14.728924,0.878586,-52.443043,294.500458,0.000000
61.310001,65.053467,-52.443043,-0.001518,0.003469,0.088101,289.372284,14.741326,0.881015,-52.443043,294.500458,0.000000
61.670002,65.296249,-52.532001,-0.001492,0.003480,0.088388,290.452209,14.796342,0.883876,-52.532001,294.500458,0.000000
62.030003,65.150650,-52.532001,-0.001479,0.003488,0.088596,289.804565,14.763348,0.885958,-52.532001,294.500458,0.000000
62.390003,65.209488,-52.576485,-0.001483,0.003499,0.088882,290.066284,14.776682,0.888820,-52.576485,294.500458,0.000000
62.750004,65.022934,-52.576485,-0.001466,0.003509,0.089133,289.236450,14.734407,0.891335,-52.576485,294.500458,0.000000
63.110004,65.143951,-52.665447,-0.001453,0.003511,0.089168,289.774780,14.761830,0.891681,-52.665447,294.500458,0.000000
63.470001,65.509995,-52.754410,-0.001462,0.003522,0.089463,291.403015,14.844777,0.894630,-52.754410,294.500458,0.000000
63.830002,64.800629,-52.709927,-0.001449,0.003522,0.089463,288.247589,14.684032,0.894630,-52.709927,294.500458,0.000000
64.190002,65.981049,-52.754410,-0.001423,0.003529,0.089636,293.498352,14.951519,0.896365,-52.754410,294.500458,0.000000
64.550003,65.158844,-52.754410,-0.001431,0.003530,0.089654,289.841003,14.765205,0.896538,-52.754410,294.500458,0.000000
64.910004,65.447433,-52.754410,-0.001418,0.003549,0.090139,291.124725,14.830600,0.901394,-52.754410,294.500458,0.000000
65.270004,65.192734,-52.887852,-0.001418,0.003557,0.090348,289.991760,14.772885,0.903476,-52.887852,294.500458,0.000000
65.630005,65.317474,-52.932331,-0.001401,0.003564,0.090530,290.546631,14.801151,0.905297,-52.932331,294.500458,0.000000
65.990005,64.760788,-52.887852,-0.001397,0.003564,0.090521,288.070374,14.675004,0.905210,-52.887852,294.500458,0.000000
66.350006,65.778854,-52.932331,-0.001397,0.003573,0.090764,292.598969,14.905701,0.907638,-52.932331,294.500458,0.000000
66.710007,65.042664,-53.021294,-0.001384,0.003573,0.090764,289.324219,14.738878,0.907638,-53.021294,294.500458,0.000000
67.070000,66.576477,-53.021294,-0.001371,0.003578,0.090885,296.146973,15.086445,0.908853,-53.021294,294.500458,0.000000
67.430000,65.781082,-52.976814,-0.001358,0.003570,0.090677,292.608856,14.906206,0.906771,-52.976814,294.500458,0.000000
67.790001,65.073578,-53.110256,-0.001362,0.003574,0.090773,289.461731,14.745884,0.907725,-53.110256,294.500458,0.000000
68.150002,65.044907,-53.065773,-0.001384,0.003600,0.091449,289.334198,14.739387,0.914490,-53.065773,294.500458,0.000000
68.510002,65.187897,-53.110256,-0.001358,0.003609,0.091666,289.970245,14.771788,0.916658,-53.110256,294.500458,0.000000
68.870003,65.380417,-53.199219,-0.001345,0.003618,0.091891,290.826630,14.815414,0.918912,-53.199219,294.500458,0.000000
69.230003,65.118256,-53.199219,-0.001354,0.003618,0.091891,289.660461,14.756007,0.918912,-53.199219,294.500458,0.000000
69.590004,65.119003,-53.243698,-0.001345,0.003624,0.092047,289.663788,14.756177,0.920473,-53.243698,294.500458,0.000000
69.950005,65.148056,-53.243698,-0.001350,0.003630,0.092203,289.793030,14.762760,0.922034,-53.243698,294.500458,0.000000
70.310005,64.842331,-53.288177,-0.001345,0.003632,0.092247,288.433105,14.693482,0.922468,-53.288177,294.500458,0.000000
70.670006,65.847733,-53.377140,-0.001324,0.003645,0.092576,292.905334,14.921309,0.925763,-53.377140,294.500458,0.000000
71.030006,65.447067,-53.332661,-0.001311,0.003645,0.092576,291.123108,14.830518,0.925763,-53.332661,294.500458,0.000000
71.390007,65.022186,-53.421623,-0.001328,0.003646,0.092602,289.233124,14.734238,0.926024,-53.421623,294.500458,0.000000
71.750000,64.723541,-53.421623,-0.001315,0.003647,0.092637,287.904694,14.666564,0.926371,-53.421623,294.500458,0.000000
72.110001,65.609787,-53.466103,-0.001306,0.003660,0.092958,291.846893,14.867391,0.929579,-53.466103,294.500458,0.000000
72.470001,65.247849,-53.466103,-0.001311,0.003660,0.092958,290.236938,14.785374,0.929579,-53.466103,294.500458,0.000000
72.830002,64.868027,-53.555065,-0.001293,0.003660,0.092967,288.547394,14.699306,0.929666,-53.555065,294.500458,0.000000
73.190002,65.718155,-53.555065,-0.001302,0.003669,0.093192,292.328949,14.891947,0.931921,-53.555065,294.500458,0.000000
73.550003,65.250458,-53.555065,-0.001298,0.003669,0.093201,290.248535,14.785965,0.932007,-53.555065,294.500458,0.000000
73.910004,64.815887,-53.644028,-0.001293,0.003669,0.093201,288.315460,14.687490,0.932007,-53.644028,294.500458,0.000000
74.270004,66.195160,-53.688507,-0.001285,0.003682,0.093513,294.450775,15.000037,0.935129,-53.688507,294.500458,0.000000
74.630005,65.766190,-53.688507,-0.001268,0.003679,0.093452,292.542633,14.902831,0.934522,-53.688507,294.500458,0.000000
74.990005,65.329391,-53.732990,-0.001281,0.003679,0.093452,290.599640,14.803851,0.934522,-53.732990,294.500458,0.000000
75.350006,64.974518,-53.777470,-0.001281,0.003679,0.093452,289.021088,14.723435,0.934522,-53.777470,294.500458,0.000000
75.710007,65.362915,-53.777470,-0.001285,0.003694,0.093834,290.748779,14.811448,0.938338,-53.777470,294.500458,0.000000
76.070007,65.099274,-53.866432,-0.001272,0.003694,0.093834,289.576019,14.751707,0.938338,-53.866432,294.500458,0.000000
76.430000,64.793930,-53.866432,-0.001263,0.003694,0.093834,288.217804,14.682514,0.938338,-53.866432,294.500458,0.000000
76.790001,65.823914,-53.910912,-0.001259,0.003708,0.094172,292.799377,14.915913,0.941720,-53.910912,294.500458,0.000000
77.150002,65.537918,-53.866432,-0.001255,0.003708,0.094172,291.527222,14.851105,0.941720,-53.866432,294.500458,0.000000
77.510002,65.258652,-53.955395,-0.001259,0.003708,0.094172,290.284973,14.787822,0.941720,-53.955395,294.500458,0.000000
77.870003,64.964096,-53.999874,-0.001246,0.003708,0.094172,288.974731,14.721074,0.941720,-53.999874,294.500458,0.000000
78.230003,64.706421,-53.999874,-0.001250,0.003708,0.094181,287.828522,14.662684,0.941807,-53.999874,294.500458,0.000000
78.590004,66.546677,-54.088837,-0.001242,0.003690,0.093730,296.014404,15.079693,0.937298,-54.088837,294.500458,0.000000
78.950005,66.180267,-54.133316,-0.001233,0.003690,0.093721,294.384521,14.996663,0.937211,-54.133316,294.500458,0.000000
79.310005,65.870087,-54.133316,-0.001237,0.003690,0.093721,293.004791,14.926375,0.937211,-54.133316,294.500458,0.000000
79.670006,65.586334,-54.088837,-0.001229,0.003690,0.093730,291.742584,14.862076,0.937298,-54.088837,294.500458,0.000000
80.030006,65.273544,-54.222279,-0.001216,0.003690,0.093730,290.351227,14.791197,0.937298,-54.222279,294.500458,0.000000
80.390007,65.194229,-54.266762,-0.001220,0.003724,0.094580,289.998413,14.773223,0.945796,-54.266762,294.500458,0.000000
80.750008,65.063156,-54.177799,-0.001220,0.003726,0.094632,289.415375,14.743522,0.946317,-54.177799,294.500458,0.000000
81.110001,65.333496,-54.266762,-0.001220,0.003732,0.094796,290.617920,14.804782,0.947964,-54.266762,294.500458,0.000000
81.470001,65.158478,-54.266762,-0.001229,0.003734,0.094831,289.839386,14.765121,0.948311,-54.266762,294.500458,0.000000
81.830002,65.191620,-54.355721,-0.001216,0.003736,0.094883,289.986816,14.772633,0.948832,-54.355721,294.500458,0.000000
82.190002,65.092560,-54.444683,-0.001220,0.003737,0.094927,289.546173,14.750185,0.949265,-54.444683,294.500458,0.000000
82.550003,65.262375,-54.400204,-0.001229,0.003742,0.095048,290.301544,14.788666,0.950479,-54.400204,294.500458,0.000000
82.910004,65.129059,-54.444683,-0.001224,0.003742,0.095048,289.708527,14.758455,0.950479,-54.444683,294.500458,0.000000
83.270004,64.962616,-54.444683,-0.001212,0.003744,0.095091,288.968140,14.720739,0.950913,-54.444683,294.500458,0.000000
83.630005,65.102997,-54.489166,-0.001220,0.003747,0.095178,289.592590,14.752550,0.951780,-54.489166,294.500458,0.000000
83.990005,65.016968,-54.533646,-0.001220,0.003748,0.095195,289.209930,14.733055,0.951954,-54.533646,294.500458,0.000000
84.350006,64.978622,-54.533646,-0.001229,0.003749,0.095230,289.039337,14.724366,0.952301,-54.533646,294.500458,0.000000
84.710007,65.654099,-54.622608,-0.001203,0.003759,0.095473,292.044006,14.877431,0.954729,-54.622608,294.500458,0.000000
85.070007,65.563995,-54.622608,-0.001207,0.003759,0.095473,291.643219,14.857014,0.954729,-54.622608,294.500458,0.000000
85.430000,65.397537,-54.711571,-0.001212,0.003759,0.095473,290.902771,14.819294,0.954729,-54.711571,294.500458,0.000000
85.790001,65.266098,-54.711571,-0.001216,0.003759,0.095482,290.318115,14.789509,0.954816,-54.711571,294.500458,0.000000
86.150002,65.086609,-54.711571,-0.001194,0.003759,0.095482,289.519684,14.748837,0.954816,-54.711571,294.500458,0.000000
86.510002,65.081024,-54.756050,-0.001203,0.003762,0.095542,289.494843,14.747571,0.955423,-54.756050,294.500458,0.000000
86.870003,65.293640,-54.756050,-0.001199,0.003766,0.095655,290.440613,14.795751,0.956550,-54.756050,294.500458,0.000000
87.230003,65.203903,-54.845013,-0.001190,0.003766,0.095655,290.041443,14.775416,0.956550,-54.845013,294.500458,0.000000
87.590004,65.041931,-54.800533,-0.001190,0.003766,0.095655,289.320953,14.738712,0.956550,-54.800533,294.500458,0.000000
87.950005,64.922012,-54.933975,-0.001190,0.003766,0.095655,288.787537,14.711538,0.956550,-54.933975,294.500458,0.000000
88.310005,64.773819,-54.933975,-0.001194,0.003766,0.095664,288.128326,14.677958,0.956637,-54.933975,294.500458,0.000000
88.670006,64.636414,-54.978455,-0.001203,0.003766,0.095664,287.517120,14.646821,0.956637,-54.978455,294.500458,0.000000
89.030006,66.404434,-55.022938,-0.001181,0.003753,0.095317,295.381683,15.047460,0.953168,-55.022938,294.500458,0.000000
89.390007,66.237991,-54.978455,-0.001173,0.003753,0.095317,294.641296,15.009744,0.953168,-54.978455,294.500458,0.000000
89.750008,66.058502,-55.067417,-0.001173,0.003753,0.095317,293.842896,14.969070,0.953168,-55.067417,294.500458,0.000000
90.110001,65.886459,-55.067417,-0.001190,0.003753,0.095325,293.077606,14.930085,0.953254,-55.067417,294.500458,0.000000
90.470001,65.690964,-55.156380,-0.001173,0.003753,0.095325,292.208008,14.885785,0.953254,-55.156380,294.500458,0.000000
90.830002,65.540161,-55.200859,-0.001177,0.003753,0.095325,291.537201,14.851613,0.953254,-55.200859,294.500458,0.000000
91.190002,65.390091,-55.156380,-0.001173,0.003754,0.095351,290.869659,14.817606,0.953515,-55.156380,294.500458,0.000000
91.550003,65.299606,-55.200859,-0.001168,0.003767,0.095681,290.467163,14.797102,0.956810,-55.200859,294.500458,0.000000
91.910004,65.191986,-55.200859,-0.001173,0.003776,0.095898,289.988434,14.772716,0.958978,-55.200859,294.500458,0.000000
92.270004,65.350998,-55.334305,-0.001164,0.003785,0.096149,290.695770,14.808748,0.961493,-55.334305,294.500458,0.000000
92.630005,65.282104,-55.378784,-0.001177,0.003785,0.096149,290.389313,14.793136,0.961493,-55.378784,294.500458,0.000000
92.990005,65.182312,-55.334305,-0.001173,0.003785,0.096149,289.945404,14.770522,0.961493,-55.334305,294.500458,0.000000
93.350006,65.060165,-55.467747,-0.001177,0.003787,0.096193,289.402069,14.742845,0.961927,-55.467747,294.500458,0.000000
93.710007,64.993881,-55.423264,-0.001173,0.003787,0.096201,289.107208,14.727824,0.962013,-55.423264,294.500458,0.000000
94.070007,64.894836,-55.423264,-0.001164,0.003787,0.096201,288.666656,14.705380,0.962013,-55.423264,294.500458,0.000000
94.430008,65.769165,-55.556709,-0.001168,0.003798,0.096470,292.555847,14.903506,0.964702,-55.556709,294.500458,0.000000
94.790001,65.626541,-55.512226,-0.001168,0.003798,0.096470,291.921448,14.871187,0.964702,-55.512226,294.500458,0.000000
95.150002,65.563248,-55.601189,-0.001160,0.003798,0.096470,291.639893,14.856845,0.964702,-55.601189,294.500458,0.000000
95.510002,65.460464,-55.601189,-0.001164,0.003798,0.096470,291.182678,14.833553,0.964702,-55.601189,294.500458,0.000000
95.870003,65.321945,-55.645668,-0.001164,0.003798,0.096470,290.566528,14.802165,0.964702,-55.645668,294.500458,0.000000
96.230003,65.256409,-55.690151,-0.001168,0.003798,0.096470,290.274994,14.787313,0.964702,-55.690151,294.500458,0.000000
96.590004,65.109695,-55.645668,-0.001155,0.003798,0.096470,289.622375,14.754068,0.964702,-55.645668,294.500458,0.000000
96.950005,65.292908,-55.734631,-0.001164,0.003804,0.096618,290.437347,14.795585,0.966176,-55.734631,294.500458,0.000000
97.310005,65.307800,-55.734631,-0.001160,0.003804,0.096618,290.503601,14.798959,0.966176,-55.734631,294.500458,0.000000
97.670006,65.262741,-55.779114,-0.001160,0.003804,0.096618,290.303162,14.788749,0.966176,-55.779114,294.500458,0.000000
98.030006,65.150284,-55.868076,-0.001151,0.003804,0.096618,289.802948,14.763266,0.966176,-55.868076,294.500458,0.000000
98.390007,65.051605,-55.779114,-0.001155,0.003804,0.096618,289.363983,14.740905,0.966176,-55.779114,294.500458,0.000000
98.750008,64.965591,-55.912556,-0.001155,0.003804,0.096618,288.981384,14.721414,0.966176,-55.912556,294.500458,0.000000
99.110008,64.889618,-55.912556,-0.001155,0.003804,0.096618,288.643433,14.704198,0.966176,-55.912556,294.500458,0.000000
99.470001,64.879562,-55.957035,-0.001173,0.003806,0.096670,288.598694,14.701919,0.966697,-55.957035,294.500458,0.000000
99.830002,64.816635,-55.957035,-0.001155,0.003806,0.096670,288.318787,14.687659,0.966697,-55.957035,294.500458,0.000000
100.190002,64.745148,-55.957035,-0.001151,0.003806,0.096670,288.000793,14.671460,0.966697,-55.957035,294.500458,0.000000
100.550003,64.822601,-56.090481,-0.001143,0.003810,0.096765,288.345337,14.689012,0.967650,-56.090481,294.500458,0.000000
100.910004,64.849411,-56.090481,-0.001151,0.003810,0.096765,288.464600,14.695086,0.967650,-56.090481,294.500458,0.000000
101.270004,64.799515,-56.134960,-0.001147,0.003810,0.096765,288.242645,14.683780,0.967650,-56.134960,294.500458,0.000000
101.630005,64.776047,-56.134960,-0.001147,0.003811,0.096791,288.138245,14.678462,0.967911,-56.134960,294.500458,0.000000
101.990005,64.731369,-56.090481,-0.001147,0.003811,0.096791,287.939514,14.668338,0.967911,-56.090481,294.500458,0.000000
102.350006,65.651505,-56.223923,-0.001155,0.003822,0.097077,292.032471,14.876843,0.970772,-56.223923,294.500458,0.000000
102.710007,65.657455,-56.223923,-0.001147,0.003822,0.097069,292.058960,14.878192,0.970686,-56.223923,294.500458,0.000000
103.070007,65.594894,-56.312885,-0.001147,0.003822,0.097069,291.780670,14.864016,0.970686,-56.312885,294.500458,0.000000
103.430008,65.548355,-56.312885,-0.001147,0.003822,0.097069,291.573639,14.853469,0.970686,-56.312885,294.500458,0.000000
103.790009,65.492874,-56.357365,-0.001138,0.003822,0.097069,291.326843,14.840898,0.970686,-56.357365,294.500458,0.000000
104.150002,65.387115,-56.357365,-0.001147,0.003822,0.097069,290.856415,14.816933,0.970686,-56.357365,294.500458,0.000000
104.510002,65.337219,-56.401848,-0.001143,0.003822,0.097069,290.634460,14.805625,0.970686,-56.401848,294.500458,0.000000
104.870003,65.269821,-56.490807,-0.001138,0.003822,0.097077,290.334656,14.790353,0.970772,-56.490807,294.500458,0.000000
105.230003,65.205399,-56.446327,-0.001134,0.003822,0.097077,290.048096,14.775755,0.970772,-56.446327,294.500458,0.000000
105.590004,65.104477,-56.490807,-0.001143,0.003822,0.097086,289.599182,14.752885,0.970859,-56.490807,294.500458,0.000000
105.950005,65.043793,-56.668732,-0.001155,0.003822,0.097086,289.329254,14.739134,0.970859,-56.668732,294.500458,0.000000
106.310005,64.987183,-56.624252,-0.001130,0.003822,0.097086,289.077423,14.726306,0.970859,-56.624252,294.500458,0.000000
106.670006,65.142471,-56.713211,-0.001134,0.003826,0.097173,289.768188,14.761495,0.971726,-56.713211,294.500458,0.000000
107.030006,65.089966,-56.668732,-0.001143,0.003826,0.097173,289.534637,14.749597,0.971726,-56.668732,294.500458,0.000000
107.390007,65.040436,-56.624252,-0.001125,0.003826,0.097173,289.314301,14.738373,0.971726,-56.624252,294.500458,0.000000
107.750008,64.988297,-56.713211,-0.001125,0.003826,0.097181,289.082367,14.726559,0.971813,-56.713211,294.500458,0.000000
108.110008,65.048630,-56.713211,-0.001125,0.003828,0.097233,289.350769,14.740230,0.972333,-56.713211,294.500458,0.000000
108.470009,65.035965,-56.802174,-0.001138,0.003828,0.097233,289.294434,14.737360,0.972333,-56.802174,294.500458,0.000000
108.830002,65.000214,-56.757694,-0.001138,0.003828,0.097233,289.135376,14.729259,0.972333,-56.757694,294.500458,0.000000
109.190002,64.934677,-56.846657,-0.001134,0.003828,0.097233,288.843872,14.714408,0.972333,-56.846657,294.500458,0.000000
109.550003,64.922012,-56.935616,-0.001143,0.003829,0.097268,288.787537,14.711538,0.972680,-56.935616,294.500458,0.000000
109.910004,64.880310,-56.891136,-0.001130,0.003829,0.097268,288.602020,14.702088,0.972680,-56.891136,294.500458,0.000000
110.270004,64.815887,-56.935616,-0.001138,0.003829,0.097268,288.315460,14.687490,0.972680,-56.935616,294.500458,0.000000
110.630005,64.784607,-56.891136,-0.001138,0.003829,0.097268,288.176331,14.680402,0.972680,-56.891136,294.500458,0.000000
110.990005,64.718704,-56.980099,-0.001121,0.003829,0.097268,287.883179,14.665468,0.972680,-56.980099,294.500458,0.000000
111.350006,65.585220,-56.980099,-0.001138,0.003840,0.097528,291.737640,14.861823,0.975282,-56.980099,294.500458,0.000000
111.710007,65.591553,-56.980099,-0.001125,0.003840,0.097528,291.765808,14.863258,0.975282,-56.980099,294.500458,0.000000
112.070007,65.584473,-57.113541,-0.001130,0.003840,0.097528,291.734314,14.861653,0.975282,-57.113541,294.500458,0.000000
112.430008,65.553940,-57.069061,-0.001138,0.003840,0.097528,291.598480,14.854734,0.975282,-57.069061,294.500458,0.000000
112.790009,65.522278,-57.158024,-0.001138,0.003840,0.097528,291.457642,14.847560,0.975282,-57.158024,294.500458,0.000000
113.150009,65.440369,-57.202503,-0.001134,0.003840,0.097528,291.093292,14.829000,0.975282,-57.202503,294.500458,0.000000
113.510002,65.377426,-57.158024,-0.001121,0.003840,0.097528,290.813324,14.814736,0.975282,-57.158024,294.500458,0.000000
113.870003,65.317474,-57.246983,-0.001125,0.003840,0.097528,290.546631,14.801151,0.975282,-57.246983,294.500458,0.000000
114.230003,65.285461,-57.246983,-0.001108,0.003840,0.097528,290.404236,14.793897,0.975282,-57.246983,294.500458,0.000000
114.590004,65.221039,-57.291466,-0.001117,0.003840,0.097528,290.117676,14.779299,0.975282,-57.291466,294.500458,0.000000
114.950005,65.179703,-57.291466,-0.001125,0.003840,0.097528,289.933807,14.769932,0.975282,-57.291466,1681.640747,0.000000
115.310005,65.062027,-57.335945,-0.001117,0.003830,0.097285,289.410339,14.743266,0.972854,-57.335945,0.097086,0.000000
115.670006,64.888138,-57.380428,-0.001130,0.003811,0.096791,288.636841,14.703862,0.967911,-57.380428,0.096488,0.000000
116.030006,64.789078,-57.380428,-0.001117,0.003795,0.096401,288.196198,14.681415,0.964008,-57.380428,0.095889,0.000000
116.390007,64.753342,-57.469387,-0.001099,0.003766,0.095664,288.037262,14.673317,0.956637,-57.469387,0.095291,0.000000
116.750008,64.645721,-57.424908,-0.001125,0.003748,0.095187,287.558533,14.648930,0.951867,-57.424908,0.094692,0.000000
117.110008,64.589111,-57.513870,-0.001125,0.003725,0.094623,287.306702,14.636102,0.946230,-57.513870,0.094094,0.000000
117.470009,64.493790,-57.558350,-0.001112,0.003701,0.094016,286.882690,14.614502,0.940159,-57.558350,0.093487,0.000000
117.830002,64.440536,-57.602833,-0.001108,0.003680,0.093478,286.645813,14.602434,0.934783,-57.602833,0.092889,0.000000
118.190002,64.339264,-57.602833,-0.001112,0.003656,0.092863,286.195343,14.579486,0.928625,-57.602833,0.092290,0.000000
118.550003,64.261429,-57.602833,-0.001117,0.003629,0.092177,285.849121,14.561848,0.921774,-57.602833,0.091692,0.000000
118.910004,64.044708,-57.647312,-0.001108,0.003609,0.091666,284.885101,14.512738,0.916658,-57.647312,0.091093,0.000000
119.270004,63.425079,-57.736275,-0.001108,0.003589,0.091171,282.128845,14.372328,0.911714,-57.736275,0.090486,0.000000
119.630005,62.492287,-57.736275,-0.001104,0.003563,0.090504,277.979584,14.160954,0.905037,-57.736275,0.089888,0.000000
119.990005,61.442200,-57.825237,-0.001104,0.003544,0.090018,273.308563,13.923001,0.900180,-57.825237,0.089290,0.000000
120.350006,59.968719,-57.780754,-0.001082,0.003519,0.089394,266.754181,13.589107,0.893936,-57.780754,0.088691,0.000000
120.710007,58.415558,-57.825237,-0.001087,0.003498,0.088847,259.845367,13.237154,0.888473,-57.825237,0.088093,0.000000
121.070007,56.878403,-57.869717,-0.001095,0.003480,0.088388,253.007767,12.888830,0.883876,-57.869717,0.087486,0.000000
121.430008,55.947098,-57.914200,-0.001095,0.003466,0.088032,248.865128,12.677794,0.880321,-57.914200,0.086887,0.000000
121.790009,53.206810,-58.003159,-0.001095,0.003437,0.087295,236.675705,12.056835,0.872949,-58.003159,0.086289,0.000000
122.150009,51.229515,-57.958679,-0.001104,0.003414,0.086714,227.880264,11.608774,0.867139,-57.958679,0.085691,0.000000
122.510002,48.070679,-58.003159,-0.001078,0.003386,0.085994,213.829056,10.892971,0.859941,-58.003159,0.085092,0.000000
122.870003,45.713562,-58.092121,-0.001091,0.003363,0.085430,203.344086,10.358841,0.854304,-58.092121,0.084485,0.000000
123.230003,43.147911,-58.092121,-0.001078,0.003341,0.084849,191.931488,9.777456,0.848494,-58.092121,0.083887,0.000000
123.590004,40.831009,-58.136604,-0.001091,0.003318,0.084277,181.625397,9.252439,0.842770,-58.136604,0.083288,0.000000
123.950005,39.007500,-58.092121,-0.001091,0.003300,0.083817,173.514023,8.839226,0.838174,-58.092121,0.082690,0.000000
124.310005,35.636414,-58.225563,-0.001091,0.003269,0.083028,158.518692,8.075327,0.830282,-58.225563,0.082092,0.000000
124.670006,33.040237,-58.270046,-0.001099,0.003245,0.082412,146.970322,7.487025,0.824125,-58.270046,0.081485,0.000000
125.030006,30.672691,-58.136604,-0.001078,0.003223,0.081866,136.438950,6.950531,0.818661,-58.136604,0.080886,0.000000
125.390007,28.941162,-58.314526,-0.001087,0.003208,0.081485,128.736725,6.558161,0.814845,-58.314526,0.080288,0.000000
125.750008,26.120811,-58.225563,-0.001078,0.003182,0.080825,116.191170,5.919061,0.808254,-58.225563,0.079689,0.000000
126.110008,23.157471,-58.314526,-0.001082,0.003153,0.080088,103.009575,5.247558,0.800883,-58.314526,0.079091,0.000000
126.470009,20.068642,-58.359009,-0.001091,0.003123,0.079334,89.269775,4.547619,0.793338,-58.359009,0.078493,0.000000
126.830009,17.991920,-58.359009,-0.001087,0.003104,0.078831,80.032059,4.077027,0.788308,-58.359009,0.077886,0.000000
127.190002,16.140114,-58.492451,-0.001087,0.003088,0.078432,71.794815,3.657402,0.784319,-58.492451,0.077287,0.000000
127.550003,13.513023,-58.359009,-0.001091,0.003064,0.077816,60.108929,3.062095,0.778162,-58.359009,0.076689,0.000000
127.910004,11.011421,-58.492451,-0.001078,0.003038,0.077174,48.981247,2.495224,0.771744,-58.492451,0.076090,0.000000
128.270004,8.136337,-58.536930,-0.001091,0.003009,0.076437,36.192234,1.843720,0.764373,-58.536930,0.075492,0.000000
128.630005,5.577393,-58.536930,-0.001095,0.002985,0.075813,24.809481,1.263855,0.758129,-58.536930,0.074885,0.000000
128.990005,3.305923,-58.581413,-0.001082,0.002961,0.075214,14.705482,0.749133,0.752145,-58.581413,0.074287,0.000000
129.350006,1.397141,-58.625893,-0.001091,0.002941,0.074703,6.214791,0.316597,0.747028,-58.625893,0.073688,0.000000
129.710007,-0.886620,-58.670376,-0.001108,0.002914,0.074026,-3.943881,-0.200911,0.740264,-58.670376,0.073090,0.000000
130.070007,-2.953659,-58.625893,-0.001082,0.002888,0.073350,-13.138532,-0.669309,0.733500,-58.625893,0.072491,0.000000
130.430008,-0.046547,-58.714855,-0.001099,0.002864,0.072752,-0.207051,-0.010548,0.727516,-58.714855,0.071884,0.000000
130.790009,0.046547,-58.759335,-0.001099,0.002846,0.072301,0.207051,0.010548,0.723006,-58.759335,0.071286,0.000000
131.150009,0.094208,-58.803818,-0.001130,0.002822,0.071676,0.419057,0.021348,0.716762,-58.803818,0.070688,0.000000
131.510010,0.070374,-58.803818,-0.001143,0.002798,0.071078,0.313037,0.015947,0.710778,-58.803818,0.070089,0.000000
131.870010,0.081917,-58.803818,-0.001199,0.002776,0.070523,0.364384,0.018563,0.705228,-58.803818,0.069491,0.000000
132.230011,0.044685,-58.892780,-0.001242,0.002745,0.069734,0.198770,0.010126,0.697336,-58.892780,0.068884,0.000000
132.590012,0.047661,-58.937260,-0.001285,0.002727,0.069265,0.212006,0.010800,0.692653,-58.937260,0.068285,0.000000
132.950012,0.061066,-58.937260,-0.001311,0.002703,0.068667,0.271634,0.013838,0.686669,-58.937260,0.067687,0.000000
133.310013,0.066284,-59.026222,-0.001362,0.002681,0.068086,0.294847,0.015020,0.680859,-59.026222,0.067089,0.000000
133.670013,0.050644,-58.981743,-0.001393,0.002656,0.067453,0.225275,0.011476,0.674528,-58.981743,0.066490,0.000000
134.029999,0.013031,-59.026222,-0.001431,0.002633,0.066889,0.057965,0.002953,0.668891,-59.026222,0.065892,0.000000
134.389999,0.037979,-59.026222,-0.001475,0.002604,0.066135,0.168940,0.008606,0.661346,-59.026222,0.065285,0.000000
134.750000,-0.003723,-59.070702,-0.001505,0.002584,0.065640,-0.016561,-0.000844,0.656403,-59.070702,0.064686,0.000000
135.110001,-0.015266,-59.159664,-0.001531,0.002563,0.065094,-0.067908,-0.003459,0.650940,-59.159664,0.064088,0.000000
135.470001,-0.011543,-59.159664,-0.001578,0.002539,0.064478,-0.051347,-0.002616,0.644782,-59.159664,0.063490,0.000000
135.830002,-0.015266,-59.248627,-0.001591,0.002518,0.063949,-0.067908,-0.003459,0.639492,-59.248627,0.062891,0.000000
136.190002,-0.001488,-59.248627,-0.001656,0.002485,0.063117,-0.006618,-0.000337,0.631167,-59.248627,0.062284,0.000000
136.550003,-0.008942,-59.248627,-0.001681,0.002467,0.062674,-0.039774,-0.002026,0.626744,-59.248627,0.061686,0.000000
136.910004,-0.012665,-59.293106,-0.001699,0.002444,0.062076,-0.056336,-0.002870,0.620760,-59.293106,0.061087,0.000000
137.270004,0.006699,-59.337589,-0.001725,0.002417,0.061391,0.029797,0.001518,0.613909,-59.337589,0.060489,0.000000
137.630005,-0.015266,-59.382069,-0.001755,0.002401,0.060983,-0.067908,-0.003459,0.609833,-59.382069,0.059891,0.000000
137.990005,-0.030167,-59.426552,-0.001789,0.002372,0.060255,-0.134188,-0.006836,0.602548,-59.426552,0.059284,0.000000
138.350006,-0.040588,-59.426552,-0.001815,0.002349,0.059665,-0.180546,-0.009197,0.596651,-59.426552,0.058685,0.000000
138.710007,-0.034264,-59.471031,-0.001837,0.002324,0.059023,-0.152412,-0.007764,0.590234,-59.471031,0.058087,0.000000
139.070007,-0.038727,-59.471031,-0.001863,0.002304,0.058520,-0.172265,-0.008776,0.585204,-59.471031,0.057488,0.000000
139.430008,-0.045807,-59.559994,-0.001893,0.002282,0.057974,-0.203759,-0.010380,0.579740,-59.559994,0.056890,0.000000
139.790009,-0.046921,-59.559994,-0.001927,0.002252,0.057211,-0.208714,-0.010632,0.572109,-59.559994,0.056283,0.000000
140.150009,-0.053253,-59.604473,-0.001957,0.002225,0.056526,-0.236882,-0.012067,0.565258,-59.604473,0.055685,0.000000
140.510010,-0.051018,-59.604473,-0.001975,0.002201,0.055901,-0.226938,-0.011561,0.559014,-59.604473,0.055086,0.000000
140.870010,-0.051758,-59.648956,-0.002001,0.002187,0.055546,-0.230230,-0.011728,0.555458,-59.648956,0.054488,0.000000
141.230011,-0.038727,-59.737919,-0.002039,0.002160,0.054869,-0.172265,-0.008776,0.548694,-59.737919,0.053889,0.000000
141.590012,-0.051758,-59.693436,-0.002052,0.002131,0.054124,-0.230230,-0.011728,0.541236,-59.693436,0.053291,0.000000
141.950012,-0.061813,-59.782398,-0.002082,0.002108,0.053543,-0.274960,-0.014007,0.535425,-59.782398,0.052684,0.000000
142.310013,-0.068520,-59.782398,-0.002104,0.002087,0.053022,-0.304790,-0.015527,0.530222,-59.782398,0.052086,0.000000
142.670013,-0.049530,-59.782398,-0.002139,0.002063,0.052406,-0.220321,-0.011224,0.524064,-59.782398,0.051487,0.000000
143.030014,-0.061813,-59.871361,-0.002151,0.002041,0.051834,-0.274960,-0.014007,0.518341,-59.871361,0.050889,0.000000
143.389999,-0.048035,-59.871361,-0.002186,0.002020,0.051314,-0.213669,-0.010885,0.513137,-59.871361,0.050290,0.000000
143.750000,-0.047668,-59.915840,-0.002212,0.001989,0.050533,-0.212040,-0.010802,0.505332,-59.915840,0.049683,0.000000
144.110001,-0.045807,-59.960323,-0.002242,0.001967,0.049970,-0.203759,-0.010380,0.499695,-59.960323,0.049085,0.000000
144.470001,-0.034630,-59.960323,-0.002268,0.001943,0.049345,-0.154041,-0.007847,0.493451,-59.960323,0.048487,0.000000
144.830002,-0.032768,-60.004803,-0.002285,0.001923,0.048833,-0.145760,-0.007425,0.488335,-60.004803,0.047888,0.000000
145.190002,-0.071495,-60.049282,-0.002294,0.001902,0.048313,-0.318026,-0.016201,0.483131,-60.049282,0.047290,0.000000
145.550003,-0.053253,-60.049282,-0.002333,0.001875,0.047619,-0.236882,-0.012067,0.476194,-60.049282,0.046683,0.000000
145.910004,-0.037613,-60.093765,-0.002358,0.001848,0.046952,-0.167311,-0.008523,0.469516,-60.093765,0.046084,0.000000
146.270004,-0.043198,-60.182728,-0.002389,0.001825,0.046353,-0.192153,-0.009789,0.463532,-60.182728,0.045486,0.000000
146.630005,-0.059212,-60.182728,-0.002406,0.001805,0.045850,-0.263387,-0.013418,0.458502,-60.182728,0.044888,0.000000
146.990005,-0.056976,-60.138245,-0.002432,0.001784,0.045304,-0.253443,-0.012911,0.453039,-60.138245,0.044289,0.000000
147.350006,-0.045807,-60.227207,-0.002453,0.001755,0.044567,-0.203759,-0.010380,0.445667,-60.227207,0.043682,0.000000
147.710007,-0.073730,-60.227207,-0.002496,0.001728,0.043890,-0.327969,-0.016708,0.438903,-60.227207,0.043084,0.000000
148.070007,-0.035004,-60.271690,-0.002505,0.001708,0.043379,-0.155704,-0.007932,0.433786,-60.271690,0.042485,0.000000
148.430008,-0.017502,-60.316170,-0.002539,0.001683,0.042737,-0.077852,-0.003966,0.427369,-60.316170,0.041887,0.000000
148.790009,-0.030533,-60.316170,-0.002600,0.001661,0.042199,-0.135817,-0.006919,0.421992,-60.316170,0.041289,0.000000
149.150009,-0.049896,-60.360649,-0.002600,0.001642,0.041696,-0.221950,-0.011307,0.416962,-60.360649,0.040690,0.000000
149.510010,-0.023087,-60.360649,-0.002630,0.001614,0.041002,-0.102694,-0.005231,0.410024,-60.360649,0.040083,0.000000
149.870010,-0.019737,-60.494095,-0.002634,0.001589,0.040369,-0.087796,-0.004473,0.403694,-60.494095,0.039485,0.000000
150.230011,-0.000374,-60.494095,-0.002673,0.001565,0.039745,-0.001663,-0.000085,0.397450,-60.494095,0.038886,0.000000
150.590012,0.001488,-60.449612,-0.002686,0.001545,0.039242,0.006618,0.000337,0.392420,-60.449612,0.038288,0.000000
150.950012,0.001114,-60.538574,-0.002729,0.001523,0.038678,0.004955,0.000252,0.386783,-60.538574,0.037690,0.000000
151.310013,-0.023834,-60.583054,-0.002742,0.001496,0.037993,-0.106020,-0.005401,0.379932,-60.583054,0.037083,0.000000
151.600006,-0.014526,-60.627537,-0.002751,0.001487,0.037759,-0.064617,-0.003292,0.377590,-60.627537,0.037612,0.000000