File: Data/compression 19/AutoNoHeating-17-19-reverse-2-2_09112024_161433.csv
Time (sec),S:Load (lbs),S:HL1 (DIM),S:LVDT (in),S:Position (in),Ch:Position (mm),Ch:Load (N),Ch:Stress (MPa),Ch:Strain (mm/mm),Ch:HL1 (DIM),Set Point (),Cycles ()
0.210000,-0.046921,-268.842865,-0.011861,-0.006708,-0.170392,-0.208714,-0.010632,-1.703922,-268.842865,-0.170176,0.000000
0.660000,-0.062553,-268.931824,-0.011839,-0.006562,-0.166672,-0.278251,-0.014175,-1.666724,-268.931824,-0.165649,0.000000
1.110000,-0.087135,-268.931824,-0.011563,-0.006273,-0.159336,-0.387597,-0.019745,-1.593358,-268.931824,-0.158156,0.000000
1.560000,-0.033882,-268.976318,-0.011266,-0.005987,-0.152068,-0.150715,-0.007678,-1.520680,-268.976318,-0.150646,0.000000
2.010000,-0.027557,-269.020782,-0.010960,-0.005686,-0.144436,-0.122581,-0.006245,-1.444361,-269.020782,-0.143153,0.000000
2.460000,-0.061813,-269.065277,-0.010654,-0.005392,-0.136961,-0.274960,-0.014007,-1.369610,-269.065277,-0.135660,0.000000
2.910000,-0.048409,-269.065277,-0.010339,-0.005096,-0.129442,-0.215332,-0.010970,-1.294419,-269.065277,-0.128167,0.000000
3.360000,-0.015266,-269.109741,-0.010042,-0.004797,-0.121854,-0.067908,-0.003459,-1.218539,-269.109741,-0.120657,0.000000
3.810000,-0.040588,-269.154236,-0.009757,-0.004502,-0.114344,-0.180546,-0.009197,-1.143440,-269.154236,-0.113165,0.000000
4.260000,-0.018242,-269.198730,-0.009438,-0.004207,-0.106868,-0.081144,-0.004134,-1.068680,-269.198730,-0.105671,0.000000
4.710000,-0.051758,-269.243195,-0.009153,-0.003912,-0.099366,-0.230230,-0.011728,-0.993664,-269.243195,-0.098179,0.000000
5.160000,-0.092346,-269.243195,-0.008830,-0.003616,-0.091856,-0.410776,-0.020926,-0.918564,-269.243195,-0.090669,0.000000
5.610000,-0.013031,-269.243195,-0.008541,-0.003322,-0.084381,-0.057965,-0.002953,-0.843812,-269.243195,-0.083175,0.000000
6.060000,0.006332,-269.287689,-0.008239,-0.003031,-0.076983,0.028168,0.001435,-0.769832,-269.287689,-0.075683,0.000000
6.510000,-0.044312,-269.376648,-0.007925,-0.002731,-0.069370,-0.197107,-0.010041,-0.693696,-269.376648,-0.068190,0.000000
6.960001,-0.059952,-269.376648,-0.007631,-0.002444,-0.062084,-0.266679,-0.013585,-0.620844,-269.376648,-0.060679,0.000000
7.410000,-0.058830,-269.421112,-0.007317,-0.002144,-0.054462,-0.261690,-0.013331,-0.544616,-269.421112,-0.053187,0.000000
7.860001,-0.030907,-269.421112,-0.007019,-0.001845,-0.046856,-0.137480,-0.007004,-0.468562,-269.421112,-0.045694,0.000000
8.310000,-0.013779,-269.465607,-0.006704,-0.001550,-0.039381,-0.061291,-0.003122,-0.393811,-269.465607,-0.038201,0.000000
8.760000,-0.036865,-269.554565,-0.006403,-0.001261,-0.032026,-0.163985,-0.008354,-0.320263,-269.554565,-0.030708,0.000000
9.210000,-0.089737,-269.510071,-0.006084,-0.000956,-0.024291,-0.399170,-0.020335,-0.242907,-269.510071,-0.023198,0.000000
9.660001,-0.028671,-269.599030,-0.005799,-0.000663,-0.016841,-0.127536,-0.006497,-0.168413,-269.599030,-0.015706,0.000000
10.110001,0.006332,-269.599030,-0.005497,-0.000375,-0.009531,0.028168,0.001435,-0.095311,-269.599030,-0.008212,0.000000
10.560000,0.008194,-269.688019,-0.005174,-0.000074,-0.001882,0.036449,0.001857,-0.018818,-269.688019,-0.000720,0.000000
11.010000,0.185814,-269.688019,-0.004928,0.000014,0.000364,0.826542,0.042106,0.003641,-269.688019,0.000477,0.000000
11.460001,0.157890,-269.776978,-0.004928,0.000014,0.000355,0.702331,0.035778,0.003550,-269.776978,0.000512,0.000000
11.910001,0.164215,-269.688019,-0.004932,0.000014,0.000355,0.730465,0.037212,0.003550,-269.688019,0.001266,0.000000
12.360001,0.282257,-269.732483,-0.004915,0.000040,0.001006,1.255542,0.063960,0.010060,-269.732483,0.002011,0.000000
12.810000,0.606972,-269.821442,-0.004868,0.000074,0.001873,2.699945,0.137542,0.018728,-269.821442,0.002766,0.000000
13.260000,0.859436,-269.865936,-0.004850,0.000097,0.002454,3.822963,0.194751,0.024541,-269.865936,0.003512,0.000000
13.710001,1.412781,-269.865936,-0.004829,0.000133,0.003391,6.284363,0.320141,0.033905,-269.865936,0.004266,0.000000
14.160001,1.865219,-269.910400,-0.004799,0.000161,0.004093,8.296909,0.422665,0.040930,-269.910400,0.005012,0.000000
14.610001,2.449097,-269.954895,-0.004777,0.000190,0.004839,10.894126,0.554973,0.048386,-269.954895,0.005767,0.000000
15.060000,2.602882,-269.954895,-0.004760,0.000201,0.005099,11.578199,0.589822,0.050990,-269.954895,0.006512,0.000000
15.510001,3.670105,-270.043854,-0.004725,0.000250,0.006339,16.325441,0.831658,0.063389,-270.043854,0.007267,0.000000
15.960001,4.373146,-270.088348,-0.004687,0.000281,0.007146,19.452724,0.990969,0.071459,-270.088348,0.008013,0.000000
16.410000,4.879944,-270.177307,-0.004665,0.000306,0.007761,21.707075,1.105811,0.077613,-270.177307,0.008767,0.000000
16.860001,5.616493,-270.132812,-0.004652,0.000336,0.008524,24.983410,1.272716,0.085243,-270.132812,0.009513,0.000000
17.310001,6.302406,-270.177307,-0.004622,0.000364,0.009253,28.034504,1.428146,0.092533,-270.177307,0.010268,0.000000
17.760000,6.943260,-270.266266,-0.004600,0.000394,0.010016,30.885164,1.573365,0.100163,-270.266266,0.011013,0.000000
18.210001,7.484314,-270.266266,-0.004570,0.000426,0.010814,33.291893,1.695970,0.108142,-270.266266,0.011768,0.000000
18.660002,8.237625,-270.310730,-0.004549,0.000455,0.011551,36.642788,1.866673,0.115515,-270.310730,0.012514,0.000000
19.110001,8.715378,-270.355225,-0.004523,0.000479,0.012167,38.767937,1.974933,0.121669,-270.355225,0.013268,0.000000
19.560001,9.485077,-270.355225,-0.004514,0.000512,0.013008,42.191730,2.149349,0.130079,-270.355225,0.014014,0.000000
20.010000,9.946068,-270.355225,-0.004475,0.000541,0.013737,44.242321,2.253811,0.137369,-270.355225,0.014769,0.000000
20.460001,10.620064,-270.488678,-0.004437,0.000574,0.014586,47.240402,2.406541,0.145862,-270.488678,0.015514,0.000000
20.910002,10.927269,-270.488678,-0.004411,0.000597,0.015168,48.606918,2.476155,0.151676,-270.488678,0.016269,0.000000
21.360001,11.670898,-270.533142,-0.004402,0.000631,0.016018,51.914749,2.644663,0.160177,-270.533142,0.017015,0.000000
21.810001,12.261856,-270.577637,-0.004368,0.000661,0.016781,54.543461,2.778576,0.167807,-270.577637,0.017769,0.000000
22.260000,12.755249,-270.622101,-0.004346,0.000690,0.017526,56.738182,2.890381,0.175263,-270.622101,0.018515,0.000000
22.710001,13.179382,-270.666595,-0.004324,0.000718,0.018246,58.624821,2.986491,0.182462,-270.666595,0.019270,0.000000
23.160002,13.684319,-270.711060,-0.004294,0.000745,0.018914,60.870888,3.100911,0.189139,-270.711060,0.020015,0.000000
23.610001,14.394058,-270.711060,-0.004264,0.000779,0.019790,64.027969,3.261740,0.197897,-270.711060,0.020770,0.000000
24.060001,14.884850,-270.800018,-0.004247,0.000810,0.020562,66.211121,3.372955,0.205618,-270.800018,0.021516,0.000000
24.510000,15.365204,-270.844513,-0.004208,0.000836,0.021247,68.347839,3.481805,0.212469,-270.844513,0.022270,0.000000
24.960001,15.702576,-270.888977,-0.004186,0.000862,0.021905,69.848549,3.558254,0.219055,-270.888977,0.023016,0.000000
25.410002,16.706863,-270.888977,-0.004152,0.000898,0.022808,74.315842,3.785829,0.228078,-270.888977,0.023771,0.000000
25.860001,16.849480,-270.977966,-0.004135,0.000926,0.023519,74.950226,3.818147,0.235186,-270.977966,0.024516,0.000000
26.310001,17.432991,-270.977966,-0.004126,0.000959,0.024369,77.545815,3.950372,0.243687,-270.977966,0.025271,0.000000
26.760002,17.760307,-271.066925,-0.004087,0.000986,0.025036,79.001793,4.024543,0.250363,-271.066925,0.026017,0.000000
27.210001,17.882072,-271.066925,-0.004070,0.001007,0.025565,79.543434,4.052135,0.255655,-271.066925,0.026771,0.000000
27.660002,18.590324,-271.066925,-0.004040,0.001043,0.026502,82.693893,4.212627,0.265018,-271.066925,0.027517,0.000000
28.110001,19.027489,-271.111389,-0.004014,0.001071,0.027213,84.638496,4.311691,0.272134,-271.111389,0.028271,0.000000
28.560001,19.368210,-271.066925,-0.003984,0.001101,0.027968,86.154099,4.388899,0.279681,-271.066925,0.029017,0.000000
29.010002,19.771118,-271.155884,-0.003967,0.001127,0.028636,87.946327,4.480199,0.286358,-271.155884,0.029771,0.000000
29.460001,20.579536,-271.200348,-0.003932,0.001164,0.029563,91.542351,4.663389,0.295631,-271.200348,0.030518,0.000000
29.910002,20.843178,-271.200348,-0.003919,0.001194,0.030318,92.715088,4.723132,0.303178,-271.200348,0.031272,0.000000
30.360001,21.094154,-271.244843,-0.003898,0.001223,0.031063,93.831482,4.780004,0.310634,-271.244843,0.032018,0.000000
30.810001,21.142937,-271.378296,-0.003859,0.001248,0.031688,94.048477,4.791058,0.316879,-271.378296,0.032772,0.000000
31.260002,22.321495,-271.333801,-0.003837,0.001287,0.032686,99.290970,5.058123,0.326856,-271.333801,0.033518,0.000000
31.710001,22.141640,-271.378296,-0.003816,0.001311,0.033301,98.490929,5.017367,0.333010,-271.378296,0.034264,0.000000
32.160000,22.334900,-271.422760,-0.003786,0.001338,0.033978,99.350594,5.061161,0.339778,-271.422760,0.035019,0.000000
32.610001,22.591469,-271.422760,-0.003760,0.001364,0.034654,100.491875,5.119300,0.346537,-271.422760,0.035764,0.000000
33.060001,23.269554,-271.511719,-0.003734,0.001399,0.035539,103.508148,5.272956,0.355386,-271.511719,0.036519,0.000000
33.510002,23.580864,-271.556213,-0.003712,0.001425,0.036198,104.892921,5.343500,0.361980,-271.556213,0.037265,0.000000
33.960003,23.207375,-271.556213,-0.003673,0.001443,0.036657,103.231560,5.258866,0.366575,-271.556213,0.038019,0.000000
34.410000,24.453331,-271.556213,-0.003648,0.001487,0.037767,108.773849,5.541204,0.377672,-271.556213,0.038765,0.000000
34.860001,24.652924,-271.600677,-0.003626,0.001513,0.038427,109.661682,5.586432,0.384265,-271.600677,0.039519,0.000000
35.310001,25.443466,-271.645172,-0.003604,0.001551,0.039389,113.178192,5.765572,0.393894,-271.645172,0.040265,0.000000
35.760002,25.396919,-271.689636,-0.003574,0.001578,0.040092,112.971138,5.755024,0.400919,-271.689636,0.041019,0.000000
36.210003,24.778786,-271.734131,-0.003540,0.001592,0.040429,110.221542,5.614953,0.404295,-271.734131,0.041766,0.000000
36.660000,24.212402,-271.734131,-0.003540,0.001611,0.040924,107.702148,5.486609,0.409238,-271.734131,0.042520,0.000000
37.110001,27.196968,-271.778625,-0.003497,0.001671,0.042433,120.978157,6.162921,0.424332,-271.778625,0.043266,0.000000
37.560001,27.068504,-271.823090,-0.003471,0.001698,0.043118,120.406723,6.133811,0.431183,-271.823090,0.044020,0.000000
38.010002,27.185799,-271.867584,-0.003445,0.001725,0.043803,120.928474,6.160390,0.438033,-271.867584,0.044766,0.000000
38.460003,27.196968,-271.912048,-0.003432,0.001749,0.044419,120.978157,6.162921,0.444188,-271.912048,0.045520,0.000000
38.910004,28.151733,-271.956543,-0.003402,0.001787,0.045382,125.225166,6.379274,0.453816,-271.956543,0.046267,0.000000
39.360001,28.441063,-272.001007,-0.003385,0.001815,0.046102,126.512169,6.444837,0.461015,-272.001007,0.047021,0.000000
39.810001,28.534904,-272.001007,-0.003341,0.001842,0.046778,126.929596,6.466102,0.467775,-272.001007,0.047766,0.000000
40.260002,28.815674,-272.001007,-0.003324,0.001867,0.047419,128.178513,6.529725,0.474194,-272.001007,0.048521,0.000000
40.710003,28.654808,-272.089966,-0.003311,0.001887,0.047931,127.462952,6.493272,0.479312,-272.089966,0.049266,0.000000
41.160004,30.262337,-272.089966,-0.003281,0.001931,0.049058,134.613602,6.857543,0.490583,-272.089966,0.050021,0.000000
41.610001,30.551674,-272.134460,-0.003242,0.001959,0.049761,135.900635,6.923109,0.497608,-272.134460,0.050767,0.000000
42.060001,30.911011,-272.223419,-0.003225,0.001989,0.050525,137.499039,7.004535,0.505246,-272.223419,0.051522,0.000000
42.510002,31.082306,-272.267914,-0.003203,0.002014,0.051157,138.261002,7.043351,0.511574,-272.267914,0.052267,0.000000
42.960003,31.733208,-272.223419,-0.003191,0.002046,0.051973,141.156357,7.190847,0.519727,-272.223419,0.053022,0.000000
43.410004,32.472000,-272.312378,-0.003147,0.002079,0.052796,144.442673,7.358260,0.527963,-272.312378,0.053767,0.000000
43.860001,32.939697,-272.312378,-0.003139,0.002108,0.053542,146.523087,7.464242,0.535419,-272.312378,0.054522,0.000000
44.310001,32.705475,-272.356873,-0.003113,0.002130,0.054098,145.481216,7.411167,0.540975,-272.356873,0.055268,0.000000
44.760002,32.949005,-272.401337,-0.003096,0.002153,0.054696,146.564499,7.466352,0.546955,-272.401337,0.056022,0.000000
45.210003,34.524139,-272.445831,-0.003078,0.002196,0.055771,153.571045,7.823282,0.557712,-272.445831,0.056768,0.000000
45.660004,34.842148,-272.490295,-0.003048,0.002221,0.056421,154.985611,7.895344,0.564214,-272.490295,0.057523,0.000000
46.110001,35.198135,-272.445831,-0.003018,0.002252,0.057202,156.569122,7.976011,0.572019,-272.445831,0.058268,0.000000
46.560001,35.759300,-272.534790,-0.003005,0.002277,0.057826,159.065308,8.103173,0.578264,-272.534790,0.059023,0.000000
47.010002,37.147133,-272.579254,-0.002988,0.002314,0.058780,165.238693,8.417660,0.587802,-272.579254,0.059769,0.000000
47.460003,37.732132,-272.623749,-0.002975,0.002345,0.059552,167.840912,8.550223,0.595523,-272.623749,0.060523,0.000000
47.910004,38.520813,-272.668243,-0.002940,0.002376,0.060358,171.349136,8.728941,0.603585,-272.668243,0.061269,0.000000
48.360001,38.430328,-272.668243,-0.002919,0.002397,0.060896,170.946640,8.708437,0.608959,-272.668243,0.062024,0.000000
48.810001,39.578354,-272.757202,-0.002910,0.002432,0.061781,176.053314,8.968584,0.617808,-272.757202,0.062769,0.000000
49.260002,40.056480,-272.801666,-0.002871,0.002461,0.062518,178.180130,9.076928,0.625181,-272.801666,0.063524,0.000000
49.710003,40.722656,-272.801666,-0.002859,0.002490,0.063246,181.143417,9.227886,0.632464,-272.801666,0.064270,0.000000
50.160004,40.861549,-272.846161,-0.002846,0.002513,0.063836,181.761246,9.259359,0.638360,-272.846161,0.065024,0.000000
50.610001,42.924866,-272.846161,-0.002824,0.002555,0.064903,190.939346,9.726913,0.649026,-272.846161,0.065770,0.000000
51.060001,42.810173,-272.935120,-0.002811,0.002576,0.065432,190.429153,9.700924,0.654317,-272.935120,0.066516,0.000000
51.510002,43.784302,-272.935120,-0.002790,0.002608,0.066247,194.762299,9.921664,0.662470,-272.935120,0.067270,0.000000
51.960003,44.210297,-272.890625,-0.002781,0.002633,0.066880,196.657227,10.018196,0.668799,-272.890625,0.068016,0.000000
52.410004,44.599800,-272.979584,-0.002751,0.002659,0.067531,198.389816,10.106459,0.675309,-272.979584,0.068771,0.000000
52.860001,46.462402,-273.068573,-0.002729,0.002699,0.068545,206.675095,10.528531,0.685452,-273.068573,0.069516,0.000000
53.310001,46.647476,-273.024078,-0.002716,0.002723,0.069170,207.498337,10.570470,0.691697,-273.024078,0.070271,0.000000
53.760002,47.666656,-273.113037,-0.002699,0.002756,0.069993,212.031876,10.801419,0.699933,-273.113037,0.071017,0.000000
54.210003,48.214417,-273.113037,-0.002686,0.002781,0.070635,214.468430,10.925543,0.706352,-273.113037,0.071771,0.000000
54.660004,49.821579,-273.157532,-0.002669,0.002818,0.071572,221.617447,11.289731,0.715716,-273.157532,0.072517,0.000000
55.110004,50.073296,-273.201996,-0.002656,0.002842,0.072179,222.737137,11.346771,0.721787,-273.201996,0.073272,0.000000
55.560001,51.468948,-273.246490,-0.002630,0.002878,0.073098,228.945312,11.663031,0.730984,-273.246490,0.074017,0.000000
56.010002,51.699074,-273.290955,-0.002608,0.002900,0.073653,229.968964,11.715178,0.736533,-273.290955,0.074772,0.000000
56.460003,53.708771,-273.335449,-0.002600,0.002939,0.074650,238.908539,12.170582,0.746502,-273.335449,0.075518,0.000000
56.910004,54.014488,-273.379913,-0.002578,0.002964,0.075292,240.268448,12.239858,0.752922,-273.379913,0.076272,0.000000
57.360004,54.447929,-273.424408,-0.002565,0.002988,0.075891,242.196487,12.338078,0.758909,-273.424408,0.077018,0.000000
57.810001,55.038513,-273.468872,-0.002561,0.003018,0.076654,244.823532,12.471906,0.766540,-273.468872,0.077773,0.000000
58.260002,57.169975,-273.513367,-0.002544,0.003057,0.077660,254.304749,12.954902,0.776600,-273.513367,0.078518,0.000000
58.710003,57.851784,-273.513367,-0.002522,0.003082,0.078284,257.337585,13.109402,0.782845,-273.513367,0.079273,0.000000
59.160004,58.184685,-273.602325,-0.002522,0.003110,0.078987,258.818390,13.184838,0.789870,-273.602325,0.080019,0.000000
59.610004,59.216904,-273.602325,-0.002514,0.003136,0.079663,263.409943,13.418742,0.796630,-273.602325,0.080773,0.000000
60.060001,60.039101,-273.646820,-0.002505,0.003164,0.080375,267.067261,13.605055,0.803745,-273.646820,0.081519,0.000000
60.510002,61.221756,-273.735779,-0.002479,0.003199,0.081259,272.327972,13.873048,0.812587,-273.735779,0.082274,0.000000
60.960003,62.248016,-273.646820,-0.002475,0.003229,0.082004,276.893005,14.105602,0.820043,-273.646820,0.083019,0.000000
61.410004,63.217308,-273.780243,-0.002458,0.003258,0.082742,281.204620,14.325246,0.827416,-273.780243,0.083773,0.000000
61.860004,63.814217,-273.780243,-0.002458,0.003282,0.083366,283.859802,14.460508,0.833661,-273.780243,0.084520,0.000000
62.310001,64.629707,-273.824738,-0.002449,0.003309,0.084051,287.487305,14.645302,0.840512,-273.824738,0.085274,0.000000
62.760002,66.011955,-273.869202,-0.002432,0.003346,0.084979,293.635834,14.958523,0.849792,-273.869202,0.086020,0.000000
63.210003,64.112862,-273.869202,-0.002440,0.003359,0.085308,285.188263,14.528183,0.853085,-273.869202,294.500488,0.000000
63.660004,65.402382,-273.913696,-0.002406,0.003358,0.085283,290.924316,14.820392,0.852828,-273.913696,294.500488,0.000000
64.110001,65.855186,-273.958191,-0.002389,0.003306,0.083965,292.938507,14.922998,0.839649,-273.958191,294.500488,0.000000
64.560005,65.317482,-274.002655,-0.002393,0.003407,0.086532,290.546661,14.801153,0.865318,-274.002655,294.500488,0.000000
65.010002,65.096672,-274.047150,-0.002410,0.003424,0.086965,289.564453,14.751117,0.869648,-274.047150,294.500488,0.000000
65.460007,65.155128,-274.047150,-0.002384,0.003443,0.087459,289.824493,14.764363,0.874591,-274.047150,294.500488,0.000000
65.910004,65.230721,-274.091614,-0.002393,0.003462,0.087928,290.160736,14.781493,0.879277,-274.091614,294.500488,0.000000
66.360001,65.201302,-274.136108,-0.002384,0.003478,0.088344,290.029877,14.774826,0.883440,-274.136108,294.500488,0.000000
66.810005,65.013634,-274.180573,-0.002376,0.003494,0.088743,289.195099,14.732300,0.887429,-274.180573,294.500488,0.000000
67.260002,64.323997,-274.225067,-0.002384,0.003501,0.088925,286.127441,14.576027,0.889253,-274.225067,294.500488,0.000000
67.710007,65.640709,-274.314026,-0.002371,0.003375,0.085734,291.984467,14.874397,0.857339,-274.314026,294.500488,0.000000
68.160004,65.389351,-274.314026,-0.002363,0.003540,0.089905,290.866364,14.817439,0.899049,-274.314026,294.500488,0.000000
68.610001,65.024422,-274.314026,-0.002363,0.003552,0.090218,289.243073,14.734745,0.902175,-274.314026,294.500488,0.000000
69.060005,65.003944,-274.358521,-0.002345,0.003563,0.090504,289.151978,14.730104,0.905037,-274.358521,294.500488,0.000000
69.510002,65.750557,-274.358521,-0.002341,0.003532,0.089706,292.473083,14.899289,0.897058,-274.358521,294.500488,0.000000
69.960007,65.246727,-274.358521,-0.002337,0.003596,0.091336,290.231934,14.785120,0.913356,-274.358521,294.500488,0.000000
70.410004,65.294029,-274.447479,-0.002328,0.003611,0.091709,290.442352,14.795838,0.917088,-274.447479,294.500488,0.000000
70.860001,64.958138,-274.447479,-0.002337,0.003620,0.091943,288.948212,14.719725,0.919427,-274.447479,294.500488,0.000000
71.310005,64.745888,-274.447479,-0.002337,0.003629,0.092177,288.004089,14.671628,0.921773,-274.447479,294.500488,0.000000
71.760002,64.905632,-274.536438,-0.002315,0.003635,0.092324,288.714661,14.707827,0.923242,-274.536438,294.500488,0.000000
72.210007,66.092018,-274.536438,-0.002302,0.003615,0.091813,293.991974,14.976665,0.918132,-274.536438,294.500488,0.000000
72.660004,65.031502,-274.580902,-0.002298,0.003660,0.092958,289.274567,14.736349,0.929578,-274.580902,294.500488,0.000000
73.110001,64.981606,-274.714355,-0.002294,0.003675,0.093348,289.052612,14.725042,0.933476,-274.714355,294.500488,0.000000
73.560005,65.174858,-274.669861,-0.002294,0.003687,0.093660,289.912262,14.768834,0.936603,-274.669861,294.500488,0.000000
74.010002,65.461220,-274.714355,-0.002302,0.003699,0.093955,291.186035,14.833725,0.939547,-274.714355,294.500488,0.000000
74.460007,65.361427,-274.714355,-0.002281,0.003729,0.094727,290.742157,14.811111,0.947268,-274.714355,294.500488,0.000000
74.910004,65.644798,-274.803314,-0.002276,0.003674,0.093322,292.002655,14.875324,0.933219,-274.803314,294.500488,0.000000
75.360001,65.124962,-274.803314,-0.002268,0.003723,0.094571,289.690308,14.757527,0.945709,-274.803314,294.500488,0.000000
75.810005,65.417656,-274.803314,-0.002268,0.003738,0.094952,290.992279,14.823853,0.949524,-274.803314,294.500488,0.000000
76.260002,65.319344,-274.847809,-0.002276,0.003745,0.095126,290.554962,14.801575,0.951258,-274.847809,294.500488,0.000000
76.710007,65.159218,-274.936768,-0.002276,0.003755,0.095386,289.842682,14.765290,0.953862,-274.936768,294.500488,0.000000
77.160004,65.265358,-274.981232,-0.002276,0.003762,0.095542,290.314819,14.789341,0.955421,-274.981232,294.500488,0.000000
77.610001,65.295891,-274.936768,-0.002259,0.003769,0.095741,290.450623,14.796261,0.957412,-274.936768,294.500488,0.000000
78.060005,65.179710,-274.981232,-0.002264,0.003776,0.095906,289.933838,14.769934,0.959062,-274.981232,294.500488,0.000000
78.510002,65.117516,-275.025726,-0.002264,0.003782,0.096071,289.657166,14.755840,0.960712,-275.025726,294.500488,0.000000
78.960007,65.060921,-275.070190,-0.002251,0.003788,0.096218,289.405426,14.743015,0.962181,-275.070190,294.500488,0.000000
79.410004,65.143578,-275.070190,-0.002242,0.003796,0.096409,289.773102,14.761745,0.964088,-275.070190,294.500488,0.000000
79.860001,64.969322,-275.159149,-0.002251,0.003810,0.096774,288.997986,14.722259,0.967737,-275.159149,294.500488,0.000000
80.310005,65.286583,-275.159149,-0.002246,0.003810,0.096765,290.409210,14.794151,0.967646,-275.159149,294.500488,0.000000
80.760002,65.773643,-275.248138,-0.002246,0.003821,0.097051,292.575775,14.904521,0.970508,-275.248138,294.500488,0.000000
81.210007,65.271309,-275.203644,-0.002233,0.003821,0.097051,290.341278,14.790690,0.970508,-275.203644,294.500488,0.000000
81.660004,65.918114,-275.248138,-0.002233,0.003836,0.097424,293.218414,14.937258,0.974240,-275.248138,294.500488,0.000000
82.110001,65.489891,-275.337097,-0.002225,0.003834,0.097389,291.313599,14.840221,0.973891,-275.337097,294.500488,0.000000
82.560005,64.939903,-275.292603,-0.002220,0.003834,0.097389,288.867126,14.715592,0.973891,-275.292603,294.500488,0.000000
83.010002,65.886467,-275.337097,-0.002233,0.003842,0.097580,293.077637,14.930086,0.975799,-275.337097,294.500488,0.000000
83.460007,65.345039,-275.337097,-0.002207,0.003842,0.097580,290.669250,14.807397,0.975799,-275.337097,294.500488,0.000000
83.910004,65.491386,-275.426056,-0.002220,0.003863,0.098109,291.320251,14.840561,0.981090,-275.426056,294.500488,0.000000
84.360001,65.432549,-275.426056,-0.002220,0.003859,0.098014,291.058502,14.827228,0.980136,-275.426056,294.500488,0.000000
84.810005,65.037453,-275.470520,-0.002216,0.003864,0.098144,289.301025,14.737697,0.981438,-275.470520,294.500488,0.000000
85.260002,65.008415,-275.470520,-0.002229,0.003866,0.098195,289.171875,14.731118,0.981953,-275.470520,294.500488,0.000000
85.710007,65.235939,-275.603973,-0.002203,0.003873,0.098369,290.183960,14.782675,0.983694,-275.603973,294.500488,0.000000
86.160004,65.167412,-275.648468,-0.002212,0.003877,0.098482,289.879120,14.767146,0.984822,-275.648468,294.500488,0.000000
86.610001,65.287315,-275.603973,-0.002212,0.003882,0.098612,290.412476,14.794317,0.986117,-275.603973,294.500488,0.000000
87.060005,65.079903,-275.692932,-0.002199,0.003889,0.098785,289.489868,14.747316,0.987850,-275.692932,294.500488,0.000000
87.510002,65.330894,-275.692932,-0.002207,0.003890,0.098802,290.606323,14.804193,0.988024,-275.692932,294.500488,0.000000
87.960007,65.204659,-275.737427,-0.002199,0.003894,0.098898,290.044800,14.775586,0.988978,-275.737427,294.500488,0.000000
88.410004,65.050865,-275.737427,-0.002203,0.003897,0.098977,289.360687,14.740736,0.989765,-275.737427,294.500488,0.000000
88.860001,65.146935,-275.870850,-0.002195,0.003899,0.099045,289.788025,14.762506,0.990454,-275.870850,294.500488,0.000000
89.310005,65.094429,-275.870850,-0.002199,0.003903,0.099132,289.554474,14.750608,0.991325,-275.870850,294.500488,0.000000
89.760002,65.230721,-275.870850,-0.002203,0.003908,0.099271,290.160736,14.781493,0.992710,-275.870850,294.500488,0.000000
90.210007,65.002831,-275.870850,-0.002203,0.003908,0.099271,289.147034,14.729852,0.992710,-275.870850,294.500488,0.000000
90.660004,65.047142,-275.959808,-0.002177,0.003912,0.099375,289.344147,14.739893,0.993754,-275.959808,294.500488,0.000000
91.110001,65.014748,-276.004303,-0.002186,0.003916,0.099462,289.200043,14.732553,0.994617,-276.004303,294.500488,0.000000
91.560005,65.202797,-276.004303,-0.002186,0.003921,0.099583,290.036530,14.775166,0.995829,-276.004303,294.500488,0.000000
92.010002,64.993523,-276.093262,-0.002173,0.003921,0.099583,289.105621,14.727742,0.995829,-276.093262,294.500488,0.000000
92.460007,65.048256,-276.093262,-0.002173,0.003925,0.099696,289.349091,14.740146,0.996956,-276.093262,294.500488,0.000000
92.910004,65.273537,-276.093262,-0.002186,0.003931,0.099835,290.351196,14.791195,0.998349,-276.093262,294.500488,0.000000
93.360008,65.090340,-276.182220,-0.002190,0.003931,0.099835,289.536285,14.749682,0.998349,-276.182220,294.500488,0.000000
93.810005,65.209129,-276.137756,-0.002182,0.003935,0.099948,290.064697,14.776600,0.999477,-276.137756,294.500488,0.000000
94.260002,65.019218,-276.226715,-0.002190,0.003935,0.099956,289.219940,14.733565,0.999560,-276.226715,294.500488,0.000000
94.710007,66.026482,-276.315674,-0.002173,0.003943,0.100156,293.700470,14.961815,1.001559,-276.315674,294.500488,0.000000
95.160004,65.727089,-276.315674,-0.002177,0.003943,0.100147,292.368683,14.893970,1.001468,-276.315674,294.500488,0.000000
95.610008,65.432167,-276.315674,-0.002177,0.003943,0.100156,291.056824,14.827141,1.001559,-276.315674,294.500488,0.000000
96.060005,65.139854,-276.360138,-0.002173,0.003943,0.100156,289.756531,14.760902,1.001559,-276.360138,294.500488,0.000000
96.510002,64.875099,-276.404633,-0.002164,0.003943,0.100156,288.578857,14.700908,1.001559,-276.404633,294.500488,0.000000
96.960007,66.168724,-276.449097,-0.002164,0.003955,0.100459,294.333191,14.994047,1.004594,-276.449097,294.500488,0.000000
97.410004,65.878654,-276.538086,-0.002164,0.003955,0.100450,293.042877,14.928316,1.004504,-276.538086,294.500488,0.000000
97.860008,65.595268,-276.538086,-0.002169,0.003955,0.100450,291.782318,14.864100,1.004504,-276.538086,294.500488,0.000000
98.310005,65.351372,-276.538086,-0.002160,0.003955,0.100459,290.697418,14.808832,1.004594,-276.538086,294.500488,0.000000
98.760002,65.082146,-276.582550,-0.002156,0.003955,0.100459,289.499847,14.747825,1.004594,-276.582550,294.500488,0.000000
99.210007,65.327171,-276.671509,-0.002169,0.003965,0.100702,290.589783,14.803349,1.007017,-276.671509,294.500488,0.000000
99.660004,65.215828,-276.671509,-0.002151,0.003965,0.100702,290.094482,14.778117,1.007017,-276.671509,294.500488,0.000000
100.110008,65.073952,-276.671509,-0.002151,0.003965,0.100719,289.463379,14.745968,1.007191,-276.671509,294.500488,0.000000
100.560005,65.080650,-276.804962,-0.002156,0.003968,0.100780,289.493195,14.747486,1.007796,-276.804962,294.500488,0.000000
101.010002,65.038582,-276.760468,-0.002151,0.003970,0.100849,289.306061,14.737954,1.008493,-276.760468,294.500488,0.000000
101.460007,65.094429,-276.760468,-0.002160,0.003973,0.100910,289.554474,14.750608,1.009098,-276.760468,294.500488,0.000000
101.910004,65.252312,-276.804962,-0.002151,0.003978,0.101049,290.256775,14.786386,1.010491,-276.804962,294.500488,0.000000
102.360008,65.279121,-276.893921,-0.002147,0.003978,0.101049,290.376038,14.792460,1.010491,-276.893921,294.500488,0.000000
102.810005,65.145073,-276.938416,-0.002143,0.003978,0.101049,289.779755,14.762084,1.010491,-276.938416,294.500488,0.000000
103.260002,65.062782,-276.938416,-0.002147,0.003980,0.101092,289.413696,14.743437,1.010923,-276.938416,294.500488,0.000000
103.710007,65.250832,-276.982880,-0.002143,0.003984,0.101188,290.250183,14.786049,1.011877,-276.982880,294.500488,0.000000
104.160004,65.282112,-276.982880,-0.002169,0.003987,0.101257,290.389343,14.793138,1.012573,-276.982880,294.500488,0.000000
104.610008,65.225502,-277.071838,-0.002147,0.003987,0.101266,290.137512,14.780310,1.012656,-277.071838,294.500488,0.000000
105.060005,65.251579,-277.116333,-0.002147,0.003989,0.101326,290.253510,14.786219,1.013262,-277.116333,294.500488,0.000000
105.510002,65.152519,-277.160797,-0.002156,0.003989,0.101326,289.812866,14.763772,1.013262,-277.160797,294.500488,0.000000
105.960007,65.229973,-277.116333,-0.002143,0.003992,0.101404,290.157410,14.781323,1.014042,-277.116333,294.500488,0.000000
106.410004,65.167046,-277.205292,-0.002156,0.003993,0.101422,289.877502,14.767064,1.014216,-277.205292,294.500488,0.000000
106.860008,65.301094,-277.249756,-0.002147,0.003997,0.101534,290.473785,14.797440,1.015344,-277.249756,294.500488,0.000000
107.310005,65.283226,-277.294250,-0.002156,0.003997,0.101526,290.394287,14.793390,1.015260,-277.294250,294.500488,0.000000
107.760002,65.189766,-277.294250,-0.002134,0.003997,0.101526,289.978577,14.772212,1.015260,-277.294250,294.500488,0.000000
108.210007,65.051979,-277.383209,-0.002130,0.003998,0.101543,289.365662,14.740989,1.015434,-277.383209,294.500488,0.000000
108.660004,65.052361,-277.427704,-0.002139,0.004000,0.101595,289.367340,14.741076,1.015949,-277.427704,294.500488,0.000000
109.110008,64.984215,-277.427704,-0.002126,0.004000,0.101595,289.064240,14.725634,1.015949,-277.427704,294.500488,0.000000
109.560005,65.593040,-277.427704,-0.002130,0.004008,0.101803,291.772430,14.863595,1.018031,-277.427704,294.500488,0.000000
110.010002,65.535316,-277.516663,-0.002139,0.004008,0.101803,291.515656,14.850515,1.018031,-277.516663,294.500488,0.000000
110.460007,65.428078,-277.516663,-0.002147,0.004008,0.101803,291.038635,14.826214,1.018031,-277.516663,294.500488,0.000000
110.910004,65.318230,-277.561127,-0.002139,0.004008,0.101812,290.549988,14.801322,1.018122,-277.561127,294.500488,0.000000
111.360008,65.200188,-277.605621,-0.002139,0.004009,0.101820,290.024933,14.774573,1.018205,-277.605621,294.500488,0.000000
111.810005,65.076927,-277.694580,-0.002139,0.004009,0.101820,289.476624,14.746643,1.018205,-277.694580,294.500488,0.000000
112.260002,65.001335,-277.694580,-0.002139,0.004009,0.101838,289.140381,14.729513,1.018379,-277.694580,294.500488,0.000000
112.710007,65.467918,-277.739044,-0.002143,0.004023,0.102185,291.215851,14.835242,1.021846,-277.739044,294.500488,0.000000
113.160004,65.841789,-277.783539,-0.002139,0.004019,0.102089,292.878906,14.919962,1.020892,-277.783539,294.500488,0.000000
113.610008,65.737526,-277.783539,-0.002134,0.004019,0.102089,292.415131,14.896337,1.020892,-277.783539,294.500488,0.000000
114.060005,65.585960,-277.783539,-0.002130,0.004019,0.102089,291.740936,14.861991,1.020892,-277.783539,294.500488,0.000000
114.510002,65.491386,-277.872498,-0.002130,0.004019,0.102089,291.320251,14.840561,1.020892,-277.872498,294.500488,0.000000
114.960007,65.359184,-277.916992,-0.002126,0.004019,0.102089,290.732178,14.810603,1.020892,-277.916992,294.500488,0.000000
115.410004,65.249718,-277.916992,-0.002130,0.004019,0.102089,290.245239,14.785798,1.020892,-277.916992,294.500488,0.000000
115.860008,65.151772,-278.005951,-0.002117,0.004019,0.102089,289.809540,14.763602,1.020892,-278.005951,294.500488,0.000000
116.310005,65.014366,-278.005951,-0.002121,0.004020,0.102098,289.198334,14.732466,1.020983,-278.005951,294.500488,0.000000
116.760002,64.936180,-278.005951,-0.002130,0.004020,0.102098,288.850555,14.714748,1.020983,-278.005951,294.500488,0.000000
117.210007,64.808815,-278.050415,-0.002130,0.004020,0.102098,288.283997,14.685887,1.020983,-278.050415,294.500488,0.000000
117.660004,65.868599,-278.094910,-0.002121,0.004031,0.102384,292.998169,14.926038,1.023844,-278.094910,294.500488,0.000000
118.110008,65.800453,-278.139374,-0.002121,0.004031,0.102384,292.695038,14.910596,1.023844,-278.139374,294.500488,0.000000
118.560005,65.661552,-278.139374,-0.002117,0.004031,0.102384,292.077179,14.879121,1.023844,-278.139374,294.500488,0.000000
119.010002,65.588936,-278.183868,-0.002126,0.004031,0.102384,291.754150,14.862665,1.023844,-278.183868,294.500488,0.000000
119.460007,65.505165,-278.272827,-0.002126,0.004031,0.102384,291.381531,14.843682,1.023844,-278.272827,294.500488,0.000000
119.910004,65.376320,-278.317322,-0.002134,0.004031,0.102384,290.808380,14.814486,1.023844,-278.317322,294.500488,0.000000
120.360008,65.281731,-278.317322,-0.002117,0.004031,0.102384,290.387634,14.793052,1.023844,-278.317322,294.500488,0.000000
120.810005,65.190498,-278.317322,-0.002121,0.004031,0.102393,289.981812,14.772378,1.023928,-278.317322,294.500488,0.000000
121.260002,65.079170,-278.361786,-0.002126,0.004031,0.102393,289.486603,14.747151,1.023928,-278.361786,294.500488,0.000000
121.710007,65.019218,-278.406281,-0.002126,0.004033,0.102428,289.219940,14.733565,1.024276,-278.406281,294.500488,0.000000
122.160004,65.126823,-278.406281,-0.002126,0.004036,0.102523,289.698578,14.757949,1.025230,-278.406281,294.500488,0.000000
122.610008,65.209129,-278.495239,-0.002117,0.004036,0.102523,290.064697,14.776600,1.025230,-278.495239,294.500488,0.000000
123.060005,65.109703,-278.495239,-0.002113,0.004036,0.102523,289.622437,14.754069,1.025230,-278.495239,294.500488,0.000000
123.510002,65.037086,-278.495239,-0.002117,0.004036,0.102523,289.299408,14.737615,1.025230,-278.495239,1681.640991,0.000000
123.960007,64.906380,-278.539703,-0.002117,0.004022,0.102167,288.717987,14.707996,1.021672,-278.539703,0.101908,0.000000
124.410004,64.656898,-278.584198,-0.002121,0.004000,0.101604,287.608246,14.651463,1.016040,-278.584198,0.101153,0.000000
124.860008,64.538109,-278.628693,-0.002108,0.003975,0.100971,287.079834,14.624544,1.009712,-278.628693,0.100407,0.000000
125.310005,64.368675,-278.628693,-0.002117,0.003941,0.100112,286.326172,14.586150,1.001120,-278.628693,0.099652,0.000000
125.760010,64.335915,-278.717651,-0.002117,0.003918,0.099514,286.180450,14.578727,0.995140,-278.717651,0.098907,0.000000
126.210007,64.206322,-278.717651,-0.002108,0.003891,0.098820,285.603973,14.549360,0.988198,-278.717651,0.098152,0.000000
126.660004,64.075615,-278.762115,-0.002113,0.003860,0.098039,285.022583,14.519741,0.980394,-278.762115,0.097407,0.000000
127.110008,63.897621,-278.806610,-0.002108,0.003826,0.097190,284.230804,14.479408,0.971900,-278.806610,0.096652,0.000000
127.560005,63.443336,-278.806610,-0.002108,0.003801,0.096556,282.210052,14.376466,0.965565,-278.806610,0.095906,0.000000
128.010010,62.380585,-278.895569,-0.002108,0.003775,0.095880,277.482697,14.135643,0.958805,-278.895569,0.095151,0.000000
128.460007,61.247826,-278.895569,-0.002108,0.003750,0.095247,272.443939,13.878955,0.952469,-278.895569,0.094406,0.000000
128.910004,60.250610,-278.895569,-0.002095,0.003730,0.094753,268.008087,13.652984,0.947526,-278.895569,0.093651,0.000000
129.360001,57.503250,-279.028992,-0.002091,0.003689,0.093695,255.787231,13.030422,0.936951,-279.028992,0.092906,0.000000
129.810013,55.594467,-278.940033,-0.002087,0.003666,0.093105,247.296539,12.597886,0.931054,-278.940033,0.092151,0.000000
130.260010,54.227112,-278.984528,-0.002091,0.003651,0.092741,241.214233,12.288039,0.927405,-278.984528,0.091405,0.000000
130.710007,50.449020,-279.028992,-0.002087,0.003608,0.091631,224.408447,11.431911,0.916308,-279.028992,0.090651,0.000000
131.160004,47.368011,-279.117981,-0.002091,0.003577,0.090868,210.703445,10.733745,0.908678,-279.117981,0.089905,0.000000
131.610001,44.207687,-279.117981,-0.002100,0.003549,0.090148,196.645615,10.017605,0.901479,-279.117981,0.089150,0.000000
132.060013,40.916664,-279.162445,-0.002082,0.003520,0.089402,182.006409,9.271849,0.894022,-279.162445,0.088405,0.000000
132.510010,39.250290,-279.206940,-0.002100,0.003506,0.089055,174.594009,8.894242,0.890548,-279.206940,0.087650,0.000000
132.960007,34.637344,-279.251404,-0.002091,0.003463,0.087971,154.074600,7.848934,0.879708,-279.251404,0.086904,0.000000
133.410004,31.109489,-279.251404,-0.002091,0.003429,0.087095,138.381927,7.049511,0.870950,-279.251404,0.086159,0.000000
133.860001,28.743431,-279.295898,-0.002082,0.003409,0.086583,127.857170,6.513355,0.865833,-279.295898,0.085404,0.000000
134.310013,25.438629,-279.340363,-0.002108,0.003378,0.085803,113.156677,5.764476,0.858028,-279.340363,0.084658,0.000000
134.760010,21.880234,-279.340363,-0.002078,0.003344,0.084944,97.328140,4.958132,0.849444,-279.340363,0.083904,0.000000
135.210007,18.551971,-279.429321,-0.002091,0.003312,0.084129,82.523293,4.203937,0.841291,-279.429321,0.083158,0.000000
135.660004,15.476173,-279.429321,-0.002091,0.003282,0.083358,68.841461,3.506951,0.833578,-279.429321,0.082403,0.000000
136.110001,12.956703,-279.429321,-0.002087,0.003259,0.082776,57.634293,2.936031,0.827764,-279.429321,0.081658,0.000000
136.560013,9.287346,-279.473816,-0.002087,0.003224,0.081883,41.312180,2.104543,0.818832,-279.473816,0.080903,0.000000
137.010010,6.525085,-279.562775,-0.002091,0.003195,0.081146,29.025030,1.478606,0.811459,-279.562775,0.080157,0.000000
137.460007,3.902840,-279.562775,-0.002091,0.003167,0.080435,17.360699,0.884396,0.804351,-279.562775,0.079403,0.000000
137.910004,2.025711,-279.651733,-0.002100,0.003145,0.079880,9.010813,0.459033,0.798802,-279.651733,0.078657,0.000000
138.360001,-1.272022,-279.607269,-0.002082,0.003107,0.078917,-5.658237,-0.288244,0.789173,-279.607269,0.077902,0.000000
138.810013,-3.088455,-279.651733,-0.002091,0.003077,0.078145,-13.738135,-0.699854,0.781452,-279.651733,0.077157,0.000000
139.260010,-0.185814,-279.696228,-0.002100,0.003045,0.077347,-0.826542,-0.042106,0.773474,-279.696228,0.076403,0.000000
139.710007,0.043571,-279.829651,-0.002082,0.003024,0.076802,0.193816,0.009873,0.768016,-279.829651,0.075656,0.000000
140.160004,0.013779,-279.829651,-0.002074,0.002989,0.075925,0.061291,0.003122,0.759250,-279.829651,0.074902,0.000000
140.610001,0.007080,-279.918640,-0.002087,0.002958,0.075145,0.031494,0.001604,0.751445,-279.918640,0.074156,0.000000
141.060013,0.022346,-279.918640,-0.002061,0.002925,0.074304,0.099402,0.005064,0.743035,-279.918640,0.073402,0.000000
141.510010,-0.040215,-279.918640,-0.002082,0.002901,0.073696,-0.178883,-0.009113,0.736964,-279.918640,0.072656,0.000000
141.960007,-0.056229,-279.963104,-0.002074,0.002873,0.072968,-0.250117,-0.012742,0.729682,-279.963104,0.071902,0.000000
142.410004,-0.046547,-280.007599,-0.002082,0.002845,0.072257,-0.207051,-0.010548,0.722567,-280.007599,0.071155,0.000000
142.860001,-0.023827,-280.007599,-0.002082,0.002813,0.071450,-0.105986,-0.005399,0.714505,-280.007599,0.070401,0.000000
143.310013,-0.021965,-280.052063,-0.002095,0.002786,0.070774,-0.097705,-0.004977,0.707738,-280.052063,0.069655,0.000000
143.760010,-0.026436,-280.096558,-0.002117,0.002757,0.070037,-0.117593,-0.005990,0.700372,-280.096558,0.068901,0.000000
144.210007,-0.033882,-280.141022,-0.002134,0.002723,0.069170,-0.150715,-0.007678,0.691697,-280.141022,0.068155,0.000000
144.660004,-0.042450,-280.096558,-0.002169,0.002691,0.068363,-0.188827,-0.009619,0.683628,-280.096558,0.067401,0.000000
145.110001,-0.063675,-280.274475,-0.002177,0.002663,0.067644,-0.283240,-0.014429,0.676436,-280.274475,0.066655,0.000000
145.560013,-0.071495,-280.229980,-0.002195,0.002637,0.066975,-0.318026,-0.016201,0.669752,-280.229980,0.065900,0.000000
146.010010,-0.047661,-280.274475,-0.002225,0.002616,0.066438,-0.212006,-0.010800,0.664378,-280.274475,0.065155,0.000000
146.460007,-0.036865,-280.274475,-0.002251,0.002574,0.065380,-0.163985,-0.008354,0.653795,-280.274475,0.064400,0.000000
146.910004,-0.043938,-280.318939,-0.002276,0.002541,0.064530,-0.195445,-0.009956,0.645302,-280.318939,0.063654,0.000000
147.360001,-0.075218,-280.452393,-0.002285,0.002516,0.063914,-0.334587,-0.017045,0.639140,-280.452393,0.062900,0.000000
147.810013,-0.075218,-280.452393,-0.002307,0.002488,0.063186,-0.334587,-0.017045,0.631858,-280.452393,0.062154,0.000000
148.260010,-0.049149,-280.452393,-0.002333,0.002457,0.062396,-0.218624,-0.011137,0.623963,-280.452393,0.061399,0.000000
148.710007,-0.064789,-280.496887,-0.002371,0.002423,0.061538,-0.288195,-0.014681,0.615378,-280.496887,0.060654,0.000000
149.160004,-0.074471,-280.541351,-0.002389,0.002395,0.060844,-0.331261,-0.016875,0.608445,-280.541351,0.059899,0.000000
149.610001,-0.059578,-280.585846,-0.002419,0.002369,0.060177,-0.265016,-0.013501,0.601768,-280.585846,0.059153,0.000000
150.060013,-0.057716,-280.585846,-0.002419,0.002344,0.059543,-0.256735,-0.013079,0.595432,-280.585846,0.058399,0.000000
150.510010,-0.059952,-280.674805,-0.002466,0.002308,0.058624,-0.266679,-0.013585,0.586242,-280.674805,0.057653,0.000000
150.960007,-0.055107,-280.674805,-0.002479,0.002277,0.057835,-0.245129,-0.012487,0.578347,-280.674805,0.056898,0.000000
151.410004,-0.045052,-280.719269,-0.002518,0.002252,0.057210,-0.200399,-0.010209,0.572102,-280.719269,0.056153,0.000000
151.860001,-0.069633,-280.763763,-0.002535,0.002221,0.056404,-0.309745,-0.015779,0.564040,-280.763763,0.055398,0.000000
152.310013,-0.067024,-280.852722,-0.002557,0.002194,0.055727,-0.298139,-0.015188,0.557273,-280.852722,0.054652,0.000000
152.760010,-0.042076,-280.852722,-0.002600,0.002157,0.054800,-0.187164,-0.009535,0.548000,-280.852722,0.053898,0.000000
153.210007,-0.057716,-280.808258,-0.002617,0.002126,0.054002,-0.256735,-0.013079,0.540021,-280.808258,0.053152,0.000000
153.660004,-0.055481,-280.897217,-0.002630,0.002112,0.053637,-0.246792,-0.012572,0.536373,-280.897217,0.052406,0.000000
154.110001,-0.068146,-280.941681,-0.002656,0.002069,0.052545,-0.303127,-0.015442,0.525449,-280.941681,0.051652,0.000000
154.560013,-0.049149,-280.941681,-0.002699,0.002039,0.051782,-0.218624,-0.011137,0.517819,-280.941681,0.050906,0.000000
155.010010,-0.039101,-280.941681,-0.002712,0.002011,0.051079,-0.173928,-0.008860,0.510794,-280.941681,0.050151,0.000000
155.460007,-0.006699,-280.986176,-0.002746,0.001990,0.050550,-0.029797,-0.001518,0.505503,-280.986176,0.049406,0.000000
155.910004,-0.053993,-280.986176,-0.002764,0.001957,0.049718,-0.240174,-0.012235,0.497176,-280.986176,0.048651,0.000000
156.360001,-0.051010,-281.030640,-0.002790,0.001926,0.048911,-0.226904,-0.011559,0.489114,-281.030640,0.047905,0.000000
156.810013,-0.017502,-281.119598,-0.002824,0.001894,0.048096,-0.077852,-0.003966,0.480962,-281.119598,0.047151,0.000000
157.260010,-0.010422,-281.119598,-0.002850,0.001864,0.047351,-0.046358,-0.002362,0.473505,-281.119598,0.046405,0.000000
157.710007,-0.011917,-281.164093,-0.002876,0.001835,0.046604,-0.053010,-0.002700,0.466042,-281.164093,0.045650,0.000000
158.160004,-0.032021,-281.164093,-0.002902,0.001804,0.045833,-0.142435,-0.007256,0.458328,-281.164093,0.044905,0.000000
158.610001,-0.033508,-281.297546,-0.002945,0.001772,0.045000,-0.149052,-0.007593,0.450001,-281.297546,0.044150,0.000000
159.060013,-0.007072,-281.253052,-0.002971,0.001748,0.044410,-0.031460,-0.001603,0.444104,-281.253052,0.043404,0.000000
159.510010,0.001862,-281.297546,-0.002997,0.001717,0.043613,0.008281,0.000422,0.436126,-281.297546,0.042650,0.000000
159.960007,-0.017128,-281.253052,-0.003022,0.001685,0.042797,-0.076189,-0.003881,0.427973,-281.253052,0.041904,0.000000
160.410004,-0.034630,-281.430969,-0.003061,0.001656,0.042052,-0.154041,-0.007847,0.420517,-281.430969,0.041149,0.000000
160.860001,-0.007446,-281.386505,-0.003091,0.001626,0.041289,-0.033123,-0.001687,0.412887,-281.386505,0.040404,0.000000
161.310013,-0.038353,-281.475464,-0.003100,0.001598,0.040586,-0.170603,-0.008691,0.405862,-281.475464,0.039649,0.000000
161.760010,-0.048782,-281.475464,-0.003143,0.001575,0.039996,-0.216995,-0.011054,0.399965,-281.475464,0.038903,0.000000
162.210007,-0.027924,-281.519928,-0.003169,0.001538,0.039077,-0.124210,-0.006328,0.390768,-281.519928,0.038149,0.000000
162.660004,-0.071121,-281.519928,-0.003186,0.001514,0.038444,-0.316363,-0.016116,0.384439,-281.519928,0.037403,0.000000
163.110001,-0.043190,-281.564423,-0.003212,0.001493,0.037932,-0.192119,-0.009787,0.379322,-281.564423,0.036648,0.000000
163.560013,-0.054733,-281.608887,-0.003255,0.001450,0.036839,-0.243466,-0.012403,0.368391,-281.608887,0.035903,0.000000
164.010010,-0.044312,-281.653381,-0.003281,0.001428,0.036276,-0.197107,-0.010041,0.362759,-281.653381,0.035148,0.000000
164.460007,-0.046547,-281.653381,-0.003316,0.001392,0.035365,-0.207051,-0.010548,0.353653,-281.653381,0.034402,0.000000
164.910004,-0.045799,-281.697876,-0.003350,0.001363,0.034620,-0.203725,-0.010378,0.346197,-281.697876,0.033648,0.000000
165.360001,-0.033142,-281.742340,-0.003372,0.001332,0.033822,-0.147423,-0.007510,0.338218,-281.742340,0.032902,0.000000
165.810013,-0.038353,-281.786835,-0.003406,0.001301,0.033041,-0.170603,-0.008691,0.330414,-281.786835,0.032147,0.000000
166.260010,-0.070374,-281.831299,-0.003428,0.001275,0.032382,-0.313037,-0.015947,0.323820,-281.831299,0.031402,0.000000
166.710007,-0.088249,-281.831299,-0.003458,0.001248,0.031688,-0.392552,-0.019998,0.316879,-281.831299,0.030648,0.000000
167.160004,-0.080055,-281.875793,-0.003484,0.001217,0.030907,-0.356103,-0.018141,0.309075,-281.875793,0.029901,0.000000
167.610001,-0.064049,-281.920258,-0.003518,0.001184,0.030075,-0.284903,-0.014514,0.300748,-281.920258,0.029147,0.000000
168.060013,-0.056602,-281.964752,-0.003544,0.001154,0.029303,-0.251780,-0.012826,0.293034,-281.964752,0.028401,0.000000
168.510010,-0.088623,-281.875793,-0.003561,0.001130,0.028696,-0.394215,-0.020082,0.286963,-281.875793,0.027647,0.000000
168.960007,-0.071121,-281.920258,-0.003600,0.001104,0.028046,-0.316363,-0.016116,0.280461,-281.920258,0.026901,0.000000
169.410004,-0.077454,-282.009216,-0.003635,0.001066,0.027074,-0.344531,-0.017551,0.270741,-282.009216,0.026147,0.000000
169.860001,-0.068512,-282.053711,-0.003665,0.001039,0.026381,-0.304756,-0.015525,0.263807,-282.053711,0.025400,0.000000
170.310013,-0.086761,-282.142670,-0.003699,0.001008,0.025591,-0.385934,-0.019660,0.255912,-282.142670,0.024646,0.000000
170.760010,-0.067772,-282.098206,-0.003721,0.000978,0.024846,-0.301465,-0.015357,0.248456,-282.098206,0.023900,0.000000
171.210007,-0.061066,-282.187164,-0.003747,0.000951,0.024160,-0.271634,-0.013838,0.241605,-282.187164,0.023146,0.000000
171.660004,-0.084526,-282.231628,-0.003768,0.000923,0.023432,-0.375991,-0.019154,0.234323,-282.231628,0.022400,0.000000
172.110001,-0.067772,-282.231628,-0.003837,0.000889,0.022574,-0.301465,-0.015357,0.225739,-282.231628,0.021646,0.000000
172.560013,-0.040588,-282.231628,-0.003842,0.000859,0.021819,-0.180546,-0.009197,0.218192,-282.231628,0.020900,0.000000
173.010010,-0.079689,-282.320587,-0.003876,0.000839,0.021307,-0.354474,-0.018058,0.213074,-282.320587,0.020154,0.000000
173.460007,-0.060326,-282.320587,-0.003880,0.000803,0.020388,-0.268342,-0.013670,0.203885,-282.320587,0.019400,0.000000
173.910004,-0.049896,-282.365082,-0.003928,0.000770,0.019556,-0.221950,-0.011307,0.195558,-282.365082,0.018653,0.000000
174.360016,-0.078941,-282.498535,-0.003941,0.000745,0.018914,-0.351149,-0.017888,0.189139,-282.498535,0.017900,0.000000
174.810013,-0.078194,-282.454041,-0.003971,0.000714,0.018142,-0.347823,-0.017719,0.181418,-282.454041,0.017153,0.000000
175.260010,-0.072983,-282.454041,-0.004005,0.000688,0.017466,-0.324644,-0.016538,0.174658,-282.454041,0.016399,0.000000
175.710007,-0.045425,-282.498535,-0.004049,0.000652,0.016563,-0.202062,-0.010294,0.165635,-282.498535,0.015653,0.000000
176.160004,-0.064049,-282.498535,-0.004122,0.000624,0.015861,-0.284903,-0.014514,0.158610,-282.498535,0.014899,0.000000
176.610016,-0.035370,-282.587494,-0.004100,0.000593,0.015055,-0.157333,-0.008015,0.150548,-282.587494,0.014152,0.000000
177.060013,-0.056229,-282.587494,-0.004113,0.000579,0.014699,-0.250117,-0.012742,0.146990,-282.587494,0.013399,0.000000
177.510010,-0.059204,-282.631958,-0.004143,0.000540,0.013719,-0.263353,-0.013416,0.137195,-282.631958,0.012652,0.000000
177.960007,-0.040215,-282.631958,-0.004182,0.000506,0.012844,-0.178883,-0.009113,0.128437,-282.631958,0.011898,0.000000
178.410004,0.021225,-282.676453,-0.004143,0.000477,0.012106,0.094413,0.004810,0.121064,-282.676453,0.011153,0.000000
178.860016,-0.017128,-282.720917,-0.004264,0.000449,0.011395,-0.076189,-0.003881,0.113948,-282.720917,0.010398,0.000000
179.310013,-0.030159,-282.765411,-0.004290,0.000419,0.010632,-0.134154,-0.006834,0.106318,-282.765411,0.009652,0.000000
179.760010,-0.026810,-282.809875,-0.004307,0.000386,0.009808,-0.119255,-0.006075,0.098082,-282.809875,0.008898,0.000000
180.210007,0.000374,-282.854370,-0.004329,0.000362,0.009192,0.001663,0.000085,0.091920,-282.854370,0.008152,0.000000
180.660004,-0.001862,-282.898834,-0.004359,0.000336,0.008524,-0.008281,-0.000422,0.085243,-282.898834,0.007397,0.000000
181.110016,-0.007820,-282.898834,-0.004402,0.000297,0.007536,-0.034786,-0.001772,0.075357,-282.898834,0.006652,0.000000
181.560013,-0.030907,-282.943329,-0.004449,0.000270,0.006851,-0.137480,-0.007004,0.068507,-282.943329,0.005897,0.000000
182.010010,-0.031647,-282.943329,-0.004458,0.000242,0.006148,-0.140772,-0.007171,0.061482,-282.943329,0.005151,0.000000
182.460007,-0.029785,-282.943329,-0.004475,0.000220,0.005593,-0.132491,-0.006749,0.055933,-282.943329,0.004397,0.000000
182.910004,-0.017128,-283.032288,-0.004510,0.000180,0.004570,-0.076189,-0.003881,0.045699,-283.032288,0.003651,0.000000
183.360016,-0.024948,-283.121246,-0.004536,0.000151,0.003833,-0.110975,-0.005653,0.038326,-283.121246,0.002896,0.000000
183.810013,-0.005211,-283.121246,-0.004600,0.000122,0.003096,-0.023179,-0.001181,0.030960,-283.121246,0.002151,0.000000
184.260010,-0.048035,-283.121246,-0.004613,0.000094,0.002384,-0.213669,-0.010885,0.023845,-283.121246,0.001396,0.000000
184.710007,-0.038353,-283.165741,-0.004622,0.000070,0.001786,-0.170603,-0.008691,0.017865,-283.165741,0.000650,0.000000
185.160004,-0.021599,-283.210205,-0.004661,0.000040,0.001023,-0.096076,-0.004894,0.010227,-283.210205,-0.000104,0.000000
185.610016,-0.008934,-283.254700,-0.004687,0.000003,0.000078,-0.039741,-0.002024,0.000780,-283.254700,-0.000850,0.000000
185.800003,-0.021599,-283.343658,-0.004691,0.000006,0.000147,-0.096076,-0.004894,0.001469,-283.343658,-0.000000,0.000000