File: Data/compression 19/AutoNoHeating-17-19-reverse-2-1_09112024_161107.csv
Time (sec),S:Load (lbs),S:HL1 (DIM),S:LVDT (in),S:Position (in),Ch:Position (mm),Ch:Load (N),Ch:Stress (MPa),Ch:Strain (mm/mm),Ch:HL1 (DIM),Set Point (),Cycles ()
0.210000,-0.046547,-252.029068,-0.011969,-0.007444,-0.189072,-0.207051,-0.010548,-1.890722,-252.029068,-0.188751,0.000000
0.610000,-0.039841,-252.073547,-0.011973,-0.007331,-0.186202,-0.177220,-0.009028,-1.862017,-252.073547,-0.185127,0.000000
1.010000,-0.056229,-252.118027,-0.011745,-0.007076,-0.179733,-0.250117,-0.012742,-1.797325,-252.118027,-0.178466,0.000000
1.410000,-0.009682,-252.118027,-0.011482,-0.006813,-0.173054,-0.043066,-0.002194,-1.730545,-252.118027,-0.171806,0.000000
1.810000,-0.002975,-252.206985,-0.011244,-0.006555,-0.166507,-0.013236,-0.000674,-1.665074,-252.206985,-0.165128,0.000000
2.210000,-0.010422,-252.206985,-0.010947,-0.006291,-0.159786,-0.046358,-0.002362,-1.597862,-252.206985,-0.158468,0.000000
2.610000,-0.034256,-252.251480,-0.010688,-0.006028,-0.153117,-0.152378,-0.007763,-1.531172,-252.251480,-0.151808,0.000000
3.010000,-0.049149,-252.251480,-0.010412,-0.005758,-0.146249,-0.218624,-0.011137,-1.462491,-252.251480,-0.145148,0.000000
3.410000,-0.060326,-252.251480,-0.010123,-0.005500,-0.139710,-0.268342,-0.013670,-1.397096,-252.251480,-0.138487,0.000000
3.810000,-0.035004,-252.295959,-0.009873,-0.005232,-0.132885,-0.155704,-0.007932,-1.328846,-252.295959,-0.131810,0.000000
4.210000,-0.008934,-252.340439,-0.009602,-0.004974,-0.126338,-0.039741,-0.002024,-1.263375,-252.340439,-0.125149,0.000000
4.610000,-0.045799,-252.340439,-0.009334,-0.004713,-0.119703,-0.203725,-0.010378,-1.197026,-252.340439,-0.118489,0.000000
5.010000,-0.064789,-252.473877,-0.009063,-0.004452,-0.113068,-0.288195,-0.014681,-1.130684,-252.473877,-0.111829,0.000000
5.410000,-0.101280,-252.429398,-0.008795,-0.004191,-0.106443,-0.450517,-0.022950,-1.064434,-252.429398,-0.105151,0.000000
5.810000,-0.020851,-252.473877,-0.008537,-0.003923,-0.099652,-0.092750,-0.004725,-0.996525,-252.473877,-0.098491,0.000000
6.210001,-0.022339,-252.518356,-0.008261,-0.003657,-0.092888,-0.099368,-0.005062,-0.928881,-252.518356,-0.091831,0.000000
6.610000,-0.016006,-252.562836,-0.007989,-0.003398,-0.086306,-0.071200,-0.003627,-0.863062,-252.562836,-0.085170,0.000000
7.010000,-0.010796,-252.518356,-0.007722,-0.003137,-0.079680,-0.048021,-0.002446,-0.796804,-252.518356,-0.078510,0.000000
7.410000,-0.038353,-252.607315,-0.007446,-0.002878,-0.073089,-0.170603,-0.008691,-0.730893,-252.607315,-0.071832,0.000000
7.810000,-0.004097,-252.607315,-0.007187,-0.002616,-0.066455,-0.018224,-0.000928,-0.664552,-252.607315,-0.065172,0.000000
8.210000,0.009308,-252.696289,-0.006907,-0.002354,-0.059804,0.041403,0.002109,-0.598036,-252.696289,-0.058511,0.000000
8.610001,0.004097,-252.651794,-0.006627,-0.002091,-0.053117,0.018224,0.000928,-0.531172,-252.651794,-0.051852,0.000000
9.010000,-0.029045,-252.696289,-0.006364,-0.001826,-0.046379,-0.129199,-0.006582,-0.463793,-252.696289,-0.045191,0.000000
9.410001,-0.030533,-252.829727,-0.006096,-0.001558,-0.039580,-0.135817,-0.006919,-0.395802,-252.829727,-0.038514,0.000000
9.810000,-0.026062,-252.829727,-0.005821,-0.001303,-0.033085,-0.115930,-0.005906,-0.330845,-252.829727,-0.031853,0.000000
10.210000,-0.023827,-252.829727,-0.005558,-0.001035,-0.026294,-0.105986,-0.005399,-0.262944,-252.829727,-0.025193,0.000000
10.610001,-0.023460,-252.785248,-0.005286,-0.000778,-0.019755,-0.104357,-0.005316,-0.197549,-252.785248,-0.018532,0.000000
11.010000,0.110222,-252.918686,-0.005088,-0.000000,-0.000000,0.490291,0.024977,-0.000000,-252.918686,0.000191,0.000000
11.410001,0.100166,-253.007645,-0.005070,-0.000001,-0.000017,0.445562,0.022698,-0.000174,-253.007645,0.000191,0.000000
11.810000,0.084534,-253.007645,-0.005083,-0.000000,-0.000008,0.376025,0.019156,-0.000083,-253.007645,0.000728,0.000000
12.210001,0.084534,-253.007645,-0.005083,0.000001,0.000026,0.376025,0.019156,0.000257,-253.007645,0.001396,0.000000
12.610001,0.255447,-253.096619,-0.005044,0.000045,0.001145,1.136287,0.057885,0.011446,-253.096619,0.002064,0.000000
13.010000,0.307579,-253.052124,-0.005023,0.000068,0.001717,1.368180,0.069698,0.017168,-253.052124,0.002732,0.000000
13.410001,0.540314,-253.052124,-0.004993,0.000095,0.002419,2.403435,0.122437,0.024193,-253.052124,0.003400,0.000000
13.810000,0.737671,-253.096619,-0.004980,0.000119,0.003018,3.281324,0.167159,0.030181,-253.096619,0.004067,0.000000
14.210001,1.176697,-253.185577,-0.004937,0.000153,0.003876,5.234209,0.266643,0.038765,-253.185577,0.004735,0.000000
14.610001,1.438477,-253.185577,-0.004915,0.000174,0.004423,6.398664,0.325963,0.044230,-253.185577,0.005403,0.000000
15.010001,1.781807,-253.185577,-0.004894,0.000196,0.004970,7.925873,0.403763,0.049696,-253.185577,0.006062,0.000000
15.410001,2.363823,-253.319016,-0.004868,0.000226,0.005733,10.514810,0.535650,0.057326,-253.319016,0.006730,0.000000
15.810000,2.802101,-253.319016,-0.004846,0.000252,0.006391,12.464369,0.634965,0.063912,-253.319016,0.007397,0.000000
16.210001,3.269806,-253.363495,-0.004838,0.000277,0.007033,14.544823,0.740949,0.070331,-253.363495,0.008065,0.000000
16.610001,3.847725,-253.363495,-0.004812,0.000306,0.007779,17.115536,0.871907,0.077787,-253.363495,0.008733,0.000000
17.010000,4.198128,-253.363495,-0.004781,0.000323,0.008212,18.674206,0.951309,0.082125,-253.363495,0.009401,0.000000
17.410002,4.877335,-253.452454,-0.004781,0.000349,0.008872,21.695467,1.105220,0.088718,-253.452454,0.010069,0.000000
17.810001,5.550583,-253.452454,-0.004738,0.000380,0.009661,24.690226,1.257780,0.096606,-253.452454,0.010736,0.000000
18.210001,6.280060,-253.496933,-0.004704,0.000415,0.010537,27.935101,1.423082,0.105371,-253.496933,0.011404,0.000000
18.610001,6.497154,-253.585907,-0.004700,0.000436,0.011083,28.900785,1.472276,0.110829,-253.585907,0.012063,0.000000
19.010000,7.047897,-253.585907,-0.004678,0.000461,0.011699,31.350613,1.597076,0.116991,-253.585907,0.012731,0.000000
19.410002,7.491020,-253.585907,-0.004665,0.000482,0.012254,33.321724,1.697490,0.122540,-253.585907,0.013399,0.000000
19.810001,8.098732,-253.719345,-0.004631,0.000512,0.013000,36.024960,1.835199,0.129996,-253.719345,0.014066,0.000000
20.210001,8.370560,-253.719345,-0.004622,0.000530,0.013451,37.234108,1.896796,0.134508,-253.719345,0.014734,0.000000
20.610001,9.119034,-253.674866,-0.004583,0.000563,0.014309,40.563488,2.066402,0.143092,-253.674866,0.015402,0.000000
21.010000,9.478371,-253.763824,-0.004570,0.000590,0.014986,42.161900,2.147830,0.149859,-253.763824,0.016070,0.000000
21.410002,9.973999,-253.852783,-0.004553,0.000612,0.015541,44.366562,2.260140,0.155408,-253.852783,0.016738,0.000000
21.810001,10.159439,-253.808304,-0.004527,0.000630,0.016009,45.191441,2.302162,0.160093,-253.808304,0.017397,0.000000
22.210001,11.132080,-253.852783,-0.004501,0.000670,0.017006,49.517963,2.522566,0.170063,-253.852783,0.018065,0.000000
22.610001,11.618019,-253.808304,-0.004462,0.000699,0.017752,51.679531,2.632681,0.177519,-253.808304,0.018732,0.000000
23.010000,12.100243,-253.852783,-0.004458,0.000726,0.018437,53.824566,2.741954,0.184370,-253.852783,0.019400,0.000000
23.410002,12.265953,-253.986237,-0.004432,0.000745,0.018923,54.561684,2.779505,0.189230,-253.986237,0.020068,0.000000
23.810001,12.975693,-253.941757,-0.004411,0.000777,0.019738,57.718765,2.940334,0.197382,-253.941757,0.020735,0.000000
24.210001,13.518242,-253.986237,-0.004389,0.000804,0.020423,60.132145,3.063277,0.204233,-253.986237,0.021403,0.000000
24.610001,13.961365,-254.075195,-0.004355,0.000831,0.021117,62.103252,3.163691,0.211167,-254.075195,0.022071,0.000000
25.010002,14.208992,-254.075195,-0.004350,0.000854,0.021681,63.204754,3.219804,0.216806,-254.075195,0.022730,0.000000
25.410002,14.538536,-254.075195,-0.004333,0.000878,0.022305,64.670639,3.294479,0.223051,-254.075195,0.023397,0.000000
25.810001,15.332436,-254.164154,-0.004294,0.000911,0.023146,68.202080,3.474380,0.231461,-254.164154,0.024066,0.000000
26.210001,15.648582,-254.208633,-0.004281,0.000936,0.023762,69.608368,3.546020,0.237623,-254.208633,0.024734,0.000000
26.610001,15.888390,-254.297592,-0.004255,0.000961,0.024421,70.675087,3.600361,0.244209,-254.297592,0.025401,0.000000
27.010002,16.397049,-254.253113,-0.004221,0.000989,0.025115,72.937714,3.715625,0.251150,-254.253113,0.026069,0.000000
27.410002,16.479347,-254.297592,-0.004212,0.001009,0.025627,73.303795,3.734273,0.256268,-254.297592,0.026736,0.000000
27.810001,17.385696,-254.297592,-0.004178,0.001043,0.026485,77.335442,3.939655,0.264852,-254.297592,0.027404,0.000000
28.210001,17.575607,-254.386566,-0.004161,0.001068,0.027135,78.180206,3.982690,0.271354,-254.386566,0.028063,0.000000
28.610001,17.917076,-254.386566,-0.004130,0.001095,0.027803,79.699135,4.060068,0.278031,-254.386566,0.028731,0.000000
29.010002,18.331902,-254.475525,-0.004122,0.001120,0.028453,81.544373,4.154068,0.284533,-254.475525,0.029399,0.000000
29.410002,18.268967,-254.475525,-0.004087,0.001141,0.028992,81.264420,4.139807,0.289915,-254.475525,0.030066,0.000000
29.810001,19.170853,-254.520004,-0.004074,0.001173,0.029798,85.276215,4.344177,0.297977,-254.520004,0.030734,0.000000
30.210001,19.372681,-254.564484,-0.004053,0.001198,0.030440,86.173988,4.389912,0.304396,-254.564484,0.031403,0.000000
30.610001,19.343636,-254.564484,-0.004031,0.001218,0.030926,86.044785,4.383330,0.309256,-254.564484,0.032070,0.000000
31.010002,19.918579,-254.608963,-0.004010,0.001247,0.031662,88.602264,4.513615,0.316622,-254.608963,0.032738,0.000000
31.410002,20.161362,-254.697922,-0.003988,0.001271,0.032296,89.682213,4.568630,0.322958,-254.697922,0.033405,0.000000
31.810001,20.884140,-254.697922,-0.003954,0.001306,0.033162,92.897293,4.732414,0.331625,-254.697922,0.034065,0.000000
32.210003,20.750832,-254.742401,-0.003941,0.001327,0.033709,92.304306,4.702206,0.337090,-254.742401,0.034732,0.000000
32.610001,21.263214,-254.742401,-0.003923,0.001356,0.034437,94.583504,4.818314,0.344372,-254.742401,0.035400,0.000000
33.010002,21.370827,-254.786880,-0.003893,0.001378,0.035010,95.062187,4.842699,0.350103,-254.786880,0.036068,0.000000
33.410000,21.528343,-254.875854,-0.003876,0.001401,0.035573,95.762856,4.878393,0.355735,-254.875854,0.036735,0.000000
33.810001,22.246651,-254.875854,-0.003850,0.001434,0.036424,98.958046,5.041163,0.364236,-254.875854,0.037403,0.000000
34.210003,22.399323,-254.920334,-0.003850,0.001460,0.037074,99.637161,5.075759,0.370738,-254.920334,0.038072,0.000000
34.610001,22.403419,-254.964813,-0.003833,0.001482,0.037638,99.655388,5.076687,0.376378,-254.964813,0.038739,0.000000
35.010002,22.890854,-254.964813,-0.003807,0.001509,0.038331,101.823601,5.187141,0.383311,-254.964813,0.039398,0.000000
35.410000,22.880424,-254.964813,-0.003781,0.001528,0.038817,101.777214,5.184779,0.388171,-254.964813,0.040066,0.000000
35.810001,24.054520,-255.009293,-0.003760,0.001568,0.039831,106.999847,5.450832,0.398315,-255.009293,0.040734,0.000000
36.210003,23.843010,-255.009293,-0.003742,0.001590,0.040395,106.059006,5.402903,0.403954,-255.009293,0.041401,0.000000
36.610001,24.302147,-255.142731,-0.003712,0.001618,0.041089,108.101349,5.506945,0.410888,-255.142731,0.042069,0.000000
37.010002,24.362473,-255.142731,-0.003695,0.001642,0.041705,108.369690,5.520615,0.417050,-255.142731,0.042737,0.000000
37.410004,24.439178,-255.187210,-0.003678,0.001665,0.042286,108.710892,5.537997,0.422856,-255.187210,0.043404,0.000000
37.810001,25.354095,-255.231705,-0.003656,0.001697,0.043110,112.780647,5.745320,0.431100,-255.231705,0.044072,0.000000
38.210003,25.166794,-255.187210,-0.003639,0.001719,0.043656,111.947487,5.702877,0.436565,-255.187210,0.044731,0.000000
38.610001,24.470085,-255.320663,-0.003630,0.001729,0.043908,108.848373,5.545001,0.439078,-255.320663,0.045399,0.000000
39.010002,26.096237,-255.365143,-0.003609,0.001773,0.045027,116.081863,5.913492,0.450266,-255.365143,0.046067,0.000000
39.410004,26.929977,-255.276184,-0.003570,0.001806,0.045876,119.790520,6.102420,0.458760,-255.276184,0.046735,0.000000
39.810001,26.794060,-255.409622,-0.003553,0.001828,0.046422,119.185928,6.071621,0.464225,-255.409622,0.047403,0.000000
40.210003,26.571754,-255.409622,-0.003548,0.001851,0.047021,118.197067,6.021246,0.470213,-255.409622,0.048070,0.000000
40.610001,27.233833,-255.454102,-0.003518,0.001878,0.047706,121.142143,6.171275,0.477063,-255.454102,0.048738,0.000000
41.010002,27.698929,-255.543060,-0.003501,0.001906,0.048417,123.210991,6.276667,0.484171,-255.543060,0.049406,0.000000
41.410004,27.848251,-255.587540,-0.003501,0.001930,0.049016,123.875206,6.310504,0.490159,-255.587540,0.050065,0.000000
41.810001,28.318924,-255.543060,-0.003471,0.001956,0.049684,125.968864,6.417160,0.496836,-255.543060,0.050733,0.000000
42.210003,28.337921,-255.543060,-0.003454,0.001980,0.050299,126.053368,6.421465,0.502990,-255.543060,0.051400,0.000000
42.610001,28.643639,-255.587540,-0.003419,0.002003,0.050880,127.413269,6.490741,0.508803,-255.587540,0.052068,0.000000
43.010002,28.900574,-255.676514,-0.003410,0.002028,0.051513,128.556168,6.548964,0.515132,-255.676514,0.052736,0.000000
43.410004,29.919754,-255.720993,-0.003397,0.002063,0.052406,133.089706,6.779913,0.524064,-255.720993,0.053404,0.000000
43.810001,30.415382,-255.676514,-0.003389,0.002092,0.053126,135.294373,6.892224,0.531263,-255.676514,0.054072,0.000000
44.210003,30.503265,-255.676514,-0.003367,0.002117,0.053768,135.685303,6.912139,0.537682,-255.676514,0.054739,0.000000
44.610001,30.726685,-255.809952,-0.003350,0.002140,0.054366,136.679123,6.962766,0.543662,-255.809952,0.055407,0.000000
45.010002,31.408875,-255.809952,-0.003341,0.002170,0.055112,139.713654,7.117353,0.551119,-255.809952,0.056066,0.000000
45.410004,31.459518,-255.854431,-0.003320,0.002193,0.055711,139.938934,7.128829,0.557106,-255.854431,0.056734,0.000000
45.810001,32.027016,-255.898911,-0.003307,0.002222,0.056431,142.463287,7.257425,0.564305,-255.898911,0.057402,0.000000
46.210003,32.386726,-255.943390,-0.003290,0.002247,0.057063,144.063354,7.338937,0.570633,-255.943390,0.058069,0.000000
46.610001,32.786278,-255.898911,-0.003285,0.002272,0.057714,145.840652,7.429477,0.577136,-255.898911,0.058737,0.000000
47.010002,33.115082,-256.032349,-0.003260,0.002299,0.058399,147.303238,7.503985,0.583987,-256.032349,0.059405,0.000000
47.410004,33.859459,-256.032349,-0.003247,0.002329,0.059153,150.614395,7.672663,0.591534,-256.032349,0.060073,0.000000
47.810001,34.145065,-256.032349,-0.003212,0.002355,0.059821,151.884842,7.737382,0.598210,-256.032349,0.060741,0.000000
48.210003,34.645905,-256.076843,-0.003216,0.002379,0.060420,154.112686,7.850874,0.604198,-256.076843,0.061399,0.000000
48.610001,34.450043,-256.076843,-0.003195,0.002398,0.060905,153.241440,7.806491,0.609050,-256.076843,0.062067,0.000000
49.010002,35.747017,-256.121307,-0.003186,0.002434,0.061825,159.010666,8.100389,0.618247,-256.121307,0.062735,0.000000
49.410004,36.140610,-256.210266,-0.003178,0.002458,0.062440,160.761459,8.189579,0.624402,-256.210266,0.063403,0.000000
49.810001,36.558044,-256.210266,-0.003169,0.002486,0.063152,162.618301,8.284171,0.631517,-256.210266,0.064071,0.000000
50.210003,37.048454,-256.210266,-0.003152,0.002513,0.063837,164.799759,8.395300,0.638368,-256.210266,0.064738,0.000000
50.610001,36.968765,-256.254761,-0.003134,0.002534,0.064365,164.445282,8.377242,0.643652,-256.254761,0.065406,0.000000
51.010002,37.290497,-256.388214,-0.003130,0.002555,0.064894,165.876419,8.450148,0.648943,-256.388214,0.066074,0.000000
51.410004,38.378571,-256.388214,-0.003109,0.002587,0.065719,170.716415,8.696709,0.657186,-256.388214,0.066733,0.000000
51.810001,38.363304,-256.388214,-0.003113,0.002609,0.066256,170.648499,8.693249,0.662561,-256.388214,0.067401,0.000000
52.210003,38.819084,-256.388214,-0.003100,0.002637,0.066976,172.675903,8.796531,0.669760,-256.388214,0.068068,0.000000
52.610001,39.119965,-256.432678,-0.003078,0.002661,0.067583,174.014297,8.864711,0.675831,-256.432678,0.068736,0.000000
53.010002,41.111786,-256.477173,-0.003061,0.002698,0.068537,182.874359,9.316064,0.685369,-256.477173,0.069404,0.000000
53.410004,40.761383,-256.477173,-0.003061,0.002717,0.069005,181.315689,9.236662,0.690054,-256.477173,0.070072,0.000000
53.810001,41.316216,-256.521637,-0.003053,0.002743,0.069673,183.783707,9.362388,0.696731,-256.521637,0.070740,0.000000
54.210003,41.927277,-256.610596,-0.003040,0.002772,0.070410,186.501846,9.500856,0.704104,-256.610596,0.071407,0.000000
54.610004,42.091492,-256.521637,-0.003031,0.002795,0.070983,187.232300,9.538068,0.709827,-256.521637,0.072067,0.000000
55.010002,43.733658,-256.610596,-0.003022,0.002829,0.071867,194.537033,9.910189,0.718668,-256.610596,0.072734,0.000000
55.410004,43.433525,-256.655090,-0.003009,0.002849,0.072370,193.201965,9.842177,0.723702,-256.655090,0.073402,0.000000
55.810001,43.443207,-256.655090,-0.002988,0.002870,0.072890,193.245041,9.844372,0.728903,-256.655090,0.074070,0.000000
56.210003,44.689163,-256.699554,-0.002984,0.002903,0.073731,198.787323,10.126710,0.737313,-256.699554,0.074737,0.000000
56.610004,44.742043,-256.744049,-0.002984,0.002925,0.074287,199.022552,10.138692,0.742869,-256.744049,0.075405,0.000000
57.010002,46.199883,-256.833008,-0.002962,0.002959,0.075171,205.507339,10.469043,0.751710,-256.833008,0.076073,0.000000
57.410004,46.195786,-256.833008,-0.002945,0.002981,0.075718,205.489120,10.468115,0.757176,-256.833008,0.076741,0.000000
57.810001,46.673538,-256.833008,-0.002936,0.003010,0.076463,207.614273,10.576375,0.764632,-256.833008,0.077409,0.000000
58.210003,47.113686,-256.877502,-0.002936,0.003034,0.077070,209.572144,10.676114,0.770703,-256.877502,0.078068,0.000000
58.610004,47.186295,-256.877502,-0.002923,0.003056,0.077634,209.895126,10.692567,0.776343,-256.877502,0.078736,0.000000
59.010002,48.436348,-257.010925,-0.002923,0.003090,0.078484,215.455643,10.975833,0.784836,-257.010925,0.079403,0.000000
59.410004,48.369324,-256.966461,-0.002897,0.003111,0.079022,215.157501,10.960645,0.790218,-256.966461,0.080071,0.000000
59.810001,47.909073,-257.010925,-0.002902,0.003127,0.079421,213.110199,10.856352,0.794207,-257.010925,0.080739,0.000000
60.210003,49.183701,-257.055420,-0.002893,0.003161,0.080297,218.780029,11.145185,0.802965,-257.055420,0.081406,0.000000
60.610004,49.800720,-257.099884,-0.002871,0.003191,0.081060,221.524673,11.285005,0.810596,-257.099884,0.082074,0.000000
61.010002,50.892891,-257.099884,-0.002867,0.003220,0.081797,226.382889,11.532495,0.817969,-257.099884,0.082742,0.000000
61.410004,51.063438,-257.144379,-0.002850,0.003244,0.082395,227.141525,11.571140,0.823949,-257.144379,0.083401,0.000000
61.810001,50.832191,-257.188873,-0.002850,0.003266,0.082959,226.112885,11.518739,0.829588,-257.188873,0.084069,0.000000
62.210003,51.197495,-257.233337,-0.002815,0.003291,0.083583,227.737823,11.601519,0.835833,-257.233337,0.084737,0.000000
62.610004,51.610451,-257.233337,-0.002828,0.003316,0.084216,229.574753,11.695095,0.842162,-257.233337,0.085405,0.000000
63.010002,52.170876,-257.277832,-0.002807,0.003343,0.084901,232.067642,11.822089,0.849012,-257.277832,0.086072,0.000000
63.410004,53.073135,-257.322296,-0.002785,0.003372,0.085639,236.081100,12.026545,0.856385,-257.322296,0.086740,0.000000
63.810001,53.555725,-257.322296,-0.002781,0.003397,0.086280,238.227768,12.135901,0.862805,-257.322296,0.087408,0.000000
64.210007,54.040184,-257.322296,-0.002777,0.003423,0.086956,240.382751,12.245681,0.869564,-257.322296,0.088075,0.000000
64.610001,54.598366,-257.455750,-0.002759,0.003449,0.087598,242.865662,12.372167,0.875984,-257.455750,0.088735,0.000000
65.010002,55.003136,-257.411255,-0.002755,0.003480,0.088388,244.666168,12.463889,0.883879,-257.411255,0.089402,0.000000
65.410004,55.790703,-257.455750,-0.002742,0.003504,0.089003,248.169434,12.642354,0.890033,-257.455750,0.090070,0.000000
65.810005,55.865929,-257.544708,-0.002734,0.003525,0.089532,248.504059,12.659400,0.895324,-257.544708,0.090738,0.000000
66.210007,56.481827,-257.455750,-0.002721,0.003554,0.090270,251.243713,12.798965,0.902697,-257.455750,0.091405,0.000000
66.610001,57.586288,-257.633667,-0.002708,0.003585,0.091059,256.156616,13.049239,0.910585,-257.633667,0.092074,0.000000
67.010002,58.075958,-257.589172,-0.002690,0.003611,0.091718,258.334778,13.160200,0.917178,-257.589172,0.092741,0.000000
67.410004,58.524666,-257.633667,-0.002673,0.003636,0.092360,260.330719,13.261879,0.923598,-257.633667,0.093409,0.000000
67.810005,59.636566,-257.678162,-0.002665,0.003665,0.093080,265.276703,13.513839,0.930797,-257.678162,0.094068,0.000000
68.210007,59.673431,-257.722626,-0.002643,0.003687,0.093652,265.440674,13.522193,0.936519,-257.722626,0.094736,0.000000
68.610001,61.094032,-257.811584,-0.002639,0.003719,0.094467,271.759827,13.844105,0.944672,-257.811584,0.095404,0.000000
69.010002,61.652969,-257.811584,-0.002634,0.003743,0.095083,274.246094,13.970762,0.950826,-257.811584,0.096071,0.000000
69.410004,61.931503,-257.767120,-0.002617,0.003765,0.095637,275.485077,14.033879,0.956375,-257.767120,0.096739,0.000000
69.810005,62.845673,-257.900543,-0.002587,0.003792,0.096323,279.551514,14.241034,0.963225,-257.900543,0.097407,0.000000
70.210007,63.821297,-257.900543,-0.002587,0.003820,0.097034,283.891296,14.462112,0.970341,-257.900543,0.098074,0.000000
70.610001,65.109703,-257.900543,-0.002583,0.003849,0.097771,289.622437,14.754069,0.977706,-257.900543,0.098743,0.000000
71.010002,65.620216,-257.945038,-0.002565,0.003871,0.098317,291.893311,14.869754,0.983172,-257.945038,0.099410,0.000000
71.410004,65.126823,-257.989502,-0.002544,0.003874,0.098395,289.698578,14.757949,0.983952,-257.989502,0.017280,0.000000
71.810005,65.818703,-257.989502,-0.002527,0.003821,0.097042,292.776215,14.914731,0.970424,-257.989502,294.500488,0.000000
72.210007,65.175987,-258.033997,-0.002527,0.003908,0.099263,289.917267,14.769090,0.992627,-258.033997,294.500488,0.000000
72.610001,65.161461,-258.078491,-0.002527,0.003923,0.099653,289.852661,14.765799,0.996533,-258.078491,294.500488,0.000000
73.010002,64.965218,-258.033997,-0.002535,0.003935,0.099939,288.979706,14.721329,0.999394,-258.033997,294.500488,0.000000
73.410004,65.279503,-258.078491,-0.002518,0.003949,0.100304,290.377716,14.792547,1.003035,-258.078491,294.500488,0.000000
73.810005,65.868599,-258.122955,-0.002496,0.003964,0.100693,292.998169,14.926038,1.006933,-258.122955,294.500488,0.000000
74.210007,64.766747,-258.167450,-0.002488,0.003965,0.100702,288.096863,14.676355,1.007024,-258.167450,294.500488,0.000000
74.610001,65.275398,-258.211914,-0.002475,0.003975,0.100962,290.359467,14.791616,1.009621,-258.211914,294.500488,0.000000
75.010002,65.103737,-258.300873,-0.002471,0.003994,0.101440,289.595886,14.752718,1.014397,-258.300873,294.500488,0.000000
75.410004,65.152519,-258.256409,-0.002462,0.004001,0.101621,289.812866,14.763772,1.016214,-258.256409,294.500488,0.000000
75.810005,64.952934,-258.345367,-0.002466,0.004007,0.101786,288.925079,14.718545,1.017864,-258.345367,294.500488,0.000000
76.210007,65.228493,-258.345367,-0.002445,0.004021,0.102133,290.150818,14.780988,1.021331,-258.345367,294.500488,0.000000
76.610001,65.371483,-258.434326,-0.002449,0.004028,0.102306,290.786865,14.813390,1.023065,-258.434326,294.500488,0.000000
77.010002,65.309288,-258.478821,-0.002440,0.004034,0.102462,290.510223,14.799295,1.024624,-258.478821,294.500488,0.000000
77.410004,64.982719,-258.434326,-0.002436,0.004042,0.102671,289.057587,14.725295,1.026706,-258.434326,294.500488,0.000000
77.810005,65.089592,-258.523285,-0.002440,0.004048,0.102810,289.532959,14.749513,1.028099,-258.523285,294.500488,0.000000
78.210007,65.048637,-258.612244,-0.002423,0.004052,0.102931,289.350800,14.740232,1.029310,-258.612244,294.500488,0.000000
78.610001,65.085869,-258.567780,-0.002423,0.004058,0.103079,289.516418,14.748669,1.030786,-258.567780,294.500488,0.000000
79.010002,65.092567,-258.523285,-0.002414,0.004064,0.103226,289.546204,14.750187,1.032262,-258.523285,294.500488,0.000000
79.410004,64.675880,-258.656738,-0.002414,0.004067,0.103295,287.692688,14.655765,1.032951,-258.656738,294.500488,0.000000
79.810005,65.843651,-258.612244,-0.002397,0.004076,0.103538,292.887177,14.920384,1.035381,-258.612244,294.500488,0.000000
80.210007,65.215080,-258.745697,-0.002397,0.004077,0.103546,290.091156,14.777948,1.035464,-258.745697,294.500488,0.000000
80.610001,64.647957,-258.790161,-0.002402,0.004077,0.103546,287.568481,14.649437,1.035464,-258.790161,294.500488,0.000000
81.010002,66.432732,-258.834656,-0.002393,0.004006,0.101760,295.507538,15.053872,1.017599,-258.834656,294.500488,0.000000
81.410004,65.804543,-258.834656,-0.002384,0.004009,0.101830,292.713226,14.911522,1.018296,-258.834656,294.500488,0.000000
81.810005,65.365898,-258.790161,-0.002376,0.004061,0.103157,290.762024,14.812124,1.031566,-258.790161,294.500488,0.000000
82.210007,65.567345,-258.923615,-0.002380,0.004101,0.104171,291.658112,14.857773,1.041709,-258.923615,294.500488,0.000000
82.610001,65.214714,-258.923615,-0.002367,0.004103,0.104223,290.089539,14.777865,1.042231,-258.923615,294.500488,0.000000
83.010002,65.190498,-259.012573,-0.002371,0.004108,0.104344,289.981812,14.772378,1.043443,-259.012573,294.500488,0.000000
83.410004,65.255302,-258.968109,-0.002363,0.004112,0.104449,290.270081,14.787063,1.044487,-258.968109,294.500488,0.000000
83.810005,65.168541,-259.012573,-0.002363,0.004116,0.104544,289.884155,14.767403,1.045441,-259.012573,294.500488,0.000000
84.210007,65.133156,-259.057068,-0.002380,0.004120,0.104648,289.726746,14.759384,1.046478,-259.057068,294.500488,0.000000
84.610001,65.136131,-259.146027,-0.002363,0.004124,0.104752,289.739990,14.760058,1.047523,-259.146027,294.500488,0.000000
85.010002,65.233330,-259.146027,-0.002376,0.004127,0.104830,290.172333,14.782084,1.048302,-259.146027,294.500488,0.000000
85.410004,65.194969,-259.146027,-0.002350,0.004130,0.104900,290.001709,14.773392,1.048999,-259.146027,294.500488,0.000000
85.810005,65.326424,-259.234985,-0.002354,0.004135,0.105030,290.586456,14.803180,1.050301,-259.234985,294.500488,0.000000
86.210007,65.130180,-259.234985,-0.002358,0.004135,0.105038,289.713501,14.758710,1.050384,-259.234985,294.500488,0.000000
86.610001,65.299980,-259.234985,-0.002345,0.004141,0.105177,290.468811,14.797187,1.051769,-259.234985,294.500488,0.000000
87.010002,65.142464,-259.234985,-0.002358,0.004141,0.105186,289.768158,14.761494,1.051860,-259.234985,294.500488,0.000000
87.410004,65.672722,-259.323944,-0.002358,0.004150,0.105403,292.126862,14.881652,1.054025,-259.323944,294.500488,0.000000
87.810005,65.526390,-259.368439,-0.002341,0.004149,0.105394,291.475952,14.848493,1.053942,-259.368439,294.500488,0.000000
88.210007,65.278008,-259.412903,-0.002350,0.004149,0.105394,290.371094,14.792209,1.053942,-259.412903,294.500488,0.000000
88.610001,65.027412,-259.457397,-0.002354,0.004149,0.105394,289.256378,14.735423,1.053942,-259.457397,294.500488,0.000000
89.010002,64.798393,-259.501862,-0.002350,0.004150,0.105403,288.237640,14.683526,1.054025,-259.501862,294.500488,0.000000
89.410004,64.569008,-259.501862,-0.002345,0.004150,0.105403,287.217285,14.631547,1.054025,-259.501862,294.500488,0.000000
89.810005,66.467369,-259.546356,-0.002337,0.004119,0.104631,295.661621,15.061721,1.046311,-259.546356,294.500488,0.000000
90.210007,66.216393,-259.590820,-0.002333,0.004119,0.104631,294.545227,15.004849,1.046311,-259.590820,294.500488,0.000000
90.610001,65.947533,-259.590820,-0.002328,0.004120,0.104639,293.349274,14.943925,1.046395,-259.590820,294.500488,0.000000
91.010002,65.748695,-259.635315,-0.002337,0.004121,0.104683,292.464813,14.898868,1.046826,-259.635315,294.500488,0.000000
91.410004,65.533836,-259.679779,-0.002324,0.004134,0.105013,291.509064,14.850180,1.050127,-259.679779,294.500488,0.000000
91.810005,65.309669,-259.679779,-0.002328,0.004142,0.105203,290.511932,14.799383,1.052034,-259.679779,294.500488,0.000000
92.210007,65.297752,-259.724274,-0.002333,0.004166,0.105811,290.458923,14.796682,1.058105,-259.724274,294.500488,0.000000
92.610001,65.255669,-259.768768,-0.002324,0.004168,0.105879,290.271698,14.787147,1.058794,-259.768768,294.500488,0.000000
93.010002,65.285454,-259.813232,-0.002315,0.004171,0.105949,290.404205,14.793895,1.059491,-259.813232,294.500488,0.000000
93.410004,65.179710,-259.857727,-0.002341,0.004172,0.105966,289.933838,14.769934,1.059665,-259.857727,294.500488,0.000000
93.810005,65.134270,-259.813232,-0.002337,0.004174,0.106019,289.731689,14.759637,1.060187,-259.813232,294.500488,0.000000
94.210007,65.065392,-259.813232,-0.002333,0.004175,0.106044,289.425323,14.744028,1.060444,-259.813232,294.500488,0.000000
94.610008,65.250832,-259.946686,-0.002333,0.004181,0.106192,290.250183,14.786049,1.061920,-259.946686,294.500488,0.000000
95.010002,65.252312,-259.946686,-0.002341,0.004181,0.106192,290.256775,14.786386,1.061920,-259.946686,294.500488,0.000000
95.410004,65.102623,-259.946686,-0.002324,0.004181,0.106192,289.590942,14.752465,1.061920,-259.946686,294.500488,0.000000
95.810005,65.032997,-259.991150,-0.002311,0.004182,0.106226,289.281219,14.736689,1.062261,-259.991150,294.500488,0.000000
96.210007,65.120125,-260.035645,-0.002324,0.004185,0.106287,289.668793,14.756431,1.062874,-260.035645,294.500488,0.000000
96.610008,65.080284,-260.080109,-0.002320,0.004186,0.106322,289.491577,14.747403,1.063222,-260.080109,294.500488,0.000000
97.010002,65.237053,-260.080109,-0.002315,0.004190,0.106418,290.188904,14.782928,1.064176,-260.080109,294.500488,0.000000
97.410004,65.210243,-260.169098,-0.002315,0.004190,0.106418,290.069641,14.776852,1.064176,-260.169098,294.500488,0.000000
97.810005,65.110451,-260.169098,-0.002324,0.004190,0.106434,289.625763,14.754239,1.064343,-260.169098,294.500488,0.000000
98.210007,65.143959,-260.169098,-0.002324,0.004195,0.106564,289.774811,14.761832,1.065645,-260.169098,294.500488,0.000000
98.610008,65.352852,-260.213562,-0.002324,0.004196,0.106574,290.704010,14.809168,1.065736,-260.213562,294.500488,0.000000
99.010002,65.262001,-260.258057,-0.002320,0.004196,0.106574,290.299866,14.788581,1.065736,-260.258057,294.500488,0.000000
99.410004,65.160713,-260.347015,-0.002328,0.004196,0.106574,289.849335,14.765629,1.065736,-260.347015,294.500488,0.000000
99.810005,65.069862,-260.302521,-0.002311,0.004197,0.106608,289.445190,14.745041,1.066084,-260.302521,294.500488,0.000000
100.210007,65.041924,-260.347015,-0.002315,0.004198,0.106625,289.320923,14.738711,1.066250,-260.347015,294.500488,0.000000
100.610008,65.132408,-260.391479,-0.002320,0.004200,0.106686,289.723419,14.759214,1.066864,-260.391479,294.500488,0.000000
101.010002,65.047508,-260.435974,-0.002315,0.004200,0.106686,289.345764,14.739976,1.066864,-260.435974,294.500488,0.000000
101.410004,64.973412,-260.435974,-0.002311,0.004200,0.106686,289.016174,14.723186,1.066864,-260.435974,294.500488,0.000000
101.810005,65.941948,-260.480438,-0.002311,0.004212,0.106990,293.324432,14.942659,1.069899,-260.480438,294.500488,0.000000
102.210007,65.913658,-260.435974,-0.002298,0.004212,0.106990,293.198608,14.936248,1.069899,-260.435974,294.500488,0.000000
102.610008,65.851845,-260.569397,-0.002315,0.004212,0.106990,292.923645,14.922241,1.069899,-260.569397,294.500488,0.000000
103.010002,65.762840,-260.569397,-0.002307,0.004212,0.106990,292.527710,14.902072,1.069899,-260.569397,294.500488,0.000000
103.410004,65.649269,-260.613892,-0.002311,0.004212,0.106990,292.022522,14.876337,1.069899,-260.613892,294.500488,0.000000
103.810005,65.559898,-260.658386,-0.002311,0.004212,0.106990,291.625000,14.856086,1.069899,-260.658386,294.500488,0.000000
104.210007,65.467552,-260.702850,-0.002315,0.004212,0.106990,291.214203,14.835159,1.069899,-260.702850,294.500488,0.000000
104.610008,65.346153,-260.702850,-0.002294,0.004212,0.106990,290.674194,14.807650,1.069899,-260.702850,294.500488,0.000000
105.010002,65.251198,-260.702850,-0.002302,0.004212,0.106990,290.251831,14.786133,1.069899,-260.702850,294.500488,0.000000
105.410004,65.146568,-260.747345,-0.002311,0.004212,0.106990,289.786407,14.762424,1.069899,-260.747345,294.500488,0.000000
105.810005,65.039314,-260.791809,-0.002320,0.004212,0.106990,289.309326,14.738119,1.069899,-260.791809,294.500488,0.000000
106.210007,64.948830,-260.836304,-0.002298,0.004212,0.106990,288.906830,14.717615,1.069899,-260.836304,294.500488,0.000000
106.610008,64.842339,-260.836304,-0.002307,0.004213,0.106998,288.433136,14.693484,1.069982,-260.836304,294.500488,0.000000
107.010002,64.745888,-260.880768,-0.002307,0.004213,0.107007,288.004089,14.671628,1.070073,-260.880768,294.500488,0.000000
107.410004,64.643486,-260.925262,-0.002298,0.004213,0.107007,287.548584,14.648423,1.070073,-260.925262,294.500488,0.000000
107.810005,66.533653,-260.925262,-0.002294,0.004193,0.106513,295.956482,15.076741,1.065130,-260.925262,294.500488,0.000000
108.210007,66.392891,-260.969727,-0.002302,0.004193,0.106513,295.330322,15.044844,1.065130,-260.969727,294.500488,0.000000
108.610008,66.289375,-261.058716,-0.002281,0.004193,0.106513,294.869873,15.021387,1.065130,-261.058716,294.500488,0.000000
109.010002,66.157188,-261.058716,-0.002294,0.004193,0.106513,294.281860,14.991433,1.065130,-261.058716,294.500488,0.000000
109.410004,66.027229,-261.058716,-0.002289,0.004193,0.106513,293.703796,14.961985,1.065130,-261.058716,294.500488,0.000000
109.810005,65.902855,-261.103180,-0.002294,0.004193,0.106513,293.150543,14.933801,1.065130,-261.103180,294.500488,0.000000
110.210007,65.848488,-261.147675,-0.002272,0.004193,0.106513,292.908691,14.921480,1.065130,-261.147675,294.500488,0.000000
110.610008,65.756508,-261.147675,-0.002298,0.004194,0.106521,292.499542,14.900638,1.065213,-261.147675,294.500488,0.000000
111.010002,65.635857,-261.236633,-0.002281,0.004195,0.106547,291.962860,14.873298,1.065471,-261.236633,294.500488,0.000000
111.410004,65.567711,-261.236633,-0.002285,0.004195,0.106547,291.659760,14.857855,1.065471,-261.236633,294.500488,0.000000
111.810005,65.451530,-261.281097,-0.002294,0.004195,0.106556,291.142944,14.831529,1.065562,-261.281097,294.500488,0.000000
112.210007,65.347267,-261.325592,-0.002289,0.004195,0.106556,290.679169,14.807902,1.065562,-261.325592,294.500488,0.000000
112.610008,65.258278,-261.414551,-0.002289,0.004195,0.106556,290.283325,14.787737,1.065562,-261.414551,294.500488,0.000000
113.010002,65.189766,-261.325592,-0.002276,0.004195,0.106556,289.978577,14.772212,1.065562,-261.325592,294.500488,0.000000
113.410004,65.562874,-261.370056,-0.002294,0.004231,0.107467,291.638214,14.856759,1.074668,-261.370056,294.500488,0.000000
113.810005,65.523781,-261.459045,-0.002276,0.004231,0.107467,291.464325,14.847900,1.074668,-261.459045,294.500488,0.000000
114.210007,65.445580,-261.459045,-0.002281,0.004231,0.107467,291.116486,14.830180,1.074668,-261.459045,294.500488,0.000000
114.610008,65.355843,-261.503510,-0.002285,0.004231,0.107467,290.717316,14.809846,1.074668,-261.503510,294.500488,0.000000
115.010002,65.282112,-261.548004,-0.002281,0.004231,0.107467,290.389343,14.793138,1.074668,-261.548004,294.500488,0.000000
115.410004,65.228111,-261.548004,-0.002285,0.004231,0.107467,290.149139,14.780901,1.074668,-261.548004,294.500488,0.000000
115.810005,65.129814,-261.592468,-0.002272,0.004233,0.107510,289.711884,14.758627,1.075099,-261.592468,294.500488,0.000000
116.210007,65.524529,-261.592468,-0.002285,0.004238,0.107648,291.467651,14.848070,1.076485,-261.592468,294.500488,0.000000
116.610008,65.503304,-261.681427,-0.002281,0.004238,0.107648,291.373260,14.843261,1.076485,-261.681427,294.500488,0.000000
117.010002,65.458992,-261.725922,-0.002285,0.004238,0.107648,291.176147,14.833220,1.076485,-261.725922,294.500488,0.000000
117.410004,65.377434,-261.725922,-0.002276,0.004238,0.107648,290.813354,14.814738,1.076485,-261.725922,294.500488,0.000000
117.810005,65.314125,-261.681427,-0.002281,0.004238,0.107658,290.531738,14.800392,1.076576,-261.681427,294.500488,0.000000
118.210007,65.245995,-261.814880,-0.002289,0.004238,0.107658,290.228668,14.784953,1.076576,-261.814880,294.500488,0.000000
118.610008,65.202797,-261.814880,-0.002272,0.004238,0.107658,290.036530,14.775166,1.076576,-261.814880,294.500488,0.000000
119.010002,65.227364,-261.859344,-0.002281,0.004241,0.107710,290.145813,14.780732,1.077098,-261.859344,294.500488,0.000000
119.410004,65.210991,-261.903839,-0.002276,0.004241,0.107710,290.072968,14.777021,1.077098,-261.903839,294.500488,0.000000
119.810005,65.151405,-261.903839,-0.002272,0.004241,0.107710,289.807922,14.763519,1.077098,-261.903839,294.500488,0.000000
120.210007,65.100014,-262.037292,-0.002281,0.004241,0.107718,289.579315,14.751874,1.077181,-262.037292,294.500488,0.000000
120.610008,65.329399,-261.948334,-0.002272,0.004247,0.107866,290.599670,14.803853,1.078657,-261.948334,294.500488,0.000000
121.010002,65.400520,-261.992798,-0.002272,0.004247,0.107866,290.916046,14.819970,1.078657,-261.992798,294.500488,0.000000
121.410004,65.389351,-262.081757,-0.002268,0.004247,0.107866,290.866364,14.817439,1.078657,-262.081757,294.500488,0.000000
121.810005,65.337593,-262.081757,-0.002276,0.004247,0.107866,290.636139,14.805711,1.078657,-262.081757,294.500488,0.000000
122.210007,65.307060,-262.126251,-0.002264,0.004247,0.107866,290.500305,14.798792,1.078657,-262.126251,294.500488,0.000000
122.610008,65.257164,-262.081757,-0.002281,0.004247,0.107866,290.278351,14.787484,1.078657,-262.081757,294.500488,0.000000
123.010002,65.234077,-262.126251,-0.002272,0.004247,0.107874,290.175659,14.782253,1.078740,-262.126251,294.500488,0.000000
123.410004,65.182686,-262.215210,-0.002289,0.004247,0.107874,289.947083,14.770608,1.078740,-262.215210,294.500488,0.000000
123.810005,65.132408,-262.170715,-0.002268,0.004249,0.107917,289.723419,14.759214,1.079172,-262.170715,294.500488,0.000000
124.210007,65.263115,-262.170715,-0.002264,0.004250,0.107952,290.304840,14.788833,1.079520,-262.170715,294.500488,0.000000
124.610008,65.248970,-262.304169,-0.002268,0.004250,0.107961,290.241913,14.785628,1.079611,-262.304169,294.500488,0.000000
125.010002,65.255669,-262.259674,-0.002285,0.004251,0.107969,290.271698,14.787147,1.079694,-262.259674,294.500488,0.000000
125.410004,65.224388,-262.304169,-0.002255,0.004251,0.107969,290.132568,14.780058,1.079694,-262.304169,294.500488,0.000000
125.810005,65.206520,-262.348663,-0.002268,0.004251,0.107979,290.053101,14.776009,1.079785,-262.348663,294.500488,0.000000
126.210007,65.178581,-262.393127,-0.002272,0.004251,0.107987,289.928802,14.769677,1.079868,-262.393127,294.500488,0.000000
126.610008,65.158104,-262.437622,-0.002264,0.004252,0.107996,289.837708,14.765038,1.079959,-262.437622,294.500488,0.000000
127.010010,65.156990,-262.482086,-0.002264,0.004253,0.108030,289.832764,14.764785,1.080300,-262.482086,294.500488,0.000000
127.410004,65.174858,-262.482086,-0.002281,0.004253,0.108030,289.912262,14.768834,1.080300,-262.482086,294.500488,0.000000
127.810005,65.162575,-262.526581,-0.002259,0.004255,0.108082,289.857605,14.766050,1.080822,-262.526581,294.500488,0.000000
128.210007,65.254555,-262.526581,-0.002281,0.004255,0.108082,290.266754,14.786894,1.080822,-262.526581,294.500488,0.000000
128.610001,65.228111,-262.615540,-0.002264,0.004255,0.108082,290.149139,14.780901,1.080822,-262.615540,294.500488,0.000000
129.010010,65.203911,-262.704498,-0.002272,0.004255,0.108082,290.041473,14.775417,1.080822,-262.704498,294.500488,0.000000
129.410004,65.171135,-262.660004,-0.002259,0.004255,0.108082,289.895691,14.767991,1.080822,-262.660004,294.500488,0.000000
129.810013,65.156990,-262.704498,-0.002272,0.004256,0.108100,289.832764,14.764785,1.080996,-262.704498,294.500488,0.000000
130.210007,65.119759,-262.793457,-0.002272,0.004256,0.108109,289.667145,14.756349,1.081087,-262.793457,294.500488,0.000000
130.610001,65.159966,-262.793457,-0.002281,0.004258,0.108143,289.846008,14.765460,1.081428,-262.793457,294.500488,0.000000
131.010010,65.180077,-262.793457,-0.002268,0.004258,0.108152,289.935455,14.770016,1.081519,-262.793457,294.500488,0.000000
131.410004,65.153633,-262.793457,-0.002264,0.004258,0.108152,289.817841,14.764025,1.081519,-262.793457,294.500488,0.000000
131.810013,65.215446,-262.882416,-0.002281,0.004259,0.108187,290.092804,14.778031,1.081867,-262.882416,1681.640991,0.000000
132.210007,65.113792,-262.882416,-0.002255,0.004247,0.107866,289.640625,14.754995,1.078657,-262.882416,0.107658,0.000000
132.610001,65.006920,-262.926910,-0.002281,0.004227,0.107371,289.165222,14.730779,1.073714,-262.926910,0.106990,0.000000
133.010010,64.922768,-263.015869,-0.002268,0.004203,0.106747,288.790894,14.711709,1.067469,-263.015869,0.106322,0.000000
133.410004,64.835258,-263.015869,-0.002272,0.004182,0.106235,288.401642,14.691880,1.062352,-263.015869,0.105654,0.000000
133.810013,64.775307,-263.060333,-0.002268,0.004158,0.105611,288.134949,14.678294,1.056107,-263.060333,0.104986,0.000000
134.210007,64.697487,-263.060333,-0.002268,0.004128,0.104848,287.788788,14.660660,1.048476,-263.060333,0.104319,0.000000
134.610001,64.607002,-263.060333,-0.002272,0.004101,0.104153,287.386292,14.640156,1.041535,-263.060333,0.103659,0.000000
135.010010,64.563423,-263.060333,-0.002255,0.004075,0.103495,287.192444,14.630281,1.034949,-263.060333,0.102992,0.000000
135.410004,64.426399,-263.104828,-0.002259,0.004048,0.102827,286.582947,14.599231,1.028273,-263.104828,0.102324,0.000000
135.810013,64.216743,-263.193787,-0.002264,0.004031,0.102384,285.650330,14.551723,1.023844,-263.193787,0.101656,0.000000
136.210007,63.419868,-263.282745,-0.002264,0.004004,0.101699,282.105652,14.371148,1.016994,-263.282745,0.100989,0.000000
136.610001,62.376854,-263.327240,-0.002259,0.003978,0.101049,277.466095,14.134797,1.010491,-263.327240,0.100321,0.000000
137.010010,60.865028,-263.282745,-0.002259,0.003952,0.100372,270.741180,13.792212,1.003724,-263.282745,0.099653,0.000000
137.410004,59.223610,-263.327240,-0.002233,0.003926,0.099722,263.439789,13.420262,0.997221,-263.327240,0.098985,0.000000
137.810013,57.905411,-263.371704,-0.002233,0.003910,0.099315,257.576141,13.121553,0.993149,-263.371704,0.098326,0.000000
138.210007,56.276283,-263.460663,-0.002242,0.003890,0.098794,250.329407,12.752388,0.987941,-263.460663,0.097659,0.000000
138.610001,53.616425,-263.416199,-0.002242,0.003858,0.098005,238.497772,12.149655,0.980053,-263.416199,0.096990,0.000000
139.010010,50.904808,-263.505157,-0.002233,0.003829,0.097268,226.435898,11.535194,0.972680,-263.505157,0.096323,0.000000
139.410004,48.162659,-263.460663,-0.002225,0.003803,0.096600,214.238205,10.913815,0.966004,-263.460663,0.095655,0.000000
139.810013,46.008484,-263.549622,-0.002229,0.003785,0.096149,204.655960,10.425672,0.961492,-263.549622,0.094987,0.000000
140.210007,42.977745,-263.505157,-0.002233,0.003756,0.095412,191.174561,9.738896,0.954119,-263.505157,0.094320,0.000000
140.610001,39.780182,-263.594116,-0.002238,0.003726,0.094649,176.951080,9.014318,0.946489,-263.594116,0.093652,0.000000
141.010010,36.876419,-263.638611,-0.002233,0.003700,0.093981,164.034500,8.356317,0.939812,-263.638611,0.092984,0.000000
141.410004,34.125328,-263.683075,-0.002238,0.003673,0.093296,151.797043,7.732910,0.932961,-263.683075,0.092325,0.000000
141.810013,31.763000,-263.683075,-0.002229,0.003654,0.092802,141.288879,7.197598,0.928018,-263.683075,0.091657,0.000000
142.210007,28.859238,-263.683075,-0.002246,0.003625,0.092082,128.372299,6.539597,0.920820,-263.683075,0.090990,0.000000
142.610001,25.498207,-263.772034,-0.002233,0.003594,0.091284,113.421692,5.777977,0.912841,-263.772034,0.090321,0.000000
143.010010,22.372513,-263.772034,-0.002229,0.003567,0.090591,99.517906,5.069684,0.905907,-263.772034,0.089654,0.000000
143.410004,19.920441,-263.816528,-0.002242,0.003543,0.089992,88.610542,4.514036,0.899919,-263.816528,0.088986,0.000000
143.810013,17.130623,-263.905487,-0.002229,0.003517,0.089324,76.200813,3.881855,0.893243,-263.905487,0.088318,0.000000
144.210007,15.136940,-263.860992,-0.002238,0.003502,0.088960,67.332474,3.430079,0.889602,-263.860992,0.087651,0.000000
144.610001,11.534241,-263.905487,-0.002229,0.003466,0.088032,51.306866,2.613696,0.880321,-263.905487,0.086991,0.000000
145.010010,8.439079,-263.949951,-0.002225,0.003437,0.087304,37.538898,1.912323,0.873039,-263.949951,0.086324,0.000000
145.410004,5.469780,-263.994446,-0.002238,0.003409,0.086592,24.330797,1.239470,0.865923,-263.994446,0.085656,0.000000
145.810013,3.238152,-263.994446,-0.002233,0.003386,0.085994,14.404017,0.733776,0.859943,-263.994446,0.084988,0.000000
146.210007,0.899651,-264.038940,-0.002233,0.003360,0.085335,4.001846,0.203864,0.853350,-264.038940,0.084321,0.000000
146.610001,-2.004108,-264.038940,-0.002238,0.003329,0.084545,-8.914720,-0.454137,0.845455,-264.038940,0.083652,0.000000
147.010010,-3.490990,-264.083405,-0.002229,0.003307,0.084008,-15.528698,-0.791070,0.840080,-264.083405,0.082985,0.000000
147.410004,-0.170547,-264.127899,-0.002229,0.003281,0.083340,-0.758633,-0.038647,0.833404,-264.127899,0.082317,0.000000
147.810013,-0.045799,-264.216858,-0.002225,0.003252,0.082612,-0.203725,-0.010378,0.826121,-264.216858,0.081658,0.000000
148.210007,0.032028,-264.216858,-0.002225,0.003233,0.082126,0.142469,0.007258,0.821262,-264.216858,0.080990,0.000000
148.610001,-0.037239,-264.261322,-0.002225,0.003197,0.081198,-0.165648,-0.008438,0.811981,-264.261322,0.080322,0.000000
149.010010,-0.002975,-264.305817,-0.002220,0.003170,0.080530,-0.013236,-0.000674,0.805305,-264.305817,0.079655,0.000000
149.410004,0.001122,-264.305817,-0.002220,0.003150,0.080019,0.004989,0.000254,0.800187,-264.305817,0.078987,0.000000
149.810013,-0.005585,-264.350281,-0.002225,0.003119,0.079213,-0.024842,-0.001266,0.792126,-264.350281,0.078319,0.000000
150.210007,-0.017128,-264.350281,-0.002220,0.003092,0.078536,-0.076189,-0.003881,0.785358,-264.350281,0.077652,0.000000
150.610001,-0.007072,-264.394775,-0.002216,0.003066,0.077877,-0.031460,-0.001603,0.778772,-264.394775,0.076983,0.000000
151.010010,-0.035744,-264.483734,-0.002207,0.003038,0.077166,-0.158996,-0.008100,0.771657,-264.483734,0.076325,0.000000
151.410004,0.011169,-264.439240,-0.002212,0.003026,0.076862,0.049684,0.002531,0.768621,-264.439240,0.075657,0.000000
151.810013,-0.005959,-264.528229,-0.002203,0.002989,0.075926,-0.026505,-0.001350,0.759257,-264.528229,0.074989,0.000000
152.210007,-0.021225,-264.483734,-0.002207,0.002968,0.075388,-0.094413,-0.004810,0.753883,-264.483734,0.074321,0.000000
152.610001,0.003357,-264.528229,-0.002190,0.002935,0.074547,0.014932,0.000761,0.745465,-264.528229,0.073653,0.000000
153.010010,-0.003349,-264.572693,-0.002203,0.002908,0.073853,-0.014898,-0.000759,0.738531,-264.572693,0.072986,0.000000
153.410004,-0.014893,-264.661652,-0.002199,0.002889,0.073376,-0.066245,-0.003375,0.733762,-264.661652,0.072318,0.000000
153.810013,-0.016754,-264.661652,-0.002203,0.002859,0.072622,-0.074526,-0.003797,0.726215,-264.661652,0.071650,0.000000
154.210007,-0.032768,-264.706146,-0.002199,0.002832,0.071927,-0.145760,-0.007425,0.719274,-264.706146,0.070983,0.000000
154.610001,-0.035370,-264.706146,-0.002186,0.002806,0.071269,-0.157333,-0.008015,0.712688,-264.706146,0.070323,0.000000
155.010010,-0.058464,-264.795105,-0.002195,0.002781,0.070635,-0.260061,-0.013248,0.706352,-264.795105,0.069656,0.000000
155.410004,-0.053246,-264.750610,-0.002203,0.002754,0.069950,-0.236848,-0.012066,0.699502,-264.750610,0.068988,0.000000
155.810013,-0.031281,-264.839569,-0.002216,0.002729,0.069309,-0.139143,-0.007088,0.693090,-264.839569,0.068320,0.000000
156.210007,-0.057343,-264.839569,-0.002233,0.002696,0.068485,-0.255072,-0.012994,0.684846,-264.839569,0.067652,0.000000
156.610001,-0.039841,-264.884064,-0.002229,0.002675,0.067938,-0.177220,-0.009028,0.679381,-264.884064,0.066984,0.000000
157.010010,-0.059204,-264.928558,-0.002264,0.002649,0.067280,-0.263353,-0.013416,0.672795,-264.928558,0.066317,0.000000
157.410004,-0.048035,-264.973022,-0.002276,0.002622,0.066603,-0.213669,-0.010885,0.666028,-264.973022,0.065649,0.000000
157.810013,-0.032021,-264.973022,-0.002289,0.002596,0.065943,-0.142435,-0.007256,0.659435,-264.973022,0.064990,0.000000
158.210007,-0.066284,-265.017517,-0.002302,0.002566,0.065180,-0.294847,-0.015020,0.651804,-265.017517,0.064322,0.000000
158.610001,-0.047661,-265.106476,-0.002324,0.002543,0.064582,-0.212006,-0.010800,0.645824,-265.106476,0.063654,0.000000
159.010010,-0.045052,-265.061981,-0.002341,0.002516,0.063906,-0.200399,-0.010209,0.639057,-265.061981,0.062987,0.000000
159.410004,-0.050270,-265.106476,-0.002350,0.002494,0.063342,-0.223612,-0.011391,0.633425,-265.106476,0.062319,0.000000
159.810013,-0.043564,-265.150940,-0.002363,0.002471,0.062769,-0.193782,-0.009872,0.627695,-265.150940,0.061651,0.000000
160.210007,-0.036491,-265.195435,-0.002380,0.002436,0.061876,-0.162322,-0.008269,0.618762,-265.195435,0.060983,0.000000
160.610001,-0.048782,-265.195435,-0.002423,0.002408,0.061157,-0.216995,-0.011054,0.611571,-265.195435,0.060315,0.000000
161.010010,-0.026062,-265.239899,-0.002445,0.002387,0.060636,-0.115930,-0.005906,0.606363,-265.239899,0.059657,0.000000
161.410004,-0.043938,-265.239899,-0.002462,0.002366,0.060107,-0.195445,-0.009956,0.601072,-265.239899,0.058988,0.000000
161.810013,-0.032768,-265.284393,-0.002483,0.002334,0.059284,-0.145760,-0.007425,0.592836,-265.284393,0.058321,0.000000
162.210007,-0.028297,-265.373352,-0.002531,0.002306,0.058573,-0.125873,-0.006412,0.585728,-265.373352,0.057653,0.000000
162.610001,-0.039467,-265.328888,-0.002539,0.002280,0.057922,-0.175557,-0.008943,0.579218,-265.328888,0.056985,0.000000
163.010010,-0.055855,-265.373352,-0.002544,0.002256,0.057306,-0.248455,-0.012657,0.573063,-265.373352,0.056318,0.000000
163.410004,-0.055855,-265.462311,-0.002587,0.002230,0.056647,-0.248455,-0.012657,0.566470,-265.462311,0.055650,0.000000
163.810013,-0.037979,-265.506805,-0.002626,0.002199,0.055858,-0.168940,-0.008606,0.558582,-265.506805,0.054982,0.000000
164.210007,-0.032394,-265.551270,-0.002643,0.002173,0.055199,-0.144098,-0.007341,0.551989,-265.551270,0.054323,0.000000
164.610001,-0.045425,-265.551270,-0.002660,0.002154,0.054722,-0.202062,-0.010294,0.547220,-265.551270,0.053655,0.000000
165.010010,-0.033882,-265.640228,-0.002703,0.002122,0.053907,-0.150715,-0.007678,0.539067,-265.640228,0.052988,0.000000
165.410004,-0.040588,-265.640228,-0.002725,0.002098,0.053291,-0.180546,-0.009197,0.532913,-265.640228,0.052319,0.000000
165.810013,-0.015640,-265.640228,-0.002742,0.002073,0.052658,-0.069571,-0.003544,0.526577,-265.640228,0.052519,0.000000
166.000015,-0.017128,-265.684723,-0.002755,0.002073,0.052667,-0.076189,-0.003881,0.526668,-265.684723,0.052519,0.000000