File: Data/compression 19/AutoNoHeating-17-19-reverse-1-2_09112024_155438.csv
Time (sec),S:Load (lbs),S:HL1 (DIM),S:LVDT (in),S:Position (in),Ch:Position (mm),Ch:Load (N),Ch:Stress (MPa),Ch:Strain (mm/mm),Ch:HL1 (DIM),Set Point (),Cycles ()
0.210000,-0.029045,-151.546600,-0.010158,-0.005404,-0.137265,-0.129199,-0.006582,-1.372645,-151.546600,-0.137047,0.000000
0.580000,0.002609,-151.591080,-0.010149,-0.005307,-0.134810,0.011607,0.000591,-1.348096,-151.591080,-0.133856,0.000000
0.950000,-0.001862,-151.591080,-0.009977,-0.005073,-0.128852,-0.008281,-0.000422,-1.288522,-151.591080,-0.127681,0.000000
1.320000,-0.014145,-151.635559,-0.009727,-0.004828,-0.122625,-0.062920,-0.003205,-1.226253,-151.635559,-0.121524,0.000000
1.690000,-0.001488,-151.724518,-0.009481,-0.004589,-0.116555,-0.006618,-0.000337,-1.165551,-151.724518,-0.115367,0.000000
2.060000,-0.024200,-151.813492,-0.009248,-0.004348,-0.110432,-0.107649,-0.005484,-1.104319,-151.813492,-0.109192,0.000000
2.430000,-0.077827,-151.857971,-0.008985,-0.004102,-0.104197,-0.346194,-0.017636,-1.041966,-151.857971,-0.103035,0.000000
2.800000,-0.036865,-151.813492,-0.008735,-0.003860,-0.098048,-0.163985,-0.008354,-0.980485,-151.813492,-0.096860,0.000000
3.170000,0.018990,-151.902451,-0.008489,-0.003615,-0.091813,0.084470,0.004303,-0.918132,-151.902451,-0.090703,0.000000
3.540000,0.020851,-151.991409,-0.008244,-0.003380,-0.085847,0.092750,0.004725,-0.858467,-151.991409,-0.084545,0.000000
3.910000,-0.016754,-152.035889,-0.007998,-0.003137,-0.079672,-0.074526,-0.003797,-0.796720,-152.035889,-0.078371,0.000000
4.280000,-0.004837,-152.124847,-0.007739,-0.002893,-0.073488,-0.021516,-0.001096,-0.734883,-152.124847,-0.072214,0.000000
4.650000,-0.017502,-152.124847,-0.007493,-0.002649,-0.067296,-0.077852,-0.003966,-0.672962,-152.124847,-0.066039,0.000000
5.020000,-0.006699,-152.213821,-0.007235,-0.002406,-0.061104,-0.029797,-0.001518,-0.611041,-152.213821,-0.059882,0.000000
5.390000,-0.001862,-152.213821,-0.006985,-0.002161,-0.054886,-0.008281,-0.000422,-0.548863,-152.213821,-0.053724,0.000000
5.760000,-0.012283,-152.258301,-0.006739,-0.001922,-0.048807,-0.054639,-0.002783,-0.488070,-152.258301,-0.047550,0.000000
6.130000,-0.029419,-152.391739,-0.006493,-0.001678,-0.042615,-0.130862,-0.006666,-0.426149,-152.391739,-0.041392,0.000000
6.500000,-0.052132,-152.391739,-0.006226,-0.001432,-0.036371,-0.231893,-0.011813,-0.363713,-152.391739,-0.035218,0.000000
6.870000,-0.033508,-152.347260,-0.005984,-0.001188,-0.030179,-0.149052,-0.007593,-0.301792,-152.347260,-0.029060,0.000000
7.240000,0.010803,-152.436218,-0.005747,-0.000948,-0.024092,0.048055,0.002448,-0.240916,-152.436218,-0.022903,0.000000
7.610000,0.022720,-152.525177,-0.005497,-0.000709,-0.018003,0.101065,0.005149,-0.180032,-152.525177,-0.016728,0.000000
7.980000,0.011169,-152.569656,-0.005247,-0.000468,-0.011881,0.049684,0.002531,-0.118808,-152.569656,-0.010571,0.000000
8.350000,-0.005959,-152.569656,-0.004984,-0.000225,-0.005714,-0.026505,-0.001350,-0.057144,-152.569656,-0.004397,0.000000
8.720000,-0.000374,-152.614136,-0.004738,0.000021,0.000521,-0.001663,-0.000085,0.005208,-152.614136,0.001761,0.000000
9.090000,0.159004,-152.614136,-0.004596,-0.000000,-0.000008,0.707286,0.036031,-0.000083,-152.614136,0.000191,0.000000
9.460000,0.148949,-152.747589,-0.004596,-0.000001,-0.000017,0.662557,0.033752,-0.000174,-152.747589,0.000191,0.000000
9.830001,0.134056,-152.836548,-0.004587,-0.000001,-0.000017,0.596311,0.030378,-0.000174,-152.836548,0.000780,0.000000
10.200001,0.156029,-152.925507,-0.004587,0.000012,0.000304,0.694051,0.035357,0.003035,-152.925507,0.001397,0.000000
10.570001,0.494141,-152.881027,-0.004562,0.000044,0.001110,2.198047,0.111974,0.011105,-152.881027,0.002012,0.000000
10.940001,0.692245,-152.881027,-0.004549,0.000065,0.001640,3.079262,0.156865,0.016396,-152.881027,0.002628,0.000000
11.310000,1.107063,-152.969986,-0.004536,0.000089,0.002264,4.924463,0.250864,0.022641,-152.969986,0.003244,0.000000
11.680000,1.375916,-153.058960,-0.004506,0.000106,0.002689,6.120378,0.311787,0.026888,-153.058960,0.003859,0.000000
12.050000,1.779572,-153.103439,-0.004480,0.000131,0.003322,7.915929,0.403257,0.033216,-153.103439,0.004475,0.000000
12.420001,2.549637,-153.103439,-0.004445,0.000166,0.004224,11.341352,0.577756,0.042239,-153.103439,0.005091,0.000000
12.790001,2.907486,-153.147919,-0.004437,0.000186,0.004736,12.933144,0.658846,0.047357,-153.147919,0.005707,0.000000
13.160001,3.438118,-153.236877,-0.004424,0.000209,0.005308,15.293512,0.779089,0.053079,-153.236877,0.006331,0.000000
13.530001,4.049553,-153.325836,-0.004402,0.000235,0.005976,18.013311,0.917642,0.059756,-153.325836,0.006947,0.000000
13.900001,4.413361,-153.370316,-0.004389,0.000254,0.006452,19.631609,1.000082,0.064525,-153.370316,0.007562,0.000000
14.270000,5.164062,-153.370316,-0.004363,0.000284,0.007207,22.970898,1.170193,0.072072,-153.370316,0.008178,0.000000
14.640000,5.689850,-153.414795,-0.004350,0.000308,0.007832,25.309715,1.289338,0.078317,-153.414795,0.008794,0.000000
15.010001,6.133347,-153.503769,-0.004320,0.000332,0.008430,27.282488,1.389836,0.084297,-153.503769,0.009410,0.000000
15.380001,6.773827,-153.548248,-0.004307,0.000358,0.009097,30.131485,1.534971,0.090974,-153.548248,0.010025,0.000000
15.750001,7.127953,-153.592728,-0.004268,0.000377,0.009574,31.706717,1.615217,0.095743,-153.592728,0.010641,0.000000
16.120001,7.812004,-153.637207,-0.004247,0.000403,0.010242,34.749531,1.770226,0.102419,-153.637207,0.011257,0.000000
16.490002,8.415619,-153.681686,-0.004230,0.000429,0.010901,37.434544,1.907007,0.109013,-153.681686,0.011882,0.000000
16.860001,8.873634,-153.681686,-0.004221,0.000453,0.011517,39.471897,2.010794,0.115167,-153.681686,0.012497,0.000000
17.230001,9.294418,-153.815125,-0.004195,0.000477,0.012115,41.343639,2.106145,0.121154,-153.815125,0.013112,0.000000
17.600000,9.763977,-153.770645,-0.004165,0.000499,0.012670,43.432339,2.212549,0.126703,-153.770645,0.013729,0.000000
17.970001,10.209709,-153.859604,-0.004156,0.000521,0.013243,45.415054,2.313553,0.132426,-153.859604,0.014344,0.000000
18.340000,11.120903,-153.904083,-0.004122,0.000552,0.014023,49.468246,2.520033,0.140230,-153.904083,0.014960,0.000000
18.710001,11.343956,-153.948578,-0.004096,0.000577,0.014648,50.460438,2.570577,0.146475,-153.948578,0.015576,0.000000
19.080002,11.953529,-154.037537,-0.004087,0.000603,0.015315,53.171955,2.708709,0.153152,-154.037537,0.016191,0.000000
19.450001,12.214561,-154.082016,-0.004057,0.000623,0.015827,54.333084,2.767859,0.158269,-154.082016,0.016807,0.000000
19.820002,12.471870,-154.037537,-0.004036,0.000639,0.016235,55.477650,2.826166,0.162349,-154.037537,0.017432,0.000000
20.190001,13.442276,-154.126495,-0.004027,0.000672,0.017076,59.794231,3.046063,0.170759,-154.126495,0.018047,0.000000
20.560001,13.792305,-154.215454,-0.003997,0.000697,0.017709,61.351238,3.125381,0.177088,-154.215454,0.018663,0.000000
20.930000,14.007164,-154.304413,-0.003980,0.000719,0.018255,62.306976,3.174069,0.182553,-154.304413,0.019279,0.000000
21.300001,14.617859,-154.304413,-0.003958,0.000742,0.018854,65.023483,3.312454,0.188541,-154.304413,0.019894,0.000000
21.670000,14.739990,-154.348907,-0.003932,0.000759,0.019279,65.566750,3.340130,0.192787,-154.348907,0.020510,0.000000
22.040001,15.948715,-154.348907,-0.003911,0.000797,0.020242,70.943428,3.614031,0.202416,-154.348907,0.021126,0.000000
22.410002,15.943130,-154.437866,-0.003902,0.000816,0.020719,70.918587,3.612765,0.207185,-154.437866,0.021742,0.000000
22.780001,16.266350,-154.437866,-0.003867,0.000838,0.021282,72.356339,3.686007,0.212817,-154.437866,0.022366,0.000000
23.150002,16.900497,-154.482346,-0.003842,0.000868,0.022054,75.177170,3.829707,0.220538,-154.482346,0.022982,0.000000
23.520000,17.053543,-154.526825,-0.003816,0.000887,0.022522,75.857948,3.864388,0.225224,-154.526825,0.023597,0.000000
23.890001,18.127838,-154.526825,-0.003803,0.000921,0.023381,80.636650,4.107827,0.233808,-154.526825,0.024213,0.000000
24.260000,17.985962,-154.615784,-0.003786,0.000939,0.023840,80.005554,4.075677,0.238403,-154.615784,0.024829,0.000000
24.630001,18.238060,-154.704742,-0.003760,0.000962,0.024439,81.126945,4.132803,0.244391,-154.704742,0.025444,0.000000
25.000002,18.334877,-154.749222,-0.003734,0.000983,0.024967,81.557610,4.154743,0.249674,-154.749222,0.026061,0.000000
25.370001,18.852478,-154.749222,-0.003708,0.001004,0.025497,83.860008,4.272033,0.254966,-154.749222,0.026676,0.000000
25.740002,19.077019,-154.793716,-0.003704,0.001028,0.026113,84.858818,4.322914,0.261127,-154.793716,0.027292,0.000000
26.110001,20.173653,-154.793716,-0.003669,0.001062,0.026979,89.736885,4.571415,0.269795,-154.793716,0.027917,0.000000
26.480001,20.197113,-154.882675,-0.003652,0.001085,0.027561,89.841248,4.576731,0.275608,-154.882675,0.028532,0.000000
26.850000,20.569855,-155.016113,-0.003622,0.001108,0.028151,91.499283,4.661196,0.281505,-155.016113,0.029147,0.000000
27.220001,20.724388,-154.927155,-0.003591,0.001128,0.028662,92.186684,4.696213,0.286623,-154.927155,0.029764,0.000000
27.590002,21.111656,-155.016113,-0.003591,0.001154,0.029304,93.909340,4.783970,0.293042,-155.016113,0.030379,0.000000
27.960001,21.928642,-155.149551,-0.003553,0.001186,0.030136,97.543472,4.969101,0.301361,-155.149551,0.030995,0.000000
28.330002,21.787140,-155.194031,-0.003527,0.001206,0.030622,96.914040,4.937037,0.306221,-155.194031,0.031611,0.000000
28.700001,21.937210,-155.238525,-0.003523,0.001226,0.031134,97.581581,4.971043,0.311338,-155.238525,0.032226,0.000000
29.070002,22.655518,-155.283005,-0.003484,0.001255,0.031879,100.776772,5.133813,0.318794,-155.283005,0.032842,0.000000
29.440001,22.814514,-155.283005,-0.003475,0.001275,0.032383,101.484024,5.169843,0.323828,-155.283005,0.033467,0.000000
29.810001,23.678795,-155.327484,-0.003441,0.001309,0.033250,105.328537,5.365692,0.332495,-155.327484,0.034082,0.000000
30.180002,23.452019,-155.416443,-0.003423,0.001328,0.033744,104.319786,5.314303,0.337439,-155.416443,0.034698,0.000000
30.550001,23.610275,-155.416443,-0.003410,0.001350,0.034290,105.023750,5.350165,0.342904,-155.416443,0.035314,0.000000
30.920002,24.064575,-155.460922,-0.003363,0.001375,0.034932,107.044579,5.453111,0.349323,-155.460922,0.035929,0.000000
31.290001,23.908173,-155.460922,-0.003359,0.001389,0.035287,106.348862,5.417669,0.352873,-155.460922,0.036545,0.000000
31.660002,24.224693,-155.594360,-0.003333,0.001416,0.035973,107.756821,5.489394,0.359732,-155.594360,0.037161,0.000000
32.030003,25.306808,-155.638855,-0.003303,0.001450,0.036822,112.570305,5.734605,0.368225,-155.638855,0.037776,0.000000
32.400002,25.289307,-155.727814,-0.003285,0.001469,0.037317,112.492455,5.730639,0.373168,-155.727814,0.038392,0.000000
32.770000,25.953621,-155.727814,-0.003247,0.001498,0.038046,115.447472,5.881175,0.380458,-155.727814,0.039017,0.000000
33.140003,25.701897,-155.727814,-0.003234,0.001514,0.038453,114.327744,5.824133,0.384530,-155.727814,0.039632,0.000000
33.510002,25.548851,-155.861252,-0.003221,0.001529,0.038826,113.646965,5.789453,0.388262,-155.861252,0.040249,0.000000
33.880001,27.123985,-155.905731,-0.003208,0.001570,0.039884,120.653511,6.146383,0.398837,-155.905731,0.040864,0.000000
34.250000,27.110207,-155.950211,-0.003186,0.001593,0.040465,120.592224,6.143260,0.404651,-155.950211,0.041479,0.000000
34.620003,27.640839,-155.950211,-0.003147,0.001619,0.041124,122.952591,6.263504,0.411244,-155.950211,0.042096,0.000000
34.990002,27.478485,-156.039169,-0.003122,0.001640,0.041653,122.230408,6.226714,0.416528,-156.039169,0.042711,0.000000
35.360001,28.234772,-156.083664,-0.003109,0.001667,0.042347,125.594536,6.398090,0.423469,-156.083664,0.043327,0.000000
35.730003,28.523735,-156.128143,-0.003083,0.001691,0.042954,126.879913,6.463571,0.429540,-156.128143,0.043943,0.000000
36.100002,29.056595,-156.217102,-0.003065,0.001717,0.043604,129.250183,6.584318,0.436043,-156.217102,0.044567,0.000000
36.470001,29.493019,-156.217102,-0.003035,0.001741,0.044211,131.191498,6.683214,0.442114,-156.217102,0.045183,0.000000
36.840000,29.571213,-156.261581,-0.003005,0.001763,0.044784,131.539322,6.700933,0.447836,-156.261581,0.045799,0.000000
37.210003,29.703407,-156.306061,-0.002992,0.001784,0.045313,132.127350,6.730888,0.453128,-156.306061,0.046414,0.000000
37.580002,30.761688,-156.395020,-0.002984,0.001815,0.046102,136.834824,6.970698,0.461023,-156.395020,0.047030,0.000000
37.950001,30.996658,-156.439499,-0.002945,0.001838,0.046692,137.880020,7.023943,0.466920,-156.439499,0.047646,0.000000
38.320004,31.260300,-156.439499,-0.002910,0.001859,0.047221,139.052765,7.083685,0.472211,-156.439499,0.048261,0.000000
38.690002,31.659851,-156.483978,-0.002902,0.001884,0.047845,140.830048,7.174225,0.478449,-156.483978,0.048877,0.000000
39.060001,31.640114,-156.572952,-0.002880,0.001906,0.048417,140.742249,7.169752,0.484171,-156.572952,0.049493,0.000000
39.430000,32.784416,-156.572952,-0.002863,0.001932,0.049068,145.832367,7.429055,0.490681,-156.572952,0.050117,0.000000
39.800003,33.286377,-156.661911,-0.002833,0.001960,0.049788,148.065201,7.542801,0.497880,-156.661911,0.050733,0.000000
40.170002,33.841583,-156.661911,-0.002833,0.001985,0.050429,150.534882,7.668612,0.504292,-156.661911,0.051349,0.000000
40.540001,34.349503,-156.661911,-0.002785,0.002010,0.051063,152.794220,7.783709,0.510628,-156.661911,0.051964,0.000000
40.910004,34.046013,-156.795349,-0.002785,0.002028,0.051505,151.444229,7.714937,0.515049,-156.795349,0.052581,0.000000
41.280003,34.414665,-156.795349,-0.002764,0.002049,0.052051,153.084076,7.798475,0.520514,-156.795349,0.053196,0.000000
41.650002,35.638283,-156.884308,-0.002725,0.002079,0.052814,158.526993,8.075750,0.528144,-156.884308,0.053811,0.000000
42.020000,36.000969,-156.928802,-0.002703,0.002103,0.053404,160.140305,8.157936,0.534041,-156.928802,0.054428,0.000000
42.390003,36.253441,-156.928802,-0.002673,0.002123,0.053916,161.263351,8.215147,0.539158,-156.928802,0.055043,0.000000
42.760002,36.740501,-156.973282,-0.002665,0.002148,0.054558,163.429916,8.325517,0.545577,-156.973282,0.055667,0.000000
43.130001,37.450989,-157.062241,-0.002660,0.002172,0.055181,166.590317,8.486515,0.551815,-157.062241,0.056283,0.000000
43.500004,38.332024,-157.106720,-0.002643,0.002200,0.055867,170.509354,8.686160,0.558673,-157.106720,0.056899,0.000000
43.870003,38.889839,-157.151199,-0.002608,0.002225,0.056518,172.990646,8.812564,0.565176,-157.151199,0.057515,0.000000
44.240002,39.599205,-157.151199,-0.002600,0.002248,0.057098,176.146057,8.973308,0.570982,-157.151199,0.058131,0.000000
44.610001,40.050148,-157.195679,-0.002570,0.002270,0.057662,178.151962,9.075493,0.576621,-157.195679,0.058746,0.000000
44.980003,40.467583,-157.240158,-0.002539,0.002293,0.058234,180.008804,9.170085,0.582344,-157.240158,0.059362,0.000000
45.350002,41.972336,-157.373611,-0.002544,0.002324,0.059041,186.702271,9.511066,0.590413,-157.373611,0.059978,0.000000
45.720001,42.303749,-157.373611,-0.002518,0.002348,0.059631,188.176468,9.586166,0.596310,-157.373611,0.060602,0.000000
46.090004,42.262413,-157.462570,-0.002475,0.002365,0.060064,187.992599,9.576800,0.600640,-157.462570,0.061218,0.000000
46.460003,43.346390,-157.418091,-0.002475,0.002392,0.060766,192.814377,9.822432,0.607665,-157.418091,0.061834,0.000000
46.830002,43.982033,-157.507050,-0.002466,0.002416,0.061374,195.641846,9.966471,0.613736,-157.507050,0.062449,0.000000
47.200001,45.563499,-157.640488,-0.002449,0.002448,0.062171,202.676575,10.324837,0.621714,-157.640488,0.063065,0.000000
47.570004,46.023003,-157.596008,-0.002402,0.002470,0.062735,204.720535,10.428962,0.627354,-157.596008,0.063681,0.000000
47.940002,46.381599,-157.684967,-0.002389,0.002490,0.063247,206.315659,10.510221,0.632471,-157.684967,0.064296,0.000000
48.310001,47.549728,-157.684967,-0.002376,0.002516,0.063915,211.511749,10.774922,0.639148,-157.684967,0.064912,0.000000
48.680004,47.796989,-157.773926,-0.002354,0.002535,0.064401,212.611633,10.830953,0.644007,-157.773926,0.065528,0.000000
49.050003,49.336746,-157.862900,-0.002341,0.002570,0.065285,219.460815,11.179866,0.652849,-157.862900,0.066152,0.000000
49.420002,50.198792,-157.951859,-0.002328,0.002592,0.065831,223.295380,11.375209,0.658314,-157.951859,0.066768,0.000000
49.790001,50.382744,-157.907379,-0.002289,0.002612,0.066351,224.113632,11.416892,0.663515,-157.907379,0.067384,0.000000
50.160004,50.951729,-157.951859,-0.002289,0.002635,0.066941,226.644608,11.545827,0.669412,-157.951859,0.067999,0.000000
50.530003,51.924362,-158.040817,-0.002264,0.002659,0.067540,230.971100,11.766229,0.675399,-158.040817,0.068615,0.000000
50.900002,53.222084,-158.085297,-0.002246,0.002688,0.068268,236.743652,12.060297,0.682682,-158.085297,0.069231,0.000000
51.270004,54.605446,-158.218750,-0.002220,0.002715,0.068953,242.897156,12.373771,0.689532,-158.218750,0.069846,0.000000
51.640003,55.083946,-158.085297,-0.002207,0.002736,0.069482,245.025635,12.482201,0.694823,-158.085297,0.070463,0.000000
52.010002,55.568398,-158.174255,-0.002177,0.002756,0.070011,247.180573,12.591979,0.700115,-158.174255,0.071078,0.000000
52.380001,56.436775,-158.218750,-0.002177,0.002777,0.070532,251.043320,12.788756,0.705315,-158.218750,0.071703,0.000000
52.750004,57.620544,-158.352188,-0.002160,0.002803,0.071199,256.308990,13.057002,0.711992,-158.352188,0.072318,0.000000
53.120003,59.318192,-158.396667,-0.002143,0.002835,0.072014,263.860504,13.441694,0.720144,-158.396667,0.072934,0.000000
53.490002,59.880844,-158.396667,-0.002121,0.002854,0.072491,266.363312,13.569194,0.724913,-158.396667,0.073550,0.000000
53.860004,60.381683,-158.352188,-0.002104,0.002875,0.073030,268.591156,13.682685,0.730295,-158.352188,0.074166,0.000000
54.230003,62.030548,-158.441147,-0.002078,0.002902,0.073715,275.925659,14.056323,0.737146,-158.441147,0.074781,0.000000
54.600002,62.417816,-158.574585,-0.002074,0.002919,0.074139,277.648315,14.144079,0.741393,-158.574585,0.075397,0.000000
54.970001,64.462151,-158.574585,-0.002057,0.002955,0.075050,286.741974,14.607331,0.750499,-158.574585,0.076013,0.000000
55.340004,65.300346,-158.619064,-0.002039,0.002976,0.075596,290.470459,14.797271,0.755965,-158.619064,0.076628,0.000000
55.710003,66.073402,-158.663559,-0.002035,0.002997,0.076126,293.909180,14.972447,0.761256,-158.663559,0.077253,0.000000
56.080002,65.195717,-158.708038,-0.001992,0.002993,0.076013,290.005035,14.773561,0.760128,-158.708038,0.013357,0.000000
56.450005,66.078239,-158.796997,-0.001983,0.002808,0.071321,293.930695,14.973543,0.713210,-158.796997,294.500488,0.000000
56.820004,65.504036,-158.930435,-0.001962,0.003018,0.076655,291.376495,14.843427,0.766547,-158.930435,294.500488,0.000000
57.190002,65.194603,-158.930435,-0.001966,0.003033,0.077036,290.000092,14.773308,0.770362,-158.930435,294.500488,0.000000
57.560001,64.905632,-158.930435,-0.001944,0.003045,0.077348,288.714661,14.707827,0.773481,-158.930435,294.500488,0.000000
57.930004,65.246361,-158.930435,-0.001932,0.003059,0.077686,290.230316,14.785036,0.776865,-158.930435,294.500488,0.000000
58.300003,65.219551,-158.930435,-0.001927,0.003063,0.077808,290.111053,14.778962,0.778076,-158.930435,294.500488,0.000000
58.670002,65.286583,-159.108368,-0.001910,0.003073,0.078059,290.409210,14.794151,0.780589,-159.108368,294.500488,0.000000
59.040001,65.116402,-159.152847,-0.001910,0.003083,0.078319,289.652222,14.755588,0.783193,-159.152847,294.500488,0.000000
59.410004,65.288445,-159.108368,-0.001914,0.003092,0.078527,290.417511,14.794573,0.785275,-159.108368,294.500488,0.000000
59.780003,65.506279,-159.241806,-0.001897,0.003105,0.078857,291.386475,14.843935,0.788568,-159.241806,294.500488,0.000000
60.150002,64.854622,-159.241806,-0.001876,0.003103,0.078805,288.487762,14.696267,0.788053,-159.241806,294.500488,0.000000
60.520004,66.666954,-159.330765,-0.001871,0.003042,0.077278,296.549408,15.106948,0.772785,-159.330765,294.500488,0.000000
60.890003,65.746452,-159.375244,-0.001858,0.003043,0.077288,292.454834,14.898359,0.772876,-159.375244,294.500488,0.000000
61.260002,65.165932,-159.375244,-0.001854,0.003121,0.079282,289.872528,14.766811,0.792822,-159.375244,294.500488,0.000000
61.630001,65.180824,-159.375244,-0.001863,0.003137,0.079672,289.938782,14.770185,0.796720,-159.375244,294.500488,0.000000
62.000004,65.151039,-159.419724,-0.001845,0.003140,0.079759,289.806305,14.763437,0.797591,-159.419724,294.500488,0.000000
62.370003,65.270561,-159.508698,-0.001854,0.003147,0.079932,290.337952,14.790521,0.799324,-159.508698,294.500488,0.000000
62.740002,65.329765,-159.597656,-0.001841,0.003154,0.080115,290.601318,14.803937,0.801149,-159.597656,294.500488,0.000000
63.110004,65.291786,-159.553177,-0.001828,0.003160,0.080271,290.432373,14.795330,0.802708,-159.553177,294.500488,0.000000
63.480003,65.223274,-159.686615,-0.001828,0.003166,0.080427,290.127625,14.779805,0.804267,-159.686615,294.500488,0.000000
63.850002,65.072838,-159.775574,-0.001815,0.003171,0.080548,289.458435,14.745716,0.805479,-159.775574,294.500488,0.000000
64.220001,65.390465,-159.820053,-0.001811,0.003179,0.080756,290.871307,14.817692,0.807560,-159.820053,294.500488,0.000000
64.590004,65.023674,-159.909012,-0.001789,0.003180,0.080765,289.239746,14.734575,0.807651,-159.909012,294.500488,0.000000
64.960007,65.299232,-159.909012,-0.001811,0.003188,0.080973,290.465485,14.797018,0.809733,-159.909012,294.500488,0.000000
65.330002,65.375572,-159.864532,-0.001789,0.003195,0.081155,290.805084,14.814316,0.811550,-159.864532,294.500488,0.000000
65.700005,65.281731,-159.909012,-0.001798,0.003198,0.081234,290.387634,14.793052,0.812337,-159.909012,294.500488,0.000000
66.070000,65.739754,-160.042465,-0.001785,0.003206,0.081441,292.425018,14.896841,0.814411,-160.042465,294.500488,0.000000
66.440002,65.298866,-160.086945,-0.001781,0.003207,0.081450,290.463867,14.796934,0.814502,-160.086945,294.500488,0.000000
66.810005,64.865791,-160.086945,-0.001763,0.003207,0.081450,288.537445,14.698799,0.814502,-160.086945,294.500488,0.000000
67.180000,64.448738,-160.131424,-0.001759,0.003207,0.081459,286.682312,14.604293,0.814585,-160.131424,294.500488,0.000000
67.550003,66.443535,-160.175903,-0.001763,0.003144,0.079854,295.555603,15.056320,0.798545,-160.175903,294.500488,0.000000
67.920006,65.967644,-160.264862,-0.001768,0.003144,0.079854,293.438721,14.948482,0.798545,-160.264862,294.500488,0.000000
68.290001,65.528984,-160.309341,-0.001768,0.003185,0.080895,291.487488,14.849080,0.808953,-160.309341,294.500488,0.000000
68.660004,65.222160,-160.309341,-0.001746,0.003216,0.081693,290.122650,14.779552,0.816932,-160.309341,294.500488,0.000000
69.030006,65.334618,-160.353836,-0.001746,0.003233,0.082110,290.622894,14.805036,0.821095,-160.353836,294.500488,0.000000
69.400002,65.248222,-160.353836,-0.001750,0.003237,0.082213,290.238586,14.785459,0.822132,-160.353836,294.500488,0.000000
69.770004,65.107094,-160.442795,-0.001763,0.003239,0.082283,289.610809,14.753479,0.822829,-160.442795,294.500488,0.000000
70.140007,65.224770,-160.487274,-0.001738,0.003247,0.082482,290.134277,14.780144,0.824819,-160.487274,294.500488,0.000000
70.510002,65.147682,-160.531754,-0.001720,0.003248,0.082491,289.791351,14.762676,0.824910,-160.531754,294.500488,0.000000
70.880005,65.273537,-160.576233,-0.001712,0.003255,0.082664,290.351196,14.791195,0.826644,-160.576233,294.500488,0.000000
71.250000,65.159218,-160.665192,-0.001725,0.003256,0.082690,289.842682,14.765290,0.826901,-160.665192,294.500488,0.000000
71.620003,65.060539,-160.620712,-0.001725,0.003258,0.082742,289.403748,14.742929,0.827423,-160.620712,294.500488,0.000000
71.990005,65.590065,-160.709671,-0.001720,0.003266,0.082951,291.759186,14.862921,0.829505,-160.709671,294.500488,0.000000
72.360001,65.283974,-160.798645,-0.001729,0.003266,0.082951,290.397614,14.793560,0.829505,-160.798645,294.500488,0.000000
72.730003,65.022194,-160.798645,-0.001716,0.003267,0.082976,289.233154,14.734240,0.829763,-160.798645,294.500488,0.000000
73.100006,65.492500,-160.798645,-0.001703,0.003275,0.083184,291.325195,14.840813,0.831844,-160.798645,294.500488,0.000000
73.470001,65.240395,-160.932083,-0.001712,0.003275,0.083184,290.203766,14.783685,0.831844,-160.932083,294.500488,0.000000
73.840004,65.084373,-160.976562,-0.001712,0.003277,0.083245,289.509766,14.748329,0.832450,-160.976562,294.500488,0.000000
74.210007,65.057564,-161.021042,-0.001712,0.003280,0.083324,289.390503,14.742254,0.833237,-161.021042,294.500488,0.000000
74.580002,65.082893,-161.065521,-0.001694,0.003284,0.083402,289.503174,14.747994,0.834017,-161.065521,294.500488,0.000000
74.950005,65.097786,-161.065521,-0.001694,0.003286,0.083453,289.569427,14.751369,0.834531,-161.065521,294.500488,0.000000
75.320007,65.200188,-161.154480,-0.001694,0.003291,0.083583,290.024933,14.774573,0.835833,-161.154480,294.500488,0.000000
75.690002,65.061287,-161.154480,-0.001686,0.003291,0.083583,289.407043,14.743098,0.835833,-161.154480,294.500488,0.000000
76.060005,65.119759,-161.243454,-0.001686,0.003294,0.083670,289.667145,14.756349,0.836704,-161.243454,294.500488,0.000000
76.430000,65.027779,-161.243454,-0.001677,0.003296,0.083723,289.257996,14.735505,0.837226,-161.243454,294.500488,0.000000
76.800003,65.339455,-161.332413,-0.001690,0.003303,0.083887,290.644409,14.806131,0.838869,-161.332413,294.500488,0.000000
77.170006,65.257164,-161.376892,-0.001673,0.003303,0.083887,290.278351,14.787484,0.838869,-161.376892,294.500488,0.000000
77.540001,65.116768,-161.465851,-0.001677,0.003304,0.083922,289.653839,14.755671,0.839217,-161.465851,294.500488,0.000000
77.910004,65.302223,-161.421371,-0.001673,0.003309,0.084043,290.478790,14.797695,0.840428,-161.421371,294.500488,0.000000
78.280006,65.143211,-161.465851,-0.001660,0.003309,0.084043,289.771484,14.761663,0.840428,-161.465851,294.500488,0.000000
78.650002,64.970802,-161.554810,-0.001660,0.003309,0.084060,289.004578,14.722594,0.840602,-161.554810,294.500488,0.000000
79.020004,65.425850,-161.599289,-0.001673,0.003318,0.084277,291.028717,14.825709,0.842775,-161.599289,294.500488,0.000000
79.390007,65.314507,-161.599289,-0.001677,0.003318,0.084268,290.533447,14.800479,0.842684,-161.599289,294.500488,0.000000
79.760002,65.140984,-161.732742,-0.001669,0.003318,0.084277,289.761566,14.761158,0.842775,-161.732742,294.500488,0.000000
80.130005,65.233330,-161.688263,-0.001664,0.003323,0.084408,290.172333,14.782084,0.844077,-161.688263,294.500488,0.000000
80.500008,65.237053,-161.732742,-0.001664,0.003324,0.084433,290.188904,14.782928,0.844334,-161.732742,294.500488,0.000000
80.870003,65.254555,-161.866180,-0.001656,0.003326,0.084486,290.266754,14.786894,0.844857,-161.866180,294.500488,0.000000
81.240005,65.209862,-161.866180,-0.001656,0.003329,0.084546,290.067963,14.776766,0.845462,-161.866180,294.500488,0.000000
81.610001,65.155495,-161.910660,-0.001647,0.003330,0.084589,289.826111,14.764446,0.845894,-161.910660,294.500488,0.000000
81.980003,65.076180,-161.955139,-0.001647,0.003332,0.084642,289.473297,14.746473,0.846416,-161.955139,294.500488,0.000000
82.350006,65.032997,-161.999619,-0.001643,0.003333,0.084650,289.281219,14.736689,0.846499,-161.999619,294.500488,0.000000
82.720001,65.348396,-162.044098,-0.001643,0.003337,0.084772,290.684174,14.808158,0.847718,-162.044098,294.500488,0.000000
83.090004,65.202415,-162.177551,-0.001647,0.003338,0.084780,290.034821,14.775078,0.847801,-162.177551,294.500488,0.000000
83.460007,65.091820,-162.177551,-0.001638,0.003339,0.084815,289.542877,14.750017,0.848150,-162.177551,294.500488,0.000000
83.830002,65.652611,-162.133072,-0.001638,0.003346,0.084980,292.037384,14.877094,0.849800,-162.133072,294.500488,0.000000
84.200005,65.483559,-162.177551,-0.001634,0.003346,0.084980,291.285431,14.838787,0.849800,-162.177551,294.500488,0.000000
84.570007,65.295143,-162.266510,-0.001630,0.003346,0.084980,290.447296,14.796091,0.849800,-162.266510,294.500488,0.000000
84.940002,65.094429,-162.355469,-0.001630,0.003346,0.084980,289.554474,14.750608,0.849800,-162.355469,294.500488,0.000000
85.310005,64.936546,-162.399948,-0.001643,0.003346,0.084980,288.852173,14.714832,0.849800,-162.399948,294.500488,0.000000
85.680000,64.745140,-162.488907,-0.001634,0.003346,0.084980,288.000763,14.671458,0.849800,-162.488907,294.500488,0.000000
86.050003,66.258461,-162.488907,-0.001625,0.003356,0.085231,294.732361,15.014381,0.852313,-162.488907,294.500488,0.000000
86.420006,66.025368,-162.488907,-0.001621,0.003355,0.085222,293.695496,14.961562,0.852222,-162.488907,294.500488,0.000000
86.790001,65.861153,-162.533401,-0.001625,0.003355,0.085222,292.965027,14.924351,0.852222,-162.533401,294.500488,0.000000
87.160004,65.602348,-162.666840,-0.001621,0.003355,0.085222,291.813812,14.865705,0.852222,-162.666840,294.500488,0.000000
87.530006,65.435524,-162.666840,-0.001608,0.003355,0.085222,291.071747,14.827902,0.852222,-162.666840,294.500488,0.000000
87.900002,65.219551,-162.666840,-0.001613,0.003356,0.085231,290.111053,14.778962,0.852313,-162.666840,294.500488,0.000000
88.270004,65.221779,-162.755798,-0.001621,0.003363,0.085430,290.120972,14.779467,0.854304,-162.755798,294.500488,0.000000
88.640007,65.111183,-162.755798,-0.001621,0.003364,0.085448,289.628998,14.754405,0.854478,-162.755798,294.500488,0.000000
89.010002,65.186043,-162.844757,-0.001625,0.003367,0.085517,289.962006,14.771369,0.855174,-162.844757,294.500488,0.000000
89.380005,65.070976,-162.933731,-0.001613,0.003370,0.085595,289.450165,14.745294,0.855954,-162.933731,294.500488,0.000000
89.750008,65.386742,-162.889236,-0.001604,0.003372,0.085656,290.854767,14.816847,0.856560,-162.889236,294.500488,0.000000
90.120003,65.278389,-163.022690,-0.001617,0.003373,0.085665,290.372772,14.792295,0.856650,-163.022690,294.500488,0.000000
90.490005,65.167046,-163.067169,-0.001604,0.003373,0.085673,289.877502,14.767064,0.856734,-163.067169,294.500488,0.000000
90.860001,65.543144,-163.111649,-0.001613,0.003379,0.085829,291.550476,14.852289,0.858293,-163.111649,294.500488,0.000000
91.230003,65.448936,-163.111649,-0.001600,0.003379,0.085829,291.131409,14.830941,0.858293,-163.111649,294.500488,0.000000
91.600006,65.300346,-163.200607,-0.001613,0.003379,0.085829,290.470459,14.797271,0.858293,-163.200607,294.500488,0.000000
91.970001,65.177101,-163.200607,-0.001604,0.003379,0.085838,289.922211,14.769342,0.858384,-163.200607,294.500488,0.000000
92.340004,65.458992,-163.245087,-0.001608,0.003385,0.085986,291.176147,14.833220,0.859860,-163.245087,294.500488,0.000000
92.710007,65.371101,-163.378540,-0.001608,0.003385,0.085986,290.785187,14.813304,0.859860,-163.378540,294.500488,0.000000
93.080002,65.261253,-163.334045,-0.001600,0.003385,0.085986,290.296539,14.788412,0.859860,-163.334045,294.500488,0.000000
93.450005,65.140236,-163.378540,-0.001595,0.003385,0.085986,289.758240,14.760988,0.859860,-163.378540,294.500488,0.000000
93.820007,65.628792,-163.378540,-0.001587,0.003392,0.086168,291.931458,14.871696,0.861677,-163.378540,294.500488,0.000000
94.190002,65.548729,-163.467499,-0.001591,0.003392,0.086168,291.575317,14.853555,0.861677,-163.467499,294.500488,0.000000
94.560005,65.438881,-163.600937,-0.001591,0.003393,0.086177,291.086670,14.828663,0.861768,-163.600937,294.500488,0.000000
94.930008,65.309669,-163.645416,-0.001587,0.003393,0.086194,290.511932,14.799383,0.861942,-163.645416,294.500488,0.000000
95.300003,65.254555,-163.556458,-0.001587,0.003394,0.086212,290.266754,14.786894,0.862116,-163.556458,294.500488,0.000000
95.670006,65.275398,-163.689896,-0.001587,0.003396,0.086263,290.359467,14.791616,0.862631,-163.689896,294.500488,0.000000
96.040001,65.299614,-163.645416,-0.001600,0.003399,0.086324,290.467194,14.797104,0.863236,-163.645416,294.500488,0.000000
96.410004,65.300728,-163.823349,-0.001600,0.003400,0.086358,290.472137,14.797357,0.863584,-163.823349,294.500488,0.000000
96.780006,65.294029,-163.867828,-0.001574,0.003401,0.086376,290.442352,14.795838,0.863758,-163.867828,294.500488,0.000000
97.150002,65.344292,-163.867828,-0.001578,0.003404,0.086454,290.665924,14.807228,0.864538,-163.867828,294.500488,0.000000
97.520004,65.345406,-163.912308,-0.001574,0.003404,0.086454,290.670868,14.807481,0.864538,-163.912308,294.500488,0.000000
97.890007,65.308922,-163.912308,-0.001587,0.003405,0.086480,290.508606,14.799213,0.864803,-163.912308,294.500488,0.000000
98.260002,65.276146,-164.045746,-0.001587,0.003405,0.086498,290.362793,14.791786,0.864977,-164.045746,294.500488,0.000000
98.630005,65.378929,-164.090225,-0.001574,0.003409,0.086584,290.820007,14.815078,0.865840,-164.090225,294.500488,0.000000
99.000008,65.340950,-164.045746,-0.001569,0.003409,0.086584,290.651062,14.806471,0.865840,-164.045746,294.500488,0.000000
99.370003,65.269814,-164.134705,-0.001574,0.003411,0.086627,290.334625,14.790351,0.866272,-164.134705,294.500488,0.000000
99.740005,65.313393,-164.179184,-0.001556,0.003411,0.086645,290.528473,14.800226,0.866446,-164.179184,294.500488,0.000000
100.110008,65.302956,-164.179184,-0.001574,0.003413,0.086679,290.482056,14.797861,0.866794,-164.179184,294.500488,0.000000
100.480003,65.230721,-164.312637,-0.001565,0.003413,0.086679,290.160736,14.781493,0.866794,-164.312637,294.500488,0.000000
100.850006,65.233330,-164.312637,-0.001548,0.003415,0.086732,290.172333,14.782084,0.867316,-164.312637,294.500488,0.000000
101.220001,65.205772,-164.357117,-0.001574,0.003415,0.086740,290.049774,14.775839,0.867400,-164.357117,294.500488,0.000000
101.590004,65.229225,-164.401596,-0.001565,0.003417,0.086792,290.154083,14.781154,0.867922,-164.401596,294.500488,0.000000
101.960007,65.147316,-164.446075,-0.001569,0.003417,0.086792,289.789734,14.762592,0.867922,-164.446075,294.500488,0.000000
102.330002,65.211723,-164.490555,-0.001561,0.003420,0.086879,290.076233,14.777188,0.868792,-164.490555,294.500488,0.000000
102.700005,65.248970,-164.579514,-0.001561,0.003420,0.086879,290.241913,14.785628,0.868792,-164.579514,294.500488,0.000000
103.070007,65.166298,-164.535034,-0.001556,0.003420,0.086879,289.874176,14.766894,0.868792,-164.535034,294.500488,0.000000
103.440002,65.044533,-164.623993,-0.001552,0.003421,0.086897,289.332520,14.739302,0.868966,-164.623993,294.500488,0.000000
103.810005,65.058311,-164.668488,-0.001556,0.003422,0.086922,289.393829,14.742424,0.869224,-164.668488,294.500488,0.000000
104.180008,64.999855,-164.801926,-0.001552,0.003422,0.086922,289.133789,14.729177,0.869224,-164.801926,294.500488,0.000000
104.550003,64.905632,-164.801926,-0.001565,0.003422,0.086922,288.714661,14.707827,0.869224,-164.801926,294.500488,0.000000
104.920006,65.610161,-164.801926,-0.001552,0.003432,0.087174,291.848572,14.867475,0.871737,-164.801926,294.500488,0.000000
105.290009,65.603844,-164.890884,-0.001539,0.003432,0.087174,291.820465,14.866044,0.871737,-164.890884,294.500488,0.000000
105.660004,65.553932,-164.890884,-0.001552,0.003432,0.087174,291.598450,14.854733,0.871737,-164.890884,294.500488,0.000000
106.030006,65.474251,-164.979843,-0.001544,0.003432,0.087174,291.244019,14.836677,0.871737,-164.979843,294.500488,0.000000
106.400002,65.343925,-165.024323,-0.001539,0.003432,0.087174,290.664307,14.807145,0.871737,-165.024323,294.500488,0.000000
106.770004,65.269814,-164.979843,-0.001548,0.003432,0.087174,290.334625,14.790351,0.871737,-164.979843,294.500488,0.000000
107.140007,65.162941,-165.068802,-0.001556,0.003432,0.087174,289.859253,14.766133,0.871737,-165.068802,294.500488,0.000000
107.510002,65.138374,-165.157776,-0.001548,0.003434,0.087217,289.749969,14.760567,0.872168,-165.157776,294.500488,0.000000
107.880005,65.067253,-165.246735,-0.001552,0.003434,0.087217,289.433594,14.744451,0.872168,-165.246735,294.500488,0.000000
108.250008,64.987938,-165.246735,-0.001535,0.003434,0.087217,289.080780,14.726477,0.872168,-165.246735,294.500488,0.000000
108.620003,65.032997,-165.246735,-0.001539,0.003436,0.087278,289.281219,14.736689,0.872782,-165.246735,294.500488,0.000000
108.990005,65.125343,-165.291214,-0.001539,0.003439,0.087339,289.691986,14.757614,0.873387,-165.291214,294.500488,0.000000
109.360008,65.092567,-165.380173,-0.001539,0.003439,0.087339,289.546204,14.750187,0.873387,-165.380173,294.500488,0.000000
109.730003,65.019218,-165.380173,-0.001539,0.003439,0.087339,289.219940,14.733565,0.873387,-165.380173,294.500488,0.000000
110.100006,65.011391,-165.424652,-0.001544,0.003440,0.087374,289.185120,14.731791,0.873735,-165.424652,294.500488,0.000000
110.470009,64.940269,-165.469131,-0.001539,0.003440,0.087374,288.868744,14.715675,0.873735,-165.469131,294.500488,0.000000
110.840004,64.833031,-165.469131,-0.001544,0.003440,0.087374,288.391724,14.691375,0.873735,-165.469131,294.500488,0.000000
111.210007,65.523781,-165.558105,-0.001552,0.003450,0.087625,291.464325,14.847900,0.876249,-165.558105,294.500488,0.000000
111.580002,65.576653,-165.647064,-0.001535,0.003450,0.087625,291.699524,14.859881,0.876249,-165.647064,294.500488,0.000000
111.950005,65.543510,-165.736023,-0.001518,0.003450,0.087625,291.552094,14.852372,0.876249,-165.736023,294.500488,0.000000
112.320007,65.460472,-165.691544,-0.001531,0.003450,0.087625,291.182709,14.833555,0.876249,-165.691544,294.500488,0.000000
112.690002,65.377800,-165.736023,-0.001526,0.003450,0.087625,290.814972,14.814821,0.876249,-165.736023,294.500488,0.000000
113.060005,65.316368,-165.824982,-0.001531,0.003450,0.087642,290.541718,14.800900,0.876423,-165.824982,294.500488,0.000000
113.430008,65.256035,-165.869461,-0.001526,0.003451,0.087651,290.273346,14.787229,0.876506,-165.869461,294.500488,0.000000
113.800003,65.173744,-165.958435,-0.001518,0.003451,0.087651,289.907288,14.768581,0.876506,-165.958435,294.500488,0.000000
114.170006,65.185661,-165.958435,-0.001518,0.003453,0.087711,289.960297,14.771281,0.877112,-165.958435,294.500488,0.000000
114.540009,65.181572,-166.047394,-0.001535,0.003453,0.087711,289.942108,14.770355,0.877112,-166.047394,294.500488,0.000000
114.910004,65.149544,-166.047394,-0.001518,0.003454,0.087738,289.799652,14.763098,0.877376,-166.047394,294.500488,0.000000
115.280006,65.080650,-166.047394,-0.001522,0.003454,0.087738,289.493195,14.747486,0.877376,-166.047394,294.500488,0.000000
115.650009,65.702141,-166.136353,-0.001513,0.003463,0.087954,292.257721,14.888318,0.879541,-166.136353,294.500488,0.000000
116.020004,65.759483,-166.180832,-0.001522,0.003462,0.087946,292.512787,14.901312,0.879458,-166.180832,294.500488,0.000000
116.390007,65.663414,-166.180832,-0.001518,0.003462,0.087946,292.085449,14.879542,0.879458,-166.180832,1681.640991,0.000000
116.760002,65.456749,-166.269791,-0.001522,0.003455,0.087746,291.166168,14.832711,0.877460,-166.269791,0.087555,0.000000
117.130005,65.357323,-166.358749,-0.001526,0.003436,0.087269,290.723877,14.810181,0.872691,-166.358749,0.086940,0.000000
117.500008,65.170403,-166.358749,-0.001509,0.003423,0.086948,289.892426,14.767824,0.869481,-166.358749,0.086324,0.000000
117.870003,64.970802,-166.403244,-0.001496,0.003396,0.086255,289.004578,14.722594,0.862547,-166.403244,0.085700,0.000000
118.240005,64.888512,-166.403244,-0.001505,0.003376,0.085743,288.638519,14.703947,0.857430,-166.403244,0.085084,0.000000
118.610008,64.747002,-166.447723,-0.001509,0.003344,0.084945,288.009033,14.671881,0.849452,-166.447723,0.084468,0.000000
118.980003,64.629341,-166.625641,-0.001500,0.003320,0.084329,287.485657,14.645218,0.843290,-166.625641,0.083852,0.000000
119.350006,64.512047,-166.581161,-0.001500,0.003298,0.083757,286.963928,14.618639,0.837567,-166.581161,0.083237,0.000000
119.720009,64.449852,-166.625641,-0.001505,0.003288,0.083514,286.687256,14.604545,0.835145,-166.625641,0.082621,0.000000
120.090004,64.317284,-166.625641,-0.001505,0.003256,0.082690,286.097565,14.574504,0.826901,-166.625641,0.082005,0.000000
120.460007,63.977318,-166.670120,-0.001522,0.003231,0.082066,284.585327,14.497467,0.820656,-166.670120,0.081390,0.000000
120.830009,63.112297,-166.803574,-0.001500,0.003204,0.081390,280.737518,14.301451,0.813896,-166.803574,0.080773,0.000000
121.200005,62.173912,-166.848053,-0.001492,0.003184,0.080878,276.563385,14.088810,0.808779,-166.848053,0.080149,0.000000
121.570007,61.498428,-166.848053,-0.001483,0.003165,0.080401,273.558685,13.935742,0.804010,-166.848053,0.079534,0.000000
121.940002,60.518349,-166.848053,-0.001496,0.003156,0.080158,269.199066,13.713654,0.801580,-166.848053,0.078918,0.000000
122.310005,58.217087,-166.981491,-0.001479,0.003120,0.079247,258.962524,13.192181,0.792474,-166.981491,0.078302,0.000000
122.680008,56.289314,-167.025970,-0.001496,0.003093,0.078571,250.387375,12.755342,0.785706,-167.025970,0.077686,0.000000
123.050003,54.038696,-167.070450,-0.001487,0.003069,0.077947,240.376129,12.245344,0.779469,-167.070450,0.077070,0.000000
123.420006,52.166031,-167.025970,-0.001483,0.003051,0.077487,232.046097,11.820992,0.774866,-167.025970,0.076455,0.000000
123.790009,49.543037,-167.114929,-0.001470,0.003022,0.076767,220.378433,11.226613,0.767668,-167.114929,0.075839,0.000000
124.160004,47.220551,-167.159409,-0.001487,0.003003,0.076264,210.047501,10.700330,0.762641,-167.159409,0.075223,0.000000
124.530006,44.551018,-167.248383,-0.001487,0.002977,0.075622,198.172821,10.095406,0.756222,-167.248383,0.074599,0.000000
124.900009,41.898232,-167.292862,-0.001479,0.002951,0.074964,186.372635,9.494274,0.749636,-167.292862,0.073983,0.000000
125.270004,39.412651,-167.292862,-0.001479,0.002928,0.074382,175.316223,8.931034,0.743823,-167.292862,0.073368,0.000000
125.640007,36.484680,-167.337341,-0.001483,0.002902,0.073706,162.291962,8.267547,0.737055,-167.337341,0.072752,0.000000
126.010010,34.323807,-167.426300,-0.001487,0.002881,0.073168,152.679916,7.777886,0.731681,-167.426300,0.072136,0.000000
126.380005,32.193832,-167.515259,-0.001487,0.002862,0.072691,143.205322,7.295227,0.726912,-167.515259,0.071520,0.000000
126.750008,29.112450,-167.515259,-0.001475,0.002829,0.071868,129.498642,6.596975,0.718676,-167.515259,0.070905,0.000000
127.120003,26.452225,-167.515259,-0.001470,0.002806,0.071260,117.665375,5.994160,0.712605,-167.515259,0.070289,0.000000
127.490005,24.282784,-167.604218,-0.001487,0.002786,0.070757,108.015213,5.502557,0.707571,-167.604218,0.069673,0.000000
127.860008,22.039612,-167.648712,-0.001475,0.002761,0.070133,98.037086,4.994247,0.701326,-167.648712,0.069049,0.000000
128.230011,19.151863,-167.648712,-0.001487,0.002735,0.069474,85.191742,4.339874,0.694740,-167.648712,0.068433,0.000000
128.600006,16.583611,-167.693192,-0.001496,0.002710,0.068840,73.767586,3.757900,0.688404,-167.693192,0.067817,0.000000
128.970001,13.755066,-167.737671,-0.001479,0.002683,0.068155,61.185589,3.116942,0.681554,-167.737671,0.067202,0.000000
129.340012,11.712234,-167.782150,-0.001483,0.002664,0.067670,52.098621,2.654030,0.676701,-167.782150,0.066586,0.000000
129.710007,9.941605,-167.826630,-0.001483,0.002647,0.067236,44.222466,2.252800,0.672364,-167.826630,0.065970,0.000000
130.080002,7.131676,-167.915588,-0.001496,0.002619,0.066534,31.723278,1.616061,0.665339,-167.915588,0.065355,0.000000
130.450012,3.795593,-167.915588,-0.001483,0.002586,0.065675,16.883642,0.860094,0.656755,-167.915588,0.064738,0.000000
130.820007,1.433640,-167.960068,-0.001479,0.002561,0.065059,6.377147,0.324867,0.650593,-167.960068,0.064115,0.000000
131.190002,-0.646065,-168.049026,-0.001492,0.002537,0.064444,-2.873840,-0.146400,0.644439,-168.049026,0.063498,0.000000
131.560013,-1.600456,-168.049026,-0.001496,0.002522,0.064062,-7.119185,-0.362669,0.640624,-168.049026,0.062883,0.000000
131.930008,-5.231831,-168.182480,-0.001505,0.002490,0.063247,-23.272345,-1.185550,0.632471,-168.182480,0.062267,0.000000
132.300003,-0.045052,-168.182480,-0.001634,0.002474,0.062831,-0.200399,-0.010209,0.628308,-168.182480,0.061651,0.000000
132.670013,-0.052505,-168.182480,-0.001643,0.002439,0.061963,-0.233556,-0.011898,0.619633,-168.182480,0.061036,0.000000
133.040009,-0.056229,-168.271439,-0.001664,0.002420,0.061469,-0.250117,-0.012742,0.614690,-168.271439,0.060420,0.000000
133.410004,-0.028297,-168.315918,-0.001703,0.002400,0.060957,-0.125873,-0.006412,0.609572,-168.315918,0.059804,0.000000
133.779999,-0.030907,-168.404877,-0.001742,0.002368,0.060151,-0.137480,-0.007004,0.601511,-168.404877,0.059188,0.000000
134.150009,-0.023087,-168.404877,-0.001759,0.002354,0.059795,-0.102694,-0.005231,0.597953,-168.404877,0.058564,0.000000
134.520004,-0.062187,-168.449356,-0.001802,0.002323,0.058997,-0.276622,-0.014092,0.589974,-168.449356,0.057948,0.000000
134.889999,-0.060692,-168.449356,-0.001832,0.002299,0.058399,-0.269971,-0.013753,0.583994,-168.449356,0.057333,0.000000
135.260010,-0.068512,-168.582809,-0.001867,0.002274,0.057749,-0.304756,-0.015525,0.577492,-168.582809,0.056717,0.000000
135.630005,-0.032021,-168.582809,-0.001884,0.002254,0.057246,-0.142435,-0.007256,0.572458,-168.582809,0.056101,0.000000
136.000000,-0.053993,-168.627289,-0.001914,0.002234,0.056751,-0.240174,-0.012235,0.567515,-168.627289,0.055485,0.000000
136.370010,-0.049149,-168.760727,-0.001957,0.002198,0.055823,-0.218624,-0.011137,0.558234,-168.760727,0.054870,0.000000
136.740005,-0.035744,-168.671768,-0.001992,0.002173,0.055191,-0.158996,-0.008100,0.551906,-168.671768,0.054254,0.000000
137.110001,-0.048782,-168.760727,-0.002026,0.002149,0.054575,-0.216995,-0.011054,0.545752,-168.760727,0.053638,0.000000
137.480011,-0.036865,-168.805206,-0.002048,0.002136,0.054254,-0.163985,-0.008354,0.542542,-168.805206,0.053014,0.000000
137.850006,-0.046173,-168.938660,-0.002070,0.002103,0.053412,-0.205388,-0.010463,0.534124,-168.938660,0.052398,0.000000
138.220001,-0.064415,-168.894165,-0.002095,0.002080,0.052823,-0.286532,-0.014597,0.528228,-168.894165,0.051783,0.000000
138.590012,-0.052872,-168.894165,-0.002126,0.002050,0.052077,-0.235185,-0.011981,0.520771,-168.894165,0.051166,0.000000
138.960007,-0.029785,-168.938660,-0.002160,0.002025,0.051427,-0.132491,-0.006749,0.514269,-168.938660,0.050551,0.000000
139.330002,-0.042450,-169.027618,-0.002195,0.002004,0.050898,-0.188827,-0.009619,0.508978,-169.027618,0.049935,0.000000
139.700012,-0.055855,-169.072098,-0.002203,0.001989,0.050525,-0.248455,-0.012657,0.505246,-169.072098,0.049319,0.000000
140.070007,-0.046547,-169.116577,-0.002229,0.001958,0.049727,-0.207051,-0.010548,0.497267,-169.116577,0.048704,0.000000
140.440002,-0.027184,-169.161057,-0.002259,0.001927,0.048946,-0.120918,-0.006160,0.489463,-169.161057,0.048088,0.000000
140.810013,-0.021965,-169.161057,-0.002294,0.001902,0.048313,-0.097705,-0.004977,0.483134,-169.161057,0.047463,0.000000
141.180008,-0.002975,-169.205536,-0.002315,0.001889,0.047992,-0.013236,-0.000674,0.479925,-169.205536,0.046848,0.000000
141.550003,-0.035370,-169.250015,-0.002341,0.001860,0.047247,-0.157333,-0.008015,0.472468,-169.250015,0.046232,0.000000
141.920013,-0.018990,-169.294495,-0.002363,0.001833,0.046553,-0.084470,-0.004303,0.465527,-169.294495,0.045616,0.000000
142.290009,-0.011917,-169.383469,-0.002402,0.001805,0.045859,-0.053010,-0.002700,0.458593,-169.383469,0.045001,0.000000
142.660004,-0.048409,-169.383469,-0.002414,0.001786,0.045356,-0.215332,-0.010970,0.453559,-169.383469,0.044385,0.000000
143.030014,-0.018242,-169.472427,-0.002449,0.001759,0.044680,-0.081144,-0.004134,0.446799,-169.472427,0.043769,0.000000
143.400009,-0.052872,-169.472427,-0.002458,0.001739,0.044159,-0.235185,-0.011981,0.441591,-169.472427,0.043153,0.000000
143.770004,-0.034630,-169.561386,-0.002488,0.001708,0.043388,-0.154041,-0.007847,0.433878,-169.561386,0.042538,0.000000
144.139999,-0.013779,-169.605865,-0.002522,0.001683,0.042754,-0.061291,-0.003122,0.427542,-169.605865,0.041913,0.000000
144.510010,-0.007072,-169.605865,-0.002557,0.001661,0.042199,-0.031460,-0.001603,0.421993,-169.605865,0.041298,0.000000
144.880005,0.003357,-169.694824,-0.002587,0.001637,0.041592,0.014932,0.000761,0.415922,-169.694824,0.040682,0.000000
145.250000,-0.021599,-169.783783,-0.002600,0.001616,0.041046,-0.096076,-0.004894,0.410464,-169.783783,0.040066,0.000000
145.620010,-0.022339,-169.783783,-0.002613,0.001589,0.040370,-0.099368,-0.005062,0.403697,-169.783783,0.039451,0.000000
145.990005,-0.031281,-169.739304,-0.002647,0.001571,0.039901,-0.139143,-0.007088,0.399011,-169.739304,0.038835,0.000000
146.360001,-0.013031,-169.828278,-0.002665,0.001540,0.039121,-0.057965,-0.002953,0.391207,-169.828278,0.038219,0.000000
146.730011,0.025322,-169.872757,-0.002695,0.001515,0.038488,0.112638,0.005738,0.384878,-169.872757,0.037603,0.000000
147.100006,0.016388,-169.917236,-0.002716,0.001491,0.037881,0.072897,0.003714,0.378807,-169.917236,0.036988,0.000000
147.470001,-0.005211,-170.006195,-0.002742,0.001473,0.037421,-0.023179,-0.001181,0.374213,-170.006195,0.036363,0.000000
147.840012,-0.008934,-170.006195,-0.002764,0.001445,0.036692,-0.039741,-0.002024,0.366923,-170.006195,0.035748,0.000000
148.210007,-0.004463,-170.050674,-0.002790,0.001417,0.035999,-0.019853,-0.001011,0.359989,-170.050674,0.035131,0.000000
148.580002,0.031281,-170.050674,-0.002811,0.001398,0.035513,0.139143,0.007088,0.355129,-170.050674,0.034516,0.000000
148.950012,0.026810,-170.184113,-0.002859,0.001375,0.034923,0.119255,0.006075,0.349232,-170.184113,0.033900,0.000000
149.320007,0.008194,-170.228607,-0.002854,0.001352,0.034334,0.036449,0.001857,0.343335,-170.228607,0.033284,0.000000
149.690002,0.014900,-170.273087,-0.002876,0.001326,0.033675,0.066279,0.003376,0.336750,-170.273087,0.032669,0.000000
150.060013,-0.006699,-170.273087,-0.002915,0.001297,0.032938,-0.029797,-0.001518,0.329377,-170.273087,0.032053,0.000000
150.430008,-0.002602,-170.317566,-0.002949,0.001276,0.032417,-0.011573,-0.000590,0.324169,-170.317566,0.031437,0.000000
150.800003,-0.005959,-170.362045,-0.002949,0.001259,0.031984,-0.026505,-0.001350,0.319839,-170.362045,0.030813,0.000000
151.170013,-0.004837,-170.406525,-0.002988,0.001229,0.031229,-0.021516,-0.001096,0.312292,-170.406525,0.030197,0.000000
151.540009,-0.020103,-170.495483,-0.003001,0.001203,0.030552,-0.089425,-0.004556,0.305524,-170.495483,0.029581,0.000000
151.910004,0.002983,-170.451004,-0.003044,0.001176,0.029859,0.013269,0.000676,0.298590,-170.451004,0.028966,0.000000
152.280014,-0.005585,-170.495483,-0.003065,0.001154,0.029304,-0.024842,-0.001266,0.293042,-170.495483,0.028350,0.000000
152.650009,-0.020851,-170.628922,-0.003091,0.001132,0.028749,-0.092750,-0.004725,0.287485,-170.628922,0.027734,0.000000
153.000000,-0.002602,-170.673416,-0.003100,0.001135,0.028818,-0.011573,-0.000590,0.288182,-170.673416,0.028749,0.000000