File: Data/compression 19/AutoNoHeating-17-19-reverse-1-3_09112024_155750.csv
Time (sec),S:Load (lbs),S:HL1 (DIM),S:LVDT (in),S:Position (in),Ch:Position (mm),Ch:Load (N),Ch:Stress (MPa),Ch:Strain (mm/mm),Ch:HL1 (DIM),Set Point (),Cycles ()
0.210000,-0.024574,-175.254944,-0.010158,-0.005553,-0.141046,-0.109312,-0.005569,-1.410456,-175.254944,-0.140828,0.000000
0.590000,-0.018616,-175.299423,-0.010158,-0.005457,-0.138617,-0.082807,-0.004218,-1.386172,-175.299423,-0.137620,0.000000
0.970000,-0.002602,-175.299423,-0.009977,-0.005217,-0.132503,-0.011573,-0.000590,-1.325031,-175.299423,-0.131289,0.000000
1.350000,0.005219,-175.388397,-0.009718,-0.004966,-0.126138,0.023213,0.001183,-1.261377,-175.388397,-0.124958,0.000000
1.730000,-0.000374,-175.388397,-0.009464,-0.004715,-0.119772,-0.001663,-0.000085,-1.197722,-175.388397,-0.118628,0.000000
2.110000,-0.013405,-175.388397,-0.009218,-0.004467,-0.113459,-0.059628,-0.003038,-1.134590,-175.388397,-0.112297,0.000000
2.490000,-0.029419,-175.477356,-0.008959,-0.004217,-0.107119,-0.130862,-0.006666,-1.071193,-175.477356,-0.105966,0.000000
2.870000,-0.040962,-175.521835,-0.008709,-0.003969,-0.100814,-0.182209,-0.009282,-1.008145,-175.521835,-0.099635,0.000000
3.250000,-0.011543,-175.521835,-0.008459,-0.003717,-0.094423,-0.051347,-0.002616,-0.944233,-175.521835,-0.093304,0.000000
3.630000,-0.013779,-175.610794,-0.008201,-0.003474,-0.088231,-0.061291,-0.003122,-0.882312,-175.610794,-0.086974,0.000000
4.010000,-0.042076,-175.699753,-0.007938,-0.003226,-0.081953,-0.187164,-0.009535,-0.819528,-175.699753,-0.080643,0.000000
4.390000,-0.049149,-175.699753,-0.007696,-0.002974,-0.075535,-0.218624,-0.011137,-0.755351,-175.699753,-0.074313,0.000000
4.770000,-0.068886,-175.699753,-0.007424,-0.002724,-0.069178,-0.306419,-0.015610,-0.691780,-175.699753,-0.067981,0.000000
5.150000,-0.014519,-175.788712,-0.007161,-0.002472,-0.062795,-0.064583,-0.003290,-0.627952,-175.788712,-0.061651,0.000000
5.530000,-0.014145,-175.833206,-0.006898,-0.002222,-0.056447,-0.062920,-0.003205,-0.564472,-175.833206,-0.055320,0.000000
5.910000,0.000748,-175.922165,-0.006635,-0.001977,-0.050204,0.003326,0.000169,-0.502036,-175.922165,-0.048989,0.000000
6.290000,-0.013779,-175.966644,-0.006390,-0.001724,-0.043778,-0.061291,-0.003122,-0.437776,-175.966644,-0.042659,0.000000
6.670001,-0.044312,-175.922165,-0.006135,-0.001471,-0.037351,-0.197107,-0.010041,-0.373509,-175.922165,-0.036327,0.000000
7.050000,-0.032021,-176.011124,-0.005881,-0.001229,-0.031228,-0.142435,-0.007256,-0.312284,-176.011124,-0.029997,0.000000
7.430000,0.011169,-176.100082,-0.005635,-0.000974,-0.024750,0.049684,0.002531,-0.247502,-176.100082,-0.023666,0.000000
7.810000,0.027931,-176.100082,-0.005381,-0.000732,-0.018585,0.124244,0.006329,-0.185846,-176.100082,-0.017336,0.000000
8.190001,-0.007072,-176.144562,-0.005113,-0.000480,-0.012193,-0.031460,-0.001603,-0.121927,-176.144562,-0.011005,0.000000
8.570001,-0.014519,-176.144562,-0.004855,-0.000232,-0.005897,-0.064583,-0.003290,-0.058969,-176.144562,-0.004674,0.000000
8.950001,0.037987,-176.233521,-0.004600,0.000015,0.000373,0.168974,0.008608,0.003732,-176.233521,0.001657,0.000000
9.330001,0.201080,-176.278015,-0.004570,-0.000006,-0.000148,0.894450,0.045565,-0.001476,-176.278015,-0.000000,0.000000
9.710000,0.178368,-176.322495,-0.004575,-0.000006,-0.000148,0.793419,0.040419,-0.001476,-176.322495,0.000330,0.000000
10.090000,0.183952,-176.366974,-0.004575,-0.000006,-0.000148,0.818261,0.041684,-0.001476,-176.366974,0.000963,0.000000
10.470000,0.357483,-176.366974,-0.004553,0.000029,0.000728,1.590163,0.081007,0.007282,-176.366974,0.001596,0.000000
10.850000,0.606598,-176.455933,-0.004536,0.000048,0.001232,2.698282,0.137457,0.012316,-176.455933,0.002229,0.000000
11.230000,0.843796,-176.500412,-0.004518,0.000071,0.001804,3.753391,0.191207,0.018039,-176.500412,0.002870,0.000000
11.610001,1.170372,-176.589371,-0.004501,0.000090,0.002298,5.206075,0.265210,0.022982,-176.589371,0.003504,0.000000
11.990001,1.875641,-176.589371,-0.004462,0.000128,0.003261,8.343267,0.425026,0.032611,-176.589371,0.004137,0.000000
12.370001,2.267754,-176.589371,-0.004428,0.000150,0.003808,10.087472,0.513880,0.038076,-176.589371,0.004770,0.000000
12.750001,2.908600,-176.678345,-0.004419,0.000179,0.004544,12.938098,0.659098,0.045441,-176.678345,0.005403,0.000000
13.130001,3.261986,-176.722824,-0.004393,0.000195,0.004943,14.510037,0.739177,0.049431,-176.722824,0.006036,0.000000
13.510000,3.980293,-176.767303,-0.004381,0.000224,0.005689,17.705229,0.901947,0.056895,-176.767303,0.006669,0.000000
13.890000,4.432350,-176.722824,-0.004350,0.000248,0.006297,19.716078,1.004385,0.062966,-176.722824,0.007302,0.000000
14.270000,5.107094,-176.811783,-0.004329,0.000277,0.007033,22.717487,1.157284,0.070331,-176.811783,0.007935,0.000000
14.650001,5.542023,-176.945221,-0.004316,0.000300,0.007632,24.652147,1.255840,0.076319,-176.945221,0.008568,0.000000
15.030001,6.084938,-176.900742,-0.004307,0.000323,0.008204,27.067156,1.378867,0.082041,-176.900742,0.009201,0.000000
15.410001,6.655045,-176.989700,-0.004286,0.000345,0.008759,29.603117,1.508055,0.087590,-176.989700,0.009835,0.000000
15.790001,7.454895,-176.989700,-0.004255,0.000377,0.009574,33.161030,1.689303,0.095743,-176.989700,0.010468,0.000000
16.170000,7.893929,-177.078659,-0.004225,0.000400,0.010164,35.113949,1.788790,0.101640,-177.078659,0.011100,0.000000
16.550001,8.256615,-177.123154,-0.004195,0.000422,0.010728,36.727257,1.870976,0.107279,-177.123154,0.011734,0.000000
16.930000,8.898956,-177.123154,-0.004195,0.000448,0.011378,39.584534,2.016532,0.113782,-177.123154,0.012367,0.000000
17.310001,9.487305,-177.212112,-0.004165,0.000472,0.011976,42.201637,2.149854,0.119762,-177.212112,0.013000,0.000000
17.690001,10.197052,-177.256592,-0.004126,0.000502,0.012740,45.358753,2.310685,0.127400,-177.256592,0.013633,0.000000
18.070002,10.512451,-177.301071,-0.004113,0.000525,0.013347,46.761719,2.382155,0.133471,-177.301071,0.014266,0.000000
18.450001,11.113457,-177.345551,-0.004092,0.000552,0.014015,49.435123,2.518345,0.140147,-177.345551,0.014899,0.000000
18.830002,11.624725,-177.434509,-0.004074,0.000578,0.014682,51.709362,2.634200,0.146824,-177.434509,0.015532,0.000000
19.210001,11.885757,-177.434509,-0.004057,0.000597,0.015159,52.870491,2.693351,0.151593,-177.434509,0.016165,0.000000
19.590000,12.769402,-177.434509,-0.004040,0.000626,0.015905,56.801136,2.893588,0.159049,-177.434509,0.016798,0.000000
19.970001,13.009575,-177.478989,-0.004018,0.000651,0.016529,57.869480,2.948012,0.165294,-177.478989,0.017432,0.000000
20.350000,13.268753,-177.567963,-0.003975,0.000670,0.017015,59.022362,3.006742,0.170154,-177.567963,0.018065,0.000000
20.730001,13.930458,-177.612442,-0.003975,0.000698,0.017718,61.965771,3.156687,0.177179,-177.612442,0.018697,0.000000
21.110001,14.048126,-177.612442,-0.003941,0.000718,0.018230,62.489185,3.183351,0.182296,-177.612442,0.019330,0.000000
21.490002,15.278816,-177.656921,-0.003898,0.000753,0.019123,67.963570,3.462229,0.191228,-177.656921,0.019964,0.000000
21.870001,15.179764,-177.745880,-0.003893,0.000771,0.019591,67.522964,3.439784,0.195906,-177.745880,0.020597,0.000000
22.250002,15.757317,-177.790359,-0.003872,0.000798,0.020258,70.092049,3.570659,0.202583,-177.790359,0.021239,0.000000
22.630001,16.365768,-177.834839,-0.003859,0.000826,0.020978,72.798576,3.708536,0.209782,-177.834839,0.021871,0.000000
23.010000,16.307678,-177.834839,-0.003829,0.000844,0.021438,72.540176,3.695373,0.214376,-177.834839,0.022505,0.000000
23.390001,17.582687,-177.879318,-0.003798,0.000880,0.022348,78.211700,3.984294,0.223483,-177.879318,0.023138,0.000000
23.770000,17.457939,-177.923798,-0.003773,0.000899,0.022843,77.656792,3.956026,0.228426,-177.923798,0.023771,0.000000
24.150002,17.635193,-178.012772,-0.003777,0.000920,0.023372,78.445259,3.996192,0.233717,-178.012772,0.024403,0.000000
24.530001,18.268593,-178.012772,-0.003729,0.000947,0.024057,81.262756,4.139722,0.240568,-178.012772,0.025037,0.000000
24.910002,18.279762,-178.012772,-0.003708,0.000966,0.024543,81.312447,4.142253,0.245428,-178.012772,0.025670,0.000000
25.290001,19.295967,-178.101730,-0.003678,0.000997,0.025332,85.832748,4.372529,0.253315,-178.101730,0.026303,0.000000
25.670002,19.460930,-178.146210,-0.003660,0.001022,0.025965,86.566536,4.409910,0.259651,-178.146210,0.026936,0.000000
26.050001,19.684357,-178.235168,-0.003643,0.001045,0.026546,87.560394,4.460539,0.265457,-178.235168,0.027569,0.000000
26.430000,20.160995,-178.190689,-0.003613,0.001072,0.027222,89.680588,4.568547,0.272225,-178.190689,0.028202,0.000000
26.810001,20.231743,-178.235168,-0.003591,0.001094,0.027786,89.995285,4.584579,0.277857,-178.235168,0.028836,0.000000
27.190001,20.907227,-178.324127,-0.003548,0.001123,0.028515,92.999985,4.737645,0.285146,-178.324127,0.029468,0.000000
27.570002,21.389076,-178.368607,-0.003535,0.001150,0.029208,95.143364,4.846834,0.292080,-178.368607,0.030101,0.000000
27.950001,21.309761,-178.457581,-0.003514,0.001170,0.029729,94.790550,4.828861,0.297288,-178.457581,0.030735,0.000000
28.330002,21.516052,-178.413101,-0.003484,0.001193,0.030309,95.708183,4.875607,0.303094,-178.413101,0.031368,0.000000
28.710001,21.146660,-178.457581,-0.003479,0.001201,0.030518,94.065041,4.791902,0.305176,-178.457581,0.032001,0.000000
29.090002,22.876335,-178.546539,-0.003432,0.001250,0.031741,101.759018,5.183852,0.317409,-178.546539,0.032634,0.000000
29.470001,23.092682,-178.591019,-0.003402,0.001276,0.032409,102.721382,5.232876,0.324085,-178.591019,0.033267,0.000000
29.850002,23.006287,-178.679977,-0.003397,0.001296,0.032929,102.337074,5.213299,0.329286,-178.679977,0.033900,0.000000
30.230001,23.343658,-178.679977,-0.003354,0.001322,0.033571,103.837776,5.289749,0.335705,-178.679977,0.034533,0.000000
30.610001,23.539528,-178.679977,-0.003341,0.001345,0.034151,104.709053,5.334133,0.341511,-178.679977,0.035166,0.000000
30.990002,23.733902,-178.768936,-0.003303,0.001365,0.034663,105.573669,5.378179,0.346628,-178.768936,0.035799,0.000000
31.370001,24.627975,-178.857910,-0.003268,0.001398,0.035505,109.550705,5.580779,0.355046,-178.857910,0.036433,0.000000
31.750002,24.696487,-178.857910,-0.003268,0.001421,0.036103,109.855461,5.596304,0.361026,-178.857910,0.037065,0.000000
32.130001,25.144455,-178.813431,-0.003238,0.001446,0.036735,111.848122,5.697815,0.367354,-178.813431,0.037698,0.000000
32.510002,24.876717,-178.946869,-0.003208,0.001463,0.037161,110.657166,5.637145,0.371609,-178.946869,0.038331,0.000000
32.890003,24.756439,-178.946869,-0.003173,0.001480,0.037586,110.122139,5.609889,0.375855,-178.946869,0.038965,0.000000
33.270000,26.155815,-179.035828,-0.003156,0.001522,0.038661,116.346878,5.926992,0.386612,-179.035828,0.039607,0.000000
33.650002,26.506592,-179.124786,-0.003117,0.001547,0.039294,117.907211,6.006480,0.392940,-179.124786,0.040239,0.000000
34.030003,26.707298,-179.169266,-0.003100,0.001574,0.039988,118.799995,6.051960,0.399882,-179.169266,0.040872,0.000000
34.410000,26.745651,-179.169266,-0.003078,0.001593,0.040456,118.970596,6.060651,0.404560,-179.169266,0.041506,0.000000
34.790001,27.245003,-179.213745,-0.003057,0.001622,0.041193,121.191826,6.173806,0.411933,-179.213745,0.042139,0.000000
35.170002,27.599129,-179.302719,-0.003014,0.001646,0.041800,122.767059,6.254052,0.418004,-179.302719,0.042772,0.000000
35.550003,27.998688,-179.302719,-0.003005,0.001671,0.042451,124.544380,6.344594,0.424506,-179.302719,0.043404,0.000000
35.930000,28.313713,-179.302719,-0.002966,0.001697,0.043093,125.945686,6.415979,0.430925,-179.302719,0.044038,0.000000
36.310001,28.629860,-179.347198,-0.002940,0.001720,0.043691,127.351974,6.487619,0.436913,-179.347198,0.044671,0.000000
36.690002,28.548683,-179.391678,-0.002910,0.001742,0.044237,126.990883,6.469224,0.442371,-179.391678,0.045304,0.000000
37.070004,29.361946,-179.480637,-0.002893,0.001771,0.044974,130.608459,6.653512,0.449744,-179.480637,0.045937,0.000000
37.450001,29.809532,-179.436157,-0.002867,0.001797,0.045642,132.599426,6.754937,0.456420,-179.436157,0.046570,0.000000
37.830002,30.002426,-179.436157,-0.002841,0.001818,0.046189,133.457458,6.798647,0.461886,-179.436157,0.047203,0.000000
38.210003,30.256012,-179.569595,-0.002807,0.001843,0.046813,134.585464,6.856111,0.468131,-179.569595,0.047837,0.000000
38.590000,30.578484,-179.569595,-0.002790,0.001865,0.047368,136.019882,6.929183,0.473680,-179.569595,0.048469,0.000000
38.970001,31.587616,-179.703049,-0.002768,0.001898,0.048201,140.508728,7.157856,0.482006,-179.703049,0.049102,0.000000
39.350002,31.889236,-179.703049,-0.002738,0.001922,0.048816,141.850403,7.226204,0.488161,-179.703049,0.049736,0.000000
39.730003,32.216919,-179.658554,-0.002721,0.001949,0.049493,143.308014,7.300458,0.494928,-179.658554,0.050369,0.000000
40.110001,32.732285,-179.703049,-0.002690,0.001974,0.050135,145.600479,7.417242,0.501347,-179.703049,0.051001,0.000000
40.490002,32.377419,-179.836487,-0.002643,0.001991,0.050568,144.021957,7.336828,0.505677,-179.836487,0.051635,0.000000
40.870003,33.457298,-179.880966,-0.002634,0.002020,0.051314,148.825500,7.581532,0.513141,-179.880966,0.052268,0.000000
41.250004,33.646835,-179.836487,-0.002608,0.002044,0.051912,149.668594,7.624482,0.519121,-179.836487,0.052901,0.000000
41.630001,33.923882,-179.880966,-0.002574,0.002067,0.052511,150.900955,7.687262,0.525109,-179.880966,0.053534,0.000000
42.010002,34.612770,-179.969925,-0.002557,0.002094,0.053187,153.965286,7.843366,0.531869,-179.969925,0.054167,0.000000
42.390003,34.487648,-180.014404,-0.002531,0.002112,0.053638,153.408722,7.815013,0.536380,-180.014404,0.054800,0.000000
42.770000,36.279877,-180.103378,-0.002514,0.002150,0.054618,161.380951,8.221138,0.546183,-180.103378,0.055433,0.000000
43.150002,36.054962,-180.147858,-0.002488,0.002167,0.055034,160.380478,8.170171,0.550339,-180.147858,0.056066,0.000000
43.530003,36.622086,-180.103378,-0.002453,0.002193,0.055702,162.903168,8.298683,0.557023,-180.103378,0.056699,0.000000
43.910004,37.189209,-180.236816,-0.002436,0.002219,0.056353,165.425858,8.427196,0.563525,-180.236816,0.057341,0.000000
44.290001,37.136711,-180.281296,-0.002402,0.002237,0.056821,165.192337,8.415298,0.568211,-180.281296,0.057974,0.000000
44.670002,39.003410,-180.325775,-0.002389,0.002275,0.057783,173.495834,8.838300,0.577832,-180.325775,0.058608,0.000000
45.050003,39.231674,-180.281296,-0.002358,0.002295,0.058304,174.511200,8.890024,0.583040,-180.281296,0.059240,0.000000
45.430000,39.203377,-180.325775,-0.002333,0.002316,0.058815,174.385330,8.883613,0.588150,-180.325775,0.059873,0.000000
45.810001,39.580589,-180.414734,-0.002302,0.002341,0.059457,176.063248,8.969090,0.594569,-180.414734,0.060506,0.000000
46.190002,40.057968,-180.548187,-0.002272,0.002360,0.059951,178.186737,9.077265,0.599512,-180.548187,0.061140,0.000000
46.570004,41.304672,-180.503693,-0.002242,0.002395,0.060844,183.732361,9.359773,0.608445,-180.503693,0.061773,0.000000
46.950001,42.195015,-180.548187,-0.002233,0.002419,0.061443,187.692795,9.561527,0.614432,-180.548187,0.062405,0.000000
47.330002,42.265762,-180.548187,-0.002212,0.002441,0.061990,188.007507,9.577559,0.619898,-180.548187,0.063039,0.000000
47.710003,43.068970,-180.637146,-0.002173,0.002467,0.062666,191.580353,9.759567,0.626657,-180.637146,0.063672,0.000000
48.090004,43.510979,-180.681625,-0.002147,0.002488,0.063203,193.546494,9.859729,0.632032,-180.681625,0.064305,0.000000
48.470001,43.786537,-180.770584,-0.002121,0.002509,0.063724,194.772247,9.922171,0.637240,-180.770584,0.064938,0.000000
48.850002,45.738136,-180.770584,-0.002100,0.002547,0.064704,203.453384,10.364409,0.647035,-180.770584,0.065571,0.000000
49.230003,45.827881,-180.815063,-0.002087,0.002568,0.065215,203.852600,10.384746,0.652153,-180.815063,0.066204,0.000000
49.610001,45.922089,-180.859543,-0.002039,0.002587,0.065701,204.271652,10.406094,0.657012,-180.859543,0.066837,0.000000
49.990002,44.951691,-180.948502,-0.002039,0.002593,0.065866,199.955109,10.186198,0.658663,-180.948502,0.067470,0.000000
50.370003,47.935135,-180.992996,-0.002009,0.002643,0.067141,213.226135,10.862257,0.671410,-180.992996,0.068103,0.000000
50.750004,49.285362,-180.948502,-0.001988,0.002671,0.067852,219.232239,11.168223,0.678518,-180.948502,0.068737,0.000000
51.130001,49.581764,-180.992996,-0.001949,0.002694,0.068424,220.550705,11.235388,0.684241,-180.992996,0.069370,0.000000
51.510002,49.965309,-180.992996,-0.001919,0.002718,0.069031,222.256790,11.322301,0.690312,-180.992996,0.070002,0.000000
51.890003,50.377151,-181.126434,-0.001901,0.002738,0.069552,224.088760,11.415626,0.695520,-181.126434,0.070636,0.000000
52.270004,51.134560,-181.215393,-0.001893,0.002763,0.070185,227.457886,11.587257,0.701848,-181.215393,0.071269,0.000000
52.650002,52.504890,-181.215393,-0.001854,0.002794,0.070965,233.553421,11.897778,0.709653,-181.215393,0.071902,0.000000
53.030003,52.825500,-181.259872,-0.001832,0.002815,0.071503,234.979568,11.970429,0.715027,-181.259872,0.072535,0.000000
53.410004,53.591850,-181.304352,-0.001807,0.002841,0.072170,238.388458,12.144087,0.721704,-181.304352,0.073168,0.000000
53.790001,54.205887,-181.348831,-0.001776,0.002861,0.072674,241.119827,12.283229,0.726738,-181.348831,0.073801,0.000000
54.170002,54.306427,-181.393326,-0.001750,0.002882,0.073194,241.567047,12.306012,0.731938,-181.393326,0.074434,0.000000
54.550003,55.805603,-181.393326,-0.001733,0.002915,0.074044,248.235718,12.645730,0.740439,-181.393326,0.075067,0.000000
54.930004,56.921600,-181.437805,-0.001686,0.002942,0.074721,253.199921,12.898620,0.747206,-181.437805,0.075709,0.000000
55.310001,57.582565,-181.526764,-0.001673,0.002966,0.075327,256.140045,13.048396,0.753270,-181.526764,0.076342,0.000000
55.690002,58.164955,-181.615723,-0.001656,0.002989,0.075926,258.730652,13.180367,0.759257,-181.615723,0.076975,0.000000
56.070004,58.712341,-181.660202,-0.001625,0.003011,0.076481,261.165527,13.304407,0.764806,-181.660202,0.077609,0.000000
56.450005,59.947868,-181.615723,-0.001608,0.003040,0.077218,266.661438,13.584381,0.772179,-181.615723,0.078241,0.000000
56.830002,60.792412,-181.704681,-0.001574,0.003067,0.077895,270.418152,13.775758,0.778947,-181.704681,0.078874,0.000000
57.210003,61.539017,-181.704681,-0.001548,0.003091,0.078510,273.739227,13.944941,0.785101,-181.704681,0.079507,0.000000
57.590004,62.279671,-181.793640,-0.001522,0.003117,0.079169,277.033813,14.112775,0.791694,-181.793640,0.080141,0.000000
57.970001,62.713112,-181.838135,-0.001509,0.003136,0.079664,278.961853,14.210995,0.796637,-181.838135,0.080773,0.000000
58.350002,64.139671,-181.882614,-0.001475,0.003167,0.080444,285.307495,14.534257,0.804442,-181.882614,0.081406,0.000000
58.730003,64.567894,-181.838135,-0.001453,0.003191,0.081042,287.212341,14.631294,0.810422,-181.838135,0.082040,0.000000
59.110004,65.259026,-181.882614,-0.001423,0.003215,0.081649,290.286652,14.787907,0.816493,-181.882614,0.082673,0.000000
59.490002,65.844765,-182.016052,-0.001401,0.003236,0.082204,292.892151,14.920637,0.822041,-182.016052,0.083306,0.000000
59.870003,65.545753,-182.060532,-0.001371,0.003241,0.082326,291.562073,14.852880,0.823260,-182.060532,0.082595,0.000000
60.250004,66.955925,-182.105011,-0.001345,0.003098,0.078683,297.834839,15.172429,0.786834,-182.105011,294.500488,0.000000
60.630001,65.128685,-182.105011,-0.001328,0.003271,0.083072,289.706848,14.758371,0.830716,-182.105011,294.500488,0.000000
61.010002,65.291420,-182.193970,-0.001315,0.003292,0.083609,290.430756,14.795248,0.836091,-182.193970,294.500488,0.000000
61.390003,65.251198,-182.238449,-0.001285,0.003306,0.083974,290.251831,14.786133,0.839740,-182.238449,294.500488,0.000000
61.770004,65.124596,-182.282944,-0.001263,0.003321,0.084346,289.688660,14.757444,0.843464,-182.282944,294.500488,0.000000
62.150002,65.304451,-182.327423,-0.001259,0.003336,0.084737,290.488708,14.798200,0.847370,-182.327423,294.500488,0.000000
62.530003,65.224388,-182.327423,-0.001250,0.003352,0.085144,290.132568,14.780058,0.851442,-182.327423,294.500488,0.000000
62.910004,65.378548,-182.327423,-0.001212,0.003364,0.085448,290.818298,14.814991,0.854478,-182.327423,294.500488,0.000000
63.290005,65.255669,-182.416382,-0.001212,0.003376,0.085743,290.271698,14.787147,0.857430,-182.416382,294.500488,0.000000
63.670002,65.434029,-182.505341,-0.001181,0.003390,0.086098,291.065094,14.827562,0.860980,-182.505341,294.500488,0.000000
64.050003,64.901543,-182.460861,-0.001190,0.003396,0.086263,288.696472,14.706901,0.862631,-182.460861,294.500488,0.000000
64.430000,64.501991,-182.549820,-0.001173,0.003402,0.086411,286.919189,14.616361,0.864107,-182.549820,294.500488,0.000000
64.810005,65.876045,-182.549820,-0.001143,0.003351,0.085119,293.031281,14.927725,0.851185,-182.549820,294.500488,0.000000
65.190002,65.269447,-182.638779,-0.001138,0.003436,0.087269,290.333008,14.790268,0.872691,-182.638779,294.500488,0.000000
65.570000,64.932823,-182.683273,-0.001112,0.003431,0.087148,288.835632,14.713987,0.871480,-182.683273,294.500488,0.000000
65.950005,65.055702,-182.772232,-0.001108,0.003445,0.087503,289.382202,14.741833,0.875030,-182.772232,294.500488,0.000000
66.330002,65.222908,-182.772232,-0.001099,0.003456,0.087772,290.125977,14.779722,0.877717,-182.772232,294.500488,0.000000
66.710007,64.851646,-182.727753,-0.001082,0.003463,0.087972,288.474518,14.695593,0.879716,-182.727753,294.500488,0.000000
67.090004,65.249718,-182.816711,-0.001069,0.003476,0.088293,290.245239,14.785798,0.882925,-182.816711,294.500488,0.000000
67.470001,65.156242,-182.950150,-0.001056,0.003484,0.088501,289.829437,14.764615,0.885007,-182.950150,294.500488,0.000000
67.850006,65.057198,-182.905670,-0.001056,0.003492,0.088700,289.388855,14.742171,0.886998,-182.905670,294.500488,0.000000
68.230003,65.299980,-182.994629,-0.001043,0.003501,0.088917,290.468811,14.797187,0.889170,-182.994629,294.500488,0.000000
68.610001,64.518379,-182.950150,-0.001035,0.003501,0.088917,286.992096,14.620074,0.889170,-182.950150,294.500488,0.000000
68.990005,65.580757,-183.083588,-0.001018,0.003508,0.089108,291.717773,14.860812,0.891078,-183.083588,294.500488,0.000000
69.370003,65.052361,-183.083588,-0.001022,0.003522,0.089454,289.367340,14.741076,0.894545,-183.083588,294.500488,0.000000
69.750000,65.284340,-183.172562,-0.001026,0.003529,0.089645,290.399261,14.793643,0.896452,-183.172562,294.500488,0.000000
70.130005,66.040627,-183.172562,-0.001005,0.003539,0.089888,293.763367,14.965019,0.898882,-183.172562,294.500488,0.000000
70.510002,65.291420,-183.172562,-0.001000,0.003539,0.089897,290.430756,14.795248,0.898966,-183.172562,294.500488,0.000000
70.890007,64.608116,-183.217041,-0.000979,0.003540,0.089906,287.391266,14.640408,0.899056,-183.217041,294.500488,0.000000
71.270004,66.253624,-183.306000,-0.000966,0.003496,0.088795,294.710846,15.013286,0.887951,-183.306000,294.500488,0.000000
71.650002,65.566597,-183.350479,-0.000974,0.003509,0.089134,291.654785,14.857604,0.891335,-183.350479,294.500488,0.000000
72.030006,65.228111,-183.394958,-0.000974,0.003557,0.090356,290.149139,14.780901,0.903560,-183.394958,294.500488,0.000000
72.410004,65.159599,-183.350479,-0.000961,0.003565,0.090556,289.844360,14.765376,0.905559,-183.350479,294.500488,0.000000
72.790001,65.135017,-183.439438,-0.000957,0.003572,0.090729,289.735016,14.759806,0.907292,-183.439438,294.500488,0.000000
73.170006,65.185295,-183.483917,-0.000957,0.003578,0.090877,289.958679,14.771199,0.908768,-183.483917,294.500488,0.000000
73.550003,65.214333,-183.528397,-0.000953,0.003583,0.091015,290.087830,14.777779,0.910154,-183.528397,294.500488,0.000000
73.930000,65.239281,-183.572891,-0.000940,0.003588,0.091146,290.198822,14.783432,0.911456,-183.572891,294.500488,0.000000
74.310005,65.320839,-183.528397,-0.000936,0.003594,0.091293,290.561615,14.801914,0.912932,-183.528397,294.500488,0.000000
74.690002,65.469032,-183.661850,-0.000923,0.003603,0.091519,291.220795,14.835495,0.915188,-183.661850,294.500488,0.000000
75.070007,65.383400,-183.750809,-0.000918,0.003603,0.091510,290.839874,14.816090,0.915097,-183.750809,294.500488,0.000000
75.450005,65.245247,-183.706329,-0.000918,0.003608,0.091632,290.225342,14.784784,0.916315,-183.706329,294.500488,0.000000
75.830002,65.531593,-183.795288,-0.000927,0.003613,0.091778,291.499084,14.849671,0.917784,-183.795288,294.500488,0.000000
76.210007,65.278389,-183.750809,-0.000910,0.003614,0.091805,290.372772,14.792295,0.918049,-183.750809,294.500488,0.000000
76.590004,65.449669,-183.973221,-0.000901,0.003620,0.091943,291.134674,14.831106,0.919434,-183.973221,294.500488,0.000000
76.970001,65.149544,-183.884247,-0.000901,0.003620,0.091943,289.799652,14.763098,0.919434,-183.884247,294.500488,0.000000
77.350006,65.400154,-183.973221,-0.000918,0.003627,0.092117,290.914429,14.819886,0.921168,-183.973221,294.500488,0.000000
77.730003,65.131676,-184.017700,-0.000905,0.003627,0.092126,289.720154,14.759048,0.921259,-184.017700,294.500488,0.000000
78.110001,65.282478,-184.017700,-0.000892,0.003633,0.092290,290.390961,14.793221,0.922901,-184.017700,294.500488,0.000000
78.490005,65.096291,-184.062180,-0.000892,0.003633,0.092290,289.562775,14.751030,0.922901,-184.062180,294.500488,0.000000
78.870003,65.327904,-184.151138,-0.000884,0.003640,0.092446,290.593018,14.803514,0.924461,-184.151138,294.500488,0.000000
79.250000,65.116402,-184.240097,-0.000892,0.003640,0.092446,289.652222,14.755588,0.924461,-184.240097,294.500488,0.000000
79.630005,65.101128,-184.151138,-0.000880,0.003643,0.092541,289.584290,14.752126,0.925414,-184.151138,294.500488,0.000000
80.010002,65.161079,-184.240097,-0.000880,0.003647,0.092628,289.850952,14.765712,0.926285,-184.240097,294.500488,0.000000
80.390007,65.115654,-184.284576,-0.000862,0.003649,0.092681,289.648895,14.755418,0.926807,-184.284576,294.500488,0.000000
80.770004,64.996498,-184.329056,-0.000858,0.003651,0.092732,289.118866,14.728416,0.927322,-184.329056,294.500488,0.000000
81.150002,65.012886,-184.418030,-0.000888,0.003653,0.092794,289.191772,14.732131,0.927935,-184.418030,294.500488,0.000000
81.530006,66.211174,-184.418030,-0.000871,0.003664,0.093053,294.522003,15.003666,0.930532,-184.418030,294.500488,0.000000
81.910004,65.876793,-184.373535,-0.000858,0.003663,0.093045,293.034607,14.927895,0.930448,-184.373535,294.500488,0.000000
82.290001,65.584846,-184.506989,-0.000845,0.003663,0.093045,291.735962,14.861739,0.930448,-184.506989,294.500488,0.000000
82.670006,65.307426,-184.551468,-0.000867,0.003664,0.093053,290.501953,14.798875,0.930532,-184.551468,294.500488,0.000000
83.050003,65.038582,-184.595947,-0.000854,0.003664,0.093053,289.306061,14.737954,0.930532,-184.595947,294.500488,0.000000
83.430000,64.784248,-184.595947,-0.000858,0.003664,0.093071,288.174744,14.680321,0.930706,-184.595947,294.500488,0.000000
83.810005,64.550026,-184.684906,-0.000854,0.003664,0.093071,287.132843,14.627245,0.930706,-184.684906,294.500488,0.000000
84.190002,64.335915,-184.684906,-0.000836,0.003664,0.093071,286.180450,14.578727,0.930706,-184.684906,294.500488,0.000000
84.570007,66.088661,-184.773865,-0.000819,0.003474,0.088240,293.977051,14.975904,0.882403,-184.773865,294.500488,0.000000
84.950005,65.835457,-184.773865,-0.000828,0.003474,0.088240,292.850739,14.918528,0.882403,-184.773865,294.500488,0.000000
85.330002,65.578514,-184.862839,-0.000815,0.003507,0.089090,291.707794,14.860304,0.890904,-184.862839,294.500488,0.000000
85.710007,65.423241,-184.862839,-0.000824,0.003634,0.092299,291.017120,14.825118,0.922992,-184.862839,294.500488,0.000000
86.090004,65.186043,-184.907318,-0.000824,0.003634,0.092308,289.962006,14.771369,0.923075,-184.907318,294.500488,0.000000
86.470001,65.664528,-184.996277,-0.000815,0.003683,0.093539,292.090393,14.879795,0.935391,-184.996277,294.500488,0.000000
86.850006,65.493248,-185.040756,-0.000819,0.003683,0.093539,291.328522,14.840981,0.935391,-185.040756,294.500488,0.000000
87.230003,65.272804,-185.129715,-0.000828,0.003683,0.093557,290.347931,14.791029,0.935565,-185.129715,294.500488,0.000000
87.610001,65.492867,-185.040756,-0.000811,0.003692,0.093765,291.326813,14.840896,0.937647,-185.040756,294.500488,0.000000
87.990005,65.372215,-185.085236,-0.000811,0.003692,0.093765,290.790131,14.813556,0.937647,-185.085236,294.500488,0.000000
88.370003,65.287697,-185.174194,-0.000806,0.003693,0.093808,290.414185,14.794403,0.938079,-185.174194,294.500488,0.000000
88.750008,65.173378,-185.263168,-0.000815,0.003694,0.093825,289.905670,14.768499,0.938253,-185.263168,294.500488,0.000000
89.130005,65.227364,-185.218674,-0.000819,0.003697,0.093903,290.145813,14.780732,0.939032,-185.218674,294.500488,0.000000
89.510002,65.150291,-185.307648,-0.000824,0.003698,0.093929,289.802979,14.763268,0.939290,-185.307648,294.500488,0.000000
89.890007,65.203911,-185.307648,-0.000802,0.003702,0.094033,290.041473,14.775417,0.940334,-185.307648,294.500488,0.000000
90.270004,65.241142,-185.352127,-0.000811,0.003702,0.094042,290.207092,14.783854,0.940418,-185.352127,294.500488,0.000000
90.650002,65.221779,-185.441086,-0.000802,0.003704,0.094086,290.120972,14.779467,0.940857,-185.441086,294.500488,0.000000
91.030006,65.257530,-185.485565,-0.000824,0.003706,0.094137,290.279999,14.787567,0.941372,-185.485565,294.500488,0.000000
91.410004,65.258644,-185.441086,-0.000811,0.003708,0.094189,290.284943,14.787820,0.941894,-185.441086,294.500488,0.000000
91.790001,65.240395,-185.530045,-0.000789,0.003709,0.094207,290.203766,14.783685,0.942068,-185.530045,294.500488,0.000000
92.170006,65.240028,-185.619003,-0.000815,0.003711,0.094267,290.202148,14.783602,0.942674,-185.619003,294.500488,0.000000
92.550003,65.215080,-185.707977,-0.000798,0.003712,0.094276,290.091156,14.777948,0.942764,-185.707977,294.500488,0.000000
92.930008,65.202049,-185.663483,-0.000806,0.003713,0.094311,290.033203,14.774996,0.943113,-185.663483,294.500488,0.000000
93.310005,65.131676,-185.663483,-0.000806,0.003714,0.094328,289.720154,14.759048,0.943279,-185.663483,294.500488,0.000000
93.690002,65.195717,-185.752457,-0.000798,0.003716,0.094380,290.005035,14.773561,0.943801,-185.752457,294.500488,0.000000
94.070007,65.096672,-185.796936,-0.000806,0.003716,0.094380,289.564453,14.751117,0.943801,-185.796936,294.500488,0.000000
94.450005,65.075813,-185.930374,-0.000806,0.003718,0.094450,289.471680,14.746390,0.944498,-185.930374,294.500488,0.000000
94.830002,65.085869,-185.930374,-0.000798,0.003718,0.094450,289.516418,14.748669,0.944498,-185.930374,294.500488,0.000000
95.210007,65.008781,-185.885895,-0.000798,0.003719,0.094458,289.173492,14.731200,0.944581,-185.885895,294.500488,0.000000
95.590004,65.011391,-185.974854,-0.000776,0.003721,0.094510,289.185120,14.731791,0.945103,-185.974854,294.500488,0.000000
95.970001,65.041924,-185.974854,-0.000793,0.003724,0.094597,289.320923,14.738711,0.945974,-185.974854,294.500488,0.000000
96.350006,65.214333,-186.063812,-0.000789,0.003725,0.094615,290.087830,14.777779,0.946148,-186.063812,294.500488,0.000000
96.730003,65.135765,-186.108292,-0.000789,0.003725,0.094615,289.738342,14.759975,0.946148,-186.108292,294.500488,0.000000
97.110008,65.101128,-186.152786,-0.000785,0.003726,0.094631,289.584290,14.752126,0.946315,-186.152786,294.500488,0.000000
97.490005,65.184547,-186.197266,-0.000785,0.003729,0.094719,289.955353,14.771029,0.947185,-186.197266,294.500488,0.000000
97.870003,65.195717,-186.241745,-0.000789,0.003729,0.094719,290.005035,14.773561,0.947185,-186.241745,294.500488,0.000000
98.250008,65.116768,-186.330704,-0.000780,0.003729,0.094727,289.653839,14.755671,0.947268,-186.330704,294.500488,0.000000
98.630005,65.043037,-186.286224,-0.000789,0.003730,0.094744,289.325867,14.738962,0.947442,-186.286224,294.500488,0.000000
99.010002,65.009163,-186.330704,-0.000780,0.003732,0.094796,289.175201,14.731286,0.947965,-186.330704,294.500488,0.000000
99.390007,65.332008,-186.419662,-0.000776,0.003735,0.094874,290.611298,14.804445,0.948744,-186.419662,294.500488,0.000000
99.770004,65.297752,-186.464142,-0.000767,0.003735,0.094874,290.458923,14.796682,0.948744,-186.464142,294.500488,0.000000
100.150002,65.221413,-186.553116,-0.000763,0.003735,0.094874,290.119324,14.779383,0.948744,-186.553116,294.500488,0.000000
100.530006,65.209862,-186.508621,-0.000776,0.003737,0.094927,290.067963,14.776766,0.949267,-186.508621,294.500488,0.000000
100.910004,65.194221,-186.553116,-0.000789,0.003737,0.094927,289.998383,14.773222,0.949267,-186.553116,294.500488,0.000000
101.290009,65.103737,-186.553116,-0.000772,0.003739,0.094962,289.595886,14.752718,0.949615,-186.553116,294.500488,0.000000
101.670006,65.312263,-186.642075,-0.000772,0.003741,0.095022,290.523468,14.799971,0.950221,-186.642075,294.500488,0.000000
102.050003,65.266090,-186.775513,-0.000780,0.003741,0.095022,290.318085,14.789508,0.950221,-186.775513,294.500488,0.000000
102.430008,65.205772,-186.731033,-0.000776,0.003741,0.095022,290.049774,14.775839,0.950221,-186.731033,294.500488,0.000000
102.810005,65.269447,-186.686554,-0.000772,0.003743,0.095074,290.333008,14.790268,0.950743,-186.686554,294.500488,0.000000
103.190002,65.216576,-186.731033,-0.000772,0.003743,0.095074,290.097809,14.778287,0.950743,-186.731033,294.500488,0.000000
103.570007,65.153267,-186.908951,-0.000755,0.003743,0.095074,289.816193,14.763942,0.950743,-186.908951,294.500488,0.000000
103.950005,65.280617,-186.953430,-0.000772,0.003746,0.095152,290.382690,14.792799,0.951523,-186.953430,294.500488,0.000000
104.330002,65.252693,-186.908951,-0.000772,0.003746,0.095152,290.258484,14.786471,0.951523,-186.908951,294.500488,0.000000
104.710007,65.210991,-186.908951,-0.000763,0.003746,0.095161,290.072968,14.777021,0.951606,-186.908951,294.500488,0.000000
105.090004,65.140602,-186.997925,-0.000776,0.003748,0.095187,289.759857,14.761071,0.951871,-186.997925,294.500488,0.000000
105.470001,65.235939,-187.042404,-0.000759,0.003749,0.095213,290.183960,14.782675,0.952128,-187.042404,294.500488,0.000000
105.850006,65.202797,-187.086884,-0.000763,0.003749,0.095213,290.036530,14.775166,0.952128,-187.086884,294.500488,0.000000
106.230003,65.117149,-187.175842,-0.000772,0.003749,0.095213,289.655548,14.755756,0.952128,-187.175842,294.500488,0.000000
106.610008,65.355461,-187.175842,-0.000767,0.003753,0.095334,290.715607,14.809759,0.953339,-187.175842,294.500488,0.000000
106.990005,65.359566,-187.175842,-0.000755,0.003753,0.095334,290.733856,14.810689,0.953339,-187.175842,294.500488,0.000000
107.370003,65.322701,-187.309280,-0.000759,0.003753,0.095334,290.569885,14.802335,0.953339,-187.309280,294.500488,0.000000
107.750008,65.273537,-187.309280,-0.000763,0.003753,0.095334,290.351196,14.791195,0.953339,-187.309280,294.500488,0.000000
108.130005,65.234077,-187.309280,-0.000763,0.003754,0.095343,290.175659,14.782253,0.953430,-187.309280,294.500488,0.000000
108.510002,65.201668,-187.398254,-0.000759,0.003754,0.095343,290.031494,14.774909,0.953430,-187.398254,294.500488,0.000000
108.890007,65.115288,-187.442734,-0.000767,0.003754,0.095351,289.647278,14.755335,0.953513,-187.442734,294.500488,0.000000
109.270004,65.065758,-187.531693,-0.000767,0.003754,0.095351,289.426941,14.744112,0.953513,-187.531693,294.500488,0.000000
109.650002,65.105598,-187.487213,-0.000746,0.003756,0.095413,289.604156,14.753139,0.954127,-187.487213,294.500488,0.000000
110.030006,65.092949,-187.487213,-0.000767,0.003756,0.095413,289.547913,14.750273,0.954127,-187.487213,294.500488,0.000000
110.410004,65.060173,-187.531693,-0.000750,0.003756,0.095413,289.402100,14.742846,0.954127,-187.531693,294.500488,0.000000
110.790009,65.092201,-187.665131,-0.000755,0.003758,0.095447,289.544586,14.750103,0.954467,-187.665131,294.500488,0.000000
111.170006,65.097786,-187.709610,-0.000755,0.003759,0.095473,289.569427,14.751369,0.954732,-187.709610,294.500488,0.000000
111.550003,65.081764,-187.754089,-0.000759,0.003759,0.095473,289.498138,14.747739,0.954732,-187.754089,294.500488,0.000000
111.930008,65.034859,-187.754089,-0.000759,0.003759,0.095473,289.289490,14.737109,0.954732,-187.754089,294.500488,0.000000
112.310005,65.005440,-187.754089,-0.000746,0.003759,0.095482,289.158630,14.730443,0.954815,-187.754089,294.500488,0.000000
112.690002,64.976768,-187.798569,-0.000742,0.003759,0.095491,289.031097,14.723947,0.954906,-187.798569,294.500488,0.000000
113.070007,64.936546,-187.932022,-0.000737,0.003759,0.095491,288.852173,14.714832,0.954906,-187.932022,294.500488,0.000000
113.450005,64.871010,-187.976501,-0.000742,0.003759,0.095491,288.560669,14.699981,0.954906,-187.976501,294.500488,0.000000
113.830002,64.815895,-187.932022,-0.000759,0.003759,0.095491,288.315491,14.687491,0.954906,-187.932022,294.500488,0.000000
114.210007,64.771217,-187.932022,-0.000742,0.003759,0.095491,288.116760,14.677368,0.954906,-187.932022,294.500488,0.000000
114.590004,65.867851,-188.020981,-0.000742,0.003771,0.095794,292.994843,14.925869,0.957942,-188.020981,294.500488,0.000000
114.970009,65.859657,-188.109940,-0.000746,0.003771,0.095794,292.958374,14.924011,0.957942,-188.109940,294.500488,0.000000
115.350006,65.832848,-188.154419,-0.000737,0.003771,0.095794,292.839142,14.917937,0.957942,-188.154419,294.500488,0.000000
115.730003,65.818703,-188.198898,-0.000755,0.003771,0.095794,292.776215,14.914731,0.957942,-188.198898,294.500488,0.000000
116.110008,65.767311,-188.287872,-0.000750,0.003771,0.095794,292.547607,14.903086,0.957942,-188.287872,294.500488,0.000000
116.490005,65.712196,-188.243378,-0.000733,0.003771,0.095794,292.302460,14.890596,0.957942,-188.243378,294.500488,0.000000
116.870003,65.619102,-188.332352,-0.000733,0.003771,0.095794,291.888336,14.869501,0.957942,-188.332352,294.500488,0.000000
117.250008,65.581871,-188.376831,-0.000742,0.003771,0.095794,291.722717,14.861064,0.957942,-188.376831,294.500488,0.000000
117.630005,65.547981,-188.421310,-0.000737,0.003771,0.095794,291.571991,14.853385,0.957942,-188.421310,294.500488,0.000000
118.010002,65.495476,-188.421310,-0.000742,0.003771,0.095794,291.338440,14.841487,0.957942,-188.421310,294.500488,0.000000
118.390007,65.441109,-188.465790,-0.000742,0.003771,0.095794,291.096588,14.829167,0.957942,-188.465790,294.500488,0.000000
118.770004,65.359932,-188.510269,-0.000742,0.003771,0.095794,290.735504,14.810773,0.957942,-188.510269,294.500488,0.000000
119.150009,65.312263,-188.599228,-0.000742,0.003771,0.095794,290.523468,14.799971,0.957942,-188.599228,294.500488,0.000000
119.530006,65.263863,-188.688202,-0.000742,0.003771,0.095794,290.308167,14.789002,0.957942,-188.688202,294.500488,0.000000
119.910004,65.224388,-188.643707,-0.000742,0.003772,0.095803,290.132568,14.780058,0.958025,-188.643707,294.500488,0.000000
120.290009,65.167793,-188.688202,-0.000729,0.003772,0.095803,289.880829,14.767234,0.958025,-188.688202,294.500488,0.000000
120.670006,65.094063,-188.732681,-0.000733,0.003764,0.095603,289.552856,14.750525,0.956034,-188.732681,0.095516,0.000000
121.050003,64.999474,-188.777161,-0.000742,0.003748,0.095195,289.132111,14.729092,0.951954,-188.777161,0.094884,0.000000
121.430008,64.863564,-188.821640,-0.000737,0.003728,0.094693,288.527527,14.698294,0.946928,-188.821640,0.094250,0.000000
121.810005,64.772331,-188.910599,-0.000711,0.003710,0.094224,288.121704,14.677621,0.942242,-188.910599,0.093617,0.000000
122.190002,64.658760,-188.866119,-0.000742,0.003681,0.093504,287.616516,14.651884,0.935043,-188.866119,0.092984,0.000000
122.570007,64.612587,-188.955078,-0.000720,0.003655,0.092845,287.411133,14.641421,0.928450,-188.955078,0.092351,0.000000
122.950005,64.532524,-188.999557,-0.000746,0.003633,0.092282,287.054993,14.623279,0.922818,-188.999557,0.091718,0.000000
123.330009,64.493416,-189.044037,-0.000750,0.003613,0.091770,286.881042,14.614417,0.917701,-189.044037,0.091085,0.000000
123.710007,64.356758,-189.044037,-0.000737,0.003590,0.091189,286.273163,14.583450,0.911887,-189.044037,0.090451,0.000000
124.090004,64.300529,-189.044037,-0.000729,0.003560,0.090426,286.023041,14.570708,0.904257,-189.044037,0.089819,0.000000
124.470009,63.887199,-189.133011,-0.000729,0.003533,0.089749,284.184448,14.477047,0.897489,-189.133011,0.089186,0.000000
124.850006,63.257515,-189.177490,-0.000716,0.003518,0.089350,281.383484,14.334357,0.893500,-189.177490,0.088552,0.000000
125.230003,62.421173,-189.221970,-0.000724,0.003495,0.088760,277.663239,14.144840,0.887603,-189.221970,0.087919,0.000000
125.610008,61.232933,-189.266449,-0.000707,0.003474,0.088240,272.377686,13.875581,0.882403,-189.266449,0.087286,0.000000
125.990005,59.633965,-189.355408,-0.000698,0.003448,0.087573,265.265137,13.513249,0.875726,-189.355408,0.086654,0.000000
126.370003,57.653313,-189.310928,-0.000711,0.003419,0.086853,256.454742,13.064427,0.868527,-189.310928,0.086020,0.000000
126.750008,56.030518,-189.444366,-0.000703,0.003401,0.086376,249.236191,12.696697,0.863758,-189.444366,0.085387,0.000000
127.130005,53.687920,-189.444366,-0.000724,0.003372,0.085656,238.815796,12.165856,0.856560,-189.444366,0.084754,0.000000
127.510010,51.824570,-189.488846,-0.000716,0.003354,0.085179,230.527206,11.743615,0.851791,-189.488846,0.084121,0.000000
127.890007,50.162292,-189.444366,-0.000711,0.003334,0.084676,223.133026,11.366938,0.846757,-189.444366,0.083488,0.000000
128.270004,46.535759,-189.577820,-0.000711,0.003304,0.083913,207.001389,10.545154,0.839126,-189.577820,0.082855,0.000000
128.650009,43.616730,-189.666779,-0.000707,0.003276,0.083210,194.016907,9.883692,0.832102,-189.666779,0.082222,0.000000
129.029999,40.971024,-189.666779,-0.000707,0.003249,0.082534,182.248215,9.284166,0.825342,-189.666779,0.081580,0.000000
129.410004,40.219208,-189.666779,-0.000707,0.003247,0.082474,178.903976,9.113803,0.824736,-189.666779,0.080947,0.000000
129.790009,35.795792,-189.711258,-0.000707,0.003202,0.081337,159.227631,8.111443,0.813374,-189.711258,0.080314,0.000000
130.170013,33.099815,-189.755737,-0.000703,0.003176,0.080678,147.235336,7.500525,0.806781,-189.755737,0.079681,0.000000
130.550003,30.337929,-189.844696,-0.000711,0.003151,0.080045,134.949844,6.874673,0.800452,-189.844696,0.079048,0.000000
130.930008,27.792763,-189.889175,-0.000707,0.003128,0.079456,123.628380,6.297930,0.794555,-189.889175,0.078415,0.000000
131.310013,26.578087,-189.844696,-0.000707,0.003119,0.079213,118.225235,6.022681,0.792126,-189.844696,0.077782,0.000000
131.690002,22.805206,-189.889175,-0.000711,0.003078,0.078172,101.442627,5.167734,0.781717,-189.889175,0.077148,0.000000
132.070007,20.010551,-189.978149,-0.000716,0.003052,0.077512,89.011375,4.534456,0.775124,-189.978149,0.076515,0.000000
132.450012,16.614517,-190.067108,-0.000716,0.003024,0.076802,73.905067,3.764903,0.768016,-190.067108,0.075883,0.000000
132.830002,14.501678,-190.111588,-0.000707,0.003006,0.076350,64.506691,3.286127,0.763504,-190.111588,0.075249,0.000000
133.210007,11.532753,-190.111588,-0.000711,0.002977,0.075605,51.300247,2.613359,0.756048,-190.111588,0.074616,0.000000
133.590012,9.140999,-190.111588,-0.000716,0.002954,0.075033,40.661194,2.071380,0.750325,-190.111588,0.073983,0.000000
133.970001,7.117157,-190.200546,-0.000716,0.002933,0.074503,31.658695,1.612771,0.745034,-190.200546,0.073350,0.000000
134.350006,3.772507,-190.245026,-0.000716,0.002899,0.073645,16.780949,0.854862,0.736450,-190.245026,0.072717,0.000000
134.730011,1.460449,-190.245026,-0.000742,0.002874,0.073003,6.496403,0.330943,0.730031,-190.245026,0.072084,0.000000
135.110001,-0.621490,-190.333984,-0.000750,0.002851,0.072413,-2.764528,-0.140832,0.724134,-190.333984,0.071450,0.000000
135.490005,-2.516491,-190.378464,-0.000746,0.002828,0.071841,-11.193911,-0.570245,0.718411,-190.378464,0.070818,0.000000
135.870010,-0.374229,-190.378464,-0.000819,0.002804,0.071234,-1.664656,-0.084802,0.712340,-190.378464,0.070185,0.000000
136.250000,-0.146339,-190.422958,-0.000841,0.002775,0.070497,-0.650950,-0.033161,0.704967,-190.422958,0.069552,0.000000
136.630005,-0.015640,-190.511917,-0.000901,0.002755,0.069968,-0.069571,-0.003544,0.699676,-190.511917,0.068918,0.000000
137.010010,0.033142,-190.511917,-0.000927,0.002731,0.069370,0.147423,0.007510,0.693696,-190.511917,0.068286,0.000000
137.389999,0.016014,-190.511917,-0.000966,0.002702,0.068624,0.071234,0.003629,0.686239,-190.511917,0.067653,0.000000
137.770004,-0.044312,-190.600876,-0.000992,0.002676,0.067982,-0.197107,-0.010041,0.679820,-190.600876,0.067019,0.000000
138.150009,-0.014893,-190.600876,-0.001043,0.002651,0.067340,-0.066245,-0.003375,0.673401,-190.600876,0.066386,0.000000
138.530014,-0.009308,-190.689835,-0.001074,0.002624,0.066647,-0.041403,-0.002109,0.666467,-190.689835,0.065753,0.000000
138.910004,-0.032021,-190.734314,-0.001095,0.002603,0.066126,-0.142435,-0.007256,0.661259,-190.734314,0.065120,0.000000
139.290009,-0.030159,-190.778793,-0.001155,0.002577,0.065450,-0.134154,-0.006834,0.654499,-190.778793,0.064487,0.000000
139.670013,0.001488,-190.689835,-0.001164,0.002558,0.064981,0.006618,0.000337,0.649813,-190.689835,0.063845,0.000000
140.050003,-0.010422,-190.867767,-0.001233,0.002525,0.064140,-0.046358,-0.002362,0.641403,-190.867767,0.063212,0.000000
140.430008,-0.044312,-190.956726,-0.001246,0.002505,0.063620,-0.197107,-0.010041,0.636195,-190.956726,0.062579,0.000000
140.810013,-0.038353,-191.001205,-0.001281,0.002480,0.062987,-0.170603,-0.008691,0.629867,-191.001205,0.061946,0.000000
141.190002,-0.046921,-190.912247,-0.001324,0.002449,0.062206,-0.208714,-0.010632,0.622063,-190.912247,0.061313,0.000000
141.570007,-0.008194,-191.001205,-0.001358,0.002434,0.061833,-0.036449,-0.001857,0.618331,-191.001205,0.060680,0.000000
141.950012,-0.042076,-191.045685,-0.001388,0.002402,0.061018,-0.187164,-0.009535,0.610178,-191.045685,0.060047,0.000000
142.330002,-0.011917,-191.134644,-0.001414,0.002384,0.060541,-0.053010,-0.002700,0.605409,-191.134644,0.059414,0.000000
142.710007,-0.029419,-191.179123,-0.001462,0.002360,0.059934,-0.130862,-0.006666,0.599338,-191.179123,0.058781,0.000000
143.090012,-0.041328,-191.179123,-0.001513,0.002329,0.059162,-0.183838,-0.009365,0.591624,-191.179123,0.058147,0.000000
143.470001,-0.033142,-191.223602,-0.001526,0.002310,0.058676,-0.147423,-0.007510,0.586765,-191.223602,0.057515,0.000000
143.850006,-0.077827,-191.223602,-0.001569,0.002280,0.057922,-0.346194,-0.017636,0.579218,-191.223602,0.056882,0.000000
144.230011,-0.077454,-191.312576,-0.001613,0.002254,0.057263,-0.344531,-0.017551,0.572632,-191.312576,0.056248,0.000000
144.610001,-0.076332,-191.401535,-0.001643,0.002228,0.056596,-0.339542,-0.017297,0.565955,-191.401535,0.055615,0.000000
144.990005,-0.065163,-191.446014,-0.001673,0.002212,0.056197,-0.289858,-0.014766,0.561966,-191.446014,0.054982,0.000000
145.370010,-0.090485,-191.446014,-0.001720,0.002184,0.055468,-0.402496,-0.020504,0.554676,-191.446014,0.054349,0.000000
145.750000,-0.072609,-191.490494,-0.001845,0.002150,0.054618,-0.322981,-0.016453,0.546183,-191.490494,0.053716,0.000000
146.130005,-0.091972,-191.579453,-0.001880,0.002128,0.054054,-0.409113,-0.020841,0.540544,-191.579453,0.053083,0.000000
146.510010,-0.070747,-191.579453,-0.001914,0.002106,0.053482,-0.314700,-0.016032,0.534821,-191.579453,0.052450,0.000000
146.889999,-0.096817,-191.623932,-0.001953,0.002078,0.052788,-0.430664,-0.021939,0.527879,-191.623932,0.051817,0.000000
147.270004,-0.089737,-191.623932,-0.001988,0.002056,0.052233,-0.399170,-0.020335,0.522331,-191.623932,0.051184,0.000000
147.650009,-0.106873,-191.579453,-0.002018,0.002027,0.051478,-0.475393,-0.024218,0.514784,-191.579453,0.050551,0.000000
148.030014,-0.087509,-191.668411,-0.002039,0.002003,0.050880,-0.389260,-0.019830,0.508803,-191.668411,0.049917,0.000000
148.410004,-0.056602,-191.757385,-0.002074,0.001975,0.050160,-0.251780,-0.012826,0.501605,-191.757385,0.049285,0.000000
148.790009,-0.067024,-191.846344,-0.002100,0.001956,0.049692,-0.298139,-0.015188,0.496919,-191.846344,0.048652,0.000000
149.170013,-0.068886,-191.757385,-0.002126,0.001933,0.049102,-0.306419,-0.015610,0.491022,-191.757385,0.048018,0.000000
149.550003,-0.080055,-191.846344,-0.002156,0.001905,0.048391,-0.356103,-0.018141,0.483914,-191.846344,0.047385,0.000000
149.930008,-0.061066,-191.890823,-0.002195,0.001878,0.047689,-0.271634,-0.013838,0.476889,-191.890823,0.046753,0.000000
150.310013,-0.059204,-192.024261,-0.002220,0.001855,0.047117,-0.263353,-0.013416,0.471166,-192.024261,0.046119,0.000000
150.690002,-0.048409,-191.979782,-0.002220,0.001845,0.046856,-0.215332,-0.010970,0.468562,-191.979782,0.045478,0.000000
151.070007,-0.061440,-192.024261,-0.002264,0.001818,0.046180,-0.273297,-0.013922,0.461803,-192.024261,0.044844,0.000000
151.450012,-0.053246,-192.068741,-0.002311,0.001778,0.045165,-0.236848,-0.012066,0.451652,-192.068741,0.044211,0.000000
151.830002,-0.026810,-192.068741,-0.002333,0.001753,0.044515,-0.119255,-0.006075,0.445149,-192.068741,0.043579,0.000000
152.210007,-0.052132,-192.157715,-0.002350,0.001730,0.043943,-0.231893,-0.011813,0.439426,-192.157715,0.042945,0.000000
152.590012,-0.070007,-192.246674,-0.002367,0.001709,0.043396,-0.311408,-0.015864,0.433961,-192.246674,0.042312,0.000000
152.970001,-0.073730,-192.246674,-0.002406,0.001684,0.042763,-0.327969,-0.016708,0.427633,-192.246674,0.041679,0.000000
153.350006,-0.037239,-192.246674,-0.002445,0.001652,0.041956,-0.165648,-0.008438,0.419563,-192.246674,0.041046,0.000000
153.730011,-0.046173,-192.335632,-0.002462,0.001626,0.041298,-0.205388,-0.010463,0.412977,-192.335632,0.040413,0.000000
154.110001,-0.052872,-192.380112,-0.002488,0.001607,0.040829,-0.235185,-0.011981,0.408292,-192.380112,0.039780,0.000000
154.490005,-0.055481,-192.380112,-0.002527,0.001578,0.040084,-0.246792,-0.012572,0.400836,-192.380112,0.039146,0.000000
154.870010,-0.043564,-192.424591,-0.002557,0.001563,0.039702,-0.193782,-0.009872,0.397020,-192.424591,0.038514,0.000000
155.100006,-0.025322,-192.469070,-0.002548,0.001551,0.039398,-0.112638,-0.005738,0.393985,-192.469070,0.039294,0.000000