File: Data/compression 19/AutoNoHeating-17-19-reverse-1-1_09112024_155104.csv
Time (sec),S:Load (lbs),S:HL1 (DIM),S:LVDT (in),S:Position (in),Ch:Position (mm),Ch:Load (N),Ch:Stress (MPa),Ch:Strain (mm/mm),Ch:HL1 (DIM),Set Point (),Cycles ()
0.210000,-0.013405,-120.676819,-0.009278,-0.009277,-0.235634,-0.059628,-0.003038,-2.356339,-120.676819,-0.235408,0.000000
0.580000,0.004845,-120.765785,-0.009265,-0.009185,-0.233310,0.021550,0.001098,-2.333100,-120.765785,-0.232443,0.000000
0.950000,-0.025322,-120.854744,-0.009106,-0.008961,-0.227603,-0.112638,-0.005738,-2.276031,-120.854744,-0.226268,0.000000
1.320000,-0.084526,-120.899223,-0.008873,-0.008716,-0.221385,-0.375991,-0.019154,-2.213853,-120.899223,-0.220111,0.000000
1.690000,0.003357,-120.854744,-0.008623,-0.008469,-0.215115,0.014932,0.000761,-2.151153,-120.854744,-0.213953,0.000000
2.060000,0.003723,-120.943703,-0.008360,-0.008227,-0.208958,0.016561,0.000844,-2.089580,-120.943703,-0.207779,0.000000
2.430000,0.018990,-121.032669,-0.008140,-0.007989,-0.202922,0.084470,0.004303,-2.029218,-121.032669,-0.201621,0.000000
2.800000,-0.009308,-121.077148,-0.007881,-0.007743,-0.196678,-0.041403,-0.002109,-1.966783,-121.077148,-0.195447,0.000000
3.170000,-0.005959,-121.121628,-0.007618,-0.007494,-0.190348,-0.026505,-0.001350,-1.903477,-121.121628,-0.189289,0.000000
3.540000,-0.002602,-121.166107,-0.007381,-0.007264,-0.184511,-0.011573,-0.000590,-1.845106,-121.166107,-0.183132,0.000000
3.910000,0.034264,-121.299553,-0.007127,-0.007017,-0.178241,0.152412,0.007764,-1.782405,-121.299553,-0.176957,0.000000
4.280000,0.040588,-121.344032,-0.006873,-0.006774,-0.172058,0.180546,0.009197,-1.720575,-121.344032,-0.170800,0.000000
4.650000,0.029045,-121.388512,-0.006610,-0.006527,-0.165779,0.129199,0.006582,-1.657792,-121.388512,-0.164626,0.000000
5.020000,0.009308,-121.432999,-0.006368,-0.006291,-0.159795,0.041403,0.002109,-1.597952,-121.432999,-0.158468,0.000000
5.390000,-0.017128,-121.477478,-0.006118,-0.006043,-0.153490,-0.076189,-0.003881,-1.534904,-121.477478,-0.152311,0.000000
5.760000,-0.036865,-121.566437,-0.005877,-0.005804,-0.147419,-0.163985,-0.008354,-1.474194,-121.566437,-0.146136,0.000000
6.130000,0.013039,-121.521957,-0.005635,-0.005558,-0.141176,0.057999,0.002955,-1.411758,-121.521957,-0.139979,0.000000
6.500000,0.031654,-121.699883,-0.005389,-0.005314,-0.134975,0.140806,0.007173,-1.349747,-121.699883,-0.133804,0.000000
6.870000,0.032768,-121.744362,-0.005126,-0.005065,-0.128661,0.145760,0.007425,-1.286615,-121.744362,-0.127647,0.000000
7.240000,0.026810,-121.788841,-0.004889,-0.004829,-0.122669,0.119255,0.006075,-1.226692,-121.788841,-0.121490,0.000000
7.610000,0.081924,-121.744362,-0.004786,-0.000001,-0.000034,0.364418,0.018564,-0.000341,-121.744362,0.000191,0.000000
7.980000,0.109108,-121.922287,-0.004799,-0.000001,-0.000034,0.485336,0.024724,-0.000341,-121.922287,0.000356,0.000000
8.350000,0.113205,-121.966766,-0.004799,-0.000001,-0.000026,0.503561,0.025653,-0.000257,-121.966766,0.000971,0.000000
8.720000,0.120651,-122.011246,-0.004794,-0.000001,-0.000026,0.536684,0.027340,-0.000257,-122.011246,0.001587,0.000000
9.090000,0.367165,-122.055733,-0.004751,0.000054,0.001370,1.633230,0.083201,0.013701,-122.055733,0.002203,0.000000
9.460000,0.504570,-122.055733,-0.004734,0.000075,0.001908,2.244440,0.114337,0.019083,-122.055733,0.002819,0.000000
9.830001,0.653885,-122.189171,-0.004721,0.000096,0.002437,2.908625,0.148172,0.024375,-122.189171,0.003434,0.000000
10.200001,1.029984,-122.278137,-0.004687,0.000124,0.003157,4.581595,0.233398,0.031574,-122.278137,0.004051,0.000000
10.570001,1.250427,-122.322617,-0.004682,0.000143,0.003625,5.562178,0.283351,0.036252,-122.322617,0.004666,0.000000
10.940001,1.541252,-122.322617,-0.004661,0.000165,0.004189,6.855832,0.349253,0.041891,-122.322617,0.005291,0.000000
11.310000,2.003365,-122.411575,-0.004631,0.000194,0.004917,8.911410,0.453969,0.049173,-122.411575,0.005906,0.000000
11.680000,2.356750,-122.456055,-0.004618,0.000219,0.005559,10.483350,0.534047,0.055593,-122.456055,0.006522,0.000000
12.050000,2.838966,-122.589500,-0.004609,0.000241,0.006132,12.628353,0.643319,0.061315,-122.589500,0.007138,0.000000
12.420001,3.161819,-122.589500,-0.004570,0.000264,0.006695,14.064475,0.716479,0.066955,-122.589500,0.007753,0.000000
12.790001,3.667130,-122.722946,-0.004566,0.000284,0.007207,16.312206,0.830983,0.072072,-122.722946,0.008369,0.000000
13.160001,4.325851,-122.722946,-0.004531,0.000317,0.008048,19.242348,0.980252,0.080482,-122.722946,0.008985,0.000000
13.530001,4.487465,-122.678467,-0.004510,0.000332,0.008430,19.961241,1.016874,0.084297,-122.678467,0.009601,0.000000
13.900001,5.250084,-122.811905,-0.004488,0.000363,0.009228,23.353540,1.189686,0.092276,-122.811905,0.010216,0.000000
14.270000,5.793373,-122.945351,-0.004480,0.000388,0.009860,25.770210,1.312797,0.098604,-122.945351,0.010841,0.000000
14.640000,6.190323,-122.989830,-0.004449,0.000409,0.010381,27.535931,1.402747,0.103812,-122.989830,0.011456,0.000000
15.010001,6.719460,-123.034309,-0.004437,0.000434,0.011022,29.889648,1.522651,0.110224,-123.034309,0.012072,0.000000
15.380001,7.364784,-123.034309,-0.004411,0.000463,0.011751,32.760197,1.668884,0.117513,-123.034309,0.012688,0.000000
15.750001,7.695076,-123.167755,-0.004406,0.000484,0.012289,34.229408,1.743729,0.122888,-123.167755,0.013304,0.000000
16.120001,8.324387,-123.256714,-0.004368,0.000510,0.012956,37.028721,1.886333,0.129565,-123.256714,0.013919,0.000000
16.490002,8.623032,-123.256714,-0.004355,0.000530,0.013460,38.357159,1.954007,0.134598,-123.256714,0.014535,0.000000
16.860001,9.260902,-123.390160,-0.004329,0.000555,0.014101,41.194550,2.098550,0.141010,-123.390160,0.015151,0.000000
17.230001,9.774033,-123.390160,-0.004307,0.000582,0.014778,43.477070,2.214827,0.147777,-123.390160,0.015766,0.000000
17.600000,10.209709,-123.434639,-0.004294,0.000605,0.015367,45.415054,2.313553,0.153674,-123.434639,0.016391,0.000000
17.970001,10.626770,-123.479118,-0.004273,0.000628,0.015940,47.270233,2.408060,0.159397,-123.479118,0.017006,0.000000
18.340000,11.097816,-123.612564,-0.004243,0.000651,0.016547,49.365555,2.514801,0.165468,-123.612564,0.017622,0.000000
18.710001,11.387527,-123.657043,-0.004225,0.000670,0.017015,50.654251,2.580451,0.170154,-123.657043,0.018238,0.000000
19.080002,12.316597,-123.701523,-0.004204,0.000706,0.017926,54.786961,2.790981,0.179260,-123.701523,0.018854,0.000000
19.450001,12.486397,-123.746002,-0.004174,0.000728,0.018481,55.542267,2.829458,0.184809,-123.746002,0.019469,0.000000
19.820002,13.099319,-123.746002,-0.004178,0.000757,0.019218,58.268684,2.968348,0.192182,-123.746002,0.020085,0.000000
20.190001,13.368546,-123.923927,-0.004148,0.000776,0.019712,59.466259,3.029356,0.197125,-123.923927,0.020701,0.000000
20.560001,13.436691,-123.923927,-0.004126,0.000791,0.020102,59.769386,3.044798,0.201023,-123.923927,0.021317,0.000000
20.930000,14.457733,-123.968414,-0.004096,0.000827,0.021005,64.311211,3.276169,0.210047,-123.968414,0.021941,0.000000
21.300001,14.721748,-124.012894,-0.004083,0.000850,0.021585,65.485611,3.335996,0.215853,-124.012894,0.022556,0.000000
21.670000,15.023743,-124.012894,-0.004053,0.000871,0.022123,66.828941,3.404429,0.221235,-124.012894,0.023173,0.000000
22.040001,15.485855,-124.101852,-0.004040,0.000897,0.022774,68.884521,3.509145,0.227737,-124.101852,0.023788,0.000000
22.410002,15.692894,-124.190819,-0.004018,0.000918,0.023320,69.805481,3.556061,0.233203,-124.190819,0.024404,0.000000
22.780001,15.524208,-124.324257,-0.004010,0.000927,0.023554,69.055130,3.517836,0.235542,-124.324257,0.025020,0.000000
23.150002,16.788788,-124.324257,-0.003971,0.000968,0.024586,74.680260,3.804394,0.245859,-124.324257,0.025636,0.000000
23.520000,17.120941,-124.368736,-0.003958,0.000994,0.025245,76.157753,3.879661,0.252452,-124.368736,0.026251,0.000000
23.890001,17.752861,-124.413223,-0.003932,0.001023,0.025973,78.968666,4.022856,0.259735,-124.413223,0.026867,0.000000
24.260000,17.667587,-124.546661,-0.003915,0.001040,0.026407,78.589355,4.003532,0.264072,-124.546661,0.027491,0.000000
24.630001,18.703529,-124.591141,-0.003893,0.001073,0.027257,83.197456,4.238280,0.272573,-124.591141,0.028107,0.000000
25.000002,18.535217,-124.635628,-0.003867,0.001092,0.027734,82.448761,4.200140,0.277342,-124.635628,0.028723,0.000000
25.370001,18.670387,-124.680107,-0.003846,0.001114,0.028289,83.050034,4.230770,0.282891,-124.680107,0.029338,0.000000
25.740002,18.662941,-124.724586,-0.003837,0.001130,0.028697,83.016907,4.229083,0.286971,-124.724586,0.029954,0.000000
26.110001,19.333206,-124.769066,-0.003816,0.001156,0.029373,85.998398,4.380967,0.293731,-124.769066,0.030570,0.000000
26.480001,20.071625,-124.813545,-0.003790,0.001186,0.030136,89.283043,4.548295,0.301361,-124.813545,0.031186,0.000000
26.850000,20.537834,-124.902512,-0.003777,0.001214,0.030848,91.356850,4.653940,0.308477,-124.902512,0.031801,0.000000
27.220001,20.341217,-124.902512,-0.003755,0.001234,0.031342,90.482254,4.609385,0.313420,-124.902512,0.032417,0.000000
27.590002,20.864403,-124.902512,-0.003729,0.001259,0.031975,92.809502,4.727942,0.319748,-124.902512,0.033041,0.000000
27.960001,20.639862,-125.080437,-0.003729,0.001279,0.032478,91.810692,4.677060,0.324782,-125.080437,0.033658,0.000000
28.330002,21.431152,-125.169395,-0.003699,0.001306,0.033172,95.330528,4.856369,0.331716,-125.169395,0.034273,0.000000
28.700001,22.384056,-125.213875,-0.003673,0.001340,0.034039,99.569252,5.072299,0.340391,-125.213875,0.034888,0.000000
29.070002,22.124512,-125.213875,-0.003652,0.001360,0.034542,98.414742,5.013486,0.345417,-125.213875,0.035505,0.000000
29.440001,22.209412,-125.258362,-0.003635,0.001380,0.035045,98.792397,5.032724,0.350451,-125.258362,0.036120,0.000000
29.810001,22.752701,-125.347321,-0.003622,0.001406,0.035704,101.209068,5.155836,0.357037,-125.347321,0.036736,0.000000
30.180002,23.075554,-125.436279,-0.003609,0.001427,0.036250,102.645187,5.228995,0.362502,-125.436279,0.037352,0.000000
30.550001,23.945412,-125.525246,-0.003570,0.001461,0.037118,106.514511,5.426108,0.371177,-125.525246,0.037968,0.000000
30.920002,23.765930,-125.480766,-0.003561,0.001482,0.037655,105.716141,5.385437,0.376552,-125.480766,0.038592,0.000000
31.290001,23.816574,-125.525246,-0.003523,0.001504,0.038193,105.941414,5.396913,0.381926,-125.525246,0.039208,0.000000
31.660002,24.228043,-125.614204,-0.003518,0.001526,0.038748,107.771713,5.490153,0.387482,-125.614204,0.039823,0.000000
32.030003,24.535622,-125.703171,-0.003501,0.001550,0.039364,109.139893,5.559851,0.393637,-125.703171,0.040439,0.000000
32.400002,25.005554,-125.792130,-0.003497,0.001575,0.040014,111.230263,5.666340,0.400139,-125.792130,0.041055,0.000000
32.770000,25.447563,-125.792130,-0.003471,0.001602,0.040691,113.196411,5.766500,0.406906,-125.792130,0.041670,0.000000
33.140003,25.456497,-125.836609,-0.003436,0.001622,0.041202,113.236153,5.768525,0.412024,-125.836609,0.042286,0.000000
33.510002,26.086929,-125.881088,-0.003419,0.001650,0.041922,116.040459,5.911383,0.419223,-125.881088,0.042902,0.000000
33.880001,25.812485,-125.970055,-0.003410,0.001666,0.042321,114.819664,5.849193,0.423212,-125.970055,0.043526,0.000000
34.250000,25.933884,-126.059013,-0.003402,0.001686,0.042824,115.359673,5.876702,0.428238,-126.059013,0.044142,0.000000
34.620003,27.305328,-126.147980,-0.003367,0.001725,0.043812,121.460167,6.187476,0.438124,-126.147980,0.044758,0.000000
34.990002,27.256920,-126.103493,-0.003354,0.001746,0.044350,121.244835,6.176507,0.443499,-126.103493,0.045373,0.000000
35.360001,27.866867,-126.192459,-0.003333,0.001774,0.045052,123.958015,6.314722,0.450524,-126.192459,0.045990,0.000000
35.730003,27.646423,-126.236938,-0.003311,0.001790,0.045460,122.977432,6.264769,0.454604,-126.236938,0.046605,0.000000
36.100002,28.221367,-126.325897,-0.003307,0.001817,0.046145,125.534912,6.395053,0.461454,-126.325897,0.047220,0.000000
36.470001,28.573257,-126.414864,-0.003268,0.001843,0.046813,127.100197,6.474793,0.468131,-126.414864,0.047837,0.000000
36.840000,29.210388,-126.414864,-0.003255,0.001869,0.047481,129.934296,6.619169,0.474808,-126.414864,0.048452,0.000000
37.210003,29.533981,-126.459343,-0.003247,0.001894,0.048105,131.373703,6.692496,0.481053,-126.459343,0.049076,0.000000
37.580002,29.662819,-126.548309,-0.003225,0.001915,0.048643,131.946808,6.721691,0.486427,-126.548309,0.049693,0.000000
37.950001,29.940613,-126.548309,-0.003221,0.001937,0.049198,133.182495,6.784640,0.491983,-126.548309,0.050308,0.000000
38.320004,31.021980,-126.637268,-0.003203,0.001967,0.049970,137.992661,7.029681,0.499697,-126.637268,0.050923,0.000000
38.690002,31.178375,-126.726227,-0.003160,0.001991,0.050559,138.688339,7.065121,0.505594,-126.726227,0.051540,0.000000
39.060001,31.386162,-126.770714,-0.003156,0.002012,0.051106,139.612625,7.112206,0.511059,-126.770714,0.052155,0.000000
39.430000,31.947327,-126.770714,-0.003143,0.002037,0.051739,142.108810,7.239367,0.517388,-126.770714,0.052771,0.000000
39.800003,32.182663,-126.815193,-0.003122,0.002060,0.052328,143.155640,7.292696,0.523284,-126.815193,0.053387,0.000000
40.170002,33.224564,-126.948631,-0.003100,0.002089,0.053057,147.790237,7.528794,0.530574,-126.948631,0.054002,0.000000
40.540001,33.605125,-126.993118,-0.003083,0.002113,0.053673,149.483063,7.615030,0.536728,-126.993118,0.054627,0.000000
40.910004,33.932442,-127.037598,-0.003087,0.002135,0.054237,150.939041,7.689201,0.542368,-127.037598,0.055243,0.000000
41.280003,34.611649,-127.082077,-0.003053,0.002164,0.054974,153.960297,7.843112,0.549741,-127.082077,0.055858,0.000000
41.650002,34.353226,-127.126556,-0.003040,0.002181,0.055390,152.810776,7.784552,0.553897,-127.126556,0.056474,0.000000
42.020000,34.909920,-127.260002,-0.003031,0.002208,0.056084,155.287079,7.910701,0.560838,-127.260002,0.057090,0.000000
42.390003,35.867287,-127.260002,-0.003001,0.002234,0.056743,159.545654,8.127644,0.567431,-127.260002,0.057705,0.000000
42.760002,36.180824,-127.393440,-0.002984,0.002258,0.057350,160.940338,8.198692,0.573502,-127.393440,0.058321,0.000000
43.130001,36.739761,-127.437927,-0.002971,0.002282,0.057957,163.426620,8.325349,0.579573,-127.437927,0.058937,0.000000
43.500004,37.036537,-127.393440,-0.002945,0.002303,0.058486,164.746750,8.392599,0.584857,-127.393440,0.059553,0.000000
43.870003,37.420456,-127.482407,-0.002936,0.002323,0.059007,166.454498,8.479597,0.590065,-127.482407,0.060177,0.000000
44.240002,38.771797,-127.660332,-0.002940,0.002355,0.059822,172.465561,8.785815,0.598218,-127.660332,0.060793,0.000000
44.610001,38.271324,-127.615852,-0.002910,0.002366,0.060108,170.239349,8.672406,0.601079,-127.615852,0.061408,0.000000
44.980003,39.662140,-127.660332,-0.002893,0.002399,0.060923,176.426010,8.987569,0.609232,-127.660332,0.062025,0.000000
45.350002,40.253464,-127.660332,-0.002876,0.002423,0.061547,179.056351,9.121565,0.615469,-127.660332,0.062640,0.000000
45.720001,40.624718,-127.704811,-0.002884,0.002445,0.062103,180.707764,9.205692,0.621026,-127.704811,0.063255,0.000000
46.090004,42.331673,-127.838257,-0.002854,0.002480,0.063004,188.300690,9.592494,0.630041,-127.838257,0.063872,0.000000
46.460003,42.618027,-127.927216,-0.002828,0.002502,0.063542,189.574448,9.657383,0.635416,-127.927216,0.064487,0.000000
46.830002,42.435570,-127.971695,-0.002833,0.002521,0.064028,188.762848,9.616037,0.640276,-127.971695,0.065103,0.000000
47.200001,43.257767,-127.927216,-0.002811,0.002542,0.064574,192.420151,9.802350,0.645741,-127.927216,0.065727,0.000000
47.570004,44.203590,-127.971695,-0.002807,0.002569,0.065259,196.627396,10.016676,0.652592,-127.971695,0.066343,0.000000
47.940002,45.382523,-128.194107,-0.002781,0.002599,0.066022,201.871536,10.283827,0.660222,-128.194107,0.066959,0.000000
48.310001,45.709839,-128.194107,-0.002759,0.002620,0.066551,203.327515,10.357998,0.665513,-128.194107,0.067575,0.000000
48.680004,46.053909,-128.194107,-0.002759,0.002638,0.067011,204.858017,10.435965,0.670108,-128.194107,0.068190,0.000000
49.050003,47.038094,-128.283066,-0.002729,0.002664,0.067670,209.235886,10.658984,0.676701,-128.283066,0.068806,0.000000
49.420002,47.721397,-128.327545,-0.002738,0.002690,0.068320,212.275375,10.813824,0.683204,-128.327545,0.069422,0.000000
49.790001,49.009056,-128.372025,-0.002725,0.002719,0.069075,218.003174,11.105611,0.690751,-128.372025,0.070037,0.000000
50.160004,50.031593,-128.460983,-0.002699,0.002746,0.069743,222.551636,11.337321,0.697427,-128.460983,0.070653,0.000000
50.530003,50.091171,-128.549942,-0.002682,0.002764,0.070194,222.816666,11.350821,0.701939,-128.549942,0.071278,0.000000
50.900002,50.727928,-128.594437,-0.002669,0.002787,0.070792,225.649094,11.495113,0.707919,-128.594437,0.071893,0.000000
51.270004,51.653648,-128.683395,-0.002677,0.002812,0.071416,229.766907,11.704885,0.714164,-128.683395,0.072509,0.000000
51.640003,52.731293,-128.638916,-0.002652,0.002838,0.072076,234.560501,11.949081,0.720758,-128.638916,0.073125,0.000000
52.010002,53.971291,-128.727875,-0.002639,0.002865,0.072778,240.076294,12.230070,0.727782,-128.727875,0.073740,0.000000
52.380001,54.554428,-128.816833,-0.002626,0.002888,0.073359,242.670212,12.362210,0.733588,-128.816833,0.074357,0.000000
52.750004,55.216881,-128.861313,-0.002613,0.002912,0.073958,245.616959,12.512323,0.739576,-128.861313,0.074972,0.000000
53.120003,55.681602,-128.950272,-0.002591,0.002930,0.074425,247.684143,12.617632,0.744254,-128.950272,0.075587,0.000000
53.490002,56.808029,-128.905792,-0.002596,0.002956,0.075093,252.694733,12.872884,0.750931,-128.905792,0.076204,0.000000
53.860004,58.318367,-129.039246,-0.002583,0.002988,0.075883,259.413055,13.215131,0.758826,-129.039246,0.076828,0.000000
54.230003,58.829262,-129.083725,-0.002578,0.003007,0.076368,261.685638,13.330901,0.763678,-129.083725,0.077443,0.000000
54.600002,59.334206,-129.172684,-0.002561,0.003029,0.076932,263.931732,13.445323,0.769318,-129.172684,0.078059,0.000000
54.970001,60.784592,-129.172684,-0.002548,0.003055,0.077591,270.383362,13.773985,0.775911,-129.172684,0.078675,0.000000
55.340004,60.417809,-129.217163,-0.002544,0.003065,0.077852,268.751831,13.690871,0.778515,-129.217163,0.079291,0.000000
55.710003,62.990158,-129.306122,-0.002531,0.003106,0.078901,280.194214,14.273773,0.789007,-129.306122,0.079907,0.000000
56.080002,63.718895,-129.350601,-0.002509,0.003128,0.079464,283.435791,14.438908,0.794639,-129.350601,0.080522,0.000000
56.450005,64.396980,-129.395081,-0.002496,0.003149,0.079993,286.452087,14.592564,0.799930,-129.395081,0.081138,0.000000
56.820004,65.987389,-129.528534,-0.002501,0.003179,0.080756,293.526550,14.952956,0.807560,-129.528534,0.081762,0.000000
57.190002,64.891869,-129.528534,-0.002471,0.003176,0.080661,288.653442,14.704707,0.806607,-129.528534,0.014167,0.000000
57.560001,66.453957,-129.573013,-0.002453,0.003053,0.077539,295.601959,15.058681,0.775389,-129.573013,294.500488,0.000000
57.930004,65.152153,-129.661972,-0.002462,0.003201,0.081303,289.811249,14.763689,0.813026,-129.661972,294.500488,0.000000
58.300003,65.304817,-129.706451,-0.002449,0.003223,0.081857,290.490326,14.798283,0.818574,-129.706451,294.500488,0.000000
58.670002,65.216194,-129.795410,-0.002440,0.003236,0.082187,290.096130,14.778201,0.821875,-129.795410,294.500488,0.000000
59.040001,65.260506,-129.795410,-0.002436,0.003249,0.082526,290.293213,14.788242,0.825258,-129.795410,294.500488,0.000000
59.410004,65.155495,-129.795410,-0.002432,0.003260,0.082795,289.826111,14.764446,0.827946,-129.795410,294.500488,0.000000
59.780003,65.085121,-129.884384,-0.002419,0.003271,0.083081,289.513092,14.748499,0.830807,-129.884384,294.500488,0.000000
60.150002,65.027031,-129.973343,-0.002414,0.003279,0.083289,289.254669,14.735335,0.832889,-129.973343,294.500488,0.000000
60.520004,65.131676,-130.062302,-0.002414,0.003292,0.083618,289.720154,14.759048,0.836182,-130.062302,294.500488,0.000000
60.890003,65.192741,-130.062302,-0.002397,0.003300,0.083809,289.991791,14.772886,0.838089,-130.062302,294.500488,0.000000
61.260002,65.313393,-130.106781,-0.002384,0.003311,0.084104,290.528473,14.800226,0.841042,-130.106781,294.500488,0.000000
61.630001,65.092949,-130.151260,-0.002380,0.003319,0.084312,289.547913,14.750273,0.843123,-130.151260,294.500488,0.000000
62.000004,65.245995,-130.284698,-0.002397,0.003328,0.084537,290.228668,14.784953,0.845371,-130.284698,294.500488,0.000000
62.370003,65.234077,-130.373672,-0.002380,0.003337,0.084763,290.175659,14.782253,0.847627,-130.373672,294.500488,0.000000
62.740002,65.013252,-130.418152,-0.002393,0.003343,0.084902,289.193390,14.732214,0.849020,-130.418152,294.500488,0.000000
63.110004,65.269447,-130.418152,-0.002384,0.003352,0.085153,290.333008,14.790268,0.851533,-130.418152,294.500488,0.000000
63.480003,66.152718,-130.462631,-0.002354,0.003362,0.085405,294.261993,14.990419,0.854046,-130.462631,294.500488,0.000000
63.850002,65.244499,-130.551590,-0.002358,0.003362,0.085405,290.222015,14.784615,0.854046,-130.551590,294.500488,0.000000
64.220001,64.966331,-130.640549,-0.002363,0.003393,0.086194,288.984680,14.721581,0.861942,-130.640549,294.500488,0.000000
64.590004,66.131493,-130.729523,-0.002333,0.003306,0.083982,294.167572,14.985610,0.839823,-130.729523,294.500488,0.000000
64.960007,65.331627,-130.774002,-0.002337,0.003350,0.085084,290.609589,14.804358,0.850837,-130.774002,294.500488,0.000000
65.330002,65.238167,-130.774002,-0.002337,0.003392,0.086159,290.193848,14.783179,0.861593,-130.774002,294.500488,0.000000
65.700005,65.173744,-130.774002,-0.002341,0.003400,0.086358,289.907288,14.768581,0.863584,-130.774002,294.500488,0.000000
66.070000,65.188271,-130.907440,-0.002341,0.003408,0.086558,289.971924,14.771873,0.865583,-130.907440,294.500488,0.000000
66.440002,65.547234,-130.996399,-0.002345,0.003418,0.086810,291.568665,14.853215,0.868096,-130.996399,294.500488,0.000000
66.810005,65.337959,-130.996399,-0.002328,0.003424,0.086957,290.637756,14.805793,0.869572,-130.996399,294.500488,0.000000
67.180000,65.136513,-131.040878,-0.002328,0.003427,0.087044,289.741669,14.760145,0.870435,-131.040878,294.500488,0.000000
67.550003,65.108589,-131.129837,-0.002324,0.003432,0.087183,289.617462,14.753818,0.871828,-131.129837,294.500488,0.000000
67.920006,65.159966,-131.174332,-0.002324,0.003439,0.087356,289.846008,14.765460,0.873561,-131.174332,294.500488,0.000000
68.290001,65.064644,-131.218811,-0.002328,0.003443,0.087442,289.421997,14.743859,0.874424,-131.218811,294.500488,0.000000
68.660004,65.353981,-131.307770,-0.002307,0.003451,0.087651,290.709015,14.809423,0.876506,-131.307770,294.500488,0.000000
69.030006,65.100395,-131.307770,-0.002315,0.003454,0.087738,289.581024,14.751961,0.877376,-131.307770,294.500488,0.000000
69.400002,65.380791,-131.396729,-0.002307,0.003462,0.087937,290.828278,14.815498,0.879367,-131.396729,294.500488,0.000000
69.770004,64.961128,-131.441208,-0.002324,0.003462,0.087946,288.961517,14.720403,0.879458,-131.441208,294.500488,0.000000
70.140007,64.938042,-131.530167,-0.002307,0.003468,0.088076,288.858826,14.715171,0.880760,-131.530167,294.500488,0.000000
70.510002,65.796349,-131.485687,-0.002311,0.003477,0.088310,292.676788,14.909666,0.883099,-131.485687,294.500488,0.000000
70.880005,65.219917,-131.530167,-0.002302,0.003477,0.088310,290.112671,14.779044,0.883099,-131.530167,294.500488,0.000000
71.250000,64.691154,-131.708099,-0.002285,0.003482,0.088440,287.760620,14.659225,0.884401,-131.708099,294.500488,0.000000
71.620003,65.836205,-131.708099,-0.002298,0.003490,0.088648,292.854065,14.918697,0.886483,-131.708099,294.500488,0.000000
71.990005,65.295891,-131.708099,-0.002294,0.003490,0.088657,290.450623,14.796261,0.886566,-131.708099,294.500488,0.000000
72.360001,65.004692,-131.841537,-0.002302,0.003506,0.089056,289.155304,14.730273,0.890556,-131.841537,294.500488,0.000000
72.730003,65.564735,-131.886017,-0.002285,0.003502,0.088943,291.646515,14.857182,0.889428,-131.886017,294.500488,0.000000
73.100006,65.066872,-131.886017,-0.002289,0.003503,0.088978,289.431915,14.744364,0.889776,-131.886017,294.500488,0.000000
73.470001,65.044899,-131.930496,-0.002276,0.003511,0.089186,289.334167,14.739385,0.891858,-131.930496,294.500488,0.000000
73.840004,65.243752,-132.063950,-0.002281,0.003517,0.089333,290.218689,14.784445,0.893334,-132.063950,294.500488,0.000000
74.210007,65.130928,-132.108429,-0.002285,0.003519,0.089394,289.716827,14.758880,0.893939,-132.108429,294.500488,0.000000
74.580002,65.197578,-132.152908,-0.002281,0.003524,0.089507,290.013306,14.773982,0.895067,-132.152908,294.500488,0.000000
74.950005,65.397545,-132.108429,-0.002268,0.003530,0.089663,290.902802,14.819296,0.896626,-132.108429,294.500488,0.000000
75.320007,65.163689,-132.241867,-0.002281,0.003532,0.089715,289.862549,14.766303,0.897149,-132.241867,294.500488,0.000000
75.690002,65.320091,-132.286346,-0.002272,0.003537,0.089836,290.558289,14.801744,0.898360,-132.286346,294.500488,0.000000
76.060005,65.031868,-132.375305,-0.002272,0.003538,0.089862,289.276184,14.736432,0.898625,-132.375305,294.500488,0.000000
76.430000,65.721138,-132.375305,-0.002264,0.003547,0.090105,292.342224,14.892623,0.901047,-132.375305,294.500488,0.000000
76.800003,65.343925,-132.508759,-0.002255,0.003547,0.090105,290.664307,14.807145,0.901047,-132.508759,294.500488,0.000000
77.170006,65.005806,-132.553238,-0.002272,0.003548,0.090114,289.160278,14.730526,0.901138,-132.553238,294.500488,0.000000
77.540001,64.667320,-132.597717,-0.002264,0.003548,0.090122,287.654602,14.653824,0.901221,-132.597717,294.500488,0.000000
77.910004,66.862450,-132.686676,-0.002259,0.003471,0.088162,297.419037,15.151248,0.881623,-132.686676,294.500488,0.000000
78.280006,66.385826,-132.775635,-0.002246,0.003455,0.087763,295.298889,15.043243,0.877634,-132.775635,294.500488,0.000000
78.650002,65.971367,-132.775635,-0.002246,0.003455,0.087763,293.455292,14.949326,0.877634,-132.775635,294.500488,0.000000
79.020004,65.587456,-132.731155,-0.002246,0.003471,0.088154,291.747589,14.862329,0.881540,-132.731155,294.500488,0.000000
79.390007,65.333488,-132.820114,-0.002255,0.003551,0.090183,290.617859,14.804780,0.901834,-132.820114,294.500488,0.000000
79.760002,65.233330,-132.998047,-0.002251,0.003568,0.090634,290.172333,14.782084,0.906339,-132.998047,294.500488,0.000000
80.130005,65.268700,-132.998047,-0.002259,0.003573,0.090756,290.329681,14.790098,0.907557,-132.998047,294.500488,0.000000
80.500008,65.084755,-133.042526,-0.002246,0.003575,0.090799,289.511444,14.748417,0.907989,-133.042526,294.500488,0.000000
80.870003,65.172264,-132.998047,-0.002242,0.003579,0.090912,289.900696,14.768247,0.909117,-132.998047,294.500488,0.000000
81.240005,65.142464,-133.131485,-0.002242,0.003582,0.090990,289.768158,14.761494,0.909896,-133.131485,294.500488,0.000000
81.610001,64.924995,-133.175964,-0.002251,0.003582,0.090990,288.800812,14.712214,0.909896,-133.175964,294.500488,0.000000
81.980003,65.303337,-133.220444,-0.002233,0.003590,0.091189,290.483765,14.797948,0.911887,-133.220444,294.500488,0.000000
82.350006,65.091087,-133.309418,-0.002242,0.003591,0.091206,289.539612,14.749851,0.912061,-133.309418,294.500488,0.000000
82.720001,64.929848,-133.353897,-0.002225,0.003596,0.091328,288.822388,14.713314,0.913280,-133.353897,294.500488,0.000000
83.090004,65.141716,-133.398376,-0.002233,0.003598,0.091389,289.764832,14.761324,0.913886,-133.398376,294.500488,0.000000
83.460007,64.975273,-133.442856,-0.002242,0.003598,0.091389,289.024445,14.723607,0.913886,-133.442856,294.500488,0.000000
83.830002,65.661934,-133.487335,-0.002238,0.003608,0.091649,292.078857,14.879207,0.916490,-133.487335,294.500488,0.000000
84.200005,65.481331,-133.531815,-0.002220,0.003608,0.091649,291.275513,14.838282,0.916490,-133.531815,294.500488,0.000000
84.570007,65.228493,-133.576294,-0.002229,0.003608,0.091649,290.150818,14.780988,0.916490,-133.576294,294.500488,0.000000
84.940002,65.046394,-133.665253,-0.002251,0.003617,0.091875,289.340820,14.739723,0.918745,-133.665253,294.500488,0.000000
85.310005,65.671974,-133.754227,-0.002233,0.003618,0.091909,292.123535,14.881482,0.919086,-133.754227,294.500488,0.000000
85.680000,65.461220,-133.798706,-0.002233,0.003618,0.091909,291.186035,14.833725,0.919086,-133.798706,294.500488,0.000000
86.050003,65.220665,-133.843185,-0.002238,0.003618,0.091909,290.115997,14.779214,0.919086,-133.843185,294.500488,0.000000
86.420006,64.971184,-133.843185,-0.002225,0.003618,0.091909,289.006256,14.722681,0.919086,-133.843185,294.500488,0.000000
86.790001,64.717598,-133.932144,-0.002220,0.003618,0.091909,287.878265,14.665217,0.919086,-133.932144,294.500488,0.000000
87.160004,64.460289,-133.932144,-0.002229,0.003618,0.091909,286.733673,14.606911,0.919086,-133.932144,294.500488,0.000000
87.530006,67.171532,-134.065582,-0.002229,0.003549,0.090157,298.793884,15.221287,0.901570,-134.065582,294.500488,0.000000
87.900002,66.393272,-134.154541,-0.002216,0.003480,0.088380,295.332031,15.044930,0.883796,-134.154541,294.500488,0.000000
88.270004,66.160530,-134.199036,-0.002212,0.003480,0.088380,294.296722,14.992190,0.883796,-134.199036,294.500488,0.000000
88.640007,65.848488,-134.199036,-0.002203,0.003480,0.088397,292.908691,14.921480,0.883970,-134.199036,294.500488,0.000000
89.010002,65.591179,-134.287994,-0.002195,0.003532,0.089706,291.764130,14.863173,0.897058,-134.287994,294.500488,0.000000
89.380005,65.389717,-134.332474,-0.002212,0.003595,0.091319,290.867981,14.817522,0.913189,-134.332474,294.500488,0.000000
89.750008,65.285088,-134.376953,-0.002195,0.003623,0.092030,290.402588,14.793813,0.920305,-134.376953,294.500488,0.000000
90.120003,65.162209,-134.421432,-0.002207,0.003641,0.092490,289.855988,14.765968,0.924900,-134.421432,294.500488,0.000000
90.490005,65.241890,-134.465912,-0.002207,0.003644,0.092568,290.210419,14.784024,0.925679,-134.465912,294.500488,0.000000
90.860001,65.270195,-134.554871,-0.002203,0.003649,0.092689,290.336334,14.790438,0.926890,-134.554871,294.500488,0.000000
91.230003,65.237053,-134.643845,-0.002199,0.003651,0.092724,290.188904,14.782928,0.927239,-134.643845,294.500488,0.000000
91.600006,65.256783,-134.643845,-0.002207,0.003653,0.092784,290.276672,14.787398,0.927844,-134.643845,294.500488,0.000000
91.970001,65.244499,-134.688324,-0.002199,0.003656,0.092863,290.222015,14.784615,0.928632,-134.688324,294.500488,0.000000
92.340004,65.184547,-134.688324,-0.002195,0.003657,0.092880,289.955353,14.771029,0.928798,-134.688324,294.500488,0.000000
92.710007,65.244133,-134.821762,-0.002207,0.003660,0.092959,290.220398,14.784533,0.929585,-134.821762,294.500488,0.000000
93.080002,65.116768,-134.910721,-0.002199,0.003660,0.092967,289.653839,14.755671,0.929669,-134.910721,294.500488,0.000000
93.450005,65.417656,-134.955200,-0.002207,0.003666,0.093114,290.992279,14.823853,0.931145,-134.955200,294.500488,0.000000
93.820007,65.288063,-134.999680,-0.002195,0.003666,0.093114,290.415802,14.794487,0.931145,-134.999680,294.500488,0.000000
94.190002,65.144707,-134.999680,-0.002190,0.003667,0.093140,289.778137,14.762002,0.931402,-134.999680,294.500488,0.000000
94.560005,65.648155,-135.044174,-0.002199,0.003676,0.093366,292.017578,14.876084,0.933658,-135.044174,294.500488,0.000000
94.930008,65.604576,-135.133133,-0.002203,0.003675,0.093357,291.823730,14.866209,0.933575,-135.133133,294.500488,0.000000
95.300003,65.479088,-135.266571,-0.002199,0.003676,0.093366,291.265533,14.837773,0.933658,-135.266571,294.500488,0.000000
95.670006,65.305199,-135.311050,-0.002195,0.003676,0.093374,290.492035,14.798369,0.933741,-135.311050,294.500488,0.000000
96.040001,65.201668,-135.311050,-0.002207,0.003678,0.093418,290.031494,14.774909,0.934180,-135.311050,294.500488,0.000000
96.410004,65.117516,-135.311050,-0.002190,0.003682,0.093531,289.657166,14.755840,0.935308,-135.311050,294.500488,0.000000
96.780006,65.480583,-135.444489,-0.002195,0.003684,0.093566,291.272186,14.838112,0.935656,-135.444489,294.500488,0.000000
97.150002,65.313011,-135.488983,-0.002186,0.003684,0.093566,290.526794,14.800140,0.935656,-135.488983,294.500488,0.000000
97.520004,65.168907,-135.533463,-0.002186,0.003685,0.093609,289.885773,14.767486,0.936088,-135.533463,294.500488,0.000000
97.890007,65.219551,-135.533463,-0.002195,0.003687,0.093661,290.111053,14.778962,0.936610,-135.533463,294.500488,0.000000
98.260002,65.227745,-135.622421,-0.002195,0.003690,0.093730,290.147491,14.780818,0.937299,-135.622421,294.500488,0.000000
98.630005,65.179329,-135.711380,-0.002195,0.003690,0.093730,289.932129,14.769847,0.937299,-135.711380,294.500488,0.000000
99.000008,65.189018,-135.755859,-0.002195,0.003692,0.093773,289.975250,14.772042,0.937730,-135.755859,294.500488,0.000000
99.370003,65.117149,-135.844818,-0.002182,0.003693,0.093808,289.655548,14.755756,0.938079,-135.844818,294.500488,0.000000
99.740005,65.255302,-135.889313,-0.002195,0.003697,0.093912,290.270081,14.787063,0.939123,-135.889313,294.500488,0.000000
100.110008,65.201302,-135.844818,-0.002190,0.003697,0.093912,290.029877,14.774826,0.939123,-135.844818,294.500488,0.000000
100.480003,65.190880,-135.978271,-0.002199,0.003699,0.093955,289.983521,14.772465,0.939555,-135.978271,294.500488,0.000000
100.850006,65.147682,-135.978271,-0.002195,0.003700,0.093990,289.791351,14.762676,0.939903,-135.978271,294.500488,0.000000
101.220001,65.097786,-135.978271,-0.002186,0.003702,0.094025,289.569427,14.751369,0.940251,-135.978271,294.500488,0.000000
101.590004,65.025169,-136.067230,-0.002177,0.003702,0.094043,289.246399,14.734915,0.940425,-136.067230,294.500488,0.000000
101.960007,65.370354,-136.156189,-0.002186,0.003708,0.094189,290.781860,14.813134,0.941894,-136.156189,294.500488,0.000000
102.330002,65.253059,-136.245148,-0.002190,0.003708,0.094172,290.260101,14.786554,0.941720,-136.245148,294.500488,0.000000
102.700005,65.168541,-136.289627,-0.002173,0.003708,0.094189,289.884155,14.767403,0.941894,-136.289627,294.500488,0.000000
103.070007,65.129066,-136.334122,-0.002190,0.003710,0.094242,289.708557,14.758457,0.942416,-136.334122,294.500488,0.000000
103.440002,65.110451,-136.378601,-0.002182,0.003711,0.094267,289.625763,14.754239,0.942674,-136.378601,294.500488,0.000000
103.810005,65.027412,-136.423080,-0.002190,0.003712,0.094276,289.256378,14.735423,0.942764,-136.423080,294.500488,0.000000
104.180008,64.913094,-136.512039,-0.002186,0.003712,0.094276,288.747864,14.709517,0.942764,-136.512039,294.500488,0.000000
104.550003,65.594154,-136.512039,-0.002186,0.003722,0.094528,291.777374,14.863848,0.945278,-136.512039,294.500488,0.000000
104.920006,65.563622,-136.512039,-0.002182,0.003722,0.094528,291.641541,14.856929,0.945278,-136.512039,294.500488,0.000000
105.290009,65.483559,-136.645477,-0.002177,0.003722,0.094528,291.285431,14.838787,0.945278,-136.645477,294.500488,0.000000
105.660004,65.342064,-136.689957,-0.002177,0.003722,0.094528,290.656006,14.806724,0.945278,-136.689957,294.500488,0.000000
106.030006,65.244499,-136.689957,-0.002182,0.003722,0.094537,290.222015,14.784615,0.945368,-136.689957,294.500488,0.000000
106.400002,65.116035,-136.778931,-0.002169,0.003723,0.094563,289.650604,14.755505,0.945626,-136.778931,294.500488,0.000000
106.770004,65.011391,-136.823410,-0.002160,0.003723,0.094563,289.185120,14.731791,0.945626,-136.823410,294.500488,0.000000
107.140007,64.911964,-136.867889,-0.002177,0.003724,0.094580,288.742828,14.709262,0.945800,-136.867889,294.500488,0.000000
107.510002,64.807701,-136.956848,-0.002186,0.003724,0.094597,288.279053,14.685635,0.945974,-136.956848,294.500488,0.000000
107.880005,65.835075,-137.090286,-0.002182,0.003736,0.094901,292.849030,14.918441,0.949009,-137.090286,294.500488,0.000000
108.250008,65.767677,-137.090286,-0.002173,0.003736,0.094901,292.549225,14.903169,0.949009,-137.090286,294.500488,0.000000
108.620003,65.657463,-137.179260,-0.002173,0.003736,0.094901,292.058990,14.878194,0.949009,-137.179260,294.500488,0.000000
108.990005,65.552452,-137.090286,-0.002160,0.003736,0.094901,291.591858,14.854398,0.949009,-137.090286,294.500488,0.000000
109.360008,65.409081,-137.223740,-0.002173,0.003736,0.094901,290.954132,14.821909,0.949009,-137.223740,294.500488,0.000000
109.730003,65.292168,-137.268219,-0.002169,0.003736,0.094901,290.434082,14.795417,0.949009,-137.268219,294.500488,0.000000
110.100006,65.153633,-137.401657,-0.002173,0.003736,0.094901,289.817841,14.764025,0.949009,-137.401657,294.500488,0.000000
110.470009,65.025169,-137.357178,-0.002164,0.003737,0.094909,289.246399,14.734915,0.949093,-137.357178,294.500488,0.000000
110.840004,64.905266,-137.401657,-0.002160,0.003737,0.094909,288.713043,14.707744,0.949093,-137.401657,294.500488,0.000000
111.210007,64.769722,-137.490616,-0.002160,0.003737,0.094909,288.110107,14.677029,0.949093,-137.490616,294.500488,0.000000
111.580002,64.650566,-137.535095,-0.002164,0.003737,0.094909,287.580078,14.650027,0.949093,-137.535095,294.500488,0.000000
111.950005,64.518745,-137.579575,-0.002151,0.003737,0.094909,286.993713,14.620157,0.949093,-137.579575,294.500488,0.000000
112.320007,64.401070,-137.624069,-0.002151,0.003737,0.094909,286.470276,14.593491,0.949093,-137.624069,294.500488,0.000000
112.690002,64.254738,-137.713028,-0.002160,0.003737,0.094909,285.819336,14.560332,0.949093,-137.713028,294.500488,0.000000
113.060005,66.570137,-137.757507,-0.002151,0.003590,0.091198,296.118744,15.085009,0.911978,-137.757507,294.500488,0.000000
113.430008,66.387688,-137.846466,-0.002156,0.003591,0.091215,295.307190,15.043665,0.912152,-137.846466,294.500488,0.000000
113.800003,66.217140,-137.846466,-0.002147,0.003591,0.091215,294.548553,15.005019,0.912152,-137.846466,294.500488,0.000000
114.170006,66.071159,-137.890945,-0.002139,0.003591,0.091215,293.899200,14.971939,0.912152,-137.890945,294.500488,0.000000
114.540009,65.933754,-137.890945,-0.002139,0.003592,0.091241,293.287994,14.940802,0.912409,-137.890945,294.500488,0.000000
114.910004,65.841042,-138.024384,-0.002134,0.003595,0.091311,292.875580,14.919793,0.913106,-138.024384,294.500488,0.000000
115.280006,65.653740,-138.113358,-0.002139,0.003626,0.092099,292.042419,14.877350,0.920994,-138.113358,294.500488,0.000000
115.650009,65.518196,-138.157837,-0.002139,0.003702,0.094025,291.439484,14.846635,0.940251,-138.157837,294.500488,0.000000
116.020004,65.399406,-138.068878,-0.002147,0.003711,0.094251,290.911102,14.819717,0.942507,-138.068878,294.500488,0.000000
116.390007,65.314125,-138.202316,-0.002139,0.003721,0.094519,290.531738,14.800392,0.945194,-138.202316,294.500488,0.000000
116.760002,65.240028,-138.291275,-0.002143,0.003724,0.094580,290.202148,14.783602,0.945800,-138.291275,294.500488,0.000000
117.130005,65.080284,-138.335754,-0.002134,0.003724,0.094580,289.491577,14.747403,0.945800,-138.335754,294.500488,0.000000
117.500008,65.241524,-138.424713,-0.002147,0.003754,0.095343,290.208801,14.783940,0.953430,-138.424713,294.500488,0.000000
117.870003,65.169655,-138.380234,-0.002130,0.003751,0.095265,289.889099,14.767654,0.952650,-138.380234,0.095144,0.000000
118.240005,64.863564,-138.424713,-0.002139,0.003732,0.094796,288.527527,14.698294,0.947965,-138.424713,0.094528,0.000000
118.610008,64.756691,-138.558167,-0.002134,0.003715,0.094363,288.052155,14.674076,0.943635,-138.558167,0.093912,0.000000
118.980003,64.635674,-138.602646,-0.002126,0.003701,0.093999,287.513824,14.646653,0.939986,-138.602646,0.093296,0.000000
119.350006,64.461403,-138.647125,-0.002134,0.003669,0.093183,286.738647,14.607162,0.931834,-138.647125,0.092681,0.000000
119.720009,64.374641,-138.691605,-0.002134,0.003649,0.092672,286.352692,14.587502,0.926724,-138.691605,0.092065,0.000000
120.090004,64.202965,-138.780563,-0.002139,0.003620,0.091943,285.589050,14.548600,0.919434,-138.780563,0.091449,0.000000
120.460007,64.053658,-138.869522,-0.002130,0.003597,0.091371,284.924896,14.514767,0.913711,-138.869522,0.090825,0.000000
120.830009,63.972481,-138.958496,-0.002134,0.003571,0.090703,284.563812,14.496371,0.907035,-138.958496,0.090209,0.000000
121.200005,63.823524,-138.914017,-0.002117,0.003558,0.090365,283.901215,14.462617,0.903651,-138.914017,0.089593,0.000000
121.570007,63.441093,-138.914017,-0.002130,0.003528,0.089602,282.200073,14.375957,0.896021,-138.914017,0.088978,0.000000
121.940002,62.740295,-138.958496,-0.002143,0.003510,0.089143,279.082764,14.217155,0.891426,-138.958496,0.088362,0.000000
122.310005,61.478325,-139.047455,-0.002139,0.003480,0.088380,273.469238,13.931188,0.883796,-139.047455,0.087746,0.000000
122.680008,60.380943,-139.180893,-0.002130,0.003460,0.087885,268.587860,13.682517,0.878853,-139.180893,0.087131,0.000000
123.050003,59.190468,-139.180893,-0.002126,0.003443,0.087460,263.292358,13.412751,0.874598,-139.180893,0.086514,0.000000
123.420006,58.259163,-139.180893,-0.002121,0.003424,0.086975,259.149689,13.201715,0.869746,-139.180893,0.085899,0.000000
123.790009,56.133659,-139.269852,-0.002134,0.003403,0.086428,249.694992,12.720069,0.864281,-139.269852,0.085274,0.000000
124.160004,53.604507,-139.269852,-0.002130,0.003372,0.085639,238.444763,12.146955,0.856385,-139.269852,0.084659,0.000000
124.530006,51.217598,-139.447784,-0.002108,0.003346,0.084997,227.827255,11.606074,0.849974,-139.447784,0.084043,0.000000
124.900009,49.071617,-139.447784,-0.002117,0.003324,0.084433,218.281448,11.119787,0.844334,-139.447784,0.083427,0.000000
125.270004,46.407295,-139.447784,-0.002113,0.003301,0.083844,206.429962,10.516044,0.838437,-139.447784,0.082812,0.000000
125.640007,43.646149,-139.581223,-0.002117,0.003275,0.083194,194.147766,9.890358,0.831935,-139.581223,0.082196,0.000000
126.010010,41.446175,-139.625702,-0.002117,0.003258,0.082760,184.361786,9.391837,0.827598,-139.625702,0.081580,0.000000
126.380005,38.033005,-139.670181,-0.002113,0.003224,0.081901,169.179260,8.618402,0.819013,-139.670181,0.080964,0.000000
126.750008,35.693390,-139.670181,-0.002117,0.003203,0.081363,158.772125,8.088238,0.813631,-139.670181,0.080340,0.000000
127.120003,33.074867,-139.670181,-0.002121,0.003179,0.080739,147.124359,7.494872,0.807386,-139.670181,0.079724,0.000000
127.490005,32.052704,-139.759155,-0.002117,0.003171,0.080531,142.577545,7.263247,0.805312,-139.759155,0.079109,0.000000
127.860008,27.984535,-139.848114,-0.002108,0.003130,0.079508,124.481430,6.341386,0.795078,-139.848114,0.078493,0.000000
128.230011,25.650131,-139.892593,-0.002113,0.003107,0.078926,114.097481,5.812403,0.789264,-139.892593,0.077877,0.000000
128.600006,22.988045,-139.892593,-0.002104,0.003083,0.078302,102.255928,5.209165,0.783019,-139.892593,0.077261,0.000000
128.970001,20.099174,-139.937073,-0.002121,0.003056,0.077617,89.405594,4.554538,0.776168,-139.937073,0.076646,0.000000
129.340012,18.068260,-140.070511,-0.002121,0.003034,0.077054,80.371635,4.094326,0.770536,-140.070511,0.076030,0.000000
129.710007,15.408028,-140.070511,-0.002130,0.003010,0.076455,68.538330,3.491509,0.764549,-140.070511,0.075414,0.000000
130.080002,12.768280,-140.114990,-0.002113,0.002983,0.075761,56.796146,2.893334,0.757615,-140.114990,0.074790,0.000000
130.450012,10.227959,-140.159470,-0.002104,0.002958,0.075137,45.496231,2.317689,0.751370,-140.159470,0.074174,0.000000
130.820007,8.095383,-140.203964,-0.002121,0.002938,0.074634,36.010059,1.834440,0.746336,-140.203964,0.073559,0.000000
131.190002,6.192924,-140.292923,-0.002113,0.002916,0.074079,27.547504,1.403337,0.740787,-140.292923,0.072942,0.000000
131.560013,3.261612,-140.337402,-0.002121,0.002888,0.073351,14.508374,0.739092,0.733505,-140.337402,0.072327,0.000000
131.930008,0.854965,-140.426361,-0.002121,0.002863,0.072717,3.803075,0.193738,0.727169,-140.426361,0.071711,0.000000
132.300003,-1.467518,-140.426361,-0.002117,0.002836,0.072041,-6.527845,-0.332544,0.720409,-140.426361,0.071095,0.000000
132.670013,-2.948071,-140.381882,-0.002126,0.002819,0.071598,-13.113672,-0.668042,0.715981,-140.381882,0.070480,0.000000
133.040009,-4.350426,-140.470840,-0.002113,0.002799,0.071104,-19.351660,-0.985821,0.711038,-140.470840,0.069864,0.000000
133.410004,-0.170547,-140.559799,-0.002104,0.002765,0.070220,-0.758633,-0.038647,0.702196,-140.559799,0.069239,0.000000
133.779999,-0.078194,-140.604294,-0.002117,0.002741,0.069621,-0.347823,-0.017719,0.696209,-140.604294,0.068624,0.000000
134.150009,-0.036491,-140.693253,-0.002108,0.002714,0.068927,-0.162322,-0.008269,0.689275,-140.693253,0.068008,0.000000
134.520004,-0.091232,-140.737732,-0.002108,0.002695,0.068451,-0.405822,-0.020674,0.684506,-140.737732,0.067392,0.000000
134.889999,-0.046547,-140.737732,-0.002113,0.002673,0.067904,-0.207051,-0.010548,0.679040,-140.737732,0.066777,0.000000
135.260010,-0.063301,-140.826691,-0.002100,0.002648,0.067262,-0.281577,-0.014344,0.672621,-140.826691,0.066161,0.000000
135.630005,-0.061066,-140.960129,-0.002117,0.002630,0.066812,-0.271634,-0.013838,0.668117,-140.960129,0.065545,0.000000
136.000000,-0.032768,-140.915649,-0.002095,0.002591,0.065822,-0.145760,-0.007425,0.658224,-140.915649,0.064929,0.000000
136.370010,-0.024574,-141.004608,-0.002100,0.002577,0.065458,-0.109312,-0.005569,0.654582,-141.004608,0.064314,0.000000
136.740005,-0.029419,-141.093582,-0.002113,0.002553,0.064834,-0.130862,-0.006666,0.648337,-141.093582,0.063689,0.000000
137.110001,-0.055107,-141.138062,-0.002108,0.002524,0.064115,-0.245129,-0.012487,0.641146,-141.138062,0.063074,0.000000
137.480011,-0.046173,-141.182541,-0.002100,0.002507,0.063681,-0.205388,-0.010463,0.636809,-141.182541,0.062458,0.000000
137.850006,-0.091232,-141.182541,-0.002108,0.002476,0.062900,-0.405822,-0.020674,0.629004,-141.182541,0.061842,0.000000
138.220001,-0.086761,-141.227020,-0.002113,0.002452,0.062276,-0.385934,-0.019660,0.622759,-141.227020,0.061227,0.000000
138.590012,-0.114693,-141.315979,-0.002117,0.002431,0.061755,-0.510179,-0.025990,0.617551,-141.315979,0.060611,0.000000
138.960007,-0.074844,-141.360458,-0.002134,0.002406,0.061122,-0.332924,-0.016960,0.611223,-141.360458,0.059995,0.000000
139.330002,-0.097191,-141.449417,-0.002147,0.002378,0.060411,-0.432327,-0.022024,0.604115,-141.449417,0.059379,0.000000
139.700012,-0.078194,-141.449417,-0.002156,0.002361,0.059969,-0.347823,-0.017719,0.599686,-141.449417,0.058764,0.000000
140.070007,-0.082664,-141.493912,-0.002195,0.002326,0.059084,-0.367710,-0.018732,0.590845,-141.493912,0.058139,0.000000
140.440002,-0.067024,-141.538391,-0.002225,0.002303,0.058486,-0.298139,-0.015188,0.584857,-141.538391,0.057524,0.000000
140.810013,-0.088623,-141.582870,-0.002220,0.002289,0.058131,-0.394215,-0.020082,0.581307,-141.582870,0.056907,0.000000
141.180008,-0.069633,-141.716309,-0.002264,0.002259,0.057376,-0.309745,-0.015779,0.573760,-141.716309,0.056292,0.000000
141.550003,-0.081177,-141.716309,-0.002276,0.002243,0.056977,-0.361092,-0.018395,0.569771,-141.716309,0.055676,0.000000
141.920013,-0.072983,-141.760788,-0.002298,0.002203,0.055954,-0.324644,-0.016538,0.559536,-141.760788,0.055060,0.000000
142.290009,-0.086388,-141.760788,-0.002350,0.002174,0.055225,-0.384271,-0.019576,0.552254,-141.760788,0.054445,0.000000
142.660004,-0.080803,-141.894241,-0.002358,0.002159,0.054844,-0.359429,-0.018310,0.548439,-141.894241,0.053829,0.000000
143.030014,-0.076706,-141.938721,-0.002380,0.002134,0.054202,-0.341205,-0.017382,0.542020,-141.938721,0.053213,0.000000
143.400009,-0.080429,-141.983200,-0.002402,0.002111,0.053612,-0.357766,-0.018225,0.536123,-141.983200,0.052589,0.000000
143.770004,-0.049896,-142.027679,-0.002427,0.002081,0.052849,-0.221950,-0.011307,0.528492,-142.027679,0.051973,0.000000
144.139999,-0.032768,-142.072159,-0.002466,0.002056,0.052233,-0.145760,-0.007425,0.522331,-142.072159,0.051357,0.000000
144.510010,-0.053619,-142.205597,-0.002466,0.002042,0.051869,-0.238511,-0.012150,0.518690,-142.205597,0.050742,0.000000
144.880005,-0.050644,-142.205597,-0.002488,0.002021,0.051322,-0.225275,-0.011476,0.513224,-142.205597,0.050126,0.000000
145.250000,-0.048782,-142.205597,-0.002501,0.001993,0.050629,-0.216995,-0.011054,0.506290,-142.205597,0.049510,0.000000
145.620010,-0.040215,-142.250076,-0.002539,0.001961,0.049822,-0.178883,-0.009113,0.498221,-142.250076,0.048895,0.000000
145.990005,-0.077827,-142.383530,-0.002561,0.001940,0.049276,-0.346194,-0.017636,0.492763,-142.383530,0.048279,0.000000
146.360001,-0.017876,-142.428009,-0.002583,0.001923,0.048851,-0.079515,-0.004051,0.488509,-142.428009,0.047663,0.000000
146.730011,-0.050644,-142.472488,-0.002613,0.001898,0.048218,-0.225275,-0.011476,0.482180,-142.472488,0.047039,0.000000
147.100006,-0.049896,-142.472488,-0.002634,0.001864,0.047333,-0.221950,-0.011307,0.473331,-142.472488,0.046423,0.000000
147.470001,-0.021225,-142.516968,-0.002660,0.001838,0.046692,-0.094413,-0.004810,0.466920,-142.516968,0.045807,0.000000
147.840012,-0.030907,-142.561447,-0.002682,0.001817,0.046145,-0.137480,-0.007004,0.461454,-142.561447,0.045192,0.000000
148.210007,-0.017876,-142.650406,-0.002725,0.001791,0.045504,-0.079515,-0.004051,0.455035,-142.650406,0.044575,0.000000
148.580002,-0.027184,-142.739365,-0.002721,0.001781,0.045235,-0.120918,-0.006160,0.452348,-142.739365,0.043960,0.000000
148.950012,-0.040962,-142.739365,-0.002755,0.001756,0.044593,-0.182209,-0.009282,0.445929,-142.739365,0.043344,0.000000
149.320007,-0.046921,-142.783859,-0.002777,0.001724,0.043787,-0.208714,-0.010632,0.437867,-142.783859,0.042728,0.000000
149.690002,-0.017876,-142.872818,-0.002811,0.001694,0.043024,-0.079515,-0.004051,0.430237,-142.872818,0.042104,0.000000
150.060013,0.000748,-142.961777,-0.002846,0.001666,0.042304,0.003326,0.000169,0.423038,-142.961777,0.041489,0.000000
150.430008,-0.013031,-142.961777,-0.002867,0.001651,0.041948,-0.057965,-0.002953,0.419480,-142.961777,0.040872,0.000000
150.800003,-0.014145,-142.917297,-0.002871,0.001624,0.041237,-0.062920,-0.003205,0.412372,-142.917297,0.040257,0.000000
151.170013,0.004845,-143.050735,-0.002915,0.001598,0.040595,0.021550,0.001098,0.405953,-143.050735,0.039641,0.000000
151.540009,-0.014145,-143.139694,-0.002936,0.001572,0.039919,-0.062920,-0.003205,0.399185,-143.139694,0.039025,0.000000
151.800003,-0.018616,-143.139694,-0.002953,0.001572,0.039936,-0.082807,-0.004218,0.399359,-143.139694,0.039754,0.000000