File: Data/compression 19/AutoNoHeating-17-19-reverse-2-4_09112024_163928.csv
Time (sec),S:Load (lbs),S:HL1 (DIM),S:LVDT (in),S:Position (in),Ch:Position (mm),Ch:Load (N),Ch:Stress (MPa),Ch:Strain (mm/mm),Ch:HL1 (DIM),Set Point (),Cycles ()
0.110000,-0.071495,-63.696720,-0.010516,-0.005750,-0.146041,-0.318026,-0.016201,-1.460408,-63.696720,-0.145815,0.000000
0.460000,-0.038353,-63.741203,-0.010511,-0.005689,-0.144488,-0.170603,-0.008691,-1.444885,-63.741203,-0.143786,0.000000
0.810000,-0.107986,-63.741203,-0.010391,-0.005480,-0.139181,-0.480348,-0.024470,-1.391811,-63.741203,-0.137958,0.000000
1.160000,-0.033516,-63.785683,-0.010167,-0.005250,-0.133353,-0.149086,-0.007595,-1.333533,-63.785683,-0.132131,0.000000
1.510000,0.004463,-63.785683,-0.009929,-0.005023,-0.127578,0.019853,0.001011,-1.275776,-63.785683,-0.126303,0.000000
1.860000,-0.019363,-63.874645,-0.009705,-0.004796,-0.121828,-0.086133,-0.004388,-1.218279,-63.874645,-0.120475,0.000000
2.210000,-0.057350,-63.830166,-0.009459,-0.004568,-0.116017,-0.255106,-0.012996,-1.160174,-63.830166,-0.114647,0.000000
2.560000,-0.064049,-63.874645,-0.009214,-0.004334,-0.110077,-0.284903,-0.014514,-1.100770,-63.874645,-0.108802,0.000000
2.910000,-0.060699,-63.874645,-0.008985,-0.004106,-0.104293,-0.270005,-0.013755,-1.042926,-63.874645,-0.102974,0.000000
3.260000,-0.008942,-63.963608,-0.008748,-0.003876,-0.098439,-0.039774,-0.002026,-0.984388,-63.963608,-0.097147,0.000000
3.610000,-0.019737,-64.008087,-0.008515,-0.003646,-0.092602,-0.087796,-0.004473,-0.926024,-64.008087,-0.091319,0.000000
3.960000,-0.018623,-64.052567,-0.008282,-0.003418,-0.086818,-0.082841,-0.004220,-0.868180,-64.052567,-0.085491,0.000000
4.310000,-0.040588,-64.052567,-0.008032,-0.003182,-0.080834,-0.180546,-0.009197,-0.808341,-64.052567,-0.079646,0.000000
4.660000,-0.032028,-64.097054,-0.007800,-0.002953,-0.075006,-0.142469,-0.007258,-0.750064,-64.097054,-0.073818,0.000000
5.010000,-0.039848,-64.097054,-0.007562,-0.002725,-0.069205,-0.177254,-0.009030,-0.692046,-64.097054,-0.067990,0.000000
5.360000,0.012657,-64.097054,-0.007334,-0.002495,-0.063386,0.056302,0.002868,-0.633855,-64.097054,-0.062163,0.000000
5.710000,-0.021599,-64.186012,-0.007088,-0.002267,-0.057575,-0.096076,-0.004894,-0.575751,-64.186012,-0.056335,0.000000
6.060000,-0.030167,-64.186012,-0.006868,-0.002038,-0.051756,-0.134188,-0.006836,-0.517560,-64.186012,-0.050507,0.000000
6.410000,-0.000000,-64.186012,-0.006618,-0.001808,-0.045928,-0.000000,-0.000000,-0.459283,-64.186012,-0.044662,0.000000
6.760000,-0.019737,-64.274971,-0.006377,-0.001576,-0.040040,-0.087796,-0.004473,-0.400398,-64.274971,-0.038834,0.000000
7.110000,-0.017128,-64.230492,-0.006157,-0.001348,-0.034238,-0.076189,-0.003881,-0.342381,-64.230492,-0.033007,0.000000
7.460001,-0.016014,-64.274971,-0.005898,-0.001115,-0.028315,-0.071234,-0.003629,-0.283149,-64.274971,-0.027179,0.000000
7.810000,-0.025696,-64.319458,-0.005678,-0.000888,-0.022557,-0.114301,-0.005823,-0.225565,-64.319458,-0.021351,0.000000
8.160001,0.022713,-64.408417,-0.005441,-0.000663,-0.016850,0.101031,0.005147,-0.168502,-64.408417,-0.015506,0.000000
8.510000,-0.001862,-64.408417,-0.005217,-0.000433,-0.010996,-0.008281,-0.000422,-0.109964,-64.408417,-0.009678,0.000000
8.860001,0.018616,-64.408417,-0.004980,-0.000198,-0.005030,0.082807,0.004218,-0.050299,-64.408417,-0.003850,0.000000
9.210000,0.079315,-64.408417,-0.004855,-0.000000,-0.000000,0.352812,0.017973,-0.000000,-64.408417,0.000234,0.000000
9.560000,0.068146,-64.452896,-0.004838,-0.000000,-0.000000,0.303127,0.015442,-0.000000,-64.452896,0.000234,0.000000
9.910001,0.130699,-64.452896,-0.004859,-0.000000,-0.000000,0.581379,0.029617,-0.000000,-64.452896,0.000798,0.000000
10.260000,0.131821,-64.541862,-0.004842,0.000000,0.000009,0.586368,0.029871,0.000087,-64.541862,0.001379,0.000000
10.610001,0.256561,-64.586342,-0.004816,0.000035,0.000885,1.141242,0.058138,0.008846,-64.586342,0.001969,0.000000
10.960001,0.419289,-64.586342,-0.004790,0.000063,0.001604,1.865089,0.095012,0.016044,-64.586342,0.002550,0.000000
11.310000,0.594307,-64.630821,-0.004769,0.000085,0.002151,2.643609,0.134672,0.021507,-64.630821,0.003131,0.000000
11.660001,0.822571,-64.630821,-0.004764,0.000108,0.002740,3.658978,0.186397,0.027404,-64.630821,0.003712,0.000000
12.010000,1.159569,-64.719788,-0.004738,0.000132,0.003347,5.158020,0.262762,0.033475,-64.719788,0.004301,0.000000
12.360001,1.400864,-64.719788,-0.004708,0.000150,0.003816,6.231353,0.317440,0.038158,-64.719788,0.004882,0.000000
12.710001,1.720734,-64.719788,-0.004695,0.000171,0.004345,7.654205,0.389924,0.043448,-64.719788,0.005464,0.000000
13.060000,2.087891,-64.764267,-0.004674,0.000197,0.004995,9.287401,0.473123,0.049952,-64.764267,0.006045,0.000000
13.410001,2.440155,-64.764267,-0.004665,0.000215,0.005464,10.854352,0.552947,0.054635,-64.764267,0.006634,0.000000
13.760000,2.938019,-64.853226,-0.004648,0.000241,0.006114,13.068960,0.665765,0.061139,-64.853226,0.007215,0.000000
14.110001,3.482056,-64.808746,-0.004626,0.000264,0.006704,15.488957,0.789045,0.067037,-64.808746,0.007796,0.000000
14.460001,4.063324,-64.897705,-0.004605,0.000294,0.007475,18.074568,0.920762,0.074755,-64.897705,0.008377,0.000000
14.810000,4.571617,-64.942192,-0.004575,0.000318,0.008074,20.335569,1.035943,0.080739,-64.942192,0.008967,0.000000
15.160001,4.984947,-64.986671,-0.004553,0.000337,0.008551,22.174152,1.129605,0.085508,-64.986671,0.009548,0.000000
15.510001,5.610161,-64.986671,-0.004527,0.000363,0.009227,24.955242,1.271281,0.092273,-64.986671,0.010129,0.000000
15.860001,5.918861,-65.031151,-0.004518,0.000379,0.009635,26.328411,1.341233,0.096349,-65.031151,0.010719,0.000000
16.210001,6.471832,-64.986671,-0.004506,0.000401,0.010181,28.788147,1.466538,0.101812,-64.986671,0.011300,0.000000
16.560001,6.868408,-65.075630,-0.004484,0.000422,0.010719,30.552206,1.556404,0.107189,-65.075630,0.011881,0.000000
16.910002,7.646667,-65.075630,-0.004454,0.000452,0.011491,34.014076,1.732760,0.114907,-65.075630,0.012462,0.000000
17.260000,7.969139,-65.075630,-0.004445,0.000472,0.011994,35.448502,1.805833,0.119937,-65.075630,0.013052,0.000000
17.610001,8.624146,-65.164597,-0.004406,0.000499,0.012679,38.362114,1.954259,0.126788,-65.164597,0.013633,0.000000
17.960001,8.937309,-65.209076,-0.004402,0.000515,0.013086,39.755138,2.025223,0.130864,-65.209076,0.014214,0.000000
18.310001,9.819458,-65.253555,-0.004376,0.000547,0.013893,43.679131,2.225121,0.138930,-65.253555,0.014795,0.000000
18.660002,9.973251,-65.298035,-0.004359,0.000565,0.014361,44.363239,2.259971,0.143613,-65.298035,0.015385,0.000000
19.010000,10.490105,-65.298035,-0.004329,0.000588,0.014925,46.662315,2.377092,0.149250,-65.298035,0.015966,0.000000
19.360001,11.059830,-65.298035,-0.004320,0.000611,0.015532,49.196579,2.506193,0.155320,-65.298035,0.016547,0.000000
19.710001,10.918335,-65.342514,-0.004299,0.000621,0.015784,48.567181,2.474130,0.157835,-65.342514,0.017136,0.000000
20.060001,11.796387,-65.387001,-0.004268,0.000653,0.016590,52.472950,2.673100,0.165900,-65.387001,0.017717,0.000000
20.410002,12.240257,-65.387001,-0.004251,0.000676,0.017180,54.447384,2.773682,0.171797,-65.387001,0.018298,0.000000
20.760000,12.327019,-65.475960,-0.004247,0.000693,0.017613,54.833317,2.793342,0.176134,-65.475960,0.018880,0.000000
21.110001,13.138412,-65.475960,-0.004199,0.000728,0.018489,58.442577,2.977207,0.184893,-65.475960,0.019469,0.000000
21.460001,13.745384,-65.475960,-0.004178,0.000753,0.019114,61.142521,3.114749,0.191137,-65.475960,0.020050,0.000000
21.810001,13.922630,-65.609406,-0.004165,0.000770,0.019547,61.930954,3.154913,0.195473,-65.609406,0.020631,0.000000
22.160002,13.959869,-65.520439,-0.004143,0.000787,0.019990,62.096600,3.163352,0.199896,-65.520439,0.021212,0.000000
22.510000,14.850212,-65.564919,-0.004109,0.000815,0.020692,66.057045,3.365106,0.206920,-65.564919,0.021802,0.000000
22.860001,15.313812,-65.609406,-0.004109,0.000838,0.021290,68.119240,3.470160,0.212904,-65.609406,0.022383,0.000000
23.210001,15.289612,-65.653885,-0.004070,0.000859,0.021828,68.011589,3.464676,0.218281,-65.653885,0.022964,0.000000
23.560001,15.186462,-65.698364,-0.004061,0.000877,0.022279,67.552757,3.441301,0.222790,-65.698364,0.023545,0.000000
23.910002,16.385880,-65.742844,-0.004053,0.000908,0.023060,72.888031,3.713093,0.230595,-65.742844,0.024135,0.000000
24.260000,16.563126,-65.698364,-0.004014,0.000930,0.023632,73.676460,3.753258,0.236319,-65.698364,0.024716,0.000000
24.610001,17.361862,-65.742844,-0.003988,0.000958,0.024326,77.229424,3.934254,0.243257,-65.742844,0.025297,0.000000
24.960001,17.390533,-65.831810,-0.003967,0.000975,0.024777,77.356956,3.940751,0.247766,-65.831810,0.025887,0.000000
25.310001,17.889519,-65.831810,-0.003941,0.001003,0.025479,79.576553,4.053823,0.254791,-65.831810,0.026468,0.000000
25.660002,18.134537,-65.876289,-0.003923,0.001025,0.026034,80.666451,4.109345,0.260341,-65.876289,0.027049,0.000000
26.010002,18.107353,-65.965248,-0.003889,0.001043,0.026494,80.545532,4.103185,0.264937,-65.965248,0.027630,0.000000
26.360001,18.838318,-65.965248,-0.003876,0.001069,0.027153,83.797020,4.268824,0.271528,-65.965248,0.028220,0.000000
26.710001,19.207718,-66.009735,-0.003850,0.001093,0.027769,85.440193,4.352531,0.277686,-66.009735,0.028801,0.000000
27.060001,19.108292,-65.965248,-0.003846,0.001110,0.028185,84.997925,4.330000,0.281848,-65.965248,0.029382,0.000000
27.410002,19.221863,-66.054214,-0.003811,0.001127,0.028636,85.503113,4.355737,0.286358,-66.054214,0.029963,0.000000
27.760002,20.099922,-66.054214,-0.003768,0.001159,0.029451,89.408920,4.554708,0.294510,-66.054214,0.030552,0.000000
28.110001,20.379196,-66.098694,-0.003755,0.001185,0.030110,90.651192,4.617992,0.301101,-66.098694,0.031133,0.000000
28.460001,20.467079,-66.098694,-0.003729,0.001205,0.030596,91.042114,4.637906,0.305957,-66.098694,0.031714,0.000000
28.810001,20.316269,-66.143173,-0.003704,0.001220,0.030995,90.371277,4.603733,0.309946,-66.143173,0.032295,0.000000
29.160002,21.336571,-66.187653,-0.003686,0.001254,0.031862,94.909805,4.834936,0.318619,-66.187653,0.032885,0.000000
29.510002,21.359657,-66.232140,-0.003643,0.001276,0.032400,95.012505,4.840168,0.323996,-66.232140,0.033466,0.000000
29.860001,21.666489,-66.232140,-0.003630,0.001301,0.033041,96.377357,4.909696,0.330413,-66.232140,0.034047,0.000000
30.210001,21.514931,-66.365578,-0.003604,0.001315,0.033406,95.703194,4.875353,0.334055,-66.365578,0.034637,0.000000
30.560001,22.016518,-66.276619,-0.003579,0.001342,0.034091,97.934364,4.989015,0.340906,-66.276619,0.035218,0.000000
30.910002,21.799057,-66.321098,-0.003557,0.001355,0.034420,96.967049,4.939737,0.344202,-66.321098,0.035799,0.000000
31.260002,22.869995,-66.365578,-0.003531,0.001392,0.035365,101.730820,5.182415,0.353655,-66.365578,0.036380,0.000000
31.610001,22.957130,-66.365578,-0.003510,0.001412,0.035860,102.118416,5.202160,0.358598,-66.365578,0.036970,0.000000
31.960001,23.533562,-66.410057,-0.003471,0.001444,0.036666,104.682510,5.332781,0.366663,-66.410057,0.037551,0.000000
32.310001,23.508247,-66.499023,-0.003454,0.001462,0.037126,104.569908,5.327045,0.371259,-66.499023,0.038132,0.000000
32.660000,23.553673,-66.543503,-0.003423,0.001484,0.037681,104.771973,5.337338,0.376810,-66.543503,0.038713,0.000000
33.010002,23.812469,-66.499023,-0.003419,0.001507,0.038288,105.923157,5.395983,0.382880,-66.499023,0.039303,0.000000
33.360001,24.355392,-66.454544,-0.003372,0.001532,0.038921,108.338196,5.519011,0.389211,-66.454544,0.039884,0.000000
33.710003,24.267509,-66.632462,-0.003346,0.001549,0.039355,107.947273,5.499096,0.393547,-66.632462,0.040465,0.000000
34.060001,24.026588,-66.632462,-0.003333,0.001562,0.039676,106.875603,5.444503,0.396756,-66.632462,0.041054,0.000000
34.410000,24.948212,-66.632462,-0.003311,0.001595,0.040517,110.975189,5.653346,0.405168,-66.632462,0.041636,0.000000
34.760002,24.995125,-66.632462,-0.003277,0.001619,0.041124,111.183868,5.663976,0.411238,-66.632462,0.042217,0.000000
35.110001,25.180939,-66.721428,-0.003264,0.001640,0.041653,112.010406,5.706082,0.416528,-66.721428,0.042798,0.000000
35.460003,25.799828,-66.721428,-0.003229,0.001666,0.042312,114.763367,5.846324,0.423119,-66.721428,0.043387,0.000000
35.810001,26.304390,-66.810387,-0.003208,0.001695,0.043040,117.007767,5.960660,0.430404,-66.810387,0.043968,0.000000
36.160000,26.512177,-66.765907,-0.003182,0.001719,0.043665,117.932053,6.007745,0.436648,-66.765907,0.044549,0.000000
36.510002,26.272736,-66.854866,-0.003147,0.001738,0.044133,116.866966,5.953487,0.441331,-66.854866,0.045130,0.000000
36.860001,26.705437,-66.810387,-0.003143,0.001762,0.044766,118.791718,6.051538,0.447662,-66.810387,0.045720,0.000000
37.210003,26.448128,-66.899353,-0.003109,0.001778,0.045156,117.647148,5.993232,0.451564,-66.899353,0.046301,0.000000
37.560001,26.763153,-66.854866,-0.003087,0.001801,0.045746,119.048454,6.064618,0.457462,-66.854866,0.046882,0.000000
37.910004,27.328041,-66.943832,-0.003065,0.001829,0.046449,121.561195,6.192623,0.464486,-66.943832,0.047463,0.000000
38.260002,27.739143,-66.943832,-0.003040,0.001851,0.047012,123.389870,6.285780,0.470123,-66.943832,0.048053,0.000000
38.610001,27.775261,-66.988312,-0.003009,0.001871,0.047515,123.550529,6.293964,0.475153,-66.988312,0.048634,0.000000
38.960003,28.305145,-67.032791,-0.002979,0.001899,0.048244,125.907578,6.414038,0.482438,-67.032791,0.049215,0.000000
39.310001,28.425797,-67.121758,-0.002936,0.001921,0.048799,126.444260,6.441378,0.487988,-67.121758,0.049805,0.000000
39.660004,29.003342,-67.121758,-0.002932,0.001946,0.049423,129.013306,6.572251,0.494232,-67.121758,0.050386,0.000000
40.010002,28.825722,-67.121758,-0.002906,0.001965,0.049918,128.223221,6.532002,0.499175,-67.121758,0.050967,0.000000
40.360001,29.235336,-67.166237,-0.002880,0.001989,0.050516,130.045273,6.624822,0.505159,-67.166237,0.051548,0.000000
40.710003,29.573822,-67.166237,-0.002846,0.002010,0.051062,131.550934,6.701524,0.510623,-67.166237,0.052138,0.000000
41.060001,29.839317,-67.210716,-0.002828,0.002035,0.051678,132.731918,6.761686,0.516780,-67.210716,0.052719,0.000000
41.410004,29.867996,-67.255196,-0.002794,0.002052,0.052120,132.859482,6.768185,0.521203,-67.255196,0.053300,0.000000
41.760002,30.176689,-67.299683,-0.002781,0.002075,0.052701,134.232620,6.838135,0.527013,-67.299683,0.053881,0.000000
42.110001,30.563210,-67.299683,-0.002764,0.002106,0.053482,135.951950,6.925722,0.534818,-67.299683,0.054470,0.000000
42.460003,31.165337,-67.433121,-0.002738,0.002127,0.054037,138.630341,7.062166,0.540368,-67.433121,0.055051,0.000000
42.810001,31.523560,-67.344162,-0.002725,0.002151,0.054644,140.223801,7.143341,0.546439,-67.344162,0.055633,0.000000
43.160004,31.453552,-67.388641,-0.002690,0.002169,0.055104,139.912384,7.127477,0.551035,-67.388641,0.056222,0.000000
43.510002,31.304977,-67.388641,-0.002652,0.002191,0.055641,139.251495,7.093810,0.556412,-67.388641,0.056803,0.000000
43.860001,32.268677,-67.522087,-0.002630,0.002215,0.056257,143.538239,7.312187,0.562569,-67.522087,0.057384,0.000000
44.210003,32.857025,-67.433121,-0.002604,0.002243,0.056968,146.155350,7.445508,0.569681,-67.433121,0.057965,0.000000
44.560001,33.165726,-67.477600,-0.002591,0.002263,0.057480,147.528519,7.515460,0.574797,-67.477600,0.058555,0.000000
44.910004,33.516502,-67.477600,-0.002578,0.002286,0.058069,149.088852,7.594948,0.580694,-67.477600,0.059136,0.000000
45.260002,33.767479,-67.566566,-0.002548,0.002306,0.058581,150.205246,7.651820,0.585811,-67.566566,0.059717,0.000000
45.610001,34.269066,-67.566566,-0.002509,0.002332,0.059240,152.436417,7.765481,0.592402,-67.566566,0.060298,0.000000
45.960003,34.973961,-67.611046,-0.002483,0.002358,0.059891,155.571945,7.925213,0.598906,-67.611046,0.060888,0.000000
46.310001,34.907684,-67.611046,-0.002471,0.002374,0.060298,155.277130,7.910194,0.602982,-67.611046,0.061469,0.000000
46.660004,35.707909,-67.744492,-0.002445,0.002402,0.061009,158.836716,8.091528,0.610093,-67.744492,0.062050,0.000000
47.010002,36.141350,-67.744492,-0.002423,0.002426,0.061625,160.764755,8.189747,0.616251,-67.744492,0.062631,0.000000
47.360001,36.227371,-67.788971,-0.002406,0.002447,0.062145,161.147400,8.209240,0.621454,-67.788971,0.063221,0.000000
47.710003,36.820557,-67.833450,-0.002371,0.002472,0.062796,163.786011,8.343657,0.627958,-67.833450,0.063802,0.000000
48.060001,37.319542,-67.833450,-0.002345,0.002492,0.063299,166.005615,8.456729,0.632988,-67.833450,0.064383,0.000000
48.410004,37.169846,-67.833450,-0.002324,0.002508,0.063706,165.339737,8.422808,0.637064,-67.833450,0.064973,0.000000
48.760002,38.264244,-67.922409,-0.002307,0.002537,0.064444,170.207855,8.670802,0.644435,-67.922409,0.065554,0.000000
49.110001,38.651886,-67.877930,-0.002276,0.002560,0.065016,171.932175,8.758643,0.650159,-67.877930,0.066135,0.000000
49.460003,39.399986,-67.966896,-0.002268,0.002587,0.065710,175.259888,8.928164,0.657097,-67.966896,0.066716,0.000000
49.810001,39.488235,-67.966896,-0.002238,0.002603,0.066126,175.652451,8.948162,0.661260,-67.966896,0.067305,0.000000
50.160004,39.967850,-67.966896,-0.002212,0.002627,0.066724,177.785873,9.056844,0.667243,-67.966896,0.067886,0.000000
50.510002,41.060020,-68.100334,-0.002182,0.002656,0.067470,182.644089,9.304334,0.674702,-68.100334,0.068467,0.000000
50.860001,41.530327,-68.100334,-0.002169,0.002681,0.068086,184.736115,9.410907,0.680859,-68.100334,0.069049,0.000000
51.210003,41.710930,-68.100334,-0.002156,0.002700,0.068580,185.539490,9.451832,0.685802,-68.100334,0.069638,0.000000
51.560001,41.797691,-68.189301,-0.002113,0.002723,0.069161,185.925415,9.471493,0.691612,-68.189301,0.070219,0.000000
51.910004,42.615791,-68.144814,-0.002082,0.002742,0.069638,189.564514,9.656877,0.696382,-68.144814,0.070800,0.000000
52.260002,43.001198,-68.189301,-0.002061,0.002766,0.070254,191.278885,9.744210,0.702540,-68.189301,0.071390,0.000000
52.610001,43.961922,-68.233780,-0.002052,0.002792,0.070913,195.552399,9.961913,0.709130,-68.233780,0.071971,0.000000
52.960003,44.253487,-68.322739,-0.002035,0.002810,0.071381,196.849335,10.027984,0.713813,-68.322739,0.072552,0.000000
53.310001,44.958763,-68.322739,-0.002013,0.002843,0.072205,199.986572,10.187801,0.722052,-68.322739,0.073133,0.000000
53.660004,45.688240,-68.322739,-0.001970,0.002860,0.072647,203.231445,10.353104,0.726475,-68.322739,0.073723,0.000000
54.010002,46.063965,-68.411705,-0.001957,0.002884,0.073246,204.902756,10.438243,0.732459,-68.411705,0.074304,0.000000
54.360004,46.739449,-68.367218,-0.001940,0.002907,0.073844,207.907455,10.591311,0.738443,-68.367218,0.074885,0.000000
54.710003,47.407852,-68.456184,-0.001906,0.002931,0.074460,210.880661,10.742772,0.744600,-68.456184,0.075466,0.000000
55.060001,47.531105,-68.456184,-0.001893,0.002948,0.074876,211.428909,10.770702,0.748763,-68.456184,0.076056,0.000000
55.410004,47.716919,-68.545143,-0.001871,0.002974,0.075544,212.255463,10.812809,0.755440,-68.545143,0.076637,0.000000
55.760002,48.785629,-68.456184,-0.001850,0.002994,0.076038,217.009323,11.054982,0.760383,-68.456184,0.077218,0.000000
56.110004,48.940910,-68.545143,-0.001815,0.003012,0.076507,217.700043,11.090169,0.765067,-68.545143,0.077799,0.000000
56.460003,49.958603,-68.589630,-0.001798,0.003041,0.077252,222.226959,11.320782,0.772525,-68.589630,0.078389,0.000000
56.810001,50.683617,-68.589630,-0.001768,0.003065,0.077860,225.451981,11.485071,0.778595,-68.589630,0.078970,0.000000
57.160004,50.973320,-68.634109,-0.001768,0.003088,0.078432,226.740646,11.550719,0.784319,-68.634109,0.079551,0.000000
57.510002,52.570427,-68.723068,-0.001733,0.003120,0.079238,233.844940,11.912629,0.792384,-68.723068,0.080140,0.000000
57.860004,52.749161,-68.723068,-0.001716,0.003136,0.079655,234.639984,11.953131,0.796547,-68.723068,0.080721,0.000000
58.210003,53.615677,-68.723068,-0.001686,0.003161,0.080288,238.494446,12.149486,0.802878,-68.723068,0.081302,0.000000
58.560001,53.522957,-68.767548,-0.001677,0.003177,0.080695,238.082001,12.128476,0.806954,-68.767548,0.081883,0.000000
58.910004,54.024910,-68.812035,-0.001647,0.003200,0.081285,240.314804,12.242219,0.812851,-68.812035,0.082473,0.000000
59.260002,55.107399,-68.856514,-0.001621,0.003228,0.081979,245.129959,12.487515,0.819789,-68.856514,0.083054,0.000000
59.610004,55.712135,-68.812035,-0.001591,0.003249,0.082534,247.819962,12.624550,0.825339,-68.812035,0.083635,0.000000
59.960003,56.071098,-68.945473,-0.001569,0.003271,0.083072,249.416702,12.705893,0.830715,-68.945473,0.084216,0.000000
60.310001,57.200874,-68.945473,-0.001552,0.003298,0.083774,254.442200,12.961904,0.837740,-68.945473,0.084806,0.000000
60.660004,57.591866,-68.945473,-0.001539,0.003320,0.084320,256.181427,13.050503,0.843203,-68.945473,0.085387,0.000000
61.010002,58.529129,-68.989952,-0.001492,0.003345,0.084962,260.350555,13.262890,0.849621,-68.989952,0.085968,0.000000
61.360004,58.560036,-69.078918,-0.001496,0.003364,0.085456,260.488037,13.269894,0.854564,-69.078918,0.086558,0.000000
61.710003,59.340157,-69.034439,-0.001462,0.003388,0.086055,263.958191,13.446671,0.860548,-69.034439,0.087139,0.000000
62.060001,59.994041,-69.078918,-0.001449,0.003409,0.086584,266.866821,13.594844,0.865838,-69.078918,0.087720,0.000000
62.410004,59.411652,-69.078918,-0.001414,0.003420,0.086879,264.276215,13.462873,0.868787,-69.078918,0.088301,0.000000
62.760002,61.094032,-69.123398,-0.001397,0.003452,0.087677,271.759827,13.844105,0.876765,-69.123398,0.088891,0.000000
63.110004,61.905800,-69.123398,-0.001380,0.003474,0.088249,275.370758,14.028055,0.882489,-69.123398,0.089472,0.000000
63.460003,61.977295,-69.167877,-0.001350,0.003491,0.088665,275.688782,14.044256,0.886652,-69.167877,0.090053,0.000000
63.810001,63.849213,-69.212357,-0.001332,0.003526,0.089558,284.015472,14.468438,0.895584,-69.212357,0.090634,0.000000
64.160004,64.694504,-69.256844,-0.001319,0.003550,0.090165,287.775513,14.659984,0.901655,-69.256844,0.091223,0.000000
64.510002,65.149918,-69.301323,-0.001302,0.003572,0.090738,289.801300,14.763183,0.907378,-69.301323,0.091805,0.000000
64.860001,64.944366,-69.390282,-0.001285,0.003589,0.091171,288.886963,14.716604,0.911714,-69.390282,0.092386,0.000000
65.210007,65.610168,-69.345802,-0.001237,0.003598,0.091380,291.848602,14.867476,0.913796,-69.345802,0.016039,0.000000
65.560005,66.883682,-69.390282,-0.001229,0.003571,0.090712,297.513489,15.156059,0.907118,-69.390282,294.500458,0.000000
65.910004,65.218430,-69.345802,-0.001199,0.003598,0.091388,290.106049,14.778708,0.913882,-69.345802,294.500458,0.000000
66.260002,65.022934,-69.345802,-0.001207,0.003634,0.092299,289.236450,14.734407,0.922988,-69.345802,294.500458,0.000000
66.610001,64.653168,-69.479248,-0.001190,0.003642,0.092516,287.591644,14.650617,0.925156,-69.479248,294.500458,0.000000
66.960007,65.461960,-69.479248,-0.001173,0.003648,0.092663,291.189331,14.833892,0.926631,-69.479248,294.500458,0.000000
67.310005,65.850342,-69.523727,-0.001147,0.003668,0.093175,292.916962,14.921901,0.931747,-69.523727,294.500458,0.000000
67.660004,64.673279,-69.523727,-0.001160,0.003668,0.093175,287.681122,14.655174,0.931747,-69.523727,294.500458,0.000000
68.010002,66.582428,-69.612686,-0.001117,0.003514,0.089246,296.173431,15.087794,0.892462,-69.612686,294.500458,0.000000
68.360001,65.462326,-69.612686,-0.001108,0.003548,0.090122,291.190979,14.833976,0.901221,-69.612686,294.500458,0.000000
68.710007,65.078415,-69.657173,-0.001108,0.003705,0.094103,289.483246,14.746980,0.941027,-69.657173,294.500458,0.000000
69.060005,64.952927,-69.701653,-0.001095,0.003715,0.094363,288.925049,14.718543,0.943628,-69.701653,294.500458,0.000000
69.410004,65.350616,-69.746132,-0.001091,0.003726,0.094649,290.694061,14.808661,0.946490,-69.746132,294.500458,0.000000
69.760002,64.652054,-69.701653,-0.001082,0.003727,0.094658,287.586700,14.650364,0.946577,-69.701653,294.500458,0.000000
70.110001,66.908630,-69.790611,-0.001061,0.003618,0.091909,297.624451,15.161713,0.919086,-69.790611,294.500458,0.000000
70.460007,65.958710,-69.746132,-0.001052,0.003603,0.091527,293.398987,14.946458,0.915270,-69.746132,294.500458,0.000000
70.810005,65.243378,-69.790611,-0.001056,0.003720,0.094484,290.217041,14.784361,0.944842,-69.790611,294.500458,0.000000
71.160004,65.218430,-69.879578,-0.001052,0.003757,0.095421,290.106049,14.778708,0.954208,-69.879578,294.500458,0.000000
71.510002,65.024048,-69.879578,-0.001052,0.003763,0.095577,289.241425,14.734660,0.955769,-69.879578,294.500458,0.000000
71.860001,65.315613,-69.879578,-0.001056,0.003772,0.095820,290.538361,14.800730,0.958198,-69.879578,294.500458,0.000000
72.210007,64.877335,-69.924057,-0.001035,0.003772,0.095820,288.588806,14.701414,0.958198,-69.924057,294.500458,0.000000
72.560005,65.373703,-69.968536,-0.001043,0.003783,0.096089,290.796753,14.813893,0.960886,-69.968536,294.500458,0.000000
72.910004,64.913452,-70.013016,-0.001026,0.003783,0.096089,288.749451,14.709599,0.960886,-70.013016,294.500458,0.000000
73.260002,64.431229,-70.013016,-0.001009,0.003783,0.096097,286.604431,14.600326,0.960973,-70.013016,294.500458,0.000000
73.610001,67.744232,-70.101982,-0.001013,0.003673,0.093296,301.341400,15.351063,0.932961,-70.101982,294.500458,0.000000
73.960007,65.828003,-70.101982,-0.000987,0.003605,0.091570,292.817596,14.916839,0.915704,-70.101982,294.500458,0.000000
74.310005,65.296631,-70.101982,-0.000983,0.003724,0.094588,290.453918,14.796428,0.945883,-70.101982,294.500458,0.000000
74.660004,65.253799,-70.101982,-0.000992,0.003801,0.096548,290.263397,14.786722,0.965482,-70.101982,294.500458,0.000000
75.010002,65.291779,-70.190941,-0.000983,0.003808,0.096730,290.432343,14.795329,0.967304,-70.190941,294.500458,0.000000
75.360001,65.164810,-70.235420,-0.000974,0.003812,0.096826,289.867554,14.766557,0.968257,-70.235420,294.500458,0.000000
75.710007,65.211349,-70.235420,-0.000974,0.003818,0.096965,290.074585,14.777102,0.969645,-70.235420,294.500458,0.000000
76.060005,65.116028,-70.279900,-0.000979,0.003821,0.097051,289.650543,14.755503,0.970512,-70.279900,294.500458,0.000000
76.410004,65.152893,-70.279900,-0.000983,0.003824,0.097138,289.814545,14.763856,0.971379,-70.279900,294.500458,0.000000
76.760002,65.120499,-70.324387,-0.000983,0.003827,0.097216,289.670441,14.756516,0.972160,-70.324387,294.500458,0.000000
77.110001,65.030014,-70.324387,-0.000979,0.003830,0.097285,289.267944,14.736012,0.972854,-70.324387,294.500458,0.000000
77.460007,65.046768,-70.368866,-0.000966,0.003834,0.097372,289.342468,14.739808,0.973721,-70.368866,294.500458,0.000000
77.810005,64.999100,-70.413345,-0.000983,0.003836,0.097433,289.130432,14.729006,0.974328,-70.413345,294.500458,0.000000
78.160004,65.423233,-70.502304,-0.000966,0.003843,0.097606,291.017090,14.825116,0.976063,-70.502304,294.500458,0.000000
78.510002,65.218063,-70.502304,-0.000970,0.003843,0.097606,290.104431,14.778625,0.976063,-70.502304,294.500458,0.000000
78.860001,64.965210,-70.502304,-0.000974,0.003843,0.097606,288.979675,14.721327,0.976063,-70.502304,294.500458,0.000000
79.210007,65.580368,-70.546791,-0.000953,0.003853,0.097858,291.716034,14.860724,0.978577,-70.546791,294.500458,0.000000
79.560005,65.414673,-70.546791,-0.000949,0.003853,0.097858,290.979004,14.823176,0.978577,-70.546791,294.500458,0.000000
79.910004,65.210983,-70.591270,-0.000940,0.003853,0.097858,290.072937,14.777020,0.978577,-70.591270,294.500458,0.000000
80.260002,64.987930,-70.635750,-0.000944,0.003853,0.097858,289.080750,14.726475,0.978577,-70.635750,294.500458,0.000000
80.610001,64.769348,-70.635750,-0.000949,0.003853,0.097866,288.108459,14.676944,0.978664,-70.635750,294.500458,0.000000
80.960007,64.571243,-70.680229,-0.000953,0.003853,0.097866,287.227234,14.632053,0.978664,-70.680229,294.500458,0.000000
81.310005,66.679993,-70.724709,-0.000949,0.003813,0.096860,296.607422,15.109902,0.968604,-70.724709,294.500458,0.000000
81.660004,66.392517,-70.769196,-0.000931,0.003813,0.096852,295.328674,15.044760,0.968518,-70.769196,294.500458,0.000000
82.010002,66.144516,-70.813675,-0.000927,0.003813,0.096852,294.225494,14.988562,0.968518,-70.813675,294.500458,0.000000
82.360001,65.925186,-70.858154,-0.000918,0.003813,0.096852,293.249878,14.938861,0.968518,-70.858154,294.500458,0.000000
82.710007,65.661179,-70.858154,-0.000927,0.003815,0.096895,292.075500,14.879036,0.968951,-70.858154,294.500458,0.000000
83.060005,65.499191,-70.858154,-0.000931,0.003836,0.097433,291.354950,14.842328,0.974328,-70.858154,294.500458,0.000000
83.410004,65.322693,-70.902634,-0.000914,0.003849,0.097762,290.569855,14.802334,0.977624,-70.902634,294.500458,0.000000
83.760002,65.161453,-70.947121,-0.000927,0.003853,0.097875,289.852631,14.765797,0.978751,-70.947121,294.500458,0.000000
84.110001,65.293640,-70.947121,-0.000927,0.003874,0.098404,290.440613,14.795751,0.984041,-70.947121,294.500458,0.000000
84.460007,65.163315,-70.991600,-0.000914,0.003874,0.098404,289.860901,14.766218,0.984041,-70.991600,294.500458,0.000000
84.810005,65.016968,-70.991600,-0.000936,0.003876,0.098439,289.209930,14.733055,0.984388,-70.991600,294.500458,0.000000
85.160004,65.584091,-71.080559,-0.000931,0.003884,0.098647,291.732605,14.861567,0.986469,-71.080559,294.500458,0.000000
85.510002,65.469040,-71.080559,-0.000923,0.003884,0.098647,291.220825,14.835497,0.986469,-71.080559,294.500458,0.000000
85.860001,65.292526,-71.080559,-0.000923,0.003884,0.098647,290.435669,14.795499,0.986469,-71.080559,294.500458,0.000000
86.210007,65.216934,-71.080559,-0.000923,0.003885,0.098673,290.099426,14.778368,0.986729,-71.080559,294.500458,0.000000
86.560005,65.238159,-71.169525,-0.000923,0.003887,0.098742,290.193817,14.783178,0.987423,-71.169525,294.500458,0.000000
86.910004,65.157364,-71.214005,-0.000918,0.003889,0.098777,289.834442,14.764870,0.987770,-71.214005,294.500458,0.000000
87.260002,65.209869,-71.169525,-0.000931,0.003890,0.098803,290.067993,14.776768,0.988030,-71.169525,294.500458,0.000000
87.610001,65.105225,-71.214005,-0.000901,0.003890,0.098812,289.602509,14.753055,0.988117,-71.214005,294.500458,0.000000
87.960007,65.031876,-71.258484,-0.000914,0.003891,0.098838,289.276245,14.736434,0.988377,-71.258484,294.500458,0.000000
88.310005,64.963348,-71.347443,-0.000923,0.003891,0.098838,288.971405,14.720905,0.988377,-71.347443,294.500458,0.000000
88.660004,64.989426,-71.347443,-0.000927,0.003894,0.098898,289.087402,14.726814,0.988984,-71.347443,294.500458,0.000000
89.010002,64.968933,-71.347443,-0.000910,0.003894,0.098916,288.996246,14.722170,0.989158,-71.347443,294.500458,0.000000
89.360001,65.040436,-71.347443,-0.000927,0.003897,0.098985,289.314301,14.738373,0.989851,-71.347443,294.500458,0.000000
89.710007,64.976013,-71.436409,-0.000914,0.003897,0.098985,289.027740,14.723775,0.989851,-71.436409,294.500458,0.000000
90.060005,64.873611,-71.480888,-0.000910,0.003897,0.098985,288.572235,14.700571,0.989851,-71.480888,294.500458,0.000000
90.410004,64.779404,-71.525368,-0.000918,0.003897,0.098985,288.153168,14.679223,0.989851,-71.525368,294.500458,0.000000
90.760002,65.571442,-71.569847,-0.000914,0.003907,0.099237,291.676331,14.858701,0.992366,-71.569847,294.500458,0.000000
91.110001,65.538300,-71.614334,-0.000910,0.003907,0.099237,291.528931,14.851191,0.992366,-71.614334,294.500458,0.000000
91.460007,65.454514,-71.569847,-0.000897,0.003907,0.099237,291.156219,14.832205,0.992366,-71.569847,294.500458,0.000000
91.810005,65.359558,-71.569847,-0.000910,0.003907,0.099237,290.733826,14.810687,0.992366,-71.569847,294.500458,0.000000
92.160004,65.270935,-71.614334,-0.000910,0.003907,0.099245,290.339630,14.790605,0.992453,-71.614334,294.500458,0.000000
92.510002,65.186783,-71.614334,-0.000910,0.003907,0.099245,289.965302,14.771536,0.992453,-71.614334,294.500458,0.000000
92.860001,65.071716,-71.703293,-0.000888,0.003908,0.099254,289.453461,14.745461,0.992540,-71.703293,294.500458,0.000000
93.210007,65.011383,-71.703293,-0.000888,0.003908,0.099254,289.185089,14.731790,0.992540,-71.703293,294.500458,0.000000
93.560005,65.204285,-71.747772,-0.000892,0.003912,0.099375,290.043152,14.775502,0.993754,-71.747772,294.500458,0.000000
93.910004,65.213211,-71.836739,-0.000892,0.003912,0.099375,290.082855,14.777525,0.993754,-71.836739,294.500458,0.000000
94.260002,65.129425,-71.881218,-0.000892,0.003912,0.099375,289.710144,14.758538,0.993754,-71.881218,294.500458,0.000000
94.610008,65.076920,-71.792252,-0.000905,0.003913,0.099393,289.476593,14.746641,0.993927,-71.792252,294.500458,0.000000
94.960007,65.026657,-71.881218,-0.000892,0.003913,0.099393,289.253021,14.735251,0.993927,-71.881218,294.500458,0.000000
95.310005,64.963348,-71.925697,-0.000888,0.003913,0.099393,288.971405,14.720905,0.993927,-71.925697,294.500458,0.000000
95.660004,64.870636,-71.925697,-0.000905,0.003913,0.099393,288.558990,14.699896,0.993927,-71.925697,294.500458,0.000000
96.010002,64.779770,-71.970177,-0.000892,0.003913,0.099393,288.154816,14.679305,0.993927,-71.970177,294.500458,0.000000
96.360008,65.560638,-71.970177,-0.000888,0.003923,0.099653,291.628296,14.856253,0.996529,-71.970177,294.500458,0.000000
96.710007,65.582611,-72.014656,-0.000892,0.003923,0.099653,291.726013,14.861233,0.996529,-72.014656,294.500458,0.000000
97.060005,65.552826,-71.970177,-0.000897,0.003923,0.099653,291.593536,14.854483,0.996529,-71.970177,294.500458,0.000000
97.410004,65.498077,-72.103622,-0.000897,0.003923,0.099653,291.350006,14.842077,0.996529,-72.103622,294.500458,0.000000
97.760002,65.406479,-72.103622,-0.000897,0.003923,0.099653,290.942535,14.821320,0.996529,-72.103622,294.500458,0.000000
98.110008,65.346893,-72.148102,-0.000897,0.003923,0.099653,290.677490,14.807817,0.996529,-72.148102,294.500458,0.000000
98.460007,65.286942,-72.192581,-0.000888,0.003923,0.099653,290.410828,14.794232,0.996529,-72.192581,294.500458,0.000000
98.810005,65.214706,-72.148102,-0.000884,0.003923,0.099653,290.089508,14.777864,0.996529,-72.148102,294.500458,0.000000
99.160004,65.163696,-72.192581,-0.000880,0.003923,0.099653,289.862610,14.766305,0.996529,-72.192581,294.500458,0.000000
99.510002,65.073196,-72.281548,-0.000884,0.003924,0.099662,289.460022,14.745797,0.996616,-72.281548,294.500458,0.000000
99.860008,65.019577,-72.281548,-0.000880,0.003924,0.099662,289.221527,14.733647,0.996616,-72.281548,294.500458,0.000000
100.210007,64.959625,-72.326027,-0.000884,0.003924,0.099662,288.954834,14.720061,0.996616,-72.326027,294.500458,0.000000
100.560005,64.884033,-72.326027,-0.000880,0.003924,0.099662,288.618591,14.702932,0.996616,-72.326027,294.500458,0.000000
100.910004,64.814026,-72.326027,-0.000884,0.003924,0.099662,288.307190,14.687069,0.996616,-72.326027,294.500458,0.000000
101.260002,64.746262,-72.414986,-0.000875,0.003924,0.099662,288.005768,14.671712,0.996616,-72.414986,294.500458,0.000000
101.610008,64.680344,-72.459473,-0.000871,0.003924,0.099662,287.712524,14.656775,0.996616,-72.459473,294.500458,0.000000
101.960007,64.611832,-72.459473,-0.000880,0.003924,0.099662,287.407776,14.641251,0.996616,-72.459473,294.500458,0.000000
102.310005,64.546661,-72.459473,-0.000875,0.003924,0.099662,287.117889,14.626483,0.996616,-72.459473,294.500458,0.000000
102.660004,64.481506,-72.503952,-0.000871,0.003924,0.099662,286.828064,14.611718,0.996616,-72.503952,294.500458,0.000000
103.010002,66.398849,-72.592911,-0.000875,0.003912,0.099367,295.356842,15.046194,0.993667,-72.592911,294.500458,0.000000
103.360008,66.308731,-72.592911,-0.000867,0.003912,0.099367,294.955963,15.025773,0.993667,-72.592911,294.500458,0.000000
103.710007,66.227936,-72.592911,-0.000880,0.003912,0.099367,294.596558,15.007464,0.993667,-72.592911,294.500458,0.000000
104.060005,66.140793,-72.592911,-0.000867,0.003912,0.099367,294.208954,14.987719,0.993667,-72.592911,294.500458,0.000000
104.410004,66.048813,-72.726357,-0.000862,0.003912,0.099367,293.799805,14.966875,0.993667,-72.726357,294.500458,0.000000
104.760002,65.970627,-72.726357,-0.000867,0.003912,0.099367,293.451996,14.949158,0.993667,-72.726357,294.500458,0.000000
105.110008,65.893906,-72.726357,-0.000867,0.003912,0.099367,293.110718,14.931772,0.993667,-72.726357,294.500458,0.000000
105.460007,65.796356,-72.770836,-0.000862,0.003912,0.099367,292.676819,14.909667,0.993667,-72.770836,294.500458,0.000000
105.810005,65.789276,-72.815315,-0.000858,0.003912,0.099367,292.645325,14.908063,0.993667,-72.815315,294.500458,0.000000
106.160004,65.745331,-72.770836,-0.000862,0.003912,0.099367,292.449829,14.898106,0.993667,-72.770836,294.500458,0.000000
106.510002,65.627670,-72.859795,-0.000862,0.003912,0.099367,291.926453,14.871443,0.993667,-72.859795,294.500458,0.000000
106.860008,65.563614,-72.904282,-0.000858,0.003912,0.099367,291.641510,14.856928,0.993667,-72.904282,294.500458,0.000000
107.210007,65.524139,-72.948761,-0.000854,0.003912,0.099375,291.465942,14.847982,0.993754,-72.948761,294.500458,0.000000
107.560005,65.479828,-72.948761,-0.000849,0.003913,0.099384,291.268829,14.837941,0.993841,-72.948761,294.500458,0.000000
107.910004,65.369980,-73.037720,-0.000858,0.003914,0.099410,290.780182,14.813048,0.994101,-73.037720,294.500458,0.000000
108.260002,65.306686,-72.993240,-0.000849,0.003914,0.099410,290.498657,14.798706,0.994101,-72.993240,294.500458,0.000000
108.610008,65.286194,-73.037720,-0.000854,0.003917,0.099488,290.407501,14.794064,0.994881,-73.037720,294.500458,0.000000
108.960007,65.242630,-73.082199,-0.000841,0.003917,0.099488,290.213715,14.784191,0.994881,-73.082199,294.500458,0.000000
109.310005,65.174866,-73.037720,-0.000845,0.003917,0.099497,289.912292,14.768836,0.994968,-73.037720,294.500458,0.000000
109.660004,65.191986,-73.126686,-0.000845,0.003932,0.099878,289.988434,14.772716,0.998784,-73.126686,294.500458,0.000000
110.010002,65.174866,-73.126686,-0.000845,0.003936,0.099974,289.912292,14.768836,0.999738,-73.126686,294.500458,0.000000
110.360008,65.113419,-73.171165,-0.000841,0.003938,0.100026,289.638947,14.754911,1.000258,-73.171165,294.500458,0.000000
110.710007,65.101883,-73.215645,-0.000849,0.003939,0.100052,289.587646,14.752297,1.000518,-73.215645,294.500458,0.000000
111.060005,65.120865,-73.215645,-0.000849,0.003940,0.100087,289.672089,14.756599,1.000865,-73.215645,294.500458,0.000000
111.410004,65.121246,-73.304604,-0.000858,0.003940,0.100087,289.673767,14.756685,1.000865,-73.304604,294.500458,0.000000
111.760002,65.084381,-73.349091,-0.000849,0.003942,0.100139,289.509796,14.748331,1.001385,-73.349091,294.500458,0.000000
112.110008,65.254181,-73.349091,-0.000854,0.003944,0.100182,290.265106,14.786808,1.001819,-73.349091,294.500458,0.000000
112.460007,65.250824,-73.349091,-0.000845,0.003944,0.100182,290.250153,14.786048,1.001819,-73.349091,294.500458,0.000000
112.810005,65.221405,-73.349091,-0.000845,0.003944,0.100182,290.119293,14.779382,1.001819,-73.349091,294.500458,0.000000
113.160004,65.179703,-73.438049,-0.000849,0.003944,0.100182,289.933807,14.769932,1.001819,-73.438049,294.500458,0.000000
113.510002,65.149536,-73.438049,-0.000845,0.003945,0.100191,289.799622,14.763096,1.001906,-73.438049,294.500458,0.000000
113.860008,65.168152,-73.482529,-0.000854,0.003946,0.100225,289.882416,14.767315,1.002253,-73.482529,294.500458,0.000000
114.210007,65.161453,-73.482529,-0.000836,0.003946,0.100225,289.852631,14.765797,1.002253,-73.482529,294.500458,0.000000
114.560005,65.148422,-73.571495,-0.000845,0.003947,0.100260,289.794647,14.762843,1.002600,-73.571495,294.500458,0.000000
114.910004,65.232574,-73.615974,-0.000849,0.003948,0.100286,290.168976,14.781913,1.002860,-73.615974,294.500458,0.000000
115.260002,65.217316,-73.571495,-0.000849,0.003948,0.100286,290.101105,14.778456,1.002860,-73.571495,294.500458,0.000000
115.610008,65.200180,-73.660454,-0.000849,0.003948,0.100286,290.024872,14.774571,1.002860,-73.660454,294.500458,0.000000
115.960007,65.173737,-73.660454,-0.000836,0.003948,0.100286,289.907257,14.768580,1.002860,-73.660454,294.500458,0.000000
116.310005,65.121613,-73.660454,-0.000845,0.003949,0.100312,289.675415,14.756768,1.003120,-73.660454,294.500458,0.000000
116.660004,65.148788,-73.704933,-0.000854,0.003949,0.100312,289.796295,14.762927,1.003120,-73.704933,294.500458,0.000000
117.010002,65.130920,-73.749420,-0.000836,0.003950,0.100321,289.716797,14.758878,1.003207,-73.749420,294.500458,0.000000
117.360008,65.092194,-73.793900,-0.000854,0.003950,0.100321,289.544525,14.750102,1.003207,-73.793900,294.500458,0.000000
117.710007,65.064636,-73.838379,-0.000845,0.003950,0.100321,289.421967,14.743857,1.003207,-73.838379,294.500458,0.000000
118.060005,65.111923,-73.882858,-0.000858,0.003952,0.100390,289.632294,14.754573,1.003900,-73.882858,294.500458,0.000000
118.410004,65.180817,-73.838379,-0.000845,0.003952,0.100390,289.938751,14.770185,1.003900,-73.838379,294.500458,0.000000
118.760002,65.181198,-73.882858,-0.000841,0.003952,0.100390,289.940460,14.770271,1.003900,-73.882858,294.500458,0.000000
119.110008,65.155502,-73.882858,-0.000854,0.003952,0.100390,289.826141,14.764448,1.003900,-73.882858,294.500458,0.000000
119.460007,65.114166,-73.971825,-0.000845,0.003952,0.100390,289.642273,14.755081,1.003900,-73.971825,294.500458,0.000000
119.810005,65.079910,-73.971825,-0.000836,0.003952,0.100390,289.489899,14.747318,1.003900,-73.971825,294.500458,0.000000
120.160004,65.048996,-74.016304,-0.000841,0.003952,0.100390,289.352386,14.740314,1.003900,-74.016304,294.500458,0.000000
120.510002,65.026657,-74.016304,-0.000841,0.003953,0.100407,289.253021,14.735251,1.004074,-74.016304,294.500458,0.000000
120.860008,65.178207,-74.060783,-0.000845,0.003956,0.100477,289.927155,14.769593,1.004768,-74.060783,294.500458,0.000000
121.210007,65.187515,-74.060783,-0.000836,0.003956,0.100477,289.968536,14.771702,1.004768,-74.060783,294.500458,0.000000
121.560005,65.175232,-74.105263,-0.000845,0.003956,0.100477,289.913910,14.768919,1.004768,-74.105263,294.500458,0.000000
121.910004,65.152145,-74.105263,-0.000845,0.003956,0.100477,289.811218,14.763687,1.004768,-74.105263,294.500458,0.000000
122.260002,65.112671,-74.194229,-0.000845,0.003956,0.100477,289.635620,14.754742,1.004768,-74.194229,294.500458,0.000000
122.610008,65.093307,-74.194229,-0.000849,0.003956,0.100477,289.549500,14.750354,1.004768,-74.194229,294.500458,0.000000
122.960007,65.081390,-74.238708,-0.000845,0.003956,0.100485,289.496490,14.747654,1.004854,-74.238708,294.500458,0.000000
123.310005,65.044159,-74.238708,-0.000849,0.003956,0.100494,289.330872,14.739217,1.004941,-74.238708,294.500458,0.000000
123.660004,65.029633,-74.327667,-0.000841,0.003957,0.100503,289.266266,14.735926,1.005028,-74.327667,294.500458,0.000000
124.010002,65.088470,-74.283188,-0.000841,0.003958,0.100537,289.527985,14.749258,1.005375,-74.283188,294.500458,0.000000
124.360008,65.081024,-74.372147,-0.000849,0.003958,0.100537,289.494843,14.747571,1.005375,-74.372147,294.500458,0.000000
124.710007,65.058685,-74.372147,-0.000836,0.003958,0.100537,289.395477,14.742508,1.005375,-74.372147,294.500458,0.000000
125.060005,65.056442,-74.416634,-0.000841,0.003958,0.100537,289.385498,14.742001,1.005375,-74.416634,294.500458,0.000000
125.410004,65.025162,-74.461113,-0.000841,0.003958,0.100537,289.246368,14.734913,1.005375,-74.461113,294.500458,0.000000
125.760010,65.353226,-74.505592,-0.000841,0.003964,0.100694,290.705658,14.809253,1.006936,-74.505592,1681.640747,0.000000
126.110008,65.368118,-74.461113,-0.000836,0.003956,0.100477,290.771912,14.812628,1.004768,-74.461113,0.100286,0.000000
126.460007,65.296997,-74.505592,-0.000836,0.003938,0.100017,290.455536,14.796512,1.000171,-74.505592,0.099705,0.000000
126.810005,65.158844,-74.550072,-0.000841,0.003919,0.099549,289.841003,14.765205,0.995488,-74.550072,0.099124,0.000000
127.160004,65.062027,-74.550072,-0.000836,0.003898,0.099002,289.410339,14.743266,0.990025,-74.550072,0.098543,0.000000
127.510010,65.082886,-74.639038,-0.000836,0.003881,0.098586,289.503143,14.747993,0.985862,-74.639038,0.097953,0.000000
127.860008,64.991653,-74.639038,-0.000828,0.003852,0.097840,289.097321,14.727320,0.978404,-74.639038,0.097372,0.000000
128.210007,64.917175,-74.727997,-0.000836,0.003833,0.097355,288.766022,14.710442,0.973548,-74.727997,0.096791,0.000000
128.560013,64.891479,-74.772476,-0.000819,0.003810,0.096765,288.651703,14.704619,0.967650,-74.772476,0.096210,0.000000
128.910004,64.837494,-74.772476,-0.000836,0.003788,0.096227,288.411591,14.692387,0.962274,-74.772476,0.095620,0.000000
129.260010,64.784607,-74.772476,-0.000832,0.003766,0.095655,288.176331,14.680402,0.956550,-74.772476,0.095039,0.000000
129.610001,64.638641,-74.772476,-0.000828,0.003746,0.095152,287.527039,14.647326,0.951520,-74.772476,0.094458,0.000000
129.960007,64.143021,-74.816963,-0.000824,0.003719,0.094467,285.322418,14.535016,0.944669,-74.816963,0.093869,0.000000
130.310013,63.404236,-74.905922,-0.000824,0.003699,0.093964,282.036133,14.367605,0.939639,-74.905922,0.093287,0.000000
130.660004,62.512024,-74.861443,-0.000811,0.003681,0.093487,278.067383,14.165427,0.934869,-74.861443,0.092706,0.000000
131.010010,61.778824,-74.905922,-0.000811,0.003665,0.093088,274.805939,13.999282,0.930880,-74.905922,0.092125,0.000000
131.360001,60.188049,-74.950401,-0.000811,0.003638,0.092403,267.729828,13.638807,0.924029,-74.950401,0.091536,0.000000
131.710007,58.311661,-74.950401,-0.000806,0.003611,0.091726,259.383209,13.213612,0.917265,-74.950401,0.090955,0.000000
132.060013,56.487038,-74.950401,-0.000806,0.003590,0.091180,251.266891,12.800146,0.911801,-74.950401,0.090374,0.000000
132.410004,54.843384,-75.039368,-0.000806,0.003569,0.090642,243.955551,12.427689,0.906424,-75.039368,0.089793,0.000000
132.760010,52.702248,-74.994881,-0.000798,0.003549,0.090139,234.431305,11.942500,0.901394,-74.994881,0.089203,0.000000
133.110001,50.861610,-75.128326,-0.000806,0.003529,0.089628,226.243744,11.525406,0.896278,-75.128326,0.088622,0.000000
133.460007,49.181839,-75.083847,-0.000793,0.003512,0.089194,218.771744,11.144765,0.891942,-75.083847,0.088041,0.000000
133.810013,45.598869,-75.217285,-0.000789,0.003478,0.088336,202.833908,10.332851,0.883356,-75.217285,0.087451,0.000000
134.160004,43.016090,-75.172806,-0.000806,0.003456,0.087772,191.345123,9.747585,0.877719,-75.172806,0.086870,0.000000
134.510010,40.648178,-75.261772,-0.000802,0.003432,0.087182,180.812134,9.211009,0.871822,-75.261772,0.086289,0.000000
134.860001,39.132248,-75.172806,-0.000802,0.003422,0.086931,174.068939,8.867494,0.869307,-75.172806,0.085708,0.000000
135.210007,36.108955,-75.261772,-0.000806,0.003392,0.086159,160.620651,8.182406,0.861589,-75.261772,0.085118,0.000000
135.560013,33.840088,-75.306252,-0.000798,0.003369,0.085560,150.528229,7.668273,0.855605,-75.306252,0.084537,0.000000
135.910004,30.668968,-75.350731,-0.000798,0.003341,0.084858,136.422379,6.949688,0.848580,-75.350731,0.083956,0.000000
136.260010,28.507713,-75.395210,-0.000802,0.003322,0.084372,126.808640,6.459940,0.843724,-75.395210,0.083375,0.000000
136.610001,25.886215,-75.439690,-0.000806,0.003298,0.083774,115.147636,5.865900,0.837740,-75.439690,0.082785,0.000000
136.960007,23.699646,-75.395210,-0.000793,0.003276,0.083219,105.421288,5.370417,0.832190,-75.395210,0.082204,0.000000
137.310013,21.255760,-75.484177,-0.000802,0.003256,0.082699,94.550346,4.816624,0.826986,-75.484177,0.081623,0.000000
137.660004,18.194862,-75.484177,-0.000798,0.003226,0.081935,80.934792,4.123014,0.819355,-75.484177,0.081042,0.000000
138.010010,15.640388,-75.484177,-0.000798,0.003203,0.081354,69.571922,3.544163,0.813545,-75.484177,0.080453,0.000000
138.360001,13.531265,-75.528656,-0.000798,0.003183,0.080843,60.190075,3.066228,0.808428,-75.528656,0.079871,0.000000
138.710007,11.779999,-75.573135,-0.000811,0.003160,0.080270,52.400051,2.669386,0.802704,-75.573135,0.079290,0.000000
139.060013,8.828201,-75.617615,-0.000798,0.003137,0.079689,39.269802,2.000499,0.796894,-75.617615,0.078701,0.000000
139.410004,6.639771,-75.573135,-0.000793,0.003118,0.079186,29.535173,1.504593,0.791864,-75.573135,0.078120,0.000000
139.760010,3.903954,-75.706581,-0.000802,0.003089,0.078458,17.365652,0.884649,0.784579,-75.706581,0.077539,0.000000
140.110001,1.946014,-75.706581,-0.000802,0.003068,0.077938,8.656304,0.440973,0.779376,-75.706581,0.076958,0.000000
140.460007,0.246140,-75.751060,-0.000806,0.003051,0.077495,1.094883,0.055776,0.774953,-75.751060,0.076368,0.000000
140.810013,-1.552795,-75.751060,-0.000806,0.003028,0.076914,-6.907179,-0.351868,0.769142,-75.751060,0.075787,0.000000
141.160004,0.264755,-75.840019,-0.000789,0.003001,0.076229,1.177690,0.059994,0.762291,-75.840019,0.075206,0.000000
141.510010,0.202194,-75.840019,-0.000802,0.002973,0.075518,0.899405,0.045818,0.755180,-75.840019,0.074625,0.000000
141.860001,0.210388,-75.795540,-0.000824,0.002951,0.074963,0.935853,0.047675,0.749630,-75.795540,0.074035,0.000000
142.210007,0.142616,-75.884506,-0.000836,0.002933,0.074495,0.634389,0.032317,0.744947,-75.884506,0.073454,0.000000
142.560013,0.115433,-75.884506,-0.000892,0.002908,0.073870,0.513470,0.026157,0.738703,-75.884506,0.072873,0.000000
142.910004,0.113197,-75.884506,-0.000927,0.002885,0.073281,0.503527,0.025651,0.732806,-75.884506,0.072283,0.000000
143.260010,0.123627,-75.973465,-0.000957,0.002867,0.072830,0.549919,0.028014,0.728296,-75.973465,0.071702,0.000000
143.610001,0.078568,-76.062424,-0.001035,0.002834,0.071980,0.349486,0.017804,0.719797,-76.062424,0.071121,0.000000
143.960007,0.067024,-76.017944,-0.001052,0.002818,0.071581,0.298139,0.015188,0.715808,-76.017944,0.070540,0.000000
144.310013,0.073357,-76.062424,-0.001108,0.002791,0.070887,0.326307,0.016623,0.708870,-76.062424,0.069950,0.000000
144.660004,0.069633,-76.106911,-0.001138,0.002768,0.070306,0.309745,0.015779,0.703060,-76.106911,0.069369,0.000000
145.010010,0.057343,-76.106911,-0.001177,0.002745,0.069734,0.255072,0.012994,0.697336,-76.106911,0.068788,0.000000
145.360001,0.062553,-76.151390,-0.001220,0.002729,0.069317,0.278251,0.014175,0.693173,-76.151390,0.068207,0.000000
145.710007,0.040588,-76.195869,-0.001263,0.002695,0.068459,0.180546,0.009197,0.684588,-76.195869,0.067618,0.000000
146.060013,0.005211,-76.151390,-0.001302,0.002678,0.068025,0.023179,0.001181,0.680252,-76.151390,0.067037,0.000000
146.410004,0.013405,-76.240349,-0.001332,0.002654,0.067409,0.059628,0.003038,0.674094,-76.240349,0.066456,0.000000
146.760010,0.040588,-76.284828,-0.001397,0.002631,0.066837,0.180546,0.009197,0.668371,-76.284828,0.066768,0.000000
146.900009,0.050270,-76.195869,-0.001380,0.002632,0.066846,0.223612,0.011391,0.668458,-76.195869,0.066768,0.000000