File: Data/compression 19/AutoNoHeating-17-19-reverse-1-4_09112024_160111.csv
Time (sec),S:Load (lbs),S:HL1 (DIM),S:LVDT (in),S:Position (in),Ch:Position (mm),Ch:Load (N),Ch:Stress (MPa),Ch:Strain (mm/mm),Ch:HL1 (DIM),Set Point (),Cycles ()
0.210000,-0.029045,-197.273026,-0.013292,-0.008646,-0.219599,-0.129199,-0.006582,-2.195988,-197.273026,-0.219694,0.000000
0.630000,-0.060692,-197.317505,-0.013301,-0.008533,-0.216737,-0.269971,-0.013753,-2.167367,-197.317505,-0.215688,0.000000
1.050000,-0.052872,-197.450943,-0.013081,-0.008267,-0.209972,-0.235185,-0.011981,-2.099724,-197.450943,-0.208698,0.000000
1.470000,-0.039841,-197.406464,-0.012788,-0.007986,-0.202844,-0.177220,-0.009028,-2.028439,-197.406464,-0.201690,0.000000
1.890000,-0.030533,-197.539902,-0.012478,-0.007711,-0.195871,-0.135817,-0.006919,-1.958713,-197.539902,-0.194701,0.000000
2.310000,-0.037605,-197.495422,-0.012210,-0.007440,-0.188977,-0.167277,-0.008521,-1.889768,-197.495422,-0.187694,0.000000
2.730000,-0.043190,-197.539902,-0.011930,-0.007167,-0.182039,-0.192119,-0.009787,-1.820391,-197.539902,-0.180704,0.000000
3.150000,-0.035004,-197.539902,-0.011650,-0.006894,-0.175101,-0.155704,-0.007932,-1.751014,-197.539902,-0.173714,0.000000
3.570000,-0.011543,-197.628860,-0.011348,-0.006606,-0.167782,-0.051347,-0.002616,-1.677821,-197.628860,-0.166706,0.000000
3.990000,-0.024574,-197.673340,-0.011068,-0.006331,-0.160818,-0.109312,-0.005569,-1.608179,-197.673340,-0.159717,0.000000
4.410000,-0.055107,-197.762314,-0.010805,-0.006064,-0.154028,-0.245129,-0.012487,-1.540278,-197.762314,-0.152710,0.000000
4.830000,-0.024200,-197.806793,-0.010524,-0.005791,-0.147081,-0.107649,-0.005484,-1.470810,-197.806793,-0.145720,0.000000
5.250000,-0.038727,-197.806793,-0.010244,-0.005512,-0.140005,-0.172265,-0.008776,-1.400048,-197.806793,-0.138713,0.000000
5.670000,-0.020477,-197.895752,-0.009947,-0.005235,-0.132963,-0.091088,-0.004640,-1.329626,-197.895752,-0.131723,0.000000
6.090000,0.008942,-197.984711,-0.009658,-0.004955,-0.125861,0.039774,0.002026,-1.258606,-197.984711,-0.124733,0.000000
6.510000,-0.049522,-197.940231,-0.009390,-0.004679,-0.118853,-0.220287,-0.011222,-1.188533,-197.940231,-0.117726,0.000000
6.930000,-0.063301,-197.984711,-0.009123,-0.004409,-0.111984,-0.281577,-0.014344,-1.119844,-197.984711,-0.110736,0.000000
7.350000,-0.031281,-198.029190,-0.008830,-0.004129,-0.104882,-0.139143,-0.007088,-1.048825,-198.029190,-0.103729,0.000000
7.770000,0.010056,-198.118149,-0.008537,-0.003857,-0.097979,0.044729,0.002279,-0.979788,-198.118149,-0.096739,0.000000
8.190001,0.013779,-198.118149,-0.008269,-0.003584,-0.091041,0.061291,0.003122,-0.910411,-198.118149,-0.089749,0.000000
8.610001,-0.002602,-198.118149,-0.007963,-0.003296,-0.083730,-0.011573,-0.000590,-0.837302,-198.118149,-0.082742,0.000000
9.030001,-0.054733,-198.162643,-0.007696,-0.003026,-0.076870,-0.243466,-0.012403,-0.768705,-198.162643,-0.075752,0.000000
9.450001,-0.081917,-198.296082,-0.007403,-0.002755,-0.069968,-0.364384,-0.018563,-0.699676,-198.296082,-0.068745,0.000000
9.870001,-0.016754,-198.385040,-0.007123,-0.002475,-0.062857,-0.074526,-0.003797,-0.628565,-198.385040,-0.061755,0.000000
10.290001,0.015266,-198.385040,-0.006834,-0.002205,-0.055997,0.067908,0.003459,-0.559968,-198.385040,-0.054748,0.000000
10.710000,-0.009682,-198.340561,-0.006562,-0.001932,-0.049076,-0.043066,-0.002194,-0.490765,-198.340561,-0.047758,0.000000
11.130000,-0.020851,-198.473999,-0.006269,-0.001646,-0.041818,-0.092750,-0.004725,-0.418178,-198.473999,-0.040768,0.000000
11.550000,-0.076706,-198.473999,-0.005980,-0.001376,-0.034941,-0.341205,-0.017382,-0.349406,-198.473999,-0.033761,0.000000
11.970000,-0.011169,-198.607452,-0.005696,-0.001099,-0.027924,-0.049684,-0.002531,-0.279242,-198.607452,-0.026771,0.000000
12.390000,-0.007072,-198.607452,-0.005415,-0.000821,-0.020848,-0.031460,-0.001603,-0.208480,-198.607452,-0.019764,0.000000
12.810000,0.005585,-198.651932,-0.005148,-0.000554,-0.014066,0.024842,0.001266,-0.140662,-198.651932,-0.012774,0.000000
13.230000,-0.025322,-198.607452,-0.004868,-0.000278,-0.007059,-0.112638,-0.005738,-0.070588,-198.607452,-0.005784,0.000000
13.650001,0.047668,-198.696411,-0.004566,0.000002,0.000043,0.212040,0.010802,0.000431,-198.696411,0.001223,0.000000
14.070001,0.118042,-198.740891,-0.004531,-0.000010,-0.000260,0.525077,0.026749,-0.002596,-198.740891,-0.000026,0.000000
14.490001,0.165337,-198.740891,-0.004523,-0.000010,-0.000260,0.735454,0.037466,-0.002596,-198.740891,0.000391,0.000000
14.910001,0.099052,-198.829849,-0.004536,-0.000010,-0.000260,0.440607,0.022446,-0.002596,-198.829849,0.001084,0.000000
15.330001,0.349289,-198.963287,-0.004501,0.000030,0.000755,1.553715,0.079150,0.007547,-198.963287,0.001786,0.000000
15.750001,0.592819,-198.963287,-0.004484,0.000054,0.001379,2.636992,0.134335,0.013792,-198.963287,0.002489,0.000000
16.170000,0.841934,-198.963287,-0.004449,0.000079,0.001995,3.745110,0.190785,0.019946,-198.963287,0.003183,0.000000
16.590000,1.327141,-198.963287,-0.004415,0.000116,0.002940,5.903417,0.300734,0.029401,-198.963287,0.003886,0.000000
17.010000,1.829842,-199.007782,-0.004389,0.000145,0.003686,8.139542,0.414648,0.036857,-199.007782,0.004588,0.000000
17.430000,2.118431,-199.096741,-0.004381,0.000165,0.004180,9.423252,0.480043,0.041800,-199.096741,0.005291,0.000000
17.850000,2.834877,-199.141220,-0.004337,0.000198,0.005038,12.610163,0.642392,0.050385,-199.141220,0.005984,0.000000
18.270000,3.346138,-199.185699,-0.004316,0.000224,0.005680,14.884365,0.758246,0.056804,-199.185699,0.006686,0.000000
18.690001,3.940071,-199.185699,-0.004307,0.000253,0.006426,17.526312,0.892833,0.064260,-199.185699,0.007389,0.000000
19.110001,4.615929,-199.274658,-0.004290,0.000282,0.007163,20.532677,1.045984,0.071633,-199.274658,0.008091,0.000000
19.530001,5.094055,-199.319138,-0.004260,0.000305,0.007745,22.659489,1.154329,0.077447,-199.319138,0.008785,0.000000
19.950001,5.921844,-199.363617,-0.004234,0.000339,0.008603,26.341681,1.341909,0.086031,-199.363617,0.009488,0.000000
20.370001,6.488968,-199.408096,-0.004208,0.000365,0.009271,28.864370,1.470421,0.092707,-199.408096,0.010190,0.000000
20.790001,6.906021,-199.408096,-0.004182,0.000392,0.009965,30.719517,1.564927,0.099649,-199.408096,0.010884,0.000000
21.210001,7.614273,-199.497070,-0.004156,0.000417,0.010598,33.869980,1.725419,0.105977,-199.497070,0.011586,0.000000
21.630001,8.312469,-199.586029,-0.004143,0.000445,0.011300,36.975712,1.883633,0.113002,-199.586029,0.012289,0.000000
22.050001,9.034874,-199.586029,-0.004105,0.000477,0.012106,40.189125,2.047332,0.121064,-199.586029,0.012991,0.000000
22.470001,9.482841,-199.541550,-0.004083,0.000505,0.012818,42.181786,2.148843,0.128179,-199.541550,0.013685,0.000000
22.890001,10.093903,-199.630508,-0.004066,0.000533,0.013538,44.899921,2.287311,0.135378,-199.630508,0.014387,0.000000
23.310001,10.344139,-199.719467,-0.004044,0.000553,0.014058,46.013027,2.344015,0.140579,-199.719467,0.015090,0.000000
23.730001,11.321243,-199.719467,-0.004010,0.000587,0.014899,50.359406,2.565430,0.148989,-199.719467,0.015784,0.000000
24.150002,11.678345,-199.719467,-0.003988,0.000612,0.015541,51.947872,2.646351,0.155408,-199.719467,0.016486,0.000000
24.570002,12.072693,-199.852921,-0.003958,0.000636,0.016165,53.702019,2.735711,0.161653,-199.852921,0.017189,0.000000
24.990002,12.728439,-199.852921,-0.003932,0.000665,0.016903,56.618927,2.884305,0.169026,-199.852921,0.017891,0.000000
25.410002,13.095596,-199.986359,-0.003919,0.000688,0.017483,58.252121,2.967505,0.174832,-199.986359,0.018585,0.000000
25.830002,13.974396,-199.986359,-0.003880,0.000725,0.018411,62.161217,3.166643,0.184112,-199.986359,0.019287,0.000000
26.250002,14.186646,-199.986359,-0.003854,0.000749,0.019036,63.105350,3.214740,0.190358,-199.986359,0.019990,0.000000
26.670002,14.681160,-199.941879,-0.003837,0.000776,0.019721,65.305061,3.326798,0.197208,-199.941879,0.020692,0.000000
27.090002,14.980171,-200.075317,-0.003811,0.000801,0.020345,66.635132,3.394555,0.203453,-200.075317,0.021386,0.000000
27.510002,15.294083,-200.164276,-0.003794,0.000822,0.020874,68.031479,3.465689,0.208745,-200.164276,0.022089,0.000000
27.930002,16.401146,-200.164276,-0.003742,0.000862,0.021898,72.955940,3.716553,0.218979,-200.164276,0.022791,0.000000
28.350002,16.316620,-200.208755,-0.003717,0.000885,0.022470,72.579948,3.697399,0.224702,-200.208755,0.023485,0.000000
28.770000,17.023384,-200.297729,-0.003699,0.000913,0.023190,75.723793,3.857554,0.231901,-200.297729,0.024187,0.000000
29.190001,17.244202,-200.297729,-0.003673,0.000937,0.023805,76.706039,3.907592,0.238055,-200.297729,0.024889,0.000000
29.610001,18.122253,-200.431168,-0.003635,0.000973,0.024716,80.611809,4.106561,0.247161,-200.431168,0.025592,0.000000
30.030001,18.124863,-200.386688,-0.003613,0.000996,0.025297,80.623413,4.107152,0.252975,-200.386688,0.026286,0.000000
30.450001,18.363548,-200.386688,-0.003591,0.001022,0.025965,81.685143,4.161240,0.259651,-200.386688,0.026989,0.000000
30.870001,18.803696,-200.431168,-0.003561,0.001049,0.026633,83.643013,4.260978,0.266328,-200.431168,0.027691,0.000000
31.290001,19.181282,-200.520126,-0.003527,0.001076,0.027318,85.322601,4.346540,0.273179,-200.520126,0.028384,0.000000
31.710001,19.874634,-200.609085,-0.003501,0.001110,0.028202,88.406784,4.503656,0.282020,-200.609085,0.029087,0.000000
32.130001,19.911873,-200.653564,-0.003458,0.001134,0.028809,88.572433,4.512095,0.288091,-200.653564,0.029789,0.000000
32.550003,20.189293,-200.653564,-0.003445,0.001159,0.029451,89.806458,4.574959,0.294510,-200.653564,0.030492,0.000000
32.970001,20.615662,-200.742538,-0.003410,0.001185,0.030110,91.703041,4.671576,0.301104,-200.742538,0.031185,0.000000
33.390003,21.138840,-200.787018,-0.003380,0.001219,0.030960,94.030258,4.790130,0.309604,-200.787018,0.031888,0.000000
33.810001,21.379021,-200.831497,-0.003350,0.001246,0.031654,95.098633,4.844555,0.316538,-200.831497,0.032590,0.000000
34.230003,21.341782,-200.787018,-0.003320,0.001271,0.032278,94.932983,4.836117,0.322783,-200.787018,0.033293,0.000000
34.650002,21.887680,-200.875977,-0.003285,0.001300,0.033024,97.361267,4.959819,0.330240,-200.875977,0.033987,0.000000
35.070004,22.100677,-200.920456,-0.003264,0.001326,0.033683,98.308723,5.008085,0.336833,-200.920456,0.034689,0.000000
35.490002,22.624611,-201.009415,-0.003234,0.001356,0.034446,100.639297,5.126810,0.344463,-201.009415,0.035392,0.000000
35.910000,22.765366,-201.053894,-0.003199,0.001382,0.035097,101.265404,5.158706,0.350966,-201.053894,0.036085,0.000000
36.330002,23.142952,-201.009415,-0.003152,0.001411,0.035843,102.944992,5.244268,0.358430,-201.009415,0.036788,0.000000
36.750000,23.238647,-201.053894,-0.003122,0.001435,0.036441,103.370667,5.265953,0.364410,-201.053894,0.037490,0.000000
37.170002,23.320572,-201.142868,-0.003113,0.001457,0.037005,103.735085,5.284517,0.370049,-201.142868,0.038193,0.000000
37.590000,24.359489,-201.231827,-0.003065,0.001495,0.037976,108.356422,5.519939,0.379761,-201.231827,0.038887,0.000000
38.010002,24.388535,-201.276306,-0.003035,0.001521,0.038626,108.485619,5.526521,0.386264,-201.276306,0.039589,0.000000
38.430000,24.557220,-201.231827,-0.003009,0.001549,0.039338,109.235970,5.564746,0.393379,-201.231827,0.040292,0.000000
38.850002,24.633560,-201.320786,-0.002975,0.001572,0.039928,109.575546,5.582044,0.399276,-201.320786,0.040985,0.000000
39.270000,25.314629,-201.409744,-0.002940,0.001604,0.040742,112.605095,5.736377,0.407421,-201.409744,0.041688,0.000000
39.690002,25.654228,-201.454224,-0.002893,0.001633,0.041471,114.115707,5.813331,0.414711,-201.454224,0.042390,0.000000
40.110001,25.656464,-201.454224,-0.002880,0.001658,0.042104,114.125648,5.813838,0.421039,-201.454224,0.043093,0.000000
40.530003,26.159538,-201.498703,-0.002846,0.001687,0.042841,116.363441,5.927836,0.428412,-201.498703,0.043787,0.000000
40.950001,26.103683,-201.454224,-0.002811,0.001709,0.043405,116.114983,5.915179,0.434052,-201.454224,0.044489,0.000000
41.370003,26.817146,-201.543182,-0.002777,0.001741,0.044220,119.288628,6.076852,0.442197,-201.543182,0.045192,0.000000
41.790001,27.008553,-201.632156,-0.002746,0.001769,0.044940,120.140045,6.120225,0.449396,-201.632156,0.045894,0.000000
42.210003,27.477364,-201.632156,-0.002716,0.001797,0.045651,122.225418,6.226460,0.456511,-201.632156,0.046588,0.000000
42.630001,27.150421,-201.676636,-0.002686,0.001817,0.046154,120.771103,6.152373,0.461538,-201.676636,0.047290,0.000000
43.050003,28.236633,-201.765594,-0.002669,0.001854,0.047091,125.602821,6.398513,0.470909,-201.765594,0.047992,0.000000
43.470001,28.398613,-201.854553,-0.002613,0.001881,0.047776,126.323341,6.435218,0.477760,-201.854553,0.048687,0.000000
43.890003,28.682365,-201.854553,-0.002574,0.001907,0.048444,127.585533,6.499517,0.484436,-201.854553,0.049388,0.000000
44.310001,29.049149,-201.810074,-0.002548,0.001937,0.049189,129.217072,6.582631,0.491893,-201.810074,0.050091,0.000000
44.730003,28.721832,-201.899033,-0.002522,0.001956,0.049692,127.761093,6.508460,0.496919,-201.899033,0.050793,0.000000
45.150002,29.856079,-201.943512,-0.002501,0.001992,0.050594,132.806473,6.765484,0.505942,-201.943512,0.051487,0.000000
45.570004,30.050835,-201.987991,-0.002453,0.002019,0.051279,133.672791,6.809617,0.512793,-201.987991,0.052190,0.000000
45.990002,30.246696,-202.121445,-0.002419,0.002046,0.051956,134.544022,6.854000,0.519560,-202.121445,0.052892,0.000000
46.410004,30.153976,-202.076965,-0.002410,0.002067,0.052511,134.131592,6.832989,0.525109,-202.076965,0.053595,0.000000
46.830002,30.334206,-202.121445,-0.002363,0.002094,0.053196,134.933289,6.873829,0.531959,-202.121445,0.054288,0.000000
47.250004,31.498985,-202.165924,-0.002333,0.002128,0.054054,140.114487,7.137772,0.540544,-202.165924,0.054991,0.000000
47.670002,31.551491,-202.254883,-0.002298,0.002155,0.054731,140.348038,7.149670,0.547311,-202.254883,0.055693,0.000000
48.090004,32.104469,-202.299362,-0.002246,0.002182,0.055424,142.807816,7.274977,0.554245,-202.299362,0.056387,0.000000
48.510002,31.684799,-202.254883,-0.002233,0.002202,0.055936,140.941025,7.179878,0.559362,-202.254883,0.057090,0.000000
48.930004,31.876945,-202.388321,-0.002212,0.002236,0.056795,141.795731,7.223419,0.567946,-202.388321,0.057792,0.000000
49.350002,33.339256,-202.432816,-0.002169,0.002266,0.057558,148.300415,7.554783,0.575577,-202.432816,0.058495,0.000000
49.770000,33.033905,-202.477295,-0.002126,0.002287,0.058087,146.942154,7.485590,0.580868,-202.477295,0.059188,0.000000
50.190002,34.063889,-202.521774,-0.002100,0.002320,0.058919,151.523743,7.718987,0.589195,-202.521774,0.059891,0.000000
50.610001,33.945847,-202.521774,-0.002087,0.002342,0.059483,150.998672,7.692239,0.594834,-202.521774,0.060593,0.000000
51.030003,35.142654,-202.566254,-0.002048,0.002377,0.060368,156.322327,7.963439,0.603676,-202.566254,0.061287,0.000000
51.450001,34.935616,-202.655212,-0.002001,0.002400,0.060966,155.401382,7.916523,0.609663,-202.655212,0.061990,0.000000
51.870003,35.599556,-202.699692,-0.001975,0.002430,0.061720,158.354736,8.066975,0.617203,-202.699692,0.062692,0.000000
52.290001,35.738075,-202.655212,-0.001936,0.002455,0.062345,158.970901,8.098364,0.623448,-202.655212,0.063395,0.000000
52.710003,35.975647,-202.699692,-0.001910,0.002484,0.063082,160.027664,8.152198,0.630821,-202.699692,0.064088,0.000000
53.130001,36.683533,-202.788651,-0.001871,0.002512,0.063810,163.176498,8.312608,0.638103,-202.788651,0.064791,0.000000
53.550003,36.693214,-202.877625,-0.001845,0.002538,0.064470,163.219574,8.314801,0.644696,-202.877625,0.065493,0.000000
53.970001,36.682785,-202.922104,-0.001798,0.002560,0.065024,163.173172,8.312438,0.650245,-202.922104,0.066196,0.000000
54.390003,37.471100,-202.922104,-0.001772,0.002592,0.065831,166.679779,8.491073,0.658314,-202.922104,0.066889,0.000000
54.810001,38.735672,-202.922104,-0.001746,0.002628,0.066742,172.304871,8.777628,0.667421,-202.922104,0.067591,0.000000
55.230003,38.667900,-203.011063,-0.001699,0.002652,0.067367,172.003403,8.762271,0.673666,-203.011063,0.068294,0.000000
55.650002,38.492889,-203.055542,-0.001664,0.002675,0.067956,171.224930,8.722613,0.679563,-203.055542,0.068988,0.000000
56.070004,38.873077,-203.055542,-0.001634,0.002701,0.068597,172.916092,8.808765,0.685974,-203.055542,0.069691,0.000000
56.490002,39.297211,-203.100021,-0.001600,0.002727,0.069266,174.802719,8.904875,0.692658,-203.100021,0.070393,0.000000
56.910004,40.164467,-203.188980,-0.001569,0.002761,0.070124,178.660477,9.101398,0.701243,-203.188980,0.071095,0.000000
57.330002,40.452682,-203.233459,-0.001544,0.002786,0.070757,179.942520,9.166709,0.707571,-203.233459,0.071789,0.000000
57.750004,40.797127,-203.277939,-0.001509,0.002814,0.071468,181.474686,9.244761,0.714679,-203.277939,0.072491,0.000000
58.170002,41.149391,-203.233459,-0.001457,0.002837,0.072058,183.041641,9.324586,0.720583,-203.233459,0.073194,0.000000
58.590004,41.596237,-203.277939,-0.001431,0.002867,0.072830,185.029297,9.425842,0.728297,-203.277939,0.073888,0.000000
59.010002,42.768845,-203.366913,-0.001418,0.002898,0.073602,190.245316,9.691558,0.736018,-203.366913,0.074590,0.000000
59.430004,42.907364,-203.455872,-0.001380,0.002923,0.074252,190.861481,9.722948,0.742521,-203.455872,0.075293,0.000000
59.850002,43.542259,-203.455872,-0.001341,0.002951,0.074945,193.685638,9.866817,0.749455,-203.455872,0.075995,0.000000
60.270004,43.839043,-203.500351,-0.001311,0.002975,0.075562,195.005798,9.934069,0.755616,-203.500351,0.076689,0.000000
60.690002,44.810188,-203.500351,-0.001281,0.003006,0.076342,199.325668,10.154134,0.763421,-203.500351,0.077391,0.000000
61.110004,45.602592,-203.544830,-0.001272,0.003036,0.077123,202.850464,10.333695,0.771225,-203.544830,0.078094,0.000000
61.530003,46.103806,-203.633789,-0.001233,0.003064,0.077833,205.079971,10.447272,0.778333,-203.633789,0.078796,0.000000
61.950005,46.810570,-203.722763,-0.001207,0.003090,0.078475,208.223816,10.607427,0.784753,-203.722763,0.079490,0.000000
62.370003,47.262634,-203.722763,-0.001168,0.003117,0.079160,210.234695,10.709866,0.791603,-203.722763,0.080193,0.000000
62.790005,48.430389,-203.767242,-0.001151,0.003147,0.079923,215.429138,10.974483,0.799234,-203.767242,0.080895,0.000000
63.210003,49.292435,-203.811722,-0.001130,0.003174,0.080618,219.263702,11.169826,0.806175,-203.811722,0.081589,0.000000
63.630005,49.693481,-203.856201,-0.001108,0.003198,0.081225,221.047638,11.260704,0.812246,-203.856201,0.082291,0.000000
64.050003,50.346992,-203.856201,-0.001065,0.003222,0.081849,223.954605,11.408792,0.818491,-203.856201,0.082994,0.000000
64.470001,52.119110,-203.856201,-0.001035,0.003257,0.082725,231.837387,11.810359,0.827249,-203.856201,0.083696,0.000000
64.889999,53.019135,-203.945160,-0.001018,0.003284,0.083418,235.840897,12.014308,0.834183,-203.945160,0.084390,0.000000
65.310005,54.170517,-204.078598,-0.001000,0.003314,0.084173,240.962494,12.275214,0.841730,-204.078598,0.085092,0.000000
65.730003,55.078728,-204.123077,-0.000987,0.003339,0.084815,245.002411,12.481018,0.848150,-204.123077,0.085794,0.000000
66.150002,55.679741,-204.123077,-0.000949,0.003360,0.085352,247.675858,12.617209,0.853524,-204.123077,0.086489,0.000000
66.570000,57.469360,-204.078598,-0.000936,0.003393,0.086185,255.636490,13.022743,0.861851,-204.078598,0.087191,0.000000
66.990005,58.618874,-204.167572,-0.000918,0.003423,0.086940,260.749786,13.283226,0.869398,-204.167572,0.087894,0.000000
67.410004,59.827225,-204.256531,-0.000892,0.003450,0.087633,266.124786,13.557043,0.876332,-204.256531,0.088596,0.000000
67.830002,60.577179,-204.256531,-0.000875,0.003471,0.088162,269.460754,13.726985,0.881623,-204.256531,0.089289,0.000000
68.250000,62.436440,-204.256531,-0.000854,0.003507,0.089073,277.731140,14.148299,0.890730,-204.256531,0.089992,0.000000
68.670006,63.844749,-204.345490,-0.000832,0.003532,0.089715,283.995636,14.467427,0.897149,-204.345490,0.090694,0.000000
69.090004,65.062401,-204.389969,-0.000828,0.003559,0.090408,289.412018,14.743351,0.904083,-204.389969,0.091397,0.000000
69.510002,65.734917,-204.434448,-0.000798,0.003571,0.090694,292.403503,14.895744,0.906944,-204.434448,0.015923,0.000000
69.930000,66.067818,-204.478928,-0.000798,0.003578,0.090885,293.884338,14.971182,0.908852,-204.478928,294.500488,0.000000
70.350006,65.579628,-204.478928,-0.000776,0.003598,0.091397,291.712769,14.860556,0.913969,-204.478928,294.500488,0.000000
70.770004,65.807899,-204.523407,-0.000755,0.003612,0.091753,292.728149,14.912283,0.917527,-204.523407,294.500488,0.000000
71.190002,64.867653,-204.656860,-0.000746,0.003612,0.091753,288.545746,14.699220,0.917527,-204.656860,294.500488,0.000000
71.610001,66.283791,-204.656860,-0.000737,0.003562,0.090469,294.845032,15.020122,0.904688,-204.656860,294.500488,0.000000
72.030006,65.329765,-204.701340,-0.000707,0.003595,0.091311,290.601318,14.803937,0.913106,-204.701340,294.500488,0.000000
72.450005,65.861885,-204.701340,-0.000716,0.003637,0.092368,292.968292,14.924516,0.923681,-204.701340,294.500488,0.000000
72.870003,65.003197,-204.790298,-0.000716,0.003637,0.092377,289.148651,14.729935,0.923772,-204.790298,294.500488,0.000000
73.290001,66.391777,-204.834778,-0.000698,0.003604,0.091544,295.325378,15.044592,0.915445,-204.834778,294.500488,0.000000
73.710007,65.602715,-204.879257,-0.000690,0.003605,0.091570,291.815460,14.865788,0.915702,-204.879257,294.500488,0.000000
74.130005,65.340569,-204.879257,-0.000703,0.003659,0.092941,290.649353,14.806384,0.929411,-204.879257,294.500488,0.000000
74.550003,65.238167,-204.923737,-0.000690,0.003665,0.093097,290.193848,14.783179,0.930971,-204.923737,294.500488,0.000000
74.970001,65.126457,-204.968216,-0.000694,0.003671,0.093236,289.696960,14.757866,0.932356,-204.968216,294.500488,0.000000
75.390007,65.171135,-205.146149,-0.000673,0.003677,0.093383,289.895691,14.767991,0.933832,-205.146149,294.500488,0.000000
75.810005,65.028526,-205.101669,-0.000668,0.003680,0.093469,289.261322,14.735675,0.934695,-205.101669,294.500488,0.000000
76.230003,65.070229,-205.101669,-0.000655,0.003685,0.093609,289.446838,14.745125,0.936088,-205.101669,294.500488,0.000000
76.650002,64.911598,-205.101669,-0.000660,0.003687,0.093644,288.741211,14.709179,0.936436,-205.101669,294.500488,0.000000
77.070007,65.231468,-205.235107,-0.000660,0.003694,0.093817,290.164062,14.781662,0.938169,-205.235107,294.500488,0.000000
77.490005,65.020699,-205.235107,-0.000647,0.003696,0.093868,289.226501,14.733901,0.938684,-205.235107,294.500488,0.000000
77.910004,65.234077,-205.235107,-0.000647,0.003701,0.094008,290.175659,14.782253,0.940077,-205.235107,294.500488,0.000000
78.330002,65.181190,-205.324066,-0.000642,0.003704,0.094077,289.940430,14.770268,0.940766,-205.324066,294.500488,0.000000
78.750000,65.270195,-205.368546,-0.000655,0.003708,0.094181,290.336334,14.790438,0.941811,-205.368546,294.500488,0.000000
79.170006,65.264229,-205.457520,-0.000647,0.003711,0.094267,290.309784,14.789085,0.942674,-205.457520,294.500488,0.000000
79.590004,65.249718,-205.457520,-0.000655,0.003714,0.094337,290.245239,14.785798,0.943370,-205.457520,294.500488,0.000000
80.010002,65.301842,-205.501999,-0.000638,0.003718,0.094432,290.477112,14.797609,0.944324,-205.501999,294.500488,0.000000
80.430000,65.192741,-205.546478,-0.000634,0.003718,0.094441,289.991791,14.772886,0.944407,-205.546478,294.500488,0.000000
80.850006,65.081764,-205.546478,-0.000642,0.003720,0.094476,289.498138,14.747739,0.944755,-205.546478,294.500488,0.000000
81.270004,65.207268,-205.635437,-0.000621,0.003724,0.094580,290.056427,14.776178,0.945800,-205.635437,294.500488,0.000000
81.690002,65.041176,-205.724396,-0.000638,0.003725,0.094606,289.317596,14.738542,0.946057,-205.724396,294.500488,0.000000
82.110001,65.015862,-205.679916,-0.000625,0.003729,0.094710,289.204987,14.732804,0.947102,-205.679916,294.500488,0.000000
82.530006,65.313759,-205.724396,-0.000629,0.003731,0.094762,290.530121,14.800309,0.947617,-205.724396,294.500488,0.000000
82.950005,65.139488,-205.857849,-0.000629,0.003731,0.094762,289.754913,14.760818,0.947617,-205.857849,294.500488,0.000000
83.370003,65.119759,-205.857849,-0.000625,0.003734,0.094840,289.667145,14.756349,0.948396,-205.857849,294.500488,0.000000
83.790001,65.188271,-205.902328,-0.000621,0.003736,0.094884,289.971924,14.771873,0.948835,-205.902328,294.500488,0.000000
84.210007,65.057564,-205.902328,-0.000625,0.003736,0.094901,289.390503,14.742254,0.949009,-205.902328,294.500488,0.000000
84.630005,65.257530,-205.946808,-0.000617,0.003740,0.094996,290.279999,14.787567,0.949963,-205.946808,294.500488,0.000000
85.050003,65.140236,-206.035767,-0.000608,0.003740,0.094996,289.758240,14.760988,0.949963,-206.035767,294.500488,0.000000
85.470001,65.076561,-206.080246,-0.000617,0.003742,0.095039,289.475006,14.746559,0.950395,-206.080246,294.500488,0.000000
85.890007,64.996132,-206.124725,-0.000604,0.003742,0.095048,289.117249,14.728334,0.950478,-206.124725,294.500488,0.000000
86.310005,64.919044,-206.080246,-0.000599,0.003743,0.095074,288.774323,14.710866,0.950743,-206.080246,294.500488,0.000000
86.730003,64.785728,-206.169205,-0.000599,0.003743,0.095074,288.181305,14.680655,0.950743,-206.169205,294.500488,0.000000
87.150002,64.652046,-206.258163,-0.000604,0.003743,0.095074,287.586670,14.650363,0.950743,-206.258163,294.500488,0.000000
87.570007,66.513908,-206.258163,-0.000582,0.003713,0.094311,295.868652,15.072268,0.943113,-206.258163,294.500488,0.000000
87.990005,66.300545,-206.302658,-0.000595,0.003713,0.094320,294.919556,15.023918,0.943196,-206.302658,294.500488,0.000000
88.410004,66.104301,-206.347137,-0.000586,0.003713,0.094320,294.046631,14.979448,0.943196,-206.347137,294.500488,0.000000
88.830002,65.900246,-206.436096,-0.000586,0.003713,0.094320,293.138947,14.933208,0.943196,-206.436096,294.500488,0.000000
89.250008,65.825020,-206.436096,-0.000582,0.003713,0.094320,292.804321,14.916163,0.943196,-206.436096,294.500488,0.000000
89.670006,65.616493,-206.436096,-0.000595,0.003714,0.094337,291.876740,14.868910,0.943370,-206.436096,294.500488,0.000000
90.090004,65.517082,-206.525055,-0.000591,0.003725,0.094615,291.434540,14.846382,0.946148,-206.525055,294.500488,0.000000
90.510002,65.398659,-206.569534,-0.000586,0.003727,0.094675,290.907776,14.819548,0.946754,-206.569534,294.500488,0.000000
90.930008,65.303337,-206.614014,-0.000591,0.003738,0.094944,290.483765,14.797948,0.949441,-206.614014,294.500488,0.000000
91.350006,65.200935,-206.658493,-0.000595,0.003742,0.095048,290.028259,14.774743,0.950478,-206.658493,294.500488,0.000000
91.770004,65.086235,-206.702972,-0.000586,0.003743,0.095065,289.518036,14.748752,0.950652,-206.702972,294.500488,0.000000
92.190002,65.597130,-206.747467,-0.000586,0.003763,0.095569,291.790619,14.864522,0.955686,-206.747467,294.500488,0.000000
92.610001,65.529732,-206.747467,-0.000586,0.003763,0.095569,291.490814,14.849250,0.955686,-206.747467,294.500488,0.000000
93.030006,65.434410,-206.836426,-0.000595,0.003763,0.095569,291.066803,14.827649,0.955686,-206.836426,294.500488,0.000000
93.450005,65.318977,-206.969864,-0.000582,0.003763,0.095569,290.553314,14.801492,0.955686,-206.969864,294.500488,0.000000
93.870003,65.234077,-206.969864,-0.000569,0.003763,0.095569,290.175659,14.782253,0.955686,-206.969864,294.500488,0.000000
94.290001,65.143578,-206.969864,-0.000573,0.003763,0.095569,289.773102,14.761745,0.955686,-206.969864,294.500488,0.000000
94.710007,65.030006,-207.014343,-0.000599,0.003763,0.095569,289.267914,14.736011,0.955686,-207.014343,294.500488,0.000000
95.130005,64.952934,-207.014343,-0.000591,0.003763,0.095569,288.925079,14.718545,0.955686,-207.014343,294.500488,0.000000
95.550003,64.849403,-207.103302,-0.000569,0.003763,0.095569,288.464539,14.695085,0.955686,-207.103302,294.500488,0.000000
95.970001,64.758186,-207.058823,-0.000569,0.003763,0.095577,288.058807,14.674415,0.955769,-207.058823,294.500488,0.000000
96.390007,64.684822,-207.147797,-0.000569,0.003763,0.095577,287.732452,14.657790,0.955769,-207.147797,294.500488,0.000000
96.810005,64.582054,-207.192276,-0.000582,0.003763,0.095577,287.275330,14.634502,0.955769,-207.192276,294.500488,0.000000
97.230003,64.485237,-207.325714,-0.000573,0.003763,0.095577,286.844666,14.612563,0.955769,-207.325714,294.500488,0.000000
97.650002,66.777931,-207.325714,-0.000569,0.003673,0.093288,297.043060,15.132095,0.932878,-207.325714,294.500488,0.000000
98.070007,66.673286,-207.281235,-0.000556,0.003673,0.093288,296.577576,15.108383,0.932878,-207.281235,294.500488,0.000000
98.490005,66.582436,-207.370193,-0.000560,0.003673,0.093288,296.173462,15.087796,0.932878,-207.370193,294.500488,0.000000
98.910004,66.410027,-207.414673,-0.000556,0.003673,0.093296,295.406555,15.048727,0.932961,-207.414673,294.500488,0.000000
99.330002,66.345970,-207.503632,-0.000573,0.003673,0.093296,295.121613,15.034211,0.932961,-207.503632,294.500488,0.000000
99.750008,66.268150,-207.592606,-0.000560,0.003673,0.093296,294.775452,15.016578,0.932961,-207.592606,294.500488,0.000000
100.170006,66.171333,-207.592606,-0.000560,0.003673,0.093296,294.344788,14.994638,0.932961,-207.592606,294.500488,0.000000
100.590004,66.080849,-207.548111,-0.000565,0.003673,0.093296,293.942291,14.974134,0.932961,-207.548111,294.500488,0.000000
101.010002,65.995201,-207.637085,-0.000560,0.003673,0.093296,293.561310,14.954726,0.932961,-207.637085,294.500488,0.000000
101.430008,65.912910,-207.726044,-0.000573,0.003676,0.093366,293.195282,14.936079,0.933658,-207.726044,294.500488,0.000000
101.850006,65.850349,-207.726044,-0.000556,0.003678,0.093409,292.916992,14.921903,0.934089,-207.726044,294.500488,0.000000
102.270004,65.765450,-207.726044,-0.000556,0.003679,0.093444,292.539337,14.902664,0.934438,-207.726044,294.500488,0.000000
102.690002,65.658211,-207.859482,-0.000543,0.003682,0.093522,292.062317,14.878363,0.935217,-207.859482,294.500488,0.000000
103.110008,65.582619,-207.903961,-0.000578,0.003711,0.094250,291.726044,14.861234,0.942499,-207.903961,294.500488,0.000000
103.530006,65.547234,-207.992920,-0.000560,0.003742,0.095039,291.568665,14.853215,0.950395,-207.992920,294.500488,0.000000
103.950005,65.469414,-207.903961,-0.000556,0.003742,0.095057,291.222504,14.835581,0.950569,-207.903961,294.500488,0.000000
104.370003,65.381538,-207.903961,-0.000556,0.003743,0.095074,290.831604,14.815668,0.950743,-207.903961,294.500488,0.000000
104.790009,65.443718,-207.992920,-0.000565,0.003767,0.095672,291.108185,14.829759,0.956723,-207.992920,294.500488,0.000000
105.210007,65.362907,-208.081894,-0.000569,0.003771,0.095777,290.748718,14.811446,0.957768,-208.081894,294.500488,0.000000
105.630005,65.309669,-208.081894,-0.000548,0.003771,0.095777,290.511932,14.799383,0.957768,-208.081894,294.500488,0.000000
106.050003,65.321205,-208.081894,-0.000560,0.003778,0.095968,290.563232,14.801996,0.959675,-208.081894,294.500488,0.000000
106.470009,65.260139,-208.170853,-0.000560,0.003781,0.096028,290.291595,14.788159,0.960281,-208.170853,294.500488,0.000000
106.890007,65.281731,-208.170853,-0.000556,0.003783,0.096080,290.387634,14.793052,0.960803,-208.170853,294.500488,0.000000
107.310005,65.262749,-208.304291,-0.000560,0.003784,0.096115,290.303192,14.788750,0.961151,-208.304291,294.500488,0.000000
107.730003,65.232582,-208.304291,-0.000552,0.003784,0.096115,290.169006,14.781914,0.961151,-208.304291,294.500488,0.000000
108.150002,65.179329,-208.259811,-0.000552,0.003784,0.096123,289.932129,14.769847,0.961235,-208.259811,294.500488,0.000000
108.570007,65.142097,-208.348770,-0.000560,0.003784,0.096123,289.766510,14.761411,0.961235,-208.348770,294.500488,0.000000
108.990005,65.400902,-208.437744,-0.000548,0.003790,0.096271,290.917755,14.820056,0.962711,-208.437744,294.500488,0.000000
109.410004,65.413933,-208.437744,-0.000560,0.003790,0.096271,290.975708,14.823009,0.962711,-208.437744,294.500488,0.000000
109.830002,65.367378,-208.526703,-0.000560,0.003790,0.096271,290.768616,14.812459,0.962711,-208.526703,294.500488,0.000000
110.250008,65.337593,-208.526703,-0.000552,0.003790,0.096271,290.636139,14.805711,0.962711,-208.526703,294.500488,0.000000
110.670006,65.311897,-208.526703,-0.000552,0.003790,0.096271,290.521820,14.799888,0.962711,-208.526703,294.500488,0.000000
111.090004,65.284340,-208.660141,-0.000552,0.003790,0.096271,290.399261,14.793643,0.962711,-208.660141,294.500488,0.000000
111.510002,65.232948,-208.660141,-0.000548,0.003790,0.096271,290.170654,14.781998,0.962711,-208.660141,294.500488,0.000000
111.930008,65.197945,-208.749100,-0.000548,0.003792,0.096314,290.014954,14.774065,0.963142,-208.749100,294.500488,0.000000
112.350006,65.220665,-208.749100,-0.000560,0.003792,0.096323,290.115997,14.779214,0.963233,-208.749100,294.500488,0.000000
112.770004,65.226631,-208.749100,-0.000535,0.003793,0.096340,290.142548,14.780566,0.963400,-208.749100,294.500488,0.000000
113.190002,65.250084,-208.838058,-0.000552,0.003794,0.096357,290.246857,14.785880,0.963574,-208.838058,294.500488,0.000000
113.610008,65.232216,-208.882553,-0.000556,0.003794,0.096357,290.167389,14.781832,0.963574,-208.882553,294.500488,0.000000
114.030006,65.259392,-208.882553,-0.000556,0.003796,0.096427,290.288269,14.787990,0.964270,-208.882553,294.500488,0.000000
114.450005,65.304085,-208.927032,-0.000543,0.003796,0.096427,290.487091,14.798118,0.964270,-208.927032,294.500488,0.000000
114.870003,65.301094,-208.971512,-0.000543,0.003796,0.096427,290.473785,14.797440,0.964270,-208.971512,294.500488,0.000000
115.290009,65.271675,-209.015991,-0.000569,0.003796,0.096427,290.342926,14.790773,0.964270,-209.015991,294.500488,0.000000
115.710007,65.246727,-209.104950,-0.000548,0.003796,0.096427,290.231934,14.785120,0.964270,-209.104950,294.500488,0.000000
116.130005,65.251579,-209.149429,-0.000548,0.003797,0.096453,290.253510,14.786219,0.964527,-209.149429,294.500488,0.000000
116.550003,65.235191,-209.149429,-0.000552,0.003797,0.096453,290.180634,14.782506,0.964527,-209.149429,294.500488,0.000000
116.970009,65.200188,-209.193909,-0.000548,0.003797,0.096453,290.024933,14.774573,0.964527,-209.193909,294.500488,0.000000
117.390007,65.166679,-209.238388,-0.000543,0.003798,0.096462,289.875854,14.766981,0.964618,-209.238388,294.500488,0.000000
117.810005,65.154015,-209.282867,-0.000543,0.003799,0.096488,289.819519,14.764111,0.964876,-209.282867,294.500488,0.000000
118.230003,65.167793,-209.327362,-0.000539,0.003799,0.096497,289.880829,14.767234,0.964967,-209.327362,294.500488,0.000000
118.650009,65.149910,-209.371841,-0.000539,0.003799,0.096497,289.801270,14.763181,0.964967,-209.371841,294.500488,0.000000
119.070007,65.110069,-209.327362,-0.000535,0.003799,0.096497,289.624054,14.754152,0.964967,-209.327362,294.500488,0.000000
119.490005,65.082893,-209.549759,-0.000543,0.003799,0.096497,289.503174,14.747994,0.964967,-209.549759,294.500488,0.000000
119.910004,65.047890,-209.505280,-0.000535,0.003799,0.096497,289.347473,14.740063,0.964967,-209.505280,294.500488,0.000000
120.330009,65.017723,-209.549759,-0.000535,0.003799,0.096497,289.213287,14.733227,0.964967,-209.549759,294.500488,0.000000
120.750008,65.293648,-209.549759,-0.000548,0.003804,0.096609,290.440643,14.795753,0.966094,-209.549759,294.500488,0.000000
121.170006,65.285835,-209.594238,-0.000543,0.003804,0.096609,290.405914,14.793983,0.966094,-209.594238,294.500488,0.000000
121.590004,65.273537,-209.683197,-0.000552,0.003804,0.096609,290.351196,14.791195,0.966094,-209.683197,294.500488,0.000000
122.010002,65.259392,-209.683197,-0.000548,0.003804,0.096609,290.288269,14.787990,0.966094,-209.683197,294.500488,0.000000
122.430008,65.228859,-209.772171,-0.000535,0.003804,0.096609,290.152466,14.781071,0.966094,-209.772171,294.500488,0.000000
122.850006,65.200554,-209.816650,-0.000543,0.003804,0.096609,290.026550,14.774657,0.966094,-209.816650,294.500488,0.000000
123.270004,65.166298,-209.772171,-0.000535,0.003804,0.096609,289.874176,14.766894,0.966094,-209.772171,294.500488,0.000000
123.690002,65.138374,-209.905609,-0.000552,0.003805,0.096635,289.749969,14.760567,0.966352,-209.905609,294.500488,0.000000
124.110008,65.133156,-209.994568,-0.000530,0.003805,0.096644,289.726746,14.759384,0.966435,-209.994568,294.500488,0.000000
124.530006,65.161079,-209.950089,-0.000539,0.003806,0.096661,289.850952,14.765712,0.966609,-209.950089,294.500488,0.000000
124.950005,65.143959,-209.994568,-0.000543,0.003806,0.096661,289.774811,14.761832,0.966609,-209.994568,294.500488,0.000000
125.370003,65.143578,-210.039047,-0.000530,0.003806,0.096670,289.773102,14.761745,0.966700,-210.039047,294.500488,0.000000
125.790009,65.119377,-210.083527,-0.000543,0.003806,0.096670,289.665466,14.756262,0.966700,-210.083527,294.500488,0.000000
126.210007,65.147316,-210.172501,-0.000522,0.003808,0.096713,289.789734,14.762592,0.967131,-210.172501,294.500488,0.000000
126.630005,65.170769,-210.128006,-0.000535,0.003808,0.096713,289.894043,14.767907,0.967131,-210.128006,294.500488,0.000000
127.050003,65.168159,-210.172501,-0.000535,0.003808,0.096713,289.882446,14.767316,0.967131,-210.172501,294.500488,0.000000
127.470009,65.154381,-210.261459,-0.000543,0.003808,0.096713,289.821167,14.764194,0.967131,-210.261459,294.500488,0.000000
127.890007,65.134651,-210.305939,-0.000530,0.003808,0.096713,289.733398,14.759723,0.967131,-210.305939,294.500488,0.000000
128.310013,65.113045,-210.394897,-0.000539,0.003808,0.096713,289.637299,14.754827,0.967131,-210.394897,294.500488,0.000000
128.730011,65.078041,-210.305939,-0.000535,0.003808,0.096713,289.481598,14.746895,0.967131,-210.305939,294.500488,0.000000
129.150009,65.050499,-210.394897,-0.000530,0.003808,0.096713,289.359070,14.740654,0.967131,-210.394897,294.500488,0.000000
129.570007,65.030006,-210.394897,-0.000530,0.003808,0.096713,289.267914,14.736011,0.967131,-210.394897,294.500488,0.000000
129.990005,65.155128,-210.483856,-0.000530,0.003811,0.096791,289.824493,14.764363,0.967911,-210.483856,1681.640991,0.000000
130.410004,65.084755,-210.572815,-0.000539,0.003800,0.096514,289.511444,14.748417,0.965141,-210.572815,0.096297,0.000000
130.830002,65.013634,-210.572815,-0.000517,0.003781,0.096036,289.195099,14.732300,0.960364,-210.572815,0.095603,0.000000
131.250000,64.898186,-210.617310,-0.000535,0.003755,0.095369,288.681549,14.706140,0.953688,-210.617310,0.094901,0.000000
131.670013,64.844566,-210.661789,-0.000535,0.003731,0.094762,288.443024,14.693989,0.947617,-210.661789,0.094198,0.000000
132.090012,64.807335,-210.750748,-0.000526,0.003702,0.094033,288.277435,14.685553,0.940334,-210.750748,0.093496,0.000000
132.510010,64.747749,-210.795227,-0.000526,0.003675,0.093357,288.012360,14.672050,0.933567,-210.795227,0.092802,0.000000
132.930008,64.695244,-210.795227,-0.000517,0.003649,0.092681,287.778809,14.660151,0.926807,-210.795227,0.092099,0.000000
133.350006,64.631203,-210.839706,-0.000522,0.003621,0.091961,287.493958,14.645640,0.919608,-210.839706,0.091397,0.000000
133.770004,64.614067,-210.884186,-0.000526,0.003599,0.091406,287.417725,14.641757,0.914060,-210.884186,0.090703,0.000000
134.190002,64.323250,-210.973145,-0.000522,0.003579,0.090894,286.124115,14.575857,0.908943,-210.973145,0.090001,0.000000
134.610001,63.080269,-210.973145,-0.000513,0.003545,0.090044,280.595062,14.294193,0.900442,-210.973145,0.089299,0.000000
135.030014,62.007835,-210.973145,-0.000513,0.003519,0.089385,275.824615,14.051176,0.893848,-210.973145,0.088596,0.000000
135.450012,60.478874,-211.062119,-0.000509,0.003493,0.088717,269.023468,13.704709,0.887172,-211.062119,0.087902,0.000000
135.870010,58.846397,-211.106598,-0.000496,0.003469,0.088119,261.761841,13.334785,0.881192,-211.106598,0.087199,0.000000
136.290009,57.086563,-211.151077,-0.000496,0.003445,0.087503,253.933716,12.936000,0.875030,-211.151077,0.086497,0.000000
136.710007,54.414787,-211.195557,-0.000496,0.003418,0.086827,242.049057,12.330566,0.868270,-211.195557,0.085804,0.000000
137.130005,51.514381,-211.195557,-0.000500,0.003387,0.086029,229.147415,11.673326,0.860291,-211.195557,0.085101,0.000000
137.550003,48.779305,-211.240036,-0.000509,0.003361,0.085361,216.981186,11.053548,0.853615,-211.240036,0.084399,0.000000
137.970001,45.874054,-211.284515,-0.000517,0.003334,0.084685,204.057983,10.395209,0.846848,-211.284515,0.083696,0.000000
138.389999,43.131905,-211.417953,-0.000509,0.003310,0.084078,191.860291,9.773829,0.840777,-211.417953,0.083002,0.000000
138.810013,41.131889,-211.417953,-0.000504,0.003293,0.083644,182.963776,9.320619,0.836439,-211.417953,0.082300,0.000000
139.230011,36.692467,-211.417953,-0.000500,0.003250,0.082543,163.216248,8.314632,0.825425,-211.417953,0.081598,0.000000
139.650009,33.957016,-211.373474,-0.000500,0.003224,0.081884,151.048355,7.694770,0.818839,-211.373474,0.080895,0.000000
140.070007,31.621872,-211.551407,-0.000500,0.003204,0.081381,140.661118,7.165618,0.813805,-211.551407,0.080201,0.000000
140.490005,28.860733,-211.551407,-0.000526,0.003179,0.080748,128.378952,6.539936,0.807477,-211.551407,0.079499,0.000000
140.910004,25.234192,-211.595886,-0.000509,0.003143,0.079820,112.247292,5.718150,0.798196,-211.595886,0.078796,0.000000
141.330002,22.001259,-211.595886,-0.000513,0.003113,0.079082,97.866486,4.985556,0.790824,-211.595886,0.078103,0.000000
141.750000,18.828270,-211.640366,-0.000513,0.003084,0.078328,83.752327,4.266547,0.783276,-211.640366,0.077400,0.000000
142.170013,17.353676,-211.729324,-0.000513,0.003073,0.078042,77.193008,3.932399,0.780415,-211.729324,0.076698,0.000000
142.590012,12.825256,-211.818283,-0.000522,0.003028,0.076923,57.049591,2.906245,0.769234,-211.818283,0.075995,0.000000
143.010010,9.966553,-211.773804,-0.000517,0.003002,0.076238,44.333439,2.258453,0.762384,-211.773804,0.075301,0.000000
143.430008,7.241531,-211.773804,-0.000517,0.002975,0.075570,32.211941,1.640954,0.755700,-211.773804,0.074599,0.000000
143.850006,4.579437,-211.818283,-0.000526,0.002951,0.074945,20.370354,1.037715,0.749455,-211.818283,0.073896,0.000000
144.270004,2.132210,-211.951736,-0.000535,0.002927,0.074347,9.484543,0.483166,0.743474,-211.951736,0.073203,0.000000
144.690002,-0.820335,-211.996216,-0.000539,0.002897,0.073584,-3.649034,-0.185891,0.735844,-211.996216,0.072500,0.000000
145.110001,-3.267941,-211.996216,-0.000552,0.002864,0.072734,-14.536526,-0.740526,0.727343,-211.996216,0.071798,0.000000
145.530014,-0.221558,-211.996216,-0.000642,0.002835,0.072006,-0.985538,-0.050206,0.720061,-211.996216,0.071095,0.000000
145.950012,-0.061813,-212.085175,-0.000655,0.002812,0.071416,-0.274960,-0.014007,0.714164,-212.085175,0.070401,0.000000
146.370010,0.005585,-212.174133,-0.000698,0.002787,0.070783,0.024842,0.001266,0.707828,-212.174133,0.069699,0.000000
146.790009,-0.023087,-212.307587,-0.000742,0.002754,0.069942,-0.102694,-0.005231,0.699418,-212.307587,0.068996,0.000000
147.210007,0.021599,-212.263092,-0.000780,0.002728,0.069292,0.096076,0.004894,0.692916,-212.263092,0.068294,0.000000
147.630005,0.019737,-212.218613,-0.000836,0.002700,0.068572,0.087796,0.004473,0.685717,-212.218613,0.067600,0.000000
148.050003,0.022720,-212.352066,-0.000892,0.002670,0.067826,0.101065,0.005149,0.678261,-212.352066,0.066898,0.000000
148.470001,0.015266,-212.396545,-0.000940,0.002643,0.067124,0.067908,0.003459,0.671236,-212.396545,0.066196,0.000000
148.890015,0.005219,-212.352066,-0.001013,0.002614,0.066404,0.023213,0.001183,0.664037,-212.352066,0.065501,0.000000
149.310013,0.027931,-212.441025,-0.001078,0.002589,0.065753,0.124244,0.006329,0.657535,-212.441025,0.064800,0.000000
149.730011,0.011169,-212.396545,-0.001125,0.002565,0.065146,0.049684,0.002531,0.651464,-212.396545,0.064097,0.000000
150.150009,-0.000000,-212.485504,-0.001190,0.002536,0.064409,-0.000000,-0.000000,0.644091,-212.485504,0.063395,0.000000
150.570007,0.013779,-212.574463,-0.001250,0.002509,0.063724,0.061291,0.003122,0.637240,-212.574463,0.062701,0.000000
150.990005,0.007080,-212.663422,-0.001315,0.002479,0.062978,0.031494,0.001604,0.629784,-212.663422,0.061998,0.000000
151.410004,-0.005585,-212.707901,-0.001375,0.002454,0.062336,-0.024842,-0.001266,0.623365,-212.707901,0.061296,0.000000
151.830002,-0.018616,-212.618942,-0.001440,0.002424,0.061582,-0.082807,-0.004218,0.615818,-212.618942,0.060602,0.000000
152.250000,-0.006699,-212.618942,-0.001457,0.002403,0.061027,-0.029797,-0.001518,0.610269,-212.618942,0.059900,0.000000
152.670013,-0.024200,-212.796875,-0.001509,0.002369,0.060177,-0.107649,-0.005484,0.601768,-212.796875,0.059197,0.000000
153.090012,-0.033882,-212.841354,-0.001548,0.002346,0.059587,-0.150715,-0.007678,0.595871,-212.841354,0.058495,0.000000
153.510010,-0.040215,-212.885834,-0.001591,0.002320,0.058929,-0.178883,-0.009113,0.589285,-212.885834,0.057801,0.000000
153.930008,-0.030907,-212.885834,-0.001625,0.002288,0.058113,-0.137480,-0.007004,0.581133,-212.885834,0.057098,0.000000
154.350006,-0.034630,-212.885834,-0.001673,0.002257,0.057333,-0.154041,-0.007847,0.573328,-212.885834,0.056396,0.000000
154.770004,-0.042450,-212.974792,-0.001703,0.002229,0.056621,-0.188827,-0.009619,0.566213,-212.974792,0.055693,0.000000
155.190002,-0.046921,-213.019272,-0.001742,0.002210,0.056127,-0.208714,-0.010632,0.561270,-213.019272,0.055000,0.000000
155.610001,-0.050270,-213.108231,-0.001763,0.002179,0.055338,-0.223612,-0.011391,0.553382,-213.108231,0.054297,0.000000
156.030014,-0.039101,-213.063751,-0.001781,0.002157,0.054792,-0.173928,-0.008860,0.547917,-213.063751,0.053595,0.000000
156.450012,-0.046547,-213.108231,-0.001824,0.002118,0.053786,-0.207051,-0.010548,0.537856,-213.108231,0.052901,0.000000
156.870010,-0.061440,-213.152710,-0.001863,0.002093,0.053169,-0.273297,-0.013922,0.531694,-213.152710,0.052198,0.000000
157.290009,-0.053246,-213.286163,-0.001876,0.002065,0.052441,-0.236848,-0.012066,0.524412,-213.286163,0.051496,0.000000
157.710007,-0.053619,-213.286163,-0.001919,0.002036,0.051704,-0.238511,-0.012150,0.517039,-213.286163,0.050793,0.000000
158.130005,-0.055481,-213.286163,-0.001949,0.002012,0.051106,-0.246792,-0.012572,0.511059,-213.286163,0.050100,0.000000
158.550003,-0.053993,-213.286163,-0.001979,0.001980,0.050282,-0.240174,-0.012235,0.502816,-213.286163,0.049397,0.000000
158.970001,-0.069260,-213.330643,-0.002018,0.001950,0.049528,-0.308082,-0.015694,0.495276,-213.330643,0.048695,0.000000
159.390015,-0.052505,-213.419601,-0.002035,0.001928,0.048981,-0.233556,-0.011898,0.489811,-213.419601,0.048001,0.000000
159.810013,-0.062187,-213.419601,-0.002065,0.001903,0.048339,-0.276622,-0.014092,0.483392,-213.419601,0.047298,0.000000
160.230011,-0.074844,-213.553040,-0.002113,0.001871,0.047524,-0.332924,-0.016960,0.475239,-213.553040,0.046597,0.000000
160.650009,-0.056229,-213.508560,-0.002139,0.001843,0.046813,-0.250117,-0.012742,0.468131,-213.508560,0.045894,0.000000
161.070007,-0.047287,-213.508560,-0.002160,0.001815,0.046102,-0.210343,-0.010715,0.461015,-213.508560,0.045200,0.000000
161.490005,-0.055481,-213.642014,-0.002190,0.001797,0.045642,-0.246792,-0.012572,0.456420,-213.642014,0.044497,0.000000
161.910004,-0.074844,-213.686493,-0.002220,0.001766,0.044844,-0.332924,-0.016960,0.448442,-213.686493,0.043795,0.000000
162.330002,-0.028671,-213.686493,-0.002251,0.001732,0.044003,-0.127536,-0.006497,0.440032,-213.686493,0.043093,0.000000
162.750015,-0.068512,-213.686493,-0.002281,0.001710,0.043422,-0.304756,-0.015525,0.434218,-213.686493,0.042399,0.000000
163.170013,-0.049522,-213.730972,-0.002307,0.001679,0.042650,-0.220287,-0.011222,0.426505,-213.730972,0.041697,0.000000
163.590012,-0.056229,-213.864410,-0.002341,0.001651,0.041939,-0.250117,-0.012742,0.419389,-213.864410,0.040994,0.000000
164.010010,-0.051384,-213.908890,-0.002367,0.001620,0.041158,-0.228567,-0.011644,0.411585,-213.908890,0.040300,0.000000
164.430008,-0.048035,-213.908890,-0.002410,0.001593,0.040473,-0.213669,-0.010885,0.404734,-213.908890,0.039598,0.000000
164.850006,-0.007072,-213.908890,-0.002436,0.001568,0.039823,-0.031460,-0.001603,0.398232,-213.908890,0.038895,0.000000
165.270004,-0.042824,-213.997849,-0.002466,0.001540,0.039121,-0.190490,-0.009704,0.391207,-213.997849,0.038193,0.000000
165.690002,-0.040962,-214.086823,-0.002488,0.001513,0.038418,-0.182209,-0.009282,0.384182,-214.086823,0.037499,0.000000
166.110001,-0.047287,-214.042343,-0.002514,0.001488,0.037803,-0.210343,-0.010715,0.378028,-214.042343,0.036797,0.000000
166.530014,-0.019737,-214.086823,-0.002539,0.001459,0.037056,-0.087796,-0.004473,0.370564,-214.086823,0.036094,0.000000
166.950012,-0.004097,-214.086823,-0.002578,0.001428,0.036276,-0.018224,-0.000928,0.362759,-214.086823,0.035400,0.000000
167.370010,-0.005959,-214.175781,-0.002621,0.001404,0.035669,-0.026505,-0.001350,0.356688,-214.175781,0.034698,0.000000
167.790009,-0.021599,-214.220261,-0.002626,0.001376,0.034958,-0.096076,-0.004894,0.349580,-214.220261,0.033995,0.000000
168.210007,-0.032021,-214.309219,-0.002665,0.001344,0.034134,-0.142435,-0.007256,0.341345,-214.309219,0.033293,0.000000
168.630005,0.007820,-214.264740,-0.002686,0.001322,0.033571,0.034786,0.001772,0.335705,-214.264740,0.032599,0.000000
169.050003,-0.008934,-214.309219,-0.002721,0.001297,0.032946,-0.039741,-0.002024,0.329460,-214.309219,0.031897,0.000000
169.470001,0.004097,-214.442657,-0.002764,0.001262,0.032053,0.018224,0.000928,0.320528,-214.442657,0.031194,0.000000
169.890015,-0.013405,-214.442657,-0.002764,0.001238,0.031455,-0.059628,-0.003038,0.314547,-214.442657,0.030492,0.000000
170.310013,-0.021599,-214.531631,-0.002798,0.001209,0.030700,-0.096076,-0.004894,0.307000,-214.531631,0.029798,0.000000
170.730011,-0.018990,-214.487152,-0.002833,0.001181,0.030006,-0.084470,-0.004303,0.300059,-214.487152,0.029095,0.000000
171.150009,-0.017128,-214.531631,-0.002863,0.001156,0.029365,-0.076189,-0.003881,0.293647,-214.531631,0.028394,0.000000
171.570007,-0.021225,-214.620590,-0.002897,0.001129,0.028680,-0.094413,-0.004810,0.286797,-214.620590,0.027699,0.000000
171.990005,-0.014893,-214.665070,-0.002923,0.001098,0.027882,-0.066245,-0.003375,0.278818,-214.665070,0.026997,0.000000
172.410004,-0.019363,-214.709549,-0.002953,0.001071,0.027197,-0.086133,-0.004388,0.271967,-214.709549,0.027101,0.000000
172.600006,-0.023087,-214.709549,-0.002949,0.001071,0.027213,-0.102694,-0.005231,0.272134,-214.709549,0.027101,0.000000