File: Data/compression 6/AutoNoheating-10-6-day3-3-240301_03012024_155535.csv
Time (sec),S:Load (lbs),S:HL1 (DIM),S:LVDT (in),S:Position (in),Ch:Position (mm),Ch:Load (N),Ch:Stress (MPa),Ch:Strain (mm/mm),Ch:HL1 (DIM),Set Point (),Cycles ()
0.110000,-0.002975,-136.111710,-0.000017,-0.000000,-0.000000,-0.013236,-0.000674,-0.000000,-136.111710,0.000182,0.000000
0.380000,-0.011543,-136.067230,0.000000,-0.000000,-0.000000,-0.051347,-0.002616,-0.000000,-136.067230,0.000182,0.000000
0.650000,-0.005585,-136.111710,0.000017,0.000149,0.003772,-0.024842,-0.001266,0.037724,-136.111710,0.004640,0.000000
0.920000,-0.071495,-136.200668,0.000177,0.000318,0.008074,-0.318026,-0.016201,0.080739,-136.200668,0.009132,0.000000
1.190000,0.002609,-136.156189,0.000323,0.000490,0.012445,0.011607,0.000591,0.124447,-136.156189,0.013624,0.000000
1.460000,-0.005211,-136.245148,0.000517,0.000671,0.017032,-0.023179,-0.001181,0.170324,-136.245148,0.018134,0.000000
1.730000,-0.002228,-136.289627,0.000703,0.000849,0.021577,-0.009910,-0.000505,0.215766,-136.289627,0.022626,0.000000
2.000000,0.008194,-136.334122,0.000897,0.001028,0.026121,0.036449,0.001857,0.261207,-136.334122,0.027118,0.000000
2.270000,-0.004097,-136.378601,0.001082,0.001201,0.030500,-0.018224,-0.000928,0.305002,-136.378601,0.031628,0.000000
2.540000,0.001862,-136.378601,0.001289,0.001373,0.034880,0.008281,0.000422,0.348797,-136.378601,0.036120,0.000000
2.810000,0.005219,-136.467560,0.001531,0.001560,0.039615,0.023213,0.001183,0.396150,-136.467560,0.040612,0.000000
3.080000,-0.025322,-136.467560,0.001595,0.001732,0.043994,-0.112638,-0.005738,0.439945,-136.467560,0.045122,0.000000
3.350000,-0.011169,-136.512039,0.001772,0.001905,0.048391,-0.049684,-0.002531,0.483910,-136.512039,0.049614,0.000000
3.620000,-0.013405,-136.512039,0.001962,0.002089,0.053048,-0.059628,-0.003038,0.530483,-136.512039,0.054106,0.000000
3.890000,0.010429,-136.556519,0.002121,0.002264,0.057506,0.046392,0.002363,0.575058,-136.556519,0.058616,0.000000
4.160000,0.021599,-136.600998,0.002324,0.002446,0.062137,0.096076,0.004894,0.621366,-136.600998,0.063108,0.000000
4.430000,0.013039,-136.645477,0.002501,0.002621,0.066585,0.057999,0.002955,0.665854,-136.645477,0.067600,0.000000
4.700000,0.003357,-136.645477,0.002665,0.002793,0.070930,0.014932,0.000761,0.709304,-136.645477,0.072110,0.000000
4.970000,-0.039841,-136.645477,0.002863,0.002973,0.075509,-0.177220,-0.009028,0.755094,-136.645477,0.076602,0.000000
5.240000,0.001122,-136.734436,0.003014,0.003149,0.079984,0.004989,0.000254,0.799843,-136.734436,0.081094,0.000000
5.510000,-0.011169,-136.778931,0.003199,0.003330,0.084589,-0.049684,-0.002531,0.845890,-136.778931,0.085604,0.000000
5.780000,-0.015640,-136.734436,0.003389,0.003506,0.089064,-0.069571,-0.003544,0.890639,-136.734436,0.090096,0.000000
6.050000,0.038361,-136.823410,0.003583,0.003680,0.093469,0.170636,0.008693,0.934695,-136.823410,0.094606,0.000000
6.320000,-0.014145,-136.778931,0.003755,0.003860,0.098040,-0.062920,-0.003205,0.980398,-136.778931,0.099098,0.000000
6.590000,0.024208,-136.867889,0.003919,0.004041,0.102645,0.107683,0.005486,1.026448,-136.867889,0.103590,0.000000
6.860000,0.000374,-136.912369,0.004109,0.004218,0.107128,0.001663,0.000085,1.071284,-136.912369,0.108100,0.000000
7.130000,-0.029045,-137.001328,0.004281,0.004386,0.111413,-0.129199,-0.006582,1.114125,-137.001328,0.112592,0.000000
7.400001,0.023460,-136.956848,0.004445,0.004563,0.115896,0.104357,0.005316,1.158961,-136.956848,0.117084,0.000000
7.670001,-0.040215,-137.001328,0.004661,0.004747,0.120562,-0.178883,-0.009113,1.205618,-137.001328,0.121594,0.000000
7.940001,0.011917,-137.001328,0.004850,0.004924,0.125071,0.053010,0.002700,1.250711,-137.001328,0.126086,0.000000
8.210000,0.033890,-137.134766,0.005010,0.005102,0.129581,0.150749,0.007680,1.295808,-137.134766,0.130578,0.000000
8.480000,-0.007446,-137.223740,0.005187,0.005277,0.134047,-0.033123,-0.001687,1.340470,-137.223740,0.135088,0.000000
8.750000,0.028679,-137.134766,0.005368,0.005452,0.138487,0.127570,0.006499,1.384874,-137.134766,0.139580,0.000000
9.020000,-0.007072,-137.179260,0.005562,0.005634,0.143101,-0.031460,-0.001603,1.431008,-137.179260,0.144072,0.000000
9.290001,0.012291,-137.179260,0.005730,0.005805,0.147454,0.054673,0.002785,1.474542,-137.179260,0.148582,0.000000
9.560000,-0.014893,-137.268219,0.005877,0.005977,0.151816,-0.066245,-0.003375,1.518163,-137.268219,0.153074,0.000000
9.830001,-0.041702,-137.268219,0.006071,0.006160,0.156465,-0.185501,-0.009450,1.564649,-137.268219,0.157566,0.000000
10.100000,0.034264,-137.312698,0.006243,0.006336,0.160931,0.152412,0.007764,1.609311,-137.312698,0.162076,0.000000
10.370001,0.061447,-137.312698,0.006416,0.006522,0.165657,0.273331,0.013924,1.656573,-137.312698,0.166568,0.000000
10.640000,0.188049,-137.357178,0.006597,0.006693,0.170002,0.836485,0.042613,1.700023,-137.357178,0.171060,0.000000
10.910001,0.678841,-137.401657,0.006743,-0.000000,-0.000000,3.019634,0.153827,-0.000000,-137.401657,0.000191,0.000000
11.180000,0.612183,-137.446136,0.006752,-0.000000,-0.000009,2.723124,0.138723,-0.000087,-137.446136,0.000191,0.000000
11.450001,0.566010,-137.446136,0.006760,-0.000000,-0.000009,2.517736,0.128260,-0.000087,-137.446136,0.000295,0.000000
11.720000,0.568619,-137.401657,0.006752,-0.000000,-0.000009,2.529343,0.128851,-0.000087,-137.401657,0.000737,0.000000
11.990001,0.630058,-137.490616,0.006752,0.000011,0.000269,2.802639,0.142773,0.002691,-137.490616,0.001188,0.000000
12.260000,0.753685,-137.535095,0.006760,0.000032,0.000824,3.352558,0.170787,0.008240,-137.535095,0.001639,0.000000
12.530001,0.859436,-137.579575,0.006791,0.000051,0.001292,3.822963,0.194751,0.012922,-137.579575,0.002090,0.000000
12.800000,0.929070,-137.624069,0.006791,0.000064,0.001613,4.132708,0.210530,0.016131,-137.624069,0.002541,0.000000
13.070001,1.022537,-137.579575,0.006808,0.000085,0.002168,4.548473,0.231710,0.021684,-137.579575,0.002992,0.000000
13.340001,1.088448,-137.624069,0.006825,0.000099,0.002506,4.841657,0.246646,0.025064,-137.624069,0.003443,0.000000
13.610001,1.211700,-137.713028,0.006851,0.000120,0.003035,5.389913,0.274575,0.030355,-137.713028,0.003894,0.000000
13.880001,1.262718,-137.801987,0.006885,0.000133,0.003373,5.616851,0.286136,0.033735,-137.801987,0.004345,0.000000
14.150001,1.376289,-137.757507,0.006890,0.000152,0.003859,6.122041,0.311872,0.038595,-137.757507,0.004787,0.000000
14.420001,1.492844,-137.801987,0.006907,0.000175,0.004457,6.640500,0.338283,0.044575,-137.801987,0.005238,0.000000
14.690001,1.556145,-137.890945,0.006929,0.000193,0.004891,6.922077,0.352627,0.048912,-137.890945,0.005689,0.000000
14.960001,1.638817,-137.890945,0.006929,0.000208,0.005273,7.289821,0.371361,0.052727,-137.890945,0.006140,0.000000
15.230000,1.730789,-137.979904,0.006929,0.000225,0.005724,7.698935,0.392202,0.057239,-137.979904,0.006591,0.000000
15.500001,1.827606,-137.979904,0.006963,0.000242,0.006157,8.129599,0.414141,0.061573,-137.979904,0.007042,0.000000
15.770000,1.907295,-137.979904,0.006972,0.000259,0.006591,8.484073,0.432199,0.065910,-137.979904,0.007493,0.000000
16.040001,2.005974,-138.024384,0.007011,0.000276,0.007007,8.923018,0.454560,0.070074,-138.024384,0.007944,0.000000
16.310001,2.122528,-138.068878,0.007019,0.000297,0.007554,9.441477,0.480972,0.075535,-138.068878,0.008395,0.000000
16.580000,2.192902,-138.157837,0.007045,0.000315,0.008013,9.754514,0.496919,0.080134,-138.157837,0.008846,0.000000
16.850000,2.216736,-138.113358,0.007062,0.000332,0.008430,9.860534,0.502320,0.084297,-138.113358,0.009288,0.000000
17.120001,2.277061,-138.113358,0.007058,0.000346,0.008776,10.128876,0.515989,0.087764,-138.113358,0.009739,0.000000
17.390001,2.413345,-138.202316,0.007067,0.000365,0.009279,10.735096,0.546872,0.092794,-138.202316,0.010190,0.000000
17.660002,2.555969,-138.246796,0.007110,0.000383,0.009730,11.369519,0.579191,0.097302,-138.246796,0.010641,0.000000
17.930000,2.566765,-138.291275,0.007110,0.000399,0.010129,11.417541,0.581637,0.101291,-138.291275,0.011092,0.000000
18.200001,2.697098,-138.291275,0.007144,0.000419,0.010632,11.997290,0.611171,0.106321,-138.291275,0.011543,0.000000
18.470001,2.826309,-138.291275,0.007153,0.000440,0.011170,12.572051,0.640451,0.111700,-138.291275,0.011994,0.000000
18.740002,2.860939,-138.335754,0.007174,0.000451,0.011456,12.726092,0.648298,0.114561,-138.335754,0.012445,0.000000
19.010000,2.908234,-138.380234,0.007183,0.000471,0.011968,12.936469,0.659015,0.119678,-138.380234,0.012896,0.000000
19.280001,3.073563,-138.469208,0.007200,0.000488,0.012402,13.671889,0.696479,0.124016,-138.469208,0.013338,0.000000
19.550001,3.224747,-138.469208,0.007217,0.000508,0.012896,14.344390,0.730738,0.128959,-138.469208,0.013789,0.000000
19.820002,3.194588,-138.513687,0.007239,0.000518,0.013165,14.210236,0.723904,0.131646,-138.513687,0.014240,0.000000
20.090000,3.299599,-138.513687,0.007235,0.000532,0.013511,14.677348,0.747700,0.135113,-138.513687,0.014691,0.000000
20.360001,3.599724,-138.602646,0.007265,0.000562,0.014283,16.012371,0.815709,0.142834,-138.602646,0.015142,0.000000
20.630001,3.632500,-138.558167,0.007304,0.000578,0.014691,16.158165,0.823136,0.146911,-138.558167,0.015593,0.000000
20.900002,3.660423,-138.647125,0.007304,0.000594,0.015090,16.282375,0.829464,0.150900,-138.647125,0.016044,0.000000
21.170000,3.787407,-138.602646,0.007325,0.000613,0.015567,16.847227,0.858239,0.155669,-138.602646,0.016495,0.000000
21.440001,3.910286,-138.602646,0.007325,0.000630,0.015992,17.393820,0.886083,0.159919,-138.602646,0.016946,0.000000
21.710001,3.984016,-138.691605,0.007334,0.000644,0.016365,17.721790,0.902791,0.163648,-138.691605,0.017388,0.000000
21.980001,4.084183,-138.736084,0.007364,0.000659,0.016729,18.167353,0.925489,0.167289,-138.736084,0.017839,0.000000
22.250002,4.338890,-138.736084,0.007390,0.000688,0.017475,19.300346,0.983207,0.174749,-138.736084,0.018290,0.000000
22.520000,4.367935,-138.780563,0.007403,0.000702,0.017839,19.429546,0.989788,0.178390,-138.780563,0.018741,0.000000
22.790001,4.439056,-138.825043,0.007420,0.000721,0.018307,19.745909,1.005905,0.183072,-138.825043,0.019192,0.000000
23.060001,4.539970,-138.869522,0.007442,0.000738,0.018750,20.194798,1.028772,0.187496,-138.869522,0.019643,0.000000
23.330002,4.754456,-138.914017,0.007468,0.000757,0.019235,21.148874,1.077375,0.192352,-138.914017,0.020094,0.000000
23.600000,4.798767,-138.958496,0.007463,0.000772,0.019617,21.345982,1.087416,0.196167,-138.958496,0.020545,0.000000
23.870001,4.855370,-138.958496,0.007485,0.000785,0.019946,21.597763,1.100242,0.199464,-138.958496,0.020996,0.000000
24.140001,5.104858,-139.002975,0.007511,0.000810,0.020571,22.707544,1.156778,0.205705,-139.002975,0.021447,0.000000
24.410002,5.170395,-139.002975,0.007511,0.000828,0.021022,22.999065,1.171628,0.210217,-139.002975,0.021889,0.000000
24.680000,5.212845,-139.091934,0.007528,0.000845,0.021464,23.187893,1.181248,0.214641,-139.091934,0.022340,0.000000
24.950001,5.387863,-139.180893,0.007562,0.000866,0.021993,23.966412,1.220907,0.219929,-139.180893,0.022791,0.000000
25.220001,5.460098,-139.136414,0.007562,0.000882,0.022409,24.287729,1.237276,0.224092,-139.136414,0.023242,0.000000
25.490002,5.549095,-139.136414,0.007606,0.000898,0.022808,24.683607,1.257443,0.228082,-139.136414,0.023693,0.000000
25.760002,5.547607,-139.180893,0.007580,0.000911,0.023147,24.676991,1.257106,0.231465,-139.180893,0.024144,0.000000
26.030001,5.874176,-139.269852,0.007610,0.000936,0.023771,26.129641,1.331107,0.237707,-139.269852,0.024595,0.000000
26.300001,5.897636,-139.225372,0.007623,0.000952,0.024170,26.233997,1.336424,0.241696,-139.225372,0.025045,0.000000
26.570002,5.973976,-139.269852,0.007670,0.000970,0.024638,26.573572,1.353722,0.246382,-139.269852,0.025497,0.000000
26.840002,6.010094,-139.314346,0.007662,0.000986,0.025054,26.734232,1.361907,0.250541,-139.314346,0.025939,0.000000
27.110001,6.228676,-139.358826,0.007683,0.001007,0.025566,27.706533,1.411438,0.255658,-139.358826,0.026390,0.000000
27.380001,6.346344,-139.403305,0.007696,0.001024,0.026000,28.229948,1.438102,0.259996,-139.403305,0.026841,0.000000
27.650002,6.345978,-139.492264,0.007713,0.001037,0.026329,28.228319,1.438019,0.263292,-139.492264,0.027292,0.000000
27.920002,6.563438,-139.492264,0.007735,0.001059,0.026902,29.195633,1.487296,0.269015,-139.492264,0.027743,0.000000
28.190001,6.792076,-139.492264,0.007774,0.001082,0.027491,30.212664,1.539106,0.274912,-139.492264,0.028194,0.000000
28.460001,6.692284,-139.492264,0.007774,0.001095,0.027803,29.768764,1.516493,0.278035,-139.492264,0.028644,0.000000
28.730001,6.722816,-139.625702,0.007791,0.001111,0.028220,29.904581,1.523412,0.282198,-139.625702,0.029096,0.000000
29.000002,6.914589,-139.670181,0.007812,0.001132,0.028757,30.757627,1.566868,0.287573,-139.670181,0.029546,0.000000
29.270000,7.062790,-139.714661,0.007812,0.001150,0.029208,31.416859,1.600451,0.292084,-139.714661,0.029998,0.000000
29.540001,7.018105,-139.670181,0.007838,0.001165,0.029581,31.218088,1.590325,0.295812,-139.670181,0.030440,0.000000
29.810001,7.342445,-139.670181,0.007851,0.001185,0.030102,32.660828,1.663822,0.301016,-139.670181,0.030891,0.000000
30.080002,7.363670,-139.714661,0.007873,0.001201,0.030501,32.755241,1.668632,0.305006,-139.714661,0.031342,0.000000
30.350002,7.388245,-139.759155,0.007886,0.001219,0.030960,32.864555,1.674200,0.309601,-139.759155,0.031793,0.000000
30.620001,7.508148,-139.803635,0.007899,0.001236,0.031403,33.397911,1.701371,0.314025,-139.803635,0.032244,0.000000
30.890001,7.640343,-139.803635,0.007920,0.001252,0.031801,33.985943,1.731326,0.318014,-139.803635,0.032695,0.000000
31.160002,7.769928,-139.803635,0.007946,0.001271,0.032287,34.562366,1.760691,0.322870,-139.803635,0.033145,0.000000
31.430002,7.715561,-139.937073,0.007959,0.001283,0.032582,34.320530,1.748371,0.325819,-139.937073,0.033597,0.000000
31.700001,7.975479,-139.937073,0.007955,0.001306,0.033172,35.476704,1.807269,0.331716,-139.937073,0.034047,0.000000
31.970001,8.122932,-139.937073,0.008006,0.001328,0.033735,36.132607,1.840683,0.337351,-139.937073,0.034490,0.000000
32.240002,8.125916,-139.892593,0.007989,0.001343,0.034108,36.145878,1.841359,0.341080,-139.892593,0.034941,0.000000
32.510002,8.170227,-139.937073,0.008011,0.001357,0.034472,36.342983,1.851400,0.344724,-139.937073,0.035391,0.000000
32.780003,8.372795,-140.026031,0.008024,0.001378,0.035010,37.244053,1.897303,0.350099,-140.026031,0.035843,0.000000
33.050003,8.500153,-140.159470,0.008063,0.001398,0.035513,37.810566,1.926162,0.355129,-140.159470,0.036293,0.000000
33.320000,8.445786,-140.159470,0.008063,0.001409,0.035782,37.568729,1.913842,0.357820,-140.159470,0.036745,0.000000
33.590000,8.620056,-140.203964,0.008088,0.001429,0.036293,38.343925,1.953333,0.362934,-140.203964,0.037195,0.000000
33.860001,8.818901,-140.159470,0.008119,0.001449,0.036805,39.228432,1.998392,0.368051,-140.159470,0.037646,0.000000
34.130001,8.758575,-140.203964,0.008119,0.001462,0.037135,38.960091,1.984722,0.371347,-140.203964,0.038097,0.000000
34.400002,8.895607,-140.292923,0.008119,0.001482,0.037655,39.569637,2.015773,0.376552,-140.292923,0.038540,0.000000
34.670002,8.946999,-140.381882,0.008144,0.001500,0.038089,39.798237,2.027419,0.380885,-140.381882,0.038990,0.000000
34.940002,9.109726,-140.337402,0.008157,0.001518,0.038557,40.522083,2.064293,0.385571,-140.337402,0.039442,0.000000
35.210003,9.120148,-140.381882,0.008188,0.001531,0.038895,40.568443,2.066655,0.388951,-140.381882,0.039892,0.000000
35.480003,9.193130,-140.381882,0.008188,0.001549,0.039355,40.893085,2.083193,0.393550,-140.381882,0.040344,0.000000
35.750000,9.582634,-140.426361,0.008218,0.001574,0.039979,42.625687,2.171456,0.399791,-140.426361,0.040794,0.000000
36.020000,9.510765,-140.470840,0.008235,0.001591,0.040404,42.305996,2.155170,0.404041,-140.470840,0.041246,0.000000
36.290001,9.551353,-140.515320,0.008252,0.001606,0.040803,42.486542,2.164367,0.408031,-140.515320,0.041696,0.000000
36.560001,9.649666,-140.426361,0.008269,0.001624,0.041254,42.923859,2.186646,0.412542,-140.426361,0.042147,0.000000
36.830002,9.740891,-140.515320,0.008287,0.001640,0.041661,43.329643,2.207317,0.416615,-140.515320,0.042598,0.000000
37.100002,9.858932,-140.604294,0.008291,0.001659,0.042130,43.854721,2.234066,0.421300,-140.604294,0.043041,0.000000
37.370003,9.953148,-140.648773,0.008321,0.001674,0.042529,44.273811,2.255415,0.425290,-140.648773,0.043491,0.000000
37.640003,10.186996,-140.648773,0.008334,0.001697,0.043093,45.314022,2.308407,0.430925,-140.648773,0.043942,0.000000
37.910004,10.219391,-140.737732,0.008356,0.001714,0.043526,45.458122,2.315747,0.435263,-140.737732,0.044393,0.000000
38.180000,10.250298,-140.648773,0.008347,0.001730,0.043951,45.595600,2.322751,0.439510,-140.648773,0.044844,0.000000
38.450001,10.179924,-140.782211,0.008390,0.001745,0.044315,45.282562,2.306804,0.443154,-140.782211,0.045295,0.000000
38.720001,10.485641,-140.782211,0.008390,0.001765,0.044836,46.642464,2.376080,0.448359,-140.782211,0.045746,0.000000
38.990002,10.611130,-140.826691,0.008407,0.001782,0.045269,47.200661,2.404516,0.452692,-140.826691,0.046197,0.000000
39.260002,10.614479,-140.826691,0.008425,0.001799,0.045686,47.215561,2.405275,0.456856,-140.826691,0.046648,0.000000
39.530003,10.827477,-140.826691,0.008429,0.001818,0.046171,48.163021,2.453541,0.461712,-140.826691,0.047091,0.000000
39.800003,10.945892,-140.915649,0.008464,0.001838,0.046683,48.689762,2.480375,0.466829,-140.915649,0.047541,0.000000
40.070004,10.809975,-141.004608,0.008468,0.001850,0.046986,48.085171,2.449575,0.469864,-141.004608,0.047992,0.000000
40.340000,10.816681,-141.004608,0.008481,0.001869,0.047463,48.114998,2.451095,0.474633,-141.004608,0.048443,0.000000
40.610001,11.037498,-141.049103,0.008502,0.001886,0.047914,49.097244,2.501133,0.479145,-141.049103,0.048894,0.000000
40.880001,11.292946,-141.004608,0.008524,0.001906,0.048418,50.233532,2.559018,0.484175,-141.004608,0.049345,0.000000
41.150002,11.052391,-141.093582,0.008528,0.001917,0.048686,49.163490,2.504508,0.486862,-141.093582,0.049796,0.000000
41.420002,11.055367,-141.138062,0.008545,0.001931,0.049042,49.176727,2.505182,0.490416,-141.138062,0.050247,0.000000
41.690002,11.749840,-141.182541,0.008580,0.001962,0.049839,52.265896,2.662552,0.498395,-141.182541,0.050698,0.000000
41.960003,11.657120,-141.182541,0.008589,0.001977,0.050212,51.853458,2.641541,0.502123,-141.182541,0.051140,0.000000
42.230003,11.574081,-141.182541,0.008601,0.001993,0.050629,51.484085,2.622724,0.506287,-141.182541,0.051592,0.000000
42.500004,11.660103,-141.227020,0.008593,0.002010,0.051062,51.866730,2.642217,0.510624,-141.227020,0.052042,0.000000
42.770000,11.831390,-141.315979,0.008627,0.002029,0.051531,52.628654,2.681031,0.515306,-141.315979,0.052493,0.000000
43.040001,11.781868,-141.315979,0.008636,0.002043,0.051895,52.408367,2.669809,0.518951,-141.315979,0.052944,0.000000
43.310001,11.850388,-141.360458,0.008658,0.002057,0.052259,52.713158,2.685336,0.522592,-141.360458,0.053395,0.000000
43.580002,12.421600,-141.315979,0.008683,0.002088,0.053031,55.254040,2.814775,0.530309,-141.315979,0.053846,0.000000
43.850002,12.239143,-141.449417,0.008688,0.002101,0.053369,54.442429,2.773429,0.533693,-141.449417,0.054297,0.000000
44.120003,12.305794,-141.449417,0.008696,0.002120,0.053837,54.738903,2.788533,0.538375,-141.449417,0.054748,0.000000
44.390003,12.238396,-141.449417,0.008727,0.002136,0.054245,54.439102,2.773260,0.542451,-141.449417,0.055199,0.000000
44.660004,12.651733,-141.493912,0.008744,0.002156,0.054766,56.277721,2.866924,0.547655,-141.493912,0.055641,0.000000
44.930000,12.619705,-141.493912,0.008757,0.002171,0.055147,56.135254,2.859666,0.551471,-141.493912,0.056092,0.000000
45.200001,12.526985,-141.538391,0.008748,0.002184,0.055468,55.722813,2.838655,0.554680,-141.538391,0.056543,0.000000
45.470001,12.946648,-141.627350,0.008770,0.002209,0.056101,57.589565,2.933752,0.561009,-141.627350,0.056994,0.000000
45.740002,13.017403,-141.716309,0.008778,0.002227,0.056561,57.904301,2.949786,0.565607,-141.716309,0.057445,0.000000
46.010002,13.111237,-141.671829,0.008821,0.002245,0.057011,58.321693,2.971049,0.570115,-141.671829,0.057896,0.000000
46.280003,13.375618,-141.627350,0.008839,0.002265,0.057523,59.497719,3.030958,0.575232,-141.627350,0.058347,0.000000
46.550003,13.377113,-141.716309,0.008856,0.002282,0.057966,59.504372,3.031297,0.579657,-141.716309,0.058798,0.000000
46.820004,13.339500,-141.805267,0.008860,0.002297,0.058347,59.337063,3.022774,0.583472,-141.805267,0.059249,0.000000
47.090004,13.199860,-141.849747,0.008886,0.002312,0.058737,58.715908,2.991131,0.587374,-141.849747,0.059691,0.000000
47.360001,13.742783,-141.849747,0.008895,0.002334,0.059284,61.130951,3.114159,0.592836,-141.849747,0.060142,0.000000
47.630001,13.710014,-141.849747,0.008916,0.002351,0.059726,60.985191,3.106734,0.597260,-141.849747,0.060593,0.000000
47.900002,13.772942,-141.894241,0.008938,0.002369,0.060168,61.265102,3.120993,0.601681,-141.894241,0.061044,0.000000
48.170002,13.786346,-141.894241,0.008938,0.002386,0.060593,61.324730,3.124031,0.605931,-141.894241,0.061495,0.000000
48.440002,14.130424,-142.027679,0.008968,0.002406,0.061105,62.855267,3.202000,0.611049,-142.027679,0.061946,0.000000
48.710003,14.234314,-142.027679,0.008972,0.002424,0.061573,63.317390,3.225542,0.615731,-142.027679,0.062397,0.000000
48.980003,14.185158,-141.983200,0.008998,0.002439,0.061963,63.098732,3.214403,0.619633,-141.983200,0.062848,0.000000
49.250004,14.316231,-142.027679,0.008994,0.002458,0.062423,63.681774,3.244104,0.624231,-142.027679,0.063299,0.000000
49.520000,14.816704,-142.072159,0.009028,0.002481,0.063022,65.907990,3.357513,0.630215,-142.072159,0.063741,0.000000
49.790001,14.527367,-142.116638,0.009033,0.002493,0.063334,64.620956,3.291948,0.633338,-142.116638,0.064192,0.000000
50.060001,14.532959,-142.116638,0.009063,0.002509,0.063741,64.645828,3.293216,0.637410,-142.116638,0.064643,0.000000
50.330002,14.891174,-142.205597,0.009071,0.002532,0.064314,66.239250,3.374388,0.643137,-142.205597,0.065094,0.000000
50.600002,14.989487,-142.205597,0.009067,0.002549,0.064756,66.676567,3.396666,0.647558,-142.205597,0.065545,0.000000
50.870003,15.188705,-142.250076,0.009097,0.002568,0.065216,67.562737,3.441810,0.652156,-142.250076,0.065996,0.000000
51.140003,15.275093,-142.294556,0.009110,0.002585,0.065658,67.947006,3.461385,0.656577,-142.294556,0.066447,0.000000
51.410004,15.260941,-142.294556,0.009136,0.002601,0.066074,67.884056,3.458179,0.660740,-142.294556,0.066898,0.000000
51.680004,15.338028,-142.339050,0.009153,0.002619,0.066534,68.226959,3.475647,0.665335,-142.339050,0.067349,0.000000
51.950001,15.394997,-142.250076,0.009145,0.002636,0.066950,68.480362,3.488556,0.669499,-142.250076,0.067800,0.000000
52.220001,15.446014,-142.383530,0.009153,0.002651,0.067331,68.707306,3.500117,0.673314,-142.383530,0.068242,0.000000
52.490002,15.660126,-142.472488,0.009196,0.002670,0.067809,69.659721,3.548635,0.678087,-142.472488,0.068693,0.000000
52.760002,15.462769,-142.472488,0.009192,0.002682,0.068112,68.781830,3.503913,0.681118,-142.472488,0.069144,0.000000
53.030003,15.831047,-142.428009,0.009214,0.002703,0.068658,70.420013,3.587367,0.686584,-142.428009,0.069595,0.000000
53.300003,16.177353,-142.516968,0.009240,0.002725,0.069222,71.960457,3.665841,0.692219,-142.516968,0.070046,0.000000
53.570004,16.287949,-142.516968,0.009235,0.002742,0.069656,72.452415,3.690902,0.696557,-142.516968,0.070497,0.000000
53.840004,16.224274,-142.650406,0.009257,0.002758,0.070046,72.169174,3.676473,0.700459,-142.650406,0.070948,0.000000
54.110004,16.543396,-142.605927,0.009270,0.002777,0.070540,73.588699,3.748787,0.705402,-142.605927,0.071399,0.000000
54.380001,16.765327,-142.650406,0.009291,0.002797,0.071043,74.575905,3.799078,0.710432,-142.650406,0.071850,0.000000
54.650002,16.504295,-142.739365,0.009291,0.002808,0.071312,73.414772,3.739927,0.713120,-142.739365,0.072292,0.000000
54.920002,16.899384,-142.739365,0.009313,0.002829,0.071867,75.172211,3.829455,0.718672,-142.739365,0.072743,0.000000
55.190002,17.128395,-142.739365,0.009334,0.002849,0.072370,76.190910,3.881350,0.723702,-142.739365,0.073194,0.000000
55.460003,16.930290,-142.828339,0.009365,0.002862,0.072700,75.309692,3.836458,0.726995,-142.828339,0.073645,0.000000
55.730003,17.232285,-142.828339,0.009369,0.002883,0.073220,76.653030,3.904891,0.732199,-142.828339,0.074096,0.000000
56.000004,17.245316,-142.828339,0.009386,0.002897,0.073593,76.710999,3.907844,0.735927,-142.828339,0.074547,0.000000
56.270004,17.642265,-142.961777,0.009399,0.002918,0.074113,78.476715,3.997794,0.741132,-142.961777,0.074998,0.000000
56.540001,17.489220,-142.961777,0.009416,0.002930,0.074434,77.795937,3.963114,0.744341,-142.961777,0.075449,0.000000
56.810001,17.879097,-142.917297,0.009425,0.002951,0.074963,79.530197,4.051461,0.749633,-142.917297,0.075900,0.000000
57.080002,18.254074,-142.961777,0.009447,0.002972,0.075501,81.198174,4.136433,0.755007,-142.961777,0.076342,0.000000
57.350002,18.355728,-143.006256,0.009468,0.002990,0.075952,81.650360,4.159468,0.759519,-143.006256,0.076793,0.000000
57.620003,18.338226,-143.050735,0.009468,0.003007,0.076368,81.572502,4.155502,0.763678,-143.050735,0.077244,0.000000
57.890003,18.458878,-143.095215,0.009498,0.003023,0.076784,82.109192,4.182841,0.767842,-143.095215,0.077695,0.000000
58.160004,18.546013,-143.139694,0.009503,0.003040,0.077218,82.496788,4.202586,0.772179,-143.139694,0.078146,0.000000
58.430004,18.824547,-143.139694,0.009528,0.003059,0.077686,83.735764,4.265703,0.776861,-143.139694,0.078597,0.000000
58.700005,18.899391,-143.139694,0.009528,0.003073,0.078059,84.068687,4.282663,0.780589,-143.139694,0.079048,0.000000
58.970001,19.382736,-143.228668,0.009554,0.003096,0.078632,86.218719,4.392191,0.786316,-143.228668,0.079499,0.000000
59.240002,19.507851,-143.273148,0.009572,0.003113,0.079074,86.775253,4.420542,0.790736,-143.273148,0.079949,0.000000
59.510002,19.573761,-143.317627,0.009580,0.003130,0.079507,87.068436,4.435478,0.795074,-143.317627,0.080401,0.000000
59.780003,19.376778,-143.273148,0.009589,0.003144,0.079854,86.192215,4.390841,0.798541,-143.273148,0.080843,0.000000
60.050003,19.969597,-143.317627,0.009602,0.003164,0.080366,88.829201,4.525176,0.803658,-143.317627,0.081294,0.000000
60.320004,20.235840,-143.362106,0.009619,0.003183,0.080860,90.013512,4.585507,0.808601,-143.362106,0.081745,0.000000
60.590004,20.168442,-143.406586,0.009632,0.003196,0.081172,89.713707,4.570234,0.811724,-143.406586,0.082196,0.000000
60.860004,20.643585,-143.451065,0.009645,0.003216,0.081693,91.827255,4.677904,0.816928,-143.451065,0.082647,0.000000
61.130001,20.908348,-143.451065,0.009662,0.003236,0.082196,93.004974,4.737899,0.821958,-143.451065,0.083098,0.000000
61.400002,20.772804,-143.540024,0.009688,0.003249,0.082517,92.402046,4.707185,0.825168,-143.540024,0.083549,0.000000
61.670002,21.122086,-143.495544,0.009701,0.003270,0.083063,93.955727,4.786333,0.830629,-143.495544,0.084000,0.000000
61.940002,21.142197,-143.540024,0.009714,0.003285,0.083444,94.045189,4.790890,0.834444,-143.540024,0.084450,0.000000
62.210003,21.538399,-143.628998,0.009727,0.003305,0.083947,95.807579,4.880671,0.839475,-143.628998,0.084893,0.000000
62.480003,21.402107,-143.628998,0.009740,0.003315,0.084208,95.201324,4.849787,0.842079,-143.628998,0.085344,0.000000
62.750004,21.470627,-143.628998,0.009748,0.003329,0.084563,95.506119,4.865314,0.845633,-143.628998,0.085795,0.000000
63.020004,22.772812,-143.628998,0.009774,0.003361,0.085370,101.298523,5.160393,0.853698,-143.628998,0.086246,0.000000
63.290005,22.756432,-143.673477,0.009766,0.003375,0.085725,101.225662,5.156681,0.857252,-143.673477,0.086697,0.000000
63.560001,22.728500,-143.806915,0.009796,0.003391,0.086142,101.101418,5.150352,0.861416,-143.806915,0.087148,0.000000
63.830002,22.911339,-143.762436,0.009804,0.003408,0.086575,101.914726,5.191784,0.865753,-143.762436,0.087599,0.000000
64.100006,23.369728,-143.806915,0.009826,0.003427,0.087035,103.953743,5.295656,0.870348,-143.806915,0.088050,0.000000
64.370003,23.422600,-143.851395,0.009835,0.003442,0.087434,104.188927,5.307637,0.874337,-143.851395,0.088501,0.000000
64.639999,23.575645,-143.895874,0.009843,0.003457,0.087798,104.869705,5.342318,0.877982,-143.895874,0.088951,0.000000
64.910004,24.788467,-143.940353,0.009869,0.003487,0.088570,110.264610,5.617147,0.885700,-143.940353,0.089394,0.000000
65.180000,24.617172,-143.940353,0.009886,0.003500,0.088891,109.502647,5.578331,0.888909,-143.940353,0.089845,0.000000
65.450005,24.851395,-143.940353,0.009912,0.003518,0.089359,110.544525,5.631406,0.893591,-143.940353,0.090295,0.000000
65.720001,24.994385,-143.984833,0.009912,0.003535,0.089793,111.180573,5.663809,0.897928,-143.984833,0.090747,0.000000
65.990005,25.618111,-144.073807,0.009938,0.003555,0.090287,113.955048,5.805147,0.902872,-144.073807,0.091197,0.000000
66.260002,25.739502,-144.118286,0.009934,0.003570,0.090677,114.495026,5.832654,0.906774,-144.118286,0.091649,0.000000
66.530006,25.775993,-144.118286,0.009951,0.003584,0.091024,114.657341,5.840923,0.910241,-144.118286,0.092099,0.000000
66.800003,26.608994,-144.118286,0.009968,0.003607,0.091622,118.362717,6.029684,0.916225,-144.118286,0.092551,0.000000
67.070000,26.919182,-144.073807,0.009994,0.003625,0.092082,119.742500,6.099974,0.920820,-144.073807,0.093001,0.000000
67.340004,27.248360,-144.162766,0.010007,0.003643,0.092542,121.206757,6.174566,0.925418,-144.162766,0.093444,0.000000
67.610001,27.836708,-144.296204,0.010024,0.003663,0.093045,123.823860,6.307889,0.930448,-144.296204,0.093895,0.000000
67.880005,28.082474,-144.296204,0.010037,0.003681,0.093487,124.917084,6.363579,0.934869,-144.296204,0.094346,0.000000
68.150002,28.359146,-144.296204,0.010050,0.003696,0.093869,126.147781,6.426274,0.938688,-144.296204,0.094796,0.000000
68.420006,28.593742,-144.340683,0.010050,0.003712,0.094285,127.191315,6.479434,0.942848,-144.340683,0.095248,0.000000
68.690002,29.310181,-144.340683,0.010054,0.003732,0.094805,130.378189,6.641782,0.948052,-144.340683,0.095698,0.000000
68.960007,29.624092,-144.474136,0.010080,0.003751,0.095265,131.774536,6.712915,0.952647,-144.474136,0.096150,0.000000
69.230003,30.107063,-144.429642,0.010106,0.003769,0.095733,133.922913,6.822358,0.957332,-144.429642,0.096600,0.000000
69.500000,30.370705,-144.429642,0.010128,0.003785,0.096141,135.095642,6.882100,0.961409,-144.429642,0.097052,0.000000
69.770004,31.107628,-144.474136,0.010128,0.003804,0.096626,138.373642,7.049089,0.966265,-144.474136,0.097494,0.000000
70.040001,31.559311,-144.518616,0.010141,0.003822,0.097077,140.382828,7.151442,0.970773,-144.518616,0.097945,0.000000
70.310005,31.849396,-144.563095,0.010162,0.003838,0.097485,141.673187,7.217176,0.974849,-144.563095,0.098396,0.000000
70.580002,32.486153,-144.607574,0.010171,0.003857,0.097970,144.505630,7.361467,0.979705,-144.607574,0.098846,0.000000
70.850006,33.663963,-144.652054,0.010197,0.003880,0.098560,149.744781,7.628363,0.985602,-144.652054,0.099297,0.000000
71.120003,33.554115,-144.652054,0.010192,0.003892,0.098864,149.256165,7.603471,0.988637,-144.652054,0.099748,0.000000
71.390007,33.760033,-144.652054,0.010223,0.003906,0.099220,150.172119,7.650133,0.992195,-144.652054,0.100199,0.000000
71.660004,34.644791,-144.741013,0.010214,0.003931,0.099835,154.107727,7.850622,0.998353,-144.741013,0.100650,0.000000
71.930000,35.325119,-144.829971,0.010231,0.003947,0.100260,157.133972,8.004786,1.002600,-144.829971,0.101101,0.000000
72.200005,35.749992,-144.785492,0.010261,0.003965,0.100720,159.023911,8.101064,1.007198,-144.785492,0.101552,0.000000
72.470001,36.618736,-144.741013,0.010274,0.003982,0.101145,162.888275,8.297924,1.011445,-144.741013,0.101995,0.000000
72.740005,37.201874,-144.829971,0.010279,0.003999,0.101587,165.482193,8.430065,1.015870,-144.829971,0.102445,0.000000
73.010002,37.706436,-144.918945,0.010287,0.004018,0.102055,167.726608,8.544400,1.020552,-144.918945,0.102897,0.000000
73.280006,38.333511,-144.963425,0.010300,0.004034,0.102463,170.515976,8.686498,1.024628,-144.963425,0.103347,0.000000
73.550003,38.903992,-144.874451,0.010335,0.004049,0.102844,173.053604,8.815770,1.028443,-144.874451,0.103798,0.000000
73.820000,39.710922,-144.963425,0.010339,0.004068,0.103339,176.643005,8.998624,1.033386,-144.963425,0.104249,0.000000
74.090004,39.887794,-145.007904,0.010356,0.004080,0.103633,177.429764,9.038704,1.036335,-145.007904,0.104700,0.000000
74.360001,40.761009,-145.096863,0.010361,0.004102,0.104180,181.314026,9.236576,1.041800,-145.096863,0.105151,0.000000
74.630005,41.938454,-145.052383,0.010378,0.004125,0.104770,186.551559,9.503389,1.047697,-145.052383,0.105602,0.000000
74.900002,42.578186,-145.141342,0.010382,0.004141,0.105177,189.397232,9.648355,1.051773,-145.141342,0.106044,0.000000
75.170006,43.212708,-145.141342,0.010404,0.004158,0.105602,192.219727,9.792139,1.056024,-145.141342,0.106496,0.000000
75.440002,44.224075,-145.096863,0.010399,0.004177,0.106088,196.718506,10.021319,1.060880,-145.096863,0.106946,0.000000
75.710007,45.185913,-145.185822,0.010404,0.004195,0.106565,200.996979,10.239274,1.065649,-145.185822,0.107398,0.000000
75.980003,45.437637,-145.274780,0.010442,0.004206,0.106834,202.116699,10.296316,1.068336,-145.274780,0.107848,0.000000
76.250000,46.361122,-145.274780,0.010455,0.004227,0.107371,206.224564,10.505581,1.073714,-145.274780,0.108299,0.000000
76.520004,47.569092,-145.274780,0.010460,0.004246,0.107848,211.597885,10.779310,1.078483,-145.274780,0.108750,0.000000
76.790001,47.980568,-145.319260,0.010468,0.004260,0.108204,213.428223,10.872552,1.082037,-145.319260,0.109201,0.000000
77.060005,49.026932,-145.363754,0.010473,0.004280,0.108715,218.082687,11.109662,1.087154,-145.363754,0.109652,0.000000
77.330002,49.679703,-145.408234,0.010499,0.004296,0.109114,220.986359,11.257582,1.091144,-145.408234,0.110094,0.000000
77.600006,50.860123,-145.408234,0.010494,0.004316,0.109635,226.237122,11.525068,1.096348,-145.408234,0.110545,0.000000
77.870003,51.519966,-145.452713,0.010529,0.004329,0.109956,229.172256,11.674591,1.099557,-145.452713,0.110996,0.000000
78.140007,52.185394,-145.452713,0.010524,0.004347,0.110415,232.132233,11.825379,1.104152,-145.452713,0.111447,0.000000
78.410004,54.065506,-145.541672,0.010520,0.004370,0.111005,240.495377,12.251418,1.110049,-145.541672,0.111898,0.000000
78.680000,54.781578,-145.630630,0.010550,0.004388,0.111465,243.680634,12.413683,1.114648,-145.630630,0.112349,0.000000
78.950005,55.822731,-145.586151,0.010563,0.004405,0.111881,248.311905,12.649612,1.118807,-145.586151,0.112800,0.000000
79.220001,56.693336,-145.586151,0.010576,0.004421,0.112297,252.184555,12.846893,1.122971,-145.586151,0.113251,0.000000
79.490005,57.660393,-145.586151,0.010576,0.004437,0.112696,256.486237,13.066031,1.126960,-145.586151,0.113702,0.000000
79.760002,58.813629,-145.719589,0.010598,0.004457,0.113199,261.616089,13.327359,1.131990,-145.719589,0.114153,0.000000
80.030006,59.767647,-145.719589,0.010598,0.004472,0.113581,265.859772,13.543543,1.135805,-145.719589,0.114595,0.000000
80.300003,61.106323,-145.719589,0.010615,0.004494,0.114136,271.814514,13.846890,1.141358,-145.719589,0.115046,0.000000
80.570007,62.210037,-145.719589,0.010632,0.004511,0.114587,276.724060,14.096996,1.145866,-145.719589,0.115497,0.000000
80.840004,63.180809,-145.764084,0.010624,0.004528,0.115003,281.042267,14.316976,1.150029,-145.764084,0.115948,0.000000
81.110001,63.759102,-145.853043,0.010628,0.004539,0.115298,283.614655,14.448019,1.152977,-145.853043,0.116399,0.000000
81.380005,64.791695,-145.942001,0.010658,0.004559,0.115809,288.207855,14.682008,1.158095,-145.942001,0.116850,0.000000
81.650002,66.507957,-145.897522,0.010654,0.004581,0.116347,295.842163,15.070918,1.163473,-145.897522,0.117301,0.000000
81.920006,67.334633,-145.897522,0.010693,0.004594,0.116694,299.519409,15.258245,1.166940,-145.897522,0.117752,0.000000
82.190002,67.016991,-145.853043,0.010688,0.004590,0.116590,298.106476,15.186268,1.165899,-145.853043,0.116815,0.000000
82.460007,66.384331,-145.986481,0.010693,0.004588,0.116538,295.292236,15.042904,1.165380,-145.986481,0.116590,0.000000
82.730003,65.819435,-145.986481,0.010684,0.004586,0.116495,292.779480,14.914898,1.164945,-145.986481,0.116590,0.000000
83.000008,65.326424,-146.075439,0.010697,0.004586,0.116486,290.586456,14.803180,1.164858,-146.075439,0.116590,0.000000
83.270004,64.890739,-146.075439,0.010688,0.004586,0.116477,288.648437,14.704452,1.164771,-146.075439,0.116590,0.000000
83.540001,64.536995,-146.119919,0.010697,0.004585,0.116468,287.074890,14.624292,1.164684,-146.119919,0.116590,0.000000
83.810005,64.179146,-146.164398,0.010693,0.004585,0.116460,285.483093,14.543202,1.164597,-146.164398,0.116590,0.000000
84.080002,63.877525,-146.253372,0.010697,0.004585,0.116460,284.141418,14.474854,1.164597,-146.253372,0.116590,0.000000
84.350006,63.588936,-146.253372,0.010705,0.004585,0.116460,282.857727,14.409458,1.164597,-146.253372,0.116590,0.000000
84.620003,63.327904,-146.208893,0.010697,0.004585,0.116460,281.696594,14.350308,1.164597,-146.208893,0.116590,0.000000
84.890007,63.096275,-146.297852,0.010705,0.004585,0.116451,280.666260,14.297821,1.164510,-146.297852,0.116590,0.000000
85.160004,62.885147,-146.342331,0.010701,0.004585,0.116451,279.727112,14.249978,1.164510,-146.342331,0.116590,0.000000
85.430000,62.686676,-146.342331,0.010701,0.004585,0.116451,278.844269,14.205004,1.164510,-146.342331,0.116590,0.000000
85.700005,62.492668,-146.386810,0.010714,0.004585,0.116451,277.981262,14.161040,1.164510,-146.386810,0.116590,0.000000
85.970001,62.319138,-146.431290,0.010714,0.004585,0.116451,277.209381,14.121718,1.164510,-146.431290,0.116590,0.000000
86.240005,62.161629,-146.431290,0.010718,0.004585,0.116451,276.508728,14.086026,1.164510,-146.431290,0.116590,0.000000
86.510002,62.009331,-146.475769,0.010710,0.004585,0.116451,275.831268,14.051515,1.164510,-146.475769,0.116590,0.000000
86.780006,61.856651,-146.520248,0.010714,0.004585,0.116451,275.152130,14.016917,1.164510,-146.520248,0.116590,0.000000
87.050003,61.711800,-146.520248,0.010731,0.004585,0.116451,274.507782,13.984094,1.164510,-146.520248,0.116590,0.000000
87.320007,61.587433,-146.564728,0.010731,0.004585,0.116451,273.954590,13.955912,1.164510,-146.564728,0.116590,0.000000
87.590004,61.471992,-146.609207,0.010723,0.004585,0.116451,273.441071,13.929752,1.164510,-146.609207,0.116590,0.000000
87.860001,61.364006,-146.609207,0.010727,0.004585,0.116451,272.960724,13.905283,1.164510,-146.609207,0.116590,0.000000
88.130005,61.241493,-146.698181,0.010718,0.004585,0.116451,272.415771,13.877521,1.164510,-146.698181,0.116590,0.000000
88.400002,61.123451,-146.787140,0.010727,0.004585,0.116451,271.890686,13.850772,1.164510,-146.787140,0.116590,0.000000
88.670006,61.033340,-146.742661,0.010723,0.004585,0.116451,271.489868,13.830352,1.164510,-146.742661,0.116590,0.000000
88.940002,60.931679,-146.831619,0.010714,0.004585,0.116451,271.037659,13.807316,1.164510,-146.831619,0.116590,0.000000
89.210007,60.834862,-146.787140,0.010723,0.004585,0.116451,270.606995,13.785377,1.164510,-146.787140,0.116590,0.000000
89.480003,60.732834,-146.831619,0.010718,0.004585,0.116451,270.153137,13.762257,1.164510,-146.831619,0.116590,0.000000
89.750008,60.648308,-146.920578,0.010723,0.004585,0.116451,269.777161,13.743103,1.164510,-146.920578,0.116590,0.000000
90.020004,60.567871,-146.831619,0.010736,0.004585,0.116451,269.419342,13.724875,1.164510,-146.831619,0.116590,0.000000
90.290001,60.494888,-146.876099,0.010731,0.004585,0.116451,269.094696,13.708338,1.164510,-146.876099,0.116590,0.000000
90.560005,60.408127,-146.920578,0.010723,0.004585,0.116451,268.708771,13.688677,1.164510,-146.920578,0.116590,0.000000
90.830002,60.340355,-147.009537,0.010731,0.004585,0.116451,268.407318,13.673320,1.164510,-147.009537,0.116590,0.000000
91.100006,60.258057,-147.009537,0.010718,0.004585,0.116451,268.041229,13.654671,1.164510,-147.009537,0.116590,0.000000
91.370003,60.176514,-147.054031,0.010718,0.004585,0.116451,267.678497,13.636193,1.164510,-147.054031,0.116590,0.000000
91.640007,60.115814,-147.098511,0.010718,0.004585,0.116451,267.408508,13.622438,1.164510,-147.098511,0.116590,0.000000
91.910004,60.062935,-147.054031,0.010731,0.004585,0.116451,267.173279,13.610456,1.164510,-147.054031,0.116590,0.000000
92.180008,59.970215,-147.098511,0.010736,0.004585,0.116451,266.760834,13.589445,1.164510,-147.098511,0.116590,0.000000
92.450005,59.899834,-147.187469,0.010718,0.004585,0.116451,266.447754,13.573497,1.164510,-147.187469,0.116590,0.000000
92.720001,59.848450,-147.231949,0.010723,0.004585,0.116451,266.219208,13.561852,1.164510,-147.231949,0.116590,0.000000
92.990005,59.784775,-147.231949,0.010731,0.004585,0.116451,265.935974,13.547423,1.164510,-147.231949,0.116590,0.000000
93.260002,59.709930,-147.276428,0.010740,0.004585,0.116451,265.603027,13.530464,1.164510,-147.276428,0.116590,0.000000
93.530006,59.663010,-147.276428,0.010723,0.004585,0.116451,265.394318,13.519832,1.164510,-147.276428,0.116590,0.000000
93.800003,59.603058,-147.365387,0.010723,0.004585,0.116451,265.127655,13.506246,1.164510,-147.365387,0.116590,0.000000
94.070007,59.549438,-147.409866,0.010731,0.004585,0.116451,264.889130,13.494096,1.164510,-147.409866,0.116590,0.000000
94.340004,59.504005,-147.409866,0.010740,0.004585,0.116451,264.687042,13.483800,1.164510,-147.409866,0.116590,0.000000
94.610008,59.439957,-147.409866,0.010731,0.004585,0.116451,264.402130,13.469287,1.164510,-147.409866,0.116590,0.000000
94.880005,59.375534,-147.454346,0.010731,0.004585,0.116451,264.115570,13.454688,1.164510,-147.454346,0.116590,0.000000
95.150002,59.328621,-147.454346,0.010736,0.004585,0.116451,263.906891,13.444057,1.164510,-147.454346,0.116590,0.000000
95.420006,59.284676,-147.498840,0.010731,0.004585,0.116451,263.711395,13.434099,1.164510,-147.498840,0.116590,0.000000
95.690002,59.241486,-147.543320,0.010744,0.004585,0.116451,263.519287,13.424313,1.164510,-147.543320,0.116590,0.000000
95.960007,59.186745,-147.543320,0.010740,0.004585,0.116451,263.275787,13.411908,1.164510,-147.543320,0.116590,0.000000
96.230003,59.152115,-147.543320,0.010740,0.004585,0.116451,263.121735,13.404060,1.164510,-147.543320,0.116590,0.000000
96.500008,59.104820,-147.632278,0.010723,0.004585,0.116451,262.911377,13.393344,1.164510,-147.632278,0.116590,0.000000
96.770004,59.051949,-147.676758,0.010736,0.004585,0.116451,262.676178,13.381363,1.164510,-147.676758,0.116590,0.000000
97.040001,59.018059,-147.676758,0.010731,0.004585,0.116451,262.525452,13.373684,1.164510,-147.676758,0.116590,0.000000
97.310005,58.971886,-147.721237,0.010727,0.004585,0.116451,262.320038,13.363220,1.164510,-147.721237,0.116590,0.000000
97.580002,58.929810,-147.765717,0.010749,0.004585,0.116451,262.132874,13.353685,1.164510,-147.765717,0.116590,0.000000
97.850006,58.888100,-147.854675,0.010740,0.004585,0.116451,261.947357,13.344234,1.164510,-147.854675,0.116590,0.000000
98.120003,58.851234,-147.810196,0.010753,0.004585,0.116451,261.783356,13.335880,1.164510,-147.810196,0.116590,0.000000
98.390007,58.819954,-147.810196,0.010731,0.004585,0.116451,261.644226,13.328792,1.164510,-147.810196,0.116590,0.000000
98.660004,58.784584,-147.810196,0.010744,0.004585,0.116451,261.486877,13.320777,1.164510,-147.810196,0.116590,0.000000
98.930008,58.731331,-147.899155,0.010718,0.004585,0.116451,261.250000,13.308709,1.164510,-147.899155,0.116590,0.000000
99.200005,58.702660,-147.988129,0.010718,0.004585,0.116451,261.122467,13.302213,1.164510,-147.988129,0.116590,0.000000
99.470001,58.666168,-148.032608,0.010749,0.004585,0.116451,260.960144,13.293944,1.164510,-148.032608,0.116590,0.000000
99.740005,58.646057,-147.988129,0.010749,0.004585,0.116451,260.870697,13.289387,1.164510,-147.988129,0.116590,0.000000
100.010002,58.604355,-147.988129,0.010736,0.004585,0.116451,260.685181,13.279936,1.164510,-147.988129,0.116590,0.000000
100.280006,58.556686,-148.077087,0.010749,0.004585,0.116451,260.473145,13.269135,1.164510,-148.077087,0.116590,0.000000
100.550003,58.517960,-148.121567,0.010740,0.004585,0.116451,260.300873,13.260360,1.164510,-148.121567,0.116590,0.000000
100.820007,58.509399,-148.166046,0.010744,0.004585,0.116451,260.262817,13.258419,1.164510,-148.166046,0.116590,0.000000
101.090004,58.473282,-148.166046,0.010736,0.004585,0.116451,260.102142,13.250236,1.164510,-148.166046,0.116590,0.000000
101.360008,58.452049,-148.255005,0.010740,0.004585,0.116451,260.007690,13.245424,1.164510,-148.255005,0.116590,0.000000
101.630005,58.417053,-148.210526,0.010731,0.004585,0.116451,259.852020,13.237494,1.164510,-148.210526,0.116590,0.000000
101.900002,58.376831,-148.299484,0.010736,0.004585,0.116451,259.673126,13.228379,1.164510,-148.299484,0.116590,0.000000
102.170006,58.346298,-148.299484,0.010731,0.004585,0.116451,259.537292,13.221460,1.164510,-148.299484,0.116590,0.000000
102.440002,58.326935,-148.299484,0.010740,0.004585,0.116451,259.451172,13.217072,1.164510,-148.299484,0.116590,0.000000
102.710007,58.293793,-148.299484,0.010749,0.004585,0.116451,259.303741,13.209562,1.164510,-148.299484,0.116590,0.000000
102.980003,58.266609,-148.299484,0.010736,0.004585,0.116451,259.182831,13.203403,1.164510,-148.299484,0.116590,0.000000
103.250008,58.243523,-148.432938,0.010723,0.004585,0.116451,259.080139,13.198171,1.164510,-148.432938,0.116590,0.000000
103.520004,58.223419,-148.432938,0.010744,0.004585,0.116451,258.990692,13.193615,1.164510,-148.432938,0.116590,0.000000
103.790009,58.188042,-148.432938,0.010757,0.004585,0.116451,258.833344,13.185598,1.164510,-148.432938,0.116590,0.000000
104.060005,58.173889,-148.432938,0.010740,0.004585,0.116451,258.770386,13.182391,1.164510,-148.432938,0.116590,0.000000
104.330002,58.144844,-148.477417,0.010749,0.004585,0.116451,258.641174,13.175810,1.164510,-148.477417,0.116590,0.000000
104.600006,58.110962,-148.610855,0.010740,0.004585,0.116451,258.490479,13.168132,1.164510,-148.610855,0.116590,0.000000
104.870003,58.084518,-148.655334,0.010740,0.004585,0.116451,258.372833,13.162140,1.164510,-148.655334,0.116590,0.000000
105.140007,58.056221,-148.566376,0.010736,0.004585,0.116451,258.246979,13.155728,1.164510,-148.566376,0.116590,0.000000
105.410004,58.037231,-148.610855,0.010744,0.004585,0.116451,258.162506,13.151425,1.164510,-148.610855,0.116590,0.000000
105.680008,58.009674,-148.655334,0.010731,0.004585,0.116451,258.039917,13.145180,1.164510,-148.655334,0.116590,0.000000
105.950005,58.001106,-148.744293,0.010744,0.004585,0.116451,258.001801,13.143239,1.164510,-148.744293,0.116590,0.000000
106.220009,57.967972,-148.788788,0.010736,0.004585,0.116451,257.854431,13.135730,1.164510,-148.788788,0.116590,0.000000
106.490005,57.932220,-148.699814,0.010749,0.004585,0.116451,257.695374,13.127628,1.164510,-148.699814,0.116590,0.000000
106.760002,57.902428,-148.788788,0.010753,0.004585,0.116451,257.562866,13.120878,1.164510,-148.788788,0.116590,0.000000
107.030006,57.883064,-148.833267,0.010736,0.004585,0.116451,257.476715,13.116489,1.164510,-148.833267,0.116590,0.000000
107.300003,57.867798,-148.833267,0.010731,0.004585,0.116451,257.408813,13.113030,1.164510,-148.833267,0.116590,0.000000
107.570007,57.856628,-148.922226,0.010744,0.004585,0.116451,257.359131,13.110499,1.164510,-148.922226,0.116590,0.000000
107.840004,57.837639,-148.922226,0.010762,0.004585,0.116451,257.274658,13.106196,1.164510,-148.922226,0.116590,0.000000
108.110008,57.794067,-148.966705,0.010740,0.004585,0.116451,257.080841,13.096323,1.164510,-148.966705,0.116590,0.000000
108.380005,57.784019,-149.011185,0.010749,0.004585,0.116451,257.036163,13.094046,1.164510,-149.011185,0.116590,0.000000
108.650002,57.744919,-149.055664,0.010744,0.004585,0.116451,256.862213,13.085185,1.164510,-149.055664,0.116590,0.000000
108.920006,57.748268,-149.100143,0.010749,0.004585,0.116451,256.877136,13.085944,1.164510,-149.100143,0.116590,0.000000
109.190002,57.712151,-149.055664,0.010762,0.004585,0.116451,256.716461,13.077760,1.164510,-149.055664,0.116590,0.000000
109.460007,57.700233,-149.055664,0.010744,0.004585,0.116451,256.663452,13.075060,1.164510,-149.055664,0.116590,0.000000
109.730003,57.676399,-149.144623,0.010753,0.004585,0.116451,256.557434,13.069658,1.164510,-149.144623,0.116590,0.000000
110.000008,57.648102,-149.233597,0.010740,0.004585,0.116451,256.431549,13.063247,1.164510,-149.233597,0.116590,0.000000
110.270004,57.626503,-149.233597,0.010749,0.004585,0.116451,256.335480,13.058352,1.164510,-149.233597,0.116590,0.000000
110.540009,57.589264,-149.233597,0.010744,0.004585,0.116451,256.169830,13.049913,1.164510,-149.233597,0.116590,0.000000
110.810005,57.596710,-149.278076,0.010744,0.004585,0.116451,256.202972,13.051601,1.164510,-149.278076,0.116590,0.000000
111.080002,57.573624,-149.322556,0.010718,0.004585,0.116451,256.100281,13.046370,1.164510,-149.322556,0.116590,0.000000
111.350006,57.555756,-149.322556,0.010749,0.004585,0.116451,256.020782,13.042320,1.164510,-149.322556,0.116590,0.000000
111.620003,57.529312,-149.411514,0.010744,0.004585,0.116451,255.903168,13.036329,1.164510,-149.411514,0.116590,0.000000
111.890007,57.491707,-149.367035,0.010749,0.004585,0.116451,255.735886,13.027807,1.164510,-149.367035,0.116590,0.000000
112.160004,57.491707,-149.367035,0.010766,0.004585,0.116451,255.735886,13.027807,1.164510,-149.367035,0.116590,0.000000
112.430008,57.479042,-149.455994,0.010749,0.004585,0.116451,255.679550,13.024938,1.164510,-149.455994,0.116590,0.000000
112.500008,57.462662,-149.455994,0.010740,0.004585,0.116451,255.606689,13.021225,1.164510,-149.455994,0.116590,0.000000