File: Data/compression 6/AutoNoheating-10-6-day1-2-240228_02282024_201646.csv
Time (sec),S:Load (lbs),S:HL1 (DIM),S:LVDT (in),S:Position (in),Ch:Position (mm),Ch:Load (N),Ch:Stress (MPa),Ch:Strain (mm/mm),Ch:HL1 (DIM),Set Point (),Cycles ()
0.010000,-0.000000,-122.633980,0.000013,-0.000000,-0.000000,-0.000000,-0.000000,-0.000000,-122.633980,-0.000147,0.000000
0.240000,-0.000000,-122.633980,0.000009,-0.000000,-0.000000,-0.000000,-0.000000,-0.000000,-122.633980,-0.000147,0.000000
0.470000,-0.019363,-122.589500,0.000000,0.000071,0.001795,-0.086133,-0.004388,0.017952,-122.589500,0.002420,0.000000
0.700000,-0.005219,-122.633980,0.000034,0.000208,0.005290,-0.023213,-0.001183,0.052901,-122.633980,0.006253,0.000000
0.930000,0.202194,-122.678467,0.000168,0.000361,0.009158,0.899405,0.045818,0.091579,-122.678467,0.010069,0.000000
1.160000,0.347046,-122.678467,0.000306,0.000503,0.012783,1.543737,0.078642,0.127831,-122.678467,0.013902,0.000000
1.390000,0.493393,-122.678467,0.000453,0.000646,0.016408,2.194721,0.111804,0.164079,-122.678467,0.017735,0.000000
1.620000,0.668777,-122.633980,0.000604,-0.000006,-0.000148,2.974871,0.151547,-0.001476,-122.633980,-0.000052,0.000000
1.850000,0.550362,-122.678467,0.000608,-0.000008,-0.000191,2.448131,0.124714,-0.001908,-122.678467,-0.000052,0.000000
2.080000,0.529137,-122.678467,0.000608,-0.000008,-0.000191,2.353717,0.119904,-0.001908,-122.678467,-0.000052,0.000000
2.310000,0.517967,-122.678467,0.000617,-0.000008,-0.000191,2.304033,0.117373,-0.001908,-122.678467,0.000286,0.000000
2.540000,0.510147,-122.678467,0.000608,-0.000008,-0.000191,2.269248,0.115601,-0.001908,-122.678467,0.000668,0.000000
2.770000,0.577919,-122.678467,0.000617,0.000014,0.000347,2.570712,0.130958,0.003471,-122.678467,0.001049,0.000000
3.000000,0.618507,-122.589500,0.000625,0.000028,0.000711,2.751258,0.140156,0.007112,-122.589500,0.001431,0.000000
3.230000,0.616272,-122.678467,0.000638,0.000040,0.001015,2.741315,0.139649,0.010147,-122.678467,0.001821,0.000000
3.460000,0.634895,-122.767426,0.000651,0.000054,0.001379,2.824156,0.143869,0.013788,-122.767426,0.002203,0.000000
3.690000,0.674736,-122.678467,0.000664,0.000071,0.001804,3.001376,0.152897,0.018039,-122.678467,0.002584,0.000000
3.920000,0.708992,-122.678467,0.000681,0.000083,0.002107,3.153754,0.160660,0.021074,-122.678467,0.002966,0.000000
4.150000,0.742882,-122.678467,0.000694,0.000096,0.002428,3.304503,0.168339,0.024284,-122.678467,0.003347,0.000000
4.380000,0.788681,-122.722946,0.000716,0.000111,0.002819,3.508229,0.178718,0.028186,-122.722946,0.003738,0.000000
4.610000,0.820335,-122.767426,0.000724,0.000129,0.003269,3.649034,0.185891,0.032694,-122.767426,0.004119,0.000000
4.840000,0.837090,-122.722946,0.000746,0.000143,0.003625,3.723560,0.189687,0.036252,-122.722946,0.004501,0.000000
5.070000,0.840813,-122.767426,0.000776,0.000164,0.004163,3.740122,0.190531,0.041626,-122.767426,0.004883,0.000000
5.300000,0.836349,-122.767426,0.000785,0.000172,0.004371,3.720268,0.189520,0.043708,-122.767426,0.005264,0.000000
5.530000,0.886986,-122.767426,0.000798,0.000188,0.004778,3.945510,0.200994,0.047784,-122.767426,0.005654,0.000000
5.760000,0.907845,-122.856384,0.000811,0.000203,0.005151,4.038294,0.205721,0.051512,-122.856384,0.006036,0.000000
5.990000,0.933907,-122.767426,0.000823,0.000221,0.005619,4.154224,0.211626,0.056194,-122.767426,0.006417,0.000000
6.220000,0.968536,-122.767426,0.000828,0.000231,0.005871,4.308265,0.219473,0.058711,-122.767426,0.006799,0.000000
6.450000,0.992371,-122.811905,0.000845,0.000246,0.006253,4.414285,0.224874,0.062526,-122.811905,0.007181,0.000000
6.680000,1.043755,-122.767426,0.000862,0.000267,0.006790,4.642852,0.236518,0.067905,-122.767426,0.007571,0.000000
6.910000,1.071312,-122.856384,0.000888,0.000283,0.007189,4.765434,0.242763,0.071894,-122.856384,0.007952,0.000000
7.140000,1.044128,-122.856384,0.000901,0.000294,0.007476,4.644515,0.236603,0.074755,-122.856384,0.008334,0.000000
7.370000,1.089561,-122.811905,0.000931,0.000312,0.007935,4.846611,0.246898,0.079350,-122.811905,0.008715,0.000000
7.600000,1.124191,-122.767426,0.000940,0.000327,0.008317,5.000653,0.254745,0.083165,-122.767426,0.009097,0.000000
7.830000,1.163292,-122.856384,0.000949,0.000342,0.008690,5.174581,0.263606,0.086897,-122.856384,0.009488,0.000000
8.060000,1.168877,-122.856384,0.000957,0.000351,0.008906,5.199423,0.264871,0.089062,-122.856384,0.009869,0.000000
8.290000,1.193077,-122.811905,0.000979,0.000364,0.009245,5.307072,0.270355,0.092446,-122.811905,0.010251,0.000000
8.520000,1.287659,-122.811905,0.001005,0.000390,0.009912,5.727792,0.291788,0.099123,-122.811905,0.010632,0.000000
8.750000,1.308517,-122.856384,0.001030,0.000406,0.010320,5.820576,0.296514,0.103199,-122.856384,0.011022,0.000000
8.980000,1.248566,-122.900871,0.001022,0.000418,0.010606,5.553897,0.282929,0.106060,-122.900871,0.011404,0.000000
9.210000,1.281700,-122.900871,0.001043,0.000429,0.010892,5.701287,0.290437,0.108922,-122.900871,0.011786,0.000000
9.440001,1.332344,-122.856384,0.001056,0.000445,0.011300,5.926562,0.301913,0.112998,-122.856384,0.012167,0.000000
9.670000,1.378517,-122.811905,0.001087,0.000463,0.011751,6.131950,0.312376,0.117510,-122.811905,0.012549,0.000000
9.900001,1.381874,-122.945351,0.001091,0.000473,0.012002,6.146883,0.313137,0.120023,-122.945351,0.012939,0.000000
10.130000,1.445175,-122.900871,0.001108,0.000489,0.012410,6.428460,0.327481,0.124099,-122.900871,0.013321,0.000000
10.360001,1.502144,-122.900871,0.001125,0.000511,0.012974,6.681870,0.340391,0.129739,-122.900871,0.013702,0.000000
10.590000,1.517418,-122.945351,0.001151,0.000526,0.013355,6.749812,0.343852,0.133554,-122.945351,0.014084,0.000000
10.820001,1.495445,-122.900871,0.001143,0.000538,0.013668,6.652073,0.338873,0.136676,-122.900871,0.014465,0.000000
11.050000,1.534172,-122.945351,0.001181,0.000551,0.013997,6.824338,0.347648,0.139969,-122.945351,0.014856,0.000000
11.280001,1.552048,-122.900871,0.001181,0.000567,0.014405,6.903853,0.351699,0.144046,-122.900871,0.015237,0.000000
11.510000,1.605667,-122.945351,0.001203,0.000582,0.014795,7.142364,0.363849,0.147948,-122.945351,0.015619,0.000000
11.740001,1.624657,-122.989830,0.001199,0.000595,0.015107,7.226834,0.368152,0.151070,-122.989830,0.016000,0.000000
11.970000,1.671204,-122.945351,0.001216,0.000609,0.015480,7.433885,0.378700,0.154798,-122.945351,0.016382,0.000000
12.200001,1.674187,-122.945351,0.001246,0.000621,0.015783,7.447155,0.379376,0.157834,-122.945351,0.016772,0.000000
12.430000,1.786270,-122.989830,0.001268,0.000646,0.016408,7.945726,0.404775,0.164079,-122.989830,0.017154,0.000000
12.660001,1.754990,-122.989830,0.001276,0.000659,0.016729,7.806584,0.397686,0.167289,-122.989830,0.017535,0.000000
12.890000,1.746796,-122.945351,0.001298,0.000673,0.017102,7.770135,0.395830,0.171017,-122.945351,0.017917,0.000000
13.120001,1.771370,-122.989830,0.001306,0.000685,0.017397,7.879447,0.401398,0.173965,-122.989830,0.018298,0.000000
13.350000,1.851059,-122.989830,0.001328,0.000703,0.017865,8.233921,0.419456,0.178647,-122.989830,0.018689,0.000000
13.580001,1.909523,-123.078789,0.001341,0.000720,0.018290,8.493982,0.432704,0.182897,-123.078789,0.019070,0.000000
13.810000,1.884575,-123.034309,0.001337,0.000729,0.018524,8.383008,0.427051,0.185240,-123.034309,0.019452,0.000000
14.040001,1.953094,-123.034309,0.001384,0.000744,0.018897,8.687799,0.442578,0.188968,-123.034309,0.019834,0.000000
14.270000,1.995171,-122.989830,0.001388,0.000763,0.019382,8.874962,0.452112,0.193824,-122.989830,0.020215,0.000000
14.500001,2.026077,-123.034309,0.001388,0.000780,0.019816,9.012442,0.459116,0.198162,-123.034309,0.020605,0.000000
14.730000,1.991447,-123.034309,0.001418,0.000795,0.020189,8.858400,0.451268,0.201890,-123.034309,0.020987,0.000000
14.960001,1.988838,-123.123276,0.001427,0.000805,0.020449,8.846794,0.450677,0.204490,-123.123276,0.021368,0.000000
15.190001,2.045067,-123.078789,0.001449,0.000821,0.020848,9.096911,0.463419,0.208480,-123.078789,0.021750,0.000000
15.420001,2.183220,-123.078789,0.001453,0.000843,0.021412,9.711447,0.494725,0.214119,-123.078789,0.022131,0.000000
15.650001,2.154175,-123.078789,0.001479,0.000853,0.021663,9.582248,0.488143,0.216632,-123.078789,0.022522,0.000000
15.880001,2.116562,-123.078789,0.001479,0.000860,0.021845,9.414938,0.479620,0.218453,-123.078789,0.022904,0.000000
16.110001,2.158264,-123.034309,0.001496,0.000878,0.022296,9.600438,0.489070,0.222964,-123.034309,0.023285,0.000000
16.340000,2.343338,-123.078789,0.001522,0.000905,0.022982,10.423688,0.531008,0.229815,-123.078789,0.023667,0.000000
16.570002,2.250618,-123.034309,0.001539,0.000914,0.023207,10.011249,0.509997,0.232071,-123.034309,0.024048,0.000000
16.800001,2.250618,-123.078789,0.001552,0.000928,0.023580,10.011249,0.509997,0.235799,-123.078789,0.024438,0.000000
17.030001,2.280777,-123.123276,0.001561,0.000943,0.023953,10.145403,0.516831,0.239527,-123.123276,0.024820,0.000000
17.260000,2.396584,-123.123276,0.001574,0.000960,0.024386,10.660536,0.543074,0.243865,-123.123276,0.025202,0.000000
17.490002,2.389885,-123.078789,0.001591,0.000974,0.024742,10.630739,0.541556,0.247419,-123.078789,0.025583,0.000000
17.720001,2.432709,-123.123276,0.001625,0.000988,0.025089,10.821229,0.551260,0.250889,-123.123276,0.025973,0.000000
17.950001,2.457657,-123.123276,0.001638,0.001000,0.025410,10.932203,0.556913,0.254099,-123.123276,0.026355,0.000000
18.180000,2.585381,-123.167755,0.001651,0.001026,0.026069,11.500347,0.585856,0.260688,-123.167755,0.026736,0.000000
18.410002,2.528778,-123.123276,0.001660,0.001038,0.026372,11.248567,0.573029,0.263724,-123.123276,0.027118,0.000000
18.640001,2.512398,-123.167755,0.001694,0.001053,0.026736,11.175703,0.569317,0.267365,-123.167755,0.027500,0.000000
18.870001,2.497124,-123.123276,0.001707,0.001063,0.026997,11.107761,0.565856,0.269969,-123.123276,0.027890,0.000000
19.100000,2.604370,-123.167755,0.001712,0.001082,0.027474,11.584817,0.590159,0.274738,-123.167755,0.028272,0.000000
19.330002,2.678848,-123.212234,0.001733,0.001098,0.027890,11.916112,0.607036,0.278901,-123.212234,0.028653,0.000000
19.560001,2.691132,-123.167755,0.001738,0.001109,0.028159,11.970751,0.609819,0.281589,-123.167755,0.029035,0.000000
19.790001,2.702301,-123.123276,0.001750,0.001121,0.028471,12.020435,0.612350,0.284711,-123.123276,0.029416,0.000000
20.020000,2.753319,-123.212234,0.001768,0.001135,0.028818,12.247374,0.623911,0.288178,-123.212234,0.029806,0.000000
20.250002,2.856094,-123.212234,0.001798,0.001156,0.029364,12.704542,0.647200,0.293644,-123.212234,0.030188,0.000000
20.480001,2.824814,-123.212234,0.001802,0.001169,0.029694,12.565399,0.640112,0.296936,-123.212234,0.030570,0.000000
20.710001,2.838593,-123.212234,0.001815,0.001183,0.030049,12.626690,0.643234,0.300494,-123.212234,0.030951,0.000000
20.940001,2.913071,-123.123276,0.001824,0.001203,0.030552,12.957986,0.660111,0.305524,-123.123276,0.031333,0.000000
21.170000,2.938019,-123.212234,0.001850,0.001219,0.030951,13.068960,0.665765,0.309514,-123.212234,0.031723,0.000000
21.400002,2.948067,-123.301193,0.001871,0.001231,0.031255,13.113656,0.668041,0.312549,-123.301193,0.032105,0.000000
21.630001,2.938759,-123.256714,0.001876,0.001240,0.031506,13.072252,0.665932,0.315062,-123.256714,0.032486,0.000000
21.860001,2.964828,-123.212234,0.001897,0.001252,0.031810,13.188216,0.671840,0.318098,-123.212234,0.032868,0.000000
22.090000,3.165535,-123.256714,0.001906,0.001277,0.032434,14.081003,0.717321,0.324343,-123.256714,0.033250,0.000000
22.320002,3.142075,-123.256714,0.001932,0.001291,0.032798,13.976645,0.712004,0.327984,-123.256714,0.033640,0.000000
22.550001,3.157341,-123.301193,0.001949,0.001309,0.033250,14.044554,0.715464,0.332495,-123.301193,0.034021,0.000000
22.780001,3.142448,-123.301193,0.001962,0.001321,0.033544,13.978309,0.712089,0.335444,-123.301193,0.034403,0.000000
23.010000,3.096275,-123.256714,0.001979,0.001332,0.033831,13.772921,0.701626,0.338305,-123.256714,0.034784,0.000000
23.240002,3.253418,-123.301193,0.002001,0.001352,0.034334,14.471926,0.737235,0.343335,-123.301193,0.035166,0.000000
23.470001,3.226234,-123.301193,0.002009,0.001364,0.034654,14.351007,0.731075,0.346545,-123.301193,0.035556,0.000000
23.700001,3.289162,-123.256714,0.002009,0.001377,0.034966,14.630922,0.745335,0.349664,-123.256714,0.035938,0.000000
23.930000,3.399757,-123.345680,0.002035,0.001397,0.035487,15.122876,0.770396,0.354868,-123.345680,0.036319,0.000000
24.160002,3.406464,-123.301193,0.002065,0.001414,0.035912,15.152707,0.771916,0.359118,-123.301193,0.036701,0.000000
24.390001,3.370712,-123.301193,0.002065,0.001429,0.036293,14.993677,0.763814,0.362934,-123.301193,0.037083,0.000000
24.620001,3.347252,-123.301193,0.002091,0.001442,0.036632,14.889320,0.758498,0.366317,-123.301193,0.037473,0.000000
24.850000,3.422844,-123.345680,0.002100,0.001458,0.037039,15.225571,0.775627,0.370394,-123.345680,0.037854,0.000000
25.080002,3.472374,-123.345680,0.002108,0.001474,0.037438,15.445890,0.786851,0.374383,-123.345680,0.038236,0.000000
25.310001,3.444069,-123.301193,0.002117,0.001483,0.037672,15.319983,0.780437,0.376722,-123.301193,0.038618,0.000000
25.540001,3.433647,-123.345680,0.002156,0.001494,0.037958,15.273625,0.778076,0.379583,-123.345680,0.038999,0.000000
25.770000,3.617966,-123.390160,0.002173,0.001515,0.038470,16.093515,0.819843,0.384701,-123.390160,0.039389,0.000000
26.000002,3.747925,-123.390160,0.002190,0.001535,0.038990,16.671602,0.849292,0.389905,-123.390160,0.039771,0.000000
26.230001,3.718140,-123.434639,0.002203,0.001551,0.039389,16.539112,0.842542,0.393894,-123.434639,0.040152,0.000000
26.460001,3.668983,-123.345680,0.002216,0.001564,0.039736,16.320454,0.831404,0.397361,-123.345680,0.040534,0.000000
26.690001,3.634354,-123.301193,0.002233,0.001576,0.040023,16.166412,0.823556,0.400226,-123.301193,0.040925,0.000000
26.920002,3.703987,-123.434639,0.002238,0.001591,0.040413,16.476158,0.839335,0.404128,-123.434639,0.041306,0.000000
27.150002,3.778091,-123.434639,0.002251,0.001607,0.040829,16.805790,0.856128,0.408288,-123.434639,0.041688,0.000000
27.380001,3.801544,-123.434639,0.002268,0.001621,0.041185,16.910112,0.861442,0.411846,-123.434639,0.042069,0.000000
27.610001,3.805641,-123.390160,0.002285,0.001634,0.041514,16.928337,0.862371,0.415142,-123.390160,0.042451,0.000000
27.840002,3.855545,-123.479118,0.002294,0.001650,0.041913,17.150320,0.873679,0.419132,-123.479118,0.042841,0.000000
28.070002,3.995552,-123.479118,0.002320,0.001669,0.042390,17.773104,0.905405,0.423901,-123.479118,0.043222,0.000000
28.300001,3.948265,-123.434639,0.002324,0.001684,0.042763,17.562759,0.894690,0.427629,-123.434639,0.043604,0.000000
28.530001,3.935600,-123.479118,0.002337,0.001697,0.043101,17.506424,0.891820,0.431012,-123.479118,0.043986,0.000000
28.760002,4.005981,-123.434639,0.002376,0.001714,0.043543,17.819496,0.907768,0.435433,-123.434639,0.044367,0.000000
28.990002,4.039864,-123.434639,0.002389,0.001729,0.043925,17.970211,0.915446,0.439248,-123.434639,0.044758,0.000000
29.220001,4.115456,-123.434639,0.002402,0.001745,0.044324,18.306461,0.932576,0.443238,-123.434639,0.045139,0.000000
29.450001,4.002632,-123.568085,0.002406,0.001754,0.044558,17.804598,0.907009,0.445581,-123.568085,0.045521,0.000000
29.680002,4.158279,-123.479118,0.002419,0.001772,0.045001,18.496950,0.942280,0.450005,-123.479118,0.045902,0.000000
29.910002,4.336273,-123.434639,0.002440,0.001795,0.045590,19.288706,0.982614,0.455902,-123.434639,0.046284,0.000000
30.140001,4.273346,-123.523598,0.002458,0.001809,0.045946,19.008793,0.968354,0.459456,-123.523598,0.046674,0.000000
30.370001,4.178017,-123.523598,0.002470,0.001820,0.046232,18.584745,0.946752,0.462317,-123.523598,0.047056,0.000000
30.600002,4.215996,-123.523598,0.002479,0.001833,0.046553,18.753685,0.955358,0.465527,-123.523598,0.047437,0.000000
30.830002,4.253235,-123.523598,0.002488,0.001846,0.046899,18.919334,0.963797,0.468994,-123.523598,0.047819,0.000000
31.060001,4.382080,-123.479118,0.002509,0.001863,0.047324,19.492466,0.992994,0.473244,-123.479118,0.048200,0.000000
31.290001,4.329201,-123.523598,0.002531,0.001874,0.047593,19.257246,0.981011,0.475932,-123.523598,0.048590,0.000000
31.520002,4.469582,-123.523598,0.002552,0.001890,0.048018,19.881693,1.012822,0.480182,-123.523598,0.048972,0.000000
31.750002,4.643112,-123.523598,0.002565,0.001913,0.048599,20.653595,1.052144,0.485992,-123.523598,0.049354,0.000000
31.980001,4.562302,-123.523598,0.002578,0.001928,0.048964,20.294130,1.033832,0.489637,-123.523598,0.049735,0.000000
32.210003,4.530281,-123.523598,0.002591,0.001941,0.049310,20.151697,1.026576,0.493104,-123.523598,0.050117,0.000000
32.440002,4.567146,-123.479118,0.002617,0.001956,0.049675,20.315681,1.034930,0.496749,-123.479118,0.050507,0.000000
32.670002,4.644974,-123.612564,0.002626,0.001971,0.050056,20.661875,1.052566,0.500564,-123.612564,0.050889,0.000000
32.900002,4.711998,-123.657043,0.002639,0.001985,0.050420,20.960014,1.067754,0.504205,-123.657043,0.051271,0.000000
33.130001,4.776047,-123.523598,0.002647,0.002000,0.050811,21.244917,1.082268,0.508107,-123.523598,0.051652,0.000000
33.360001,4.824455,-123.523598,0.002682,0.002015,0.051175,21.460249,1.093237,0.511748,-123.523598,0.052034,0.000000
33.590000,4.764130,-123.612564,0.002686,0.002026,0.051453,21.191908,1.079567,0.514526,-123.612564,0.052424,0.000000
33.820004,4.986435,-123.612564,0.002708,0.002050,0.052060,22.180771,1.129942,0.520597,-123.612564,0.052805,0.000000
34.050003,4.905632,-123.612564,0.002703,0.002062,0.052380,21.821341,1.111632,0.523803,-123.612564,0.053187,0.000000
34.280003,4.901535,-123.657043,0.002734,0.002076,0.052736,21.803116,1.110704,0.527361,-123.657043,0.053568,0.000000
34.510002,4.838608,-123.523598,0.002734,0.002087,0.053005,21.523203,1.096444,0.530048,-123.523598,0.053959,0.000000
34.740002,4.992393,-123.612564,0.002781,0.002103,0.053404,22.207275,1.131292,0.534037,-123.612564,0.054340,0.000000
34.970001,5.192734,-123.657043,0.002790,0.002122,0.053889,23.098433,1.176690,0.538893,-123.657043,0.054722,0.000000
35.200001,5.024422,-123.612564,0.002794,0.002130,0.054098,22.349745,1.138550,0.540975,-123.612564,0.055104,0.000000
35.430000,5.144325,-123.568085,0.002811,0.002143,0.054445,22.883102,1.165721,0.544446,-123.568085,0.055485,0.000000
35.660000,5.364021,-123.568085,0.002824,0.002166,0.055008,23.860359,1.215505,0.550081,-123.568085,0.055875,0.000000
35.890003,5.402008,-123.612564,0.002850,0.002183,0.055450,24.029331,1.224113,0.554502,-123.612564,0.056257,0.000000
36.120003,5.286194,-123.746002,0.002867,0.002196,0.055771,23.514164,1.197869,0.557712,-123.746002,0.056639,0.000000
36.350002,5.304443,-123.657043,0.002867,0.002209,0.056118,23.595343,1.202004,0.561183,-123.657043,0.057020,0.000000
36.580002,5.304817,-123.657043,0.002893,0.002221,0.056422,23.597006,1.202089,0.564218,-123.657043,0.057402,0.000000
36.810001,5.601967,-123.568085,0.002902,0.002242,0.056951,24.918793,1.269424,0.569506,-123.568085,0.057792,0.000000
37.040001,5.473503,-123.657043,0.002932,0.002253,0.057228,24.347359,1.240314,0.572284,-123.657043,0.058173,0.000000
37.270000,5.470146,-123.746002,0.002932,0.002266,0.057558,24.332426,1.239553,0.575577,-123.746002,0.058555,0.000000
37.500000,5.425461,-123.701523,0.002923,0.002276,0.057818,24.133656,1.229427,0.578181,-123.701523,0.058936,0.000000
37.730003,5.885345,-123.701523,0.002971,0.002305,0.058546,26.179323,1.333638,0.585463,-123.701523,0.059318,0.000000
37.960003,5.711449,-123.701523,0.002984,0.002317,0.058841,25.405792,1.294233,0.588411,-123.701523,0.059709,0.000000
38.190002,5.703995,-123.701523,0.003005,0.002330,0.059171,25.372637,1.292544,0.591708,-123.701523,0.060090,0.000000
38.420002,5.798210,-123.657043,0.003005,0.002346,0.059578,25.791727,1.313893,0.595784,-123.657043,0.060472,0.000000
38.650002,5.879761,-123.701523,0.003031,0.002359,0.059908,26.154482,1.332373,0.599081,-123.701523,0.060853,0.000000
38.880001,5.984764,-123.746002,0.003035,0.002377,0.060368,26.621561,1.356167,0.603676,-123.746002,0.061235,0.000000
39.110001,6.017532,-123.790489,0.003053,0.002388,0.060654,26.767321,1.363592,0.606537,-123.790489,0.061625,0.000000
39.340000,5.910294,-123.701523,0.003070,0.002399,0.060931,26.290298,1.339292,0.609311,-123.701523,0.062007,0.000000
39.570004,6.459167,-123.879448,0.003091,0.002428,0.061677,28.731812,1.463668,0.616771,-123.879448,0.062388,0.000000
39.800003,6.202232,-123.790489,0.003091,0.002439,0.061963,27.588907,1.405446,0.619633,-123.790489,0.062770,0.000000
40.030003,6.216011,-123.701523,0.003130,0.002455,0.062353,27.650198,1.408568,0.623535,-123.701523,0.063151,0.000000
40.260002,6.230530,-123.746002,0.003143,0.002465,0.062614,27.714781,1.411858,0.626135,-123.746002,0.063542,0.000000
40.490002,6.400711,-123.746002,0.003152,0.002482,0.063047,28.471785,1.450422,0.630473,-123.746002,0.063923,0.000000
40.720001,6.538483,-123.834969,0.003169,0.002497,0.063420,29.084623,1.481641,0.634201,-123.834969,0.064305,0.000000
40.950001,6.532158,-123.790489,0.003165,0.002510,0.063758,29.056490,1.480208,0.637585,-123.790489,0.064686,0.000000
41.180000,6.664345,-123.790489,0.003191,0.002523,0.064097,29.644485,1.510162,0.640968,-123.790489,0.065068,0.000000
41.410004,6.792068,-123.834969,0.003216,0.002540,0.064513,30.212629,1.539105,0.645128,-123.834969,0.065458,0.000000
41.640003,7.001717,-123.790489,0.003238,0.002560,0.065033,31.145191,1.586612,0.650332,-123.790489,0.065840,0.000000
41.870003,6.883301,-123.834969,0.003234,0.002575,0.065406,30.618450,1.559778,0.654060,-123.834969,0.066221,0.000000
42.100002,6.847557,-123.834969,0.003247,0.002585,0.065666,30.459455,1.551679,0.656664,-123.834969,0.066603,0.000000
42.330002,7.054962,-123.790489,0.003281,0.002603,0.066126,31.382038,1.598677,0.661259,-123.790489,0.066985,0.000000
42.560001,7.158485,-123.790489,0.003298,0.002621,0.066577,31.842533,1.622136,0.665771,-123.790489,0.067375,0.000000
42.790001,7.241898,-123.879448,0.003303,0.002634,0.066898,32.213570,1.641037,0.668976,-123.879448,0.067756,0.000000
43.020000,7.043793,-123.923927,0.003311,0.002643,0.067132,31.332355,1.596146,0.671319,-123.923927,0.068138,0.000000
43.250004,7.305946,-123.834969,0.003324,0.002660,0.067557,32.498474,1.655551,0.675570,-123.834969,0.068519,0.000000
43.480003,7.683533,-123.879448,0.003346,0.002677,0.068008,34.178059,1.741113,0.680077,-123.879448,0.068910,0.000000
43.710003,7.596397,-123.790489,0.003363,0.002692,0.068389,33.790462,1.721368,0.683893,-123.790489,0.069291,0.000000
43.940002,7.760239,-123.879448,0.003389,0.002710,0.068823,34.519264,1.758495,0.688230,-123.879448,0.069673,0.000000
44.170002,7.674225,-123.968414,0.003393,0.002723,0.069161,34.136658,1.739004,0.691614,-123.968414,0.070055,0.000000
44.400002,7.775505,-123.923927,0.003410,0.002738,0.069543,34.587173,1.761955,0.695429,-123.923927,0.070436,0.000000
44.630001,8.011215,-123.879448,0.003419,0.002753,0.069933,35.635666,1.815367,0.699331,-123.879448,0.070826,0.000000
44.860001,8.039146,-123.879448,0.003445,0.002766,0.070254,35.759911,1.821697,0.702541,-123.879448,0.071208,0.000000
45.090004,8.167244,-123.968414,0.003454,0.002780,0.070601,36.329716,1.850724,0.706008,-123.968414,0.071589,0.000000
45.320004,8.440567,-124.012894,0.003466,0.002798,0.071069,37.545517,1.912660,0.710690,-124.012894,0.071971,0.000000
45.550003,8.725800,-123.968414,0.003488,0.002817,0.071563,38.814297,1.977294,0.715633,-123.968414,0.072353,0.000000
45.780003,8.640152,-123.923927,0.003505,0.002832,0.071936,38.433315,1.957886,0.719365,-123.923927,0.072743,0.000000
46.010002,8.623398,-123.923927,0.003518,0.002844,0.072240,38.358788,1.954090,0.722400,-123.923927,0.073125,0.000000
46.240002,8.723564,-123.968414,0.003531,0.002857,0.072578,38.804352,1.976788,0.725780,-123.968414,0.073506,0.000000
46.470001,9.112320,-123.923927,0.003544,0.002876,0.073055,40.533623,2.064881,0.730549,-123.923927,0.073888,0.000000
46.700001,9.009552,-123.968414,0.003548,0.002887,0.073324,40.076488,2.041594,0.733240,-123.968414,0.074269,0.000000
46.930004,8.903419,-124.012894,0.003561,0.002895,0.073523,39.604389,2.017544,0.735235,-124.012894,0.074659,0.000000
47.160004,9.134666,-124.012894,0.003579,0.002909,0.073879,40.633026,2.069945,0.738789,-124.012894,0.075041,0.000000
47.390003,9.931541,-124.057373,0.003600,0.002935,0.074538,44.177704,2.250520,0.745382,-124.057373,0.075423,0.000000
47.620003,10.046608,-124.057373,0.003617,0.002953,0.075015,44.689545,2.276594,0.750151,-124.057373,0.075804,0.000000
47.850002,10.016441,-123.968414,0.003639,0.002966,0.075344,44.555355,2.269758,0.753444,-123.968414,0.076186,0.000000
48.080002,10.114380,-124.012894,0.003639,0.002980,0.075700,44.991009,2.291951,0.757002,-124.012894,0.076576,0.000000
48.310001,10.172096,-123.923927,0.003652,0.002994,0.076047,45.247746,2.305030,0.760469,-123.923927,0.076958,0.000000
48.540001,10.630859,-124.012894,0.003669,0.003014,0.076567,47.288425,2.408987,0.765673,-124.012894,0.077339,0.000000
48.770000,10.518776,-124.012894,0.003682,0.003022,0.076749,46.789852,2.383589,0.767493,-124.012894,0.077721,0.000000
49.000004,10.593620,-124.057373,0.003682,0.003034,0.077070,47.122776,2.400549,0.770703,-124.057373,0.078102,0.000000
49.230003,11.371506,-124.012894,0.003699,0.003057,0.077660,50.582985,2.576820,0.776600,-124.012894,0.078493,0.000000
49.460003,11.462364,-124.012894,0.003729,0.003072,0.078033,50.987141,2.597409,0.780328,-124.012894,0.078874,0.000000
49.690002,11.680206,-124.057373,0.003742,0.003088,0.078432,51.956154,2.646773,0.784317,-124.057373,0.079256,0.000000
49.920002,11.969910,-124.057373,0.003751,0.003104,0.078839,53.244816,2.712420,0.788394,-124.057373,0.079637,0.000000
50.150002,11.962837,-124.057373,0.003751,0.003115,0.079117,53.213356,2.710818,0.791172,-124.057373,0.080019,0.000000
50.380001,12.375427,-124.012894,0.003790,0.003131,0.079524,55.048649,2.804312,0.795244,-124.012894,0.080409,0.000000
50.610001,12.530701,-124.057373,0.003798,0.003144,0.079854,55.739342,2.839497,0.798541,-124.057373,0.080791,0.000000
50.840004,12.852432,-124.057373,0.003803,0.003159,0.080236,57.170475,2.912403,0.802356,-124.057373,0.081172,0.000000
51.070004,13.213264,-124.101852,0.003820,0.003175,0.080652,58.775536,2.994169,0.806520,-124.101852,0.081554,0.000000
51.300003,13.956520,-124.101852,0.003842,0.003198,0.081224,62.081703,3.162593,0.812242,-124.101852,0.081935,0.000000
51.530003,13.803841,-124.057373,0.003846,0.003208,0.081485,61.402550,3.127995,0.814846,-124.057373,0.082326,0.000000
51.760002,13.980347,-124.101852,0.003863,0.003222,0.081831,62.187687,3.167992,0.818313,-124.101852,0.082707,0.000000
51.990002,14.185898,-124.101852,0.003876,0.003234,0.082135,63.102024,3.214570,0.821349,-124.101852,0.083089,0.000000
52.220001,14.882233,-124.235298,0.003880,0.003252,0.082612,66.199478,3.372362,0.826118,-124.235298,0.083471,0.000000
52.450001,15.149223,-124.101852,0.003889,0.003265,0.082924,67.387108,3.432863,0.829240,-124.101852,0.083861,0.000000
52.680004,15.245300,-124.146332,0.003915,0.003276,0.083219,67.814484,3.454634,0.832189,-124.146332,0.084242,0.000000
52.910004,15.660866,-124.146332,0.003923,0.003290,0.083566,69.663010,3.548803,0.835659,-124.146332,0.084624,0.000000
53.140003,17.036034,-124.146332,0.003928,0.003318,0.084277,75.780060,3.860420,0.842771,-124.146332,0.085005,0.000000
53.370003,16.974594,-124.146332,0.003932,0.003330,0.084572,75.506767,3.846498,0.845720,-124.146332,0.085387,0.000000
53.600002,17.394257,-124.146332,0.003949,0.003345,0.084962,77.373520,3.941595,0.849622,-124.146332,0.085777,0.000000
53.830002,17.571136,-124.146332,0.003980,0.003356,0.085231,78.160316,3.981677,0.852309,-124.146332,0.086159,0.000000
54.060001,17.864197,-124.190819,0.003975,0.003367,0.085534,79.463913,4.048085,0.855345,-124.190819,0.086540,0.000000
54.290001,18.616013,-124.190819,0.003988,0.003385,0.085985,82.808159,4.218449,0.859852,-124.190819,0.086922,0.000000
54.520004,19.281075,-124.235298,0.003980,0.003402,0.086402,85.766502,4.369154,0.864016,-124.235298,0.087304,0.000000
54.750004,19.645248,-124.190819,0.004001,0.003414,0.086705,87.386429,4.451677,0.867051,-124.190819,0.087694,0.000000
54.980003,20.627571,-124.190819,0.004010,0.003437,0.087295,91.756020,4.674274,0.872948,-124.190819,0.088075,0.000000
55.210003,21.201393,-124.235298,0.004040,0.003451,0.087651,94.308510,4.804304,0.876506,-124.235298,0.088457,0.000000
55.440002,21.571159,-124.235298,0.004036,0.003465,0.088023,95.953308,4.888095,0.880234,-124.235298,0.088839,0.000000
55.670002,21.976303,-124.235298,0.004040,0.003478,0.088344,97.755478,4.979901,0.883444,-124.235298,0.089220,0.000000
55.900002,22.087639,-124.279778,0.004036,0.003487,0.088578,98.250725,5.005130,0.885783,-124.279778,0.089610,0.000000
56.130001,23.026024,-124.190819,0.004070,0.003505,0.089038,102.424873,5.217772,0.890381,-124.190819,0.089992,0.000000
56.360004,23.942802,-124.190819,0.004087,0.003522,0.089463,106.502907,5.425517,0.894632,-124.190819,0.090373,0.000000
56.590004,24.028450,-124.324257,0.004083,0.003529,0.089645,106.883881,5.444924,0.896452,-124.324257,0.090755,0.000000
56.820004,24.570625,-124.279778,0.004096,0.003542,0.089966,109.295601,5.567783,0.899658,-124.279778,0.091137,0.000000
57.050003,26.118950,-124.235298,0.004092,0.003568,0.090616,116.182892,5.918639,0.906164,-124.235298,0.091527,0.000000
57.280003,26.932579,-124.235298,0.004117,0.003583,0.090998,119.802094,6.103010,0.909980,-124.235298,0.091909,0.000000
57.510002,27.444221,-124.279778,0.004122,0.003597,0.091371,122.077995,6.218949,0.913708,-124.279778,0.092290,0.000000
57.740002,28.070549,-124.279778,0.004122,0.003611,0.091709,124.864037,6.360878,0.917091,-124.279778,0.092672,0.000000
57.970001,28.353554,-124.368736,0.004135,0.003622,0.091995,126.122910,6.425007,0.919953,-124.368736,0.093053,0.000000
58.200005,29.774529,-124.235298,0.004143,0.003642,0.092498,132.443710,6.747005,0.924983,-124.235298,0.093444,0.000000
58.430004,30.404953,-124.324257,0.004165,0.003655,0.092837,135.247986,6.889861,0.928367,-124.324257,0.093825,0.000000
58.660004,31.097565,-124.324257,0.004165,0.003668,0.093175,138.328873,7.046809,0.931747,-124.324257,0.094207,0.000000
58.890003,31.670647,-124.324257,0.004174,0.003684,0.093582,140.878067,7.176671,0.935823,-124.324257,0.094588,0.000000
59.120003,33.594322,-124.368736,0.004178,0.003706,0.094138,149.435013,7.612582,0.941375,-124.368736,0.094970,0.000000
59.350002,34.043404,-124.368736,0.004178,0.003717,0.094406,151.432617,7.714345,0.944063,-124.368736,0.095360,0.000000
59.580002,34.808632,-124.279778,0.004186,0.003732,0.094788,154.836533,7.887749,0.947878,-124.279778,0.095742,0.000000
59.810001,35.714241,-124.368736,0.004199,0.003746,0.095161,158.864883,8.092963,0.951606,-124.368736,0.096123,0.000000
60.040005,36.801567,-124.413223,0.004208,0.003764,0.095594,163.701553,8.339355,0.955943,-124.413223,0.096505,0.000000
60.270004,37.884430,-124.368736,0.004208,0.003780,0.096002,168.518356,8.584735,0.960020,-124.368736,0.096886,0.000000
60.500004,38.571457,-124.413223,0.004208,0.003793,0.096340,171.574402,8.740417,0.963400,-124.413223,0.097277,0.000000
60.730003,38.838448,-124.368736,0.004225,0.003800,0.096531,172.762039,8.800918,0.965307,-124.368736,0.097658,0.000000
60.960003,41.005653,-124.324257,0.004234,0.003826,0.097181,182.402252,9.292014,0.971813,-124.324257,0.098040,0.000000
61.190002,41.842743,-124.413223,0.004234,0.003839,0.097502,186.125809,9.481701,0.975023,-124.413223,0.098421,0.000000
61.420002,43.001572,-124.413223,0.004225,0.003854,0.097893,191.280548,9.744295,0.978925,-124.413223,0.098812,0.000000
61.650002,43.569809,-124.368736,0.004247,0.003864,0.098144,193.808197,9.873059,0.981438,-124.368736,0.099193,0.000000
61.880001,44.763260,-124.368736,0.004260,0.003882,0.098604,199.116928,10.143500,0.986037,-124.368736,0.099575,0.000000
62.110004,45.995819,-124.368736,0.004255,0.003896,0.098959,204.599625,10.422802,0.989591,-124.368736,0.099956,0.000000
62.340004,47.031754,-124.413223,0.004273,0.003910,0.099315,209.207687,10.657548,0.993145,-124.413223,0.100338,0.000000
62.570004,47.986519,-124.413223,0.004277,0.003923,0.099653,213.454697,10.873901,0.996529,-124.413223,0.100728,0.000000
62.800003,49.385147,-124.368736,0.004281,0.003944,0.100182,219.676102,11.190834,1.001820,-124.368736,0.101110,0.000000
63.030003,50.758835,-124.413223,0.004286,0.003958,0.100537,225.786575,11.502116,1.005374,-124.413223,0.101492,0.000000
63.260002,51.565392,-124.413223,0.004286,0.003972,0.100884,229.374313,11.684885,1.008845,-124.413223,0.101873,0.000000
63.490002,52.923805,-124.457703,0.004286,0.003987,0.101257,235.416840,11.992705,1.012573,-124.457703,0.102255,0.000000
63.720001,54.541763,-124.457703,0.004299,0.004007,0.101769,242.613876,12.359340,1.017690,-124.457703,0.102645,0.000000
63.950005,55.909859,-124.502182,0.004294,0.004021,0.102124,248.699478,12.669355,1.021244,-124.502182,0.103026,0.000000
64.180000,56.763336,-124.457703,0.004312,0.004033,0.102428,252.495926,12.862756,1.024280,-124.457703,0.103408,0.000000
64.410004,57.552765,-124.457703,0.004307,0.004045,0.102732,256.007477,13.041642,1.027315,-124.457703,0.103789,0.000000
64.639999,58.895172,-124.546661,0.004307,0.004060,0.103130,261.978821,13.345837,1.031304,-124.546661,0.104171,0.000000
64.870003,60.481850,-124.502182,0.004312,0.004077,0.103564,269.036713,13.705383,1.035642,-124.502182,0.104562,0.000000
65.100006,61.796700,-124.457703,0.004307,0.004094,0.103998,274.885437,14.003332,1.039976,-124.457703,0.104943,0.000000
65.330002,63.180435,-124.457703,0.004324,0.004109,0.104379,281.040619,14.316892,1.043795,-124.457703,0.105325,0.000000
65.560005,64.218613,-124.502182,0.004346,0.004122,0.104691,285.658661,14.552146,1.046913,-124.502182,0.105706,0.000000
65.790001,65.538300,-124.546661,0.004333,0.004140,0.105151,291.528931,14.851191,1.051512,-124.546661,0.106088,0.000000
66.020004,67.089233,-124.546661,0.004320,0.004154,0.105507,298.427826,15.202638,1.055066,-124.546661,0.106478,0.000000
66.250000,67.187531,-124.502182,0.004346,0.004149,0.105377,298.865051,15.224912,1.053768,-124.502182,0.105585,0.000000
66.480003,66.852768,-124.502182,0.004346,0.004148,0.105368,297.375977,15.149054,1.053681,-124.502182,0.105368,0.000000
66.710007,66.574234,-124.546661,0.004350,0.004148,0.105351,296.136993,15.085937,1.053507,-124.546661,0.105368,0.000000
66.940002,66.339264,-124.591141,0.004346,0.004147,0.105342,295.091797,15.032692,1.053420,-124.591141,0.105368,0.000000
67.170006,66.121429,-124.591141,0.004350,0.004147,0.105333,294.122803,14.983330,1.053332,-124.591141,0.105368,0.000000
67.400002,65.943069,-124.546661,0.004346,0.004147,0.105325,293.329437,14.942913,1.053245,-124.546661,0.105368,0.000000
67.630005,65.781082,-124.546661,0.004346,0.004147,0.105325,292.608856,14.906206,1.053245,-124.546661,0.105368,0.000000
67.860001,65.612030,-124.546661,0.004350,0.004147,0.105325,291.856873,14.867899,1.053245,-124.546661,0.105368,0.000000
68.090004,65.493607,-124.591141,0.004350,0.004146,0.105316,291.330109,14.841063,1.053158,-124.591141,0.105368,0.000000
68.320000,65.373337,-124.591141,0.004355,0.004146,0.105316,290.795135,14.813809,1.053158,-124.591141,0.105368,0.000000
68.550003,65.243011,-124.635628,0.004359,0.004146,0.105316,290.215424,14.784278,1.053158,-124.635628,0.105368,0.000000
68.780006,65.129059,-124.591141,0.004355,0.004146,0.105316,289.708527,14.758455,1.053158,-124.591141,0.105368,0.000000
69.010002,65.045273,-124.546661,0.004355,0.004146,0.105316,289.335815,14.739470,1.053158,-124.546661,0.105368,0.000000
69.240005,64.960373,-124.635628,0.004359,0.004146,0.105316,288.958160,14.720231,1.053158,-124.635628,0.105368,0.000000
69.470001,64.852020,-124.635628,0.004359,0.004146,0.105316,288.476196,14.695679,1.053158,-124.635628,0.105368,0.000000
69.700005,64.793549,-124.591141,0.004359,0.004146,0.105316,288.216095,14.682427,1.053158,-124.591141,0.105368,0.000000
69.930000,64.733597,-124.591141,0.004359,0.004146,0.105316,287.949432,14.668842,1.053158,-124.591141,0.105368,0.000000
70.160004,64.647202,-124.591141,0.004368,0.004146,0.105316,287.565125,14.649265,1.053158,-124.591141,0.105368,0.000000
70.390007,64.576462,-124.724586,0.004359,0.004146,0.105316,287.250458,14.633235,1.053158,-124.724586,0.105368,0.000000
70.620003,64.513519,-124.724586,0.004342,0.004146,0.105316,286.970459,14.618973,1.053158,-124.724586,0.105368,0.000000
70.850006,64.444260,-124.635628,0.004368,0.004146,0.105316,286.662384,14.603277,1.053158,-124.635628,0.105368,0.000000
71.080002,64.395111,-124.635628,0.004350,0.004146,0.105307,286.443756,14.592141,1.053071,-124.635628,0.105368,0.000000
71.310005,64.346329,-124.680107,0.004368,0.004146,0.105307,286.226776,14.581086,1.053071,-124.680107,0.105368,0.000000
71.540001,64.302383,-124.769066,0.004359,0.004146,0.105307,286.031281,14.571128,1.053071,-124.769066,0.105368,0.000000
71.770004,64.239456,-124.724586,0.004372,0.004146,0.105307,285.751373,14.556869,1.053071,-124.724586,0.105368,0.000000
72.000000,64.182480,-124.635628,0.004342,0.004146,0.105307,285.497925,14.543958,1.053071,-124.635628,0.105368,0.000000
72.230003,64.153809,-124.635628,0.004376,0.004146,0.105307,285.370392,14.537461,1.053071,-124.635628,0.105368,0.000000
72.460007,64.111740,-124.724586,0.004350,0.004146,0.105307,285.183258,14.527928,1.053071,-124.724586,0.105368,0.000000
72.690002,64.054398,-124.724586,0.004368,0.004146,0.105307,284.928192,14.514935,1.053071,-124.724586,0.105368,0.000000
72.920006,64.014923,-124.769066,0.004363,0.004146,0.105307,284.752594,14.505988,1.053071,-124.769066,0.105368,0.000000
73.150002,63.978806,-124.724586,0.004359,0.004146,0.105307,284.591949,14.497805,1.053071,-124.724586,0.105368,0.000000
73.380005,63.942307,-124.769066,0.004355,0.004146,0.105307,284.429596,14.489534,1.053071,-124.769066,0.105368,0.000000
73.610001,63.906937,-124.724586,0.004368,0.004146,0.105307,284.272247,14.481519,1.053071,-124.724586,0.105368,0.000000
73.840004,63.870804,-124.769066,0.004359,0.004146,0.105307,284.111511,14.473331,1.053071,-124.769066,0.105368,0.000000
74.070007,63.832077,-124.769066,0.004355,0.004146,0.105307,283.939270,14.464556,1.053071,-124.769066,0.105368,0.000000
74.300003,63.785904,-124.769066,0.004359,0.004146,0.105307,283.733856,14.454092,1.053071,-124.769066,0.105368,0.000000
74.530006,63.758728,-124.724586,0.004359,0.004146,0.105307,283.612976,14.447934,1.053071,-124.724586,0.105368,0.000000
74.760002,63.740860,-124.769066,0.004376,0.004146,0.105307,283.533508,14.443885,1.053071,-124.769066,0.105368,0.000000
74.990005,63.717773,-124.813545,0.004359,0.004146,0.105307,283.430817,14.438654,1.053071,-124.813545,0.105368,0.000000
75.220001,63.663406,-124.813545,0.004359,0.004146,0.105307,283.188965,14.426334,1.053071,-124.813545,0.105368,0.000000
75.450005,63.636963,-124.769066,0.004363,0.004146,0.105307,283.071350,14.420341,1.053071,-124.769066,0.105368,0.000000
75.680000,63.605682,-124.769066,0.004372,0.004146,0.105307,282.932220,14.413254,1.053071,-124.769066,0.105368,0.000000
75.910004,63.591156,-124.769066,0.004359,0.004146,0.105307,282.867584,14.409962,1.053071,-124.769066,0.105368,0.000000
76.140007,63.563599,-124.858032,0.004372,0.004146,0.105307,282.744995,14.403718,1.053071,-124.858032,0.105368,0.000000
76.370003,63.528229,-124.813545,0.004355,0.004146,0.105307,282.587677,14.395702,1.053071,-124.813545,0.105368,0.000000
76.600006,63.508499,-124.769066,0.004363,0.004146,0.105307,282.499908,14.391232,1.053071,-124.769066,0.105368,0.000000
76.830002,63.486893,-124.813545,0.004359,0.004146,0.105307,282.403809,14.386335,1.053071,-124.813545,0.105368,0.000000
77.060005,63.449280,-124.813545,0.004363,0.004146,0.105307,282.236481,14.377812,1.053071,-124.813545,0.105368,0.000000
77.290001,63.426193,-124.902512,0.004355,0.004146,0.105307,282.133789,14.372581,1.053071,-124.902512,0.105368,0.000000
77.520004,63.406464,-124.858032,0.004363,0.004146,0.105307,282.046051,14.368111,1.053071,-124.858032,0.105368,0.000000
77.750000,63.402740,-124.858032,0.004359,0.004146,0.105307,282.029480,14.367266,1.053071,-124.858032,0.105368,0.000000
77.980003,63.365875,-124.858032,0.004368,0.004146,0.105307,281.865479,14.358912,1.053071,-124.858032,0.105368,0.000000
78.210007,63.330124,-124.858032,0.004372,0.004146,0.105307,281.706451,14.350811,1.053071,-124.858032,0.105368,0.000000
78.440002,63.323059,-124.946991,0.004368,0.004146,0.105307,281.675049,14.349211,1.053071,-124.946991,0.105368,0.000000
78.670006,63.312622,-124.858032,0.004363,0.004146,0.105307,281.628601,14.346845,1.053071,-124.858032,0.105368,0.000000
78.900002,63.292511,-124.858032,0.004359,0.004146,0.105307,281.539154,14.342288,1.053071,-124.858032,0.105368,0.000000
79.130005,63.256393,-124.858032,0.004363,0.004146,0.105307,281.378479,14.334104,1.053071,-124.858032,0.105368,0.000000
79.360001,63.237411,-124.902512,0.004376,0.004146,0.105307,281.294067,14.329802,1.053071,-124.902512,0.105368,0.000000
79.590004,63.229965,-124.946991,0.004385,0.004146,0.105307,281.260925,14.328115,1.053071,-124.946991,0.105368,0.000000
79.820007,63.197937,-124.902512,0.004363,0.004146,0.105307,281.118469,14.320857,1.053071,-124.902512,0.105368,0.000000
80.050003,63.175598,-124.946991,0.004359,0.004146,0.105307,281.019104,14.315795,1.053071,-124.946991,0.105368,0.000000
80.280006,63.166656,-124.946991,0.004372,0.004146,0.105307,280.979309,14.313768,1.053071,-124.946991,0.105368,0.000000
80.510002,63.146545,-124.902512,0.004381,0.004146,0.105307,280.889862,14.309212,1.053071,-124.902512,0.105368,0.000000
80.740005,63.135010,-124.991470,0.004376,0.004146,0.105307,280.838562,14.306598,1.053071,-124.991470,0.105368,0.000000
80.970001,63.108932,-124.946991,0.004363,0.004146,0.105307,280.722565,14.300689,1.053071,-124.946991,0.105368,0.000000
81.200005,63.091431,-124.946991,0.004359,0.004146,0.105307,280.644714,14.296722,1.053071,-124.946991,0.105368,0.000000
81.430000,63.075058,-124.991470,0.004363,0.004146,0.105307,280.571869,14.293013,1.053071,-124.991470,0.105368,0.000000
81.660004,63.060532,-124.946991,0.004372,0.004146,0.105307,280.507263,14.289721,1.053071,-124.946991,0.105368,0.000000
81.890007,63.043030,-125.035950,0.004381,0.004146,0.105307,280.429413,14.285754,1.053071,-125.035950,0.105368,0.000000
82.120003,63.023666,-124.991470,0.004368,0.004146,0.105307,280.343262,14.281367,1.053071,-124.991470,0.105368,0.000000
82.350006,63.016586,-124.946991,0.004355,0.004146,0.105307,280.311768,14.279763,1.053071,-124.946991,0.105368,0.000000
82.580002,63.007645,-124.991470,0.004363,0.004146,0.105307,280.272003,14.277737,1.053071,-124.991470,0.105368,0.000000
82.810005,62.979721,-124.991470,0.004363,0.004146,0.105307,280.147797,14.271409,1.053071,-124.991470,0.105368,0.000000
83.040001,62.959244,-125.035950,0.004376,0.004146,0.105307,280.056702,14.266768,1.053071,-125.035950,0.105368,0.000000
83.270004,62.942490,-125.035950,0.004372,0.004146,0.105307,279.982178,14.262972,1.053071,-125.035950,0.105368,0.000000
83.500008,62.945839,-125.035950,0.004359,0.004146,0.105307,279.997070,14.263731,1.053071,-125.035950,0.105368,0.000000
83.730003,62.920143,-125.035950,0.004359,0.004146,0.105307,279.882782,14.257908,1.053071,-125.035950,0.105368,0.000000
83.960007,62.906364,-125.080437,0.004359,0.004146,0.105307,279.821472,14.254786,1.053071,-125.080437,0.105368,0.000000
84.190002,62.874718,-125.035950,0.004376,0.004146,0.105307,279.680725,14.247614,1.053071,-125.035950,0.105368,0.000000
84.420006,62.867638,-125.124916,0.004350,0.004146,0.105307,279.649231,14.246010,1.053071,-125.124916,0.105368,0.000000
84.650002,62.871735,-125.035950,0.004368,0.004146,0.105307,279.667450,14.246939,1.053071,-125.035950,0.105368,0.000000
84.880005,62.848648,-125.035950,0.004381,0.004146,0.105307,279.564758,14.241707,1.053071,-125.035950,0.105368,0.000000
85.110001,62.821465,-125.035950,0.004372,0.004146,0.105307,279.443817,14.235547,1.053071,-125.035950,0.105368,0.000000
85.340004,62.816994,-125.124916,0.004372,0.004146,0.105307,279.423950,14.234534,1.053071,-125.124916,0.105368,0.000000
85.570007,62.804337,-125.124916,0.004368,0.004146,0.105307,279.367645,14.231667,1.053071,-125.124916,0.105368,0.000000
85.800003,62.789444,-125.124916,0.004376,0.004146,0.105307,279.301392,14.228292,1.053071,-125.124916,0.105368,0.000000
86.030006,62.781998,-125.080437,0.004368,0.004146,0.105307,279.268280,14.226604,1.053071,-125.080437,0.105368,0.000000
86.260002,62.756302,-125.124916,0.004368,0.004146,0.105307,279.153961,14.220781,1.053071,-125.124916,0.105368,0.000000
86.490005,62.755928,-125.124916,0.004368,0.004146,0.105307,279.152313,14.220696,1.053071,-125.124916,0.105368,0.000000
86.720001,62.748108,-125.169395,0.004355,0.004146,0.105307,279.117523,14.218925,1.053071,-125.169395,0.105368,0.000000
86.950005,62.724648,-125.124916,0.004363,0.004146,0.105307,279.013153,14.213609,1.053071,-125.124916,0.105368,0.000000
87.180008,62.711990,-125.080437,0.004376,0.004146,0.105307,278.956879,14.210740,1.053071,-125.080437,0.105368,0.000000
87.410004,62.700447,-125.080437,0.004381,0.004146,0.105307,278.905518,14.208124,1.053071,-125.080437,0.105368,0.000000
87.640007,62.694862,-125.169395,0.004372,0.004146,0.105307,278.880676,14.206859,1.053071,-125.169395,0.105368,0.000000
87.870003,62.688904,-125.258362,0.004363,0.004146,0.105307,278.854156,14.205508,1.053071,-125.258362,0.105368,0.000000
88.100006,62.660599,-125.124916,0.004363,0.004146,0.105307,278.728271,14.199095,1.053071,-125.124916,0.105368,0.000000
88.330002,62.641983,-125.124916,0.004381,0.004146,0.105307,278.645447,14.194876,1.053071,-125.124916,0.105368,0.000000
88.560005,62.642357,-125.124916,0.004372,0.004146,0.105307,278.647125,14.194962,1.053071,-125.124916,0.105368,0.000000
88.790001,62.641983,-125.213875,0.004363,0.004146,0.105307,278.645447,14.194876,1.053071,-125.213875,0.105368,0.000000
89.020004,62.624107,-125.258362,0.004368,0.004146,0.105307,278.565948,14.190825,1.053071,-125.258362,0.105368,0.000000
89.250008,62.605118,-125.258362,0.004363,0.004146,0.105307,278.481476,14.186522,1.053071,-125.258362,0.105368,0.000000
89.480003,62.606606,-125.169395,0.004372,0.004146,0.105307,278.488098,14.186860,1.053071,-125.169395,0.105368,0.000000
89.710007,62.594322,-125.169395,0.004385,0.004146,0.105307,278.433441,14.184076,1.053071,-125.169395,0.105368,0.000000
89.940002,62.569000,-125.258362,0.004376,0.004146,0.105307,278.320801,14.178338,1.053071,-125.258362,0.105368,0.000000
90.170006,62.553360,-125.213875,0.004381,0.004146,0.105307,278.251251,14.174793,1.053071,-125.213875,0.105368,0.000000
90.400002,62.555222,-125.258362,0.004363,0.004146,0.105307,278.259521,14.175216,1.053071,-125.258362,0.105368,0.000000
90.630005,62.545914,-125.258362,0.004368,0.004146,0.105307,278.218109,14.173107,1.053071,-125.258362,0.105368,0.000000
90.860001,62.519844,-125.258362,0.004389,0.004146,0.105307,278.102142,14.167199,1.053071,-125.258362,0.105368,0.000000
91.090004,62.508301,-125.302841,0.004376,0.004146,0.105307,278.050812,14.164583,1.053071,-125.302841,0.105368,0.000000
91.320007,62.495644,-125.258362,0.004363,0.004146,0.105307,277.994507,14.161716,1.053071,-125.258362,0.105368,0.000000
91.550003,62.510536,-125.258362,0.004372,0.004146,0.105307,278.060760,14.165090,1.053071,-125.258362,0.105368,0.000000
91.780006,62.487450,-125.258362,0.004372,0.004146,0.105307,277.958069,14.159859,1.053071,-125.258362,0.105368,0.000000
92.010002,62.472549,-125.258362,0.004389,0.004146,0.105307,277.891785,14.156482,1.053071,-125.258362,0.105368,0.000000
92.240005,62.471436,-125.302841,0.004381,0.004146,0.105307,277.886810,14.156230,1.053071,-125.302841,0.105368,0.000000
92.470001,62.466965,-125.391800,0.004363,0.004146,0.105307,277.866943,14.155217,1.053071,-125.391800,0.105368,0.000000
92.700005,62.445366,-125.213875,0.004359,0.004146,0.105307,277.770874,14.150322,1.053071,-125.213875,0.105368,0.000000
92.930008,62.426003,-125.302841,0.004363,0.004146,0.105307,277.684723,14.145934,1.053071,-125.302841,0.105368,0.000000
93.160004,62.426750,-125.258362,0.004372,0.004146,0.105307,277.688049,14.146104,1.053071,-125.258362,0.105368,0.000000
93.390007,62.426750,-125.347321,0.004389,0.004146,0.105307,277.688049,14.146104,1.053071,-125.347321,0.105368,0.000000
93.620003,62.407387,-125.302841,0.004368,0.004146,0.105307,277.601929,14.141715,1.053071,-125.302841,0.105368,0.000000
93.850006,62.380951,-125.347321,0.004368,0.004146,0.105307,277.484314,14.135726,1.053071,-125.347321,0.105368,0.000000
94.080002,62.395096,-125.347321,0.004385,0.004146,0.105307,277.547241,14.138931,1.053071,-125.347321,0.105368,0.000000
94.310005,62.383553,-125.347321,0.004385,0.004146,0.105307,277.495911,14.136314,1.053071,-125.347321,0.105368,0.000000
94.540001,62.364563,-125.347321,0.004381,0.004146,0.105307,277.411438,14.132011,1.053071,-125.347321,0.105368,0.000000
94.770004,62.341476,-125.391800,0.004372,0.004146,0.105307,277.308746,14.126781,1.053071,-125.391800,0.105368,0.000000
95.000008,62.349297,-125.436279,0.004359,0.004146,0.105307,277.343536,14.128552,1.053071,-125.436279,0.105368,0.000000
95.230003,62.353020,-125.347321,0.004368,0.004146,0.105307,277.360077,14.129396,1.053071,-125.347321,0.105368,0.000000
95.460007,62.330307,-125.347321,0.004376,0.004146,0.105307,277.259064,14.124249,1.053071,-125.347321,0.105368,0.000000
95.690002,62.313553,-125.391800,0.004381,0.004146,0.105307,277.184540,14.120453,1.053071,-125.391800,0.105368,0.000000
95.920006,62.315041,-125.391800,0.004376,0.004146,0.105307,277.191132,14.120790,1.053071,-125.391800,0.105368,0.000000
96.150002,62.306099,-125.347321,0.004381,0.004146,0.105307,277.151367,14.118764,1.053071,-125.347321,0.105368,0.000000
96.380005,62.301262,-125.436279,0.004376,0.004146,0.105307,277.129852,14.117668,1.053071,-125.436279,0.105368,0.000000
96.600006,62.289345,-125.391800,0.004363,0.004146,0.105307,277.076843,14.114967,1.053071,-125.391800,0.105368,0.000000