File: Data/compression 6/AutoNoheating-10-6-day3-2-240301_03012024_155302.csv
Time (sec),S:Load (lbs),S:HL1 (DIM),S:LVDT (in),S:Position (in),Ch:Position (mm),Ch:Load (N),Ch:Stress (MPa),Ch:Strain (mm/mm),Ch:HL1 (DIM),Set Point (),Cycles ()
0.110000,0.011169,-115.517029,0.000013,-0.000000,-0.000000,0.049684,0.002531,-0.000000,-115.517029,0.000148,0.000000
0.340000,0.006699,-115.605995,0.000000,-0.000000,-0.000000,0.029797,0.001518,-0.000000,-115.605995,0.000148,0.000000
0.570000,0.007446,-115.694954,0.000009,0.000095,0.002411,0.033123,0.001687,0.024110,-115.694954,0.003269,0.000000
0.800000,0.016380,-115.694954,0.000095,0.000239,0.006071,0.072863,0.003712,0.060706,-115.694954,0.007085,0.000000
1.030000,0.005585,-115.650475,0.000254,0.000391,0.009930,0.024842,0.001266,0.099297,-115.650475,0.010918,0.000000
1.260000,-0.011169,-115.694954,0.000414,0.000538,0.013676,-0.049684,-0.002531,0.136763,-115.694954,0.014752,0.000000
1.490000,0.001862,-115.739433,0.000569,0.000692,0.017570,0.008281,0.000422,0.175702,-115.739433,0.018585,0.000000
1.720000,0.002609,-115.828400,0.000686,0.000833,0.021160,0.011607,0.000591,0.211602,-115.828400,0.022418,0.000000
1.950000,0.013031,-115.828400,0.000836,0.000989,0.025124,0.057965,0.002953,0.251238,-115.828400,0.026251,0.000000
2.180000,-0.015266,-115.783913,0.001013,0.001146,0.029104,-0.067908,-0.003459,0.291043,-115.783913,0.030084,0.000000
2.410000,-0.064796,-115.872879,0.001147,0.001291,0.032798,-0.288229,-0.014683,0.327984,-115.872879,0.033917,0.000000
2.640000,-0.023460,-115.872879,0.001302,0.001444,0.036675,-0.104357,-0.005316,0.366749,-115.872879,0.037751,0.000000
2.870000,0.002609,-116.050804,0.001466,0.001594,0.040500,0.011607,0.000591,0.404995,-116.050804,0.041584,0.000000
3.100000,0.039841,-115.961838,0.001604,0.001743,0.044281,0.177220,0.009028,0.442806,-115.961838,0.045417,0.000000
3.330000,0.033516,-116.006317,0.001789,0.001902,0.048322,0.149086,0.007595,0.483218,-116.006317,0.049250,0.000000
3.560000,0.002609,-116.050804,0.001910,0.002047,0.051999,0.011607,0.000591,0.519988,-116.050804,0.053083,0.000000
3.790000,-0.011917,-116.050804,0.002078,0.002198,0.055823,-0.053010,-0.002700,0.558234,-116.050804,0.056899,0.000000
4.020000,0.004471,-116.139763,0.002233,0.002351,0.059709,0.019887,0.001013,0.597086,-116.139763,0.060732,0.000000
4.250000,0.022713,-116.184242,0.002371,0.002492,0.063308,0.101031,0.005147,0.633077,-116.184242,0.064565,0.000000
4.480000,-0.010056,-116.184242,0.002518,0.002646,0.067210,-0.044729,-0.002279,0.672099,-116.184242,0.068398,0.000000
4.710000,0.002235,-116.228722,0.002669,0.002805,0.071251,0.009944,0.000507,0.712514,-116.228722,0.072231,0.000000
4.940000,-0.002983,-116.273209,0.002824,0.002954,0.075033,-0.013269,-0.000676,0.750325,-116.273209,0.076064,0.000000
5.170000,0.009308,-116.362167,0.002984,0.003105,0.078857,0.041403,0.002109,0.788568,-116.362167,0.079898,0.000000
5.400000,0.034256,-116.317688,0.003117,0.003254,0.082664,0.152378,0.007763,0.826640,-116.317688,0.083731,0.000000
5.630000,0.036865,-116.317688,0.003272,0.003402,0.086410,0.163985,0.008354,0.864103,-116.317688,0.087564,0.000000
5.860000,0.016754,-116.362167,0.003415,0.003557,0.090339,0.074526,0.003797,0.903390,-116.362167,0.091397,0.000000
6.090000,-0.002983,-116.406647,0.003579,0.003707,0.094146,-0.013269,-0.000676,0.941462,-116.406647,0.095230,0.000000
6.320000,-0.013031,-116.451126,0.003708,0.003851,0.097823,-0.057965,-0.002953,0.978233,-116.451126,0.099063,0.000000
6.550000,0.009682,-116.495613,0.003880,0.004010,0.101847,0.043066,0.002194,1.018470,-116.495613,0.102879,0.000000
6.780000,0.046173,-116.495613,0.004005,0.004150,0.105411,0.205388,0.010463,1.054112,-116.495613,0.106712,0.000000
7.010000,0.129959,-116.584572,0.004191,0.004308,0.109418,0.578087,0.029449,1.094179,-116.584572,0.110545,0.000000
7.240000,0.237572,-116.584572,0.004324,0.004464,0.113390,1.056772,0.053835,1.133898,-116.584572,0.114378,0.000000
7.470000,0.426735,-116.629051,0.004458,0.004612,0.117153,1.898212,0.096700,1.171535,-116.629051,0.118212,0.000000
7.700000,0.696335,-116.673538,0.004613,0.004738,0.120354,3.097452,0.157792,1.203536,-116.673538,0.121577,0.000000
7.930000,0.528770,-116.584572,0.004613,-0.000003,-0.000078,2.352088,0.119821,-0.000780,-116.584572,0.000139,0.000000
8.160001,0.492645,-116.673538,0.004613,-0.000003,-0.000078,2.191396,0.111635,-0.000780,-116.673538,0.000139,0.000000
8.390000,0.541054,-116.718018,0.004613,-0.000003,-0.000078,2.406727,0.122605,-0.000780,-116.718018,0.000442,0.000000
8.620001,0.533234,-116.806976,0.004618,-0.000003,-0.000078,2.371942,0.120832,-0.000780,-116.806976,0.000824,0.000000
8.850000,0.509773,-116.851456,0.004609,-0.000003,-0.000069,2.267585,0.115516,-0.000693,-116.851456,0.001205,0.000000
9.080001,0.664314,-116.851456,0.004644,0.000026,0.000668,2.955018,0.150536,0.006677,-116.851456,0.001587,0.000000
9.310000,0.698944,-116.895943,0.004644,0.000040,0.001023,3.109059,0.158383,0.010234,-116.895943,0.001977,0.000000
9.540001,0.756660,-116.940422,0.004661,0.000063,0.001596,3.365794,0.171462,0.015957,-116.940422,0.002359,0.000000
9.770000,0.787193,-116.984901,0.004678,0.000080,0.002021,3.501611,0.178381,0.020208,-116.984901,0.002741,0.000000
10.000000,0.802086,-116.940422,0.004687,0.000090,0.002298,3.567856,0.181755,0.022982,-116.940422,0.003122,0.000000
10.230000,0.826294,-117.029381,0.004700,0.000103,0.002628,3.675539,0.187241,0.026279,-117.029381,0.003504,0.000000
10.460000,0.867630,-117.073860,0.004730,0.000121,0.003061,3.859411,0.196608,0.030612,-117.073860,0.003894,0.000000
10.690001,0.900024,-117.118347,0.004756,0.000135,0.003417,4.003509,0.203948,0.034170,-117.118347,0.004275,0.000000
10.920000,0.939125,-117.162827,0.004756,0.000153,0.003876,4.177437,0.212809,0.038765,-117.162827,0.004657,0.000000
11.150001,0.961464,-117.207306,0.004764,0.000163,0.004137,4.276805,0.217871,0.041369,-117.207306,0.005038,0.000000
11.380000,0.989761,-117.207306,0.004781,0.000178,0.004510,4.402678,0.224283,0.045097,-117.207306,0.005420,0.000000
11.610001,1.041153,-117.207306,0.004799,0.000196,0.004969,4.631279,0.235929,0.049692,-117.207306,0.005811,0.000000
11.840000,1.074295,-117.207306,0.004807,0.000210,0.005342,4.778703,0.243439,0.053420,-117.207306,0.006192,0.000000
12.070001,1.078392,-117.296265,0.004833,0.000225,0.005715,4.796927,0.244367,0.057152,-117.296265,0.006574,0.000000
12.300000,1.099243,-117.340752,0.004850,0.000239,0.006062,4.889678,0.249092,0.060619,-117.340752,0.006955,0.000000
12.530001,1.142067,-117.296265,0.004850,0.000252,0.006409,5.080168,0.258796,0.064090,-117.296265,0.007337,0.000000
12.760000,1.190475,-117.340752,0.004876,0.000268,0.006817,5.295499,0.269766,0.068166,-117.340752,0.007727,0.000000
12.990001,1.241859,-117.385231,0.004902,0.000283,0.007198,5.524066,0.281409,0.071981,-117.385231,0.008109,0.000000
13.220000,1.231804,-117.474190,0.004907,0.000290,0.007371,5.479337,0.279131,0.073715,-117.474190,0.008490,0.000000
13.450001,1.339798,-117.474190,0.004919,0.000317,0.008048,5.959719,0.303603,0.080478,-117.474190,0.008872,0.000000
13.680000,1.376289,-117.518669,0.004932,0.000333,0.008455,6.122041,0.311872,0.084555,-117.518669,0.009262,0.000000
13.910001,1.379639,-117.474190,0.004971,0.000346,0.008794,6.136940,0.312631,0.087938,-117.474190,0.009644,0.000000
14.140000,1.377403,-117.607635,0.004954,0.000358,0.009097,6.126996,0.312124,0.090974,-117.607635,0.010025,0.000000
14.370001,1.420601,-117.607635,0.004975,0.000371,0.009418,6.319149,0.321913,0.094180,-117.607635,0.010407,0.000000
14.600000,1.493958,-117.652115,0.004984,0.000390,0.009912,6.645455,0.338536,0.099123,-117.652115,0.010788,0.000000
14.830001,1.530449,-117.696594,0.005027,0.000405,0.010294,6.807777,0.346805,0.102942,-117.696594,0.011179,0.000000
15.060000,1.543854,-117.652115,0.005036,0.000415,0.010537,6.867404,0.349842,0.105368,-117.652115,0.011560,0.000000
15.290001,1.595612,-117.741081,0.005062,0.000431,0.010936,7.097635,0.361571,0.109357,-117.741081,0.011942,0.000000
15.520000,1.703232,-117.785561,0.005066,0.000454,0.011534,7.576354,0.385958,0.115341,-117.785561,0.012323,0.000000
15.750001,1.695038,-117.785561,0.005092,0.000467,0.011872,7.539905,0.384101,0.118725,-117.785561,0.012705,0.000000
15.980000,1.674187,-117.874519,0.005101,0.000478,0.012141,7.447155,0.379376,0.121412,-117.874519,0.013095,0.000000
16.210001,1.690567,-117.874519,0.005092,0.000491,0.012471,7.520018,0.383088,0.124709,-117.874519,0.013477,0.000000
16.440001,1.746796,-117.874519,0.005135,0.000507,0.012878,7.770135,0.395830,0.128785,-117.874519,0.013858,0.000000
16.670000,1.852928,-117.918999,0.005144,0.000524,0.013312,8.242236,0.419880,0.133119,-117.918999,0.014240,0.000000
16.900002,1.874519,-118.007965,0.005157,0.000538,0.013668,8.338279,0.424772,0.136676,-118.007965,0.014621,0.000000
17.130001,1.863350,-118.052444,0.005170,0.000547,0.013902,8.288594,0.422241,0.139015,-118.052444,0.015012,0.000000
17.360001,1.938568,-118.007965,0.005204,0.000568,0.014431,8.623181,0.439286,0.144307,-118.007965,0.015393,0.000000
17.590000,2.039482,-118.052444,0.005208,0.000589,0.014960,9.072069,0.462153,0.149598,-118.052444,0.015775,0.000000
17.820002,2.021606,-118.141403,0.005213,0.000599,0.015202,8.992555,0.458103,0.152024,-118.141403,0.016157,0.000000
18.050001,2.059593,-118.141403,0.005247,0.000617,0.015679,9.161529,0.466711,0.156793,-118.141403,0.016538,0.000000
18.280001,2.043579,-118.141403,0.005247,0.000628,0.015940,9.090294,0.463082,0.159397,-118.141403,0.016928,0.000000
18.510000,2.140022,-118.185890,0.005277,0.000644,0.016347,9.519295,0.484936,0.163473,-118.185890,0.017310,0.000000
18.740002,2.249504,-118.230370,0.005286,0.000664,0.016859,10.006294,0.509745,0.168591,-118.230370,0.017691,0.000000
18.970001,2.202957,-118.274849,0.005307,0.000671,0.017032,9.799243,0.499197,0.170324,-118.274849,0.018073,0.000000
19.200001,2.259552,-118.363808,0.005299,0.000685,0.017388,10.050989,0.512022,0.173878,-118.363808,0.018455,0.000000
19.430000,2.386909,-118.363808,0.005338,0.000706,0.017926,10.617504,0.540881,0.179256,-118.363808,0.018845,0.000000
19.660002,2.432709,-118.319328,0.005368,0.000724,0.018394,10.821229,0.551260,0.183938,-118.319328,0.019227,0.000000
19.890001,2.357864,-118.452774,0.005372,0.000733,0.018611,10.488304,0.534300,0.186107,-118.452774,0.019608,0.000000
20.120001,2.480743,-118.408295,0.005376,0.000752,0.019105,11.034898,0.562144,0.191050,-118.408295,0.019990,0.000000
20.350000,2.509415,-118.452774,0.005385,0.000769,0.019530,11.162434,0.568642,0.195301,-118.452774,0.020371,0.000000
20.580002,2.584267,-118.452774,0.005402,0.000782,0.019851,11.495392,0.585603,0.198510,-118.452774,0.020761,0.000000
20.810001,2.624855,-118.497253,0.005437,0.000795,0.020189,11.675939,0.594801,0.201890,-118.497253,0.021143,0.000000
21.040001,2.600273,-118.541733,0.005437,0.000806,0.020475,11.566592,0.589230,0.204751,-118.541733,0.021525,0.000000
21.270000,2.770821,-118.586212,0.005467,0.000828,0.021022,12.325226,0.627877,0.210217,-118.586212,0.021906,0.000000
21.500002,2.836731,-118.675179,0.005489,0.000847,0.021507,12.618409,0.642812,0.215073,-118.675179,0.022288,0.000000
21.730001,2.796143,-118.675179,0.005497,0.000855,0.021724,12.437863,0.633615,0.217242,-118.675179,0.022678,0.000000
21.960001,2.846413,-118.675179,0.005527,0.000874,0.022201,12.661476,0.645006,0.222011,-118.675179,0.023059,0.000000
22.190001,2.907852,-118.630699,0.005523,0.000889,0.022591,12.934772,0.658929,0.225913,-118.630699,0.023441,0.000000
22.420002,3.026642,-118.808617,0.005545,0.000906,0.023016,13.463176,0.685847,0.230163,-118.808617,0.023823,0.000000
22.650002,3.047493,-118.764137,0.005549,0.000919,0.023354,13.555925,0.690572,0.233543,-118.764137,0.024213,0.000000
22.880001,2.990898,-118.808617,0.005575,0.000926,0.023511,13.304179,0.677747,0.235106,-118.808617,0.024595,0.000000
23.110001,3.089577,-118.853104,0.005575,0.000943,0.023961,13.743124,0.700108,0.239614,-118.853104,0.024976,0.000000
23.340002,3.281342,-118.853104,0.005609,0.000966,0.024534,14.596136,0.743563,0.245337,-118.853104,0.025358,0.000000
23.570002,3.276131,-118.897583,0.005627,0.000981,0.024907,14.572957,0.742382,0.249069,-118.897583,0.025739,0.000000
23.800001,3.274643,-118.986542,0.005635,0.000995,0.025262,14.566339,0.742045,0.252623,-118.986542,0.026129,0.000000
24.030001,3.349487,-118.942062,0.005661,0.001010,0.025644,14.899263,0.759005,0.256438,-118.942062,0.026511,0.000000
24.260000,3.385239,-118.942062,0.005670,0.001026,0.026051,15.058293,0.767106,0.260514,-118.942062,0.026893,0.000000
24.490002,3.452637,-119.075508,0.005691,0.001042,0.026459,15.358095,0.782379,0.264591,-119.075508,0.027274,0.000000
24.720001,3.430298,-119.075508,0.005696,0.001051,0.026702,15.258727,0.777317,0.267021,-119.075508,0.027656,0.000000
24.950001,3.574028,-119.119987,0.005721,0.001068,0.027127,15.898070,0.809886,0.271267,-119.119987,0.028046,0.000000
25.180000,3.681648,-119.119987,0.005752,0.001088,0.027638,16.376789,0.834273,0.276384,-119.119987,0.028428,0.000000
25.410002,3.675316,-119.119987,0.005777,0.001102,0.028003,16.348621,0.832838,0.280029,-119.119987,0.028809,0.000000
25.640001,3.676804,-119.164467,0.005773,0.001118,0.028402,16.355240,0.833176,0.284019,-119.164467,0.029191,0.000000
25.870001,3.690956,-119.297913,0.005777,0.001129,0.028671,16.418192,0.836383,0.286706,-119.297913,0.029573,0.000000
26.100000,3.737503,-119.253433,0.005816,0.001145,0.029078,16.625244,0.846930,0.290782,-119.253433,0.029963,0.000000
26.330002,3.852936,-119.253433,0.005829,0.001163,0.029529,17.138714,0.873088,0.295290,-119.253433,0.030344,0.000000
26.560001,3.884216,-119.297913,0.005846,0.001176,0.029876,17.277857,0.880176,0.298761,-119.297913,0.030726,0.000000
26.790001,3.925919,-119.342392,0.005846,0.001189,0.030197,17.463358,0.889626,0.301970,-119.342392,0.031107,0.000000
27.020000,4.021248,-119.431351,0.005864,0.001207,0.030665,17.887403,0.911228,0.306652,-119.431351,0.031489,0.000000
27.250002,4.064819,-119.431351,0.005890,0.001224,0.031090,18.081219,0.921101,0.310903,-119.431351,0.031879,0.000000
27.480001,4.077850,-119.475838,0.005902,0.001238,0.031454,18.139185,0.924054,0.314544,-119.475838,0.032261,0.000000
27.710001,4.026093,-119.431351,0.005937,0.001250,0.031741,17.908955,0.912326,0.317405,-119.431351,0.032642,0.000000
27.940001,4.108383,-119.520317,0.005950,0.001267,0.032174,18.275002,0.930973,0.321743,-119.520317,0.033024,0.000000
28.170002,4.216743,-119.609276,0.005967,0.001285,0.032634,18.757011,0.955528,0.326337,-119.609276,0.033405,0.000000
28.400002,4.277069,-119.609276,0.005967,0.001299,0.033007,19.025354,0.969198,0.330066,-119.609276,0.033796,0.000000
28.630001,4.191422,-119.564796,0.005997,0.001308,0.033223,18.644375,0.949790,0.332234,-119.564796,0.034178,0.000000
28.860001,4.416336,-119.653755,0.006015,0.001330,0.033779,19.644844,1.000756,0.337787,-119.653755,0.034559,0.000000
29.090002,4.486717,-119.698242,0.006023,0.001347,0.034221,19.957914,1.016705,0.342207,-119.698242,0.034941,0.000000
29.320002,4.437187,-119.742722,0.006045,0.001360,0.034533,19.737595,1.005481,0.345330,-119.742722,0.035322,0.000000
29.550001,4.399582,-119.742722,0.006058,0.001373,0.034871,19.570318,0.996960,0.348714,-119.742722,0.035712,0.000000
29.780001,4.458786,-119.742722,0.006071,0.001387,0.035235,19.833672,1.010375,0.352355,-119.742722,0.036094,0.000000
30.010002,4.504219,-119.831680,0.006079,0.001401,0.035591,20.035767,1.020671,0.355909,-119.831680,0.036475,0.000000
30.240002,4.640129,-119.876160,0.006114,0.001418,0.036025,20.640326,1.051468,0.360246,-119.876160,0.036857,0.000000
30.470001,4.706787,-119.965126,0.006109,0.001434,0.036424,20.936834,1.066573,0.364236,-119.965126,0.037239,0.000000
30.700001,4.645348,-119.965126,0.006135,0.001444,0.036675,20.663538,1.052651,0.366749,-119.965126,0.037629,0.000000
30.930002,4.747375,-119.965126,0.006153,0.001461,0.037100,21.117380,1.075771,0.370999,-119.965126,0.038011,0.000000
31.160002,4.866905,-119.965126,0.006183,0.001480,0.037603,21.649076,1.102857,0.376029,-119.965126,0.038392,0.000000
31.390001,4.859459,-120.009605,0.006200,0.001493,0.037915,21.615953,1.101169,0.379152,-120.009605,0.038774,0.000000
31.620001,4.853127,-120.098564,0.006213,0.001507,0.038271,21.587786,1.099734,0.382706,-120.098564,0.039164,0.000000
31.850002,4.952553,-120.054085,0.006230,0.001523,0.038687,22.030056,1.122265,0.386869,-120.054085,0.039546,0.000000
32.080002,5.015480,-120.143051,0.006243,0.001539,0.039103,22.309969,1.136524,0.391033,-120.143051,0.039927,0.000000
32.310001,5.054581,-120.143051,0.006265,0.001555,0.039502,22.483898,1.145384,0.395022,-120.143051,0.040309,0.000000
32.540001,4.964844,-120.187531,0.006260,0.001563,0.039702,22.084728,1.125050,0.397017,-120.187531,0.040690,0.000000
32.770000,5.140976,-120.232010,0.006273,0.001583,0.040196,22.868202,1.164962,0.401960,-120.232010,0.041080,0.000000
33.000000,5.249336,-120.232010,0.006299,0.001600,0.040638,23.350214,1.189517,0.406384,-120.232010,0.041462,0.000000
33.230003,5.235558,-120.276489,0.006321,0.001613,0.040976,23.288923,1.186394,0.409764,-120.276489,0.041844,0.000000
33.460003,5.311523,-120.276489,0.006347,0.001630,0.041393,23.626837,1.203608,0.413927,-120.276489,0.042225,0.000000
33.690002,5.238159,-120.365456,0.006355,0.001641,0.041688,23.300495,1.186984,0.416876,-120.365456,0.042607,0.000000
33.920002,5.334976,-120.365456,0.006355,0.001656,0.042052,23.731159,1.208923,0.420517,-120.365456,0.042997,0.000000
34.150002,5.456741,-120.409935,0.006381,0.001672,0.042477,24.272799,1.236515,0.424767,-120.409935,0.043379,0.000000
34.380001,5.432541,-120.454414,0.006420,0.001684,0.042780,24.165150,1.231031,0.427803,-120.454414,0.043760,0.000000
34.610001,5.463448,-120.409935,0.006420,0.001697,0.043110,24.302629,1.238035,0.431100,-120.409935,0.044142,0.000000
34.840000,5.713310,-120.543381,0.006450,0.001719,0.043656,25.414074,1.294655,0.436561,-120.543381,0.044523,0.000000
35.070004,5.704002,-120.587860,0.006472,0.001734,0.044046,25.372669,1.292545,0.440463,-120.587860,0.044914,0.000000
35.300003,5.739372,-120.543381,0.006476,0.001750,0.044454,25.530003,1.300560,0.444540,-120.543381,0.045295,0.000000
35.530003,5.783318,-120.587860,0.006489,0.001765,0.044835,25.725481,1.310519,0.448355,-120.587860,0.045677,0.000000
35.760002,5.834328,-120.676819,0.006519,0.001778,0.045174,25.952385,1.322078,0.451739,-120.676819,0.046058,0.000000
35.990002,5.964661,-120.676819,0.006523,0.001796,0.045608,26.532135,1.351611,0.456076,-120.676819,0.046440,0.000000
36.220001,5.933754,-120.721298,0.006541,0.001807,0.045902,26.394655,1.344608,0.459024,-120.721298,0.046830,0.000000
36.450001,5.790390,-120.676819,0.006554,0.001815,0.046102,25.756941,1.312121,0.461019,-120.676819,0.047212,0.000000
36.680000,5.992958,-120.765785,0.006579,0.001834,0.046588,26.658009,1.358024,0.465875,-120.765785,0.047594,0.000000
36.910000,6.281921,-120.810265,0.006592,0.001856,0.047151,27.943382,1.423504,0.471511,-120.810265,0.047975,0.000000
37.140003,6.226440,-120.810265,0.006614,0.001869,0.047481,27.696590,1.410932,0.474808,-120.810265,0.048357,0.000000
37.370003,6.237984,-120.854744,0.006635,0.001884,0.047854,27.747938,1.413547,0.478536,-120.854744,0.048747,0.000000
37.600002,6.218246,-120.854744,0.006640,0.001896,0.048148,27.660141,1.409075,0.481484,-120.854744,0.049128,0.000000
37.830002,6.381721,-120.899223,0.006657,0.001911,0.048539,28.387316,1.446119,0.485386,-120.899223,0.049510,0.000000
38.060001,6.557480,-120.943703,0.006666,0.001927,0.048946,29.169127,1.485946,0.489463,-120.943703,0.049892,0.000000
38.290001,6.502739,-121.077148,0.006700,0.001938,0.049232,28.925627,1.473542,0.492324,-121.077148,0.050273,0.000000
38.520000,6.690414,-121.032669,0.006691,0.001956,0.049675,29.760450,1.516070,0.496749,-121.032669,0.050663,0.000000
38.750000,6.763771,-120.988190,0.006726,0.001971,0.050065,30.086756,1.532692,0.500651,-120.988190,0.051045,0.000000
38.980003,6.966713,-121.032669,0.006748,0.001992,0.050585,30.989487,1.578680,0.505855,-121.032669,0.051427,0.000000
39.210003,6.843460,-121.166107,0.006765,0.002002,0.050854,30.441231,1.550750,0.508542,-121.166107,0.051808,0.000000
39.440002,6.895966,-121.166107,0.006782,0.002018,0.051253,30.674788,1.562648,0.512532,-121.166107,0.052198,0.000000
39.670002,6.793564,-121.210594,0.006791,0.002028,0.051504,30.219282,1.539443,0.515045,-121.210594,0.052580,0.000000
39.900002,7.196838,-121.166107,0.006799,0.002048,0.052016,32.013138,1.630827,0.520162,-121.166107,0.052962,0.000000
40.130001,7.310417,-121.255074,0.006825,0.002064,0.052424,32.518360,1.656564,0.524238,-121.255074,0.053343,0.000000
40.360001,7.045662,-121.344032,0.006825,0.002071,0.052606,31.340670,1.596570,0.526059,-121.344032,0.053725,0.000000
40.590000,7.181946,-121.344032,0.006851,0.002083,0.052909,31.946890,1.627452,0.529094,-121.344032,0.054115,0.000000
40.820004,7.699173,-121.344032,0.006868,0.002110,0.053594,34.247631,1.744658,0.535945,-121.344032,0.054496,0.000000
41.050003,7.719276,-121.388512,0.006890,0.002125,0.053985,34.337055,1.749213,0.539847,-121.388512,0.054878,0.000000
41.280003,7.695824,-121.388512,0.006898,0.002139,0.054340,34.232735,1.743899,0.543405,-121.388512,0.055260,0.000000
41.510002,7.708107,-121.432999,0.006929,0.002152,0.054653,34.287373,1.746682,0.546528,-121.432999,0.055641,0.000000
41.740002,7.952385,-121.477478,0.006920,0.002169,0.055104,35.373974,1.802036,0.551035,-121.477478,0.056032,0.000000
41.970001,7.946053,-121.521957,0.006937,0.002182,0.055433,35.345806,1.800601,0.554332,-121.521957,0.056413,0.000000
42.200001,8.016434,-121.566437,0.006972,0.002195,0.055762,35.658878,1.816550,0.557625,-121.566437,0.056795,0.000000
42.430000,8.149368,-121.610924,0.006980,0.002208,0.056083,36.250202,1.846673,0.560834,-121.610924,0.057176,0.000000
42.660004,8.757828,-121.610924,0.007011,0.002234,0.056743,38.956764,1.984552,0.567428,-121.610924,0.057558,0.000000
42.890003,8.688568,-121.699883,0.007015,0.002250,0.057150,38.648682,1.968858,0.571504,-121.699883,0.057948,0.000000
43.120003,8.572388,-121.610924,0.007036,0.002263,0.057480,38.131886,1.942531,0.574797,-121.610924,0.058330,0.000000
43.350002,8.658028,-121.655403,0.007049,0.002277,0.057827,38.512829,1.961937,0.578268,-121.655403,0.058711,0.000000
43.580002,8.812569,-121.699883,0.007067,0.002292,0.058226,39.200264,1.996957,0.582257,-121.699883,0.059093,0.000000
43.810001,9.101898,-121.833328,0.007084,0.002308,0.058633,40.487267,2.062520,0.586333,-121.833328,0.059474,0.000000
44.040001,9.113815,-121.788841,0.007084,0.002321,0.058945,40.540276,2.065220,0.589452,-121.788841,0.059865,0.000000
44.270000,9.226646,-121.833328,0.007105,0.002335,0.059310,41.042171,2.090788,0.593097,-121.833328,0.060246,0.000000
44.500004,9.408737,-121.833328,0.007114,0.002348,0.059648,41.852154,2.132050,0.596477,-121.833328,0.060628,0.000000
44.730003,9.680939,-121.877808,0.007144,0.002367,0.060125,43.062965,2.193732,0.601250,-121.877808,0.061009,0.000000
44.960003,9.648170,-122.011246,0.007157,0.002380,0.060454,42.917206,2.186307,0.604542,-122.011246,0.061391,0.000000
45.190002,9.769936,-122.011246,0.007161,0.002396,0.060862,43.458843,2.213899,0.608619,-122.011246,0.061781,0.000000
45.420002,9.965431,-121.966766,0.007196,0.002414,0.061313,44.328453,2.258199,0.613130,-121.966766,0.062163,0.000000
45.650002,10.280083,-121.966766,0.007213,0.002430,0.061712,45.728092,2.329500,0.617120,-121.966766,0.062544,0.000000
45.880001,10.369453,-122.055733,0.007230,0.002444,0.062067,46.125633,2.349752,0.620674,-122.055733,0.062926,0.000000
46.110001,10.215294,-122.100212,0.007243,0.002454,0.062327,45.439896,2.314819,0.623274,-122.100212,0.063308,0.000000
46.340004,10.465157,-122.100212,0.007239,0.002470,0.062735,46.551342,2.371438,0.627350,-122.100212,0.063698,0.000000
46.570004,11.139893,-122.144691,0.007261,0.002492,0.063299,49.552715,2.524336,0.632990,-122.144691,0.064079,0.000000
46.800003,10.992432,-122.233650,0.007265,0.002504,0.063603,48.896778,2.490921,0.636025,-122.233650,0.064461,0.000000
47.030003,11.254211,-122.144691,0.007282,0.002520,0.064010,50.061234,2.550241,0.640101,-122.144691,0.064842,0.000000
47.260002,11.293312,-122.233650,0.007308,0.002533,0.064348,50.235161,2.559101,0.643481,-122.233650,0.065224,0.000000
47.490002,11.472054,-122.278137,0.007330,0.002549,0.064738,51.030243,2.599605,0.647384,-122.278137,0.065614,0.000000
47.720001,11.831764,-122.278137,0.007343,0.002565,0.065146,52.630318,2.681116,0.651460,-122.278137,0.065996,0.000000
47.950001,11.933044,-122.322617,0.007347,0.002578,0.065484,53.080833,2.704067,0.654844,-122.322617,0.066378,0.000000
48.180004,12.160568,-122.367096,0.007373,0.002593,0.065875,54.092911,2.755624,0.658746,-122.367096,0.066759,0.000000
48.410004,12.621933,-122.367096,0.007399,0.002612,0.066343,56.145161,2.860171,0.663428,-122.367096,0.067149,0.000000
48.640003,12.985374,-122.456055,0.007390,0.002630,0.066794,57.761829,2.942528,0.667939,-122.456055,0.067531,0.000000
48.870003,12.879242,-122.500542,0.007416,0.002642,0.067106,57.289730,2.918478,0.671058,-122.500542,0.067912,0.000000
49.100002,12.903450,-122.456055,0.007420,0.002654,0.067418,57.397411,2.923964,0.674181,-122.456055,0.068294,0.000000
49.330002,13.284012,-122.545021,0.007450,0.002668,0.067765,59.090237,3.010200,0.677651,-122.545021,0.068676,0.000000
49.560001,13.852631,-122.589500,0.007455,0.002688,0.068268,61.619579,3.139051,0.682682,-122.589500,0.069066,0.000000
49.790001,14.034714,-122.545021,0.007480,0.002702,0.068624,62.429523,3.180312,0.686236,-122.545021,0.069448,0.000000
50.020004,14.045143,-122.589500,0.007476,0.002715,0.068953,62.475918,3.182675,0.689532,-122.589500,0.069829,0.000000
50.250004,14.625298,-122.678467,0.007506,0.002731,0.069378,65.056572,3.314140,0.693783,-122.678467,0.070211,0.000000
50.480003,15.070656,-122.722946,0.007528,0.002749,0.069829,67.037628,3.415059,0.698290,-122.722946,0.070592,0.000000
50.710003,15.126884,-122.767426,0.007528,0.002761,0.070133,67.287743,3.427801,0.701326,-122.767426,0.070982,0.000000
50.940002,15.358871,-122.767426,0.007537,0.002775,0.070497,68.319672,3.480370,0.704967,-122.767426,0.071364,0.000000
51.170002,15.767365,-122.811905,0.007567,0.002792,0.070904,70.136742,3.572936,0.709043,-122.811905,0.071746,0.000000
51.400002,16.099892,-122.811905,0.007575,0.002806,0.071278,71.615898,3.648288,0.712775,-122.811905,0.072127,0.000000
51.630001,16.565735,-122.856384,0.007584,0.002822,0.071685,73.688072,3.753849,0.716848,-122.856384,0.072509,0.000000
51.860001,16.649887,-122.900871,0.007610,0.002833,0.071954,74.062393,3.772918,0.719539,-122.900871,0.072899,0.000000
52.090004,16.928055,-122.856384,0.007597,0.002848,0.072327,75.299751,3.835952,0.723267,-122.856384,0.073280,0.000000
52.320004,17.614708,-122.900871,0.007610,0.002867,0.072830,78.354134,3.991550,0.728297,-122.900871,0.073662,0.000000
52.550003,18.058205,-122.900871,0.007644,0.002883,0.073229,80.326904,4.092048,0.732286,-122.900871,0.074044,0.000000
52.780003,18.052246,-123.034309,0.007653,0.002896,0.073558,80.300400,4.090697,0.735583,-123.034309,0.074425,0.000000
53.010002,18.475632,-123.034309,0.007662,0.002910,0.073914,82.183716,4.186638,0.739137,-123.034309,0.074816,0.000000
53.240002,19.167870,-123.078789,0.007675,0.002928,0.074364,85.262939,4.343501,0.743645,-123.078789,0.075197,0.000000
53.470001,19.669083,-123.078789,0.007675,0.002944,0.074772,87.492447,4.457078,0.747721,-123.078789,0.075579,0.000000
53.700001,20.055611,-123.034309,0.007709,0.002959,0.075154,89.211815,4.544666,0.751540,-123.034309,0.075960,0.000000
53.930004,20.010925,-123.123276,0.007709,0.002968,0.075379,89.013039,4.534540,0.753792,-123.123276,0.076342,0.000000
54.160004,20.773911,-123.256714,0.007735,0.002985,0.075830,92.406967,4.707435,0.758304,-123.256714,0.076732,0.000000
54.390003,21.344765,-123.212234,0.007735,0.003003,0.076264,94.946259,4.836793,0.762637,-123.212234,0.077114,0.000000
54.620003,21.640053,-123.256714,0.007756,0.003015,0.076576,96.259766,4.903706,0.765760,-123.256714,0.077495,0.000000
54.850002,22.272339,-123.301193,0.007756,0.003032,0.077010,99.072311,5.046984,0.770097,-123.301193,0.077877,0.000000
55.080002,22.475281,-123.345680,0.007774,0.003043,0.077305,99.975044,5.092971,0.773046,-123.345680,0.078258,0.000000
55.310001,23.113159,-123.390160,0.007791,0.003060,0.077712,102.812469,5.237517,0.777122,-123.390160,0.078649,0.000000
55.540001,23.976318,-123.345680,0.007800,0.003077,0.078154,106.651993,5.433111,0.781543,-123.345680,0.079030,0.000000
55.770004,23.829605,-123.434639,0.007804,0.003084,0.078337,105.999374,5.399866,0.783367,-123.434639,0.079412,0.000000
56.000004,24.490189,-123.479118,0.007825,0.003103,0.078822,108.937798,5.549556,0.788223,-123.479118,0.079794,0.000000
56.230003,25.821426,-123.523598,0.007851,0.003124,0.079342,114.859444,5.851219,0.793424,-123.523598,0.080175,0.000000
56.460003,26.333061,-123.523598,0.007864,0.003138,0.079716,117.135307,5.967157,0.797156,-123.523598,0.080565,0.000000
56.690002,26.800766,-123.568085,0.007864,0.003152,0.080071,119.215759,6.073140,0.800710,-123.568085,0.080947,0.000000
56.920002,27.315384,-123.568085,0.007856,0.003166,0.080427,121.504898,6.189754,0.804267,-123.568085,0.081328,0.000000
57.150002,27.812500,-123.568085,0.007881,0.003179,0.080756,123.716179,6.302403,0.807560,-123.568085,0.081710,0.000000
57.380001,28.582565,-123.657043,0.007903,0.003197,0.081198,127.141602,6.476902,0.811985,-123.657043,0.082100,0.000000
57.610004,29.068886,-123.701523,0.007890,0.003209,0.081519,129.304855,6.587103,0.815194,-123.701523,0.082482,0.000000
57.840004,29.431946,-123.701523,0.007907,0.003224,0.081892,130.919830,6.669374,0.818923,-123.701523,0.082863,0.000000
58.070004,30.359901,-123.701523,0.007925,0.003240,0.082309,135.047592,6.879652,0.823086,-123.701523,0.083245,0.000000
58.300003,31.486694,-123.746002,0.007929,0.003259,0.082777,140.059814,7.134987,0.827768,-123.746002,0.083626,0.000000
58.530003,32.010254,-123.790489,0.007942,0.003273,0.083123,142.388718,7.253627,0.831235,-123.790489,0.084017,0.000000
58.760002,32.535301,-123.834969,0.007963,0.003286,0.083453,144.724243,7.372605,0.834531,-123.834969,0.084399,0.000000
58.990002,32.963524,-123.879448,0.007976,0.003297,0.083748,146.629074,7.469641,0.837480,-123.879448,0.084780,0.000000
59.220001,34.269806,-123.834969,0.007959,0.003317,0.084251,152.439713,7.765649,0.842510,-123.834969,0.085162,0.000000
59.450005,35.083069,-123.968414,0.007989,0.003333,0.084667,156.057281,7.949937,0.846673,-123.968414,0.085543,0.000000
59.680004,35.125893,-123.923927,0.008002,0.003338,0.084798,156.247772,7.959641,0.847975,-123.923927,0.085933,0.000000
59.910004,36.074699,-124.057373,0.007994,0.003356,0.085231,160.468277,8.174644,0.852309,-124.057373,0.086315,0.000000
60.140003,37.057388,-124.012894,0.008015,0.003374,0.085699,164.839493,8.397325,0.856995,-124.012894,0.086696,0.000000
60.370003,38.396812,-124.057373,0.008015,0.003392,0.086150,170.797546,8.700842,0.861503,-124.057373,0.087078,0.000000
60.600002,38.741257,-124.101852,0.008037,0.003402,0.086419,172.329712,8.778893,0.864190,-124.101852,0.087460,0.000000
60.830002,39.894867,-124.190819,0.008054,0.003422,0.086931,177.461227,9.040306,0.869307,-124.190819,0.087850,0.000000
61.060001,40.452309,-124.146332,0.008054,0.003435,0.087252,179.940857,9.166624,0.872517,-124.146332,0.088232,0.000000
61.290005,41.939568,-124.190819,0.008058,0.003455,0.087755,186.556519,9.503642,0.877547,-124.190819,0.088613,0.000000
61.520004,42.435196,-124.190819,0.008071,0.003465,0.088015,188.761185,9.615952,0.880147,-124.190819,0.088995,0.000000
61.750004,42.671280,-124.235298,0.008084,0.003476,0.088301,189.811340,9.669451,0.883008,-124.235298,0.089377,0.000000
61.980003,43.289040,-124.279778,0.008080,0.003488,0.088587,192.559265,9.809436,0.885870,-124.279778,0.089767,0.000000
62.210003,45.501305,-124.368736,0.008093,0.003513,0.089238,202.399918,10.310742,0.892376,-124.368736,0.090148,0.000000
62.440002,46.585655,-124.324257,0.008093,0.003528,0.089602,207.223343,10.556460,0.896017,-124.324257,0.090530,0.000000
62.670002,47.197090,-124.368736,0.008110,0.003542,0.089957,209.943146,10.695014,0.899575,-124.368736,0.090911,0.000000
62.900002,47.899384,-124.413223,0.008119,0.003555,0.090287,213.067093,10.854156,0.902868,-124.413223,0.091293,0.000000
63.130005,49.370255,-124.413223,0.008127,0.003573,0.090747,219.609863,11.187459,0.907466,-124.413223,0.091683,0.000000
63.360004,49.983925,-124.457703,0.008132,0.003583,0.090998,222.339600,11.326519,0.909980,-124.457703,0.092065,0.000000
63.590004,50.716011,-124.502182,0.008144,0.003594,0.091293,225.596085,11.492413,0.912928,-124.502182,0.092446,0.000000
63.820004,51.605606,-124.502182,0.008149,0.003607,0.091622,229.553207,11.693997,0.916225,-124.502182,0.092828,0.000000
64.050003,53.887878,-124.546661,0.008175,0.003636,0.092342,239.705261,12.211167,0.923424,-124.546661,0.093209,0.000000
64.280006,55.048935,-124.680107,0.008175,0.003650,0.092715,244.869888,12.474267,0.927152,-124.680107,0.093600,0.000000
64.510002,55.788094,-124.635628,0.008166,0.003664,0.093054,248.157837,12.641763,0.930535,-124.635628,0.093981,0.000000
64.740005,56.695198,-124.635628,0.008188,0.003675,0.093348,252.192841,12.847316,0.933484,-124.635628,0.094363,0.000000
64.970001,57.652191,-124.635628,0.008192,0.003691,0.093756,256.449768,13.064174,0.937556,-124.635628,0.094745,0.000000
65.200005,59.247437,-124.680107,0.008196,0.003708,0.094181,263.545746,13.425661,0.941807,-124.680107,0.095126,0.000000
65.430000,60.132568,-124.769066,0.008218,0.003719,0.094467,267.483032,13.626235,0.944668,-124.769066,0.095516,0.000000
65.660004,61.203506,-124.813545,0.008213,0.003734,0.094840,272.246796,13.868913,0.948400,-124.813545,0.095898,0.000000
65.889999,62.294189,-124.769066,0.008222,0.003749,0.095230,277.098389,14.116065,0.952302,-124.769066,0.096279,0.000000
66.120003,63.932632,-124.813545,0.008231,0.003769,0.095742,284.386566,14.487342,0.957419,-124.813545,0.096661,0.000000
66.350006,64.790939,-124.858032,0.008244,0.003781,0.096037,288.204498,14.681837,0.960368,-124.858032,0.097051,0.000000
66.580002,66.122925,-124.902512,0.008257,0.003798,0.096470,294.129456,14.983669,0.964702,-124.902512,0.097433,0.000000
66.810005,67.712585,-124.946991,0.008252,0.003812,0.096826,301.200623,15.343891,0.968259,-124.946991,0.097797,0.000000
67.040001,67.311157,-124.902512,0.008278,0.003806,0.096661,299.414978,15.252926,0.966609,-124.902512,0.096921,0.000000
67.270004,66.788727,-124.902512,0.008278,0.003804,0.096609,297.091095,15.134542,0.966091,-124.902512,0.096661,0.000000
67.500000,66.418213,-125.035950,0.008269,0.003802,0.096583,295.442963,15.050583,0.965829,-125.035950,0.096661,0.000000
67.730003,66.080093,-125.080437,0.008274,0.003802,0.096566,293.938934,14.973964,0.965655,-125.080437,0.096661,0.000000
67.960007,65.797089,-125.080437,0.008278,0.003802,0.096566,292.680054,14.909834,0.965655,-125.080437,0.096661,0.000000
68.190002,65.529358,-125.080437,0.008282,0.003801,0.096557,291.489136,14.849164,0.965568,-125.080437,0.096661,0.000000
68.420006,65.312637,-125.124916,0.008282,0.003801,0.096557,290.525116,14.800055,0.965568,-125.124916,0.096661,0.000000
68.650002,65.104111,-125.213875,0.008287,0.003801,0.096548,289.597534,14.752803,0.965481,-125.213875,0.096661,0.000000
68.880005,64.921280,-125.258362,0.008291,0.003801,0.096548,288.784271,14.711372,0.965481,-125.258362,0.096661,0.000000
69.110001,64.748123,-125.258362,0.008282,0.003801,0.096548,288.014038,14.672134,0.965481,-125.258362,0.096661,0.000000
69.340004,64.590240,-125.169395,0.008295,0.003801,0.096548,287.311737,14.636357,0.965481,-125.169395,0.096661,0.000000
69.570000,64.450226,-125.258362,0.008300,0.003801,0.096548,286.688934,14.604630,0.965481,-125.258362,0.096661,0.000000
69.800003,64.311325,-125.391800,0.008274,0.003801,0.096548,286.071075,14.573154,0.965481,-125.391800,0.096661,0.000000
70.030006,64.190308,-125.436279,0.008282,0.003801,0.096548,285.532745,14.545732,0.965481,-125.436279,0.096661,0.000000
70.260002,64.065933,-125.480766,0.008291,0.003801,0.096540,284.979492,14.517549,0.965398,-125.480766,0.096661,0.000000
70.490005,63.953857,-125.436279,0.008295,0.003801,0.096540,284.480957,14.492151,0.965398,-125.436279,0.096661,0.000000
70.720001,63.855911,-125.436279,0.008295,0.003801,0.096540,284.045288,14.469956,0.965398,-125.436279,0.096661,0.000000
70.950005,63.745697,-125.525246,0.008295,0.003801,0.096540,283.555023,14.444982,0.965398,-125.525246,0.096661,0.000000
71.180000,63.660416,-125.525246,0.008300,0.003801,0.096540,283.175659,14.425656,0.965398,-125.525246,0.096661,0.000000
71.410004,63.575897,-125.525246,0.008287,0.003801,0.096540,282.799713,14.406505,0.965398,-125.525246,0.096661,0.000000
71.640007,63.501053,-125.525246,0.008295,0.003801,0.096540,282.466797,14.389544,0.965398,-125.525246,0.096661,0.000000
71.870003,63.412048,-125.569725,0.008287,0.003801,0.096540,282.070892,14.369376,0.965398,-125.569725,0.096661,0.000000
72.100006,63.347260,-125.658684,0.008295,0.003801,0.096540,281.782684,14.354694,0.965398,-125.658684,0.096661,0.000000
72.330002,63.269806,-125.703171,0.008304,0.003801,0.096540,281.438141,14.337143,0.965398,-125.703171,0.096661,0.000000
72.560005,63.195709,-125.703171,0.008304,0.003801,0.096540,281.108551,14.320353,0.965398,-125.703171,0.096661,0.000000
72.790001,63.130157,-125.703171,0.008295,0.003801,0.096540,280.816956,14.305498,0.965398,-125.703171,0.096661,0.000000
73.020004,63.076172,-125.792130,0.008291,0.003801,0.096540,280.576813,14.293265,0.965398,-125.792130,0.096661,0.000000
73.250000,63.005417,-125.836609,0.008287,0.003801,0.096540,280.262085,14.277232,0.965398,-125.836609,0.096661,0.000000
73.480003,62.943230,-125.836609,0.008282,0.003801,0.096540,279.985474,14.263140,0.965398,-125.836609,0.096661,0.000000
73.710007,62.902275,-125.836609,0.008300,0.003801,0.096540,279.803284,14.253860,0.965398,-125.836609,0.096661,0.000000
73.940002,62.846786,-125.881088,0.008304,0.003801,0.096540,279.556458,14.241285,0.965398,-125.881088,0.096661,0.000000
74.170006,62.788696,-125.881088,0.008300,0.003801,0.096540,279.298065,14.228122,0.965398,-125.881088,0.096661,0.000000
74.400002,62.736565,-125.881088,0.008304,0.003801,0.096540,279.066162,14.216310,0.965398,-125.881088,0.096661,0.000000
74.630005,62.694862,-126.059013,0.008304,0.003801,0.096540,278.880676,14.206859,0.965398,-126.059013,0.096661,0.000000
74.860001,62.641243,-125.970055,0.008300,0.003801,0.096540,278.642151,14.194709,0.965398,-125.970055,0.096661,0.000000
75.090004,62.596924,-125.970055,0.008304,0.003801,0.096540,278.445038,14.184666,0.965398,-125.970055,0.096661,0.000000
75.320007,62.557083,-126.059013,0.008304,0.003801,0.096540,278.267792,14.175638,0.965398,-126.059013,0.096661,0.000000
75.550003,62.516121,-126.147980,0.008313,0.003801,0.096540,278.085602,14.166355,0.965398,-126.147980,0.096661,0.000000
75.780006,62.457657,-126.103493,0.008295,0.003801,0.096540,277.825531,14.153107,0.965398,-126.103493,0.096661,0.000000
76.010002,62.416328,-126.192459,0.008308,0.003801,0.096540,277.641693,14.143742,0.965398,-126.192459,0.096661,0.000000
76.240005,62.383926,-126.192459,0.008300,0.003801,0.096540,277.497559,14.136400,0.965398,-126.192459,0.096661,0.000000
76.470001,62.336266,-126.192459,0.008304,0.003801,0.096540,277.285553,14.125600,0.965398,-126.192459,0.096661,0.000000
76.700005,62.297913,-126.236938,0.008308,0.003801,0.096540,277.114960,14.116909,0.965398,-126.236938,0.096661,0.000000
76.930000,62.262161,-126.325897,0.008304,0.003801,0.096540,276.955933,14.108808,0.965398,-126.325897,0.096661,0.000000
77.160004,62.228653,-126.325897,0.008295,0.003801,0.096540,276.806885,14.101213,0.965398,-126.325897,0.096661,0.000000
77.390007,62.195511,-126.325897,0.008304,0.003801,0.096540,276.659454,14.093704,0.965398,-126.325897,0.096661,0.000000
77.620003,62.156784,-126.370384,0.008295,0.003801,0.096540,276.487183,14.084929,0.965398,-126.370384,0.096661,0.000000
77.850006,62.119919,-126.414864,0.008304,0.003801,0.096540,276.323212,14.076575,0.965398,-126.414864,0.096661,0.000000
78.080002,62.085289,-126.503822,0.008300,0.003801,0.096540,276.169159,14.068727,0.965398,-126.503822,0.096661,0.000000
78.310005,62.054756,-126.459343,0.008295,0.003801,0.096540,276.033356,14.061810,0.965398,-126.459343,0.096661,0.000000
78.540001,62.021980,-126.503822,0.008304,0.003801,0.096540,275.887543,14.054381,0.965398,-126.503822,0.096661,0.000000
78.770004,61.989586,-126.548309,0.008295,0.003801,0.096540,275.743439,14.047041,0.965398,-126.548309,0.096661,0.000000
79.000000,61.959053,-126.637268,0.008304,0.003801,0.096540,275.607635,14.040122,0.965398,-126.637268,0.096661,0.000000
79.230003,61.928894,-126.681747,0.008308,0.003801,0.096540,275.473480,14.033288,0.965398,-126.681747,0.096661,0.000000
79.460007,61.902077,-126.637268,0.008317,0.003801,0.096540,275.354187,14.027211,0.965398,-126.637268,0.096661,0.000000
79.690002,61.866333,-126.637268,0.008308,0.003801,0.096540,275.195190,14.019112,0.965398,-126.637268,0.096661,0.000000
79.920006,61.850319,-126.681747,0.008308,0.003801,0.096540,275.123962,14.015483,0.965398,-126.681747,0.096661,0.000000
80.150002,61.816437,-126.726227,0.008304,0.003801,0.096540,274.973236,14.007805,0.965398,-126.726227,0.096661,0.000000
80.380005,61.789627,-126.770714,0.008300,0.003801,0.096540,274.853973,14.001730,0.965398,-126.770714,0.096661,0.000000
80.610001,61.752014,-126.815193,0.008304,0.003801,0.096540,274.686676,13.993206,0.965398,-126.815193,0.096661,0.000000
80.840004,61.736374,-126.770714,0.008313,0.003801,0.096540,274.617096,13.989662,0.965398,-126.770714,0.096661,0.000000
81.070007,61.707329,-126.859673,0.008313,0.003801,0.096540,274.487915,13.983080,0.965398,-126.859673,0.096661,0.000000
81.300003,61.674934,-126.993118,0.008295,0.003801,0.096540,274.343811,13.975740,0.965398,-126.993118,0.096661,0.000000
81.530006,61.639931,-126.948631,0.008308,0.003801,0.096540,274.188110,13.967808,0.965398,-126.948631,0.096661,0.000000
81.760002,61.630249,-126.904152,0.008313,0.003801,0.096540,274.145050,13.965614,0.965398,-126.904152,0.096661,0.000000
81.990005,61.607536,-126.993118,0.008321,0.003801,0.096540,274.044006,13.960467,0.965398,-126.993118,0.096661,0.000000
82.220001,61.573273,-127.037598,0.008317,0.003801,0.096540,273.891602,13.952703,0.965398,-127.037598,0.096661,0.000000
82.450005,61.553169,-127.082077,0.008317,0.003801,0.096540,273.802185,13.948148,0.965398,-127.082077,0.096661,0.000000
82.680000,61.533058,-127.037598,0.008308,0.003801,0.096540,273.712708,13.943590,0.965398,-127.037598,0.096661,0.000000
82.910004,61.511459,-127.082077,0.008304,0.003801,0.096540,273.616638,13.938696,0.965398,-127.082077,0.096661,0.000000
83.140007,61.477203,-127.082077,0.008304,0.003801,0.096540,273.464264,13.930934,0.965398,-127.082077,0.096661,0.000000
83.370003,61.451508,-127.126556,0.008313,0.003801,0.096540,273.349945,13.925111,0.965398,-127.126556,0.096661,0.000000
83.600006,61.419861,-127.215523,0.008304,0.003801,0.096540,273.209198,13.917940,0.965398,-127.215523,0.096661,0.000000
83.830002,61.397514,-127.304482,0.008313,0.003801,0.096540,273.109772,13.912876,0.965398,-127.304482,0.096661,0.000000
84.060005,61.380386,-127.260002,0.008326,0.003801,0.096540,273.033600,13.908994,0.965398,-127.260002,0.096661,0.000000
84.290001,61.373680,-127.260002,0.008321,0.003801,0.096540,273.003754,13.907475,0.965398,-127.260002,0.096661,0.000000
84.520004,61.334953,-127.260002,0.008308,0.003801,0.096540,272.831512,13.898699,0.965398,-127.260002,0.096661,0.000000
84.750008,61.298462,-127.348961,0.008313,0.003801,0.096540,272.669189,13.890429,0.965398,-127.348961,0.096661,0.000000
84.980003,61.297348,-127.437927,0.008313,0.003801,0.096540,272.664215,13.890177,0.965398,-127.437927,0.096661,0.000000
85.210007,61.270912,-127.393440,0.008308,0.003801,0.096540,272.546631,13.884187,0.965398,-127.393440,0.096661,0.000000
85.440002,61.248566,-127.482407,0.008300,0.003800,0.096531,272.447235,13.879124,0.965311,-127.482407,0.096661,0.000000
85.670006,61.233673,-127.437927,0.008304,0.003800,0.096531,272.380981,13.875749,0.965311,-127.437927,0.096661,0.000000
85.900002,61.205002,-127.571365,0.008308,0.003800,0.096531,272.253448,13.869251,0.965311,-127.571365,0.096661,0.000000
86.130005,61.187126,-127.571365,0.008304,0.003800,0.096531,272.173920,13.865201,0.965311,-127.571365,0.096661,0.000000
86.360001,61.171486,-127.571365,0.008308,0.003800,0.096531,272.104370,13.861656,0.965311,-127.571365,0.096661,0.000000
86.590004,61.151375,-127.615852,0.008326,0.003800,0.096531,272.014893,13.857100,0.965311,-127.615852,0.096661,0.000000
86.820007,61.140953,-127.571365,0.008330,0.003800,0.096531,271.968536,13.854737,0.965311,-127.571365,0.096661,0.000000
87.050003,61.110413,-127.704811,0.008308,0.003800,0.096531,271.832703,13.847817,0.965311,-127.704811,0.096661,0.000000
87.280006,61.098503,-127.704811,0.008313,0.003800,0.096531,271.779724,13.845119,0.965311,-127.704811,0.096661,0.000000
87.510002,61.072807,-127.704811,0.008317,0.003800,0.096531,271.665405,13.839296,0.965311,-127.704811,0.096661,0.000000
87.740005,61.059402,-127.749290,0.008300,0.003800,0.096531,271.605774,13.836259,0.965311,-127.749290,0.096661,0.000000
87.970001,61.039291,-127.704811,0.008317,0.003800,0.096531,271.516327,13.831701,0.965311,-127.704811,0.096661,0.000000
88.200005,61.019554,-127.838257,0.008317,0.003800,0.096531,271.428528,13.827229,0.965311,-127.838257,0.096661,0.000000
88.430008,61.007271,-127.838257,0.008317,0.003800,0.096531,271.373901,13.824445,0.965311,-127.838257,0.096661,0.000000
88.660004,60.984184,-127.838257,0.008313,0.003800,0.096531,271.271210,13.819214,0.965311,-127.838257,0.096661,0.000000
88.890007,60.965561,-127.927216,0.008326,0.003800,0.096531,271.188354,13.814994,0.965311,-127.927216,0.096661,0.000000
89.120003,60.945831,-127.882736,0.008317,0.003800,0.096531,271.100586,13.810523,0.965311,-127.882736,0.096661,0.000000
89.350006,60.942848,-127.971695,0.008317,0.003800,0.096531,271.087341,13.809847,0.965311,-127.971695,0.096661,0.000000
89.580002,60.923859,-128.016174,0.008321,0.003800,0.096531,271.002869,13.805544,0.965311,-128.016174,0.096661,0.000000
89.810005,60.904495,-128.016174,0.008317,0.003800,0.096531,270.916718,13.801156,0.965311,-128.016174,0.096661,0.000000
90.040001,60.892578,-128.016174,0.008321,0.003800,0.096531,270.863708,13.798455,0.965311,-128.016174,0.096661,0.000000
90.270004,60.870979,-128.016174,0.008321,0.003800,0.096531,270.767639,13.793561,0.965311,-128.016174,0.096661,0.000000
90.500008,60.847519,-128.149612,0.008300,0.003800,0.096531,270.663269,13.788245,0.965311,-128.149612,0.096661,0.000000
90.730003,60.833374,-128.105133,0.008326,0.003800,0.096531,270.600372,13.785040,0.965311,-128.105133,0.096661,0.000000
90.960007,60.836723,-128.194107,0.008317,0.003800,0.096531,270.615265,13.785798,0.965311,-128.194107,0.096661,0.000000
91.190002,60.816612,-128.149612,0.008313,0.003800,0.096531,270.525787,13.781241,0.965311,-128.149612,0.096661,0.000000
91.420006,60.799110,-128.238586,0.008321,0.003800,0.096531,270.447937,13.777275,0.965311,-128.238586,0.096661,0.000000
91.650002,60.788689,-128.283066,0.008326,0.003800,0.096531,270.401581,13.774914,0.965311,-128.283066,0.096661,0.000000
91.880005,60.777145,-128.372025,0.008300,0.003800,0.096531,270.350250,13.772298,0.965311,-128.372025,0.096661,0.000000
92.110001,60.765228,-128.372025,0.008300,0.003800,0.096531,270.297241,13.769598,0.965311,-128.372025,0.096661,0.000000
92.340004,60.754425,-128.327545,0.008326,0.003800,0.096531,270.249176,13.767149,0.965311,-128.327545,0.096661,0.000000
92.570007,60.733948,-128.372025,0.008334,0.003800,0.096531,270.158081,13.762509,0.965311,-128.372025,0.096661,0.000000
92.800003,60.722404,-128.416504,0.008330,0.003800,0.096531,270.106750,13.759893,0.965311,-128.416504,0.096661,0.000000
93.030006,60.703415,-128.460983,0.008330,0.003800,0.096531,270.022278,13.755590,0.965311,-128.460983,0.096661,0.000000
93.260002,60.688889,-128.460983,0.008313,0.003800,0.096531,269.957672,13.752299,0.965311,-128.460983,0.096661,0.000000
93.490005,60.678093,-128.505463,0.008308,0.003800,0.096531,269.909637,13.749852,0.965311,-128.505463,0.096661,0.000000
93.720001,60.660965,-128.505463,0.008330,0.003800,0.096531,269.833435,13.745971,0.965311,-128.505463,0.096661,0.000000
93.950005,60.654633,-128.638916,0.008308,0.003800,0.096531,269.805267,13.744535,0.965311,-128.638916,0.096661,0.000000
94.180008,60.642342,-128.505463,0.008326,0.003800,0.096531,269.750610,13.741751,0.965311,-128.505463,0.096661,0.000000
94.410004,60.628563,-128.594437,0.008308,0.003800,0.096531,269.689331,13.738628,0.965311,-128.594437,0.096661,0.000000
94.640007,60.612556,-128.638916,0.008317,0.003800,0.096531,269.618103,13.735002,0.965311,-128.638916,0.096661,0.000000
94.870003,60.605110,-128.727875,0.008317,0.003800,0.096531,269.584991,13.733314,0.965311,-128.727875,0.096661,0.000000
95.100006,60.579788,-128.772354,0.008317,0.003800,0.096531,269.472351,13.727576,0.965311,-128.772354,0.096661,0.000000
95.330002,60.577927,-128.727875,0.008321,0.003800,0.096531,269.464081,13.727155,0.965311,-128.727875,0.096661,0.000000
95.560005,60.572708,-128.772354,0.008321,0.003800,0.096531,269.440857,13.725971,0.965311,-128.772354,0.096661,0.000000
95.790001,60.558563,-128.683395,0.008317,0.003800,0.096531,269.377930,13.722767,0.965311,-128.683395,0.096661,0.000000
96.020004,60.547760,-128.816833,0.008326,0.003800,0.096531,269.329895,13.720318,0.965311,-128.816833,0.096661,0.000000
96.250008,60.540314,-128.905792,0.008317,0.003800,0.096531,269.296753,13.718632,0.965311,-128.905792,0.096661,0.000000
96.480003,60.519836,-128.861313,0.008304,0.003800,0.096531,269.205688,13.713990,0.965311,-128.861313,0.096661,0.000000
96.710007,60.518715,-128.950272,0.008313,0.003800,0.096531,269.200684,13.713737,0.965311,-128.950272,0.096661,0.000000
96.940002,60.497116,-128.950272,0.008317,0.003800,0.096531,269.104614,13.708842,0.965311,-128.950272,0.096661,0.000000
97.170006,60.489296,-128.950272,0.008330,0.003800,0.096531,269.069824,13.707070,0.965311,-128.950272,0.096661,0.000000
97.300003,60.479248,-129.039246,0.008300,0.003800,0.096531,269.025146,13.704793,0.965311,-129.039246,0.096661,0.000000