File: Data/compression 6/AutoNoheating-10-6-day3-1-240301_03012024_155023.csv
Time (sec),S:Load (lbs),S:HL1 (DIM),S:LVDT (in),S:Position (in),Ch:Position (mm),Ch:Load (N),Ch:Stress (MPa),Ch:Strain (mm/mm),Ch:HL1 (DIM),Set Point (),Cycles ()
0.110000,0.000374,-89.540154,-0.000026,0.000000,0.000009,0.001663,0.000085,0.000087,-89.540154,0.000217,0.000000
0.340000,-0.001862,-89.584633,-0.000013,0.000000,0.000009,-0.008281,-0.000422,0.000087,-89.584633,0.000217,0.000000
0.570000,0.065170,-89.629120,0.000009,0.000094,0.002385,0.289892,0.014768,0.023849,-89.629120,0.003287,0.000000
0.800000,0.063309,-89.673599,0.000060,0.000238,0.006053,0.281611,0.014346,0.060532,-89.673599,0.007120,0.000000
1.030000,0.016388,-89.673599,0.000211,0.000389,0.009878,0.072897,0.003714,0.098778,-89.673599,0.010953,0.000000
1.260000,0.049904,-89.673599,0.000336,0.000534,0.013555,0.221983,0.011308,0.135548,-89.673599,0.014786,0.000000
1.490000,0.030540,-89.762558,0.000517,0.000684,0.017370,0.135851,0.006921,0.173704,-89.762558,0.018619,0.000000
1.720000,0.062187,-89.807037,0.000677,0.000834,0.021186,0.276622,0.014092,0.211863,-89.807037,0.022452,0.000000
1.950000,0.025696,-89.851524,0.000815,0.000992,0.025184,0.114301,0.005823,0.251843,-89.851524,0.026286,0.000000
2.180000,0.036125,-89.940483,0.000949,0.001142,0.029017,0.160693,0.008186,0.290173,-89.940483,0.030119,0.000000
2.410000,-0.006699,-89.940483,0.001099,0.001290,0.032764,-0.029797,-0.001518,0.327639,-89.940483,0.033952,0.000000
2.640000,0.046921,-89.984962,0.001263,0.001442,0.036623,0.208714,0.010632,0.366230,-89.984962,0.037785,0.000000
2.870000,0.066658,-90.029442,0.001414,0.001591,0.040422,0.296510,0.015105,0.404215,-90.029442,0.041618,0.000000
3.100000,0.077827,-90.162888,0.001578,0.001744,0.044306,0.346194,0.017636,0.443064,-90.162888,0.045451,0.000000
3.330000,0.057350,-90.118408,0.001720,0.001902,0.048304,0.255106,0.012996,0.483043,-90.118408,0.049267,0.000000
3.560000,0.040222,-90.162888,0.001876,0.002044,0.051930,0.178917,0.009114,0.519295,-90.162888,0.053100,0.000000
3.790000,0.043571,-90.162888,0.002035,0.002195,0.055762,0.193816,0.009873,0.557625,-90.162888,0.056934,0.000000
4.020000,0.042824,-90.296333,0.002169,0.002341,0.059466,0.190490,0.009704,0.594656,-90.296333,0.060766,0.000000
4.250000,0.051392,-90.385292,0.002307,0.002500,0.063498,0.228601,0.011646,0.634984,-90.385292,0.064599,0.000000
4.480000,0.042824,-90.296333,0.002462,0.002651,0.067331,0.190490,0.009704,0.673314,-90.296333,0.068433,0.000000
4.710000,0.068146,-90.385292,0.002617,0.002799,0.071104,0.303127,0.015442,0.711038,-90.385292,0.072266,0.000000
4.940000,0.052132,-90.429771,0.002751,0.002950,0.074928,0.231893,0.011813,0.749284,-90.429771,0.076099,0.000000
5.170000,0.052879,-90.474251,0.002906,0.003106,0.078900,0.235219,0.011983,0.789003,-90.474251,0.079932,0.000000
5.400000,0.080811,-90.518738,0.003061,0.003253,0.082620,0.359463,0.018312,0.826205,-90.518738,0.083765,0.000000
5.630000,0.070007,-90.518738,0.003191,0.003399,0.086341,0.311408,0.015864,0.863410,-90.518738,0.087598,0.000000
5.860000,0.052505,-90.652176,0.003376,0.003559,0.090408,0.233556,0.011898,0.904083,-90.652176,0.091432,0.000000
6.090000,0.030907,-90.607697,0.003531,0.003704,0.094077,0.137480,0.007004,0.940766,-90.607697,0.095265,0.000000
6.320000,0.024208,-90.696663,0.003660,0.003850,0.097780,0.107683,0.005486,0.977797,-90.696663,0.099081,0.000000
6.550000,0.054367,-90.785622,0.003820,0.004006,0.101752,0.241837,0.012320,1.017516,-90.785622,0.102914,0.000000
6.780000,0.087509,-90.830101,0.003958,0.004152,0.105463,0.389260,0.019830,1.054634,-90.830101,0.106747,0.000000
7.010000,0.093842,-90.830101,0.004148,0.004311,0.109505,0.417428,0.021265,1.095046,-90.830101,0.110580,0.000000
7.240000,0.051765,-90.785622,0.004281,0.004462,0.113338,0.230264,0.011730,1.133375,-90.785622,0.114413,0.000000
7.470000,0.068520,-90.963547,0.004441,0.004609,0.117076,0.304790,0.015527,1.170755,-90.963547,0.118246,0.000000
7.700000,0.076340,-90.963547,0.004579,0.004765,0.121021,0.339576,0.017299,1.210213,-90.963547,0.122080,0.000000
7.930000,0.074478,-91.052505,0.004738,0.004902,0.124516,0.331295,0.016877,1.245162,-91.052505,0.125912,0.000000
8.160001,0.056229,-91.052505,0.004911,0.005059,0.128506,0.250117,0.012742,1.285055,-91.052505,0.129745,0.000000
8.390000,0.071129,-91.052505,0.005053,0.005212,0.132373,0.316397,0.016118,1.323733,-91.052505,0.133579,0.000000
8.620001,0.006332,-91.052505,0.005213,0.005364,0.136241,0.028168,0.001435,1.362411,-91.052505,0.137412,0.000000
8.850000,0.061447,-91.230431,0.005364,0.005516,0.140100,0.273331,0.013924,1.401002,-91.230431,0.141245,0.000000
9.080001,0.098312,-91.274910,0.005501,0.005665,0.143899,0.437315,0.022278,1.438987,-91.274910,0.145061,0.000000
9.310000,0.101662,-91.230431,0.005661,0.005819,0.147793,0.452214,0.023037,1.477926,-91.230431,0.148894,0.000000
9.540001,0.104637,-91.319389,0.005816,0.005975,0.151756,0.465449,0.023711,1.517557,-91.319389,0.152727,0.000000
9.770000,0.073730,-91.274910,0.005989,0.006118,0.155407,0.327969,0.016708,1.554067,-91.274910,0.156560,0.000000
10.000000,0.045059,-91.408356,0.006122,0.006265,0.159127,0.200433,0.010211,1.591272,-91.408356,0.160393,0.000000
10.230000,0.075226,-91.452835,0.006269,0.006419,0.163039,0.334621,0.017046,1.630385,-91.452835,0.164227,0.000000
10.460000,0.085274,-91.452835,0.006428,0.006565,0.166750,0.379317,0.019323,1.667500,-91.452835,0.168060,0.000000
10.690001,0.048042,-91.497314,0.006562,0.006718,0.170635,0.213703,0.010887,1.706352,-91.497314,0.171893,0.000000
10.920000,0.043198,-91.497314,0.006722,0.006873,0.174581,0.192153,0.009789,1.745813,-91.497314,0.175726,0.000000
11.150001,0.071129,-91.630760,0.006868,0.007025,0.178440,0.316397,0.016118,1.784404,-91.630760,0.179559,0.000000
11.380000,0.088257,-91.675240,0.007019,0.007178,0.182317,0.392586,0.019999,1.823169,-91.675240,0.183392,0.000000
11.610001,0.110222,-91.630760,0.007153,0.007325,0.186054,0.490291,0.024977,1.860545,-91.630760,0.187226,0.000000
11.840000,0.088257,-91.675240,0.007312,0.007475,0.189853,0.392586,0.019999,1.898530,-91.675240,0.191058,0.000000
12.070001,0.100914,-91.808685,0.007485,0.007629,0.193764,0.448888,0.022867,1.937643,-91.808685,0.194874,0.000000
12.300000,0.081177,-91.853165,0.007631,0.007777,0.197545,0.361092,0.018395,1.975454,-91.853165,0.198707,0.000000
12.530001,0.043198,-91.897644,0.007765,0.007923,0.201257,0.192153,0.009789,2.012569,-91.897644,0.202541,0.000000
12.760000,0.088631,-91.853165,0.007920,0.008080,0.205237,0.394249,0.020084,2.052374,-91.853165,0.206374,0.000000
12.990001,0.085648,-91.942123,0.008075,0.008230,0.209045,0.380979,0.019408,2.090447,-91.942123,0.210207,0.000000
13.220000,0.107994,-91.942123,0.008235,0.008382,0.212904,0.480382,0.024472,2.129037,-91.942123,0.214040,0.000000
13.450001,0.058464,-91.986610,0.008395,0.008536,0.216806,0.260061,0.013248,2.168064,-91.986610,0.217873,0.000000
13.680000,0.110222,-92.075569,0.008545,0.008686,0.220631,0.490291,0.024977,2.206310,-92.075569,0.221706,0.000000
13.910001,0.173157,-92.031090,0.008692,0.008839,0.224516,0.770240,0.039238,2.245162,-92.031090,0.225539,0.000000
14.140000,0.251724,-92.075569,0.008839,0.008980,0.228098,1.119725,0.057042,2.280978,-92.075569,0.229373,0.000000
14.370001,0.307587,-92.209015,0.009015,0.009138,0.232104,1.368214,0.069700,2.321041,-92.209015,0.233206,0.000000
14.600000,0.452065,-92.253494,0.009166,0.009287,0.235885,2.010883,0.102439,2.358853,-92.253494,0.237039,0.000000
14.830001,0.667297,-92.209015,0.009300,-0.000002,-0.000044,2.968287,0.151212,-0.000435,-92.209015,0.000130,0.000000
15.060000,0.590210,-92.342453,0.009304,-0.000002,-0.000052,2.625385,0.133743,-0.000522,-92.342453,0.000130,0.000000
15.290001,0.561913,-92.342453,0.009304,-0.000002,-0.000061,2.499512,0.127331,-0.000609,-92.342453,0.000130,0.000000
15.520000,0.543297,-92.342453,0.009309,-0.000002,-0.000061,2.416705,0.123113,-0.000609,-92.342453,0.000512,0.000000
15.750001,0.540688,-92.520378,0.009322,-0.000002,-0.000061,2.405098,0.122522,-0.000609,-92.520378,0.000902,0.000000
15.980000,0.545532,-92.520378,0.009313,0.000013,0.000338,2.426649,0.123619,0.003380,-92.520378,0.001283,0.000000
16.210001,0.560051,-92.520378,0.009317,0.000026,0.000659,2.491231,0.126909,0.006590,-92.520378,0.001665,0.000000
16.440001,0.601387,-92.475899,0.009339,0.000038,0.000971,2.675103,0.136276,0.009712,-92.475899,0.002046,0.000000
16.670000,0.747726,-92.564857,0.009369,0.000061,0.001552,3.326053,0.169437,0.015522,-92.564857,0.002437,0.000000
16.900002,0.728737,-92.698303,0.009365,0.000067,0.001691,3.241584,0.165134,0.016911,-92.698303,0.002818,0.000000
17.130001,0.829277,-92.742783,0.009373,0.000089,0.002263,3.688808,0.187917,0.022634,-92.742783,0.003200,0.000000
17.360001,0.787575,-92.698303,0.009408,0.000098,0.002489,3.503308,0.178467,0.024889,-92.698303,0.003582,0.000000
17.590000,0.882156,-92.787262,0.009421,0.000122,0.003104,3.924027,0.199899,0.031044,-92.787262,0.003963,0.000000
17.820002,0.886620,-92.787262,0.009447,0.000136,0.003451,3.943881,0.200911,0.034514,-92.787262,0.004353,0.000000
18.050001,0.892952,-92.920708,0.009451,0.000150,0.003798,3.972049,0.202346,0.037981,-92.920708,0.004735,0.000000
18.280001,0.904495,-92.876228,0.009477,0.000164,0.004154,4.023396,0.204962,0.041539,-92.876228,0.005116,0.000000
18.510000,0.952904,-92.876228,0.009464,0.000177,0.004492,4.238728,0.215931,0.044923,-92.876228,0.005498,0.000000
18.740002,1.066109,-93.009666,0.009516,0.000198,0.005021,4.742289,0.241584,0.050210,-93.009666,0.005880,0.000000
18.970001,1.040413,-93.009666,0.009516,0.000207,0.005247,4.627988,0.235761,0.052466,-93.009666,0.006270,0.000000
19.200001,1.123825,-93.143112,0.009533,0.000225,0.005724,4.999023,0.254662,0.057235,-93.143112,0.006652,0.000000
19.430000,1.171486,-93.098633,0.009550,0.000244,0.006209,5.211030,0.265463,0.062091,-93.098633,0.007033,0.000000
19.660002,1.203880,-93.098633,0.009572,0.000258,0.006547,5.355127,0.272803,0.065475,-93.098633,0.007415,0.000000
19.890001,1.216171,-93.187592,0.009593,0.000274,0.006955,5.409800,0.275588,0.069551,-93.187592,0.007796,0.000000
20.120001,1.273888,-93.187592,0.009602,0.000286,0.007259,5.666535,0.288667,0.072587,-93.187592,0.008186,0.000000
20.350000,1.305542,-93.276558,0.009610,0.000301,0.007649,5.807341,0.295840,0.076489,-93.276558,0.008568,0.000000
20.580002,1.400871,-93.321037,0.009632,0.000318,0.008065,6.231387,0.317442,0.080652,-93.321037,0.008950,0.000000
20.810001,1.447044,-93.365517,0.009653,0.000333,0.008447,6.436775,0.327905,0.084468,-93.365517,0.009331,0.000000
21.040001,1.456726,-93.365517,0.009653,0.000344,0.008733,6.479841,0.330099,0.087329,-93.365517,0.009713,0.000000
21.270000,1.526360,-93.454475,0.009675,0.000361,0.009158,6.789587,0.345878,0.091579,-93.454475,0.010103,0.000000
21.500002,1.593010,-93.454475,0.009692,0.000379,0.009626,7.086062,0.360981,0.096261,-93.454475,0.010485,0.000000
21.730001,1.600090,-93.587921,0.009710,0.000389,0.009877,7.117556,0.362586,0.098774,-93.587921,0.010866,0.000000
21.960001,1.640305,-93.543442,0.009727,0.000405,0.010294,7.296439,0.371698,0.102938,-93.543442,0.011248,0.000000
22.190001,1.711052,-93.543442,0.009753,0.000426,0.010814,7.611139,0.387730,0.108142,-93.543442,0.011629,0.000000
22.420002,1.748291,-93.632401,0.009770,0.000438,0.011135,7.776787,0.396168,0.111352,-93.632401,0.012020,0.000000
22.650002,1.796326,-93.676880,0.009783,0.000454,0.011534,7.990456,0.407053,0.115341,-93.676880,0.012401,0.000000
22.880001,1.810478,-93.765846,0.009809,0.000464,0.011794,8.053410,0.410260,0.117941,-93.765846,0.012783,0.000000
23.110001,1.877876,-93.676880,0.009826,0.000481,0.012219,8.353210,0.425533,0.122192,-93.676880,0.013164,0.000000
23.340002,1.953094,-93.854805,0.009817,0.000500,0.012687,8.687799,0.442578,0.126873,-93.854805,0.013546,0.000000
23.570002,1.957191,-93.810326,0.009860,0.000514,0.013051,8.706022,0.443506,0.130515,-93.810326,0.013936,0.000000
23.800001,1.989586,-93.899284,0.009886,0.000529,0.013433,8.850120,0.450847,0.134333,-93.899284,0.014318,0.000000
24.030001,2.006721,-93.943771,0.009891,0.000545,0.013841,8.926343,0.454730,0.138410,-93.943771,0.014699,0.000000
24.260000,2.075233,-93.943771,0.009891,0.000559,0.014188,9.231099,0.470255,0.141877,-93.943771,0.015081,0.000000
24.490002,2.129974,-94.032730,0.009934,0.000574,0.014578,9.474599,0.482659,0.145779,-94.032730,0.015462,0.000000
24.720001,2.138168,-94.032730,0.009938,0.000587,0.014908,9.511047,0.484516,0.149076,-94.032730,0.015853,0.000000
24.950001,2.197746,-94.121689,0.009973,0.000603,0.015315,9.776064,0.498016,0.153152,-94.121689,0.016234,0.000000
25.180000,2.306854,-94.121689,0.009977,0.000624,0.015844,10.261400,0.522741,0.158439,-94.121689,0.016616,0.000000
25.410002,2.339622,-94.166176,0.009994,0.000639,0.016243,10.407161,0.530166,0.162429,-94.166176,0.016998,0.000000
25.640001,2.283020,-94.210655,0.010003,0.000652,0.016573,10.155380,0.517340,0.165725,-94.210655,0.017388,0.000000
25.870001,2.304619,-94.344101,0.010029,0.000664,0.016859,10.251456,0.522234,0.168587,-94.344101,0.017769,0.000000
26.100000,2.328079,-94.299614,0.010037,0.000677,0.017197,10.355814,0.527550,0.171970,-94.299614,0.018151,0.000000
26.330002,2.453941,-94.388580,0.010037,0.000697,0.017709,10.915676,0.556071,0.177088,-94.388580,0.018532,0.000000
26.560001,2.479630,-94.388580,0.010054,0.000712,0.018090,11.029943,0.561892,0.180903,-94.388580,0.018914,0.000000
26.790001,2.499741,-94.433060,0.010089,0.000723,0.018376,11.119402,0.566449,0.183764,-94.433060,0.019304,0.000000
27.020000,2.581291,-94.433060,0.010102,0.000740,0.018784,11.482157,0.584929,0.187841,-94.433060,0.019686,0.000000
27.250002,2.645340,-94.566505,0.010145,0.000760,0.019296,11.767060,0.599443,0.192958,-94.566505,0.020068,0.000000
27.480001,2.620392,-94.610985,0.010145,0.000774,0.019651,11.656085,0.593789,0.196512,-94.610985,0.020449,0.000000
27.710001,2.637146,-94.566505,0.010154,0.000787,0.019998,11.730611,0.597586,0.199982,-94.566505,0.020831,0.000000
27.940001,2.685555,-94.522018,0.010175,0.000800,0.020319,11.945943,0.608555,0.203188,-94.522018,0.021221,0.000000
28.170002,2.717209,-94.655464,0.010192,0.000815,0.020692,12.086749,0.615728,0.206920,-94.655464,0.021602,0.000000
28.400002,2.791306,-94.699944,0.010210,0.000831,0.021100,12.416348,0.632519,0.210997,-94.699944,0.021984,0.000000
28.630001,2.771942,-94.744423,0.010205,0.000842,0.021377,12.330215,0.628131,0.213771,-94.744423,0.022366,0.000000
28.860001,2.840836,-94.833389,0.010227,0.000857,0.021767,12.636668,0.643743,0.217673,-94.833389,0.022747,0.000000
29.090002,2.971909,-94.788910,0.010248,0.000876,0.022253,13.219709,0.673444,0.222529,-94.788910,0.023137,0.000000
29.320002,3.011383,-94.922348,0.010274,0.000894,0.022712,13.395301,0.682389,0.227124,-94.922348,0.023519,0.000000
29.550001,2.992760,-95.011314,0.010296,0.000905,0.022990,13.312460,0.678169,0.229902,-95.011314,0.023900,0.000000
29.780001,3.029251,-94.966827,0.010296,0.000919,0.023354,13.474782,0.686438,0.233543,-94.966827,0.024282,0.000000
30.010002,3.017334,-95.011314,0.010317,0.000933,0.023710,13.421772,0.683738,0.237097,-95.011314,0.024664,0.000000
30.240002,3.159210,-94.966827,0.010330,0.000953,0.024213,14.052869,0.715887,0.242127,-94.966827,0.025054,0.000000
30.470001,3.174477,-95.055794,0.010356,0.000966,0.024542,14.120777,0.719347,0.245424,-95.055794,0.025436,0.000000
30.700001,3.159584,-95.144753,0.010365,0.000977,0.024820,14.054532,0.715972,0.248198,-95.144753,0.025817,0.000000
30.930002,3.250816,-95.144753,0.010378,0.000994,0.025245,14.460353,0.736646,0.252449,-95.144753,0.026199,0.000000
31.160002,3.366623,-95.144753,0.010382,0.001012,0.025696,14.975487,0.762888,0.256957,-95.144753,0.026580,0.000000
31.390001,3.308907,-95.144753,0.010408,0.001024,0.025999,14.718752,0.749809,0.259992,-95.144753,0.026971,0.000000
31.620001,3.387848,-95.278198,0.010425,0.001040,0.026416,15.069901,0.767697,0.264155,-95.278198,0.027352,0.000000
31.850002,3.327896,-95.367157,0.010438,0.001051,0.026684,14.803222,0.754112,0.266843,-95.367157,0.027734,0.000000
32.080002,3.414284,-95.411636,0.010451,0.001069,0.027144,15.187492,0.773688,0.271441,-95.411636,0.028115,0.000000
32.310001,3.592278,-95.367157,0.010490,0.001085,0.027569,15.979248,0.814022,0.275688,-95.367157,0.028497,0.000000
32.540001,3.480194,-95.456123,0.010481,0.001092,0.027743,15.480677,0.788623,0.277425,-95.456123,0.028887,0.000000
32.770000,3.684998,-95.500603,0.010499,0.001115,0.028315,16.391687,0.835032,0.283148,-95.500603,0.029269,0.000000
33.000000,3.736389,-95.500603,0.010511,0.001132,0.028749,16.620289,0.846678,0.287485,-95.500603,0.029650,0.000000
33.230003,3.793732,-95.634048,0.010520,0.001150,0.029208,16.875360,0.859672,0.292080,-95.634048,0.030032,0.000000
33.460003,3.744209,-95.634048,0.010542,0.001161,0.029494,16.655075,0.848450,0.294942,-95.634048,0.030414,0.000000
33.690002,3.789635,-95.723007,0.010559,0.001175,0.029850,16.857138,0.858743,0.298500,-95.723007,0.030804,0.000000
33.920002,3.854057,-95.723007,0.010598,0.001191,0.030240,17.143703,0.873342,0.302402,-95.723007,0.031185,0.000000
34.150002,3.972847,-95.767487,0.010615,0.001207,0.030648,17.672106,0.900260,0.306478,-95.767487,0.031567,0.000000
34.380001,3.952736,-95.811966,0.010624,0.001219,0.030968,17.582647,0.895703,0.309684,-95.811966,0.031948,0.000000
34.610001,4.073013,-95.856453,0.010637,0.001234,0.031342,18.117668,0.922958,0.313416,-95.856453,0.032339,0.000000
34.840000,4.163498,-95.811966,0.010645,0.001251,0.031766,18.520164,0.943462,0.317662,-95.811966,0.032720,0.000000
35.070004,4.236115,-95.856453,0.010671,0.001267,0.032191,18.843178,0.959917,0.321913,-95.856453,0.033102,0.000000
35.300003,4.306862,-95.945412,0.010675,0.001283,0.032599,19.157879,0.975949,0.325989,-95.945412,0.033483,0.000000
35.530003,4.261803,-95.989891,0.010701,0.001296,0.032929,18.957445,0.965738,0.329286,-95.989891,0.033865,0.000000
35.760002,4.191429,-95.989891,0.010705,0.001305,0.033145,18.644407,0.949791,0.331451,-95.989891,0.034255,0.000000
35.990002,4.456184,-96.034370,0.010718,0.001325,0.033657,19.822098,1.009786,0.336568,-96.034370,0.034637,0.000000
36.220001,4.396233,-96.123337,0.010753,0.001334,0.033882,19.555420,0.996201,0.338824,-96.123337,0.035019,0.000000
36.450001,4.499008,-96.167816,0.010762,0.001350,0.034281,20.012589,1.019490,0.342813,-96.167816,0.035400,0.000000
36.680000,4.649445,-96.256775,0.010766,0.001368,0.034758,20.681763,1.053579,0.347582,-96.256775,0.035782,0.000000
36.910000,4.586143,-96.256775,0.010783,0.001380,0.035053,20.400185,1.039235,0.350530,-96.256775,0.036172,0.000000
37.140003,4.811424,-96.212296,0.010818,0.001401,0.035591,21.402285,1.090284,0.355909,-96.212296,0.036553,0.000000
37.370003,4.725037,-96.301262,0.010813,0.001410,0.035825,21.018013,1.070709,0.358248,-96.301262,0.036935,0.000000
37.600002,4.928352,-96.345741,0.010835,0.001432,0.036371,21.922405,1.116781,0.363713,-96.345741,0.037316,0.000000
37.830002,5.026283,-96.345741,0.010843,0.001445,0.036710,22.358025,1.138972,0.367097,-96.345741,0.037698,0.000000
38.060001,5.255669,-96.434700,0.010869,0.001465,0.037213,23.378382,1.190952,0.372127,-96.434700,0.038089,0.000000
38.290001,5.170395,-96.434700,0.010878,0.001476,0.037490,22.999065,1.171628,0.374901,-96.434700,0.038470,0.000000
38.520000,5.143959,-96.434700,0.010895,0.001488,0.037785,22.881474,1.165638,0.377850,-96.434700,0.038852,0.000000
38.750000,5.189011,-96.568146,0.010895,0.001501,0.038132,23.081873,1.175847,0.381317,-96.568146,0.039233,0.000000
38.980003,5.647774,-96.657104,0.010917,0.001527,0.038774,25.122553,1.279804,0.387736,-96.657104,0.039615,0.000000
39.210003,5.518936,-96.612625,0.010951,0.001537,0.039034,24.549454,1.250609,0.390336,-96.612625,0.040005,0.000000
39.440002,5.571442,-96.701584,0.010951,0.001552,0.039415,24.783010,1.262507,0.394151,-96.701584,0.040387,0.000000
39.670002,5.721130,-96.657104,0.010986,0.001567,0.039797,25.448858,1.296427,0.397970,-96.657104,0.040768,0.000000
39.900002,5.844391,-96.746071,0.010990,0.001582,0.040179,25.997149,1.324358,0.401786,-96.746071,0.041150,0.000000
40.130001,6.049568,-96.835030,0.010994,0.001600,0.040638,26.909822,1.370852,0.406380,-96.835030,0.041531,0.000000
40.360001,5.772522,-96.835030,0.011003,0.001603,0.040725,25.677460,1.308072,0.407247,-96.835030,0.041921,0.000000
40.590000,6.260704,-96.835030,0.011037,0.001630,0.041393,27.849003,1.418696,0.413927,-96.835030,0.042303,0.000000
40.820004,6.366829,-96.923996,0.011055,0.001648,0.041852,28.321070,1.442744,0.418522,-96.923996,0.042685,0.000000
41.050003,6.302780,-96.879509,0.011068,0.001658,0.042112,28.036167,1.428230,0.421123,-96.879509,0.043066,0.000000
41.280003,6.468109,-96.968475,0.011076,0.001677,0.042598,28.771585,1.465695,0.425979,-96.968475,0.043448,0.000000
41.510002,6.350441,-97.101913,0.011085,0.001685,0.042789,28.248173,1.439031,0.427886,-97.101913,0.043838,0.000000
41.740002,6.761543,-97.101913,0.011094,0.001705,0.043309,30.076847,1.532188,0.433090,-97.101913,0.044220,0.000000
41.970001,6.800270,-97.101913,0.011119,0.001716,0.043595,30.249111,1.540963,0.435952,-97.101913,0.044601,0.000000
42.200001,6.914589,-97.146400,0.011124,0.001733,0.044012,30.757627,1.566868,0.440115,-97.146400,0.044983,0.000000
42.430000,6.922783,-97.235359,0.011137,0.001744,0.044289,30.794077,1.568725,0.442889,-97.235359,0.045365,0.000000
42.660004,7.279884,-97.235359,0.011163,0.001766,0.044853,32.382542,1.649645,0.448529,-97.235359,0.045755,0.000000
42.890003,7.423248,-97.279839,0.011171,0.001778,0.045173,33.020256,1.682132,0.451735,-97.279839,0.046136,0.000000
43.120003,7.516716,-97.279839,0.011188,0.001795,0.045599,33.436024,1.703312,0.455985,-97.279839,0.046518,0.000000
43.350002,7.586723,-97.368805,0.011206,0.001808,0.045928,33.747433,1.719176,0.459282,-97.368805,0.046899,0.000000
43.580002,7.830254,-97.413284,0.011223,0.001824,0.046336,34.830708,1.774361,0.463358,-97.413284,0.047290,0.000000
43.810001,8.047714,-97.457764,0.011244,0.001842,0.046778,35.798019,1.823638,0.467779,-97.457764,0.047671,0.000000
44.040001,8.154961,-97.457764,0.011240,0.001856,0.047151,36.275078,1.847941,0.471511,-97.457764,0.048053,0.000000
44.270000,8.096123,-97.457764,0.011257,0.001866,0.047402,36.013351,1.834608,0.474024,-97.457764,0.048435,0.000000
44.500004,8.518394,-97.591209,0.011257,0.001886,0.047905,37.891712,1.930296,0.479054,-97.591209,0.048816,0.000000
44.730003,8.711281,-97.635689,0.011283,0.001902,0.048322,38.749714,1.974005,0.483218,-97.635689,0.049206,0.000000
44.960003,8.997643,-97.724648,0.011318,0.001921,0.048799,40.023514,2.038895,0.487987,-97.724648,0.049588,0.000000
45.190002,9.006577,-97.680168,0.011326,0.001933,0.049102,40.063251,2.040919,0.491022,-97.680168,0.049969,0.000000
45.420002,9.110466,-97.680168,0.011339,0.001947,0.049449,40.525375,2.064461,0.494493,-97.680168,0.050351,0.000000
45.650002,9.431824,-97.724648,0.011348,0.001965,0.049909,41.954845,2.137282,0.499088,-97.724648,0.050733,0.000000
45.880001,9.434059,-97.858093,0.011348,0.001976,0.050195,41.964790,2.137788,0.501949,-97.858093,0.051123,0.000000
46.110001,9.491402,-97.858093,0.011369,0.001985,0.050420,42.219864,2.150782,0.504205,-97.858093,0.051504,0.000000
46.340004,10.174706,-97.858093,0.011391,0.002008,0.050993,45.259350,2.305621,0.509928,-97.858093,0.051886,0.000000
46.570004,10.504257,-97.858093,0.011417,0.002027,0.051478,46.725269,2.380299,0.514784,-97.858093,0.052268,0.000000
46.800003,10.722099,-97.991531,0.011417,0.002043,0.051903,47.694279,2.429662,0.519034,-97.991531,0.052649,0.000000
47.030003,10.568306,-98.036018,0.011413,0.002053,0.052146,47.010174,2.394812,0.521460,-98.036018,0.053039,0.000000
47.260002,10.851685,-98.080498,0.011447,0.002068,0.052528,48.270702,2.459027,0.525279,-98.080498,0.053421,0.000000
47.490002,11.281403,-98.080498,0.011456,0.002086,0.052979,50.182186,2.556402,0.529787,-98.080498,0.053803,0.000000
47.720001,11.379333,-98.080498,0.011464,0.002100,0.053334,50.617802,2.578594,0.533341,-98.080498,0.054184,0.000000
47.950001,11.572594,-98.213943,0.011477,0.002112,0.053655,51.477467,2.622387,0.536551,-98.213943,0.054566,0.000000
48.180004,12.012367,-98.258423,0.011507,0.002130,0.054106,53.433678,2.722041,0.541062,-98.258423,0.054956,0.000000
48.410004,12.330002,-98.302902,0.011507,0.002146,0.054514,54.846588,2.794019,0.545138,-98.302902,0.055337,0.000000
48.640003,12.599228,-98.213943,0.011512,0.002161,0.054895,56.044167,2.855026,0.548954,-98.213943,0.055719,0.000000
48.870003,12.694183,-98.347382,0.011542,0.002174,0.055225,56.466549,2.876543,0.552246,-98.347382,0.056101,0.000000
49.100002,12.944786,-98.258423,0.011551,0.002187,0.055554,57.581284,2.933330,0.555543,-98.258423,0.056482,0.000000
49.330002,13.146988,-98.436348,0.011572,0.002202,0.055927,58.480724,2.979150,0.559271,-98.436348,0.056873,0.000000
49.560001,13.677986,-98.436348,0.011581,0.002221,0.056404,60.842720,3.099476,0.564044,-98.436348,0.057254,0.000000
49.790001,14.267082,-98.480827,0.011576,0.002238,0.056855,63.463150,3.232967,0.568552,-98.480827,0.057636,0.000000
50.020004,14.119995,-98.480827,0.011585,0.002246,0.057046,62.808876,3.199637,0.570459,-98.480827,0.058017,0.000000
50.250004,14.495720,-98.480827,0.011607,0.002261,0.057419,64.480179,3.284777,0.574188,-98.480827,0.058399,0.000000
50.480003,15.266899,-98.569786,0.011632,0.002280,0.057913,67.910561,3.459529,0.579131,-98.569786,0.058789,0.000000
50.710003,15.524208,-98.658752,0.011624,0.002296,0.058312,69.055130,3.517836,0.583120,-98.658752,0.059171,0.000000
50.940002,15.731621,-98.658752,0.011654,0.002309,0.058650,69.977745,3.564836,0.586504,-98.658752,0.059552,0.000000
51.170002,15.918922,-98.703232,0.011658,0.002323,0.059006,70.810905,3.607279,0.590058,-98.703232,0.059934,0.000000
51.400002,16.690109,-98.747711,0.011663,0.002342,0.059474,74.241310,3.782033,0.594743,-98.747711,0.060315,0.000000
51.630001,17.193558,-98.792191,0.011676,0.002356,0.059847,76.480766,3.896116,0.598471,-98.792191,0.060706,0.000000
51.860001,17.237122,-98.925636,0.011697,0.002367,0.060116,76.674545,3.905988,0.601159,-98.925636,0.061087,0.000000
52.090004,17.349205,-98.881157,0.011701,0.002380,0.060454,77.173119,3.931386,0.604542,-98.881157,0.061469,0.000000
52.320004,17.895103,-98.836670,0.011710,0.002393,0.060792,79.601395,4.055089,0.607922,-98.836670,0.061850,0.000000
52.550003,18.913170,-98.970116,0.011736,0.002416,0.061365,84.129982,4.285786,0.613649,-98.970116,0.062241,0.000000
52.780003,19.069572,-99.014595,0.011736,0.002427,0.061634,84.825691,4.321227,0.616336,-99.014595,0.062622,0.000000
53.010002,19.436356,-99.059074,0.011749,0.002442,0.062015,86.457230,4.404341,0.620151,-99.059074,0.063004,0.000000
53.240002,19.567802,-99.059074,0.011762,0.002452,0.062276,87.041931,4.434127,0.622755,-99.059074,0.063385,0.000000
53.470001,20.432449,-99.103561,0.011762,0.002472,0.062778,90.888077,4.630059,0.627782,-99.103561,0.063767,0.000000
53.700001,21.009254,-99.148041,0.011770,0.002486,0.063151,93.453835,4.760765,0.631514,-99.148041,0.064157,0.000000
53.930004,21.019310,-99.148041,0.011792,0.002495,0.063385,93.498558,4.763043,0.633853,-99.148041,0.064539,0.000000
54.160004,22.433952,-99.237000,0.011801,0.002521,0.064027,99.791206,5.083606,0.640272,-99.237000,0.064920,0.000000
54.390003,22.995491,-99.237000,0.011818,0.002536,0.064417,102.289055,5.210853,0.644174,-99.237000,0.065302,0.000000
54.620003,23.543999,-99.281487,0.011822,0.002550,0.064764,104.728935,5.335146,0.647645,-99.281487,0.065683,0.000000
54.850002,23.693687,-99.325966,0.011839,0.002563,0.065102,105.394783,5.369066,0.651025,-99.325966,0.066074,0.000000
55.080002,24.150589,-99.370445,0.011848,0.002576,0.065432,107.427185,5.472602,0.654321,-99.370445,0.066456,0.000000
55.310001,25.038696,-99.414925,0.011848,0.002596,0.065926,111.377686,5.673850,0.659264,-99.414925,0.066837,0.000000
55.540001,25.647903,-99.459404,0.011852,0.002610,0.066282,114.087570,5.811898,0.662818,-99.459404,0.067219,0.000000
55.770004,25.912659,-99.459404,0.011874,0.002619,0.066516,115.265266,5.871892,0.665161,-99.459404,0.067600,0.000000
56.000004,26.580696,-99.503891,0.011891,0.002633,0.066880,118.236839,6.023272,0.668802,-99.503891,0.067990,0.000000
56.230003,27.603973,-99.592850,0.011887,0.002653,0.067383,122.788605,6.255150,0.673832,-99.592850,0.068372,0.000000
56.460003,28.409790,-99.637329,0.011904,0.002670,0.067817,126.373055,6.437750,0.678170,-99.637329,0.068753,0.000000
56.690002,29.039467,-99.681808,0.011913,0.002685,0.068199,129.173996,6.580437,0.681985,-99.681808,0.069135,0.000000
56.920002,29.493019,-99.637329,0.011930,0.002698,0.068528,131.191498,6.683214,0.685282,-99.637329,0.069517,0.000000
57.150002,29.609947,-99.681808,0.011921,0.002705,0.068710,131.711624,6.709710,0.687102,-99.681808,0.069907,0.000000
57.380001,30.915855,-99.770775,0.011930,0.002727,0.069265,137.520599,7.005633,0.692651,-99.770775,0.070289,0.000000
57.610004,31.659111,-99.859734,0.011939,0.002740,0.069603,140.826752,7.174057,0.696035,-99.859734,0.070670,0.000000
57.840004,32.093666,-99.904213,0.011952,0.002755,0.069976,142.759750,7.272529,0.699763,-99.904213,0.071052,0.000000
58.070004,33.269623,-99.904213,0.011964,0.002773,0.070427,147.990677,7.539004,0.704274,-99.904213,0.071433,0.000000
58.300003,34.256409,-99.904213,0.011977,0.002789,0.070852,152.380112,7.762613,0.708521,-99.904213,0.071824,0.000000
58.530003,34.976204,-99.904213,0.011973,0.002803,0.071190,155.581924,7.925721,0.711905,-99.904213,0.072205,0.000000
58.760002,35.533646,-99.993179,0.011986,0.002820,0.071633,158.061554,8.052039,0.716325,-99.993179,0.072587,0.000000
58.990002,36.477608,-100.037659,0.011995,0.002831,0.071919,162.260498,8.265944,0.719191,-100.037659,0.072968,0.000000
59.220001,37.156815,-100.082138,0.011995,0.002848,0.072335,165.281769,8.419854,0.723350,-100.082138,0.073350,0.000000
59.450005,38.499222,-100.037659,0.012025,0.002864,0.072751,171.253098,8.724049,0.727514,-100.037659,0.073740,0.000000
59.680004,38.870476,-100.171104,0.012029,0.002874,0.073012,172.904510,8.808175,0.730118,-100.171104,0.074121,0.000000
59.910004,39.655807,-100.260063,0.012025,0.002888,0.073367,176.397842,8.986134,0.733672,-100.260063,0.074503,0.000000
60.140003,40.644829,-100.260063,0.012038,0.002906,0.073818,180.797226,9.210250,0.738183,-100.260063,0.074885,0.000000
60.370003,42.409874,-100.260063,0.012033,0.002929,0.074391,188.648544,9.610215,0.743906,-100.260063,0.075275,0.000000
60.600002,42.712616,-100.260063,0.012038,0.002936,0.074564,189.995209,9.678817,0.745639,-100.260063,0.075657,0.000000
60.830002,43.559013,-100.349022,0.012068,0.002951,0.074954,193.760162,9.870614,0.749542,-100.349022,0.076038,0.000000
61.060001,44.552132,-100.437988,0.012068,0.002966,0.075327,198.177780,10.095657,0.753270,-100.437988,0.076420,0.000000
61.290005,45.587700,-100.437988,0.012059,0.002983,0.075769,202.784210,10.330320,0.757694,-100.437988,0.076802,0.000000
61.520004,46.833290,-100.482468,0.012077,0.002999,0.076168,208.324875,10.612576,0.761684,-100.482468,0.077192,0.000000
61.750004,47.498344,-100.482468,0.012072,0.003012,0.076506,211.283188,10.763279,0.765064,-100.482468,0.077573,0.000000
61.980003,48.946503,-100.526947,0.012089,0.003031,0.076992,217.724915,11.091436,0.769923,-100.526947,0.077955,0.000000
62.210003,50.327629,-100.615913,0.012102,0.003047,0.077400,223.868469,11.404404,0.773996,-100.615913,0.078336,0.000000
62.440002,50.923058,-100.749352,0.012098,0.003058,0.077677,226.517075,11.539330,0.776774,-100.749352,0.078718,0.000000
62.670002,52.314980,-100.660393,0.012102,0.003077,0.078154,232.708649,11.854744,0.781543,-100.660393,0.079108,0.000000
62.900002,52.691452,-100.660393,0.012115,0.003085,0.078371,234.383286,11.940053,0.783712,-100.660393,0.079490,0.000000
63.130005,54.354095,-100.793839,0.012124,0.003106,0.078891,241.779099,12.316813,0.788912,-100.793839,0.079871,0.000000
63.360004,55.185974,-100.793839,0.012133,0.003119,0.079212,245.479477,12.505321,0.792122,-100.793839,0.080253,0.000000
63.590004,56.393951,-100.838318,0.012128,0.003134,0.079594,250.852829,12.779052,0.795937,-100.838318,0.080635,0.000000
63.820004,57.096992,-100.793839,0.012133,0.003143,0.079837,253.980103,12.938364,0.798367,-100.793839,0.081025,0.000000
64.050003,58.900764,-100.882797,0.012150,0.003165,0.080383,262.003693,13.347104,0.803828,-100.882797,0.081406,0.000000
64.280006,59.929626,-100.927277,0.012137,0.003177,0.080704,266.580292,13.580247,0.807038,-100.927277,0.081788,0.000000
64.510002,60.723526,-100.971756,0.012141,0.003189,0.080990,270.111725,13.760148,0.809899,-100.971756,0.082170,0.000000
64.740005,62.556717,-101.060722,0.012150,0.003211,0.081563,278.266174,14.175554,0.815626,-101.060722,0.082551,0.000000
64.970001,63.669739,-101.016243,0.012171,0.003227,0.081962,283.217133,14.427769,0.819615,-101.016243,0.082941,0.000000
65.200005,65.060547,-101.060722,0.012163,0.003243,0.082369,289.403778,14.742930,0.823692,-101.060722,0.083323,0.000000
65.430000,66.142654,-101.105202,0.012180,0.003256,0.082690,294.217224,14.988139,0.826897,-101.105202,0.083704,0.000000
65.660004,66.943634,-101.149681,0.012180,0.003269,0.083037,297.780151,15.169644,0.830368,-101.149681,0.084086,0.000000
65.889999,67.186798,-101.238647,0.012184,0.003263,0.082880,298.861816,15.224747,0.828805,-101.238647,0.083141,0.000000
66.120003,66.750000,-101.283127,0.012193,0.003262,0.082855,296.918823,15.125767,0.828548,-101.283127,0.082880,0.000000
66.350006,66.391037,-101.238647,0.012176,0.003261,0.082820,295.322083,15.044424,0.828199,-101.238647,0.082880,0.000000
66.580002,66.074524,-101.372086,0.012197,0.003260,0.082803,293.914154,14.972701,0.828025,-101.372086,0.082880,0.000000
66.810005,65.799713,-101.416565,0.012202,0.003260,0.082794,292.691742,14.910428,0.827938,-101.416565,0.082880,0.000000
67.040001,65.557663,-101.461052,0.012184,0.003259,0.082785,291.615051,14.855579,0.827851,-101.461052,0.082880,0.000000
67.270004,65.344666,-101.505531,0.012189,0.003259,0.082785,290.667603,14.807313,0.827851,-101.505531,0.082880,0.000000
67.500000,65.127945,-101.461052,0.012193,0.003259,0.082776,289.703583,14.758204,0.827764,-101.461052,0.082880,0.000000
67.730003,64.945480,-101.461052,0.012197,0.003259,0.082776,288.891937,14.716857,0.827764,-101.461052,0.082880,0.000000
67.960007,64.796158,-101.505531,0.012202,0.003259,0.082776,288.227692,14.683020,0.827764,-101.505531,0.082880,0.000000
68.190002,64.642746,-101.594490,0.012193,0.003259,0.082768,287.545288,14.648255,0.827681,-101.594490,0.082880,0.000000
68.420006,64.489334,-101.594490,0.012176,0.003259,0.082768,286.862885,14.613492,0.827681,-101.594490,0.082880,0.000000
68.650002,64.354523,-101.638969,0.012189,0.003259,0.082768,286.263214,14.582944,0.827681,-101.638969,0.082880,0.000000
68.880005,64.246536,-101.683456,0.012210,0.003259,0.082768,285.782867,14.558474,0.827681,-101.683456,0.082880,0.000000
69.110001,64.147125,-101.727936,0.012197,0.003259,0.082768,285.340668,14.535946,0.827681,-101.727936,0.082880,0.000000
69.340004,64.016037,-101.816895,0.012202,0.003259,0.082768,284.757568,14.506241,0.827681,-101.816895,0.082880,0.000000
69.570000,63.919968,-101.861382,0.012210,0.003259,0.082768,284.330231,14.484472,0.827681,-101.861382,0.082880,0.000000
69.800003,63.837311,-101.861382,0.012206,0.003259,0.082768,283.962555,14.465741,0.827681,-101.861382,0.082880,0.000000
70.030006,63.744217,-101.905861,0.012210,0.003259,0.082768,283.548431,14.444646,0.827681,-101.905861,0.082880,0.000000
70.260002,63.662659,-101.905861,0.012210,0.003258,0.082759,283.185638,14.426165,0.827594,-101.905861,0.082880,0.000000
70.490005,63.582977,-101.994820,0.012202,0.003258,0.082759,282.831207,14.408109,0.827594,-101.994820,0.082880,0.000000
70.720001,63.507004,-102.039299,0.012206,0.003258,0.082759,282.493256,14.390892,0.827594,-102.039299,0.082880,0.000000
70.950005,63.432541,-101.994820,0.012202,0.003258,0.082759,282.162048,14.374020,0.827594,-101.994820,0.082880,0.000000
71.180000,63.363647,-102.039299,0.012206,0.003258,0.082759,281.855591,14.358408,0.827594,-102.039299,0.082880,0.000000
71.410004,63.286194,-102.128265,0.012210,0.003258,0.082759,281.511047,14.340857,0.827594,-102.128265,0.082880,0.000000
71.640007,63.215073,-102.128265,0.012202,0.003258,0.082759,281.194702,14.324739,0.827594,-102.128265,0.082880,0.000000
71.870003,63.170380,-102.217224,0.012206,0.003258,0.082759,280.995880,14.314613,0.827594,-102.217224,0.082880,0.000000
72.100006,63.113411,-102.217224,0.012215,0.003258,0.082759,280.742462,14.301703,0.827594,-102.217224,0.082880,0.000000
72.330002,63.050850,-102.261703,0.012202,0.003258,0.082759,280.464203,14.287526,0.827594,-102.261703,0.082880,0.000000
72.560005,62.980103,-102.261703,0.012223,0.003258,0.082759,280.149475,14.271495,0.827594,-102.261703,0.082880,0.000000
72.790001,62.927971,-102.350670,0.012202,0.003258,0.082759,279.917603,14.259682,0.827594,-102.350670,0.082880,0.000000
73.020004,62.880310,-102.395149,0.012202,0.003258,0.082759,279.705597,14.248881,0.827594,-102.395149,0.082880,0.000000
73.250000,62.835991,-102.439629,0.012202,0.003258,0.082759,279.508453,14.238839,0.827594,-102.439629,0.082880,0.000000
73.480003,62.766731,-102.439629,0.012219,0.003258,0.082759,279.200378,14.223145,0.827594,-102.439629,0.082880,0.000000
73.710007,62.728752,-102.528595,0.012206,0.003258,0.082759,279.031433,14.214539,0.827594,-102.528595,0.082880,0.000000
73.940002,62.688538,-102.528595,0.012219,0.003258,0.082759,278.852539,14.205426,0.827594,-102.528595,0.082880,0.000000
74.170006,62.632309,-102.528595,0.012202,0.003258,0.082759,278.602417,14.192684,0.827594,-102.528595,0.082880,0.000000
74.400002,62.590225,-102.573074,0.012219,0.003258,0.082759,278.415222,14.183147,0.827594,-102.573074,0.082880,0.000000
74.630005,62.548523,-102.617554,0.012189,0.003258,0.082759,278.229736,14.173697,0.827594,-102.617554,0.082880,0.000000
74.860001,62.513893,-102.706512,0.012227,0.003258,0.082759,278.075684,14.165851,0.827594,-102.706512,0.082880,0.000000
75.090004,62.459526,-102.706512,0.012210,0.003258,0.082759,277.833862,14.153531,0.827594,-102.706512,0.082880,0.000000
75.320007,62.440163,-102.795479,0.012223,0.003258,0.082759,277.747711,14.149143,0.827594,-102.795479,0.082880,0.000000
75.550003,62.391006,-102.795479,0.012210,0.003258,0.082759,277.529053,14.138004,0.827594,-102.795479,0.082880,0.000000
75.780006,62.343719,-102.839958,0.012210,0.003258,0.082759,277.318726,14.127289,0.827594,-102.839958,0.082880,0.000000
76.010002,62.313187,-102.839958,0.012215,0.003258,0.082759,277.182892,14.120370,0.827594,-102.839958,0.082880,0.000000
76.240005,62.279297,-102.884438,0.012202,0.003258,0.082759,277.032135,14.112691,0.827594,-102.884438,0.082880,0.000000
76.470001,62.254723,-102.973404,0.012215,0.003258,0.082759,276.922852,14.107122,0.827594,-102.973404,0.082880,0.000000
76.700005,62.203331,-103.062363,0.012206,0.003258,0.082759,276.694244,14.095476,0.827594,-103.062363,0.082880,0.000000
76.930000,62.173920,-103.017883,0.012206,0.003258,0.082759,276.563416,14.088812,0.827594,-103.017883,0.082880,0.000000
77.160004,62.148964,-103.017883,0.012223,0.003258,0.082759,276.452393,14.083156,0.827594,-103.017883,0.082880,0.000000
77.390007,62.110985,-103.195808,0.012227,0.003258,0.082759,276.283447,14.074551,0.827594,-103.195808,0.082880,0.000000
77.620003,62.065186,-103.151329,0.012202,0.003258,0.082759,276.079742,14.064172,0.827594,-103.151329,0.082880,0.000000
77.850006,62.055878,-103.195808,0.012223,0.003258,0.082759,276.038330,14.062063,0.827594,-103.195808,0.082880,0.000000
78.080002,62.029060,-103.195808,0.012227,0.003258,0.082759,275.919037,14.055986,0.827594,-103.195808,0.082880,0.000000
78.310005,61.991829,-103.284767,0.012219,0.003258,0.082759,275.753418,14.047549,0.827594,-103.284767,0.082880,0.000000
78.540001,61.954964,-103.240288,0.012215,0.003258,0.082759,275.589447,14.039196,0.827594,-103.240288,0.082880,0.000000
78.770004,61.946022,-103.373734,0.012215,0.003258,0.082759,275.549683,14.037169,0.827594,-103.373734,0.082880,0.000000
79.000000,61.914001,-103.373734,0.012202,0.003258,0.082759,275.407227,14.029913,0.827594,-103.373734,0.082880,0.000000
79.230003,61.867081,-103.418213,0.012227,0.003258,0.082759,275.198517,14.019281,0.827594,-103.418213,0.082880,0.000000
79.460007,61.848465,-103.418213,0.012223,0.003258,0.082759,275.115723,14.015062,0.827594,-103.418213,0.082880,0.000000
79.690002,61.826866,-103.507172,0.012219,0.003258,0.082759,275.019623,14.010168,0.827594,-103.507172,0.082880,0.000000
79.920006,61.799683,-103.551651,0.012210,0.003258,0.082759,274.898712,14.004008,0.827594,-103.551651,0.082880,0.000000
80.150002,61.761703,-103.551651,0.012206,0.003258,0.082759,274.729767,13.995402,0.827594,-103.551651,0.082880,0.000000
80.380005,61.733772,-103.640617,0.012223,0.003258,0.082759,274.605530,13.989073,0.827594,-103.640617,0.082880,0.000000
80.610001,61.716644,-103.640617,0.012219,0.003258,0.082759,274.529358,13.985191,0.827594,-103.640617,0.082880,0.000000
80.840004,61.707336,-103.685097,0.012219,0.003258,0.082759,274.487946,13.983082,0.827594,-103.685097,0.082880,0.000000
81.070007,61.668610,-103.729576,0.012223,0.003258,0.082759,274.315674,13.974307,0.827594,-103.729576,0.082880,0.000000
81.300003,61.650734,-103.774055,0.012210,0.003258,0.082759,274.236176,13.970256,0.827594,-103.774055,0.082880,0.000000
81.530006,61.634346,-103.729576,0.012206,0.003258,0.082759,274.163269,13.966542,0.827594,-103.729576,0.082880,0.000000
81.760002,61.611259,-103.818542,0.012236,0.003258,0.082751,274.060577,13.961311,0.827507,-103.818542,0.082880,0.000000
81.990005,61.591896,-103.907501,0.012206,0.003258,0.082751,273.974426,13.956923,0.827507,-103.907501,0.082880,0.000000
82.220001,61.571045,-103.907501,0.012215,0.003258,0.082751,273.881683,13.952198,0.827507,-103.907501,0.082880,0.000000
82.450005,61.539024,-103.907501,0.012227,0.003258,0.082751,273.739258,13.944942,0.827507,-103.907501,0.082880,0.000000
82.680000,61.543861,-103.951981,0.012206,0.003258,0.082751,273.760773,13.946038,0.827507,-103.951981,0.082880,0.000000
82.910004,61.516678,-103.951981,0.012210,0.003258,0.082751,273.639862,13.939878,0.827507,-103.951981,0.082880,0.000000
83.140007,61.495453,-104.085426,0.012219,0.003258,0.082751,273.545441,13.935069,0.827507,-104.085426,0.082880,0.000000
83.370003,61.471992,-104.129906,0.012210,0.003258,0.082751,273.441071,13.929752,0.827507,-104.129906,0.082880,0.000000
83.600006,61.476837,-104.174385,0.012223,0.003258,0.082751,273.462616,13.930850,0.827507,-104.174385,0.082880,0.000000
83.830002,61.453377,-104.174385,0.012232,0.003258,0.082751,273.358276,13.925534,0.827507,-104.174385,0.082880,0.000000
84.060005,61.433266,-104.174385,0.012219,0.003258,0.082751,273.268799,13.920977,0.827507,-104.174385,0.082880,0.000000
84.290001,61.425446,-104.263351,0.012232,0.003258,0.082751,273.234039,13.919206,0.827507,-104.263351,0.082880,0.000000
84.520004,61.396027,-104.307831,0.012232,0.003258,0.082751,273.103180,13.912539,0.827507,-104.307831,0.082880,0.000000
84.750008,61.382256,-104.352310,0.012215,0.003258,0.082751,273.041901,13.909418,0.827507,-104.352310,0.082880,0.000000
84.980003,61.367355,-104.352310,0.012210,0.003258,0.082751,272.975616,13.906042,0.827507,-104.352310,0.082880,0.000000
85.210007,61.347618,-104.352310,0.012206,0.003258,0.082751,272.887848,13.901568,0.827507,-104.352310,0.082880,0.000000
85.440002,61.339058,-104.396790,0.012206,0.003258,0.082751,272.849762,13.899630,0.827507,-104.396790,0.082880,0.000000
85.670006,61.320442,-104.441277,0.012223,0.003258,0.082751,272.766937,13.895411,0.827507,-104.441277,0.082880,0.000000
85.900002,61.308525,-104.485756,0.012219,0.003258,0.082751,272.713928,13.892710,0.827507,-104.485756,0.082880,0.000000
86.130005,61.288414,-104.485756,0.012223,0.003258,0.082751,272.624481,13.888154,0.827507,-104.485756,0.082880,0.000000
86.360001,61.276123,-104.530235,0.012219,0.003258,0.082751,272.569794,13.885368,0.827507,-104.530235,0.082880,0.000000
86.590004,61.259369,-104.619194,0.012227,0.003258,0.082751,272.495270,13.881572,0.827507,-104.619194,0.082880,0.000000
86.820007,61.237030,-104.708160,0.012210,0.003258,0.082751,272.395905,13.876510,0.827507,-104.708160,0.082880,0.000000
87.050003,61.218033,-104.708160,0.012219,0.003258,0.082751,272.311401,13.872205,0.827507,-104.708160,0.082880,0.000000
87.280006,61.202026,-104.752640,0.012210,0.003258,0.082751,272.240204,13.868578,0.827507,-104.752640,0.082880,0.000000
87.510002,61.191971,-104.708160,0.012215,0.003258,0.082751,272.195496,13.866299,0.827507,-104.708160,0.082880,0.000000
87.740005,61.176704,-104.797119,0.012223,0.003258,0.082751,272.127563,13.862840,0.827507,-104.797119,0.082880,0.000000
87.970001,61.164413,-104.841599,0.012210,0.003258,0.082751,272.072906,13.860054,0.827507,-104.841599,0.082880,0.000000
88.200005,61.137978,-104.841599,0.012219,0.003258,0.082751,271.955292,13.854064,0.827507,-104.841599,0.082880,0.000000
88.430008,61.144676,-104.841599,0.012227,0.003258,0.082751,271.985107,13.855582,0.827507,-104.841599,0.082880,0.000000
88.660004,61.126060,-104.930565,0.012227,0.003258,0.082751,271.902283,13.851363,0.827507,-104.930565,0.082880,0.000000
88.890007,61.102600,-104.975044,0.012223,0.003258,0.082751,271.797943,13.846047,0.827507,-104.975044,0.082880,0.000000
89.120003,61.088448,-105.019524,0.012219,0.003258,0.082751,271.734985,13.842840,0.827507,-105.019524,0.082880,0.000000
89.350006,61.078400,-105.019524,0.012210,0.003258,0.082751,271.690277,13.840564,0.827507,-105.019524,0.082880,0.000000
89.580002,61.060898,-105.064003,0.012215,0.003258,0.082751,271.612427,13.836597,0.827507,-105.064003,0.082880,0.000000
89.810005,61.044884,-105.152969,0.012223,0.003258,0.082751,271.541199,13.832969,0.827507,-105.152969,0.082880,0.000000
90.040001,61.024773,-105.197449,0.012215,0.003258,0.082751,271.451752,13.828411,0.827507,-105.197449,0.082880,0.000000
90.270004,61.025146,-105.197449,0.012227,0.003258,0.082751,271.453400,13.828496,0.827507,-105.197449,0.082880,0.000000
90.500008,61.006531,-105.241928,0.012223,0.003258,0.082751,271.370605,13.824278,0.827507,-105.241928,0.082880,0.000000
90.730003,60.977112,-105.241928,0.012219,0.003258,0.082751,271.239746,13.817611,0.827507,-105.241928,0.082880,0.000000
90.960007,60.965195,-105.286407,0.012232,0.003258,0.082751,271.186737,13.814911,0.827507,-105.286407,0.082880,0.000000
91.190002,60.961845,-105.330894,0.012240,0.003258,0.082751,271.171844,13.814152,0.827507,-105.330894,0.082880,0.000000
91.420006,60.934662,-105.419853,0.012202,0.003258,0.082751,271.050903,13.807992,0.827507,-105.419853,0.082880,0.000000
91.650002,60.922371,-105.419853,0.012210,0.003258,0.082751,270.996246,13.805207,0.827507,-105.419853,0.082880,0.000000
91.880005,60.917160,-105.419853,0.012227,0.003258,0.082751,270.973053,13.804026,0.827507,-105.419853,0.082880,0.000000
92.110001,60.890350,-105.419853,0.012219,0.003258,0.082751,270.853821,13.797951,0.827507,-105.419853,0.082880,0.000000
92.340004,60.877312,-105.464333,0.012219,0.003258,0.082751,270.795807,13.794996,0.827507,-105.464333,0.082880,0.000000
92.570007,60.862045,-105.553299,0.012223,0.003258,0.082751,270.727905,13.791536,0.827507,-105.553299,0.082880,0.000000
92.800003,60.848267,-105.553299,0.012219,0.003258,0.082751,270.666595,13.788415,0.827507,-105.553299,0.082880,0.000000
93.030006,60.845291,-105.642258,0.012227,0.003258,0.082751,270.653381,13.787740,0.827507,-105.642258,0.082880,0.000000
93.260002,60.823692,-105.642258,0.012227,0.003258,0.082751,270.557281,13.782845,0.827507,-105.642258,0.082880,0.000000
93.490005,60.812897,-105.642258,0.012219,0.003258,0.082751,270.509277,13.780399,0.827507,-105.642258,0.082880,0.000000
93.720001,60.794647,-105.775703,0.012215,0.003258,0.082751,270.428101,13.776264,0.827507,-105.775703,0.082880,0.000000
93.950005,60.781616,-105.775703,0.012227,0.003258,0.082751,270.370117,13.773311,0.827507,-105.775703,0.082880,0.000000
94.180008,60.776405,-105.820183,0.012219,0.003258,0.082751,270.346954,13.772130,0.827507,-105.820183,0.082880,0.000000
94.410004,60.771561,-105.820183,0.012215,0.003258,0.082751,270.325409,13.771032,0.827507,-105.820183,0.082880,0.000000
94.640007,60.739166,-105.864662,0.012232,0.003258,0.082751,270.181305,13.763692,0.827507,-105.864662,0.082880,0.000000
94.870003,60.727249,-105.909142,0.012227,0.003258,0.082751,270.128296,13.760991,0.827507,-105.909142,0.082880,0.000000
95.100006,60.728737,-105.953629,0.012210,0.003258,0.082751,270.134918,13.761328,0.827507,-105.953629,0.082880,0.000000
95.330002,60.717567,-105.953629,0.012219,0.003258,0.082751,270.085236,13.758797,0.827507,-105.953629,0.082880,0.000000
95.560005,60.691498,-105.953629,0.012227,0.003258,0.082751,269.969269,13.752890,0.827507,-105.953629,0.082880,0.000000
95.790001,60.689270,-106.087067,0.012232,0.003258,0.082751,269.959351,13.752385,0.827507,-106.087067,0.082880,0.000000
96.020004,60.686287,-106.131546,0.012215,0.003258,0.082751,269.946075,13.751710,0.827507,-106.131546,0.082880,0.000000
96.200005,60.682938,-106.176033,0.012206,0.003258,0.082751,269.931183,13.750951,0.827507,-106.176033,0.082880,0.000000