File: Data/compression 6/AutoNoheating-10-6-day1-3-240228_02282024_201943.csv
Time (sec),S:Load (lbs),S:HL1 (DIM),S:LVDT (in),S:Position (in),Ch:Position (mm),Ch:Load (N),Ch:Stress (MPa),Ch:Strain (mm/mm),Ch:HL1 (DIM),Set Point (),Cycles ()
0.110000,-0.011177,-127.749290,-0.000004,-0.000000,-0.000000,-0.049718,-0.002533,-0.000000,-127.749290,0.000165,0.000000
0.370000,-0.024208,-127.838257,-0.000017,-0.000000,-0.000000,-0.107683,-0.005486,-0.000000,-127.838257,0.000165,0.000000
0.630000,-0.066284,-127.793770,-0.000013,0.000125,0.003183,-0.294847,-0.015020,0.031827,-127.793770,0.004067,0.000000
0.890000,-0.005592,-127.793770,0.000134,0.000295,0.007484,-0.024876,-0.001267,0.074843,-127.793770,0.008404,0.000000
1.150000,0.004837,-127.838257,0.000293,0.000453,0.011517,0.021516,0.001096,0.115171,-127.838257,0.012740,0.000000
1.410000,-0.029419,-127.749290,0.000479,0.000632,0.016061,-0.130862,-0.006666,0.160612,-127.749290,0.017059,0.000000
1.670000,-0.008568,-127.793770,0.000660,0.000799,0.020302,-0.038112,-0.001941,0.203018,-127.793770,0.021394,0.000000
1.930000,0.004463,-127.793770,0.000811,0.000968,0.024577,0.019853,0.001011,0.245772,-127.793770,0.025731,0.000000
2.190000,-0.047295,-127.793770,0.001005,0.001144,0.029052,-0.210377,-0.010717,0.290521,-127.793770,0.030067,0.000000
2.450000,-0.010056,-127.793770,0.001155,0.001311,0.033293,-0.044729,-0.002279,0.332931,-127.793770,0.034386,0.000000
2.710000,-0.035004,-127.838257,0.001332,0.001475,0.037464,-0.155704,-0.007932,0.374644,-127.838257,0.038722,0.000000
2.970000,-0.071503,-127.838257,0.001526,0.001653,0.041991,-0.318060,-0.016203,0.419911,-127.838257,0.043058,0.000000
3.230000,-0.000374,-127.838257,0.001681,0.001827,0.046397,-0.001663,-0.000085,0.463968,-127.838257,0.047377,0.000000
3.490000,0.012657,-127.838257,0.001858,0.001996,0.050690,0.056302,0.002868,0.506896,-127.838257,0.051713,0.000000
3.750000,-0.016388,-127.838257,0.002026,0.002167,0.055043,-0.072897,-0.003714,0.550430,-127.838257,0.056049,0.000000
4.010000,0.004837,-127.838257,0.002195,0.002338,0.059379,0.021516,0.001096,0.593789,-127.838257,0.060385,0.000000
4.270000,-0.007454,-127.793770,0.002354,0.002505,0.063637,-0.033157,-0.001689,0.636370,-127.793770,0.064704,0.000000
4.530000,-0.054001,-127.838257,0.002535,0.002676,0.067965,-0.240208,-0.012237,0.679646,-127.838257,0.069040,0.000000
4.790000,-0.016762,-127.971695,0.002721,0.002846,0.072292,-0.074560,-0.003798,0.722919,-127.971695,0.073376,0.000000
5.050000,-0.026070,-127.882736,0.002897,0.003022,0.076758,-0.115964,-0.005907,0.767584,-127.882736,0.077712,0.000000
5.310000,-0.024582,-127.882736,0.003057,0.003190,0.081016,-0.109346,-0.005570,0.810164,-127.882736,0.082031,0.000000
5.570000,-0.010056,-127.882736,0.003229,0.003358,0.085292,-0.044729,-0.002279,0.852919,-127.882736,0.086367,0.000000
5.830000,0.010796,-127.793770,0.003419,0.003532,0.089714,0.048021,0.002446,0.897145,-127.793770,0.090703,0.000000
6.090000,-0.003731,-127.971695,0.003583,0.003700,0.093973,-0.016595,-0.000845,0.939725,-127.971695,0.095039,0.000000
6.350000,-0.013412,-127.971695,0.003747,0.003872,0.098344,-0.059662,-0.003039,0.983437,-127.971695,0.099358,0.000000
6.610000,-0.000374,-127.882736,0.003923,0.004041,0.102636,-0.001663,-0.000085,1.026361,-127.882736,0.103694,0.000000
6.870000,-0.063309,-127.927216,0.004083,0.004209,0.106920,-0.281611,-0.014346,1.069203,-127.927216,0.108030,0.000000
7.130000,-0.008568,-127.927216,0.004260,0.004380,0.111248,-0.038112,-0.001941,1.112479,-127.927216,0.112349,0.000000
7.390000,-0.002983,-127.971695,0.004424,0.004557,0.115740,-0.013269,-0.000676,1.157402,-127.971695,0.116685,0.000000
7.650001,-0.023094,-128.016174,0.004596,0.004722,0.119929,-0.102728,-0.005233,1.199289,-128.016174,0.121022,0.000000
7.910000,0.029411,-127.971695,0.004764,0.004893,0.124274,0.130828,0.006665,1.242736,-127.971695,0.125358,0.000000
8.170000,0.032394,-128.060654,0.004954,0.005068,0.128740,0.144098,0.007341,1.287398,-128.060654,0.129677,0.000000
8.430000,0.026062,-127.927216,0.005113,0.005231,0.132876,0.115930,0.005906,1.328763,-127.927216,0.134013,0.000000
8.690001,0.106125,-128.105133,0.005290,0.005400,0.137169,0.472067,0.024048,1.371691,-128.105133,0.138349,0.000000
8.950001,0.186928,-128.016174,0.005441,0.005574,0.141583,0.831496,0.042358,1.415835,-128.016174,0.142685,0.000000
9.210000,0.318001,-128.016174,0.005627,0.005745,0.145928,1.414538,0.072060,1.459281,-128.016174,0.147003,0.000000
9.470000,0.690002,-128.060654,0.005790,0.005911,0.150152,3.069284,0.156357,1.501517,-128.060654,0.151270,0.000000
9.730000,0.572708,-128.016174,0.005790,-0.000002,-0.000044,2.547533,0.129778,-0.000435,-128.016174,0.000173,0.000000
9.990001,0.536957,-128.060654,0.005786,-0.000002,-0.000044,2.388503,0.121676,-0.000435,-128.060654,0.000173,0.000000
10.250001,0.527649,-128.060654,0.005790,-0.000001,-0.000035,2.347100,0.119567,-0.000348,-128.060654,0.000607,0.000000
10.510000,0.538818,-128.016174,0.005795,0.000007,0.000182,2.396784,0.122098,0.001821,-128.016174,0.001040,0.000000
10.770000,0.605476,-128.149612,0.005799,0.000028,0.000711,2.693293,0.137203,0.007112,-128.149612,0.001474,0.000000
11.030001,0.667664,-128.060654,0.005825,0.000046,0.001171,2.969916,0.151295,0.011707,-128.060654,0.001908,0.000000
11.290001,0.671387,-128.149612,0.005821,0.000060,0.001535,2.986477,0.152138,0.015348,-128.149612,0.002341,0.000000
11.550000,0.711227,-128.105133,0.005846,0.000077,0.001960,3.163697,0.161166,0.019598,-128.105133,0.002775,0.000000
11.810000,0.774162,-128.060654,0.005855,0.000096,0.002428,3.443646,0.175428,0.024280,-128.060654,0.003208,0.000000
12.070001,0.821075,-128.149612,0.005890,0.000112,0.002844,3.652326,0.186058,0.028443,-128.149612,0.003642,0.000000
12.330001,0.840065,-128.060654,0.005877,0.000123,0.003122,3.736796,0.190361,0.031218,-128.060654,0.004076,0.000000
12.590000,0.925339,-128.105133,0.005902,0.000141,0.003582,4.116112,0.209685,0.035816,-128.105133,0.004509,0.000000
12.850000,0.979706,-128.060654,0.005928,0.000165,0.004197,4.357949,0.222005,0.041974,-128.060654,0.004943,0.000000
13.110001,0.982315,-128.105133,0.005941,0.000180,0.004562,4.369555,0.222596,0.045616,-128.105133,0.005377,0.000000
13.370001,1.009499,-128.105133,0.005967,0.000194,0.004926,4.490474,0.228756,0.049257,-128.105133,0.005810,0.000000
13.630001,1.045990,-128.105133,0.005971,0.000210,0.005342,4.652796,0.237025,0.053420,-128.105133,0.006244,0.000000
13.890000,1.109665,-128.194107,0.005984,0.000230,0.005854,4.936036,0.251454,0.058537,-128.194107,0.006678,0.000000
14.150001,1.149139,-128.149612,0.006002,0.000244,0.006200,5.111628,0.260399,0.062004,-128.149612,0.007102,0.000000
14.410001,1.215424,-128.149612,0.006006,0.000259,0.006574,5.406474,0.275419,0.065736,-128.149612,0.007536,0.000000
14.670001,1.302925,-128.194107,0.006019,0.000285,0.007233,5.795701,0.295247,0.072326,-128.194107,0.007970,0.000000
14.930000,1.322662,-128.149612,0.006066,0.000302,0.007666,5.883496,0.299720,0.076663,-128.149612,0.008403,0.000000
15.190001,1.323036,-128.149612,0.006066,0.000317,0.008057,5.885159,0.299804,0.080565,-128.149612,0.008837,0.000000
15.450001,1.358040,-128.194107,0.006071,0.000335,0.008507,6.040863,0.307736,0.085073,-128.194107,0.009271,0.000000
15.710001,1.435493,-128.149612,0.006096,0.000351,0.008915,6.385394,0.325287,0.089149,-128.149612,0.009704,0.000000
15.970001,1.481667,-128.238586,0.006105,0.000365,0.009271,6.590782,0.335750,0.092707,-128.238586,0.010138,0.000000
16.230001,1.506989,-128.149612,0.006127,0.000378,0.009609,6.703420,0.341488,0.096087,-128.149612,0.010571,0.000000
16.490002,1.583321,-128.238586,0.006153,0.000396,0.010069,7.042962,0.358786,0.100686,-128.238586,0.011005,0.000000
16.750000,1.695412,-128.194107,0.006165,0.000421,0.010693,7.541568,0.384186,0.106927,-128.194107,0.011439,0.000000
17.010000,1.719612,-128.283066,0.006183,0.000436,0.011066,7.649217,0.389670,0.110659,-128.283066,0.011872,0.000000
17.270000,1.718864,-128.238586,0.006187,0.000452,0.011473,7.645891,0.389500,0.114732,-128.238586,0.012306,0.000000
17.530001,1.774353,-128.194107,0.006209,0.000466,0.011846,7.892716,0.402074,0.118463,-128.194107,0.012740,0.000000
17.790001,1.858505,-128.327545,0.006239,0.000486,0.012349,8.267044,0.421143,0.123494,-128.327545,0.013173,0.000000
18.050001,1.922554,-128.194107,0.006234,0.000504,0.012800,8.551948,0.435657,0.128001,-128.194107,0.013607,0.000000
18.310001,2.001129,-128.283066,0.006252,0.000521,0.013234,8.901467,0.453462,0.132339,-128.283066,0.014040,0.000000
18.570002,2.046928,-128.283066,0.006260,0.000539,0.013702,9.105192,0.463841,0.137021,-128.283066,0.014474,0.000000
18.830002,2.060333,-128.283066,0.006282,0.000555,0.014101,9.164820,0.466878,0.141010,-128.283066,0.014908,0.000000
19.090000,2.116936,-128.327545,0.006295,0.000571,0.014509,9.416600,0.479704,0.145086,-128.327545,0.015341,0.000000
19.350000,2.194763,-128.327545,0.006316,0.000591,0.015012,9.762794,0.497340,0.150117,-128.327545,0.015775,0.000000
19.610001,2.212631,-128.283066,0.006334,0.000604,0.015350,9.842276,0.501389,0.153496,-128.283066,0.016208,0.000000
19.870001,2.300514,-128.327545,0.006338,0.000623,0.015836,10.233198,0.521304,0.158356,-128.327545,0.016642,0.000000
20.130001,2.269608,-128.283066,0.006364,0.000633,0.016078,10.095718,0.514300,0.160782,-128.283066,0.017076,0.000000
20.390001,2.357483,-128.372025,0.006381,0.000651,0.016546,10.486608,0.534213,0.165464,-128.372025,0.017509,0.000000
20.650002,2.536972,-128.372025,0.006394,0.000678,0.017232,11.285015,0.574886,0.172319,-128.372025,0.017943,0.000000
20.910002,2.482231,-128.283066,0.006407,0.000691,0.017544,11.041515,0.562482,0.175437,-128.283066,0.018376,0.000000
21.170000,2.504944,-128.372025,0.006411,0.000707,0.017969,11.142547,0.567628,0.179688,-128.372025,0.018810,0.000000
21.430000,2.567131,-128.372025,0.006433,0.000723,0.018376,11.419169,0.581720,0.183764,-128.372025,0.019244,0.000000
21.690001,2.654266,-128.372025,0.006450,0.000743,0.018862,11.806767,0.601465,0.188620,-128.372025,0.019677,0.000000
21.950001,2.701927,-128.416504,0.006467,0.000757,0.019235,12.018772,0.612265,0.192348,-128.416504,0.020111,0.000000
22.210001,2.752571,-128.460983,0.006476,0.000773,0.019642,12.244048,0.623742,0.196425,-128.460983,0.020544,0.000000
22.470001,2.825188,-128.416504,0.006506,0.000794,0.020172,12.567062,0.640197,0.201716,-128.416504,0.020978,0.000000
22.730001,2.840080,-128.416504,0.006515,0.000812,0.020614,12.633308,0.643571,0.206141,-128.416504,0.021412,0.000000
22.990002,2.876198,-128.460983,0.006536,0.000828,0.021021,12.793967,0.651756,0.210213,-128.460983,0.021837,0.000000
23.250002,2.913063,-128.372025,0.006541,0.000842,0.021386,12.957952,0.660110,0.213858,-128.372025,0.022270,0.000000
23.510000,2.979721,-128.416504,0.006549,0.000857,0.021767,13.254461,0.675214,0.217673,-128.416504,0.022704,0.000000
23.770000,3.056427,-128.416504,0.006566,0.000876,0.022262,13.595666,0.692596,0.222616,-128.416504,0.023137,0.000000
24.030001,3.045258,-128.416504,0.006601,0.000889,0.022574,13.545982,0.690065,0.225739,-128.416504,0.023571,0.000000
24.290001,3.085106,-128.549942,0.006592,0.000905,0.022990,13.723236,0.699095,0.229902,-128.549942,0.024005,0.000000
24.550001,3.266449,-128.460983,0.006614,0.000931,0.023658,14.529891,0.740188,0.236579,-128.460983,0.024438,0.000000
24.810001,3.249687,-128.460983,0.006618,0.000947,0.024057,14.455331,0.736390,0.240568,-128.460983,0.024872,0.000000
25.070002,3.239265,-128.460983,0.006653,0.000962,0.024447,14.408973,0.734028,0.244470,-128.460983,0.025305,0.000000
25.330002,3.293259,-128.460983,0.006661,0.000976,0.024802,14.649146,0.746263,0.248024,-128.460983,0.025739,0.000000
25.590002,3.394547,-128.505463,0.006674,0.000995,0.025262,15.099697,0.769215,0.252623,-128.505463,0.026173,0.000000
25.850000,3.447052,-128.505463,0.006687,0.001011,0.025679,15.333253,0.781113,0.256786,-128.505463,0.026606,0.000000
26.110001,3.451889,-128.549942,0.006691,0.001024,0.025999,15.354770,0.782209,0.259992,-128.549942,0.027040,0.000000
26.370001,3.598602,-128.549942,0.006704,0.001045,0.026554,16.007383,0.815455,0.265544,-128.549942,0.027474,0.000000
26.630001,3.616104,-128.505463,0.006722,0.001064,0.027014,16.085234,0.819421,0.270139,-128.505463,0.027907,0.000000
26.890001,3.616852,-128.594437,0.006739,0.001083,0.027517,16.088560,0.819590,0.275169,-128.594437,0.028341,0.000000
27.150002,3.618713,-128.505463,0.006748,0.001096,0.027838,16.096842,0.820012,0.278379,-128.505463,0.028774,0.000000
27.410002,3.741966,-128.549942,0.006773,0.001115,0.028324,16.645098,0.847942,0.283235,-128.549942,0.029208,0.000000
27.670002,3.806389,-128.549942,0.006782,0.001132,0.028749,16.931664,0.862540,0.287485,-128.549942,0.029642,0.000000
27.930002,3.837296,-128.549942,0.006799,0.001148,0.029165,17.069143,0.869544,0.291649,-128.549942,0.030075,0.000000
28.190001,3.727814,-128.594437,0.006804,0.001159,0.029434,16.582144,0.844735,0.294336,-128.594437,0.030509,0.000000
28.450001,4.037628,-128.594437,0.006829,0.001189,0.030205,17.960268,0.914940,0.302054,-128.594437,0.030943,0.000000
28.710001,3.916985,-128.638916,0.006842,0.001202,0.030535,17.423618,0.887601,0.305350,-128.638916,0.031376,0.000000
28.970001,3.922195,-128.594437,0.006851,0.001216,0.030890,17.446796,0.888782,0.308904,-128.594437,0.031810,0.000000
29.230001,4.060349,-128.594437,0.006881,0.001238,0.031446,18.061333,0.920088,0.314457,-128.594437,0.032244,0.000000
29.490002,4.112106,-128.683395,0.006873,0.001254,0.031853,18.291563,0.931817,0.318533,-128.683395,0.032677,0.000000
29.750002,4.096092,-128.638916,0.006898,0.001267,0.032183,18.220327,0.928188,0.321826,-128.638916,0.033111,0.000000
30.010002,4.109871,-128.683395,0.006898,0.001279,0.032486,18.281618,0.931310,0.324861,-128.683395,0.033544,0.000000
30.270002,4.403297,-128.549942,0.006933,0.001311,0.033293,19.586845,0.997801,0.332927,-128.549942,0.033978,0.000000
30.530001,4.278557,-128.594437,0.006937,0.001324,0.033640,19.031971,0.969535,0.336398,-128.594437,0.034412,0.000000
30.790001,4.221214,-128.683395,0.006954,0.001338,0.033986,18.776899,0.956541,0.339865,-128.683395,0.034845,0.000000
31.050001,4.324356,-128.549942,0.006972,0.001358,0.034489,19.235697,0.979913,0.344895,-128.549942,0.035279,0.000000
31.310001,4.395111,-128.727875,0.006985,0.001375,0.034923,19.550430,0.995946,0.349232,-128.727875,0.035712,0.000000
31.570002,4.434952,-128.638916,0.006998,0.001389,0.035279,19.727652,1.004974,0.352786,-128.638916,0.036146,0.000000
31.830002,4.520226,-128.683395,0.007011,0.001405,0.035686,20.106968,1.024298,0.356863,-128.683395,0.036579,0.000000
32.090000,4.614433,-128.683395,0.007023,0.001424,0.036181,20.526024,1.045645,0.361806,-128.683395,0.037005,0.000000
32.350002,4.670288,-128.727875,0.007036,0.001445,0.036692,20.774479,1.058302,0.366923,-128.727875,0.037438,0.000000
32.610001,4.596191,-128.727875,0.007054,0.001458,0.037039,20.444880,1.041512,0.370390,-128.727875,0.037872,0.000000
32.870003,4.664337,-128.772354,0.007071,0.001474,0.037447,20.748009,1.056954,0.374466,-128.772354,0.038305,0.000000
33.130001,4.713112,-128.638916,0.007080,0.001493,0.037924,20.964970,1.068007,0.379235,-128.638916,0.038739,0.000000
33.390003,4.720932,-128.683395,0.007105,0.001510,0.038366,20.999754,1.069778,0.383660,-128.683395,0.039173,0.000000
33.650002,4.716095,-128.727875,0.007118,0.001521,0.038643,20.978239,1.068682,0.386434,-128.727875,0.039606,0.000000
33.910000,4.835251,-128.727875,0.007127,0.001540,0.039112,21.508270,1.095683,0.391120,-128.727875,0.040040,0.000000
34.170002,4.965958,-128.727875,0.007144,0.001562,0.039676,22.089684,1.125302,0.396755,-128.727875,0.040473,0.000000
34.430000,4.894463,-128.816833,0.007157,0.001577,0.040066,21.771656,1.109101,0.400658,-128.816833,0.040907,0.000000
34.690002,4.889244,-128.727875,0.007161,0.001593,0.040456,21.748444,1.107919,0.404560,-128.727875,0.041341,0.000000
34.950001,4.904144,-128.727875,0.007179,0.001609,0.040864,21.814724,1.111295,0.408636,-128.727875,0.041774,0.000000
35.210003,5.060539,-128.772354,0.007192,0.001629,0.041384,22.510403,1.146735,0.413840,-128.772354,0.042208,0.000000
35.470001,5.026283,-128.816833,0.007213,0.001643,0.041739,22.358025,1.138972,0.417394,-128.816833,0.042641,0.000000
35.730003,5.131287,-128.861313,0.007213,0.001661,0.042191,22.825104,1.162766,0.421906,-128.861313,0.043075,0.000000
35.990002,5.210976,-128.772354,0.007243,0.001682,0.042728,23.179577,1.180824,0.427281,-128.772354,0.043509,0.000000
36.250000,5.226990,-128.772354,0.007269,0.001701,0.043196,23.250813,1.184453,0.431962,-128.772354,0.043942,0.000000
36.510002,5.140968,-128.861313,0.007265,0.001716,0.043578,22.868170,1.164960,0.435781,-128.861313,0.044376,0.000000
36.770000,5.143204,-128.772354,0.007274,0.001733,0.044029,22.878113,1.165467,0.440289,-128.772354,0.044809,0.000000
37.030003,5.203529,-128.816833,0.007295,0.001747,0.044385,23.146454,1.179137,0.443847,-128.816833,0.045243,0.000000
37.290001,5.223267,-128.905792,0.007308,0.001763,0.044783,23.234251,1.183609,0.447833,-128.905792,0.045677,0.000000
37.550003,5.235924,-128.905792,0.007325,0.001776,0.045122,23.290552,1.186477,0.451216,-128.905792,0.046110,0.000000
37.810001,5.349869,-128.905792,0.007338,0.001797,0.045633,23.797405,1.212298,0.456333,-128.905792,0.046544,0.000000
38.070004,5.521164,-128.861313,0.007351,0.001819,0.046197,24.559364,1.251114,0.461969,-128.861313,0.046977,0.000000
38.330002,5.445572,-128.905792,0.007381,0.001835,0.046605,24.223114,1.233984,0.466045,-128.905792,0.047411,0.000000
38.590000,5.402374,-128.861313,0.007377,0.001850,0.046995,24.030960,1.224195,0.469948,-128.861313,0.047845,0.000000
38.850002,5.397911,-128.905792,0.007403,0.001864,0.047351,24.011108,1.223184,0.473505,-128.905792,0.048278,0.000000
39.110001,5.503288,-128.950272,0.007411,0.001883,0.047836,24.479849,1.247063,0.478362,-128.950272,0.048712,0.000000
39.370003,5.613510,-128.861313,0.007416,0.001902,0.048322,24.970140,1.272040,0.483218,-128.861313,0.049146,0.000000
39.630001,5.658195,-128.905792,0.007437,0.001919,0.048747,25.168911,1.282165,0.487468,-128.905792,0.049579,0.000000
39.890003,5.716286,-128.950272,0.007450,0.001939,0.049250,25.427309,1.295329,0.492498,-128.950272,0.050013,0.000000
40.150002,5.629150,-128.950272,0.007472,0.001953,0.049614,25.039711,1.275584,0.496139,-128.950272,0.050447,0.000000
40.410004,5.670860,-128.905792,0.007489,0.001970,0.050048,25.225246,1.285035,0.500477,-128.905792,0.050880,0.000000
40.670002,5.787407,-128.905792,0.007511,0.001990,0.050542,25.743671,1.311445,0.505420,-128.905792,0.051314,0.000000
40.930000,5.731926,-128.950272,0.007502,0.002003,0.050889,25.496880,1.298873,0.508887,-128.950272,0.051747,0.000000
41.190002,5.870445,-128.950272,0.007515,0.002024,0.051400,26.113045,1.330262,0.514004,-128.950272,0.052172,0.000000
41.450001,5.699905,-128.994751,0.007545,0.002033,0.051626,25.354446,1.291617,0.516260,-128.994751,0.052606,0.000000
41.710003,5.855553,-128.905792,0.007545,0.002053,0.052155,26.046799,1.326887,0.521547,-128.905792,0.053039,0.000000
41.970001,6.148239,-128.994751,0.007584,0.002078,0.052771,27.348734,1.393211,0.527705,-128.994751,0.053473,0.000000
42.230003,5.919975,-129.039246,0.007584,0.002089,0.053057,26.333364,1.341486,0.530567,-129.039246,0.053907,0.000000
42.490002,5.927048,-128.994751,0.007606,0.002107,0.053508,26.364824,1.343088,0.535078,-128.994751,0.054340,0.000000
42.750004,5.981789,-128.994751,0.007614,0.002121,0.053872,26.608324,1.355493,0.538719,-128.994751,0.054774,0.000000
43.010002,6.111000,-129.039246,0.007618,0.002141,0.054384,27.183086,1.384772,0.543836,-129.039246,0.055208,0.000000
43.270000,6.110252,-128.950272,0.007644,0.002156,0.054774,27.179760,1.384603,0.547739,-128.950272,0.055641,0.000000
43.530003,6.159782,-129.083725,0.007644,0.002172,0.055164,27.400080,1.395827,0.551641,-129.083725,0.056075,0.000000
43.790001,6.303886,-128.994751,0.007670,0.002196,0.055771,28.041088,1.428481,0.557712,-128.994751,0.056508,0.000000
44.050003,6.192551,-129.039246,0.007696,0.002210,0.056144,27.545841,1.403252,0.561440,-129.039246,0.056942,0.000000
44.310001,6.189941,-129.083725,0.007705,0.002226,0.056543,27.534235,1.402661,0.565429,-129.083725,0.057376,0.000000
44.570004,6.182495,-129.083725,0.007713,0.002242,0.056951,27.501112,1.400973,0.569506,-129.083725,0.057809,0.000000
44.830002,6.281548,-129.128204,0.007718,0.002260,0.057410,27.941719,1.423419,0.574104,-129.128204,0.058243,0.000000
45.090004,6.334793,-128.994751,0.007748,0.002274,0.057757,28.178568,1.435485,0.577571,-128.994751,0.058676,0.000000
45.350002,6.328842,-129.172684,0.007765,0.002289,0.058139,28.152096,1.434136,0.581386,-129.172684,0.059110,0.000000
45.610001,6.273354,-129.083725,0.007752,0.002302,0.058477,27.905270,1.421562,0.584770,-129.083725,0.059544,0.000000
45.870003,6.659882,-129.172684,0.007787,0.002332,0.059223,29.624634,1.509151,0.592226,-129.172684,0.059977,0.000000
46.130001,6.548164,-129.172684,0.007782,0.002348,0.059630,29.127689,1.483835,0.596303,-129.172684,0.060411,0.000000
46.390003,6.490074,-129.083725,0.007830,0.002361,0.059977,28.869291,1.470672,0.599773,-129.083725,0.060844,0.000000
46.650002,6.385811,-129.172684,0.007830,0.002373,0.060281,28.405506,1.447045,0.602809,-129.172684,0.061278,0.000000
46.910004,6.589500,-129.172684,0.007830,0.002392,0.060758,29.311562,1.493202,0.607578,-129.172684,0.061712,0.000000
47.170002,6.611473,-129.128204,0.007860,0.002408,0.061174,29.409302,1.498181,0.611741,-129.128204,0.062145,0.000000
47.430004,6.604767,-129.172684,0.007860,0.002422,0.061521,29.379471,1.496662,0.615208,-129.172684,0.062579,0.000000
47.690002,6.884048,-129.083725,0.007886,0.002443,0.062050,30.621777,1.559948,0.620499,-129.083725,0.063012,0.000000
47.950001,6.890007,-129.172684,0.007903,0.002462,0.062527,30.648281,1.561298,0.625268,-129.172684,0.063446,0.000000
48.210003,6.894470,-129.172684,0.007907,0.002480,0.063004,30.668135,1.562309,0.630037,-129.172684,0.063880,0.000000
48.470001,6.751854,-129.172684,0.007942,0.002493,0.063316,30.033747,1.529992,0.633160,-129.172684,0.064313,0.000000
48.730003,6.911598,-129.172684,0.007938,0.002512,0.063810,30.744324,1.566191,0.638103,-129.172684,0.064747,0.000000
48.990002,7.066139,-129.217163,0.007950,0.002531,0.064278,31.431757,1.601210,0.642785,-129.217163,0.065180,0.000000
49.250004,6.805847,-129.261642,0.007968,0.002540,0.064513,30.273920,1.542227,0.645128,-129.261642,0.065614,0.000000
49.510002,6.846809,-129.172684,0.007976,0.002554,0.064860,30.456129,1.551509,0.648599,-129.172684,0.066048,0.000000
49.770000,7.444466,-129.261642,0.008015,0.002587,0.065710,33.114635,1.686940,0.657096,-129.261642,0.066481,0.000000
50.030003,7.154762,-129.306122,0.008011,0.002598,0.065996,31.825972,1.621292,0.659957,-129.306122,0.066906,0.000000
50.290001,7.168541,-129.217163,0.008024,0.002615,0.066412,31.887262,1.624415,0.664120,-129.217163,0.067340,0.000000
50.550003,7.295891,-129.217163,0.008050,0.002633,0.066880,32.453743,1.653273,0.668802,-129.217163,0.067773,0.000000
50.810001,7.358078,-129.217163,0.008067,0.002649,0.067279,32.730366,1.667364,0.672792,-129.217163,0.068207,0.000000
51.070004,7.298126,-129.306122,0.008088,0.002663,0.067635,32.463688,1.653779,0.676349,-129.306122,0.068641,0.000000
51.330002,7.393082,-129.217163,0.008106,0.002677,0.067999,32.886070,1.675296,0.679990,-129.217163,0.069074,0.000000
51.590004,8.045479,-129.261642,0.008110,0.002709,0.068814,35.788078,1.823132,0.688143,-129.261642,0.069508,0.000000
51.850002,7.632889,-129.261642,0.008123,0.002722,0.069135,33.952785,1.729637,0.691353,-129.261642,0.069942,0.000000
52.110001,7.560272,-129.261642,0.008140,0.002737,0.069508,33.629772,1.713182,0.695081,-129.261642,0.070375,0.000000
52.370003,7.444466,-129.350601,0.008140,0.002750,0.069846,33.114635,1.686940,0.698465,-129.350601,0.070809,0.000000
52.630001,7.792259,-129.261642,0.008157,0.002770,0.070366,34.661701,1.765751,0.703665,-129.261642,0.071242,0.000000
52.890003,7.868599,-129.261642,0.008179,0.002787,0.070792,35.001278,1.783050,0.707915,-129.261642,0.071676,0.000000
53.150002,8.003395,-129.395081,0.008188,0.002803,0.071190,35.600880,1.813595,0.711905,-129.395081,0.072110,0.000000
53.410004,7.978821,-129.350601,0.008209,0.002817,0.071555,35.491566,1.808027,0.715546,-129.350601,0.072543,0.000000
53.670002,8.382469,-129.395081,0.008244,0.002843,0.072223,37.287086,1.899495,0.722226,-129.395081,0.072977,0.000000
53.930004,8.168732,-129.306122,0.008248,0.002857,0.072561,36.336334,1.851061,0.725606,-129.306122,0.073411,0.000000
54.190002,8.334061,-129.306122,0.008261,0.002874,0.072994,37.071754,1.888525,0.729944,-129.306122,0.073844,0.000000
54.450001,8.403702,-129.395081,0.008274,0.002891,0.073419,37.381531,1.904306,0.734194,-129.395081,0.074278,0.000000
54.710003,8.429016,-129.306122,0.008278,0.002907,0.073835,37.494137,1.910042,0.738354,-129.306122,0.074712,0.000000
54.970001,8.433113,-129.395081,0.008300,0.002920,0.074165,37.512360,1.910971,0.741650,-129.395081,0.075145,0.000000
55.230003,8.710159,-129.395081,0.008313,0.002939,0.074642,38.744724,1.973750,0.746419,-129.395081,0.075579,0.000000
55.490002,8.971939,-129.350601,0.008338,0.002959,0.075162,39.909180,2.033070,0.751623,-129.350601,0.076012,0.000000
55.750004,8.853897,-129.395081,0.008347,0.002976,0.075579,39.384102,2.006322,0.755787,-129.395081,0.076446,0.000000
56.010002,8.923904,-129.350601,0.008377,0.002993,0.076021,39.695511,2.022186,0.760208,-129.350601,0.076880,0.000000
56.270004,8.914963,-129.395081,0.008377,0.003007,0.076385,39.655735,2.020159,0.763852,-129.395081,0.077313,0.000000
56.530003,9.230736,-129.439575,0.008390,0.003027,0.076880,41.060364,2.091715,0.768795,-129.439575,0.077747,0.000000
56.790001,9.367767,-129.395081,0.008412,0.003044,0.077322,41.669910,2.122766,0.773216,-129.395081,0.078180,0.000000
57.050003,9.387505,-129.439575,0.008407,0.003056,0.077625,41.757706,2.127239,0.776252,-129.439575,0.078614,0.000000
57.310001,9.771049,-129.439575,0.008429,0.003078,0.078189,43.463799,2.214152,0.781891,-129.439575,0.079048,0.000000
57.570004,9.977341,-129.484055,0.008451,0.003099,0.078727,44.381428,2.260898,0.787266,-129.484055,0.079481,0.000000
57.830002,9.822433,-129.395081,0.008459,0.003113,0.079082,43.692368,2.225795,0.790824,-129.395081,0.079915,0.000000
58.090004,9.953140,-129.395081,0.008476,0.003133,0.079568,44.273781,2.255414,0.795680,-129.395081,0.080348,0.000000
58.350002,10.006386,-129.484055,0.008494,0.003146,0.079906,44.510628,2.267479,0.799059,-129.484055,0.080782,0.000000
58.610004,10.210449,-129.439575,0.008502,0.003162,0.080305,45.418346,2.313721,0.803049,-129.439575,0.081216,0.000000
58.870003,10.358650,-129.439575,0.008524,0.003176,0.080661,46.077576,2.347304,0.806607,-129.439575,0.081649,0.000000
59.130001,10.455467,-129.484055,0.008532,0.003192,0.081068,46.508240,2.369243,0.810683,-129.484055,0.082074,0.000000
59.390003,11.157021,-129.528534,0.008554,0.003218,0.081736,49.628906,2.528217,0.817359,-129.528534,0.082508,0.000000
59.650002,11.116806,-129.484055,0.008554,0.003233,0.082109,49.450024,2.519104,0.821088,-129.484055,0.082941,0.000000
59.910004,11.174896,-129.439575,0.008580,0.003249,0.082516,49.708420,2.532268,0.825164,-129.439575,0.083375,0.000000
60.170002,11.283997,-129.528534,0.008606,0.003263,0.082880,50.193722,2.556990,0.828805,-129.528534,0.083809,0.000000
60.430004,11.757660,-129.528534,0.008614,0.003285,0.083444,52.300682,2.664324,0.834444,-129.528534,0.084242,0.000000
60.690002,12.013107,-129.573013,0.008636,0.003301,0.083843,53.436970,2.722209,0.838434,-129.573013,0.084676,0.000000
60.950005,12.079384,-129.528534,0.008632,0.003315,0.084199,53.731785,2.737227,0.841988,-129.528534,0.085109,0.000000
61.210003,12.853180,-129.484055,0.008653,0.003341,0.084849,57.173801,2.912572,0.848494,-129.484055,0.085543,0.000000
61.470001,12.689705,-129.617493,0.008666,0.003352,0.085153,56.446625,2.875528,0.851529,-129.617493,0.085977,0.000000
61.730003,12.953720,-129.484055,0.008688,0.003370,0.085595,57.621025,2.935355,0.855950,-129.484055,0.086410,0.000000
61.990002,13.289970,-129.573013,0.008709,0.003387,0.086037,59.116741,3.011550,0.860375,-129.573013,0.086844,0.000000
62.250004,13.559937,-129.573013,0.008714,0.003404,0.086454,60.317612,3.072726,0.864538,-129.573013,0.087277,0.000000
62.510002,13.962471,-129.484055,0.008735,0.003420,0.086861,62.108173,3.163941,0.868611,-129.484055,0.087711,0.000000
62.770004,13.872734,-129.617493,0.008735,0.003431,0.087139,61.709003,3.143606,0.871389,-129.617493,0.088145,0.000000
63.030003,14.395912,-129.528534,0.008748,0.003448,0.087590,64.036217,3.262160,0.875897,-129.528534,0.088578,0.000000
63.290005,15.508194,-129.617493,0.008770,0.003476,0.088301,68.983894,3.514207,0.883008,-129.617493,0.089012,0.000000
63.550003,15.357010,-129.617493,0.008787,0.003488,0.088596,68.311394,3.479948,0.885957,-129.617493,0.089445,0.000000
63.810001,15.656021,-129.661972,0.008791,0.003505,0.089021,69.641457,3.547705,0.890207,-129.661972,0.089879,0.000000
64.070000,16.000099,-129.661972,0.008808,0.003519,0.089394,71.171997,3.625674,0.893935,-129.661972,0.090313,0.000000
64.330002,16.690849,-129.617493,0.008821,0.003540,0.089914,74.244606,3.782201,0.899140,-129.617493,0.090746,0.000000
64.590004,16.967522,-129.617493,0.008830,0.003554,0.090269,75.475304,3.844895,0.902694,-129.617493,0.091180,0.000000
64.850006,17.467987,-129.661972,0.008834,0.003570,0.090677,77.701485,3.958302,0.906770,-129.661972,0.091614,0.000000
65.110001,18.544891,-129.617493,0.008852,0.003596,0.091328,82.491798,4.202332,0.913276,-129.617493,0.092047,0.000000
65.370003,18.584732,-129.750931,0.008864,0.003609,0.091657,82.669014,4.211360,0.916569,-129.750931,0.092481,0.000000
65.630005,19.023392,-129.706451,0.008882,0.003625,0.092065,84.620270,4.310762,0.920645,-129.706451,0.092915,0.000000
65.889999,19.336182,-129.706451,0.008890,0.003640,0.092446,86.011635,4.381641,0.924461,-129.706451,0.093348,0.000000
66.150002,20.198593,-129.706451,0.008899,0.003659,0.092940,89.847832,4.577066,0.929404,-129.706451,0.093782,0.000000
66.410004,20.511765,-129.706451,0.008921,0.003672,0.093270,91.240883,4.648032,0.932700,-129.706451,0.094215,0.000000
66.670006,21.107185,-129.706451,0.008938,0.003688,0.093678,93.889450,4.782957,0.936777,-129.706451,0.094649,0.000000
66.930000,21.411415,-129.661972,0.008951,0.003701,0.094007,95.242729,4.851896,0.940073,-129.661972,0.095083,0.000000
67.190002,23.001068,-129.750931,0.008959,0.003730,0.094736,102.313858,5.212116,0.947355,-129.750931,0.095516,0.000000
67.450005,23.424828,-129.706451,0.008990,0.003745,0.095126,104.198837,5.308142,0.951258,-129.706451,0.095950,0.000000
67.710007,23.941681,-129.706451,0.008985,0.003760,0.095499,106.497917,5.425262,0.954990,-129.706451,0.096383,0.000000
67.970001,24.453323,-129.750931,0.008998,0.003776,0.095906,108.773811,5.541203,0.959062,-129.750931,0.096817,0.000000
68.230003,25.289673,-129.706451,0.009015,0.003792,0.096323,112.494080,5.730721,0.963225,-129.706451,0.097242,0.000000
68.490005,25.878395,-129.795410,0.009020,0.003808,0.096721,115.112854,5.864128,0.967215,-129.795410,0.097676,0.000000
68.750000,26.421310,-129.750931,0.009037,0.003821,0.097042,117.527855,5.987154,0.970424,-129.750931,0.098109,0.000000
69.010002,27.561516,-129.839890,0.009028,0.003841,0.097572,122.599747,6.245529,0.975716,-129.839890,0.098543,0.000000
69.270004,28.621658,-129.795410,0.009050,0.003860,0.098040,127.315498,6.485761,0.980398,-129.795410,0.098977,0.000000
69.530006,29.449814,-129.795410,0.009071,0.003879,0.098517,130.999313,6.673423,0.985167,-129.795410,0.099410,0.000000
69.790001,30.038536,-129.839890,0.009076,0.003892,0.098855,133.618088,6.806829,0.988550,-129.839890,0.099844,0.000000
70.050003,30.917336,-129.795410,0.009067,0.003911,0.099332,137.527176,7.005969,0.993319,-129.795410,0.100277,0.000000
70.310005,32.199791,-129.839890,0.009084,0.003929,0.099791,143.231827,7.296577,0.997914,-129.839890,0.100711,0.000000
70.570000,32.384109,-129.750931,0.009102,0.003940,0.100069,144.051712,7.338344,1.000692,-129.750931,0.101145,0.000000
70.830002,33.113586,-129.795410,0.009097,0.003955,0.100451,147.296585,7.503646,1.004507,-129.795410,0.101578,0.000000
71.090004,35.432724,-129.839890,0.009115,0.003985,0.101222,157.612625,8.029170,1.012225,-129.839890,0.102012,0.000000
71.350006,36.063148,-129.839890,0.009132,0.003997,0.101526,160.416901,8.172027,1.015260,-129.839890,0.102445,0.000000
71.610001,36.883858,-129.884384,0.009140,0.004013,0.101925,164.067596,8.358002,1.019250,-129.884384,0.102879,0.000000
71.870003,38.133171,-129.839890,0.009149,0.004033,0.102428,169.624817,8.641100,1.024280,-129.839890,0.103312,0.000000
72.130005,39.162407,-129.884384,0.009162,0.004049,0.102836,174.203079,8.874328,1.028356,-129.884384,0.103746,0.000000
72.390007,39.949974,-129.884384,0.009166,0.004063,0.103191,177.706360,9.052794,1.031910,-129.884384,0.104180,0.000000
72.650002,40.877930,-129.839890,0.009175,0.004076,0.103521,181.834106,9.263071,1.035207,-129.839890,0.104613,0.000000
72.910004,43.060402,-129.928864,0.009175,0.004105,0.104275,191.542236,9.757627,1.042750,-129.928864,0.105047,0.000000
73.170006,44.219223,-129.884384,0.009192,0.004120,0.104648,196.696930,10.020219,1.046482,-129.884384,0.105480,0.000000
73.430000,45.010147,-129.839890,0.009196,0.004135,0.105021,200.215134,10.199445,1.050210,-129.839890,0.105914,0.000000
73.690002,45.640572,-129.973343,0.009188,0.004145,0.105272,203.019409,10.342301,1.052723,-129.973343,0.106348,0.000000
73.950005,47.367264,-129.884384,0.009205,0.004166,0.105819,210.700119,10.733575,1.058189,-129.884384,0.106781,0.000000
74.210007,48.383095,-130.017822,0.009227,0.004182,0.106226,215.218750,10.963766,1.062265,-130.017822,0.107215,0.000000
74.470001,49.713951,-129.884384,0.009227,0.004201,0.106695,221.138702,11.265343,1.066947,-129.884384,0.107648,0.000000
74.730003,50.842613,-129.884384,0.009244,0.004216,0.107085,226.159241,11.521101,1.070849,-129.884384,0.108082,0.000000
74.990005,52.789009,-129.973343,0.009244,0.004238,0.107657,234.817245,11.962160,1.076572,-129.973343,0.108516,0.000000
75.250000,53.658127,-129.884384,0.009248,0.004250,0.107952,238.683273,12.159105,1.079520,-129.884384,0.108949,0.000000
75.510002,55.103302,-129.973343,0.009257,0.004269,0.108438,245.111725,12.486587,1.084380,-129.973343,0.109383,0.000000
75.770004,56.753281,-129.928864,0.009274,0.004288,0.108915,252.451202,12.860477,1.089149,-129.928864,0.109817,0.000000
76.030006,57.997749,-130.017822,0.009265,0.004304,0.109314,257.986877,13.142477,1.093138,-130.017822,0.110250,0.000000
76.290001,59.155457,-129.928864,0.009265,0.004318,0.109678,263.136627,13.404819,1.096779,-129.928864,0.110684,0.000000
76.550003,60.150063,-129.928864,0.009274,0.004332,0.110033,267.560852,13.630198,1.100333,-129.928864,0.111118,0.000000
76.810005,62.270355,-130.062302,0.009296,0.004355,0.110623,276.992371,14.110664,1.106234,-130.062302,0.111551,0.000000
77.070007,63.616859,-129.928864,0.009296,0.004370,0.110987,282.981934,14.415787,1.109875,-129.928864,0.111985,0.000000
77.330002,65.206139,-130.017822,0.009300,0.004388,0.111456,290.051392,14.775923,1.114557,-130.017822,0.112410,0.000000
77.590004,66.314323,-130.017822,0.009309,0.004403,0.111846,294.980835,15.027040,1.118459,-130.017822,0.112843,0.000000
77.850006,67.724861,-130.062302,0.009321,0.004411,0.112037,301.255219,15.346673,1.120367,-130.062302,0.112262,0.000000
78.110001,67.265724,-130.062302,0.009321,0.004411,0.112037,299.212891,15.242631,1.120367,-130.062302,0.112262,0.000000
78.370003,66.992043,-129.973343,0.009326,0.004407,0.111950,297.995483,15.180614,1.119500,-129.973343,0.112037,0.000000
78.630005,66.664726,-130.062302,0.009321,0.004406,0.111924,296.539520,15.106443,1.119239,-130.062302,0.112037,0.000000
78.890007,66.423790,-130.106781,0.009326,0.004406,0.111907,295.467773,15.051846,1.119069,-130.106781,0.112037,0.000000
79.150002,66.197014,-130.017822,0.009330,0.004405,0.111898,294.459015,15.000458,1.118981,-130.017822,0.112037,0.000000
79.410004,65.985893,-130.106781,0.009321,0.004405,0.111898,293.519897,14.952618,1.118981,-130.106781,0.112037,0.000000
79.670006,65.810493,-130.062302,0.009326,0.004405,0.111889,292.739685,14.912871,1.118894,-130.062302,0.112037,0.000000
79.930000,65.643669,-130.106781,0.009330,0.004405,0.111889,291.997620,14.875068,1.118894,-130.106781,0.112037,0.000000
80.190002,65.505531,-130.106781,0.009330,0.004405,0.111881,291.383148,14.843765,1.118807,-130.106781,0.112037,0.000000
80.450005,65.367744,-130.106781,0.009339,0.004405,0.111881,290.770264,14.812542,1.118807,-130.106781,0.112037,0.000000
80.710007,65.249336,-130.151260,0.009339,0.004405,0.111881,290.243530,14.785711,1.118807,-130.151260,0.112037,0.000000
80.970001,65.140602,-129.973343,0.009339,0.004405,0.111881,289.759857,14.761071,1.118807,-129.973343,0.112037,0.000000
81.230003,65.027031,-130.151260,0.009334,0.004405,0.111881,289.254669,14.735335,1.118807,-130.151260,0.112037,0.000000
81.490005,64.949196,-130.151260,0.009343,0.004405,0.111881,288.908447,14.717698,1.118807,-130.151260,0.112037,0.000000
81.750008,64.850899,-130.106781,0.009339,0.004405,0.111881,288.471191,14.695423,1.118807,-130.106781,0.112037,0.000000
82.010002,64.770470,-130.151260,0.009321,0.004405,0.111881,288.113434,14.677198,1.118807,-130.151260,0.112037,0.000000
82.270004,64.683327,-130.106781,0.009343,0.004404,0.111872,287.725800,14.657451,1.118720,-130.106781,0.112037,0.000000
82.530006,64.614815,-130.195740,0.009334,0.004404,0.111872,287.421051,14.641926,1.118720,-130.195740,0.112037,0.000000
82.790001,64.536980,-130.195740,0.009343,0.004404,0.111872,287.074829,14.624289,1.118720,-130.195740,0.112037,0.000000
83.050003,64.474800,-130.151260,0.009343,0.004404,0.111872,286.798248,14.610199,1.118720,-130.151260,0.112037,0.000000
83.310005,64.411125,-130.240219,0.009343,0.004404,0.111872,286.514984,14.595770,1.118720,-130.240219,0.112037,0.000000
83.570007,64.350426,-130.151260,0.009347,0.004404,0.111872,286.244995,14.582015,1.118720,-130.151260,0.112037,0.000000
83.830002,64.300529,-130.195740,0.009339,0.004404,0.111872,286.023041,14.570708,1.118720,-130.195740,0.112037,0.000000
84.090004,64.235359,-130.106781,0.009343,0.004404,0.111872,285.733154,14.555941,1.118720,-130.106781,0.112037,0.000000
84.350006,64.182121,-130.195740,0.009356,0.004404,0.111872,285.496338,14.543877,1.118720,-130.195740,0.112037,0.000000
84.610001,64.134819,-130.240219,0.009343,0.004404,0.111872,285.285919,14.533157,1.118720,-130.240219,0.112037,0.000000
84.870003,64.078224,-130.195740,0.009347,0.004404,0.111872,285.034180,14.520333,1.118720,-130.195740,0.112037,0.000000
85.130005,64.042839,-130.329193,0.009343,0.004404,0.111872,284.876770,14.512315,1.118720,-130.329193,0.112037,0.000000
85.390007,63.993690,-130.284698,0.009347,0.004404,0.111872,284.658142,14.501177,1.118720,-130.284698,0.112037,0.000000
85.650002,63.950127,-130.240219,0.009347,0.004404,0.111872,284.464355,14.491306,1.118720,-130.240219,0.112037,0.000000
85.910004,63.909538,-130.329193,0.009339,0.004404,0.111872,284.283813,14.482109,1.118720,-130.329193,0.112037,0.000000
86.170006,63.871178,-130.240219,0.009343,0.004404,0.111872,284.113190,14.473415,1.118720,-130.240219,0.112037,0.000000
86.430000,63.835808,-130.329193,0.009356,0.004404,0.111872,283.955841,14.465401,1.118720,-130.329193,0.112037,0.000000
86.690002,63.792992,-130.284698,0.009352,0.004404,0.111872,283.765411,14.455699,1.118720,-130.284698,0.112037,0.000000
86.950005,63.758354,-130.284698,0.009343,0.004404,0.111872,283.611328,14.447849,1.118720,-130.284698,0.112037,0.000000
87.210007,63.717766,-130.284698,0.009334,0.004404,0.111872,283.430786,14.438652,1.118720,-130.284698,0.112037,0.000000
87.470001,63.683876,-130.284698,0.009356,0.004404,0.111872,283.280029,14.430973,1.118720,-130.284698,0.112037,0.000000
87.730003,63.652596,-130.329193,0.009352,0.004404,0.111872,283.140900,14.423884,1.118720,-130.329193,0.112037,0.000000
87.990005,63.625420,-130.284698,0.009343,0.004404,0.111872,283.019989,14.417727,1.118720,-130.284698,0.112037,0.000000
88.250008,63.594887,-130.329193,0.009356,0.004404,0.111872,282.884186,14.410808,1.118720,-130.329193,0.112037,0.000000
88.510002,63.537544,-130.284698,0.009343,0.004404,0.111872,282.629120,14.397813,1.118720,-130.284698,0.112037,0.000000
88.770004,63.511467,-130.373672,0.009360,0.004404,0.111872,282.513123,14.391904,1.118720,-130.373672,0.112037,0.000000
89.030006,63.489128,-130.418152,0.009343,0.004404,0.111872,282.413757,14.386842,1.118720,-130.418152,0.112037,0.000000
89.290001,63.452629,-130.329193,0.009365,0.004404,0.111872,282.251404,14.378572,1.118720,-130.329193,0.112037,0.000000
89.550003,63.433266,-130.418152,0.009343,0.004404,0.111872,282.165253,14.374184,1.118720,-130.418152,0.112037,0.000000
89.810005,63.401253,-130.418152,0.009356,0.004404,0.111872,282.022858,14.366929,1.118720,-130.418152,0.112037,0.000000
90.070007,63.380028,-130.373672,0.009347,0.004404,0.111872,281.928436,14.362120,1.118720,-130.373672,0.112037,0.000000
90.330002,63.364754,-130.507111,0.009343,0.004404,0.111872,281.860504,14.358659,1.118720,-130.507111,0.112037,0.000000
90.590004,63.336449,-130.373672,0.009356,0.004404,0.111872,281.734589,14.352244,1.118720,-130.373672,0.112037,0.000000
90.850006,63.304802,-130.462631,0.009356,0.004404,0.111872,281.593811,14.345073,1.118720,-130.462631,0.112037,0.000000
91.110001,63.285439,-130.418152,0.009352,0.004404,0.111872,281.507690,14.340685,1.118720,-130.418152,0.112037,0.000000
91.370003,63.258263,-130.418152,0.009365,0.004404,0.111872,281.386810,14.334527,1.118720,-130.418152,0.112037,0.000000
91.630005,63.229591,-130.462631,0.009347,0.004404,0.111872,281.259277,14.328030,1.118720,-130.462631,0.112037,0.000000
91.890007,63.222878,-130.462631,0.009356,0.004404,0.111872,281.229401,14.326509,1.118720,-130.462631,0.112037,0.000000
92.150002,63.176338,-130.507111,0.009360,0.004404,0.111872,281.022400,14.315963,1.118720,-130.507111,0.112037,0.000000
92.410004,63.175957,-130.418152,0.009347,0.004404,0.111872,281.020691,14.315877,1.118720,-130.418152,0.112037,0.000000
92.670006,63.152870,-130.418152,0.009365,0.004404,0.111872,280.917999,14.310645,1.118720,-130.418152,0.112037,0.000000
92.930008,63.118614,-130.551590,0.009347,0.004404,0.111872,280.765625,14.302883,1.118720,-130.551590,0.112037,0.000000
93.190002,63.097023,-130.462631,0.009360,0.004404,0.111872,280.669586,14.297990,1.118720,-130.462631,0.112037,0.000000
93.450005,63.084740,-130.507111,0.009356,0.004404,0.111872,280.614929,14.295206,1.118720,-130.507111,0.112037,0.000000
93.710007,63.060158,-130.507111,0.009347,0.004404,0.111872,280.505585,14.289637,1.118720,-130.507111,0.112037,0.000000
93.970001,63.044136,-130.462631,0.009356,0.004404,0.111872,280.434326,14.286005,1.118720,-130.462631,0.112037,0.000000
94.230003,63.024780,-130.507111,0.009343,0.004404,0.111872,280.348236,14.281619,1.118720,-130.507111,0.112037,0.000000
94.490005,63.003181,-130.507111,0.009352,0.004404,0.111872,280.252136,14.276725,1.118720,-130.507111,0.112037,0.000000
94.750008,62.975258,-130.507111,0.009356,0.004404,0.111872,280.127930,14.270397,1.118720,-130.507111,0.112037,0.000000
95.010002,62.978981,-130.596069,0.009360,0.004404,0.111872,280.144501,14.271241,1.118720,-130.596069,0.112037,0.000000
95.270004,62.949936,-130.551590,0.009360,0.004404,0.111872,280.015289,14.264659,1.118720,-130.551590,0.112037,0.000000
95.530006,62.931686,-130.551590,0.009356,0.004404,0.111872,279.934113,14.260524,1.118720,-130.551590,0.112037,0.000000
95.790001,62.924240,-130.551590,0.009352,0.004404,0.111872,279.901001,14.258837,1.118720,-130.551590,0.112037,0.000000
96.050003,62.904503,-130.551590,0.009360,0.004404,0.111872,279.813202,14.254364,1.118720,-130.551590,0.112037,0.000000
96.310005,62.879181,-130.551590,0.009343,0.004404,0.111872,279.700562,14.248626,1.118720,-130.551590,0.112037,0.000000
96.570007,62.874344,-130.640549,0.009360,0.004404,0.111872,279.679047,14.247530,1.118720,-130.640549,0.112037,0.000000
96.830002,62.859077,-130.596069,0.009347,0.004404,0.111872,279.611145,14.244071,1.118720,-130.596069,0.112037,0.000000
97.090004,62.849396,-130.596069,0.009365,0.004404,0.111872,279.568085,14.241877,1.118720,-130.596069,0.112037,0.000000
97.350006,62.836731,-130.640549,0.009347,0.004404,0.111872,279.511749,14.239007,1.118720,-130.640549,0.112037,0.000000
97.610008,62.808807,-130.596069,0.009360,0.004404,0.111872,279.387543,14.232679,1.118720,-130.596069,0.112037,0.000000
97.870003,62.793907,-130.596069,0.009365,0.004404,0.111872,279.321259,14.229303,1.118720,-130.596069,0.112037,0.000000
98.130005,62.799126,-130.640549,0.009339,0.004404,0.111872,279.344452,14.230485,1.118720,-130.640549,0.112037,0.000000
98.390007,62.755180,-130.596069,0.009356,0.004404,0.111872,279.148987,14.220527,1.118720,-130.596069,0.112037,0.000000
98.650002,62.745125,-130.640549,0.009365,0.004404,0.111872,279.104248,14.218248,1.118720,-130.640549,0.112037,0.000000
98.910004,62.752579,-130.640549,0.009352,0.004404,0.111872,279.137421,14.219938,1.118720,-130.640549,0.112037,0.000000
99.170006,62.723900,-130.685028,0.009360,0.004404,0.111872,279.009827,14.213439,1.118720,-130.685028,0.112037,0.000000
99.430008,62.712357,-130.685028,0.009343,0.004404,0.111872,278.958496,14.210823,1.118720,-130.685028,0.112037,0.000000
99.690002,62.699699,-130.685028,0.009360,0.004404,0.111872,278.902191,14.207955,1.118720,-130.685028,0.112037,0.000000
99.950005,62.687042,-130.685028,0.009356,0.004404,0.111872,278.845886,14.205087,1.118720,-130.685028,0.112037,0.000000
100.210007,62.657997,-130.685028,0.009356,0.004404,0.111872,278.716705,14.198505,1.118720,-130.685028,0.112037,0.000000
100.470001,62.657249,-130.685028,0.009360,0.004404,0.111872,278.713379,14.198336,1.118720,-130.685028,0.112037,0.000000
100.730003,62.639000,-130.685028,0.009356,0.004404,0.111872,278.632202,14.194201,1.118720,-130.685028,0.112037,0.000000
100.990005,62.618896,-130.685028,0.009356,0.004404,0.111872,278.542755,14.189645,1.118720,-130.685028,0.112037,0.000000
101.250008,62.619637,-130.774002,0.009352,0.004404,0.111872,278.546051,14.189812,1.118720,-130.774002,0.112037,0.000000
101.510002,62.611076,-130.685028,0.009343,0.004404,0.111872,278.507965,14.187873,1.118720,-130.685028,0.112037,0.000000
101.770004,62.591713,-130.818481,0.009369,0.004404,0.111872,278.421844,14.183485,1.118720,-130.818481,0.112037,0.000000
102.030006,62.576813,-130.729523,0.009356,0.004404,0.111872,278.355560,14.180108,1.118720,-130.729523,0.112037,0.000000
102.290009,62.579048,-130.729523,0.009360,0.004404,0.111872,278.365509,14.180614,1.118720,-130.729523,0.112037,0.000000
102.550003,62.554848,-130.774002,0.009360,0.004404,0.111872,278.257874,14.175132,1.118720,-130.774002,0.112037,0.000000
102.810005,62.535484,-130.729523,0.009347,0.004404,0.111872,278.171722,14.170744,1.118720,-130.729523,0.112037,0.000000
103.070007,62.543304,-130.818481,0.009356,0.004404,0.111872,278.206512,14.172515,1.118720,-130.818481,0.112037,0.000000
103.330002,62.520218,-130.818481,0.009343,0.004404,0.111872,278.103821,14.167284,1.118720,-130.818481,0.112037,0.000000
103.590004,62.502342,-130.774002,0.009365,0.004404,0.111872,278.024292,14.163233,1.118720,-130.774002,0.112037,0.000000
103.850006,62.483727,-130.862961,0.009356,0.004404,0.111872,277.941498,14.159015,1.118720,-130.862961,0.112037,0.000000
104.110008,62.501968,-130.774002,0.009356,0.004404,0.111872,278.022644,14.163149,1.118720,-130.774002,0.112037,0.000000
104.370003,62.471436,-130.818481,0.009369,0.004404,0.111872,277.886810,14.156230,1.118720,-130.818481,0.112037,0.000000
104.630005,62.471062,-130.862961,0.009356,0.004404,0.111872,277.885162,14.156145,1.118720,-130.862961,0.112037,0.000000
104.890007,62.454681,-130.818481,0.009369,0.004404,0.111872,277.812286,14.152433,1.118720,-130.818481,0.112037,0.000000
105.150002,62.450951,-130.818481,0.009360,0.004404,0.111872,277.795715,14.151587,1.118720,-130.818481,0.112037,0.000000
105.410004,62.444626,-130.818481,0.009343,0.004404,0.111872,277.767578,14.150155,1.118720,-130.818481,0.112037,0.000000
105.670006,62.417442,-130.862961,0.009369,0.004404,0.111872,277.646637,14.143994,1.118720,-130.862961,0.112037,0.000000
105.930008,62.411110,-130.818481,0.009352,0.004404,0.111872,277.618469,14.142560,1.118720,-130.818481,0.112037,0.000000
106.190002,62.385414,-130.774002,0.009365,0.004404,0.111872,277.504181,14.136737,1.118720,-130.774002,0.112037,0.000000
106.450005,62.395096,-130.862961,0.009365,0.004404,0.111872,277.547241,14.138931,1.118720,-130.862961,0.112037,0.000000
106.710007,62.372757,-130.907440,0.009365,0.004404,0.111872,277.447876,14.133869,1.118720,-130.907440,0.112037,0.000000
106.970009,62.368286,-130.907440,0.009356,0.004404,0.111872,277.427979,14.132856,1.118720,-130.907440,0.112037,0.000000
107.230003,62.369034,-130.862961,0.009356,0.004404,0.111872,277.431305,14.133025,1.118720,-130.862961,0.112037,0.000000
107.490005,62.342964,-130.862961,0.009356,0.004404,0.111872,277.315369,14.127117,1.118720,-130.862961,0.112037,0.000000
107.750008,62.333282,-130.951920,0.009365,0.004404,0.111872,277.272278,14.124924,1.118720,-130.951920,0.112037,0.000000
108.010002,62.329559,-130.862961,0.009356,0.004404,0.111872,277.255737,14.124080,1.118720,-130.862961,0.112037,0.000000
108.270004,62.328072,-130.907440,0.009365,0.004404,0.111872,277.249115,14.123743,1.118720,-130.907440,0.112037,0.000000
108.300003,62.322861,-130.951920,0.009360,0.004404,0.111872,277.225922,14.122561,1.118720,-130.951920,0.112037,0.000000