File: Data/compression 6/AutoNoheating-10-6-day2-1-240229_02292024_165802.csv
Time (sec),S:Load (lbs),S:HL1 (DIM),S:LVDT (in),S:Position (in),Ch:Position (mm),Ch:Load (N),Ch:Stress (MPa),Ch:Strain (mm/mm),Ch:HL1 (DIM),Set Point (),Cycles ()
0.110000,0.007820,-69.301323,0.000004,-0.000000,-0.000000,0.034786,0.001772,-0.000000,-69.301323,0.000174,0.000000
0.320000,-0.001488,-69.256844,0.000009,-0.000000,-0.000000,-0.006618,-0.000337,-0.000000,-69.256844,0.000174,0.000000
0.530000,-0.004837,-69.301323,0.000004,0.000099,0.002506,-0.021516,-0.001096,0.025064,-69.301323,0.003331,0.000000
0.740000,-0.001862,-69.301323,0.000034,0.000222,0.005629,-0.008281,-0.000422,0.056289,-69.301323,0.006834,0.000000
0.950000,-0.019363,-69.390282,0.000147,0.000358,0.009097,-0.086133,-0.004388,0.090974,-69.390282,0.010337,0.000000
1.160000,-0.004837,-69.345802,0.000297,0.000495,0.012567,-0.021516,-0.001096,0.125666,-69.345802,0.013841,0.000000
1.370000,-0.008186,-69.345802,0.000444,0.000634,0.016105,-0.036415,-0.001855,0.161047,-69.345802,0.017327,0.000000
1.580000,0.003357,-69.345802,0.000573,0.000774,0.019652,0.014932,0.000761,0.196519,-69.345802,0.020831,0.000000
1.790000,0.043945,-69.345802,0.000733,0.000910,0.023120,0.195479,0.009958,0.231204,-69.345802,0.024335,0.000000
2.000000,0.039101,-69.345802,0.000858,0.001042,0.026477,0.173928,0.008860,0.264769,-69.345802,0.027821,0.000000
2.210000,0.048409,-69.345802,0.000996,0.001181,0.029998,0.215332,0.010970,0.299976,-69.345802,0.031325,0.000000
2.420000,0.048035,-69.301323,0.001138,0.001329,0.033761,0.213669,0.010885,0.337613,-69.301323,0.034828,0.000000
2.630000,0.026443,-69.390282,0.001281,0.001466,0.037248,0.117626,0.005992,0.372479,-69.390282,0.038332,0.000000
2.840000,0.010803,-69.345802,0.001431,0.001605,0.040777,0.048055,0.002448,0.407769,-69.345802,0.041818,0.000000
3.050000,0.007446,-69.390282,0.001552,0.001739,0.044168,0.033123,0.001687,0.441682,-69.390282,0.045322,0.000000
3.260000,-0.020103,-69.390282,0.001694,0.001877,0.047663,-0.089425,-0.004556,0.476632,-69.390282,0.048825,0.000000
3.470000,-0.016754,-69.390282,0.001832,0.002013,0.051123,-0.074526,-0.003797,0.511233,-69.390282,0.052311,0.000000
3.680000,-0.008934,-69.434761,0.001970,0.002152,0.054661,-0.039741,-0.002024,0.546615,-69.434761,0.055815,0.000000
3.890000,0.037987,-69.390282,0.002108,0.002293,0.058234,0.168974,0.008608,0.582344,-69.390282,0.059318,0.000000
4.100000,0.033142,-69.434761,0.002242,0.002430,0.061712,0.147423,0.007510,0.617120,-69.434761,0.062822,0.000000
4.310000,0.061447,-69.390282,0.002367,0.002562,0.065086,0.273331,0.013924,0.650858,-69.390282,0.066308,0.000000
4.520000,0.059952,-69.390282,0.002501,0.002700,0.068589,0.266679,0.013585,0.685891,-69.390282,0.069812,0.000000
4.730000,0.054741,-69.434761,0.002639,0.002837,0.072067,0.243500,0.012404,0.720667,-69.434761,0.073316,0.000000
4.940000,0.046921,-69.434761,0.002790,0.002979,0.075666,0.208714,0.010632,0.756661,-69.434761,0.076802,0.000000
5.150000,0.030167,-69.434761,0.002923,0.003120,0.079256,0.134188,0.006836,0.792557,-69.434761,0.080306,0.000000
5.360000,0.027557,-69.434761,0.003053,0.003257,0.082717,0.122581,0.006245,0.827166,-69.434761,0.083809,0.000000
5.570000,-0.005959,-69.434761,0.003182,0.003391,0.086142,-0.026505,-0.001350,0.861419,-69.434761,0.087296,0.000000
5.780000,-0.025322,-69.479248,0.003316,0.003530,0.089672,-0.112638,-0.005738,0.896717,-69.479248,0.090799,0.000000
5.990000,0.001862,-69.390282,0.003454,0.003665,0.093097,0.008281,0.000422,0.930971,-69.390282,0.094302,0.000000
6.200000,0.044312,-69.479248,0.003583,0.003806,0.096670,0.197107,0.010041,0.966700,-69.479248,0.097806,0.000000
6.410000,0.060699,-69.568207,0.003725,0.003944,0.100173,0.270005,0.013755,1.001733,-69.568207,0.101292,0.000000
6.620000,0.044312,-69.479248,0.003876,0.004083,0.103703,0.197107,0.010041,1.037031,-69.479248,0.104796,0.000000
6.830000,0.056602,-69.568207,0.004005,0.004221,0.107206,0.251780,0.012826,1.072064,-69.568207,0.108299,0.000000
7.040000,0.076714,-69.479248,0.004148,0.004349,0.110477,0.341239,0.017384,1.104765,-69.479248,0.111785,0.000000
7.250000,0.066284,-69.523727,0.004294,0.004495,0.114171,0.294847,0.015020,1.141706,-69.523727,0.115289,0.000000
7.460001,0.099800,-69.523727,0.004441,0.004634,0.117691,0.443933,0.022615,1.176913,-69.523727,0.118793,0.000000
7.670001,0.185074,-69.523727,0.004587,0.004769,0.121143,0.823250,0.041938,1.211431,-69.523727,0.122297,0.000000
7.880001,0.397324,-69.568207,0.004725,0.004911,0.124733,1.767384,0.090035,1.247335,-69.568207,0.125783,0.000000
8.090000,0.691498,-69.523727,0.004889,0.005021,0.127526,3.075936,0.156696,1.275260,-69.523727,0.127647,0.000000
8.300000,0.589844,-69.568207,0.004881,-0.000000,-0.000009,2.623756,0.133661,-0.000091,-69.568207,0.000139,0.000000
8.510000,0.568245,-69.568207,0.004868,-0.000000,-0.000009,2.527680,0.128766,-0.000091,-69.568207,0.000139,0.000000
8.720000,0.557068,-69.479248,0.004889,-0.000001,-0.000017,2.477962,0.126233,-0.000174,-69.479248,0.000373,0.000000
8.930000,0.542549,-69.612686,0.004881,-0.000000,-0.000009,2.413379,0.122943,-0.000091,-69.612686,0.000728,0.000000
9.140000,0.542549,-69.523727,0.004889,0.000012,0.000304,2.413379,0.122943,0.003035,-69.523727,0.001075,0.000000
9.350000,0.593933,-69.568207,0.004898,0.000024,0.000607,2.641946,0.134587,0.006071,-69.568207,0.001431,0.000000
9.560000,0.657616,-69.612686,0.004898,0.000032,0.000815,2.925220,0.149018,0.008153,-69.612686,0.001777,0.000000
9.770000,0.759644,-69.523727,0.004915,0.000051,0.001292,3.379063,0.172138,0.012922,-69.523727,0.002125,0.000000
9.980000,0.813637,-69.612686,0.004928,0.000064,0.001631,3.619237,0.184373,0.016305,-69.612686,0.002480,0.000000
10.190001,0.825928,-69.523727,0.004945,0.000076,0.001942,3.673910,0.187158,0.019424,-69.523727,0.002827,0.000000
10.400001,0.911568,-69.612686,0.004954,0.000090,0.002289,4.054856,0.206564,0.022891,-69.612686,0.003174,0.000000
10.610001,0.932426,-69.612686,0.004967,0.000104,0.002645,4.147640,0.211291,0.026449,-69.612686,0.003530,0.000000
10.820001,0.960350,-69.568207,0.004988,0.000119,0.003018,4.271850,0.217618,0.030181,-69.568207,0.003876,0.000000
11.030001,1.005409,-69.612686,0.005010,0.000134,0.003400,4.472284,0.227829,0.033996,-69.612686,0.004223,0.000000
11.240001,1.007645,-69.568207,0.005019,0.000144,0.003668,4.482227,0.228336,0.036683,-69.568207,0.004579,0.000000
11.450001,1.067223,-69.657173,0.005040,0.000160,0.004058,4.747243,0.241836,0.040582,-69.657173,0.004926,0.000000
11.660001,1.115257,-69.657173,0.005040,0.000174,0.004423,4.960912,0.252721,0.044230,-69.657173,0.005281,0.000000
11.870001,1.169998,-69.612686,0.005079,0.000191,0.004856,5.204412,0.265125,0.048560,-69.612686,0.005628,0.000000
12.080001,1.155098,-69.701653,0.005075,0.000199,0.005056,5.138133,0.261749,0.050559,-69.701653,0.005975,0.000000
12.290001,1.179306,-69.657173,0.005079,0.000207,0.005255,5.245815,0.267235,0.052549,-69.657173,0.006331,0.000000
12.500001,1.292877,-69.612686,0.005092,0.000227,0.005767,5.751005,0.292970,0.057667,-69.612686,0.006677,0.000000
12.710001,1.348732,-69.657173,0.005126,0.000245,0.006227,5.999460,0.305627,0.062269,-69.657173,0.007025,0.000000
12.920001,1.350594,-69.657173,0.005144,0.000258,0.006565,6.007740,0.306049,0.065645,-69.657173,0.007380,0.000000
13.130001,1.312988,-69.746132,0.005152,0.000264,0.006704,5.840464,0.297527,0.067038,-69.746132,0.007727,0.000000
13.340001,1.404594,-69.657173,0.005165,0.000283,0.007181,6.247948,0.318286,0.071807,-69.657173,0.008074,0.000000
13.550000,1.420601,-69.701653,0.005195,0.000295,0.007502,6.319149,0.321913,0.075017,-69.701653,0.008430,0.000000
13.760000,1.487633,-69.746132,0.005204,0.000313,0.007961,6.617321,0.337102,0.079611,-69.746132,0.008776,0.000000
13.970000,1.498428,-69.701653,0.005221,0.000323,0.008195,6.665342,0.339549,0.081951,-69.701653,0.009131,0.000000
14.180000,1.508484,-69.701653,0.005234,0.000333,0.008464,6.710072,0.341827,0.084638,-69.701653,0.009479,0.000000
14.390000,1.584076,-69.657173,0.005243,0.000348,0.008829,7.046322,0.358957,0.088286,-69.657173,0.009826,0.000000
14.600000,1.670090,-69.701653,0.005264,0.000366,0.009296,7.428930,0.378448,0.092965,-69.701653,0.010181,0.000000
14.810000,1.711426,-69.701653,0.005295,0.000384,0.009756,7.612802,0.387815,0.097559,-69.701653,0.010528,0.000000
15.020000,1.659294,-69.657173,0.005303,0.000394,0.010016,7.380909,0.376001,0.100163,-69.657173,0.010875,0.000000
15.230000,1.671211,-69.790611,0.005333,0.000407,0.010337,7.433919,0.378702,0.103373,-69.790611,0.011231,0.000000
15.440001,1.741219,-69.746132,0.005338,0.000422,0.010719,7.745327,0.394566,0.107188,-69.746132,0.011577,0.000000
15.650001,1.763931,-69.746132,0.005355,0.000434,0.011031,7.846358,0.399713,0.110307,-69.746132,0.011924,0.000000
15.860001,1.823135,-69.790611,0.005368,0.000449,0.011396,8.109712,0.413128,0.113956,-69.790611,0.012280,0.000000
16.070002,1.831329,-69.746132,0.005389,0.000459,0.011664,8.146160,0.414985,0.116643,-69.746132,0.012626,0.000000
16.280001,1.912132,-69.790611,0.005407,0.000476,0.012089,8.505589,0.433295,0.120890,-69.790611,0.012982,0.000000
16.490002,1.922562,-69.746132,0.005428,0.000488,0.012384,8.551981,0.435659,0.123842,-69.746132,0.013329,0.000000
16.700001,1.971344,-69.790611,0.005454,0.000505,0.012817,8.768976,0.446713,0.128172,-69.790611,0.013676,0.000000
16.910002,1.991821,-69.835091,0.005471,0.000519,0.013182,8.860064,0.451353,0.131820,-69.835091,0.014031,0.000000
17.120001,1.990334,-69.657173,0.005480,0.000534,0.013564,8.853446,0.451016,0.135635,-69.657173,0.014379,0.000000
17.330000,1.950119,-69.835091,0.005506,0.000544,0.013823,8.674562,0.441903,0.138232,-69.835091,0.014726,0.000000
17.540001,2.084915,-69.835091,0.005506,0.000559,0.014205,9.274166,0.472449,0.142047,-69.835091,0.015081,0.000000
17.750000,2.105026,-69.835091,0.005549,0.000575,0.014595,9.363625,0.477006,0.145953,-69.835091,0.015428,0.000000
17.960001,2.147102,-69.835091,0.005545,0.000588,0.014925,9.550788,0.486540,0.149246,-69.835091,0.015775,0.000000
18.170000,2.120667,-69.790611,0.005553,0.000597,0.015168,9.433196,0.480550,0.151676,-69.790611,0.016130,0.000000
18.380001,2.139656,-69.790611,0.005579,0.000610,0.015506,9.517666,0.484853,0.155060,-69.790611,0.016477,0.000000
18.590000,2.322861,-69.835091,0.005614,0.000634,0.016104,10.332601,0.526368,0.161040,-69.835091,0.016824,0.000000
18.800001,2.299400,-69.835091,0.005627,0.000647,0.016425,10.228244,0.521052,0.164249,-69.835091,0.017180,0.000000
19.010000,2.233124,-69.879578,0.005639,0.000655,0.016642,9.933431,0.506033,0.166422,-69.879578,0.017526,0.000000
19.220001,2.298660,-69.835091,0.005665,0.000669,0.016989,10.224952,0.520884,0.169889,-69.835091,0.017882,0.000000
19.430000,2.290466,-69.879578,0.005670,0.000681,0.017292,10.188503,0.519027,0.172924,-69.879578,0.018229,0.000000
19.640001,2.378342,-69.879578,0.005687,0.000695,0.017648,10.579392,0.538940,0.176482,-69.879578,0.018576,0.000000
19.850000,2.428986,-69.835091,0.005721,0.000711,0.018065,10.804667,0.550416,0.180645,-69.835091,0.018931,0.000000
20.060001,2.316902,-69.924057,0.005717,0.000715,0.018168,10.306095,0.525017,0.181683,-69.924057,0.019278,0.000000
20.270000,2.517616,-69.879578,0.005752,0.000737,0.018723,11.198916,0.570500,0.187231,-69.879578,0.019625,0.000000
20.480001,2.558205,-69.924057,0.005760,0.000754,0.019157,11.379462,0.579697,0.191569,-69.924057,0.019980,0.000000
20.690001,2.556709,-69.924057,0.005790,0.000769,0.019530,11.372811,0.579359,0.195301,-69.924057,0.020328,0.000000
20.900002,2.521339,-69.924057,0.005799,0.000780,0.019807,11.215478,0.571344,0.198071,-69.924057,0.020675,0.000000
21.110001,2.541443,-69.879578,0.005816,0.000791,0.020102,11.304902,0.575899,0.201023,-69.879578,0.021030,0.000000
21.320002,2.546288,-69.924057,0.005829,0.000803,0.020406,11.326452,0.576997,0.204059,-69.924057,0.021377,0.000000
21.530001,2.689651,-69.968536,0.005846,0.000819,0.020813,11.964168,0.609484,0.208131,-69.968536,0.021733,0.000000
21.740002,2.701935,-69.968536,0.005855,0.000832,0.021126,12.018806,0.612267,0.211258,-69.968536,0.022080,0.000000
21.950001,2.627838,-69.924057,0.005877,0.000839,0.021317,11.689208,0.595477,0.213165,-69.924057,0.022426,0.000000
22.160002,2.908600,-69.968536,0.005894,0.000863,0.021932,12.938098,0.659098,0.219320,-69.968536,0.022782,0.000000
22.370001,2.779015,-69.968536,0.005920,0.000874,0.022192,12.361674,0.629734,0.221924,-69.968536,0.023129,0.000000
22.580002,2.853867,-69.968536,0.005946,0.000889,0.022591,12.694633,0.646695,0.225913,-69.968536,0.023475,0.000000
22.790001,2.869881,-69.968536,0.005963,0.000903,0.022938,12.765867,0.650324,0.229380,-69.968536,0.023831,0.000000
23.000002,2.892967,-69.879578,0.005971,0.000917,0.023294,12.868561,0.655556,0.232938,-69.879578,0.024178,0.000000
23.210001,2.933922,-70.013016,0.005989,0.000930,0.023615,13.050736,0.664836,0.236147,-70.013016,0.024525,0.000000
23.420002,3.029251,-69.968536,0.006006,0.000946,0.024039,13.474782,0.686438,0.240394,-69.968536,0.024880,0.000000
23.630001,3.014732,-70.013016,0.006036,0.000959,0.024351,13.410199,0.683148,0.243513,-70.013016,0.025228,0.000000
23.840002,3.011375,-69.924057,0.006036,0.000969,0.024621,13.395267,0.682387,0.246207,-69.924057,0.025583,0.000000
24.050001,3.045265,-69.968536,0.006058,0.000982,0.024933,13.546016,0.690067,0.249326,-69.968536,0.025930,0.000000
24.260000,3.193840,-70.013016,0.006084,0.001000,0.025401,14.206910,0.723734,0.254012,-70.013016,0.026277,0.000000
24.470001,3.216553,-70.013016,0.006092,0.001015,0.025791,14.307941,0.728881,0.257910,-70.013016,0.026633,0.000000
24.680000,3.199799,-70.013016,0.006109,0.001027,0.026095,14.233415,0.725085,0.260946,-70.013016,0.026979,0.000000
24.890001,3.170006,-70.013016,0.006131,0.001040,0.026425,14.100890,0.718334,0.264246,-70.013016,0.027326,0.000000
25.100000,3.156235,-70.013016,0.006148,0.001051,0.026702,14.039634,0.715213,0.267017,-70.013016,0.027682,0.000000
25.310001,3.189743,-70.013016,0.006153,0.001063,0.027005,14.188685,0.722806,0.270052,-70.013016,0.028029,0.000000
25.520000,3.395668,-70.013016,0.006174,0.001082,0.027474,15.104686,0.769469,0.274738,-70.013016,0.028375,0.000000
25.730001,3.266083,-70.101982,0.006191,0.001087,0.027621,14.528262,0.740105,0.276214,-70.101982,0.028731,0.000000
25.940001,3.330132,-70.057495,0.006200,0.001101,0.027968,14.813165,0.754619,0.279681,-70.057495,0.029078,0.000000
26.150002,3.510361,-70.013016,0.006217,0.001120,0.028445,15.614864,0.795459,0.284450,-70.013016,0.029425,0.000000
26.360001,3.571053,-70.057495,0.006239,0.001138,0.028896,15.884835,0.809212,0.288962,-70.057495,0.029780,0.000000
26.570002,3.479820,-70.057495,0.006265,0.001147,0.029130,15.479013,0.788539,0.291301,-70.057495,0.030127,0.000000
26.780001,3.610153,-70.101982,0.006286,0.001165,0.029581,16.058764,0.818072,0.295812,-70.101982,0.030483,0.000000
26.990002,3.571426,-70.101982,0.006295,0.001177,0.029885,15.886498,0.809297,0.298848,-70.101982,0.030829,0.000000
27.200001,3.550949,-70.013016,0.006308,0.001188,0.030179,15.795410,0.804657,0.301792,-70.013016,0.031177,0.000000
27.410002,3.803787,-70.101982,0.006325,0.001208,0.030674,16.920090,0.861951,0.306735,-70.101982,0.031532,0.000000
27.620001,3.741974,-70.057495,0.006342,0.001219,0.030960,16.645132,0.847943,0.309597,-70.057495,0.031879,0.000000
27.830002,3.616486,-70.057495,0.006359,0.001225,0.031125,16.086931,0.819507,0.311247,-70.057495,0.032226,0.000000
28.040001,3.684258,-70.057495,0.006359,0.001237,0.031419,16.388395,0.834865,0.314192,-70.057495,0.032582,0.000000
28.250002,4.027580,-70.146461,0.006398,0.001259,0.031975,17.915571,0.912663,0.319748,-70.146461,0.032929,0.000000
28.460001,4.042847,-70.190941,0.006420,0.001278,0.032469,17.983480,0.916122,0.324691,-70.190941,0.033275,0.000000
28.670002,3.869324,-70.101982,0.006428,0.001289,0.032729,17.211611,0.876801,0.327287,-70.101982,0.033631,0.000000
28.880001,3.889061,-70.146461,0.006441,0.001300,0.033032,17.299408,0.881274,0.330323,-70.146461,0.033978,0.000000
29.090002,3.964279,-70.146461,0.006459,0.001314,0.033388,17.633995,0.898319,0.333881,-70.146461,0.034334,0.000000
29.300001,4.087532,-70.057495,0.006472,0.001329,0.033761,18.182251,0.926248,0.337613,-70.057495,0.034680,0.000000
29.510002,4.131844,-70.190941,0.006497,0.001342,0.034082,18.379358,0.936289,0.340822,-70.190941,0.035027,0.000000
29.720001,4.032799,-70.190941,0.006489,0.001351,0.034307,17.938786,0.913845,0.343070,-70.190941,0.035383,0.000000
29.930002,4.094612,-70.190941,0.006523,0.001362,0.034593,18.213745,0.927852,0.345932,-70.190941,0.035729,0.000000
30.140001,4.561562,-70.190941,0.006541,0.001392,0.035357,20.290840,1.033665,0.353570,-70.190941,0.036077,0.000000
30.350002,4.347076,-70.101982,0.006566,0.001405,0.035678,19.336761,0.985062,0.356779,-70.101982,0.036432,0.000000
30.560001,4.239090,-70.190941,0.006575,0.001415,0.035947,18.856415,0.960591,0.359467,-70.190941,0.036779,0.000000
30.770002,4.275955,-70.146461,0.006597,0.001429,0.036302,19.020399,0.968945,0.363017,-70.146461,0.037126,0.000000
30.980001,4.204086,-70.190941,0.006605,0.001438,0.036519,18.700710,0.952660,0.365189,-70.190941,0.037481,0.000000
31.190001,4.447250,-70.190941,0.006635,0.001456,0.036978,19.782358,1.007761,0.369784,-70.190941,0.037829,0.000000
31.400002,4.427139,-70.146461,0.006648,0.001467,0.037265,19.692900,1.003204,0.372646,-70.146461,0.038184,0.000000
31.610001,4.484108,-70.235420,0.006661,0.001478,0.037542,19.946308,1.016113,0.375424,-70.235420,0.038531,0.000000
31.820002,4.506081,-70.190941,0.006670,0.001489,0.037829,20.044048,1.021092,0.378285,-70.190941,0.038878,0.000000
32.030003,4.797279,-70.235420,0.006700,0.001512,0.038409,21.339365,1.087079,0.384091,-70.235420,0.039233,0.000000
32.240002,4.780518,-70.235420,0.006713,0.001525,0.038739,21.264805,1.083281,0.387392,-70.235420,0.039580,0.000000
32.450001,4.735092,-70.146461,0.006743,0.001538,0.039060,21.062742,1.072987,0.390601,-70.146461,0.039927,0.000000
32.660000,4.689285,-70.279900,0.006756,0.001548,0.039329,20.858982,1.062607,0.393288,-70.279900,0.040283,0.000000
32.870003,4.709396,-70.235420,0.006756,0.001561,0.039641,20.948441,1.067165,0.396407,-70.235420,0.040629,0.000000
33.080002,4.989792,-70.235420,0.006782,0.001581,0.040162,22.195704,1.130703,0.401615,-70.235420,0.040976,0.000000
33.290001,5.014000,-70.324387,0.006804,0.001595,0.040508,22.303385,1.136189,0.405082,-70.324387,0.041332,0.000000
33.500000,4.912338,-70.190941,0.006817,0.001604,0.040742,21.851171,1.113152,0.407421,-70.190941,0.041679,0.000000
33.710003,4.838234,-70.368866,0.006829,0.001613,0.040976,21.521540,1.096359,0.409760,-70.368866,0.042026,0.000000
33.920002,5.194969,-70.279900,0.006838,0.001634,0.041497,23.108377,1.177197,0.414968,-70.279900,0.042381,0.000000
34.130001,5.267586,-70.324387,0.006868,0.001650,0.041921,23.431391,1.193652,0.419215,-70.324387,0.042728,0.000000
34.340000,5.114540,-70.279900,0.006881,0.001659,0.042147,22.750610,1.158971,0.421471,-70.279900,0.043083,0.000000
34.550003,5.269821,-70.279900,0.006890,0.001676,0.042572,23.441336,1.194159,0.425717,-70.279900,0.043431,0.000000
34.760002,5.339821,-70.324387,0.006911,0.001691,0.042945,23.752710,1.210021,0.429449,-70.324387,0.043778,0.000000
34.970001,5.387489,-70.324387,0.006929,0.001704,0.043283,23.964750,1.220822,0.432833,-70.324387,0.044133,0.000000
35.180000,5.347267,-70.279900,0.006954,0.001716,0.043587,23.785831,1.211708,0.435869,-70.279900,0.044480,0.000000
35.390003,5.408340,-70.368866,0.006963,0.001728,0.043881,24.057499,1.225548,0.438813,-70.368866,0.044827,0.000000
35.600002,5.506645,-70.279900,0.006985,0.001740,0.044194,24.494781,1.247824,0.441939,-70.279900,0.045183,0.000000
35.810001,5.512978,-70.368866,0.007002,0.001753,0.044515,24.522949,1.249259,0.445149,-70.368866,0.045529,0.000000
36.020000,5.840668,-70.324387,0.007028,0.001773,0.045027,25.980587,1.323514,0.450266,-70.324387,0.045876,0.000000
36.230003,5.868591,-70.324387,0.007036,0.001789,0.045451,26.104797,1.329842,0.454513,-70.324387,0.046232,0.000000
36.440002,5.710709,-70.324387,0.007045,0.001800,0.045712,25.402500,1.294065,0.457117,-70.324387,0.046578,0.000000
36.650002,5.821671,-70.324387,0.007075,0.001815,0.046093,25.896084,1.319209,0.460932,-70.324387,0.046934,0.000000
36.860001,5.714806,-70.368866,0.007088,0.001827,0.046414,25.420725,1.294993,0.464142,-70.368866,0.047281,0.000000
37.070004,6.034302,-70.324387,0.007118,0.001843,0.046813,26.841915,1.367392,0.468131,-70.324387,0.047628,0.000000
37.280003,5.972855,-70.457825,0.007123,0.001855,0.047125,26.568584,1.353468,0.471250,-70.457825,0.047983,0.000000
37.490002,5.903595,-70.413345,0.007127,0.001865,0.047368,26.260502,1.337774,0.473680,-70.413345,0.048330,0.000000
37.700001,6.237984,-70.413345,0.007148,0.001880,0.047740,27.747938,1.413547,0.477404,-70.413345,0.048678,0.000000
37.910004,6.544075,-70.457825,0.007170,0.001899,0.048244,29.109499,1.482909,0.482438,-70.457825,0.049033,0.000000
38.120003,6.401833,-70.457825,0.007196,0.001911,0.048538,28.476774,1.450676,0.485382,-70.457825,0.049380,0.000000
38.330002,6.456566,-70.457825,0.007213,0.001926,0.048911,28.720240,1.463079,0.489114,-70.457825,0.049727,0.000000
38.540001,6.462898,-70.457825,0.007230,0.001940,0.049267,28.748407,1.464514,0.492672,-70.457825,0.050082,0.000000
38.750000,6.378746,-70.413345,0.007235,0.001948,0.049475,28.374079,1.445445,0.494754,-70.413345,0.050429,0.000000
38.960003,6.659142,-70.502304,0.007261,0.001966,0.049926,29.621342,1.508983,0.499258,-70.502304,0.050785,0.000000
39.170002,6.874741,-70.368866,0.007274,0.001982,0.050342,30.580374,1.557838,0.503421,-70.368866,0.051132,0.000000
39.380001,6.540726,-70.368866,0.007286,0.001987,0.050481,29.094601,1.482150,0.504814,-70.368866,0.051478,0.000000
39.590000,6.763031,-70.502304,0.007304,0.002002,0.050863,30.083464,1.532525,0.508629,-70.502304,0.051834,0.000000
39.800003,6.971558,-70.368866,0.007312,0.002018,0.051262,31.011038,1.579778,0.512619,-70.368866,0.052181,0.000000
40.010002,7.331268,-70.457825,0.007343,0.002039,0.051799,32.611111,1.661289,0.517993,-70.457825,0.052528,0.000000
40.220001,7.142479,-70.457825,0.007360,0.002051,0.052095,31.771334,1.618509,0.520945,-70.457825,0.052883,0.000000
40.430000,7.139870,-70.457825,0.007386,0.002061,0.052346,31.759727,1.617918,0.523459,-70.457825,0.053230,0.000000
40.640003,7.244507,-70.546791,0.007377,0.002073,0.052667,32.225174,1.641629,0.526668,-70.546791,0.053577,0.000000
40.850002,7.646667,-70.413345,0.007407,0.002090,0.053091,34.014076,1.732760,0.530915,-70.413345,0.053932,0.000000
41.060001,7.777000,-70.502304,0.007429,0.002105,0.053456,34.593826,1.762293,0.534556,-70.502304,0.054280,0.000000
41.270000,7.676086,-70.502304,0.007437,0.002113,0.053681,34.144939,1.739426,0.536812,-70.502304,0.054635,0.000000
41.480003,7.733803,-70.502304,0.007450,0.002125,0.053976,34.401672,1.752505,0.539764,-70.502304,0.054982,0.000000
41.690002,8.206718,-70.502304,0.007455,0.002143,0.054427,36.505306,1.859669,0.544268,-70.502304,0.055329,0.000000
41.900002,8.598083,-70.591270,0.007480,0.002163,0.054939,38.246185,1.948354,0.549385,-70.591270,0.055684,0.000000
42.110001,8.228317,-70.546791,0.007485,0.002170,0.055129,36.601383,1.864563,0.551293,-70.546791,0.056032,0.000000
42.320004,8.525101,-70.502304,0.007515,0.002185,0.055511,37.921543,1.931815,0.555108,-70.502304,0.056378,0.000000
42.530003,8.550415,-70.635750,0.007524,0.002196,0.055780,38.034145,1.937552,0.557795,-70.635750,0.056734,0.000000
42.740002,8.646118,-70.591270,0.007532,0.002207,0.056057,38.459854,1.959238,0.560573,-70.591270,0.057081,0.000000
42.950001,9.286972,-70.502304,0.007541,0.002226,0.056543,41.310516,2.104458,0.565433,-70.502304,0.057427,0.000000
43.160004,9.114563,-70.546791,0.007571,0.002236,0.056786,40.543602,2.065389,0.567855,-70.546791,0.057783,0.000000
43.370003,9.107117,-70.502304,0.007562,0.002245,0.057020,40.510479,2.063702,0.570202,-70.502304,0.058130,0.000000
43.580002,10.192581,-70.635750,0.007601,0.002269,0.057627,45.338867,2.309672,0.576273,-70.635750,0.058477,0.000000
43.790001,10.211197,-70.635750,0.007606,0.002282,0.057957,45.421673,2.313890,0.579566,-70.635750,0.058832,0.000000
44.000004,10.354195,-70.546791,0.007606,0.002295,0.058295,46.057758,2.346294,0.582950,-70.546791,0.059179,0.000000
44.210003,10.548943,-70.635750,0.007636,0.002309,0.058651,46.924042,2.390424,0.586507,-70.635750,0.059535,0.000000
44.420002,10.800293,-70.546791,0.007649,0.002322,0.058971,48.042103,2.447381,0.589709,-70.546791,0.059882,0.000000
44.630001,10.989830,-70.635750,0.007662,0.002335,0.059309,48.885204,2.490331,0.593093,-70.635750,0.060229,0.000000
44.840004,11.541687,-70.680229,0.007670,0.002352,0.059735,51.339989,2.615384,0.597347,-70.680229,0.060584,0.000000
45.050003,11.841820,-70.546791,0.007683,0.002365,0.060081,52.675045,2.683395,0.600814,-70.546791,0.060932,0.000000
45.260002,11.765854,-70.635750,0.007696,0.002374,0.060290,52.337132,2.666181,0.602896,-70.635750,0.061278,0.000000
45.470001,12.116257,-70.591270,0.007705,0.002386,0.060601,53.895802,2.745583,0.606015,-70.591270,0.061634,0.000000
45.680000,12.950745,-70.546791,0.007718,0.002406,0.061113,57.607788,2.934681,0.611132,-70.546791,0.061981,0.000000
45.890003,13.235985,-70.680229,0.007735,0.002419,0.061443,58.876602,2.999317,0.614432,-70.680229,0.062327,0.000000
46.100002,13.532021,-70.635750,0.007752,0.002434,0.061816,60.193436,3.066400,0.618157,-70.635750,0.062683,0.000000
46.310001,13.923012,-70.724709,0.007765,0.002446,0.062137,61.932648,3.154999,0.621366,-70.724709,0.063030,0.000000
46.520000,13.919289,-70.635750,0.007761,0.002456,0.062388,61.916088,3.154156,0.623879,-70.635750,0.063386,0.000000
46.730003,14.665894,-70.635750,0.007774,0.002472,0.062779,65.237152,3.323339,0.627785,-70.635750,0.063732,0.000000
46.940002,15.314934,-70.635750,0.007782,0.002486,0.063134,68.124229,3.470414,0.631343,-70.635750,0.064079,0.000000
47.150002,15.412498,-70.591270,0.007787,0.002496,0.063403,68.558220,3.492522,0.634030,-70.591270,0.064435,0.000000
47.360001,15.534264,-70.680229,0.007804,0.002503,0.063576,69.099854,3.520114,0.635764,-70.680229,0.064782,0.000000
47.570004,16.567970,-70.680229,0.007817,0.002523,0.064088,73.698013,3.754356,0.640881,-70.680229,0.065128,0.000000
47.780003,17.247925,-70.680229,0.007825,0.002539,0.064495,76.722603,3.908436,0.644954,-70.680229,0.065484,0.000000
47.990002,17.566299,-70.724709,0.007825,0.002553,0.064851,78.138802,3.980580,0.648511,-70.724709,0.065831,0.000000
48.200001,18.465584,-70.635750,0.007843,0.002571,0.065293,82.139023,4.184361,0.652932,-70.635750,0.066178,0.000000
48.410004,18.343445,-70.680229,0.007856,0.002578,0.065476,81.595718,4.156684,0.654757,-70.680229,0.066533,0.000000
48.620003,19.522377,-70.680229,0.007869,0.002598,0.065978,86.839867,4.423834,0.659783,-70.680229,0.066881,0.000000
48.830002,20.142372,-70.724709,0.007881,0.002612,0.066334,89.597748,4.564327,0.663341,-70.724709,0.067236,0.000000
49.040001,20.362816,-70.769196,0.007873,0.002620,0.066542,90.578331,4.614280,0.665422,-70.769196,0.067583,0.000000
49.250004,20.932922,-70.635750,0.007894,0.002633,0.066872,93.114288,4.743468,0.668715,-70.635750,0.067930,0.000000
49.460003,21.281090,-70.813675,0.007907,0.002642,0.067106,94.663017,4.822364,0.671062,-70.813675,0.068286,0.000000
49.670002,23.107201,-70.635750,0.007912,0.002670,0.067825,102.785965,5.236166,0.678253,-70.635750,0.068632,0.000000
49.880001,23.742096,-70.769196,0.007920,0.002682,0.068111,105.610115,5.380035,0.681115,-70.769196,0.068979,0.000000
50.090004,24.066063,-70.724709,0.007925,0.002692,0.068381,107.051193,5.453448,0.683809,-70.724709,0.069335,0.000000
50.300003,24.569138,-70.724709,0.007942,0.002705,0.068702,109.288979,5.567446,0.687019,-70.724709,0.069681,0.000000
50.510002,25.157860,-70.769196,0.007950,0.002716,0.068979,111.907753,5.700852,0.689790,-70.769196,0.070028,0.000000
50.720001,26.227310,-70.724709,0.007946,0.002732,0.069395,116.664902,5.943193,0.693953,-70.724709,0.070384,0.000000
50.930004,26.716980,-70.769196,0.007959,0.002744,0.069707,118.843063,6.054154,0.697072,-70.769196,0.070731,0.000000
51.140003,27.424492,-70.813675,0.007963,0.002758,0.070046,121.990234,6.214479,0.700455,-70.813675,0.071078,0.000000
51.350002,27.722389,-70.769196,0.007968,0.002763,0.070176,123.315346,6.281983,0.701757,-70.769196,0.071433,0.000000
51.560001,30.600082,-70.858154,0.007972,0.002797,0.071034,136.115967,6.934078,0.710342,-70.858154,0.071781,0.000000
51.770004,30.951599,-70.769196,0.007994,0.002805,0.071242,137.679596,7.013733,0.712423,-70.769196,0.072136,0.000000
51.980003,31.711983,-70.858154,0.007998,0.002819,0.071606,141.061951,7.186038,0.716064,-70.858154,0.072483,0.000000
52.190002,32.304802,-70.813675,0.008002,0.002829,0.071849,143.698929,7.320373,0.718494,-70.813675,0.072830,0.000000
52.400002,32.682014,-70.813675,0.007998,0.002842,0.072179,145.376862,7.405850,0.721795,-70.813675,0.073185,0.000000
52.610001,34.594894,-70.813675,0.008006,0.002861,0.072665,153.885773,7.839315,0.726647,-70.813675,0.073532,0.000000
52.820004,34.829117,-70.769196,0.008015,0.002866,0.072795,154.927643,7.892390,0.727949,-70.769196,0.073879,0.000000
53.030003,36.168167,-70.858154,0.008024,0.002885,0.073289,160.884048,8.195824,0.732892,-70.858154,0.074235,0.000000
53.240002,37.166496,-70.858154,0.008024,0.002900,0.073653,165.324829,8.422049,0.736533,-70.858154,0.074581,0.000000
53.450001,38.475388,-70.813675,0.008028,0.002915,0.074035,171.147064,8.718648,0.740348,-70.813675,0.074928,0.000000
53.660004,39.398499,-70.902634,0.008032,0.002928,0.074365,175.253281,8.927827,0.743649,-70.902634,0.075284,0.000000
53.870003,40.238571,-70.858154,0.008024,0.002940,0.074668,178.990097,9.118191,0.746684,-70.858154,0.075631,0.000000
54.080002,41.300575,-70.858154,0.008032,0.002956,0.075084,183.714127,9.358844,0.750840,-70.858154,0.075986,0.000000
54.290001,42.588242,-70.902634,0.008041,0.002971,0.075457,189.441956,9.650634,0.754572,-70.902634,0.076333,0.000000
54.500004,44.081825,-70.858154,0.008058,0.002987,0.075874,196.085754,9.989084,0.758735,-70.858154,0.076680,0.000000
54.710003,44.676132,-70.858154,0.008067,0.002995,0.076073,198.729355,10.123756,0.760726,-70.858154,0.077035,0.000000
54.920002,45.327782,-70.902634,0.008054,0.003004,0.076298,201.628036,10.271422,0.762982,-70.902634,0.077382,0.000000
55.130001,46.339523,-70.902634,0.008067,0.003022,0.076749,206.128494,10.500687,0.767493,-70.902634,0.077730,0.000000
55.340004,48.397995,-70.902634,0.008054,0.003041,0.077253,215.285034,10.967143,0.772527,-70.902634,0.078085,0.000000
55.550003,49.594429,-70.858154,0.008067,0.003054,0.077573,220.607040,11.238258,0.775729,-70.858154,0.078432,0.000000
55.760002,50.125061,-70.947121,0.008067,0.003061,0.077747,222.967407,11.358501,0.777470,-70.947121,0.078779,0.000000
55.970001,51.460014,-70.858154,0.008071,0.003078,0.078180,228.905579,11.661006,0.781800,-70.858154,0.079135,0.000000
56.180004,52.597610,-70.947121,0.008084,0.003090,0.078493,233.965851,11.918789,0.784927,-70.947121,0.079481,0.000000
56.390003,54.031250,-70.947121,0.008067,0.003107,0.078926,240.343002,12.243656,0.789264,-70.947121,0.079837,0.000000
56.600002,54.999046,-70.947121,0.008071,0.003118,0.079195,244.647980,12.462961,0.791951,-70.947121,0.080184,0.000000
56.810001,55.988068,-70.947121,0.008084,0.003130,0.079499,249.047363,12.687078,0.794987,-70.947121,0.080530,0.000000
57.020004,56.878036,-70.902634,0.008084,0.003139,0.079742,253.006149,12.888747,0.797417,-70.902634,0.080886,0.000000
57.230003,58.357841,-70.947121,0.008097,0.003158,0.080219,259.588654,13.224076,0.802186,-70.947121,0.081233,0.000000
57.440002,60.177254,-70.947121,0.008088,0.003175,0.080652,267.681793,13.636360,0.806516,-70.947121,0.081580,0.000000
57.650002,61.695419,-70.947121,0.008080,0.003191,0.081050,274.434937,13.980382,0.810505,-70.947121,0.081935,0.000000
57.860004,62.498627,-70.947121,0.008084,0.003201,0.081293,278.007782,14.162392,0.812935,-70.947121,0.082282,0.000000
58.070004,63.979927,-70.902634,0.008110,0.003216,0.081692,284.596924,14.498058,0.816924,-70.902634,0.082630,0.000000
58.280003,65.241524,-70.991600,0.008093,0.003230,0.082031,290.208801,14.783940,0.820308,-70.991600,0.082985,0.000000
58.490002,66.568275,-70.991600,0.008106,0.003243,0.082369,296.110474,15.084587,0.823692,-70.991600,0.083331,0.000000
58.700005,67.547249,-70.947121,0.008101,0.003245,0.082430,300.465179,15.306425,0.824297,-70.947121,0.083601,0.000000
58.910004,67.283989,-71.036079,0.008101,0.003245,0.082430,299.294128,15.246770,0.824297,-71.036079,0.082646,0.000000
59.120003,67.074715,-70.991600,0.008101,0.003245,0.082421,298.363220,15.199347,0.824214,-70.991600,0.082430,0.000000
59.330002,66.862450,-71.036079,0.008114,0.003244,0.082395,297.419037,15.151248,0.823949,-71.036079,0.082430,0.000000
59.540005,66.695641,-71.036079,0.008101,0.003244,0.082387,296.677032,15.113449,0.823866,-71.036079,0.082430,0.000000
59.750004,66.555992,-70.991600,0.008110,0.003243,0.082377,296.055847,15.081803,0.823775,-70.991600,0.082430,0.000000
59.960003,66.408531,-71.036079,0.008101,0.003243,0.082377,295.399902,15.048388,0.823775,-71.036079,0.082430,0.000000
60.170002,66.291237,-71.036079,0.008106,0.003243,0.082369,294.878143,15.021810,0.823692,-71.036079,0.082430,0.000000
60.380001,66.166115,-71.036079,0.008106,0.003243,0.082369,294.321564,14.993456,0.823692,-71.036079,0.082430,0.000000
60.590004,66.061852,-71.080559,0.008106,0.003243,0.082369,293.857788,14.969830,0.823692,-71.080559,0.082430,0.000000
60.800003,65.967278,-71.036079,0.008110,0.003243,0.082360,293.437103,14.948399,0.823601,-71.036079,0.082430,0.000000
61.010002,65.889076,-71.080559,0.008106,0.003243,0.082360,293.089264,14.930678,0.823601,-71.080559,0.082430,0.000000
61.220001,65.801567,-71.036079,0.008097,0.003243,0.082360,292.699982,14.910849,0.823601,-71.036079,0.082430,0.000000
61.430004,65.736778,-71.125038,0.008114,0.003243,0.082360,292.411804,14.896167,0.823601,-71.125038,0.082430,0.000000
61.640003,65.667885,-71.080559,0.008097,0.003243,0.082360,292.105347,14.880556,0.823601,-71.080559,0.082430,0.000000
61.850002,65.589684,-71.080559,0.008097,0.003243,0.082360,291.757477,14.862835,0.823601,-71.080559,0.082430,0.000000
62.060001,65.540535,-71.125038,0.008101,0.003243,0.082360,291.538849,14.851697,0.823601,-71.125038,0.082430,0.000000
62.270004,65.477226,-71.080559,0.008106,0.003243,0.082360,291.257263,14.837352,0.823601,-71.080559,0.082430,0.000000
62.480003,65.416542,-71.080559,0.008106,0.003242,0.082352,290.987305,14.823601,0.823517,-71.080559,0.082430,0.000000
62.690002,65.371849,-71.125038,0.008101,0.003242,0.082352,290.788513,14.813473,0.823517,-71.125038,0.082430,0.000000
62.900002,65.333122,-71.080559,0.008101,0.003242,0.082352,290.616241,14.804697,0.823517,-71.080559,0.082430,0.000000
63.110004,65.277641,-71.169525,0.008101,0.003242,0.082352,290.369446,14.792125,0.823517,-71.169525,0.082430,0.000000
63.320004,65.229225,-71.036079,0.008110,0.003242,0.082352,290.154083,14.781154,0.823517,-71.036079,0.082430,0.000000
63.530003,65.198326,-71.125038,0.008101,0.003242,0.082352,290.016632,14.774152,0.823517,-71.125038,0.082430,0.000000
63.740002,65.159599,-71.125038,0.008101,0.003242,0.082352,289.844360,14.765376,0.823517,-71.125038,0.082430,0.000000
63.950005,65.111565,-71.169525,0.008119,0.003242,0.082352,289.630707,14.754492,0.823517,-71.169525,0.082430,0.000000
64.160004,65.084373,-71.169525,0.008106,0.003242,0.082352,289.509766,14.748329,0.823517,-71.169525,0.082430,0.000000
64.370003,65.041557,-71.080559,0.008119,0.003242,0.082352,289.319305,14.738627,0.823517,-71.080559,0.082430,0.000000
64.580002,65.014366,-71.169525,0.008106,0.003242,0.082352,289.198334,14.732466,0.823517,-71.169525,0.082430,0.000000
64.790001,64.980110,-71.125038,0.008110,0.003242,0.082352,289.045959,14.724703,0.823517,-71.125038,0.082430,0.000000
65.000000,64.946968,-71.169525,0.008106,0.003242,0.082352,288.898529,14.717194,0.823517,-71.169525,0.082430,0.000000
65.210007,64.912712,-71.169525,0.008101,0.003242,0.082352,288.746155,14.709432,0.823517,-71.169525,0.082430,0.000000
65.420006,64.887398,-71.125038,0.008110,0.003242,0.082352,288.633575,14.703694,0.823517,-71.125038,0.082430,0.000000
65.630005,64.855370,-71.214005,0.008110,0.003242,0.082352,288.491089,14.696436,0.823517,-71.214005,0.082430,0.000000
65.840004,64.822227,-71.214005,0.008097,0.003242,0.082352,288.343658,14.688927,0.823517,-71.214005,0.082430,0.000000
66.050003,64.795052,-71.214005,0.008119,0.003242,0.082352,288.222778,14.682769,0.823517,-71.214005,0.082430,0.000000
66.260002,64.770103,-71.214005,0.008114,0.003242,0.082352,288.111816,14.677115,0.823517,-71.214005,0.082430,0.000000
66.470001,64.745140,-71.125038,0.008101,0.003242,0.082352,288.000763,14.671458,0.823517,-71.125038,0.082430,0.000000
66.680000,64.707542,-71.302963,0.008114,0.003242,0.082352,287.833527,14.662939,0.823517,-71.302963,0.082430,0.000000
66.889999,64.692268,-71.258484,0.008106,0.003242,0.082352,287.765594,14.659477,0.823517,-71.258484,0.082430,0.000000
67.100006,64.672157,-71.258484,0.008119,0.003242,0.082352,287.676117,14.654920,0.823517,-71.258484,0.082430,0.000000
67.310005,64.645348,-71.258484,0.008101,0.003242,0.082352,287.556854,14.648846,0.823517,-71.258484,0.082430,0.000000
67.520004,64.620781,-71.214005,0.008114,0.003242,0.082352,287.447601,14.643278,0.823517,-71.214005,0.082430,0.000000
67.730003,64.602150,-71.302963,0.008110,0.003242,0.082352,287.364716,14.639056,0.823517,-71.302963,0.082430,0.000000
67.940002,64.571999,-71.258484,0.008119,0.003242,0.082352,287.230591,14.632224,0.823517,-71.258484,0.082430,0.000000
68.150002,64.568642,-71.258484,0.008123,0.003242,0.082352,287.215668,14.631463,0.823517,-71.258484,0.082430,0.000000
68.360001,64.538857,-71.258484,0.008110,0.003242,0.082352,287.083160,14.624714,0.823517,-71.258484,0.082430,0.000000
68.570000,64.521355,-71.214005,0.008119,0.003242,0.082352,287.005310,14.620748,0.823517,-71.214005,0.082430,0.000000
68.780006,64.504219,-71.347443,0.008110,0.003242,0.082352,286.929108,14.616865,0.823517,-71.347443,0.082430,0.000000
68.990005,64.487465,-71.302963,0.008114,0.003242,0.082352,286.854584,14.613069,0.823517,-71.302963,0.082430,0.000000
69.200005,64.460655,-71.258484,0.008110,0.003242,0.082352,286.735321,14.606993,0.823517,-71.258484,0.082430,0.000000
69.410004,64.426765,-71.302963,0.008106,0.003242,0.082352,286.584564,14.599314,0.823517,-71.302963,0.082430,0.000000
69.620003,64.427513,-71.347443,0.008106,0.003242,0.082352,286.587891,14.599483,0.823517,-71.347443,0.082430,0.000000
69.830002,64.400337,-71.391930,0.008114,0.003242,0.082352,286.467010,14.593325,0.823517,-71.391930,0.082430,0.000000
70.040001,64.381340,-71.258484,0.008106,0.003242,0.082352,286.382507,14.589021,0.823517,-71.258484,0.082430,0.000000
70.250000,64.372780,-71.302963,0.008119,0.003242,0.082352,286.344421,14.587080,0.823517,-71.302963,0.082430,0.000000
70.460007,64.347832,-71.347443,0.008097,0.003242,0.082352,286.233459,14.581428,0.823517,-71.347443,0.082430,0.000000
70.670006,64.330696,-71.302963,0.008106,0.003242,0.082352,286.157227,14.577543,0.823517,-71.302963,0.082430,0.000000
70.880005,64.321388,-71.347443,0.008110,0.003242,0.082352,286.115814,14.575435,0.823517,-71.347443,0.082430,0.000000
71.090004,64.313194,-71.302963,0.008114,0.003242,0.082352,286.079376,14.573578,0.823517,-71.302963,0.082430,0.000000
71.300003,64.302025,-71.391930,0.008114,0.003242,0.082352,286.029694,14.571047,0.823517,-71.391930,0.082430,0.000000
71.510002,64.294197,-71.391930,0.008110,0.003242,0.082352,285.994873,14.569273,0.823517,-71.391930,0.082430,0.000000
71.720001,64.273354,-71.391930,0.008110,0.003242,0.082352,285.902161,14.564549,0.823517,-71.391930,0.082430,0.000000
71.930000,64.251747,-71.436409,0.008114,0.003242,0.082352,285.806030,14.559654,0.823517,-71.436409,0.082430,0.000000
72.140007,64.231270,-71.347443,0.008106,0.003242,0.082352,285.714966,14.555014,0.823517,-71.347443,0.082430,0.000000
72.350006,64.216011,-71.436409,0.008110,0.003242,0.082352,285.647095,14.551556,0.823517,-71.436409,0.082430,0.000000
72.560005,64.204094,-71.436409,0.008106,0.003242,0.082352,285.594086,14.548856,0.823517,-71.436409,0.082430,0.000000
72.770004,64.191063,-71.347443,0.008110,0.003242,0.082352,285.536102,14.545902,0.823517,-71.347443,0.082430,0.000000
72.980003,64.162010,-71.436409,0.008114,0.003242,0.082352,285.406860,14.539319,0.823517,-71.436409,0.082430,0.000000
73.190002,64.164619,-71.391930,0.008097,0.003242,0.082352,285.418488,14.539911,0.823517,-71.391930,0.082430,0.000000
73.400002,64.140038,-71.480888,0.008119,0.003242,0.082352,285.309143,14.534341,0.823517,-71.480888,0.082430,0.000000
73.610001,64.134453,-71.436409,0.008114,0.003242,0.082352,285.284302,14.533075,0.823517,-71.436409,0.082430,0.000000
73.820000,64.131844,-71.436409,0.008106,0.003242,0.082352,285.272675,14.532483,0.823517,-71.436409,0.082430,0.000000
74.030006,64.111748,-71.436409,0.008110,0.003242,0.082352,285.183289,14.527930,0.823517,-71.436409,0.082430,0.000000
74.240005,64.092384,-71.391930,0.008119,0.003242,0.082352,285.097168,14.523541,0.823517,-71.391930,0.082430,0.000000
74.450005,64.086800,-71.436409,0.008106,0.003242,0.082352,285.072327,14.522276,0.823517,-71.436409,0.082430,0.000000
74.660004,64.074135,-71.480888,0.008114,0.003242,0.082352,285.015991,14.519406,0.823517,-71.480888,0.082430,0.000000
74.870003,64.067436,-71.436409,0.008119,0.003242,0.082352,284.986176,14.517888,0.823517,-71.436409,0.082430,0.000000
75.080002,64.050667,-71.480888,0.008114,0.003242,0.082352,284.911591,14.514089,0.823517,-71.480888,0.082430,0.000000
75.290001,64.042107,-71.480888,0.008110,0.003242,0.082352,284.873505,14.512149,0.823517,-71.480888,0.082430,0.000000
75.500000,64.017525,-71.480888,0.008127,0.003242,0.082352,284.764160,14.506578,0.823517,-71.480888,0.082430,0.000000
75.710007,64.010826,-71.480888,0.008101,0.003242,0.082352,284.734375,14.505061,0.823517,-71.480888,0.082430,0.000000
75.920006,63.993706,-71.525368,0.008114,0.003242,0.082352,284.658234,14.501182,0.823517,-71.525368,0.082430,0.000000
76.130005,63.981789,-71.614334,0.008114,0.003242,0.082352,284.605225,14.498481,0.823517,-71.614334,0.082430,0.000000
76.340004,63.974342,-71.525368,0.008114,0.003242,0.082352,284.572083,14.496793,0.823517,-71.525368,0.082430,0.000000
76.550003,63.959816,-71.480888,0.008123,0.003242,0.082352,284.507477,14.493501,0.823517,-71.480888,0.082430,0.000000
76.760002,63.950127,-71.480888,0.008114,0.003242,0.082352,284.464355,14.491306,0.823517,-71.480888,0.082430,0.000000
76.970001,63.950127,-71.480888,0.008119,0.003242,0.082352,284.464355,14.491306,0.823517,-71.480888,0.082430,0.000000
77.180000,63.930397,-71.569847,0.008106,0.003242,0.082352,284.376617,14.486835,0.823517,-71.569847,0.082430,0.000000
77.390007,63.918480,-71.480888,0.008110,0.003242,0.082352,284.323608,14.484135,0.823517,-71.480888,0.082430,0.000000
77.600006,63.913643,-71.525368,0.008110,0.003242,0.082352,284.302094,14.483038,0.823517,-71.525368,0.082430,0.000000
77.810005,63.908806,-71.525368,0.008101,0.003242,0.082352,284.280579,14.481942,0.823517,-71.525368,0.082430,0.000000
78.020004,63.887947,-71.525368,0.008114,0.003242,0.082352,284.187775,14.477216,0.823517,-71.525368,0.082430,0.000000
78.230003,63.874168,-71.569847,0.008114,0.003242,0.082352,284.126495,14.474093,0.823517,-71.569847,0.082430,0.000000
78.440002,63.865974,-71.525368,0.008106,0.003242,0.082352,284.090057,14.472237,0.823517,-71.525368,0.082430,0.000000
78.650002,63.867836,-71.569847,0.008114,0.003242,0.082352,284.098328,14.472658,0.823517,-71.569847,0.082430,0.000000
78.860001,63.847359,-71.569847,0.008114,0.003242,0.082352,284.007233,14.468018,0.823517,-71.569847,0.082430,0.000000
79.070007,63.836937,-71.569847,0.008110,0.003242,0.082352,283.960876,14.465656,0.823517,-71.569847,0.082430,0.000000
79.280006,63.837669,-71.658813,0.008114,0.003242,0.082352,283.964142,14.465823,0.823517,-71.658813,0.082430,0.000000
79.490005,63.809746,-71.614334,0.008101,0.003242,0.082352,283.839935,14.459496,0.823517,-71.614334,0.082430,0.000000
79.700005,63.802299,-71.525368,0.008101,0.003242,0.082352,283.806793,14.457808,0.823517,-71.525368,0.082430,0.000000
79.910004,63.790382,-71.614334,0.008114,0.003242,0.082352,283.753784,14.455108,0.823517,-71.614334,0.082430,0.000000
80.120003,63.793358,-71.569847,0.008114,0.003242,0.082352,283.767029,14.455781,0.823517,-71.569847,0.082430,0.000000
80.330002,63.784798,-71.614334,0.008119,0.003242,0.082352,283.728943,14.453842,0.823517,-71.614334,0.082430,0.000000
80.540001,63.765800,-71.614334,0.008110,0.003242,0.082352,283.644440,14.449537,0.823517,-71.614334,0.082430,0.000000
80.750008,63.768044,-71.614334,0.008110,0.003242,0.082352,283.654419,14.450046,0.823517,-71.614334,0.082430,0.000000
80.960007,63.761711,-71.658813,0.008110,0.003242,0.082352,283.626251,14.448610,0.823517,-71.658813,0.082430,0.000000
81.170006,63.753899,-71.614334,0.008106,0.003242,0.082352,283.591492,14.446840,0.823517,-71.614334,0.082430,0.000000
81.380005,63.744576,-71.658813,0.008106,0.003242,0.082352,283.550018,14.444728,0.823517,-71.658813,0.082430,0.000000
81.590004,63.738991,-71.614334,0.008114,0.003242,0.082352,283.525177,14.443462,0.823517,-71.614334,0.082430,0.000000
81.800003,63.730812,-71.658813,0.008123,0.003242,0.082352,283.488800,14.441608,0.823517,-71.658813,0.082430,0.000000
82.010002,63.738258,-71.703293,0.008114,0.003242,0.082352,283.521942,14.443295,0.823517,-71.703293,0.082430,0.000000
82.220001,63.716286,-71.658813,0.008110,0.003242,0.082352,283.424194,14.438317,0.823517,-71.658813,0.082430,0.000000
82.430000,63.710701,-71.658813,0.008119,0.003242,0.082352,283.399353,14.437052,0.823517,-71.658813,0.082430,0.000000
82.640007,63.696922,-71.658813,0.008110,0.003242,0.082352,283.338074,14.433928,0.823517,-71.658813,0.082430,0.000000
82.850006,63.680534,-71.703293,0.008106,0.003242,0.082352,283.265167,14.430216,0.823517,-71.703293,0.082430,0.000000
83.060005,63.678673,-71.658813,0.008110,0.003242,0.082352,283.256897,14.429793,0.823517,-71.658813,0.082430,0.000000
83.270004,63.670479,-71.658813,0.008110,0.003242,0.082352,283.220428,14.427937,0.823517,-71.658813,0.082430,0.000000
83.480003,63.665260,-71.747772,0.008101,0.003242,0.082352,283.197235,14.426754,0.823517,-71.747772,0.082430,0.000000
83.690002,63.660057,-71.792252,0.008114,0.003242,0.082352,283.174072,14.425575,0.823517,-71.792252,0.082430,0.000000
83.900002,63.638832,-71.658813,0.008110,0.003242,0.082352,283.079651,14.420766,0.823517,-71.658813,0.082430,0.000000
84.110001,63.647392,-71.792252,0.008110,0.003242,0.082352,283.117737,14.422705,0.823517,-71.792252,0.082430,0.000000
84.320007,63.626915,-71.658813,0.008123,0.003242,0.082352,283.026642,14.418065,0.823517,-71.658813,0.082430,0.000000
84.530006,63.620583,-71.792252,0.008110,0.003242,0.082352,282.998474,14.416630,0.823517,-71.792252,0.082430,0.000000
84.740005,63.608665,-71.747772,0.008114,0.003242,0.082352,282.945465,14.413930,0.823517,-71.747772,0.082430,0.000000
84.950005,63.607918,-71.703293,0.008114,0.003242,0.082352,282.942139,14.413760,0.823517,-71.703293,0.082430,0.000000
85.160004,63.597496,-71.792252,0.008114,0.003242,0.082352,282.895782,14.411399,0.823517,-71.792252,0.082430,0.000000
85.370003,63.594887,-71.747772,0.008119,0.003242,0.082352,282.884186,14.410808,0.823517,-71.747772,0.082430,0.000000
85.580002,63.591164,-71.792252,0.008106,0.003242,0.082352,282.867615,14.409964,0.823517,-71.792252,0.082430,0.000000
85.790001,63.581108,-71.792252,0.008106,0.003242,0.082352,282.822906,14.407685,0.823517,-71.792252,0.082430,0.000000
86.000008,63.581490,-71.792252,0.008110,0.003242,0.082352,282.824585,14.407772,0.823517,-71.792252,0.082430,0.000000
86.210007,63.580360,-71.836739,0.008106,0.003242,0.082352,282.819580,14.407516,0.823517,-71.836739,0.082430,0.000000
86.420006,63.573662,-71.792252,0.008119,0.003242,0.082352,282.789764,14.405998,0.823517,-71.792252,0.082430,0.000000
86.630005,63.560997,-71.836739,0.008110,0.003242,0.082352,282.733429,14.403128,0.823517,-71.836739,0.082430,0.000000
86.840004,63.560997,-71.792252,0.008127,0.003242,0.082352,282.733429,14.403128,0.823517,-71.792252,0.082430,0.000000
87.050003,63.551689,-71.792252,0.008119,0.003242,0.082352,282.692047,14.401018,0.823517,-71.792252,0.082430,0.000000
87.260002,63.544624,-71.836739,0.008114,0.003242,0.082352,282.660614,14.399418,0.823517,-71.836739,0.082430,0.000000
87.470001,63.549080,-71.792252,0.008114,0.003242,0.082352,282.680420,14.400428,0.823517,-71.792252,0.082430,0.000000
87.680008,63.534569,-71.881218,0.008119,0.003242,0.082352,282.615875,14.397140,0.823517,-71.881218,0.082430,0.000000
87.890007,63.529350,-71.792252,0.008110,0.003242,0.082352,282.592651,14.395956,0.823517,-71.792252,0.082430,0.000000
88.100006,63.523399,-71.836739,0.008110,0.003242,0.082352,282.566193,14.394608,0.823517,-71.836739,0.082430,0.000000
88.310005,63.524132,-71.881218,0.008114,0.003242,0.082352,282.569458,14.394774,0.823517,-71.881218,0.082430,0.000000
88.520004,63.511848,-71.836739,0.008106,0.003242,0.082352,282.514801,14.391991,0.823517,-71.836739,0.082430,0.000000
88.730003,63.509987,-71.925697,0.008114,0.003242,0.082352,282.506531,14.391569,0.823517,-71.925697,0.082430,0.000000
88.940002,63.498451,-71.836739,0.008110,0.003242,0.082352,282.455231,14.388955,0.823517,-71.836739,0.082430,0.000000
89.100006,63.473488,-71.881218,0.008132,0.003242,0.082352,282.344177,14.383298,0.823517,-71.881218,0.082430,0.000000