File: Data/compression 6/AutoNoheating-10-6-day2-2-240229_02292024_170133.csv
Time (sec),S:Load (lbs),S:HL1 (DIM),S:LVDT (in),S:Position (in),Ch:Position (mm),Ch:Load (N),Ch:Stress (MPa),Ch:Strain (mm/mm),Ch:HL1 (DIM),Set Point (),Cycles ()
0.010000,-0.011169,-75.306252,0.000000,-0.000000,-0.000000,-0.049684,-0.002531,-0.000000,-75.306252,0.000208,0.000000
0.210000,-0.004471,-75.350731,0.000000,-0.000000,-0.000000,-0.019887,-0.001013,-0.000000,-75.350731,0.000208,0.000000
0.410000,0.024574,-75.306252,0.000017,0.000039,0.000989,0.109312,0.005569,0.009886,-75.306252,0.001543,0.000000
0.610000,0.014519,-75.306252,0.000000,0.000154,0.003911,0.064583,0.003290,0.039113,-75.306252,0.004873,0.000000
0.810000,0.009308,-75.350731,0.000108,0.000281,0.007146,0.041403,0.002109,0.071459,-75.350731,0.008204,0.000000
1.010000,0.011169,-75.350731,0.000220,0.000412,0.010458,0.049684,0.002531,0.104584,-75.350731,0.011534,0.000000
1.210000,0.001114,-75.350731,0.000341,0.000538,0.013659,0.004955,0.000252,0.136589,-75.350731,0.014864,0.000000
1.410000,-0.009682,-75.439690,0.000479,0.000668,0.016971,-0.043066,-0.002194,0.169715,-75.439690,0.018194,0.000000
1.610000,-0.014153,-75.350731,0.000621,0.000799,0.020301,-0.062954,-0.003207,0.203014,-75.350731,0.021525,0.000000
1.810000,-0.021225,-75.395210,0.000742,0.000929,0.023606,-0.094413,-0.004810,0.236056,-75.395210,0.024855,0.000000
2.010000,-0.012291,-75.395210,0.000880,0.001070,0.027179,-0.054673,-0.002785,0.271786,-75.395210,0.028185,0.000000
2.210000,0.013031,-75.395210,0.001013,0.001201,0.030509,0.057965,0.002953,0.305093,-75.395210,0.031532,0.000000
2.410000,0.011917,-75.395210,0.001143,0.001332,0.033830,0.053010,0.002700,0.338301,-75.395210,0.034863,0.000000
2.610000,0.025696,-75.395210,0.001276,0.001463,0.037161,0.114301,0.005823,0.371609,-75.395210,0.038193,0.000000
2.810000,0.013405,-75.395210,0.001397,0.001592,0.040448,0.059628,0.003038,0.404477,-75.395210,0.041523,0.000000
3.010000,0.004097,-75.439690,0.001539,0.001724,0.043778,0.018224,0.000928,0.437776,-75.439690,0.044853,0.000000
3.210000,-0.021599,-75.439690,0.001669,0.001856,0.047133,-0.096076,-0.004894,0.471333,-75.439690,0.048183,0.000000
3.410000,-0.010803,-75.395210,0.001794,0.001986,0.050438,-0.048055,-0.002448,0.504375,-75.395210,0.051513,0.000000
3.610000,-0.036491,-75.484177,0.001919,0.002115,0.053733,-0.162322,-0.008269,0.537334,-75.484177,0.054843,0.000000
3.810000,-0.037979,-75.484177,0.002074,0.002246,0.057055,-0.168940,-0.008606,0.570550,-75.484177,0.058173,0.000000
4.010000,-0.065910,-75.395210,0.002199,0.002378,0.060411,-0.293184,-0.014935,0.604107,-75.395210,0.061504,0.000000
4.210000,-0.035751,-75.395210,0.002333,0.002508,0.063698,-0.159030,-0.008101,0.636975,-75.395210,0.064851,0.000000
4.410000,-0.001122,-75.439690,0.002475,0.002642,0.067115,-0.004989,-0.000254,0.671145,-75.439690,0.068181,0.000000
4.610000,0.000748,-75.395210,0.002613,0.002770,0.070366,0.003326,0.000169,0.703665,-75.395210,0.071511,0.000000
4.810000,-0.012665,-75.439690,0.002742,0.002904,0.073766,-0.056336,-0.002870,0.737661,-75.439690,0.074842,0.000000
5.010000,0.004837,-75.439690,0.002871,0.003037,0.077131,0.021516,0.001096,0.771309,-75.439690,0.078172,0.000000
5.210000,0.018616,-75.439690,0.002992,0.003168,0.080478,0.082807,0.004218,0.804782,-75.439690,0.081502,0.000000
5.410000,0.009308,-75.484177,0.003126,0.003297,0.083739,0.041403,0.002109,0.837393,-75.484177,0.084832,0.000000
5.610000,0.009308,-75.439690,0.003264,0.003426,0.087026,0.041403,0.002109,0.870261,-75.439690,0.088162,0.000000
5.810000,-0.005959,-75.528656,0.003380,0.003555,0.090295,-0.026505,-0.001350,0.902955,-75.528656,0.091492,0.000000
6.010000,0.006332,-75.528656,0.003535,0.003689,0.093703,0.028168,0.001435,0.937034,-75.528656,0.094840,0.000000
6.210001,-0.002983,-75.528656,0.003669,0.003821,0.097060,-0.013269,-0.000676,0.970598,-75.528656,0.098170,0.000000
6.410000,0.036865,-75.484177,0.003803,0.003952,0.100372,0.163985,0.008354,1.003724,-75.484177,0.101500,0.000000
6.610000,0.047661,-75.528656,0.003928,0.004079,0.103599,0.212006,0.010800,1.035986,-75.528656,0.104830,0.000000
6.810000,0.045425,-75.573135,0.004057,0.004210,0.106938,0.202062,0.010294,1.069377,-75.573135,0.108160,0.000000
7.010000,0.049522,-75.528656,0.004195,0.004347,0.110415,0.220287,0.011222,1.104152,-75.528656,0.111490,0.000000
7.210001,0.019737,-75.528656,0.004320,0.004478,0.113745,0.087796,0.004473,1.137452,-75.528656,0.114821,0.000000
7.410000,0.028671,-75.528656,0.004445,0.004609,0.117067,0.127536,0.006497,1.170668,-75.528656,0.118151,0.000000
7.610000,0.005211,-75.528656,0.004596,0.004740,0.120388,0.023179,0.001181,1.203884,-75.528656,0.121481,0.000000
7.810000,0.019737,-75.573135,0.004730,0.004869,0.123675,0.087796,0.004473,1.236752,-75.573135,0.124811,0.000000
8.010000,0.008934,-75.617615,0.004850,0.005000,0.126997,0.039741,0.002024,1.269969,-75.617615,0.128159,0.000000
8.210000,-0.004097,-75.573135,0.004980,0.005132,0.130344,-0.018224,-0.000928,1.303442,-75.573135,0.131489,0.000000
8.410001,-0.001488,-75.662094,0.005113,0.005271,0.133873,-0.006618,-0.000337,1.338732,-75.662094,0.134819,0.000000
8.610001,0.021973,-75.573135,0.005243,0.005398,0.137117,0.097739,0.004979,1.371169,-75.573135,0.138149,0.000000
8.810000,0.024200,-75.617615,0.005376,0.005529,0.140447,0.107649,0.005484,1.404469,-75.617615,0.141479,0.000000
9.010000,0.031281,-75.573135,0.005506,0.005664,0.143856,0.139143,0.007088,1.438555,-75.573135,0.144809,0.000000
9.210000,0.027924,-75.528656,0.005635,0.005791,0.147090,0.124210,0.006328,1.470901,-75.528656,0.148139,0.000000
9.410001,0.027184,-75.617615,0.005756,0.005921,0.150394,0.120918,0.006160,1.503943,-75.617615,0.151469,0.000000
9.610001,-0.003723,-75.573135,0.005907,0.006052,0.153733,-0.016561,-0.000844,1.537333,-75.573135,0.154800,0.000000
9.810000,-0.000000,-75.573135,0.006019,0.006183,0.157046,-0.000000,-0.000000,1.570459,-75.573135,0.158130,0.000000
10.010000,-0.009308,-75.528656,0.006161,0.006313,0.160341,-0.041403,-0.002109,1.603410,-75.528656,0.161477,0.000000
10.210000,-0.015640,-75.617615,0.006278,0.006444,0.163689,-0.069571,-0.003544,1.636891,-75.617615,0.164807,0.000000
10.410001,-0.026070,-75.617615,0.006411,0.006576,0.167019,-0.115964,-0.005907,1.670191,-75.617615,0.168138,0.000000
10.610001,-0.012291,-75.662094,0.006549,0.006706,0.170341,-0.054673,-0.002785,1.703407,-75.662094,0.171468,0.000000
10.810000,0.026062,-75.662094,0.006683,0.006840,0.173749,0.115930,0.005906,1.737486,-75.662094,0.174798,0.000000
11.010000,0.026810,-75.617615,0.006808,0.006969,0.177018,0.119255,0.006075,1.770180,-75.617615,0.178128,0.000000
11.210001,0.034630,-75.662094,0.006946,0.007104,0.180452,0.154041,0.007847,1.804524,-75.662094,0.181458,0.000000
11.410001,0.042076,-75.617615,0.007088,0.007237,0.183826,0.187164,0.009535,1.838255,-75.617615,0.184788,0.000000
11.610001,0.046921,-75.617615,0.007209,0.007366,0.187087,0.208714,0.010632,1.870866,-75.617615,0.188118,0.000000
11.810000,0.062187,-75.662094,0.007347,0.007495,0.190373,0.276622,0.014092,1.903734,-75.662094,0.191466,0.000000
12.010000,0.080429,-75.662094,0.007485,0.007624,0.193643,0.357766,0.018225,1.936428,-75.662094,0.194796,0.000000
12.210001,0.097191,-75.662094,0.007614,0.007755,0.196964,0.432327,0.022024,1.969644,-75.662094,0.198126,0.000000
12.410001,0.112457,-75.662094,0.007748,0.007886,0.200294,0.500235,0.025483,2.002944,-75.662094,0.201456,0.000000
12.610001,0.151558,-75.662094,0.007877,0.008018,0.203659,0.674163,0.034344,2.036592,-75.662094,0.204786,0.000000
12.810000,0.217468,-75.662094,0.008015,0.008149,0.206989,0.967347,0.049279,2.069891,-75.662094,0.208117,0.000000
13.010000,0.268852,-75.662094,0.008136,0.008277,0.210224,1.195915,0.060923,2.102244,-75.662094,0.211447,0.000000
13.210001,0.336998,-75.706581,0.008282,0.008409,0.213598,1.499042,0.076365,2.135975,-75.706581,0.214777,0.000000
13.410001,0.426369,-75.751060,0.008412,0.008546,0.217067,1.896583,0.096617,2.170668,-75.751060,0.218107,0.000000
13.610001,0.533607,-75.662094,0.008554,0.008676,0.220362,2.373605,0.120917,2.203619,-75.662094,0.221438,0.000000
13.810000,0.684044,-75.706581,0.008688,0.000009,0.000225,3.042779,0.155007,0.002248,-75.706581,0.001283,0.000000
14.010000,0.526161,-75.706581,0.008701,0.000003,0.000069,2.340482,0.119230,0.000689,-75.706581,0.000182,0.000000
14.210001,0.486320,-75.662094,0.008696,0.000003,0.000069,2.163262,0.110202,0.000689,-75.662094,0.000182,0.000000
14.410001,0.462486,-75.751060,0.008709,0.000002,0.000061,2.057242,0.104801,0.000606,-75.751060,0.000294,0.000000
14.610001,0.463974,-75.706581,0.008688,0.000003,0.000069,2.063859,0.105138,0.000689,-75.706581,0.000633,0.000000
14.810000,0.483711,-75.706581,0.008701,0.000003,0.000078,2.151655,0.109611,0.000780,-75.706581,0.000962,0.000000
15.010001,0.537331,-75.706581,0.008701,0.000023,0.000590,2.390166,0.121761,0.005897,-75.706581,0.001300,0.000000
15.210001,0.548134,-75.706581,0.008709,0.000031,0.000789,2.438221,0.124209,0.007888,-75.706581,0.001630,0.000000
15.410001,0.546272,-75.706581,0.008718,0.000046,0.001170,2.429940,0.123787,0.011703,-75.706581,0.001960,0.000000
15.610001,0.569733,-75.706581,0.008735,0.000055,0.001404,2.534297,0.129103,0.014042,-75.706581,0.002298,0.000000
15.810000,0.587227,-75.795540,0.008744,0.000066,0.001674,2.612116,0.133068,0.016737,-75.795540,0.002627,0.000000
16.010000,0.632286,-75.751060,0.008757,0.000082,0.002090,2.812549,0.143278,0.020900,-75.751060,0.002966,0.000000
16.210001,0.656120,-75.795540,0.008774,0.000095,0.002402,2.918569,0.148679,0.024019,-75.795540,0.003295,0.000000
16.410000,0.636009,-75.751060,0.008787,0.000102,0.002601,2.829110,0.144122,0.026010,-75.751060,0.003633,0.000000
16.610001,0.711227,-75.751060,0.008791,0.000121,0.003061,3.163697,0.161166,0.030612,-75.751060,0.003963,0.000000
16.810001,0.694847,-75.795540,0.008821,0.000134,0.003399,3.090834,0.157455,0.033988,-75.795540,0.004292,0.000000
17.010000,0.727615,-75.706581,0.008826,0.000153,0.003893,3.236595,0.164880,0.038931,-75.706581,0.004630,0.000000
17.210001,0.714951,-75.795540,0.008839,0.000162,0.004110,3.180259,0.162010,0.041104,-75.795540,0.004960,0.000000
17.410002,0.708252,-75.795540,0.008852,0.000175,0.004449,3.150462,0.160492,0.044488,-75.795540,0.005298,0.000000
17.610001,0.724266,-75.840019,0.008856,0.000185,0.004700,3.221696,0.164121,0.047001,-75.840019,0.005628,0.000000
17.810001,0.745117,-75.795540,0.008869,0.000196,0.004986,3.314447,0.168846,0.049862,-75.795540,0.005967,0.000000
18.010000,0.776772,-75.884506,0.008882,0.000210,0.005342,3.455252,0.176019,0.053420,-75.884506,0.006296,0.000000
18.210001,0.812141,-75.795540,0.008895,0.000225,0.005714,3.612586,0.184034,0.057144,-75.795540,0.006634,0.000000
18.410002,0.798737,-75.840019,0.008916,0.000232,0.005905,3.552958,0.180996,0.059052,-75.840019,0.006963,0.000000
18.610001,0.818100,-75.840019,0.008929,0.000248,0.006304,3.639091,0.185384,0.063041,-75.840019,0.007293,0.000000
18.810001,0.853851,-75.840019,0.008942,0.000265,0.006730,3.798120,0.193485,0.067295,-75.840019,0.007631,0.000000
19.010000,0.876938,-75.840019,0.008959,0.000284,0.007206,3.900815,0.198717,0.072064,-75.840019,0.007961,0.000000
19.210001,0.837463,-75.840019,0.008981,0.000293,0.007449,3.725223,0.189772,0.074494,-75.840019,0.008299,0.000000
19.410002,0.857574,-75.884506,0.008981,0.000304,0.007718,3.814682,0.194329,0.077182,-75.884506,0.008629,0.000000
19.610001,0.847893,-75.840019,0.008994,0.000313,0.007944,3.771615,0.192135,0.079437,-75.840019,0.008966,0.000000
19.810001,0.909332,-75.840019,0.009015,0.000329,0.008351,4.044912,0.206058,0.083510,-75.840019,0.009296,0.000000
20.010000,0.918640,-75.884506,0.009011,0.000338,0.008594,4.086316,0.208167,0.085940,-75.884506,0.009635,0.000000
20.210001,0.952530,-75.884506,0.009046,0.000353,0.008966,4.237065,0.215846,0.089664,-75.884506,0.009964,0.000000
20.410002,0.993492,-75.884506,0.009041,0.000365,0.009270,4.419274,0.225129,0.092700,-75.884506,0.010293,0.000000
20.610001,0.992371,-75.795540,0.009058,0.000379,0.009626,4.414285,0.224874,0.096257,-75.795540,0.010632,0.000000
20.810001,1.044502,-75.884506,0.009076,0.000398,0.010112,4.646178,0.236688,0.101117,-75.884506,0.010961,0.000000
21.010000,1.025887,-75.884506,0.009102,0.000408,0.010354,4.563371,0.232469,0.103540,-75.884506,0.011299,0.000000
21.210001,0.987160,-76.017944,0.009102,0.000421,0.010692,4.391106,0.223694,0.106923,-76.017944,0.011629,0.000000
21.410002,1.015083,-75.928986,0.009136,0.000435,0.011040,4.515316,0.230021,0.110398,-75.928986,0.011967,0.000000
21.610001,1.022163,-75.928986,0.009132,0.000443,0.011265,4.546810,0.231626,0.112646,-75.928986,0.012297,0.000000
21.810001,1.136848,-75.884506,0.009145,0.000462,0.011733,5.056954,0.257614,0.117332,-75.884506,0.012626,0.000000
22.010000,1.100731,-75.884506,0.009166,0.000470,0.011941,4.896296,0.249429,0.119413,-75.884506,0.012965,0.000000
22.210001,1.104828,-75.973465,0.009179,0.000482,0.012253,4.914520,0.250358,0.122532,-75.973465,0.013294,0.000000
22.410002,1.161057,-75.928986,0.009184,0.000495,0.012583,5.164638,0.263099,0.125833,-75.928986,0.013632,0.000000
22.610001,1.164032,-75.973465,0.009201,0.000509,0.012922,5.177873,0.263773,0.129216,-75.973465,0.013962,0.000000
22.810001,1.246330,-75.928986,0.009209,0.000529,0.013433,5.543954,0.282422,0.134333,-75.928986,0.014300,0.000000
23.010000,1.234787,-75.884506,0.009244,0.000542,0.013763,5.492607,0.279807,0.137626,-75.884506,0.014630,0.000000
23.210001,1.202759,-75.884506,0.009253,0.000554,0.014075,5.350138,0.272549,0.140745,-75.884506,0.014968,0.000000
23.410002,1.227715,-75.928986,0.009274,0.000566,0.014378,5.461147,0.278204,0.143781,-75.928986,0.015298,0.000000
23.610001,1.213936,-75.973465,0.009283,0.000576,0.014638,5.399857,0.275082,0.146385,-75.973465,0.015627,0.000000
23.810001,1.308517,-75.973465,0.009296,0.000592,0.015037,5.820576,0.296514,0.150374,-75.973465,0.015965,0.000000
24.010000,1.344261,-75.973465,0.009313,0.000606,0.015401,5.979572,0.304614,0.154015,-75.973465,0.016295,0.000000
24.210001,1.337563,-76.017944,0.009317,0.000615,0.015619,5.949775,0.303096,0.156187,-76.017944,0.016633,0.000000
24.410002,1.345009,-75.973465,0.009330,0.000623,0.015826,5.982898,0.304783,0.158262,-75.973465,0.016962,0.000000
24.610001,1.508110,-76.017944,0.009365,0.000653,0.016581,6.708408,0.341743,0.165809,-76.017944,0.017301,0.000000
24.810001,1.434006,-76.017944,0.009373,0.000664,0.016876,6.378776,0.324950,0.168761,-76.017944,0.017630,0.000000
25.010002,1.407196,-76.017944,0.009378,0.000675,0.017145,6.259521,0.318875,0.171448,-76.017944,0.017960,0.000000
25.210001,1.437355,-76.017944,0.009412,0.000687,0.017439,6.393674,0.325709,0.174393,-76.017944,0.018298,0.000000
25.410002,1.368843,-76.017944,0.009412,0.000693,0.017596,6.088918,0.310184,0.175960,-76.017944,0.018628,0.000000
25.610001,1.522255,-76.017944,0.009434,0.000713,0.018116,6.771328,0.344948,0.181160,-76.017944,0.018966,0.000000
25.810001,1.574020,-76.062424,0.009459,0.000724,0.018394,7.001592,0.356678,0.183938,-76.062424,0.019295,0.000000
26.010002,1.616096,-75.973465,0.009455,0.000738,0.018749,7.188756,0.366213,0.187489,-75.973465,0.019634,0.000000
26.210001,1.661522,-75.973465,0.009472,0.000750,0.019044,7.390819,0.376506,0.190441,-75.973465,0.019963,0.000000
26.410002,1.689079,-76.062424,0.009485,0.000765,0.019426,7.513400,0.382751,0.194256,-76.062424,0.020301,0.000000
26.610001,1.690567,-76.062424,0.009511,0.000779,0.019781,7.520018,0.383088,0.197814,-76.062424,0.020631,0.000000
26.810001,1.692062,-76.062424,0.009511,0.000790,0.020076,7.526670,0.383427,0.200758,-76.062424,0.020961,0.000000
27.010002,1.700249,-76.062424,0.009528,0.000804,0.020423,7.563084,0.385282,0.204225,-76.062424,0.021298,0.000000
27.210001,1.747169,-76.106911,0.009554,0.000818,0.020787,7.771798,0.395914,0.207874,-76.106911,0.021628,0.000000
27.410002,1.788879,-76.062424,0.009563,0.000833,0.021160,7.957333,0.405366,0.211598,-76.062424,0.021967,0.000000
27.610001,1.881226,-76.062424,0.009585,0.000848,0.021550,8.368110,0.426292,0.215504,-76.062424,0.022296,0.000000
27.810001,1.813454,-76.106911,0.009606,0.000858,0.021784,8.066645,0.410934,0.217843,-76.106911,0.022634,0.000000
28.010002,1.805634,-76.062424,0.009615,0.000867,0.022018,8.031859,0.409162,0.220182,-76.062424,0.022964,0.000000
28.210001,1.871170,-76.151390,0.009628,0.000878,0.022313,8.323380,0.424013,0.223135,-76.151390,0.023302,0.000000
28.410002,1.976181,-76.151390,0.009636,0.000896,0.022756,8.790492,0.447809,0.227555,-76.151390,0.023631,0.000000
28.610001,1.975807,-76.106911,0.009649,0.000911,0.023129,8.788830,0.447724,0.231287,-76.106911,0.023961,0.000000
28.810001,1.991074,-76.062424,0.009675,0.000923,0.023441,8.856738,0.451184,0.234406,-76.062424,0.024299,0.000000
29.010002,2.010811,-76.062424,0.009684,0.000937,0.023787,8.944533,0.455656,0.237873,-76.062424,0.024629,0.000000
29.210001,2.029060,-76.151390,0.009710,0.000950,0.024126,9.025711,0.459792,0.241257,-76.151390,0.024967,0.000000
29.410002,2.077469,-76.151390,0.009718,0.000963,0.024464,9.241043,0.470761,0.244640,-76.151390,0.025297,0.000000
29.610001,2.078209,-76.151390,0.009735,0.000975,0.024759,9.244335,0.470929,0.247593,-76.151390,0.025635,0.000000
29.810001,2.137047,-76.106911,0.009753,0.000987,0.025063,9.506059,0.484262,0.250628,-76.106911,0.025964,0.000000
30.010002,2.123642,-76.195869,0.009766,0.000997,0.025314,9.446431,0.481224,0.253141,-76.195869,0.026294,0.000000
30.210001,2.263649,-76.151390,0.009783,0.001011,0.025678,10.069214,0.512950,0.256782,-76.151390,0.026632,0.000000
30.410002,2.312057,-76.151390,0.009800,0.001028,0.026120,10.284545,0.523920,0.261203,-76.151390,0.026962,0.000000
30.610001,2.381325,-76.195869,0.009817,0.001047,0.026589,10.592662,0.539616,0.265889,-76.195869,0.027300,0.000000
30.810001,2.278175,-76.195869,0.009839,0.001058,0.026883,10.133830,0.516242,0.268834,-76.195869,0.027630,0.000000
31.010002,2.288971,-76.151390,0.009843,0.001069,0.027144,10.181851,0.518688,0.271438,-76.151390,0.027967,0.000000
31.210001,2.342224,-76.151390,0.009856,0.001081,0.027465,10.418734,0.530756,0.274647,-76.151390,0.028297,0.000000
31.410002,2.379456,-76.195869,0.009873,0.001094,0.027786,10.584347,0.539192,0.277857,-76.195869,0.028636,0.000000
31.610001,2.422279,-76.195869,0.009899,0.001107,0.028107,10.774837,0.548896,0.281066,-76.195869,0.028965,0.000000
31.810001,2.499733,-76.195869,0.009904,0.001120,0.028445,11.119368,0.566448,0.284450,-76.195869,0.029294,0.000000
32.010002,2.461006,-76.195869,0.009921,0.001129,0.028670,10.947103,0.557672,0.286698,-76.195869,0.029633,0.000000
32.210003,2.668045,-76.195869,0.009942,0.001145,0.029086,11.868057,0.604588,0.290862,-76.195869,0.029962,0.000000
32.410000,2.711990,-76.240349,0.009947,0.001162,0.029512,12.063536,0.614546,0.295116,-76.240349,0.030300,0.000000
32.610001,2.732468,-76.240349,0.009964,0.001176,0.029876,12.154623,0.619186,0.298757,-76.240349,0.030630,0.000000
32.810001,2.689270,-76.284828,0.009985,0.001188,0.030170,11.962470,0.609397,0.301702,-76.284828,0.030968,0.000000
33.010002,2.822586,-76.240349,0.010003,0.001202,0.030543,12.555490,0.639607,0.305433,-76.240349,0.031298,0.000000
33.210003,2.678101,-76.240349,0.010007,0.001209,0.030708,11.912786,0.606866,0.307084,-76.240349,0.031636,0.000000
33.410000,2.948441,-76.240349,0.010024,0.001230,0.031254,13.115318,0.668126,0.312541,-76.240349,0.031966,0.000000
33.610001,2.905624,-76.284828,0.010054,0.001242,0.031540,12.924863,0.658424,0.315403,-76.284828,0.032295,0.000000
33.810001,2.815506,-76.284828,0.010059,0.001248,0.031705,12.523996,0.638003,0.317053,-76.284828,0.032633,0.000000
34.010002,3.046005,-76.284828,0.010076,0.001266,0.032147,13.549308,0.690235,0.321474,-76.284828,0.032963,0.000000
34.210003,3.023666,-76.329315,0.010093,0.001275,0.032373,13.449940,0.685173,0.323730,-76.329315,0.033301,0.000000
34.410000,3.221390,-76.329315,0.010102,0.001296,0.032929,14.329457,0.729977,0.329286,-76.329315,0.033630,0.000000
34.610001,3.111168,-76.329315,0.010115,0.001305,0.033153,13.839166,0.705001,0.331534,-76.329315,0.033969,0.000000
34.810001,3.186760,-76.329315,0.010132,0.001317,0.033449,14.175416,0.722130,0.334486,-76.329315,0.034299,0.000000
35.010002,3.197563,-76.284828,0.010145,0.001327,0.033717,14.223472,0.724578,0.337174,-76.284828,0.034628,0.000000
35.210003,3.341301,-76.329315,0.010171,0.001341,0.034073,14.862849,0.757150,0.340731,-76.329315,0.034966,0.000000
35.410000,3.393433,-76.284828,0.010179,0.001357,0.034472,15.094742,0.768963,0.344721,-76.284828,0.035296,0.000000
35.610001,3.594513,-76.329315,0.010201,0.001370,0.034810,15.989192,0.814528,0.348104,-76.329315,0.035634,0.000000
35.810001,3.366249,-76.284828,0.010205,0.001375,0.034914,14.973824,0.762803,0.349141,-76.284828,0.035963,0.000000
36.010002,3.751282,-76.329315,0.010210,0.001393,0.035374,16.686535,0.850053,0.353736,-76.329315,0.036302,0.000000
36.210003,3.755379,-76.329315,0.010231,0.001407,0.035738,16.704760,0.850981,0.357377,-76.329315,0.036631,0.000000
36.410000,3.906555,-76.373795,0.010248,0.001427,0.036241,17.377226,0.885238,0.362411,-76.373795,0.036969,0.000000
36.610001,3.744949,-76.329315,0.010266,0.001434,0.036414,16.658367,0.848618,0.364145,-76.329315,0.037299,0.000000
36.810001,3.907303,-76.418274,0.010292,0.001448,0.036779,17.380550,0.885408,0.367786,-76.418274,0.037629,0.000000
37.010002,3.925919,-76.373795,0.010292,0.001458,0.037022,17.463358,0.889626,0.370216,-76.373795,0.037967,0.000000
37.210003,4.034279,-76.373795,0.010300,0.001471,0.037360,17.945368,0.914181,0.373599,-76.373795,0.038296,0.000000
37.410004,4.234619,-76.373795,0.010330,0.001484,0.037681,18.836527,0.959578,0.376809,-76.373795,0.038635,0.000000
37.610001,4.354897,-76.373795,0.010352,0.001497,0.038028,19.371548,0.986834,0.380276,-76.373795,0.038964,0.000000
37.810001,4.169456,-76.373795,0.010348,0.001501,0.038131,18.546669,0.944812,0.381313,-76.373795,0.039302,0.000000
38.010002,4.961861,-76.418274,0.010365,0.001528,0.038816,22.071459,1.124374,0.388164,-76.418274,0.039632,0.000000
38.210003,4.656891,-76.418274,0.010374,0.001538,0.039059,20.714886,1.055267,0.390594,-76.418274,0.039962,0.000000
38.410004,4.992393,-76.373795,0.010391,0.001556,0.039519,22.207275,1.131292,0.395188,-76.373795,0.040299,0.000000
38.610001,4.937286,-76.418274,0.010417,0.001566,0.039788,21.962147,1.118805,0.397883,-76.418274,0.040629,0.000000
38.810001,5.140602,-76.373795,0.010417,0.001579,0.040100,22.866541,1.164877,0.401002,-76.373795,0.040968,0.000000
39.010002,5.297745,-76.418274,0.010447,0.001592,0.040439,23.565546,1.200486,0.404386,-76.418274,0.041297,0.000000
39.210003,5.391579,-76.418274,0.010451,0.001604,0.040733,23.982941,1.221749,0.407330,-76.418274,0.041635,0.000000
39.410004,5.661919,-76.462753,0.010464,0.001616,0.041037,25.185472,1.283009,0.410366,-76.462753,0.041965,0.000000
39.610001,5.784805,-76.462753,0.010473,0.001627,0.041323,25.732100,1.310856,0.413227,-76.462753,0.042303,0.000000
39.810001,6.079353,-76.418274,0.010477,0.001640,0.041661,27.042315,1.377601,0.416611,-76.418274,0.042632,0.000000
40.010002,6.227928,-76.507233,0.010490,0.001655,0.042043,27.703209,1.411269,0.420426,-76.507233,0.042962,0.000000
40.210003,6.514656,-76.462753,0.010507,0.001669,0.042389,28.978638,1.476242,0.423893,-76.462753,0.043300,0.000000
40.410004,6.821861,-76.507233,0.010529,0.001686,0.042832,30.345154,1.545856,0.428321,-76.507233,0.043630,0.000000
40.610001,6.832664,-76.462753,0.010533,0.001697,0.043092,30.393209,1.548304,0.430918,-76.462753,0.043968,0.000000
40.810001,7.015869,-76.507233,0.010546,0.001709,0.043413,31.208145,1.589819,0.434127,-76.507233,0.044298,0.000000
41.010002,6.993156,-76.462753,0.010555,0.001718,0.043647,31.107113,1.584672,0.436474,-76.462753,0.044636,0.000000
41.210003,7.520058,-76.551720,0.010568,0.001732,0.043985,33.450886,1.704069,0.439850,-76.551720,0.044965,0.000000
41.410004,8.084206,-76.507233,0.010576,0.001749,0.044428,35.960342,1.831907,0.444279,-76.507233,0.045304,0.000000
41.610001,7.888710,-76.551720,0.010593,0.001755,0.044566,35.090736,1.787607,0.445664,-76.551720,0.045633,0.000000
41.810001,8.227196,-76.507233,0.010598,0.001767,0.044878,36.596394,1.864309,0.448783,-76.507233,0.045962,0.000000
42.010002,8.872147,-76.507233,0.010615,0.001784,0.045304,39.465279,2.010457,0.453037,-76.507233,0.046301,0.000000
42.210003,9.263138,-76.507233,0.010615,0.001799,0.045703,41.204494,2.099057,0.457026,-76.507233,0.046631,0.000000
42.410004,9.372612,-76.551720,0.010641,0.001812,0.046032,41.691460,2.123864,0.460319,-76.551720,0.046968,0.000000
42.610001,10.047356,-76.596199,0.010632,0.001829,0.046457,44.692871,2.276763,0.464573,-76.596199,0.047298,0.000000
42.810001,10.055916,-76.507233,0.010649,0.001838,0.046674,44.730949,2.278703,0.466738,-76.507233,0.047637,0.000000
43.010002,10.449890,-76.507233,0.010658,0.001852,0.047038,46.483433,2.367979,0.470379,-76.507233,0.047966,0.000000
43.210003,11.301132,-76.551720,0.010671,0.001869,0.047463,50.269947,2.560873,0.474626,-76.551720,0.048295,0.000000
43.410004,11.418427,-76.551720,0.010684,0.001877,0.047680,50.791698,2.587452,0.476798,-76.551720,0.048634,0.000000
43.610001,11.297783,-76.596199,0.010680,0.001882,0.047810,50.255047,2.560114,0.478100,-76.596199,0.048963,0.000000
43.810001,11.999329,-76.640678,0.010697,0.001897,0.048174,53.375679,2.719087,0.481741,-76.640678,0.049301,0.000000
44.010002,13.047188,-76.551720,0.010701,0.001917,0.048686,58.036789,2.956535,0.486859,-76.551720,0.049631,0.000000
44.210003,13.881676,-76.596199,0.010710,0.001935,0.049145,61.748779,3.145633,0.491453,-76.596199,0.049969,0.000000
44.410004,14.011627,-76.685158,0.010731,0.001944,0.049371,62.326832,3.175080,0.493709,-76.685158,0.050299,0.000000
44.610001,14.508003,-76.640678,0.010736,0.001958,0.049735,64.534821,3.287560,0.497350,-76.640678,0.050637,0.000000
44.810001,14.867340,-76.596199,0.010749,0.001969,0.050021,66.133232,3.368987,0.500212,-76.596199,0.050967,0.000000
45.010002,15.410637,-76.640678,0.010749,0.001982,0.050334,68.549934,3.492100,0.503338,-76.640678,0.051296,0.000000
45.210003,16.372475,-76.596199,0.010757,0.001998,0.050741,72.828407,3.710056,0.507411,-76.596199,0.051634,0.000000
45.410004,16.932144,-76.640678,0.010770,0.002008,0.051001,75.317940,3.836879,0.510015,-76.640678,0.051964,0.000000
45.610001,17.209190,-76.685158,0.010770,0.002017,0.051227,76.550301,3.899658,0.512270,-76.685158,0.052302,0.000000
45.810001,17.769989,-76.640678,0.010774,0.002032,0.051617,79.044861,4.026737,0.516169,-76.640678,0.052631,0.000000
46.010002,19.897720,-76.729637,0.010787,0.002056,0.052224,88.509483,4.508888,0.522240,-76.729637,0.052970,0.000000
46.210003,20.185196,-76.685158,0.010796,0.002065,0.052450,89.788239,4.574031,0.524496,-76.685158,0.053300,0.000000
46.410004,20.718430,-76.729637,0.010805,0.002078,0.052788,92.160179,4.694863,0.527879,-76.729637,0.053637,0.000000
46.610001,21.442322,-76.685158,0.010800,0.002090,0.053091,95.380211,4.858900,0.530915,-76.685158,0.053967,0.000000
46.810001,21.835548,-76.685158,0.010818,0.002099,0.053308,97.129372,4.948006,0.533080,-76.685158,0.054297,0.000000
47.010002,23.105713,-76.729637,0.010822,0.002117,0.053759,102.779343,5.235829,0.537591,-76.729637,0.054635,0.000000
47.210003,23.736511,-76.729637,0.010831,0.002127,0.054028,105.585274,5.378770,0.540279,-76.729637,0.054964,0.000000
47.410004,24.593712,-76.685158,0.010835,0.002137,0.054288,109.398293,5.573015,0.542883,-76.685158,0.055303,0.000000
47.610001,25.339943,-76.685158,0.010839,0.002149,0.054574,112.717697,5.742113,0.545744,-76.685158,0.055632,0.000000
47.810001,26.810074,-76.685158,0.010848,0.002169,0.055086,119.257164,6.075250,0.550861,-76.685158,0.055970,0.000000
48.010002,27.862022,-76.685158,0.010843,0.002184,0.055468,123.936462,6.313625,0.554676,-76.685158,0.056300,0.000000
48.210003,28.549797,-76.729637,0.010839,0.002195,0.055754,126.995842,6.469476,0.557538,-76.729637,0.056630,0.000000
48.410004,29.510887,-76.729637,0.010861,0.002207,0.056048,131.270981,6.687263,0.560482,-76.729637,0.056968,0.000000
48.610001,30.494324,-76.774124,0.010848,0.002219,0.056369,135.645523,6.910113,0.563692,-76.774124,0.057297,0.000000
48.810001,31.472176,-76.818604,0.010865,0.002232,0.056682,139.995224,7.131697,0.566818,-76.818604,0.057636,0.000000
49.010002,32.833199,-76.729637,0.010856,0.002249,0.057124,146.049362,7.440109,0.571239,-76.729637,0.057965,0.000000
49.210003,33.437553,-76.729637,0.010874,0.002260,0.057410,148.737671,7.577058,0.574100,-76.729637,0.058303,0.000000
49.410004,34.137993,-76.818604,0.010874,0.002269,0.057627,151.853378,7.735780,0.576265,-76.818604,0.058633,0.000000
49.610001,35.571625,-76.774124,0.010882,0.002286,0.058052,158.230484,8.060645,0.580520,-76.774124,0.058971,0.000000
49.810001,36.784065,-76.818604,0.010908,0.002301,0.058442,163.623688,8.335388,0.584418,-76.818604,0.059300,0.000000
50.010002,38.012527,-76.774124,0.010900,0.002313,0.058763,169.088165,8.613762,0.587628,-76.774124,0.059630,0.000000
50.210003,38.683167,-76.685158,0.010887,0.002322,0.058971,172.071320,8.765731,0.589709,-76.685158,0.059969,0.000000
50.410004,39.958542,-76.818604,0.010895,0.002337,0.059370,177.744476,9.054735,0.593699,-76.818604,0.060298,0.000000
50.610001,41.092049,-76.818604,0.010904,0.002350,0.059699,182.786560,9.311591,0.596991,-76.818604,0.060636,0.000000
50.810001,42.346199,-76.818604,0.010895,0.002366,0.060098,188.365295,9.595786,0.600981,-76.818604,0.060966,0.000000
51.010002,43.495712,-76.774124,0.010908,0.002378,0.060402,193.478592,9.856269,0.604016,-76.774124,0.061304,0.000000
51.210003,44.295197,-76.818604,0.010908,0.002386,0.060592,197.034882,10.037435,0.605924,-76.818604,0.061633,0.000000
51.410004,45.228729,-76.774124,0.010895,0.002399,0.060931,201.187439,10.248977,0.609308,-76.774124,0.061963,0.000000
51.610001,46.621407,-76.863083,0.010904,0.002412,0.061269,207.382370,10.564561,0.612691,-76.863083,0.062301,0.000000
51.810001,48.269150,-76.863083,0.010912,0.002430,0.061729,214.711899,10.937945,0.617286,-76.863083,0.062631,0.000000
52.010002,50.009995,-76.818604,0.010904,0.002448,0.062171,222.455566,11.332427,0.621714,-76.818604,0.062969,0.000000
52.210003,51.077583,-76.818604,0.010904,0.002458,0.062431,227.204437,11.574346,0.624311,-76.818604,0.063299,0.000000
52.410004,52.020058,-76.863083,0.010917,0.002469,0.062709,231.396774,11.787913,0.627089,-76.863083,0.063637,0.000000
52.610001,53.239204,-76.863083,0.010912,0.002480,0.062995,236.819809,12.064177,0.629950,-76.863083,0.063966,0.000000
52.810001,54.370102,-76.863083,0.010921,0.002493,0.063316,241.850296,12.320441,0.633160,-76.863083,0.064305,0.000000
53.010002,55.689789,-76.907562,0.010904,0.002506,0.063654,247.720551,12.619486,0.636544,-76.907562,0.064634,0.000000
53.210003,57.009109,-76.907562,0.010925,0.002519,0.063975,253.589188,12.918449,0.639746,-76.907562,0.064963,0.000000
53.410004,58.355980,-76.952042,0.010912,0.002534,0.064373,259.580353,13.223654,0.643735,-76.952042,0.065302,0.000000
53.610004,59.398247,-76.907562,0.010921,0.002544,0.064608,264.216583,13.459835,0.646082,-76.907562,0.065632,0.000000
53.810001,61.339798,-76.907562,0.010925,0.002563,0.065093,272.853058,13.899796,0.650934,-76.907562,0.065969,0.000000
54.010002,62.592834,-76.863083,0.010917,0.002575,0.065414,278.426819,14.183740,0.654143,-76.863083,0.066299,0.000000
54.210003,63.705482,-76.863083,0.010925,0.002587,0.065710,283.376129,14.435868,0.657096,-76.863083,0.066638,0.000000
54.410004,65.252312,-76.907562,0.010934,0.002602,0.066091,290.256775,14.786386,0.660911,-76.907562,0.066967,0.000000
54.610004,65.964668,-76.996529,0.010930,0.002608,0.066239,293.425507,14.947807,0.662387,-76.996529,0.067305,0.000000
54.810001,67.719276,-76.952042,0.010930,0.002619,0.066525,301.230377,15.345407,0.665248,-76.952042,0.066707,0.000000
55.010002,67.482826,-76.996529,0.010934,0.002618,0.066490,300.178589,15.291827,0.664900,-76.996529,0.066707,0.000000
55.210003,67.393822,-76.952042,0.010921,0.002617,0.066481,299.782684,15.271658,0.664809,-76.952042,0.066490,0.000000
55.410004,67.257164,-76.907562,0.010947,0.002617,0.066464,299.174805,15.240691,0.664635,-76.907562,0.066490,0.000000
55.610004,67.159599,-76.907562,0.010925,0.002616,0.066455,298.740814,15.218582,0.664552,-76.907562,0.066490,0.000000
55.810001,67.051613,-76.952042,0.010934,0.002616,0.066455,298.260468,15.194113,0.664552,-76.952042,0.066490,0.000000
56.010002,66.961876,-76.952042,0.010947,0.002616,0.066447,297.861298,15.173778,0.664469,-76.952042,0.066490,0.000000
56.210003,66.886665,-76.996529,0.010938,0.002616,0.066447,297.526733,15.156735,0.664469,-76.996529,0.066490,0.000000
56.410004,66.817024,-76.907562,0.010925,0.002616,0.066447,297.216980,15.140955,0.664469,-76.907562,0.066490,0.000000
56.610004,66.745155,-76.952042,0.010951,0.002616,0.066438,296.897278,15.124669,0.664378,-76.952042,0.066490,0.000000
56.810001,66.687431,-76.952042,0.010934,0.002616,0.066438,296.640503,15.111588,0.664378,-76.952042,0.066490,0.000000
57.010002,66.629723,-76.952042,0.010938,0.002616,0.066438,296.383820,15.098511,0.664378,-76.952042,0.066490,0.000000
57.210003,66.562691,-76.996529,0.010938,0.002616,0.066438,296.085632,15.083322,0.664378,-76.996529,0.066490,0.000000
57.410004,66.522102,-76.952042,0.010951,0.002616,0.066438,295.905090,15.074124,0.664378,-76.952042,0.066490,0.000000
57.610004,66.503853,-77.041008,0.010947,0.002616,0.066438,295.823914,15.069988,0.664378,-77.041008,0.066490,0.000000
57.810001,66.453957,-76.907562,0.010934,0.002615,0.066429,295.601959,15.058681,0.664294,-76.907562,0.066490,0.000000
58.010002,66.392891,-76.996529,0.010930,0.002615,0.066429,295.330322,15.044844,0.664294,-76.996529,0.066490,0.000000
58.210003,66.358269,-76.952042,0.010951,0.002615,0.066429,295.176331,15.036999,0.664294,-76.952042,0.066490,0.000000
58.410004,66.331078,-77.041008,0.010938,0.002615,0.066429,295.055359,15.030837,0.664294,-77.041008,0.066490,0.000000
58.610004,66.300179,-77.041008,0.010930,0.002615,0.066429,294.917938,15.023836,0.664294,-77.041008,0.066490,0.000000
58.810001,66.262184,-76.996529,0.010934,0.002615,0.066429,294.748901,15.015226,0.664294,-76.996529,0.066490,0.000000
59.010002,66.244682,-77.041008,0.010938,0.002615,0.066429,294.671051,15.011259,0.664294,-77.041008,0.066490,0.000000
59.210003,66.203728,-76.996529,0.010934,0.002615,0.066429,294.488892,15.001980,0.664294,-76.996529,0.066490,0.000000
59.410004,66.170952,-77.041008,0.010943,0.002615,0.066429,294.343109,14.994552,0.664294,-77.041008,0.066490,0.000000
59.610004,66.150475,-76.996529,0.010943,0.002615,0.066429,294.252014,14.989912,0.664294,-76.996529,0.066490,0.000000
59.810001,66.126640,-77.085487,0.010938,0.002615,0.066429,294.145996,14.984511,0.664294,-77.085487,0.066490,0.000000
60.010002,66.100945,-77.129967,0.010943,0.002615,0.066429,294.031677,14.978688,0.664294,-77.129967,0.066490,0.000000
60.210003,66.076378,-77.085487,0.010938,0.002615,0.066429,293.922394,14.973121,0.664294,-77.085487,0.066490,0.000000
60.410004,66.051048,-77.085487,0.010938,0.002615,0.066429,293.809723,14.967381,0.664294,-77.085487,0.066490,0.000000
60.610004,66.033928,-77.041008,0.010951,0.002615,0.066429,293.733582,14.963503,0.664294,-77.041008,0.066490,0.000000
60.810001,66.020515,-77.041008,0.010938,0.002615,0.066429,293.673920,14.960464,0.664294,-77.041008,0.066490,0.000000
61.010002,65.986259,-77.085487,0.010947,0.002615,0.066429,293.521545,14.952700,0.664294,-77.085487,0.066490,0.000000
61.210003,65.951637,-77.085487,0.010943,0.002615,0.066429,293.367523,14.944855,0.664294,-77.085487,0.066490,0.000000
61.410004,65.946785,-77.041008,0.010938,0.002615,0.066429,293.345947,14.943755,0.664294,-77.041008,0.066490,0.000000
61.610004,65.925941,-77.085487,0.010956,0.002615,0.066429,293.253235,14.939032,0.664294,-77.085487,0.066490,0.000000
61.810001,65.904716,-77.129967,0.010943,0.002615,0.066429,293.158813,14.934223,0.664294,-77.129967,0.066490,0.000000
62.010002,65.885353,-77.129967,0.010943,0.002615,0.066429,293.072693,14.929834,0.664294,-77.129967,0.066490,0.000000
62.210003,65.877907,-77.129967,0.010943,0.002615,0.066429,293.039551,14.928147,0.664294,-77.129967,0.066490,0.000000
62.410004,65.859276,-77.085487,0.010943,0.002615,0.066429,292.956696,14.923925,0.664294,-77.085487,0.066490,0.000000
62.610004,65.831352,-77.085487,0.010943,0.002615,0.066429,292.832489,14.917598,0.664294,-77.085487,0.066490,0.000000
62.810001,65.817207,-77.085487,0.010960,0.002615,0.066429,292.769562,14.914392,0.664294,-77.085487,0.066490,0.000000
63.010002,65.812370,-77.041008,0.010938,0.002615,0.066429,292.748047,14.913296,0.664294,-77.041008,0.066490,0.000000
63.210003,65.785927,-77.129967,0.010943,0.002615,0.066429,292.630432,14.907305,0.664294,-77.129967,0.066490,0.000000
63.410004,65.761345,-77.129967,0.010934,0.002615,0.066429,292.521057,14.901734,0.664294,-77.129967,0.066490,0.000000
63.610004,65.753899,-77.174454,0.010943,0.002615,0.066429,292.487946,14.900046,0.664294,-77.174454,0.066490,0.000000
63.810001,65.744225,-77.174454,0.010943,0.002615,0.066429,292.444916,14.897855,0.664294,-77.174454,0.066490,0.000000
64.010002,65.736397,-77.174454,0.010947,0.002615,0.066429,292.410095,14.896081,0.664294,-77.174454,0.066490,0.000000
64.210007,65.712563,-77.174454,0.010938,0.002615,0.066429,292.304077,14.890679,0.664294,-77.174454,0.066490,0.000000
64.410004,65.700645,-77.174454,0.010943,0.002615,0.066429,292.251068,14.887980,0.664294,-77.174454,0.066490,0.000000
64.610001,65.695061,-77.129967,0.010943,0.002615,0.066429,292.226227,14.886714,0.664294,-77.129967,0.066490,0.000000
64.810005,65.677940,-77.174454,0.010943,0.002615,0.066429,292.150055,14.882834,0.664294,-77.174454,0.066490,0.000000
65.010002,65.665642,-77.174454,0.010930,0.002615,0.066429,292.095367,14.880048,0.664294,-77.174454,0.066490,0.000000
65.210007,65.647026,-77.218933,0.010943,0.002615,0.066429,292.012543,14.875829,0.664294,-77.218933,0.066490,0.000000
65.410004,65.644051,-77.174454,0.010943,0.002615,0.066429,291.999329,14.875154,0.664294,-77.174454,0.066490,0.000000
65.610001,65.627296,-77.218933,0.010951,0.002615,0.066429,291.924805,14.871358,0.664294,-77.218933,0.066490,0.000000
65.810005,65.618736,-77.218933,0.010947,0.002615,0.066429,291.886719,14.869418,0.664294,-77.218933,0.066490,0.000000
66.010002,65.615379,-77.218933,0.010943,0.002615,0.066429,291.871796,14.868657,0.664294,-77.218933,0.066490,0.000000
66.210007,65.604958,-77.174454,0.010938,0.002615,0.066429,291.825439,14.866296,0.664294,-77.174454,0.066490,0.000000
66.410004,65.585594,-77.174454,0.010943,0.002615,0.066429,291.739288,14.861908,0.664294,-77.174454,0.066490,0.000000
66.610001,65.571068,-77.263412,0.010947,0.002615,0.066429,291.674683,14.858616,0.664294,-77.263412,0.066490,0.000000
66.810005,65.578148,-77.263412,0.010943,0.002615,0.066429,291.706177,14.860221,0.664294,-77.263412,0.066490,0.000000
67.010002,65.567711,-77.263412,0.010947,0.002615,0.066429,291.659760,14.857855,0.664294,-77.263412,0.066490,0.000000
67.210007,65.553185,-77.263412,0.010943,0.002615,0.066429,291.595123,14.854565,0.664294,-77.263412,0.066490,0.000000
67.410004,65.536812,-77.218933,0.010943,0.002615,0.066429,291.522308,14.850854,0.664294,-77.218933,0.066490,0.000000
67.610001,65.531593,-77.218933,0.010947,0.002615,0.066429,291.499084,14.849671,0.664294,-77.218933,0.066490,0.000000
67.810005,65.527122,-77.263412,0.010947,0.002615,0.066429,291.479187,14.848658,0.664294,-77.263412,0.066490,0.000000
68.010002,65.529366,-77.218933,0.010943,0.002615,0.066429,291.489166,14.849166,0.664294,-77.218933,0.066490,0.000000
68.210007,65.511482,-77.263412,0.010934,0.002615,0.066429,291.409637,14.845114,0.664294,-77.263412,0.066490,0.000000
68.410004,65.494728,-77.263412,0.010938,0.002615,0.066429,291.335114,14.841318,0.664294,-77.263412,0.066490,0.000000
68.610001,65.493980,-77.263412,0.010943,0.002615,0.066429,291.331787,14.841148,0.664294,-77.263412,0.066490,0.000000
68.810005,65.492500,-77.263412,0.010925,0.002615,0.066429,291.325195,14.840813,0.664294,-77.263412,0.066490,0.000000
69.010002,65.474251,-77.263412,0.010934,0.002615,0.066429,291.244019,14.836677,0.664294,-77.263412,0.066490,0.000000
69.210007,65.468666,-77.263412,0.010934,0.002615,0.066429,291.219177,14.835411,0.664294,-77.263412,0.066490,0.000000
69.410004,65.466805,-77.218933,0.010938,0.002615,0.066429,291.210876,14.834991,0.664294,-77.218933,0.066490,0.000000
69.610001,65.457863,-77.263412,0.010943,0.002615,0.066429,291.171112,14.832964,0.664294,-77.263412,0.066490,0.000000
69.810005,65.441856,-77.307892,0.010938,0.002615,0.066429,291.099915,14.829336,0.664294,-77.307892,0.066490,0.000000
70.010002,65.422493,-77.307892,0.010930,0.002615,0.066429,291.013794,14.824948,0.664294,-77.307892,0.066490,0.000000
70.210007,65.428444,-77.307892,0.010943,0.002615,0.066429,291.040253,14.826298,0.664294,-77.307892,0.066490,0.000000
70.410004,65.414299,-77.352371,0.010943,0.002615,0.066429,290.977325,14.823092,0.664294,-77.352371,0.066490,0.000000
70.610001,65.420631,-77.307892,0.010947,0.002615,0.066429,291.005493,14.824528,0.664294,-77.307892,0.066490,0.000000
70.810005,65.406471,-77.263412,0.010951,0.002615,0.066429,290.942505,14.821319,0.664294,-77.263412,0.066490,0.000000
71.010002,65.412056,-77.307892,0.010943,0.002615,0.066429,290.967346,14.822584,0.664294,-77.307892,0.066490,0.000000
71.210007,65.404243,-77.307892,0.010938,0.002615,0.066429,290.932617,14.820813,0.664294,-77.307892,0.066490,0.000000
71.410004,65.399025,-77.352371,0.010934,0.002615,0.066429,290.909393,14.819631,0.664294,-77.352371,0.066490,0.000000
71.610001,65.375572,-77.352371,0.010938,0.002615,0.066429,290.805084,14.814316,0.664294,-77.352371,0.066490,0.000000
71.810005,65.379662,-77.352371,0.010943,0.002615,0.066429,290.823273,14.815243,0.664294,-77.352371,0.066490,0.000000
72.010002,65.372963,-77.441338,0.010925,0.002615,0.066429,290.793457,14.813725,0.664294,-77.441338,0.066490,0.000000
72.210007,65.357704,-77.396858,0.010951,0.002615,0.066429,290.725586,14.810267,0.664294,-77.396858,0.066490,0.000000
72.410004,65.347267,-77.396858,0.010938,0.002615,0.066429,290.679169,14.807902,0.664294,-77.396858,0.066490,0.000000
72.610001,65.351372,-77.441338,0.010938,0.002615,0.066429,290.697418,14.808832,0.664294,-77.441338,0.066490,0.000000
72.810005,65.336464,-77.396858,0.010947,0.002615,0.066429,290.631104,14.805454,0.664294,-77.396858,0.066490,0.000000
73.010002,65.338707,-77.396858,0.010947,0.002615,0.066429,290.641083,14.805963,0.664294,-77.396858,0.066490,0.000000
73.210007,65.343925,-77.441338,0.010943,0.002615,0.066429,290.664307,14.807145,0.664294,-77.441338,0.066490,0.000000
73.410004,65.329765,-77.441338,0.010938,0.002615,0.066429,290.601318,14.803937,0.664294,-77.441338,0.066490,0.000000
73.610001,65.317482,-77.441338,0.010943,0.002615,0.066429,290.546661,14.801153,0.664294,-77.441338,0.066490,0.000000
73.810005,65.311897,-77.441338,0.010938,0.002615,0.066429,290.521820,14.799888,0.664294,-77.441338,0.066490,0.000000
74.010002,65.291039,-77.396858,0.010943,0.002615,0.066429,290.429047,14.795160,0.664294,-77.396858,0.066490,0.000000
74.210007,65.289925,-77.396858,0.010943,0.002615,0.066429,290.424103,14.794909,0.664294,-77.396858,0.066490,0.000000
74.410004,65.289558,-77.441338,0.010943,0.002615,0.066429,290.422455,14.794826,0.664294,-77.441338,0.066490,0.000000
74.610001,65.278008,-77.441338,0.010938,0.002615,0.066429,290.371094,14.792209,0.664294,-77.441338,0.066490,0.000000
74.810005,65.273170,-77.441338,0.010947,0.002615,0.066429,290.349548,14.791112,0.664294,-77.441338,0.066490,0.000000
75.010002,65.257896,-77.441338,0.010938,0.002615,0.066429,290.281616,14.787651,0.664294,-77.441338,0.066490,0.000000
75.210007,65.248589,-77.441338,0.010947,0.002615,0.066429,290.240204,14.785542,0.664294,-77.441338,0.066490,0.000000
75.410004,65.242638,-77.485817,0.010943,0.002615,0.066429,290.213745,14.784193,0.664294,-77.485817,0.066490,0.000000
75.610001,65.239281,-77.530296,0.010943,0.002615,0.066429,290.198822,14.783432,0.664294,-77.530296,0.066490,0.000000
75.810005,65.240395,-77.485817,0.010934,0.002615,0.066429,290.203766,14.783685,0.664294,-77.485817,0.066490,0.000000
76.010002,65.227364,-77.485817,0.010943,0.002615,0.066429,290.145813,14.780732,0.664294,-77.485817,0.066490,0.000000
76.210007,65.211723,-77.485817,0.010947,0.002615,0.066429,290.076233,14.777188,0.664294,-77.485817,0.066490,0.000000
76.410004,65.225502,-77.485817,0.010934,0.002615,0.066429,290.137512,14.780310,0.664294,-77.485817,0.066490,0.000000
76.610001,65.214333,-77.485817,0.010938,0.002615,0.066429,290.087830,14.777779,0.664294,-77.485817,0.066490,0.000000
76.810005,65.203911,-77.530296,0.010934,0.002615,0.066429,290.041473,14.775417,0.664294,-77.530296,0.066490,0.000000
77.010002,65.201668,-77.530296,0.010938,0.002615,0.066429,290.031494,14.774909,0.664294,-77.530296,0.066490,0.000000
77.210007,65.180824,-77.485817,0.010947,0.002615,0.066429,289.938782,14.770185,0.664294,-77.485817,0.066490,0.000000
77.410004,65.184166,-77.530296,0.010943,0.002615,0.066429,289.953644,14.770943,0.664294,-77.530296,0.066490,0.000000
77.610001,65.187157,-77.574776,0.010943,0.002615,0.066429,289.966949,14.771621,0.664294,-77.574776,0.066490,0.000000
77.810005,65.177467,-77.574776,0.010943,0.002615,0.066429,289.923859,14.769425,0.664294,-77.574776,0.066490,0.000000
78.010002,65.161827,-77.530296,0.010947,0.002615,0.066429,289.854279,14.765881,0.664294,-77.530296,0.066490,0.000000
78.210007,65.169655,-77.530296,0.010943,0.002615,0.066429,289.889099,14.767654,0.664294,-77.530296,0.066490,0.000000
78.410004,65.164070,-77.530296,0.010943,0.002615,0.066429,289.864258,14.766389,0.664294,-77.530296,0.066490,0.000000
78.610001,65.151405,-77.619263,0.010938,0.002615,0.066429,289.807922,14.763519,0.664294,-77.619263,0.066490,0.000000
78.810005,65.137993,-77.574776,0.010943,0.002615,0.066429,289.748260,14.760480,0.664294,-77.574776,0.066490,0.000000
79.010002,65.145073,-77.574776,0.010947,0.002615,0.066429,289.779755,14.762084,0.664294,-77.574776,0.066490,0.000000
79.210007,65.150658,-77.574776,0.010951,0.002615,0.066429,289.804596,14.763350,0.664294,-77.574776,0.066490,0.000000
79.410004,65.130547,-77.530296,0.010951,0.002615,0.066429,289.715149,14.758793,0.664294,-77.530296,0.066490,0.000000
79.610001,65.123848,-77.619263,0.010938,0.002615,0.066429,289.685333,14.757275,0.664294,-77.619263,0.066490,0.000000
79.810005,65.115288,-77.619263,0.010934,0.002615,0.066429,289.647278,14.755335,0.664294,-77.619263,0.066490,0.000000
80.010002,65.132408,-77.574776,0.010947,0.002615,0.066429,289.723419,14.759214,0.664294,-77.574776,0.066490,0.000000
80.210007,65.116402,-77.574776,0.010925,0.002615,0.066429,289.652222,14.755588,0.664294,-77.574776,0.066490,0.000000
80.410004,65.100761,-77.619263,0.010943,0.002615,0.066429,289.582642,14.752044,0.664294,-77.619263,0.066490,0.000000
80.610001,65.102623,-77.663742,0.010947,0.002615,0.066429,289.590942,14.752465,0.664294,-77.663742,0.066490,0.000000
80.810005,65.101128,-77.663742,0.010943,0.002615,0.066429,289.584290,14.752126,0.664294,-77.663742,0.066490,0.000000
81.010002,65.085121,-77.619263,0.010947,0.002615,0.066429,289.513092,14.748499,0.664294,-77.619263,0.066490,0.000000
81.210007,65.086617,-77.708221,0.010938,0.002615,0.066429,289.519745,14.748837,0.664294,-77.708221,0.066490,0.000000
81.410004,65.092201,-77.619263,0.010938,0.002615,0.066429,289.544586,14.750103,0.664294,-77.619263,0.066490,0.000000
81.610001,65.091820,-77.663742,0.010947,0.002615,0.066429,289.542877,14.750017,0.664294,-77.663742,0.066490,0.000000
81.810005,65.076927,-77.663742,0.010951,0.002615,0.066429,289.476624,14.746643,0.664294,-77.663742,0.066490,0.000000
82.010002,65.077293,-77.708221,0.010947,0.002615,0.066429,289.478271,14.746725,0.664294,-77.708221,0.066490,0.000000
82.210007,65.063515,-77.708221,0.010943,0.002615,0.066429,289.416962,14.743604,0.664294,-77.708221,0.066490,0.000000
82.410004,65.056068,-77.708221,0.010956,0.002615,0.066429,289.383850,14.741916,0.664294,-77.708221,0.066490,0.000000
82.610001,65.064644,-77.619263,0.010947,0.002615,0.066429,289.421997,14.743859,0.664294,-77.619263,0.066490,0.000000
82.810005,65.063515,-77.708221,0.010947,0.002615,0.066429,289.416962,14.743604,0.664294,-77.708221,0.066490,0.000000
83.010002,65.044167,-77.708221,0.010943,0.002615,0.066429,289.330902,14.739220,0.664294,-77.708221,0.066490,0.000000
83.210007,65.049004,-77.752701,0.010943,0.002615,0.066429,289.352417,14.740315,0.664294,-77.752701,0.066490,0.000000
83.410004,65.045647,-77.752701,0.010938,0.002615,0.066429,289.337494,14.739554,0.664294,-77.752701,0.066490,0.000000
83.610001,65.051613,-77.752701,0.010947,0.002615,0.066429,289.364014,14.740906,0.664294,-77.752701,0.066490,0.000000
83.810005,65.040810,-77.752701,0.010943,0.002615,0.066429,289.315979,14.738459,0.664294,-77.752701,0.066490,0.000000
84.010002,65.033363,-77.708221,0.010930,0.002615,0.066429,289.282837,14.736771,0.664294,-77.708221,0.066490,0.000000
84.210007,65.035591,-77.752701,0.010947,0.002615,0.066429,289.292755,14.737276,0.664294,-77.752701,0.066490,0.000000
84.410004,65.026283,-77.752701,0.010943,0.002615,0.066429,289.251343,14.735167,0.664294,-77.752701,0.066490,0.000000
84.610001,65.031120,-77.752701,0.010934,0.002615,0.066429,289.272858,14.736262,0.664294,-77.752701,0.066490,0.000000
84.810005,65.041924,-77.886147,0.010930,0.002615,0.066429,289.320923,14.738711,0.664294,-77.886147,0.066490,0.000000
85.010002,65.019951,-77.841667,0.010943,0.002615,0.066429,289.223175,14.733731,0.664294,-77.841667,0.066490,0.000000
85.210007,65.012505,-77.797180,0.010938,0.002615,0.066429,289.190063,14.732044,0.664294,-77.797180,0.066490,0.000000
85.300003,65.018837,-77.797180,0.010943,0.002615,0.066429,289.218231,14.733479,0.664294,-77.797180,0.066490,0.000000