File: Data/compression 6/AutoNoheating-10-6-day2-3-240229_02292024_170353.csv
Time (sec),S:Load (lbs),S:HL1 (DIM),S:LVDT (in),S:Position (in),Ch:Position (mm),Ch:Load (N),Ch:Stress (MPa),Ch:Strain (mm/mm),Ch:HL1 (DIM),Set Point (),Cycles ()
0.010000,-0.007820,-79.354019,0.000017,-0.000000,-0.000000,-0.034786,-0.001772,-0.000000,-79.354019,0.000217,0.000000
0.200000,-0.011543,-79.354019,0.000004,-0.000000,-0.000000,-0.051347,-0.002616,-0.000000,-79.354019,0.000217,0.000000
0.390000,0.059952,-79.309532,0.000000,0.000033,0.000833,0.266679,0.013585,0.008327,-79.309532,0.001362,0.000000
0.580000,0.047661,-79.309532,-0.000004,0.000141,0.003573,0.212006,0.010800,0.035729,-79.309532,0.004518,0.000000
0.770000,0.064423,-79.398499,0.000103,0.000261,0.006617,0.286566,0.014598,0.066168,-79.398499,0.007692,0.000000
0.960000,0.121765,-79.354019,0.000220,0.000385,0.009782,0.541638,0.027592,0.097824,-79.354019,0.010849,0.000000
1.150000,0.141876,-79.398499,0.000336,0.000507,0.012870,0.631097,0.032150,0.128702,-79.398499,0.014023,0.000000
1.340000,0.151932,-79.354019,0.000466,0.000636,0.016148,0.675826,0.034428,0.161479,-79.354019,0.017180,0.000000
1.530000,0.192146,-79.398499,0.000595,0.000761,0.019322,0.854709,0.043541,0.193219,-79.398499,0.020354,0.000000
1.720000,0.258430,-79.398499,0.000729,0.000882,0.022401,1.149556,0.058561,0.224005,-79.398499,0.023511,0.000000
1.910000,0.266251,-79.354019,0.000854,0.001007,0.025584,1.184342,0.060333,0.255836,-79.354019,0.026685,0.000000
2.100000,0.311302,-79.398499,0.000970,0.001133,0.028766,1.384741,0.070542,0.287660,-79.398499,0.029842,0.000000
2.290000,0.338486,-79.398499,0.001108,0.001255,0.031871,1.505660,0.076702,0.318711,-79.398499,0.033016,0.000000
2.480000,0.402534,-79.398499,0.001237,0.001382,0.035106,1.790563,0.091216,0.351057,-79.398499,0.036172,0.000000
2.670000,0.448334,-79.442978,0.001362,0.001508,0.038297,1.994288,0.101594,0.382971,-79.442978,0.039346,0.000000
2.860000,0.538826,-79.398499,0.001500,0.001635,0.041540,2.396818,0.122100,0.415400,-79.398499,0.042503,0.000000
3.050000,0.634895,-79.354019,0.001617,0.001757,0.044619,2.824156,0.143869,0.446186,-79.354019,0.045677,0.000000
3.240000,0.597290,-79.442978,0.001664,0.000008,0.000191,2.656879,0.135348,0.001908,-79.442978,0.000338,0.000000
3.430000,0.552231,-79.442978,0.001677,0.000007,0.000182,2.456445,0.125137,0.001817,-79.442978,0.000338,0.000000
3.620000,0.518341,-79.442978,0.001664,0.000007,0.000173,2.305696,0.117458,0.001733,-79.442978,0.000338,0.000000
3.810000,0.541428,-79.442978,0.001669,0.000007,0.000173,2.408390,0.122689,0.001733,-79.442978,0.000520,0.000000
4.000000,0.508659,-79.487457,0.001664,0.000007,0.000173,2.262630,0.115264,0.001733,-79.487457,0.000841,0.000000
4.190000,0.501213,-79.531944,0.001681,0.000012,0.000312,2.229507,0.113577,0.003119,-79.531944,0.001153,0.000000
4.380000,0.526535,-79.442978,0.001673,0.000023,0.000572,2.342145,0.119315,0.005723,-79.442978,0.001474,0.000000
4.570000,0.560425,-79.531944,0.001673,0.000032,0.000824,2.492894,0.126994,0.008236,-79.531944,0.001795,0.000000
4.760000,0.583138,-79.487457,0.001673,0.000042,0.001057,2.593925,0.132141,0.010575,-79.487457,0.002107,0.000000
4.950000,0.594681,-79.487457,0.001699,0.000066,0.001665,2.645272,0.134757,0.016646,-79.487457,0.002428,0.000000
5.140000,0.609200,-79.487457,0.001725,0.000076,0.001942,2.709855,0.138047,0.019424,-79.487457,0.002740,0.000000
5.330000,0.630058,-79.531944,0.001729,0.000085,0.002159,2.802639,0.142773,0.021589,-79.531944,0.003061,0.000000
5.520000,0.615906,-79.487457,0.001738,0.000098,0.002489,2.739686,0.139566,0.024889,-79.487457,0.003373,0.000000
5.710000,0.630424,-79.487457,0.001750,0.000111,0.002809,2.804268,0.142856,0.028091,-79.487457,0.003694,0.000000
5.900000,0.645699,-79.531944,0.001750,0.000126,0.003208,2.872211,0.146317,0.032081,-79.531944,0.004006,0.000000
6.090000,0.674370,-79.531944,0.001772,0.000138,0.003503,2.999747,0.152814,0.035033,-79.531944,0.004327,0.000000
6.280000,0.684052,-79.487457,0.001785,0.000147,0.003746,3.042813,0.155008,0.037463,-79.487457,0.004640,0.000000
6.470000,0.716072,-79.531944,0.001794,0.000158,0.004023,3.185248,0.162264,0.040233,-79.531944,0.004960,0.000000
6.660000,0.724266,-79.487457,0.001811,0.000172,0.004362,3.221696,0.164121,0.043617,-79.487457,0.005272,0.000000
6.850000,0.731712,-79.576424,0.001832,0.000189,0.004795,3.254819,0.165808,0.047955,-79.576424,0.005593,0.000000
7.040000,0.744743,-79.576424,0.001845,0.000203,0.005151,3.312784,0.168761,0.051512,-79.576424,0.005905,0.000000
7.230000,0.699692,-79.487457,0.001858,0.000215,0.005455,3.112385,0.158552,0.054548,-79.487457,0.006226,0.000000
7.420001,0.694473,-79.531944,0.001867,0.000223,0.005663,3.089171,0.157370,0.056630,-79.531944,0.006539,0.000000
7.610000,0.733200,-79.531944,0.001888,0.000240,0.006105,3.261437,0.166146,0.061050,-79.531944,0.006860,0.000000
7.800000,0.721657,-79.531944,0.001888,0.000250,0.006356,3.210090,0.163530,0.063564,-79.531944,0.007172,0.000000
7.990000,0.753685,-79.620903,0.001897,0.000262,0.006660,3.352558,0.170787,0.066599,-79.620903,0.007493,0.000000
8.180000,0.777512,-79.576424,0.001914,0.000278,0.007051,3.458544,0.176187,0.070505,-79.576424,0.007804,0.000000
8.370001,0.788315,-79.576424,0.001936,0.000287,0.007284,3.506599,0.178635,0.072844,-79.576424,0.008125,0.000000
8.560000,0.799110,-79.576424,0.001936,0.000301,0.007649,3.554621,0.181081,0.076485,-79.576424,0.008438,0.000000
8.750000,0.824432,-79.576424,0.001944,0.000316,0.008030,3.667258,0.186819,0.080300,-79.576424,0.008759,0.000000
8.940001,0.808418,-79.620903,0.001966,0.000327,0.008308,3.596024,0.183190,0.083078,-79.620903,0.009071,0.000000
9.130000,0.801346,-79.620903,0.001966,0.000338,0.008585,3.564564,0.181588,0.085849,-79.620903,0.009392,0.000000
9.320001,0.788315,-79.576424,0.001983,0.000350,0.008898,3.506599,0.178635,0.088975,-79.576424,0.009704,0.000000
9.510000,0.805817,-79.531944,0.001996,0.000364,0.009244,3.584451,0.182601,0.092442,-79.531944,0.010025,0.000000
9.700001,0.824059,-79.620903,0.001992,0.000376,0.009548,3.665596,0.186734,0.095478,-79.620903,0.010337,0.000000
9.890000,0.841560,-79.620903,0.002018,0.000390,0.009894,3.743448,0.190700,0.098945,-79.620903,0.010658,0.000000
10.080001,0.865021,-79.620903,0.002031,0.000405,0.010276,3.847805,0.196017,0.102760,-79.620903,0.010978,0.000000
10.270000,0.841560,-79.709862,0.002039,0.000410,0.010415,3.743448,0.190700,0.104153,-79.709862,0.011291,0.000000
10.460000,0.881409,-79.620903,0.002061,0.000424,0.010779,3.920702,0.199730,0.107794,-79.620903,0.011612,0.000000
10.650001,0.878799,-79.620903,0.002065,0.000436,0.011074,3.909095,0.199139,0.110738,-79.620903,0.011924,0.000000
10.840000,0.913055,-79.620903,0.002095,0.000454,0.011534,4.061473,0.206901,0.115341,-79.620903,0.012245,0.000000
11.030001,0.903008,-79.620903,0.002082,0.000466,0.011829,4.016778,0.204624,0.118286,-79.620903,0.012557,0.000000
11.220000,0.889969,-79.709862,0.002095,0.000473,0.012011,3.958779,0.201670,0.120110,-79.709862,0.012878,0.000000
11.410001,0.905235,-79.620903,0.002117,0.000485,0.012315,4.026688,0.205129,0.123145,-79.620903,0.013190,0.000000
11.600000,0.919388,-79.709862,0.002121,0.000499,0.012687,4.089641,0.208336,0.126870,-79.709862,0.013511,0.000000
11.790001,0.940239,-79.665382,0.002139,0.000512,0.013017,4.182392,0.213061,0.130170,-79.665382,0.013823,0.000000
11.980000,0.953278,-79.665382,0.002147,0.000527,0.013389,4.240390,0.216016,0.133894,-79.665382,0.014144,0.000000
12.170001,0.943962,-79.665382,0.002160,0.000533,0.013537,4.198953,0.213905,0.135371,-79.665382,0.014456,0.000000
12.360001,0.984184,-79.709862,0.002173,0.000550,0.013979,4.377870,0.223019,0.139791,-79.709862,0.014777,0.000000
12.550000,0.973381,-79.754349,0.002182,0.000561,0.014257,4.329815,0.220571,0.142569,-79.754349,0.015090,0.000000
12.740001,1.003548,-79.709862,0.002212,0.000576,0.014630,4.464003,0.227407,0.146301,-79.709862,0.015411,0.000000
12.930000,1.001312,-79.709862,0.002212,0.000586,0.014881,4.454060,0.226901,0.148814,-79.709862,0.015722,0.000000
13.120001,0.980827,-79.754349,0.002225,0.000600,0.015246,4.362938,0.222259,0.152456,-79.754349,0.016043,0.000000
13.310000,0.990143,-79.709862,0.002233,0.000610,0.015489,4.404375,0.224370,0.154885,-79.709862,0.016355,0.000000
13.500001,0.999077,-79.754349,0.002246,0.000622,0.015800,4.444116,0.226394,0.158004,-79.754349,0.016676,0.000000
13.690001,1.023651,-79.754349,0.002268,0.000635,0.016121,4.553428,0.231963,0.161214,-79.754349,0.016989,0.000000
13.880001,1.050461,-79.709862,0.002268,0.000647,0.016425,4.672683,0.238038,0.164249,-79.709862,0.017310,0.000000
14.070001,1.034821,-79.798828,0.002289,0.000658,0.016703,4.603112,0.234494,0.167027,-79.798828,0.017622,0.000000
14.260000,1.054184,-79.709862,0.002285,0.000667,0.016937,4.689244,0.238881,0.169366,-79.709862,0.017943,0.000000
14.450001,1.094406,-79.754349,0.002307,0.000688,0.017474,4.868162,0.247996,0.174741,-79.754349,0.018255,0.000000
14.640000,1.088448,-79.709862,0.002324,0.000696,0.017682,4.841657,0.246646,0.176823,-79.709862,0.018576,0.000000
14.830001,1.135735,-79.754349,0.002333,0.000716,0.018186,5.052000,0.257361,0.181857,-79.754349,0.018888,0.000000
15.020000,1.081367,-79.754349,0.002358,0.000725,0.018420,4.810163,0.245041,0.184196,-79.754349,0.019209,0.000000
15.210001,1.101105,-79.754349,0.002354,0.000736,0.018697,4.897958,0.249514,0.186974,-79.754349,0.019521,0.000000
15.400001,1.114136,-79.798828,0.002371,0.000748,0.018992,4.955923,0.252467,0.189918,-79.798828,0.019842,0.000000
15.590001,1.122704,-79.754349,0.002389,0.000757,0.019226,4.994035,0.254408,0.192258,-79.754349,0.020163,0.000000
15.780001,1.169624,-79.843307,0.002389,0.000772,0.019608,5.202749,0.265041,0.196080,-79.843307,0.020475,0.000000
15.970001,1.165527,-79.843307,0.002402,0.000783,0.019885,5.184525,0.264112,0.198851,-79.843307,0.020796,0.000000
16.160000,1.167389,-79.754349,0.002419,0.000790,0.020068,5.192805,0.264534,0.200675,-79.754349,0.021108,0.000000
16.350000,1.205368,-79.798828,0.002410,0.000806,0.020484,5.361745,0.273140,0.204839,-79.798828,0.021429,0.000000
16.540001,1.238884,-79.754349,0.002445,0.000822,0.020883,5.510831,0.280735,0.208828,-79.754349,0.021741,0.000000
16.730001,1.258621,-79.798828,0.002470,0.000841,0.021351,5.598627,0.285208,0.213506,-79.798828,0.022062,0.000000
16.920000,1.200905,-79.798828,0.002479,0.000848,0.021550,5.341892,0.272129,0.215504,-79.798828,0.022374,0.000000
17.110001,1.195686,-79.798828,0.002479,0.000858,0.021784,5.318678,0.270946,0.217843,-79.798828,0.022695,0.000000
17.300001,1.205368,-79.887787,0.002496,0.000867,0.022027,5.361745,0.273140,0.220273,-79.887787,0.023007,0.000000
17.490002,1.247818,-79.843307,0.002509,0.000881,0.022374,5.550571,0.282760,0.223740,-79.843307,0.023328,0.000000
17.680000,1.264206,-79.843307,0.002509,0.000891,0.022634,5.623469,0.286473,0.226344,-79.843307,0.023640,0.000000
17.870001,1.332352,-79.843307,0.002535,0.000909,0.023077,5.926596,0.301915,0.230765,-79.843307,0.023961,0.000000
18.060001,1.270538,-79.843307,0.002548,0.000913,0.023181,5.651637,0.287908,0.231810,-79.843307,0.024273,0.000000
18.250000,1.318573,-79.932266,0.002548,0.000925,0.023501,5.865305,0.298793,0.235012,-79.932266,0.024594,0.000000
18.440001,1.361023,-79.843307,0.002578,0.000944,0.023979,6.054132,0.308412,0.239788,-79.843307,0.024906,0.000000
18.630001,1.374428,-79.887787,0.002570,0.000958,0.024326,6.113760,0.311450,0.243255,-79.887787,0.025227,0.000000
18.820002,1.377777,-79.887787,0.002591,0.000970,0.024629,6.128659,0.312209,0.246291,-79.887787,0.025540,0.000000
19.010000,1.378899,-79.887787,0.002613,0.000985,0.025028,6.133647,0.312463,0.250280,-79.887787,0.025861,0.000000
19.200001,1.369583,-79.843307,0.002613,0.000994,0.025254,6.092210,0.310352,0.252536,-79.843307,0.026173,0.000000
19.390001,1.352829,-79.887787,0.002626,0.001003,0.025487,6.017684,0.306555,0.254875,-79.887787,0.026494,0.000000
19.580002,1.462677,-79.887787,0.002647,0.001023,0.025990,6.506312,0.331447,0.259901,-79.887787,0.026805,0.000000
19.770000,1.464172,-79.887787,0.002669,0.001035,0.026294,6.512964,0.331786,0.262937,-79.887787,0.027126,0.000000
19.960001,1.432518,-79.887787,0.002665,0.001040,0.026424,6.372159,0.324613,0.264239,-79.887787,0.027439,0.000000
20.150002,1.478691,-79.976753,0.002673,0.001052,0.026710,6.577547,0.335076,0.267100,-79.976753,0.027760,0.000000
20.340000,1.468636,-79.887787,0.002682,0.001061,0.026962,6.532817,0.332798,0.269621,-79.887787,0.028072,0.000000
20.530001,1.562477,-79.932266,0.002708,0.001086,0.027586,6.950245,0.354062,0.275858,-79.932266,0.028393,0.000000
20.720001,1.540131,-79.932266,0.002716,0.001097,0.027864,6.850843,0.348999,0.278636,-79.932266,0.028705,0.000000
20.910002,1.537155,-79.887787,0.002738,0.001109,0.028176,6.837607,0.348324,0.281755,-79.887787,0.029026,0.000000
21.100000,1.526352,-80.021233,0.002751,0.001121,0.028471,6.789553,0.345876,0.284707,-80.021233,0.029347,0.000000
21.290001,1.534920,-79.887787,0.002755,0.001133,0.028766,6.827664,0.347818,0.287660,-79.887787,0.029659,0.000000
21.480001,1.608650,-80.021233,0.002768,0.001147,0.029130,7.155633,0.364525,0.291301,-80.021233,0.029979,0.000000
21.670000,1.655571,-80.021233,0.002785,0.001157,0.029399,7.364347,0.375158,0.293988,-80.021233,0.030292,0.000000
21.860001,1.654076,-79.976753,0.002790,0.001168,0.029676,7.357696,0.374819,0.296758,-79.976753,0.030613,0.000000
22.050001,1.687218,-80.021233,0.002798,0.001179,0.029954,7.505119,0.382329,0.299537,-80.021233,0.030925,0.000000
22.240002,1.699509,-79.932266,0.002815,0.001196,0.030370,7.559792,0.385114,0.303700,-79.932266,0.031246,0.000000
22.430000,1.768768,-79.932266,0.002833,0.001215,0.030856,7.867875,0.400809,0.308560,-79.932266,0.031558,0.000000
22.620001,1.708076,-79.932266,0.002859,0.001223,0.031055,7.597904,0.387056,0.310551,-79.932266,0.031879,0.000000
22.810001,1.701370,-80.065712,0.002850,0.001236,0.031402,7.568073,0.385536,0.314018,-80.065712,0.032191,0.000000
23.000002,1.736374,-80.021233,0.002863,0.001248,0.031688,7.723777,0.393468,0.316879,-80.021233,0.032512,0.000000
23.190001,1.790367,-80.021233,0.002884,0.001259,0.031974,7.963951,0.405703,0.319740,-80.021233,0.032824,0.000000
23.380001,1.803398,-80.065712,0.002897,0.001271,0.032278,8.021915,0.408656,0.322776,-80.065712,0.033145,0.000000
23.570002,1.841759,-79.932266,0.002923,0.001281,0.032538,8.192552,0.417349,0.325380,-79.932266,0.033457,0.000000
23.760000,1.901337,-80.021233,0.002919,0.001295,0.032894,8.457568,0.430849,0.328938,-80.021233,0.033778,0.000000
23.950001,1.937454,-80.065712,0.002932,0.001306,0.033180,8.618227,0.439033,0.331799,-80.065712,0.034091,0.000000
24.140001,1.967247,-79.976753,0.002949,0.001321,0.033552,8.750751,0.445785,0.335523,-79.976753,0.034412,0.000000
24.330002,2.007835,-80.065712,0.002966,0.001337,0.033969,8.931298,0.454982,0.339687,-80.065712,0.034723,0.000000
24.520000,1.980652,-80.065712,0.002962,0.001347,0.034212,8.810379,0.448822,0.342117,-80.065712,0.035044,0.000000
24.710001,1.991074,-80.021233,0.002992,0.001359,0.034507,8.856738,0.451184,0.345069,-80.021233,0.035356,0.000000
24.900002,2.005600,-80.065712,0.002988,0.001369,0.034776,8.921354,0.454475,0.347756,-80.065712,0.035677,0.000000
25.090002,2.064804,-80.065712,0.003018,0.001384,0.035165,9.184708,0.467891,0.351655,-80.065712,0.035990,0.000000
25.280001,2.103157,-80.065712,0.003018,0.001398,0.035513,9.355309,0.476582,0.355129,-80.065712,0.036311,0.000000
25.470001,2.115448,-80.021233,0.003044,0.001410,0.035816,9.409983,0.479367,0.358165,-80.021233,0.036623,0.000000
25.660002,2.143005,-80.065712,0.003044,0.001420,0.036068,9.532564,0.485612,0.360678,-80.065712,0.036944,0.000000
25.850000,2.171677,-80.110191,0.003057,0.001430,0.036319,9.660100,0.492109,0.363191,-80.110191,0.037255,0.000000
26.040001,2.245407,-80.021233,0.003065,0.001444,0.036675,9.988070,0.508817,0.366749,-80.021233,0.037576,0.000000
26.230001,2.339989,-80.110191,0.003096,0.001462,0.037143,10.408790,0.530249,0.371427,-80.110191,0.037897,0.000000
26.420002,2.291206,-80.110191,0.003104,0.001473,0.037403,10.191795,0.519195,0.374031,-80.110191,0.038210,0.000000
26.610001,2.271843,-80.065712,0.003117,0.001480,0.037594,10.105662,0.514807,0.375938,-80.065712,0.038530,0.000000
26.800001,2.305359,-80.154671,0.003130,0.001494,0.037950,10.254748,0.522402,0.379496,-80.154671,0.038843,0.000000
26.990002,2.377602,-80.021233,0.003143,0.001509,0.038322,10.576100,0.538772,0.383221,-80.021233,0.039164,0.000000
27.180002,2.422653,-80.154671,0.003147,0.001522,0.038670,10.776500,0.548981,0.386695,-80.154671,0.039476,0.000000
27.370001,2.468086,-80.110191,0.003173,0.001534,0.038973,10.978596,0.559276,0.389731,-80.110191,0.039797,0.000000
27.560001,2.480377,-80.110191,0.003173,0.001545,0.039250,11.033269,0.562062,0.392501,-80.110191,0.040109,0.000000
27.750002,2.463989,-80.154671,0.003191,0.001553,0.039458,10.960372,0.558348,0.394583,-80.154671,0.040429,0.000000
27.940001,2.634537,-80.154671,0.003216,0.001570,0.039866,11.719005,0.596995,0.398663,-80.154671,0.040742,0.000000
28.130001,2.646828,-80.154671,0.003229,0.001583,0.040205,11.773678,0.599780,0.402047,-80.154671,0.041063,0.000000
28.320002,2.746620,-80.110191,0.003238,0.001600,0.040629,12.217577,0.622393,0.406293,-80.110191,0.041375,0.000000
28.510002,2.695976,-80.110191,0.003242,0.001612,0.040941,11.992301,0.610917,0.409412,-80.110191,0.041696,0.000000
28.700001,2.649803,-80.199158,0.003268,0.001620,0.041141,11.786913,0.600454,0.411411,-80.199158,0.042008,0.000000
28.890001,2.846786,-80.154671,0.003268,0.001637,0.041592,12.663138,0.645091,0.415922,-80.154671,0.042329,0.000000
29.080002,2.812531,-80.199158,0.003281,0.001647,0.041844,12.510760,0.637329,0.418435,-80.199158,0.042641,0.000000
29.270000,2.903015,-80.154671,0.003298,0.001660,0.042155,12.913257,0.657833,0.421554,-80.154671,0.042962,0.000000
29.460001,2.952545,-80.154671,0.003303,0.001672,0.042459,13.133576,0.669056,0.424590,-80.154671,0.043274,0.000000
29.650002,2.917915,-80.243637,0.003333,0.001679,0.042650,12.979536,0.661209,0.426497,-80.243637,0.043595,0.000000
29.840002,3.109680,-80.154671,0.003341,0.001694,0.043031,13.832548,0.704664,0.430312,-80.154671,0.043907,0.000000
30.030001,3.188995,-80.243637,0.003359,0.001708,0.043387,14.185360,0.722637,0.433870,-80.243637,0.044228,0.000000
30.220001,3.210968,-80.199158,0.003376,0.001723,0.043769,14.283099,0.727616,0.437685,-80.199158,0.044541,0.000000
30.410002,3.255653,-80.199158,0.003376,0.001735,0.044064,14.481870,0.737742,0.440637,-80.199158,0.044862,0.000000
30.600002,3.250816,-80.243637,0.003393,0.001747,0.044367,14.460353,0.736646,0.443673,-80.243637,0.045173,0.000000
30.790001,3.397156,-80.288116,0.003402,0.001761,0.044722,15.111303,0.769807,0.447223,-80.288116,0.045494,0.000000
30.980001,3.355080,-80.288116,0.003410,0.001771,0.044983,14.924140,0.760272,0.449827,-80.288116,0.045806,0.000000
31.170002,3.531212,-80.243637,0.003436,0.001787,0.045382,15.707615,0.800184,0.453816,-80.243637,0.046127,0.000000
31.360001,3.417267,-80.199158,0.003441,0.001794,0.045564,15.200762,0.774364,0.455641,-80.199158,0.046440,0.000000
31.550001,3.561745,-80.332596,0.003466,0.001806,0.045868,15.843431,0.807103,0.458676,-80.332596,0.046761,0.000000
31.740002,3.782188,-80.243637,0.003466,0.001822,0.046283,16.824015,0.857056,0.462832,-80.243637,0.047081,0.000000
31.930002,3.733406,-80.332596,0.003479,0.001831,0.046509,16.607019,0.846002,0.465088,-80.332596,0.047394,0.000000
32.120003,4.124397,-80.243637,0.003497,0.001852,0.047038,18.346235,0.934602,0.470379,-80.243637,0.047715,0.000000
32.310001,4.013802,-80.288116,0.003501,0.001862,0.047307,17.854280,0.909540,0.473066,-80.288116,0.048027,0.000000
32.500000,3.970978,-80.243637,0.003523,0.001870,0.047506,17.663792,0.899836,0.475065,-80.243637,0.048347,0.000000
32.690002,4.019020,-80.288116,0.003527,0.001880,0.047740,17.877495,0.910723,0.477404,-80.288116,0.048659,0.000000
32.880001,4.248398,-80.288116,0.003535,0.001895,0.048131,18.897818,0.962701,0.481310,-80.288116,0.048980,0.000000
33.070000,4.383942,-80.288116,0.003553,0.001908,0.048469,19.500746,0.993415,0.484686,-80.288116,0.049293,0.000000
33.260002,4.490067,-80.332596,0.003561,0.001922,0.048824,19.972813,1.017464,0.488244,-80.332596,0.049614,0.000000
33.450001,4.499748,-80.332596,0.003579,0.001931,0.049050,20.015881,1.019657,0.490500,-80.332596,0.049926,0.000000
33.640003,4.567146,-80.288116,0.003570,0.001941,0.049293,20.315681,1.034930,0.492930,-80.288116,0.050247,0.000000
33.830002,4.824455,-80.421562,0.003587,0.001957,0.049700,21.460249,1.093237,0.497002,-80.421562,0.050559,0.000000
34.020000,5.037086,-80.377075,0.003622,0.001972,0.050099,22.406080,1.141420,0.500991,-80.377075,0.050880,0.000000
34.210003,4.941383,-80.288116,0.003622,0.001981,0.050307,21.980371,1.119733,0.503073,-80.288116,0.051192,0.000000
34.400002,5.112679,-80.332596,0.003630,0.001995,0.050680,22.742331,1.158549,0.506805,-80.332596,0.051513,0.000000
34.590000,5.208374,-80.332596,0.003648,0.002006,0.050958,23.168005,1.180234,0.509576,-80.332596,0.051825,0.000000
34.780003,5.237793,-80.377075,0.003656,0.002015,0.051183,23.298866,1.186901,0.511831,-80.377075,0.052146,0.000000
34.970001,5.519302,-80.332596,0.003673,0.002031,0.051599,24.551083,1.250692,0.515995,-80.332596,0.052458,0.000000
35.160000,5.654106,-80.332596,0.003686,0.002040,0.051817,25.150721,1.281239,0.518167,-80.332596,0.052779,0.000000
35.350002,5.857048,-80.377075,0.003699,0.002055,0.052189,26.053452,1.327226,0.521892,-80.377075,0.053091,0.000000
35.540001,5.706238,-80.332596,0.003699,0.002060,0.052328,25.382614,1.293052,0.523284,-80.332596,0.053412,0.000000
35.730003,6.483749,-80.377075,0.003721,0.002083,0.052918,28.841158,1.469239,0.529181,-80.377075,0.053724,0.000000
35.920002,6.303894,-80.332596,0.003729,0.002090,0.053082,28.041121,1.428483,0.530824,-80.332596,0.054045,0.000000
36.110001,6.929108,-80.377075,0.003742,0.002112,0.053655,30.822210,1.570158,0.536547,-80.377075,0.054357,0.000000
36.300003,6.624878,-80.377075,0.003751,0.002118,0.053794,29.468929,1.501219,0.537940,-80.377075,0.054678,0.000000
36.490002,6.897827,-80.332596,0.003777,0.002131,0.054132,30.683067,1.563070,0.541316,-80.332596,0.054991,0.000000
36.680000,6.960762,-80.466042,0.003773,0.002140,0.054366,30.963017,1.577331,0.543662,-80.466042,0.055312,0.000000
36.870003,7.194611,-80.466042,0.003786,0.002151,0.054627,32.003227,1.630322,0.546266,-80.466042,0.055624,0.000000
37.060001,7.571823,-80.377075,0.003803,0.002165,0.054982,33.681152,1.715800,0.549817,-80.377075,0.055945,0.000000
37.250000,7.666405,-80.421562,0.003807,0.002175,0.055242,34.101871,1.737232,0.552421,-80.421562,0.056265,0.000000
37.440002,7.918877,-80.377075,0.003820,0.002186,0.055520,35.224922,1.794443,0.555199,-80.377075,0.056577,0.000000
37.630001,8.305397,-80.466042,0.003829,0.002200,0.055875,36.944252,1.882030,0.558749,-80.466042,0.056898,0.000000
37.820004,8.689682,-80.377075,0.003833,0.002216,0.056274,38.653637,1.969110,0.562738,-80.377075,0.057211,0.000000
38.010002,9.400917,-80.421562,0.003863,0.002236,0.056795,41.817368,2.130278,0.567946,-80.421562,0.057531,0.000000
38.200001,9.272820,-80.466042,0.003867,0.002245,0.057019,41.247562,2.101251,0.570194,-80.466042,0.057844,0.000000
38.390003,9.330162,-80.466042,0.003889,0.002255,0.057272,41.502632,2.114245,0.572715,-80.466042,0.058165,0.000000
38.580002,9.587471,-80.510521,0.003893,0.002266,0.057549,42.647202,2.172552,0.575486,-80.510521,0.058477,0.000000
38.770000,9.501457,-80.421562,0.003893,0.002272,0.057714,42.264591,2.153061,0.577136,-80.421562,0.058798,0.000000
38.960003,10.413399,-80.466042,0.003906,0.002289,0.058130,46.321110,2.359710,0.581299,-80.466042,0.059109,0.000000
39.150002,11.008820,-80.510521,0.003911,0.002305,0.058546,48.969677,2.494634,0.585463,-80.510521,0.059430,0.000000
39.340000,10.948120,-80.421562,0.003941,0.002311,0.058702,48.699669,2.480879,0.587022,-80.421562,0.059743,0.000000
39.530003,11.264267,-80.510521,0.003932,0.002323,0.058997,50.105961,2.552519,0.589974,-80.510521,0.060064,0.000000
39.720001,12.069336,-80.421562,0.003954,0.002340,0.059440,53.687088,2.734951,0.594395,-80.421562,0.060376,0.000000
39.910004,12.552307,-80.466042,0.003945,0.002355,0.059821,55.835449,2.844393,0.598210,-80.466042,0.060697,0.000000
40.100002,12.857277,-80.466042,0.003975,0.002366,0.060107,57.192024,2.913501,0.601072,-80.466042,0.061009,0.000000
40.290001,13.364822,-80.421562,0.003980,0.002382,0.060506,59.449699,3.028512,0.605061,-80.421562,0.061330,0.000000
40.480003,13.570740,-80.555000,0.003988,0.002392,0.060766,60.365665,3.075174,0.607665,-80.555000,0.061642,0.000000
40.670002,13.612823,-80.510521,0.004005,0.002400,0.060957,60.552864,3.084710,0.609572,-80.510521,0.061963,0.000000
40.860001,14.718025,-80.510521,0.003988,0.002418,0.061417,65.469048,3.335152,0.614167,-80.510521,0.062275,0.000000
41.050003,15.272858,-80.510521,0.004023,0.002433,0.061789,67.937065,3.460879,0.617892,-80.510521,0.062596,0.000000
41.240002,15.359245,-80.510521,0.004023,0.002438,0.061928,68.321335,3.480455,0.619285,-80.510521,0.062908,0.000000
41.430000,15.830673,-80.555000,0.004031,0.002450,0.062232,70.418350,3.587282,0.622320,-80.555000,0.063229,0.000000
41.620003,16.121124,-80.510521,0.004049,0.002461,0.062509,71.710342,3.653099,0.625091,-80.510521,0.063542,0.000000
41.810001,17.454964,-80.510521,0.004057,0.002481,0.063030,77.643555,3.955351,0.630299,-80.510521,0.063863,0.000000
42.000004,18.097305,-80.599480,0.004061,0.002495,0.063368,80.500832,4.100908,0.633682,-80.599480,0.064174,0.000000
42.190002,18.335625,-80.555000,0.004083,0.002505,0.063637,81.560928,4.154912,0.636370,-80.555000,0.064495,0.000000
42.380001,18.829758,-80.643967,0.004083,0.002515,0.063888,83.758942,4.266884,0.638883,-80.643967,0.064807,0.000000
42.570004,19.530937,-80.510521,0.004092,0.002528,0.064218,86.877945,4.425774,0.642176,-80.510521,0.065128,0.000000
42.760002,19.774841,-80.555000,0.004096,0.002541,0.064530,87.962891,4.481043,0.645302,-80.555000,0.065449,0.000000
42.950001,20.689384,-80.643967,0.004109,0.002550,0.064764,92.030975,4.688282,0.647641,-80.643967,0.065762,0.000000
43.140003,21.088943,-80.555000,0.004117,0.002559,0.064990,93.808304,4.778823,0.649897,-80.555000,0.066082,0.000000
43.330002,22.101799,-80.599480,0.004109,0.002574,0.065389,98.313713,5.008339,0.653886,-80.599480,0.066395,0.000000
43.520000,22.191536,-80.510521,0.004135,0.002580,0.065527,98.712883,5.028674,0.655271,-80.510521,0.066716,0.000000
43.710003,24.398216,-80.599480,0.004130,0.002610,0.066282,108.528687,5.528715,0.662818,-80.599480,0.067027,0.000000
43.900002,25.042793,-80.688446,0.004152,0.002621,0.066568,111.395905,5.674778,0.665680,-80.688446,0.067348,0.000000
44.090004,25.370110,-80.599480,0.004148,0.002631,0.066837,112.851883,5.748949,0.668367,-80.599480,0.067660,0.000000
44.280003,26.121933,-80.599480,0.004156,0.002643,0.067123,116.196159,5.919314,0.671228,-80.599480,0.067981,0.000000
44.470001,26.284286,-80.599480,0.004178,0.002647,0.067245,116.918343,5.956104,0.672447,-80.599480,0.068294,0.000000
44.660004,27.665039,-80.732925,0.004169,0.002668,0.067773,123.060242,6.268988,0.677731,-80.732925,0.068615,0.000000
44.850002,28.769867,-80.688446,0.004182,0.002680,0.068068,127.974762,6.519345,0.680683,-80.688446,0.068927,0.000000
45.040001,29.548500,-80.643967,0.004191,0.002692,0.068389,131.438293,6.695786,0.683893,-80.643967,0.069248,0.000000
45.230003,30.184143,-80.688446,0.004195,0.002704,0.068684,134.265778,6.839825,0.686837,-80.688446,0.069560,0.000000
45.420002,31.042084,-80.599480,0.004204,0.002715,0.068962,138.082092,7.034237,0.689615,-80.599480,0.069881,0.000000
45.610001,32.280228,-80.643967,0.004199,0.002730,0.069343,143.589630,7.314804,0.693431,-80.643967,0.070193,0.000000
45.800003,33.366066,-80.688446,0.004208,0.002744,0.069690,148.419678,7.560859,0.696898,-80.688446,0.070514,0.000000
45.990002,33.809189,-80.643967,0.004217,0.002751,0.069863,150.390778,7.661272,0.698631,-80.643967,0.070826,0.000000
46.180000,34.781822,-80.732925,0.004221,0.002764,0.070201,154.717270,7.881673,0.702015,-80.732925,0.071147,0.000000
46.370003,35.964478,-80.599480,0.004243,0.002779,0.070583,159.977982,8.149667,0.705830,-80.599480,0.071459,0.000000
46.560001,36.914398,-80.643967,0.004243,0.002791,0.070904,164.203445,8.364922,0.709040,-80.643967,0.071780,0.000000
46.750004,38.169296,-80.732925,0.004264,0.002806,0.071268,169.785507,8.649286,0.712681,-80.732925,0.072092,0.000000
46.940002,38.769936,-80.688446,0.004264,0.002814,0.071485,172.457291,8.785393,0.714853,-80.688446,0.072413,0.000000
47.130001,39.580215,-80.732925,0.004268,0.002825,0.071754,176.061584,8.969005,0.717540,-80.732925,0.072725,0.000000
47.320004,40.759521,-80.688446,0.004277,0.002840,0.072127,181.307404,9.236239,0.721272,-80.688446,0.073046,0.000000
47.510002,41.982391,-80.777405,0.004268,0.002855,0.072517,186.747009,9.513346,0.725171,-80.777405,0.073358,0.000000
47.700001,43.356819,-80.732925,0.004290,0.002868,0.072846,192.860764,9.824796,0.728464,-80.732925,0.073679,0.000000
47.890003,44.097092,-80.732925,0.004290,0.002876,0.073055,196.153656,9.992544,0.730545,-80.732925,0.073992,0.000000
48.080002,45.170639,-80.821892,0.004299,0.002890,0.073410,200.929031,10.235813,0.734103,-80.821892,0.074313,0.000000
48.270000,46.033798,-80.732925,0.004303,0.002902,0.073706,204.768555,10.431407,0.737055,-80.732925,0.074633,0.000000
48.460003,47.139000,-80.777405,0.004299,0.002913,0.074000,209.684738,10.681849,0.740000,-80.777405,0.074945,0.000000
48.650002,48.613968,-80.732925,0.004307,0.002928,0.074373,216.245728,11.016083,0.743732,-80.732925,0.075266,0.000000
48.840004,49.467445,-80.732925,0.004320,0.002938,0.074616,220.042191,11.209483,0.746162,-80.732925,0.075578,0.000000
49.030003,50.459450,-80.732925,0.004316,0.002948,0.074885,224.454849,11.434275,0.748849,-80.732925,0.075899,0.000000
49.220001,51.382561,-80.777405,0.004329,0.002960,0.075179,228.561050,11.643455,0.751794,-80.777405,0.076211,0.000000
49.410004,52.873169,-80.732925,0.004333,0.002976,0.075578,235.191605,11.981231,0.755783,-80.732925,0.076532,0.000000
49.600002,54.109070,-80.821892,0.004333,0.002989,0.075925,240.689163,12.261291,0.759250,-80.821892,0.076845,0.000000
49.790001,55.677132,-80.777405,0.004342,0.003005,0.076324,247.664246,12.616618,0.763239,-80.777405,0.077166,0.000000
49.980003,56.737274,-80.777405,0.004337,0.003015,0.076584,252.380005,12.856851,0.765843,-80.777405,0.077478,0.000000
50.170002,57.585167,-80.777405,0.004346,0.003025,0.076827,256.151611,13.048985,0.768273,-80.777405,0.077799,0.000000
50.360001,59.011726,-80.821892,0.004350,0.003038,0.077157,262.497284,13.372249,0.771566,-80.821892,0.078110,0.000000
50.550003,60.197731,-80.821892,0.004359,0.003053,0.077538,267.772888,13.641001,0.775381,-80.821892,0.078431,0.000000
50.740002,61.453003,-80.821892,0.004359,0.003064,0.077816,273.356598,13.925449,0.778159,-80.821892,0.078744,0.000000
50.930004,62.756676,-80.821892,0.004359,0.003075,0.078110,279.155640,14.220865,0.781104,-80.821892,0.079065,0.000000
51.120003,63.937836,-80.777405,0.004376,0.003092,0.078527,284.409698,14.488521,0.785267,-80.777405,0.079377,0.000000
51.310001,64.969315,-80.777405,0.004372,0.003099,0.078727,288.997955,14.722258,0.787266,-80.777405,0.079698,0.000000
51.500004,66.860214,-80.866371,0.004381,0.003118,0.079194,297.409088,15.150742,0.791944,-80.866371,0.080010,0.000000
51.690002,67.428085,-80.821892,0.004376,0.003118,0.079186,299.935089,15.279422,0.791861,-80.821892,0.079325,0.000000
51.880001,67.243759,-80.910851,0.004389,0.003117,0.079169,299.115173,15.237654,0.791686,-80.910851,0.079325,0.000000
52.070004,67.086624,-80.866371,0.004381,0.003117,0.079160,298.416199,15.202045,0.791603,-80.866371,0.079160,0.000000
52.260002,66.947357,-80.910851,0.004389,0.003116,0.079151,297.796722,15.170488,0.791512,-80.910851,0.079160,0.000000
52.450001,66.832672,-80.821892,0.004393,0.003116,0.079143,297.286560,15.144500,0.791429,-80.821892,0.079160,0.000000
52.640003,66.724670,-80.866371,0.004402,0.003116,0.079143,296.806152,15.120027,0.791429,-80.866371,0.079160,0.000000
52.830002,66.633072,-80.955330,0.004389,0.003116,0.079143,296.398712,15.099270,0.791429,-80.955330,0.079160,0.000000
53.020004,66.538498,-80.821892,0.004389,0.003116,0.079143,295.978027,15.077840,0.791429,-80.821892,0.079160,0.000000
53.210003,66.471085,-80.910851,0.004385,0.003116,0.079143,295.678162,15.062564,0.791429,-80.910851,0.079160,0.000000
53.400002,66.398483,-80.910851,0.004398,0.003116,0.079143,295.355194,15.046111,0.791429,-80.910851,0.079160,0.000000
53.590004,66.323639,-80.866371,0.004393,0.003116,0.079143,295.022278,15.029151,0.791429,-80.866371,0.079160,0.000000
53.780003,66.271133,-80.866371,0.004381,0.003116,0.079143,294.788727,15.017254,0.791429,-80.866371,0.079160,0.000000
53.970001,66.208191,-80.866371,0.004402,0.003116,0.079134,294.508728,15.002991,0.791338,-80.866371,0.079160,0.000000
54.160004,66.148621,-80.955330,0.004389,0.003116,0.079134,294.243774,14.989492,0.791338,-80.955330,0.079160,0.000000
54.350002,66.106918,-80.955330,0.004398,0.003116,0.079134,294.058258,14.980042,0.791338,-80.955330,0.079160,0.000000
54.540001,66.056274,-80.866371,0.004385,0.003116,0.079134,293.832977,14.968565,0.791338,-80.866371,0.079160,0.000000
54.730003,66.013443,-80.955330,0.004398,0.003116,0.079134,293.642456,14.958859,0.791338,-80.955330,0.079160,0.000000
54.920002,65.971741,-80.866371,0.004389,0.003116,0.079134,293.456970,14.949410,0.791338,-80.866371,0.079160,0.000000
55.110004,65.927429,-81.044296,0.004389,0.003116,0.079134,293.259857,14.939369,0.791338,-81.044296,0.079160,0.000000
55.300003,65.898010,-80.910851,0.004393,0.003116,0.079134,293.128998,14.932703,0.791338,-80.910851,0.079160,0.000000
55.490002,65.849609,-80.955330,0.004402,0.003116,0.079134,292.913696,14.921734,0.791338,-80.955330,0.079160,0.000000
55.680004,65.821304,-80.955330,0.004393,0.003116,0.079134,292.787781,14.915320,0.791338,-80.955330,0.079160,0.000000
55.870003,65.793381,-80.910851,0.004393,0.003116,0.079134,292.663574,14.908993,0.791338,-80.910851,0.079160,0.000000
56.060001,65.747192,-80.999809,0.004393,0.003116,0.079134,292.458130,14.898526,0.791338,-80.999809,0.079160,0.000000
56.250004,65.727097,-80.955330,0.004406,0.003116,0.079134,292.368713,14.893972,0.791338,-80.955330,0.079160,0.000000
56.440002,65.699905,-80.999809,0.004393,0.003116,0.079134,292.247772,14.887812,0.791338,-80.999809,0.079160,0.000000
56.630001,65.670486,-80.999809,0.004398,0.003116,0.079134,292.116913,14.881145,0.791338,-80.999809,0.079160,0.000000
56.820004,65.638092,-80.955330,0.004398,0.003116,0.079134,291.972809,14.873804,0.791338,-80.955330,0.079160,0.000000
57.010002,65.604950,-81.044296,0.004385,0.003116,0.079134,291.825378,14.866295,0.791338,-81.044296,0.079160,0.000000
57.200005,65.596024,-81.044296,0.004398,0.003116,0.079134,291.785675,14.864272,0.791338,-81.044296,0.079160,0.000000
57.390003,65.552826,-80.999809,0.004389,0.003116,0.079134,291.593536,14.854483,0.791338,-80.999809,0.079160,0.000000
57.580002,65.520798,-81.088776,0.004385,0.003116,0.079134,291.451050,14.847225,0.791338,-81.088776,0.079160,0.000000
57.770004,65.513718,-81.044296,0.004398,0.003116,0.079134,291.419556,14.845620,0.791338,-81.044296,0.079160,0.000000
57.960003,65.496597,-80.999809,0.004398,0.003116,0.079134,291.343414,14.841741,0.791338,-80.999809,0.079160,0.000000
58.150002,65.457870,-81.044296,0.004398,0.003116,0.079134,291.171143,14.832966,0.791338,-81.044296,0.079160,0.000000
58.340004,65.438507,-81.044296,0.004402,0.003116,0.079134,291.085022,14.828578,0.791338,-81.044296,0.079160,0.000000
58.530003,65.431793,-81.044296,0.004398,0.003116,0.079134,291.055145,14.827056,0.791338,-81.044296,0.079160,0.000000
58.720001,65.402390,-80.999809,0.004398,0.003116,0.079134,290.924347,14.820393,0.791338,-80.999809,0.079160,0.000000
58.910004,65.383026,-81.088776,0.004398,0.003116,0.079134,290.838226,14.816006,0.791338,-81.088776,0.079160,0.000000
59.100002,65.369980,-81.044296,0.004402,0.003116,0.079134,290.780182,14.813048,0.791338,-81.044296,0.079160,0.000000
59.290001,65.355835,-81.044296,0.004393,0.003116,0.079134,290.717285,14.809844,0.791338,-81.044296,0.079160,0.000000
59.480003,65.318604,-81.088776,0.004398,0.003116,0.079134,290.551666,14.801407,0.791338,-81.088776,0.079160,0.000000
59.670002,65.312637,-81.044296,0.004398,0.003116,0.079134,290.525116,14.800055,0.791338,-81.044296,0.079160,0.000000
59.860004,65.289551,-81.088776,0.004393,0.003116,0.079134,290.422424,14.794824,0.791338,-81.088776,0.079160,0.000000
60.050003,65.275406,-81.088776,0.004398,0.003116,0.079134,290.359497,14.791618,0.791338,-81.088776,0.079160,0.000000
60.240002,65.263855,-81.044296,0.004398,0.003116,0.079134,290.308136,14.789001,0.791338,-81.044296,0.079160,0.000000
60.430004,65.247101,-81.088776,0.004393,0.003116,0.079134,290.233612,14.785204,0.791338,-81.088776,0.079160,0.000000
60.620003,65.242264,-81.044296,0.004398,0.003116,0.079134,290.212097,14.784108,0.791338,-81.044296,0.079160,0.000000
60.810001,65.214706,-81.088776,0.004389,0.003116,0.079134,290.089508,14.777864,0.791338,-81.088776,0.079160,0.000000
61.000004,65.206512,-81.088776,0.004398,0.003116,0.079134,290.053040,14.776007,0.791338,-81.088776,0.079160,0.000000
61.190002,65.189758,-81.044296,0.004406,0.003116,0.079134,289.978516,14.772210,0.791338,-81.044296,0.079160,0.000000
61.380001,65.186035,-81.088776,0.004393,0.003116,0.079134,289.961975,14.771367,0.791338,-81.088776,0.079160,0.000000
61.570004,65.170395,-81.177734,0.004398,0.003116,0.079134,289.892395,14.767822,0.791338,-81.177734,0.079160,0.000000
61.760002,65.152527,-81.133255,0.004389,0.003116,0.079134,289.812927,14.763774,0.791338,-81.133255,0.079160,0.000000
61.950005,65.143585,-81.133255,0.004406,0.003116,0.079134,289.773132,14.761747,0.791338,-81.133255,0.079160,0.000000
62.140003,65.125717,-81.133255,0.004398,0.003116,0.079134,289.693665,14.757698,0.791338,-81.133255,0.079160,0.000000
62.330002,65.118637,-81.222214,0.004402,0.003116,0.079134,289.662170,14.756094,0.791338,-81.222214,0.079160,0.000000
62.520004,65.107086,-81.133255,0.004398,0.003116,0.079134,289.610779,14.753476,0.791338,-81.133255,0.079160,0.000000
62.710003,65.084381,-81.177734,0.004402,0.003116,0.079134,289.509796,14.748331,0.791338,-81.177734,0.079160,0.000000
62.900002,65.082886,-81.177734,0.004402,0.003116,0.079134,289.503143,14.747993,0.791338,-81.177734,0.079160,0.000000
63.090004,65.066132,-81.133255,0.004402,0.003116,0.079134,289.428619,14.744196,0.791338,-81.133255,0.079160,0.000000
63.280003,65.064270,-81.266701,0.004389,0.003116,0.079134,289.420319,14.743774,0.791338,-81.266701,0.079160,0.000000
63.470001,65.048630,-81.177734,0.004398,0.003116,0.079134,289.350769,14.740230,0.791338,-81.177734,0.079160,0.000000
63.660004,65.038208,-81.177734,0.004402,0.003116,0.079134,289.304413,14.737868,0.791338,-81.177734,0.079160,0.000000
63.850002,65.028900,-81.177734,0.004411,0.003116,0.079134,289.263000,14.735760,0.791338,-81.177734,0.079160,0.000000
64.040001,65.026657,-81.222214,0.004389,0.003116,0.079134,289.253021,14.735251,0.791338,-81.222214,0.079160,0.000000
64.230003,65.007675,-81.177734,0.004393,0.003116,0.079134,289.168579,14.730949,0.791338,-81.177734,0.079160,0.000000
64.420006,64.992035,-81.133255,0.004398,0.003116,0.079134,289.098999,14.727406,0.791338,-81.133255,0.079160,0.000000
64.610001,64.996872,-81.177734,0.004402,0.003116,0.079134,289.120514,14.728501,0.791338,-81.177734,0.079160,0.000000
64.800003,64.974899,-81.177734,0.004402,0.003116,0.079134,289.022797,14.723523,0.791338,-81.177734,0.079160,0.000000
64.990005,64.962616,-81.177734,0.004398,0.003116,0.079134,288.968140,14.720739,0.791338,-81.177734,0.079160,0.000000
65.180000,64.966339,-81.311180,0.004398,0.003116,0.079134,288.984711,14.721582,0.791338,-81.311180,0.079160,0.000000
65.370003,64.949585,-81.222214,0.004393,0.003116,0.079134,288.910187,14.717786,0.791338,-81.222214,0.079160,0.000000
65.560005,64.941010,-81.311180,0.004398,0.003116,0.079134,288.872040,14.715843,0.791338,-81.311180,0.079160,0.000000
65.750000,64.928726,-81.266701,0.004406,0.003116,0.079134,288.817413,14.713059,0.791338,-81.266701,0.079160,0.000000
65.940002,64.922394,-81.266701,0.004398,0.003116,0.079134,288.789246,14.711624,0.791338,-81.266701,0.079160,0.000000
66.130005,64.917923,-81.222214,0.004406,0.003116,0.079134,288.769348,14.710611,0.791338,-81.222214,0.079160,0.000000
66.320000,64.898560,-81.266701,0.004398,0.003116,0.079134,288.683197,14.706223,0.791338,-81.266701,0.079160,0.000000
66.510002,64.901535,-81.266701,0.004402,0.003116,0.079134,288.696442,14.706899,0.791338,-81.266701,0.079160,0.000000
66.700005,64.897812,-81.311180,0.004406,0.003116,0.079134,288.679871,14.706054,0.791338,-81.311180,0.079160,0.000000
66.889999,64.903030,-81.311180,0.004385,0.003116,0.079134,288.703094,14.707237,0.791338,-81.311180,0.079160,0.000000
67.080002,64.887772,-81.311180,0.004398,0.003116,0.079134,288.635223,14.703779,0.791338,-81.311180,0.079160,0.000000
67.270004,64.872864,-81.311180,0.004393,0.003116,0.079134,288.568909,14.700401,0.791338,-81.311180,0.079160,0.000000
67.460007,64.871384,-81.355659,0.004406,0.003116,0.079134,288.562317,14.700066,0.791338,-81.355659,0.079160,0.000000
67.650002,64.856491,-81.355659,0.004402,0.003116,0.079134,288.496094,14.696691,0.791338,-81.355659,0.079160,0.000000
67.840004,64.844940,-81.266701,0.004393,0.003116,0.079134,288.444702,14.694074,0.791338,-81.266701,0.079160,0.000000
68.030006,64.856857,-81.311180,0.004393,0.003116,0.079134,288.497711,14.696774,0.791338,-81.311180,0.079160,0.000000
68.220001,64.838989,-81.266701,0.004398,0.003116,0.079134,288.418243,14.692725,0.791338,-81.266701,0.079160,0.000000
68.410004,64.830048,-81.311180,0.004402,0.003116,0.079134,288.378448,14.690699,0.791338,-81.311180,0.079160,0.000000
68.600006,64.836746,-81.311180,0.004406,0.003116,0.079134,288.408264,14.692217,0.791338,-81.311180,0.079160,0.000000
68.790001,64.817764,-81.266701,0.004402,0.003116,0.079134,288.323822,14.687915,0.791338,-81.266701,0.079160,0.000000
68.980003,64.813293,-81.400139,0.004406,0.003116,0.079134,288.303925,14.686902,0.791338,-81.400139,0.079160,0.000000
69.170006,64.822220,-81.311180,0.004398,0.003116,0.079134,288.343628,14.688925,0.791338,-81.311180,0.079160,0.000000
69.360001,64.801376,-81.400139,0.004398,0.003116,0.079134,288.250916,14.684201,0.791338,-81.400139,0.079160,0.000000
69.550003,64.796539,-81.355659,0.004411,0.003116,0.079134,288.229401,14.683105,0.791338,-81.355659,0.079160,0.000000
69.740005,64.802124,-81.355659,0.004398,0.003116,0.079134,288.254242,14.684371,0.791338,-81.355659,0.079160,0.000000
69.930000,64.791321,-81.444618,0.004393,0.003116,0.079134,288.206177,14.681923,0.791338,-81.444618,0.079160,0.000000
70.120003,64.780899,-81.355659,0.004406,0.003116,0.079134,288.159821,14.679562,0.791338,-81.355659,0.079160,0.000000
70.310005,64.776794,-81.400139,0.004393,0.003116,0.079134,288.141571,14.678632,0.791338,-81.400139,0.079160,0.000000
70.500000,64.770462,-81.444618,0.004398,0.003116,0.079134,288.113403,14.677197,0.791338,-81.444618,0.079160,0.000000
70.690002,64.767120,-81.355659,0.004398,0.003116,0.079134,288.098541,14.676439,0.791338,-81.355659,0.079160,0.000000
70.880005,64.751846,-81.444618,0.004402,0.003116,0.079134,288.030609,14.672977,0.791338,-81.444618,0.079160,0.000000
71.070000,64.754089,-81.355659,0.004402,0.003116,0.079134,288.040588,14.673486,0.791338,-81.355659,0.079160,0.000000
71.260002,64.754822,-81.400139,0.004393,0.003116,0.079134,288.043823,14.673653,0.791338,-81.400139,0.079160,0.000000
71.450005,64.746262,-81.400139,0.004402,0.003116,0.079134,288.005768,14.671712,0.791338,-81.400139,0.079160,0.000000
71.640007,64.738068,-81.444618,0.004393,0.003116,0.079134,287.969299,14.669856,0.791338,-81.444618,0.079160,0.000000
71.830002,64.737320,-81.444618,0.004406,0.003116,0.079134,287.965973,14.669686,0.791338,-81.444618,0.079160,0.000000
72.020004,64.722809,-81.444618,0.004398,0.003116,0.079134,287.901428,14.666399,0.791338,-81.444618,0.079160,0.000000
72.210007,64.710892,-81.400139,0.004398,0.003116,0.079134,287.848419,14.663698,0.791338,-81.400139,0.079160,0.000000
72.400002,64.703445,-81.444618,0.004389,0.003116,0.079134,287.815308,14.662010,0.791338,-81.444618,0.079160,0.000000
72.590004,64.709778,-81.400139,0.004406,0.003116,0.079134,287.843475,14.663445,0.791338,-81.400139,0.079160,0.000000
72.780006,64.696732,-81.489105,0.004406,0.003116,0.079134,287.785431,14.660489,0.791338,-81.489105,0.079160,0.000000
72.970001,64.697113,-81.444618,0.004402,0.003116,0.079134,287.787140,14.660576,0.791338,-81.444618,0.079160,0.000000
73.160004,64.693390,-81.489105,0.004406,0.003116,0.079134,287.770569,14.659732,0.791338,-81.489105,0.079160,0.000000
73.350006,64.684814,-81.489105,0.004398,0.003116,0.079134,287.732422,14.657789,0.791338,-81.489105,0.079160,0.000000
73.540001,64.694870,-81.400139,0.004398,0.003116,0.079134,287.777161,14.660068,0.791338,-81.400139,0.079160,0.000000
73.730003,64.670670,-81.533585,0.004402,0.003116,0.079134,287.669495,14.654583,0.791338,-81.533585,0.079160,0.000000
73.920006,64.663223,-81.444618,0.004406,0.003116,0.079134,287.636383,14.652895,0.791338,-81.444618,0.079160,0.000000
74.110001,64.662476,-81.489105,0.004393,0.003116,0.079134,287.633057,14.652726,0.791338,-81.489105,0.079160,0.000000
74.300003,64.660248,-81.533585,0.004402,0.003116,0.079134,287.623138,14.652222,0.791338,-81.533585,0.079160,0.000000
74.490005,64.649078,-81.489105,0.004402,0.003116,0.079134,287.573456,14.649691,0.791338,-81.489105,0.079160,0.000000
74.680000,64.645721,-81.533585,0.004398,0.003116,0.079134,287.558533,14.648930,0.791338,-81.533585,0.079160,0.000000
74.870003,64.643494,-81.489105,0.004406,0.003116,0.079134,287.548615,14.648425,0.791338,-81.489105,0.079160,0.000000
75.060005,64.646088,-81.489105,0.004398,0.003116,0.079134,287.560150,14.649013,0.791338,-81.489105,0.079160,0.000000
75.250000,64.636047,-81.489105,0.004406,0.003116,0.079134,287.515503,14.646737,0.791338,-81.489105,0.079160,0.000000
75.440002,64.627853,-81.489105,0.004393,0.003116,0.079134,287.479034,14.644881,0.791338,-81.489105,0.079160,0.000000
75.630005,64.627853,-81.578064,0.004398,0.003116,0.079134,287.479034,14.644881,0.791338,-81.578064,0.079160,0.000000
75.820007,64.619659,-81.578064,0.004402,0.003116,0.079134,287.442596,14.643024,0.791338,-81.578064,0.079160,0.000000
76.010002,64.609604,-81.533585,0.004393,0.003116,0.079134,287.397858,14.640746,0.791338,-81.533585,0.079160,0.000000
76.200005,64.606247,-81.578064,0.004393,0.003116,0.079134,287.382935,14.639985,0.791338,-81.578064,0.079160,0.000000
76.390007,64.595825,-81.578064,0.004398,0.003116,0.079134,287.336578,14.637623,0.791338,-81.578064,0.079160,0.000000
76.580002,64.598801,-81.622543,0.004393,0.003116,0.079134,287.349823,14.638297,0.791338,-81.622543,0.079160,0.000000
76.770004,64.600662,-81.533585,0.004402,0.003116,0.079134,287.358093,14.638720,0.791338,-81.533585,0.079160,0.000000
76.960007,64.593216,-81.578064,0.004402,0.003116,0.079134,287.324982,14.637032,0.791338,-81.578064,0.079160,0.000000
77.150002,64.578323,-81.578064,0.004406,0.003116,0.079134,287.258728,14.633657,0.791338,-81.578064,0.079160,0.000000
77.340004,64.592468,-81.533585,0.004406,0.003116,0.079134,287.321655,14.636862,0.791338,-81.533585,0.079160,0.000000
77.530006,64.580551,-81.622543,0.004406,0.003116,0.079134,287.268646,14.634162,0.791338,-81.622543,0.079160,0.000000
77.720001,64.569763,-81.578064,0.004406,0.003116,0.079134,287.220642,14.631718,0.791338,-81.578064,0.079160,0.000000
77.910004,64.561935,-81.667023,0.004402,0.003116,0.079134,287.185822,14.629944,0.791338,-81.667023,0.079160,0.000000
78.100006,64.560822,-81.667023,0.004406,0.003116,0.079134,287.180878,14.629691,0.791338,-81.667023,0.079160,0.000000
78.290001,64.535507,-81.622543,0.004398,0.003116,0.079134,287.068268,14.623955,0.791338,-81.622543,0.079160,0.000000
78.480003,64.536987,-81.667023,0.004398,0.003116,0.079134,287.074860,14.624290,0.791338,-81.667023,0.079160,0.000000
78.670006,64.545547,-81.622543,0.004398,0.003116,0.079134,287.112946,14.626230,0.791338,-81.622543,0.079160,0.000000
78.860001,64.529907,-81.667023,0.004402,0.003116,0.079134,287.043365,14.622686,0.791338,-81.667023,0.079160,0.000000
79.050003,64.541824,-81.711510,0.004411,0.003116,0.079134,287.096375,14.625386,0.791338,-81.711510,0.079160,0.000000
79.240005,64.525070,-81.667023,0.004402,0.003116,0.079134,287.021851,14.621590,0.791338,-81.667023,0.079160,0.000000
79.430000,64.519119,-81.667023,0.004411,0.003116,0.079134,286.995361,14.620241,0.791338,-81.667023,0.079160,0.000000
79.620003,64.525070,-81.622543,0.004406,0.003116,0.079134,287.021851,14.621590,0.791338,-81.622543,0.079160,0.000000
79.810005,64.508682,-81.622543,0.004385,0.003116,0.079134,286.948944,14.617876,0.791338,-81.622543,0.079160,0.000000
80.000000,64.490067,-81.667023,0.004398,0.003116,0.079134,286.866150,14.613658,0.791338,-81.667023,0.079160,0.000000
80.190002,64.509430,-81.755989,0.004402,0.003116,0.079134,286.952271,14.618046,0.791338,-81.755989,0.079160,0.000000
80.380005,64.505341,-81.711510,0.004393,0.003116,0.079134,286.934082,14.617119,0.791338,-81.711510,0.079160,0.000000
80.570007,64.478149,-81.667023,0.004406,0.003116,0.079134,286.813141,14.610958,0.791338,-81.667023,0.079160,0.000000
80.760002,64.488586,-81.622543,0.004406,0.003116,0.079134,286.859558,14.613322,0.791338,-81.622543,0.079160,0.000000
80.950005,64.491562,-81.667023,0.004398,0.003116,0.079134,286.872803,14.613997,0.791338,-81.667023,0.079160,0.000000
81.140007,64.472565,-81.622543,0.004398,0.003116,0.079134,286.788300,14.609693,0.791338,-81.622543,0.079160,0.000000
81.330002,64.478531,-81.755989,0.004398,0.003116,0.079134,286.814819,14.611044,0.791338,-81.755989,0.079160,0.000000
81.520004,64.466980,-81.667023,0.004393,0.003116,0.079134,286.763458,14.608427,0.791338,-81.667023,0.079160,0.000000
81.710007,64.451340,-81.711510,0.004398,0.003116,0.079134,286.693878,14.604882,0.791338,-81.711510,0.079160,0.000000
81.900002,64.459534,-81.711510,0.004411,0.003116,0.079134,286.730316,14.606739,0.791338,-81.711510,0.079160,0.000000
82.090004,64.458420,-81.711510,0.004402,0.003116,0.079134,286.725372,14.606486,0.791338,-81.711510,0.079160,0.000000
82.100006,64.459167,-81.711510,0.004402,0.003116,0.079134,286.728699,14.606656,0.791338,-81.711510,0.079160,0.000000