File: Data/compression 6/AutoNoheating-10-6-day2-5-240229_02292024_170950.csv
Time (sec),S:Load (lbs),S:HL1 (DIM),S:LVDT (in),S:Position (in),Ch:Position (mm),Ch:Load (N),Ch:Stress (MPa),Ch:Strain (mm/mm),Ch:HL1 (DIM),Set Point (),Cycles ()
0.010000,-0.005211,-89.718079,0.000004,-0.000000,-0.000000,-0.023179,-0.001181,-0.000000,-89.718079,0.000156,0.000000
0.310000,0.002235,-89.762558,-0.000013,-0.000000,-0.000000,0.009944,0.000507,-0.000000,-89.762558,0.000156,0.000000
0.610000,-0.016014,-89.718079,0.000004,0.000158,0.004015,-0.071234,-0.003629,0.040150,-89.718079,0.004926,0.000000
0.910000,0.002609,-89.718079,0.000177,0.000349,0.008863,0.011607,0.000591,0.088627,-89.718079,0.009938,0.000000
1.210000,-0.019363,-89.762558,0.000379,0.000549,0.013944,-0.086133,-0.004388,0.139443,-89.762558,0.014933,0.000000
1.510000,0.020851,-89.762558,0.000578,0.000741,0.018809,0.092750,0.004725,0.188094,-89.762558,0.019928,0.000000
1.810000,-0.006699,-89.762558,0.000767,0.000936,0.023779,-0.029797,-0.001518,0.237790,-89.762558,0.024924,0.000000
2.110000,0.028297,-89.807037,0.000966,0.001132,0.028749,0.125873,0.006412,0.287485,-89.807037,0.029919,0.000000
2.410000,-0.027931,-89.762558,0.001164,0.001326,0.033692,-0.124244,-0.006329,0.336916,-89.762558,0.034914,0.000000
2.710000,-0.014893,-89.851524,0.001354,0.001523,0.038695,-0.066245,-0.003375,0.386953,-89.851524,0.039909,0.000000
3.010000,-0.016380,-89.807037,0.001574,0.001726,0.043829,-0.072863,-0.003712,0.438291,-89.807037,0.044922,0.000000
3.310000,0.015266,-89.851524,0.001772,0.001927,0.048937,0.067908,0.003459,0.489372,-89.851524,0.049917,0.000000
3.610000,0.012291,-89.807037,0.001979,0.002124,0.053958,0.054673,0.002785,0.539582,-89.807037,0.054912,0.000000
3.910000,0.035378,-89.851524,0.002186,0.002321,0.058963,0.157367,0.008017,0.589626,-89.851524,0.059907,0.000000
4.210000,0.017876,-89.851524,0.002358,0.002509,0.063732,0.079515,0.004051,0.637323,-89.851524,0.064903,0.000000
4.510000,-0.028297,-89.851524,0.002561,0.002709,0.068797,-0.125873,-0.006412,0.687965,-89.851524,0.069898,0.000000
4.810000,0.019363,-89.851524,0.002755,0.002903,0.073749,0.086133,0.004388,0.737487,-89.851524,0.074911,0.000000
5.110000,-0.051018,-89.851524,0.002971,0.003104,0.078830,-0.226938,-0.011561,0.788303,-89.851524,0.079906,0.000000
5.410000,0.041710,-89.851524,0.003160,0.003295,0.083704,0.185535,0.009452,0.837045,-89.851524,0.084901,0.000000
5.710000,-0.011917,-89.851524,0.003367,0.003499,0.088881,-0.053010,-0.002700,0.888814,-89.851524,0.089897,0.000000
6.010000,0.025322,-89.851524,0.003561,0.003694,0.093834,0.112638,0.005738,0.938336,-89.851524,0.094891,0.000000
6.310000,0.002235,-89.896004,0.003768,0.003887,0.098734,0.009944,0.000507,0.987335,-89.896004,0.099886,0.000000
6.610000,0.016754,-89.896004,0.003971,0.004086,0.103772,0.074526,0.003797,1.037720,-89.896004,0.104882,0.000000
6.910000,0.011169,-89.940483,0.004152,0.004283,0.108793,0.049684,0.002531,1.087930,-89.940483,0.109894,0.000000
7.210001,-0.004471,-89.896004,0.004363,0.004484,0.113901,-0.019887,-0.001013,1.139011,-89.896004,0.114890,0.000000
7.510000,0.036491,-89.984962,0.004553,0.004677,0.118784,0.162322,0.008269,1.187836,-89.984962,0.119885,0.000000
7.810000,0.005211,-89.940483,0.004756,0.004877,0.123883,0.023179,0.001181,1.238826,-89.940483,0.124880,0.000000
8.110001,0.040215,-89.896004,0.004941,0.005068,0.128739,0.178883,0.009113,1.287394,-89.896004,0.129876,0.000000
8.410001,-0.004471,-89.984962,0.005139,0.005266,0.133760,-0.019887,-0.001013,1.337605,-89.984962,0.134871,0.000000
8.710000,0.034630,-89.984962,0.005333,0.005459,0.138660,0.154041,0.007847,1.386604,-89.984962,0.139883,0.000000
9.010000,-0.009682,-89.940483,0.005540,0.005657,0.143681,-0.043066,-0.002194,1.436814,-89.940483,0.144878,0.000000
9.310000,0.006706,-89.984962,0.005734,0.005855,0.148712,0.029831,0.001520,1.487116,-89.984962,0.149874,0.000000
9.610001,0.027184,-89.940483,0.005950,0.006059,0.153906,0.120918,0.006160,1.539059,-89.940483,0.154869,0.000000
9.910001,0.044685,-90.029442,0.006157,0.006257,0.158928,0.198770,0.010126,1.589277,-90.029442,0.159864,0.000000
10.210000,0.040962,-90.029442,0.006338,0.006453,0.163906,0.182209,0.009282,1.639056,-90.029442,0.164859,0.000000
10.510000,0.020111,-90.029442,0.006545,0.006647,0.168822,0.089459,0.004557,1.688222,-90.029442,0.169872,0.000000
10.810000,0.029419,-90.029442,0.006743,0.006834,0.173584,0.130862,0.006666,1.735836,-90.029442,0.174867,0.000000
11.110001,-0.020851,-90.029442,0.006937,0.007038,0.178770,-0.092750,-0.004725,1.787697,-90.029442,0.179862,0.000000
11.410001,0.056602,-90.029442,0.007127,0.007229,0.183609,0.251780,0.012826,1.836090,-90.029442,0.184857,0.000000
11.710001,0.023834,-90.118408,0.007330,0.007433,0.188786,0.106020,0.005401,1.887860,-90.118408,0.189853,0.000000
12.010000,0.072243,-90.073929,0.007528,0.007627,0.193721,0.321352,0.016370,1.937208,-90.073929,0.194848,0.000000
12.310000,0.036118,-90.073929,0.007735,0.007828,0.198837,0.160659,0.008184,1.988372,-90.073929,0.199843,0.000000
12.610001,0.068520,-90.073929,0.007929,0.008023,0.203780,0.304790,0.015527,2.037803,-90.073929,0.204856,0.000000
12.910001,0.093468,-90.073929,0.008136,0.008216,0.208680,0.415765,0.021180,2.086802,-90.073929,0.209851,0.000000
13.210001,0.209648,-90.118408,0.008317,0.008416,0.213771,0.932561,0.047507,2.137709,-90.118408,0.214846,0.000000
13.510000,0.589462,-90.073929,0.008511,0.008613,0.218766,2.622059,0.133574,2.187662,-90.073929,0.219841,0.000000
13.810000,0.624100,-90.118408,0.008571,-0.000001,-0.000026,2.776134,0.141423,-0.000257,-90.118408,0.000052,0.000000
14.110001,0.590584,-90.118408,0.008571,-0.000001,-0.000026,2.627048,0.133828,-0.000257,-90.118408,0.000052,0.000000
14.410001,0.564148,-90.118408,0.008563,-0.000001,-0.000026,2.509455,0.127838,-0.000257,-90.118408,0.000512,0.000000
14.710001,0.556694,-90.118408,0.008576,-0.000001,-0.000017,2.476299,0.126149,-0.000174,-90.118408,0.001015,0.000000
15.010001,0.675484,-90.162888,0.008593,0.000023,0.000590,3.004702,0.153067,0.005897,-90.162888,0.001509,0.000000
15.310000,0.764481,-90.162888,0.008584,0.000045,0.001136,3.400579,0.173234,0.011362,-90.162888,0.002012,0.000000
15.610001,0.826294,-90.162888,0.008623,0.000060,0.001535,3.675539,0.187241,0.015352,-90.162888,0.002515,0.000000
15.910001,0.933167,-90.251846,0.008627,0.000085,0.002168,4.150932,0.211459,0.021680,-90.251846,0.003010,0.000000
16.210001,1.009872,-90.162888,0.008658,0.000101,0.002576,4.492137,0.228840,0.025760,-90.162888,0.003512,0.000000
16.510000,1.086586,-90.207367,0.008670,0.000126,0.003201,4.833376,0.246224,0.032005,-90.207367,0.004015,0.000000
16.810001,1.139832,-90.207367,0.008688,0.000143,0.003633,5.070224,0.258290,0.036335,-90.207367,0.004509,0.000000
17.110001,1.198669,-90.251846,0.008722,0.000161,0.004102,5.331948,0.271622,0.041021,-90.251846,0.005013,0.000000
17.410002,1.315590,-90.207367,0.008731,0.000185,0.004709,5.852036,0.298117,0.047092,-90.207367,0.005515,0.000000
17.710001,1.365494,-90.251846,0.008757,0.000203,0.005169,6.074019,0.309425,0.051687,-90.251846,0.006010,0.000000
18.010000,1.430283,-90.207367,0.008778,0.000220,0.005585,6.362215,0.324107,0.055850,-90.207367,0.006513,0.000000
18.310001,1.560242,-90.251846,0.008783,0.000241,0.006114,6.940302,0.353556,0.061141,-90.251846,0.007016,0.000000
18.610001,1.633598,-90.296333,0.008813,0.000265,0.006739,7.266608,0.370179,0.067386,-90.296333,0.007510,0.000000
18.910002,1.700623,-90.251846,0.008839,0.000284,0.007216,7.564747,0.385367,0.072155,-90.251846,0.008013,0.000000
19.210001,1.755363,-90.251846,0.008852,0.000304,0.007710,7.808247,0.397771,0.077098,-90.251846,0.008508,0.000000
19.510000,1.880112,-90.251846,0.008864,0.000324,0.008239,8.363154,0.426039,0.082390,-90.251846,0.009010,0.000000
19.810001,1.954956,-90.251846,0.008890,0.000341,0.008673,8.696079,0.442999,0.086727,-90.251846,0.009514,0.000000
20.110001,2.012672,-90.296333,0.008921,0.000356,0.009054,8.952814,0.456078,0.090542,-90.296333,0.010008,0.000000
20.410002,2.207054,-90.251846,0.008938,0.000382,0.009704,9.817467,0.500126,0.097045,-90.251846,0.010511,0.000000
20.710001,2.266258,-90.296333,0.008968,0.000404,0.010259,10.080820,0.513541,0.102593,-90.296333,0.011014,0.000000
21.010000,2.255836,-90.340813,0.008972,0.000418,0.010623,10.034462,0.511180,0.106234,-90.340813,0.011508,0.000000
21.310001,2.418930,-90.340813,0.008994,0.000441,0.011205,10.759938,0.548137,0.112048,-90.340813,0.012011,0.000000
21.610001,2.572350,-90.296333,0.009020,0.000464,0.011777,11.442382,0.582903,0.117771,-90.296333,0.012514,0.000000
21.910002,2.589104,-90.296333,0.009033,0.000477,0.012106,11.516909,0.586699,0.121064,-90.296333,0.013009,0.000000
22.210001,2.769707,-90.385292,0.009050,0.000498,0.012653,12.320271,0.627625,0.126529,-90.385292,0.013511,0.000000
22.510000,2.871735,-90.296333,0.009067,0.000520,0.013199,12.774114,0.650744,0.131994,-90.296333,0.014015,0.000000
22.810001,2.918655,-90.385292,0.009089,0.000539,0.013694,12.982827,0.661377,0.136937,-90.385292,0.014509,0.000000
23.110001,3.053085,-90.385292,0.009115,0.000559,0.014188,13.580802,0.691839,0.141881,-90.385292,0.015012,0.000000
23.410002,3.223999,-90.429771,0.009115,0.000581,0.014751,14.341063,0.730569,0.147512,-90.429771,0.015515,0.000000
23.710001,3.305550,-90.429771,0.009149,0.000600,0.015237,14.703819,0.749048,0.152372,-90.429771,0.016009,0.000000
24.010000,3.285812,-90.429771,0.009153,0.000613,0.015558,14.616023,0.744576,0.155582,-90.429771,0.016512,0.000000
24.310001,3.587067,-90.429771,0.009179,0.000636,0.016148,15.956069,0.812841,0.161479,-90.429771,0.017015,0.000000
24.610001,3.642174,-90.429771,0.009188,0.000657,0.016685,16.201199,0.825328,0.166853,-90.429771,0.017510,0.000000
24.910002,3.654839,-90.385292,0.009209,0.000672,0.017076,16.257534,0.828198,0.170759,-90.385292,0.018012,0.000000
25.210001,3.825012,-90.385292,0.009227,0.000691,0.017561,17.014503,0.866760,0.175612,-90.385292,0.018516,0.000000
25.510002,4.109505,-90.474251,0.009253,0.000719,0.018255,18.279989,0.931227,0.182553,-90.474251,0.019010,0.000000
25.810001,4.049179,-90.474251,0.009270,0.000731,0.018576,18.011648,0.917557,0.185763,-90.474251,0.019513,0.000000
26.110001,4.192917,-90.429771,0.009296,0.000751,0.019079,18.651026,0.950129,0.190789,-90.429771,0.020016,0.000000
26.410002,4.406281,-90.563217,0.009313,0.000776,0.019712,19.600115,0.998477,0.197125,-90.563217,0.020510,0.000000
26.710001,4.438683,-90.474251,0.009339,0.000794,0.020163,19.744246,1.005820,0.201629,-90.474251,0.021013,0.000000
27.010002,4.469963,-90.563217,0.009343,0.000809,0.020553,19.883389,1.012908,0.205535,-90.563217,0.021516,0.000000
27.310001,4.691895,-90.518738,0.009360,0.000830,0.021091,20.870588,1.063198,0.210909,-90.518738,0.022011,0.000000
27.610001,4.728012,-90.563217,0.009369,0.000846,0.021499,21.031248,1.071383,0.214990,-90.563217,0.022513,0.000000
27.910002,4.904892,-90.518738,0.009399,0.000866,0.022002,21.818048,1.111465,0.220016,-90.518738,0.023016,0.000000
28.210001,5.092194,-90.474251,0.009425,0.000889,0.022574,22.651209,1.153908,0.225739,-90.474251,0.023510,0.000000
28.510002,5.250076,-90.563217,0.009442,0.000911,0.023138,23.353506,1.189684,0.231378,-90.563217,0.024014,0.000000
28.810001,5.229973,-90.563217,0.009455,0.000928,0.023572,23.264082,1.185129,0.235716,-90.563217,0.024516,0.000000
29.110001,5.369240,-90.518738,0.009464,0.000947,0.024057,23.883572,1.216687,0.240568,-90.518738,0.025011,0.000000
29.410002,5.544250,-90.563217,0.009485,0.000966,0.024543,24.662058,1.256345,0.245428,-90.563217,0.025514,0.000000
29.710001,5.584099,-90.563217,0.009498,0.000982,0.024942,24.839312,1.265375,0.249417,-90.563217,0.026017,0.000000
30.010002,5.723366,-90.607697,0.009507,0.001002,0.025453,25.458803,1.296933,0.254534,-90.607697,0.026511,0.000000
30.310001,5.970993,-90.607697,0.009533,0.001026,0.026069,26.560303,1.353046,0.260688,-90.607697,0.027014,0.000000
30.610001,6.055893,-90.696663,0.009559,0.001047,0.026606,26.937958,1.372285,0.266063,-90.696663,0.027517,0.000000
30.910002,6.037651,-90.607697,0.009576,0.001061,0.026954,26.856813,1.368151,0.269538,-90.607697,0.028011,0.000000
31.210001,6.321022,-90.607697,0.009593,0.001082,0.027474,28.117310,1.432364,0.274738,-90.607697,0.028515,0.000000
31.510002,6.471832,-90.607697,0.009602,0.001102,0.028003,28.788147,1.466538,0.280029,-90.607697,0.029017,0.000000
31.810001,6.540352,-90.607697,0.009628,0.001121,0.028471,29.092937,1.482065,0.284715,-90.607697,0.029512,0.000000
32.110001,6.843086,-90.652176,0.009636,0.001148,0.029165,30.439568,1.550665,0.291649,-90.652176,0.030015,0.000000
32.410000,6.845322,-90.696663,0.009662,0.001164,0.029564,30.449511,1.551172,0.295638,-90.696663,0.030509,0.000000
32.710003,6.958527,-90.652176,0.009675,0.001185,0.030101,30.953072,1.576825,0.301013,-90.652176,0.031012,0.000000
33.010002,6.887032,-90.652176,0.009684,0.001198,0.030431,30.635046,1.560624,0.304313,-90.652176,0.031515,0.000000
33.310001,7.313766,-90.696663,0.009714,0.001225,0.031107,32.533257,1.657323,0.311073,-90.696663,0.032010,0.000000
33.610001,7.286209,-90.696663,0.009718,0.001242,0.031541,32.410675,1.651079,0.315410,-90.696663,0.032512,0.000000
33.910000,7.561768,-90.696663,0.009748,0.001264,0.032113,33.636421,1.713521,0.321133,-90.696663,0.033016,0.000000
34.210003,7.784073,-90.696663,0.009770,0.001287,0.032695,34.625286,1.763896,0.326947,-90.696663,0.033510,0.000000
34.510002,7.745346,-90.652176,0.009783,0.001305,0.033137,34.453018,1.755121,0.331368,-90.652176,0.034013,0.000000
34.810001,7.731941,-90.696663,0.009804,0.001320,0.033527,34.393391,1.752083,0.335274,-90.696663,0.034516,0.000000
35.110001,8.071175,-90.785622,0.009813,0.001343,0.034117,35.902378,1.828954,0.341170,-90.785622,0.035010,0.000000
35.410000,8.147507,-90.741142,0.009822,0.001360,0.034533,36.241920,1.846251,0.345334,-90.741142,0.035513,0.000000
35.710003,8.057396,-90.785622,0.009843,0.001371,0.034828,35.841087,1.825832,0.348278,-90.785622,0.036016,0.000000
36.010002,8.709419,-90.741142,0.009860,0.001405,0.035695,38.741432,1.973583,0.356953,-90.741142,0.036511,0.000000
36.310001,8.513176,-90.785622,0.009873,0.001420,0.036059,37.868500,1.929113,0.360595,-90.785622,0.037013,0.000000
36.610001,8.647232,-90.741142,0.009891,0.001443,0.036657,38.464809,1.959491,0.366575,-90.741142,0.037517,0.000000
36.910000,8.806610,-90.785622,0.009908,0.001459,0.037056,39.173759,1.995606,0.370564,-90.785622,0.038011,0.000000
37.210003,8.900444,-90.785622,0.009929,0.001477,0.037508,39.591152,2.016869,0.375076,-90.785622,0.038514,0.000000
37.510002,9.006943,-90.785622,0.009929,0.001497,0.038019,40.064884,2.041003,0.380193,-90.785622,0.039017,0.000000
37.810001,9.314522,-90.830101,0.009968,0.001518,0.038548,41.433064,2.110701,0.385484,-90.830101,0.039511,0.000000
38.110001,9.479485,-90.830101,0.009977,0.001539,0.039103,42.166855,2.148082,0.391033,-90.830101,0.040014,0.000000
38.410004,9.587845,-90.874580,0.009994,0.001559,0.039607,42.648865,2.172637,0.396067,-90.874580,0.040517,0.000000
38.710003,9.637001,-90.874580,0.009994,0.001582,0.040187,42.867523,2.183776,0.401873,-90.874580,0.041011,0.000000
39.010002,9.921867,-90.874580,0.010024,0.001602,0.040691,44.134670,2.248327,0.406906,-90.874580,0.041514,0.000000
39.310001,9.836594,-90.874580,0.010042,0.001617,0.041080,43.755352,2.229004,0.410805,-90.874580,0.042017,0.000000
39.610001,10.104324,-90.830101,0.010054,0.001639,0.041618,44.946278,2.289673,0.416179,-90.830101,0.042511,0.000000
39.910004,10.362381,-90.874580,0.010080,0.001660,0.042174,46.094173,2.348149,0.421736,-90.874580,0.043015,0.000000
40.210003,10.482285,-90.919067,0.010080,0.001683,0.042737,46.627529,2.375320,0.427368,-90.919067,0.043517,0.000000
40.510002,10.516914,-90.874580,0.010102,0.001700,0.043188,46.781570,2.383167,0.431879,-90.874580,0.044012,0.000000
40.810001,10.749649,-90.919067,0.010119,0.001722,0.043734,47.816826,2.435905,0.437345,-90.919067,0.044515,0.000000
41.110001,10.789124,-90.919067,0.010145,0.001739,0.044168,47.992420,2.444850,0.441682,-90.919067,0.045018,0.000000
41.410004,10.760445,-90.963547,0.010145,0.001753,0.044532,47.864849,2.438352,0.445323,-90.963547,0.045512,0.000000
41.710003,11.168938,-90.963547,0.010179,0.001780,0.045200,49.681915,2.530918,0.452000,-90.963547,0.046015,0.000000
42.010002,11.403160,-91.008026,0.010184,0.001802,0.045772,50.723789,2.583993,0.457722,-91.008026,0.046518,0.000000
42.310001,11.198357,-90.919067,0.010214,0.001816,0.046136,49.812778,2.537584,0.461364,-90.919067,0.047012,0.000000
42.610001,11.387894,-90.963547,0.010218,0.001838,0.046691,50.655880,2.580534,0.466912,-90.963547,0.047516,0.000000
42.910004,11.730850,-90.963547,0.010248,0.001861,0.047281,52.181427,2.658249,0.472809,-90.963547,0.048018,0.000000
43.210003,11.601639,-90.963547,0.010266,0.001874,0.047611,51.606667,2.628969,0.476110,-90.963547,0.048513,0.000000
43.510002,11.941238,-91.008026,0.010261,0.001897,0.048174,53.117283,2.705923,0.481741,-91.008026,0.049016,0.000000
43.810001,12.188499,-90.963547,0.010296,0.001918,0.048721,54.217152,2.761954,0.487207,-90.963547,0.049519,0.000000
44.110001,12.206367,-91.052505,0.010309,0.001938,0.049215,54.296635,2.766002,0.492150,-91.052505,0.050013,0.000000
44.410004,12.307655,-91.052505,0.010313,0.001957,0.049709,54.747185,2.788954,0.497093,-91.052505,0.050516,0.000000
44.710003,12.562729,-91.008026,0.010339,0.001978,0.050248,55.881809,2.846755,0.502475,-91.008026,0.051019,0.000000
45.010002,12.708702,-91.096985,0.010356,0.001998,0.050750,56.531132,2.879833,0.507501,-91.096985,0.051513,0.000000
45.310001,12.490860,-91.052505,0.010361,0.002011,0.051089,55.562119,2.830469,0.510885,-91.052505,0.052017,0.000000
45.610001,12.909782,-91.052505,0.010369,0.002034,0.051669,57.425579,2.925399,0.516691,-91.052505,0.052511,0.000000
45.910004,13.060219,-91.052505,0.010399,0.002054,0.052173,58.094753,2.959488,0.521725,-91.052505,0.053014,0.000000
46.210003,12.917229,-91.008026,0.010412,0.002070,0.052571,57.458702,2.927086,0.525714,-91.008026,0.053517,0.000000
46.510002,13.127243,-91.141472,0.010421,0.002089,0.053066,58.392895,2.974676,0.530657,-91.141472,0.054011,0.000000
46.810001,13.644844,-91.052505,0.010447,0.002117,0.053759,60.695297,3.091966,0.537591,-91.052505,0.054514,0.000000
47.110001,13.456421,-91.096985,0.010468,0.002130,0.054098,59.857151,3.049268,0.540975,-91.096985,0.055017,0.000000
47.410004,13.643730,-91.096985,0.010468,0.002150,0.054601,60.690342,3.091713,0.546009,-91.096985,0.055512,0.000000
47.710003,13.893219,-91.141472,0.010486,0.002174,0.055208,61.800125,3.148248,0.552080,-91.141472,0.056014,0.000000
48.010002,13.914070,-91.096985,0.010494,0.002192,0.055676,61.892876,3.152973,0.556758,-91.096985,0.056518,0.000000
48.310001,13.871246,-91.185951,0.010529,0.002208,0.056075,61.702385,3.143269,0.560747,-91.185951,0.057012,0.000000
48.610001,13.809433,-91.096985,0.010537,0.002226,0.056552,61.427425,3.129262,0.565516,-91.096985,0.057515,0.000000
48.910004,14.090202,-91.185951,0.010546,0.002245,0.057012,62.676350,3.192886,0.570119,-91.185951,0.058017,0.000000
49.210003,14.310272,-91.185951,0.010576,0.002264,0.057497,63.655270,3.242754,0.574971,-91.185951,0.058512,0.000000
49.510002,14.634613,-91.096985,0.010585,0.002287,0.058078,65.098007,3.316251,0.580785,-91.096985,0.059015,0.000000
49.810001,14.884476,-91.230431,0.010593,0.002309,0.058651,66.209457,3.372870,0.586507,-91.230431,0.059517,0.000000
50.110001,14.731796,-91.141472,0.010606,0.002326,0.059084,65.530304,3.338273,0.590845,-91.141472,0.060012,0.000000
50.410004,14.826012,-91.141472,0.010632,0.002344,0.059535,65.949394,3.359622,0.595349,-91.141472,0.060515,0.000000
50.710003,14.955223,-91.185951,0.010637,0.002364,0.060038,66.524155,3.388902,0.600383,-91.185951,0.061018,0.000000
51.010002,14.894524,-91.185951,0.010645,0.002378,0.060411,66.254150,3.375147,0.604107,-91.185951,0.061512,0.000000
51.310001,14.921341,-91.230431,0.010680,0.002397,0.060879,66.373436,3.381224,0.608793,-91.230431,0.062016,0.000000
51.610001,15.432602,-91.230431,0.010693,0.002422,0.061521,68.647644,3.497078,0.615212,-91.230431,0.062518,0.000000
51.910004,15.550644,-91.274910,0.010688,0.002444,0.062085,69.172722,3.523826,0.620851,-91.274910,0.063012,0.000000
52.210003,15.477287,-91.274910,0.010727,0.002460,0.062475,68.846413,3.507203,0.624750,-91.274910,0.063516,0.000000
52.510002,15.766251,-91.230431,0.010723,0.002480,0.062995,70.131783,3.572684,0.629950,-91.230431,0.064018,0.000000
52.810001,15.859344,-91.274910,0.010744,0.002500,0.063498,70.545891,3.593779,0.634984,-91.274910,0.064513,0.000000
53.110004,15.785988,-91.274910,0.010762,0.002517,0.063923,70.219582,3.577156,0.639231,-91.274910,0.065016,0.000000
53.410004,16.340446,-91.274910,0.010779,0.002544,0.064626,72.685936,3.702798,0.646256,-91.274910,0.065519,0.000000
53.710003,16.282356,-91.274910,0.010787,0.002561,0.065059,72.427536,3.689635,0.650593,-91.274910,0.066013,0.000000
54.010002,16.361671,-91.319389,0.010805,0.002583,0.065597,72.780350,3.707608,0.655968,-91.319389,0.066516,0.000000
54.310001,16.128197,-91.319389,0.010822,0.002599,0.066005,71.741798,3.654702,0.660048,-91.319389,0.067019,0.000000
54.610004,16.782829,-91.274910,0.010848,0.002623,0.066620,74.653755,3.803043,0.666202,-91.274910,0.067513,0.000000
54.910004,16.525520,-91.319389,0.010852,0.002639,0.067028,73.509186,3.744736,0.670282,-91.319389,0.068017,0.000000
55.210003,16.811127,-91.319389,0.010874,0.002660,0.067574,74.779625,3.809456,0.675740,-91.319389,0.068519,0.000000
55.510002,17.183128,-91.408356,0.010887,0.002685,0.068199,76.434372,3.893752,0.681985,-91.408356,0.069014,0.000000
55.810001,16.979439,-91.363876,0.010904,0.002702,0.068641,75.528313,3.847596,0.686413,-91.363876,0.069517,0.000000
56.110004,16.868103,-91.363876,0.010917,0.002717,0.069014,75.033073,3.822367,0.690138,-91.363876,0.070020,0.000000
56.410004,17.318298,-91.319389,0.010930,0.002742,0.069647,77.035637,3.924382,0.696474,-91.319389,0.070514,0.000000
56.710003,17.236374,-91.363876,0.010943,0.002758,0.070046,76.671219,3.905818,0.700463,-91.363876,0.071017,0.000000
57.010002,16.942200,-91.408356,0.010951,0.002770,0.070349,75.362671,3.839157,0.703491,-91.408356,0.071520,0.000000
57.310001,17.978516,-91.363876,0.010977,0.002804,0.071217,79.972435,4.073990,0.712166,-91.363876,0.072014,0.000000
57.610004,17.613220,-91.408356,0.010990,0.002818,0.071581,78.347519,3.991213,0.715807,-91.408356,0.072518,0.000000
57.910004,17.631088,-91.452835,0.010994,0.002839,0.072119,78.426994,3.995262,0.721189,-91.452835,0.073020,0.000000
58.210003,17.785629,-91.408356,0.011007,0.002857,0.072578,79.114433,4.030281,0.725784,-91.408356,0.073515,0.000000
58.510002,17.788231,-91.408356,0.011037,0.002875,0.073030,79.125999,4.030870,0.730295,-91.408356,0.074018,0.000000
58.810001,17.886169,-91.363876,0.011037,0.002896,0.073558,79.561653,4.053064,0.735579,-91.363876,0.074512,0.000000
59.110004,18.166191,-91.452835,0.011055,0.002916,0.074070,80.807251,4.116518,0.740696,-91.452835,0.075015,0.000000
59.410004,18.281624,-91.452835,0.011081,0.002936,0.074573,81.320724,4.142675,0.745730,-91.452835,0.075518,0.000000
59.710003,18.525162,-91.452835,0.011094,0.002958,0.075128,82.404037,4.197862,0.751279,-91.452835,0.076013,0.000000
60.010002,18.300987,-91.452835,0.011102,0.002978,0.075631,81.406860,4.147063,0.756305,-91.452835,0.076515,0.000000
60.310001,18.870720,-91.497314,0.011128,0.003000,0.076212,83.941154,4.276166,0.762119,-91.497314,0.077018,0.000000
60.610004,18.565002,-91.497314,0.011132,0.003015,0.076593,82.581253,4.206890,0.765934,-91.497314,0.077512,0.000000
60.910004,18.767944,-91.452835,0.011145,0.003037,0.077131,83.483986,4.252877,0.771309,-91.452835,0.078016,0.000000
61.210003,19.090050,-91.497314,0.011154,0.003059,0.077686,84.916779,4.325867,0.776865,-91.497314,0.078518,0.000000
61.510002,19.198776,-91.497314,0.011175,0.003080,0.078232,85.400421,4.350505,0.782323,-91.497314,0.079013,0.000000
61.810001,18.971634,-91.452835,0.011188,0.003096,0.078631,84.390045,4.299034,0.786312,-91.452835,0.079516,0.000000
62.110004,19.341026,-91.497314,0.011201,0.003120,0.079238,86.033180,4.382740,0.792383,-91.497314,0.080019,0.000000
62.410004,19.350334,-91.541794,0.011219,0.003137,0.079689,86.074585,4.384848,0.796894,-91.541794,0.080513,0.000000
62.710003,19.096375,-91.541794,0.011227,0.003151,0.080045,84.944916,4.327300,0.800452,-91.541794,0.081016,0.000000
63.010002,19.497421,-91.497314,0.011240,0.003177,0.080687,86.728859,4.418179,0.806871,-91.497314,0.081519,0.000000
63.310001,19.918205,-91.586281,0.011253,0.003199,0.081259,88.600601,4.513530,0.812594,-91.586281,0.082013,0.000000
63.610004,19.536148,-91.586281,0.011279,0.003214,0.081624,86.901123,4.426954,0.816235,-91.586281,0.082517,0.000000
63.910004,19.683235,-91.630760,0.011288,0.003234,0.082144,87.555405,4.460285,0.821436,-91.630760,0.083019,0.000000
64.210007,20.002357,-91.630760,0.011305,0.003258,0.082751,88.974930,4.532599,0.827507,-91.630760,0.083514,0.000000
64.510002,19.748398,-91.630760,0.011326,0.003272,0.083115,87.845261,4.475051,0.831148,-91.630760,0.084017,0.000000
64.810005,19.838516,-91.630760,0.011326,0.003291,0.083592,88.246124,4.495472,0.835917,-91.630760,0.084520,0.000000
65.110001,20.411598,-91.630760,0.011344,0.003316,0.084234,90.795326,4.625334,0.842336,-91.630760,0.085014,0.000000
65.410004,20.258926,-91.586281,0.011352,0.003336,0.084728,90.116203,4.590738,0.847279,-91.586281,0.085517,0.000000
65.710007,20.398567,-91.630760,0.011365,0.003355,0.085205,90.737358,4.622381,0.852048,-91.630760,0.086020,0.000000
66.010002,20.542671,-91.630760,0.011382,0.003376,0.085760,91.378365,4.655036,0.857604,-91.630760,0.086514,0.000000
66.310005,20.801468,-91.630760,0.011404,0.003395,0.086246,92.529549,4.713680,0.862456,-91.630760,0.087018,0.000000
66.610001,20.246262,-91.630760,0.011408,0.003406,0.086523,90.059868,4.587868,0.865235,-91.630760,0.087520,0.000000
66.910004,20.846901,-91.630760,0.011413,0.003432,0.087174,92.731644,4.723975,0.871737,-91.630760,0.088015,0.000000
67.210007,21.185760,-91.675240,0.011447,0.003453,0.087694,94.238968,4.800762,0.876937,-91.675240,0.088518,0.000000
67.510002,20.812271,-91.719719,0.011451,0.003467,0.088050,92.577606,4.716128,0.880495,-91.719719,0.089021,0.000000
67.810005,20.924728,-91.719719,0.011456,0.003486,0.088536,93.077843,4.741611,0.885355,-91.719719,0.089515,0.000000
68.110001,21.368965,-91.719719,0.011469,0.003511,0.089177,95.053902,4.842277,0.891767,-91.719719,0.090018,0.000000
68.410004,21.459084,-91.675240,0.011486,0.003528,0.089610,95.454773,4.862698,0.896104,-91.675240,0.090521,0.000000
68.710007,21.577126,-91.675240,0.011507,0.003547,0.090096,95.979851,4.889446,0.900964,-91.675240,0.091015,0.000000
69.010002,21.877998,-91.719719,0.011525,0.003570,0.090686,97.318199,4.957625,0.906861,-91.719719,0.091519,0.000000
69.310005,21.834061,-91.675240,0.011538,0.003589,0.091171,97.122749,4.947669,0.911713,-91.675240,0.092021,0.000000
69.610001,21.635216,-91.764198,0.011546,0.003605,0.091579,96.238243,4.902610,0.915793,-91.764198,0.092516,0.000000
69.910004,21.648987,-91.764198,0.011559,0.003625,0.092074,96.299500,4.905730,0.920736,-91.764198,0.093019,0.000000
70.210007,21.726440,-91.719719,0.011576,0.003641,0.092473,96.644035,4.923282,0.924726,-91.719719,0.093522,0.000000
70.510002,22.076103,-91.764198,0.011581,0.003661,0.092993,98.199409,5.002517,0.929926,-91.764198,0.094016,0.000000
70.810005,22.503586,-91.808685,0.011602,0.003684,0.093565,100.100952,5.099386,0.935649,-91.808685,0.094519,0.000000
71.110001,22.956390,-91.719719,0.011615,0.003708,0.094172,102.115128,5.201993,0.941720,-91.719719,0.095022,0.000000
71.410004,22.612694,-91.808685,0.011637,0.003723,0.094563,100.586288,5.124110,0.945626,-91.808685,0.095516,0.000000
71.710007,22.622742,-91.808685,0.011654,0.003743,0.095065,100.630981,5.126387,0.950652,-91.808685,0.096019,0.000000
72.010002,22.760895,-91.897644,0.011671,0.003762,0.095542,101.245514,5.157692,0.955421,-91.897644,0.096513,0.000000
72.310005,22.595932,-91.808685,0.011671,0.003777,0.095933,100.511726,5.120311,0.959327,-91.808685,0.097017,0.000000
72.610001,22.654396,-91.808685,0.011693,0.003793,0.096340,100.771790,5.133559,0.963400,-91.808685,0.097519,0.000000
72.910004,23.350731,-91.853165,0.011697,0.003820,0.097034,103.869240,5.291351,0.970341,-91.853165,0.098014,0.000000
73.210007,23.571922,-91.897644,0.011714,0.003843,0.097606,104.853149,5.341474,0.976064,-91.897644,0.098517,0.000000
73.510002,23.389458,-91.853165,0.011736,0.003859,0.098014,104.041504,5.300127,0.980136,-91.853165,0.099020,0.000000
73.810005,23.577881,-91.853165,0.011749,0.003879,0.098525,104.879654,5.342824,0.985254,-91.853165,0.099514,0.000000
74.110001,23.788269,-91.853165,0.011770,0.003897,0.098986,105.815506,5.390499,0.989856,-91.853165,0.100017,0.000000
74.410004,23.664642,-91.897644,0.011770,0.003913,0.099393,105.265587,5.362485,0.993929,-91.897644,0.100520,0.000000
74.710007,24.321510,-91.853165,0.011788,0.003941,0.100095,108.187485,5.511333,1.000953,-91.853165,0.101014,0.000000
75.010002,24.424652,-91.897644,0.011805,0.003960,0.100581,108.646278,5.534706,1.005813,-91.897644,0.101518,0.000000
75.310005,24.552750,-91.942123,0.011809,0.003981,0.101110,109.216087,5.563733,1.011097,-91.942123,0.102020,0.000000
75.610001,24.039619,-91.942123,0.011831,0.003995,0.101483,106.933571,5.447455,1.014829,-91.942123,0.102515,0.000000
75.910004,25.069977,-91.942123,0.011831,0.004021,0.102142,111.516823,5.680938,1.021422,-91.942123,0.103018,0.000000
76.210007,24.530785,-91.986610,0.011848,0.004035,0.102480,109.118378,5.558755,1.024798,-91.986610,0.103521,0.000000
76.510002,24.352417,-91.986610,0.011865,0.004051,0.102896,108.324959,5.518337,1.028962,-91.986610,0.104015,0.000000
76.810005,25.520920,-91.986610,0.011870,0.004080,0.103643,113.522720,5.783123,1.036425,-91.986610,0.104518,0.000000
77.110001,25.278503,-91.942123,0.011887,0.004097,0.104059,112.444397,5.728191,1.040589,-91.942123,0.105021,0.000000
77.410004,25.504166,-91.986610,0.011908,0.004116,0.104536,113.448196,5.779326,1.045358,-91.986610,0.105515,0.000000
77.710007,25.871323,-91.986610,0.011913,0.004138,0.105099,115.081390,5.862525,1.050990,-91.986610,0.106019,0.000000
78.010002,25.990479,-91.986610,0.011930,0.004156,0.105568,115.611420,5.889527,1.055675,-91.986610,0.106521,0.000000
78.310005,25.642685,-92.031090,0.011939,0.004168,0.105871,114.064362,5.810716,1.058711,-92.031090,0.107016,0.000000
78.610001,26.992905,-92.031090,0.011956,0.004201,0.106712,120.070435,6.116679,1.067121,-92.031090,0.107519,0.000000
78.910004,26.707672,-92.031090,0.011960,0.004216,0.107085,118.801659,6.052045,1.070853,-92.031090,0.108022,0.000000
79.210007,26.828690,-92.031090,0.011969,0.004236,0.107588,119.339973,6.079468,1.075879,-92.031090,0.108516,0.000000
79.510002,27.058815,-92.031090,0.011986,0.004256,0.108100,120.363617,6.131615,1.080996,-92.031090,0.109019,0.000000
79.810005,27.223404,-92.075569,0.011999,0.004274,0.108551,121.095749,6.168911,1.085508,-92.075569,0.109522,0.000000
80.110001,27.274048,-92.120049,0.012021,0.004292,0.109019,121.321022,6.180387,1.090194,-92.120049,0.110016,0.000000
80.410004,27.892929,-92.075569,0.012029,0.004314,0.109574,124.073944,6.320628,1.095742,-92.075569,0.110520,0.000000
80.710007,28.292488,-92.031090,0.012038,0.004336,0.110129,125.851273,6.411170,1.101291,-92.031090,0.111022,0.000000
81.010002,28.506973,-92.075569,0.012059,0.004356,0.110641,126.805351,6.459773,1.106408,-92.075569,0.111517,0.000000
81.310005,28.334190,-92.075569,0.012072,0.004371,0.111014,126.036774,6.420619,1.110140,-92.075569,0.112020,0.000000
81.610001,29.358963,-92.075569,0.012077,0.004398,0.111707,130.595184,6.652836,1.117074,-92.075569,0.112523,0.000000
81.910004,29.290817,-92.075569,0.012102,0.004413,0.112098,130.292068,6.637394,1.120980,-92.075569,0.113017,0.000000
82.210007,29.277786,-92.120049,0.012115,0.004432,0.112575,130.234100,6.634441,1.125749,-92.120049,0.113520,0.000000
82.510002,30.216164,-92.075569,0.012115,0.004456,0.113182,134.408203,6.847081,1.131820,-92.075569,0.114023,0.000000
82.810005,30.648857,-92.164528,0.012124,0.004478,0.113745,136.332932,6.945130,1.137452,-92.164528,0.114517,0.000000
83.110001,30.669342,-92.209015,0.012150,0.004494,0.114153,136.424042,6.949772,1.141532,-92.209015,0.115020,0.000000
83.410004,31.325836,-92.209015,0.012154,0.004516,0.114716,139.344284,7.098536,1.147164,-92.209015,0.115523,0.000000
83.710007,31.596176,-92.209015,0.012176,0.004535,0.115177,140.546814,7.159796,1.151766,-92.209015,0.116018,0.000000
84.010002,31.663200,-92.209015,0.012184,0.004549,0.115541,140.844955,7.174984,1.155407,-92.209015,0.116520,0.000000
84.310005,32.498810,-92.209015,0.012193,0.004571,0.116113,144.561920,7.364336,1.161130,-92.209015,0.117024,0.000000
84.610001,33.532883,-92.209015,0.012206,0.004597,0.116755,149.161713,7.598660,1.167549,-92.209015,0.117518,0.000000
84.910004,33.445747,-92.209015,0.012210,0.004611,0.117127,148.774109,7.578915,1.171274,-92.209015,0.118021,0.000000
85.210007,34.018456,-92.209015,0.012232,0.004632,0.117648,151.321640,7.708692,1.176482,-92.209015,0.118515,0.000000
85.510002,34.815712,-92.253494,0.012223,0.004654,0.118211,154.868027,7.889353,1.182114,-92.253494,0.119018,0.000000
85.810005,35.027214,-92.253494,0.012253,0.004670,0.118610,155.808823,7.937280,1.186103,-92.253494,0.119521,0.000000
86.110001,34.946411,-92.253494,0.012249,0.004684,0.118975,155.449402,7.918970,1.189752,-92.253494,0.120015,0.000000
86.410004,36.778114,-92.253494,0.012271,0.004713,0.119712,163.597229,8.334040,1.197117,-92.253494,0.120519,0.000000
86.710007,37.150108,-92.253494,0.012279,0.004731,0.120163,165.251938,8.418335,1.201628,-92.253494,0.121021,0.000000
87.010002,37.888527,-92.253494,0.012279,0.004752,0.120692,168.536591,8.585663,1.206920,-92.253494,0.121516,0.000000
87.310005,38.359207,-92.297974,0.012305,0.004770,0.121151,170.630280,8.692320,1.211515,-92.297974,0.122019,0.000000
87.610001,39.597717,-92.297974,0.012318,0.004794,0.121768,176.139450,8.972971,1.217676,-92.297974,0.122522,0.000000
87.910004,39.526962,-92.297974,0.012318,0.004805,0.122045,175.824707,8.956938,1.220447,-92.297974,0.123016,0.000000
88.210007,40.361450,-92.342453,0.012331,0.004826,0.122591,179.536697,9.146036,1.225912,-92.342453,0.123519,0.000000
88.510002,41.722847,-92.297974,0.012348,0.004851,0.123216,185.592499,9.454532,1.232157,-92.297974,0.124022,0.000000
88.810005,41.881104,-92.342453,0.012357,0.004864,0.123554,186.296448,9.490394,1.235541,-92.342453,0.124516,0.000000
89.110001,42.636650,-92.297974,0.012378,0.004883,0.124039,189.657288,9.661603,1.240393,-92.297974,0.125020,0.000000
89.410004,43.618591,-92.386932,0.012370,0.004905,0.124594,194.025177,9.884114,1.245942,-92.386932,0.125522,0.000000
89.710007,44.737946,-92.386932,0.012383,0.004925,0.125098,199.004318,10.137763,1.250976,-92.386932,0.126017,0.000000
90.010002,45.333366,-92.342453,0.012391,0.004944,0.125565,201.652878,10.272688,1.255654,-92.342453,0.126520,0.000000
90.310005,46.802002,-92.386932,0.012409,0.004967,0.126172,208.185699,10.605485,1.261725,-92.386932,0.127023,0.000000
90.610001,47.400040,-92.386932,0.012409,0.004985,0.126624,210.845901,10.741003,1.266237,-92.386932,0.127517,0.000000
90.910004,48.235641,-92.386932,0.012434,0.005002,0.127040,214.562851,10.930352,1.270400,-92.386932,0.128020,0.000000
91.210007,48.847076,-92.386932,0.012434,0.005018,0.127447,217.282654,11.068906,1.274473,-92.386932,0.128523,0.000000
91.510002,49.839447,-92.386932,0.012447,0.005036,0.127925,221.696930,11.293780,1.279249,-92.386932,0.129017,0.000000
91.810005,50.594994,-92.431419,0.012456,0.005055,0.128384,225.057770,11.464989,1.283844,-92.431419,0.129521,0.000000
92.110001,52.446053,-92.431419,0.012465,0.005081,0.129052,233.291687,11.884445,1.290521,-92.431419,0.130023,0.000000
92.410004,54.115776,-92.431419,0.012465,0.005105,0.129677,240.718994,12.262810,1.296766,-92.431419,0.130518,0.000000
92.710007,54.636353,-92.520378,0.012482,0.005120,0.130049,243.034637,12.380774,1.300490,-92.520378,0.131020,0.000000
93.010002,55.394501,-92.475899,0.012503,0.005135,0.130431,246.407043,12.552573,1.304305,-92.475899,0.131524,0.000000
93.310005,56.755524,-92.564857,0.012499,0.005157,0.130994,252.461182,12.860986,1.309945,-92.564857,0.132018,0.000000
93.610008,57.474197,-92.520378,0.012495,0.005173,0.131385,255.658005,13.023839,1.313851,-92.520378,0.132521,0.000000
93.910004,58.710106,-92.520378,0.012503,0.005191,0.131845,261.155609,13.303901,1.318445,-92.520378,0.133024,0.000000
94.210007,60.411850,-92.520378,0.012529,0.005216,0.132486,268.725342,13.689521,1.324865,-92.520378,0.133518,0.000000
94.510002,61.773613,-92.520378,0.012538,0.005237,0.133032,274.782745,13.998100,1.330323,-92.520378,0.134021,0.000000
94.810005,62.815514,-92.520378,0.012542,0.005256,0.133509,279.417358,14.234199,1.335091,-92.520378,0.134524,0.000000
95.110008,63.779953,-92.564857,0.012551,0.005275,0.133995,283.707397,14.452744,1.339951,-92.564857,0.135019,0.000000
95.410004,65.356949,-92.653824,0.012572,0.005296,0.134507,290.722229,14.810097,1.345068,-92.653824,0.135521,0.000000
95.710007,66.311722,-92.564857,0.012559,0.005311,0.134906,294.969269,15.026451,1.349058,-92.564857,0.136025,0.000000
96.010002,67.463089,-92.564857,0.012581,0.005322,0.135166,300.090820,15.287354,1.351662,-92.564857,0.135374,0.000000
96.310005,66.677765,-92.564857,0.012598,0.005321,0.135157,296.597504,15.109398,1.351571,-92.564857,0.135374,0.000000
96.610008,66.010834,-92.609337,0.012594,0.005320,0.135131,293.630859,14.958269,1.351313,-92.609337,0.135157,0.000000
96.910004,65.444092,-92.609337,0.012598,0.005320,0.135122,291.109863,14.829843,1.351223,-92.609337,0.135157,0.000000
97.210007,64.953674,-92.609337,0.012594,0.005319,0.135114,288.928375,14.718713,1.351139,-92.609337,0.135157,0.000000
97.510002,64.526566,-92.653824,0.012603,0.005319,0.135105,287.028503,14.621929,1.351049,-92.653824,0.135157,0.000000
97.810005,64.129990,-92.653824,0.012611,0.005319,0.135105,285.264435,14.532063,1.351049,-92.653824,0.135157,0.000000
98.110008,63.787399,-92.609337,0.012603,0.005319,0.135097,283.740509,14.454432,1.350965,-92.609337,0.135157,0.000000
98.410004,63.476471,-92.609337,0.012611,0.005319,0.135097,282.357452,14.383974,1.350965,-92.609337,0.135157,0.000000
98.710007,63.184525,-92.653824,0.012616,0.005319,0.135097,281.058807,14.317818,1.350965,-92.653824,0.135157,0.000000
99.010002,62.934296,-92.698303,0.012628,0.005319,0.135097,279.945740,14.261116,1.350965,-92.698303,0.135157,0.000000
99.310005,62.696350,-92.698303,0.012616,0.005318,0.135088,278.887299,14.207196,1.350882,-92.698303,0.135157,0.000000
99.610008,62.464737,-92.698303,0.012620,0.005318,0.135088,277.857025,14.154712,1.350882,-92.698303,0.135157,0.000000
99.910004,62.256210,-92.698303,0.012628,0.005318,0.135088,276.929443,14.107459,1.350882,-92.698303,0.135157,0.000000
100.210007,62.077095,-92.698303,0.012620,0.005318,0.135088,276.132721,14.066872,1.350882,-92.698303,0.135157,0.000000
100.510002,61.895004,-92.653824,0.012624,0.005318,0.135088,275.322723,14.025608,1.350882,-92.653824,0.135157,0.000000
100.810005,61.735634,-92.742783,0.012628,0.005318,0.135088,274.613800,13.989495,1.350882,-92.742783,0.135157,0.000000
101.110008,61.566948,-92.742783,0.012628,0.005318,0.135088,273.863464,13.951269,1.350882,-92.742783,0.135157,0.000000
101.410004,61.419113,-92.742783,0.012633,0.005318,0.135088,273.205872,13.917770,1.350882,-92.742783,0.135157,0.000000
101.710007,61.271286,-92.831741,0.012624,0.005318,0.135088,272.548279,13.884272,1.350882,-92.831741,0.135157,0.000000
102.010002,61.133881,-92.787262,0.012628,0.005318,0.135079,271.937073,13.853135,1.350791,-92.787262,0.135157,0.000000
102.310005,61.025146,-92.742783,0.012637,0.005318,0.135079,271.453400,13.828496,1.350791,-92.742783,0.135157,0.000000
102.610008,60.898163,-92.787262,0.012633,0.005318,0.135079,270.888550,13.799721,1.350791,-92.787262,0.135157,0.000000
102.910004,60.783844,-92.787262,0.012624,0.005318,0.135079,270.380035,13.773815,1.350791,-92.787262,0.135157,0.000000
103.210007,60.665436,-92.787262,0.012646,0.005318,0.135079,269.853333,13.746984,1.350791,-92.787262,0.135157,0.000000
103.510002,60.555954,-92.787262,0.012637,0.005318,0.135079,269.366333,13.722176,1.350791,-92.787262,0.135157,0.000000
103.810005,60.464722,-92.831741,0.012637,0.005318,0.135079,268.960510,13.701502,1.350791,-92.831741,0.135157,0.000000
104.110008,60.364555,-92.787262,0.012633,0.005318,0.135079,268.514954,13.678803,1.350791,-92.787262,0.135157,0.000000
104.410004,60.276672,-92.831741,0.012633,0.005318,0.135079,268.124023,13.658889,1.350791,-92.831741,0.135157,0.000000
104.710007,60.192894,-92.787262,0.012628,0.005318,0.135079,267.751373,13.639904,1.350791,-92.787262,0.135157,0.000000
105.010002,60.121399,-92.876228,0.012650,0.005318,0.135079,267.433350,13.623704,1.350791,-92.876228,0.135157,0.000000
105.310005,60.026817,-92.876228,0.012641,0.005318,0.135079,267.012634,13.602272,1.350791,-92.876228,0.135157,0.000000
105.610008,59.926270,-92.876228,0.012641,0.005318,0.135079,266.565369,13.579487,1.350791,-92.876228,0.135157,0.000000
105.910004,59.857384,-92.831741,0.012641,0.005318,0.135079,266.258942,13.563877,1.350791,-92.831741,0.135157,0.000000
106.210007,59.774719,-92.876228,0.012637,0.005318,0.135079,265.891235,13.545145,1.350791,-92.876228,0.135157,0.000000
106.510002,59.718117,-92.920708,0.012641,0.005318,0.135079,265.639465,13.532319,1.350791,-92.920708,0.135157,0.000000
106.810005,59.640289,-92.920708,0.012637,0.005318,0.135079,265.293243,13.514683,1.350791,-92.920708,0.135157,0.000000
107.110008,59.568054,-92.876228,0.012646,0.005318,0.135079,264.971924,13.498314,1.350791,-92.876228,0.135157,0.000000
107.410004,59.512566,-92.920708,0.012650,0.005318,0.135079,264.725128,13.485741,1.350791,-92.920708,0.135157,0.000000
107.710007,59.444420,-92.876228,0.012641,0.005318,0.135079,264.421997,13.470298,1.350791,-92.876228,0.135157,0.000000
108.010002,59.390800,-93.009666,0.012641,0.005318,0.135079,264.183472,13.458147,1.350791,-93.009666,0.135157,0.000000
108.310005,59.316330,-92.965187,0.012641,0.005318,0.135079,263.852203,13.441273,1.350791,-92.965187,0.135157,0.000000
108.610008,59.260841,-92.965187,0.012650,0.005318,0.135079,263.605377,13.428699,1.350791,-92.965187,0.135157,0.000000
108.910004,59.200890,-92.920708,0.012641,0.005318,0.135079,263.338715,13.415112,1.350791,-92.920708,0.135157,0.000000
109.210007,59.154716,-93.009666,0.012641,0.005318,0.135079,263.133331,13.404650,1.350791,-93.009666,0.135157,0.000000
109.510002,59.101471,-92.965187,0.012650,0.005318,0.135079,262.896484,13.392585,1.350791,-92.965187,0.135157,0.000000
109.810005,59.033325,-93.009666,0.012650,0.005318,0.135079,262.593353,13.377142,1.350791,-93.009666,0.135157,0.000000
110.110008,58.991249,-93.009666,0.012650,0.005318,0.135079,262.406189,13.367608,1.350791,-93.009666,0.135157,0.000000
110.410004,58.933159,-93.054146,0.012646,0.005318,0.135079,262.147797,13.354445,1.350791,-93.054146,0.135157,0.000000
110.710007,58.891075,-93.009666,0.012650,0.005318,0.135079,261.960571,13.344909,1.350791,-93.009666,0.135157,0.000000
111.010002,58.837456,-93.009666,0.012650,0.005318,0.135079,261.722076,13.332758,1.350791,-93.009666,0.135157,0.000000
111.310005,58.776390,-92.965187,0.012659,0.005318,0.135079,261.450439,13.318921,1.350791,-92.965187,0.135157,0.000000
111.610008,58.754791,-93.054146,0.012650,0.005318,0.135079,261.354370,13.314026,1.350791,-93.054146,0.135157,0.000000
111.910004,58.709358,-93.098633,0.012654,0.005318,0.135079,261.152283,13.303731,1.350791,-93.098633,0.135157,0.000000
112.210007,58.656487,-93.098633,0.012650,0.005318,0.135079,260.917084,13.291750,1.350791,-93.098633,0.135157,0.000000
112.510002,58.618126,-93.009666,0.012667,0.005318,0.135079,260.746460,13.283057,1.350791,-93.009666,0.135157,0.000000
112.810005,58.563759,-93.054146,0.012650,0.005318,0.135079,260.504608,13.270737,1.350791,-93.054146,0.135157,0.000000
113.110008,58.517960,-93.098633,0.012650,0.005318,0.135079,260.300873,13.260360,1.350791,-93.098633,0.135157,0.000000
113.410004,58.482956,-93.098633,0.012646,0.005318,0.135079,260.145172,13.252427,1.350791,-93.098633,0.135157,0.000000
113.710007,58.442741,-93.098633,0.012650,0.005318,0.135079,259.966309,13.243315,1.350791,-93.098633,0.135157,0.000000
114.010002,58.407364,-93.187592,0.012654,0.005318,0.135079,259.808929,13.235298,1.350791,-93.187592,0.135157,0.000000
114.310005,58.358955,-93.143112,0.012659,0.005318,0.135079,259.593597,13.224328,1.350791,-93.143112,0.135157,0.000000
114.610008,58.323212,-93.143112,0.012659,0.005318,0.135079,259.434601,13.216228,1.350791,-93.143112,0.135157,0.000000
114.910004,58.277039,-93.187592,0.012654,0.005318,0.135079,259.229218,13.205766,1.350791,-93.187592,0.135157,0.000000
115.210007,58.245384,-93.187592,0.012650,0.005318,0.135079,259.088409,13.198593,1.350791,-93.187592,0.135157,0.000000
115.510002,58.202187,-93.232071,0.012650,0.005318,0.135079,258.896271,13.188804,1.350791,-93.232071,0.135157,0.000000
115.810005,58.173515,-93.187592,0.012659,0.005318,0.135079,258.768707,13.182307,1.350791,-93.187592,0.135157,0.000000
116.110008,58.121010,-93.232071,0.012659,0.005318,0.135079,258.535156,13.170409,1.350791,-93.232071,0.135157,0.000000
116.410004,58.093086,-93.232071,0.012654,0.005318,0.135079,258.410950,13.164082,1.350791,-93.232071,0.135157,0.000000
116.710007,58.054726,-93.143112,0.012654,0.005318,0.135079,258.240326,13.155389,1.350791,-93.143112,0.135157,0.000000
117.010002,58.029037,-93.232071,0.012646,0.005318,0.135079,258.126038,13.149568,1.350791,-93.232071,0.135157,0.000000
117.310005,57.984726,-93.232071,0.012650,0.005318,0.135079,257.928955,13.139526,1.350791,-93.232071,0.135157,0.000000
117.610008,57.966103,-93.232071,0.012663,0.005318,0.135079,257.846100,13.135306,1.350791,-93.232071,0.135157,0.000000
117.910004,57.911736,-93.232071,0.012659,0.005318,0.135079,257.604279,13.122987,1.350791,-93.232071,0.135157,0.000000
118.210007,57.882324,-93.276558,0.012663,0.005318,0.135079,257.473450,13.116323,1.350791,-93.276558,0.135157,0.000000
118.510002,57.858490,-93.276558,0.012663,0.005318,0.135079,257.367432,13.110922,1.350791,-93.276558,0.135157,0.000000
118.810005,57.841736,-93.276558,0.012646,0.005318,0.135079,257.292877,13.107125,1.350791,-93.276558,0.135157,0.000000
119.110008,57.819763,-93.232071,0.012659,0.005318,0.135079,257.195160,13.102145,1.350791,-93.232071,0.135157,0.000000
119.410004,57.775826,-93.232071,0.012667,0.005318,0.135079,256.999695,13.092189,1.350791,-93.232071,0.135157,0.000000
119.710007,57.748642,-93.276558,0.012659,0.005318,0.135079,256.878784,13.086029,1.350791,-93.276558,0.135157,0.000000
120.010002,57.718849,-93.276558,0.012654,0.005318,0.135079,256.746277,13.079278,1.350791,-93.276558,0.135157,0.000000
120.310005,57.687195,-93.321037,0.012663,0.005318,0.135079,256.605469,13.072105,1.350791,-93.321037,0.135157,0.000000
120.610008,57.661133,-93.321037,0.012672,0.005318,0.135079,256.489532,13.066199,1.350791,-93.321037,0.135157,0.000000
120.910004,57.638420,-93.321037,0.012650,0.005318,0.135079,256.388489,13.061053,1.350791,-93.321037,0.135157,0.000000
121.210007,57.601555,-93.276558,0.012654,0.005318,0.135079,256.224518,13.052699,1.350791,-93.276558,0.135157,0.000000
121.510002,57.576599,-93.365517,0.012659,0.005318,0.135079,256.113495,13.047044,1.350791,-93.365517,0.135157,0.000000
121.810005,57.549423,-93.321037,0.012659,0.005318,0.135079,255.992615,13.040885,1.350791,-93.321037,0.135157,0.000000
122.110008,57.541229,-93.365517,0.012663,0.005318,0.135079,255.956177,13.039029,1.350791,-93.365517,0.135157,0.000000
122.410004,57.511436,-93.321037,0.012667,0.005318,0.135079,255.823639,13.032278,1.350791,-93.321037,0.135157,0.000000
122.710007,57.482765,-93.365517,0.012672,0.005318,0.135079,255.696106,13.025781,1.350791,-93.365517,0.135157,0.000000
123.010002,57.445900,-93.321037,0.012654,0.005318,0.135079,255.532120,13.017426,1.350791,-93.321037,0.135157,0.000000
123.310005,57.435104,-93.321037,0.012667,0.005318,0.135079,255.484100,13.014981,1.350791,-93.321037,0.135157,0.000000
123.610008,57.403824,-93.409996,0.012672,0.005318,0.135079,255.344955,13.007893,1.350791,-93.409996,0.135157,0.000000
123.910004,57.378876,-93.409996,0.012663,0.005318,0.135079,255.233994,13.002239,1.350791,-93.409996,0.135157,0.000000
124.210007,57.352432,-93.321037,0.012654,0.005318,0.135079,255.116364,12.996246,1.350791,-93.321037,0.135157,0.000000
124.510002,57.321526,-93.409996,0.012650,0.005318,0.135079,254.978882,12.989244,1.350791,-93.409996,0.135157,0.000000
124.810005,57.296577,-93.409996,0.012663,0.005318,0.135079,254.867905,12.983589,1.350791,-93.409996,0.135157,0.000000
125.110008,57.282799,-93.365517,0.012667,0.005318,0.135079,254.806610,12.980468,1.350791,-93.365517,0.135157,0.000000
125.410004,57.259338,-93.454475,0.012672,0.005318,0.135079,254.702255,12.975151,1.350791,-93.454475,0.135157,0.000000
125.710007,57.235886,-93.409996,0.012667,0.005318,0.135079,254.597931,12.969836,1.350791,-93.409996,0.135157,0.000000
126.010010,57.211678,-93.454475,0.012663,0.005318,0.135079,254.490250,12.964352,1.350791,-93.454475,0.135157,0.000000
126.310005,57.199387,-93.454475,0.012667,0.005318,0.135079,254.435577,12.961566,1.350791,-93.454475,0.135157,0.000000
126.400009,57.184494,-93.409996,0.012650,0.005318,0.135079,254.369339,12.958192,1.350791,-93.409996,0.135157,0.000000