File: Data/compression 6/AutoNoheating-10-6-day1-4-240228_02282024_202246.csv
Time (sec),S:Load (lbs),S:HL1 (DIM),S:LVDT (in),S:Position (in),Ch:Position (mm),Ch:Load (N),Ch:Stress (MPa),Ch:Strain (mm/mm),Ch:HL1 (DIM),Set Point (),Cycles ()
0.110000,0.015266,-133.131485,0.000013,-0.000000,-0.000000,0.067908,0.003459,-0.000000,-133.131485,0.000165,0.000000
0.390000,0.005585,-133.087006,0.000013,-0.000000,-0.000000,0.024842,0.001266,-0.000000,-133.087006,0.000165,0.000000
0.670000,0.014519,-133.131485,0.000022,0.000154,0.003903,0.064583,0.003290,0.039026,-133.131485,0.004831,0.000000
0.950000,0.029411,-133.131485,0.000194,0.000339,0.008620,0.130828,0.006665,0.086205,-133.131485,0.009496,0.000000
1.230000,-0.000748,-133.131485,0.000371,0.000517,0.013130,-0.003326,-0.000169,0.131298,-133.131485,0.014162,0.000000
1.510000,0.000740,-133.042526,0.000543,0.000691,0.017544,0.003292,0.000168,0.175441,-133.042526,0.018828,0.000000
1.790000,-0.017136,-133.131485,0.000733,0.000882,0.022409,-0.076223,-0.003883,0.224092,-133.131485,0.023493,0.000000
2.070000,0.005211,-133.131485,0.000923,0.001057,0.026841,0.023179,0.001181,0.268410,-133.131485,0.028159,0.000000
2.350000,-0.065910,-133.175964,0.001099,0.001250,0.031741,-0.293184,-0.014935,0.317405,-133.175964,0.032825,0.000000
2.630000,0.029785,-133.220444,0.001293,0.001431,0.036346,0.132491,0.006749,0.363456,-133.220444,0.037491,0.000000
2.910000,-0.018250,-133.175964,0.001470,0.001619,0.041133,-0.081178,-0.004135,0.411327,-133.175964,0.042156,0.000000
3.190000,0.004089,-133.175964,0.001660,0.001802,0.045772,0.018190,0.000927,0.457722,-133.175964,0.046804,0.000000
3.470000,0.027550,-133.175964,0.001867,0.001991,0.050559,0.122547,0.006243,0.505594,-133.175964,0.051470,0.000000
3.750000,-0.000374,-133.220444,0.002031,0.002167,0.055034,-0.001663,-0.000085,0.550343,-133.220444,0.056136,0.000000
4.030000,0.003723,-133.264923,0.002216,0.002351,0.059709,0.016561,0.000844,0.597086,-133.264923,0.060801,0.000000
4.310000,-0.036125,-133.175964,0.002397,0.002533,0.064340,-0.160693,-0.008186,0.643398,-133.175964,0.065467,0.000000
4.590000,0.007072,-133.175964,0.002583,0.002716,0.068988,0.031460,0.001603,0.689880,-133.175964,0.070133,0.000000
4.870000,0.001114,-133.175964,0.002777,0.002907,0.073836,0.004955,0.000252,0.738357,-133.175964,0.074798,0.000000
5.150000,0.037231,-133.220444,0.002966,0.003084,0.078328,0.165614,0.008437,0.783280,-133.220444,0.079464,0.000000
5.430000,-0.001495,-133.309418,0.003122,0.003274,0.083158,-0.006652,-0.000339,0.831583,-133.309418,0.084130,0.000000
5.710000,0.018990,-133.220444,0.003316,0.003457,0.087798,0.084470,0.004303,0.877982,-133.220444,0.088796,0.000000
5.990000,0.016006,-133.220444,0.003518,0.003642,0.092498,0.071200,0.003627,0.924983,-133.220444,0.093461,0.000000
6.270000,0.000740,-133.264923,0.003695,0.003817,0.096956,0.003292,0.000168,0.969561,-133.264923,0.098127,0.000000
6.550000,-0.006332,-133.264923,0.003885,0.004002,0.101648,-0.028168,-0.001435,1.016479,-133.264923,0.102792,0.000000
6.830000,-0.034637,-133.309418,0.004061,0.004190,0.106426,-0.154075,-0.007849,1.064260,-133.309418,0.107458,0.000000
7.110000,0.047287,-133.264923,0.004234,0.004367,0.110918,0.210343,0.010715,1.109182,-133.264923,0.112124,0.000000
7.390000,-0.004845,-133.264923,0.004428,0.004555,0.115697,-0.021550,-0.001098,1.156967,-133.264923,0.116789,0.000000
7.670001,0.027184,-133.264923,0.004648,0.004743,0.120475,0.120918,0.006160,1.204751,-133.264923,0.121455,0.000000
7.950000,-0.002235,-133.309418,0.004816,0.004927,0.125141,-0.009944,-0.000507,1.251407,-133.309418,0.126121,0.000000
8.230000,0.021965,-133.353897,0.004984,0.005104,0.129633,0.097705,0.004977,1.296330,-133.353897,0.130787,0.000000
8.510000,0.009682,-133.264923,0.005195,0.005291,0.134385,0.043066,0.002194,1.343853,-133.264923,0.135435,0.000000
8.790000,0.000740,-133.309418,0.005368,0.005474,0.139043,0.003292,0.000168,1.390427,-133.309418,0.140101,0.000000
9.070001,0.037605,-133.264923,0.005553,0.005658,0.143717,0.167277,0.008521,1.437170,-133.264923,0.144766,0.000000
9.350000,0.003723,-133.353897,0.005743,0.005839,0.148304,0.016561,0.000844,1.483043,-133.353897,0.149432,0.000000
9.630000,0.051010,-133.353897,0.005920,0.006021,0.152935,0.226904,0.011559,1.529355,-133.353897,0.154097,0.000000
9.910001,0.010422,-133.398376,0.006114,0.006210,0.157731,0.046358,0.002362,1.577313,-133.398376,0.158763,0.000000
10.190001,0.038727,-133.353897,0.006303,0.006389,0.162284,0.172265,0.008776,1.622842,-133.353897,0.163429,0.000000
10.470000,-0.020859,-133.309418,0.006493,0.006578,0.167071,-0.092784,-0.004727,1.670713,-133.309418,0.168094,0.000000
10.750001,0.012283,-133.398376,0.006679,0.006758,0.171659,0.054639,0.002783,1.716590,-133.398376,0.172760,0.000000
11.030001,0.019363,-133.442856,0.006855,0.006949,0.176507,0.086133,0.004388,1.765067,-133.442856,0.177426,0.000000
11.310000,0.021591,-133.398376,0.007028,0.007127,0.181033,0.096042,0.004893,1.810334,-133.398376,0.182092,0.000000
11.590000,0.072983,-133.353897,0.007226,0.007310,0.185682,0.324644,0.016538,1.856820,-133.353897,0.186757,0.000000
11.870001,0.060318,-133.353897,0.007407,0.007493,0.190322,0.268308,0.013668,1.903216,-133.353897,0.191423,0.000000
12.150001,0.222305,-133.442856,0.007597,0.007673,0.194883,0.988863,0.050375,1.948831,-133.442856,0.196089,0.000000
12.430000,0.481476,-133.487335,0.007774,0.007861,0.199662,2.141711,0.109104,1.996615,-133.487335,0.200754,0.000000
12.710001,0.583878,-133.442856,0.007821,-0.000000,-0.000009,2.597217,0.132309,-0.000087,-133.442856,0.000208,0.000000
12.990001,0.548126,-133.442856,0.007834,-0.000000,-0.000009,2.438187,0.124207,-0.000087,-133.442856,0.000208,0.000000
13.270000,0.512383,-133.487335,0.007821,-0.000000,-0.000000,2.279191,0.116108,-0.000000,-133.487335,0.000511,0.000000
13.550000,0.523926,-133.487335,0.007843,0.000003,0.000087,2.330538,0.118723,0.000867,-133.487335,0.000980,0.000000
13.830001,0.574944,-133.531815,0.007847,0.000025,0.000624,2.557477,0.130284,0.006241,-133.531815,0.001448,0.000000
14.110001,0.681808,-133.487335,0.007860,0.000042,0.001075,3.032835,0.154500,0.010753,-133.487335,0.001916,0.000000
14.390000,0.704155,-133.531815,0.007881,0.000060,0.001517,3.132238,0.159564,0.015174,-133.531815,0.002376,0.000000
14.670001,0.736923,-133.487335,0.007881,0.000074,0.001891,3.277998,0.166989,0.018906,-133.487335,0.002844,0.000000
14.950001,0.856079,-133.487335,0.007907,0.000095,0.002402,3.808030,0.193990,0.024019,-133.487335,0.003313,0.000000
15.230000,0.920128,-133.487335,0.007920,0.000114,0.002905,4.092933,0.208504,0.029049,-133.487335,0.003781,0.000000
15.510001,0.942841,-133.576294,0.007942,0.000128,0.003252,4.193964,0.213651,0.032520,-133.576294,0.004249,0.000000
15.790001,1.022530,-133.576294,0.007959,0.000150,0.003807,4.548439,0.231709,0.038068,-133.576294,0.004709,0.000000
16.070002,1.081367,-133.531815,0.007976,0.000170,0.004310,4.810163,0.245041,0.043099,-133.531815,0.005177,0.000000
16.350000,1.088066,-133.576294,0.008002,0.000188,0.004778,4.839960,0.246559,0.047784,-133.576294,0.005646,0.000000
16.630001,1.118233,-133.620773,0.008011,0.000201,0.005108,4.974148,0.253395,0.051077,-133.620773,0.006114,0.000000
16.910002,1.252289,-133.620773,0.008015,0.000222,0.005646,5.570459,0.283773,0.056455,-133.620773,0.006582,0.000000
17.190001,1.310379,-133.620773,0.008041,0.000243,0.006166,5.828857,0.296936,0.061660,-133.620773,0.007051,0.000000
17.470001,1.366974,-133.620773,0.008054,0.000258,0.006547,6.080604,0.309761,0.065475,-133.620773,0.007510,0.000000
17.750000,1.489487,-133.576294,0.008080,0.000281,0.007137,6.625568,0.337523,0.071372,-133.576294,0.007978,0.000000
18.030001,1.502892,-133.665253,0.008093,0.000297,0.007554,6.685195,0.340560,0.075535,-133.665253,0.008447,0.000000
18.310001,1.536781,-133.620773,0.008097,0.000316,0.008022,6.835945,0.348240,0.080217,-133.620773,0.008915,0.000000
18.590000,1.613487,-133.620773,0.008114,0.000335,0.008516,7.177150,0.365621,0.085160,-133.620773,0.009383,0.000000
18.870001,1.730415,-133.576294,0.008140,0.000352,0.008941,7.697272,0.392118,0.089411,-133.576294,0.009843,0.000000
19.150002,1.781799,-133.665253,0.008144,0.000367,0.009331,7.925839,0.403762,0.093313,-133.665253,0.010311,0.000000
19.430000,1.895744,-133.754227,0.008162,0.000385,0.009791,8.432692,0.429582,0.097908,-133.754227,0.010779,0.000000
19.710001,1.991074,-133.665253,0.008170,0.000412,0.010458,8.856738,0.451184,0.104584,-133.665253,0.011248,0.000000
19.990002,2.011551,-133.665253,0.008201,0.000428,0.010875,8.947825,0.455824,0.108748,-133.665253,0.011716,0.000000
20.270000,2.058472,-133.665253,0.008222,0.000446,0.011317,9.156539,0.466456,0.113172,-133.665253,0.012184,0.000000
20.550001,2.185822,-133.620773,0.008239,0.000466,0.011838,9.723020,0.495314,0.118376,-133.620773,0.012644,0.000000
20.830002,2.302002,-133.709732,0.008252,0.000482,0.012254,10.239816,0.521641,0.122536,-133.709732,0.013112,0.000000
21.110001,2.322113,-133.709732,0.008261,0.000495,0.012583,10.329275,0.526198,0.125833,-133.709732,0.013581,0.000000
21.390001,2.448349,-133.709732,0.008265,0.000514,0.013060,10.890800,0.554804,0.130602,-133.709732,0.014049,0.000000
21.670000,2.614426,-133.665253,0.008291,0.000540,0.013719,11.629546,0.592437,0.137195,-133.665253,0.014517,0.000000
21.950001,2.603996,-133.754227,0.008313,0.000555,0.014092,11.583154,0.590074,0.140923,-133.754227,0.014977,0.000000
22.230001,2.694855,-133.754227,0.008330,0.000576,0.014638,11.987312,0.610663,0.146385,-133.754227,0.015445,0.000000
22.510000,2.768959,-133.754227,0.008338,0.000596,0.015133,12.316945,0.627455,0.151328,-133.754227,0.015914,0.000000
22.790001,2.831146,-133.754227,0.008334,0.000612,0.015540,12.593568,0.641547,0.155404,-133.754227,0.016382,0.000000
23.070002,2.912697,-133.754227,0.008373,0.000627,0.015922,12.956323,0.660027,0.159223,-133.754227,0.016850,0.000000
23.350000,2.971901,-133.798706,0.008382,0.000643,0.016330,13.219676,0.673442,0.163296,-133.798706,0.017310,0.000000
23.630001,3.190483,-133.754227,0.008395,0.000667,0.016954,14.191978,0.722974,0.169541,-133.754227,0.017778,0.000000
23.910002,3.185646,-133.887665,0.008412,0.000685,0.017388,14.170462,0.721878,0.173878,-133.887665,0.018246,0.000000
24.190001,3.256020,-133.798706,0.008420,0.000704,0.017882,14.483499,0.737825,0.178821,-133.798706,0.018714,0.000000
24.470001,3.294746,-133.843185,0.008438,0.000718,0.018229,14.655764,0.746600,0.182288,-133.843185,0.019183,0.000000
24.750002,3.445930,-133.843185,0.008468,0.000739,0.018767,15.328264,0.780859,0.187666,-133.843185,0.019651,0.000000
25.030001,3.512589,-133.843185,0.008464,0.000755,0.019166,15.624774,0.795964,0.191656,-133.843185,0.020111,0.000000
25.310001,3.599724,-133.932144,0.008476,0.000769,0.019538,16.012371,0.815709,0.195384,-133.932144,0.020579,0.000000
25.590002,3.857033,-133.843185,0.008494,0.000800,0.020310,17.156939,0.874016,0.203101,-133.843185,0.021047,0.000000
25.870001,3.783676,-133.843185,0.008524,0.000816,0.020735,16.830631,0.857393,0.207352,-133.843185,0.021516,0.000000
26.150002,3.799316,-133.798706,0.008532,0.000832,0.021125,16.900204,0.860937,0.211254,-133.798706,0.021984,0.000000
26.430000,3.870064,-133.843185,0.008554,0.000848,0.021533,17.214903,0.876969,0.215330,-133.843185,0.022444,0.000000
26.710001,4.049919,-133.887665,0.008563,0.000868,0.022036,18.014940,0.917725,0.220360,-133.887665,0.022912,0.000000
26.990002,4.101311,-133.932144,0.008576,0.000882,0.022409,18.243542,0.929370,0.224088,-133.932144,0.023380,0.000000
27.270000,4.183228,-133.887665,0.008576,0.000899,0.022834,18.607925,0.947933,0.228339,-133.887665,0.023849,0.000000
27.550001,4.423409,-133.843185,0.008614,0.000925,0.023502,19.676304,1.002359,0.235015,-133.843185,0.024317,0.000000
27.830002,4.377609,-133.887665,0.008627,0.000943,0.023944,19.472578,0.991980,0.239440,-133.887665,0.024785,0.000000
28.110001,4.488571,-133.932144,0.008640,0.000962,0.024438,19.966162,1.017125,0.244383,-133.932144,0.025245,0.000000
28.390001,4.496025,-133.932144,0.008645,0.000979,0.024855,19.999319,1.018814,0.248546,-133.932144,0.025713,0.000000
28.670002,4.763756,-133.932144,0.008662,0.001002,0.025444,21.190245,1.079482,0.254443,-133.932144,0.026181,0.000000
28.950001,4.639389,-133.932144,0.008670,0.001010,0.025661,20.637033,1.051301,0.256612,-133.932144,0.026650,0.000000
29.230001,4.783493,-133.976624,0.008683,0.001030,0.026164,21.278040,1.083955,0.261642,-133.976624,0.027118,0.000000
29.510002,5.047134,-133.976624,0.008696,0.001056,0.026832,22.450775,1.143697,0.268319,-133.976624,0.027578,0.000000
29.790001,5.032608,-133.932144,0.008722,0.001071,0.027196,22.386158,1.140405,0.271960,-133.932144,0.028046,0.000000
30.070002,5.120491,-134.065582,0.008744,0.001089,0.027673,22.777082,1.160320,0.276729,-134.065582,0.028514,0.000000
30.350002,5.175232,-133.976624,0.008739,0.001107,0.028115,23.020582,1.172724,0.281153,-133.976624,0.028982,0.000000
30.630001,5.380775,-134.021103,0.008761,0.001129,0.028679,23.934885,1.219301,0.286789,-134.021103,0.029451,0.000000
30.910002,5.196831,-134.021103,0.008761,0.001137,0.028878,23.116657,1.177619,0.288784,-134.021103,0.029911,0.000000
31.190001,5.365883,-134.021103,0.008783,0.001155,0.029338,23.868639,1.215926,0.293382,-134.021103,0.030379,0.000000
31.470001,5.732674,-133.976624,0.008795,0.001184,0.030075,25.500206,1.299042,0.300752,-133.976624,0.030847,0.000000
31.750002,5.610535,-133.976624,0.008813,0.001199,0.030457,24.956905,1.271365,0.304567,-133.976624,0.031315,0.000000
32.030003,5.672722,-134.021103,0.008830,0.001215,0.030856,25.233526,1.285457,0.308556,-134.021103,0.031784,0.000000
32.310001,5.701019,-134.110062,0.008830,0.001232,0.031281,25.359400,1.291869,0.312806,-134.110062,0.032252,0.000000
32.590000,5.957581,-134.021103,0.008852,0.001254,0.031862,26.500643,1.350007,0.318616,-134.021103,0.032712,0.000000
32.870003,5.867470,-134.021103,0.008856,0.001264,0.032105,26.099810,1.329588,0.321046,-134.021103,0.033180,0.000000
33.150002,6.219734,-134.065582,0.008873,0.001292,0.032816,27.666759,1.409412,0.328158,-134.065582,0.033648,0.000000
33.430000,6.291977,-134.065582,0.008903,0.001310,0.033275,27.988111,1.425782,0.332753,-134.065582,0.034117,0.000000
33.710003,6.262184,-134.199036,0.008903,0.001328,0.033726,27.855587,1.419031,0.337264,-134.199036,0.034585,0.000000
33.990002,6.376129,-134.110062,0.008921,0.001345,0.034151,28.362438,1.444852,0.341511,-134.110062,0.035044,0.000000
34.270000,6.303894,-134.065582,0.008933,0.001356,0.034455,28.041121,1.428483,0.344547,-134.065582,0.035513,0.000000
34.550003,6.686691,-134.065582,0.008955,0.001382,0.035114,29.743889,1.515226,0.351140,-134.065582,0.035981,0.000000
34.830002,6.774200,-134.110062,0.008964,0.001402,0.035608,30.133148,1.535056,0.356083,-134.110062,0.036449,0.000000
35.110001,6.755203,-134.154541,0.008977,0.001418,0.036007,30.048645,1.530751,0.360072,-134.154541,0.036917,0.000000
35.390003,6.959267,-134.154541,0.008994,0.001439,0.036545,30.956364,1.576992,0.365447,-134.154541,0.037386,0.000000
35.670002,6.989426,-134.110062,0.008994,0.001458,0.037030,31.090519,1.583827,0.370303,-134.110062,0.037846,0.000000
35.950001,6.985703,-134.154541,0.009002,0.001472,0.037377,31.073957,1.582983,0.373774,-134.154541,0.038314,0.000000
36.230003,7.100021,-134.154541,0.009024,0.001488,0.037802,31.582472,1.608888,0.378024,-134.154541,0.038782,0.000000
36.510002,7.442978,-134.199036,0.009033,0.001512,0.038409,33.108021,1.686603,0.384091,-134.199036,0.039250,0.000000
36.790001,7.336853,-134.199036,0.009041,0.001524,0.038704,32.635952,1.662555,0.387040,-134.199036,0.039719,0.000000
37.070004,7.212852,-134.154541,0.009067,0.001538,0.039077,32.084370,1.634456,0.390771,-134.154541,0.040179,0.000000
37.350002,7.603096,-134.199036,0.009076,0.001562,0.039684,33.820259,1.722886,0.396842,-134.199036,0.040647,0.000000
37.630001,7.731567,-134.199036,0.009102,0.001583,0.040204,34.391731,1.751998,0.402043,-134.199036,0.041115,0.000000
37.910004,7.728584,-134.243515,0.009097,0.001599,0.040612,34.378460,1.751322,0.406119,-134.243515,0.041584,0.000000
38.190002,7.879395,-134.199036,0.009123,0.001618,0.041106,35.049297,1.785496,0.411062,-134.199036,0.042052,0.000000
38.470001,8.086807,-134.199036,0.009132,0.001638,0.041609,35.971916,1.832497,0.416092,-134.199036,0.042511,0.000000
38.750000,8.065208,-134.199036,0.009149,0.001653,0.041991,35.875839,1.827602,0.419908,-134.199036,0.042980,0.000000
39.030003,8.269272,-134.243515,0.009162,0.001674,0.042529,36.783558,1.873844,0.425286,-134.243515,0.043448,0.000000
39.310001,8.420082,-134.287994,0.009175,0.001695,0.043040,37.454395,1.908018,0.430403,-134.287994,0.043916,0.000000
39.590000,8.407791,-134.332474,0.009179,0.001713,0.043509,37.399723,1.905233,0.435085,-134.332474,0.044384,0.000000
39.870003,8.459183,-134.243515,0.009196,0.001730,0.043942,37.628323,1.916878,0.439423,-134.243515,0.044853,0.000000
40.150002,8.547432,-134.243515,0.009209,0.001747,0.044384,38.020878,1.936876,0.443843,-134.243515,0.045312,0.000000
40.430000,8.680000,-134.243515,0.009214,0.001764,0.044809,38.610569,1.966916,0.448094,-134.243515,0.045781,0.000000
40.710003,8.902306,-134.332474,0.009227,0.001783,0.045295,39.599434,2.017291,0.452950,-134.332474,0.046249,0.000000
40.990002,9.054977,-134.287994,0.009235,0.001806,0.045876,40.278553,2.051887,0.458760,-134.287994,0.046717,0.000000
41.270000,9.103760,-134.332474,0.009261,0.001824,0.046336,40.495544,2.062942,0.463358,-134.332474,0.047186,0.000000
41.550003,9.170410,-134.332474,0.009291,0.001843,0.046813,40.792023,2.078045,0.468127,-134.332474,0.047645,0.000000
41.830002,9.287338,-134.287994,0.009304,0.001863,0.047324,41.312145,2.104541,0.473244,-134.287994,0.048114,0.000000
42.110001,9.315636,-134.376953,0.009309,0.001880,0.047741,41.438019,2.110953,0.477408,-134.376953,0.048582,0.000000
42.390003,9.373360,-134.332474,0.009317,0.001893,0.048087,41.694786,2.124034,0.480875,-134.332474,0.049050,0.000000
42.670002,9.536827,-134.332474,0.009343,0.001911,0.048530,42.421925,2.161076,0.485299,-134.332474,0.049519,0.000000
42.950001,9.963936,-134.421432,0.009356,0.001937,0.049198,44.321800,2.257860,0.491976,-134.421432,0.049987,0.000000
43.230003,9.873825,-134.376953,0.009373,0.001952,0.049579,43.920967,2.237441,0.495791,-134.376953,0.050446,0.000000
43.510002,9.965431,-134.332474,0.009382,0.001972,0.050082,44.328453,2.258199,0.500821,-134.332474,0.050915,0.000000
43.790001,10.099854,-134.376953,0.009390,0.001991,0.050568,44.926392,2.288660,0.505677,-134.376953,0.051383,0.000000
44.070004,10.049210,-134.376953,0.009403,0.002005,0.050932,44.701118,2.277184,0.509322,-134.376953,0.051851,0.000000
44.350002,10.263702,-134.376953,0.009421,0.002024,0.051418,45.655228,2.325788,0.514178,-134.376953,0.052320,0.000000
44.630001,10.229439,-134.332474,0.009425,0.002038,0.051764,45.502815,2.318024,0.517645,-134.332474,0.052779,0.000000
44.910004,10.748528,-134.465912,0.009451,0.002065,0.052441,47.811840,2.435651,0.524409,-134.465912,0.053247,0.000000
45.190002,10.641281,-134.421432,0.009468,0.002080,0.052840,47.334782,2.411349,0.528398,-134.421432,0.053716,0.000000
45.470001,10.751511,-134.376953,0.009485,0.002099,0.053325,47.825108,2.436327,0.533254,-134.376953,0.054184,0.000000
45.750004,10.745178,-134.421432,0.009490,0.002115,0.053733,47.796940,2.434892,0.537330,-134.421432,0.054652,0.000000
46.030003,10.989082,-134.376953,0.009516,0.002137,0.054271,48.881878,2.490162,0.542709,-134.376953,0.055112,0.000000
46.310001,11.006584,-134.421432,0.009524,0.002152,0.054652,48.959732,2.494128,0.546524,-134.421432,0.055580,0.000000
46.590004,11.077332,-134.421432,0.009541,0.002168,0.055060,49.274433,2.510159,0.550600,-134.421432,0.056049,0.000000
46.870003,11.540192,-134.465912,0.009546,0.002193,0.055711,51.333336,2.615045,0.557106,-134.465912,0.056517,0.000000
47.150002,11.598282,-134.421432,0.009580,0.002213,0.056222,51.591736,2.628208,0.562220,-134.421432,0.056985,0.000000
47.430004,11.437790,-134.510391,0.009580,0.002229,0.056612,50.877831,2.591840,0.566122,-134.510391,0.057454,0.000000
47.710003,11.396454,-134.510391,0.009602,0.002244,0.056994,50.693958,2.582474,0.569941,-134.510391,0.057913,0.000000
47.990002,11.639618,-134.510391,0.009610,0.002263,0.057471,51.775608,2.637575,0.574710,-134.510391,0.058382,0.000000
48.270000,11.774788,-134.510391,0.009619,0.002281,0.057930,52.376873,2.668205,0.579305,-134.510391,0.058850,0.000000
48.550003,11.804207,-134.510391,0.009623,0.002295,0.058295,52.507736,2.674871,0.582950,-134.510391,0.059318,0.000000
48.830002,12.411545,-134.510391,0.009662,0.002323,0.058997,55.209309,2.812496,0.589971,-134.510391,0.059787,0.000000
49.110001,12.247696,-134.554871,0.009671,0.002341,0.059457,54.480473,2.775367,0.594569,-134.554871,0.060246,0.000000
49.390003,12.140831,-134.554871,0.009679,0.002359,0.059925,54.005112,2.751152,0.599251,-134.554871,0.060714,0.000000
49.670002,12.142319,-134.510391,0.009692,0.002371,0.060229,54.011730,2.751489,0.602287,-134.510391,0.061182,0.000000
49.950001,12.417503,-134.554871,0.009714,0.002394,0.060801,55.235813,2.813847,0.608009,-134.554871,0.061651,0.000000
50.230003,12.435379,-134.554871,0.009731,0.002408,0.061165,55.315327,2.817897,0.611654,-134.554871,0.062119,0.000000
50.510002,12.448410,-134.554871,0.009740,0.002424,0.061581,55.373295,2.820850,0.615814,-134.554871,0.062587,0.000000
50.790001,12.937332,-134.599365,0.009753,0.002448,0.062188,57.548126,2.931641,0.621885,-134.599365,0.063047,0.000000
51.070004,13.089630,-134.554871,0.009770,0.002468,0.062691,58.225582,2.966153,0.626915,-134.554871,0.063515,0.000000
51.350002,12.987602,-134.554871,0.009783,0.002487,0.063169,57.771740,2.943033,0.631688,-134.554871,0.063984,0.000000
51.630001,13.095222,-134.599365,0.009796,0.002501,0.063533,58.250458,2.967420,0.635329,-134.599365,0.064452,0.000000
51.910004,13.356628,-134.643845,0.009813,0.002524,0.064105,59.413250,3.026655,0.641051,-134.643845,0.064920,0.000000
52.190002,13.108253,-134.643845,0.009817,0.002534,0.064374,58.308422,2.970373,0.643739,-134.643845,0.065380,0.000000
52.470001,13.110115,-134.643845,0.009839,0.002553,0.064834,58.316704,2.970794,0.648337,-134.643845,0.065848,0.000000
52.750004,13.861931,-134.643845,0.009839,0.002579,0.065519,61.660950,3.141159,0.655188,-134.643845,0.066317,0.000000
53.030003,13.771446,-134.643845,0.009873,0.002595,0.065918,61.258453,3.120654,0.659177,-134.643845,0.066785,0.000000
53.310001,13.682449,-134.688324,0.009869,0.002612,0.066334,60.862576,3.100487,0.663341,-134.688324,0.067253,0.000000
53.590004,13.699951,-134.688324,0.009891,0.002627,0.066733,60.940426,3.104453,0.667330,-134.688324,0.067722,0.000000
53.870003,14.033226,-134.688324,0.009908,0.002649,0.067279,62.422909,3.179975,0.672792,-134.688324,0.068181,0.000000
54.150002,13.836617,-134.688324,0.009929,0.002661,0.067600,61.548344,3.135422,0.676001,-134.688324,0.068649,0.000000
54.430004,14.048119,-134.732803,0.009925,0.002683,0.068138,62.489151,3.183349,0.681379,-134.732803,0.069118,0.000000
54.710003,14.716156,-134.732803,0.009942,0.002709,0.068797,65.460732,3.334729,0.687969,-134.732803,0.069586,0.000000
54.990002,14.487518,-134.732803,0.009955,0.002725,0.069205,64.443703,3.282919,0.692045,-134.732803,0.070054,0.000000
55.270004,14.521782,-134.732803,0.009990,0.002742,0.069655,64.596115,3.290683,0.696553,-134.732803,0.070514,0.000000
55.550003,14.444695,-134.688324,0.009994,0.002757,0.070037,64.253212,3.273214,0.700368,-134.688324,0.070982,0.000000
55.830002,14.721001,-134.688324,0.009990,0.002776,0.070505,65.482285,3.335826,0.705054,-134.688324,0.071450,0.000000
56.110004,14.972725,-134.777283,0.010016,0.002796,0.071017,66.602005,3.392868,0.710171,-134.777283,0.071919,0.000000
56.390003,14.741478,-134.732803,0.010011,0.002810,0.071381,65.573372,3.340466,0.713812,-134.732803,0.072387,0.000000
56.670002,15.380096,-134.732803,0.010029,0.002836,0.072031,68.414085,3.485180,0.720315,-134.732803,0.072847,0.000000
56.950005,15.332436,-134.732803,0.010050,0.002855,0.072509,68.202080,3.474380,0.725087,-134.732803,0.073315,0.000000
57.230003,15.173805,-134.732803,0.010063,0.002869,0.072873,67.496460,3.438434,0.728729,-134.732803,0.073783,0.000000
57.510002,15.126511,-134.777283,0.010080,0.002885,0.073272,67.286079,3.427716,0.732718,-134.777283,0.074252,0.000000
57.790001,15.799385,-134.777283,0.010085,0.002908,0.073853,70.279175,3.580192,0.738528,-134.777283,0.074720,0.000000
58.070004,15.402443,-134.777283,0.010119,0.002920,0.074165,68.513489,3.490244,0.741650,-134.777283,0.075188,0.000000
58.350002,15.283653,-134.866241,0.010119,0.002932,0.074469,67.985085,3.463326,0.744686,-134.866241,0.075648,0.000000
58.630001,16.125587,-134.777283,0.010145,0.002959,0.075171,71.730194,3.654110,0.751710,-134.777283,0.076116,0.000000
58.910004,16.141968,-134.910721,0.010149,0.002979,0.075674,71.803062,3.657822,0.756741,-134.910721,0.076585,0.000000
59.190002,16.243256,-134.866241,0.010158,0.002997,0.076134,72.253609,3.680774,0.761335,-134.866241,0.077053,0.000000
59.470001,16.196335,-134.777283,0.010175,0.003014,0.076559,72.044899,3.670142,0.765586,-134.777283,0.077521,0.000000
59.750004,16.527374,-134.821762,0.010188,0.003035,0.077088,73.517433,3.745157,0.770877,-134.821762,0.077981,0.000000
60.030003,16.464073,-134.866241,0.010210,0.003051,0.077504,73.235855,3.730812,0.775037,-134.866241,0.078449,0.000000
60.310001,16.308418,-134.866241,0.010223,0.003065,0.077842,72.543465,3.695540,0.778420,-134.866241,0.078917,0.000000
60.590004,16.969383,-134.910721,0.010236,0.003090,0.078475,75.483589,3.845317,0.784753,-134.910721,0.079386,0.000000
60.870003,16.838310,-134.866241,0.010248,0.003105,0.078874,74.900543,3.815616,0.788742,-134.866241,0.079854,0.000000
61.150002,17.061729,-134.866241,0.010261,0.003126,0.079394,75.894363,3.866243,0.793942,-134.866241,0.080322,0.000000
61.430004,17.009598,-134.910721,0.010274,0.003142,0.079811,75.662468,3.854430,0.798106,-134.910721,0.080782,0.000000
61.710003,17.288506,-134.910721,0.010292,0.003162,0.080314,76.903114,3.917631,0.803136,-134.910721,0.081250,0.000000
61.990002,16.922462,-134.866241,0.010309,0.003172,0.080565,75.274872,3.834685,0.805653,-134.866241,0.081719,0.000000
62.270004,17.999367,-134.910721,0.010317,0.003202,0.081328,80.065186,4.078715,0.813283,-134.910721,0.082187,0.000000
62.550003,17.981865,-134.910721,0.010343,0.003221,0.081823,79.987328,4.074749,0.818226,-134.910721,0.082655,0.000000
62.830002,17.967339,-134.866241,0.010339,0.003240,0.082300,79.922714,4.071457,0.822995,-134.866241,0.083115,0.000000
63.110004,17.713013,-134.999680,0.010361,0.003255,0.082681,78.791412,4.013826,0.826810,-134.999680,0.083583,0.000000
63.390003,17.956169,-134.999680,0.010374,0.003273,0.083132,79.873032,4.068926,0.831322,-134.999680,0.084052,0.000000
63.670002,18.048515,-134.955200,0.010378,0.003292,0.083609,80.283806,4.089852,0.836091,-134.955200,0.084520,0.000000
63.950005,18.344551,-134.955200,0.010408,0.003309,0.084043,81.600639,4.156935,0.840428,-134.955200,0.084988,0.000000
64.230003,18.522919,-134.999680,0.010417,0.003329,0.084563,82.394058,4.197353,0.845629,-134.999680,0.085448,0.000000
64.510002,18.827896,-135.044174,0.010425,0.003349,0.085057,83.750664,4.266462,0.850572,-135.044174,0.085916,0.000000
64.790001,18.920616,-134.999680,0.010438,0.003368,0.085551,84.163101,4.287473,0.855515,-134.999680,0.086384,0.000000
65.070000,19.051689,-135.044174,0.010460,0.003387,0.086020,84.746147,4.317174,0.860201,-135.044174,0.086852,0.000000
65.350006,18.958221,-134.999680,0.010464,0.003402,0.086419,84.330383,4.295994,0.864190,-134.999680,0.087321,0.000000
65.630005,19.213303,-135.044174,0.010490,0.003421,0.086905,85.465042,4.353796,0.869046,-135.044174,0.087789,0.000000
65.910004,18.893806,-135.133133,0.010507,0.003433,0.087199,84.043846,4.281398,0.871994,-135.133133,0.088249,0.000000
66.190002,19.905540,-135.044174,0.010494,0.003461,0.087902,88.544266,4.510660,0.879019,-135.044174,0.088717,0.000000
66.470001,19.787125,-135.088654,0.010520,0.003475,0.088275,88.017525,4.483827,0.882747,-135.088654,0.089185,0.000000
66.750000,20.100662,-135.044174,0.010537,0.003497,0.088830,89.412209,4.554875,0.888300,-135.044174,0.089654,0.000000
67.030006,19.892136,-135.044174,0.010559,0.003511,0.089185,88.484642,4.507622,0.891854,-135.044174,0.090122,0.000000
67.310005,20.269348,-135.088654,0.010555,0.003532,0.089706,90.162567,4.593100,0.897058,-135.088654,0.090582,0.000000
67.590004,20.520325,-135.133133,0.010585,0.003550,0.090165,91.278961,4.649972,0.901653,-135.133133,0.091050,0.000000
67.870003,20.391113,-135.088654,0.010572,0.003563,0.090512,90.704201,4.620692,0.905124,-135.088654,0.091518,0.000000
68.150002,21.136604,-135.088654,0.010602,0.003588,0.091128,94.020309,4.789623,0.911278,-135.088654,0.091987,0.000000
68.430000,21.610634,-135.133133,0.010619,0.003611,0.091717,96.128899,4.897039,0.917175,-135.133133,0.092455,0.000000
68.710007,21.090797,-135.133133,0.010628,0.003623,0.092013,93.816551,4.779243,0.920127,-135.133133,0.092923,0.000000
68.990005,21.326881,-135.133133,0.010645,0.003641,0.092472,94.866707,4.832740,0.924722,-135.133133,0.093383,0.000000
69.270004,21.727188,-135.133133,0.010654,0.003661,0.092984,96.647362,4.923451,0.929839,-135.133133,0.093851,0.000000
69.550003,21.930870,-135.177612,0.010662,0.003678,0.093409,97.553383,4.969606,0.934086,-135.177612,0.094319,0.000000
69.830002,21.564087,-135.133133,0.010684,0.003693,0.093790,95.921852,4.886492,0.937905,-135.133133,0.094788,0.000000
70.110001,22.888245,-135.177612,0.010684,0.003719,0.094458,101.811996,5.186550,0.944581,-135.177612,0.095256,0.000000
70.390007,23.159332,-135.177612,0.010701,0.003736,0.094892,103.017853,5.247980,0.948919,-135.177612,0.095715,0.000000
70.670006,23.090065,-135.133133,0.010718,0.003752,0.095299,102.709740,5.232284,0.952991,-135.133133,0.096184,0.000000
70.950005,23.126190,-135.133133,0.010736,0.003768,0.095698,102.870430,5.240469,0.956980,-135.133133,0.096652,0.000000
71.230003,23.453506,-135.177612,0.010740,0.003786,0.096167,104.326408,5.314641,0.961666,-135.177612,0.097120,0.000000
71.510002,23.931633,-135.266571,0.010740,0.003807,0.096695,106.453217,5.422986,0.966954,-135.266571,0.097589,0.000000
71.790001,24.010948,-135.222092,0.010774,0.003822,0.097086,106.806030,5.440958,0.970860,-135.222092,0.098048,0.000000
72.070000,24.732979,-135.222092,0.010783,0.003845,0.097667,110.017784,5.604573,0.976669,-135.222092,0.098517,0.000000
72.350006,25.155991,-135.177612,0.010800,0.003864,0.098144,111.899437,5.700429,0.981438,-135.177612,0.098985,0.000000
72.630005,25.360054,-135.266571,0.010805,0.003880,0.098560,112.807152,5.746671,0.985602,-135.266571,0.099453,0.000000
72.910004,25.802803,-135.266571,0.010822,0.003900,0.099054,114.776604,5.846999,0.990545,-135.266571,0.099922,0.000000
73.190002,26.064949,-135.222092,0.010822,0.003917,0.099497,115.942680,5.906402,0.994966,-135.222092,0.100390,0.000000
73.470001,26.504723,-135.266571,0.010835,0.003932,0.099878,117.898895,6.006056,0.998781,-135.266571,0.100850,0.000000
73.750000,26.648087,-135.266571,0.010861,0.003947,0.100251,118.536606,6.038543,1.002513,-135.266571,0.101318,0.000000
74.030006,27.975594,-135.266571,0.010869,0.003975,0.100954,124.441658,6.339360,1.009537,-135.266571,0.101786,0.000000
74.310005,28.480904,-135.311050,0.010887,0.003994,0.101439,126.689384,6.453865,1.014393,-135.311050,0.102255,0.000000
74.590004,28.656662,-135.311050,0.010904,0.004009,0.101830,127.471199,6.493692,1.018296,-135.311050,0.102723,0.000000
74.870003,28.994408,-135.222092,0.010912,0.004024,0.102220,128.973572,6.570227,1.022198,-135.222092,0.103182,0.000000
75.150002,30.058647,-135.311050,0.010930,0.004046,0.102766,133.707535,6.811387,1.027660,-135.311050,0.103651,0.000000
75.430000,30.126045,-135.266571,0.010938,0.004059,0.103096,134.007339,6.826659,1.030956,-135.266571,0.104119,0.000000
75.710007,30.886055,-135.400009,0.010947,0.004077,0.103547,137.388031,6.998880,1.035468,-135.400009,0.104587,0.000000
75.990005,32.395653,-135.355530,0.010943,0.004106,0.104292,144.103058,7.340960,1.042924,-135.355530,0.105055,0.000000
76.270004,32.754997,-135.355530,0.010973,0.004119,0.104631,145.701508,7.422389,1.046308,-135.355530,0.105524,0.000000
76.550003,33.297173,-135.311050,0.010981,0.004138,0.105116,148.113220,7.545247,1.051164,-135.311050,0.105983,0.000000
76.830002,33.707893,-135.311050,0.011007,0.004152,0.105472,149.940201,7.638318,1.054718,-135.311050,0.106452,0.000000
77.110001,34.466049,-135.400009,0.011007,0.004173,0.105983,153.312637,7.810118,1.059835,-135.400009,0.106920,0.000000
77.390007,35.391022,-135.400009,0.011016,0.004190,0.106435,157.427124,8.019720,1.064347,-135.400009,0.107388,0.000000
77.670006,35.618538,-135.400009,0.011029,0.004202,0.106738,158.439163,8.071276,1.067378,-135.400009,0.107857,0.000000
77.950005,37.485619,-135.444489,0.011055,0.004231,0.107458,166.744354,8.494363,1.074577,-135.444489,0.108317,0.000000
78.230003,38.373726,-135.400009,0.011050,0.004250,0.107961,170.694855,8.695610,1.079607,-135.400009,0.108785,0.000000
78.510002,38.907707,-135.444489,0.011063,0.004265,0.108325,173.070129,8.816613,1.083252,-135.444489,0.109253,0.000000
78.790001,39.441689,-135.444489,0.011063,0.004280,0.108707,175.445389,8.937614,1.087067,-135.444489,0.109721,0.000000
79.070007,40.618385,-135.400009,0.011081,0.004303,0.109296,180.679596,9.204257,1.092964,-135.400009,0.110190,0.000000
79.350006,41.282326,-135.400009,0.011102,0.004316,0.109617,183.632950,9.354709,1.096174,-135.400009,0.110649,0.000000
79.630005,41.781677,-135.444489,0.011098,0.004328,0.109938,185.854187,9.467864,1.099380,-135.444489,0.111117,0.000000
79.910004,43.757858,-135.533463,0.011119,0.004356,0.110640,194.644669,9.915672,1.106404,-135.533463,0.111586,0.000000
80.190002,44.463875,-135.488983,0.011124,0.004372,0.111057,197.785187,10.075658,1.110568,-135.488983,0.112054,0.000000
80.470001,45.772018,-135.488983,0.011137,0.004394,0.111603,203.604111,10.372087,1.116033,-135.488983,0.112522,0.000000
80.750008,46.674652,-135.444489,0.011154,0.004410,0.112019,207.619217,10.576628,1.120193,-135.444489,0.112991,0.000000
81.030006,48.055779,-135.488983,0.011167,0.004430,0.112531,213.762772,10.889595,1.125310,-135.488983,0.113450,0.000000
81.310005,48.597954,-135.533463,0.011171,0.004443,0.112861,216.174500,11.012454,1.128606,-135.533463,0.113919,0.000000
81.590004,49.349030,-135.533463,0.011175,0.004457,0.113216,219.515442,11.182650,1.132161,-135.533463,0.114387,0.000000
81.870003,51.226532,-135.444489,0.011180,0.004483,0.113875,227.866989,11.608098,1.138754,-135.444489,0.114855,0.000000
82.150002,52.689209,-135.488983,0.011197,0.004503,0.114370,234.373306,11.939545,1.143697,-135.488983,0.115323,0.000000
82.430000,53.844307,-135.444489,0.011188,0.004521,0.114829,239.511444,12.201295,1.148292,-135.444489,0.115783,0.000000
82.710007,54.810989,-135.577942,0.011219,0.004537,0.115237,243.811462,12.420348,1.152368,-135.577942,0.116252,0.000000
82.990005,55.945984,-135.577942,0.011227,0.004556,0.115714,248.860168,12.677541,1.157137,-135.577942,0.116720,0.000000
83.270004,56.909309,-135.533463,0.011232,0.004569,0.116043,253.145248,12.895834,1.160434,-135.533463,0.117188,0.000000
83.550003,58.288948,-135.533463,0.011244,0.004592,0.116642,259.282196,13.208465,1.166418,-135.533463,0.117656,0.000000
83.830002,60.421524,-135.533463,0.011253,0.004614,0.117205,268.768372,13.691713,1.172053,-135.533463,0.118125,0.000000
84.110001,61.884575,-135.622421,0.011270,0.004635,0.117717,275.276337,14.023245,1.177171,-135.622421,0.118584,0.000000
84.390007,63.027763,-135.622421,0.011266,0.004650,0.118099,280.361481,14.282295,1.180986,-135.622421,0.119053,0.000000
84.670006,64.287865,-135.533463,0.011279,0.004667,0.118550,285.966705,14.567838,1.185497,-135.533463,0.119521,0.000000
84.950005,65.484306,-135.622421,0.011283,0.004683,0.118957,291.288757,14.838956,1.189574,-135.622421,0.119989,0.000000
85.230003,67.006554,-135.577942,0.011305,0.004703,0.119460,298.060028,15.183902,1.194604,-135.577942,0.120458,0.000000
85.510002,66.905281,-135.711380,0.011300,0.004698,0.119330,297.609558,15.160954,1.193302,-135.711380,0.119564,0.000000
85.790001,66.445015,-135.666901,0.011309,0.004695,0.119261,295.562195,15.056655,1.192609,-135.666901,0.119330,0.000000
86.070007,65.969872,-135.622421,0.011305,0.004694,0.119217,293.448639,14.948986,1.192174,-135.622421,0.119330,0.000000
86.350006,65.566216,-135.622421,0.011331,0.004693,0.119200,291.653107,14.857516,1.192000,-135.622421,0.119330,0.000000
86.630005,65.196465,-135.666901,0.011326,0.004693,0.119191,290.008362,14.773730,1.191913,-135.666901,0.119330,0.000000
86.910004,64.893715,-135.666901,0.011322,0.004693,0.119191,288.661652,14.705127,1.191913,-135.666901,0.119330,0.000000
87.190002,64.623375,-135.711380,0.011318,0.004692,0.119183,287.459137,14.643867,1.191826,-135.711380,0.119330,0.000000
87.470001,64.387657,-135.666901,0.011331,0.004692,0.119183,286.410614,14.590451,1.191826,-135.666901,0.119330,0.000000
87.750008,64.160515,-135.666901,0.011322,0.004692,0.119183,285.400238,14.538980,1.191826,-135.666901,0.119330,0.000000
88.030006,63.958321,-135.711380,0.011335,0.004692,0.119174,284.500824,14.493162,1.191738,-135.711380,0.119330,0.000000
88.310005,63.760582,-135.755859,0.011331,0.004692,0.119174,283.621246,14.448355,1.191738,-135.755859,0.119330,0.000000
88.590004,63.595253,-135.711380,0.011326,0.004692,0.119174,282.885803,14.410891,1.191738,-135.711380,0.119330,0.000000
88.870003,63.445564,-135.711380,0.011339,0.004692,0.119174,282.219971,14.376970,1.191738,-135.711380,0.119330,0.000000
89.150002,63.297356,-135.711380,0.011339,0.004692,0.119174,281.560699,14.343386,1.191738,-135.711380,0.119330,0.000000
89.430008,63.157341,-135.711380,0.011344,0.004692,0.119174,280.937897,14.311658,1.191738,-135.711380,0.119330,0.000000
89.710007,63.027390,-135.800339,0.011339,0.004692,0.119174,280.359833,14.282210,1.191738,-135.800339,0.119330,0.000000
89.990005,62.904503,-135.800339,0.011339,0.004692,0.119174,279.813202,14.254364,1.191738,-135.800339,0.119330,0.000000
90.270004,62.799866,-135.711380,0.011322,0.004692,0.119174,279.347748,14.230653,1.191738,-135.711380,0.119330,0.000000
90.550003,62.692627,-135.711380,0.011344,0.004692,0.119174,278.870728,14.206352,1.191738,-135.711380,0.119330,0.000000
90.830002,62.599533,-135.755859,0.011348,0.004692,0.119174,278.456635,14.185257,1.191738,-135.755859,0.119330,0.000000
91.110001,62.490799,-135.844818,0.011339,0.004692,0.119174,277.972961,14.160618,1.191738,-135.844818,0.119330,0.000000
91.390007,62.401428,-135.889313,0.011326,0.004692,0.119174,277.575409,14.140366,1.191738,-135.889313,0.119330,0.000000
91.670006,62.312057,-135.800339,0.011344,0.004692,0.119166,277.177887,14.120114,1.191655,-135.800339,0.119330,0.000000
91.950005,62.233864,-135.800339,0.011344,0.004692,0.119166,276.830048,14.102395,1.191655,-135.800339,0.119330,0.000000
92.230003,62.160873,-135.800339,0.011348,0.004692,0.119166,276.505371,14.085855,1.191655,-135.800339,0.119330,0.000000
92.510002,62.068527,-135.800339,0.011335,0.004692,0.119166,276.094604,14.064929,1.191655,-135.800339,0.119330,0.000000
92.790001,62.007462,-135.844818,0.011352,0.004692,0.119166,275.822968,14.051092,1.191655,-135.844818,0.119330,0.000000
93.070007,61.939690,-135.844818,0.011348,0.004692,0.119166,275.521515,14.035734,1.191655,-135.844818,0.119330,0.000000
93.350006,61.870796,-135.800339,0.011348,0.004692,0.119166,275.215057,14.020123,1.191655,-135.800339,0.119330,0.000000
93.630005,61.801537,-135.844818,0.011352,0.004692,0.119166,274.906952,14.004428,1.191655,-135.844818,0.119330,0.000000
93.910004,61.730042,-135.889313,0.011352,0.004692,0.119166,274.588928,13.988228,1.191655,-135.889313,0.119330,0.000000
94.190002,61.673065,-135.889313,0.011352,0.004692,0.119166,274.335510,13.975316,1.191655,-135.889313,0.119330,0.000000
94.470001,61.615349,-135.889313,0.011344,0.004692,0.119166,274.078766,13.962238,1.191655,-135.889313,0.119330,0.000000
94.750008,61.563591,-135.889313,0.011339,0.004692,0.119166,273.848541,13.950509,1.191655,-135.889313,0.119330,0.000000
95.030006,61.512947,-135.889313,0.011348,0.004692,0.119166,273.623260,13.939033,1.191655,-135.889313,0.119330,0.000000
95.310005,61.464165,-135.933792,0.011357,0.004692,0.119166,273.406250,13.927979,1.191655,-135.933792,0.119330,0.000000
95.590004,61.415756,-135.889313,0.011348,0.004692,0.119166,273.190918,13.917009,1.191655,-135.889313,0.119330,0.000000
95.870003,61.368095,-135.933792,0.011357,0.004692,0.119166,272.978912,13.906209,1.191655,-135.933792,0.119330,0.000000
96.150002,61.323036,-135.889313,0.011344,0.004692,0.119166,272.778503,13.895998,1.191655,-135.889313,0.119330,0.000000
96.430008,61.269043,-135.889313,0.011357,0.004692,0.119166,272.538300,13.883763,1.191655,-135.889313,0.119330,0.000000
96.710007,61.236275,-135.933792,0.011339,0.004692,0.119166,272.392548,13.876338,1.191655,-135.933792,0.119330,0.000000
96.990005,61.180046,-135.933792,0.011348,0.004692,0.119166,272.142426,13.863597,1.191655,-135.933792,0.119330,0.000000
97.270004,61.153610,-135.978271,0.011348,0.004692,0.119166,272.024841,13.857607,1.191655,-135.978271,0.119330,0.000000
97.550003,61.104454,-136.022751,0.011335,0.004692,0.119166,271.806183,13.846467,1.191655,-136.022751,0.119330,0.000000
97.830002,61.057167,-135.978271,0.011344,0.004692,0.119166,271.595856,13.835752,1.191655,-135.978271,0.119330,0.000000
98.110008,61.023651,-136.022751,0.011352,0.004692,0.119166,271.446747,13.828157,1.191655,-136.022751,0.119330,0.000000
98.390007,60.991997,-136.022751,0.011357,0.004692,0.119166,271.305939,13.820984,1.191655,-136.022751,0.119330,0.000000
98.670006,60.944710,-135.978271,0.011344,0.004692,0.119166,271.095612,13.810269,1.191655,-135.978271,0.119330,0.000000
98.950005,60.926086,-135.978271,0.011348,0.004692,0.119166,271.012756,13.806048,1.191655,-135.978271,0.119330,0.000000
99.230003,60.889221,-136.022751,0.011357,0.004692,0.119166,270.848785,13.797694,1.191655,-136.022751,0.119330,0.000000
99.510002,60.849754,-136.022751,0.011357,0.004692,0.119166,270.673218,13.788752,1.191655,-136.022751,0.119330,0.000000
99.790009,60.816238,-136.022751,0.011352,0.004692,0.119166,270.524139,13.781157,1.191655,-136.022751,0.119330,0.000000
100.070007,60.782356,-136.022751,0.011348,0.004692,0.119166,270.373413,13.773479,1.191655,-136.022751,0.119330,0.000000
100.350006,60.743256,-136.111710,0.011348,0.004692,0.119166,270.199493,13.764618,1.191655,-136.111710,0.119330,0.000000
100.630005,60.716820,-136.067230,0.011357,0.004692,0.119166,270.081909,13.758628,1.191655,-136.067230,0.119330,0.000000
100.910004,60.689636,-136.067230,0.011357,0.004692,0.119166,269.960999,13.752468,1.191655,-136.067230,0.119330,0.000000
101.190002,60.659470,-136.156189,0.011344,0.004692,0.119166,269.826782,13.745632,1.191655,-136.156189,0.119330,0.000000
101.470001,60.623726,-136.111710,0.011335,0.004692,0.119166,269.667816,13.737533,1.191655,-136.111710,0.119330,0.000000
101.750008,60.598404,-136.156189,0.011352,0.004692,0.119166,269.555176,13.731794,1.191655,-136.156189,0.119330,0.000000
102.030006,60.558189,-136.111710,0.011352,0.004692,0.119166,269.376282,13.722682,1.191655,-136.111710,0.119330,0.000000
102.310005,60.533981,-136.111710,0.011348,0.004692,0.119166,269.268585,13.717196,1.191655,-136.111710,0.119330,0.000000
102.590004,60.503448,-136.156189,0.011361,0.004692,0.119166,269.132782,13.710278,1.191655,-136.156189,0.119330,0.000000
102.870003,60.460999,-136.156189,0.011352,0.004692,0.119166,268.943939,13.700658,1.191655,-136.156189,0.119330,0.000000
103.150002,60.445732,-136.156189,0.011357,0.004692,0.119166,268.876038,13.697198,1.191655,-136.156189,0.119330,0.000000
103.430008,60.407745,-136.156189,0.011369,0.004692,0.119166,268.707062,13.688591,1.191655,-136.156189,0.119330,0.000000
103.710007,60.385780,-136.156189,0.011365,0.004692,0.119166,268.609375,13.683614,1.191655,-136.156189,0.119330,0.000000
103.990005,60.360458,-136.200668,0.011357,0.004692,0.119166,268.496735,13.677876,1.191655,-136.200668,0.119330,0.000000
104.270004,60.336624,-136.156189,0.011357,0.004692,0.119166,268.390717,13.672474,1.191655,-136.156189,0.119330,0.000000
104.550003,60.308693,-136.156189,0.011361,0.004692,0.119166,268.266479,13.666144,1.191655,-136.156189,0.119330,0.000000
104.830002,60.284492,-136.200668,0.011361,0.004692,0.119166,268.158813,13.660662,1.191655,-136.200668,0.119330,0.000000
105.110008,60.251724,-136.200668,0.011357,0.004692,0.119166,268.013062,13.653236,1.191655,-136.200668,0.119330,0.000000
105.390007,60.236458,-136.245148,0.011339,0.004692,0.119166,267.945160,13.649776,1.191655,-136.245148,0.119330,0.000000
105.670006,60.215233,-136.245148,0.011365,0.004692,0.119166,267.850739,13.644966,1.191655,-136.245148,0.119330,0.000000
105.950005,60.195496,-136.156189,0.011374,0.004692,0.119166,267.762939,13.640494,1.191655,-136.156189,0.119330,0.000000
106.230003,60.163467,-136.245148,0.011361,0.004692,0.119166,267.620483,13.633237,1.191655,-136.245148,0.119330,0.000000
106.510002,60.137779,-136.245148,0.011369,0.004692,0.119166,267.506195,13.627416,1.191655,-136.245148,0.119330,0.000000
106.790009,60.128838,-136.245148,0.011361,0.004692,0.119166,267.466431,13.625389,1.191655,-136.245148,0.119330,0.000000
107.070007,60.101654,-136.289627,0.011344,0.004692,0.119166,267.345520,13.619229,1.191655,-136.289627,0.119330,0.000000
107.350006,60.074104,-136.200668,0.011357,0.004692,0.119166,267.222961,13.612987,1.191655,-136.200668,0.119330,0.000000
107.630005,60.050270,-136.245148,0.011348,0.004692,0.119166,267.116943,13.607585,1.191655,-136.245148,0.119330,0.000000
107.910004,60.032021,-136.245148,0.011352,0.004692,0.119166,267.035767,13.603450,1.191655,-136.245148,0.119330,0.000000
108.190002,60.015640,-136.334122,0.011361,0.004692,0.119166,266.962891,13.599739,1.191655,-136.334122,0.119330,0.000000
108.470009,59.988083,-136.245148,0.011352,0.004692,0.119166,266.840332,13.593493,1.191655,-136.245148,0.119330,0.000000
108.750008,59.970955,-136.289627,0.011357,0.004692,0.119166,266.764130,13.589613,1.191655,-136.289627,0.119330,0.000000
109.030006,59.960526,-136.334122,0.011369,0.004692,0.119166,266.717743,13.587250,1.191655,-136.334122,0.119330,0.000000
109.310005,59.932976,-136.334122,0.011361,0.004692,0.119166,266.595184,13.581006,1.191655,-136.334122,0.119330,0.000000
109.590004,59.903183,-136.334122,0.011357,0.004692,0.119166,266.462677,13.574256,1.191655,-136.334122,0.119330,0.000000
109.870003,59.896851,-136.378601,0.011352,0.004692,0.119166,266.434509,13.572821,1.191655,-136.378601,0.119330,0.000000
110.150002,59.875626,-136.289627,0.011361,0.004692,0.119166,266.340088,13.568010,1.191655,-136.289627,0.119330,0.000000
110.430008,59.856262,-136.334122,0.011369,0.004692,0.119166,266.253937,13.563623,1.191655,-136.334122,0.119330,0.000000
110.710007,59.832802,-136.423080,0.011357,0.004692,0.119166,266.149597,13.558307,1.191655,-136.423080,0.119330,0.000000
110.990005,59.814186,-136.378601,0.011352,0.004692,0.119166,266.066803,13.554088,1.191655,-136.378601,0.119330,0.000000
111.270004,59.786629,-136.334122,0.011361,0.004692,0.119166,265.944214,13.547844,1.191655,-136.334122,0.119330,0.000000
111.550003,59.763916,-136.289627,0.011357,0.004692,0.119166,265.843170,13.542697,1.191655,-136.289627,0.119330,0.000000
111.830002,59.750511,-136.378601,0.011357,0.004692,0.119166,265.783539,13.539660,1.191655,-136.378601,0.119330,0.000000
112.110008,59.741943,-136.378601,0.011365,0.004692,0.119166,265.745422,13.537718,1.191655,-136.378601,0.119330,0.000000
112.390007,59.714760,-136.467560,0.011369,0.004692,0.119166,265.624512,13.531558,1.191655,-136.467560,0.119330,0.000000
112.670006,59.703590,-136.467560,0.011352,0.004692,0.119166,265.574829,13.529027,1.191655,-136.467560,0.119330,0.000000
112.950005,59.694656,-136.423080,0.011357,0.004692,0.119166,265.535095,13.527002,1.191655,-136.423080,0.119330,0.000000
113.230003,59.666351,-136.423080,0.011357,0.004692,0.119166,265.409180,13.520589,1.191655,-136.423080,0.119330,0.000000
113.510002,59.643265,-136.423080,0.011369,0.004692,0.119166,265.306488,13.515357,1.191655,-136.423080,0.119330,0.000000
113.790009,59.642891,-136.512039,0.011361,0.004692,0.119166,265.304840,13.515272,1.191655,-136.512039,0.119330,0.000000
114.070007,59.625763,-136.423080,0.011348,0.004692,0.119166,265.228638,13.511392,1.191655,-136.423080,0.119330,0.000000
114.350006,59.614594,-136.423080,0.011348,0.004692,0.119166,265.178955,13.508861,1.191655,-136.423080,0.119330,0.000000
114.630005,59.594482,-136.423080,0.011352,0.004692,0.119166,265.089508,13.504303,1.191655,-136.423080,0.119330,0.000000
114.910004,59.584801,-136.512039,0.011357,0.004692,0.119166,265.046417,13.502109,1.191655,-136.512039,0.119330,0.000000
115.190002,59.578102,-136.467560,0.011361,0.004692,0.119166,265.016632,13.500590,1.191655,-136.467560,0.119330,0.000000
115.470009,59.553894,-136.467560,0.011361,0.004692,0.119166,264.908966,13.495106,1.191655,-136.467560,0.119330,0.000000
115.750008,59.552406,-136.467560,0.011357,0.004692,0.119166,264.902344,13.494768,1.191655,-136.467560,0.119330,0.000000
115.800003,59.537140,-136.467560,0.011361,0.004692,0.119166,264.834412,13.491309,1.191655,-136.467560,0.119330,0.000000