File: Data/compression 6/AutoNoheating-10-6-day3-5-240301_03012024_160114.csv
Time (sec),S:Load (lbs),S:HL1 (DIM),S:LVDT (in),S:Position (in),Ch:Position (mm),Ch:Load (N),Ch:Stress (MPa),Ch:Strain (mm/mm),Ch:HL1 (DIM),Set Point (),Cycles ()
0.110000,-0.006325,-173.342270,0.000013,-0.000000,-0.000000,-0.028134,-0.001433,-0.000000,-173.342270,0.000199,0.000000
0.370000,-0.006699,-173.386749,0.000013,-0.000000,-0.000000,-0.029797,-0.001518,-0.000000,-173.386749,0.000199,0.000000
0.630000,-0.059204,-173.386749,0.000000,0.000134,0.003408,-0.263353,-0.013416,0.034083,-173.386749,0.004345,0.000000
0.890000,-0.008186,-173.475708,0.000172,0.000304,0.007709,-0.036415,-0.001855,0.077095,-173.475708,0.008664,0.000000
1.150000,0.002235,-173.475708,0.000341,0.000473,0.012002,0.009944,0.000507,0.120023,-173.475708,0.013000,0.000000
1.410000,-0.040215,-173.520187,0.000504,0.000640,0.016260,-0.178883,-0.009113,0.162603,-173.520187,0.017336,0.000000
1.670000,0.003357,-173.520187,0.000698,0.000815,0.020701,0.014932,0.000761,0.207007,-173.520187,0.021655,0.000000
1.930000,-0.016380,-173.564667,0.000871,0.000976,0.024803,-0.072863,-0.003712,0.248028,-173.564667,0.025991,0.000000
2.190000,-0.060692,-173.564667,0.001039,0.001152,0.029260,-0.269971,-0.013753,0.292603,-173.564667,0.030327,0.000000
2.450000,-0.026436,-173.653625,0.001216,0.001325,0.033666,-0.117593,-0.005990,0.336655,-173.653625,0.034663,0.000000
2.710000,-0.023087,-173.609146,0.001380,0.001491,0.037872,-0.102694,-0.005231,0.378717,-173.609146,0.038982,0.000000
2.970000,-0.034256,-173.653625,0.001569,0.001664,0.042277,-0.152378,-0.007763,0.422773,-173.653625,0.043318,0.000000
3.230000,-0.007072,-173.742599,0.001720,0.001836,0.046622,-0.031460,-0.001603,0.466220,-173.742599,0.047654,0.000000
3.490000,0.009308,-173.698120,0.001893,0.002009,0.051019,0.041403,0.002109,0.510189,-173.698120,0.051990,0.000000
3.750000,-0.006699,-173.742599,0.002074,0.002172,0.055181,-0.029797,-0.001518,0.551815,-173.742599,0.056309,0.000000
4.010000,-0.007072,-173.698120,0.002255,0.002344,0.059526,-0.031460,-0.001603,0.595262,-173.698120,0.060645,0.000000
4.270000,-0.008560,-173.787079,0.002432,0.002518,0.063967,-0.038078,-0.001940,0.639666,-173.787079,0.064981,0.000000
4.530000,-0.056229,-173.876038,0.002596,0.002685,0.068207,-0.250117,-0.012742,0.682072,-173.876038,0.069317,0.000000
4.790000,-0.021965,-173.831558,0.002768,0.002857,0.072578,-0.097705,-0.004977,0.725780,-173.831558,0.073636,0.000000
5.050000,0.002609,-173.831558,0.002932,0.003031,0.076984,0.011607,0.000591,0.769836,-173.831558,0.077972,0.000000
5.310000,-0.025688,-173.876038,0.003122,0.003198,0.081242,-0.114267,-0.005821,0.812416,-173.876038,0.082308,0.000000
5.570000,0.010429,-173.920517,0.003290,0.003371,0.085621,0.046392,0.002363,0.856211,-173.920517,0.086645,0.000000
5.830000,0.017502,-173.964996,0.003471,0.003542,0.089966,0.077852,0.003966,0.899658,-173.964996,0.090963,0.000000
6.090000,-0.019363,-173.876038,0.003635,0.003709,0.094207,-0.086133,-0.004388,0.942068,-173.876038,0.095299,0.000000
6.350000,0.001122,-174.009476,0.003811,0.003880,0.098560,0.004989,0.000254,0.985602,-174.009476,0.099635,0.000000
6.610000,-0.024574,-174.053955,0.003980,0.004052,0.102914,-0.109312,-0.005569,1.029136,-174.053955,0.103954,0.000000
6.870000,-0.074097,-174.009476,0.004169,0.004221,0.107215,-0.329598,-0.016791,1.072151,-174.009476,0.108290,0.000000
7.130000,0.024948,-174.098450,0.004342,0.004392,0.111568,0.110975,0.005653,1.115685,-174.098450,0.112627,0.000000
7.390000,0.025322,-174.053955,0.004518,0.004567,0.116009,0.112638,0.005738,1.160089,-174.053955,0.116963,0.000000
7.650001,-0.022713,-174.098450,0.004661,0.004733,0.120206,-0.101031,-0.005147,1.202060,-174.098450,0.121282,0.000000
7.910000,0.013405,-174.142929,0.004850,0.004899,0.124430,0.059628,0.003038,1.244296,-174.142929,0.125618,0.000000
8.170000,-0.003723,-174.142929,0.005032,0.005076,0.128931,-0.016561,-0.000844,1.289306,-174.142929,0.129954,0.000000
8.430000,-0.014145,-174.187408,0.005208,0.005245,0.133232,-0.062920,-0.003205,1.332317,-174.187408,0.134290,0.000000
8.690001,0.008568,-174.187408,0.005351,0.005411,0.137438,0.038112,0.001941,1.374379,-174.187408,0.138609,0.000000
8.950001,-0.018990,-174.231888,0.005545,0.005586,0.141895,-0.084470,-0.004303,1.418953,-174.231888,0.142945,0.000000
9.210000,-0.031281,-174.276367,0.005713,0.005752,0.146101,-0.139143,-0.007088,1.461015,-174.276367,0.147281,0.000000
9.470000,0.021973,-174.320847,0.005868,0.005924,0.150472,0.097739,0.004979,1.504723,-174.320847,0.151617,0.000000
9.730000,-0.009682,-174.276367,0.006071,0.006102,0.154991,-0.043066,-0.002194,1.549907,-174.276367,0.155936,0.000000
9.990001,-0.007446,-174.320847,0.006226,0.006269,0.159223,-0.033123,-0.001687,1.592226,-174.320847,0.160272,0.000000
10.250001,0.030907,-174.365326,0.006407,0.006436,0.163463,0.137480,0.007004,1.634632,-174.365326,0.164608,0.000000
10.510000,-0.028297,-174.365326,0.006571,0.006610,0.167895,-0.125873,-0.006412,1.678949,-174.365326,0.168927,0.000000
10.770000,-0.013405,-174.409805,0.006752,0.006776,0.172118,-0.059628,-0.003038,1.721181,-174.409805,0.173263,0.000000
11.030001,0.000374,-174.409805,0.006911,0.006942,0.176333,0.001663,0.000085,1.763330,-174.409805,0.177599,0.000000
11.290001,-0.044685,-174.498764,0.007101,0.007122,0.180903,-0.198770,-0.010126,1.809032,-174.498764,0.181935,0.000000
11.550000,-0.001114,-174.498764,0.007269,0.007293,0.185240,-0.004955,-0.000252,1.852396,-174.498764,0.186254,0.000000
11.810000,0.019737,-174.587738,0.007429,0.007462,0.189532,0.087796,0.004473,1.895320,-174.587738,0.190590,0.000000
12.070001,-0.018990,-174.543259,0.007614,0.007632,0.193842,-0.084470,-0.004303,1.938423,-174.543259,0.194926,0.000000
12.330001,0.007820,-174.632217,0.007795,0.007806,0.198274,0.034786,0.001772,1.982736,-174.632217,0.199263,0.000000
12.590000,0.013405,-174.587738,0.007955,0.007975,0.202558,0.059628,0.003038,2.025577,-174.587738,0.203581,0.000000
12.850000,-0.036865,-174.676697,0.008132,0.008143,0.206825,-0.163985,-0.008354,2.068248,-174.676697,0.207918,0.000000
13.110001,-0.010048,-174.721176,0.008308,0.008314,0.211178,-0.044695,-0.002277,2.111782,-174.721176,0.212253,0.000000
13.370001,-0.011169,-174.721176,0.008476,0.008479,0.215367,-0.049684,-0.002531,2.153670,-174.721176,0.216589,0.000000
13.630001,0.004097,-174.676697,0.008640,0.008653,0.219790,0.018224,0.000928,2.197896,-174.676697,0.220908,0.000000
13.890000,0.018990,-174.721176,0.008826,0.008827,0.224204,0.084470,0.004303,2.242039,-174.721176,0.225244,0.000000
14.150001,0.035378,-174.765656,0.008998,0.008999,0.228575,0.157367,0.008017,2.285747,-174.765656,0.229581,0.000000
14.410001,0.027184,-174.765656,0.009162,0.009165,0.232789,0.120918,0.006160,2.327892,-174.765656,0.233917,0.000000
14.670001,0.009682,-174.810135,0.009343,0.009337,0.237152,0.043066,0.002194,2.371517,-174.810135,0.238236,0.000000
14.930000,0.029419,-174.854614,0.009516,0.009507,0.241488,0.130862,0.006666,2.414876,-174.854614,0.242572,0.000000
15.190001,0.077080,-174.854614,0.009684,0.009677,0.245798,0.342868,0.017467,2.457979,-174.854614,0.246908,0.000000
15.450001,0.754059,-174.899094,0.009826,0.000010,0.000243,3.354221,0.170872,0.002426,-174.899094,0.000364,0.000000
15.710001,0.684425,-174.899094,0.009822,0.000008,0.000191,3.044476,0.155093,0.001908,-174.899094,0.000364,0.000000
15.970001,0.656494,-174.943573,0.009848,0.000007,0.000182,2.920232,0.148764,0.001821,-174.943573,0.000373,0.000000
16.230001,0.603615,-175.032547,0.009830,0.000007,0.000182,2.685013,0.136781,0.001821,-175.032547,0.000807,0.000000
16.490002,0.639740,-174.988068,0.009835,0.000012,0.000304,2.845706,0.144967,0.003035,-174.988068,0.001240,0.000000
16.750000,0.718681,-174.988068,0.009848,0.000025,0.000642,3.196854,0.162856,0.006415,-174.988068,0.001674,0.000000
17.010000,0.903008,-175.032547,0.009848,0.000044,0.001118,4.016778,0.204624,0.011184,-175.032547,0.002107,0.000000
17.270000,1.022163,-175.032547,0.009886,0.000067,0.001709,4.546810,0.231626,0.017085,-175.032547,0.002541,0.000000
17.530001,1.132011,-175.165985,0.009886,0.000084,0.002124,5.035438,0.256517,0.021245,-175.165985,0.002975,0.000000
17.790001,1.231064,-175.032547,0.009912,0.000101,0.002567,5.476046,0.278963,0.025669,-175.032547,0.003408,0.000000
18.050001,1.296974,-175.121506,0.009916,0.000113,0.002862,5.769229,0.293899,0.028618,-175.121506,0.003842,0.000000
18.310001,1.466408,-175.165985,0.009951,0.000131,0.003330,6.522908,0.332293,0.033300,-175.165985,0.004275,0.000000
18.570002,1.590408,-175.121506,0.009964,0.000148,0.003764,7.074490,0.360392,0.037637,-175.121506,0.004709,0.000000
18.830002,1.768768,-175.210464,0.009973,0.000168,0.004275,7.867875,0.400809,0.042754,-175.210464,0.005134,0.000000
19.090000,1.861862,-175.210464,0.009994,0.000183,0.004640,8.281977,0.421904,0.046395,-175.210464,0.005568,0.000000
19.350000,2.030922,-175.254944,0.010003,0.000203,0.005169,9.033992,0.460213,0.051687,-175.254944,0.006001,0.000000
19.610001,2.092361,-175.299423,0.009998,0.000215,0.005472,9.307288,0.474136,0.054722,-175.299423,0.006435,0.000000
19.870001,2.210030,-175.299423,0.010033,0.000236,0.005984,9.830703,0.500800,0.059839,-175.299423,0.006868,0.000000
20.130001,2.383186,-175.388397,0.010067,0.000254,0.006461,10.600943,0.540038,0.064608,-175.388397,0.007302,0.000000
20.390001,2.499741,-175.388397,0.010085,0.000274,0.006955,11.119402,0.566449,0.069551,-175.388397,0.007736,0.000000
20.650002,2.592461,-175.388397,0.010089,0.000287,0.007284,11.531841,0.587460,0.072844,-175.388397,0.008169,0.000000
20.910002,2.715340,-175.477356,0.010098,0.000302,0.007666,12.078434,0.615305,0.076663,-175.477356,0.008603,0.000000
21.170000,2.881790,-175.432877,0.010136,0.000325,0.008265,12.818843,0.653023,0.082647,-175.432877,0.009036,0.000000
21.430000,2.932808,-175.477356,0.010136,0.000337,0.008568,13.045781,0.664584,0.085682,-175.477356,0.009470,0.000000
21.690001,3.015472,-175.521835,0.010162,0.000357,0.009080,13.413491,0.683316,0.090796,-175.521835,0.009904,0.000000
21.950001,3.095909,-175.521835,0.010192,0.000372,0.009453,13.771292,0.701543,0.094528,-175.521835,0.010337,0.000000
22.210001,3.276878,-175.566315,0.010192,0.000392,0.009947,14.576283,0.742551,0.099471,-175.566315,0.010771,0.000000
22.470001,3.349495,-175.521835,0.010201,0.000408,0.010372,14.899298,0.759006,0.103717,-175.521835,0.011204,0.000000
22.730001,3.488014,-175.655273,0.010218,0.000425,0.010797,15.515462,0.790395,0.107968,-175.655273,0.011638,0.000000
22.990002,3.565468,-175.610794,0.010227,0.000443,0.011248,15.859993,0.807947,0.112480,-175.610794,0.012072,0.000000
23.250002,3.680534,-175.655273,0.010266,0.000464,0.011785,16.371834,0.834021,0.117854,-175.655273,0.012505,0.000000
23.510000,3.661171,-175.655273,0.010266,0.000472,0.011994,16.285702,0.829633,0.119936,-175.655273,0.012939,0.000000
23.770000,3.752769,-175.699753,0.010300,0.000491,0.012479,16.693151,0.850390,0.124792,-175.699753,0.013372,0.000000
24.030001,3.787773,-175.699753,0.010309,0.000508,0.012913,16.848856,0.858322,0.129129,-175.699753,0.013806,0.000000
24.290001,3.978432,-175.744232,0.010305,0.000530,0.013450,17.696949,0.901525,0.134504,-175.744232,0.014240,0.000000
24.550001,4.024605,-175.788712,0.010326,0.000541,0.013754,17.902336,0.911988,0.137539,-175.788712,0.014673,0.000000
24.810001,4.166847,-175.788712,0.010348,0.000562,0.014274,18.535063,0.944221,0.142744,-175.788712,0.015107,0.000000
25.070002,4.228294,-175.833206,0.010378,0.000580,0.014734,18.808393,0.958145,0.147342,-175.833206,0.015540,0.000000
25.330002,4.321014,-175.877686,0.010391,0.000598,0.015185,19.220833,0.979156,0.151850,-175.877686,0.015974,0.000000
25.590002,4.351173,-175.877686,0.010391,0.000613,0.015575,19.354986,0.985990,0.155752,-175.877686,0.016408,0.000000
25.850000,4.437195,-175.877686,0.010417,0.000629,0.015965,19.737629,1.005483,0.159654,-175.877686,0.016841,0.000000
26.110001,4.534752,-175.966644,0.010421,0.000646,0.016399,20.171583,1.027589,0.163992,-175.966644,0.017275,0.000000
26.370001,4.612953,-175.877686,0.010438,0.000664,0.016876,20.519440,1.045310,0.168761,-175.877686,0.017709,0.000000
26.630001,4.525070,-175.966644,0.010455,0.000674,0.017110,20.128517,1.025396,0.171104,-175.966644,0.018142,0.000000
26.890001,4.760788,-176.011124,0.010468,0.000693,0.017605,21.177042,1.078810,0.176047,-176.011124,0.018576,0.000000
27.150002,4.945854,-175.966644,0.010516,0.000717,0.018212,22.000257,1.120746,0.182118,-175.966644,0.019010,0.000000
27.410002,4.882919,-176.011124,0.010516,0.000731,0.018558,21.720310,1.106485,0.185585,-176.011124,0.019443,0.000000
27.670002,4.965591,-176.011124,0.010537,0.000747,0.018975,22.088055,1.125219,0.189748,-176.011124,0.019877,0.000000
27.930002,5.069107,-176.055603,0.010550,0.000766,0.019460,22.548513,1.148676,0.194604,-176.055603,0.020302,0.000000
28.190001,5.180450,-176.100082,0.010563,0.000785,0.019937,23.043795,1.173907,0.199373,-176.100082,0.020735,0.000000
28.450001,5.150284,-176.189041,0.010568,0.000796,0.020206,22.909607,1.167071,0.202064,-176.189041,0.021169,0.000000
28.710001,5.253059,-176.189041,0.010589,0.000815,0.020692,23.366776,1.190360,0.206920,-176.189041,0.021603,0.000000
28.970001,5.385628,-176.189041,0.010606,0.000836,0.021229,23.956469,1.220401,0.212295,-176.189041,0.022036,0.000000
29.230001,5.391953,-176.233521,0.010619,0.000849,0.021559,23.984602,1.221834,0.215591,-176.233521,0.022470,0.000000
29.490002,5.465317,-176.233521,0.010645,0.000868,0.022045,24.310944,1.238458,0.220447,-176.233521,0.022903,0.000000
29.750002,5.496964,-176.278015,0.010667,0.000884,0.022444,24.451715,1.245630,0.224437,-176.278015,0.023337,0.000000
30.010002,5.600853,-176.366974,0.010671,0.000900,0.022869,24.913837,1.269171,0.228687,-176.366974,0.023771,0.000000
30.270002,5.667137,-176.278015,0.010688,0.000917,0.023294,25.208685,1.284192,0.232938,-176.278015,0.024204,0.000000
30.530001,5.633995,-176.411453,0.010714,0.000930,0.023623,25.061262,1.276682,0.236230,-176.411453,0.024638,0.000000
30.790001,5.909180,-176.366974,0.010718,0.000954,0.024239,26.285343,1.339039,0.242388,-176.366974,0.025072,0.000000
31.050001,5.906578,-176.366974,0.010727,0.000970,0.024629,26.273771,1.338450,0.246291,-176.366974,0.025505,0.000000
31.310001,5.976952,-176.411453,0.010757,0.000988,0.025106,26.586809,1.354397,0.251060,-176.411453,0.025939,0.000000
31.570002,5.965034,-176.411453,0.010774,0.001003,0.025487,26.533798,1.351696,0.254875,-176.411453,0.026372,0.000000
31.830002,6.076752,-176.500412,0.010779,0.001022,0.025956,27.030741,1.377012,0.259561,-176.500412,0.026806,0.000000
32.090000,6.190697,-176.500412,0.010813,0.001039,0.026389,27.537594,1.402832,0.263894,-176.500412,0.027240,0.000000
32.350002,6.173195,-176.544891,0.010818,0.001053,0.026754,27.459742,1.398866,0.267539,-176.544891,0.027673,0.000000
32.610001,6.127022,-176.589371,0.010822,0.001066,0.027066,27.254354,1.388403,0.270662,-176.589371,0.028107,0.000000
32.870003,6.378746,-176.589371,0.010852,0.001090,0.027682,28.374079,1.445445,0.276816,-176.589371,0.028540,0.000000
33.130001,6.348579,-176.589371,0.010861,0.001104,0.028046,28.239891,1.438609,0.280461,-176.589371,0.028974,0.000000
33.390003,6.362732,-176.589371,0.010865,0.001121,0.028471,28.302845,1.441816,0.284707,-176.589371,0.029407,0.000000
33.650002,6.365334,-176.633850,0.010891,0.001133,0.028783,28.314417,1.442405,0.287830,-176.633850,0.029841,0.000000
33.910000,6.583549,-176.722824,0.010904,0.001154,0.029303,29.285091,1.491854,0.293034,-176.722824,0.030275,0.000000
34.170002,6.617432,-176.633850,0.010930,0.001169,0.029685,29.435806,1.499531,0.296849,-176.633850,0.030708,0.000000
34.430000,6.644989,-176.722824,0.010943,0.001186,0.030136,29.558388,1.505776,0.301361,-176.722824,0.031142,0.000000
34.690002,6.806595,-176.722824,0.010943,0.001206,0.030639,30.277246,1.542396,0.306391,-176.722824,0.031575,0.000000
34.950001,6.866554,-176.856262,0.010947,0.001225,0.031116,30.543959,1.555983,0.311160,-176.856262,0.032009,0.000000
35.210003,6.845695,-176.900742,0.010986,0.001238,0.031437,30.451174,1.551257,0.314370,-176.900742,0.032443,0.000000
35.470001,6.918686,-176.811783,0.011003,0.001258,0.031966,30.775852,1.567797,0.319657,-176.811783,0.032876,0.000000
35.730003,6.948845,-176.856262,0.011003,0.001271,0.032295,30.910006,1.574631,0.322954,-176.856262,0.033310,0.000000
35.990002,7.186417,-176.945221,0.011016,0.001293,0.032833,31.966778,1.628465,0.328332,-176.945221,0.033743,0.000000
36.250000,7.025551,-176.945221,0.011029,0.001303,0.033102,31.251211,1.592013,0.331019,-176.945221,0.034177,0.000000
36.510002,7.050133,-176.989700,0.011033,0.001317,0.033440,31.360558,1.597583,0.334399,-176.989700,0.034611,0.000000
36.770000,7.372978,-176.900742,0.011081,0.001344,0.034142,32.796646,1.670741,0.341424,-176.900742,0.035044,0.000000
37.030003,7.389359,-176.989700,0.011085,0.001362,0.034602,32.869507,1.674453,0.346023,-176.989700,0.035469,0.000000
37.290001,7.322708,-176.989700,0.011089,0.001377,0.034975,32.573032,1.659349,0.349751,-176.989700,0.035903,0.000000
37.550003,7.408356,-177.078659,0.011115,0.001395,0.035426,32.954014,1.678757,0.354262,-177.078659,0.036337,0.000000
37.810001,7.460854,-177.078659,0.011119,0.001409,0.035790,33.187534,1.690654,0.357903,-177.078659,0.036770,0.000000
38.070004,7.483948,-177.034180,0.011141,0.001425,0.036198,33.290264,1.695887,0.361980,-177.034180,0.037204,0.000000
38.330002,7.592674,-177.123154,0.011145,0.001443,0.036640,33.773903,1.720525,0.366401,-177.123154,0.037637,0.000000
38.590000,7.784447,-177.123154,0.011167,0.001464,0.037178,34.626949,1.763981,0.371779,-177.123154,0.038071,0.000000
38.850002,7.875305,-177.167633,0.011197,0.001483,0.037672,35.031109,1.784570,0.376722,-177.167633,0.038505,0.000000
39.110001,7.874191,-177.212112,0.011197,0.001500,0.038089,35.026154,1.784317,0.380885,-177.212112,0.038938,0.000000
39.370003,7.785194,-177.167633,0.011219,0.001511,0.038383,34.630276,1.764150,0.383834,-177.167633,0.039372,0.000000
39.630001,7.890205,-177.212112,0.011223,0.001531,0.038878,35.097385,1.787946,0.388777,-177.212112,0.039805,0.000000
39.890003,8.019043,-177.212112,0.011223,0.001548,0.039320,35.670486,1.817141,0.393198,-177.212112,0.040239,0.000000
40.150002,8.033936,-177.256592,0.011257,0.001566,0.039771,35.736729,1.820516,0.397709,-177.256592,0.040673,0.000000
40.410004,8.134476,-177.301071,0.011283,0.001582,0.040179,36.183956,1.843299,0.401786,-177.301071,0.041106,0.000000
40.670002,8.305771,-177.301071,0.011300,0.001602,0.040690,36.945915,1.882115,0.406903,-177.301071,0.041540,0.000000
40.930000,8.242470,-177.345551,0.011300,0.001614,0.041002,36.664337,1.867770,0.410021,-177.345551,0.041974,0.000000
41.190002,8.313965,-177.390030,0.011309,0.001634,0.041505,36.982361,1.883971,0.415052,-177.390030,0.042407,0.000000
41.450001,8.529938,-177.390030,0.011331,0.001653,0.041982,37.943058,1.932912,0.419824,-177.390030,0.042841,0.000000
41.710003,8.597336,-177.478989,0.011331,0.001672,0.042468,38.242859,1.948184,0.424680,-177.478989,0.043275,0.000000
41.970001,8.604782,-177.434509,0.011357,0.001687,0.042850,38.275982,1.949872,0.428496,-177.434509,0.043708,0.000000
42.230003,8.592125,-177.523483,0.011378,0.001700,0.043179,38.219681,1.947003,0.431792,-177.523483,0.044142,0.000000
42.490002,8.856506,-177.478989,0.011387,0.001724,0.043795,39.395706,2.006913,0.437946,-177.478989,0.044575,0.000000
42.750004,8.794693,-177.567963,0.011391,0.001736,0.044107,39.120747,1.992906,0.441069,-177.567963,0.045009,0.000000
43.010002,8.876991,-177.567963,0.011404,0.001756,0.044610,39.486828,2.011555,0.446099,-177.567963,0.045443,0.000000
43.270000,8.910500,-177.612442,0.011438,0.001771,0.044983,39.635883,2.019148,0.449827,-177.612442,0.045876,0.000000
43.530003,9.131691,-177.656921,0.011443,0.001791,0.045494,40.619789,2.069271,0.454944,-177.656921,0.046310,0.000000
43.790001,9.195740,-177.656921,0.011451,0.001808,0.045919,40.904694,2.083784,0.459195,-177.656921,0.046743,0.000000
44.050003,9.268356,-177.701401,0.011469,0.001824,0.046327,41.227707,2.100240,0.463271,-177.701401,0.047177,0.000000
44.310001,9.372620,-177.701401,0.011482,0.001841,0.046769,41.691494,2.123866,0.467692,-177.701401,0.047611,0.000000
44.570004,9.469437,-177.656921,0.011516,0.001861,0.047264,42.122158,2.145805,0.472639,-177.656921,0.048044,0.000000
44.830002,9.386024,-177.745880,0.011520,0.001871,0.047533,41.751122,2.126904,0.475326,-177.745880,0.048478,0.000000
45.090004,9.490288,-177.834839,0.011520,0.001890,0.048001,42.214909,2.150530,0.480008,-177.834839,0.048911,0.000000
45.350002,9.621361,-177.834839,0.011525,0.001910,0.048513,42.797951,2.180232,0.485125,-177.834839,0.049345,0.000000
45.610001,9.743874,-177.879318,0.011546,0.001925,0.048903,43.342915,2.207993,0.489027,-177.879318,0.049779,0.000000
45.870003,9.820580,-177.745880,0.011568,0.001940,0.049276,43.684120,2.225375,0.492755,-177.745880,0.050204,0.000000
46.130001,10.048103,-177.834839,0.011585,0.001960,0.049796,44.696198,2.276933,0.497960,-177.834839,0.050637,0.000000
46.390003,10.282692,-177.879318,0.011602,0.001981,0.050325,45.739697,2.330091,0.503251,-177.879318,0.051071,0.000000
46.650002,10.263329,-177.923798,0.011615,0.001997,0.050715,45.653564,2.325703,0.507153,-177.923798,0.051504,0.000000
46.910004,10.309509,-178.012772,0.011628,0.002013,0.051132,45.858986,2.336168,0.511317,-178.012772,0.051938,0.000000
47.170002,10.369827,-178.012772,0.011637,0.002027,0.051487,46.127296,2.349837,0.514871,-178.012772,0.052372,0.000000
47.430004,10.531815,-178.012772,0.011637,0.002046,0.051973,46.847851,2.386543,0.519727,-178.012772,0.052805,0.000000
47.690002,10.691933,-178.057251,0.011658,0.002063,0.052389,47.560093,2.422827,0.523890,-178.057251,0.053239,0.000000
47.950001,10.616341,-178.012772,0.011676,0.002076,0.052719,47.223843,2.405697,0.527187,-178.012772,0.053672,0.000000
48.210003,10.952965,-178.101730,0.011676,0.002095,0.053222,48.721222,2.481977,0.532217,-178.101730,0.054106,0.000000
48.470001,11.228897,-178.101730,0.011701,0.002115,0.053725,49.948627,2.544504,0.537247,-178.101730,0.054540,0.000000
48.730003,11.122765,-178.190689,0.011701,0.002129,0.054089,49.476528,2.520454,0.540888,-178.190689,0.054973,0.000000
48.990002,11.284378,-178.190689,0.011719,0.002146,0.054496,50.195419,2.557077,0.544964,-178.190689,0.055407,0.000000
49.250004,11.479126,-178.190689,0.011758,0.002164,0.054965,51.061703,2.601207,0.549646,-178.190689,0.055840,0.000000
49.510002,11.728989,-178.235168,0.011758,0.002183,0.055459,52.173149,2.657827,0.554589,-178.235168,0.056274,0.000000
49.770000,11.600151,-178.279648,0.011758,0.002194,0.055736,51.600048,2.628632,0.557364,-178.279648,0.056708,0.000000
50.030003,11.848518,-178.324127,0.011788,0.002215,0.056265,52.704842,2.684913,0.562655,-178.324127,0.057141,0.000000
50.290001,12.089073,-178.368607,0.011796,0.002235,0.056760,53.774883,2.739423,0.567598,-178.368607,0.057575,0.000000
50.550003,12.124825,-178.324127,0.011818,0.002248,0.057089,53.933914,2.747524,0.570895,-178.324127,0.058008,0.000000
50.810001,12.351967,-178.368607,0.011835,0.002267,0.057584,54.944294,2.798996,0.575838,-178.368607,0.058442,0.000000
51.070004,12.434265,-178.368607,0.011839,0.002282,0.057965,55.310375,2.817645,0.579653,-178.368607,0.058876,0.000000
51.330002,12.612999,-178.413101,0.011844,0.002300,0.058416,56.105423,2.858146,0.584161,-178.413101,0.059309,0.000000
51.590004,12.812225,-178.457581,0.011870,0.002317,0.058841,56.991623,2.903292,0.588411,-178.457581,0.059743,0.000000
51.850002,12.559753,-178.413101,0.011883,0.002325,0.059067,55.868572,2.846081,0.590667,-178.413101,0.060177,0.000000
52.110001,13.345833,-178.502060,0.011891,0.002352,0.059752,59.365231,3.024209,0.597518,-178.502060,0.060610,0.000000
52.370003,13.410622,-178.502060,0.011913,0.002368,0.060151,59.653423,3.038890,0.601507,-178.502060,0.061044,0.000000
52.630001,13.639259,-178.591019,0.011934,0.002387,0.060628,60.670456,3.090700,0.606276,-178.591019,0.061478,0.000000
52.890003,13.717834,-178.546539,0.011934,0.002403,0.061044,61.019974,3.108506,0.610439,-178.546539,0.061911,0.000000
53.150002,13.951683,-178.591019,0.011960,0.002422,0.061512,62.060184,3.161496,0.615121,-178.591019,0.062345,0.000000
53.410004,14.194466,-178.635498,0.011960,0.002438,0.061920,63.140137,3.216512,0.619197,-178.635498,0.062779,0.000000
53.670002,14.192604,-178.591019,0.011990,0.002452,0.062284,63.131855,3.216090,0.622839,-178.591019,0.063212,0.000000
53.930004,14.110687,-178.724457,0.012008,0.002462,0.062527,62.767471,3.197528,0.625268,-178.724457,0.063646,0.000000
54.190002,14.885963,-178.679977,0.011995,0.002489,0.063221,66.216072,3.373208,0.632206,-178.679977,0.064079,0.000000
54.450001,14.881493,-178.679977,0.012033,0.002504,0.063593,66.196182,3.372195,0.635934,-178.679977,0.064513,0.000000
54.710003,15.083694,-178.768936,0.012038,0.002521,0.064036,67.095627,3.418014,0.640359,-178.768936,0.064947,0.000000
54.970001,15.048691,-178.679977,0.012051,0.002534,0.064357,66.939919,3.410082,0.643568,-178.679977,0.065371,0.000000
55.230003,15.542831,-178.813431,0.012077,0.002554,0.064869,69.137970,3.522056,0.648686,-178.813431,0.065805,0.000000
55.490002,15.892487,-178.768936,0.012077,0.002572,0.065328,70.693314,3.601289,0.653280,-178.768936,0.066239,0.000000
55.750004,15.835144,-178.857910,0.012102,0.002585,0.065658,70.438240,3.588295,0.656577,-178.857910,0.066672,0.000000
56.010002,16.407478,-178.902390,0.012107,0.002604,0.066135,72.984108,3.717988,0.661346,-178.902390,0.067106,0.000000
56.270004,16.761978,-178.813431,0.012111,0.002624,0.066638,74.561005,3.798319,0.666376,-178.813431,0.067540,0.000000
56.530003,16.794373,-178.946869,0.012141,0.002636,0.066967,74.705101,3.805659,0.669669,-178.946869,0.067973,0.000000
56.790001,17.239357,-178.946869,0.012146,0.002657,0.067487,76.684486,3.906494,0.674873,-178.946869,0.068407,0.000000
57.050003,17.317184,-178.946869,0.012154,0.002671,0.067852,77.030685,3.924130,0.678518,-178.946869,0.068840,0.000000
57.310001,17.814301,-178.991348,0.012180,0.002691,0.068363,79.241966,4.036778,0.683632,-178.991348,0.069274,0.000000
57.570004,17.767380,-179.035828,0.012202,0.002702,0.068641,79.033249,4.026146,0.686410,-179.035828,0.069708,0.000000
57.830002,17.899574,-179.035828,0.012202,0.002715,0.068962,79.621284,4.056101,0.689615,-179.035828,0.070141,0.000000
58.090004,18.808167,-179.080307,0.012219,0.002742,0.069655,83.662903,4.261992,0.696553,-179.080307,0.070575,0.000000
58.350002,19.129890,-179.035828,0.012249,0.002760,0.070098,85.094002,4.334895,0.700978,-179.035828,0.071008,0.000000
58.610004,19.214790,-179.080307,0.012258,0.002774,0.070471,85.471657,4.354134,0.704706,-179.080307,0.071442,0.000000
58.870003,19.440079,-179.169266,0.012253,0.002793,0.070930,86.473785,4.405185,0.709304,-179.169266,0.071876,0.000000
59.130001,19.981506,-179.124786,0.012275,0.002808,0.071321,88.882179,4.527874,0.713207,-179.124786,0.072309,0.000000
59.390003,20.218712,-179.213745,0.012284,0.002824,0.071720,89.937325,4.581625,0.717196,-179.213745,0.072743,0.000000
59.650002,20.634277,-179.213745,0.012309,0.002841,0.072162,91.785851,4.675794,0.721617,-179.213745,0.073176,0.000000
59.910004,21.408066,-179.258240,0.012322,0.002864,0.072743,95.227829,4.851137,0.727427,-179.258240,0.073610,0.000000
60.170002,21.888428,-179.258240,0.012340,0.002882,0.073211,97.364586,4.959989,0.732112,-179.258240,0.074044,0.000000
60.430004,22.021362,-179.213745,0.012340,0.002898,0.073610,97.955910,4.990112,0.736102,-179.213745,0.074477,0.000000
60.690002,22.015038,-179.347198,0.012348,0.002910,0.073914,97.927780,4.988679,0.739137,-179.347198,0.074911,0.000000
60.950005,22.486832,-179.347198,0.012365,0.002928,0.074382,100.026421,5.095589,0.743819,-179.347198,0.075344,0.000000
61.210003,22.897926,-179.391678,0.012383,0.002945,0.074807,101.855064,5.188745,0.748069,-179.391678,0.075778,0.000000
61.470001,23.408081,-179.391678,0.012400,0.002965,0.075318,104.124344,5.304347,0.753183,-179.391678,0.076212,0.000000
61.730003,23.782684,-179.436157,0.012417,0.002980,0.075683,105.790665,5.389234,0.756828,-179.436157,0.076645,0.000000
61.990002,24.533386,-179.436157,0.012409,0.003001,0.076220,109.129951,5.559345,0.762202,-179.436157,0.077079,0.000000
62.250004,24.646217,-179.436157,0.012452,0.003013,0.076532,109.631851,5.584913,0.765325,-179.436157,0.077512,0.000000
62.510002,25.226006,-179.569595,0.012447,0.003033,0.077027,112.210876,5.716294,0.770268,-179.569595,0.077946,0.000000
62.770004,25.876167,-179.480637,0.012456,0.003050,0.077478,115.102943,5.863624,0.774779,-179.480637,0.078380,0.000000
63.030003,26.334557,-179.569595,0.012482,0.003068,0.077937,117.141960,5.967496,0.779374,-179.569595,0.078813,0.000000
63.290005,26.784752,-179.658554,0.012482,0.003085,0.078371,119.144524,6.069511,0.783712,-179.658554,0.079247,0.000000
63.550003,27.049881,-179.525116,0.012512,0.003098,0.078700,120.323883,6.129591,0.787005,-179.525116,0.079681,0.000000
63.810001,27.835213,-179.658554,0.012529,0.003121,0.079282,123.817207,6.307549,0.792818,-179.658554,0.080114,0.000000
64.070000,28.245567,-179.614075,0.012542,0.003137,0.079681,125.642555,6.400537,0.796807,-179.614075,0.080539,0.000000
64.330002,28.814186,-179.703049,0.012538,0.003154,0.080123,128.171906,6.529388,0.801228,-179.703049,0.080973,0.000000
64.590004,29.165703,-179.747528,0.012559,0.003169,0.080496,129.735519,6.609043,0.804956,-179.747528,0.081406,0.000000
64.850006,29.941353,-179.703049,0.012581,0.003189,0.080999,133.185791,6.784807,0.809986,-179.703049,0.081840,0.000000
65.110001,30.209465,-179.792007,0.012585,0.003204,0.081389,134.378418,6.845563,0.813889,-179.792007,0.082274,0.000000
65.370003,31.143745,-179.747528,0.012585,0.003223,0.081866,138.534302,7.057274,0.818661,-179.747528,0.082707,0.000000
65.630005,31.654640,-179.747528,0.012603,0.003239,0.082265,140.806870,7.173044,0.822651,-179.747528,0.083141,0.000000
65.889999,32.219154,-179.880966,0.012637,0.003256,0.082707,143.317963,7.300965,0.827071,-179.880966,0.083574,0.000000
66.150002,32.619461,-179.880966,0.012628,0.003270,0.083054,145.098602,7.391675,0.830542,-179.880966,0.084008,0.000000
66.410004,33.356010,-179.880966,0.012637,0.003289,0.083549,148.374939,7.558580,0.835485,-179.880966,0.084442,0.000000
66.670006,33.730614,-179.925446,0.012663,0.003307,0.084008,150.041260,7.643466,0.840080,-179.925446,0.084875,0.000000
66.930000,34.692825,-179.925446,0.012667,0.003326,0.084485,154.321396,7.861506,0.844849,-179.925446,0.085309,0.000000
67.190002,35.249153,-179.969925,0.012684,0.003338,0.084797,156.796066,7.987572,0.847972,-179.969925,0.085743,0.000000
67.450005,36.108589,-179.969925,0.012702,0.003358,0.085291,160.619034,8.182323,0.852915,-179.969925,0.086176,0.000000
67.710007,36.848862,-180.014404,0.012719,0.003378,0.085803,163.911926,8.350071,0.858032,-180.014404,0.086610,0.000000
67.970001,37.548553,-180.014404,0.012715,0.003393,0.086176,167.024307,8.508624,0.861760,-180.014404,0.087044,0.000000
68.230003,38.129456,-180.014404,0.012728,0.003409,0.086592,169.608292,8.640258,0.865923,-180.014404,0.087477,0.000000
68.490005,38.574814,-180.103378,0.012736,0.003425,0.086991,171.589340,8.741178,0.869913,-180.103378,0.087911,0.000000
68.750000,39.649475,-180.058884,0.012745,0.003442,0.087434,176.369675,8.984699,0.874337,-180.058884,0.088344,0.000000
69.010002,40.357727,-180.103378,0.012753,0.003461,0.087911,179.520142,9.145191,0.879106,-180.103378,0.088778,0.000000
69.270004,40.331291,-180.147858,0.012766,0.003470,0.088145,179.402542,9.139201,0.881445,-180.147858,0.089211,0.000000
69.530006,41.755989,-180.192337,0.012775,0.003492,0.088691,185.739914,9.462043,0.886911,-180.192337,0.089645,0.000000
69.790001,43.054451,-180.236816,0.012797,0.003514,0.089255,191.515762,9.756278,0.892546,-180.236816,0.090079,0.000000
70.050003,43.561996,-180.147858,0.012801,0.003528,0.089619,193.773437,9.871289,0.896191,-180.147858,0.090512,0.000000
70.310005,44.293335,-180.236816,0.012801,0.003544,0.090018,197.026596,10.037013,0.900181,-180.236816,0.090946,0.000000
70.570000,45.225380,-180.236816,0.012818,0.003564,0.090530,201.172531,10.248218,0.905298,-180.236816,0.091379,0.000000
70.830002,46.284409,-180.281296,0.012840,0.003582,0.090981,205.883331,10.488197,0.909805,-180.281296,0.091813,0.000000
71.090004,46.630714,-180.325775,0.012835,0.003593,0.091267,207.423782,10.566671,0.912667,-180.325775,0.092247,0.000000
71.350006,47.349022,-180.325775,0.012844,0.003610,0.091692,210.618973,10.729442,0.916917,-180.325775,0.092680,0.000000
71.610001,48.378632,-180.414734,0.012853,0.003630,0.092195,215.198898,10.962755,0.921947,-180.414734,0.093114,0.000000
71.870003,49.366913,-180.414734,0.012857,0.003646,0.092602,219.595001,11.186702,0.926024,-180.414734,0.093547,0.000000
72.130005,50.332100,-180.370255,0.012870,0.003665,0.093079,223.888367,11.405416,0.930793,-180.370255,0.093981,0.000000
72.390007,50.901825,-180.459213,0.012891,0.003679,0.093452,226.422623,11.534518,0.934521,-180.459213,0.094415,0.000000
72.650002,51.942986,-180.503693,0.012909,0.003696,0.093877,231.053940,11.770449,0.938771,-180.503693,0.094848,0.000000
72.910004,52.942802,-180.548187,0.012909,0.003714,0.094337,235.501343,11.997010,0.943366,-180.548187,0.095273,0.000000
73.170006,53.114838,-180.503693,0.012917,0.003720,0.094493,236.266602,12.035994,0.944929,-180.503693,0.095707,0.000000
73.430000,55.260445,-180.459213,0.012930,0.003750,0.095256,245.810730,12.522196,0.952560,-180.459213,0.096140,0.000000
73.690002,56.067383,-180.592667,0.012926,0.003766,0.095646,249.400177,12.705050,0.956462,-180.592667,0.096574,0.000000
73.950005,57.139809,-180.548187,0.012930,0.003785,0.096132,254.170563,12.948066,0.961318,-180.548187,0.097008,0.000000
74.210007,58.046539,-180.637146,0.012952,0.003800,0.096522,258.203888,13.153534,0.965220,-180.637146,0.097441,0.000000
74.470001,58.878044,-180.548187,0.012973,0.003816,0.096921,261.902618,13.341955,0.969209,-180.548187,0.097875,0.000000
74.730003,60.297157,-180.637146,0.012969,0.003836,0.097424,268.215149,13.663531,0.974240,-180.637146,0.098308,0.000000
74.990005,60.975990,-180.726105,0.012969,0.003849,0.097754,271.234741,13.817356,0.977536,-180.726105,0.098742,0.000000
75.250000,61.661903,-180.681625,0.012995,0.003860,0.098040,274.285858,13.972787,0.980398,-180.681625,0.099176,0.000000
75.510002,63.499557,-180.770584,0.012995,0.003885,0.098690,282.460144,14.389206,0.986900,-180.770584,0.099609,0.000000
75.770004,64.286377,-180.770584,0.013016,0.003899,0.099046,285.960083,14.567501,0.990458,-180.770584,0.100043,0.000000
76.030006,65.388229,-180.770584,0.013004,0.003918,0.099514,290.861359,14.817184,0.995140,-180.770584,0.100476,0.000000
76.290001,66.029083,-180.904022,0.013025,0.003929,0.099800,293.712036,14.962404,0.998001,-180.904022,0.100910,0.000000
76.550003,67.287338,-180.815063,0.013025,0.003940,0.100069,299.309021,15.247529,1.000692,-180.815063,0.100294,0.000000
76.810005,66.573120,-180.859543,0.013034,0.003940,0.100069,296.132019,15.085684,1.000692,-180.859543,0.100294,0.000000
77.070007,66.046219,-180.904022,0.013042,0.003936,0.099982,293.788269,14.966287,0.999822,-180.904022,0.100069,0.000000
77.330002,65.535324,-180.948502,0.013047,0.003935,0.099948,291.515686,14.850517,0.999477,-180.948502,0.100069,0.000000
77.590004,65.099274,-180.992996,0.013047,0.003935,0.099939,289.576019,14.751707,0.999390,-180.992996,0.100069,0.000000
77.850006,64.687057,-180.992996,0.013047,0.003934,0.099930,287.742401,14.658298,0.999303,-180.992996,0.100069,0.000000
78.110001,64.321762,-181.037476,0.013051,0.003934,0.099922,286.117493,14.575521,0.999216,-181.037476,0.100069,0.000000
78.370003,64.015305,-180.992996,0.013055,0.003934,0.099922,284.754303,14.506076,0.999216,-180.992996,0.100069,0.000000
78.630005,63.714798,-181.037476,0.013064,0.003934,0.099913,283.417572,14.437980,0.999129,-181.037476,0.100069,0.000000
78.890007,63.449661,-181.170914,0.013042,0.003934,0.099913,282.238190,14.377898,0.999129,-181.170914,0.100069,0.000000
79.150002,63.216553,-181.081955,0.013060,0.003934,0.099913,281.201263,14.325076,0.999129,-181.081955,0.100069,0.000000
79.410004,62.986061,-181.170914,0.013047,0.003934,0.099913,280.175995,14.272846,0.999129,-181.170914,0.100069,0.000000
79.670006,62.793167,-181.126434,0.013064,0.003934,0.099913,279.317963,14.229136,0.999129,-181.126434,0.100069,0.000000
79.930000,62.611450,-181.126434,0.013051,0.003933,0.099904,278.509644,14.187957,0.999042,-181.126434,0.100069,0.000000
80.190002,62.428246,-181.170914,0.013068,0.003933,0.099904,277.694702,14.146442,0.999042,-181.170914,0.100069,0.000000
80.450005,62.250626,-181.215393,0.013064,0.003933,0.099904,276.904602,14.106194,0.999042,-181.215393,0.100069,0.000000
80.710007,62.106140,-181.259872,0.013077,0.003933,0.099904,276.261902,14.073452,0.999042,-181.259872,0.100069,0.000000
80.970001,61.956451,-181.348831,0.013068,0.003933,0.099904,275.596069,14.039533,0.999042,-181.348831,0.100069,0.000000
81.230003,61.817924,-181.259872,0.013064,0.003933,0.099904,274.979858,14.008142,0.999042,-181.259872,0.100069,0.000000
81.490005,61.690201,-181.348831,0.013073,0.003933,0.099904,274.411713,13.979199,0.999042,-181.348831,0.100069,0.000000
81.750008,61.561363,-181.393326,0.013068,0.003933,0.099904,273.838623,13.950004,0.999042,-181.393326,0.100069,0.000000
82.010002,61.444069,-181.348831,0.013055,0.003933,0.099904,273.316864,13.923425,0.999042,-181.348831,0.100069,0.000000
82.270004,61.332726,-181.482285,0.013064,0.003933,0.099904,272.821594,13.898194,0.999042,-181.482285,0.100069,0.000000
82.530006,61.232559,-181.393326,0.013073,0.003933,0.099904,272.376038,13.875497,0.999042,-181.393326,0.100069,0.000000
82.790001,61.116753,-181.482285,0.013077,0.003933,0.099904,271.860901,13.849255,0.999042,-181.482285,0.100069,0.000000
83.050003,61.015839,-181.437805,0.013073,0.003933,0.099904,271.412018,13.826386,0.999042,-181.437805,0.100069,0.000000
83.310005,60.939125,-181.482285,0.013094,0.003933,0.099904,271.070770,13.809004,0.999042,-181.482285,0.100069,0.000000
83.570007,60.839706,-181.482285,0.013077,0.003933,0.099904,270.628540,13.786474,0.999042,-181.482285,0.100069,0.000000
83.830002,60.746986,-181.526764,0.013077,0.003933,0.099904,270.216095,13.765464,0.999042,-181.526764,0.100069,0.000000
84.090004,60.674744,-181.571243,0.013098,0.003933,0.099904,269.894745,13.749093,0.999042,-181.571243,0.100069,0.000000
84.350006,60.577179,-181.571243,0.013077,0.003933,0.099904,269.460754,13.726985,0.999042,-181.571243,0.100069,0.000000
84.610001,60.504570,-181.615723,0.013077,0.003933,0.099904,269.137756,13.710531,0.999042,-181.615723,0.100069,0.000000
84.870003,60.429726,-181.704681,0.013077,0.003933,0.099904,268.804840,13.693571,0.999042,-181.704681,0.100069,0.000000
85.130005,60.357483,-181.660202,0.013081,0.003933,0.099904,268.483490,13.677201,0.999042,-181.660202,0.100069,0.000000
85.390007,60.284866,-181.704681,0.013098,0.003933,0.099904,268.160492,13.660746,0.999042,-181.704681,0.100069,0.000000
85.650002,60.206673,-181.704681,0.013081,0.003933,0.099904,267.812653,13.643027,0.999042,-181.704681,0.100069,0.000000
85.910004,60.161613,-181.704681,0.013081,0.003933,0.099904,267.612213,13.632817,0.999042,-181.704681,0.100069,0.000000
86.170006,60.074104,-181.793640,0.013085,0.003933,0.099904,267.222961,13.612987,0.999042,-181.793640,0.100069,0.000000
86.430000,60.015648,-181.749161,0.013077,0.003933,0.099904,266.962921,13.599741,0.999042,-181.749161,0.100069,0.000000
86.690002,59.952339,-181.838135,0.013090,0.003933,0.099904,266.681335,13.585394,0.999042,-181.838135,0.100069,0.000000
86.950005,59.886063,-181.882614,0.013073,0.003933,0.099904,266.386505,13.570375,0.999042,-181.882614,0.100069,0.000000
87.210007,59.832062,-181.838135,0.013077,0.003933,0.099904,266.146301,13.558139,0.999042,-181.838135,0.100069,0.000000
87.470001,59.786263,-181.927094,0.013077,0.003933,0.099904,265.942566,13.547760,0.999042,-181.927094,0.100069,0.000000
87.730003,59.722961,-181.882614,0.013073,0.003933,0.099904,265.661011,13.533417,0.999042,-181.882614,0.100069,0.000000
87.990005,59.668594,-181.927094,0.013090,0.003933,0.099904,265.419159,13.521097,0.999042,-181.927094,0.100069,0.000000
88.250008,59.614601,-182.016052,0.013077,0.003933,0.099904,265.178986,13.508862,0.999042,-182.016052,0.100069,0.000000
88.510002,59.553528,-182.016052,0.013085,0.003933,0.099904,264.907318,13.495022,0.999042,-182.016052,0.100069,0.000000
88.770004,59.490227,-181.971573,0.013085,0.003933,0.099904,264.625732,13.480679,0.999042,-181.971573,0.100069,0.000000
89.030006,59.448151,-182.016052,0.013077,0.003933,0.099904,264.438568,13.471144,0.999042,-182.016052,0.100069,0.000000
89.290001,59.398994,-182.105011,0.013098,0.003933,0.099904,264.219910,13.460005,0.999042,-182.105011,0.100069,0.000000
89.550003,59.352074,-182.060532,0.013081,0.003933,0.099904,264.011200,13.449372,0.999042,-182.060532,0.100069,0.000000
89.810005,59.295845,-182.060532,0.013085,0.003933,0.099904,263.761078,13.436630,0.999042,-182.060532,0.100069,0.000000
90.070007,59.253029,-182.149490,0.013103,0.003933,0.099904,263.570648,13.426929,0.999042,-182.149490,0.100069,0.000000
90.330002,59.198662,-182.149490,0.013085,0.003933,0.099904,263.328796,13.414608,0.999042,-182.149490,0.100069,0.000000
90.590004,59.163284,-182.193970,0.013081,0.003933,0.099904,263.171417,13.406591,0.999042,-182.193970,0.100069,0.000000
90.850006,59.116364,-182.238449,0.013098,0.003933,0.099904,262.962708,13.395959,0.999042,-182.238449,0.100069,0.000000
91.110001,59.071678,-182.238449,0.013073,0.003933,0.099904,262.763947,13.385833,0.999042,-182.238449,0.100069,0.000000
91.370003,59.016571,-182.282944,0.013098,0.003933,0.099904,262.518829,13.373345,0.999042,-182.282944,0.100069,0.000000
91.630005,58.973747,-182.238449,0.013090,0.003933,0.099904,262.328339,13.363642,0.999042,-182.238449,0.100069,0.000000
91.890007,58.932411,-182.327423,0.013090,0.003933,0.099904,262.144470,13.354275,0.999042,-182.327423,0.100069,0.000000
92.150002,58.882515,-182.371902,0.013073,0.003933,0.099904,261.922516,13.342969,0.999042,-182.371902,0.100069,0.000000
92.410004,58.838951,-182.371902,0.013081,0.003933,0.099904,261.728729,13.333097,0.999042,-182.371902,0.100069,0.000000
92.670006,58.792770,-182.416382,0.013098,0.003933,0.099904,261.523315,13.322632,0.999042,-182.416382,0.100069,0.000000
92.930008,58.756279,-182.416382,0.013094,0.003933,0.099904,261.360992,13.314363,0.999042,-182.416382,0.100069,0.000000
93.190002,58.718674,-182.371902,0.013098,0.003933,0.099904,261.193695,13.305841,0.999042,-182.371902,0.100069,0.000000
93.450005,58.679199,-182.460861,0.013094,0.003933,0.099904,261.018127,13.296897,0.999042,-182.460861,0.100069,0.000000
93.710007,58.642708,-182.505341,0.013090,0.003933,0.099904,260.855804,13.288628,0.999042,-182.505341,0.100069,0.000000
93.970001,58.615150,-182.505341,0.013103,0.003933,0.099904,260.733215,13.282383,0.999042,-182.505341,0.100069,0.000000
94.230003,58.572327,-182.505341,0.013073,0.003933,0.099904,260.542725,13.272679,0.999042,-182.505341,0.100069,0.000000
94.490005,58.520195,-182.549820,0.013090,0.003933,0.099904,260.310822,13.260866,0.999042,-182.549820,0.100069,0.000000
94.750008,58.507538,-182.594299,0.013098,0.003933,0.099904,260.254517,13.257998,0.999042,-182.594299,0.100069,0.000000
95.010002,58.475136,-182.594299,0.013094,0.003933,0.099904,260.110382,13.250655,0.999042,-182.594299,0.100069,0.000000
95.270004,58.447212,-182.638779,0.013073,0.003933,0.099904,259.986176,13.244328,0.999042,-182.638779,0.100069,0.000000
95.530006,58.406998,-182.683273,0.013103,0.003933,0.099904,259.807312,13.235215,0.999042,-182.683273,0.100069,0.000000
95.790001,58.374969,-182.638779,0.013085,0.003933,0.099904,259.664825,13.227957,0.999042,-182.638779,0.100069,0.000000
96.050003,58.341461,-182.727753,0.013094,0.003933,0.099904,259.515778,13.220364,0.999042,-182.727753,0.100069,0.000000
96.310005,58.310921,-182.683273,0.013085,0.003933,0.099904,259.379944,13.213443,0.999042,-182.683273,0.100069,0.000000
96.570007,58.284111,-182.772232,0.013103,0.003933,0.099904,259.260681,13.207368,0.999042,-182.772232,0.100069,0.000000
96.830002,58.246506,-182.772232,0.013085,0.003933,0.099904,259.093384,13.198847,0.999042,-182.772232,0.100069,0.000000
97.090004,58.209641,-182.727753,0.013098,0.003933,0.099904,258.929413,13.190493,0.999042,-182.727753,0.100069,0.000000
97.350006,58.195862,-182.861191,0.013077,0.003933,0.099904,258.868134,13.187371,0.999042,-182.861191,0.100069,0.000000
97.610008,58.163834,-182.816711,0.013094,0.003933,0.099904,258.725647,13.180113,0.999042,-182.816711,0.100069,0.000000
97.870003,58.136284,-182.905670,0.013081,0.003933,0.099904,258.603119,13.173870,0.999042,-182.905670,0.100069,0.000000
98.130005,58.106865,-182.861191,0.013098,0.003933,0.099904,258.472229,13.167204,0.999042,-182.861191,0.100069,0.000000
98.390007,58.080795,-182.950150,0.013090,0.003933,0.099904,258.356293,13.161296,0.999042,-182.950150,0.100069,0.000000
98.650002,58.049889,-182.994629,0.013107,0.003933,0.099904,258.218811,13.154293,0.999042,-182.994629,0.100069,0.000000
98.910004,58.022705,-182.994629,0.013103,0.003933,0.099904,258.097870,13.148133,0.999042,-182.994629,0.100069,0.000000
99.170006,58.000366,-182.994629,0.013098,0.003933,0.099904,257.998505,13.143071,0.999042,-182.994629,0.100069,0.000000
99.430008,57.973183,-183.039108,0.013098,0.003933,0.099904,257.877594,13.136911,0.999042,-183.039108,0.100069,0.000000
99.690002,57.951584,-182.950150,0.013103,0.003933,0.099904,257.781525,13.132016,0.999042,-182.950150,0.100069,0.000000
99.950005,57.920677,-183.039108,0.013094,0.003933,0.099904,257.644043,13.125013,0.999042,-183.039108,0.100069,0.000000
100.210007,57.899826,-183.083588,0.013107,0.003933,0.099904,257.551300,13.120288,0.999042,-183.083588,0.100069,0.000000
100.470001,57.869659,-183.083588,0.013103,0.003933,0.099904,257.417114,13.113453,0.999042,-183.083588,0.100069,0.000000
100.730003,57.854767,-183.172562,0.013111,0.003933,0.099904,257.350861,13.110077,0.999042,-183.172562,0.100069,0.000000
100.990005,57.828697,-183.128082,0.013103,0.003933,0.099904,257.234894,13.104170,0.999042,-183.128082,0.100069,0.000000
101.250008,57.805244,-183.172562,0.013098,0.003933,0.099904,257.130554,13.098855,0.999042,-183.172562,0.100069,0.000000
101.510002,57.782524,-183.217041,0.013094,0.003933,0.099904,257.029510,13.093707,0.999042,-183.217041,0.100069,0.000000
101.770004,57.756836,-183.172562,0.013098,0.003933,0.099904,256.915253,13.087886,0.999042,-183.172562,0.100069,0.000000
102.030006,57.716988,-183.350479,0.013085,0.003933,0.099904,256.737976,13.078856,0.999042,-183.350479,0.100069,0.000000
102.290009,57.717735,-183.261520,0.013081,0.003933,0.099904,256.741302,13.079025,0.999042,-183.261520,0.100069,0.000000
102.550003,57.687202,-183.306000,0.013103,0.003933,0.099904,256.605499,13.072106,0.999042,-183.306000,0.100069,0.000000
102.810005,57.668205,-183.350479,0.013094,0.003933,0.099904,256.520996,13.067801,0.999042,-183.350479,0.100069,0.000000
103.070007,57.646980,-183.306000,0.013094,0.003933,0.099904,256.426575,13.062992,0.999042,-183.306000,0.100069,0.000000
103.330002,57.614586,-183.394958,0.013103,0.003933,0.099904,256.282471,13.055652,0.999042,-183.394958,0.100069,0.000000
103.590004,57.594849,-183.394958,0.013081,0.003933,0.099904,256.194672,13.051179,0.999042,-183.394958,0.100069,0.000000
103.850006,57.583305,-183.439438,0.013098,0.003933,0.099904,256.143341,13.048564,0.999042,-183.439438,0.100069,0.000000
104.110008,57.559479,-183.439438,0.013081,0.003933,0.099904,256.037354,13.043164,0.999042,-183.439438,0.100069,0.000000
104.370003,57.536758,-183.439438,0.013098,0.003933,0.099904,255.936279,13.038015,0.999042,-183.439438,0.100069,0.000000
104.630005,57.528198,-183.528397,0.013098,0.003933,0.099904,255.898209,13.036077,0.999042,-183.528397,0.100069,0.000000
104.890007,57.508461,-183.528397,0.013103,0.003933,0.099904,255.810410,13.031604,0.999042,-183.528397,0.100069,0.000000
105.150002,57.493568,-183.528397,0.013094,0.003933,0.099904,255.744171,13.028229,0.999042,-183.528397,0.100069,0.000000
105.410004,57.481277,-183.617371,0.013103,0.003933,0.099904,255.689499,13.025444,0.999042,-183.617371,0.100069,0.000000
105.670006,57.451118,-183.528397,0.013111,0.003933,0.099904,255.555344,13.018610,0.999042,-183.528397,0.100069,0.000000
105.930008,57.434357,-183.617371,0.013094,0.003933,0.099904,255.480774,13.014812,0.999042,-183.617371,0.100069,0.000000
106.190002,57.416115,-183.617371,0.013103,0.003933,0.099904,255.399628,13.010677,0.999042,-183.617371,0.100069,0.000000
106.450005,57.385574,-183.706329,0.013111,0.003933,0.099904,255.263779,13.003757,0.999042,-183.706329,0.100069,0.000000
106.710007,57.385574,-183.750809,0.013090,0.003933,0.099904,255.263779,13.003757,0.999042,-183.750809,0.100069,0.000000
106.970009,57.359886,-183.750809,0.013090,0.003933,0.099904,255.149521,12.997936,0.999042,-183.750809,0.100069,0.000000
107.000008,57.375153,-183.706329,0.013085,0.003933,0.099904,255.217422,13.001395,0.999042,-183.706329,0.100069,0.000000