File: Data/compression 6/AutoNoheating-10-6-day1-1-240228_02282024_201331.csv
Time (sec),S:Load (lbs),S:HL1 (DIM),S:LVDT (in),S:Position (in),Ch:Position (mm),Ch:Load (N),Ch:Stress (MPa),Ch:Strain (mm/mm),Ch:HL1 (DIM),Set Point (),Cycles ()
0.110000,-0.018242,-116.940422,-0.000022,-0.000000,-0.000000,-0.081144,-0.004134,-0.000000,-116.940422,0.000182,0.000000
0.410000,-0.024200,-116.940422,-0.000030,-0.000000,-0.000000,-0.107649,-0.005484,-0.000000,-116.940422,0.000182,0.000000
0.710000,0.009315,-117.029381,-0.000026,0.000150,0.003816,0.041437,0.002111,0.038159,-117.029381,0.005126,0.000000
1.010000,-0.039093,-117.029381,0.000207,0.000350,0.008880,-0.173894,-0.008859,0.088805,-117.029381,0.010121,0.000000
1.310000,0.005219,-116.984901,0.000418,0.000552,0.014023,0.023213,0.001183,0.140230,-116.984901,0.015116,0.000000
1.610000,-0.021965,-117.029381,0.000612,0.000745,0.018932,-0.097705,-0.004977,0.189317,-117.029381,0.020111,0.000000
1.910000,-0.026436,-117.073860,0.000819,0.000942,0.023918,-0.117593,-0.005990,0.239183,-117.073860,0.025124,0.000000
2.210000,-0.051384,-117.029381,0.001026,0.001136,0.028853,-0.228567,-0.011644,0.288526,-117.029381,0.030119,0.000000
2.510000,-0.051758,-117.029381,0.001203,0.001336,0.033943,-0.230230,-0.011728,0.339433,-117.029381,0.035114,0.000000
2.810000,-0.008934,-117.073860,0.001414,0.001537,0.039034,-0.039741,-0.002024,0.390340,-117.073860,0.040109,0.000000
3.110000,-0.026810,-117.073860,0.001630,0.001733,0.044029,-0.119255,-0.006075,0.440293,-117.073860,0.045105,0.000000
3.410000,-0.003349,-117.118347,0.001845,0.001923,0.048842,-0.014898,-0.000759,0.488422,-117.118347,0.050100,0.000000
3.710000,-0.018242,-117.073860,0.002031,0.002123,0.053924,-0.081144,-0.004134,0.539242,-117.073860,0.055112,0.000000
4.010000,-0.008934,-117.073860,0.002220,0.002315,0.058789,-0.039741,-0.002024,0.587893,-117.073860,0.060108,0.000000
4.310000,-0.052132,-117.073860,0.002440,0.002516,0.063906,-0.231893,-0.011813,0.639061,-117.073860,0.065103,0.000000
4.610000,-0.013031,-117.073860,0.002608,0.002705,0.068702,-0.057965,-0.002953,0.687019,-117.073860,0.070098,0.000000
4.910000,-0.044685,-117.162827,0.002833,0.002911,0.073949,-0.198770,-0.010126,0.739485,-117.162827,0.075093,0.000000
5.210000,-0.007446,-117.073860,0.003040,0.003106,0.078900,-0.033123,-0.001687,0.789003,-117.073860,0.080088,0.000000
5.510000,-0.017502,-117.118347,0.003247,0.003308,0.084026,-0.077852,-0.003966,0.840258,-117.118347,0.085101,0.000000
5.810000,-0.004837,-117.118347,0.003462,0.003506,0.089064,-0.021516,-0.001096,0.890643,-117.118347,0.090096,0.000000
6.110000,-0.013771,-117.162827,0.003669,0.003700,0.093973,-0.061257,-0.003121,0.939729,-117.162827,0.095091,0.000000
6.410000,-0.020477,-117.207306,0.003867,0.003895,0.098933,-0.091088,-0.004640,0.989334,-117.207306,0.100087,0.000000
6.710001,-0.013771,-117.073860,0.004061,0.004086,0.103790,-0.061257,-0.003121,1.037898,-117.073860,0.105082,0.000000
7.010000,-0.080803,-117.207306,0.004260,0.004289,0.108941,-0.359429,-0.018310,1.089410,-117.207306,0.110077,0.000000
7.310000,0.006332,-117.207306,0.004458,0.004480,0.113789,0.028168,0.001435,1.137887,-117.207306,0.115072,0.000000
7.610000,-0.034630,-117.162827,0.004644,0.004680,0.118879,-0.154041,-0.007847,1.188794,-117.162827,0.120085,0.000000
7.910000,0.008568,-117.207306,0.004868,0.004880,0.123953,0.038112,0.001941,1.239527,-117.207306,0.125080,0.000000
8.210000,-0.022713,-117.251785,0.005066,0.005076,0.128922,-0.101031,-0.005147,1.289219,-117.251785,0.130075,0.000000
8.510000,-0.009308,-117.251785,0.005269,0.005273,0.133926,-0.041403,-0.002109,1.339259,-117.251785,0.135070,0.000000
8.810000,-0.016006,-117.207306,0.005476,0.005467,0.138869,-0.071200,-0.003627,1.388689,-117.207306,0.140066,0.000000
9.110001,-0.021225,-117.251785,0.005687,0.005674,0.144116,-0.094413,-0.004810,1.441156,-117.251785,0.145061,0.000000
9.410001,0.006706,-117.207306,0.005872,0.005864,0.148938,0.029831,0.001520,1.489375,-117.207306,0.150074,0.000000
9.710000,-0.028297,-117.207306,0.006066,0.006063,0.154002,-0.125873,-0.006412,1.540021,-117.207306,0.155069,0.000000
10.010000,-0.000000,-117.296265,0.006265,0.006257,0.158919,-0.000000,-0.000000,1.589194,-117.296265,0.160064,0.000000
10.310000,-0.027924,-117.251785,0.006480,0.006454,0.163923,-0.124210,-0.006328,1.639230,-117.251785,0.165059,0.000000
10.610001,0.003357,-117.251785,0.006661,0.006648,0.168858,0.014932,0.000761,1.688578,-117.251785,0.170055,0.000000
10.910001,-0.053246,-117.251785,0.006873,0.006847,0.173914,-0.236848,-0.012066,1.739137,-117.251785,0.175049,0.000000
11.210001,-0.026436,-117.251785,0.007071,0.007041,0.178848,-0.117593,-0.005990,1.788480,-117.251785,0.180045,0.000000
11.510000,-0.002602,-117.251785,0.007286,0.007243,0.183974,-0.011573,-0.000590,1.839735,-117.251785,0.185058,0.000000
11.810000,0.024956,-117.296265,0.007472,0.007441,0.189003,0.111009,0.005655,1.890033,-117.296265,0.190053,0.000000
12.110001,0.001862,-117.296265,0.007662,0.007635,0.193921,0.008281,0.000422,1.939206,-117.296265,0.195048,0.000000
12.410001,0.001495,-117.296265,0.007877,0.007837,0.199072,0.006652,0.000339,1.990718,-117.296265,0.200043,0.000000
12.710001,-0.007446,-117.340752,0.008063,0.008024,0.203807,-0.033123,-0.001687,2.038068,-117.340752,0.205038,0.000000
13.010000,-0.033134,-117.340752,0.008269,0.008224,0.208880,-0.147389,-0.007508,2.088800,-117.340752,0.210034,0.000000
13.310000,-0.020103,-117.296265,0.008472,0.008411,0.213650,-0.089425,-0.004556,2.136497,-117.296265,0.215046,0.000000
13.610001,-0.006325,-117.340752,0.008675,0.008618,0.218897,-0.028134,-0.001433,2.188967,-117.340752,0.220041,0.000000
13.910001,0.027931,-117.385231,0.008869,0.008811,0.223805,0.124244,0.006329,2.238050,-117.385231,0.225037,0.000000
14.210001,-0.002228,-117.385231,0.009076,0.009013,0.228922,-0.009910,-0.000505,2.289218,-117.385231,0.230032,0.000000
14.510000,0.014526,-117.296265,0.009274,0.009211,0.233952,0.064617,0.003292,2.339515,-117.296265,0.235027,0.000000
14.810000,-0.005959,-117.340752,0.009477,0.009401,0.238791,-0.026505,-0.001350,2.387909,-117.340752,0.240022,0.000000
15.110001,-0.018990,-117.340752,0.009679,0.009599,0.243821,-0.084470,-0.004303,2.438207,-117.340752,0.245035,0.000000
15.410001,-0.003723,-117.429710,0.009873,0.009797,0.248833,-0.016561,-0.000844,2.488334,-117.429710,0.250030,0.000000
15.710001,0.004097,-117.385231,0.010085,0.009999,0.253985,0.018224,0.000928,2.539846,-117.385231,0.255025,0.000000
16.010000,0.019737,-117.429710,0.010266,0.010193,0.258902,0.087796,0.004473,2.589016,-117.429710,0.260020,0.000000
16.310001,-0.013031,-117.474190,0.010494,0.010392,0.263958,-0.057965,-0.002953,2.639578,-117.474190,0.265016,0.000000
16.610001,0.039101,-117.474190,0.010671,0.010585,0.268849,0.173928,0.008860,2.688487,-117.474190,0.270011,0.000000
16.910002,-0.016380,-117.474190,0.010891,0.010783,0.273887,-0.072863,-0.003712,2.738875,-117.474190,0.275006,0.000000
17.210001,-0.002975,-117.385231,0.011072,0.010975,0.278753,-0.013236,-0.000674,2.787526,-117.385231,0.280019,0.000000
17.510000,-0.043564,-117.474190,0.011283,0.011177,0.283886,-0.193782,-0.009872,2.838864,-117.474190,0.285014,0.000000
17.810001,0.020859,-117.518669,0.011486,0.011374,0.288908,0.092784,0.004727,2.889078,-117.518669,0.290009,0.000000
18.110001,0.010429,-117.518669,0.011676,0.011570,0.293877,0.046392,0.002363,2.938770,-117.518669,0.295004,0.000000
18.410002,0.032768,-117.429710,0.011904,0.011773,0.299028,0.145760,0.007425,2.990283,-117.429710,0.299999,0.000000
18.710001,0.005592,-117.563156,0.012094,0.011967,0.303971,0.024876,0.001267,3.039713,-117.563156,0.304995,0.000000
19.010000,-0.022339,-117.518669,0.012296,0.012163,0.308932,-0.099368,-0.005062,3.089318,-117.518669,0.310007,0.000000
19.310001,0.006706,-117.518669,0.012499,0.012354,0.313789,0.029831,0.001520,3.137886,-117.518669,0.315002,0.000000
19.610001,-0.066277,-117.563156,0.012680,0.012555,0.318896,-0.294813,-0.015018,3.188963,-117.563156,0.319998,0.000000
19.910002,0.043945,-117.518669,0.012874,0.012747,0.323761,0.195479,0.009958,3.237614,-117.518669,0.324993,0.000000
20.210001,-0.004089,-117.474190,0.013090,0.012948,0.328878,-0.018190,-0.000927,3.288782,-117.474190,0.329988,0.000000
20.510000,0.039848,-117.607635,0.013292,0.013146,0.333908,0.177254,0.009030,3.339080,-117.607635,0.334983,0.000000
20.810001,0.020859,-117.607635,0.013491,0.013342,0.338877,0.092784,0.004727,3.388772,-117.607635,0.339996,0.000000
21.110001,-0.002228,-117.652115,0.013689,0.013541,0.343950,-0.009910,-0.000505,3.439504,-117.652115,0.344991,0.000000
21.410002,-0.003723,-117.563156,0.013883,0.013730,0.348746,-0.016561,-0.000844,3.487463,-117.563156,0.349987,0.000000
21.710001,-0.010796,-117.607635,0.014090,0.013931,0.353846,-0.048021,-0.002446,3.538457,-117.607635,0.354982,0.000000
22.010000,0.013405,-117.607635,0.014288,0.014129,0.358867,0.059628,0.003038,3.588667,-117.607635,0.359977,0.000000
22.310001,-0.015266,-117.607635,0.014495,0.014329,0.363949,-0.067908,-0.003459,3.639487,-117.607635,0.364972,0.000000
22.610001,0.037239,-117.607635,0.014694,0.014518,0.368753,0.165648,0.008438,3.687532,-117.607635,0.369967,0.000000
22.910002,0.012291,-117.607635,0.014883,0.014719,0.373853,0.054673,0.002785,3.738526,-117.607635,0.374980,0.000000
23.210001,0.037987,-117.607635,0.015082,0.014909,0.378683,0.168974,0.008608,3.786829,-117.607635,0.379975,0.000000
23.510000,-0.014519,-117.652115,0.015284,0.015109,0.383765,-0.064583,-0.003290,3.837649,-117.652115,0.384970,0.000000
23.810001,-0.000000,-117.696594,0.015483,0.015298,0.388561,-0.000000,-0.000000,3.885607,-117.696594,0.389966,0.000000
24.110001,-0.010048,-117.696594,0.015690,0.015503,0.393764,-0.044695,-0.002277,3.937638,-117.696594,0.394961,0.000000
24.410002,0.032402,-117.652115,0.015884,0.015704,0.398872,0.144131,0.007342,3.988719,-117.652115,0.399956,0.000000
24.710001,0.022720,-117.696594,0.016104,0.015901,0.403876,0.101065,0.005149,4.038759,-117.696594,0.404969,0.000000
25.010002,0.025696,-117.696594,0.016302,0.016101,0.408958,0.114301,0.005823,4.089579,-117.696594,0.409964,0.000000
25.310001,0.014526,-117.652115,0.016492,0.016290,0.413762,0.064617,0.003292,4.137620,-117.652115,0.414959,0.000000
25.610001,-0.020477,-117.696594,0.016699,0.016491,0.418870,-0.091088,-0.004640,4.188702,-117.696594,0.419954,0.000000
25.910002,0.026070,-117.696594,0.016880,0.016680,0.423666,0.115964,0.005907,4.236660,-117.696594,0.424949,0.000000
26.210001,-0.032768,-117.741081,0.017099,0.016884,0.428843,-0.145760,-0.007425,4.288434,-117.741081,0.429945,0.000000
26.510002,0.048042,-117.696594,0.017276,0.017074,0.433682,0.213703,0.010887,4.336823,-117.696594,0.434940,0.000000
26.810001,0.001495,-117.741081,0.017470,0.017276,0.438816,0.006652,0.000339,4.388162,-117.741081,0.439952,0.000000
27.110001,0.039848,-117.785561,0.017682,0.017475,0.443864,0.177254,0.009030,4.438637,-117.785561,0.444948,0.000000
27.410002,0.008194,-117.785561,0.017897,0.017671,0.448850,0.036449,0.001857,4.488503,-117.785561,0.449943,0.000000
27.710001,0.018250,-117.741081,0.018078,0.017868,0.453854,0.081178,0.004135,4.538539,-117.741081,0.454938,0.000000
28.010002,0.022720,-117.785561,0.018281,0.018062,0.458763,0.101065,0.005149,4.587626,-117.785561,0.459933,0.000000
28.310001,-0.006325,-117.785561,0.018471,0.018264,0.463914,-0.028134,-0.001433,4.639138,-117.785561,0.464929,0.000000
28.610001,0.036865,-117.785561,0.018669,0.018455,0.468762,0.163985,0.008354,4.687615,-117.785561,0.469941,0.000000
28.910002,0.002609,-117.830040,0.018884,0.018656,0.473861,0.011607,0.000591,4.738609,-117.830040,0.474936,0.000000
29.210001,0.045059,-117.830040,0.019070,0.018849,0.478752,0.200433,0.010211,4.787521,-117.830040,0.479931,0.000000
29.510002,0.015640,-117.830040,0.019272,0.019046,0.483773,0.069571,0.003544,4.837732,-117.830040,0.484927,0.000000
29.810001,0.036865,-117.874519,0.019471,0.019242,0.488751,0.163985,0.008354,4.887511,-117.874519,0.489922,0.000000
30.110001,0.017876,-117.830040,0.019661,0.019440,0.493764,0.079515,0.004051,4.937638,-117.830040,0.494917,0.000000
30.410002,0.081551,-117.830040,0.019863,0.019637,0.498776,0.362755,0.018480,4.987765,-117.830040,0.499930,0.000000
30.710001,0.261040,-117.874519,0.020074,0.019835,0.503815,1.161163,0.059152,5.038149,-117.874519,0.504925,0.000000
31.010002,0.685165,-117.874519,0.020251,-0.000003,-0.000087,3.047768,0.155261,-0.000867,-117.874519,0.001197,0.000000
31.310001,0.578667,-117.874519,0.020268,-0.000006,-0.000156,2.574038,0.131128,-0.001559,-117.874519,0.000009,0.000000
31.610001,0.514252,-117.874519,0.020260,-0.000006,-0.000165,2.287506,0.116531,-0.001646,-117.874519,0.000130,0.000000
31.910002,0.544411,-117.830040,0.020256,-0.000006,-0.000156,2.421660,0.123365,-0.001559,-117.830040,0.000633,0.000000
32.210003,0.639740,-117.830040,0.020277,0.000013,0.000338,2.845706,0.144967,0.003384,-117.830040,0.001136,0.000000
32.510002,0.675117,-117.918999,0.020307,0.000032,0.000815,3.003073,0.152984,0.008153,-117.918999,0.001631,0.000000
32.810001,0.736557,-117.963486,0.020307,0.000047,0.001205,3.276369,0.166906,0.012055,-117.963486,0.002134,0.000000
33.110001,0.854973,-117.963486,0.020320,0.000071,0.001804,3.803109,0.193740,0.018039,-117.963486,0.002628,0.000000
33.410000,0.897797,-118.007965,0.020346,0.000086,0.002194,3.993599,0.203444,0.021941,-118.007965,0.003131,0.000000
33.710003,0.951416,-117.963486,0.020359,0.000101,0.002567,4.232110,0.215594,0.025669,-117.963486,0.003634,0.000000
34.010002,1.066849,-117.963486,0.020381,0.000126,0.003200,4.745580,0.241751,0.032001,-117.963486,0.004128,0.000000
34.310001,1.142067,-117.963486,0.020415,0.000149,0.003790,5.080168,0.258796,0.037898,-117.963486,0.004631,0.000000
34.610001,1.165527,-117.963486,0.020428,0.000167,0.004249,5.184525,0.264112,0.042493,-117.963486,0.005134,0.000000
34.910000,1.212448,-117.963486,0.020445,0.000186,0.004727,5.393239,0.274745,0.047266,-117.963486,0.005629,0.000000
35.210003,1.332352,-117.963486,0.020462,0.000207,0.005264,5.926596,0.301915,0.052640,-117.963486,0.006131,0.000000
35.510002,1.372192,-118.007965,0.020475,0.000221,0.005620,6.103817,0.310943,0.056198,-118.007965,0.006634,0.000000
35.810001,1.506622,-118.052444,0.020501,0.000244,0.006201,6.701791,0.341406,0.062008,-118.052444,0.007128,0.000000
36.110001,1.581841,-118.052444,0.020519,0.000268,0.006799,7.036378,0.358450,0.067992,-118.052444,0.007631,0.000000
36.410000,1.614609,-118.007965,0.020553,0.000286,0.007276,7.182138,0.365876,0.072761,-118.007965,0.008134,0.000000
36.710003,1.705093,-118.052444,0.020575,0.000307,0.007788,7.584634,0.386380,0.077878,-118.052444,0.008629,0.000000
37.010002,1.766907,-118.007965,0.020587,0.000325,0.008247,7.859594,0.400387,0.082473,-118.007965,0.009132,0.000000
37.310001,1.845856,-118.096924,0.020605,0.000344,0.008733,8.210776,0.418277,0.087329,-118.096924,0.009635,0.000000
37.610001,1.885323,-118.052444,0.020622,0.000360,0.009132,8.386333,0.427220,0.091318,-118.052444,0.010129,0.000000
37.910004,2.052895,-118.096924,0.020648,0.000386,0.009800,9.131731,0.465193,0.097998,-118.096924,0.010632,0.000000
38.210003,2.094597,-118.096924,0.020665,0.000406,0.010311,9.317232,0.474642,0.103112,-118.096924,0.011135,0.000000
38.510002,2.100182,-118.096924,0.020691,0.000423,0.010736,9.342074,0.475908,0.107362,-118.096924,0.011629,0.000000
38.810001,2.182106,-118.096924,0.020708,0.000440,0.011187,9.706492,0.494472,0.111874,-118.096924,0.012132,0.000000
39.110001,2.300148,-118.096924,0.020734,0.000463,0.011760,10.231569,0.521221,0.117597,-118.096924,0.012635,0.000000
39.410004,2.246529,-118.141403,0.020730,0.000472,0.011985,9.993058,0.509071,0.119852,-118.141403,0.013130,0.000000
39.710003,2.509796,-118.141403,0.020777,0.000503,0.012766,11.164131,0.568728,0.127657,-118.141403,0.013633,0.000000
40.010002,2.549263,-118.185890,0.020799,0.000525,0.013338,11.339688,0.577671,0.133380,-118.185890,0.014136,0.000000
40.310001,2.559692,-118.185890,0.020820,0.000542,0.013763,11.386081,0.580035,0.137630,-118.185890,0.014630,0.000000
40.610001,2.595070,-118.185890,0.020833,0.000559,0.014205,11.543447,0.588051,0.142051,-118.185890,0.015133,0.000000
40.910004,2.710503,-118.185890,0.020855,0.000578,0.014674,12.056918,0.614209,0.146737,-118.185890,0.015636,0.000000
41.210003,2.799126,-118.185890,0.020881,0.000598,0.015194,12.451133,0.634291,0.151937,-118.185890,0.016130,0.000000
41.510002,2.824448,-118.185890,0.020889,0.000613,0.015576,12.563770,0.640029,0.155756,-118.185890,0.016633,0.000000
41.810001,2.946960,-118.185890,0.020907,0.000638,0.016217,13.108735,0.667791,0.162171,-118.185890,0.017136,0.000000
42.110001,3.007286,-118.230370,0.020937,0.000660,0.016755,13.377076,0.681461,0.167550,-118.230370,0.017631,0.000000
42.410004,3.012871,-118.185890,0.020958,0.000678,0.017223,13.401918,0.682726,0.172232,-118.185890,0.018134,0.000000
42.710003,3.024040,-118.185890,0.020967,0.000693,0.017605,13.451603,0.685257,0.176047,-118.185890,0.018637,0.000000
43.010002,3.167778,-118.185890,0.021006,0.000714,0.018134,14.090981,0.717829,0.181338,-118.185890,0.019131,0.000000
43.310001,3.135376,-118.230370,0.021010,0.000729,0.018507,13.946849,0.710486,0.185066,-118.230370,0.019634,0.000000
43.610001,3.180435,-118.274849,0.021023,0.000743,0.018862,14.147283,0.720697,0.188620,-118.274849,0.020137,0.000000
43.910004,3.363274,-118.274849,0.021070,0.000773,0.019625,14.960588,0.762129,0.196254,-118.274849,0.020631,0.000000
44.210003,3.397530,-118.319328,0.021075,0.000794,0.020163,15.112967,0.769891,0.201629,-118.319328,0.021134,0.000000
44.510002,3.388962,-118.319328,0.021096,0.000811,0.020605,15.074855,0.767950,0.206053,-118.319328,0.021637,0.000000
44.810001,3.526001,-118.363808,0.021122,0.000832,0.021134,15.684436,0.799003,0.211345,-118.363808,0.022132,0.000000
45.110001,3.565468,-118.319328,0.021139,0.000853,0.021655,15.859993,0.807947,0.216545,-118.319328,0.022635,0.000000
45.410004,3.617226,-118.319328,0.021165,0.000868,0.022045,16.090223,0.819675,0.220447,-118.319328,0.023137,0.000000
45.710003,3.790382,-118.319328,0.021182,0.000893,0.022678,16.860462,0.858913,0.226780,-118.319328,0.023632,0.000000
46.010002,3.823898,-118.363808,0.021208,0.000915,0.023250,17.009550,0.866508,0.232502,-118.363808,0.024135,0.000000
46.310001,3.765434,-118.319328,0.021234,0.000932,0.023667,16.749489,0.853260,0.236666,-118.319328,0.024629,0.000000
46.610001,3.785172,-118.363808,0.021256,0.000951,0.024143,16.837284,0.857732,0.241435,-118.363808,0.025132,0.000000
46.910004,3.932999,-118.363808,0.021269,0.000971,0.024664,17.494852,0.891230,0.246639,-118.363808,0.025635,0.000000
47.210003,3.911774,-118.363808,0.021290,0.000986,0.025045,17.400438,0.886421,0.250454,-118.363808,0.026129,0.000000
47.510002,4.188820,-118.363808,0.021320,0.001014,0.025765,18.632801,0.949200,0.257653,-118.363808,0.026632,0.000000
47.810001,4.137802,-118.363808,0.021333,0.001036,0.026303,18.405863,0.937639,0.263031,-118.363808,0.027135,0.000000
48.110001,4.120674,-118.319328,0.021364,0.001054,0.026763,18.329674,0.933758,0.267626,-118.319328,0.027630,0.000000
48.410004,4.135941,-118.363808,0.021385,0.001070,0.027170,18.397583,0.937218,0.271702,-118.363808,0.028133,0.000000
48.710003,4.291969,-118.408295,0.021407,0.001093,0.027751,19.091633,0.972574,0.277512,-118.408295,0.028636,0.000000
49.010002,4.319527,-118.408295,0.021424,0.001109,0.028159,19.214214,0.978819,0.281589,-118.408295,0.029130,0.000000
49.310001,4.302765,-118.452774,0.021458,0.001122,0.028489,19.139654,0.975020,0.284885,-118.452774,0.029633,0.000000
49.610001,4.544067,-118.408295,0.021484,0.001152,0.029260,20.213020,1.029700,0.292603,-118.408295,0.030136,0.000000
49.910004,4.516510,-118.408295,0.021493,0.001169,0.029694,20.090441,1.023456,0.296940,-118.408295,0.030630,0.000000
50.210003,4.514648,-118.408295,0.021523,0.001189,0.030197,20.082159,1.023034,0.301970,-118.408295,0.031133,0.000000
50.510002,4.637527,-118.452774,0.021549,0.001209,0.030717,20.628752,1.050879,0.307171,-118.452774,0.031636,0.000000
50.810001,4.737328,-118.452774,0.021562,0.001229,0.031220,21.072685,1.073494,0.312201,-118.452774,0.032131,0.000000
51.110001,4.616302,-118.497253,0.021566,0.001241,0.031532,20.534340,1.046069,0.315323,-118.497253,0.032634,0.000000
51.410004,4.815521,-118.497253,0.021596,0.001266,0.032166,21.420507,1.091213,0.321656,-118.497253,0.033137,0.000000
51.710003,4.894470,-118.452774,0.021631,0.001288,0.032712,21.771690,1.109103,0.327117,-118.452774,0.033631,0.000000
52.010002,4.965591,-118.452774,0.021657,0.001310,0.033284,22.088055,1.125219,0.332840,-118.452774,0.034134,0.000000
52.310001,4.941383,-118.541733,0.021670,0.001326,0.033692,21.980371,1.119733,0.336916,-118.541733,0.034637,0.000000
52.610001,5.004318,-118.541733,0.021696,0.001347,0.034203,22.260319,1.133995,0.342033,-118.541733,0.035131,0.000000
52.910004,5.084373,-118.541733,0.021713,0.001364,0.034654,22.616423,1.152135,0.346545,-118.541733,0.035634,0.000000
53.210003,5.184174,-118.541733,0.021721,0.001384,0.035166,23.060356,1.174750,0.351662,-118.541733,0.036137,0.000000
53.510002,5.327164,-118.586212,0.021756,0.001409,0.035782,23.696407,1.207153,0.357816,-118.586212,0.036632,0.000000
53.810001,5.268326,-118.541733,0.021765,0.001428,0.036276,23.434683,1.193820,0.362759,-118.541733,0.037135,0.000000
54.110004,5.280617,-118.586212,0.021799,0.001447,0.036745,23.489357,1.196605,0.367445,-118.586212,0.037638,0.000000
54.410004,5.387489,-118.586212,0.021834,0.001466,0.037239,23.964750,1.220822,0.372388,-118.586212,0.038132,0.000000
54.710003,5.413185,-118.586212,0.021846,0.001484,0.037681,24.079050,1.226645,0.376809,-118.586212,0.038635,0.000000
55.010002,5.236305,-118.586212,0.021864,0.001492,0.037889,23.292250,1.186564,0.378891,-118.586212,0.039138,0.000000
55.310001,5.776993,-118.630699,0.021881,0.001530,0.038852,25.697348,1.309085,0.388519,-118.630699,0.039632,0.000000
55.610004,5.692459,-118.586212,0.021898,0.001546,0.039277,25.321323,1.289930,0.392766,-118.586212,0.040135,0.000000
55.910004,5.667885,-118.586212,0.021941,0.001565,0.039762,25.212011,1.284361,0.397622,-118.586212,0.040638,0.000000
56.210003,5.717781,-118.630699,0.021946,0.001585,0.040265,25.433960,1.295668,0.402652,-118.630699,0.041133,0.000000
56.510002,5.822418,-118.630699,0.021984,0.001604,0.040742,25.899410,1.319379,0.407421,-118.630699,0.041636,0.000000
56.810001,5.771774,-118.630699,0.022006,0.001619,0.041124,25.674135,1.307903,0.411240,-118.630699,0.042138,0.000000
57.110004,6.068184,-118.630699,0.022015,0.001643,0.041722,26.992630,1.375070,0.417224,-118.630699,0.042633,0.000000
57.410004,6.133720,-118.675179,0.022032,0.001666,0.042312,27.284151,1.389921,0.423121,-118.675179,0.043136,0.000000
57.710003,6.062599,-118.675179,0.022066,0.001684,0.042780,26.967789,1.373805,0.427803,-118.675179,0.043639,0.000000
58.010002,6.167236,-118.675179,0.022105,0.001703,0.043248,27.433237,1.397516,0.432485,-118.675179,0.044133,0.000000
58.310001,6.278572,-118.675179,0.022105,0.001723,0.043769,27.928484,1.422745,0.437689,-118.675179,0.044636,0.000000
58.610004,6.313576,-118.764137,0.022127,0.001742,0.044246,28.084188,1.430677,0.442458,-118.764137,0.045139,0.000000
58.910004,6.281929,-118.719658,0.022135,0.001759,0.044688,27.943417,1.423505,0.446883,-118.719658,0.045633,0.000000
59.210003,6.539238,-118.675179,0.022178,0.001782,0.045269,29.087984,1.481813,0.452692,-118.675179,0.046136,0.000000
59.510002,6.599930,-118.719658,0.022200,0.001804,0.045824,29.357954,1.495566,0.458241,-118.719658,0.046631,0.000000
59.810001,6.510933,-118.719658,0.022213,0.001821,0.046249,28.962076,1.475399,0.462491,-118.719658,0.047134,0.000000
60.110004,6.538490,-118.719658,0.022239,0.001837,0.046648,29.084658,1.481643,0.466481,-118.719658,0.047637,0.000000
60.410004,6.776436,-118.764137,0.022265,0.001859,0.047229,30.143091,1.535562,0.472291,-118.764137,0.048131,0.000000
60.710003,6.550034,-118.764137,0.022265,0.001870,0.047506,29.136005,1.484259,0.475065,-118.764137,0.048634,0.000000
61.010002,7.073219,-118.764137,0.022316,0.001901,0.048287,31.463251,1.602814,0.482873,-118.764137,0.049137,0.000000
61.310001,7.080666,-118.764137,0.022334,0.001922,0.048825,31.496374,1.604502,0.488248,-118.764137,0.049631,0.000000
61.610004,7.004326,-118.764137,0.022351,0.001940,0.049267,31.156797,1.587203,0.492672,-118.764137,0.050134,0.000000
61.910004,6.940651,-118.808617,0.022377,0.001955,0.049666,30.873558,1.572774,0.496661,-118.808617,0.050637,0.000000
62.210003,7.135033,-118.808617,0.022390,0.001976,0.050178,31.738211,1.616822,0.501779,-118.808617,0.051132,0.000000
62.510002,7.306694,-118.808617,0.022429,0.001997,0.050715,32.501797,1.655720,0.507153,-118.808617,0.051635,0.000000
62.810001,7.269829,-118.764137,0.022429,0.002012,0.051097,32.337814,1.647367,0.510968,-118.764137,0.052138,0.000000
63.110004,7.483200,-118.853104,0.022450,0.002036,0.051721,33.286938,1.695717,0.517213,-118.853104,0.052632,0.000000
63.410004,7.495491,-118.853104,0.022476,0.002056,0.052233,33.341610,1.698503,0.522331,-118.853104,0.053135,0.000000
63.710003,7.556557,-118.853104,0.022510,0.002077,0.052745,33.613243,1.712340,0.527448,-118.853104,0.053638,0.000000
64.010002,7.303345,-118.897583,0.022515,0.002088,0.053031,32.486900,1.654962,0.530309,-118.897583,0.054132,0.000000
64.310005,7.591560,-118.808617,0.022536,0.002109,0.053569,33.768948,1.720272,0.535688,-118.808617,0.054635,0.000000
64.610001,7.645927,-118.853104,0.022554,0.002126,0.053993,34.010784,1.732592,0.539934,-118.853104,0.055138,0.000000
64.910004,7.846260,-118.853104,0.022575,0.002147,0.054540,34.901909,1.777988,0.545400,-118.853104,0.055633,0.000000
65.210007,8.087189,-118.853104,0.022605,0.002171,0.055138,35.973614,1.832583,0.551383,-118.853104,0.056136,0.000000
65.510002,8.047348,-118.942062,0.022631,0.002191,0.055659,35.796391,1.823555,0.556588,-118.942062,0.056639,0.000000
65.810005,8.080856,-118.853104,0.022653,0.002210,0.056144,35.945446,1.831148,0.561444,-118.853104,0.057133,0.000000
66.110001,8.244331,-118.853104,0.022679,0.002231,0.056673,36.672619,1.868192,0.566731,-118.853104,0.057636,0.000000
66.410004,8.225708,-118.853104,0.022704,0.002249,0.057133,36.589775,1.863972,0.571330,-118.853104,0.058139,0.000000
66.710007,8.303162,-118.897583,0.022717,0.002266,0.057549,36.934307,1.881523,0.575493,-118.897583,0.058633,0.000000
67.010002,8.670326,-118.942062,0.022743,0.002290,0.058165,38.567535,1.964724,0.581648,-118.942062,0.059136,0.000000
67.310005,8.660645,-118.942062,0.022765,0.002310,0.058685,38.524471,1.962530,0.586852,-118.942062,0.059639,0.000000
67.610001,8.616333,-118.986542,0.022791,0.002329,0.059162,38.327362,1.952489,0.591621,-118.986542,0.060134,0.000000
67.910004,8.639420,-118.986542,0.022808,0.002346,0.059596,38.430058,1.957721,0.595958,-118.986542,0.060636,0.000000
68.210007,8.891884,-118.942062,0.022829,0.002368,0.060159,39.553074,2.014930,0.601594,-118.942062,0.061139,0.000000
68.510002,8.907898,-118.986542,0.022855,0.002385,0.060576,39.624310,2.018559,0.605757,-118.986542,0.061634,0.000000
68.810005,9.393845,-118.986542,0.022877,0.002410,0.061218,41.785908,2.128676,0.612176,-118.986542,0.062137,0.000000
69.110001,9.325325,-118.942062,0.022911,0.002433,0.061790,41.481117,2.113149,0.617899,-118.942062,0.062640,0.000000
69.410004,9.178612,-119.031029,0.022942,0.002450,0.062232,40.828503,2.079903,0.622320,-119.031029,0.063134,0.000000
69.710007,9.120148,-118.986542,0.022946,0.002467,0.062666,40.568443,2.066655,0.626657,-118.986542,0.063637,0.000000
70.010002,9.486191,-118.986542,0.022963,0.002489,0.063221,42.196686,2.149602,0.632206,-118.986542,0.064140,0.000000
70.310005,9.564392,-119.075508,0.022985,0.002506,0.063646,42.544540,2.167322,0.636457,-119.075508,0.064634,0.000000
70.610001,9.470551,-119.075508,0.023011,0.002520,0.064001,42.127113,2.146057,0.640014,-119.075508,0.065137,0.000000
70.910004,9.880905,-119.031029,0.023032,0.002547,0.064686,43.952461,2.239045,0.646865,-119.031029,0.065640,0.000000
71.210007,10.003792,-119.031029,0.023049,0.002568,0.065233,44.499088,2.266891,0.652327,-119.031029,0.066135,0.000000
71.510002,9.959480,-119.075508,0.023084,0.002585,0.065658,44.301979,2.256850,0.656577,-119.075508,0.066638,0.000000
71.810005,10.224609,-119.075508,0.023105,0.002608,0.066239,45.481335,2.316930,0.662387,-119.075508,0.067141,0.000000
72.110001,10.341904,-119.075508,0.023127,0.002627,0.066724,46.003086,2.343509,0.667243,-119.075508,0.067635,0.000000
72.410004,10.147522,-119.075508,0.023144,0.002642,0.067097,45.138432,2.299461,0.670975,-119.075508,0.068138,0.000000
72.710007,10.404091,-119.075508,0.023174,0.002662,0.067626,46.279709,2.357601,0.676262,-119.075508,0.068632,0.000000
73.010002,10.761192,-119.119987,0.023187,0.002685,0.068207,47.868176,2.438521,0.682072,-119.119987,0.069135,0.000000
73.310005,10.871788,-119.164467,0.023222,0.002708,0.068789,48.360130,2.463583,0.687886,-119.164467,0.069638,0.000000
73.610001,10.721352,-119.075508,0.023239,0.002723,0.069153,47.690952,2.429493,0.691527,-119.075508,0.070133,0.000000
73.910004,11.027817,-119.119987,0.023256,0.002746,0.069751,49.054180,2.498939,0.697511,-119.119987,0.070636,0.000000
74.210007,11.085533,-119.164467,0.023287,0.002764,0.070193,49.310913,2.512018,0.701931,-119.164467,0.071139,0.000000
74.510002,11.234108,-119.119987,0.023295,0.002781,0.070644,49.971809,2.545685,0.706443,-119.119987,0.071633,0.000000
74.810005,11.669411,-119.208946,0.023334,0.002806,0.071260,51.908131,2.644326,0.712601,-119.208946,0.072136,0.000000
75.110001,11.554352,-119.164467,0.023360,0.002823,0.071711,51.396324,2.618253,0.717109,-119.164467,0.072639,0.000000
75.410004,11.513016,-119.119987,0.023368,0.002841,0.072171,51.212452,2.608887,0.721708,-119.119987,0.073133,0.000000
75.710007,11.876450,-119.164467,0.023394,0.002864,0.072734,52.829086,2.691242,0.727343,-119.164467,0.073636,0.000000
76.010002,12.016090,-119.119987,0.023416,0.002881,0.073185,53.450241,2.722885,0.731851,-119.119987,0.074139,0.000000
76.310005,11.807564,-119.164467,0.023433,0.002896,0.073567,52.522667,2.675632,0.735666,-119.164467,0.074634,0.000000
76.610001,12.587685,-119.208946,0.023450,0.002921,0.074182,55.992817,2.852410,0.741824,-119.208946,0.075137,0.000000
76.910004,12.926910,-119.208946,0.023476,0.002944,0.074790,57.501770,2.929280,0.747895,-119.208946,0.075640,0.000000
77.210007,12.859138,-119.297913,0.023498,0.002963,0.075266,57.200306,2.913922,0.752664,-119.297913,0.076134,0.000000
77.510002,12.802544,-119.253433,0.023515,0.002979,0.075665,56.948559,2.901098,0.756653,-119.253433,0.076637,0.000000
77.810005,13.304123,-119.253433,0.023532,0.003003,0.076272,59.179695,3.014757,0.762724,-119.253433,0.077140,0.000000
78.110001,13.241943,-119.253433,0.023550,0.003017,0.076637,58.903107,3.000667,0.766369,-119.253433,0.077634,0.000000
78.410004,13.827682,-119.253433,0.023567,0.003040,0.077227,61.508602,3.133398,0.772266,-119.253433,0.078137,0.000000
78.710007,14.156860,-119.253433,0.023601,0.003062,0.077764,62.972858,3.207990,0.777641,-119.253433,0.078640,0.000000
79.010002,14.246605,-119.208946,0.023631,0.003082,0.078276,63.372063,3.228327,0.782758,-119.208946,0.079134,0.000000
79.310005,14.609291,-119.208946,0.023653,0.003102,0.078788,64.985374,3.310513,0.787875,-119.208946,0.079637,0.000000
79.610001,14.941818,-119.253433,0.023666,0.003122,0.079291,66.464523,3.385864,0.792905,-119.253433,0.080140,0.000000
79.910004,15.256477,-119.297913,0.023675,0.003140,0.079767,67.864204,3.457167,0.797674,-119.297913,0.080635,0.000000
80.210007,15.115715,-119.297913,0.023696,0.003153,0.080080,67.238060,3.425270,0.800797,-119.297913,0.081138,0.000000
80.510002,16.001595,-119.342392,0.023713,0.003180,0.080773,71.178650,3.626013,0.807734,-119.342392,0.081641,0.000000
80.810005,16.489403,-119.297913,0.023735,0.003202,0.081320,73.348526,3.736552,0.813200,-119.297913,0.082135,0.000000
81.110001,16.605949,-119.253433,0.023739,0.003218,0.081745,73.866951,3.762962,0.817446,-119.253433,0.082638,0.000000
81.410004,16.839432,-119.297913,0.023774,0.003235,0.082170,74.905533,3.815870,0.821697,-119.297913,0.083141,0.000000
81.710007,17.773338,-119.342392,0.023795,0.003258,0.082751,79.059761,4.027496,0.827507,-119.342392,0.083635,0.000000
82.010002,17.613968,-119.342392,0.023808,0.003269,0.083028,78.350845,3.991382,0.830281,-119.342392,0.084138,0.000000
82.310005,19.018555,-119.342392,0.023813,0.003299,0.083800,84.598755,4.309666,0.838002,-119.342392,0.084641,0.000000
82.610001,19.589775,-119.386871,0.023843,0.003320,0.084320,87.139671,4.439106,0.843203,-119.386871,0.085136,0.000000
82.910004,19.747284,-119.386871,0.023851,0.003337,0.084771,87.840309,4.474799,0.847714,-119.386871,0.085639,0.000000
83.210007,20.073112,-119.386871,0.023873,0.003353,0.085162,89.289665,4.548632,0.851617,-119.386871,0.086142,0.000000
83.510002,20.623482,-119.431351,0.023894,0.003372,0.085639,91.737831,4.673348,0.856385,-119.431351,0.086636,0.000000
83.810005,21.489990,-119.386871,0.023890,0.003393,0.086194,95.592247,4.869701,0.861938,-119.386871,0.087139,0.000000
84.110001,22.072006,-119.431351,0.023920,0.003410,0.086618,98.181190,5.001588,0.866185,-119.431351,0.087642,0.000000
84.410004,23.201042,-119.342392,0.023929,0.003434,0.087217,103.203392,5.257431,0.872168,-119.342392,0.088136,0.000000
84.710007,23.526497,-119.475838,0.023950,0.003449,0.087616,104.651085,5.331181,0.876158,-119.475838,0.088639,0.000000
85.010002,24.657021,-119.475838,0.023955,0.003474,0.088232,109.679909,5.587360,0.882316,-119.475838,0.089142,0.000000
85.310005,24.728142,-119.431351,0.023959,0.003486,0.088544,109.996269,5.603477,0.885438,-119.431351,0.089637,0.000000
85.610001,25.795364,-119.431351,0.023976,0.003506,0.089064,114.743515,5.845313,0.890643,-119.431351,0.090140,0.000000
85.910004,26.616814,-119.431351,0.023989,0.003524,0.089515,118.397499,6.031456,0.895150,-119.431351,0.090634,0.000000
86.210007,27.161964,-119.475838,0.024007,0.003540,0.089923,120.822449,6.154989,0.899227,-119.475838,0.091137,0.000000
86.510002,29.058464,-119.431351,0.024011,0.003568,0.090634,129.258499,6.584742,0.906339,-119.431351,0.091640,0.000000
86.810005,29.797989,-119.475838,0.024024,0.003587,0.091111,132.548080,6.752321,0.911107,-119.475838,0.092134,0.000000
87.110001,30.822014,-119.475838,0.024041,0.003607,0.091622,137.103165,6.984368,0.916225,-119.475838,0.092637,0.000000
87.410004,31.795029,-119.475838,0.024045,0.003628,0.092143,141.431351,7.204856,0.921429,-119.475838,0.093140,0.000000
87.710007,32.849213,-119.520317,0.024071,0.003646,0.092620,146.120590,7.443738,0.926198,-119.520317,0.093635,0.000000
88.010002,33.416710,-119.475838,0.024063,0.003661,0.092993,148.644943,7.572335,0.929926,-119.475838,0.094138,0.000000
88.310005,35.009346,-119.564796,0.024088,0.003686,0.093617,155.729355,7.933231,0.936171,-119.564796,0.094641,0.000000
88.610001,36.416542,-119.520317,0.024093,0.003707,0.094155,161.988876,8.252106,0.941546,-119.520317,0.095135,0.000000
88.910004,37.369438,-119.564796,0.024106,0.003725,0.094614,166.227570,8.468036,0.946144,-119.564796,0.095638,0.000000
89.210007,38.574814,-119.564796,0.024106,0.003744,0.095091,171.589340,8.741178,0.950913,-119.564796,0.096141,0.000000
89.510002,39.650597,-119.520317,0.024123,0.003763,0.095568,176.374664,8.984954,0.955682,-119.520317,0.096635,0.000000
89.810005,40.645950,-119.609276,0.024140,0.003778,0.095950,180.802216,9.210505,0.959497,-119.609276,0.097138,0.000000
90.110001,41.617096,-119.520317,0.024132,0.003794,0.096357,185.122086,9.430569,0.963574,-119.520317,0.097641,0.000000
90.410004,44.610970,-119.564796,0.024144,0.003829,0.097268,198.439499,10.108990,0.972680,-119.564796,0.098135,0.000000
90.710007,45.453651,-119.564796,0.024166,0.003846,0.097684,202.187943,10.299945,0.976844,-119.564796,0.098638,0.000000
91.010002,46.509323,-119.564796,0.024170,0.003861,0.098057,206.883804,10.539164,0.980572,-119.564796,0.099141,0.000000
91.310005,48.201012,-119.609276,0.024175,0.003884,0.098656,214.408813,10.922504,0.986556,-119.609276,0.099635,0.000000
91.610001,49.513252,-119.698242,0.024179,0.003901,0.099098,220.245941,11.219864,0.990980,-119.698242,0.100138,0.000000
91.910004,50.771500,-119.653755,0.024196,0.003918,0.099523,225.842911,11.504986,0.995231,-119.653755,0.100641,0.000000
92.210007,52.807259,-119.653755,0.024209,0.003943,0.100156,234.898422,11.966295,1.001559,-119.653755,0.101136,0.000000
92.510002,54.042046,-119.653755,0.024209,0.003962,0.100633,240.391022,12.246103,1.006328,-119.653755,0.101639,0.000000
92.810005,55.603775,-119.653755,0.024213,0.003982,0.101136,247.337952,12.599996,1.011358,-119.653755,0.102142,0.000000
93.110001,57.262321,-119.698242,0.024226,0.004004,0.101691,254.715530,12.975827,1.016910,-119.698242,0.102636,0.000000
93.410004,58.830009,-119.742722,0.024213,0.004022,0.102168,261.688965,13.331070,1.021679,-119.742722,0.103139,0.000000
93.710007,60.155655,-119.698242,0.024222,0.004037,0.102541,267.585724,13.631466,1.025408,-119.698242,0.103642,0.000000
94.010002,61.899849,-119.698242,0.024235,0.004058,0.103061,275.344269,14.026707,1.030612,-119.698242,0.104136,0.000000
94.310005,64.121422,-119.698242,0.024239,0.004082,0.103694,285.226318,14.530122,1.036944,-119.698242,0.104639,0.000000
94.610008,65.384132,-119.698242,0.024248,0.004100,0.104128,290.843140,14.816257,1.041278,-119.698242,0.105142,0.000000
94.910004,66.951088,-119.742722,0.024248,0.004117,0.104562,297.813324,15.171333,1.045615,-119.742722,0.105637,0.000000
95.210007,67.142860,-119.742722,0.024261,0.004115,0.104527,298.666351,15.214790,1.045267,-119.742722,0.104744,0.000000
95.510002,66.735100,-119.653755,0.024265,0.004113,0.104475,296.852539,15.122390,1.044748,-119.653755,0.104527,0.000000
95.810005,66.350441,-119.698242,0.024265,0.004112,0.104440,295.141510,15.035225,1.044400,-119.698242,0.104527,0.000000
96.110008,66.035789,-119.698242,0.024261,0.004111,0.104431,293.741852,14.963923,1.044313,-119.698242,0.104527,0.000000
96.410004,65.760231,-119.742722,0.024270,0.004111,0.104423,292.516113,14.901482,1.044226,-119.742722,0.104527,0.000000
96.710007,65.538307,-119.742722,0.024282,0.004111,0.104414,291.528961,14.851192,1.044139,-119.742722,0.104527,0.000000
97.010002,65.334618,-119.742722,0.024278,0.004111,0.104414,290.622894,14.805036,1.044139,-119.742722,0.104527,0.000000
97.310005,65.133156,-119.787201,0.024274,0.004110,0.104405,289.726746,14.759384,1.044052,-119.787201,0.104527,0.000000
97.610008,64.970802,-119.787201,0.024274,0.004110,0.104405,289.004578,14.722594,1.044052,-119.787201,0.104527,0.000000
97.910004,64.816643,-119.831680,0.024282,0.004110,0.104405,288.318817,14.687661,1.044052,-119.831680,0.104527,0.000000
98.210007,64.690407,-119.742722,0.024274,0.004110,0.104405,287.757294,14.659056,1.044052,-119.742722,0.104527,0.000000
98.510002,64.560829,-119.831680,0.024278,0.004110,0.104405,287.180908,14.629693,1.044052,-119.831680,0.104527,0.000000
98.810005,64.459908,-119.831680,0.024274,0.004110,0.104397,286.731995,14.606823,1.043969,-119.831680,0.104527,0.000000
99.110008,64.340385,-119.876160,0.024282,0.004110,0.104397,286.200317,14.579740,1.043969,-119.876160,0.104527,0.000000
99.410004,64.246544,-119.787201,0.024278,0.004110,0.104397,285.782898,14.558475,1.043969,-119.787201,0.104527,0.000000
99.710007,64.155678,-119.831680,0.024274,0.004110,0.104397,285.378693,14.537885,1.043969,-119.831680,0.104527,0.000000
100.010002,64.058495,-119.787201,0.024278,0.004110,0.104397,284.946411,14.515862,1.043969,-119.787201,0.104527,0.000000
100.310005,63.982155,-119.876160,0.024282,0.004110,0.104397,284.606842,14.498564,1.043969,-119.876160,0.104527,0.000000
100.610008,63.904701,-119.920647,0.024278,0.004110,0.104397,284.262299,14.481012,1.043969,-119.920647,0.104527,0.000000
100.910004,63.829109,-119.831680,0.024278,0.004110,0.104397,283.926056,14.463882,1.043969,-119.831680,0.104527,0.000000
101.210007,63.746452,-119.876160,0.024282,0.004110,0.104397,283.558380,14.445152,1.043969,-119.876160,0.104527,0.000000
101.510002,63.680901,-119.831680,0.024291,0.004110,0.104397,283.266785,14.430298,1.043969,-119.831680,0.104527,0.000000
101.810005,63.618721,-119.831680,0.024278,0.004110,0.104397,282.990204,14.416208,1.043969,-119.831680,0.104527,0.000000
102.110008,63.563606,-119.920647,0.024287,0.004110,0.104397,282.745056,14.403719,1.043969,-119.920647,0.104527,0.000000
102.410004,63.493980,-119.876160,0.024282,0.004110,0.104397,282.435333,14.387942,1.043969,-119.876160,0.104527,0.000000
102.710007,63.431038,-119.920647,0.024282,0.004110,0.104397,282.155334,14.373679,1.043969,-119.920647,0.104527,0.000000
103.010002,63.384132,-119.965126,0.024278,0.004110,0.104397,281.946716,14.363050,1.043969,-119.965126,0.104527,0.000000
103.310005,63.323799,-119.920647,0.024282,0.004110,0.104397,281.678314,14.349378,1.043969,-119.920647,0.104527,0.000000
103.610008,63.257515,-120.009605,0.024304,0.004110,0.104397,281.383484,14.334357,1.043969,-120.009605,0.104527,0.000000
103.910004,63.233315,-119.965126,0.024287,0.004110,0.104397,281.275818,14.328875,1.043969,-119.965126,0.104527,0.000000
104.210007,63.182671,-119.965126,0.024295,0.004110,0.104397,281.050568,14.317398,1.043969,-119.965126,0.104527,0.000000
104.510002,63.119743,-119.965126,0.024295,0.004110,0.104397,280.770630,14.303139,1.043969,-119.965126,0.104527,0.000000
104.810005,63.092186,-120.009605,0.024287,0.004110,0.104397,280.648071,14.296894,1.043969,-120.009605,0.104527,0.000000
105.110008,63.039680,-120.009605,0.024295,0.004110,0.104397,280.414490,14.284995,1.043969,-120.009605,0.104527,0.000000
105.410004,63.000954,-119.965126,0.024282,0.004110,0.104397,280.242249,14.276220,1.043969,-119.965126,0.104527,0.000000
105.710007,62.959251,-120.098564,0.024291,0.004110,0.104397,280.056732,14.266770,1.043969,-120.098564,0.104527,0.000000
106.010002,62.923874,-120.009605,0.024278,0.004110,0.104397,279.899384,14.258754,1.043969,-120.009605,0.104527,0.000000
106.310005,62.884033,-120.009605,0.024291,0.004110,0.104397,279.722137,14.249725,1.043969,-120.009605,0.104527,0.000000
106.610008,62.853127,-120.009605,0.024304,0.004110,0.104397,279.584656,14.242722,1.043969,-120.009605,0.104527,0.000000
106.910004,62.824448,-120.054085,0.024300,0.004110,0.104397,279.457092,14.236223,1.043969,-120.054085,0.104527,0.000000
107.210007,62.781258,-120.009605,0.024291,0.004110,0.104397,279.264984,14.226436,1.043969,-120.009605,0.104527,0.000000
107.510002,62.757423,-120.054085,0.024295,0.004110,0.104397,279.158966,14.221035,1.043969,-120.054085,0.104527,0.000000
107.810005,62.714973,-120.098564,0.024295,0.004110,0.104397,278.970123,14.211416,1.043969,-120.098564,0.104527,0.000000
108.110008,62.694862,-120.098564,0.024291,0.004110,0.104397,278.880676,14.206859,1.043969,-120.098564,0.104527,0.000000
108.410004,62.650551,-120.098564,0.024295,0.004110,0.104397,278.683563,14.196817,1.043969,-120.098564,0.104527,0.000000
108.710007,62.629326,-120.098564,0.024295,0.004110,0.104397,278.589142,14.192008,1.043969,-120.098564,0.104527,0.000000
109.010002,62.600281,-120.143051,0.024295,0.004110,0.104397,278.459961,14.185426,1.043969,-120.143051,0.104527,0.000000
109.310005,62.585762,-120.098564,0.024291,0.004110,0.104397,278.395386,14.182137,1.043969,-120.098564,0.104527,0.000000
109.610008,62.546661,-120.054085,0.024300,0.004110,0.104397,278.221436,14.173277,1.043969,-120.054085,0.104527,0.000000
109.910004,62.516502,-120.054085,0.024291,0.004110,0.104397,278.087280,14.166442,1.043969,-120.054085,0.104527,0.000000
110.210007,62.502350,-120.187531,0.024300,0.004110,0.104397,278.024323,14.163235,1.043969,-120.187531,0.104527,0.000000
110.510002,62.468834,-120.143051,0.024282,0.004110,0.104397,277.875244,14.155640,1.043969,-120.143051,0.104527,0.000000
110.810005,62.448357,-120.187531,0.024291,0.004110,0.104397,277.784149,14.151000,1.043969,-120.187531,0.104527,0.000000
111.110008,62.423409,-120.187531,0.024291,0.004110,0.104397,277.673187,14.145347,1.043969,-120.187531,0.104527,0.000000
111.410004,62.405907,-120.187531,0.024295,0.004110,0.104388,277.595337,14.141380,1.043882,-120.187531,0.104527,0.000000
111.710007,62.373138,-120.187531,0.024300,0.004110,0.104388,277.449585,14.133955,1.043882,-120.187531,0.104527,0.000000
112.010002,62.346321,-120.232010,0.024291,0.004110,0.104388,277.330292,14.127878,1.043882,-120.232010,0.104527,0.000000
112.310005,62.334412,-120.187531,0.024287,0.004110,0.104388,277.277313,14.125180,1.043882,-120.187531,0.104527,0.000000
112.610008,62.311325,-120.232010,0.024287,0.004110,0.104388,277.174622,14.119948,1.043882,-120.232010,0.104527,0.000000
112.910004,62.281532,-120.276489,0.024300,0.004110,0.104388,277.042084,14.113197,1.043882,-120.276489,0.104527,0.000000
113.210007,62.259560,-120.232010,0.024300,0.004110,0.104388,276.944366,14.108218,1.043882,-120.232010,0.104527,0.000000
113.510002,62.241318,-120.232010,0.024300,0.004110,0.104388,276.863220,14.104084,1.043882,-120.232010,0.104527,0.000000
113.810005,62.220833,-120.276489,0.024295,0.004110,0.104388,276.772095,14.099442,1.043882,-120.276489,0.104527,0.000000
114.110008,62.199234,-120.276489,0.024291,0.004110,0.104388,276.676025,14.094547,1.043882,-120.276489,0.104527,0.000000
114.410004,62.185089,-120.276489,0.024295,0.004110,0.104388,276.613098,14.091343,1.043882,-120.276489,0.104527,0.000000
114.710007,62.172050,-120.276489,0.024304,0.004110,0.104388,276.555084,14.088388,1.043882,-120.276489,0.104527,0.000000
115.010002,62.137794,-120.320976,0.024295,0.004110,0.104388,276.402710,14.080626,1.043882,-120.320976,0.104527,0.000000
115.310005,62.120667,-120.276489,0.024291,0.004110,0.104388,276.326538,14.076744,1.043882,-120.276489,0.104527,0.000000
115.610008,62.096092,-120.320976,0.024308,0.004110,0.104388,276.217224,14.071176,1.043882,-120.320976,0.104527,0.000000
115.910004,62.085663,-120.320976,0.024291,0.004110,0.104388,276.170807,14.068812,1.043882,-120.320976,0.104527,0.000000
116.210007,62.079330,-120.365456,0.024313,0.004110,0.104388,276.142639,14.067378,1.043882,-120.365456,0.104527,0.000000
116.510002,62.048058,-120.365456,0.024295,0.004110,0.104388,276.003540,14.060291,1.043882,-120.365456,0.104527,0.000000
116.810005,62.035767,-120.320976,0.024300,0.004110,0.104388,275.948883,14.057506,1.043882,-120.320976,0.104527,0.000000
117.110008,62.017891,-120.320976,0.024300,0.004110,0.104388,275.869354,14.053455,1.043882,-120.320976,0.104527,0.000000
117.410004,62.003372,-120.320976,0.024304,0.004110,0.104388,275.804779,14.050165,1.043882,-120.320976,0.104527,0.000000
117.710007,61.981773,-120.365456,0.024300,0.004110,0.104388,275.708710,14.045271,1.043882,-120.365456,0.104527,0.000000
118.010002,61.971344,-120.365456,0.024295,0.004110,0.104388,275.662292,14.042907,1.043882,-120.365456,0.104527,0.000000
118.310005,61.944908,-120.409935,0.024295,0.004110,0.104388,275.544708,14.036917,1.043882,-120.409935,0.104527,0.000000
118.610008,61.931503,-120.365456,0.024295,0.004110,0.104388,275.485077,14.033879,1.043882,-120.365456,0.104527,0.000000
118.910004,61.911766,-120.454414,0.024287,0.004110,0.104388,275.397278,14.029407,1.043882,-120.454414,0.104527,0.000000
119.210007,61.900597,-120.498894,0.024300,0.004110,0.104388,275.347595,14.026875,1.043882,-120.498894,0.104527,0.000000
119.510002,61.884956,-120.454414,0.024295,0.004110,0.104388,275.278046,14.023332,1.043882,-120.454414,0.104527,0.000000
119.810005,61.873787,-120.498894,0.024300,0.004110,0.104388,275.228363,14.020801,1.043882,-120.498894,0.104527,0.000000
120.110008,61.860008,-120.454414,0.024304,0.004110,0.104388,275.167053,14.017678,1.043882,-120.454414,0.104527,0.000000
120.410004,61.837288,-120.498894,0.024291,0.004110,0.104388,275.066010,14.012529,1.043882,-120.498894,0.104527,0.000000
120.710007,61.819420,-120.543381,0.024304,0.004110,0.104388,274.986511,14.008481,1.043882,-120.543381,0.104527,0.000000
121.010002,61.813087,-120.543381,0.024304,0.004110,0.104388,274.958344,14.007047,1.043882,-120.543381,0.104527,0.000000
121.310005,61.798561,-120.498894,0.024295,0.004110,0.104388,274.893738,14.003755,1.043882,-120.498894,0.104527,0.000000
121.610008,61.770638,-120.498894,0.024287,0.004110,0.104388,274.769531,13.997427,1.043882,-120.498894,0.104527,0.000000
121.910004,61.756859,-120.498894,0.024300,0.004110,0.104388,274.708221,13.994304,1.043882,-120.498894,0.104527,0.000000
122.210007,61.758720,-120.543381,0.024291,0.004110,0.104388,274.716522,13.994726,1.043882,-120.543381,0.104527,0.000000
122.510002,61.737495,-120.543381,0.024291,0.004110,0.104388,274.622101,13.989916,1.043882,-120.543381,0.104527,0.000000
122.810005,61.717018,-120.543381,0.024291,0.004110,0.104388,274.531006,13.985276,1.043882,-120.543381,0.104527,0.000000
123.110008,61.716270,-120.632339,0.024304,0.004110,0.104388,274.527679,13.985106,1.043882,-120.632339,0.104527,0.000000
123.410004,61.696159,-120.587860,0.024291,0.004110,0.104388,274.438232,13.980549,1.043882,-120.587860,0.104527,0.000000
123.710007,61.673820,-120.543381,0.024295,0.004110,0.104388,274.338867,13.975488,1.043882,-120.543381,0.104527,0.000000
124.010002,61.653336,-120.587860,0.024295,0.004110,0.104388,274.247742,13.970845,1.043882,-120.587860,0.104527,0.000000
124.310005,61.656693,-120.587860,0.024300,0.004110,0.104388,274.262665,13.971606,1.043882,-120.587860,0.104527,0.000000
124.610008,61.650360,-120.632339,0.024295,0.004110,0.104388,274.234497,13.970172,1.043882,-120.632339,0.104527,0.000000
124.910004,61.636208,-120.632339,0.024304,0.004110,0.104388,274.171539,13.966964,1.043882,-120.632339,0.104527,0.000000
125.210007,61.623550,-120.632339,0.024287,0.004110,0.104388,274.115234,13.964096,1.043882,-120.632339,0.104527,0.000000
125.500008,61.605301,-120.543381,0.024300,0.004110,0.104388,274.034058,13.959961,1.043882,-120.543381,0.104527,0.000000