File: Data/compression 6/AutoNoheating-10-6-day2-4-240229_02292024_170638.csv
Time (sec),S:Load (lbs),S:HL1 (DIM),S:LVDT (in),S:Position (in),Ch:Position (mm),Ch:Load (N),Ch:Stress (MPa),Ch:Strain (mm/mm),Ch:HL1 (DIM),Set Point (),Cycles ()
0.010000,-0.014893,-84.069000,-0.010999,-0.012739,-0.323571,-0.066245,-0.003375,-3.235707,-84.069000,-0.323744,0.000000
0.320000,-0.018990,-84.113480,-0.010994,-0.012739,-0.323571,-0.084470,-0.004303,-3.235707,-84.113480,-0.323744,0.000000
0.630000,-0.028671,-84.157959,-0.011012,-0.012579,-0.319503,-0.127536,-0.006497,-3.195034,-84.157959,-0.318732,0.000000
0.940000,0.002235,-84.157959,-0.010835,-0.012383,-0.314526,0.009944,0.000507,-3.145255,-84.157959,-0.313563,0.000000
1.250000,-0.023834,-84.113480,-0.010645,-0.012178,-0.309331,-0.106020,-0.005401,-3.093311,-84.113480,-0.308395,0.000000
1.560000,-0.043198,-84.113480,-0.010438,-0.011981,-0.304318,-0.192153,-0.009789,-3.043184,-84.113480,-0.303226,0.000000
1.870000,-0.007820,-84.157959,-0.010244,-0.011785,-0.299341,-0.034786,-0.001772,-2.993405,-84.157959,-0.298074,0.000000
2.180000,-0.066284,-84.202438,-0.010042,-0.011575,-0.294007,-0.294847,-0.015020,-2.940068,-84.202438,-0.292905,0.000000
2.490000,-0.036491,-84.202438,-0.009817,-0.011369,-0.288760,-0.162322,-0.008269,-2.887602,-84.202438,-0.287737,0.000000
2.800000,-0.017128,-84.202438,-0.009606,-0.011166,-0.283609,-0.076189,-0.003881,-2.836090,-84.202438,-0.282568,0.000000
3.110000,-0.033516,-84.113480,-0.009412,-0.010963,-0.278458,-0.149086,-0.007595,-2.784578,-84.113480,-0.277399,0.000000
3.420000,-0.000374,-84.202438,-0.009201,-0.010762,-0.273350,-0.001663,-0.000085,-2.733497,-84.202438,-0.272248,0.000000
3.730000,-0.016380,-84.202438,-0.009020,-0.010561,-0.268242,-0.072863,-0.003712,-2.682416,-84.202438,-0.267080,0.000000
4.040000,-0.007446,-84.246918,-0.008795,-0.010352,-0.262952,-0.033123,-0.001687,-2.629518,-84.246918,-0.261911,0.000000
4.350000,-0.021973,-84.202438,-0.008597,-0.010148,-0.257766,-0.097739,-0.004979,-2.577657,-84.202438,-0.256742,0.000000
4.660000,-0.055855,-84.202438,-0.008399,-0.009945,-0.252606,-0.248455,-0.012657,-2.526062,-84.202438,-0.251591,0.000000
4.970000,0.022346,-84.246918,-0.008183,-0.009751,-0.247671,0.099402,0.005064,-2.476714,-84.246918,-0.246422,0.000000
5.280000,-0.021973,-84.291405,-0.007976,-0.009540,-0.242312,-0.097739,-0.004979,-2.423120,-84.291405,-0.241254,0.000000
5.590000,0.012291,-84.291405,-0.007774,-0.009336,-0.237126,0.054673,0.002785,-2.371259,-84.291405,-0.236085,0.000000
5.900000,-0.013779,-84.335884,-0.007567,-0.009135,-0.232018,-0.061291,-0.003122,-2.320179,-84.335884,-0.230934,0.000000
6.210001,-0.046921,-84.202438,-0.007377,-0.008931,-0.226841,-0.208714,-0.010632,-2.268409,-84.202438,-0.225765,0.000000
6.520000,0.005211,-84.246918,-0.007170,-0.008732,-0.221793,0.023179,0.001181,-2.217933,-84.246918,-0.220597,0.000000
6.830000,-0.042076,-84.335884,-0.006963,-0.008525,-0.216547,-0.187164,-0.009535,-2.165467,-84.335884,-0.215428,0.000000
7.140000,0.010429,-84.291405,-0.006743,-0.008318,-0.211274,0.046392,0.002363,-2.112736,-84.291405,-0.210277,0.000000
7.450000,-0.001488,-84.380363,-0.006536,-0.008115,-0.206114,-0.006618,-0.000337,-2.061140,-84.380363,-0.205108,0.000000
7.760000,-0.005585,-84.291405,-0.006321,-0.007913,-0.200989,-0.024842,-0.001266,-2.009885,-84.291405,-0.199939,0.000000
8.070001,0.012665,-84.335884,-0.006135,-0.007719,-0.196054,0.056336,0.002870,-1.960538,-84.335884,-0.194771,0.000000
8.380000,-0.033142,-84.335884,-0.005920,-0.007516,-0.190894,-0.147423,-0.007510,-1.908942,-84.335884,-0.189619,0.000000
8.690001,-0.010056,-84.246918,-0.005708,-0.007307,-0.185586,-0.044729,-0.002279,-1.855863,-84.246918,-0.184451,0.000000
9.000000,-0.000740,-84.424843,-0.005506,-0.007099,-0.180305,-0.003292,-0.000168,-1.803048,-84.424843,-0.179282,0.000000
9.310000,-0.023087,-84.291405,-0.005299,-0.006895,-0.175136,-0.102694,-0.005231,-1.751362,-84.291405,-0.174113,0.000000
9.620001,0.032768,-84.380363,-0.005092,-0.006693,-0.169994,0.145760,0.007425,-1.699940,-84.380363,-0.168945,0.000000
9.930000,0.014526,-84.380363,-0.004915,-0.006492,-0.164894,0.064617,0.003292,-1.648942,-84.380363,-0.163793,0.000000
10.240001,0.005959,-84.380363,-0.004687,-0.006285,-0.159639,0.026505,0.001350,-1.596393,-84.380363,-0.158624,0.000000
10.550000,-0.001114,-84.469330,-0.004501,-0.006089,-0.154670,-0.004955,-0.000252,-1.546697,-84.469330,-0.153456,0.000000
10.860001,-0.055107,-84.380363,-0.004286,-0.005879,-0.149337,-0.245129,-0.012487,-1.493368,-84.380363,-0.148287,0.000000
11.170000,0.045433,-84.424843,-0.004074,-0.005681,-0.144298,0.202096,0.010295,-1.442976,-84.424843,-0.143136,0.000000
11.480000,0.007820,-84.380363,-0.003880,-0.005475,-0.139077,0.034786,0.001772,-1.390775,-84.380363,-0.137967,0.000000
11.790001,0.046921,-84.424843,-0.003660,-0.005268,-0.133804,0.208714,0.010632,-1.338044,-84.424843,-0.132798,0.000000
12.100000,0.021599,-84.469330,-0.003471,-0.005065,-0.128653,0.096076,0.004894,-1.286531,-84.469330,-0.127630,0.000000
12.410001,-0.004471,-84.424843,-0.003251,-0.004863,-0.123519,-0.019887,-0.001013,-1.235193,-84.424843,-0.122478,0.000000
12.720000,0.017502,-84.513809,-0.003065,-0.004669,-0.118594,0.077852,0.003966,-1.185936,-84.513809,-0.117310,0.000000
13.030001,-0.032768,-84.513809,-0.002859,-0.004460,-0.113295,-0.145760,-0.007425,-1.132948,-84.513809,-0.112141,0.000000
13.340001,0.043938,-84.513809,-0.002652,-0.004254,-0.108048,0.195445,0.009956,-1.080482,-84.513809,-0.106972,0.000000
13.650001,0.037613,-84.558289,-0.002445,-0.004051,-0.102905,0.167311,0.008523,-1.029052,-84.558289,-0.101821,0.000000
13.960001,0.029045,-84.513809,-0.002238,-0.003847,-0.097711,0.129199,0.006582,-0.977108,-84.513809,-0.096653,0.000000
14.270000,0.098305,-84.513809,-0.002026,-0.003648,-0.092655,0.437281,0.022276,-0.926550,-84.513809,-0.091484,0.000000
14.580001,0.129585,-84.513809,-0.001811,-0.003443,-0.087460,0.576424,0.029364,-0.874598,-84.513809,-0.086315,0.000000
14.890000,0.301994,-84.513809,-0.001600,-0.003239,-0.082283,1.343338,0.068433,-0.822829,-84.513809,-0.081164,0.000000
15.200001,0.554092,-84.558289,-0.001414,-0.003036,-0.077105,2.464726,0.125559,-0.771051,-84.558289,-0.075995,0.000000
15.510001,0.572708,-84.558289,-0.001311,-0.000007,-0.000173,2.547533,0.129778,-0.001733,-84.558289,-0.000026,0.000000
15.820001,0.527649,-84.647247,-0.001311,-0.000007,-0.000182,2.347100,0.119567,-0.001824,-84.647247,-0.000026,0.000000
16.130001,0.518341,-84.558289,-0.001311,-0.000007,-0.000182,2.305696,0.117458,-0.001824,-84.558289,0.000477,0.000000
16.440001,0.490791,-84.558289,-0.001302,-0.000007,-0.000182,2.183149,0.111215,-0.001824,-84.558289,0.000989,0.000000
16.750000,0.549995,-84.647247,-0.001293,0.000018,0.000468,2.446502,0.124631,0.004678,-84.647247,0.001509,0.000000
17.060001,0.697830,-84.558289,-0.001272,0.000046,0.001162,3.104104,0.158131,0.011620,-84.558289,0.002029,0.000000
17.370001,0.747353,-84.647247,-0.001259,0.000065,0.001639,3.324390,0.169353,0.016389,-84.647247,0.002540,0.000000
17.680000,0.764481,-84.602768,-0.001250,0.000083,0.002107,3.400579,0.173234,0.021074,-84.602768,0.003061,0.000000
17.990002,0.822197,-84.602768,-0.001203,0.000106,0.002688,3.657315,0.186312,0.026880,-84.602768,0.003573,0.000000
18.300001,0.834862,-84.647247,-0.001194,0.000122,0.003096,3.713650,0.189182,0.030960,-84.647247,0.004093,0.000000
18.610001,0.889595,-84.602768,-0.001164,0.000147,0.003737,3.957116,0.201585,0.037372,-84.602768,0.004614,0.000000
18.920000,0.910080,-84.647247,-0.001143,0.000170,0.004310,4.048238,0.206227,0.043102,-84.647247,0.005125,0.000000
19.230001,0.959236,-84.602768,-0.001125,0.000188,0.004778,4.266895,0.217366,0.047781,-84.602768,0.005646,0.000000
19.540001,1.015457,-84.691734,-0.001104,0.000204,0.005177,4.516979,0.230106,0.051770,-84.691734,0.006157,0.000000
19.850000,1.078018,-84.647247,-0.001087,0.000231,0.005862,4.795264,0.244282,0.058620,-84.647247,0.006677,0.000000
20.160002,1.097382,-84.736214,-0.001052,0.000248,0.006296,4.881397,0.248670,0.062958,-84.736214,0.007189,0.000000
20.470001,1.116005,-84.691734,-0.001030,0.000268,0.006816,4.964238,0.252890,0.068158,-84.691734,0.007709,0.000000
20.780001,1.168877,-84.647247,-0.001013,0.000288,0.007310,5.199423,0.264871,0.073101,-84.647247,0.008230,0.000000
21.090000,1.245216,-84.736214,-0.000987,0.000308,0.007822,5.538999,0.282170,0.078219,-84.736214,0.008742,0.000000
21.400002,1.273514,-84.780693,-0.000974,0.000325,0.008247,5.664872,0.288582,0.082473,-84.780693,0.009262,0.000000
21.710001,1.368843,-84.736214,-0.000961,0.000349,0.008863,6.088918,0.310184,0.088627,-84.736214,0.009773,0.000000
22.020000,1.428047,-84.780693,-0.000923,0.000374,0.009505,6.352271,0.323600,0.095046,-84.780693,0.010293,0.000000
22.330002,1.396767,-84.736214,-0.000905,0.000388,0.009851,6.213129,0.316512,0.098513,-84.736214,0.010814,0.000000
22.640001,1.471619,-84.780693,-0.000875,0.000409,0.010390,6.546087,0.333474,0.103895,-84.780693,0.011326,0.000000
22.950001,1.549446,-84.780693,-0.000867,0.000430,0.010927,6.892281,0.351110,0.109270,-84.780693,0.011846,0.000000
23.260000,1.567688,-84.736214,-0.000854,0.000447,0.011361,6.973424,0.355243,0.113607,-84.736214,0.012358,0.000000
23.570002,1.685356,-84.780693,-0.000828,0.000472,0.011976,7.496839,0.381907,0.119762,-84.780693,0.012878,0.000000
23.880001,1.753502,-84.780693,-0.000798,0.000493,0.012523,7.799966,0.397349,0.125227,-84.780693,0.013389,0.000000
24.190001,1.767281,-84.825172,-0.000767,0.000512,0.013017,7.861257,0.400472,0.130170,-84.825172,0.013910,0.000000
24.500002,1.849571,-84.825172,-0.000750,0.000534,0.013554,8.227304,0.419119,0.135545,-84.825172,0.014430,0.000000
24.810001,1.945648,-84.780693,-0.000724,0.000557,0.014136,8.654675,0.440890,0.141358,-84.780693,0.014942,0.000000
25.120001,1.988472,-84.825172,-0.000711,0.000574,0.014578,8.845165,0.450594,0.145779,-84.825172,0.015463,0.000000
25.430000,2.020119,-84.825172,-0.000694,0.000591,0.015012,8.985937,0.457765,0.150117,-84.825172,0.015974,0.000000
25.740002,2.134438,-84.825172,-0.000660,0.000614,0.015601,9.494452,0.483670,0.156013,-84.825172,0.016495,0.000000
26.050001,2.159019,-84.869652,-0.000647,0.000633,0.016087,9.603798,0.489241,0.160866,-84.869652,0.017006,0.000000
26.360001,2.239075,-84.825172,-0.000621,0.000656,0.016651,9.959902,0.507382,0.166505,-84.825172,0.017526,0.000000
26.670002,2.344460,-84.869652,-0.000608,0.000677,0.017197,10.428677,0.531262,0.171970,-84.869652,0.018047,0.000000
26.980001,2.413719,-84.869652,-0.000578,0.000697,0.017700,10.736759,0.546957,0.176997,-84.869652,0.018558,0.000000
27.290001,2.405899,-84.914139,-0.000573,0.000711,0.018064,10.701974,0.545185,0.180638,-84.914139,0.019079,0.000000
27.600000,2.582779,-84.914139,-0.000539,0.000739,0.018766,11.488774,0.585266,0.187663,-84.914139,0.019591,0.000000
27.910002,2.554474,-84.869652,-0.000522,0.000754,0.019157,11.362867,0.578852,0.191569,-84.869652,0.020111,0.000000
28.220001,2.633789,-84.958618,-0.000500,0.000776,0.019703,11.715679,0.596825,0.197034,-84.958618,0.020631,0.000000
28.530001,2.675125,-85.003098,-0.000479,0.000794,0.020163,11.899550,0.606192,0.201629,-85.003098,0.021142,0.000000
28.840002,2.808807,-84.914139,-0.000448,0.000817,0.020743,12.494199,0.636485,0.207435,-84.914139,0.021663,0.000000
29.150002,2.755928,-84.914139,-0.000448,0.000827,0.021004,12.258980,0.624502,0.210039,-84.914139,0.022175,0.000000
29.460001,3.053085,-85.003098,-0.000410,0.000860,0.021845,13.580802,0.691839,0.218449,-85.003098,0.022695,0.000000
29.770002,3.075050,-85.003098,-0.000392,0.000883,0.022435,13.678507,0.696816,0.224346,-85.003098,0.023207,0.000000
30.080002,3.062393,-84.958618,-0.000366,0.000899,0.022825,13.622205,0.693948,0.228252,-84.958618,0.023727,0.000000
30.390001,3.075424,-85.003098,-0.000349,0.000916,0.023267,13.680170,0.696901,0.232673,-85.003098,0.024248,0.000000
30.700001,3.263474,-85.003098,-0.000336,0.000936,0.023771,14.516655,0.739514,0.237707,-85.003098,0.024759,0.000000
31.010002,3.298851,-85.003098,-0.000315,0.000954,0.024221,14.674022,0.747530,0.242211,-85.003098,0.025279,0.000000
31.320002,3.477585,-85.047577,-0.000297,0.000977,0.024820,15.469069,0.788032,0.248198,-85.047577,0.025791,0.000000
31.630001,3.587440,-84.958618,-0.000259,0.001001,0.025435,15.957732,0.812926,0.254353,-84.958618,0.026311,0.000000
31.940002,3.569191,-85.003098,-0.000246,0.001021,0.025939,15.876554,0.808790,0.259386,-85.003098,0.026832,0.000000
32.250000,3.579247,-85.047577,-0.000237,0.001037,0.026338,15.921284,0.811069,0.263376,-85.047577,0.027344,0.000000
32.560001,3.790756,-85.047577,-0.000220,0.001058,0.026867,16.862125,0.858998,0.268667,-85.047577,0.027864,0.000000
32.870003,3.839165,-85.092056,-0.000198,0.001078,0.027378,17.077457,0.869967,0.273784,-85.092056,0.028375,0.000000
33.180000,3.929276,-85.047577,-0.000168,0.001094,0.027777,17.478291,0.890387,0.277773,-85.047577,0.028895,0.000000
33.490002,4.143761,-85.092056,-0.000142,0.001123,0.028514,18.432367,0.938990,0.285139,-85.092056,0.029407,0.000000
33.800003,4.081947,-85.047577,-0.000138,0.001140,0.028948,18.157408,0.924982,0.289476,-85.047577,0.029928,0.000000
34.110001,4.173553,-85.092056,-0.000103,0.001163,0.029529,18.564894,0.945741,0.295290,-85.092056,0.030448,0.000000
34.420002,4.242813,-85.136543,-0.000099,0.001181,0.029997,18.872974,0.961435,0.299968,-85.136543,0.030960,0.000000
34.730003,4.419319,-85.047577,-0.000069,0.001204,0.030570,19.658113,1.001432,0.305698,-85.047577,0.031480,0.000000
35.040001,4.452087,-85.181023,-0.000052,0.001220,0.030977,19.803873,1.008857,0.309771,-85.181023,0.031991,0.000000
35.350002,4.450226,-85.136543,-0.000043,0.001240,0.031506,19.795593,1.008436,0.315062,-85.136543,0.032512,0.000000
35.660000,4.752220,-85.136543,-0.000009,0.001266,0.032148,21.138931,1.076869,0.321481,-85.136543,0.033024,0.000000
35.970001,4.688911,-85.136543,0.000004,0.001284,0.032616,20.857319,1.062522,0.326160,-85.136543,0.033544,0.000000
36.280003,4.739182,-85.136543,0.000026,0.001301,0.033041,21.080933,1.073914,0.330414,-85.136543,0.034065,0.000000
36.590000,4.859093,-85.181023,0.000047,0.001321,0.033561,21.614325,1.101086,0.335614,-85.181023,0.034576,0.000000
36.900002,4.771957,-85.136543,0.000047,0.001333,0.033857,21.226727,1.081341,0.338566,-85.136543,0.035097,0.000000
37.210003,5.213959,-85.269981,0.000082,0.001367,0.034723,23.192846,1.181500,0.347234,-85.269981,0.035608,0.000000
37.520000,5.290672,-85.181023,0.000108,0.001389,0.035287,23.534086,1.198884,0.352873,-85.181023,0.036128,0.000000
37.830002,5.294022,-85.181023,0.000121,0.001408,0.035764,23.548985,1.199643,0.357642,-85.181023,0.036649,0.000000
38.140003,5.206886,-85.181023,0.000142,0.001425,0.036206,23.161386,1.179897,0.362063,-85.181023,0.037160,0.000000
38.450001,5.577393,-85.225502,0.000168,0.001448,0.036779,24.809481,1.263855,0.367786,-85.225502,0.037681,0.000000
38.760002,5.541275,-85.225502,0.000190,0.001464,0.037187,24.648823,1.255671,0.371866,-85.225502,0.038193,0.000000
39.070004,5.776985,-85.314461,0.000198,0.001488,0.037802,25.697313,1.309083,0.378020,-85.314461,0.038713,0.000000
39.380001,5.856674,-85.269981,0.000216,0.001510,0.038366,26.051788,1.327141,0.383660,-85.269981,0.039224,0.000000
39.690002,5.902473,-85.314461,0.000241,0.001530,0.038851,26.255514,1.337520,0.388512,-85.314461,0.039744,0.000000
40.000000,6.073769,-85.225502,0.000254,0.001553,0.039450,27.017471,1.376336,0.394500,-85.225502,0.040265,0.000000
40.310001,6.185852,-85.269981,0.000289,0.001574,0.039979,27.516045,1.401734,0.399791,-85.269981,0.040777,0.000000
40.620003,6.157555,-85.314461,0.000297,0.001589,0.040369,27.390171,1.395322,0.403689,-85.314461,0.041297,0.000000
40.930000,6.308365,-85.269981,0.000315,0.001609,0.040872,28.061008,1.429496,0.408723,-85.269981,0.041809,0.000000
41.240002,6.492317,-85.314461,0.000332,0.001632,0.041453,28.879269,1.471180,0.414529,-85.314461,0.042329,0.000000
41.550003,6.566788,-85.314461,0.000358,0.001653,0.041974,29.210531,1.488055,0.419737,-85.314461,0.042850,0.000000
41.860001,6.559715,-85.269981,0.000375,0.001672,0.042468,29.179071,1.486453,0.424680,-85.269981,0.043361,0.000000
42.170002,6.716858,-85.358948,0.000388,0.001693,0.043005,29.878077,1.522062,0.430055,-85.358948,0.043881,0.000000
42.480003,6.862450,-85.314461,0.000405,0.001713,0.043509,30.525702,1.555053,0.435089,-85.314461,0.044393,0.000000
42.790001,6.850540,-85.403427,0.000435,0.001729,0.043908,30.472725,1.552355,0.439078,-85.403427,0.044913,0.000000
43.100002,7.104866,-85.358948,0.000448,0.001755,0.044566,31.604023,1.609986,0.445664,-85.358948,0.045425,0.000000
43.410004,7.247490,-85.403427,0.000483,0.001777,0.045148,32.238445,1.642305,0.451477,-85.403427,0.045946,0.000000
43.720001,7.135033,-85.403427,0.000479,0.001795,0.045599,31.738211,1.616822,0.455989,-85.403427,0.046466,0.000000
44.030003,7.119392,-85.358948,0.000513,0.001812,0.046014,31.668638,1.613277,0.460145,-85.358948,0.046977,0.000000
44.340004,7.488411,-85.403427,0.000522,0.001838,0.046683,33.310116,1.696898,0.466829,-85.403427,0.047497,0.000000
44.650002,7.414680,-85.403427,0.000530,0.001853,0.047064,32.982147,1.680191,0.470644,-85.403427,0.048009,0.000000
44.960003,7.695450,-85.403427,0.000556,0.001876,0.047654,34.231071,1.743814,0.476541,-85.403427,0.048530,0.000000
45.270000,7.782959,-85.403427,0.000586,0.001898,0.048217,34.620331,1.763644,0.482173,-85.403427,0.049042,0.000000
45.580002,7.805672,-85.447906,0.000599,0.001917,0.048703,34.721363,1.768790,0.487033,-85.447906,0.049562,0.000000
45.890003,7.782585,-85.581352,0.000612,0.001933,0.049102,34.618668,1.763559,0.491022,-85.581352,0.050082,0.000000
46.200001,8.033562,-85.492386,0.000634,0.001957,0.049700,35.735065,1.820431,0.497002,-85.492386,0.050593,0.000000
46.510002,7.993721,-85.447906,0.000664,0.001974,0.050134,35.557846,1.811403,0.501340,-85.447906,0.051114,0.000000
46.820004,8.064102,-85.492386,0.000668,0.001993,0.050628,35.870918,1.827352,0.506283,-85.492386,0.051626,0.000000
47.130001,8.545952,-85.447906,0.000686,0.002022,0.051357,38.014294,1.936540,0.513572,-85.447906,0.052146,0.000000
47.440002,8.395882,-85.536865,0.000720,0.002038,0.051764,37.346748,1.902534,0.517645,-85.536865,0.052666,0.000000
47.750004,8.429771,-85.447906,0.000716,0.002055,0.052189,37.497498,1.910214,0.521892,-85.447906,0.053178,0.000000
48.060001,8.676277,-85.536865,0.000737,0.002078,0.052779,38.594009,1.966073,0.527788,-85.536865,0.053699,0.000000
48.370003,8.687454,-85.447906,0.000763,0.002096,0.053239,38.643726,1.968605,0.532391,-85.447906,0.054210,0.000000
48.680004,8.796181,-85.536865,0.000772,0.002117,0.053767,39.127365,1.993243,0.537675,-85.536865,0.054730,0.000000
48.990002,9.084770,-85.536865,0.000798,0.002141,0.054392,40.411076,2.058638,0.543920,-85.536865,0.055242,0.000000
49.300003,8.916084,-85.492386,0.000819,0.002157,0.054791,39.660725,2.020414,0.547909,-85.492386,0.055762,0.000000
49.610001,9.015884,-85.581352,0.000836,0.002178,0.055320,40.104656,2.043029,0.553200,-85.581352,0.056283,0.000000
49.920002,9.044930,-85.536865,0.000849,0.002194,0.055728,40.233856,2.049610,0.557280,-85.536865,0.056795,0.000000
50.230003,9.302238,-85.581352,0.000880,0.002219,0.056361,41.378422,2.107918,0.563609,-85.581352,0.057315,0.000000
50.540001,9.133179,-85.625832,0.000880,0.002233,0.056708,40.626408,2.069608,0.567076,-85.625832,0.057826,0.000000
50.850002,9.742012,-85.581352,0.000905,0.002264,0.057497,43.334633,2.207572,0.574971,-85.581352,0.058346,0.000000
51.160004,9.695091,-85.625832,0.000918,0.002283,0.057982,43.125919,2.196939,0.579823,-85.625832,0.058867,0.000000
51.470001,9.615028,-85.625832,0.000949,0.002301,0.058451,42.769783,2.178797,0.584509,-85.625832,0.059379,0.000000
51.780003,9.684288,-85.625832,0.000961,0.002319,0.058902,43.077866,2.194491,0.589020,-85.625832,0.059899,0.000000
52.090004,9.811646,-85.625832,0.000979,0.002338,0.059396,43.644379,2.223351,0.593964,-85.625832,0.060411,0.000000
52.400002,9.872337,-85.581352,0.000996,0.002357,0.059864,43.914349,2.237103,0.598642,-85.581352,0.060931,0.000000
52.710003,10.045868,-85.670311,0.001013,0.002379,0.060428,44.686253,2.276426,0.604281,-85.670311,0.061442,0.000000
53.020004,10.300941,-85.581352,0.001035,0.002404,0.061070,45.820877,2.334227,0.610700,-85.581352,0.061963,0.000000
53.330002,10.209709,-85.625832,0.001048,0.002422,0.061520,45.415054,2.313553,0.615204,-85.625832,0.062483,0.000000
53.640003,10.041397,-85.670311,0.001061,0.002436,0.061868,44.666367,2.275413,0.618679,-85.670311,0.062995,0.000000
53.950001,10.355309,-85.581352,0.001082,0.002459,0.062466,46.062714,2.346546,0.624659,-85.581352,0.063515,0.000000
54.260002,10.385468,-85.714790,0.001095,0.002476,0.062900,46.196865,2.353380,0.628997,-85.714790,0.064027,0.000000
54.570004,10.652832,-85.625832,0.001112,0.002502,0.063542,47.386162,2.413966,0.635416,-85.625832,0.064548,0.000000
54.880001,10.782791,-85.670311,0.001138,0.002523,0.064096,47.964249,2.443415,0.640964,-85.670311,0.065068,0.000000
55.190002,10.704964,-85.759277,0.001143,0.002542,0.064556,47.618057,2.425780,0.645559,-85.759277,0.065579,0.000000
55.500004,10.732521,-85.714790,0.001164,0.002562,0.065077,47.740639,2.432024,0.650767,-85.714790,0.066099,0.000000
55.810001,11.062439,-85.759277,0.001177,0.002585,0.065666,49.208187,2.506784,0.656664,-85.759277,0.066611,0.000000
56.120003,10.957802,-85.714790,0.001207,0.002602,0.066091,48.742737,2.483073,0.660911,-85.714790,0.067132,0.000000
56.430004,10.947380,-85.759277,0.001220,0.002619,0.066516,48.696377,2.480712,0.665157,-85.759277,0.067644,0.000000
56.740002,11.311935,-85.759277,0.001246,0.002645,0.067192,50.318001,2.563321,0.671925,-85.759277,0.068164,0.000000
57.050003,11.406517,-85.759277,0.001263,0.002669,0.067782,50.738720,2.584754,0.677822,-85.759277,0.068684,0.000000
57.360004,11.115692,-85.759277,0.001268,0.002684,0.068181,49.445068,2.518852,0.681811,-85.759277,0.069195,0.000000
57.670002,11.208786,-85.803757,0.001293,0.002705,0.068701,49.859169,2.539947,0.687011,-85.803757,0.069716,0.000000
57.980003,11.537590,-85.803757,0.001306,0.002729,0.069317,51.321762,2.614455,0.693173,-85.803757,0.070228,0.000000
58.290001,11.202454,-85.803757,0.001324,0.002738,0.069543,49.831001,2.538512,0.695429,-85.803757,0.070748,0.000000
58.600002,12.035454,-85.848236,0.001362,0.002774,0.070470,53.536373,2.727273,0.704702,-85.848236,0.071260,0.000000
58.910004,11.767715,-85.803757,0.001362,0.002790,0.070861,52.345413,2.666603,0.708608,-85.803757,0.071780,0.000000
59.220001,11.754311,-85.803757,0.001388,0.002810,0.071381,52.285786,2.663565,0.713808,-85.803757,0.072301,0.000000
59.530003,11.878685,-85.803757,0.001406,0.002831,0.071902,52.839031,2.691749,0.719016,-85.803757,0.072812,0.000000
59.840004,11.913315,-85.892715,0.001423,0.002852,0.072439,52.993073,2.699596,0.724391,-85.892715,0.073332,0.000000
60.150002,11.960236,-85.848236,0.001440,0.002871,0.072933,53.201786,2.710228,0.729334,-85.848236,0.073844,0.000000
60.460003,12.227592,-85.937195,0.001457,0.002895,0.073523,54.391048,2.770812,0.735231,-85.937195,0.074364,0.000000
60.770004,12.125938,-85.892715,0.001470,0.002911,0.073939,53.938869,2.747777,0.739394,-85.892715,0.074885,0.000000
61.080002,12.261108,-85.937195,0.001496,0.002932,0.074477,54.540134,2.778407,0.744769,-85.937195,0.075397,0.000000
61.390003,12.465172,-85.937195,0.001513,0.002955,0.075067,55.447853,2.824648,0.750666,-85.937195,0.075917,0.000000
61.700005,12.452881,-85.892715,0.001535,0.002975,0.075570,55.393181,2.821863,0.755700,-85.892715,0.076428,0.000000
62.010002,12.321060,-85.937195,0.001544,0.002991,0.075969,54.806812,2.791992,0.759689,-85.937195,0.076948,0.000000
62.320004,12.477455,-85.848236,0.001569,0.003012,0.076515,55.502491,2.827432,0.765154,-85.848236,0.077460,0.000000
62.630001,12.639442,-85.981682,0.001595,0.003034,0.077070,56.223049,2.864139,0.770703,-85.981682,0.077981,0.000000
62.940002,12.737373,-85.937195,0.001595,0.003055,0.077608,56.658665,2.886330,0.776078,-85.937195,0.078501,0.000000
63.250004,12.749664,-85.937195,0.001608,0.003075,0.078111,56.713341,2.889115,0.781111,-85.937195,0.079013,0.000000
63.560001,12.857277,-85.981682,0.001621,0.003096,0.078640,57.192024,2.913501,0.786395,-85.981682,0.079533,0.000000
63.870003,12.966751,-85.937195,0.001660,0.003117,0.079160,57.678989,2.938308,0.791603,-85.937195,0.080044,0.000000
64.180000,13.005112,-85.981682,0.001677,0.003136,0.079663,57.849625,2.947000,0.796630,-85.981682,0.080565,0.000000
64.490005,13.185707,-85.981682,0.001694,0.003158,0.080218,58.652954,2.987924,0.802178,-85.981682,0.081085,0.000000
64.800003,13.236725,-85.981682,0.001712,0.003180,0.080764,58.879894,2.999485,0.807644,-85.981682,0.081597,0.000000
65.110001,13.065804,-85.981682,0.001703,0.003198,0.081233,58.119598,2.960753,0.812329,-85.981682,0.082117,0.000000
65.420006,13.100067,-86.026161,0.001750,0.003216,0.081684,58.272011,2.968518,0.816841,-86.026161,0.082629,0.000000
65.730003,13.409134,-86.070641,0.001759,0.003240,0.082300,59.646805,3.038553,0.822995,-86.070641,0.083150,0.000000
66.040001,13.580055,-86.026161,0.001785,0.003261,0.082829,60.407104,3.077284,0.828286,-86.026161,0.083661,0.000000
66.350006,13.829918,-86.026161,0.001802,0.003285,0.083444,61.518547,3.133904,0.834441,-86.026161,0.084181,0.000000
66.660004,13.457542,-86.026161,0.001807,0.003301,0.083852,59.862137,3.049523,0.838521,-86.026161,0.084701,0.000000
66.970001,13.408386,-86.026161,0.001841,0.003319,0.084312,59.643482,3.038384,0.843116,-86.026161,0.085213,0.000000
67.280006,13.649689,-86.026161,0.001845,0.003342,0.084884,60.716846,3.093064,0.848838,-86.026161,0.085734,0.000000
67.590004,13.659370,-85.981682,0.001858,0.003364,0.085439,60.759914,3.095258,0.854387,-85.981682,0.086246,0.000000
67.900002,13.594574,-86.115120,0.001884,0.003379,0.085820,60.471684,3.080575,0.858202,-86.115120,0.086766,0.000000
68.210007,13.834755,-86.070641,0.001901,0.003401,0.086392,61.540062,3.135000,0.863925,-86.070641,0.087277,0.000000
68.520004,14.197815,-86.115120,0.001923,0.003427,0.087034,63.155037,3.217271,0.870344,-86.115120,0.087797,0.000000
68.830002,13.859329,-86.159599,0.001944,0.003441,0.087399,61.649376,3.140569,0.873985,-86.159599,0.088318,0.000000
69.140007,13.884651,-86.070641,0.001957,0.003459,0.087859,61.762012,3.146307,0.878588,-86.070641,0.088830,0.000000
69.450005,14.217178,-86.159599,0.001966,0.003484,0.088500,63.241169,3.221659,0.884999,-86.159599,0.089350,0.000000
69.760002,14.093178,-86.159599,0.001975,0.003499,0.088881,62.689587,3.193560,0.888814,-86.159599,0.089862,0.000000
70.070000,14.297989,-86.115120,0.002005,0.003521,0.089428,63.600632,3.239970,0.894280,-86.115120,0.090382,0.000000
70.380005,14.628281,-86.159599,0.002026,0.003547,0.090087,65.069839,3.314816,0.900873,-86.159599,0.090903,0.000000
70.690002,14.511353,-86.115120,0.002035,0.003565,0.090547,64.549721,3.288320,0.905468,-86.115120,0.091414,0.000000
71.000000,14.306175,-86.204086,0.002061,0.003581,0.090955,63.637047,3.241826,0.909548,-86.204086,0.091934,0.000000
71.310005,14.537048,-86.204086,0.002057,0.003601,0.091466,64.664024,3.294142,0.914658,-86.204086,0.092446,0.000000
71.620003,14.690094,-86.204086,0.002091,0.003623,0.092012,65.344803,3.328823,0.920123,-86.204086,0.092966,0.000000
71.930000,14.678177,-86.204086,0.002104,0.003641,0.092481,65.291794,3.326123,0.924809,-86.204086,0.093478,0.000000
72.240005,15.348824,-86.159599,0.002139,0.003670,0.093218,68.274979,3.478093,0.932182,-86.159599,0.093999,0.000000
72.550003,14.881493,-86.204086,0.002139,0.003684,0.093582,66.196182,3.372195,0.935823,-86.204086,0.094519,0.000000
72.860001,14.952988,-86.204086,0.002164,0.003706,0.094129,66.514214,3.388395,0.941288,-86.204086,0.095030,0.000000
73.170006,14.819679,-86.204086,0.002173,0.003723,0.094571,65.921227,3.358187,0.945709,-86.204086,0.095550,0.000000
73.480003,14.909050,-86.248566,0.002182,0.003741,0.095022,66.318764,3.378439,0.950221,-86.248566,0.096062,0.000000
73.790001,15.140663,-86.248566,0.002195,0.003761,0.095533,67.349030,3.430923,0.955330,-86.248566,0.096583,0.000000
74.100006,15.346214,-86.293045,0.002225,0.003784,0.096114,68.263367,3.477502,0.961144,-86.293045,0.097103,0.000000
74.410004,15.672783,-86.248566,0.002233,0.003809,0.096756,69.716019,3.551503,0.967563,-86.248566,0.097615,0.000000
74.720001,15.332062,-86.248566,0.002268,0.003825,0.097155,68.200417,3.474295,0.971552,-86.248566,0.098135,0.000000
75.030006,14.976448,-86.204086,0.002276,0.003837,0.097459,66.618568,3.393712,0.974588,-86.204086,0.098646,0.000000
75.340004,15.733109,-86.337524,0.002289,0.003865,0.098179,69.984360,3.565173,0.981787,-86.337524,0.099167,0.000000
75.650002,15.473190,-86.382004,0.002315,0.003880,0.098551,68.828186,3.506275,0.985511,-86.382004,0.099679,0.000000
75.960007,16.183678,-86.293045,0.002324,0.003906,0.099219,71.988594,3.667274,0.992187,-86.293045,0.100199,0.000000
76.270004,15.994141,-86.337524,0.002350,0.003926,0.099713,71.145493,3.624324,0.997131,-86.337524,0.100719,0.000000
76.580002,16.296883,-86.337524,0.002363,0.003950,0.100320,72.492157,3.692926,1.003202,-86.337524,0.101231,0.000000
76.890007,15.946854,-86.293045,0.002376,0.003964,0.100685,70.935150,3.613609,1.006850,-86.293045,0.101752,0.000000
77.200005,16.686012,-86.337524,0.002393,0.003992,0.101387,74.223091,3.781105,1.013875,-86.337524,0.102263,0.000000
77.510002,16.021324,-86.337524,0.002406,0.004000,0.101612,71.266411,3.630484,1.016123,-86.337524,0.102783,0.000000
77.820007,16.150169,-86.426491,0.002427,0.004020,0.102116,71.839539,3.659681,1.021157,-86.426491,0.103303,0.000000
78.130005,16.913528,-86.426491,0.002436,0.004051,0.102896,75.235130,3.832660,1.028962,-86.426491,0.103815,0.000000
78.440002,16.749313,-86.426491,0.002475,0.004070,0.103390,74.504669,3.795449,1.033905,-86.426491,0.104336,0.000000
78.750000,16.833099,-86.426491,0.002470,0.004089,0.103867,74.877365,3.814435,1.038674,-86.426491,0.104848,0.000000
79.060005,16.846504,-86.426491,0.002492,0.004110,0.104387,74.936996,3.817472,1.043874,-86.426491,0.105368,0.000000
79.370003,17.192062,-86.426491,0.002514,0.004130,0.104908,76.474113,3.895777,1.049082,-86.426491,0.105879,0.000000
79.680000,16.505409,-86.426491,0.002522,0.004137,0.105073,73.419724,3.740179,1.050732,-86.426491,0.106399,0.000000
79.990005,18.068260,-86.470970,0.002548,0.004178,0.106113,80.371635,4.094326,1.061133,-86.470970,0.106920,0.000000
80.300003,17.488472,-86.426491,0.002557,0.004193,0.106495,77.792610,3.962945,1.064948,-86.426491,0.107432,0.000000
80.610001,17.690674,-86.382004,0.002574,0.004213,0.107016,78.692047,4.008764,1.070156,-86.382004,0.107952,0.000000
80.920006,17.941277,-86.470970,0.002600,0.004237,0.107631,79.806786,4.065551,1.076311,-86.470970,0.108464,0.000000
81.230003,18.136398,-86.470970,0.002600,0.004257,0.108117,80.674728,4.109766,1.081170,-86.470970,0.108984,0.000000
81.540001,18.124115,-86.470970,0.002613,0.004272,0.108499,80.620087,4.106983,1.084986,-86.470970,0.109495,0.000000
81.850006,18.592560,-86.559929,0.002630,0.004296,0.109114,82.703835,4.213134,1.091140,-86.559929,0.110016,0.000000
82.160004,18.589577,-86.515450,0.002647,0.004313,0.109556,82.690567,4.212458,1.095561,-86.515450,0.110536,0.000000
82.470001,18.796249,-86.559929,0.002669,0.004335,0.110112,83.609894,4.259291,1.101117,-86.559929,0.111048,0.000000
82.780006,19.145157,-86.515450,0.002682,0.004357,0.110667,85.161911,4.338355,1.106665,-86.515450,0.111568,0.000000
83.090004,19.446777,-86.515450,0.002699,0.004378,0.111213,86.503586,4.406703,1.112131,-86.515450,0.112080,0.000000
83.400002,19.294853,-86.604408,0.002716,0.004395,0.111629,85.827797,4.372276,1.116294,-86.604408,0.112601,0.000000
83.710007,19.923416,-86.470970,0.002716,0.004419,0.112237,88.623779,4.514710,1.122365,-86.470970,0.113121,0.000000
84.020004,20.210518,-86.559929,0.002751,0.004438,0.112731,89.900871,4.579769,1.127308,-86.559929,0.113632,0.000000
84.330002,20.401543,-86.559929,0.002759,0.004458,0.113233,90.750595,4.623056,1.132335,-86.559929,0.114152,0.000000
84.640007,20.709496,-86.515450,0.002772,0.004478,0.113754,92.120438,4.692839,1.137535,-86.515450,0.114664,0.000000
84.950005,21.031227,-86.604408,0.002781,0.004499,0.114265,93.551567,4.765744,1.142652,-86.604408,0.115185,0.000000
85.260002,21.265450,-86.559929,0.002794,0.004516,0.114699,94.593445,4.818820,1.146990,-86.559929,0.115697,0.000000
85.570007,21.740219,-86.604408,0.002820,0.004538,0.115271,96.705322,4.926404,1.152712,-86.604408,0.116217,0.000000
85.880005,22.290962,-86.559929,0.002828,0.004560,0.115835,99.155151,5.051204,1.158352,-86.559929,0.116737,0.000000
86.190002,22.691261,-86.648895,0.002841,0.004581,0.116364,100.935768,5.141913,1.163643,-86.648895,0.117248,0.000000
86.500008,22.966446,-86.648895,0.002863,0.004603,0.116911,102.159851,5.204271,1.169109,-86.648895,0.117769,0.000000
86.810005,23.331367,-86.648895,0.002871,0.004622,0.117396,103.783104,5.286963,1.173961,-86.648895,0.118281,0.000000
87.120003,23.983765,-86.648895,0.002897,0.004642,0.117899,106.685112,5.434799,1.178995,-86.648895,0.118801,0.000000
87.430008,24.301773,-86.648895,0.002902,0.004661,0.118385,108.099686,5.506861,1.183847,-86.648895,0.119321,0.000000
87.740005,25.341438,-86.648895,0.002915,0.004685,0.118992,112.724350,5.742452,1.189918,-86.648895,0.119833,0.000000
88.050003,25.587944,-86.693375,0.002928,0.004704,0.119486,113.820862,5.798311,1.194861,-86.693375,0.120354,0.000000
88.360001,26.113365,-86.648895,0.002945,0.004724,0.119998,116.158051,5.917373,1.199978,-86.648895,0.120865,0.000000
88.670006,26.600052,-86.782333,0.002971,0.004745,0.120518,118.322937,6.027658,1.205179,-86.782333,0.121385,0.000000
88.980003,27.526520,-86.693375,0.002975,0.004769,0.121125,122.444077,6.237598,1.211250,-86.693375,0.121897,0.000000
89.290001,27.481087,-86.782333,0.002988,0.004782,0.121472,122.241982,6.227304,1.214724,-86.782333,0.122417,0.000000
89.600006,28.474205,-86.693375,0.003001,0.004806,0.122062,126.659592,6.452347,1.220621,-86.693375,0.122938,0.000000
89.910004,29.476631,-86.693375,0.003027,0.004828,0.122643,131.118607,6.679500,1.226427,-86.693375,0.123450,0.000000
90.220001,29.458755,-86.826813,0.003022,0.004842,0.122981,131.039093,6.675449,1.229811,-86.826813,0.123970,0.000000
90.530006,30.244461,-86.737854,0.003035,0.004864,0.123553,134.534088,6.853493,1.235534,-86.737854,0.124481,0.000000
90.840004,31.278168,-86.693375,0.003070,0.004886,0.124108,139.132233,7.087734,1.241082,-86.693375,0.125001,0.000000
91.150002,31.466217,-86.782333,0.003074,0.004899,0.124438,139.968719,7.130347,1.244383,-86.782333,0.125513,0.000000
91.460007,32.477211,-86.782333,0.003078,0.004922,0.125019,144.465851,7.359441,1.250189,-86.782333,0.126034,0.000000
91.770004,33.704552,-86.826813,0.003109,0.004947,0.125661,149.925339,7.637561,1.256608,-86.826813,0.126554,0.000000
92.080002,34.333115,-86.782333,0.003109,0.004966,0.126147,152.721329,7.779995,1.261468,-86.782333,0.127066,0.000000
92.390007,34.766182,-86.782333,0.003122,0.004982,0.126537,154.647705,7.878129,1.265366,-86.782333,0.127586,0.000000
92.700005,35.878464,-86.826813,0.003139,0.005005,0.127126,159.595383,8.130177,1.271263,-86.826813,0.128097,0.000000
93.010002,36.711830,-86.782333,0.003143,0.005022,0.127552,163.302383,8.319019,1.275517,-86.782333,0.128618,0.000000
93.320007,37.725800,-86.871300,0.003165,0.005044,0.128124,167.812744,8.548789,1.281240,-86.871300,0.129138,0.000000
93.630005,39.489731,-86.782333,0.003165,0.005072,0.128817,175.659103,8.948502,1.288174,-86.782333,0.129650,0.000000
93.940002,40.013283,-86.826813,0.003191,0.005089,0.129269,177.987976,9.067140,1.292686,-86.826813,0.130170,0.000000
94.250008,40.688026,-86.915779,0.003191,0.005105,0.129658,180.989380,9.220038,1.296584,-86.915779,0.130682,0.000000
94.560005,41.728058,-86.826813,0.003221,0.005126,0.130205,185.615677,9.455713,1.302049,-86.826813,0.131203,0.000000
94.870003,42.395348,-86.915779,0.003225,0.005143,0.130630,188.583923,9.606923,1.306304,-86.915779,0.131714,0.000000
95.180008,43.697540,-86.871300,0.003229,0.005164,0.131159,194.376373,9.902004,1.311587,-86.871300,0.132234,0.000000
95.490005,45.281609,-86.871300,0.003242,0.005191,0.131844,201.422653,10.260960,1.318438,-86.871300,0.132754,0.000000
95.800003,46.559219,-86.915779,0.003247,0.005211,0.132347,207.105759,10.550469,1.323472,-86.915779,0.133266,0.000000
96.110008,47.228371,-86.915779,0.003260,0.005228,0.132798,210.082291,10.702102,1.327983,-86.915779,0.133787,0.000000
96.420006,47.908325,-86.960258,0.003285,0.005246,0.133240,213.106873,10.856182,1.332404,-86.960258,0.134299,0.000000
96.730003,49.590332,-86.960258,0.003277,0.005269,0.133830,220.588821,11.237329,1.338301,-86.960258,0.134819,0.000000
97.040001,50.632973,-86.960258,0.003303,0.005286,0.134264,225.226715,11.473596,1.342638,-86.960258,0.135339,0.000000
97.350006,52.045753,-87.004738,0.003298,0.005308,0.134819,231.511078,11.793736,1.348187,-87.004738,0.135850,0.000000
97.660004,53.306236,-86.915779,0.003333,0.005328,0.135321,237.117981,12.079366,1.353214,-86.915779,0.136371,0.000000
97.970001,54.954727,-86.960258,0.003328,0.005351,0.135912,244.450836,12.452919,1.359118,-86.960258,0.136883,0.000000
98.280006,55.692772,-87.004738,0.003337,0.005367,0.136311,247.733826,12.620163,1.363107,-87.004738,0.137403,0.000000
98.590004,57.818649,-87.004738,0.003350,0.005393,0.136987,257.190186,13.101893,1.369867,-87.004738,0.137915,0.000000
98.900002,58.259537,-87.093704,0.003359,0.005404,0.137255,259.151367,13.201800,1.372554,-87.093704,0.138435,0.000000
99.210007,59.321541,-86.960258,0.003367,0.005425,0.137785,263.875397,13.442453,1.377846,-86.960258,0.138956,0.000000
99.520004,62.064064,-87.049225,0.003376,0.005456,0.138582,276.074738,14.063918,1.385824,-87.049225,0.139467,0.000000
99.830002,63.138351,-87.004738,0.003385,0.005473,0.139007,280.853424,14.307355,1.390071,-87.004738,0.139987,0.000000
100.140007,64.197754,-87.049225,0.003406,0.005488,0.139406,285.565857,14.547419,1.394060,-87.049225,0.140499,0.000000
100.450005,65.967270,-87.049225,0.003397,0.005513,0.140031,293.437073,14.948397,1.400305,-87.049225,0.141019,0.000000
100.760002,67.436279,-87.093704,0.003419,0.005531,0.140482,299.971558,15.281280,1.404817,-87.093704,0.141540,0.000000
101.070007,66.775696,-87.093704,0.003428,0.005523,0.140283,297.033142,15.131589,1.402826,-87.093704,0.140499,0.000000
101.380005,66.202240,-87.093704,0.003428,0.005522,0.140248,294.482269,15.001641,1.402478,-87.093704,0.140283,0.000000
101.690002,65.711075,-87.049225,0.003445,0.005521,0.140239,292.297455,14.890343,1.402387,-87.049225,0.140283,0.000000
102.000008,65.263855,-87.138184,0.003445,0.005521,0.140230,290.308136,14.789001,1.402304,-87.138184,0.140283,0.000000
102.310005,64.874359,-87.093704,0.003436,0.005521,0.140221,288.575562,14.700740,1.402213,-87.093704,0.140283,0.000000
102.620003,64.569016,-87.138184,0.003441,0.005521,0.140221,287.217316,14.631549,1.402213,-87.138184,0.140283,0.000000
102.930008,64.271118,-87.093704,0.003449,0.005521,0.140221,285.892212,14.564043,1.402213,-87.093704,0.140283,0.000000
103.240005,63.987747,-87.093704,0.003454,0.005520,0.140213,284.631714,14.499830,1.402130,-87.093704,0.140283,0.000000
103.550003,63.762833,-87.093704,0.003436,0.005520,0.140213,283.631256,14.448864,1.402130,-87.093704,0.140283,0.000000
103.860008,63.553925,-87.093704,0.003445,0.005520,0.140213,282.701965,14.401525,1.402130,-87.093704,0.140283,0.000000
104.170006,63.342789,-87.138184,0.003462,0.005520,0.140213,281.762787,14.353681,1.402130,-87.138184,0.140283,0.000000
104.480003,63.168900,-87.138184,0.003449,0.005520,0.140213,280.989288,14.314277,1.402130,-87.138184,0.140283,0.000000
104.790009,62.996109,-87.182663,0.003454,0.005520,0.140213,280.220703,14.275123,1.402130,-87.182663,0.140283,0.000000
105.100006,62.837112,-87.227142,0.003454,0.005520,0.140213,279.513428,14.239093,1.402130,-87.227142,0.140283,0.000000
105.410004,62.696350,-87.182663,0.003449,0.005520,0.140213,278.887299,14.207196,1.402130,-87.182663,0.140283,0.000000
105.720001,62.561180,-87.182663,0.003462,0.005520,0.140213,278.286041,14.176566,1.402130,-87.182663,0.140283,0.000000
106.030006,62.423775,-87.227142,0.003466,0.005520,0.140213,277.674805,14.145430,1.402130,-87.227142,0.140283,0.000000
106.340004,62.299774,-87.227142,0.003462,0.005520,0.140213,277.123230,14.117331,1.402130,-87.227142,0.140283,0.000000
106.650002,62.171310,-87.271629,0.003462,0.005520,0.140213,276.551788,14.088220,1.402130,-87.271629,0.140283,0.000000
106.960007,62.075607,-87.227142,0.003454,0.005520,0.140213,276.126099,14.066533,1.402130,-87.227142,0.140283,0.000000
107.270004,61.965759,-87.227142,0.003462,0.005520,0.140213,275.637451,14.041641,1.402130,-87.227142,0.140283,0.000000
107.580002,61.861496,-87.271629,0.003462,0.005520,0.140213,275.173676,14.018016,1.402130,-87.271629,0.140283,0.000000
107.890007,61.773613,-87.271629,0.003466,0.005520,0.140213,274.782745,13.998100,1.402130,-87.271629,0.140283,0.000000
108.200005,61.662643,-87.360588,0.003458,0.005520,0.140213,274.289124,13.972955,1.402130,-87.360588,0.140283,0.000000
108.510002,61.582214,-87.271629,0.003466,0.005520,0.140213,273.931366,13.954729,1.402130,-87.271629,0.140283,0.000000
108.820007,61.502899,-87.271629,0.003462,0.005520,0.140204,273.578552,13.936756,1.402039,-87.271629,0.140283,0.000000
109.130005,61.407196,-87.360588,0.003466,0.005520,0.140204,273.152863,13.915070,1.402039,-87.360588,0.140283,0.000000
109.440002,61.344643,-87.316109,0.003471,0.005520,0.140204,272.874603,13.900895,1.402039,-87.316109,0.140283,0.000000
109.750008,61.262344,-87.360588,0.003466,0.005520,0.140204,272.508514,13.882245,1.402039,-87.360588,0.140283,0.000000
110.060005,61.200157,-87.316109,0.003454,0.005520,0.140204,272.231903,13.868154,1.402039,-87.316109,0.140283,0.000000
110.370003,61.127174,-87.316109,0.003475,0.005520,0.140204,271.907257,13.851616,1.402039,-87.316109,0.140283,0.000000
110.680008,61.062386,-87.360588,0.003458,0.005520,0.140204,271.619049,13.836934,1.402039,-87.360588,0.140283,0.000000
110.990005,61.000198,-87.360588,0.003471,0.005520,0.140204,271.342438,13.822843,1.402039,-87.360588,0.140283,0.000000
111.300003,60.939125,-87.449547,0.003466,0.005520,0.140204,271.070770,13.809004,1.402039,-87.449547,0.140283,0.000000
111.610008,60.873589,-87.360588,0.003462,0.005520,0.140204,270.779236,13.794152,1.402039,-87.360588,0.140283,0.000000
111.920006,60.812889,-87.405067,0.003475,0.005520,0.140204,270.509247,13.780397,1.402039,-87.405067,0.140283,0.000000
112.230003,60.774536,-87.449547,0.003458,0.005520,0.140204,270.338654,13.771707,1.402039,-87.449547,0.140283,0.000000
112.540009,60.710861,-87.405067,0.003475,0.005520,0.140204,270.055389,13.757277,1.402039,-87.405067,0.140283,0.000000
112.850006,60.655380,-87.405067,0.003479,0.005520,0.140204,269.808594,13.744705,1.402039,-87.405067,0.140283,0.000000
113.160004,60.601387,-87.405067,0.003466,0.005520,0.140204,269.568420,13.732471,1.402039,-87.405067,0.140283,0.000000
113.470009,60.549995,-87.405067,0.003471,0.005520,0.140204,269.339844,13.720825,1.402039,-87.405067,0.140283,0.000000
113.780006,60.505310,-87.538513,0.003471,0.005520,0.140204,269.141052,13.710699,1.402039,-87.538513,0.140283,0.000000
114.090004,60.454300,-87.405067,0.003475,0.005520,0.140204,268.914154,13.699141,1.402039,-87.405067,0.140283,0.000000
114.400009,60.411102,-87.449547,0.003475,0.005520,0.140204,268.722015,13.689352,1.402039,-87.449547,0.140283,0.000000
114.710007,60.362694,-87.449547,0.003462,0.005520,0.140204,268.506683,13.678382,1.402039,-87.449547,0.140283,0.000000
115.020004,60.314659,-87.494034,0.003479,0.005520,0.140204,268.292999,13.667498,1.402039,-87.494034,0.140283,0.000000
115.330002,60.278542,-87.538513,0.003471,0.005520,0.140204,268.132355,13.659313,1.402039,-87.538513,0.140283,0.000000
115.640007,60.244278,-87.449547,0.003471,0.005520,0.140204,267.979919,13.651548,1.402039,-87.449547,0.140283,0.000000
115.950005,60.196617,-87.494034,0.003466,0.005520,0.140204,267.767914,13.640749,1.402039,-87.494034,0.140283,0.000000
116.260002,60.153419,-87.538513,0.003475,0.005520,0.140204,267.575775,13.630960,1.402039,-87.538513,0.140283,0.000000
116.570007,60.121773,-87.538513,0.003479,0.005520,0.140204,267.434998,13.623788,1.402039,-87.538513,0.140283,0.000000
116.880005,60.077827,-87.538513,0.003466,0.005520,0.140204,267.239532,13.613831,1.402039,-87.538513,0.140283,0.000000
117.190002,60.037613,-87.538513,0.003479,0.005520,0.140204,267.060638,13.604717,1.402039,-87.538513,0.140283,0.000000
117.500008,60.001495,-87.582993,0.003479,0.005520,0.140204,266.899994,13.596533,1.402039,-87.582993,0.140283,0.000000
117.810005,59.969841,-87.582993,0.003471,0.005520,0.140204,266.759186,13.589360,1.402039,-87.582993,0.140283,0.000000
118.120003,59.928139,-87.538513,0.003475,0.005520,0.140204,266.573669,13.579910,1.402039,-87.538513,0.140283,0.000000
118.430008,59.896858,-87.582993,0.003475,0.005520,0.140204,266.434540,13.572823,1.402039,-87.582993,0.140283,0.000000
118.740005,59.857010,-87.538513,0.003471,0.005520,0.140204,266.257263,13.563792,1.402039,-87.538513,0.140283,0.000000
119.050003,59.843605,-87.671951,0.003471,0.005520,0.140204,266.197662,13.560754,1.402039,-87.671951,0.140283,0.000000
119.360008,59.792221,-87.671951,0.003466,0.005520,0.140204,265.969086,13.549111,1.402039,-87.671951,0.140283,0.000000
119.670006,59.761688,-87.627472,0.003475,0.005520,0.140204,265.833252,13.542192,1.402039,-87.627472,0.140283,0.000000
119.980003,59.730408,-87.627472,0.003466,0.005520,0.140204,265.694122,13.535104,1.402039,-87.627472,0.140283,0.000000
120.290009,59.710670,-87.627472,0.003462,0.005520,0.140204,265.606323,13.530631,1.402039,-87.627472,0.140283,0.000000
120.600006,59.660774,-87.671951,0.003471,0.005520,0.140204,265.384369,13.519325,1.402039,-87.671951,0.140283,0.000000
120.910004,59.642151,-87.627472,0.003471,0.005520,0.140204,265.301544,13.515104,1.402039,-87.627472,0.140283,0.000000
121.220009,59.612740,-87.627472,0.003479,0.005520,0.140204,265.170715,13.508440,1.402039,-87.627472,0.140283,0.000000
121.530006,59.590019,-87.716438,0.003479,0.005520,0.140204,265.069641,13.503291,1.402039,-87.716438,0.140283,0.000000
121.840004,59.557625,-87.671951,0.003471,0.005520,0.140204,264.925537,13.495951,1.402039,-87.671951,0.140283,0.000000
122.150009,59.536026,-87.671951,0.003475,0.005520,0.140204,264.829468,13.491056,1.402039,-87.671951,0.140283,0.000000
122.460007,59.489105,-87.716438,0.003462,0.005520,0.140204,264.620758,13.480424,1.402039,-87.716438,0.140283,0.000000
122.770004,59.474586,-87.716438,0.003484,0.005520,0.140204,264.556183,13.477134,1.402039,-87.716438,0.140283,0.000000
123.080009,59.439209,-87.760918,0.003466,0.005520,0.140204,264.398804,13.469118,1.402039,-87.760918,0.140283,0.000000
123.390007,59.425430,-87.716438,0.003466,0.005520,0.140204,264.337524,13.465995,1.402039,-87.716438,0.140283,0.000000
123.700005,59.384468,-87.716438,0.003466,0.005520,0.140204,264.155304,13.456713,1.402039,-87.716438,0.140283,0.000000
124.010002,59.363991,-87.760918,0.003466,0.005520,0.140204,264.064209,13.452073,1.402039,-87.760918,0.140283,0.000000
124.320007,59.344254,-87.760918,0.003471,0.005520,0.140204,263.976410,13.447600,1.402039,-87.760918,0.140283,0.000000
124.630005,59.329361,-87.805397,0.003466,0.005520,0.140204,263.910187,13.444225,1.402039,-87.805397,0.140283,0.000000
124.940002,59.288773,-87.760918,0.003471,0.005520,0.140204,263.729645,13.435028,1.402039,-87.760918,0.140283,0.000000
125.250008,59.267548,-87.805397,0.003475,0.005520,0.140204,263.635223,13.430219,1.402039,-87.805397,0.140283,0.000000
125.560005,59.246696,-87.805397,0.003466,0.005520,0.140204,263.542480,13.425493,1.402039,-87.805397,0.140283,0.000000
125.870003,59.213928,-87.760918,0.003479,0.005520,0.140204,263.396698,13.418068,1.402039,-87.760918,0.140283,0.000000
126.180008,59.207970,-87.760918,0.003475,0.005520,0.140204,263.370209,13.416718,1.402039,-87.760918,0.140283,0.000000
126.490005,59.174080,-87.805397,0.003462,0.005520,0.140204,263.219452,13.409039,1.402039,-87.805397,0.140283,0.000000
126.800003,59.158440,-87.760918,0.003471,0.005520,0.140204,263.149872,13.405495,1.402039,-87.760918,0.140283,0.000000
127.110008,59.126045,-87.894356,0.003466,0.005520,0.140204,263.005798,13.398153,1.402039,-87.894356,0.140283,0.000000
127.420006,59.124931,-87.760918,0.003466,0.005520,0.140204,263.000824,13.397902,1.402039,-87.760918,0.140283,0.000000
127.730003,59.096252,-87.894356,0.003497,0.005520,0.140204,262.873260,13.391402,1.402039,-87.894356,0.140283,0.000000
128.040009,59.063858,-87.849876,0.003471,0.005520,0.140204,262.729156,13.384061,1.402039,-87.849876,0.140283,0.000000
128.350006,59.061623,-87.894356,0.003484,0.005520,0.140204,262.719208,13.383554,1.402039,-87.894356,0.140283,0.000000
128.660004,59.035934,-87.849876,0.003475,0.005520,0.140204,262.604950,13.377734,1.402039,-87.849876,0.140283,0.000000
128.970001,59.020660,-87.849876,0.003475,0.005520,0.140204,262.537018,13.374272,1.402039,-87.849876,0.140283,0.000000
129.279999,58.988266,-87.938843,0.003471,0.005520,0.140204,262.392914,13.366932,1.402039,-87.938843,0.140283,0.000000
129.590012,58.981194,-87.894356,0.003471,0.005520,0.140204,262.361450,13.365330,1.402039,-87.894356,0.140283,0.000000
129.900009,58.960342,-87.894356,0.003475,0.005520,0.140204,262.268707,13.360604,1.402039,-87.894356,0.140283,0.000000
130.210007,58.932785,-87.983322,0.003471,0.005520,0.140204,262.146118,13.354361,1.402039,-87.983322,0.140283,0.000000
130.520004,58.924965,-87.938843,0.003488,0.005520,0.140204,262.111328,13.352588,1.402039,-87.938843,0.140283,0.000000
130.830002,58.897408,-87.938843,0.003488,0.005520,0.140204,261.988739,13.346343,1.402039,-87.938843,0.140283,0.000000
131.139999,58.874695,-87.938843,0.003484,0.005520,0.140204,261.887726,13.341196,1.402039,-87.938843,0.140283,0.000000
131.300003,58.884003,-87.894356,0.003488,0.005520,0.140204,261.929138,13.343306,1.402039,-87.894356,0.140283,0.000000