File: Data/compression 6/AutoNoheating-10-6-day3-4-240301_03012024_155819.csv
Time (sec),S:Load (lbs),S:HL1 (DIM),S:LVDT (in),S:Position (in),Ch:Position (mm),Ch:Load (N),Ch:Stress (MPa),Ch:Strain (mm/mm),Ch:HL1 (DIM),Set Point (),Cycles ()
0.110000,-0.018616,-155.238525,0.000000,-0.000000,-0.000000,-0.082807,-0.004218,-0.000000,-155.238525,0.000208,0.000000
0.360000,-0.001488,-155.194031,0.000000,-0.000000,-0.000000,-0.006618,-0.000337,-0.000000,-155.194031,0.000208,0.000000
0.610000,-0.005959,-155.283005,0.000000,0.000123,0.003131,-0.026505,-0.001350,0.031309,-155.283005,0.004042,0.000000
0.860000,-0.010796,-155.283005,0.000160,0.000283,0.007181,-0.048021,-0.002446,0.071807,-155.283005,0.008204,0.000000
1.110000,0.004845,-155.327484,0.000315,0.000442,0.011222,0.021550,0.001098,0.112222,-155.327484,0.012367,0.000000
1.360000,0.009682,-155.416443,0.000487,0.000613,0.015558,0.043066,0.002194,0.155582,-155.416443,0.016529,0.000000
1.610000,-0.033882,-155.371964,0.000642,0.000772,0.019608,-0.150715,-0.007678,0.196080,-155.371964,0.020692,0.000000
1.860000,-0.002235,-155.371964,0.000806,0.000939,0.023849,-0.009944,-0.000507,0.238490,-155.371964,0.024855,0.000000
2.110000,-0.006325,-155.371964,0.000974,0.001090,0.027682,-0.028134,-0.001433,0.276820,-155.371964,0.029018,0.000000
2.360000,-0.051758,-155.460922,0.001155,0.001266,0.032157,-0.230230,-0.011728,0.321568,-155.460922,0.033198,0.000000
2.610000,0.002983,-155.505402,0.001324,0.001433,0.036397,0.013269,0.000676,0.363974,-155.505402,0.037360,0.000000
2.860000,0.032028,-155.460922,0.001466,0.001591,0.040404,0.142469,0.007258,0.404041,-155.460922,0.041523,0.000000
3.110000,0.047295,-155.549881,0.001673,0.001762,0.044758,0.210377,0.010717,0.447575,-155.549881,0.045686,0.000000
3.360000,-0.001114,-155.594360,0.001819,0.001920,0.048764,-0.004955,-0.000252,0.487642,-155.594360,0.049848,0.000000
3.610000,0.007446,-155.638855,0.001979,0.002086,0.052988,0.033123,0.001687,0.529878,-155.638855,0.054011,0.000000
3.860000,-0.005959,-155.594360,0.002147,0.002245,0.057011,-0.026505,-0.001350,0.570115,-155.594360,0.058173,0.000000
4.110000,-0.048782,-155.683334,0.002302,0.002411,0.061235,-0.216995,-0.011054,0.612351,-155.683334,0.062336,0.000000
4.360000,-0.036118,-155.638855,0.002475,0.002579,0.065519,-0.160659,-0.008184,0.655192,-155.638855,0.066516,0.000000
4.610000,0.048035,-155.727814,0.002639,0.002737,0.069517,0.213669,0.010885,0.695168,-155.727814,0.070679,0.000000
4.860000,0.023834,-155.683334,0.002815,0.002908,0.073871,0.106020,0.005401,0.738706,-155.683334,0.074842,0.000000
5.110000,-0.007446,-155.772293,0.002962,0.003066,0.077877,-0.033123,-0.001687,0.778769,-155.772293,0.079004,0.000000
5.360000,0.006706,-155.727814,0.003126,0.003233,0.082127,0.029831,0.001520,0.821265,-155.727814,0.083167,0.000000
5.610000,0.011169,-155.772293,0.003316,0.003398,0.086315,0.049684,0.002531,0.863153,-155.772293,0.087330,0.000000
5.860000,-0.028297,-155.816772,0.003479,0.003560,0.090426,-0.125873,-0.006412,0.904257,-155.816772,0.091492,0.000000
6.110000,0.001862,-155.861252,0.003622,0.003721,0.094502,0.008281,0.000422,0.945016,-155.861252,0.095655,0.000000
6.360000,0.015266,-155.905731,0.003811,0.003882,0.098604,0.067908,0.003459,0.986037,-155.905731,0.099835,0.000000
6.610000,-0.008934,-155.861252,0.003962,0.004054,0.102974,-0.039741,-0.002024,1.029745,-155.861252,0.103998,0.000000
6.860000,-0.006699,-155.861252,0.004152,0.004218,0.107137,-0.029797,-0.001518,1.071371,-155.861252,0.108161,0.000000
7.110000,0.030907,-155.905731,0.004294,0.004381,0.111274,0.137480,0.007004,1.112740,-155.905731,0.112323,0.000000
7.360000,0.036491,-155.994690,0.004467,0.004548,0.115515,0.162322,0.008269,1.155146,-155.994690,0.116486,0.000000
7.610000,0.007446,-155.994690,0.004648,0.004707,0.119547,0.033123,0.001687,1.195470,-155.994690,0.120648,0.000000
7.860001,0.002609,-156.039169,0.004812,0.004872,0.123753,0.011607,0.000591,1.237532,-156.039169,0.124811,0.000000
8.110001,0.021973,-155.994690,0.004984,0.005031,0.127794,0.097739,0.004979,1.277943,-155.994690,0.128991,0.000000
8.360001,0.003357,-156.128143,0.005126,0.005199,0.132053,0.014932,0.000761,1.320527,-156.128143,0.133154,0.000000
8.610001,-0.044312,-156.083664,0.005286,0.005362,0.136189,-0.197107,-0.010041,1.361892,-156.083664,0.137317,0.000000
8.860001,0.033142,-156.128143,0.005471,0.005527,0.140378,0.147423,0.007510,1.403780,-156.128143,0.141479,0.000000
9.110001,0.028671,-156.128143,0.005635,0.005693,0.144593,0.127536,0.006497,1.445928,-156.128143,0.145642,0.000000
9.360001,0.006332,-156.172623,0.005790,0.005855,0.148712,0.028168,0.001435,1.487119,-156.172623,0.149805,0.000000
9.610001,0.038727,-156.217102,0.005963,0.006020,0.152918,0.172265,0.008776,1.529181,-156.217102,0.153967,0.000000
9.860001,0.115807,-156.217102,0.006109,0.006183,0.157046,0.515133,0.026242,1.570459,-156.217102,0.158130,0.000000
10.110001,0.248375,-156.306061,0.006286,0.006350,0.161287,1.104827,0.056283,1.612869,-156.306061,0.162310,0.000000
10.360001,0.758522,-156.261581,0.006433,0.006490,0.164851,3.374074,0.171884,1.648511,-156.261581,0.166108,0.000000
10.610001,0.593933,-156.306061,0.006454,-0.000000,-0.000000,2.641946,0.134587,-0.000000,-156.306061,0.000217,0.000000
10.860001,0.562286,-156.350540,0.006437,-0.000000,-0.000000,2.501175,0.127416,-0.000000,-156.350540,0.000217,0.000000
11.110001,0.577553,-156.350540,0.006437,-0.000000,-0.000000,2.569083,0.130875,-0.000000,-156.350540,0.000581,0.000000
11.360001,0.571968,-156.439499,0.006446,0.000000,0.000009,2.544241,0.129610,0.000087,-156.439499,0.000997,0.000000
11.610001,0.673996,-156.439499,0.006446,0.000019,0.000494,2.998084,0.152730,0.004943,-156.439499,0.001414,0.000000
11.860001,0.791664,-156.439499,0.006450,0.000036,0.000911,3.521498,0.179394,0.009106,-156.439499,0.001830,0.000000
12.110001,0.888107,-156.439499,0.006493,0.000052,0.001327,3.950499,0.201248,0.013270,-156.439499,0.002246,0.000000
12.360001,0.944336,-156.439499,0.006493,0.000062,0.001570,4.200616,0.213990,0.015696,-156.439499,0.002662,0.000000
12.610001,1.087326,-156.528473,0.006519,0.000088,0.002246,4.836668,0.246392,0.022460,-156.528473,0.003079,0.000000
12.860001,1.181915,-156.528473,0.006528,0.000103,0.002627,5.257422,0.267826,0.026275,-156.528473,0.003495,0.000000
13.110001,1.229576,-156.617432,0.006541,0.000121,0.003061,5.469428,0.278626,0.030612,-156.617432,0.003911,0.000000
13.360001,1.301819,-156.661911,0.006562,0.000131,0.003330,5.790780,0.294996,0.033300,-156.661911,0.004327,0.000000
13.610001,1.492096,-156.706390,0.006566,0.000151,0.003842,6.637174,0.338114,0.038417,-156.706390,0.004744,0.000000
13.860001,1.610886,-156.661911,0.006597,0.000170,0.004319,7.165577,0.365032,0.043186,-156.661911,0.005160,0.000000
14.110001,1.614983,-156.661911,0.006605,0.000177,0.004501,7.183801,0.365960,0.045010,-156.661911,0.005576,0.000000
14.360001,1.723343,-156.750870,0.006614,0.000189,0.004813,7.665812,0.390515,0.048129,-156.750870,0.005993,0.000000
14.610001,1.953094,-156.795349,0.006640,0.000220,0.005585,8.687799,0.442578,0.055850,-156.795349,0.006417,0.000000
14.860001,2.023476,-156.750870,0.006674,0.000234,0.005932,9.000869,0.458526,0.059317,-156.750870,0.006834,0.000000
15.110001,2.069275,-156.795349,0.006683,0.000249,0.006313,9.204595,0.468904,0.063132,-156.795349,0.007250,0.000000
15.360001,2.219345,-156.839828,0.006709,0.000267,0.006782,9.872140,0.502911,0.067818,-156.839828,0.007666,0.000000
15.610001,2.372017,-156.884308,0.006700,0.000282,0.007155,10.551258,0.537507,0.071546,-156.884308,0.008083,0.000000
15.860001,2.454308,-156.884308,0.006717,0.000297,0.007545,10.917305,0.556154,0.075448,-156.884308,0.008499,0.000000
16.110001,2.530273,-156.928802,0.006722,0.000312,0.007918,11.255219,0.573368,0.079176,-156.928802,0.008915,0.000000
16.360001,2.720924,-156.973282,0.006748,0.000333,0.008455,12.103276,0.616570,0.084555,-156.973282,0.009331,0.000000
16.610001,2.846786,-156.973282,0.006769,0.000351,0.008924,12.663138,0.645091,0.089236,-156.973282,0.009748,0.000000
16.860001,2.850510,-157.062241,0.006778,0.000363,0.009210,12.679700,0.645935,0.092098,-157.062241,0.010164,0.000000
17.110001,2.939140,-157.017761,0.006799,0.000379,0.009635,13.073949,0.666019,0.096348,-157.017761,0.010580,0.000000
17.360001,3.037445,-157.017761,0.006825,0.000394,0.010016,13.511230,0.688295,0.100163,-157.017761,0.010996,0.000000
17.610001,3.282463,-157.062241,0.006838,0.000415,0.010537,14.601125,0.743817,0.105368,-157.062241,0.011413,0.000000
17.860001,3.324547,-157.106720,0.006825,0.000430,0.010910,14.788322,0.753353,0.109096,-157.106720,0.011829,0.000000
18.110001,3.401627,-157.151199,0.006847,0.000442,0.011222,15.131190,0.770820,0.112218,-157.151199,0.012245,0.000000
18.360001,3.584084,-157.151199,0.006885,0.000466,0.011838,15.942800,0.812165,0.118376,-157.151199,0.012662,0.000000
18.610001,3.609039,-157.195679,0.006885,0.000479,0.012159,16.053808,0.817820,0.121586,-157.195679,0.013078,0.000000
18.860001,3.639572,-157.240158,0.006903,0.000496,0.012592,16.189625,0.824739,0.125920,-157.240158,0.013494,0.000000
19.110001,3.750908,-157.240158,0.006924,0.000512,0.013000,16.684872,0.849968,0.129996,-157.240158,0.013910,0.000000
19.360001,3.859268,-157.284637,0.006950,0.000531,0.013485,17.166882,0.874523,0.134852,-157.284637,0.014327,0.000000
19.610001,3.963531,-157.284637,0.006963,0.000548,0.013910,17.630669,0.898149,0.139102,-157.284637,0.014743,0.000000
19.860001,3.957573,-157.329117,0.006980,0.000558,0.014179,17.604164,0.896799,0.141790,-157.329117,0.015168,0.000000
20.110001,4.043221,-157.329117,0.006993,0.000573,0.014543,17.985144,0.916207,0.145435,-157.329117,0.015584,0.000000
20.360001,4.236481,-157.373611,0.006998,0.000597,0.015159,18.844807,0.960000,0.151589,-157.373611,0.016000,0.000000
20.610001,4.230156,-157.418091,0.007023,0.000610,0.015506,18.816673,0.958567,0.155060,-157.418091,0.016417,0.000000
20.860001,4.299789,-157.418091,0.007036,0.000629,0.015983,19.126419,0.974346,0.159829,-157.418091,0.016833,0.000000
21.110001,4.342239,-157.418091,0.007067,0.000644,0.016364,19.315245,0.983965,0.163644,-157.418091,0.017249,0.000000
21.360001,4.485229,-157.462570,0.007080,0.000662,0.016816,19.951298,1.016368,0.168155,-157.462570,0.017665,0.000000
21.610001,4.532150,-157.551529,0.007092,0.000679,0.017249,20.160011,1.027000,0.172489,-157.551529,0.018082,0.000000
21.860001,4.512039,-157.596008,0.007105,0.000686,0.017414,20.070553,1.022443,0.174139,-157.596008,0.018498,0.000000
22.110001,4.775307,-157.551529,0.007123,0.000715,0.018160,21.241625,1.082100,0.181595,-157.551529,0.018914,0.000000
22.360001,4.852760,-157.640488,0.007127,0.000734,0.018636,21.586157,1.099651,0.186364,-157.640488,0.019330,0.000000
22.610001,4.767860,-157.596008,0.007136,0.000746,0.018940,21.208502,1.080413,0.189400,-157.596008,0.019747,0.000000
22.860001,4.790199,-157.640488,0.007174,0.000761,0.019330,21.307871,1.085475,0.193302,-157.640488,0.020163,0.000000
23.110001,4.867279,-157.729446,0.007200,0.000774,0.019660,21.650738,1.102941,0.196599,-157.729446,0.020579,0.000000
23.360001,5.042671,-157.729446,0.007226,0.000794,0.020172,22.430922,1.142686,0.201716,-157.729446,0.020996,0.000000
23.610001,5.091820,-157.729446,0.007217,0.000811,0.020588,22.649546,1.153823,0.205879,-157.729446,0.021412,0.000000
23.860001,5.181564,-157.729446,0.007248,0.000826,0.020978,23.048750,1.174159,0.209782,-157.729446,0.021828,0.000000
24.110001,5.226250,-157.773926,0.007252,0.000843,0.021420,23.247520,1.184285,0.214202,-157.773926,0.022244,0.000000
24.360001,5.296997,-157.818420,0.007256,0.000861,0.021871,23.562220,1.200317,0.218714,-157.818420,0.022661,0.000000
24.610001,5.255295,-157.862900,0.007291,0.000875,0.022218,23.376719,1.190867,0.222181,-157.862900,0.023077,0.000000
24.860001,5.311523,-157.907379,0.007286,0.000889,0.022591,23.626837,1.203608,0.225913,-157.907379,0.023502,0.000000
25.110001,5.410576,-157.862900,0.007312,0.000906,0.023016,24.067444,1.226054,0.230159,-157.862900,0.023918,0.000000
25.360001,5.514091,-157.907379,0.007330,0.000922,0.023424,24.527905,1.249511,0.234236,-157.907379,0.024334,0.000000
25.610001,5.501808,-157.907379,0.007334,0.000936,0.023762,24.473265,1.246727,0.237619,-157.907379,0.024751,0.000000
25.860001,5.623573,-158.040817,0.007355,0.000953,0.024196,25.014904,1.274320,0.241957,-158.040817,0.025167,0.000000
26.110001,5.803055,-157.996338,0.007373,0.000975,0.024759,25.813276,1.314991,0.247593,-157.996338,0.025583,0.000000
26.360001,5.770287,-158.040817,0.007394,0.000990,0.025158,25.667517,1.307566,0.251582,-158.040817,0.025999,0.000000
26.610001,5.782204,-158.040817,0.007407,0.001006,0.025540,25.720526,1.310266,0.255397,-158.040817,0.026416,0.000000
26.860001,5.925934,-158.129776,0.007442,0.001025,0.026034,26.359871,1.342836,0.260340,-158.129776,0.026832,0.000000
27.110001,5.970993,-158.174255,0.007433,0.001042,0.026459,26.560303,1.353046,0.264591,-158.174255,0.027248,0.000000
27.360001,6.013069,-158.129776,0.007480,0.001058,0.026867,26.747467,1.362581,0.268667,-158.129776,0.027665,0.000000
27.610001,5.973228,-158.174255,0.007463,0.001068,0.027118,26.570248,1.353553,0.271180,-158.174255,0.028081,0.000000
27.860001,6.106537,-158.263229,0.007485,0.001088,0.027630,27.163233,1.383761,0.276297,-158.263229,0.028497,0.000000
28.110001,6.231285,-158.218750,0.007506,0.001106,0.028081,27.718140,1.412029,0.280809,-158.218750,0.028913,0.000000
28.360001,6.215271,-158.218750,0.007528,0.001120,0.028436,27.646906,1.408401,0.284363,-158.218750,0.029330,0.000000
28.610001,6.298309,-158.307709,0.007541,0.001139,0.028922,28.016279,1.427217,0.289219,-158.307709,0.029746,0.000000
28.860001,6.307991,-158.352188,0.007554,0.001152,0.029269,28.059345,1.429411,0.292690,-158.352188,0.030162,0.000000
29.110001,6.347092,-158.352188,0.007562,0.001168,0.029668,28.233274,1.438272,0.296679,-158.352188,0.030578,0.000000
29.360001,6.499763,-158.396667,0.007597,0.001186,0.030127,28.912392,1.472867,0.301274,-158.396667,0.030995,0.000000
29.610001,6.412254,-158.396667,0.007580,0.001196,0.030370,28.523132,1.453038,0.303700,-158.396667,0.031411,0.000000
29.860001,6.693771,-158.441147,0.007627,0.001221,0.031021,29.775383,1.516830,0.310206,-158.441147,0.031836,0.000000
30.110001,6.703827,-158.441147,0.007631,0.001237,0.031420,29.820112,1.519109,0.314195,-158.441147,0.032252,0.000000
30.360001,6.767502,-158.485626,0.007666,0.001254,0.031845,30.103352,1.533538,0.318446,-158.485626,0.032668,0.000000
30.610001,6.745903,-158.530106,0.007675,0.001267,0.032183,30.007275,1.528643,0.321826,-158.530106,0.033085,0.000000
30.860001,6.838249,-158.530106,0.007700,0.001284,0.032616,30.418051,1.549569,0.326163,-158.530106,0.033501,0.000000
31.110001,6.884048,-158.574585,0.007700,0.001299,0.032998,30.621777,1.559948,0.329978,-158.574585,0.033917,0.000000
31.360001,6.991295,-158.619064,0.007713,0.001318,0.033466,31.098833,1.584250,0.334660,-158.619064,0.034334,0.000000
31.610001,7.052361,-158.574585,0.007748,0.001332,0.033822,31.370466,1.598088,0.338218,-158.574585,0.034749,0.000000
31.860001,7.156998,-158.708038,0.007743,0.001351,0.034316,31.835917,1.621799,0.343161,-158.708038,0.035166,0.000000
32.110001,7.219559,-158.619064,0.007752,0.001366,0.034706,32.114201,1.635975,0.347064,-158.619064,0.035582,0.000000
32.360001,7.237061,-158.708038,0.007774,0.001383,0.035123,32.192055,1.639941,0.351227,-158.708038,0.035999,0.000000
32.610001,7.213600,-158.708038,0.007791,0.001395,0.035443,32.087696,1.634625,0.354433,-158.708038,0.036415,0.000000
32.860001,7.173386,-158.752518,0.007808,0.001410,0.035808,31.908813,1.625512,0.358078,-158.752518,0.036831,0.000000
33.110001,7.428459,-158.796997,0.007821,0.001428,0.036267,33.043438,1.683313,0.362672,-158.796997,0.037247,0.000000
33.360001,7.530861,-158.796997,0.007830,0.001445,0.036701,33.498943,1.706517,0.367010,-158.796997,0.037663,0.000000
33.610001,7.459366,-158.841476,0.007851,0.001459,0.037065,33.180916,1.690316,0.370651,-158.841476,0.038080,0.000000
33.860001,7.733803,-158.841476,0.007877,0.001481,0.037620,34.401672,1.752505,0.376203,-158.841476,0.038496,0.000000
34.110001,7.758385,-158.885956,0.007907,0.001496,0.038002,34.511021,1.758075,0.380019,-158.885956,0.038913,0.000000
34.360001,7.743484,-158.930435,0.007907,0.001509,0.038331,34.444740,1.754699,0.383311,-158.930435,0.039328,0.000000
34.610001,7.754288,-158.974915,0.007925,0.001528,0.038808,34.492794,1.757147,0.388084,-158.974915,0.039745,0.000000
34.860001,7.860413,-158.930435,0.007929,0.001543,0.039190,34.964863,1.781195,0.391899,-158.930435,0.040161,0.000000
35.110001,8.179161,-158.974915,0.007950,0.001564,0.039719,36.382725,1.853424,0.397191,-158.974915,0.040586,0.000000
35.360001,8.067825,-159.063889,0.007972,0.001574,0.039988,35.887478,1.828195,0.399878,-159.063889,0.041003,0.000000
35.610001,8.067825,-159.108368,0.007985,0.001587,0.040317,35.887478,1.828195,0.403171,-159.108368,0.041418,0.000000
35.860001,8.448387,-159.152847,0.008011,0.001613,0.040976,37.580303,1.914432,0.409764,-159.152847,0.041835,0.000000
36.110001,8.448013,-159.108368,0.008011,0.001630,0.041393,37.578640,1.914347,0.413927,-159.108368,0.042251,0.000000
36.360001,8.388435,-159.152847,0.008041,0.001644,0.041748,37.313625,1.900847,0.417481,-159.152847,0.042667,0.000000
36.610001,8.361626,-159.197327,0.008058,0.001657,0.042078,37.194370,1.894771,0.420778,-159.197327,0.043084,0.000000
36.860001,8.691551,-159.241806,0.008063,0.001679,0.042659,38.661949,1.969534,0.426588,-159.241806,0.043500,0.000000
37.110001,8.587654,-159.241806,0.008084,0.001692,0.042971,38.199795,1.945990,0.429710,-159.241806,0.043916,0.000000
37.360001,8.553772,-159.241806,0.008097,0.001703,0.043248,38.049080,1.938313,0.432485,-159.241806,0.044332,0.000000
37.610001,8.625641,-159.286285,0.008114,0.001716,0.043587,38.368767,1.954598,0.435869,-159.286285,0.044749,0.000000
37.860001,9.103394,-159.286285,0.008140,0.001745,0.044332,40.493916,2.062859,0.443325,-159.286285,0.045165,0.000000
38.110001,9.016258,-159.286285,0.008149,0.001758,0.044645,40.106319,2.043113,0.446447,-159.286285,0.045581,0.000000
38.360001,9.087379,-159.375244,0.008153,0.001777,0.045139,40.422684,2.059230,0.451390,-159.375244,0.045997,0.000000
38.610001,8.932472,-159.419724,0.008179,0.001787,0.045390,39.733620,2.024127,0.453904,-159.419724,0.046414,0.000000
38.860001,9.281013,-159.375244,0.008183,0.001807,0.045902,41.284008,2.103108,0.459021,-159.375244,0.046830,0.000000
39.110001,9.450439,-159.375244,0.008201,0.001826,0.046371,42.037655,2.141500,0.463706,-159.375244,0.047246,0.000000
39.360001,9.561783,-159.464203,0.008226,0.001840,0.046743,42.532936,2.166731,0.467435,-159.464203,0.047663,0.000000
39.610001,9.671257,-159.464203,0.008226,0.001859,0.047212,43.019901,2.191538,0.472116,-159.464203,0.048079,0.000000
39.860001,9.804939,-159.508698,0.008248,0.001876,0.047654,43.614548,2.221831,0.476541,-159.508698,0.048495,0.000000
40.110001,9.723389,-159.553177,0.008257,0.001889,0.047975,43.251793,2.203351,0.479747,-159.553177,0.048920,0.000000
40.360001,9.861168,-159.508698,0.008282,0.001905,0.048391,43.864666,2.234573,0.483910,-159.508698,0.049336,0.000000
40.610001,10.084969,-159.553177,0.008300,0.001925,0.048903,44.860180,2.285286,0.489027,-159.553177,0.049753,0.000000
40.860001,10.162788,-159.597656,0.008304,0.001942,0.049328,45.206341,2.302921,0.493278,-159.597656,0.050169,0.000000
41.110001,10.162422,-159.686615,0.008326,0.001955,0.049666,45.204712,2.302838,0.496658,-159.686615,0.050585,0.000000
41.360001,10.306900,-159.686615,0.008343,0.001971,0.050065,45.847382,2.335577,0.500647,-159.686615,0.051001,0.000000
41.610001,10.433136,-159.775574,0.008369,0.001990,0.050542,46.408905,2.364182,0.505420,-159.775574,0.051418,0.000000
41.860001,10.604797,-159.731094,0.008373,0.002006,0.050958,47.172493,2.403081,0.509583,-159.731094,0.051834,0.000000
42.110001,10.697517,-159.775574,0.008390,0.002025,0.051427,47.584934,2.424092,0.514265,-159.775574,0.052250,0.000000
42.360001,10.731773,-159.864532,0.008412,0.002038,0.051773,47.737312,2.431854,0.517732,-159.864532,0.052666,0.000000
42.610001,10.888916,-159.820053,0.008433,0.002057,0.052259,48.436317,2.467464,0.522588,-159.820053,0.053083,0.000000
42.860001,11.004356,-159.864532,0.008438,0.002070,0.052588,48.949821,2.493623,0.525885,-159.864532,0.053499,0.000000
43.110001,11.021111,-159.864532,0.008446,0.002084,0.052936,49.024349,2.497419,0.529355,-159.864532,0.053915,0.000000
43.360001,11.338745,-159.864532,0.008481,0.002107,0.053508,50.437256,2.569396,0.535078,-159.864532,0.054332,0.000000
43.610001,11.578552,-159.953506,0.008502,0.002126,0.054002,51.503971,2.623737,0.540021,-159.953506,0.054748,0.000000
43.860001,11.653770,-159.953506,0.008511,0.002142,0.054401,51.838558,2.640782,0.544011,-159.953506,0.055164,0.000000
44.110001,11.507057,-160.042465,0.008520,0.002154,0.054705,51.185947,2.607537,0.547046,-160.042465,0.055580,0.000000
44.360001,11.557327,-160.042465,0.008528,0.002167,0.055034,51.409561,2.618928,0.550343,-160.042465,0.055997,0.000000
44.610001,11.803467,-159.997986,0.008550,0.002183,0.055459,52.504444,2.674704,0.554589,-159.997986,0.056413,0.000000
44.860001,12.137108,-160.042465,0.008563,0.002206,0.056031,53.988552,2.750308,0.560312,-160.042465,0.056829,0.000000
45.110001,11.899910,-160.131424,0.008584,0.002214,0.056239,52.933445,2.696558,0.562394,-160.131424,0.057254,0.000000
45.360001,12.279358,-160.131424,0.008593,0.002235,0.056769,54.621311,2.782542,0.567685,-160.131424,0.057670,0.000000
45.610001,12.677048,-160.131424,0.008606,0.002256,0.057306,56.390324,2.872660,0.573063,-160.131424,0.058087,0.000000
45.860001,12.585075,-160.131424,0.008627,0.002268,0.057619,55.981213,2.851819,0.576186,-160.131424,0.058503,0.000000
46.110001,12.700882,-160.175903,0.008640,0.002285,0.058035,56.496346,2.878061,0.580346,-160.175903,0.058919,0.000000
46.360001,12.790627,-160.175903,0.008662,0.002300,0.058408,56.895550,2.898397,0.584077,-160.175903,0.059335,0.000000
46.610001,13.063202,-160.264862,0.008658,0.002319,0.058902,58.108025,2.960164,0.589020,-160.264862,0.059752,0.000000
46.860001,13.203957,-160.353836,0.008688,0.002334,0.059275,58.734131,2.992059,0.592749,-160.353836,0.060168,0.000000
47.110001,13.132088,-160.309341,0.008701,0.002346,0.059578,58.414444,2.975774,0.595784,-160.309341,0.060584,0.000000
47.360001,13.537971,-160.309341,0.008696,0.002365,0.060081,60.219906,3.067748,0.600814,-160.309341,0.061001,0.000000
47.610001,13.950935,-160.353836,0.008735,0.002385,0.060584,62.056858,3.161327,0.605844,-160.353836,0.061417,0.000000
47.860001,13.828796,-160.398315,0.008739,0.002398,0.060905,61.513557,3.133650,0.609050,-160.398315,0.061833,0.000000
48.110001,13.949448,-160.442795,0.008765,0.002415,0.061339,62.050243,3.160990,0.613388,-160.442795,0.062249,0.000000
48.360001,14.288307,-160.442795,0.008774,0.002434,0.061824,63.557564,3.237777,0.618244,-160.442795,0.062666,0.000000
48.610001,14.546730,-160.487274,0.008787,0.002453,0.062319,64.707085,3.296336,0.623187,-160.487274,0.063082,0.000000
48.860001,14.472260,-160.442795,0.008791,0.002465,0.062605,64.375824,3.279461,0.626048,-160.442795,0.063498,0.000000
49.110001,14.634239,-160.487274,0.008808,0.002481,0.063021,65.096344,3.316166,0.630212,-160.487274,0.063914,0.000000
49.360001,14.796967,-160.531754,0.008830,0.002497,0.063411,65.820198,3.353041,0.634114,-160.531754,0.064331,0.000000
49.610001,15.160774,-160.531754,0.008856,0.002516,0.063897,67.438492,3.435481,0.638970,-160.531754,0.064747,0.000000
49.860001,15.404678,-160.620712,0.008864,0.002533,0.064331,68.523430,3.490750,0.643307,-160.620712,0.065163,0.000000
50.110001,15.561821,-160.576233,0.008886,0.002549,0.064738,69.222435,3.526359,0.647384,-160.576233,0.065579,0.000000
50.360001,15.466118,-160.709671,0.008890,0.002560,0.065016,68.796730,3.504672,0.650158,-160.709671,0.066004,0.000000
50.610001,15.938286,-160.665192,0.008916,0.002581,0.065545,70.897034,3.611667,0.655449,-160.665192,0.066421,0.000000
50.860001,15.804237,-160.665192,0.008933,0.002590,0.065796,70.300758,3.581291,0.657962,-160.665192,0.066837,0.000000
51.110001,16.473763,-160.754150,0.008925,0.002613,0.066369,73.278954,3.733008,0.663689,-160.754150,0.067253,0.000000
51.360001,16.610794,-160.754150,0.008951,0.002629,0.066776,73.888504,3.764060,0.667761,-160.754150,0.067669,0.000000
51.610001,16.756020,-160.798645,0.008977,0.002647,0.067236,74.534500,3.796968,0.672360,-160.798645,0.068086,0.000000
51.860001,16.963058,-160.798645,0.008990,0.002662,0.067609,75.455452,3.843884,0.676088,-160.798645,0.068502,0.000000
52.110001,17.168236,-160.843124,0.008990,0.002678,0.068025,76.368126,3.890378,0.680252,-160.843124,0.068918,0.000000
52.360001,17.442673,-160.843124,0.009002,0.002693,0.068407,77.588882,3.952566,0.684067,-160.843124,0.069335,0.000000
52.610001,17.629974,-160.932083,0.009033,0.002709,0.068797,78.422043,3.995009,0.687969,-160.932083,0.069751,0.000000
52.860001,17.833664,-160.932083,0.009046,0.002726,0.069239,79.328102,4.041166,0.692394,-160.932083,0.070167,0.000000
53.110004,17.736473,-160.932083,0.009046,0.002737,0.069517,78.895775,4.019142,0.695168,-160.932083,0.070583,0.000000
53.360004,18.531860,-161.021042,0.009067,0.002760,0.070098,82.433830,4.199379,0.700978,-161.021042,0.071000,0.000000
53.610004,18.680435,-161.021042,0.009080,0.002775,0.070488,83.094727,4.233047,0.704880,-161.021042,0.071416,0.000000
53.860004,18.883751,-161.021042,0.009110,0.002792,0.070913,83.999123,4.279119,0.709130,-161.021042,0.071832,0.000000
54.110004,18.860298,-161.154480,0.009106,0.002802,0.071182,83.894798,4.273805,0.711818,-161.154480,0.072248,0.000000
54.360004,19.445663,-161.065521,0.009119,0.002823,0.071693,86.498634,4.406450,0.716935,-161.065521,0.072665,0.000000
54.610004,19.795692,-161.110001,0.009136,0.002841,0.072170,88.055641,4.485768,0.721704,-161.110001,0.073081,0.000000
54.860004,19.904053,-161.154480,0.009166,0.002853,0.072474,88.537651,4.510323,0.724739,-161.154480,0.073497,0.000000
55.110004,19.851921,-161.198959,0.009149,0.002869,0.072864,88.305756,4.498509,0.728642,-161.198959,0.073914,0.000000
55.360004,20.810036,-161.198959,0.009179,0.002890,0.073402,92.567665,4.715621,0.734020,-161.198959,0.074338,0.000000
55.610004,21.017448,-161.243454,0.009201,0.002905,0.073792,93.490280,4.762622,0.737922,-161.243454,0.074755,0.000000
55.860004,21.277740,-161.287933,0.009209,0.002922,0.074217,94.648117,4.821605,0.742172,-161.287933,0.075171,0.000000
56.110004,21.114265,-161.243454,0.009218,0.002934,0.074512,93.920944,4.784561,0.745121,-161.243454,0.075587,0.000000
56.360004,21.862732,-161.287933,0.009240,0.002955,0.075050,97.250290,4.954166,0.750495,-161.287933,0.076004,0.000000
56.610004,22.248138,-161.376892,0.009244,0.002970,0.075448,98.964661,5.041500,0.754485,-161.376892,0.076420,0.000000
56.860004,22.338997,-161.376892,0.009265,0.002982,0.075752,99.368820,5.062089,0.757520,-161.376892,0.076836,0.000000
57.110004,22.216118,-161.376892,0.009257,0.002993,0.076021,98.822227,5.034244,0.760211,-161.376892,0.077252,0.000000
57.360004,23.791252,-161.465851,0.009287,0.003025,0.076827,105.828773,5.391175,0.768273,-161.465851,0.077669,0.000000
57.610004,23.566711,-161.421371,0.009317,0.003035,0.077096,104.829971,5.340293,0.770964,-161.421371,0.078085,0.000000
57.860004,23.860886,-161.465851,0.009313,0.003054,0.077573,106.138519,5.406954,0.775733,-161.465851,0.078501,0.000000
58.110004,24.134575,-161.465851,0.009334,0.003066,0.077877,107.355949,5.468973,0.778769,-161.465851,0.078917,0.000000
58.360004,24.661484,-161.510330,0.009347,0.003084,0.078336,109.699760,5.588372,0.783364,-161.510330,0.079334,0.000000
58.610004,24.876717,-161.510330,0.009373,0.003098,0.078692,110.657166,5.637145,0.786921,-161.510330,0.079750,0.000000
58.860004,25.271057,-161.554810,0.009378,0.003112,0.079048,112.411278,5.726503,0.790475,-161.554810,0.080166,0.000000
59.110004,26.306625,-161.643784,0.009382,0.003138,0.079706,117.017715,5.961166,0.797065,-161.643784,0.080583,0.000000
59.360004,26.734482,-161.643784,0.009399,0.003155,0.080132,118.920914,6.058120,0.801315,-161.643784,0.080999,0.000000
59.610004,26.897957,-161.688263,0.009425,0.003170,0.080522,119.648087,6.095164,0.805218,-161.688263,0.081415,0.000000
59.860004,26.979134,-161.688263,0.009425,0.003182,0.080817,120.009178,6.113559,0.808166,-161.688263,0.081831,0.000000
60.110004,27.354111,-161.732742,0.009442,0.003199,0.081250,121.677162,6.198530,0.812503,-161.732742,0.082248,0.000000
60.360004,27.872078,-161.688263,0.009472,0.003215,0.081667,123.981194,6.315903,0.816667,-161.688263,0.082673,0.000000
60.610004,28.165886,-161.777222,0.009472,0.003230,0.082048,125.288116,6.382481,0.820482,-161.777222,0.083089,0.000000
60.860004,28.383720,-161.777222,0.009477,0.003244,0.082404,126.257095,6.431843,0.824036,-161.777222,0.083505,0.000000
61.110004,29.515732,-161.821701,0.009503,0.003266,0.082968,131.292526,6.688361,0.829675,-161.821701,0.083921,0.000000
61.360004,30.032585,-161.777222,0.009503,0.003283,0.083384,133.591614,6.805481,0.833835,-161.777222,0.084338,0.000000
61.610004,30.342773,-161.821701,0.009516,0.003299,0.083791,134.971390,6.875771,0.837911,-161.821701,0.084754,0.000000
61.860004,30.620186,-161.866180,0.009520,0.003316,0.084234,136.205383,6.938633,0.842336,-161.866180,0.085170,0.000000
62.110004,31.527664,-161.910660,0.009559,0.003333,0.084667,140.242050,7.144271,0.846673,-161.910660,0.085586,0.000000
62.360004,32.081383,-161.955139,0.009572,0.003351,0.085127,142.705124,7.269745,0.851268,-161.955139,0.086003,0.000000
62.610004,32.277618,-161.955139,0.009572,0.003364,0.085439,143.578018,7.314213,0.854391,-161.955139,0.086419,0.000000
62.860004,32.963158,-161.999619,0.009597,0.003382,0.085907,146.627441,7.469558,0.859073,-161.999619,0.086835,0.000000
63.110004,33.621140,-162.044098,0.009597,0.003400,0.086358,149.554291,7.618659,0.863584,-162.044098,0.087252,0.000000
63.360004,34.459351,-162.044098,0.009615,0.003420,0.086870,153.282852,7.808600,0.868698,-162.044098,0.087668,0.000000
63.610004,34.731552,-162.044098,0.009619,0.003432,0.087182,154.493652,7.870282,0.871820,-162.044098,0.088084,0.000000
63.860004,35.078606,-162.133072,0.009636,0.003447,0.087564,156.037430,7.948926,0.875635,-162.133072,0.088500,0.000000
64.110001,35.682594,-162.133072,0.009649,0.003462,0.087928,158.724106,8.085792,0.879280,-162.133072,0.088917,0.000000
64.360001,36.423615,-162.133072,0.009649,0.003482,0.088431,162.020325,8.253710,0.884310,-162.133072,0.089333,0.000000
64.610001,37.196663,-162.177551,0.009675,0.003500,0.088891,165.459015,8.428885,0.888905,-162.177551,0.089749,0.000000
64.860001,37.874748,-162.222031,0.009679,0.003517,0.089333,168.475296,8.582541,0.893330,-162.222031,0.090165,0.000000
65.110001,38.898773,-162.222031,0.009692,0.003538,0.089853,173.030380,8.814589,0.898530,-162.222031,0.090582,0.000000
65.360001,39.003784,-162.310989,0.009714,0.003548,0.090113,173.497498,8.838384,0.901134,-162.310989,0.090998,0.000000
65.610001,39.135231,-162.310989,0.009714,0.003560,0.090417,174.082199,8.868170,0.904170,-162.310989,0.091423,0.000000
65.860001,40.155533,-162.355469,0.009718,0.003581,0.090954,178.620728,9.099374,0.909544,-162.355469,0.091839,0.000000
66.110001,41.016830,-162.355469,0.009735,0.003598,0.091379,182.451981,9.294547,0.913795,-162.355469,0.092255,0.000000
66.360001,41.399628,-162.399948,0.009740,0.003609,0.091674,184.154739,9.381290,0.916743,-162.399948,0.092672,0.000000
66.610001,42.235229,-162.444427,0.009761,0.003626,0.092108,187.871689,9.570640,0.921081,-162.444427,0.093088,0.000000
66.860001,43.243614,-162.444427,0.009783,0.003649,0.092689,192.357208,9.799143,0.926890,-162.444427,0.093504,0.000000
67.110001,44.050179,-162.444427,0.009774,0.003664,0.093053,195.944977,9.981914,0.930532,-162.444427,0.093921,0.000000
67.360001,44.568520,-162.488907,0.009796,0.003679,0.093443,198.250671,10.099371,0.934434,-162.488907,0.094337,0.000000
67.610001,45.038452,-162.488907,0.009796,0.003693,0.093790,200.341034,10.205859,0.937905,-162.488907,0.094753,0.000000
67.860001,45.876289,-162.533401,0.009809,0.003711,0.094267,204.067932,10.395716,0.942674,-162.533401,0.095169,0.000000
68.110001,46.691414,-162.533401,0.009817,0.003725,0.094623,207.693787,10.580426,0.946228,-162.533401,0.095586,0.000000
68.360001,46.989685,-162.622360,0.009839,0.003736,0.094901,209.020554,10.648014,0.949006,-162.622360,0.096002,0.000000
68.610001,47.909447,-162.666840,0.009852,0.003756,0.095412,213.111862,10.856436,0.954123,-162.666840,0.096418,0.000000
68.860001,49.241051,-162.666840,0.009848,0.003777,0.095941,219.035126,11.158181,0.959410,-162.666840,0.096834,0.000000
69.110001,50.256882,-162.666840,0.009865,0.003794,0.096375,223.553772,11.388371,0.963748,-162.666840,0.097251,0.000000
69.360001,50.760330,-162.666840,0.009882,0.003810,0.096765,225.793228,11.502456,0.967650,-162.666840,0.097667,0.000000
69.610001,51.806320,-162.755798,0.009886,0.003828,0.097224,230.446014,11.739480,0.972245,-162.755798,0.098083,0.000000
69.860001,52.693687,-162.755798,0.009882,0.003845,0.097667,234.393234,11.940559,0.976669,-162.755798,0.098500,0.000000
70.110001,53.460030,-162.844757,0.009895,0.003860,0.098040,237.802094,12.114216,0.980398,-162.844757,0.098916,0.000000
70.360001,53.865540,-162.844757,0.009908,0.003872,0.098361,239.605881,12.206105,0.983607,-162.844757,0.099332,0.000000
70.610001,54.872810,-162.844757,0.009925,0.003890,0.098803,244.086456,12.434357,0.988028,-162.844757,0.099757,0.000000
70.860001,56.099403,-162.844757,0.009925,0.003911,0.099341,249.542603,12.712307,0.993406,-162.844757,0.100173,0.000000
71.110001,56.755524,-162.889236,0.009921,0.003925,0.099696,252.461182,12.860986,0.996960,-162.889236,0.100590,0.000000
71.360001,57.494682,-162.933731,0.009955,0.003939,0.100061,255.749115,13.028481,1.000605,-162.933731,0.101006,0.000000
71.610001,58.406250,-162.978210,0.009960,0.003955,0.100468,259.803986,13.235045,1.004681,-162.978210,0.101422,0.000000
71.860001,59.301804,-162.933731,0.009964,0.003972,0.100893,263.787598,13.437981,1.008928,-162.933731,0.101838,0.000000
72.110001,60.290459,-162.933731,0.009960,0.003987,0.101257,268.185364,13.662013,1.012573,-162.933731,0.102255,0.000000
72.360001,61.165161,-163.022690,0.009973,0.004003,0.101665,272.076233,13.860224,1.016649,-163.022690,0.102671,0.000000
72.610001,62.472183,-163.022690,0.009990,0.004022,0.102151,277.890137,14.156399,1.021505,-163.022690,0.103087,0.000000
72.860001,63.455627,-163.067169,0.009994,0.004037,0.102541,282.264740,14.379251,1.025408,-163.067169,0.103503,0.000000
73.110001,64.587265,-163.067169,0.010011,0.004056,0.103018,287.298492,14.635684,1.030177,-163.067169,0.103920,0.000000
73.360001,65.245621,-163.111649,0.010024,0.004070,0.103373,290.227020,14.784869,1.033734,-163.111649,0.104336,0.000000
73.610001,66.150101,-163.156128,0.010016,0.004083,0.103711,294.250336,14.989827,1.037114,-163.156128,0.104752,0.000000
73.860001,67.486176,-163.156128,0.010029,0.004095,0.104006,300.193512,15.292586,1.040063,-163.156128,0.105125,0.000000
74.110001,66.624878,-163.156128,0.010050,0.004094,0.103980,296.362244,15.097413,1.039801,-163.156128,0.104206,0.000000
74.360001,66.087921,-163.245087,0.010042,0.004093,0.103954,293.973755,14.975738,1.039544,-163.245087,0.103980,0.000000
74.610001,65.523773,-163.245087,0.010054,0.004092,0.103937,291.464294,14.847898,1.039370,-163.245087,0.103980,0.000000
74.860001,65.062775,-163.289566,0.010054,0.004092,0.103928,289.413666,14.743436,1.039283,-163.289566,0.103980,0.000000
75.110001,64.620773,-163.289566,0.010046,0.004092,0.103928,287.447571,14.643277,1.039283,-163.289566,0.103980,0.000000
75.360001,64.263672,-163.378540,0.010072,0.004091,0.103920,285.859100,14.562356,1.039196,-163.378540,0.103980,0.000000
75.610001,63.905441,-163.334045,0.010054,0.004091,0.103920,284.265594,14.481180,1.039196,-163.334045,0.103980,0.000000
75.860001,63.596756,-163.378540,0.010063,0.004091,0.103920,282.892487,14.411231,1.039196,-163.378540,0.103980,0.000000
76.110001,63.301834,-163.334045,0.010076,0.004091,0.103920,281.580627,14.344401,1.039196,-163.334045,0.103980,0.000000
76.360001,63.068352,-163.423019,0.010067,0.004091,0.103920,280.542053,14.291492,1.039196,-163.423019,0.103980,0.000000
76.610001,62.807693,-163.467499,0.010067,0.004091,0.103920,279.382568,14.232427,1.039196,-163.467499,0.103980,0.000000
76.860001,62.608849,-163.511978,0.010063,0.004091,0.103911,278.498077,14.187368,1.039109,-163.511978,0.103980,0.000000
77.110001,62.383934,-163.467499,0.010063,0.004091,0.103911,277.497589,14.136402,1.039109,-163.467499,0.103980,0.000000
77.360001,62.204819,-163.467499,0.010093,0.004091,0.103911,276.700867,14.095813,1.039109,-163.467499,0.103980,0.000000
77.610001,62.007835,-163.511978,0.010072,0.004091,0.103911,275.824615,14.051176,1.039109,-163.511978,0.103980,0.000000
77.860001,61.870804,-163.511978,0.010093,0.004091,0.103911,275.215088,14.020124,1.039109,-163.511978,0.103980,0.000000
78.110001,61.692062,-163.600937,0.010076,0.004091,0.103911,274.420013,13.979621,1.039109,-163.600937,0.103980,0.000000
78.360001,61.546097,-163.689896,0.010076,0.004091,0.103911,273.770721,13.946545,1.039109,-163.689896,0.103980,0.000000
78.610001,61.400124,-163.689896,0.010085,0.004091,0.103911,273.121399,13.913466,1.039109,-163.689896,0.103980,0.000000
78.860001,61.283569,-163.645416,0.010076,0.004091,0.103911,272.602936,13.887055,1.039109,-163.645416,0.103980,0.000000
79.110001,61.147285,-163.778854,0.010080,0.004091,0.103911,271.996704,13.856173,1.039109,-163.778854,0.103980,0.000000
79.360001,61.031845,-163.734375,0.010093,0.004091,0.103911,271.483215,13.830013,1.039109,-163.734375,0.103980,0.000000
79.610001,60.906357,-163.778854,0.010093,0.004091,0.103911,270.925018,13.801578,1.039109,-163.778854,0.103980,0.000000
79.860001,60.795395,-163.867828,0.010102,0.004091,0.103911,270.431427,13.776434,1.039109,-163.867828,0.103980,0.000000
80.110001,60.695969,-163.778854,0.010093,0.004091,0.103911,269.989166,13.753902,1.039109,-163.778854,0.103980,0.000000
80.360001,60.581276,-163.823349,0.010093,0.004091,0.103911,269.478973,13.727913,1.039109,-163.823349,0.103980,0.000000
80.610001,60.486694,-163.912308,0.010089,0.004091,0.103911,269.058258,13.706481,1.039109,-163.912308,0.103980,0.000000
80.860001,60.388763,-163.912308,0.010098,0.004091,0.103911,268.622650,13.684290,1.039109,-163.912308,0.103980,0.000000
81.110001,60.302742,-163.956787,0.010102,0.004091,0.103911,268.239990,13.664797,1.039109,-163.956787,0.103980,0.000000
81.360001,60.215233,-163.912308,0.010089,0.004091,0.103911,267.850739,13.644966,1.039109,-163.912308,0.103980,0.000000
81.610001,60.129593,-163.956787,0.010093,0.004091,0.103911,267.469788,13.625561,1.039109,-163.956787,0.103980,0.000000
81.860001,60.041336,-163.956787,0.010089,0.004091,0.103911,267.077209,13.605560,1.039109,-163.956787,0.103980,0.000000
82.110001,59.989204,-164.045746,0.010093,0.004091,0.103911,266.845306,13.593748,1.039109,-164.045746,0.103980,0.000000
82.360001,59.903191,-164.090225,0.010080,0.004091,0.103911,266.462708,13.574258,1.039109,-164.090225,0.103980,0.000000
82.610001,59.830574,-164.090225,0.010080,0.004091,0.103911,266.139679,13.557802,1.039109,-164.090225,0.103980,0.000000
82.860001,59.740463,-164.090225,0.010080,0.004091,0.103911,265.738861,13.537383,1.039109,-164.090225,0.103980,0.000000
83.110001,59.684235,-164.134705,0.010098,0.004091,0.103911,265.488739,13.524641,1.039109,-164.134705,0.103980,0.000000
83.360001,59.594116,-164.179184,0.010093,0.004091,0.103911,265.087860,13.504219,1.039109,-164.179184,0.103980,0.000000
83.610001,59.549065,-164.179184,0.010106,0.004091,0.103911,264.887482,13.494011,1.039109,-164.179184,0.103980,0.000000
83.860001,59.482033,-164.268158,0.010102,0.004091,0.103911,264.589294,13.478822,1.039109,-164.268158,0.103980,0.000000
84.110001,59.429161,-164.223679,0.010106,0.004091,0.103911,264.354126,13.466841,1.039109,-164.223679,0.103980,0.000000
84.360001,59.358780,-164.268158,0.010093,0.004091,0.103911,264.041046,13.450891,1.039109,-164.268158,0.103980,0.000000
84.610001,59.307388,-164.357117,0.010115,0.004091,0.103911,263.812439,13.439246,1.039109,-164.357117,0.103980,0.000000
84.860001,59.248932,-164.312637,0.010098,0.004091,0.103911,263.552399,13.426000,1.039109,-164.312637,0.103980,0.000000
85.110001,59.186371,-164.401596,0.010098,0.004091,0.103911,263.274139,13.411824,1.039109,-164.401596,0.103980,0.000000
85.360001,59.131256,-164.357117,0.010106,0.004091,0.103911,263.028961,13.399334,1.039109,-164.357117,0.103980,0.000000
85.610001,59.069077,-164.401596,0.010098,0.004091,0.103911,262.752380,13.385244,1.039109,-164.401596,0.103980,0.000000
85.860001,59.018433,-164.446075,0.010089,0.004091,0.103911,262.527100,13.373768,1.039109,-164.446075,0.103980,0.000000
86.110001,58.964806,-164.446075,0.010093,0.004091,0.103902,262.288544,13.361616,1.039022,-164.446075,0.103980,0.000000
86.360001,58.919380,-164.490555,0.010093,0.004091,0.103902,262.086487,13.351322,1.039022,-164.490555,0.103980,0.000000
86.610001,58.867249,-164.490555,0.010093,0.004091,0.103902,261.854614,13.339509,1.039022,-164.490555,0.103980,0.000000
86.860001,58.825172,-164.579514,0.010106,0.004091,0.103902,261.667450,13.329974,1.039022,-164.579514,0.103980,0.000000
87.110001,58.773041,-164.579514,0.010111,0.004091,0.103902,261.435547,13.318162,1.039022,-164.579514,0.103980,0.000000
87.360001,58.738777,-164.490555,0.010080,0.004091,0.103902,261.283142,13.310397,1.039022,-164.490555,0.103980,0.000000
87.610001,58.680313,-164.623993,0.010111,0.004091,0.103902,261.023071,13.297149,1.039022,-164.623993,0.103980,0.000000
87.860001,58.641586,-164.668488,0.010098,0.004091,0.103902,260.850800,13.288374,1.039022,-164.668488,0.103980,0.000000
88.110001,58.600998,-164.623993,0.010089,0.004091,0.103902,260.670258,13.279176,1.039022,-164.623993,0.103980,0.000000
88.360001,58.559296,-164.668488,0.010102,0.004091,0.103902,260.484772,13.269726,1.039022,-164.668488,0.103980,0.000000
88.610001,58.506042,-164.757446,0.010098,0.004091,0.103902,260.247864,13.257659,1.039022,-164.757446,0.103980,0.000000
88.860001,58.488914,-164.712967,0.010115,0.004091,0.103902,260.171692,13.253778,1.039022,-164.712967,0.103980,0.000000
89.110001,58.430824,-164.757446,0.010106,0.004091,0.103902,259.913300,13.240614,1.039022,-164.757446,0.103980,0.000000
89.360001,58.399551,-164.757446,0.010102,0.004091,0.103902,259.774170,13.233527,1.039022,-164.757446,0.103980,0.000000
89.610001,58.355980,-164.801926,0.010098,0.004091,0.103902,259.580353,13.223654,1.039022,-164.801926,0.103980,0.000000
89.860001,58.318001,-164.801926,0.010098,0.004091,0.103902,259.411438,13.215048,1.039022,-164.801926,0.103980,0.000000
90.110001,58.267357,-164.846405,0.010093,0.004091,0.103902,259.186157,13.203572,1.039022,-164.846405,0.103980,0.000000
90.360001,58.243896,-164.846405,0.010115,0.004091,0.103902,259.081787,13.198256,1.039022,-164.846405,0.103980,0.000000
90.610001,58.207779,-164.890884,0.010102,0.004091,0.103902,258.921143,13.190072,1.039022,-164.890884,0.103980,0.000000
90.860001,58.169418,-164.935364,0.010115,0.004091,0.103902,258.750488,13.181378,1.039022,-164.935364,0.103980,0.000000
91.110001,58.119896,-164.890884,0.010111,0.004091,0.103902,258.530212,13.170156,1.039022,-164.890884,0.103980,0.000000
91.360001,58.097183,-164.979843,0.010106,0.004091,0.103902,258.429169,13.165009,1.039022,-164.979843,0.103980,0.000000
91.610001,58.047287,-164.979843,0.010098,0.004091,0.103902,258.207214,13.153704,1.039022,-164.979843,0.103980,0.000000
91.860001,58.034996,-165.068802,0.010115,0.004091,0.103902,258.152557,13.150918,1.039022,-165.068802,0.103980,0.000000
92.110001,57.989197,-165.113297,0.010119,0.004091,0.103902,257.948822,13.140540,1.039022,-165.113297,0.103980,0.000000
92.360001,57.966850,-165.157776,0.010098,0.004091,0.103902,257.849426,13.135476,1.039022,-165.157776,0.103980,0.000000
92.610001,57.920303,-165.113297,0.010111,0.004091,0.103902,257.642365,13.124928,1.039022,-165.113297,0.103980,0.000000
92.860001,57.898705,-165.157776,0.010111,0.004091,0.103902,257.546295,13.120033,1.039022,-165.157776,0.103980,0.000000
93.110001,57.865196,-165.202255,0.010115,0.004091,0.103902,257.397247,13.112441,1.039022,-165.202255,0.103980,0.000000
93.360008,57.831306,-165.202255,0.010111,0.004091,0.103902,257.246490,13.104761,1.039022,-165.202255,0.103980,0.000000
93.610008,57.804497,-165.202255,0.010106,0.004091,0.103902,257.127258,13.098686,1.039022,-165.202255,0.103980,0.000000
93.860008,57.784386,-165.291214,0.010098,0.004091,0.103902,257.037781,13.094130,1.039022,-165.291214,0.103980,0.000000
94.110008,57.734863,-165.335693,0.010106,0.004091,0.103902,256.817505,13.082908,1.039022,-165.335693,0.103980,0.000000
94.360008,57.710289,-165.291214,0.010093,0.004091,0.103902,256.708191,13.077339,1.039022,-165.291214,0.103980,0.000000
94.610008,57.689430,-165.335693,0.010106,0.004091,0.103902,256.615387,13.072612,1.039022,-165.335693,0.103980,0.000000
94.860008,57.652939,-165.335693,0.010102,0.004091,0.103902,256.453094,13.064343,1.039022,-165.335693,0.103980,0.000000
95.110008,57.617569,-165.380173,0.010102,0.004091,0.103902,256.295746,13.056328,1.039022,-165.380173,0.103980,0.000000
95.360008,57.585915,-165.380173,0.010106,0.004091,0.103902,256.154938,13.049155,1.039022,-165.380173,0.103980,0.000000
95.610008,57.566925,-165.424652,0.010111,0.004091,0.103902,256.070465,13.044851,1.039022,-165.424652,0.103980,0.000000
95.860008,57.534523,-165.469131,0.010115,0.004091,0.103902,255.926346,13.037509,1.039022,-165.469131,0.103980,0.000000
96.110008,57.516281,-165.513626,0.010115,0.004091,0.103902,255.845200,13.033376,1.039022,-165.513626,0.103980,0.000000
96.360008,57.489471,-165.469131,0.010111,0.004091,0.103902,255.725937,13.027300,1.039022,-165.469131,0.103980,0.000000
96.610008,57.472343,-165.513626,0.010123,0.004091,0.103902,255.649750,13.023419,1.039022,-165.513626,0.103980,0.000000
96.860008,57.443298,-165.558105,0.010102,0.004091,0.103902,255.520554,13.016837,1.039022,-165.558105,0.103980,0.000000
97.110008,57.423187,-165.558105,0.010115,0.004091,0.103902,255.431091,13.012280,1.039022,-165.558105,0.103980,0.000000
97.360008,57.384834,-165.602585,0.010111,0.004091,0.103902,255.260498,13.003590,1.039022,-165.602585,0.103980,0.000000
97.610008,57.360252,-165.647064,0.010106,0.004091,0.103902,255.151138,12.998019,1.039022,-165.647064,0.103980,0.000000
97.860008,57.325623,-165.691544,0.010115,0.004091,0.103902,254.997101,12.990171,1.039022,-165.691544,0.103980,0.000000
98.110008,57.321899,-165.647064,0.010111,0.004091,0.103902,254.980545,12.989328,1.039022,-165.647064,0.103980,0.000000
98.360008,57.280197,-165.691544,0.010106,0.004091,0.103902,254.795044,12.979878,1.039022,-165.691544,0.103980,0.000000
98.610008,57.266045,-165.736023,0.010111,0.004091,0.103902,254.732086,12.976671,1.039022,-165.736023,0.103980,0.000000
98.860008,57.229553,-165.824982,0.010115,0.004091,0.103902,254.569763,12.968402,1.039022,-165.824982,0.103980,0.000000
99.110008,57.216522,-165.780502,0.010106,0.004091,0.103902,254.511795,12.965449,1.039022,-165.780502,0.103980,0.000000
99.360008,57.181892,-165.824982,0.010115,0.004091,0.103902,254.357758,12.957602,1.039022,-165.824982,0.103980,0.000000
99.610008,57.177048,-165.824982,0.010111,0.004091,0.103902,254.336212,12.956504,1.039022,-165.824982,0.103980,0.000000
99.860008,57.131622,-165.869461,0.010111,0.004091,0.103902,254.134155,12.946211,1.039022,-165.869461,0.103980,0.000000
100.110008,57.129387,-165.824982,0.010106,0.004091,0.103902,254.124207,12.945704,1.039022,-165.824982,0.103980,0.000000
100.360008,57.089539,-165.913940,0.010119,0.004091,0.103902,253.946945,12.936674,1.039022,-165.913940,0.103980,0.000000
100.610008,57.080231,-165.958435,0.010115,0.004091,0.103902,253.905548,12.934566,1.039022,-165.958435,0.103980,0.000000
100.860008,57.053421,-165.958435,0.010115,0.004091,0.103902,253.786285,12.928490,1.039022,-165.958435,0.103980,0.000000
101.110008,57.030708,-166.002914,0.010119,0.004091,0.103902,253.685257,12.923344,1.039022,-166.002914,0.103980,0.000000
101.360008,57.007622,-166.047394,0.010123,0.004091,0.103902,253.582565,12.918112,1.039022,-166.047394,0.103980,0.000000
101.610008,56.987885,-166.091873,0.010123,0.004091,0.103902,253.494766,12.913639,1.039022,-166.091873,0.103980,0.000000
101.860008,56.972244,-166.091873,0.010102,0.004091,0.103902,253.425201,12.910095,1.039022,-166.091873,0.103980,0.000000
102.110008,56.947670,-166.091873,0.010115,0.004091,0.103902,253.315887,12.904527,1.039022,-166.091873,0.103980,0.000000
102.360008,56.909309,-166.136353,0.010115,0.004091,0.103902,253.145248,12.895834,1.039022,-166.136353,0.103980,0.000000
102.610008,56.898514,-166.136353,0.010106,0.004091,0.103902,253.097229,12.893388,1.039022,-166.136353,0.103980,0.000000
102.860008,56.883621,-166.225311,0.010102,0.004091,0.103902,253.030991,12.890013,1.039022,-166.225311,0.103980,0.000000
103.110008,56.859787,-166.225311,0.010123,0.004091,0.103902,252.924957,12.884612,1.039022,-166.225311,0.103980,0.000000
103.360008,56.857925,-166.225311,0.010119,0.004091,0.103902,252.916687,12.884190,1.039022,-166.225311,0.103980,0.000000
103.610008,56.821434,-166.269791,0.010102,0.004091,0.103902,252.754364,12.875920,1.039022,-166.269791,0.103980,0.000000
103.860008,56.809143,-166.269791,0.010111,0.004091,0.103902,252.699692,12.873137,1.039022,-166.269791,0.103980,0.000000
104.110008,56.786057,-166.269791,0.010106,0.004091,0.103902,252.597000,12.867905,1.039022,-166.269791,0.103980,0.000000
104.300003,56.784569,-166.403244,0.010119,0.004091,0.103902,252.590378,12.867567,1.039022,-166.403244,0.103980,0.000000