File: Data/compression 34/AutoNoHeating-10-34-reverse-1-2_11152024_194500.csv
Time (sec),S:Load (lbs),S:HL1 (DIM),S:LVDT (in),S:Position (in),Ch:Position (mm),Ch:Load (N),Ch:Stress (MPa),Ch:Strain (mm/mm),Ch:HL1 (DIM),Set Point (),Cycles ()
0.210000,-0.126984,-332.495117,-0.011775,-0.007081,-0.179854,-0.564851,-0.028775,-1.798540,-332.495117,-0.179620,0.000000
0.590000,-0.040222,-332.450623,-0.011779,-0.006976,-0.177200,-0.178917,-0.009114,-1.772002,-332.450623,-0.176428,0.000000
0.970000,-0.078201,-332.539581,-0.011598,-0.006746,-0.171346,-0.347857,-0.017721,-1.713465,-332.539581,-0.170098,0.000000
1.350000,-0.068893,-332.539581,-0.011361,-0.006495,-0.164964,-0.306453,-0.015611,-1.649637,-332.539581,-0.163767,0.000000
1.730000,-0.089745,-332.584076,-0.011089,-0.006246,-0.158650,-0.399204,-0.020336,-1.586503,-332.584076,-0.157436,0.000000
2.110000,-0.121399,-332.539581,-0.010856,-0.006001,-0.152432,-0.540009,-0.027509,-1.524323,-332.539581,-0.151105,0.000000
2.490000,-0.134804,-332.539581,-0.010580,-0.005756,-0.146206,-0.599637,-0.030547,-1.462056,-332.539581,-0.144775,0.000000
2.870000,-0.051765,-332.584076,-0.010322,-0.005505,-0.139831,-0.230264,-0.011730,-1.398315,-332.584076,-0.138444,0.000000
3.250000,-0.053627,-332.584076,-0.010050,-0.005245,-0.133232,-0.238545,-0.012152,-1.332319,-332.584076,-0.132113,0.000000
3.630000,-0.017502,-332.673035,-0.009809,-0.005008,-0.127205,-0.077852,-0.003966,-1.272047,-332.673035,-0.125782,0.000000
4.010000,-0.065544,-332.584076,-0.009554,-0.004751,-0.120674,-0.291555,-0.014853,-1.206745,-332.584076,-0.119452,0.000000
4.390000,-0.072243,-332.628540,-0.009283,-0.004501,-0.114326,-0.321352,-0.016370,-1.143264,-332.628540,-0.113121,0.000000
4.770000,-0.077827,-332.673035,-0.009024,-0.004255,-0.108074,-0.346194,-0.017636,-1.080737,-332.673035,-0.106790,0.000000
5.150000,-0.020859,-332.628540,-0.008765,-0.004005,-0.101726,-0.092784,-0.004727,-1.017256,-332.628540,-0.100459,0.000000
5.530000,-0.005592,-332.673035,-0.008515,-0.003756,-0.095412,-0.024876,-0.001267,-0.954122,-332.673035,-0.094129,0.000000
5.910000,-0.039101,-332.717499,-0.008269,-0.003507,-0.089073,-0.173928,-0.008860,-0.890728,-332.717499,-0.087798,0.000000
6.290000,-0.059586,-332.628540,-0.008006,-0.003260,-0.082794,-0.265050,-0.013502,-0.827940,-332.628540,-0.081467,0.000000
6.670001,-0.080811,-332.761993,-0.007731,-0.003010,-0.076463,-0.359463,-0.018312,-0.764633,-332.761993,-0.075136,0.000000
7.050000,-0.024956,-332.761993,-0.007506,-0.002758,-0.070063,-0.111009,-0.005655,-0.700632,-332.761993,-0.068806,0.000000
7.430000,-0.016388,-332.761993,-0.007217,-0.002510,-0.063758,-0.072897,-0.003714,-0.637585,-332.761993,-0.062475,0.000000
7.810000,-0.017136,-332.806488,-0.006985,-0.002262,-0.057462,-0.076223,-0.003883,-0.574624,-332.806488,-0.056144,0.000000
8.190001,-0.049904,-332.717499,-0.006722,-0.002015,-0.051175,-0.221983,-0.011308,-0.511750,-332.717499,-0.049813,0.000000
8.570001,-0.050270,-332.761993,-0.006463,-0.001765,-0.044827,-0.223612,-0.011391,-0.448269,-332.761993,-0.043483,0.000000
8.950001,-0.098312,-332.895447,-0.006239,-0.001527,-0.038791,-0.437315,-0.022278,-0.387910,-332.895447,-0.037152,0.000000
9.330001,-0.052505,-332.895447,-0.005963,-0.001273,-0.032339,-0.233556,-0.011898,-0.323389,-332.895447,-0.030821,0.000000
9.710000,-0.015274,-332.850952,-0.005696,-0.001009,-0.025635,-0.067942,-0.003461,-0.256352,-332.850952,-0.024490,0.000000
10.090000,-0.019363,-332.806488,-0.005445,-0.000768,-0.019513,-0.086133,-0.004388,-0.195126,-332.806488,-0.018160,0.000000
10.470000,-0.053627,-332.806488,-0.005187,-0.000515,-0.013069,-0.238545,-0.012152,-0.130691,-332.806488,-0.011829,0.000000
10.850000,-0.067772,-332.850952,-0.004937,-0.000263,-0.006678,-0.301465,-0.015357,-0.066776,-332.850952,-0.005498,0.000000
11.230000,0.097557,-332.939911,-0.004678,-0.000025,-0.000624,0.433956,0.022107,-0.006244,-332.939911,0.000833,0.000000
11.610001,0.167564,-332.939911,-0.004648,-0.000001,-0.000035,0.745364,0.037971,-0.000347,-332.939911,0.000165,0.000000
11.990001,0.131447,-332.939911,-0.004652,-0.000001,-0.000035,0.584705,0.029786,-0.000347,-332.939911,0.000486,0.000000
12.370001,0.136284,-332.939911,-0.004644,-0.000001,-0.000035,0.606221,0.030882,-0.000347,-332.939911,0.001119,0.000000
12.750001,0.109100,-332.984406,-0.004652,-0.000001,-0.000017,0.485303,0.024722,-0.000173,-332.984406,0.001752,0.000000
13.130001,0.280396,-333.073364,-0.004600,0.000050,0.001275,1.247262,0.063539,0.012748,-333.073364,0.002394,0.000000
13.510000,0.331779,-333.028870,-0.004596,0.000072,0.001830,1.475829,0.075182,0.018299,-333.028870,0.003027,0.000000
13.890000,0.350769,-333.028870,-0.004566,0.000094,0.002385,1.560299,0.079485,0.023849,-333.028870,0.003660,0.000000
14.270000,0.428223,-332.984406,-0.004540,0.000121,0.003061,1.904830,0.097037,0.030613,-332.984406,0.004293,0.000000
14.650001,0.562279,-333.117828,-0.004518,0.000149,0.003772,2.501141,0.127414,0.037724,-333.117828,0.004926,0.000000
15.030001,0.666168,-333.162323,-0.004480,0.000180,0.004579,2.963264,0.150956,0.045790,-333.162323,0.005559,0.000000
15.410001,0.762245,-333.073364,-0.004454,0.000204,0.005186,3.390636,0.172727,0.051860,-333.073364,0.006192,0.000000
15.790001,0.802086,-333.117828,-0.004432,0.000226,0.005732,3.567856,0.181755,0.057324,-333.117828,0.006825,0.000000
16.170000,0.971146,-333.117828,-0.004402,0.000254,0.006452,4.319871,0.220065,0.064522,-333.117828,0.007458,0.000000
16.550001,1.102219,-333.117828,-0.004398,0.000277,0.007033,4.902913,0.249766,0.070332,-333.117828,0.008091,0.000000
16.930000,1.284309,-333.162323,-0.004355,0.000309,0.007857,5.712893,0.291029,0.078571,-333.162323,0.008724,0.000000
17.310001,1.396767,-333.206818,-0.004346,0.000334,0.008490,6.213129,0.316512,0.084901,-333.206818,0.009357,0.000000
17.690001,1.427673,-333.206818,-0.004307,0.000356,0.009045,6.350608,0.323515,0.090452,-333.206818,0.009990,0.000000
18.070002,1.581833,-333.162323,-0.004290,0.000380,0.009661,7.036344,0.358448,0.096609,-333.162323,0.010624,0.000000
18.450001,1.708443,-333.251282,-0.004268,0.000402,0.010199,7.599533,0.387139,0.101986,-333.251282,0.011257,0.000000
18.830002,1.819412,-333.251282,-0.004234,0.000420,0.010676,8.093150,0.412285,0.106756,-333.251282,0.011890,0.000000
19.210001,2.016022,-333.251282,-0.004225,0.000453,0.011508,8.967712,0.456837,0.115081,-333.251282,0.012523,0.000000
19.590000,2.094589,-333.251282,-0.004191,0.000476,0.012098,9.317198,0.474641,0.120978,-333.251282,0.013156,0.000000
19.970001,2.317268,-333.251282,-0.004165,0.000507,0.012878,10.307725,0.525101,0.128783,-333.251282,0.013789,0.000000
20.350000,2.329933,-333.295776,-0.004156,0.000520,0.013217,10.364060,0.527970,0.132165,-333.295776,0.014422,0.000000
20.730001,2.487076,-333.384735,-0.004139,0.000546,0.013876,11.063066,0.563579,0.138756,-333.384735,0.015055,0.000000
21.110001,2.680336,-333.340240,-0.004105,0.000573,0.014561,11.922730,0.607373,0.145607,-333.340240,0.015688,0.000000
21.490002,2.806572,-333.295776,-0.004079,0.000595,0.015107,12.484256,0.635978,0.151071,-333.295776,0.016321,0.000000
21.870001,2.916794,-333.295776,-0.004066,0.000623,0.015836,12.974547,0.660955,0.158356,-333.295776,0.016954,0.000000
22.250002,3.039673,-333.384735,-0.004014,0.000648,0.016451,13.521140,0.688800,0.164513,-333.384735,0.017587,0.000000
22.630001,3.178940,-333.429199,-0.004005,0.000672,0.017058,14.140631,0.720358,0.170583,-333.429199,0.018220,0.000000
23.010000,3.175217,-333.473694,-0.003997,0.000688,0.017466,14.124069,0.719514,0.174659,-333.473694,0.018853,0.000000
23.390001,3.470139,-333.340240,-0.003954,0.000728,0.018498,15.435947,0.786345,0.184979,-333.340240,0.019487,0.000000
23.770000,3.601212,-333.429199,-0.003936,0.000754,0.019140,16.018990,0.816046,0.191397,-333.429199,0.020120,0.000000
24.150002,3.552055,-333.384735,-0.003919,0.000765,0.019426,15.800331,0.804907,0.194259,-333.384735,0.020761,0.000000
24.530001,3.917725,-333.518158,-0.003885,0.000799,0.020284,17.426908,0.887769,0.202844,-333.518158,0.021394,0.000000
24.910002,4.073006,-333.473694,-0.003859,0.000827,0.021013,18.117634,0.922956,0.210129,-333.473694,0.022028,0.000000
25.290001,4.195518,-333.518158,-0.003829,0.000853,0.021672,18.662598,0.950718,0.216720,-333.518158,0.022661,0.000000
25.670002,4.217491,-333.473694,-0.003820,0.000875,0.022227,18.760338,0.955697,0.222270,-333.473694,0.023294,0.000000
26.050001,4.322868,-333.518158,-0.003786,0.000895,0.022721,19.229078,0.979576,0.227213,-333.518158,0.023927,0.000000
26.430000,4.515015,-333.562653,-0.003768,0.000918,0.023311,20.083788,1.023117,0.233110,-333.562653,0.024560,0.000000
26.810001,4.572357,-333.607147,-0.003751,0.000942,0.023927,20.338861,1.036111,0.239268,-333.607147,0.025193,0.000000
27.190001,4.644600,-333.518158,-0.003729,0.000965,0.024516,20.660212,1.052481,0.245165,-333.518158,0.025826,0.000000
27.570002,4.882919,-333.562653,-0.003704,0.001001,0.025427,21.720310,1.106485,0.254271,-333.562653,0.026459,0.000000
27.950001,4.990158,-333.562653,-0.003669,0.001019,0.025878,22.197332,1.130786,0.258780,-333.562653,0.027092,0.000000
28.330002,5.183052,-333.607147,-0.003656,0.001050,0.026659,23.055367,1.174496,0.266585,-333.607147,0.027725,0.000000
28.710001,5.329018,-333.696106,-0.003635,0.001080,0.027422,23.704655,1.207573,0.274217,-333.696106,0.028358,0.000000
29.090002,5.216194,-333.651611,-0.003617,0.001095,0.027821,23.202791,1.182006,0.278206,-333.651611,0.028991,0.000000
29.470001,5.296623,-333.696106,-0.003587,0.001122,0.028506,23.560556,1.200232,0.285057,-333.696106,0.029624,0.000000
29.850002,5.603828,-333.696106,-0.003566,0.001152,0.029260,24.927074,1.269846,0.292602,-333.696106,0.030258,0.000000
30.230001,5.672348,-333.696106,-0.003548,0.001176,0.029867,25.231865,1.285372,0.298673,-333.696106,0.030891,0.000000
30.610001,5.779587,-333.696106,-0.003523,0.001198,0.030431,25.708885,1.309673,0.304310,-333.696106,0.031524,0.000000
30.990002,5.903587,-333.740570,-0.003492,0.001220,0.030986,26.260468,1.337772,0.309860,-333.740570,0.032157,0.000000
31.370001,5.978439,-333.696106,-0.003484,0.001247,0.031671,26.593426,1.354734,0.316711,-333.696106,0.032790,0.000000
31.750002,5.769165,-333.740570,-0.003462,0.001257,0.031940,25.662527,1.307312,0.319399,-333.740570,0.033423,0.000000
32.130001,6.040253,-333.740570,-0.003432,0.001292,0.032807,26.868385,1.368741,0.328072,-333.740570,0.034056,0.000000
32.510002,6.277077,-333.785065,-0.003419,0.001321,0.033553,27.921831,1.422406,0.335530,-333.785065,0.034689,0.000000
32.890003,6.560455,-333.785065,-0.003406,0.001353,0.034368,29.182364,1.486620,0.343682,-333.785065,0.035322,0.000000
33.270000,6.361610,-333.740570,-0.003380,0.001370,0.034810,28.297857,1.441561,0.348104,-333.740570,0.035955,0.000000
33.650002,6.349319,-333.785065,-0.003376,0.001388,0.035244,28.243183,1.438776,0.352441,-333.785065,0.036588,0.000000
34.030003,6.826698,-333.874023,-0.003337,0.001424,0.036181,30.366671,1.546952,0.361807,-333.874023,0.037221,0.000000
34.410000,6.745522,-333.829529,-0.003311,0.001448,0.036779,30.005579,1.528557,0.367791,-333.829529,0.037854,0.000000
34.790001,6.885536,-333.918488,-0.003303,0.001469,0.037308,30.628395,1.560285,0.373081,-333.918488,0.038496,0.000000
35.170002,6.849785,-333.874023,-0.003285,0.001488,0.037802,30.469364,1.552183,0.378024,-333.874023,0.039129,0.000000
35.550003,6.735100,-333.829529,-0.003268,0.001508,0.038305,29.959221,1.526195,0.383054,-333.829529,0.039762,0.000000
35.930000,7.373718,-333.918488,-0.003234,0.001547,0.039303,32.799938,1.670908,0.393027,-333.918488,0.040395,0.000000
36.310001,7.240410,-333.962982,-0.003225,0.001574,0.039970,32.206951,1.640700,0.399704,-333.962982,0.041028,0.000000
36.690002,7.165932,-333.962982,-0.003195,0.001589,0.040361,31.875656,1.623823,0.403607,-333.962982,0.041662,0.000000
37.070004,7.502930,-333.962982,-0.003169,0.001623,0.041228,33.374699,1.700188,0.412279,-333.962982,0.042295,0.000000
37.450001,7.696190,-333.962982,-0.003147,0.001652,0.041965,34.234364,1.743982,0.419650,-333.962982,0.042928,0.000000
37.830002,7.639221,-334.007446,-0.003130,0.001674,0.042520,33.980953,1.731072,0.425201,-334.007446,0.043561,0.000000
38.210003,8.008987,-334.007446,-0.003091,0.001703,0.043266,35.625755,1.814862,0.432659,-334.007446,0.044194,0.000000
38.590000,8.022392,-334.051941,-0.003078,0.001730,0.043951,35.685383,1.817900,0.439510,-334.051941,0.044827,0.000000
38.970001,7.863014,-334.007446,-0.003061,0.001751,0.044480,34.976433,1.781785,0.444800,-334.007446,0.045460,0.000000
39.350002,8.096863,-334.007446,-0.003035,0.001777,0.045139,36.016644,1.834775,0.451391,-334.007446,0.046093,0.000000
39.730003,8.081970,-334.051941,-0.003005,0.001799,0.045694,35.950397,1.831401,0.456941,-334.051941,0.046726,0.000000
40.110001,8.122559,-334.140900,-0.003001,0.001819,0.046197,36.130943,1.840598,0.461971,-334.140900,0.047359,0.000000
40.490002,8.435349,-334.096436,-0.002979,0.001851,0.047004,37.522305,1.911477,0.470036,-334.096436,0.047992,0.000000
40.870003,8.497910,-334.096436,-0.002971,0.001872,0.047541,37.800591,1.925654,0.475413,-334.096436,0.048625,0.000000
41.250004,8.820381,-334.140900,-0.002936,0.001904,0.048365,39.235016,1.998727,0.483652,-334.140900,0.049258,0.000000
41.630001,8.465515,-334.229858,-0.002928,0.001918,0.048729,37.656490,1.918313,0.487294,-334.229858,0.049891,0.000000
42.010002,8.726547,-334.185394,-0.002910,0.001944,0.049389,38.817619,1.977464,0.493885,-334.185394,0.050525,0.000000
42.390003,8.855011,-334.185394,-0.002884,0.001969,0.050004,39.389057,2.006574,0.500042,-334.185394,0.051158,0.000000
42.770000,9.136154,-334.185394,-0.002867,0.001996,0.050689,40.639645,2.070282,0.506893,-334.185394,0.051791,0.000000
43.150002,8.821129,-334.140900,-0.002841,0.002014,0.051166,39.238342,1.998896,0.511663,-334.140900,0.052424,0.000000
43.530003,9.154778,-334.229858,-0.002811,0.002042,0.051860,40.722485,2.074502,0.518601,-334.229858,0.053057,0.000000
43.910004,9.247124,-334.229858,-0.002807,0.002070,0.052580,41.133259,2.095428,0.525799,-334.229858,0.053690,0.000000
44.290001,9.495125,-334.274353,-0.002777,0.002099,0.053317,42.236423,2.151626,0.533170,-334.274353,0.054323,0.000000
44.670002,9.466080,-334.229858,-0.002751,0.002125,0.053967,42.107227,2.145044,0.539675,-334.229858,0.054956,0.000000
45.050003,9.485443,-334.229858,-0.002734,0.002148,0.054557,42.193359,2.149432,0.545572,-334.229858,0.055589,0.000000
45.430000,9.259781,-334.274353,-0.002712,0.002163,0.054947,41.189564,2.098296,0.549474,-334.274353,0.056222,0.000000
45.810001,9.873825,-334.407776,-0.002695,0.002195,0.055745,43.920967,2.237441,0.557453,-334.407776,0.056864,0.000000
46.190002,10.080864,-334.274353,-0.002673,0.002223,0.056465,44.841923,2.284357,0.564651,-334.274353,0.057497,0.000000
46.570004,10.086449,-334.318817,-0.002660,0.002250,0.057159,44.866764,2.285622,0.571588,-334.318817,0.058130,0.000000
46.950001,9.892441,-334.363312,-0.002634,0.002271,0.057688,44.003773,2.241659,0.576879,-334.363312,0.058763,0.000000
47.330002,10.022026,-334.407776,-0.002613,0.002293,0.058243,44.580200,2.271024,0.582429,-334.407776,0.059396,0.000000
47.710003,10.455467,-334.363312,-0.002600,0.002322,0.058971,46.508240,2.369243,0.589714,-334.363312,0.060029,0.000000
48.090004,10.362381,-334.407776,-0.002561,0.002342,0.059474,46.094173,2.348149,0.594743,-334.407776,0.060662,0.000000
48.470001,10.406319,-334.407776,-0.002552,0.002364,0.060038,46.289616,2.358105,0.600380,-334.407776,0.061296,0.000000
48.850002,10.185875,-334.363312,-0.002531,0.002386,0.060610,45.309036,2.308152,0.606104,-334.363312,0.061929,0.000000
49.230003,10.700119,-334.407776,-0.002509,0.002415,0.061348,47.596508,2.424681,0.613475,-334.407776,0.062562,0.000000
49.610001,11.167076,-334.496765,-0.002496,0.002447,0.062145,49.673634,2.530496,0.621454,-334.496765,0.063195,0.000000
49.990002,11.343208,-334.496765,-0.002475,0.002475,0.062865,50.457111,2.570408,0.628652,-334.496765,0.063828,0.000000
50.370003,11.048286,-334.452271,-0.002449,0.002494,0.063342,49.145233,2.503577,0.633422,-334.452271,0.064461,0.000000
50.750004,11.136909,-334.452271,-0.002423,0.002520,0.064001,49.539448,2.523660,0.640013,-334.452271,0.065094,0.000000
51.130001,11.730850,-334.496765,-0.002393,0.002550,0.064782,52.181427,2.658249,0.647818,-334.496765,0.065727,0.000000
51.510002,11.707390,-334.541229,-0.002376,0.002572,0.065337,52.077072,2.652932,0.653368,-334.541229,0.066360,0.000000
51.890003,11.545403,-334.541229,-0.002380,0.002589,0.065762,51.356514,2.616226,0.657617,-334.541229,0.066993,0.000000
52.270004,11.817612,-334.541229,-0.002341,0.002613,0.066377,52.567364,2.677909,0.663775,-334.541229,0.067626,0.000000
52.650002,12.381752,-334.585724,-0.002333,0.002645,0.067184,55.076782,2.805745,0.671840,-334.585724,0.068259,0.000000
53.030003,11.817612,-334.585724,-0.002289,0.002656,0.067461,52.567364,2.677909,0.674615,-334.585724,0.068892,0.000000
53.410004,12.524742,-334.585724,-0.002289,0.002684,0.068181,55.712837,2.838147,0.681813,-334.585724,0.069525,0.000000
53.790001,12.591774,-334.585724,-0.002268,0.002715,0.068953,56.011009,2.853337,0.689531,-334.585724,0.070159,0.000000
54.170002,13.224060,-334.630188,-0.002242,0.002747,0.069786,58.823559,2.996615,0.697857,-334.630188,0.070792,0.000000
54.550003,12.899727,-334.585724,-0.002207,0.002766,0.070263,57.380852,2.923120,0.702626,-334.585724,0.071425,0.000000
54.930004,12.931374,-334.630188,-0.002199,0.002788,0.070818,57.521622,2.930291,0.708177,-334.630188,0.072058,0.000000
55.310001,14.085732,-334.674683,-0.002177,0.002819,0.071598,62.656464,3.191873,0.715981,-334.674683,0.072691,0.000000
55.690002,13.857468,-334.630188,-0.002151,0.002843,0.072214,61.641094,3.140147,0.722139,-334.630188,0.073324,0.000000
56.070004,13.484718,-334.674683,-0.002134,0.002857,0.072569,59.983025,3.055681,0.725694,-334.674683,0.073957,0.000000
56.450005,14.086105,-334.674683,-0.002104,0.002886,0.073307,62.658127,3.191957,0.733066,-334.674683,0.074590,0.000000
56.830002,13.789322,-334.674683,-0.002100,0.002903,0.073749,61.337967,3.124705,0.737489,-334.674683,0.075232,0.000000
57.210003,15.303017,-334.808105,-0.002074,0.002944,0.074781,68.071220,3.467713,0.747809,-334.808105,0.075865,0.000000
57.590004,15.470955,-334.719147,-0.002035,0.002974,0.075535,68.818245,3.505768,0.755354,-334.719147,0.076498,0.000000
57.970001,14.963043,-334.763641,-0.002026,0.002995,0.076073,66.558937,3.390674,0.760731,-334.763641,0.077131,0.000000
58.350002,15.558838,-334.808105,-0.001996,0.003022,0.076749,69.209167,3.525683,0.767495,-334.808105,0.077764,0.000000
58.730003,15.678368,-334.763641,-0.001979,0.003048,0.077409,69.740860,3.552769,0.774086,-334.763641,0.078397,0.000000
59.110004,15.670547,-334.852600,-0.001953,0.003066,0.077886,69.706078,3.550997,0.778855,-334.852600,0.079030,0.000000
59.490002,16.777611,-334.897095,-0.001923,0.003101,0.078761,74.630539,3.801861,0.787614,-334.897095,0.079663,0.000000
59.870003,16.810005,-334.852600,-0.001914,0.003126,0.079395,74.774635,3.809202,0.793945,-334.852600,0.080296,0.000000
60.250004,16.907944,-334.808105,-0.001876,0.003148,0.079958,75.210289,3.831395,0.799582,-334.808105,0.080929,0.000000
60.630001,17.355164,-334.897095,-0.001858,0.003175,0.080635,77.199623,3.932736,0.806347,-334.897095,0.081563,0.000000
61.010002,17.406174,-334.897095,-0.001841,0.003195,0.081164,77.426529,3.944295,0.811637,-334.897095,0.082196,0.000000
61.390003,17.617683,-334.941559,-0.001819,0.003215,0.081667,78.367371,3.992224,0.816667,-334.941559,0.082829,0.000000
61.770004,18.609680,-334.897095,-0.001798,0.003248,0.082491,82.779991,4.217014,0.824905,-334.897095,0.083462,0.000000
62.150002,18.009422,-334.852600,-0.001776,0.003264,0.082907,80.109909,4.080994,0.829068,-334.852600,0.084095,0.000000
62.530003,19.563332,-334.941559,-0.001755,0.003301,0.083835,87.022049,4.433114,0.838347,-334.941559,0.084728,0.000000
62.910004,18.817467,-335.030518,-0.001742,0.003310,0.084078,83.704269,4.264099,0.840775,-335.030518,0.085361,0.000000
63.290005,19.899582,-334.986053,-0.001729,0.003341,0.084867,88.517761,4.509310,0.848667,-334.986053,0.085994,0.000000
63.670002,19.777817,-334.986053,-0.001694,0.003358,0.085283,87.976120,4.481717,0.852830,-334.986053,0.086627,0.000000
64.050003,20.703537,-335.030518,-0.001690,0.003392,0.086159,92.093933,4.691488,0.861589,-335.030518,0.087260,0.000000
64.430000,20.731087,-335.030518,-0.001664,0.003406,0.086506,92.216476,4.697731,0.865058,-335.030518,0.087893,0.000000
64.810005,21.891777,-335.075012,-0.001634,0.003440,0.087382,97.379486,4.960748,0.873817,-335.075012,0.088526,0.000000
65.190002,22.413841,-335.075012,-0.001617,0.003467,0.088058,99.701744,5.079049,0.880581,-335.075012,0.089159,0.000000
65.570000,22.331917,-335.075012,-0.001591,0.003485,0.088509,99.337326,5.060485,0.885091,-335.075012,0.089793,0.000000
65.950005,23.628517,-335.030518,-0.001578,0.003521,0.089446,105.104897,5.354299,0.894457,-335.030518,0.090426,0.000000
66.330002,23.912636,-335.119476,-0.001544,0.003544,0.090027,106.368713,5.418681,0.900267,-335.119476,0.091059,0.000000
66.710007,24.117073,-335.075012,-0.001544,0.003562,0.090469,107.278099,5.465007,0.904690,-335.075012,0.091692,0.000000
67.090004,25.323929,-335.119476,-0.001518,0.003592,0.091241,112.646461,5.738484,0.912408,-335.119476,0.092325,0.000000
67.470001,25.848976,-335.163971,-0.001500,0.003612,0.091735,114.981987,5.857461,0.917351,-335.163971,0.092958,0.000000
67.850006,26.311089,-335.163971,-0.001466,0.003634,0.092316,117.037567,5.962178,0.923162,-335.163971,0.093600,0.000000
68.230003,27.327667,-335.208435,-0.001470,0.003666,0.093105,121.559532,6.192538,0.931054,-335.208435,0.094233,0.000000
68.610001,27.898514,-335.208435,-0.001444,0.003686,0.093634,124.098785,6.321894,0.936344,-335.208435,0.094866,0.000000
68.990005,29.107239,-335.252930,-0.001414,0.003713,0.094319,129.475464,6.595794,0.943195,-335.252930,0.095499,0.000000
69.370003,30.021782,-335.163971,-0.001401,0.003739,0.094979,133.543549,6.803033,0.949786,-335.163971,0.096132,0.000000
69.750000,30.332710,-335.208435,-0.001388,0.003765,0.095638,134.926636,6.873490,0.956376,-335.208435,0.096765,0.000000
70.130005,31.695221,-335.252930,-0.001362,0.003788,0.096210,140.987381,7.182240,0.962100,-335.252930,0.097398,0.000000
70.510002,32.108932,-335.252930,-0.001345,0.003808,0.096722,142.827667,7.275988,0.967217,-335.252930,0.098031,0.000000
70.890007,34.210976,-335.208435,-0.001345,0.003843,0.097606,152.178024,7.752318,0.976063,-335.208435,0.098664,0.000000
71.270004,35.170578,-335.297424,-0.001319,0.003868,0.098248,156.446548,7.969767,0.982480,-335.297424,0.099297,0.000000
71.650002,36.461594,-335.252930,-0.001298,0.003892,0.098864,162.189270,8.262315,0.988637,-335.252930,0.099930,0.000000
72.030006,37.469231,-335.297424,-0.001285,0.003917,0.099488,166.671463,8.490649,0.994881,-335.297424,0.100563,0.000000
72.410004,39.045113,-335.386383,-0.001263,0.003946,0.100234,173.681335,8.847749,1.002339,-335.386383,0.101197,0.000000
72.790001,39.920563,-335.341888,-0.001250,0.003969,0.100806,177.575531,9.046128,1.008063,-335.341888,0.101830,0.000000
73.170006,40.685043,-335.341888,-0.001255,0.003989,0.101309,180.976105,9.219363,1.013093,-335.341888,0.102463,0.000000
73.550003,42.300766,-335.297424,-0.001224,0.004011,0.101882,188.163208,9.585491,1.018817,-335.297424,0.103096,0.000000
73.930000,43.583588,-335.430847,-0.001194,0.004040,0.102619,193.869476,9.876183,1.026188,-335.430847,0.103729,0.000000
74.310005,44.091499,-335.386383,-0.001212,0.004049,0.102853,196.128784,9.991277,1.028530,-335.386383,0.104362,0.000000
74.690002,46.766624,-335.341888,-0.001177,0.004084,0.103738,208.028336,10.597468,1.037375,-335.341888,0.104995,0.000000
75.070007,48.168610,-335.430847,-0.001173,0.004110,0.104397,214.264679,10.915163,1.043966,-335.430847,0.105628,0.000000
75.450005,50.766655,-335.430847,-0.001168,0.004143,0.105238,225.821365,11.503888,1.052378,-335.430847,0.106261,0.000000
75.830002,51.372505,-335.430847,-0.001143,0.004158,0.105602,228.516312,11.641175,1.056021,-335.430847,0.106894,0.000000
76.210007,52.204010,-335.475342,-0.001138,0.004175,0.106036,232.215027,11.829598,1.060357,-335.475342,0.107527,0.000000
76.590004,53.751221,-335.475342,-0.001134,0.004208,0.106886,239.097366,12.180201,1.068856,-335.475342,0.108160,0.000000
76.970001,57.044106,-335.564301,-0.001112,0.004237,0.107631,253.744858,12.926379,1.076314,-335.564301,0.108793,0.000000
77.350006,58.430824,-335.519806,-0.001087,0.004258,0.108152,259.913300,13.240614,1.081517,-335.519806,0.109427,0.000000
77.730003,60.402161,-335.564301,-0.001078,0.004285,0.108846,268.682220,13.687325,1.088455,-335.564301,0.110060,0.000000
78.110001,61.010246,-335.564301,-0.001104,0.004296,0.109123,271.387115,13.825120,1.091230,-335.564301,0.110693,0.000000
78.490005,64.240944,-335.608765,-0.001069,0.004334,0.110077,285.757996,14.557206,1.100770,-335.608765,0.111334,0.000000
78.870003,66.086433,-335.519806,-0.001061,0.004347,0.110424,293.967133,14.975400,1.104239,-335.519806,0.110710,0.000000
79.250000,65.286949,-335.564301,-0.001039,0.004347,0.110415,290.410858,14.794234,1.104152,-335.564301,294.500488,0.000000
79.630005,66.139671,-335.608765,-0.001052,0.004362,0.110805,294.203949,14.987464,1.108054,-335.608765,294.500488,0.000000
80.010002,65.566597,-335.742218,-0.001030,0.004362,0.110797,291.654785,14.857604,1.107968,-335.742218,294.500488,0.000000
80.390007,65.109688,-335.564301,-0.001039,0.004363,0.110831,289.622345,14.754066,1.108315,-335.564301,294.500488,0.000000
80.770004,65.541267,-335.697723,-0.001030,0.004374,0.111109,291.542114,14.851864,1.111089,-335.697723,294.500488,0.000000
81.150002,65.264595,-335.653259,-0.001035,0.004375,0.111126,290.311432,14.789169,1.111263,-335.653259,294.500488,0.000000
81.530006,65.203911,-335.742218,-0.001018,0.004377,0.111178,290.041473,14.775417,1.111783,-335.742218,294.500488,0.000000
81.910004,65.292534,-335.742218,-0.001030,0.004381,0.111282,290.435699,14.795500,1.112824,-335.742218,294.500488,0.000000
82.290001,65.215446,-335.742218,-0.001030,0.004381,0.111282,290.092804,14.778031,1.112824,-335.742218,294.500488,0.000000
82.670006,65.040810,-335.742218,-0.001030,0.004381,0.111282,289.315979,14.738459,1.112824,-335.742218,294.500488,0.000000
83.050003,65.027779,-335.742218,-0.001022,0.004386,0.111404,289.257996,14.735505,1.114038,-335.742218,294.500488,0.000000
83.430000,65.143578,-335.786713,-0.001026,0.004386,0.111395,289.773102,14.761745,1.113951,-335.786713,294.500488,0.000000
83.810005,65.036705,-335.831177,-0.001026,0.004386,0.111395,289.297699,14.737528,1.113951,-335.831177,294.500488,0.000000
84.190002,64.942879,-335.786713,-0.001030,0.004386,0.111395,288.880341,14.716267,1.113951,-335.786713,294.500488,0.000000
84.570007,64.819618,-335.697723,-0.001018,0.004386,0.111404,288.332062,14.688335,1.114038,-335.697723,294.500488,0.000000
84.950005,64.717216,-335.831177,-0.001030,0.004386,0.111404,287.876556,14.665131,1.114038,-335.831177,294.500488,0.000000
85.330002,66.210426,-335.920135,-0.001005,0.004395,0.111621,294.518677,15.003497,1.116206,-335.920135,294.500488,0.000000
85.710007,66.078606,-335.875671,-0.001009,0.004394,0.111612,293.932312,14.973626,1.116120,-335.875671,294.500488,0.000000
86.090004,65.937111,-335.875671,-0.001013,0.004394,0.111612,293.302917,14.941563,1.116120,-335.875671,294.500488,0.000000
86.470001,65.881630,-335.875671,-0.001013,0.004394,0.111612,293.056122,14.928990,1.116120,-335.875671,294.500488,0.000000
86.850006,65.772896,-335.875671,-0.001000,0.004394,0.111612,292.572449,14.904351,1.116120,-335.875671,294.500488,0.000000
87.230003,65.653725,-335.920135,-0.001013,0.004394,0.111612,292.042358,14.877347,1.116120,-335.920135,294.500488,0.000000
87.610001,65.557655,-335.964630,-0.001018,0.004394,0.111612,291.615021,14.855577,1.116120,-335.964630,294.500488,0.000000
87.990005,65.488777,-335.964630,-0.001005,0.004394,0.111612,291.308624,14.839969,1.116120,-335.964630,294.500488,0.000000
88.370003,65.381523,-335.964630,-0.000983,0.004394,0.111612,290.831543,14.815665,1.116120,-335.964630,294.500488,0.000000
88.750008,65.304817,-335.875671,-0.000992,0.004394,0.111612,290.490326,14.798283,1.116120,-335.875671,294.500488,0.000000
89.130005,65.258644,-335.964630,-0.001000,0.004394,0.111612,290.284943,14.787820,1.116120,-335.964630,294.500488,0.000000
89.510002,65.180443,-336.009094,-0.000996,0.004394,0.111612,289.937103,14.770100,1.116120,-336.009094,294.500488,0.000000
89.890007,65.104485,-336.053589,-0.001009,0.004394,0.111612,289.599213,14.752887,1.116120,-336.053589,294.500488,0.000000
90.270004,65.037086,-336.053589,-0.001000,0.004394,0.111612,289.299408,14.737615,1.116120,-336.053589,294.500488,0.000000
90.650002,64.986443,-336.009094,-0.000996,0.004394,0.111612,289.074127,14.726138,1.116120,-336.009094,294.500488,0.000000
91.030006,64.931328,-336.142548,-0.001009,0.004394,0.111612,288.828979,14.713649,1.116120,-336.142548,294.500488,0.000000
91.410004,64.858711,-336.098053,-0.001018,0.004394,0.111612,288.505951,14.697194,1.116120,-336.098053,294.500488,0.000000
91.790001,64.801735,-336.142548,-0.001000,0.004395,0.111621,288.252502,14.684283,1.116206,-336.142548,294.500488,0.000000
92.170006,66.098351,-336.142548,-0.001000,0.004405,0.111881,294.020142,14.978101,1.118808,-336.142548,294.500488,0.000000
92.550003,66.038399,-336.142548,-0.000992,0.004405,0.111881,293.753479,14.964515,1.118808,-336.142548,294.500488,0.000000
92.930008,65.975090,-336.187042,-0.000987,0.004405,0.111881,293.471863,14.950169,1.118808,-336.187042,294.500488,0.000000
93.310005,65.941948,-336.187042,-0.000992,0.004405,0.111881,293.324432,14.942659,1.118808,-336.187042,294.500488,0.000000
93.690002,65.908806,-336.187042,-0.001009,0.004405,0.111881,293.177002,14.935149,1.118808,-336.187042,294.500488,0.000000
94.070007,65.863747,-336.187042,-0.000996,0.004405,0.111881,292.976562,14.924938,1.118808,-336.187042,294.500488,0.000000
94.450005,65.784431,-336.187042,-0.001000,0.004405,0.111881,292.623779,14.906965,1.118808,-336.187042,294.500488,0.000000
94.830002,65.788902,-336.276001,-0.001009,0.004405,0.111881,292.643646,14.907978,1.118808,-336.276001,294.500488,0.000000
95.210007,65.752785,-336.320465,-0.000992,0.004405,0.111881,292.483002,14.899794,1.118808,-336.320465,294.500488,0.000000
95.590004,65.618355,-336.231506,-0.000996,0.004405,0.111881,291.885010,14.869332,1.118808,-336.231506,294.500488,0.000000
95.970001,65.594521,-336.231506,-0.000987,0.004405,0.111881,291.778992,14.863931,1.118808,-336.231506,294.500488,0.000000
96.350006,65.576653,-336.276001,-0.000992,0.004405,0.111881,291.699524,14.859881,1.118808,-336.276001,294.500488,0.000000
96.730003,65.547234,-336.320465,-0.000983,0.004405,0.111881,291.568665,14.853215,1.118808,-336.320465,294.500488,0.000000
97.110008,65.502541,-336.320465,-0.001009,0.004405,0.111881,291.369843,14.843087,1.118808,-336.320465,294.500488,0.000000
97.490005,65.471642,-336.364960,-0.000992,0.004405,0.111881,291.232422,14.836086,1.118808,-336.364960,294.500488,0.000000
97.870003,65.400139,-336.320465,-0.001000,0.004405,0.111881,290.914337,14.819883,1.118808,-336.320465,294.500488,0.000000
98.250008,65.358437,-336.320465,-0.000974,0.004405,0.111881,290.728851,14.810433,1.118808,-336.320465,294.500488,0.000000
98.630005,65.328270,-336.409424,-0.000987,0.004405,0.111881,290.594666,14.803597,1.118808,-336.409424,294.500488,0.000000
99.010002,65.301094,-336.453918,-0.000992,0.004405,0.111881,290.473785,14.797440,1.118808,-336.453918,294.500488,0.000000
99.390007,65.277260,-336.453918,-0.000992,0.004405,0.111881,290.367767,14.792039,1.118808,-336.453918,294.500488,0.000000
99.770004,65.270561,-336.409424,-0.001000,0.004405,0.111881,290.337952,14.790521,1.118808,-336.409424,294.500488,0.000000
100.150002,65.221779,-336.364960,-0.000983,0.004405,0.111881,290.120972,14.779467,1.118808,-336.364960,294.500488,0.000000
100.530006,65.195335,-336.498383,-0.000996,0.004405,0.111881,290.003326,14.773474,1.118808,-336.498383,294.500488,0.000000
100.910004,65.149544,-336.453918,-0.000996,0.004405,0.111881,289.799652,14.763098,1.118808,-336.453918,294.500488,0.000000
101.290009,65.098152,-336.498383,-0.000992,0.004405,0.111881,289.571045,14.751452,1.118808,-336.498383,294.500488,0.000000
101.670006,65.084007,-336.453918,-0.001000,0.004405,0.111881,289.508118,14.748247,1.118808,-336.453918,294.500488,0.000000
102.050003,65.059425,-336.498383,-0.000970,0.004405,0.111881,289.398773,14.742677,1.118808,-336.498383,294.500488,0.000000
102.430008,65.028511,-336.498383,-0.000992,0.004405,0.111881,289.261261,14.735672,1.118808,-336.498383,294.500488,0.000000
102.810005,65.009148,-336.631836,-0.000979,0.004405,0.111881,289.175140,14.731283,1.118808,-336.631836,294.500488,0.000000
103.190002,64.995003,-336.542877,-0.000992,0.004405,0.111881,289.112213,14.728079,1.118808,-336.542877,294.500488,0.000000
103.570007,64.970055,-336.542877,-0.001009,0.004405,0.111881,289.001251,14.722425,1.118808,-336.542877,294.500488,0.000000
103.950005,64.945107,-336.542877,-0.001000,0.004405,0.111881,288.890259,14.716771,1.118808,-336.542877,294.500488,0.000000
104.330002,64.921654,-336.631836,-0.000987,0.004405,0.111881,288.785950,14.711456,1.118808,-336.631836,294.500488,0.000000
104.710007,64.889626,-336.631836,-0.000979,0.004405,0.111881,288.643463,14.704200,1.118808,-336.631836,294.500488,0.000000
105.090004,64.866905,-336.587372,-0.000992,0.004405,0.111881,288.542419,14.699051,1.118808,-336.587372,294.500488,0.000000
105.470001,64.829674,-336.587372,-0.000992,0.004405,0.111889,288.376801,14.690615,1.118895,-336.587372,294.500488,0.000000
105.850006,64.788704,-336.676331,-0.000987,0.004405,0.111889,288.194550,14.681330,1.118895,-336.676331,294.500488,0.000000
106.230003,64.780510,-336.676331,-0.000992,0.004405,0.111889,288.158112,14.679474,1.118895,-336.676331,294.500488,0.000000
106.610008,64.752220,-336.765289,-0.000992,0.004405,0.111889,288.032257,14.673063,1.118895,-336.765289,294.500488,0.000000
106.990005,64.751839,-336.720795,-0.000987,0.004405,0.111889,288.030579,14.672976,1.118895,-336.720795,294.500488,0.000000
107.370003,64.735466,-336.720795,-0.000987,0.004405,0.111889,287.957733,14.669267,1.118895,-336.720795,294.500488,0.000000
107.750008,64.700829,-336.676331,-0.000979,0.004405,0.111889,287.803650,14.661417,1.118895,-336.676331,294.500488,0.000000
108.130005,64.705666,-336.720795,-0.000987,0.004405,0.111889,287.825165,14.662513,1.118895,-336.720795,294.500488,0.000000
108.510002,64.683693,-336.809753,-0.000992,0.004405,0.111898,287.727448,14.657535,1.118981,-336.809753,294.500488,0.000000
108.890007,64.665825,-336.809753,-0.000992,0.004405,0.111898,287.647949,14.653485,1.118981,-336.809753,294.500488,0.000000
109.270004,64.627480,-336.809753,-0.001005,0.004405,0.111898,287.477386,14.644796,1.118981,-336.809753,294.500488,0.000000
109.650002,64.610710,-336.765289,-0.000996,0.004405,0.111898,287.402802,14.640997,1.118981,-336.765289,294.500488,0.000000
110.030006,64.579430,-336.765289,-0.000987,0.004406,0.111915,287.263641,14.633908,1.119155,-336.765289,294.500488,0.000000
110.410004,66.398842,-336.809753,-0.000992,0.004411,0.112046,295.356812,15.046192,1.120456,-336.809753,294.500488,0.000000
110.790009,66.373161,-336.943207,-0.000996,0.004411,0.112046,295.242554,15.040373,1.120456,-336.943207,294.500488,0.000000
111.170006,66.355659,-336.854248,-0.001000,0.004411,0.112046,295.164703,15.036407,1.120456,-336.854248,294.500488,0.000000
111.550003,66.338524,-336.854248,-0.000983,0.004411,0.112046,295.088501,15.032525,1.120456,-336.854248,294.500488,0.000000
111.930008,66.315437,-336.943207,-0.000970,0.004411,0.112046,294.985809,15.027293,1.120456,-336.943207,294.500488,0.000000
112.310005,66.300163,-336.987671,-0.000987,0.004411,0.112046,294.917847,15.023831,1.120456,-336.987671,294.500488,0.000000
112.690002,66.272621,-336.943207,-0.000987,0.004411,0.112046,294.795349,15.017591,1.120456,-336.943207,294.500488,0.000000
113.070007,66.251762,-336.943207,-0.000987,0.004411,0.112046,294.702545,15.012863,1.120456,-336.943207,294.500488,0.000000
113.450005,66.223457,-336.987671,-0.000979,0.004411,0.112046,294.576660,15.006450,1.120456,-336.987671,294.500488,0.000000
113.830002,66.214149,-336.987671,-0.000983,0.004411,0.112046,294.535248,15.004341,1.120456,-336.987671,294.500488,0.000000
114.210007,66.188835,-337.032166,-0.000992,0.004411,0.112046,294.422638,14.998604,1.120456,-337.032166,294.500488,0.000000
114.590004,66.174675,-337.032166,-0.000983,0.004411,0.112046,294.359650,14.995396,1.120456,-337.032166,294.500488,0.000000
114.970009,66.154198,-337.032166,-0.000974,0.004411,0.112046,294.268555,14.990756,1.120456,-337.032166,294.500488,0.000000
115.350006,66.133720,-336.987671,-0.000979,0.004411,0.112046,294.177490,14.986115,1.120456,-336.987671,294.500488,0.000000
115.730003,66.116585,-336.987671,-0.000996,0.004411,0.112046,294.101257,14.982232,1.120456,-336.987671,294.500488,0.000000
116.110008,66.098717,-337.076660,-0.000983,0.004411,0.112046,294.021790,14.978183,1.120456,-337.076660,294.500488,0.000000
116.490005,66.079720,-337.076660,-0.000983,0.004411,0.112046,293.937286,14.973878,1.120456,-337.076660,294.500488,0.000000
116.870003,66.060738,-337.076660,-0.000996,0.004411,0.112046,293.852844,14.969577,1.120456,-337.076660,294.500488,0.000000
117.250008,66.049934,-337.032166,-0.000983,0.004411,0.112046,293.804779,14.967130,1.120456,-337.032166,294.500488,0.000000
117.630005,66.022758,-337.076660,-0.000983,0.004411,0.112046,293.683899,14.960971,1.120456,-337.076660,294.500488,0.000000
118.010002,66.008598,-337.121124,-0.000983,0.004411,0.112046,293.620911,14.957763,1.120456,-337.121124,294.500488,0.000000
118.390007,65.983284,-337.121124,-0.000979,0.004411,0.112046,293.508301,14.952025,1.120456,-337.121124,294.500488,0.000000
118.770004,66.026848,-337.165619,-0.000996,0.004411,0.112046,293.702087,14.961898,1.120456,-337.165619,294.500488,0.000000
119.150009,66.003395,-337.165619,-0.000979,0.004411,0.112046,293.597778,14.956583,1.120456,-337.165619,294.500488,0.000000
119.530006,65.903587,-337.210083,-0.000987,0.004411,0.112046,293.153809,14.933966,1.120456,-337.210083,294.500488,0.000000
119.910004,65.931526,-337.210083,-0.000992,0.004411,0.112046,293.278076,14.940297,1.120456,-337.210083,294.500488,0.000000
120.290009,65.880135,-337.254578,-0.000974,0.004411,0.112046,293.049469,14.928652,1.120456,-337.254578,294.500488,0.000000
120.670006,65.954979,-337.254578,-0.001000,0.004411,0.112046,293.382385,14.945612,1.120456,-337.254578,294.500488,0.000000
121.050003,65.854439,-337.254578,-0.000983,0.004411,0.112046,292.935181,14.922830,1.120456,-337.254578,294.500488,0.000000
121.430008,65.853325,-337.254578,-0.000974,0.004411,0.112046,292.930206,14.922577,1.120456,-337.254578,294.500488,0.000000
121.810005,65.839546,-337.254578,-0.000983,0.004411,0.112046,292.868927,14.919454,1.120456,-337.254578,294.500488,0.000000
122.190002,65.845131,-337.254578,-0.000974,0.004411,0.112046,292.893768,14.920719,1.120456,-337.254578,294.500488,0.000000
122.570007,65.884605,-337.299042,-0.000983,0.004411,0.112046,293.069366,14.929666,1.120456,-337.299042,294.500488,0.000000
122.950005,65.849220,-337.343536,-0.000996,0.004411,0.112046,292.911957,14.921646,1.120456,-337.343536,294.500488,0.000000
123.330009,65.813850,-337.343536,-0.000983,0.004411,0.112046,292.754639,14.913632,1.120456,-337.343536,294.500488,0.000000
123.710007,65.795235,-337.299042,-0.000979,0.004411,0.112046,292.671814,14.909413,1.120456,-337.299042,294.500488,0.000000
124.090004,65.776985,-337.343536,-0.000983,0.004411,0.112046,292.590637,14.905278,1.120456,-337.343536,294.500488,0.000000
124.470009,65.802315,-337.388000,-0.000983,0.004411,0.112046,292.703308,14.911017,1.120456,-337.388000,294.500488,0.000000
124.850006,65.761711,-337.388000,-0.000974,0.004411,0.112046,292.522705,14.901816,1.120456,-337.388000,294.500488,0.000000
125.230003,65.798210,-337.388000,-0.000983,0.004411,0.112046,292.685059,14.910088,1.120456,-337.388000,294.500488,0.000000
125.610008,65.743095,-337.343536,-0.000983,0.004411,0.112046,292.439880,14.897599,1.120456,-337.343536,294.500488,0.000000
125.990005,65.745338,-337.476990,-0.000970,0.004411,0.112046,292.449860,14.898107,1.120456,-337.476990,294.500488,0.000000
126.370003,65.744225,-337.432495,-0.000979,0.004411,0.112046,292.444916,14.897855,1.120456,-337.432495,294.500488,0.000000
126.750008,65.755013,-337.432495,-0.000987,0.004411,0.112046,292.492889,14.900299,1.120456,-337.432495,294.500488,0.000000
127.130005,65.680168,-337.432495,-0.000974,0.004411,0.112046,292.159973,14.883339,1.120456,-337.432495,294.500488,0.000000
127.510010,65.673470,-337.432495,-0.000987,0.004411,0.112046,292.130188,14.881822,1.120456,-337.432495,294.500488,0.000000
127.890007,65.623573,-337.476990,-0.000974,0.004411,0.112046,291.908234,14.870514,1.120456,-337.476990,294.500488,0.000000
128.270004,65.620583,-337.565948,-0.000992,0.004411,0.112046,291.894928,14.869837,1.120456,-337.565948,294.500488,0.000000
128.650009,65.595634,-337.565948,-0.000987,0.004411,0.112046,291.783966,14.864182,1.120456,-337.565948,294.500488,0.000000
129.029999,65.594902,-337.521454,-0.000966,0.004411,0.112046,291.780701,14.864017,1.120456,-337.521454,294.500488,0.000000
129.410004,65.607933,-337.565948,-0.000974,0.004411,0.112046,291.838654,14.866970,1.120456,-337.565948,294.500488,0.000000
129.790009,65.572929,-337.565948,-0.000966,0.004411,0.112046,291.682953,14.859038,1.120456,-337.565948,294.500488,0.000000
130.170013,65.578880,-337.654907,-0.000970,0.004411,0.112046,291.709442,14.860386,1.120456,-337.654907,294.500488,0.000000
130.550003,65.581123,-337.654907,-0.000987,0.004411,0.112046,291.719421,14.860894,1.120456,-337.654907,294.500488,0.000000
130.930008,65.571815,-337.565948,-0.000970,0.004411,0.112046,291.678009,14.858786,1.120456,-337.565948,294.500488,0.000000
131.310013,65.561012,-337.610413,-0.000992,0.004411,0.112046,291.629944,14.856339,1.120456,-337.610413,294.500488,0.000000
131.690002,65.547234,-337.610413,-0.000966,0.004411,0.112046,291.568665,14.853215,1.120456,-337.610413,294.500488,0.000000
132.070007,65.549461,-337.654907,-0.000987,0.004411,0.112046,291.578552,14.853720,1.120456,-337.654907,294.500488,0.000000
132.450012,65.528984,-337.743866,-0.000974,0.004411,0.112046,291.487488,14.849080,1.120456,-337.743866,294.500488,0.000000
132.830002,65.520790,-337.699371,-0.000987,0.004411,0.112046,291.451019,14.847223,1.120456,-337.699371,294.500488,0.000000
133.210007,65.519676,-337.654907,-0.000966,0.004411,0.112046,291.446075,14.846972,1.120456,-337.654907,294.500488,0.000000
133.590012,65.491005,-337.654907,-0.000970,0.004411,0.112046,291.318542,14.840473,1.120456,-337.654907,294.500488,0.000000
133.970001,65.509254,-337.788330,-0.000987,0.004411,0.112046,291.399719,14.844608,1.120456,-337.788330,294.500488,0.000000
134.350006,65.487282,-337.788330,-0.000992,0.004411,0.112046,291.301971,14.839630,1.120456,-337.788330,294.500488,0.000000
134.730011,65.488029,-337.743866,-0.000987,0.004411,0.112046,291.305298,14.839800,1.120456,-337.743866,294.500488,0.000000
135.110001,65.472389,-337.788330,-0.000979,0.004411,0.112046,291.235718,14.836256,1.120456,-337.788330,294.500488,0.000000
135.490005,65.427330,-337.788330,-0.000987,0.004411,0.112046,291.035309,14.826045,1.120456,-337.788330,294.500488,0.000000
135.870010,65.407967,-337.788330,-0.000979,0.004411,0.112046,290.949158,14.821657,1.120456,-337.788330,294.500488,0.000000
136.250000,65.412437,-337.832825,-0.000979,0.004411,0.112046,290.969055,14.822670,1.120456,-337.832825,294.500488,0.000000
136.630005,65.394936,-337.832825,-0.000987,0.004411,0.112046,290.891205,14.818705,1.120456,-337.832825,294.500488,0.000000
137.010010,65.375938,-337.832825,-0.000979,0.004411,0.112046,290.806702,14.814400,1.120456,-337.832825,294.500488,0.000000
137.389999,65.361412,-337.832825,-0.000970,0.004412,0.112054,290.742096,14.811108,1.120542,-337.832825,294.500488,0.000000
137.770004,65.355095,-337.877319,-0.000970,0.004412,0.112054,290.713989,14.809676,1.120542,-337.877319,294.500488,0.000000
138.150009,65.358070,-338.010742,-0.000974,0.004412,0.112054,290.727203,14.810350,1.120542,-338.010742,294.500488,0.000000
138.530014,65.334236,-337.877319,-0.000979,0.004412,0.112054,290.621185,14.804950,1.120542,-337.877319,294.500488,0.000000
138.910004,65.330132,-337.877319,-0.000970,0.004412,0.112054,290.602936,14.804019,1.120542,-337.877319,294.500488,0.000000
139.290009,65.313377,-337.921783,-0.000979,0.004414,0.112106,290.528412,14.800222,1.121063,-337.921783,294.500488,0.000000
139.670013,65.334984,-337.966278,-0.000979,0.004414,0.112115,290.624512,14.805119,1.121150,-337.966278,0.112046,0.000000
140.050003,65.291786,-337.966278,-0.000961,0.004399,0.111733,290.432373,14.795330,1.117334,-337.966278,0.111404,0.000000
140.430008,65.211723,-337.966278,-0.000979,0.004380,0.111248,290.076233,14.777188,1.112477,-337.966278,0.110771,0.000000
140.810013,65.221779,-338.010742,-0.000979,0.004361,0.110779,290.120972,14.779467,1.107794,-338.010742,0.110138,0.000000
141.190002,65.181557,-337.966278,-0.000961,0.004338,0.110190,289.942047,14.770352,1.101897,-337.966278,0.109505,0.000000
141.570007,65.132042,-338.010742,-0.000974,0.004308,0.109418,289.721802,14.759132,1.094179,-338.010742,0.108872,0.000000
141.950012,65.130913,-338.055237,-0.000966,0.004285,0.108828,289.716766,14.758876,1.088282,-338.055237,0.108238,0.000000
142.330002,65.124962,-338.099701,-0.000974,0.004254,0.108048,289.690308,14.757527,1.080477,-338.099701,0.107605,0.000000
142.710007,65.048256,-338.010742,-0.000979,0.004234,0.107536,289.349091,14.740146,1.075360,-338.010742,0.106972,0.000000
143.090012,65.011009,-338.055237,-0.000974,0.004209,0.106912,289.183411,14.731706,1.069116,-338.055237,0.106339,0.000000
143.470001,64.782005,-338.099701,-0.000966,0.004188,0.106374,288.164764,14.679812,1.063739,-338.099701,0.105706,0.000000
143.850006,64.149345,-338.188660,-0.000961,0.004164,0.105767,285.350525,14.536449,1.057669,-338.188660,0.105073,0.000000
144.230011,63.376671,-338.099701,-0.000974,0.004143,0.105238,281.913513,14.361359,1.052378,-338.099701,0.104440,0.000000
144.610001,62.266258,-338.144196,-0.000966,0.004121,0.104665,276.974152,14.109735,1.046655,-338.144196,0.103807,0.000000
144.990005,61.247444,-338.144196,-0.000953,0.004101,0.104154,272.442230,13.878869,1.041538,-338.144196,0.103174,0.000000
145.370010,59.643265,-338.188660,-0.000961,0.004073,0.103460,265.306488,13.515357,1.034600,-338.188660,0.102541,0.000000
145.750000,57.611229,-338.233154,-0.000966,0.004051,0.102888,256.267548,13.054891,1.028877,-338.233154,0.101908,0.000000
146.130005,55.560944,-338.233154,-0.000970,0.004025,0.102246,247.147415,12.590289,1.022459,-338.233154,0.101275,0.000000
146.510010,53.219093,-338.188660,-0.000974,0.004001,0.101630,236.730347,12.059619,1.016302,-338.188660,0.100642,0.000000
146.889999,51.191902,-338.188660,-0.000966,0.003981,0.101110,227.712952,11.600251,1.011099,-338.188660,0.100008,0.000000
147.270004,48.649345,-338.277618,-0.000970,0.003954,0.100442,216.403091,11.024099,1.004421,-338.277618,0.099375,0.000000
147.650009,45.857666,-338.277618,-0.000970,0.003929,0.099800,203.985092,10.391496,0.998003,-338.277618,0.098742,0.000000
148.030014,42.440407,-338.277618,-0.000979,0.003900,0.099063,188.784363,9.617134,0.990632,-338.277618,0.098109,0.000000
148.410004,40.363312,-338.233154,-0.000974,0.003879,0.098534,179.544983,9.146457,0.985342,-338.233154,0.097476,0.000000
148.790009,37.717606,-338.233154,-0.000961,0.003856,0.097953,167.776291,8.546931,0.979532,-338.233154,0.096843,0.000000
149.170013,34.365509,-338.277618,-0.000979,0.003825,0.097155,152.865417,7.787335,0.971553,-338.277618,0.096210,0.000000
149.550003,32.606049,-338.366608,-0.000987,0.003813,0.096843,145.038940,7.388636,0.968431,-338.366608,0.095577,0.000000
149.930008,29.505676,-338.366608,-0.000992,0.003780,0.096019,131.247803,6.686082,0.960192,-338.366608,0.094944,0.000000
150.310013,26.714371,-338.366608,-0.001000,0.003758,0.095456,118.831459,6.053563,0.954555,-338.366608,0.094311,0.000000
150.690002,23.448288,-338.366608,-0.000992,0.003729,0.094710,104.303192,5.313458,0.947097,-338.366608,0.093678,0.000000
151.070007,20.578415,-338.366608,-0.000996,0.003704,0.094094,91.537361,4.663135,0.940940,-338.366608,0.093036,0.000000
151.450012,18.992111,-338.411072,-0.001009,0.003693,0.093790,84.481133,4.303674,0.937905,-338.411072,0.092403,0.000000
151.830002,15.284393,-338.455566,-0.001018,0.003657,0.092880,67.988380,3.463493,0.928799,-338.455566,0.091770,0.000000
152.210007,13.103409,-338.411072,-0.001022,0.003634,0.092316,58.286873,2.969275,0.923162,-338.411072,0.091137,0.000000
152.590012,9.153282,-338.500031,-0.001013,0.003604,0.091553,40.715832,2.074163,0.915530,-338.500031,0.090504,0.000000
152.970001,7.035973,-338.455566,-0.001009,0.003579,0.090903,31.297569,1.594374,0.909026,-338.455566,0.089871,0.000000
153.350006,4.557091,-338.455566,-0.001030,0.003560,0.090426,20.270952,1.032652,0.904256,-338.455566,0.089238,0.000000
153.730011,1.325645,-338.544525,-0.001043,0.003533,0.089741,5.896765,0.300396,0.897405,-338.544525,0.088604,0.000000
154.110001,-1.257133,-338.500031,-0.001043,0.003504,0.089012,-5.592009,-0.284871,0.890121,-338.500031,0.087971,0.000000
154.490005,-0.180977,-338.500031,-0.001065,0.003477,0.088318,-0.805025,-0.041010,0.883183,-338.500031,0.087338,0.000000
154.870010,-0.054367,-338.500031,-0.001087,0.003455,0.087763,-0.241837,-0.012320,0.877632,-338.500031,0.086705,0.000000
155.250000,-0.069633,-338.588989,-0.001112,0.003436,0.087269,-0.309745,-0.015779,0.872689,-338.588989,0.086072,0.000000
155.630005,-0.071129,-338.588989,-0.001112,0.003407,0.086532,-0.316397,-0.016118,0.865318,-338.588989,0.085439,0.000000
156.010010,-0.084534,-338.588989,-0.001138,0.003379,0.085829,-0.376025,-0.019156,0.858293,-338.588989,0.084806,0.000000
156.390015,-0.011177,-338.633484,-0.001173,0.003362,0.085404,-0.049718,-0.002533,0.854044,-338.633484,0.085222,0.000000
156.500000,-0.006706,-338.588989,-0.001160,0.003363,0.085413,-0.029831,-0.001520,0.854131,-338.588989,0.085222,0.000000