File: Data/compression 34/AutoNoHeating-17-34-reverse-1-3_11152024_203712.csv
Time (sec),S:Load (lbs),S:HL1 (DIM),S:LVDT (in),S:Position (in),Ch:Position (mm),Ch:Load (N),Ch:Stress (MPa),Ch:Strain (mm/mm),Ch:HL1 (DIM),Set Point (),Cycles ()
0.110000,-0.049896,-161.376892,-0.012253,-0.007491,-0.190278,-0.221950,-0.011307,-1.902780,-161.376892,-0.190079,0.000000
0.530000,-0.058830,-161.376892,-0.012245,-0.007419,-0.188439,-0.261690,-0.013331,-1.884395,-161.376892,-0.187720,0.000000
0.950000,-0.047661,-161.376892,-0.012098,-0.007161,-0.181883,-0.212006,-0.010800,-1.818832,-161.376892,-0.180712,0.000000
1.370000,-0.030907,-161.421371,-0.011809,-0.006891,-0.175032,-0.137480,-0.007004,-1.750322,-161.421371,-0.173723,0.000000
1.790000,-0.020851,-161.465851,-0.011546,-0.006622,-0.168190,-0.092750,-0.004725,-1.681898,-161.465851,-0.166733,0.000000
2.210000,-0.052505,-161.510330,-0.011257,-0.006340,-0.161026,-0.233556,-0.011898,-1.610265,-161.510330,-0.159726,0.000000
2.630000,-0.070000,-161.510330,-0.010960,-0.006065,-0.154054,-0.311374,-0.015862,-1.540540,-161.510330,-0.152736,0.000000
3.050000,-0.086388,-161.510330,-0.010693,-0.005792,-0.147125,-0.384271,-0.019576,-1.471248,-161.510330,-0.145729,0.000000
3.470000,-0.013031,-161.599289,-0.010421,-0.005512,-0.140014,-0.057965,-0.002953,-1.400136,-161.599289,-0.138739,0.000000
3.890000,-0.018990,-161.599289,-0.010119,-0.005236,-0.133006,-0.084470,-0.004303,-1.330064,-161.599289,-0.131732,0.000000
4.310000,-0.007072,-161.599289,-0.009843,-0.004967,-0.126164,-0.031460,-0.001603,-1.261640,-161.599289,-0.124742,0.000000
4.730000,-0.061066,-161.599289,-0.009550,-0.004687,-0.119044,-0.271634,-0.013838,-1.190441,-161.599289,-0.117752,0.000000
5.150000,-0.120277,-161.554810,-0.009291,-0.004416,-0.112167,-0.535021,-0.027255,-1.121670,-161.554810,-0.110745,0.000000
5.570000,-0.071869,-161.643784,-0.008990,-0.004141,-0.105186,-0.319689,-0.016286,-1.051858,-161.643784,-0.103755,0.000000
5.990000,-0.010048,-161.688263,-0.008705,-0.003862,-0.098092,-0.044695,-0.002277,-0.980919,-161.688263,-0.096748,0.000000
6.410000,-0.017128,-161.688263,-0.008429,-0.003587,-0.091102,-0.076189,-0.003881,-0.911021,-161.688263,-0.089758,0.000000
6.830000,-0.042076,-161.643784,-0.008136,-0.003314,-0.084173,-0.187164,-0.009535,-0.841729,-161.643784,-0.082751,0.000000
7.250000,-0.127724,-161.777222,-0.007851,-0.003034,-0.077062,-0.568143,-0.028943,-0.770617,-161.777222,-0.075761,0.000000
7.670001,-0.096069,-161.777222,-0.007575,-0.002763,-0.070176,-0.427338,-0.021770,-0.701759,-161.777222,-0.068771,0.000000
8.090000,-0.058456,-161.821701,-0.007291,-0.002491,-0.063281,-0.260027,-0.013246,-0.632815,-161.821701,-0.061764,0.000000
8.510000,-0.016006,-161.777222,-0.006985,-0.002206,-0.056040,-0.071200,-0.003627,-0.560401,-161.777222,-0.054774,0.000000
8.930000,-0.033882,-161.732742,-0.006696,-0.001931,-0.049050,-0.150715,-0.007678,-0.490503,-161.732742,-0.047767,0.000000
9.350000,-0.055855,-161.821701,-0.006428,-0.001652,-0.041965,-0.248455,-0.012657,-0.419651,-161.821701,-0.040777,0.000000
9.770000,-0.106499,-161.866180,-0.006161,-0.001380,-0.035053,-0.473730,-0.024133,-0.350533,-161.866180,-0.033787,0.000000
10.190001,-0.039093,-161.910660,-0.005851,-0.001111,-0.028211,-0.173894,-0.008859,-0.282109,-161.910660,-0.026780,0.000000
10.610001,-0.019730,-161.910660,-0.005583,-0.000834,-0.021178,-0.087762,-0.004471,-0.211777,-161.910660,-0.019790,0.000000
11.030001,-0.024948,-161.910660,-0.005286,-0.000556,-0.014110,-0.110975,-0.005653,-0.141098,-161.910660,-0.012783,0.000000
11.450001,-0.005959,-161.910660,-0.004997,-0.000277,-0.007033,-0.026505,-0.001350,-0.070332,-161.910660,-0.005793,0.000000
11.870001,0.126610,-161.999619,-0.004941,-0.000000,-0.000000,0.563189,0.028690,-0.000000,-161.999619,0.000234,0.000000
12.290001,0.146347,-162.044098,-0.004928,-0.000000,-0.000000,0.650984,0.033163,-0.000000,-162.044098,0.000598,0.000000
12.710001,0.134804,-161.955139,-0.004924,0.000001,0.000017,0.599637,0.030547,0.000173,-161.955139,0.001301,0.000000
13.130001,0.358971,-162.044098,-0.004907,0.000033,0.000841,1.596781,0.081344,0.008412,-162.044098,0.001995,0.000000
13.550000,0.590584,-162.088593,-0.004894,0.000065,0.001656,2.627048,0.133828,0.016564,-162.088593,0.002697,0.000000
13.970000,0.774910,-162.088593,-0.004876,0.000088,0.002246,3.446972,0.175597,0.022461,-162.088593,0.003400,0.000000
14.390000,1.080254,-162.088593,-0.004846,0.000114,0.002888,4.805208,0.244789,0.028879,-162.088593,0.004102,0.000000
14.810000,1.342033,-162.044098,-0.004833,0.000132,0.003356,5.969663,0.304109,0.033562,-162.044098,0.004796,0.000000
15.230000,2.082306,-162.133072,-0.004794,0.000174,0.004432,9.262559,0.471857,0.044315,-162.133072,0.005498,0.000000
15.650001,2.530273,-162.088593,-0.004790,0.000203,0.005169,11.255219,0.573368,0.051687,-162.088593,0.006201,0.000000
16.070002,2.958504,-162.177551,-0.004751,0.000230,0.005836,13.160082,0.670407,0.058364,-162.177551,0.006894,0.000000
16.490002,3.347260,-162.177551,-0.004725,0.000252,0.006391,14.889354,0.758500,0.063915,-162.177551,0.007597,0.000000
16.910002,3.994446,-162.133072,-0.004712,0.000279,0.007094,17.768183,0.905154,0.070939,-162.133072,0.008299,0.000000
17.330000,4.608856,-162.177551,-0.004678,0.000312,0.007926,20.501217,1.044382,0.079264,-162.177551,0.009002,0.000000
17.750000,4.966331,-162.310989,-0.004665,0.000331,0.008403,22.091345,1.125387,0.084034,-162.310989,0.009696,0.000000
18.170000,5.751671,-162.310989,-0.004644,0.000364,0.009236,25.584709,1.303347,0.092360,-162.310989,0.010398,0.000000
18.590000,5.935249,-162.222031,-0.004605,0.000380,0.009644,26.401308,1.344947,0.096436,-162.222031,0.011100,0.000000
19.010000,6.913841,-162.222031,-0.004583,0.000418,0.010624,30.754301,1.566699,0.106235,-162.222031,0.011794,0.000000
19.430000,7.415802,-162.399948,-0.004566,0.000448,0.011378,32.987133,1.680445,0.113780,-162.399948,0.012497,0.000000
19.850000,7.937866,-162.355469,-0.004531,0.000474,0.012028,35.309391,1.798746,0.120284,-162.355469,0.013199,0.000000
20.270000,8.294228,-162.355469,-0.004514,0.000501,0.012714,36.894566,1.879499,0.127135,-162.355469,0.013902,0.000000
20.690001,8.736237,-162.355469,-0.004493,0.000521,0.013243,38.860722,1.979660,0.132425,-162.355469,0.014595,0.000000
21.110001,9.730095,-162.399948,-0.004471,0.000560,0.014223,43.281624,2.204871,0.142225,-162.399948,0.015298,0.000000
21.530001,10.045494,-162.399948,-0.004458,0.000585,0.014864,44.684589,2.276341,0.148642,-162.399948,0.016000,0.000000
21.950001,10.275246,-162.444427,-0.004432,0.000607,0.015428,45.706577,2.328404,0.154279,-162.444427,0.016703,0.000000
22.370001,11.024834,-162.444427,-0.004389,0.000645,0.016382,49.040909,2.498263,0.163819,-162.444427,0.017397,0.000000
22.790001,11.462372,-162.488907,-0.004363,0.000670,0.017024,50.987175,2.597410,0.170236,-162.488907,0.018099,0.000000
23.210001,11.813148,-162.533401,-0.004337,0.000695,0.017657,52.547508,2.676898,0.176567,-162.533401,0.018801,0.000000
23.630001,12.094284,-162.533401,-0.004324,0.000715,0.018160,53.798061,2.740604,0.181597,-162.533401,0.019495,0.000000
24.050001,12.919464,-162.577881,-0.004299,0.000749,0.019018,57.468647,2.927592,0.190183,-162.577881,0.020198,0.000000
24.470001,13.347694,-162.622360,-0.004277,0.000778,0.019764,59.373508,3.024631,0.197641,-162.622360,0.020900,0.000000
24.890001,13.822098,-162.577881,-0.004238,0.000807,0.020501,61.483761,3.132132,0.205012,-162.577881,0.021603,0.000000
25.310001,13.903648,-162.533401,-0.004234,0.000829,0.021048,61.846516,3.150612,0.210476,-162.533401,0.022296,0.000000
25.730001,14.513962,-162.622360,-0.004208,0.000858,0.021793,64.561325,3.288911,0.217934,-162.622360,0.022999,0.000000
26.150002,14.694191,-162.622360,-0.004178,0.000884,0.022461,65.363029,3.329751,0.224611,-162.622360,0.023701,0.000000
26.570002,15.621399,-162.666840,-0.004152,0.000920,0.023363,69.487450,3.539860,0.233631,-162.666840,0.024395,0.000000
26.990002,15.655289,-162.711319,-0.004126,0.000944,0.023987,69.638199,3.547539,0.239875,-162.711319,0.025098,0.000000
27.410002,15.974037,-162.666840,-0.004113,0.000972,0.024690,71.056068,3.619769,0.246899,-162.666840,0.025800,0.000000
27.830002,16.389603,-162.800278,-0.004083,0.000999,0.025366,72.904594,3.713937,0.253664,-162.800278,0.026502,0.000000
28.250002,16.259277,-162.755798,-0.004061,0.001016,0.025809,72.324875,3.684405,0.258086,-162.755798,0.027196,0.000000
28.670002,17.253883,-162.800278,-0.004031,0.001053,0.026737,76.749107,3.909786,0.267366,-162.800278,0.027899,0.000000
29.090002,17.512680,-162.800278,-0.004018,0.001082,0.027482,77.900291,3.968430,0.274824,-162.800278,0.028601,0.000000
29.510002,17.263565,-162.800278,-0.004014,0.001100,0.027951,76.792175,3.911980,0.279507,-162.800278,0.029304,0.000000
29.930002,17.737968,-162.800278,-0.003984,0.001130,0.028705,78.902428,4.019481,0.287052,-162.800278,0.029997,0.000000
30.350002,17.972931,-162.844757,-0.003949,0.001156,0.029373,79.947586,4.072724,0.293729,-162.844757,0.030700,0.000000
30.770002,18.866257,-162.933731,-0.003923,0.001196,0.030379,83.921303,4.275155,0.303789,-162.933731,0.031402,0.000000
31.190001,18.725121,-162.933731,-0.003898,0.001219,0.030951,83.293495,4.243173,0.309513,-162.933731,0.032096,0.000000
31.610001,18.882263,-162.889236,-0.003889,0.001243,0.031584,83.992500,4.278782,0.315844,-162.889236,0.032798,0.000000
32.030003,18.825668,-162.933731,-0.003880,0.001271,0.032278,83.740753,4.265957,0.322781,-162.933731,0.033501,0.000000
32.450001,19.125053,-162.978210,-0.003850,0.001300,0.033015,85.072487,4.333799,0.330153,-162.978210,0.034203,0.000000
32.870003,19.609879,-162.933731,-0.003820,0.001328,0.033726,87.229095,4.443662,0.337264,-162.933731,0.034897,0.000000
33.290001,19.984489,-162.978210,-0.003794,0.001363,0.034628,88.895447,4.528550,0.346283,-162.978210,0.035600,0.000000
33.710003,19.673187,-162.978210,-0.003786,0.001382,0.035114,87.510704,4.458008,0.351140,-162.978210,0.036302,0.000000
34.130001,19.745796,-162.978210,-0.003764,0.001405,0.035695,87.833687,4.474461,0.356950,-162.978210,0.036996,0.000000
34.550003,20.223175,-163.156128,-0.003747,0.001440,0.036580,89.957176,4.582637,0.365796,-163.156128,0.037698,0.000000
34.970001,20.517349,-163.067169,-0.003712,0.001470,0.037325,91.265724,4.649298,0.373254,-163.067169,0.038401,0.000000
35.390003,20.310310,-163.067169,-0.003695,0.001489,0.037828,90.344772,4.602382,0.378284,-163.067169,0.039103,0.000000
35.810001,20.439896,-163.067169,-0.003695,0.001518,0.038566,90.921196,4.631747,0.385655,-163.067169,0.039797,0.000000
36.230003,20.079819,-163.156128,-0.003678,0.001533,0.038938,89.319496,4.550152,0.389384,-163.156128,0.040499,0.000000
36.650002,21.411049,-163.200607,-0.003652,0.001579,0.040101,95.241104,4.851813,0.401005,-163.200607,0.041202,0.000000
37.070004,21.344765,-163.200607,-0.003609,0.001611,0.040916,94.946259,4.836793,0.409157,-163.200607,0.041904,0.000000
37.490002,21.299332,-163.156128,-0.003613,0.001634,0.041505,94.744156,4.826498,0.415054,-163.156128,0.042598,0.000000
37.910004,21.030113,-163.200607,-0.003579,0.001654,0.042000,93.546616,4.765492,0.419997,-163.200607,0.043301,0.000000
38.330002,21.877998,-163.245087,-0.003579,0.001691,0.042954,97.318199,4.957625,0.429537,-163.245087,0.044003,0.000000
38.750000,21.937950,-163.200607,-0.003553,0.001716,0.043578,97.584877,4.971210,0.435781,-163.200607,0.044697,0.000000
39.170002,21.847839,-163.245087,-0.003531,0.001739,0.044159,97.184044,4.950791,0.441591,-163.245087,0.045399,0.000000
39.590000,21.966255,-163.289566,-0.003510,0.001762,0.044766,97.710785,4.977624,0.447662,-163.289566,0.046102,0.000000
40.010002,21.800179,-163.245087,-0.003501,0.001783,0.045287,96.972038,4.939991,0.452865,-163.245087,0.046804,0.000000
40.430000,23.068108,-163.334045,-0.003471,0.001828,0.046440,102.612068,5.227308,0.464399,-163.334045,0.047498,0.000000
40.850002,22.539711,-163.378540,-0.003462,0.001852,0.047038,100.261642,5.107572,0.470383,-163.378540,0.048200,0.000000
41.270000,23.163063,-163.334045,-0.003415,0.001884,0.047862,103.034447,5.248825,0.478622,-163.334045,0.048903,0.000000
41.690002,22.484596,-163.378540,-0.003406,0.001899,0.048235,100.016479,5.095082,0.482351,-163.378540,0.049597,0.000000
42.110001,22.500984,-163.378540,-0.003393,0.001922,0.048825,100.089378,5.098796,0.488248,-163.378540,0.050299,0.000000
42.530003,23.729813,-163.423019,-0.003385,0.001964,0.049883,105.555481,5.377253,0.498828,-163.423019,0.051002,0.000000
42.950001,23.600967,-163.467499,-0.003341,0.001989,0.050533,104.982346,5.348055,0.505332,-163.467499,0.051704,0.000000
43.370003,24.087662,-163.467499,-0.003324,0.002022,0.051366,107.147270,5.458343,0.513658,-163.467499,0.052398,0.000000
43.790001,24.062340,-163.467499,-0.003311,0.002050,0.052060,107.034630,5.452604,0.520596,-163.467499,0.053100,0.000000
44.210003,24.360985,-163.511978,-0.003294,0.002077,0.052762,108.363075,5.520278,0.527620,-163.511978,0.053803,0.000000
44.630001,24.376991,-163.556458,-0.003277,0.002099,0.053317,108.434273,5.523905,0.533170,-163.556458,0.054505,0.000000
45.050003,24.427261,-163.600937,-0.003251,0.002126,0.054011,108.657883,5.535296,0.540108,-163.600937,0.055199,0.000000
45.470001,24.733727,-163.511978,-0.003225,0.002148,0.054566,110.021111,5.604743,0.545658,-163.511978,0.055901,0.000000
45.890003,25.291916,-163.556458,-0.003208,0.002181,0.055407,112.504059,5.731230,0.554071,-163.556458,0.056604,0.000000
46.310001,25.923454,-163.600937,-0.003191,0.002213,0.056205,115.313286,5.874339,0.562049,-163.600937,0.057298,0.000000
46.730003,25.735779,-163.689896,-0.003182,0.002234,0.056734,114.478462,5.831811,0.567339,-163.689896,0.058000,0.000000
47.150002,26.455948,-163.645416,-0.003156,0.002269,0.057627,117.681931,5.995004,0.576271,-163.645416,0.058703,0.000000
47.570004,26.434349,-163.645416,-0.003122,0.002292,0.058208,117.585854,5.990109,0.582082,-163.645416,0.059405,0.000000
47.990002,27.127708,-163.689896,-0.003117,0.002324,0.059041,120.670074,6.147227,0.590407,-163.689896,0.060099,0.000000
48.410004,27.243889,-163.734375,-0.003104,0.002352,0.059752,121.186867,6.173553,0.597519,-163.734375,0.060801,0.000000
48.830002,27.029404,-163.734375,-0.003074,0.002371,0.060220,120.232796,6.124951,0.602202,-163.734375,0.061504,0.000000
49.250004,27.369003,-163.778854,-0.003048,0.002403,0.061044,121.743408,6.201905,0.610440,-163.778854,0.062197,0.000000
49.670002,27.029778,-163.778854,-0.003040,0.002420,0.061478,120.234459,6.125035,0.614776,-163.778854,0.062900,0.000000
50.090004,28.619804,-163.823349,-0.003014,0.002460,0.062484,127.307251,6.485341,0.624836,-163.823349,0.063602,0.000000
50.510002,29.224907,-163.778854,-0.003005,0.002488,0.063186,129.998886,6.622458,0.631861,-163.778854,0.064305,0.000000
50.930004,29.218582,-163.912308,-0.002975,0.002510,0.063758,129.970749,6.621026,0.637584,-163.912308,0.064999,0.000000
51.350002,29.543663,-163.912308,-0.002953,0.002537,0.064452,131.416779,6.694690,0.644522,-163.912308,0.065701,0.000000
51.770004,29.821075,-163.912308,-0.002928,0.002563,0.065103,132.650772,6.757552,0.651026,-163.912308,0.066403,0.000000
52.190002,30.842125,-163.867828,-0.002910,0.002598,0.065996,137.192627,6.988925,0.659959,-163.867828,0.067106,0.000000
52.610001,31.266258,-163.912308,-0.002902,0.002626,0.066707,139.079269,7.085035,0.667070,-163.912308,0.067800,0.000000
53.030003,31.387650,-163.956787,-0.002880,0.002653,0.067392,139.619232,7.112543,0.673921,-163.956787,0.068502,0.000000
53.450001,31.848648,-163.956787,-0.002859,0.002677,0.068008,141.669861,7.217007,0.680078,-163.956787,0.069205,0.000000
53.870003,32.734520,-164.045746,-0.002837,0.002709,0.068797,145.610413,7.417748,0.687970,-164.045746,0.069898,0.000000
54.290001,33.362717,-163.956787,-0.002807,0.002740,0.069586,148.404770,7.560100,0.695862,-163.956787,0.070601,0.000000
54.710003,33.772697,-163.956787,-0.002794,0.002765,0.070219,150.228455,7.653003,0.702193,-163.956787,0.071303,0.000000
55.130001,33.462883,-164.045746,-0.002777,0.002784,0.070722,148.850342,7.582798,0.707223,-164.045746,0.072006,0.000000
55.550003,33.751099,-164.090225,-0.002751,0.002813,0.071459,150.132385,7.648108,0.714594,-164.090225,0.072700,0.000000
55.970001,35.452469,-164.090225,-0.002734,0.002847,0.072318,157.700455,8.033645,0.723180,-164.090225,0.073402,0.000000
56.390003,35.537369,-164.090225,-0.002721,0.002871,0.072925,158.078110,8.052883,0.729250,-164.090225,0.074104,0.000000
56.810001,36.068375,-164.090225,-0.002708,0.002898,0.073601,160.440140,8.173210,0.736014,-164.090225,0.074807,0.000000
57.230003,36.089966,-164.179184,-0.002677,0.002917,0.074104,160.536179,8.178102,0.741044,-164.179184,0.075501,0.000000
57.650002,37.061859,-164.134705,-0.002652,0.002949,0.074911,164.859390,8.398337,0.749110,-164.134705,0.076203,0.000000
58.070004,38.619125,-164.223679,-0.002626,0.002983,0.075778,171.786453,8.751219,0.757782,-164.223679,0.076906,0.000000
58.490002,39.400360,-164.179184,-0.002604,0.003011,0.076481,175.261551,8.928249,0.764806,-164.179184,0.077599,0.000000
58.910004,39.716133,-164.223679,-0.002604,0.003038,0.077174,176.666183,8.999804,0.771744,-164.223679,0.078302,0.000000
59.330002,39.831940,-164.268158,-0.002574,0.003057,0.077651,177.181320,9.026047,0.776514,-164.268158,0.079004,0.000000
59.750004,41.439842,-164.268158,-0.002570,0.003091,0.078501,184.333618,9.390402,0.785013,-164.268158,0.079707,0.000000
60.170002,41.830833,-164.357117,-0.002544,0.003115,0.079117,186.072845,9.479002,0.791170,-164.357117,0.080400,0.000000
60.590004,42.491425,-164.223679,-0.002527,0.003143,0.079828,189.011292,9.628694,0.798281,-164.223679,0.081103,0.000000
61.010002,43.352348,-164.268158,-0.002509,0.003168,0.080479,192.840881,9.823783,0.804785,-164.268158,0.081805,0.000000
61.430004,44.380096,-164.312637,-0.002496,0.003198,0.081233,197.412521,10.056674,0.812330,-164.312637,0.082499,0.000000
61.850002,46.131737,-164.401596,-0.002475,0.003233,0.082109,205.204208,10.453601,0.821089,-164.401596,0.083202,0.000000
62.270004,46.289627,-164.401596,-0.002440,0.003258,0.082751,205.906540,10.489379,0.827507,-164.401596,0.083904,0.000000
62.690002,47.959343,-164.357117,-0.002445,0.003288,0.083505,213.333817,10.867743,0.835052,-164.357117,0.084607,0.000000
63.110004,47.967163,-164.357117,-0.002410,0.003307,0.083999,213.368591,10.869514,0.839995,-164.357117,0.085300,0.000000
63.530003,49.135666,-164.446075,-0.002393,0.003336,0.084745,218.566360,11.134300,0.847453,-164.446075,0.086003,0.000000
63.950005,50.931244,-164.401596,-0.002389,0.003369,0.085569,226.553482,11.541185,0.855692,-164.401596,0.086705,0.000000
64.370003,51.725517,-164.535034,-0.002363,0.003398,0.086315,230.086594,11.721170,0.863150,-164.535034,0.087408,0.000000
64.790001,52.968864,-164.446075,-0.002341,0.003425,0.086983,235.617279,12.002916,0.869827,-164.446075,0.088101,0.000000
65.210007,53.922516,-164.446075,-0.002333,0.003451,0.087651,239.859329,12.219017,0.876505,-164.446075,0.088804,0.000000
65.630005,55.407906,-164.535034,-0.002324,0.003479,0.088370,246.466675,12.555611,0.883703,-164.535034,0.089506,0.000000
66.050003,56.099777,-164.579514,-0.002302,0.003502,0.088943,249.544266,12.712391,0.889427,-164.579514,0.090200,0.000000
66.470001,57.299934,-164.579514,-0.002294,0.003530,0.089662,254.882843,12.984350,0.896625,-164.579514,0.090903,0.000000
66.889999,57.905411,-164.623993,-0.002268,0.003547,0.090105,257.576141,13.121553,0.901047,-164.623993,0.091605,0.000000
67.310005,60.033150,-164.623993,-0.002264,0.003583,0.091015,267.040802,13.603706,0.910153,-164.623993,0.092308,0.000000
67.730003,61.830215,-164.623993,-0.002246,0.003616,0.091848,275.034546,14.010927,0.918479,-164.623993,0.093001,0.000000
68.150002,62.812164,-164.623993,-0.002233,0.003638,0.092394,279.402466,14.233440,0.923942,-164.623993,0.093704,0.000000
68.570000,64.751106,-164.757446,-0.002212,0.003670,0.093227,288.027313,14.672811,0.932268,-164.757446,0.094406,0.000000
68.990005,65.848122,-164.712967,-0.002177,0.003699,0.093947,292.907074,14.921397,0.939466,-164.712967,0.095100,0.000000
69.410004,65.438881,-164.668488,-0.002190,0.003698,0.093938,291.086670,14.828663,0.939379,-164.668488,0.016491,0.000000
69.830002,65.875298,-164.801926,-0.002186,0.003742,0.095048,293.027954,14.927555,0.950479,-164.801926,294.500488,0.000000
70.250000,65.785561,-164.801926,-0.002151,0.003532,0.089706,292.628784,14.907221,0.897058,-164.801926,294.500488,0.000000
70.670006,65.285835,-164.801926,-0.002143,0.003724,0.094580,290.405914,14.793983,0.945796,-164.801926,294.500488,0.000000
71.090004,65.179710,-164.846405,-0.002151,0.003734,0.094840,289.933838,14.769934,0.948398,-164.846405,294.500488,0.000000
71.510002,65.072456,-164.757446,-0.002134,0.003741,0.095031,289.456757,14.745629,0.950306,-164.757446,294.500488,0.000000
71.930000,65.062035,-164.801926,-0.002130,0.003748,0.095204,289.410370,14.743267,0.952040,-164.801926,294.500488,0.000000
72.350006,65.049751,-164.801926,-0.002130,0.003759,0.095482,289.355743,14.740485,0.954815,-164.801926,294.500488,0.000000
72.770004,65.052727,-164.979843,-0.002117,0.003760,0.095516,289.368988,14.741158,0.955162,-164.979843,294.500488,0.000000
73.190002,65.405739,-164.935364,-0.002121,0.003770,0.095750,290.939270,14.821152,0.957504,-164.935364,294.500488,0.000000
73.610001,64.996498,-164.935364,-0.002108,0.003770,0.095759,289.118866,14.728416,0.957591,-164.935364,294.500488,0.000000
74.030006,65.210991,-164.890884,-0.002104,0.003779,0.095976,290.072968,14.777021,0.959759,-164.890884,294.500488,0.000000
74.450005,64.934319,-164.979843,-0.002104,0.003779,0.095976,288.842285,14.714327,0.959759,-164.979843,294.500488,0.000000
74.870003,65.646294,-164.935364,-0.002082,0.003790,0.096262,292.009308,14.875662,0.962620,-164.935364,294.500488,0.000000
75.290001,65.323067,-165.024323,-0.002074,0.003790,0.096262,290.571503,14.802419,0.962620,-165.024323,294.500488,0.000000
75.710007,64.977501,-164.979843,-0.002082,0.003790,0.096271,289.034363,14.724113,0.962707,-164.979843,294.500488,0.000000
76.130005,64.639015,-165.024323,-0.002078,0.003790,0.096271,287.528687,14.647410,0.962707,-165.024323,294.500488,0.000000
76.550003,65.971001,-165.068802,-0.002074,0.003796,0.096418,293.453674,14.949242,0.964182,-165.068802,294.500488,0.000000
76.970001,65.568092,-165.113297,-0.002082,0.003796,0.096418,291.661438,14.857943,0.964182,-165.113297,294.500488,0.000000
77.390007,65.223640,-165.113297,-0.002061,0.003798,0.096470,290.129242,14.779888,0.964702,-165.113297,294.500488,0.000000
77.810005,64.948463,-165.157776,-0.002074,0.003801,0.096557,288.905182,14.717532,0.965569,-165.157776,294.500488,0.000000
78.230003,65.100395,-165.113297,-0.002070,0.003809,0.096748,289.581024,14.751961,0.967477,-165.113297,294.500488,0.000000
78.650002,64.894096,-165.157776,-0.002078,0.003809,0.096748,288.663361,14.705213,0.967477,-165.157776,294.500488,0.000000
79.070007,64.685188,-165.202255,-0.002074,0.003809,0.096748,287.734100,14.657873,0.967477,-165.202255,294.500488,0.000000
79.490005,65.252312,-165.246735,-0.002057,0.003818,0.096982,290.256775,14.786386,0.969819,-165.246735,294.500488,0.000000
79.910004,65.083641,-165.246735,-0.002052,0.003819,0.096991,289.506500,14.748164,0.969905,-165.246735,294.500488,0.000000
80.330002,64.929848,-165.246735,-0.002070,0.003819,0.097008,288.822388,14.713314,0.970079,-165.246735,294.500488,0.000000
80.750008,64.782005,-165.246735,-0.002065,0.003819,0.097008,288.164764,14.679812,0.970079,-165.246735,294.500488,0.000000
81.170006,64.982719,-165.335693,-0.002052,0.003824,0.097121,289.057587,14.725295,0.971206,-165.335693,294.500488,0.000000
81.590004,64.839729,-165.380173,-0.002065,0.003824,0.097121,288.421509,14.692893,0.971206,-165.380173,294.500488,0.000000
82.010002,64.693764,-165.380173,-0.002048,0.003824,0.097121,287.772247,14.659817,0.971206,-165.380173,294.500488,0.000000
82.430000,65.795235,-165.380173,-0.002035,0.003837,0.097450,292.671814,14.909413,0.974501,-165.380173,294.500488,0.000000
82.850006,65.746086,-165.424652,-0.002065,0.003837,0.097450,292.453186,14.898275,0.974501,-165.424652,294.500488,0.000000
83.270004,65.568459,-165.424652,-0.002052,0.003837,0.097450,291.663055,14.858025,0.974501,-165.424652,294.500488,0.000000
83.690002,65.440361,-165.469131,-0.002044,0.003837,0.097450,291.093262,14.828998,0.974501,-165.469131,294.500488,0.000000
84.110001,65.297005,-165.469131,-0.002048,0.003837,0.097450,290.455597,14.796514,0.974501,-165.469131,294.500488,0.000000
84.530006,65.161827,-165.380173,-0.002057,0.003837,0.097450,289.854279,14.765881,0.974501,-165.380173,294.500488,0.000000
84.950005,65.020699,-165.513626,-0.002057,0.003837,0.097450,289.226501,14.733901,0.974501,-165.513626,294.500488,0.000000
85.370003,64.909737,-165.513626,-0.002044,0.003837,0.097459,288.732941,14.708756,0.974588,-165.513626,294.500488,0.000000
85.790001,64.760048,-165.558105,-0.002035,0.003837,0.097459,288.067078,14.674837,0.974588,-165.558105,294.500488,0.000000
86.210007,64.652428,-165.558105,-0.002026,0.003837,0.097459,287.588348,14.650450,0.974588,-165.558105,294.500488,0.000000
86.630005,64.502357,-165.513626,-0.002048,0.003837,0.097459,286.920807,14.616443,0.974588,-165.513626,294.500488,0.000000
87.050003,64.394737,-165.647064,-0.002031,0.003837,0.097459,286.442108,14.592055,0.974588,-165.647064,294.500488,0.000000
87.470001,66.678505,-165.558105,-0.002048,0.003789,0.096245,296.600800,15.109565,0.962447,-165.558105,294.500488,0.000000
87.890007,66.483009,-165.691544,-0.002026,0.003789,0.096245,295.731201,15.065265,0.962447,-165.691544,294.500488,0.000000
88.310005,66.326988,-165.647064,-0.002031,0.003790,0.096253,295.037170,15.029910,0.962534,-165.647064,294.500488,0.000000
88.730003,66.194420,-165.602585,-0.002018,0.003790,0.096253,294.447479,14.999869,0.962534,-165.602585,294.500488,0.000000
89.150002,66.058876,-165.691544,-0.002018,0.003790,0.096253,293.844543,14.969155,0.962534,-165.691544,294.500488,0.000000
89.570007,65.975471,-165.736023,-0.002026,0.003791,0.096288,293.473541,14.950256,0.962881,-165.736023,294.500488,0.000000
89.990005,65.793373,-165.736023,-0.002018,0.003793,0.096340,292.663544,14.908991,0.963401,-165.736023,294.500488,0.000000
90.410004,65.723747,-165.780502,-0.002018,0.003800,0.096514,292.353821,14.893213,0.965135,-165.780502,294.500488,0.000000
90.830002,65.561760,-165.691544,-0.002013,0.003806,0.096678,291.633270,14.856507,0.966783,-165.691544,294.500488,0.000000
91.250008,65.505531,-165.780502,-0.002026,0.003811,0.096800,291.383148,14.843765,0.967997,-165.780502,294.500488,0.000000
91.670006,65.350624,-165.824982,-0.002026,0.003817,0.096947,290.694092,14.808662,0.969472,-165.824982,294.500488,0.000000
92.090004,65.270195,-165.869461,-0.002009,0.003823,0.097095,290.336334,14.790438,0.970946,-165.869461,294.500488,0.000000
92.510002,65.187904,-165.824982,-0.002013,0.003823,0.097112,289.970276,14.771790,0.971119,-165.824982,294.500488,0.000000
92.930008,65.149544,-165.869461,-0.002013,0.003840,0.097537,289.799652,14.763098,0.975369,-165.869461,294.500488,0.000000
93.350006,65.131676,-165.869461,-0.002022,0.003849,0.097762,289.720154,14.759048,0.977624,-165.869461,294.500488,0.000000
93.770004,65.089958,-165.913940,-0.002031,0.003852,0.097849,289.534607,14.749595,0.978491,-165.913940,294.500488,0.000000
94.190002,65.019951,-165.913940,-0.002026,0.003852,0.097849,289.223175,14.733731,0.978491,-165.913940,294.500488,0.000000
94.610008,65.453407,-165.913940,-0.002018,0.003860,0.098049,291.151306,14.831954,0.980485,-165.913940,294.500488,0.000000
95.030006,65.401268,-165.913940,-0.002026,0.003860,0.098040,290.919373,14.820139,0.980399,-165.913940,294.500488,0.000000
95.450005,65.329765,-165.958435,-0.002013,0.003860,0.098040,290.601318,14.803937,0.980399,-165.958435,294.500488,0.000000
95.870003,65.279869,-166.047394,-0.002018,0.003860,0.098040,290.379364,14.792629,0.980399,-166.047394,294.500488,0.000000
96.290001,65.208000,-166.002914,-0.002018,0.003860,0.098040,290.059662,14.776343,0.980399,-166.002914,294.500488,0.000000
96.710007,65.143959,-166.091873,-0.002026,0.003860,0.098040,289.774811,14.761832,0.980399,-166.091873,294.500488,0.000000
97.130005,65.074699,-166.002914,-0.002009,0.003860,0.098040,289.466705,14.746138,0.980399,-166.002914,294.500488,0.000000
97.550003,65.309669,-166.047394,-0.002022,0.003865,0.098170,290.511932,14.799383,0.981699,-166.047394,294.500488,0.000000
97.970001,65.308540,-166.091873,-0.002022,0.003865,0.098170,290.506897,14.799127,0.981699,-166.091873,294.500488,0.000000
98.390007,65.259773,-166.180832,-0.002022,0.003865,0.098170,290.289978,14.788075,0.981699,-166.180832,294.500488,0.000000
98.810005,65.210991,-166.091873,-0.002009,0.003865,0.098170,290.072968,14.777021,0.981699,-166.091873,294.500488,0.000000
99.230003,65.158485,-166.180832,-0.002031,0.003865,0.098170,289.839417,14.765123,0.981699,-166.180832,294.500488,0.000000
99.650002,65.148430,-166.180832,-0.002026,0.003866,0.098196,289.794678,14.762845,0.981960,-166.180832,294.500488,0.000000
100.070007,65.085869,-166.225311,-0.002026,0.003866,0.098196,289.516418,14.748669,0.981960,-166.225311,294.500488,0.000000
100.490005,65.048637,-166.225311,-0.002001,0.003866,0.098196,289.350800,14.740232,0.981960,-166.225311,294.500488,0.000000
100.910004,65.009163,-166.225311,-0.002013,0.003866,0.098196,289.175201,14.731286,0.981960,-166.225311,294.500488,0.000000
101.330002,64.965218,-166.225311,-0.002018,0.003866,0.098205,288.979706,14.721329,0.982046,-166.225311,294.500488,0.000000
101.750008,64.918678,-166.314270,-0.002026,0.003866,0.098205,288.772705,14.710783,0.982046,-166.314270,294.500488,0.000000
102.170006,64.858345,-166.314270,-0.002009,0.003866,0.098205,288.504333,14.697111,0.982046,-166.314270,294.500488,0.000000
102.590004,64.803230,-166.403244,-0.002013,0.003866,0.098205,288.259155,14.684622,0.982046,-166.403244,294.500488,0.000000
103.010002,65.613152,-166.314270,-0.001996,0.003879,0.098517,291.861877,14.868153,0.985168,-166.314270,294.500488,0.000000
103.430008,65.696556,-166.358749,-0.002009,0.003878,0.098491,292.232880,14.887053,0.984908,-166.358749,294.500488,0.000000
103.850006,65.666389,-166.403244,-0.002013,0.003878,0.098491,292.098694,14.880217,0.984908,-166.403244,294.500488,0.000000
104.270004,65.618355,-166.403244,-0.002001,0.003878,0.098491,291.885010,14.869332,0.984908,-166.403244,294.500488,0.000000
104.690002,65.607567,-166.492203,-0.002005,0.003878,0.098491,291.837036,14.866887,0.984908,-166.492203,294.500488,0.000000
105.110008,65.578514,-166.447723,-0.002013,0.003878,0.098491,291.707794,14.860304,0.984908,-166.447723,294.500488,0.000000
105.530006,65.539421,-166.447723,-0.002005,0.003878,0.098491,291.533905,14.851445,0.984908,-166.447723,294.500488,0.000000
105.950005,65.496223,-166.447723,-0.002018,0.003878,0.098499,291.341766,14.841657,0.984995,-166.447723,294.500488,0.000000
106.370003,65.446693,-166.492203,-0.001996,0.003878,0.098499,291.121429,14.830433,0.984995,-166.492203,294.500488,0.000000
106.790009,65.383400,-166.536682,-0.001988,0.003878,0.098499,290.839874,14.816090,0.984995,-166.536682,294.500488,0.000000
107.210007,65.355461,-166.581161,-0.002001,0.003878,0.098499,290.715607,14.809759,0.984995,-166.581161,294.500488,0.000000
107.630005,65.324181,-166.536682,-0.002001,0.003878,0.098508,290.576477,14.802671,0.985082,-166.536682,294.500488,0.000000
108.050003,65.289558,-166.625641,-0.002009,0.003878,0.098508,290.422455,14.794826,0.985082,-166.625641,294.500488,0.000000
108.470009,65.248222,-166.670120,-0.001996,0.003879,0.098517,290.238586,14.785459,0.985168,-166.670120,294.500488,0.000000
108.890007,65.199440,-166.670120,-0.001996,0.003879,0.098517,290.021606,14.774405,0.985168,-166.670120,294.500488,0.000000
109.310005,65.171135,-166.625641,-0.001996,0.003879,0.098517,289.895691,14.767991,0.985168,-166.625641,294.500488,0.000000
109.730003,65.143593,-166.625641,-0.002013,0.003879,0.098526,289.773163,14.761749,0.985255,-166.625641,294.500488,0.000000
110.150002,65.101875,-166.625641,-0.002009,0.003879,0.098526,289.587616,14.752295,0.985255,-166.625641,294.500488,0.000000
110.570007,65.052361,-166.803574,-0.002013,0.003879,0.098526,289.367340,14.741076,0.985255,-166.803574,294.500488,0.000000
110.990005,65.020332,-166.714600,-0.002001,0.003879,0.098526,289.224884,14.733818,0.985255,-166.714600,294.500488,0.000000
111.410004,64.987556,-166.803574,-0.001996,0.003879,0.098526,289.079102,14.726391,0.985255,-166.803574,294.500488,0.000000
111.830002,64.957405,-166.759079,-0.001996,0.003879,0.098526,288.944977,14.719558,0.985255,-166.759079,294.500488,0.000000
112.250008,65.354347,-166.848053,-0.002009,0.003886,0.098699,290.710663,14.809507,0.986990,-166.848053,294.500488,0.000000
112.670006,65.384132,-166.892532,-0.002005,0.003886,0.098699,290.843140,14.816257,0.986990,-166.892532,294.500488,0.000000
113.090004,65.380409,-166.848053,-0.001983,0.003886,0.098699,290.826599,14.815413,0.986990,-166.848053,294.500488,0.000000
113.510002,65.367760,-166.848053,-0.001988,0.003886,0.098699,290.770325,14.812547,0.986990,-166.848053,294.500488,0.000000
113.930008,65.348396,-166.848053,-0.001996,0.003886,0.098699,290.684174,14.808158,0.986990,-166.848053,294.500488,0.000000
114.350006,65.328651,-166.937012,-0.001996,0.003886,0.098699,290.596344,14.803684,0.986990,-166.937012,294.500488,0.000000
114.770004,65.288063,-166.981491,-0.001996,0.003886,0.098699,290.415802,14.794487,0.986990,-166.981491,294.500488,0.000000
115.190002,65.270195,-166.937012,-0.002005,0.003886,0.098699,290.336334,14.790438,0.986990,-166.937012,294.500488,0.000000
115.610008,65.249336,-166.937012,-0.001996,0.003886,0.098699,290.243530,14.785711,0.986990,-166.937012,294.500488,0.000000
116.030006,65.210243,-166.981491,-0.002005,0.003886,0.098699,290.069641,14.776852,0.986990,-166.981491,294.500488,0.000000
116.450005,65.172997,-167.070450,-0.001992,0.003886,0.098699,289.903961,14.768412,0.986990,-167.070450,294.500488,0.000000
116.870003,65.138741,-167.025970,-0.002005,0.003886,0.098699,289.751587,14.760650,0.986990,-167.025970,294.500488,0.000000
117.290009,65.100014,-167.025970,-0.001996,0.003886,0.098699,289.579315,14.751874,0.986990,-167.025970,294.500488,0.000000
117.710007,65.076180,-166.981491,-0.001996,0.003886,0.098699,289.473297,14.746473,0.986990,-166.981491,294.500488,0.000000
118.130005,65.053474,-167.114929,-0.002009,0.003886,0.098708,289.372314,14.741328,0.987076,-167.114929,294.500488,0.000000
118.550003,65.023308,-167.114929,-0.002001,0.003886,0.098708,289.238129,14.734492,0.987076,-167.114929,294.500488,0.000000
118.970009,65.002831,-167.114929,-0.001996,0.003886,0.098708,289.147034,14.729852,0.987076,-167.114929,294.500488,0.000000
119.390007,64.978996,-167.114929,-0.002001,0.003886,0.098708,289.041016,14.724450,0.987076,-167.114929,294.500488,0.000000
119.810005,64.934685,-167.159409,-0.001996,0.003886,0.098708,288.843903,14.714410,0.987076,-167.159409,294.500488,0.000000
120.230003,64.904900,-167.159409,-0.001983,0.003886,0.098708,288.711426,14.707661,0.987076,-167.159409,294.500488,0.000000
120.650009,64.878456,-167.203888,-0.001992,0.003886,0.098708,288.593781,14.701669,0.987076,-167.203888,294.500488,0.000000
121.070007,64.829674,-167.203888,-0.001992,0.003886,0.098716,288.376801,14.690615,0.987163,-167.203888,294.500488,0.000000
121.490005,64.811058,-167.203888,-0.001992,0.003890,0.098794,288.293976,14.686396,0.987944,-167.203888,294.500488,0.000000
121.910004,65.469780,-167.203888,-0.001996,0.003895,0.098933,291.224121,14.835664,0.989331,-167.203888,294.500488,0.000000
122.330009,65.489891,-167.337341,-0.001992,0.003895,0.098933,291.313599,14.840221,0.989331,-167.337341,294.500488,0.000000
122.750008,65.493996,-167.381821,-0.001970,0.003895,0.098933,291.331848,14.841151,0.989331,-167.381821,294.500488,0.000000
123.170006,65.494728,-167.337341,-0.001975,0.003895,0.098933,291.335114,14.841318,0.989331,-167.337341,294.500488,0.000000
123.590004,65.488029,-167.337341,-0.001988,0.003895,0.098933,291.305298,14.839800,0.989331,-167.337341,294.500488,0.000000
124.010002,65.455635,-167.381821,-0.001992,0.003895,0.098933,291.161194,14.832459,0.989331,-167.381821,294.500488,0.000000
124.430008,65.430687,-167.337341,-0.001983,0.003895,0.098933,291.050232,14.826806,0.989331,-167.337341,294.500488,0.000000
124.850006,65.402763,-167.426300,-0.001983,0.003895,0.098933,290.926025,14.820478,0.989331,-167.426300,294.500488,0.000000
125.270004,65.385262,-167.470779,-0.001983,0.003895,0.098933,290.848175,14.816512,0.989331,-167.470779,294.500488,0.000000
125.690002,65.344292,-167.426300,-0.001966,0.003895,0.098933,290.665924,14.807228,0.989331,-167.426300,294.500488,0.000000
126.110008,65.315254,-167.381821,-0.001970,0.003895,0.098933,290.536774,14.800649,0.989331,-167.381821,294.500488,0.000000
126.530006,65.296638,-167.470779,-0.001996,0.003895,0.098933,290.453949,14.796430,0.989331,-167.470779,294.500488,0.000000
126.950005,65.279137,-167.515259,-0.001983,0.003895,0.098933,290.376099,14.792464,0.989331,-167.515259,294.500488,0.000000
127.370003,65.257164,-167.515259,-0.001970,0.003895,0.098933,290.278351,14.787484,0.989331,-167.515259,294.500488,0.000000
127.790009,65.230354,-167.470779,-0.001979,0.003895,0.098933,290.159119,14.781409,0.989331,-167.470779,294.500488,0.000000
128.210007,65.202797,-167.559738,-0.001962,0.003895,0.098933,290.036530,14.775166,0.989331,-167.559738,294.500488,0.000000
128.630005,65.181938,-167.604218,-0.001983,0.003895,0.098933,289.943756,14.770438,0.989331,-167.604218,294.500488,0.000000
129.050003,65.139488,-167.693192,-0.001988,0.003895,0.098933,289.754913,14.760818,0.989331,-167.693192,294.500488,0.000000
129.470001,65.116768,-167.604218,-0.001979,0.003895,0.098933,289.653839,14.755671,0.989331,-167.604218,294.500488,0.000000
129.889999,65.098152,-167.559738,-0.001966,0.003892,0.098855,289.571045,14.751452,0.988551,-167.559738,0.098907,0.000000
130.310013,65.019218,-167.648712,-0.001970,0.003877,0.098465,289.219940,14.733565,0.984648,-167.648712,0.098205,0.000000
130.730011,64.935799,-167.693192,-0.001970,0.003859,0.098014,288.848846,14.714663,0.980139,-167.693192,0.097511,0.000000
131.150009,64.919411,-167.693192,-0.001975,0.003827,0.097216,288.775970,14.710948,0.972160,-167.693192,0.096808,0.000000
131.570007,64.839363,-167.782150,-0.001970,0.003803,0.096592,288.419891,14.692809,0.965916,-167.782150,0.096106,0.000000
131.990005,64.809563,-167.693192,-0.001966,0.003777,0.095941,288.287323,14.686057,0.959412,-167.693192,0.095403,0.000000
132.410004,64.754463,-167.737671,-0.001979,0.003749,0.095213,288.042236,14.673572,0.952127,-167.737671,0.094710,0.000000
132.830002,64.724297,-167.871109,-0.001992,0.003723,0.094571,287.908051,14.666736,0.945710,-167.871109,0.094007,0.000000
133.250000,64.593224,-167.826630,-0.001979,0.003695,0.093860,287.325012,14.637033,0.938598,-167.826630,0.093305,0.000000
133.670013,64.504967,-167.826630,-0.001966,0.003675,0.093348,286.932434,14.617035,0.933482,-167.826630,0.092602,0.000000
134.090012,63.895393,-167.826630,-0.001979,0.003648,0.092654,284.220917,14.478903,0.926544,-167.826630,0.091909,0.000000
134.510010,62.903023,-167.871109,-0.001957,0.003620,0.091952,279.806610,14.254029,0.919519,-167.871109,0.091206,0.000000
134.930008,61.878250,-167.915588,-0.001975,0.003597,0.091371,275.248199,14.021812,0.913709,-167.915588,0.090504,0.000000
135.350006,60.297157,-167.871109,-0.001975,0.003570,0.090686,268.215149,13.663531,0.906858,-167.871109,0.089810,0.000000
135.770004,58.471046,-167.871109,-0.001970,0.003547,0.090087,260.092194,13.249728,0.900874,-167.871109,0.089107,0.000000
136.190002,56.332878,-167.960068,-0.001962,0.003518,0.089368,250.581161,12.765213,0.893676,-167.960068,0.088405,0.000000
136.610001,54.330261,-167.915588,-0.001962,0.003497,0.088813,241.673065,12.311413,0.888126,-167.915588,0.087703,0.000000
137.030014,52.029747,-167.960068,-0.001975,0.003472,0.088180,231.439880,11.790109,0.881795,-167.960068,0.087009,0.000000
137.450012,48.758080,-167.960068,-0.001970,0.003437,0.087312,216.886765,11.048738,0.873123,-167.960068,0.086306,0.000000
137.870010,46.364098,-168.004547,-0.001979,0.003416,0.086766,206.237808,10.506254,0.867659,-168.004547,0.085604,0.000000
138.290009,43.201912,-168.004547,-0.001992,0.003383,0.085933,192.171707,9.789693,0.859334,-168.004547,0.084910,0.000000
138.710007,40.399811,-168.049026,-0.001996,0.003358,0.085300,179.707336,9.154728,0.853003,-168.049026,0.084208,0.000000
139.130005,37.581696,-168.138000,-0.001988,0.003328,0.084520,167.171738,8.516133,0.845198,-168.138000,0.083505,0.000000
139.550003,34.819061,-168.049026,-0.001996,0.003303,0.083887,154.882919,7.890112,0.838867,-168.049026,0.082803,0.000000
139.970001,32.210220,-168.049026,-0.001992,0.003279,0.083288,143.278214,7.298940,0.832884,-168.049026,0.082109,0.000000
140.389999,28.663376,-168.138000,-0.002013,0.003247,0.082473,127.501060,6.495214,0.824732,-168.138000,0.081406,0.000000
140.810013,26.385941,-168.138000,-0.002001,0.003225,0.081927,117.370529,5.979140,0.819268,-168.138000,0.080704,0.000000
141.230011,22.882294,-168.182480,-0.002018,0.003194,0.081120,101.785522,5.185202,0.811203,-168.182480,0.080002,0.000000
141.650009,19.717125,-168.271439,-0.002013,0.003165,0.080400,87.706154,4.467964,0.804005,-168.271439,0.079308,0.000000
142.070007,15.957649,-168.182480,-0.002022,0.003130,0.079499,70.983170,3.616055,0.794986,-168.182480,0.078605,0.000000
142.490005,13.651550,-168.226959,-0.002022,0.003109,0.078961,60.725128,3.093486,0.789609,-168.226959,0.077903,0.000000
142.910004,10.615227,-168.226959,-0.002035,0.003079,0.078198,47.218887,2.405445,0.781977,-168.226959,0.077209,0.000000
143.330002,7.622841,-168.271439,-0.002035,0.003050,0.077478,33.908089,1.727360,0.774779,-168.271439,0.076507,0.000000
143.750000,4.962234,-168.271439,-0.002039,0.003026,0.076871,22.073122,1.124458,0.768709,-168.271439,0.075804,0.000000
144.170013,1.897614,-168.226959,-0.002035,0.002996,0.076108,8.441007,0.430005,0.761077,-168.226959,0.075102,0.000000
144.590012,-0.253212,-168.226959,-0.002048,0.002972,0.075492,-1.126343,-0.057379,0.754920,-168.226959,0.074408,0.000000
145.010010,-2.760765,-168.404877,-0.002065,0.002939,0.074642,-12.280497,-0.625598,0.746421,-168.404877,0.073706,0.000000
145.430008,-0.170174,-168.404877,-0.002095,0.002914,0.074018,-0.756970,-0.038562,0.740177,-168.404877,0.073003,0.000000
145.850006,-0.030907,-168.360397,-0.002095,0.002888,0.073350,-0.137480,-0.007004,0.733500,-168.360397,0.072309,0.000000
146.270004,-0.065536,-168.360397,-0.002121,0.002860,0.072639,-0.291521,-0.014851,0.726388,-168.360397,0.071607,0.000000
146.690002,-0.021591,-168.404877,-0.002134,0.002834,0.071980,-0.096042,-0.004893,0.719797,-168.404877,0.070904,0.000000
147.110001,-0.019363,-168.538330,-0.002160,0.002802,0.071173,-0.086133,-0.004388,0.711732,-168.538330,0.070202,0.000000
147.530014,0.000748,-168.493835,-0.002160,0.002780,0.070601,0.003326,0.000169,0.706008,-168.493835,0.069508,0.000000
147.950012,-0.067398,-168.538330,-0.002173,0.002748,0.069794,-0.299802,-0.015273,0.697943,-168.538330,0.068806,0.000000
148.370010,-0.045799,-168.493835,-0.002182,0.002722,0.069135,-0.203725,-0.010378,0.691352,-168.493835,0.068103,0.000000
148.790009,-0.048409,-168.493835,-0.002203,0.002694,0.068424,-0.215332,-0.010970,0.684241,-168.493835,0.067401,0.000000
149.210007,-0.023827,-168.582809,-0.002216,0.002666,0.067722,-0.105986,-0.005399,0.677217,-168.582809,0.066707,0.000000
149.630005,-0.049149,-168.582809,-0.002216,0.002638,0.067002,-0.218624,-0.011137,0.670019,-168.582809,0.066005,0.000000
150.050003,-0.029785,-168.582809,-0.002233,0.002608,0.066239,-0.132491,-0.006749,0.662387,-168.582809,0.065302,0.000000
150.470001,-0.064415,-168.538330,-0.002242,0.002584,0.065623,-0.286532,-0.014597,0.656230,-168.538330,0.064608,0.000000
150.890015,-0.069260,-168.582809,-0.002259,0.002556,0.064921,-0.308082,-0.015694,0.649205,-168.582809,0.063906,0.000000
151.310013,-0.067024,-168.671768,-0.002272,0.002531,0.064287,-0.298139,-0.015188,0.642874,-168.671768,0.063203,0.000000
151.730011,-0.039841,-168.671768,-0.002285,0.002499,0.063464,-0.177220,-0.009028,0.634636,-168.671768,0.062501,0.000000
152.150009,-0.041702,-168.671768,-0.002289,0.002475,0.062865,-0.185501,-0.009450,0.628652,-168.671768,0.061807,0.000000
152.570007,-0.042450,-168.671768,-0.002289,0.002446,0.062128,-0.188827,-0.009619,0.621280,-168.671768,0.061105,0.000000
152.990005,-0.044685,-168.671768,-0.002333,0.002417,0.061400,-0.198770,-0.010126,0.613996,-168.671768,0.060402,0.000000
153.410004,-0.059204,-168.805206,-0.002341,0.002391,0.060740,-0.263353,-0.013416,0.607405,-168.805206,0.059700,0.000000
153.830002,-0.053993,-168.760727,-0.002358,0.002358,0.059891,-0.240174,-0.012235,0.598906,-168.760727,0.059006,0.000000
154.250000,-0.085640,-168.805206,-0.002376,0.002336,0.059327,-0.380946,-0.019406,0.593269,-168.805206,0.058304,0.000000
154.670013,-0.072235,-168.805206,-0.002384,0.002308,0.058633,-0.321318,-0.016369,0.586331,-168.805206,0.057601,0.000000
155.090012,-0.075958,-168.849686,-0.002397,0.002282,0.057974,-0.337879,-0.017212,0.579740,-168.849686,0.056907,0.000000
155.510010,-0.088249,-168.894165,-0.002436,0.002253,0.057228,-0.392552,-0.019998,0.572282,-168.894165,0.056205,0.000000
155.930008,-0.106499,-168.938660,-0.002445,0.002224,0.056500,-0.473730,-0.024133,0.564998,-168.938660,0.055502,0.000000
156.350006,-0.083412,-168.938660,-0.002466,0.002198,0.055823,-0.371036,-0.018901,0.558233,-168.938660,0.054800,0.000000
156.770004,-0.084526,-168.938660,-0.002496,0.002171,0.055138,-0.375991,-0.019154,0.551382,-168.938660,0.054106,0.000000
157.190002,-0.094208,-168.938660,-0.002522,0.002144,0.054462,-0.419057,-0.021348,0.544618,-168.938660,0.053404,0.000000
157.610001,-0.118408,-169.027618,-0.002548,0.002114,0.053690,-0.526706,-0.026832,0.536899,-169.027618,0.052701,0.000000
158.030014,-0.086761,-169.027618,-0.002552,0.002093,0.053170,-0.385934,-0.019660,0.531696,-169.027618,0.052008,0.000000
158.450012,-0.070000,-169.027618,-0.002570,0.002068,0.052528,-0.311374,-0.015862,0.525279,-169.027618,0.051305,0.000000
158.870010,-0.086761,-168.938660,-0.002600,0.002031,0.051600,-0.385934,-0.019660,0.515999,-168.938660,0.050603,0.000000
159.290009,-0.092346,-169.027618,-0.002626,0.002005,0.050923,-0.410776,-0.020926,0.509235,-169.027618,0.049900,0.000000
159.710007,-0.101280,-169.072098,-0.002656,0.001976,0.050186,-0.450517,-0.022950,0.501864,-169.072098,0.049206,0.000000
160.130005,-0.080055,-169.072098,-0.002669,0.001951,0.049562,-0.356103,-0.018141,0.495619,-169.072098,0.048504,0.000000
160.550003,-0.081177,-169.072098,-0.002708,0.001923,0.048833,-0.361092,-0.018395,0.488335,-169.072098,0.047801,0.000000
160.970001,-0.068886,-169.072098,-0.002712,0.001899,0.048226,-0.306419,-0.015610,0.482264,-169.072098,0.047099,0.000000
161.390015,-0.067772,-169.161057,-0.002746,0.001866,0.047385,-0.301465,-0.015357,0.473852,-169.161057,0.046405,0.000000
161.810013,-0.064415,-169.161057,-0.002777,0.001840,0.046743,-0.286532,-0.014597,0.467435,-169.161057,0.045703,0.000000
162.230011,-0.053246,-169.205536,-0.002802,0.001819,0.046206,-0.236848,-0.012066,0.462058,-169.205536,0.045000,0.000000
162.650009,-0.076332,-169.205536,-0.002815,0.001783,0.045278,-0.339542,-0.017297,0.452779,-169.205536,0.044307,0.000000
163.070007,-0.097557,-169.161057,-0.002846,0.001758,0.044653,-0.433956,-0.022107,0.446535,-169.161057,0.043604,0.000000
163.490005,-0.054367,-169.205536,-0.002893,0.001724,0.043778,-0.241837,-0.012320,0.437776,-169.205536,0.042902,0.000000
163.910004,-0.062927,-169.338974,-0.002902,0.001704,0.043292,-0.279914,-0.014260,0.432919,-169.338974,0.042199,0.000000
164.330002,-0.056969,-169.338974,-0.002923,0.001677,0.042598,-0.253409,-0.012909,0.425981,-169.338974,0.041505,0.000000
164.750015,-0.074844,-169.294495,-0.002962,0.001645,0.041792,-0.332924,-0.016960,0.417916,-169.294495,0.040803,0.000000
165.170013,-0.057716,-169.338974,-0.002997,0.001620,0.041150,-0.256735,-0.013079,0.411499,-169.338974,0.040101,0.000000
165.590012,-0.069633,-169.338974,-0.003009,0.001592,0.040430,-0.309745,-0.015779,0.404301,-169.338974,0.039407,0.000000
166.010010,-0.020851,-169.427948,-0.003044,0.001562,0.039684,-0.092750,-0.004725,0.396842,-169.427948,0.038704,0.000000
166.430008,-0.018990,-169.472427,-0.003078,0.001533,0.038947,-0.084470,-0.004303,0.389471,-169.472427,0.038002,0.000000
166.850006,-0.010048,-169.383469,-0.003087,0.001511,0.038383,-0.044695,-0.002277,0.383834,-169.383469,0.037299,0.000000
167.270004,-0.050636,-169.427948,-0.003139,0.001479,0.037568,-0.225241,-0.011474,0.375682,-169.427948,0.036606,0.000000
167.690002,-0.009682,-169.427948,-0.003134,0.001454,0.036926,-0.043066,-0.002194,0.369265,-169.427948,0.035903,0.000000
168.110001,-0.008186,-169.472427,-0.003191,0.001426,0.036233,-0.036415,-0.001855,0.362327,-169.472427,0.035201,0.000000
168.530014,-0.004097,-169.561386,-0.003221,0.001400,0.035556,-0.018224,-0.000928,0.355563,-169.561386,0.034498,0.000000
168.950012,-0.033142,-169.472427,-0.003225,0.001369,0.034776,-0.147423,-0.007510,0.347758,-169.472427,0.033804,0.000000
169.370010,-0.059578,-169.561386,-0.003251,0.001342,0.034091,-0.265016,-0.013501,0.340906,-169.561386,0.033102,0.000000
169.790009,-0.039093,-169.605865,-0.003290,0.001322,0.033579,-0.173894,-0.008859,0.335790,-169.605865,0.032400,0.000000
170.210007,-0.039467,-169.561386,-0.003333,0.001288,0.032703,-0.175557,-0.008943,0.327031,-169.561386,0.031706,0.000000
170.630005,-0.036118,-169.605865,-0.003341,0.001264,0.032105,-0.160659,-0.008184,0.321047,-169.605865,0.031003,0.000000
171.050003,-0.062187,-169.605865,-0.003363,0.001232,0.031298,-0.276622,-0.014092,0.312982,-169.605865,0.030301,0.000000
171.470001,-0.046913,-169.650345,-0.003397,0.001205,0.030613,-0.208680,-0.010631,0.306131,-169.650345,0.029598,0.000000
171.800003,-0.029785,-169.650345,-0.003428,0.001188,0.030171,-0.132491,-0.006749,0.301708,-169.650345,0.030093,0.000000