File: Data/compression 34/AutoNoHeating-15-34-reverse-1-4_11152024_202253.csv
Time (sec),S:Load (lbs),S:HL1 (DIM),S:LVDT (in),S:Position (in),Ch:Position (mm),Ch:Load (N),Ch:Stress (MPa),Ch:Strain (mm/mm),Ch:HL1 (DIM),Set Point (),Cycles ()
0.110000,-0.071121,-116.451126,-0.012077,-0.006721,-0.170713,-0.316363,-0.016116,-1.707134,-116.451126,-0.170497,0.000000
0.510000,-0.052132,-116.495613,-0.012042,-0.006651,-0.168936,-0.231893,-0.011813,-1.689356,-116.495613,-0.168294,0.000000
0.910000,-0.065910,-116.451126,-0.011904,-0.006411,-0.162848,-0.293184,-0.014935,-1.628476,-116.451126,-0.161616,0.000000
1.310000,-0.035004,-116.584572,-0.011641,-0.006151,-0.156231,-0.155704,-0.007932,-1.562307,-116.584572,-0.154956,0.000000
1.710000,-0.012657,-116.584572,-0.011387,-0.005893,-0.149683,-0.056302,-0.002868,-1.496832,-116.584572,-0.148296,0.000000
2.110000,-0.067024,-116.584572,-0.011106,-0.005625,-0.142884,-0.298139,-0.015188,-1.428841,-116.584572,-0.141635,0.000000
2.510000,-0.096069,-116.540092,-0.010839,-0.005366,-0.136293,-0.427338,-0.021770,-1.362932,-116.540092,-0.134975,0.000000
2.910000,-0.132187,-116.584572,-0.010563,-0.005105,-0.129668,-0.587997,-0.029954,-1.296676,-116.584572,-0.128297,0.000000
3.310000,-0.037605,-116.629051,-0.010296,-0.004847,-0.123103,-0.167277,-0.008521,-1.231027,-116.629051,-0.121637,0.000000
3.710000,-0.015640,-116.718018,-0.010042,-0.004573,-0.116148,-0.069571,-0.003544,-1.161475,-116.718018,-0.114977,0.000000
4.110000,-0.025688,-116.629051,-0.009770,-0.004318,-0.109669,-0.114267,-0.005821,-1.096694,-116.629051,-0.108316,0.000000
4.510000,-0.025688,-116.629051,-0.009498,-0.004059,-0.103104,-0.114267,-0.005821,-1.031045,-116.629051,-0.101639,0.000000
4.910000,-0.030159,-116.718018,-0.009222,-0.003788,-0.096227,-0.134154,-0.006834,-0.962274,-116.718018,-0.094979,0.000000
5.310000,-0.002235,-116.762497,-0.008942,-0.003526,-0.089550,-0.009944,-0.000507,-0.895497,-116.762497,-0.088318,0.000000
5.710000,-0.000000,-116.762497,-0.008679,-0.003264,-0.082907,-0.000000,-0.000000,-0.829068,-116.762497,-0.081658,0.000000
6.110000,-0.011543,-116.806976,-0.008412,-0.003004,-0.076290,-0.051347,-0.002616,-0.762898,-116.806976,-0.074998,0.000000
6.510000,-0.032768,-116.806976,-0.008136,-0.002745,-0.069725,-0.145760,-0.007425,-0.697250,-116.806976,-0.068320,0.000000
6.910000,-0.043564,-116.806976,-0.007869,-0.002477,-0.062926,-0.193782,-0.009872,-0.629259,-116.806976,-0.061660,0.000000
7.310000,-0.060692,-116.895943,-0.007588,-0.002216,-0.056283,-0.269971,-0.013753,-0.562829,-116.895943,-0.054999,0.000000
7.710001,-0.012657,-116.895943,-0.007321,-0.001955,-0.049657,-0.056302,-0.002868,-0.496573,-116.895943,-0.048339,0.000000
8.110001,-0.001488,-116.851456,-0.007054,-0.001697,-0.043101,-0.006618,-0.000337,-0.431011,-116.851456,-0.041679,0.000000
8.510000,-0.062927,-116.940422,-0.006795,-0.001429,-0.036293,-0.279914,-0.014260,-0.362934,-116.940422,-0.035001,0.000000
8.910001,-0.077454,-116.940422,-0.006510,-0.001169,-0.029694,-0.344531,-0.017551,-0.296938,-116.940422,-0.028341,0.000000
9.310000,-0.112823,-116.984901,-0.006243,-0.000908,-0.023060,-0.501864,-0.025566,-0.230595,-116.984901,-0.021681,0.000000
9.710000,-0.019363,-117.029381,-0.005984,-0.000651,-0.016529,-0.086133,-0.004388,-0.165293,-117.029381,-0.015020,0.000000
10.110001,0.133682,-117.029381,-0.005696,0.000004,0.000104,0.594648,0.030293,0.001041,-117.029381,0.001283,0.000000
10.510000,0.119904,-117.029381,-0.005678,-0.000004,-0.000113,0.533358,0.027171,-0.001127,-117.029381,0.000078,0.000000
10.910001,0.125862,-117.029381,-0.005687,-0.000004,-0.000113,0.559863,0.028521,-0.001127,-117.029381,0.000486,0.000000
11.310000,0.133682,-117.118347,-0.005691,-0.000004,-0.000113,0.594648,0.030293,-0.001127,-117.118347,0.001153,0.000000
11.710001,0.257309,-117.118347,-0.005657,0.000032,0.000815,1.144567,0.058307,0.008152,-117.118347,0.001821,0.000000
12.110001,0.341095,-117.251785,-0.005648,0.000049,0.001249,1.517266,0.077293,0.012488,-117.251785,0.002489,0.000000
12.510000,0.522072,-117.207306,-0.005622,0.000073,0.001856,2.322292,0.118303,0.018559,-117.207306,0.003148,0.000000
12.910001,0.673248,-117.207306,-0.005596,0.000102,0.002593,2.994758,0.152560,0.025930,-117.207306,0.003816,0.000000
13.310000,1.077652,-117.207306,-0.005562,0.000135,0.003417,4.793635,0.244199,0.034169,-117.207306,0.004484,0.000000
13.710001,1.384109,-117.207306,-0.005536,0.000160,0.004076,6.156826,0.313644,0.040760,-117.207306,0.005151,0.000000
14.110001,1.707329,-117.296265,-0.005506,0.000183,0.004657,7.594578,0.386886,0.046570,-117.296265,0.005819,0.000000
14.510000,2.074120,-117.251785,-0.005493,0.000211,0.005359,9.226145,0.470002,0.053595,-117.251785,0.006487,0.000000
14.910001,2.302757,-117.340752,-0.005480,0.000229,0.005819,10.243176,0.521812,0.058191,-117.340752,0.007155,0.000000
15.310000,2.863548,-117.385231,-0.005450,0.000267,0.006782,12.737699,0.648889,0.067817,-117.385231,0.007822,0.000000
15.710001,3.196823,-117.385231,-0.005420,0.000293,0.007441,14.220180,0.724410,0.074408,-117.385231,0.008481,0.000000
16.110001,3.616112,-117.429710,-0.005389,0.000321,0.008143,16.085268,0.819423,0.081432,-117.429710,0.009149,0.000000
16.510000,3.941940,-117.385231,-0.005364,0.000345,0.008759,17.534626,0.893256,0.087590,-117.385231,0.009817,0.000000
16.910002,3.971725,-117.429710,-0.005364,0.000355,0.009010,17.667118,0.900006,0.090105,-117.429710,0.010485,0.000000
17.310001,4.677742,-117.385231,-0.005316,0.000393,0.009990,20.807636,1.059991,0.099904,-117.385231,0.011153,0.000000
17.710001,4.981598,-117.474190,-0.005307,0.000423,0.010745,22.159254,1.128846,0.107449,-117.474190,0.011820,0.000000
18.110001,5.151405,-117.429710,-0.005286,0.000438,0.011135,22.914595,1.167325,0.111352,-117.429710,0.012488,0.000000
18.510000,5.576279,-117.607635,-0.005243,0.000472,0.011994,24.804527,1.263603,0.119937,-117.607635,0.013156,0.000000
18.910002,5.861145,-117.563156,-0.005213,0.000497,0.012618,26.071674,1.328154,0.126181,-117.563156,0.013815,0.000000
19.310001,6.417839,-117.607635,-0.005200,0.000530,0.013459,28.547974,1.454303,0.134593,-117.607635,0.014483,0.000000
19.710001,6.498650,-117.696594,-0.005170,0.000552,0.014023,28.907436,1.472615,0.140230,-117.696594,0.015150,0.000000
20.110001,6.841972,-117.696594,-0.005144,0.000579,0.014717,30.434612,1.550413,0.147168,-117.696594,0.015818,0.000000
20.510000,7.070610,-117.696594,-0.005126,0.000601,0.015272,31.451645,1.602223,0.152718,-117.696594,0.016486,0.000000
20.910002,7.395691,-117.696594,-0.005113,0.000627,0.015914,32.897675,1.675887,0.159136,-117.696594,0.017154,0.000000
21.310001,7.909935,-117.741081,-0.005079,0.000659,0.016737,35.185146,1.792417,0.167375,-117.741081,0.017821,0.000000
21.710001,8.052559,-117.741081,-0.005053,0.000684,0.017379,35.819572,1.824736,0.173792,-117.741081,0.018489,0.000000
22.110001,8.272255,-117.696594,-0.005040,0.000708,0.017978,36.796829,1.874520,0.179776,-117.696594,0.019157,0.000000
22.510000,8.383972,-117.830040,-0.005023,0.000731,0.018559,37.293770,1.899835,0.185586,-117.830040,0.019816,0.000000
22.910002,8.985725,-117.830040,-0.004975,0.000765,0.019426,39.970505,2.036195,0.194259,-117.830040,0.020484,0.000000
23.310001,9.368149,-117.830040,-0.004937,0.000792,0.020128,41.671608,2.122853,0.201283,-117.830040,0.021152,0.000000
23.710001,9.428848,-117.918999,-0.004945,0.000814,0.020666,41.941612,2.136607,0.206660,-117.918999,0.021819,0.000000
24.110001,9.831383,-117.963486,-0.004911,0.000845,0.021464,43.732174,2.227823,0.214638,-117.963486,0.022487,0.000000
24.510000,10.092041,-117.918999,-0.004894,0.000867,0.022028,44.891640,2.286889,0.220275,-117.918999,0.023155,0.000000
24.910002,10.507233,-117.918999,-0.004872,0.000891,0.022643,46.738506,2.380973,0.226433,-117.918999,0.023823,0.000000
25.310001,10.829338,-117.963486,-0.004842,0.000921,0.023398,48.171303,2.453963,0.233977,-117.963486,0.024490,0.000000
25.710001,10.900833,-118.007965,-0.004829,0.000949,0.024100,48.489326,2.470164,0.241002,-118.007965,0.025150,0.000000
26.110001,11.298897,-118.007965,-0.004799,0.000974,0.024742,50.260002,2.560367,0.247420,-118.007965,0.025817,0.000000
26.510002,11.195007,-118.007965,-0.004777,0.000991,0.025167,49.797878,2.536825,0.251669,-118.007965,0.026485,0.000000
26.910002,11.777771,-118.052444,-0.004743,0.001023,0.025982,52.390141,2.668881,0.259821,-118.052444,0.027153,0.000000
27.310001,12.207863,-118.052444,-0.004725,0.001052,0.026728,54.303288,2.766341,0.267279,-118.052444,0.027821,0.000000
27.710001,12.270050,-118.185890,-0.004704,0.001073,0.027257,54.579910,2.780433,0.272569,-118.185890,0.028488,0.000000
28.110001,12.760834,-118.141403,-0.004674,0.001105,0.028055,56.763023,2.891646,0.280547,-118.141403,0.029156,0.000000
28.510002,12.486771,-118.185890,-0.004678,0.001120,0.028436,55.543930,2.829543,0.284363,-118.185890,0.029824,0.000000
28.910002,13.233749,-118.185890,-0.004639,0.001158,0.029408,58.866657,2.998810,0.294076,-118.185890,0.030483,0.000000
29.310001,13.127251,-118.230370,-0.004618,0.001182,0.030015,58.392929,2.974678,0.300147,-118.230370,0.031151,0.000000
29.710001,13.279549,-118.230370,-0.004579,0.001206,0.030630,59.070381,3.009189,0.306304,-118.230370,0.031819,0.000000
30.110001,13.562180,-118.141403,-0.004562,0.001234,0.031342,60.327587,3.073234,0.313415,-118.141403,0.032486,0.000000
30.510002,13.829918,-118.185890,-0.004540,0.001259,0.031966,61.518547,3.133904,0.319659,-118.185890,0.033154,0.000000
30.910002,14.316231,-118.319328,-0.004527,0.001289,0.032746,63.681774,3.244104,0.327464,-118.319328,0.033822,0.000000
31.310001,14.557159,-118.363808,-0.004493,0.001319,0.033510,64.753479,3.298699,0.335096,-118.363808,0.034490,0.000000
31.710001,14.735901,-118.363808,-0.004467,0.001347,0.034203,65.548561,3.339203,0.342034,-118.363808,0.035157,0.000000
32.110001,14.652489,-118.319328,-0.004445,0.001373,0.034862,65.177528,3.320302,0.348625,-118.319328,0.035816,0.000000
32.510002,14.737389,-118.408295,-0.004424,0.001397,0.035487,65.555176,3.339540,0.354869,-118.408295,0.036484,0.000000
32.910000,14.969749,-118.408295,-0.004389,0.001423,0.036137,66.588768,3.392194,0.361373,-118.408295,0.037152,0.000000
33.310001,15.020760,-118.408295,-0.004376,0.001443,0.036658,66.815674,3.403753,0.366576,-118.408295,0.037820,0.000000
33.710003,15.130241,-118.452774,-0.004363,0.001468,0.037291,67.302673,3.428562,0.372907,-118.452774,0.038487,0.000000
34.110001,15.656029,-118.452774,-0.004359,0.001496,0.037993,69.641495,3.547707,0.379932,-118.452774,0.039155,0.000000
34.510002,15.894722,-118.452774,-0.004324,0.001524,0.038704,70.703255,3.601795,0.387043,-118.452774,0.039823,0.000000
34.910000,16.130058,-118.497253,-0.004294,0.001554,0.039467,71.750084,3.655123,0.394674,-118.497253,0.040491,0.000000
35.310001,15.858231,-118.586212,-0.004277,0.001572,0.039927,70.540932,3.593526,0.399271,-118.586212,0.041159,0.000000
35.710003,16.016113,-118.586212,-0.004255,0.001598,0.040577,71.243233,3.629303,0.405775,-118.586212,0.041818,0.000000
36.110001,16.066757,-118.541733,-0.004221,0.001624,0.041245,71.468506,3.640779,0.412453,-118.541733,0.042485,0.000000
36.510002,16.597015,-118.586212,-0.004212,0.001654,0.042008,73.827209,3.760937,0.420084,-118.586212,0.043153,0.000000
36.910000,16.756020,-118.630699,-0.004186,0.001683,0.042746,74.534500,3.796968,0.427456,-118.630699,0.043821,0.000000
37.310001,16.731812,-118.675179,-0.004156,0.001708,0.043379,74.426811,3.791483,0.433786,-118.675179,0.044489,0.000000
37.710003,16.622711,-118.675179,-0.004135,0.001732,0.044003,73.941513,3.766760,0.440030,-118.675179,0.045156,0.000000
38.110001,16.392212,-118.719658,-0.004130,0.001749,0.044428,72.916199,3.714528,0.444280,-118.719658,0.045824,0.000000
38.510002,16.819695,-118.719658,-0.004105,0.001776,0.045122,74.817741,3.811397,0.451218,-118.719658,0.046492,0.000000
38.910004,17.398735,-118.675179,-0.004096,0.001812,0.046015,77.393440,3.942610,0.460150,-118.675179,0.047151,0.000000
39.310001,17.136208,-118.719658,-0.004061,0.001831,0.046501,76.225655,3.883120,0.465006,-118.719658,0.047819,0.000000
39.710003,17.705193,-118.808617,-0.004031,0.001866,0.047385,78.756630,4.012054,0.473852,-118.808617,0.048487,0.000000
40.110001,17.443420,-118.764137,-0.004018,0.001890,0.048001,77.592209,3.952735,0.480009,-118.764137,0.049154,0.000000
40.510002,17.214783,-118.808617,-0.004001,0.001905,0.048383,76.575180,3.900925,0.483825,-118.808617,0.049822,0.000000
40.910004,18.079430,-118.853104,-0.003971,0.001946,0.049423,80.421318,4.096857,0.494232,-118.853104,0.050490,0.000000
41.310001,17.876488,-118.853104,-0.003967,0.001968,0.049996,79.518585,4.050870,0.499956,-118.853104,0.051158,0.000000
41.710003,18.185181,-118.808617,-0.003945,0.002000,0.050793,80.891724,4.120821,0.507934,-118.808617,0.051825,0.000000
42.110001,18.302856,-118.853104,-0.003911,0.002021,0.051340,81.415169,4.147487,0.513398,-118.853104,0.052484,0.000000
42.510002,18.730339,-118.853104,-0.003889,0.002052,0.052112,83.316711,4.244356,0.521116,-118.853104,0.053152,0.000000
42.910004,18.598145,-118.942062,-0.003863,0.002079,0.052814,82.728676,4.214400,0.528140,-118.942062,0.053820,0.000000
43.310001,18.639107,-118.942062,-0.003859,0.002106,0.053482,82.910889,4.223682,0.534818,-118.942062,0.054488,0.000000
43.710003,18.344185,-118.986542,-0.003842,0.002128,0.054046,81.599007,4.156852,0.540455,-118.986542,0.055156,0.000000
44.110001,18.141243,-119.031029,-0.003811,0.002145,0.054479,80.696281,4.110865,0.544791,-119.031029,0.055823,0.000000
44.510002,19.052437,-119.031029,-0.003790,0.002185,0.055502,84.749474,4.317344,0.555024,-119.031029,0.056491,0.000000
44.910004,18.817848,-119.031029,-0.003773,0.002208,0.056092,83.705971,4.264185,0.560922,-119.031029,0.057159,0.000000
45.310001,18.613037,-119.031029,-0.003755,0.002230,0.056630,82.794922,4.217774,0.566298,-119.031029,0.057818,0.000000
45.710003,18.803322,-119.164467,-0.003721,0.002258,0.057350,83.641350,4.260894,0.573496,-119.164467,0.058486,0.000000
46.110001,18.544151,-119.119987,-0.003738,0.002279,0.057887,82.488503,4.202165,0.578873,-119.119987,0.059153,0.000000
46.510002,19.361511,-119.164467,-0.003691,0.002314,0.058781,86.124306,4.387381,0.587806,-119.164467,0.059821,0.000000
46.910004,19.208466,-119.119987,-0.003669,0.002337,0.059353,85.443520,4.352701,0.593529,-119.119987,0.060489,0.000000
47.310001,19.394653,-119.164467,-0.003656,0.002369,0.060168,86.271729,4.394891,0.601681,-119.164467,0.061157,0.000000
47.710003,19.023026,-119.208946,-0.003639,0.002387,0.060636,84.618645,4.310679,0.606364,-119.208946,0.061825,0.000000
48.110001,19.194313,-119.208946,-0.003622,0.002411,0.061243,85.380569,4.349494,0.612435,-119.208946,0.062492,0.000000
48.510002,19.433380,-119.208946,-0.003591,0.002439,0.061946,86.443993,4.403667,0.619459,-119.208946,0.063160,0.000000
48.910004,19.540993,-119.208946,-0.003583,0.002469,0.062709,86.922676,4.428052,0.627091,-119.208946,0.063819,0.000000
49.310001,19.244957,-119.297913,-0.003561,0.002488,0.063195,85.605843,4.360970,0.631947,-119.297913,0.064487,0.000000
49.710003,19.464287,-119.386871,-0.003535,0.002515,0.063889,86.581474,4.410670,0.638885,-119.386871,0.065155,0.000000
50.110001,20.044067,-119.342392,-0.003540,0.002548,0.064721,89.160461,4.542050,0.647211,-119.342392,0.065822,0.000000
50.510002,19.812454,-119.386871,-0.003501,0.002573,0.065354,88.130196,4.489566,0.653541,-119.386871,0.066490,0.000000
50.910004,19.784149,-119.342392,-0.003471,0.002601,0.066065,88.004288,4.483152,0.660653,-119.342392,0.067158,0.000000
51.310001,20.177750,-119.386871,-0.003454,0.002629,0.066768,89.755112,4.572343,0.667677,-119.386871,0.067826,0.000000
51.710003,19.641533,-119.431351,-0.003441,0.002645,0.067193,87.369904,4.450835,0.671926,-119.431351,0.068493,0.000000
52.110001,19.848946,-119.386871,-0.003423,0.002673,0.067904,88.292519,4.497835,0.679038,-119.386871,0.069153,0.000000
52.510002,20.384415,-119.431351,-0.003397,0.002705,0.068719,90.674408,4.619174,0.687190,-119.431351,0.069820,0.000000
52.910004,20.480118,-119.475838,-0.003393,0.002736,0.069499,91.100113,4.640861,0.694995,-119.475838,0.070488,0.000000
53.310001,20.445488,-119.520317,-0.003359,0.002764,0.070202,90.946075,4.633014,0.702019,-119.520317,0.071156,0.000000
53.710003,20.305473,-119.609276,-0.003337,0.002788,0.070809,90.323257,4.601286,0.708090,-119.609276,0.071824,0.000000
54.110004,20.338615,-119.564796,-0.003320,0.002813,0.071451,90.470680,4.608796,0.714507,-119.564796,0.072491,0.000000
54.510002,20.363937,-119.564796,-0.003298,0.002838,0.072075,90.583321,4.614534,0.720751,-119.564796,0.073159,0.000000
54.910004,19.954697,-119.609276,-0.003272,0.002854,0.072500,88.762924,4.521799,0.725001,-119.609276,0.073827,0.000000
55.310001,20.966431,-119.609276,-0.003264,0.002889,0.073376,93.263344,4.751061,0.733760,-119.609276,0.074486,0.000000
55.710003,21.073677,-119.653755,-0.003238,0.002916,0.074070,93.740395,4.775363,0.740697,-119.653755,0.075154,0.000000
56.110004,21.090431,-119.698242,-0.003216,0.002942,0.074738,93.814926,4.779160,0.747375,-119.698242,0.075822,0.000000
56.510002,21.172356,-119.653755,-0.003208,0.002966,0.075336,94.179344,4.797724,0.753359,-119.653755,0.076489,0.000000
56.910004,20.729607,-119.698242,-0.003186,0.002988,0.075900,92.209892,4.697396,0.758996,-119.698242,0.077157,0.000000
57.310001,21.446793,-119.787201,-0.003156,0.003018,0.076663,95.400101,4.859912,0.766627,-119.787201,0.077825,0.000000
57.710003,21.614365,-119.787201,-0.003147,0.003043,0.077304,96.145493,4.897885,0.773045,-119.787201,0.078493,0.000000
58.110004,22.321869,-119.742722,-0.003109,0.003079,0.078198,99.292633,5.058208,0.781977,-119.742722,0.079160,0.000000
58.510002,22.156166,-119.787201,-0.003083,0.003104,0.078848,98.555550,5.020659,0.788482,-119.787201,0.079819,0.000000
58.910004,22.114456,-119.831680,-0.003057,0.003129,0.079481,98.370010,5.011208,0.794812,-119.831680,0.080487,0.000000
59.310001,21.805763,-119.876160,-0.003053,0.003148,0.079950,96.996880,4.941257,0.799495,-119.876160,0.081155,0.000000
59.710003,21.545845,-119.876160,-0.003022,0.003165,0.080383,95.840706,4.882359,0.803832,-119.876160,0.081823,0.000000
60.110004,23.056190,-119.920647,-0.003005,0.003205,0.081415,102.559059,5.224607,0.814151,-119.920647,0.082491,0.000000
60.510002,22.538589,-119.965126,-0.002984,0.003223,0.081866,100.256653,5.107317,0.818661,-119.965126,0.083158,0.000000
60.910004,22.973518,-119.965126,-0.002966,0.003252,0.082603,102.191315,5.205873,0.826033,-119.965126,0.083826,0.000000
61.310001,23.017838,-119.920647,-0.002936,0.003281,0.083340,102.388458,5.215917,0.833404,-119.920647,0.084494,0.000000
61.710003,23.145187,-119.965126,-0.002910,0.003302,0.083869,102.954933,5.244774,0.838694,-119.965126,0.085162,0.000000
62.110004,23.968498,-120.009605,-0.002889,0.003336,0.084745,106.617203,5.431339,0.847453,-120.009605,0.085821,0.000000
62.510002,23.841522,-120.009605,-0.002880,0.003362,0.085404,106.052391,5.402566,0.854044,-120.009605,0.086488,0.000000
62.910004,23.884346,-120.054085,-0.002854,0.003384,0.085942,106.242874,5.412270,0.859421,-120.054085,0.087156,0.000000
63.310001,23.712685,-120.054085,-0.002833,0.003402,0.086419,105.479286,5.373371,0.864190,-120.054085,0.087824,0.000000
63.710003,25.164558,-120.143051,-0.002802,0.003442,0.087416,111.937546,5.702371,0.874164,-120.143051,0.088492,0.000000
64.110001,25.331009,-120.143051,-0.002781,0.003469,0.088101,112.677956,5.740088,0.881015,-120.143051,0.089159,0.000000
64.510002,25.472137,-120.187531,-0.002764,0.003492,0.088700,113.305725,5.772069,0.886998,-120.187531,0.089827,0.000000
64.910004,25.718651,-120.143051,-0.002742,0.003518,0.089359,114.402275,5.827929,0.893589,-120.143051,0.090495,0.000000
65.310005,25.850098,-120.232010,-0.002738,0.003541,0.089949,114.986977,5.857716,0.899486,-120.232010,0.091154,0.000000
65.710007,26.868164,-120.232010,-0.002682,0.003574,0.090773,119.515564,6.088413,0.907725,-120.232010,0.091822,0.000000
66.110001,26.909874,-120.232010,-0.002673,0.003598,0.091397,119.701096,6.097865,0.913969,-120.232010,0.092490,0.000000
66.510002,26.765762,-120.232010,-0.002647,0.003616,0.091839,119.060059,6.065208,0.918392,-120.232010,0.093157,0.000000
66.910004,27.685898,-120.276489,-0.002621,0.003648,0.092654,123.153023,6.273714,0.926544,-120.276489,0.093825,0.000000
67.310005,27.736534,-120.276489,-0.002621,0.003667,0.093149,123.378265,6.285188,0.931487,-120.276489,0.094493,0.000000
67.710007,29.005585,-120.320976,-0.002583,0.003700,0.093990,129.023285,6.572760,0.939899,-120.320976,0.095161,0.000000
68.110001,29.701172,-120.365456,-0.002565,0.003731,0.094762,132.117416,6.730382,0.947618,-120.365456,0.095828,0.000000
68.510002,29.991623,-120.365456,-0.002531,0.003757,0.095438,133.409409,6.796199,0.954382,-120.365456,0.096488,0.000000
68.910004,30.394157,-120.365456,-0.002522,0.003782,0.096054,135.199966,6.887414,0.960539,-120.365456,0.097155,0.000000
69.310005,30.126427,-120.320976,-0.002518,0.003796,0.096409,134.009033,6.826746,0.964095,-120.320976,0.097823,0.000000
69.710007,31.667671,-120.409935,-0.002483,0.003830,0.097277,140.864838,7.175997,0.972767,-120.409935,0.098491,0.000000
70.110001,32.228096,-120.409935,-0.002462,0.003858,0.098005,143.357727,7.302991,0.980052,-120.409935,0.099159,0.000000
70.510002,32.771011,-120.454414,-0.002440,0.003882,0.098612,145.772736,7.426017,0.986122,-120.454414,0.099826,0.000000
70.910004,33.506447,-120.409935,-0.002410,0.003909,0.099297,149.044113,7.592669,0.992973,-120.409935,0.100494,0.000000
71.310005,34.162941,-120.543381,-0.002397,0.003934,0.099922,151.964355,7.741433,0.999217,-120.543381,0.101162,0.000000
71.710007,35.534019,-120.543381,-0.002384,0.003968,0.100780,158.063217,8.052124,1.007803,-120.543381,0.101821,0.000000
72.110001,35.592850,-120.543381,-0.002354,0.003987,0.101257,158.324905,8.065455,1.012573,-120.543381,0.102489,0.000000
72.510002,36.813858,-120.587860,-0.002350,0.004019,0.102090,163.756226,8.342139,1.020898,-120.587860,0.103156,0.000000
72.910004,36.894669,-120.632339,-0.002307,0.004038,0.102558,164.115677,8.360452,1.025581,-120.632339,0.103824,0.000000
73.310005,37.145645,-120.587860,-0.002302,0.004056,0.103026,165.232086,8.417323,1.030264,-120.587860,0.104492,0.000000
73.710007,39.395523,-120.676819,-0.002289,0.004096,0.104041,175.240036,8.927154,1.040411,-120.676819,0.105160,0.000000
74.110001,39.905296,-120.676819,-0.002255,0.004118,0.104596,177.507629,9.042670,1.045961,-120.676819,0.105828,0.000000
74.510002,41.379150,-120.721298,-0.002238,0.004155,0.105533,184.063660,9.376649,1.055327,-120.721298,0.106495,0.000000
74.910004,42.206558,-120.676819,-0.002225,0.004178,0.106131,187.744141,9.564143,1.061311,-120.676819,0.107163,0.000000
75.310005,42.879066,-120.721298,-0.002195,0.004202,0.106738,190.735611,9.716535,1.067381,-120.721298,0.107822,0.000000
75.710007,43.917236,-120.676819,-0.002190,0.004228,0.107389,195.353622,9.951789,1.073886,-120.676819,0.108490,0.000000
76.110001,44.587883,-120.765785,-0.002160,0.004250,0.107961,198.336807,10.103758,1.079609,-120.765785,0.109158,0.000000
76.510002,45.491631,-120.765785,-0.002160,0.004275,0.108577,202.356873,10.308551,1.085767,-120.765785,0.109825,0.000000
76.910004,47.063042,-120.854744,-0.002134,0.004306,0.109383,209.346863,10.664639,1.093832,-120.854744,0.110493,0.000000
77.310005,48.784889,-120.810265,-0.002108,0.004334,0.110077,217.006027,11.054813,1.100770,-120.810265,0.111161,0.000000
77.710007,49.754921,-120.854744,-0.002100,0.004357,0.110658,221.320938,11.274627,1.106580,-120.854744,0.111829,0.000000
78.110001,50.878372,-120.854744,-0.002082,0.004382,0.111291,226.318298,11.529204,1.112911,-120.854744,0.112497,0.000000
78.510002,52.014847,-120.899223,-0.002052,0.004406,0.111915,231.373596,11.786733,1.119155,-120.899223,0.113156,0.000000
78.910004,52.603195,-120.988190,-0.002048,0.004425,0.112384,233.990692,11.920054,1.123838,-120.988190,0.113823,0.000000
79.310005,55.158417,-120.943703,-0.002044,0.004465,0.113398,245.356888,12.499076,1.133984,-120.943703,0.114491,0.000000
79.710007,56.508644,-121.032669,-0.002009,0.004492,0.114101,251.363007,12.805041,1.141009,-121.032669,0.115159,0.000000
80.110001,58.344063,-121.032669,-0.002001,0.004523,0.114873,259.527344,13.220954,1.148727,-121.032669,0.115827,0.000000
80.510002,58.940231,-121.032669,-0.001979,0.004540,0.115324,262.179230,13.356047,1.153237,-121.032669,0.116494,0.000000
80.910004,58.946938,-121.032669,-0.001988,0.004559,0.115801,262.209076,13.357567,1.158006,-121.032669,0.117162,0.000000
81.310005,61.836548,-121.077148,-0.001962,0.004592,0.116625,275.062714,14.012362,1.166245,-121.077148,0.117830,0.000000
81.710007,63.544624,-121.077148,-0.001940,0.004618,0.117310,282.660614,14.399418,1.173096,-121.077148,0.118489,0.000000
82.110001,65.342430,-121.121628,-0.001927,0.004648,0.118047,290.657654,14.806807,1.180468,-121.121628,0.119157,0.000000
82.510002,66.162773,-121.077148,-0.001914,0.004657,0.118298,294.306702,14.992699,1.182983,-121.077148,0.020760,0.000000
82.910004,65.001335,-121.166107,-0.001914,0.004658,0.118307,289.140381,14.729513,1.183069,-121.166107,294.500488,0.000000
83.310005,65.266472,-121.210594,-0.001884,0.004673,0.118706,290.319763,14.789594,1.187058,-121.210594,294.500488,0.000000
83.710007,65.094063,-121.166107,-0.001888,0.004681,0.118888,289.552856,14.750525,1.188880,-121.166107,294.500488,0.000000
84.110001,65.353981,-121.299553,-0.001880,0.004690,0.119131,290.709015,14.809423,1.191308,-121.299553,294.500488,0.000000
84.510002,64.968193,-121.299553,-0.001876,0.004691,0.119139,288.992950,14.722003,1.191395,-121.299553,294.500488,0.000000
84.910004,64.707909,-121.255074,-0.001867,0.004697,0.119296,287.835144,14.663021,1.192956,-121.255074,294.500488,0.000000
85.310005,65.030754,-121.299553,-0.001867,0.004701,0.119400,289.271240,14.736180,1.193996,-121.299553,294.500488,0.000000
85.710007,65.315620,-121.344032,-0.001845,0.004709,0.119616,290.538391,14.800731,1.196164,-121.344032,294.500488,0.000000
86.110001,65.127571,-121.388512,-0.001876,0.004709,0.119616,289.701904,14.758119,1.196164,-121.388512,294.500488,0.000000
86.510002,65.094063,-121.344032,-0.001841,0.004713,0.119721,289.552856,14.750525,1.197205,-121.344032,294.500488,0.000000
86.910004,65.280617,-121.344032,-0.001845,0.004720,0.119885,290.382690,14.792799,1.198853,-121.344032,294.500488,0.000000
87.310005,65.255302,-121.477478,-0.001837,0.004720,0.119885,290.270081,14.787063,1.198853,-121.477478,294.500488,0.000000
87.710007,65.226997,-121.432999,-0.001850,0.004725,0.120015,290.144165,14.780648,1.200154,-121.432999,294.500488,0.000000
88.110001,65.234444,-121.477478,-0.001850,0.004725,0.120015,290.177307,14.782336,1.200154,-121.477478,294.500488,0.000000
88.510002,65.142845,-121.432999,-0.001837,0.004727,0.120067,289.769836,14.761580,1.200674,-121.432999,294.500488,0.000000
88.910004,65.276894,-121.477478,-0.001832,0.004732,0.120180,290.366119,14.791956,1.201801,-121.477478,294.500488,0.000000
89.310005,65.238167,-121.521957,-0.001824,0.004732,0.120180,290.193848,14.783179,1.201801,-121.521957,294.500488,0.000000
89.710007,65.096291,-121.655403,-0.001837,0.004733,0.120206,289.562775,14.751030,1.202062,-121.655403,294.500488,0.000000
90.110001,65.136513,-121.566437,-0.001841,0.004735,0.120258,289.741669,14.760145,1.202582,-121.566437,294.500488,0.000000
90.510002,65.113792,-121.610924,-0.001837,0.004737,0.120319,289.640625,14.754995,1.203189,-121.610924,294.500488,0.000000
90.910004,65.017723,-121.566437,-0.001824,0.004737,0.120319,289.213287,14.733227,1.203189,-121.566437,294.500488,0.000000
91.310005,65.299232,-121.699883,-0.001841,0.004742,0.120440,290.465485,14.797018,1.204403,-121.699883,294.500488,0.000000
91.710007,65.212471,-121.655403,-0.001815,0.004742,0.120440,290.079559,14.777357,1.204403,-121.655403,294.500488,0.000000
92.110001,65.117897,-121.699883,-0.001819,0.004743,0.120466,289.658875,14.755926,1.204663,-121.699883,294.500488,0.000000
92.510002,65.084373,-121.744362,-0.001815,0.004746,0.120544,289.509766,14.748329,1.205444,-121.744362,294.500488,0.000000
92.910004,65.270195,-121.788841,-0.001824,0.004747,0.120570,290.336334,14.790438,1.205704,-121.788841,294.500488,0.000000
93.310005,65.188637,-121.788841,-0.001819,0.004747,0.120570,289.973541,14.771956,1.205704,-121.788841,294.500488,0.000000
93.710007,65.093681,-121.744362,-0.001819,0.004747,0.120579,289.551147,14.750440,1.205791,-121.744362,294.500488,0.000000
94.110008,64.996498,-121.744362,-0.001811,0.004748,0.120596,289.118866,14.728416,1.205964,-121.744362,294.500488,0.000000
94.510002,64.974907,-121.744362,-0.001819,0.004749,0.120614,289.022827,14.723524,1.206137,-121.744362,294.500488,0.000000
94.910004,65.098534,-121.877808,-0.001824,0.004751,0.120683,289.572754,14.751538,1.206831,-121.877808,294.500488,0.000000
95.310005,65.033730,-121.922287,-0.001824,0.004751,0.120683,289.284485,14.736854,1.206831,-121.922287,294.500488,0.000000
95.710007,64.966713,-121.877808,-0.001824,0.004753,0.120718,288.986359,14.721668,1.207178,-121.877808,294.500488,0.000000
96.110008,64.968941,-121.877808,-0.001811,0.004753,0.120718,288.996277,14.722173,1.207178,-121.877808,294.500488,0.000000
96.510002,64.871010,-121.922287,-0.001807,0.004753,0.120718,288.560669,14.699981,1.207178,-121.922287,294.500488,0.000000
96.910004,64.812920,-121.922287,-0.001828,0.004753,0.120718,288.302277,14.686818,1.207178,-121.922287,294.500488,0.000000
97.310005,65.766945,-122.011246,-0.001807,0.004764,0.121013,292.545990,14.903003,1.210127,-122.011246,294.500488,0.000000
97.710007,65.764702,-121.966766,-0.001815,0.004764,0.121013,292.536011,14.902494,1.210127,-121.966766,294.500488,0.000000
98.110008,65.722252,-122.011246,-0.001802,0.004764,0.121013,292.347168,14.892875,1.210127,-122.011246,294.500488,0.000000
98.510002,65.655602,-122.011246,-0.001815,0.004764,0.121013,292.050690,14.877772,1.210127,-122.011246,294.500488,0.000000
98.910004,65.592674,-122.055733,-0.001794,0.004764,0.121013,291.770782,14.863513,1.210127,-122.055733,294.500488,0.000000
99.310005,65.532722,-122.100212,-0.001807,0.004764,0.121013,291.504120,14.849927,1.210127,-122.100212,294.500488,0.000000
99.710007,65.463829,-122.100212,-0.001802,0.004764,0.121013,291.197662,14.834315,1.210127,-122.100212,294.500488,0.000000
100.110008,65.378548,-122.144691,-0.001798,0.004764,0.121013,290.818298,14.814991,1.210127,-122.144691,294.500488,0.000000
100.510002,65.310783,-122.144691,-0.001798,0.004764,0.121013,290.516876,14.799635,1.210127,-122.144691,294.500488,0.000000
100.910004,65.258278,-122.189171,-0.001798,0.004765,0.121021,290.283325,14.787737,1.210214,-122.189171,294.500488,0.000000
101.310005,65.211723,-122.189171,-0.001807,0.004765,0.121021,290.076233,14.777188,1.210214,-122.189171,294.500488,0.000000
101.710007,65.132042,-122.233650,-0.001811,0.004765,0.121030,289.721802,14.759132,1.210300,-122.233650,294.500488,0.000000
102.110008,65.067619,-122.233650,-0.001802,0.004765,0.121030,289.435211,14.744533,1.210300,-122.233650,294.500488,0.000000
102.510002,65.012505,-122.278137,-0.001802,0.004765,0.121039,289.190063,14.732044,1.210387,-122.278137,294.500488,0.000000
102.910004,64.958519,-122.322617,-0.001794,0.004765,0.121039,288.949921,14.719810,1.210387,-122.322617,294.500488,0.000000
103.310005,64.899681,-122.322617,-0.001807,0.004765,0.121039,288.688202,14.706478,1.210387,-122.322617,294.500488,0.000000
103.710007,65.136131,-122.367096,-0.001789,0.004770,0.121169,289.739990,14.760058,1.211688,-122.367096,294.500488,0.000000
104.110008,65.183800,-122.367096,-0.001807,0.004770,0.121169,289.952026,14.770861,1.211688,-122.367096,294.500488,0.000000
104.510002,65.174126,-122.411575,-0.001802,0.004770,0.121169,289.908997,14.768668,1.211688,-122.411575,294.500488,0.000000
104.910004,65.132042,-122.456055,-0.001794,0.004770,0.121169,289.721802,14.759132,1.211688,-122.456055,294.500488,0.000000
105.310005,65.081779,-122.411575,-0.001802,0.004770,0.121169,289.498199,14.747742,1.211688,-122.411575,294.500488,0.000000
105.710007,65.054588,-122.456055,-0.001802,0.004770,0.121169,289.377258,14.741581,1.211688,-122.456055,294.500488,0.000000
106.110008,65.001335,-122.500542,-0.001802,0.004770,0.121169,289.140381,14.729513,1.211688,-122.500542,294.500488,0.000000
106.510002,64.959267,-122.545021,-0.001794,0.004770,0.121169,288.953247,14.719980,1.211688,-122.545021,294.500488,0.000000
106.910004,65.187157,-122.545021,-0.001798,0.004775,0.121282,289.966949,14.771621,1.212815,-122.545021,294.500488,0.000000
107.310005,65.201302,-122.545021,-0.001794,0.004775,0.121282,290.029877,14.774826,1.212815,-122.545021,294.500488,0.000000
107.710007,65.158852,-122.589500,-0.001785,0.004775,0.121282,289.841034,14.765207,1.212815,-122.589500,294.500488,0.000000
108.110008,65.126457,-122.589500,-0.001789,0.004775,0.121282,289.696960,14.757866,1.212815,-122.589500,294.500488,0.000000
108.510002,65.091454,-122.633980,-0.001798,0.004775,0.121282,289.541260,14.749934,1.212815,-122.633980,294.500488,0.000000
108.910004,65.049370,-122.633980,-0.001794,0.004775,0.121282,289.354034,14.740397,1.212815,-122.633980,294.500488,0.000000
109.310005,65.018837,-122.722946,-0.001798,0.004775,0.121282,289.218231,14.733479,1.212815,-122.722946,294.500488,0.000000
109.710007,64.987938,-122.678467,-0.001781,0.004775,0.121290,289.080780,14.726477,1.212902,-122.678467,294.500488,0.000000
110.110008,65.215828,-122.678467,-0.001789,0.004779,0.121386,290.094482,14.778117,1.213856,-122.678467,294.500488,0.000000
110.510002,65.239281,-122.678467,-0.001794,0.004779,0.121386,290.198822,14.783432,1.213856,-122.678467,294.500488,0.000000
110.910004,65.211723,-122.722946,-0.001789,0.004779,0.121386,290.076233,14.777188,1.213856,-122.722946,294.500488,0.000000
111.310005,65.186409,-122.767426,-0.001789,0.004779,0.121386,289.963623,14.771451,1.213856,-122.767426,294.500488,0.000000
111.710007,65.151039,-122.722946,-0.001794,0.004779,0.121386,289.806305,14.763437,1.213856,-122.722946,294.500488,0.000000
112.110008,65.092201,-122.811905,-0.001794,0.004779,0.121386,289.544586,14.750103,1.213856,-122.811905,294.500488,0.000000
112.510002,65.057564,-122.856384,-0.001776,0.004779,0.121386,289.390503,14.742254,1.213856,-122.856384,294.500488,0.000000
112.910004,65.022942,-122.856384,-0.001789,0.004779,0.121386,289.236481,14.734409,1.213856,-122.856384,294.500488,0.000000
113.310005,65.002083,-122.900871,-0.001785,0.004779,0.121386,289.143707,14.729683,1.213856,-122.900871,294.500488,0.000000
113.710007,64.986076,-122.900871,-0.001798,0.004780,0.121403,289.072510,14.726055,1.214029,-122.900871,294.500488,0.000000
114.110008,64.951820,-122.945351,-0.001785,0.004780,0.121403,288.920135,14.718292,1.214029,-122.945351,294.500488,0.000000
114.510002,64.927986,-122.945351,-0.001785,0.004780,0.121403,288.814117,14.712892,1.214029,-122.945351,294.500488,0.000000
114.910004,64.959267,-122.989830,-0.001785,0.004781,0.121446,288.953247,14.719980,1.214463,-122.989830,294.500488,0.000000
115.310005,64.959633,-123.078789,-0.001789,0.004781,0.121446,288.954865,14.720063,1.214463,-123.078789,294.500488,0.000000
115.710007,64.938774,-123.034309,-0.001781,0.004781,0.121446,288.862091,14.715337,1.214463,-123.034309,294.500488,0.000000
116.110008,64.908989,-123.034309,-0.001785,0.004781,0.121446,288.729614,14.708587,1.214463,-123.034309,294.500488,0.000000
116.510002,64.884407,-123.034309,-0.001785,0.004782,0.121455,288.620270,14.703016,1.214550,-123.034309,294.500488,0.000000
116.910004,65.390846,-123.123276,-0.001785,0.004789,0.121637,290.873016,14.817778,1.216371,-123.123276,294.500488,0.000000
117.310005,65.501808,-123.034309,-0.001781,0.004788,0.121611,291.366608,14.842922,1.216111,-123.034309,294.500488,0.000000
117.710007,65.491386,-123.078789,-0.001776,0.004788,0.121611,291.320251,14.840561,1.216111,-123.078789,294.500488,0.000000
118.110008,65.438499,-123.123276,-0.001781,0.004788,0.121611,291.084991,14.828575,1.216111,-123.123276,294.500488,0.000000
118.510002,65.399773,-123.167755,-0.001781,0.004788,0.121611,290.912720,14.819800,1.216111,-123.167755,294.500488,0.000000
118.910004,65.363289,-123.167755,-0.001776,0.004788,0.121611,290.750427,14.811533,1.216111,-123.167755,294.500488,0.000000
119.310005,65.336479,-123.212234,-0.001776,0.004788,0.121611,290.631165,14.805458,1.216111,-123.212234,294.500488,0.000000
119.710007,65.318596,-123.256714,-0.001776,0.004788,0.121611,290.551636,14.801406,1.216111,-123.256714,294.500488,0.000000
120.110008,65.301476,-123.256714,-0.001789,0.004788,0.121611,290.475464,14.797526,1.216111,-123.256714,294.500488,0.000000
120.510002,65.286583,-123.301193,-0.001776,0.004788,0.121611,290.409210,14.794151,1.216111,-123.301193,294.500488,0.000000
120.910004,65.256416,-123.301193,-0.001781,0.004788,0.121611,290.275024,14.787314,1.216111,-123.301193,294.500488,0.000000
121.310005,65.237801,-123.345680,-0.001768,0.004788,0.121611,290.192230,14.783097,1.216111,-123.345680,294.500488,0.000000
121.710007,65.193108,-123.390160,-0.001776,0.004788,0.121611,289.993439,14.772969,1.216111,-123.390160,294.500488,0.000000
122.110008,65.156242,-123.345680,-0.001781,0.004788,0.121611,289.829437,14.764615,1.216111,-123.345680,294.500488,0.000000
122.510002,65.105980,-123.390160,-0.001772,0.004788,0.121611,289.605865,14.753226,1.216111,-123.390160,294.500488,0.000000
122.910004,65.089958,-123.479118,-0.001768,0.004788,0.121611,289.534607,14.749595,1.216111,-123.479118,294.500488,0.000000
123.310005,65.064278,-123.434639,-0.001772,0.004788,0.121611,289.420349,14.743775,1.216111,-123.434639,294.500488,0.000000
123.710007,65.046776,-123.479118,-0.001781,0.004788,0.121611,289.342499,14.739810,1.216111,-123.479118,294.500488,0.000000
124.110008,65.015862,-123.479118,-0.001776,0.004788,0.121611,289.204987,14.732804,1.216111,-123.479118,294.500488,0.000000
124.510002,64.997612,-123.568085,-0.001763,0.004788,0.121611,289.123810,14.728669,1.216111,-123.568085,294.500488,0.000000
124.910004,64.968193,-123.523598,-0.001776,0.004788,0.121611,288.992950,14.722003,1.216111,-123.523598,294.500488,0.000000
125.310005,64.959999,-123.523598,-0.001772,0.004788,0.121611,288.956512,14.720146,1.216111,-123.523598,294.500488,0.000000
125.710007,64.922020,-123.568085,-0.001772,0.004788,0.121611,288.787567,14.711540,1.216111,-123.568085,294.500488,0.000000
126.110008,64.880684,-123.568085,-0.001781,0.004788,0.121611,288.603699,14.702173,1.216111,-123.568085,294.500488,0.000000
126.510010,64.846428,-123.612564,-0.001759,0.004788,0.121620,288.451324,14.694410,1.216197,-123.612564,294.500488,0.000000
126.910004,65.687614,-123.657043,-0.001763,0.004799,0.121897,292.193115,14.885026,1.218972,-123.657043,294.500488,0.000000
127.310005,65.784065,-123.657043,-0.001772,0.004799,0.121897,292.622131,14.906882,1.218972,-123.657043,294.500488,0.000000
127.710007,65.801201,-123.701523,-0.001763,0.004799,0.121897,292.698364,14.910765,1.218972,-123.701523,294.500488,0.000000
128.110001,65.799706,-123.701523,-0.001763,0.004799,0.121897,292.691711,14.910426,1.218972,-123.701523,294.500488,0.000000
128.510010,65.781837,-123.746002,-0.001776,0.004799,0.121897,292.612213,14.906377,1.218972,-123.746002,294.500488,0.000000
128.910004,65.790764,-123.746002,-0.001772,0.004799,0.121897,292.651947,14.908401,1.218972,-123.746002,294.500488,0.000000
129.310013,65.786674,-123.746002,-0.001785,0.004799,0.121897,292.633759,14.907474,1.218972,-123.746002,294.500488,0.000000
129.710007,65.775871,-123.790489,-0.001768,0.004799,0.121897,292.585693,14.905025,1.218972,-123.790489,294.500488,0.000000
130.110001,65.774010,-123.834969,-0.001772,0.004799,0.121897,292.577393,14.904604,1.218972,-123.834969,294.500488,0.000000
130.510010,65.751671,-123.834969,-0.001763,0.004799,0.121897,292.478027,14.899541,1.218972,-123.834969,294.500488,0.000000
130.910004,65.725227,-123.923927,-0.001759,0.004799,0.121897,292.360413,14.893550,1.218972,-123.923927,294.500488,0.000000
131.310013,65.682411,-123.879448,-0.001768,0.004799,0.121897,292.169952,14.883847,1.218972,-123.879448,294.500488,0.000000
131.710007,65.661552,-123.879448,-0.001759,0.004799,0.121897,292.077179,14.879121,1.218972,-123.879448,294.500488,0.000000
132.110001,65.639214,-123.923927,-0.001768,0.004799,0.121897,291.977814,14.874058,1.218972,-123.923927,294.500488,0.000000
132.510010,65.602715,-123.968414,-0.001763,0.004799,0.121897,291.815460,14.865788,1.218972,-123.968414,294.500488,0.000000
132.910004,65.599739,-123.923927,-0.001768,0.004799,0.121897,291.802216,14.865113,1.218972,-123.923927,294.500488,0.000000
133.310013,65.589317,-124.012894,-0.001776,0.004799,0.121897,291.755859,14.862752,1.218972,-124.012894,294.500488,0.000000
133.710007,65.572182,-124.057373,-0.001768,0.004799,0.121897,291.679626,14.858869,1.218972,-124.057373,294.500488,0.000000
134.110001,65.541283,-124.057373,-0.001772,0.004799,0.121897,291.542175,14.851867,1.218972,-124.057373,294.500488,0.000000
134.510010,65.526009,-124.101852,-0.001768,0.004799,0.121897,291.474243,14.848406,1.218972,-124.101852,294.500488,0.000000
134.910004,65.516335,-124.101852,-0.001776,0.004799,0.121897,291.431213,14.846213,1.218972,-124.101852,294.500488,0.000000
135.310013,65.484673,-124.146332,-0.001772,0.004799,0.121897,291.290375,14.839039,1.218972,-124.146332,294.500488,0.000000
135.710007,65.462334,-124.101852,-0.001763,0.004799,0.121897,291.191010,14.833977,1.218972,-124.101852,294.500488,0.000000
136.110001,65.438133,-124.146332,-0.001763,0.004799,0.121897,291.083344,14.828493,1.218972,-124.146332,294.500488,0.000000
136.510010,65.401268,-124.235298,-0.001768,0.004799,0.121897,290.919373,14.820139,1.218972,-124.235298,294.500488,0.000000
136.910004,65.359566,-124.235298,-0.001768,0.004799,0.121897,290.733856,14.810689,1.218972,-124.235298,294.500488,0.000000
137.310013,65.337227,-124.235298,-0.001781,0.004799,0.121897,290.634491,14.805627,1.218972,-124.235298,294.500488,0.000000
137.710007,65.315620,-124.190819,-0.001759,0.004799,0.121897,290.538391,14.800731,1.218972,-124.190819,294.500488,0.000000
138.110001,65.300362,-124.279778,-0.001768,0.004799,0.121897,290.470520,14.797274,1.218972,-124.279778,294.500488,0.000000
138.510010,65.278389,-124.324257,-0.001776,0.004799,0.121897,290.372772,14.792295,1.218972,-124.324257,294.500488,0.000000
138.910004,65.268333,-124.279778,-0.001763,0.004799,0.121897,290.328033,14.790016,1.218972,-124.279778,294.500488,0.000000
139.310013,65.246727,-124.368736,-0.001759,0.004799,0.121897,290.231934,14.785120,1.218972,-124.368736,294.500488,0.000000
139.710007,65.224022,-124.368736,-0.001772,0.004799,0.121897,290.130951,14.779975,1.218972,-124.368736,294.500488,0.000000
140.110001,65.218437,-124.413223,-0.001755,0.004799,0.121897,290.106110,14.778709,1.218972,-124.413223,294.500488,0.000000
140.510010,65.189018,-124.457703,-0.001772,0.004799,0.121897,289.975250,14.772042,1.218972,-124.457703,294.500488,0.000000
140.910004,65.161461,-124.457703,-0.001772,0.004799,0.121897,289.852661,14.765799,1.218972,-124.457703,294.500488,0.000000
141.310013,65.120506,-124.457703,-0.001781,0.004799,0.121897,289.670471,14.756518,1.218972,-124.457703,294.500488,0.000000
141.710007,65.096672,-124.502182,-0.001768,0.004799,0.121897,289.564453,14.751117,1.218972,-124.502182,294.500488,0.000000
142.110001,65.086983,-124.502182,-0.001776,0.004799,0.121897,289.521362,14.748921,1.218972,-124.502182,294.500488,0.000000
142.510010,65.063530,-124.546661,-0.001763,0.004799,0.121897,289.417023,14.743607,1.218972,-124.546661,294.500488,0.000000
142.910004,65.054222,-124.546661,-0.001759,0.004799,0.121897,289.375641,14.741497,1.218972,-124.546661,1681.640991,0.000000
143.310013,65.047890,-124.546661,-0.001768,0.004792,0.121715,289.347473,14.740063,1.217151,-124.546661,0.121689,0.000000
143.710007,65.001717,-124.546661,-0.001759,0.004775,0.121282,289.142090,14.729600,1.212815,-124.546661,0.121021,0.000000
144.110001,64.932823,-124.591141,-0.001776,0.004757,0.120822,288.835632,14.713987,1.208219,-124.591141,0.120354,0.000000
144.510010,64.859840,-124.635628,-0.001763,0.004734,0.120232,288.510986,14.697450,1.202322,-124.635628,0.119686,0.000000
144.910004,64.846062,-124.635628,-0.001750,0.004706,0.119521,288.449677,14.694327,1.195210,-124.635628,0.119018,0.000000
145.310013,64.792442,-124.680107,-0.001755,0.004680,0.118871,288.211182,14.682177,1.188706,-124.680107,0.118350,0.000000
145.710007,64.789467,-124.724586,-0.001763,0.004660,0.118368,288.197937,14.681503,1.183676,-124.724586,0.117683,0.000000
146.110001,64.742546,-124.724586,-0.001742,0.004627,0.117526,287.989227,14.670871,1.175264,-124.724586,0.117015,0.000000
146.510010,64.711266,-124.680107,-0.001755,0.004605,0.116963,287.850098,14.663782,1.169627,-124.680107,0.116356,0.000000
146.910004,64.593224,-124.769066,-0.001759,0.004576,0.116243,287.325012,14.637033,1.162429,-124.769066,0.115688,0.000000
147.310013,64.209297,-124.813545,-0.001746,0.004554,0.115662,285.617218,14.550035,1.156619,-124.813545,0.115020,0.000000
147.710007,63.698036,-124.769066,-0.001755,0.004533,0.115150,283.343018,14.434181,1.151502,-124.769066,0.114352,0.000000
148.110001,62.394363,-124.813545,-0.001759,0.004503,0.114370,277.543976,14.138765,1.143697,-124.813545,0.113685,0.000000
148.510010,61.283569,-124.858032,-0.001755,0.004481,0.113823,272.602936,13.887055,1.138234,-124.858032,0.113017,0.000000
148.910004,59.701736,-124.813545,-0.001750,0.004456,0.113173,265.566589,13.528606,1.131729,-124.813545,0.112349,0.000000
149.310013,57.967972,-124.858032,-0.001755,0.004433,0.112601,257.854431,13.135730,1.126006,-124.858032,0.111681,0.000000
149.710007,56.346283,-124.902512,-0.001759,0.004414,0.112124,250.640778,12.768250,1.121236,-124.902512,0.111022,0.000000
150.110001,53.899429,-124.946991,-0.001742,0.004382,0.111300,239.756638,12.213785,1.112997,-124.946991,0.110354,0.000000
150.510010,51.391495,-125.035950,-0.001750,0.004358,0.110693,228.600784,11.645479,1.106927,-125.035950,0.109687,0.000000
150.910004,48.914848,-124.991470,-0.001763,0.004335,0.110112,217.584106,11.084263,1.101117,-124.991470,0.109019,0.000000
151.310013,46.053169,-125.035950,-0.001768,0.004307,0.109392,204.854721,10.435798,1.093918,-125.035950,0.108351,0.000000
151.710007,43.301704,-124.991470,-0.001763,0.004282,0.108767,192.615601,9.812306,1.087674,-124.991470,0.107683,0.000000
152.110001,40.450447,-125.035950,-0.001776,0.004252,0.108013,179.932571,9.166203,1.080130,-125.035950,0.107016,0.000000
152.510010,38.035614,-125.035950,-0.001768,0.004231,0.107475,169.190857,8.618993,1.074753,-125.035950,0.106348,0.000000
152.910004,35.821861,-125.080437,-0.001776,0.004211,0.106955,159.343597,8.117350,1.069549,-125.080437,0.105689,0.000000
153.310013,32.547966,-125.124916,-0.001785,0.004176,0.106070,144.780579,7.375474,1.060704,-125.124916,0.105021,0.000000
153.710007,29.619629,-125.124916,-0.001794,0.004148,0.105368,131.754684,6.711904,1.053679,-125.124916,0.104353,0.000000
154.110001,26.621658,-125.213875,-0.001819,0.004121,0.104665,118.419052,6.032554,1.046655,-125.213875,0.103686,0.000000
154.510010,24.363213,-125.213875,-0.001798,0.004098,0.104084,108.372986,5.520783,1.040844,-125.213875,0.103018,0.000000
154.910004,21.669098,-125.213875,-0.001824,0.004078,0.103590,96.388962,4.910288,1.035901,-125.213875,0.102350,0.000000
155.310013,18.624214,-125.213875,-0.001815,0.004046,0.102758,82.844643,4.220307,1.027576,-125.213875,0.101682,0.000000
155.710007,15.575974,-125.258362,-0.001815,0.004021,0.102133,69.285393,3.529566,1.021332,-125.258362,0.101014,0.000000
156.110001,12.628273,-125.302841,-0.001819,0.003992,0.101387,56.173363,2.861608,1.013874,-125.302841,0.100355,0.000000
156.510010,10.044380,-125.258362,-0.001832,0.003968,0.100798,44.679634,2.276089,1.007976,-125.258362,0.099688,0.000000
156.910004,6.685204,-125.302841,-0.001837,0.003937,0.100008,29.737270,1.514889,1.000085,-125.302841,0.099020,0.000000
157.310013,4.012688,-125.347321,-0.001841,0.003912,0.099367,17.849327,0.909288,0.993667,-125.347321,0.098352,0.000000
157.710007,0.921623,-125.436279,-0.001850,0.003880,0.098552,4.099585,0.208843,0.985515,-125.436279,0.097684,0.000000
158.110001,-1.222496,-125.436279,-0.001871,0.003855,0.097927,-5.437934,-0.277022,0.979271,-125.436279,0.097017,0.000000
158.510010,-0.290817,-125.480766,-0.001901,0.003832,0.097329,-1.293620,-0.065900,0.973287,-125.480766,0.096349,0.000000
158.910004,-0.020851,-125.436279,-0.001897,0.003806,0.096661,-0.092750,-0.004725,0.966610,-125.436279,0.095681,0.000000
159.310013,0.013039,-125.480766,-0.001932,0.003778,0.095959,0.057999,0.002955,0.959585,-125.480766,0.095013,0.000000
159.710007,0.077827,-125.480766,-0.001949,0.003754,0.095360,0.346194,0.017636,0.953601,-125.480766,0.094354,0.000000
160.110001,0.066658,-125.480766,-0.001983,0.003729,0.094710,0.296510,0.015105,0.947097,-125.480766,0.093686,0.000000
160.510010,0.116554,-125.525246,-0.001983,0.003702,0.094042,0.518459,0.026412,0.940420,-125.525246,0.093019,0.000000
160.910004,0.103149,-125.614204,-0.001996,0.003672,0.093279,0.458832,0.023374,0.932788,-125.614204,0.092351,0.000000
161.310013,0.086021,-125.614204,-0.002013,0.003650,0.092715,0.382642,0.019493,0.927151,-125.614204,0.091683,0.000000
161.710007,0.045433,-125.569725,-0.002018,0.003621,0.091969,0.202096,0.010295,0.919693,-125.569725,0.091015,0.000000
162.110001,0.030540,-125.614204,-0.002048,0.003598,0.091380,0.135851,0.006921,0.913796,-125.614204,0.090348,0.000000
162.510010,0.074104,-125.614204,-0.002048,0.003572,0.090738,0.329632,0.016792,0.907378,-125.614204,0.089680,0.000000
162.910004,0.049904,-125.703171,-0.002065,0.003542,0.089975,0.221983,0.011308,0.899747,-125.703171,0.089021,0.000000
163.310013,0.048042,-125.703171,-0.002070,0.003519,0.089394,0.213703,0.010887,0.893936,-125.703171,0.088353,0.000000
163.710007,0.007080,-125.747650,-0.002078,0.003497,0.088813,0.031494,0.001604,0.888126,-125.747650,0.087685,0.000000
164.100006,0.049156,-125.792130,-0.002091,0.003479,0.088362,0.218658,0.011139,0.883616,-125.792130,0.088206,0.000000