File: Data/compression 34/AutoNoHeating-12-34-reverse-1-3_11152024_195959.csv
Time (sec),S:Load (lbs),S:HL1 (DIM),S:LVDT (in),S:Position (in),Ch:Position (mm),Ch:Load (N),Ch:Stress (MPa),Ch:Strain (mm/mm),Ch:HL1 (DIM),Set Point (),Cycles ()
0.210000,-0.049530,-365.944794,-0.013995,-0.009039,-0.229589,-0.220321,-0.011224,-2.295893,-365.944794,-0.229373,0.000000
0.640000,-0.054367,-365.900299,-0.013995,-0.008913,-0.226381,-0.241837,-0.012320,-2.263806,-365.900299,-0.225453,0.000000
1.070000,-0.085648,-365.900299,-0.013771,-0.008645,-0.219590,-0.380979,-0.019408,-2.195902,-365.900299,-0.218289,0.000000
1.500000,-0.103523,-365.944794,-0.013482,-0.008366,-0.212488,-0.460494,-0.023459,-2.124876,-365.944794,-0.211126,0.000000
1.930000,-0.084160,-366.033752,-0.013189,-0.008079,-0.205212,-0.374362,-0.019071,-2.052116,-366.033752,-0.203963,0.000000
2.360000,-0.039101,-366.033752,-0.012887,-0.007794,-0.197962,-0.173928,-0.008860,-1.979616,-366.033752,-0.196800,0.000000
2.790000,-0.053253,-366.033752,-0.012590,-0.007514,-0.190868,-0.236882,-0.012067,-1.908677,-366.033752,-0.189636,0.000000
3.220000,-0.088997,-365.989258,-0.012309,-0.007235,-0.183756,-0.395878,-0.020167,-1.837565,-365.989258,-0.182473,0.000000
3.650000,-0.161240,-366.033752,-0.012021,-0.006954,-0.176619,-0.717230,-0.036537,-1.766192,-366.033752,-0.175310,0.000000
4.080000,-0.065910,-366.122711,-0.011736,-0.006668,-0.169369,-0.293184,-0.014935,-1.693692,-366.122711,-0.168146,0.000000
4.510000,-0.026070,-366.078217,-0.011434,-0.006386,-0.162197,-0.115964,-0.005907,-1.621972,-366.078217,-0.160983,0.000000
4.940000,-0.043198,-366.122711,-0.011154,-0.006105,-0.155077,-0.192153,-0.009789,-1.550773,-366.122711,-0.153820,0.000000
5.370000,-0.084908,-366.122711,-0.010848,-0.005824,-0.147923,-0.377688,-0.019240,-1.479227,-366.122711,-0.146657,0.000000
5.800000,-0.151932,-366.122711,-0.010572,-0.005545,-0.140846,-0.675826,-0.034428,-1.408461,-366.122711,-0.139493,0.000000
6.230000,-0.061073,-366.211670,-0.010283,-0.005257,-0.133527,-0.271668,-0.013839,-1.335267,-366.211670,-0.132330,0.000000
6.660000,-0.018623,-366.211670,-0.010003,-0.004979,-0.126468,-0.082841,-0.004220,-1.264675,-366.211670,-0.125167,0.000000
7.090000,-0.056229,-366.211670,-0.009675,-0.004697,-0.119313,-0.250117,-0.012742,-1.193129,-366.211670,-0.118003,0.000000
7.520000,-0.116554,-366.167175,-0.009403,-0.004415,-0.112132,-0.518459,-0.026412,-1.121323,-366.167175,-0.110840,0.000000
7.950000,-0.140388,-366.167175,-0.009123,-0.004134,-0.105012,-0.624479,-0.031812,-1.050124,-366.167175,-0.103677,0.000000
8.380000,-0.042450,-366.256165,-0.008834,-0.003849,-0.097754,-0.188827,-0.009619,-0.977537,-366.256165,-0.096514,0.000000
8.810000,-0.010803,-366.256165,-0.008541,-0.003571,-0.090703,-0.048055,-0.002448,-0.907031,-366.256165,-0.089350,0.000000
9.240001,-0.048042,-366.256165,-0.008257,-0.003289,-0.083540,-0.213703,-0.010887,-0.835399,-366.256165,-0.082170,0.000000
9.670000,-0.119904,-366.211670,-0.007959,-0.003005,-0.076325,-0.533358,-0.027171,-0.763245,-366.211670,-0.075006,0.000000
10.100000,-0.119537,-366.256165,-0.007675,-0.002726,-0.069231,-0.531729,-0.027088,-0.692306,-366.256165,-0.067843,0.000000
10.530001,-0.021973,-366.345123,-0.007368,-0.002440,-0.061972,-0.097739,-0.004979,-0.619720,-366.345123,-0.060680,0.000000
10.960001,-0.005592,-366.389587,-0.007084,-0.002162,-0.054913,-0.024876,-0.001267,-0.549127,-366.389587,-0.053516,0.000000
11.390000,-0.040588,-366.389587,-0.006799,-0.001879,-0.047715,-0.180546,-0.009197,-0.477148,-366.389587,-0.046353,0.000000
11.820001,-0.108734,-366.345123,-0.006497,-0.001595,-0.040508,-0.483674,-0.024640,-0.405081,-366.345123,-0.039190,0.000000
12.250001,-0.079315,-366.345123,-0.006222,-0.001314,-0.033388,-0.352812,-0.017973,-0.333882,-366.345123,-0.032027,0.000000
12.680000,-0.032402,-366.345123,-0.005907,-0.001029,-0.026138,-0.144131,-0.007342,-0.261382,-366.345123,-0.024863,0.000000
13.110001,0.004463,-366.478546,-0.005639,-0.000753,-0.019122,0.019853,0.001011,-0.191223,-366.478546,-0.017700,0.000000
13.540001,-0.087135,-366.478546,-0.005329,-0.000466,-0.011838,-0.387597,-0.019745,-0.118376,-366.478546,-0.010537,0.000000
13.970000,-0.077087,-366.389587,-0.005053,-0.000185,-0.004692,-0.342902,-0.017468,-0.046917,-366.389587,-0.003374,0.000000
14.400001,0.218582,-366.434082,-0.004777,0.000064,0.001630,0.972302,0.049531,0.016304,-366.434082,0.001821,0.000000
14.830001,0.056969,-366.434082,-0.004769,-0.000001,-0.000026,0.253409,0.012909,-0.000260,-366.434082,0.000191,0.000000
15.260001,0.087502,-366.478546,-0.004773,-0.000001,-0.000017,0.389226,0.019828,-0.000173,-366.478546,0.000798,0.000000
15.690001,0.095322,-366.478546,-0.004786,-0.000000,-0.000000,0.424012,0.021600,-0.000000,-366.478546,0.001518,0.000000
16.120001,0.300133,-366.434082,-0.004734,0.000040,0.001006,1.335057,0.068011,0.010060,-366.434082,0.002229,0.000000
16.550001,0.415192,-366.478546,-0.004700,0.000077,0.001951,1.846865,0.094084,0.019513,-366.478546,0.002949,0.000000
16.980001,0.435303,-366.567505,-0.004687,0.000097,0.002463,1.936323,0.098641,0.024629,-366.567505,0.003668,0.000000
17.410002,0.595795,-366.567505,-0.004665,0.000129,0.003278,2.650227,0.135009,0.032781,-366.567505,0.004380,0.000000
17.840000,0.831505,-366.567505,-0.004635,0.000159,0.004033,3.698718,0.188422,0.040326,-366.567505,0.005099,0.000000
18.270000,0.949921,-366.567505,-0.004596,0.000189,0.004804,4.225458,0.215255,0.048045,-366.567505,0.005819,0.000000
18.700001,1.015831,-366.567505,-0.004596,0.000209,0.005299,4.518642,0.230191,0.052988,-366.567505,0.006530,0.000000
19.130001,1.257500,-366.612000,-0.004544,0.000244,0.006201,5.593638,0.284954,0.062007,-366.612000,0.007250,0.000000
19.560001,1.352829,-366.656494,-0.004523,0.000267,0.006782,6.017684,0.306555,0.067817,-366.656494,0.007970,0.000000
19.990002,1.600822,-366.612000,-0.004501,0.000293,0.007449,7.120814,0.362752,0.074495,-366.612000,0.008681,0.000000
20.420000,1.794456,-366.612000,-0.004467,0.000321,0.008143,7.982141,0.406630,0.081433,-366.612000,0.009401,0.000000
20.850000,2.121407,-366.656494,-0.004428,0.000359,0.009123,9.436487,0.480718,0.091232,-366.656494,0.010112,0.000000
21.280001,2.401802,-366.656494,-0.004393,0.000388,0.009843,10.683749,0.544256,0.098430,-366.656494,0.010832,0.000000
21.710001,2.632668,-366.700958,-0.004389,0.000412,0.010476,11.710690,0.596571,0.104761,-366.700958,0.011551,0.000000
22.140001,2.936157,-366.789917,-0.004346,0.000445,0.011291,13.060679,0.665343,0.112913,-366.789917,0.012263,0.000000
22.570002,3.147285,-366.789917,-0.004312,0.000475,0.012063,13.999825,0.713185,0.120631,-366.789917,0.012982,0.000000
23.000002,3.356934,-366.789917,-0.004286,0.000502,0.012748,14.932386,0.760692,0.127482,-366.789917,0.013702,0.000000
23.430000,3.646271,-366.745453,-0.004251,0.000529,0.013442,16.219423,0.826257,0.134420,-366.745453,0.014413,0.000000
23.860001,3.855911,-366.789917,-0.004234,0.000550,0.013980,17.151951,0.873762,0.139797,-366.789917,0.015133,0.000000
24.290001,4.100937,-366.834412,-0.004208,0.000576,0.014630,18.241879,0.929286,0.146301,-366.834412,0.015853,0.000000
24.720001,4.480011,-366.834412,-0.004182,0.000615,0.015610,19.928083,1.015185,0.156101,-366.834412,0.016564,0.000000
25.150002,4.681465,-366.878876,-0.004152,0.000643,0.016339,20.824198,1.060835,0.163385,-366.878876,0.017284,0.000000
25.580002,4.849777,-366.834412,-0.004126,0.000663,0.016850,21.572887,1.098975,0.168502,-366.834412,0.018004,0.000000
26.010002,5.030380,-366.878876,-0.004087,0.000689,0.017492,22.376249,1.139900,0.174920,-366.878876,0.018715,0.000000
26.440001,5.257523,-366.967834,-0.004070,0.000716,0.018186,23.386629,1.191372,0.181857,-366.967834,0.019435,0.000000
26.870001,5.368492,-366.878876,-0.004057,0.000744,0.018906,23.880245,1.216518,0.189055,-366.878876,0.020146,0.000000
27.300001,5.655960,-366.923370,-0.004001,0.000771,0.019582,25.158966,1.281659,0.195820,-366.923370,0.020865,0.000000
27.730001,5.893906,-366.878876,-0.003988,0.000806,0.020484,26.217402,1.335578,0.204839,-366.878876,0.021585,0.000000
28.160002,6.126640,-366.967834,-0.003945,0.000833,0.021152,27.252657,1.388317,0.211516,-366.967834,0.022296,0.000000
28.590002,6.149353,-366.967834,-0.003932,0.000856,0.021733,27.353689,1.393463,0.217327,-366.967834,0.023016,0.000000
29.020000,6.160530,-366.967834,-0.003915,0.000877,0.022288,27.403406,1.395996,0.222877,-366.967834,0.023736,0.000000
29.450001,6.338890,-366.967834,-0.003885,0.000901,0.022886,28.196791,1.436413,0.228861,-366.967834,0.024447,0.000000
29.880001,7.008423,-367.012329,-0.003842,0.000948,0.024092,31.175022,1.588131,0.240915,-367.012329,0.025167,0.000000
30.310001,7.021828,-366.967834,-0.003820,0.000973,0.024725,31.234650,1.591169,0.247246,-366.967834,0.025887,0.000000
30.740002,7.270195,-367.012329,-0.003786,0.001004,0.025514,32.339443,1.647450,0.255138,-367.012329,0.026598,0.000000
31.170002,7.467926,-367.101288,-0.003760,0.001029,0.026138,33.218994,1.692256,0.261382,-367.101288,0.027318,0.000000
31.600002,7.661560,-366.967834,-0.003721,0.001062,0.026979,34.080322,1.736134,0.269794,-366.967834,0.028037,0.000000
32.030003,7.749809,-367.012329,-0.003686,0.001088,0.027638,34.472874,1.756132,0.276385,-367.012329,0.028749,0.000000
32.460003,7.908073,-367.101288,-0.003652,0.001118,0.028393,35.176868,1.791995,0.283930,-367.101288,0.029468,0.000000
32.890003,8.077873,-367.145782,-0.003643,0.001143,0.029043,35.932175,1.830472,0.290434,-367.145782,0.030188,0.000000
33.320000,8.303528,-367.101288,-0.003600,0.001174,0.029815,36.935936,1.881606,0.298152,-367.101288,0.030899,0.000000
33.750000,8.496422,-367.101288,-0.003587,0.001202,0.030526,37.793972,1.925317,0.305264,-367.101288,0.031619,0.000000
34.180000,8.556374,-367.056793,-0.003548,0.001228,0.031185,38.060650,1.938902,0.311855,-367.056793,0.032330,0.000000
34.610001,8.674416,-367.190247,-0.003527,0.001258,0.031949,38.585728,1.965651,0.319486,-367.190247,0.033050,0.000000
35.040001,9.003220,-367.190247,-0.003497,0.001289,0.032738,40.048321,2.040159,0.327378,-367.190247,0.033770,0.000000
35.470001,9.099663,-367.145782,-0.003462,0.001315,0.033397,40.477322,2.062013,0.333969,-367.145782,0.034481,0.000000
35.900002,9.298508,-367.145782,-0.003428,0.001344,0.034125,41.361828,2.107072,0.341253,-367.145782,0.035201,0.000000
36.330002,9.416550,-367.145782,-0.003415,0.001370,0.034793,41.886906,2.133821,0.347931,-367.145782,0.035920,0.000000
36.760002,9.613541,-367.234741,-0.003372,0.001399,0.035539,42.763165,2.178459,0.355389,-367.234741,0.036632,0.000000
37.190002,9.644447,-367.279205,-0.003346,0.001425,0.036189,42.900646,2.185463,0.361893,-367.279205,0.037351,0.000000
37.620003,10.083099,-367.190247,-0.003328,0.001459,0.037048,44.851868,2.284863,0.370479,-367.190247,0.038071,0.000000
38.050003,10.260719,-367.234741,-0.003277,0.001489,0.037828,45.641960,2.325112,0.378284,-367.234741,0.038782,0.000000
38.480003,10.004898,-367.279205,-0.003247,0.001506,0.038245,44.504009,2.267142,0.382447,-367.279205,0.039502,0.000000
38.910004,10.262207,-367.279205,-0.003242,0.001536,0.039016,45.648575,2.325449,0.390165,-367.279205,0.040222,0.000000
39.340000,10.743317,-367.279205,-0.003199,0.001566,0.039780,47.788658,2.434470,0.397796,-367.279205,0.040933,0.000000
39.770000,10.646126,-367.279205,-0.003160,0.001594,0.040482,47.356331,2.412446,0.404821,-367.279205,0.041653,0.000000
40.200001,11.033020,-367.323700,-0.003130,0.001625,0.041280,49.077324,2.500118,0.412800,-367.323700,0.042364,0.000000
40.630001,11.444122,-367.323700,-0.003096,0.001660,0.042173,50.905998,2.593275,0.421732,-367.323700,0.043084,0.000000
41.060001,11.263145,-367.323700,-0.003061,0.001681,0.042694,50.100975,2.552265,0.426935,-367.323700,0.043804,0.000000
41.490002,11.756165,-367.368164,-0.003027,0.001716,0.043587,52.294033,2.663985,0.435868,-367.368164,0.044515,0.000000
41.920002,11.710365,-367.368164,-0.003001,0.001742,0.044237,52.090305,2.653607,0.442372,-367.368164,0.045235,0.000000
42.350002,11.766594,-367.323700,-0.002971,0.001770,0.044948,52.340424,2.666348,0.449483,-367.323700,0.045954,0.000000
42.780003,11.761009,-367.368164,-0.002949,0.001792,0.045512,52.315582,2.665083,0.455120,-367.368164,0.046665,0.000000
43.210003,12.054810,-367.457123,-0.002919,0.001820,0.046240,53.622471,2.731659,0.462405,-367.457123,0.047385,0.000000
43.640003,12.231316,-367.457123,-0.002880,0.001852,0.047030,54.407608,2.771656,0.470297,-367.457123,0.048105,0.000000
44.070004,12.365738,-367.457123,-0.002833,0.001883,0.047828,55.005550,2.802116,0.478275,-367.457123,0.048816,0.000000
44.500004,12.685608,-367.457123,-0.002815,0.001912,0.048573,56.428402,2.874600,0.485733,-367.457123,0.049536,0.000000
44.930000,12.661407,-367.501617,-0.002768,0.001937,0.049198,56.320755,2.869116,0.491977,-367.501617,0.050256,0.000000
45.360001,12.526604,-367.501617,-0.002746,0.001953,0.049605,55.721115,2.838569,0.496053,-367.501617,0.050967,0.000000
45.790001,13.200226,-367.501617,-0.002729,0.001994,0.050637,58.717537,2.991214,0.506373,-367.501617,0.051687,0.000000
46.220001,13.340614,-367.501617,-0.002699,0.002020,0.051314,59.342018,3.023026,0.513138,-367.501617,0.052398,0.000000
46.650002,13.187943,-367.457123,-0.002647,0.002042,0.051877,58.662899,2.988431,0.518775,-367.457123,0.053118,0.000000
47.080002,13.720802,-367.590576,-0.002621,0.002077,0.052745,61.033176,3.109178,0.527447,-367.590576,0.053837,0.000000
47.510002,13.819855,-367.635071,-0.002596,0.002104,0.053430,61.473785,3.131624,0.534298,-367.635071,0.054548,0.000000
47.940002,13.899170,-367.590576,-0.002578,0.002125,0.053985,61.826595,3.149597,0.539848,-367.590576,0.055268,0.000000
48.370003,14.413422,-367.590576,-0.002527,0.002160,0.054852,64.114105,3.266128,0.548520,-367.590576,0.055988,0.000000
48.800003,14.669235,-367.635071,-0.002488,0.002190,0.055615,65.252014,3.324096,0.556152,-367.635071,0.056699,0.000000
49.230003,14.631256,-367.590576,-0.002458,0.002217,0.056309,65.083076,3.315490,0.563090,-367.590576,0.057419,0.000000
49.660004,14.824142,-367.635071,-0.002423,0.002247,0.057063,65.941078,3.359199,0.570635,-367.635071,0.058139,0.000000
50.090004,14.982033,-367.724030,-0.002397,0.002273,0.057723,66.643410,3.394977,0.577226,-367.724030,0.058850,0.000000
50.520004,15.018150,-367.724030,-0.002358,0.002294,0.058269,66.804070,3.403162,0.582689,-367.724030,0.059570,0.000000
50.950001,15.757683,-367.635071,-0.002341,0.002330,0.059179,70.093674,3.570742,0.591795,-367.635071,0.060290,0.000000
51.380001,15.491066,-367.679535,-0.002302,0.002353,0.059761,68.907700,3.510326,0.597605,-367.679535,0.061001,0.000000
51.810001,15.763641,-367.768494,-0.002276,0.002383,0.060532,70.120178,3.572092,0.605324,-367.768494,0.061720,0.000000
52.240002,15.647835,-367.812988,-0.002246,0.002407,0.061148,69.605049,3.545850,0.611481,-367.812988,0.062440,0.000000
52.670002,16.606316,-367.812988,-0.002195,0.002444,0.062076,73.868584,3.763045,0.620760,-367.812988,0.063151,0.000000
53.100002,16.435776,-367.724030,-0.002169,0.002467,0.062666,73.109985,3.724400,0.626657,-367.724030,0.063871,0.000000
53.530003,17.012947,-367.768494,-0.002139,0.002502,0.063542,75.677368,3.855189,0.635416,-367.768494,0.064582,0.000000
53.960003,16.899002,-367.812988,-0.002104,0.002526,0.064157,75.170517,3.829369,0.641574,-367.812988,0.065302,0.000000
54.390003,17.036781,-367.812988,-0.002082,0.002553,0.064851,75.783386,3.860590,0.648511,-367.812988,0.066022,0.000000
54.820004,17.494431,-367.768494,-0.002039,0.002582,0.065588,77.819115,3.964295,0.655883,-367.768494,0.066733,0.000000
55.250004,18.070862,-367.857452,-0.002005,0.002614,0.066403,80.383209,4.094916,0.664035,-367.857452,0.067453,0.000000
55.680004,18.134163,-367.857452,-0.001983,0.002643,0.067123,80.664787,4.109260,0.671233,-367.857452,0.068173,0.000000
56.110004,18.246246,-367.946442,-0.001957,0.002668,0.067756,81.163361,4.134659,0.677564,-367.946442,0.068884,0.000000
56.540001,18.596649,-367.946442,-0.001923,0.002697,0.068511,82.722031,4.214061,0.685108,-367.946442,0.069604,0.000000
56.970001,18.774269,-367.901947,-0.001888,0.002722,0.069135,83.512123,4.254310,0.691352,-367.901947,0.070323,0.000000
57.400002,19.032700,-367.901947,-0.001845,0.002747,0.069768,84.661674,4.312871,0.697683,-367.901947,0.071034,0.000000
57.830002,19.737602,-367.946442,-0.001824,0.002780,0.070610,87.797241,4.472605,0.706095,-367.946442,0.071754,0.000000
58.260002,19.538750,-367.990906,-0.001802,0.002800,0.071113,86.912697,4.427544,0.711125,-367.990906,0.072474,0.000000
58.690002,20.686775,-368.079865,-0.001772,0.002838,0.072084,92.019371,4.687690,0.720838,-368.079865,0.073185,0.000000
59.120003,21.038666,-367.990906,-0.001725,0.002866,0.072795,93.584656,4.767430,0.727949,-367.990906,0.073905,0.000000
59.550003,20.918022,-367.990906,-0.001694,0.002895,0.073532,93.048012,4.740091,0.735321,-367.990906,0.074616,0.000000
59.980003,20.832001,-367.990906,-0.001664,0.002914,0.074026,92.665367,4.720599,0.740264,-367.990906,0.075336,0.000000
60.410004,22.220955,-368.035400,-0.001634,0.002951,0.074963,98.843742,5.035341,0.749630,-368.035400,0.076056,0.000000
60.840004,23.144432,-368.079865,-0.001613,0.002983,0.075778,102.951576,5.244603,0.757782,-368.079865,0.076767,0.000000
61.270004,22.760147,-368.079865,-0.001574,0.003002,0.076246,101.242187,5.157523,0.762465,-368.079865,0.077487,0.000000
61.700005,22.863663,-368.079865,-0.001556,0.003024,0.076802,101.702652,5.180980,0.768015,-368.079865,0.078206,0.000000
62.130001,24.168083,-368.124359,-0.001513,0.003063,0.077799,107.505005,5.476566,0.777988,-368.124359,0.078918,0.000000
62.560001,24.625732,-368.168823,-0.001496,0.003090,0.078493,109.540726,5.580270,0.784926,-368.168823,0.079637,0.000000
62.990002,25.169395,-368.168823,-0.001475,0.003118,0.079186,111.959061,5.703466,0.791864,-368.168823,0.080357,0.000000
63.420002,25.993454,-368.168823,-0.001436,0.003153,0.080080,115.624657,5.890201,0.800796,-368.168823,0.081068,0.000000
63.850002,26.331200,-368.168823,-0.001401,0.003178,0.080713,117.127029,5.966735,0.807127,-368.168823,0.081788,0.000000
64.280006,26.732613,-368.168823,-0.001393,0.003202,0.081337,118.912598,6.057696,0.813371,-368.168823,0.082508,0.000000
64.710007,28.418716,-368.213318,-0.001337,0.003241,0.082317,126.412766,6.439774,0.823171,-368.213318,0.083219,0.000000
65.139999,28.767258,-368.257782,-0.001324,0.003266,0.082967,127.963150,6.518754,0.829675,-368.257782,0.083939,0.000000
65.570000,29.122131,-368.213318,-0.001302,0.003291,0.083601,129.541718,6.599169,0.836006,-368.213318,0.084650,0.000000
66.000000,30.249298,-368.213318,-0.001259,0.003323,0.084407,134.555603,6.854589,0.844071,-368.213318,0.085370,0.000000
66.430000,30.657425,-368.213318,-0.001246,0.003346,0.084997,136.371033,6.947072,0.849968,-368.213318,0.086090,0.000000
66.860001,30.887177,-368.346741,-0.001220,0.003364,0.085456,137.393021,6.999134,0.854564,-368.346741,0.086801,0.000000
67.290001,32.949745,-368.346741,-0.001212,0.003405,0.086480,146.567780,7.466519,0.864798,-368.346741,0.087520,0.000000
67.720001,34.064255,-368.302277,-0.001177,0.003437,0.087295,151.525375,7.719070,0.872950,-368.302277,0.088240,0.000000
68.150002,32.835052,-368.302277,-0.001168,0.003439,0.087356,146.057602,7.440529,0.873557,-368.302277,0.088951,0.000000
68.580002,35.291595,-368.346741,-0.001125,0.003485,0.088526,156.984863,7.997190,0.885264,-368.346741,0.089671,0.000000
69.010002,35.738075,-368.391235,-0.001104,0.003509,0.089133,158.970901,8.098364,0.891335,-368.391235,0.090391,0.000000
69.440002,37.324379,-368.391235,-0.001082,0.003539,0.089888,166.027130,8.457825,0.898879,-368.391235,0.091102,0.000000
69.870003,38.198708,-368.346741,-0.001082,0.003564,0.090521,169.916336,8.655951,0.905210,-368.346741,0.091822,0.000000
70.300003,39.927261,-368.391235,-0.001048,0.003600,0.091449,177.605331,9.047647,0.914490,-368.391235,0.092542,0.000000
70.730003,39.821510,-368.391235,-0.001013,0.003616,0.091857,177.134918,9.023684,0.918566,-368.391235,0.093253,0.000000
71.160004,41.830086,-368.480194,-0.001000,0.003653,0.092776,186.069519,9.478833,0.927758,-368.480194,0.093973,0.000000
71.590004,42.263901,-368.435730,-0.000992,0.003673,0.093296,187.999222,9.577137,0.932961,-368.435730,0.094692,0.000000
72.020004,42.826553,-368.435730,-0.000966,0.003693,0.093790,190.502029,9.704636,0.937905,-368.435730,0.095403,0.000000
72.450005,45.745209,-368.480194,-0.000927,0.003737,0.094918,203.484848,10.366013,0.949179,-368.480194,0.096123,0.000000
72.880005,47.531853,-368.480194,-0.000923,0.003771,0.095785,211.432236,10.770872,0.957851,-368.480194,0.096834,0.000000
73.310005,47.878906,-368.480194,-0.000914,0.003788,0.096227,212.976013,10.849516,0.962274,-368.480194,0.097554,0.000000
73.740005,49.594421,-368.524689,-0.000905,0.003819,0.096999,220.607010,11.238256,0.969992,-368.524689,0.098274,0.000000
74.170006,51.537094,-368.524689,-0.000871,0.003855,0.097910,229.248444,11.678473,0.979098,-368.524689,0.098985,0.000000
74.600006,53.361717,-368.569153,-0.000845,0.003884,0.098664,237.364777,12.091938,0.986643,-368.569153,0.099705,0.000000
75.030006,54.430794,-368.569153,-0.000828,0.003910,0.099315,242.120270,12.334194,0.993147,-368.569153,0.100425,0.000000
75.460007,56.100891,-368.613647,-0.000828,0.003938,0.100034,249.549225,12.712644,1.000345,-368.613647,0.101136,0.000000
75.890007,56.288567,-368.524689,-0.000802,0.003950,0.100329,250.384048,12.755172,1.003294,-368.524689,0.101856,0.000000
76.320007,59.143913,-368.569153,-0.000785,0.003990,0.101344,263.085266,13.402203,1.013440,-368.569153,0.102575,0.000000
76.750000,61.596359,-368.613647,-0.000767,0.004026,0.102263,273.994293,13.957935,1.022633,-368.613647,0.103287,0.000000
77.180000,62.962219,-368.613647,-0.000746,0.004051,0.102896,280.069946,14.267443,1.028963,-368.613647,0.104006,0.000000
77.610001,64.789833,-368.658112,-0.000742,0.004080,0.103642,288.199585,14.681586,1.036422,-368.658112,0.104726,0.000000
78.040001,66.226433,-368.702606,-0.000733,0.004094,0.103998,294.589874,15.007124,1.039977,-368.702606,0.104258,0.000000
78.470001,64.997231,-368.702606,-0.000707,0.004094,0.103980,289.122131,14.728583,1.039804,-368.702606,294.500488,0.000000
78.900002,65.682396,-368.658112,-0.000703,0.004107,0.104319,292.169891,14.883844,1.043186,-368.658112,294.500488,0.000000
79.330002,64.848289,-368.791565,-0.000690,0.004114,0.104483,288.459595,14.694832,1.044834,-368.791565,294.500488,0.000000
79.760002,64.980110,-368.791565,-0.000707,0.004121,0.104674,289.045959,14.724703,1.046742,-368.791565,294.500488,0.000000
80.190002,65.345406,-368.747070,-0.000698,0.004130,0.104900,290.670868,14.807481,1.048996,-368.747070,294.500488,0.000000
80.620003,64.943245,-368.747070,-0.000681,0.004130,0.104908,288.881989,14.716350,1.049083,-368.747070,294.500488,0.000000
81.050003,64.520973,-368.791565,-0.000673,0.004130,0.104908,287.003632,14.620662,1.049083,-368.791565,294.500488,0.000000
81.480003,67.132790,-368.836060,-0.000655,0.004105,0.104275,298.621552,15.212508,1.042752,-368.836060,294.500488,0.000000
81.910004,66.466240,-368.880524,-0.000664,0.004022,0.102159,295.656616,15.061465,1.021592,-368.880524,294.500488,0.000000
82.340004,66.082329,-368.836060,-0.000664,0.004022,0.102168,293.948883,14.974470,1.021679,-368.836060,294.500488,0.000000
82.770004,65.773628,-368.836060,-0.000660,0.004030,0.102359,292.575714,14.904517,1.023587,-368.836060,294.500488,0.000000
83.200005,65.453392,-368.880524,-0.000660,0.004108,0.104336,291.151215,14.831951,1.043359,-368.880524,294.500488,0.000000
83.630005,65.190498,-368.925018,-0.000668,0.004120,0.104657,289.981812,14.772378,1.046568,-368.925018,294.500488,0.000000
84.060005,65.157738,-368.969482,-0.000664,0.004145,0.105281,289.836090,14.764955,1.052812,-368.969482,294.500488,0.000000
84.490005,65.010643,-368.880524,-0.000655,0.004146,0.105299,289.181793,14.731623,1.052985,-368.880524,294.500488,0.000000
84.920006,65.220284,-368.880524,-0.000655,0.004151,0.105429,290.114319,14.779127,1.054286,-368.880524,294.500488,0.000000
85.350006,65.049370,-368.925018,-0.000651,0.004151,0.105429,289.354034,14.740397,1.054286,-368.925018,294.500488,0.000000
85.780006,64.890739,-369.013977,-0.000647,0.004151,0.105429,288.648437,14.704452,1.054286,-369.013977,294.500488,0.000000
86.210007,65.745705,-369.102936,-0.000647,0.004162,0.105723,292.451508,14.898190,1.057235,-369.102936,294.500488,0.000000
86.640007,65.606071,-368.925018,-0.000655,0.004162,0.105723,291.830383,14.866549,1.057235,-368.925018,294.500488,0.000000
87.070007,65.511864,-369.013977,-0.000655,0.004162,0.105723,291.411316,14.845201,1.057235,-369.013977,294.500488,0.000000
87.500008,65.341682,-369.013977,-0.000651,0.004162,0.105723,290.654327,14.806637,1.057235,-369.013977,294.500488,0.000000
87.930008,65.238167,-369.058441,-0.000642,0.004162,0.105723,290.193848,14.783179,1.057235,-369.058441,294.500488,0.000000
88.360001,65.102989,-369.058441,-0.000647,0.004162,0.105723,289.592560,14.752548,1.057235,-369.058441,294.500488,0.000000
88.790001,65.002449,-369.058441,-0.000651,0.004162,0.105723,289.145325,14.729765,1.057235,-369.058441,294.500488,0.000000
89.220001,64.875465,-369.102936,-0.000634,0.004162,0.105723,288.580475,14.700991,1.057235,-369.102936,294.500488,0.000000
89.650002,64.769341,-369.058441,-0.000638,0.004162,0.105723,288.108429,14.676943,1.057235,-369.058441,294.500488,0.000000
90.080002,64.619286,-369.147400,-0.000638,0.004163,0.105741,287.440948,14.642940,1.057408,-369.147400,294.500488,0.000000
90.510002,66.094612,-369.147400,-0.000647,0.004169,0.105897,294.003510,14.977253,1.058969,-369.147400,294.500488,0.000000
90.940002,65.859276,-369.147400,-0.000638,0.004169,0.105897,292.956696,14.923925,1.058969,-369.147400,294.500488,0.000000
91.370003,65.790764,-369.147400,-0.000629,0.004169,0.105897,292.651947,14.908401,1.058969,-369.147400,294.500488,0.000000
91.800003,65.685753,-369.147400,-0.000617,0.004169,0.105897,292.184814,14.884604,1.058969,-369.147400,294.500488,0.000000
92.230003,65.574043,-369.236389,-0.000625,0.004169,0.105897,291.687927,14.859290,1.058969,-369.236389,294.500488,0.000000
92.660004,65.493980,-369.191895,-0.000642,0.004169,0.105897,291.331787,14.841148,1.058969,-369.191895,294.500488,0.000000
93.090004,65.362907,-369.236389,-0.000621,0.004170,0.105906,290.748718,14.811446,1.059056,-369.236389,294.500488,0.000000
93.520004,65.283226,-369.191895,-0.000638,0.004170,0.105914,290.394287,14.793390,1.059143,-369.191895,294.500488,0.000000
93.950005,65.235558,-369.280853,-0.000629,0.004170,0.105914,290.182251,14.782589,1.059143,-369.280853,294.500488,0.000000
94.380005,65.115654,-369.325348,-0.000621,0.004170,0.105914,289.648895,14.755418,1.059143,-369.325348,294.500488,0.000000
94.810005,65.035957,-369.280853,-0.000625,0.004170,0.105914,289.294373,14.737358,1.059143,-369.280853,294.500488,0.000000
95.240005,64.978996,-369.280853,-0.000642,0.004170,0.105914,289.041016,14.724450,1.059143,-369.280853,294.500488,0.000000
95.670006,64.876961,-369.236389,-0.000621,0.004170,0.105914,288.587128,14.701330,1.059143,-369.236389,294.500488,0.000000
96.100006,64.790565,-369.280853,-0.000621,0.004170,0.105914,288.202820,14.681752,1.059143,-369.280853,294.500488,0.000000
96.530006,64.739555,-369.369812,-0.000612,0.004170,0.105914,287.975922,14.670193,1.059143,-369.369812,294.500488,0.000000
96.960007,65.699532,-369.414307,-0.000638,0.004186,0.106322,292.246124,14.887727,1.063219,-369.414307,294.500488,0.000000
97.390007,65.676811,-369.369812,-0.000634,0.004186,0.106322,292.145050,14.882579,1.063219,-369.369812,294.500488,0.000000
97.820007,65.604576,-369.369812,-0.000621,0.004186,0.106322,291.823730,14.866209,1.063219,-369.369812,294.500488,0.000000
98.250008,65.578880,-369.458771,-0.000617,0.004186,0.106322,291.709442,14.860386,1.063219,-369.458771,294.500488,0.000000
98.680008,65.567711,-369.458771,-0.000617,0.004186,0.106322,291.659760,14.857855,1.063219,-369.458771,294.500488,0.000000
99.110008,65.533089,-369.458771,-0.000617,0.004186,0.106322,291.505737,14.850011,1.063219,-369.458771,294.500488,0.000000
99.540001,65.489510,-369.458771,-0.000612,0.004186,0.106322,291.311890,14.840136,1.063219,-369.458771,294.500488,0.000000
99.970001,65.390465,-369.503265,-0.000621,0.004186,0.106322,290.871307,14.817692,1.063219,-369.503265,294.500488,0.000000
100.400002,65.322685,-369.547729,-0.000621,0.004186,0.106322,290.569824,14.802332,1.063219,-369.547729,294.500488,0.000000
100.830002,65.301460,-369.547729,-0.000621,0.004186,0.106322,290.475403,14.797522,1.063219,-369.547729,294.500488,0.000000
101.260002,65.241142,-369.547729,-0.000621,0.004186,0.106331,290.207092,14.783854,1.063305,-369.547729,294.500488,0.000000
101.690002,65.207634,-369.547729,-0.000625,0.004186,0.106331,290.058044,14.776261,1.063305,-369.547729,294.500488,0.000000
102.120003,65.140968,-369.592224,-0.000625,0.004186,0.106331,289.761505,14.761155,1.063305,-369.592224,294.500488,0.000000
102.550003,65.078423,-369.547729,-0.000604,0.004186,0.106331,289.483276,14.746982,1.063305,-369.547729,294.500488,0.000000
102.980003,65.040062,-369.592224,-0.000621,0.004186,0.106331,289.312653,14.738289,1.063305,-369.592224,294.500488,0.000000
103.410004,65.020332,-369.636688,-0.000617,0.004186,0.106331,289.224884,14.733818,1.063305,-369.636688,294.500488,0.000000
103.840004,64.981224,-369.592224,-0.000612,0.004186,0.106331,289.050934,14.724956,1.063305,-369.592224,294.500488,0.000000
104.270004,64.923515,-369.636688,-0.000608,0.004186,0.106331,288.794220,14.711879,1.063305,-369.636688,294.500488,0.000000
104.700005,64.857231,-369.636688,-0.000625,0.004186,0.106331,288.499359,14.696858,1.063305,-369.636688,294.500488,0.000000
105.130005,64.812172,-369.725677,-0.000617,0.004186,0.106331,288.298950,14.686648,1.063305,-369.725677,294.500488,0.000000
105.560005,64.779396,-369.725677,-0.000617,0.004186,0.106331,288.153137,14.679221,1.063305,-369.725677,294.500488,0.000000
105.990005,64.749611,-369.725677,-0.000617,0.004187,0.106339,288.020660,14.672471,1.063392,-369.725677,294.500488,0.000000
106.420006,64.719078,-369.725677,-0.000617,0.004187,0.106339,287.884827,14.665552,1.063392,-369.725677,294.500488,0.000000
106.850006,64.684441,-369.725677,-0.000617,0.004187,0.106339,287.730774,14.657703,1.063392,-369.725677,294.500488,0.000000
107.280006,64.638649,-369.725677,-0.000608,0.004187,0.106339,287.527069,14.647327,1.063392,-369.725677,294.500488,0.000000
107.710007,64.592476,-369.814636,-0.000608,0.004187,0.106339,287.321686,14.636864,1.063392,-369.814636,294.500488,0.000000
108.140007,64.551506,-369.725677,-0.000621,0.004187,0.106339,287.139435,14.627581,1.063392,-369.725677,294.500488,0.000000
108.570007,64.520973,-369.770142,-0.000612,0.004187,0.106339,287.003632,14.620662,1.063392,-369.770142,294.500488,0.000000
109.000008,64.494164,-369.859100,-0.000612,0.004187,0.106348,286.884369,14.614587,1.063479,-369.859100,294.500488,0.000000
109.430008,64.462883,-369.859100,-0.000617,0.004187,0.106348,286.745239,14.607498,1.063479,-369.859100,294.500488,0.000000
109.860008,65.871193,-369.814636,-0.000604,0.004203,0.106747,293.009705,14.926626,1.067468,-369.814636,294.500488,0.000000
110.290009,65.913277,-369.770142,-0.000629,0.004202,0.106738,293.196899,14.936162,1.067382,-369.770142,294.500488,0.000000
110.720009,65.973595,-369.903595,-0.000608,0.004202,0.106738,293.465210,14.949830,1.067382,-369.903595,294.500488,0.000000
111.150002,65.868217,-369.903595,-0.000608,0.004202,0.106729,292.996460,14.925951,1.067295,-369.903595,294.500488,0.000000
111.580002,65.813850,-369.903595,-0.000617,0.004202,0.106729,292.754639,14.913632,1.067295,-369.903595,294.500488,0.000000
112.010002,65.846992,-369.903595,-0.000621,0.004202,0.106729,292.902039,14.921142,1.067295,-369.903595,294.500488,0.000000
112.440002,65.837685,-369.903595,-0.000617,0.004202,0.106729,292.860657,14.919033,1.067295,-369.903595,294.500488,0.000000
112.870003,65.787041,-369.859100,-0.000612,0.004202,0.106729,292.635376,14.907557,1.067295,-369.859100,294.500488,0.000000
113.300003,65.794853,-369.992554,-0.000612,0.004202,0.106729,292.670135,14.909328,1.067295,-369.992554,294.500488,0.000000
113.730003,65.786674,-370.037018,-0.000612,0.004202,0.106729,292.633759,14.907474,1.067295,-370.037018,294.500488,0.000000
114.160004,65.761711,-369.992554,-0.000608,0.004202,0.106729,292.522705,14.901816,1.067295,-369.992554,294.500488,0.000000
114.590004,65.669746,-369.992554,-0.000595,0.004202,0.106729,292.113617,14.880977,1.067295,-369.992554,294.500488,0.000000
115.020004,65.613518,-369.992554,-0.000612,0.004202,0.106729,291.863495,14.868236,1.067295,-369.992554,294.500488,0.000000
115.450005,65.593407,-370.081512,-0.000604,0.004202,0.106729,291.774048,14.863678,1.067295,-370.081512,294.500488,0.000000
115.880005,65.590050,-370.037018,-0.000604,0.004202,0.106729,291.759125,14.862917,1.067295,-370.037018,294.500488,0.000000
116.310005,65.555794,-369.992554,-0.000604,0.004202,0.106729,291.606720,14.855155,1.067295,-369.992554,294.500488,0.000000
116.740005,65.547234,-370.037018,-0.000617,0.004202,0.106729,291.568665,14.853215,1.067295,-370.037018,294.500488,0.000000
117.170006,65.515205,-370.081512,-0.000604,0.004202,0.106729,291.426178,14.845958,1.067295,-370.081512,294.500488,0.000000
117.600006,65.496223,-370.081512,-0.000621,0.004202,0.106729,291.341766,14.841657,1.067295,-370.081512,294.500488,0.000000
118.030006,65.453026,-370.081512,-0.000617,0.004202,0.106729,291.149597,14.831867,1.067295,-370.081512,294.500488,0.000000
118.460007,65.399406,-370.037018,-0.000599,0.004202,0.106729,290.911102,14.819717,1.067295,-370.037018,294.500488,0.000000
118.890007,65.366631,-370.126007,-0.000595,0.004202,0.106729,290.765289,14.812291,1.067295,-370.126007,294.500488,0.000000
119.320007,65.341682,-370.170471,-0.000604,0.004202,0.106729,290.654327,14.806637,1.067295,-370.170471,294.500488,0.000000
119.750008,65.321571,-370.170471,-0.000604,0.004202,0.106729,290.564850,14.802079,1.067295,-370.170471,294.500488,0.000000
120.180008,65.314873,-370.170471,-0.000612,0.004202,0.106729,290.535065,14.800561,1.067295,-370.170471,294.500488,0.000000
120.610008,65.287315,-370.214966,-0.000599,0.004202,0.106729,290.412476,14.794317,1.067295,-370.214966,294.500488,0.000000
121.040009,65.268318,-370.126007,-0.000604,0.004202,0.106729,290.327972,14.790012,1.067295,-370.126007,294.500488,0.000000
121.470009,65.240776,-370.303925,-0.000595,0.004202,0.106729,290.205475,14.783772,1.067295,-370.303925,294.500488,0.000000
121.900009,65.216942,-370.259430,-0.000612,0.004202,0.106729,290.099457,14.778370,1.067295,-370.259430,294.500488,0.000000
122.330009,65.202049,-370.259430,-0.000617,0.004202,0.106729,290.033203,14.774996,1.067295,-370.259430,294.500488,0.000000
122.760002,65.167412,-370.259430,-0.000599,0.004202,0.106729,289.879120,14.767146,1.067295,-370.259430,294.500488,0.000000
123.190002,65.116402,-370.259430,-0.000599,0.004202,0.106729,289.652222,14.755588,1.067295,-370.259430,294.500488,0.000000
123.620003,65.104485,-370.348389,-0.000595,0.004202,0.106729,289.599213,14.752887,1.067295,-370.348389,294.500488,0.000000
124.050003,65.071709,-370.259430,-0.000599,0.004202,0.106729,289.453430,14.745460,1.067295,-370.259430,294.500488,0.000000
124.480003,65.057564,-370.303925,-0.000604,0.004202,0.106729,289.390503,14.742254,1.067295,-370.303925,294.500488,0.000000
124.910004,65.045647,-370.303925,-0.000591,0.004202,0.106729,289.337494,14.739554,1.067295,-370.303925,294.500488,0.000000
125.340004,65.017723,-370.348389,-0.000599,0.004202,0.106729,289.213287,14.733227,1.067295,-370.348389,294.500488,0.000000
125.770004,65.007668,-370.437347,-0.000599,0.004202,0.106729,289.168549,14.730948,1.067295,-370.437347,294.500488,0.000000
126.200005,64.992393,-370.392883,-0.000604,0.004202,0.106729,289.100616,14.727487,1.067295,-370.392883,294.500488,0.000000
126.630005,64.969307,-370.392883,-0.000599,0.004202,0.106729,288.997925,14.722256,1.067295,-370.392883,294.500488,0.000000
127.060005,64.962975,-370.392883,-0.000595,0.004202,0.106729,288.969757,14.720820,1.067295,-370.392883,294.500488,0.000000
127.490005,64.955162,-370.481842,-0.000591,0.004202,0.106738,288.934998,14.719049,1.067382,-370.481842,294.500488,0.000000
127.920006,64.936546,-370.392883,-0.000612,0.004202,0.106738,288.852173,14.714832,1.067382,-370.392883,294.500488,0.000000
128.350006,64.900047,-370.437347,-0.000604,0.004202,0.106738,288.689819,14.706561,1.067382,-370.437347,294.500488,0.000000
128.779999,64.874352,-370.481842,-0.000595,0.004202,0.106738,288.575531,14.700738,1.067382,-370.481842,294.500488,0.000000
129.210007,64.845680,-370.526337,-0.000595,0.004202,0.106738,288.447998,14.694242,1.067382,-370.526337,294.500488,0.000000
129.639999,64.825203,-370.526337,-0.000599,0.004202,0.106738,288.356903,14.689601,1.067382,-370.526337,294.500488,0.000000
130.070007,64.783119,-370.526337,-0.000599,0.004202,0.106738,288.169708,14.680064,1.067382,-370.526337,294.500488,0.000000
130.500000,64.776421,-370.481842,-0.000604,0.004202,0.106738,288.139923,14.678547,1.067382,-370.481842,294.500488,0.000000
130.930008,64.760033,-370.526337,-0.000595,0.004202,0.106738,288.067017,14.674833,1.067382,-370.526337,294.500488,0.000000
131.360001,64.744392,-370.526337,-0.000586,0.004202,0.106738,287.997437,14.671289,1.067382,-370.526337,294.500488,0.000000
131.790009,64.729500,-370.615295,-0.000599,0.004202,0.106738,287.931183,14.667914,1.067382,-370.615295,294.500488,0.000000
132.220001,64.714241,-370.526337,-0.000595,0.004202,0.106738,287.863312,14.664456,1.067382,-370.526337,294.500488,0.000000
132.650009,64.691887,-370.526337,-0.000608,0.004202,0.106738,287.763885,14.659391,1.067382,-370.526337,294.500488,0.000000
133.080002,64.720192,-370.615295,-0.000604,0.004202,0.106738,287.889801,14.665805,1.067382,-370.615295,294.500488,0.000000
133.510010,64.701195,-370.659760,-0.000604,0.004202,0.106738,287.805298,14.661500,1.067382,-370.659760,294.500488,0.000000
133.940002,64.687798,-370.659760,-0.000599,0.004202,0.106738,287.745697,14.658464,1.067382,-370.659760,294.500488,0.000000
134.370010,64.666206,-370.704254,-0.000608,0.004202,0.106738,287.649658,14.653572,1.067382,-370.704254,294.500488,0.000000
134.800003,64.640129,-370.615295,-0.000599,0.004202,0.106738,287.533661,14.647663,1.067382,-370.615295,294.500488,0.000000
135.230011,64.621513,-370.659760,-0.000604,0.004202,0.106738,287.450836,14.643444,1.067382,-370.659760,294.500488,0.000000
135.660004,64.612206,-370.704254,-0.000595,0.004203,0.106747,287.409454,14.641335,1.067468,-370.704254,294.500488,0.000000
136.090012,64.587257,-370.659760,-0.000608,0.004205,0.106808,287.298462,14.635682,1.068075,-370.659760,294.500488,0.000000
136.520004,65.936363,-370.748718,-0.000604,0.004217,0.107120,293.299591,14.941394,1.071197,-370.748718,294.500488,0.000000
136.950012,65.975456,-370.748718,-0.000604,0.004216,0.107085,293.473480,14.950252,1.070850,-370.748718,294.500488,0.000000
137.380005,65.904716,-370.748718,-0.000591,0.004216,0.107076,293.158813,14.934223,1.070764,-370.748718,294.500488,0.000000
137.810013,65.934502,-370.837677,-0.000599,0.004216,0.107076,293.291321,14.940971,1.070764,-370.837677,294.500488,0.000000
138.240005,65.883492,-370.837677,-0.000599,0.004216,0.107076,293.064392,14.929413,1.070764,-370.837677,294.500488,0.000000
138.670013,65.865242,-370.837677,-0.000586,0.004216,0.107076,292.983215,14.925277,1.070764,-370.837677,1681.640991,0.000000
139.100006,65.814217,-370.837677,-0.000608,0.004204,0.106773,292.756256,14.913714,1.067728,-370.837677,0.106539,0.000000
139.530014,65.811623,-370.837677,-0.000582,0.004182,0.106226,292.744720,14.913127,1.062265,-370.837677,0.105819,0.000000
139.960007,65.746452,-370.926636,-0.000586,0.004161,0.105689,292.454834,14.898359,1.056888,-370.926636,0.105108,0.000000
140.389999,65.694695,-370.882172,-0.000599,0.004129,0.104882,292.224609,14.886631,1.048823,-370.882172,0.104388,0.000000
140.820007,65.689857,-370.882172,-0.000586,0.004102,0.104189,292.203094,14.885534,1.041885,-370.882172,0.103668,0.000000
141.250000,65.681664,-370.882172,-0.000591,0.004077,0.103555,292.166626,14.883677,1.035554,-370.882172,0.102957,0.000000
141.680008,65.632881,-370.926636,-0.000591,0.004044,0.102723,291.949646,14.872623,1.027229,-370.926636,0.102237,0.000000
142.110001,65.524147,-370.971130,-0.000573,0.004023,0.102194,291.465973,14.847984,1.021939,-370.971130,0.101517,0.000000
142.540009,65.464195,-370.971130,-0.000591,0.003996,0.101491,291.199280,14.834398,1.014914,-370.971130,0.100806,0.000000
142.970001,64.868019,-370.971130,-0.000582,0.003963,0.100668,288.547363,14.699304,1.006676,-370.971130,0.100087,0.000000
143.400009,64.147118,-370.926636,-0.000582,0.003947,0.100251,285.340637,14.535945,1.002513,-370.926636,0.099375,0.000000
143.830002,62.957756,-371.015625,-0.000578,0.003920,0.099558,280.050079,14.266431,0.995575,-371.015625,0.098656,0.000000
144.260010,61.342773,-371.060089,-0.000578,0.003889,0.098777,272.866272,13.900472,0.987770,-371.060089,0.097936,0.000000
144.690002,59.517029,-371.104584,-0.000578,0.003862,0.098092,264.744965,13.486752,0.980919,-371.104584,0.097225,0.000000
145.120010,57.569527,-371.060089,-0.000582,0.003838,0.097485,256.082031,13.045441,0.974848,-371.060089,0.096505,0.000000
145.550003,55.250389,-371.060089,-0.000569,0.003813,0.096843,245.766006,12.519917,0.968431,-371.060089,0.095785,0.000000
145.980011,52.957321,-371.104584,-0.000573,0.003788,0.096219,235.565933,12.000300,0.962187,-371.104584,0.095074,0.000000
146.410004,49.585487,-371.149048,-0.000582,0.003753,0.095317,220.567261,11.236232,0.953168,-371.149048,0.094354,0.000000
146.840012,47.010155,-371.193542,-0.000573,0.003727,0.094675,209.111618,10.652653,0.946750,-371.193542,0.093634,0.000000
147.270004,43.620079,-371.149048,-0.000573,0.003698,0.093921,194.031799,9.884451,0.939206,-371.149048,0.092923,0.000000
147.700012,40.976234,-371.149048,-0.000591,0.003674,0.093313,182.271393,9.285348,0.933135,-371.149048,0.092203,0.000000
148.130005,38.552460,-371.193542,-0.000573,0.003643,0.092542,171.489899,8.736112,0.925417,-371.193542,0.091484,0.000000
148.560013,34.418755,-371.193542,-0.000591,0.003612,0.091752,153.102264,7.799401,0.917525,-371.193542,0.090773,0.000000
148.990005,31.170181,-371.238007,-0.000591,0.003584,0.091024,138.651886,7.063264,0.910240,-371.238007,0.090053,0.000000
149.420013,28.435844,-371.149048,-0.000604,0.003558,0.090382,126.488953,6.443655,0.903823,-371.149048,0.089342,0.000000
149.850006,26.705429,-371.193542,-0.000604,0.003540,0.089923,118.791679,6.051537,0.899226,-371.193542,0.088622,0.000000
150.280014,22.153183,-371.193542,-0.000608,0.003503,0.088969,98.542282,5.019983,0.889687,-371.193542,0.087902,0.000000
150.710007,19.383842,-371.282501,-0.000608,0.003477,0.088327,86.223640,4.392442,0.883270,-371.282501,0.087191,0.000000
151.140015,15.452713,-371.238007,-0.000625,0.003442,0.087434,68.737099,3.501635,0.874337,-371.238007,0.086471,0.000000
151.570007,12.903450,-371.282501,-0.000638,0.003418,0.086827,57.397411,2.923964,0.868267,-371.282501,0.085751,0.000000
152.000000,9.978088,-371.282501,-0.000629,0.003393,0.086185,44.384754,2.261067,0.861849,-371.282501,0.085040,0.000000
152.430008,6.694511,-371.371460,-0.000629,0.003362,0.085404,29.778673,1.516998,0.854044,-371.371460,0.084320,0.000000
152.860001,3.607910,-371.371460,-0.000638,0.003331,0.084607,16.048786,0.817564,0.846065,-371.371460,0.083601,0.000000
153.290009,1.182655,-371.371460,-0.000642,0.003306,0.083973,5.260714,0.267994,0.839735,-371.371460,0.082889,0.000000
153.720001,-1.854420,-371.326965,-0.000660,0.003271,0.083072,-8.248871,-0.420218,0.830716,-371.326965,0.082170,0.000000
154.150009,-0.164963,-371.371460,-0.000716,0.003244,0.082395,-0.733791,-0.037381,0.823951,-371.371460,0.081450,0.000000
154.580002,-0.099800,-371.415955,-0.000742,0.003221,0.081823,-0.443933,-0.022615,0.818228,-371.415955,0.080739,0.000000
155.010010,-0.139267,-371.415955,-0.000789,0.003189,0.080999,-0.619490,-0.031558,0.809989,-371.415955,0.080019,0.000000
155.440002,-0.100540,-371.460419,-0.000828,0.003159,0.080227,-0.447225,-0.022783,0.802271,-371.460419,0.079308,0.000000
155.870010,-0.078201,-371.415955,-0.000871,0.003132,0.079551,-0.347857,-0.017721,0.795506,-371.415955,0.078588,0.000000
156.300003,-0.077454,-371.460419,-0.000897,0.003108,0.078935,-0.344531,-0.017551,0.789349,-371.460419,0.077868,0.000000
156.730011,-0.070007,-371.460419,-0.000936,0.003075,0.078102,-0.311408,-0.015864,0.781024,-371.460419,0.077157,0.000000
157.160004,-0.108360,-371.504913,-0.000987,0.003051,0.077487,-0.482011,-0.024555,0.774866,-371.504913,0.076437,0.000000
157.590012,-0.120277,-371.504913,-0.001030,0.003013,0.076524,-0.535021,-0.027255,0.765240,-371.504913,0.075717,0.000000
158.020004,-0.075226,-371.549377,-0.001069,0.002988,0.075900,-0.334621,-0.017046,0.758996,-371.549377,0.075006,0.000000
158.450012,-0.064423,-371.504913,-0.001099,0.002968,0.075388,-0.286566,-0.014598,0.753879,-371.504913,0.074287,0.000000
158.880005,-0.080437,-371.549377,-0.001151,0.002935,0.074538,-0.357800,-0.018227,0.745381,-371.549377,0.073567,0.000000
159.310013,-0.075226,-371.638336,-0.001190,0.002911,0.073931,-0.334621,-0.017046,0.739310,-371.638336,0.072856,0.000000
159.740005,-0.085648,-371.638336,-0.001224,0.002883,0.073220,-0.380979,-0.019408,0.732199,-371.638336,0.072136,0.000000
160.170013,-0.079689,-371.593872,-0.001242,0.002853,0.072465,-0.354474,-0.018058,0.724654,-371.593872,0.071416,0.000000
160.600006,-0.029419,-371.593872,-0.001281,0.002831,0.071919,-0.130862,-0.006666,0.719190,-371.593872,0.070705,0.000000
161.030014,-0.016388,-371.638336,-0.001311,0.002802,0.071165,-0.072897,-0.003714,0.711645,-371.638336,0.069985,0.000000
161.460007,-0.035751,-371.682831,-0.001350,0.002770,0.070358,-0.159030,-0.008101,0.703580,-371.682831,0.069265,0.000000
161.890015,-0.094589,-371.727295,-0.001401,0.002739,0.069560,-0.420754,-0.021434,0.695602,-371.727295,0.068554,0.000000
162.320007,-0.019737,-371.682831,-0.001423,0.002714,0.068936,-0.087796,-0.004473,0.689358,-371.682831,0.067834,0.000000
162.750015,-0.011177,-371.727295,-0.001440,0.002691,0.068346,-0.049718,-0.002533,0.683461,-371.727295,0.067123,0.000000
163.180008,-0.023834,-371.638336,-0.001487,0.002648,0.067262,-0.106020,-0.005401,0.672620,-371.638336,0.066403,0.000000
163.610001,-0.017502,-371.771790,-0.001513,0.002632,0.066863,-0.077852,-0.003966,0.668631,-371.771790,0.065684,0.000000
164.040009,-0.073357,-371.727295,-0.001539,0.002600,0.066039,-0.326307,-0.016623,0.660393,-371.727295,0.064973,0.000000
164.470001,-0.037239,-371.727295,-0.001578,0.002578,0.065476,-0.165648,-0.008438,0.654756,-371.727295,0.064253,0.000000
164.900009,-0.040588,-371.727295,-0.001608,0.002548,0.064712,-0.180546,-0.009197,0.647124,-371.727295,0.063533,0.000000
165.330002,-0.027184,-371.727295,-0.001643,0.002520,0.064001,-0.120918,-0.006160,0.640013,-371.727295,0.062822,0.000000
165.760010,-0.073730,-371.771790,-0.001686,0.002484,0.063099,-0.327969,-0.016708,0.630994,-371.771790,0.062102,0.000000
166.190002,-0.062561,-371.816284,-0.001750,0.002455,0.062354,-0.278285,-0.014177,0.623535,-371.816284,0.061382,0.000000
166.620010,-0.050270,-371.816284,-0.001789,0.002437,0.061894,-0.223612,-0.011391,0.618939,-371.816284,0.060671,0.000000
167.050003,-0.076714,-371.816284,-0.001798,0.002406,0.061113,-0.341239,-0.017384,0.611134,-371.816284,0.059951,0.000000
167.480011,-0.058090,-371.771790,-0.001854,0.002378,0.060402,-0.258398,-0.013163,0.604023,-371.771790,0.059232,0.000000
167.910004,-0.064423,-371.860748,-0.001858,0.002344,0.059526,-0.286566,-0.014598,0.595264,-371.860748,0.058520,0.000000
168.340012,-0.069633,-371.949707,-0.001910,0.002313,0.058746,-0.309745,-0.015779,0.587459,-371.949707,0.057801,0.000000
168.770004,-0.064423,-371.949707,-0.001940,0.002288,0.058121,-0.286566,-0.014598,0.581215,-371.949707,0.057089,0.000000
169.200012,-0.062561,-371.905243,-0.001970,0.002266,0.057566,-0.278285,-0.014177,0.575665,-371.905243,0.056370,0.000000
169.630005,-0.093094,-371.949707,-0.002001,0.002230,0.056639,-0.414102,-0.021095,0.566385,-371.949707,0.055650,0.000000
170.060013,-0.090858,-371.949707,-0.002035,0.002197,0.055815,-0.404159,-0.020589,0.558147,-371.949707,0.054939,0.000000
170.490005,-0.117302,-371.949707,-0.002065,0.002175,0.055242,-0.521785,-0.026581,0.552423,-371.949707,0.054219,0.000000
170.920013,-0.094955,-371.949707,-0.002113,0.002147,0.054522,-0.422383,-0.021517,0.545225,-371.949707,0.053499,0.000000
171.350006,-0.093094,-371.994202,-0.002126,0.002117,0.053777,-0.414102,-0.021095,0.537767,-371.994202,0.052788,0.000000
171.780014,-0.105385,-371.949707,-0.002164,0.002089,0.053048,-0.468775,-0.023881,0.530482,-371.949707,0.052068,0.000000
172.210007,-0.084160,-371.994202,-0.002182,0.002056,0.052224,-0.374362,-0.019071,0.522243,-371.994202,0.051348,0.000000
172.640015,-0.085648,-372.038666,-0.002212,0.002040,0.051808,-0.380979,-0.019408,0.518081,-372.038666,0.050637,0.000000
173.070007,-0.099052,-372.038666,-0.002246,0.002004,0.050906,-0.440607,-0.022446,0.509062,-372.038666,0.049918,0.000000
173.500015,-0.124001,-372.127625,-0.002281,0.001980,0.050282,-0.551582,-0.028099,0.502818,-372.127625,0.049198,0.000000
173.930008,-0.104271,-372.038666,-0.002311,0.001954,0.049631,-0.463820,-0.023628,0.496313,-372.038666,0.048487,0.000000
174.360016,-0.099052,-372.127625,-0.002333,0.001920,0.048773,-0.440607,-0.022446,0.487728,-372.127625,0.047767,0.000000
174.790009,-0.108360,-372.172119,-0.002371,0.001901,0.048278,-0.482011,-0.024555,0.482785,-372.172119,0.047056,0.000000
175.220001,-0.098312,-372.127625,-0.002402,0.001864,0.047342,-0.437315,-0.022278,0.473419,-372.127625,0.046336,0.000000
175.650009,-0.088257,-372.127625,-0.002432,0.001832,0.046535,-0.392586,-0.019999,0.465353,-372.127625,0.045616,0.000000
176.080002,-0.075226,-372.127625,-0.002458,0.001802,0.045772,-0.334621,-0.017046,0.457722,-372.127625,0.044905,0.000000
176.510010,-0.087135,-372.216583,-0.002475,0.001785,0.045339,-0.387597,-0.019745,0.453386,-372.216583,0.044185,0.000000
176.940002,-0.088631,-372.172119,-0.002527,0.001745,0.044324,-0.394249,-0.020084,0.443239,-372.172119,0.043465,0.000000
177.370010,-0.087509,-372.305573,-0.002557,0.001722,0.043743,-0.389260,-0.019830,0.437429,-372.305573,0.042754,0.000000
177.800003,-0.074104,-372.216583,-0.002570,0.001700,0.043171,-0.329632,-0.016792,0.431705,-372.216583,0.042034,0.000000
178.000015,-0.049904,-372.172119,-0.002565,0.001705,0.043301,-0.221983,-0.011308,0.433006,-372.172119,0.043162,0.000000