File: Data/compression 34/AutoNoHeating-15-34-reverse-1-2_11152024_201618.csv
Time (sec),S:Load (lbs),S:HL1 (DIM),S:LVDT (in),S:Position (in),Ch:Position (mm),Ch:Load (N),Ch:Stress (MPa),Ch:Strain (mm/mm),Ch:HL1 (DIM),Set Point (),Cycles ()
0.110000,-0.052872,-92.520378,-0.011982,-0.006961,-0.176819,-0.235185,-0.011981,-1.768187,-92.520378,-0.177061,0.000000
0.490000,-0.044685,-92.564857,-0.011969,-0.006934,-0.176125,-0.198770,-0.010126,-1.761249,-92.564857,-0.175414,0.000000
0.870000,-0.039467,-92.609337,-0.011831,-0.006706,-0.170332,-0.175557,-0.008943,-1.703318,-92.609337,-0.169083,0.000000
1.250000,-0.036491,-92.609337,-0.011572,-0.006463,-0.164157,-0.162322,-0.008269,-1.641572,-92.609337,-0.162752,0.000000
1.630000,-0.019363,-92.564857,-0.011331,-0.006212,-0.157792,-0.086133,-0.004388,-1.577917,-92.564857,-0.156421,0.000000
2.010000,-0.055107,-92.609337,-0.011063,-0.005966,-0.151539,-0.245129,-0.012487,-1.515390,-92.609337,-0.150091,0.000000
2.390000,-0.077820,-92.698303,-0.010809,-0.005712,-0.145078,-0.346160,-0.017634,-1.450782,-92.698303,-0.143760,0.000000
2.770000,-0.113197,-92.742783,-0.010568,-0.005467,-0.138851,-0.503527,-0.025651,-1.388515,-92.742783,-0.137429,0.000000
3.150000,-0.039093,-92.698303,-0.010292,-0.005218,-0.132538,-0.173894,-0.008859,-1.325381,-92.698303,-0.131099,0.000000
3.530000,-0.051010,-92.742783,-0.010046,-0.004965,-0.126103,-0.226904,-0.011559,-1.261033,-92.742783,-0.124768,0.000000
3.910000,-0.027184,-92.787262,-0.009783,-0.004716,-0.119799,-0.120918,-0.006160,-1.197986,-92.787262,-0.118437,0.000000
4.290000,-0.066277,-92.787262,-0.009516,-0.004461,-0.113320,-0.294813,-0.015018,-1.133204,-92.787262,-0.112106,0.000000
4.670000,-0.113571,-92.831741,-0.009274,-0.004215,-0.107059,-0.505190,-0.025736,-1.070590,-92.831741,-0.105776,0.000000
5.050000,-0.096817,-92.876228,-0.009015,-0.003962,-0.100642,-0.430664,-0.021939,-1.006415,-92.876228,-0.099445,0.000000
5.430000,-0.038727,-92.831741,-0.008761,-0.003716,-0.094380,-0.172265,-0.008776,-0.943802,-92.831741,-0.093114,0.000000
5.810000,0.010056,-92.876228,-0.008507,-0.003473,-0.088223,0.044729,0.002279,-0.882229,-92.876228,-0.086783,0.000000
6.190000,-0.032768,-92.920708,-0.008248,-0.003217,-0.081719,-0.145760,-0.007425,-0.817187,-92.920708,-0.080453,0.000000
6.570000,-0.053619,-93.009666,-0.007981,-0.002970,-0.075431,-0.238511,-0.012150,-0.754313,-93.009666,-0.074122,0.000000
6.950000,-0.067398,-92.920708,-0.007731,-0.002721,-0.069118,-0.299802,-0.015273,-0.691179,-92.920708,-0.067791,0.000000
7.330000,-0.025688,-92.965187,-0.007480,-0.002473,-0.062804,-0.114267,-0.005821,-0.628045,-92.965187,-0.061460,0.000000
7.710001,-0.002235,-92.965187,-0.007205,-0.002221,-0.056404,-0.009944,-0.000507,-0.564044,-92.965187,-0.055130,0.000000
8.090000,-0.000366,-93.054146,-0.006946,-0.001973,-0.050126,-0.001629,-0.000083,-0.501256,-93.054146,-0.048799,0.000000
8.470000,-0.040955,-93.054146,-0.006687,-0.001720,-0.043699,-0.182175,-0.009280,-0.436995,-93.054146,-0.042468,0.000000
8.850000,-0.053619,-93.143112,-0.006437,-0.001467,-0.037273,-0.238511,-0.012150,-0.372734,-93.143112,-0.036137,0.000000
9.230000,-0.030533,-93.098633,-0.006187,-0.001223,-0.031055,-0.135817,-0.006919,-0.310553,-93.098633,-0.029807,0.000000
9.610001,0.001495,-93.098633,-0.005911,-0.000972,-0.024690,0.006652,0.000339,-0.246899,-93.098633,-0.023476,0.000000
9.990001,-0.003349,-93.143112,-0.005674,-0.000727,-0.018455,-0.014898,-0.000759,-0.184546,-93.143112,-0.017145,0.000000
10.370001,-0.002235,-93.276558,-0.005420,-0.000479,-0.012176,-0.009944,-0.000507,-0.121758,-93.276558,-0.010814,0.000000
10.750001,0.111343,-93.187592,-0.005170,-0.000234,-0.005932,0.495280,0.025231,-0.059318,-93.187592,-0.004518,0.000000
11.130000,0.070007,-93.232071,-0.005152,-0.000000,-0.000000,0.311408,0.015864,-0.000000,-93.232071,0.000217,0.000000
11.510000,0.132942,-93.232071,-0.005161,-0.000000,-0.000000,0.591356,0.030125,-0.000000,-93.232071,0.000607,0.000000
11.890000,0.105385,-93.321037,-0.005144,0.000000,0.000009,0.468775,0.023881,0.000087,-93.321037,0.001240,0.000000
12.270000,0.201080,-93.409996,-0.005126,0.000035,0.000893,0.894450,0.045565,0.008932,-93.409996,0.001873,0.000000
12.650001,0.245026,-93.409996,-0.005118,0.000057,0.001448,1.089929,0.055524,0.014483,-93.409996,0.002506,0.000000
13.030001,0.312050,-93.365517,-0.005083,0.000080,0.002021,1.388067,0.070712,0.020206,-93.365517,0.003139,0.000000
13.410001,0.397697,-93.365517,-0.005075,0.000100,0.002550,1.769047,0.090120,0.025496,-93.365517,0.003772,0.000000
13.790001,0.568985,-93.365517,-0.005040,0.000127,0.003217,2.530972,0.128934,0.032174,-93.365517,0.004406,0.000000
14.170001,0.751076,-93.409996,-0.005010,0.000157,0.003998,3.340952,0.170196,0.039979,-93.409996,0.005039,0.000000
14.550001,0.876198,-93.543442,-0.004980,0.000180,0.004570,3.897522,0.198549,0.045703,-93.543442,0.005672,0.000000
14.930000,1.074669,-93.454475,-0.004958,0.000206,0.005238,4.780366,0.243523,0.052380,-93.454475,0.006313,0.000000
15.310000,1.172600,-93.543442,-0.004950,0.000230,0.005836,5.215984,0.265715,0.058364,-93.543442,0.006946,0.000000
15.690001,1.488747,-93.543442,-0.004902,0.000254,0.006443,6.622276,0.337355,0.064435,-93.543442,0.007580,0.000000
16.070002,1.835052,-93.543442,-0.004894,0.000285,0.007241,8.162721,0.415829,0.072413,-93.543442,0.008213,0.000000
16.450001,1.982513,-93.587921,-0.004859,0.000305,0.007744,8.818660,0.449244,0.077443,-93.587921,0.008846,0.000000
16.830000,2.196259,-93.587921,-0.004859,0.000330,0.008377,9.769446,0.497679,0.083774,-93.587921,0.009479,0.000000
17.210001,2.446487,-93.632401,-0.004812,0.000355,0.009019,10.882520,0.554382,0.090191,-93.632401,0.010112,0.000000
17.590000,2.585388,-93.676880,-0.004794,0.000372,0.009461,11.500381,0.585857,0.094614,-93.676880,0.010745,0.000000
17.970001,3.254166,-93.676880,-0.004777,0.000406,0.010320,14.475252,0.737405,0.103200,-93.676880,0.011378,0.000000
18.350000,3.475357,-93.721367,-0.004756,0.000432,0.010970,15.459160,0.787527,0.109704,-93.721367,0.012011,0.000000
18.730001,3.898743,-93.721367,-0.004717,0.000460,0.011673,17.342474,0.883468,0.116729,-93.721367,0.012644,0.000000
19.110001,4.068169,-93.765846,-0.004704,0.000481,0.012211,18.096117,0.921860,0.122105,-93.765846,0.013277,0.000000
19.490002,4.212280,-93.765846,-0.004695,0.000497,0.012618,18.737158,0.954516,0.126181,-93.765846,0.013910,0.000000
19.870001,4.969315,-93.721367,-0.004648,0.000532,0.013511,22.104616,1.126063,0.135114,-93.721367,0.014543,0.000000
20.250002,5.043419,-93.810326,-0.004639,0.000553,0.014049,22.434248,1.142855,0.140491,-93.810326,0.015176,0.000000
20.630001,5.356583,-93.854805,-0.004618,0.000575,0.014595,23.827271,1.213819,0.145954,-93.854805,0.015810,0.000000
21.010000,5.713684,-93.899284,-0.004592,0.000601,0.015263,25.415735,1.294739,0.152632,-93.899284,0.016443,0.000000
21.390001,5.725601,-93.810326,-0.004557,0.000618,0.015697,25.468746,1.297440,0.156968,-93.810326,0.017076,0.000000
21.770000,6.456940,-93.899284,-0.004536,0.000656,0.016659,28.721903,1.463163,0.166594,-93.899284,0.017709,0.000000
22.150002,6.635307,-93.943771,-0.004501,0.000680,0.017266,29.515322,1.503582,0.172665,-93.943771,0.018342,0.000000
22.530001,6.783142,-94.032730,-0.004501,0.000697,0.017700,30.172922,1.537082,0.177001,-94.032730,0.018975,0.000000
22.910002,7.234451,-94.032730,-0.004475,0.000729,0.018507,32.180447,1.639350,0.185066,-94.032730,0.019608,0.000000
23.290001,7.400162,-94.032730,-0.004449,0.000749,0.019027,32.917564,1.676901,0.190269,-94.032730,0.020241,0.000000
23.670002,7.927811,-94.032730,-0.004411,0.000780,0.019816,35.264664,1.796468,0.198161,-94.032730,0.020874,0.000000
24.050001,8.035797,-94.121689,-0.004381,0.000800,0.020328,35.745010,1.820938,0.203278,-94.121689,0.021507,0.000000
24.430000,8.088303,-94.166176,-0.004385,0.000819,0.020813,35.978565,1.832836,0.208134,-94.166176,0.022140,0.000000
24.810001,8.768257,-94.166176,-0.004346,0.000857,0.021767,39.003155,1.986915,0.217674,-94.166176,0.022773,0.000000
25.190001,8.507225,-94.166176,-0.004342,0.000865,0.021967,37.842026,1.927765,0.219668,-94.166176,0.023406,0.000000
25.570002,9.424751,-94.166176,-0.004290,0.000906,0.023016,41.923386,2.135679,0.230162,-94.166176,0.024048,0.000000
25.950001,9.451187,-94.210655,-0.004260,0.000928,0.023563,42.040981,2.141670,0.235625,-94.210655,0.024681,0.000000
26.330002,9.512627,-94.210655,-0.004243,0.000945,0.024005,42.314278,2.155592,0.240048,-94.210655,0.025314,0.000000
26.710001,10.015335,-94.210655,-0.004230,0.000979,0.024872,44.550434,2.269507,0.248720,-94.210655,0.025947,0.000000
27.090002,10.035439,-94.255135,-0.004199,0.000994,0.025236,44.639858,2.274063,0.252363,-94.255135,0.026580,0.000000
27.470001,10.705711,-94.255135,-0.004161,0.001031,0.026199,47.621384,2.425949,0.261989,-94.255135,0.027214,0.000000
27.850000,10.798058,-94.299614,-0.004143,0.001054,0.026763,48.032158,2.446875,0.267626,-94.299614,0.027847,0.000000
28.230001,11.001747,-94.388580,-0.004126,0.001075,0.027300,48.938217,2.493032,0.273003,-94.388580,0.028480,0.000000
28.610001,11.188675,-94.388580,-0.004109,0.001097,0.027855,49.769711,2.535390,0.278553,-94.388580,0.029113,0.000000
28.990002,11.403534,-94.344101,-0.004087,0.001122,0.028506,50.725452,2.584078,0.285057,-94.344101,0.029746,0.000000
29.370001,11.935654,-94.344101,-0.004049,0.001150,0.029208,53.092438,2.704658,0.292082,-94.344101,0.030379,0.000000
29.750002,12.133011,-94.388580,-0.004031,0.001178,0.029928,53.970329,2.749380,0.299280,-94.388580,0.031012,0.000000
30.130001,12.235420,-94.477539,-0.003997,0.001201,0.030500,54.425869,2.772586,0.305003,-94.477539,0.031645,0.000000
30.510002,12.481552,-94.477539,-0.003984,0.001227,0.031159,55.520718,2.828360,0.311594,-94.477539,0.032278,0.000000
30.890001,12.411919,-94.477539,-0.003962,0.001247,0.031671,55.210972,2.812581,0.316711,-94.477539,0.032911,0.000000
31.270002,12.874405,-94.522018,-0.003932,0.001270,0.032269,57.268211,2.917382,0.322695,-94.522018,0.033544,0.000000
31.650002,13.419937,-94.566505,-0.003898,0.001303,0.033093,59.694862,3.041001,0.330933,-94.566505,0.034177,0.000000
32.030003,13.456802,-94.566505,-0.003872,0.001325,0.033666,59.858845,3.049355,0.336657,-94.566505,0.034810,0.000000
32.410000,13.742783,-94.655464,-0.003850,0.001350,0.034290,61.130951,3.114159,0.342901,-94.655464,0.035444,0.000000
32.790001,13.914818,-94.655464,-0.003842,0.001375,0.034923,61.896202,3.153143,0.349232,-94.655464,0.036077,0.000000
33.170002,14.013870,-94.610985,-0.003794,0.001398,0.035522,62.336807,3.175588,0.355216,-94.610985,0.036710,0.000000
33.550003,14.596634,-94.610985,-0.003768,0.001430,0.036328,64.929070,3.307645,0.363281,-94.610985,0.037343,0.000000
33.930000,14.455132,-94.744423,-0.003747,0.001450,0.036840,64.299637,3.275580,0.368397,-94.744423,0.037976,0.000000
34.310001,14.770905,-94.788910,-0.003747,0.001477,0.037525,65.704262,3.347135,0.375249,-94.788910,0.038609,0.000000
34.690002,14.647644,-94.744423,-0.003704,0.001494,0.037958,65.155975,3.319204,0.379585,-94.744423,0.039242,0.000000
35.070004,15.093002,-94.699944,-0.003678,0.001523,0.038687,67.137024,3.420123,0.386869,-94.699944,0.039875,0.000000
35.450001,15.464630,-94.744423,-0.003635,0.001553,0.039441,68.790108,3.504335,0.394414,-94.744423,0.040508,0.000000
35.830002,15.469101,-94.877869,-0.003630,0.001577,0.040066,68.809998,3.505348,0.400658,-94.877869,0.041141,0.000000
36.210003,15.705185,-94.922348,-0.003600,0.001603,0.040708,69.860153,3.558846,0.407076,-94.922348,0.041774,0.000000
36.590000,15.565918,-94.833389,-0.003587,0.001621,0.041185,69.240662,3.527287,0.411845,-94.833389,0.042416,0.000000
36.970001,15.710770,-94.922348,-0.003553,0.001647,0.041826,69.884995,3.560111,0.418263,-94.922348,0.043049,0.000000
37.350002,16.512863,-94.922348,-0.003518,0.001681,0.042702,73.452881,3.741868,0.427022,-94.922348,0.043682,0.000000
37.730003,16.415298,-94.966827,-0.003488,0.001703,0.043266,73.018898,3.719760,0.432659,-94.966827,0.044315,0.000000
38.110001,16.464081,-94.966827,-0.003471,0.001724,0.043778,73.235886,3.730814,0.437776,-94.966827,0.044948,0.000000
38.490002,16.567596,-95.055794,-0.003454,0.001751,0.044471,73.696350,3.754271,0.444713,-95.055794,0.045581,0.000000
38.870003,16.391464,-95.011314,-0.003428,0.001766,0.044862,72.912872,3.714359,0.448616,-95.011314,0.046214,0.000000
39.250000,17.238983,-94.966827,-0.003393,0.001802,0.045781,76.682823,3.906409,0.457808,-94.966827,0.046848,0.000000
39.630001,17.372665,-95.100273,-0.003363,0.001827,0.046397,77.277473,3.936702,0.463966,-95.100273,0.047481,0.000000
40.010002,17.651199,-95.144753,-0.003337,0.001855,0.047125,78.516457,3.999819,0.471250,-95.144753,0.048114,0.000000
40.390003,17.505234,-95.100273,-0.003307,0.001877,0.047671,77.867172,3.966743,0.476714,-95.100273,0.048747,0.000000
40.770000,17.271011,-95.100273,-0.003285,0.001893,0.048088,76.825294,3.913667,0.480877,-95.100273,0.049380,0.000000
41.150002,18.284607,-95.144753,-0.003272,0.001930,0.049033,81.333992,4.143351,0.490329,-95.144753,0.050013,0.000000
41.530003,18.096558,-95.189232,-0.003229,0.001952,0.049571,80.497505,4.100739,0.495706,-95.189232,0.050646,0.000000
41.910004,18.095444,-95.278198,-0.003225,0.001972,0.050100,80.492554,4.100486,0.500996,-95.278198,0.051279,0.000000
42.290001,18.468559,-95.278198,-0.003203,0.001998,0.050750,82.152252,4.185036,0.507500,-95.278198,0.051912,0.000000
42.670002,18.045914,-95.278198,-0.003165,0.002012,0.051106,80.272232,4.089262,0.511056,-95.278198,0.052545,0.000000
43.050003,19.082230,-95.322678,-0.003143,0.002053,0.052138,84.881996,4.324095,0.521376,-95.322678,0.053178,0.000000
43.430000,18.947060,-95.322678,-0.003104,0.002077,0.052762,84.280731,4.293465,0.527620,-95.322678,0.053811,0.000000
43.810001,18.891571,-95.367157,-0.003070,0.002097,0.053265,84.033905,4.280891,0.532650,-95.367157,0.054444,0.000000
44.190002,19.221497,-95.411636,-0.003061,0.002124,0.053959,85.501488,4.355653,0.539588,-95.411636,0.055078,0.000000
44.570004,19.416245,-95.367157,-0.003031,0.002149,0.054583,86.367767,4.399784,0.545832,-95.367157,0.055711,0.000000
44.950001,19.123192,-95.456123,-0.003018,0.002165,0.054999,85.064209,4.333377,0.549995,-95.456123,0.056344,0.000000
45.330002,19.727180,-95.411636,-0.002966,0.002199,0.055858,87.750885,4.470243,0.558580,-95.411636,0.056977,0.000000
45.710003,19.437469,-95.500603,-0.002945,0.002218,0.056326,86.462181,4.404593,0.563263,-95.500603,0.057610,0.000000
46.090004,20.209030,-95.545082,-0.002919,0.002253,0.057220,89.894257,4.579432,0.572196,-95.545082,0.058243,0.000000
46.470001,19.520882,-95.500603,-0.002893,0.002267,0.057592,86.833221,4.423495,0.575925,-95.500603,0.058876,0.000000
46.850002,20.131203,-95.500603,-0.002876,0.002298,0.058373,89.548065,4.561796,0.583730,-95.500603,0.059509,0.000000
47.230003,20.531128,-95.545082,-0.002824,0.002325,0.059058,91.327019,4.652420,0.590581,-95.545082,0.060142,0.000000
47.610001,20.081680,-95.589561,-0.002807,0.002345,0.059552,89.327774,4.550574,0.595524,-95.589561,0.060784,0.000000
47.990002,20.775780,-95.678528,-0.002794,0.002376,0.060350,92.415283,4.707859,0.603502,-95.678528,0.061417,0.000000
48.370003,20.492035,-95.634048,-0.002772,0.002392,0.060767,91.153122,4.643561,0.607665,-95.634048,0.062050,0.000000
48.750004,21.017822,-95.589561,-0.002734,0.002426,0.061608,93.491943,4.762707,0.616077,-95.589561,0.062683,0.000000
49.130001,21.079636,-95.634048,-0.002712,0.002449,0.062206,93.766899,4.776714,0.622061,-95.634048,0.063316,0.000000
49.510002,21.212570,-95.723007,-0.002690,0.002473,0.062822,94.358223,4.806837,0.628218,-95.723007,0.063949,0.000000
49.890003,21.196564,-95.767487,-0.002656,0.002495,0.063377,94.287025,4.803210,0.633769,-95.767487,0.064582,0.000000
50.270004,20.998833,-95.767487,-0.002634,0.002515,0.063871,93.407471,4.758403,0.638712,-95.767487,0.065215,0.000000
50.650002,21.853798,-95.767487,-0.002626,0.002547,0.064695,97.210548,4.952141,0.646950,-95.767487,0.065848,0.000000
51.030003,22.074615,-95.767487,-0.002578,0.002576,0.065432,98.192795,5.002179,0.654322,-95.767487,0.066482,0.000000
51.410004,22.019501,-95.811966,-0.002552,0.002602,0.066091,97.947632,4.989690,0.660913,-95.811966,0.067115,0.000000
51.790001,22.033279,-95.856453,-0.002514,0.002625,0.066672,98.008919,4.992812,0.666723,-95.856453,0.067748,0.000000
52.170002,21.755493,-95.900932,-0.002514,0.002644,0.067167,96.773270,4.929865,0.671666,-95.900932,0.068381,0.000000
52.550003,22.073494,-95.856453,-0.002483,0.002669,0.067791,98.187805,5.001925,0.677910,-95.856453,0.069014,0.000000
52.930004,22.860321,-95.900932,-0.002458,0.002700,0.068572,101.687790,5.180223,0.685715,-95.900932,0.069647,0.000000
53.310001,22.292084,-95.945412,-0.002432,0.002716,0.068996,99.160141,5.051458,0.689965,-95.945412,0.070280,0.000000
53.690002,22.893463,-96.034370,-0.002397,0.002747,0.069786,101.835213,5.187733,0.697856,-96.034370,0.070913,0.000000
54.070004,23.049110,-96.078857,-0.002371,0.002773,0.070445,102.527565,5.223003,0.704447,-96.078857,0.071546,0.000000
54.450001,22.556465,-96.078857,-0.002341,0.002795,0.070982,100.336166,5.111368,0.709824,-96.078857,0.072179,0.000000
54.830002,23.746941,-96.078857,-0.002320,0.002827,0.071815,105.631668,5.381134,0.718150,-96.078857,0.072812,0.000000
55.210003,23.399513,-96.078857,-0.002281,0.002849,0.072361,104.086235,5.302406,0.723613,-96.078857,0.073445,0.000000
55.590004,23.651237,-96.167816,-0.002251,0.002876,0.073038,105.205956,5.359447,0.730377,-96.167816,0.074078,0.000000
55.970001,23.475105,-96.123337,-0.002246,0.002893,0.073471,104.422485,5.319535,0.734714,-96.123337,0.074711,0.000000
56.350002,24.024353,-96.212296,-0.002212,0.002922,0.074209,106.865662,5.443996,0.742085,-96.212296,0.075345,0.000000
56.730003,24.636909,-96.167816,-0.002177,0.002951,0.074963,109.590446,5.582803,0.749630,-96.167816,0.075978,0.000000
57.110004,24.490570,-96.256775,-0.002160,0.002976,0.075579,108.939499,5.549643,0.755787,-96.256775,0.076611,0.000000
57.490002,24.802986,-96.167816,-0.002121,0.002999,0.076186,110.329193,5.620437,0.761858,-96.167816,0.077244,0.000000
57.870003,24.655899,-96.256775,-0.002100,0.003020,0.076697,109.674919,5.587107,0.766974,-96.256775,0.077877,0.000000
58.250004,24.520729,-96.301262,-0.002082,0.003038,0.077166,109.073654,5.556477,0.771657,-96.301262,0.078510,0.000000
58.630001,25.377190,-96.256775,-0.002061,0.003068,0.077938,112.883377,5.750553,0.779376,-96.256775,0.079152,0.000000
59.010002,25.797966,-96.301262,-0.002013,0.003097,0.078666,114.755081,5.845902,0.786660,-96.301262,0.079785,0.000000
59.390003,25.965538,-96.345741,-0.002013,0.003121,0.079273,115.500481,5.883875,0.792731,-96.345741,0.080418,0.000000
59.770004,26.263802,-96.345741,-0.001970,0.003144,0.079854,116.827225,5.951463,0.798541,-96.345741,0.081051,0.000000
60.150002,26.119324,-96.390221,-0.001966,0.003163,0.080340,116.184555,5.918723,0.803398,-96.390221,0.081684,0.000000
60.530003,27.309052,-96.390221,-0.001940,0.003195,0.081164,121.476730,6.188319,0.811637,-96.390221,0.082317,0.000000
60.910004,27.656853,-96.390221,-0.001914,0.003224,0.081883,123.023827,6.267133,0.818834,-96.390221,0.082950,0.000000
61.290005,28.301796,-96.479179,-0.001876,0.003251,0.082586,125.892677,6.413279,0.825859,-96.479179,0.083583,0.000000
61.670002,27.937248,-96.568146,-0.001850,0.003273,0.083124,124.271088,6.330671,0.831236,-96.568146,0.084216,0.000000
62.050003,28.201630,-96.479179,-0.001837,0.003292,0.083609,125.447113,6.390581,0.836092,-96.479179,0.084849,0.000000
62.430004,29.456528,-96.523666,-0.001802,0.003324,0.084442,131.029175,6.674944,0.844418,-96.523666,0.085482,0.000000
62.810001,29.706764,-96.523666,-0.001776,0.003347,0.085005,132.142288,6.731649,0.850055,-96.523666,0.086116,0.000000
63.190002,30.044128,-96.568146,-0.001772,0.003369,0.085578,133.642960,6.808097,0.855778,-96.568146,0.086749,0.000000
63.570004,30.709557,-96.701584,-0.001725,0.003394,0.086220,136.602936,6.958885,0.862196,-96.701584,0.087382,0.000000
63.950005,30.485764,-96.701584,-0.001725,0.003411,0.086627,135.607452,6.908173,0.866272,-96.701584,0.088015,0.000000
64.330002,32.101860,-96.657104,-0.001694,0.003448,0.087590,142.796204,7.274385,0.875898,-96.657104,0.088648,0.000000
64.710007,32.313370,-96.657104,-0.001673,0.003468,0.088093,143.737045,7.322314,0.880928,-96.657104,0.089281,0.000000
65.090004,32.878998,-96.701584,-0.001643,0.003495,0.088769,146.253082,7.450488,0.887692,-96.701584,0.089914,0.000000
65.470001,33.776047,-96.790550,-0.001634,0.003523,0.089489,150.243362,7.653762,0.894890,-96.790550,0.090547,0.000000
65.850006,33.515388,-96.790550,-0.001600,0.003544,0.090009,149.083893,7.594696,0.900094,-96.790550,0.091180,0.000000
66.230003,34.201294,-96.746071,-0.001582,0.003565,0.090538,152.134949,7.750124,0.905384,-96.746071,0.091813,0.000000
66.610001,35.430122,-96.790550,-0.001556,0.003596,0.091336,157.601059,8.028581,0.913362,-96.790550,0.092446,0.000000
66.990005,35.793190,-96.790550,-0.001531,0.003614,0.091787,159.216064,8.110852,0.917872,-96.790550,0.093079,0.000000
67.370003,36.690979,-96.835030,-0.001505,0.003646,0.092611,163.209625,8.314294,0.926110,-96.835030,0.093712,0.000000
67.750000,36.965416,-96.923996,-0.001496,0.003661,0.092984,164.430389,8.376483,0.929839,-96.923996,0.094345,0.000000
68.130005,38.124237,-96.923996,-0.001483,0.003689,0.093712,169.585083,8.639075,0.937124,-96.923996,0.094979,0.000000
68.510002,39.654320,-96.923996,-0.001462,0.003722,0.094536,176.391220,8.985797,0.945363,-96.923996,0.095612,0.000000
68.890007,39.503136,-96.968475,-0.001431,0.003736,0.094892,175.718719,8.951539,0.948918,-96.968475,0.096245,0.000000
69.270004,40.816864,-96.968475,-0.001414,0.003770,0.095759,181.562485,9.249233,0.957591,-96.968475,0.096886,0.000000
69.650002,41.662895,-97.057434,-0.001397,0.003788,0.096219,185.325821,9.440947,0.962187,-97.057434,0.097520,0.000000
70.030006,42.587868,-97.012955,-0.001367,0.003813,0.096852,189.440292,9.650549,0.968518,-97.012955,0.098153,0.000000
70.410004,44.253860,-96.968475,-0.001367,0.003847,0.097710,196.850998,10.028068,0.977103,-96.968475,0.098786,0.000000
70.790001,44.824341,-97.012955,-0.001337,0.003870,0.098300,199.388626,10.157341,0.983000,-97.012955,0.099419,0.000000
71.170006,45.582115,-97.057434,-0.001328,0.003892,0.098855,202.759369,10.329055,0.988551,-97.057434,0.100052,0.000000
71.550003,46.662369,-97.190880,-0.001298,0.003913,0.099401,207.564590,10.573844,0.994014,-97.190880,0.100685,0.000000
71.930000,47.918007,-97.190880,-0.001293,0.003943,0.100147,213.149933,10.858376,1.001472,-97.190880,0.101318,0.000000
72.310005,49.880783,-97.101913,-0.001272,0.003973,0.100910,221.880798,11.303147,1.009104,-97.101913,0.101951,0.000000
72.690002,50.760696,-97.146400,-0.001242,0.003998,0.101543,225.794861,11.502539,1.015435,-97.146400,0.102584,0.000000
73.070000,51.986176,-97.190880,-0.001229,0.004023,0.102194,231.246063,11.780236,1.021939,-97.190880,0.103217,0.000000
73.450005,52.436005,-97.324318,-0.001212,0.004043,0.102688,233.246994,11.882169,1.026882,-97.324318,0.103850,0.000000
73.830002,53.528175,-97.279839,-0.001203,0.004065,0.103261,238.105209,12.129658,1.032606,-97.279839,0.104483,0.000000
74.210007,55.436577,-97.235359,-0.001199,0.004097,0.104067,246.594208,12.562108,1.040671,-97.235359,0.105116,0.000000
74.590004,56.706367,-97.279839,-0.001164,0.004117,0.104561,252.242523,12.849847,1.045614,-97.279839,0.105750,0.000000
74.970001,58.373482,-97.324318,-0.001147,0.004144,0.105264,259.658203,13.227620,1.052639,-97.324318,0.106383,0.000000
75.350006,59.705086,-97.368805,-0.001143,0.004170,0.105914,265.581482,13.529366,1.059143,-97.368805,0.107016,0.000000
75.730003,60.453926,-97.368805,-0.001112,0.004187,0.106339,268.912506,13.699056,1.063392,-97.368805,0.107649,0.000000
76.110001,62.692627,-97.324318,-0.001104,0.004221,0.107224,278.870728,14.206352,1.072238,-97.324318,0.108282,0.000000
76.490005,63.938957,-97.457764,-0.001087,0.004242,0.107753,284.414673,14.488775,1.077528,-97.457764,0.108915,0.000000
76.870003,64.748878,-97.457764,-0.001065,0.004264,0.108316,288.017395,14.672306,1.083165,-97.457764,0.109548,0.000000
77.250000,66.500145,-97.457764,-0.001048,0.004279,0.108698,295.807404,15.069149,1.086981,-97.457764,0.019083,0.000000
77.630005,65.316002,-97.546722,-0.001043,0.004279,0.108689,290.540100,14.800818,1.086894,-97.546722,294.500488,0.000000
78.010002,65.552818,-97.502243,-0.001039,0.004295,0.109088,291.593506,14.854481,1.090883,-97.502243,294.500488,0.000000
78.390007,64.883675,-97.502243,-0.001030,0.004295,0.109088,288.617004,14.702851,1.090883,-97.502243,294.500488,0.000000
78.770004,66.377632,-97.546722,-0.001022,0.004284,0.108819,295.262451,15.041386,1.088195,-97.546722,294.500488,0.000000
79.150002,65.730812,-97.591209,-0.001013,0.004284,0.108819,292.385254,14.894815,1.088195,-97.591209,294.500488,0.000000
79.530006,65.118263,-97.635689,-0.001009,0.004295,0.109088,289.660492,14.756009,1.090883,-97.635689,294.500488,0.000000
79.910004,64.977882,-97.591209,-0.001022,0.004315,0.109600,289.036041,14.724199,1.096000,-97.591209,294.500488,0.000000
80.290001,65.106728,-97.680168,-0.001009,0.004321,0.109747,289.609192,14.753395,1.097474,-97.680168,294.500488,0.000000
80.670006,64.886650,-97.635689,-0.000996,0.004321,0.109765,288.630249,14.703525,1.097648,-97.635689,294.500488,0.000000
81.050003,65.825401,-97.769127,-0.000987,0.004334,0.110086,292.806000,14.916249,1.100856,-97.769127,294.500488,0.000000
81.430000,65.574425,-97.769127,-0.001000,0.004334,0.110086,291.689606,14.859378,1.100856,-97.769127,294.500488,0.000000
81.810005,65.310402,-97.724648,-0.000992,0.004334,0.110086,290.515167,14.799548,1.100856,-97.724648,294.500488,0.000000
82.190002,65.067619,-97.724648,-0.000974,0.004334,0.110094,289.435211,14.744533,1.100943,-97.724648,294.500488,0.000000
82.570007,64.820732,-97.813614,-0.000974,0.004334,0.110094,288.337006,14.688588,1.100943,-97.813614,294.500488,0.000000
82.950005,65.902473,-97.858093,-0.000979,0.004338,0.110181,293.148834,14.933714,1.101810,-97.858093,294.500488,0.000000
83.330002,65.648903,-97.858093,-0.000987,0.004338,0.110181,292.020905,14.876254,1.101810,-97.858093,294.500488,0.000000
83.710007,65.427711,-97.858093,-0.000970,0.004338,0.110181,291.036987,14.826132,1.101810,-97.858093,294.500488,0.000000
84.090004,65.222160,-97.813614,-0.000979,0.004338,0.110181,290.122650,14.779552,1.101810,-97.813614,294.500488,0.000000
84.470001,64.998726,-97.858093,-0.000970,0.004338,0.110181,289.128784,14.728922,1.101810,-97.858093,294.500488,0.000000
84.850006,64.815147,-97.991531,-0.000974,0.004338,0.110190,288.312164,14.687323,1.101897,-97.991531,294.500488,0.000000
85.230003,64.644600,-97.991531,-0.000957,0.004338,0.110190,287.553528,14.648676,1.101897,-97.991531,294.500488,0.000000
85.610001,66.399223,-97.991531,-0.000961,0.004318,0.109678,295.358490,15.046279,1.096780,-97.991531,294.500488,0.000000
85.990005,66.207451,-97.947052,-0.000957,0.004318,0.109678,294.505463,15.002823,1.096780,-97.947052,294.500488,0.000000
86.370003,66.029839,-98.036018,-0.000961,0.004318,0.109678,293.715393,14.962575,1.096780,-98.036018,294.500488,0.000000
86.750008,65.888710,-98.036018,-0.000949,0.004318,0.109678,293.087616,14.930594,1.096780,-98.036018,294.500488,0.000000
87.130005,65.757256,-98.124977,-0.000974,0.004318,0.109678,292.502869,14.900806,1.096780,-98.124977,294.500488,0.000000
87.510002,65.568092,-98.124977,-0.000970,0.004319,0.109695,291.661438,14.857943,1.096954,-98.124977,294.500488,0.000000
87.890007,65.415794,-98.124977,-0.000961,0.004319,0.109695,290.983978,14.823431,1.096954,-98.124977,294.500488,0.000000
88.270004,65.330894,-98.080498,-0.000957,0.004341,0.110259,290.606323,14.804193,1.102591,-98.080498,294.500488,0.000000
88.650002,65.231087,-98.213943,-0.000949,0.004341,0.110268,290.162354,14.781575,1.102677,-98.213943,294.500488,0.000000
89.030006,65.172264,-98.258423,-0.000970,0.004351,0.110528,289.900696,14.768247,1.105279,-98.258423,294.500488,0.000000
89.410004,65.338341,-98.213943,-0.000970,0.004361,0.110762,290.639465,14.805880,1.107621,-98.213943,294.500488,0.000000
89.790001,65.292534,-98.258423,-0.000966,0.004361,0.110762,290.435699,14.795500,1.107621,-98.258423,294.500488,0.000000
90.170006,65.241524,-98.258423,-0.000944,0.004361,0.110762,290.208801,14.783940,1.107621,-98.258423,294.500488,0.000000
90.550003,65.235939,-98.347382,-0.000966,0.004363,0.110823,290.183960,14.782675,1.108228,-98.347382,294.500488,0.000000
90.930008,65.246727,-98.391861,-0.000961,0.004363,0.110831,290.231934,14.785120,1.108315,-98.391861,294.500488,0.000000
91.310005,65.328651,-98.302902,-0.000949,0.004366,0.110901,290.596344,14.803684,1.109008,-98.302902,294.500488,0.000000
91.690002,65.314125,-98.391861,-0.000944,0.004366,0.110901,290.531738,14.800392,1.109008,-98.391861,294.500488,0.000000
92.070007,65.256783,-98.347382,-0.000953,0.004367,0.110909,290.276672,14.787398,1.109095,-98.347382,294.500488,0.000000
92.450005,65.261253,-98.480827,-0.000953,0.004368,0.110936,290.296539,14.788412,1.109355,-98.480827,294.500488,0.000000
92.830002,65.241890,-98.480827,-0.000953,0.004369,0.110970,290.210419,14.784024,1.109702,-98.480827,294.500488,0.000000
93.210007,65.225502,-98.436348,-0.000957,0.004369,0.110970,290.137512,14.780310,1.109702,-98.436348,294.500488,0.000000
93.590004,65.195351,-98.480827,-0.000957,0.004369,0.110970,290.003418,14.773478,1.109702,-98.480827,294.500488,0.000000
93.970001,65.122368,-98.480827,-0.000940,0.004369,0.110970,289.678772,14.756939,1.109702,-98.480827,294.500488,0.000000
94.350006,65.226250,-98.658752,-0.000953,0.004371,0.111031,290.140839,14.780479,1.110309,-98.658752,294.500488,0.000000
94.730003,65.210991,-98.658752,-0.000953,0.004371,0.111031,290.072968,14.777021,1.110309,-98.658752,294.500488,0.000000
95.110008,65.148048,-98.569786,-0.000949,0.004371,0.111031,289.792999,14.762759,1.110309,-98.569786,294.500488,0.000000
95.490005,65.149178,-98.614265,-0.000953,0.004374,0.111100,289.798004,14.763015,1.111003,-98.614265,294.500488,0.000000
95.870003,65.224022,-98.658752,-0.000936,0.004374,0.111100,290.130951,14.779975,1.111003,-98.658752,294.500488,0.000000
96.250008,65.205406,-98.747711,-0.000940,0.004374,0.111100,290.048126,14.775756,1.111003,-98.747711,294.500488,0.000000
96.630005,65.121620,-98.703232,-0.000936,0.004374,0.111109,289.675446,14.756769,1.111089,-98.703232,294.500488,0.000000
97.010002,65.088844,-98.658752,-0.000949,0.004374,0.111109,289.529633,14.749343,1.111089,-98.658752,294.500488,0.000000
97.390007,65.069862,-98.747711,-0.000940,0.004374,0.111109,289.445190,14.745041,1.111089,-98.747711,294.500488,0.000000
97.770004,65.377815,-98.747711,-0.000936,0.004382,0.111291,290.815033,14.814825,1.112911,-98.747711,294.500488,0.000000
98.150002,65.550957,-98.747711,-0.000936,0.004381,0.111274,291.585205,14.854059,1.112737,-98.747711,294.500488,0.000000
98.530006,65.529366,-98.792191,-0.000936,0.004381,0.111274,291.489166,14.849166,1.112737,-98.792191,294.500488,0.000000
98.910004,65.517082,-98.792191,-0.000949,0.004381,0.111274,291.434540,14.846382,1.112737,-98.792191,294.500488,0.000000
99.290001,65.477226,-98.836670,-0.000940,0.004381,0.111274,291.257263,14.837352,1.112737,-98.836670,294.500488,0.000000
99.670006,65.428078,-98.836670,-0.000923,0.004381,0.111274,291.038635,14.826214,1.112737,-98.836670,294.500488,0.000000
100.050003,65.381538,-98.925636,-0.000931,0.004381,0.111274,290.831604,14.815668,1.112737,-98.925636,294.500488,0.000000
100.430008,65.324928,-99.014595,-0.000949,0.004381,0.111274,290.579803,14.802840,1.112737,-99.014595,294.500488,0.000000
100.810005,65.302956,-98.881157,-0.000931,0.004381,0.111274,290.482056,14.797861,1.112737,-98.881157,294.500488,0.000000
101.190002,65.257912,-98.925636,-0.000927,0.004381,0.111282,290.281677,14.787654,1.112824,-98.925636,294.500488,0.000000
101.570007,65.205025,-99.014595,-0.000936,0.004381,0.111282,290.046448,14.775670,1.112824,-99.014595,294.500488,0.000000
101.950005,65.159599,-99.014595,-0.000936,0.004382,0.111291,289.844360,14.765376,1.112911,-99.014595,294.500488,0.000000
102.330002,65.148796,-99.059074,-0.000927,0.004382,0.111308,289.796326,14.762929,1.113084,-99.059074,294.500488,0.000000
102.710007,65.113426,-99.059074,-0.000931,0.004383,0.111317,289.638977,14.754913,1.113171,-99.059074,294.500488,0.000000
103.090004,65.092567,-99.103561,-0.000927,0.004383,0.111317,289.546204,14.750187,1.113171,-99.103561,294.500488,0.000000
103.470001,65.060539,-99.103561,-0.000918,0.004383,0.111317,289.403748,14.742929,1.113171,-99.103561,294.500488,0.000000
103.850006,65.037834,-99.192520,-0.000940,0.004383,0.111317,289.302734,14.737784,1.113171,-99.192520,294.500488,0.000000
104.230003,65.371483,-99.148041,-0.000931,0.004388,0.111465,290.786865,14.813390,1.114645,-99.148041,294.500488,0.000000
104.610008,65.428078,-99.148041,-0.000936,0.004388,0.111456,291.038635,14.826214,1.114558,-99.148041,294.500488,0.000000
104.990005,65.399773,-99.192520,-0.000931,0.004388,0.111456,290.912720,14.819800,1.114558,-99.192520,294.500488,0.000000
105.370003,65.372597,-99.237000,-0.000918,0.004388,0.111456,290.791840,14.813643,1.114558,-99.237000,294.500488,0.000000
105.750008,65.352119,-99.281487,-0.000940,0.004388,0.111456,290.700745,14.809002,1.114558,-99.281487,294.500488,0.000000
106.130005,65.315620,-99.281487,-0.000936,0.004388,0.111456,290.538391,14.800731,1.114558,-99.281487,294.500488,0.000000
106.510002,65.301094,-99.325966,-0.000918,0.004388,0.111456,290.473785,14.797440,1.114558,-99.325966,294.500488,0.000000
106.890007,65.269081,-99.370445,-0.000927,0.004388,0.111456,290.331360,14.790185,1.114558,-99.370445,294.500488,0.000000
107.270004,65.242638,-99.459404,-0.000914,0.004388,0.111456,290.213745,14.784193,1.114558,-99.459404,294.500488,0.000000
107.650002,65.202797,-99.459404,-0.000936,0.004388,0.111456,290.036530,14.775166,1.114558,-99.459404,294.500488,0.000000
108.030006,65.145073,-99.503891,-0.000931,0.004388,0.111465,289.779755,14.762084,1.114645,-99.503891,294.500488,0.000000
108.410004,65.117516,-99.370445,-0.000936,0.004388,0.111465,289.657166,14.755840,1.114645,-99.370445,294.500488,0.000000
108.790009,65.074699,-99.459404,-0.000931,0.004388,0.111465,289.466705,14.746138,1.114645,-99.459404,294.500488,0.000000
109.170006,65.055336,-99.503891,-0.000918,0.004388,0.111465,289.380585,14.741750,1.114645,-99.503891,294.500488,0.000000
109.550003,65.137993,-99.548370,-0.000931,0.004390,0.111517,289.748260,14.760480,1.115166,-99.548370,294.500488,0.000000
109.930008,65.146935,-99.548370,-0.000927,0.004390,0.111517,289.788025,14.762506,1.115166,-99.548370,294.500488,0.000000
110.310005,65.134651,-99.548370,-0.000927,0.004390,0.111517,289.733398,14.759723,1.115166,-99.548370,294.500488,0.000000
110.690002,65.112679,-99.681808,-0.000931,0.004390,0.111517,289.635651,14.754745,1.115166,-99.681808,294.500488,0.000000
111.070007,65.521538,-99.637329,-0.000918,0.004397,0.111681,291.454346,14.847392,1.116813,-99.637329,294.500488,0.000000
111.450005,65.561394,-99.637329,-0.000923,0.004397,0.111673,291.631653,14.856424,1.116727,-99.637329,294.500488,0.000000
111.830002,65.587456,-99.637329,-0.000931,0.004396,0.111655,291.747589,14.862329,1.116553,-99.637329,294.500488,0.000000
112.210007,65.582237,-99.681808,-0.000927,0.004396,0.111655,291.724365,14.861147,1.116553,-99.681808,294.500488,0.000000
112.590004,65.567711,-99.637329,-0.000931,0.004396,0.111655,291.659760,14.857855,1.116553,-99.637329,294.500488,0.000000
112.970009,65.559532,-99.726295,-0.000923,0.004396,0.111655,291.623352,14.856002,1.116553,-99.726295,294.500488,0.000000
113.350006,65.530479,-99.815254,-0.000923,0.004396,0.111655,291.494141,14.849419,1.116553,-99.815254,294.500488,0.000000
113.730003,65.514091,-99.815254,-0.000927,0.004396,0.111655,291.421234,14.845706,1.116553,-99.815254,294.500488,0.000000
114.110008,65.493248,-99.815254,-0.000923,0.004396,0.111655,291.328522,14.840981,1.116553,-99.815254,294.500488,0.000000
114.490005,65.453026,-99.815254,-0.000914,0.004396,0.111655,291.149597,14.831867,1.116553,-99.815254,294.500488,0.000000
114.870003,65.431801,-99.904213,-0.000918,0.004396,0.111655,291.055176,14.827059,1.116553,-99.904213,294.500488,0.000000
115.250008,65.392326,-99.904213,-0.000936,0.004396,0.111655,290.879608,14.818112,1.116553,-99.904213,294.500488,0.000000
115.630005,65.369987,-99.859734,-0.000914,0.004396,0.111655,290.780212,14.813051,1.116553,-99.859734,294.500488,0.000000
116.010002,65.353233,-99.948700,-0.000918,0.004396,0.111655,290.705688,14.809255,1.116553,-99.948700,294.500488,0.000000
116.390007,65.316734,-100.037659,-0.000910,0.004396,0.111655,290.543335,14.800983,1.116553,-100.037659,294.500488,0.000000
116.770004,65.288063,-99.993179,-0.000923,0.004396,0.111655,290.415802,14.794487,1.116553,-99.993179,294.500488,0.000000
117.150009,65.272804,-99.993179,-0.000918,0.004396,0.111655,290.347931,14.791029,1.116553,-99.993179,294.500488,0.000000
117.530006,65.259026,-99.993179,-0.000918,0.004396,0.111655,290.286652,14.787907,1.116553,-99.993179,294.500488,0.000000
117.910004,65.234810,-100.037659,-0.000923,0.004396,0.111655,290.178925,14.782419,1.116553,-100.037659,294.500488,0.000000
118.290009,65.206139,-100.082138,-0.000923,0.004396,0.111655,290.051392,14.775923,1.116553,-100.082138,294.500488,0.000000
118.670006,65.179329,-100.082138,-0.000914,0.004396,0.111655,289.932129,14.769847,1.116553,-100.082138,294.500488,0.000000
119.050003,65.118263,-100.126617,-0.000918,0.004396,0.111664,289.660492,14.756009,1.116640,-100.126617,294.500488,0.000000
119.430008,65.086617,-100.082138,-0.000923,0.004396,0.111664,289.519745,14.748837,1.116640,-100.082138,294.500488,0.000000
119.810005,65.068733,-100.126617,-0.000914,0.004396,0.111664,289.440186,14.744785,1.116640,-100.126617,294.500488,0.000000
120.190002,65.039696,-100.260063,-0.000914,0.004396,0.111664,289.311005,14.738206,1.116640,-100.260063,294.500488,0.000000
120.570007,65.028145,-100.171104,-0.000927,0.004396,0.111664,289.259644,14.735588,1.116640,-100.171104,294.500488,0.000000
120.950005,65.305565,-100.215584,-0.000918,0.004401,0.111794,290.493652,14.798452,1.117941,-100.215584,294.500488,0.000000
121.330009,65.336845,-100.215584,-0.000918,0.004401,0.111794,290.632812,14.805541,1.117941,-100.215584,294.500488,0.000000
121.710007,65.349510,-100.304543,-0.000910,0.004401,0.111794,290.689148,14.808411,1.117941,-100.304543,294.500488,0.000000
122.090004,65.351738,-100.304543,-0.000914,0.004401,0.111794,290.699036,14.808915,1.117941,-100.304543,294.500488,0.000000
122.470009,65.342064,-100.304543,-0.000918,0.004401,0.111794,290.656006,14.806724,1.117941,-100.304543,294.500488,0.000000
122.850006,65.349510,-100.304543,-0.000923,0.004401,0.111794,290.689148,14.808411,1.117941,-100.304543,294.500488,0.000000
123.230003,65.333488,-100.304543,-0.000927,0.004401,0.111794,290.617859,14.804780,1.117941,-100.304543,294.500488,0.000000
123.610008,65.320839,-100.393509,-0.000927,0.004401,0.111794,290.561615,14.801914,1.117941,-100.393509,294.500488,0.000000
123.990005,65.307808,-100.437988,-0.000927,0.004401,0.111794,290.503632,14.798961,1.117941,-100.437988,294.500488,0.000000
124.370003,65.285088,-100.437988,-0.000914,0.004401,0.111794,290.402588,14.793813,1.117941,-100.437988,294.500488,0.000000
124.750008,65.285454,-100.482468,-0.000927,0.004401,0.111794,290.404205,14.793895,1.117941,-100.482468,294.500488,0.000000
125.130005,65.258278,-100.437988,-0.000910,0.004401,0.111794,290.283325,14.787737,1.117941,-100.437988,294.500488,0.000000
125.510010,65.237801,-100.482468,-0.000910,0.004401,0.111794,290.192230,14.783097,1.117941,-100.482468,294.500488,0.000000
125.890007,65.230354,-100.571434,-0.000914,0.004401,0.111794,290.159119,14.781409,1.117941,-100.571434,294.500488,0.000000
126.270004,65.201683,-100.526947,-0.000910,0.004401,0.111794,290.031586,14.774913,1.117941,-100.526947,294.500488,0.000000
126.650009,65.203163,-100.482468,-0.000923,0.004401,0.111794,290.038147,14.775248,1.117941,-100.482468,294.500488,0.000000
127.030006,65.164436,-100.615913,-0.000910,0.004401,0.111794,289.865875,14.766473,1.117941,-100.615913,294.500488,0.000000
127.410004,65.142464,-100.660393,-0.000923,0.004401,0.111794,289.768158,14.761494,1.117941,-100.660393,294.500488,0.000000
127.790009,65.122734,-100.660393,-0.000923,0.004401,0.111794,289.680389,14.757022,1.117941,-100.660393,294.500488,0.000000
128.170013,65.089958,-100.615913,-0.000905,0.004401,0.111794,289.534607,14.749595,1.117941,-100.615913,294.500488,0.000000
128.550003,65.078041,-100.660393,-0.000927,0.004401,0.111794,289.481598,14.746895,1.117941,-100.660393,294.500488,0.000000
128.930008,65.448936,-100.704872,-0.000910,0.004410,0.112011,291.131409,14.830941,1.120109,-100.704872,294.500488,0.000000
129.310013,65.585594,-100.704872,-0.000918,0.004409,0.111985,291.739288,14.861908,1.119848,-100.704872,294.500488,0.000000
129.690002,65.606438,-100.793839,-0.000905,0.004409,0.111985,291.832001,14.866632,1.119848,-100.793839,294.500488,0.000000
130.070007,65.598991,-100.749352,-0.000923,0.004409,0.111985,291.798889,14.864944,1.119848,-100.749352,294.500488,0.000000
130.450012,65.620598,-100.749352,-0.000910,0.004409,0.111985,291.894989,14.869841,1.119848,-100.749352,294.500488,0.000000
130.830002,65.602715,-100.882797,-0.000918,0.004409,0.111985,291.815460,14.865788,1.119848,-100.882797,294.500488,0.000000
131.210007,65.602715,-100.882797,-0.000927,0.004409,0.111985,291.815460,14.865788,1.119848,-100.882797,294.500488,0.000000
131.590012,65.604210,-100.882797,-0.000918,0.004409,0.111985,291.822113,14.866126,1.119848,-100.882797,294.500488,0.000000
131.970001,65.577034,-100.838318,-0.000905,0.004409,0.111985,291.701202,14.859968,1.119848,-100.838318,294.500488,0.000000
132.350006,65.575905,-100.971756,-0.000905,0.004409,0.111985,291.696198,14.859713,1.119848,-100.971756,294.500488,0.000000
132.730011,65.575172,-101.016243,-0.000914,0.004409,0.111985,291.692932,14.859547,1.119848,-101.016243,294.500488,0.000000
133.110001,65.565849,-100.971756,-0.000901,0.004409,0.111985,291.651459,14.857434,1.119848,-100.971756,294.500488,0.000000
133.490005,65.555809,-101.016243,-0.000892,0.004409,0.111985,291.606812,14.855159,1.119848,-101.016243,294.500488,0.000000
133.870010,65.534203,-100.971756,-0.000910,0.004409,0.111985,291.510681,14.850263,1.119848,-100.971756,294.500488,0.000000
134.250000,65.517815,-101.060722,-0.000905,0.004409,0.111985,291.437805,14.846549,1.119848,-101.060722,294.500488,0.000000
134.630005,65.511864,-101.105202,-0.000910,0.004409,0.111985,291.411316,14.845201,1.119848,-101.105202,294.500488,0.000000
135.010010,65.483559,-101.016243,-0.000914,0.004409,0.111985,291.285431,14.838787,1.119848,-101.016243,294.500488,0.000000
135.389999,65.470161,-101.060722,-0.000910,0.004409,0.111985,291.225830,14.835751,1.119848,-101.060722,294.500488,0.000000
135.770004,65.444084,-101.105202,-0.000918,0.004409,0.111985,291.109833,14.829841,1.119848,-101.105202,294.500488,0.000000
136.150009,65.440742,-101.194160,-0.000918,0.004409,0.111985,291.094971,14.829084,1.119848,-101.194160,294.500488,0.000000
136.530014,65.410576,-101.194160,-0.000901,0.004409,0.111985,290.960785,14.822248,1.119848,-101.194160,294.500488,0.000000
136.910004,65.389351,-101.194160,-0.000910,0.004409,0.111985,290.866364,14.817439,1.119848,-101.194160,294.500488,0.000000
137.290009,65.360680,-101.194160,-0.000905,0.004409,0.111985,290.738831,14.810942,1.119848,-101.194160,294.500488,0.000000
137.670013,65.359566,-101.238647,-0.000910,0.004409,0.111985,290.733856,14.810689,1.119848,-101.238647,1681.640991,0.000000
138.050003,65.381538,-101.283127,-0.000910,0.004404,0.111872,290.831604,14.815668,1.118721,-101.283127,0.111716,0.000000
138.430008,65.374077,-101.372086,-0.000914,0.004386,0.111404,290.798431,14.813977,1.114038,-101.372086,0.111083,0.000000
138.810013,65.197578,-101.283127,-0.000905,0.004367,0.110909,290.013306,14.773982,1.109095,-101.283127,0.110450,0.000000
139.190002,65.174126,-101.327606,-0.000897,0.004344,0.110346,289.908997,14.768668,1.103458,-101.327606,0.109817,0.000000
139.570007,65.148430,-101.327606,-0.000910,0.004317,0.109643,289.794678,14.762845,1.096433,-101.327606,0.109184,0.000000
139.950012,65.121620,-101.416565,-0.000905,0.004294,0.109071,289.675446,14.756769,1.090710,-101.416565,0.108551,0.000000
140.330002,65.124229,-101.372086,-0.000914,0.004270,0.108464,289.687042,14.757361,1.084639,-101.372086,0.107918,0.000000
140.710007,65.095924,-101.461052,-0.000901,0.004243,0.107770,289.561127,14.750948,1.077701,-101.461052,0.107284,0.000000
141.090012,65.043419,-101.416565,-0.000905,0.004223,0.107276,289.327576,14.739050,1.072758,-101.416565,0.106651,0.000000
141.470001,65.043053,-101.461052,-0.000892,0.004199,0.106660,289.325958,14.738967,1.066601,-101.461052,0.106018,0.000000
141.850006,64.792809,-101.550011,-0.000901,0.004175,0.106036,288.212799,14.682261,1.060357,-101.550011,0.105385,0.000000
142.230011,64.274467,-101.505531,-0.000901,0.004154,0.105524,285.907104,14.564802,1.055240,-101.505531,0.104752,0.000000
142.610001,63.314125,-101.550011,-0.000892,0.004127,0.104830,281.635284,14.347186,1.048302,-101.550011,0.104119,0.000000
142.990005,62.219719,-101.505531,-0.000901,0.004107,0.104319,276.767120,14.099191,1.043186,-101.505531,0.103486,0.000000
143.370010,61.074669,-101.638969,-0.000892,0.004082,0.103686,271.673706,13.839718,1.036855,-101.638969,0.102853,0.000000
143.750000,59.320427,-101.550011,-0.000905,0.004060,0.103130,263.870453,13.442201,1.031305,-101.550011,0.102220,0.000000
144.130005,57.446648,-101.638969,-0.000901,0.004037,0.102549,255.535446,13.017596,1.025494,-101.638969,0.101587,0.000000
144.510010,55.604523,-101.638969,-0.000884,0.004014,0.101951,247.341263,12.600164,1.019511,-101.638969,0.100954,0.000000
144.889999,52.839279,-101.683456,-0.000901,0.003983,0.101179,235.040848,11.973552,1.011792,-101.683456,0.100321,0.000000
145.270004,50.942421,-101.727936,-0.000905,0.003967,0.100754,226.603210,11.543718,1.007543,-101.727936,0.099688,0.000000
145.650009,48.266174,-101.772415,-0.000905,0.003937,0.100000,214.698669,10.937271,0.999998,-101.772415,0.099055,0.000000
146.030014,46.113495,-101.727936,-0.000897,0.003917,0.099479,205.123077,10.449467,0.994795,-101.727936,0.098413,0.000000
146.410004,43.204887,-101.727936,-0.000888,0.003890,0.098794,192.184937,9.790367,0.987944,-101.727936,0.097780,0.000000
146.790009,40.177872,-101.816895,-0.000901,0.003864,0.098135,178.720093,9.104436,0.981353,-101.816895,0.097147,0.000000
147.170013,38.186424,-101.905861,-0.000884,0.003843,0.097615,169.861694,8.653168,0.976149,-101.905861,0.096514,0.000000
147.550003,35.514656,-101.861382,-0.000918,0.003820,0.097034,157.977081,8.047736,0.970339,-101.861382,0.095880,0.000000
147.930008,32.614990,-101.816895,-0.000905,0.003792,0.096305,145.078720,7.390663,0.963054,-101.816895,0.095247,0.000000
148.310013,30.769142,-101.861382,-0.000918,0.003772,0.095811,136.867981,6.972387,0.958111,-101.861382,0.094614,0.000000
148.690002,27.308311,-101.861382,-0.000923,0.003740,0.095005,121.473434,6.188152,0.950046,-101.861382,0.093981,0.000000
149.070007,25.262871,-101.950340,-0.000910,0.003724,0.094580,112.374863,5.724648,0.945796,-101.950340,0.093348,0.000000
149.450012,22.233246,-101.950340,-0.000940,0.003694,0.093825,98.898415,5.038126,0.938251,-101.950340,0.092715,0.000000
149.830002,19.145905,-102.039299,-0.000940,0.003667,0.093149,85.165237,4.338524,0.931487,-102.039299,0.092082,0.000000
150.210007,16.729210,-102.039299,-0.000944,0.003643,0.092524,74.415245,3.790893,0.925243,-102.039299,0.091449,0.000000
150.590012,13.383072,-102.039299,-0.000949,0.003614,0.091805,59.530876,3.032647,0.918045,-102.039299,0.090816,0.000000
150.970001,11.098190,-102.083786,-0.000944,0.003595,0.091310,49.367214,2.514886,0.913102,-102.083786,0.090183,0.000000
151.350006,8.130386,-102.083786,-0.000957,0.003563,0.090504,36.165764,1.842372,0.905037,-102.083786,0.089550,0.000000
151.730011,5.816460,-102.128265,-0.000970,0.003546,0.090061,25.872904,1.318029,0.900614,-102.128265,0.088917,0.000000
152.110001,3.597122,-102.083786,-0.000979,0.003523,0.089489,16.000799,0.815120,0.894890,-102.083786,0.088284,0.000000
152.490005,0.162727,-102.217224,-0.000987,0.003487,0.088578,0.723847,0.036875,0.885784,-102.217224,0.087651,0.000000
152.870010,-1.404957,-102.172745,-0.000992,0.003467,0.088058,-6.249560,-0.318368,0.880581,-102.172745,0.087017,0.000000
153.250000,-0.122505,-102.217224,-0.001043,0.003444,0.087486,-0.544930,-0.027760,0.874857,-102.217224,0.086384,0.000000
153.630005,0.021225,-102.128265,-0.001065,0.003414,0.086705,0.094413,0.004810,0.867052,-102.128265,0.085751,0.000000
154.010010,0.014153,-102.217224,-0.001108,0.003391,0.086124,0.062954,0.003207,0.861242,-102.217224,0.085118,0.000000
154.390015,0.057724,-102.306190,-0.001164,0.003359,0.085309,0.256769,0.013080,0.853090,-102.306190,0.084485,0.000000
154.770004,0.067032,-102.306190,-0.001194,0.003342,0.084875,0.298173,0.015190,0.848754,-102.306190,0.083852,0.000000
155.150009,0.066658,-102.306190,-0.001237,0.003312,0.084130,0.296510,0.015105,0.841296,-102.306190,0.083219,0.000000
155.530014,0.048409,-102.261703,-0.001289,0.003290,0.083575,0.215332,0.010970,0.835745,-102.261703,0.082586,0.000000
155.800003,0.086395,-102.350670,-0.001302,0.003277,0.083245,0.384305,0.019577,0.832450,-102.350670,0.083124,0.000000