File: Data/compression 34/AutoNoHeating-17-34-reverse-1-2_11152024_203412.csv
Time (sec),S:Load (lbs),S:HL1 (DIM),S:LVDT (in),S:Position (in),Ch:Position (mm),Ch:Load (N),Ch:Stress (MPa),Ch:Strain (mm/mm),Ch:HL1 (DIM),Set Point (),Cycles ()
0.110000,-0.049149,-152.525177,-0.010292,-0.005764,-0.146396,-0.218624,-0.011137,-1.463964,-152.525177,-0.146500,0.000000
0.460000,-0.064415,-152.525177,-0.010287,-0.005743,-0.145885,-0.286532,-0.014597,-1.458847,-152.525177,-0.145148,0.000000
0.810000,-0.035004,-152.525177,-0.010214,-0.005536,-0.140621,-0.155704,-0.007932,-1.406206,-152.525177,-0.139320,0.000000
1.160000,-0.004837,-152.525177,-0.009977,-0.005305,-0.134758,-0.021516,-0.001096,-1.347582,-152.525177,-0.133492,0.000000
1.510000,-0.044685,-152.525177,-0.009748,-0.005082,-0.129095,-0.198770,-0.010126,-1.290952,-152.525177,-0.127664,0.000000
1.860000,-0.071869,-152.569656,-0.009494,-0.004850,-0.123189,-0.319689,-0.016286,-1.231894,-152.569656,-0.121819,0.000000
2.210000,-0.129959,-152.569656,-0.009278,-0.004618,-0.117292,-0.578087,-0.029449,-1.172923,-152.569656,-0.115991,0.000000
2.560000,-0.080803,-152.614136,-0.009028,-0.004388,-0.111447,-0.359429,-0.018310,-1.114472,-152.614136,-0.110164,0.000000
2.910000,-0.024574,-152.614136,-0.008778,-0.004157,-0.105576,-0.109312,-0.005569,-1.055761,-152.614136,-0.104336,0.000000
3.260000,-0.015266,-152.658630,-0.008558,-0.003930,-0.099826,-0.067908,-0.003459,-0.998264,-152.658630,-0.098508,0.000000
3.610000,-0.033882,-152.658630,-0.008351,-0.003707,-0.094163,-0.150715,-0.007678,-0.941634,-152.658630,-0.092663,0.000000
3.960000,-0.063301,-152.658630,-0.008080,-0.003472,-0.088188,-0.281577,-0.014344,-0.881882,-152.658630,-0.086835,0.000000
4.310000,-0.077454,-152.614136,-0.007851,-0.003239,-0.082265,-0.344531,-0.017551,-0.822650,-152.614136,-0.081008,0.000000
4.660000,-0.056969,-152.703110,-0.007606,-0.003010,-0.076446,-0.253409,-0.012909,-0.764459,-152.703110,-0.075180,0.000000
5.010000,-0.034256,-152.747589,-0.007399,-0.002788,-0.070809,-0.152378,-0.007763,-0.708090,-152.747589,-0.069352,0.000000
5.360000,-0.044312,-152.703110,-0.007131,-0.002553,-0.064842,-0.197107,-0.010041,-0.648425,-152.703110,-0.063524,0.000000
5.710000,-0.023827,-152.792068,-0.006924,-0.002326,-0.059075,-0.105986,-0.005399,-0.590754,-152.792068,-0.057679,0.000000
6.060000,-0.036491,-152.792068,-0.006670,-0.002098,-0.053282,-0.162322,-0.008269,-0.532823,-152.792068,-0.051851,0.000000
6.410000,-0.059952,-152.792068,-0.006428,-0.001861,-0.047272,-0.266679,-0.013585,-0.472725,-152.792068,-0.046024,0.000000
6.760000,-0.064049,-152.792068,-0.006213,-0.001637,-0.041592,-0.284903,-0.014514,-0.415921,-152.792068,-0.040196,0.000000
7.110000,-0.047287,-152.747589,-0.005971,-0.001415,-0.035929,-0.210343,-0.010715,-0.359292,-152.747589,-0.034368,0.000000
7.460001,-0.058090,-152.836548,-0.005721,-0.001176,-0.029867,-0.258398,-0.013163,-0.298672,-152.836548,-0.028523,0.000000
7.810000,0.001495,-152.836548,-0.005493,-0.000950,-0.024126,0.006652,0.000339,-0.241262,-152.836548,-0.022695,0.000000
8.160001,-0.039467,-152.881027,-0.005269,-0.000715,-0.018168,-0.175557,-0.008943,-0.181684,-152.881027,-0.016868,0.000000
8.510000,-0.019363,-152.881027,-0.005027,-0.000487,-0.012367,-0.086133,-0.004388,-0.123666,-152.881027,-0.011040,0.000000
8.860001,-0.077454,-152.881027,-0.004794,-0.000268,-0.006799,-0.344531,-0.017551,-0.067991,-152.881027,-0.005212,0.000000
9.210000,0.177994,-152.925507,-0.004712,-0.000003,-0.000069,0.791756,0.040334,-0.000694,-152.925507,0.000078,0.000000
9.560000,0.125122,-152.925507,-0.004691,-0.000003,-0.000078,0.556571,0.028353,-0.000781,-152.925507,0.000182,0.000000
9.910001,0.120277,-152.925507,-0.004695,-0.000002,-0.000052,0.535021,0.027255,-0.000520,-152.925507,0.000763,0.000000
10.260000,0.124001,-152.925507,-0.004682,0.000010,0.000243,0.551582,0.028099,0.002428,-152.925507,0.001344,0.000000
10.610001,0.232361,-153.058960,-0.004669,0.000027,0.000676,1.033593,0.052654,0.006764,-153.058960,0.001925,0.000000
10.960001,0.465843,-152.969986,-0.004639,0.000053,0.001353,2.072174,0.105562,0.013529,-152.969986,0.002515,0.000000
11.310000,0.687775,-152.925507,-0.004626,0.000081,0.002055,3.059375,0.155852,0.020553,-152.925507,0.003096,0.000000
11.660001,0.864281,-153.058960,-0.004592,0.000097,0.002463,3.844512,0.195849,0.024629,-153.058960,0.003677,0.000000
12.010000,1.087334,-153.058960,-0.004592,0.000120,0.003053,4.836702,0.246393,0.030526,-153.058960,0.004258,0.000000
12.360001,1.337563,-153.058960,-0.004566,0.000141,0.003573,5.949775,0.303096,0.035730,-153.058960,0.004848,0.000000
12.710001,1.570671,-153.103439,-0.004544,0.000159,0.004041,6.986694,0.355919,0.040413,-153.103439,0.005429,0.000000
13.060000,2.175400,-153.103439,-0.004506,0.000192,0.004882,9.676661,0.492953,0.048825,-153.103439,0.006010,0.000000
13.410001,2.558571,-153.103439,-0.004475,0.000218,0.005533,11.381092,0.579780,0.055329,-153.103439,0.006600,0.000000
13.760000,2.953659,-153.147919,-0.004480,0.000237,0.006019,13.138532,0.669309,0.060185,-153.147919,0.007181,0.000000
14.110001,3.504028,-153.103439,-0.004441,0.000264,0.006712,15.586697,0.794024,0.067123,-153.103439,0.007762,0.000000
14.460001,3.729309,-153.147919,-0.004428,0.000282,0.007155,16.588795,0.845074,0.071546,-153.147919,0.008343,0.000000
14.810000,4.103172,-153.192398,-0.004432,0.000299,0.007588,18.251822,0.929792,0.075882,-153.192398,0.008932,0.000000
15.160001,4.987556,-153.192398,-0.004385,0.000331,0.008412,22.185759,1.130196,0.084121,-153.192398,0.009513,0.000000
15.510001,5.538300,-153.192398,-0.004385,0.000356,0.009036,24.635588,1.254997,0.090365,-153.192398,0.010095,0.000000
15.860001,5.821671,-153.281357,-0.004359,0.000378,0.009600,25.896084,1.319209,0.096002,-153.281357,0.010676,0.000000
16.210001,6.255112,-153.236877,-0.004342,0.000395,0.010034,27.824127,1.417429,0.100338,-153.236877,0.011265,0.000000
16.560001,6.882187,-153.236877,-0.004312,0.000422,0.010719,30.613497,1.559526,0.107189,-153.236877,0.011846,0.000000
16.910002,7.362175,-153.281357,-0.004294,0.000449,0.011404,32.748589,1.668293,0.114040,-153.281357,0.012427,0.000000
17.260000,7.774391,-153.325836,-0.004277,0.000468,0.011898,34.582218,1.761702,0.118983,-153.325836,0.013008,0.000000
17.610001,7.916641,-153.325836,-0.004255,0.000485,0.012323,35.214977,1.793937,0.123233,-153.325836,0.013598,0.000000
17.960001,8.612602,-153.325836,-0.004234,0.000506,0.012861,38.310768,1.951644,0.128610,-153.325836,0.014179,0.000000
18.310001,8.974182,-153.325836,-0.004221,0.000530,0.013468,39.919155,2.033579,0.134680,-153.325836,0.014760,0.000000
18.660002,9.543533,-153.370316,-0.004195,0.000557,0.014153,42.451756,2.162596,0.141531,-153.370316,0.015350,0.000000
19.010000,10.179550,-153.370316,-0.004178,0.000588,0.014934,45.280899,2.306719,0.149336,-153.370316,0.015931,0.000000
19.360001,10.179924,-153.325836,-0.004152,0.000602,0.015281,45.282562,2.306804,0.152805,-153.325836,0.016512,0.000000
19.710001,10.419357,-153.414795,-0.004143,0.000619,0.015731,46.347614,2.361060,0.157315,-153.414795,0.017093,0.000000
20.060001,11.087021,-153.414795,-0.004122,0.000648,0.016451,49.317532,2.512355,0.164513,-153.414795,0.017683,0.000000
20.410002,10.911263,-153.414795,-0.004100,0.000658,0.016711,48.535721,2.472527,0.167114,-153.414795,0.018264,0.000000
20.760000,12.029121,-153.459274,-0.004070,0.000701,0.017795,53.508205,2.725838,0.177955,-153.459274,0.018845,0.000000
21.110001,12.130409,-153.503769,-0.004044,0.000720,0.018298,53.958755,2.748790,0.182985,-153.503769,0.019426,0.000000
21.460001,12.572784,-153.459274,-0.004036,0.000746,0.018940,55.926537,2.849034,0.189402,-153.459274,0.020016,0.000000
21.810001,12.658058,-153.548248,-0.004014,0.000762,0.019365,56.305855,2.868357,0.193651,-153.548248,0.020597,0.000000
22.160002,12.898987,-153.548248,-0.003992,0.000783,0.019894,57.377560,2.922952,0.198942,-153.548248,0.021178,0.000000
22.510000,13.147354,-153.548248,-0.003975,0.000804,0.020432,58.482353,2.979233,0.204318,-153.548248,0.021767,0.000000
22.860001,14.079033,-153.548248,-0.003962,0.000838,0.021273,62.626667,3.190355,0.212730,-153.548248,0.022348,0.000000
23.210001,14.335228,-153.592728,-0.003928,0.000857,0.021759,63.766277,3.248409,0.217587,-153.592728,0.022929,0.000000
23.560001,14.347511,-153.637207,-0.003919,0.000873,0.022166,63.820919,3.251193,0.221663,-153.637207,0.023510,0.000000
23.910002,15.115715,-153.637207,-0.003893,0.000903,0.022947,67.238060,3.425270,0.229468,-153.637207,0.024100,0.000000
24.260000,15.085182,-153.637207,-0.003880,0.000920,0.023363,67.102242,3.418351,0.233631,-153.637207,0.024681,0.000000
24.610001,15.370422,-153.637207,-0.003846,0.000941,0.023892,68.371056,3.482988,0.238921,-153.637207,0.025262,0.000000
24.960001,16.104370,-153.637207,-0.003833,0.000973,0.024725,71.635818,3.649302,0.247246,-153.637207,0.025843,0.000000
25.310001,16.327415,-153.637207,-0.003807,0.000997,0.025314,72.627968,3.699845,0.253143,-153.637207,0.026433,0.000000
25.660002,16.399284,-153.726166,-0.003786,0.001015,0.025774,72.947662,3.716131,0.257739,-153.726166,0.027014,0.000000
26.010002,16.489029,-153.681686,-0.003790,0.001035,0.026294,73.346863,3.736467,0.262943,-153.681686,0.027595,0.000000
26.360001,17.241966,-153.681686,-0.003760,0.001061,0.026962,76.696098,3.907085,0.269620,-153.681686,0.028176,0.000000
26.710001,17.777435,-153.770645,-0.003729,0.001091,0.027717,79.077980,4.028424,0.277165,-153.770645,0.028766,0.000000
27.060001,17.946495,-153.770645,-0.003712,0.001112,0.028254,79.829994,4.066734,0.282542,-153.770645,0.029347,0.000000
27.410002,18.193375,-153.726166,-0.003695,0.001139,0.028931,80.928169,4.122678,0.289306,-153.726166,0.029928,0.000000
27.760002,18.143105,-153.815125,-0.003686,0.001157,0.029382,80.704559,4.111286,0.293816,-153.815125,0.030518,0.000000
28.110001,18.326317,-153.815125,-0.003665,0.001174,0.029824,81.519531,4.152802,0.298239,-153.815125,0.031099,0.000000
28.460001,19.274376,-153.815125,-0.003648,0.001206,0.030622,85.736710,4.367636,0.306217,-153.815125,0.031680,0.000000
28.810001,19.299324,-153.904083,-0.003617,0.001228,0.031194,85.847679,4.373290,0.311941,-153.904083,0.032261,0.000000
29.160002,19.221870,-153.904083,-0.003600,0.001246,0.031654,85.503151,4.355738,0.316537,-153.904083,0.032851,0.000000
29.510002,19.580833,-153.815125,-0.003579,0.001272,0.032304,87.099899,4.437080,0.323042,-153.815125,0.033432,0.000000
29.860001,19.338425,-153.904083,-0.003561,0.001287,0.032686,86.021606,4.382150,0.326857,-153.904083,0.034013,0.000000
30.210001,19.392044,-153.948578,-0.003540,0.001304,0.033111,86.260117,4.394300,0.331107,-153.948578,0.034594,0.000000
30.560001,20.624969,-153.948578,-0.003510,0.001342,0.034099,91.744446,4.673685,0.340993,-153.948578,0.035183,0.000000
30.910002,20.568741,-153.993057,-0.003505,0.001366,0.034689,91.494331,4.660943,0.346890,-153.993057,0.035764,0.000000
31.260002,20.699440,-154.037537,-0.003479,0.001388,0.035261,92.075706,4.690560,0.352614,-154.037537,0.036345,0.000000
31.610001,20.912811,-153.993057,-0.003471,0.001411,0.035842,93.024834,4.738911,0.358424,-153.993057,0.036935,0.000000
31.960001,20.525169,-153.993057,-0.003454,0.001426,0.036233,91.300514,4.651070,0.362327,-153.993057,0.037516,0.000000
32.310001,20.839828,-154.037537,-0.003436,0.001446,0.036727,92.700188,4.722373,0.367270,-154.037537,0.038097,0.000000
32.660000,21.856407,-154.126495,-0.003406,0.001482,0.037655,97.222153,4.952733,0.376549,-154.126495,0.038678,0.000000
33.010002,21.413284,-154.082016,-0.003402,0.001496,0.037993,95.251045,4.852320,0.379932,-154.082016,0.039268,0.000000
33.360001,21.618828,-154.082016,-0.003385,0.001519,0.038583,96.165352,4.898897,0.385829,-154.082016,0.039849,0.000000
33.710003,21.864227,-154.082016,-0.003359,0.001539,0.039103,97.256943,4.954505,0.391032,-154.082016,0.040430,0.000000
34.060001,21.971092,-154.082016,-0.003346,0.001563,0.039693,97.732300,4.978721,0.396929,-154.082016,0.041011,0.000000
34.410000,23.012993,-154.126495,-0.003316,0.001594,0.040491,102.366905,5.214819,0.404908,-154.126495,0.041601,0.000000
34.760002,22.989906,-154.215454,-0.003290,0.001617,0.041080,102.264214,5.209587,0.410805,-154.215454,0.042182,0.000000
35.110001,22.775421,-154.215454,-0.003277,0.001635,0.041540,101.310135,5.160985,0.415401,-154.215454,0.042763,0.000000
35.460003,23.063637,-154.215454,-0.003255,0.001661,0.042182,102.592178,5.226295,0.421819,-154.215454,0.043344,0.000000
35.810001,22.955276,-154.259933,-0.003234,0.001683,0.042746,102.110168,5.201740,0.427456,-154.259933,0.043934,0.000000
36.160000,22.723289,-154.259933,-0.003234,0.001695,0.043049,101.078239,5.149171,0.430491,-154.259933,0.044515,0.000000
36.510002,23.976318,-154.259933,-0.003199,0.001733,0.044029,106.651993,5.433111,0.440290,-154.259933,0.045096,0.000000
36.860001,23.994194,-154.259933,-0.003186,0.001754,0.044558,106.731506,5.437162,0.445581,-154.259933,0.045685,0.000000
37.210003,24.128990,-154.304413,-0.003160,0.001777,0.045130,107.331108,5.467707,0.451304,-154.304413,0.046266,0.000000
37.560001,23.906685,-154.304413,-0.003156,0.001794,0.045555,106.342247,5.417332,0.455554,-154.304413,0.046848,0.000000
37.910004,24.425774,-154.348907,-0.003139,0.001820,0.046240,108.651268,5.534960,0.462405,-154.348907,0.047429,0.000000
38.260002,24.701332,-154.304413,-0.003113,0.001848,0.046943,109.877014,5.597402,0.469429,-154.304413,0.048018,0.000000
38.610001,24.775429,-154.348907,-0.003104,0.001868,0.047446,110.206612,5.614192,0.474459,-154.348907,0.048599,0.000000
38.960003,24.558708,-154.348907,-0.003074,0.001885,0.047871,109.242592,5.565083,0.478709,-154.348907,0.049180,0.000000
39.310001,25.023430,-154.393387,-0.003070,0.001909,0.048478,111.309776,5.670390,0.484779,-154.393387,0.049761,0.000000
39.660004,25.011147,-154.437866,-0.003044,0.001929,0.048990,111.255135,5.667607,0.489896,-154.437866,0.050351,0.000000
40.010002,25.432297,-154.348907,-0.003035,0.001955,0.049666,113.128510,5.763041,0.496660,-154.348907,0.050932,0.000000
40.360001,26.163635,-154.482346,-0.003014,0.001986,0.050455,116.381660,5.928764,0.504552,-154.482346,0.051513,0.000000
40.710003,25.686630,-154.437866,-0.003014,0.002001,0.050828,114.259834,5.820673,0.508281,-154.437866,0.052103,0.000000
41.060001,25.602470,-154.437866,-0.002975,0.002023,0.051374,113.885475,5.801602,0.513744,-154.437866,0.052684,0.000000
41.410004,26.096237,-154.571304,-0.002958,0.002050,0.052060,116.081863,5.913492,0.520596,-154.571304,0.053265,0.000000
41.760002,26.441055,-154.526825,-0.002949,0.002072,0.052623,117.615685,5.991629,0.526233,-154.526825,0.053846,0.000000
42.110001,27.276283,-154.482346,-0.002915,0.002100,0.053343,121.330971,6.180894,0.533431,-154.482346,0.054436,0.000000
42.460003,27.208511,-154.571304,-0.002902,0.002121,0.053881,121.029503,6.165536,0.538807,-154.571304,0.055017,0.000000
42.810001,27.425980,-154.571304,-0.002906,0.002145,0.054470,121.996849,6.214816,0.544704,-154.571304,0.055598,0.000000
43.160004,27.474388,-154.615784,-0.002859,0.002171,0.055147,122.212181,6.225785,0.551469,-154.615784,0.056179,0.000000
43.510002,27.167549,-154.615784,-0.002850,0.002182,0.055416,120.847298,6.156254,0.554157,-154.615784,0.056769,0.000000
43.860001,27.583862,-154.615784,-0.002837,0.002209,0.056101,122.699150,6.250593,0.561008,-154.615784,0.057350,0.000000
44.210003,28.427658,-154.571304,-0.002820,0.002238,0.056847,126.452538,6.441800,0.568466,-154.571304,0.057931,0.000000
44.560001,28.847328,-154.660263,-0.002807,0.002258,0.057341,128.319321,6.536898,0.573410,-154.660263,0.058512,0.000000
44.910004,28.318184,-154.660263,-0.002794,0.002272,0.057714,125.965576,6.416992,0.577139,-154.660263,0.059101,0.000000
45.260002,29.183205,-154.660263,-0.002772,0.002304,0.058520,129.813385,6.613009,0.585204,-154.660263,0.059682,0.000000
45.610001,29.668777,-154.704742,-0.002734,0.002329,0.059145,131.973312,6.723041,0.591448,-154.704742,0.060264,0.000000
45.960003,29.365669,-154.749222,-0.002738,0.002345,0.059561,130.625015,6.654356,0.595611,-154.749222,0.060853,0.000000
46.310001,30.384476,-154.749222,-0.002695,0.002373,0.060272,135.156891,6.885221,0.602722,-154.749222,0.061434,0.000000
46.660004,30.950859,-154.793716,-0.002695,0.002400,0.060949,137.676300,7.013565,0.609486,-154.793716,0.062015,0.000000
47.010002,30.806374,-154.793716,-0.002673,0.002417,0.061400,137.033600,6.980824,0.613996,-154.793716,0.062596,0.000000
47.360001,30.745682,-154.838196,-0.002660,0.002435,0.061842,136.763626,6.967071,0.618419,-154.838196,0.063186,0.000000
47.710003,31.550377,-154.793716,-0.002652,0.002460,0.062484,140.343079,7.149418,0.624836,-154.793716,0.063767,0.000000
48.060001,32.596001,-154.882675,-0.002630,0.002491,0.063273,144.994247,7.386359,0.632728,-154.882675,0.064348,0.000000
48.410004,32.920708,-154.793716,-0.002608,0.002514,0.063862,146.438629,7.459939,0.638625,-154.793716,0.064929,0.000000
48.760002,33.438309,-154.882675,-0.002591,0.002538,0.064470,148.741028,7.577229,0.644696,-154.882675,0.065519,0.000000
49.110001,33.235359,-154.882675,-0.002578,0.002555,0.064903,147.838257,7.531240,0.649032,-154.882675,0.066100,0.000000
49.460003,33.366806,-154.927155,-0.002552,0.002574,0.065380,148.422974,7.561026,0.653801,-154.927155,0.066681,0.000000
49.810001,34.740868,-154.927155,-0.002548,0.002606,0.066204,154.535095,7.872393,0.662040,-154.927155,0.067262,0.000000
50.160004,34.925186,-154.927155,-0.002522,0.002628,0.066742,155.354980,7.914160,0.667417,-154.927155,0.067852,0.000000
50.510002,35.182129,-154.971634,-0.002505,0.002650,0.067305,156.497925,7.972384,0.673054,-154.971634,0.068433,0.000000
50.860001,35.568649,-155.016113,-0.002501,0.002670,0.067826,158.217255,8.059972,0.678257,-155.016113,0.069014,0.000000
51.210003,35.405922,-154.971634,-0.002475,0.002688,0.068277,157.493408,8.023097,0.682767,-154.971634,0.069604,0.000000
51.560001,35.489708,-155.060593,-0.002466,0.002701,0.068615,157.866104,8.042083,0.686149,-155.060593,0.070185,0.000000
51.910004,37.712395,-155.060593,-0.002445,0.002741,0.069612,167.753113,8.545752,0.696122,-155.060593,0.070766,0.000000
52.260002,38.161476,-155.060593,-0.002423,0.002764,0.070211,169.750717,8.647513,0.702106,-155.060593,0.071347,0.000000
52.610001,38.804192,-155.060593,-0.002414,0.002791,0.070887,172.609665,8.793155,0.708870,-155.060593,0.071936,0.000000
52.960003,38.987770,-155.105072,-0.002393,0.002808,0.071329,173.426270,8.834755,0.713293,-155.105072,0.072517,0.000000
53.310001,38.956123,-155.105072,-0.002384,0.002828,0.071841,173.285492,8.827584,0.718410,-155.105072,0.073098,0.000000
53.660004,39.964508,-155.149551,-0.002354,0.002852,0.072431,177.771011,9.056087,0.724307,-155.149551,0.073679,0.000000
54.010002,41.341537,-155.194031,-0.002337,0.002881,0.073185,183.896347,9.368126,0.731852,-155.194031,0.074269,0.000000
54.360004,41.118118,-155.194031,-0.002324,0.002895,0.073541,182.902527,9.317499,0.735407,-155.194031,0.074850,0.000000
54.710003,41.674438,-155.149551,-0.002302,0.002919,0.074139,185.377167,9.443563,0.741391,-155.149551,0.075431,0.000000
55.060001,42.342476,-155.194031,-0.002298,0.002942,0.074720,188.348740,9.594942,0.747202,-155.194031,0.076021,0.000000
55.410004,42.897682,-155.149551,-0.002268,0.002963,0.075258,190.818420,9.720754,0.752578,-155.149551,0.076602,0.000000
55.760002,44.826942,-155.238525,-0.002264,0.002994,0.076047,199.400192,10.157930,0.760470,-155.238525,0.077183,0.000000
56.110004,45.602966,-155.194031,-0.002238,0.003019,0.076680,202.852127,10.333780,0.766801,-155.194031,0.077764,0.000000
56.460003,45.798462,-155.238525,-0.002225,0.003035,0.077088,203.721741,10.378079,0.770877,-155.238525,0.078354,0.000000
56.810001,46.890633,-155.327484,-0.002212,0.003063,0.077799,208.579956,10.625569,0.777988,-155.327484,0.078935,0.000000
57.160004,46.933456,-155.327484,-0.002190,0.003082,0.078276,208.770447,10.635273,0.782758,-155.327484,0.079516,0.000000
57.510002,47.170654,-155.283005,-0.002195,0.003102,0.078779,209.825546,10.689023,0.787788,-155.283005,0.080097,0.000000
57.860004,49.487556,-155.371964,-0.002164,0.003133,0.079585,220.131653,11.214041,0.795853,-155.371964,0.080687,0.000000
58.210003,50.231560,-155.327484,-0.002156,0.003153,0.080080,223.441132,11.382634,0.800796,-155.327484,0.081268,0.000000
58.560001,50.975929,-155.371964,-0.002139,0.003175,0.080643,226.752258,11.551311,0.806433,-155.371964,0.081849,0.000000
58.910004,51.666679,-155.371964,-0.002117,0.003196,0.081181,229.824875,11.707837,0.811810,-155.371964,0.082430,0.000000
59.260002,52.866837,-155.371964,-0.002113,0.003224,0.081901,235.163437,11.979796,0.819008,-155.371964,0.083020,0.000000
59.610004,53.894585,-155.416443,-0.002091,0.003247,0.082473,239.735092,12.212687,0.824732,-155.416443,0.083601,0.000000
59.960003,54.676193,-155.505402,-0.002082,0.003266,0.082967,243.211853,12.389803,0.829675,-155.505402,0.084182,0.000000
60.310001,54.997551,-155.416443,-0.002057,0.003284,0.083410,244.641327,12.462624,0.834098,-155.416443,0.084771,0.000000
60.660004,55.979874,-155.460922,-0.002044,0.003303,0.083904,249.010910,12.685221,0.839041,-155.460922,0.085352,0.000000
61.010002,57.142418,-155.505402,-0.002031,0.003327,0.084511,254.182175,12.948657,0.845111,-155.505402,0.085933,0.000000
61.360004,58.584244,-155.460922,-0.002018,0.003354,0.085196,260.595734,13.275380,0.851962,-155.460922,0.086514,0.000000
61.710003,60.489677,-155.549881,-0.002005,0.003385,0.085977,269.071533,13.707157,0.859767,-155.549881,0.087104,0.000000
62.060001,60.628571,-155.549881,-0.001979,0.003399,0.086332,269.689362,13.738630,0.863323,-155.549881,0.087685,0.000000
62.410004,61.698395,-155.549881,-0.001988,0.003421,0.086887,274.448181,13.981055,0.868873,-155.549881,0.088266,0.000000
62.760002,63.226616,-155.549881,-0.001966,0.003451,0.087668,281.246033,14.327356,0.876678,-155.549881,0.088847,0.000000
63.110004,63.729683,-155.549881,-0.001949,0.003464,0.087997,283.483795,14.441352,0.879974,-155.549881,0.089437,0.000000
63.460003,66.042488,-155.683334,-0.001927,0.003499,0.088873,293.771667,14.965442,0.888733,-155.683334,0.090018,0.000000
63.810001,65.304817,-155.594360,-0.001919,0.003495,0.088761,290.490326,14.798283,0.887606,-155.594360,0.015591,0.000000
64.160004,65.879768,-155.683334,-0.001914,0.003510,0.089159,293.047852,14.928569,0.891595,-155.683334,294.500488,0.000000
64.510002,65.063148,-155.683334,-0.001910,0.003521,0.089437,289.415344,14.743520,0.894370,-155.683334,294.500488,0.000000
64.860001,65.393440,-155.683334,-0.001910,0.003531,0.089697,290.884552,14.818365,0.896971,-155.683334,294.500488,0.000000
65.210007,65.310402,-155.727814,-0.001901,0.003539,0.089888,290.515167,14.799548,0.898879,-155.727814,294.500488,0.000000
65.560005,65.465309,-155.683334,-0.001884,0.003548,0.090131,291.204224,14.834651,0.901308,-155.683334,294.500488,0.000000
65.910004,65.343925,-155.772293,-0.001888,0.003555,0.090304,290.664307,14.807145,0.903042,-155.772293,294.500488,0.000000
66.260002,65.136879,-155.772293,-0.001871,0.003560,0.090426,289.743317,14.760228,0.904256,-155.772293,294.500488,0.000000
66.610001,65.400520,-155.727814,-0.001863,0.003567,0.090608,290.916046,14.819970,0.906077,-155.727814,294.500488,0.000000
66.960007,65.055336,-155.772293,-0.001867,0.003570,0.090668,289.380585,14.741750,0.906684,-155.772293,294.500488,0.000000
67.310005,65.738258,-155.772293,-0.001858,0.003584,0.091024,292.418365,14.896502,0.910240,-155.772293,294.500488,0.000000
67.660004,65.307808,-155.816772,-0.001845,0.003581,0.090946,290.503632,14.798961,0.909460,-155.816772,294.500488,0.000000
68.010002,64.873619,-155.861252,-0.001850,0.003581,0.090955,288.572266,14.700572,0.909546,-155.861252,294.500488,0.000000
68.360001,65.349876,-155.905731,-0.001841,0.003591,0.091223,290.690765,14.808494,0.912235,-155.905731,294.500488,0.000000
68.710007,65.056450,-155.905731,-0.001841,0.003592,0.091232,289.385529,14.742002,0.912321,-155.905731,294.500488,0.000000
69.060005,64.735100,-155.861252,-0.001832,0.003592,0.091241,287.956116,14.669183,0.912408,-155.861252,294.500488,0.000000
69.410004,65.674583,-155.950211,-0.001828,0.003606,0.091588,292.135132,14.882073,0.915877,-155.950211,294.500488,0.000000
69.760002,65.433662,-155.905731,-0.001828,0.003606,0.091588,291.063477,14.827479,0.915877,-155.905731,294.500488,0.000000
70.110001,65.091820,-155.950211,-0.001832,0.003606,0.091588,289.542877,14.750017,0.915877,-155.950211,294.500488,0.000000
70.460007,64.906380,-155.950211,-0.001824,0.003608,0.091640,288.717987,14.707996,0.916397,-155.950211,294.500488,0.000000
70.810005,64.656151,-155.950211,-0.001824,0.003608,0.091640,287.604919,14.651293,0.916397,-155.950211,294.500488,0.000000
71.160004,65.708473,-156.039169,-0.001837,0.003620,0.091943,292.285889,14.889753,0.919433,-156.039169,294.500488,0.000000
71.510002,65.419136,-155.950211,-0.001819,0.003620,0.091943,290.998840,14.824188,0.919433,-155.950211,294.500488,0.000000
71.860001,65.181190,-155.950211,-0.001819,0.003620,0.091943,289.940430,14.770268,0.919433,-155.950211,294.500488,0.000000
72.210007,64.925743,-156.039169,-0.001819,0.003620,0.091952,288.804138,14.712383,0.919519,-156.039169,294.500488,0.000000
72.560005,64.684074,-156.083664,-0.001807,0.003620,0.091952,287.729126,14.657620,0.919519,-156.083664,294.500488,0.000000
72.910004,66.325874,-156.128143,-0.001807,0.003645,0.092585,295.032227,15.029657,0.925850,-156.128143,294.500488,0.000000
73.260002,66.186607,-156.128143,-0.001802,0.003605,0.091562,294.412720,14.998099,0.915617,-156.128143,294.500488,0.000000
73.610001,65.913658,-156.083664,-0.001798,0.003605,0.091562,293.198608,14.936248,0.915617,-156.083664,294.500488,0.000000
73.960007,65.647774,-156.128143,-0.001794,0.003605,0.091562,292.015869,14.875998,0.915617,-156.128143,294.500488,0.000000
74.310005,65.457863,-156.128143,-0.001798,0.003605,0.091562,291.171112,14.832964,0.915617,-156.128143,294.500488,0.000000
74.660004,65.249336,-156.217102,-0.001794,0.003605,0.091579,290.243530,14.785711,0.915790,-156.217102,294.500488,0.000000
75.010002,65.218437,-156.172623,-0.001785,0.003634,0.092316,290.106110,14.778709,0.923162,-156.172623,294.500488,0.000000
75.360001,65.274284,-156.172623,-0.001789,0.003639,0.092420,290.354523,14.791364,0.924202,-156.172623,294.500488,0.000000
75.710007,65.164818,-156.217102,-0.001798,0.003639,0.092420,289.867584,14.766559,0.924202,-156.217102,294.500488,0.000000
76.060005,65.085869,-156.261581,-0.001785,0.003640,0.092455,289.516418,14.748669,0.924549,-156.261581,294.500488,0.000000
76.410004,64.958519,-156.261581,-0.001798,0.003640,0.092464,288.949921,14.719810,0.924636,-156.261581,294.500488,0.000000
76.760002,65.252693,-156.261581,-0.001785,0.003647,0.092628,290.258484,14.786471,0.926284,-156.261581,294.500488,0.000000
77.110001,65.217308,-156.306061,-0.001781,0.003647,0.092628,290.101074,14.778454,0.926284,-156.306061,294.500488,0.000000
77.460007,65.092567,-156.261581,-0.001789,0.003647,0.092628,289.546204,14.750187,0.926284,-156.261581,294.500488,0.000000
77.810005,65.237419,-156.306061,-0.001772,0.003652,0.092750,290.190521,14.783010,0.927498,-156.306061,294.500488,0.000000
78.160004,65.241142,-156.350540,-0.001781,0.003652,0.092750,290.207092,14.783854,0.927498,-156.350540,294.500488,0.000000
78.510002,65.128685,-156.350540,-0.001789,0.003652,0.092750,289.706848,14.758371,0.927498,-156.350540,294.500488,0.000000
78.860001,65.007301,-156.350540,-0.001776,0.003652,0.092750,289.166931,14.730865,0.927498,-156.350540,294.500488,0.000000
79.210007,65.384132,-156.395020,-0.001789,0.003660,0.092958,290.843140,14.816257,0.929579,-156.395020,294.500488,0.000000
79.560005,65.450050,-156.395020,-0.001763,0.003659,0.092949,291.136353,14.831194,0.929492,-156.395020,294.500488,0.000000
79.910004,65.341682,-156.483978,-0.001772,0.003659,0.092949,290.654327,14.806637,0.929492,-156.483978,294.500488,0.000000
80.260002,65.270561,-156.439499,-0.001768,0.003659,0.092949,290.337952,14.790521,0.929492,-156.439499,294.500488,0.000000
80.610001,65.157738,-156.439499,-0.001763,0.003659,0.092949,289.836090,14.764955,0.929492,-156.439499,294.500488,0.000000
80.960007,65.043419,-156.483978,-0.001772,0.003659,0.092949,289.327576,14.739050,0.929492,-156.483978,294.500488,0.000000
81.310005,64.955162,-156.483978,-0.001772,0.003660,0.092958,288.934998,14.719049,0.929579,-156.483978,294.500488,0.000000
81.660004,64.849419,-156.528473,-0.001746,0.003660,0.092958,288.464630,14.695088,0.929579,-156.528473,294.500488,0.000000
82.010002,64.769722,-156.528473,-0.001768,0.003660,0.092958,288.110107,14.677029,0.929579,-156.528473,294.500488,0.000000
82.360001,65.514473,-156.528473,-0.001759,0.003671,0.093235,291.422943,14.845792,0.932354,-156.528473,294.500488,0.000000
82.710007,65.549477,-156.572952,-0.001776,0.003671,0.093235,291.578644,14.853724,0.932354,-156.572952,294.500488,0.000000
83.060005,65.497337,-156.572952,-0.001755,0.003671,0.093235,291.346710,14.841908,0.932354,-156.572952,294.500488,0.000000
83.410004,65.417656,-156.617432,-0.001763,0.003671,0.093235,290.992279,14.823853,0.932354,-156.617432,294.500488,0.000000
83.760002,65.342812,-156.572952,-0.001763,0.003671,0.093235,290.659332,14.806892,0.932354,-156.572952,294.500488,0.000000
84.110001,65.254173,-156.661911,-0.001755,0.003671,0.093235,290.265045,14.786807,0.932354,-156.661911,294.500488,0.000000
84.460007,65.192360,-156.661911,-0.001759,0.003671,0.093235,289.990112,14.772799,0.932354,-156.661911,294.500488,0.000000
84.810005,65.114174,-156.661911,-0.001776,0.003671,0.093244,289.642303,14.755083,0.932441,-156.661911,294.500488,0.000000
85.160004,65.016609,-156.706390,-0.001759,0.003671,0.093244,289.208313,14.732974,0.932441,-156.706390,294.500488,0.000000
85.510002,64.949959,-156.706390,-0.001755,0.003671,0.093253,288.911835,14.717872,0.932528,-156.706390,294.500488,0.000000
85.860001,64.883675,-156.661911,-0.001755,0.003671,0.093253,288.617004,14.702851,0.932528,-156.661911,294.500488,0.000000
86.210007,65.631401,-156.750870,-0.001759,0.003681,0.093504,291.943054,14.872288,0.935043,-156.750870,294.500488,0.000000
86.560005,65.608681,-156.839828,-0.001755,0.003681,0.093504,291.841980,14.867140,0.935043,-156.839828,294.500488,0.000000
86.910004,65.569954,-156.795349,-0.001742,0.003681,0.093504,291.669708,14.858364,0.935043,-156.795349,294.500488,0.000000
87.260002,65.534950,-156.795349,-0.001755,0.003681,0.093504,291.514008,14.850431,0.935043,-156.795349,294.500488,0.000000
87.610001,65.481331,-156.884308,-0.001746,0.003681,0.093504,291.275513,14.838282,0.935043,-156.884308,294.500488,0.000000
87.960007,65.383766,-156.839828,-0.001750,0.003681,0.093504,290.841522,14.816174,0.935043,-156.839828,294.500488,0.000000
88.310005,65.324562,-156.884308,-0.001763,0.003681,0.093504,290.578156,14.802757,0.935043,-156.884308,294.500488,0.000000
88.660004,65.272057,-156.884308,-0.001759,0.003681,0.093504,290.344604,14.790859,0.935043,-156.884308,294.500488,0.000000
89.010002,65.213585,-156.973282,-0.001750,0.003682,0.093513,290.084503,14.777609,0.935130,-156.973282,294.500488,0.000000
89.360001,65.171135,-156.928802,-0.001738,0.003682,0.093522,289.895691,14.767991,0.935216,-156.928802,294.500488,0.000000
89.710007,65.102257,-156.973282,-0.001755,0.003682,0.093530,289.589294,14.752382,0.935303,-156.973282,294.500488,0.000000
90.060005,65.056084,-156.973282,-0.001750,0.003682,0.093530,289.383911,14.741920,0.935303,-156.973282,294.500488,0.000000
90.410004,64.994270,-156.973282,-0.001755,0.003682,0.093530,289.108948,14.727912,0.935303,-156.973282,294.500488,0.000000
90.760002,64.940636,-157.017761,-0.001755,0.003682,0.093530,288.870361,14.715758,0.935303,-157.017761,294.500488,0.000000
91.110001,64.869896,-157.017761,-0.001742,0.003686,0.093626,288.555695,14.699728,0.936257,-157.017761,294.500488,0.000000
91.460007,65.510750,-157.062241,-0.001733,0.003690,0.093730,291.406372,14.844948,0.937298,-157.062241,294.500488,0.000000
91.810005,65.497337,-157.106720,-0.001763,0.003690,0.093730,291.346710,14.841908,0.937298,-157.106720,294.500488,0.000000
92.160004,65.453773,-157.062241,-0.001755,0.003690,0.093730,291.152924,14.832037,0.937298,-157.062241,294.500488,0.000000
92.510002,65.387489,-157.106720,-0.001742,0.003690,0.093730,290.858093,14.817017,0.937298,-157.106720,294.500488,0.000000
92.860001,65.327171,-157.106720,-0.001742,0.003690,0.093730,290.589783,14.803349,0.937298,-157.106720,294.500488,0.000000
93.210007,65.298500,-157.195679,-0.001750,0.003690,0.093730,290.462250,14.796852,0.937298,-157.195679,294.500488,0.000000
93.560005,65.246361,-157.151199,-0.001750,0.003690,0.093730,290.230316,14.785036,0.937298,-157.151199,294.500488,0.000000
93.910004,65.209496,-157.195679,-0.001755,0.003690,0.093730,290.066315,14.776683,0.937298,-157.195679,294.500488,0.000000
94.260002,65.146187,-157.240158,-0.001746,0.003690,0.093730,289.784698,14.762337,0.937298,-157.240158,294.500488,0.000000
94.610008,65.066505,-157.195679,-0.001733,0.003690,0.093730,289.430267,14.744281,0.937298,-157.195679,294.500488,0.000000
94.960007,65.030006,-157.151199,-0.001733,0.003690,0.093730,289.267914,14.736011,0.937298,-157.151199,294.500488,0.000000
95.310005,64.972298,-157.284637,-0.001746,0.003690,0.093738,289.011200,14.722934,0.937384,-157.284637,294.500488,0.000000
95.660004,64.920906,-157.240158,-0.001746,0.003690,0.093738,288.782623,14.711287,0.937384,-157.240158,294.500488,0.000000
96.010002,65.252693,-157.329117,-0.001738,0.003700,0.093973,290.258484,14.786471,0.939726,-157.329117,294.500488,0.000000
96.360008,65.594154,-157.329117,-0.001738,0.003700,0.093973,291.777374,14.863848,0.939726,-157.329117,294.500488,0.000000
96.710007,65.593407,-157.373611,-0.001746,0.003700,0.093973,291.774048,14.863678,0.939726,-157.373611,294.500488,0.000000
97.060005,65.575539,-157.329117,-0.001750,0.003700,0.093973,291.694550,14.859629,0.939726,-157.329117,294.500488,0.000000
97.410004,65.555809,-157.329117,-0.001742,0.003700,0.093973,291.606812,14.855159,0.939726,-157.329117,294.500488,0.000000
97.760002,65.524147,-157.373611,-0.001750,0.003700,0.093973,291.465973,14.847984,0.939726,-157.373611,294.500488,0.000000
98.110008,65.494362,-157.373611,-0.001742,0.003700,0.093973,291.333466,14.841234,0.939726,-157.373611,294.500488,0.000000
98.460007,65.436272,-157.418091,-0.001742,0.003700,0.093973,291.075073,14.828072,0.939726,-157.418091,294.500488,0.000000
98.810005,65.387123,-157.418091,-0.001746,0.003700,0.093973,290.856445,14.816934,0.939726,-157.418091,294.500488,0.000000
99.160004,65.329033,-157.373611,-0.001742,0.003700,0.093973,290.598053,14.803770,0.939726,-157.373611,294.500488,0.000000
99.510002,65.304817,-157.418091,-0.001729,0.003700,0.093973,290.490326,14.798283,0.939726,-157.418091,294.500488,0.000000
99.860008,65.269447,-157.418091,-0.001733,0.003700,0.093973,290.333008,14.790268,0.939726,-157.418091,294.500488,0.000000
100.210007,65.226250,-157.462570,-0.001738,0.003700,0.093973,290.140839,14.780479,0.939726,-157.462570,294.500488,0.000000
100.560005,65.187157,-157.462570,-0.001738,0.003700,0.093973,289.966949,14.771621,0.939726,-157.462570,294.500488,0.000000
100.910004,65.136513,-157.507050,-0.001750,0.003700,0.093973,289.741669,14.760145,0.939726,-157.507050,294.500488,0.000000
101.260002,65.081032,-157.507050,-0.001738,0.003700,0.093973,289.494873,14.747572,0.939726,-157.507050,294.500488,0.000000
101.610008,65.061668,-157.551529,-0.001742,0.003700,0.093981,289.408752,14.743185,0.939812,-157.551529,294.500488,0.000000
101.960007,65.021828,-157.596008,-0.001720,0.003700,0.093981,289.231537,14.734157,0.939812,-157.596008,294.500488,0.000000
102.310005,64.986076,-157.551529,-0.001733,0.003700,0.093990,289.072510,14.726055,0.939899,-157.551529,294.500488,0.000000
102.660004,64.957024,-157.640488,-0.001725,0.003700,0.093990,288.943268,14.719472,0.939899,-157.640488,294.500488,0.000000
103.010002,64.912712,-157.596008,-0.001733,0.003700,0.093990,288.746155,14.709432,0.939899,-157.596008,294.500488,0.000000
103.360008,64.882927,-157.596008,-0.001733,0.003701,0.093999,288.613678,14.702682,0.939986,-157.596008,294.500488,0.000000
103.710007,65.420631,-157.596008,-0.001733,0.003708,0.094189,291.005493,14.824528,0.941894,-157.596008,294.500488,0.000000
104.060005,65.489143,-157.551529,-0.001738,0.003708,0.094189,291.310272,14.840053,0.941894,-157.551529,294.500488,0.000000
104.410004,65.495857,-157.596008,-0.001725,0.003708,0.094189,291.340118,14.841574,0.941894,-157.596008,294.500488,0.000000
104.760002,65.469414,-157.640488,-0.001733,0.003708,0.094189,291.222504,14.835581,0.941894,-157.640488,294.500488,0.000000
105.110008,65.405357,-157.684967,-0.001729,0.003708,0.094189,290.937561,14.821066,0.941894,-157.684967,294.500488,0.000000
105.460007,65.384514,-157.684967,-0.001720,0.003708,0.094189,290.844849,14.816342,0.941894,-157.684967,294.500488,0.000000
105.810005,65.339088,-157.684967,-0.001733,0.003708,0.094189,290.642792,14.806049,0.941894,-157.684967,294.500488,0.000000
106.160004,65.328651,-157.729446,-0.001720,0.003708,0.094189,290.596344,14.803684,0.941894,-157.729446,294.500488,0.000000
106.510002,65.297371,-157.773926,-0.001733,0.003708,0.094189,290.457214,14.796596,0.941894,-157.773926,294.500488,0.000000
106.860008,65.267952,-157.773926,-0.001720,0.003708,0.094189,290.326355,14.789929,0.941894,-157.773926,294.500488,0.000000
107.210007,65.248970,-157.773926,-0.001733,0.003708,0.094189,290.241913,14.785628,0.941894,-157.773926,294.500488,0.000000
107.560005,65.200554,-157.818420,-0.001742,0.003708,0.094189,290.026550,14.774657,0.941894,-157.818420,294.500488,0.000000
107.910004,65.171516,-157.818420,-0.001725,0.003708,0.094189,289.897369,14.768077,0.941894,-157.818420,294.500488,0.000000
108.260002,65.103371,-157.773926,-0.001716,0.003709,0.094198,289.594269,14.752634,0.941981,-157.773926,294.500488,0.000000
108.610008,65.075066,-157.773926,-0.001725,0.003709,0.094198,289.468353,14.746221,0.941981,-157.773926,294.500488,0.000000
108.960007,65.053093,-157.862900,-0.001733,0.003709,0.094198,289.370605,14.741241,0.941981,-157.862900,294.500488,0.000000
109.310005,65.046028,-157.862900,-0.001720,0.003709,0.094198,289.339172,14.739640,0.941981,-157.862900,294.500488,0.000000
109.660004,65.011772,-157.862900,-0.001733,0.003709,0.094198,289.186798,14.731878,0.941981,-157.862900,294.500488,0.000000
110.010002,64.977882,-157.951859,-0.001729,0.003709,0.094198,289.036041,14.724199,0.941981,-157.951859,294.500488,0.000000
110.360008,64.951439,-157.951859,-0.001720,0.003709,0.094198,288.918427,14.718206,0.941981,-157.951859,294.500488,0.000000
110.710007,64.919411,-157.951859,-0.001725,0.003709,0.094198,288.775970,14.710948,0.941981,-157.951859,294.500488,0.000000
111.060005,64.885155,-157.951859,-0.001733,0.003709,0.094198,288.623596,14.703186,0.941981,-157.951859,294.500488,0.000000
111.410004,64.839363,-157.951859,-0.001720,0.003709,0.094198,288.419891,14.692809,0.941981,-157.951859,294.500488,0.000000
111.760002,65.328651,-157.996338,-0.001712,0.003716,0.094389,290.596344,14.803684,0.943888,-157.996338,294.500488,0.000000
112.110008,65.364403,-157.996338,-0.001720,0.003716,0.094380,290.755371,14.811786,0.943802,-157.996338,294.500488,0.000000
112.460007,65.362541,-158.040817,-0.001725,0.003716,0.094380,290.747101,14.811363,0.943802,-158.040817,294.500488,0.000000
112.810005,65.349129,-158.085297,-0.001720,0.003716,0.094380,290.687439,14.808324,0.943802,-158.085297,294.500488,0.000000
113.160004,65.327904,-158.085297,-0.001720,0.003716,0.094380,290.593018,14.803514,0.943802,-158.085297,294.500488,0.000000
113.510002,65.318230,-158.129776,-0.001733,0.003716,0.094380,290.549988,14.801322,0.943802,-158.129776,294.500488,0.000000
113.860008,65.294762,-158.174255,-0.001720,0.003716,0.094380,290.445618,14.796005,0.943802,-158.174255,294.500488,0.000000
114.210007,65.288811,-158.085297,-0.001716,0.003716,0.094380,290.419128,14.794656,0.943802,-158.085297,294.500488,0.000000
114.560005,65.271675,-158.085297,-0.001712,0.003716,0.094380,290.342926,14.790773,0.943802,-158.085297,294.500488,0.000000
114.910004,65.265358,-158.174255,-0.001729,0.003716,0.094380,290.314819,14.789341,0.943802,-158.174255,294.500488,0.000000
115.260002,65.237053,-158.218750,-0.001729,0.003716,0.094380,290.188904,14.782928,0.943802,-158.218750,294.500488,0.000000
115.610008,65.215080,-158.174255,-0.001716,0.003716,0.094380,290.091156,14.777948,0.943802,-158.174255,294.500488,0.000000
115.960007,65.185661,-158.218750,-0.001720,0.003716,0.094380,289.960297,14.771281,0.943802,-158.218750,294.500488,0.000000
116.310005,65.152153,-158.263229,-0.001729,0.003716,0.094380,289.811249,14.763689,0.943802,-158.263229,294.500488,0.000000
116.660004,65.106346,-158.263229,-0.001712,0.003716,0.094380,289.607483,14.753309,0.943802,-158.263229,294.500488,0.000000
117.010002,65.087730,-158.263229,-0.001733,0.003716,0.094389,289.524689,14.749090,0.943888,-158.263229,294.500488,0.000000
117.360008,65.065010,-158.263229,-0.001712,0.003716,0.094389,289.423615,14.743942,0.943888,-158.263229,294.500488,0.000000
117.710007,65.039696,-158.307709,-0.001712,0.003716,0.094389,289.311005,14.738206,0.943888,-158.307709,294.500488,0.000000
118.060005,65.021828,-158.352188,-0.001729,0.003716,0.094389,289.231537,14.734157,0.943888,-158.352188,294.500488,0.000000
118.410004,65.008415,-158.352188,-0.001716,0.003716,0.094389,289.171875,14.731118,0.943888,-158.352188,294.500488,0.000000
118.760002,64.983467,-158.441147,-0.001720,0.003716,0.094389,289.060913,14.725465,0.943888,-158.441147,294.500488,0.000000
119.110008,64.962242,-158.396667,-0.001729,0.003716,0.094389,288.966492,14.720654,0.943888,-158.396667,294.500488,0.000000
119.460007,64.956657,-158.352188,-0.001707,0.003716,0.094398,288.941650,14.719389,0.943975,-158.352188,294.500488,0.000000
119.810005,64.914574,-158.441147,-0.001738,0.003716,0.094398,288.754456,14.709852,0.943975,-158.441147,294.500488,0.000000
120.160004,64.882927,-158.441147,-0.001707,0.003716,0.094398,288.613678,14.702682,0.943975,-158.441147,294.500488,0.000000
120.510002,64.866539,-158.441147,-0.001712,0.003717,0.094406,288.540771,14.698968,0.944062,-158.441147,294.500488,0.000000
120.860008,64.844566,-158.530106,-0.001703,0.003717,0.094406,288.443024,14.693989,0.944062,-158.530106,294.500488,0.000000
121.210007,65.495857,-158.441147,-0.001707,0.003726,0.094640,291.340118,14.841574,0.946403,-158.441147,294.500488,0.000000
121.560005,65.541283,-158.485626,-0.001699,0.003725,0.094614,291.542175,14.851867,0.946143,-158.485626,294.500488,0.000000
121.910004,65.542397,-158.485626,-0.001703,0.003725,0.094614,291.547150,14.852119,0.946143,-158.485626,294.500488,0.000000
122.260002,65.553566,-158.574585,-0.001707,0.003725,0.094614,291.596832,14.854650,0.946143,-158.574585,294.500488,0.000000
122.610008,65.549843,-158.574585,-0.001725,0.003725,0.094614,291.580261,14.853807,0.946143,-158.574585,294.500488,0.000000
122.960007,65.549477,-158.530106,-0.001707,0.003725,0.094614,291.578644,14.853724,0.946143,-158.530106,294.500488,0.000000
123.310005,65.516335,-158.530106,-0.001725,0.003725,0.094614,291.431213,14.846213,0.946143,-158.530106,294.500488,0.000000
123.660004,65.512978,-158.663559,-0.001703,0.003725,0.094614,291.416290,14.845453,0.946143,-158.663559,294.500488,0.000000
124.010002,65.508507,-158.574585,-0.001707,0.003725,0.094614,291.396393,14.844440,0.946143,-158.574585,1681.640991,0.000000
124.360008,65.472389,-158.619064,-0.001712,0.003717,0.094424,291.235718,14.836256,0.944235,-158.619064,0.094450,0.000000
124.710007,65.391960,-158.619064,-0.001707,0.003705,0.094103,290.877960,14.818030,0.941027,-158.619064,0.093860,0.000000
125.060005,65.317116,-158.663559,-0.001716,0.003693,0.093799,290.545044,14.801069,0.937991,-158.663559,0.093279,0.000000
125.410004,65.295891,-158.752518,-0.001703,0.003668,0.093166,290.450623,14.796261,0.931661,-158.752518,0.092698,0.000000
125.760010,65.217308,-158.708038,-0.001699,0.003647,0.092628,290.101074,14.778454,0.926284,-158.708038,0.092117,0.000000
126.110008,65.233330,-158.708038,-0.001703,0.003629,0.092177,290.172333,14.782084,0.921774,-158.708038,0.091527,0.000000
126.460007,65.140236,-158.708038,-0.001686,0.003602,0.091484,289.758240,14.760988,0.914836,-158.708038,0.090946,0.000000
126.810005,65.112312,-158.752518,-0.001690,0.003579,0.090903,289.634033,14.754661,0.909026,-158.752518,0.090365,0.000000
127.160004,65.107460,-158.796997,-0.001703,0.003558,0.090365,289.612457,14.753561,0.903649,-158.796997,0.089784,0.000000
127.510010,64.994270,-158.752518,-0.001690,0.003531,0.089688,289.108948,14.727912,0.896885,-158.752518,0.089194,0.000000
127.860008,64.966713,-158.885956,-0.001703,0.003512,0.089212,288.986359,14.721668,0.892115,-158.885956,0.088613,0.000000
128.210007,64.771217,-158.841476,-0.001707,0.003495,0.088761,288.116760,14.677368,0.887606,-158.841476,0.088032,0.000000
128.560013,64.183617,-158.841476,-0.001694,0.003469,0.088119,285.502991,14.544216,0.881188,-158.841476,0.087442,0.000000
128.910004,63.447807,-158.796997,-0.001690,0.003450,0.087633,282.229950,14.377479,0.876332,-158.796997,0.086861,0.000000
129.260010,62.508675,-158.841476,-0.001694,0.003429,0.087087,278.052460,14.164668,0.870868,-158.841476,0.086280,0.000000
129.610001,61.311874,-158.885956,-0.001699,0.003406,0.086506,272.728851,13.893469,0.865058,-158.885956,0.085699,0.000000
129.960007,60.169434,-158.930435,-0.001694,0.003388,0.086046,267.647003,13.634589,0.860461,-158.930435,0.085110,0.000000
130.310013,58.580521,-158.930435,-0.001690,0.003363,0.085422,260.579163,13.274535,0.854217,-158.930435,0.084528,0.000000
130.660004,57.019165,-158.885956,-0.001690,0.003348,0.085031,253.633911,12.920728,0.850315,-158.885956,0.083947,0.000000
131.010010,55.280930,-158.930435,-0.001686,0.003323,0.084407,245.901855,12.526837,0.844071,-158.930435,0.083366,0.000000
131.360001,53.350174,-158.974915,-0.001694,0.003306,0.083973,237.313431,12.089322,0.839735,-158.974915,0.082777,0.000000
131.710007,50.573395,-159.019394,-0.001699,0.003278,0.083262,224.961700,11.460094,0.832623,-159.019394,0.082196,0.000000
132.060013,48.730522,-159.019394,-0.001690,0.003257,0.082733,216.764191,11.042495,0.827333,-159.019394,0.081615,0.000000
132.410004,46.154083,-158.974915,-0.001699,0.003233,0.082109,205.303619,10.458665,0.821089,-158.974915,0.081025,0.000000
132.760010,43.355331,-158.974915,-0.001703,0.003208,0.081476,192.854141,9.824458,0.814758,-158.974915,0.080444,0.000000
133.110001,40.826172,-159.063889,-0.001699,0.003184,0.080869,181.603882,9.251343,0.808688,-159.063889,0.079863,0.000000
133.460007,38.390862,-159.108368,-0.001729,0.003161,0.080288,170.771088,8.699494,0.802878,-159.108368,0.079282,0.000000
133.810013,36.267960,-159.108368,-0.001716,0.003140,0.079759,161.327942,8.218437,0.797588,-159.108368,0.078692,0.000000
134.160004,33.557091,-159.063889,-0.001707,0.003113,0.079082,149.269394,7.604146,0.790823,-159.063889,0.078111,0.000000
134.510010,31.736938,-159.152847,-0.001716,0.003098,0.078701,141.172958,7.191693,0.787007,-159.152847,0.077530,0.000000
134.860001,29.189163,-159.152847,-0.001725,0.003073,0.078059,129.839890,6.614359,0.780590,-159.152847,0.076949,0.000000
135.210007,26.750122,-159.197327,-0.001729,0.003050,0.077461,118.990486,6.061664,0.774606,-159.197327,0.076359,0.000000
135.560013,23.901474,-159.197327,-0.001733,0.003023,0.076793,106.319069,5.416152,0.767928,-159.197327,0.075778,0.000000
135.910004,22.149460,-159.197327,-0.001733,0.003006,0.076359,98.525719,5.019139,0.763592,-159.197327,0.075197,0.000000
136.260010,19.516418,-159.197327,-0.001738,0.002984,0.075796,86.813362,4.422483,0.757955,-159.197327,0.074616,0.000000
136.610001,16.455513,-159.241806,-0.001738,0.002955,0.075058,73.197777,3.728873,0.750584,-159.241806,0.074026,0.000000
136.960007,13.926361,-159.197327,-0.001755,0.002934,0.074512,61.947548,3.155758,0.745120,-159.197327,0.073445,0.000000
137.310013,10.732147,-159.241806,-0.001772,0.002902,0.073714,47.738976,2.431939,0.737142,-159.241806,0.072864,0.000000
137.660004,8.865074,-159.241806,-0.001772,0.002885,0.073281,39.433819,2.008855,0.732806,-159.241806,0.072275,0.000000
138.010010,6.479652,-159.286285,-0.001776,0.002861,0.072665,28.822933,1.468310,0.726648,-159.286285,0.071694,0.000000
138.360001,4.175789,-159.286285,-0.001798,0.002839,0.072110,18.574837,0.946247,0.721098,-159.286285,0.071113,0.000000
138.710007,1.866333,-159.330765,-0.001781,0.002818,0.071572,8.301864,0.422917,0.715721,-159.330765,0.070531,0.000000
139.060013,0.025322,-159.330765,-0.001781,0.002797,0.071043,0.112638,0.005738,0.710431,-159.330765,0.069942,0.000000
139.410004,-2.517609,-159.375244,-0.001815,0.002770,0.070367,-11.198882,-0.570498,0.703667,-159.375244,0.069361,0.000000
139.760010,-0.336624,-159.330765,-0.001837,0.002749,0.069820,-1.497379,-0.076280,0.698203,-159.330765,0.068780,0.000000
140.110001,-0.079681,-159.419724,-0.001854,0.002725,0.069222,-0.354441,-0.018056,0.692220,-159.419724,0.068199,0.000000
140.460007,0.045807,-159.419724,-0.001863,0.002706,0.068728,0.203759,0.010380,0.687276,-159.419724,0.067609,0.000000
140.810013,-0.002602,-159.419724,-0.001884,0.002680,0.068060,-0.011573,-0.000590,0.680599,-159.419724,0.067028,0.000000
141.160004,-0.035744,-159.508698,-0.001888,0.002654,0.067401,-0.158996,-0.008100,0.674008,-159.508698,0.066447,0.000000
141.300003,0.036491,-159.508698,-0.001910,0.002654,0.067401,0.162322,0.008269,0.674008,-159.508698,0.067210,0.000000