File: Data/compression 34/AutoNoHeating-15-34-reverse-1-3_11152024_201936.csv
Time (sec),S:Load (lbs),S:HL1 (DIM),S:LVDT (in),S:Position (in),Ch:Position (mm),Ch:Load (N),Ch:Stress (MPa),Ch:Strain (mm/mm),Ch:HL1 (DIM),Set Point (),Cycles ()
0.110000,-0.035004,-104.975044,-0.013202,-0.007933,-0.201509,-0.155704,-0.007932,-2.015086,-104.975044,-0.201309,0.000000
0.500000,-0.065536,-104.886086,-0.013206,-0.007885,-0.200286,-0.291521,-0.014851,-2.002858,-104.886086,-0.199523,0.000000
0.890000,-0.059952,-105.019524,-0.013060,-0.007648,-0.194250,-0.266679,-0.013585,-1.942499,-105.019524,-0.193036,0.000000
1.280000,-0.057343,-105.064003,-0.012801,-0.007396,-0.187850,-0.255072,-0.012994,-1.878497,-105.064003,-0.186532,0.000000
1.670000,-0.077820,-105.019524,-0.012538,-0.007140,-0.181363,-0.346160,-0.017634,-1.813629,-105.019524,-0.180027,0.000000
2.060000,-0.099045,-105.019524,-0.012279,-0.006885,-0.174885,-0.440573,-0.022444,-1.748847,-105.019524,-0.173541,0.000000
2.450000,-0.135544,-104.975044,-0.012021,-0.006628,-0.168346,-0.602929,-0.030715,-1.683458,-104.975044,-0.167036,0.000000
2.840000,-0.041702,-105.108490,-0.011758,-0.006376,-0.161954,-0.185501,-0.009450,-1.619544,-105.108490,-0.160549,0.000000
3.230000,-0.062927,-105.064003,-0.011495,-0.006116,-0.155346,-0.279914,-0.014260,-1.553461,-105.064003,-0.154045,0.000000
3.620000,-0.035370,-105.108490,-0.011227,-0.005864,-0.148937,-0.157333,-0.008015,-1.489373,-105.108490,-0.147541,0.000000
4.010000,-0.045799,-105.152969,-0.010951,-0.005603,-0.142312,-0.203725,-0.010378,-1.423117,-105.152969,-0.141054,0.000000
4.400000,-0.113197,-105.197449,-0.010693,-0.005348,-0.135851,-0.503527,-0.025651,-1.358509,-105.197449,-0.134550,0.000000
4.790000,-0.099045,-105.152969,-0.010421,-0.005098,-0.129485,-0.440573,-0.022444,-1.294855,-105.152969,-0.128063,0.000000
5.180000,-0.053246,-105.197449,-0.010158,-0.004838,-0.122886,-0.236848,-0.012066,-1.228859,-105.197449,-0.121559,0.000000
5.570000,-0.028297,-105.197449,-0.009904,-0.004584,-0.116434,-0.125873,-0.006412,-1.164337,-105.197449,-0.115055,0.000000
5.960001,-0.063301,-105.241928,-0.009649,-0.004332,-0.110034,-0.281577,-0.014344,-1.100336,-105.241928,-0.108568,0.000000
6.350000,-0.071495,-105.330894,-0.009365,-0.004071,-0.103399,-0.318026,-0.016201,-1.033993,-105.330894,-0.102064,0.000000
6.740000,-0.106499,-105.330894,-0.009097,-0.003821,-0.097043,-0.473730,-0.024133,-0.970426,-105.330894,-0.095577,0.000000
7.130000,-0.046173,-105.330894,-0.008847,-0.003566,-0.090573,-0.205388,-0.010463,-0.905730,-105.330894,-0.089073,0.000000
7.520000,-0.030159,-105.330894,-0.008584,-0.003301,-0.083835,-0.134154,-0.006834,-0.838347,-105.330894,-0.082569,0.000000
7.910000,-0.021965,-105.419853,-0.008321,-0.003052,-0.077513,-0.097705,-0.004977,-0.775126,-105.419853,-0.076082,0.000000
8.300000,-0.043938,-105.419853,-0.008050,-0.002795,-0.070982,-0.195445,-0.009956,-0.709824,-105.419853,-0.069578,0.000000
8.690001,-0.072609,-105.419853,-0.007800,-0.002537,-0.064444,-0.322981,-0.016453,-0.644435,-105.419853,-0.063091,0.000000
9.080001,-0.083038,-105.419853,-0.007541,-0.002286,-0.058052,-0.369373,-0.018817,-0.580521,-105.419853,-0.056586,0.000000
9.470000,-0.031273,-105.419853,-0.007261,-0.002028,-0.051513,-0.139109,-0.007087,-0.515132,-105.419853,-0.050082,0.000000
9.860001,-0.029411,-105.508820,-0.007006,-0.001769,-0.044931,-0.130828,-0.006665,-0.449310,-105.508820,-0.043595,0.000000
10.250001,-0.042450,-105.508820,-0.006735,-0.001516,-0.038513,-0.188827,-0.009619,-0.385135,-105.508820,-0.037091,0.000000
10.640000,-0.042076,-105.508820,-0.006472,-0.001256,-0.031905,-0.187164,-0.009535,-0.319052,-105.508820,-0.030604,0.000000
11.030001,-0.052872,-105.597778,-0.006209,-0.001004,-0.025505,-0.235185,-0.011981,-0.255051,-105.597778,-0.024100,0.000000
11.420000,-0.008934,-105.553299,-0.005946,-0.000746,-0.018958,-0.039741,-0.002024,-0.189576,-105.553299,-0.017596,0.000000
11.810000,-0.007072,-105.642258,-0.005687,-0.000488,-0.012401,-0.031460,-0.001603,-0.124013,-105.642258,-0.011109,0.000000
12.200001,0.014153,-105.642258,-0.005424,-0.000235,-0.005975,0.062954,0.003207,-0.059752,-105.642258,-0.004605,0.000000
12.590000,0.064796,-105.686737,-0.005290,-0.000006,-0.000147,0.288229,0.014683,-0.001474,-105.686737,0.000087,0.000000
12.980000,0.145599,-105.731224,-0.005282,-0.000006,-0.000147,0.647658,0.032993,-0.001474,-105.731224,0.000225,0.000000
13.370001,0.141502,-105.686737,-0.005282,-0.000005,-0.000139,0.629434,0.032065,-0.001388,-105.686737,0.000876,0.000000
13.760000,0.232735,-105.731224,-0.005286,0.000018,0.000460,1.035256,0.052738,0.004596,-105.731224,0.001526,0.000000
14.150001,0.381683,-105.820183,-0.005251,0.000044,0.001110,1.697812,0.086491,0.011101,-105.820183,0.002177,0.000000
14.540001,0.570847,-105.731224,-0.005221,0.000071,0.001795,2.539252,0.129356,0.017952,-105.731224,0.002827,0.000000
14.930000,0.778633,-105.864662,-0.005217,0.000096,0.002437,3.463533,0.176441,0.024369,-105.864662,0.003478,0.000000
15.320001,0.987534,-105.775703,-0.005174,0.000116,0.002957,4.392769,0.223778,0.029572,-105.775703,0.004128,0.000000
15.710001,1.402359,-105.953629,-0.005182,0.000150,0.003798,6.238004,0.317779,0.037984,-105.953629,0.004778,0.000000
16.100000,1.663391,-105.864662,-0.005135,0.000173,0.004388,7.399133,0.376930,0.043882,-105.864662,0.005429,0.000000
16.490002,1.926285,-105.909142,-0.005109,0.000197,0.005013,8.568542,0.436502,0.050126,-105.909142,0.006079,0.000000
16.880001,2.265144,-105.909142,-0.005088,0.000220,0.005576,10.075866,0.513289,0.055763,-105.909142,0.006730,0.000000
17.270000,2.639748,-105.953629,-0.005066,0.000244,0.006192,11.742184,0.598175,0.061920,-105.953629,0.007380,0.000000
17.660002,3.161819,-105.998108,-0.005044,0.000277,0.007033,14.064475,0.716479,0.070332,-105.998108,0.008031,0.000000
18.050001,3.425087,-105.998108,-0.005019,0.000303,0.007684,15.235548,0.776136,0.076836,-105.998108,0.008681,0.000000
18.440001,3.853683,-106.042587,-0.004984,0.000327,0.008299,17.142040,0.873257,0.082993,-106.042587,0.009331,0.000000
18.830002,4.030190,-106.042587,-0.004967,0.000347,0.008802,17.927177,0.913254,0.088023,-106.042587,0.009982,0.000000
19.220001,4.277069,-106.042587,-0.004958,0.000370,0.009409,19.025354,0.969198,0.094094,-106.042587,0.010624,0.000000
19.610001,4.935059,-106.042587,-0.004919,0.000405,0.010294,21.952236,1.118300,0.102940,-106.042587,0.011274,0.000000
20.000000,5.117889,-106.131546,-0.004911,0.000428,0.010884,22.765509,1.159730,0.108837,-106.131546,0.011924,0.000000
20.390001,5.408714,-106.131546,-0.004868,0.000449,0.011395,24.059162,1.225632,0.113953,-106.131546,0.012575,0.000000
20.780001,5.612770,-106.220512,-0.004859,0.000475,0.012063,24.966848,1.271872,0.120631,-106.220512,0.013225,0.000000
21.170000,5.769173,-106.131546,-0.004859,0.000491,0.012479,25.662561,1.307313,0.124794,-106.131546,0.013876,0.000000
21.560001,6.320282,-106.264992,-0.004807,0.000522,0.013260,28.114017,1.432196,0.132599,-106.264992,0.014526,0.000000
21.950001,6.767128,-106.220512,-0.004773,0.000556,0.014110,30.101688,1.533453,0.141098,-106.220512,0.015176,0.000000
22.340000,7.021461,-106.176033,-0.004747,0.000580,0.014725,31.233021,1.591086,0.147255,-106.176033,0.015827,0.000000
22.730001,7.214348,-106.353951,-0.004738,0.000603,0.015324,32.091022,1.634795,0.153239,-106.353951,0.016477,0.000000
23.120001,7.513733,-106.309471,-0.004708,0.000626,0.015905,33.422752,1.702636,0.159049,-106.309471,0.017128,0.000000
23.510000,8.152351,-106.398437,-0.004682,0.000658,0.016720,36.263470,1.847349,0.167201,-106.398437,0.017778,0.000000
23.900002,8.233902,-106.353951,-0.004665,0.000679,0.017258,36.626225,1.865829,0.172578,-106.353951,0.018429,0.000000
24.290001,8.526962,-106.353951,-0.004644,0.000705,0.017908,37.929821,1.932237,0.179082,-106.353951,0.019079,0.000000
24.680000,8.784645,-106.442917,-0.004613,0.000729,0.018515,39.076054,1.990629,0.185153,-106.442917,0.019729,0.000000
25.070002,8.921677,-106.442917,-0.004592,0.000747,0.018966,39.685600,2.021681,0.189662,-106.442917,0.020380,0.000000
25.460001,9.621735,-106.442917,-0.004562,0.000787,0.019981,42.799614,2.180316,0.199809,-106.442917,0.021030,0.000000
25.850000,9.696579,-106.487396,-0.004531,0.000807,0.020510,43.132538,2.197276,0.205099,-106.487396,0.021681,0.000000
26.240002,9.952026,-106.531876,-0.004514,0.000831,0.021117,44.268826,2.255162,0.211169,-106.531876,0.022331,0.000000
26.630001,10.287910,-106.576355,-0.004501,0.000859,0.021819,45.762913,2.331274,0.218194,-106.576355,0.022981,0.000000
27.020000,10.335571,-106.531876,-0.004471,0.000876,0.022262,45.974918,2.342074,0.222617,-106.531876,0.023632,0.000000
27.410002,11.269485,-106.620842,-0.004441,0.000916,0.023268,50.129173,2.553702,0.232677,-106.620842,0.024282,0.000000
27.800001,11.205811,-106.620842,-0.004419,0.000938,0.023814,49.845936,2.539273,0.238140,-106.620842,0.024933,0.000000
28.190001,11.553604,-106.576355,-0.004398,0.000961,0.024421,51.392998,2.618084,0.244211,-106.576355,0.025574,0.000000
28.580002,11.820595,-106.665321,-0.004372,0.000991,0.025176,52.580631,2.678585,0.251756,-106.665321,0.026225,0.000000
28.970001,11.966934,-106.620842,-0.004346,0.001015,0.025774,53.231583,2.711746,0.257739,-106.620842,0.026875,0.000000
29.360001,12.358299,-106.665321,-0.004307,0.001044,0.026520,54.972462,2.800431,0.265198,-106.665321,0.027526,0.000000
29.750002,12.451393,-106.754280,-0.004299,0.001063,0.026988,55.386562,2.821526,0.269881,-106.754280,0.028176,0.000000
30.140001,12.979416,-106.665321,-0.004281,0.001089,0.027673,57.735325,2.941178,0.276732,-106.665321,0.028827,0.000000
30.530001,13.192787,-106.754280,-0.004268,0.001114,0.028306,58.684448,2.989528,0.283062,-106.754280,0.029477,0.000000
30.920002,13.452332,-106.754280,-0.004234,0.001139,0.028939,59.838959,3.048342,0.289393,-106.754280,0.030127,0.000000
31.310001,13.879066,-106.754280,-0.004208,0.001172,0.029772,61.737171,3.145041,0.297719,-106.754280,0.030778,0.000000
31.700001,13.645592,-106.843246,-0.004195,0.001192,0.030266,60.698624,3.092135,0.302662,-106.843246,0.031428,0.000000
32.090000,14.080894,-106.843246,-0.004148,0.001216,0.030891,62.634945,3.190776,0.308906,-106.843246,0.032079,0.000000
32.480003,14.264473,-106.932205,-0.004126,0.001240,0.031498,63.451546,3.232376,0.314976,-106.932205,0.032729,0.000000
32.870003,14.480453,-106.887726,-0.004105,0.001268,0.032200,64.412277,3.281318,0.322001,-106.887726,0.033380,0.000000
33.260002,15.034172,-106.887726,-0.004092,0.001300,0.033015,66.875336,3.406792,0.330153,-106.887726,0.034030,0.000000
33.650002,15.129868,-106.932205,-0.004066,0.001326,0.033683,67.301010,3.428477,0.336830,-106.932205,0.034680,0.000000
34.040001,15.132103,-106.932205,-0.004031,0.001346,0.034186,67.310959,3.428983,0.341860,-106.932205,0.035331,0.000000
34.430000,15.112740,-106.976685,-0.004027,0.001367,0.034715,67.224823,3.424596,0.347150,-106.976685,0.035981,0.000000
34.820004,15.657150,-107.065651,-0.003984,0.001397,0.035496,69.646484,3.547961,0.354955,-107.065651,0.036632,0.000000
35.210003,16.036598,-106.976685,-0.003975,0.001425,0.036189,71.334351,3.633945,0.361893,-106.976685,0.037282,0.000000
35.600002,15.814285,-107.065651,-0.003949,0.001443,0.036658,70.345451,3.583568,0.366576,-107.065651,0.037932,0.000000
35.990002,16.273796,-107.065651,-0.003919,0.001473,0.037412,72.389458,3.687695,0.374121,-107.065651,0.038583,0.000000
36.380001,16.426468,-107.154610,-0.003919,0.001502,0.038149,73.068581,3.722291,0.381493,-107.154610,0.039233,0.000000
36.770000,16.450676,-107.154610,-0.003863,0.001522,0.038661,73.176262,3.727777,0.386609,-107.154610,0.039884,0.000000
37.160004,17.053543,-107.154610,-0.003846,0.001555,0.039502,75.857948,3.864388,0.395021,-107.154610,0.040534,0.000000
37.550003,16.827888,-107.199089,-0.003829,0.001577,0.040048,74.854187,3.813254,0.400485,-107.199089,0.041176,0.000000
37.940002,17.088921,-107.199089,-0.003807,0.001602,0.040682,76.015312,3.872405,0.406816,-107.199089,0.041826,0.000000
38.330002,17.065086,-107.199089,-0.003807,0.001622,0.041202,75.909294,3.867004,0.412019,-107.199089,0.042477,0.000000
38.720001,17.426292,-107.199089,-0.003764,0.001648,0.041861,77.516022,3.948854,0.418610,-107.199089,0.043127,0.000000
39.110001,17.965111,-107.243576,-0.003729,0.001685,0.042798,79.912804,4.070952,0.427976,-107.243576,0.043778,0.000000
39.500000,17.737968,-107.332535,-0.003708,0.001707,0.043370,78.902428,4.019481,0.433700,-107.332535,0.044428,0.000000
39.890003,17.913727,-107.332535,-0.003686,0.001733,0.044020,79.684235,4.059309,0.440204,-107.332535,0.045078,0.000000
40.280003,18.322586,-107.332535,-0.003682,0.001759,0.044688,81.502930,4.151958,0.446881,-107.332535,0.045729,0.000000
40.670002,18.773163,-107.377014,-0.003648,0.001788,0.045408,83.507202,4.254060,0.454079,-107.377014,0.046379,0.000000
41.060001,18.757149,-107.332535,-0.003617,0.001810,0.045980,83.435966,4.250431,0.459803,-107.332535,0.047030,0.000000
41.450001,18.508774,-107.465981,-0.003609,0.001832,0.046527,82.331139,4.194148,0.465267,-107.465981,0.047680,0.000000
41.840000,18.870346,-107.332535,-0.003574,0.001862,0.047298,83.939491,4.276082,0.472985,-107.332535,0.048330,0.000000
42.230003,18.950409,-107.421494,-0.003553,0.001884,0.047854,84.295631,4.294224,0.478535,-107.421494,0.048981,0.000000
42.620003,19.374916,-107.510460,-0.003531,0.001908,0.048461,86.183929,4.390419,0.484606,-107.510460,0.049631,0.000000
43.010002,19.575996,-107.421494,-0.003510,0.001934,0.049120,87.078384,4.435984,0.491197,-107.421494,0.050282,0.000000
43.400002,19.629616,-107.554939,-0.003501,0.001961,0.049805,87.316895,4.448134,0.498048,-107.554939,0.050932,0.000000
43.790001,19.939804,-107.510460,-0.003466,0.001992,0.050585,88.696678,4.518425,0.505853,-107.510460,0.051583,0.000000
44.180000,19.515297,-107.554939,-0.003475,0.002009,0.051036,86.808372,4.422229,0.510362,-107.554939,0.052233,0.000000
44.570004,19.764046,-107.554939,-0.003419,0.002035,0.051687,87.914864,4.478597,0.516867,-107.554939,0.052883,0.000000
44.960003,20.032898,-107.554939,-0.003410,0.002062,0.052363,89.110779,4.539519,0.523631,-107.554939,0.053534,0.000000
45.350002,19.896606,-107.554939,-0.003389,0.002084,0.052927,88.504524,4.508636,0.529268,-107.554939,0.054184,0.000000
45.740002,20.297279,-107.643898,-0.003359,0.002111,0.053612,90.286804,4.599429,0.536119,-107.643898,0.054835,0.000000
46.130001,20.325211,-107.688385,-0.003346,0.002130,0.054106,90.411049,4.605759,0.541062,-107.688385,0.055485,0.000000
46.520000,21.282951,-107.732864,-0.003324,0.002167,0.055043,94.671295,4.822786,0.550428,-107.732864,0.056127,0.000000
46.910004,21.307526,-107.643898,-0.003294,0.002194,0.055719,94.780609,4.828354,0.557193,-107.643898,0.056777,0.000000
47.300003,21.332474,-107.777344,-0.003281,0.002219,0.056361,94.891586,4.834008,0.563610,-107.777344,0.057428,0.000000
47.690002,21.613991,-107.732864,-0.003251,0.002247,0.057072,96.143829,4.897800,0.570721,-107.732864,0.058078,0.000000
48.080002,21.112030,-107.821823,-0.003229,0.002263,0.057471,93.911003,4.784054,0.574710,-107.821823,0.058729,0.000000
48.470001,21.444191,-107.821823,-0.003199,0.002290,0.058156,95.388527,4.859323,0.581562,-107.821823,0.059379,0.000000
48.860001,22.012054,-107.866310,-0.003178,0.002321,0.058954,97.914505,4.988003,0.589540,-107.866310,0.060029,0.000000
49.250004,21.543236,-107.910789,-0.003156,0.002339,0.059405,95.829102,4.881767,0.594050,-107.910789,0.060680,0.000000
49.640003,21.908539,-107.910789,-0.003130,0.002372,0.060255,97.454048,4.964546,0.602548,-107.910789,0.061330,0.000000
50.030003,22.405655,-107.955269,-0.003113,0.002401,0.060983,99.665329,5.077194,0.609833,-107.955269,0.061981,0.000000
50.420002,22.175903,-107.955269,-0.003083,0.002424,0.061573,98.643341,5.025131,0.615730,-107.955269,0.062631,0.000000
50.810001,22.347939,-107.910789,-0.003061,0.002449,0.062206,99.408592,5.064116,0.622061,-107.910789,0.063281,0.000000
51.200001,21.937950,-107.999748,-0.003061,0.002469,0.062709,97.584877,4.971210,0.627091,-107.999748,0.063932,0.000000
51.590004,22.035141,-107.999748,-0.003035,0.002493,0.063316,98.017204,4.993235,0.633161,-107.999748,0.064582,0.000000
51.980003,22.671524,-107.999748,-0.003027,0.002522,0.064062,100.847977,5.137441,0.640620,-107.999748,0.065233,0.000000
52.370003,22.985062,-108.044228,-0.002979,0.002552,0.064825,102.242661,5.208489,0.648251,-108.044228,0.065883,0.000000
52.760002,22.982086,-108.044228,-0.002953,0.002575,0.065406,102.229424,5.207815,0.654062,-108.044228,0.066534,0.000000
53.150002,22.855850,-108.133194,-0.002940,0.002598,0.065979,101.667900,5.179210,0.659785,-108.133194,0.067184,0.000000
53.540001,23.216309,-108.088715,-0.002915,0.002629,0.066776,103.271301,5.260890,0.667764,-108.088715,0.067834,0.000000
53.930004,22.833138,-108.088715,-0.002910,0.002648,0.067271,101.566872,5.174063,0.672707,-108.088715,0.068485,0.000000
54.320004,23.214073,-108.133194,-0.002871,0.002675,0.067938,103.261353,5.260384,0.679385,-108.133194,0.069135,0.000000
54.710003,23.433029,-108.133194,-0.002846,0.002705,0.068710,104.235321,5.310000,0.687103,-108.133194,0.069786,0.000000
55.100002,23.092682,-108.177673,-0.002837,0.002725,0.069205,102.721382,5.232876,0.692046,-108.177673,0.070436,0.000000
55.490002,23.287056,-108.177673,-0.002811,0.002753,0.069924,103.585999,5.276922,0.699244,-108.177673,0.071078,0.000000
55.880001,22.747116,-108.266632,-0.002790,0.002775,0.070479,101.184227,5.154570,0.704794,-108.266632,0.071728,0.000000
56.270004,23.748055,-108.266632,-0.002759,0.002806,0.071277,105.636620,5.381386,0.712773,-108.266632,0.072379,0.000000
56.660004,23.841522,-108.266632,-0.002738,0.002829,0.071867,106.052391,5.402566,0.718670,-108.266632,0.073029,0.000000
57.050003,23.347382,-108.355598,-0.002725,0.002847,0.072318,103.854340,5.290592,0.723180,-108.355598,0.073679,0.000000
57.440002,24.251129,-108.355598,-0.002703,0.002882,0.073211,107.874413,5.495385,0.732112,-108.355598,0.074330,0.000000
57.830002,23.840408,-108.400078,-0.002682,0.002906,0.073810,106.047432,5.402314,0.738096,-108.400078,0.074980,0.000000
58.220001,23.961800,-108.355598,-0.002656,0.002932,0.074469,106.587410,5.429821,0.744687,-108.355598,0.075631,0.000000
58.610004,24.494293,-108.400078,-0.002630,0.002962,0.075223,108.956055,5.550487,0.752232,-108.400078,0.076281,0.000000
59.000004,24.540840,-108.489037,-0.002617,0.002983,0.075761,109.163109,5.561034,0.757608,-108.489037,0.076932,0.000000
59.390003,24.601532,-108.489037,-0.002600,0.003011,0.076489,109.433083,5.574787,0.764893,-108.489037,0.077582,0.000000
59.780003,24.063828,-108.489037,-0.002574,0.003030,0.076958,107.041252,5.452941,0.769576,-108.489037,0.078232,0.000000
60.170002,24.801498,-108.533524,-0.002552,0.003063,0.077790,110.322578,5.620100,0.777901,-108.533524,0.078883,0.000000
60.560001,25.812859,-108.578003,-0.002539,0.003093,0.078571,114.821327,5.849277,0.785706,-108.578003,0.079533,0.000000
60.950005,25.488525,-108.578003,-0.002509,0.003110,0.079004,113.378624,5.775782,0.790043,-108.578003,0.080184,0.000000
61.340004,25.638588,-108.578003,-0.002479,0.003136,0.079646,114.046135,5.809787,0.796460,-108.578003,0.080834,0.000000
61.730003,25.762962,-108.622482,-0.002471,0.003159,0.080244,114.599380,5.837971,0.802444,-108.622482,0.081485,0.000000
62.120003,26.728149,-108.578003,-0.002453,0.003192,0.081068,118.892746,6.056685,0.810683,-108.578003,0.082135,0.000000
62.510002,26.509941,-108.666962,-0.002419,0.003216,0.081675,117.922104,6.007239,0.816753,-108.666962,0.082785,0.000000
62.900002,26.814171,-108.666962,-0.002402,0.003238,0.082248,119.275391,6.076178,0.822477,-108.666962,0.083436,0.000000
63.290005,27.210373,-108.622482,-0.002384,0.003265,0.082933,121.037781,6.165959,0.829328,-108.622482,0.084086,0.000000
63.680004,27.254318,-108.755928,-0.002358,0.003286,0.083453,121.233261,6.175917,0.834531,-108.755928,0.084737,0.000000
64.070000,28.306267,-108.800407,-0.002324,0.003317,0.084242,125.912560,6.414292,0.842423,-108.800407,0.085387,0.000000
64.460007,28.181892,-108.711441,-0.002315,0.003338,0.084789,125.359322,6.386108,0.847887,-108.711441,0.086029,0.000000
64.850006,29.165703,-108.844887,-0.002298,0.003372,0.085639,129.735519,6.609043,0.856385,-108.844887,0.086679,0.000000
65.240005,29.383171,-108.755928,-0.002289,0.003395,0.086237,130.702866,6.658322,0.862369,-108.755928,0.087330,0.000000
65.630005,28.937065,-108.889366,-0.002268,0.003414,0.086714,128.718491,6.557232,0.867139,-108.889366,0.087980,0.000000
66.020004,30.401237,-108.800407,-0.002238,0.003447,0.087564,135.231461,6.889019,0.875638,-108.800407,0.088630,0.000000
66.410004,30.692802,-108.844887,-0.002216,0.003470,0.088127,136.528397,6.955089,0.881275,-108.844887,0.089281,0.000000
66.800003,31.083794,-108.933846,-0.002190,0.003493,0.088717,138.267624,7.043688,0.887172,-108.933846,0.089931,0.000000
67.190002,31.730606,-108.889366,-0.002164,0.003518,0.089359,141.144791,7.190259,0.893589,-108.889366,0.090582,0.000000
67.580002,31.474037,-109.022812,-0.002156,0.003534,0.089767,140.003510,7.132119,0.897665,-109.022812,0.091232,0.000000
67.970001,33.439049,-109.022812,-0.002117,0.003575,0.090799,148.744324,7.577397,0.907985,-109.022812,0.091883,0.000000
68.360001,33.844193,-109.067291,-0.002126,0.003600,0.091432,150.546494,7.669204,0.914316,-109.067291,0.092533,0.000000
68.750000,34.066124,-109.022812,-0.002095,0.003623,0.092013,151.533691,7.719494,0.920126,-109.022812,0.093183,0.000000
69.140007,34.825394,-109.067291,-0.002074,0.003648,0.092672,154.911087,7.891547,0.926717,-109.067291,0.093834,0.000000
69.530006,35.330704,-109.111771,-0.002048,0.003673,0.093296,157.158813,8.006052,0.932961,-109.111771,0.094484,0.000000
69.920006,36.126465,-109.111771,-0.002035,0.003700,0.093981,160.698547,8.186374,0.939812,-109.111771,0.095135,0.000000
70.310005,36.762100,-109.111771,-0.002001,0.003721,0.094519,163.525986,8.330411,0.945189,-109.111771,0.095785,0.000000
70.700005,37.012337,-109.200737,-0.001988,0.003747,0.095178,164.639099,8.387115,0.951780,-109.200737,0.096435,0.000000
71.090004,38.761742,-109.111771,-0.001970,0.003778,0.095959,172.420837,8.783537,0.959585,-109.111771,0.097086,0.000000
71.480003,39.699745,-109.245216,-0.001966,0.003806,0.096678,176.593292,8.996091,0.966783,-109.245216,0.097736,0.000000
71.870003,40.447472,-109.200737,-0.001932,0.003831,0.097320,179.919342,9.165528,0.973201,-109.200737,0.098387,0.000000
72.260002,40.839577,-109.245216,-0.001919,0.003850,0.097780,181.663513,9.254380,0.977797,-109.245216,0.099037,0.000000
72.650002,41.247330,-109.289696,-0.001893,0.003869,0.098283,183.477280,9.346779,0.982827,-109.289696,0.099688,0.000000
73.040001,43.075676,-109.245216,-0.001901,0.003903,0.099133,191.610184,9.761087,0.991326,-109.245216,0.100338,0.000000
73.430000,44.275833,-109.378662,-0.001871,0.003933,0.099896,196.948746,10.033048,0.998957,-109.378662,0.100980,0.000000
73.820000,45.250328,-109.334175,-0.001845,0.003960,0.100572,201.283508,10.253871,1.005722,-109.334175,0.101630,0.000000
74.210007,45.687500,-109.334175,-0.001828,0.003980,0.101101,203.228149,10.352935,1.011012,-109.334175,0.102281,0.000000
74.600006,46.677635,-109.423141,-0.001798,0.004001,0.101613,207.632492,10.577304,1.016128,-109.423141,0.102931,0.000000
74.990005,48.354057,-109.467621,-0.001794,0.004035,0.102489,215.089584,10.957187,1.024887,-109.467621,0.103581,0.000000
75.380005,48.576736,-109.467621,-0.001776,0.004051,0.102888,216.080109,11.007646,1.028877,-109.467621,0.104232,0.000000
75.770004,51.000511,-109.423141,-0.001759,0.004089,0.103868,226.861603,11.556881,1.038676,-109.423141,0.104882,0.000000
76.160004,52.051712,-109.512100,-0.001746,0.004110,0.104397,231.537582,11.795087,1.043966,-109.512100,0.105533,0.000000
76.550003,52.837791,-109.512100,-0.001733,0.004131,0.104934,235.034241,11.973215,1.049343,-109.512100,0.106183,0.000000
76.940002,54.039810,-109.512100,-0.001725,0.004162,0.105723,240.381088,12.245597,1.057235,-109.512100,0.106834,0.000000
77.330002,55.111870,-109.601067,-0.001699,0.004182,0.106218,245.149841,12.488528,1.062178,-109.601067,0.107484,0.000000
77.720001,56.954369,-109.512100,-0.001694,0.004210,0.106938,253.345688,12.906045,1.069376,-109.512100,0.108134,0.000000
78.110001,58.523552,-109.645546,-0.001677,0.004237,0.107614,260.325775,13.261627,1.076140,-109.645546,0.108785,0.000000
78.500000,58.991989,-109.645546,-0.001660,0.004252,0.108013,262.409485,13.367775,1.080130,-109.645546,0.109435,0.000000
78.890007,61.494339,-109.601067,-0.001634,0.004292,0.109019,273.540466,13.934816,1.090189,-109.601067,0.110086,0.000000
79.280006,62.550011,-109.690025,-0.001638,0.004311,0.109487,278.236359,14.174034,1.094872,-109.690025,0.110736,0.000000
79.670006,64.485603,-109.645546,-0.001625,0.004342,0.110294,286.846283,14.612646,1.102938,-109.645546,0.111386,0.000000
80.060005,66.027229,-109.690025,-0.001608,0.004367,0.110918,293.703796,14.961985,1.109182,-109.690025,0.112037,0.000000
80.450005,65.541649,-109.690025,-0.001582,0.004365,0.110875,291.543823,14.851950,1.108748,-109.690025,0.019455,0.000000
80.840004,65.231468,-109.778984,-0.001578,0.004377,0.111170,290.164062,14.781662,1.111697,-109.778984,294.500488,0.000000
81.230003,65.833595,-109.823471,-0.001578,0.004391,0.111525,292.842468,14.918106,1.115252,-109.823471,294.500488,0.000000
81.620003,65.250450,-109.734505,-0.001565,0.004391,0.111525,290.248505,14.785963,1.115252,-109.734505,294.500488,0.000000
82.010002,65.108955,-109.823471,-0.001582,0.004397,0.111690,289.619110,14.753900,1.116900,-109.823471,294.500488,0.000000
82.400002,64.846062,-109.823471,-0.001556,0.004400,0.111759,288.449677,14.694327,1.117594,-109.823471,294.500488,0.000000
82.790001,65.571449,-109.823471,-0.001544,0.004410,0.112020,291.676361,14.858703,1.120196,-109.823471,294.500488,0.000000
83.180000,65.111183,-109.912430,-0.001539,0.004411,0.112046,289.628998,14.754405,1.120456,-109.912430,294.500488,0.000000
83.570007,65.036720,-109.823471,-0.001544,0.004414,0.112124,289.297791,14.737532,1.121236,-109.823471,294.500488,0.000000
83.960007,65.011772,-109.956909,-0.001556,0.004419,0.112236,289.186798,14.731878,1.122364,-109.956909,294.500488,0.000000
84.350006,64.789085,-109.956909,-0.001535,0.004419,0.112236,288.196259,14.681417,1.122364,-109.956909,294.500488,0.000000
84.740005,66.071907,-110.001389,-0.001526,0.004430,0.112514,293.902527,14.972108,1.125139,-110.001389,294.500488,0.000000
85.130005,65.644051,-110.045876,-0.001526,0.004423,0.112332,291.999329,14.875154,1.123317,-110.045876,294.500488,0.000000
85.520004,65.327538,-110.001389,-0.001535,0.004423,0.112332,290.591400,14.803432,1.123317,-110.001389,294.500488,0.000000
85.910004,65.028526,-110.090355,-0.001522,0.004425,0.112384,289.261322,14.735675,1.123838,-110.090355,294.500488,0.000000
86.300003,65.499199,-110.045876,-0.001509,0.004438,0.112722,291.354980,14.842331,1.127220,-110.045876,294.500488,0.000000
86.690002,65.302589,-110.134834,-0.001531,0.004438,0.112722,290.480438,14.797779,1.127220,-110.134834,294.500488,0.000000
87.080002,65.113426,-110.134834,-0.001513,0.004438,0.112731,289.638977,14.754913,1.127307,-110.134834,294.500488,0.000000
87.470001,64.958519,-110.134834,-0.001513,0.004438,0.112731,288.949921,14.719810,1.127307,-110.134834,294.500488,0.000000
87.860001,65.252312,-110.223793,-0.001518,0.004444,0.112878,290.256775,14.786386,1.128781,-110.223793,294.500488,0.000000
88.250008,65.127953,-110.179314,-0.001505,0.004444,0.112878,289.703613,14.758204,1.128781,-110.179314,294.500488,0.000000
88.640007,65.012138,-110.223793,-0.001526,0.004444,0.112878,289.188446,14.731961,1.128781,-110.223793,294.500488,0.000000
89.030006,64.913094,-110.268280,-0.001522,0.004445,0.112895,288.747864,14.709517,1.128954,-110.268280,294.500488,0.000000
89.420006,64.776802,-110.223793,-0.001505,0.004445,0.112904,288.141602,14.678634,1.129041,-110.223793,294.500488,0.000000
89.810005,66.174690,-110.312759,-0.001513,0.004451,0.113060,294.359711,14.995399,1.130602,-110.312759,294.500488,0.000000
90.200005,65.966164,-110.268280,-0.001505,0.004451,0.113052,293.432159,14.948146,1.130515,-110.268280,294.500488,0.000000
90.590004,65.836937,-110.312759,-0.001509,0.004451,0.113052,292.857330,14.918863,1.130515,-110.312759,294.500488,0.000000
90.980003,65.659691,-110.312759,-0.001492,0.004451,0.113052,292.068878,14.878698,1.130515,-110.312759,294.500488,0.000000
91.370003,65.543144,-110.357239,-0.001505,0.004451,0.113052,291.550476,14.852289,1.130515,-110.357239,294.500488,0.000000
91.760002,65.370354,-110.401718,-0.001496,0.004451,0.113052,290.781860,14.813134,1.130515,-110.401718,294.500488,0.000000
92.150002,65.257530,-110.446205,-0.001492,0.004451,0.113052,290.279999,14.787567,1.130515,-110.446205,294.500488,0.000000
92.540001,65.142845,-110.446205,-0.001505,0.004451,0.113052,289.769836,14.761580,1.130515,-110.446205,294.500488,0.000000
92.930008,65.019218,-110.490685,-0.001496,0.004451,0.113052,289.219940,14.733565,1.130515,-110.490685,294.500488,0.000000
93.320007,64.931328,-110.446205,-0.001487,0.004451,0.113060,288.828979,14.713649,1.130602,-110.446205,294.500488,0.000000
93.710007,64.801750,-110.535164,-0.001496,0.004451,0.113060,288.252594,14.684287,1.130602,-110.535164,294.500488,0.000000
94.100006,66.379860,-110.535164,-0.001496,0.004459,0.113260,295.272369,15.041891,1.132597,-110.535164,294.500488,0.000000
94.490005,66.250282,-110.535164,-0.001500,0.004459,0.113260,294.695984,15.012528,1.132597,-110.535164,294.500488,0.000000
94.880005,66.118080,-110.624123,-0.001487,0.004459,0.113260,294.107910,14.982571,1.132597,-110.624123,294.500488,0.000000
95.270004,66.022758,-110.624123,-0.001487,0.004459,0.113260,293.683899,14.960971,1.132597,-110.624123,294.500488,0.000000
95.660004,65.870079,-110.668610,-0.001496,0.004459,0.113260,293.004730,14.926373,1.132597,-110.668610,294.500488,0.000000
96.050003,65.839546,-110.624123,-0.001483,0.004459,0.113260,292.868927,14.919454,1.132597,-110.624123,294.500488,0.000000
96.440002,65.750557,-110.713089,-0.001492,0.004459,0.113260,292.473083,14.899289,1.132597,-110.713089,294.500488,0.000000
96.830002,65.642570,-110.802048,-0.001496,0.004459,0.113268,291.992737,14.874819,1.132684,-110.802048,294.500488,0.000000
97.220001,65.572563,-110.668610,-0.001475,0.004459,0.113268,291.681335,14.858955,1.132684,-110.668610,294.500488,0.000000
97.610008,65.486916,-110.757568,-0.001483,0.004459,0.113268,291.300354,14.839547,1.132684,-110.757568,294.500488,0.000000
98.000008,65.399040,-110.757568,-0.001479,0.004459,0.113268,290.909454,14.819633,1.132684,-110.757568,294.500488,0.000000
98.390007,65.308540,-110.757568,-0.001496,0.004459,0.113268,290.506897,14.799127,1.132684,-110.757568,294.500488,0.000000
98.780006,65.248970,-110.846527,-0.001479,0.004459,0.113268,290.241913,14.785628,1.132684,-110.846527,294.500488,0.000000
99.170006,65.155128,-110.802048,-0.001487,0.004459,0.113268,289.824493,14.764363,1.132684,-110.802048,294.500488,0.000000
99.560005,65.076180,-110.891014,-0.001479,0.004459,0.113268,289.473297,14.746473,1.132684,-110.891014,294.500488,0.000000
99.950005,65.019585,-110.846527,-0.001483,0.004459,0.113268,289.221558,14.733649,1.132684,-110.846527,294.500488,0.000000
100.340004,64.965218,-110.891014,-0.001483,0.004459,0.113268,288.979706,14.721329,1.132684,-110.891014,294.500488,0.000000
100.730003,64.882179,-110.935493,-0.001496,0.004459,0.113268,288.610352,14.702512,1.132684,-110.935493,294.500488,0.000000
101.120003,66.083824,-110.891014,-0.001492,0.004475,0.113676,293.955536,14.974809,1.136759,-110.891014,294.500488,0.000000
101.510002,66.000038,-111.024452,-0.001487,0.004475,0.113676,293.582825,14.955822,1.136759,-111.024452,294.500488,0.000000
101.900002,65.886101,-110.979973,-0.001466,0.004475,0.113676,293.076019,14.930004,1.136759,-110.979973,294.500488,0.000000
102.290009,65.865242,-110.979973,-0.001487,0.004475,0.113676,292.983215,14.925277,1.136759,-110.979973,294.500488,0.000000
102.680008,65.801567,-111.068932,-0.001479,0.004475,0.113676,292.699982,14.910849,1.136759,-111.068932,294.500488,0.000000
103.070007,65.761345,-111.024452,-0.001483,0.004475,0.113676,292.521057,14.901734,1.136759,-111.024452,294.500488,0.000000
103.460007,65.657829,-111.113419,-0.001483,0.004475,0.113676,292.060608,14.878277,1.136759,-111.113419,294.500488,0.000000
103.850006,65.604210,-111.068932,-0.001479,0.004475,0.113676,291.822113,14.866126,1.136759,-111.068932,294.500488,0.000000
104.240005,65.562126,-111.113419,-0.001475,0.004475,0.113676,291.634888,14.856590,1.136759,-111.113419,294.500488,0.000000
104.630005,65.512978,-111.157898,-0.001483,0.004475,0.113676,291.416290,14.845453,1.136759,-111.157898,294.500488,0.000000
105.020004,65.451530,-111.202377,-0.001475,0.004475,0.113676,291.142944,14.831529,1.136759,-111.202377,294.500488,0.000000
105.410004,65.398659,-111.202377,-0.001483,0.004476,0.113685,290.907776,14.819548,1.136846,-111.202377,294.500488,0.000000
105.800003,65.329765,-111.202377,-0.001470,0.004476,0.113702,290.601318,14.803937,1.137020,-111.202377,294.500488,0.000000
106.190002,65.293282,-111.246857,-0.001475,0.004477,0.113711,290.439026,14.795669,1.137106,-111.246857,294.500488,0.000000
106.580002,65.240776,-111.291336,-0.001483,0.004477,0.113711,290.205475,14.783772,1.137106,-111.291336,294.500488,0.000000
106.970009,65.199440,-111.291336,-0.001475,0.004477,0.113711,290.021606,14.774405,1.137106,-111.291336,294.500488,0.000000
107.360008,65.142464,-111.335823,-0.001470,0.004477,0.113711,289.768158,14.761494,1.137106,-111.335823,294.500488,0.000000
107.750008,65.094429,-111.380302,-0.001457,0.004477,0.113711,289.554474,14.750608,1.137106,-111.380302,294.500488,0.000000
108.140007,65.051613,-111.335823,-0.001470,0.004477,0.113711,289.364014,14.740906,1.137106,-111.335823,294.500488,0.000000
108.530006,65.002464,-111.424782,-0.001470,0.004477,0.113711,289.145416,14.729769,1.137106,-111.424782,294.500488,0.000000
108.920006,64.959633,-111.335823,-0.001475,0.004477,0.113711,288.954865,14.720063,1.137106,-111.335823,294.500488,0.000000
109.310005,64.915688,-111.380302,-0.001466,0.004477,0.113711,288.759399,14.710105,1.137106,-111.380302,294.500488,0.000000
109.700005,64.862068,-111.424782,-0.001479,0.004477,0.113711,288.520874,14.697954,1.137106,-111.424782,294.500488,0.000000
110.090004,64.812920,-111.469261,-0.001479,0.004477,0.113711,288.302277,14.686818,1.137106,-111.469261,294.500488,0.000000
110.480003,64.773445,-111.469261,-0.001483,0.004477,0.113711,288.126678,14.677873,1.137106,-111.469261,294.500488,0.000000
110.870003,64.730995,-111.469261,-0.001475,0.004477,0.113711,287.937836,14.668253,1.137106,-111.469261,294.500488,0.000000
111.260002,64.688545,-111.513741,-0.001483,0.004477,0.113711,287.749023,14.658634,1.137106,-111.513741,294.500488,0.000000
111.650002,64.650932,-111.558228,-0.001453,0.004477,0.113711,287.581696,14.650110,1.137106,-111.558228,294.500488,0.000000
112.040009,66.453224,-111.513741,-0.001470,0.004466,0.113433,295.598694,15.058517,1.134331,-111.513741,294.500488,0.000000
112.430008,66.410774,-111.602707,-0.001475,0.004466,0.113433,295.409882,15.048897,1.134331,-111.602707,294.500488,0.000000
112.820007,66.366463,-111.558228,-0.001466,0.004466,0.113433,295.212769,15.038856,1.134331,-111.558228,294.500488,0.000000
113.210007,66.322151,-111.602707,-0.001453,0.004466,0.113433,295.015656,15.028814,1.134331,-111.602707,294.500488,0.000000
113.600006,66.272987,-111.647186,-0.001457,0.004466,0.113433,294.796967,15.017673,1.134331,-111.647186,294.500488,0.000000
113.990005,66.228676,-111.647186,-0.001466,0.004466,0.113433,294.599854,15.007632,1.134331,-111.647186,294.500488,0.000000
114.380005,66.195534,-111.691666,-0.001462,0.004466,0.113433,294.452454,15.000122,1.134331,-111.691666,294.500488,0.000000
114.770004,66.146385,-111.691666,-0.001453,0.004466,0.113433,294.233826,14.988985,1.134331,-111.691666,294.500488,0.000000
115.160004,66.111015,-111.736153,-0.001475,0.004466,0.113433,294.076477,14.980970,1.134331,-111.736153,294.500488,0.000000
115.550003,66.077492,-111.736153,-0.001444,0.004466,0.113433,293.927368,14.973373,1.134331,-111.736153,294.500488,0.000000
115.940002,66.037651,-111.825111,-0.001453,0.004466,0.113433,293.750153,14.964346,1.134331,-111.825111,294.500488,0.000000
116.330002,65.990730,-111.869591,-0.001462,0.004466,0.113433,293.541443,14.953713,1.134331,-111.869591,294.500488,0.000000
116.720009,65.939339,-111.780632,-0.001453,0.004466,0.113433,293.312836,14.942067,1.134331,-111.780632,294.500488,0.000000
117.110008,65.884239,-111.869591,-0.001466,0.004466,0.113433,293.067719,14.929582,1.134331,-111.869591,294.500488,0.000000
117.500008,65.903221,-111.914070,-0.001462,0.004466,0.113433,293.152161,14.933884,1.134331,-111.914070,294.500488,0.000000
117.890007,65.870461,-111.825111,-0.001457,0.004466,0.113433,293.006439,14.926459,1.134331,-111.825111,294.500488,0.000000
118.280006,65.849236,-111.914070,-0.001466,0.004466,0.113433,292.912018,14.921650,1.134331,-111.914070,294.500488,0.000000
118.670006,65.794121,-111.914070,-0.001462,0.004466,0.113433,292.666870,14.909161,1.134331,-111.914070,294.500488,0.000000
119.060005,65.779594,-111.914070,-0.001457,0.004466,0.113433,292.602264,14.905869,1.134331,-111.914070,294.500488,0.000000
119.450005,65.751671,-112.047516,-0.001449,0.004466,0.113442,292.478027,14.899541,1.134418,-112.047516,294.500488,0.000000
119.840004,65.743111,-112.003036,-0.001457,0.004466,0.113442,292.439972,14.897602,1.134418,-112.003036,294.500488,0.000000
120.230003,65.674217,-112.047516,-0.001466,0.004466,0.113442,292.133514,14.881990,1.134418,-112.047516,294.500488,0.000000
120.620003,65.603844,-112.091995,-0.001462,0.004467,0.113459,291.820465,14.866044,1.134591,-112.091995,294.500488,0.000000
121.010002,65.577766,-112.047516,-0.001462,0.004467,0.113459,291.704468,14.860134,1.134591,-112.047516,294.500488,0.000000
121.400009,65.575172,-112.180962,-0.001457,0.004467,0.113468,291.692932,14.859547,1.134678,-112.180962,294.500488,0.000000
121.790009,65.551338,-112.136475,-0.001457,0.004468,0.113476,291.586914,14.854146,1.134765,-112.136475,294.500488,0.000000
122.180008,65.511116,-112.136475,-0.001466,0.004472,0.113598,291.407990,14.845031,1.135979,-112.136475,294.500488,0.000000
122.570007,65.490639,-112.136475,-0.001457,0.004472,0.113598,291.316925,14.840391,1.135979,-112.136475,294.500488,0.000000
122.960007,65.501060,-112.136475,-0.001457,0.004473,0.113615,291.363281,14.842752,1.136152,-112.136475,294.500488,0.000000
123.350006,65.448189,-112.225441,-0.001462,0.004473,0.113624,291.128082,14.830771,1.136239,-112.225441,294.500488,0.000000
123.740005,65.419884,-112.180962,-0.001457,0.004473,0.113624,291.002167,14.824358,1.136239,-112.180962,294.500488,0.000000
124.130005,65.372215,-112.225441,-0.001457,0.004475,0.113667,290.790131,14.813556,1.136673,-112.225441,294.500488,0.000000
124.520004,65.371849,-112.358879,-0.001444,0.004483,0.113867,290.788513,14.813473,1.138667,-112.358879,294.500488,0.000000
124.910004,65.380043,-112.314400,-0.001462,0.004484,0.113893,290.824951,14.815329,1.138928,-112.314400,294.500488,0.000000
125.300003,65.330147,-112.358879,-0.001483,0.004484,0.113901,290.602997,14.804023,1.139014,-112.358879,294.500488,0.000000
125.690002,65.328285,-112.314400,-0.001453,0.004487,0.113971,290.594727,14.803600,1.139708,-112.314400,294.500488,0.000000
126.080009,65.305565,-112.358879,-0.001462,0.004490,0.114049,290.493652,14.798452,1.140488,-112.358879,294.500488,0.000000
126.470009,65.350258,-112.403366,-0.001462,0.004492,0.114101,290.692474,14.808580,1.141009,-112.403366,294.500488,0.000000
126.860008,65.343925,-112.403366,-0.001483,0.004492,0.114101,290.664307,14.807145,1.141009,-112.403366,294.500488,0.000000
127.250008,65.296257,-112.492325,-0.001466,0.004493,0.114110,290.452271,14.796344,1.141096,-112.492325,294.500488,0.000000
127.640007,65.288063,-112.447845,-0.001453,0.004493,0.114110,290.415802,14.794487,1.141096,-112.447845,294.500488,0.000000
128.029999,65.269447,-112.447845,-0.001457,0.004493,0.114110,290.333008,14.790268,1.141096,-112.447845,294.500488,0.000000
128.420013,65.251198,-112.536804,-0.001457,0.004493,0.114110,290.251831,14.786133,1.141096,-112.536804,294.500488,0.000000
128.810013,65.225883,-112.447845,-0.001466,0.004493,0.114110,290.139221,14.780396,1.141096,-112.447845,294.500488,0.000000
129.200012,65.194969,-112.581284,-0.001466,0.004493,0.114118,290.001709,14.773392,1.141182,-112.581284,294.500488,0.000000
129.590012,65.236305,-112.581284,-0.001453,0.004495,0.114170,290.185577,14.782759,1.141703,-112.581284,294.500488,0.000000
129.980011,65.263115,-112.625771,-0.001457,0.004495,0.114170,290.304840,14.788833,1.141703,-112.625771,294.500488,0.000000
130.370010,65.251945,-112.714729,-0.001466,0.004495,0.114170,290.255157,14.786302,1.141703,-112.714729,294.500488,0.000000
130.760010,65.252693,-112.670250,-0.001440,0.004495,0.114170,290.258484,14.786471,1.141703,-112.670250,294.500488,0.000000
131.150009,65.233696,-112.670250,-0.001470,0.004495,0.114170,290.173981,14.782166,1.141703,-112.670250,294.500488,0.000000
131.540009,65.221779,-112.670250,-0.001449,0.004495,0.114170,290.120972,14.779467,1.141703,-112.670250,294.500488,0.000000
131.930008,65.197212,-112.714729,-0.001444,0.004495,0.114170,290.011688,14.773900,1.141703,-112.714729,294.500488,0.000000
132.320007,65.182686,-112.714729,-0.001457,0.004495,0.114170,289.947083,14.770608,1.141703,-112.714729,294.500488,0.000000
132.710007,65.152519,-112.759209,-0.001444,0.004495,0.114170,289.812866,14.763772,1.141703,-112.759209,294.500488,0.000000
133.100006,65.247108,-112.714729,-0.001457,0.004498,0.114248,290.233643,14.785206,1.142483,-112.714729,294.500488,0.000000
133.490005,65.260139,-112.803696,-0.001453,0.004498,0.114248,290.291595,14.788159,1.142483,-112.803696,294.500488,0.000000
133.880005,65.266090,-112.848175,-0.001466,0.004498,0.114248,290.318085,14.789508,1.142483,-112.848175,294.500488,0.000000
134.270004,65.251579,-112.892654,-0.001462,0.004498,0.114248,290.253510,14.786219,1.142483,-112.892654,294.500488,0.000000
134.660004,65.259392,-112.892654,-0.001466,0.004498,0.114248,290.288269,14.787990,1.142483,-112.892654,294.500488,0.000000
135.050003,65.239281,-112.892654,-0.001462,0.004498,0.114248,290.198822,14.783432,1.142483,-112.892654,294.500488,0.000000
135.440002,65.234444,-112.981613,-0.001453,0.004498,0.114248,290.177307,14.782336,1.142483,-112.981613,294.500488,0.000000
135.830002,65.218437,-112.937134,-0.001462,0.004498,0.114248,290.106110,14.778709,1.142483,-112.937134,294.500488,0.000000
136.220001,65.208000,-112.981613,-0.001453,0.004498,0.114248,290.059662,14.776343,1.142483,-112.981613,294.500488,0.000000
136.610001,65.202049,-112.937134,-0.001457,0.004498,0.114248,290.033203,14.774996,1.142483,-112.937134,294.500488,0.000000
137.000000,65.182686,-112.981613,-0.001449,0.004498,0.114248,289.947083,14.770608,1.142483,-112.981613,294.500488,0.000000
137.389999,65.156990,-113.026100,-0.001449,0.004498,0.114248,289.832764,14.764785,1.142483,-113.026100,294.500488,0.000000
137.780014,65.140984,-113.026100,-0.001444,0.004498,0.114248,289.761566,14.761158,1.142483,-113.026100,294.500488,0.000000
138.170013,65.114906,-113.115059,-0.001440,0.004498,0.114248,289.645569,14.755248,1.142483,-113.115059,294.500488,0.000000
138.560013,65.102623,-113.070580,-0.001449,0.004498,0.114248,289.590942,14.752465,1.142483,-113.070580,294.500488,0.000000
138.950012,65.094429,-113.115059,-0.001453,0.004499,0.114266,289.554474,14.750608,1.142657,-113.115059,294.500488,0.000000
139.340012,65.108955,-113.159538,-0.001462,0.004499,0.114274,289.619110,14.753900,1.142743,-113.159538,294.500488,0.000000
139.730011,65.529366,-113.070580,-0.001440,0.004504,0.114413,291.489166,14.849166,1.144131,-113.070580,294.500488,0.000000
140.120010,65.543510,-113.204018,-0.001470,0.004504,0.114413,291.552094,14.852372,1.144131,-113.204018,294.500488,0.000000
140.510010,65.554314,-113.248505,-0.001444,0.004504,0.114413,291.600159,14.854820,1.144131,-113.248505,294.500488,0.000000
140.900009,65.540169,-113.248505,-0.001453,0.004503,0.114378,291.537231,14.851615,1.143784,-113.248505,0.114413,0.000000
141.290009,65.428825,-113.337463,-0.001449,0.004490,0.114049,291.041962,14.826384,1.140488,-113.337463,0.113823,0.000000
141.680008,65.444466,-113.337463,-0.001444,0.004472,0.113598,291.111511,14.829928,1.135979,-113.337463,0.113173,0.000000
142.070007,65.329033,-113.337463,-0.001453,0.004447,0.112956,290.598053,14.803770,1.129561,-113.337463,0.112523,0.000000
142.460007,65.304817,-113.292984,-0.001436,0.004424,0.112358,290.490326,14.798283,1.123578,-113.292984,0.111872,0.000000
142.850006,65.292168,-113.337463,-0.001440,0.004401,0.111794,290.434082,14.795417,1.117941,-113.337463,0.111222,0.000000
143.240005,65.288811,-113.426422,-0.001436,0.004376,0.111161,290.419128,14.794656,1.111610,-113.426422,0.110571,0.000000
143.630005,65.234077,-113.381943,-0.001436,0.004350,0.110502,290.175659,14.782253,1.105019,-113.381943,0.109921,0.000000
144.020004,65.179329,-113.470909,-0.001462,0.004326,0.109869,289.932129,14.769847,1.098688,-113.470909,0.109270,0.000000
144.410004,65.112312,-113.426422,-0.001444,0.004299,0.109201,289.634033,14.754661,1.092011,-113.426422,0.108620,0.000000
144.800003,64.991661,-113.426422,-0.001453,0.004279,0.108689,289.097351,14.727321,1.086894,-113.426422,0.107970,0.000000
145.190002,64.459541,-113.515388,-0.001436,0.004251,0.107987,286.730347,14.606741,1.079869,-113.515388,0.107319,0.000000
145.580002,63.556160,-113.470909,-0.001440,0.004230,0.107449,282.711914,14.402032,1.074493,-113.470909,0.106669,0.000000
145.970001,62.729866,-113.515388,-0.001436,0.004209,0.106912,279.036377,14.214791,1.069116,-113.515388,0.106018,0.000000
146.360001,61.139091,-113.515388,-0.001427,0.004179,0.106157,271.960266,13.854317,1.061571,-113.515388,0.105368,0.000000
146.750000,59.617577,-113.559868,-0.001444,0.004159,0.105645,265.192230,13.509536,1.056454,-113.559868,0.104718,0.000000
147.139999,57.815292,-113.648827,-0.001436,0.004133,0.104969,257.175262,13.101132,1.049690,-113.648827,0.104076,0.000000
147.530014,55.544937,-113.604347,-0.001444,0.004106,0.104293,247.076218,12.586662,1.042926,-113.604347,0.103425,0.000000
147.920013,53.614563,-113.604347,-0.001436,0.004085,0.103764,238.489487,12.149234,1.037636,-113.604347,0.102775,0.000000
148.310013,51.116684,-113.737793,-0.001449,0.004060,0.103122,227.378372,11.583206,1.031218,-113.737793,0.102124,0.000000
148.700012,48.946877,-113.648827,-0.001453,0.004039,0.102584,217.726578,11.091520,1.025841,-113.648827,0.101474,0.000000
149.090012,46.006622,-113.693314,-0.001453,0.004009,0.101838,204.647675,10.425249,1.018383,-113.693314,0.100824,0.000000
149.480011,43.346390,-113.693314,-0.001457,0.003985,0.101223,192.814377,9.822432,1.012226,-113.693314,0.100173,0.000000
149.870010,40.765480,-113.693314,-0.001457,0.003959,0.100555,181.333908,9.237590,1.005548,-113.693314,0.099523,0.000000
150.260010,38.095940,-113.782272,-0.001462,0.003933,0.099904,169.459198,8.632664,0.999044,-113.782272,0.098872,0.000000
150.650009,35.685204,-113.782272,-0.001462,0.003913,0.099401,158.735718,8.086383,0.994014,-113.782272,0.098222,0.000000
151.040009,33.013428,-113.826752,-0.001470,0.003886,0.098708,146.851059,7.480949,0.987076,-113.826752,0.097572,0.000000
151.430008,29.802460,-113.782272,-0.001462,0.003858,0.097988,132.567963,6.753334,0.979878,-113.782272,0.096921,0.000000
151.820007,27.563011,-113.871231,-0.001470,0.003835,0.097398,122.606400,6.245867,0.973981,-113.871231,0.096271,0.000000
152.210007,24.959015,-113.871231,-0.001483,0.003808,0.096730,111.023247,5.655794,0.967304,-113.871231,0.095620,0.000000
152.600006,21.822144,-113.871231,-0.001475,0.003785,0.096132,97.069740,4.944969,0.961320,-113.871231,0.094970,0.000000
152.990005,18.431694,-114.004677,-0.001496,0.003753,0.095317,81.988274,4.176682,0.953168,-114.004677,0.094319,0.000000
153.380005,15.617676,-113.960197,-0.001483,0.003728,0.094684,69.470894,3.539016,0.946837,-113.960197,0.093669,0.000000
153.770004,13.008835,-113.915718,-0.001496,0.003704,0.094085,57.866188,2.947844,0.940853,-113.915718,0.093019,0.000000
154.160004,10.523247,-114.049156,-0.001496,0.003683,0.093548,46.809738,2.384602,0.935476,-114.049156,0.092368,0.000000
154.550003,7.582993,-114.004677,-0.001518,0.003655,0.092828,33.730835,1.718331,0.928278,-114.004677,0.091718,0.000000
154.940002,4.675514,-114.093643,-0.001513,0.003624,0.092047,20.797726,1.059487,0.920473,-114.093643,0.091067,0.000000
155.330002,2.164978,-114.138123,-0.001509,0.003601,0.091466,9.630303,0.490591,0.914663,-114.138123,0.090417,0.000000
155.720001,-0.181343,-114.093643,-0.001522,0.003575,0.090807,-0.806654,-0.041093,0.908072,-114.093643,0.089767,0.000000
156.110001,-0.824432,-114.138123,-0.001539,0.003547,0.090105,-3.667258,-0.186819,0.901048,-114.138123,0.089125,0.000000
156.500000,-0.026062,-114.138123,-0.001561,0.003523,0.089472,-0.115930,-0.005906,0.894717,-114.138123,0.088474,0.000000
156.890015,0.047295,-114.182602,-0.001613,0.003489,0.088622,0.210377,0.010717,0.886218,-114.182602,0.087824,0.000000
157.280014,0.087883,-114.182602,-0.001613,0.003469,0.088110,0.390923,0.019915,0.881101,-114.182602,0.087174,0.000000
157.670013,0.093094,-114.227081,-0.001651,0.003444,0.087468,0.414102,0.021095,0.874684,-114.227081,0.086523,0.000000
158.060013,0.053993,-114.271561,-0.001664,0.003417,0.086801,0.240174,0.012235,0.868006,-114.271561,0.085873,0.000000
158.450012,0.053627,-114.227081,-0.001690,0.003393,0.086176,0.238545,0.012152,0.861762,-114.227081,0.085222,0.000000
158.840012,0.035378,-114.360527,-0.001699,0.003369,0.085569,0.157367,0.008017,0.855692,-114.360527,0.084572,0.000000
159.230011,0.027184,-114.316048,-0.001720,0.003345,0.084953,0.120918,0.006160,0.849534,-114.316048,0.083921,0.000000
159.620010,0.051018,-114.316048,-0.001755,0.003316,0.084216,0.226938,0.011561,0.842163,-114.316048,0.083271,0.000000
160.000000,0.056602,-114.405006,-0.001768,0.003303,0.083895,0.251780,0.012826,0.838954,-114.405006,0.083765,0.000000