File: Data/compression 34/AutoNoHeating-15-34-reverse-1-1rere_11152024_201307.csv
Time (sec),S:Load (lbs),S:HL1 (DIM),S:LVDT (in),S:Position (in),Ch:Position (mm),Ch:Load (N),Ch:Stress (MPa),Ch:Strain (mm/mm),Ch:HL1 (DIM),Set Point (),Cycles ()
0.110000,-0.029411,-79.354019,-0.010555,-0.005699,-0.144749,-0.130828,-0.006665,-1.447486,-79.354019,-0.144549,0.000000
0.480000,-0.022713,-79.354019,-0.010559,-0.005638,-0.143214,-0.101031,-0.005147,-1.432137,-79.354019,-0.142572,0.000000
0.850000,-0.099045,-79.442978,-0.010421,-0.005423,-0.137733,-0.440573,-0.022444,-1.377328,-79.442978,-0.136415,0.000000
1.220000,-0.060692,-79.531944,-0.010197,-0.005177,-0.131506,-0.269971,-0.013753,-1.315061,-79.531944,-0.130240,0.000000
1.590000,0.011543,-79.576424,-0.009947,-0.004942,-0.125531,0.051347,0.002616,-1.255309,-79.576424,-0.124083,0.000000
1.960000,-0.038353,-79.487457,-0.009671,-0.004694,-0.119218,-0.170603,-0.008691,-1.192175,-79.487457,-0.117925,0.000000
2.330000,-0.052132,-79.531944,-0.009429,-0.004451,-0.113043,-0.231893,-0.011813,-1.130429,-79.531944,-0.111751,0.000000
2.700000,-0.069260,-79.531944,-0.009188,-0.004207,-0.106868,-0.308082,-0.015694,-1.068682,-79.531944,-0.105593,0.000000
3.070000,-0.005211,-79.665382,-0.008929,-0.003962,-0.100642,-0.023179,-0.001181,-1.006415,-79.665382,-0.099419,0.000000
3.440000,0.001122,-79.620903,-0.008670,-0.003724,-0.094580,0.004989,0.000254,-0.945796,-79.620903,-0.093261,0.000000
3.810000,-0.024948,-79.665382,-0.008433,-0.003483,-0.088457,-0.110975,-0.005653,-0.884570,-79.665382,-0.087104,0.000000
4.180000,-0.061066,-79.665382,-0.008188,-0.003248,-0.082508,-0.271634,-0.013838,-0.825078,-79.665382,-0.080929,0.000000
4.550000,-0.086761,-79.798828,-0.007925,-0.002996,-0.076090,-0.385934,-0.019660,-0.760904,-79.798828,-0.074772,0.000000
4.920000,-0.128838,-79.798828,-0.007675,-0.002752,-0.069907,-0.573098,-0.029195,-0.699071,-79.798828,-0.068598,0.000000
5.290000,-0.052872,-79.754349,-0.007442,-0.002513,-0.063828,-0.235185,-0.011981,-0.638278,-79.754349,-0.062440,0.000000
5.660000,-0.010796,-79.798828,-0.007170,-0.002268,-0.057601,-0.048021,-0.002446,-0.576011,-79.798828,-0.056283,0.000000
6.030000,0.006706,-79.843307,-0.006920,-0.002030,-0.051557,0.029831,0.001520,-0.515566,-79.843307,-0.050108,0.000000
6.400000,-0.046913,-79.843307,-0.006687,-0.001784,-0.045321,-0.208680,-0.010631,-0.453212,-79.843307,-0.043951,0.000000
6.770000,-0.032021,-79.976753,-0.006437,-0.001534,-0.038964,-0.142435,-0.007256,-0.389645,-79.976753,-0.037776,0.000000
7.140000,-0.030533,-79.932266,-0.006178,-0.001294,-0.032868,-0.135817,-0.006919,-0.328679,-79.932266,-0.031619,0.000000
7.510000,0.004097,-79.932266,-0.005937,-0.001052,-0.026711,0.018224,0.000928,-0.267106,-79.932266,-0.025462,0.000000
7.880001,-0.009308,-79.932266,-0.005696,-0.000814,-0.020666,-0.041403,-0.002109,-0.206660,-79.932266,-0.019287,0.000000
8.250000,-0.009308,-79.932266,-0.005433,-0.000573,-0.014552,-0.041403,-0.002109,-0.145520,-79.932266,-0.013130,0.000000
8.620001,-0.046547,-80.065712,-0.005200,-0.000326,-0.008291,-0.207051,-0.010548,-0.082907,-80.065712,-0.006955,0.000000
8.990001,0.099426,-80.021233,-0.004932,-0.000082,-0.002081,0.442270,0.022530,-0.020813,-80.021233,-0.000798,0.000000
9.360001,0.160126,-80.065712,-0.004907,-0.000010,-0.000260,0.712275,0.036285,-0.002602,-80.065712,-0.000026,0.000000
9.730000,0.145973,-80.065712,-0.004915,-0.000010,-0.000260,0.649321,0.033078,-0.002602,-80.065712,0.000312,0.000000
10.100000,0.147835,-80.110191,-0.004919,-0.000010,-0.000251,0.657602,0.033500,-0.002515,-80.110191,0.000928,0.000000
10.470000,0.338860,-80.199158,-0.004889,0.000023,0.000572,1.507323,0.076787,0.005724,-80.199158,0.001544,0.000000
10.840000,0.458023,-80.110191,-0.004872,0.000045,0.001136,2.037388,0.103790,0.011361,-80.110191,0.002159,0.000000
11.210001,0.591705,-80.199158,-0.004855,0.000067,0.001691,2.632037,0.134082,0.016911,-80.199158,0.002775,0.000000
11.580001,0.766716,-80.243637,-0.004833,0.000091,0.002315,3.410523,0.173740,0.023155,-80.243637,0.003391,0.000000
11.950001,0.984184,-80.288116,-0.004820,0.000115,0.002923,4.377870,0.223019,0.029226,-80.288116,0.004007,0.000000
12.320001,1.264954,-80.288116,-0.004773,0.000140,0.003547,5.626795,0.286643,0.035470,-80.288116,0.004622,0.000000
12.690001,1.638443,-80.332596,-0.004756,0.000167,0.004241,7.288158,0.371276,0.042407,-80.332596,0.005247,0.000000
13.060000,1.792976,-80.332596,-0.004747,0.000183,0.004657,7.975557,0.406294,0.046570,-80.332596,0.005862,0.000000
13.430000,2.157532,-80.377075,-0.004721,0.000216,0.005498,9.597180,0.488904,0.054982,-80.377075,0.006478,0.000000
13.800000,2.398079,-80.332596,-0.004691,0.000236,0.005993,10.667188,0.543412,0.059925,-80.332596,0.007094,0.000000
14.170001,2.657997,-80.466042,-0.004669,0.000258,0.006548,11.823361,0.602311,0.065476,-80.466042,0.007710,0.000000
14.540001,3.148781,-80.510521,-0.004631,0.000288,0.007319,14.006476,0.713524,0.073194,-80.510521,0.008325,0.000000
14.910001,3.226982,-80.466042,-0.004622,0.000305,0.007736,14.354333,0.731245,0.077357,-80.466042,0.008941,0.000000
15.280001,3.463814,-80.510521,-0.004605,0.000324,0.008239,15.407813,0.784911,0.082386,-80.510521,0.009557,0.000000
15.650001,3.905815,-80.510521,-0.004592,0.000356,0.009036,17.373934,0.885070,0.090365,-80.510521,0.010173,0.000000
16.020000,3.913635,-80.599480,-0.004566,0.000370,0.009409,17.408720,0.886842,0.094094,-80.599480,0.010797,0.000000
16.390001,4.415970,-80.599480,-0.004523,0.000407,0.010346,19.643215,1.000673,0.103460,-80.599480,0.011413,0.000000
16.760000,4.564171,-80.599480,-0.004506,0.000431,0.010936,20.302446,1.034256,0.109357,-80.599480,0.012028,0.000000
17.130001,4.803978,-80.599480,-0.004497,0.000454,0.011543,21.369162,1.088597,0.115428,-80.599480,0.012644,0.000000
17.500000,5.113052,-80.688446,-0.004462,0.000482,0.012237,22.743994,1.158634,0.122366,-80.688446,0.013260,0.000000
17.870001,5.083260,-80.732925,-0.004432,0.000497,0.012618,22.611467,1.151883,0.126181,-80.732925,0.013876,0.000000
18.240002,5.457497,-80.777405,-0.004419,0.000523,0.013286,24.276157,1.236686,0.132859,-80.777405,0.014491,0.000000
18.610001,5.738632,-80.732925,-0.004376,0.000553,0.014049,25.526711,1.300393,0.140491,-80.732925,0.015107,0.000000
18.980001,5.825394,-80.777405,-0.004359,0.000573,0.014552,25.912645,1.320053,0.145520,-80.777405,0.015731,0.000000
19.350000,5.948280,-80.866371,-0.004342,0.000594,0.015090,26.459272,1.347900,0.150897,-80.866371,0.016347,0.000000
19.720001,6.091644,-80.866371,-0.004324,0.000621,0.015775,27.096987,1.380386,0.157748,-80.866371,0.016963,0.000000
20.090000,6.563065,-80.910851,-0.004290,0.000648,0.016469,29.193970,1.487212,0.164686,-80.910851,0.017579,0.000000
20.460001,6.836014,-80.910851,-0.004260,0.000679,0.017240,30.408108,1.549063,0.172404,-80.910851,0.018194,0.000000
20.830002,6.802872,-80.910851,-0.004247,0.000694,0.017631,30.260685,1.541553,0.176307,-80.910851,0.018810,0.000000
21.200001,7.025925,-80.955330,-0.004234,0.000717,0.018212,31.252874,1.592097,0.182117,-80.955330,0.019426,0.000000
21.570002,7.349892,-81.044296,-0.004186,0.000746,0.018949,32.693951,1.665509,0.189489,-81.044296,0.020042,0.000000
21.940001,7.251587,-81.044296,-0.004165,0.000760,0.019296,32.256668,1.643233,0.192958,-81.044296,0.020657,0.000000
22.310001,7.828392,-80.999809,-0.004143,0.000797,0.020232,34.822426,1.773939,0.202324,-80.999809,0.021282,0.000000
22.680000,7.841797,-81.044296,-0.004135,0.000818,0.020779,34.882053,1.776977,0.207787,-81.044296,0.021897,0.000000
23.050001,8.064476,-81.088776,-0.004105,0.000841,0.021351,35.872581,1.827436,0.213511,-81.088776,0.022513,0.000000
23.420002,8.281563,-81.133255,-0.004083,0.000867,0.022028,36.838230,1.876629,0.220275,-81.133255,0.023129,0.000000
23.790001,8.403702,-81.177734,-0.004057,0.000887,0.022522,37.381531,1.904306,0.225219,-81.177734,0.023745,0.000000
24.160002,8.873642,-81.177734,-0.004027,0.000918,0.023328,39.471931,2.010796,0.233284,-81.177734,0.024360,0.000000
24.530001,8.843475,-81.177734,-0.004001,0.000942,0.023918,39.337742,2.003960,0.239181,-81.177734,0.024976,0.000000
24.900002,8.916832,-81.177734,-0.003975,0.000964,0.024482,39.664051,2.020583,0.244818,-81.177734,0.025592,0.000000
25.270000,9.312668,-81.266701,-0.003945,0.000994,0.025245,41.424816,2.110281,0.252449,-81.266701,0.026208,0.000000
25.640001,9.157761,-81.266701,-0.003928,0.001009,0.025627,40.735752,2.075178,0.256265,-81.266701,0.026832,0.000000
26.010002,9.494011,-81.311180,-0.003893,0.001029,0.026147,42.231468,2.151374,0.261469,-81.311180,0.027448,0.000000
26.380001,9.880531,-81.355659,-0.003863,0.001059,0.026910,43.950798,2.238960,0.269100,-81.355659,0.028063,0.000000
26.750002,9.870476,-81.355659,-0.003850,0.001080,0.027422,43.906071,2.236682,0.274217,-81.355659,0.028679,0.000000
27.120001,10.195930,-81.355659,-0.003833,0.001112,0.028246,45.353764,2.310431,0.282455,-81.355659,0.029295,0.000000
27.490002,10.371323,-81.400139,-0.003807,0.001135,0.028827,46.133945,2.350175,0.288266,-81.400139,0.029911,0.000000
27.860001,10.351212,-81.489105,-0.003764,0.001153,0.029278,46.044487,2.345618,0.292775,-81.489105,0.030526,0.000000
28.230001,10.910889,-81.444618,-0.003738,0.001186,0.030136,48.534058,2.472443,0.301361,-81.444618,0.031142,0.000000
28.600002,10.795082,-81.489105,-0.003721,0.001206,0.030630,48.018925,2.446201,0.306304,-81.489105,0.031758,0.000000
28.970001,11.056862,-81.533585,-0.003678,0.001233,0.031324,49.183376,2.505521,0.313242,-81.533585,0.032382,0.000000
29.340002,11.057228,-81.578064,-0.003660,0.001251,0.031766,49.185005,2.505604,0.317665,-81.578064,0.032998,0.000000
29.710001,11.317894,-81.533585,-0.003635,0.001279,0.032478,50.344505,2.564672,0.324776,-81.533585,0.033614,0.000000
30.080002,11.801605,-81.533585,-0.003617,0.001309,0.033258,52.496162,2.674282,0.332581,-81.533585,0.034229,0.000000
30.450001,11.749474,-81.622543,-0.003583,0.001331,0.033796,52.264267,2.662469,0.337958,-81.622543,0.034845,0.000000
30.820002,11.968056,-81.622543,-0.003566,0.001357,0.034464,53.236572,2.712000,0.344636,-81.622543,0.035461,0.000000
31.190001,11.924484,-81.667023,-0.003535,0.001377,0.034975,53.042755,2.702127,0.349752,-81.667023,0.036077,0.000000
31.560001,12.010506,-81.711510,-0.003518,0.001396,0.035470,53.425396,2.721619,0.354695,-81.711510,0.036692,0.000000
31.930002,12.560867,-81.711510,-0.003471,0.001430,0.036328,55.873528,2.846333,0.363281,-81.711510,0.037308,0.000000
32.300003,12.485275,-81.711510,-0.003449,0.001452,0.036892,55.537277,2.829204,0.368918,-81.711510,0.037932,0.000000
32.670002,12.612259,-81.800468,-0.003415,0.001476,0.037481,56.102131,2.857979,0.374815,-81.800468,0.038548,0.000000
33.040001,12.742958,-81.844948,-0.003385,0.001500,0.038097,56.683510,2.887596,0.380972,-81.844948,0.039164,0.000000
33.410000,12.770142,-81.844948,-0.003376,0.001519,0.038592,56.804428,2.893755,0.385915,-81.844948,0.039780,0.000000
33.780003,13.053520,-81.933914,-0.003350,0.001547,0.039285,58.064957,2.957970,0.392853,-81.933914,0.040395,0.000000
34.150002,13.296303,-81.800468,-0.003311,0.001572,0.039927,59.144909,3.012985,0.399271,-81.800468,0.041011,0.000000
34.520000,13.299660,-81.933914,-0.003298,0.001598,0.040577,59.159840,3.013746,0.405775,-81.933914,0.041627,0.000000
34.890003,13.625114,-81.978394,-0.003260,0.001624,0.041254,60.607536,3.087495,0.412539,-81.978394,0.042243,0.000000
35.260002,13.363708,-81.933914,-0.003229,0.001640,0.041653,59.444744,3.028260,0.416529,-81.933914,0.042858,0.000000
35.630001,13.538719,-81.978394,-0.003212,0.001665,0.042303,60.223232,3.067918,0.423033,-81.978394,0.043483,0.000000
36.000000,14.310280,-81.978394,-0.003191,0.001697,0.043110,63.655304,3.242756,0.431098,-81.978394,0.044098,0.000000
36.370003,13.948700,-82.067352,-0.003169,0.001715,0.043561,62.046917,3.160821,0.435607,-82.067352,0.044714,0.000000
36.740002,14.121483,-82.067352,-0.003130,0.001737,0.044107,62.815495,3.199974,0.441071,-82.067352,0.045330,0.000000
37.110001,14.440231,-82.111839,-0.003100,0.001762,0.044749,64.233360,3.272203,0.447488,-82.111839,0.045946,0.000000
37.480003,14.270058,-82.111839,-0.003074,0.001783,0.045287,63.476387,3.233641,0.452865,-82.111839,0.046561,0.000000
37.850002,15.042358,-82.111839,-0.003022,0.001817,0.046162,66.911751,3.408647,0.461624,-82.111839,0.047177,0.000000
38.220001,14.758240,-82.156319,-0.003014,0.001838,0.046683,65.647926,3.344265,0.466828,-82.156319,0.047793,0.000000
38.590000,15.024490,-82.289757,-0.002984,0.001862,0.047298,66.832268,3.404598,0.472985,-82.289757,0.048409,0.000000
38.960003,15.095238,-82.289757,-0.002953,0.001886,0.047906,67.146973,3.420630,0.479055,-82.289757,0.049033,0.000000
39.330002,15.217751,-82.245277,-0.002919,0.001908,0.048469,67.691933,3.448391,0.484692,-82.245277,0.049649,0.000000
39.700001,15.773697,-82.245277,-0.002884,0.001938,0.049224,70.164909,3.574371,0.492237,-82.245277,0.050264,0.000000
40.070004,15.697365,-82.289757,-0.002867,0.001961,0.049805,69.825363,3.557074,0.498048,-82.289757,0.050880,0.000000
40.440002,15.279190,-82.378723,-0.002833,0.001979,0.050273,67.965233,3.462314,0.502731,-82.378723,0.051496,0.000000
40.810001,16.046280,-82.423203,-0.002802,0.002012,0.051097,71.377419,3.636139,0.510969,-82.423203,0.052112,0.000000
41.180000,15.432610,-82.423203,-0.002772,0.002020,0.051296,68.647675,3.497079,0.512964,-82.423203,0.052727,0.000000
41.550003,16.464821,-82.467682,-0.002734,0.002060,0.052328,73.239182,3.730982,0.523284,-82.467682,0.053343,0.000000
41.920002,16.465942,-82.423203,-0.002712,0.002083,0.052918,73.244171,3.731236,0.529181,-82.423203,0.053967,0.000000
42.290001,16.384392,-82.512161,-0.002695,0.002103,0.053404,72.881416,3.712756,0.534038,-82.512161,0.054583,0.000000
42.660004,16.366516,-82.467682,-0.002652,0.002124,0.053950,72.801903,3.708706,0.539501,-82.467682,0.055199,0.000000
43.030003,16.382904,-82.512161,-0.002630,0.002146,0.054496,72.874794,3.712419,0.544965,-82.512161,0.055815,0.000000
43.400002,16.736282,-82.467682,-0.002591,0.002175,0.055234,74.446701,3.792496,0.552336,-82.467682,0.056430,0.000000
43.770000,17.268028,-82.556648,-0.002561,0.002205,0.055997,76.812027,3.912991,0.559968,-82.556648,0.057046,0.000000
44.140003,17.138069,-82.601128,-0.002552,0.002223,0.056474,76.233940,3.883542,0.564737,-82.601128,0.057662,0.000000
44.510002,17.197281,-82.645607,-0.002518,0.002245,0.057020,76.497330,3.896960,0.570201,-82.645607,0.058278,0.000000
44.880001,17.479912,-82.645607,-0.002471,0.002270,0.057662,77.754532,3.961004,0.576618,-82.645607,0.058893,0.000000
45.250004,17.521248,-82.734566,-0.002449,0.002292,0.058208,77.938400,3.970371,0.582082,-82.734566,0.059518,0.000000
45.620003,18.513992,-82.690086,-0.002410,0.002330,0.059179,82.354347,4.195331,0.591795,-82.690086,0.060133,0.000000
45.990002,18.138268,-82.734566,-0.002380,0.002351,0.059708,80.683044,4.110190,0.597085,-82.734566,0.060749,0.000000
46.360001,18.463348,-82.779053,-0.002345,0.002377,0.060368,82.129074,4.183855,0.603676,-82.779053,0.061365,0.000000
46.730003,18.275673,-82.779053,-0.002302,0.002397,0.060888,81.294250,4.141326,0.608879,-82.779053,0.061981,0.000000
47.100002,18.071983,-82.823532,-0.002289,0.002414,0.061313,80.388199,4.095170,0.613129,-82.823532,0.062596,0.000000
47.470001,18.913544,-82.868011,-0.002259,0.002444,0.062076,84.131645,4.285871,0.620760,-82.868011,0.063212,0.000000
47.840004,19.048340,-82.868011,-0.002233,0.002469,0.062700,84.731247,4.316416,0.627004,-82.868011,0.063828,0.000000
48.210003,19.033447,-82.956970,-0.002212,0.002489,0.063221,84.665001,4.313041,0.632208,-82.956970,0.064444,0.000000
48.580002,19.425926,-82.956970,-0.002156,0.002520,0.064001,86.410835,4.401978,0.640013,-82.956970,0.065068,0.000000
48.950001,19.490349,-82.912491,-0.002156,0.002542,0.064556,86.697403,4.416576,0.645563,-82.912491,0.065684,0.000000
49.320004,19.740211,-82.868011,-0.002130,0.002566,0.065181,87.808846,4.473196,0.651807,-82.868011,0.066299,0.000000
49.690002,20.066780,-83.001457,-0.002087,0.002595,0.065900,89.261497,4.547197,0.659005,-83.001457,0.066915,0.000000
50.060001,19.927139,-83.001457,-0.002052,0.002616,0.066456,88.640343,4.515554,0.664555,-83.001457,0.067531,0.000000
50.430004,20.031036,-83.045937,-0.002031,0.002638,0.067011,89.102501,4.539098,0.670105,-83.045937,0.068147,0.000000
50.800003,20.264885,-83.090416,-0.002001,0.002663,0.067652,90.142708,4.592088,0.676523,-83.090416,0.068762,0.000000
51.170002,20.309196,-83.090416,-0.001979,0.002680,0.068060,90.339821,4.602129,0.680599,-83.090416,0.069378,0.000000
51.540001,21.363014,-83.223862,-0.001940,0.002717,0.069005,95.027435,4.840928,0.690051,-83.223862,0.069994,0.000000
51.910004,21.342529,-83.179375,-0.001919,0.002741,0.069612,94.936310,4.836287,0.696122,-83.179375,0.070618,0.000000
52.280003,21.390938,-83.179375,-0.001884,0.002762,0.070159,95.151642,4.847256,0.701586,-83.179375,0.071234,0.000000
52.650002,21.667236,-83.268341,-0.001858,0.002786,0.070766,96.380684,4.909866,0.707656,-83.268341,0.071850,0.000000
53.020004,21.819542,-83.268341,-0.001824,0.002807,0.071295,97.058167,4.944379,0.712946,-83.268341,0.072465,0.000000
53.390003,22.714722,-83.312820,-0.001802,0.002837,0.072066,101.040131,5.147230,0.720665,-83.312820,0.073081,0.000000
53.760002,22.674507,-83.357300,-0.001772,0.002859,0.072613,100.861244,5.138117,0.726128,-83.357300,0.073697,0.000000
54.130001,22.764992,-83.312820,-0.001725,0.002881,0.073177,101.263741,5.158621,0.731765,-83.312820,0.074313,0.000000
54.500004,23.092682,-83.357300,-0.001729,0.002906,0.073801,102.721382,5.232876,0.738009,-83.357300,0.074928,0.000000
54.870003,22.977249,-83.357300,-0.001703,0.002924,0.074261,102.207909,5.206719,0.742605,-83.357300,0.075544,0.000000
55.240002,24.227669,-83.490746,-0.001660,0.002955,0.075058,107.770050,5.490068,0.750584,-83.490746,0.076168,0.000000
55.610004,24.624619,-83.401787,-0.001647,0.002980,0.075683,109.535774,5.580019,0.756828,-83.401787,0.076784,0.000000
55.980003,25.216324,-83.490746,-0.001587,0.003008,0.076394,112.167809,5.714101,0.763939,-83.490746,0.077400,0.000000
56.350002,25.110191,-83.446266,-0.001574,0.003029,0.076932,111.695709,5.690051,0.769316,-83.446266,0.078016,0.000000
56.720001,25.115784,-83.446266,-0.001548,0.003048,0.077426,111.720589,5.691318,0.774259,-83.446266,0.078631,0.000000
57.090004,26.235878,-83.535225,-0.001531,0.003079,0.078198,116.703011,5.945135,0.781977,-83.535225,0.079247,0.000000
57.460003,26.626869,-83.579704,-0.001492,0.003100,0.078744,118.442230,6.033735,0.787441,-83.579704,0.079863,0.000000
57.830002,26.776192,-83.579704,-0.001470,0.003121,0.079273,119.106453,6.067572,0.792731,-83.579704,0.080479,0.000000
58.200005,27.105370,-83.579704,-0.001457,0.003142,0.079819,120.570709,6.142165,0.798195,-83.579704,0.081094,0.000000
58.570004,27.543274,-83.624191,-0.001423,0.003167,0.080453,122.518600,6.241395,0.804525,-83.624191,0.081719,0.000000
58.940002,28.791100,-83.624191,-0.001406,0.003197,0.081198,128.069214,6.524157,0.811983,-83.624191,0.082334,0.000000
59.310001,29.197731,-83.713150,-0.001384,0.003223,0.081875,129.877991,6.616301,0.818748,-83.713150,0.082950,0.000000
59.680004,29.194748,-83.713150,-0.001358,0.003242,0.082352,129.864731,6.615624,0.823518,-83.713150,0.083566,0.000000
60.050003,30.325272,-83.713150,-0.001328,0.003269,0.083037,134.893539,6.871805,0.830369,-83.713150,0.084182,0.000000
60.420002,30.413895,-83.757629,-0.001315,0.003289,0.083549,135.287766,6.891887,0.835485,-83.757629,0.084797,0.000000
60.790005,30.668968,-83.802109,-0.001311,0.003309,0.084060,136.422379,6.949688,0.840602,-83.802109,0.085413,0.000000
61.160004,32.571793,-83.891075,-0.001268,0.003346,0.084997,144.886566,7.380874,0.849968,-83.891075,0.086029,0.000000
61.530003,33.093857,-83.891075,-0.001246,0.003370,0.085595,147.208832,7.499175,0.855952,-83.891075,0.086645,0.000000
61.900002,33.662102,-83.846596,-0.001224,0.003391,0.086124,149.736511,7.627941,0.861242,-83.846596,0.087269,0.000000
62.270004,33.954414,-83.891075,-0.001199,0.003411,0.086645,151.036774,7.694180,0.866445,-83.891075,0.087885,0.000000
62.640003,34.807518,-83.891075,-0.001173,0.003436,0.087286,154.831573,7.887496,0.872863,-83.891075,0.088500,0.000000
63.010002,36.196838,-83.935555,-0.001173,0.003468,0.088093,161.011581,8.202321,0.880928,-83.935555,0.089116,0.000000
63.380005,36.686134,-84.024513,-0.001155,0.003488,0.088596,163.188080,8.313197,0.885958,-84.024513,0.089732,0.000000
63.750004,36.679810,-84.024513,-0.001125,0.003505,0.089029,163.159943,8.311764,0.890294,-84.024513,0.090348,0.000000
64.120003,38.534592,-83.980034,-0.001104,0.003536,0.089819,171.410431,8.732063,0.898186,-83.980034,0.090963,0.000000
64.490005,39.250298,-84.069000,-0.001087,0.003561,0.090452,174.594040,8.894245,0.904516,-84.069000,0.091579,0.000000
64.860001,40.568863,-84.113480,-0.001052,0.003588,0.091137,180.459320,9.193035,0.911367,-84.113480,0.092203,0.000000
65.230003,41.131523,-84.113480,-0.001052,0.003608,0.091631,182.962158,9.320537,0.916311,-84.113480,0.092819,0.000000
65.600006,41.761574,-84.113480,-0.001018,0.003628,0.092151,185.764755,9.463308,0.921514,-84.113480,0.093435,0.000000
65.970001,42.742401,-84.202438,-0.001005,0.003652,0.092767,190.127701,9.685567,0.927671,-84.202438,0.094051,0.000000
66.340004,43.901230,-84.202438,-0.000987,0.003678,0.093409,195.282425,9.948160,0.934089,-84.202438,0.094666,0.000000
66.710007,45.128197,-84.246918,-0.000961,0.003705,0.094103,200.740250,10.226195,0.941027,-84.246918,0.095282,0.000000
67.080002,46.634071,-84.246918,-0.000940,0.003733,0.094814,207.438705,10.567431,0.948138,-84.246918,0.095898,0.000000
67.450005,47.730331,-84.291405,-0.000936,0.003759,0.095473,212.315125,10.815848,0.954729,-84.291405,0.096514,0.000000
67.820000,49.049644,-84.246918,-0.000918,0.003785,0.096132,218.183716,11.114808,0.961320,-84.246918,0.097129,0.000000
68.190002,49.188171,-84.335884,-0.000892,0.003797,0.096436,218.799911,11.146199,0.964355,-84.335884,0.097754,0.000000
68.560005,50.012230,-84.335884,-0.000888,0.003818,0.096973,222.465515,11.332933,0.969732,-84.335884,0.098369,0.000000
68.930000,52.647514,-84.424843,-0.000862,0.003854,0.097901,234.187836,11.930097,0.979011,-84.424843,0.098985,0.000000
69.300003,53.306236,-84.424843,-0.000854,0.003872,0.098352,237.117981,12.079366,0.983521,-84.424843,0.099601,0.000000
69.670006,55.036278,-84.380363,-0.000845,0.003901,0.099098,244.813583,12.471399,0.990979,-84.380363,0.100217,0.000000
70.040001,56.298622,-84.469330,-0.000832,0.003925,0.099696,250.428772,12.757450,0.996963,-84.469330,0.100832,0.000000
70.410004,57.073158,-84.513809,-0.000819,0.003944,0.100173,253.874084,12.932963,1.001732,-84.513809,0.101448,0.000000
70.780006,59.120834,-84.513809,-0.000789,0.003976,0.100980,262.982605,13.396973,1.009798,-84.513809,0.102064,0.000000
71.150002,60.580536,-84.558289,-0.000776,0.003999,0.101587,269.475677,13.727745,1.015868,-84.558289,0.102680,0.000000
71.520004,61.327141,-84.513809,-0.000776,0.004017,0.102020,272.796753,13.896929,1.020204,-84.513809,0.103304,0.000000
71.890007,63.416893,-84.602768,-0.000755,0.004047,0.102801,282.092438,14.370473,1.028009,-84.602768,0.103920,0.000000
72.260002,64.572365,-84.691734,-0.000733,0.004069,0.103347,287.232239,14.632307,1.033473,-84.691734,0.104535,0.000000
72.630005,66.126274,-84.602768,-0.000720,0.004084,0.103738,294.144348,14.984428,1.037375,-84.602768,0.103980,0.000000
73.000000,65.053474,-84.602768,-0.000707,0.004083,0.103720,289.372314,14.741328,1.037202,-84.602768,294.500488,0.000000
73.370003,66.294960,-84.691734,-0.000686,0.004054,0.102966,294.894714,15.022653,1.029657,-84.691734,294.500488,0.000000
73.740005,65.471642,-84.736214,-0.000694,0.004069,0.103356,291.232422,14.836086,1.033560,-84.736214,294.500488,0.000000
74.110001,65.316368,-84.780693,-0.000690,0.004107,0.104310,290.541718,14.800900,1.043099,-84.780693,294.500488,0.000000
74.480003,65.502556,-84.780693,-0.000690,0.004116,0.104553,291.369934,14.843092,1.045527,-84.780693,294.500488,0.000000
74.850006,65.166679,-84.780693,-0.000677,0.004117,0.104561,289.875854,14.766981,1.045614,-84.780693,294.500488,0.000000
75.220001,65.257164,-84.780693,-0.000694,0.004122,0.104709,290.278351,14.787484,1.047088,-84.780693,294.500488,0.000000
75.590004,65.102257,-84.914139,-0.000681,0.004125,0.104787,289.589294,14.752382,1.047869,-84.914139,294.500488,0.000000
75.960007,65.127953,-84.914139,-0.000664,0.004131,0.104917,289.703613,14.758204,1.049170,-84.914139,294.500488,0.000000
76.330002,65.109703,-84.914139,-0.000673,0.004137,0.105073,289.622437,14.754069,1.050731,-84.914139,294.500488,0.000000
76.700005,65.331261,-84.914139,-0.000677,0.004137,0.105090,290.607971,14.804276,1.050904,-84.914139,294.500488,0.000000
77.070007,65.101875,-84.958618,-0.000677,0.004137,0.105090,289.587616,14.752295,1.050904,-84.958618,294.500488,0.000000
77.440002,65.526756,-85.003098,-0.000660,0.004145,0.105281,291.477570,14.848576,1.052812,-85.003098,294.500488,0.000000
77.810005,65.402763,-85.003098,-0.000668,0.004145,0.105290,290.926025,14.820478,1.052899,-85.003098,294.500488,0.000000
78.180000,65.218437,-84.958618,-0.000664,0.004145,0.105290,290.106110,14.778709,1.052899,-84.958618,294.500488,0.000000
78.550003,65.014748,-85.047577,-0.000664,0.004146,0.105299,289.200043,14.732553,1.052985,-85.047577,294.500488,0.000000
78.920006,65.592293,-85.092056,-0.000655,0.004155,0.105541,291.769104,14.863425,1.055414,-85.092056,294.500488,0.000000
79.290001,65.560265,-85.181023,-0.000660,0.004155,0.105541,291.626617,14.856169,1.055414,-85.181023,294.500488,0.000000
79.660004,65.421745,-85.181023,-0.000638,0.004155,0.105541,291.010468,14.824780,1.055414,-85.181023,294.500488,0.000000
80.030006,65.265724,-85.136543,-0.000642,0.004156,0.105550,290.316437,14.789425,1.055500,-85.136543,294.500488,0.000000
80.400002,65.135765,-85.225502,-0.000651,0.004156,0.105559,289.738342,14.759975,1.055587,-85.225502,294.500488,0.000000
80.770004,65.020699,-85.269981,-0.000638,0.004156,0.105567,289.226501,14.733901,1.055674,-85.269981,294.500488,0.000000
81.140007,65.660072,-85.269981,-0.000638,0.004164,0.105776,292.070587,14.878785,1.057755,-85.269981,294.500488,0.000000
81.510002,65.586342,-85.225502,-0.000634,0.004164,0.105776,291.742615,14.862078,1.057755,-85.225502,294.500488,0.000000
81.880005,65.515587,-85.269981,-0.000625,0.004164,0.105776,291.427887,14.846044,1.057755,-85.269981,294.500488,0.000000
82.250008,65.356209,-85.225502,-0.000638,0.004165,0.105784,290.718933,14.809928,1.057842,-85.225502,294.500488,0.000000
82.620003,65.245613,-85.314461,-0.000651,0.004165,0.105784,290.226990,14.784867,1.057842,-85.314461,294.500488,0.000000
82.990005,65.174492,-85.403427,-0.000647,0.004166,0.105819,289.910614,14.768751,1.058189,-85.403427,294.500488,0.000000
83.360001,65.069481,-85.403427,-0.000629,0.004166,0.105819,289.443512,14.744955,1.058189,-85.403427,294.500488,0.000000
83.730003,65.025551,-85.314461,-0.000625,0.004167,0.105836,289.248108,14.735001,1.058362,-85.314461,294.500488,0.000000
84.100006,65.043785,-85.403427,-0.000642,0.004170,0.105906,289.329193,14.739132,1.059056,-85.403427,294.500488,0.000000
84.470001,65.044167,-85.447906,-0.000625,0.004170,0.105906,289.330902,14.739220,1.059056,-85.447906,294.500488,0.000000
84.840004,65.003197,-85.492386,-0.000642,0.004170,0.105914,289.148651,14.729935,1.059143,-85.492386,294.500488,0.000000
85.210007,65.336845,-85.492386,-0.000629,0.004176,0.106062,290.632812,14.805541,1.060617,-85.492386,294.500488,0.000000
85.580002,65.374077,-85.536865,-0.000634,0.004176,0.106062,290.798431,14.813977,1.060617,-85.536865,294.500488,0.000000
85.950005,65.329399,-85.492386,-0.000629,0.004176,0.106062,290.599670,14.803853,1.060617,-85.492386,294.500488,0.000000
86.320007,65.288063,-85.581352,-0.000647,0.004176,0.106062,290.415802,14.794487,1.060617,-85.581352,294.500488,0.000000
86.690002,65.221046,-85.670311,-0.000629,0.004176,0.106062,290.117706,14.779301,1.060617,-85.670311,294.500488,0.000000
87.060005,65.147682,-85.670311,-0.000612,0.004176,0.106062,289.791351,14.762676,1.060617,-85.670311,294.500488,0.000000
87.430008,65.062782,-85.625832,-0.000629,0.004176,0.106062,289.413696,14.743437,1.060617,-85.625832,294.500488,0.000000
87.800003,64.996864,-85.670311,-0.000629,0.004176,0.106070,289.120483,14.728499,1.060704,-85.670311,294.500488,0.000000
88.170006,65.377815,-85.714790,-0.000621,0.004182,0.106226,290.815033,14.814825,1.062265,-85.714790,294.500488,0.000000
88.540001,65.415794,-85.803757,-0.000612,0.004182,0.106226,290.983978,14.823431,1.062265,-85.803757,294.500488,0.000000
88.910004,65.372215,-85.714790,-0.000612,0.004182,0.106226,290.790131,14.813556,1.062265,-85.714790,294.500488,0.000000
89.280006,65.334618,-85.714790,-0.000608,0.004182,0.106226,290.622894,14.805036,1.062265,-85.714790,294.500488,0.000000
89.650002,65.281731,-85.803757,-0.000625,0.004182,0.106226,290.387634,14.793052,1.062265,-85.803757,294.500488,0.000000
90.020004,65.238167,-85.848236,-0.000617,0.004182,0.106226,290.193848,14.783179,1.062265,-85.848236,294.500488,0.000000
90.390007,65.182320,-85.937195,-0.000617,0.004182,0.106226,289.945435,14.770525,1.062265,-85.937195,294.500488,0.000000
90.760002,65.103737,-85.848236,-0.000604,0.004182,0.106226,289.595886,14.752718,1.062265,-85.848236,294.500488,0.000000
91.130005,65.066872,-85.892715,-0.000629,0.004182,0.106235,289.431915,14.744364,1.062352,-85.892715,294.500488,0.000000
91.500008,65.004326,-85.937195,-0.000621,0.004182,0.106235,289.153687,14.730190,1.062352,-85.937195,294.500488,0.000000
91.870003,65.406853,-85.937195,-0.000617,0.004189,0.106400,290.944214,14.821404,1.063999,-85.937195,294.500488,0.000000
92.240005,65.489525,-86.026161,-0.000625,0.004189,0.106400,291.311951,14.840138,1.063999,-86.026161,294.500488,0.000000
92.610001,65.474998,-85.981682,-0.000608,0.004189,0.106400,291.247345,14.836846,1.063999,-85.981682,294.500488,0.000000
92.980003,65.409828,-86.026161,-0.000625,0.004189,0.106400,290.957458,14.822079,1.063999,-86.026161,294.500488,0.000000
93.350006,65.346901,-86.026161,-0.000604,0.004189,0.106400,290.677521,14.807819,1.063999,-86.026161,294.500488,0.000000
93.720001,65.307808,-86.115120,-0.000625,0.004189,0.106400,290.503632,14.798961,1.063999,-86.115120,294.500488,0.000000
94.090004,65.280617,-86.159599,-0.000617,0.004189,0.106400,290.382690,14.792799,1.063999,-86.159599,294.500488,0.000000
94.460007,65.240028,-86.115120,-0.000617,0.004189,0.106400,290.202148,14.783602,1.063999,-86.115120,294.500488,0.000000
94.830002,65.191628,-86.159599,-0.000617,0.004189,0.106400,289.986847,14.772635,1.063999,-86.159599,294.500488,0.000000
95.200005,65.134270,-86.159599,-0.000621,0.004189,0.106400,289.731689,14.759637,1.063999,-86.159599,294.500488,0.000000
95.570007,65.080650,-86.159599,-0.000608,0.004189,0.106400,289.493195,14.747486,1.063999,-86.159599,294.500488,0.000000
95.940002,65.043785,-86.337524,-0.000612,0.004189,0.106400,289.329193,14.739132,1.063999,-86.337524,294.500488,0.000000
96.310005,65.010277,-86.159599,-0.000608,0.004189,0.106400,289.180145,14.731539,1.063999,-86.159599,294.500488,0.000000
96.680008,64.981224,-86.204086,-0.000612,0.004189,0.106400,289.050934,14.724956,1.063999,-86.204086,294.500488,0.000000
97.050003,64.934319,-86.293045,-0.000621,0.004189,0.106409,288.842285,14.714327,1.064086,-86.293045,294.500488,0.000000
97.420006,65.084373,-86.382004,-0.000621,0.004193,0.106495,289.509766,14.748329,1.064953,-86.382004,294.500488,0.000000
97.790001,65.095177,-86.293045,-0.000608,0.004193,0.106495,289.557800,14.750778,1.064953,-86.293045,294.500488,0.000000
98.160004,65.062416,-86.382004,-0.000612,0.004193,0.106495,289.412079,14.743355,1.064953,-86.382004,294.500488,0.000000
98.530006,65.055702,-86.382004,-0.000621,0.004193,0.106495,289.382202,14.741833,1.064953,-86.382004,294.500488,0.000000
98.900002,65.027779,-86.382004,-0.000625,0.004193,0.106495,289.257996,14.735505,1.064953,-86.382004,294.500488,0.000000
99.270004,64.992409,-86.470970,-0.000612,0.004193,0.106495,289.100677,14.727489,1.064953,-86.470970,294.500488,0.000000
99.640007,64.993523,-86.470970,-0.000595,0.004193,0.106495,289.105621,14.727742,1.064953,-86.470970,294.500488,0.000000
100.010002,64.966713,-86.515450,-0.000604,0.004193,0.106495,288.986359,14.721668,1.064953,-86.515450,294.500488,0.000000
100.380005,64.934685,-86.559929,-0.000617,0.004193,0.106495,288.843903,14.714410,1.064953,-86.559929,294.500488,0.000000
100.750008,64.899315,-86.559929,-0.000608,0.004193,0.106495,288.686584,14.706395,1.064953,-86.559929,294.500488,0.000000
101.120003,64.859459,-86.559929,-0.000612,0.004193,0.106495,288.509277,14.697364,1.064953,-86.559929,294.500488,0.000000
101.490005,64.990913,-86.648895,-0.000604,0.004196,0.106591,289.094025,14.727151,1.065907,-86.648895,294.500488,0.000000
101.860008,65.005440,-86.693375,-0.000612,0.004196,0.106591,289.158630,14.730443,1.065907,-86.693375,294.500488,0.000000
102.230003,65.005806,-86.604408,-0.000604,0.004196,0.106591,289.160278,14.730526,1.065907,-86.604408,294.500488,0.000000
102.600006,64.990166,-86.693375,-0.000612,0.004196,0.106591,289.090698,14.726981,1.065907,-86.693375,294.500488,0.000000
102.970001,64.981606,-86.737854,-0.000621,0.004196,0.106591,289.052612,14.725042,1.065907,-86.737854,294.500488,0.000000
103.340004,64.945854,-86.782333,-0.000599,0.004196,0.106591,288.893585,14.716941,1.065907,-86.782333,294.500488,0.000000
103.710007,64.934319,-86.693375,-0.000617,0.004196,0.106591,288.842285,14.714327,1.065907,-86.693375,294.500488,0.000000
104.080002,64.907509,-86.737854,-0.000621,0.004196,0.106591,288.723022,14.708252,1.065907,-86.737854,294.500488,0.000000
104.450005,64.879951,-86.826813,-0.000608,0.004196,0.106591,288.600433,14.702006,1.065907,-86.826813,294.500488,0.000000
104.820007,64.855736,-86.826813,-0.000612,0.004196,0.106591,288.492706,14.696520,1.065907,-86.826813,294.500488,0.000000
105.190002,64.951439,-86.915779,-0.000591,0.004205,0.106808,288.918427,14.718206,1.068075,-86.915779,294.500488,0.000000
105.560005,65.572563,-86.871300,-0.000604,0.004205,0.106816,291.681335,14.858955,1.068162,-86.871300,294.500488,0.000000
105.930008,65.586342,-86.826813,-0.000617,0.004205,0.106808,291.742615,14.862078,1.068075,-86.826813,294.500488,0.000000
106.300003,65.581871,-86.915779,-0.000604,0.004205,0.106808,291.722717,14.861064,1.068075,-86.915779,294.500488,0.000000
106.670006,65.571815,-87.049225,-0.000604,0.004205,0.106808,291.678009,14.858786,1.068075,-87.049225,294.500488,0.000000
107.040009,65.561760,-87.004738,-0.000608,0.004205,0.106808,291.633270,14.856507,1.068075,-87.004738,294.500488,0.000000
107.410004,65.564735,-87.004738,-0.000591,0.004205,0.106808,291.646515,14.857182,1.068075,-87.004738,294.500488,0.000000
107.780006,65.534950,-87.049225,-0.000612,0.004205,0.106808,291.514008,14.850431,1.068075,-87.049225,294.500488,0.000000
108.150002,65.517082,-87.049225,-0.000599,0.004205,0.106808,291.434540,14.846382,1.068075,-87.049225,294.500488,0.000000
108.520004,65.504036,-87.093704,-0.000595,0.004205,0.106808,291.376495,14.843427,1.068075,-87.093704,294.500488,0.000000
108.890007,65.476494,-87.138184,-0.000599,0.004205,0.106808,291.253998,14.837185,1.068075,-87.138184,294.500488,0.000000
109.260002,65.442604,-87.138184,-0.000591,0.004205,0.106808,291.103241,14.829506,1.068075,-87.138184,294.500488,0.000000
109.630005,65.409462,-87.138184,-0.000599,0.004205,0.106808,290.955811,14.821997,1.068075,-87.138184,294.500488,0.000000
110.000008,65.366264,-87.138184,-0.000604,0.004205,0.106808,290.763672,14.812207,1.068075,-87.138184,294.500488,0.000000
110.370003,65.352852,-87.271629,-0.000608,0.004205,0.106808,290.704010,14.809168,1.068075,-87.271629,294.500488,0.000000
110.740005,65.323814,-87.227142,-0.000591,0.004205,0.106808,290.574829,14.802588,1.068075,-87.227142,294.500488,0.000000
111.110008,65.309288,-87.271629,-0.000586,0.004205,0.106808,290.510223,14.799295,1.068075,-87.271629,294.500488,0.000000
111.480003,65.307426,-87.271629,-0.000608,0.004205,0.106808,290.501953,14.798875,1.068075,-87.271629,294.500488,0.000000
111.850006,65.298119,-87.360588,-0.000582,0.004205,0.106816,290.460541,14.796765,1.068162,-87.360588,294.500488,0.000000
112.220009,65.290672,-87.316109,-0.000599,0.004205,0.106816,290.427429,14.795078,1.068162,-87.316109,294.500488,0.000000
112.590004,65.257164,-87.360588,-0.000599,0.004205,0.106816,290.278351,14.787484,1.068162,-87.360588,294.500488,0.000000
112.960007,65.229225,-87.405067,-0.000586,0.004205,0.106816,290.154083,14.781154,1.068162,-87.405067,294.500488,0.000000
113.330002,65.226997,-87.405067,-0.000599,0.004205,0.106816,290.144165,14.780648,1.068162,-87.405067,294.500488,0.000000
113.700005,65.199821,-87.449547,-0.000599,0.004205,0.106816,290.023285,14.774490,1.068162,-87.449547,294.500488,0.000000
114.070007,65.151039,-87.538513,-0.000599,0.004206,0.106825,289.806305,14.763437,1.068249,-87.538513,294.500488,0.000000
114.440002,65.126823,-87.538513,-0.000591,0.004206,0.106825,289.698578,14.757949,1.068249,-87.538513,294.500488,0.000000
114.810005,65.104866,-87.538513,-0.000591,0.004206,0.106825,289.600922,14.752974,1.068249,-87.538513,294.500488,0.000000
115.180008,65.090706,-87.538513,-0.000599,0.004206,0.106825,289.537933,14.749764,1.068249,-87.538513,294.500488,0.000000
115.550003,65.063896,-87.538513,-0.000599,0.004206,0.106825,289.418671,14.743690,1.068249,-87.538513,294.500488,0.000000
115.920006,65.061287,-87.582993,-0.000612,0.004206,0.106825,289.407043,14.743098,1.068249,-87.582993,294.500488,0.000000
116.290009,65.036339,-87.582993,-0.000604,0.004206,0.106834,289.296082,14.737446,1.068335,-87.582993,294.500488,0.000000
116.660004,65.507027,-87.627472,-0.000595,0.004213,0.107016,291.389801,14.844105,1.070157,-87.627472,294.500488,0.000000
117.030006,65.572182,-87.627472,-0.000586,0.004213,0.107007,291.679626,14.858869,1.070070,-87.627472,294.500488,0.000000
117.400009,65.584480,-87.627472,-0.000599,0.004213,0.107007,291.734344,14.861655,1.070070,-87.627472,294.500488,0.000000
117.770004,65.582985,-87.627472,-0.000582,0.004213,0.107007,291.727692,14.861317,1.070070,-87.627472,294.500488,0.000000
118.140007,65.585594,-87.760918,-0.000586,0.004213,0.107007,291.739288,14.861908,1.070070,-87.760918,294.500488,0.000000
118.510002,65.578514,-87.760918,-0.000595,0.004213,0.107007,291.707794,14.860304,1.070070,-87.760918,294.500488,0.000000
118.880005,65.574425,-87.805397,-0.000599,0.004213,0.107007,291.689606,14.859378,1.070070,-87.805397,294.500488,0.000000
119.250008,65.565117,-87.760918,-0.000608,0.004213,0.107007,291.648193,14.857267,1.070070,-87.760918,294.500488,0.000000
119.620003,65.559151,-87.805397,-0.000591,0.004213,0.107007,291.621674,14.855916,1.070070,-87.805397,294.500488,0.000000
119.990005,65.550209,-87.894356,-0.000599,0.004213,0.107007,291.581879,14.853889,1.070070,-87.894356,294.500488,0.000000
120.360008,65.543892,-87.894356,-0.000586,0.004213,0.107007,291.553802,14.852458,1.070070,-87.894356,294.500488,0.000000
120.730003,65.530479,-87.849876,-0.000586,0.004213,0.107007,291.494141,14.849419,1.070070,-87.849876,294.500488,0.000000
121.100006,65.506279,-87.938843,-0.000595,0.004213,0.107007,291.386475,14.843935,1.070070,-87.938843,294.500488,0.000000
121.470009,65.490639,-87.894356,-0.000591,0.004213,0.107007,291.316925,14.840391,1.070070,-87.894356,294.500488,0.000000
121.840004,65.486168,-87.983322,-0.000604,0.004213,0.107007,291.297028,14.839377,1.070070,-87.983322,294.500488,0.000000
122.210007,65.447075,-88.027802,-0.000599,0.004213,0.107007,291.123138,14.830519,1.070070,-88.027802,294.500488,0.000000
122.580009,65.441490,-87.983322,-0.000586,0.004213,0.107007,291.098297,14.829253,1.070070,-87.983322,294.500488,0.000000
122.950005,65.422493,-88.072281,-0.000595,0.004213,0.107007,291.013794,14.824948,1.070070,-88.072281,294.500488,0.000000
123.320007,65.396431,-88.027802,-0.000595,0.004213,0.107007,290.897858,14.819043,1.070070,-88.027802,294.500488,0.000000
123.690002,65.380791,-88.072281,-0.000604,0.004213,0.107007,290.828278,14.815498,1.070070,-88.072281,294.500488,0.000000
124.060005,65.361794,-88.116760,-0.000586,0.004213,0.107007,290.743774,14.811193,1.070070,-88.116760,294.500488,0.000000
124.430008,65.343925,-88.205727,-0.000591,0.004213,0.107007,290.664307,14.807145,1.070070,-88.205727,294.500488,0.000000
124.800003,65.323814,-88.161247,-0.000604,0.004213,0.107007,290.574829,14.802588,1.070070,-88.161247,294.500488,0.000000
125.170006,65.300362,-88.161247,-0.000578,0.004213,0.107007,290.470520,14.797274,1.070070,-88.161247,294.500488,0.000000
125.540009,65.297371,-88.205727,-0.000591,0.004213,0.107007,290.457214,14.796596,1.070070,-88.205727,294.500488,0.000000
125.910004,65.288445,-88.294685,-0.000604,0.004213,0.107016,290.417511,14.794573,1.070157,-88.294685,294.500488,0.000000
126.280006,65.272804,-88.294685,-0.000591,0.004213,0.107016,290.347931,14.791029,1.070157,-88.294685,294.500488,0.000000
126.650009,65.262367,-88.205727,-0.000591,0.004213,0.107016,290.301514,14.788664,1.070157,-88.205727,294.500488,0.000000
127.020004,65.234444,-88.294685,-0.000586,0.004213,0.107016,290.177307,14.782336,1.070157,-88.294685,294.500488,0.000000
127.390007,65.231087,-88.339172,-0.000591,0.004213,0.107016,290.162354,14.781575,1.070157,-88.339172,294.500488,0.000000
127.760010,65.255302,-88.428131,-0.000595,0.004216,0.107076,290.270081,14.787063,1.070764,-88.428131,294.500488,0.000000
128.130005,65.270195,-88.428131,-0.000595,0.004216,0.107076,290.336334,14.790438,1.070764,-88.428131,294.500488,0.000000
128.500000,65.272423,-88.383652,-0.000595,0.004216,0.107076,290.346252,14.790943,1.070764,-88.383652,294.500488,0.000000
128.870010,65.262749,-88.428131,-0.000599,0.004216,0.107076,290.303192,14.788750,1.070764,-88.428131,294.500488,0.000000
129.240005,65.273170,-88.517090,-0.000595,0.004216,0.107076,290.349548,14.791112,1.070764,-88.517090,294.500488,0.000000
129.610001,65.257164,-88.561577,-0.000586,0.004216,0.107076,290.278351,14.787484,1.070764,-88.561577,294.500488,0.000000
129.980011,65.247108,-88.606056,-0.000582,0.004216,0.107076,290.233643,14.785206,1.070764,-88.606056,294.500488,0.000000
130.350006,65.241890,-88.517090,-0.000582,0.004216,0.107076,290.210419,14.784024,1.070764,-88.517090,294.500488,0.000000
130.720001,65.222160,-88.561577,-0.000595,0.004216,0.107076,290.122650,14.779552,1.070764,-88.561577,294.500488,0.000000
131.090012,65.212852,-88.561577,-0.000604,0.004216,0.107076,290.081268,14.777444,1.070764,-88.561577,294.500488,0.000000
131.460007,65.189766,-88.606056,-0.000608,0.004216,0.107076,289.978577,14.772212,1.070764,-88.606056,294.500488,0.000000
131.830002,65.178963,-88.650536,-0.000608,0.004216,0.107076,289.930511,14.769765,1.070764,-88.650536,294.500488,0.000000
132.200012,65.237419,-88.695015,-0.000591,0.004217,0.107120,290.190521,14.783010,1.071197,-88.695015,294.500488,0.000000
132.570007,65.249718,-88.695015,-0.000599,0.004217,0.107120,290.245239,14.785798,1.071197,-88.695015,294.500488,0.000000
132.940002,65.263496,-88.695015,-0.000578,0.004217,0.107120,290.306519,14.788919,1.071197,-88.695015,294.500488,0.000000
133.310013,65.263863,-88.783981,-0.000591,0.004212,0.106990,290.308167,14.789002,1.069896,-88.783981,0.107120,0.000000
133.680008,65.145454,-88.828461,-0.000582,0.004203,0.106755,289.781464,14.762171,1.067555,-88.828461,0.106539,0.000000
134.050003,65.194221,-88.783981,-0.000569,0.004183,0.106244,289.998383,14.773222,1.062438,-88.783981,0.105923,0.000000
134.420013,65.080650,-88.739494,-0.000582,0.004165,0.105793,289.493195,14.747486,1.057929,-88.739494,0.105307,0.000000
134.790009,65.061668,-88.828461,-0.000573,0.004144,0.105247,289.408752,14.743185,1.052465,-88.828461,0.104691,0.000000
135.160004,65.028526,-88.872940,-0.000565,0.004118,0.104596,289.261322,14.735675,1.045961,-88.872940,0.104076,0.000000
135.530014,65.021446,-88.961899,-0.000578,0.004095,0.104015,289.229828,14.734070,1.040151,-88.961899,0.103460,0.000000
135.900009,64.992027,-88.917419,-0.000569,0.004068,0.103330,289.098969,14.727404,1.033299,-88.917419,0.102844,0.000000
136.270004,64.974907,-88.917419,-0.000573,0.004046,0.102775,289.022827,14.723524,1.027749,-88.917419,0.102229,0.000000
136.639999,64.917931,-88.917419,-0.000578,0.004022,0.102168,288.769379,14.710613,1.021679,-88.917419,0.101613,0.000000
137.010010,64.841957,-89.006386,-0.000578,0.003997,0.101517,288.431427,14.693397,1.015175,-89.006386,0.100988,0.000000
137.380005,64.741417,-89.050865,-0.000565,0.003979,0.101066,287.984192,14.670615,1.010665,-89.050865,0.100373,0.000000
137.750000,64.202980,-89.050865,-0.000560,0.003955,0.100459,285.589111,14.548603,1.004594,-89.050865,0.099757,0.000000
138.120010,63.296242,-89.050865,-0.000582,0.003933,0.099896,281.555756,14.343134,0.998957,-89.050865,0.099141,0.000000
138.490005,62.464737,-89.095345,-0.000573,0.003913,0.099393,277.857025,14.154712,0.993927,-89.095345,0.098526,0.000000
138.860001,60.941360,-89.139824,-0.000582,0.003886,0.098716,271.080719,13.809510,0.987163,-89.139824,0.097910,0.000000
139.230011,59.367714,-89.228790,-0.000569,0.003864,0.098144,264.080780,13.452916,0.981439,-89.228790,0.097294,0.000000
139.600006,58.043930,-89.184303,-0.000569,0.003847,0.097719,258.192291,13.152943,0.977190,-89.184303,0.096678,0.000000
139.970001,55.554993,-89.184303,-0.000560,0.003819,0.096999,247.120956,12.588941,0.969992,-89.184303,0.096063,0.000000
140.340012,53.447739,-89.184303,-0.000560,0.003795,0.096383,237.747421,12.111431,0.963835,-89.184303,0.095438,0.000000
140.710007,51.212387,-89.228790,-0.000569,0.003773,0.095846,227.804077,11.604893,0.958458,-89.228790,0.094822,0.000000
141.080002,48.295219,-89.273270,-0.000565,0.003744,0.095091,214.827866,10.943852,0.950913,-89.273270,0.094207,0.000000
141.450012,45.970131,-89.273270,-0.000565,0.003723,0.094562,204.485352,10.416981,0.945623,-89.273270,0.093591,0.000000
141.820007,43.554176,-89.273270,-0.000578,0.003701,0.094016,193.738647,9.869517,0.940159,-89.273270,0.092975,0.000000
142.190002,41.069710,-89.228790,-0.000582,0.003679,0.093435,182.687195,9.306529,0.934349,-89.228790,0.092360,0.000000
142.560013,38.947929,-89.406715,-0.000569,0.003659,0.092932,173.249039,8.825727,0.929319,-89.406715,0.091744,0.000000
142.930008,35.655785,-89.451195,-0.000578,0.003627,0.092117,158.604858,8.079717,0.921167,-89.451195,0.091128,0.000000
143.300003,33.455437,-89.406715,-0.000569,0.003607,0.091622,148.817215,7.581110,0.916224,-89.406715,0.090504,0.000000
143.670013,31.082680,-89.406715,-0.000578,0.003582,0.090972,138.262665,7.043436,0.909720,-89.406715,0.089888,0.000000
144.040009,28.388191,-89.451195,-0.000582,0.003560,0.090426,126.276978,6.432856,0.904256,-89.451195,0.089272,0.000000
144.410004,25.858665,-89.495674,-0.000586,0.003537,0.089827,115.025085,5.859657,0.898272,-89.495674,0.088656,0.000000
144.780014,22.951927,-89.540154,-0.000604,0.003508,0.089099,102.095268,5.200981,0.890988,-89.540154,0.088041,0.000000
145.150009,20.326324,-89.540154,-0.000591,0.003483,0.088474,90.416008,4.606011,0.884744,-89.540154,0.087425,0.000000
145.520004,17.798660,-89.540154,-0.000608,0.003461,0.087919,79.172394,4.033234,0.879193,-89.540154,0.086809,0.000000
145.889999,15.192429,-89.584633,-0.000604,0.003434,0.087226,67.579300,3.442654,0.872256,-89.584633,0.086194,0.000000
146.260010,12.693436,-89.673599,-0.000604,0.003417,0.086792,56.463223,2.876374,0.867919,-89.673599,0.085578,0.000000
146.630005,9.441505,-89.718079,-0.000612,0.003385,0.085977,41.997913,2.139476,0.859767,-89.718079,0.084953,0.000000
147.000000,6.574608,-89.718079,-0.000608,0.003360,0.085335,29.245316,1.489827,0.853350,-89.718079,0.084338,0.000000
147.370010,4.283401,-89.673599,-0.000625,0.003338,0.084780,19.053522,0.970633,0.847800,-89.673599,0.083722,0.000000
147.740005,1.784782,-89.762558,-0.000638,0.003311,0.084104,7.939109,0.404437,0.841035,-89.762558,0.083106,0.000000
148.110001,-0.498978,-89.807037,-0.000660,0.003289,0.083549,-2.219563,-0.113070,0.835485,-89.807037,0.082491,0.000000
148.480011,-1.132755,-89.807037,-0.000664,0.003261,0.082837,-5.038747,-0.256686,0.828374,-89.807037,0.081875,0.000000
148.850006,-0.087875,-89.807037,-0.000707,0.003237,0.082222,-0.390889,-0.019913,0.822217,-89.807037,0.081259,0.000000
149.220001,-0.092346,-89.762558,-0.000746,0.003217,0.081701,-0.410776,-0.020926,0.817013,-89.762558,0.080643,0.000000
149.590012,-0.133308,-89.807037,-0.000767,0.003190,0.081025,-0.592985,-0.030208,0.810249,-89.807037,0.080028,0.000000
149.960007,-0.065536,-89.851524,-0.000815,0.003166,0.080427,-0.291521,-0.014851,0.804265,-89.851524,0.079403,0.000000
150.330002,-0.061440,-89.984962,-0.000849,0.003136,0.079655,-0.273297,-0.013922,0.796547,-89.984962,0.078787,0.000000
150.700012,-0.048035,-89.851524,-0.000914,0.003110,0.079004,-0.213669,-0.010885,0.790043,-89.851524,0.078172,0.000000
151.070007,-0.039841,-89.940483,-0.000927,0.003093,0.078571,-0.177220,-0.009028,0.785706,-89.940483,0.077556,0.000000
151.440002,-0.026062,-89.896004,-0.000966,0.003066,0.077868,-0.115930,-0.005906,0.778682,-89.896004,0.076940,0.000000
151.810013,-0.042824,-90.029442,-0.001000,0.003041,0.077235,-0.190490,-0.009704,0.772351,-90.029442,0.076325,0.000000
152.180008,-0.045425,-90.073929,-0.001018,0.003023,0.076793,-0.202062,-0.010294,0.767928,-90.073929,0.075709,0.000000
152.550003,-0.020851,-90.073929,-0.001061,0.002995,0.076064,-0.092750,-0.004725,0.760644,-90.073929,0.075093,0.000000
152.800003,-0.000740,-90.029442,-0.001091,0.002989,0.075917,-0.003292,-0.000168,0.759169,-90.029442,0.075709,0.000000