File: Data/compression 34/AutoNoHeating-12-34-reverse-1-2_11152024_195644.csv
Time (sec),S:Load (lbs),S:HL1 (DIM),S:LVDT (in),S:Position (in),Ch:Position (mm),Ch:Load (N),Ch:Stress (MPa),Ch:Strain (mm/mm),Ch:HL1 (DIM),Set Point (),Cycles ()
0.210000,-0.110222,-358.827820,-0.011434,-0.006611,-0.167930,-0.490291,-0.024977,-1.679296,-358.827820,-0.167635,0.000000
0.590000,-0.079689,-358.783356,-0.011426,-0.006524,-0.165718,-0.354474,-0.018058,-1.657182,-358.783356,-0.164929,0.000000
0.970000,-0.044312,-358.827820,-0.011240,-0.006300,-0.160020,-0.197107,-0.010041,-1.600205,-358.827820,-0.158598,0.000000
1.350000,-0.089371,-358.872314,-0.010990,-0.006044,-0.153525,-0.397541,-0.020252,-1.535250,-358.872314,-0.152267,0.000000
1.730000,-0.100540,-358.872314,-0.010727,-0.005797,-0.147238,-0.447225,-0.022783,-1.472376,-358.872314,-0.145937,0.000000
2.110000,-0.096451,-358.916809,-0.010468,-0.005546,-0.140863,-0.429035,-0.021856,-1.408635,-358.916809,-0.139606,0.000000
2.490000,-0.052505,-358.872314,-0.010214,-0.005297,-0.134533,-0.233556,-0.011898,-1.345327,-358.872314,-0.133275,0.000000
2.870000,-0.012665,-358.872314,-0.009964,-0.005052,-0.128332,-0.056336,-0.002870,-1.283320,-358.872314,-0.126944,0.000000
3.250000,-0.055862,-358.961273,-0.009710,-0.004798,-0.121863,-0.248488,-0.012659,-1.218625,-358.961273,-0.120614,0.000000
3.630000,-0.041336,-358.961273,-0.009451,-0.004551,-0.115584,-0.183872,-0.009367,-1.155838,-358.961273,-0.114283,0.000000
4.010000,-0.062187,-359.050232,-0.009192,-0.004300,-0.109227,-0.276622,-0.014092,-1.092271,-359.050232,-0.107952,0.000000
4.390000,-0.039848,-358.961273,-0.008951,-0.004054,-0.102983,-0.177254,-0.009030,-1.029830,-358.961273,-0.101621,0.000000
4.770000,-0.048782,-358.916809,-0.008679,-0.003804,-0.096609,-0.216995,-0.011054,-0.966089,-358.916809,-0.095291,0.000000
5.150000,-0.060326,-358.961273,-0.008433,-0.003554,-0.090278,-0.268342,-0.013670,-0.902782,-358.961273,-0.088960,0.000000
5.530000,-0.067032,-358.961273,-0.008170,-0.003310,-0.084086,-0.298173,-0.015190,-0.840862,-358.961273,-0.082629,0.000000
5.910000,-0.085648,-358.961273,-0.007916,-0.003062,-0.077781,-0.380979,-0.019408,-0.777815,-358.961273,-0.076299,0.000000
6.290000,-0.136292,-358.961273,-0.007662,-0.002815,-0.071494,-0.606255,-0.030884,-0.714941,-358.961273,-0.069968,0.000000
6.670001,-0.063675,-359.005768,-0.007407,-0.002558,-0.064973,-0.283240,-0.014429,-0.649725,-359.005768,-0.063637,0.000000
7.050000,-0.061073,-359.005768,-0.007140,-0.002303,-0.058486,-0.271668,-0.013839,-0.584857,-359.005768,-0.057306,0.000000
7.430000,-0.055862,-359.094727,-0.006873,-0.002060,-0.052320,-0.248488,-0.012659,-0.523197,-359.094727,-0.050976,0.000000
7.810000,-0.070755,-359.094727,-0.006627,-0.001807,-0.045894,-0.314734,-0.016033,-0.458936,-359.094727,-0.044645,0.000000
8.190001,-0.118416,-359.094727,-0.006385,-0.001558,-0.039572,-0.526740,-0.026833,-0.395715,-359.094727,-0.038314,0.000000
8.570001,-0.102402,-359.094727,-0.006109,-0.001308,-0.033223,-0.455506,-0.023205,-0.332234,-359.094727,-0.031983,0.000000
8.950001,-0.066658,-359.139191,-0.005859,-0.001058,-0.026867,-0.296510,-0.015105,-0.268666,-359.139191,-0.025653,0.000000
9.330001,-0.051765,-359.094727,-0.005601,-0.000812,-0.020631,-0.230264,-0.011730,-0.206313,-359.094727,-0.019322,0.000000
9.710000,-0.063309,-359.183685,-0.005342,-0.000558,-0.014162,-0.281611,-0.014346,-0.141618,-359.183685,-0.012991,0.000000
10.090000,-0.055862,-359.183685,-0.005079,-0.000312,-0.007918,-0.248488,-0.012659,-0.079178,-359.183685,-0.006660,0.000000
10.470000,0.169426,-359.139191,-0.004838,-0.000084,-0.002125,0.753644,0.038392,-0.021247,-359.139191,-0.000659,0.000000
10.850000,0.142616,-359.228149,-0.004829,-0.000000,-0.000009,0.634389,0.032317,-0.000087,-359.228149,0.000165,0.000000
11.230000,0.115059,-359.183685,-0.004829,-0.000000,-0.000009,0.511808,0.026073,-0.000087,-359.183685,0.000564,0.000000
11.610001,0.129585,-359.272644,-0.004850,-0.000000,-0.000000,0.576424,0.029364,-0.000000,-359.272644,0.001197,0.000000
11.990001,0.135544,-359.228149,-0.004829,0.000030,0.000754,0.602929,0.030715,0.007545,-359.228149,0.001830,0.000000
12.370001,0.233849,-359.272644,-0.004799,0.000052,0.001310,1.040210,0.052991,0.013095,-359.272644,0.002463,0.000000
12.750001,0.399551,-359.272644,-0.004769,0.000077,0.001951,1.777293,0.090540,0.019513,-359.272644,0.003096,0.000000
13.130001,0.636757,-359.183685,-0.004734,0.000105,0.002662,2.832436,0.144291,0.026624,-359.183685,0.003729,0.000000
13.510000,0.822937,-359.361603,-0.004708,0.000140,0.003547,3.660607,0.186480,0.035469,-359.361603,0.004362,0.000000
13.890000,0.941727,-359.317108,-0.004674,0.000158,0.004024,4.189010,0.213398,0.040239,-359.317108,0.004995,0.000000
14.270000,1.054558,-359.272644,-0.004661,0.000174,0.004423,4.690907,0.238966,0.044228,-359.272644,0.005628,0.000000
14.650001,1.318565,-359.361603,-0.004644,0.000200,0.005082,5.865272,0.298791,0.050819,-359.361603,0.006261,0.000000
15.030001,1.595612,-359.406097,-0.004618,0.000229,0.005828,7.097635,0.361571,0.058277,-359.406097,0.006894,0.000000
15.410001,1.831322,-359.406097,-0.004587,0.000260,0.006608,8.146126,0.414983,0.066083,-359.406097,0.007528,0.000000
15.790001,1.854782,-359.406097,-0.004570,0.000268,0.006816,8.250483,0.420300,0.068164,-359.406097,0.008161,0.000000
16.170000,2.036499,-359.406097,-0.004557,0.000291,0.007389,9.058800,0.461477,0.073888,-359.406097,0.008794,0.000000
16.550001,2.450211,-359.406097,-0.004501,0.000330,0.008386,10.899081,0.555226,0.083861,-359.406097,0.009427,0.000000
16.930000,2.610329,-359.450562,-0.004475,0.000353,0.008958,11.611321,0.591509,0.089584,-359.450562,0.010060,0.000000
17.310001,2.856842,-359.495056,-0.004449,0.000382,0.009696,12.707868,0.647370,0.096956,-359.495056,0.010693,0.000000
17.690001,2.983818,-359.450562,-0.004428,0.000407,0.010329,13.272686,0.676143,0.103286,-359.450562,0.011326,0.000000
18.070002,3.005417,-359.450562,-0.004428,0.000424,0.010762,13.368762,0.681037,0.107623,-359.450562,0.011959,0.000000
18.450001,3.307037,-359.450562,-0.004381,0.000456,0.011577,14.710437,0.749385,0.115774,-359.450562,0.012592,0.000000
18.830002,3.314484,-359.495056,-0.004359,0.000474,0.012046,14.743560,0.751073,0.120458,-359.495056,0.013225,0.000000
19.210001,3.746063,-359.495056,-0.004337,0.000509,0.012922,16.663321,0.848870,0.129217,-359.495056,0.013858,0.000000
19.590000,3.825005,-359.539520,-0.004299,0.000533,0.013529,17.014471,0.866758,0.135287,-359.539520,0.014491,0.000000
19.970001,3.863358,-359.539520,-0.004281,0.000556,0.014118,17.185072,0.875449,0.141184,-359.539520,0.015124,0.000000
20.350000,4.128494,-359.495056,-0.004243,0.000582,0.014786,18.364460,0.935530,0.147862,-359.495056,0.015757,0.000000
20.730001,4.226051,-359.539520,-0.004221,0.000604,0.015350,18.798414,0.957637,0.153499,-359.539520,0.016391,0.000000
21.110001,4.260681,-359.628479,-0.004195,0.000620,0.015757,18.952456,0.965484,0.157575,-359.628479,0.017024,0.000000
21.490002,4.549644,-359.584015,-0.004178,0.000649,0.016495,20.237829,1.030964,0.164946,-359.584015,0.017665,0.000000
21.870001,4.638641,-359.584015,-0.004148,0.000677,0.017197,20.633707,1.051131,0.171971,-359.584015,0.018298,0.000000
22.250002,4.488945,-359.584015,-0.004130,0.000690,0.017535,19.967825,1.017209,0.175353,-359.584015,0.018932,0.000000
22.630001,4.614067,-359.628479,-0.004092,0.000708,0.017995,20.524395,1.045563,0.179949,-359.628479,0.019565,0.000000
23.010000,5.078789,-359.672974,-0.004066,0.000752,0.019105,22.591581,1.150870,0.191050,-359.672974,0.020198,0.000000
23.390001,5.114906,-359.628479,-0.004031,0.000775,0.019695,22.752239,1.159054,0.196947,-359.628479,0.020831,0.000000
23.770000,5.342796,-359.672974,-0.004005,0.000806,0.020467,23.765945,1.210695,0.204665,-359.672974,0.021464,0.000000
24.150002,5.426956,-359.717438,-0.003967,0.000829,0.021056,24.140306,1.229766,0.210562,-359.717438,0.022097,0.000000
24.530001,5.555420,-359.717438,-0.003949,0.000854,0.021681,24.711742,1.258876,0.216806,-359.717438,0.022730,0.000000
24.910002,5.517441,-359.717438,-0.003936,0.000874,0.022201,24.542803,1.250270,0.222010,-359.717438,0.023363,0.000000
25.290001,5.683891,-359.717438,-0.003889,0.000899,0.022825,25.283211,1.287988,0.228254,-359.717438,0.023996,0.000000
25.670002,5.836189,-359.717438,-0.003859,0.000931,0.023641,25.960667,1.322499,0.236406,-359.717438,0.024629,0.000000
26.050001,5.918488,-359.761932,-0.003824,0.000955,0.024248,26.326748,1.341148,0.242476,-359.761932,0.025262,0.000000
26.430000,5.723732,-359.717438,-0.003824,0.000964,0.024490,25.460432,1.297016,0.244904,-359.717438,0.025895,0.000000
26.810001,6.099831,-359.806427,-0.003764,0.000998,0.025358,27.133402,1.382241,0.253577,-359.806427,0.026528,0.000000
27.190001,6.304634,-359.850891,-0.003747,0.001030,0.026173,28.044413,1.428650,0.261729,-359.850891,0.027161,0.000000
27.570002,6.241333,-359.850891,-0.003704,0.001055,0.026789,27.762836,1.414306,0.267886,-359.850891,0.027795,0.000000
27.950001,6.300537,-359.761932,-0.003669,0.001080,0.027439,28.026188,1.427722,0.274390,-359.761932,0.028428,0.000000
28.330002,6.310219,-359.850891,-0.003639,0.001101,0.027959,28.069256,1.429916,0.279593,-359.850891,0.029061,0.000000
28.710001,6.461403,-359.895386,-0.003622,0.001127,0.028636,28.741756,1.464175,0.286358,-359.895386,0.029694,0.000000
29.090002,6.541092,-359.850891,-0.003583,0.001152,0.029269,29.096230,1.482233,0.292689,-359.850891,0.030327,0.000000
29.470001,6.538857,-359.850891,-0.003557,0.001176,0.029859,29.086287,1.481726,0.298586,-359.850891,0.030960,0.000000
29.850002,6.621895,-359.850891,-0.003518,0.001202,0.030535,29.455660,1.500543,0.305350,-359.850891,0.031593,0.000000
30.230001,6.473320,-359.850891,-0.003505,0.001220,0.030977,28.794765,1.466875,0.309773,-359.850891,0.032226,0.000000
30.610001,6.688553,-359.939850,-0.003462,0.001247,0.031662,29.752169,1.515648,0.316624,-359.939850,0.032859,0.000000
30.990002,6.837875,-359.939850,-0.003428,0.001278,0.032460,30.416389,1.549485,0.324603,-359.939850,0.033492,0.000000
31.370001,6.651688,-359.895386,-0.003406,0.001296,0.032920,29.588184,1.507294,0.329199,-359.895386,0.034125,0.000000
31.750002,6.825958,-359.895386,-0.003363,0.001326,0.033674,30.363379,1.546784,0.336744,-359.895386,0.034758,0.000000
32.130001,6.869148,-359.939850,-0.003316,0.001351,0.034325,30.555498,1.556571,0.343248,-359.939850,0.035391,0.000000
32.510002,6.953308,-359.984344,-0.003294,0.001376,0.034949,30.929859,1.575642,0.349492,-359.984344,0.036033,0.000000
32.890003,6.969696,-359.939850,-0.003268,0.001397,0.035496,31.002756,1.579356,0.354955,-359.939850,0.036666,0.000000
33.270000,7.018471,-359.984344,-0.003238,0.001424,0.036163,31.219717,1.590408,0.361633,-359.984344,0.037299,0.000000
33.650002,7.021080,-359.984344,-0.003199,0.001447,0.036762,31.231323,1.590999,0.367617,-359.984344,0.037932,0.000000
34.030003,6.918678,-359.984344,-0.003178,0.001462,0.037126,30.775818,1.567795,0.371259,-359.984344,0.038566,0.000000
34.410000,7.418030,-360.073303,-0.003139,0.001502,0.038141,32.997044,1.680950,0.381406,-360.073303,0.039199,0.000000
34.790001,7.613899,-360.117767,-0.003087,0.001534,0.038964,33.868317,1.725334,0.389645,-360.117767,0.039832,0.000000
35.170002,7.325684,-360.073303,-0.003057,0.001557,0.039545,32.586269,1.660024,0.395455,-360.073303,0.040465,0.000000
35.550003,7.100395,-360.028809,-0.003040,0.001572,0.039927,31.584135,1.608973,0.399271,-360.028809,0.041098,0.000000
35.930000,7.326797,-360.117767,-0.003001,0.001599,0.040603,32.591225,1.660276,0.406035,-360.117767,0.041731,0.000000
36.310001,7.611664,-360.117767,-0.002962,0.001627,0.041332,33.858372,1.724828,0.413320,-360.117767,0.042364,0.000000
36.690002,7.701401,-360.206757,-0.002915,0.001656,0.042060,34.257542,1.745162,0.420604,-360.206757,0.042997,0.000000
37.070004,7.331642,-360.117767,-0.002902,0.001667,0.042329,32.612774,1.661374,0.423293,-360.117767,0.043630,0.000000
37.450001,7.457870,-360.162262,-0.002876,0.001689,0.042910,33.174263,1.689978,0.429103,-360.162262,0.044263,0.000000
37.830002,8.108406,-360.117767,-0.002833,0.001728,0.043899,36.067993,1.837391,0.438990,-360.117767,0.044896,0.000000
38.210003,7.921852,-360.162262,-0.002798,0.001751,0.044480,35.238159,1.795117,0.444800,-360.162262,0.045529,0.000000
38.590000,7.991112,-360.251221,-0.002781,0.001779,0.045191,35.546242,1.810812,0.451911,-360.251221,0.046162,0.000000
38.970001,7.988503,-360.251221,-0.002738,0.001803,0.045798,35.534634,1.810220,0.457982,-360.251221,0.046795,0.000000
39.350002,7.834343,-360.162262,-0.002708,0.001823,0.046301,34.848900,1.775287,0.463012,-360.162262,0.047429,0.000000
39.730003,7.708855,-360.251221,-0.002682,0.001840,0.046726,34.290699,1.746851,0.467261,-360.251221,0.048062,0.000000
40.110001,7.752045,-360.340179,-0.002682,0.001859,0.047212,34.482819,1.756638,0.472118,-360.340179,0.048695,0.000000
40.490002,8.494926,-360.340179,-0.002613,0.001902,0.048304,37.787319,1.924978,0.483045,-360.340179,0.049328,0.000000
40.870003,8.429764,-360.295715,-0.002578,0.001929,0.048998,37.497463,1.910212,0.489983,-360.295715,0.049961,0.000000
41.250004,8.217888,-360.340179,-0.002544,0.001951,0.049562,36.554993,1.862200,0.495619,-360.340179,0.050594,0.000000
41.630001,8.487480,-360.295715,-0.002509,0.001980,0.050290,37.754196,1.923290,0.502904,-360.295715,0.051227,0.000000
42.010002,8.418594,-360.340179,-0.002470,0.002000,0.050811,37.447777,1.907681,0.508107,-360.340179,0.051860,0.000000
42.390003,8.335556,-360.384674,-0.002453,0.002020,0.051296,37.078403,1.888864,0.512964,-360.384674,0.052493,0.000000
42.770000,8.710907,-360.429138,-0.002436,0.002048,0.052016,38.748051,1.973920,0.520162,-360.429138,0.053126,0.000000
43.150002,8.715378,-360.340179,-0.002389,0.002074,0.052675,38.767937,1.974933,0.526753,-360.340179,0.053759,0.000000
43.530003,8.377632,-360.384674,-0.002371,0.002084,0.052927,37.265568,1.898399,0.529268,-360.384674,0.054401,0.000000
43.910004,8.909378,-360.473633,-0.002337,0.002123,0.053924,39.630894,2.018894,0.539241,-360.473633,0.055034,0.000000
44.290001,8.894112,-360.518097,-0.002320,0.002144,0.054462,39.562984,2.015435,0.544618,-360.518097,0.055667,0.000000
44.670002,8.793945,-360.429138,-0.002294,0.002163,0.054939,39.117424,1.992736,0.549387,-360.429138,0.056300,0.000000
45.050003,9.127594,-360.473633,-0.002233,0.002194,0.055728,40.601566,2.068342,0.557279,-360.473633,0.056933,0.000000
45.430000,9.266861,-360.473633,-0.002207,0.002222,0.056448,41.221058,2.099901,0.564477,-360.473633,0.057566,0.000000
45.810001,9.312660,-360.473633,-0.002182,0.002246,0.057037,41.424782,2.110279,0.570374,-360.473633,0.058200,0.000000
46.190002,9.324577,-360.473633,-0.002151,0.002269,0.057636,41.477791,2.112979,0.576358,-360.473633,0.058833,0.000000
46.570004,9.532356,-360.518097,-0.002139,0.002297,0.058356,42.402039,2.160063,0.583556,-360.518097,0.059466,0.000000
46.950001,9.651520,-360.473633,-0.002082,0.002327,0.059101,42.932106,2.187066,0.591014,-360.473633,0.060099,0.000000
47.330002,9.676094,-360.473633,-0.002070,0.002350,0.059700,43.041416,2.192634,0.596998,-360.473633,0.060732,0.000000
47.710003,9.452301,-360.562592,-0.002048,0.002363,0.060012,42.045937,2.141922,0.600120,-360.562592,0.061365,0.000000
48.090004,9.934525,-360.562592,-0.002009,0.002395,0.060836,44.190971,2.251195,0.608359,-360.562592,0.061998,0.000000
48.470001,10.213058,-360.562592,-0.001979,0.002423,0.061538,45.429955,2.314312,0.615383,-360.562592,0.062631,0.000000
48.850002,10.394028,-360.607056,-0.001940,0.002452,0.062275,46.234943,2.355320,0.622755,-360.607056,0.063264,0.000000
49.230003,10.370201,-360.562592,-0.001906,0.002475,0.062865,46.128960,2.349921,0.628652,-360.562592,0.063897,0.000000
49.610001,10.309128,-360.562592,-0.001880,0.002493,0.063333,45.857292,2.336082,0.633335,-360.562592,0.064530,0.000000
49.990002,10.713524,-360.607056,-0.001854,0.002523,0.064079,47.656136,2.427719,0.640793,-360.607056,0.065163,0.000000
50.370003,10.551170,-360.651550,-0.001841,0.002539,0.064496,46.933949,2.390929,0.644956,-360.651550,0.065796,0.000000
50.750004,10.789864,-360.651550,-0.001798,0.002571,0.065293,47.995708,2.445018,0.652934,-360.651550,0.066429,0.000000
51.130001,11.191650,-360.607056,-0.001763,0.002599,0.066005,49.782948,2.536064,0.660045,-360.607056,0.067063,0.000000
51.510002,10.843483,-360.651550,-0.001746,0.002616,0.066447,48.234222,2.457168,0.664468,-360.651550,0.067696,0.000000
51.890003,11.682442,-360.696045,-0.001720,0.002646,0.067201,51.966095,2.647279,0.672013,-360.696045,0.068329,0.000000
52.270004,11.500351,-360.740509,-0.001686,0.002664,0.067678,51.156116,2.606017,0.676783,-360.740509,0.068962,0.000000
52.650002,11.749092,-360.740509,-0.001656,0.002692,0.068372,52.262573,2.662382,0.683721,-360.740509,0.069595,0.000000
53.030003,12.109924,-360.696045,-0.001625,0.002723,0.069153,53.867634,2.744148,0.691526,-360.696045,0.070228,0.000000
53.410004,12.465912,-360.740509,-0.001600,0.002749,0.069829,55.451145,2.824816,0.698290,-360.740509,0.070861,0.000000
53.790001,12.670715,-360.785004,-0.001561,0.002773,0.070427,56.362156,2.871225,0.704274,-360.785004,0.071494,0.000000
54.170002,12.865089,-360.740509,-0.001539,0.002796,0.071017,57.226776,2.915271,0.710171,-360.740509,0.072136,0.000000
54.550003,13.006226,-360.829468,-0.001513,0.002820,0.071624,57.854580,2.947253,0.716242,-360.829468,0.072769,0.000000
54.930004,12.987602,-360.785004,-0.001492,0.002841,0.072171,57.771740,2.943033,0.721705,-360.785004,0.073402,0.000000
55.310001,13.301140,-360.829468,-0.001470,0.002860,0.072647,59.166424,3.014081,0.726475,-360.829468,0.074035,0.000000
55.690002,13.543930,-360.829468,-0.001449,0.002883,0.073220,60.246410,3.069098,0.732199,-360.829468,0.074668,0.000000
56.070004,14.874046,-360.918427,-0.001401,0.002928,0.074365,66.163063,3.370507,0.743646,-360.918427,0.075301,0.000000
56.450005,14.698654,-360.829468,-0.001393,0.002954,0.075024,65.382881,3.330763,0.750237,-360.829468,0.075934,0.000000
56.830002,14.532204,-360.873962,-0.001354,0.002971,0.075466,64.642471,3.293044,0.754660,-360.873962,0.076567,0.000000
57.210003,14.409325,-360.873962,-0.001345,0.002985,0.075813,64.095879,3.265200,0.758129,-360.873962,0.077200,0.000000
57.590004,15.773697,-360.918427,-0.001298,0.003021,0.076732,70.164909,3.574371,0.767321,-360.918427,0.077834,0.000000
57.970001,16.406731,-360.918427,-0.001276,0.003052,0.077530,72.980782,3.717818,0.775300,-360.918427,0.078467,0.000000
58.350002,16.028023,-360.962921,-0.001263,0.003067,0.077903,71.296204,3.632002,0.779029,-360.962921,0.079100,0.000000
58.730003,16.434654,-360.918427,-0.001237,0.003089,0.078449,73.104996,3.724146,0.784492,-360.918427,0.079733,0.000000
59.110004,16.610413,-360.918427,-0.001224,0.003118,0.079186,73.886803,3.763973,0.791864,-360.918427,0.080366,0.000000
59.490002,17.752106,-360.918427,-0.001181,0.003146,0.079906,78.965309,4.022685,0.799062,-360.918427,0.080999,0.000000
59.870003,18.494247,-361.007385,-0.001155,0.003176,0.080661,82.266518,4.190856,0.806607,-361.007385,0.081632,0.000000
60.250004,18.802574,-361.007385,-0.001138,0.003199,0.081259,83.638023,4.260724,0.812590,-361.007385,0.082265,0.000000
60.630001,19.001419,-361.007385,-0.001117,0.003220,0.081788,84.522530,4.305783,0.817881,-361.007385,0.082898,0.000000
61.010002,19.759941,-361.007385,-0.001104,0.003248,0.082508,87.896606,4.477666,0.825078,-361.007385,0.083531,0.000000
61.390003,19.992676,-361.051880,-0.001069,0.003270,0.083054,88.931862,4.530405,0.830542,-361.051880,0.084164,0.000000
61.770004,20.824554,-361.096375,-0.001039,0.003295,0.083696,92.632248,4.718912,0.836959,-361.096375,0.084797,0.000000
62.150002,21.796074,-361.096375,-0.001022,0.003326,0.084485,96.953781,4.939061,0.844851,-361.096375,0.085430,0.000000
62.530003,21.869804,-361.051880,-0.001005,0.003347,0.085023,97.281746,4.955768,0.850228,-361.051880,0.086063,0.000000
62.910004,22.747856,-361.096375,-0.000983,0.003375,0.085717,101.187515,5.154737,0.857166,-361.096375,0.086697,0.000000
63.290005,23.081505,-361.096375,-0.000949,0.003395,0.086246,102.671661,5.230343,0.862456,-361.096375,0.087330,0.000000
63.670002,23.599472,-361.140839,-0.000927,0.003416,0.086757,104.975693,5.347716,0.867572,-361.140839,0.087963,0.000000
64.050003,24.325600,-361.185333,-0.000931,0.003438,0.087330,108.205673,5.512259,0.873296,-361.185333,0.088596,0.000000
64.430000,25.539909,-361.185333,-0.000901,0.003470,0.088136,113.607193,5.787426,0.881362,-361.185333,0.089229,0.000000
64.810005,26.799271,-361.096375,-0.000871,0.003502,0.088943,119.209106,6.072802,0.889427,-361.096375,0.089862,0.000000
65.190002,26.223953,-361.140839,-0.000854,0.003516,0.089307,116.649971,5.942433,0.893069,-361.140839,0.090504,0.000000
65.570000,27.740631,-361.229797,-0.000841,0.003542,0.089957,123.396492,6.286117,0.899573,-361.229797,0.091137,0.000000
65.950005,28.198273,-361.229797,-0.000819,0.003561,0.090460,125.432182,6.389820,0.904603,-361.229797,0.091770,0.000000
66.330002,29.593552,-361.229797,-0.000802,0.003593,0.091258,131.638687,6.705995,0.912581,-361.229797,0.092403,0.000000
66.710007,30.168495,-361.185333,-0.000780,0.003619,0.091917,134.196167,6.836279,0.919172,-361.185333,0.093036,0.000000
67.090004,31.203690,-361.274292,-0.000759,0.003641,0.092481,138.800949,7.070857,0.924810,-361.274292,0.093669,0.000000
67.470001,32.387466,-361.229797,-0.000729,0.003667,0.093149,144.066650,7.339105,0.931487,-361.229797,0.094302,0.000000
67.850006,33.641243,-361.318756,-0.000724,0.003696,0.093877,149.643723,7.623215,0.938772,-361.318756,0.094935,0.000000
68.230003,34.578506,-361.274292,-0.000703,0.003721,0.094519,153.812881,7.835601,0.945189,-361.274292,0.095568,0.000000
68.610001,35.324364,-361.318756,-0.000690,0.003743,0.095074,157.130615,8.004616,0.950740,-361.318756,0.096201,0.000000
68.990005,35.823341,-361.318756,-0.000655,0.003762,0.095542,159.350174,8.117685,0.955422,-361.318756,0.096834,0.000000
69.370003,37.631958,-361.318756,-0.000642,0.003791,0.096279,167.395309,8.527524,0.962794,-361.318756,0.097467,0.000000
69.750000,39.078995,-361.363251,-0.000638,0.003821,0.097060,173.832047,8.855427,0.970599,-361.363251,0.098101,0.000000
70.130005,40.431458,-361.363251,-0.000625,0.003848,0.097728,179.848099,9.161900,0.977277,-361.363251,0.098734,0.000000
70.510002,41.186623,-361.363251,-0.000599,0.003869,0.098265,183.207245,9.333022,0.982653,-361.363251,0.099367,0.000000
70.890007,42.264641,-361.363251,-0.000586,0.003890,0.098803,188.002518,9.577305,0.988030,-361.363251,0.100000,0.000000
71.270004,43.791374,-361.407715,-0.000569,0.003919,0.099540,194.793762,9.923266,0.995402,-361.407715,0.100633,0.000000
71.650002,44.399086,-361.452209,-0.000560,0.003934,0.099922,197.496994,10.060976,0.999217,-361.452209,0.101266,0.000000
72.030006,45.904213,-361.407715,-0.000560,0.003960,0.100572,204.192139,10.402043,1.005722,-361.407715,0.101899,0.000000
72.410004,47.563133,-361.407715,-0.000526,0.003989,0.101309,211.571381,10.777961,1.013093,-361.407715,0.102532,0.000000
72.790001,48.216270,-361.407715,-0.000530,0.004005,0.101734,214.476685,10.925963,1.017342,-361.407715,0.103165,0.000000
73.170006,50.611748,-361.496704,-0.000513,0.004043,0.102680,225.132294,11.468785,1.026795,-361.496704,0.103798,0.000000
73.550003,52.135490,-361.541168,-0.000496,0.004068,0.103321,231.910248,11.814072,1.033213,-361.541168,0.104431,0.000000
73.930000,53.745628,-361.541168,-0.000474,0.004091,0.103902,239.072495,12.178934,1.039023,-361.541168,0.105064,0.000000
74.310005,55.140915,-361.496704,-0.000470,0.004117,0.104579,245.279037,12.495111,1.045788,-361.496704,0.105697,0.000000
74.690002,56.702644,-361.541168,-0.000461,0.004143,0.105238,252.225952,12.849003,1.052378,-361.541168,0.106331,0.000000
75.070007,58.461731,-361.585663,-0.000448,0.004168,0.105880,260.050781,13.247617,1.058796,-361.585663,0.106964,0.000000
75.450005,59.511818,-361.585663,-0.000435,0.004190,0.106417,264.721802,13.485571,1.064173,-361.585663,0.107597,0.000000
75.830002,61.078018,-361.585663,-0.000418,0.004210,0.106929,271.688599,13.840477,1.069289,-361.585663,0.108230,0.000000
76.210007,62.594315,-361.585663,-0.000410,0.004234,0.107536,278.433411,14.184074,1.075360,-361.585663,0.108872,0.000000
76.590004,63.970985,-361.585663,-0.000397,0.004254,0.108056,284.557159,14.496032,1.080563,-361.585663,0.109505,0.000000
76.970001,66.093498,-361.585663,-0.000379,0.004281,0.108741,293.998566,14.977000,1.087414,-361.585663,0.110138,0.000000
77.350006,66.298683,-361.674622,-0.000384,0.004283,0.108793,294.911285,15.023497,1.087935,-361.674622,0.019104,0.000000
77.730003,65.580376,-361.719086,-0.000375,0.004282,0.108767,291.716095,14.860725,1.087674,-361.719086,294.500488,0.000000
78.110001,64.935051,-361.674622,-0.000379,0.004283,0.108776,288.845520,14.714493,1.087761,-361.674622,294.500488,0.000000
78.490005,65.806770,-361.630127,-0.000354,0.004300,0.109227,292.723145,14.912027,1.092271,-361.630127,294.500488,0.000000
78.870003,65.364769,-361.719086,-0.000345,0.004300,0.109227,290.757019,14.811869,1.092271,-361.719086,294.500488,0.000000
79.250000,65.107826,-361.763580,-0.000349,0.004301,0.109253,289.614075,14.753644,1.092531,-361.763580,294.500488,0.000000
79.630005,64.932076,-361.763580,-0.000358,0.004305,0.109348,288.832306,14.713819,1.093485,-361.763580,294.500488,0.000000
80.010002,64.898933,-361.719086,-0.000349,0.004311,0.109496,288.684875,14.706308,1.094959,-361.719086,294.500488,0.000000
80.390007,65.253059,-361.719086,-0.000345,0.004312,0.109522,290.260101,14.786554,1.095219,-361.719086,294.500488,0.000000
80.770004,65.043419,-361.763580,-0.000341,0.004312,0.109522,289.327576,14.739050,1.095219,-361.763580,294.500488,0.000000
81.150002,64.932823,-361.763580,-0.000336,0.004313,0.109548,288.835632,14.713987,1.095479,-361.763580,294.500488,0.000000
81.530006,65.854439,-361.808044,-0.000341,0.004323,0.109817,292.935181,14.922830,1.098168,-361.808044,294.500488,0.000000
81.910004,65.748680,-361.808044,-0.000345,0.004323,0.109817,292.464722,14.898865,1.098168,-361.808044,294.500488,0.000000
82.290001,65.577400,-361.852539,-0.000328,0.004323,0.109817,291.702850,14.860051,1.098168,-361.852539,294.500488,0.000000
82.670006,65.428444,-361.808044,-0.000332,0.004323,0.109817,291.040253,14.826298,1.098168,-361.808044,294.500488,0.000000
83.050003,65.282478,-361.852539,-0.000332,0.004324,0.109825,290.390961,14.793221,1.098254,-361.852539,294.500488,0.000000
83.430000,65.152519,-361.897003,-0.000336,0.004324,0.109825,289.812866,14.763772,1.098254,-361.897003,294.500488,0.000000
83.810005,65.007286,-361.897003,-0.000336,0.004324,0.109825,289.166840,14.730862,1.098254,-361.897003,294.500488,0.000000
84.190002,64.886269,-361.897003,-0.000323,0.004324,0.109825,288.628540,14.703439,1.098254,-361.897003,294.500488,0.000000
84.570007,64.759285,-361.852539,-0.000315,0.004324,0.109825,288.063690,14.674664,1.098254,-361.852539,294.500488,0.000000
84.950005,66.410759,-361.985992,-0.000315,0.004314,0.109574,295.409821,15.048893,1.095740,-361.985992,294.500488,0.000000
85.330002,66.280067,-361.941498,-0.000315,0.004314,0.109574,294.828461,15.019279,1.095740,-361.941498,294.500488,0.000000
85.710007,66.152702,-361.941498,-0.000323,0.004314,0.109574,294.261902,14.990417,1.095740,-361.941498,294.500488,0.000000
86.090004,66.030205,-361.985992,-0.000328,0.004314,0.109574,293.717010,14.962658,1.095740,-361.985992,294.500488,0.000000
86.470001,65.873436,-361.985992,-0.000315,0.004314,0.109583,293.019684,14.927135,1.095826,-361.985992,294.500488,0.000000
86.850006,65.835823,-361.985992,-0.000310,0.004314,0.109583,292.852356,14.918611,1.095826,-361.985992,294.500488,0.000000
87.230003,65.722984,-362.030457,-0.000315,0.004314,0.109583,292.350433,14.893042,1.095826,-362.030457,294.500488,0.000000
87.610001,65.603462,-362.030457,-0.000319,0.004315,0.109591,291.818787,14.865956,1.095913,-362.030457,294.500488,0.000000
87.990005,65.542015,-361.985992,-0.000315,0.004315,0.109591,291.545441,14.852034,1.095913,-361.985992,294.500488,0.000000
88.370003,65.427330,-361.985992,-0.000319,0.004315,0.109600,291.035309,14.826045,1.096000,-361.985992,294.500488,0.000000
88.750008,65.310402,-362.119415,-0.000302,0.004315,0.109609,290.515167,14.799548,1.096086,-362.119415,294.500488,0.000000
89.130005,65.351357,-362.163910,-0.000315,0.004335,0.110112,290.697357,14.808829,1.101116,-362.163910,294.500488,0.000000
89.510002,65.296623,-362.119415,-0.000323,0.004335,0.110120,290.453888,14.796426,1.101203,-362.119415,294.500488,0.000000
89.890007,65.241142,-362.119415,-0.000315,0.004335,0.110120,290.207092,14.783854,1.101203,-362.119415,294.500488,0.000000
90.270004,65.502174,-361.985992,-0.000306,0.004342,0.110294,291.368225,14.843005,1.102938,-361.985992,294.500488,0.000000
90.650002,65.567345,-362.163910,-0.000319,0.004342,0.110285,291.658112,14.857773,1.102851,-362.163910,294.500488,0.000000
91.030006,65.546852,-362.163910,-0.000323,0.004342,0.110285,291.566956,14.853129,1.102851,-362.163910,294.500488,0.000000
91.410004,65.508125,-362.163910,-0.000328,0.004342,0.110285,291.394684,14.844353,1.102851,-362.163910,294.500488,0.000000
91.790001,65.469414,-362.074951,-0.000310,0.004342,0.110285,291.222504,14.835581,1.102851,-362.074951,294.500488,0.000000
92.170006,65.385994,-362.163910,-0.000315,0.004342,0.110285,290.851440,14.816678,1.102851,-362.163910,294.500488,0.000000
92.550003,65.321953,-362.163910,-0.000297,0.004342,0.110285,290.566559,14.802166,1.102851,-362.163910,294.500488,0.000000
92.930008,65.293648,-362.208374,-0.000319,0.004343,0.110311,290.440643,14.795753,1.103111,-362.208374,294.500488,0.000000
93.310005,65.291405,-362.252869,-0.000323,0.004343,0.110320,290.430664,14.795244,1.103198,-362.252869,294.500488,0.000000
93.690002,65.327538,-362.208374,-0.000315,0.004346,0.110380,290.591400,14.803432,1.103805,-362.208374,294.500488,0.000000
94.070007,65.353233,-362.208374,-0.000310,0.004346,0.110380,290.705688,14.809255,1.103805,-362.208374,294.500488,0.000000
94.450005,65.345039,-362.341827,-0.000306,0.004346,0.110380,290.669250,14.807397,1.103805,-362.341827,294.500488,0.000000
94.830002,65.315620,-362.386322,-0.000306,0.004346,0.110380,290.538391,14.800731,1.103805,-362.386322,294.500488,0.000000
95.210007,65.278008,-362.341827,-0.000332,0.004346,0.110380,290.371094,14.792209,1.103805,-362.341827,294.500488,0.000000
95.590004,65.252678,-362.297333,-0.000310,0.004346,0.110380,290.258423,14.786469,1.103805,-362.297333,294.500488,0.000000
95.970001,65.219551,-362.252869,-0.000315,0.004346,0.110380,290.111053,14.778962,1.103805,-362.252869,294.500488,0.000000
96.350006,65.293648,-362.386322,-0.000310,0.004348,0.110441,290.440643,14.795753,1.104412,-362.386322,294.500488,0.000000
96.730003,65.287315,-362.386322,-0.000297,0.004348,0.110441,290.412476,14.794317,1.104412,-362.386322,294.500488,0.000000
97.110008,65.269447,-362.430786,-0.000310,0.004348,0.110441,290.333008,14.790268,1.104412,-362.430786,294.500488,0.000000
97.490005,65.247475,-362.386322,-0.000306,0.004348,0.110441,290.235260,14.785289,1.104412,-362.386322,294.500488,0.000000
97.870003,65.220665,-362.386322,-0.000306,0.004348,0.110450,290.115997,14.779214,1.104499,-362.386322,294.500488,0.000000
98.250008,65.177101,-362.430786,-0.000315,0.004348,0.110450,289.922211,14.769342,1.104499,-362.430786,294.500488,0.000000
98.630005,65.521172,-362.430786,-0.000293,0.004353,0.110571,291.452728,14.847310,1.105713,-362.430786,294.500488,0.000000
99.010002,65.523033,-362.475281,-0.000319,0.004353,0.110571,291.460999,14.847732,1.105713,-362.475281,294.500488,0.000000
99.390007,65.513344,-362.475281,-0.000302,0.004353,0.110571,291.417908,14.845536,1.105713,-362.475281,294.500488,0.000000
99.770004,65.514091,-362.430786,-0.000306,0.004353,0.110571,291.421234,14.845706,1.105713,-362.430786,294.500488,0.000000
100.150002,65.495476,-362.430786,-0.000306,0.004353,0.110571,291.338440,14.841487,1.105713,-362.430786,294.500488,0.000000
100.530006,65.444832,-362.519745,-0.000293,0.004353,0.110571,291.113159,14.830010,1.105713,-362.519745,294.500488,0.000000
100.910004,65.407967,-362.519745,-0.000297,0.004353,0.110571,290.949158,14.821657,1.105713,-362.519745,294.500488,0.000000
101.290009,65.371849,-362.519745,-0.000315,0.004353,0.110571,290.788513,14.813473,1.105713,-362.519745,294.500488,0.000000
101.670006,65.343178,-362.564240,-0.000310,0.004353,0.110571,290.660980,14.806976,1.105713,-362.564240,294.500488,0.000000
102.050003,65.327538,-362.519745,-0.000302,0.004353,0.110571,290.591400,14.803432,1.105713,-362.519745,294.500488,0.000000
102.430008,65.305183,-362.564240,-0.000293,0.004353,0.110571,290.491974,14.798367,1.105713,-362.564240,294.500488,0.000000
102.810005,65.293648,-362.608704,-0.000302,0.004353,0.110571,290.440643,14.795753,1.105713,-362.608704,294.500488,0.000000
103.190002,65.262733,-362.653198,-0.000297,0.004353,0.110571,290.303131,14.788747,1.105713,-362.653198,294.500488,0.000000
103.570007,65.241142,-362.564240,-0.000302,0.004353,0.110571,290.207092,14.783854,1.105713,-362.564240,294.500488,0.000000
103.950005,65.244499,-362.608704,-0.000315,0.004355,0.110623,290.222015,14.784615,1.106233,-362.608704,294.500488,0.000000
104.330002,65.279869,-362.608704,-0.000297,0.004355,0.110623,290.379364,14.792629,1.106233,-362.608704,294.500488,0.000000
104.710007,65.271309,-362.697662,-0.000293,0.004355,0.110623,290.341278,14.790690,1.106233,-362.697662,294.500488,0.000000
105.090004,65.266090,-362.697662,-0.000323,0.004355,0.110623,290.318085,14.789508,1.106233,-362.697662,294.500488,0.000000
105.470001,65.234810,-362.653198,-0.000297,0.004355,0.110623,290.178925,14.782419,1.106233,-362.653198,294.500488,0.000000
105.850006,65.236305,-362.697662,-0.000310,0.004355,0.110623,290.185577,14.782759,1.106233,-362.697662,294.500488,0.000000
106.230003,65.221031,-362.697662,-0.000297,0.004355,0.110623,290.117645,14.779297,1.106233,-362.697662,294.500488,0.000000
106.610008,65.209496,-362.742157,-0.000310,0.004356,0.110641,290.066315,14.776683,1.106406,-362.742157,294.500488,0.000000
106.990005,65.200188,-362.742157,-0.000302,0.004356,0.110641,290.024933,14.774573,1.106406,-362.742157,294.500488,0.000000
107.370003,65.171883,-362.786652,-0.000315,0.004356,0.110641,289.899017,14.768160,1.106406,-362.786652,294.500488,0.000000
107.750008,65.132042,-362.742157,-0.000302,0.004356,0.110641,289.721802,14.759132,1.106406,-362.742157,294.500488,0.000000
108.130005,65.116402,-362.786652,-0.000289,0.004356,0.110641,289.652222,14.755588,1.106406,-362.786652,294.500488,0.000000
108.510002,65.080284,-362.786652,-0.000293,0.004356,0.110641,289.491577,14.747403,1.106406,-362.786652,294.500488,0.000000
108.890007,65.065010,-362.786652,-0.000306,0.004356,0.110641,289.423615,14.743942,1.106406,-362.786652,294.500488,0.000000
109.270004,65.406471,-362.831116,-0.000306,0.004362,0.110805,290.942505,14.821319,1.108054,-362.831116,294.500488,0.000000
109.650002,65.562126,-362.831116,-0.000293,0.004362,0.110805,291.634888,14.856590,1.108054,-362.831116,294.500488,0.000000
110.030006,65.573296,-362.831116,-0.000289,0.004362,0.110805,291.684601,14.859120,1.108054,-362.831116,294.500488,0.000000
110.410004,65.580376,-362.875610,-0.000293,0.004362,0.110805,291.716095,14.860725,1.108054,-362.875610,294.500488,0.000000
110.790009,65.584846,-362.920074,-0.000302,0.004362,0.110805,291.735962,14.861739,1.108054,-362.920074,294.500488,0.000000
111.170006,65.569206,-362.920074,-0.000297,0.004362,0.110805,291.666382,14.858194,1.108054,-362.920074,294.500488,0.000000
111.550003,65.572548,-362.831116,-0.000306,0.004362,0.110805,291.681274,14.858952,1.108054,-362.831116,294.500488,0.000000
111.930008,65.554680,-362.875610,-0.000293,0.004362,0.110805,291.601776,14.854903,1.108054,-362.875610,294.500488,0.000000
112.310005,65.550591,-362.964569,-0.000293,0.004362,0.110805,291.583588,14.853976,1.108054,-362.964569,294.500488,0.000000
112.690002,65.538292,-362.964569,-0.000297,0.004362,0.110805,291.528870,14.851189,1.108054,-362.964569,294.500488,0.000000
113.070007,65.518562,-362.964569,-0.000293,0.004362,0.110805,291.441132,14.846719,1.108054,-362.964569,294.500488,0.000000
113.450005,65.509621,-362.964569,-0.000306,0.004362,0.110805,291.401337,14.844692,1.108054,-362.964569,294.500488,0.000000
113.830002,65.504784,-363.009033,-0.000280,0.004362,0.110805,291.379822,14.843596,1.108054,-363.009033,294.500488,0.000000
114.210007,65.469414,-363.009033,-0.000297,0.004362,0.110805,291.222504,14.835581,1.108054,-363.009033,294.500488,0.000000
114.590004,65.425468,-363.053528,-0.000289,0.004362,0.110805,291.027008,14.825624,1.108054,-363.053528,294.500488,0.000000
114.970009,65.404610,-363.053528,-0.000306,0.004362,0.110805,290.934235,14.820896,1.108054,-363.053528,294.500488,0.000000
115.350006,65.375938,-363.097992,-0.000285,0.004362,0.110805,290.806702,14.814400,1.108054,-363.097992,294.500488,0.000000
115.730003,65.365517,-363.053528,-0.000285,0.004362,0.110805,290.760345,14.812038,1.108054,-363.053528,294.500488,0.000000
116.110008,65.336845,-363.097992,-0.000293,0.004362,0.110805,290.632812,14.805541,1.108054,-363.097992,294.500488,0.000000
116.490005,65.326408,-363.142487,-0.000310,0.004362,0.110805,290.586365,14.803176,1.108054,-363.142487,294.500488,0.000000
116.870003,65.310402,-363.097992,-0.000297,0.004363,0.110814,290.515167,14.799548,1.108141,-363.097992,294.500488,0.000000
117.250008,65.311516,-363.142487,-0.000315,0.004363,0.110814,290.520142,14.799801,1.108141,-363.142487,294.500488,0.000000
117.630005,65.299232,-363.053528,-0.000297,0.004363,0.110814,290.465485,14.797018,1.108141,-363.053528,294.500488,0.000000
118.010002,65.291039,-363.142487,-0.000297,0.004363,0.110814,290.429047,14.795160,1.108141,-363.142487,294.500488,0.000000
118.390007,65.280617,-363.186951,-0.000297,0.004363,0.110814,290.382690,14.792799,1.108141,-363.186951,294.500488,0.000000
118.770004,65.270180,-363.142487,-0.000306,0.004363,0.110814,290.336273,14.790435,1.108141,-363.142487,294.500488,0.000000
119.150009,65.248222,-363.186951,-0.000306,0.004363,0.110814,290.238586,14.785459,1.108141,-363.186951,294.500488,0.000000
119.530006,65.240028,-363.186951,-0.000289,0.004363,0.110814,290.202148,14.783602,1.108141,-363.186951,294.500488,0.000000
119.910004,65.208748,-363.231445,-0.000293,0.004363,0.110814,290.062988,14.776513,1.108141,-363.231445,294.500488,0.000000
120.290009,65.196083,-363.275940,-0.000289,0.004363,0.110814,290.006653,14.773643,1.108141,-363.275940,294.500488,0.000000
120.670006,65.164436,-363.275940,-0.000297,0.004363,0.110831,289.865875,14.766473,1.108315,-363.275940,294.500488,0.000000
121.050003,65.353233,-363.231445,-0.000302,0.004367,0.110918,290.705688,14.809255,1.109182,-363.231445,294.500488,0.000000
121.430008,65.389351,-363.231445,-0.000302,0.004367,0.110918,290.866364,14.817439,1.109182,-363.231445,294.500488,0.000000
121.810005,65.403862,-363.275940,-0.000285,0.004367,0.110918,290.930908,14.820727,1.109182,-363.275940,294.500488,0.000000
122.190002,65.395683,-363.320404,-0.000293,0.004367,0.110918,290.894531,14.818873,1.109182,-363.320404,294.500488,0.000000
122.570007,65.401268,-363.320404,-0.000289,0.004367,0.110918,290.919373,14.820139,1.109182,-363.320404,294.500488,0.000000
122.950005,65.402382,-363.364899,-0.000289,0.004367,0.110918,290.924316,14.820392,1.109182,-363.364899,294.500488,0.000000
123.330009,65.375191,-363.275940,-0.000293,0.004367,0.110918,290.803375,14.814230,1.109182,-363.275940,294.500488,0.000000
123.710007,65.377052,-363.409363,-0.000280,0.004367,0.110918,290.811646,14.814652,1.109182,-363.409363,294.500488,0.000000
124.090004,65.362907,-363.409363,-0.000280,0.004367,0.110918,290.748718,14.811446,1.109182,-363.409363,294.500488,0.000000
124.470009,65.355461,-363.453857,-0.000289,0.004367,0.110918,290.715607,14.809759,1.109182,-363.453857,294.500488,0.000000
124.850006,65.339455,-363.409363,-0.000293,0.004367,0.110918,290.644409,14.806131,1.109182,-363.409363,294.500488,0.000000
125.230003,65.335732,-363.409363,-0.000297,0.004367,0.110918,290.627838,14.805288,1.109182,-363.409363,294.500488,0.000000
125.610008,65.316368,-363.409363,-0.000280,0.004367,0.110918,290.541718,14.800900,1.109182,-363.409363,294.500488,0.000000
125.990005,65.308907,-363.409363,-0.000297,0.004367,0.110918,290.508514,14.799210,1.109182,-363.409363,294.500488,0.000000
126.370003,65.317101,-363.498322,-0.000315,0.004367,0.110918,290.544983,14.801066,1.109182,-363.498322,294.500488,0.000000
126.750008,65.294395,-363.409363,-0.000297,0.004367,0.110918,290.443970,14.795921,1.109182,-363.409363,294.500488,0.000000
127.130005,65.294395,-363.453857,-0.000293,0.004367,0.110918,290.443970,14.795921,1.109182,-363.453857,294.500488,0.000000
127.510010,65.289925,-363.542816,-0.000285,0.004367,0.110918,290.424103,14.794909,1.109182,-363.542816,294.500488,0.000000
127.890007,65.270561,-363.542816,-0.000285,0.004367,0.110918,290.337952,14.790521,1.109182,-363.542816,294.500488,0.000000
128.270004,65.266838,-363.542816,-0.000289,0.004367,0.110918,290.321381,14.789678,1.109182,-363.542816,294.500488,0.000000
128.650009,65.251198,-363.542816,-0.000302,0.004367,0.110918,290.251831,14.786133,1.109182,-363.542816,294.500488,0.000000
129.029999,65.247093,-363.498322,-0.000293,0.004367,0.110918,290.233551,14.785203,1.109182,-363.498322,294.500488,0.000000
129.410004,65.238167,-363.542816,-0.000297,0.004367,0.110918,290.193848,14.783179,1.109182,-363.542816,294.500488,0.000000
129.790009,65.222893,-363.676270,-0.000289,0.004367,0.110918,290.125916,14.779719,1.109182,-363.676270,294.500488,0.000000
130.170013,65.209114,-363.676270,-0.000285,0.004367,0.110918,290.064636,14.776596,1.109182,-363.676270,294.500488,0.000000
130.550003,65.181557,-363.676270,-0.000293,0.004367,0.110918,289.942047,14.770352,1.109182,-363.676270,294.500488,0.000000
130.930008,65.168159,-363.587280,-0.000289,0.004367,0.110918,289.882446,14.767316,1.109182,-363.587280,294.500488,0.000000
131.310013,65.147301,-363.676270,-0.000302,0.004367,0.110918,289.789673,14.762589,1.109182,-363.676270,294.500488,0.000000
131.690002,65.145073,-363.676270,-0.000280,0.004367,0.110918,289.779755,14.762084,1.109182,-363.676270,294.500488,0.000000
132.070007,65.109688,-363.676270,-0.000302,0.004367,0.110918,289.622345,14.754066,1.109182,-363.676270,294.500488,0.000000
132.450012,65.095177,-363.676270,-0.000285,0.004367,0.110918,289.557800,14.750778,1.109182,-363.676270,294.500488,0.000000
132.830002,65.143211,-363.720734,-0.000285,0.004370,0.110988,289.771484,14.761663,1.109876,-363.720734,294.500488,0.000000
133.210007,65.234444,-363.765228,-0.000293,0.004370,0.110988,290.177307,14.782336,1.109876,-363.765228,294.500488,0.000000
133.590012,65.241508,-363.676270,-0.000285,0.004370,0.110988,290.208710,14.783937,1.109876,-363.676270,294.500488,0.000000
133.970001,65.247475,-363.765228,-0.000297,0.004370,0.110988,290.235260,14.785289,1.109876,-363.765228,294.500488,0.000000
134.350006,65.241508,-363.720734,-0.000293,0.004370,0.110988,290.208710,14.783937,1.109876,-363.720734,294.500488,0.000000
134.730011,65.245613,-363.765228,-0.000293,0.004370,0.110988,290.226990,14.784867,1.109876,-363.765228,294.500488,0.000000
135.110001,65.240395,-363.720734,-0.000280,0.004370,0.110988,290.203766,14.783685,1.109876,-363.720734,294.500488,0.000000
135.490005,65.232582,-363.765228,-0.000280,0.004370,0.110988,290.169006,14.781914,1.109876,-363.765228,294.500488,0.000000
135.870010,65.231834,-363.809692,-0.000285,0.004370,0.110988,290.165680,14.781745,1.109876,-363.809692,294.500488,0.000000
136.250000,65.229591,-363.854187,-0.000289,0.004370,0.110988,290.155701,14.781238,1.109876,-363.854187,294.500488,0.000000
136.630005,65.211723,-363.809692,-0.000285,0.004370,0.110988,290.076233,14.777188,1.109876,-363.809692,294.500488,0.000000
137.010010,65.189751,-363.765228,-0.000293,0.004370,0.110988,289.978485,14.772208,1.109876,-363.765228,294.500488,0.000000
137.389999,65.181938,-363.854187,-0.000280,0.004370,0.110988,289.943756,14.770438,1.109876,-363.854187,294.500488,0.000000
137.770004,65.171135,-363.854187,-0.000285,0.004370,0.110988,289.895691,14.767991,1.109876,-363.854187,1681.640991,0.000000
138.150009,65.158470,-363.943146,-0.000302,0.004360,0.110736,289.839355,14.765121,1.107360,-363.943146,0.110537,0.000000
138.530014,65.130180,-363.809692,-0.000276,0.004345,0.110354,289.713501,14.758710,1.103545,-363.809692,0.109904,0.000000
138.910004,65.040428,-363.898651,-0.000272,0.004321,0.109765,289.314270,14.738372,1.097647,-363.898651,0.109270,0.000000
139.290009,65.020332,-363.898651,-0.000272,0.004299,0.109201,289.224884,14.733818,1.092011,-363.898651,0.108637,0.000000
139.670013,64.993507,-363.943146,-0.000254,0.004273,0.108533,289.105560,14.727739,1.085333,-363.943146,0.108004,0.000000
140.050003,64.962242,-363.987610,-0.000280,0.004247,0.107874,288.966492,14.720654,1.078742,-363.987610,0.107371,0.000000
140.430008,64.981972,-363.943146,-0.000263,0.004224,0.107302,289.054260,14.725125,1.073018,-363.943146,0.106738,0.000000
140.810013,64.912712,-363.943146,-0.000263,0.004199,0.106660,288.746155,14.709432,1.066601,-363.943146,0.106105,0.000000
141.190002,64.939140,-363.898651,-0.000276,0.004177,0.106096,288.863708,14.715420,1.060964,-363.898651,0.105472,0.000000
141.570007,64.849403,-363.943146,-0.000280,0.004155,0.105533,288.464539,14.695085,1.055327,-363.943146,0.104839,0.000000
141.950012,64.660606,-364.076599,-0.000285,0.004132,0.104952,287.624756,14.652303,1.049517,-364.076599,0.104206,0.000000
142.330002,63.957573,-364.032104,-0.000289,0.004107,0.104319,284.497498,14.492993,1.043186,-364.032104,0.103573,0.000000
142.710007,62.959991,-364.032104,-0.000263,0.004083,0.103703,280.060028,14.266937,1.037028,-364.032104,0.102940,0.000000
143.090012,61.991074,-364.076599,-0.000263,0.004061,0.103139,275.750061,14.047379,1.031392,-364.076599,0.102307,0.000000
143.470001,60.760757,-364.076599,-0.000272,0.004041,0.102636,270.277344,13.768584,1.026362,-364.076599,0.101674,0.000000
143.850006,59.409416,-364.121063,-0.000272,0.004021,0.102133,264.266296,13.462366,1.021332,-364.121063,0.101040,0.000000
144.230011,57.788109,-364.032104,-0.000267,0.003993,0.101422,257.054352,13.094973,1.014220,-364.032104,0.100407,0.000000
144.610001,55.378860,-364.121063,-0.000259,0.003965,0.100720,246.337479,12.549028,1.007196,-364.121063,0.099774,0.000000
144.990005,52.680275,-364.121063,-0.000267,0.003938,0.100026,234.333572,11.937521,1.000258,-364.121063,0.099141,0.000000
145.370010,50.535782,-364.165558,-0.000254,0.003917,0.099497,224.794388,11.451572,0.994968,-364.165558,0.098508,0.000000
145.750000,48.523109,-364.165558,-0.000263,0.003901,0.099089,215.841568,10.995494,0.990892,-364.165558,0.097875,0.000000
146.130005,45.518059,-364.121063,-0.000267,0.003874,0.098395,202.474442,10.314539,0.983954,-364.121063,0.097242,0.000000
146.510010,42.965446,-364.165558,-0.000276,0.003852,0.097832,191.119858,9.736109,0.978317,-364.165558,0.096609,0.000000
146.889999,39.500153,-364.121063,-0.000254,0.003816,0.096938,175.705460,8.950863,0.969385,-364.121063,0.095976,0.000000
147.270004,37.396988,-364.210022,-0.000276,0.003799,0.096505,166.350113,8.474278,0.965049,-364.210022,0.095343,0.000000
147.650009,34.024788,-364.298981,-0.000276,0.003766,0.095664,151.349823,7.710127,0.956637,-364.298981,0.094710,0.000000
148.030014,32.038925,-364.165558,-0.000276,0.003752,0.095291,142.516251,7.260124,0.952908,-364.165558,0.094077,0.000000
148.410004,29.824051,-364.210022,-0.000272,0.003731,0.094770,132.664001,6.758226,0.947704,-364.210022,0.093435,0.000000
148.790009,26.076866,-364.210022,-0.000263,0.003693,0.093808,115.995697,5.909102,0.938078,-364.210022,0.092802,0.000000
149.170013,23.464676,-364.254517,-0.000285,0.003672,0.093270,104.376091,5.317172,0.932701,-364.254517,0.092169,0.000000
149.550003,20.802956,-364.254517,-0.000297,0.003648,0.092672,92.536171,4.714017,0.926717,-364.254517,0.091536,0.000000
149.930008,17.831055,-364.298981,-0.000285,0.003620,0.091952,79.316490,4.040575,0.919519,-364.298981,0.090903,0.000000
150.310013,16.058929,-364.298981,-0.000302,0.003606,0.091605,71.433685,3.639005,0.916051,-364.298981,0.090270,0.000000
150.690002,12.114761,-364.254517,-0.000285,0.003568,0.090634,53.889149,2.745244,0.906338,-364.254517,0.089636,0.000000
151.070007,9.601990,-364.298981,-0.000306,0.003546,0.090079,42.711784,2.175842,0.900787,-364.298981,0.089003,0.000000
151.450012,6.699722,-364.387939,-0.000323,0.003518,0.089368,29.801853,1.518179,0.893676,-364.387939,0.088370,0.000000
151.830002,5.402748,-364.343475,-0.000315,0.003510,0.089142,24.032623,1.224280,0.891421,-364.343475,0.087737,0.000000
152.210007,2.319130,-364.343475,-0.000306,0.003477,0.088327,10.316005,0.525522,0.883269,-364.343475,0.087104,0.000000
152.590012,-0.590584,-364.387939,-0.000319,0.003448,0.087572,-2.627048,-0.133828,0.875724,-364.387939,0.086471,0.000000
152.970001,-0.284492,-364.343475,-0.000371,0.003422,0.086922,-1.265486,-0.064467,0.869220,-364.343475,0.085838,0.000000
153.350006,-0.194756,-364.476898,-0.000405,0.003396,0.086254,-0.866316,-0.044132,0.862543,-364.476898,0.085205,0.000000
153.730011,-0.079689,-364.387939,-0.000414,0.003372,0.085647,-0.354474,-0.018058,0.856472,-364.387939,0.084572,0.000000
154.110001,-0.037987,-364.432434,-0.000470,0.003352,0.085144,-0.168974,-0.008608,0.851442,-364.432434,0.083939,0.000000
154.490005,-0.076340,-364.387939,-0.000517,0.003317,0.084260,-0.339576,-0.017299,0.842596,-364.387939,0.083306,0.000000
154.700012,0.017868,-364.476898,-0.000535,0.003314,0.084173,0.079481,0.004049,0.841729,-364.476898,0.084008,0.000000