File: Data/compression 34/AutoNoHeating-10-34-reverse-1-1_11152024_194105.csv
Time (sec),S:Load (lbs),S:HL1 (DIM),S:LVDT (in),S:Position (in),Ch:Position (mm),Ch:Load (N),Ch:Stress (MPa),Ch:Strain (mm/mm),Ch:HL1 (DIM),Set Point (),Cycles ()
0.210000,0.012283,-322.931702,-0.008800,-0.008663,-0.220032,0.054639,0.002783,-2.200325,-322.931702,-0.219772,0.000000
0.660000,-0.036499,-322.976196,-0.008795,-0.008535,-0.216798,-0.162356,-0.008271,-2.167977,-322.976196,-0.215714,0.000000
1.110000,-0.000374,-322.976196,-0.008537,-0.008250,-0.209556,-0.001663,-0.000085,-2.095564,-322.976196,-0.208221,0.000000
1.560000,-0.033516,-323.020660,-0.008239,-0.007954,-0.202038,-0.149086,-0.007595,-2.020375,-323.020660,-0.200711,0.000000
2.010000,-0.081551,-323.065155,-0.007942,-0.007665,-0.194692,-0.362755,-0.018480,-1.946922,-323.065155,-0.193218,0.000000
2.460000,-0.038727,-323.065155,-0.007623,-0.007363,-0.187009,-0.172265,-0.008776,-1.870085,-323.065155,-0.185725,0.000000
2.910000,-0.024956,-323.065155,-0.007338,-0.007068,-0.179516,-0.111009,-0.005655,-1.795157,-323.065155,-0.178232,0.000000
3.360000,-0.024582,-323.109619,-0.007015,-0.006768,-0.171910,-0.109346,-0.005570,-1.719101,-323.109619,-0.170739,0.000000
3.810000,-0.035751,-323.109619,-0.006726,-0.006479,-0.164573,-0.159030,-0.008101,-1.645734,-323.109619,-0.163229,0.000000
4.260000,-0.052132,-323.154114,-0.006420,-0.006176,-0.156881,-0.231893,-0.011813,-1.568811,-323.154114,-0.155736,0.000000
4.710000,-0.092720,-323.154114,-0.006118,-0.005894,-0.149709,-0.412439,-0.021011,-1.497092,-323.154114,-0.148244,0.000000
5.160000,0.001488,-323.154114,-0.005816,-0.005593,-0.142052,0.006618,0.000337,-1.420516,-323.154114,-0.140751,0.000000
5.610000,0.004837,-323.154114,-0.005519,-0.005304,-0.134715,0.021516,0.001096,-1.347148,-323.154114,-0.133241,0.000000
6.060000,-0.067406,-323.154114,-0.005208,-0.005007,-0.127179,-0.299836,-0.015274,-1.271786,-323.154114,-0.125748,0.000000
6.510000,0.019363,-323.243073,-0.004907,-0.004704,-0.119478,0.086133,0.004388,-1.194777,-323.243073,-0.118255,0.000000
6.960001,0.172775,-323.198578,-0.004665,-0.000004,-0.000095,0.768543,0.039151,-0.000954,-323.198578,0.000095,0.000000
7.410000,0.153786,-323.243073,-0.004665,-0.000004,-0.000104,0.684073,0.034848,-0.001041,-323.243073,0.000113,0.000000
7.860001,0.135910,-323.287567,-0.004648,-0.000004,-0.000104,0.604558,0.030798,-0.001041,-323.287567,0.000859,0.000000
8.310000,0.218948,-323.287567,-0.004644,0.000020,0.000512,0.973931,0.049614,0.005116,-323.287567,0.001613,0.000000
8.760000,0.239059,-323.287567,-0.004613,0.000047,0.001205,1.063390,0.054172,0.012054,-323.287567,0.002359,0.000000
9.210000,0.293800,-323.332031,-0.004583,0.000079,0.002003,1.306889,0.066576,0.020033,-323.332031,0.003113,0.000000
9.660001,0.362312,-323.376526,-0.004566,0.000103,0.002628,1.611646,0.082101,0.026277,-323.376526,0.003859,0.000000
10.110001,0.437904,-323.376526,-0.004514,0.000132,0.003347,1.947896,0.099231,0.033475,-323.376526,0.004614,0.000000
10.560000,0.548874,-323.420990,-0.004497,0.000172,0.004362,2.441513,0.124377,0.043621,-323.420990,0.005359,0.000000
11.010000,0.632286,-323.376526,-0.004458,0.000199,0.005047,2.812549,0.143278,0.050473,-323.376526,0.006114,0.000000
11.460001,0.692986,-323.420990,-0.004432,0.000229,0.005828,3.082554,0.157033,0.058277,-323.420990,0.006860,0.000000
11.910001,0.831879,-323.420990,-0.004411,0.000256,0.006496,3.700381,0.188506,0.064955,-323.420990,0.007614,0.000000
12.360001,0.985664,-323.465485,-0.004389,0.000291,0.007380,4.384454,0.223355,0.073801,-323.465485,0.008360,0.000000
12.810000,1.141319,-323.465485,-0.004324,0.000325,0.008256,5.076842,0.258627,0.082560,-323.465485,0.009115,0.000000
13.260000,1.189354,-323.509949,-0.004307,0.000350,0.008880,5.290511,0.269511,0.088804,-323.509949,0.009860,0.000000
13.710001,1.348732,-323.554443,-0.004273,0.000381,0.009687,5.999460,0.305627,0.096869,-323.554443,0.010615,0.000000
14.160001,1.496933,-323.554443,-0.004255,0.000407,0.010346,6.658690,0.339210,0.103460,-323.554443,0.011361,0.000000
14.610001,1.631363,-323.509949,-0.004234,0.000436,0.011083,7.256665,0.369672,0.110831,-323.509949,0.012115,0.000000
15.060000,1.706581,-323.509949,-0.004191,0.000467,0.011864,7.591252,0.386717,0.118636,-323.509949,0.012861,0.000000
15.510001,1.883453,-323.598907,-0.004156,0.000498,0.012653,8.378019,0.426797,0.126528,-323.598907,0.013607,0.000000
15.960001,1.962029,-323.554443,-0.004130,0.000521,0.013225,8.727539,0.444602,0.132252,-323.554443,0.014361,0.000000
16.410000,2.134811,-323.643402,-0.004105,0.000548,0.013919,9.496116,0.483755,0.139190,-323.643402,0.015107,0.000000
16.860001,2.185822,-323.598907,-0.004087,0.000570,0.014474,9.723020,0.495314,0.144740,-323.598907,0.015862,0.000000
17.310001,2.427490,-323.643402,-0.004040,0.000613,0.015567,10.798016,0.550077,0.155667,-323.643402,0.016607,0.000000
17.760000,2.519096,-323.643402,-0.004027,0.000636,0.016148,11.205501,0.570835,0.161477,-323.643402,0.017362,0.000000
18.210001,2.633041,-323.687866,-0.003997,0.000667,0.016946,11.712353,0.596656,0.169456,-323.687866,0.018108,0.000000
18.660002,2.828537,-323.732361,-0.003967,0.000698,0.017717,12.581961,0.640956,0.177174,-323.732361,0.018862,0.000000
19.110001,2.903755,-323.687866,-0.003928,0.000729,0.018524,12.916548,0.658000,0.185239,-323.687866,0.019608,0.000000
19.560001,2.997971,-323.732361,-0.003902,0.000753,0.019122,13.335639,0.679350,0.191223,-323.732361,0.020362,0.000000
20.010000,3.267563,-323.821320,-0.003867,0.000788,0.020024,14.534845,0.740440,0.200242,-323.821320,0.021108,0.000000
20.460001,3.257141,-323.776855,-0.003833,0.000812,0.020614,14.488487,0.738079,0.206139,-323.776855,0.021863,0.000000
20.910002,3.402367,-323.821320,-0.003807,0.000841,0.021368,15.134482,0.770987,0.213684,-323.821320,0.022609,0.000000
21.360001,3.396782,-323.821320,-0.003781,0.000864,0.021941,15.109641,0.769722,0.219408,-323.821320,0.023363,0.000000
21.810001,3.893150,-323.821320,-0.003738,0.000910,0.023112,17.317598,0.882200,0.231116,-323.821320,0.024109,0.000000
22.260000,3.871178,-323.865814,-0.003721,0.000935,0.023745,17.219858,0.877221,0.237446,-323.865814,0.024863,0.000000
22.710001,3.900597,-323.865814,-0.003691,0.000958,0.024326,17.350719,0.883888,0.243257,-323.865814,0.025609,0.000000
23.160002,3.915123,-323.910278,-0.003656,0.000982,0.024933,17.415337,0.887180,0.249327,-323.910278,0.026364,0.000000
23.610001,4.370529,-323.910278,-0.003626,0.001026,0.026060,19.441084,0.990376,0.260601,-323.910278,0.027109,0.000000
24.060001,4.339996,-323.865814,-0.003591,0.001055,0.026797,19.305267,0.983457,0.267973,-323.865814,0.027864,0.000000
24.510000,4.471817,-323.954773,-0.003553,0.001087,0.027621,19.891636,1.013328,0.276211,-323.954773,0.028610,0.000000
24.960001,4.461395,-323.954773,-0.003523,0.001114,0.028298,19.845278,1.010967,0.282976,-323.954773,0.029364,0.000000
25.410002,4.784981,-323.999237,-0.003488,0.001151,0.029234,21.284658,1.084292,0.292342,-323.999237,0.030110,0.000000
25.860001,4.783493,-323.999237,-0.003458,0.001173,0.029807,21.278040,1.083955,0.298065,-323.999237,0.030865,0.000000
26.310001,4.730247,-323.999237,-0.003432,0.001193,0.030292,21.041191,1.071889,0.302922,-323.999237,0.031610,0.000000
26.760002,4.908607,-323.999237,-0.003393,0.001227,0.031159,21.834576,1.112306,0.311594,-323.999237,0.032365,0.000000
27.210001,4.792427,-324.043732,-0.003359,0.001251,0.031766,21.317780,1.085979,0.317665,-324.043732,0.033111,0.000000
27.660002,5.235184,-324.088196,-0.003341,0.001284,0.032625,23.287260,1.186310,0.326250,-324.088196,0.033865,0.000000
28.110001,5.344284,-324.043732,-0.003316,0.001316,0.033414,23.772562,1.211032,0.334142,-324.043732,0.034611,0.000000
28.560001,5.445572,-324.088196,-0.003255,0.001353,0.034377,24.223114,1.233984,0.343768,-324.088196,0.035365,0.000000
29.010002,5.316360,-324.132690,-0.003251,0.001372,0.034845,23.648352,1.204704,0.348451,-324.132690,0.036111,0.000000
29.460001,5.798950,-324.132690,-0.003199,0.001405,0.035686,25.795019,1.314061,0.356863,-324.132690,0.036866,0.000000
29.910002,5.878639,-324.132690,-0.003173,0.001438,0.036536,26.149494,1.332119,0.365362,-324.132690,0.037612,0.000000
30.360001,5.938591,-324.221649,-0.003152,0.001463,0.037169,26.416172,1.345704,0.371693,-324.221649,0.038366,0.000000
30.810001,5.995567,-324.221649,-0.003117,0.001491,0.037872,26.669615,1.358615,0.378717,-324.221649,0.039112,0.000000
31.260002,6.115471,-324.177185,-0.003096,0.001522,0.038652,27.202972,1.385786,0.386522,-324.177185,0.039866,0.000000
31.710001,6.227928,-324.266144,-0.003053,0.001550,0.039372,27.703209,1.411269,0.393720,-324.266144,0.040612,0.000000
32.160000,6.280060,-324.266144,-0.003005,0.001581,0.040170,27.935101,1.423082,0.401699,-324.266144,0.041367,0.000000
32.610001,6.455818,-324.266144,-0.002971,0.001616,0.041037,28.716913,1.462909,0.410371,-324.266144,0.042112,0.000000
33.060001,6.632324,-324.355103,-0.002945,0.001648,0.041861,29.502052,1.502906,0.418610,-324.355103,0.042867,0.000000
33.510002,6.733604,-324.355103,-0.002915,0.001675,0.042555,29.952568,1.525857,0.425548,-324.355103,0.043613,0.000000
33.960003,6.906013,-324.355103,-0.002884,0.001709,0.043405,30.719482,1.564925,0.434046,-324.355103,0.044367,0.000000
34.410000,6.908623,-324.355103,-0.002841,0.001740,0.044194,30.731089,1.565516,0.441938,-324.355103,0.045113,0.000000
34.860001,7.068375,-324.399567,-0.002807,0.001769,0.044931,31.441700,1.601717,0.449310,-324.399567,0.045868,0.000000
35.310001,7.055336,-324.444061,-0.002772,0.001792,0.045529,31.383701,1.598762,0.455293,-324.444061,0.046613,0.000000
35.760002,7.497345,-324.399567,-0.002729,0.001829,0.046457,33.349857,1.698923,0.464573,-324.399567,0.047359,0.000000
36.210003,7.372971,-324.399567,-0.002716,0.001856,0.047151,32.796612,1.670739,0.471510,-324.399567,0.048114,0.000000
36.660000,7.514847,-324.444061,-0.002669,0.001886,0.047914,33.427708,1.702889,0.479142,-324.444061,0.048859,0.000000
37.110001,7.444466,-324.488525,-0.002652,0.001909,0.048487,33.114635,1.686940,0.484866,-324.488525,0.049614,0.000000
37.560001,7.664543,-324.488525,-0.002621,0.001937,0.049198,34.093590,1.736810,0.491977,-324.488525,0.050360,0.000000
38.010002,7.706993,-324.533020,-0.002591,0.001965,0.049909,34.282417,1.746430,0.499088,-324.533020,0.051114,0.000000
38.460003,7.799339,-324.577515,-0.002561,0.001992,0.050594,34.693195,1.767356,0.505939,-324.577515,0.051860,0.000000
38.910004,7.969513,-324.533020,-0.002527,0.002024,0.051409,35.450165,1.805918,0.514091,-324.533020,0.052615,0.000000
39.360001,8.315445,-324.577515,-0.002501,0.002060,0.052320,36.988945,1.884307,0.523197,-324.577515,0.053360,0.000000
39.810001,8.276344,-324.577515,-0.002466,0.002087,0.053013,36.815018,1.875446,0.530135,-324.577515,0.054115,0.000000
40.260002,8.460297,-324.577515,-0.002440,0.002119,0.053829,37.633278,1.917131,0.538287,-324.577515,0.054861,0.000000
40.710003,7.973610,-324.666473,-0.002406,0.002130,0.054106,35.468388,1.806846,0.541062,-324.666473,0.055615,0.000000
41.160004,8.760056,-324.621979,-0.002380,0.002172,0.055173,38.966675,1.985057,0.551729,-324.621979,0.056361,0.000000
41.610001,8.902679,-324.710937,-0.002345,0.002207,0.056057,39.601097,2.017376,0.560575,-324.710937,0.057115,0.000000
42.060001,8.909752,-324.666473,-0.002307,0.002237,0.056821,39.632557,2.018979,0.568206,-324.666473,0.057861,0.000000
42.510002,8.833786,-324.666473,-0.002276,0.002259,0.057384,39.294643,2.001765,0.573843,-324.666473,0.058616,0.000000
42.960003,8.677765,-324.755432,-0.002259,0.002281,0.057939,38.600628,1.966410,0.579393,-324.755432,0.059362,0.000000
43.410004,9.264999,-324.710937,-0.002229,0.002324,0.059041,41.212776,2.099479,0.590407,-324.710937,0.060116,0.000000
43.860001,9.553955,-324.799896,-0.002190,0.002356,0.059847,42.498116,2.164957,0.598472,-324.799896,0.060862,0.000000
44.310001,9.213982,-324.755432,-0.002160,0.002379,0.060420,40.985836,2.087918,0.604196,-324.755432,0.061616,0.000000
44.760002,9.431076,-324.755432,-0.002130,0.002403,0.061027,41.951523,2.137112,0.610267,-324.755432,0.062362,0.000000
45.210003,9.841431,-324.844391,-0.002100,0.002441,0.062007,43.776871,2.230100,0.620066,-324.844391,0.063117,0.000000
45.660004,10.096504,-324.799896,-0.002061,0.002477,0.062926,44.911495,2.287900,0.629259,-324.799896,0.063862,0.000000
46.110001,9.893188,-324.888855,-0.002044,0.002505,0.063620,44.007099,2.241828,0.636197,-324.888855,0.064617,0.000000
46.560001,10.246941,-324.888855,-0.002005,0.002536,0.064418,45.580669,2.321990,0.644175,-324.888855,0.065363,0.000000
47.010002,10.305405,-324.888855,-0.001975,0.002564,0.065120,45.840729,2.335238,0.651200,-324.888855,0.066117,0.000000
47.460003,10.294609,-324.933350,-0.001957,0.002588,0.065736,45.792709,2.332792,0.657357,-324.933350,0.066863,0.000000
47.910004,10.690811,-324.933350,-0.001923,0.002622,0.066603,47.555103,2.422572,0.666029,-324.933350,0.067618,0.000000
48.360001,10.433128,-324.933350,-0.001884,0.002643,0.067141,46.408875,2.364181,0.671406,-324.933350,0.068363,0.000000
48.810001,11.022224,-324.977814,-0.001871,0.002677,0.067990,49.029305,2.497672,0.679905,-324.977814,0.069118,0.000000
49.260002,10.691185,-324.977814,-0.001841,0.002695,0.068450,47.556767,2.422657,0.684501,-324.977814,0.069864,0.000000
49.710003,11.567001,-324.977814,-0.001802,0.002745,0.069716,51.452591,2.621120,0.697163,-324.977814,0.070618,0.000000
50.160004,10.879974,-325.066803,-0.001781,0.002761,0.070141,48.396542,2.465437,0.701412,-325.066803,0.071364,0.000000
50.610001,11.013283,-325.111267,-0.001759,0.002784,0.070714,48.989529,2.495646,0.707136,-325.111267,0.072118,0.000000
51.060001,11.850380,-325.066803,-0.001716,0.002823,0.071694,52.713123,2.685334,0.716935,-325.066803,0.072864,0.000000
51.510002,11.908844,-325.066803,-0.001703,0.002851,0.072422,52.973183,2.698583,0.724220,-325.066803,0.073619,0.000000
51.960003,11.958740,-325.111267,-0.001681,0.002879,0.073124,53.195133,2.709889,0.731245,-325.111267,0.074365,0.000000
52.410004,11.556206,-325.155762,-0.001660,0.002901,0.073688,51.404572,2.618674,0.736882,-325.155762,0.075119,0.000000
52.860001,12.805885,-325.155762,-0.001608,0.002945,0.074807,56.963425,2.901855,0.748069,-325.155762,0.075865,0.000000
53.310001,12.702370,-325.200226,-0.001591,0.002973,0.075509,56.502964,2.878398,0.755093,-325.200226,0.076619,0.000000
53.760002,12.972336,-325.155762,-0.001552,0.003007,0.076377,57.703831,2.939573,0.763766,-325.155762,0.077365,0.000000
54.210003,12.967499,-325.200226,-0.001531,0.003035,0.077079,57.682316,2.938477,0.770790,-325.200226,0.078120,0.000000
54.660004,13.244537,-325.155762,-0.001513,0.003061,0.077747,58.914646,3.001255,0.777468,-325.155762,0.078865,0.000000
55.110004,14.256279,-325.244720,-0.001479,0.003099,0.078718,63.415096,3.230519,0.787181,-325.244720,0.079611,0.000000
55.560001,14.169518,-325.244720,-0.001440,0.003127,0.079438,63.029163,3.210859,0.794379,-325.244720,0.080366,0.000000
56.010002,14.240265,-325.244720,-0.001401,0.003155,0.080132,63.343861,3.226890,0.801316,-325.244720,0.081112,0.000000
56.460003,14.672218,-325.289185,-0.001388,0.003183,0.080843,65.265289,3.324772,0.808428,-325.289185,0.081866,0.000000
56.910004,14.861755,-325.378143,-0.001358,0.003208,0.081476,66.108391,3.367722,0.814758,-325.378143,0.082612,0.000000
57.360004,15.515266,-325.333679,-0.001328,0.003242,0.082334,69.015350,3.515810,0.823344,-325.333679,0.083366,0.000000
57.810001,15.950943,-325.289185,-0.001315,0.003273,0.083132,70.953339,3.614535,0.831322,-325.289185,0.084112,0.000000
58.260002,16.129311,-325.289185,-0.001272,0.003300,0.083809,71.746758,3.654954,0.838087,-325.289185,0.084867,0.000000
58.710003,16.792130,-325.378143,-0.001259,0.003329,0.084546,74.695122,3.805151,0.845458,-325.378143,0.085612,0.000000
59.160004,16.843895,-325.422638,-0.001229,0.003349,0.085066,74.925385,3.816881,0.850662,-325.422638,0.086367,0.000000
59.610004,18.162460,-325.422638,-0.001212,0.003389,0.086072,80.790657,4.115673,0.860721,-325.422638,0.087113,0.000000
60.060001,18.808159,-325.467133,-0.001181,0.003420,0.086879,83.662872,4.261990,0.868787,-325.467133,0.087867,0.000000
60.510002,19.123558,-325.422638,-0.001164,0.003446,0.087520,85.065834,4.333460,0.875204,-325.422638,0.088613,0.000000
60.960003,19.618813,-325.467133,-0.001138,0.003472,0.088197,87.268837,4.445686,0.881968,-325.467133,0.089368,0.000000
61.410004,20.668533,-325.467133,-0.001095,0.003505,0.089029,91.938225,4.683557,0.890294,-325.467133,0.090113,0.000000
61.860004,20.817482,-325.467133,-0.001074,0.003529,0.089628,92.600784,4.717309,0.896278,-325.467133,0.090868,0.000000
62.310001,21.407692,-325.556091,-0.001056,0.003552,0.090226,95.226173,4.851052,0.902261,-325.556091,0.091614,0.000000
62.760002,22.773178,-325.511597,-0.001026,0.003588,0.091145,101.300156,5.160476,0.911454,-325.511597,0.092368,0.000000
63.210003,22.808929,-325.600555,-0.001022,0.003608,0.091648,101.459183,5.168577,0.916484,-325.600555,0.093114,0.000000
63.660004,24.627968,-325.600555,-0.000996,0.003650,0.092698,109.550674,5.580777,0.926978,-325.600555,0.093868,0.000000
64.110001,25.685135,-325.600555,-0.000974,0.003679,0.093444,114.253189,5.820334,0.934436,-325.600555,0.094614,0.000000
64.560005,27.295647,-325.556091,-0.000949,0.003711,0.094267,121.417099,6.185282,0.942674,-325.556091,0.095369,0.000000
65.010002,27.422249,-325.689514,-0.000923,0.003732,0.094805,121.980255,6.213971,0.948051,-325.689514,0.096115,0.000000
65.460007,28.615334,-325.689514,-0.000892,0.003763,0.095568,127.287361,6.484327,0.955683,-325.689514,0.096869,0.000000
65.910004,30.111153,-325.645050,-0.000880,0.003794,0.096375,133.941101,6.823285,0.963748,-325.645050,0.097615,0.000000
66.360001,31.889229,-325.689514,-0.000858,0.003828,0.097233,141.850372,7.226202,0.972333,-325.689514,0.098369,0.000000
66.810005,33.256210,-325.689514,-0.000858,0.003862,0.098101,147.931015,7.535965,0.981005,-325.689514,0.099115,0.000000
67.260002,34.121231,-325.645050,-0.000819,0.003885,0.098690,151.778824,7.731981,0.986903,-325.645050,0.099870,0.000000
67.710007,35.725410,-325.778473,-0.000802,0.003920,0.099566,158.914566,8.095493,0.995662,-325.778473,0.100616,0.000000
68.160004,37.429390,-325.822968,-0.000776,0.003949,0.100295,166.494247,8.481621,1.002946,-325.822968,0.101370,0.000000
68.610001,38.670502,-325.822968,-0.000759,0.003978,0.101040,172.014984,8.762860,1.010404,-325.822968,0.102116,0.000000
69.060005,40.390495,-325.867462,-0.000755,0.004004,0.101708,179.665894,9.152617,1.017082,-325.867462,0.102870,0.000000
69.510002,41.662888,-325.822968,-0.000737,0.004036,0.102523,185.325775,9.440946,1.025234,-325.822968,0.103616,0.000000
69.960007,42.425133,-325.822968,-0.000711,0.004046,0.102775,188.716415,9.613672,1.027749,-325.822968,0.104371,0.000000
70.410004,45.855431,-325.956421,-0.000703,0.004092,0.103946,203.975143,10.390989,1.039457,-325.956421,0.105116,0.000000
70.860001,48.230049,-325.867462,-0.000681,0.004128,0.104839,214.537979,10.929085,1.048389,-325.867462,0.105871,0.000000
71.310005,49.758270,-325.911926,-0.000660,0.004150,0.105420,221.335846,11.275386,1.054199,-325.911926,0.106617,0.000000
71.760002,50.888420,-325.956421,-0.000655,0.004172,0.105975,226.362991,11.531481,1.059750,-325.956421,0.107371,0.000000
72.210007,53.925858,-325.911926,-0.000638,0.004210,0.106938,239.874191,12.219774,1.069376,-325.911926,0.108117,0.000000
72.660004,55.944489,-326.000885,-0.000617,0.004238,0.107649,248.853516,12.677202,1.076487,-326.000885,0.108872,0.000000
73.110001,57.823479,-326.045380,-0.000604,0.004269,0.108421,257.211670,13.102987,1.084205,-326.045380,0.109617,0.000000
73.560005,59.912117,-326.000885,-0.000582,0.004293,0.109054,266.502411,13.576280,1.090536,-326.000885,0.110372,0.000000
74.010002,62.605118,-326.045380,-0.000586,0.004327,0.109912,278.481476,14.186522,1.099122,-326.045380,0.111118,0.000000
74.460007,64.448738,-326.089844,-0.000565,0.004359,0.110727,286.682312,14.604293,1.107274,-326.089844,0.111872,0.000000
74.910004,65.501427,-326.045380,-0.000565,0.004363,0.110814,291.364899,14.842835,1.108141,-326.045380,0.019444,0.000000
75.360001,64.750359,-326.089844,-0.000552,0.004366,0.110892,288.023987,14.672641,1.108922,-326.089844,294.500488,0.000000
75.810005,65.533089,-326.089844,-0.000543,0.004375,0.111135,291.505737,14.850011,1.111350,-326.089844,294.500488,0.000000
76.260002,65.005806,-326.134338,-0.000552,0.004375,0.111135,289.160278,14.730526,1.111350,-326.134338,294.500488,0.000000
76.710007,64.606621,-326.178802,-0.000543,0.004375,0.111135,287.384613,14.640070,1.111350,-326.178802,294.500488,0.000000
77.160004,66.750374,-326.178802,-0.000513,0.004298,0.109166,296.920502,15.125851,1.091663,-326.178802,294.500488,0.000000
77.610001,66.435341,-326.178802,-0.000543,0.004296,0.109123,295.519165,15.054463,1.091230,-326.178802,294.500488,0.000000
78.060005,66.132607,-326.223297,-0.000530,0.004296,0.109123,294.172516,14.985863,1.091230,-326.223297,294.500488,0.000000
78.510002,65.855934,-326.178802,-0.000526,0.004297,0.109140,292.941833,14.923168,1.091403,-326.178802,294.500488,0.000000
78.960007,65.667137,-326.267761,-0.000526,0.004299,0.109184,292.102020,14.880386,1.091837,-326.267761,294.500488,0.000000
79.410004,65.504784,-326.312256,-0.000522,0.004360,0.110736,291.379822,14.843596,1.107360,-326.312256,294.500488,0.000000
79.860001,65.323814,-326.312256,-0.000522,0.004371,0.111031,290.574829,14.802588,1.110309,-326.312256,294.500488,0.000000
80.310005,65.195335,-326.312256,-0.000517,0.004371,0.111031,290.003326,14.773474,1.110309,-326.312256,294.500488,0.000000
80.760002,65.189003,-326.312256,-0.000517,0.004392,0.111569,289.975159,14.772038,1.115686,-326.312256,294.500488,0.000000
81.210007,65.173744,-326.356750,-0.000526,0.004393,0.111586,289.907288,14.768581,1.115859,-326.356750,294.500488,0.000000
81.660004,65.348381,-326.401215,-0.000526,0.004399,0.111733,290.684113,14.808154,1.117333,-326.401215,294.500488,0.000000
82.110001,65.336098,-326.401215,-0.000517,0.004399,0.111733,290.629486,14.805371,1.117333,-326.401215,294.500488,0.000000
82.560005,65.275780,-326.401215,-0.000522,0.004399,0.111733,290.361176,14.791703,1.117333,-326.401215,294.500488,0.000000
83.010002,65.212837,-326.356750,-0.000522,0.004399,0.111733,290.081177,14.777440,1.117333,-326.356750,294.500488,0.000000
83.460007,65.275398,-326.401215,-0.000522,0.004402,0.111811,290.359467,14.791616,1.118114,-326.401215,294.500488,0.000000
83.910004,65.260872,-326.445709,-0.000513,0.004402,0.111820,290.294861,14.788324,1.118201,-326.445709,294.500488,0.000000
84.360001,65.232948,-326.490173,-0.000513,0.004403,0.111829,290.170654,14.781998,1.118287,-326.490173,294.500488,0.000000
84.810005,65.204277,-326.490173,-0.000513,0.004403,0.111846,290.043121,14.775500,1.118461,-326.490173,294.500488,0.000000
85.260002,65.152885,-326.490173,-0.000517,0.004403,0.111846,289.814514,14.763855,1.118461,-326.490173,294.500488,0.000000
85.710007,65.262733,-326.490173,-0.000504,0.004406,0.111907,290.303131,14.788747,1.119068,-326.490173,294.500488,0.000000
86.160004,65.231834,-326.534668,-0.000513,0.004406,0.111907,290.165680,14.781745,1.119068,-326.534668,294.500488,0.000000
86.610001,65.193474,-326.534668,-0.000513,0.004406,0.111915,289.995056,14.773052,1.119155,-326.534668,294.500488,0.000000
87.060005,65.208366,-326.534668,-0.000513,0.004407,0.111950,290.061310,14.776427,1.119501,-326.534668,294.500488,0.000000
87.510002,65.213219,-326.534668,-0.000517,0.004407,0.111950,290.082886,14.777527,1.119501,-326.534668,294.500488,0.000000
87.960007,65.171501,-326.579132,-0.000513,0.004408,0.111959,289.897308,14.768073,1.119588,-326.579132,294.500488,0.000000
88.410004,65.204277,-326.579132,-0.000513,0.004409,0.111985,290.043121,14.775500,1.119848,-326.579132,294.500488,0.000000
88.860001,65.194588,-326.668091,-0.000509,0.004409,0.111985,290.000000,14.773304,1.119848,-326.668091,294.500488,0.000000
89.310005,65.195717,-326.668091,-0.000504,0.004410,0.112002,290.005035,14.773561,1.120022,-326.668091,294.500488,0.000000
89.760002,65.172249,-326.668091,-0.000504,0.004410,0.112002,289.900635,14.768242,1.120022,-326.668091,294.500488,0.000000
90.210007,65.168907,-326.712585,-0.000513,0.004412,0.112054,289.885773,14.767486,1.120542,-326.712585,294.500488,0.000000
90.660004,65.222527,-326.712585,-0.000513,0.004412,0.112054,290.124298,14.779635,1.120542,-326.712585,294.500488,0.000000
91.110001,65.215828,-326.757080,-0.000517,0.004412,0.112054,290.094482,14.778117,1.120542,-326.757080,294.500488,0.000000
91.560005,65.200554,-326.712585,-0.000509,0.004412,0.112063,290.026550,14.774657,1.120629,-326.712585,294.500488,0.000000
92.010002,65.168526,-326.757080,-0.000513,0.004412,0.112063,289.884094,14.767399,1.120629,-326.757080,294.500488,0.000000
92.460007,65.157738,-326.801544,-0.000500,0.004413,0.112080,289.836090,14.764955,1.120803,-326.801544,294.500488,0.000000
92.910004,65.153267,-326.757080,-0.000517,0.004413,0.112080,289.816193,14.763942,1.120803,-326.757080,294.500488,0.000000
93.360008,65.132408,-326.801544,-0.000509,0.004413,0.112080,289.723419,14.759214,1.120803,-326.801544,294.500488,0.000000
93.810005,65.109688,-326.801544,-0.000513,0.004413,0.112080,289.622345,14.754066,1.120803,-326.801544,294.500488,0.000000
94.260002,65.082878,-326.846039,-0.000496,0.004413,0.112080,289.503113,14.747991,1.120803,-326.846039,294.500488,0.000000
94.710007,65.061653,-326.890503,-0.000492,0.004413,0.112080,289.408691,14.743181,1.120803,-326.890503,294.500488,0.000000
95.160004,65.029640,-326.934998,-0.000504,0.004413,0.112080,289.266296,14.735928,1.120803,-326.934998,294.500488,0.000000
95.610008,64.997978,-326.890503,-0.000504,0.004413,0.112098,289.125458,14.728752,1.120976,-326.890503,294.500488,0.000000
96.060005,65.545738,-326.890503,-0.000500,0.004419,0.112254,291.562012,14.852877,1.122537,-326.890503,294.500488,0.000000
96.510002,65.542763,-326.934998,-0.000513,0.004419,0.112254,291.548767,14.852202,1.122537,-326.934998,294.500488,0.000000
96.960007,65.542763,-326.934998,-0.000504,0.004419,0.112254,291.548767,14.852202,1.122537,-326.934998,294.500488,0.000000
97.410004,65.523033,-326.934998,-0.000487,0.004419,0.112254,291.460999,14.847732,1.122537,-326.934998,294.500488,0.000000
97.860008,65.509254,-326.934998,-0.000500,0.004419,0.112254,291.399719,14.844608,1.122537,-326.934998,294.500488,0.000000
98.310005,65.508507,-327.023956,-0.000517,0.004419,0.112254,291.396393,14.844440,1.122537,-327.023956,294.500488,0.000000
98.760002,65.473869,-327.023956,-0.000504,0.004419,0.112254,291.242310,14.836591,1.122537,-327.023956,294.500488,0.000000
99.210007,65.437004,-327.023956,-0.000500,0.004419,0.112254,291.078339,14.828237,1.122537,-327.023956,294.500488,0.000000
99.660004,65.409447,-327.023956,-0.000509,0.004419,0.112254,290.955750,14.821993,1.122537,-327.023956,294.500488,0.000000
100.110008,65.372963,-327.068420,-0.000500,0.004419,0.112254,290.793457,14.813725,1.122537,-327.068420,294.500488,0.000000
100.560005,65.365135,-327.068420,-0.000492,0.004419,0.112254,290.758636,14.811952,1.122537,-327.068420,294.500488,0.000000
101.010002,65.334602,-327.068420,-0.000500,0.004419,0.112254,290.622833,14.805033,1.122537,-327.068420,294.500488,0.000000
101.460007,65.310036,-327.112915,-0.000496,0.004419,0.112254,290.513550,14.799465,1.122537,-327.112915,294.500488,0.000000
101.910004,65.302208,-327.112915,-0.000492,0.004419,0.112254,290.478729,14.797691,1.122537,-327.112915,294.500488,0.000000
102.360008,65.279121,-327.201874,-0.000496,0.004420,0.112262,290.376038,14.792460,1.122623,-327.201874,294.500488,0.000000
102.810005,65.251945,-327.201874,-0.000492,0.004420,0.112262,290.255157,14.786302,1.122623,-327.201874,294.500488,0.000000
103.260002,65.240395,-327.201874,-0.000500,0.004420,0.112262,290.203766,14.783685,1.122623,-327.201874,294.500488,0.000000
103.710007,65.210976,-327.246368,-0.000496,0.004420,0.112271,290.072906,14.777019,1.122710,-327.246368,294.500488,0.000000
104.160004,65.190498,-327.246368,-0.000496,0.004420,0.112271,289.981812,14.772378,1.122710,-327.246368,294.500488,0.000000
104.610008,65.156242,-327.246368,-0.000509,0.004420,0.112271,289.829437,14.764615,1.122710,-327.246368,294.500488,0.000000
105.060005,65.184547,-327.335327,-0.000492,0.004421,0.112288,289.955353,14.771029,1.122884,-327.335327,294.500488,0.000000
105.510002,65.175972,-327.290833,-0.000509,0.004421,0.112288,289.917206,14.769087,1.122884,-327.290833,294.500488,0.000000
105.960007,65.150658,-327.290833,-0.000500,0.004421,0.112288,289.804596,14.763350,1.122884,-327.290833,294.500488,0.000000
106.410004,65.131660,-327.246368,-0.000513,0.004421,0.112288,289.720093,14.759045,1.122884,-327.246368,294.500488,0.000000
106.860008,65.117516,-327.335327,-0.000483,0.004421,0.112306,289.657166,14.755840,1.123057,-327.335327,294.500488,0.000000
107.310005,65.141350,-327.379791,-0.000492,0.004422,0.112314,289.763184,14.761241,1.123144,-327.379791,294.500488,0.000000
107.760002,65.131294,-327.379791,-0.000492,0.004422,0.112314,289.718475,14.758963,1.123144,-327.379791,294.500488,0.000000
108.210007,65.117516,-327.379791,-0.000504,0.004422,0.112314,289.657166,14.755840,1.123144,-327.379791,294.500488,0.000000
108.660004,65.102242,-327.468750,-0.000496,0.004422,0.112314,289.589233,14.752378,1.123144,-327.468750,294.500488,0.000000
109.110008,65.106712,-327.468750,-0.000504,0.004422,0.112314,289.609131,14.753392,1.123144,-327.468750,294.500488,0.000000
109.560005,65.085487,-327.468750,-0.000500,0.004422,0.112314,289.514709,14.748582,1.123144,-327.468750,294.500488,0.000000
110.010002,65.066124,-327.468750,-0.000492,0.004422,0.112314,289.428589,14.744194,1.123144,-327.468750,294.500488,0.000000
110.460007,65.052345,-327.468750,-0.000500,0.004422,0.112314,289.367279,14.741073,1.123144,-327.468750,294.500488,0.000000
110.910004,65.278008,-327.557709,-0.000500,0.004426,0.112418,290.371094,14.792209,1.124184,-327.557709,294.500488,0.000000
111.360008,65.316734,-327.557709,-0.000496,0.004426,0.112418,290.543335,14.800983,1.124184,-327.557709,294.500488,0.000000
111.810005,65.329765,-327.602203,-0.000496,0.004426,0.112418,290.601318,14.803937,1.124184,-327.602203,294.500488,0.000000
112.260002,65.352486,-327.557709,-0.000496,0.004426,0.112418,290.702362,14.809085,1.124184,-327.557709,294.500488,0.000000
112.710007,65.340569,-327.602203,-0.000509,0.004426,0.112418,290.649353,14.806384,1.124184,-327.602203,294.500488,0.000000
113.160004,65.343910,-327.602203,-0.000487,0.004426,0.112418,290.664215,14.807141,1.124184,-327.602203,294.500488,0.000000
113.610008,65.338326,-327.602203,-0.000500,0.004426,0.112418,290.639374,14.805876,1.124184,-327.602203,294.500488,0.000000
114.060005,65.326408,-327.646698,-0.000479,0.004426,0.112418,290.586365,14.803176,1.124184,-327.646698,294.500488,0.000000
114.510002,65.322685,-327.646698,-0.000496,0.004426,0.112418,290.569824,14.802332,1.124184,-327.646698,294.500488,0.000000
114.960007,65.322685,-327.691162,-0.000496,0.004426,0.112418,290.569824,14.802332,1.124184,-327.691162,294.500488,0.000000
115.410004,65.317101,-327.691162,-0.000496,0.004426,0.112418,290.544983,14.801066,1.124184,-327.691162,294.500488,0.000000
115.860008,65.290672,-327.780121,-0.000504,0.004426,0.112418,290.427429,14.795078,1.124184,-327.780121,294.500488,0.000000
116.310005,65.297005,-327.735657,-0.000496,0.004426,0.112418,290.455597,14.796514,1.124184,-327.735657,294.500488,0.000000
116.760002,65.268318,-327.780121,-0.000487,0.004426,0.112418,290.327972,14.790012,1.124184,-327.780121,294.500488,0.000000
117.210007,65.267952,-327.780121,-0.000492,0.004426,0.112418,290.326355,14.789929,1.124184,-327.780121,294.500488,0.000000
117.660004,65.259758,-327.780121,-0.000500,0.004426,0.112418,290.289886,14.788073,1.124184,-327.780121,294.500488,0.000000
118.110008,65.247841,-327.780121,-0.000492,0.004426,0.112418,290.236877,14.785373,1.124184,-327.780121,294.500488,0.000000
118.560005,65.229591,-327.869080,-0.000504,0.004426,0.112418,290.155701,14.781238,1.124184,-327.869080,294.500488,0.000000
119.010002,65.221413,-327.869080,-0.000500,0.004426,0.112418,290.119324,14.779383,1.124184,-327.869080,294.500488,0.000000
119.460007,65.222527,-327.913574,-0.000504,0.004426,0.112418,290.124298,14.779635,1.124184,-327.913574,294.500488,0.000000
119.910004,65.184914,-327.913574,-0.000483,0.004426,0.112418,289.956970,14.771112,1.124184,-327.913574,294.500488,0.000000
120.360008,65.179695,-327.913574,-0.000492,0.004426,0.112418,289.933777,14.769930,1.124184,-327.913574,294.500488,0.000000
120.810005,65.156990,-327.958038,-0.000513,0.004426,0.112418,289.832764,14.764785,1.124184,-327.958038,294.500488,0.000000
121.260002,65.139107,-327.958038,-0.000496,0.004426,0.112418,289.753204,14.760733,1.124184,-327.958038,294.500488,0.000000
121.710007,65.123466,-327.958038,-0.000492,0.004426,0.112427,289.683655,14.757189,1.124271,-327.958038,294.500488,0.000000
122.160004,65.118629,-328.002533,-0.000504,0.004426,0.112427,289.662140,14.756093,1.124271,-328.002533,294.500488,0.000000
122.610008,65.090324,-328.002533,-0.000496,0.004426,0.112427,289.536224,14.749679,1.124271,-328.002533,294.500488,0.000000
123.060005,65.084740,-328.002533,-0.000483,0.004426,0.112427,289.511383,14.748413,1.124271,-328.002533,294.500488,0.000000
123.510002,65.075432,-328.047028,-0.000496,0.004426,0.112427,289.469971,14.746304,1.124271,-328.047028,294.500488,0.000000
123.960007,65.074684,-328.047028,-0.000500,0.004426,0.112427,289.466644,14.746135,1.124271,-328.047028,294.500488,0.000000
124.410004,65.062035,-328.091492,-0.000487,0.004427,0.112453,289.410370,14.743267,1.124532,-328.091492,294.500488,0.000000
124.860008,65.073952,-328.091492,-0.000496,0.004427,0.112453,289.463379,14.745968,1.124532,-328.091492,294.500488,0.000000
125.310005,65.064644,-328.091492,-0.000487,0.004427,0.112453,289.421997,14.743859,1.124532,-328.091492,294.500488,0.000000
125.760010,65.060921,-328.135986,-0.000487,0.004427,0.112453,289.405426,14.743015,1.124532,-328.135986,294.500488,0.000000
126.210007,65.063148,-328.135986,-0.000504,0.004427,0.112453,289.415344,14.743520,1.124532,-328.135986,294.500488,0.000000
126.660004,65.052345,-328.135986,-0.000483,0.004427,0.112453,289.367279,14.741073,1.124532,-328.135986,294.500488,0.000000
127.110008,65.040428,-328.224945,-0.000500,0.004427,0.112453,289.314270,14.738372,1.124532,-328.224945,294.500488,0.000000
127.560005,65.039314,-328.180450,-0.000504,0.004427,0.112453,289.309326,14.738119,1.124532,-328.180450,294.500488,0.000000
128.010010,65.034096,-328.269409,-0.000474,0.004427,0.112453,289.286102,14.736937,1.124532,-328.269409,294.500488,0.000000
128.460007,65.010643,-328.180450,-0.000496,0.004427,0.112453,289.181793,14.731623,1.124532,-328.180450,294.500488,0.000000
128.910004,65.307426,-328.269409,-0.000504,0.004432,0.112575,290.501953,14.798875,1.125746,-328.269409,294.500488,0.000000
129.360001,65.343544,-328.269409,-0.000500,0.004432,0.112575,290.662598,14.807058,1.125746,-328.269409,294.500488,0.000000
129.810013,65.360680,-328.269409,-0.000496,0.004432,0.112575,290.738831,14.810942,1.125746,-328.269409,294.500488,0.000000
130.260010,65.374077,-328.313904,-0.000487,0.004432,0.112566,290.798431,14.813977,1.125659,-328.313904,294.500488,0.000000
130.710007,65.366631,-328.313904,-0.000496,0.004432,0.112566,290.765289,14.812291,1.125659,-328.313904,294.500488,0.000000
131.160004,65.370354,-328.358368,-0.000483,0.004432,0.112566,290.781860,14.813134,1.125659,-328.358368,294.500488,0.000000
131.610001,65.367744,-328.313904,-0.000500,0.004432,0.112566,290.770264,14.812542,1.125659,-328.313904,294.500488,0.000000
132.060013,65.363274,-328.313904,-0.000492,0.004432,0.112566,290.750366,14.811529,1.125659,-328.313904,294.500488,0.000000
132.510010,65.364021,-328.447357,-0.000500,0.004432,0.112566,290.753693,14.811699,1.125659,-328.447357,294.500488,0.000000
132.960007,65.360680,-328.447357,-0.000487,0.004432,0.112566,290.738831,14.810942,1.125659,-328.447357,294.500488,0.000000
133.410004,65.361046,-328.402863,-0.000492,0.004432,0.112566,290.740448,14.811025,1.125659,-328.402863,294.500488,0.000000
133.860001,65.363274,-328.447357,-0.000492,0.004432,0.112566,290.750366,14.811529,1.125659,-328.447357,294.500488,0.000000
134.310013,65.345772,-328.491821,-0.000496,0.004432,0.112566,290.672516,14.807564,1.125659,-328.491821,294.500488,0.000000
134.760010,65.342049,-328.447357,-0.000492,0.004432,0.112566,290.655945,14.806720,1.125659,-328.447357,294.500488,0.000000
135.210007,65.345039,-328.447357,-0.000509,0.004432,0.112566,290.669250,14.807397,1.125659,-328.447357,1681.640991,0.000000
135.660004,65.324547,-328.491821,-0.000492,0.004422,0.112314,290.578094,14.802753,1.123144,-328.491821,0.112115,0.000000
136.110001,65.242256,-328.536316,-0.000487,0.004402,0.111803,290.212036,14.784107,1.118027,-328.536316,0.111369,0.000000
136.560013,65.189003,-328.580780,-0.000492,0.004374,0.111109,289.975159,14.772038,1.111089,-328.580780,0.110615,0.000000
137.010010,65.159966,-328.580780,-0.000487,0.004350,0.110485,289.846008,14.765460,1.104845,-328.580780,0.109869,0.000000
137.460007,65.142097,-328.580780,-0.000474,0.004319,0.109704,289.766510,14.761411,1.097040,-328.580780,0.109114,0.000000
137.910004,65.104851,-328.580780,-0.000470,0.004290,0.108958,289.600830,14.752970,1.089582,-328.580780,0.108369,0.000000
138.360001,65.081017,-328.625275,-0.000479,0.004255,0.108065,289.494812,14.747569,1.080650,-328.625275,0.107614,0.000000
138.810013,65.054955,-328.669739,-0.000479,0.004230,0.107449,289.378876,14.741663,1.074493,-328.669739,0.106868,0.000000
139.260010,64.912331,-328.625275,-0.000470,0.004204,0.106790,288.744476,14.709344,1.067902,-328.625275,0.106114,0.000000
139.710007,64.187325,-328.714233,-0.000470,0.004175,0.106044,285.519470,14.545055,1.060444,-328.714233,0.105368,0.000000
140.160004,63.247459,-328.714233,-0.000461,0.004150,0.105411,281.338745,14.332079,1.054113,-328.714233,0.104613,0.000000
140.610001,61.670090,-328.714233,-0.000461,0.004123,0.104717,274.322266,13.974642,1.047175,-328.714233,0.103868,0.000000
141.060013,60.255821,-328.714233,-0.000466,0.004099,0.104119,268.031281,13.654164,1.041191,-328.714233,0.103113,0.000000
141.510010,57.738213,-328.758698,-0.000474,0.004066,0.103287,256.832397,13.083667,1.032866,-328.758698,0.102367,0.000000
141.960007,55.369919,-328.714233,-0.000474,0.004040,0.102619,246.297699,12.547003,1.026188,-328.714233,0.101613,0.000000
142.410004,52.497437,-328.758698,-0.000470,0.004009,0.101838,233.520264,11.896090,1.018383,-328.758698,0.100867,0.000000
142.860001,49.508781,-328.803192,-0.000470,0.003980,0.101092,220.226059,11.218851,1.010925,-328.803192,0.100121,0.000000
143.310013,46.545441,-328.892151,-0.000483,0.003953,0.100416,207.044464,10.547348,1.004161,-328.892151,0.099367,0.000000
143.760010,44.067673,-328.847656,-0.000483,0.003933,0.099904,196.022797,9.985877,0.999044,-328.847656,0.098621,0.000000
144.210007,39.920929,-328.892151,-0.000492,0.003894,0.098916,177.577164,9.046211,0.989157,-328.892151,0.097866,0.000000
144.660004,36.999672,-328.892151,-0.000492,0.003866,0.098196,164.582764,8.384245,0.981960,-328.892151,0.097121,0.000000
145.110001,33.548149,-328.892151,-0.000504,0.003835,0.097415,149.229614,7.602119,0.974155,-328.892151,0.096366,0.000000
145.560013,30.148392,-328.892151,-0.000487,0.003806,0.096661,134.106750,6.831723,0.966610,-328.892151,0.095620,0.000000
146.010010,27.698921,-328.892151,-0.000509,0.003785,0.096132,123.210953,6.276665,0.961320,-328.892151,0.094866,0.000000
146.460007,23.924187,-328.936646,-0.000509,0.003749,0.095213,106.420097,5.421299,0.952127,-328.936646,0.094120,0.000000
146.910004,20.546768,-328.936646,-0.000517,0.003720,0.094476,91.396591,4.655964,0.944756,-328.936646,0.093366,0.000000
147.360001,17.322762,-328.981110,-0.000517,0.003689,0.093695,77.055489,3.925394,0.936951,-328.981110,0.092620,0.000000
147.810013,14.110306,-329.025604,-0.000526,0.003662,0.093027,62.765774,3.197441,0.930273,-329.025604,0.091865,0.000000
148.260010,11.337624,-328.981110,-0.000535,0.003632,0.092247,50.432270,2.569142,0.922468,-328.981110,0.091119,0.000000
148.710007,7.014748,-329.025604,-0.000530,0.003598,0.091388,31.203156,1.589565,0.913882,-329.025604,0.090365,0.000000
149.160004,3.713669,-329.070068,-0.000548,0.003566,0.090573,16.519224,0.841529,0.905730,-329.070068,0.089619,0.000000
149.610001,1.308884,-329.025604,-0.000543,0.003546,0.090079,5.822206,0.296597,0.900787,-329.025604,0.088865,0.000000
150.060013,-0.940987,-329.070068,-0.000543,0.003520,0.089411,-4.185718,-0.213231,0.894110,-329.070068,0.088119,0.000000
150.510010,-0.102402,-329.159027,-0.000608,0.003479,0.088362,-0.455506,-0.023205,0.883616,-329.159027,0.087364,0.000000
150.960007,-0.065910,-329.114563,-0.000642,0.003448,0.087590,-0.293184,-0.014935,0.875898,-329.114563,0.086618,0.000000
151.410004,-0.072990,-329.159027,-0.000677,0.003421,0.086905,-0.324678,-0.016540,0.869047,-329.159027,0.085864,0.000000
151.860001,-0.065170,-329.203522,-0.000703,0.003398,0.086306,-0.289892,-0.014768,0.863063,-329.203522,0.085118,0.000000
152.310013,-0.090118,-329.159027,-0.000729,0.003361,0.085361,-0.400867,-0.020421,0.853610,-329.159027,0.084364,0.000000
152.760010,-0.077087,-329.159027,-0.000776,0.003336,0.084745,-0.342902,-0.017468,0.847453,-329.159027,0.083618,0.000000
153.210007,-0.055862,-329.159027,-0.000815,0.003301,0.083843,-0.248488,-0.012659,0.838434,-329.159027,0.082863,0.000000
153.660004,-0.063675,-329.247986,-0.000845,0.003276,0.083219,-0.283240,-0.014429,0.832190,-329.247986,0.082118,0.000000
154.110001,-0.074852,-329.203522,-0.000875,0.003246,0.082438,-0.332958,-0.016962,0.824385,-329.203522,0.081363,0.000000
154.560013,-0.093094,-329.247986,-0.000914,0.003216,0.081675,-0.414102,-0.021095,0.816753,-329.247986,0.080617,0.000000
155.010010,-0.057724,-329.247986,-0.000940,0.003189,0.080990,-0.256769,-0.013080,0.809902,-329.247986,0.079863,0.000000
155.460007,-0.080811,-329.247986,-0.000983,0.003155,0.080140,-0.359463,-0.018312,0.801403,-329.247986,0.079117,0.000000
155.910004,-0.070381,-329.336975,-0.001022,0.003125,0.079386,-0.313071,-0.015949,0.793858,-329.336975,0.078363,0.000000
156.360001,-0.068146,-329.381439,-0.001065,0.003092,0.078536,-0.303127,-0.015442,0.785360,-329.381439,0.077617,0.000000
156.810013,-0.054367,-329.336975,-0.001104,0.003061,0.077747,-0.241837,-0.012320,0.777468,-329.336975,0.076862,0.000000
157.260010,-0.060326,-329.381439,-0.001108,0.003044,0.077322,-0.268342,-0.013670,0.773218,-329.381439,0.076116,0.000000
157.710007,-0.054367,-329.425934,-0.001160,0.003016,0.076611,-0.241837,-0.012320,0.766107,-329.425934,0.075362,0.000000
158.160004,-0.054367,-329.425934,-0.001203,0.002976,0.075579,-0.241837,-0.012320,0.755787,-329.425934,0.074616,0.000000
158.610001,-0.047668,-329.425934,-0.001220,0.002954,0.075032,-0.212040,-0.010802,0.750323,-329.425934,0.073862,0.000000
159.060013,-0.067032,-329.425934,-0.001250,0.002921,0.074200,-0.298173,-0.015190,0.741998,-329.425934,0.073116,0.000000
159.510010,-0.064796,-329.514893,-0.001293,0.002893,0.073480,-0.288229,-0.014683,0.734800,-329.514893,0.072361,0.000000
159.960007,-0.067406,-329.470398,-0.001311,0.002852,0.072439,-0.299836,-0.015274,0.724393,-329.470398,0.071615,0.000000
160.410004,-0.068146,-329.514893,-0.001341,0.002829,0.071850,-0.303127,-0.015442,0.718496,-329.514893,0.070861,0.000000
160.860001,-0.060326,-329.514893,-0.001380,0.002799,0.071095,-0.268342,-0.013670,0.710952,-329.514893,0.070115,0.000000
161.310013,-0.056976,-329.514893,-0.001414,0.002770,0.070349,-0.253443,-0.012911,0.703493,-329.514893,0.069361,0.000000
161.760010,-0.042824,-329.559357,-0.001440,0.002744,0.069708,-0.190490,-0.009704,0.697076,-329.559357,0.068615,0.000000
162.210007,-0.064423,-329.559357,-0.001479,0.002713,0.068910,-0.286566,-0.014598,0.689097,-329.559357,0.067869,0.000000
162.660004,-0.006332,-329.603851,-0.001505,0.002684,0.068164,-0.028168,-0.001435,0.681639,-329.603851,0.067115,0.000000
163.110001,-0.002609,-329.648315,-0.001526,0.002651,0.067340,-0.011607,-0.000591,0.673401,-329.648315,0.066369,0.000000
163.560013,-0.026070,-329.692810,-0.001565,0.002623,0.066612,-0.115964,-0.005907,0.666116,-329.692810,0.065614,0.000000
164.010010,-0.046547,-329.603851,-0.001600,0.002591,0.065822,-0.207051,-0.010548,0.658224,-329.603851,0.064868,0.000000
164.460007,-0.002983,-329.648315,-0.001625,0.002568,0.065233,-0.013269,-0.000676,0.652327,-329.648315,0.064114,0.000000
164.910004,-0.005959,-329.737305,-0.001660,0.002536,0.064409,-0.026505,-0.001350,0.644088,-329.737305,0.063368,0.000000
165.360001,0.006699,-329.692810,-0.001699,0.002502,0.063542,0.029797,0.001518,0.635416,-329.692810,0.062614,0.000000
165.810013,-0.053253,-329.737305,-0.001729,0.002477,0.062926,-0.236882,-0.012067,0.629259,-329.737305,0.061868,0.000000
166.260010,-0.048409,-329.737305,-0.001742,0.002450,0.062223,-0.215332,-0.010970,0.622234,-329.737305,0.061113,0.000000
166.710007,-0.021599,-329.781769,-0.001785,0.002414,0.061304,-0.096076,-0.004894,0.613042,-329.781769,0.060368,0.000000
167.160004,-0.042824,-329.781769,-0.001807,0.002388,0.060645,-0.190490,-0.009704,0.606451,-329.781769,0.059613,0.000000
167.610001,-0.035004,-329.781769,-0.001845,0.002357,0.059856,-0.155704,-0.007932,0.598559,-329.781769,0.058867,0.000000
168.060013,-0.033516,-329.781769,-0.001880,0.002325,0.059058,-0.149086,-0.007595,0.590581,-329.781769,0.058113,0.000000
168.510010,-0.056602,-329.826263,-0.001914,0.002299,0.058390,-0.251780,-0.012826,0.583903,-329.826263,0.057367,0.000000
168.960007,-0.049904,-329.826263,-0.001944,0.002269,0.057636,-0.221983,-0.011308,0.576358,-329.826263,0.056612,0.000000
169.410004,-0.065170,-329.870728,-0.001970,0.002239,0.056873,-0.289892,-0.014768,0.568727,-329.870728,0.055867,0.000000
169.860001,-0.043198,-329.915222,-0.002013,0.002209,0.056101,-0.192153,-0.009789,0.561008,-329.915222,0.055112,0.000000
170.310013,-0.055489,-329.915222,-0.002044,0.002180,0.055364,-0.246826,-0.012574,0.553637,-329.915222,0.054366,0.000000
170.760010,-0.056976,-329.915222,-0.002065,0.002159,0.054843,-0.253443,-0.012911,0.548433,-329.915222,0.053612,0.000000
171.210007,-0.048409,-329.915222,-0.002095,0.002129,0.054080,-0.215332,-0.010970,0.540802,-329.915222,0.052866,0.000000
171.660004,-0.086769,-329.915222,-0.002130,0.002091,0.053118,-0.385968,-0.019662,0.531176,-329.915222,0.052112,0.000000
172.110001,-0.105759,-329.915222,-0.002164,0.002060,0.052320,-0.470438,-0.023965,0.523197,-329.915222,0.051366,0.000000
172.560013,-0.069267,-329.959686,-0.002182,0.002033,0.051635,-0.308116,-0.015696,0.516346,-329.959686,0.050611,0.000000
173.010010,-0.075966,-330.004181,-0.002212,0.002008,0.050993,-0.337913,-0.017214,0.509928,-330.004181,0.049865,0.000000
173.460007,-0.091232,-330.093140,-0.002251,0.001972,0.050100,-0.405822,-0.020674,0.500996,-330.093140,0.049111,0.000000
173.910004,-0.099052,-330.093140,-0.002285,0.001943,0.049362,-0.440607,-0.022446,0.493625,-330.093140,0.048365,0.000000
174.360016,-0.097565,-330.093140,-0.002289,0.001920,0.048773,-0.433989,-0.022108,0.487728,-330.093140,0.047611,0.000000
174.810013,-0.072990,-330.048645,-0.002345,0.001898,0.048209,-0.324678,-0.016540,0.482091,-330.048645,0.046865,0.000000
175.260010,-0.075966,-330.048645,-0.002371,0.001855,0.047116,-0.337913,-0.017214,0.471164,-330.048645,0.046110,0.000000
175.710007,-0.096817,-330.137604,-0.002397,0.001824,0.046336,-0.430664,-0.021939,0.463359,-330.137604,0.045365,0.000000
176.160004,-0.078949,-330.137604,-0.002427,0.001793,0.045538,-0.351183,-0.017890,0.455380,-330.137604,0.044610,0.000000
176.610016,-0.050270,-330.137604,-0.002458,0.001772,0.045009,-0.223612,-0.011391,0.450090,-330.137604,0.043864,0.000000
177.060013,-0.080811,-330.182098,-0.002488,0.001748,0.044393,-0.359463,-0.018312,0.443933,-330.182098,0.043110,0.000000
177.510010,-0.062935,-330.226593,-0.002548,0.001702,0.043231,-0.279948,-0.014261,0.432312,-330.226593,0.042364,0.000000
177.960007,-0.076340,-330.182098,-0.002574,0.001677,0.042598,-0.339576,-0.017299,0.425981,-330.182098,0.041609,0.000000
178.410004,-0.060699,-330.182098,-0.002591,0.001652,0.041965,-0.270005,-0.013755,0.419650,-330.182098,0.040864,0.000000
178.860016,-0.087509,-330.271057,-0.002626,0.001622,0.041211,-0.389260,-0.019830,0.412106,-330.271057,0.040109,0.000000
179.310013,-0.088631,-330.315552,-0.002647,0.001590,0.040378,-0.394249,-0.020084,0.403780,-330.315552,0.039363,0.000000
179.760010,-0.068520,-330.315552,-0.002682,0.001563,0.039693,-0.304790,-0.015527,0.396929,-330.315552,0.038609,0.000000
180.210007,-0.071129,-330.315552,-0.002712,0.001534,0.038964,-0.316397,-0.016118,0.389644,-330.315552,0.037863,0.000000
180.660004,-0.094589,-330.315552,-0.002742,0.001501,0.038123,-0.420754,-0.021434,0.381232,-330.315552,0.037109,0.000000
181.110016,-0.061813,-330.360016,-0.002781,0.001466,0.037247,-0.274960,-0.014007,0.372473,-330.360016,0.036363,0.000000
181.560013,-0.068893,-330.404510,-0.002798,0.001439,0.036562,-0.306453,-0.015611,0.365622,-330.404510,0.035608,0.000000
182.010010,-0.036499,-330.404510,-0.002837,0.001408,0.035764,-0.162356,-0.008271,0.357644,-330.404510,0.034862,0.000000
182.460007,-0.069633,-330.448975,-0.002876,0.001380,0.035062,-0.309745,-0.015779,0.350619,-330.448975,0.034117,0.000000
182.910004,-0.077087,-330.448975,-0.002893,0.001353,0.034359,-0.342902,-0.017468,0.343595,-330.448975,0.033362,0.000000
183.360016,-0.075966,-330.448975,-0.002932,0.001326,0.033674,-0.337913,-0.017214,0.336744,-330.448975,0.032616,0.000000
183.810013,-0.021973,-330.493469,-0.002949,0.001299,0.032998,-0.097739,-0.004979,0.329979,-330.493469,0.031862,0.000000
184.260010,-0.004097,-330.493469,-0.002992,0.001269,0.032235,-0.018224,-0.000928,0.322348,-330.493469,0.031116,0.000000
184.710007,-0.035378,-330.493469,-0.003018,0.001233,0.031324,-0.157367,-0.008017,0.313242,-330.493469,0.030362,0.000000
185.160004,-0.062561,-330.537933,-0.003044,0.001205,0.030596,-0.278285,-0.014177,0.305957,-330.537933,0.029616,0.000000
185.610016,-0.067032,-330.537933,-0.003083,0.001178,0.029919,-0.298173,-0.015190,0.299193,-330.537933,0.028861,0.000000
186.060013,0.009308,-330.493469,-0.003096,0.001150,0.029217,0.041403,0.002109,0.292168,-330.493469,0.028115,0.000000
186.400009,-0.029419,-330.582428,-0.003139,0.001135,0.028818,-0.130862,-0.006666,0.288179,-330.582428,0.028688,0.000000