File: Data/compression 34/AutoNoHeating-12-34-reverse-1-1_11152024_195315.csv
Time (sec),S:Load (lbs),S:HL1 (DIM),S:LVDT (in),S:Position (in),Ch:Position (mm),Ch:Load (N),Ch:Stress (MPa),Ch:Strain (mm/mm),Ch:HL1 (DIM),Set Point (),Cycles ()
0.210000,-0.062187,-351.088135,-0.012102,-0.007060,-0.179316,-0.276622,-0.014092,-1.793162,-351.088135,-0.179325,0.000000
0.610000,-0.102776,-351.132629,-0.012124,-0.006962,-0.176845,-0.457169,-0.023289,-1.768447,-351.132629,-0.175821,0.000000
1.010000,-0.133316,-351.177094,-0.011904,-0.006713,-0.170514,-0.593019,-0.030210,-1.705139,-351.177094,-0.169161,0.000000
1.410000,-0.069633,-351.088135,-0.011628,-0.006446,-0.163732,-0.309745,-0.015779,-1.637322,-351.088135,-0.162483,0.000000
1.810000,-0.055862,-351.177094,-0.011365,-0.006190,-0.157237,-0.248488,-0.012659,-1.572367,-351.177094,-0.155823,0.000000
2.210000,-0.077827,-351.177094,-0.011102,-0.005926,-0.150516,-0.346194,-0.017636,-1.505157,-351.177094,-0.149163,0.000000
2.610000,-0.083786,-351.132629,-0.010822,-0.005667,-0.143942,-0.372699,-0.018986,-1.439421,-351.132629,-0.142503,0.000000
3.010000,-0.096451,-351.221588,-0.010546,-0.005404,-0.137256,-0.429035,-0.021856,-1.372558,-351.221588,-0.135842,0.000000
3.410000,-0.032768,-351.266083,-0.010283,-0.005135,-0.130439,-0.145760,-0.007425,-1.304394,-351.266083,-0.129165,0.000000
3.810000,-0.026443,-351.177094,-0.009998,-0.004876,-0.123848,-0.117626,-0.005992,-1.238485,-351.177094,-0.122504,0.000000
4.210000,-0.049904,-351.221588,-0.009735,-0.004612,-0.117136,-0.221983,-0.011308,-1.171362,-351.221588,-0.115844,0.000000
4.610000,-0.067406,-351.266083,-0.009468,-0.004351,-0.110519,-0.299836,-0.015274,-1.105192,-351.266083,-0.109184,0.000000
5.010000,-0.084160,-351.266083,-0.009196,-0.004090,-0.103894,-0.374362,-0.019071,-1.038936,-351.266083,-0.102523,0.000000
5.410000,-0.050644,-351.310547,-0.008916,-0.003825,-0.097155,-0.225275,-0.011476,-0.971553,-351.310547,-0.095846,0.000000
5.810000,-0.059952,-351.355042,-0.008645,-0.003554,-0.090261,-0.266679,-0.013585,-0.902608,-351.355042,-0.089185,0.000000
6.210001,-0.045433,-351.310547,-0.008373,-0.003302,-0.083861,-0.202096,-0.010295,-0.838607,-351.310547,-0.082525,0.000000
6.610000,-0.080811,-351.310547,-0.008101,-0.003036,-0.077105,-0.359463,-0.018312,-0.771050,-351.310547,-0.075865,0.000000
7.010000,-0.133682,-351.355042,-0.007825,-0.002776,-0.070505,-0.594648,-0.030293,-0.705054,-351.355042,-0.069205,0.000000
7.410000,-0.110222,-351.355042,-0.007575,-0.002518,-0.063949,-0.490291,-0.024977,-0.639492,-351.355042,-0.062527,0.000000
7.810000,-0.060326,-351.355042,-0.007291,-0.002249,-0.057124,-0.268342,-0.013670,-0.571242,-351.355042,-0.055867,0.000000
8.210000,-0.059586,-351.355042,-0.007032,-0.001985,-0.050429,-0.265050,-0.013502,-0.504292,-351.355042,-0.049206,0.000000
8.610001,-0.060699,-351.399506,-0.006760,-0.001729,-0.043908,-0.270005,-0.013755,-0.439076,-351.399506,-0.042546,0.000000
9.010000,-0.064796,-351.488464,-0.006502,-0.001465,-0.037204,-0.288229,-0.014683,-0.372040,-351.488464,-0.035886,0.000000
9.410001,-0.089371,-351.444000,-0.006243,-0.001204,-0.030587,-0.397541,-0.020252,-0.305870,-351.444000,-0.029208,0.000000
9.810000,-0.022720,-351.444000,-0.005959,-0.000938,-0.023814,-0.101065,-0.005149,-0.238140,-351.444000,-0.022548,0.000000
10.210000,-0.011177,-351.444000,-0.005687,-0.000678,-0.017223,-0.049718,-0.002533,-0.172231,-351.444000,-0.015888,0.000000
10.610001,-0.040588,-351.488464,-0.005407,-0.000413,-0.010493,-0.180546,-0.009197,-0.104934,-351.488464,-0.009227,0.000000
11.010000,-0.049904,-351.488464,-0.005144,-0.000153,-0.003894,-0.221983,-0.011308,-0.038938,-351.488464,-0.002550,0.000000
11.410001,0.019363,-351.488464,-0.004863,0.000107,0.002723,0.086133,0.004388,0.027231,-351.488464,0.004111,0.000000
11.810000,0.095695,-351.488464,-0.004773,-0.000000,-0.000000,0.425675,0.021685,-0.000000,-351.488464,0.000243,0.000000
12.210001,0.123627,-351.577423,-0.004760,-0.000000,-0.000000,0.549919,0.028014,-0.000000,-351.577423,0.000460,0.000000
12.610001,0.097183,-351.577423,-0.004769,0.000000,0.000009,0.432293,0.022022,0.000087,-351.577423,0.001127,0.000000
13.010000,0.154533,-351.577423,-0.004756,0.000019,0.000477,0.687399,0.035018,0.004770,-351.577423,0.001795,0.000000
13.410001,0.198471,-351.577423,-0.004734,0.000059,0.001509,0.882843,0.044974,0.015090,-351.577423,0.002463,0.000000
13.810000,0.190651,-351.621918,-0.004691,0.000081,0.002047,0.848058,0.043202,0.020467,-351.621918,0.003131,0.000000
14.210001,0.224541,-351.577423,-0.004665,0.000105,0.002671,0.998807,0.050882,0.026711,-351.577423,0.003798,0.000000
14.610001,0.374229,-351.621918,-0.004635,0.000135,0.003417,1.664656,0.084802,0.034169,-351.621918,0.004466,0.000000
15.010001,0.409233,-351.577423,-0.004613,0.000164,0.004171,1.820360,0.092734,0.041714,-351.577423,0.005134,0.000000
15.410001,0.431206,-351.710876,-0.004579,0.000182,0.004614,1.918099,0.097713,0.046136,-351.710876,0.005793,0.000000
15.810000,0.426361,-351.621918,-0.004575,0.000202,0.005125,1.896549,0.096615,0.051253,-351.621918,0.006461,0.000000
16.210001,0.570473,-351.666412,-0.004531,0.000240,0.006105,2.537589,0.129271,0.061053,-351.666412,0.007129,0.000000
16.610001,0.628937,-351.666412,-0.004506,0.000265,0.006738,2.797651,0.142519,0.067383,-351.666412,0.007796,0.000000
17.010000,0.683670,-351.755371,-0.004475,0.000290,0.007363,3.041116,0.154922,0.073628,-351.755371,0.008464,0.000000
17.410002,0.744370,-351.710876,-0.004445,0.000318,0.008065,3.311121,0.168677,0.080652,-351.710876,0.009132,0.000000
17.810001,0.798363,-351.755371,-0.004406,0.000346,0.008776,3.551295,0.180912,0.087763,-351.755371,0.009800,0.000000
18.210001,0.860550,-351.755371,-0.004389,0.000369,0.009383,3.827917,0.195003,0.093834,-351.755371,0.010467,0.000000
18.610001,1.007637,-351.755371,-0.004368,0.000395,0.010042,4.482193,0.228334,0.100425,-351.755371,0.011135,0.000000
19.010000,1.123444,-351.755371,-0.004320,0.000430,0.010910,4.997327,0.254576,0.109097,-351.755371,0.011794,0.000000
19.410002,1.183395,-351.799835,-0.004294,0.000455,0.011569,5.264006,0.268161,0.115688,-351.799835,0.012462,0.000000
19.810001,1.294365,-351.844330,-0.004264,0.000482,0.012237,5.757623,0.293307,0.122366,-351.844330,0.013130,0.000000
20.210001,1.413147,-351.888794,-0.004251,0.000504,0.012809,6.285992,0.320224,0.128089,-351.888794,0.013798,0.000000
20.610001,1.520393,-351.799835,-0.004208,0.000527,0.013390,6.763048,0.344526,0.133900,-351.799835,0.014465,0.000000
21.010000,1.704720,-351.844330,-0.004208,0.000555,0.014101,7.582971,0.386295,0.141011,-351.844330,0.015133,0.000000
21.410002,1.728920,-351.844330,-0.004169,0.000576,0.014630,7.690620,0.391779,0.146301,-351.844330,0.015801,0.000000
21.810001,1.924042,-351.888794,-0.004126,0.000606,0.015402,8.558565,0.435994,0.154019,-351.888794,0.016469,0.000000
22.210001,2.069267,-351.888794,-0.004109,0.000630,0.015992,9.204560,0.468903,0.159917,-351.888794,0.017128,0.000000
22.610001,2.242050,-351.977753,-0.004074,0.000658,0.016703,9.973137,0.508056,0.167028,-351.977753,0.017795,0.000000
23.010000,2.376106,-351.933289,-0.004040,0.000680,0.017284,10.569448,0.538433,0.172838,-351.933289,0.018463,0.000000
23.410002,2.517982,-351.977753,-0.004023,0.000706,0.017934,11.200545,0.570583,0.179342,-351.977753,0.019131,0.000000
23.810001,2.663574,-351.933289,-0.003992,0.000733,0.018611,11.848170,0.603575,0.186107,-351.933289,0.019799,0.000000
24.210001,2.767471,-351.977753,-0.003962,0.000762,0.019365,12.310328,0.627118,0.193652,-351.977753,0.020467,0.000000
24.610001,2.876572,-352.022247,-0.003932,0.000784,0.019920,12.795630,0.651840,0.199202,-352.022247,0.021134,0.000000
25.010002,3.033714,-351.977753,-0.003893,0.000817,0.020753,13.494636,0.687449,0.207527,-351.977753,0.021802,0.000000
25.410002,3.130531,-352.022247,-0.003880,0.000845,0.021473,13.925299,0.709388,0.214725,-352.022247,0.022461,0.000000
25.810001,3.240379,-352.066742,-0.003846,0.000870,0.022106,14.413927,0.734280,0.221056,-352.066742,0.023129,0.000000
26.210001,3.140961,-352.022247,-0.003816,0.000877,0.022288,13.971691,0.711752,0.222877,-352.022247,0.023797,0.000000
26.610001,3.433647,-352.022247,-0.003781,0.000918,0.023311,15.273625,0.778076,0.233110,-352.022247,0.024464,0.000000
27.010002,3.618340,-352.066742,-0.003747,0.000949,0.024109,16.095179,0.819927,0.241089,-352.066742,0.025132,0.000000
27.410002,3.606049,-352.111206,-0.003704,0.000975,0.024759,16.040504,0.817142,0.247593,-352.111206,0.025800,0.000000
27.810001,3.694305,-352.111206,-0.003682,0.000999,0.025384,16.433092,0.837142,0.253837,-352.111206,0.026468,0.000000
28.210001,3.842506,-352.111206,-0.003660,0.001027,0.026086,17.092321,0.870724,0.260862,-352.111206,0.027135,0.000000
28.610001,3.856659,-352.155701,-0.003639,0.001050,0.026667,17.155275,0.873931,0.266672,-352.155701,0.027795,0.000000
29.010002,3.787025,-352.155701,-0.003587,0.001065,0.027049,16.845531,0.858152,0.270488,-352.155701,0.028462,0.000000
29.410002,3.954224,-352.200165,-0.003561,0.001102,0.027994,17.589266,0.896040,0.279941,-352.200165,0.029130,0.000000
29.810001,3.916237,-352.155701,-0.003544,0.001123,0.028514,17.420292,0.887432,0.285144,-352.155701,0.029798,0.000000
30.210001,4.205940,-352.200165,-0.003505,0.001159,0.029442,18.708956,0.953080,0.294423,-352.200165,0.030466,0.000000
30.610001,4.154930,-352.244659,-0.003458,0.001179,0.029954,18.482052,0.941521,0.299540,-352.244659,0.031133,0.000000
31.010002,4.228661,-352.200165,-0.003436,0.001205,0.030613,18.810022,0.958228,0.306131,-352.200165,0.031801,0.000000
31.410002,4.261055,-352.244659,-0.003415,0.001233,0.031316,18.954119,0.965569,0.313155,-352.244659,0.032469,0.000000
31.810001,4.466980,-352.244659,-0.003389,0.001265,0.032139,19.870119,1.012232,0.321394,-352.244659,0.033137,0.000000
32.210003,4.492668,-352.289124,-0.003359,0.001289,0.032729,19.984386,1.018053,0.327291,-352.289124,0.033796,0.000000
32.610001,4.468842,-352.289124,-0.003320,0.001309,0.033241,19.878401,1.012654,0.332408,-352.289124,0.034464,0.000000
33.010002,4.587624,-352.289124,-0.003298,0.001335,0.033909,20.406769,1.039570,0.339085,-352.289124,0.035131,0.000000
33.410000,4.538841,-352.378082,-0.003264,0.001359,0.034524,20.189774,1.028516,0.345243,-352.378082,0.035799,0.000000
33.810001,4.648323,-352.289124,-0.003229,0.001381,0.035079,20.676773,1.053325,0.350793,-352.289124,0.036467,0.000000
34.210003,4.985321,-352.333618,-0.003208,0.001417,0.035990,22.175816,1.129690,0.359899,-352.333618,0.037135,0.000000
34.610001,5.053467,-352.378082,-0.003169,0.001451,0.036848,22.478943,1.145132,0.368484,-352.378082,0.037802,0.000000
35.010002,4.903023,-352.333618,-0.003139,0.001467,0.037265,21.809734,1.111041,0.372647,-352.333618,0.038470,0.000000
35.410000,4.917923,-352.378082,-0.003109,0.001488,0.037785,21.876015,1.114417,0.377850,-352.378082,0.039129,0.000000
35.810001,5.291412,-352.378082,-0.003087,0.001523,0.038687,23.537378,1.199051,0.386869,-352.378082,0.039797,0.000000
36.210003,5.355461,-352.422577,-0.003044,0.001551,0.039398,23.822281,1.213565,0.393981,-352.422577,0.040465,0.000000
36.610001,5.247841,-352.467041,-0.003031,0.001570,0.039866,23.343561,1.189178,0.398664,-352.467041,0.041133,0.000000
37.010002,5.504036,-352.378082,-0.002992,0.001600,0.040647,24.483175,1.247232,0.406469,-352.378082,0.041800,0.000000
37.410004,5.420624,-352.422577,-0.002958,0.001616,0.041054,24.112139,1.228331,0.410545,-352.422577,0.042468,0.000000
37.810001,5.703995,-352.467041,-0.002945,0.001649,0.041896,25.372637,1.292544,0.418957,-352.467041,0.043136,0.000000
38.210003,5.929283,-352.422577,-0.002923,0.001687,0.042841,26.374769,1.343595,0.428410,-352.422577,0.043804,0.000000
38.610001,5.772141,-352.511536,-0.002880,0.001705,0.043309,25.675764,1.307986,0.433093,-352.511536,0.044463,0.000000
39.010002,5.950882,-352.556030,-0.002854,0.001736,0.044098,26.470844,1.348489,0.440984,-352.556030,0.045130,0.000000
39.410004,6.129623,-352.556030,-0.002807,0.001765,0.044827,27.265926,1.388993,0.448269,-352.556030,0.045798,0.000000
39.810001,6.208939,-352.556030,-0.002802,0.001787,0.045399,27.618738,1.406965,0.453993,-352.556030,0.046466,0.000000
40.210003,6.494919,-352.511536,-0.002768,0.001820,0.046232,28.890842,1.471770,0.462318,-352.511536,0.047134,0.000000
40.610001,6.446884,-352.556030,-0.002725,0.001845,0.046874,28.677174,1.460885,0.468736,-352.556030,0.047801,0.000000
41.010002,6.445763,-352.600494,-0.002716,0.001870,0.047507,28.672184,1.460631,0.475066,-352.600494,0.048469,0.000000
41.410004,6.668442,-352.511536,-0.002682,0.001898,0.048200,29.662710,1.511091,0.482004,-352.511536,0.049137,0.000000
41.810001,6.741058,-352.600494,-0.002660,0.001921,0.048781,29.985725,1.527546,0.487815,-352.600494,0.049796,0.000000
42.210003,6.886284,-352.600494,-0.002634,0.001947,0.049449,30.631720,1.560454,0.494492,-352.600494,0.050464,0.000000
42.610001,6.989059,-352.600494,-0.002604,0.001970,0.050030,31.088888,1.583743,0.500303,-352.600494,0.051132,0.000000
43.010002,7.105980,-352.644989,-0.002552,0.001998,0.050741,31.608978,1.610238,0.507414,-352.644989,0.051799,0.000000
43.410004,7.157372,-352.644989,-0.002548,0.002020,0.051305,31.837578,1.621884,0.513051,-352.644989,0.052467,0.000000
43.810001,7.418404,-352.644989,-0.002527,0.002049,0.052042,32.998707,1.681034,0.520422,-352.644989,0.053135,0.000000
44.210003,7.374458,-352.733948,-0.002492,0.002072,0.052641,32.803230,1.671076,0.526406,-352.733948,0.053803,0.000000
44.610001,7.546494,-352.733948,-0.002466,0.002093,0.053170,33.568481,1.710060,0.531696,-352.733948,0.054470,0.000000
45.010002,7.824287,-352.733948,-0.002440,0.002123,0.053924,34.804169,1.773009,0.539241,-352.733948,0.055138,0.000000
45.410004,8.070427,-352.733948,-0.002410,0.002152,0.054661,35.899052,1.828785,0.546612,-352.733948,0.055797,0.000000
45.810001,8.151978,-352.733948,-0.002371,0.002181,0.055398,36.261806,1.847265,0.553984,-352.733948,0.056465,0.000000
46.210003,8.310982,-352.822906,-0.002354,0.002207,0.056049,36.969093,1.883295,0.560488,-352.822906,0.057133,0.000000
46.610001,8.277466,-352.733948,-0.002328,0.002231,0.056656,36.820007,1.875701,0.566559,-352.733948,0.057801,0.000000
47.010002,8.573502,-352.822906,-0.002285,0.002261,0.057419,38.136841,1.942783,0.574190,-352.822906,0.058468,0.000000
47.410004,8.385078,-352.778412,-0.002264,0.002275,0.057783,37.298691,1.900086,0.577833,-352.778412,0.059136,0.000000
47.810001,9.072105,-352.867371,-0.002233,0.002308,0.058633,40.354740,2.055768,0.586331,-352.867371,0.059804,0.000000
48.210003,9.219940,-352.822906,-0.002220,0.002336,0.059336,41.012341,2.089268,0.593356,-352.822906,0.060472,0.000000
48.610001,9.498100,-352.822906,-0.002195,0.002367,0.060125,42.249660,2.152300,0.601248,-352.822906,0.061131,0.000000
49.010002,9.634392,-352.911865,-0.002160,0.002394,0.060810,42.855915,2.183184,0.608099,-352.911865,0.061799,0.000000
49.410004,9.355110,-352.911865,-0.002143,0.002405,0.061079,41.613609,2.119898,0.610787,-352.911865,0.062466,0.000000
49.810001,10.006020,-352.911865,-0.002104,0.002443,0.062059,44.508999,2.267396,0.620587,-352.911865,0.063134,0.000000
50.210003,10.029480,-353.045319,-0.002095,0.002463,0.062562,44.613354,2.272713,0.625617,-353.045319,0.063802,0.000000
50.610001,10.459564,-353.000824,-0.002057,0.002497,0.063429,46.526466,2.370171,0.634289,-353.000824,0.064470,0.000000
51.010002,10.597717,-353.000824,-0.002022,0.002519,0.063993,47.141003,2.401477,0.639926,-353.000824,0.065137,0.000000
51.410004,10.751511,-352.956360,-0.002005,0.002548,0.064712,47.825108,2.436327,0.647124,-352.956360,0.065805,0.000000
51.810001,11.286232,-353.000824,-0.001983,0.002574,0.065380,50.203667,2.557497,0.653802,-353.000824,0.066464,0.000000
52.210003,11.691376,-353.000824,-0.001944,0.002604,0.066135,52.005836,2.649304,0.661346,-353.000824,0.067132,0.000000
52.610001,11.700684,-353.000824,-0.001927,0.002627,0.066724,52.047241,2.651413,0.667244,-353.000824,0.067800,0.000000
53.010002,12.186630,-353.045319,-0.001914,0.002655,0.067444,54.208839,2.761530,0.674442,-353.045319,0.068467,0.000000
53.410004,12.413780,-353.045319,-0.001871,0.002682,0.068112,55.219254,2.813003,0.681119,-353.045319,0.069135,0.000000
53.810001,12.583954,-353.089783,-0.001863,0.002706,0.068728,55.976223,2.851565,0.687276,-353.089783,0.069803,0.000000
54.210003,12.983505,-353.134277,-0.001832,0.002728,0.069291,57.753517,2.942104,0.692913,-353.134277,0.070471,0.000000
54.610004,13.315292,-353.045319,-0.001811,0.002755,0.069968,59.229378,3.017288,0.699678,-353.045319,0.071139,0.000000
55.010002,13.242310,-353.089783,-0.001794,0.002773,0.070445,58.904736,3.000750,0.704448,-353.089783,0.071798,0.000000
55.410004,14.549332,-353.134277,-0.001750,0.002810,0.071373,64.718658,3.296926,0.713727,-353.134277,0.072465,0.000000
55.810001,14.715408,-353.134277,-0.001733,0.002835,0.072006,65.457405,3.334559,0.720058,-353.134277,0.073133,0.000000
56.210003,15.058365,-353.134277,-0.001690,0.002866,0.072786,66.982956,3.412274,0.727863,-353.134277,0.073801,0.000000
56.610004,14.916496,-353.223236,-0.001690,0.002886,0.073315,66.351891,3.380126,0.733153,-353.223236,0.074469,0.000000
57.010002,15.371162,-353.223236,-0.001664,0.002904,0.073758,68.374344,3.483155,0.737575,-353.223236,0.075136,0.000000
57.410004,16.597008,-353.178741,-0.001630,0.002942,0.074738,73.827179,3.760936,0.747375,-353.178741,0.075804,0.000000
57.810001,16.849106,-353.267700,-0.001621,0.002968,0.075388,74.948563,3.818062,0.753879,-353.267700,0.076472,0.000000
58.210003,16.719147,-353.312195,-0.001600,0.002984,0.075796,74.370476,3.788613,0.757955,-353.312195,0.077140,0.000000
58.610004,17.400589,-353.267700,-0.001552,0.003011,0.076472,77.401688,3.943030,0.764720,-353.267700,0.077799,0.000000
59.010002,18.422005,-353.267700,-0.001526,0.003041,0.077235,81.945168,4.174486,0.772351,-353.267700,0.078467,0.000000
59.410004,19.108292,-353.312195,-0.001522,0.003071,0.078016,84.997925,4.330000,0.780156,-353.312195,0.079134,0.000000
59.810001,19.317192,-353.312195,-0.001492,0.003095,0.078614,85.927162,4.377338,0.786140,-353.312195,0.079802,0.000000
60.210003,20.255569,-353.401154,-0.001479,0.003129,0.079473,90.101273,4.589978,0.794726,-353.401154,0.080470,0.000000
60.610004,20.488678,-353.356689,-0.001449,0.003150,0.080019,91.138191,4.642801,0.800189,-353.356689,0.081138,0.000000
61.010002,20.960098,-353.356689,-0.001418,0.003174,0.080626,93.235176,4.749626,0.806260,-353.356689,0.081805,0.000000
61.410004,22.280159,-353.401154,-0.001414,0.003208,0.081485,99.107094,5.048756,0.814845,-353.401154,0.082473,0.000000
61.810001,23.247955,-353.356689,-0.001375,0.003239,0.082282,103.412071,5.268062,0.822824,-353.356689,0.083132,0.000000
62.210003,23.315727,-353.401154,-0.001354,0.003260,0.082811,103.713531,5.283419,0.828114,-353.401154,0.083800,0.000000
62.610004,24.130478,-353.401154,-0.001337,0.003287,0.083479,107.337723,5.468045,0.834791,-353.401154,0.084468,0.000000
63.010002,24.685310,-353.445648,-0.001328,0.003309,0.084060,109.805748,5.593771,0.840602,-353.445648,0.085136,0.000000
63.410004,25.170883,-353.445648,-0.001298,0.003329,0.084555,111.965683,5.703804,0.845545,-353.445648,0.085803,0.000000
63.810001,26.595581,-353.534607,-0.001281,0.003362,0.085404,118.303055,6.026645,0.854044,-353.534607,0.086471,0.000000
64.210007,27.380547,-353.534607,-0.001268,0.003390,0.086098,121.794754,6.204521,0.860982,-353.534607,0.087139,0.000000
64.610001,28.490959,-353.490112,-0.001233,0.003416,0.086775,126.734116,6.456143,0.867746,-353.490112,0.087807,0.000000
65.010002,28.957916,-353.490112,-0.001220,0.003439,0.087338,128.811249,6.561958,0.873383,-353.490112,0.088466,0.000000
65.410004,29.962944,-353.490112,-0.001216,0.003463,0.087954,133.281830,6.789701,0.879541,-353.490112,0.089133,0.000000
65.810005,30.734505,-353.534607,-0.001194,0.003486,0.088552,136.713898,6.964538,0.885524,-353.534607,0.089801,0.000000
66.210007,31.851624,-353.534607,-0.001181,0.003517,0.089342,141.683090,7.217681,0.893416,-353.534607,0.090469,0.000000
66.610001,32.271660,-353.534607,-0.001147,0.003531,0.089689,143.551514,7.312863,0.896885,-353.534607,0.091137,0.000000
67.010002,34.533821,-353.579071,-0.001138,0.003573,0.090755,153.614105,7.825476,0.907552,-353.579071,0.091805,0.000000
67.410004,35.065567,-353.579071,-0.001125,0.003593,0.091267,155.979431,7.945971,0.912669,-353.579071,0.092472,0.000000
67.810005,35.318405,-353.579071,-0.001095,0.003609,0.091666,157.104111,8.003265,0.916658,-353.579071,0.093140,0.000000
68.210007,37.554131,-353.579071,-0.001082,0.003650,0.092698,167.049118,8.509888,0.926978,-353.579071,0.093799,0.000000
68.610001,38.502190,-353.623566,-0.001082,0.003673,0.093296,171.266296,8.724721,0.932961,-353.623566,0.094467,0.000000
69.010002,37.564186,-353.623566,-0.001061,0.003674,0.093313,167.093842,8.512167,0.933135,-353.623566,0.095135,0.000000
69.410004,41.185883,-353.668030,-0.001035,0.003723,0.094562,183.203949,9.332854,0.945623,-353.668030,0.095802,0.000000
69.810005,42.160004,-353.712524,-0.001022,0.003747,0.095178,187.537064,9.553593,0.951780,-353.712524,0.096470,0.000000
70.210007,43.624924,-353.712524,-0.001018,0.003778,0.095967,194.053360,9.885549,0.959672,-353.712524,0.097138,0.000000
70.610001,44.517868,-353.712524,-0.000996,0.003800,0.096514,198.025360,10.087893,0.965136,-353.712524,0.097806,0.000000
71.010002,46.594215,-353.801483,-0.000987,0.003833,0.097355,207.261429,10.558400,0.973548,-353.801483,0.098473,0.000000
71.410004,48.238991,-353.712524,-0.000949,0.003862,0.098083,214.577744,10.931111,0.980832,-353.712524,0.099141,0.000000
71.810005,48.502998,-353.712524,-0.000957,0.003879,0.098517,215.752106,10.990936,0.985168,-353.712524,0.099800,0.000000
72.210007,50.078133,-353.801483,-0.000936,0.003906,0.099219,222.758652,11.347867,0.992193,-353.801483,0.100468,0.000000
72.610001,51.543793,-353.756989,-0.000940,0.003927,0.099748,229.278244,11.679991,0.997483,-353.756989,0.101136,0.000000
73.010002,53.776169,-353.801483,-0.000918,0.003961,0.100598,239.208344,12.185854,1.005982,-353.801483,0.101804,0.000000
73.410004,55.423172,-353.801483,-0.000897,0.003988,0.101301,246.534576,12.559071,1.013007,-353.801483,0.102471,0.000000
73.810005,56.970001,-353.845978,-0.000884,0.004017,0.102020,253.415222,12.909587,1.020204,-353.845978,0.103139,0.000000
74.210007,58.435287,-353.890442,-0.000884,0.004039,0.102584,259.933136,13.241626,1.025841,-353.890442,0.103807,0.000000
74.610001,60.492645,-353.890442,-0.000858,0.004068,0.103321,269.084717,13.707829,1.033213,-353.890442,0.104475,0.000000
75.010002,61.789619,-353.890442,-0.000858,0.004091,0.103911,274.853943,14.001728,1.039110,-353.890442,0.105134,0.000000
75.410004,63.768776,-353.890442,-0.000845,0.004120,0.104657,283.657684,14.450211,1.046568,-353.890442,0.105802,0.000000
75.810005,65.174858,-353.934937,-0.000832,0.004141,0.105177,289.912262,14.768834,1.051771,-353.934937,0.106469,0.000000
76.210007,66.444283,-353.890442,-0.000836,0.004151,0.105446,295.558929,15.056490,1.054460,-353.890442,0.105723,0.000000
76.610001,65.490257,-353.934937,-0.000819,0.004150,0.105420,291.315216,14.840305,1.054200,-353.934937,294.500488,0.000000
77.010002,64.720192,-353.934937,-0.000811,0.004151,0.105429,287.889801,14.665805,1.054286,-353.934937,294.500488,0.000000
77.410004,65.457863,-353.979401,-0.000815,0.004170,0.105906,291.171112,14.832964,1.059056,-353.979401,294.500488,0.000000
77.810005,65.014366,-354.023895,-0.000802,0.004170,0.105914,289.198334,14.732466,1.059143,-354.023895,294.500488,0.000000
78.210007,64.666573,-353.979401,-0.000802,0.004170,0.105914,287.651276,14.653654,1.059143,-353.979401,294.500488,0.000000
78.610001,64.331062,-354.068359,-0.000806,0.004170,0.105923,286.158844,14.577627,1.059230,-354.068359,294.500488,0.000000
79.010002,66.096107,-354.023895,-0.000789,0.004175,0.106036,294.010162,14.977592,1.060357,-354.023895,294.500488,0.000000
79.410004,65.772148,-354.023895,-0.000802,0.004175,0.106036,292.569122,14.904181,1.060357,-354.023895,294.500488,0.000000
79.810005,65.383766,-354.112854,-0.000793,0.004175,0.106036,290.841522,14.816174,1.060357,-354.112854,294.500488,0.000000
80.210007,65.121986,-354.068359,-0.000789,0.004175,0.106044,289.677063,14.756853,1.060444,-354.068359,294.500488,0.000000
80.610001,64.906013,-354.157318,-0.000785,0.004175,0.106044,288.716370,14.707913,1.060444,-354.157318,294.500488,0.000000
81.010002,65.831352,-354.112854,-0.000785,0.004198,0.106625,292.832489,14.917598,1.066254,-354.112854,294.500488,0.000000
81.410004,65.669365,-354.112854,-0.000785,0.004198,0.106625,292.111938,14.880891,1.066254,-354.112854,294.500488,0.000000
81.810005,65.521904,-354.112854,-0.000785,0.004198,0.106625,291.455994,14.847476,1.066254,-354.112854,294.500488,0.000000
82.210007,65.349129,-354.246307,-0.000772,0.004198,0.106625,290.687439,14.808324,1.066254,-354.246307,294.500488,0.000000
82.610001,65.229225,-354.201813,-0.000767,0.004198,0.106625,290.154083,14.781154,1.066254,-354.201813,294.500488,0.000000
83.010002,65.059792,-354.157318,-0.000776,0.004198,0.106625,289.400421,14.742759,1.066254,-354.157318,294.500488,0.000000
83.410004,64.948830,-354.246307,-0.000789,0.004198,0.106625,288.906830,14.717615,1.066254,-354.246307,294.500488,0.000000
83.810005,64.787590,-354.246307,-0.000776,0.004198,0.106625,288.189606,14.681078,1.066254,-354.246307,294.500488,0.000000
84.210007,64.663216,-354.201813,-0.000763,0.004198,0.106625,287.636353,14.652894,1.066254,-354.201813,294.500488,0.000000
84.610001,64.540337,-354.246307,-0.000776,0.004198,0.106634,287.089752,14.625050,1.066341,-354.246307,294.500488,0.000000
85.010002,64.507195,-354.246307,-0.000776,0.004212,0.106972,286.942322,14.617539,1.069723,-354.246307,294.500488,0.000000
85.410004,66.217506,-354.290771,-0.000755,0.004208,0.106894,294.550171,15.005101,1.068943,-354.290771,294.500488,0.000000
85.810005,66.069298,-354.290771,-0.000759,0.004208,0.106894,293.890900,14.971517,1.068943,-354.290771,294.500488,0.000000
86.210007,65.967262,-354.290771,-0.000772,0.004208,0.106886,293.437042,14.948395,1.068856,-354.290771,294.500488,0.000000
86.610001,65.848488,-354.290771,-0.000767,0.004208,0.106886,292.908691,14.921480,1.068856,-354.290771,294.500488,0.000000
87.010002,65.760597,-354.335266,-0.000763,0.004208,0.106886,292.517731,14.901565,1.068856,-354.335266,294.500488,0.000000
87.410004,65.620964,-354.379730,-0.000767,0.004208,0.106886,291.896637,14.869923,1.068856,-354.379730,294.500488,0.000000
87.810005,65.550591,-354.379730,-0.000767,0.004208,0.106886,291.583588,14.853976,1.068856,-354.379730,294.500488,0.000000
88.210007,65.467537,-354.379730,-0.000759,0.004208,0.106894,291.214142,14.835155,1.068943,-354.379730,294.500488,0.000000
88.610001,65.339455,-354.379730,-0.000772,0.004208,0.106894,290.644409,14.806131,1.068943,-354.379730,294.500488,0.000000
89.010002,65.288063,-354.379730,-0.000755,0.004209,0.106920,290.415802,14.794487,1.069203,-354.379730,294.500488,0.000000
89.410004,65.222145,-354.468689,-0.000767,0.004210,0.106929,290.122589,14.779550,1.069289,-354.468689,294.500488,0.000000
89.810005,65.143211,-354.513184,-0.000772,0.004210,0.106929,289.771484,14.761663,1.069289,-354.513184,294.500488,0.000000
90.210007,65.061287,-354.513184,-0.000763,0.004212,0.106990,289.407043,14.743098,1.069896,-354.513184,294.500488,0.000000
90.610001,64.995750,-354.513184,-0.000750,0.004212,0.106990,289.115540,14.728248,1.069896,-354.513184,294.500488,0.000000
91.010002,64.936546,-354.513184,-0.000767,0.004212,0.106990,288.852173,14.714832,1.069896,-354.513184,294.500488,0.000000
91.410004,64.874352,-354.557648,-0.000746,0.004212,0.106990,288.575531,14.700738,1.069896,-354.557648,294.500488,0.000000
91.810005,64.805840,-354.557648,-0.000755,0.004213,0.106998,288.270782,14.685213,1.069983,-354.557648,294.500488,0.000000
92.210007,64.763008,-354.646637,-0.000759,0.004213,0.106998,288.080261,14.675508,1.069983,-354.646637,294.500488,0.000000
92.610001,65.807152,-354.602142,-0.000755,0.004227,0.107354,292.724823,14.912114,1.073539,-354.602142,294.500488,0.000000
93.010002,65.875298,-354.557648,-0.000750,0.004227,0.107354,293.027954,14.927555,1.073539,-354.557648,294.500488,0.000000
93.410004,65.862267,-354.646637,-0.000759,0.004227,0.107354,292.970001,14.924603,1.073539,-354.646637,294.500488,0.000000
93.810005,65.839546,-354.646637,-0.000755,0.004227,0.107354,292.868927,14.919454,1.073539,-354.646637,294.500488,0.000000
94.210007,65.794853,-354.602142,-0.000750,0.004227,0.107354,292.670135,14.909328,1.073539,-354.602142,294.500488,0.000000
94.610008,65.771400,-354.646637,-0.000755,0.004227,0.107354,292.565796,14.904013,1.073539,-354.646637,294.500488,0.000000
95.010002,65.687248,-354.646637,-0.000763,0.004227,0.107354,292.191467,14.884943,1.073539,-354.646637,294.500488,0.000000
95.410004,65.626549,-354.691101,-0.000750,0.004227,0.107354,291.921478,14.871188,1.073539,-354.691101,294.500488,0.000000
95.810005,65.601219,-354.646637,-0.000755,0.004227,0.107354,291.808807,14.865449,1.073539,-354.646637,294.500488,0.000000
96.210007,65.549843,-354.735596,-0.000742,0.004227,0.107363,291.580261,14.853807,1.073625,-354.735596,294.500488,0.000000
96.610008,65.519676,-354.780060,-0.000755,0.004227,0.107363,291.446075,14.846972,1.073625,-354.780060,294.500488,0.000000
97.010002,65.487282,-354.735596,-0.000750,0.004227,0.107363,291.301971,14.839630,1.073625,-354.735596,294.500488,0.000000
97.410004,65.419502,-354.780060,-0.000750,0.004227,0.107363,291.000488,14.824271,1.073625,-354.780060,294.500488,0.000000
97.810005,65.391579,-354.824554,-0.000759,0.004227,0.107363,290.876282,14.817944,1.073625,-354.824554,294.500488,0.000000
98.210007,65.339821,-354.735596,-0.000750,0.004227,0.107363,290.646027,14.806215,1.073625,-354.735596,294.500488,0.000000
98.610008,65.307426,-354.780060,-0.000755,0.004227,0.107363,290.501953,14.798875,1.073625,-354.780060,294.500488,0.000000
99.010002,65.275398,-354.780060,-0.000746,0.004227,0.107363,290.359467,14.791616,1.073625,-354.780060,294.500488,0.000000
99.410004,65.241890,-354.869019,-0.000750,0.004227,0.107371,290.210419,14.784024,1.073712,-354.869019,294.500488,0.000000
99.810005,65.187889,-354.824554,-0.000759,0.004227,0.107371,289.970215,14.771787,1.073712,-354.824554,294.500488,0.000000
100.210007,65.153633,-354.869019,-0.000759,0.004227,0.107371,289.817841,14.764025,1.073712,-354.869019,294.500488,0.000000
100.610008,65.104103,-354.869019,-0.000750,0.004227,0.107371,289.597504,14.752801,1.073712,-354.869019,294.500488,0.000000
101.010002,65.070961,-354.913513,-0.000742,0.004227,0.107371,289.450104,14.745290,1.073712,-354.913513,294.500488,0.000000
101.410004,65.029259,-354.913513,-0.000750,0.004227,0.107371,289.264587,14.735841,1.073712,-354.913513,294.500488,0.000000
101.810005,65.008034,-354.869019,-0.000746,0.004227,0.107371,289.170166,14.731030,1.073712,-354.869019,294.500488,0.000000
102.210007,64.963722,-354.913513,-0.000733,0.004227,0.107371,288.973083,14.720990,1.073712,-354.913513,294.500488,0.000000
102.610008,64.938408,-354.913513,-0.000755,0.004227,0.107371,288.860474,14.715253,1.073712,-354.913513,294.500488,0.000000
103.010002,64.906746,-354.957977,-0.000759,0.004227,0.107371,288.719635,14.708078,1.073712,-354.957977,294.500488,0.000000
103.410004,64.864677,-354.957977,-0.000737,0.004227,0.107371,288.532501,14.698546,1.073712,-354.957977,294.500488,0.000000
103.810005,64.820366,-354.957977,-0.000742,0.004227,0.107371,288.335388,14.688504,1.073712,-354.957977,294.500488,0.000000
104.210007,65.903587,-355.002472,-0.000750,0.004241,0.107709,293.153809,14.933966,1.077095,-355.002472,294.500488,0.000000
104.610008,65.973976,-354.957977,-0.000737,0.004240,0.107692,293.466888,14.949917,1.076921,-354.957977,294.500488,0.000000
105.010002,65.972115,-355.046967,-0.000742,0.004240,0.107692,293.458618,14.949494,1.076921,-355.046967,294.500488,0.000000
105.410004,65.867104,-355.002472,-0.000755,0.004240,0.107692,292.991516,14.925699,1.076921,-355.002472,294.500488,0.000000
105.810005,65.853325,-355.091431,-0.000750,0.004240,0.107692,292.930206,14.922577,1.076921,-355.091431,294.500488,0.000000
106.210007,65.873436,-355.046967,-0.000746,0.004240,0.107692,293.019684,14.927135,1.076921,-355.046967,294.500488,0.000000
106.610008,65.904716,-355.046967,-0.000755,0.004240,0.107692,293.158813,14.934223,1.076921,-355.046967,294.500488,0.000000
107.010002,65.879387,-355.046967,-0.000737,0.004240,0.107692,293.046143,14.928483,1.076921,-355.046967,294.500488,0.000000
107.410004,65.862267,-355.002472,-0.000750,0.004240,0.107692,292.970001,14.924603,1.076921,-355.002472,294.500488,0.000000
107.810005,65.836189,-355.135925,-0.000746,0.004240,0.107692,292.854004,14.918694,1.076921,-355.135925,294.500488,0.000000
108.210007,65.781456,-355.091431,-0.000755,0.004240,0.107692,292.610535,14.906291,1.076921,-355.091431,294.500488,0.000000
108.610008,65.765450,-355.135925,-0.000746,0.004240,0.107692,292.539337,14.902664,1.076921,-355.135925,294.500488,0.000000
109.010002,65.755013,-355.180389,-0.000737,0.004240,0.107692,292.492889,14.900299,1.076921,-355.180389,294.500488,0.000000
109.410004,65.727837,-355.135925,-0.000755,0.004240,0.107692,292.372009,14.894140,1.076921,-355.135925,294.500488,0.000000
109.810005,65.680168,-355.135925,-0.000742,0.004240,0.107692,292.159973,14.883339,1.076921,-355.135925,294.500488,0.000000
110.210007,65.663414,-355.180389,-0.000737,0.004240,0.107692,292.085449,14.879542,1.076921,-355.180389,294.500488,0.000000
110.610008,65.627296,-355.269348,-0.000746,0.004240,0.107692,291.924805,14.871358,1.076921,-355.269348,294.500488,0.000000
111.010002,65.603081,-355.224884,-0.000746,0.004240,0.107692,291.817078,14.865870,1.076921,-355.224884,294.500488,0.000000
111.410004,65.594154,-355.313843,-0.000755,0.004240,0.107692,291.777374,14.863848,1.076921,-355.313843,294.500488,0.000000
111.810005,65.569206,-355.313843,-0.000737,0.004240,0.107692,291.666382,14.858194,1.076921,-355.313843,294.500488,0.000000
112.210007,65.558403,-355.269348,-0.000737,0.004240,0.107692,291.618347,14.855746,1.076921,-355.269348,294.500488,0.000000
112.610008,65.525261,-355.313843,-0.000755,0.004240,0.107692,291.470917,14.848237,1.076921,-355.313843,294.500488,0.000000
113.010002,65.505898,-355.313843,-0.000733,0.004240,0.107692,291.384796,14.843848,1.076921,-355.313843,294.500488,0.000000
113.410004,65.480949,-355.313843,-0.000750,0.004240,0.107692,291.273804,14.838195,1.076921,-355.313843,294.500488,0.000000
113.810005,65.466423,-355.358307,-0.000750,0.004240,0.107692,291.209198,14.834903,1.076921,-355.358307,294.500488,0.000000
114.210007,65.434410,-355.358307,-0.000746,0.004240,0.107692,291.066803,14.827649,1.076921,-355.358307,294.500488,0.000000
114.610008,65.403130,-355.358307,-0.000755,0.004240,0.107692,290.927643,14.820561,1.076921,-355.358307,294.500488,0.000000
115.010002,65.383385,-355.447266,-0.000755,0.004240,0.107692,290.839813,14.816087,1.076921,-355.447266,294.500488,0.000000
115.410004,65.365517,-355.402802,-0.000746,0.004240,0.107692,290.760345,14.812038,1.076921,-355.402802,294.500488,0.000000
115.810005,65.340935,-355.402802,-0.000737,0.004240,0.107692,290.651001,14.806468,1.076921,-355.402802,294.500488,0.000000
116.210007,65.328651,-355.402802,-0.000733,0.004240,0.107692,290.596344,14.803684,1.076921,-355.402802,294.500488,0.000000
116.610008,65.299599,-355.491760,-0.000755,0.004240,0.107692,290.467133,14.797101,1.076921,-355.491760,294.500488,0.000000
117.010002,65.286568,-355.491760,-0.000755,0.004240,0.107692,290.409149,14.794147,1.076921,-355.491760,294.500488,0.000000
117.410004,65.272423,-355.491760,-0.000746,0.004240,0.107692,290.346252,14.790943,1.076921,-355.491760,294.500488,0.000000
117.810005,65.252678,-355.491760,-0.000737,0.004240,0.107692,290.258423,14.786469,1.076921,-355.491760,294.500488,0.000000
118.210007,65.231087,-355.580719,-0.000742,0.004240,0.107692,290.162354,14.781575,1.076921,-355.580719,294.500488,0.000000
118.610008,65.216560,-355.580719,-0.000729,0.004240,0.107692,290.097748,14.778284,1.076921,-355.580719,294.500488,0.000000
119.010002,65.197578,-355.625214,-0.000733,0.004240,0.107692,290.013306,14.773982,1.076921,-355.625214,294.500488,0.000000
119.410004,65.156609,-355.491760,-0.000737,0.004240,0.107692,289.831085,14.764699,1.076921,-355.491760,294.500488,0.000000
119.810005,65.125328,-355.580719,-0.000746,0.004240,0.107692,289.691925,14.757610,1.076921,-355.580719,294.500488,0.000000
120.210007,65.108955,-355.625214,-0.000755,0.004240,0.107692,289.619110,14.753900,1.076921,-355.625214,294.500488,0.000000
120.610008,65.090706,-355.669678,-0.000746,0.004240,0.107692,289.537933,14.749764,1.076921,-355.669678,294.500488,0.000000
121.010002,65.075813,-355.669678,-0.000737,0.004240,0.107692,289.471680,14.746390,1.076921,-355.669678,294.500488,0.000000
121.410004,65.060173,-355.625214,-0.000737,0.004240,0.107692,289.402100,14.742846,1.076921,-355.625214,294.500488,0.000000
121.810005,65.032982,-355.669678,-0.000759,0.004240,0.107692,289.281158,14.736685,1.076921,-355.669678,294.500488,0.000000
122.210007,65.016228,-355.625214,-0.000729,0.004240,0.107692,289.206635,14.732888,1.076921,-355.625214,294.500488,0.000000
122.610008,64.999474,-355.625214,-0.000742,0.004240,0.107692,289.132111,14.729092,1.076921,-355.625214,294.500488,0.000000
123.010002,64.978249,-355.669678,-0.000755,0.004240,0.107692,289.037689,14.724281,1.076921,-355.669678,294.500488,0.000000
123.410004,64.976753,-355.758636,-0.000742,0.004240,0.107692,289.031036,14.723943,1.076921,-355.758636,294.500488,0.000000
123.810005,64.954414,-355.714172,-0.000733,0.004240,0.107692,288.931671,14.718881,1.076921,-355.714172,294.500488,0.000000
124.210007,64.961113,-355.714172,-0.000737,0.004240,0.107692,288.961456,14.720399,1.076921,-355.714172,294.500488,0.000000
124.610008,64.927238,-355.803131,-0.000729,0.004240,0.107692,288.810791,14.712722,1.076921,-355.803131,294.500488,0.000000
125.010002,64.905266,-355.758636,-0.000724,0.004240,0.107692,288.713043,14.707744,1.076921,-355.758636,294.500488,0.000000
125.410004,64.889626,-355.758636,-0.000742,0.004240,0.107692,288.643463,14.704200,1.076921,-355.758636,294.500488,0.000000
125.810005,65.884224,-355.803131,-0.000733,0.004253,0.108022,293.067657,14.929579,1.080216,-355.803131,294.500488,0.000000
126.210007,65.893532,-355.803131,-0.000733,0.004253,0.108022,293.109070,14.931687,1.080216,-355.803131,294.500488,0.000000
126.610008,65.922585,-355.847595,-0.000737,0.004252,0.108004,293.238312,14.938271,1.080043,-355.847595,294.500488,0.000000
127.010010,65.933006,-355.847595,-0.000737,0.004252,0.107996,293.284668,14.940633,1.079956,-355.847595,294.500488,0.000000
127.410004,65.958702,-355.892090,-0.000733,0.004252,0.107996,293.398956,14.946455,1.079956,-355.892090,294.500488,0.000000
127.810005,65.963921,-355.803131,-0.000742,0.004252,0.107996,293.422180,14.947638,1.079956,-355.803131,294.500488,0.000000
128.210007,65.962807,-355.847595,-0.000733,0.004252,0.107996,293.417206,14.947386,1.079956,-355.847595,294.500488,0.000000
128.610001,65.915504,-355.892090,-0.000733,0.004252,0.107996,293.206818,14.936666,1.079956,-355.892090,294.500488,0.000000
129.010010,65.937843,-355.892090,-0.000737,0.004252,0.107996,293.306183,14.941729,1.079956,-355.892090,294.500488,0.000000
129.410004,65.877892,-355.936584,-0.000737,0.004252,0.107996,293.039490,14.928144,1.079956,-355.936584,294.500488,0.000000
129.810013,65.861137,-355.936584,-0.000729,0.004252,0.107996,292.964966,14.924347,1.079956,-355.936584,294.500488,0.000000
130.210007,65.852577,-355.981049,-0.000742,0.004252,0.107996,292.926880,14.922407,1.079956,-355.981049,294.500488,0.000000
130.610001,65.877525,-356.025543,-0.000737,0.004252,0.107996,293.037872,14.928061,1.079956,-356.025543,294.500488,0.000000
131.010010,65.841774,-355.981049,-0.000737,0.004252,0.107996,292.878845,14.919959,1.079956,-355.981049,294.500488,0.000000
131.410004,65.846245,-355.981049,-0.000733,0.004252,0.107996,292.898712,14.920972,1.079956,-355.981049,294.500488,0.000000
131.810013,65.849220,-355.936584,-0.000729,0.004252,0.107996,292.911957,14.921646,1.079956,-355.936584,294.500488,0.000000
132.210007,65.839546,-356.025543,-0.000733,0.004252,0.107996,292.868927,14.919454,1.079956,-356.025543,294.500488,0.000000
132.610001,65.836571,-355.936584,-0.000724,0.004252,0.107996,292.855682,14.918780,1.079956,-355.936584,294.500488,0.000000
133.010010,65.833214,-356.070007,-0.000746,0.004252,0.107996,292.840759,14.918019,1.079956,-356.070007,294.500488,0.000000
133.410004,65.790016,-356.025543,-0.000729,0.004252,0.107996,292.648621,14.908231,1.079956,-356.025543,294.500488,0.000000
133.810013,65.784065,-356.070007,-0.000733,0.004252,0.107996,292.622131,14.906882,1.079956,-356.070007,294.500488,0.000000
134.210007,65.772514,-356.070007,-0.000737,0.004252,0.107996,292.570770,14.904265,1.079956,-356.070007,294.500488,0.000000
134.610001,65.777351,-356.114502,-0.000720,0.004252,0.107996,292.592285,14.905361,1.079956,-356.114502,294.500488,0.000000
135.010010,65.760231,-356.114502,-0.000737,0.004252,0.107996,292.516113,14.901482,1.079956,-356.114502,294.500488,0.000000
135.410004,65.752785,-356.114502,-0.000750,0.004252,0.107996,292.483002,14.899794,1.079956,-356.114502,294.500488,0.000000
135.810013,65.752037,-356.114502,-0.000729,0.004252,0.107996,292.479675,14.899625,1.079956,-356.114502,294.500488,0.000000
136.210007,65.686867,-356.158966,-0.000742,0.004252,0.107996,292.189789,14.884857,1.079956,-356.158966,294.500488,0.000000
136.610001,65.673088,-356.114502,-0.000720,0.004252,0.107996,292.128479,14.881734,1.079956,-356.114502,294.500488,0.000000
137.010010,65.694313,-356.158966,-0.000733,0.004250,0.107961,292.222900,14.886544,1.079609,-356.158966,0.107857,0.000000
137.410004,65.703621,-356.203461,-0.000733,0.004233,0.107519,292.264313,14.888653,1.075186,-356.203461,0.107198,0.000000
137.810013,65.564735,-356.203461,-0.000724,0.004214,0.107024,291.646515,14.857182,1.070243,-356.203461,0.106530,0.000000
138.210007,65.520042,-356.203461,-0.000716,0.004187,0.106348,291.447693,14.847054,1.063479,-356.203461,0.105862,0.000000
138.610001,65.496223,-356.203461,-0.000720,0.004163,0.105750,291.341766,14.841657,1.057495,-356.203461,0.105194,0.000000
139.010010,65.496590,-356.203461,-0.000724,0.004142,0.105194,291.343384,14.841740,1.051945,-356.203461,0.104527,0.000000
139.410004,65.469032,-356.247925,-0.000707,0.004112,0.104457,291.220795,14.835495,1.044574,-356.247925,0.103859,0.000000
139.810013,65.454506,-356.203461,-0.000729,0.004087,0.103807,291.156189,14.832203,1.038069,-356.203461,0.103191,0.000000
140.210007,65.393440,-356.336914,-0.000729,0.004061,0.103157,290.884552,14.818365,1.031565,-356.336914,0.102523,0.000000
140.610001,65.305183,-356.292419,-0.000729,0.004031,0.102385,290.491974,14.798367,1.023847,-356.292419,0.101864,0.000000
141.010010,65.074318,-356.292419,-0.000716,0.004009,0.101821,289.465027,14.746051,1.018210,-356.292419,0.101197,0.000000
141.410004,64.453575,-356.336914,-0.000720,0.003989,0.101309,286.703827,14.605389,1.013093,-356.336914,0.100529,0.000000
141.810013,63.566948,-356.292419,-0.000720,0.003965,0.100702,282.759918,14.404477,1.007023,-356.292419,0.099861,0.000000
142.210007,62.159760,-356.336914,-0.000720,0.003935,0.099948,276.500427,14.085603,0.999478,-356.336914,0.099193,0.000000
142.610001,60.743629,-356.381378,-0.000711,0.003913,0.099384,270.201172,13.764704,0.993841,-356.381378,0.098526,0.000000
143.010010,59.337547,-356.425873,-0.000716,0.003890,0.098803,263.946594,13.446080,0.988030,-356.425873,0.097858,0.000000
143.410004,57.127892,-356.381378,-0.000716,0.003864,0.098135,254.117554,12.945365,0.981353,-356.381378,0.097190,0.000000
143.810013,54.914879,-356.381378,-0.000698,0.003839,0.097511,244.273575,12.443889,0.975109,-356.381378,0.096531,0.000000
144.210007,52.645645,-356.425873,-0.000698,0.003816,0.096921,234.179520,11.929674,0.969212,-356.425873,0.095863,0.000000
144.610001,50.863098,-356.425873,-0.000720,0.003799,0.096505,226.250366,11.525743,0.965049,-356.425873,0.095195,0.000000
145.010010,47.332260,-356.425873,-0.000703,0.003766,0.095646,210.544403,10.725643,0.956463,-356.425873,0.094528,0.000000
145.410004,44.383446,-356.470337,-0.000703,0.003735,0.094874,197.427429,10.057432,0.948745,-356.470337,0.093860,0.000000
145.810013,41.675552,-356.470337,-0.000716,0.003713,0.094302,185.382111,9.443815,0.943021,-356.470337,0.093192,0.000000
146.210007,38.316750,-356.514832,-0.000711,0.003680,0.093470,170.441422,8.682700,0.934696,-356.514832,0.092524,0.000000
146.610001,35.657639,-356.514832,-0.000711,0.003658,0.092915,158.613098,8.080136,0.929146,-356.514832,0.091857,0.000000
147.010010,33.536980,-356.514832,-0.000720,0.003640,0.092446,149.179932,7.599588,0.924463,-356.514832,0.091189,0.000000
147.410004,29.913048,-356.514832,-0.000711,0.003605,0.091579,133.059875,6.778394,0.915790,-356.514832,0.090530,0.000000
147.810013,26.914703,-356.470337,-0.000724,0.003577,0.090868,119.722580,6.098959,0.908679,-356.470337,0.089862,0.000000
148.210007,24.901657,-356.559296,-0.000724,0.003554,0.090270,110.768105,5.642797,0.902695,-356.559296,0.089194,0.000000
148.610001,21.758461,-356.559296,-0.000720,0.003533,0.089741,96.786469,4.930538,0.897405,-356.559296,0.088526,0.000000
149.010010,19.268036,-356.603790,-0.000724,0.003511,0.089168,85.708504,4.366199,0.891681,-356.603790,0.087859,0.000000
149.410004,15.164490,-356.603790,-0.000737,0.003472,0.088188,67.455017,3.436322,0.881882,-356.603790,0.087191,0.000000
149.810013,12.681145,-356.603790,-0.000737,0.003446,0.087529,56.408550,2.873589,0.875291,-356.603790,0.086523,0.000000
150.210007,9.322342,-356.648254,-0.000729,0.003419,0.086853,41.467850,2.112473,0.868527,-356.648254,0.085855,0.000000
150.610001,7.698425,-356.648254,-0.000733,0.003405,0.086488,34.244305,1.744488,0.864884,-356.648254,0.085196,0.000000
151.010010,4.357124,-356.692749,-0.000737,0.003372,0.085656,19.381456,0.987338,0.856559,-356.692749,0.084529,0.000000
151.410004,1.378517,-356.648254,-0.000742,0.003341,0.084867,6.131950,0.312376,0.848667,-356.648254,0.083861,0.000000
151.810013,-0.500099,-356.648254,-0.000733,0.003319,0.084312,-2.224552,-0.113324,0.843117,-356.648254,0.083193,0.000000
152.210007,-0.199966,-356.692749,-0.000763,0.003292,0.083618,-0.889495,-0.045313,0.836179,-356.692749,0.082525,0.000000
152.610001,-0.022346,-356.692749,-0.000793,0.003272,0.083098,-0.099402,-0.005064,0.830976,-356.692749,0.081857,0.000000
153.010010,-0.061813,-356.737213,-0.000828,0.003237,0.082230,-0.274960,-0.014007,0.822303,-356.737213,0.081190,0.000000
153.410004,-0.061073,-356.692749,-0.000867,0.003208,0.081493,-0.271668,-0.013839,0.814932,-356.692749,0.080522,0.000000
153.810013,-0.041710,-356.781708,-0.000910,0.003181,0.080799,-0.185535,-0.009452,0.807994,-356.781708,0.079863,0.000000
154.210007,-0.040588,-356.737213,-0.000944,0.003165,0.080383,-0.180546,-0.009197,0.803832,-356.737213,0.079195,0.000000
154.610001,-0.068146,-356.737213,-0.000983,0.003134,0.079594,-0.303127,-0.015442,0.795940,-356.737213,0.078527,0.000000
155.010010,-0.074478,-356.781708,-0.001022,0.003106,0.078900,-0.331295,-0.016877,0.789002,-356.781708,0.077860,0.000000
155.410004,-0.044685,-356.826202,-0.001043,0.003083,0.078310,-0.198770,-0.010126,0.783105,-356.826202,0.077192,0.000000
155.810013,-0.071495,-356.781708,-0.001091,0.003054,0.077565,-0.318026,-0.016201,0.775647,-356.781708,0.076524,0.000000
156.210007,-0.062187,-356.826202,-0.001130,0.003033,0.077027,-0.276622,-0.014092,0.770270,-356.826202,0.075856,0.000000
156.610001,-0.078949,-356.870667,-0.001164,0.003006,0.076342,-0.351183,-0.017890,0.763419,-356.870667,0.075188,0.000000
157.010010,-0.062561,-356.870667,-0.001212,0.002968,0.075379,-0.278285,-0.014177,0.753793,-356.870667,0.074529,0.000000
157.410004,-0.070381,-356.826202,-0.001237,0.002948,0.074868,-0.313071,-0.015949,0.748676,-356.826202,0.073862,0.000000
157.810013,-0.053993,-356.915161,-0.001272,0.002925,0.074304,-0.240174,-0.012235,0.743039,-356.915161,0.073194,0.000000
158.210007,-0.067032,-356.915161,-0.001315,0.002896,0.073549,-0.298173,-0.015190,0.735494,-356.915161,0.072526,0.000000
158.610001,-0.081177,-356.915161,-0.001332,0.002870,0.072890,-0.361092,-0.018395,0.728903,-356.915161,0.071858,0.000000
159.010010,-0.080811,-356.915161,-0.001371,0.002844,0.072231,-0.359463,-0.018312,0.722312,-356.915161,0.071191,0.000000
159.410004,-0.055489,-356.959625,-0.001406,0.002821,0.071659,-0.246826,-0.012574,0.716589,-356.959625,0.070523,0.000000
159.810013,-0.024956,-357.004120,-0.001436,0.002792,0.070904,-0.111009,-0.005655,0.709044,-357.004120,0.069855,0.000000
160.210007,-0.029419,-356.915161,-0.001483,0.002765,0.070228,-0.130862,-0.006666,0.702279,-356.915161,0.069196,0.000000
160.610001,-0.011917,-357.004120,-0.001500,0.002746,0.069742,-0.053010,-0.002700,0.697423,-357.004120,0.068528,0.000000
161.010010,-0.078949,-357.093079,-0.001531,0.002711,0.068849,-0.351183,-0.017890,0.688491,-357.093079,0.067860,0.000000
161.410004,-0.017876,-357.048584,-0.001561,0.002688,0.068268,-0.079515,-0.004051,0.682680,-357.048584,0.067193,0.000000
161.810013,-0.005959,-357.093079,-0.001595,0.002661,0.067583,-0.026505,-0.001350,0.675829,-357.093079,0.066525,0.000000
162.210007,-0.007080,-357.093079,-0.001621,0.002636,0.066959,-0.031494,-0.001604,0.669585,-357.093079,0.065857,0.000000
162.610001,-0.010429,-357.093079,-0.001651,0.002612,0.066343,-0.046392,-0.002363,0.663428,-357.093079,0.065189,0.000000
163.010010,-0.075592,-357.137543,-0.001690,0.002581,0.065562,-0.336250,-0.017129,0.655623,-357.137543,0.064522,0.000000
163.410004,-0.044312,-357.093079,-0.001712,0.002555,0.064903,-0.197107,-0.010041,0.649032,-357.093079,0.063854,0.000000
163.700012,-0.029419,-357.093079,-0.001738,0.002540,0.064522,-0.130862,-0.006666,0.645216,-357.093079,0.064418,0.000000