File: Data/compression 34/AutoNoHeating-15-34-reverse-1-0_11152024_202618.csv
Time (sec),S:Load (lbs),S:HL1 (DIM),S:LVDT (in),S:Position (in),Ch:Position (mm),Ch:Load (N),Ch:Stress (MPa),Ch:Strain (mm/mm),Ch:HL1 (DIM),Set Point (),Cycles ()
0.110000,-0.061066,-128.016174,-0.013702,-0.007926,-0.201309,-0.271634,-0.013838,-2.013091,-128.016174,-0.201101,0.000000
0.510000,-0.048775,-128.016174,-0.013706,-0.007848,-0.199349,-0.216961,-0.011053,-1.993492,-128.016174,-0.198621,0.000000
0.910000,-0.073730,-128.016174,-0.013564,-0.007606,-0.193201,-0.327969,-0.016708,-1.932005,-128.016174,-0.191960,0.000000
1.310000,-0.028671,-128.060654,-0.013310,-0.007344,-0.186532,-0.127536,-0.006497,-1.865316,-128.060654,-0.185300,0.000000
1.710000,-0.020103,-128.016174,-0.013016,-0.007081,-0.179854,-0.089425,-0.004556,-1.798540,-128.016174,-0.178640,0.000000
2.110000,-0.020103,-128.105133,-0.012732,-0.006820,-0.173220,-0.089425,-0.004556,-1.732197,-128.105133,-0.171962,0.000000
2.510000,-0.061440,-128.105133,-0.012478,-0.006561,-0.166637,-0.273297,-0.013922,-1.666374,-128.105133,-0.165302,0.000000
2.910000,-0.069633,-128.105133,-0.012197,-0.006294,-0.159864,-0.309745,-0.015779,-1.598644,-128.105133,-0.158642,0.000000
3.310000,-0.078568,-128.149612,-0.011939,-0.006032,-0.153213,-0.349486,-0.017804,-1.532128,-128.149612,-0.151981,0.000000
3.710000,-0.032768,-128.149612,-0.011667,-0.005775,-0.146674,-0.145760,-0.007425,-1.466739,-128.149612,-0.145304,0.000000
4.110000,-0.032394,-128.105133,-0.011400,-0.005509,-0.139927,-0.144098,-0.007341,-1.399269,-128.105133,-0.138643,0.000000
4.510000,-0.071495,-128.194107,-0.011128,-0.005245,-0.133232,-0.318026,-0.016201,-1.332319,-128.194107,-0.131983,0.000000
4.910000,-0.109848,-128.194107,-0.010843,-0.004986,-0.126650,-0.488628,-0.024892,-1.266496,-128.194107,-0.125323,0.000000
5.310000,-0.134048,-128.238586,-0.010580,-0.004726,-0.120041,-0.596277,-0.030376,-1.200414,-128.238586,-0.118662,0.000000
5.710000,-0.046547,-128.283066,-0.010326,-0.004468,-0.113476,-0.207051,-0.010548,-1.134765,-128.283066,-0.111985,0.000000
6.110000,-0.039093,-128.238586,-0.010037,-0.004194,-0.106521,-0.173894,-0.008859,-1.065213,-128.238586,-0.105325,0.000000
6.510000,-0.029411,-128.283066,-0.009774,-0.003938,-0.100034,-0.130828,-0.006665,-1.000345,-128.283066,-0.098664,0.000000
6.910000,-0.048035,-128.327545,-0.009507,-0.003680,-0.093470,-0.213669,-0.010885,-0.934696,-128.327545,-0.092004,0.000000
7.310000,-0.053993,-128.372025,-0.009244,-0.003409,-0.086601,-0.240174,-0.012235,-0.866012,-128.372025,-0.085344,0.000000
7.710001,-0.000366,-128.327545,-0.008955,-0.003147,-0.079932,-0.001629,-0.000083,-0.799322,-128.327545,-0.078666,0.000000
8.110001,0.002609,-128.372025,-0.008692,-0.002884,-0.073263,0.011607,0.000591,-0.732632,-128.372025,-0.072006,0.000000
8.510000,-0.012283,-128.372025,-0.008433,-0.002624,-0.066638,-0.054639,-0.002783,-0.666376,-128.372025,-0.065345,0.000000
8.910001,-0.056229,-128.416504,-0.008170,-0.002364,-0.060055,-0.250117,-0.012742,-0.600554,-128.416504,-0.058685,0.000000
9.310000,-0.055855,-128.416504,-0.007886,-0.002097,-0.053265,-0.248455,-0.012657,-0.532650,-128.416504,-0.052025,0.000000
9.710000,-0.067024,-128.460983,-0.007614,-0.001836,-0.046631,-0.298139,-0.015188,-0.466307,-128.460983,-0.045347,0.000000
10.110001,-0.017128,-128.416504,-0.007343,-0.001577,-0.040048,-0.076189,-0.003881,-0.400485,-128.416504,-0.038687,0.000000
10.510000,-0.017128,-128.505463,-0.007067,-0.001311,-0.033310,-0.076189,-0.003881,-0.333101,-128.505463,-0.032027,0.000000
10.910001,-0.059578,-128.460983,-0.006804,-0.001048,-0.026624,-0.265016,-0.013501,-0.266238,-128.460983,-0.025366,0.000000
11.310000,-0.076706,-128.505463,-0.006541,-0.000790,-0.020059,-0.341205,-0.017382,-0.200589,-128.505463,-0.018706,0.000000
11.710001,-0.124367,-128.549942,-0.006273,-0.000529,-0.013433,-0.553211,-0.028182,-0.134333,-128.549942,-0.012028,0.000000
12.110001,-0.037605,-128.594437,-0.006002,-0.000271,-0.006894,-0.167277,-0.008521,-0.068944,-128.594437,-0.005368,0.000000
12.510000,-0.018616,-128.638916,-0.005713,0.000003,0.000078,-0.082807,-0.004218,0.000781,-128.638916,0.001292,0.000000
12.910001,-0.015640,-128.594437,-0.005463,0.000259,0.006574,-0.069571,-0.003544,0.065736,-128.594437,0.007952,0.000000
13.310000,-0.039841,-128.594437,-0.005191,0.000514,0.013052,-0.177220,-0.009028,0.130517,-128.594437,0.014630,0.000000
13.710001,-0.035744,-128.638916,-0.004898,0.000790,0.020059,-0.158996,-0.008100,0.200589,-128.638916,0.021290,0.000000
14.110001,0.086769,-128.683395,-0.004656,0.001051,0.026693,0.385968,0.019662,0.266932,-128.683395,0.027951,0.000000
14.510000,0.103897,-128.727875,-0.004583,-0.000002,-0.000061,0.462157,0.023543,-0.000607,-128.727875,0.000139,0.000000
14.910001,0.142624,-128.683395,-0.004587,-0.000002,-0.000061,0.634423,0.032319,-0.000607,-128.683395,0.000304,0.000000
15.310000,0.102036,-128.683395,-0.004600,-0.000002,-0.000052,0.453877,0.023122,-0.000520,-128.683395,0.000963,0.000000
15.710001,0.148209,-128.772354,-0.004592,0.000023,0.000572,0.659265,0.033585,0.005724,-128.772354,0.001630,0.000000
16.110001,0.187675,-128.772354,-0.004566,0.000040,0.001023,0.834822,0.042528,0.010233,-128.772354,0.002298,0.000000
16.510000,0.365303,-128.816833,-0.004540,0.000076,0.001934,1.624949,0.082779,0.019339,-128.816833,0.002966,0.000000
16.910002,0.522072,-128.816833,-0.004510,0.000098,0.002498,2.322292,0.118303,0.024976,-128.816833,0.003634,0.000000
17.310001,0.708626,-128.905792,-0.004475,0.000123,0.003131,3.152125,0.160577,0.031307,-128.905792,0.004301,0.000000
17.710001,0.919388,-128.861313,-0.004449,0.000155,0.003946,4.089641,0.208336,0.039459,-128.861313,0.004969,0.000000
18.110001,1.117493,-128.950272,-0.004432,0.000173,0.004397,4.970856,0.253227,0.043968,-128.950272,0.005637,0.000000
18.510000,1.485397,-128.950272,-0.004411,0.000207,0.005255,6.607378,0.336596,0.052554,-128.950272,0.006305,0.000000
18.910002,1.760582,-128.950272,-0.004368,0.000233,0.005923,7.831460,0.398954,0.059232,-128.950272,0.006964,0.000000
19.310001,2.041351,-128.950272,-0.004350,0.000262,0.006643,9.080384,0.462577,0.066429,-128.950272,0.007632,0.000000
19.710001,2.366798,-128.994751,-0.004324,0.000289,0.007337,10.528045,0.536324,0.073367,-128.994751,0.008299,0.000000
20.110001,2.697098,-128.950272,-0.004303,0.000315,0.007996,11.997290,0.611171,0.079958,-128.950272,0.008967,0.000000
20.510000,3.011749,-129.039246,-0.004264,0.000340,0.008638,13.396930,0.682472,0.086376,-129.039246,0.009635,0.000000
20.910002,3.214325,-129.083725,-0.004234,0.000362,0.009184,14.298032,0.728376,0.091839,-129.083725,0.010303,0.000000
21.310001,3.543129,-129.039246,-0.004230,0.000389,0.009886,15.760625,0.802885,0.098864,-129.039246,0.010970,0.000000
21.710001,3.616859,-129.083725,-0.004208,0.000412,0.010476,16.088594,0.819592,0.104761,-129.083725,0.011638,0.000000
22.110001,4.015297,-129.128204,-0.004182,0.000439,0.011144,17.860933,0.909879,0.111439,-129.128204,0.012297,0.000000
22.510000,4.290482,-129.172684,-0.004143,0.000470,0.011950,19.085014,0.972237,0.119504,-129.172684,0.012965,0.000000
22.910002,4.389900,-129.172684,-0.004126,0.000492,0.012497,19.527252,0.994766,0.124967,-129.172684,0.013633,0.000000
23.310001,4.683701,-129.172684,-0.004092,0.000517,0.013138,20.834141,1.061342,0.131385,-129.172684,0.014301,0.000000
23.710001,4.841217,-129.217163,-0.004066,0.000542,0.013754,21.534809,1.097035,0.137542,-129.217163,0.014968,0.000000
24.110001,5.097038,-129.261642,-0.004040,0.000572,0.014535,22.672758,1.155005,0.145347,-129.261642,0.015636,0.000000
24.510000,5.325302,-129.306122,-0.003992,0.000602,0.015281,23.688128,1.206731,0.152805,-129.306122,0.016304,0.000000
24.910002,5.462334,-129.306122,-0.003975,0.000628,0.015948,24.297674,1.237782,0.159483,-129.306122,0.016972,0.000000
25.310001,5.533829,-129.350601,-0.003954,0.000652,0.016555,24.615700,1.253983,0.165553,-129.350601,0.017631,0.000000
25.710001,5.523407,-129.306122,-0.003919,0.000670,0.017015,24.569342,1.251622,0.170150,-129.306122,0.018298,0.000000
26.110001,5.881996,-129.350601,-0.003902,0.000700,0.017787,26.164425,1.332879,0.177868,-129.350601,0.018966,0.000000
26.510002,6.051804,-129.395081,-0.003876,0.000727,0.018455,26.919767,1.371358,0.184546,-129.395081,0.019634,0.000000
26.910002,6.082336,-129.439575,-0.003842,0.000750,0.019044,27.055584,1.378277,0.190443,-129.439575,0.020302,0.000000
27.310001,6.341133,-129.439575,-0.003807,0.000782,0.019868,28.206768,1.436921,0.198681,-129.439575,0.020970,0.000000
27.710001,6.377251,-129.395081,-0.003781,0.000805,0.020441,28.367428,1.445106,0.204405,-129.395081,0.021637,0.000000
28.110001,6.347466,-129.439575,-0.003773,0.000822,0.020883,28.234938,1.438356,0.208828,-129.439575,0.022305,0.000000
28.510002,6.723557,-129.528534,-0.003721,0.000862,0.021906,29.907873,1.523580,0.219061,-129.528534,0.022964,0.000000
28.910002,6.760796,-129.528534,-0.003691,0.000886,0.022513,30.073521,1.532018,0.225132,-129.528534,0.023632,0.000000
29.310001,6.768242,-129.573013,-0.003673,0.000914,0.023207,30.106644,1.533705,0.232070,-129.573013,0.024300,0.000000
29.710001,7.012894,-129.573013,-0.003630,0.000940,0.023866,31.194908,1.589144,0.238661,-129.573013,0.024967,0.000000
30.110001,7.171150,-129.573013,-0.003587,0.000969,0.024612,31.898869,1.625006,0.246119,-129.573013,0.025635,0.000000
30.510002,7.219559,-129.617493,-0.003566,0.000998,0.025340,32.114201,1.635975,0.253403,-129.617493,0.026303,0.000000
30.910002,7.149551,-129.617493,-0.003548,0.001022,0.025947,31.802794,1.620111,0.259474,-129.617493,0.026971,0.000000
31.310001,7.117905,-129.706451,-0.003518,0.001042,0.026468,31.662022,1.612940,0.264677,-129.706451,0.027638,0.000000
31.710001,7.162590,-129.706451,-0.003484,0.001065,0.027040,31.860792,1.623066,0.270401,-129.706451,0.028306,0.000000
32.110001,7.605339,-129.750931,-0.003441,0.001101,0.027977,33.830238,1.723395,0.279767,-129.750931,0.028965,0.000000
32.510002,7.498840,-129.706451,-0.003415,0.001124,0.028558,33.356506,1.699262,0.285577,-129.706451,0.029633,0.000000
32.910000,7.457504,-129.750931,-0.003380,0.001145,0.029087,33.172634,1.689895,0.290868,-129.750931,0.030301,0.000000
33.310001,7.509636,-129.750931,-0.003354,0.001171,0.029746,33.404530,1.701708,0.297458,-129.750931,0.030969,0.000000
33.710003,7.456764,-129.795410,-0.003324,0.001192,0.030284,33.169342,1.689727,0.302835,-129.795410,0.031636,0.000000
34.110001,7.941216,-129.795410,-0.003294,0.001230,0.031237,35.324291,1.799505,0.312375,-129.795410,0.032304,0.000000
34.510002,7.811256,-129.795410,-0.003268,0.001255,0.031879,34.746204,1.770056,0.318792,-129.795410,0.032972,0.000000
34.910000,7.910309,-129.839890,-0.003225,0.001280,0.032504,35.186810,1.792502,0.325036,-129.839890,0.033640,0.000000
35.310001,7.896164,-129.839890,-0.003191,0.001304,0.033111,35.123890,1.789296,0.331107,-129.839890,0.034299,0.000000
35.710003,7.928932,-129.884384,-0.003165,0.001326,0.033674,35.269653,1.796722,0.336744,-129.884384,0.034967,0.000000
36.110001,8.136337,-129.884384,-0.003139,0.001360,0.034542,36.192234,1.843720,0.345416,-129.884384,0.035634,0.000000
36.510002,8.143791,-129.973343,-0.003117,0.001380,0.035053,36.225391,1.845409,0.350533,-129.973343,0.036302,0.000000
36.910000,8.291992,-129.973343,-0.003074,0.001405,0.035695,36.884624,1.878992,0.356950,-129.973343,0.036970,0.000000
37.310001,8.341888,-129.973343,-0.003031,0.001432,0.036363,37.106571,1.890299,0.363628,-129.973343,0.037638,0.000000
37.710003,8.772728,-130.017822,-0.003009,0.001462,0.037143,39.023045,1.987929,0.371433,-130.017822,0.038305,0.000000
38.110001,8.692665,-130.062302,-0.002971,0.001489,0.037828,38.666904,1.969786,0.378284,-130.062302,0.038973,0.000000
38.510002,8.590637,-130.106781,-0.002949,0.001513,0.038418,38.213062,1.946666,0.384181,-130.106781,0.039632,0.000000
38.910004,8.938431,-130.062302,-0.002902,0.001546,0.039268,39.760124,2.025477,0.392680,-130.062302,0.040300,0.000000
39.310001,8.927635,-130.106781,-0.002880,0.001571,0.039892,39.712105,2.023031,0.398924,-130.106781,0.040968,0.000000
39.710003,9.125732,-130.106781,-0.002863,0.001594,0.040491,40.593285,2.067920,0.404908,-130.106781,0.041636,0.000000
40.110001,9.287720,-130.151260,-0.002824,0.001624,0.041254,41.313839,2.104627,0.412539,-130.151260,0.042303,0.000000
40.510002,9.120895,-130.151260,-0.002785,0.001644,0.041748,40.571770,2.066824,0.417482,-130.151260,0.042971,0.000000
40.910004,9.648918,-130.195740,-0.002751,0.001681,0.042702,42.920532,2.186476,0.427022,-130.195740,0.043639,0.000000
41.310001,9.467201,-130.240219,-0.002729,0.001706,0.043327,42.112213,2.145298,0.433266,-130.240219,0.044307,0.000000
41.710003,9.598648,-130.240219,-0.002699,0.001728,0.043890,42.696918,2.175085,0.438903,-130.240219,0.044966,0.000000
42.110001,9.736053,-130.240219,-0.002669,0.001753,0.044523,43.308128,2.206221,0.445234,-130.240219,0.045633,0.000000
42.510002,9.847389,-130.195740,-0.002639,0.001774,0.045070,43.803375,2.231450,0.450697,-130.195740,0.046301,0.000000
42.910004,10.111778,-130.240219,-0.002621,0.001805,0.045859,44.979435,2.291362,0.458589,-130.240219,0.046969,0.000000
43.310001,9.969902,-130.329193,-0.002583,0.001828,0.046423,44.348339,2.259212,0.464226,-130.329193,0.047637,0.000000
43.710003,10.513191,-130.373672,-0.002548,0.001860,0.047238,46.765011,2.382323,0.472378,-130.373672,0.048304,0.000000
44.110001,10.350464,-130.329193,-0.002531,0.001881,0.047784,46.041164,2.345449,0.477841,-130.329193,0.048972,0.000000
44.510002,10.526596,-130.329193,-0.002501,0.001903,0.048348,46.824638,2.385361,0.483478,-130.329193,0.049640,0.000000
44.910004,10.789864,-130.373672,-0.002471,0.001932,0.049076,47.995708,2.445018,0.490763,-130.373672,0.050308,0.000000
45.310001,10.987595,-130.418152,-0.002458,0.001962,0.049822,48.875263,2.489825,0.498221,-130.418152,0.050967,0.000000
45.710003,11.537964,-130.418152,-0.002410,0.001995,0.050663,51.323425,2.614540,0.506633,-130.418152,0.051635,0.000000
46.110001,11.301880,-130.462631,-0.002380,0.002014,0.051149,50.273273,2.561043,0.511490,-130.462631,0.052302,0.000000
46.510002,11.700691,-130.507111,-0.002358,0.002047,0.051982,52.047276,2.651415,0.519815,-130.507111,0.052970,0.000000
46.910004,11.397209,-130.462631,-0.002324,0.002062,0.052372,50.697319,2.582645,0.523718,-130.462631,0.053638,0.000000
47.310001,11.669411,-130.507111,-0.002302,0.002086,0.052979,51.908131,2.644326,0.529788,-130.507111,0.054306,0.000000
47.710003,12.488632,-130.507111,-0.002276,0.002123,0.053933,55.552212,2.829964,0.539328,-130.507111,0.054973,0.000000
48.110001,12.335213,-130.596069,-0.002233,0.002143,0.054436,54.869766,2.795199,0.544358,-130.596069,0.055641,0.000000
48.510002,12.640556,-130.507111,-0.002220,0.002169,0.055095,56.228004,2.864391,0.550949,-130.507111,0.056300,0.000000
48.910004,12.821907,-130.596069,-0.002173,0.002197,0.055797,57.034691,2.905486,0.557973,-130.596069,0.056968,0.000000
49.310001,12.626411,-130.596069,-0.002169,0.002214,0.056231,56.165085,2.861186,0.562309,-130.596069,0.057636,0.000000
49.710003,13.638519,-130.685028,-0.002134,0.002254,0.057254,60.667164,3.090533,0.572542,-130.685028,0.058304,0.000000
50.110001,13.558083,-130.640549,-0.002100,0.002280,0.057922,60.309364,3.072305,0.579220,-130.640549,0.058971,0.000000
50.510002,13.677612,-130.640549,-0.002061,0.002302,0.058460,60.841057,3.099391,0.584597,-130.640549,0.059639,0.000000
50.910004,13.689156,-130.729523,-0.002052,0.002322,0.058989,60.892406,3.102007,0.589887,-130.729523,0.060307,0.000000
51.310001,14.501678,-130.685028,-0.002031,0.002359,0.059925,64.506691,3.286127,0.599253,-130.685028,0.060975,0.000000
51.710003,14.498322,-130.774002,-0.001983,0.002384,0.060558,64.491753,3.285367,0.605584,-130.774002,0.061634,0.000000
52.110001,15.053162,-130.729523,-0.001979,0.002412,0.061269,66.959808,3.411095,0.612695,-130.729523,0.062301,0.000000
52.510002,15.266899,-130.818481,-0.001927,0.002437,0.061911,67.910561,3.459529,0.619112,-130.818481,0.062969,0.000000
52.910004,15.523468,-130.818481,-0.001932,0.002460,0.062492,69.051834,3.517668,0.624923,-130.818481,0.063637,0.000000
53.310001,16.270073,-130.818481,-0.001893,0.002490,0.063255,72.372902,3.686851,0.632554,-130.818481,0.064305,0.000000
53.710003,16.265976,-130.862961,-0.001867,0.002514,0.063854,72.354675,3.685923,0.638538,-130.862961,0.064973,0.000000
54.110004,16.441360,-130.862961,-0.001832,0.002540,0.064513,73.134827,3.725665,0.645129,-130.862961,0.065640,0.000000
54.510002,17.003647,-130.951920,-0.001811,0.002565,0.065146,75.636002,3.853081,0.651460,-130.951920,0.066308,0.000000
54.910004,17.152222,-130.907440,-0.001781,0.002587,0.065701,76.296890,3.886749,0.657010,-130.907440,0.066967,0.000000
55.310001,18.133797,-130.907440,-0.001763,0.002620,0.066542,80.663155,4.109177,0.665422,-130.907440,0.067635,0.000000
55.710003,18.572823,-130.951920,-0.001733,0.002649,0.067288,82.616043,4.208662,0.672880,-130.951920,0.068303,0.000000
56.110004,18.490906,-130.996399,-0.001712,0.002667,0.067748,82.251656,4.190099,0.677477,-130.996399,0.068970,0.000000
56.510002,19.077759,-130.996399,-0.001686,0.002700,0.068572,84.862106,4.323082,0.685715,-130.996399,0.069638,0.000000
56.910004,19.246071,-131.040878,-0.001664,0.002720,0.069101,85.610802,4.361222,0.691005,-131.040878,0.070306,0.000000
57.310001,20.439156,-131.085358,-0.001634,0.002750,0.069846,90.917908,4.631579,0.698464,-131.085358,0.070974,0.000000
57.710003,20.726257,-131.085358,-0.001608,0.002778,0.070549,92.195000,4.696637,0.705488,-131.085358,0.071642,0.000000
58.110004,20.955261,-131.040878,-0.001587,0.002799,0.071086,93.213661,4.748530,0.710865,-131.040878,0.072309,0.000000
58.510002,21.597603,-131.085358,-0.001561,0.002822,0.071685,96.070938,4.894087,0.716849,-131.085358,0.072968,0.000000
58.910004,21.744690,-131.129837,-0.001544,0.002841,0.072171,96.725212,4.927417,0.721705,-131.129837,0.073636,0.000000
59.310001,23.250565,-131.174332,-0.001531,0.002884,0.073246,103.423676,5.268653,0.732459,-131.174332,0.074304,0.000000
59.710003,23.609535,-131.174332,-0.001496,0.002907,0.073836,105.020454,5.349998,0.738356,-131.174332,0.074972,0.000000
60.110004,24.505836,-131.218811,-0.001462,0.002936,0.074573,109.007408,5.553102,0.745727,-131.218811,0.075639,0.000000
60.510002,24.414978,-131.174332,-0.001453,0.002955,0.075067,108.603249,5.532513,0.750671,-131.174332,0.076307,0.000000
60.910004,25.020081,-131.218811,-0.001431,0.002978,0.075631,111.294876,5.669631,0.756308,-131.218811,0.076975,0.000000
61.310001,26.656654,-131.263290,-0.001406,0.003014,0.076567,118.574722,6.040484,0.765674,-131.263290,0.077643,0.000000
61.710003,27.334373,-131.263290,-0.001388,0.003040,0.077218,121.589363,6.194057,0.772178,-131.263290,0.078302,0.000000
62.110004,28.073532,-131.307770,-0.001362,0.003069,0.077955,124.877304,6.361553,0.779549,-131.307770,0.078970,0.000000
62.510002,29.157509,-131.307770,-0.001328,0.003098,0.078692,129.699081,6.607186,0.786921,-131.307770,0.079637,0.000000
62.910004,29.474770,-131.352249,-0.001332,0.003120,0.079256,131.110321,6.679079,0.792558,-131.352249,0.080305,0.000000
63.310001,30.514809,-131.352249,-0.001293,0.003146,0.079906,135.736649,6.914754,0.799062,-131.352249,0.080973,0.000000
63.710003,30.597847,-131.441208,-0.001285,0.003164,0.080374,136.106018,6.933571,0.803745,-131.441208,0.081641,0.000000
64.110001,32.053078,-131.396729,-0.001250,0.003198,0.081224,142.579208,7.263331,0.812244,-131.396729,0.082308,0.000000
64.510002,32.927040,-131.485687,-0.001242,0.003221,0.081814,146.466797,7.461374,0.818141,-131.485687,0.082976,0.000000
64.910004,33.961487,-131.485687,-0.001216,0.003248,0.082508,151.068237,7.695783,0.825079,-131.485687,0.083635,0.000000
65.310005,35.425659,-131.485687,-0.001203,0.003275,0.083193,157.581207,8.027569,0.831930,-131.485687,0.084303,0.000000
65.710007,36.195351,-131.485687,-0.001181,0.003301,0.083852,161.004959,8.201983,0.838521,-131.485687,0.084971,0.000000
66.110001,36.988129,-131.485687,-0.001173,0.003321,0.084364,164.531418,8.381630,0.843637,-131.485687,0.085639,0.000000
66.510002,38.093704,-131.619141,-0.001143,0.003349,0.085057,169.449265,8.632156,0.850575,-131.619141,0.086306,0.000000
66.910004,39.741081,-131.574646,-0.001130,0.003382,0.085907,176.777161,9.005457,0.859074,-131.574646,0.086974,0.000000
67.310005,40.814262,-131.619141,-0.001108,0.003406,0.086523,181.550903,9.248645,0.865231,-131.619141,0.087642,0.000000
67.710007,42.157036,-131.663620,-0.001082,0.003436,0.087278,187.523865,9.552921,0.872776,-131.663620,0.088310,0.000000
68.110001,43.220901,-131.708099,-0.001087,0.003460,0.087885,192.256165,9.793997,0.878847,-131.708099,0.088969,0.000000
68.510002,43.261490,-131.663620,-0.001043,0.003472,0.088197,192.436722,9.803194,0.881969,-131.663620,0.089636,0.000000
68.910004,45.580254,-131.708099,-0.001048,0.003509,0.089125,202.751099,10.328633,0.891248,-131.708099,0.090304,0.000000
69.310005,46.856743,-131.708099,-0.001013,0.003537,0.089845,208.429199,10.617889,0.898446,-131.708099,0.090972,0.000000
69.710007,47.166931,-131.708099,-0.001013,0.003548,0.090113,209.808990,10.688179,0.901134,-131.708099,0.091640,0.000000
70.110001,49.590332,-131.752579,-0.000992,0.003585,0.091067,220.588821,11.237329,0.910674,-131.752579,0.092308,0.000000
70.510002,50.924545,-131.752579,-0.000983,0.003612,0.091752,226.523697,11.539667,0.917525,-131.752579,0.092975,0.000000
70.910004,52.778961,-131.841537,-0.000957,0.003643,0.092524,234.772537,11.959884,0.925243,-131.841537,0.093643,0.000000
71.310005,54.149292,-131.841537,-0.000940,0.003669,0.093183,240.868088,12.270405,0.931834,-131.841537,0.094302,0.000000
71.710007,55.359131,-131.841537,-0.000944,0.003690,0.093738,246.249710,12.544559,0.937384,-131.841537,0.094970,0.000000
72.110001,56.902237,-131.930496,-0.000931,0.003717,0.094424,253.113785,12.894231,0.944235,-131.930496,0.095638,0.000000
72.510002,58.554459,-131.886017,-0.000910,0.003745,0.095126,260.463226,13.268630,0.951260,-131.886017,0.096305,0.000000
72.910004,60.598778,-131.886017,-0.000892,0.003774,0.095872,269.556824,13.731879,0.958718,-131.886017,0.096973,0.000000
73.310005,62.090134,-131.974976,-0.000871,0.003800,0.096514,276.190704,14.069825,0.965136,-131.974976,0.097641,0.000000
73.710007,63.650749,-132.019470,-0.000867,0.003825,0.097155,283.132660,14.423466,0.971553,-132.019470,0.098309,0.000000
74.110001,64.545555,-131.974976,-0.000854,0.003844,0.097632,287.112976,14.626232,0.976323,-131.974976,0.098976,0.000000
74.510002,66.285652,-132.019470,-0.000836,0.003876,0.098439,294.853302,15.020544,0.984388,-132.019470,0.099644,0.000000
74.910004,65.606071,-132.019470,-0.000832,0.003866,0.098196,291.830383,14.866549,0.981960,-132.019470,294.500488,0.000000
75.310005,64.820732,-132.063950,-0.000811,0.003867,0.098222,288.337006,14.688588,0.982220,-132.063950,294.500488,0.000000
75.710007,66.003395,-132.063950,-0.000815,0.003874,0.098404,293.597778,14.956583,0.984041,-132.063950,294.500488,0.000000
76.110001,65.332008,-132.108429,-0.000811,0.003874,0.098404,290.611298,14.804445,0.984041,-132.108429,294.500488,0.000000
76.510002,64.841225,-132.152908,-0.000802,0.003875,0.098430,288.428162,14.693232,0.984301,-132.152908,294.500488,0.000000
76.910004,65.846992,-132.152908,-0.000789,0.003889,0.098777,292.902039,14.921142,0.987770,-132.152908,294.500488,0.000000
77.310005,65.387856,-132.108429,-0.000798,0.003889,0.098777,290.859711,14.817100,0.987770,-132.108429,294.500488,0.000000
77.710007,65.022194,-132.197388,-0.000785,0.003889,0.098777,289.233154,14.734240,0.987770,-132.197388,294.500488,0.000000
78.110001,66.184364,-132.197388,-0.000793,0.003904,0.099167,294.402771,14.997591,0.991673,-132.197388,294.500488,0.000000
78.510002,65.846992,-132.241867,-0.000793,0.003904,0.099159,292.902039,14.921142,0.991586,-132.241867,294.500488,0.000000
78.910004,65.552818,-132.241867,-0.000785,0.003904,0.099159,291.593506,14.854481,0.991586,-132.241867,294.500488,0.000000
79.310005,65.298119,-132.241867,-0.000767,0.003906,0.099202,290.460541,14.796765,0.992019,-132.241867,294.500488,0.000000
79.710007,65.098900,-132.286346,-0.000780,0.003909,0.099297,289.574371,14.751621,0.992973,-132.286346,294.500488,0.000000
80.110001,65.040062,-132.330826,-0.000772,0.003912,0.099358,289.312653,14.738289,0.993580,-132.330826,294.500488,0.000000
80.510002,65.186043,-132.330826,-0.000776,0.003915,0.099445,289.962006,14.771369,0.994448,-132.330826,294.500488,0.000000
80.910004,65.140984,-132.375305,-0.000772,0.003917,0.099479,289.761566,14.761158,0.994795,-132.375305,294.500488,0.000000
81.310005,65.038948,-132.419785,-0.000780,0.003917,0.099488,289.307678,14.738036,0.994881,-132.419785,294.500488,0.000000
81.710007,65.264610,-132.375305,-0.000763,0.003921,0.099601,290.311493,14.789172,0.996009,-132.375305,294.500488,0.000000
82.110001,65.172630,-132.419785,-0.000767,0.003921,0.099601,289.902344,14.768330,0.996009,-132.419785,294.500488,0.000000
82.510002,65.051613,-132.419785,-0.000776,0.003923,0.099636,289.364014,14.740906,0.996356,-132.419785,294.500488,0.000000
82.910004,65.290306,-132.419785,-0.000772,0.003925,0.099705,290.425781,14.794995,0.997049,-132.419785,294.500488,0.000000
83.310005,65.226997,-132.464279,-0.000763,0.003925,0.099705,290.144165,14.780648,0.997049,-132.464279,294.500488,0.000000
83.710007,65.100761,-132.464279,-0.000772,0.003925,0.099705,289.582642,14.752044,0.997049,-132.464279,294.500488,0.000000
84.110001,65.015495,-132.508759,-0.000767,0.003925,0.099705,289.203369,14.732721,0.997049,-132.508759,294.500488,0.000000
84.510002,65.318977,-132.553238,-0.000755,0.003931,0.099844,290.553314,14.801492,0.998437,-132.553238,294.500488,0.000000
84.910004,65.273918,-132.508759,-0.000759,0.003931,0.099844,290.352875,14.791282,0.998437,-132.508759,294.500488,0.000000
85.310005,65.223274,-132.597717,-0.000750,0.003931,0.099844,290.127625,14.779805,0.998437,-132.597717,294.500488,0.000000
85.710007,65.145821,-132.642197,-0.000755,0.003931,0.099844,289.783081,14.762254,0.998437,-132.642197,294.500488,0.000000
86.110001,65.118263,-132.597717,-0.000746,0.003934,0.099913,289.660492,14.756009,0.999131,-132.597717,294.500488,0.000000
86.510002,65.194969,-132.642197,-0.000763,0.003934,0.099913,290.001709,14.773392,0.999131,-132.642197,294.500488,0.000000
86.910004,65.138374,-132.642197,-0.000767,0.003934,0.099913,289.749969,14.760567,0.999131,-132.642197,294.500488,0.000000
87.310005,65.065758,-132.642197,-0.000755,0.003934,0.099913,289.426941,14.744112,0.999131,-132.642197,294.500488,0.000000
87.710007,65.006187,-132.686676,-0.000755,0.003934,0.099913,289.161957,14.730613,0.999131,-132.686676,294.500488,0.000000
88.110001,65.211723,-132.731155,-0.000746,0.003938,0.100026,290.076233,14.777188,1.000258,-132.731155,294.500488,0.000000
88.510002,65.219185,-132.731155,-0.000759,0.003938,0.100026,290.109436,14.778878,1.000258,-132.731155,294.500488,0.000000
88.910004,65.176353,-132.820114,-0.000759,0.003938,0.100026,289.918915,14.769173,1.000258,-132.820114,294.500488,0.000000
89.310005,65.105598,-132.820114,-0.000750,0.003938,0.100026,289.604156,14.753139,1.000258,-132.820114,294.500488,0.000000
89.710007,65.066505,-132.820114,-0.000750,0.003938,0.100026,289.430267,14.744281,1.000258,-132.820114,294.500488,0.000000
90.110001,65.003944,-132.820114,-0.000772,0.003938,0.100026,289.151978,14.730104,1.000258,-132.820114,294.500488,0.000000
90.510002,64.963737,-132.864594,-0.000755,0.003938,0.100026,288.973145,14.720993,1.000258,-132.864594,294.500488,0.000000
90.910004,64.898186,-132.820114,-0.000755,0.003938,0.100034,288.681549,14.706140,1.000345,-132.820114,294.500488,0.000000
91.310005,65.161095,-132.864594,-0.000750,0.003945,0.100199,289.851013,14.765716,1.001992,-132.864594,294.500488,0.000000
91.710007,65.336479,-132.864594,-0.000750,0.003945,0.100199,290.631165,14.805458,1.001992,-132.864594,294.500488,0.000000
92.110001,65.337959,-132.953568,-0.000737,0.003945,0.100199,290.637756,14.805793,1.001992,-132.953568,294.500488,0.000000
92.510002,65.314873,-132.953568,-0.000746,0.003945,0.100199,290.535065,14.800561,1.001992,-132.953568,294.500488,0.000000
92.910004,65.277641,-132.998047,-0.000750,0.003945,0.100199,290.369446,14.792125,1.001992,-132.998047,294.500488,0.000000
93.310005,65.259773,-132.998047,-0.000742,0.003945,0.100199,290.289978,14.788075,1.001992,-132.998047,294.500488,0.000000
93.710007,65.219185,-133.042526,-0.000737,0.003945,0.100199,290.109436,14.778878,1.001992,-133.042526,294.500488,0.000000
94.110008,65.155876,-133.042526,-0.000750,0.003945,0.100199,289.827820,14.764533,1.001992,-133.042526,294.500488,0.000000
94.510002,65.109322,-133.087006,-0.000750,0.003945,0.100208,289.620728,14.753983,1.002079,-133.087006,294.500488,0.000000
94.910004,65.075447,-133.087006,-0.000737,0.003945,0.100208,289.470032,14.746306,1.002079,-133.087006,294.500488,0.000000
95.310005,65.024803,-133.131485,-0.000746,0.003945,0.100208,289.244781,14.734831,1.002079,-133.131485,294.500488,0.000000
95.710007,64.983833,-133.131485,-0.000750,0.003945,0.100208,289.062531,14.725547,1.002079,-133.131485,294.500488,0.000000
96.110008,64.971184,-133.175964,-0.000737,0.003946,0.100217,289.006256,14.722681,1.002166,-133.175964,294.500488,0.000000
96.510002,64.926872,-133.131485,-0.000759,0.003946,0.100225,288.809143,14.712640,1.002253,-133.131485,294.500488,0.000000
96.910004,65.340950,-133.220444,-0.000737,0.003951,0.100364,290.651062,14.806471,1.003640,-133.220444,294.500488,0.000000
97.310005,65.354347,-133.175964,-0.000742,0.003951,0.100364,290.710663,14.809507,1.003640,-133.175964,294.500488,0.000000
97.710007,65.341316,-133.220444,-0.000733,0.003951,0.100364,290.652679,14.806554,1.003640,-133.220444,294.500488,0.000000
98.110008,65.309669,-133.309418,-0.000746,0.003951,0.100364,290.511932,14.799383,1.003640,-133.309418,294.500488,0.000000
98.510002,65.300728,-133.220444,-0.000742,0.003951,0.100364,290.472137,14.797357,1.003640,-133.220444,294.500488,0.000000
98.910004,65.267220,-133.264923,-0.000742,0.003951,0.100364,290.323090,14.789763,1.003640,-133.264923,294.500488,0.000000
99.310005,65.232948,-133.309418,-0.000746,0.003951,0.100364,290.170654,14.781998,1.003640,-133.309418,294.500488,0.000000
99.710007,65.202049,-133.353897,-0.000729,0.003951,0.100364,290.033203,14.774996,1.003640,-133.353897,294.500488,0.000000
100.110008,65.159233,-133.353897,-0.000737,0.003951,0.100364,289.842743,14.765293,1.003640,-133.353897,294.500488,0.000000
100.510002,65.120872,-133.353897,-0.000742,0.003951,0.100364,289.672119,14.756600,1.003640,-133.353897,294.500488,0.000000
100.910004,65.077675,-133.398376,-0.000746,0.003951,0.100364,289.479950,14.746812,1.003640,-133.398376,294.500488,0.000000
101.310005,65.041176,-133.353897,-0.000737,0.003951,0.100364,289.317596,14.738542,1.003640,-133.353897,294.500488,0.000000
101.710007,65.023308,-133.353897,-0.000737,0.003951,0.100364,289.238129,14.734492,1.003640,-133.353897,294.500488,0.000000
102.110008,64.992409,-133.353897,-0.000742,0.003952,0.100373,289.100677,14.727489,1.003727,-133.353897,294.500488,0.000000
102.510002,64.959267,-133.398376,-0.000733,0.003952,0.100381,288.953247,14.719980,1.003814,-133.398376,294.500488,0.000000
102.910004,64.948097,-133.487335,-0.000733,0.003952,0.100381,288.903564,14.717449,1.003814,-133.487335,294.500488,0.000000
103.310005,65.730446,-133.487335,-0.000733,0.003962,0.100624,292.383636,14.894732,1.006242,-133.487335,294.500488,0.000000
103.710007,65.791512,-133.487335,-0.000737,0.003962,0.100624,292.655273,14.908570,1.006242,-133.487335,294.500488,0.000000
104.110008,65.797096,-133.531815,-0.000729,0.003962,0.100624,292.680115,14.909836,1.006242,-133.531815,294.500488,0.000000
104.510002,65.802315,-133.531815,-0.000742,0.003962,0.100624,292.703308,14.911017,1.006242,-133.531815,294.500488,0.000000
104.910004,65.792625,-133.576294,-0.000729,0.003962,0.100624,292.660217,14.908822,1.006242,-133.576294,294.500488,0.000000
105.310005,65.768425,-133.531815,-0.000733,0.003962,0.100624,292.552551,14.903338,1.006242,-133.531815,294.500488,0.000000
105.710007,65.759865,-133.576294,-0.000724,0.003962,0.100624,292.514496,14.901399,1.006242,-133.576294,294.500488,0.000000
106.110008,65.760231,-133.665253,-0.000733,0.003962,0.100624,292.516113,14.901482,1.006242,-133.665253,294.500488,0.000000
106.510002,65.694695,-133.665253,-0.000742,0.003962,0.100624,292.224609,14.886631,1.006242,-133.665253,294.500488,0.000000
106.910004,65.644798,-133.709732,-0.000733,0.003962,0.100624,292.002655,14.875324,1.006242,-133.709732,294.500488,0.000000
107.310005,65.639214,-133.709732,-0.000737,0.003962,0.100624,291.977814,14.874058,1.006242,-133.709732,294.500488,0.000000
107.710007,65.596016,-133.709732,-0.000733,0.003962,0.100624,291.785645,14.864270,1.006242,-133.709732,294.500488,0.000000
108.110008,65.582619,-133.754227,-0.000729,0.003962,0.100624,291.726044,14.861234,1.006242,-133.754227,294.500488,0.000000
108.510002,65.564369,-133.798706,-0.000737,0.003962,0.100624,291.644867,14.857099,1.006242,-133.798706,294.500488,0.000000
108.910004,65.556541,-133.798706,-0.000746,0.003962,0.100624,291.610046,14.855325,1.006242,-133.798706,294.500488,0.000000
109.310005,65.524147,-133.798706,-0.000746,0.003962,0.100624,291.465973,14.847984,1.006242,-133.798706,294.500488,0.000000
109.710007,65.501442,-133.843185,-0.000724,0.003962,0.100624,291.364960,14.842839,1.006242,-133.843185,294.500488,0.000000
110.110008,65.485054,-133.843185,-0.000720,0.003962,0.100624,291.292053,14.839126,1.006242,-133.843185,294.500488,0.000000
110.510002,65.444832,-133.887665,-0.000733,0.003962,0.100624,291.113159,14.830010,1.006242,-133.887665,294.500488,0.000000
110.910004,65.410210,-133.887665,-0.000742,0.003962,0.100624,290.959137,14.822165,1.006242,-133.887665,294.500488,0.000000
111.310005,65.366631,-133.887665,-0.000724,0.003962,0.100624,290.765289,14.812291,1.006242,-133.887665,294.500488,0.000000
111.710007,65.350990,-133.976624,-0.000733,0.003962,0.100624,290.695709,14.808746,1.006242,-133.976624,294.500488,0.000000
112.110008,65.333870,-133.976624,-0.000729,0.003962,0.100624,290.619568,14.804866,1.006242,-133.976624,294.500488,0.000000
112.510002,65.312263,-133.976624,-0.000724,0.003962,0.100624,290.523468,14.799971,1.006242,-133.976624,294.500488,0.000000
112.910004,65.282112,-134.021103,-0.000733,0.003962,0.100624,290.389343,14.793138,1.006242,-134.021103,294.500488,0.000000
113.310005,65.264229,-134.021103,-0.000733,0.003962,0.100624,290.309784,14.789085,1.006242,-134.021103,294.500488,0.000000
113.710007,65.238167,-134.065582,-0.000733,0.003962,0.100624,290.193848,14.783179,1.006242,-134.065582,294.500488,0.000000
114.110008,65.226997,-134.065582,-0.000724,0.003962,0.100624,290.144165,14.780648,1.006242,-134.065582,294.500488,0.000000
114.510002,65.212852,-134.065582,-0.000711,0.003962,0.100624,290.081268,14.777444,1.006242,-134.065582,294.500488,0.000000
114.910004,65.174858,-134.110062,-0.000729,0.003962,0.100633,289.912262,14.768834,1.006329,-134.110062,294.500488,0.000000
115.310005,65.135399,-134.110062,-0.000720,0.003962,0.100633,289.736725,14.759892,1.006329,-134.110062,294.500488,0.000000
115.710007,65.134651,-134.199036,-0.000729,0.003962,0.100633,289.733398,14.759723,1.006329,-134.199036,294.500488,0.000000
116.110008,65.080650,-134.154541,-0.000720,0.003962,0.100633,289.493195,14.747486,1.006329,-134.154541,294.500488,0.000000
116.510002,65.030754,-134.199036,-0.000729,0.003962,0.100633,289.271240,14.736180,1.006329,-134.199036,294.500488,0.000000
116.910004,65.015114,-134.154541,-0.000729,0.003962,0.100633,289.201660,14.732635,1.006329,-134.154541,294.500488,0.000000
117.310005,64.993523,-134.243515,-0.000720,0.003962,0.100633,289.105621,14.727742,1.006329,-134.243515,294.500488,0.000000
117.710007,64.987938,-134.287994,-0.000724,0.003962,0.100633,289.080780,14.726477,1.006329,-134.287994,294.500488,0.000000
118.110008,64.962242,-134.287994,-0.000733,0.003962,0.100633,288.966492,14.720654,1.006329,-134.287994,294.500488,0.000000
118.510002,64.944374,-134.243515,-0.000707,0.003962,0.100633,288.886993,14.716606,1.006329,-134.243515,294.500488,0.000000
118.910004,64.933571,-134.287994,-0.000729,0.003962,0.100633,288.838959,14.714157,1.006329,-134.287994,294.500488,0.000000
119.310005,64.901176,-134.332474,-0.000720,0.003962,0.100633,288.694855,14.706817,1.006329,-134.332474,294.500488,0.000000
119.710007,64.862816,-134.421432,-0.000729,0.003962,0.100633,288.524200,14.698124,1.006329,-134.421432,294.500488,0.000000
120.110008,64.840096,-134.376953,-0.000729,0.003962,0.100633,288.423157,14.692976,1.006329,-134.376953,294.500488,0.000000
120.510002,64.802498,-134.376953,-0.000720,0.003962,0.100633,288.255920,14.684456,1.006329,-134.376953,294.500488,0.000000
120.910004,64.780891,-134.465912,-0.000724,0.003962,0.100642,288.159790,14.679560,1.006415,-134.465912,294.500488,0.000000
121.310005,64.773445,-134.510391,-0.000724,0.003962,0.100642,288.126678,14.677873,1.006415,-134.510391,294.500488,0.000000
121.710007,64.764503,-134.510391,-0.000720,0.003962,0.100642,288.086914,14.675847,1.006415,-134.510391,294.500488,0.000000
122.110008,64.744026,-134.510391,-0.000729,0.003962,0.100642,287.995819,14.671206,1.006415,-134.510391,294.500488,0.000000
122.510002,64.730247,-134.510391,-0.000720,0.003962,0.100642,287.934509,14.668084,1.006415,-134.510391,294.500488,0.000000
122.910004,64.710884,-134.599365,-0.000729,0.003962,0.100642,287.848389,14.663696,1.006415,-134.599365,294.500488,0.000000
123.310005,64.694878,-134.599365,-0.000716,0.003963,0.100650,287.777191,14.660069,1.006502,-134.599365,294.500488,0.000000
123.710007,65.589684,-134.599365,-0.000724,0.003973,0.100919,291.757477,14.862835,1.009191,-134.599365,294.500488,0.000000
124.110008,65.672722,-134.599365,-0.000729,0.003973,0.100919,292.126862,14.881652,1.009191,-134.599365,294.500488,0.000000
124.510002,65.725227,-134.599365,-0.000733,0.003973,0.100919,292.360413,14.893550,1.009191,-134.599365,294.500488,0.000000
124.910004,65.764336,-134.688324,-0.000711,0.003973,0.100919,292.534363,14.902411,1.009191,-134.688324,294.500488,0.000000
125.310005,65.767677,-134.643845,-0.000724,0.003973,0.100919,292.549225,14.903169,1.009191,-134.643845,294.500488,0.000000
125.710007,65.759117,-134.732803,-0.000724,0.003973,0.100919,292.511169,14.901229,1.009191,-134.732803,294.500488,0.000000
126.110008,65.762840,-134.732803,-0.000716,0.003973,0.100919,292.527710,14.902072,1.009191,-134.732803,294.500488,0.000000
126.510010,65.764336,-134.777283,-0.000711,0.003973,0.100919,292.534363,14.902411,1.009191,-134.777283,294.500488,0.000000
126.910004,65.751305,-134.777283,-0.000724,0.003973,0.100919,292.476410,14.899459,1.009191,-134.777283,294.500488,0.000000
127.310005,65.751305,-134.777283,-0.000707,0.003973,0.100919,292.476410,14.899459,1.009191,-134.777283,294.500488,0.000000
127.710007,65.701775,-134.821762,-0.000707,0.003973,0.100919,292.256104,14.888235,1.009191,-134.821762,294.500488,0.000000
128.110001,65.696190,-134.866241,-0.000720,0.003973,0.100919,292.231262,14.886970,1.009191,-134.866241,294.500488,0.000000
128.510010,65.678307,-134.866241,-0.000716,0.003973,0.100919,292.151703,14.882917,1.009191,-134.866241,294.500488,0.000000
128.910004,65.656349,-134.910721,-0.000707,0.003973,0.100919,292.054016,14.877941,1.009191,-134.910721,294.500488,0.000000
129.310013,65.654488,-134.910721,-0.000711,0.003973,0.100919,292.045746,14.877520,1.009191,-134.910721,294.500488,0.000000
129.710007,65.631020,-134.910721,-0.000707,0.003973,0.100919,291.941345,14.872202,1.009191,-134.910721,294.500488,0.000000
130.110001,65.612404,-134.955200,-0.000711,0.003973,0.100919,291.858551,14.867983,1.009191,-134.955200,294.500488,0.000000
130.510010,65.604576,-134.910721,-0.000716,0.003973,0.100919,291.823730,14.866209,1.009191,-134.910721,294.500488,0.000000
130.910004,65.597130,-134.955200,-0.000720,0.003973,0.100919,291.790619,14.864522,1.009191,-134.955200,294.500488,0.000000
131.310013,65.590813,-134.999680,-0.000720,0.003973,0.100919,291.762512,14.863091,1.009191,-134.999680,294.500488,0.000000
131.710007,65.570320,-134.999680,-0.000707,0.003973,0.100919,291.671356,14.858447,1.009191,-134.999680,294.500488,0.000000
132.110001,65.563988,-134.999680,-0.000716,0.003973,0.100919,291.643188,14.857012,1.009191,-134.999680,294.500488,0.000000
132.510010,65.555428,-135.044174,-0.000716,0.003973,0.100919,291.605103,14.855073,1.009191,-135.044174,294.500488,0.000000
132.910004,65.559532,-135.044174,-0.000703,0.003973,0.100919,291.623352,14.856002,1.009191,-135.044174,294.500488,0.000000
133.310013,65.528984,-135.088654,-0.000711,0.003973,0.100919,291.487488,14.849080,1.009191,-135.088654,294.500488,0.000000
133.710007,65.521172,-135.088654,-0.000716,0.003973,0.100919,291.452728,14.847310,1.009191,-135.088654,294.500488,0.000000
134.110001,65.501060,-135.133133,-0.000716,0.003973,0.100919,291.363281,14.842752,1.009191,-135.133133,294.500488,0.000000
134.510010,65.482811,-135.177612,-0.000703,0.003973,0.100919,291.282104,14.838617,1.009191,-135.177612,294.500488,0.000000
134.910004,65.432167,-135.133133,-0.000694,0.003974,0.100928,291.056824,14.827141,1.009277,-135.133133,294.500488,0.000000
135.310013,65.441856,-135.222092,-0.000716,0.003968,0.100798,291.099915,14.829336,1.007976,-135.222092,0.100876,0.000000
135.710007,65.330513,-135.222092,-0.000707,0.003956,0.100485,290.604645,14.804106,1.004854,-135.222092,0.100208,0.000000
136.110001,65.375572,-135.266571,-0.000703,0.003935,0.099948,290.805084,14.814316,0.999478,-135.266571,0.099540,0.000000
136.510010,65.261253,-135.266571,-0.000703,0.003913,0.099384,290.296539,14.788412,0.993841,-135.266571,0.098872,0.000000
136.910004,65.286583,-135.266571,-0.000716,0.003888,0.098760,290.409210,14.794151,0.987597,-135.266571,0.098205,0.000000
137.310013,65.233696,-135.311050,-0.000703,0.003859,0.098014,290.173981,14.782166,0.980139,-135.311050,0.097537,0.000000
137.710007,65.215080,-135.400009,-0.000698,0.003836,0.097441,290.091156,14.777948,0.974415,-135.400009,0.096869,0.000000
138.110001,65.220299,-135.311050,-0.000711,0.003815,0.096895,290.114380,14.779131,0.968951,-135.311050,0.096201,0.000000
138.510010,65.139122,-135.355530,-0.000698,0.003784,0.096115,289.753296,14.760736,0.961146,-135.355530,0.095542,0.000000
138.910004,65.080284,-135.400009,-0.000707,0.003756,0.095395,289.491577,14.747403,0.953948,-135.400009,0.094874,0.000000
139.310013,64.908623,-135.400009,-0.000707,0.003733,0.094822,288.727966,14.708505,0.948225,-135.400009,0.094207,0.000000
139.710007,64.378365,-135.444489,-0.000707,0.003711,0.094259,286.369263,14.588346,0.942588,-135.444489,0.093539,0.000000
140.110001,63.375191,-135.488983,-0.000698,0.003687,0.093643,281.906921,14.361024,0.936430,-135.488983,0.092871,0.000000
140.510010,62.267006,-135.444489,-0.000703,0.003660,0.092975,276.977478,14.109905,0.929753,-135.444489,0.092203,0.000000
140.910004,61.069458,-135.488983,-0.000707,0.003641,0.092472,271.650513,13.838537,0.924723,-135.488983,0.091536,0.000000
141.310013,59.280579,-135.533463,-0.000694,0.003613,0.091761,263.693176,13.433170,0.917612,-135.533463,0.090868,0.000000
141.710007,57.418716,-135.533463,-0.000703,0.003592,0.091232,255.411209,13.011267,0.912321,-135.533463,0.090200,0.000000
142.110001,55.355400,-135.533463,-0.000686,0.003563,0.090504,246.233124,12.543714,0.905037,-135.533463,0.089541,0.000000
142.510010,52.487762,-135.577942,-0.000707,0.003536,0.089810,233.477234,11.893897,0.898099,-135.577942,0.088873,0.000000
142.910004,50.533180,-135.577942,-0.000703,0.003515,0.089281,224.782806,11.450982,0.892809,-135.577942,0.088206,0.000000
143.310013,47.305084,-135.622421,-0.000711,0.003486,0.088552,210.423523,10.719485,0.885524,-135.622421,0.087538,0.000000
143.710007,44.589745,-135.666901,-0.000698,0.003461,0.087911,198.345093,10.104180,0.879107,-135.666901,0.086870,0.000000
144.110001,42.273956,-135.622421,-0.000698,0.003439,0.087347,188.043945,9.579415,0.873470,-135.622421,0.086202,0.000000
144.510010,38.718178,-135.666901,-0.000707,0.003407,0.086532,172.227051,8.773664,0.865318,-135.666901,0.085534,0.000000
144.910004,36.316002,-135.666901,-0.000720,0.003383,0.085933,161.541641,8.229324,0.859334,-135.666901,0.084867,0.000000
145.310013,33.347443,-135.800339,-0.000729,0.003356,0.085248,148.336838,7.556639,0.852483,-135.800339,0.084208,0.000000
145.710007,30.796326,-135.755859,-0.000729,0.003334,0.084693,136.988892,6.978547,0.846933,-135.755859,0.083540,0.000000
146.110001,27.843033,-135.711380,-0.000724,0.003305,0.083956,123.851997,6.309321,0.839561,-135.711380,0.082872,0.000000
146.510010,24.830917,-135.844818,-0.000737,0.003279,0.083280,110.453438,5.626766,0.832797,-135.844818,0.082204,0.000000
146.910004,22.102173,-135.844818,-0.000737,0.003255,0.082681,98.315376,5.008424,0.826813,-135.844818,0.081537,0.000000
147.310013,19.527588,-135.800339,-0.000729,0.003233,0.082118,86.863052,4.425014,0.821176,-135.800339,0.080869,0.000000
147.710007,16.178467,-135.844818,-0.000742,0.003202,0.081328,71.965416,3.666093,0.813284,-135.844818,0.080201,0.000000
148.110001,13.333168,-135.889313,-0.000759,0.003177,0.080695,59.308895,3.021339,0.806954,-135.889313,0.079533,0.000000
148.510010,10.489738,-135.933792,-0.000759,0.003151,0.080045,46.660686,2.377009,0.800449,-135.933792,0.078874,0.000000
148.910004,8.253639,-135.933792,-0.000776,0.003131,0.079525,36.714020,1.870301,0.795246,-135.933792,0.078206,0.000000
149.310013,4.508316,-136.022751,-0.000767,0.003093,0.078571,20.053991,1.021599,0.785707,-136.022751,0.077539,0.000000
149.710007,1.408691,-135.933792,-0.000772,0.003065,0.077851,6.266172,0.319214,0.778509,-135.933792,0.076871,0.000000
150.110001,-0.968536,-136.022751,-0.000776,0.003038,0.077174,-4.308265,-0.219473,0.771744,-136.022751,0.076203,0.000000
150.510010,-0.318748,-135.933792,-0.000823,0.003017,0.076637,-1.417864,-0.072229,0.766367,-135.933792,0.075535,0.000000
150.910004,-0.142990,-136.067230,-0.000862,0.002988,0.075891,-0.636052,-0.032402,0.758909,-136.067230,0.074868,0.000000
151.310013,-0.049522,-136.022751,-0.000888,0.002965,0.075319,-0.220287,-0.011222,0.753186,-136.022751,0.074200,0.000000
151.710007,-0.081177,-136.111710,-0.000949,0.002933,0.074503,-0.361092,-0.018395,0.745034,-136.111710,0.073541,0.000000
152.110001,-0.042824,-136.156189,-0.000970,0.002909,0.073879,-0.190490,-0.009704,0.738790,-136.156189,0.072873,0.000000
152.510010,-0.031273,-136.111710,-0.001000,0.002889,0.073376,-0.139109,-0.007087,0.733760,-136.111710,0.072205,0.000000
152.910004,-0.072235,-136.156189,-0.001048,0.002855,0.072526,-0.321318,-0.016369,0.725261,-136.156189,0.071537,0.000000
153.310013,-0.058456,-136.245148,-0.001112,0.002833,0.071954,-0.260027,-0.013246,0.719537,-136.245148,0.070870,0.000000
153.710007,-0.039093,-136.200668,-0.001138,0.002798,0.071069,-0.173894,-0.008859,0.710691,-136.200668,0.070202,0.000000
154.110001,-0.041328,-136.200668,-0.001199,0.002774,0.070471,-0.183838,-0.009365,0.704708,-136.200668,0.069534,0.000000
154.510010,-0.049522,-136.200668,-0.001242,0.002749,0.069829,-0.220287,-0.011222,0.698290,-136.200668,0.068866,0.000000
154.910004,-0.032768,-136.245148,-0.001285,0.002726,0.069231,-0.145760,-0.007425,0.692306,-136.245148,0.068199,0.000000
155.310013,-0.048035,-136.245148,-0.001306,0.002697,0.068511,-0.213669,-0.010885,0.685108,-136.245148,0.067540,0.000000
155.710007,-0.053246,-136.289627,-0.001367,0.002673,0.067886,-0.236848,-0.012066,0.678864,-136.289627,0.066872,0.000000
156.110001,-0.055855,-136.334122,-0.001406,0.002650,0.067314,-0.248455,-0.012657,0.673141,-136.334122,0.066204,0.000000
156.510010,-0.000740,-136.334122,-0.001436,0.002621,0.066586,-0.003292,-0.000168,0.665856,-136.334122,0.065536,0.000000
156.910004,0.002235,-136.334122,-0.001500,0.002591,0.065814,0.009944,0.000507,0.658138,-136.334122,0.064868,0.000000
157.310013,-0.027550,-136.378601,-0.001518,0.002569,0.065250,-0.122547,-0.006243,0.652501,-136.378601,0.064201,0.000000
157.710007,-0.056969,-136.423080,-0.001569,0.002541,0.064530,-0.253409,-0.012909,0.645303,-136.423080,0.063533,0.000000
158.110001,-0.054733,-136.423080,-0.001587,0.002515,0.063880,-0.243466,-0.012403,0.638798,-136.423080,0.062865,0.000000
158.510010,0.010056,-136.512039,-0.001643,0.002490,0.063247,0.044729,0.002279,0.632468,-136.512039,0.062206,0.000000
158.910004,0.014900,-136.512039,-0.001647,0.002463,0.062570,0.066279,0.003376,0.625703,-136.512039,0.061538,0.000000
159.310013,0.004471,-136.512039,-0.001694,0.002439,0.061955,0.019887,0.001013,0.619546,-136.512039,0.060871,0.000000
159.710007,-0.030159,-136.556519,-0.001720,0.002416,0.061374,-0.134154,-0.006834,0.613736,-136.556519,0.060203,0.000000
160.110001,-0.036491,-136.556519,-0.001742,0.002384,0.060550,-0.162322,-0.008269,0.605497,-136.556519,0.059535,0.000000
160.510010,0.003357,-136.600998,-0.001789,0.002356,0.059839,0.014932,0.000761,0.598386,-136.600998,0.058867,0.000000
160.910004,-0.025688,-136.645477,-0.001819,0.002331,0.059214,-0.114267,-0.005821,0.592142,-136.645477,0.058200,0.000000
161.310013,-0.027550,-136.556519,-0.001845,0.002303,0.058503,-0.122547,-0.006243,0.585030,-136.556519,0.057532,0.000000
161.710007,-0.046547,-136.600998,-0.001863,0.002278,0.057853,-0.207051,-0.010548,0.578526,-136.600998,0.056873,0.000000
162.110001,-0.071869,-136.689957,-0.001893,0.002253,0.057228,-0.319689,-0.016286,0.572282,-136.689957,0.056205,0.000000
162.510010,-0.052872,-136.689957,-0.001914,0.002228,0.056595,-0.235185,-0.011981,0.565952,-136.689957,0.055537,0.000000
162.910004,-0.053246,-136.689957,-0.001940,0.002203,0.055945,-0.236848,-0.012066,0.559447,-136.689957,0.054869,0.000000
163.310013,-0.060318,-136.734436,-0.001975,0.002178,0.055320,-0.268308,-0.013668,0.553203,-136.734436,0.054202,0.000000
163.710007,-0.013031,-136.689957,-0.002018,0.002143,0.054444,-0.057965,-0.002953,0.544444,-136.689957,0.053534,0.000000
164.110001,-0.049896,-136.689957,-0.002031,0.002124,0.053941,-0.221950,-0.011307,0.539414,-136.689957,0.052866,0.000000
164.500015,-0.014893,-136.734436,-0.002057,0.002099,0.053308,-0.066245,-0.003375,0.533084,-136.734436,0.053248,0.000000