File: Data/compression 34/AutoNoHeating-15-34-reverse-1-1re_11152024_200956.csv
Time (sec),S:Load (lbs),S:HL1 (DIM),S:LVDT (in),S:Position (in),Ch:Position (mm),Ch:Load (N),Ch:Stress (MPa),Ch:Strain (mm/mm),Ch:HL1 (DIM),Set Point (),Cycles ()
0.110000,-0.027550,-65.209076,-0.007377,-0.007322,-0.185977,-0.122547,-0.006243,-1.859766,-65.209076,-0.185777,0.000000
0.270000,-0.035744,-65.209076,-0.007386,-0.007322,-0.185977,-0.158996,-0.008100,-1.859766,-65.209076,-0.185777,0.000000
0.430000,-0.052872,-65.120110,-0.007377,-0.007313,-0.185760,-0.235185,-0.011981,-1.857597,-65.120110,-0.185118,0.000000
0.590000,-0.010048,-65.253555,-0.007386,-0.007220,-0.183392,-0.044695,-0.002277,-1.833922,-65.253555,-0.182447,0.000000
0.750000,-0.029045,-65.209076,-0.007338,-0.007128,-0.181059,-0.129199,-0.006582,-1.810594,-65.209076,-0.179793,0.000000
0.910000,-0.028671,-65.253555,-0.007235,-0.007029,-0.178536,-0.127536,-0.006497,-1.785358,-65.253555,-0.177122,0.000000
1.070000,-0.039841,-65.298035,-0.007131,-0.006919,-0.175735,-0.177220,-0.009028,-1.757346,-65.298035,-0.174451,0.000000
1.230000,0.012291,-65.298035,-0.007006,-0.006817,-0.173150,0.054673,0.002785,-1.731503,-65.298035,-0.171797,0.000000
1.390000,-0.001488,-65.298035,-0.006898,-0.006713,-0.170514,-0.006618,-0.000337,-1.705139,-65.298035,-0.169126,0.000000
1.550000,-0.020103,-65.253555,-0.006795,-0.006600,-0.167652,-0.089425,-0.004556,-1.676521,-65.253555,-0.166455,0.000000
1.710000,-0.048035,-65.298035,-0.006700,-0.006509,-0.165319,-0.213669,-0.010885,-1.653192,-65.298035,-0.163802,0.000000
1.870000,-0.058830,-65.298035,-0.006566,-0.006396,-0.162466,-0.261690,-0.013331,-1.624661,-65.298035,-0.161131,0.000000
2.030000,-0.078568,-65.253555,-0.006463,-0.006291,-0.159795,-0.349486,-0.017804,-1.597950,-65.253555,-0.158459,0.000000
2.190000,-0.056969,-65.342514,-0.006368,-0.006183,-0.157037,-0.253409,-0.012909,-1.570372,-65.342514,-0.155806,0.000000
2.350000,-0.072235,-65.387001,-0.006265,-0.006079,-0.154410,-0.321318,-0.016369,-1.544095,-65.387001,-0.153135,0.000000
2.510000,-0.028671,-65.387001,-0.006170,-0.005974,-0.151738,-0.127536,-0.006497,-1.517385,-65.387001,-0.150464,0.000000
2.670000,-0.084900,-65.342514,-0.006062,-0.005876,-0.149241,-0.377654,-0.019239,-1.492409,-65.342514,-0.147793,0.000000
2.830000,-0.030159,-65.342514,-0.005911,-0.005768,-0.146518,-0.134154,-0.006834,-1.465178,-65.342514,-0.145139,0.000000
2.990000,-0.047661,-65.475960,-0.005838,-0.005657,-0.143699,-0.212006,-0.010800,-1.436993,-65.475960,-0.142468,0.000000
3.150000,0.006332,-65.387001,-0.005713,-0.005558,-0.141167,0.028168,0.001435,-1.411670,-65.387001,-0.139797,0.000000
3.310000,0.013405,-65.431480,-0.005609,-0.005449,-0.138409,0.059628,0.003038,-1.384092,-65.431480,-0.137143,0.000000
3.470000,-0.010796,-65.387001,-0.005523,-0.005345,-0.135756,-0.048021,-0.002446,-1.357555,-65.387001,-0.134472,0.000000
3.630000,-0.012657,-65.431480,-0.005411,-0.005247,-0.133284,-0.056302,-0.002868,-1.332839,-65.431480,-0.131801,0.000000
3.790000,-0.047661,-65.431480,-0.005299,-0.005136,-0.130457,-0.212006,-0.010800,-1.304568,-65.431480,-0.129147,0.000000
3.950000,-0.039467,-65.475960,-0.005174,-0.005030,-0.127760,-0.175557,-0.008943,-1.277597,-65.475960,-0.126476,0.000000
4.110000,-0.029411,-65.520439,-0.005079,-0.004926,-0.125123,-0.130828,-0.006665,-1.251233,-65.520439,-0.123805,0.000000
4.270000,-0.025322,-65.520439,-0.004963,-0.004815,-0.122314,-0.112638,-0.005738,-1.223135,-65.520439,-0.121151,0.000000
4.430000,0.015640,-65.520439,-0.004859,-0.004714,-0.119747,0.069571,0.003544,-1.197465,-65.520439,-0.118480,0.000000
4.590000,0.167946,-65.520439,-0.004790,-0.000001,-0.000026,0.747060,0.038057,-0.000260,-65.520439,0.000165,0.000000
4.750000,0.166451,-65.564919,-0.004799,-0.000001,-0.000026,0.740409,0.037718,-0.000260,-65.564919,0.000165,0.000000
4.910000,0.161987,-65.564919,-0.004799,-0.000001,-0.000026,0.720556,0.036707,-0.000260,-65.564919,0.000165,0.000000
5.070000,0.150444,-65.653885,-0.004807,-0.000001,-0.000035,0.669208,0.034091,-0.000347,-65.653885,0.000165,0.000000
5.230000,0.157143,-65.564919,-0.004777,-0.000001,-0.000026,0.699005,0.035609,-0.000260,-65.564919,0.000425,0.000000
5.390000,0.137039,-65.564919,-0.004803,-0.000001,-0.000026,0.609581,0.031054,-0.000260,-65.564919,0.000694,0.000000
5.550000,0.118042,-65.609406,-0.004807,-0.000000,-0.000000,0.525077,0.026749,-0.000000,-65.609406,0.000954,0.000000
5.710000,0.106873,-65.609406,-0.004799,0.000005,0.000139,0.475393,0.024218,0.001388,-65.609406,0.001223,0.000000
5.870000,0.146721,-65.653885,-0.004781,0.000022,0.000564,0.652647,0.033247,0.005637,-65.653885,0.001492,0.000000
6.030000,0.156403,-65.653885,-0.004769,0.000027,0.000676,0.695713,0.035441,0.006764,-65.653885,0.001760,0.000000
6.190000,0.191032,-65.698364,-0.004781,0.000039,0.000989,0.849755,0.043289,0.009886,-65.698364,0.002021,0.000000
6.350000,0.272949,-65.653885,-0.004756,0.000045,0.001136,1.214139,0.061851,0.011361,-65.653885,0.002289,0.000000
6.510000,0.307579,-65.698364,-0.004751,0.000053,0.001336,1.368180,0.069698,0.013355,-65.698364,0.002558,0.000000
6.670001,0.422272,-65.742844,-0.004751,0.000066,0.001674,1.878358,0.095688,0.016737,-65.742844,0.002827,0.000000
6.830000,0.503075,-65.698364,-0.004730,0.000080,0.002021,2.237788,0.113998,0.020206,-65.698364,0.003087,0.000000
6.990000,0.638992,-65.742844,-0.004712,0.000092,0.002333,2.842380,0.144798,0.023328,-65.742844,0.003356,0.000000
7.150001,0.657616,-65.742844,-0.004700,0.000100,0.002532,2.925220,0.149018,0.025323,-65.742844,0.003625,0.000000
7.310000,0.748100,-65.742844,-0.004700,0.000109,0.002758,3.327716,0.169522,0.027578,-65.742844,0.003894,0.000000
7.470000,0.887741,-65.831810,-0.004682,0.000125,0.003165,3.948869,0.201165,0.031654,-65.831810,0.004154,0.000000
7.630001,0.924232,-65.742844,-0.004669,0.000135,0.003417,4.111191,0.209434,0.034169,-65.742844,0.004423,0.000000
7.790000,0.977478,-65.831810,-0.004661,0.000137,0.003478,4.348040,0.221500,0.034776,-65.831810,0.004692,0.000000
7.950000,1.072060,-65.742844,-0.004652,0.000151,0.003824,4.768759,0.242932,0.038245,-65.742844,0.004961,0.000000
8.110001,1.187500,-65.876289,-0.004639,0.000162,0.004119,5.282264,0.269091,0.041193,-65.876289,0.005221,0.000000
8.270000,1.263466,-65.787323,-0.004631,0.000169,0.004293,5.620177,0.286305,0.042928,-65.787323,0.005490,0.000000
8.430000,1.308517,-65.876289,-0.004639,0.000175,0.004458,5.820576,0.296514,0.044575,-65.876289,0.005758,0.000000
8.590000,1.582214,-65.920769,-0.004622,0.000193,0.004908,7.038041,0.358535,0.049085,-65.920769,0.006027,0.000000
8.750000,1.781059,-65.920769,-0.004613,0.000207,0.005264,7.922547,0.403594,0.052641,-65.920769,0.006287,0.000000
8.910001,1.892029,-65.920769,-0.004587,0.000220,0.005594,8.416164,0.428740,0.055936,-65.920769,0.006556,0.000000
9.070001,1.932617,-65.920769,-0.004587,0.000228,0.005793,8.596710,0.437937,0.057931,-65.920769,0.006825,0.000000
9.230000,2.043213,-65.920769,-0.004575,0.000236,0.005993,9.088665,0.462999,0.059925,-65.920769,0.007094,0.000000
9.390000,2.148590,-65.965248,-0.004562,0.000246,0.006244,9.557406,0.486878,0.062440,-65.965248,0.007354,0.000000
9.550000,2.245407,-65.920769,-0.004553,0.000254,0.006443,9.988070,0.508817,0.064435,-65.920769,0.007623,0.000000
9.710000,2.345947,-66.009735,-0.004549,0.000262,0.006652,10.435294,0.531599,0.066516,-66.009735,0.007892,0.000000
9.870001,2.522827,-65.965248,-0.004540,0.000278,0.007068,11.222095,0.571681,0.070679,-65.965248,0.008161,0.000000
10.030001,2.621880,-65.920769,-0.004523,0.000287,0.007293,11.662703,0.594126,0.072934,-65.920769,0.008421,0.000000
10.190001,2.677361,-66.054214,-0.004536,0.000294,0.007475,11.909494,0.606699,0.074755,-66.054214,0.008690,0.000000
10.350000,2.785721,-66.009735,-0.004514,0.000306,0.007762,12.391505,0.631253,0.077617,-66.009735,0.008958,0.000000
10.510000,3.018082,-66.009735,-0.004484,0.000319,0.008100,13.425097,0.683907,0.080999,-66.009735,0.009227,0.000000
10.670000,3.100006,-66.009735,-0.004480,0.000332,0.008438,13.789515,0.702471,0.084381,-66.009735,0.009496,0.000000
10.830001,3.245972,-66.009735,-0.004471,0.000343,0.008724,14.438803,0.735548,0.087243,-66.009735,0.009756,0.000000
10.990001,3.311508,-66.054214,-0.004471,0.000353,0.008967,14.730324,0.750398,0.089671,-66.054214,0.010025,0.000000
11.150001,3.414658,-66.054214,-0.004462,0.000362,0.009201,15.189156,0.773772,0.092013,-66.054214,0.010294,0.000000
11.310000,3.365501,-66.098694,-0.004445,0.000366,0.009288,14.970498,0.762634,0.092880,-66.098694,0.010563,0.000000
11.470000,3.661171,-66.098694,-0.004441,0.000382,0.009696,16.285702,0.829633,0.096956,-66.098694,0.010823,0.000000
11.630000,3.810493,-66.098694,-0.004415,0.000396,0.010060,16.949921,0.863470,0.100598,-66.098694,0.011092,0.000000
11.790001,3.683136,-66.187653,-0.004419,0.000396,0.010068,16.383408,0.834611,0.100685,-66.187653,0.011361,0.000000
11.950001,3.887199,-66.143173,-0.004402,0.000414,0.010519,17.291126,0.880852,0.105194,-66.143173,0.011629,0.000000
12.110001,3.992950,-66.187653,-0.004398,0.000425,0.010788,17.761530,0.904815,0.107883,-66.187653,0.011890,0.000000
12.270000,4.090889,-66.187653,-0.004385,0.000433,0.011005,18.197184,0.927009,0.110051,-66.187653,0.012159,0.000000
12.430000,4.026840,-66.143173,-0.004376,0.000437,0.011092,17.912279,0.912495,0.110918,-66.143173,0.012427,0.000000
12.590000,4.418205,-66.187653,-0.004346,0.000460,0.011682,19.653158,1.001180,0.116815,-66.187653,0.012696,0.000000
12.750001,4.552254,-66.187653,-0.004346,0.000472,0.011976,20.249435,1.031556,0.119764,-66.187653,0.012956,0.000000
12.910001,4.577202,-66.232140,-0.004333,0.000481,0.012211,20.360411,1.037209,0.122105,-66.232140,0.013225,0.000000
13.070001,4.657265,-66.232140,-0.004324,0.000491,0.012479,20.716549,1.055351,0.124794,-66.232140,0.013494,0.000000
13.230000,4.673279,-66.232140,-0.004307,0.000497,0.012635,20.787783,1.058980,0.126355,-66.232140,0.013763,0.000000
13.390000,4.609970,-66.321098,-0.004307,0.000505,0.012835,20.506170,1.044634,0.128349,-66.321098,0.014023,0.000000
13.550000,4.877335,-66.276619,-0.004299,0.000518,0.013156,21.695467,1.105220,0.131558,-66.276619,0.014292,0.000000
13.710001,5.024796,-66.365578,-0.004281,0.000535,0.013589,22.351406,1.138635,0.135894,-66.365578,0.014561,0.000000
13.870001,4.954422,-66.321098,-0.004281,0.000539,0.013702,22.038370,1.122688,0.137022,-66.321098,0.014830,0.000000
14.030001,4.941383,-66.276619,-0.004264,0.000548,0.013919,21.980371,1.119733,0.139190,-66.276619,0.015090,0.000000
14.190001,5.171509,-66.321098,-0.004260,0.000560,0.014231,23.004021,1.171881,0.142312,-66.321098,0.015359,0.000000
14.350000,5.108582,-66.321098,-0.004251,0.000566,0.014370,22.724106,1.157621,0.143699,-66.321098,0.015627,0.000000
14.510000,5.503296,-66.365578,-0.004247,0.000587,0.014908,24.479883,1.247065,0.149076,-66.365578,0.015896,0.000000
14.670001,5.525635,-66.365578,-0.004221,0.000599,0.015202,24.579250,1.252127,0.152025,-66.365578,0.016156,0.000000
14.830001,5.542023,-66.321098,-0.004208,0.000607,0.015419,24.652147,1.255840,0.154193,-66.321098,0.016425,0.000000
14.990001,5.568459,-66.454544,-0.004186,0.000615,0.015619,24.769741,1.261831,0.156187,-66.454544,0.016694,0.000000
15.150001,5.578888,-66.365578,-0.004199,0.000625,0.015879,24.816133,1.264194,0.158789,-66.365578,0.016963,0.000000
15.310000,5.625061,-66.454544,-0.004186,0.000629,0.015966,25.021521,1.274657,0.159656,-66.454544,0.017223,0.000000
15.470000,5.891678,-66.410057,-0.004178,0.000646,0.016399,26.207493,1.335073,0.163992,-66.410057,0.017492,0.000000
15.630001,5.912529,-66.410057,-0.004161,0.000658,0.016711,26.300243,1.339798,0.167114,-66.410057,0.017761,0.000000
15.790001,5.902107,-66.543503,-0.004143,0.000663,0.016842,26.253883,1.337437,0.168415,-66.543503,0.018030,0.000000
15.950001,6.094254,-66.499023,-0.004130,0.000681,0.017292,27.108593,1.380978,0.172925,-66.499023,0.018290,0.000000
16.110001,6.048447,-66.499023,-0.004122,0.000688,0.017483,26.904835,1.370598,0.174833,-66.499023,0.018559,0.000000
16.270000,6.186600,-66.543503,-0.004122,0.000699,0.017752,27.519369,1.401904,0.177521,-66.543503,0.018827,0.000000
16.430000,6.287888,-66.454544,-0.004092,0.000712,0.018073,27.969921,1.424856,0.180730,-66.454544,0.019096,0.000000
16.590000,6.367203,-66.587982,-0.004092,0.000721,0.018316,28.322733,1.442829,0.183158,-66.587982,0.019356,0.000000
16.750000,6.409279,-66.454544,-0.004087,0.000732,0.018602,28.509897,1.452363,0.186020,-66.454544,0.019625,0.000000
16.910002,6.424919,-66.587982,-0.004066,0.000742,0.018836,28.579468,1.455908,0.188361,-66.587982,0.019894,0.000000
17.070002,6.388054,-66.587982,-0.004070,0.000746,0.018940,28.415483,1.447554,0.189402,-66.587982,0.020163,0.000000
17.230001,6.565674,-66.587982,-0.004049,0.000757,0.019235,29.205576,1.487803,0.192351,-66.587982,0.020423,0.000000
17.390001,6.671799,-66.676949,-0.004044,0.000770,0.019565,29.677643,1.511851,0.195646,-66.676949,0.020692,0.000000
17.550001,6.717606,-66.587982,-0.004023,0.000779,0.019781,29.881403,1.522231,0.197814,-66.587982,0.020961,0.000000
17.710001,6.763779,-66.632462,-0.004018,0.000793,0.020137,30.086790,1.532694,0.201370,-66.632462,0.021230,0.000000
17.870001,6.693024,-66.676949,-0.004018,0.000794,0.020172,29.772057,1.516661,0.201717,-66.676949,0.021490,0.000000
18.030001,6.736969,-66.632462,-0.003984,0.000803,0.020388,29.967535,1.526619,0.203885,-66.632462,0.021759,0.000000
18.190001,6.962997,-66.632462,-0.003988,0.000818,0.020787,30.972960,1.577838,0.207874,-66.632462,0.022028,0.000000
18.350000,7.071732,-66.632462,-0.003975,0.000833,0.021152,31.456633,1.602477,0.211516,-66.632462,0.022296,0.000000
18.510000,7.306694,-66.676949,-0.003958,0.000851,0.021611,32.501797,1.655720,0.216113,-66.676949,0.022557,0.000000
18.670000,7.230728,-66.721428,-0.003949,0.000858,0.021793,32.163887,1.638506,0.217934,-66.721428,0.022825,0.000000
18.830002,7.224770,-66.676949,-0.003941,0.000869,0.022062,32.137379,1.637156,0.220622,-66.676949,0.023094,0.000000
18.990002,7.237434,-66.721428,-0.003923,0.000878,0.022305,32.193714,1.640026,0.223050,-66.721428,0.023363,0.000000
19.150002,7.220680,-66.765907,-0.003919,0.000883,0.022426,32.119190,1.636230,0.224265,-66.765907,0.023623,0.000000
19.310001,7.480965,-66.721428,-0.003898,0.000902,0.022921,33.276993,1.695211,0.229208,-66.721428,0.023892,0.000000
19.470001,7.454155,-66.721428,-0.003893,0.000913,0.023181,33.157738,1.689136,0.231809,-66.721428,0.024161,0.000000
19.630001,7.427345,-66.721428,-0.003876,0.000920,0.023363,33.038483,1.683061,0.233631,-66.721428,0.024430,0.000000
19.790001,7.448944,-66.810387,-0.003872,0.000929,0.023597,33.134560,1.687955,0.235972,-66.810387,0.024690,0.000000
19.950001,7.346169,-66.765907,-0.003867,0.000933,0.023701,32.677391,1.664665,0.237013,-66.765907,0.024959,0.000000
20.110001,7.389359,-66.854866,-0.003846,0.000941,0.023909,32.869507,1.674453,0.239094,-66.854866,0.025228,0.000000
20.270000,7.699921,-66.810387,-0.003829,0.000959,0.024360,34.250957,1.744827,0.243604,-66.810387,0.025496,0.000000
20.430000,7.816475,-66.810387,-0.003807,0.000972,0.024690,34.769417,1.771238,0.246899,-66.810387,0.025757,0.000000
20.590000,7.859299,-66.854866,-0.003798,0.000984,0.024985,34.959908,1.780942,0.249848,-66.854866,0.026025,0.000000
20.750002,7.806419,-66.854866,-0.003798,0.000994,0.025236,34.724689,1.768960,0.252363,-66.854866,0.026294,0.000000
20.910002,7.783707,-66.899353,-0.003781,0.001002,0.025453,34.623657,1.763813,0.254531,-66.899353,0.026563,0.000000
21.070002,7.815353,-66.943832,-0.003773,0.001011,0.025679,34.764427,1.770984,0.256786,-66.943832,0.026823,0.000000
21.230001,8.022766,-66.899353,-0.003755,0.001025,0.026034,35.687046,1.817985,0.260341,-66.899353,0.027092,0.000000
21.390001,8.052933,-66.988312,-0.003738,0.001036,0.026303,35.821236,1.824821,0.263030,-66.988312,0.027361,0.000000
21.550001,8.010109,-66.943832,-0.003729,0.001046,0.026572,35.630745,1.815117,0.265718,-66.943832,0.027630,0.000000
21.710001,7.965797,-66.899353,-0.003712,0.001054,0.026780,35.433636,1.805076,0.267799,-66.899353,0.027890,0.000000
21.870001,7.919991,-66.943832,-0.003717,0.001061,0.026962,35.229877,1.794695,0.269620,-66.943832,0.028159,0.000000
22.030001,7.949409,-66.988312,-0.003704,0.001070,0.027179,35.360741,1.801362,0.271789,-66.988312,0.028428,0.000000
22.190001,7.934143,-67.032791,-0.003682,0.001077,0.027344,35.292831,1.797902,0.273436,-67.032791,0.028696,0.000000
22.350000,8.305397,-66.988312,-0.003669,0.001099,0.027907,36.944252,1.882030,0.279073,-66.988312,0.028957,0.000000
22.510000,8.375031,-66.988312,-0.003660,0.001111,0.028220,37.253998,1.897809,0.282195,-66.988312,0.029226,0.000000
22.670002,8.201134,-67.077271,-0.003652,0.001116,0.028358,36.480465,1.858403,0.283583,-67.077271,0.029494,0.000000
22.830002,8.261833,-67.077271,-0.003635,0.001129,0.028688,36.750469,1.872158,0.286878,-67.077271,0.029763,0.000000
22.990002,8.252518,-67.077271,-0.003626,0.001140,0.028957,36.709034,1.870047,0.289567,-67.077271,0.030023,0.000000
23.150002,8.158310,-67.077271,-0.003617,0.001143,0.029035,36.289974,1.848699,0.290347,-67.077271,0.030292,0.000000
23.310001,8.308380,-67.077271,-0.003596,0.001157,0.029399,36.957520,1.882706,0.293990,-67.077271,0.030561,0.000000
23.470001,8.429398,-67.077271,-0.003579,0.001174,0.029815,37.495834,1.910129,0.298152,-67.077271,0.030830,0.000000
23.630001,8.341515,-67.121758,-0.003583,0.001178,0.029928,37.104912,1.890214,0.299280,-67.121758,0.031090,0.000000
23.790001,8.407425,-67.166237,-0.003566,0.001192,0.030284,37.398094,1.905150,0.302835,-67.166237,0.031359,0.000000
23.950001,8.464401,-67.121758,-0.003531,0.001201,0.030509,37.651539,1.918061,0.305090,-67.121758,0.031628,0.000000
24.110001,8.504242,-67.166237,-0.003527,0.001214,0.030830,37.828758,1.927089,0.308299,-67.166237,0.031897,0.000000
24.270000,8.635689,-67.166237,-0.003523,0.001224,0.031090,38.413464,1.956875,0.310900,-67.166237,0.032157,0.000000
24.430000,8.636436,-67.166237,-0.003488,0.001237,0.031420,38.416786,1.957044,0.314196,-67.166237,0.032426,0.000000
24.590002,8.653938,-67.210716,-0.003488,0.001250,0.031740,38.494640,1.961010,0.317405,-67.210716,0.032694,0.000000
24.750002,8.566055,-67.210716,-0.003488,0.001257,0.031940,38.103718,1.941096,0.319399,-67.210716,0.032963,0.000000
24.910002,8.604042,-67.210716,-0.003466,0.001268,0.032209,38.272690,1.949704,0.322088,-67.210716,0.033223,0.000000
25.070002,8.731018,-67.255196,-0.003466,0.001280,0.032521,38.837509,1.978477,0.325210,-67.255196,0.033492,0.000000
25.230001,8.621918,-67.255196,-0.003436,0.001289,0.032746,38.352207,1.953755,0.327464,-67.255196,0.033761,0.000000
25.390001,8.531425,-67.299683,-0.003428,0.001294,0.032877,37.949677,1.933249,0.328765,-67.299683,0.034030,0.000000
25.550001,8.583557,-67.255196,-0.003428,0.001308,0.033223,38.181568,1.945062,0.332234,-67.255196,0.034290,0.000000
25.710001,8.651703,-67.255196,-0.003415,0.001314,0.033388,38.484695,1.960504,0.333882,-67.255196,0.034559,0.000000
25.870001,8.535896,-67.299683,-0.003415,0.001321,0.033544,37.969563,1.934262,0.335443,-67.299683,0.034828,0.000000
26.030001,8.946625,-67.255196,-0.003389,0.001343,0.034108,39.796574,2.027334,0.341080,-67.255196,0.035097,0.000000
26.190001,9.036736,-67.388641,-0.003354,0.001353,0.034377,40.197407,2.047754,0.343768,-67.388641,0.035357,0.000000
26.350000,9.028915,-67.388641,-0.003363,0.001364,0.034646,40.162621,2.045981,0.346457,-67.388641,0.035626,0.000000
26.510002,8.872894,-67.388641,-0.003333,0.001372,0.034854,39.468605,2.010627,0.348538,-67.388641,0.035894,0.000000
26.670002,8.958908,-67.388641,-0.003328,0.001384,0.035149,39.851215,2.030118,0.351487,-67.388641,0.036163,0.000000
26.830002,8.905663,-67.299683,-0.003320,0.001392,0.035348,39.614365,2.018052,0.353481,-67.299683,0.036423,0.000000
26.990002,8.914597,-67.388641,-0.003311,0.001400,0.035565,39.654106,2.020077,0.355649,-67.388641,0.036692,0.000000
27.150002,8.939545,-67.388641,-0.003307,0.001410,0.035808,39.765079,2.025730,0.358077,-67.388641,0.036961,0.000000
27.310001,9.018860,-67.433121,-0.003281,0.001425,0.036189,40.117893,2.043703,0.361893,-67.433121,0.037230,0.000000
27.470001,8.959656,-67.433121,-0.003268,0.001433,0.036389,39.854538,2.030287,0.363888,-67.433121,0.037490,0.000000
27.630001,8.946999,-67.433121,-0.003260,0.001443,0.036649,39.798237,2.027419,0.366490,-67.433121,0.037759,0.000000
27.790001,8.965988,-67.477600,-0.003251,0.001451,0.036848,39.882706,2.031722,0.368484,-67.477600,0.038028,0.000000
27.950001,9.200211,-67.433121,-0.003238,0.001464,0.037187,40.924580,2.084797,0.371866,-67.433121,0.038297,0.000000
28.110001,9.178238,-67.522087,-0.003229,0.001475,0.037464,40.826839,2.079818,0.374642,-67.522087,0.038557,0.000000
28.270000,9.346176,-67.522087,-0.003199,0.001489,0.037828,41.573868,2.117874,0.378284,-67.522087,0.038826,0.000000
28.430002,9.250854,-67.477600,-0.003203,0.001497,0.038028,41.149857,2.096274,0.380278,-67.477600,0.039095,0.000000
28.590002,9.261276,-67.566566,-0.003178,0.001506,0.038262,41.196213,2.098635,0.382620,-67.566566,0.039363,0.000000
28.750002,9.270218,-67.522087,-0.003178,0.001520,0.038618,41.235989,2.100662,0.386176,-67.522087,0.039624,0.000000
28.910002,9.368149,-67.522087,-0.003160,0.001532,0.038912,41.671608,2.122853,0.389124,-67.522087,0.039892,0.000000
29.070002,9.412460,-67.566566,-0.003147,0.001542,0.039173,41.868713,2.132894,0.391726,-67.566566,0.040161,0.000000
29.230001,9.249359,-67.611046,-0.003130,0.001548,0.039320,41.143204,2.095935,0.393200,-67.611046,0.040430,0.000000
29.390001,9.272820,-67.611046,-0.003130,0.001558,0.039580,41.247562,2.101251,0.395802,-67.611046,0.040690,0.000000
29.550001,9.157387,-67.611046,-0.003109,0.001564,0.039728,40.734089,2.075094,0.397276,-67.611046,0.040959,0.000000
29.710001,9.293304,-67.611046,-0.003096,0.001579,0.040109,41.338684,2.105893,0.401092,-67.611046,0.041228,0.000000
29.870001,9.386024,-67.700005,-0.003091,0.001589,0.040369,41.751122,2.126904,0.403694,-67.700005,0.041497,0.000000
30.030001,9.699562,-67.611046,-0.003070,0.001606,0.040786,43.145805,2.197952,0.407856,-67.611046,0.041757,0.000000
30.190001,9.680939,-67.655525,-0.003065,0.001616,0.041046,43.062965,2.193732,0.410458,-67.655525,0.042026,0.000000
30.350002,9.621735,-67.655525,-0.003048,0.001625,0.041271,42.799614,2.180316,0.412713,-67.655525,0.042295,0.000000
30.510002,9.644073,-67.655525,-0.003035,0.001634,0.041505,42.898983,2.185378,0.415054,-67.655525,0.042563,0.000000
30.670002,9.583755,-67.744492,-0.003035,0.001644,0.041766,42.630672,2.171710,0.417656,-67.744492,0.042824,0.000000
30.830002,9.584496,-67.655525,-0.003022,0.001650,0.041913,42.633965,2.171878,0.419130,-67.655525,0.043092,0.000000
30.990002,9.620247,-67.655525,-0.003001,0.001660,0.042165,42.792995,2.179979,0.421645,-67.655525,0.043361,0.000000
31.150002,9.864151,-67.744492,-0.002992,0.001676,0.042572,43.877934,2.235249,0.425721,-67.744492,0.043630,0.000000
31.310001,9.731583,-67.655525,-0.002992,0.001685,0.042789,43.288242,2.205208,0.427889,-67.655525,0.043890,0.000000
31.470001,9.624344,-67.788971,-0.002966,0.001692,0.042980,42.811218,2.180907,0.429797,-67.788971,0.044159,0.000000
31.630001,9.510025,-67.744492,-0.002962,0.001697,0.043101,42.302704,2.155002,0.431011,-67.744492,0.044428,0.000000
31.790001,10.059647,-67.788971,-0.002949,0.001717,0.043621,44.747543,2.279548,0.436215,-67.788971,0.044697,0.000000
31.950001,10.099113,-67.788971,-0.002923,0.001730,0.043934,44.923100,2.288492,0.439337,-67.788971,0.044957,0.000000
32.110001,10.077888,-67.788971,-0.002915,0.001740,0.044194,44.828686,2.283682,0.441938,-67.788971,0.045226,0.000000
32.270000,10.038422,-67.788971,-0.002902,0.001750,0.044454,44.653130,2.274739,0.444540,-67.788971,0.045495,0.000000
32.430000,9.906227,-67.788971,-0.002884,0.001758,0.044662,44.065098,2.244783,0.446621,-67.788971,0.045764,0.000000
32.590000,9.813133,-67.833450,-0.002889,0.001761,0.044740,43.650997,2.223688,0.447402,-67.833450,0.046024,0.000000
32.750000,10.041771,-67.877930,-0.002871,0.001777,0.045148,44.668030,2.275498,0.451478,-67.877930,0.046293,0.000000
32.910000,10.245461,-67.833450,-0.002850,0.001792,0.045529,45.574085,2.321655,0.455293,-67.833450,0.046561,0.000000
33.070000,9.978470,-67.922409,-0.002846,0.001795,0.045581,44.386452,2.261153,0.455814,-67.922409,0.046830,0.000000
33.230003,10.141937,-67.833450,-0.002833,0.001808,0.045920,45.113590,2.298196,0.459196,-67.833450,0.047090,0.000000
33.390003,10.026131,-67.922409,-0.002820,0.001818,0.046171,44.598457,2.271954,0.461711,-67.922409,0.047359,0.000000
33.550003,10.237267,-67.922409,-0.002820,0.001829,0.046457,45.537636,2.319798,0.464573,-67.922409,0.047628,0.000000
33.710003,10.014214,-67.877930,-0.002798,0.001832,0.046535,44.545448,2.269253,0.465353,-67.877930,0.047897,0.000000
33.870003,10.236893,-67.966896,-0.002790,0.001845,0.046874,45.535973,2.319713,0.468735,-67.966896,0.048157,0.000000
34.030003,10.669220,-67.877930,-0.002768,0.001867,0.047429,47.459061,2.417680,0.474286,-67.877930,0.048426,0.000000
34.190002,10.580597,-68.011375,-0.002742,0.001876,0.047663,47.064846,2.397598,0.476627,-68.011375,0.048695,0.000000
34.350002,10.523994,-68.011375,-0.002755,0.001885,0.047880,46.813065,2.384771,0.478795,-68.011375,0.048964,0.000000
34.510002,10.548195,-67.966896,-0.002716,0.001895,0.048140,46.920715,2.390255,0.481397,-67.966896,0.049224,0.000000
34.670002,10.458458,-68.055855,-0.002716,0.001903,0.048339,46.521545,2.369920,0.483392,-68.055855,0.049493,0.000000
34.830002,10.693420,-68.011375,-0.002716,0.001916,0.048677,47.566711,2.423164,0.486774,-68.011375,0.049761,0.000000
34.990002,10.832321,-68.055855,-0.002677,0.001931,0.049042,48.184570,2.454639,0.490416,-68.055855,0.050030,0.000000
35.150002,10.676666,-68.055855,-0.002690,0.001937,0.049206,47.492184,2.419367,0.492064,-68.055855,0.050290,0.000000
35.310001,10.494202,-68.055855,-0.002677,0.001943,0.049362,46.680542,2.378020,0.493625,-68.055855,0.050559,0.000000
35.470001,10.738106,-68.055855,-0.002669,0.001957,0.049718,47.765480,2.433290,0.497180,-68.055855,0.050828,0.000000
35.630001,10.668098,-68.100334,-0.002656,0.001962,0.049839,47.454071,2.417426,0.498395,-68.100334,0.051097,0.000000
35.790001,11.165222,-68.144814,-0.002639,0.001983,0.050360,49.665390,2.530076,0.503598,-68.144814,0.051357,0.000000
35.950001,11.135803,-68.055855,-0.002630,0.001994,0.050646,49.534527,2.523409,0.506460,-68.055855,0.051626,0.000000
36.110001,11.145859,-68.100334,-0.002617,0.002004,0.050897,49.579254,2.525688,0.508975,-68.100334,0.051895,0.000000
36.270000,11.046432,-68.144814,-0.002587,0.002012,0.051114,49.136986,2.503157,0.511143,-68.144814,0.052164,0.000000
36.430000,10.897858,-68.144814,-0.002587,0.002017,0.051244,48.476093,2.469490,0.512444,-68.144814,0.052424,0.000000
36.590000,11.006958,-68.189301,-0.002574,0.002027,0.051496,48.961395,2.494212,0.514959,-68.189301,0.052693,0.000000
36.750000,11.359222,-68.189301,-0.002578,0.002044,0.051929,50.528343,2.574037,0.519295,-68.189301,0.052961,0.000000
36.910000,11.062813,-68.189301,-0.002552,0.002049,0.052042,49.209850,2.506869,0.520422,-68.189301,0.053230,0.000000
37.070004,11.251610,-68.233780,-0.002539,0.002062,0.052363,50.049660,2.549651,0.523631,-68.233780,0.053490,0.000000
37.230003,11.216232,-68.189301,-0.002535,0.002070,0.052571,49.892292,2.541635,0.525712,-68.189301,0.053759,0.000000
37.390003,11.571106,-68.278259,-0.002518,0.002086,0.052996,51.470848,2.622050,0.529962,-68.278259,0.054028,0.000000
37.550003,11.504448,-68.322739,-0.002509,0.002096,0.053239,51.174339,2.606945,0.532390,-68.322739,0.054297,0.000000
37.710003,11.453804,-68.233780,-0.002509,0.002106,0.053490,50.949066,2.595469,0.534905,-68.233780,0.054566,0.000000
37.870003,11.614296,-68.322739,-0.002483,0.002119,0.053811,51.662968,2.631837,0.538114,-68.322739,0.054826,0.000000
38.030003,11.680206,-68.233780,-0.002488,0.002127,0.054028,51.956154,2.646773,0.540282,-68.233780,0.055095,0.000000
38.190002,11.526794,-68.322739,-0.002471,0.002134,0.054193,51.273743,2.612009,0.541929,-68.322739,0.055364,0.000000
38.350002,11.604988,-68.367218,-0.002436,0.002144,0.054453,51.621567,2.629728,0.544531,-68.367218,0.055633,0.000000
38.510002,11.751335,-68.278259,-0.002449,0.002155,0.054739,52.272549,2.662890,0.547393,-68.278259,0.055893,0.000000
38.670002,11.721916,-68.367218,-0.002440,0.002163,0.054939,52.141689,2.656224,0.549387,-68.367218,0.056162,0.000000
38.830002,11.964333,-68.278259,-0.002427,0.002177,0.055294,53.220009,2.711157,0.552943,-68.278259,0.056430,0.000000
38.990002,11.832138,-68.367218,-0.002393,0.002187,0.055537,52.631977,2.681201,0.555371,-68.367218,0.056699,0.000000
39.150002,11.852249,-68.411705,-0.002402,0.002195,0.055763,52.721436,2.685758,0.557626,-68.411705,0.056959,0.000000
39.310001,11.746490,-68.411705,-0.002402,0.002198,0.055841,52.250999,2.661793,0.558407,-68.411705,0.057228,0.000000
39.470001,12.073807,-68.411705,-0.002376,0.002213,0.056222,53.706974,2.735964,0.562222,-68.411705,0.057497,0.000000
39.630001,12.309517,-68.367218,-0.002371,0.002228,0.056604,54.755466,2.789376,0.566038,-68.367218,0.057766,0.000000
39.790001,12.529961,-68.411705,-0.002341,0.002244,0.056985,55.736050,2.839329,0.569854,-68.411705,0.058026,0.000000
39.950001,12.602577,-68.456184,-0.002328,0.002256,0.057298,56.059063,2.855785,0.572976,-68.456184,0.058295,0.000000
40.110001,12.512459,-68.411705,-0.002324,0.002266,0.057558,55.658195,2.835364,0.575578,-68.411705,0.058564,0.000000
40.270000,12.472244,-68.545143,-0.002311,0.002275,0.057775,55.479313,2.826251,0.577746,-68.545143,0.058833,0.000000
40.430000,12.436501,-68.500664,-0.002294,0.002281,0.057939,55.320316,2.818151,0.579394,-68.500664,0.059093,0.000000
40.590000,12.715408,-68.545143,-0.002289,0.002298,0.058364,56.560963,2.881353,0.583643,-68.545143,0.059362,0.000000
40.750004,12.780945,-68.500664,-0.002294,0.002308,0.058616,56.852482,2.896204,0.586158,-68.500664,0.059630,0.000000
40.910004,12.741470,-68.500664,-0.002268,0.002317,0.058841,56.676891,2.887259,0.588413,-68.500664,0.059899,0.000000
41.070004,12.565338,-68.500664,-0.002246,0.002325,0.059058,55.893417,2.847346,0.590581,-68.500664,0.060159,0.000000
41.230003,12.526611,-68.500664,-0.002233,0.002329,0.059145,55.721149,2.838571,0.591448,-68.500664,0.060428,0.000000
41.390003,12.425323,-68.589630,-0.002238,0.002334,0.059275,55.270599,2.815619,0.592749,-68.589630,0.060697,0.000000
41.550003,12.862862,-68.589630,-0.002220,0.002350,0.059682,57.216866,2.914766,0.596825,-68.589630,0.060966,0.000000
41.710003,13.290718,-68.545143,-0.002216,0.002367,0.060116,59.120068,3.011720,0.601161,-68.545143,0.061226,0.000000
41.870003,13.510048,-68.589630,-0.002199,0.002380,0.060446,60.095695,3.061421,0.604456,-68.589630,0.061495,0.000000
42.030003,13.321625,-68.589630,-0.002190,0.002388,0.060654,59.257545,3.018723,0.606538,-68.589630,0.061764,0.000000
42.190002,13.352905,-68.634109,-0.002173,0.002397,0.060888,59.396690,3.025811,0.608879,-68.634109,0.062033,0.000000
42.350002,13.282158,-68.634109,-0.002182,0.002407,0.061131,59.081989,3.009780,0.611307,-68.634109,0.062293,0.000000
42.510002,13.157784,-68.589630,-0.002164,0.002414,0.061313,58.528744,2.981596,0.613129,-68.589630,0.062562,0.000000
42.670002,13.683945,-68.634109,-0.002147,0.002432,0.061781,60.869225,3.100826,0.617812,-68.634109,0.062831,0.000000
42.830002,13.720810,-68.589630,-0.002143,0.002439,0.061955,61.033211,3.109180,0.619546,-68.589630,0.063099,0.000000
42.990002,13.821724,-68.767548,-0.002121,0.002450,0.062241,61.482098,3.132047,0.622408,-68.767548,0.063360,0.000000
43.150002,13.775177,-68.678589,-0.002108,0.002459,0.062449,61.275047,3.121500,0.624489,-68.678589,0.063628,0.000000
43.310001,13.838478,-68.634109,-0.002100,0.002469,0.062700,61.556625,3.135844,0.627004,-68.634109,0.063897,0.000000
43.470001,13.755440,-68.723068,-0.002100,0.002475,0.062865,61.187252,3.117027,0.628652,-68.723068,0.064166,0.000000
43.630001,14.207870,-68.723068,-0.002082,0.002493,0.063325,63.199764,3.219549,0.633248,-68.723068,0.064426,0.000000
43.790001,14.557159,-68.767548,-0.002065,0.002507,0.063680,64.753479,3.298699,0.636804,-68.767548,0.064695,0.000000
43.950001,14.415283,-68.767548,-0.002061,0.002514,0.063854,64.122383,3.266550,0.638538,-68.767548,0.064964,0.000000
44.110001,14.450287,-68.767548,-0.002048,0.002525,0.064140,64.278084,3.274482,0.641400,-68.767548,0.065233,0.000000
44.270000,14.563118,-68.856514,-0.002022,0.002535,0.064392,64.779984,3.300050,0.643915,-68.856514,0.065493,0.000000
44.430000,14.430183,-68.767548,-0.002022,0.002542,0.064556,64.188660,3.269926,0.645563,-68.767548,0.065762,0.000000
44.590004,14.739624,-68.812035,-0.002026,0.002556,0.064921,65.565125,3.340047,0.649205,-68.812035,0.066031,0.000000
44.750004,14.949638,-68.900993,-0.002005,0.002569,0.065250,66.499313,3.387636,0.652501,-68.900993,0.066299,0.000000
44.910004,14.749306,-68.812035,-0.002001,0.002573,0.065354,65.608185,3.342240,0.653541,-68.812035,0.066560,0.000000
45.070004,14.672966,-68.900993,-0.001975,0.002585,0.065649,65.268616,3.324942,0.656490,-68.900993,0.066828,0.000000
45.230003,15.176041,-68.900993,-0.001970,0.002597,0.065970,67.506401,3.438940,0.659699,-68.900993,0.067097,0.000000
45.390003,15.045715,-68.900993,-0.001953,0.002603,0.066117,66.926682,3.409408,0.661173,-68.900993,0.067366,0.000000
45.550003,15.666084,-68.856514,-0.001949,0.002622,0.066603,69.686226,3.549985,0.666029,-68.856514,0.067626,0.000000
45.710003,15.693642,-68.900993,-0.001944,0.002632,0.066854,69.808807,3.556230,0.668544,-68.900993,0.067895,0.000000
45.870003,15.687683,-68.945473,-0.001906,0.002643,0.067123,69.782303,3.554880,0.671233,-68.945473,0.068164,0.000000
46.030003,15.675766,-68.945473,-0.001910,0.002651,0.067331,69.729286,3.552179,0.673314,-68.945473,0.068433,0.000000
46.190002,15.962494,-68.989952,-0.001906,0.002664,0.067678,71.004723,3.617153,0.676783,-68.989952,0.068693,0.000000
46.350002,15.964729,-68.945473,-0.001901,0.002676,0.067964,71.014664,3.617660,0.679645,-68.945473,0.068962,0.000000
46.510002,16.083511,-68.945473,-0.001880,0.002683,0.068155,71.543030,3.644576,0.681553,-68.945473,0.069231,0.000000
46.670002,16.054840,-68.989952,-0.001858,0.002692,0.068372,71.415497,3.638079,0.683721,-68.989952,0.069499,0.000000
46.830002,16.073830,-68.989952,-0.001863,0.002701,0.068606,71.499962,3.642382,0.686062,-68.989952,0.069760,0.000000
46.990002,16.408966,-69.034439,-0.001841,0.002714,0.068936,72.990730,3.718325,0.689358,-69.034439,0.070028,0.000000
47.150002,16.236557,-69.078918,-0.001854,0.002719,0.069057,72.223816,3.679256,0.690572,-69.078918,0.070297,0.000000
47.310001,16.681175,-68.989952,-0.001824,0.002733,0.069421,74.201576,3.780008,0.694214,-68.989952,0.070566,0.000000
47.470001,17.013329,-69.078918,-0.001811,0.002748,0.069812,75.679062,3.855275,0.698117,-69.078918,0.070826,0.000000
47.630001,17.356285,-69.078918,-0.001798,0.002760,0.070115,77.204613,3.932990,0.701152,-69.078918,0.071095,0.000000
47.790001,17.298569,-69.034439,-0.001789,0.002768,0.070306,76.947876,3.919912,0.703060,-69.034439,0.071364,0.000000
47.950001,17.311974,-69.078918,-0.001794,0.002778,0.070566,77.007507,3.922949,0.705662,-69.078918,0.071633,0.000000
48.110001,17.433365,-69.078918,-0.001794,0.002789,0.070835,77.547478,3.950457,0.708350,-69.078918,0.071893,0.000000
48.270000,17.568161,-69.034439,-0.001759,0.002798,0.071078,78.147079,3.981002,0.710778,-69.034439,0.072162,0.000000
48.430004,17.726418,-69.123398,-0.001763,0.002808,0.071321,78.851044,4.016863,0.713206,-69.123398,0.072431,0.000000
48.590004,18.044052,-69.078918,-0.001733,0.002820,0.071624,80.263954,4.088840,0.716242,-69.078918,0.072700,0.000000
48.750004,17.997879,-69.167877,-0.001729,0.002830,0.071884,80.058563,4.078378,0.718843,-69.167877,0.072960,0.000000
48.910004,18.041077,-69.123398,-0.001725,0.002836,0.072023,80.250717,4.088167,0.720231,-69.123398,0.073229,0.000000
49.070004,18.010918,-69.123398,-0.001712,0.002843,0.072223,80.116562,4.081332,0.722226,-69.123398,0.073497,0.000000
49.230003,17.972557,-69.123398,-0.001716,0.002850,0.072379,79.945923,4.072640,0.723787,-69.123398,0.073766,0.000000
49.390003,18.909073,-69.123398,-0.001694,0.002870,0.072908,84.111755,4.284857,0.729077,-69.123398,0.074026,0.000000
49.550003,19.170479,-69.212357,-0.001686,0.002883,0.073229,85.274551,4.344092,0.732285,-69.212357,0.074295,0.000000
49.710003,19.259850,-69.167877,-0.001677,0.002890,0.073411,85.672089,4.364344,0.734107,-69.167877,0.074564,0.000000
49.870003,19.099358,-69.256844,-0.001669,0.002899,0.073627,84.958183,4.327977,0.736275,-69.256844,0.074833,0.000000
50.030003,19.718613,-69.212357,-0.001656,0.002915,0.074044,87.712769,4.468302,0.740437,-69.212357,0.075093,0.000000
50.190002,19.648605,-69.212357,-0.001621,0.002924,0.074261,87.401360,4.452437,0.742605,-69.212357,0.075362,0.000000
50.350002,19.889908,-69.256844,-0.001630,0.002937,0.074607,88.474731,4.507118,0.746074,-69.256844,0.075631,0.000000
50.510002,20.151314,-69.256844,-0.001630,0.002947,0.074842,89.637520,4.566353,0.748416,-69.256844,0.075900,0.000000
50.670002,20.304726,-69.345802,-0.001604,0.002957,0.075102,90.319931,4.601117,0.751017,-69.345802,0.076160,0.000000
50.830002,20.185196,-69.256844,-0.001608,0.002963,0.075249,89.788239,4.574031,0.752492,-69.256844,0.076429,0.000000
50.990002,20.243660,-69.301323,-0.001591,0.002970,0.075449,90.048294,4.587279,0.754486,-69.301323,0.076697,0.000000
51.150002,20.433197,-69.390282,-0.001582,0.002980,0.075691,90.891403,4.630229,0.756915,-69.390282,0.076966,0.000000
51.310001,20.873344,-69.390282,-0.001578,0.002992,0.076004,92.849274,4.729968,0.760037,-69.390282,0.077226,0.000000
51.470001,21.363014,-69.390282,-0.001561,0.003005,0.076316,95.027435,4.840928,0.763159,-69.390282,0.077495,0.000000
51.630001,21.724586,-69.345802,-0.001565,0.003017,0.076637,96.635788,4.922862,0.766367,-69.345802,0.077764,0.000000
51.790001,21.942047,-69.345802,-0.001535,0.003032,0.077001,97.603104,4.972139,0.770010,-69.345802,0.078033,0.000000
51.950001,21.704475,-69.523727,-0.001531,0.003037,0.077131,96.546326,4.918304,0.771311,-69.523727,0.078293,0.000000
52.110001,22.004982,-69.390282,-0.001518,0.003048,0.077426,97.883049,4.986400,0.774259,-69.390282,0.078562,0.000000
52.270004,21.857521,-69.390282,-0.001531,0.003056,0.077625,97.227112,4.952985,0.776254,-69.390282,0.078831,0.000000
52.430004,22.296173,-69.479248,-0.001505,0.003064,0.077834,99.178329,5.052385,0.778335,-69.479248,0.079100,0.000000
52.590004,22.719193,-69.434761,-0.001500,0.003076,0.078137,101.060013,5.148243,0.781370,-69.434761,0.079360,0.000000
52.750004,22.909103,-69.479248,-0.001487,0.003087,0.078415,101.904785,5.191277,0.784145,-69.479248,0.079629,0.000000
52.910004,22.761269,-69.479248,-0.001492,0.003091,0.078519,101.247177,5.157777,0.785186,-69.479248,0.079898,0.000000
53.070004,23.472130,-69.568207,-0.001466,0.003111,0.079030,104.409248,5.318861,0.790303,-69.568207,0.080166,0.000000
53.230003,24.132713,-69.479248,-0.001470,0.003123,0.079334,107.347672,5.468551,0.793338,-69.479248,0.080427,0.000000
53.390003,24.587387,-69.479248,-0.001449,0.003137,0.079689,109.370163,5.571581,0.796894,-69.479248,0.080695,0.000000
53.550003,24.689041,-69.568207,-0.001427,0.003147,0.079924,109.822342,5.594616,0.799235,-69.568207,0.080964,0.000000
53.710003,24.523338,-69.479248,-0.001431,0.003152,0.080054,109.085258,5.557068,0.800536,-69.479248,0.081233,0.000000
53.870003,24.600044,-69.568207,-0.001436,0.003160,0.080262,109.426460,5.574450,0.802617,-69.568207,0.081493,0.000000
54.030003,25.173500,-69.612686,-0.001431,0.003174,0.080626,111.977318,5.704397,0.806260,-69.612686,0.081762,0.000000
54.190002,25.448311,-69.568207,-0.001401,0.003184,0.080886,113.199738,5.766670,0.808861,-69.568207,0.082031,0.000000
54.350002,25.586090,-69.568207,-0.001397,0.003193,0.081103,113.812614,5.797891,0.811029,-69.568207,0.082300,0.000000
54.510002,26.102570,-69.568207,-0.001393,0.003207,0.081467,116.110031,5.914927,0.814672,-69.568207,0.082560,0.000000
54.670002,25.996811,-69.612686,-0.001367,0.003214,0.081623,115.639587,5.890962,0.816233,-69.612686,0.082829,0.000000
54.830002,26.479034,-69.612686,-0.001358,0.003227,0.081970,117.784630,6.000235,0.819702,-69.612686,0.083098,0.000000
54.990002,26.363228,-69.568207,-0.001345,0.003231,0.082057,117.269493,5.973993,0.820569,-69.568207,0.083366,0.000000
55.150002,26.122307,-69.657173,-0.001350,0.003239,0.082265,116.197823,5.919399,0.822650,-69.657173,0.083627,0.000000
55.310001,27.806175,-69.657173,-0.001345,0.003260,0.082803,123.688042,6.300969,0.828027,-69.657173,0.083895,0.000000
55.470001,28.179291,-69.657173,-0.001328,0.003272,0.083098,125.347748,6.385519,0.830976,-69.657173,0.084164,0.000000
55.630001,28.172585,-69.657173,-0.001332,0.003281,0.083349,125.317917,6.383999,0.833491,-69.657173,0.084433,0.000000
55.790001,28.613846,-69.701653,-0.001315,0.003291,0.083592,127.280746,6.483990,0.835919,-69.701653,0.084693,0.000000
55.950001,28.460060,-69.790611,-0.001306,0.003296,0.083731,126.596672,6.449142,0.837306,-69.790611,0.084962,0.000000
56.110004,29.308319,-69.701653,-0.001298,0.003315,0.084199,130.369919,6.641360,0.841989,-69.701653,0.085231,0.000000
56.270004,29.230125,-69.746132,-0.001285,0.003323,0.084416,130.022095,6.623641,0.844158,-69.746132,0.085500,0.000000
56.430004,29.932793,-69.790611,-0.001285,0.003334,0.084685,133.147705,6.782868,0.846846,-69.790611,0.085760,0.000000
56.590004,29.788681,-69.746132,-0.001285,0.003340,0.084823,132.506668,6.750212,0.848233,-69.746132,0.086029,0.000000
56.750004,29.745857,-69.790611,-0.001276,0.003345,0.084971,132.316177,6.740508,0.849708,-69.790611,0.086298,0.000000
56.910004,30.444427,-69.746132,-0.001259,0.003361,0.085361,135.423584,6.898806,0.853610,-69.746132,0.086566,0.000000
57.070004,31.162361,-69.835091,-0.001242,0.003376,0.085751,138.617111,7.061492,0.857513,-69.835091,0.086827,0.000000
57.230003,31.832634,-69.790611,-0.001233,0.003390,0.086098,141.598633,7.213378,0.860982,-69.790611,0.087095,0.000000
57.390003,32.284325,-69.879578,-0.001224,0.003399,0.086341,143.607849,7.315732,0.863410,-69.879578,0.087364,0.000000
57.550003,32.226608,-69.835091,-0.001224,0.003404,0.086471,143.351120,7.302654,0.864711,-69.835091,0.087633,0.000000
57.710003,32.281715,-69.835091,-0.001212,0.003413,0.086679,143.596237,7.315142,0.866792,-69.835091,0.087893,0.000000
57.870003,32.932999,-69.835091,-0.001194,0.003426,0.087017,146.493301,7.462724,0.870174,-69.835091,0.088162,0.000000
58.030003,33.253609,-69.879578,-0.001216,0.003437,0.087295,147.919434,7.535376,0.872949,-69.879578,0.088431,0.000000
58.190002,33.452454,-69.879578,-0.001186,0.003447,0.087564,148.803940,7.580434,0.875638,-69.879578,0.088700,0.000000
58.350002,33.838608,-69.968536,-0.001190,0.003453,0.087711,150.521652,7.667938,0.877112,-69.968536,0.088960,0.000000
58.510002,34.596756,-69.968536,-0.001168,0.003468,0.088084,153.894058,7.839737,0.880841,-69.968536,0.089229,0.000000
58.670002,35.243195,-69.924057,-0.001160,0.003482,0.088440,156.769562,7.986222,0.884397,-69.924057,0.089498,0.000000
58.830002,35.385811,-69.968536,-0.001164,0.003491,0.088683,157.403946,8.018539,0.886825,-69.968536,0.089767,0.000000
58.990002,35.776802,-69.968536,-0.001138,0.003500,0.088908,159.143158,8.107140,0.889080,-69.968536,0.090027,0.000000
59.150002,36.308922,-70.013016,-0.001143,0.003513,0.089220,161.510147,8.227719,0.892202,-70.013016,0.090296,0.000000
59.310001,36.933762,-70.013016,-0.001147,0.003525,0.089541,164.289581,8.369310,0.895411,-70.013016,0.090564,0.000000
59.470001,36.989250,-70.013016,-0.001134,0.003531,0.089697,164.536407,8.381884,0.896971,-70.013016,0.090833,0.000000
59.630001,37.123672,-70.057495,-0.001125,0.003539,0.089888,165.134338,8.412345,0.898879,-70.057495,0.091093,0.000000
59.790005,36.987015,-70.013016,-0.001108,0.003544,0.090009,164.526459,8.381377,0.900094,-70.013016,0.091362,0.000000
59.950005,37.757454,-70.057495,-0.001117,0.003557,0.090339,167.953537,8.555962,0.903389,-70.057495,0.091631,0.000000
60.110004,38.399422,-70.057495,-0.001099,0.003569,0.090651,170.809158,8.701433,0.906511,-70.057495,0.091900,0.000000
60.270004,38.828026,-70.101982,-0.001091,0.003581,0.090955,172.715683,8.798556,0.909546,-70.101982,0.092160,0.000000
60.430004,39.375786,-70.057495,-0.001091,0.003590,0.091197,175.152237,8.922681,0.911975,-70.057495,0.092429,0.000000
60.590004,39.470367,-70.013016,-0.001069,0.003597,0.091362,175.572968,8.944113,0.913622,-70.013016,0.092698,0.000000
60.750004,40.245270,-70.146461,-0.001074,0.003612,0.091752,179.019897,9.119708,0.917525,-70.146461,0.092967,0.000000
60.910004,41.093163,-70.057495,-0.001056,0.003626,0.092091,182.791519,9.311844,0.920907,-70.057495,0.093227,0.000000
61.070004,41.770508,-70.057495,-0.001048,0.003638,0.092403,185.804504,9.465333,0.924029,-70.057495,0.093496,0.000000
61.230003,42.462006,-70.146461,-0.001043,0.003653,0.092784,188.880432,9.622027,0.927845,-70.146461,0.093764,0.000000
61.390003,42.621758,-70.146461,-0.001035,0.003659,0.092949,189.591049,9.658228,0.929492,-70.146461,0.094033,0.000000
61.550003,42.915558,-70.190941,-0.001035,0.003667,0.093140,190.897934,9.724805,0.931400,-70.190941,0.094293,0.000000
61.710003,43.176590,-70.146461,-0.001048,0.003677,0.093400,192.059067,9.783955,0.934002,-70.146461,0.094562,0.000000
61.870003,43.654343,-70.235420,-0.001022,0.003689,0.093704,194.184219,9.892216,0.937037,-70.235420,0.094831,0.000000
62.030003,44.617668,-70.235420,-0.001030,0.003704,0.094085,198.469299,10.110508,0.940853,-70.235420,0.095100,0.000000
62.190002,45.100266,-70.146461,-0.001005,0.003714,0.094337,200.615997,10.219867,0.943368,-70.146461,0.095360,0.000000
62.350002,44.899559,-70.279900,-0.001013,0.003715,0.094354,199.723221,10.174386,0.943542,-70.279900,0.095629,0.000000
62.510002,45.410080,-70.279900,-0.001013,0.003726,0.094640,201.994125,10.290071,0.946403,-70.279900,0.095898,0.000000
62.670002,45.358696,-70.279900,-0.000992,0.003732,0.094788,201.765564,10.278428,0.947878,-70.279900,0.096167,0.000000
62.830002,46.027847,-70.279900,-0.000987,0.003745,0.095135,204.742096,10.430059,0.951347,-70.279900,0.096427,0.000000
62.990002,47.440254,-70.235420,-0.000979,0.003762,0.095560,211.024796,10.750115,0.955596,-70.235420,0.096696,0.000000
63.150002,48.374535,-70.279900,-0.000983,0.003777,0.095941,215.180679,10.961826,0.959412,-70.279900,0.096965,0.000000
63.310001,48.703339,-70.279900,-0.000966,0.003784,0.096106,216.643265,11.036335,0.961059,-70.279900,0.097233,0.000000
63.470001,49.221687,-70.368866,-0.000957,0.003795,0.096401,218.949005,11.153793,0.964008,-70.368866,0.097494,0.000000
63.630005,49.495377,-70.368866,-0.000970,0.003801,0.096548,220.166428,11.215813,0.965482,-70.368866,0.097762,0.000000
63.790005,49.770561,-70.368866,-0.000944,0.003808,0.096722,221.390518,11.278171,0.967217,-70.368866,0.098031,0.000000
63.950005,50.689575,-70.457825,-0.000936,0.003823,0.097095,225.478485,11.486423,0.970946,-70.457825,0.098300,0.000000
64.110001,51.535606,-70.368866,-0.000940,0.003836,0.097441,229.241821,11.678136,0.974415,-70.368866,0.098560,0.000000
64.270004,52.158211,-70.413345,-0.000931,0.003848,0.097745,232.011307,11.819220,0.977450,-70.413345,0.098829,0.000000
64.430000,52.504890,-70.368866,-0.000918,0.003856,0.097953,233.553421,11.897778,0.979531,-70.368866,0.099098,0.000000
64.590004,52.835556,-70.413345,-0.000923,0.003865,0.098179,235.024292,11.972709,0.981786,-70.413345,0.099367,0.000000
64.750000,53.253731,-70.413345,-0.000918,0.003873,0.098387,236.884430,12.067468,0.983868,-70.413345,0.099636,0.000000
64.910004,53.640259,-70.368866,-0.000914,0.003884,0.098656,238.603790,12.155056,0.986556,-70.368866,0.099896,0.000000
65.070000,55.236992,-70.457825,-0.000905,0.003901,0.099098,245.706406,12.516881,0.990979,-70.457825,0.100165,0.000000
65.230003,55.824966,-70.457825,-0.000897,0.003912,0.099358,248.321854,12.650119,0.993580,-70.457825,0.100433,0.000000
65.389999,56.277397,-70.457825,-0.000875,0.003922,0.099627,250.334366,12.752640,0.996269,-70.457825,0.100702,0.000000
65.550003,56.728714,-70.546791,-0.000880,0.003931,0.099835,252.341919,12.854910,0.998350,-70.546791,0.100962,0.000000
65.710007,57.079857,-70.457825,-0.000888,0.003940,0.100069,253.903885,12.934480,1.000692,-70.457825,0.101231,0.000000
65.870003,57.679749,-70.591270,-0.000867,0.003950,0.100329,256.572327,13.070417,1.003293,-70.591270,0.101500,0.000000
66.030006,58.191017,-70.502304,-0.000867,0.003960,0.100581,258.846558,13.186274,1.005808,-70.502304,0.101769,0.000000
66.190002,59.215416,-70.546791,-0.000854,0.003971,0.100867,263.403320,13.418405,1.008670,-70.546791,0.102029,0.000000
66.350006,59.198662,-70.591270,-0.000854,0.003976,0.100980,263.328796,13.414608,1.009798,-70.591270,0.102298,0.000000
66.510002,60.268486,-70.546791,-0.000858,0.003991,0.101361,268.087616,13.657035,1.013613,-70.546791,0.102567,0.000000
66.670006,60.928329,-70.591270,-0.000845,0.004001,0.101622,271.022736,13.806557,1.016215,-70.591270,0.102836,0.000000
66.830002,61.964645,-70.591270,-0.000845,0.004017,0.102029,275.632507,14.041389,1.020291,-70.591270,0.103096,0.000000
66.990005,62.555222,-70.546791,-0.000828,0.004030,0.102359,278.259521,14.175216,1.023587,-70.546791,0.103365,0.000000
67.150002,63.216927,-70.635750,-0.000832,0.004039,0.102601,281.202942,14.325160,1.026015,-70.635750,0.103633,0.000000
67.310005,64.106895,-70.635750,-0.000819,0.004049,0.102836,285.161713,14.526830,1.028356,-70.635750,0.103902,0.000000
67.470001,64.349693,-70.635750,-0.000811,0.004055,0.103000,286.241730,14.581848,1.030004,-70.635750,0.104162,0.000000
67.630005,65.084007,-70.635750,-0.000819,0.004068,0.103330,289.508118,14.748247,1.033299,-70.635750,0.104431,0.000000
67.790001,65.981804,-70.635750,-0.000802,0.004080,0.103625,293.501709,14.951691,1.036248,-70.635750,0.104700,0.000000
67.950005,66.340385,-70.680229,-0.000793,0.004079,0.103599,295.096771,15.032946,1.035988,-70.680229,0.103824,0.000000
68.110001,65.863747,-70.680229,-0.000798,0.004079,0.103599,292.976562,14.924938,1.035988,-70.680229,0.018182,0.000000
68.270004,65.496590,-70.680229,-0.000798,0.004078,0.103590,291.343384,14.841740,1.035901,-70.680229,291.649841,0.000000
68.430000,65.108955,-70.724709,-0.000793,0.004078,0.103581,289.619110,14.753900,1.035814,-70.724709,1663.518799,0.000000
68.590004,64.787605,-70.724709,-0.000793,0.004078,0.103573,288.189667,14.681081,1.035728,-70.724709,1663.518799,0.000000
68.750000,64.256599,-70.724709,-0.000793,0.004078,0.103573,285.827637,14.560754,1.035728,-70.724709,0.103573,0.000000
68.800003,64.164986,-70.724709,-0.000793,0.004078,0.103573,285.420105,14.539993,1.035728,-70.724709,0.103573,0.000000