File: Data/compression 34/AutoNoHeating-10-34-reverse-1-3_11152024_194819.csv
Time (sec),S:Load (lbs),S:HL1 (DIM),S:LVDT (in),S:Position (in),Ch:Position (mm),Ch:Load (N),Ch:Stress (MPa),Ch:Strain (mm/mm),Ch:HL1 (DIM),Set Point (),Cycles ()
0.210000,-0.022346,-340.190308,-0.012620,-0.007871,-0.199913,-0.099402,-0.005064,-1.999129,-340.190308,-0.199635,0.000000
0.620000,-0.034637,-340.190308,-0.012603,-0.007753,-0.196938,-0.154075,-0.007849,-1.969383,-340.190308,-0.196010,0.000000
1.030000,-0.088257,-340.190308,-0.012387,-0.007500,-0.190495,-0.392586,-0.019999,-1.904948,-340.190308,-0.189194,0.000000
1.440000,-0.068520,-340.190308,-0.012111,-0.007225,-0.183522,-0.304790,-0.015527,-1.835223,-340.190308,-0.182360,0.000000
1.850000,-0.043945,-340.234802,-0.011839,-0.006962,-0.176827,-0.195479,-0.009958,-1.768273,-340.234802,-0.175526,0.000000
2.260000,-0.024956,-340.279266,-0.011563,-0.006692,-0.169968,-0.111009,-0.005655,-1.699676,-340.279266,-0.168693,0.000000
2.670000,-0.036125,-340.234802,-0.011283,-0.006425,-0.163203,-0.160693,-0.008186,-1.632032,-340.234802,-0.161859,0.000000
3.080000,-0.054741,-340.279266,-0.011012,-0.006155,-0.156343,-0.243500,-0.012404,-1.563434,-340.279266,-0.155043,0.000000
3.490000,-0.116180,-340.279266,-0.010727,-0.005880,-0.149362,-0.516796,-0.026327,-1.493623,-340.279266,-0.148209,0.000000
3.900000,-0.109482,-340.323761,-0.010473,-0.005617,-0.142667,-0.486999,-0.024809,-1.426673,-340.323761,-0.141375,0.000000
4.310000,-0.063675,-340.368225,-0.010179,-0.005346,-0.135799,-0.283240,-0.014429,-1.357989,-340.368225,-0.134541,0.000000
4.720000,-0.040588,-340.323761,-0.009895,-0.005077,-0.128956,-0.180546,-0.009197,-1.289565,-340.323761,-0.127708,0.000000
5.130000,-0.063675,-340.457214,-0.009628,-0.004819,-0.122409,-0.283240,-0.014429,-1.224089,-340.457214,-0.120891,0.000000
5.540000,-0.040962,-340.368225,-0.009343,-0.004541,-0.115332,-0.182209,-0.009282,-1.153323,-340.368225,-0.114058,0.000000
5.950000,-0.078201,-340.457214,-0.009080,-0.004273,-0.108542,-0.347857,-0.017721,-1.085420,-340.457214,-0.107224,0.000000
6.360000,-0.033516,-340.412720,-0.008791,-0.004002,-0.101648,-0.149086,-0.007595,-1.016475,-340.412720,-0.100390,0.000000
6.770000,0.004089,-340.457214,-0.008520,-0.003732,-0.094796,0.018190,0.000927,-0.947964,-340.457214,-0.093556,0.000000
7.180000,-0.067032,-340.412720,-0.008231,-0.003467,-0.088058,-0.298173,-0.015190,-0.880581,-340.412720,-0.086723,0.000000
7.590000,-0.100914,-340.412720,-0.007963,-0.003200,-0.081268,-0.448888,-0.022867,-0.812677,-340.412720,-0.079906,0.000000
8.000000,-0.130707,-340.457214,-0.007696,-0.002931,-0.074443,-0.581413,-0.029619,-0.744426,-340.457214,-0.073072,0.000000
8.410001,-0.053627,-340.457214,-0.007416,-0.002669,-0.067791,-0.238545,-0.012152,-0.677910,-340.457214,-0.066239,0.000000
8.820001,-0.003357,-340.457214,-0.007118,-0.002388,-0.060654,-0.014932,-0.000761,-0.606538,-340.457214,-0.059405,0.000000
9.230000,-0.031654,-340.546173,-0.006851,-0.002119,-0.053829,-0.140806,-0.007173,-0.538287,-340.546173,-0.052571,0.000000
9.640000,-0.058464,-340.546173,-0.006566,-0.001853,-0.047056,-0.260061,-0.013248,-0.470557,-340.546173,-0.045755,0.000000
10.050000,-0.076340,-340.546173,-0.006295,-0.001584,-0.040231,-0.339576,-0.017299,-0.402306,-340.546173,-0.038921,0.000000
10.460000,-0.010056,-340.546173,-0.006032,-0.001320,-0.033518,-0.044729,-0.002279,-0.335183,-340.546173,-0.032087,0.000000
10.870001,-0.040588,-340.635132,-0.005734,-0.001042,-0.026459,-0.180546,-0.009197,-0.264591,-340.635132,-0.025254,0.000000
11.280001,-0.027931,-340.635132,-0.005484,-0.000781,-0.019833,-0.124244,-0.006329,-0.198334,-340.635132,-0.018420,0.000000
11.690001,-0.012291,-340.590637,-0.005204,-0.000508,-0.012896,-0.054673,-0.002785,-0.128956,-340.590637,-0.011586,0.000000
12.100000,0.099792,-340.679596,-0.004963,-0.000007,-0.000182,0.443899,0.022613,-0.001821,-340.679596,0.000035,0.000000
12.510000,0.089737,-340.635132,-0.004963,-0.000007,-0.000182,0.399170,0.020335,-0.001821,-340.635132,0.000035,0.000000
12.920001,0.119156,-340.679596,-0.004963,-0.000007,-0.000182,0.530032,0.027001,-0.001821,-340.679596,0.000702,0.000000
13.330001,0.062927,-340.768555,-0.004950,0.000017,0.000442,0.279914,0.014260,0.004423,-340.768555,0.001388,0.000000
13.740001,0.166451,-340.679596,-0.004928,0.000045,0.001145,0.740409,0.037718,0.011447,-340.679596,0.002073,0.000000
14.150001,0.233101,-340.724091,-0.004907,0.000071,0.001795,1.036885,0.052821,0.017952,-340.724091,0.002758,0.000000
14.560000,0.230499,-340.724091,-0.004889,0.000089,0.002272,1.025312,0.052232,0.022721,-340.724091,0.003434,0.000000
14.970000,0.313164,-340.768555,-0.004842,0.000118,0.003009,1.393022,0.070964,0.030093,-340.768555,0.004119,0.000000
15.380001,0.307205,-340.768555,-0.004833,0.000146,0.003703,1.366517,0.069614,0.037031,-340.768555,0.004804,0.000000
15.790001,0.339973,-340.768555,-0.004816,0.000157,0.003998,1.512277,0.077039,0.039979,-340.768555,0.005490,0.000000
16.200001,0.560417,-340.768555,-0.004786,0.000199,0.005056,2.492860,0.126992,0.050559,-340.768555,0.006175,0.000000
16.610001,0.654259,-340.768555,-0.004734,0.000231,0.005880,2.910288,0.148257,0.058798,-340.768555,0.006851,0.000000
17.020000,0.727982,-340.813049,-0.004717,0.000258,0.006556,3.238224,0.164963,0.065562,-340.813049,0.007536,0.000000
17.430000,0.777138,-340.902008,-0.004704,0.000275,0.006981,3.456881,0.176102,0.069812,-340.902008,0.008221,0.000000
17.840000,0.988647,-340.857513,-0.004665,0.000305,0.007736,4.397724,0.224031,0.077357,-340.857513,0.008906,0.000000
18.250000,1.081367,-340.902008,-0.004652,0.000326,0.008282,4.810163,0.245041,0.082820,-340.902008,0.009592,0.000000
18.660002,1.192703,-340.902008,-0.004609,0.000353,0.008967,5.305409,0.270270,0.089671,-340.902008,0.010268,0.000000
19.070002,1.403839,-340.946503,-0.004592,0.000386,0.009808,6.244588,0.318114,0.098083,-340.946503,0.010953,0.000000
19.480001,1.426186,-340.902008,-0.004575,0.000406,0.010311,6.343990,0.323178,0.103113,-340.902008,0.011638,0.000000
19.890001,1.661148,-340.990967,-0.004544,0.000437,0.011092,7.389156,0.376422,0.110918,-340.990967,0.012323,0.000000
20.300001,1.824249,-340.990967,-0.004514,0.000472,0.011976,8.114666,0.413381,0.119764,-340.990967,0.013008,0.000000
20.710001,1.953835,-340.902008,-0.004493,0.000499,0.012679,8.691090,0.442745,0.126789,-340.902008,0.013685,0.000000
21.120001,2.055122,-340.990967,-0.004462,0.000522,0.013260,9.141641,0.465697,0.132599,-340.990967,0.014370,0.000000
21.530001,2.277054,-340.990967,-0.004428,0.000554,0.014075,10.128841,0.515988,0.140751,-340.990967,0.015055,0.000000
21.940001,2.435684,-340.990967,-0.004406,0.000578,0.014691,10.834464,0.551934,0.146908,-340.990967,0.015740,0.000000
22.350000,2.578300,-341.079926,-0.004372,0.000609,0.015471,11.468853,0.584251,0.154713,-341.079926,0.016425,0.000000
22.760000,2.655388,-341.079926,-0.004350,0.000637,0.016182,11.811755,0.601719,0.161824,-341.079926,0.017102,0.000000
23.170002,2.723160,-341.035461,-0.004333,0.000660,0.016772,12.113219,0.617077,0.167721,-341.035461,0.017787,0.000000
23.580002,2.962967,-341.124420,-0.004303,0.000690,0.017535,13.179935,0.671418,0.175353,-341.124420,0.018472,0.000000
23.990002,3.089195,-341.079926,-0.004277,0.000713,0.018116,13.741426,0.700022,0.181164,-341.079926,0.019157,0.000000
24.400002,3.274643,-341.124420,-0.004255,0.000741,0.018819,14.566339,0.742045,0.188188,-341.124420,0.019842,0.000000
24.810001,3.243362,-341.079926,-0.004234,0.000757,0.019235,14.427197,0.734956,0.192351,-341.079926,0.020519,0.000000
25.220001,3.585571,-341.168884,-0.004204,0.000800,0.020310,15.949418,0.812502,0.203104,-341.168884,0.021204,0.000000
25.630001,3.507370,-341.168884,-0.004195,0.000816,0.020718,15.601561,0.794781,0.207180,-341.168884,0.021889,0.000000
26.040001,3.709198,-341.213379,-0.004161,0.000843,0.021420,16.499336,0.840516,0.214205,-341.213379,0.022574,0.000000
26.450001,3.842880,-341.257843,-0.004130,0.000870,0.022106,17.093985,0.870809,0.221056,-341.257843,0.023259,0.000000
26.860001,3.856285,-341.213379,-0.004113,0.000895,0.022739,17.153612,0.873847,0.227387,-341.213379,0.023935,0.000000
27.270000,3.985870,-341.213379,-0.004096,0.000921,0.023389,17.730038,0.903211,0.233891,-341.213379,0.024621,0.000000
27.680002,4.251373,-341.257843,-0.004066,0.000954,0.024239,18.911053,0.963375,0.242390,-341.257843,0.025306,0.000000
28.090002,4.167587,-341.213379,-0.004040,0.000972,0.024699,18.538355,0.944389,0.246986,-341.213379,0.025991,0.000000
28.500002,4.408890,-341.346832,-0.004031,0.001005,0.025522,19.611721,0.999069,0.255225,-341.346832,0.026676,0.000000
28.910002,4.520599,-341.257843,-0.003992,0.001033,0.026242,20.108631,1.024382,0.262423,-341.257843,0.027352,0.000000
29.320002,4.569756,-341.346832,-0.003971,0.001059,0.026893,20.327288,1.035521,0.268927,-341.346832,0.028037,0.000000
29.730001,4.802483,-341.302338,-0.003954,0.001088,0.027638,21.362509,1.088258,0.276385,-341.302338,0.028723,0.000000
30.140001,4.862434,-341.302338,-0.003932,0.001112,0.028237,21.629189,1.101843,0.282369,-341.302338,0.029408,0.000000
30.550001,4.896324,-341.391296,-0.003906,0.001139,0.028939,21.779938,1.109523,0.289393,-341.391296,0.030093,0.000000
30.960001,4.963348,-341.346832,-0.003876,0.001169,0.029685,22.078075,1.124711,0.296851,-341.346832,0.030769,0.000000
31.370001,4.939514,-341.346832,-0.003872,0.001187,0.030145,21.972055,1.119310,0.301448,-341.346832,0.031454,0.000000
31.780001,5.308914,-341.391296,-0.003842,0.001222,0.031038,23.615231,1.203017,0.310380,-341.391296,0.032139,0.000000
32.190002,5.392326,-341.346832,-0.003820,0.001251,0.031766,23.986265,1.221919,0.317665,-341.346832,0.032825,0.000000
32.600002,5.388969,-341.480255,-0.003816,0.001276,0.032400,23.971333,1.221158,0.323996,-341.480255,0.033510,0.000000
33.010002,5.504410,-341.391296,-0.003773,0.001302,0.033059,24.484838,1.247317,0.330586,-341.391296,0.034186,0.000000
33.420002,5.693947,-341.435791,-0.003742,0.001330,0.033770,25.327940,1.290267,0.337698,-341.435791,0.034871,0.000000
33.830002,5.644043,-341.524750,-0.003729,0.001358,0.034481,25.105957,1.278958,0.344809,-341.524750,0.035556,0.000000
34.240002,5.775497,-341.435791,-0.003708,0.001390,0.035305,25.690695,1.308746,0.353048,-341.435791,0.036241,0.000000
34.650002,5.734909,-341.524750,-0.003691,0.001417,0.035981,25.510149,1.299549,0.359812,-341.524750,0.036926,0.000000
35.060001,5.905449,-341.524750,-0.003660,0.001444,0.036666,26.268749,1.338194,0.366663,-341.524750,0.037603,0.000000
35.470001,5.932632,-341.524750,-0.003635,0.001469,0.037308,26.389668,1.344354,0.373081,-341.524750,0.038288,0.000000
35.880001,5.917366,-341.524750,-0.003635,0.001488,0.037794,26.321758,1.340894,0.377937,-341.524750,0.038973,0.000000
36.290001,6.220108,-341.613708,-0.003622,0.001523,0.038678,27.668423,1.409497,0.386783,-341.613708,0.039658,0.000000
36.700001,6.090897,-341.613708,-0.003596,0.001544,0.039225,27.093660,1.380217,0.392246,-341.613708,0.040343,0.000000
37.110001,6.290482,-341.524750,-0.003579,0.001574,0.039979,27.981459,1.425444,0.399791,-341.524750,0.041020,0.000000
37.520000,6.349693,-341.658173,-0.003553,0.001600,0.040630,28.244846,1.438861,0.406295,-341.658173,0.041705,0.000000
37.930000,6.518005,-341.658173,-0.003544,0.001631,0.041419,28.993536,1.477001,0.414187,-341.658173,0.042390,0.000000
38.340000,6.404800,-341.613708,-0.003514,0.001656,0.042069,28.489975,1.451349,0.420691,-341.613708,0.043075,0.000000
38.750000,6.269257,-341.702667,-0.003501,0.001673,0.042503,27.887047,1.420634,0.425027,-341.702667,0.043760,0.000000
39.160004,6.621895,-341.569214,-0.003475,0.001702,0.043231,29.455660,1.500543,0.432312,-341.569214,0.044437,0.000000
39.570004,6.602158,-341.702667,-0.003454,0.001729,0.043925,29.367865,1.496070,0.439250,-341.702667,0.045122,0.000000
39.980003,6.599930,-341.702667,-0.003454,0.001753,0.044532,29.357954,1.495566,0.445321,-341.702667,0.045807,0.000000
40.390003,6.852768,-341.702667,-0.003428,0.001785,0.045339,30.482634,1.552859,0.453386,-341.702667,0.046492,0.000000
40.800003,6.618172,-341.791626,-0.003419,0.001799,0.045703,29.439098,1.499699,0.457028,-341.791626,0.047177,0.000000
41.210003,7.091461,-341.747162,-0.003389,0.001838,0.046683,31.544395,1.606948,0.466828,-341.747162,0.047854,0.000000
41.620003,7.117523,-341.791626,-0.003359,0.001872,0.047559,31.660324,1.612854,0.475587,-341.791626,0.048539,0.000000
42.030003,7.081779,-341.791626,-0.003354,0.001899,0.048226,31.501328,1.604754,0.482264,-341.791626,0.049224,0.000000
42.440002,6.964104,-341.747162,-0.003341,0.001921,0.048781,30.977880,1.578088,0.487815,-341.747162,0.049909,0.000000
42.850002,7.189766,-341.880585,-0.003303,0.001953,0.049605,31.981676,1.629224,0.496053,-341.880585,0.050594,0.000000
43.260002,7.310410,-341.836121,-0.003290,0.001979,0.050256,32.518326,1.656562,0.502557,-341.836121,0.051270,0.000000
43.670002,7.326050,-341.836121,-0.003272,0.002006,0.050950,32.587898,1.660107,0.509495,-341.836121,0.051955,0.000000
44.080002,7.305199,-341.880585,-0.003264,0.002036,0.051713,32.495148,1.655382,0.517127,-341.880585,0.052641,0.000000
44.490002,7.308182,-341.969543,-0.003247,0.002062,0.052363,32.508415,1.656058,0.523631,-341.969543,0.053326,0.000000
44.900002,7.456383,-341.925079,-0.003212,0.002089,0.053057,33.167648,1.689641,0.530569,-341.925079,0.054011,0.000000
45.310001,7.495483,-341.880585,-0.003208,0.002112,0.053638,33.341576,1.698501,0.536379,-341.880585,0.054687,0.000000
45.720001,7.679436,-341.925079,-0.003182,0.002140,0.054349,34.159836,1.740185,0.543490,-341.925079,0.055372,0.000000
46.130001,7.420639,-341.969543,-0.003173,0.002156,0.054757,33.008652,1.681541,0.547566,-341.969543,0.056057,0.000000
46.540001,7.994835,-341.925079,-0.003152,0.002199,0.055849,35.562801,1.811655,0.558493,-341.925079,0.056743,0.000000
46.950001,7.373344,-341.925079,-0.003139,0.002206,0.056031,32.798275,1.670824,0.560315,-341.925079,0.057428,0.000000
47.360001,7.849609,-341.925079,-0.003109,0.002241,0.056925,34.916805,1.778747,0.569247,-341.925079,0.058104,0.000000
47.770000,8.003769,-341.969543,-0.003087,0.002268,0.057618,35.602543,1.813680,0.576185,-341.969543,0.058789,0.000000
48.180004,8.119949,-342.014038,-0.003083,0.002296,0.058330,36.119339,1.840007,0.583296,-342.014038,0.059474,0.000000
48.590004,8.112877,-341.969543,-0.003053,0.002320,0.058928,36.087879,1.838404,0.589280,-341.969543,0.060159,0.000000
49.000004,8.426414,-342.058502,-0.003040,0.002353,0.059778,37.482563,1.909453,0.597779,-342.058502,0.060845,0.000000
49.410004,8.003769,-342.014038,-0.003027,0.002372,0.060246,35.602543,1.813680,0.602462,-342.014038,0.061521,0.000000
49.820004,8.270020,-342.058502,-0.002997,0.002403,0.061035,36.786884,1.874013,0.610354,-342.058502,0.062206,0.000000
50.230003,8.429024,-342.191956,-0.002984,0.002434,0.061816,37.494171,1.910044,0.618159,-342.191956,0.062891,0.000000
50.640003,8.418221,-342.102997,-0.002971,0.002457,0.062414,37.446114,1.907596,0.624142,-342.102997,0.063576,0.000000
51.050003,8.493065,-342.147461,-0.002940,0.002480,0.062987,37.779041,1.924556,0.629866,-342.147461,0.064261,0.000000
51.460003,8.765274,-342.191956,-0.002932,0.002511,0.063767,38.989887,1.986239,0.637671,-342.191956,0.064938,0.000000
51.870003,8.700104,-342.191956,-0.002897,0.002534,0.064374,38.699993,1.971472,0.643742,-342.191956,0.065623,0.000000
52.280003,8.859482,-342.191956,-0.002889,0.002568,0.065224,39.408943,2.007587,0.652241,-342.191956,0.066308,0.000000
52.690002,8.697502,-342.147461,-0.002867,0.002586,0.065692,38.688423,1.970882,0.656924,-342.147461,0.066993,0.000000
53.100002,9.102272,-342.191956,-0.002850,0.002620,0.066560,40.488930,2.062604,0.665596,-342.191956,0.067678,0.000000
53.510002,9.343193,-342.236450,-0.002846,0.002649,0.067297,41.560600,2.117198,0.672967,-342.236450,0.068355,0.000000
53.920002,9.296272,-342.236450,-0.002815,0.002676,0.067964,41.351883,2.106565,0.679645,-342.236450,0.069040,0.000000
54.330002,9.402771,-342.280914,-0.002802,0.002700,0.068589,41.825615,2.130698,0.685889,-342.280914,0.069725,0.000000
54.740002,9.586357,-342.236450,-0.002781,0.002729,0.069309,42.642246,2.172300,0.693087,-342.236450,0.070410,0.000000
55.150002,9.649658,-342.280914,-0.002759,0.002756,0.070011,42.923824,2.186644,0.700111,-342.280914,0.071095,0.000000
55.560001,9.845894,-342.325409,-0.002742,0.002788,0.070818,43.796722,2.231112,0.708177,-342.325409,0.071772,0.000000
55.970001,9.840309,-342.280914,-0.002712,0.002813,0.071442,43.771881,2.229846,0.714421,-342.280914,0.072457,0.000000
56.380001,10.089058,-342.369873,-0.002708,0.002841,0.072162,44.878372,2.286213,0.721619,-342.369873,0.073142,0.000000
56.790001,10.018677,-342.369873,-0.002690,0.002866,0.072804,44.565300,2.270265,0.728036,-342.369873,0.073827,0.000000
57.200005,10.052933,-342.369873,-0.002660,0.002887,0.073324,44.717678,2.278027,0.733239,-342.369873,0.074512,0.000000
57.610004,10.383606,-342.414368,-0.002643,0.002915,0.074035,46.188587,2.352959,0.740351,-342.414368,0.075188,0.000000
58.020004,10.114380,-342.325409,-0.002639,0.002942,0.074738,44.991009,2.291951,0.747375,-342.325409,0.075874,0.000000
58.430004,10.044373,-342.414368,-0.002600,0.002954,0.075024,44.679600,2.276088,0.750237,-342.414368,0.076559,0.000000
58.840004,11.037865,-342.369873,-0.002596,0.002997,0.076125,49.098873,2.501216,0.761251,-342.369873,0.077244,0.000000
59.250004,11.302620,-342.414368,-0.002570,0.003029,0.076940,50.276566,2.561210,0.769403,-342.414368,0.077929,0.000000
59.660004,11.003227,-342.503326,-0.002557,0.003055,0.077591,48.944798,2.493367,0.775907,-342.503326,0.078605,0.000000
60.070004,10.804382,-342.458832,-0.002544,0.003072,0.078024,48.060291,2.448308,0.780243,-342.458832,0.079290,0.000000
60.480003,11.050522,-342.458832,-0.002531,0.003101,0.078753,49.155178,2.504084,0.787528,-342.458832,0.079976,0.000000
60.890003,11.311554,-342.503326,-0.002501,0.003123,0.079325,50.316303,2.563235,0.793252,-342.503326,0.080661,0.000000
61.300003,11.549126,-342.503326,-0.002492,0.003152,0.080054,51.373077,2.617069,0.800536,-342.503326,0.081346,0.000000
61.710003,11.331291,-342.547791,-0.002466,0.003173,0.080600,50.404102,2.567707,0.806000,-342.547791,0.082022,0.000000
62.120003,11.699570,-342.547791,-0.002458,0.003198,0.081224,52.042286,2.651160,0.812244,-342.547791,0.082707,0.000000
62.530003,12.824501,-342.547791,-0.002423,0.003242,0.082334,57.046230,2.906074,0.823344,-342.547791,0.083392,0.000000
62.940002,12.864349,-342.592285,-0.002414,0.003271,0.083089,57.223484,2.915103,0.830889,-342.592285,0.084078,0.000000
63.350002,12.888550,-342.547791,-0.002393,0.003298,0.083774,57.331131,2.920587,0.837740,-342.547791,0.084763,0.000000
63.760002,12.766411,-342.592285,-0.002367,0.003319,0.084303,56.787830,2.892910,0.843030,-342.592285,0.085439,0.000000
64.170006,13.401306,-342.592285,-0.002363,0.003351,0.085118,59.611988,3.036779,0.851182,-342.592285,0.086124,0.000000
64.580002,13.608345,-342.636780,-0.002328,0.003376,0.085751,60.532944,3.083695,0.857513,-342.636780,0.086809,0.000000
64.990005,13.909225,-342.681244,-0.002320,0.003406,0.086514,61.871326,3.151875,0.865144,-342.681244,0.087494,0.000000
65.400002,14.027267,-342.681244,-0.002294,0.003435,0.087243,62.396400,3.178624,0.872429,-342.681244,0.088180,0.000000
65.810005,14.204147,-342.681244,-0.002264,0.003461,0.087902,63.183205,3.218706,0.879020,-342.681244,0.088856,0.000000
66.220001,14.700142,-342.681244,-0.002259,0.003487,0.088561,65.389496,3.331100,0.885611,-342.681244,0.089541,0.000000
66.630005,14.963783,-342.681244,-0.002238,0.003510,0.089159,66.562233,3.390842,0.891595,-342.681244,0.090226,0.000000
67.040001,15.584160,-342.770203,-0.002225,0.003538,0.089871,69.321808,3.531421,0.898706,-342.770203,0.090911,0.000000
67.450005,15.322380,-342.681244,-0.002203,0.003554,0.090278,68.157349,3.472101,0.902782,-342.681244,0.091596,0.000000
67.860001,16.800323,-342.770203,-0.002182,0.003598,0.091380,74.731575,3.807008,0.913796,-342.770203,0.092273,0.000000
68.270004,16.379547,-342.725739,-0.002160,0.003613,0.091761,72.859863,3.711658,0.917612,-342.725739,0.092958,0.000000
68.680000,17.071411,-342.770203,-0.002139,0.003641,0.092472,75.937431,3.868437,0.924723,-342.770203,0.093643,0.000000
69.090004,17.466499,-342.859161,-0.002130,0.003663,0.093036,77.694870,3.957965,0.930360,-342.859161,0.094328,0.000000
69.500000,17.938667,-342.814697,-0.002108,0.003693,0.093799,79.795174,4.064960,0.937991,-342.814697,0.095013,0.000000
69.910004,18.079796,-342.859161,-0.002082,0.003708,0.094181,80.422951,4.096940,0.941807,-342.859161,0.095690,0.000000
70.320000,19.859741,-342.859161,-0.002061,0.003751,0.095282,88.340538,4.500282,0.952821,-342.859161,0.096375,0.000000
70.730003,20.167686,-342.859161,-0.002044,0.003778,0.095950,89.710350,4.570063,0.959499,-342.859161,0.097060,0.000000
71.140007,20.948555,-342.903656,-0.002026,0.003808,0.096722,93.183830,4.747010,0.967217,-342.903656,0.097745,0.000000
71.550003,21.471741,-342.948120,-0.002013,0.003830,0.097285,95.511070,4.865566,0.972854,-342.948120,0.098430,0.000000
71.960007,22.195999,-342.992615,-0.001975,0.003857,0.097979,98.732735,5.029685,0.979792,-342.992615,0.099107,0.000000
72.370003,23.215561,-342.948120,-0.001966,0.003885,0.098682,103.267975,5.260721,0.986816,-342.948120,0.099792,0.000000
72.780006,24.085045,-342.948120,-0.001962,0.003909,0.099289,107.135628,5.457749,0.992887,-342.948120,0.100477,0.000000
73.190002,24.700211,-342.992615,-0.001923,0.003933,0.099896,109.872025,5.597147,0.998957,-342.992615,0.101162,0.000000
73.600006,25.891800,-342.992615,-0.001923,0.003966,0.100746,115.172478,5.867166,1.007456,-342.992615,0.101847,0.000000
74.010002,26.661865,-342.992615,-0.001910,0.003989,0.101309,118.597900,6.041665,1.013093,-342.992615,0.102523,0.000000
74.420006,28.058632,-343.037109,-0.001897,0.004019,0.102081,124.811028,6.358177,1.020811,-343.037109,0.103209,0.000000
74.830002,28.482025,-343.081573,-0.001871,0.004037,0.102541,126.694374,6.454119,1.025408,-343.081573,0.103894,0.000000
75.240005,30.388939,-343.037109,-0.001854,0.004075,0.103495,135.176758,6.886232,1.034947,-343.037109,0.104579,0.000000
75.650002,31.540688,-343.081573,-0.001837,0.004099,0.104110,140.299988,7.147222,1.041104,-343.081573,0.105264,0.000000
76.060005,32.866333,-343.037109,-0.001811,0.004129,0.104874,146.196747,7.447618,1.048736,-343.037109,0.105940,0.000000
76.470001,33.885147,-343.081573,-0.001802,0.004154,0.105507,150.728668,7.678484,1.055067,-343.081573,0.106625,0.000000
76.880005,35.968567,-343.081573,-0.001789,0.004186,0.106322,159.996170,8.150594,1.063219,-343.081573,0.107311,0.000000
77.290001,37.065582,-343.126068,-0.001759,0.004214,0.107033,164.875946,8.399181,1.070330,-343.126068,0.107996,0.000000
77.700005,38.588585,-343.170532,-0.001768,0.004240,0.107701,171.650604,8.744299,1.077008,-343.170532,0.108681,0.000000
78.110001,39.668465,-343.170532,-0.001746,0.004264,0.108308,176.454147,8.989003,1.083078,-343.170532,0.109357,0.000000
78.520004,40.871971,-343.215027,-0.001733,0.004285,0.108837,181.807602,9.261721,1.088368,-343.215027,0.110042,0.000000
78.930000,42.740166,-343.170532,-0.001716,0.004312,0.109531,190.117752,9.685061,1.095306,-343.170532,0.110727,0.000000
79.340004,43.522514,-343.259491,-0.001712,0.004330,0.109982,193.597809,9.862343,1.099816,-343.259491,0.111412,0.000000
79.750000,44.953545,-343.215027,-0.001694,0.004354,0.110589,199.963348,10.186619,1.105886,-343.215027,0.112098,0.000000
80.160004,48.083336,-343.170532,-0.001673,0.004395,0.111621,213.885361,10.895840,1.116206,-343.170532,0.112774,0.000000
80.570007,50.187241,-343.303986,-0.001673,0.004427,0.112436,223.244003,11.372591,1.124358,-343.303986,0.113459,0.000000
80.980003,52.045753,-343.259491,-0.001647,0.004453,0.113112,231.511078,11.793736,1.131122,-343.259491,0.114144,0.000000
81.390007,52.956947,-343.215027,-0.001634,0.004470,0.113546,235.564270,12.000216,1.135459,-343.215027,0.114829,0.000000
81.800003,55.188950,-343.303986,-0.001630,0.004499,0.114274,245.492706,12.505995,1.142743,-343.303986,0.115514,0.000000
82.210007,57.542343,-343.303986,-0.001625,0.004531,0.115090,255.961121,13.039281,1.150895,-343.303986,0.116191,0.000000
82.620003,59.010979,-343.348450,-0.001604,0.004550,0.115575,262.493958,13.372079,1.155752,-343.348450,0.116876,0.000000
83.030006,60.072609,-343.348450,-0.001587,0.004568,0.116017,267.216309,13.612647,1.160175,-343.348450,0.117561,0.000000
83.440002,62.251366,-343.348450,-0.001578,0.004596,0.116746,276.907898,14.106361,1.167459,-343.348450,0.118246,0.000000
83.850006,65.467537,-343.392944,-0.001578,0.004632,0.117657,291.214142,14.835155,1.176565,-343.392944,0.118931,0.000000
84.260002,66.078987,-343.348450,-0.001548,0.004636,0.117761,293.934021,14.973713,1.177606,-343.348450,0.020678,0.000000
84.670006,65.342049,-343.437408,-0.001539,0.004636,0.117752,290.655945,14.806720,1.177519,-343.437408,294.500488,0.000000
85.080002,64.784248,-343.437408,-0.001544,0.004636,0.117752,288.174744,14.680321,1.177519,-343.437408,294.500488,0.000000
85.490005,64.372765,-343.392944,-0.001548,0.004636,0.117761,286.344360,14.587077,1.177606,-343.392944,294.500488,0.000000
85.900002,68.065956,-343.526398,-0.001544,0.004538,0.115254,302.772491,15.423966,1.152543,-343.526398,294.500488,0.000000
86.310005,65.495094,-343.481903,-0.001531,0.004472,0.113581,291.336731,14.841401,1.135806,-343.481903,294.500488,0.000000
86.720001,65.238914,-343.570862,-0.001509,0.004594,0.116685,290.197174,14.783349,1.166852,-343.570862,294.500488,0.000000
87.130005,64.993141,-343.481903,-0.001509,0.004604,0.116945,289.103943,14.727656,1.169454,-343.481903,294.500488,0.000000
87.540001,65.148796,-343.570862,-0.001513,0.004640,0.117865,289.796326,14.762929,1.178647,-343.570862,294.500488,0.000000
87.950005,65.261620,-343.570862,-0.001522,0.004647,0.118029,290.298187,14.788494,1.180294,-343.570862,294.500488,0.000000
88.360001,65.198326,-343.570862,-0.001513,0.004650,0.118107,290.016632,14.774152,1.181075,-343.570862,294.500488,0.000000
88.770004,65.122734,-343.526398,-0.001526,0.004651,0.118134,289.680389,14.757022,1.181335,-343.526398,294.500488,0.000000
89.180008,65.045280,-343.615356,-0.001518,0.004652,0.118159,289.335846,14.739471,1.181595,-343.615356,294.500488,0.000000
89.590004,64.927238,-343.659821,-0.001513,0.004652,0.118159,288.810791,14.712722,1.181595,-343.659821,294.500488,0.000000
90.000008,65.702888,-343.615356,-0.001526,0.004665,0.118480,292.261047,14.888488,1.184804,-343.615356,294.500488,0.000000
90.410004,65.647026,-343.659821,-0.001518,0.004665,0.118480,292.012543,14.875829,1.184804,-343.659821,294.500488,0.000000
90.820007,65.571068,-343.704315,-0.001509,0.004665,0.118480,291.674683,14.858616,1.184804,-343.704315,294.500488,0.000000
91.230003,65.502174,-343.704315,-0.001513,0.004665,0.118480,291.368225,14.843005,1.184804,-343.704315,294.500488,0.000000
91.640007,65.399025,-343.659821,-0.001509,0.004665,0.118480,290.909393,14.819631,1.184804,-343.659821,294.500488,0.000000
92.050003,65.317848,-343.704315,-0.001513,0.004665,0.118480,290.548309,14.801236,1.184804,-343.704315,294.500488,0.000000
92.460007,65.269066,-343.748779,-0.001513,0.004665,0.118489,290.331299,14.790182,1.184891,-343.748779,294.500488,0.000000
92.870003,65.176353,-343.704315,-0.001500,0.004666,0.118506,289.918915,14.769173,1.185064,-343.704315,294.500488,0.000000
93.280006,65.096657,-343.837738,-0.001513,0.004666,0.118506,289.564392,14.751113,1.185064,-343.837738,294.500488,0.000000
93.690002,65.056816,-343.748779,-0.001513,0.004666,0.118506,289.387177,14.742085,1.185064,-343.748779,294.500488,0.000000
94.100006,65.000587,-343.837738,-0.001513,0.004666,0.118515,289.137054,14.729344,1.185151,-343.837738,294.500488,0.000000
94.510002,64.947716,-343.793274,-0.001509,0.004666,0.118515,288.901855,14.717363,1.185151,-343.793274,294.500488,0.000000
94.920006,65.694313,-343.793274,-0.001513,0.004676,0.118767,292.222900,14.886544,1.187666,-343.793274,294.500488,0.000000
95.330002,65.752785,-343.926727,-0.001513,0.004676,0.118767,292.483002,14.899794,1.187666,-343.926727,294.500488,0.000000
95.740005,65.750542,-343.837738,-0.001509,0.004676,0.118767,292.473022,14.899285,1.187666,-343.837738,294.500488,0.000000
96.150002,65.686501,-343.882233,-0.001500,0.004676,0.118767,292.188141,14.884773,1.187666,-343.882233,294.500488,0.000000
96.560005,65.643669,-343.882233,-0.001509,0.004676,0.118767,291.997620,14.875068,1.187666,-343.882233,294.500488,0.000000
96.970001,65.601219,-343.882233,-0.001513,0.004676,0.118767,291.808807,14.865449,1.187666,-343.882233,294.500488,0.000000
97.380005,65.565102,-343.926727,-0.001518,0.004676,0.118767,291.648132,14.857265,1.187666,-343.926727,294.500488,0.000000
97.790001,65.546486,-343.882233,-0.001509,0.004676,0.118767,291.565338,14.853046,1.187666,-343.882233,294.500488,0.000000
98.200005,65.514839,-343.971191,-0.001505,0.004676,0.118767,291.424561,14.845875,1.187666,-343.971191,294.500488,0.000000
98.610008,65.466057,-343.971191,-0.001522,0.004676,0.118767,291.207550,14.834821,1.187666,-343.971191,294.500488,0.000000
99.020004,65.424355,-343.971191,-0.001496,0.004676,0.118767,291.022064,14.825371,1.187666,-343.971191,294.500488,0.000000
99.430008,65.368858,-344.015686,-0.001513,0.004676,0.118767,290.775208,14.812795,1.187666,-344.015686,294.500488,0.000000
99.840004,65.327904,-343.971191,-0.001505,0.004676,0.118767,290.593018,14.803514,1.187666,-343.971191,294.500488,0.000000
100.250008,65.303703,-344.060150,-0.001500,0.004676,0.118767,290.485382,14.798031,1.187666,-344.060150,294.500488,0.000000
100.660004,65.273918,-344.060150,-0.001513,0.004676,0.118767,290.352875,14.791282,1.187666,-344.060150,294.500488,0.000000
101.070007,65.248222,-344.060150,-0.001496,0.004676,0.118767,290.238586,14.785459,1.187666,-344.060150,294.500488,0.000000
101.480003,65.210976,-344.104645,-0.001513,0.004676,0.118767,290.072906,14.777019,1.187666,-344.104645,294.500488,0.000000
101.890007,65.153267,-344.104645,-0.001505,0.004676,0.118767,289.816193,14.763942,1.187666,-344.104645,294.500488,0.000000
102.300003,65.115273,-344.149109,-0.001513,0.004676,0.118775,289.647186,14.755332,1.187752,-344.149109,294.500488,0.000000
102.710007,65.077675,-344.149109,-0.001522,0.004676,0.118775,289.479950,14.746812,1.187752,-344.149109,294.500488,0.000000
103.120003,65.043419,-344.149109,-0.001518,0.004676,0.118775,289.327576,14.739050,1.187752,-344.149109,294.500488,0.000000
103.530006,65.006920,-344.282562,-0.001505,0.004676,0.118775,289.165222,14.730779,1.187752,-344.282562,294.500488,0.000000
103.940002,64.983467,-344.193604,-0.001496,0.004676,0.118775,289.060913,14.725465,1.187752,-344.193604,294.500488,0.000000
104.350006,64.956642,-344.149109,-0.001509,0.004676,0.118775,288.941589,14.719386,1.187752,-344.149109,294.500488,0.000000
104.760002,64.919411,-344.282562,-0.001513,0.004676,0.118775,288.775970,14.710948,1.187752,-344.282562,294.500488,0.000000
105.170006,64.886269,-344.149109,-0.001500,0.004676,0.118775,288.628540,14.703439,1.187752,-344.149109,294.500488,0.000000
105.580002,64.849403,-344.238068,-0.001496,0.004676,0.118775,288.464539,14.695085,1.187752,-344.238068,294.500488,0.000000
105.990005,65.128685,-344.238068,-0.001518,0.004688,0.119087,289.706848,14.758371,1.190874,-344.238068,294.500488,0.000000
106.400002,65.757988,-344.238068,-0.001500,0.004687,0.119053,292.506134,14.900973,1.190528,-344.238068,294.500488,0.000000
106.810005,65.771034,-344.282562,-0.001531,0.004687,0.119053,292.564178,14.903929,1.190528,-344.282562,294.500488,0.000000
107.220009,65.788155,-344.282562,-0.001500,0.004687,0.119053,292.640320,14.907809,1.190528,-344.282562,294.500488,0.000000
107.630005,65.777351,-344.371521,-0.001496,0.004687,0.119053,292.592285,14.905361,1.190528,-344.371521,294.500488,0.000000
108.040009,65.779213,-344.327057,-0.001509,0.004687,0.119053,292.600555,14.905783,1.190528,-344.327057,294.500488,0.000000
108.450005,65.767311,-344.327057,-0.001496,0.004687,0.119053,292.547607,14.903086,1.190528,-344.327057,294.500488,0.000000
108.860008,65.762459,-344.371521,-0.001505,0.004687,0.119053,292.526031,14.901986,1.190528,-344.371521,294.500488,0.000000
109.270004,65.686134,-344.371521,-0.001496,0.004687,0.119053,292.186523,14.884691,1.190528,-344.371521,294.500488,0.000000
109.680008,65.682396,-344.371521,-0.001496,0.004687,0.119053,292.169891,14.883844,1.190528,-344.371521,294.500488,0.000000
110.090004,65.665276,-344.416016,-0.001492,0.004687,0.119053,292.093719,14.879964,1.190528,-344.416016,294.500488,0.000000
110.500008,65.645164,-344.371521,-0.001483,0.004687,0.119053,292.004272,14.875406,1.190528,-344.371521,294.500488,0.000000
110.910004,65.614265,-344.504974,-0.001500,0.004687,0.119053,291.866821,14.868405,1.190528,-344.504974,294.500488,0.000000
111.320007,65.597496,-344.460480,-0.001500,0.004687,0.119053,291.792236,14.864605,1.190528,-344.460480,294.500488,0.000000
111.730003,65.585579,-344.460480,-0.001500,0.004687,0.119053,291.739227,14.861904,1.190528,-344.460480,294.500488,0.000000
112.140007,65.579628,-344.460480,-0.001509,0.004687,0.119053,291.712769,14.860556,1.190528,-344.460480,294.500488,0.000000
112.550003,65.558037,-344.460480,-0.001492,0.004687,0.119053,291.616699,14.855663,1.190528,-344.460480,294.500488,0.000000
112.960007,65.535683,-344.593933,-0.001496,0.004687,0.119053,291.517273,14.850598,1.190528,-344.593933,294.500488,0.000000
113.370003,65.518181,-344.504974,-0.001500,0.004687,0.119053,291.439423,14.846632,1.190528,-344.504974,294.500488,0.000000
113.780006,65.505898,-344.549438,-0.001492,0.004687,0.119053,291.384796,14.843848,1.190528,-344.549438,294.500488,0.000000
114.190002,65.477974,-344.549438,-0.001492,0.004687,0.119053,291.260590,14.837522,1.190528,-344.549438,294.500488,0.000000
114.600006,65.456367,-344.549438,-0.001500,0.004687,0.119053,291.164459,14.832624,1.190528,-344.549438,294.500488,0.000000
115.010002,65.416161,-344.682892,-0.001500,0.004687,0.119053,290.985626,14.823514,1.190528,-344.682892,294.500488,0.000000
115.420006,65.386360,-344.593933,-0.001500,0.004687,0.119053,290.853058,14.816761,1.190528,-344.593933,294.500488,0.000000
115.830002,65.373329,-344.638397,-0.001496,0.004687,0.119053,290.795105,14.813807,1.190528,-344.638397,294.500488,0.000000
116.240005,65.346153,-344.638397,-0.001496,0.004687,0.119053,290.674194,14.807650,1.190528,-344.638397,294.500488,0.000000
116.650009,65.346519,-344.638397,-0.001483,0.004687,0.119053,290.675842,14.807734,1.190528,-344.638397,294.500488,0.000000
117.060005,65.334984,-344.682892,-0.001492,0.004687,0.119053,290.624512,14.805119,1.190528,-344.682892,294.500488,0.000000
117.470009,65.313011,-344.682892,-0.001500,0.004687,0.119053,290.526794,14.800140,1.190528,-344.682892,294.500488,0.000000
117.880005,65.305565,-344.727356,-0.001487,0.004687,0.119053,290.493652,14.798452,1.190528,-344.727356,294.500488,0.000000
118.290009,65.282097,-344.682892,-0.001509,0.004687,0.119053,290.389282,14.793135,1.190528,-344.682892,294.500488,0.000000
118.700005,65.278374,-344.727356,-0.001496,0.004687,0.119053,290.372711,14.792291,1.190528,-344.727356,294.500488,0.000000
119.110008,65.249336,-344.771851,-0.001500,0.004687,0.119053,290.243530,14.785711,1.190528,-344.771851,294.500488,0.000000
119.520004,65.250084,-344.727356,-0.001492,0.004687,0.119053,290.246857,14.785880,1.190528,-344.727356,294.500488,0.000000
119.930008,65.218422,-344.771851,-0.001487,0.004687,0.119053,290.106018,14.778706,1.190528,-344.771851,294.500488,0.000000
120.340004,65.190865,-344.816345,-0.001496,0.004687,0.119053,289.983459,14.772461,1.190528,-344.816345,294.500488,0.000000
120.750008,65.177467,-344.727356,-0.001492,0.004687,0.119053,289.923859,14.769425,1.190528,-344.727356,294.500488,0.000000
121.160004,65.161079,-344.816345,-0.001500,0.004687,0.119053,289.850952,14.765712,1.190528,-344.816345,294.500488,0.000000
121.570007,65.141716,-344.816345,-0.001496,0.004687,0.119053,289.764832,14.761324,1.190528,-344.816345,294.500488,0.000000
121.980003,65.129799,-344.905304,-0.001487,0.004687,0.119053,289.711823,14.758624,1.190528,-344.905304,294.500488,0.000000
122.390007,65.098900,-344.905304,-0.001505,0.004687,0.119053,289.574371,14.751621,1.190528,-344.905304,294.500488,0.000000
122.800003,65.082878,-344.860809,-0.001492,0.004687,0.119053,289.503113,14.747991,1.190528,-344.860809,294.500488,0.000000
123.210007,65.067986,-344.905304,-0.001492,0.004687,0.119053,289.436859,14.744617,1.190528,-344.905304,294.500488,0.000000
123.620003,65.046761,-344.905304,-0.001496,0.004687,0.119053,289.342438,14.739807,1.190528,-344.905304,294.500488,0.000000
124.030006,65.022194,-344.905304,-0.001500,0.004687,0.119053,289.233154,14.734240,1.190528,-344.905304,294.500488,0.000000
124.440002,65.032234,-344.994263,-0.001513,0.004687,0.119053,289.277832,14.736515,1.190528,-344.994263,294.500488,0.000000
124.850006,65.015480,-344.949768,-0.001496,0.004687,0.119053,289.203308,14.732718,1.190528,-344.949768,294.500488,0.000000
125.260002,65.007668,-344.994263,-0.001492,0.004687,0.119053,289.168549,14.730948,1.190528,-344.994263,294.500488,0.000000
125.670006,64.997231,-344.905304,-0.001496,0.004687,0.119053,289.122131,14.728583,1.190528,-344.905304,294.500488,0.000000
126.080009,64.965218,-344.994263,-0.001500,0.004687,0.119053,288.979706,14.721329,1.190528,-344.994263,294.500488,0.000000
126.490005,64.957024,-345.083221,-0.001496,0.004687,0.119053,288.943268,14.719472,1.190528,-345.083221,294.500488,0.000000
126.900009,64.948082,-344.949768,-0.001487,0.004687,0.119053,288.903503,14.717445,1.190528,-344.949768,294.500488,0.000000
127.310005,64.943245,-345.083221,-0.001496,0.004687,0.119053,288.881989,14.716350,1.190528,-345.083221,294.500488,0.000000
127.720009,64.914574,-345.127686,-0.001505,0.004687,0.119053,288.754456,14.709852,1.190528,-345.127686,294.500488,0.000000
128.130005,64.891853,-345.127686,-0.001483,0.004687,0.119053,288.653381,14.704704,1.190528,-345.127686,294.500488,0.000000
128.540009,64.880684,-345.172180,-0.001500,0.004687,0.119053,288.603699,14.702173,1.190528,-345.172180,294.500488,0.000000
128.950012,64.846062,-345.083221,-0.001492,0.004687,0.119053,288.449677,14.694327,1.190528,-345.083221,294.500488,0.000000
129.360001,64.838982,-345.172180,-0.001500,0.004687,0.119053,288.418182,14.692723,1.190528,-345.172180,294.500488,0.000000
129.770004,64.829674,-345.083221,-0.001505,0.004687,0.119053,288.376801,14.690615,1.190528,-345.083221,294.500488,0.000000
130.180008,64.799507,-345.127686,-0.001509,0.004687,0.119053,288.242615,14.683779,1.190528,-345.127686,294.500488,0.000000
130.590012,64.791313,-345.216675,-0.001496,0.004687,0.119053,288.206146,14.681921,1.190528,-345.216675,294.500488,0.000000
131.000000,64.791313,-345.172180,-0.001492,0.004687,0.119053,288.206146,14.681921,1.190528,-345.172180,294.500488,0.000000
131.410004,64.773445,-345.216675,-0.001492,0.004687,0.119053,288.126678,14.677873,1.190528,-345.216675,294.500488,0.000000
131.820007,64.763756,-345.172180,-0.001496,0.004687,0.119053,288.083588,14.675677,1.190528,-345.172180,294.500488,0.000000
132.230011,64.747383,-345.261139,-0.001487,0.004687,0.119053,288.010742,14.671967,1.190528,-345.261139,294.500488,0.000000
132.639999,64.732475,-345.305634,-0.001496,0.004687,0.119061,287.944427,14.668589,1.190614,-345.305634,294.500488,0.000000
133.050003,64.722420,-345.261139,-0.001492,0.004687,0.119061,287.899689,14.666310,1.190614,-345.261139,294.500488,0.000000
133.460007,64.717964,-345.305634,-0.001483,0.004687,0.119061,287.879883,14.665300,1.190614,-345.305634,294.500488,0.000000
133.870010,64.703804,-345.261139,-0.001492,0.004687,0.119061,287.816895,14.662092,1.190614,-345.261139,294.500488,0.000000
134.279999,64.694496,-345.350098,-0.001475,0.004687,0.119061,287.775482,14.659982,1.190614,-345.350098,294.500488,0.000000
134.690002,64.687431,-345.394592,-0.001505,0.004687,0.119061,287.744080,14.658381,1.190614,-345.394592,294.500488,0.000000
135.100006,64.676994,-345.350098,-0.001496,0.004687,0.119061,287.697632,14.656016,1.190614,-345.350098,294.500488,0.000000
135.510010,64.657631,-345.394592,-0.001487,0.004687,0.119061,287.611511,14.651628,1.190614,-345.394592,294.500488,0.000000
135.920013,64.640877,-345.350098,-0.001500,0.004687,0.119061,287.536987,14.647833,1.190614,-345.350098,294.500488,0.000000
136.330002,64.634544,-345.350098,-0.001487,0.004687,0.119061,287.508820,14.646398,1.190614,-345.350098,294.500488,0.000000
136.740005,64.632683,-345.439056,-0.001492,0.004687,0.119061,287.500519,14.645975,1.190614,-345.439056,294.500488,0.000000
137.150009,64.609596,-345.439056,-0.001487,0.004687,0.119061,287.397827,14.640744,1.190614,-345.439056,294.500488,0.000000
137.560013,64.594704,-345.439056,-0.001500,0.004687,0.119061,287.331604,14.637368,1.190614,-345.439056,294.500488,0.000000
137.970001,64.586510,-345.439056,-0.001487,0.004687,0.119061,287.295135,14.635512,1.190614,-345.439056,294.500488,0.000000
138.380005,64.581673,-345.483551,-0.001479,0.004687,0.119061,287.273621,14.634417,1.190614,-345.483551,294.500488,0.000000
138.790009,66.433113,-345.528015,-0.001492,0.004679,0.118836,295.509247,15.053959,1.188359,-345.528015,294.500488,0.000000
139.200012,66.407417,-345.483551,-0.001475,0.004679,0.118836,295.394958,15.048136,1.188359,-345.483551,294.500488,0.000000
139.610001,66.370552,-345.572510,-0.001483,0.004679,0.118836,295.230957,15.039782,1.188359,-345.572510,294.500488,0.000000
140.020004,66.422676,-345.572510,-0.001487,0.004679,0.118836,295.462830,15.051593,1.188359,-345.572510,294.500488,0.000000
140.430008,66.407784,-345.528015,-0.001475,0.004679,0.118836,295.396576,15.048219,1.188359,-345.528015,294.500488,0.000000
140.840012,66.392525,-345.617004,-0.001492,0.004679,0.118836,295.328705,15.044762,1.188359,-345.617004,294.500488,0.000000
141.250000,66.380974,-345.528015,-0.001487,0.004679,0.118836,295.277313,15.042143,1.188359,-345.528015,294.500488,0.000000
141.660004,66.370918,-345.661469,-0.001492,0.004679,0.118836,295.232574,15.039865,1.188359,-345.661469,294.500488,0.000000
142.070007,66.359383,-345.617004,-0.001500,0.004679,0.118836,295.181274,15.037251,1.188359,-345.617004,294.500488,0.000000
142.480011,66.328102,-345.617004,-0.001470,0.004679,0.118836,295.042145,15.030163,1.188359,-345.617004,294.500488,0.000000
142.889999,66.318413,-345.750427,-0.001475,0.004679,0.118836,294.999023,15.027967,1.188359,-345.750427,294.500488,0.000000
143.300003,66.307243,-345.705963,-0.001479,0.004679,0.118836,294.949341,15.025436,1.188359,-345.705963,294.500488,0.000000
143.710007,66.297188,-345.750427,-0.001475,0.004679,0.118836,294.904633,15.023158,1.188359,-345.750427,294.500488,0.000000
144.120010,66.277824,-345.750427,-0.001483,0.004679,0.118836,294.818481,15.018770,1.188359,-345.750427,294.500488,0.000000
144.530014,66.258461,-345.705963,-0.001466,0.004679,0.118836,294.732361,15.014381,1.188359,-345.705963,1681.640991,0.000000
144.940002,66.306877,-345.750427,-0.001487,0.004678,0.118827,294.947723,15.025352,1.188273,-345.750427,0.118498,0.000000
145.350006,66.234261,-345.750427,-0.001479,0.004662,0.118420,294.624695,15.008898,1.184197,-345.750427,0.117813,0.000000
145.760010,66.181007,-345.794922,-0.001487,0.004637,0.117778,294.387817,14.996830,1.177779,-345.794922,0.117128,0.000000
146.170013,66.110634,-345.794922,-0.001479,0.004607,0.117015,294.074799,14.980884,1.170148,-345.794922,0.116442,0.000000
146.580002,66.127022,-345.794922,-0.001470,0.004582,0.116373,294.147675,14.984597,1.163730,-345.794922,0.115766,0.000000
146.990005,66.062218,-345.839386,-0.001487,0.004549,0.115540,293.859436,14.969913,1.155405,-345.839386,0.115081,0.000000
147.400009,66.075249,-345.839386,-0.001483,0.004528,0.115011,293.917389,14.972865,1.150115,-345.839386,0.114396,0.000000
147.810013,66.019035,-345.839386,-0.001462,0.004499,0.114274,293.667328,14.960127,1.142743,-345.839386,0.113711,0.000000
148.220001,65.669365,-345.972839,-0.001470,0.004475,0.113667,292.111938,14.880891,1.136673,-345.972839,0.113026,0.000000
148.630005,65.030373,-345.928345,-0.001475,0.004453,0.113112,289.269531,14.736093,1.131122,-345.928345,0.112349,0.000000
149.040009,64.014549,-345.928345,-0.001466,0.004427,0.112453,284.750946,14.505904,1.124532,-345.928345,0.111664,0.000000
149.450012,63.038933,-345.928345,-0.001475,0.004405,0.111889,280.411163,14.284826,1.118895,-345.928345,0.110979,0.000000
149.860001,61.457466,-345.972839,-0.001466,0.004375,0.111135,273.376465,13.926461,1.111350,-345.972839,0.110294,0.000000
150.270004,59.360634,-345.972839,-0.001466,0.004350,0.110502,264.049286,13.451312,1.105019,-345.972839,0.109609,0.000000
150.680008,57.590378,-345.928345,-0.001457,0.004331,0.109999,256.174805,13.050166,1.099989,-345.928345,0.108932,0.000000
151.090012,55.068298,-346.017303,-0.001462,0.004300,0.109210,244.956024,12.478655,1.092097,-346.017303,0.108247,0.000000
151.500000,52.823639,-345.972839,-0.001462,0.004277,0.108646,234.971283,11.970008,1.086460,-345.972839,0.107562,0.000000
151.910004,50.009247,-346.017303,-0.001466,0.004248,0.107900,222.452240,11.332257,1.079002,-346.017303,0.106877,0.000000
152.320007,47.539299,-346.061798,-0.001462,0.004229,0.107406,211.465363,10.772558,1.074059,-346.061798,0.106192,0.000000
152.730011,43.917603,-345.972839,-0.001466,0.004193,0.106495,195.355255,9.951871,1.064953,-345.972839,0.105515,0.000000
153.140015,41.469254,-346.150757,-0.001483,0.004170,0.105914,184.464447,9.397068,1.059143,-346.150757,0.104830,0.000000
153.550003,38.275787,-346.017303,-0.001500,0.004140,0.105160,170.259201,8.673417,1.051598,-346.017303,0.104145,0.000000
153.960007,35.654289,-346.106293,-0.001483,0.004120,0.104648,158.598206,8.079377,1.046481,-346.106293,0.103460,0.000000
154.370010,32.959427,-346.150757,-0.001487,0.004093,0.103954,146.610855,7.468713,1.039544,-346.150757,0.102775,0.000000
154.780014,29.167191,-346.106293,-0.001492,0.004057,0.103044,129.742142,6.609380,1.030438,-346.106293,0.102098,0.000000
155.190002,25.989731,-346.239716,-0.001483,0.004030,0.102359,115.608093,5.889358,1.023587,-346.239716,0.101413,0.000000
155.600006,23.329132,-346.150757,-0.001509,0.004005,0.101734,103.773163,5.286457,1.017343,-346.150757,0.100728,0.000000
156.010010,20.967171,-346.150757,-0.001505,0.003989,0.101309,93.266632,4.751228,1.013093,-346.150757,0.100043,0.000000
156.420013,17.149986,-346.284210,-0.001518,0.003952,0.100390,76.286949,3.886242,1.003901,-346.284210,0.099358,0.000000
156.830002,13.977371,-346.150757,-0.001509,0.003925,0.099705,62.174454,3.167318,0.997049,-346.150757,0.098682,0.000000
157.240005,11.081802,-346.284210,-0.001522,0.003900,0.099063,49.294319,2.511172,0.990632,-346.284210,0.097997,0.000000
157.650009,7.649269,-346.195251,-0.001522,0.003869,0.098265,34.025650,1.733349,0.982654,-346.195251,0.097311,0.000000
158.060013,5.390091,-346.239716,-0.001535,0.003852,0.097832,23.976322,1.221412,0.978317,-346.239716,0.096626,0.000000
158.470001,2.880295,-346.239716,-0.001531,0.003825,0.097155,12.812191,0.652684,0.971553,-346.239716,0.095941,0.000000
158.880005,-0.787567,-346.239716,-0.001526,0.003788,0.096227,-3.503273,-0.178465,0.962274,-346.239716,0.095265,0.000000
159.290009,-0.308701,-346.328674,-0.001544,0.003762,0.095542,-1.373169,-0.069953,0.955423,-346.328674,0.094580,0.000000
159.700012,-0.099426,-346.239716,-0.001569,0.003737,0.094909,-0.442270,-0.022530,0.949092,-346.239716,0.093895,0.000000
160.110001,-0.027931,-346.284210,-0.001578,0.003718,0.094450,-0.124244,-0.006329,0.944496,-346.284210,0.093209,0.000000
160.520004,-0.057724,-346.328674,-0.001591,0.003693,0.093799,-0.256769,-0.013080,0.937991,-346.328674,0.092524,0.000000
160.930008,-0.078201,-346.328674,-0.001604,0.003655,0.092837,-0.347857,-0.017721,0.928365,-346.328674,0.091848,0.000000
161.340012,-0.040588,-346.328674,-0.001604,0.003625,0.092065,-0.180546,-0.009197,0.920647,-346.328674,0.091163,0.000000
161.750015,-0.029045,-346.328674,-0.001608,0.003601,0.091475,-0.129199,-0.006582,0.914750,-346.328674,0.090478,0.000000
162.160004,-0.018250,-346.328674,-0.001604,0.003580,0.090929,-0.081178,-0.004135,0.909286,-346.328674,0.089793,0.000000
162.570007,-0.042824,-346.417633,-0.001613,0.003549,0.090157,-0.190490,-0.009704,0.901568,-346.417633,0.089107,0.000000
162.980011,-0.046181,-346.373169,-0.001608,0.003523,0.089472,-0.205422,-0.010465,0.894717,-346.373169,0.088431,0.000000
163.390015,-0.029793,-346.373169,-0.001600,0.003494,0.088743,-0.132525,-0.006751,0.887432,-346.373169,0.087746,0.000000
163.800003,-0.033516,-346.506622,-0.001591,0.003469,0.088110,-0.149086,-0.007595,0.881101,-346.506622,0.087061,0.000000
164.210007,-0.025696,-346.373169,-0.001604,0.003444,0.087477,-0.114301,-0.005823,0.874771,-346.373169,0.086376,0.000000
164.620010,-0.016762,-346.551086,-0.001604,0.003409,0.086592,-0.074560,-0.003798,0.865925,-346.551086,0.085691,0.000000
165.030014,-0.032402,-346.462128,-0.001595,0.003388,0.086046,-0.144131,-0.007342,0.860461,-346.462128,0.085014,0.000000
165.440002,-0.000374,-346.462128,-0.001587,0.003363,0.085422,-0.001663,-0.000085,0.854217,-346.462128,0.084329,0.000000
165.850006,-0.034264,-346.551086,-0.001587,0.003342,0.084884,-0.152412,-0.007764,0.848841,-346.551086,0.083644,0.000000
166.260010,-0.048409,-346.462128,-0.001591,0.003307,0.083991,-0.215332,-0.010970,0.839908,-346.462128,0.082959,0.000000
166.670013,-0.024956,-346.595581,-0.001595,0.003279,0.083280,-0.111009,-0.005655,0.832797,-346.595581,0.082274,0.000000
167.080002,-0.035004,-346.551086,-0.001582,0.003259,0.082777,-0.155704,-0.007932,0.827767,-346.551086,0.081597,0.000000
167.490005,-0.058090,-346.551086,-0.001582,0.003227,0.081961,-0.258398,-0.013163,0.819615,-346.551086,0.080912,0.000000
167.900009,-0.060326,-346.640045,-0.001604,0.003200,0.081276,-0.268342,-0.013670,0.812764,-346.640045,0.080227,0.000000
168.310013,-0.051018,-346.506622,-0.001600,0.003166,0.080418,-0.226938,-0.011561,0.804179,-346.506622,0.079542,0.000000
168.700012,-0.008942,-346.595581,-0.001617,0.003151,0.080045,-0.039774,-0.002026,0.800449,-346.595581,0.079915,0.000000