File: Data/compression 34/AutoNoHeating-17-34-reverse-1-1_11152024_203044.csv
Time (sec),S:Load (lbs),S:HL1 (DIM),S:LVDT (in),S:Position (in),Ch:Position (mm),Ch:Load (N),Ch:Stress (MPa),Ch:Strain (mm/mm),Ch:HL1 (DIM),Set Point (),Cycles ()
0.110000,-0.046547,-141.938721,-0.011529,-0.006913,-0.175596,-0.207051,-0.010548,-1.755959,-141.938721,-0.175379,0.000000
0.500000,-0.005585,-141.983200,-0.011520,-0.006852,-0.174044,-0.024842,-0.001266,-1.740435,-141.983200,-0.173384,0.000000
0.890000,-0.004097,-141.894241,-0.011395,-0.006623,-0.168224,-0.018224,-0.000928,-1.682244,-141.894241,-0.166880,0.000000
1.280000,-0.048035,-141.983200,-0.011141,-0.006366,-0.161703,-0.213669,-0.010885,-1.617029,-141.983200,-0.160376,0.000000
1.670000,-0.055107,-141.983200,-0.010861,-0.006107,-0.155129,-0.245129,-0.012487,-1.551293,-141.983200,-0.153889,0.000000
2.060000,-0.075218,-141.983200,-0.010602,-0.005853,-0.148677,-0.334587,-0.017045,-1.486772,-141.983200,-0.147385,0.000000
2.450000,-0.026810,-141.983200,-0.010348,-0.005601,-0.142268,-0.119255,-0.006075,-1.422684,-141.983200,-0.140898,0.000000
2.840000,-0.015266,-142.027679,-0.010076,-0.005345,-0.135764,-0.067908,-0.003459,-1.357642,-142.027679,-0.134394,0.000000
3.230000,-0.014145,-142.072159,-0.009835,-0.005091,-0.129312,-0.062920,-0.003205,-1.293120,-142.072159,-0.127890,0.000000
3.620000,-0.049896,-142.072159,-0.009550,-0.004834,-0.122773,-0.221950,-0.011307,-1.227731,-142.072159,-0.121403,0.000000
4.010000,-0.066650,-142.161118,-0.009296,-0.004573,-0.116165,-0.296476,-0.015103,-1.161649,-142.161118,-0.114899,0.000000
4.400000,-0.072235,-142.161118,-0.009028,-0.004318,-0.109669,-0.321318,-0.016369,-1.096694,-142.161118,-0.108395,0.000000
4.790000,-0.023087,-142.161118,-0.008752,-0.004065,-0.103243,-0.102694,-0.005231,-1.032432,-142.161118,-0.101908,0.000000
5.180000,0.008942,-142.250076,-0.008507,-0.003816,-0.096930,0.039774,0.002026,-0.969298,-142.250076,-0.095403,0.000000
5.570000,-0.031273,-142.161118,-0.008231,-0.003554,-0.090261,-0.139109,-0.007087,-0.902608,-142.161118,-0.088917,0.000000
5.960001,-0.054733,-142.339050,-0.007976,-0.003297,-0.083739,-0.243466,-0.012403,-0.837393,-142.339050,-0.082412,0.000000
6.350000,-0.064049,-142.205597,-0.007709,-0.003043,-0.077287,-0.284903,-0.014514,-0.772871,-142.205597,-0.075908,0.000000
6.740000,-0.020477,-142.250076,-0.007442,-0.002791,-0.070887,-0.091088,-0.004640,-0.708870,-142.250076,-0.069421,0.000000
7.130000,-0.011917,-142.294556,-0.007179,-0.002526,-0.064157,-0.053010,-0.002700,-0.641574,-142.294556,-0.062917,0.000000
7.520000,-0.014519,-142.294556,-0.006929,-0.002276,-0.057818,-0.064583,-0.003290,-0.578179,-142.294556,-0.056430,0.000000
7.910000,-0.048775,-142.383530,-0.006666,-0.002019,-0.051270,-0.216961,-0.011053,-0.512704,-142.383530,-0.049926,0.000000
8.300000,-0.091972,-142.294556,-0.006394,-0.001759,-0.044671,-0.409113,-0.020841,-0.446708,-142.294556,-0.043422,0.000000
8.690001,-0.080055,-142.339050,-0.006135,-0.001503,-0.038184,-0.356103,-0.018141,-0.381839,-142.339050,-0.036935,0.000000
9.080001,-0.035004,-142.428009,-0.005872,-0.001250,-0.031740,-0.155704,-0.007932,-0.317405,-142.428009,-0.030431,0.000000
9.470000,0.006332,-142.339050,-0.005614,-0.001001,-0.025427,0.028168,0.001435,-0.254271,-142.339050,-0.023944,0.000000
9.860001,-0.065163,-142.428009,-0.005351,-0.000738,-0.018741,-0.289858,-0.014766,-0.187407,-142.428009,-0.017440,0.000000
10.250001,-0.065536,-142.428009,-0.005088,-0.000485,-0.012315,-0.291521,-0.014851,-0.123146,-142.428009,-0.010936,0.000000
10.640000,-0.093834,-142.516968,-0.004833,-0.000227,-0.005776,-0.417394,-0.021263,-0.057757,-142.516968,-0.004449,0.000000
11.030001,0.026443,-142.472488,-0.004566,0.000020,0.000503,0.117626,0.005992,0.005030,-142.472488,0.002055,0.000000
11.420000,0.132568,-142.472488,-0.004518,0.000001,0.000017,0.589693,0.030040,0.000173,-142.472488,0.000217,0.000000
11.810000,0.167946,-142.561447,-0.004514,0.000001,0.000017,0.747060,0.038057,0.000173,-142.561447,0.000477,0.000000
12.200001,0.115067,-142.561447,-0.004510,0.000001,0.000026,0.511841,0.026074,0.000260,-142.561447,0.001127,0.000000
12.590000,0.222679,-142.605927,-0.004480,0.000028,0.000720,0.990526,0.050460,0.007198,-142.605927,0.001778,0.000000
12.980000,0.368652,-142.516968,-0.004467,0.000054,0.001370,1.639848,0.083538,0.013702,-142.516968,0.002428,0.000000
13.370001,0.599525,-142.605927,-0.004454,0.000079,0.001995,2.666822,0.135854,0.019946,-142.605927,0.003079,0.000000
13.760000,0.849754,-142.605927,-0.004419,0.000099,0.002524,3.779896,0.192557,0.025236,-142.605927,0.003729,0.000000
14.150001,1.073181,-142.650406,-0.004419,0.000123,0.003131,4.773748,0.243186,0.031307,-142.650406,0.004379,0.000000
14.540001,1.712914,-142.694885,-0.004376,0.000157,0.003998,7.619420,0.388152,0.039979,-142.694885,0.005030,0.000000
14.930000,2.115082,-142.650406,-0.004350,0.000178,0.004518,9.408354,0.479284,0.045182,-142.650406,0.005680,0.000000
15.320001,2.776413,-142.694885,-0.004333,0.000214,0.005446,12.350101,0.629144,0.054462,-142.694885,0.006322,0.000000
15.710001,3.130539,-142.694885,-0.004307,0.000235,0.005967,13.925333,0.709390,0.059665,-142.694885,0.006972,0.000000
16.100000,3.598236,-142.694885,-0.004277,0.000259,0.006574,16.005753,0.815372,0.065736,-142.694885,0.007623,0.000000
16.490002,4.190681,-142.783859,-0.004255,0.000284,0.007207,18.641083,0.949622,0.072066,-142.783859,0.008273,0.000000
16.880001,4.418945,-142.739365,-0.004238,0.000298,0.007571,19.656450,1.001347,0.075709,-142.739365,0.008924,0.000000
17.270000,5.111931,-142.783859,-0.004234,0.000328,0.008343,22.739004,1.158380,0.083427,-142.783859,0.009574,0.000000
17.660002,5.418770,-142.828339,-0.004195,0.000349,0.008854,24.103891,1.227911,0.088544,-142.828339,0.010225,0.000000
18.050001,6.059990,-142.783859,-0.004161,0.000381,0.009670,26.956181,1.373213,0.096696,-142.783859,0.010875,0.000000
18.440001,6.694511,-142.872818,-0.004152,0.000411,0.010450,29.778673,1.516998,0.104501,-142.872818,0.011525,0.000000
18.830002,7.202431,-142.828339,-0.004126,0.000434,0.011014,32.038013,1.632094,0.110138,-142.828339,0.012176,0.000000
19.220001,7.684280,-142.872818,-0.004122,0.000462,0.011742,34.181385,1.741283,0.117422,-142.872818,0.012826,0.000000
19.610001,7.768440,-142.872818,-0.004096,0.000478,0.012132,34.555748,1.760354,0.121325,-142.872818,0.013477,0.000000
20.000000,8.543343,-142.917297,-0.004066,0.000511,0.012982,38.002686,1.935949,0.129824,-142.917297,0.014127,0.000000
20.390001,8.867683,-142.961777,-0.004036,0.000537,0.013650,39.445427,2.009446,0.136501,-142.961777,0.014778,0.000000
20.780001,9.301491,-142.961777,-0.004005,0.000564,0.014335,41.375099,2.107748,0.143352,-142.961777,0.015428,0.000000
21.170000,9.588966,-142.961777,-0.003988,0.000591,0.015020,42.653854,2.172891,0.150203,-142.961777,0.016078,0.000000
21.560001,9.687271,-143.006256,-0.003967,0.000607,0.015428,43.091133,2.195167,0.154279,-143.006256,0.016729,0.000000
21.950001,10.279343,-143.050735,-0.003936,0.000638,0.016208,45.724800,2.329332,0.162084,-143.050735,0.017379,0.000000
22.340000,10.528465,-143.139694,-0.003906,0.000662,0.016816,46.832954,2.385784,0.168155,-143.139694,0.018030,0.000000
22.730001,10.719490,-143.006256,-0.003893,0.000690,0.017527,47.682674,2.429071,0.175266,-143.006256,0.018680,0.000000
23.120001,11.318634,-143.139694,-0.003880,0.000719,0.018255,50.347797,2.564839,0.182551,-143.139694,0.019330,0.000000
23.510000,11.378586,-143.139694,-0.003846,0.000740,0.018784,50.614479,2.578424,0.187841,-143.139694,0.019981,0.000000
23.900002,11.521576,-143.095215,-0.003820,0.000759,0.019287,51.250530,2.610826,0.192871,-143.095215,0.020631,0.000000
24.290001,12.158707,-143.139694,-0.003786,0.000794,0.020163,54.084629,2.755202,0.201630,-143.139694,0.021273,0.000000
24.680000,12.433891,-143.139694,-0.003786,0.000820,0.020822,55.308712,2.817560,0.208221,-143.139694,0.021923,0.000000
25.070002,12.440964,-143.228668,-0.003747,0.000839,0.021316,55.340172,2.819163,0.213164,-143.228668,0.022574,0.000000
25.460001,12.520653,-143.228668,-0.003742,0.000858,0.021793,55.694645,2.837220,0.217934,-143.228668,0.023224,0.000000
25.850000,13.584526,-143.228668,-0.003708,0.000900,0.022851,60.426991,3.078298,0.228514,-143.228668,0.023875,0.000000
26.240002,13.639259,-143.273148,-0.003682,0.000925,0.023493,60.670456,3.090700,0.234931,-143.273148,0.024525,0.000000
26.630001,13.924500,-143.184189,-0.003652,0.000950,0.024118,61.939266,3.155337,0.241175,-143.184189,0.025176,0.000000
27.020000,14.080521,-143.273148,-0.003626,0.000972,0.024699,62.633286,3.190691,0.246986,-143.273148,0.025826,0.000000
27.410002,14.318092,-143.273148,-0.003604,0.000995,0.025262,63.690056,3.244526,0.252623,-143.273148,0.026476,0.000000
27.800001,15.042358,-143.317627,-0.003591,0.001028,0.026121,66.911751,3.408647,0.261208,-143.317627,0.027127,0.000000
28.190001,15.001030,-143.317627,-0.003553,0.001049,0.026641,66.727913,3.399282,0.266412,-143.317627,0.027777,0.000000
28.580002,15.333557,-143.362106,-0.003531,0.001074,0.027292,68.207069,3.474634,0.272916,-143.362106,0.028428,0.000000
28.970001,15.671295,-143.406586,-0.003505,0.001100,0.027933,69.709404,3.551166,0.279333,-143.406586,0.029078,0.000000
29.360001,15.473198,-143.362106,-0.003484,0.001121,0.028480,68.828224,3.506277,0.284797,-143.362106,0.029728,0.000000
29.750002,16.370239,-143.406586,-0.003458,0.001154,0.029304,72.818459,3.709549,0.293036,-143.406586,0.030379,0.000000
30.140001,16.468178,-143.406586,-0.003445,0.001178,0.029911,73.254112,3.731742,0.299106,-143.406586,0.031029,0.000000
30.530001,16.823418,-143.451065,-0.003410,0.001202,0.030535,74.834297,3.812241,0.305350,-143.451065,0.031680,0.000000
30.920002,17.085571,-143.495544,-0.003385,0.001229,0.031229,76.000420,3.871646,0.312288,-143.495544,0.032330,0.000000
31.310001,16.976463,-143.495544,-0.003372,0.001251,0.031766,75.515083,3.846922,0.317665,-143.495544,0.032981,0.000000
31.700001,17.812065,-143.540024,-0.003350,0.001283,0.032590,79.232025,4.036272,0.325903,-143.540024,0.033631,0.000000
32.090000,17.908882,-143.495544,-0.003311,0.001305,0.033145,79.662689,4.058211,0.331454,-143.495544,0.034281,0.000000
32.480003,17.927505,-143.540024,-0.003298,0.001325,0.033657,79.745529,4.062431,0.336570,-143.540024,0.034932,0.000000
32.870003,18.051506,-143.628998,-0.003272,0.001346,0.034186,80.297112,4.090530,0.341860,-143.628998,0.035582,0.000000
33.260002,18.317749,-143.628998,-0.003268,0.001372,0.034854,81.481415,4.150861,0.348538,-143.628998,0.036224,0.000000
33.650002,19.384598,-143.628998,-0.003212,0.001409,0.035799,86.226997,4.392612,0.357991,-143.628998,0.036874,0.000000
34.040001,19.205482,-143.673477,-0.003195,0.001434,0.036432,85.430252,4.352025,0.364322,-143.673477,0.037525,0.000000
34.430000,19.195801,-143.628998,-0.003178,0.001456,0.036970,85.387184,4.349831,0.369698,-143.628998,0.038175,0.000000
34.820004,19.654564,-143.673477,-0.003134,0.001486,0.037742,87.427864,4.453788,0.377417,-143.673477,0.038826,0.000000
35.210003,19.672066,-143.717957,-0.003139,0.001507,0.038279,87.505722,4.457754,0.382793,-143.717957,0.039476,0.000000
35.600002,20.244034,-143.673477,-0.003117,0.001535,0.038982,90.049957,4.587364,0.389818,-143.673477,0.040127,0.000000
35.990002,20.300262,-143.717957,-0.003070,0.001563,0.039702,90.300079,4.600105,0.397016,-143.717957,0.040777,0.000000
36.380001,20.685669,-143.762436,-0.003048,0.001593,0.040465,92.014450,4.687440,0.404647,-143.762436,0.041427,0.000000
36.770000,20.913185,-143.806915,-0.003005,0.001619,0.041115,93.026497,4.738995,0.411152,-143.806915,0.042078,0.000000
37.160004,20.989151,-143.851395,-0.002984,0.001645,0.041792,93.364410,4.756210,0.417916,-143.851395,0.042728,0.000000
37.550003,21.015961,-143.806915,-0.002971,0.001666,0.042312,93.483665,4.762285,0.423119,-143.806915,0.043379,0.000000
37.940002,21.168259,-143.851395,-0.002940,0.001688,0.042884,94.161118,4.796796,0.428843,-143.851395,0.044029,0.000000
38.330002,21.168259,-143.895874,-0.002928,0.001706,0.043327,94.161118,4.796796,0.433266,-143.895874,0.044679,0.000000
38.720001,22.062325,-143.895874,-0.002897,0.001739,0.044168,98.138123,4.999394,0.441678,-143.895874,0.045330,0.000000
39.110001,22.090630,-143.895874,-0.002876,0.001761,0.044740,98.264030,5.005808,0.447402,-143.895874,0.045980,0.000000
39.500000,22.723289,-143.940353,-0.002863,0.001792,0.045512,101.078239,5.149171,0.455120,-143.940353,0.046631,0.000000
39.890003,22.576202,-143.984833,-0.002824,0.001816,0.046128,100.423965,5.115840,0.461277,-143.984833,0.047281,0.000000
40.280003,22.732224,-143.984833,-0.002820,0.001837,0.046657,101.117981,5.151196,0.466567,-143.984833,0.047932,0.000000
40.670002,22.964958,-143.984833,-0.002781,0.001861,0.047281,102.153236,5.203934,0.472811,-143.984833,0.048582,0.000000
41.060001,23.171249,-143.984833,-0.002768,0.001885,0.047871,103.070862,5.250680,0.478709,-143.984833,0.049232,0.000000
41.450001,24.066063,-144.073807,-0.002729,0.001917,0.048703,107.051193,5.453448,0.487034,-144.073807,0.049883,0.000000
41.840000,24.235123,-144.029312,-0.002712,0.001947,0.049449,107.803207,5.491757,0.494492,-144.029312,0.050533,0.000000
42.230003,24.009460,-144.118286,-0.002690,0.001964,0.049874,106.799416,5.440621,0.498742,-144.118286,0.051184,0.000000
42.620003,24.389656,-144.073807,-0.002669,0.001990,0.050551,108.490608,5.526775,0.505506,-144.073807,0.051825,0.000000
43.010002,24.535622,-144.118286,-0.002652,0.002012,0.051114,109.139893,5.559851,0.511143,-144.118286,0.052476,0.000000
43.400002,25.455383,-144.162766,-0.002608,0.002045,0.051955,113.231201,5.768272,0.519555,-144.162766,0.053126,0.000000
43.790001,25.798340,-144.207245,-0.002583,0.002074,0.052675,114.756744,5.845987,0.526753,-144.207245,0.053777,0.000000
44.180000,25.950638,-144.207245,-0.002565,0.002098,0.053300,115.434204,5.880498,0.532997,-144.207245,0.054427,0.000000
44.570004,26.372910,-144.251724,-0.002539,0.002121,0.053872,117.312561,5.976187,0.538721,-144.251724,0.055078,0.000000
44.960003,26.752731,-144.251724,-0.002527,0.002147,0.054540,119.002090,6.062255,0.545398,-144.251724,0.055728,0.000000
45.350002,27.369377,-144.207245,-0.002492,0.002177,0.055294,121.745071,6.201990,0.552943,-144.207245,0.056378,0.000000
45.740002,27.613281,-144.296204,-0.002475,0.002203,0.055953,122.830009,6.257259,0.559534,-144.296204,0.057029,0.000000
46.130001,27.418159,-144.296204,-0.002453,0.002221,0.056422,121.962067,6.213044,0.564217,-144.296204,0.057679,0.000000
46.520000,27.986397,-144.296204,-0.002436,0.002247,0.057063,124.489708,6.341808,0.570634,-144.296204,0.058330,0.000000
46.910004,28.624275,-144.340683,-0.002410,0.002274,0.057749,127.327133,6.486353,0.577486,-144.340683,0.058980,0.000000
47.300003,29.475517,-144.296204,-0.002376,0.002303,0.058503,131.113647,6.679248,0.585030,-144.296204,0.059630,0.000000
47.690002,29.857941,-144.385162,-0.002367,0.002332,0.059240,132.814758,6.765906,0.592402,-144.385162,0.060281,0.000000
48.080002,30.331230,-144.429642,-0.002328,0.002357,0.059865,134.920044,6.873155,0.598646,-144.429642,0.060931,0.000000
48.470001,30.362137,-144.385162,-0.002311,0.002378,0.060402,135.057526,6.880158,0.604023,-144.385162,0.061582,0.000000
48.860001,30.130524,-144.429642,-0.002289,0.002397,0.060888,134.027267,6.827674,0.608879,-144.429642,0.062232,0.000000
49.250004,31.872108,-144.429642,-0.002272,0.002435,0.061859,141.774216,7.222323,0.618592,-144.429642,0.062883,0.000000
49.640003,32.006905,-144.474136,-0.002238,0.002457,0.062414,142.373825,7.252868,0.624142,-144.474136,0.063533,0.000000
50.030003,31.913811,-144.518616,-0.002220,0.002473,0.062822,141.959717,7.231773,0.628218,-144.518616,0.064183,0.000000
50.420002,32.788139,-144.474136,-0.002195,0.002503,0.063576,145.848923,7.429899,0.635763,-144.474136,0.064834,0.000000
50.810001,32.894638,-144.518616,-0.002190,0.002522,0.064062,146.322662,7.454031,0.640620,-144.518616,0.065484,0.000000
51.200001,34.661179,-144.563095,-0.002156,0.002559,0.065007,154.180618,7.854336,0.650072,-144.563095,0.066135,0.000000
51.590004,35.160156,-144.563095,-0.002147,0.002584,0.065632,156.400192,7.967405,0.656316,-144.563095,0.066776,0.000000
51.980003,35.892982,-144.563095,-0.002100,0.002612,0.066351,159.659958,8.133466,0.663514,-144.563095,0.067427,0.000000
52.370003,36.265732,-144.563095,-0.002082,0.002635,0.066941,161.318039,8.217933,0.669412,-144.563095,0.068077,0.000000
52.760002,36.013260,-144.652054,-0.002070,0.002651,0.067331,160.194977,8.160722,0.673314,-144.652054,0.068728,0.000000
53.150002,37.573502,-144.607574,-0.002048,0.002683,0.068155,167.135284,8.514277,0.681553,-144.607574,0.069378,0.000000
53.540001,38.018860,-144.652054,-0.002026,0.002707,0.068762,169.116333,8.615196,0.687623,-144.652054,0.070028,0.000000
53.930004,38.412453,-144.652054,-0.002001,0.002730,0.069335,170.867126,8.704387,0.693347,-144.652054,0.070679,0.000000
54.320004,39.395523,-144.696533,-0.001988,0.002758,0.070046,175.240036,8.927154,0.700458,-144.696533,0.071329,0.000000
54.710003,39.554893,-144.741013,-0.001970,0.002779,0.070583,175.948959,8.963267,0.705835,-144.741013,0.071980,0.000000
55.100002,41.929512,-144.741013,-0.001944,0.002818,0.071581,186.511780,9.501363,0.715808,-144.741013,0.072630,0.000000
55.490002,41.857277,-144.741013,-0.001927,0.002836,0.072032,186.190460,9.484995,0.720318,-144.741013,0.073281,0.000000
55.880001,43.023170,-144.829971,-0.001897,0.002866,0.072795,191.376617,9.749190,0.727949,-144.829971,0.073931,0.000000
56.270004,43.567955,-144.785492,-0.001884,0.002888,0.073350,193.799942,9.872640,0.733500,-144.785492,0.074581,0.000000
56.660004,43.823776,-144.829971,-0.001867,0.002910,0.073905,194.937897,9.930610,0.739050,-144.829971,0.075232,0.000000
57.050003,45.968636,-144.829971,-0.001845,0.002945,0.074798,204.478699,10.416641,0.747982,-144.829971,0.075882,0.000000
57.440002,47.050011,-144.918945,-0.001824,0.002971,0.075466,209.288895,10.661685,0.754660,-144.918945,0.076533,0.000000
57.830002,48.172340,-144.874451,-0.001811,0.003001,0.076229,214.281265,10.916008,0.762291,-144.874451,0.077183,0.000000
58.220001,48.926392,-144.874451,-0.001785,0.003025,0.076828,217.635452,11.086879,0.768275,-144.874451,0.077834,0.000000
58.610004,49.729225,-144.918945,-0.001772,0.003049,0.077452,221.206635,11.268804,0.774519,-144.918945,0.078484,0.000000
59.000004,50.627762,-144.918945,-0.001755,0.003071,0.078016,225.203537,11.472415,0.780156,-144.918945,0.079134,0.000000
59.390003,51.184830,-145.007904,-0.001725,0.003093,0.078553,227.681488,11.598648,0.785533,-145.007904,0.079785,0.000000
59.780003,51.548264,-144.963425,-0.001712,0.003116,0.079152,229.298126,11.681004,0.791517,-144.963425,0.080435,0.000000
60.170002,53.519981,-145.007904,-0.001712,0.003140,0.079767,238.068771,12.127801,0.797674,-145.007904,0.081086,0.000000
60.560001,54.913399,-145.052383,-0.001669,0.003169,0.080487,244.266998,12.443554,0.804872,-145.052383,0.081727,0.000000
60.950005,56.620354,-145.007904,-0.001656,0.003201,0.081294,251.859909,12.830356,0.812937,-145.007904,0.082378,0.000000
61.340004,57.272377,-145.052383,-0.001638,0.003218,0.081736,254.760254,12.978106,0.817360,-145.052383,0.083028,0.000000
61.730003,58.639725,-145.052383,-0.001630,0.003246,0.082447,260.842529,13.287951,0.824471,-145.052383,0.083679,0.000000
62.120003,59.916969,-145.052383,-0.001625,0.003272,0.083106,266.523987,13.577379,0.831062,-145.052383,0.084329,0.000000
62.510002,61.184151,-145.096863,-0.001595,0.003296,0.083713,272.160706,13.864527,0.837133,-145.096863,0.084979,0.000000
62.900002,63.494728,-145.096863,-0.001591,0.003330,0.084589,282.438660,14.388111,0.845892,-145.096863,0.085630,0.000000
63.290005,64.018272,-145.141342,-0.001569,0.003351,0.085110,284.767487,14.506747,0.851095,-145.141342,0.086280,0.000000
63.680004,65.935616,-145.141342,-0.001548,0.003378,0.085795,293.296265,14.941224,0.857946,-145.141342,0.086931,0.000000
64.070000,65.568459,-145.230301,-0.001544,0.003379,0.085821,291.663055,14.858025,0.858207,-145.230301,0.015074,0.000000
64.460007,65.506279,-145.185822,-0.001535,0.003395,0.086237,291.386475,14.843935,0.862369,-145.185822,294.500488,0.000000
64.850006,64.762642,-145.230301,-0.001535,0.003398,0.086315,288.078613,14.675425,0.863150,-145.230301,294.500488,0.000000
65.240005,64.938042,-145.319260,-0.001518,0.003408,0.086575,288.858826,14.715171,0.865751,-145.319260,294.500488,0.000000
65.630005,65.308174,-145.274780,-0.001505,0.003420,0.086861,290.505280,14.799045,0.868613,-145.274780,294.500488,0.000000
66.020004,64.707161,-145.363754,-0.001513,0.003421,0.086887,287.831818,14.662852,0.868873,-145.363754,294.500488,0.000000
66.410004,65.516335,-145.319260,-0.001496,0.003433,0.087208,291.431213,14.846213,0.872082,-145.319260,294.500488,0.000000
66.800003,64.923134,-145.319260,-0.001496,0.003433,0.087208,288.792511,14.711793,0.872082,-145.319260,294.500488,0.000000
67.190002,66.648720,-145.363754,-0.001483,0.003438,0.087330,296.468323,15.102816,0.873296,-145.363754,294.500488,0.000000
67.580002,65.820564,-145.319260,-0.001470,0.003419,0.086835,292.784485,14.915154,0.868353,-145.319260,294.500488,0.000000
67.970001,65.280617,-145.363754,-0.001466,0.003419,0.086835,290.382690,14.792799,0.868353,-145.363754,294.500488,0.000000
68.360001,65.493248,-145.408234,-0.001466,0.003457,0.087807,291.328522,14.840981,0.878066,-145.408234,294.500488,0.000000
68.750000,65.265724,-145.452713,-0.001475,0.003457,0.087798,290.316437,14.789425,0.877979,-145.452713,294.500488,0.000000
69.140007,64.955162,-145.497192,-0.001462,0.003457,0.087815,288.934998,14.719049,0.878153,-145.497192,294.500488,0.000000
69.530006,64.982719,-145.497192,-0.001444,0.003462,0.087937,289.057587,14.725295,0.879367,-145.497192,294.500488,0.000000
69.920006,65.130928,-145.497192,-0.001466,0.003468,0.088075,289.716827,14.758880,0.880754,-145.497192,294.500488,0.000000
70.310005,65.309669,-145.541672,-0.001440,0.003473,0.088223,290.511932,14.799383,0.882229,-145.541672,294.500488,0.000000
70.700005,65.175240,-145.497192,-0.001462,0.003473,0.088223,289.913940,14.768920,0.882229,-145.497192,294.500488,0.000000
71.090004,64.978630,-145.586151,-0.001444,0.003475,0.088266,289.039368,14.724368,0.882662,-145.586151,294.500488,0.000000
71.480003,65.005058,-145.586151,-0.001440,0.003477,0.088327,289.156952,14.730357,0.883269,-145.586151,294.500488,0.000000
71.870003,64.886284,-145.586151,-0.001440,0.003479,0.088362,288.628601,14.703442,0.883616,-145.586151,294.500488,0.000000
72.260002,65.396049,-145.586151,-0.001440,0.003487,0.088570,290.896149,14.818957,0.885698,-145.586151,294.500488,0.000000
72.650002,65.257912,-145.630630,-0.001431,0.003487,0.088570,290.281677,14.787654,0.885698,-145.630630,294.500488,0.000000
73.040001,65.053474,-145.630630,-0.001436,0.003487,0.088570,289.372314,14.741328,0.885698,-145.630630,294.500488,0.000000
73.430000,64.864677,-145.675110,-0.001440,0.003487,0.088570,288.532501,14.698546,0.885698,-145.675110,294.500488,0.000000
73.820000,64.712379,-145.719589,-0.001431,0.003488,0.088596,287.855042,14.664035,0.885958,-145.719589,294.500488,0.000000
74.210007,65.898018,-145.719589,-0.001427,0.003502,0.088960,293.129028,14.932705,0.889600,-145.719589,294.500488,0.000000
74.600006,65.845512,-145.808563,-0.001423,0.003502,0.088960,292.895477,14.920807,0.889600,-145.808563,294.500488,0.000000
74.990005,65.655968,-145.719589,-0.001414,0.003502,0.088960,292.052338,14.877855,0.889600,-145.719589,294.500488,0.000000
75.380005,65.511497,-145.719589,-0.001431,0.003502,0.088960,291.409698,14.845118,0.889600,-145.719589,294.500488,0.000000
75.770004,65.343925,-145.808563,-0.001418,0.003502,0.088960,290.664307,14.807145,0.889600,-145.808563,294.500488,0.000000
76.160004,65.210243,-145.808563,-0.001410,0.003502,0.088960,290.069641,14.776852,0.889600,-145.808563,294.500488,0.000000
76.550003,65.055336,-145.808563,-0.001418,0.003502,0.088960,289.380585,14.741750,0.889600,-145.808563,294.500488,0.000000
76.940002,64.892235,-145.853043,-0.001410,0.003503,0.088969,288.655090,14.704790,0.889687,-145.853043,294.500488,0.000000
77.330002,65.860405,-145.853043,-0.001418,0.003515,0.089290,292.961700,14.924181,0.892896,-145.853043,294.500488,0.000000
77.720001,65.832100,-145.897522,-0.001410,0.003515,0.089290,292.835815,14.917768,0.892896,-145.897522,294.500488,0.000000
78.110001,65.756508,-145.897522,-0.001401,0.003515,0.089290,292.499542,14.900638,0.892896,-145.897522,294.500488,0.000000
78.500000,65.621712,-145.986481,-0.001410,0.003515,0.089290,291.899963,14.870092,0.892896,-145.986481,294.500488,0.000000
78.890007,65.534203,-145.986481,-0.001393,0.003515,0.089290,291.510681,14.850263,0.892896,-145.986481,294.500488,0.000000
79.280006,65.394188,-145.942001,-0.001414,0.003516,0.089298,290.887878,14.818535,0.892982,-145.942001,294.500488,0.000000
79.670006,65.286583,-146.119919,-0.001397,0.003516,0.089298,290.409210,14.794151,0.892982,-146.119919,294.500488,0.000000
80.060005,65.183800,-146.030960,-0.001397,0.003516,0.089298,289.952026,14.770861,0.892982,-146.030960,294.500488,0.000000
80.450005,65.049004,-146.075439,-0.001406,0.003516,0.089298,289.352417,14.740315,0.892982,-146.075439,294.500488,0.000000
80.840004,64.986076,-146.075439,-0.001406,0.003516,0.089307,289.072510,14.726055,0.893069,-146.075439,294.500488,0.000000
81.230003,64.852394,-146.164398,-0.001401,0.003516,0.089307,288.477844,14.695763,0.893069,-146.164398,294.500488,0.000000
81.620003,64.757439,-146.119919,-0.001410,0.003516,0.089307,288.055481,14.674245,0.893069,-146.119919,294.500488,0.000000
82.010002,64.674400,-146.164398,-0.001406,0.003516,0.089307,287.686096,14.655428,0.893069,-146.164398,294.500488,0.000000
82.400002,65.933022,-146.164398,-0.001401,0.003522,0.089454,293.284729,14.940637,0.894543,-146.164398,294.500488,0.000000
82.790001,65.851845,-146.164398,-0.001384,0.003522,0.089454,292.923645,14.922241,0.894543,-146.164398,294.500488,0.000000
83.180000,65.752037,-146.164398,-0.001401,0.003522,0.089454,292.479675,14.899625,0.894543,-146.164398,294.500488,0.000000
83.570007,65.585594,-146.253372,-0.001388,0.003522,0.089454,291.739288,14.861908,0.894543,-146.253372,294.500488,0.000000
83.960007,65.496223,-146.164398,-0.001375,0.003522,0.089454,291.341766,14.841657,0.894543,-146.164398,294.500488,0.000000
84.350006,65.375206,-146.208893,-0.001384,0.003522,0.089454,290.803436,14.814233,0.894543,-146.208893,294.500488,0.000000
84.740005,65.292534,-146.208893,-0.001393,0.003522,0.089454,290.435699,14.795500,0.894543,-146.208893,294.500488,0.000000
85.130005,65.222527,-146.253372,-0.001375,0.003522,0.089463,290.124298,14.779635,0.894630,-146.253372,294.500488,0.000000
85.520004,65.088097,-146.342331,-0.001393,0.003522,0.089463,289.526306,14.749174,0.894630,-146.342331,294.500488,0.000000
85.910004,65.010643,-146.297852,-0.001388,0.003522,0.089463,289.181793,14.731623,0.894630,-146.297852,294.500488,0.000000
86.300003,64.938774,-146.386810,-0.001397,0.003522,0.089463,288.862091,14.715337,0.894630,-146.386810,294.500488,0.000000
86.690002,64.834892,-146.386810,-0.001384,0.003523,0.089472,288.399994,14.691796,0.894717,-146.386810,294.500488,0.000000
87.080002,65.649269,-146.386810,-0.001375,0.003538,0.089853,292.022522,14.876337,0.898533,-146.386810,294.500488,0.000000
87.470001,65.642937,-146.386810,-0.001393,0.003538,0.089853,291.994354,14.874902,0.898533,-146.386810,294.500488,0.000000
87.860001,65.594536,-146.431290,-0.001384,0.003538,0.089853,291.779053,14.863934,0.898533,-146.431290,294.500488,0.000000
88.250008,65.568840,-146.475769,-0.001384,0.003538,0.089853,291.664764,14.858112,0.898533,-146.475769,294.500488,0.000000
88.640007,65.526390,-146.386810,-0.001388,0.003538,0.089853,291.475952,14.848493,0.898533,-146.386810,294.500488,0.000000
89.030006,65.480949,-146.520248,-0.001397,0.003538,0.089853,291.273804,14.838195,0.898533,-146.520248,294.500488,0.000000
89.420006,65.374825,-146.431290,-0.001384,0.003538,0.089853,290.801758,14.814147,0.898533,-146.431290,294.500488,0.000000
89.810005,65.306679,-146.520248,-0.001393,0.003538,0.089862,290.498627,14.798705,0.898619,-146.520248,294.500488,0.000000
90.200005,65.267586,-146.564728,-0.001380,0.003538,0.089862,290.324707,14.789846,0.898619,-146.564728,294.500488,0.000000
90.590004,65.226631,-146.564728,-0.001388,0.003538,0.089862,290.142548,14.780566,0.898619,-146.564728,294.500488,0.000000
90.980003,65.137260,-146.609207,-0.001388,0.003538,0.089862,289.744995,14.760314,0.898619,-146.609207,294.500488,0.000000
91.370003,65.071342,-146.653702,-0.001397,0.003538,0.089862,289.451782,14.745378,0.898619,-146.653702,294.500488,0.000000
91.760002,65.021080,-146.520248,-0.001384,0.003538,0.089862,289.228210,14.733988,0.898619,-146.520248,294.500488,0.000000
92.150002,64.965599,-146.653702,-0.001397,0.003538,0.089862,288.981415,14.721416,0.898619,-146.653702,294.500488,0.000000
92.540001,64.914955,-146.609207,-0.001384,0.003538,0.089862,288.756134,14.709940,0.898619,-146.609207,294.500488,0.000000
92.930008,64.839363,-146.698181,-0.001384,0.003538,0.089862,288.419891,14.692809,0.898619,-146.698181,294.500488,0.000000
93.320007,64.782753,-146.698181,-0.001380,0.003538,0.089862,288.168091,14.679982,0.898619,-146.698181,294.500488,0.000000
93.710007,64.737328,-146.787140,-0.001380,0.003538,0.089862,287.966003,14.669687,0.898619,-146.787140,294.500488,0.000000
94.100006,64.683327,-146.742661,-0.001375,0.003538,0.089871,287.725800,14.657451,0.898706,-146.742661,294.500488,0.000000
94.490005,65.869713,-146.742661,-0.001371,0.003552,0.090217,293.003113,14.926290,0.902175,-146.742661,294.500488,0.000000
94.880005,65.816841,-146.831619,-0.001393,0.003552,0.090217,292.767944,14.914310,0.902175,-146.831619,294.500488,0.000000
95.270004,65.839546,-146.787140,-0.001362,0.003552,0.090217,292.868927,14.919454,0.902175,-146.787140,294.500488,0.000000
95.660004,65.837318,-146.831619,-0.001375,0.003552,0.090217,292.859009,14.918950,0.902175,-146.831619,294.500488,0.000000
96.050003,65.755394,-146.831619,-0.001358,0.003552,0.090217,292.494598,14.900386,0.902175,-146.831619,294.500488,0.000000
96.440002,65.754280,-146.831619,-0.001375,0.003552,0.090217,292.489655,14.900133,0.902175,-146.831619,294.500488,0.000000
96.830002,65.749062,-146.965057,-0.001380,0.003552,0.090217,292.466431,14.898951,0.902175,-146.965057,294.500488,0.000000
97.220001,65.659691,-146.876099,-0.001380,0.003552,0.090217,292.068878,14.878698,0.902175,-146.876099,294.500488,0.000000
97.610008,65.591179,-146.876099,-0.001384,0.003552,0.090217,291.764130,14.863173,0.902175,-146.876099,294.500488,0.000000
98.000008,65.573677,-147.009537,-0.001375,0.003552,0.090217,291.686279,14.859208,0.902175,-147.009537,294.500488,0.000000
98.390007,65.553200,-146.920578,-0.001375,0.003552,0.090217,291.595184,14.854568,0.902175,-146.920578,294.500488,0.000000
98.780006,65.498085,-147.009537,-0.001362,0.003552,0.090217,291.350037,14.842078,0.902175,-147.009537,294.500488,0.000000
99.170006,65.461586,-147.009537,-0.001375,0.003552,0.090217,291.187683,14.833807,0.902175,-147.009537,294.500488,0.000000
99.560005,65.382271,-147.054031,-0.001371,0.003552,0.090217,290.834869,14.815834,0.902175,-147.054031,294.500488,0.000000
99.950005,65.343925,-147.054031,-0.001362,0.003552,0.090217,290.664307,14.807145,0.902175,-147.054031,294.500488,0.000000
100.340004,65.302589,-147.009537,-0.001358,0.003552,0.090217,290.480438,14.797779,0.902175,-147.009537,294.500488,0.000000
100.730003,65.279869,-147.142990,-0.001375,0.003552,0.090217,290.379364,14.792629,0.902175,-147.142990,294.500488,0.000000
101.120003,65.239281,-147.054031,-0.001367,0.003552,0.090217,290.198822,14.783432,0.902175,-147.054031,294.500488,0.000000
101.510002,65.188637,-147.098511,-0.001371,0.003552,0.090217,289.973541,14.771956,0.902175,-147.098511,294.500488,0.000000
101.900002,65.117897,-147.142990,-0.001358,0.003552,0.090217,289.658875,14.755926,0.902175,-147.142990,294.500488,0.000000
102.290009,65.081398,-147.142990,-0.001367,0.003552,0.090226,289.496521,14.747656,0.902262,-147.142990,294.500488,0.000000
102.680008,65.050499,-147.187469,-0.001367,0.003552,0.090226,289.359070,14.740654,0.902262,-147.187469,294.500488,0.000000
103.070007,65.002831,-147.231949,-0.001375,0.003552,0.090226,289.147034,14.729852,0.902262,-147.231949,294.500488,0.000000
103.460007,64.977882,-147.231949,-0.001367,0.003552,0.090226,289.036041,14.724199,0.902262,-147.231949,294.500488,0.000000
103.850006,64.929466,-147.187469,-0.001367,0.003552,0.090226,288.820679,14.713227,0.902262,-147.187469,294.500488,0.000000
104.240005,64.888512,-147.276428,-0.001350,0.003552,0.090226,288.638519,14.703947,0.902262,-147.276428,294.500488,0.000000
104.630005,64.837120,-147.320908,-0.001367,0.003552,0.090226,288.409912,14.692301,0.902262,-147.320908,294.500488,0.000000
105.020004,64.813286,-147.276428,-0.001358,0.003552,0.090226,288.303894,14.686900,0.902262,-147.276428,294.500488,0.000000
105.410004,64.775688,-147.320908,-0.001384,0.003553,0.090252,288.136658,14.678381,0.902522,-147.320908,294.500488,0.000000
105.800003,64.747383,-147.365387,-0.001345,0.003553,0.090252,288.010742,14.671967,0.902522,-147.365387,294.500488,0.000000
106.190002,64.723915,-147.320908,-0.001362,0.003553,0.090252,287.906342,14.666649,0.902522,-147.320908,294.500488,0.000000
106.580002,64.855370,-147.365387,-0.001358,0.003562,0.090478,288.491089,14.696436,0.904777,-147.365387,294.500488,0.000000
106.970009,65.629906,-147.409866,-0.001362,0.003564,0.090530,291.936401,14.871949,0.905297,-147.409866,294.500488,0.000000
107.360008,65.642189,-147.365387,-0.001367,0.003564,0.090530,291.991028,14.874733,0.905297,-147.365387,294.500488,0.000000
107.750008,65.641075,-147.409866,-0.001354,0.003564,0.090530,291.986084,14.874480,0.905297,-147.409866,294.500488,0.000000
108.140007,65.620216,-147.454346,-0.001375,0.003564,0.090530,291.893311,14.869754,0.905297,-147.454346,294.500488,0.000000
108.530006,65.613899,-147.498840,-0.001358,0.003564,0.090530,291.865204,14.868322,0.905297,-147.498840,294.500488,0.000000
108.920006,65.591927,-147.454346,-0.001362,0.003564,0.090530,291.767456,14.863343,0.905297,-147.454346,294.500488,0.000000
109.310005,65.571449,-147.587799,-0.001362,0.003564,0.090530,291.676361,14.858703,0.905297,-147.587799,294.500488,0.000000
109.700005,65.553566,-147.498840,-0.001345,0.003564,0.090530,291.596832,14.854650,0.905297,-147.498840,294.500488,0.000000
110.090004,65.532341,-147.498840,-0.001362,0.003564,0.090530,291.502411,14.849841,0.905297,-147.498840,294.500488,0.000000
110.480003,65.505898,-147.587799,-0.001350,0.003564,0.090530,291.384796,14.843848,0.905297,-147.587799,294.500488,0.000000
110.870003,65.477974,-147.543320,-0.001371,0.003564,0.090530,291.260590,14.837522,0.905297,-147.543320,294.500488,0.000000
111.260002,65.421745,-147.676758,-0.001367,0.003564,0.090530,291.010468,14.824780,0.905297,-147.676758,294.500488,0.000000
111.650002,65.403877,-147.721237,-0.001354,0.003564,0.090530,290.930969,14.820731,0.905297,-147.721237,294.500488,0.000000
112.040009,65.370735,-147.587799,-0.001362,0.003564,0.090530,290.783539,14.813220,0.905297,-147.587799,294.500488,0.000000
112.430008,65.345039,-147.721237,-0.001358,0.003564,0.090530,290.669250,14.807397,0.905297,-147.721237,294.500488,0.000000
112.820007,65.316734,-147.676758,-0.001354,0.003564,0.090530,290.543335,14.800983,0.905297,-147.676758,294.500488,0.000000
113.210007,65.285088,-147.765717,-0.001358,0.003564,0.090530,290.402588,14.793813,0.905297,-147.765717,294.500488,0.000000
113.600006,65.260506,-147.721237,-0.001362,0.003564,0.090530,290.293213,14.788242,0.905297,-147.721237,294.500488,0.000000
113.990005,65.255669,-147.765717,-0.001358,0.003564,0.090530,290.271698,14.787147,0.905297,-147.765717,294.500488,0.000000
114.380005,65.207268,-147.810196,-0.001354,0.003564,0.090530,290.056427,14.776178,0.905297,-147.810196,294.500488,0.000000
114.770004,65.189384,-147.810196,-0.001350,0.003564,0.090530,289.976868,14.772126,0.905297,-147.810196,294.500488,0.000000
115.160004,65.175606,-147.810196,-0.001358,0.003565,0.090538,289.915588,14.769003,0.905384,-147.810196,294.500488,0.000000
115.550003,65.134651,-147.810196,-0.001345,0.003565,0.090538,289.733398,14.759723,0.905384,-147.810196,294.500488,0.000000
115.940002,65.092201,-147.854675,-0.001358,0.003565,0.090538,289.544586,14.750103,0.905384,-147.854675,294.500488,0.000000
116.330002,65.084007,-147.988129,-0.001375,0.003565,0.090538,289.508118,14.748247,0.905384,-147.988129,294.500488,0.000000
116.720009,65.073586,-147.810196,-0.001358,0.003565,0.090547,289.461761,14.745886,0.905470,-147.810196,294.500488,0.000000
117.110008,65.035225,-147.988129,-0.001358,0.003565,0.090547,289.291138,14.737193,0.905470,-147.988129,294.500488,0.000000
117.500008,65.025917,-147.899155,-0.001354,0.003565,0.090547,289.249725,14.735084,0.905470,-147.899155,294.500488,0.000000
117.890007,65.003578,-147.943649,-0.001341,0.003565,0.090547,289.150360,14.730021,0.905470,-147.943649,294.500488,0.000000
118.280006,65.341316,-147.988129,-0.001371,0.003571,0.090694,290.652679,14.806554,0.906945,-147.988129,294.500488,0.000000
118.670006,65.366631,-147.988129,-0.001358,0.003571,0.090694,290.765289,14.812291,0.906945,-147.988129,294.500488,0.000000
119.060005,65.371483,-148.077087,-0.001358,0.003571,0.090694,290.786865,14.813390,0.906945,-148.077087,294.500488,0.000000
119.450005,65.367012,-148.032608,-0.001341,0.003571,0.090694,290.766998,14.812377,0.906945,-148.032608,294.500488,0.000000
119.840004,65.357323,-148.032608,-0.001358,0.003571,0.090694,290.723877,14.810181,0.906945,-148.032608,294.500488,0.000000
120.230003,65.337593,-148.121567,-0.001354,0.003571,0.090694,290.636139,14.805711,0.906945,-148.121567,294.500488,0.000000
120.620003,65.326790,-148.121567,-0.001350,0.003571,0.090694,290.588074,14.803262,0.906945,-148.121567,294.500488,0.000000
121.010002,65.314873,-148.121567,-0.001350,0.003571,0.090694,290.535065,14.800561,0.906945,-148.121567,294.500488,0.000000
121.400009,65.292168,-148.121567,-0.001345,0.003571,0.090694,290.434082,14.795417,0.906945,-148.121567,294.500488,0.000000
121.790009,65.275780,-148.166046,-0.001362,0.003571,0.090694,290.361176,14.791703,0.906945,-148.166046,294.500488,0.000000
122.180008,65.261253,-148.210526,-0.001354,0.003571,0.090694,290.296539,14.788412,0.906945,-148.210526,294.500488,0.000000
122.570007,65.232582,-148.210526,-0.001354,0.003571,0.090694,290.169006,14.781914,0.906945,-148.210526,294.500488,0.000000
122.960007,65.226631,-148.210526,-0.001358,0.003571,0.090694,290.142548,14.780566,0.906945,-148.210526,294.500488,0.000000
123.350006,65.195351,-148.210526,-0.001345,0.003571,0.090694,290.003418,14.773478,0.906945,-148.210526,294.500488,0.000000
123.740005,65.165184,-148.210526,-0.001350,0.003571,0.090694,289.869202,14.766642,0.906945,-148.210526,294.500488,0.000000
124.130005,65.149544,-148.299484,-0.001345,0.003571,0.090694,289.799652,14.763098,0.906945,-148.299484,294.500488,0.000000
124.520004,65.114906,-148.299484,-0.001341,0.003571,0.090703,289.645569,14.755248,0.907031,-148.299484,1681.640991,0.000000
124.910004,65.110069,-148.343979,-0.001350,0.003562,0.090469,289.624054,14.754152,0.904690,-148.343979,0.090313,0.000000
125.300003,65.040062,-148.299484,-0.001345,0.003543,0.089992,289.312653,14.738289,0.899920,-148.299484,0.089662,0.000000
125.690002,64.922401,-148.388458,-0.001350,0.003523,0.089480,288.789276,14.711626,0.894804,-148.388458,0.089012,0.000000
126.080009,64.929100,-148.432938,-0.001328,0.003501,0.088934,288.819061,14.713144,0.889340,-148.432938,0.088362,0.000000
126.470009,64.878822,-148.343979,-0.001332,0.003473,0.088223,288.595428,14.701751,0.882229,-148.343979,0.087711,0.000000
126.860008,64.879951,-148.477417,-0.001337,0.003452,0.087685,288.600433,14.702006,0.876852,-148.477417,0.087061,0.000000
127.250008,64.796532,-148.432938,-0.001328,0.003422,0.086913,288.229370,14.683104,0.869134,-148.432938,0.086410,0.000000
127.640007,64.752968,-148.432938,-0.001332,0.003398,0.086306,288.035583,14.673232,0.863063,-148.432938,0.085760,0.000000
128.029999,64.737694,-148.477417,-0.001337,0.003377,0.085769,287.967651,14.669771,0.857686,-148.477417,0.085110,0.000000
128.420013,64.638649,-148.477417,-0.001341,0.003349,0.085057,287.527069,14.647327,0.850575,-148.477417,0.084459,0.000000
128.810013,64.253242,-148.566376,-0.001345,0.003327,0.084494,285.812683,14.559994,0.844938,-148.566376,0.083809,0.000000
129.200012,63.480202,-148.566376,-0.001319,0.003304,0.083921,282.374054,14.384819,0.839214,-148.566376,0.083158,0.000000
129.590012,62.544052,-148.477417,-0.001341,0.003279,0.083297,278.209839,14.172685,0.832970,-148.477417,0.082508,0.000000
129.980011,61.600464,-148.566376,-0.001319,0.003260,0.082803,274.012543,13.958864,0.828027,-148.566376,0.081857,0.000000
130.370010,60.025696,-148.566376,-0.001332,0.003236,0.082187,267.007629,13.602017,0.821870,-148.566376,0.081207,0.000000
130.760010,58.238312,-148.610855,-0.001315,0.003209,0.081519,259.056946,13.196990,0.815192,-148.610855,0.080557,0.000000
131.150009,56.225639,-148.610855,-0.001337,0.003182,0.080834,250.104141,12.740911,0.808341,-148.610855,0.079906,0.000000
131.540009,54.285950,-148.610855,-0.001319,0.003161,0.080296,241.475967,12.301373,0.802964,-148.610855,0.079256,0.000000
131.930008,51.681206,-148.699814,-0.001328,0.003134,0.079611,229.889481,11.711128,0.796113,-148.699814,0.078605,0.000000
132.320007,49.215355,-148.699814,-0.001319,0.003110,0.078996,218.920837,11.152358,0.789956,-148.699814,0.077955,0.000000
132.710007,46.766258,-148.744293,-0.001332,0.003087,0.078415,208.026703,10.597385,0.784145,-148.744293,0.077304,0.000000
133.100006,44.703316,-148.699814,-0.001332,0.003067,0.077894,198.850281,10.129916,0.778942,-148.699814,0.076654,0.000000
133.490005,41.350105,-148.744293,-0.001341,0.003037,0.077148,183.934448,9.370069,0.771484,-148.744293,0.076012,0.000000
133.880005,38.256805,-148.788788,-0.001328,0.003006,0.076351,170.174774,8.669116,0.763506,-148.788788,0.075362,0.000000
134.270004,35.296440,-148.788788,-0.001332,0.002980,0.075683,157.006409,7.998288,0.756828,-148.788788,0.074711,0.000000
134.660004,32.994438,-148.877747,-0.001345,0.002957,0.075110,146.766586,7.476646,0.751104,-148.877747,0.074061,0.000000
135.050003,30.066475,-148.833267,-0.001345,0.002932,0.074469,133.742355,6.813160,0.744687,-148.833267,0.073411,0.000000
135.440002,27.420769,-148.877747,-0.001354,0.002905,0.073792,121.973671,6.213635,0.737922,-148.877747,0.072760,0.000000
135.830002,24.950447,-148.922226,-0.001354,0.002882,0.073211,110.985130,5.653852,0.732112,-148.922226,0.072110,0.000000
136.220001,21.788261,-148.877747,-0.001367,0.002853,0.072465,96.919029,4.937291,0.724654,-148.877747,0.071459,0.000000
136.610001,19.358528,-148.922226,-0.001380,0.002831,0.071919,86.111031,4.386705,0.719190,-148.922226,0.070809,0.000000
137.000000,16.580261,-148.922226,-0.001380,0.002805,0.071243,73.752686,3.757141,0.712426,-148.922226,0.070159,0.000000
137.389999,13.666069,-148.966705,-0.001380,0.002777,0.070540,60.789711,3.096775,0.705401,-148.966705,0.069508,0.000000
137.780014,11.228149,-148.922226,-0.001393,0.002758,0.070054,49.945305,2.544335,0.700545,-148.922226,0.068858,0.000000
138.170013,7.241905,-148.966705,-0.001388,0.002719,0.069075,32.213604,1.641039,0.690745,-148.966705,0.068207,0.000000
138.560013,5.309662,-149.011185,-0.001393,0.002701,0.068615,23.618555,1.203187,0.686149,-149.011185,0.067557,0.000000
138.950012,2.429359,-149.011185,-0.001414,0.002672,0.067869,10.806331,0.550501,0.678691,-149.011185,0.066906,0.000000
139.340012,-0.018990,-149.100143,-0.001414,0.002648,0.067262,-0.084470,-0.004303,0.672620,-149.100143,0.066256,0.000000
139.730011,-1.817177,-149.011185,-0.001414,0.002627,0.066716,-8.083206,-0.411778,0.667157,-149.011185,0.065606,0.000000
140.120010,-0.293800,-149.100143,-0.001466,0.002596,0.065944,-1.306889,-0.066576,0.659438,-149.100143,0.064955,0.000000
140.510010,-0.012283,-149.144623,-0.001487,0.002573,0.065363,-0.054639,-0.002783,0.653628,-149.144623,0.064305,0.000000
140.900009,0.036865,-149.144623,-0.001505,0.002549,0.064756,0.163985,0.008354,0.647557,-149.144623,0.063654,0.000000
141.290009,-0.012657,-149.144623,-0.001552,0.002519,0.063993,-0.056302,-0.002868,0.639926,-149.144623,0.063004,0.000000
141.680008,-0.005959,-149.189117,-0.001565,0.002495,0.063377,-0.026505,-0.001350,0.633769,-149.189117,0.062354,0.000000
142.070007,-0.048775,-149.144623,-0.001600,0.002468,0.062683,-0.216961,-0.011053,0.626831,-149.144623,0.061703,0.000000
142.460007,0.000748,-149.189117,-0.001625,0.002444,0.062085,0.003326,0.000169,0.620847,-149.189117,0.061061,0.000000
142.850006,-0.003723,-149.189117,-0.001660,0.002419,0.061434,-0.016561,-0.000844,0.614343,-149.189117,0.060411,0.000000
143.240005,-0.001862,-149.322556,-0.001694,0.002390,0.060714,-0.008281,-0.000422,0.607145,-149.322556,0.059761,0.000000
143.630005,-0.015640,-149.278076,-0.001716,0.002366,0.060090,-0.069571,-0.003544,0.600901,-149.278076,0.059110,0.000000
144.020004,-0.039093,-149.278076,-0.001755,0.002350,0.059682,-0.173894,-0.008859,0.596825,-149.278076,0.058460,0.000000
144.410004,-0.047661,-149.322556,-0.001776,0.002316,0.058833,-0.212006,-0.010800,0.588326,-149.322556,0.057809,0.000000
144.800003,-0.016754,-149.367035,-0.001824,0.002292,0.058208,-0.074526,-0.003797,0.582082,-149.367035,0.057159,0.000000
145.190002,-0.007820,-149.367035,-0.001837,0.002267,0.057584,-0.034786,-0.001772,0.575838,-149.367035,0.056508,0.000000
145.580002,-0.029411,-149.367035,-0.001867,0.002240,0.056899,-0.130828,-0.006665,0.568987,-149.367035,0.055858,0.000000
145.970001,-0.024948,-149.367035,-0.001884,0.002217,0.056309,-0.110975,-0.005653,0.563090,-149.367035,0.055208,0.000000
146.360001,-0.059578,-149.411514,-0.001914,0.002190,0.055633,-0.265016,-0.013501,0.556325,-149.411514,0.054557,0.000000
146.750000,-0.050636,-149.411514,-0.001966,0.002161,0.054878,-0.225241,-0.011474,0.548780,-149.411514,0.053907,0.000000
147.139999,-0.059578,-149.500473,-0.001966,0.002137,0.054280,-0.265016,-0.013501,0.542797,-149.500473,0.053256,0.000000
147.530014,-0.068886,-149.455994,-0.002001,0.002115,0.053725,-0.306419,-0.015610,0.537246,-149.455994,0.052606,0.000000
147.920013,-0.002975,-149.500473,-0.002035,0.002081,0.052866,-0.013236,-0.000674,0.528661,-149.500473,0.051955,0.000000
148.310013,-0.056229,-149.589432,-0.002065,0.002061,0.052346,-0.250117,-0.012742,0.523457,-149.589432,0.051305,0.000000
148.700012,-0.045052,-149.544952,-0.002082,0.002033,0.051626,-0.200399,-0.010209,0.516259,-149.544952,0.050655,0.000000
149.090012,-0.032021,-149.544952,-0.002117,0.002007,0.050976,-0.142435,-0.007256,0.509755,-149.544952,0.050004,0.000000
149.480011,-0.038727,-149.500473,-0.002121,0.001985,0.050421,-0.172265,-0.008776,0.504205,-149.500473,0.049354,0.000000
149.870010,-0.048409,-149.589432,-0.002164,0.001952,0.049588,-0.215332,-0.010970,0.495880,-149.589432,0.048703,0.000000
150.260010,-0.096069,-149.589432,-0.002190,0.001930,0.049033,-0.427338,-0.021770,0.490329,-149.589432,0.048053,0.000000
150.650009,-0.083778,-149.544952,-0.002216,0.001906,0.048417,-0.372665,-0.018984,0.484172,-149.544952,0.047403,0.000000
151.040009,-0.065910,-149.722885,-0.002259,0.001885,0.047871,-0.293184,-0.014935,0.478709,-149.722885,0.046752,0.000000
151.430008,-0.062553,-149.633926,-0.002264,0.001862,0.047298,-0.278251,-0.014175,0.472985,-149.633926,0.046110,0.000000
151.820007,-0.073357,-149.678406,-0.002302,0.001827,0.046405,-0.326307,-0.016623,0.464052,-149.678406,0.045460,0.000000
152.210007,-0.091599,-149.722885,-0.002311,0.001806,0.045876,-0.407451,-0.020757,0.458762,-149.722885,0.044810,0.000000
152.600006,-0.076332,-149.722885,-0.002350,0.001781,0.045234,-0.339542,-0.017297,0.452345,-149.722885,0.044159,0.000000
152.990005,-0.062927,-149.767365,-0.002371,0.001757,0.044619,-0.279914,-0.014260,0.446188,-149.767365,0.043509,0.000000
153.380005,-0.077454,-149.722885,-0.002384,0.001729,0.043925,-0.344531,-0.017551,0.439250,-149.722885,0.042858,0.000000
153.770004,-0.110962,-149.767365,-0.002432,0.001702,0.043231,-0.493583,-0.025144,0.432312,-149.767365,0.042208,0.000000
154.160004,-0.091599,-149.811844,-0.002453,0.001681,0.042685,-0.407451,-0.020757,0.426849,-149.811844,0.041557,0.000000
154.550003,-0.067024,-149.811844,-0.002462,0.001654,0.042000,-0.298139,-0.015188,0.419997,-149.811844,0.040907,0.000000
154.940002,-0.083038,-149.856323,-0.002514,0.001623,0.041237,-0.369373,-0.018817,0.412366,-149.856323,0.040257,0.000000
155.330002,-0.071495,-149.811844,-0.002531,0.001602,0.040690,-0.318026,-0.016201,0.406902,-149.811844,0.039606,0.000000
155.720001,-0.071121,-149.900803,-0.002574,0.001571,0.039901,-0.316363,-0.016116,0.399011,-149.900803,0.038956,0.000000
156.110001,-0.078941,-149.945282,-0.002578,0.001548,0.039311,-0.351149,-0.017888,0.393113,-149.945282,0.038305,0.000000
156.500000,-0.053993,-149.945282,-0.002617,0.001522,0.038652,-0.240174,-0.012235,0.386523,-149.945282,0.037655,0.000000
156.890015,-0.074844,-149.989761,-0.002634,0.001496,0.037993,-0.332924,-0.016960,0.379932,-149.989761,0.037005,0.000000
157.280014,-0.068138,-149.900803,-0.002660,0.001471,0.037369,-0.303093,-0.015440,0.373688,-149.900803,0.036354,0.000000
157.670013,-0.059952,-149.989761,-0.002695,0.001443,0.036658,-0.266679,-0.013585,0.366576,-149.989761,0.035704,0.000000
158.060013,-0.062553,-149.989761,-0.002716,0.001423,0.036155,-0.278251,-0.014175,0.361546,-149.989761,0.035053,0.000000
158.450012,-0.077820,-149.989761,-0.002746,0.001393,0.035374,-0.346160,-0.017634,0.353741,-149.989761,0.034403,0.000000
158.840012,-0.032768,-150.034241,-0.002772,0.001365,0.034672,-0.145760,-0.007425,0.346717,-150.034241,0.034594,0.000000
158.900009,-0.023827,-149.989761,-0.002772,0.001365,0.034672,-0.105986,-0.005399,0.346717,-149.989761,0.034594,0.000000