File: Data/compression 18/AutoNoHeating-17-18-reverse-1-4_09092024_172140.csv
Time (sec),S:Load (lbs),S:HL1 (DIM),S:LVDT (in),S:Position (in),Ch:Position (mm),Ch:Load (N),Ch:Stress (MPa),Ch:Strain (mm/mm),Ch:HL1 (DIM),Set Point (),Cycles ()
0.110000,-0.079689,-205.190628,-0.010042,-0.005798,-0.147264,-0.354474,-0.018058,-1.472642,-205.190628,-0.146986,0.000000
0.490000,-0.033142,-205.279587,-0.010050,-0.005767,-0.146492,-0.147423,-0.007510,-1.464921,-205.279587,-0.145720,0.000000
0.870000,-0.048035,-205.279587,-0.009921,-0.005529,-0.140448,-0.213669,-0.010885,-1.404476,-205.279587,-0.139389,0.000000
1.250000,-0.040588,-205.235107,-0.009675,-0.005288,-0.134316,-0.180546,-0.009197,-1.343161,-205.235107,-0.133059,0.000000
1.630000,-0.060699,-205.324066,-0.009425,-0.005038,-0.127977,-0.270005,-0.013755,-1.279771,-205.324066,-0.126728,0.000000
2.010000,-0.088249,-205.413025,-0.009149,-0.004784,-0.121507,-0.392552,-0.019998,-1.215072,-205.413025,-0.120398,0.000000
2.390000,-0.055481,-205.501999,-0.008903,-0.004532,-0.115116,-0.246792,-0.012572,-1.151161,-205.501999,-0.114066,0.000000
2.770000,-0.047661,-205.413025,-0.008653,-0.004288,-0.108915,-0.212006,-0.010800,-1.089149,-205.413025,-0.107736,0.000000
3.150000,0.002235,-205.501999,-0.008407,-0.004041,-0.102654,0.009944,0.000507,-1.026539,-205.501999,-0.101405,0.000000
3.530000,-0.034256,-205.501999,-0.008149,-0.003786,-0.096167,-0.152378,-0.007763,-0.961666,-205.501999,-0.095074,0.000000
3.910000,-0.052879,-205.546478,-0.007881,-0.003545,-0.090044,-0.235219,-0.011983,-0.900442,-205.546478,-0.088744,0.000000
4.290000,-0.067398,-205.679916,-0.007644,-0.003295,-0.083696,-0.299802,-0.015273,-0.836961,-205.679916,-0.082413,0.000000
4.670000,-0.042824,-205.635437,-0.007381,-0.003046,-0.077357,-0.190490,-0.009704,-0.773572,-205.635437,-0.076082,0.000000
5.050000,-0.010056,-205.679916,-0.007131,-0.002798,-0.071070,-0.044729,-0.002279,-0.710697,-205.679916,-0.069751,0.000000
5.430000,-0.005585,-205.679916,-0.006864,-0.002548,-0.064730,-0.024842,-0.001266,-0.647300,-205.679916,-0.063420,0.000000
5.810000,-0.071121,-205.813354,-0.006618,-0.002300,-0.058417,-0.316363,-0.016116,-0.584168,-205.813354,-0.057090,0.000000
6.190000,-0.039841,-205.724396,-0.006355,-0.002043,-0.051886,-0.177220,-0.009028,-0.518864,-205.724396,-0.050759,0.000000
6.570000,-0.054367,-205.768875,-0.006092,-0.001794,-0.045556,-0.241837,-0.012320,-0.455558,-205.768875,-0.044429,0.000000
6.950000,-0.030907,-205.813354,-0.005846,-0.001545,-0.039251,-0.137480,-0.007004,-0.392509,-205.813354,-0.038097,0.000000
7.330000,-0.002975,-205.857849,-0.005579,-0.001293,-0.032842,-0.013236,-0.000674,-0.328423,-205.857849,-0.031767,0.000000
7.710001,-0.023460,-205.946808,-0.005346,-0.001046,-0.026581,-0.104357,-0.005316,-0.265806,-205.946808,-0.025436,0.000000
8.090000,-0.041702,-205.946808,-0.005083,-0.000804,-0.020423,-0.185501,-0.009450,-0.204233,-205.946808,-0.019105,0.000000
8.470000,-0.051384,-205.991287,-0.004829,-0.000548,-0.013928,-0.228567,-0.011644,-0.139277,-205.991287,-0.012775,0.000000
8.850000,-0.018616,-205.946808,-0.004562,-0.000299,-0.007606,-0.082807,-0.004218,-0.076061,-205.946808,-0.006443,0.000000
9.230000,0.007820,-206.080246,-0.004316,-0.000051,-0.001292,0.034786,0.001772,-0.012922,-206.080246,-0.000113,0.000000
9.610001,0.138519,-206.169205,-0.004212,-0.000001,-0.000017,0.616165,0.031389,-0.000174,-206.169205,0.000191,0.000000
9.990001,0.124001,-206.169205,-0.004208,-0.000001,-0.000017,0.551582,0.028099,-0.000174,-206.169205,0.000364,0.000000
10.370001,0.121391,-206.213684,-0.004225,-0.000000,-0.000009,0.539975,0.027508,-0.000091,-206.213684,0.000997,0.000000
10.750001,0.235336,-206.213684,-0.004199,0.000028,0.000711,1.046828,0.053328,0.007108,-206.213684,0.001631,0.000000
11.130000,0.382797,-206.258163,-0.004169,0.000056,0.001413,1.702767,0.086743,0.014133,-206.258163,0.002263,0.000000
11.510000,0.594681,-206.391617,-0.004156,0.000078,0.001977,2.645272,0.134757,0.019772,-206.391617,0.002896,0.000000
11.890000,0.781982,-206.302658,-0.004135,0.000097,0.002462,3.478431,0.177200,0.024625,-206.302658,0.003530,0.000000
12.270000,1.178185,-206.347137,-0.004105,0.000127,0.003235,5.240827,0.266980,0.032346,-206.347137,0.004163,0.000000
12.650001,1.476830,-206.391617,-0.004105,0.000153,0.003876,6.569266,0.334654,0.038765,-206.391617,0.004795,0.000000
13.030001,1.824249,-206.480576,-0.004092,0.000176,0.004466,8.114666,0.413381,0.044662,-206.480576,0.005428,0.000000
13.410001,2.307961,-206.525055,-0.004061,0.000202,0.005126,10.266321,0.522991,0.051255,-206.525055,0.006062,0.000000
13.790001,2.615547,-206.569534,-0.004040,0.000222,0.005636,11.634535,0.592691,0.056365,-206.569534,0.006695,0.000000
14.170001,3.300339,-206.569534,-0.004001,0.000254,0.006443,14.680640,0.747867,0.064434,-206.569534,0.007328,0.000000
14.550001,3.461205,-206.658493,-0.003992,0.000270,0.006851,15.396207,0.784320,0.068507,-206.658493,0.007961,0.000000
14.930000,4.051414,-206.658493,-0.003958,0.000299,0.007597,18.021591,0.918064,0.075970,-206.658493,0.008594,0.000000
15.310000,4.556351,-206.702972,-0.003936,0.000326,0.008273,20.267660,1.032484,0.082730,-206.702972,0.009236,0.000000
15.690001,4.989044,-206.747467,-0.003936,0.000347,0.008820,22.192377,1.130534,0.088196,-206.747467,0.009869,0.000000
16.070002,5.696556,-206.702972,-0.003893,0.000380,0.009643,25.339546,1.290858,0.096432,-206.702972,0.010502,0.000000
16.450001,6.015678,-206.791946,-0.003880,0.000403,0.010242,26.759073,1.363172,0.102419,-206.791946,0.011135,0.000000
16.830000,6.302773,-206.925385,-0.003872,0.000421,0.010684,28.036133,1.428229,0.106840,-206.925385,0.011768,0.000000
17.210001,6.788353,-206.925385,-0.003842,0.000445,0.011299,30.196102,1.538263,0.112994,-206.925385,0.012401,0.000000
17.590000,7.196098,-206.925385,-0.003811,0.000469,0.011924,32.009846,1.630659,0.119239,-206.925385,0.013034,0.000000
17.970001,7.688004,-206.925385,-0.003786,0.000497,0.012635,34.197948,1.742127,0.126355,-206.925385,0.013667,0.000000
18.350000,7.862648,-207.014343,-0.003768,0.000518,0.013147,34.974804,1.781701,0.131472,-207.014343,0.014300,0.000000
18.730001,8.210815,-207.014343,-0.003738,0.000546,0.013858,36.523533,1.860597,0.138580,-207.014343,0.014934,0.000000
19.110001,8.542969,-207.058823,-0.003742,0.000571,0.014491,38.001022,1.935864,0.144908,-207.058823,0.015567,0.000000
19.490002,8.235390,-207.058823,-0.003725,0.000574,0.014578,36.632843,1.866166,0.145779,-207.058823,0.016199,0.000000
19.870001,9.193130,-207.103302,-0.003682,0.000622,0.015810,40.893085,2.083193,0.158095,-207.103302,0.016833,0.000000
20.250002,9.399055,-207.236755,-0.003669,0.000646,0.016399,41.809086,2.129856,0.163992,-207.236755,0.017466,0.000000
20.630001,9.298882,-207.236755,-0.003643,0.000661,0.016798,41.363491,2.107157,0.167981,-207.236755,0.018099,0.000000
21.010000,10.011978,-207.281235,-0.003617,0.000699,0.017760,44.535503,2.268747,0.177602,-207.281235,0.018732,0.000000
21.390001,10.076401,-207.236755,-0.003587,0.000723,0.018359,44.822067,2.283345,0.183590,-207.236755,0.019365,0.000000
21.770000,10.474838,-207.325714,-0.003548,0.000756,0.019192,46.594406,2.373632,0.191917,-207.325714,0.019998,0.000000
22.150002,10.448029,-207.325714,-0.003544,0.000778,0.019755,46.475151,2.367557,0.197549,-207.325714,0.020631,0.000000
22.530001,10.526970,-207.414673,-0.003523,0.000798,0.020267,46.826302,2.385445,0.202666,-207.414673,0.021264,0.000000
22.910002,10.792847,-207.414673,-0.003484,0.000825,0.020943,48.008980,2.445694,0.209433,-207.414673,0.021897,0.000000
23.290001,10.898224,-207.414673,-0.003475,0.000847,0.021507,48.477722,2.469573,0.215073,-207.414673,0.022531,0.000000
23.670002,11.054245,-207.548111,-0.003449,0.000869,0.022080,49.171738,2.504928,0.220796,-207.548111,0.023164,0.000000
24.050001,11.398323,-207.548111,-0.003432,0.000899,0.022843,50.702274,2.582897,0.228426,-207.548111,0.023796,0.000000
24.430000,11.516365,-207.637085,-0.003406,0.000923,0.023441,51.227348,2.609646,0.234406,-207.637085,0.024429,0.000000
24.810001,11.861923,-207.637085,-0.003372,0.000951,0.024160,52.764469,2.687950,0.241605,-207.637085,0.025063,0.000000
25.190001,11.748726,-207.592606,-0.003337,0.000971,0.024664,52.260944,2.662299,0.246639,-207.592606,0.025696,0.000000
25.570002,11.859688,-207.726044,-0.003328,0.000994,0.025236,52.754524,2.687444,0.252362,-207.726044,0.026328,0.000000
25.950001,12.436119,-207.770523,-0.003307,0.001029,0.026138,55.318619,2.818065,0.261377,-207.770523,0.026970,0.000000
26.330002,12.391068,-207.770523,-0.003277,0.001052,0.026719,55.118221,2.807856,0.267191,-207.770523,0.027604,0.000000
26.710001,12.612625,-207.815002,-0.003251,0.001076,0.027326,56.103760,2.858062,0.273262,-207.815002,0.028237,0.000000
27.090002,12.608162,-207.859482,-0.003234,0.001097,0.027855,56.083904,2.857050,0.278553,-207.859482,0.028870,0.000000
27.470001,12.780937,-207.859482,-0.003203,0.001119,0.028419,56.852448,2.896202,0.284185,-207.859482,0.029502,0.000000
27.850000,13.070274,-207.992920,-0.003191,0.001145,0.029095,58.139484,2.961766,0.290952,-207.992920,0.030136,0.000000
28.230001,13.368919,-207.992920,-0.003173,0.001173,0.029789,59.467922,3.029441,0.297894,-207.992920,0.030769,0.000000
28.610001,13.520844,-208.037415,-0.003147,0.001197,0.030413,60.143715,3.063867,0.304131,-208.037415,0.031402,0.000000
28.990002,13.641121,-207.992920,-0.003117,0.001221,0.031012,60.678738,3.091122,0.310119,-207.992920,0.032035,0.000000
29.370001,13.745384,-208.081894,-0.003091,0.001244,0.031610,61.142521,3.114749,0.316099,-208.081894,0.032668,0.000000
29.750002,14.122597,-208.170853,-0.003061,0.001271,0.032295,62.820446,3.200226,0.322950,-208.170853,0.033301,0.000000
30.130001,14.332245,-208.215332,-0.003048,0.001298,0.032972,63.753010,3.247733,0.329717,-208.215332,0.033935,0.000000
30.510002,14.582481,-208.170853,-0.003022,0.001323,0.033605,64.866119,3.304437,0.336046,-208.170853,0.034567,0.000000
30.890001,14.487892,-208.215332,-0.002992,0.001344,0.034143,64.445366,3.283003,0.341428,-208.215332,0.035200,0.000000
31.270002,14.908302,-208.304291,-0.002975,0.001370,0.034810,66.315437,3.378269,0.348104,-208.304291,0.035834,0.000000
31.650002,15.299294,-208.348770,-0.002949,0.001401,0.035573,68.054657,3.466869,0.355735,-208.348770,0.036467,0.000000
32.030003,15.437820,-208.393250,-0.002945,0.001424,0.036181,68.670853,3.498260,0.361806,-208.393250,0.037100,0.000000
32.410000,15.650444,-208.393250,-0.002893,0.001451,0.036857,69.616653,3.546441,0.368565,-208.393250,0.037733,0.000000
32.790001,15.897697,-208.393250,-0.002871,0.001476,0.037490,70.716492,3.602470,0.374901,-208.393250,0.038366,0.000000
33.170002,15.898071,-208.437744,-0.002863,0.001494,0.037941,70.718155,3.602554,0.379413,-208.437744,0.038999,0.000000
33.550003,16.599243,-208.526703,-0.002837,0.001525,0.038739,73.837120,3.761442,0.387392,-208.526703,0.039632,0.000000
33.930000,16.651382,-208.571182,-0.002824,0.001549,0.039345,74.069046,3.773257,0.393455,-208.571182,0.040265,0.000000
34.310001,16.645050,-208.571182,-0.002790,0.001571,0.039909,74.040878,3.771822,0.399094,-208.571182,0.040898,0.000000
34.690002,16.990608,-208.571182,-0.002755,0.001598,0.040586,75.578003,3.850127,0.405862,-208.571182,0.041531,0.000000
35.070004,16.872566,-208.660141,-0.002746,0.001616,0.041054,75.052925,3.823378,0.410540,-208.660141,0.042164,0.000000
35.450001,18.021339,-208.749100,-0.002716,0.001652,0.041965,80.162918,4.083694,0.419646,-208.749100,0.042797,0.000000
35.830002,17.546188,-208.793579,-0.002703,0.001665,0.042295,78.049347,3.976023,0.422947,-208.793579,0.043430,0.000000
36.210003,18.071983,-208.793579,-0.002677,0.001695,0.043040,80.388199,4.095170,0.430403,-208.793579,0.044064,0.000000
36.590000,18.525528,-208.793579,-0.002652,0.001724,0.043778,82.405663,4.197945,0.437776,-208.793579,0.044697,0.000000
36.970001,18.570587,-208.927032,-0.002634,0.001744,0.044289,82.606094,4.208155,0.442893,-208.927032,0.045339,0.000000
37.350002,19.385338,-208.927032,-0.002613,0.001777,0.045139,86.230286,4.392780,0.451387,-208.927032,0.045971,0.000000
37.730003,19.332085,-208.971512,-0.002596,0.001798,0.045677,85.993408,4.380713,0.456769,-208.971512,0.046604,0.000000
38.110001,19.360764,-208.971512,-0.002565,0.001819,0.046197,86.120979,4.387212,0.461969,-208.971512,0.047238,0.000000
38.490002,19.729782,-208.971512,-0.002539,0.001843,0.046812,87.762451,4.470833,0.468123,-208.971512,0.047871,0.000000
38.870003,20.240303,-209.104950,-0.002518,0.001866,0.047394,90.033363,4.586518,0.473937,-209.104950,0.048503,0.000000
39.250000,20.718056,-209.104950,-0.002514,0.001893,0.048070,92.158516,4.694778,0.480704,-209.104950,0.049137,0.000000
39.630001,20.977600,-209.060471,-0.002488,0.001916,0.048668,93.313026,4.753592,0.486685,-209.060471,0.049770,0.000000
40.010002,21.327629,-209.149429,-0.002453,0.001943,0.049354,94.870033,4.832910,0.493535,-209.149429,0.050403,0.000000
40.390003,21.664261,-209.193909,-0.002436,0.001967,0.049961,96.367447,4.909192,0.499606,-209.193909,0.051036,0.000000
40.770000,21.737617,-209.282867,-0.002406,0.001989,0.050525,96.693748,4.925815,0.505246,-209.282867,0.051669,0.000000
41.150002,22.093231,-209.282867,-0.002397,0.002009,0.051027,98.275604,5.006398,0.510272,-209.282867,0.052302,0.000000
41.530003,23.071823,-209.327362,-0.002371,0.002044,0.051912,102.628593,5.228150,0.519121,-209.327362,0.052936,0.000000
41.910004,22.967934,-209.282867,-0.002350,0.002060,0.052319,102.166473,5.204608,0.523194,-209.282867,0.053568,0.000000
42.290001,23.805023,-209.327362,-0.002333,0.002093,0.053161,105.890030,5.394295,0.531611,-209.327362,0.054201,0.000000
42.670002,24.231018,-209.460800,-0.002298,0.002120,0.053837,107.784950,5.490827,0.538371,-209.460800,0.054835,0.000000
43.050003,25.133278,-209.505280,-0.002276,0.002151,0.054635,111.798401,5.695282,0.546350,-209.505280,0.055468,0.000000
43.430000,25.192116,-209.460800,-0.002268,0.002172,0.055172,112.060127,5.708615,0.551724,-209.460800,0.056100,0.000000
43.810001,25.633751,-209.460800,-0.002242,0.002196,0.055780,114.024620,5.808691,0.557795,-209.460800,0.056734,0.000000
44.190002,26.049316,-209.549759,-0.002220,0.002221,0.056404,115.873146,5.902860,0.564040,-209.549759,0.057367,0.000000
44.570004,26.471954,-209.638718,-0.002190,0.002242,0.056951,117.753136,5.998631,0.569506,-209.638718,0.058000,0.000000
44.950001,26.895721,-209.727692,-0.002173,0.002265,0.057540,119.638145,6.094658,0.575402,-209.727692,0.058633,0.000000
45.330002,27.813240,-209.638718,-0.002160,0.002294,0.058268,123.719467,6.302570,0.582685,-209.638718,0.059266,0.000000
45.710003,28.505486,-209.683197,-0.002121,0.002321,0.058954,126.798729,6.459435,0.589535,-209.683197,0.059899,0.000000
46.090004,28.950844,-209.772171,-0.002113,0.002344,0.059543,128.779785,6.560355,0.595432,-209.772171,0.060532,0.000000
46.470001,29.460991,-209.816650,-0.002095,0.002368,0.060150,131.049026,6.675956,0.601503,-209.816650,0.061165,0.000000
46.850002,29.619247,-209.861130,-0.002074,0.002388,0.060645,131.752991,6.711817,0.606446,-209.861130,0.061798,0.000000
47.230003,31.302002,-209.861130,-0.002044,0.002425,0.061590,139.238266,7.093135,0.615901,-209.861130,0.062431,0.000000
47.610001,31.422279,-209.861130,-0.002022,0.002445,0.062093,139.773285,7.120390,0.620935,-209.861130,0.063065,0.000000
47.990002,32.286552,-209.950089,-0.002001,0.002472,0.062796,143.617752,7.316237,0.627959,-209.950089,0.063707,0.000000
48.370003,32.690948,-210.083527,-0.002001,0.002493,0.063333,145.416595,7.407875,0.633334,-210.083527,0.064339,0.000000
48.750004,33.236107,-210.039047,-0.001966,0.002517,0.063941,147.841583,7.531410,0.639405,-210.039047,0.064972,0.000000
49.130001,34.154747,-210.083527,-0.001949,0.002542,0.064556,151.927902,7.739576,0.645559,-210.083527,0.065605,0.000000
49.510002,34.995193,-210.172501,-0.001923,0.002568,0.065233,155.666397,7.930024,0.652327,-210.172501,0.066239,0.000000
49.890003,35.762276,-210.172501,-0.001923,0.002592,0.065840,159.078552,8.103848,0.658398,-210.172501,0.066872,0.000000
50.270004,36.518570,-210.172501,-0.001901,0.002618,0.066498,162.442719,8.275227,0.664983,-210.172501,0.067504,0.000000
50.650002,36.756882,-210.216980,-0.001867,0.002635,0.066932,163.502777,8.329228,0.669321,-210.216980,0.068138,0.000000
51.030003,38.276535,-210.261459,-0.001845,0.002668,0.067756,170.262527,8.673587,0.677564,-210.261459,0.068771,0.000000
51.410004,39.152359,-210.350418,-0.001837,0.002694,0.068415,174.158386,8.872051,0.684150,-210.350418,0.069404,0.000000
51.790001,40.033394,-210.350418,-0.001819,0.002721,0.069109,178.077423,9.071697,0.691092,-210.350418,0.070037,0.000000
52.170002,40.588974,-210.439377,-0.001802,0.002739,0.069578,180.548767,9.197593,0.695777,-210.439377,0.070670,0.000000
52.550003,41.416756,-210.394897,-0.001785,0.002762,0.070167,184.230927,9.385171,0.701674,-210.394897,0.071303,0.000000
52.930004,42.737190,-210.394897,-0.001772,0.002793,0.070930,190.104523,9.684385,0.709304,-210.394897,0.071936,0.000000
53.310001,43.879997,-210.528336,-0.001742,0.002818,0.071589,195.187973,9.943349,0.715890,-210.528336,0.072569,0.000000
53.690002,44.556969,-210.528336,-0.001725,0.002840,0.072136,198.199295,10.096753,0.721356,-210.528336,0.073202,0.000000
54.070004,46.040878,-210.661789,-0.001716,0.002870,0.072899,204.800049,10.433012,0.728986,-210.661789,0.073836,0.000000
54.450001,46.115349,-210.572815,-0.001694,0.002889,0.073385,205.131317,10.449887,0.733846,-210.572815,0.074469,0.000000
54.830002,47.685272,-210.572815,-0.001673,0.002915,0.074052,212.114685,10.805636,0.740522,-210.572815,0.075101,0.000000
55.210003,48.703339,-210.617310,-0.001656,0.002940,0.074677,216.643265,11.036335,0.746767,-210.617310,0.075735,0.000000
55.590004,49.966057,-210.795227,-0.001647,0.002964,0.075292,222.260117,11.322471,0.752922,-210.795227,0.076368,0.000000
55.970001,51.298401,-210.795227,-0.001638,0.002992,0.075986,228.186676,11.624383,0.759863,-210.795227,0.077001,0.000000
56.350002,52.056183,-210.795227,-0.001625,0.003013,0.076533,231.557465,11.796100,0.765328,-210.795227,0.077634,0.000000
56.730003,54.024170,-210.795227,-0.001613,0.003046,0.077374,240.311508,12.242052,0.773739,-210.795227,0.078267,0.000000
57.110004,54.661301,-210.839706,-0.001582,0.003063,0.077799,243.145615,12.386428,0.777985,-210.839706,0.078900,0.000000
57.490002,56.331017,-210.973145,-0.001574,0.003092,0.078527,250.572876,12.764791,0.785275,-210.973145,0.079533,0.000000
57.870003,57.763161,-210.928665,-0.001561,0.003120,0.079238,256.943359,13.089319,0.792383,-210.928665,0.080166,0.000000
58.250004,58.120270,-210.928665,-0.001552,0.003137,0.079672,258.531860,13.170241,0.796720,-210.928665,0.080799,0.000000
58.630001,60.694847,-211.062119,-0.001539,0.003174,0.080608,269.984161,13.753649,0.806084,-211.062119,0.081432,0.000000
59.010002,61.560989,-211.017639,-0.001513,0.003193,0.081112,273.836945,13.949920,0.811118,-211.017639,0.082074,0.000000
59.390003,62.692627,-211.106598,-0.001500,0.003215,0.081649,278.870728,14.206352,0.816493,-211.106598,0.082708,0.000000
59.770004,63.362526,-211.106598,-0.001492,0.003234,0.082144,281.850586,14.358154,0.821436,-211.106598,0.083340,0.000000
60.150002,64.694878,-211.195557,-0.001487,0.003259,0.082776,287.777191,14.660069,0.827764,-211.195557,0.083973,0.000000
60.530003,66.672920,-211.195557,-0.001462,0.003275,0.083175,296.575958,15.108299,0.831753,-211.195557,0.083427,0.000000
60.910004,65.463448,-211.240036,-0.001444,0.003274,0.083150,291.195953,14.834229,0.831496,-211.240036,294.500488,0.000000
61.290005,65.838432,-211.284515,-0.001444,0.003287,0.083496,292.863983,14.919202,0.834963,-211.284515,294.500488,0.000000
61.670002,64.948463,-211.284515,-0.001436,0.003288,0.083514,288.905182,14.717532,0.835137,-211.284515,294.500488,0.000000
62.050003,66.347466,-211.284515,-0.001436,0.003258,0.082742,295.128265,15.034551,0.827416,-211.284515,294.500488,0.000000
62.430004,65.544258,-211.328995,-0.001414,0.003259,0.082785,291.555420,14.852542,0.827855,-211.328995,294.500488,0.000000
62.810001,65.135765,-211.417953,-0.001406,0.003308,0.084016,289.738342,14.759975,0.840163,-211.417953,294.500488,0.000000
63.190002,65.154381,-211.506927,-0.001418,0.003313,0.084138,289.821167,14.764194,0.841382,-211.506927,294.500488,0.000000
63.570004,65.038567,-211.462448,-0.001406,0.003317,0.084259,289.306000,14.737949,0.842593,-211.462448,294.500488,0.000000
63.950005,65.357704,-211.506927,-0.001397,0.003324,0.084424,290.725586,14.810267,0.844244,-211.506927,294.500488,0.000000
64.330002,64.958519,-211.551407,-0.001401,0.003324,0.084424,288.949921,14.719810,0.844244,-211.551407,294.500488,0.000000
64.710007,64.548531,-211.595886,-0.001393,0.003324,0.084433,287.126190,14.626905,0.844327,-211.595886,294.500488,0.000000
65.090004,66.935066,-211.684845,-0.001397,0.003246,0.082447,297.742035,15.167704,0.824471,-211.684845,294.500488,0.000000
65.470001,66.397362,-211.684845,-0.001388,0.003217,0.081718,295.350220,15.045857,0.817182,-211.684845,294.500488,0.000000
65.850006,66.007484,-211.684845,-0.001384,0.003217,0.081718,293.615967,14.957510,0.817182,-211.684845,294.500488,0.000000
66.230003,65.636238,-211.729324,-0.001367,0.003218,0.081727,291.964569,14.873384,0.817272,-211.729324,294.500488,0.000000
66.610001,65.352852,-211.862762,-0.001367,0.003317,0.084251,290.704010,14.809168,0.842510,-211.862762,294.500488,0.000000
66.990005,65.182686,-211.818283,-0.001375,0.003341,0.084849,289.947083,14.770608,0.848490,-211.818283,294.500488,0.000000
67.370003,65.032249,-211.862762,-0.001375,0.003345,0.084953,289.277893,14.736519,0.849535,-211.862762,294.500488,0.000000
67.750000,65.477974,-211.907257,-0.001371,0.003355,0.085205,291.260590,14.837522,0.852048,-211.907257,294.500488,0.000000
68.130005,65.281364,-211.862762,-0.001371,0.003355,0.085205,290.386017,14.792969,0.852048,-211.862762,294.500488,0.000000
68.510002,65.240776,-211.996216,-0.001362,0.003358,0.085292,290.205475,14.783772,0.852919,-211.996216,294.500488,0.000000
68.890007,65.121239,-211.996216,-0.001375,0.003358,0.085292,289.673737,14.756683,0.852919,-211.996216,294.500488,0.000000
69.270004,65.102623,-211.996216,-0.001367,0.003360,0.085352,289.590942,14.752465,0.853524,-211.996216,294.500488,0.000000
69.650002,65.288063,-212.040695,-0.001358,0.003365,0.085483,290.415802,14.794487,0.854826,-212.040695,294.500488,0.000000
70.030006,65.208382,-212.085175,-0.001358,0.003365,0.085483,290.061371,14.776431,0.854826,-212.085175,294.500488,0.000000
70.410004,65.059792,-212.218613,-0.001358,0.003367,0.085517,289.400421,14.742759,0.855167,-212.218613,294.500488,0.000000
70.790001,65.165550,-212.263092,-0.001362,0.003369,0.085561,289.870850,14.766726,0.855606,-212.263092,294.500488,0.000000
71.170006,65.018471,-212.263092,-0.001358,0.003369,0.085561,289.216614,14.733397,0.855606,-212.263092,294.500488,0.000000
71.550003,64.875481,-212.307587,-0.001354,0.003369,0.085561,288.580536,14.700994,0.855606,-212.307587,294.500488,0.000000
71.930000,64.722801,-212.263092,-0.001345,0.003369,0.085561,287.901398,14.666396,0.855606,-212.263092,294.500488,0.000000
72.310005,64.585762,-212.307587,-0.001350,0.003369,0.085561,287.291809,14.635343,0.855606,-212.307587,294.500488,0.000000
72.690002,66.187721,-212.396545,-0.001358,0.003375,0.085734,294.417694,14.998352,0.857339,-212.396545,294.500488,0.000000
73.070000,65.987373,-212.441025,-0.001354,0.003375,0.085734,293.526489,14.952952,0.857339,-212.441025,294.500488,0.000000
73.450005,65.841774,-212.441025,-0.001350,0.003375,0.085734,292.878845,14.919959,0.857339,-212.441025,294.500488,0.000000
73.830002,65.648888,-212.485504,-0.001345,0.003375,0.085734,292.020844,14.876251,0.857339,-212.485504,294.500488,0.000000
74.210007,65.513344,-212.574463,-0.001337,0.003375,0.085734,291.417908,14.845536,0.857339,-212.574463,294.500488,0.000000
74.590004,65.340569,-212.574463,-0.001345,0.003375,0.085734,290.649353,14.806384,0.857339,-212.574463,294.500488,0.000000
74.970001,65.226616,-212.574463,-0.001337,0.003375,0.085734,290.142487,14.780562,0.857339,-212.574463,294.500488,0.000000
75.350006,65.076180,-212.663422,-0.001337,0.003375,0.085734,289.473297,14.746473,0.857339,-212.663422,294.500488,0.000000
75.730003,64.971916,-212.663422,-0.001328,0.003375,0.085734,289.009521,14.722846,0.857339,-212.663422,294.500488,0.000000
76.110001,64.814781,-212.796875,-0.001324,0.003375,0.085734,288.310547,14.687239,0.857339,-212.796875,294.500488,0.000000
76.490005,64.707542,-212.752396,-0.001337,0.003375,0.085734,287.833527,14.662939,0.857339,-212.752396,294.500488,0.000000
76.870003,66.074135,-212.796875,-0.001337,0.003388,0.086046,293.912445,14.972612,0.860458,-212.796875,294.500488,0.000000
77.250000,65.899864,-212.796875,-0.001341,0.003388,0.086046,293.137238,14.933123,0.860458,-212.796875,294.500488,0.000000
77.630005,65.828743,-212.841354,-0.001345,0.003388,0.086046,292.820862,14.917006,0.860458,-212.841354,294.500488,0.000000
78.010002,65.736397,-212.974792,-0.001332,0.003388,0.086046,292.410095,14.896081,0.860458,-212.974792,294.500488,0.000000
78.390007,65.579262,-212.930313,-0.001328,0.003388,0.086046,291.711121,14.860474,0.860458,-212.930313,294.500488,0.000000
78.770004,65.502174,-213.019272,-0.001337,0.003388,0.086046,291.368225,14.843005,0.860458,-213.019272,294.500488,0.000000
79.150002,65.361046,-213.063751,-0.001328,0.003388,0.086046,290.740448,14.811025,0.860458,-213.063751,294.500488,0.000000
79.530006,65.285454,-213.019272,-0.001345,0.003388,0.086046,290.404205,14.793895,0.860458,-213.019272,294.500488,0.000000
79.910004,65.188637,-213.063751,-0.001328,0.003388,0.086046,289.973541,14.771956,0.860458,-213.063751,294.500488,0.000000
80.290001,65.069847,-213.152710,-0.001319,0.003388,0.086046,289.445129,14.745038,0.860458,-213.152710,294.500488,0.000000
80.670006,64.986809,-213.152710,-0.001328,0.003388,0.086046,289.075775,14.726221,0.860458,-213.152710,294.500488,0.000000
81.050003,64.885902,-213.197205,-0.001324,0.003388,0.086046,288.626923,14.703356,0.860458,-213.197205,294.500488,0.000000
81.430000,64.802483,-213.241684,-0.001328,0.003388,0.086046,288.255829,14.684452,0.860458,-213.241684,294.500488,0.000000
81.810005,65.998177,-213.241684,-0.001319,0.003402,0.086410,293.574554,14.955400,0.864099,-213.241684,294.500488,0.000000
82.190002,65.845512,-213.286163,-0.001324,0.003402,0.086402,292.895477,14.920807,0.864016,-213.286163,294.500488,0.000000
82.570007,65.797096,-213.375122,-0.001319,0.003402,0.086402,292.680115,14.909836,0.864016,-213.375122,294.500488,0.000000
82.950005,65.721138,-213.375122,-0.001324,0.003402,0.086410,292.342224,14.892623,0.864099,-213.375122,294.500488,0.000000
83.330002,65.596382,-213.464081,-0.001319,0.003402,0.086410,291.787292,14.864352,0.864099,-213.464081,294.500488,0.000000
83.710007,65.548347,-213.419601,-0.001315,0.003402,0.086410,291.573608,14.853468,0.864099,-213.419601,294.500488,0.000000
84.090004,65.467552,-213.508560,-0.001315,0.003402,0.086410,291.214203,14.835159,0.864099,-213.508560,294.500488,0.000000
84.470001,65.363655,-213.553040,-0.001311,0.003402,0.086410,290.752045,14.811616,0.864099,-213.553040,294.500488,0.000000
84.850006,65.289177,-213.553040,-0.001319,0.003402,0.086410,290.420776,14.794740,0.864099,-213.553040,294.500488,0.000000
85.230003,65.225502,-213.686493,-0.001319,0.003402,0.086410,290.137512,14.780310,0.864099,-213.686493,294.500488,0.000000
85.610001,65.140602,-213.597534,-0.001319,0.003402,0.086410,289.759857,14.761071,0.864099,-213.597534,294.500488,0.000000
85.990005,65.067619,-213.686493,-0.001315,0.003402,0.086410,289.435211,14.744533,0.864099,-213.686493,294.500488,0.000000
86.370003,65.012886,-213.819931,-0.001319,0.003402,0.086410,289.191772,14.732131,0.864099,-213.819931,294.500488,0.000000
86.750008,64.944740,-213.775452,-0.001315,0.003402,0.086410,288.888641,14.716688,0.864099,-213.775452,294.500488,0.000000
87.130005,65.595650,-213.819931,-0.001319,0.003416,0.086757,291.784027,14.864186,0.867574,-213.819931,294.500488,0.000000
87.510002,65.674965,-213.819931,-0.001319,0.003416,0.086757,292.136841,14.882160,0.867574,-213.819931,294.500488,0.000000
87.890007,65.647408,-213.864410,-0.001315,0.003416,0.086757,292.014252,14.875915,0.867574,-213.864410,294.500488,0.000000
88.270004,65.597878,-214.042343,-0.001319,0.003416,0.086757,291.793945,14.864691,0.867574,-214.042343,294.500488,0.000000
88.650002,65.577019,-213.997849,-0.001324,0.003416,0.086757,291.701141,14.859965,0.867574,-213.997849,294.500488,0.000000
89.030006,65.538292,-214.042343,-0.001319,0.003416,0.086757,291.528870,14.851189,0.867574,-214.042343,294.500488,0.000000
89.410004,65.497337,-213.997849,-0.001315,0.003416,0.086757,291.346710,14.841908,0.867574,-213.997849,294.500488,0.000000
89.790001,65.419518,-214.086823,-0.001311,0.003416,0.086757,291.000549,14.824275,0.867574,-214.086823,294.500488,0.000000
90.170006,65.380043,-214.086823,-0.001311,0.003416,0.086757,290.824951,14.815329,0.867574,-214.086823,294.500488,0.000000
90.550003,65.318596,-214.220261,-0.001324,0.003416,0.086766,290.551636,14.801406,0.867657,-214.220261,294.500488,0.000000
90.930008,65.274651,-214.175781,-0.001324,0.003416,0.086766,290.356140,14.791448,0.867657,-214.175781,294.500488,0.000000
91.310005,65.279121,-214.175781,-0.001311,0.003417,0.086801,290.376038,14.792460,0.868005,-214.175781,294.500488,0.000000
91.690002,65.269814,-214.264740,-0.001311,0.003417,0.086801,290.334625,14.790351,0.868005,-214.264740,294.500488,0.000000
92.070007,65.236305,-214.353699,-0.001315,0.003417,0.086801,290.185577,14.782759,0.868005,-214.353699,294.500488,0.000000
92.450005,65.188271,-214.398178,-0.001319,0.003417,0.086801,289.971924,14.771873,0.868005,-214.398178,294.500488,0.000000
92.830002,65.301476,-214.398178,-0.001311,0.003420,0.086878,290.475464,14.797526,0.868785,-214.398178,294.500488,0.000000
93.210007,65.296623,-214.442657,-0.001298,0.003420,0.086878,290.453888,14.796426,0.868785,-214.442657,294.500488,0.000000
93.590004,65.298866,-214.442657,-0.001302,0.003420,0.086878,290.463867,14.796934,0.868785,-214.442657,294.500488,0.000000
93.970001,65.256035,-214.487152,-0.001311,0.003420,0.086878,290.273346,14.787229,0.868785,-214.487152,294.500488,0.000000
94.350006,65.225136,-214.576111,-0.001315,0.003421,0.086887,290.135895,14.780228,0.868868,-214.576111,294.500488,0.000000
94.730003,65.211357,-214.620590,-0.001311,0.003421,0.086904,290.074615,14.777104,0.869042,-214.620590,294.500488,0.000000
95.110008,65.194221,-214.576111,-0.001315,0.003421,0.086904,289.998383,14.773222,0.869042,-214.576111,294.500488,0.000000
95.490005,65.185661,-214.665070,-0.001311,0.003422,0.086922,289.960297,14.771281,0.869216,-214.665070,294.500488,0.000000
95.870003,65.237801,-214.665070,-0.001311,0.003423,0.086948,290.192230,14.783097,0.869481,-214.665070,294.500488,0.000000
96.250008,65.304070,-214.798508,-0.001306,0.003425,0.086991,290.487000,14.798114,0.869913,-214.798508,294.500488,0.000000
96.630005,65.309288,-214.754028,-0.001319,0.003425,0.086991,290.510223,14.799295,0.869913,-214.754028,294.500488,0.000000
97.010002,65.301476,-214.798508,-0.001311,0.003425,0.086991,290.475464,14.797526,0.869913,-214.798508,294.500488,0.000000
97.390007,65.289177,-214.798508,-0.001298,0.003425,0.087000,290.420776,14.794740,0.869996,-214.798508,294.500488,0.000000
97.770004,65.278389,-214.842987,-0.001302,0.003425,0.087000,290.372772,14.792295,0.869996,-214.842987,294.500488,0.000000
98.150002,65.252312,-214.931961,-0.001302,0.003426,0.087009,290.256775,14.786386,0.870087,-214.931961,294.500488,0.000000
98.530006,65.233330,-214.931961,-0.001311,0.003426,0.087009,290.172333,14.782084,0.870087,-214.931961,294.500488,0.000000
98.910004,65.219551,-214.931961,-0.001302,0.003426,0.087026,290.111053,14.778962,0.870261,-214.931961,294.500488,0.000000
99.290001,65.313377,-214.976440,-0.001293,0.003428,0.087078,290.528412,14.800222,0.870783,-214.976440,294.500488,0.000000
99.670006,65.310402,-215.020920,-0.001302,0.003428,0.087078,290.515167,14.799548,0.870783,-215.020920,294.500488,0.000000
100.050003,65.298119,-215.065399,-0.001306,0.003428,0.087078,290.460541,14.796765,0.870783,-215.065399,294.500488,0.000000
100.430008,65.300728,-215.109879,-0.001293,0.003428,0.087078,290.472137,14.797357,0.870783,-215.109879,294.500488,0.000000
100.810005,65.266472,-215.154358,-0.001315,0.003428,0.087078,290.319763,14.789594,0.870783,-215.154358,294.500488,0.000000
101.190002,65.248970,-215.154358,-0.001298,0.003428,0.087078,290.241913,14.785628,0.870783,-215.154358,294.500488,0.000000
101.570007,65.254173,-215.243317,-0.001302,0.003429,0.087104,290.265045,14.786807,0.871041,-215.243317,294.500488,0.000000
101.950005,65.250084,-215.287796,-0.001298,0.003430,0.087112,290.246857,14.785880,0.871124,-215.287796,294.500488,0.000000
102.330002,65.239281,-215.287796,-0.001302,0.003430,0.087112,290.198822,14.783432,0.871124,-215.287796,294.500488,0.000000
102.710007,65.219551,-215.332291,-0.001302,0.003430,0.087112,290.111053,14.778962,0.871124,-215.332291,294.500488,0.000000
103.090004,65.221779,-215.376770,-0.001302,0.003430,0.087130,290.120972,14.779467,0.871298,-215.376770,294.500488,0.000000
103.470001,65.199806,-215.332291,-0.001302,0.003430,0.087130,290.023224,14.774487,0.871298,-215.332291,294.500488,0.000000
103.850006,65.178963,-215.465729,-0.001293,0.003430,0.087130,289.930511,14.769765,0.871298,-215.465729,294.500488,0.000000
104.230003,65.150658,-215.465729,-0.001306,0.003430,0.087130,289.804596,14.763350,0.871298,-215.465729,294.500488,0.000000
104.610008,65.119759,-215.465729,-0.001306,0.003430,0.087130,289.667145,14.756349,0.871298,-215.465729,294.500488,0.000000
104.990005,65.085869,-215.510208,-0.001302,0.003431,0.087147,289.516418,14.748669,0.871472,-215.510208,294.500488,0.000000
105.370003,65.112679,-215.510208,-0.001281,0.003432,0.087174,289.635651,14.754745,0.871737,-215.510208,294.500488,0.000000
105.750008,65.125710,-215.599167,-0.001298,0.003432,0.087174,289.693634,14.757697,0.871737,-215.599167,294.500488,0.000000
106.130005,65.127205,-215.599167,-0.001302,0.003432,0.087174,289.700287,14.758035,0.871737,-215.599167,294.500488,0.000000
106.510002,65.101128,-215.643646,-0.001298,0.003432,0.087174,289.584290,14.752126,0.871737,-215.643646,294.500488,0.000000
106.890007,65.081398,-215.688126,-0.001311,0.003432,0.087174,289.496521,14.747656,0.871737,-215.688126,294.500488,0.000000
107.270004,65.066124,-215.688126,-0.001285,0.003432,0.087174,289.428589,14.744194,0.871737,-215.688126,294.500488,0.000000
107.650002,65.046394,-215.777100,-0.001298,0.003432,0.087174,289.340820,14.739723,0.871737,-215.777100,294.500488,0.000000
108.030006,65.031120,-215.777100,-0.001289,0.003432,0.087174,289.272858,14.736262,0.871737,-215.777100,294.500488,0.000000
108.410004,65.006920,-215.821579,-0.001302,0.003432,0.087174,289.165222,14.730779,0.871737,-215.821579,294.500488,0.000000
108.790009,64.982719,-215.821579,-0.001306,0.003432,0.087174,289.057587,14.725295,0.871737,-215.821579,294.500488,0.000000
109.170006,64.964104,-215.910538,-0.001298,0.003432,0.087174,288.974762,14.721076,0.871737,-215.910538,294.500488,0.000000
109.550003,64.945107,-215.955017,-0.001315,0.003432,0.087174,288.890259,14.716771,0.871737,-215.955017,294.500488,0.000000
109.930008,64.909355,-216.043976,-0.001298,0.003432,0.087174,288.731232,14.708670,0.871737,-216.043976,294.500488,0.000000
110.310005,64.869514,-215.999496,-0.001298,0.003432,0.087174,288.554016,14.699642,0.871737,-215.999496,294.500488,0.000000
110.690002,65.644417,-215.999496,-0.001311,0.003442,0.087425,292.000946,14.875237,0.874250,-215.999496,294.500488,0.000000
111.070007,65.683891,-216.043976,-0.001302,0.003442,0.087425,292.176544,14.884183,0.874250,-216.043976,294.500488,0.000000
111.450005,65.706230,-216.088455,-0.001289,0.003442,0.087425,292.275909,14.889245,0.874250,-216.088455,294.500488,0.000000
111.830002,65.733055,-216.221909,-0.001298,0.003442,0.087425,292.395233,14.895324,0.874250,-216.221909,294.500488,0.000000
112.210007,65.679802,-216.177429,-0.001298,0.003442,0.087425,292.158356,14.883256,0.874250,-216.177429,294.500488,0.000000
112.590004,65.682411,-216.177429,-0.001298,0.003442,0.087425,292.169952,14.883847,0.874250,-216.177429,294.500488,0.000000
112.970009,65.666023,-216.221909,-0.001285,0.003442,0.087425,292.097046,14.880134,0.874250,-216.221909,294.500488,0.000000
113.350006,65.651497,-216.310867,-0.001293,0.003442,0.087425,292.032440,14.876842,0.874250,-216.310867,294.500488,0.000000
113.730003,65.611290,-216.355347,-0.001293,0.003442,0.087425,291.853607,14.867730,0.874250,-216.355347,294.500488,0.000000
114.110008,65.601234,-216.355347,-0.001281,0.003442,0.087425,291.808868,14.865452,0.874250,-216.355347,294.500488,0.000000
114.490005,65.582985,-216.444305,-0.001289,0.003442,0.087425,291.727692,14.861317,0.874250,-216.444305,294.500488,0.000000
114.870003,65.570702,-216.444305,-0.001298,0.003442,0.087425,291.673035,14.858533,0.874250,-216.444305,294.500488,0.000000
115.250008,65.558037,-216.488785,-0.001298,0.003442,0.087425,291.616699,14.855663,0.874250,-216.488785,294.500488,0.000000
115.630005,65.540154,-216.577744,-0.001293,0.003442,0.087425,291.537170,14.851611,0.874250,-216.577744,294.500488,0.000000
116.010002,65.518929,-216.444305,-0.001298,0.003442,0.087425,291.442749,14.846802,0.874250,-216.444305,294.500488,0.000000
116.390007,65.494728,-216.533264,-0.001302,0.003442,0.087425,291.335114,14.841318,0.874250,-216.533264,294.500488,0.000000
116.770004,65.470894,-216.577744,-0.001285,0.003442,0.087425,291.229095,14.835917,0.874250,-216.577744,294.500488,0.000000
117.150009,65.449303,-216.711197,-0.001281,0.003442,0.087425,291.133026,14.831024,0.874250,-216.711197,294.500488,0.000000
117.530006,65.393440,-216.711197,-0.001289,0.003442,0.087425,290.884552,14.818365,0.874250,-216.711197,294.500488,0.000000
117.910004,65.368492,-216.755676,-0.001306,0.003442,0.087425,290.773590,14.812712,0.874250,-216.755676,294.500488,0.000000
118.290009,65.349510,-216.800156,-0.001281,0.003442,0.087425,290.689148,14.808411,0.874250,-216.800156,294.500488,0.000000
118.670006,65.329018,-216.755676,-0.001285,0.003442,0.087425,290.597992,14.803767,0.874250,-216.755676,294.500488,0.000000
119.050003,65.306313,-216.933594,-0.001298,0.003442,0.087425,290.496979,14.798622,0.874250,-216.933594,294.500488,0.000000
119.430008,65.291786,-216.889114,-0.001311,0.003442,0.087425,290.432373,14.795330,0.874250,-216.889114,294.500488,0.000000
119.810005,65.270927,-216.889114,-0.001302,0.003442,0.087425,290.339600,14.790604,0.874250,-216.889114,294.500488,0.000000
120.190002,65.262001,-216.889114,-0.001289,0.003442,0.087425,290.299866,14.788581,0.874250,-216.889114,294.500488,0.000000
120.570007,65.234810,-217.022568,-0.001281,0.003442,0.087425,290.178925,14.782419,0.874250,-217.022568,294.500488,0.000000
120.950005,65.216194,-217.111526,-0.001293,0.003442,0.087425,290.096130,14.778201,0.874250,-217.111526,294.500488,0.000000
121.330009,65.189018,-217.111526,-0.001281,0.003439,0.087338,289.975250,14.772042,0.873380,-217.111526,0.087269,0.000000
121.710007,65.152885,-217.111526,-0.001272,0.003420,0.086878,289.814514,14.763855,0.868785,-217.111526,0.086627,0.000000
122.090004,65.034111,-217.156006,-0.001293,0.003403,0.086445,289.286163,14.736940,0.864447,-217.156006,0.085994,0.000000
122.470009,64.932076,-217.156006,-0.001281,0.003382,0.085907,288.832306,14.713819,0.859073,-217.156006,0.085361,0.000000
122.850006,64.940269,-217.289444,-0.001281,0.003360,0.085352,288.868744,14.715675,0.853524,-217.289444,0.084728,0.000000
123.230003,64.910103,-217.289444,-0.001281,0.003335,0.084701,288.734558,14.708839,0.847014,-217.289444,0.084095,0.000000
123.610008,64.863564,-217.289444,-0.001276,0.003313,0.084147,288.527527,14.698294,0.841465,-217.289444,0.083461,0.000000
123.990005,64.854622,-217.333923,-0.001285,0.003281,0.083331,288.487762,14.696267,0.833313,-217.333923,0.082829,0.000000
124.370003,64.770836,-217.378403,-0.001285,0.003258,0.082751,288.115082,14.677281,0.827507,-217.378403,0.082196,0.000000
124.750008,64.700829,-217.422882,-0.001285,0.003232,0.082100,287.803650,14.661417,0.821004,-217.422882,0.081562,0.000000
125.130005,64.587257,-217.422882,-0.001293,0.003213,0.081623,287.298462,14.635682,0.816228,-217.422882,0.080929,0.000000
125.510010,63.916985,-217.422882,-0.001281,0.003192,0.081077,284.316956,14.483795,0.810770,-217.422882,0.080297,0.000000
125.890007,63.076172,-217.511856,-0.001272,0.003166,0.080409,280.576813,14.293265,0.804093,-217.511856,0.079663,0.000000
126.270004,61.729301,-217.511856,-0.001263,0.003138,0.079715,274.585632,13.988060,0.797152,-217.511856,0.079030,0.000000
126.650009,60.627075,-217.645294,-0.001272,0.003122,0.079291,269.682709,13.738292,0.792905,-217.645294,0.078397,0.000000
127.030006,58.808037,-217.645294,-0.001255,0.003095,0.078605,261.591217,13.326092,0.786055,-217.645294,0.077764,0.000000
127.410004,57.532661,-217.600815,-0.001263,0.003078,0.078180,255.918060,13.037087,0.781800,-217.600815,0.077131,0.000000
127.790009,54.968880,-217.689774,-0.001272,0.003047,0.077391,244.513794,12.456126,0.773913,-217.689774,0.076498,0.000000
128.170013,52.924553,-217.734253,-0.001255,0.003027,0.076880,235.420166,11.992875,0.768795,-217.734253,0.075864,0.000000
128.550003,50.368591,-217.778732,-0.001259,0.003001,0.076238,224.050690,11.413686,0.762376,-217.778732,0.075232,0.000000
128.930008,47.936996,-217.778732,-0.001276,0.002978,0.075640,213.234406,10.862679,0.756396,-217.778732,0.074599,0.000000
129.310013,45.095047,-217.778732,-0.001272,0.002949,0.074902,200.592789,10.218684,0.749023,-217.778732,0.073965,0.000000
129.690002,41.936958,-217.867691,-0.001263,0.002925,0.074286,186.544907,9.503051,0.742861,-217.867691,0.073332,0.000000
130.070007,39.086075,-217.912186,-0.001263,0.002899,0.073645,173.863541,8.857031,0.736450,-217.912186,0.072700,0.000000
130.450012,37.457687,-217.956665,-0.001259,0.002886,0.073315,166.620117,8.488033,0.733149,-217.956665,0.072066,0.000000
130.830002,34.323807,-217.956665,-0.001263,0.002854,0.072482,152.679916,7.777886,0.724823,-217.956665,0.071433,0.000000
131.210007,32.326401,-217.956665,-0.001259,0.002838,0.072092,143.795013,7.325267,0.720924,-217.956665,0.070800,0.000000
131.590012,29.204430,-218.045624,-0.001250,0.002808,0.071312,129.907791,6.617818,0.713120,-218.045624,0.070167,0.000000
131.970001,25.860153,-218.090103,-0.001250,0.002777,0.070532,115.031708,5.859994,0.705315,-218.090103,0.069534,0.000000
132.350006,23.382759,-218.134583,-0.001263,0.002756,0.070011,104.011703,5.298609,0.700107,-218.134583,0.068901,0.000000
132.730011,20.548630,-218.223541,-0.001259,0.002728,0.069300,91.404869,4.656386,0.692999,-218.223541,0.068259,0.000000
133.110001,18.691605,-218.090103,-0.001263,0.002713,0.068918,83.144409,4.235579,0.689184,-218.090103,0.067626,0.000000
133.490005,14.978683,-218.179062,-0.001268,0.002675,0.067956,66.628510,3.394218,0.679555,-218.179062,0.066993,0.000000
133.870010,12.365372,-218.268021,-0.001268,0.002652,0.067358,55.003922,2.802033,0.673575,-218.268021,0.066360,0.000000
134.250000,9.804939,-218.356995,-0.001259,0.002626,0.066707,43.614548,2.221831,0.667065,-218.356995,0.065727,0.000000
134.630005,8.445404,-218.401474,-0.001268,0.002617,0.066482,37.567032,1.913756,0.664817,-218.401474,0.065094,0.000000
135.010010,4.672905,-218.312515,-0.001263,0.002578,0.065476,20.786119,1.058895,0.654757,-218.312515,0.064461,0.000000
135.389999,1.408684,-218.445953,-0.001250,0.002548,0.064721,6.266139,0.319212,0.647209,-218.445953,0.063828,0.000000
135.770004,-0.921993,-218.401474,-0.001263,0.002526,0.064157,-4.101231,-0.208927,0.641570,-218.401474,0.063195,0.000000
136.150009,-3.332363,-218.534912,-0.001263,0.002500,0.063489,-14.823092,-0.755124,0.634893,-218.534912,0.062561,0.000000
136.530014,-0.307205,-218.579391,-0.001281,0.002474,0.062847,-1.366517,-0.069614,0.628474,-218.579391,0.061928,0.000000
136.910004,-0.056976,-218.534912,-0.001276,0.002458,0.062423,-0.253443,-0.012911,0.624228,-218.534912,0.061296,0.000000
137.290009,-0.138519,-218.579391,-0.001289,0.002427,0.061651,-0.616165,-0.031389,0.616506,-218.579391,0.060662,0.000000
137.670013,-0.083786,-218.668350,-0.001272,0.002401,0.060983,-0.372699,-0.018986,0.609830,-218.668350,0.060029,0.000000
138.050003,-0.100914,-218.668350,-0.001315,0.002374,0.060290,-0.448888,-0.022867,0.602896,-218.668350,0.059396,0.000000
138.430008,-0.055115,-218.712830,-0.001328,0.002355,0.059821,-0.245163,-0.012489,0.598210,-218.712830,0.058763,0.000000
138.810013,-0.041702,-218.712830,-0.001375,0.002326,0.059075,-0.185501,-0.009450,0.590754,-218.712830,0.058130,0.000000
139.190002,-0.044312,-218.757324,-0.001384,0.002311,0.058711,-0.197107,-0.010041,0.587113,-218.757324,0.057497,0.000000
139.570007,-0.045059,-218.801804,-0.001423,0.002275,0.057792,-0.200433,-0.010211,0.577916,-218.801804,0.056864,0.000000
139.950012,-0.049522,-218.890762,-0.001453,0.002251,0.057167,-0.220287,-0.011222,0.571671,-218.890762,0.056231,0.000000
140.330002,-0.046547,-218.935242,-0.001470,0.002231,0.056664,-0.207051,-0.010548,0.566644,-218.935242,0.055598,0.000000
140.710007,-0.037613,-218.890762,-0.001509,0.002206,0.056022,-0.167311,-0.008523,0.560225,-218.890762,0.054964,0.000000
141.090012,-0.050644,-218.935242,-0.001531,0.002174,0.055225,-0.225275,-0.011476,0.552246,-218.935242,0.054331,0.000000
141.470001,-0.034256,-219.024200,-0.001548,0.002149,0.054574,-0.152378,-0.007763,0.545744,-219.024200,0.053699,0.000000
141.850006,-0.069633,-219.024200,-0.001582,0.002124,0.053950,-0.309745,-0.015779,0.539499,-219.024200,0.053066,0.000000
142.230011,-0.052879,-219.068680,-0.001625,0.002105,0.053456,-0.235219,-0.011983,0.534556,-219.068680,0.052432,0.000000
142.610001,-0.059952,-219.068680,-0.001651,0.002079,0.052814,-0.266679,-0.013585,0.528137,-219.068680,0.051799,0.000000
142.990005,-0.049522,-219.113159,-0.001664,0.002052,0.052111,-0.220287,-0.011222,0.521112,-219.113159,0.051166,0.000000
143.370010,-0.011543,-219.157639,-0.001694,0.002025,0.051435,-0.051347,-0.002616,0.514352,-219.157639,0.050533,0.000000
143.750000,-0.037613,-219.202133,-0.001720,0.002008,0.051001,-0.167311,-0.008523,0.510015,-219.202133,0.049891,0.000000
144.130005,-0.041702,-219.246613,-0.001738,0.001986,0.050447,-0.185501,-0.009450,0.504466,-219.246613,0.049258,0.000000
144.510010,-0.054367,-219.202133,-0.001768,0.001959,0.049762,-0.241837,-0.012320,0.497615,-219.202133,0.048625,0.000000
144.889999,-0.061066,-219.291092,-0.001802,0.001934,0.049120,-0.271634,-0.013838,0.491196,-219.291092,0.047992,0.000000
145.270004,-0.009682,-219.424530,-0.001811,0.001900,0.048270,-0.043066,-0.002194,0.482695,-219.424530,0.047359,0.000000
145.650009,-0.036491,-219.380051,-0.001837,0.001881,0.047775,-0.162322,-0.008269,0.477752,-219.380051,0.046726,0.000000
146.030014,-0.079689,-219.424530,-0.001880,0.001857,0.047160,-0.354474,-0.018058,0.471598,-219.424530,0.046093,0.000000
146.410004,-0.045433,-219.380051,-0.001914,0.001826,0.046379,-0.202096,-0.010295,0.463793,-219.380051,0.045460,0.000000
146.790009,-0.040962,-219.424530,-0.001910,0.001813,0.046041,-0.182209,-0.009282,0.460410,-219.424530,0.044827,0.000000
147.170013,-0.040588,-219.469009,-0.001953,0.001778,0.045165,-0.180546,-0.009197,0.451652,-219.469009,0.044194,0.000000
147.550003,-0.042450,-219.602463,-0.001979,0.001754,0.044549,-0.188827,-0.009619,0.445490,-219.602463,0.043560,0.000000
147.930008,-0.073730,-219.602463,-0.002005,0.001726,0.043846,-0.327969,-0.016708,0.438465,-219.602463,0.042928,0.000000
148.310013,-0.064049,-219.602463,-0.002022,0.001706,0.043335,-0.284903,-0.014514,0.433348,-219.602463,0.042295,0.000000
148.690002,-0.065536,-219.646942,-0.002061,0.001679,0.042659,-0.291521,-0.014851,0.426588,-219.646942,0.041661,0.000000
149.070007,-0.060326,-219.691422,-0.002074,0.001654,0.042009,-0.268342,-0.013670,0.420085,-219.691422,0.041028,0.000000
149.450012,-0.058838,-219.735901,-0.002095,0.001628,0.041349,-0.261724,-0.013333,0.413492,-219.735901,0.040395,0.000000
149.830002,-0.050270,-219.780380,-0.002143,0.001603,0.040716,-0.223612,-0.011391,0.407164,-219.780380,0.039762,0.000000
150.210007,-0.086388,-219.780380,-0.002173,0.001581,0.040170,-0.384271,-0.019576,0.401698,-219.780380,0.039129,0.000000
150.590012,-0.086021,-219.824860,-0.002182,0.001555,0.039502,-0.382642,-0.019493,0.395022,-219.824860,0.038496,0.000000
150.970001,-0.050644,-219.913818,-0.002216,0.001526,0.038765,-0.225275,-0.011476,0.387649,-219.913818,0.037863,0.000000
151.350006,-0.057716,-219.958298,-0.002242,0.001501,0.038132,-0.256735,-0.013079,0.381321,-219.958298,0.037230,0.000000
151.730011,-0.093094,-219.913818,-0.002259,0.001488,0.037794,-0.414102,-0.021095,0.377937,-219.913818,0.036597,0.000000
152.110001,-0.091980,-219.958298,-0.002281,0.001467,0.037255,-0.409147,-0.020843,0.372555,-219.958298,0.035963,0.000000
152.490005,-0.073357,-220.002777,-0.002324,0.001440,0.036579,-0.326307,-0.016623,0.365795,-220.002777,0.035330,0.000000
152.870010,-0.101662,-220.091751,-0.002333,0.001409,0.035782,-0.452214,-0.023037,0.357816,-220.091751,0.034698,0.000000
153.250000,-0.038353,-220.047272,-0.002363,0.001378,0.035001,-0.170603,-0.008691,0.350012,-220.047272,0.034065,0.000000
153.630005,-0.081924,-220.091751,-0.002402,0.001349,0.034272,-0.364418,-0.018564,0.342722,-220.091751,0.033431,0.000000
154.000000,-0.034256,-220.180710,-0.002410,0.001345,0.034169,-0.152378,-0.007763,0.341685,-220.180710,0.034065,0.000000