File: Data/compression 18/AutoNoHeating-17-18-reverse-1-2_09092024_171415.csv
Time (sec),S:Load (lbs),S:HL1 (DIM),S:LVDT (in),S:Position (in),Ch:Position (mm),Ch:Load (N),Ch:Stress (MPa),Ch:Strain (mm/mm),Ch:HL1 (DIM),Set Point (),Cycles ()
0.010000,-0.027931,-154.660263,-0.012253,-0.007813,-0.198439,-0.124244,-0.006329,-1.984390,-154.660263,-0.198213,0.000000
0.380000,-0.005959,-154.660263,-0.012262,-0.007784,-0.197719,-0.026505,-0.001350,-1.977191,-154.660263,-0.197086,0.000000
0.750000,-0.059952,-154.793716,-0.012184,-0.007565,-0.192142,-0.266679,-0.013585,-1.921425,-154.793716,-0.190928,0.000000
1.120000,-0.081924,-154.838196,-0.011930,-0.007326,-0.186081,-0.364418,-0.018564,-1.860806,-154.838196,-0.184771,0.000000
1.490000,-0.032021,-154.882675,-0.011663,-0.007084,-0.179923,-0.142435,-0.007256,-1.799233,-154.882675,-0.178596,0.000000
1.860000,-0.021225,-154.927155,-0.011426,-0.006840,-0.173731,-0.094413,-0.004810,-1.737312,-154.927155,-0.172439,0.000000
2.230000,-0.028671,-154.971634,-0.011193,-0.006596,-0.167539,-0.127536,-0.006497,-1.675391,-154.971634,-0.166282,0.000000
2.600000,-0.056602,-154.971634,-0.010943,-0.006361,-0.161564,-0.251780,-0.012826,-1.615643,-154.971634,-0.160107,0.000000
2.970000,-0.064423,-155.060593,-0.010680,-0.006109,-0.155164,-0.286566,-0.014598,-1.551640,-155.060593,-0.153950,0.000000
3.340000,-0.088623,-155.105072,-0.010434,-0.005870,-0.149102,-0.394215,-0.020082,-1.491022,-155.105072,-0.147775,0.000000
3.710000,-0.016014,-155.105072,-0.010188,-0.005621,-0.142780,-0.071234,-0.003629,-1.427799,-155.105072,-0.141618,0.000000
4.080000,-0.031281,-155.194031,-0.009925,-0.005375,-0.136527,-0.139143,-0.007088,-1.365272,-155.194031,-0.135461,0.000000
4.450000,-0.008934,-155.283005,-0.009705,-0.005139,-0.130535,-0.039741,-0.002024,-1.305350,-155.283005,-0.129286,0.000000
4.820000,-0.042076,-155.371964,-0.009459,-0.004897,-0.124378,-0.187164,-0.009535,-1.243777,-155.371964,-0.123129,0.000000
5.190000,-0.057716,-155.371964,-0.009196,-0.004650,-0.118099,-0.256735,-0.013079,-1.180986,-155.371964,-0.116954,0.000000
5.560000,-0.028671,-155.416443,-0.008964,-0.004414,-0.112115,-0.127536,-0.006497,-1.121146,-155.416443,-0.110797,0.000000
5.930000,-0.015266,-155.416443,-0.008718,-0.004169,-0.105897,-0.067908,-0.003459,-1.058968,-155.416443,-0.104639,0.000000
6.300000,0.003723,-155.505402,-0.008459,-0.003922,-0.099609,0.016561,0.000844,-0.996094,-155.505402,-0.098465,0.000000
6.670001,-0.029419,-155.549881,-0.008222,-0.003679,-0.093444,-0.130862,-0.006666,-0.934438,-155.549881,-0.092308,0.000000
7.040000,-0.040962,-155.594360,-0.007972,-0.003442,-0.087417,-0.182209,-0.009282,-0.874167,-155.594360,-0.086133,0.000000
7.410000,-0.058090,-155.638855,-0.007722,-0.003196,-0.081190,-0.258398,-0.013163,-0.811898,-155.638855,-0.079976,0.000000
7.780000,-0.036865,-155.594360,-0.007480,-0.002951,-0.074955,-0.163985,-0.008354,-0.749545,-155.594360,-0.073818,0.000000
8.150001,-0.017128,-155.727814,-0.007222,-0.002707,-0.068753,-0.076189,-0.003881,-0.687534,-155.727814,-0.067644,0.000000
8.520000,0.017128,-155.772293,-0.006976,-0.002470,-0.062726,0.076189,0.003881,-0.627263,-155.772293,-0.061486,0.000000
8.890000,-0.005959,-155.772293,-0.006704,-0.002220,-0.056378,-0.026505,-0.001350,-0.563783,-155.772293,-0.055312,0.000000
9.260000,-0.034256,-155.861252,-0.006467,-0.001982,-0.050351,-0.152378,-0.007763,-0.503512,-155.861252,-0.049154,0.000000
9.630000,-0.037979,-155.905731,-0.006217,-0.001742,-0.044246,-0.168940,-0.008606,-0.442462,-155.905731,-0.042997,0.000000
10.000000,0.001862,-155.905731,-0.005989,-0.001499,-0.038080,0.008281,0.000422,-0.380798,-155.905731,-0.036822,0.000000
10.370001,0.007446,-156.039169,-0.005717,-0.001255,-0.031888,0.033123,0.001687,-0.318877,-156.039169,-0.030665,0.000000
10.740001,-0.003723,-156.083664,-0.005463,-0.001009,-0.025635,-0.016561,-0.000844,-0.256351,-156.083664,-0.024491,0.000000
11.110001,-0.035004,-156.039169,-0.005226,-0.000779,-0.019790,-0.155704,-0.007932,-0.197905,-156.039169,-0.018333,0.000000
11.480000,-0.034256,-156.128143,-0.004975,-0.000528,-0.013399,-0.152378,-0.007763,-0.133985,-156.128143,-0.012176,0.000000
11.850000,-0.059952,-156.217102,-0.004730,-0.000283,-0.007198,-0.266679,-0.013585,-0.071981,-156.217102,-0.006001,0.000000
12.220000,0.011543,-156.217102,-0.004501,-0.000041,-0.001049,0.051347,0.002616,-0.010492,-156.217102,0.000156,0.000000
12.590000,0.146713,-156.306061,-0.004329,0.000008,0.000200,0.652613,0.033246,0.001998,-156.306061,0.000477,0.000000
12.960001,0.138153,-156.261581,-0.004329,0.000008,0.000200,0.614536,0.031306,0.001998,-156.261581,0.000477,0.000000
13.330001,0.142242,-156.306061,-0.004346,0.000008,0.000200,0.632726,0.032233,0.001998,-156.306061,0.001093,0.000000
13.700001,0.125488,-156.439499,-0.004333,0.000028,0.000702,0.558200,0.028436,0.007025,-156.439499,0.001709,0.000000
14.070001,0.266617,-156.483978,-0.004303,0.000054,0.001379,1.185971,0.060416,0.013792,-156.483978,0.002325,0.000000
14.440001,0.395462,-156.483978,-0.004294,0.000074,0.001891,1.759103,0.089613,0.018909,-156.483978,0.002940,0.000000
14.810000,0.664314,-156.572952,-0.004255,0.000107,0.002706,2.955018,0.150536,0.027062,-156.572952,0.003556,0.000000
15.180000,0.912682,-156.528473,-0.004238,0.000130,0.003304,4.059811,0.206817,0.033042,-156.528473,0.004180,0.000000
15.550001,1.150261,-156.661911,-0.004225,0.000151,0.003824,5.116616,0.260653,0.038243,-156.661911,0.004796,0.000000
15.920001,1.563217,-156.795349,-0.004204,0.000181,0.004596,6.953537,0.354230,0.045964,-156.795349,0.005412,0.000000
16.290001,1.689827,-156.706390,-0.004169,0.000191,0.004839,7.516726,0.382920,0.048394,-156.706390,0.006027,0.000000
16.660000,2.100555,-156.795349,-0.004148,0.000216,0.005481,9.343738,0.475993,0.054813,-156.795349,0.006643,0.000000
17.030001,2.688530,-156.795349,-0.004130,0.000247,0.006279,11.959179,0.609230,0.062791,-156.795349,0.007259,0.000000
17.400002,3.084358,-156.839828,-0.004118,0.000272,0.006912,13.719911,0.698926,0.069120,-156.839828,0.007875,0.000000
17.770000,3.591156,-156.928802,-0.004092,0.000298,0.007562,15.974259,0.813768,0.075622,-156.928802,0.008490,0.000000
18.140001,3.846237,-156.973282,-0.004083,0.000317,0.008048,17.108917,0.871570,0.080482,-156.973282,0.009106,0.000000
18.510000,4.265152,-157.106720,-0.004066,0.000337,0.008560,18.972343,0.966497,0.085599,-157.106720,0.009730,0.000000
18.880001,4.722427,-157.062241,-0.004023,0.000362,0.009184,21.006407,1.070117,0.091844,-157.062241,0.010346,0.000000
19.250000,5.226616,-157.106720,-0.004027,0.000389,0.009878,23.249149,1.184368,0.098778,-157.106720,0.010962,0.000000
19.620001,5.680916,-157.195679,-0.003992,0.000416,0.010572,25.269976,1.287314,0.105720,-157.195679,0.011577,0.000000
19.990002,5.969872,-157.284637,-0.003980,0.000438,0.011118,26.555315,1.352792,0.111178,-157.284637,0.012193,0.000000
20.360001,6.361610,-157.284637,-0.003945,0.000459,0.011664,28.297857,1.441561,0.116643,-157.284637,0.012809,0.000000
20.730001,6.919800,-157.284637,-0.003919,0.000491,0.012480,30.780807,1.568049,0.124796,-157.284637,0.013425,0.000000
21.100000,7.196472,-157.373611,-0.003889,0.000516,0.013104,32.011505,1.630744,0.131041,-157.373611,0.014040,0.000000
21.470001,7.225891,-157.462570,-0.003898,0.000531,0.013476,32.142368,1.637410,0.134765,-157.462570,0.014657,0.000000
21.840000,7.787422,-157.507050,-0.003850,0.000557,0.014153,34.640182,1.764655,0.141532,-157.507050,0.015280,0.000000
22.210001,8.180275,-157.551529,-0.003850,0.000585,0.014856,36.387680,1.853677,0.148557,-157.551529,0.015897,0.000000
22.580002,8.393646,-157.507050,-0.003816,0.000607,0.015428,37.336803,1.902027,0.154280,-157.507050,0.016512,0.000000
22.950001,8.753357,-157.596008,-0.003803,0.000638,0.016200,38.936874,1.983539,0.162001,-157.596008,0.017128,0.000000
23.320002,8.716125,-157.684967,-0.003768,0.000656,0.016660,38.771263,1.975102,0.166596,-157.684967,0.017744,0.000000
23.690001,8.951462,-157.773926,-0.003742,0.000678,0.017214,39.818092,2.028430,0.172145,-157.773926,0.018359,0.000000
24.060001,9.281380,-157.773926,-0.003725,0.000705,0.017909,41.285641,2.103191,0.179086,-157.773926,0.018975,0.000000
24.430000,9.332397,-157.862900,-0.003695,0.000729,0.018507,41.512577,2.114752,0.185066,-157.862900,0.019591,0.000000
24.800001,9.669395,-157.818420,-0.003665,0.000757,0.019235,43.011620,2.191116,0.192348,-157.818420,0.020207,0.000000
25.170002,9.830635,-157.907379,-0.003635,0.000779,0.019790,43.728848,2.227654,0.197905,-157.907379,0.020831,0.000000
25.540001,9.999687,-157.951859,-0.003635,0.000803,0.020398,44.480831,2.265962,0.203976,-157.951859,0.021447,0.000000
25.910002,10.182899,-157.996338,-0.003596,0.000831,0.021108,45.295799,2.307478,0.211084,-157.996338,0.022062,0.000000
26.280001,10.435364,-157.996338,-0.003566,0.000857,0.021776,46.418816,2.364687,0.217760,-157.996338,0.022678,0.000000
26.650002,10.537766,-158.040817,-0.003548,0.000882,0.022392,46.874321,2.387892,0.223922,-158.040817,0.023294,0.000000
27.020000,10.624901,-158.129776,-0.003527,0.000905,0.022982,47.261921,2.407637,0.229819,-158.129776,0.023909,0.000000
27.390001,10.802895,-158.218750,-0.003505,0.000926,0.023510,48.053677,2.447971,0.235103,-158.218750,0.024525,0.000000
27.760002,10.934341,-158.263229,-0.003475,0.000950,0.024126,48.638378,2.477757,0.241264,-158.263229,0.025141,0.000000
28.130001,11.104523,-158.263229,-0.003458,0.000973,0.024716,49.395386,2.516321,0.247161,-158.263229,0.025757,0.000000
28.500002,11.401299,-158.352188,-0.003432,0.000999,0.025384,50.715508,2.583571,0.253838,-158.352188,0.026381,0.000000
28.870001,11.459389,-158.396667,-0.003410,0.001024,0.026017,50.973907,2.596735,0.260166,-158.396667,0.026997,0.000000
29.240002,11.445610,-158.530106,-0.003389,0.001044,0.026511,50.912617,2.593612,0.265109,-158.530106,0.027612,0.000000
29.610001,11.766228,-158.485626,-0.003354,0.001072,0.027222,52.338795,2.666265,0.272225,-158.485626,0.028229,0.000000
29.980001,11.860435,-158.530106,-0.003333,0.001094,0.027786,52.757851,2.687613,0.277864,-158.530106,0.028844,0.000000
30.350002,12.306908,-158.574585,-0.003324,0.001125,0.028584,54.743858,2.788785,0.285835,-158.574585,0.029460,0.000000
30.720001,12.306534,-158.619064,-0.003294,0.001148,0.029157,54.742195,2.788700,0.291566,-158.619064,0.030076,0.000000
31.090002,12.450272,-158.708038,-0.003272,0.001172,0.029764,55.381573,2.821272,0.297637,-158.708038,0.030691,0.000000
31.460001,12.695297,-158.752518,-0.003229,0.001198,0.030431,56.471504,2.876796,0.304313,-158.752518,0.031307,0.000000
31.830002,12.298714,-158.841476,-0.003216,0.001207,0.030657,54.707409,2.786928,0.306569,-158.841476,0.031932,0.000000
32.200001,12.867332,-158.796997,-0.003199,0.001240,0.031489,57.236752,2.915779,0.314888,-158.796997,0.032547,0.000000
32.570000,13.205444,-158.885956,-0.003173,0.001266,0.032148,58.740749,2.992396,0.321481,-158.885956,0.033162,0.000000
32.940002,13.414719,-158.930435,-0.003152,0.001292,0.032807,59.671650,3.039819,0.328075,-158.930435,0.033779,0.000000
33.310001,13.634415,-158.930435,-0.003113,0.001317,0.033458,60.648907,3.089603,0.334577,-158.930435,0.034394,0.000000
33.680000,13.629204,-159.019394,-0.003096,0.001338,0.033978,60.625725,3.088422,0.339778,-159.019394,0.035010,0.000000
34.050003,14.053337,-159.019394,-0.003074,0.001365,0.034680,62.512367,3.184532,0.346802,-159.019394,0.035626,0.000000
34.420002,13.752831,-159.108368,-0.003053,0.001379,0.035019,61.175644,3.116436,0.350186,-159.108368,0.036241,0.000000
34.790001,14.480446,-159.152847,-0.003031,0.001414,0.035921,64.412239,3.281316,0.359209,-159.152847,0.036866,0.000000
35.160000,14.598114,-159.241806,-0.003005,0.001438,0.036536,64.935654,3.307980,0.365363,-159.241806,0.037482,0.000000
35.530003,14.539284,-159.241806,-0.002979,0.001457,0.037005,64.673965,3.294649,0.370049,-159.241806,0.038097,0.000000
35.900002,15.076988,-159.330765,-0.002975,0.001488,0.037803,67.065796,3.416494,0.378028,-159.330765,0.038713,0.000000
36.270000,15.388664,-159.286285,-0.002923,0.001516,0.038505,68.452194,3.487121,0.385053,-159.286285,0.039329,0.000000
36.640003,15.381958,-159.419724,-0.002919,0.001537,0.039034,68.422363,3.485602,0.390336,-159.419724,0.039944,0.000000
37.010002,15.620277,-159.464203,-0.002884,0.001562,0.039676,69.482468,3.539605,0.396755,-159.464203,0.040560,0.000000
37.380001,15.826202,-159.464203,-0.002867,0.001586,0.040274,70.398460,3.586269,0.402743,-159.464203,0.041176,0.000000
37.750000,15.823593,-159.464203,-0.002854,0.001603,0.040708,70.386856,3.585677,0.407081,-159.464203,0.041792,0.000000
38.120003,16.384392,-159.553177,-0.002828,0.001631,0.041436,72.881416,3.712756,0.414363,-159.553177,0.042416,0.000000
38.490002,16.697929,-159.597656,-0.002790,0.001658,0.042112,74.276100,3.783805,0.421123,-159.597656,0.043032,0.000000
38.860001,16.653984,-159.731094,-0.002777,0.001680,0.042668,74.080620,3.773847,0.426679,-159.731094,0.043647,0.000000
39.230003,16.948158,-159.775574,-0.002738,0.001704,0.043292,75.389175,3.840508,0.432924,-159.775574,0.044264,0.000000
39.600002,17.024872,-159.731094,-0.002729,0.001724,0.043778,75.730415,3.857891,0.437776,-159.731094,0.044879,0.000000
39.970001,17.647850,-159.820053,-0.002716,0.001752,0.044506,78.501556,3.999060,0.445058,-159.820053,0.045494,0.000000
40.340000,17.671677,-159.864532,-0.002690,0.001774,0.045061,78.607544,4.004459,0.450614,-159.864532,0.046111,0.000000
40.710003,18.322960,-159.909012,-0.002669,0.001801,0.045755,81.504593,4.152042,0.457548,-159.909012,0.046726,0.000000
41.080002,18.667404,-159.953506,-0.002630,0.001829,0.046449,83.036758,4.230094,0.464490,-159.953506,0.047342,0.000000
41.450001,18.430199,-159.953506,-0.002613,0.001843,0.046821,81.981621,4.176342,0.468214,-159.953506,0.047967,0.000000
41.820004,19.436356,-159.997986,-0.002604,0.001880,0.047759,86.457230,4.404341,0.477586,-159.997986,0.048582,0.000000
42.190002,19.442680,-160.042465,-0.002570,0.001901,0.048287,86.485359,4.405775,0.482869,-160.042465,0.049198,0.000000
42.560001,19.475822,-160.175903,-0.002548,0.001922,0.048825,86.632782,4.413285,0.488251,-160.175903,0.049814,0.000000
42.930000,19.582321,-160.175903,-0.002531,0.001942,0.049319,87.106514,4.437418,0.493195,-160.175903,0.050429,0.000000
43.300003,19.753242,-160.175903,-0.002514,0.001964,0.049892,87.866814,4.476149,0.498917,-160.175903,0.051045,0.000000
43.670002,21.012978,-160.175903,-0.002483,0.001998,0.050750,93.470390,4.761609,0.507501,-160.175903,0.051661,0.000000
44.040001,21.227463,-160.264862,-0.002471,0.002020,0.051314,94.424469,4.810212,0.513141,-160.264862,0.052276,0.000000
44.410004,21.465408,-160.353836,-0.002445,0.002045,0.051947,95.482903,4.864131,0.519469,-160.353836,0.052892,0.000000
44.780003,21.556267,-160.398315,-0.002423,0.002065,0.052459,95.887062,4.884720,0.524586,-160.398315,0.053517,0.000000
45.150002,21.652344,-160.353836,-0.002389,0.002086,0.052988,96.314438,4.906491,0.529878,-160.353836,0.054132,0.000000
45.520000,22.653648,-160.442795,-0.002376,0.002116,0.053751,100.768463,5.133390,0.537508,-160.442795,0.054748,0.000000
45.890003,22.957504,-160.487274,-0.002367,0.002140,0.054366,102.120079,5.202245,0.543662,-160.487274,0.055364,0.000000
46.260002,23.304558,-160.576233,-0.002333,0.002164,0.054973,103.663849,5.280889,0.549733,-160.576233,0.055979,0.000000
46.630001,23.425575,-160.576233,-0.002315,0.002185,0.055494,104.202164,5.308311,0.554941,-160.576233,0.056596,0.000000
47.000004,24.380341,-160.620712,-0.002285,0.002217,0.056300,108.449173,5.524664,0.563003,-160.620712,0.057211,0.000000
47.370003,24.548279,-160.709671,-0.002281,0.002237,0.056821,109.196198,5.562720,0.568211,-160.709671,0.057826,0.000000
47.740002,25.020821,-160.754150,-0.002264,0.002263,0.057489,111.298172,5.669799,0.574888,-160.754150,0.058443,0.000000
48.110001,25.625931,-160.754150,-0.002220,0.002289,0.058147,113.989830,5.806919,0.581473,-160.754150,0.059067,0.000000
48.480003,25.806900,-160.843124,-0.002220,0.002309,0.058659,114.794823,5.847927,0.586591,-160.843124,0.059682,0.000000
48.850002,26.401207,-160.843124,-0.002177,0.002334,0.059284,117.438431,5.982599,0.592836,-160.843124,0.060299,0.000000
49.220001,26.621651,-160.887604,-0.002173,0.002352,0.059752,118.419014,6.032552,0.597521,-160.887604,0.060914,0.000000
49.590004,27.065895,-160.976562,-0.002147,0.002376,0.060342,120.395111,6.133219,0.603418,-160.976562,0.061530,0.000000
49.960003,28.144653,-161.021042,-0.002121,0.002407,0.061131,125.193672,6.377670,0.611306,-161.021042,0.062146,0.000000
50.330002,28.674911,-161.110001,-0.002095,0.002431,0.061747,127.552376,6.497828,0.617468,-161.110001,0.062761,0.000000
50.700001,29.408485,-161.110001,-0.002078,0.002457,0.062405,130.815475,6.664058,0.624053,-161.110001,0.063377,0.000000
51.070004,29.621109,-161.110001,-0.002065,0.002478,0.062952,131.761276,6.712239,0.629519,-161.110001,0.063993,0.000000
51.440002,30.302925,-161.243454,-0.002048,0.002501,0.063524,134.794144,6.866741,0.635242,-161.243454,0.064617,0.000000
51.810001,31.455048,-161.243454,-0.002022,0.002532,0.064305,139.919037,7.127816,0.643046,-161.243454,0.065233,0.000000
52.180004,31.711983,-161.332413,-0.002005,0.002554,0.064869,141.061951,7.186038,0.648686,-161.332413,0.065849,0.000000
52.550003,32.000572,-161.287933,-0.001992,0.002577,0.065450,142.345657,7.251433,0.654499,-161.287933,0.066464,0.000000
52.920002,33.025711,-161.376892,-0.001962,0.002602,0.066083,146.905701,7.483733,0.660828,-161.376892,0.067080,0.000000
53.290001,32.153992,-161.465851,-0.001944,0.002605,0.066178,143.028091,7.286199,0.661781,-161.465851,0.067696,0.000000
53.660004,34.306305,-161.465851,-0.001927,0.002644,0.067167,152.602066,7.773920,0.671667,-161.465851,0.068311,0.000000
54.030003,35.406662,-161.554810,-0.001901,0.002674,0.067930,157.496704,8.023264,0.679298,-161.554810,0.068927,0.000000
54.400002,36.145821,-161.599289,-0.001884,0.002700,0.068589,160.784637,8.190760,0.685891,-161.599289,0.069543,0.000000
54.770004,36.908813,-161.599289,-0.001863,0.002724,0.069196,164.178604,8.363656,0.691962,-161.599289,0.070167,0.000000
55.140003,37.166122,-161.732742,-0.001837,0.002743,0.069673,165.323166,8.421964,0.696731,-161.732742,0.070783,0.000000
55.510002,38.660828,-161.777222,-0.001819,0.002773,0.070428,171.971954,8.760669,0.704278,-161.777222,0.071399,0.000000
55.880001,37.825592,-161.777222,-0.001802,0.002789,0.070835,168.256638,8.571402,0.708351,-161.777222,0.072014,0.000000
56.250004,40.018120,-161.821701,-0.001776,0.002819,0.071607,178.009491,9.068235,0.716072,-161.821701,0.072631,0.000000
56.620003,40.982567,-161.955139,-0.001768,0.002844,0.072248,182.299561,9.286782,0.722483,-161.955139,0.073246,0.000000
56.990002,41.559746,-161.910660,-0.001759,0.002864,0.072752,184.866989,9.417573,0.727517,-161.910660,0.073861,0.000000
57.360004,43.305801,-161.999619,-0.001729,0.002898,0.073602,192.633820,9.813234,0.736018,-161.999619,0.074478,0.000000
57.730003,43.998413,-162.044098,-0.001716,0.002921,0.074192,195.714722,9.970183,0.741915,-162.044098,0.075102,0.000000
58.100002,45.001953,-162.044098,-0.001694,0.002944,0.074790,200.178680,10.197588,0.747895,-162.044098,0.075718,0.000000
58.470001,45.998055,-161.999619,-0.001694,0.002969,0.075423,204.609558,10.423308,0.754231,-161.999619,0.076333,0.000000
58.840004,46.396118,-162.177551,-0.001664,0.002986,0.075848,206.380234,10.513511,0.758478,-162.177551,0.076949,0.000000
59.210003,46.904037,-162.222031,-0.001647,0.003005,0.076325,208.639572,10.628607,0.763247,-162.222031,0.077565,0.000000
59.580002,48.883942,-162.266510,-0.001621,0.003039,0.077192,217.446640,11.077259,0.771922,-162.266510,0.078181,0.000000
59.950005,50.262459,-162.266510,-0.001617,0.003065,0.077842,223.578583,11.389636,0.778424,-162.266510,0.078796,0.000000
60.320004,51.232117,-162.355469,-0.001600,0.003089,0.078467,227.891830,11.609364,0.784669,-162.355469,0.079412,0.000000
60.690002,52.043892,-162.399948,-0.001595,0.003108,0.078944,231.502792,11.793315,0.789438,-162.399948,0.080028,0.000000
61.060001,52.984879,-162.444427,-0.001561,0.003132,0.079559,235.688507,12.006545,0.795592,-162.444427,0.080652,0.000000
61.430004,54.769287,-162.488907,-0.001539,0.003159,0.080227,243.625961,12.410898,0.802269,-162.488907,0.081268,0.000000
61.800003,54.855675,-162.488907,-0.001548,0.003179,0.080739,244.010223,12.430473,0.807386,-162.488907,0.081884,0.000000
62.170002,56.699295,-162.577881,-0.001522,0.003201,0.081303,252.211060,12.848244,0.813026,-162.577881,0.082499,0.000000
62.540005,58.661324,-162.622360,-0.001518,0.003233,0.082118,260.938599,13.292846,0.821178,-162.622360,0.083115,0.000000
62.910004,59.237015,-162.666840,-0.001496,0.003252,0.082595,263.499390,13.423300,0.825947,-162.666840,0.083731,0.000000
63.280003,61.736748,-162.711319,-0.001470,0.003286,0.083462,274.618774,13.989747,0.834622,-162.711319,0.084346,0.000000
63.650002,62.468834,-162.711319,-0.001466,0.003306,0.083974,277.875244,14.155640,0.839740,-162.711319,0.084963,0.000000
64.020004,63.203148,-162.800278,-0.001444,0.003324,0.084424,281.141632,14.322039,0.844244,-162.800278,0.085578,0.000000
64.389999,63.965401,-162.844757,-0.001440,0.003340,0.084841,284.532318,14.494766,0.848407,-162.844757,0.086202,0.000000
64.760002,66.154579,-162.889236,-0.001418,0.003374,0.085691,294.270264,14.990842,0.856908,-162.889236,0.086818,0.000000
65.130005,65.163322,-162.889236,-0.001414,0.003362,0.085396,289.860931,14.766220,0.853956,-162.889236,290.064636,0.000000
65.500000,66.391777,-162.978210,-0.001410,0.003338,0.084780,295.325378,15.044592,0.847801,-162.978210,294.500488,0.000000
65.870003,65.426216,-162.978210,-0.001401,0.003339,0.084806,291.030334,14.825793,0.848059,-162.978210,294.500488,0.000000
66.240005,65.060173,-163.111649,-0.001388,0.003385,0.085985,289.402100,14.742846,0.859852,-163.111649,294.500488,0.000000
66.610001,65.503670,-163.111649,-0.001388,0.003398,0.086306,291.374878,14.843344,0.863062,-163.111649,294.500488,0.000000
66.980003,64.907875,-163.156128,-0.001380,0.003398,0.086306,288.724640,14.708335,0.863062,-163.156128,294.500488,0.000000
67.350006,64.377617,-163.156128,-0.001380,0.003399,0.086324,286.365936,14.588177,0.863236,-163.156128,294.500488,0.000000
67.720001,66.439064,-163.289566,-0.001358,0.003256,0.082698,295.535706,15.055307,0.826984,-163.289566,294.500488,0.000000
68.090004,65.809761,-163.334045,-0.001362,0.003258,0.082742,292.736450,14.912705,0.827423,-163.334045,294.500488,0.000000
68.460007,65.320091,-163.334045,-0.001354,0.003351,0.085119,290.558289,14.801744,0.851185,-163.334045,294.500488,0.000000
68.830002,65.022194,-163.378540,-0.001350,0.003405,0.086480,289.233154,14.734240,0.864796,-163.378540,294.500488,0.000000
69.200005,65.244499,-163.423019,-0.001354,0.003430,0.087121,290.222015,14.784615,0.871215,-163.423019,294.500488,0.000000
69.570000,65.292152,-163.467499,-0.001350,0.003431,0.087156,290.433990,14.795413,0.871563,-163.467499,294.500488,0.000000
69.940002,65.259026,-163.556458,-0.001354,0.003436,0.087269,290.286652,14.787907,0.872691,-163.556458,294.500488,0.000000
70.310005,65.234810,-163.556458,-0.001350,0.003439,0.087339,290.178925,14.782419,0.873387,-163.556458,294.500488,0.000000
70.680000,65.203911,-163.511978,-0.001332,0.003442,0.087425,290.041473,14.775417,0.874250,-163.511978,294.500488,0.000000
71.050003,65.265724,-163.600937,-0.001341,0.003446,0.087520,290.316437,14.789425,0.875204,-163.600937,294.500488,0.000000
71.420006,65.270561,-163.734375,-0.001337,0.003448,0.087590,290.337952,14.790521,0.875900,-163.734375,294.500488,0.000000
71.790001,65.117149,-163.734375,-0.001319,0.003448,0.087590,289.655548,14.755756,0.875900,-163.734375,294.500488,0.000000
72.160004,65.097038,-163.778854,-0.001324,0.003451,0.087660,289.566101,14.751200,0.876597,-163.778854,294.500488,0.000000
72.530006,65.080284,-163.778854,-0.001332,0.003454,0.087720,289.491577,14.747403,0.877202,-163.778854,294.500488,0.000000
72.900002,65.585960,-163.912308,-0.001337,0.003461,0.087902,291.740936,14.861991,0.879019,-163.912308,294.500488,0.000000
73.270004,65.466423,-163.912308,-0.001328,0.003461,0.087902,291.209198,14.834903,0.879019,-163.912308,294.500488,0.000000
73.640007,65.270561,-164.001266,-0.001324,0.003461,0.087902,290.337952,14.790521,0.879019,-164.001266,294.500488,0.000000
74.010002,65.079903,-164.001266,-0.001298,0.003461,0.087919,289.489868,14.747316,0.879193,-164.001266,294.500488,0.000000
74.380005,65.292534,-164.001266,-0.001319,0.003466,0.088041,290.435699,14.795500,0.880412,-164.001266,294.500488,0.000000
74.750000,65.190132,-164.134705,-0.001324,0.003466,0.088041,289.980194,14.772295,0.880412,-164.134705,294.500488,0.000000
75.120003,65.027397,-164.223679,-0.001319,0.003466,0.088041,289.256317,14.735419,0.880412,-164.223679,294.500488,0.000000
75.490005,65.418770,-164.223679,-0.001315,0.003473,0.088205,290.997223,14.824105,0.882055,-164.223679,294.500488,0.000000
75.860001,65.323433,-164.223679,-0.001302,0.003473,0.088205,290.573151,14.802502,0.882055,-164.223679,294.500488,0.000000
76.230003,65.222893,-164.312637,-0.001306,0.003473,0.088205,290.125916,14.779719,0.882055,-164.312637,294.500488,0.000000
76.600006,65.458244,-164.312637,-0.001319,0.003478,0.088345,291.172821,14.833050,0.883447,-164.312637,294.500488,0.000000
76.970001,65.390099,-164.401596,-0.001302,0.003478,0.088345,290.869690,14.817608,0.883447,-164.401596,294.500488,0.000000
77.340004,65.299232,-164.446075,-0.001306,0.003478,0.088353,290.465485,14.797018,0.883531,-164.446075,294.500488,0.000000
77.710007,65.280251,-164.446075,-0.001302,0.003479,0.088379,290.381042,14.792717,0.883788,-164.446075,294.500488,0.000000
78.080002,65.161827,-164.490555,-0.001302,0.003479,0.088379,289.854279,14.765881,0.883788,-164.490555,294.500488,0.000000
78.450005,65.056068,-164.623993,-0.001302,0.003480,0.088396,289.383850,14.741916,0.883962,-164.623993,294.500488,0.000000
78.820007,65.197945,-164.579514,-0.001302,0.003483,0.088458,290.014954,14.774065,0.884575,-164.579514,294.500488,0.000000
79.190002,65.091072,-164.712967,-0.001293,0.003483,0.088458,289.539551,14.749847,0.884575,-164.712967,294.500488,0.000000
79.560005,65.003197,-164.712967,-0.001293,0.003483,0.088458,289.148651,14.729935,0.884575,-164.712967,294.500488,0.000000
79.930000,64.952934,-164.757446,-0.001306,0.003484,0.088501,288.925079,14.718545,0.885007,-164.757446,294.500488,0.000000
80.300003,64.905266,-164.801926,-0.001306,0.003484,0.088501,288.713043,14.707744,0.885007,-164.801926,294.500488,0.000000
80.670006,65.411324,-164.890884,-0.001289,0.003491,0.088665,290.964111,14.822417,0.886649,-164.890884,294.500488,0.000000
81.040001,65.348381,-164.935364,-0.001289,0.003491,0.088665,290.684113,14.808154,0.886649,-164.935364,294.500488,0.000000
81.410004,65.300346,-164.935364,-0.001298,0.003491,0.088665,290.470459,14.797271,0.886649,-164.935364,294.500488,0.000000
81.780006,65.225502,-164.979843,-0.001289,0.003491,0.088665,290.137512,14.780310,0.886649,-164.979843,294.500488,0.000000
82.150002,65.106346,-165.024323,-0.001289,0.003491,0.088665,289.607483,14.753309,0.886649,-165.024323,294.500488,0.000000
82.520004,65.033363,-165.113297,-0.001302,0.003491,0.088665,289.282837,14.736771,0.886649,-165.113297,294.500488,0.000000
82.890007,64.976753,-165.157776,-0.001281,0.003491,0.088665,289.031036,14.723943,0.886649,-165.157776,294.500488,0.000000
83.260002,64.862068,-165.157776,-0.001293,0.003491,0.088665,288.520874,14.697954,0.886649,-165.157776,294.500488,0.000000
83.630005,65.758003,-165.246735,-0.001302,0.003501,0.088917,292.506195,14.900976,0.889170,-165.246735,294.500488,0.000000
84.000008,65.647408,-165.291214,-0.001298,0.003501,0.088917,292.014252,14.875915,0.889170,-165.291214,294.500488,0.000000
84.370003,65.581123,-165.335693,-0.001285,0.003501,0.088917,291.719421,14.860894,0.889170,-165.335693,294.500488,0.000000
84.740005,65.539787,-165.380173,-0.001285,0.003501,0.088917,291.535522,14.851528,0.889170,-165.380173,294.500488,0.000000
85.110001,65.463081,-165.380173,-0.001276,0.003501,0.088917,291.194336,14.834146,0.889170,-165.380173,294.500488,0.000000
85.480003,65.364403,-165.380173,-0.001281,0.003501,0.088917,290.755371,14.811786,0.889170,-165.380173,294.500488,0.000000
85.850006,65.312263,-165.513626,-0.001293,0.003501,0.088917,290.523468,14.799971,0.889170,-165.513626,294.500488,0.000000
86.220001,65.239662,-165.558105,-0.001281,0.003501,0.088917,290.200500,14.783519,0.889170,-165.558105,294.500488,0.000000
86.590004,65.164803,-165.602585,-0.001281,0.003501,0.088917,289.867523,14.766556,0.889170,-165.602585,294.500488,0.000000
86.960007,65.088478,-165.602585,-0.001289,0.003501,0.088917,289.528015,14.749260,0.889170,-165.602585,294.500488,0.000000
87.330002,65.022194,-165.691544,-0.001289,0.003501,0.088917,289.233154,14.734240,0.889170,-165.691544,294.500488,0.000000
87.700005,64.952934,-165.691544,-0.001302,0.003501,0.088917,288.925079,14.718545,0.889170,-165.691544,294.500488,0.000000
88.070007,64.875847,-165.780502,-0.001285,0.003501,0.088917,288.582184,14.701077,0.889170,-165.780502,294.500488,0.000000
88.440002,64.821114,-165.869461,-0.001272,0.003501,0.088925,288.338715,14.688674,0.889253,-165.869461,294.500488,0.000000
88.810005,64.728767,-165.824982,-0.001281,0.003501,0.088925,287.927948,14.667748,0.889253,-165.824982,294.500488,0.000000
89.180008,64.675133,-165.913940,-0.001285,0.003501,0.088925,287.689362,14.655595,0.889253,-165.913940,294.500488,0.000000
89.550003,66.492317,-165.958435,-0.001293,0.003511,0.089186,295.772614,15.067375,0.891858,-165.958435,294.500488,0.000000
89.920006,66.290123,-166.002914,-0.001272,0.003502,0.088960,294.873199,15.021557,0.889602,-166.002914,294.500488,0.000000
90.290001,66.205223,-166.047394,-0.001272,0.003502,0.088960,294.495544,15.002318,0.889602,-166.047394,294.500488,0.000000
90.660004,66.129631,-166.047394,-0.001263,0.003502,0.088960,294.159302,14.985188,0.889602,-166.047394,294.500488,0.000000
91.030006,66.063713,-166.091873,-0.001281,0.003502,0.088960,293.866058,14.970251,0.889602,-166.091873,294.500488,0.000000
91.400002,65.981056,-166.180832,-0.001268,0.003502,0.088960,293.498383,14.951521,0.889602,-166.180832,294.500488,0.000000
91.770004,65.873436,-166.225311,-0.001272,0.003502,0.088960,293.019684,14.927135,0.889602,-166.225311,294.500488,0.000000
92.140007,65.860023,-166.269791,-0.001272,0.003502,0.088960,292.960022,14.924095,0.889602,-166.269791,294.500488,0.000000
92.510002,65.778481,-166.225311,-0.001268,0.003502,0.088960,292.597290,14.905617,0.889602,-166.225311,294.500488,0.000000
92.880005,65.737892,-166.269791,-0.001263,0.003502,0.088960,292.416748,14.896420,0.889602,-166.269791,294.500488,0.000000
93.250008,65.620216,-166.403244,-0.001268,0.003502,0.088960,291.893311,14.869754,0.889602,-166.403244,294.500488,0.000000
93.620003,65.582237,-166.447723,-0.001268,0.003502,0.088960,291.724365,14.861147,0.889602,-166.447723,294.500488,0.000000
93.990005,65.537178,-166.403244,-0.001263,0.003502,0.088960,291.523926,14.850937,0.889602,-166.403244,294.500488,0.000000
94.360008,65.468666,-166.492203,-0.001263,0.003502,0.088960,291.219177,14.835411,0.889602,-166.492203,294.500488,0.000000
94.730003,65.381905,-166.492203,-0.001281,0.003502,0.088960,290.833252,14.815751,0.889602,-166.492203,294.500488,0.000000
95.100006,65.323067,-166.625641,-0.001268,0.003502,0.088960,290.571503,14.802419,0.889602,-166.625641,294.500488,0.000000
95.470001,65.287315,-166.714600,-0.001272,0.003502,0.088960,290.412476,14.794317,0.889602,-166.714600,294.500488,0.000000
95.840004,65.230339,-166.670120,-0.001263,0.003502,0.088960,290.159027,14.781406,0.889602,-166.670120,294.500488,0.000000
96.210007,65.297752,-166.714600,-0.001272,0.003516,0.089299,290.458923,14.796682,0.892985,-166.714600,294.500488,0.000000
96.580002,65.272423,-166.714600,-0.001276,0.003516,0.089299,290.346252,14.790943,0.892985,-166.714600,294.500488,0.000000
96.950005,65.231087,-166.848053,-0.001263,0.003516,0.089299,290.162354,14.781575,0.892985,-166.848053,294.500488,0.000000
97.320007,65.194969,-166.892532,-0.001259,0.003516,0.089299,290.001709,14.773392,0.892985,-166.892532,294.500488,0.000000
97.690002,65.139488,-166.892532,-0.001259,0.003516,0.089299,289.754913,14.760818,0.892985,-166.892532,294.500488,0.000000
98.060005,65.231087,-166.937012,-0.001263,0.003519,0.089394,290.162354,14.781575,0.893939,-166.937012,294.500488,0.000000
98.430008,65.263863,-167.025970,-0.001276,0.003519,0.089394,290.308167,14.789002,0.893939,-167.025970,294.500488,0.000000
98.800003,65.244118,-167.070450,-0.001276,0.003519,0.089394,290.220337,14.784528,0.893939,-167.070450,294.500488,0.000000
99.170006,65.218437,-167.070450,-0.001255,0.003519,0.089394,290.106110,14.778709,0.893939,-167.070450,294.500488,0.000000
99.540001,65.179710,-167.114929,-0.001268,0.003519,0.089394,289.933838,14.769934,0.893939,-167.114929,294.500488,0.000000
99.910004,65.142097,-167.114929,-0.001259,0.003519,0.089394,289.766510,14.761411,0.893939,-167.114929,294.500488,0.000000
100.280006,65.100761,-167.159409,-0.001268,0.003519,0.089394,289.582642,14.752044,0.893939,-167.159409,294.500488,0.000000
100.650002,65.066124,-167.292862,-0.001259,0.003519,0.089394,289.428589,14.744194,0.893939,-167.292862,294.500488,0.000000
101.020004,65.045647,-167.292862,-0.001268,0.003519,0.089394,289.337494,14.739554,0.893939,-167.292862,294.500488,0.000000
101.390007,64.997246,-167.337341,-0.001272,0.003520,0.089402,289.122192,14.728586,0.894022,-167.337341,294.500488,0.000000
101.760002,65.743843,-167.381821,-0.001272,0.003529,0.089628,292.443207,14.897767,0.896278,-167.381821,294.500488,0.000000
102.130005,65.699165,-167.470779,-0.001255,0.003529,0.089628,292.244476,14.887644,0.896278,-167.470779,294.500488,0.000000
102.500008,65.682411,-167.515259,-0.001250,0.003529,0.089628,292.169952,14.883847,0.896278,-167.515259,294.500488,0.000000
102.870003,65.666389,-167.604218,-0.001263,0.003529,0.089628,292.098694,14.880217,0.896278,-167.604218,294.500488,0.000000
103.240005,65.616875,-167.559738,-0.001259,0.003529,0.089628,291.878448,14.868996,0.896278,-167.559738,294.500488,0.000000
103.610008,65.598244,-167.604218,-0.001246,0.003529,0.089628,291.795563,14.864775,0.896278,-167.604218,294.500488,0.000000
103.980003,65.587456,-167.648712,-0.001263,0.003529,0.089628,291.747589,14.862329,0.896278,-167.648712,294.500488,0.000000
104.350006,65.569954,-167.693192,-0.001255,0.003529,0.089628,291.669708,14.858364,0.896278,-167.693192,294.500488,0.000000
104.720001,65.525642,-167.782150,-0.001272,0.003529,0.089628,291.472626,14.848323,0.896278,-167.782150,294.500488,0.000000
105.090004,65.501427,-167.826630,-0.001250,0.003529,0.089628,291.364899,14.842835,0.896278,-167.826630,294.500488,0.000000
105.460007,65.485054,-167.826630,-0.001259,0.003529,0.089628,291.292053,14.839126,0.896278,-167.826630,294.500488,0.000000
105.830002,65.420631,-167.871109,-0.001263,0.003529,0.089628,291.005493,14.824528,0.896278,-167.871109,294.500488,0.000000
106.200005,65.383018,-167.960068,-0.001263,0.003529,0.089628,290.838196,14.816004,0.896278,-167.960068,294.500488,0.000000
106.570007,65.355843,-167.960068,-0.001263,0.003529,0.089628,290.717316,14.809846,0.896278,-167.960068,294.500488,0.000000
106.940002,65.323067,-168.049026,-0.001268,0.003529,0.089628,290.571503,14.802419,0.896278,-168.049026,294.500488,0.000000
107.310005,65.292152,-168.049026,-0.001255,0.003529,0.089628,290.433990,14.795413,0.896278,-168.049026,294.500488,0.000000
107.680008,65.288811,-168.138000,-0.001259,0.003529,0.089628,290.419128,14.794656,0.896278,-168.138000,294.500488,0.000000
108.050003,65.246727,-168.182480,-0.001242,0.003529,0.089628,290.231934,14.785120,0.896278,-168.182480,294.500488,0.000000
108.420006,65.213219,-168.226959,-0.001250,0.003529,0.089628,290.082886,14.777527,0.896278,-168.226959,294.500488,0.000000
108.790009,65.170387,-168.226959,-0.001250,0.003529,0.089628,289.892365,14.767821,0.896278,-168.226959,294.500488,0.000000
109.160004,65.118263,-168.315918,-0.001246,0.003529,0.089628,289.660492,14.756009,0.896278,-168.315918,294.500488,0.000000
109.530006,65.085121,-168.360397,-0.001263,0.003529,0.089628,289.513092,14.748499,0.896278,-168.360397,294.500488,0.000000
109.900002,65.063896,-168.449356,-0.001255,0.003529,0.089628,289.418671,14.743690,0.896278,-168.449356,294.500488,0.000000
110.270004,65.023674,-168.449356,-0.001263,0.003529,0.089628,289.239746,14.734575,0.896278,-168.449356,294.500488,0.000000
110.640007,64.997612,-168.493835,-0.001255,0.003529,0.089628,289.123810,14.728669,0.896278,-168.493835,294.500488,0.000000
111.010002,64.979362,-168.493835,-0.001246,0.003529,0.089628,289.042633,14.724534,0.896278,-168.493835,294.500488,0.000000
111.380005,64.944359,-168.538330,-0.001250,0.003529,0.089628,288.886932,14.716602,0.896278,-168.538330,294.500488,0.000000
111.750008,64.917931,-168.627289,-0.001250,0.003529,0.089628,288.769379,14.710613,0.896278,-168.627289,294.500488,0.000000
112.120003,64.862434,-168.716248,-0.001255,0.003529,0.089637,288.522522,14.698038,0.896369,-168.716248,294.500488,0.000000
112.490005,64.836754,-168.716248,-0.001259,0.003529,0.089637,288.408295,14.692219,0.896369,-168.716248,294.500488,0.000000
112.860008,64.801750,-168.760727,-0.001255,0.003529,0.089637,288.252594,14.684287,0.896369,-168.760727,294.500488,0.000000
113.230003,64.755577,-168.805206,-0.001255,0.003529,0.089637,288.047180,14.673823,0.896369,-168.805206,294.500488,0.000000
113.600006,64.744026,-168.849686,-0.001246,0.003529,0.089637,287.995819,14.671206,0.896369,-168.849686,294.500488,0.000000
113.970009,64.716103,-168.894165,-0.001250,0.003529,0.089637,287.871613,14.664879,0.896369,-168.894165,294.500488,0.000000
114.340004,66.016426,-168.938660,-0.001242,0.003539,0.089888,293.655731,14.959536,0.898882,-168.938660,294.500488,0.000000
114.710007,65.924828,-168.938660,-0.001246,0.003539,0.089879,293.248291,14.938779,0.898791,-168.938660,294.500488,0.000000
115.080002,65.871574,-169.027618,-0.001246,0.003539,0.089879,293.011383,14.926712,0.898791,-169.027618,294.500488,0.000000
115.450005,65.851097,-169.116577,-0.001255,0.003539,0.089879,292.920319,14.922072,0.898791,-169.116577,294.500488,0.000000
115.820007,65.849236,-169.161057,-0.001246,0.003539,0.089879,292.912018,14.921650,0.898791,-169.161057,294.500488,0.000000
116.190002,65.787041,-169.205536,-0.001246,0.003539,0.089879,292.635376,14.907557,0.898791,-169.205536,294.500488,0.000000
116.560005,65.768425,-169.161057,-0.001242,0.003539,0.089879,292.552551,14.903338,0.898791,-169.161057,294.500488,0.000000
116.930008,65.759117,-169.205536,-0.001250,0.003539,0.089879,292.511169,14.901229,0.898791,-169.205536,294.500488,0.000000
117.300003,65.693581,-169.294495,-0.001263,0.003539,0.089879,292.219635,14.886378,0.898791,-169.294495,294.500488,0.000000
117.670006,65.655220,-169.427948,-0.001255,0.003539,0.089879,292.049011,14.877686,0.898791,-169.427948,294.500488,0.000000
118.040009,65.617241,-169.383469,-0.001233,0.003539,0.089879,291.880066,14.869080,0.898791,-169.383469,294.500488,0.000000
118.410004,65.596764,-169.383469,-0.001237,0.003539,0.089879,291.788971,14.864439,0.898791,-169.383469,294.500488,0.000000
118.780006,65.577400,-169.427948,-0.001233,0.003539,0.089879,291.702850,14.860051,0.898791,-169.427948,294.500488,0.000000
119.150009,65.545372,-169.516907,-0.001246,0.003539,0.089879,291.560364,14.852794,0.898791,-169.516907,294.500488,0.000000
119.520004,65.522652,-169.605865,-0.001250,0.003539,0.089879,291.459320,14.847645,0.898791,-169.605865,294.500488,0.000000
119.890007,65.489891,-169.694824,-0.001242,0.003539,0.089879,291.313599,14.840221,0.898791,-169.694824,294.500488,0.000000
120.260002,65.467552,-169.650345,-0.001250,0.003539,0.089879,291.214203,14.835159,0.898791,-169.650345,294.500488,0.000000
120.630005,65.421745,-169.694824,-0.001250,0.003539,0.089879,291.010468,14.824780,0.898791,-169.694824,294.500488,0.000000
121.000008,65.392326,-169.783783,-0.001242,0.003539,0.089879,290.879608,14.818112,0.898791,-169.783783,294.500488,0.000000
121.370003,65.352852,-169.828278,-0.001259,0.003539,0.089879,290.704010,14.809168,0.898791,-169.828278,294.500488,0.000000
121.740005,65.338707,-169.872757,-0.001237,0.003539,0.089879,290.641083,14.805963,0.898791,-169.872757,294.500488,0.000000
122.110008,65.309288,-169.917236,-0.001242,0.003539,0.089879,290.510223,14.799295,0.898791,-169.917236,294.500488,0.000000
122.480003,65.290672,-169.872757,-0.001242,0.003539,0.089879,290.427429,14.795078,0.898791,-169.872757,294.500488,0.000000
122.850006,65.263863,-170.006195,-0.001255,0.003539,0.089879,290.308167,14.789002,0.898791,-170.006195,294.500488,0.000000
123.220009,65.253059,-170.050674,-0.001242,0.003539,0.089879,290.260101,14.786554,0.898791,-170.050674,294.500488,0.000000
123.590004,65.214333,-170.050674,-0.001237,0.003539,0.089879,290.087830,14.777779,0.898791,-170.050674,294.500488,0.000000
123.960007,65.190498,-170.095154,-0.001242,0.003539,0.089879,289.981812,14.772378,0.898791,-170.095154,294.500488,0.000000
124.330009,65.175240,-170.139633,-0.001250,0.003539,0.089879,289.913940,14.768920,0.898791,-170.139633,294.500488,0.000000
124.700005,65.113045,-170.273087,-0.001237,0.003539,0.089879,289.637299,14.754827,0.898791,-170.273087,294.500488,0.000000
125.070007,65.095924,-170.273087,-0.001237,0.003539,0.089879,289.561127,14.750948,0.898791,-170.273087,294.500488,0.000000
125.440002,65.066505,-170.273087,-0.001246,0.003539,0.089879,289.430267,14.744281,0.898791,-170.273087,1681.640991,0.000000
125.810005,65.041176,-170.273087,-0.001237,0.003531,0.089688,289.317596,14.738542,0.896884,-170.273087,0.089480,0.000000
126.180008,65.042305,-170.362045,-0.001237,0.003516,0.089316,289.322632,14.738797,0.893160,-170.362045,0.088865,0.000000
126.550003,64.876961,-170.406525,-0.001237,0.003493,0.088726,288.587128,14.701330,0.887263,-170.406525,0.088249,0.000000
126.920006,64.809944,-170.451004,-0.001255,0.003471,0.088154,288.289032,14.686143,0.881540,-170.451004,0.087633,0.000000
127.290009,64.791313,-170.495483,-0.001237,0.003446,0.087520,288.206146,14.681921,0.875204,-170.495483,0.087018,0.000000
127.660004,64.768974,-170.539963,-0.001224,0.003433,0.087199,288.106781,14.676860,0.871994,-170.539963,0.086402,0.000000
128.029999,64.771950,-170.539963,-0.001237,0.003397,0.086289,288.120026,14.677533,0.862888,-170.539963,0.085786,0.000000
128.400009,64.711998,-170.673416,-0.001250,0.003377,0.085777,287.853333,14.663948,0.857771,-170.673416,0.085171,0.000000
128.770004,64.693764,-170.717896,-0.001233,0.003354,0.085187,287.772247,14.659817,0.851874,-170.717896,0.084546,0.000000
129.139999,64.644234,-170.717896,-0.001237,0.003329,0.084564,287.551910,14.648593,0.845636,-170.717896,0.083930,0.000000
129.510010,64.391396,-170.762375,-0.001224,0.003310,0.084078,286.427246,14.591298,0.840777,-170.762375,0.083315,0.000000
129.880005,63.805275,-170.806854,-0.001237,0.003287,0.083488,283.820038,14.458482,0.834880,-170.806854,0.082698,0.000000
130.250000,62.893707,-170.851334,-0.001229,0.003261,0.082829,279.765167,14.251918,0.828286,-170.851334,0.082083,0.000000
130.620010,61.749405,-170.940292,-0.001229,0.003239,0.082265,274.675079,13.992616,0.822654,-170.940292,0.081468,0.000000
130.990005,60.493393,-170.940292,-0.001212,0.003218,0.081727,269.088043,13.707999,0.817272,-170.940292,0.080851,0.000000
131.360001,58.786438,-170.895813,-0.001216,0.003194,0.081138,261.495148,13.321198,0.811375,-170.895813,0.080236,0.000000
131.730011,57.836891,-170.984772,-0.001212,0.003182,0.080834,257.271332,13.106027,0.808340,-170.984772,0.079620,0.000000
132.100006,55.013565,-171.073730,-0.001229,0.003147,0.079923,244.712555,12.466251,0.799234,-171.073730,0.078996,0.000000
132.470001,53.352409,-171.118225,-0.001212,0.003130,0.079499,237.323364,12.089829,0.794987,-171.118225,0.078380,0.000000
132.840012,51.624229,-171.118225,-0.001216,0.003103,0.078805,229.636047,11.698217,0.788053,-171.118225,0.077764,0.000000
133.210007,47.924706,-171.162704,-0.001203,0.003076,0.078137,213.179733,10.859894,0.781369,-171.162704,0.077148,0.000000
133.580002,46.170090,-171.207184,-0.001233,0.003063,0.077808,205.374817,10.462292,0.778076,-171.207184,0.076533,0.000000
133.950012,42.418434,-171.296143,-0.001212,0.003026,0.076862,188.686615,9.612154,0.768621,-171.296143,0.075917,0.000000
134.320007,40.078819,-171.296143,-0.001216,0.003006,0.076359,178.279495,9.081990,0.763595,-171.296143,0.075301,0.000000
134.690002,38.445595,-171.340622,-0.001203,0.002982,0.075752,171.014542,8.711896,0.757524,-171.340622,0.074686,0.000000
135.060013,35.401451,-171.340622,-0.001194,0.002964,0.075276,157.473526,8.022083,0.752755,-171.340622,0.074070,0.000000
135.430008,32.772125,-171.385101,-0.001199,0.002939,0.074651,145.777695,7.426270,0.746510,-171.385101,0.073445,0.000000
135.800003,29.849007,-171.429581,-0.001224,0.002912,0.073974,132.775009,6.763882,0.739743,-171.429581,0.072830,0.000000
136.170013,26.801880,-171.518555,-0.001212,0.002883,0.073220,119.220718,6.073392,0.732203,-171.518555,0.072214,0.000000
136.540009,23.874657,-171.607513,-0.001212,0.002856,0.072552,106.199776,5.410074,0.725519,-171.607513,0.071598,0.000000
136.910004,22.520340,-171.607513,-0.001212,0.002838,0.072084,100.175476,5.103182,0.720841,-171.607513,0.070983,0.000000
137.280014,19.788620,-171.607513,-0.001220,0.002821,0.071642,88.024178,4.484166,0.716420,-171.607513,0.070366,0.000000
137.650009,16.702393,-171.696472,-0.001224,0.002789,0.070835,74.295952,3.784816,0.708351,-171.696472,0.069751,0.000000
138.020004,13.827682,-171.829910,-0.001220,0.002764,0.070202,61.508602,3.133398,0.702022,-171.829910,0.069136,0.000000
138.389999,11.599030,-171.785431,-0.001216,0.002740,0.069586,51.595058,2.628378,0.695861,-171.785431,0.068519,0.000000
138.760010,9.062057,-171.829910,-0.001212,0.002719,0.069066,40.310043,2.053492,0.690660,-171.829910,0.067895,0.000000
139.130005,6.480766,-171.874390,-0.001216,0.002692,0.068372,28.827888,1.468563,0.683719,-171.874390,0.067280,0.000000
139.500000,3.009514,-171.918869,-0.001216,0.002660,0.067566,13.386986,0.681966,0.675657,-171.918869,0.066664,0.000000
139.870010,0.484459,-172.007843,-0.001212,0.002637,0.066984,2.154981,0.109780,0.669843,-172.007843,0.066048,0.000000
140.240005,-1.588913,-172.007843,-0.001212,0.002616,0.066456,-7.067838,-0.360053,0.664559,-172.007843,0.065433,0.000000
140.610001,-2.901154,-172.052322,-0.001212,0.002604,0.066135,-12.904976,-0.657411,0.661350,-172.052322,0.064816,0.000000
140.980011,-0.201828,-172.141281,-0.001229,0.002583,0.065597,-0.897776,-0.045735,0.655968,-172.141281,0.064201,0.000000
141.350006,-0.082298,-172.141281,-0.001233,0.002549,0.064738,-0.366081,-0.018649,0.647384,-172.141281,0.063585,0.000000
141.720001,-0.068520,-172.230240,-0.001255,0.002522,0.064053,-0.304790,-0.015527,0.640533,-172.230240,0.062961,0.000000
142.090012,-0.063675,-172.274719,-0.001237,0.002498,0.063446,-0.283240,-0.014429,0.634462,-172.274719,0.062345,0.000000
142.460007,-0.067772,-172.319199,-0.001255,0.002472,0.062796,-0.301465,-0.015357,0.627959,-172.319199,0.061729,0.000000
142.830002,-0.006706,-172.319199,-0.001281,0.002472,0.062796,-0.029831,-0.001520,0.627959,-172.319199,0.061113,0.000000
143.200012,-0.052505,-172.408173,-0.001337,0.002427,0.061651,-0.233556,-0.011898,0.616514,-172.408173,0.060498,0.000000
143.570007,-0.052505,-172.452652,-0.001358,0.002399,0.060922,-0.233556,-0.011898,0.609224,-172.452652,0.059882,0.000000
143.940002,-0.040962,-172.452652,-0.001388,0.002371,0.060220,-0.182209,-0.009282,0.602199,-172.452652,0.059266,0.000000
144.310013,-0.025322,-172.541611,-0.001397,0.002351,0.059709,-0.112638,-0.005738,0.597090,-172.541611,0.058651,0.000000
144.680008,-0.015640,-172.497131,-0.001436,0.002328,0.059136,-0.069571,-0.003544,0.591360,-172.497131,0.058035,0.000000
145.050003,-0.041702,-172.630569,-0.001475,0.002296,0.058312,-0.185501,-0.009450,0.583124,-172.630569,0.057411,0.000000
145.420013,-0.052132,-172.675049,-0.001505,0.002274,0.057757,-0.231893,-0.011813,0.577575,-172.675049,0.056795,0.000000
145.790009,-0.033516,-172.764008,-0.001513,0.002247,0.057081,-0.149086,-0.007595,0.570808,-172.764008,0.056179,0.000000
146.160004,-0.060699,-172.764008,-0.001539,0.002230,0.056647,-0.270005,-0.013755,0.566470,-172.764008,0.055563,0.000000
146.530014,-0.033890,-172.719528,-0.001556,0.002217,0.056318,-0.150749,-0.007680,0.563177,-172.719528,0.054948,0.000000
146.900009,-0.053253,-172.808502,-0.001595,0.002177,0.055286,-0.236882,-0.012067,0.552860,-172.808502,0.054332,0.000000
147.270004,-0.078941,-172.852982,-0.001634,0.002154,0.054722,-0.351149,-0.017888,0.547220,-172.852982,0.053716,0.000000
147.639999,-0.014893,-172.941940,-0.001651,0.002128,0.054045,-0.066245,-0.003375,0.540453,-172.941940,0.053101,0.000000
148.010010,-0.068886,-172.986420,-0.001677,0.002110,0.053603,-0.306419,-0.015610,0.536032,-172.986420,0.052484,0.000000
148.380005,-0.063301,-172.941940,-0.001694,0.002086,0.052988,-0.281577,-0.014344,0.529878,-172.941940,0.051860,0.000000
148.750000,-0.077454,-173.030899,-0.001725,0.002056,0.052233,-0.344531,-0.017551,0.522331,-173.030899,0.051244,0.000000
149.120010,-0.086388,-173.119858,-0.001755,0.002035,0.051696,-0.384271,-0.019576,0.516956,-173.119858,0.050629,0.000000
149.490005,-0.011169,-173.164337,-0.001776,0.002005,0.050915,-0.049684,-0.002531,0.509152,-173.164337,0.050013,0.000000
149.860001,-0.011917,-173.164337,-0.001798,0.001990,0.050534,-0.053010,-0.002700,0.505336,-173.164337,0.049397,0.000000
150.230011,-0.059204,-173.164337,-0.001824,0.001968,0.049978,-0.263353,-0.013416,0.499780,-173.164337,0.048781,0.000000
150.600006,-0.052505,-173.297791,-0.001867,0.001936,0.049180,-0.233556,-0.011898,0.491802,-173.297791,0.048166,0.000000
150.970001,-0.063301,-173.342270,-0.001880,0.001917,0.048703,-0.281577,-0.014344,0.487033,-173.342270,0.047550,0.000000
151.340012,-0.035378,-173.386749,-0.001906,0.001892,0.048045,-0.157367,-0.008017,0.480447,-173.386749,0.046934,0.000000
151.710007,-0.056602,-173.342270,-0.001927,0.001864,0.047333,-0.251780,-0.012826,0.473331,-173.342270,0.046310,0.000000
152.080002,-0.093842,-173.386749,-0.001953,0.001839,0.046700,-0.417428,-0.021265,0.467003,-173.386749,0.045694,0.000000
152.450012,-0.073730,-173.475708,-0.001970,0.001825,0.046362,-0.327969,-0.016708,0.463619,-173.475708,0.045079,0.000000
152.820007,-0.053253,-173.609146,-0.002013,0.001789,0.045434,-0.236882,-0.012067,0.454339,-173.609146,0.044463,0.000000
153.190002,-0.064049,-173.609146,-0.002039,0.001766,0.044862,-0.284903,-0.014514,0.448616,-173.609146,0.043847,0.000000
153.300003,-0.036118,-173.609146,-0.002057,0.001761,0.044723,-0.160659,-0.008184,0.447231,-173.609146,0.044575,0.000000