File: Data/compression 18/AutoNoHeating-17-18-reverse-1-3_09092024_171803.csv
Time (sec),S:Load (lbs),S:HL1 (DIM),S:LVDT (in),S:Position (in),Ch:Position (mm),Ch:Load (N),Ch:Stress (MPa),Ch:Strain (mm/mm),Ch:HL1 (DIM),Set Point (),Cycles ()
0.110000,0.016380,-182.016052,-0.011482,-0.007136,-0.181259,0.072863,0.003712,-1.812586,-182.016052,-0.181510,0.000000
0.480000,-0.022713,-182.105011,-0.011486,-0.007130,-0.181111,-0.101031,-0.005147,-1.811110,-182.105011,-0.180262,0.000000
0.850000,-0.013031,-182.149490,-0.011421,-0.006907,-0.175440,-0.057965,-0.002953,-1.754397,-182.149490,-0.174104,0.000000
1.220000,-0.021225,-182.238449,-0.011171,-0.006662,-0.169213,-0.094413,-0.004810,-1.692128,-182.238449,-0.167930,0.000000
1.590000,-0.058464,-182.282944,-0.010925,-0.006422,-0.163125,-0.260061,-0.013248,-1.631252,-182.282944,-0.161772,0.000000
1.960000,-0.060699,-182.238449,-0.010667,-0.006169,-0.156690,-0.270005,-0.013755,-1.566901,-182.238449,-0.155598,0.000000
2.330000,-0.095329,-182.327423,-0.010438,-0.005939,-0.150854,-0.424046,-0.021602,-1.508538,-182.327423,-0.149441,0.000000
2.700000,-0.036865,-182.416382,-0.010197,-0.005691,-0.144541,-0.163985,-0.008354,-1.445406,-182.416382,-0.143283,0.000000
3.070000,-0.032021,-182.416382,-0.009938,-0.005443,-0.138253,-0.142435,-0.007256,-1.382531,-182.416382,-0.137109,0.000000
3.440000,-0.032768,-182.460861,-0.009692,-0.005210,-0.132330,-0.145760,-0.007425,-1.323298,-182.460861,-0.130951,0.000000
3.810000,-0.033142,-182.549820,-0.009429,-0.004956,-0.125895,-0.147423,-0.007510,-1.258947,-182.549820,-0.124793,0.000000
4.180000,-0.063301,-182.549820,-0.009196,-0.004711,-0.119659,-0.281577,-0.014344,-1.196595,-182.549820,-0.118619,0.000000
4.550000,-0.063301,-182.549820,-0.008942,-0.004478,-0.113737,-0.281577,-0.014344,-1.137369,-182.549820,-0.112461,0.000000
4.920000,-0.036491,-182.727753,-0.008718,-0.004236,-0.107605,-0.162322,-0.008269,-1.076053,-182.727753,-0.106287,0.000000
5.290000,0.005585,-182.727753,-0.008446,-0.003994,-0.101439,0.024842,0.001266,-1.014390,-182.727753,-0.100129,0.000000
5.660000,-0.032768,-182.683273,-0.008192,-0.003748,-0.095195,-0.145760,-0.007425,-0.951954,-182.683273,-0.093972,0.000000
6.030000,-0.058090,-182.727753,-0.007946,-0.003508,-0.089099,-0.258398,-0.013163,-0.890987,-182.727753,-0.087797,0.000000
6.400000,-0.067772,-182.772232,-0.007713,-0.003261,-0.082837,-0.301465,-0.015357,-0.828370,-182.772232,-0.081640,0.000000
6.770000,-0.040962,-182.816711,-0.007463,-0.003021,-0.076724,-0.182209,-0.009282,-0.767236,-182.816711,-0.075466,0.000000
7.140000,-0.020111,-182.950150,-0.007205,-0.002774,-0.070454,-0.089459,-0.004557,-0.704535,-182.950150,-0.069308,0.000000
7.510000,-0.005211,-182.950150,-0.006950,-0.002537,-0.064452,-0.023179,-0.001181,-0.644522,-182.950150,-0.063151,0.000000
7.880001,-0.030159,-182.950150,-0.006683,-0.002287,-0.058095,-0.134154,-0.006834,-0.580951,-182.950150,-0.056976,0.000000
8.250000,-0.031654,-182.950150,-0.006454,-0.002044,-0.051930,-0.140806,-0.007173,-0.519295,-182.950150,-0.050819,0.000000
8.620001,-0.058464,-183.039108,-0.006204,-0.001804,-0.045833,-0.260061,-0.013248,-0.458328,-183.039108,-0.044644,0.000000
8.990001,-0.024208,-183.083588,-0.005980,-0.001566,-0.039788,-0.107683,-0.005486,-0.397883,-183.083588,-0.038487,0.000000
9.360001,-0.007446,-183.128082,-0.005713,-0.001326,-0.033683,-0.033123,-0.001687,-0.336825,-183.128082,-0.032330,0.000000
9.730000,-0.016754,-183.172562,-0.005458,-0.001078,-0.027387,-0.074526,-0.003797,-0.273867,-183.172562,-0.026155,0.000000
10.100000,-0.044312,-183.128082,-0.005221,-0.000842,-0.021394,-0.197107,-0.010041,-0.213945,-183.128082,-0.019998,0.000000
10.470000,-0.037979,-183.217041,-0.004980,-0.000589,-0.014959,-0.168940,-0.008606,-0.149594,-183.217041,-0.013823,0.000000
10.840000,-0.046173,-183.306000,-0.004725,-0.000354,-0.008985,-0.205388,-0.010463,-0.089846,-183.306000,-0.007666,0.000000
11.210001,0.002235,-183.306000,-0.004462,-0.000107,-0.002715,0.009944,0.000507,-0.027145,-183.306000,-0.001509,0.000000
11.580001,0.148949,-183.350479,-0.004251,0.000021,0.000546,0.662557,0.033752,0.005458,-183.350479,0.000719,0.000000
11.950001,0.125114,-183.394958,-0.004247,0.000021,0.000546,0.556537,0.028351,0.005458,-183.394958,0.000719,0.000000
12.320001,0.122513,-183.439438,-0.004255,0.000021,0.000546,0.544964,0.027762,0.005458,-183.439438,0.001135,0.000000
12.690001,0.122139,-183.528397,-0.004243,0.000022,0.000555,0.543301,0.027677,0.005549,-183.528397,0.001752,0.000000
13.060000,0.282257,-183.572891,-0.004221,0.000059,0.001491,1.255542,0.063960,0.014912,-183.572891,0.002367,0.000000
13.430000,0.481102,-183.617371,-0.004208,0.000085,0.002151,2.140049,0.109019,0.021506,-183.617371,0.002983,0.000000
13.800000,0.734688,-183.528397,-0.004169,0.000108,0.002740,3.268054,0.166483,0.027403,-183.528397,0.003599,0.000000
14.170001,0.951042,-183.661850,-0.004182,0.000125,0.003174,4.230447,0.215509,0.031740,-183.661850,0.004223,0.000000
14.540001,1.295113,-183.706329,-0.004148,0.000148,0.003755,5.760949,0.293477,0.037546,-183.706329,0.004839,0.000000
14.910001,1.609024,-183.706329,-0.004130,0.000172,0.004371,7.157297,0.364610,0.043708,-183.706329,0.005455,0.000000
15.280001,2.025337,-183.750809,-0.004100,0.000198,0.005029,9.009150,0.458948,0.050294,-183.750809,0.006070,0.000000
15.650001,2.516869,-183.795288,-0.004092,0.000225,0.005714,11.195591,0.570331,0.057144,-183.795288,0.006686,0.000000
16.020000,2.850136,-183.839767,-0.004066,0.000243,0.006175,12.678038,0.645850,0.061747,-183.839767,0.007302,0.000000
16.390001,3.333847,-183.884247,-0.004036,0.000268,0.006798,14.829692,0.755461,0.067984,-183.884247,0.007917,0.000000
16.760000,3.710320,-183.928726,-0.004023,0.000288,0.007328,16.504326,0.840770,0.073276,-183.928726,0.008533,0.000000
17.130001,4.119186,-184.017700,-0.003997,0.000310,0.007874,18.323057,0.933421,0.078741,-184.017700,0.009149,0.000000
17.500000,4.778282,-183.973221,-0.003980,0.000345,0.008767,21.254860,1.082774,0.087673,-183.973221,0.009773,0.000000
17.870001,5.105225,-183.973221,-0.003958,0.000366,0.009296,22.709173,1.156860,0.092965,-183.973221,0.010389,0.000000
18.240002,5.952377,-184.151138,-0.003945,0.000399,0.010147,26.477497,1.348828,0.101465,-184.151138,0.011005,0.000000
18.610001,6.086052,-184.151138,-0.003923,0.000421,0.010692,27.072111,1.379119,0.106923,-184.151138,0.011620,0.000000
18.980001,6.565674,-184.240097,-0.003889,0.000445,0.011309,29.205576,1.487803,0.113085,-184.240097,0.012237,0.000000
19.350000,6.603653,-184.195618,-0.003872,0.000456,0.011586,29.374516,1.496409,0.115856,-184.195618,0.012852,0.000000
19.720001,7.235573,-184.240097,-0.003863,0.000487,0.012358,32.185436,1.639604,0.123577,-184.240097,0.013467,0.000000
20.090000,7.771782,-184.240097,-0.003837,0.000516,0.013112,34.570614,1.761111,0.131124,-184.240097,0.014084,0.000000
20.460001,8.116974,-184.329056,-0.003807,0.000543,0.013780,36.106102,1.839333,0.137800,-184.329056,0.014699,0.000000
20.830002,8.291245,-184.329056,-0.003768,0.000567,0.014395,36.881298,1.878823,0.143955,-184.329056,0.015324,0.000000
21.200001,8.263313,-184.418030,-0.003777,0.000585,0.014847,36.757053,1.872494,0.148466,-184.418030,0.015939,0.000000
21.570002,8.610741,-184.418030,-0.003747,0.000604,0.015341,38.302486,1.951222,0.153409,-184.418030,0.016555,0.000000
21.940001,9.309311,-184.506989,-0.003734,0.000639,0.016226,41.409882,2.109520,0.162258,-184.506989,0.017171,0.000000
22.310001,9.410599,-184.506989,-0.003699,0.000663,0.016850,41.860435,2.132472,0.168496,-184.506989,0.017787,0.000000
22.680000,9.391975,-184.595947,-0.003660,0.000684,0.017361,41.777592,2.128252,0.173613,-184.595947,0.018402,0.000000
23.050001,9.616150,-184.595947,-0.003648,0.000707,0.017968,42.774773,2.179051,0.179684,-184.595947,0.019018,0.000000
23.420002,10.043633,-184.640427,-0.003626,0.000738,0.018749,44.676308,2.275920,0.187489,-184.640427,0.019634,0.000000
23.790001,9.955750,-184.595947,-0.003596,0.000759,0.019287,44.285385,2.256005,0.192871,-184.595947,0.020258,0.000000
24.160002,10.335945,-184.684906,-0.003570,0.000789,0.020050,45.976582,2.342159,0.200501,-184.684906,0.020874,0.000000
24.530001,10.340408,-184.773865,-0.003566,0.000810,0.020570,45.996433,2.343170,0.205701,-184.773865,0.021490,0.000000
24.900002,10.448402,-184.773865,-0.003523,0.000832,0.021125,46.476814,2.367642,0.211250,-184.773865,0.022105,0.000000
25.270000,10.784279,-184.818344,-0.003497,0.000857,0.021776,47.970867,2.443753,0.217760,-184.818344,0.022721,0.000000
25.640001,10.906418,-184.862839,-0.003484,0.000881,0.022374,48.514168,2.471430,0.223740,-184.862839,0.023337,0.000000
26.010002,11.023338,-184.862839,-0.003471,0.000906,0.023007,49.034256,2.497924,0.230069,-184.862839,0.023952,0.000000
26.380001,11.143616,-184.996277,-0.003436,0.000927,0.023536,49.569279,2.525179,0.235360,-184.996277,0.024569,0.000000
26.750002,11.410240,-184.996277,-0.003410,0.000954,0.024221,50.755283,2.585598,0.242211,-184.996277,0.025184,0.000000
27.120001,11.524925,-184.996277,-0.003393,0.000978,0.024846,51.265427,2.611585,0.248456,-184.996277,0.025808,0.000000
27.490002,11.718185,-185.085236,-0.003372,0.001001,0.025427,52.125092,2.655379,0.254269,-185.085236,0.026424,0.000000
27.860001,11.743141,-185.085236,-0.003341,0.001022,0.025956,52.236099,2.661034,0.259561,-185.085236,0.027040,0.000000
28.230001,12.175461,-185.129715,-0.003324,0.001053,0.026754,54.159153,2.758999,0.267539,-185.129715,0.027655,0.000000
28.600002,12.195572,-185.218674,-0.003298,0.001076,0.027335,54.248611,2.763556,0.273345,-185.218674,0.028271,0.000000
28.970001,12.298714,-185.218674,-0.003277,0.001100,0.027951,54.707409,2.786928,0.279507,-185.218674,0.028887,0.000000
29.340002,12.543365,-185.218674,-0.003247,0.001123,0.028531,55.795677,2.842367,0.285313,-185.218674,0.029502,0.000000
29.710001,12.027634,-185.263168,-0.003234,0.001128,0.028653,53.501587,2.725501,0.286532,-185.263168,0.030119,0.000000
30.080002,13.067665,-185.396606,-0.003212,0.001171,0.029745,58.127876,2.961175,0.297455,-185.396606,0.030734,0.000000
30.450001,13.284386,-185.396606,-0.003182,0.001197,0.030396,59.091900,3.010285,0.303957,-185.396606,0.031359,0.000000
30.820002,13.340988,-185.485565,-0.003143,0.001219,0.030968,59.343678,3.023111,0.309680,-185.485565,0.031974,0.000000
31.190001,13.440414,-185.441086,-0.003126,0.001242,0.031549,59.785950,3.045641,0.315494,-185.441086,0.032590,0.000000
31.560001,13.561806,-185.485565,-0.003096,0.001266,0.032165,60.325924,3.073149,0.321648,-185.485565,0.033206,0.000000
31.930002,14.138611,-185.619003,-0.003087,0.001296,0.032920,62.891682,3.203855,0.329195,-185.619003,0.033822,0.000000
32.300003,14.145309,-185.574524,-0.003078,0.001320,0.033518,62.921478,3.205373,0.335183,-185.574524,0.034437,0.000000
32.670002,14.166908,-185.619003,-0.003027,0.001340,0.034047,63.017555,3.210267,0.340466,-185.619003,0.035053,0.000000
33.040001,14.309898,-185.707977,-0.003027,0.001363,0.034620,63.653606,3.242669,0.346197,-185.707977,0.035669,0.000000
33.410000,14.159088,-185.707977,-0.003009,0.001378,0.035010,62.982769,3.208495,0.350095,-185.707977,0.036284,0.000000
33.780003,15.180511,-185.796936,-0.002971,0.001419,0.036033,67.526291,3.439953,0.360330,-185.796936,0.036909,0.000000
34.150002,15.113106,-185.885895,-0.002936,0.001440,0.036570,67.226456,3.424679,0.365704,-185.885895,0.037524,0.000000
34.520000,15.338020,-185.841415,-0.002919,0.001467,0.037265,68.226921,3.475645,0.372646,-185.841415,0.038140,0.000000
34.890003,15.628845,-185.930374,-0.002897,0.001491,0.037880,69.520576,3.541547,0.378800,-185.930374,0.038756,0.000000
35.260002,15.508942,-185.930374,-0.002880,0.001509,0.038331,68.987221,3.514376,0.383311,-185.930374,0.039372,0.000000
35.630001,15.578575,-185.930374,-0.002854,0.001528,0.038800,69.296967,3.530156,0.387997,-185.930374,0.039987,0.000000
36.000000,16.127449,-186.063812,-0.002846,0.001555,0.039502,71.738480,3.654532,0.395022,-186.063812,0.040603,0.000000
36.370003,16.768677,-186.063812,-0.002811,0.001587,0.040317,74.590797,3.799836,0.403167,-186.063812,0.041219,0.000000
36.740002,16.827141,-186.108292,-0.002794,0.001610,0.040898,74.850861,3.813085,0.408981,-186.108292,0.041834,0.000000
37.110001,16.892677,-186.152786,-0.002751,0.001632,0.041462,75.142380,3.827935,0.414620,-186.152786,0.042459,0.000000
37.480003,17.109024,-186.152786,-0.002759,0.001655,0.042034,76.104736,3.876960,0.420343,-186.152786,0.043075,0.000000
37.850002,17.765892,-186.241745,-0.002716,0.001683,0.042745,79.026634,4.025809,0.427451,-186.241745,0.043691,0.000000
38.220001,17.157433,-186.286224,-0.002703,0.001691,0.042962,76.320068,3.887930,0.429623,-186.286224,0.044306,0.000000
38.590000,18.206406,-186.330704,-0.002673,0.001727,0.043856,80.986137,4.125630,0.438556,-186.330704,0.044922,0.000000
38.960003,18.381790,-186.286224,-0.002647,0.001753,0.044532,81.766289,4.165373,0.445316,-186.286224,0.045538,0.000000
39.330002,18.620857,-186.330704,-0.002634,0.001777,0.045139,82.829712,4.219547,0.451387,-186.330704,0.046154,0.000000
39.700001,19.332458,-186.419662,-0.002608,0.001808,0.045919,85.995071,4.380797,0.459191,-186.419662,0.046769,0.000000
40.070004,19.227821,-186.464142,-0.002591,0.001829,0.046457,85.529617,4.357087,0.464573,-186.464142,0.047385,0.000000
40.440002,19.204361,-186.553116,-0.002561,0.001848,0.046952,85.425262,4.351770,0.469516,-186.553116,0.048009,0.000000
40.810001,19.116859,-186.553116,-0.002544,0.001867,0.047419,85.036041,4.331943,0.474194,-186.553116,0.048625,0.000000
41.180000,19.064354,-186.508621,-0.002518,0.001887,0.047923,84.802483,4.320044,0.479228,-186.508621,0.049241,0.000000
41.550003,20.446228,-186.597595,-0.002501,0.001916,0.048659,90.949364,4.633182,0.486594,-186.597595,0.049856,0.000000
41.920002,21.030479,-186.686554,-0.002488,0.001947,0.049457,93.548248,4.765574,0.494572,-186.686554,0.050472,0.000000
42.290001,21.244965,-186.686554,-0.002475,0.001972,0.050082,94.502319,4.814178,0.500817,-186.686554,0.051088,0.000000
42.660004,21.515305,-186.686554,-0.002436,0.001996,0.050689,95.704857,4.875438,0.506888,-186.686554,0.051704,0.000000
43.030003,21.444931,-186.775513,-0.002423,0.002015,0.051183,95.391815,4.859491,0.511831,-186.775513,0.052319,0.000000
43.400002,22.327454,-186.731033,-0.002402,0.002044,0.051920,99.317474,5.059473,0.519204,-186.731033,0.052936,0.000000
43.770000,22.837227,-186.864471,-0.002371,0.002069,0.052553,101.585060,5.174990,0.525533,-186.864471,0.053559,0.000000
44.140003,23.249443,-186.819992,-0.002350,0.002095,0.053204,103.418686,5.268399,0.532043,-186.819992,0.054175,0.000000
44.510002,23.799438,-186.864471,-0.002320,0.002120,0.053837,105.865189,5.393030,0.538371,-186.864471,0.054791,0.000000
44.880001,24.019516,-186.953430,-0.002307,0.002144,0.054453,106.844147,5.442900,0.544525,-186.953430,0.055407,0.000000
45.250004,24.838364,-186.997925,-0.002289,0.002171,0.055147,110.486557,5.628454,0.551467,-186.997925,0.056022,0.000000
45.620003,25.199188,-187.086884,-0.002268,0.002196,0.055780,112.091591,5.710217,0.557795,-187.086884,0.056638,0.000000
45.990002,25.416283,-187.086884,-0.002251,0.002219,0.056352,113.057274,5.759412,0.563518,-187.086884,0.057254,0.000000
46.360001,25.506027,-187.086884,-0.002229,0.002239,0.056873,113.456474,5.779748,0.568726,-187.086884,0.057870,0.000000
46.730003,25.819191,-187.131363,-0.002207,0.002256,0.057306,114.849495,5.850712,0.573063,-187.131363,0.058494,0.000000
47.100002,26.555000,-187.131363,-0.002186,0.002284,0.058025,118.122543,6.017449,0.580255,-187.131363,0.059109,0.000000
47.470001,27.545883,-187.264801,-0.002156,0.002315,0.058789,122.530205,6.241986,0.587893,-187.264801,0.059726,0.000000
47.840004,27.936127,-187.309280,-0.002156,0.002336,0.059335,124.266098,6.330417,0.593350,-187.309280,0.060341,0.000000
48.210003,28.161781,-187.264801,-0.002117,0.002355,0.059829,125.269859,6.381551,0.598293,-187.264801,0.060957,0.000000
48.580002,29.194748,-187.353760,-0.002091,0.002385,0.060584,129.864731,6.615624,0.605841,-187.353760,0.061573,0.000000
48.950001,29.301613,-187.398254,-0.002078,0.002404,0.061053,130.340088,6.639840,0.610526,-187.398254,0.062188,0.000000
49.320004,30.682373,-187.442734,-0.002052,0.002436,0.061885,136.482010,6.952725,0.618853,-187.442734,0.062804,0.000000
49.690002,31.176514,-187.487213,-0.002039,0.002459,0.062458,138.680054,7.064699,0.624576,-187.487213,0.063420,0.000000
50.060001,31.617775,-187.531693,-0.002013,0.002482,0.063038,140.642883,7.164690,0.630382,-187.531693,0.064044,0.000000
50.430004,32.329002,-187.576172,-0.001988,0.002506,0.063645,143.806580,7.325857,0.636453,-187.576172,0.064660,0.000000
50.800003,32.619080,-187.576172,-0.001975,0.002526,0.064149,145.096909,7.391589,0.641487,-187.576172,0.065276,0.000000
51.170002,33.166100,-187.620651,-0.001957,0.002547,0.064704,147.530182,7.515545,0.647035,-187.620651,0.065891,0.000000
51.540001,34.068726,-187.709610,-0.001940,0.002575,0.065397,151.545258,7.720084,0.653969,-187.709610,0.066507,0.000000
51.910004,34.944923,-187.754089,-0.001923,0.002600,0.066031,155.442780,7.918633,0.660305,-187.754089,0.067123,0.000000
52.280003,35.634926,-187.798569,-0.001893,0.002624,0.066638,158.512070,8.074989,0.666376,-187.798569,0.067739,0.000000
52.650002,36.530479,-187.754089,-0.001888,0.002649,0.067296,162.495682,8.277925,0.672962,-187.754089,0.068354,0.000000
53.020004,37.161652,-187.798569,-0.001863,0.002672,0.067878,165.303284,8.420950,0.678775,-187.798569,0.068970,0.000000
53.390003,38.403519,-187.843063,-0.001850,0.002701,0.068597,170.827377,8.702362,0.685974,-187.843063,0.069594,0.000000
53.760002,39.268913,-187.932022,-0.001837,0.002727,0.069256,174.676849,8.898463,0.692560,-187.932022,0.070211,0.000000
54.130001,40.126114,-187.976501,-0.001824,0.002752,0.069890,178.489868,9.092708,0.698896,-187.976501,0.070826,0.000000
54.500004,40.542793,-187.976501,-0.001794,0.002769,0.070341,180.343353,9.187128,0.703408,-187.976501,0.071441,0.000000
54.870003,40.073235,-187.976501,-0.001785,0.002780,0.070609,178.254654,9.080725,0.706095,-187.976501,0.072058,0.000000
55.240002,43.126320,-188.065460,-0.001763,0.002825,0.071754,191.835449,9.772564,0.717540,-188.065460,0.072673,0.000000
55.610004,43.822655,-188.198898,-0.001746,0.002848,0.072335,194.932907,9.930355,0.723346,-188.198898,0.073289,0.000000
55.980003,44.473557,-188.243378,-0.001716,0.002868,0.072838,197.828262,10.077852,0.728380,-188.243378,0.073905,0.000000
56.350002,45.923950,-188.198898,-0.001699,0.002899,0.073627,204.279938,10.406516,0.736268,-188.198898,0.074520,0.000000
56.720001,45.809258,-188.198898,-0.001694,0.002914,0.074009,203.769760,10.380527,0.740091,-188.198898,0.075145,0.000000
57.090004,46.959518,-188.243378,-0.001669,0.002934,0.074520,208.886368,10.641178,0.745200,-188.243378,0.075761,0.000000
57.460003,48.448639,-188.287872,-0.001664,0.002961,0.075206,215.510315,10.978619,0.752059,-188.287872,0.076376,0.000000
57.830002,49.907219,-188.376831,-0.001651,0.002991,0.075960,221.998398,11.309137,0.759598,-188.376831,0.076992,0.000000
58.200005,51.309570,-188.421310,-0.001630,0.003016,0.076602,228.236374,11.626914,0.766017,-188.421310,0.077608,0.000000
58.570004,51.895691,-188.465790,-0.001608,0.003036,0.077113,230.843567,11.759731,0.771134,-188.465790,0.078223,0.000000
58.940002,53.007591,-188.376831,-0.001617,0.003062,0.077773,235.789536,12.011692,0.777728,-188.376831,0.078839,0.000000
59.310001,54.513840,-188.510269,-0.001587,0.003085,0.078353,242.489670,12.353013,0.783534,-188.510269,0.079455,0.000000
59.680004,55.504723,-188.643707,-0.001569,0.003107,0.078917,246.897339,12.577549,0.789173,-188.643707,0.080071,0.000000
60.050003,57.034058,-188.554749,-0.001556,0.003135,0.079620,253.700165,12.924103,0.796198,-188.554749,0.080695,0.000000
60.420002,58.204422,-188.688202,-0.001535,0.003160,0.080262,258.906189,13.189310,0.802617,-188.688202,0.081311,0.000000
60.790005,59.099976,-188.643707,-0.001518,0.003177,0.080704,262.889832,13.392246,0.807038,-188.643707,0.081926,0.000000
61.160004,61.292503,-188.688202,-0.001513,0.003211,0.081571,272.642670,13.889080,0.815713,-188.688202,0.082543,0.000000
61.530003,62.458031,-188.777161,-0.001505,0.003235,0.082161,277.827209,14.153193,0.821610,-188.777161,0.083158,0.000000
61.900002,62.791306,-188.866119,-0.001492,0.003249,0.082516,279.309662,14.228713,0.825160,-188.866119,0.083773,0.000000
62.270004,63.474617,-188.866119,-0.001466,0.003264,0.082915,282.349213,14.383554,0.829149,-188.866119,0.084390,0.000000
62.640003,66.325127,-188.866119,-0.001449,0.003301,0.083843,295.028900,15.029489,0.838430,-188.866119,0.084997,0.000000
63.010002,65.154747,-188.866119,-0.001444,0.003291,0.083592,289.822784,14.764277,0.835917,-188.866119,290.250183,0.000000
63.380005,66.245430,-188.955078,-0.001436,0.003277,0.083236,294.674377,15.011429,0.832359,-188.955078,294.500488,0.000000
63.750004,65.259758,-189.044037,-0.001436,0.003277,0.083236,290.289886,14.788073,0.832359,-189.044037,294.500488,0.000000
64.120003,65.214333,-189.088516,-0.001440,0.003318,0.084277,290.087830,14.777779,0.842767,-189.088516,294.500488,0.000000
64.490005,65.515953,-189.044037,-0.001414,0.003330,0.084589,291.429504,14.846127,0.845886,-189.044037,294.500488,0.000000
64.860001,65.129433,-189.088516,-0.001410,0.003333,0.084650,289.710175,14.758540,0.846499,-189.088516,294.500488,0.000000
65.230003,65.143959,-189.133011,-0.001406,0.003340,0.084832,289.774811,14.761832,0.848316,-189.133011,294.500488,0.000000
65.600006,65.225136,-189.221970,-0.001406,0.003344,0.084936,290.135895,14.780228,0.849361,-189.221970,294.500488,0.000000
65.970001,65.817955,-189.310928,-0.001406,0.003353,0.085161,292.772888,14.914561,0.851609,-189.310928,294.500488,0.000000
66.340004,65.298485,-189.310928,-0.001388,0.003353,0.085161,290.462158,14.796848,0.851609,-189.310928,294.500488,0.000000
66.710007,64.910851,-189.310928,-0.001393,0.003353,0.085161,288.737885,14.709009,0.851609,-189.310928,294.500488,0.000000
67.080002,64.497887,-189.310928,-0.001393,0.003353,0.085170,286.900940,14.615430,0.851700,-189.310928,294.500488,0.000000
67.450005,66.680733,-189.399887,-0.001388,0.003279,0.083296,296.610718,15.110070,0.832965,-189.399887,294.500488,0.000000
67.820000,66.210808,-189.488846,-0.001375,0.003279,0.083296,294.520386,15.003584,0.832965,-189.488846,294.500488,0.000000
68.190002,65.840660,-189.488846,-0.001358,0.003280,0.083314,292.873871,14.919706,0.833139,-189.488846,294.500488,0.000000
68.560005,65.498085,-189.533325,-0.001354,0.003333,0.084650,291.350037,14.842078,0.846499,-189.533325,294.500488,0.000000
68.930000,65.215828,-189.533325,-0.001380,0.003344,0.084944,290.094482,14.778117,0.849444,-189.533325,294.500488,0.000000
69.300003,65.131294,-189.622299,-0.001371,0.003374,0.085690,289.718475,14.758963,0.856900,-189.622299,294.500488,0.000000
69.670006,65.016609,-189.711258,-0.001362,0.003374,0.085707,289.208313,14.732974,0.857074,-189.711258,294.500488,0.000000
70.040001,65.471275,-189.666779,-0.001362,0.003383,0.085916,291.230774,14.836003,0.859156,-189.666779,294.500488,0.000000
70.410004,65.265343,-189.755737,-0.001371,0.003383,0.085916,290.314758,14.789338,0.859156,-189.755737,294.500488,0.000000
70.780006,65.039314,-189.755737,-0.001354,0.003385,0.085976,289.309326,14.738119,0.859762,-189.755737,294.500488,0.000000
71.150002,65.155495,-189.755737,-0.001367,0.003387,0.086028,289.826111,14.764446,0.860284,-189.755737,294.500488,0.000000
71.520004,65.225502,-189.933655,-0.001354,0.003390,0.086115,290.137512,14.780310,0.861154,-189.933655,294.500488,0.000000
71.890007,65.107094,-189.933655,-0.001345,0.003391,0.086133,289.610809,14.753479,0.861329,-189.933655,294.500488,0.000000
72.260002,65.310036,-189.933655,-0.001345,0.003395,0.086237,290.513550,14.799465,0.862366,-189.933655,294.500488,0.000000
72.630005,65.196465,-190.022629,-0.001341,0.003395,0.086237,290.008362,14.773730,0.862366,-190.022629,294.500488,0.000000
73.000000,65.019203,-190.022629,-0.001345,0.003395,0.086237,289.219849,14.733562,0.862366,-190.022629,294.500488,0.000000
73.370003,64.871376,-190.111588,-0.001337,0.003395,0.086237,288.562286,14.700065,0.862366,-190.111588,294.500488,0.000000
73.740005,64.719826,-190.156067,-0.001350,0.003395,0.086237,287.888153,14.665722,0.862366,-190.156067,294.500488,0.000000
74.110001,65.882744,-190.111588,-0.001337,0.003401,0.086384,293.061096,14.929243,0.863842,-190.111588,294.500488,0.000000
74.480003,65.651497,-190.245026,-0.001350,0.003401,0.086384,292.032440,14.876842,0.863842,-190.245026,294.500488,0.000000
74.850006,65.492500,-190.245026,-0.001332,0.003401,0.086384,291.325195,14.840813,0.863842,-190.245026,294.500488,0.000000
75.220001,65.305565,-190.289505,-0.001358,0.003401,0.086384,290.493652,14.798452,0.863842,-190.289505,294.500488,0.000000
75.590004,65.141350,-190.422958,-0.001332,0.003401,0.086384,289.763184,14.761241,0.863842,-190.422958,294.500488,0.000000
75.960007,64.998726,-190.422958,-0.001319,0.003401,0.086384,289.128784,14.728922,0.863842,-190.422958,294.500488,0.000000
76.330002,64.853127,-190.378464,-0.001332,0.003401,0.086384,288.481110,14.695929,0.863842,-190.378464,294.500488,0.000000
76.700005,64.723167,-190.422958,-0.001337,0.003401,0.086384,287.903015,14.666480,0.863842,-190.422958,294.500488,0.000000
77.070007,64.577950,-190.422958,-0.001337,0.003401,0.086392,287.257080,14.633573,0.863925,-190.422958,294.500488,0.000000
77.440002,66.227180,-190.600876,-0.001332,0.003412,0.086653,294.593201,15.007293,0.866529,-190.600876,294.500488,0.000000
77.810005,66.063713,-190.600876,-0.001341,0.003412,0.086653,293.866058,14.970251,0.866529,-190.600876,294.500488,0.000000
78.180000,65.926689,-190.600876,-0.001319,0.003411,0.086645,293.256561,14.939201,0.866446,-190.600876,294.500488,0.000000
78.550003,65.829491,-190.645355,-0.001328,0.003411,0.086645,292.824188,14.917175,0.866446,-190.645355,294.500488,0.000000
78.920006,65.662666,-190.645355,-0.001328,0.003411,0.086645,292.082123,14.879373,0.866446,-190.645355,294.500488,0.000000
79.290001,65.554314,-190.734314,-0.001319,0.003411,0.086645,291.600159,14.854820,0.866446,-190.734314,294.500488,0.000000
79.660004,65.455635,-190.823273,-0.001324,0.003411,0.086645,291.161194,14.832459,0.866446,-190.823273,294.500488,0.000000
80.030006,65.332008,-190.778793,-0.001315,0.003411,0.086645,290.611298,14.804445,0.866446,-190.778793,294.500488,0.000000
80.400002,65.243004,-190.867767,-0.001328,0.003411,0.086645,290.215363,14.784276,0.866446,-190.867767,294.500488,0.000000
80.770004,65.104485,-190.912247,-0.001319,0.003411,0.086645,289.599213,14.752887,0.866446,-190.912247,294.500488,0.000000
81.140007,65.011757,-190.956726,-0.001337,0.003412,0.086653,289.186737,14.731875,0.866529,-190.956726,294.500488,0.000000
81.510002,64.916435,-191.001205,-0.001311,0.003412,0.086653,288.762726,14.710275,0.866529,-191.001205,294.500488,0.000000
81.880005,64.810677,-191.090164,-0.001319,0.003412,0.086653,288.292297,14.686310,0.866529,-191.090164,294.500488,0.000000
82.250008,64.728767,-191.045685,-0.001328,0.003412,0.086653,287.927948,14.667748,0.866529,-191.045685,294.500488,0.000000
82.620003,64.629341,-191.090164,-0.001315,0.003412,0.086653,287.485657,14.645218,0.866529,-191.090164,294.500488,0.000000
82.990005,64.530281,-191.179123,-0.001319,0.003412,0.086653,287.045013,14.622770,0.866529,-191.179123,294.500488,0.000000
83.360001,66.681847,-191.268097,-0.001311,0.003385,0.085985,296.615662,15.110322,0.859852,-191.268097,294.500488,0.000000
83.730003,66.568657,-191.268097,-0.001311,0.003385,0.085985,296.112183,15.084673,0.859852,-191.268097,294.500488,0.000000
84.100006,66.436455,-191.223602,-0.001306,0.003385,0.085985,295.524109,15.054716,0.859852,-191.223602,294.500488,0.000000
84.470001,66.356407,-191.268097,-0.001319,0.003385,0.085985,295.168030,15.036577,0.859852,-191.268097,294.500488,0.000000
84.840004,66.251015,-191.357056,-0.001311,0.003385,0.085985,294.699219,15.012694,0.859852,-191.357056,294.500488,0.000000
85.210007,66.169090,-191.446014,-0.001302,0.003385,0.085985,294.334808,14.994130,0.859852,-191.446014,294.500488,0.000000
85.580002,66.058876,-191.446014,-0.001306,0.003385,0.085985,293.844543,14.969155,0.859852,-191.446014,294.500488,0.000000
85.950005,65.988869,-191.446014,-0.001311,0.003385,0.085985,293.533142,14.953291,0.859852,-191.446014,294.500488,0.000000
86.320007,65.853691,-191.490494,-0.001315,0.003386,0.085994,292.931854,14.922660,0.859936,-191.490494,294.500488,0.000000
86.690002,65.877159,-191.534973,-0.001302,0.003386,0.085994,293.036224,14.927978,0.859936,-191.534973,294.500488,0.000000
87.060005,65.787422,-191.579453,-0.001302,0.003386,0.085994,292.637054,14.907643,0.859936,-191.579453,294.500488,0.000000
87.430008,65.726341,-191.668411,-0.001302,0.003386,0.085994,292.365356,14.893802,0.859936,-191.668411,294.500488,0.000000
87.800003,65.598244,-191.668411,-0.001298,0.003387,0.086020,291.795563,14.864775,0.860201,-191.668411,294.500488,0.000000
88.170006,65.548729,-191.712906,-0.001302,0.003399,0.086332,291.575317,14.853555,0.863319,-191.712906,294.500488,0.000000
88.540001,65.481697,-191.712906,-0.001315,0.003399,0.086332,291.277130,14.838365,0.863319,-191.712906,294.500488,0.000000
88.910004,65.381905,-191.801865,-0.001306,0.003399,0.086332,290.833252,14.815751,0.863319,-191.801865,294.500488,0.000000
89.280006,65.333488,-191.846344,-0.001311,0.003406,0.086505,290.617859,14.804780,0.865053,-191.846344,294.500488,0.000000
89.650002,65.306313,-191.846344,-0.001293,0.003412,0.086661,290.496979,14.798622,0.866612,-191.846344,294.500488,0.000000
90.020004,65.256783,-191.801865,-0.001306,0.003412,0.086661,290.276672,14.787398,0.866612,-191.801865,294.500488,0.000000
90.390007,65.241890,-191.979782,-0.001306,0.003424,0.086965,290.210419,14.784024,0.869648,-191.979782,294.500488,0.000000
90.760002,65.320091,-192.024261,-0.001319,0.003435,0.087260,290.558289,14.801744,0.872600,-192.024261,294.500488,0.000000
91.130005,65.281364,-192.068741,-0.001298,0.003436,0.087268,290.386017,14.792969,0.872683,-192.068741,294.500488,0.000000
91.500008,65.241142,-192.068741,-0.001298,0.003436,0.087268,290.207092,14.783854,0.872683,-192.068741,294.500488,0.000000
91.870003,65.198692,-192.113220,-0.001311,0.003436,0.087268,290.018280,14.774235,0.872683,-192.113220,294.500488,0.000000
92.240005,65.109322,-192.113220,-0.001293,0.003436,0.087277,289.620728,14.753983,0.872774,-192.113220,294.500488,0.000000
92.610001,65.328285,-192.157715,-0.001311,0.003441,0.087408,290.594727,14.803600,0.874076,-192.157715,294.500488,0.000000
92.980003,65.342064,-192.202194,-0.001298,0.003441,0.087408,290.656006,14.806724,0.874076,-192.202194,294.500488,0.000000
93.350006,65.296623,-192.246674,-0.001285,0.003441,0.087408,290.453888,14.796426,0.874076,-192.246674,294.500488,0.000000
93.720001,65.274651,-192.291153,-0.001298,0.003441,0.087408,290.356140,14.791448,0.874076,-192.291153,294.500488,0.000000
94.090004,65.224754,-192.335632,-0.001315,0.003441,0.087408,290.134186,14.780140,0.874076,-192.335632,294.500488,0.000000
94.460007,65.203163,-192.380112,-0.001306,0.003441,0.087408,290.038147,14.775248,0.874076,-192.380112,294.500488,0.000000
94.830002,65.298485,-192.424591,-0.001306,0.003444,0.087486,290.462158,14.796848,0.874856,-192.424591,294.500488,0.000000
95.200005,65.291786,-192.469070,-0.001306,0.003444,0.087486,290.432373,14.795330,0.874856,-192.469070,294.500488,0.000000
95.570007,65.259026,-192.513550,-0.001298,0.003444,0.087486,290.286652,14.787907,0.874856,-192.513550,294.500488,0.000000
95.940002,65.227745,-192.558044,-0.001306,0.003444,0.087486,290.147491,14.780818,0.874856,-192.558044,294.500488,0.000000
96.310005,65.185661,-192.558044,-0.001306,0.003444,0.087486,289.960297,14.771281,0.874856,-192.558044,294.500488,0.000000
96.680008,65.529366,-192.558044,-0.001289,0.003450,0.087633,291.489166,14.849166,0.876332,-192.558044,294.500488,0.000000
97.050003,65.547600,-192.691483,-0.001298,0.003450,0.087633,291.570282,14.853299,0.876332,-192.691483,294.500488,0.000000
97.420006,65.540901,-192.691483,-0.001293,0.003450,0.087633,291.540497,14.851781,0.876332,-192.691483,294.500488,0.000000
97.790001,65.503288,-192.735962,-0.001289,0.003450,0.087624,291.373169,14.843257,0.876241,-192.735962,294.500488,0.000000
98.160004,65.468285,-192.780441,-0.001302,0.003450,0.087624,291.217468,14.835325,0.876241,-192.780441,294.500488,0.000000
98.530006,65.429192,-192.869400,-0.001298,0.003450,0.087624,291.043579,14.826467,0.876241,-192.869400,294.500488,0.000000
98.900002,65.390831,-192.869400,-0.001298,0.003450,0.087624,290.872955,14.817774,0.876241,-192.869400,294.500488,0.000000
99.270004,65.357323,-192.913879,-0.001298,0.003450,0.087624,290.723877,14.810181,0.876241,-192.913879,294.500488,0.000000
99.640007,65.314507,-192.913879,-0.001298,0.003450,0.087633,290.533447,14.800479,0.876332,-192.913879,294.500488,0.000000
100.010002,65.280251,-192.958359,-0.001289,0.003450,0.087633,290.381042,14.792717,0.876332,-192.958359,294.500488,0.000000
100.380005,65.235558,-193.047333,-0.001302,0.003450,0.087633,290.182251,14.782589,0.876332,-193.047333,294.500488,0.000000
100.750008,65.198326,-193.136292,-0.001298,0.003450,0.087633,290.016632,14.774152,0.876332,-193.136292,294.500488,0.000000
101.120003,65.168526,-193.180771,-0.001293,0.003450,0.087633,289.884094,14.767399,0.876332,-193.180771,294.500488,0.000000
101.490005,65.300346,-193.136292,-0.001298,0.003454,0.087719,290.470459,14.797271,0.877195,-193.136292,294.500488,0.000000
101.860008,65.318230,-193.225250,-0.001302,0.003454,0.087719,290.549988,14.801322,0.877195,-193.225250,294.500488,0.000000
102.230003,65.300346,-193.180771,-0.001302,0.003454,0.087719,290.470459,14.797271,0.877195,-193.180771,294.500488,0.000000
102.600006,65.308922,-193.269730,-0.001298,0.003455,0.087754,290.508606,14.799213,0.877543,-193.269730,294.500488,0.000000
102.970001,65.329399,-193.314209,-0.001289,0.003455,0.087763,290.599670,14.803853,0.877626,-193.314209,294.500488,0.000000
103.340004,65.326042,-193.403168,-0.001289,0.003455,0.087763,290.584747,14.803092,0.877626,-193.403168,294.500488,0.000000
103.710007,65.305931,-193.358688,-0.001289,0.003455,0.087763,290.495300,14.798535,0.877626,-193.358688,294.500488,0.000000
104.080002,65.287315,-193.403168,-0.001293,0.003455,0.087763,290.412476,14.794317,0.877626,-193.403168,294.500488,0.000000
104.450005,65.266838,-193.447662,-0.001289,0.003455,0.087763,290.321381,14.789678,0.877626,-193.447662,294.500488,0.000000
104.820007,65.248222,-193.536621,-0.001289,0.003456,0.087772,290.238586,14.785459,0.877717,-193.536621,294.500488,0.000000
105.190002,65.293282,-193.536621,-0.001289,0.003457,0.087807,290.439026,14.795669,0.878065,-193.536621,294.500488,0.000000
105.560005,65.278755,-193.536621,-0.001293,0.003457,0.087807,290.374420,14.792377,0.878065,-193.536621,294.500488,0.000000
105.930008,65.261253,-193.625580,-0.001293,0.003457,0.087807,290.296539,14.788412,0.878065,-193.625580,294.500488,0.000000
106.300003,65.235924,-193.670059,-0.001298,0.003457,0.087807,290.183868,14.782672,0.878065,-193.670059,294.500488,0.000000
106.670006,65.376686,-193.759018,-0.001306,0.003460,0.087885,290.810028,14.814569,0.878845,-193.759018,294.500488,0.000000
107.040009,65.405739,-193.759018,-0.001285,0.003460,0.087885,290.939270,14.821152,0.878845,-193.759018,294.500488,0.000000
107.410004,65.408333,-193.759018,-0.001298,0.003460,0.087885,290.950806,14.821740,0.878845,-193.759018,294.500488,0.000000
107.780006,65.374077,-193.803497,-0.001285,0.003460,0.087885,290.798431,14.813977,0.878845,-193.803497,294.500488,0.000000
108.150002,65.349129,-193.892471,-0.001289,0.003460,0.087885,290.687439,14.808324,0.878845,-193.892471,294.500488,0.000000
108.520004,65.338341,-193.981430,-0.001298,0.003460,0.087885,290.639465,14.805880,0.878845,-193.981430,294.500488,0.000000
108.890007,65.322701,-193.981430,-0.001285,0.003460,0.087885,290.569885,14.802335,0.878845,-193.981430,294.500488,0.000000
109.260002,65.298119,-193.936951,-0.001289,0.003460,0.087885,290.460541,14.796765,0.878845,-193.936951,294.500488,0.000000
109.630005,65.269066,-193.981430,-0.001293,0.003460,0.087885,290.331299,14.790182,0.878845,-193.981430,294.500488,0.000000
110.000008,65.243385,-194.114868,-0.001281,0.003460,0.087885,290.217072,14.784363,0.878845,-194.114868,294.500488,0.000000
110.370003,65.234810,-194.159348,-0.001293,0.003461,0.087902,290.178925,14.782419,0.879019,-194.159348,294.500488,0.000000
110.740005,65.212105,-194.203827,-0.001281,0.003461,0.087910,290.077942,14.777274,0.879102,-194.203827,294.500488,0.000000
111.110008,65.216942,-194.203827,-0.001268,0.003462,0.087928,290.099457,14.778370,0.879277,-194.203827,294.500488,0.000000
111.480003,65.221779,-194.248306,-0.001285,0.003462,0.087928,290.120972,14.779467,0.879277,-194.248306,294.500488,0.000000
111.850006,65.217308,-194.248306,-0.001298,0.003462,0.087928,290.101074,14.778454,0.879277,-194.248306,294.500488,0.000000
112.220009,65.180443,-194.381760,-0.001289,0.003462,0.087928,289.937103,14.770100,0.879277,-194.381760,294.500488,0.000000
112.590004,65.159966,-194.337280,-0.001289,0.003462,0.087928,289.846008,14.765460,0.879277,-194.337280,294.500488,0.000000
112.960007,65.117882,-194.381760,-0.001293,0.003462,0.087928,289.658813,14.755923,0.879277,-194.381760,294.500488,0.000000
113.330002,65.102257,-194.426239,-0.001289,0.003462,0.087928,289.589294,14.752382,0.879277,-194.426239,294.500488,0.000000
113.700005,65.316734,-194.426239,-0.001281,0.003465,0.088006,290.543335,14.800983,0.880056,-194.426239,294.500488,0.000000
114.070007,65.297005,-194.559677,-0.001293,0.003465,0.088006,290.455597,14.796514,0.880056,-194.559677,294.500488,0.000000
114.440002,65.278755,-194.559677,-0.001285,0.003465,0.088006,290.374420,14.792377,0.880056,-194.559677,294.500488,0.000000
114.810005,65.257896,-194.515198,-0.001272,0.003465,0.088006,290.281616,14.787651,0.880056,-194.515198,294.500488,0.000000
115.180008,65.253807,-194.559677,-0.001281,0.003465,0.088006,290.263428,14.786724,0.880056,-194.559677,294.500488,0.000000
115.550003,65.245247,-194.693115,-0.001285,0.003465,0.088006,290.225342,14.784784,0.880056,-194.693115,294.500488,0.000000
115.920006,65.215080,-194.693115,-0.001276,0.003465,0.088006,290.091156,14.777948,0.880056,-194.693115,294.500488,0.000000
116.290009,65.193474,-194.782089,-0.001289,0.003465,0.088006,289.995056,14.773052,0.880056,-194.782089,294.500488,0.000000
116.660004,65.172630,-194.782089,-0.001281,0.003465,0.088006,289.902344,14.768330,0.880056,-194.782089,294.500488,0.000000
117.030006,65.126076,-194.826569,-0.001289,0.003465,0.088006,289.695251,14.757779,0.880056,-194.826569,294.500488,0.000000
117.400009,65.100014,-194.871048,-0.001263,0.003465,0.088006,289.579315,14.751874,0.880056,-194.871048,294.500488,0.000000
117.770004,65.077293,-194.871048,-0.001289,0.003465,0.088006,289.478271,14.746725,0.880056,-194.871048,294.500488,0.000000
118.140007,65.069115,-194.960007,-0.001289,0.003465,0.088006,289.441864,14.744872,0.880056,-194.960007,294.500488,0.000000
118.510002,65.035225,-195.004486,-0.001281,0.003465,0.088006,289.291138,14.737193,0.880056,-195.004486,294.500488,0.000000
118.880005,65.018471,-195.004486,-0.001268,0.003465,0.088006,289.216614,14.733397,0.880056,-195.004486,294.500488,0.000000
119.250008,64.991661,-195.004486,-0.001285,0.003465,0.088006,289.097351,14.727321,0.880056,-195.004486,294.500488,0.000000
119.620003,64.977501,-195.093445,-0.001281,0.003465,0.088006,289.034363,14.724113,0.880056,-195.093445,294.500488,0.000000
119.990005,64.955910,-195.182419,-0.001289,0.003465,0.088006,288.938324,14.719219,0.880056,-195.182419,294.500488,0.000000
120.360008,64.928352,-195.226898,-0.001281,0.003465,0.088006,288.815735,14.712975,0.880056,-195.226898,294.500488,0.000000
120.730003,64.892982,-195.226898,-0.001293,0.003465,0.088006,288.658417,14.704960,0.880056,-195.226898,294.500488,0.000000
121.100006,64.885902,-195.271378,-0.001276,0.003465,0.088006,288.626923,14.703356,0.880056,-195.271378,294.500488,0.000000
121.470009,64.859459,-195.315857,-0.001281,0.003465,0.088006,288.509277,14.697364,0.880056,-195.315857,294.500488,0.000000
121.840004,64.821480,-195.315857,-0.001285,0.003465,0.088006,288.340332,14.688757,0.880056,-195.315857,294.500488,0.000000
122.210007,64.789452,-195.404816,-0.001272,0.003465,0.088006,288.197876,14.681499,0.880056,-195.404816,294.500488,0.000000
122.580009,64.782005,-195.449295,-0.001276,0.003465,0.088006,288.164764,14.679812,0.880056,-195.449295,294.500488,0.000000
122.950005,64.761162,-195.360336,-0.001276,0.003465,0.088006,288.072021,14.675090,0.880056,-195.360336,294.500488,0.000000
123.320007,64.752220,-195.449295,-0.001281,0.003465,0.088015,288.032257,14.673063,0.880147,-195.449295,1681.640991,0.000000
123.690002,64.696739,-195.538254,-0.001285,0.003454,0.087729,287.785461,14.660490,0.877286,-195.538254,0.087520,0.000000
124.060005,64.705666,-195.627228,-0.001289,0.003437,0.087312,287.825165,14.662513,0.873122,-195.627228,0.086904,0.000000
124.430008,64.541084,-195.627228,-0.001272,0.003417,0.086783,287.093079,14.625219,0.867831,-195.627228,0.086289,0.000000
124.800003,64.520973,-195.671707,-0.001263,0.003397,0.086280,287.003632,14.620662,0.862797,-195.671707,0.085673,0.000000
125.170006,64.440910,-195.627228,-0.001285,0.003371,0.085612,286.647491,14.602519,0.856121,-195.627228,0.085057,0.000000
125.540009,64.442406,-195.716187,-0.001276,0.003353,0.085161,286.654144,14.602858,0.851609,-195.716187,0.084442,0.000000
125.910004,64.416710,-195.760666,-0.001281,0.003320,0.084329,286.539825,14.597035,0.843290,-195.760666,0.083826,0.000000
126.280006,64.374641,-195.849625,-0.001272,0.003299,0.083791,286.352692,14.587502,0.837908,-195.849625,0.083210,0.000000
126.650009,64.368675,-195.805145,-0.001272,0.003278,0.083253,286.326172,14.586150,0.832533,-195.805145,0.082586,0.000000
127.020004,64.305748,-195.894104,-0.001272,0.003251,0.082586,286.046265,14.571891,0.825857,-195.894104,0.081970,0.000000
127.390007,64.120308,-195.938583,-0.001263,0.003236,0.082204,285.221375,14.529869,0.822041,-195.938583,0.081354,0.000000
127.760010,63.371086,-196.027557,-0.001268,0.003209,0.081510,281.888672,14.360093,0.815100,-196.027557,0.080739,0.000000
128.130005,62.466599,-196.027557,-0.001268,0.003184,0.080885,277.865295,14.155133,0.808855,-196.027557,0.080122,0.000000
128.500000,61.317459,-196.027557,-0.001250,0.003165,0.080383,272.753693,13.894734,0.803828,-196.027557,0.079507,0.000000
128.870010,59.956436,-196.027557,-0.001250,0.003139,0.079741,266.699554,13.586323,0.797409,-196.027557,0.078892,0.000000
129.240005,58.173889,-196.116516,-0.001246,0.003119,0.079221,258.770386,13.182391,0.792209,-196.116516,0.078275,0.000000
129.610001,56.326920,-196.205475,-0.001255,0.003096,0.078640,250.554657,12.763862,0.786395,-196.205475,0.077660,0.000000
129.980011,54.159714,-196.205475,-0.001246,0.003069,0.077946,240.914444,12.272766,0.779461,-196.205475,0.077035,0.000000
130.350006,52.410309,-196.249954,-0.001250,0.003051,0.077503,233.132690,11.876346,0.775033,-196.249954,0.076419,0.000000
130.720001,50.306404,-196.205475,-0.001246,0.003032,0.077009,223.774063,11.399593,0.770090,-196.205475,0.075804,0.000000
131.090012,47.026543,-196.383392,-0.001246,0.002997,0.076133,209.184509,10.656366,0.761332,-196.383392,0.075188,0.000000
131.460007,45.103615,-196.294434,-0.001250,0.002984,0.075804,200.630905,10.220626,0.758039,-196.294434,0.074572,0.000000
131.830002,41.555275,-196.472366,-0.001246,0.002949,0.074893,184.847092,9.416560,0.748932,-196.472366,0.073957,0.000000
132.200012,39.066711,-196.427887,-0.001246,0.002928,0.074373,173.777405,8.852643,0.743732,-196.427887,0.073341,0.000000
132.570007,36.416534,-196.427887,-0.001246,0.002901,0.073696,161.988831,8.252105,0.736964,-196.427887,0.072725,0.000000
132.940002,34.367744,-196.427887,-0.001246,0.002883,0.073228,152.875366,7.787842,0.732279,-196.427887,0.072110,0.000000
133.310013,31.816246,-196.605804,-0.001246,0.002860,0.072656,141.525726,7.209664,0.726556,-196.605804,0.071485,0.000000
133.680008,29.002975,-196.605804,-0.001255,0.002835,0.071997,129.011673,6.572168,0.719970,-196.605804,0.070869,0.000000
134.050003,25.837807,-196.605804,-0.001246,0.002805,0.071242,114.932304,5.854930,0.712423,-196.605804,0.070254,0.000000
134.420013,22.824944,-196.650284,-0.001255,0.002778,0.070566,101.530418,5.172206,0.705656,-196.650284,0.069638,0.000000
134.790009,20.885628,-196.739243,-0.001255,0.002758,0.070063,92.903915,4.732751,0.700629,-196.739243,0.069022,0.000000
135.160004,19.251282,-196.783722,-0.001259,0.002747,0.069768,85.633980,4.362403,0.697677,-196.783722,0.068407,0.000000
135.530014,15.905518,-196.828201,-0.001250,0.002712,0.068874,70.751274,3.604242,0.688745,-196.828201,0.067790,0.000000
135.900009,12.971970,-196.783722,-0.001242,0.002686,0.068233,57.702202,2.939490,0.682333,-196.783722,0.067175,0.000000
136.270004,11.041214,-196.828201,-0.001250,0.002667,0.067739,49.113773,2.501975,0.677390,-196.828201,0.066560,0.000000
136.639999,8.290497,-196.917175,-0.001272,0.002643,0.067123,36.877972,1.878654,0.671228,-196.917175,0.065935,0.000000
137.010010,5.657082,-196.961655,-0.001250,0.002615,0.066412,25.163956,1.281913,0.664120,-196.961655,0.065319,0.000000
137.380005,2.196251,-197.006134,-0.001246,0.002586,0.065675,9.769412,0.497678,0.656747,-197.006134,0.064704,0.000000
137.750000,-0.440887,-197.050613,-0.001237,0.002559,0.064998,-1.961165,-0.099907,0.649980,-197.050613,0.064087,0.000000
138.120010,-2.494522,-197.050613,-0.001246,0.002538,0.064461,-11.096189,-0.565267,0.644605,-197.050613,0.063472,0.000000
138.490005,-3.406090,-197.095093,-0.001263,0.002513,0.063836,-15.151044,-0.771831,0.638360,-197.095093,0.062857,0.000000
138.860001,-0.131821,-197.095093,-0.001250,0.002501,0.063515,-0.586368,-0.029871,0.635151,-197.095093,0.062240,0.000000
139.230011,-0.105385,-197.184052,-0.001272,0.002468,0.062691,-0.468775,-0.023881,0.626915,-197.184052,0.061625,0.000000
139.600006,-0.070747,-197.184052,-0.001250,0.002445,0.062102,-0.314700,-0.016032,0.621018,-197.184052,0.061000,0.000000
139.970001,-0.057343,-197.273026,-0.001268,0.002420,0.061477,-0.255072,-0.012994,0.614773,-197.273026,0.060385,0.000000
140.340012,-0.039474,-197.273026,-0.001281,0.002399,0.060922,-0.175591,-0.008945,0.609224,-197.273026,0.059769,0.000000
140.710007,-0.060699,-197.406464,-0.001315,0.002369,0.060168,-0.270005,-0.013755,0.601677,-197.406464,0.059153,0.000000
141.080002,-0.059952,-197.406464,-0.001345,0.002343,0.059517,-0.266679,-0.013585,0.595175,-197.406464,0.058537,0.000000
141.450012,-0.074844,-197.450943,-0.001362,0.002321,0.058945,-0.332924,-0.016960,0.589452,-197.450943,0.057922,0.000000
141.820007,-0.057343,-197.450943,-0.001406,0.002295,0.058295,-0.255072,-0.012994,0.582950,-197.450943,0.057306,0.000000
142.190002,-0.047295,-197.495422,-0.001410,0.002275,0.057783,-0.210377,-0.010717,0.577832,-197.495422,0.056690,0.000000
142.560013,-0.036118,-197.539902,-0.001440,0.002251,0.057184,-0.160659,-0.008184,0.571845,-197.539902,0.056075,0.000000
142.930008,-0.055855,-197.628860,-0.001500,0.002218,0.056343,-0.248455,-0.012657,0.563435,-197.628860,0.055450,0.000000
143.300003,-0.079315,-197.628860,-0.001492,0.002197,0.055797,-0.352812,-0.017973,0.557969,-197.628860,0.054834,0.000000
143.670013,-0.029045,-197.539902,-0.001526,0.002170,0.055121,-0.129199,-0.006582,0.551209,-197.539902,0.054219,0.000000
144.040009,-0.074104,-197.628860,-0.001561,0.002152,0.054652,-0.329632,-0.016792,0.546524,-197.628860,0.053603,0.000000
144.410004,-0.032394,-197.673340,-0.001587,0.002133,0.054184,-0.144098,-0.007341,0.541838,-197.673340,0.052987,0.000000
144.780014,-0.050270,-197.806793,-0.001621,0.002098,0.053300,-0.223612,-0.011391,0.532996,-197.806793,0.052372,0.000000
145.150009,-0.055481,-197.895752,-0.001638,0.002090,0.053074,-0.246792,-0.012572,0.530741,-197.895752,0.051755,0.000000
145.520004,-0.015266,-197.806793,-0.001660,0.002050,0.052068,-0.067908,-0.003459,0.520680,-197.806793,0.051140,0.000000
145.889999,-0.065910,-197.851273,-0.001690,0.002036,0.051704,-0.293184,-0.014935,0.517039,-197.851273,0.050525,0.000000
146.260010,-0.083038,-197.940231,-0.001707,0.002008,0.051010,-0.369373,-0.018817,0.510098,-197.940231,0.049900,0.000000
146.630005,-0.078201,-197.940231,-0.001738,0.001990,0.050542,-0.347857,-0.017721,0.505420,-197.940231,0.049284,0.000000
147.000000,-0.065910,-198.029190,-0.001768,0.001964,0.049883,-0.293184,-0.014935,0.498826,-198.029190,0.048668,0.000000
147.370010,-0.018250,-198.029190,-0.001802,0.001927,0.048955,-0.081178,-0.004135,0.489546,-198.029190,0.048053,0.000000
147.740005,-0.029793,-198.029190,-0.001819,0.001910,0.048521,-0.132525,-0.006751,0.485208,-198.029190,0.047437,0.000000
148.110001,-0.083412,-198.118149,-0.001837,0.001886,0.047914,-0.371036,-0.018901,0.479137,-198.118149,0.046821,0.000000
148.480011,-0.051018,-198.162643,-0.001880,0.001857,0.047176,-0.226938,-0.011561,0.471764,-198.162643,0.046205,0.000000
148.850006,-0.057343,-198.251602,-0.001901,0.001843,0.046821,-0.255072,-0.012994,0.468214,-198.251602,0.045590,0.000000
149.220001,-0.061440,-198.251602,-0.001914,0.001810,0.045980,-0.273297,-0.013922,0.459797,-198.251602,0.044974,0.000000
149.590012,-0.058090,-198.251602,-0.001944,0.001785,0.045347,-0.258398,-0.013163,0.453468,-198.251602,0.044350,0.000000
149.960007,-0.107246,-198.207123,-0.001966,0.001760,0.044705,-0.477056,-0.024302,0.447049,-198.207123,0.043734,0.000000
150.330002,-0.076340,-198.340561,-0.002009,0.001736,0.044089,-0.339576,-0.017299,0.440895,-198.340561,0.043118,0.000000
150.700012,-0.063675,-198.385040,-0.002013,0.001710,0.043422,-0.283240,-0.014429,0.434218,-198.385040,0.042502,0.000000
151.070007,-0.040962,-198.429520,-0.002044,0.001684,0.042780,-0.182209,-0.009282,0.427799,-198.429520,0.041887,0.000000
151.440002,-0.066658,-198.562973,-0.002070,0.001663,0.042233,-0.296510,-0.015105,0.422334,-198.562973,0.041271,0.000000
151.810013,-0.086761,-198.473999,-0.002100,0.001641,0.041688,-0.385934,-0.019660,0.416876,-198.473999,0.040655,0.000000
152.180008,-0.090858,-198.562973,-0.002134,0.001616,0.041037,-0.404159,-0.020589,0.410366,-198.562973,0.040040,0.000000
152.400009,-0.029793,-198.562973,-0.002130,0.001602,0.040682,-0.132525,-0.006751,0.406816,-198.562973,0.040586,0.000000