File: Data/compression 18/AutoNoHeating-17-18-reverse-2-1_09092024_172831.csv
Time (sec),S:Load (lbs),S:HL1 (DIM),S:LVDT (in),S:Position (in),Ch:Position (mm),Ch:Load (N),Ch:Stress (MPa),Ch:Strain (mm/mm),Ch:HL1 (DIM),Set Point (),Cycles ()
0.110000,-0.084900,-242.999435,-0.011016,-0.006809,-0.172942,-0.377654,-0.019239,-1.729424,-242.999435,-0.172709,0.000000
0.520000,-0.031281,-243.043915,-0.011029,-0.006704,-0.170271,-0.139143,-0.007088,-1.702711,-243.043915,-0.169326,0.000000
0.930000,-0.055115,-243.088394,-0.010848,-0.006443,-0.163654,-0.245163,-0.012489,-1.636543,-243.088394,-0.162492,0.000000
1.340000,-0.091606,-243.132874,-0.010572,-0.006177,-0.156890,-0.407484,-0.020758,-1.568900,-243.132874,-0.155658,0.000000
1.750000,-0.045433,-243.132874,-0.010283,-0.005904,-0.149970,-0.202096,-0.010295,-1.499696,-243.132874,-0.148825,0.000000
2.160000,-0.029419,-243.177353,-0.010020,-0.005642,-0.143301,-0.130862,-0.006666,-1.433007,-243.177353,-0.142008,0.000000
2.570000,-0.028297,-243.177353,-0.009757,-0.005377,-0.136579,-0.125873,-0.006412,-1.365795,-243.177353,-0.135174,0.000000
2.980000,-0.077080,-243.266327,-0.009485,-0.005101,-0.129572,-0.342868,-0.017467,-1.295721,-243.266327,-0.128341,0.000000
3.390000,-0.075966,-243.221848,-0.009201,-0.004826,-0.122582,-0.337913,-0.017214,-1.225821,-243.221848,-0.121507,0.000000
3.800000,-0.072243,-243.355286,-0.008921,-0.004556,-0.115714,-0.321352,-0.016370,-1.157141,-243.355286,-0.114673,0.000000
4.210000,-0.023087,-243.310806,-0.008658,-0.004290,-0.108975,-0.102694,-0.005231,-1.089755,-243.310806,-0.107857,0.000000
4.620000,-0.037979,-243.355286,-0.008382,-0.004022,-0.102168,-0.168940,-0.008606,-1.021679,-243.355286,-0.101023,0.000000
5.030000,-0.069260,-243.488724,-0.008123,-0.003762,-0.095551,-0.308082,-0.015694,-0.955512,-243.488724,-0.094189,0.000000
5.440000,-0.068520,-243.399765,-0.007843,-0.003492,-0.088709,-0.304790,-0.015527,-0.887089,-243.399765,-0.087356,0.000000
5.850000,-0.030533,-243.533203,-0.007545,-0.003218,-0.081736,-0.135817,-0.006919,-0.817363,-243.533203,-0.080522,0.000000
6.260000,-0.045059,-243.488724,-0.007269,-0.002953,-0.074998,-0.200433,-0.010211,-0.749977,-243.488724,-0.073706,0.000000
6.670001,-0.000000,-243.533203,-0.007002,-0.002687,-0.068260,-0.000000,-0.000000,-0.682598,-243.533203,-0.066872,0.000000
7.080000,-0.025696,-243.622162,-0.006726,-0.002407,-0.061148,-0.114301,-0.005823,-0.611480,-243.622162,-0.060038,0.000000
7.490000,-0.056229,-243.666656,-0.006441,-0.002142,-0.054410,-0.250117,-0.012742,-0.544101,-243.666656,-0.053204,0.000000
7.900001,-0.075592,-243.622162,-0.006157,-0.001872,-0.047559,-0.336250,-0.017129,-0.475587,-243.622162,-0.046371,0.000000
8.310000,-0.018616,-243.755615,-0.005902,-0.001602,-0.040691,-0.082807,-0.004218,-0.406906,-243.755615,-0.039537,0.000000
8.720000,-0.023087,-243.755615,-0.005614,-0.001331,-0.033813,-0.102694,-0.005231,-0.338135,-243.755615,-0.032720,0.000000
9.130000,-0.027184,-243.755615,-0.005346,-0.001064,-0.027032,-0.120918,-0.006160,-0.270317,-243.755615,-0.025887,0.000000
9.540001,-0.049896,-243.844574,-0.005079,-0.000805,-0.020458,-0.221950,-0.011307,-0.204581,-243.844574,-0.019053,0.000000
9.950001,0.018616,-243.844574,-0.004790,-0.000530,-0.013468,0.082807,0.004218,-0.134682,-243.844574,-0.012219,0.000000
10.360001,0.173523,-243.889053,-0.004704,-0.000004,-0.000113,0.771869,0.039321,-0.001128,-243.889053,0.000078,0.000000
10.770000,0.192513,-243.933533,-0.004687,-0.000005,-0.000122,0.856338,0.043624,-0.001219,-243.933533,0.000312,0.000000
11.180000,0.117294,-244.022491,-0.004691,-0.000004,-0.000113,0.521751,0.026579,-0.001128,-244.022491,0.000997,0.000000
11.590000,0.234970,-243.933533,-0.004682,0.000025,0.000633,1.045199,0.053245,0.006328,-243.933533,0.001682,0.000000
12.000001,0.269226,-244.022491,-0.004661,0.000046,0.001162,1.197577,0.061007,0.011620,-244.022491,0.002359,0.000000
12.410001,0.535469,-244.022491,-0.004631,0.000085,0.002151,2.381885,0.121339,0.021506,-244.022491,0.003044,0.000000
12.820001,0.752190,-244.155945,-0.004600,0.000109,0.002758,3.345906,0.170449,0.027577,-244.155945,0.003729,0.000000
13.230000,1.054184,-244.111465,-0.004579,0.000139,0.003529,4.689244,0.238881,0.035290,-244.111465,0.004414,0.000000
13.640000,1.285431,-244.200424,-0.004575,0.000159,0.004032,5.717882,0.291283,0.040324,-244.200424,0.005099,0.000000
14.050000,1.612000,-244.200424,-0.004540,0.000187,0.004752,7.170532,0.365284,0.047523,-244.200424,0.005776,0.000000
14.460001,2.033524,-244.289383,-0.004514,0.000217,0.005506,9.045565,0.460803,0.055063,-244.289383,0.006461,0.000000
14.870001,2.405151,-244.244904,-0.004484,0.000244,0.006191,10.698647,0.545015,0.061913,-244.244904,0.007146,0.000000
15.280001,2.739540,-244.289383,-0.004475,0.000268,0.006816,12.186083,0.620789,0.068158,-244.289383,0.007831,0.000000
15.690001,3.114151,-244.289383,-0.004437,0.000292,0.007406,13.852435,0.705677,0.074055,-244.289383,0.008516,0.000000
16.100000,3.635841,-244.333862,-0.004406,0.000325,0.008247,16.173031,0.823893,0.082473,-244.333862,0.009192,0.000000
16.510000,4.032051,-244.333862,-0.004398,0.000353,0.008958,17.935459,0.913676,0.089581,-244.333862,0.009877,0.000000
16.920000,4.519112,-244.333862,-0.004363,0.000379,0.009626,20.102013,1.024045,0.096257,-244.333862,0.010563,0.000000
17.330000,4.740677,-244.511795,-0.004346,0.000398,0.010112,21.087584,1.074253,0.101117,-244.511795,0.011248,0.000000
17.740002,5.458977,-244.378342,-0.004324,0.000435,0.011057,24.282742,1.237022,0.110572,-244.378342,0.011933,0.000000
18.150002,5.695808,-244.511795,-0.004277,0.000460,0.011681,25.336222,1.290689,0.116809,-244.511795,0.012609,0.000000
18.560001,6.045837,-244.556274,-0.004255,0.000487,0.012375,26.893229,1.370006,0.123751,-244.556274,0.013294,0.000000
18.970001,6.443161,-244.556274,-0.004251,0.000518,0.013156,28.660612,1.460041,0.131555,-244.556274,0.013979,0.000000
19.380001,6.529175,-244.689713,-0.004234,0.000535,0.013589,29.043221,1.479532,0.135893,-244.689713,0.014664,0.000000
19.790001,6.723557,-244.645233,-0.004199,0.000559,0.014205,29.907873,1.523580,0.142047,-244.645233,0.015349,0.000000
20.200001,7.193863,-244.689713,-0.004178,0.000590,0.014994,31.999901,1.630153,0.149942,-244.689713,0.016026,0.000000
20.610001,7.423988,-244.734192,-0.004135,0.000619,0.015714,33.023548,1.682300,0.157141,-244.734192,0.016711,0.000000
21.020000,7.621346,-244.689713,-0.004118,0.000644,0.016364,33.901440,1.727022,0.163644,-244.689713,0.017396,0.000000
21.430000,7.859291,-244.823151,-0.004100,0.000669,0.016997,34.959873,1.780941,0.169972,-244.823151,0.018081,0.000000
21.840000,8.347847,-244.823151,-0.004044,0.000703,0.017856,37.133080,1.891649,0.178556,-244.823151,0.018766,0.000000
22.250002,8.056648,-244.867630,-0.004049,0.000715,0.018159,35.837761,1.825662,0.181592,-244.867630,0.019443,0.000000
22.660002,8.417480,-244.912109,-0.004010,0.000753,0.019114,37.442822,1.907428,0.191137,-244.912109,0.020128,0.000000
23.070002,8.608505,-244.956604,-0.003971,0.000777,0.019747,38.292545,1.950715,0.197466,-244.956604,0.020813,0.000000
23.480001,8.814804,-244.956604,-0.003954,0.000806,0.020475,39.210205,1.997463,0.204748,-244.956604,0.021498,0.000000
23.890001,9.077698,-245.001083,-0.003928,0.000836,0.021247,40.379616,2.057036,0.212469,-245.001083,0.022183,0.000000
24.300001,9.161110,-245.090042,-0.003889,0.000862,0.021889,40.750652,2.075937,0.218888,-245.090042,0.022860,0.000000
24.710001,9.055725,-245.090042,-0.003880,0.000878,0.022313,40.281876,2.052057,0.223135,-245.090042,0.023545,0.000000
25.120001,9.431450,-245.134521,-0.003850,0.000909,0.023086,41.953186,2.137197,0.230856,-245.134521,0.024230,0.000000
25.530001,9.966545,-245.223480,-0.003820,0.000944,0.023987,44.333408,2.258451,0.239872,-245.223480,0.024915,0.000000
25.940001,9.804565,-245.134521,-0.003803,0.000965,0.024507,43.612885,2.221746,0.245072,-245.134521,0.025600,0.000000
26.350000,9.948677,-245.267960,-0.003773,0.000995,0.025271,44.253925,2.254402,0.252710,-245.267960,0.026277,0.000000
26.760002,10.076401,-245.267960,-0.003742,0.001020,0.025904,44.822067,2.283345,0.259038,-245.267960,0.026962,0.000000
27.170002,10.253647,-245.312439,-0.003712,0.001046,0.026571,45.610500,2.323510,0.265715,-245.312439,0.027647,0.000000
27.580002,10.683365,-245.312439,-0.003691,0.001079,0.027395,47.521980,2.420885,0.273951,-245.312439,0.028332,0.000000
27.990002,10.599213,-245.401413,-0.003660,0.001102,0.027994,47.147652,2.401816,0.279938,-245.401413,0.029017,0.000000
28.400002,10.653206,-245.445892,-0.003648,0.001125,0.028584,47.387825,2.414051,0.285835,-245.445892,0.029693,0.000000
28.810001,11.044197,-245.445892,-0.003600,0.001160,0.029459,49.127041,2.502651,0.294594,-245.445892,0.030378,0.000000
29.220001,11.070633,-245.534851,-0.003566,0.001187,0.030144,49.244637,2.508641,0.301444,-245.534851,0.031063,0.000000
29.630001,11.375237,-245.534851,-0.003553,0.001217,0.030899,50.599579,2.577665,0.308991,-245.534851,0.031749,0.000000
30.040001,11.370766,-245.579330,-0.003523,0.001240,0.031497,50.579693,2.576652,0.314971,-245.579330,0.032434,0.000000
30.450001,11.588600,-245.668289,-0.003514,0.001266,0.032156,51.548668,2.626014,0.321565,-245.668289,0.033110,0.000000
30.860001,11.727867,-245.579330,-0.003475,0.001292,0.032824,52.168159,2.657573,0.328241,-245.579330,0.033795,0.000000
31.270002,11.806068,-245.712769,-0.003445,0.001316,0.033414,52.516014,2.675293,0.334138,-245.712769,0.034480,0.000000
31.680002,12.184029,-245.712769,-0.003419,0.001347,0.034221,54.197266,2.760940,0.342207,-245.712769,0.035165,0.000000
32.090000,12.294991,-245.712769,-0.003393,0.001373,0.034862,54.690849,2.786085,0.348619,-245.712769,0.035851,0.000000
32.500000,12.565338,-245.801743,-0.003385,0.001403,0.035634,55.893417,2.847346,0.356340,-245.801743,0.036527,0.000000
32.910000,12.474106,-245.801743,-0.003350,0.001421,0.036094,55.487595,2.826673,0.360935,-245.801743,0.037212,0.000000
33.320000,12.985374,-245.935181,-0.003320,0.001455,0.036969,57.761829,2.942528,0.369693,-245.935181,0.037897,0.000000
33.730003,13.081444,-245.890701,-0.003290,0.001484,0.037689,58.189167,2.964298,0.376892,-245.890701,0.038582,0.000000
34.140003,13.080696,-245.935181,-0.003255,0.001507,0.038279,58.185841,2.964128,0.382789,-245.935181,0.039268,0.000000
34.550003,13.446373,-245.979660,-0.003234,0.001538,0.039059,59.812454,3.046992,0.390594,-245.979660,0.039944,0.000000
34.960003,13.393120,-246.024139,-0.003216,0.001557,0.039554,59.575573,3.034925,0.395537,-246.024139,0.040629,0.000000
35.370003,13.693626,-246.024139,-0.003169,0.001586,0.040274,60.912292,3.103020,0.402736,-246.024139,0.041314,0.000000
35.780003,14.125946,-246.068619,-0.003160,0.001616,0.041046,62.835346,3.200985,0.410457,-246.068619,0.041999,0.000000
36.190002,14.303200,-246.068619,-0.003126,0.001642,0.041713,63.623810,3.241151,0.417133,-246.068619,0.042685,0.000000
36.600002,14.427940,-246.157578,-0.003100,0.001668,0.042373,64.178680,3.269418,0.423727,-246.157578,0.043361,0.000000
37.010002,14.463692,-246.157578,-0.003070,0.001691,0.042945,64.337715,3.277519,0.429449,-246.157578,0.044046,0.000000
37.420002,14.965652,-246.291031,-0.003053,0.001724,0.043794,66.570549,3.391265,0.437943,-246.291031,0.044731,0.000000
37.830002,15.170456,-246.246552,-0.003022,0.001752,0.044497,67.481560,3.437675,0.444967,-246.246552,0.045416,0.000000
38.240002,15.499634,-246.291031,-0.002997,0.001781,0.045226,68.945816,3.512267,0.452257,-246.291031,0.046102,0.000000
38.650002,15.287010,-246.379990,-0.002984,0.001797,0.045650,68.000015,3.464086,0.456504,-246.379990,0.046778,0.000000
39.060001,16.151283,-246.335510,-0.002945,0.001834,0.046587,71.844498,3.659933,0.465868,-246.335510,0.047463,0.000000
39.470001,16.171761,-246.468948,-0.002915,0.001859,0.047229,71.935585,3.664573,0.472287,-246.468948,0.048148,0.000000
39.880001,16.383644,-246.468948,-0.002897,0.001886,0.047905,72.878090,3.712587,0.479054,-246.468948,0.048833,0.000000
40.290001,16.578392,-246.513428,-0.002859,0.001916,0.048659,73.744370,3.756717,0.486594,-246.513428,0.049519,0.000000
40.700001,16.606323,-246.424469,-0.002850,0.001936,0.049180,73.868614,3.763047,0.491802,-246.424469,0.050195,0.000000
41.110001,16.686378,-246.557907,-0.002820,0.001959,0.049761,74.224716,3.781188,0.497608,-246.557907,0.050880,0.000000
41.520000,17.340637,-246.646881,-0.002802,0.001990,0.050559,77.135010,3.929445,0.505586,-246.646881,0.051565,0.000000
41.930000,17.615822,-246.602386,-0.002781,0.002019,0.051270,78.359093,3.991802,0.512702,-246.602386,0.052250,0.000000
42.340000,17.773712,-246.646881,-0.002746,0.002043,0.051886,79.061417,4.027581,0.518856,-246.646881,0.052935,0.000000
42.750004,18.108475,-246.691360,-0.002729,0.002069,0.052545,80.550522,4.103439,0.525449,-246.691360,0.053612,0.000000
43.160004,18.951897,-246.691360,-0.002699,0.002101,0.053369,84.302246,4.294561,0.533685,-246.691360,0.054297,0.000000
43.570004,18.331520,-246.780319,-0.002673,0.002115,0.053733,81.542671,4.153982,0.537326,-246.780319,0.054982,0.000000
43.980003,19.004402,-246.735840,-0.002643,0.002149,0.054592,84.535805,4.306459,0.545918,-246.735840,0.055667,0.000000
44.390003,19.447525,-246.824799,-0.002617,0.002176,0.055277,86.506912,4.406872,0.552769,-246.824799,0.056352,0.000000
44.800003,19.972572,-246.824799,-0.002604,0.002205,0.056005,88.842438,4.525849,0.560051,-246.824799,0.057029,0.000000
45.210003,20.474899,-246.913757,-0.002583,0.002236,0.056795,91.076904,4.639678,0.567946,-246.913757,0.057714,0.000000
45.620003,20.632042,-246.958237,-0.002552,0.002260,0.057410,91.775909,4.675288,0.574100,-246.958237,0.058399,0.000000
46.030003,20.072739,-246.958237,-0.002527,0.002272,0.057696,89.288002,4.548547,0.576962,-246.958237,0.059084,0.000000
46.440002,21.239380,-247.002716,-0.002496,0.002306,0.058581,94.477478,4.812912,0.585811,-247.002716,0.059769,0.000000
46.850002,22.279785,-247.002716,-0.002479,0.002341,0.059465,99.105431,5.048671,0.594652,-247.002716,0.060446,0.000000
47.260002,22.425758,-247.047195,-0.002462,0.002365,0.060072,99.754753,5.081749,0.600723,-247.047195,0.061131,0.000000
47.670002,22.845047,-247.136169,-0.002436,0.002395,0.060835,101.619843,5.176762,0.608354,-247.136169,0.061816,0.000000
48.080002,23.324295,-247.091690,-0.002419,0.002421,0.061486,103.751648,5.285361,0.614864,-247.091690,0.062501,0.000000
48.490002,23.581604,-247.136169,-0.002380,0.002445,0.062093,104.896210,5.343668,0.620927,-247.136169,0.063186,0.000000
48.900002,24.681595,-247.225128,-0.002363,0.002477,0.062917,109.789215,5.592929,0.629171,-247.225128,0.063863,0.000000
49.310001,24.779152,-247.225128,-0.002324,0.002501,0.063524,110.223175,5.615036,0.635242,-247.225128,0.064548,0.000000
49.720001,24.960869,-247.269608,-0.002320,0.002524,0.064122,111.031487,5.656214,0.641222,-247.269608,0.065233,0.000000
50.130001,26.146873,-247.269608,-0.002276,0.002557,0.064955,116.307098,5.924966,0.649549,-247.269608,0.065918,0.000000
50.540001,26.391151,-247.358566,-0.002268,0.002584,0.065632,117.393707,5.980320,0.656316,-247.358566,0.066603,0.000000
50.950001,27.415550,-247.358566,-0.002242,0.002615,0.066420,121.950455,6.212452,0.664204,-247.358566,0.067279,0.000000
51.360001,27.641205,-247.403046,-0.002207,0.002639,0.067027,122.954224,6.263587,0.670275,-247.403046,0.067964,0.000000
51.770004,28.228065,-247.447525,-0.002199,0.002664,0.067669,125.564705,6.396571,0.676694,-247.447525,0.068649,0.000000
52.180004,28.806358,-247.403046,-0.002173,0.002690,0.068329,128.137085,6.527614,0.683287,-247.403046,0.069335,0.000000
52.590004,29.265121,-247.536499,-0.002147,0.002715,0.068952,130.177765,6.631571,0.689525,-247.536499,0.070020,0.000000
53.000004,30.277603,-247.580978,-0.002143,0.002745,0.069725,134.681503,6.861003,0.697246,-247.580978,0.070696,0.000000
53.410004,31.006340,-247.580978,-0.002100,0.002771,0.070384,137.923096,7.026137,0.703839,-247.580978,0.071381,0.000000
53.820004,31.742142,-247.669937,-0.002082,0.002796,0.071026,141.196091,7.192872,0.710258,-247.669937,0.072066,0.000000
54.230003,32.195694,-247.625458,-0.002061,0.002820,0.071616,143.213593,7.295648,0.716155,-247.625458,0.072751,0.000000
54.640003,33.478889,-247.669937,-0.002039,0.002853,0.072474,148.921539,7.586425,0.724739,-247.669937,0.073436,0.000000
55.050003,34.164055,-247.669937,-0.002026,0.002881,0.073176,151.969299,7.741686,0.731764,-247.669937,0.074113,0.000000
55.460003,34.642929,-247.758896,-0.002009,0.002905,0.073792,154.099442,7.850200,0.737918,-247.758896,0.074798,0.000000
55.870003,35.881813,-247.803375,-0.001992,0.002935,0.074555,159.610275,8.130935,0.745549,-247.803375,0.075483,0.000000
56.280003,35.378365,-247.803375,-0.001962,0.002945,0.074815,157.370819,8.016852,0.748153,-247.803375,0.076168,0.000000
56.690002,37.265549,-247.892334,-0.001944,0.002985,0.075821,165.765442,8.444494,0.758213,-247.892334,0.076853,0.000000
57.100002,38.558792,-247.892334,-0.001923,0.003014,0.076550,171.518066,8.737547,0.765495,-247.892334,0.077530,0.000000
57.510002,39.512444,-247.936829,-0.001893,0.003041,0.077235,175.760132,8.953648,0.772346,-247.936829,0.078215,0.000000
57.920002,40.253838,-247.981308,-0.001884,0.003065,0.077851,179.058014,9.121650,0.778507,-247.981308,0.078900,0.000000
58.330002,40.991875,-247.981308,-0.001876,0.003091,0.078501,182.340973,9.288892,0.785010,-247.981308,0.079585,0.000000
58.740002,42.490677,-248.070267,-0.001837,0.003122,0.079299,189.007965,9.628525,0.792988,-248.070267,0.080270,0.000000
59.150002,43.439484,-248.070267,-0.001824,0.003150,0.080001,193.228470,9.843528,0.800013,-248.070267,0.080947,0.000000
59.560001,44.562187,-248.159225,-0.001798,0.003177,0.080686,198.222504,10.097937,0.806864,-248.159225,0.081632,0.000000
59.970001,44.968819,-248.203705,-0.001789,0.003195,0.081163,200.031296,10.190081,0.811633,-248.203705,0.082317,0.000000
60.380001,46.985954,-248.159225,-0.001781,0.003231,0.082074,209.003967,10.647169,0.820739,-248.159225,0.083002,0.000000
60.790005,48.116852,-248.292664,-0.001750,0.003256,0.082707,214.034439,10.903435,0.827068,-248.292664,0.083687,0.000000
61.200005,49.441750,-248.248184,-0.001725,0.003284,0.083418,219.927887,11.203661,0.834183,-248.248184,0.084364,0.000000
61.610004,50.271400,-248.292664,-0.001712,0.003309,0.084060,223.618362,11.391662,0.840602,-248.292664,0.085049,0.000000
62.020004,50.987473,-248.337143,-0.001694,0.003329,0.084545,226.803604,11.553926,0.845455,-248.337143,0.085734,0.000000
62.430004,52.091553,-248.337143,-0.001694,0.003353,0.085170,231.714798,11.804114,0.851700,-248.337143,0.086419,0.000000
62.840004,54.039062,-248.426117,-0.001664,0.003386,0.086011,240.377762,12.245427,0.860110,-248.426117,0.087104,0.000000
63.250004,55.569511,-248.381638,-0.001651,0.003415,0.086731,247.185532,12.592231,0.867309,-248.381638,0.087780,0.000000
63.660004,56.971123,-248.515076,-0.001630,0.003441,0.087408,253.420212,12.909842,0.874076,-248.515076,0.088465,0.000000
64.070000,58.028290,-248.515076,-0.001617,0.003466,0.088040,258.122711,13.149399,0.880404,-248.515076,0.089150,0.000000
64.480003,60.422272,-248.559555,-0.001582,0.003500,0.088891,268.771698,13.691883,0.888905,-248.559555,0.089835,0.000000
64.889999,60.465469,-248.604034,-0.001569,0.003512,0.089202,268.963837,13.701672,0.892024,-248.604034,0.090521,0.000000
65.300003,62.526550,-248.648514,-0.001569,0.003549,0.090148,278.131989,14.168719,0.901479,-248.648514,0.091197,0.000000
65.710007,64.291222,-248.648514,-0.001544,0.003573,0.090763,285.981628,14.568599,0.907633,-248.648514,0.091882,0.000000
66.120003,65.472023,-248.648514,-0.001552,0.003598,0.091388,291.234100,14.836172,0.913878,-248.648514,0.092567,0.000000
66.530006,65.827629,-248.648514,-0.001518,0.003607,0.091613,292.815918,14.916754,0.916134,-248.648514,0.016083,0.000000
66.940002,66.193672,-248.737473,-0.001518,0.003619,0.091917,294.444153,14.999701,0.919169,-248.737473,294.500488,0.000000
67.350006,65.039314,-248.737473,-0.001500,0.003619,0.091917,289.309326,14.738119,0.919169,-248.737473,294.500488,0.000000
67.760002,67.145088,-248.826447,-0.001487,0.003479,0.088370,298.676270,15.215295,0.883697,-248.826447,294.500488,0.000000
68.170006,65.605324,-248.915405,-0.001487,0.003473,0.088223,291.827057,14.866379,0.882229,-248.915405,294.500488,0.000000
68.580002,65.290291,-248.915405,-0.001457,0.003640,0.092454,290.425720,14.794991,0.924544,-248.915405,294.500488,0.000000
68.990005,65.209114,-248.959885,-0.001470,0.003650,0.092706,290.064636,14.776596,0.927065,-248.959885,294.500488,0.000000
69.400002,65.192360,-248.826447,-0.001457,0.003656,0.092853,289.990112,14.772799,0.928533,-248.826447,294.500488,0.000000
69.810005,65.209114,-248.959885,-0.001466,0.003662,0.093010,290.064636,14.776596,0.930100,-248.959885,294.500488,0.000000
70.220001,65.075813,-249.004364,-0.001462,0.003665,0.093088,289.471680,14.746390,0.930880,-249.004364,294.500488,0.000000
70.630005,64.969307,-249.004364,-0.001453,0.003669,0.093192,288.997925,14.722256,0.931917,-249.004364,294.500488,0.000000
71.040001,65.171516,-249.137802,-0.001444,0.003675,0.093348,289.897369,14.768077,0.933476,-249.137802,294.500488,0.000000
71.450005,65.349129,-249.093323,-0.001453,0.003683,0.093538,290.687439,14.808324,0.935384,-249.093323,294.500488,0.000000
71.860001,65.144325,-249.182281,-0.001436,0.003683,0.093538,289.776428,14.761915,0.935384,-249.182281,294.500488,0.000000
72.270004,64.834145,-249.182281,-0.001440,0.003683,0.093547,288.396667,14.691628,0.935475,-249.182281,294.500488,0.000000
72.680000,65.390099,-249.182281,-0.001423,0.003692,0.093773,290.869690,14.817608,0.937730,-249.182281,294.500488,0.000000
73.090004,65.083626,-249.226776,-0.001436,0.003692,0.093773,289.506439,14.748160,0.937730,-249.226776,294.500488,0.000000
73.500000,64.786110,-249.271255,-0.001418,0.003692,0.093773,288.183014,14.680742,0.937730,-249.271255,294.500488,0.000000
73.910004,64.506081,-249.360214,-0.001418,0.003692,0.093773,286.937378,14.617288,0.937730,-249.360214,294.500488,0.000000
74.320007,66.340019,-249.360214,-0.001427,0.003676,0.093374,295.095154,15.032864,0.933741,-249.360214,294.500488,0.000000
74.730003,65.975456,-249.360214,-0.001410,0.003676,0.093374,293.473480,14.950252,0.933741,-249.360214,294.500488,0.000000
75.140007,65.724480,-249.449173,-0.001410,0.003676,0.093374,292.357086,14.893380,0.933741,-249.449173,294.500488,0.000000
75.550003,65.392326,-249.404694,-0.001401,0.003676,0.093374,290.879608,14.818112,0.933741,-249.404694,294.500488,0.000000
75.960007,65.084373,-249.493652,-0.001410,0.003677,0.093400,289.509766,14.748329,0.933999,-249.493652,294.500488,0.000000
76.370003,65.228477,-249.493652,-0.001397,0.003712,0.094276,290.150757,14.780985,0.942757,-249.493652,294.500488,0.000000
76.780006,65.157356,-249.493652,-0.001410,0.003712,0.094276,289.834381,14.764868,0.942757,-249.493652,294.500488,0.000000
77.190002,65.141350,-249.627090,-0.001410,0.003715,0.094363,289.763184,14.761241,0.943627,-249.627090,294.500488,0.000000
77.600006,65.034843,-249.582611,-0.001410,0.003716,0.094380,289.289429,14.737106,0.943801,-249.582611,294.500488,0.000000
78.010002,65.138741,-249.671585,-0.001410,0.003719,0.094466,289.751587,14.760650,0.944664,-249.671585,294.500488,0.000000
78.420006,65.184547,-249.671585,-0.001414,0.003722,0.094527,289.955353,14.771029,0.945270,-249.671585,294.500488,0.000000
78.830002,65.070976,-249.671585,-0.001397,0.003722,0.094544,289.450165,14.745294,0.945444,-249.671585,294.500488,0.000000
79.240005,64.972664,-249.760544,-0.001397,0.003724,0.094579,289.012848,14.723016,0.945792,-249.760544,294.500488,0.000000
79.650002,65.661552,-249.716064,-0.001393,0.003732,0.094796,292.077179,14.879121,0.947965,-249.716064,294.500488,0.000000
80.060005,65.567711,-249.849503,-0.001384,0.003732,0.094796,291.659760,14.857855,0.947965,-249.849503,294.500488,0.000000
80.470001,65.433662,-249.805023,-0.001388,0.003732,0.094796,291.063477,14.827479,0.947965,-249.805023,294.500488,0.000000
80.880005,65.288811,-249.893982,-0.001401,0.003732,0.094796,290.419128,14.794656,0.947965,-249.893982,294.500488,0.000000
81.290001,65.143959,-249.938461,-0.001388,0.003732,0.094805,289.774811,14.761832,0.948048,-249.938461,294.500488,0.000000
81.700005,65.031502,-249.849503,-0.001401,0.003733,0.094822,289.274567,14.736349,0.948222,-249.849503,294.500488,0.000000
82.110001,65.385246,-250.027420,-0.001393,0.003738,0.094952,290.848114,14.816508,0.949524,-250.027420,294.500488,0.000000
82.520004,65.283974,-250.027420,-0.001401,0.003738,0.094952,290.397614,14.793560,0.949524,-250.027420,294.500488,0.000000
82.930000,65.172249,-250.071899,-0.001388,0.003738,0.094952,289.900635,14.768242,0.949524,-250.071899,294.500488,0.000000
83.340004,65.044899,-250.160873,-0.001371,0.003738,0.094952,289.334167,14.739385,0.949524,-250.160873,294.500488,0.000000
83.750008,64.952934,-250.160873,-0.001388,0.003738,0.094952,288.925079,14.718545,0.949524,-250.160873,294.500488,0.000000
84.160004,64.836372,-250.160873,-0.001375,0.003738,0.094952,288.406586,14.692132,0.949524,-250.160873,294.500488,0.000000
84.570007,64.727272,-250.116394,-0.001380,0.003738,0.094952,287.921295,14.667409,0.949524,-250.116394,294.500488,0.000000
84.980003,64.614067,-250.249832,-0.001380,0.003739,0.094961,287.417725,14.641757,0.949607,-250.249832,294.500488,0.000000
85.390007,64.500130,-250.249832,-0.001380,0.003739,0.094961,286.910919,14.615938,0.949607,-250.249832,294.500488,0.000000
85.800003,66.694511,-250.294312,-0.001384,0.003691,0.093764,296.671997,15.113192,0.937640,-250.294312,294.500488,0.000000
86.210007,66.550407,-250.338791,-0.001375,0.003691,0.093764,296.031006,15.080538,0.937640,-250.338791,294.500488,0.000000
86.620003,66.365715,-250.383270,-0.001375,0.003692,0.093773,295.209442,15.038686,0.937730,-250.383270,294.500488,0.000000
87.030006,66.229424,-250.338791,-0.001371,0.003692,0.093773,294.603180,15.007801,0.937730,-250.338791,294.500488,0.000000
87.440002,66.105415,-250.427750,-0.001380,0.003692,0.093773,294.051575,14.979701,0.937730,-250.427750,294.500488,0.000000
87.850006,65.985146,-250.427750,-0.001380,0.003692,0.093773,293.516602,14.952448,0.937730,-250.427750,294.500488,0.000000
88.260002,65.884605,-250.516724,-0.001375,0.003692,0.093773,293.069366,14.929666,0.937730,-250.516724,294.500488,0.000000
88.670006,65.797096,-250.472229,-0.001371,0.003692,0.093773,292.680115,14.909836,0.937730,-250.472229,294.500488,0.000000
89.080002,65.664528,-250.561203,-0.001354,0.003695,0.093842,292.090393,14.879795,0.938419,-250.561203,294.500488,0.000000
89.490005,65.570320,-250.605682,-0.001371,0.003713,0.094319,291.671356,14.858447,0.943188,-250.605682,294.500488,0.000000
89.900002,65.480583,-250.650162,-0.001358,0.003716,0.094380,291.272186,14.838112,0.943801,-250.650162,294.500488,0.000000
90.310005,65.391960,-250.739120,-0.001350,0.003723,0.094571,290.877960,14.818030,0.945709,-250.739120,294.500488,0.000000
90.720001,65.308174,-250.650162,-0.001362,0.003724,0.094579,290.505280,14.799045,0.945792,-250.650162,294.500488,0.000000
91.130005,65.285835,-250.783600,-0.001354,0.003738,0.094935,290.405914,14.793983,0.949350,-250.783600,294.500488,0.000000
91.540001,65.224388,-250.739120,-0.001350,0.003742,0.095048,290.132568,14.780058,0.950478,-250.739120,294.500488,0.000000
91.950005,65.243385,-250.739120,-0.001367,0.003752,0.095291,290.217072,14.784363,0.952908,-250.739120,294.500488,0.000000
92.360001,65.330147,-250.872559,-0.001367,0.003758,0.095464,290.602997,14.804023,0.954641,-250.872559,294.500488,0.000000
92.770004,65.355843,-250.828079,-0.001358,0.003758,0.095464,290.717316,14.809846,0.954641,-250.828079,294.500488,0.000000
93.180008,65.293648,-250.917038,-0.001354,0.003758,0.095464,290.440643,14.795753,0.954641,-250.917038,294.500488,0.000000
93.590004,65.240395,-250.961533,-0.001375,0.003758,0.095464,290.203766,14.783685,0.954641,-250.961533,294.500488,0.000000
94.000008,65.195717,-250.961533,-0.001362,0.003759,0.095472,290.005035,14.773561,0.954725,-250.961533,294.500488,0.000000
94.410004,65.328651,-251.006012,-0.001358,0.003764,0.095611,290.596344,14.803684,0.956110,-251.006012,294.500488,0.000000
94.820007,65.415413,-251.006012,-0.001362,0.003764,0.095611,290.982300,14.823344,0.956110,-251.006012,294.500488,0.000000
95.230003,65.362907,-251.094971,-0.001354,0.003764,0.095611,290.748718,14.811446,0.956110,-251.094971,294.500488,0.000000
95.640007,65.311897,-251.094971,-0.001354,0.003764,0.095611,290.521820,14.799888,0.956110,-251.094971,294.500488,0.000000
96.050003,65.266838,-251.139450,-0.001354,0.003764,0.095611,290.321381,14.789678,0.956110,-251.139450,294.500488,0.000000
96.460007,65.206520,-251.183929,-0.001362,0.003765,0.095628,290.053101,14.776009,0.956284,-251.183929,294.500488,0.000000
96.870003,65.164803,-251.183929,-0.001350,0.003765,0.095628,289.867523,14.766556,0.956284,-251.183929,294.500488,0.000000
97.280006,65.110069,-251.317368,-0.001350,0.003765,0.095628,289.624054,14.754152,0.956284,-251.317368,294.500488,0.000000
97.690002,65.638100,-251.228409,-0.001358,0.003774,0.095854,291.972839,14.873806,0.958540,-251.228409,294.500488,0.000000
98.100006,65.609428,-251.228409,-0.001354,0.003772,0.095811,291.845306,14.867310,0.958108,-251.228409,294.500488,0.000000
98.510002,65.569206,-251.361847,-0.001358,0.003772,0.095811,291.666382,14.858194,0.958108,-251.361847,294.500488,0.000000
98.920006,65.547234,-251.406342,-0.001354,0.003772,0.095811,291.568665,14.853215,0.958108,-251.406342,294.500488,0.000000
99.330002,65.495110,-251.406342,-0.001358,0.003772,0.095811,291.336792,14.841404,0.958108,-251.406342,294.500488,0.000000
99.740005,65.444466,-251.495300,-0.001350,0.003772,0.095811,291.111511,14.829928,0.958108,-251.495300,294.500488,0.000000
100.150002,65.374077,-251.450821,-0.001354,0.003772,0.095811,290.798431,14.813977,0.958108,-251.450821,294.500488,0.000000
100.560005,65.327156,-251.495300,-0.001350,0.003772,0.095811,290.589691,14.803345,0.958108,-251.495300,294.500488,0.000000
100.970001,65.263481,-251.584259,-0.001354,0.003772,0.095811,290.306458,14.788917,0.958108,-251.584259,294.500488,0.000000
101.380005,65.226250,-251.628738,-0.001337,0.003772,0.095811,290.140839,14.780479,0.958108,-251.628738,294.500488,0.000000
101.790009,65.162941,-251.584259,-0.001362,0.003772,0.095811,289.859253,14.766133,0.958108,-251.584259,294.500488,0.000000
102.200005,65.110435,-251.673218,-0.001345,0.003772,0.095811,289.625671,14.754235,0.958108,-251.673218,294.500488,0.000000
102.610008,65.047890,-251.717697,-0.001358,0.003772,0.095811,289.347473,14.740063,0.958108,-251.717697,294.500488,0.000000
103.020004,65.004692,-251.628738,-0.001358,0.003772,0.095811,289.155304,14.730273,0.958108,-251.628738,294.500488,0.000000
103.430008,64.952187,-251.851151,-0.001358,0.003772,0.095811,288.921753,14.718376,0.958108,-251.851151,294.500488,0.000000
103.840004,64.909355,-251.762177,-0.001350,0.003772,0.095811,288.731232,14.708670,0.958108,-251.762177,294.500488,0.000000
104.250008,64.844948,-251.851151,-0.001341,0.003772,0.095811,288.444733,14.694075,0.958108,-251.851151,294.500488,0.000000
104.660004,64.785728,-251.895630,-0.001354,0.003772,0.095811,288.181305,14.680655,0.958108,-251.895630,294.500488,0.000000
105.070007,64.756310,-251.895630,-0.001345,0.003772,0.095811,288.050446,14.673989,0.958108,-251.895630,294.500488,0.000000
105.480003,65.461586,-251.984589,-0.001341,0.003795,0.096392,291.187683,14.833807,0.963922,-251.984589,294.500488,0.000000
105.890007,66.232399,-251.940109,-0.001332,0.003780,0.096019,294.616425,15.008476,0.960190,-251.940109,294.500488,0.000000
106.300003,66.170586,-252.029068,-0.001345,0.003780,0.096019,294.341461,14.994469,0.960190,-252.029068,294.500488,0.000000
106.710007,66.108772,-252.029068,-0.001337,0.003780,0.096019,294.066498,14.980462,0.960190,-252.029068,294.500488,0.000000
107.120003,66.049568,-252.073547,-0.001341,0.003780,0.096019,293.803162,14.967046,0.960190,-252.073547,294.500488,0.000000
107.530006,65.989616,-252.162506,-0.001332,0.003780,0.096019,293.536469,14.953461,0.960190,-252.162506,294.500488,0.000000
107.940002,65.963921,-252.206985,-0.001345,0.003780,0.096019,293.422180,14.947638,0.960190,-252.206985,294.500488,0.000000
108.350006,65.906944,-252.206985,-0.001332,0.003780,0.096019,293.168732,14.934727,0.960190,-252.206985,294.500488,0.000000
108.760002,65.864494,-252.206985,-0.001350,0.003780,0.096019,292.979889,14.925108,0.960190,-252.206985,294.500488,0.000000
109.170006,65.778847,-252.206985,-0.001328,0.003780,0.096019,292.598938,14.905700,0.960190,-252.206985,294.500488,0.000000
109.580002,65.756508,-252.340439,-0.001341,0.003780,0.096019,292.499542,14.900638,0.960190,-252.340439,294.500488,0.000000
109.990005,65.669380,-252.251480,-0.001345,0.003780,0.096019,292.112000,14.880895,0.960190,-252.251480,294.500488,0.000000
110.400002,65.605690,-252.384918,-0.001337,0.003780,0.096019,291.828674,14.866462,0.960190,-252.384918,294.500488,0.000000
110.810005,65.582985,-252.340439,-0.001341,0.003780,0.096019,291.727692,14.861317,0.960190,-252.340439,294.500488,0.000000
111.220009,65.553200,-252.384918,-0.001337,0.003780,0.096019,291.595184,14.854568,0.960190,-252.384918,294.500488,0.000000
111.630005,65.511116,-252.429398,-0.001345,0.003780,0.096019,291.407990,14.845031,0.960190,-252.429398,294.500488,0.000000
112.040009,65.462334,-252.473877,-0.001328,0.003780,0.096019,291.191010,14.833977,0.960190,-252.473877,294.500488,0.000000
112.450005,65.383018,-252.518356,-0.001332,0.003780,0.096019,290.838196,14.816004,0.960190,-252.518356,294.500488,0.000000
112.860008,65.338707,-252.562836,-0.001332,0.003781,0.096027,290.641083,14.805963,0.960273,-252.562836,294.500488,0.000000
113.270004,65.314873,-252.607315,-0.001332,0.003781,0.096036,290.535065,14.800561,0.960364,-252.607315,294.500488,0.000000
113.680008,65.276527,-252.607315,-0.001337,0.003781,0.096036,290.364502,14.791872,0.960364,-252.607315,294.500488,0.000000
114.090004,65.246361,-252.651794,-0.001337,0.003781,0.096045,290.230316,14.785036,0.960447,-252.651794,294.500488,0.000000
114.500008,65.195717,-252.696289,-0.001341,0.003781,0.096045,290.005035,14.773561,0.960447,-252.696289,294.500488,0.000000
114.910004,65.224754,-252.696289,-0.001332,0.003787,0.096192,290.134186,14.780140,0.961923,-252.696289,294.500488,0.000000
115.320007,65.227745,-252.740768,-0.001350,0.003787,0.096192,290.147491,14.780818,0.961923,-252.740768,294.500488,0.000000
115.730003,65.197578,-252.829727,-0.001345,0.003787,0.096201,290.013306,14.773982,0.962007,-252.829727,294.500488,0.000000
116.140007,65.162209,-252.785248,-0.001328,0.003787,0.096201,289.855988,14.765968,0.962007,-252.785248,294.500488,0.000000
116.550003,65.175240,-252.785248,-0.001328,0.003789,0.096235,289.913940,14.768920,0.962355,-252.785248,294.500488,0.000000
116.960007,65.191246,-252.829727,-0.001332,0.003789,0.096235,289.985138,14.772547,0.962355,-252.829727,294.500488,0.000000
117.370003,65.151772,-252.918686,-0.001341,0.003789,0.096235,289.809540,14.763602,0.962355,-252.918686,294.500488,0.000000
117.780006,65.159218,-252.963165,-0.001337,0.003789,0.096253,289.842682,14.765290,0.962529,-252.963165,294.500488,0.000000
118.190002,65.158485,-252.963165,-0.001328,0.003790,0.096262,289.839417,14.765123,0.962620,-252.963165,294.500488,0.000000
118.600006,65.120491,-253.052124,-0.001337,0.003790,0.096270,289.670410,14.756514,0.962703,-253.052124,294.500488,0.000000
119.010002,65.108208,-252.963165,-0.001350,0.003790,0.096270,289.615784,14.753730,0.962703,-252.963165,294.500488,0.000000
119.420006,65.157738,-253.052124,-0.001337,0.003791,0.096297,289.836090,14.764955,0.962968,-253.052124,294.500488,0.000000
119.830009,65.135384,-253.141098,-0.001337,0.003791,0.096297,289.736664,14.759890,0.962968,-253.141098,294.500488,0.000000
120.240005,65.123100,-253.096619,-0.001319,0.003791,0.096297,289.682007,14.757106,0.962968,-253.096619,294.500488,0.000000
120.650009,65.090340,-253.185577,-0.001337,0.003792,0.096305,289.536285,14.749682,0.963051,-253.185577,294.500488,0.000000
121.060005,65.084007,-253.141098,-0.001332,0.003793,0.096348,289.508118,14.748247,0.963483,-253.141098,294.500488,0.000000
121.470009,65.156609,-253.274536,-0.001332,0.003793,0.096348,289.831085,14.764699,0.963483,-253.274536,294.500488,0.000000
121.880005,65.146568,-253.274536,-0.001328,0.003793,0.096348,289.786407,14.762424,0.963483,-253.274536,294.500488,0.000000
122.290009,65.130928,-253.230057,-0.001324,0.003793,0.096348,289.716827,14.758880,0.963483,-253.230057,294.500488,0.000000
122.700005,65.119759,-253.363495,-0.001337,0.003793,0.096348,289.667145,14.756349,0.963483,-253.363495,294.500488,0.000000
123.110008,65.095543,-253.407974,-0.001328,0.003793,0.096348,289.559448,14.750860,0.963483,-253.407974,294.500488,0.000000
123.520004,65.064644,-253.363495,-0.001337,0.003793,0.096348,289.421997,14.743859,0.963483,-253.363495,294.500488,0.000000
123.930008,65.060921,-253.407974,-0.001341,0.003794,0.096366,289.405426,14.743015,0.963657,-253.407974,294.500488,0.000000
124.340004,65.054955,-253.452454,-0.001324,0.003794,0.096366,289.378876,14.741663,0.963657,-253.452454,294.500488,0.000000
124.750008,65.020699,-253.585907,-0.001337,0.003794,0.096375,289.226501,14.733901,0.963748,-253.585907,294.500488,0.000000
125.160004,65.014366,-253.541428,-0.001337,0.003794,0.096375,289.198334,14.732466,0.963748,-253.541428,294.500488,0.000000
125.570007,65.013618,-253.541428,-0.001328,0.003795,0.096383,289.195007,14.732296,0.963831,-253.541428,294.500488,0.000000
125.980003,64.996864,-253.585907,-0.001328,0.003795,0.096392,289.120483,14.728499,0.963922,-253.585907,294.500488,0.000000
126.390007,65.496971,-253.585907,-0.001315,0.003801,0.096548,291.345093,14.841826,0.965481,-253.585907,294.500488,0.000000
126.800003,65.502922,-253.719345,-0.001345,0.003801,0.096548,291.371552,14.843175,0.965481,-253.719345,1681.640991,0.000000
127.210007,65.476112,-253.719345,-0.001319,0.003790,0.096270,291.252289,14.837099,0.962703,-253.719345,0.096149,0.000000
127.620003,65.417274,-253.763824,-0.001332,0.003776,0.095898,290.990570,14.823767,0.958979,-253.763824,0.095464,0.000000
128.029999,65.292534,-253.808304,-0.001341,0.003748,0.095195,290.435699,14.795500,0.951954,-253.808304,0.094779,0.000000
128.440002,65.197945,-253.808304,-0.001324,0.003725,0.094614,290.014954,14.774065,0.946140,-253.808304,0.094094,0.000000
128.850006,65.203163,-253.852783,-0.001345,0.003702,0.094042,290.038147,14.775248,0.940418,-253.852783,0.093409,0.000000
129.260010,65.127571,-253.852783,-0.001324,0.003674,0.093314,289.701904,14.758119,0.933136,-253.852783,0.092732,0.000000
129.670013,65.079155,-253.941757,-0.001319,0.003644,0.092567,289.486542,14.747148,0.925672,-253.941757,0.092047,0.000000
130.080002,65.053474,-253.897263,-0.001337,0.003622,0.091987,289.372314,14.741328,0.919866,-253.897263,0.091362,0.000000
130.490005,64.924263,-253.986237,-0.001319,0.003591,0.091214,288.797546,14.712049,0.912145,-253.986237,0.090677,0.000000
130.900009,64.738441,-254.030716,-0.001332,0.003571,0.090703,287.970978,14.669940,0.907027,-254.030716,0.089992,0.000000
131.310013,63.794853,-254.030716,-0.001315,0.003543,0.089983,283.773682,14.456120,0.899828,-254.030716,0.089315,0.000000
131.720001,63.026276,-254.164154,-0.001315,0.003525,0.089523,280.354889,14.281958,0.895234,-254.164154,0.088630,0.000000
132.130005,61.400124,-254.164154,-0.001315,0.003491,0.088682,273.121399,13.913466,0.886824,-254.164154,0.087945,0.000000
132.540009,60.107986,-254.164154,-0.001298,0.003472,0.088179,267.373688,13.620665,0.881790,-254.164154,0.087260,0.000000
132.950012,58.402153,-254.208633,-0.001306,0.003450,0.087642,259.785736,13.234117,0.876415,-254.208633,0.086575,0.000000
133.360001,55.838371,-254.208633,-0.001302,0.003417,0.086791,248.381485,12.653155,0.867914,-254.208633,0.085898,0.000000
133.770004,53.521095,-254.297592,-0.001302,0.003392,0.086159,238.073715,12.128054,0.861586,-254.297592,0.085213,0.000000
134.180008,50.783783,-254.297592,-0.001306,0.003363,0.085430,225.897552,11.507770,0.854304,-254.297592,0.084528,0.000000
134.590012,48.513054,-254.386566,-0.001289,0.003339,0.084814,215.796844,10.993215,0.848142,-254.386566,0.083843,0.000000
135.000000,45.363899,-254.386566,-0.001293,0.003315,0.084199,201.788696,10.279606,0.841988,-254.386566,0.083158,0.000000
135.410004,42.624359,-254.342072,-0.001289,0.003288,0.083522,189.602615,9.658818,0.835220,-254.342072,0.082473,0.000000
135.820007,40.645943,-254.520004,-0.001306,0.003270,0.083063,180.802185,9.210503,0.830625,-254.520004,0.081796,0.000000
136.230011,36.782204,-254.475525,-0.001289,0.003233,0.082117,163.615417,8.334967,0.821171,-254.475525,0.081111,0.000000
136.639999,33.632683,-254.520004,-0.001289,0.003205,0.081415,149.605652,7.621275,0.814146,-254.520004,0.080426,0.000000
137.050003,30.891647,-254.564484,-0.001293,0.003180,0.080773,137.412903,7.000147,0.807734,-254.564484,0.079741,0.000000
137.460007,28.521126,-254.520004,-0.001289,0.003161,0.080279,126.868301,6.462979,0.802791,-254.520004,0.079056,0.000000
137.870010,25.013000,-254.653442,-0.001289,0.003124,0.079342,111.263382,5.668027,0.793420,-254.653442,0.078380,0.000000
138.280014,22.325966,-254.608963,-0.001302,0.003101,0.078761,99.310860,5.059136,0.787614,-254.608963,0.077695,0.000000
138.690002,19.429649,-254.742401,-0.001298,0.003075,0.078094,86.427399,4.402821,0.780937,-254.742401,0.077009,0.000000
139.100006,18.043304,-254.742401,-0.001298,0.003064,0.077824,80.260628,4.088671,0.778243,-254.742401,0.076324,0.000000
139.510010,13.707771,-254.786880,-0.001298,0.003018,0.076645,60.975212,3.106225,0.766449,-254.786880,0.075639,0.000000
139.920013,9.512627,-254.875854,-0.001298,0.002984,0.075796,42.314278,2.155592,0.757955,-254.875854,0.074963,0.000000
140.330002,7.480217,-254.831375,-0.001302,0.002965,0.075310,33.273666,1.695041,0.753096,-254.831375,0.074278,0.000000
140.740005,5.133156,-254.964813,-0.001298,0.002941,0.074702,22.833418,1.163190,0.747025,-254.964813,0.073593,0.000000
141.150009,2.658363,-254.920334,-0.001311,0.002920,0.074156,11.824990,0.602394,0.741559,-254.920334,0.072908,0.000000
141.560013,-0.167564,-254.964813,-0.001302,0.002893,0.073480,-0.745364,-0.037971,0.734800,-254.964813,0.072223,0.000000
141.970001,-3.221024,-255.009293,-0.001298,0.002859,0.072630,-14.327828,-0.729894,0.726299,-255.009293,0.071546,0.000000
142.380005,-0.313911,-255.009293,-0.001311,0.002832,0.071945,-1.396348,-0.071133,0.719448,-255.009293,0.070861,0.000000
142.790009,-0.029045,-255.098251,-0.001328,0.002804,0.071225,-0.129199,-0.006582,0.712249,-255.098251,0.070176,0.000000
143.200012,-0.062561,-255.053772,-0.001337,0.002772,0.070401,-0.278285,-0.014177,0.704013,-255.053772,0.069491,0.000000
143.610001,-0.046921,-255.142731,-0.001354,0.002750,0.069837,-0.208714,-0.010632,0.698374,-255.142731,0.068806,0.000000
144.020004,-0.052132,-255.187210,-0.001384,0.002718,0.069048,-0.231893,-0.011813,0.690478,-255.187210,0.068129,0.000000
144.430008,-0.031281,-255.142731,-0.001449,0.002694,0.068432,-0.139143,-0.007088,0.684324,-255.142731,0.067444,0.000000
144.840012,-0.003349,-255.231705,-0.001462,0.002671,0.067852,-0.014898,-0.000759,0.678518,-255.231705,0.066759,0.000000
145.250000,-0.016388,-255.276184,-0.001487,0.002635,0.066932,-0.072897,-0.003714,0.669321,-255.276184,0.066074,0.000000
145.660004,-0.041336,-255.320663,-0.001518,0.002612,0.066342,-0.183872,-0.009367,0.663424,-255.320663,0.065389,0.000000
146.070007,-0.042450,-255.365143,-0.001565,0.002585,0.065666,-0.188827,-0.009619,0.656657,-255.365143,0.064712,0.000000
146.480011,-0.044685,-255.320663,-0.001591,0.002560,0.065015,-0.198770,-0.010126,0.650154,-255.320663,0.064027,0.000000
146.889999,-0.041336,-255.365143,-0.001621,0.002534,0.064365,-0.183872,-0.009367,0.643652,-255.365143,0.063342,0.000000
147.300003,-0.045059,-255.454102,-0.001638,0.002506,0.063645,-0.200433,-0.010211,0.636453,-255.454102,0.062657,0.000000
147.710007,-0.031281,-255.498581,-0.001660,0.002476,0.062900,-0.139143,-0.007088,0.628997,-255.498581,0.061972,0.000000
148.120010,-0.045059,-255.543060,-0.001707,0.002456,0.062371,-0.200433,-0.010211,0.623705,-255.543060,0.061295,0.000000
148.530014,-0.052505,-255.543060,-0.001712,0.002435,0.061850,-0.233556,-0.011898,0.618505,-255.543060,0.060610,0.000000
148.940002,-0.075218,-255.587540,-0.001763,0.002400,0.060966,-0.334587,-0.017045,0.609656,-255.587540,0.059925,0.000000
149.350006,-0.068146,-255.587540,-0.001781,0.002383,0.060532,-0.303127,-0.015442,0.605318,-255.587540,0.059240,0.000000
149.760010,-0.026810,-255.676514,-0.001819,0.002341,0.059457,-0.119255,-0.006075,0.594569,-255.676514,0.058555,0.000000
150.170013,-0.044685,-255.676514,-0.001845,0.002314,0.058772,-0.198770,-0.010126,0.587718,-255.676514,0.057879,0.000000
150.580002,-0.032394,-255.720993,-0.001867,0.002300,0.058416,-0.144098,-0.007341,0.584161,-255.720993,0.057194,0.000000
150.990005,-0.057716,-255.765472,-0.001901,0.002263,0.057471,-0.256735,-0.013079,0.574706,-255.765472,0.056508,0.000000
151.400009,-0.058838,-255.809952,-0.001944,0.002238,0.056846,-0.261724,-0.013333,0.568461,-255.809952,0.055823,0.000000
151.810013,-0.064049,-255.854431,-0.001962,0.002207,0.056066,-0.284903,-0.014514,0.560656,-255.854431,0.055138,0.000000
152.220001,-0.057343,-255.854431,-0.002005,0.002181,0.055407,-0.255072,-0.012994,0.554071,-255.854431,0.054462,0.000000
152.630005,-0.064796,-255.854431,-0.002018,0.002155,0.054748,-0.288229,-0.014683,0.547477,-255.854431,0.053777,0.000000
153.040009,-0.081924,-255.987869,-0.002044,0.002128,0.054054,-0.364418,-0.018564,0.540536,-255.987869,0.053091,0.000000
153.450012,-0.060326,-255.943390,-0.002061,0.002098,0.053282,-0.268342,-0.013670,0.532822,-255.943390,0.052406,0.000000
153.860001,-0.092346,-255.987869,-0.002104,0.002075,0.052701,-0.410776,-0.020926,0.527009,-255.987869,0.051721,0.000000
154.270004,-0.066284,-256.076843,-0.002121,0.002052,0.052129,-0.294847,-0.015020,0.521286,-256.076843,0.051045,0.000000
154.680008,-0.066284,-256.032349,-0.002151,0.002031,0.051582,-0.294847,-0.015020,0.515821,-256.032349,0.050360,0.000000
155.090012,-0.081924,-256.121307,-0.002190,0.001994,0.050637,-0.364418,-0.018564,0.506374,-256.121307,0.049674,0.000000
155.500000,-0.078568,-256.076843,-0.002216,0.001963,0.049848,-0.349486,-0.017804,0.498478,-256.076843,0.048989,0.000000
155.910004,-0.074844,-256.165802,-0.002251,0.001937,0.049198,-0.332924,-0.016960,0.491976,-256.165802,0.048304,0.000000
156.320007,-0.071869,-256.165802,-0.002268,0.001911,0.048547,-0.319689,-0.016286,0.485473,-256.165802,0.047628,0.000000
156.730011,-0.076340,-256.254761,-0.002298,0.001889,0.047983,-0.339576,-0.017299,0.479834,-256.254761,0.046943,0.000000
157.140015,-0.077454,-256.254761,-0.002311,0.001875,0.047619,-0.344531,-0.017551,0.476193,-256.254761,0.046257,0.000000
157.550003,-0.059952,-256.254761,-0.002367,0.001830,0.046491,-0.266679,-0.013585,0.464914,-256.254761,0.045572,0.000000
157.960007,-0.066284,-256.299225,-0.002380,0.001803,0.045806,-0.294847,-0.015020,0.458063,-256.299225,0.044887,0.000000
158.370010,-0.065536,-256.343719,-0.002410,0.001779,0.045191,-0.291521,-0.014851,0.451909,-256.343719,0.044211,0.000000
158.780014,-0.080429,-256.432678,-0.002436,0.001759,0.044679,-0.357766,-0.018225,0.446792,-256.432678,0.043526,0.000000
159.190002,-0.054367,-256.477173,-0.002475,0.001725,0.043812,-0.241837,-0.012320,0.438117,-256.477173,0.042840,0.000000
159.600006,-0.062935,-256.432678,-0.002509,0.001699,0.043153,-0.279948,-0.014261,0.431531,-256.432678,0.042155,0.000000
160.010010,-0.076340,-256.521637,-0.002527,0.001671,0.042451,-0.339576,-0.017299,0.424506,-256.521637,0.041470,0.000000
160.420013,-0.067398,-256.566132,-0.002561,0.001665,0.042303,-0.299802,-0.015273,0.423030,-256.566132,0.040794,0.000000
160.830002,-0.074844,-256.521637,-0.002578,0.001627,0.041323,-0.332924,-0.016960,0.413227,-256.521637,0.040109,0.000000
161.240005,-0.088249,-256.610596,-0.002630,0.001584,0.040230,-0.392552,-0.019998,0.402304,-256.610596,0.039423,0.000000
161.650009,-0.074104,-256.566132,-0.002639,0.001566,0.039771,-0.329632,-0.016792,0.397709,-256.566132,0.038738,0.000000
162.060013,-0.033890,-256.699554,-0.002656,0.001546,0.039259,-0.150749,-0.007680,0.392592,-256.699554,0.038053,0.000000
162.470001,-0.067398,-256.655090,-0.002690,0.001521,0.038635,-0.299802,-0.015273,0.386347,-256.655090,0.037377,0.000000
162.880005,-0.062187,-256.699554,-0.002721,0.001484,0.037698,-0.276622,-0.014092,0.376983,-256.699554,0.036692,0.000000
163.290009,-0.062935,-256.788544,-0.002751,0.001459,0.037047,-0.279948,-0.014261,0.370473,-256.788544,0.036007,0.000000
163.700012,-0.028297,-256.788544,-0.002785,0.001432,0.036371,-0.125873,-0.006412,0.363713,-256.788544,0.035322,0.000000
164.110001,-0.028297,-256.877502,-0.002807,0.001404,0.035669,-0.125873,-0.006412,0.356688,-256.877502,0.034636,0.000000
164.520004,-0.051018,-256.833008,-0.002828,0.001376,0.034957,-0.226938,-0.011561,0.349573,-256.833008,0.033960,0.000000
164.930008,-0.052879,-256.877502,-0.002850,0.001350,0.034281,-0.235219,-0.011983,0.342813,-256.877502,0.033275,0.000000
165.340012,-0.037979,-256.921967,-0.002902,0.001318,0.033483,-0.168940,-0.008606,0.334835,-256.921967,0.032590,0.000000
165.750015,-0.009308,-256.877502,-0.002940,0.001295,0.032902,-0.041403,-0.002109,0.329021,-256.877502,0.031905,0.000000
166.160004,-0.011917,-257.055420,-0.002936,0.001273,0.032339,-0.053010,-0.002700,0.323389,-257.055420,0.031220,0.000000
166.570007,-0.020477,-257.010925,-0.002988,0.001237,0.031428,-0.091088,-0.004640,0.314283,-257.010925,0.030543,0.000000
166.900009,-0.043938,-257.010925,-0.003014,0.001224,0.031081,-0.195445,-0.009956,0.310808,-257.010925,0.030951,0.000000