File: Data/compression 18/AutoNoHeating-17-18-reverse-2-2_09092024_173210.csv
Time (sec),S:Load (lbs),S:HL1 (DIM),S:LVDT (in),S:Position (in),Ch:Position (mm),Ch:Load (N),Ch:Stress (MPa),Ch:Strain (mm/mm),Ch:HL1 (DIM),Set Point (),Cycles ()
0.010000,-0.030907,-261.281097,-0.009662,-0.005063,-0.128593,-0.137480,-0.007004,-1.285926,-261.281097,-0.128783,0.000000
0.470000,-0.005959,-261.281097,-0.009671,-0.005013,-0.127318,-0.026505,-0.001350,-1.273178,-261.281097,-0.126563,0.000000
0.930000,-0.035751,-261.414551,-0.009550,-0.004729,-0.120128,-0.159030,-0.008101,-1.201280,-261.414551,-0.118897,0.000000
1.390000,-0.035004,-261.370056,-0.009248,-0.004424,-0.112358,-0.155704,-0.007932,-1.123584,-261.370056,-0.111230,0.000000
1.850000,-0.046547,-261.414551,-0.008946,-0.004129,-0.104865,-0.207051,-0.010548,-1.048651,-261.414551,-0.103565,0.000000
2.310000,-0.033890,-261.459045,-0.008636,-0.003825,-0.097147,-0.150749,-0.007680,-0.971469,-261.459045,-0.095898,0.000000
2.770000,-0.019737,-261.503510,-0.008330,-0.003527,-0.089594,-0.087796,-0.004473,-0.895938,-261.503510,-0.088232,0.000000
3.230000,-0.030533,-261.548004,-0.008011,-0.003220,-0.081797,-0.135817,-0.006919,-0.817969,-261.548004,-0.080583,0.000000
3.690000,-0.035004,-261.592468,-0.007705,-0.002919,-0.074139,-0.155704,-0.007932,-0.741393,-261.592468,-0.072917,0.000000
4.150000,-0.014893,-261.636963,-0.007386,-0.002620,-0.066551,-0.066245,-0.003375,-0.665513,-261.636963,-0.065250,0.000000
4.610000,-0.030159,-261.636963,-0.007071,-0.002311,-0.058694,-0.134154,-0.006834,-0.586939,-261.636963,-0.057584,0.000000
5.070000,0.004097,-261.592468,-0.006765,-0.002011,-0.051080,0.018224,0.000928,-0.510802,-261.592468,-0.049917,0.000000
5.530000,-0.019363,-261.681427,-0.006454,-0.001707,-0.043370,-0.086133,-0.004388,-0.433704,-261.681427,-0.042252,0.000000
5.990000,-0.083038,-261.725922,-0.006161,-0.001411,-0.035851,-0.369373,-0.018817,-0.358513,-261.725922,-0.034602,0.000000
6.450000,0.011169,-261.725922,-0.005859,-0.001112,-0.028246,0.049684,0.002531,-0.282459,-261.725922,-0.026936,0.000000
6.910000,0.021225,-261.814880,-0.005540,-0.000809,-0.020553,0.094413,0.004810,-0.205535,-261.814880,-0.019270,0.000000
7.370000,-0.018990,-261.770386,-0.005243,-0.000511,-0.012974,-0.084470,-0.004303,-0.129739,-261.770386,-0.011604,0.000000
7.830000,0.104637,-261.903839,-0.005044,-0.000000,-0.000000,0.465449,0.023711,-0.000000,-261.903839,0.000226,0.000000
8.290000,0.107246,-261.948334,-0.005040,-0.000000,-0.000000,0.477056,0.024302,-0.000000,-261.948334,0.000399,0.000000
8.750000,0.090485,-261.859344,-0.005036,0.000006,0.000148,0.402496,0.020504,0.001476,-261.859344,0.001171,0.000000
9.210000,0.194382,-261.948334,-0.005010,0.000038,0.000963,0.864653,0.044048,0.009629,-261.948334,0.001934,0.000000
9.670000,0.261406,-262.037292,-0.004975,0.000067,0.001691,1.162792,0.059235,0.016911,-262.037292,0.002697,0.000000
10.130000,0.466583,-262.037292,-0.004950,0.000101,0.002576,2.075466,0.105729,0.025760,-262.037292,0.003469,0.000000
10.590000,0.627075,-262.126251,-0.004928,0.000126,0.003201,2.789370,0.142097,0.032005,-262.126251,0.004232,0.000000
11.050000,0.892952,-262.126251,-0.004885,0.000164,0.004154,3.972049,0.202346,0.041543,-262.126251,0.005004,0.000000
11.510000,1.101479,-262.215210,-0.004868,0.000190,0.004822,4.899621,0.249599,0.048220,-262.215210,0.005767,0.000000
11.970000,1.415390,-262.215210,-0.004850,0.000218,0.005542,6.295969,0.320732,0.055418,-262.215210,0.006530,0.000000
12.430000,1.810104,-262.259674,-0.004825,0.000248,0.006297,8.051746,0.410176,0.062966,-262.259674,0.007303,0.000000
12.890000,2.218597,-262.304169,-0.004777,0.000280,0.007112,9.868814,0.502741,0.071118,-262.304169,0.008066,0.000000
13.350000,2.599907,-262.304169,-0.004751,0.000309,0.007857,11.564963,0.589147,0.078574,-262.304169,0.008837,0.000000
13.810000,2.924240,-262.348663,-0.004743,0.000336,0.008525,13.007669,0.662642,0.085251,-262.348663,0.009601,0.000000
14.270000,3.429176,-262.304169,-0.004717,0.000366,0.009306,15.253738,0.777062,0.093055,-262.304169,0.010372,0.000000
14.730000,3.930763,-262.393127,-0.004678,0.000397,0.010078,17.484909,0.890724,0.100777,-262.393127,0.011135,0.000000
15.190001,4.392136,-262.482086,-0.004652,0.000427,0.010849,19.537195,0.995272,0.108490,-262.482086,0.011898,0.000000
15.650001,4.843445,-262.437622,-0.004644,0.000460,0.011673,21.544718,1.097540,0.116734,-262.437622,0.012670,0.000000
16.110001,5.289177,-262.615540,-0.004596,0.000488,0.012393,23.527433,1.198545,0.123925,-262.615540,0.013433,0.000000
16.570002,5.768051,-262.571045,-0.004579,0.000517,0.013121,25.657574,1.307059,0.131215,-262.571045,0.014205,0.000000
17.030001,6.135956,-262.615540,-0.004549,0.000546,0.013859,27.294094,1.390427,0.138588,-262.615540,0.014969,0.000000
17.490002,6.580566,-262.571045,-0.004514,0.000581,0.014769,29.271822,1.491178,0.147694,-262.571045,0.015732,0.000000
17.950001,6.888519,-262.660004,-0.004484,0.000610,0.015489,30.641665,1.560961,0.154885,-262.660004,0.016504,0.000000
18.410002,7.175613,-262.793457,-0.004471,0.000637,0.016191,31.918722,1.626017,0.161910,-262.793457,0.017267,0.000000
18.870001,7.572563,-262.748993,-0.004428,0.000672,0.017076,33.684444,1.715967,0.170759,-262.748993,0.018039,0.000000
19.330002,7.830620,-262.748993,-0.004393,0.000702,0.017822,34.832336,1.774444,0.178216,-262.748993,0.018802,0.000000
19.790001,8.027603,-262.837952,-0.004376,0.000729,0.018524,35.708561,1.819081,0.185240,-262.837952,0.019565,0.000000
20.250002,8.296829,-262.882416,-0.004337,0.000759,0.019279,36.906139,1.880088,0.192787,-262.882416,0.020337,0.000000
20.710001,8.667343,-262.882416,-0.004307,0.000797,0.020242,38.554268,1.964048,0.202416,-262.882416,0.021100,0.000000
21.170000,8.827461,-262.971375,-0.004290,0.000826,0.020970,39.266510,2.000331,0.209698,-262.971375,0.021871,0.000000
21.630001,9.018112,-262.882416,-0.004264,0.000856,0.021741,40.114567,2.043533,0.217412,-262.882416,0.022634,0.000000
22.090000,8.896721,-263.015869,-0.004234,0.000877,0.022288,39.574593,2.016026,0.222877,-263.015869,0.023398,0.000000
22.550001,9.141373,-263.060333,-0.004204,0.000902,0.022904,40.662857,2.071465,0.229039,-263.060333,0.024170,0.000000
23.010000,9.355858,-263.015869,-0.004178,0.000931,0.023650,41.616936,2.120068,0.236495,-263.015869,0.024933,0.000000
23.470001,9.914787,-263.104828,-0.004156,0.000975,0.024768,44.103176,2.246723,0.247684,-263.104828,0.025705,0.000000
23.930000,9.728233,-263.149292,-0.004109,0.000997,0.025323,43.273342,2.204449,0.253232,-263.149292,0.026468,0.000000
24.390001,10.293121,-263.238281,-0.004079,0.001035,0.026277,45.786091,2.332454,0.262770,-263.238281,0.027240,0.000000
24.850000,10.231308,-263.193787,-0.004070,0.001061,0.026954,45.511131,2.318447,0.269538,-263.193787,0.028003,0.000000
25.310001,10.462173,-263.238281,-0.004027,0.001092,0.027743,46.538071,2.370762,0.277425,-263.238281,0.028766,0.000000
25.770000,10.769753,-263.282745,-0.003997,0.001123,0.028515,47.906250,2.440461,0.285146,-263.282745,0.029538,0.000000
26.230001,10.820023,-263.238281,-0.003967,0.001156,0.029356,48.129864,2.451852,0.293556,-263.238281,0.030301,0.000000
26.690001,11.045685,-263.416199,-0.003936,0.001187,0.030145,49.133659,2.502988,0.301452,-263.416199,0.031073,0.000000
27.150002,11.024460,-263.371704,-0.003915,0.001214,0.030830,49.039246,2.498178,0.308302,-263.371704,0.031836,0.000000
27.610001,11.103027,-263.460663,-0.003876,0.001236,0.031393,49.388733,2.515982,0.313934,-263.460663,0.032599,0.000000
28.070002,11.623230,-263.505157,-0.003859,0.001271,0.032296,51.702709,2.633862,0.322958,-263.505157,0.033371,0.000000
28.530001,11.881660,-263.505157,-0.003820,0.001305,0.033146,52.852264,2.692423,0.331458,-263.505157,0.034134,0.000000
28.990002,11.959488,-263.549622,-0.003790,0.001335,0.033909,53.198460,2.710059,0.339089,-263.549622,0.034906,0.000000
29.450001,12.099129,-263.549622,-0.003747,0.001363,0.034629,53.819614,2.741702,0.346288,-263.549622,0.035669,0.000000
29.910002,12.312492,-263.549622,-0.003729,0.001394,0.035418,54.768700,2.790051,0.354175,-263.549622,0.036433,0.000000
30.370001,12.796951,-263.683075,-0.003699,0.001429,0.036293,56.923683,2.899831,0.362934,-263.683075,0.037204,0.000000
30.830002,12.709442,-263.683075,-0.003665,0.001456,0.036988,56.534424,2.880001,0.369875,-263.683075,0.037967,0.000000
31.290001,12.968987,-263.772034,-0.003643,0.001489,0.037811,57.688934,2.938814,0.378111,-263.772034,0.038739,0.000000
31.750002,13.008087,-263.727570,-0.003626,0.001517,0.038531,57.862862,2.947675,0.385310,-263.727570,0.039502,0.000000
32.210003,13.444504,-263.772034,-0.003570,0.001551,0.039407,59.804138,3.046568,0.394068,-263.772034,0.040274,0.000000
32.670002,13.287369,-263.860992,-0.003548,0.001577,0.040066,59.105167,3.010961,0.400661,-263.860992,0.041037,0.000000
33.130001,13.416206,-263.905487,-0.003531,0.001606,0.040803,59.678265,3.040156,0.408034,-263.905487,0.041800,0.000000
33.590000,13.435196,-263.905487,-0.003505,0.001631,0.041419,59.762737,3.044459,0.414189,-263.905487,0.042572,0.000000
34.050003,13.947952,-263.905487,-0.003471,0.001663,0.042252,62.043591,3.160651,0.422515,-263.905487,0.043336,0.000000
34.510002,14.082008,-263.949951,-0.003432,0.001695,0.043058,62.639900,3.191029,0.430577,-263.949951,0.044108,0.000000
34.970001,14.222023,-263.994446,-0.003406,0.001723,0.043769,63.262718,3.222757,0.437693,-263.994446,0.044871,0.000000
35.430000,14.652855,-264.038940,-0.003389,0.001755,0.044585,65.179153,3.320385,0.445845,-264.038940,0.045634,0.000000
35.890003,14.624557,-264.127899,-0.003376,0.001779,0.045174,65.053284,3.313972,0.451742,-264.127899,0.046405,0.000000
36.350002,15.343231,-264.127899,-0.003320,0.001822,0.046267,68.250099,3.476826,0.462666,-264.127899,0.047169,0.000000
36.810001,15.336906,-264.127899,-0.003303,0.001847,0.046926,68.221970,3.475393,0.469259,-264.127899,0.047940,0.000000
37.270000,15.727524,-264.261322,-0.003264,0.001882,0.047810,69.959518,3.563908,0.478100,-264.261322,0.048703,0.000000
37.730003,15.057625,-264.261322,-0.003238,0.001893,0.048088,66.979660,3.412107,0.480878,-264.261322,0.049467,0.000000
38.190002,16.119255,-264.305817,-0.003208,0.001938,0.049232,71.702026,3.652675,0.492324,-264.305817,0.050238,0.000000
38.650002,16.221291,-264.350281,-0.003186,0.001968,0.049979,72.155907,3.675797,0.499788,-264.350281,0.051001,0.000000
39.110001,16.511742,-264.350281,-0.003147,0.001999,0.050768,73.447899,3.741614,0.507676,-264.350281,0.051774,0.000000
39.570004,16.490143,-264.439240,-0.003122,0.002022,0.051357,73.351822,3.736720,0.513572,-264.439240,0.052537,0.000000
40.030003,17.292229,-264.439240,-0.003100,0.002063,0.052389,76.919678,3.918475,0.523890,-264.439240,0.053300,0.000000
40.490002,17.342133,-264.483734,-0.003070,0.002091,0.053118,77.141655,3.929784,0.531180,-264.483734,0.054072,0.000000
40.950001,17.768867,-264.617187,-0.003048,0.002124,0.053942,79.039871,4.026483,0.539416,-264.617187,0.054835,0.000000
41.410004,17.418091,-264.528229,-0.003022,0.002141,0.054393,77.479538,3.946996,0.543927,-264.528229,0.055607,0.000000
41.870003,18.451431,-264.572693,-0.002975,0.002184,0.055468,82.076065,4.181154,0.554676,-264.572693,0.056370,0.000000
42.330002,18.625694,-264.528229,-0.002958,0.002214,0.056240,82.851227,4.220643,0.562398,-264.528229,0.057142,0.000000
42.790001,18.868858,-264.617187,-0.002915,0.002245,0.057020,83.932877,4.275744,0.570202,-264.617187,0.057905,0.000000
43.250004,19.008499,-264.661652,-0.002893,0.002271,0.057688,84.554024,4.307387,0.576879,-264.661652,0.058668,0.000000
43.710003,18.811882,-264.661652,-0.002876,0.002295,0.058295,83.679428,4.262834,0.582950,-264.661652,0.059440,0.000000
44.170002,19.784897,-264.795105,-0.002850,0.002329,0.059162,88.007614,4.483322,0.591624,-264.795105,0.060203,0.000000
44.630001,20.080559,-264.795105,-0.002811,0.002361,0.059969,89.322784,4.550320,0.599686,-264.795105,0.060975,0.000000
45.090004,20.467453,-264.839569,-0.002777,0.002394,0.060801,91.043777,4.637991,0.608013,-264.839569,0.061738,0.000000
45.550003,20.542297,-264.928558,-0.002759,0.002416,0.061365,91.376701,4.654951,0.613653,-264.928558,0.062501,0.000000
46.010002,21.067345,-264.884064,-0.002729,0.002448,0.062171,93.712227,4.773929,0.621714,-264.884064,0.063273,0.000000
46.470001,21.230072,-265.017517,-0.002699,0.002473,0.062822,94.436073,4.810803,0.628217,-265.017517,0.064036,0.000000
46.930004,22.596306,-264.973022,-0.002682,0.002517,0.063923,100.513390,5.120396,0.639231,-264.973022,0.064808,0.000000
47.390003,22.724403,-265.017517,-0.002647,0.002543,0.064592,101.083191,5.149424,0.645915,-265.017517,0.065571,0.000000
47.850002,23.227852,-265.061981,-0.002608,0.002576,0.065433,103.322647,5.263506,0.654325,-265.061981,0.066334,0.000000
48.310001,23.339561,-265.061981,-0.002587,0.002604,0.066143,103.819557,5.288820,0.661433,-265.061981,0.067106,0.000000
48.770000,23.183907,-265.150940,-0.002565,0.002623,0.066620,103.127167,5.253549,0.666202,-265.150940,0.067869,0.000000
49.230003,24.269745,-265.195435,-0.002552,0.002660,0.067557,107.957214,5.499603,0.675573,-265.195435,0.068641,0.000000
49.690002,25.094925,-265.195435,-0.002509,0.002692,0.068389,111.627800,5.686592,0.683893,-265.195435,0.069404,0.000000
50.150002,25.717155,-265.239899,-0.002488,0.002725,0.069222,114.395622,5.827590,0.692219,-265.239899,0.070176,0.000000
50.610001,25.836693,-265.195435,-0.002462,0.002751,0.069881,114.927353,5.854678,0.698813,-265.195435,0.070940,0.000000
51.070004,26.347961,-265.284393,-0.002436,0.002779,0.070584,117.201584,5.970533,0.705837,-265.284393,0.071703,0.000000
51.530003,26.590370,-265.328888,-0.002410,0.002803,0.071199,118.279877,6.025464,0.711992,-265.328888,0.072474,0.000000
51.990002,28.095505,-265.328888,-0.002380,0.002846,0.072283,124.975044,6.366532,0.722832,-265.328888,0.073238,0.000000
52.450001,28.238495,-265.462311,-0.002358,0.002872,0.072952,125.611099,6.398934,0.729516,-265.462311,0.074009,0.000000
52.910004,29.328056,-265.373352,-0.002337,0.002906,0.073801,130.457703,6.645833,0.738009,-265.373352,0.074772,0.000000
53.370003,29.899277,-265.506805,-0.002315,0.002936,0.074573,132.998627,6.775273,0.745730,-265.506805,0.075536,0.000000
53.830002,30.593376,-265.551270,-0.002294,0.002966,0.075345,136.086136,6.932558,0.753451,-265.551270,0.076307,0.000000
54.290001,31.143745,-265.506805,-0.002255,0.002994,0.076056,138.534302,7.057274,0.760559,-265.506805,0.077070,0.000000
54.750004,31.651283,-265.551270,-0.002229,0.003020,0.076698,140.791946,7.172283,0.766979,-265.551270,0.077842,0.000000
55.210003,32.619453,-265.551270,-0.002203,0.003054,0.077565,145.098572,7.391674,0.775646,-265.551270,0.078605,0.000000
55.670002,33.949196,-265.640228,-0.002186,0.003087,0.078397,151.013565,7.692998,0.783973,-265.640228,0.079368,0.000000
56.130001,34.857040,-265.684723,-0.002164,0.003117,0.079160,155.051865,7.898718,0.791603,-265.684723,0.080141,0.000000
56.590004,35.433098,-265.773682,-0.002147,0.003143,0.079837,157.614288,8.029255,0.798371,-265.773682,0.080904,0.000000
57.050003,36.165932,-265.818176,-0.002117,0.003172,0.080574,160.874100,8.195317,0.805744,-265.818176,0.081676,0.000000
57.510002,37.648720,-265.773682,-0.002095,0.003205,0.081407,167.469864,8.531322,0.814070,-265.773682,0.082439,0.000000
57.970001,38.315262,-265.862640,-0.002065,0.003235,0.082161,170.434799,8.682363,0.821610,-265.862640,0.083210,0.000000
58.430004,39.726181,-265.907135,-0.002044,0.003268,0.083003,176.710876,9.002081,0.830027,-265.907135,0.083974,0.000000
58.890003,40.175262,-265.907135,-0.002026,0.003291,0.083601,178.708496,9.103845,0.836008,-265.907135,0.084737,0.000000
59.350002,41.480804,-265.951599,-0.001996,0.003328,0.084529,184.515839,9.399685,0.845288,-265.951599,0.085508,0.000000
59.810001,42.878685,-266.040558,-0.001970,0.003358,0.085292,190.733917,9.716449,0.852919,-266.040558,0.086272,0.000000
60.270004,43.942184,-266.040558,-0.001936,0.003386,0.086012,195.464600,9.957441,0.860117,-266.040558,0.087044,0.000000
60.730003,44.902534,-266.085052,-0.001940,0.003414,0.086723,199.736450,10.175060,0.867225,-266.085052,0.087807,0.000000
61.190002,46.440056,-266.085052,-0.001923,0.003449,0.087616,206.575684,10.523467,0.876158,-266.085052,0.088570,0.000000
61.650002,47.759377,-266.218506,-0.001880,0.003479,0.088370,212.444321,10.822429,0.883705,-266.218506,0.089342,0.000000
62.110004,48.570404,-266.218506,-0.001876,0.003505,0.089021,216.051941,11.006210,0.890207,-266.218506,0.090105,0.000000
62.570004,49.999565,-266.174011,-0.001850,0.003534,0.089775,222.409180,11.330063,0.897754,-266.174011,0.090877,0.000000
63.030003,51.496132,-266.262970,-0.001845,0.003568,0.090626,229.066238,11.669189,0.906255,-266.262970,0.091640,0.000000
63.490002,53.468590,-266.262970,-0.001798,0.003600,0.091441,237.840164,12.116156,0.914408,-266.262970,0.092403,0.000000
63.950005,54.792000,-266.396423,-0.001798,0.003631,0.092221,243.726990,12.416044,0.922212,-266.396423,0.093175,0.000000
64.410004,56.503799,-266.351929,-0.001768,0.003663,0.093045,251.341446,12.803945,0.930448,-266.351929,0.093938,0.000000
64.870003,56.958466,-266.396423,-0.001755,0.003681,0.093496,253.363907,12.906972,0.934960,-266.396423,0.094710,0.000000
65.330002,59.093651,-266.485382,-0.001725,0.003716,0.094380,262.861694,13.390813,0.943801,-266.485382,0.095473,0.000000
65.790001,61.056419,-266.485382,-0.001707,0.003751,0.095282,271.592529,13.835583,0.952825,-266.485382,0.096236,0.000000
66.250000,62.846786,-266.529846,-0.001699,0.003781,0.096036,279.556458,14.241285,0.960364,-266.529846,0.097008,0.000000
66.710007,63.607552,-266.529846,-0.001677,0.003803,0.096592,282.940521,14.413677,0.965920,-266.529846,0.097771,0.000000
67.170006,66.299431,-266.574341,-0.001673,0.003839,0.097520,294.914612,15.023666,0.975201,-266.574341,0.098525,0.000000
67.630005,64.728767,-266.663300,-0.001647,0.003834,0.097372,287.927948,14.667748,0.973725,-266.663300,294.500488,0.000000
68.090004,66.096107,-266.618835,-0.001630,0.003660,0.092967,294.010162,14.977592,0.929669,-266.618835,294.500488,0.000000
68.550003,65.198692,-266.752258,-0.001625,0.003850,0.097780,290.018280,14.774235,0.977797,-266.752258,294.500488,0.000000
69.010002,66.103554,-266.752258,-0.001608,0.003868,0.098257,294.043304,14.979279,0.982566,-266.752258,294.500488,0.000000
69.470001,65.061668,-266.796753,-0.001595,0.003869,0.098266,289.408752,14.743185,0.982657,-266.796753,294.500488,0.000000
69.930000,65.029640,-266.885712,-0.001600,0.003885,0.098673,289.266296,14.735928,0.986730,-266.885712,294.500488,0.000000
70.390007,65.211357,-266.841217,-0.001587,0.003894,0.098916,290.074615,14.777104,0.989160,-266.841217,294.500488,0.000000
70.850006,64.903023,-266.885712,-0.001595,0.003898,0.099011,288.703064,14.707235,0.990113,-266.885712,294.500488,0.000000
71.310005,65.852211,-266.930176,-0.001578,0.003907,0.099237,292.925262,14.922324,0.992369,-266.930176,294.500488,0.000000
71.770004,65.205025,-266.930176,-0.001574,0.003907,0.099237,290.046448,14.775670,0.992369,-266.930176,294.500488,0.000000
72.230003,64.593956,-267.108124,-0.001582,0.003907,0.099237,287.328278,14.637200,0.992369,-267.108124,294.500488,0.000000
72.690002,66.146004,-267.019135,-0.001569,0.003893,0.098873,294.232117,14.988898,0.988728,-267.019135,294.500488,0.000000
73.150002,65.585594,-267.108124,-0.001556,0.003893,0.098890,291.739288,14.861908,0.988902,-267.108124,294.500488,0.000000
73.610001,65.218056,-267.152588,-0.001556,0.003920,0.099575,290.104401,14.778623,0.995753,-267.152588,294.500488,0.000000
74.070007,65.150291,-267.108124,-0.001552,0.003931,0.099835,289.802979,14.763268,0.998349,-267.108124,294.500488,0.000000
74.530006,65.131294,-267.241547,-0.001548,0.003935,0.099957,289.718475,14.758963,0.999568,-267.241547,294.500488,0.000000
74.990005,65.184547,-267.241547,-0.001548,0.003942,0.100121,289.955353,14.771029,1.001211,-267.241547,294.500488,0.000000
75.450005,65.072090,-267.241547,-0.001535,0.003943,0.100148,289.455109,14.745546,1.001476,-267.241547,294.500488,0.000000
75.910004,65.733055,-267.330505,-0.001539,0.003952,0.100391,292.395233,14.895324,1.003906,-267.330505,294.500488,0.000000
76.370003,65.448555,-267.330505,-0.001531,0.003952,0.100391,291.129700,14.830854,1.003906,-267.330505,294.500488,0.000000
76.830002,65.166664,-267.419464,-0.001531,0.003953,0.100399,289.875793,14.766976,1.003989,-267.419464,294.500488,0.000000
77.290001,65.774010,-267.419464,-0.001526,0.003962,0.100642,292.577393,14.904604,1.006419,-267.419464,294.500488,0.000000
77.750000,65.563988,-267.508453,-0.001526,0.003962,0.100642,291.643188,14.857012,1.006419,-267.508453,294.500488,0.000000
78.210007,65.298119,-267.508453,-0.001522,0.003962,0.100642,290.460541,14.796765,1.006419,-267.508453,294.500488,0.000000
78.670006,65.074699,-267.508453,-0.001531,0.003963,0.100650,289.466705,14.746138,1.006502,-267.508453,294.500488,0.000000
79.130005,65.864876,-267.597412,-0.001526,0.003969,0.100824,292.981598,14.925194,1.008235,-267.597412,294.500488,0.000000
79.590004,65.596382,-267.597412,-0.001518,0.003969,0.100824,291.787292,14.864352,1.008235,-267.597412,294.500488,0.000000
80.050003,65.346519,-267.641876,-0.001509,0.003969,0.100824,290.675842,14.807734,1.008235,-267.641876,294.500488,0.000000
80.510002,65.112297,-267.686371,-0.001522,0.003970,0.100833,289.633972,14.754658,1.008326,-267.686371,294.500488,0.000000
80.970001,65.494728,-267.686371,-0.001492,0.003979,0.101058,291.335114,14.841318,1.010582,-267.686371,294.500488,0.000000
81.430000,65.308540,-267.730835,-0.001496,0.003979,0.101058,290.506897,14.799127,1.010582,-267.730835,294.500488,0.000000
81.890007,65.171516,-267.775330,-0.001518,0.003979,0.101058,289.897369,14.768077,1.010582,-267.775330,294.500488,0.000000
82.350006,65.466423,-267.864288,-0.001509,0.003984,0.101206,291.209198,14.834903,1.012058,-267.864288,294.500488,0.000000
82.810005,65.331627,-267.953247,-0.001509,0.003984,0.101206,290.609589,14.804358,1.012058,-267.953247,294.500488,0.000000
83.270004,65.198326,-267.864288,-0.001509,0.003985,0.101214,290.016632,14.774152,1.012141,-267.864288,294.500488,0.000000
83.730003,65.123482,-267.953247,-0.001505,0.003987,0.101257,289.683716,14.757192,1.012573,-267.953247,294.500488,0.000000
84.190002,65.556175,-267.953247,-0.001505,0.003993,0.101413,291.608429,14.855242,1.014132,-267.953247,294.500488,0.000000
84.650002,65.476860,-268.042206,-0.001492,0.003993,0.101413,291.255615,14.837269,1.014132,-268.042206,294.500488,0.000000
85.110001,65.327156,-268.086700,-0.001505,0.003993,0.101422,290.589691,14.803345,1.014223,-268.086700,294.500488,0.000000
85.570007,65.278755,-268.042206,-0.001496,0.003995,0.101475,290.374420,14.792377,1.014745,-268.042206,294.500488,0.000000
86.030006,65.257530,-268.086700,-0.001500,0.003996,0.101509,290.279999,14.787567,1.015086,-268.086700,294.500488,0.000000
86.490005,65.245979,-268.131165,-0.001492,0.003997,0.101535,290.228607,14.784950,1.015351,-268.131165,294.500488,0.000000
86.950005,65.245247,-268.175659,-0.001479,0.003998,0.101561,290.225342,14.784784,1.015608,-268.175659,294.500488,0.000000
87.410004,65.218803,-268.175659,-0.001487,0.004000,0.101596,290.107727,14.778792,1.015957,-268.175659,294.500488,0.000000
87.870003,65.225136,-268.175659,-0.001483,0.004001,0.101630,290.135895,14.780228,1.016305,-268.175659,294.500488,0.000000
88.330002,65.213585,-268.220123,-0.001492,0.004003,0.101674,290.084503,14.777609,1.016736,-268.220123,294.500488,0.000000
88.790001,65.229607,-268.264618,-0.001487,0.004004,0.101691,290.155792,14.781240,1.016910,-268.264618,294.500488,0.000000
89.250008,65.188271,-268.353577,-0.001479,0.004004,0.101708,289.971924,14.771873,1.017085,-268.353577,294.500488,0.000000
89.710007,65.187157,-268.442535,-0.001492,0.004006,0.101761,289.966949,14.771621,1.017607,-268.442535,294.500488,0.000000
90.170006,65.153633,-268.398071,-0.001487,0.004006,0.101761,289.817841,14.764025,1.017607,-268.398071,294.500488,0.000000
90.630005,65.280983,-268.487030,-0.001496,0.004009,0.101830,290.384308,14.792882,1.018296,-268.487030,294.500488,0.000000
91.090004,65.241142,-268.442535,-0.001475,0.004009,0.101830,290.207092,14.783854,1.018296,-268.442535,294.500488,0.000000
91.550003,65.165932,-268.487030,-0.001470,0.004009,0.101839,289.872528,14.766811,1.018387,-268.487030,294.500488,0.000000
92.010002,65.168526,-268.575989,-0.001470,0.004011,0.101873,289.884094,14.767399,1.018735,-268.575989,294.500488,0.000000
92.470001,65.095924,-268.531494,-0.001470,0.004011,0.101873,289.561127,14.750948,1.018735,-268.531494,294.500488,0.000000
92.930008,65.072838,-268.620453,-0.001479,0.004012,0.101917,289.458435,14.745716,1.019166,-268.620453,294.500488,0.000000
93.390007,65.081764,-268.664948,-0.001483,0.004013,0.101925,289.498138,14.747739,1.019250,-268.664948,294.500488,0.000000
93.850006,65.046394,-268.620453,-0.001470,0.004013,0.101942,289.340820,14.739723,1.019424,-268.620453,294.500488,0.000000
94.310005,64.979744,-268.709412,-0.001496,0.004013,0.101942,289.044342,14.724620,1.019424,-268.709412,294.500488,0.000000
94.770004,65.269447,-268.709412,-0.001462,0.004019,0.102090,290.333008,14.790268,1.020900,-268.709412,294.500488,0.000000
95.230003,65.272423,-268.798401,-0.001479,0.004018,0.102055,290.346252,14.790943,1.020552,-268.798401,294.500488,0.000000
95.690002,65.209496,-268.842865,-0.001470,0.004018,0.102055,290.066315,14.776683,1.020552,-268.842865,294.500488,0.000000
96.150002,65.127937,-268.842865,-0.001479,0.004018,0.102055,289.703522,14.758202,1.020552,-268.842865,294.500488,0.000000
96.610008,65.042305,-268.887360,-0.001483,0.004018,0.102064,289.322632,14.738797,1.020642,-268.887360,294.500488,0.000000
97.070007,64.984215,-268.887360,-0.001470,0.004018,0.102064,289.064240,14.725634,1.020642,-268.887360,294.500488,0.000000
97.530006,64.906013,-269.020782,-0.001466,0.004019,0.102073,288.716370,14.707913,1.020726,-269.020782,294.500488,0.000000
97.990005,64.841591,-268.976318,-0.001470,0.004019,0.102073,288.429810,14.693315,1.020726,-268.976318,294.500488,0.000000
98.450005,64.761894,-269.020782,-0.001475,0.004019,0.102073,288.075287,14.675255,1.020726,-269.020782,294.500488,0.000000
98.910004,65.421745,-269.109741,-0.001475,0.004028,0.102306,291.010468,14.824780,1.023065,-269.109741,294.500488,0.000000
99.370003,65.505898,-269.065277,-0.001470,0.004028,0.102306,291.384796,14.843848,1.023065,-269.065277,294.500488,0.000000
99.830002,65.478340,-269.154236,-0.001466,0.004028,0.102306,291.262207,14.837604,1.023065,-269.154236,294.500488,0.000000
100.290009,65.412804,-269.109741,-0.001470,0.004028,0.102306,290.970673,14.822754,1.023065,-269.109741,294.500488,0.000000
100.750008,65.334984,-269.154236,-0.001457,0.004028,0.102306,290.624512,14.805119,1.023065,-269.154236,294.500488,0.000000
101.210007,65.303703,-269.287689,-0.001462,0.004028,0.102306,290.485382,14.798031,1.023065,-269.287689,294.500488,0.000000
101.670006,65.241890,-269.243195,-0.001457,0.004028,0.102316,290.210419,14.784024,1.023156,-269.243195,294.500488,0.000000
102.130005,65.187523,-269.332153,-0.001462,0.004028,0.102316,289.968597,14.771704,1.023156,-269.332153,294.500488,0.000000
102.590004,65.089592,-269.332153,-0.001462,0.004028,0.102316,289.532959,14.749513,1.023156,-269.332153,294.500488,0.000000
103.050003,65.040810,-269.421112,-0.001462,0.004028,0.102316,289.315979,14.738459,1.023156,-269.421112,294.500488,0.000000
103.510002,64.988670,-269.465607,-0.001457,0.004028,0.102316,289.084045,14.726644,1.023156,-269.465607,294.500488,0.000000
103.970001,64.941017,-269.421112,-0.001466,0.004028,0.102316,288.872070,14.715845,1.023156,-269.421112,294.500488,0.000000
104.430008,64.858711,-269.554565,-0.001462,0.004028,0.102316,288.505951,14.697194,1.023156,-269.554565,294.500488,0.000000
104.890007,64.787590,-269.554565,-0.001457,0.004028,0.102316,288.189606,14.681078,1.023156,-269.554565,294.500488,0.000000
105.350006,64.736580,-269.599030,-0.001466,0.004028,0.102316,287.962677,14.669519,1.023156,-269.599030,294.500488,0.000000
105.810005,64.678490,-269.643524,-0.001457,0.004028,0.102316,287.704285,14.656355,1.023156,-269.643524,294.500488,0.000000
106.270004,64.621513,-269.554565,-0.001449,0.004028,0.102316,287.450836,14.643444,1.023156,-269.554565,294.500488,0.000000
106.730003,64.550774,-269.776978,-0.001457,0.004028,0.102316,287.136169,14.627414,1.023156,-269.776978,294.500488,0.000000
107.190002,64.499748,-269.732483,-0.001470,0.004028,0.102316,286.909210,14.615852,1.023156,-269.732483,294.500488,0.000000
107.650002,64.452080,-269.776978,-0.001457,0.004028,0.102316,286.697174,14.605050,1.023156,-269.776978,294.500488,0.000000
108.110008,64.404427,-269.821442,-0.001466,0.004028,0.102316,286.485199,14.594252,1.023156,-269.821442,294.500488,0.000000
108.570007,64.384315,-269.776978,-0.001453,0.004043,0.102680,286.395752,14.589694,1.026797,-269.776978,294.500488,0.000000
109.030006,66.363472,-269.865936,-0.001449,0.004020,0.102107,295.199463,15.038177,1.021074,-269.865936,294.500488,0.000000
109.490005,66.278954,-269.821442,-0.001462,0.004020,0.102107,294.823517,15.019026,1.021074,-269.821442,294.500488,0.000000
109.950005,66.212288,-269.954895,-0.001453,0.004020,0.102107,294.526978,15.003919,1.021074,-269.954895,294.500488,0.000000
110.410004,66.146751,-270.043854,-0.001453,0.004020,0.102107,294.235443,14.989068,1.021074,-270.043854,294.500488,0.000000
110.870003,66.086433,-269.999359,-0.001440,0.004020,0.102107,293.967133,14.975400,1.021074,-269.999359,294.500488,0.000000
111.330002,66.013817,-270.088348,-0.001444,0.004020,0.102107,293.644135,14.958945,1.021074,-270.088348,294.500488,0.000000
111.790009,65.910667,-270.088348,-0.001444,0.004020,0.102107,293.185303,14.935571,1.021074,-270.088348,294.500488,0.000000
112.250008,65.918114,-270.177307,-0.001436,0.004020,0.102107,293.218414,14.937258,1.021074,-270.177307,294.500488,0.000000
112.710007,65.824287,-270.177307,-0.001453,0.004020,0.102116,292.801056,14.915997,1.021157,-270.177307,294.500488,0.000000
113.170006,65.851830,-270.177307,-0.001436,0.004020,0.102116,292.923553,14.922237,1.021157,-270.177307,294.500488,0.000000
113.630005,65.760231,-270.266266,-0.001449,0.004020,0.102116,292.516113,14.901482,1.021157,-270.266266,294.500488,0.000000
114.090004,65.744591,-270.221771,-0.001453,0.004020,0.102116,292.446533,14.897937,1.021157,-270.221771,294.500488,0.000000
114.550003,65.609795,-270.310730,-0.001436,0.004020,0.102116,291.846954,14.867392,1.021157,-270.310730,294.500488,0.000000
115.010002,65.573296,-270.399689,-0.001449,0.004020,0.102116,291.684601,14.859120,1.021157,-270.399689,294.500488,0.000000
115.470009,65.554680,-270.399689,-0.001444,0.004020,0.102116,291.601776,14.854903,1.021157,-270.399689,294.500488,0.000000
115.930008,65.497704,-270.488678,-0.001453,0.004020,0.102116,291.348328,14.841991,1.021157,-270.488678,294.500488,0.000000
116.390007,65.454140,-270.444183,-0.001440,0.004020,0.102116,291.154541,14.832120,1.021157,-270.444183,294.500488,0.000000
116.850006,65.366631,-270.533142,-0.001431,0.004021,0.102142,290.765289,14.812291,1.021422,-270.533142,294.500488,0.000000
117.310005,65.324562,-270.533142,-0.001453,0.004021,0.102142,290.578156,14.802757,1.021422,-270.533142,294.500488,0.000000
117.770004,65.285088,-270.577637,-0.001440,0.004021,0.102142,290.402588,14.793813,1.021422,-270.577637,294.500488,0.000000
118.230003,65.269066,-270.666595,-0.001440,0.004021,0.102142,290.331299,14.790182,1.021422,-270.666595,294.500488,0.000000
118.690002,65.224022,-270.666595,-0.001453,0.004021,0.102142,290.130951,14.779975,1.021422,-270.666595,294.500488,0.000000
119.150009,65.154015,-270.711060,-0.001449,0.004021,0.102142,289.819519,14.764111,1.021422,-270.711060,294.500488,0.000000
119.610008,65.089958,-270.666595,-0.001444,0.004022,0.102151,289.534607,14.749595,1.021505,-270.666595,294.500488,0.000000
120.070007,65.184914,-270.800018,-0.001440,0.004041,0.102645,289.956970,14.771112,1.026448,-270.800018,294.500488,0.000000
120.530006,65.124962,-270.844513,-0.001444,0.004041,0.102645,289.690308,14.757527,1.026448,-270.844513,294.500488,0.000000
120.990005,65.073952,-270.800018,-0.001431,0.004041,0.102645,289.463379,14.745968,1.026448,-270.800018,294.500488,0.000000
121.450005,65.052345,-270.844513,-0.001457,0.004041,0.102654,289.367279,14.741073,1.026539,-270.844513,294.500488,0.000000
121.910004,65.020332,-270.888977,-0.001436,0.004041,0.102654,289.224884,14.733818,1.026539,-270.888977,294.500488,0.000000
122.370003,64.968941,-270.977966,-0.001436,0.004041,0.102654,288.996277,14.722173,1.026539,-270.977966,294.500488,0.000000
122.830009,65.196465,-270.977966,-0.001449,0.004050,0.102870,290.008362,14.773730,1.028704,-270.977966,294.500488,0.000000
123.290009,65.359932,-270.977966,-0.001436,0.004050,0.102870,290.735504,14.810773,1.028704,-270.977966,294.500488,0.000000
123.750008,65.341316,-271.155884,-0.001431,0.004050,0.102870,290.652679,14.806554,1.028704,-271.155884,294.500488,0.000000
124.210007,65.340935,-270.977966,-0.001440,0.004050,0.102870,290.651001,14.806468,1.028704,-270.977966,294.500488,0.000000
124.670006,65.327156,-271.200348,-0.001440,0.004050,0.102870,290.589691,14.803345,1.028704,-271.200348,294.500488,0.000000
125.130005,65.300728,-271.111389,-0.001440,0.004050,0.102870,290.472137,14.797357,1.028704,-271.111389,294.500488,0.000000
125.590004,65.271309,-271.155884,-0.001449,0.004050,0.102870,290.341278,14.790690,1.028704,-271.155884,294.500488,0.000000
126.050003,65.247108,-271.244843,-0.001453,0.004050,0.102870,290.233643,14.785206,1.028704,-271.244843,294.500488,0.000000
126.510010,65.208000,-271.244843,-0.001449,0.004050,0.102870,290.059662,14.776343,1.028704,-271.244843,294.500488,0.000000
126.970009,65.178963,-271.378296,-0.001436,0.004050,0.102870,289.930511,14.769765,1.028704,-271.378296,294.500488,0.000000
127.430008,65.136513,-271.333801,-0.001431,0.004050,0.102870,289.741669,14.760145,1.028704,-271.333801,294.500488,0.000000
127.890007,65.113045,-271.333801,-0.001440,0.004046,0.102758,289.637299,14.754827,1.027576,-271.333801,0.102870,0.000000
128.350006,64.943245,-271.422760,-0.001444,0.004033,0.102437,288.881989,14.716350,1.024367,-271.422760,0.102151,0.000000
128.810013,64.899681,-271.422760,-0.001436,0.004008,0.101812,288.688202,14.706478,1.018122,-271.422760,0.101387,0.000000
129.270004,64.850533,-271.511719,-0.001440,0.003986,0.101249,288.469574,14.695340,1.012490,-271.511719,0.100615,0.000000
129.730011,64.744392,-271.511719,-0.001431,0.003950,0.100321,287.997437,14.671289,1.003209,-271.511719,0.099852,0.000000
130.190002,64.742912,-271.511719,-0.001440,0.003925,0.099705,287.990845,14.670954,0.997055,-271.511719,0.099081,0.000000
130.650009,64.643120,-271.600677,-0.001427,0.003893,0.098881,287.546967,14.648341,0.988811,-271.600677,0.098318,0.000000
131.110001,64.595451,-271.556213,-0.001427,0.003867,0.098231,287.334930,14.637538,0.982309,-271.556213,0.097554,0.000000
131.570007,64.451714,-271.689636,-0.001436,0.003833,0.097355,286.695526,14.604967,0.973551,-271.689636,0.096783,0.000000
132.029999,63.839912,-271.645172,-0.001423,0.003805,0.096653,283.974121,14.466331,0.966526,-271.645172,0.096020,0.000000
132.490005,62.894829,-271.689636,-0.001410,0.003780,0.096002,279.770172,14.252172,0.960023,-271.689636,0.095248,0.000000
132.950012,61.331230,-271.734131,-0.001418,0.003749,0.095230,272.814941,13.897856,0.952302,-271.734131,0.094485,0.000000
133.410004,59.509216,-271.734131,-0.001418,0.003720,0.094476,264.710205,13.484982,0.944755,-271.734131,0.093722,0.000000
133.870010,57.494682,-271.867584,-0.001414,0.003694,0.093817,255.749115,13.028481,0.938169,-271.867584,0.092949,0.000000
134.330002,55.183739,-271.867584,-0.001418,0.003667,0.093132,245.469528,12.504814,0.931319,-271.867584,0.092186,0.000000
134.790009,52.863113,-271.912048,-0.001406,0.003639,0.092438,235.146866,11.978952,0.924377,-271.912048,0.091414,0.000000
135.250000,50.637070,-271.956543,-0.001406,0.003619,0.091926,225.244934,11.474524,0.919260,-271.956543,0.090651,0.000000
135.710007,46.474693,-271.956543,-0.001401,0.003577,0.090851,206.729767,10.531316,0.908511,-271.956543,0.089888,0.000000
136.170013,43.057800,-272.045502,-0.001406,0.003544,0.090027,191.530655,9.757037,0.900268,-272.045502,0.089116,0.000000
136.630005,40.522316,-272.001007,-0.001414,0.003522,0.089464,180.252258,9.182488,0.894636,-272.001007,0.088353,0.000000
137.090012,38.337982,-272.001007,-0.001406,0.003499,0.088865,170.535858,8.687510,0.888648,-272.001007,0.087581,0.000000
137.550003,33.695236,-272.134460,-0.001423,0.003459,0.087868,149.883896,7.635450,0.878679,-272.134460,0.086818,0.000000
138.010010,30.954948,-272.089966,-0.001401,0.003435,0.087243,137.694489,7.014492,0.872433,-272.089966,0.086047,0.000000
138.470001,28.148376,-272.223419,-0.001393,0.003410,0.086610,125.210236,6.378513,0.866098,-272.223419,0.085284,0.000000
138.930008,24.785110,-272.134460,-0.001414,0.003374,0.085699,110.249680,5.616386,0.856991,-272.134460,0.084520,0.000000
139.389999,19.862350,-272.267914,-0.001401,0.003331,0.084607,88.352150,4.500873,0.846068,-272.267914,0.083748,0.000000
139.850006,17.365219,-272.267914,-0.001410,0.003309,0.084060,77.244354,3.935015,0.840602,-272.267914,0.082985,0.000000
140.310013,13.942368,-272.312378,-0.001410,0.003276,0.083219,62.018749,3.159386,0.832192,-272.312378,0.082213,0.000000
140.770004,10.999886,-272.401337,-0.001397,0.003250,0.082552,48.929935,2.492610,0.825516,-272.401337,0.081450,0.000000
141.230011,7.943077,-272.401337,-0.001410,0.003220,0.081797,35.332573,1.799927,0.817969,-272.401337,0.080687,0.000000
141.690002,4.486343,-272.445831,-0.001410,0.003187,0.080947,19.956251,1.016620,0.809468,-272.445831,0.079915,0.000000
142.150009,1.356552,-272.490295,-0.001418,0.003158,0.080219,6.034245,0.307399,0.802186,-272.490295,0.079152,0.000000
142.610001,-1.688335,-272.490295,-0.001401,0.003124,0.079343,-7.510091,-0.382582,0.793428,-272.490295,0.078380,0.000000
143.070007,-4.100193,-272.534790,-0.001410,0.003097,0.078666,-18.238569,-0.929117,0.786660,-272.534790,0.077617,0.000000
143.530014,-0.048782,-272.534790,-0.001444,0.003063,0.077790,-0.216995,-0.011054,0.777902,-272.534790,0.076854,0.000000
143.990005,0.023834,-272.579254,-0.001427,0.003039,0.077192,0.106020,0.005401,0.771922,-272.579254,0.076082,0.000000
144.450012,-0.029419,-272.623749,-0.001462,0.003002,0.076247,-0.130862,-0.006666,0.762467,-272.623749,0.075319,0.000000
144.910004,-0.015640,-272.623749,-0.001509,0.002972,0.075492,-0.069571,-0.003544,0.754920,-272.623749,0.074547,0.000000
145.370010,-0.036491,-272.712708,-0.001544,0.002940,0.074686,-0.162322,-0.008269,0.746858,-272.712708,0.073783,0.000000
145.830002,-0.017876,-272.668243,-0.001587,0.002913,0.074001,-0.079515,-0.004051,0.740008,-272.668243,0.073020,0.000000
146.290009,-0.058090,-272.801666,-0.001621,0.002884,0.073246,-0.258398,-0.013163,0.732460,-272.801666,0.072249,0.000000
146.750000,-0.035378,-272.801666,-0.001651,0.002861,0.072665,-0.157367,-0.008017,0.726647,-272.801666,0.071485,0.000000
147.210007,-0.032021,-272.801666,-0.001690,0.002820,0.071633,-0.142435,-0.007256,0.716329,-272.801666,0.070714,0.000000
147.670013,-0.065536,-272.935120,-0.001703,0.002801,0.071139,-0.291521,-0.014851,0.711386,-272.935120,0.069951,0.000000
148.130005,-0.071495,-272.935120,-0.001759,0.002766,0.070254,-0.318026,-0.016201,0.702545,-272.935120,0.069179,0.000000
148.590012,-0.064796,-272.979584,-0.001772,0.002732,0.069387,-0.288229,-0.014683,0.693870,-272.979584,0.068416,0.000000
149.050003,-0.054367,-273.024078,-0.001802,0.002716,0.068996,-0.241837,-0.012320,0.689964,-273.024078,0.067653,0.000000
149.510010,-0.027557,-273.024078,-0.001850,0.002676,0.067965,-0.122581,-0.006245,0.679646,-273.024078,0.066881,0.000000
149.970001,-0.052132,-273.024078,-0.001867,0.002646,0.067210,-0.231893,-0.011813,0.672099,-273.024078,0.066118,0.000000
150.430008,-0.061066,-273.024078,-0.001901,0.002614,0.066386,-0.271634,-0.013838,0.663863,-273.024078,0.065345,0.000000
150.890015,-0.070381,-273.113037,-0.001944,0.002584,0.065632,-0.313071,-0.015949,0.656316,-273.113037,0.064582,0.000000
151.350006,-0.068520,-273.157532,-0.001979,0.002551,0.064791,-0.304790,-0.015527,0.647906,-273.157532,0.063819,0.000000
151.810013,-0.077454,-273.157532,-0.001996,0.002520,0.064010,-0.344531,-0.017551,0.640101,-273.157532,0.063047,0.000000
152.270004,-0.065536,-273.201996,-0.002039,0.002488,0.063187,-0.291521,-0.014851,0.631866,-273.201996,0.062284,0.000000
152.730011,-0.058464,-273.246490,-0.002070,0.002466,0.062631,-0.260061,-0.013248,0.626309,-273.246490,0.061513,0.000000
153.190002,-0.080803,-273.246490,-0.002091,0.002428,0.061677,-0.359429,-0.018310,0.616771,-273.246490,0.060749,0.000000
153.650009,-0.089371,-273.335449,-0.002143,0.002405,0.061097,-0.397541,-0.020252,0.610965,-273.335449,0.059986,0.000000
154.110001,-0.072243,-273.335449,-0.002164,0.002381,0.060480,-0.321352,-0.016370,0.604804,-273.335449,0.059215,0.000000
154.570007,-0.092346,-273.379913,-0.002190,0.002342,0.059483,-0.410776,-0.020926,0.594834,-273.379913,0.058451,0.000000
155.030014,-0.072983,-273.379913,-0.002225,0.002306,0.058564,-0.324644,-0.016538,0.585637,-273.379913,0.057680,0.000000
155.490005,-0.096817,-273.557861,-0.002255,0.002276,0.057810,-0.430664,-0.021939,0.578097,-273.557861,0.056916,0.000000
155.950012,-0.100914,-273.513367,-0.002289,0.002260,0.057393,-0.448888,-0.022867,0.573934,-273.513367,0.056144,0.000000
156.410004,-0.061813,-273.513367,-0.002315,0.002227,0.056561,-0.274960,-0.014007,0.565607,-273.513367,0.055381,0.000000
156.870010,-0.085274,-273.602325,-0.002354,0.002190,0.055615,-0.379317,-0.019323,0.556152,-273.602325,0.054618,0.000000
157.330002,-0.059204,-273.602325,-0.002402,0.002154,0.054714,-0.263353,-0.013416,0.547137,-273.602325,0.053846,0.000000
157.790009,-0.081177,-273.646820,-0.002423,0.002128,0.054054,-0.361092,-0.018395,0.540544,-273.646820,0.053083,0.000000
158.250000,-0.059952,-273.646820,-0.002445,0.002108,0.053534,-0.266679,-0.013585,0.535343,-273.646820,0.052311,0.000000
158.710007,-0.071121,-273.691284,-0.002483,0.002069,0.052563,-0.316363,-0.016116,0.525631,-273.691284,0.051548,0.000000
159.170013,-0.071121,-273.780243,-0.002505,0.002041,0.051852,-0.316363,-0.016116,0.518515,-273.780243,0.050785,0.000000
159.630005,-0.077827,-273.780243,-0.002552,0.002011,0.051089,-0.346194,-0.017636,0.510885,-273.780243,0.050013,0.000000
160.090012,-0.075966,-273.824738,-0.002578,0.001983,0.050360,-0.337913,-0.017214,0.503603,-273.824738,0.049250,0.000000
160.550003,-0.061440,-273.869202,-0.002608,0.001942,0.049319,-0.273297,-0.013922,0.493195,-273.869202,0.048478,0.000000
161.010010,-0.040215,-273.869202,-0.002634,0.001915,0.048652,-0.178883,-0.009113,0.486518,-273.869202,0.047715,0.000000
161.470001,-0.059952,-273.958191,-0.002669,0.001887,0.047932,-0.266679,-0.013585,0.479319,-273.958191,0.046952,0.000000
161.930008,-0.078568,-273.958191,-0.002712,0.001857,0.047169,-0.349486,-0.017804,0.471689,-273.958191,0.046180,0.000000
162.390015,-0.067772,-274.091614,-0.002729,0.001832,0.046544,-0.301465,-0.015357,0.465444,-274.091614,0.045416,0.000000
162.850006,-0.070381,-273.958191,-0.002759,0.001797,0.045651,-0.313071,-0.015949,0.456511,-273.958191,0.044645,0.000000
163.310013,-0.008934,-274.136108,-0.002798,0.001763,0.044793,-0.039741,-0.002024,0.447927,-274.136108,0.043882,0.000000
163.770004,-0.040962,-274.091614,-0.002833,0.001739,0.044168,-0.182209,-0.009282,0.441682,-274.091614,0.043119,0.000000
164.230011,-0.034630,-274.136108,-0.002863,0.001710,0.043439,-0.154041,-0.007847,0.434392,-274.136108,0.042347,0.000000
164.690002,-0.039841,-274.225067,-0.002897,0.001672,0.042477,-0.177220,-0.009028,0.424771,-274.225067,0.041584,0.000000
165.150009,-0.021225,-274.225067,-0.002923,0.001645,0.041783,-0.094413,-0.004810,0.417830,-274.225067,0.040812,0.000000
165.610001,-0.011543,-274.269531,-0.002936,0.001619,0.041133,-0.051347,-0.002616,0.411327,-274.269531,0.040049,0.000000
166.070007,-0.020477,-274.269531,-0.002988,0.001586,0.040283,-0.091088,-0.004640,0.402826,-274.269531,0.039277,0.000000
166.530014,-0.036118,-274.314026,-0.003014,0.001552,0.039416,-0.160659,-0.008184,0.394159,-274.314026,0.038514,0.000000
166.990005,-0.046547,-274.358521,-0.003053,0.001521,0.038635,-0.207051,-0.010548,0.386355,-274.358521,0.037751,0.000000
167.450012,-0.041336,-274.402985,-0.003083,0.001496,0.037994,-0.183872,-0.009367,0.379935,-274.402985,0.036978,0.000000
167.910004,-0.021225,-274.491943,-0.003104,0.001462,0.037143,-0.094413,-0.004810,0.371434,-274.491943,0.036215,0.000000
168.370010,-0.055115,-274.491943,-0.003143,0.001439,0.036562,-0.245163,-0.012489,0.365621,-274.491943,0.035444,0.000000
168.830002,-0.062187,-274.536438,-0.003182,0.001405,0.035686,-0.276622,-0.014092,0.356863,-274.536438,0.034680,0.000000
169.290009,-0.046547,-274.580902,-0.003212,0.001374,0.034888,-0.207051,-0.010548,0.348884,-274.580902,0.033917,0.000000
169.750015,-0.060699,-274.536438,-0.003247,0.001350,0.034299,-0.270005,-0.013755,0.342987,-274.536438,0.033146,0.000000
170.210007,-0.051018,-274.625397,-0.003264,0.001318,0.033483,-0.226938,-0.011561,0.334835,-274.625397,0.032382,0.000000
170.670013,-0.034630,-274.669861,-0.003316,0.001282,0.032556,-0.154041,-0.007847,0.325562,-274.669861,0.031611,0.000000
171.130005,-0.060326,-274.714355,-0.003324,0.001256,0.031905,-0.268342,-0.013670,0.319052,-274.714355,0.030848,0.000000
171.590012,-0.051758,-274.714355,-0.003367,0.001223,0.031056,-0.230230,-0.011728,0.310558,-274.714355,0.030085,0.000000
172.050003,-0.056229,-274.714355,-0.003389,0.001191,0.030249,-0.250117,-0.012742,0.302489,-274.714355,0.029312,0.000000
172.510010,-0.066284,-274.892273,-0.003432,0.001161,0.029478,-0.294847,-0.015020,0.294775,-274.892273,0.028549,0.000000
172.970001,-0.065163,-274.803314,-0.003466,0.001130,0.028705,-0.289858,-0.014766,0.287054,-274.803314,0.027777,0.000000
173.430008,-0.075966,-274.892273,-0.003479,0.001102,0.027995,-0.337913,-0.017214,0.279946,-274.892273,0.027014,0.000000
173.890015,-0.085274,-274.936768,-0.003531,0.001073,0.027266,-0.379317,-0.019323,0.272656,-274.936768,0.026242,0.000000
174.350006,-0.070747,-274.892273,-0.003548,0.001040,0.026416,-0.314700,-0.016032,0.264155,-274.892273,0.025479,0.000000
174.810013,-0.102776,-275.025726,-0.003579,0.001013,0.025722,-0.457169,-0.023289,0.257221,-275.025726,0.024716,0.000000
175.270004,-0.081177,-275.025726,-0.003609,0.000998,0.025358,-0.361092,-0.018395,0.253580,-275.025726,0.023944,0.000000
175.730011,-0.097191,-275.070190,-0.003639,0.000951,0.024161,-0.432327,-0.022024,0.241613,-275.070190,0.023181,0.000000
176.190002,-0.086761,-275.114685,-0.003682,0.000918,0.023311,-0.385934,-0.019660,0.233112,-275.114685,0.022410,0.000000
176.650009,-0.088623,-275.159149,-0.003721,0.000884,0.022461,-0.394215,-0.020082,0.224611,-275.159149,0.021646,0.000000
177.110016,-0.077454,-275.248138,-0.003734,0.000864,0.021949,-0.344531,-0.017551,0.219494,-275.248138,0.020883,0.000000
177.570007,-0.059204,-275.159149,-0.003768,0.000839,0.021317,-0.263353,-0.013416,0.213165,-275.159149,0.020111,0.000000
178.030014,-0.099052,-275.292603,-0.003807,0.000802,0.020380,-0.440607,-0.022446,0.203801,-275.292603,0.019348,0.000000
178.490005,-0.087509,-275.248138,-0.003842,0.000770,0.019556,-0.389260,-0.019830,0.195558,-275.248138,0.018576,0.000000
178.950012,-0.079315,-275.292603,-0.003863,0.000743,0.018862,-0.352812,-0.017973,0.188624,-275.292603,0.017813,0.000000
179.410004,-0.090111,-275.337097,-0.003898,0.000715,0.018152,-0.400833,-0.020419,0.181516,-275.337097,0.017050,0.000000
179.870010,-0.068886,-275.337097,-0.003919,0.000684,0.017370,-0.306419,-0.015610,0.173704,-275.337097,0.016278,0.000000
180.330002,-0.070007,-275.426056,-0.003958,0.000651,0.016529,-0.311408,-0.015864,0.165294,-275.426056,0.015515,0.000000
180.790009,-0.089745,-275.381561,-0.003988,0.000620,0.015758,-0.399204,-0.020336,0.157580,-275.381561,0.014743,0.000000
181.250015,-0.108360,-275.470520,-0.004027,0.000590,0.014977,-0.482011,-0.024555,0.149768,-275.470520,0.013980,0.000000
181.710007,-0.071869,-275.515015,-0.004066,0.000556,0.014118,-0.319689,-0.016286,0.141184,-275.515015,0.013208,0.000000
182.170013,-0.067024,-275.470520,-0.004087,0.000525,0.013347,-0.298139,-0.015188,0.133471,-275.470520,0.012445,0.000000
182.630005,-0.055855,-275.603973,-0.004100,0.000505,0.012826,-0.248455,-0.012657,0.128263,-275.603973,0.011682,0.000000
183.090012,-0.083038,-275.603973,-0.004148,0.000469,0.011925,-0.369373,-0.018817,0.119247,-275.603973,0.010910,0.000000
183.550003,-0.073357,-275.648468,-0.004165,0.000445,0.011292,-0.326307,-0.016623,0.112919,-275.648468,0.010147,0.000000
184.010010,-0.071495,-275.692932,-0.004212,0.000411,0.010450,-0.318026,-0.016201,0.104501,-275.692932,0.009375,0.000000
184.470001,-0.030159,-275.692932,-0.004243,0.000382,0.009696,-0.134154,-0.006834,0.096961,-275.692932,0.008611,0.000000
184.930008,-0.028297,-275.737427,-0.004268,0.000351,0.008924,-0.125873,-0.006412,0.089240,-275.737427,0.007848,0.000000
185.390015,-0.030907,-275.737427,-0.004303,0.000317,0.008057,-0.137480,-0.007004,0.080565,-275.737427,0.007077,0.000000
185.850006,-0.059578,-275.826385,-0.004333,0.000290,0.007371,-0.265016,-0.013501,0.073715,-275.826385,0.006314,0.000000
186.310013,-0.054741,-275.870850,-0.004385,0.000259,0.006591,-0.243500,-0.012404,0.065910,-275.870850,0.005542,0.000000
186.770004,-0.004845,-275.826385,-0.004402,0.000230,0.005845,-0.021550,-0.001098,0.058454,-275.826385,0.004779,0.000000
187.230011,-0.023834,-275.915344,-0.004424,0.000198,0.005038,-0.106020,-0.005401,0.050385,-275.915344,0.004016,0.000000
187.690002,-0.014153,-275.915344,-0.004462,0.000165,0.004189,-0.062954,-0.003207,0.041891,-275.915344,0.003244,0.000000
188.150009,-0.041702,-275.959808,-0.004493,0.000135,0.003426,-0.185501,-0.009450,0.034261,-275.959808,0.002481,0.000000
188.610016,-0.061440,-276.048767,-0.004523,0.000116,0.002948,-0.273297,-0.013922,0.029484,-276.048767,0.001709,0.000000
189.070007,-0.048782,-275.959808,-0.004540,0.000077,0.001943,-0.216995,-0.011054,0.019432,-275.959808,0.000945,0.000000
189.530014,-0.062935,-276.093262,-0.004596,0.000049,0.001249,-0.279948,-0.014261,0.012490,-276.093262,0.000182,0.000000
189.990005,-0.032021,-276.137756,-0.004609,0.000015,0.000373,-0.142435,-0.007256,0.003732,-276.137756,-0.000590,0.000000
190.400009,-0.039841,-276.137756,-0.004626,0.000004,0.000095,-0.177220,-0.009028,0.000954,-276.137756,-0.000017,0.000000