File: Data/compression 18/AutoNoHeating-17-18-reverse-1-1_09092024_171055.csv
Time (sec),S:Load (lbs),S:HL1 (DIM),S:LVDT (in),S:Position (in),Ch:Position (mm),Ch:Load (N),Ch:Stress (MPa),Ch:Strain (mm/mm),Ch:HL1 (DIM),Set Point (),Cycles ()
0.110000,-0.012291,-126.281418,-0.006791,-0.006801,-0.172752,-0.054673,-0.002785,-1.727517,-126.281418,-0.172621,0.000000
0.480000,-0.016754,-126.236938,-0.006804,-0.006728,-0.170887,-0.074526,-0.003797,-1.708873,-126.236938,-0.169933,0.000000
0.850000,-0.048035,-126.325897,-0.006648,-0.006505,-0.165215,-0.213669,-0.010885,-1.652152,-126.325897,-0.163758,0.000000
1.220000,-0.051384,-126.370384,-0.006390,-0.006255,-0.158876,-0.228567,-0.011644,-1.588763,-126.370384,-0.157601,0.000000
1.590000,-0.062561,-126.503822,-0.006148,-0.006012,-0.152692,-0.278285,-0.014177,-1.526925,-126.503822,-0.151443,0.000000
1.960000,-0.010796,-126.459343,-0.005902,-0.005768,-0.146509,-0.048021,-0.002446,-1.465095,-126.459343,-0.145269,0.000000
2.330000,0.013405,-126.548309,-0.005657,-0.005521,-0.140239,0.059628,0.003038,-1.402394,-126.548309,-0.139112,0.000000
2.700000,0.018990,-126.637268,-0.005407,-0.005287,-0.134290,0.084470,0.004303,-1.342903,-126.637268,-0.132937,0.000000
3.070000,-0.022713,-126.726227,-0.005170,-0.005044,-0.128107,-0.101031,-0.005147,-1.281066,-126.726227,-0.126780,0.000000
3.440000,0.003349,-126.726227,-0.004915,-0.004798,-0.121871,0.014898,0.000759,-1.218714,-126.726227,-0.120622,0.000000
3.810000,-0.019737,-126.815193,-0.004656,-0.004555,-0.115697,-0.087796,-0.004473,-1.156967,-126.815193,-0.114448,0.000000
4.180000,0.127350,-126.815193,-0.004406,-0.004313,-0.109557,0.566480,0.028858,-1.095568,-126.815193,-0.108395,0.000000
4.550000,0.131821,-126.815193,-0.004411,-0.000002,-0.000052,0.586368,0.029871,-0.000522,-126.815193,0.000139,0.000000
4.920000,0.117668,-126.948631,-0.004402,-0.000002,-0.000052,0.523414,0.026664,-0.000522,-126.948631,0.000503,0.000000
5.290000,0.153419,-127.037598,-0.004393,-0.000002,-0.000052,0.682444,0.034765,-0.000522,-127.037598,0.001119,0.000000
5.660000,0.192886,-127.082077,-0.004385,0.000027,0.000685,0.858001,0.043709,0.006851,-127.082077,0.001743,0.000000
6.030000,0.370880,-127.082077,-0.004372,0.000056,0.001413,1.649757,0.084043,0.014133,-127.082077,0.002359,0.000000
6.400000,0.571220,-127.126556,-0.004337,0.000082,0.002081,2.540915,0.129440,0.020809,-127.126556,0.002974,0.000000
6.770000,0.714584,-127.215523,-0.004320,0.000101,0.002559,3.178630,0.161927,0.025586,-127.215523,0.003590,0.000000
7.140000,1.019180,-127.260002,-0.004299,0.000129,0.003287,4.533540,0.230950,0.032868,-127.260002,0.004206,0.000000
7.510000,1.245583,-127.393440,-0.004281,0.000147,0.003746,5.540628,0.282253,0.037463,-127.393440,0.004822,0.000000
7.880001,1.679771,-127.393440,-0.004234,0.000177,0.004501,7.471996,0.380642,0.045010,-127.393440,0.005437,0.000000
8.250000,1.954208,-127.482407,-0.004234,0.000200,0.005082,8.692753,0.442830,0.050816,-127.482407,0.006053,0.000000
8.620001,2.377968,-127.482407,-0.004212,0.000227,0.005758,10.577729,0.538855,0.057583,-127.482407,0.006669,0.000000
8.990001,2.805084,-127.660332,-0.004191,0.000251,0.006383,12.477638,0.635641,0.063828,-127.660332,0.007293,0.000000
9.360001,3.057549,-127.615852,-0.004174,0.000269,0.006842,13.600656,0.692850,0.068423,-127.615852,0.007909,0.000000
9.730000,3.449661,-127.704811,-0.004165,0.000290,0.007371,15.344860,0.781704,0.073715,-127.704811,0.008525,0.000000
10.100000,3.949753,-127.660332,-0.004135,0.000319,0.008091,17.569378,0.895027,0.080913,-127.660332,0.009141,0.000000
10.470000,4.487831,-127.793770,-0.004109,0.000348,0.008837,19.962870,1.016957,0.088370,-127.793770,0.009756,0.000000
10.840000,4.822968,-127.882736,-0.004087,0.000370,0.009409,21.453630,1.092900,0.094092,-127.882736,0.010372,0.000000
11.210001,5.169647,-127.927216,-0.004066,0.000393,0.009982,22.995739,1.171459,0.099815,-127.927216,0.010988,0.000000
11.580001,5.600853,-127.971695,-0.004031,0.000415,0.010545,24.913837,1.269171,0.105455,-127.971695,0.011604,0.000000
11.950001,6.023125,-127.927216,-0.004027,0.000444,0.011274,26.792196,1.364860,0.112737,-127.927216,0.012227,0.000000
12.320001,6.168724,-128.060654,-0.004005,0.000456,0.011577,27.439856,1.397853,0.115772,-128.060654,0.012844,0.000000
12.690001,6.899689,-128.149612,-0.003975,0.000492,0.012497,30.691349,1.563492,0.124970,-128.149612,0.013459,0.000000
13.060000,7.219185,-128.238586,-0.003962,0.000516,0.013112,32.112537,1.635891,0.131124,-128.238586,0.014075,0.000000
13.430000,7.279884,-128.194107,-0.003941,0.000537,0.013642,32.382542,1.649645,0.136415,-128.194107,0.014691,0.000000
13.800000,7.817589,-128.283066,-0.003902,0.000568,0.014439,34.774372,1.771491,0.144394,-128.283066,0.015306,0.000000
14.170001,7.839554,-128.327545,-0.003889,0.000589,0.014969,34.872078,1.776468,0.149685,-128.327545,0.015922,0.000000
14.540001,7.954994,-128.372025,-0.003872,0.000608,0.015445,35.385582,1.802627,0.154454,-128.372025,0.016538,0.000000
14.910001,8.163895,-128.460983,-0.003842,0.000626,0.015905,36.314816,1.849965,0.159049,-128.460983,0.017154,0.000000
15.280001,8.604034,-128.549942,-0.003816,0.000657,0.016694,38.272655,1.949702,0.166944,-128.549942,0.017778,0.000000
15.650001,9.015137,-128.549942,-0.003794,0.000687,0.017448,40.101330,2.042859,0.174484,-128.549942,0.018394,0.000000
16.020000,8.781288,-128.594437,-0.003773,0.000703,0.017847,39.061119,1.989868,0.178473,-128.594437,0.019009,0.000000
16.390001,9.183449,-128.683395,-0.003738,0.000732,0.018593,40.850021,2.080999,0.185929,-128.683395,0.019625,0.000000
16.760000,9.201698,-128.772354,-0.003747,0.000750,0.019044,40.931198,2.085135,0.190441,-128.772354,0.020241,0.000000
17.130001,9.417671,-128.816833,-0.003699,0.000776,0.019703,41.891895,2.134075,0.197034,-128.816833,0.020857,0.000000
17.500000,9.418785,-128.861313,-0.003678,0.000792,0.020128,41.896847,2.134327,0.201281,-128.861313,0.021472,0.000000
17.870001,9.768074,-128.861313,-0.003635,0.000822,0.020891,43.450562,2.213477,0.208911,-128.861313,0.022088,0.000000
18.240002,10.037300,-128.950272,-0.003626,0.000855,0.021706,44.648140,2.274485,0.217064,-128.950272,0.022704,0.000000
18.610001,10.359772,-128.994751,-0.003604,0.000882,0.022409,46.082565,2.347558,0.224088,-128.994751,0.023329,0.000000
18.980001,10.443932,-129.128204,-0.003579,0.000904,0.022973,46.456928,2.366629,0.229728,-129.128204,0.023944,0.000000
19.350000,10.265938,-129.172684,-0.003557,0.000921,0.023397,45.665173,2.326295,0.233975,-129.172684,0.024559,0.000000
19.720001,10.650970,-129.217163,-0.003527,0.000953,0.024213,47.377884,2.413544,0.242127,-129.217163,0.025176,0.000000
20.090000,10.830826,-129.217163,-0.003501,0.000979,0.024863,48.177917,2.454300,0.248630,-129.217163,0.025791,0.000000
20.460001,10.754486,-129.261642,-0.003479,0.000997,0.025323,47.838345,2.437001,0.253232,-129.261642,0.026407,0.000000
20.830002,10.977165,-129.395081,-0.003462,0.001020,0.025895,48.828869,2.487461,0.258955,-129.395081,0.027023,0.000000
21.200001,11.175644,-129.439575,-0.003432,0.001042,0.026459,49.711746,2.532437,0.264587,-129.439575,0.027638,0.000000
21.570002,11.577805,-129.395081,-0.003393,0.001073,0.027266,51.500648,2.623568,0.272656,-129.395081,0.028254,0.000000
21.940001,11.605362,-129.573013,-0.003385,0.001095,0.027812,51.623230,2.629813,0.278122,-129.573013,0.028879,0.000000
22.310001,11.574455,-129.617493,-0.003367,0.001115,0.028332,51.485748,2.622809,0.283322,-129.617493,0.029494,0.000000
22.680000,11.964699,-129.661972,-0.003333,0.001143,0.029043,53.221638,2.711240,0.290430,-129.661972,0.030110,0.000000
23.050001,12.065239,-129.661972,-0.003311,0.001168,0.029659,53.668861,2.734022,0.296592,-129.661972,0.030726,0.000000
23.420002,12.464050,-129.750931,-0.003285,0.001199,0.030448,55.442863,2.824394,0.304480,-129.750931,0.031341,0.000000
23.790001,12.465538,-129.795410,-0.003264,0.001220,0.030995,55.449482,2.824731,0.309945,-129.795410,0.031957,0.000000
24.160002,12.581345,-129.884384,-0.003238,0.001245,0.031627,55.964615,2.850973,0.316273,-129.884384,0.032573,0.000000
24.530001,12.825249,-129.973343,-0.003208,0.001272,0.032304,57.049557,2.906243,0.323041,-129.973343,0.033189,0.000000
24.900002,12.650612,-130.017822,-0.003199,0.001286,0.032668,56.272732,2.866670,0.326682,-130.017822,0.033804,0.000000
25.270000,12.904564,-130.017822,-0.003169,0.001311,0.033293,57.402367,2.924216,0.332927,-130.017822,0.034429,0.000000
25.640001,13.091125,-130.106781,-0.003134,0.001333,0.033857,58.232235,2.966491,0.338566,-130.106781,0.035044,0.000000
26.010002,13.545418,-130.195740,-0.003122,0.001366,0.034689,60.253029,3.069436,0.346893,-130.195740,0.035661,0.000000
26.380001,13.661232,-130.240219,-0.003109,0.001389,0.035287,60.768196,3.095679,0.352873,-130.240219,0.036276,0.000000
26.750002,13.746872,-130.284698,-0.003061,0.001411,0.035834,61.149139,3.115086,0.358339,-130.284698,0.036891,0.000000
27.120001,13.901779,-130.329193,-0.003048,0.001435,0.036441,61.838203,3.150188,0.364410,-130.329193,0.037508,0.000000
27.490002,14.198189,-130.373672,-0.003027,0.001461,0.037100,63.156696,3.217355,0.370995,-130.373672,0.038123,0.000000
27.860001,14.521408,-130.462631,-0.003009,0.001488,0.037785,64.594452,3.290598,0.377846,-130.462631,0.038739,0.000000
28.230001,14.739616,-130.507111,-0.002984,0.001513,0.038418,65.565086,3.340045,0.384182,-130.507111,0.039355,0.000000
28.600002,14.804039,-130.640549,-0.002953,0.001535,0.038981,65.851654,3.354643,0.389814,-130.640549,0.039979,0.000000
28.970001,14.991714,-130.685028,-0.002928,0.001558,0.039563,66.686478,3.397171,0.395627,-130.685028,0.040595,0.000000
29.340002,15.417709,-130.640549,-0.002906,0.001586,0.040274,68.581398,3.493703,0.402736,-130.640549,0.041211,0.000000
29.710001,15.592728,-130.729523,-0.002880,0.001611,0.040907,69.359917,3.533363,0.409071,-130.729523,0.041826,0.000000
30.080002,15.731621,-130.818481,-0.002863,0.001635,0.041540,69.977745,3.564836,0.415400,-130.818481,0.042442,0.000000
30.450001,16.074944,-130.818481,-0.002824,0.001659,0.042147,71.504921,3.642634,0.421471,-130.818481,0.043058,0.000000
30.820002,15.928230,-130.907440,-0.002802,0.001677,0.042589,70.852310,3.609389,0.425892,-130.907440,0.043673,0.000000
31.190001,15.976639,-130.996399,-0.002794,0.001696,0.043075,71.067642,3.620358,0.430751,-130.996399,0.044289,0.000000
31.560001,16.871826,-130.996399,-0.002772,0.001729,0.043908,75.049629,3.823210,0.439078,-130.996399,0.044905,0.000000
31.930002,16.966408,-131.085358,-0.002755,0.001754,0.044541,75.470352,3.844643,0.445406,-131.085358,0.045529,0.000000
32.300003,17.197647,-131.174332,-0.002721,0.001778,0.045156,76.498955,3.897043,0.451561,-131.174332,0.046145,0.000000
32.670002,17.182755,-131.174332,-0.002690,0.001797,0.045650,76.432709,3.893668,0.456504,-131.174332,0.046761,0.000000
33.040001,17.618805,-131.174332,-0.002673,0.001823,0.046292,78.372360,3.992478,0.462923,-131.174332,0.047376,0.000000
33.410000,18.002350,-131.352249,-0.002660,0.001844,0.046831,80.078453,4.079391,0.468305,-131.352249,0.047992,0.000000
33.780003,18.109215,-131.352249,-0.002647,0.001868,0.047437,80.553810,4.103607,0.474368,-131.352249,0.048608,0.000000
34.150002,18.642456,-131.441208,-0.002617,0.001896,0.048157,82.925789,4.224441,0.481567,-131.441208,0.049223,0.000000
34.520000,18.886360,-131.485687,-0.002591,0.001921,0.048790,84.010727,4.279710,0.487903,-131.485687,0.049839,0.000000
34.890003,18.890823,-131.485687,-0.002578,0.001943,0.049363,84.030579,4.280722,0.493626,-131.485687,0.050464,0.000000
35.260002,19.723450,-131.530167,-0.002527,0.001975,0.050169,87.734283,4.469398,0.501688,-131.530167,0.051079,0.000000
35.630001,19.839630,-131.663620,-0.002522,0.001998,0.050750,88.251083,4.495724,0.507501,-131.663620,0.051696,0.000000
36.000000,19.586044,-131.708099,-0.002501,0.002012,0.051097,87.123077,4.438261,0.510968,-131.708099,0.052311,0.000000
36.370003,19.761436,-131.841537,-0.002483,0.002029,0.051531,87.903259,4.478005,0.515306,-131.841537,0.052926,0.000000
36.740002,20.925095,-131.797058,-0.002445,0.002065,0.052450,93.079468,4.741694,0.524496,-131.797058,0.053543,0.000000
37.110001,21.473602,-131.841537,-0.002440,0.002094,0.053187,95.519356,4.865988,0.531869,-131.841537,0.054158,0.000000
37.480003,21.863480,-131.930496,-0.002419,0.002119,0.053829,97.253616,4.954335,0.538288,-131.930496,0.054774,0.000000
37.850002,21.566322,-131.974976,-0.002393,0.002132,0.054158,95.931793,4.886999,0.541581,-131.974976,0.055390,0.000000
38.220001,22.293564,-132.063950,-0.002354,0.002162,0.054921,99.166725,5.051794,0.549211,-132.063950,0.056014,0.000000
38.590000,22.844307,-132.063950,-0.002333,0.002189,0.055606,101.616554,5.176594,0.556062,-132.063950,0.056630,0.000000
38.960003,22.771324,-132.152908,-0.002324,0.002211,0.056153,101.291908,5.160056,0.561527,-132.152908,0.057246,0.000000
39.330002,23.946899,-132.197388,-0.002307,0.002240,0.056898,106.521126,5.426445,0.568983,-132.197388,0.057861,0.000000
39.700001,23.898117,-132.241867,-0.002285,0.002261,0.057427,106.304131,5.415390,0.574275,-132.241867,0.058477,0.000000
40.070004,24.761650,-132.375305,-0.002251,0.002290,0.058173,110.145317,5.611070,0.581731,-132.375305,0.059093,0.000000
40.440002,24.886024,-132.375305,-0.002233,0.002310,0.058676,110.698563,5.639254,0.586765,-132.375305,0.059708,0.000000
40.810001,25.570068,-132.419785,-0.002207,0.002336,0.059327,113.741348,5.794261,0.593267,-132.419785,0.060324,0.000000
41.180000,25.742851,-132.464279,-0.002182,0.002360,0.059934,114.509918,5.833414,0.599338,-132.464279,0.060940,0.000000
41.550003,26.388550,-132.553238,-0.002164,0.002385,0.060576,117.382133,5.979731,0.605757,-132.553238,0.061564,0.000000
41.920002,26.517014,-132.642197,-0.002143,0.002402,0.061009,117.953568,6.008841,0.610095,-132.642197,0.062180,0.000000
42.290001,27.148186,-132.686676,-0.002121,0.002430,0.061720,120.761162,6.151867,0.617203,-132.686676,0.062796,0.000000
42.660004,27.706001,-132.686676,-0.002100,0.002452,0.062275,123.242447,6.278270,0.622751,-132.686676,0.063411,0.000000
43.030003,28.202744,-132.731155,-0.002078,0.002473,0.062804,125.452072,6.390833,0.628043,-132.731155,0.064028,0.000000
43.400002,29.043564,-132.775635,-0.002065,0.002502,0.063559,129.192230,6.581366,0.635590,-132.775635,0.064643,0.000000
43.770000,29.221931,-132.864594,-0.002052,0.002521,0.064028,129.985641,6.621785,0.640276,-132.864594,0.065258,0.000000
44.140003,30.450012,-132.953568,-0.002026,0.002553,0.064842,135.448425,6.900072,0.648421,-132.953568,0.065875,0.000000
44.510002,30.829834,-133.042526,-0.002009,0.002572,0.065336,137.137955,6.986140,0.653364,-133.042526,0.066490,0.000000
44.880001,32.261230,-132.998047,-0.001979,0.002607,0.066221,143.505127,7.310499,0.662213,-132.998047,0.067115,0.000000
45.250004,32.400497,-133.087006,-0.001957,0.002628,0.066741,144.124603,7.342058,0.667413,-133.087006,0.067730,0.000000
45.620003,32.800804,-133.175964,-0.001944,0.002651,0.067340,145.905258,7.432769,0.673401,-133.175964,0.068346,0.000000
45.990002,33.828178,-133.309418,-0.001910,0.002678,0.068017,150.475250,7.665575,0.680168,-133.309418,0.068962,0.000000
46.360001,34.200920,-133.309418,-0.001901,0.002698,0.068519,152.133286,7.750039,0.685195,-133.309418,0.069578,0.000000
46.730003,34.941940,-133.264923,-0.001893,0.002725,0.069205,155.429520,7.917957,0.692045,-133.264923,0.070193,0.000000
47.100002,35.954422,-133.353897,-0.001863,0.002749,0.069829,159.933258,8.147388,0.698290,-133.353897,0.070809,0.000000
47.470001,36.568092,-133.442856,-0.001850,0.002771,0.070393,162.662994,8.286448,0.703930,-133.442856,0.071425,0.000000
47.840004,37.471840,-133.531815,-0.001828,0.002798,0.071069,166.683075,8.491240,0.710690,-133.531815,0.072040,0.000000
48.210003,37.786865,-133.620773,-0.001802,0.002817,0.071555,168.084366,8.562626,0.715550,-133.620773,0.072665,0.000000
48.580002,38.956116,-133.620773,-0.001789,0.002846,0.072301,173.285461,8.827582,0.723006,-133.620773,0.073281,0.000000
48.950001,40.154411,-133.665253,-0.001772,0.002873,0.072968,178.615738,9.099119,0.729682,-133.665253,0.073896,0.000000
49.320004,40.813141,-133.709732,-0.001755,0.002893,0.073488,181.545914,9.248390,0.734883,-133.709732,0.074512,0.000000
49.690002,41.899719,-133.798706,-0.001729,0.002921,0.074182,186.379257,9.494613,0.741824,-133.798706,0.075128,0.000000
50.060001,42.325340,-133.843185,-0.001712,0.002938,0.074634,188.272522,9.591060,0.746336,-133.843185,0.075743,0.000000
50.430004,43.664024,-133.798706,-0.001699,0.002969,0.075414,194.227280,9.894409,0.754140,-133.798706,0.076359,0.000000
50.800003,44.920776,-133.932144,-0.001690,0.002995,0.076064,199.817596,10.179193,0.760643,-133.932144,0.076975,0.000000
51.170002,45.527000,-133.932144,-0.001669,0.003015,0.076584,202.514206,10.316566,0.765843,-133.932144,0.077590,0.000000
51.540001,46.794182,-134.021103,-0.001651,0.003042,0.077261,208.150909,10.603713,0.772611,-134.021103,0.078215,0.000000
51.910004,47.593300,-134.154541,-0.001638,0.003064,0.077825,211.705566,10.784797,0.778250,-134.154541,0.078831,0.000000
52.280003,47.642822,-134.154541,-0.001608,0.003080,0.078224,211.925858,10.796019,0.782239,-134.154541,0.079446,0.000000
52.650002,49.609695,-134.154541,-0.001613,0.003111,0.079022,220.674942,11.241717,0.790218,-134.154541,0.080062,0.000000
53.020004,51.189301,-134.199036,-0.001587,0.003139,0.079724,227.701385,11.599661,0.797243,-134.199036,0.080678,0.000000
53.390003,52.174225,-134.332474,-0.001569,0.003160,0.080270,232.082550,11.822848,0.802701,-134.332474,0.081293,0.000000
53.760002,53.162872,-134.287994,-0.001556,0.003183,0.080851,236.480270,12.046879,0.808514,-134.287994,0.081910,0.000000
54.130001,53.407150,-134.332474,-0.001531,0.003201,0.081303,237.566864,12.102233,0.813026,-134.332474,0.082525,0.000000
54.500004,55.861084,-134.421432,-0.001526,0.003237,0.082222,248.482513,12.658303,0.822215,-134.421432,0.083141,0.000000
54.870003,56.345535,-134.554871,-0.001496,0.003253,0.082620,250.637451,12.768081,0.826205,-134.554871,0.083765,0.000000
55.240002,58.293419,-134.599365,-0.001487,0.003281,0.083332,259.302063,13.209477,0.833320,-134.599365,0.084381,0.000000
55.610004,60.049156,-134.643845,-0.001492,0.003310,0.084086,267.112000,13.607333,0.840860,-134.643845,0.084997,0.000000
55.980003,60.245026,-134.732803,-0.001466,0.003323,0.084416,267.983246,13.651718,0.844160,-134.732803,0.085613,0.000000
56.350002,62.980469,-134.688324,-0.001457,0.003361,0.085378,280.151123,14.271579,0.853781,-134.688324,0.086228,0.000000
56.720001,63.762077,-134.777283,-0.001431,0.003380,0.085847,283.627899,14.448693,0.858467,-134.777283,0.086844,0.000000
57.090004,64.788338,-134.821762,-0.001436,0.003401,0.086393,288.192932,14.681248,0.863933,-134.821762,0.087460,0.000000
57.460003,65.676826,-134.910721,-0.001418,0.003420,0.086870,292.145111,14.882582,0.868702,-134.910721,0.088075,0.000000
57.830002,66.725044,-134.910721,-0.001393,0.003431,0.087147,296.807831,15.120111,0.871472,-134.910721,0.087425,0.000000
58.200005,65.569572,-134.955200,-0.001384,0.003430,0.087121,291.668030,14.858277,0.871215,-134.955200,294.500488,0.000000
58.570004,64.649818,-135.044174,-0.001393,0.003430,0.087121,287.576752,14.649858,0.871215,-135.044174,294.500488,0.000000
58.940002,65.553932,-135.133133,-0.001380,0.003442,0.087425,291.598450,14.854733,0.874250,-135.133133,294.500488,0.000000
59.310001,64.750725,-135.177612,-0.001380,0.003442,0.087425,288.025604,14.672724,0.874250,-135.177612,294.500488,0.000000
59.680004,65.828377,-135.222092,-0.001362,0.003459,0.087859,292.819244,14.916924,0.878588,-135.222092,294.500488,0.000000
60.050003,65.132790,-135.311050,-0.001345,0.003460,0.087894,289.725128,14.759300,0.878936,-135.311050,294.500488,0.000000
60.420002,66.017174,-135.311050,-0.001350,0.003476,0.088283,293.659058,14.959705,0.882834,-135.311050,294.500488,0.000000
60.790005,65.392326,-135.355530,-0.001350,0.003476,0.088293,290.879608,14.818112,0.882925,-135.355530,294.500488,0.000000
61.160004,64.897438,-135.488983,-0.001354,0.003477,0.088309,288.678223,14.705970,0.883092,-135.488983,294.500488,0.000000
61.530003,66.825218,-135.488983,-0.001345,0.003499,0.088882,297.253418,15.142811,0.888822,-135.488983,294.500488,0.000000
61.900002,66.070793,-135.577942,-0.001332,0.003453,0.087711,293.897552,14.971855,0.877112,-135.577942,294.500488,0.000000
62.270004,65.619469,-135.577942,-0.001328,0.003453,0.087711,291.889984,14.869585,0.877112,-135.577942,294.500488,0.000000
62.640003,65.296623,-135.666901,-0.001319,0.003479,0.088370,290.453888,14.796426,0.883705,-135.666901,294.500488,0.000000
63.010002,65.221031,-135.711380,-0.001324,0.003493,0.088735,290.117645,14.779297,0.887346,-135.711380,294.500488,0.000000
63.380005,65.175240,-135.800339,-0.001324,0.003499,0.088873,289.913940,14.768920,0.888731,-135.800339,294.500488,0.000000
63.750004,65.310036,-135.755859,-0.001306,0.003504,0.089012,290.513550,14.799465,0.890116,-135.755859,294.500488,0.000000
64.120003,65.225136,-135.889313,-0.001324,0.003505,0.089021,290.135895,14.780228,0.890207,-135.889313,294.500488,0.000000
64.490005,65.641823,-135.933792,-0.001332,0.003514,0.089264,291.989410,14.874649,0.892637,-135.933792,294.500488,0.000000
64.860001,65.510750,-135.978271,-0.001306,0.003513,0.089220,291.406372,14.844948,0.892198,-135.978271,294.500488,0.000000
65.230003,65.263115,-136.111710,-0.001293,0.003513,0.089220,290.304840,14.788833,0.892198,-136.111710,294.500488,0.000000
65.600006,65.043037,-136.111710,-0.001293,0.003513,0.089229,289.325867,14.738962,0.892289,-136.111710,294.500488,0.000000
65.970001,64.814400,-136.111710,-0.001302,0.003513,0.089229,288.308838,14.687153,0.892289,-136.111710,294.500488,0.000000
66.340004,65.905464,-136.200668,-0.001306,0.003519,0.089377,293.162140,14.934391,0.893765,-136.200668,294.500488,0.000000
66.710007,65.662666,-136.334122,-0.001302,0.003519,0.089377,292.082123,14.879373,0.893765,-136.334122,294.500488,0.000000
67.080002,65.467552,-136.334122,-0.001298,0.003519,0.089377,291.214203,14.835159,0.893765,-136.334122,294.500488,0.000000
67.450005,65.261253,-136.334122,-0.001289,0.003519,0.089377,290.296539,14.788412,0.893765,-136.334122,294.500488,0.000000
67.820000,65.035591,-136.378601,-0.001289,0.003519,0.089377,289.292755,14.737276,0.893765,-136.378601,294.500488,0.000000
68.190002,65.569954,-136.467560,-0.001298,0.003532,0.089714,291.669708,14.858364,0.897141,-136.467560,294.500488,0.000000
68.560005,65.437386,-136.512039,-0.001302,0.003532,0.089714,291.080017,14.828324,0.897141,-136.512039,294.500488,0.000000
68.930000,65.287697,-136.556519,-0.001298,0.003532,0.089714,290.414185,14.794403,0.897141,-136.556519,294.500488,0.000000
69.300003,65.160713,-136.645477,-0.001285,0.003532,0.089723,289.849335,14.765629,0.897232,-136.645477,294.500488,0.000000
69.670006,65.011757,-136.689957,-0.001285,0.003533,0.089732,289.186737,14.731875,0.897315,-136.689957,294.500488,0.000000
70.040001,64.917183,-136.734436,-0.001293,0.003536,0.089809,288.766052,14.710443,0.898095,-136.734436,294.500488,0.000000
70.410004,65.591179,-136.823410,-0.001276,0.003542,0.089975,291.764130,14.863173,0.899745,-136.823410,294.500488,0.000000
70.780006,65.539787,-136.867889,-0.001285,0.003542,0.089975,291.535522,14.851528,0.899745,-136.867889,294.500488,0.000000
71.150002,65.434029,-136.912369,-0.001281,0.003542,0.089975,291.065094,14.827562,0.899745,-136.912369,294.500488,0.000000
71.520004,65.295891,-137.001328,-0.001272,0.003543,0.089984,290.450623,14.796261,0.899836,-137.001328,294.500488,0.000000
71.890007,65.213966,-136.956848,-0.001285,0.003543,0.089992,290.086212,14.777697,0.899919,-136.956848,294.500488,0.000000
72.260002,65.117516,-137.045807,-0.001281,0.003543,0.090000,289.657166,14.755840,0.900003,-137.045807,294.500488,0.000000
72.630005,65.008415,-137.134766,-0.001276,0.003545,0.090052,289.171875,14.731118,0.900525,-137.134766,294.500488,0.000000
73.000000,65.208748,-137.268219,-0.001293,0.003547,0.090096,290.062988,14.776513,0.900964,-137.268219,294.500488,0.000000
73.370003,65.125710,-137.223740,-0.001268,0.003547,0.090105,289.693634,14.757697,0.901047,-137.223740,294.500488,0.000000
73.740005,65.043785,-137.223740,-0.001276,0.003548,0.090113,289.329193,14.739132,0.901130,-137.223740,294.500488,0.000000
74.110001,64.976021,-137.268219,-0.001285,0.003548,0.090113,289.027771,14.723777,0.901130,-137.268219,294.500488,0.000000
74.480003,64.916069,-137.446136,-0.001281,0.003548,0.090113,288.761108,14.710192,0.901130,-137.446136,294.500488,0.000000
74.850006,65.673836,-137.490616,-0.001281,0.003557,0.090356,292.131805,14.881904,0.903560,-137.490616,294.500488,0.000000
75.220001,65.607552,-137.490616,-0.001285,0.003557,0.090356,291.836975,14.866884,0.903560,-137.490616,294.500488,0.000000
75.590004,65.571434,-137.535095,-0.001272,0.003557,0.090356,291.676300,14.858700,0.903560,-137.535095,294.500488,0.000000
75.960007,65.524147,-137.624069,-0.001276,0.003557,0.090356,291.465973,14.847984,0.903560,-137.624069,294.500488,0.000000
76.330002,65.415413,-137.668549,-0.001268,0.003557,0.090356,290.982300,14.823344,0.903560,-137.668549,294.500488,0.000000
76.700005,65.320091,-137.757507,-0.001268,0.003557,0.090356,290.558289,14.801744,0.903560,-137.757507,294.500488,0.000000
77.070007,65.271675,-137.713028,-0.001272,0.003557,0.090356,290.342926,14.790773,0.903560,-137.713028,294.500488,0.000000
77.440002,65.185295,-137.757507,-0.001255,0.003558,0.090365,289.958679,14.771199,0.903651,-137.757507,294.500488,0.000000
77.810005,65.100761,-137.890945,-0.001272,0.003558,0.090365,289.582642,14.752044,0.903651,-137.890945,294.500488,0.000000
78.180000,65.028526,-137.935425,-0.001276,0.003557,0.090356,289.261322,14.735675,0.903560,-137.935425,294.500488,0.000000
78.550003,64.954796,-137.979904,-0.001272,0.003557,0.090356,288.933350,14.718967,0.903560,-137.979904,294.500488,0.000000
78.920006,64.860954,-138.068878,-0.001272,0.003557,0.090356,288.515930,14.697701,0.903560,-138.068878,294.500488,0.000000
79.290001,64.780891,-138.068878,-0.001263,0.003557,0.090356,288.159790,14.679560,0.903560,-138.068878,294.500488,0.000000
79.660004,64.716850,-138.113358,-0.001263,0.003557,0.090356,287.874939,14.665048,0.903560,-138.113358,294.500488,0.000000
80.030006,64.632683,-138.113358,-0.001259,0.003557,0.090356,287.500519,14.645975,0.903560,-138.113358,294.500488,0.000000
80.400002,64.554863,-138.246796,-0.001272,0.003558,0.090365,287.154358,14.628341,0.903651,-138.246796,294.500488,0.000000
80.770004,66.332939,-138.335754,-0.001250,0.003562,0.090478,295.063660,15.031260,0.904779,-138.335754,294.500488,0.000000
81.140007,66.210426,-138.291275,-0.001250,0.003562,0.090478,294.518677,15.003497,0.904779,-138.291275,294.500488,0.000000
81.510002,66.135948,-138.380234,-0.001250,0.003562,0.090478,294.187378,14.986620,0.904779,-138.380234,294.500488,0.000000
81.880005,66.041008,-138.424713,-0.001246,0.003562,0.090478,293.765076,14.965106,0.904779,-138.424713,294.500488,0.000000
82.250008,65.918861,-138.513687,-0.001255,0.003562,0.090478,293.221741,14.937428,0.904779,-138.513687,294.500488,0.000000
82.620003,65.875664,-138.602646,-0.001259,0.003562,0.090478,293.029602,14.927639,0.904779,-138.602646,294.500488,0.000000
82.990005,65.835823,-138.558167,-0.001259,0.003562,0.090478,292.852356,14.918611,0.904779,-138.558167,294.500488,0.000000
83.360001,65.763588,-138.691605,-0.001250,0.003562,0.090478,292.531036,14.902242,0.904779,-138.691605,294.500488,0.000000
83.730003,65.645164,-138.736084,-0.001250,0.003562,0.090478,292.004272,14.875406,0.904779,-138.736084,294.500488,0.000000
84.100006,65.580009,-138.825043,-0.001259,0.003562,0.090478,291.714447,14.860642,0.904779,-138.825043,294.500488,0.000000
84.470001,65.524513,-138.869522,-0.001246,0.003562,0.090478,291.467590,14.848067,0.904779,-138.869522,294.500488,0.000000
84.840004,65.474617,-138.914017,-0.001259,0.003562,0.090478,291.245636,14.836761,0.904779,-138.914017,294.500488,0.000000
85.210007,65.378929,-138.914017,-0.001250,0.003562,0.090478,290.820007,14.815078,0.904779,-138.914017,294.500488,0.000000
85.580002,65.308540,-138.958496,-0.001263,0.003562,0.090478,290.506897,14.799127,0.904779,-138.958496,294.500488,0.000000
85.950005,65.261253,-139.002975,-0.001255,0.003562,0.090478,290.296539,14.788412,0.904779,-139.002975,294.500488,0.000000
86.320007,65.215080,-139.091934,-0.001250,0.003562,0.090478,290.091156,14.777948,0.904779,-139.091934,294.500488,0.000000
86.690002,65.125710,-139.180893,-0.001250,0.003562,0.090478,289.693634,14.757697,0.904779,-139.180893,294.500488,0.000000
87.060005,65.060921,-139.136414,-0.001255,0.003562,0.090478,289.405426,14.743015,0.904779,-139.136414,294.500488,0.000000
87.430008,65.013252,-139.225372,-0.001250,0.003562,0.090478,289.193390,14.732214,0.904779,-139.225372,294.500488,0.000000
87.800003,64.946602,-139.358826,-0.001255,0.003562,0.090486,288.896912,14.717111,0.904862,-139.358826,294.500488,0.000000
88.170006,64.884041,-139.358826,-0.001250,0.003562,0.090486,288.618622,14.702934,0.904862,-139.358826,294.500488,0.000000
88.540001,65.779961,-139.403305,-0.001250,0.003581,0.090955,292.603882,14.905951,0.909548,-139.403305,294.500488,0.000000
88.910004,65.706230,-139.492264,-0.001246,0.003581,0.090955,292.275909,14.889245,0.909548,-139.492264,294.500488,0.000000
89.280006,65.636238,-139.447784,-0.001237,0.003581,0.090955,291.964569,14.873384,0.909548,-139.447784,294.500488,0.000000
89.650002,65.571068,-139.581223,-0.001250,0.003581,0.090955,291.674683,14.858616,0.909548,-139.581223,294.500488,0.000000
90.020004,65.554680,-139.714661,-0.001259,0.003581,0.090955,291.601776,14.854903,0.909548,-139.714661,294.500488,0.000000
90.390007,65.523781,-139.670181,-0.001246,0.003581,0.090955,291.464325,14.847900,0.909548,-139.670181,294.500488,0.000000
90.760002,65.462334,-139.714661,-0.001229,0.003581,0.090955,291.191010,14.833977,0.909548,-139.714661,294.500488,0.000000
91.130005,65.401268,-139.714661,-0.001237,0.003581,0.090955,290.919373,14.820139,0.909548,-139.714661,294.500488,0.000000
91.500008,65.367744,-139.803635,-0.001242,0.003581,0.090955,290.770264,14.812542,0.909548,-139.803635,294.500488,0.000000
91.870003,65.320839,-139.937073,-0.001246,0.003581,0.090955,290.561615,14.801914,0.909548,-139.937073,294.500488,0.000000
92.240005,65.273170,-139.981552,-0.001242,0.003581,0.090955,290.349548,14.791112,0.909548,-139.981552,294.500488,0.000000
92.610001,65.250084,-139.981552,-0.001246,0.003581,0.090955,290.246857,14.785880,0.909548,-139.981552,294.500488,0.000000
92.980003,65.202415,-140.026031,-0.001250,0.003581,0.090955,290.034821,14.775078,0.909548,-140.026031,294.500488,0.000000
93.350006,65.125343,-140.070511,-0.001255,0.003581,0.090963,289.691986,14.757614,0.909631,-140.070511,294.500488,0.000000
93.720001,65.088478,-140.203964,-0.001233,0.003581,0.090963,289.528015,14.749260,0.909631,-140.203964,294.500488,0.000000
94.090004,65.055336,-140.159470,-0.001220,0.003581,0.090963,289.380585,14.741750,0.909631,-140.159470,294.500488,0.000000
94.460007,65.008415,-140.248444,-0.001246,0.003581,0.090963,289.171875,14.731118,0.909631,-140.248444,294.500488,0.000000
94.830002,64.987190,-140.292923,-0.001242,0.003581,0.090963,289.077454,14.726308,0.909631,-140.292923,294.500488,0.000000
95.200005,64.939888,-140.292923,-0.001263,0.003581,0.090963,288.867035,14.715590,0.909631,-140.292923,294.500488,0.000000
95.570007,64.906761,-140.470840,-0.001237,0.003581,0.090963,288.719696,14.708082,0.909631,-140.470840,294.500488,0.000000
95.940002,64.837868,-140.470840,-0.001242,0.003581,0.090963,288.413239,14.692471,0.909631,-140.470840,294.500488,0.000000
96.310005,64.808815,-140.559799,-0.001246,0.003581,0.090963,288.283997,14.685887,0.909631,-140.559799,294.500488,0.000000
96.680008,64.766747,-140.515320,-0.001237,0.003581,0.090963,288.096863,14.676355,0.909631,-140.515320,294.500488,0.000000
97.050003,64.725410,-140.648773,-0.001246,0.003581,0.090963,287.912994,14.666987,0.909631,-140.648773,294.500488,0.000000
97.420006,66.005623,-140.648773,-0.001242,0.003588,0.091136,293.607666,14.957088,0.911365,-140.648773,294.500488,0.000000
97.790001,65.884972,-140.693253,-0.001246,0.003588,0.091128,293.070984,14.929749,0.911282,-140.693253,294.500488,0.000000
98.160004,65.839180,-140.782211,-0.001229,0.003588,0.091128,292.867310,14.919372,0.911282,-140.782211,294.500488,0.000000
98.530006,65.822044,-140.782211,-0.001237,0.003588,0.091128,292.791077,14.915488,0.911282,-140.782211,294.500488,0.000000
98.900002,65.830238,-140.826691,-0.001242,0.003588,0.091128,292.827515,14.917345,0.911282,-140.826691,294.500488,0.000000
99.270004,65.777367,-140.915649,-0.001237,0.003588,0.091128,292.592346,14.905364,0.911282,-140.915649,294.500488,0.000000
99.640007,65.728951,-141.004608,-0.001233,0.003588,0.091128,292.376984,14.894393,0.911282,-141.004608,294.500488,0.000000
100.010002,65.661552,-140.960129,-0.001224,0.003588,0.091128,292.077179,14.879121,0.911282,-140.960129,294.500488,0.000000
100.380005,65.614265,-141.138062,-0.001233,0.003588,0.091128,291.866821,14.868405,0.911282,-141.138062,294.500488,0.000000
100.750008,65.573677,-141.049103,-0.001242,0.003588,0.091128,291.686279,14.859208,0.911282,-141.049103,294.500488,0.000000
101.120003,65.548347,-141.271500,-0.001237,0.003588,0.091128,291.573608,14.853468,0.911282,-141.271500,294.500488,0.000000
101.490005,65.528236,-141.227020,-0.001229,0.003588,0.091128,291.484161,14.848910,0.911282,-141.227020,294.500488,0.000000
101.860008,65.478722,-141.227020,-0.001233,0.003588,0.091128,291.263885,14.837690,0.911282,-141.227020,294.500488,0.000000
102.230003,65.437386,-141.315979,-0.001233,0.003588,0.091128,291.080017,14.828324,0.911282,-141.315979,294.500488,0.000000
102.600006,65.394188,-141.360458,-0.001255,0.003588,0.091136,290.887878,14.818535,0.911365,-141.360458,294.500488,0.000000
102.970001,65.346153,-141.449417,-0.001233,0.003588,0.091136,290.674194,14.807650,0.911365,-141.449417,294.500488,0.000000
103.340004,65.310036,-141.493912,-0.001224,0.003588,0.091136,290.513550,14.799465,0.911365,-141.493912,294.500488,0.000000
103.710007,65.295509,-141.538391,-0.001229,0.003588,0.091136,290.448944,14.796174,0.911365,-141.538391,294.500488,0.000000
104.080002,65.245613,-141.582870,-0.001233,0.003590,0.091189,290.226990,14.784867,0.911887,-141.582870,294.500488,0.000000
104.450005,65.218437,-141.627350,-0.001233,0.003590,0.091189,290.106110,14.778709,0.911887,-141.627350,294.500488,0.000000
104.820007,65.176720,-141.671829,-0.001233,0.003590,0.091189,289.920532,14.769256,0.911887,-141.671829,294.500488,0.000000
105.190002,65.141716,-141.805267,-0.001229,0.003590,0.091189,289.764832,14.761324,0.911887,-141.805267,294.500488,0.000000
105.560005,65.085121,-141.805267,-0.001237,0.003590,0.091189,289.513092,14.748499,0.911887,-141.805267,294.500488,0.000000
105.930008,65.276146,-141.849747,-0.001233,0.003596,0.091336,290.362793,14.791786,0.913363,-141.849747,294.500488,0.000000
106.300003,65.307060,-141.894241,-0.001242,0.003596,0.091336,290.500305,14.798792,0.913363,-141.894241,294.500488,0.000000
106.670006,65.279869,-141.894241,-0.001246,0.003596,0.091336,290.379364,14.792629,0.913363,-141.894241,294.500488,0.000000
107.040009,65.285454,-141.983200,-0.001237,0.003596,0.091336,290.404205,14.793895,0.913363,-141.983200,294.500488,0.000000
107.410004,65.268700,-142.072159,-0.001229,0.003596,0.091336,290.329681,14.790098,0.913363,-142.072159,294.500488,0.000000
107.780006,65.245247,-142.027679,-0.001220,0.003596,0.091336,290.225342,14.784784,0.913363,-142.027679,294.500488,0.000000
108.150002,65.213966,-142.116638,-0.001233,0.003596,0.091336,290.086212,14.777697,0.913363,-142.116638,294.500488,0.000000
108.520004,65.210609,-142.250076,-0.001233,0.003596,0.091336,290.071289,14.776936,0.913363,-142.250076,294.500488,0.000000
108.890007,65.183434,-142.250076,-0.001224,0.003596,0.091336,289.950378,14.770777,0.913363,-142.250076,294.500488,0.000000
109.260002,65.139854,-142.383530,-0.001224,0.003596,0.091336,289.756531,14.760902,0.913363,-142.383530,294.500488,0.000000
109.630005,65.105232,-142.339050,-0.001224,0.003596,0.091336,289.602539,14.753057,0.913363,-142.339050,294.500488,0.000000
110.000008,65.084373,-142.339050,-0.001224,0.003596,0.091336,289.509766,14.748329,0.913363,-142.339050,294.500488,0.000000
110.370003,65.062035,-142.428009,-0.001229,0.003596,0.091345,289.410370,14.743267,0.913447,-142.428009,294.500488,0.000000
110.740005,65.035591,-142.516968,-0.001233,0.003596,0.091345,289.292755,14.737276,0.913447,-142.516968,294.500488,0.000000
111.110008,65.015862,-142.605927,-0.001220,0.003596,0.091345,289.204987,14.732804,0.913447,-142.605927,294.500488,0.000000
111.480003,64.999840,-142.561447,-0.001224,0.003596,0.091345,289.133728,14.729175,0.913447,-142.561447,294.500488,0.000000
111.850006,65.144707,-142.650406,-0.001233,0.003600,0.091449,289.778137,14.762002,0.914491,-142.650406,294.500488,0.000000
112.220009,65.205391,-142.739365,-0.001229,0.003600,0.091449,290.048065,14.775753,0.914491,-142.739365,294.500488,0.000000
112.590004,65.210609,-142.828339,-0.001229,0.003600,0.091449,290.071289,14.776936,0.914491,-142.828339,294.500488,0.000000
112.960007,65.206520,-142.872818,-0.001220,0.003600,0.091449,290.053101,14.776009,0.914491,-142.872818,294.500488,0.000000
113.330002,65.195335,-142.872818,-0.001224,0.003600,0.091449,290.003326,14.773474,0.914491,-142.872818,294.500488,0.000000
113.700005,65.159218,-142.961777,-0.001229,0.003600,0.091449,289.842682,14.765290,0.914491,-142.961777,294.500488,0.000000
114.070007,65.150291,-142.961777,-0.001224,0.003600,0.091449,289.802979,14.763268,0.914491,-142.961777,294.500488,0.000000
114.440002,65.129433,-143.095215,-0.001224,0.003600,0.091449,289.710175,14.758540,0.914491,-143.095215,294.500488,0.000000
114.810005,65.103371,-143.095215,-0.001224,0.003600,0.091449,289.594269,14.752634,0.914491,-143.095215,294.500488,0.000000
115.180008,65.087730,-143.139694,-0.001224,0.003600,0.091449,289.524689,14.749090,0.914491,-143.139694,294.500488,0.000000
115.550003,65.056450,-143.184189,-0.001224,0.003600,0.091449,289.385529,14.742002,0.914491,-143.184189,294.500488,0.000000
115.920006,65.035225,-143.228668,-0.001233,0.003600,0.091449,289.291138,14.737193,0.914491,-143.228668,294.500488,0.000000
116.290009,65.030388,-143.317627,-0.001229,0.003600,0.091449,289.269623,14.736096,0.914491,-143.317627,294.500488,0.000000
116.660004,65.011757,-143.362106,-0.001229,0.003600,0.091449,289.186737,14.731875,0.914491,-143.362106,294.500488,0.000000
117.030006,64.981972,-143.362106,-0.001220,0.003600,0.091449,289.054260,14.725125,0.914491,-143.362106,294.500488,0.000000
117.400009,65.495476,-143.495544,-0.001212,0.003610,0.091683,291.338440,14.841487,0.916830,-143.495544,294.500488,0.000000
117.770004,65.627296,-143.540024,-0.001216,0.003609,0.091675,291.924805,14.871358,0.916747,-143.540024,294.500488,0.000000
118.140007,65.656715,-143.584503,-0.001224,0.003609,0.091675,292.055664,14.878025,0.916747,-143.584503,294.500488,0.000000
118.510002,65.693199,-143.673477,-0.001242,0.003606,0.091596,292.217957,14.886292,0.915960,-143.673477,0.091675,0.000000
118.880005,65.638100,-143.584503,-0.001207,0.003597,0.091354,291.972839,14.873806,0.913537,-143.584503,0.091111,0.000000
119.250008,65.570702,-143.717957,-0.001212,0.003579,0.090911,291.673035,14.858533,0.909109,-143.717957,0.090495,0.000000
119.620003,65.430305,-143.717957,-0.001237,0.003561,0.090461,291.048523,14.826719,0.904605,-143.717957,0.089879,0.000000
119.990005,65.351738,-143.806915,-0.001220,0.003534,0.089766,290.699036,14.808915,0.897664,-143.806915,0.089264,0.000000
120.360008,65.348763,-143.895874,-0.001212,0.003519,0.089385,290.685822,14.808242,0.893848,-143.895874,0.088648,0.000000
120.730003,65.327538,-143.895874,-0.001216,0.003484,0.088492,290.591400,14.803432,0.884916,-143.895874,0.088023,0.000000
121.100006,65.262749,-143.940353,-0.001220,0.003461,0.087910,290.303192,14.788750,0.879102,-143.940353,0.087408,0.000000
121.470009,65.267952,-144.073807,-0.001220,0.003443,0.087460,290.326355,14.789929,0.874598,-144.073807,0.086792,0.000000
121.840004,65.175240,-144.118286,-0.001216,0.003415,0.086731,289.913940,14.768920,0.867309,-144.118286,0.086176,0.000000
122.210007,65.126823,-144.118286,-0.001216,0.003396,0.086254,289.698578,14.757949,0.862540,-144.118286,0.085561,0.000000
122.580009,64.851265,-144.118286,-0.001216,0.003373,0.085673,288.472839,14.695507,0.856734,-144.118286,0.084944,0.000000
122.950005,64.176537,-144.251724,-0.001229,0.003350,0.085084,285.471497,14.542611,0.850837,-144.251724,0.084329,0.000000
123.320007,63.111916,-144.296204,-0.001216,0.003324,0.084424,280.735809,14.301365,0.844244,-144.296204,0.083714,0.000000
123.690002,62.037621,-144.385162,-0.001203,0.003303,0.083887,275.957123,14.057925,0.838869,-144.385162,0.083097,0.000000
124.060005,61.212074,-144.385162,-0.001203,0.003292,0.083609,272.284912,13.870854,0.836091,-144.385162,0.082473,0.000000
124.430008,59.340157,-144.385162,-0.001194,0.003265,0.082933,263.958191,13.446671,0.829331,-144.385162,0.081857,0.000000
124.800003,57.402328,-144.474136,-0.001190,0.003237,0.082222,255.338303,13.007554,0.822215,-144.474136,0.081242,0.000000
125.170006,55.280930,-144.518616,-0.001190,0.003213,0.081606,245.901855,12.526837,0.816061,-144.518616,0.080626,0.000000
125.540009,52.681396,-144.652054,-0.001203,0.003184,0.080877,234.338562,11.937775,0.808771,-144.652054,0.080010,0.000000
125.910004,52.303810,-144.652054,-0.001181,0.003184,0.080869,232.658966,11.852212,0.808688,-144.652054,0.079394,0.000000
126.280006,48.199150,-144.696533,-0.001181,0.003143,0.079837,214.400528,10.922084,0.798371,-144.696533,0.078779,0.000000
126.650009,45.381401,-144.696533,-0.001190,0.003115,0.079117,201.866547,10.283573,0.791172,-144.696533,0.078163,0.000000
127.020004,42.604622,-144.829971,-0.001190,0.003091,0.078510,189.514816,9.654346,0.785101,-144.829971,0.077547,0.000000
127.390007,40.624344,-144.918945,-0.001199,0.003074,0.078085,180.706100,9.205608,0.780847,-144.918945,0.076923,0.000000
127.760010,37.939537,-144.874451,-0.001186,0.003049,0.077434,168.763489,8.597222,0.774344,-144.874451,0.076307,0.000000
128.130005,35.652054,-144.918945,-0.001199,0.003028,0.076905,158.588257,8.078871,0.769053,-144.918945,0.075691,0.000000
128.500000,32.616104,-144.963425,-0.001203,0.002999,0.076169,145.083679,7.390915,0.761687,-144.963425,0.075076,0.000000
128.870010,29.771919,-145.096863,-0.001194,0.002972,0.075483,132.432114,6.746414,0.754829,-145.096863,0.074460,0.000000
129.240005,27.832603,-145.141342,-0.001194,0.002954,0.075041,123.805603,6.306958,0.750408,-145.141342,0.073844,0.000000
129.610001,25.100510,-145.185822,-0.001190,0.002931,0.074451,111.652641,5.687857,0.744512,-145.185822,0.073229,0.000000
129.980011,22.390015,-145.185822,-0.001190,0.002906,0.073818,99.595757,5.073650,0.738183,-145.185822,0.072612,0.000000
130.350006,20.077209,-145.274780,-0.001199,0.002885,0.073272,89.307892,4.549561,0.732718,-145.274780,0.071997,0.000000
130.720001,17.016304,-145.274780,-0.001207,0.002854,0.072483,75.692299,3.855950,0.724830,-145.274780,0.071373,0.000000
131.090012,14.665146,-145.408234,-0.001186,0.002832,0.071927,65.233826,3.323170,0.719274,-145.408234,0.070757,0.000000
131.460007,12.809616,-145.408234,-0.001186,0.002818,0.071572,56.980019,2.902700,0.715724,-145.408234,0.070141,0.000000
131.830002,8.812943,-145.541672,-0.001186,0.002775,0.070497,39.201927,1.997041,0.704967,-145.541672,0.069525,0.000000
132.200012,6.132233,-145.497192,-0.001199,0.002751,0.069872,27.277533,1.389584,0.698722,-145.497192,0.068910,0.000000
132.570007,2.889236,-145.541672,-0.001203,0.002723,0.069161,12.851966,0.654710,0.691614,-145.541672,0.068294,0.000000
132.940002,1.013969,-145.630630,-0.001199,0.002705,0.068710,4.510361,0.229769,0.687102,-145.630630,0.067678,0.000000
133.310013,-0.884010,-145.719589,-0.001194,0.002686,0.068233,-3.932274,-0.200320,0.682333,-145.719589,0.067062,0.000000
133.680008,-3.436626,-145.719589,-0.001186,0.002660,0.067566,-15.286878,-0.778751,0.675657,-145.719589,0.066447,0.000000
134.050003,-0.264015,-145.719589,-0.001220,0.002636,0.066959,-1.174398,-0.059827,0.669586,-145.719589,0.065822,0.000000
134.420013,-0.100540,-145.853043,-0.001233,0.002613,0.066369,-0.447225,-0.022783,0.663689,-145.853043,0.065207,0.000000
134.790009,-0.068520,-145.897522,-0.001224,0.002583,0.065614,-0.304790,-0.015527,0.656142,-145.897522,0.064591,0.000000
135.160004,-0.055855,-145.897522,-0.001233,0.002561,0.065050,-0.248455,-0.012657,0.650502,-145.897522,0.063975,0.000000
135.530014,-0.028297,-145.897522,-0.001268,0.002541,0.064539,-0.125873,-0.006412,0.645385,-145.897522,0.063359,0.000000
135.900009,-0.022713,-145.986481,-0.001302,0.002518,0.063958,-0.101031,-0.005147,0.639579,-145.986481,0.062744,0.000000
136.270004,-0.084160,-146.119919,-0.001324,0.002490,0.063246,-0.374362,-0.019071,0.632464,-146.119919,0.062128,0.000000
136.639999,-0.049522,-146.164398,-0.001358,0.002461,0.062501,-0.220287,-0.011222,0.625007,-146.164398,0.061512,0.000000
137.010010,-0.020477,-146.208893,-0.001384,0.002434,0.061833,-0.091088,-0.004640,0.618331,-146.208893,0.060888,0.000000
137.380005,-0.002235,-146.297852,-0.001401,0.002420,0.061469,-0.009944,-0.000507,0.614690,-146.297852,0.060272,0.000000
137.750000,-0.010429,-146.297852,-0.001444,0.002396,0.060862,-0.046392,-0.002363,0.608619,-146.297852,0.059657,0.000000
138.120010,-0.053993,-146.342331,-0.001483,0.002365,0.060064,-0.240174,-0.012235,0.600640,-146.342331,0.059041,0.000000
138.490005,-0.018250,-146.431290,-0.001505,0.002336,0.059336,-0.081178,-0.004135,0.593358,-146.431290,0.058425,0.000000
138.860001,-0.048409,-146.431290,-0.001513,0.002311,0.058702,-0.215332,-0.010970,0.587022,-146.431290,0.057809,0.000000
139.230011,-0.060699,-146.520248,-0.001556,0.002292,0.058217,-0.270005,-0.013755,0.582170,-146.520248,0.057194,0.000000
139.600006,-0.036865,-146.564728,-0.001552,0.002289,0.058130,-0.163985,-0.008354,0.581299,-146.564728,0.056578,0.000000
139.970001,-0.037979,-146.609207,-0.001604,0.002243,0.056977,-0.168940,-0.008606,0.569771,-146.609207,0.055962,0.000000
140.340012,-0.026436,-146.698181,-0.001643,0.002216,0.056283,-0.117593,-0.005990,0.562829,-146.698181,0.055337,0.000000
140.710007,-0.013031,-146.742661,-0.001656,0.002198,0.055832,-0.057965,-0.002953,0.558317,-146.742661,0.054722,0.000000
141.080002,-0.053993,-146.787140,-0.001677,0.002176,0.055259,-0.240174,-0.012235,0.552595,-146.787140,0.054106,0.000000
141.450012,-0.038353,-146.831619,-0.001699,0.002153,0.054679,-0.170603,-0.008691,0.546789,-146.831619,0.053490,0.000000
141.820007,-0.068520,-146.876099,-0.001738,0.002123,0.053924,-0.304790,-0.015527,0.539242,-146.876099,0.052875,0.000000
142.190002,-0.069260,-146.965057,-0.001746,0.002111,0.053621,-0.308082,-0.015694,0.536206,-146.965057,0.052259,0.000000
142.560013,-0.037239,-147.009537,-0.001781,0.002073,0.052649,-0.165648,-0.008438,0.526494,-147.009537,0.051643,0.000000
142.930008,-0.043571,-147.009537,-0.001802,0.002046,0.051973,-0.193816,-0.009873,0.519727,-147.009537,0.051027,0.000000
143.300003,-0.056976,-147.054031,-0.001837,0.002028,0.051513,-0.253443,-0.012911,0.515132,-147.054031,0.050412,0.000000
143.670013,-0.045433,-147.098511,-0.001858,0.002003,0.050880,-0.202096,-0.010295,0.508803,-147.098511,0.049787,0.000000
144.040009,-0.047295,-147.187469,-0.001893,0.001983,0.050360,-0.210377,-0.010717,0.503595,-147.187469,0.049172,0.000000
144.410004,-0.031281,-147.187469,-0.001910,0.001950,0.049536,-0.139143,-0.007088,0.495359,-147.187469,0.048556,0.000000
144.780014,-0.067398,-147.231949,-0.001944,0.001925,0.048903,-0.299802,-0.015273,0.489031,-147.231949,0.047940,0.000000
145.150009,-0.082298,-147.320908,-0.001966,0.001903,0.048339,-0.366081,-0.018649,0.483392,-147.320908,0.047325,0.000000
145.520004,-0.070747,-147.365387,-0.001992,0.001901,0.048296,-0.314700,-0.016032,0.482960,-147.365387,0.046709,0.000000
145.889999,-0.062561,-147.498840,-0.002018,0.001857,0.047177,-0.278285,-0.014177,0.471772,-147.498840,0.046093,0.000000
146.260010,-0.057716,-147.498840,-0.002035,0.001832,0.046535,-0.256735,-0.013079,0.465353,-147.498840,0.045477,0.000000
146.630005,-0.100914,-147.454346,-0.002070,0.001804,0.045833,-0.448888,-0.022867,0.458328,-147.454346,0.044862,0.000000
147.000000,-0.086388,-147.587799,-0.002095,0.001781,0.045226,-0.384271,-0.019576,0.452257,-147.587799,0.044237,0.000000
147.370010,-0.061813,-147.632278,-0.002130,0.001754,0.044549,-0.274960,-0.014007,0.445490,-147.632278,0.043622,0.000000
147.740005,-0.083786,-147.721237,-0.002151,0.001732,0.044003,-0.372699,-0.018986,0.440032,-147.721237,0.043005,0.000000
148.110001,-0.058838,-147.721237,-0.002177,0.001704,0.043292,-0.261724,-0.013333,0.432916,-147.721237,0.042390,0.000000
148.480011,-0.134796,-147.765717,-0.002195,0.001685,0.042789,-0.599603,-0.030545,0.427890,-147.765717,0.041774,0.000000
148.850006,-0.096817,-147.765717,-0.002229,0.001658,0.042121,-0.430664,-0.021939,0.421213,-147.765717,0.041158,0.000000
149.220001,-0.084526,-147.899155,-0.002259,0.001650,0.041913,-0.375991,-0.019154,0.419132,-147.899155,0.040543,0.000000
149.590012,-0.084526,-147.988129,-0.002264,0.001621,0.041167,-0.375991,-0.019154,0.411668,-147.988129,0.039927,0.000000
149.960007,-0.102028,-147.988129,-0.002285,0.001593,0.040456,-0.453843,-0.023120,0.404560,-147.988129,0.039311,0.000000
150.330002,-0.061440,-147.988129,-0.002324,0.001562,0.039684,-0.273297,-0.013922,0.396839,-147.988129,0.038687,0.000000
150.700012,-0.072983,-148.032608,-0.002354,0.001537,0.039043,-0.324644,-0.016538,0.390427,-148.032608,0.038072,0.000000
151.000000,-0.024948,-148.166046,-0.002376,0.001522,0.038652,-0.110975,-0.005653,0.386521,-148.166046,0.038514,0.000000