File: Data/compression 18/AutoNoHeating-17-18-reverse-2-4_09092024_174029.csv
Time (sec),S:Load (lbs),S:HL1 (DIM),S:LVDT (in),S:Position (in),Ch:Position (mm),Ch:Load (N),Ch:Stress (MPa),Ch:Strain (mm/mm),Ch:HL1 (DIM),Set Point (),Cycles ()
0.110000,-0.071869,-298.778534,-0.009291,-0.004631,-0.117622,-0.319689,-0.016286,-1.176217,-298.778534,-0.117370,0.000000
0.490000,-0.027557,-298.778534,-0.009287,-0.004591,-0.116624,-0.122581,-0.006245,-1.166240,-298.778534,-0.115896,0.000000
0.870000,-0.055855,-298.823029,-0.009179,-0.004360,-0.110753,-0.248455,-0.012657,-1.107528,-298.823029,-0.109565,0.000000
1.250000,-0.064423,-298.823029,-0.008921,-0.004109,-0.104362,-0.286566,-0.014598,-1.043617,-298.823029,-0.103235,0.000000
1.630000,-0.021225,-298.823029,-0.008679,-0.003857,-0.097970,-0.094413,-0.004810,-0.979705,-298.823029,-0.096903,0.000000
2.010000,-0.002235,-298.867523,-0.008416,-0.003616,-0.091839,-0.009944,-0.000507,-0.918390,-298.867523,-0.090573,0.000000
2.390000,-0.031281,-298.911987,-0.008157,-0.003360,-0.085352,-0.139143,-0.007088,-0.853524,-298.911987,-0.084242,0.000000
2.770000,-0.040588,-299.000946,-0.007899,-0.003119,-0.079221,-0.180546,-0.009197,-0.792209,-299.000946,-0.077911,0.000000
3.150000,-0.055855,-299.000946,-0.007649,-0.002867,-0.072821,-0.248455,-0.012657,-0.728206,-299.000946,-0.071581,0.000000
3.530000,-0.016754,-299.045441,-0.007411,-0.002620,-0.066560,-0.074526,-0.003797,-0.665596,-299.045441,-0.065250,0.000000
3.910000,0.001114,-299.045441,-0.007140,-0.002371,-0.060211,0.004955,0.000252,-0.602109,-299.045441,-0.058919,0.000000
4.290000,-0.017128,-299.045441,-0.006873,-0.002123,-0.053932,-0.076189,-0.003881,-0.539325,-299.045441,-0.052588,0.000000
4.670000,-0.033890,-299.134399,-0.006631,-0.001873,-0.047575,-0.150749,-0.007680,-0.475754,-299.134399,-0.046257,0.000000
5.050000,-0.023087,-299.178864,-0.006359,-0.001618,-0.041089,-0.102694,-0.005231,-0.410888,-299.178864,-0.039927,0.000000
5.430000,-0.045433,-299.178864,-0.006144,-0.001373,-0.034871,-0.202096,-0.010295,-0.348710,-299.178864,-0.033596,0.000000
5.810000,-0.010796,-299.134399,-0.005872,-0.001119,-0.028419,-0.048021,-0.002446,-0.284185,-299.134399,-0.027266,0.000000
6.190000,-0.011917,-299.178864,-0.005601,-0.000866,-0.022002,-0.053010,-0.002700,-0.220016,-299.178864,-0.020934,0.000000
6.570000,-0.010796,-299.178864,-0.005351,-0.000620,-0.015740,-0.048021,-0.002446,-0.157399,-299.178864,-0.014604,0.000000
6.950000,-0.037239,-299.223358,-0.005113,-0.000378,-0.009600,-0.165648,-0.008438,-0.096000,-299.223358,-0.008273,0.000000
7.330000,-0.032394,-299.312317,-0.004855,-0.000124,-0.003139,-0.144098,-0.007341,-0.031392,-299.312317,-0.001942,0.000000
7.710001,0.191025,-299.312317,-0.004717,-0.000000,-0.000008,0.849721,0.043287,-0.000083,-299.312317,0.000192,0.000000
8.090000,0.124001,-299.312317,-0.004682,-0.000001,-0.000017,0.551582,0.028099,-0.000167,-299.312317,0.000208,0.000000
8.470000,0.124374,-299.401276,-0.004691,-0.000000,-0.000008,0.553245,0.028184,-0.000083,-299.401276,0.000842,0.000000
8.850000,0.122879,-299.401276,-0.004700,-0.000000,-0.000008,0.546593,0.027845,-0.000083,-299.401276,0.001475,0.000000
9.230000,0.349281,-299.401276,-0.004691,0.000041,0.001041,1.553681,0.079148,0.010408,-299.401276,0.002107,0.000000
9.610001,0.546646,-299.445770,-0.004644,0.000073,0.001856,2.431603,0.123872,0.018561,-299.445770,0.002741,0.000000
9.990001,0.657982,-299.445770,-0.004609,0.000094,0.002394,2.926850,0.149101,0.023936,-299.445770,0.003374,0.000000
10.370001,0.856827,-299.534729,-0.004605,0.000120,0.003045,3.811356,0.194160,0.030446,-299.534729,0.004007,0.000000
10.750001,1.196060,-299.534729,-0.004600,0.000147,0.003730,5.320342,0.271031,0.037296,-299.534729,0.004640,0.000000
11.130000,1.292877,-299.490234,-0.004575,0.000158,0.004007,5.751005,0.292970,0.040067,-299.490234,0.005273,0.000000
11.510000,1.554657,-299.534729,-0.004557,0.000179,0.004553,6.915460,0.352290,0.045532,-299.534729,0.005906,0.000000
11.890000,2.121033,-299.623688,-0.004510,0.000220,0.005585,9.434825,0.480633,0.055850,-299.623688,0.006540,0.000000
12.270000,2.490799,-299.623688,-0.004510,0.000244,0.006192,11.079627,0.564423,0.061921,-299.623688,0.007172,0.000000
12.650001,2.915672,-299.668182,-0.004462,0.000270,0.006851,12.969558,0.660701,0.068514,-299.668182,0.007805,0.000000
13.030001,3.157349,-299.712646,-0.004454,0.000288,0.007303,14.044588,0.715465,0.073026,-299.712646,0.008439,0.000000
13.410001,3.827614,-299.712646,-0.004428,0.000323,0.008204,17.026077,0.867350,0.082041,-299.712646,0.009072,0.000000
13.790001,4.122162,-299.757141,-0.004398,0.000347,0.008811,18.336292,0.934095,0.088112,-299.757141,0.009704,0.000000
14.170001,4.439796,-299.846100,-0.004376,0.000368,0.009358,19.749201,1.006072,0.093578,-299.846100,0.010338,0.000000
14.550001,4.826691,-299.801605,-0.004368,0.000394,0.010000,21.470192,1.093744,0.099997,-299.801605,0.010971,0.000000
14.930000,5.181190,-299.801605,-0.004355,0.000412,0.010468,23.047087,1.174075,0.104675,-299.801605,0.011604,0.000000
15.310000,5.864120,-299.846100,-0.004324,0.000447,0.011352,26.084911,1.328829,0.113524,-299.846100,0.012246,0.000000
15.690001,6.120689,-299.890564,-0.004290,0.000474,0.012029,27.226187,1.386968,0.120292,-299.890564,0.012878,0.000000
16.070002,6.418953,-299.979523,-0.004260,0.000494,0.012558,28.552929,1.454556,0.125575,-299.979523,0.013512,0.000000
16.450001,6.834152,-299.935059,-0.004260,0.000524,0.013321,30.399828,1.548641,0.133213,-299.935059,0.014145,0.000000
16.830000,6.831169,-299.935059,-0.004234,0.000537,0.013642,30.386559,1.547965,0.136415,-299.935059,0.014778,0.000000
17.210001,7.305206,-299.935059,-0.004204,0.000566,0.014370,32.495182,1.655383,0.143705,-299.935059,0.015411,0.000000
17.590000,7.668640,-300.068481,-0.004174,0.000593,0.015056,34.111816,1.737739,0.150556,-300.068481,0.016044,0.000000
17.970001,7.975098,-300.068481,-0.004152,0.000620,0.015749,35.475006,1.807183,0.157489,-300.068481,0.016677,0.000000
18.350000,8.211929,-300.068481,-0.004148,0.000645,0.016373,36.528484,1.860850,0.163735,-300.068481,0.017310,0.000000
18.730001,8.226082,-300.068481,-0.004109,0.000663,0.016850,36.591438,1.864057,0.168504,-300.068481,0.017943,0.000000
19.110001,8.789482,-300.024017,-0.004083,0.000697,0.017709,39.097569,1.991725,0.177088,-300.024017,0.018576,0.000000
19.490002,8.671440,-300.157471,-0.004057,0.000714,0.018143,38.572491,1.964976,0.181425,-300.157471,0.019209,0.000000
19.870001,9.050140,-300.246429,-0.004031,0.000744,0.018897,40.257034,2.050791,0.188972,-300.246429,0.019843,0.000000
20.250002,9.304100,-300.201935,-0.004018,0.000770,0.019565,41.386703,2.108339,0.195649,-300.201935,0.020476,0.000000
20.630001,9.197227,-300.201935,-0.003997,0.000787,0.019999,40.911312,2.084122,0.199986,-300.201935,0.021108,0.000000
21.010000,9.461983,-300.201935,-0.003962,0.000820,0.020831,42.089001,2.144116,0.208313,-300.201935,0.021742,0.000000
21.390001,9.811272,-300.335388,-0.003941,0.000847,0.021525,43.642715,2.223266,0.215247,-300.335388,0.022375,0.000000
21.770000,9.782967,-300.335388,-0.003923,0.000868,0.022054,43.516808,2.216852,0.220538,-300.335388,0.023008,0.000000
22.150002,9.666046,-300.246429,-0.003906,0.000886,0.022505,42.996719,2.190357,0.225050,-300.246429,0.023641,0.000000
22.530001,9.800095,-300.335388,-0.003872,0.000905,0.022990,43.592999,2.220733,0.229902,-300.335388,0.024274,0.000000
22.910002,10.178802,-300.335388,-0.003850,0.000935,0.023737,45.277576,2.306550,0.237366,-300.335388,0.024907,0.000000
23.290001,10.584686,-300.424347,-0.003829,0.000966,0.024543,47.083035,2.398524,0.245428,-300.424347,0.025540,0.000000
23.670002,10.669212,-300.468811,-0.003794,0.000992,0.025185,47.459026,2.417678,0.251847,-300.468811,0.026173,0.000000
24.050001,10.304665,-300.513306,-0.003786,0.001001,0.025419,45.837437,2.335070,0.254186,-300.513306,0.026806,0.000000
24.430000,10.894127,-300.424347,-0.003768,0.001031,0.026199,48.459496,2.468644,0.261990,-300.424347,0.027440,0.000000
24.810001,11.139519,-300.557800,-0.003734,0.001060,0.026936,49.551056,2.524251,0.269363,-300.557800,0.028073,0.000000
25.190001,11.359970,-300.557800,-0.003699,0.001093,0.027760,50.531670,2.574206,0.277599,-300.557800,0.028705,0.000000
25.570002,11.323105,-300.602264,-0.003682,0.001117,0.028367,50.367687,2.565852,0.283670,-300.602264,0.029338,0.000000
25.950001,11.245651,-300.602264,-0.003660,0.001137,0.028888,50.023155,2.548301,0.288878,-300.602264,0.029980,0.000000
26.330002,11.652649,-300.557800,-0.003639,0.001168,0.029668,51.833572,2.640528,0.296683,-300.557800,0.030614,0.000000
26.710001,11.597168,-300.602264,-0.003596,0.001187,0.030145,51.586781,2.627956,0.301452,-300.602264,0.031247,0.000000
27.090002,12.000450,-300.691223,-0.003574,0.001220,0.030995,53.380669,2.719341,0.309953,-300.691223,0.031879,0.000000
27.470001,11.941986,-300.735718,-0.003570,0.001242,0.031541,53.120605,2.706093,0.315410,-300.735718,0.032513,0.000000
27.850000,11.974754,-300.735718,-0.003540,0.001264,0.032097,53.266369,2.713518,0.320967,-300.735718,0.033146,0.000000
28.230001,12.156097,-300.780182,-0.003527,0.001287,0.032677,54.073021,2.754611,0.326773,-300.780182,0.033779,0.000000
28.610001,12.524002,-300.824677,-0.003488,0.001317,0.033440,55.709545,2.837979,0.334403,-300.824677,0.034412,0.000000
28.990002,12.546349,-300.869141,-0.003458,0.001334,0.033891,55.808945,2.843043,0.338915,-300.869141,0.035045,0.000000
29.370001,13.022606,-300.913635,-0.003449,0.001367,0.034732,57.927444,2.950965,0.347325,-300.913635,0.035678,0.000000
29.750002,12.794342,-300.869141,-0.003423,0.001385,0.035175,56.912075,2.899240,0.351753,-300.869141,0.036311,0.000000
30.130001,13.095970,-300.913635,-0.003406,0.001412,0.035869,58.253784,2.967589,0.358687,-300.913635,0.036944,0.000000
30.510002,13.278427,-300.913635,-0.003372,0.001437,0.036493,59.065395,3.008934,0.364932,-300.913635,0.037577,0.000000
30.890001,13.813156,-300.958130,-0.003346,0.001467,0.037274,61.443989,3.130106,0.372736,-300.958130,0.038210,0.000000
31.270002,13.785599,-301.002594,-0.003320,0.001492,0.037890,61.321407,3.123861,0.378898,-301.002594,0.038844,0.000000
31.650002,13.834007,-301.002594,-0.003303,0.001515,0.038480,61.536739,3.134831,0.384795,-301.002594,0.039476,0.000000
32.030003,13.917419,-301.002594,-0.003281,0.001538,0.039078,61.907772,3.153732,0.390775,-301.002594,0.040109,0.000000
32.410000,14.183296,-300.958130,-0.003251,0.001562,0.039676,63.090454,3.213981,0.396763,-300.958130,0.040743,0.000000
32.790001,14.635727,-301.002594,-0.003238,0.001591,0.040422,65.102966,3.316503,0.404219,-301.002594,0.041376,0.000000
33.170002,14.818565,-301.180511,-0.003203,0.001617,0.041064,65.916267,3.357935,0.410638,-301.180511,0.042009,0.000000
33.550003,14.920219,-301.225006,-0.003191,0.001641,0.041679,66.368454,3.380970,0.416793,-301.225006,0.042642,0.000000
33.930000,15.254608,-301.136047,-0.003169,0.001668,0.042356,67.855888,3.456743,0.423560,-301.136047,0.043275,0.000000
34.310001,15.174919,-301.180511,-0.003143,0.001686,0.042824,67.501411,3.438686,0.428238,-301.180511,0.043908,0.000000
34.690002,15.623260,-301.225006,-0.003122,0.001717,0.043604,69.495735,3.540282,0.436043,-301.225006,0.044541,0.000000
35.070004,15.849663,-301.313965,-0.003096,0.001743,0.044264,70.502823,3.591585,0.442636,-301.313965,0.045174,0.000000
35.450001,15.921532,-301.313965,-0.003078,0.001765,0.044836,70.822510,3.607871,0.448359,-301.313965,0.045807,0.000000
35.830002,16.132668,-301.269470,-0.003044,0.001789,0.045451,71.761688,3.655715,0.454513,-301.269470,0.046441,0.000000
36.210003,16.315872,-301.313965,-0.003022,0.001813,0.046042,72.576622,3.697230,0.460417,-301.313965,0.047073,0.000000
36.590000,16.968643,-301.313965,-0.002988,0.001844,0.046831,75.480293,3.845150,0.468305,-301.313965,0.047706,0.000000
36.970001,16.967148,-301.358429,-0.002979,0.001867,0.047429,75.473640,3.844810,0.474293,-301.358429,0.048348,0.000000
37.350002,17.262444,-301.402924,-0.002958,0.001893,0.048080,76.787186,3.911726,0.480795,-301.402924,0.048981,0.000000
37.730003,17.483261,-301.447418,-0.002936,0.001918,0.048721,77.769432,3.961764,0.487214,-301.447418,0.049615,0.000000
38.110001,17.320160,-301.358429,-0.002902,0.001935,0.049137,77.043922,3.924804,0.491370,-301.358429,0.050248,0.000000
38.490002,17.692162,-301.447418,-0.002880,0.001961,0.049805,78.698662,4.009101,0.498054,-301.447418,0.050880,0.000000
38.870003,18.257423,-301.491882,-0.002841,0.001990,0.050534,81.213074,4.137191,0.505336,-301.491882,0.051514,0.000000
39.250000,18.602608,-301.447418,-0.002833,0.002017,0.051227,82.748535,4.215411,0.512270,-301.447418,0.052147,0.000000
39.630001,18.924713,-301.491882,-0.002824,0.002043,0.051895,84.181328,4.288402,0.518955,-301.491882,0.052780,0.000000
40.010002,18.803322,-301.491882,-0.002790,0.002061,0.052338,83.641350,4.260894,0.523375,-301.491882,0.053412,0.000000
40.390003,19.367462,-301.580841,-0.002781,0.002090,0.053075,86.150772,4.388730,0.530748,-301.580841,0.054046,0.000000
40.770000,19.616211,-301.625336,-0.002742,0.002111,0.053630,87.257263,4.445097,0.536297,-301.625336,0.054679,0.000000
41.150002,19.872032,-301.625336,-0.002729,0.002136,0.054263,88.395210,4.503067,0.542625,-301.625336,0.055312,0.000000
41.530003,20.505806,-301.714294,-0.002708,0.002165,0.054991,91.214378,4.646682,0.549915,-301.714294,0.055945,0.000000
41.910004,20.515488,-301.669800,-0.002682,0.002186,0.055520,91.257446,4.648876,0.555199,-301.669800,0.056578,0.000000
42.290001,20.675240,-301.758759,-0.002660,0.002208,0.056092,91.968056,4.685076,0.560921,-301.758759,0.057211,0.000000
42.670002,21.678780,-301.803253,-0.002630,0.002244,0.056994,96.432030,4.912481,0.569945,-301.803253,0.057845,0.000000
43.050003,21.704475,-301.847748,-0.002621,0.002265,0.057541,96.546326,4.918304,0.575410,-301.847748,0.058477,0.000000
43.430000,21.386841,-301.803253,-0.002596,0.002278,0.057870,95.133423,4.846328,0.578703,-301.803253,0.059110,0.000000
43.810001,22.077591,-301.803253,-0.002565,0.002306,0.058581,98.206032,5.002853,0.585811,-301.803253,0.059744,0.000000
44.190002,22.683067,-301.847748,-0.002539,0.002331,0.059206,100.899323,5.140057,0.592056,-301.847748,0.060377,0.000000
44.570004,23.409943,-301.892212,-0.002527,0.002362,0.060003,104.132622,5.304769,0.600035,-301.892212,0.061009,0.000000
44.950001,23.803535,-301.892212,-0.002509,0.002387,0.060637,105.883415,5.393958,0.606370,-301.892212,0.061643,0.000000
45.330002,23.490746,-301.981171,-0.002492,0.002399,0.060941,104.492058,5.323079,0.609406,-301.981171,0.062276,0.000000
45.710003,24.699089,-301.936707,-0.002471,0.002430,0.061721,109.867035,5.596894,0.617210,-301.936707,0.062909,0.000000
46.090004,25.408836,-301.981171,-0.002440,0.002459,0.062458,113.024147,5.757725,0.624576,-301.981171,0.063542,0.000000
46.470001,26.193794,-302.070129,-0.002410,0.002490,0.063239,116.515816,5.935599,0.632388,-302.070129,0.064175,0.000000
46.850002,26.348328,-302.070129,-0.002397,0.002515,0.063872,117.203217,5.970616,0.638716,-302.070129,0.064808,0.000000
47.230003,26.271622,-302.070129,-0.002371,0.002533,0.064340,116.862007,5.953234,0.643402,-302.070129,0.065442,0.000000
47.610001,27.338470,-302.114624,-0.002358,0.002563,0.065103,121.607590,6.194986,0.651032,-302.114624,0.066074,0.000000
47.990002,27.471779,-302.159088,-0.002337,0.002584,0.065641,122.200577,6.225194,0.656407,-302.159088,0.066716,0.000000
48.370003,28.382973,-302.159088,-0.002315,0.002615,0.066430,126.253769,6.431674,0.664302,-302.159088,0.067349,0.000000
48.750004,28.474205,-302.159088,-0.002294,0.002638,0.066993,126.659592,6.452347,0.669934,-302.159088,0.067982,0.000000
49.130001,28.877113,-302.203583,-0.002255,0.002660,0.067557,128.451813,6.543647,0.675573,-302.203583,0.068616,0.000000
49.510002,29.254700,-302.203583,-0.002259,0.002681,0.068095,130.131409,6.629210,0.680948,-302.203583,0.069248,0.000000
49.890003,30.040031,-302.203583,-0.002233,0.002708,0.068772,133.624741,6.807168,0.687715,-302.203583,0.069881,0.000000
50.270004,30.717377,-302.292542,-0.002203,0.002733,0.069413,136.637711,6.960657,0.694135,-302.292542,0.070514,0.000000
50.650002,31.644585,-302.381500,-0.002199,0.002763,0.070185,140.762146,7.170765,0.701848,-302.381500,0.071148,0.000000
51.030003,31.925728,-302.381500,-0.002169,0.002782,0.070653,142.012726,7.234473,0.706534,-302.381500,0.071781,0.000000
51.410004,32.482422,-302.337036,-0.002151,0.002805,0.071243,144.489029,7.360622,0.712431,-302.337036,0.072413,0.000000
51.790001,33.386169,-302.425995,-0.002130,0.002831,0.071919,148.509094,7.565414,0.719191,-302.425995,0.073047,0.000000
52.170002,34.615372,-302.470459,-0.002100,0.002862,0.072700,153.976868,7.843956,0.727003,-302.470459,0.073680,0.000000
52.550003,35.135574,-302.470459,-0.002091,0.002885,0.073281,156.290848,7.961835,0.732809,-302.470459,0.074313,0.000000
52.930004,35.639397,-302.514954,-0.002082,0.002909,0.073888,158.531952,8.076002,0.738880,-302.514954,0.074946,0.000000
53.310001,36.664909,-302.470459,-0.002044,0.002935,0.074556,163.093658,8.308387,0.745556,-302.470459,0.075579,0.000000
53.690002,36.758751,-302.425995,-0.002039,0.002952,0.074989,163.511093,8.329652,0.749894,-302.425995,0.076212,0.000000
54.070004,37.436836,-302.603912,-0.002005,0.002975,0.075553,166.527359,8.483308,0.755533,-302.603912,0.076845,0.000000
54.450001,39.081604,-302.648376,-0.001988,0.003009,0.076420,173.843658,8.856018,0.764201,-302.648376,0.077478,0.000000
54.830002,39.988335,-302.648376,-0.001975,0.003035,0.077079,177.876999,9.061485,0.770794,-302.648376,0.078111,0.000000
55.210003,40.917030,-302.648376,-0.001962,0.003062,0.077782,182.008041,9.271932,0.777819,-302.648376,0.078745,0.000000
55.590004,41.558632,-302.648376,-0.001932,0.003083,0.078311,184.862030,9.417320,0.783110,-302.648376,0.079378,0.000000
55.970001,42.790810,-302.737366,-0.001910,0.003111,0.079022,190.343033,9.696536,0.790218,-302.737366,0.080010,0.000000
56.350002,43.739983,-302.737366,-0.001906,0.003138,0.079699,194.565155,9.911622,0.796985,-302.737366,0.080644,0.000000
56.730003,44.533508,-302.737366,-0.001888,0.003161,0.080279,198.094940,10.091437,0.802791,-302.737366,0.081277,0.000000
57.110004,45.653236,-302.781830,-0.001880,0.003187,0.080948,203.075745,10.345172,0.809475,-302.781830,0.081910,0.000000
57.490002,46.103432,-302.826324,-0.001858,0.003207,0.081450,205.078308,10.447186,0.814502,-302.826324,0.082543,0.000000
57.870003,47.687881,-302.826324,-0.001832,0.003237,0.082231,212.126297,10.806229,0.822306,-302.826324,0.083176,0.000000
58.250004,48.985970,-302.870789,-0.001815,0.003262,0.082847,217.900482,11.100379,0.828468,-302.870789,0.083809,0.000000
58.630001,49.789177,-302.870789,-0.001819,0.003286,0.083471,221.473328,11.282389,0.834706,-302.870789,0.084442,0.000000
59.010002,51.304359,-302.915283,-0.001789,0.003314,0.084173,228.213196,11.625734,0.841730,-302.915283,0.085084,0.000000
59.390003,51.897179,-302.915283,-0.001785,0.003333,0.084659,230.850174,11.760068,0.846590,-302.915283,0.085717,0.000000
59.770004,52.465416,-303.004242,-0.001755,0.003352,0.085136,233.377823,11.888833,0.851359,-303.004242,0.086350,0.000000
60.150002,54.331001,-302.959747,-0.001746,0.003383,0.085916,241.676361,12.311581,0.859164,-302.959747,0.086983,0.000000
60.530003,56.083389,-303.048706,-0.001725,0.003413,0.086679,249.471375,12.708678,0.866794,-303.048706,0.087617,0.000000
60.910004,57.322273,-303.048706,-0.001707,0.003438,0.087321,254.982208,12.989412,0.873213,-303.048706,0.088249,0.000000
61.290005,57.924774,-303.048706,-0.001694,0.003454,0.087738,257.662262,13.125942,0.877376,-303.048706,0.088882,0.000000
61.670002,59.177055,-303.137695,-0.001686,0.003483,0.088466,263.232697,13.409712,0.884659,-303.137695,0.089515,0.000000
62.050003,61.045250,-303.182159,-0.001681,0.003509,0.089125,271.542847,13.833052,0.891252,-303.182159,0.090149,0.000000
62.430004,62.140030,-303.226654,-0.001664,0.003533,0.089732,276.412659,14.081133,0.897323,-303.226654,0.090781,0.000000
62.810001,63.111168,-303.182159,-0.001656,0.003556,0.090330,280.732483,14.301195,0.903303,-303.182159,0.091414,0.000000
63.190002,65.031868,-303.182159,-0.001617,0.003581,0.090964,289.276184,14.736432,0.909639,-303.182159,0.092048,0.000000
63.570004,66.046959,-303.271118,-0.001608,0.003603,0.091510,293.791534,14.966455,0.915097,-303.271118,0.092681,0.000000
63.950005,66.128883,-303.271118,-0.001608,0.003609,0.091657,294.155975,14.985019,0.916573,-303.271118,0.016090,0.000000
64.330002,65.018837,-303.315613,-0.001604,0.003609,0.091666,289.218231,14.733479,0.916664,-303.315613,294.500488,0.000000
64.710007,65.808266,-303.360077,-0.001600,0.003596,0.091336,292.729797,14.912367,0.913363,-303.360077,294.500488,0.000000
65.090004,65.408714,-303.360077,-0.001578,0.003629,0.092178,290.952484,14.821827,0.921781,-303.360077,294.500488,0.000000
65.470001,65.239662,-303.360077,-0.001574,0.003639,0.092420,290.200500,14.783519,0.924203,-303.360077,294.500488,0.000000
65.850006,65.399773,-303.404572,-0.001574,0.003645,0.092585,290.912720,14.819800,0.925853,-303.404572,294.500488,0.000000
66.230003,65.297752,-303.449036,-0.001556,0.003651,0.092741,290.458923,14.796682,0.927413,-303.449036,294.500488,0.000000
66.610001,65.250084,-303.449036,-0.001561,0.003656,0.092871,290.246857,14.785880,0.928715,-303.449036,294.500488,0.000000
66.990005,65.190880,-303.449036,-0.001548,0.003661,0.092993,289.983521,14.772465,0.929926,-303.449036,294.500488,0.000000
67.370003,65.146568,-303.582489,-0.001544,0.003665,0.093097,289.786407,14.762424,0.930971,-303.582489,294.500488,0.000000
67.750000,65.137627,-303.538025,-0.001531,0.003670,0.093227,289.746643,14.760398,0.932273,-303.538025,294.500488,0.000000
68.130005,65.003197,-303.626984,-0.001548,0.003673,0.093288,289.148651,14.729935,0.932878,-303.626984,294.500488,0.000000
68.510002,64.952553,-303.626984,-0.001539,0.003676,0.093366,288.923370,14.718459,0.933658,-303.626984,294.500488,0.000000
68.890007,65.307793,-303.582489,-0.001531,0.003683,0.093557,290.503571,14.798957,0.935565,-303.582489,294.500488,0.000000
69.270004,65.038567,-303.626984,-0.001518,0.003683,0.093557,289.306000,14.737949,0.935565,-303.626984,294.500488,0.000000
69.650002,65.032616,-303.760406,-0.001526,0.003687,0.093652,289.279510,14.736601,0.936519,-303.760406,294.500488,0.000000
70.030006,65.117149,-303.671448,-0.001513,0.003692,0.093765,289.655548,14.755756,0.937647,-303.671448,294.500488,0.000000
70.410004,64.950325,-303.715942,-0.001531,0.003695,0.093860,288.913483,14.717954,0.938601,-303.715942,294.500488,0.000000
70.790001,65.365883,-303.715942,-0.001509,0.003699,0.093947,290.761963,14.812121,0.939471,-303.715942,294.500488,0.000000
71.170006,65.126457,-303.804901,-0.001513,0.003699,0.093947,289.696960,14.757866,0.939471,-303.804901,294.500488,0.000000
71.550003,64.920906,-303.849365,-0.001518,0.003699,0.093947,288.782623,14.711287,0.939471,-303.849365,294.500488,0.000000
71.930000,64.637901,-303.849365,-0.001509,0.003699,0.093947,287.523743,14.647158,0.939471,-303.849365,294.500488,0.000000
72.310005,64.422676,-303.849365,-0.001505,0.003699,0.093947,286.566376,14.598387,0.939471,-303.849365,294.500488,0.000000
72.690002,64.170204,-303.893860,-0.001492,0.003699,0.093947,285.443329,14.541177,0.939471,-303.893860,294.500488,0.000000
73.070000,63.960930,-303.893860,-0.001500,0.003699,0.093947,284.512421,14.493753,0.939471,-303.893860,294.500488,0.000000
73.450005,65.903221,-303.893860,-0.001483,0.003511,0.089168,293.152161,14.933884,0.891683,-303.893860,294.500488,0.000000
73.830002,65.660057,-303.982819,-0.001479,0.003537,0.089845,292.070526,14.878782,0.898451,-303.982819,294.500488,0.000000
74.210007,65.427330,-303.938324,-0.001470,0.003551,0.090192,291.035309,14.826045,0.901918,-303.938324,294.500488,0.000000
74.590004,65.294762,-304.027313,-0.001475,0.003675,0.093348,290.445618,14.796005,0.933484,-304.027313,294.500488,0.000000
74.970001,65.062782,-304.071777,-0.001466,0.003676,0.093366,289.413696,14.743437,0.933658,-304.071777,294.500488,0.000000
75.350006,65.168526,-304.071777,-0.001466,0.003706,0.094120,289.884094,14.767399,0.941205,-304.071777,294.500488,0.000000
75.730003,65.040810,-304.071777,-0.001470,0.003708,0.094189,289.315979,14.738459,0.941894,-304.071777,294.500488,0.000000
76.110001,65.048256,-304.160736,-0.001466,0.003713,0.094302,289.349091,14.740146,0.943022,-304.160736,294.500488,0.000000
76.490005,65.284706,-304.071777,-0.001466,0.003720,0.094476,290.400879,14.793726,0.944763,-304.071777,294.500488,0.000000
76.870003,65.182686,-304.160736,-0.001453,0.003720,0.094476,289.947083,14.770608,0.944763,-304.160736,294.500488,0.000000
77.250000,65.025917,-304.205231,-0.001470,0.003720,0.094485,289.249725,14.735084,0.944846,-304.205231,294.500488,0.000000
77.630005,65.100761,-304.249695,-0.001479,0.003724,0.094580,289.582642,14.752044,0.945800,-304.249695,294.500488,0.000000
78.010002,65.046028,-304.249695,-0.001470,0.003727,0.094675,289.339172,14.739640,0.946754,-304.249695,294.500488,0.000000
78.390007,65.269447,-304.249695,-0.001466,0.003729,0.094710,290.333008,14.790268,0.947102,-304.249695,294.500488,0.000000
78.770004,65.171516,-304.338654,-0.001470,0.003729,0.094710,289.897369,14.768077,0.947102,-304.338654,294.500488,0.000000
79.150002,65.044899,-304.427643,-0.001479,0.003729,0.094710,289.334167,14.739385,0.947102,-304.427643,294.500488,0.000000
79.530006,65.043785,-304.427643,-0.001487,0.003732,0.094788,289.329193,14.739132,0.947882,-304.427643,294.500488,0.000000
79.910004,65.021446,-304.383148,-0.001466,0.003732,0.094796,289.229828,14.734070,0.947965,-304.383148,294.500488,0.000000
80.290001,65.563622,-304.383148,-0.001470,0.003740,0.094987,291.641541,14.856929,0.949872,-304.383148,294.500488,0.000000
80.670006,65.566597,-304.427643,-0.001457,0.003740,0.094987,291.654785,14.857604,0.949872,-304.427643,294.500488,0.000000
81.050003,65.494728,-304.561066,-0.001475,0.003740,0.094987,291.335114,14.841318,0.949872,-304.561066,294.500488,0.000000
81.430000,65.377068,-304.516602,-0.001479,0.003740,0.094987,290.811707,14.814655,0.949872,-304.516602,294.500488,0.000000
81.810005,65.295143,-304.472107,-0.001457,0.003740,0.094987,290.447296,14.796091,0.949872,-304.472107,294.500488,0.000000
82.190002,65.202049,-304.561066,-0.001466,0.003740,0.094987,290.033203,14.774996,0.949872,-304.561066,294.500488,0.000000
82.570007,65.092201,-304.605560,-0.001466,0.003740,0.094996,289.544586,14.750103,0.949963,-304.605560,294.500488,0.000000
82.950005,65.162941,-304.605560,-0.001462,0.003748,0.095204,289.859253,14.766133,0.952045,-304.605560,294.500488,0.000000
83.330002,65.654472,-304.650024,-0.001462,0.003749,0.095213,292.045685,14.877517,0.952128,-304.650024,294.500488,0.000000
83.710007,65.610161,-304.650024,-0.001457,0.003749,0.095213,291.848572,14.867475,0.952128,-304.650024,294.500488,0.000000
84.090004,65.552818,-304.694519,-0.001440,0.003749,0.095213,291.593506,14.854481,0.952128,-304.694519,294.500488,0.000000
84.470001,65.478340,-304.738983,-0.001462,0.003749,0.095213,291.262207,14.837604,0.952128,-304.738983,294.500488,0.000000
84.850006,65.381157,-304.827972,-0.001470,0.003749,0.095222,290.829926,14.815581,0.952219,-304.827972,294.500488,0.000000
85.230003,65.299980,-304.738983,-0.001462,0.003749,0.095222,290.468811,14.797187,0.952219,-304.738983,294.500488,0.000000
85.610001,65.227364,-304.827972,-0.001453,0.003749,0.095222,290.145813,14.780732,0.952219,-304.827972,294.500488,0.000000
85.990005,65.144325,-304.827972,-0.001444,0.003750,0.095248,289.776428,14.761915,0.952476,-304.827972,294.500488,0.000000
86.370003,65.077293,-304.916931,-0.001457,0.003750,0.095248,289.478271,14.746725,0.952476,-304.916931,294.500488,0.000000
86.750008,65.164803,-304.916931,-0.001457,0.003753,0.095317,289.867523,14.766556,0.953173,-304.916931,294.500488,0.000000
87.130005,65.169273,-304.916931,-0.001457,0.003753,0.095317,289.887421,14.767569,0.953173,-304.916931,294.500488,0.000000
87.510002,65.133156,-304.872437,-0.001440,0.003754,0.095352,289.726746,14.759384,0.953521,-304.872437,294.500488,0.000000
87.890007,65.215080,-304.916931,-0.001457,0.003755,0.095370,290.091156,14.777948,0.953695,-304.916931,294.500488,0.000000
88.270004,65.142464,-305.005890,-0.001444,0.003755,0.095370,289.768158,14.761494,0.953695,-305.005890,294.500488,0.000000
88.650002,65.086617,-305.050354,-0.001449,0.003755,0.095370,289.519745,14.748837,0.953695,-305.050354,294.500488,0.000000
89.030006,65.022942,-305.005890,-0.001457,0.003755,0.095370,289.236481,14.734409,0.953695,-305.005890,294.500488,0.000000
89.410004,64.974159,-305.050354,-0.001449,0.003755,0.095370,289.019501,14.723354,0.953695,-305.050354,294.500488,0.000000
89.790001,65.595650,-305.139313,-0.001449,0.003763,0.095569,291.784027,14.864186,0.955686,-305.139313,294.500488,0.000000
90.170006,65.578880,-305.139313,-0.001453,0.003763,0.095569,291.709442,14.860386,0.955686,-305.139313,294.500488,0.000000
90.550003,65.558403,-305.139313,-0.001453,0.003763,0.095569,291.618347,14.855746,0.955686,-305.139313,294.500488,0.000000
90.930008,65.505898,-305.228271,-0.001431,0.003763,0.095569,291.384796,14.843848,0.955686,-305.228271,294.500488,0.000000
91.310005,65.450783,-305.183807,-0.001444,0.003763,0.095569,291.139618,14.831359,0.955686,-305.183807,294.500488,0.000000
91.690002,65.379662,-305.317261,-0.001444,0.003763,0.095569,290.823273,14.815243,0.955686,-305.317261,294.500488,0.000000
92.070007,65.317848,-305.317261,-0.001444,0.003763,0.095569,290.548309,14.801236,0.955686,-305.317261,294.500488,0.000000
92.450005,65.281364,-305.228271,-0.001453,0.003763,0.095569,290.386017,14.792969,0.955686,-305.228271,294.500488,0.000000
92.830002,65.224754,-305.317261,-0.001440,0.003763,0.095569,290.134186,14.780140,0.955686,-305.317261,294.500488,0.000000
93.210007,65.156609,-305.361725,-0.001440,0.003763,0.095578,289.831085,14.764699,0.955777,-305.361725,294.500488,0.000000
93.590004,65.078423,-305.406219,-0.001436,0.003763,0.095578,289.483276,14.746982,0.955777,-305.406219,294.500488,0.000000
93.970001,65.028145,-305.361725,-0.001449,0.003763,0.095578,289.259644,14.735588,0.955777,-305.361725,294.500488,0.000000
94.350006,64.976021,-305.495178,-0.001444,0.003763,0.095578,289.027771,14.723777,0.955777,-305.495178,294.500488,0.000000
94.730003,64.929100,-305.406219,-0.001453,0.003763,0.095578,288.819061,14.713144,0.955777,-305.406219,294.500488,0.000000
95.110008,64.851646,-305.495178,-0.001440,0.003763,0.095578,288.474518,14.695593,0.955777,-305.495178,294.500488,0.000000
95.490005,64.784248,-305.495178,-0.001440,0.003763,0.095578,288.174744,14.680321,0.955777,-305.495178,294.500488,0.000000
95.870003,64.729881,-305.495178,-0.001444,0.003763,0.095578,287.932892,14.668001,0.955777,-305.495178,294.500488,0.000000
96.250008,64.688911,-305.495178,-0.001444,0.003763,0.095578,287.750641,14.658716,0.955777,-305.495178,294.500488,0.000000
96.630005,64.637535,-305.584137,-0.001436,0.003763,0.095578,287.522125,14.647076,0.955777,-305.584137,294.500488,0.000000
97.010002,66.391396,-305.584137,-0.001431,0.003772,0.095812,295.323669,15.044506,0.958116,-305.584137,294.500488,0.000000
97.390007,66.294212,-305.673096,-0.001440,0.003772,0.095812,294.891388,15.022483,0.958116,-305.673096,294.500488,0.000000
97.770004,66.209312,-305.717590,-0.001440,0.003772,0.095812,294.513733,15.003245,0.958116,-305.717590,294.500488,0.000000
98.150002,66.153084,-305.673096,-0.001436,0.003772,0.095812,294.263611,14.990503,0.958116,-305.673096,294.500488,0.000000
98.530006,66.080467,-305.717590,-0.001427,0.003772,0.095812,293.940613,14.974048,0.958116,-305.717590,294.500488,0.000000
98.910004,66.012703,-305.762054,-0.001427,0.003772,0.095812,293.639160,14.958693,0.958116,-305.762054,294.500488,0.000000
99.290001,65.964668,-305.762054,-0.001418,0.003772,0.095812,293.425507,14.947807,0.958116,-305.762054,294.500488,0.000000
99.670006,65.905464,-305.806549,-0.001431,0.003772,0.095812,293.162140,14.934391,0.958116,-305.806549,294.500488,0.000000
100.050003,65.826149,-305.762054,-0.001427,0.003772,0.095812,292.809326,14.916419,0.958116,-305.762054,294.500488,0.000000
100.430008,65.820549,-305.895508,-0.001436,0.003772,0.095812,292.784424,14.915150,0.958116,-305.895508,294.500488,0.000000
100.810005,65.762093,-305.851013,-0.001431,0.003772,0.095812,292.524384,14.901904,0.958116,-305.851013,294.500488,0.000000
101.190002,65.673103,-305.939972,-0.001436,0.003772,0.095812,292.128540,14.881738,0.958116,-305.939972,294.500488,0.000000
101.570007,65.626183,-305.851013,-0.001436,0.003772,0.095812,291.919830,14.871106,0.958116,-305.851013,294.500488,0.000000
101.950005,65.583733,-305.939972,-0.001436,0.003772,0.095812,291.731018,14.861486,0.958116,-305.939972,294.500488,0.000000
102.330002,65.545372,-305.939972,-0.001436,0.003772,0.095812,291.560364,14.852794,0.958116,-305.939972,294.500488,0.000000
102.710007,65.496223,-306.028931,-0.001427,0.003772,0.095812,291.341766,14.841657,0.958116,-306.028931,294.500488,0.000000
103.090004,65.420998,-306.028931,-0.001423,0.003772,0.095812,291.007141,14.824610,0.958116,-306.028931,294.500488,0.000000
103.470001,65.361046,-306.028931,-0.001423,0.003772,0.095812,290.740448,14.811025,0.958116,-306.028931,294.500488,0.000000
103.850006,65.309288,-306.028931,-0.001440,0.003772,0.095812,290.510223,14.799295,0.958116,-306.028931,294.500488,0.000000
104.230003,65.271309,-306.117920,-0.001427,0.003772,0.095812,290.341278,14.790690,0.958116,-306.117920,294.500488,0.000000
104.610008,65.236671,-306.206879,-0.001414,0.003772,0.095812,290.187195,14.782842,0.958116,-306.206879,294.500488,0.000000
104.990005,65.194603,-306.162384,-0.001423,0.003772,0.095812,290.000092,14.773308,0.958116,-306.162384,294.500488,0.000000
105.370003,65.139854,-306.206879,-0.001418,0.003772,0.095812,289.756531,14.760902,0.958116,-306.206879,294.500488,0.000000
105.750008,65.085869,-306.206879,-0.001423,0.003772,0.095812,289.516418,14.748669,0.958116,-306.206879,294.500488,0.000000
106.130005,65.037453,-306.251343,-0.001418,0.003772,0.095812,289.301025,14.737697,0.958116,-306.251343,294.500488,0.000000
106.510002,65.008781,-306.295837,-0.001427,0.003772,0.095812,289.173492,14.731200,0.958116,-306.295837,294.500488,0.000000
106.890007,64.976021,-306.295837,-0.001431,0.003772,0.095812,289.027771,14.723777,0.958116,-306.295837,294.500488,0.000000
107.270004,64.941017,-306.384796,-0.001431,0.003772,0.095812,288.872070,14.715845,0.958116,-306.384796,294.500488,0.000000
107.650002,65.303337,-306.340302,-0.001427,0.003791,0.096279,290.483765,14.797948,0.962794,-306.340302,294.500488,0.000000
108.030006,65.778847,-306.384796,-0.001418,0.003787,0.096193,292.598938,14.905700,0.961931,-306.384796,294.500488,0.000000
108.410004,65.767677,-306.429260,-0.001423,0.003787,0.096193,292.549225,14.903169,0.961931,-306.429260,294.500488,0.000000
108.790009,65.730064,-306.473755,-0.001427,0.003787,0.096193,292.381927,14.894646,0.961931,-306.473755,294.500488,0.000000
109.170006,65.661552,-306.429260,-0.001423,0.003787,0.096193,292.077179,14.879121,0.961931,-306.429260,294.500488,0.000000
109.550003,65.647408,-306.473755,-0.001427,0.003787,0.096193,292.014252,14.875915,0.961931,-306.473755,294.500488,0.000000
109.930008,65.606819,-306.518219,-0.001414,0.003787,0.096193,291.833710,14.866717,0.961931,-306.518219,294.500488,0.000000
110.310005,65.592659,-306.562714,-0.001427,0.003787,0.096193,291.770721,14.863509,0.961931,-306.562714,294.500488,0.000000
110.690002,65.562126,-306.518219,-0.001414,0.003787,0.096193,291.634888,14.856590,0.961931,-306.518219,294.500488,0.000000
111.070007,65.532707,-306.607208,-0.001436,0.003787,0.096193,291.504028,14.849923,0.961931,-306.607208,294.500488,0.000000
111.450005,65.498451,-306.607208,-0.001423,0.003787,0.096193,291.351654,14.842161,0.961931,-306.607208,294.500488,0.000000
111.830002,65.463081,-306.651672,-0.001423,0.003787,0.096193,291.194336,14.834146,0.961931,-306.651672,294.500488,0.000000
112.210007,65.403877,-306.651672,-0.001418,0.003787,0.096193,290.930969,14.820731,0.961931,-306.651672,294.500488,0.000000
112.590004,65.375572,-306.696167,-0.001440,0.003787,0.096193,290.805084,14.814316,0.961931,-306.696167,294.500488,0.000000
112.970009,65.340569,-306.696167,-0.001423,0.003787,0.096193,290.649353,14.806384,0.961931,-306.696167,294.500488,0.000000
113.350006,65.310783,-306.740631,-0.001418,0.003787,0.096193,290.516876,14.799635,0.961931,-306.740631,294.500488,0.000000
113.730003,65.287315,-306.785126,-0.001410,0.003787,0.096193,290.412476,14.794317,0.961931,-306.785126,294.500488,0.000000
114.110008,65.260139,-306.829590,-0.001427,0.003787,0.096193,290.291595,14.788159,0.961931,-306.829590,294.500488,0.000000
114.490005,65.232582,-306.829590,-0.001423,0.003787,0.096193,290.169006,14.781914,0.961931,-306.829590,294.500488,0.000000
114.870003,65.196083,-306.785126,-0.001414,0.003787,0.096193,290.006653,14.773643,0.961931,-306.785126,294.500488,0.000000
115.250008,65.152885,-306.874084,-0.001418,0.003787,0.096193,289.814514,14.763855,0.961931,-306.874084,294.500488,0.000000
115.630005,65.104485,-306.963043,-0.001427,0.003787,0.096193,289.599213,14.752887,0.961931,-306.963043,294.500488,0.000000
116.010002,65.071709,-306.918549,-0.001423,0.003787,0.096193,289.453430,14.745460,0.961931,-306.918549,294.500488,0.000000
116.390007,65.051979,-306.918549,-0.001423,0.003787,0.096193,289.365662,14.740989,0.961931,-306.918549,294.500488,0.000000
116.770004,65.019203,-306.918549,-0.001414,0.003787,0.096193,289.219849,14.733562,0.961931,-306.918549,294.500488,0.000000
117.150009,64.999474,-307.007538,-0.001410,0.003787,0.096193,289.132111,14.729092,0.961931,-307.007538,294.500488,0.000000
117.530006,64.966713,-307.096497,-0.001423,0.003787,0.096193,288.986359,14.721668,0.961931,-307.096497,294.500488,0.000000
117.910004,64.946220,-307.096497,-0.001423,0.003787,0.096193,288.895203,14.717024,0.961931,-307.096497,294.500488,0.000000
118.290009,65.348015,-307.096497,-0.001423,0.003795,0.096401,290.682495,14.808072,0.964013,-307.096497,294.500488,0.000000
118.670006,65.449303,-307.096497,-0.001423,0.003795,0.096401,291.133026,14.831024,0.964013,-307.096497,294.500488,0.000000
119.050003,65.454887,-307.185455,-0.001406,0.003795,0.096401,291.157867,14.832290,0.964013,-307.185455,294.500488,0.000000
119.430008,65.457115,-307.229919,-0.001423,0.003795,0.096401,291.167786,14.832794,0.964013,-307.229919,294.500488,0.000000
119.810005,65.432915,-307.185455,-0.001431,0.003795,0.096401,291.060150,14.827311,0.964013,-307.185455,294.500488,0.000000
120.190002,65.397163,-307.229919,-0.001423,0.003795,0.096401,290.901123,14.819209,0.964013,-307.229919,294.500488,0.000000
120.570007,65.381905,-307.274414,-0.001418,0.003795,0.096401,290.833252,14.815751,0.964013,-307.274414,294.500488,0.000000
120.950005,65.362541,-307.274414,-0.001418,0.003795,0.096401,290.747101,14.811363,0.964013,-307.274414,294.500488,0.000000
121.330009,65.329399,-307.274414,-0.001410,0.003795,0.096401,290.599670,14.803853,0.964013,-307.274414,294.500488,0.000000
121.710007,65.318596,-307.274414,-0.001431,0.003795,0.096401,290.551636,14.801406,0.964013,-307.274414,294.500488,0.000000
122.090004,65.297005,-307.274414,-0.001423,0.003795,0.096401,290.455597,14.796514,0.964013,-307.274414,294.500488,0.000000
122.470009,65.282112,-307.363373,-0.001427,0.003795,0.096401,290.389343,14.793138,0.964013,-307.363373,294.500488,0.000000
122.850006,65.266090,-307.407867,-0.001418,0.003795,0.096401,290.318085,14.789508,0.964013,-307.407867,294.500488,0.000000
123.230003,65.245979,-307.452332,-0.001414,0.003795,0.096401,290.228607,14.784950,0.964013,-307.452332,294.500488,0.000000
123.610008,65.211723,-307.452332,-0.001418,0.003795,0.096401,290.076233,14.777188,0.964013,-307.452332,294.500488,0.000000
123.990005,65.194969,-307.496826,-0.001414,0.003795,0.096401,290.001709,14.773392,0.964013,-307.496826,294.500488,0.000000
124.370003,65.162575,-307.496826,-0.001406,0.003795,0.096401,289.857605,14.766050,0.964013,-307.496826,1681.640991,0.000000
124.750008,65.133156,-307.585785,-0.001410,0.003786,0.096167,289.726746,14.759384,0.961674,-307.585785,0.095959,0.000000
125.130005,65.076927,-307.541290,-0.001418,0.003769,0.095734,289.476624,14.746643,0.957336,-307.541290,0.095326,0.000000
125.510010,64.952553,-307.585785,-0.001414,0.003745,0.095127,288.923370,14.718459,0.951265,-307.585785,0.094693,0.000000
125.890007,64.883675,-307.541290,-0.001414,0.003724,0.094580,288.617004,14.702851,0.945800,-307.541290,0.094060,0.000000
126.270004,64.888878,-307.630249,-0.001418,0.003695,0.093843,288.640137,14.704030,0.938427,-307.630249,0.093426,0.000000
126.650009,64.793556,-307.674744,-0.001401,0.003673,0.093305,288.216125,14.682429,0.933052,-307.674744,0.092794,0.000000
127.030006,64.805092,-307.674744,-0.001414,0.003652,0.092768,288.267456,14.685044,0.927678,-307.674744,0.092161,0.000000
127.410004,64.711998,-307.719208,-0.001406,0.003627,0.092134,287.853333,14.663948,0.921342,-307.719208,0.091527,0.000000
127.790009,64.649818,-307.674744,-0.001410,0.003598,0.091389,287.576752,14.649858,0.913886,-307.674744,0.090894,0.000000
128.170013,64.558220,-307.719208,-0.001410,0.003576,0.090834,287.169312,14.629102,0.908337,-307.719208,0.090261,0.000000
128.550003,64.172066,-307.808167,-0.001401,0.003555,0.090305,285.451599,14.541597,0.903046,-307.808167,0.089628,0.000000
128.930008,63.198677,-307.808167,-0.001393,0.003533,0.089732,281.121765,14.321025,0.897323,-307.808167,0.088995,0.000000
129.310013,62.259933,-307.808167,-0.001397,0.003509,0.089116,276.946014,14.108302,0.891161,-307.808167,0.088362,0.000000
129.690002,60.902260,-307.852661,-0.001388,0.003484,0.088483,270.906769,13.800650,0.884833,-307.852661,0.087729,0.000000
130.070007,59.273872,-307.897156,-0.001380,0.003459,0.087868,263.663361,13.431651,0.878679,-307.897156,0.087096,0.000000
130.450012,57.878967,-307.897156,-0.001397,0.003441,0.087391,257.458496,13.115561,0.873910,-307.897156,0.086463,0.000000
130.830002,55.580315,-307.897156,-0.001393,0.003414,0.086706,247.233582,12.594680,0.867059,-307.897156,0.085830,0.000000
131.210007,53.652916,-307.941620,-0.001384,0.003394,0.086202,238.660095,12.157925,0.862025,-307.941620,0.085196,0.000000
131.590012,50.748405,-307.897156,-0.001380,0.003362,0.085387,225.740189,11.499753,0.853872,-307.897156,0.084564,0.000000
131.970001,47.804428,-307.986115,-0.001367,0.003333,0.084667,212.644714,10.832638,0.846673,-307.986115,0.083931,0.000000
132.350006,45.833466,-308.030579,-0.001380,0.003316,0.084225,203.877441,10.386012,0.842253,-308.030579,0.083297,0.000000
132.730011,43.576889,-308.075073,-0.001393,0.003295,0.083705,193.839676,9.874664,0.837052,-308.075073,0.082664,0.000000
133.110001,40.898041,-308.075073,-0.001388,0.003266,0.082968,181.923569,9.267629,0.829679,-308.075073,0.082032,0.000000
133.490005,37.661003,-308.119537,-0.001371,0.003239,0.082265,167.524506,8.534105,0.822654,-308.119537,0.081398,0.000000
133.870010,35.225319,-308.208496,-0.001384,0.003216,0.081684,156.690048,7.982172,0.816841,-308.208496,0.080765,0.000000
134.250000,33.179878,-308.208496,-0.001393,0.003200,0.081268,147.591476,7.518668,0.812678,-308.208496,0.080132,0.000000
134.630005,29.908585,-308.252991,-0.001384,0.003169,0.080496,133.040024,6.777382,0.804964,-308.252991,0.079499,0.000000
135.010010,27.522049,-308.208496,-0.001388,0.003148,0.079950,122.424187,6.236585,0.799498,-308.208496,0.078858,0.000000
135.389999,24.623505,-308.252991,-0.001384,0.003117,0.079178,109.530823,5.579766,0.791777,-308.252991,0.078224,0.000000
135.770004,22.119293,-308.252991,-0.001375,0.003097,0.078658,98.391533,5.012304,0.786577,-308.252991,0.077591,0.000000
136.150009,19.104942,-308.297485,-0.001384,0.003068,0.077938,84.983025,4.329242,0.779378,-308.297485,0.076958,0.000000
136.530014,17.148499,-308.341949,-0.001388,0.003052,0.077521,76.280334,3.885905,0.775215,-308.341949,0.076325,0.000000
136.910004,13.389771,-308.341949,-0.001393,0.003016,0.076602,59.560673,3.034165,0.766025,-308.341949,0.075692,0.000000
137.290009,10.557129,-308.341949,-0.001371,0.002990,0.075943,46.960453,2.392280,0.759432,-308.341949,0.075059,0.000000
137.670013,8.359764,-308.386444,-0.001380,0.002968,0.075388,37.186089,1.894350,0.753883,-308.386444,0.074425,0.000000
138.050003,5.464935,-308.430908,-0.001384,0.002941,0.074703,24.309246,1.238372,0.747032,-308.430908,0.073793,0.000000
138.430008,2.962219,-308.430908,-0.001384,0.002917,0.074104,13.176609,0.671248,0.741045,-308.430908,0.073160,0.000000
138.810013,0.968910,-308.475403,-0.001388,0.002899,0.073645,4.309928,0.219558,0.736450,-308.475403,0.072526,0.000000
139.190002,-1.723713,-308.475403,-0.001384,0.002870,0.072908,-7.667458,-0.390599,0.729077,-308.475403,0.071893,0.000000
139.570007,-4.321011,-308.519867,-0.001375,0.002844,0.072249,-19.220816,-0.979155,0.722491,-308.519867,0.071260,0.000000
139.950012,-0.183205,-308.608826,-0.001406,0.002818,0.071581,-0.814935,-0.041515,0.715814,-308.608826,0.070627,0.000000
140.330002,-0.019363,-308.608826,-0.001414,0.002808,0.071321,-0.086133,-0.004388,0.713210,-308.608826,0.069994,0.000000
140.710007,-0.053993,-308.608826,-0.001397,0.002772,0.070410,-0.240174,-0.012235,0.704104,-308.608826,0.069361,0.000000
141.090012,-0.068146,-308.653320,-0.001406,0.002741,0.069621,-0.303127,-0.015442,0.696209,-308.653320,0.068728,0.000000
141.470001,-0.042076,-308.653320,-0.001427,0.002717,0.069023,-0.187164,-0.009535,0.690229,-308.653320,0.068095,0.000000
141.850006,-0.045433,-308.742279,-0.001466,0.002695,0.068441,-0.202096,-0.010295,0.684415,-308.742279,0.067462,0.000000
142.230011,-0.043571,-308.697815,-0.001487,0.002673,0.067904,-0.193816,-0.009873,0.679040,-308.697815,0.066829,0.000000
142.610001,-0.029045,-308.697815,-0.001535,0.002645,0.067193,-0.129199,-0.006582,0.671932,-308.697815,0.066196,0.000000
142.990005,-0.044312,-308.697815,-0.001561,0.002617,0.066464,-0.197107,-0.010041,0.664643,-308.697815,0.065563,0.000000
143.370010,-0.043198,-308.831238,-0.001595,0.002592,0.065849,-0.192153,-0.009789,0.658488,-308.831238,0.064930,0.000000
143.750000,-0.031281,-308.875732,-0.001604,0.002567,0.065207,-0.139143,-0.007088,0.652069,-308.875732,0.064296,0.000000
144.130005,-0.036491,-308.920197,-0.001651,0.002550,0.064765,-0.162322,-0.008269,0.647649,-308.920197,0.063663,0.000000
144.510010,-0.041702,-308.920197,-0.001681,0.002519,0.063975,-0.185501,-0.009450,0.639753,-308.920197,0.063031,0.000000
144.889999,-0.023087,-308.875732,-0.001699,0.002490,0.063255,-0.102694,-0.005231,0.632554,-308.875732,0.062397,0.000000
145.270004,-0.052505,-308.875732,-0.001729,0.002470,0.062735,-0.233556,-0.011898,0.627354,-308.875732,0.061764,0.000000
145.650009,-0.053619,-309.009155,-0.001742,0.002444,0.062085,-0.238511,-0.012150,0.620851,-309.009155,0.061131,0.000000
146.030014,-0.079689,-308.964691,-0.001763,0.002423,0.061539,-0.354474,-0.018058,0.615386,-308.964691,0.060489,0.000000
146.410004,-0.060326,-309.009155,-0.001811,0.002395,0.060836,-0.268342,-0.013670,0.608361,-309.009155,0.059857,0.000000
146.790009,-0.063675,-309.009155,-0.001828,0.002373,0.060272,-0.283240,-0.014429,0.602722,-309.009155,0.059223,0.000000
147.170013,-0.026070,-309.009155,-0.001863,0.002343,0.059501,-0.115964,-0.005907,0.595008,-309.009155,0.058590,0.000000
147.550003,-0.052132,-309.053650,-0.001880,0.002316,0.058833,-0.231893,-0.011813,0.588332,-309.053650,0.057957,0.000000
147.930008,-0.043938,-309.142609,-0.001910,0.002293,0.058243,-0.195445,-0.009956,0.582435,-309.142609,0.057324,0.000000
148.310013,-0.055115,-309.098114,-0.001944,0.002276,0.057818,-0.245163,-0.012489,0.578181,-309.098114,0.056691,0.000000
148.690002,-0.048782,-309.142609,-0.001953,0.002250,0.057142,-0.216995,-0.011054,0.571421,-309.142609,0.056058,0.000000
149.070007,-0.067398,-309.187103,-0.001979,0.002217,0.056309,-0.299802,-0.015273,0.563094,-309.187103,0.055424,0.000000
149.450012,-0.080063,-309.187103,-0.002031,0.002191,0.055659,-0.356137,-0.018143,0.556592,-309.187103,0.054792,0.000000
149.830002,-0.095329,-309.187103,-0.002031,0.002172,0.055173,-0.424046,-0.021602,0.551732,-309.187103,0.054159,0.000000
150.210007,-0.074844,-309.231567,-0.002087,0.002146,0.054506,-0.332924,-0.016960,0.545055,-309.231567,0.053525,0.000000
150.590012,-0.076340,-309.231567,-0.002078,0.002123,0.053924,-0.339576,-0.017299,0.539242,-309.231567,0.052892,0.000000
150.970001,-0.073357,-309.320526,-0.002117,0.002092,0.053144,-0.326307,-0.016623,0.531437,-309.320526,0.052260,0.000000
151.350006,-0.090858,-309.365021,-0.002160,0.002063,0.052407,-0.404159,-0.020589,0.524072,-309.365021,0.051626,0.000000
151.730011,-0.094955,-309.365021,-0.002177,0.002047,0.051999,-0.422383,-0.021517,0.519992,-309.365021,0.050993,0.000000
152.110001,-0.078568,-309.409485,-0.002216,0.002020,0.051306,-0.349486,-0.017804,0.513058,-309.409485,0.050360,0.000000
152.490005,-0.063301,-309.365021,-0.002220,0.002003,0.050872,-0.281577,-0.014344,0.508720,-309.365021,0.049727,0.000000
152.870010,-0.077454,-309.409485,-0.002251,0.001967,0.049952,-0.344531,-0.017551,0.499523,-309.409485,0.049094,0.000000
153.250000,-0.081551,-309.453979,-0.002285,0.001936,0.049164,-0.362755,-0.018480,0.491635,-309.453979,0.048461,0.000000
153.630005,-0.067772,-309.542938,-0.002307,0.001917,0.048695,-0.301465,-0.015357,0.486949,-309.542938,0.047828,0.000000
154.010010,-0.071869,-309.498444,-0.002328,0.001895,0.048132,-0.319689,-0.016286,0.481318,-309.498444,0.047195,0.000000
154.390015,-0.054367,-309.542938,-0.002371,0.001870,0.047498,-0.241837,-0.012320,0.474982,-309.542938,0.046562,0.000000
154.770004,-0.077454,-309.542938,-0.002380,0.001841,0.046761,-0.344531,-0.017551,0.467609,-309.542938,0.045929,0.000000
155.150009,-0.068520,-309.542938,-0.002414,0.001816,0.046137,-0.304790,-0.015527,0.461371,-309.542938,0.045295,0.000000
155.530014,-0.059578,-309.631897,-0.002436,0.001802,0.045772,-0.265016,-0.013501,0.457722,-309.631897,0.044663,0.000000
155.910004,-0.077454,-309.587433,-0.002479,0.001768,0.044906,-0.344531,-0.017551,0.449055,-309.587433,0.044030,0.000000
156.290009,-0.067772,-309.631897,-0.002488,0.001746,0.044359,-0.301465,-0.015357,0.443590,-309.631897,0.043396,0.000000
156.400009,-0.042450,-309.676392,-0.002505,0.001747,0.044376,-0.188827,-0.009619,0.443764,-309.676392,0.044264,0.000000