File: Data/compression 18/AutoNoHeating-17-18-reverse-2-3_09092024_173627.csv
Time (sec),S:Load (lbs),S:HL1 (DIM),S:LVDT (in),S:Position (in),Ch:Position (mm),Ch:Load (N),Ch:Stress (MPa),Ch:Strain (mm/mm),Ch:HL1 (DIM),Set Point (),Cycles ()
0.110000,-0.025696,-281.164093,-0.011124,-0.006113,-0.155268,-0.114301,-0.005823,-1.552678,-281.164093,-0.155406,0.000000
0.560000,-0.030159,-281.119598,-0.011137,-0.005994,-0.152259,-0.134154,-0.006834,-1.522588,-281.119598,-0.151331,0.000000
1.010000,-0.027184,-281.208588,-0.010934,-0.005717,-0.145199,-0.120918,-0.006160,-1.451992,-281.208588,-0.143838,0.000000
1.460000,-0.081551,-281.208588,-0.010611,-0.005411,-0.137429,-0.362755,-0.018480,-1.374288,-281.208588,-0.136345,0.000000
1.910000,-0.050644,-281.253052,-0.010309,-0.005118,-0.129997,-0.225275,-0.011476,-1.299968,-281.253052,-0.128852,0.000000
2.360000,-0.002975,-281.253052,-0.010033,-0.004830,-0.122686,-0.013236,-0.000674,-1.226859,-281.253052,-0.121342,0.000000
2.810000,-0.013405,-281.297546,-0.009697,-0.004531,-0.115098,-0.059628,-0.003038,-1.150979,-281.297546,-0.113849,0.000000
3.260000,-0.051758,-281.386505,-0.009412,-0.004242,-0.107753,-0.230230,-0.011728,-1.077529,-281.386505,-0.106356,0.000000
3.710000,-0.037979,-281.386505,-0.009115,-0.003942,-0.100121,-0.168940,-0.008606,-1.001211,-281.386505,-0.098864,0.000000
4.160000,0.001488,-281.386505,-0.008800,-0.003643,-0.092541,0.006618,0.000337,-0.925414,-281.386505,-0.091370,0.000000
4.610000,-0.032394,-281.430969,-0.008507,-0.003346,-0.084979,-0.144098,-0.007341,-0.849792,-281.430969,-0.083860,0.000000
5.060000,-0.007072,-281.519928,-0.008196,-0.003057,-0.077660,-0.031460,-0.001603,-0.776600,-281.519928,-0.076368,0.000000
5.510000,-0.040215,-281.475464,-0.007907,-0.002758,-0.070063,-0.178883,-0.009113,-0.700629,-281.475464,-0.068874,0.000000
5.960001,-0.073357,-281.519928,-0.007601,-0.002465,-0.062614,-0.326307,-0.016623,-0.626135,-281.519928,-0.061382,0.000000
6.410000,-0.005211,-281.564423,-0.007286,-0.002168,-0.055077,-0.023179,-0.001181,-0.550770,-281.564423,-0.053872,0.000000
6.860000,0.018990,-281.564423,-0.006976,-0.001876,-0.047654,0.084470,0.004303,-0.476541,-281.564423,-0.046379,0.000000
7.310000,-0.034256,-281.697876,-0.006674,-0.001579,-0.040118,-0.152378,-0.007763,-0.401176,-281.697876,-0.038886,0.000000
7.760000,-0.031654,-281.697876,-0.006372,-0.001283,-0.032599,-0.140806,-0.007173,-0.325985,-281.697876,-0.031393,0.000000
8.210000,-0.041336,-281.697876,-0.006096,-0.000988,-0.025106,-0.183872,-0.009367,-0.251060,-281.697876,-0.023883,0.000000
8.660001,-0.013031,-281.742340,-0.005764,-0.000691,-0.017544,-0.057965,-0.002953,-0.175437,-281.742340,-0.016390,0.000000
9.110001,-0.006332,-281.786835,-0.005476,-0.000397,-0.010086,-0.028168,-0.001435,-0.100860,-281.786835,-0.008898,0.000000
9.560000,-0.023834,-281.831299,-0.005182,-0.000103,-0.002610,-0.106020,-0.005401,-0.026101,-281.831299,-0.001405,0.000000
10.010000,-0.054741,-281.831299,-0.004868,0.000195,0.004943,-0.243500,-0.012404,0.049431,-281.831299,0.006106,0.000000
10.460000,0.159744,-281.920258,-0.004682,-0.000000,-0.000008,0.710578,0.036199,-0.000083,-281.920258,0.000191,0.000000
10.910001,0.161606,-281.875793,-0.004708,-0.000001,-0.000017,0.718859,0.036620,-0.000174,-281.875793,0.000408,0.000000
11.360001,0.100914,-282.009216,-0.004704,-0.000000,-0.000008,0.448888,0.022867,-0.000083,-282.009216,0.001163,0.000000
11.810000,0.248001,-281.964752,-0.004695,0.000034,0.000859,1.103164,0.056198,0.008592,-281.964752,0.001908,0.000000
12.260000,0.398811,-282.009216,-0.004648,0.000070,0.001769,1.774001,0.090372,0.017691,-282.009216,0.002663,0.000000
12.710001,0.546272,-282.098206,-0.004626,0.000096,0.002437,2.429940,0.123787,0.024375,-282.098206,0.003409,0.000000
13.160001,0.862045,-282.009216,-0.004600,0.000129,0.003287,3.834569,0.195342,0.032868,-282.009216,0.004163,0.000000
13.610001,1.108925,-282.142670,-0.004583,0.000150,0.003816,4.932744,0.251286,0.038159,-282.142670,0.004909,0.000000
14.060000,1.499168,-282.142670,-0.004540,0.000183,0.004649,6.668634,0.339716,0.046486,-282.142670,0.005663,0.000000
14.510000,1.872292,-282.187164,-0.004523,0.000214,0.005446,8.328369,0.424267,0.054465,-282.187164,0.006409,0.000000
14.960001,2.354507,-282.142670,-0.004497,0.000246,0.006244,10.473372,0.533539,0.062443,-282.142670,0.007163,0.000000
15.410001,2.815880,-282.187164,-0.004475,0.000275,0.006973,12.525659,0.638087,0.069725,-282.187164,0.007910,0.000000
15.860001,3.183037,-282.276123,-0.004458,0.000298,0.007580,14.158854,0.721286,0.075796,-282.276123,0.008664,0.000000
16.310001,3.685371,-282.320587,-0.004415,0.000329,0.008369,16.393351,0.835117,0.083692,-282.320587,0.009410,0.000000
16.760000,4.238342,-282.320587,-0.004389,0.000363,0.009210,18.853088,0.960422,0.092102,-282.320587,0.010164,0.000000
17.210001,4.756683,-282.454041,-0.004372,0.000392,0.009956,21.158785,1.077880,0.099558,-282.454041,0.010910,0.000000
17.660002,5.139488,-282.454041,-0.004337,0.000417,0.010580,22.861586,1.164625,0.105803,-282.454041,0.011664,0.000000
18.110001,5.794113,-282.454041,-0.004312,0.000454,0.011526,25.773502,1.312965,0.115258,-282.454041,0.012411,0.000000
18.560001,6.117332,-282.409546,-0.004281,0.000483,0.012271,27.211254,1.386207,0.122714,-282.409546,0.013165,0.000000
19.010000,6.582428,-282.587494,-0.004264,0.000514,0.013052,29.280102,1.491600,0.130518,-282.587494,0.013910,0.000000
19.460001,6.787231,-282.587494,-0.004225,0.000535,0.013598,30.191113,1.538009,0.135984,-282.587494,0.014665,0.000000
19.910002,7.166306,-282.587494,-0.004212,0.000562,0.014266,31.877319,1.623908,0.142660,-282.587494,0.015411,0.000000
20.360001,7.625816,-282.720917,-0.004174,0.000596,0.015142,33.921326,1.728035,0.151419,-282.720917,0.016165,0.000000
20.810001,7.901001,-282.765411,-0.004148,0.000629,0.015984,35.145409,1.790392,0.159836,-282.765411,0.016911,0.000000
21.260000,8.139687,-282.720917,-0.004122,0.000656,0.016669,36.207134,1.844479,0.166687,-282.720917,0.017666,0.000000
21.710001,8.271881,-282.720917,-0.004100,0.000679,0.017249,36.795166,1.874435,0.172493,-282.720917,0.018411,0.000000
22.160002,8.596588,-282.809875,-0.004061,0.000712,0.018090,38.239532,1.948015,0.180903,-282.809875,0.019158,0.000000
22.610001,9.001732,-282.809875,-0.004049,0.000745,0.018923,40.041702,2.039822,0.189230,-282.809875,0.019912,0.000000
23.060001,9.305962,-282.898834,-0.004001,0.000780,0.019808,41.394985,2.108761,0.198079,-282.898834,0.020658,0.000000
23.510000,9.231857,-282.943329,-0.003988,0.000802,0.020371,41.065353,2.091969,0.203711,-282.943329,0.021412,0.000000
23.960001,9.611305,-282.943329,-0.003936,0.000838,0.021273,42.753220,2.177953,0.212734,-282.943329,0.022158,0.000000
24.410002,9.588593,-282.943329,-0.003919,0.000864,0.021950,42.652191,2.172806,0.219501,-282.943329,0.022912,0.000000
24.860001,9.591194,-283.032288,-0.003902,0.000887,0.022531,42.663761,2.173396,0.225307,-283.032288,0.023658,0.000000
25.310001,9.983681,-283.032288,-0.003859,0.000915,0.023242,44.409630,2.262334,0.232423,-283.032288,0.024413,0.000000
25.760002,10.410416,-283.121246,-0.003837,0.000954,0.024239,46.307842,2.359034,0.242392,-283.121246,0.025158,0.000000
26.210001,10.232048,-283.121246,-0.003807,0.000978,0.024829,45.514423,2.318615,0.248289,-283.121246,0.025913,0.000000
26.660002,10.222366,-283.165741,-0.003781,0.001000,0.025410,45.471355,2.316421,0.254103,-283.165741,0.026659,0.000000
27.110001,10.718369,-283.121246,-0.003751,0.001034,0.026269,47.677685,2.428817,0.262687,-283.121246,0.027413,0.000000
27.560001,10.869926,-283.254700,-0.003725,0.001065,0.027049,48.351849,2.463161,0.270491,-283.254700,0.028159,0.000000
28.010002,11.178993,-283.254700,-0.003678,0.001102,0.027995,49.726646,2.533196,0.279946,-283.254700,0.028914,0.000000
28.460001,11.035255,-283.299164,-0.003665,0.001126,0.028593,49.087269,2.500625,0.285926,-283.299164,0.029659,0.000000
28.910002,11.449333,-283.343658,-0.003626,0.001158,0.029425,50.929176,2.594456,0.294253,-283.343658,0.030414,0.000000
29.360001,11.477264,-283.388153,-0.003600,0.001185,0.030110,51.053421,2.600785,0.301104,-283.388153,0.031160,0.000000
29.810001,11.889854,-283.388153,-0.003574,0.001223,0.031056,52.888714,2.694279,0.310558,-283.388153,0.031914,0.000000
30.260002,11.791916,-283.432617,-0.003535,0.001247,0.031671,52.453060,2.672086,0.316712,-283.432617,0.032660,0.000000
30.710001,11.982948,-283.477112,-0.003510,0.001276,0.032409,53.302814,2.715375,0.324085,-283.477112,0.033415,0.000000
31.160002,12.314728,-283.521576,-0.003497,0.001306,0.033172,54.778645,2.790557,0.331716,-283.521576,0.034160,0.000000
31.610001,12.457718,-283.477112,-0.003466,0.001334,0.033874,55.414696,2.822959,0.338741,-283.477112,0.034915,0.000000
32.060001,12.751526,-283.566071,-0.003436,0.001367,0.034724,56.721619,2.889537,0.347241,-283.566071,0.035661,0.000000
32.510002,12.616348,-283.566071,-0.003419,0.001392,0.035366,56.120319,2.858905,0.353661,-283.566071,0.036415,0.000000
32.960003,12.907921,-283.655029,-0.003385,0.001422,0.036120,57.417301,2.924977,0.361200,-283.655029,0.037161,0.000000
33.410000,13.171188,-283.699493,-0.003359,0.001452,0.036875,58.588371,2.984634,0.368747,-283.699493,0.037916,0.000000
33.860001,13.546165,-283.743988,-0.003316,0.001485,0.037725,60.256355,3.069605,0.377248,-283.743988,0.038661,0.000000
34.310001,13.589363,-283.832947,-0.003290,0.001514,0.038445,60.448505,3.079394,0.384447,-283.832947,0.039416,0.000000
34.760002,13.988914,-283.788483,-0.003268,0.001545,0.039251,62.225800,3.169933,0.392509,-283.788483,0.040162,0.000000
35.210003,13.931198,-283.743988,-0.003234,0.001569,0.039841,61.969063,3.156855,0.398406,-283.743988,0.040916,0.000000
35.660000,14.431664,-283.877441,-0.003199,0.001604,0.040734,64.195244,3.270262,0.407338,-283.877441,0.041662,0.000000
36.110001,14.688232,-283.877441,-0.003178,0.001634,0.041514,65.336517,3.328401,0.415142,-283.877441,0.042417,0.000000
36.560001,14.873299,-283.877441,-0.003152,0.001662,0.042217,66.159737,3.370338,0.422167,-283.877441,0.043162,0.000000
37.010002,14.865852,-283.921906,-0.003126,0.001685,0.042806,66.126617,3.368650,0.428064,-283.921906,0.043917,0.000000
37.460003,15.557724,-283.877441,-0.003100,0.001725,0.043804,69.204216,3.525430,0.438041,-283.877441,0.044663,0.000000
37.910004,15.678368,-284.010864,-0.003065,0.001751,0.044472,69.740860,3.552769,0.444718,-284.010864,0.045417,0.000000
38.360001,15.997864,-284.010864,-0.003031,0.001783,0.045278,71.162048,3.625168,0.452779,-284.010864,0.046163,0.000000
38.810001,15.929352,-284.055359,-0.003014,0.001805,0.045850,70.857292,3.609643,0.458502,-284.055359,0.046918,0.000000
39.260002,16.729576,-284.099823,-0.002975,0.001843,0.046813,74.416870,3.790976,0.468131,-284.099823,0.047663,0.000000
39.710003,16.835701,-284.144318,-0.002945,0.001872,0.047541,74.888939,3.815024,0.475413,-284.144318,0.048417,0.000000
40.160004,16.862885,-284.144318,-0.002932,0.001897,0.048183,75.009857,3.821184,0.481832,-284.144318,0.049164,0.000000
40.610001,17.189461,-284.188782,-0.002889,0.001927,0.048938,76.462540,3.895187,0.489379,-284.188782,0.049917,0.000000
41.060001,17.206215,-284.233276,-0.002876,0.001949,0.049502,76.537064,3.898984,0.495019,-284.233276,0.050664,0.000000
41.510002,17.987450,-284.277771,-0.002846,0.001986,0.050438,80.012169,4.076015,0.504383,-284.277771,0.051409,0.000000
41.960003,18.254066,-284.322235,-0.002815,0.002017,0.051227,81.198143,4.136431,0.512270,-284.322235,0.052164,0.000000
42.410004,18.601868,-284.366730,-0.002794,0.002046,0.051956,82.745239,4.215243,0.519560,-284.366730,0.052910,0.000000
42.860001,18.304710,-284.366730,-0.002764,0.002063,0.052406,81.423416,4.147907,0.524064,-284.366730,0.053665,0.000000
43.310001,19.527954,-284.411194,-0.002734,0.002105,0.053456,86.864677,4.425097,0.534563,-284.411194,0.054410,0.000000
43.760002,19.039406,-284.455688,-0.002721,0.002120,0.053855,84.691505,4.314391,0.538553,-284.455688,0.055165,0.000000
44.210003,20.200462,-284.411194,-0.002686,0.002163,0.054939,89.856148,4.577490,0.549393,-284.411194,0.055910,0.000000
44.660004,20.156151,-284.500153,-0.002652,0.002187,0.055537,89.659035,4.567449,0.555373,-284.500153,0.056665,0.000000
45.110001,21.217041,-284.500153,-0.002621,0.002226,0.056535,94.378113,4.807850,0.565350,-284.500153,0.057411,0.000000
45.560001,21.338058,-284.589111,-0.002600,0.002253,0.057237,94.916428,4.835273,0.572375,-284.589111,0.058165,0.000000
46.010002,21.252411,-284.589111,-0.002570,0.002275,0.057792,94.535446,4.815865,0.577923,-284.589111,0.058911,0.000000
46.460003,21.844482,-284.633606,-0.002557,0.002303,0.058495,97.169113,4.950030,0.584948,-284.633606,0.059665,0.000000
46.910004,22.438049,-284.678101,-0.002531,0.002332,0.059240,99.809425,5.084535,0.592404,-284.678101,0.060411,0.000000
47.360001,22.678596,-284.722565,-0.002492,0.002366,0.060099,100.879433,5.139043,0.600988,-284.722565,0.061165,0.000000
47.810001,23.609528,-284.722565,-0.002483,0.002397,0.060879,105.020424,5.349995,0.608793,-284.722565,0.061912,0.000000
48.260002,23.316475,-284.811523,-0.002453,0.002423,0.061539,103.716858,5.283589,0.615386,-284.811523,0.062666,0.000000
48.710003,24.870758,-284.767059,-0.002423,0.002455,0.062362,110.630653,5.635795,0.623622,-284.767059,0.063412,0.000000
49.160004,25.729820,-284.856018,-0.002393,0.002489,0.063230,114.451958,5.830461,0.632297,-284.856018,0.064166,0.000000
49.610001,25.751045,-284.856018,-0.002367,0.002515,0.063880,114.546371,5.835270,0.638799,-284.856018,0.064912,0.000000
50.060001,25.447189,-284.900482,-0.002350,0.002532,0.064323,113.194748,5.766416,0.643228,-284.900482,0.065666,0.000000
50.510002,27.112068,-284.989441,-0.002311,0.002574,0.065372,120.600502,6.143682,0.653719,-284.989441,0.066413,0.000000
50.960003,28.054169,-285.033936,-0.002289,0.002608,0.066248,124.791176,6.357166,0.662478,-285.033936,0.067167,0.000000
51.410004,28.232910,-285.033936,-0.002276,0.002635,0.066941,125.586258,6.397669,0.669412,-285.033936,0.067912,0.000000
51.860001,28.580330,-285.078430,-0.002233,0.002661,0.067600,127.131660,6.476395,0.676005,-285.078430,0.068667,0.000000
52.310001,28.999619,-285.122894,-0.002220,0.002688,0.068286,128.996750,6.571408,0.682856,-285.122894,0.069413,0.000000
52.760002,30.102219,-285.078430,-0.002186,0.002720,0.069083,133.901352,6.821260,0.690834,-285.078430,0.070167,0.000000
53.210003,30.997772,-285.122894,-0.002173,0.002751,0.069881,137.884979,7.024196,0.698813,-285.122894,0.070913,0.000000
53.660004,31.808426,-285.211853,-0.002126,0.002780,0.070609,141.490952,7.207892,0.706095,-285.211853,0.071668,0.000000
54.110004,32.561737,-285.256348,-0.002117,0.002808,0.071312,144.841843,7.378595,0.713120,-285.256348,0.072413,0.000000
54.560001,33.150833,-285.256348,-0.002095,0.002837,0.072067,147.462265,7.512086,0.720667,-285.256348,0.073168,0.000000
55.010002,34.899490,-285.300812,-0.002074,0.002875,0.073020,155.240692,7.908338,0.730205,-285.300812,0.073914,0.000000
55.460003,35.205582,-285.300812,-0.002039,0.002899,0.073637,156.602249,7.977699,0.736366,-285.300812,0.074668,0.000000
55.910004,36.257904,-285.389771,-0.002022,0.002929,0.074408,161.283218,8.216158,0.744080,-285.389771,0.075414,0.000000
56.360004,36.563622,-285.345306,-0.002005,0.002952,0.074980,162.643112,8.285435,0.749803,-285.345306,0.076169,0.000000
56.810001,38.154396,-285.434265,-0.001975,0.002989,0.075908,169.719223,8.645909,0.759083,-285.434265,0.076914,0.000000
57.260002,39.246941,-285.434265,-0.001944,0.003020,0.076698,174.579117,8.893484,0.766979,-285.434265,0.077669,0.000000
57.710003,40.146965,-285.434265,-0.001940,0.003046,0.077374,178.582626,9.097433,0.773739,-285.434265,0.078415,0.000000
58.160004,41.125557,-285.567719,-0.001923,0.003076,0.078129,182.935608,9.319184,0.781286,-285.567719,0.079169,0.000000
58.610004,42.436310,-285.478729,-0.001880,0.003110,0.078987,188.766129,9.616205,0.789870,-285.478729,0.079915,0.000000
59.060001,42.746872,-285.567719,-0.001867,0.003127,0.079421,190.147583,9.686580,0.794207,-285.567719,0.080670,0.000000
59.510002,44.498878,-285.656677,-0.001858,0.003166,0.080427,197.940903,10.083590,0.804267,-285.656677,0.081415,0.000000
59.960003,45.666267,-285.701141,-0.001824,0.003194,0.081138,203.133698,10.348124,0.811383,-285.701141,0.082170,0.000000
60.410004,46.822861,-285.656677,-0.001824,0.003221,0.081823,208.278488,10.610212,0.818234,-285.656677,0.082916,0.000000
60.860004,48.917084,-285.745636,-0.001794,0.003259,0.082785,217.594055,11.084770,0.827855,-285.745636,0.083670,0.000000
61.310001,49.724754,-285.790100,-0.001763,0.003285,0.083427,221.186752,11.267791,0.834274,-285.790100,0.084416,0.000000
61.760002,51.270477,-285.790100,-0.001742,0.003315,0.084208,228.062469,11.618056,0.842079,-285.790100,0.085162,0.000000
62.210003,51.718063,-285.790100,-0.001725,0.003338,0.084789,230.053436,11.719481,0.847892,-285.790100,0.085916,0.000000
62.660004,53.143509,-285.790100,-0.001707,0.003372,0.085648,236.394135,12.042492,0.856476,-285.790100,0.086662,0.000000
63.110004,55.513657,-285.879059,-0.001686,0.003403,0.086445,246.937073,12.579574,0.864455,-285.879059,0.087417,0.000000
63.560001,57.053795,-285.879059,-0.001669,0.003433,0.087200,253.787949,12.928575,0.872002,-285.879059,0.088162,0.000000
64.010002,57.799652,-285.968048,-0.001660,0.003454,0.087729,257.105682,13.097589,0.877286,-285.968048,0.088917,0.000000
64.460007,60.023087,-285.968048,-0.001660,0.003493,0.088717,266.996033,13.601425,0.887172,-285.968048,0.089663,0.000000
64.910004,61.011742,-285.968048,-0.001617,0.003515,0.089273,271.393768,13.825458,0.892728,-285.968048,0.090417,0.000000
65.360001,63.085854,-286.057007,-0.001604,0.003546,0.090079,280.619904,14.295459,0.900790,-286.057007,0.091163,0.000000
65.810005,65.154015,-286.012512,-0.001587,0.003579,0.090912,289.819519,14.764111,0.909117,-286.012512,0.091918,0.000000
66.260002,66.155312,-286.101471,-0.001565,0.003602,0.091501,294.273529,14.991008,0.915013,-286.101471,0.092663,0.000000
66.710007,65.483559,-286.101471,-0.001561,0.003602,0.091484,291.285431,14.838787,0.914839,-286.101471,294.500488,0.000000
67.160004,66.174675,-286.145966,-0.001539,0.003651,0.092733,294.359650,14.995396,0.927330,-286.145966,294.500488,0.000000
67.610001,65.161827,-286.190430,-0.001522,0.003603,0.091510,289.854279,14.765881,0.915097,-286.190430,294.500488,0.000000
68.060005,65.199806,-286.234924,-0.001509,0.003625,0.092065,290.023224,14.774487,0.920653,-286.234924,294.500488,0.000000
68.510002,66.355278,-286.279388,-0.001522,0.003598,0.091389,295.163025,15.036321,0.913886,-286.279388,294.500488,0.000000
68.960007,65.554680,-286.368378,-0.001518,0.003621,0.091961,291.601776,14.854903,0.919608,-286.368378,294.500488,0.000000
69.410004,65.125343,-286.279388,-0.001526,0.003649,0.092681,289.691986,14.757614,0.926807,-286.279388,294.500488,0.000000
69.860001,65.225883,-286.368378,-0.001487,0.003657,0.092889,290.139221,14.780396,0.928889,-286.368378,294.500488,0.000000
70.310005,65.135017,-286.368378,-0.001492,0.003663,0.093045,289.735016,14.759806,0.930448,-286.368378,294.500488,0.000000
70.760002,65.170021,-286.368378,-0.001479,0.003668,0.093167,289.890747,14.767738,0.931667,-286.368378,294.500488,0.000000
71.210007,65.015480,-286.457336,-0.001487,0.003671,0.093245,289.203308,14.732718,0.932447,-286.457336,294.500488,0.000000
71.660004,64.894463,-286.457336,-0.001470,0.003677,0.093401,288.664978,14.705296,0.934006,-286.457336,294.500488,0.000000
72.110001,65.000587,-286.546295,-0.001492,0.003680,0.093461,289.137054,14.729344,0.934612,-286.546295,294.500488,0.000000
72.560005,65.181190,-286.590759,-0.001466,0.003685,0.093609,289.940430,14.770268,0.936088,-286.590759,294.500488,0.000000
73.010002,64.918663,-286.590759,-0.001483,0.003686,0.093626,288.772644,14.710779,0.936262,-286.590759,294.500488,0.000000
73.460007,65.845131,-286.635254,-0.001466,0.003698,0.093938,292.893768,14.920719,0.939381,-286.635254,294.500488,0.000000
73.910004,65.518929,-286.679718,-0.001453,0.003698,0.093938,291.442749,14.846802,0.939381,-286.679718,294.500488,0.000000
74.360001,65.239662,-286.635254,-0.001462,0.003698,0.093938,290.200500,14.783519,0.939381,-286.635254,294.500488,0.000000
74.810005,64.944740,-286.768677,-0.001449,0.003698,0.093938,288.888641,14.716688,0.939381,-286.768677,294.500488,0.000000
75.260002,64.650932,-286.724213,-0.001453,0.003698,0.093938,287.581696,14.650110,0.939381,-286.724213,294.500488,0.000000
75.710007,64.385429,-286.768677,-0.001453,0.003698,0.093938,286.400696,14.589947,0.939381,-286.768677,294.500488,0.000000
76.160004,66.316185,-286.768677,-0.001457,0.003679,0.093435,294.989136,15.027463,0.934354,-286.768677,294.500488,0.000000
76.610001,66.000038,-286.813171,-0.001453,0.003679,0.093435,293.582825,14.955822,0.934354,-286.813171,294.500488,0.000000
77.060005,65.741234,-286.857666,-0.001444,0.003679,0.093435,292.431610,14.897177,0.934354,-286.857666,294.500488,0.000000
77.510002,65.483559,-286.946625,-0.001444,0.003679,0.093444,291.285431,14.838787,0.934438,-286.946625,294.500488,0.000000
77.960007,65.231468,-286.946625,-0.001427,0.003679,0.093453,290.164062,14.781662,0.934528,-286.946625,294.500488,0.000000
78.410004,65.092567,-286.991089,-0.001423,0.003705,0.094111,289.546204,14.750187,0.941114,-286.991089,294.500488,0.000000
78.860001,65.225502,-287.035583,-0.001436,0.003718,0.094441,290.137512,14.780310,0.944415,-287.035583,294.500488,0.000000
79.310005,65.092567,-287.035583,-0.001444,0.003718,0.094441,289.546204,14.750187,0.944415,-287.035583,294.500488,0.000000
79.760002,65.082893,-287.124542,-0.001436,0.003722,0.094528,289.503174,14.747994,0.945278,-287.124542,294.500488,0.000000
80.210007,65.102257,-287.080048,-0.001436,0.003724,0.094580,289.589294,14.752382,0.945800,-287.080048,294.500488,0.000000
80.660004,65.018089,-287.169006,-0.001431,0.003724,0.094597,289.214905,14.733310,0.945974,-287.169006,294.500488,0.000000
81.110001,65.283974,-287.169006,-0.001436,0.003729,0.094728,290.397614,14.793560,0.947276,-287.169006,294.500488,0.000000
81.560005,65.206139,-287.257996,-0.001440,0.003729,0.094728,290.051392,14.775923,0.947276,-287.257996,294.500488,0.000000
82.010002,65.044167,-287.257996,-0.001427,0.003730,0.094745,289.330902,14.739220,0.947450,-287.257996,294.500488,0.000000
82.460007,65.969505,-287.391418,-0.001431,0.003740,0.094996,293.447021,14.948903,0.949963,-287.391418,294.500488,0.000000
82.910004,65.815712,-287.302460,-0.001427,0.003740,0.094996,292.762909,14.914053,0.949963,-287.302460,294.500488,0.000000
83.360001,65.671974,-287.302460,-0.001418,0.003740,0.094996,292.123535,14.881482,0.949963,-287.302460,294.500488,0.000000
83.810005,65.549461,-287.435913,-0.001414,0.003740,0.094996,291.578552,14.853720,0.949963,-287.435913,294.500488,0.000000
84.260002,65.408333,-287.391418,-0.001423,0.003740,0.095005,290.950806,14.821740,0.950046,-287.391418,294.500488,0.000000
84.710007,65.273170,-287.480377,-0.001431,0.003740,0.095005,290.349548,14.791112,0.950046,-287.480377,294.500488,0.000000
85.160004,65.176353,-287.480377,-0.001418,0.003740,0.095005,289.918915,14.769173,0.950046,-287.480377,294.500488,0.000000
85.610001,65.038567,-287.480377,-0.001418,0.003741,0.095022,289.306000,14.737949,0.950221,-287.480377,294.500488,0.000000
86.060005,64.946220,-287.569336,-0.001410,0.003741,0.095031,288.895203,14.717024,0.950311,-287.569336,294.500488,0.000000
86.510002,64.827446,-287.569336,-0.001418,0.003741,0.095031,288.366882,14.690109,0.950311,-287.569336,294.500488,0.000000
86.960007,64.743660,-287.613831,-0.001418,0.003742,0.095049,287.994171,14.671123,0.950486,-287.613831,294.500488,0.000000
87.410004,66.107277,-287.658325,-0.001414,0.003754,0.095343,294.059845,14.980124,0.953430,-287.658325,294.500488,0.000000
87.860001,65.933006,-287.658325,-0.001410,0.003753,0.095335,293.284668,14.940633,0.953347,-287.658325,294.500488,0.000000
88.310005,65.835823,-287.702789,-0.001406,0.003753,0.095335,292.852356,14.918611,0.953347,-287.702789,294.500488,0.000000
88.760002,65.691719,-287.791748,-0.001410,0.003753,0.095335,292.211365,14.885957,0.953347,-287.791748,294.500488,0.000000
89.210007,65.586327,-287.791748,-0.001401,0.003753,0.095335,291.742554,14.862074,0.953347,-287.791748,294.500488,0.000000
89.660004,65.467171,-287.747284,-0.001406,0.003753,0.095335,291.212524,14.835073,0.953347,-287.747284,294.500488,0.000000
90.110001,65.350624,-287.791748,-0.001397,0.003753,0.095335,290.694092,14.808662,0.953347,-287.791748,294.500488,0.000000
90.560005,65.258644,-287.880707,-0.001418,0.003753,0.095335,290.284943,14.787820,0.953347,-287.880707,294.500488,0.000000
91.010002,65.158852,-287.836243,-0.001397,0.003753,0.095335,289.841034,14.765207,0.953347,-287.836243,294.500488,0.000000
91.460007,65.050117,-287.969666,-0.001401,0.003753,0.095335,289.357361,14.740567,0.953347,-287.969666,294.500488,0.000000
91.910004,64.968193,-287.925201,-0.001397,0.003753,0.095335,288.992950,14.722003,0.953347,-287.925201,294.500488,0.000000
92.360001,65.763954,-288.014160,-0.001406,0.003765,0.095629,292.532684,14.902325,0.956292,-288.014160,294.500488,0.000000
92.810005,65.769173,-288.058624,-0.001393,0.003765,0.095629,292.555878,14.903507,0.956292,-288.058624,294.500488,0.000000
93.260002,65.737511,-288.014160,-0.001397,0.003765,0.095629,292.415039,14.896333,0.956292,-288.014160,294.500488,0.000000
93.710007,65.632881,-288.103119,-0.001406,0.003765,0.095629,291.949646,14.872623,0.956292,-288.103119,294.500488,0.000000
94.160004,65.574791,-288.147614,-0.001397,0.003765,0.095629,291.691223,14.859460,0.956292,-288.147614,294.500488,0.000000
94.610008,65.522285,-288.192078,-0.001401,0.003765,0.095629,291.457672,14.847562,0.956292,-288.192078,294.500488,0.000000
95.060005,65.447807,-288.236572,-0.001397,0.003765,0.095638,291.126373,14.830686,0.956382,-288.236572,294.500488,0.000000
95.510002,65.349510,-288.236572,-0.001410,0.003765,0.095638,290.689148,14.808411,0.956382,-288.236572,294.500488,0.000000
95.960007,65.303337,-288.281036,-0.001393,0.003765,0.095638,290.483765,14.797948,0.956382,-288.281036,294.500488,0.000000
96.410004,65.214333,-288.325531,-0.001393,0.003765,0.095638,290.087830,14.777779,0.956382,-288.325531,294.500488,0.000000
96.860008,65.157356,-288.325531,-0.001410,0.003765,0.095638,289.834381,14.764868,0.956382,-288.325531,294.500488,0.000000
97.310005,65.063148,-288.369995,-0.001401,0.003765,0.095638,289.415344,14.743520,0.956382,-288.369995,294.500488,0.000000
97.760002,65.013252,-288.458954,-0.001401,0.003765,0.095638,289.193390,14.732214,0.956382,-288.458954,294.500488,0.000000
98.210007,64.943245,-288.503448,-0.001388,0.003765,0.095638,288.881989,14.716350,0.956382,-288.503448,294.500488,0.000000
98.660004,64.865791,-288.547943,-0.001393,0.003765,0.095638,288.537445,14.698799,0.956382,-288.547943,294.500488,0.000000
99.110008,65.749809,-288.547943,-0.001397,0.003776,0.095915,292.469757,14.899120,0.959153,-288.547943,294.500488,0.000000
99.560005,65.760231,-288.547943,-0.001388,0.003776,0.095915,292.516113,14.901482,0.959153,-288.547943,294.500488,0.000000
100.010002,65.675697,-288.503448,-0.001388,0.003776,0.095915,292.140106,14.882326,0.959153,-288.503448,294.500488,0.000000
100.460007,65.632515,-288.636902,-0.001388,0.003776,0.095915,291.947998,14.872540,0.959153,-288.636902,294.500488,0.000000
100.910004,65.587456,-288.681366,-0.001384,0.003776,0.095915,291.747589,14.862329,0.959153,-288.681366,294.500488,0.000000
101.360008,65.551338,-288.770325,-0.001393,0.003776,0.095915,291.586914,14.854146,0.959153,-288.770325,294.500488,0.000000
101.810005,65.516701,-288.725861,-0.001393,0.003776,0.095915,291.432831,14.846296,0.959153,-288.725861,294.500488,0.000000
102.260002,65.441109,-288.770325,-0.001388,0.003776,0.095915,291.096588,14.829167,0.959153,-288.770325,294.500488,0.000000
102.710007,65.362907,-288.814819,-0.001371,0.003776,0.095915,290.748718,14.811446,0.959153,-288.814819,294.500488,0.000000
103.160004,65.311897,-288.814819,-0.001375,0.003776,0.095915,290.521820,14.799888,0.959153,-288.814819,294.500488,0.000000
103.610008,65.280251,-288.859283,-0.001388,0.003776,0.095915,290.381042,14.792717,0.959153,-288.859283,294.500488,0.000000
104.060005,65.214333,-288.903778,-0.001388,0.003776,0.095915,290.087830,14.777779,0.959153,-288.903778,294.500488,0.000000
104.510002,65.162575,-288.903778,-0.001401,0.003776,0.095915,289.857605,14.766050,0.959153,-288.903778,294.500488,0.000000
104.960007,65.075432,-288.903778,-0.001380,0.003776,0.095915,289.469971,14.746304,0.959153,-288.903778,294.500488,0.000000
105.410004,65.030388,-289.037231,-0.001388,0.003777,0.095924,289.269623,14.736096,0.959244,-289.037231,294.500488,0.000000
105.860008,64.986443,-289.037231,-0.001380,0.003777,0.095924,289.074127,14.726138,0.959244,-289.037231,294.500488,0.000000
106.310005,64.940269,-289.081696,-0.001393,0.003777,0.095924,288.868744,14.715675,0.959244,-289.081696,294.500488,0.000000
106.760002,64.880318,-289.081696,-0.001388,0.003777,0.095924,288.602081,14.702090,0.959244,-289.081696,294.500488,0.000000
107.210007,64.813667,-289.170654,-0.001397,0.003777,0.095924,288.305603,14.686987,0.959244,-289.170654,294.500488,0.000000
107.660004,64.763023,-289.170654,-0.001388,0.003777,0.095924,288.080322,14.675510,0.959244,-289.170654,294.500488,0.000000
108.110008,64.710884,-289.170654,-0.001388,0.003777,0.095924,287.848389,14.663696,0.959244,-289.170654,294.500488,0.000000
108.560005,64.681099,-289.259613,-0.001393,0.003777,0.095924,287.715912,14.656946,0.959244,-289.259613,294.500488,0.000000
109.010002,64.620399,-289.215149,-0.001384,0.003777,0.095924,287.445892,14.643191,0.959244,-289.215149,294.500488,0.000000
109.460007,66.354164,-289.304108,-0.001375,0.003786,0.096167,295.158051,15.036069,0.961666,-289.304108,294.500488,0.000000
109.910004,66.253990,-289.304108,-0.001384,0.003786,0.096167,294.712463,15.013369,0.961666,-289.304108,294.500488,0.000000
110.360008,66.201500,-289.348572,-0.001384,0.003786,0.096167,294.478973,15.001474,0.961666,-289.348572,294.500488,0.000000
110.810005,66.129631,-289.437561,-0.001388,0.003786,0.096158,294.159302,14.985188,0.961583,-289.437561,294.500488,0.000000
111.260002,66.090523,-289.393066,-0.001371,0.003786,0.096158,293.985321,14.976327,0.961583,-289.393066,294.500488,0.000000
111.710007,66.022758,-289.526520,-0.001375,0.003786,0.096158,293.683899,14.960971,0.961583,-289.526520,294.500488,0.000000
112.160004,65.988121,-289.570984,-0.001388,0.003786,0.096158,293.529816,14.953122,0.961583,-289.570984,294.500488,0.000000
112.610008,65.878639,-289.526520,-0.001380,0.003786,0.096158,293.042816,14.928313,0.961583,-289.526520,294.500488,0.000000
113.060005,65.851830,-289.526520,-0.001371,0.003786,0.096158,292.923553,14.922237,0.961583,-289.526520,294.500488,0.000000
113.510002,65.828377,-289.526520,-0.001371,0.003786,0.096158,292.819244,14.916924,0.961583,-289.526520,294.500488,0.000000
113.960007,65.779228,-289.615479,-0.001384,0.003786,0.096158,292.600616,14.905787,0.961583,-289.615479,294.500488,0.000000
114.410004,65.747566,-289.615479,-0.001375,0.003786,0.096158,292.459778,14.898612,0.961583,-289.615479,294.500488,0.000000
114.860008,65.684639,-289.659943,-0.001384,0.003786,0.096158,292.179871,14.884353,0.961583,-289.659943,294.500488,0.000000
115.310005,65.593407,-289.659943,-0.001380,0.003786,0.096158,291.774048,14.863678,0.961583,-289.659943,294.500488,0.000000
115.760002,65.572182,-289.748901,-0.001384,0.003786,0.096167,291.679626,14.858869,0.961666,-289.748901,294.500488,0.000000
116.210007,65.534569,-289.748901,-0.001367,0.003786,0.096167,291.512329,14.850346,0.961666,-289.748901,294.500488,0.000000
116.660004,65.511864,-289.793396,-0.001367,0.003786,0.096167,291.411316,14.845201,0.961666,-289.793396,294.500488,0.000000
117.110008,65.453026,-289.837891,-0.001367,0.003786,0.096167,291.149597,14.831867,0.961666,-289.837891,294.500488,0.000000
117.560005,65.385994,-289.837891,-0.001371,0.003786,0.096167,290.851440,14.816678,0.961666,-289.837891,294.500488,0.000000
118.010002,65.331261,-289.882355,-0.001380,0.003786,0.096167,290.607971,14.804276,0.961666,-289.882355,294.500488,0.000000
118.460007,65.304070,-289.971313,-0.001375,0.003786,0.096167,290.487000,14.798114,0.961666,-289.971313,294.500488,0.000000
118.910004,65.272057,-289.882355,-0.001388,0.003786,0.096167,290.344604,14.790859,0.961666,-289.882355,294.500488,0.000000
119.360008,65.240776,-289.971313,-0.001362,0.003786,0.096176,290.205475,14.783772,0.961757,-289.971313,294.500488,0.000000
119.810005,65.198692,-289.971313,-0.001380,0.003786,0.096176,290.018280,14.774235,0.961757,-289.971313,294.500488,0.000000
120.260002,65.129799,-290.015808,-0.001375,0.003786,0.096176,289.711823,14.758624,0.961757,-290.015808,294.500488,0.000000
120.710007,65.078041,-290.060272,-0.001367,0.003786,0.096176,289.481598,14.746895,0.961757,-290.060272,294.500488,0.000000
121.160004,65.043419,-290.104767,-0.001380,0.003786,0.096176,289.327576,14.739050,0.961757,-290.104767,294.500488,0.000000
121.610008,65.015480,-290.193726,-0.001367,0.003786,0.096176,289.203308,14.732718,0.961757,-290.193726,294.500488,0.000000
122.060005,64.977882,-290.193726,-0.001380,0.003786,0.096176,289.036041,14.724199,0.961757,-290.193726,294.500488,0.000000
122.510002,64.954048,-290.149231,-0.001380,0.003786,0.096176,288.930023,14.718798,0.961757,-290.149231,294.500488,0.000000
122.960007,65.383766,-290.193726,-0.001367,0.003797,0.096454,290.841522,14.816174,0.964535,-290.193726,294.500488,0.000000
123.410004,65.400887,-290.282684,-0.001367,0.003797,0.096454,290.917664,14.820053,0.964535,-290.282684,294.500488,0.000000
123.860008,65.375938,-290.371643,-0.001380,0.003797,0.096454,290.806702,14.814400,0.964535,-290.371643,294.500488,0.000000
124.310005,65.364769,-290.371643,-0.001371,0.003797,0.096454,290.757019,14.811869,0.964535,-290.371643,294.500488,0.000000
124.760002,65.330147,-290.327179,-0.001358,0.003797,0.096454,290.602997,14.804023,0.964535,-290.327179,294.500488,0.000000
125.210007,65.320457,-290.371643,-0.001371,0.003797,0.096454,290.559906,14.801826,0.964535,-290.371643,294.500488,0.000000
125.660004,65.299614,-290.460602,-0.001375,0.003797,0.096454,290.467194,14.797104,0.964535,-290.460602,294.500488,0.000000
126.110008,65.285454,-290.505096,-0.001367,0.003797,0.096454,290.404205,14.793895,0.964535,-290.505096,294.500488,0.000000
126.560005,65.251564,-290.549561,-0.001362,0.003797,0.096454,290.253448,14.786216,0.964535,-290.549561,294.500488,0.000000
127.010010,65.228111,-290.549561,-0.001362,0.003797,0.096454,290.149139,14.780901,0.964535,-290.549561,1681.640991,0.000000
127.460007,65.162941,-290.549561,-0.001362,0.003783,0.096080,289.859253,14.766133,0.960803,-290.549561,0.095820,0.000000
127.910004,65.011391,-290.594055,-0.001362,0.003757,0.095438,289.185120,14.731791,0.954384,-290.594055,0.095074,0.000000
128.360001,64.985329,-290.683014,-0.001380,0.003728,0.094701,289.069183,14.725885,0.947011,-290.683014,0.094320,0.000000
128.810013,64.892235,-290.638519,-0.001354,0.003704,0.094086,288.655090,14.704790,0.940857,-290.638519,0.093574,0.000000
129.260010,64.848289,-290.727509,-0.001371,0.003675,0.093340,288.459595,14.694832,0.933401,-290.727509,0.092819,0.000000
129.710007,64.782005,-290.727509,-0.001358,0.003646,0.092620,288.164764,14.679812,0.926202,-290.727509,0.092074,0.000000
130.160004,64.713127,-290.727509,-0.001371,0.003615,0.091831,287.858368,14.664205,0.918306,-290.727509,0.091319,0.000000
130.610001,64.643486,-290.816467,-0.001345,0.003586,0.091077,287.548584,14.648423,0.910767,-290.816467,0.090573,0.000000
131.060013,64.252495,-290.860931,-0.001354,0.003562,0.090478,285.809357,14.559824,0.904779,-290.860931,0.089819,0.000000
131.510010,63.251564,-290.860931,-0.001354,0.003536,0.089810,281.356995,14.333010,0.898103,-290.860931,0.089073,0.000000
131.960007,62.151573,-290.905426,-0.001345,0.003507,0.089073,276.464020,14.083748,0.890730,-290.905426,0.088318,0.000000
132.410004,60.463234,-290.994385,-0.001341,0.003476,0.088284,268.953888,13.701164,0.882842,-290.994385,0.087573,0.000000
132.860001,58.679939,-290.949890,-0.001341,0.003453,0.087703,261.021393,13.297065,0.877028,-290.949890,0.086818,0.000000
133.310013,56.453156,-290.905426,-0.001328,0.003426,0.087026,251.116180,12.792468,0.870261,-290.905426,0.086072,0.000000
133.760010,54.076675,-291.083344,-0.001328,0.003397,0.086280,240.545059,12.253949,0.862805,-291.083344,0.085318,0.000000
134.210007,50.752502,-291.083344,-0.001341,0.003363,0.085430,225.758408,11.500682,0.854304,-291.083344,0.084572,0.000000
134.660004,47.238052,-291.127838,-0.001319,0.003331,0.084607,210.125351,10.704295,0.846068,-291.127838,0.083818,0.000000
135.110001,44.932693,-291.127838,-0.001337,0.003309,0.084052,199.870605,10.181893,0.840519,-291.127838,0.083072,0.000000
135.560013,41.968987,-291.172302,-0.001337,0.003281,0.083332,186.687378,9.510308,0.833320,-291.172302,0.082318,0.000000
136.010010,38.515976,-291.216797,-0.001350,0.003248,0.082499,171.327621,8.727845,0.824994,-291.216797,0.081571,0.000000
136.460007,35.465500,-291.261261,-0.001341,0.003224,0.081884,157.758423,8.036597,0.818839,-291.261261,0.080817,0.000000
136.910004,31.981583,-291.350220,-0.001341,0.003189,0.081008,142.261185,7.247130,0.810081,-291.350220,0.080071,0.000000
137.360001,29.020477,-291.261261,-0.001337,0.003163,0.080340,129.089523,6.576134,0.803405,-291.261261,0.079317,0.000000
137.810013,26.589256,-291.350220,-0.001341,0.003143,0.079820,118.274918,6.025212,0.798196,-291.350220,0.078571,0.000000
138.260010,22.629822,-291.350220,-0.001341,0.003104,0.078840,100.662476,5.127991,0.788401,-291.350220,0.077817,0.000000
138.710007,19.708557,-291.350220,-0.001341,0.003078,0.078189,87.668037,4.466023,0.781891,-291.350220,0.077070,0.000000
139.160004,15.958023,-291.483673,-0.001337,0.003044,0.077313,70.984833,3.616140,0.773133,-291.483673,0.076316,0.000000
139.610001,12.743706,-291.483673,-0.001337,0.003015,0.076576,56.686832,2.887765,0.765760,-291.483673,0.075570,0.000000
140.060013,9.281013,-291.528168,-0.001337,0.002981,0.075727,41.284008,2.103108,0.757267,-291.528168,0.074816,0.000000
140.510010,6.586151,-291.528168,-0.001332,0.002954,0.075042,29.296663,1.492443,0.750416,-291.528168,0.074070,0.000000
140.960007,3.647018,-291.528168,-0.001332,0.002926,0.074330,16.222748,0.826426,0.743300,-291.528168,0.073316,0.000000
141.410004,0.612923,-291.572632,-0.001337,0.002898,0.073602,2.726416,0.138890,0.736018,-291.572632,0.072570,0.000000
141.860001,-2.359726,-291.661591,-0.001332,0.002868,0.072839,-10.496585,-0.534722,0.728388,-291.661591,0.071815,0.000000
142.310013,-5.212471,-291.661591,-0.001350,0.002838,0.072084,-23.186230,-1.181163,0.720841,-291.661591,0.071070,0.000000
142.760010,-0.019363,-291.750549,-0.001354,0.002814,0.071486,-0.086133,-0.004388,0.714861,-291.750549,0.070315,0.000000
143.210007,-0.039101,-291.750549,-0.001367,0.002774,0.070471,-0.173928,-0.008860,0.704710,-291.750549,0.069569,0.000000
143.660004,-0.069260,-291.750549,-0.001388,0.002749,0.069821,-0.308082,-0.015694,0.698207,-291.750549,0.068823,0.000000
144.110001,-0.031281,-291.795044,-0.001427,0.002717,0.069005,-0.139143,-0.007088,0.690054,-291.795044,0.068069,0.000000
144.560013,-0.030159,-291.839508,-0.001449,0.002693,0.068390,-0.134154,-0.006834,0.683900,-291.839508,0.067323,0.000000
145.010010,-0.024574,-291.884003,-0.001487,0.002660,0.067575,-0.109312,-0.005569,0.675748,-291.884003,0.066569,0.000000
145.460007,-0.049522,-291.884003,-0.001522,0.002630,0.066794,-0.220287,-0.011222,0.667943,-291.884003,0.065822,0.000000
145.910004,-0.035378,-291.972961,-0.001565,0.002597,0.065962,-0.157367,-0.008017,0.659616,-291.972961,0.065068,0.000000
146.360001,-0.060326,-292.061920,-0.001591,0.002573,0.065363,-0.268342,-0.013670,0.653629,-292.061920,0.064323,0.000000
146.810013,-0.051018,-291.972961,-0.001630,0.002541,0.064548,-0.226938,-0.011561,0.645476,-291.972961,0.063568,0.000000
147.260010,-0.056602,-292.061920,-0.001660,0.002510,0.063750,-0.251780,-0.012826,0.637497,-292.061920,0.062822,0.000000
147.710007,-0.029793,-292.061920,-0.001703,0.002480,0.062987,-0.132525,-0.006751,0.629867,-292.061920,0.062068,0.000000
148.160004,-0.070747,-292.106415,-0.001729,0.002453,0.062302,-0.314700,-0.016032,0.623016,-292.106415,0.061322,0.000000
148.610001,-0.051758,-292.150879,-0.001750,0.002428,0.061677,-0.230230,-0.011728,0.616771,-292.150879,0.060567,0.000000
149.060013,-0.078568,-292.195374,-0.001794,0.002394,0.060819,-0.349486,-0.017804,0.608187,-292.195374,0.059822,0.000000
149.510010,-0.059578,-292.195374,-0.001815,0.002366,0.060091,-0.265016,-0.013501,0.600905,-292.195374,0.059067,0.000000
149.960007,-0.060326,-292.239838,-0.001854,0.002336,0.059336,-0.268342,-0.013670,0.593358,-292.239838,0.058321,0.000000
150.410004,-0.068886,-292.328796,-0.001884,0.002306,0.058564,-0.306419,-0.015610,0.585637,-292.328796,0.057567,0.000000
150.860001,-0.061066,-292.328796,-0.001906,0.002275,0.057783,-0.271634,-0.013838,0.577832,-292.328796,0.056821,0.000000
151.310013,-0.074478,-292.284332,-0.001940,0.002251,0.057185,-0.331295,-0.016877,0.571852,-292.284332,0.056066,0.000000
151.760010,-0.059952,-292.328796,-0.001975,0.002213,0.056222,-0.266679,-0.013585,0.562223,-292.328796,0.055321,0.000000
152.210007,-0.071869,-292.328796,-0.002018,0.002187,0.055555,-0.319689,-0.016286,0.555547,-292.328796,0.054566,0.000000
152.660004,-0.078568,-292.417786,-0.002039,0.002159,0.054826,-0.349486,-0.017804,0.548265,-292.417786,0.053820,0.000000
153.110001,-0.065536,-292.417786,-0.002048,0.002133,0.054176,-0.291521,-0.014851,0.541762,-292.417786,0.053066,0.000000
153.560013,-0.067024,-292.417786,-0.002095,0.002095,0.053213,-0.298139,-0.015188,0.532134,-292.417786,0.052320,0.000000
154.010010,-0.091606,-292.506744,-0.002134,0.002061,0.052355,-0.407484,-0.020758,0.523549,-292.506744,0.051565,0.000000
154.460007,-0.087883,-292.551208,-0.002156,0.002041,0.051843,-0.390923,-0.019915,0.518432,-292.551208,0.050820,0.000000
154.910004,-0.098679,-292.551208,-0.002203,0.002010,0.051045,-0.438944,-0.022361,0.510454,-292.551208,0.050065,0.000000
155.360001,-0.080063,-292.551208,-0.002220,0.001976,0.050178,-0.356137,-0.018143,0.501779,-292.551208,0.049319,0.000000
155.810013,-0.070747,-292.640167,-0.002276,0.001940,0.049285,-0.314700,-0.016032,0.492846,-292.640167,0.048565,0.000000
156.260010,-0.066658,-292.684662,-0.002285,0.001916,0.048678,-0.296510,-0.015105,0.486775,-292.684662,0.047819,0.000000
156.710007,-0.086021,-292.729126,-0.002311,0.001893,0.048088,-0.382642,-0.019493,0.480878,-292.729126,0.047064,0.000000
157.160004,-0.081551,-292.729126,-0.002350,0.001860,0.047255,-0.362755,-0.018480,0.472552,-292.729126,0.046319,0.000000
157.610001,-0.071495,-292.729126,-0.002389,0.001829,0.046457,-0.318026,-0.016201,0.464573,-292.729126,0.045564,0.000000
158.060013,-0.068146,-292.773621,-0.002414,0.001802,0.045764,-0.303127,-0.015442,0.457639,-292.773621,0.044818,0.000000
158.510010,-0.068146,-292.818115,-0.002445,0.001770,0.044957,-0.303127,-0.015442,0.449570,-292.818115,0.044064,0.000000
158.960007,-0.078941,-292.907074,-0.002479,0.001744,0.044307,-0.351149,-0.017888,0.443067,-292.907074,0.043318,0.000000
159.410004,-0.048409,-292.951538,-0.002501,0.001712,0.043483,-0.215332,-0.010970,0.434831,-292.951538,0.042563,0.000000
159.860001,-0.068520,-292.951538,-0.002544,0.001680,0.042676,-0.304790,-0.015527,0.426762,-292.951538,0.041818,0.000000
160.310013,-0.067398,-292.996033,-0.002548,0.001669,0.042382,-0.299802,-0.015273,0.423817,-292.996033,0.041063,0.000000
160.760010,-0.072617,-292.996033,-0.002596,0.001633,0.041489,-0.323015,-0.016455,0.414885,-292.996033,0.040317,0.000000
161.210007,-0.071121,-293.084991,-0.002643,0.001590,0.040395,-0.316363,-0.016116,0.403954,-293.084991,0.039564,0.000000
161.660004,-0.057716,-293.084991,-0.002652,0.001565,0.039763,-0.256735,-0.013079,0.397626,-293.084991,0.038817,0.000000
162.110001,-0.076340,-293.084991,-0.002695,0.001539,0.039095,-0.339576,-0.017299,0.390949,-293.084991,0.038063,0.000000
162.560013,-0.055115,-293.129456,-0.002708,0.001516,0.038496,-0.245163,-0.012489,0.384962,-293.129456,0.037317,0.000000
163.010010,-0.068146,-293.129456,-0.002742,0.001479,0.037569,-0.303127,-0.015442,0.375689,-293.129456,0.036563,0.000000
163.460007,-0.053253,-293.218414,-0.002781,0.001448,0.036771,-0.236882,-0.012067,0.367710,-293.218414,0.035816,0.000000
163.910004,-0.021599,-293.218414,-0.002811,0.001419,0.036051,-0.096076,-0.004894,0.360511,-293.218414,0.035071,0.000000
164.360001,-0.033890,-293.307404,-0.002841,0.001389,0.035287,-0.150749,-0.007680,0.352873,-293.307404,0.034316,0.000000
164.810013,-0.039474,-293.307404,-0.002871,0.001362,0.034602,-0.175591,-0.008945,0.346023,-293.307404,0.033571,0.000000
165.260010,-0.044312,-293.351868,-0.002915,0.001326,0.033683,-0.197107,-0.010041,0.336833,-293.351868,0.032816,0.000000
165.710007,-0.003723,-293.351868,-0.002940,0.001302,0.033059,-0.016561,-0.000844,0.330588,-293.351868,0.032070,0.000000
166.160004,-0.025696,-293.396362,-0.002962,0.001274,0.032356,-0.114301,-0.005823,0.323563,-293.396362,0.031315,0.000000
166.610001,-0.010056,-293.440826,-0.003001,0.001242,0.031558,-0.044729,-0.002279,0.315585,-293.440826,0.030570,0.000000
167.060013,-0.044312,-293.485321,-0.003035,0.001209,0.030700,-0.197107,-0.010041,0.307000,-293.485321,0.029816,0.000000
167.510010,-0.024574,-293.485321,-0.003061,0.001178,0.029928,-0.109312,-0.005569,0.299279,-293.485321,0.029070,0.000000
167.960007,-0.030533,-293.529785,-0.003104,0.001160,0.029460,-0.135817,-0.006919,0.294601,-293.529785,0.028316,0.000000
168.410004,-0.019737,-293.574280,-0.003122,0.001123,0.028515,-0.087796,-0.004473,0.285146,-293.574280,0.027569,0.000000
168.860001,-0.023460,-293.574280,-0.003160,0.001092,0.027734,-0.104357,-0.005316,0.277342,-293.574280,0.026815,0.000000
169.310013,-0.049896,-293.574280,-0.003182,0.001063,0.027006,-0.221950,-0.011307,0.270060,-293.574280,0.026069,0.000000
169.760010,-0.070007,-293.707733,-0.003203,0.001034,0.026251,-0.311408,-0.015864,0.262513,-293.707733,0.025315,0.000000
170.210007,-0.077080,-293.707733,-0.003247,0.001008,0.025609,-0.342868,-0.017467,0.256094,-293.707733,0.024569,0.000000
170.660004,-0.064796,-293.663239,-0.003268,0.000980,0.024889,-0.288229,-0.014683,0.248895,-293.663239,0.023815,0.000000
171.110001,-0.025696,-293.707733,-0.003307,0.000943,0.023961,-0.114301,-0.005823,0.239614,-293.707733,0.023068,0.000000
171.560013,-0.043198,-293.841156,-0.003337,0.000913,0.023198,-0.192153,-0.009789,0.231984,-293.841156,0.022314,0.000000
172.010010,-0.043571,-293.841156,-0.003367,0.000885,0.022488,-0.193816,-0.009873,0.224876,-293.841156,0.021568,0.000000
172.460007,-0.035004,-293.841156,-0.003402,0.000865,0.021976,-0.155704,-0.007932,0.219759,-293.841156,0.020814,0.000000
172.910004,-0.088249,-293.930115,-0.003441,0.000828,0.021039,-0.392552,-0.019998,0.210395,-293.930115,0.020068,0.000000
173.360001,-0.071869,-293.885651,-0.003454,0.000794,0.020172,-0.319689,-0.016286,0.201720,-293.885651,0.019314,0.000000
173.810013,-0.085274,-293.885651,-0.003484,0.000769,0.019530,-0.379317,-0.019323,0.195301,-293.885651,0.018568,0.000000
174.260010,-0.059578,-293.930115,-0.003523,0.000736,0.018706,-0.265016,-0.013501,0.187065,-293.930115,0.017813,0.000000
174.710007,-0.078201,-294.019073,-0.003557,0.000708,0.017978,-0.347857,-0.017721,0.179783,-294.019073,0.017068,0.000000
175.160004,-0.088249,-294.108063,-0.003583,0.000682,0.017319,-0.392552,-0.019998,0.173189,-294.108063,0.016313,0.000000
175.610016,-0.071495,-294.019073,-0.003600,0.000662,0.016825,-0.318026,-0.016201,0.168246,-294.019073,0.015567,0.000000
176.060013,-0.057716,-294.063568,-0.003652,0.000620,0.015749,-0.256735,-0.013079,0.157489,-294.063568,0.014813,0.000000
176.510010,-0.076340,-294.108063,-0.003673,0.000591,0.015003,-0.339576,-0.017299,0.150033,-294.108063,0.014067,0.000000
176.960007,-0.091980,-294.152527,-0.003717,0.000557,0.014153,-0.409147,-0.020843,0.141532,-294.152527,0.013312,0.000000
177.410004,-0.090858,-294.108063,-0.003738,0.000528,0.013399,-0.404159,-0.020589,0.133993,-294.108063,0.012567,0.000000
177.860016,-0.075218,-294.241486,-0.003777,0.000500,0.012697,-0.334587,-0.017045,0.126968,-294.241486,0.011812,0.000000
178.310013,-0.061440,-294.285980,-0.003798,0.000471,0.011968,-0.273297,-0.013922,0.119678,-294.285980,0.011066,0.000000
178.760010,-0.070381,-294.330444,-0.003833,0.000440,0.011187,-0.313071,-0.015949,0.111874,-294.330444,0.010312,0.000000
179.210007,-0.055855,-294.330444,-0.003867,0.000409,0.010390,-0.248455,-0.012657,0.103895,-294.330444,0.009566,0.000000
179.660004,-0.067398,-294.374939,-0.003902,0.000382,0.009696,-0.299802,-0.015273,0.096961,-294.374939,0.008811,0.000000
180.110016,-0.059204,-294.330444,-0.003932,0.000350,0.008898,-0.263353,-0.013416,0.088983,-294.330444,0.008066,0.000000
180.560013,-0.066284,-294.419403,-0.003941,0.000326,0.008274,-0.294847,-0.015020,0.082738,-294.419403,0.007311,0.000000
181.010010,-0.091606,-294.419403,-0.003975,0.000299,0.007597,-0.407484,-0.020758,0.075970,-294.419403,0.006565,0.000000
181.460007,-0.084160,-294.463898,-0.003997,0.000271,0.006895,-0.374362,-0.019071,0.068946,-294.463898,0.005811,0.000000
181.910004,-0.098305,-294.508362,-0.004040,0.000242,0.006149,-0.437281,-0.022276,0.061489,-294.508362,0.005065,0.000000
182.360016,-0.064049,-294.552856,-0.004079,0.000203,0.005160,-0.284903,-0.014514,0.051603,-294.552856,0.004310,0.000000
182.810013,-0.061066,-294.597351,-0.004105,0.000175,0.004450,-0.271634,-0.013838,0.044495,-294.597351,0.003565,0.000000
183.260010,-0.055481,-294.686310,-0.004126,0.000149,0.003773,-0.246792,-0.012572,0.037728,-294.686310,0.002819,0.000000
183.710007,-0.081177,-294.641815,-0.004161,0.000122,0.003105,-0.361092,-0.018395,0.031051,-294.641815,0.002064,0.000000
184.160004,-0.072617,-294.641815,-0.004195,0.000093,0.002368,-0.323015,-0.016455,0.023678,-294.641815,0.001319,0.000000
184.610016,-0.046921,-294.686310,-0.004217,0.000059,0.001509,-0.208714,-0.010632,0.015094,-294.686310,0.000564,0.000000
185.060013,-0.019363,-294.730774,-0.004251,0.000026,0.000651,-0.086133,-0.004388,0.006510,-294.730774,-0.000182,0.000000
185.510010,-0.035004,-294.819733,-0.004286,0.000007,0.000182,-0.155704,-0.007932,0.001824,-294.819733,-0.000936,0.000000
185.700012,-0.043938,-294.730774,-0.004290,0.000004,0.000113,-0.195445,-0.009956,0.001128,-294.730774,-0.000008,0.000000