File: Data/compression 22/AutoNoHeating-17-22-reverse-1-2_09172024_163555.csv
Time (sec),S:Load (lbs),S:HL1 (DIM),S:LVDT (in),S:Position (in),Ch:Position (mm),Ch:Load (N),Ch:Stress (MPa),Ch:Strain (mm/mm),Ch:HL1 (DIM),Set Point (),Cycles ()
0.210000,-0.002975,-104.752640,-0.012383,-0.007743,-0.196669,-0.013236,-0.000674,-1.966692,-104.752640,-0.196461,0.000000
0.660000,-0.029785,-104.841599,-0.012391,-0.007628,-0.193747,-0.132491,-0.006749,-1.937473,-104.841599,-0.192541,0.000000
1.110000,-0.009682,-104.797119,-0.012124,-0.007337,-0.186349,-0.043066,-0.002194,-1.863493,-104.797119,-0.185049,0.000000
1.560000,-0.030907,-104.841599,-0.011818,-0.007036,-0.178727,-0.137480,-0.007004,-1.787265,-104.841599,-0.177555,0.000000
2.010000,-0.010796,-104.841599,-0.011516,-0.006744,-0.171294,-0.048021,-0.002446,-1.712945,-104.841599,-0.170063,0.000000
2.460000,0.009682,-104.886086,-0.011240,-0.006452,-0.163888,0.043066,0.002194,-1.638882,-104.886086,-0.162570,0.000000
2.910000,-0.005585,-104.841599,-0.010938,-0.006152,-0.156257,-0.024842,-0.001266,-1.562571,-104.841599,-0.155060,0.000000
3.360000,-0.046547,-104.886086,-0.010658,-0.005857,-0.148773,-0.207051,-0.010548,-1.487729,-104.886086,-0.147567,0.000000
3.810000,0.005585,-104.841599,-0.010356,-0.005565,-0.141349,0.024842,0.001266,-1.413492,-104.841599,-0.140074,0.000000
4.260000,0.042084,-104.841599,-0.010059,-0.005267,-0.133770,0.187198,0.009536,-1.337695,-104.841599,-0.132582,0.000000
4.710000,0.018623,-104.841599,-0.009740,-0.004972,-0.126294,0.082841,0.004220,-1.262944,-104.841599,-0.125071,0.000000
5.160000,0.013039,-104.886086,-0.009438,-0.004680,-0.118862,0.057999,0.002955,-1.188624,-104.886086,-0.117579,0.000000
5.610000,-0.011909,-104.886086,-0.009140,-0.004385,-0.111369,-0.052976,-0.002699,-1.113690,-104.886086,-0.110086,0.000000
6.060000,0.025696,-104.886086,-0.008839,-0.004082,-0.103686,0.114301,0.005823,-1.036857,-104.886086,-0.102593,0.000000
6.510000,0.026070,-104.930565,-0.008528,-0.003790,-0.096254,0.115964,0.005907,-0.962537,-104.930565,-0.095083,0.000000
6.960001,0.014153,-104.886086,-0.008235,-0.003500,-0.088900,0.062954,0.003207,-0.888996,-104.886086,-0.087590,0.000000
7.410000,-0.021591,-104.886086,-0.007907,-0.003199,-0.081242,-0.096042,-0.004893,-0.812420,-104.886086,-0.080097,0.000000
7.860001,0.014526,-104.886086,-0.007588,-0.002907,-0.073827,0.064617,0.003292,-0.738266,-104.886086,-0.072604,0.000000
8.310000,0.018250,-104.975044,-0.007295,-0.002611,-0.066326,0.081178,0.004135,-0.663257,-104.975044,-0.065094,0.000000
8.760000,0.017876,-104.975044,-0.006989,-0.002315,-0.058798,0.079515,0.004051,-0.587983,-104.975044,-0.057602,0.000000
9.210000,0.026070,-104.930565,-0.006679,-0.002020,-0.051305,0.115964,0.005907,-0.513050,-104.930565,-0.050108,0.000000
9.660001,0.001862,-104.930565,-0.006385,-0.001725,-0.043812,0.008281,0.000422,-0.438124,-104.930565,-0.042616,0.000000
10.110001,-0.005585,-104.886086,-0.006092,-0.001428,-0.036259,-0.024842,-0.001266,-0.362585,-104.886086,-0.035123,0.000000
10.560000,0.043571,-104.975044,-0.005790,-0.001131,-0.028723,0.193816,0.009873,-0.287228,-104.975044,-0.027612,0.000000
11.010000,0.045807,-104.930565,-0.005489,-0.000845,-0.021455,0.203759,0.010380,-0.214551,-104.930565,-0.020120,0.000000
11.460001,0.030540,-104.975044,-0.005178,-0.000544,-0.013807,0.135851,0.006921,-0.138065,-104.975044,-0.012627,0.000000
11.910001,0.056229,-104.975044,-0.004868,-0.000246,-0.006253,0.250117,0.012742,-0.062526,-104.975044,-0.005134,0.000000
12.360001,0.046547,-104.975044,-0.004825,-0.000001,-0.000017,0.207051,0.010548,-0.000174,-104.975044,0.000216,0.000000
12.810000,0.106133,-104.975044,-0.004820,-0.000000,-0.000009,0.472101,0.024050,-0.000091,-104.975044,0.000737,0.000000
13.260000,0.112831,-105.019524,-0.004829,-0.000000,-0.000000,0.501898,0.025568,-0.000000,-105.019524,0.001491,0.000000
13.710001,0.238319,-105.064003,-0.004786,0.000050,0.001275,1.060098,0.054004,0.012748,-105.064003,0.002238,0.000000
14.160001,0.306465,-105.019524,-0.004764,0.000080,0.002020,1.363225,0.069446,0.020204,-105.019524,0.002992,0.000000
14.610001,0.537338,-105.019524,-0.004743,0.000108,0.002740,2.390200,0.121763,0.027403,-105.019524,0.003738,0.000000
15.060000,0.749588,-105.019524,-0.004717,0.000131,0.003339,3.334334,0.169859,0.033390,-105.019524,0.004492,0.000000
15.510001,1.035568,-105.019524,-0.004674,0.000168,0.004258,4.606438,0.234663,0.042580,-105.019524,0.005238,0.000000
15.960001,1.292137,-105.019524,-0.004652,0.000197,0.005004,5.747713,0.292802,0.050036,-105.019524,0.005992,0.000000
16.410000,1.651848,-105.019524,-0.004626,0.000220,0.005593,7.347786,0.374314,0.055933,-105.019524,0.006739,0.000000
16.860001,2.147102,-104.975044,-0.004609,0.000252,0.006409,9.550788,0.486540,0.064086,-104.975044,0.007493,0.000000
17.310001,2.873970,-105.019524,-0.004566,0.000291,0.007389,12.784058,0.651251,0.073889,-105.019524,0.008239,0.000000
17.760000,3.312630,-105.108490,-0.004553,0.000316,0.008022,14.735312,0.750653,0.080217,-105.108490,0.008993,0.000000
18.210001,3.967262,-105.019524,-0.004523,0.000349,0.008872,17.647264,0.898994,0.088718,-105.019524,0.009739,0.000000
18.660002,4.458420,-105.064003,-0.004488,0.000374,0.009487,19.832043,1.010292,0.094872,-105.064003,0.010493,0.000000
19.110001,5.151031,-105.019524,-0.004475,0.000404,0.010259,22.912933,1.167240,0.102593,-105.019524,0.011239,0.000000
19.560001,5.827629,-105.064003,-0.004445,0.000434,0.011022,25.922588,1.320560,0.110224,-105.064003,0.011994,0.000000
20.010000,6.422684,-105.064003,-0.004424,0.000462,0.011733,28.569525,1.455401,0.117332,-105.064003,0.012739,0.000000
20.460001,7.197594,-105.152969,-0.004402,0.000494,0.012540,32.016495,1.630998,0.125401,-105.152969,0.013494,0.000000
20.910002,7.387497,-105.108490,-0.004376,0.000508,0.012904,32.861229,1.674031,0.129042,-105.108490,0.014240,0.000000
21.360001,8.655060,-105.108490,-0.004337,0.000553,0.014049,38.499630,1.961265,0.140488,-105.108490,0.014994,0.000000
21.810001,9.201698,-105.197449,-0.004316,0.000584,0.014829,40.931198,2.085135,0.148292,-105.197449,0.015740,0.000000
22.260000,9.707756,-105.197449,-0.004286,0.000612,0.015541,43.182255,2.199809,0.155408,-105.197449,0.016495,0.000000
22.710001,10.311745,-105.152969,-0.004264,0.000636,0.016165,45.868931,2.336675,0.161653,-105.152969,0.017240,0.000000
23.160002,11.177505,-105.197449,-0.004238,0.000670,0.017015,49.720028,2.532859,0.170146,-105.197449,0.017995,0.000000
23.610001,11.547272,-105.197449,-0.004217,0.000698,0.017726,51.364830,2.616649,0.177262,-105.197449,0.018741,0.000000
24.060001,12.214195,-105.197449,-0.004169,0.000730,0.018550,54.331455,2.767776,0.185498,-105.197449,0.019495,0.000000
24.510000,12.633858,-105.152969,-0.004126,0.000753,0.019114,56.198204,2.862873,0.191137,-105.152969,0.020241,0.000000
24.960001,13.145866,-105.152969,-0.004135,0.000779,0.019781,58.475735,2.978896,0.197814,-105.152969,0.020996,0.000000
25.410002,14.152763,-105.241928,-0.004092,0.000818,0.020778,62.954636,3.207062,0.207783,-105.241928,0.021741,0.000000
25.860001,14.583229,-105.241928,-0.004074,0.000847,0.021516,64.869446,3.304607,0.215156,-105.241928,0.022487,0.000000
26.310001,15.281052,-105.197449,-0.004044,0.000880,0.022357,67.973511,3.462736,0.223574,-105.197449,0.023242,0.000000
26.760002,15.384941,-105.241928,-0.004023,0.000901,0.022895,68.435638,3.486277,0.228948,-105.241928,0.023987,0.000000
27.210001,16.508018,-105.241928,-0.003984,0.000938,0.023814,73.431335,3.740771,0.238138,-105.241928,0.024742,0.000000
27.660002,16.657715,-105.241928,-0.003945,0.000965,0.024508,74.097214,3.774692,0.245080,-105.241928,0.025487,0.000000
28.110001,17.401337,-105.330894,-0.003936,0.000995,0.025279,77.405014,3.943199,0.252793,-105.330894,0.026242,0.000000
28.560001,16.700539,-105.197449,-0.003928,0.001009,0.025635,74.287704,3.784396,0.256351,-105.197449,0.026988,0.000000
29.010002,18.228004,-105.241928,-0.003876,0.001046,0.026581,81.082214,4.130525,0.265806,-105.241928,0.027743,0.000000
29.460001,18.737785,-105.241928,-0.003863,0.001080,0.027439,83.349831,4.246043,0.274390,-105.241928,0.028488,0.000000
29.910002,19.095261,-105.286407,-0.003833,0.001109,0.028159,84.939964,4.327048,0.281589,-105.286407,0.029243,0.000000
30.360001,19.448273,-105.241928,-0.003794,0.001138,0.028914,86.510239,4.407042,0.289136,-105.241928,0.029988,0.000000
30.810001,19.737976,-105.286407,-0.003773,0.001162,0.029521,87.798904,4.472689,0.295207,-105.286407,0.030743,0.000000
31.260002,20.729980,-105.241928,-0.003742,0.001204,0.030578,92.211555,4.697481,0.305782,-105.241928,0.031489,0.000000
31.710001,20.678589,-105.286407,-0.003708,0.001229,0.031220,91.982956,4.685835,0.312201,-105.286407,0.032244,0.000000
32.160000,21.424454,-105.241928,-0.003691,0.001262,0.032061,95.300728,4.854851,0.320611,-105.241928,0.032989,0.000000
32.610001,21.491104,-105.330894,-0.003656,0.001287,0.032677,95.597206,4.869954,0.326773,-105.330894,0.033744,0.000000
33.060001,22.270111,-105.330894,-0.003622,0.001323,0.033596,99.062401,5.046479,0.335962,-105.330894,0.034489,0.000000
33.510002,22.344955,-105.286407,-0.003583,0.001348,0.034238,99.395325,5.063439,0.342382,-105.286407,0.035244,0.000000
33.960003,22.939262,-105.330894,-0.003557,0.001379,0.035027,102.038933,5.198111,0.350269,-105.330894,0.035990,0.000000
34.410000,23.132523,-105.375374,-0.003540,0.001405,0.035695,102.898598,5.241904,0.356953,-105.375374,0.036745,0.000000
34.860001,23.686241,-105.330894,-0.003514,0.001437,0.036502,105.361664,5.367379,0.365015,-105.330894,0.037490,0.000000
35.310001,24.089523,-105.419853,-0.003471,0.001467,0.037256,107.155548,5.458764,0.372562,-105.419853,0.038245,0.000000
35.760002,24.502113,-105.330894,-0.003454,0.001497,0.038019,108.990845,5.552258,0.380193,-105.330894,0.038990,0.000000
36.210003,24.604515,-105.419853,-0.003423,0.001523,0.038687,109.446350,5.575463,0.386869,-105.419853,0.039745,0.000000
36.660000,25.188019,-105.419853,-0.003393,0.001554,0.039476,112.041901,5.707686,0.394765,-105.419853,0.040491,0.000000
37.110001,25.716042,-105.419853,-0.003359,0.001586,0.040274,114.390663,5.827338,0.402736,-105.419853,0.041246,0.000000
37.560001,25.634499,-105.508820,-0.003324,0.001609,0.040881,114.027946,5.808860,0.408807,-105.508820,0.041991,0.000000
38.010002,26.239975,-105.464333,-0.003298,0.001642,0.041705,116.721237,5.946063,0.417050,-105.464333,0.042746,0.000000
38.460003,27.017487,-105.464333,-0.003260,0.001678,0.042633,120.179779,6.122250,0.426331,-105.464333,0.043491,0.000000
38.910004,26.937424,-105.464333,-0.003229,0.001700,0.043188,119.823647,6.104107,0.431879,-105.464333,0.044246,0.000000
39.360001,27.485558,-105.464333,-0.003195,0.001734,0.044055,122.261864,6.228317,0.440547,-105.464333,0.044992,0.000000
39.810001,27.949165,-105.464333,-0.003165,0.001764,0.044809,124.324097,6.333372,0.448094,-105.464333,0.045746,0.000000
40.260002,27.913414,-105.464333,-0.003139,0.001788,0.045426,124.165070,6.325270,0.454256,-105.464333,0.046492,0.000000
40.710003,28.821632,-105.464333,-0.003100,0.001823,0.046292,128.205017,6.531075,0.462923,-105.464333,0.047246,0.000000
41.160004,28.876740,-105.508820,-0.003061,0.001850,0.046986,128.450150,6.543563,0.469864,-105.508820,0.047992,0.000000
41.610001,29.770065,-105.508820,-0.003031,0.001883,0.047827,132.423859,6.745993,0.478274,-105.508820,0.048746,0.000000
42.060001,29.452805,-105.464333,-0.003009,0.001903,0.048347,131.012619,6.674101,0.483475,-105.464333,0.049493,0.000000
42.510002,30.566566,-105.508820,-0.002975,0.001941,0.049293,135.966873,6.926483,0.492930,-105.508820,0.050247,0.000000
42.960003,30.937454,-105.508820,-0.002949,0.001969,0.050005,137.616669,7.010528,0.500045,-105.508820,0.050993,0.000000
43.410004,31.560806,-105.508820,-0.002897,0.002001,0.050819,140.389481,7.151781,0.508190,-105.508820,0.051747,0.000000
43.860001,31.618149,-105.508820,-0.002876,0.002024,0.051400,140.644547,7.164775,0.514004,-105.508820,0.052493,0.000000
44.310001,31.801727,-105.553299,-0.002850,0.002051,0.052085,141.461151,7.206374,0.520855,-105.553299,0.053247,0.000000
44.760002,32.893150,-105.508820,-0.002824,0.002085,0.052953,146.316040,7.453694,0.529530,-105.508820,0.053994,0.000000
45.210003,33.346329,-105.553299,-0.002781,0.002114,0.053707,148.331879,7.556386,0.537069,-105.553299,0.054739,0.000000
45.660004,33.816261,-105.553299,-0.002742,0.002145,0.054488,150.422241,7.662874,0.544881,-105.553299,0.055493,0.000000
46.110001,34.058304,-105.553299,-0.002729,0.002171,0.055147,151.498901,7.717722,0.551467,-105.553299,0.056240,0.000000
46.560001,34.521164,-105.553299,-0.002699,0.002203,0.055962,153.557800,7.822608,0.559619,-105.553299,0.056994,0.000000
47.010002,35.519119,-105.508820,-0.002660,0.002233,0.056708,157.996933,8.048747,0.567076,-105.508820,0.057740,0.000000
47.460003,36.465324,-105.553299,-0.002639,0.002265,0.057540,162.205872,8.263161,0.575402,-105.553299,0.058494,0.000000
47.910004,36.413933,-105.597778,-0.002591,0.002289,0.058130,161.977264,8.251515,0.581299,-105.597778,0.059240,0.000000
48.360001,36.825775,-105.597778,-0.002574,0.002314,0.058772,163.809235,8.344839,0.587718,-105.597778,0.059994,0.000000
48.810001,38.096687,-105.597778,-0.002531,0.002352,0.059743,169.462524,8.632833,0.597431,-105.597778,0.060741,0.000000
49.260002,38.114189,-105.597778,-0.002509,0.002376,0.060359,169.540375,8.636799,0.603592,-105.597778,0.061495,0.000000
49.710003,38.343567,-105.642258,-0.002471,0.002396,0.060870,170.560699,8.688776,0.608702,-105.642258,0.062241,0.000000
50.160004,39.488983,-105.597778,-0.002440,0.002431,0.061747,175.655777,8.948332,0.617468,-105.597778,0.062995,0.000000
50.610001,41.212700,-105.553299,-0.002402,0.002471,0.062752,183.323242,9.338931,0.627520,-105.553299,0.063741,0.000000
51.060001,41.537033,-105.642258,-0.002376,0.002497,0.063420,184.765945,9.412426,0.634205,-105.642258,0.064495,0.000000
51.510002,42.422905,-105.642258,-0.002345,0.002528,0.064201,188.706512,9.613167,0.642009,-105.642258,0.065241,0.000000
51.960003,41.984253,-105.642258,-0.002315,0.002544,0.064626,186.755280,9.513767,0.646256,-105.642258,0.065996,0.000000
52.410004,44.618416,-105.686737,-0.002272,0.002593,0.065875,198.472626,10.110678,0.658746,-105.686737,0.066741,0.000000
52.860001,44.679115,-105.642258,-0.002242,0.002618,0.066499,198.742630,10.124433,0.664991,-105.642258,0.067496,0.000000
53.310001,45.286079,-105.686737,-0.002225,0.002646,0.067202,201.442535,10.261972,0.672016,-105.686737,0.068242,0.000000
53.760002,45.492004,-105.686737,-0.002186,0.002670,0.067809,202.358536,10.308636,0.678087,-105.686737,0.068996,0.000000
54.210003,47.361687,-105.686737,-0.002160,0.002709,0.068806,210.675308,10.732311,0.688056,-105.686737,0.069742,0.000000
54.660004,47.855820,-105.731224,-0.002117,0.002737,0.069508,212.873322,10.844283,0.695081,-105.731224,0.070497,0.000000
55.110004,48.632591,-105.642258,-0.002078,0.002766,0.070254,216.328568,11.020303,0.702537,-105.642258,0.071242,0.000000
55.560001,49.146835,-105.731224,-0.002061,0.002792,0.070913,218.616043,11.136831,0.709130,-105.731224,0.071997,0.000000
56.010002,49.954887,-105.686737,-0.002035,0.002819,0.071598,222.210434,11.319940,0.715981,-105.686737,0.072743,0.000000
56.460003,51.401924,-105.731224,-0.001996,0.002854,0.072491,228.647171,11.647842,0.724913,-105.731224,0.073497,0.000000
56.910004,51.865532,-105.731224,-0.001962,0.002879,0.073133,230.709412,11.752897,0.731333,-105.731224,0.074243,0.000000
57.360004,52.675438,-105.775703,-0.001927,0.002909,0.073879,234.312057,11.936424,0.738789,-105.775703,0.074998,0.000000
57.810001,53.326721,-105.731224,-0.001901,0.002936,0.074564,237.209106,12.084008,0.745639,-105.731224,0.075743,0.000000
58.260002,55.231407,-105.731224,-0.001863,0.002973,0.075527,245.681564,12.515615,0.755268,-105.731224,0.076498,0.000000
58.710003,55.681602,-105.775703,-0.001845,0.002999,0.076185,247.684143,12.617632,0.761854,-105.775703,0.077244,0.000000
59.160004,56.700417,-105.775703,-0.001828,0.003029,0.076949,252.216049,12.848498,0.769492,-105.775703,0.077998,0.000000
59.610004,57.567665,-105.820183,-0.001781,0.003058,0.077669,256.073761,13.045020,0.776691,-105.820183,0.078744,0.000000
60.060001,59.040405,-105.775703,-0.001750,0.003092,0.078527,262.624847,13.378747,0.785275,-105.775703,0.079499,0.000000
60.510002,59.633591,-105.731224,-0.001716,0.003120,0.079256,265.263458,13.513165,0.792557,-105.731224,0.080244,0.000000
60.960003,60.547394,-105.820183,-0.001681,0.003147,0.079941,269.328247,13.720236,0.799408,-105.820183,0.080999,0.000000
61.410004,61.113770,-105.775703,-0.001656,0.003174,0.080608,271.847626,13.848578,0.806084,-105.775703,0.081745,0.000000
61.860004,62.065926,-105.820183,-0.001613,0.003207,0.081459,276.083038,14.064341,0.814585,-105.820183,0.082499,0.000000
62.310001,63.311890,-105.820183,-0.001574,0.003238,0.082256,281.625336,14.346680,0.822564,-105.820183,0.083245,0.000000
62.760002,63.959076,-105.820183,-0.001548,0.003264,0.082907,284.504181,14.493334,0.829066,-105.820183,0.084000,0.000000
63.210003,65.107468,-105.864662,-0.001518,0.003295,0.083696,289.612488,14.753563,0.836961,-105.864662,0.084745,0.000000
63.660004,65.804550,-105.864662,-0.001496,0.003321,0.084346,292.713257,14.911524,0.843464,-105.864662,0.085500,0.000000
64.110001,65.359192,-105.820183,-0.001457,0.003330,0.084589,290.732208,14.810605,0.845894,-105.820183,0.014852,0.000000
64.560005,65.991852,-105.820183,-0.001423,0.003162,0.080305,293.546417,14.953967,0.803049,-105.820183,294.500519,0.000000
65.010002,65.099274,-105.820183,-0.001414,0.003366,0.085500,289.576019,14.751707,0.855000,-105.820183,294.500519,0.000000
65.460007,65.200180,-105.909142,-0.001384,0.003382,0.085907,290.024872,14.774571,0.859073,-105.909142,294.500519,0.000000
65.910004,65.542023,-105.820183,-0.001337,0.003402,0.086411,291.545471,14.852035,0.864107,-105.820183,294.500519,0.000000
66.360001,66.683716,-105.820183,-0.001332,0.003353,0.085162,296.623993,15.110746,0.851617,-105.820183,294.500519,0.000000
66.810005,65.063904,-105.820183,-0.001324,0.003412,0.086670,289.418701,14.743691,0.866703,-105.820183,294.500519,0.000000
67.260002,65.049377,-105.820183,-0.001302,0.003440,0.087364,289.354095,14.740399,0.873645,-105.820183,294.500519,0.000000
67.710007,65.243759,-105.909142,-0.001276,0.003456,0.087772,290.218750,14.784447,0.877717,-105.909142,294.500519,0.000000
68.160004,66.141174,-105.864662,-0.001259,0.003455,0.087754,294.210632,14.987804,0.877543,-105.864662,294.500519,0.000000
68.610001,64.733231,-105.909142,-0.001242,0.003479,0.088370,287.947784,14.668760,0.883705,-105.909142,294.500519,0.000000
69.060005,65.120865,-105.864662,-0.001220,0.003484,0.088483,289.672089,14.756599,0.884833,-105.864662,294.500519,0.000000
69.510002,65.806030,-105.998108,-0.001212,0.003487,0.088561,292.719849,14.911860,0.885612,-105.998108,294.500519,0.000000
69.960007,65.393814,-105.909142,-0.001207,0.003515,0.089272,290.886200,14.818450,0.892720,-105.909142,294.500519,0.000000
70.410004,65.597504,-105.953629,-0.001177,0.003527,0.089585,291.792267,14.864607,0.895847,-105.953629,294.500519,0.000000
70.860001,64.576828,-105.998108,-0.001173,0.003527,0.089593,287.252075,14.633319,0.895930,-105.998108,294.500519,0.000000
71.310005,66.345230,-105.998108,-0.001155,0.003362,0.085396,295.118317,15.034044,0.853956,-105.998108,294.500519,0.000000
71.760002,65.256790,-105.998108,-0.001134,0.003469,0.088110,290.276703,14.787400,0.881101,-105.998108,294.500519,0.000000
72.210007,64.977875,-105.953629,-0.001143,0.003554,0.090278,289.036011,14.724196,0.902781,-105.953629,294.500519,0.000000
72.660004,65.139114,-105.953629,-0.001134,0.003567,0.090591,289.753265,14.760735,0.905907,-105.953629,294.500519,0.000000
73.110001,65.105972,-106.042587,-0.001134,0.003576,0.090842,289.605835,14.753223,0.908420,-106.042587,294.500519,0.000000
73.560005,65.430679,-105.953629,-0.001112,0.003586,0.091085,291.050201,14.826804,0.910850,-105.953629,294.500519,0.000000
74.010002,64.792816,-105.998108,-0.001091,0.003587,0.091102,288.212830,14.682262,0.911017,-105.998108,294.500519,0.000000
74.460007,65.482819,-106.042587,-0.001095,0.003600,0.091440,291.282135,14.838619,0.914400,-106.042587,294.500519,0.000000
74.910004,64.810684,-105.998108,-0.001074,0.003600,0.091449,288.292328,14.686312,0.914491,-105.998108,294.500519,0.000000
75.360001,65.633621,-106.042587,-0.001074,0.003640,0.092446,291.952942,14.872791,0.924461,-106.042587,294.500519,0.000000
75.810005,66.237610,-106.087067,-0.001043,0.003459,0.087867,294.639618,15.009657,0.878671,-106.087067,294.500519,0.000000
76.260002,65.520432,-106.087067,-0.001048,0.003510,0.089142,291.449432,14.847141,0.891418,-106.087067,294.500519,0.000000
76.710007,65.173752,-106.087067,-0.001048,0.003621,0.091961,289.907318,14.768583,0.919608,-106.087067,294.500519,0.000000
77.160004,65.179337,-106.087067,-0.001043,0.003632,0.092255,289.932159,14.769849,0.922553,-106.087067,294.500519,0.000000
77.610001,65.309296,-106.042587,-0.001035,0.003639,0.092438,290.510254,14.799298,0.924377,-106.042587,294.500519,0.000000
78.060005,65.240768,-106.042587,-0.001022,0.003644,0.092568,290.205444,14.783769,0.925679,-106.042587,294.500519,0.000000
78.510002,65.271317,-106.087067,-0.001009,0.003650,0.092706,290.341309,14.790692,0.927065,-106.087067,294.500519,0.000000
78.960007,64.914948,-106.087067,-0.001022,0.003651,0.092732,288.756104,14.709937,0.927322,-106.087067,294.500519,0.000000
79.410004,65.907318,-106.087067,-0.001018,0.003660,0.092958,293.170380,14.934812,0.929578,-106.087067,294.500519,0.000000
79.860001,65.448929,-106.087067,-0.001000,0.003660,0.092958,291.131378,14.830939,0.929578,-106.087067,294.500519,0.000000
80.310005,64.961121,-106.131546,-0.001009,0.003660,0.092967,288.961487,14.720401,0.929669,-106.131546,294.500519,0.000000
80.760002,64.479279,-106.087067,-0.000992,0.003660,0.092967,286.818146,14.611214,0.929669,-106.087067,294.500519,0.000000
81.210007,66.649826,-106.131546,-0.000974,0.003519,0.089394,296.473236,15.103066,0.893939,-106.131546,294.500519,0.000000
81.660004,66.156067,-106.087067,-0.000983,0.003520,0.089402,294.276886,14.991179,0.894022,-106.087067,294.500519,0.000000
82.110001,65.730072,-106.131546,-0.000966,0.003525,0.089541,292.381958,14.894648,0.895408,-106.131546,294.500519,0.000000
82.560005,65.359558,-106.220512,-0.000966,0.003650,0.092706,290.733826,14.810687,0.927065,-106.220512,294.500519,0.000000
83.010002,65.250458,-106.176033,-0.000970,0.003683,0.093539,290.248535,14.785965,0.935391,-106.176033,294.500519,0.000000
83.460007,65.082138,-106.131546,-0.000966,0.003690,0.093730,289.499817,14.747823,0.937299,-106.131546,294.500519,0.000000
83.910004,65.190872,-106.131546,-0.000961,0.003695,0.093843,289.983490,14.772463,0.938427,-106.131546,294.500519,0.000000
84.360001,65.123856,-106.220512,-0.000953,0.003697,0.093912,289.685364,14.757277,0.939116,-106.220512,294.500519,0.000000
84.810005,65.028900,-106.131546,-0.000949,0.003700,0.093981,289.263000,14.735760,0.939812,-106.131546,294.500519,0.000000
85.260002,64.901169,-106.176033,-0.000949,0.003701,0.094016,288.694824,14.706815,0.940160,-106.176033,294.500519,0.000000
85.710007,65.113052,-106.176033,-0.000949,0.003707,0.094164,289.637329,14.754828,0.941636,-106.176033,294.500519,0.000000
86.160004,65.270569,-106.131546,-0.000936,0.003712,0.094276,290.337982,14.790523,0.942764,-106.131546,294.500519,0.000000
86.610001,65.035599,-106.220512,-0.000936,0.003712,0.094276,289.292786,14.737277,0.942764,-106.220512,294.500519,0.000000
87.060005,64.801010,-106.220512,-0.000944,0.003713,0.094302,288.249298,14.684118,0.943022,-106.220512,294.500519,0.000000
87.510002,66.071915,-106.220512,-0.000923,0.003724,0.094579,293.902557,14.972110,0.945792,-106.220512,294.500519,0.000000
87.960007,65.772522,-106.220512,-0.000927,0.003723,0.094571,292.570801,14.904266,0.945709,-106.220512,294.500519,0.000000
88.410004,65.467545,-106.264992,-0.000931,0.003724,0.094579,291.214172,14.835157,0.945792,-106.264992,294.500519,0.000000
88.860001,65.206512,-106.264992,-0.000927,0.003724,0.094579,290.053040,14.776007,0.945792,-106.264992,294.500519,0.000000
89.310005,64.920532,-106.264992,-0.000923,0.003724,0.094579,288.780945,14.711203,0.945792,-106.264992,294.500519,0.000000
89.760002,64.676636,-106.264992,-0.000918,0.003724,0.094579,287.696045,14.655934,0.945792,-106.264992,294.500519,0.000000
90.210007,66.236496,-106.309471,-0.000923,0.003737,0.094927,294.634644,15.009405,0.949267,-106.309471,294.500519,0.000000
90.660004,65.957596,-106.220512,-0.000923,0.003737,0.094918,293.394043,14.946205,0.949176,-106.220512,294.500519,0.000000
91.110001,65.745712,-106.220512,-0.000901,0.003737,0.094918,292.451538,14.898191,0.949176,-106.220512,294.500519,0.000000
91.560005,65.479843,-106.264992,-0.000905,0.003737,0.094918,291.268890,14.837944,0.949176,-106.264992,294.500519,0.000000
92.010002,65.225128,-106.264992,-0.000897,0.003737,0.094918,290.135864,14.780226,0.949176,-106.264992,294.500519,0.000000
92.460007,65.003571,-106.309471,-0.000918,0.003737,0.094918,289.150330,14.730020,0.949176,-106.309471,294.500519,0.000000
92.910004,64.767487,-106.309471,-0.000901,0.003737,0.094918,288.100159,14.676522,0.949176,-106.309471,294.500519,0.000000
93.360008,64.567154,-106.309471,-0.000901,0.003737,0.094918,287.209045,14.631126,0.949176,-106.309471,294.500519,0.000000
93.810005,66.290115,-106.353951,-0.000897,0.003733,0.094814,294.873169,15.021554,0.948139,-106.353951,294.500519,0.000000
94.260002,66.075638,-106.264992,-0.000897,0.003733,0.094814,293.919128,14.972954,0.948139,-106.264992,294.500519,0.000000
94.710007,65.867844,-106.309471,-0.000892,0.003733,0.094822,292.994812,14.925867,0.948222,-106.309471,294.500519,0.000000
95.160004,65.644806,-106.353951,-0.000884,0.003733,0.094822,292.002686,14.875325,0.948222,-106.353951,294.500519,0.000000
95.610008,65.467178,-106.353951,-0.000884,0.003733,0.094822,291.212555,14.835074,0.948222,-106.353951,294.500519,0.000000
96.060005,65.266464,-106.353951,-0.000880,0.003734,0.094840,290.319733,14.789592,0.948396,-106.353951,294.500519,0.000000
96.510002,65.192001,-106.309471,-0.000871,0.003755,0.095386,289.988495,14.772718,0.953862,-106.309471,294.500519,0.000000
96.960007,65.229233,-106.398437,-0.000884,0.003760,0.095507,290.154114,14.781156,0.955073,-106.398437,294.500519,0.000000
97.410004,65.088470,-106.398437,-0.000875,0.003760,0.095507,289.527985,14.749258,0.955073,-106.398437,294.500519,0.000000
97.860008,65.257904,-106.398437,-0.000880,0.003766,0.095647,290.281647,14.787653,0.956466,-106.398437,294.500519,0.000000
98.310005,65.222534,-106.398437,-0.000884,0.003766,0.095647,290.124329,14.779637,0.956466,-106.398437,294.500519,0.000000
98.760002,65.072098,-106.442917,-0.000875,0.003766,0.095647,289.455139,14.745547,0.956466,-106.442917,294.500519,0.000000
99.210007,64.998367,-106.442917,-0.000875,0.003767,0.095672,289.127167,14.728841,0.956723,-106.442917,294.500519,0.000000
99.660004,64.974899,-106.398437,-0.000871,0.003768,0.095707,289.022797,14.723523,0.957071,-106.398437,294.500519,0.000000
100.110008,64.882187,-106.487396,-0.000875,0.003769,0.095725,288.610382,14.702514,0.957245,-106.487396,294.500519,0.000000
100.560005,64.779404,-106.398437,-0.000880,0.003770,0.095768,288.153168,14.679223,0.957677,-106.398437,294.500519,0.000000
101.010002,65.774765,-106.442917,-0.000858,0.003780,0.096002,292.580780,14.904775,0.960016,-106.442917,294.500519,0.000000
101.460007,65.622452,-106.442917,-0.000867,0.003780,0.096002,291.903259,14.870260,0.960016,-106.442917,294.500519,0.000000
101.910004,65.512238,-106.487396,-0.000858,0.003780,0.096002,291.412994,14.845285,0.960016,-106.487396,294.500519,0.000000
102.360008,65.371109,-106.531876,-0.000867,0.003780,0.096002,290.785217,14.813306,0.960016,-106.531876,294.500519,0.000000
102.810005,65.271683,-106.442917,-0.000867,0.003780,0.096011,290.342957,14.790774,0.960107,-106.442917,294.500519,0.000000
103.260002,65.141724,-106.487396,-0.000849,0.003780,0.096011,289.764862,14.761325,0.960107,-106.487396,294.500519,0.000000
103.710007,65.018845,-106.487396,-0.000858,0.003780,0.096011,289.218262,14.733480,0.960107,-106.487396,294.500519,0.000000
104.160004,65.593414,-106.531876,-0.000849,0.003789,0.096245,291.774078,14.863680,0.962446,-106.531876,294.500519,0.000000
104.610008,65.585220,-106.531876,-0.000845,0.003789,0.096245,291.737640,14.861823,0.962446,-106.531876,294.500519,0.000000
105.060005,65.554306,-106.487396,-0.000854,0.003789,0.096245,291.600128,14.854818,0.962446,-106.487396,294.500519,0.000000
105.510002,65.469788,-106.576355,-0.000862,0.003789,0.096245,291.224152,14.835666,0.962446,-106.576355,294.500519,0.000000
105.960007,65.337967,-106.576355,-0.000849,0.003789,0.096245,290.637787,14.805795,0.962446,-106.576355,294.500519,0.000000
106.410004,65.245987,-106.531876,-0.000841,0.003789,0.096245,290.228638,14.784952,0.962446,-106.531876,294.500519,0.000000
106.860008,65.144699,-106.531876,-0.000854,0.003789,0.096245,289.778107,14.762000,0.962446,-106.531876,294.500519,0.000000
107.310005,65.035233,-106.576355,-0.000849,0.003789,0.096245,289.291168,14.737195,0.962446,-106.576355,294.500519,0.000000
107.760002,64.947342,-106.576355,-0.000858,0.003789,0.096245,288.900208,14.717278,0.962446,-106.576355,294.500519,0.000000
108.210007,64.830795,-106.576355,-0.000849,0.003789,0.096245,288.381775,14.690868,0.962446,-106.576355,294.500519,0.000000
108.660004,64.729874,-106.576355,-0.000849,0.003790,0.096254,287.932861,14.667999,0.962537,-106.576355,294.500519,0.000000
109.110008,64.654663,-106.665321,-0.000849,0.003790,0.096254,287.598297,14.650956,0.962537,-106.665321,294.500519,0.000000
109.560005,64.525818,-106.576355,-0.000849,0.003790,0.096254,287.025177,14.621759,0.962537,-106.576355,294.500519,0.000000
110.010002,65.772156,-106.620842,-0.000849,0.003803,0.096591,292.569153,14.904184,0.965913,-106.620842,294.500519,0.000000
110.460007,65.661926,-106.620842,-0.000836,0.003803,0.096591,292.078827,14.879205,0.965913,-106.620842,294.500519,0.000000
110.910004,65.578888,-106.576355,-0.000836,0.003803,0.096591,291.709473,14.860388,0.965913,-106.576355,294.500519,0.000000
111.360008,65.537186,-106.620842,-0.000845,0.003803,0.096591,291.523956,14.850938,0.965913,-106.620842,294.500519,0.000000
111.810005,65.447449,-106.709801,-0.000832,0.003803,0.096591,291.124786,14.830605,0.965913,-106.709801,294.500519,0.000000
112.260002,65.346909,-106.620842,-0.000828,0.003803,0.096591,290.677582,14.807821,0.965913,-106.620842,294.500519,0.000000
112.710007,65.264984,-106.665321,-0.000845,0.003803,0.096591,290.313141,14.789257,0.965913,-106.665321,294.500519,0.000000
113.160004,65.195724,-106.665321,-0.000849,0.003803,0.096591,290.005066,14.773561,0.965913,-106.665321,294.500519,0.000000
113.610008,65.090332,-106.665321,-0.000836,0.003803,0.096591,289.536255,14.749681,0.965913,-106.665321,294.500519,0.000000
114.060005,65.009537,-106.665321,-0.000824,0.003803,0.096591,289.176849,14.731372,0.965913,-106.665321,294.500519,0.000000
114.510002,64.936172,-106.665321,-0.000828,0.003803,0.096591,288.850525,14.714746,0.965913,-106.665321,294.500519,0.000000
114.960007,64.862442,-106.665321,-0.000841,0.003803,0.096591,288.522552,14.698040,0.965913,-106.665321,294.500519,0.000000
115.410004,64.767487,-106.709801,-0.000832,0.003803,0.096591,288.100159,14.676522,0.965913,-106.709801,294.500519,0.000000
115.860008,64.690033,-106.709801,-0.000824,0.003803,0.096591,287.755646,14.658971,0.965913,-106.709801,294.500519,0.000000
116.310005,64.617416,-106.709801,-0.000828,0.003803,0.096591,287.432617,14.642516,0.965913,-106.709801,294.500519,0.000000
116.760002,64.533264,-106.754280,-0.000836,0.003803,0.096591,287.058289,14.623446,0.965913,-106.754280,294.500519,0.000000
117.210007,64.464386,-106.754280,-0.000828,0.003803,0.096600,286.751923,14.607840,0.966004,-106.754280,294.500519,0.000000
117.660004,66.127396,-106.709801,-0.000824,0.003830,0.097285,294.149353,14.984682,0.972854,-106.709801,294.500519,0.000000
118.110008,66.322891,-106.754280,-0.000832,0.003796,0.096427,295.018951,15.028982,0.964270,-106.754280,294.500519,0.000000
118.560005,66.208572,-106.709801,-0.000819,0.003796,0.096427,294.510437,15.003077,0.964270,-106.709801,294.500519,0.000000
119.010002,66.131119,-106.798767,-0.000824,0.003796,0.096427,294.165894,14.985526,0.964270,-106.798767,294.500519,0.000000
119.460007,66.027222,-106.754280,-0.000824,0.003796,0.096427,293.703766,14.961983,0.964270,-106.754280,294.500519,0.000000
119.910004,65.927429,-106.754280,-0.000819,0.003797,0.096435,293.259857,14.939369,0.964353,-106.754280,294.500519,0.000000
120.360008,65.828751,-106.843246,-0.000824,0.003797,0.096435,292.820892,14.917008,0.964353,-106.843246,294.500519,0.000000
120.810005,65.817581,-106.798767,-0.000819,0.003797,0.096435,292.771210,14.914477,0.964353,-106.798767,294.500519,0.000000
121.260002,65.743103,-106.798767,-0.000819,0.003797,0.096435,292.439941,14.897600,0.964353,-106.798767,294.500519,0.000000
121.710007,65.611282,-106.754280,-0.000811,0.003797,0.096435,291.853546,14.867729,0.964353,-106.754280,294.500519,0.000000
122.160004,65.555801,-106.843246,-0.000824,0.003797,0.096435,291.606781,14.855157,0.964353,-106.843246,294.500519,0.000000
122.610008,65.519318,-106.798767,-0.000828,0.003797,0.096435,291.444489,14.846889,0.964353,-106.798767,294.500519,0.000000
123.060005,65.410950,-106.843246,-0.000819,0.003797,0.096435,290.962433,14.822333,0.964353,-106.843246,294.500519,0.000000
123.510002,65.334244,-106.887726,-0.000819,0.003798,0.096470,290.621216,14.804952,0.964702,-106.887726,294.500519,0.000000
123.960007,65.274292,-106.887726,-0.000811,0.003799,0.096505,290.354553,14.791366,0.965050,-106.887726,294.500519,0.000000
124.410004,65.241150,-106.843246,-0.000845,0.003807,0.096687,290.207123,14.783856,0.966867,-106.843246,1681.641113,0.000000
124.860008,65.196091,-106.887726,-0.000824,0.003802,0.096566,290.006683,14.773645,0.965655,-106.887726,0.096297,0.000000
125.310005,64.980865,-106.887726,-0.000815,0.003780,0.096019,289.049316,14.724874,0.960190,-106.887726,0.095551,0.000000
125.760010,64.929474,-106.887726,-0.000811,0.003756,0.095404,288.820740,14.713228,0.954036,-106.887726,0.094796,0.000000
126.210007,64.828552,-106.887726,-0.000815,0.003719,0.094467,288.371796,14.690360,0.944672,-106.887726,0.094051,0.000000
126.660004,64.763397,-106.932205,-0.000815,0.003689,0.093695,288.081970,14.675596,0.936951,-106.932205,0.093296,0.000000
127.110008,64.677002,-106.887726,-0.000811,0.003669,0.093192,287.697662,14.656018,0.931917,-106.887726,0.092551,0.000000
127.560005,64.518372,-106.932205,-0.000798,0.003642,0.092498,286.992065,14.620072,0.924983,-106.932205,0.091796,0.000000
128.010010,64.450226,-106.887726,-0.000815,0.003614,0.091787,286.688934,14.604630,0.917875,-106.887726,0.091050,0.000000
128.460007,63.868958,-106.976685,-0.000793,0.003583,0.091015,284.103302,14.472912,0.910154,-106.976685,0.090295,0.000000
128.910004,63.081009,-106.932205,-0.000811,0.003563,0.090504,280.598328,14.294361,0.905037,-106.932205,0.089550,0.000000
129.360001,61.378899,-107.021172,-0.000802,0.003525,0.089541,273.026978,13.908657,0.895408,-107.021172,0.088795,0.000000
129.810013,59.740463,-106.976685,-0.000789,0.003496,0.088804,265.738861,13.537383,0.888042,-106.976685,0.088050,0.000000
130.260010,57.636559,-106.976685,-0.000789,0.003470,0.088145,256.380219,13.060631,0.881449,-106.976685,0.087295,0.000000
130.710007,55.322632,-106.976685,-0.000780,0.003440,0.087364,246.087357,12.536287,0.873645,-106.976685,0.086549,0.000000
131.160004,52.912270,-106.932205,-0.000776,0.003414,0.086705,235.365524,11.990091,0.867051,-106.932205,0.085794,0.000000
131.610001,50.417000,-106.976685,-0.000785,0.003387,0.086037,224.266022,11.424656,0.860375,-106.976685,0.085049,0.000000
132.060013,47.745224,-106.976685,-0.000776,0.003362,0.085387,212.381363,10.819222,0.853872,-106.976685,0.084294,0.000000
132.510010,44.350677,-106.932205,-0.000789,0.003329,0.084555,197.281662,10.050007,0.845546,-106.932205,0.083549,0.000000
132.960007,41.073059,-107.065651,-0.000798,0.003299,0.083800,182.702087,9.307288,0.837998,-107.065651,0.082794,0.000000
133.410004,38.526772,-107.021172,-0.000789,0.003274,0.083158,171.375641,8.730290,0.831579,-107.021172,0.082048,0.000000
133.860001,34.848106,-107.021172,-0.000798,0.003241,0.082326,155.012115,7.896694,0.823260,-107.021172,0.081293,0.000000
134.310013,31.946579,-106.976685,-0.000793,0.003213,0.081606,142.105484,7.239198,0.816061,-106.976685,0.080548,0.000000
134.760010,27.685898,-106.976685,-0.000806,0.003174,0.080626,123.153023,6.273714,0.806258,-106.976685,0.079793,0.000000
135.210007,25.258774,-107.021172,-0.000798,0.003153,0.080079,112.356636,5.723720,0.800793,-107.021172,0.079048,0.000000
135.660004,22.124886,-107.021172,-0.000802,0.003122,0.079308,98.416405,5.013571,0.793079,-107.021172,0.078293,0.000000
136.110001,18.742996,-106.976685,-0.000815,0.003093,0.078571,83.373009,4.247223,0.785706,-106.976685,0.077547,0.000000
136.560013,15.765511,-106.976685,-0.000824,0.003065,0.077851,70.128494,3.572516,0.778507,-106.976685,0.076792,0.000000
137.010010,12.278984,-107.021172,-0.000819,0.003033,0.077027,54.619648,2.782458,0.770272,-107.021172,0.076047,0.000000
137.460007,9.413582,-107.065651,-0.000832,0.003004,0.076307,41.873703,2.133148,0.763073,-107.065651,0.075292,0.000000
137.910004,7.316376,-107.110130,-0.000845,0.002986,0.075839,32.544865,1.657914,0.758387,-107.110130,0.074547,0.000000
138.360001,3.550201,-107.021172,-0.000849,0.002946,0.074833,15.792085,0.804487,0.748327,-107.021172,0.073792,0.000000
138.810013,0.544411,-107.110130,-0.000854,0.002913,0.073992,2.421660,0.123365,0.739917,-107.110130,0.073046,0.000000
139.260010,-1.446663,-107.065651,-0.000871,0.002893,0.073480,-6.435078,-0.327819,0.734800,-107.065651,0.072292,0.000000
139.710007,-3.596371,-107.110130,-0.000880,0.002860,0.072639,-15.997456,-0.814949,0.726389,-107.110130,0.071546,0.000000
140.160004,-0.146713,-107.021172,-0.000961,0.002825,0.071746,-0.652613,-0.033246,0.717457,-107.021172,0.070792,0.000000
140.610001,-0.027184,-107.110130,-0.000987,0.002803,0.071199,-0.120918,-0.006160,0.711992,-107.110130,0.070046,0.000000
141.060013,0.033890,-107.110130,-0.001030,0.002774,0.070462,0.150749,0.007680,0.704619,-107.110130,0.069292,0.000000
141.510010,0.008194,-107.110130,-0.001078,0.002741,0.069621,0.036449,0.001857,0.696209,-107.110130,0.068545,0.000000
141.960007,-0.030159,-107.154610,-0.001121,0.002711,0.068866,-0.134154,-0.006834,0.688662,-107.154610,0.067800,0.000000
142.410004,-0.028297,-107.110130,-0.001160,0.002676,0.067982,-0.125873,-0.006412,0.679820,-107.110130,0.067045,0.000000
142.860001,0.010429,-107.110130,-0.001194,0.002656,0.067461,0.046392,0.002363,0.674612,-107.110130,0.066299,0.000000
143.310013,-0.012283,-107.110130,-0.001233,0.002635,0.066932,-0.054639,-0.002783,0.669321,-107.110130,0.065545,0.000000
143.760010,-0.022339,-107.154610,-0.001268,0.002592,0.065848,-0.099368,-0.005062,0.658481,-107.154610,0.064799,0.000000
144.210007,-0.023827,-107.154610,-0.001315,0.002562,0.065077,-0.105986,-0.005399,0.650767,-107.154610,0.064044,0.000000
144.660004,-0.040588,-107.154610,-0.001345,0.002534,0.064365,-0.180546,-0.009197,0.643652,-107.154610,0.063299,0.000000
145.110001,-0.030533,-107.154610,-0.001384,0.002510,0.063750,-0.135817,-0.006919,0.637497,-107.154610,0.062545,0.000000
145.560013,-0.039093,-107.154610,-0.001431,0.002474,0.062848,-0.173894,-0.008859,0.628482,-107.154610,0.061798,0.000000
146.010010,-0.012283,-107.154610,-0.001462,0.002441,0.061998,-0.054639,-0.002783,0.619981,-107.154610,0.061044,0.000000
146.460007,-0.012657,-107.199089,-0.001483,0.002420,0.061460,-0.056302,-0.002868,0.614599,-107.199089,0.060298,0.000000
146.910004,-0.038727,-107.154610,-0.001522,0.002383,0.060533,-0.172265,-0.008776,0.605326,-107.154610,0.059544,0.000000
147.360001,-0.036491,-107.199089,-0.001556,0.002363,0.060029,-0.162322,-0.008269,0.600292,-107.199089,0.058798,0.000000
147.810013,-0.053619,-107.154610,-0.001617,0.002322,0.058980,-0.238511,-0.012150,0.589800,-107.154610,0.058044,0.000000
148.260010,-0.070000,-107.243576,-0.001630,0.002292,0.058217,-0.311374,-0.015862,0.582170,-107.243576,0.057297,0.000000
148.710007,-0.055855,-107.199089,-0.001669,0.002283,0.057982,-0.248455,-0.012657,0.579823,-107.199089,0.056543,0.000000
149.160004,-0.030159,-107.288055,-0.001707,0.002244,0.056994,-0.134154,-0.006834,0.569937,-107.288055,0.055797,0.000000
149.610001,-0.055107,-107.288055,-0.001746,0.002210,0.056127,-0.245129,-0.012487,0.561270,-107.288055,0.055043,0.000000
150.060013,-0.081543,-107.288055,-0.001772,0.002180,0.055381,-0.362721,-0.018478,0.553813,-107.288055,0.054297,0.000000
150.510010,-0.046547,-107.243576,-0.001785,0.002165,0.054982,-0.207051,-0.010548,0.549824,-107.243576,0.053543,0.000000
150.960007,-0.062180,-107.199089,-0.001863,0.002119,0.053811,-0.276589,-0.014090,0.538114,-107.199089,0.052797,0.000000
151.410004,-0.065163,-107.288055,-0.001871,0.002088,0.053031,-0.289858,-0.014766,0.530309,-107.288055,0.052042,0.000000
151.860001,-0.055107,-107.243576,-0.001923,0.002057,0.052241,-0.245129,-0.012487,0.522414,-107.243576,0.051297,0.000000
152.310013,-0.061813,-107.243576,-0.001949,0.002027,0.051487,-0.274960,-0.014007,0.514874,-107.243576,0.050542,0.000000
152.760010,-0.069633,-107.288055,-0.001988,0.001998,0.050758,-0.309745,-0.015779,0.507585,-107.288055,0.049796,0.000000
153.210007,-0.062180,-107.243576,-0.002005,0.001973,0.050126,-0.276589,-0.014090,0.501256,-107.243576,0.049042,0.000000
153.660004,-0.042816,-107.332535,-0.002065,0.001937,0.049189,-0.190456,-0.009702,0.491893,-107.332535,0.048296,0.000000
154.110001,-0.043938,-107.288055,-0.002095,0.001905,0.048391,-0.195445,-0.009956,0.483914,-107.288055,0.047541,0.000000
154.560013,-0.049522,-107.288055,-0.002113,0.001887,0.047940,-0.220287,-0.011222,0.479402,-107.288055,0.046796,0.000000
155.010010,-0.065163,-107.332535,-0.002151,0.001854,0.047099,-0.289858,-0.014766,0.470992,-107.332535,0.046041,0.000000
155.460007,-0.053619,-107.288055,-0.002186,0.001825,0.046345,-0.238511,-0.012150,0.463445,-107.288055,0.045295,0.000000
155.910004,-0.061440,-107.288055,-0.002220,0.001791,0.045494,-0.273297,-0.013922,0.454944,-107.288055,0.044541,0.000000
156.360001,-0.070374,-107.332535,-0.002242,0.001762,0.044766,-0.313037,-0.015947,0.447662,-107.332535,0.043795,0.000000
156.810013,-0.079681,-107.332535,-0.002285,0.001735,0.044064,-0.354441,-0.018056,0.440637,-107.332535,0.043040,0.000000
157.260010,-0.077454,-107.377014,-0.002302,0.001705,0.043301,-0.344531,-0.017551,0.433007,-107.377014,0.042295,0.000000
157.710007,-0.041328,-107.377014,-0.002354,0.001673,0.042503,-0.183838,-0.009365,0.425029,-107.377014,0.041540,0.000000
158.160004,-0.024200,-107.332535,-0.002397,0.001643,0.041731,-0.107649,-0.005484,0.417307,-107.332535,0.040794,0.000000
158.610001,-0.051758,-107.377014,-0.002423,0.001614,0.040985,-0.230230,-0.011728,0.409851,-107.377014,0.040040,0.000000
159.060013,-0.062927,-107.421494,-0.002440,0.001588,0.040326,-0.279914,-0.014260,0.403258,-107.421494,0.039294,0.000000
159.510010,-0.050270,-107.421494,-0.002483,0.001557,0.039537,-0.223612,-0.011391,0.395370,-107.421494,0.038539,0.000000
159.960007,0.010803,-107.377014,-0.002514,0.001522,0.038661,0.048055,0.002448,0.386612,-107.377014,0.037794,0.000000
160.410004,-0.004837,-107.421494,-0.002557,0.001498,0.038037,-0.021516,-0.001096,0.380367,-107.421494,0.037039,0.000000
160.860001,-0.019363,-107.421494,-0.002578,0.001472,0.037386,-0.086133,-0.004388,0.373864,-107.421494,0.036293,0.000000
161.310013,-0.030533,-107.421494,-0.002626,0.001436,0.036476,-0.135817,-0.006919,0.364758,-107.421494,0.035548,0.000000
161.760010,-0.014519,-107.465981,-0.002656,0.001411,0.035842,-0.064583,-0.003290,0.358422,-107.465981,0.034793,0.000000
162.210007,-0.006325,-107.421494,-0.002673,0.001390,0.035305,-0.028134,-0.001433,0.353047,-107.421494,0.034047,0.000000
162.660004,-0.008934,-107.465981,-0.002716,0.001353,0.034368,-0.039741,-0.002024,0.343684,-107.465981,0.033293,0.000000
163.110001,-0.016380,-107.465981,-0.002746,0.001323,0.033614,-0.072863,-0.003712,0.336137,-107.465981,0.032547,0.000000
163.560013,-0.042816,-107.465981,-0.002777,0.001291,0.032798,-0.190456,-0.009702,0.327984,-107.465981,0.031792,0.000000
164.010010,-0.008186,-107.465981,-0.002807,0.001262,0.032044,-0.036415,-0.001855,0.320437,-107.465981,0.031047,0.000000
164.460007,-0.041702,-107.465981,-0.002841,0.001230,0.031246,-0.185501,-0.009450,0.312458,-107.465981,0.030292,0.000000
164.910004,-0.022713,-107.465981,-0.002880,0.001208,0.030683,-0.101031,-0.005147,0.306826,-107.465981,0.029546,0.000000
165.360001,-0.014519,-107.465981,-0.002928,0.001170,0.029729,-0.064583,-0.003290,0.297288,-107.465981,0.028792,0.000000
165.810013,-0.059952,-107.554939,-0.002940,0.001143,0.029035,-0.266679,-0.013585,0.290347,-107.554939,0.028046,0.000000
166.260010,-0.068512,-107.554939,-0.002975,0.001114,0.028297,-0.304756,-0.015525,0.282974,-107.554939,0.027291,0.000000
166.710007,-0.026062,-107.510460,-0.003005,0.001082,0.027491,-0.115930,-0.005906,0.274912,-107.510460,0.026546,0.000000
167.160004,-0.032394,-107.554939,-0.003040,0.001054,0.026762,-0.144098,-0.007341,0.267622,-107.554939,0.025791,0.000000
167.610001,-0.035370,-107.510460,-0.003078,0.001022,0.025948,-0.157333,-0.008015,0.259477,-107.510460,0.025045,0.000000
168.060013,-0.048775,-107.599419,-0.003104,0.000995,0.025279,-0.216961,-0.011053,0.252793,-107.599419,0.024291,0.000000
168.510010,-0.032768,-107.554939,-0.003143,0.000968,0.024594,-0.145760,-0.007425,0.245942,-107.554939,0.023545,0.000000
168.960007,-0.042450,-107.599419,-0.003173,0.000952,0.024178,-0.188827,-0.009619,0.241779,-107.599419,0.022790,0.000000
169.410004,-0.061066,-107.554939,-0.003208,0.000907,0.023042,-0.271634,-0.013838,0.230424,-107.554939,0.022045,0.000000
169.860001,-0.035370,-107.599419,-0.003260,0.000884,0.022453,-0.157333,-0.008015,0.224528,-107.599419,0.021290,0.000000
170.310013,-0.055855,-107.599419,-0.003285,0.000859,0.021819,-0.248455,-0.012657,0.218192,-107.599419,0.020544,0.000000
170.760010,-0.049149,-107.643898,-0.003324,0.000823,0.020909,-0.218624,-0.011137,0.209085,-107.643898,0.019790,0.000000
171.210007,-0.088997,-107.599419,-0.003350,0.000791,0.020102,-0.395878,-0.020167,0.201023,-107.599419,0.019044,0.000000
171.660004,-0.081543,-107.643898,-0.003389,0.000759,0.019279,-0.362721,-0.018478,0.192787,-107.643898,0.018290,0.000000
172.110001,-0.075218,-107.688385,-0.003402,0.000742,0.018853,-0.334587,-0.017045,0.188533,-107.688385,0.017544,0.000000
172.560013,-0.077080,-107.643898,-0.003458,0.000705,0.017908,-0.342868,-0.017467,0.179079,-107.643898,0.016790,0.000000
173.010010,-0.080803,-107.688385,-0.003488,0.000668,0.016971,-0.359429,-0.018310,0.169715,-107.688385,0.016043,0.000000
173.460007,-0.065536,-107.688385,-0.003527,0.000640,0.016252,-0.291521,-0.014851,0.162516,-107.688385,0.015289,0.000000
173.910004,-0.066650,-107.688385,-0.003548,0.000616,0.015644,-0.296476,-0.015103,0.156445,-107.688385,0.014543,0.000000
174.360016,-0.077080,-107.732864,-0.003587,0.000586,0.014881,-0.342868,-0.017467,0.148814,-107.732864,0.013789,0.000000
174.810013,-0.070374,-107.732864,-0.003609,0.000551,0.013997,-0.313037,-0.015947,0.139973,-107.732864,0.013043,0.000000
175.260010,-0.086014,-107.643898,-0.003639,0.000523,0.013277,-0.382608,-0.019491,0.132774,-107.643898,0.012289,0.000000
175.710007,-0.058090,-107.688385,-0.003665,0.000497,0.012635,-0.258398,-0.013163,0.126355,-107.688385,0.011542,0.000000
176.160004,-0.104637,-107.732864,-0.003704,0.000467,0.011872,-0.465449,-0.023711,0.118725,-107.732864,0.010788,0.000000
176.610016,-0.068138,-107.688385,-0.003738,0.000439,0.011143,-0.303093,-0.015440,0.111435,-107.688385,0.010042,0.000000
177.060013,-0.076706,-107.732864,-0.003764,0.000406,0.010312,-0.341205,-0.017382,0.103116,-107.732864,0.009288,0.000000
177.510010,-0.084152,-107.688385,-0.003803,0.000369,0.009384,-0.374328,-0.019069,0.093835,-107.688385,0.008543,0.000000
177.960007,-0.096443,-107.777344,-0.003829,0.000347,0.008802,-0.429001,-0.021854,0.088022,-107.777344,0.007788,0.000000
178.410004,-0.067398,-107.732864,-0.003859,0.000313,0.007961,-0.299802,-0.015273,0.079611,-107.732864,0.007042,0.000000
178.860016,-0.068138,-107.777344,-0.003902,0.000285,0.007241,-0.303093,-0.015440,0.072413,-107.777344,0.006287,0.000000
179.310013,-0.065163,-107.732864,-0.003915,0.000263,0.006669,-0.289858,-0.014766,0.066690,-107.732864,0.005542,0.000000
179.760010,-0.083778,-107.777344,-0.003954,0.000229,0.005811,-0.372665,-0.018984,0.058106,-107.777344,0.004787,0.000000
180.210007,-0.069633,-107.866310,-0.003988,0.000199,0.005048,-0.309745,-0.015779,0.050475,-107.866310,0.004042,0.000000
180.660004,-0.051384,-107.732864,-0.004023,0.000174,0.004431,-0.228567,-0.011644,0.044314,-107.732864,0.003287,0.000000
181.110016,-0.047661,-107.732864,-0.004040,0.000142,0.003616,-0.212006,-0.010800,0.036161,-107.732864,0.002541,0.000000
181.560013,-0.024200,-107.777344,-0.004083,0.000108,0.002749,-0.107649,-0.005484,0.027493,-107.777344,0.001795,0.000000
182.010010,-0.034630,-107.777344,-0.004105,0.000083,0.002116,-0.154041,-0.007847,0.021158,-107.777344,0.001041,0.000000
182.460007,-0.033882,-107.732864,-0.004143,0.000050,0.001275,-0.150715,-0.007678,0.012748,-107.732864,0.000294,0.000000
182.910004,-0.046547,-107.821823,-0.004178,0.000020,0.000512,-0.207051,-0.010548,0.005117,-107.821823,-0.000459,0.000000
183.360016,-0.032768,-107.821823,-0.004199,0.000004,0.000095,-0.145760,-0.007425,0.000954,-107.821823,-0.000000,0.000000
183.400009,-0.037979,-107.866310,-0.004204,0.000004,0.000095,-0.168940,-0.008606,0.000954,-107.866310,-0.000000,0.000000