File: Data/compression 22/AutoNoHeating-17-22-reverse-1-1_09172024_163230.csv
Time (sec),S:Load (lbs),S:HL1 (DIM),S:LVDT (in),S:Position (in),Ch:Position (mm),Ch:Load (N),Ch:Stress (MPa),Ch:Strain (mm/mm),Ch:HL1 (DIM),Set Point (),Cycles ()
0.110000,-0.002602,-100.704872,-0.006571,-0.006195,-0.157358,-0.011573,-0.000590,-1.573578,-100.704872,-0.157063,0.000000
0.480000,0.020485,-100.749352,-0.006579,-0.006113,-0.155259,0.091121,0.004642,-1.552594,-100.749352,-0.154496,0.000000
0.850000,0.016014,-100.660393,-0.006428,-0.005887,-0.149536,0.071234,0.003629,-1.495359,-100.660393,-0.148339,0.000000
1.220000,-0.014519,-100.660393,-0.006191,-0.005642,-0.143309,-0.064583,-0.003290,-1.433090,-100.660393,-0.142164,0.000000
1.590000,0.056229,-100.704872,-0.005976,-0.005403,-0.137230,0.250117,0.012742,-1.372297,-100.704872,-0.136007,0.000000
1.960000,0.056602,-100.749352,-0.005717,-0.005160,-0.131072,0.251780,0.012826,-1.310724,-100.749352,-0.129850,0.000000
2.330000,0.075226,-100.704872,-0.005450,-0.004923,-0.125036,0.334621,0.017046,-1.250363,-100.704872,-0.123675,0.000000
2.700000,0.059212,-100.793839,-0.005217,-0.004678,-0.118810,0.263387,0.013418,-1.188101,-100.793839,-0.117518,0.000000
3.070000,0.074478,-100.704872,-0.004971,-0.004436,-0.112679,0.331295,0.016877,-1.126786,-100.704872,-0.111343,0.000000
3.440000,0.066284,-100.749352,-0.004708,-0.004193,-0.106496,0.294847,0.015020,-1.064956,-100.749352,-0.105186,0.000000
3.810000,0.122887,-100.749352,-0.004570,0.000006,0.000165,0.546627,0.027847,0.001650,-100.749352,0.000329,0.000000
4.180000,0.110970,-100.749352,-0.004562,0.000006,0.000156,0.493617,0.025146,0.001559,-100.749352,0.000416,0.000000
4.550000,0.099800,-100.660393,-0.004579,0.000006,0.000156,0.443933,0.022615,0.001559,-100.660393,0.001032,0.000000
4.920000,0.134430,-100.749352,-0.004575,0.000006,0.000165,0.597974,0.030462,0.001650,-100.749352,0.001648,0.000000
5.290000,0.169060,-100.749352,-0.004566,0.000043,0.001084,0.752015,0.038309,0.010840,-100.749352,0.002263,0.000000
5.660000,0.226776,-100.793839,-0.004523,0.000074,0.001890,1.008751,0.051388,0.018902,-100.793839,0.002879,0.000000
6.030000,0.262527,-100.793839,-0.004493,0.000102,0.002584,1.167781,0.059490,0.025843,-100.793839,0.003495,0.000000
6.400000,0.341095,-100.749352,-0.004475,0.000123,0.003122,1.517266,0.077293,0.031218,-100.749352,0.004110,0.000000
6.770000,0.412216,-100.793839,-0.004475,0.000145,0.003677,1.833629,0.093410,0.036766,-100.793839,0.004727,0.000000
7.140000,0.548882,-100.749352,-0.004441,0.000164,0.004171,2.441547,0.124378,0.041710,-100.749352,0.005351,0.000000
7.510000,0.723892,-100.838318,-0.004406,0.000195,0.004952,3.220033,0.164036,0.049522,-100.838318,0.005967,0.000000
7.880001,0.827042,-100.793839,-0.004389,0.000219,0.005558,3.678865,0.187410,0.055585,-100.793839,0.006582,0.000000
8.250000,0.986046,-100.838318,-0.004368,0.000241,0.006114,4.386151,0.223441,0.061141,-100.838318,0.007198,0.000000
8.620001,1.232185,-100.838318,-0.004350,0.000266,0.006755,5.481034,0.279217,0.067553,-100.838318,0.007814,0.000000
8.990001,1.492470,-100.838318,-0.004320,0.000288,0.007319,6.638837,0.338198,0.073192,-100.838318,0.008430,0.000000
9.360001,1.644775,-100.838318,-0.004307,0.000305,0.007753,7.316326,0.372711,0.077530,-100.838318,0.009045,0.000000
9.730000,2.001503,-100.749352,-0.004273,0.000337,0.008551,8.903130,0.453547,0.085508,-100.749352,0.009661,0.000000
10.100000,2.386909,-100.838318,-0.004264,0.000365,0.009279,10.617504,0.540881,0.092790,-100.838318,0.010277,0.000000
10.470000,2.749977,-100.838318,-0.004225,0.000390,0.009913,12.232509,0.623154,0.099126,-100.838318,0.010901,0.000000
10.840000,3.059418,-100.882797,-0.004217,0.000408,0.010372,13.608970,0.693274,0.103721,-100.882797,0.011517,0.000000
11.210001,3.509239,-100.927277,-0.004199,0.000430,0.010927,15.609876,0.795205,0.109270,-100.927277,0.012132,0.000000
11.580001,4.011574,-100.749352,-0.004156,0.000457,0.011620,17.844372,0.909036,0.116204,-100.749352,0.012748,0.000000
11.950001,4.506454,-100.838318,-0.004143,0.000483,0.012280,20.045712,1.021177,0.122797,-100.838318,0.013364,0.000000
12.320001,4.962608,-100.838318,-0.004126,0.000505,0.012817,22.074785,1.124543,0.128172,-100.838318,0.013980,0.000000
12.690001,5.530106,-100.927277,-0.004109,0.000531,0.013486,24.599138,1.253140,0.134856,-100.927277,0.014595,0.000000
13.060000,5.999664,-100.927277,-0.004079,0.000553,0.014040,26.687840,1.359543,0.140404,-100.927277,0.015211,0.000000
13.430000,6.619667,-100.882797,-0.004079,0.000578,0.014673,29.445749,1.500038,0.146733,-100.882797,0.015827,0.000000
13.800000,7.072098,-100.838318,-0.004053,0.000601,0.015272,31.458261,1.602560,0.152721,-100.838318,0.016451,0.000000
14.170001,7.466072,-100.927277,-0.004027,0.000620,0.015740,33.210747,1.691836,0.157399,-100.927277,0.017067,0.000000
14.540001,8.513184,-100.927277,-0.004018,0.000655,0.016625,37.868530,1.929115,0.166248,-100.927277,0.017683,0.000000
14.910001,8.729904,-100.927277,-0.003984,0.000674,0.017119,38.832554,1.978225,0.171191,-100.927277,0.018298,0.000000
15.280001,8.862465,-100.882797,-0.003949,0.000688,0.017483,39.422215,2.008263,0.174832,-100.882797,0.018914,0.000000
15.650001,10.052567,-100.927277,-0.003936,0.000728,0.018489,44.716049,2.277944,0.184892,-100.927277,0.019530,0.000000
16.020000,10.077148,-100.927277,-0.003919,0.000744,0.018906,44.825394,2.283514,0.189056,-100.927277,0.020145,0.000000
16.390001,10.656929,-100.971756,-0.003885,0.000770,0.019565,47.404388,2.414895,0.195649,-100.971756,0.020762,0.000000
16.760000,11.619888,-100.971756,-0.003872,0.000802,0.020379,51.687843,2.633104,0.203794,-100.971756,0.021377,0.000000
17.130001,11.812027,-100.971756,-0.003846,0.000820,0.020831,52.542519,2.676644,0.208305,-100.971756,0.022002,0.000000
17.500000,12.484535,-100.927277,-0.003820,0.000852,0.021628,55.533985,2.829036,0.216284,-100.927277,0.022617,0.000000
17.870001,12.617096,-100.971756,-0.003811,0.000872,0.022149,56.123646,2.859075,0.221492,-100.971756,0.023233,0.000000
18.240002,13.365196,-100.971756,-0.003781,0.000899,0.022843,59.451363,3.028597,0.228426,-100.971756,0.023849,0.000000
18.610001,13.599045,-101.016243,-0.003764,0.000920,0.023372,60.491573,3.081588,0.233717,-101.016243,0.024464,0.000000
18.980001,13.754326,-101.016243,-0.003738,0.000935,0.023745,61.182297,3.116775,0.237449,-101.016243,0.025080,0.000000
19.350000,14.775742,-101.016243,-0.003704,0.000973,0.024724,65.725784,3.348231,0.247244,-101.016243,0.025696,0.000000
19.720001,14.887825,-100.971756,-0.003695,0.000993,0.025228,66.224350,3.373629,0.252278,-100.971756,0.026312,0.000000
20.090000,15.554001,-101.016243,-0.003673,0.001020,0.025904,69.187653,3.524587,0.259038,-101.016243,0.026927,0.000000
20.460001,15.743538,-100.971756,-0.003656,0.001040,0.026425,70.030754,3.567537,0.264246,-100.971756,0.027552,0.000000
20.830002,16.499084,-101.016243,-0.003626,0.001069,0.027153,73.391594,3.738746,0.271528,-101.016243,0.028167,0.000000
21.200001,16.913162,-100.971756,-0.003622,0.001095,0.027812,75.233505,3.832577,0.278122,-100.971756,0.028783,0.000000
21.570002,17.251648,-101.105202,-0.003591,0.001120,0.028436,76.739166,3.909279,0.284359,-101.105202,0.029399,0.000000
21.940001,17.647476,-101.105202,-0.003561,0.001142,0.029000,78.499893,3.998975,0.289999,-101.105202,0.030015,0.000000
22.310001,17.875374,-101.060722,-0.003544,0.001164,0.029572,79.513634,4.050618,0.295721,-101.060722,0.030630,0.000000
22.680000,18.367645,-101.105202,-0.003527,0.001188,0.030179,81.703369,4.162168,0.301792,-101.105202,0.031246,0.000000
23.050001,18.211998,-101.105202,-0.003497,0.001200,0.030474,81.011009,4.126898,0.304745,-101.105202,0.031862,0.000000
23.420002,19.375290,-101.060722,-0.003475,0.001240,0.031506,86.185593,4.390503,0.315062,-101.060722,0.032477,0.000000
23.790001,19.412155,-101.105202,-0.003441,0.001263,0.032088,86.349579,4.398857,0.320876,-101.105202,0.033102,0.000000
24.160002,19.505241,-101.105202,-0.003415,0.001282,0.032573,86.763649,4.419951,0.325728,-101.105202,0.033717,0.000000
24.530001,20.074600,-101.016243,-0.003410,0.001307,0.033189,89.296280,4.548970,0.331890,-101.016243,0.034334,0.000000
24.900002,20.945580,-101.105202,-0.003385,0.001338,0.033978,93.170593,4.746336,0.339778,-101.105202,0.034949,0.000000
25.270000,21.001068,-101.105202,-0.003363,0.001362,0.034594,93.417419,4.758910,0.345939,-101.105202,0.035565,0.000000
25.640001,20.977608,-101.149681,-0.003324,0.001381,0.035071,93.313057,4.753594,0.350708,-101.149681,0.036181,0.000000
26.010002,21.654579,-101.105202,-0.003298,0.001408,0.035773,96.324379,4.906998,0.357733,-101.105202,0.036796,0.000000
26.380001,21.568558,-101.105202,-0.003281,0.001430,0.036319,95.941734,4.887505,0.363191,-101.105202,0.037412,0.000000
26.750002,22.945595,-101.149681,-0.003277,0.001462,0.037134,102.067101,5.199546,0.371344,-101.149681,0.038028,0.000000
27.120001,22.681580,-101.194160,-0.003247,0.001479,0.037577,100.892708,5.139719,0.375772,-101.194160,0.038652,0.000000
27.490002,23.242004,-101.105202,-0.003216,0.001509,0.038340,103.385597,5.266713,0.383402,-101.105202,0.039268,0.000000
27.860001,23.464684,-101.194160,-0.003199,0.001533,0.038947,104.376122,5.317173,0.389473,-101.194160,0.039884,0.000000
28.230001,23.237907,-101.149681,-0.003173,0.001551,0.039398,103.367378,5.265785,0.393977,-101.149681,0.040499,0.000000
28.600002,23.731674,-101.105202,-0.003165,0.001575,0.040014,105.563759,5.377674,0.400139,-101.105202,0.041115,0.000000
28.970001,24.258209,-101.238647,-0.003139,0.001602,0.040682,107.905907,5.496989,0.406816,-101.238647,0.041731,0.000000
29.340002,24.509560,-101.194160,-0.003109,0.001626,0.041289,109.023964,5.553946,0.412887,-101.194160,0.042347,0.000000
29.710001,25.038330,-101.194160,-0.003078,0.001651,0.041939,111.376053,5.673767,0.419389,-101.194160,0.042962,0.000000
30.080002,25.125832,-101.194160,-0.003057,0.001674,0.042511,111.765282,5.693595,0.425112,-101.194160,0.043587,0.000000
30.450001,25.420380,-101.194160,-0.003035,0.001695,0.043049,113.075493,5.760340,0.430494,-101.194160,0.044202,0.000000
30.820002,26.122307,-101.194160,-0.003022,0.001723,0.043760,116.197823,5.919399,0.437602,-101.194160,0.044818,0.000000
31.190001,26.289497,-101.194160,-0.003001,0.001746,0.044350,116.941528,5.957285,0.443499,-101.194160,0.045434,0.000000
31.560001,26.927376,-101.238647,-0.002962,0.001774,0.045070,119.778946,6.101830,0.450698,-101.238647,0.046049,0.000000
31.930002,26.918434,-101.194160,-0.002936,0.001797,0.045634,119.739174,6.099804,0.456337,-101.194160,0.046665,0.000000
32.300003,26.862206,-101.194160,-0.002932,0.001816,0.046119,119.489059,6.087063,0.461189,-101.194160,0.047281,0.000000
32.670002,27.734673,-101.238647,-0.002915,0.001845,0.046865,123.369987,6.284767,0.468646,-101.238647,0.047897,0.000000
33.040001,27.891815,-101.238647,-0.002871,0.001868,0.047446,124.068993,6.320376,0.474459,-101.238647,0.048513,0.000000
33.410000,28.149498,-101.238647,-0.002846,0.001890,0.048010,125.215218,6.378767,0.480099,-101.238647,0.049137,0.000000
33.780003,28.775085,-101.238647,-0.002820,0.001918,0.048712,127.997971,6.520527,0.487124,-101.238647,0.049752,0.000000
34.150002,28.750511,-101.283127,-0.002807,0.001939,0.049241,127.888664,6.514959,0.492407,-101.283127,0.050369,0.000000
34.520000,29.372368,-101.238647,-0.002790,0.001963,0.049848,130.654816,6.655873,0.498478,-101.238647,0.050984,0.000000
34.890003,29.901138,-101.283127,-0.002764,0.001990,0.050542,133.006912,6.775695,0.505420,-101.283127,0.051600,0.000000
35.260002,30.248566,-101.327606,-0.002738,0.002012,0.051097,134.552338,6.854423,0.510968,-101.327606,0.052216,0.000000
35.630001,30.950111,-101.283127,-0.002703,0.002038,0.051774,137.672974,7.013395,0.517736,-101.283127,0.052831,0.000000
36.000000,31.086029,-101.283127,-0.002690,0.002059,0.052302,138.277557,7.044195,0.523019,-101.283127,0.053447,0.000000
36.370003,30.897232,-101.372086,-0.002673,0.002076,0.052736,137.437759,7.001413,0.527357,-101.372086,0.054063,0.000000
36.740002,30.498428,-101.372086,-0.002647,0.002101,0.053378,135.663788,6.911043,0.533776,-101.372086,0.054687,0.000000
37.110001,32.560623,-101.372086,-0.002626,0.002133,0.054185,144.836884,7.378343,0.541846,-101.372086,0.055303,0.000000
37.480003,33.910477,-101.327606,-0.002596,0.002165,0.054999,150.841339,7.684224,0.549991,-101.327606,0.055919,0.000000
37.850002,32.467903,-101.327606,-0.002574,0.002169,0.055086,144.424454,7.357332,0.550861,-101.327606,0.056534,0.000000
38.220001,33.700829,-101.327606,-0.002561,0.002203,0.055945,149.908768,7.636717,0.559445,-101.327606,0.057150,0.000000
38.590000,34.291039,-101.372086,-0.002522,0.002229,0.056612,152.534164,7.770461,0.566122,-101.372086,0.057766,0.000000
38.960003,35.130737,-101.372086,-0.002509,0.002258,0.057359,156.269318,7.960739,0.573586,-101.372086,0.058381,0.000000
39.330002,35.427521,-101.327606,-0.002479,0.002284,0.058009,157.589478,8.027990,0.580088,-101.327606,0.058997,0.000000
39.700001,35.969322,-101.327606,-0.002453,0.002307,0.058589,159.999542,8.150765,0.585894,-101.327606,0.059613,0.000000
40.070004,36.153648,-101.327606,-0.002436,0.002329,0.059145,160.819458,8.192533,0.591450,-101.327606,0.060237,0.000000
40.440002,37.856133,-101.372086,-0.002419,0.002363,0.060021,168.392487,8.578322,0.600209,-101.372086,0.060854,0.000000
40.810001,37.723564,-101.327606,-0.002384,0.002381,0.060480,167.802795,8.548283,0.604804,-101.327606,0.061469,0.000000
41.180000,37.942154,-101.372086,-0.002358,0.002402,0.061009,168.775131,8.597815,0.610095,-101.372086,0.062084,0.000000
41.550003,38.807175,-101.372086,-0.002337,0.002430,0.061729,172.622940,8.793832,0.617294,-101.372086,0.062701,0.000000
41.920002,38.615768,-101.416565,-0.002311,0.002447,0.062146,171.771515,8.750459,0.621457,-101.416565,0.063316,0.000000
42.290001,40.356987,-101.461052,-0.002285,0.002479,0.062978,179.516846,9.145024,0.629776,-101.461052,0.063932,0.000000
42.660004,40.483963,-101.461052,-0.002272,0.002501,0.063533,180.081665,9.173798,0.635332,-101.461052,0.064548,0.000000
43.030003,40.994484,-101.416565,-0.002251,0.002523,0.064096,182.352570,9.289483,0.640964,-101.416565,0.065163,0.000000
43.400002,41.964890,-101.461052,-0.002238,0.002551,0.064799,186.669159,9.509380,0.647989,-101.461052,0.065788,0.000000
43.770000,42.002502,-101.416565,-0.002207,0.002568,0.065215,186.836456,9.517903,0.652153,-101.416565,0.066404,0.000000
44.140003,42.731979,-101.461052,-0.002190,0.002591,0.065822,190.081345,9.683206,0.658224,-101.461052,0.067019,0.000000
44.510002,44.272110,-101.461052,-0.002173,0.002626,0.066690,196.932175,10.032203,0.666898,-101.461052,0.067635,0.000000
44.880001,44.725662,-101.416565,-0.002143,0.002648,0.067262,198.949677,10.134980,0.672621,-101.416565,0.068251,0.000000
45.250004,45.131172,-101.416565,-0.002113,0.002670,0.067809,200.753479,10.226870,0.678087,-101.416565,0.068866,0.000000
45.620003,45.494606,-101.461052,-0.002100,0.002689,0.068303,202.370117,10.309225,0.683030,-101.461052,0.069482,0.000000
45.990002,46.063965,-101.505531,-0.002061,0.002710,0.068840,204.902756,10.438243,0.688404,-101.505531,0.070098,0.000000
46.360001,47.954132,-101.505531,-0.002044,0.002746,0.069751,213.310638,10.866562,0.697511,-101.505531,0.070713,0.000000
46.730003,48.252029,-101.461052,-0.002026,0.002768,0.070306,214.635742,10.934066,0.703059,-101.461052,0.071338,0.000000
47.100002,48.766647,-101.461052,-0.002009,0.002790,0.070861,216.924881,11.050680,0.708608,-101.461052,0.071954,0.000000
47.470001,49.628685,-101.505531,-0.001988,0.002814,0.071468,220.759415,11.246020,0.714679,-101.505531,0.072569,0.000000
47.840004,50.208099,-101.505531,-0.001962,0.002835,0.072014,223.336777,11.377318,0.720144,-101.505531,0.073185,0.000000
48.210003,51.599281,-101.505531,-0.001940,0.002865,0.072769,229.525070,11.692564,0.727691,-101.505531,0.073801,0.000000
48.580002,52.171249,-101.416565,-0.001919,0.002889,0.073393,232.069305,11.822174,0.733929,-101.416565,0.074416,0.000000
48.950001,52.893280,-101.505531,-0.001897,0.002913,0.073992,235.281067,11.985788,0.739917,-101.505531,0.075033,0.000000
49.320004,53.697227,-101.550011,-0.001897,0.002939,0.074651,238.857193,12.167966,0.746510,-101.550011,0.075648,0.000000
49.690002,54.041298,-101.505531,-0.001837,0.002960,0.075179,240.387695,12.245934,0.751794,-101.505531,0.076264,0.000000
50.060001,54.557785,-101.505531,-0.001845,0.002979,0.075665,242.685150,12.362971,0.756653,-101.505531,0.076888,0.000000
50.430004,55.943382,-101.505531,-0.001824,0.003011,0.076489,248.848587,12.676951,0.764889,-101.505531,0.077504,0.000000
50.800003,56.243515,-101.505531,-0.001807,0.003031,0.076983,250.183655,12.744963,0.769832,-101.505531,0.078119,0.000000
51.170002,57.575859,-101.594490,-0.001789,0.003059,0.077695,256.110199,13.046876,0.776948,-101.594490,0.078736,0.000000
51.540001,57.416855,-101.594490,-0.001750,0.003075,0.078111,255.402924,13.010845,0.781111,-101.594490,0.079351,0.000000
51.910004,58.211502,-101.594490,-0.001725,0.003101,0.078770,258.937683,13.190915,0.787697,-101.594490,0.079967,0.000000
52.280003,60.156403,-101.505531,-0.001716,0.003132,0.079542,267.589050,13.631636,0.795418,-101.505531,0.080583,0.000000
52.650002,60.751450,-101.594490,-0.001703,0.003158,0.080209,270.235931,13.766476,0.802095,-101.594490,0.081198,0.000000
53.020004,61.632111,-101.638969,-0.001694,0.003182,0.080817,274.153320,13.966036,0.808166,-101.638969,0.081814,0.000000
53.390003,62.133324,-101.594490,-0.001656,0.003201,0.081311,276.382812,14.079613,0.813109,-101.594490,0.082438,0.000000
53.760002,62.549637,-101.594490,-0.001647,0.003222,0.081848,278.234680,14.173950,0.818484,-101.594490,0.083054,0.000000
54.130001,63.977310,-101.594490,-0.001608,0.003248,0.082508,284.585297,14.497466,0.825077,-101.594490,0.083670,0.000000
54.500004,64.972672,-101.594490,-0.001604,0.003275,0.083193,289.012878,14.723018,0.831927,-101.594490,0.084286,0.000000
54.870003,65.758743,-101.638969,-0.001595,0.003301,0.083852,292.509491,14.901145,0.838521,-101.638969,0.084901,0.000000
55.240002,65.177475,-101.683456,-0.001552,0.003302,0.083860,289.923889,14.769426,0.838604,-101.683456,0.014726,0.000000
55.610004,65.776993,-101.638969,-0.001539,0.003293,0.083652,292.590668,14.905280,0.836522,-101.638969,294.500519,0.000000
55.980003,65.541275,-101.638969,-0.001522,0.003329,0.084545,291.542145,14.851865,0.845455,-101.638969,294.500519,0.000000
56.350002,67.435532,-101.594490,-0.001513,0.003372,0.085639,299.968231,15.281110,0.856385,-101.594490,294.500519,0.000000
56.720001,65.546494,-101.594490,-0.001492,0.003220,0.081797,291.565369,14.853048,0.817969,-101.594490,294.500519,0.000000
57.090004,64.572739,-101.727936,-0.001487,0.003362,0.085405,287.233887,14.632392,0.854046,-101.727936,294.500519,0.000000
57.460003,65.226624,-101.638969,-0.001475,0.003377,0.085786,290.142517,14.780564,0.857862,-101.638969,294.500519,0.000000
57.830002,65.130188,-101.683456,-0.001462,0.003395,0.086228,289.713531,14.758712,0.862282,-101.683456,294.500519,0.000000
58.200005,65.803055,-101.638969,-0.001444,0.003403,0.086445,292.706604,14.911185,0.864447,-101.638969,294.500519,0.000000
58.570004,65.501816,-101.683456,-0.001444,0.003421,0.086905,291.366638,14.842924,0.869050,-101.683456,294.500519,0.000000
58.940002,64.737701,-101.683456,-0.001431,0.003429,0.087087,287.967682,14.669773,0.870866,-101.683456,294.500519,0.000000
59.310001,65.100388,-101.638969,-0.001418,0.003433,0.087209,289.580994,14.751959,0.872085,-101.638969,294.500519,0.000000
59.680004,67.353622,-101.638969,-0.001406,0.003421,0.086888,299.603882,15.262548,0.868876,-101.638969,294.500519,0.000000
60.050003,65.963928,-101.683456,-0.001384,0.003342,0.084893,293.422211,14.947639,0.848929,-101.683456,294.500519,0.000000
60.420002,65.167419,-101.816895,-0.001380,0.003445,0.087511,289.879150,14.767148,0.875113,-101.816895,294.500519,0.000000
60.790005,65.117523,-101.727936,-0.001384,0.003470,0.088127,289.657196,14.755842,0.881275,-101.727936,294.500519,0.000000
61.160004,64.818878,-101.772415,-0.001384,0.003474,0.088240,288.328766,14.688168,0.882403,-101.772415,294.500519,0.000000
61.530003,64.800629,-101.683456,-0.001367,0.003486,0.088535,288.247589,14.684032,0.885347,-101.683456,294.500519,0.000000
61.900002,66.604401,-101.683456,-0.001362,0.003501,0.088934,296.271179,15.092772,0.889337,-101.683456,294.500519,0.000000
62.270004,65.636978,-101.727936,-0.001350,0.003479,0.088361,291.967865,14.873551,0.883614,-101.727936,294.500519,0.000000
62.640003,64.891861,-101.772415,-0.001354,0.003480,0.088396,288.653412,14.704706,0.883962,-101.772415,294.500519,0.000000
63.010002,65.731567,-101.772415,-0.001332,0.003511,0.089168,292.388611,14.894986,0.891683,-101.772415,294.500519,0.000000
63.380005,64.987183,-101.727936,-0.001332,0.003511,0.089168,289.077423,14.726306,0.891683,-101.727936,294.500519,0.000000
63.750004,65.343918,-101.727936,-0.001319,0.003527,0.089576,290.664276,14.807143,0.895756,-101.727936,294.500519,0.000000
64.120003,65.232590,-101.727936,-0.001319,0.003533,0.089732,290.169037,14.781916,0.897315,-101.727936,294.500519,0.000000
64.490005,64.864304,-101.772415,-0.001302,0.003534,0.089758,288.530823,14.698461,0.897580,-101.772415,294.500519,0.000000
64.860001,64.941010,-101.816895,-0.001298,0.003540,0.089922,288.872040,14.715843,0.899223,-101.816895,294.500519,0.000000
65.230003,64.522842,-101.772415,-0.001298,0.003546,0.090062,287.011932,14.621084,0.900616,-101.772415,294.500519,0.000000
65.600006,66.094254,-101.772415,-0.001298,0.003520,0.089420,294.001923,14.977172,0.894197,-101.772415,294.500519,0.000000
65.970001,65.530853,-101.816895,-0.001285,0.003524,0.089498,291.495789,14.849504,0.894976,-101.816895,294.500519,0.000000
66.340004,65.040817,-101.861382,-0.001281,0.003541,0.089949,289.316010,14.738461,0.899488,-101.861382,294.500519,0.000000
66.710007,65.760605,-101.772415,-0.001272,0.003566,0.090564,292.517792,14.901566,0.905642,-101.772415,294.500519,0.000000
67.080002,65.234818,-101.816895,-0.001272,0.003566,0.090564,290.178955,14.782421,0.905642,-101.816895,294.500519,0.000000
67.450005,64.739929,-101.816895,-0.001272,0.003566,0.090564,287.977600,14.670278,0.905642,-101.816895,294.500519,0.000000
67.820000,64.280426,-101.861382,-0.001272,0.003566,0.090564,285.933624,14.566153,0.905642,-101.861382,294.500519,0.000000
68.190002,66.677017,-101.905861,-0.001255,0.003483,0.088466,296.594177,15.109228,0.884659,-101.905861,294.500519,0.000000
68.560005,66.166870,-101.861382,-0.001250,0.003483,0.088457,294.324951,14.993628,0.884568,-101.861382,294.500519,0.000000
68.930000,65.744965,-101.861382,-0.001242,0.003484,0.088501,292.448212,14.898022,0.885007,-101.861382,294.500519,0.000000
69.300003,65.292160,-101.861382,-0.001250,0.003539,0.089897,290.434021,14.795415,0.898966,-101.861382,294.500519,0.000000
69.670006,65.012146,-101.861382,-0.001250,0.003569,0.090660,289.188477,14.731963,0.906596,-101.861382,294.500519,0.000000
70.040001,65.072830,-101.905861,-0.001255,0.003593,0.091267,289.458405,14.745714,0.912667,-101.905861,294.500519,0.000000
70.410004,64.776062,-101.905861,-0.001259,0.003594,0.091276,288.138306,14.678466,0.912758,-101.905861,294.500519,0.000000
70.780006,65.615005,-101.861382,-0.001224,0.003608,0.091631,291.870117,14.868573,0.916308,-101.861382,294.500519,0.000000
71.150002,65.333496,-101.905861,-0.001233,0.003608,0.091631,290.617920,14.804782,0.916308,-101.905861,294.500519,0.000000
71.520004,65.043411,-101.905861,-0.001237,0.003608,0.091640,289.327545,14.739048,0.916399,-101.905861,294.500519,0.000000
71.890007,64.766006,-101.905861,-0.001233,0.003608,0.091648,288.093597,14.676187,0.916482,-101.905861,294.500519,0.000000
72.260002,65.763962,-101.905861,-0.001237,0.003621,0.091961,292.532715,14.902327,0.919608,-101.905861,294.500519,0.000000
72.630005,65.486908,-101.861382,-0.001224,0.003621,0.091969,291.300323,14.839546,0.919692,-101.861382,294.500519,0.000000
73.000000,65.205399,-101.905861,-0.001220,0.003621,0.091969,290.048096,14.775755,0.919692,-101.905861,294.500519,0.000000
73.370003,64.929840,-101.905861,-0.001224,0.003621,0.091969,288.822357,14.713312,0.919692,-101.905861,294.500519,0.000000
73.740005,64.674774,-101.950340,-0.001216,0.003621,0.091969,287.687775,14.655514,0.919692,-101.950340,294.500519,0.000000
74.110001,67.164825,-101.905861,-0.001212,0.003647,0.092637,298.764069,15.219767,0.926368,-101.905861,294.500519,0.000000
74.480003,66.466248,-101.861382,-0.001212,0.003567,0.090599,295.656647,15.061467,0.905990,-101.861382,294.500519,0.000000
74.850006,66.218994,-101.950340,-0.001199,0.003567,0.090607,294.556793,15.005439,0.906074,-101.950340,294.500519,0.000000
75.220001,65.899506,-101.950340,-0.001190,0.003567,0.090607,293.135651,14.933042,0.906074,-101.950340,294.500519,0.000000
75.590004,65.660065,-101.950340,-0.001194,0.003568,0.090625,292.070557,14.878783,0.906248,-101.950340,294.500519,0.000000
75.960007,65.438507,-101.905861,-0.001199,0.003602,0.091484,291.085022,14.828578,0.914839,-101.905861,294.500519,0.000000
76.330002,65.286957,-101.950340,-0.001186,0.003617,0.091874,290.410889,14.794236,0.918738,-101.950340,294.500519,0.000000
76.700005,65.119751,-101.861382,-0.001177,0.003632,0.092255,289.667114,14.756347,0.922553,-101.861382,294.500519,0.000000
77.070007,65.183426,-101.994820,-0.001203,0.003643,0.092524,289.950348,14.770775,0.925240,-101.994820,294.500519,0.000000
77.440002,65.032990,-102.039299,-0.001194,0.003646,0.092619,289.281189,14.736687,0.926194,-102.039299,294.500519,0.000000
77.810005,65.259766,-102.039299,-0.001186,0.003649,0.092689,290.289948,14.788074,0.926890,-102.039299,294.500519,0.000000
78.180000,65.349503,-101.950340,-0.001190,0.003654,0.092819,290.689117,14.808409,0.928192,-101.950340,294.500519,0.000000
78.550003,65.301468,-101.994820,-0.001186,0.003654,0.092819,290.475433,14.797524,0.928192,-101.994820,294.500519,0.000000
78.920006,65.145081,-101.994820,-0.001190,0.003654,0.092819,289.779785,14.762086,0.928192,-101.994820,294.500519,0.000000
79.290001,65.098160,-102.083786,-0.001190,0.003657,0.092880,289.571075,14.751454,0.928798,-102.083786,294.500519,0.000000
79.660004,65.290680,-102.039299,-0.001194,0.003661,0.092993,290.427460,14.795079,0.929926,-102.039299,294.500519,0.000000
80.030006,65.224014,-101.994820,-0.001173,0.003661,0.092993,290.130920,14.779973,0.929926,-101.994820,294.500519,0.000000
80.400002,65.124969,-102.039299,-0.001177,0.003662,0.093027,289.690338,14.757528,0.930274,-102.039299,294.500519,0.000000
80.770004,65.116409,-102.039299,-0.001177,0.003665,0.093088,289.652252,14.755589,0.930880,-102.039299,294.500519,0.000000
81.140007,65.040817,-102.083786,-0.001177,0.003666,0.093105,289.316010,14.738461,0.931054,-102.083786,294.500519,0.000000
81.510002,64.974152,-102.039299,-0.001164,0.003666,0.093105,289.019470,14.723353,0.931054,-102.039299,294.500519,0.000000
81.880005,65.301102,-101.994820,-0.001173,0.003671,0.093244,290.473816,14.797441,0.932439,-101.994820,294.500519,0.000000
82.250008,65.204651,-102.083786,-0.001181,0.003671,0.093244,290.044769,14.775585,0.932439,-102.083786,294.500519,0.000000
82.620003,65.089966,-102.128265,-0.001186,0.003671,0.093253,289.534637,14.749597,0.932530,-102.128265,294.500519,0.000000
82.990005,64.957397,-102.083786,-0.001177,0.003671,0.093253,288.944946,14.719557,0.932530,-102.083786,294.500519,0.000000
83.360001,65.508514,-102.083786,-0.001155,0.003679,0.093452,291.396423,14.844441,0.934521,-102.083786,294.500519,0.000000
83.730003,65.415421,-102.083786,-0.001173,0.003679,0.093452,290.982330,14.823346,0.934521,-102.083786,294.500519,0.000000
84.100006,65.316360,-102.083786,-0.001151,0.003679,0.093452,290.541687,14.800900,0.934521,-102.083786,294.500519,0.000000
84.470001,65.189392,-102.039299,-0.001160,0.003679,0.093452,289.976898,14.772127,0.934521,-102.039299,294.500519,0.000000
84.840004,65.110077,-102.128265,-0.001147,0.003680,0.093478,289.624084,14.754154,0.934778,-102.128265,294.500519,0.000000
85.210007,65.158859,-102.083786,-0.001155,0.003689,0.093695,289.841095,14.765209,0.936951,-102.083786,294.500519,0.000000
85.580002,65.622452,-102.128265,-0.001160,0.003688,0.093678,291.903259,14.870260,0.936777,-102.128265,294.500519,0.000000
85.950005,65.561386,-102.128265,-0.001168,0.003688,0.093678,291.631622,14.856422,0.936777,-102.128265,294.500519,0.000000
86.320007,65.456757,-102.172745,-0.001164,0.003688,0.093678,291.166199,14.832713,0.936777,-102.172745,294.500519,0.000000
86.690002,65.304825,-102.217224,-0.001155,0.003688,0.093678,290.490356,14.798285,0.936777,-102.217224,294.500519,0.000000
87.060005,65.230728,-102.128265,-0.001164,0.003688,0.093678,290.160767,14.781495,0.936777,-102.128265,294.500519,0.000000
87.430008,65.070602,-102.083786,-0.001164,0.003688,0.093678,289.448486,14.745210,0.936777,-102.083786,294.500519,0.000000
87.800003,64.967453,-102.172745,-0.001155,0.003688,0.093678,288.989655,14.721835,0.936777,-102.172745,294.500519,0.000000
88.170006,65.647400,-102.217224,-0.001147,0.003697,0.093912,292.014221,14.875913,0.939116,-102.217224,294.500519,0.000000
88.540001,65.613525,-102.128265,-0.001147,0.003697,0.093912,291.863525,14.868237,0.939116,-102.128265,294.500519,0.000000
88.910004,65.545746,-102.172745,-0.001151,0.003697,0.093912,291.562042,14.852879,0.939116,-102.172745,294.500519,0.000000
89.280006,65.457870,-102.128265,-0.001151,0.003697,0.093912,291.171143,14.832966,0.939116,-102.128265,294.500519,0.000000
89.650002,65.336105,-102.172745,-0.001155,0.003697,0.093912,290.629517,14.805373,0.939116,-102.172745,294.500519,0.000000
90.020004,65.263123,-102.261703,-0.001151,0.003698,0.093921,290.304871,14.788835,0.939207,-102.261703,294.500519,0.000000
90.390007,65.170776,-102.172745,-0.001155,0.003698,0.093929,289.894104,14.767909,0.939290,-102.172745,294.500519,0.000000
90.760002,65.076935,-102.172745,-0.001134,0.003698,0.093929,289.476654,14.746644,0.939290,-102.172745,294.500519,0.000000
91.130005,65.223648,-102.128265,-0.001147,0.003702,0.094042,290.129272,14.779890,0.940418,-102.128265,294.500519,0.000000
91.500008,65.236679,-102.261703,-0.001151,0.003702,0.094042,290.187256,14.782843,0.940418,-102.261703,294.500519,0.000000
91.870003,65.172256,-102.217224,-0.001130,0.003702,0.094042,289.900665,14.768245,0.940418,-102.217224,294.500519,0.000000
92.240005,65.193481,-102.172745,-0.001130,0.003703,0.094068,289.995087,14.773054,0.940683,-102.172745,294.500519,0.000000
92.610001,65.189392,-102.217224,-0.001130,0.003704,0.094094,289.976898,14.772127,0.940940,-102.217224,294.500519,0.000000
92.980003,65.107468,-102.261703,-0.001134,0.003704,0.094094,289.612488,14.753563,0.940940,-102.261703,294.500519,0.000000
93.350006,65.137634,-102.261703,-0.001147,0.003707,0.094146,289.746674,14.760399,0.941462,-102.261703,294.500519,0.000000
93.720001,65.082520,-102.306190,-0.001138,0.003707,0.094146,289.501495,14.747910,0.941462,-102.306190,294.500519,0.000000
94.090004,65.017349,-102.261703,-0.001143,0.003707,0.094146,289.211609,14.733142,0.941462,-102.261703,294.500519,0.000000
94.460007,65.047134,-102.217224,-0.001130,0.003708,0.094189,289.344116,14.739891,0.941894,-102.217224,294.500519,0.000000
94.830002,64.995010,-102.306190,-0.001138,0.003708,0.094189,289.112244,14.728080,0.941894,-102.306190,294.500519,0.000000
95.200005,64.991653,-102.261703,-0.001134,0.003709,0.094207,289.097321,14.727320,0.942068,-102.261703,294.500519,0.000000
95.570007,64.940277,-102.306190,-0.001125,0.003709,0.094207,288.868774,14.715677,0.942068,-102.306190,294.500519,0.000000
95.940002,65.313385,-102.261703,-0.001130,0.003715,0.094372,290.528442,14.800224,0.943718,-102.261703,294.500519,0.000000
96.310005,65.286957,-102.306190,-0.001130,0.003714,0.094337,290.410889,14.794236,0.943370,-102.306190,294.500519,0.000000
96.680008,65.222900,-102.306190,-0.001130,0.003714,0.094337,290.125946,14.779721,0.943370,-102.306190,294.500519,0.000000
97.050003,65.149551,-102.306190,-0.001130,0.003714,0.094337,289.799683,14.763099,0.943370,-102.306190,294.500519,0.000000
97.420006,65.084000,-102.306190,-0.001121,0.003714,0.094337,289.508087,14.748245,0.943370,-102.306190,294.500519,0.000000
97.790001,64.996506,-102.306190,-0.001112,0.003714,0.094337,289.118896,14.728418,0.943370,-102.306190,294.500519,0.000000
98.160004,64.962616,-102.306190,-0.001112,0.003714,0.094337,288.968140,14.720739,0.943370,-102.306190,294.500519,0.000000
98.530006,64.850906,-102.306190,-0.001125,0.003714,0.094337,288.471252,14.695426,0.943370,-102.306190,294.500519,0.000000
98.900002,64.786484,-102.350670,-0.001121,0.003714,0.094337,288.184662,14.680827,0.943370,-102.350670,294.500519,0.000000
99.270004,64.735458,-102.306190,-0.001130,0.003714,0.094337,287.957703,14.669265,0.943370,-102.306190,294.500519,0.000000
99.640007,64.656525,-102.350670,-0.001125,0.003714,0.094337,287.606598,14.651378,0.943370,-102.350670,294.500519,0.000000
100.010002,66.151978,-102.350670,-0.001112,0.003731,0.094779,294.258698,14.990252,0.947791,-102.350670,294.500519,0.000000
100.380005,66.033188,-102.350670,-0.001121,0.003721,0.094510,293.730286,14.963334,0.945103,-102.350670,294.500519,0.000000
100.750008,65.916626,-102.395149,-0.001117,0.003721,0.094501,293.211792,14.936921,0.945013,-102.395149,294.500519,0.000000
101.120003,65.820557,-102.350670,-0.001112,0.003721,0.094501,292.784454,14.915152,0.945013,-102.350670,294.500519,0.000000
101.490005,65.766190,-102.350670,-0.001108,0.003721,0.094501,292.542633,14.902831,0.945013,-102.350670,294.500519,0.000000
101.860008,65.704010,-102.395149,-0.001117,0.003721,0.094501,292.266022,14.888741,0.945013,-102.395149,294.500519,0.000000
102.230003,65.610168,-102.395149,-0.001112,0.003721,0.094501,291.848602,14.867476,0.945013,-102.395149,294.500519,0.000000
102.600006,65.528992,-102.350670,-0.001121,0.003721,0.094501,291.487518,14.849082,0.945013,-102.350670,294.500519,0.000000
102.970001,65.456375,-102.439629,-0.001121,0.003721,0.094501,291.164490,14.832626,0.945013,-102.439629,294.500519,0.000000
103.340004,65.390472,-102.395149,-0.001117,0.003721,0.094510,290.871338,14.817693,0.945103,-102.395149,294.500519,0.000000
103.710007,65.308182,-102.350670,-0.001125,0.003721,0.094510,290.505310,14.799046,0.945103,-102.350670,294.500519,0.000000
104.080002,65.259018,-102.350670,-0.001108,0.003721,0.094510,290.286621,14.787905,0.945103,-102.350670,294.500519,0.000000
104.450005,65.171890,-102.484108,-0.001112,0.003721,0.094510,289.899048,14.768161,0.945103,-102.484108,294.500519,0.000000
104.820007,65.086609,-102.439629,-0.001099,0.003721,0.094510,289.519684,14.748837,0.945103,-102.439629,294.500519,0.000000
105.190002,65.040436,-102.395149,-0.001104,0.003721,0.094510,289.314301,14.738373,0.945103,-102.395149,294.500519,0.000000
105.560005,64.998734,-102.395149,-0.001112,0.003721,0.094510,289.128815,14.728924,0.945103,-102.395149,294.500519,0.000000
105.930008,64.914948,-102.439629,-0.001112,0.003721,0.094510,288.756104,14.709937,0.945103,-102.439629,294.500519,0.000000
106.300003,64.847916,-102.484108,-0.001104,0.003721,0.094510,288.457947,14.694748,0.945103,-102.484108,294.500519,0.000000
106.670006,64.788345,-102.439629,-0.001099,0.003721,0.094510,288.192963,14.681249,0.945103,-102.439629,294.500519,0.000000
107.040009,64.710510,-102.350670,-0.001104,0.003721,0.094510,287.846741,14.663610,0.945103,-102.350670,294.500519,0.000000
107.410004,64.663971,-102.484108,-0.001117,0.003721,0.094510,287.639709,14.653065,0.945103,-102.484108,294.500519,0.000000
107.780006,66.273361,-102.484108,-0.001104,0.003738,0.094944,294.798645,15.017758,0.949441,-102.484108,294.500519,0.000000
108.150002,66.187714,-102.528595,-0.001095,0.003738,0.094944,294.417664,14.998350,0.949441,-102.528595,294.500519,0.000000
108.520004,66.137070,-102.528595,-0.001082,0.003738,0.094935,294.192383,14.986874,0.949350,-102.528595,294.500519,0.000000
108.890007,66.046585,-102.439629,-0.001091,0.003738,0.094935,293.789886,14.966371,0.949350,-102.439629,294.500519,0.000000
109.260002,65.982162,-102.528595,-0.001099,0.003738,0.094935,293.503326,14.951772,0.949350,-102.528595,294.500519,0.000000
109.630005,65.867844,-102.528595,-0.001095,0.003738,0.094935,292.994812,14.925867,0.949350,-102.528595,294.500519,0.000000
110.000008,65.851471,-102.528595,-0.001091,0.003738,0.094944,292.921967,14.922156,0.949441,-102.528595,294.500519,0.000000
110.370003,65.788162,-102.528595,-0.001095,0.003738,0.094944,292.640350,14.907811,0.949441,-102.528595,294.500519,0.000000
110.740005,65.745346,-102.528595,-0.001095,0.003738,0.094944,292.449890,14.898108,0.949441,-102.528595,294.500519,0.000000
111.110008,65.665283,-102.528595,-0.001108,0.003738,0.094944,292.093781,14.879966,0.949441,-102.528595,294.500519,0.000000
111.480003,65.607193,-102.573074,-0.001108,0.003738,0.094944,291.835358,14.866803,0.949441,-102.573074,294.500519,0.000000
111.850006,65.565109,-102.617554,-0.001095,0.003738,0.094944,291.648163,14.857265,0.949441,-102.617554,294.500519,0.000000
112.220009,65.523773,-102.528595,-0.001082,0.003738,0.094944,291.464294,14.847898,0.949441,-102.528595,294.500519,0.000000
112.590004,65.436264,-102.528595,-0.001095,0.003738,0.094944,291.075043,14.828069,0.949441,-102.528595,294.500519,0.000000
112.960007,65.386002,-102.573074,-0.001108,0.003738,0.094952,290.851471,14.816680,0.949524,-102.573074,294.500519,0.000000
113.330002,65.339081,-102.617554,-0.001091,0.003738,0.094952,290.642761,14.806047,0.949524,-102.617554,294.500519,0.000000
113.700005,65.292542,-102.617554,-0.001095,0.003738,0.094952,290.435730,14.795502,0.949524,-102.617554,294.500519,0.000000
114.070007,65.254181,-102.528595,-0.001104,0.003739,0.094962,290.265106,14.786808,0.949615,-102.528595,294.500519,0.000000
114.440002,65.383392,-102.617554,-0.001091,0.003744,0.095108,290.839844,14.816088,0.951084,-102.617554,294.500519,0.000000
114.810005,65.396057,-102.528595,-0.001104,0.003744,0.095108,290.896179,14.818958,0.951084,-102.528595,294.500519,0.000000
115.180008,65.351746,-102.573074,-0.001095,0.003744,0.095108,290.699097,14.808917,0.951084,-102.573074,294.500519,0.000000
115.550003,65.334610,-102.662033,-0.001095,0.003745,0.095117,290.622864,14.805035,0.951174,-102.662033,1681.641113,0.000000
115.920006,65.305573,-102.573074,-0.001087,0.003740,0.094996,290.493683,14.798454,0.949956,-102.573074,0.094805,0.000000
116.290009,65.240768,-102.662033,-0.001099,0.003722,0.094536,290.205444,14.783769,0.945361,-102.662033,0.094189,0.000000
116.660004,65.094055,-102.617554,-0.001099,0.003708,0.094189,289.552826,14.750524,0.941894,-102.617554,0.093574,0.000000
117.030006,64.961868,-102.617554,-0.001095,0.003681,0.093504,288.964813,14.720570,0.935043,-102.617554,0.092958,0.000000
117.400009,64.924637,-102.662033,-0.001091,0.003660,0.092958,288.799194,14.712132,0.929578,-102.662033,0.092342,0.000000
117.770004,64.887390,-102.662033,-0.001074,0.003634,0.092298,288.633514,14.703692,0.922984,-102.662033,0.091726,0.000000
118.140007,64.809570,-102.662033,-0.001091,0.003605,0.091579,288.287354,14.686059,0.915793,-102.662033,0.091102,0.000000
118.510002,64.747375,-102.662033,-0.001091,0.003589,0.091171,288.010712,14.671965,0.911713,-102.662033,0.090486,0.000000
118.880005,64.662476,-102.662033,-0.001082,0.003567,0.090599,287.633057,14.652726,0.905990,-102.662033,0.089871,0.000000
119.250008,64.620407,-102.662033,-0.001074,0.003540,0.089905,287.445923,14.643193,0.899049,-102.662033,0.089255,0.000000
119.620003,64.387665,-102.662033,-0.001082,0.003519,0.089377,286.410645,14.590453,0.893765,-102.662033,0.088639,0.000000
119.990005,63.436630,-102.662033,-0.001069,0.003488,0.088604,282.180237,14.374947,0.886044,-102.662033,0.088023,0.000000
120.360008,62.372391,-102.662033,-0.001082,0.003462,0.087937,277.446259,14.133785,0.879367,-102.662033,0.087408,0.000000
120.730003,61.454865,-102.706512,-0.001069,0.003446,0.087529,273.364899,13.925872,0.875287,-102.706512,0.086792,0.000000
121.100006,60.233482,-102.750999,-0.001065,0.003426,0.087026,267.931915,13.649102,0.870261,-102.750999,0.086176,0.000000
121.470009,58.687393,-102.706512,-0.001069,0.003403,0.086436,261.054565,13.298753,0.864364,-102.706512,0.085551,0.000000
121.840004,57.342384,-102.662033,-0.001069,0.003386,0.085994,255.071671,12.993970,0.859943,-102.662033,0.084936,0.000000
122.210007,55.322632,-102.706512,-0.001074,0.003362,0.085387,246.087357,12.536287,0.853872,-102.706512,0.084321,0.000000
122.580009,53.912460,-102.750999,-0.001074,0.003345,0.084971,239.814606,12.216738,0.849709,-102.750999,0.083704,0.000000
122.950005,51.176643,-102.750999,-0.001061,0.003314,0.084173,227.645081,11.596793,0.841730,-102.750999,0.083089,0.000000
123.320007,47.917267,-102.706512,-0.001069,0.003286,0.083461,213.146652,10.858208,0.834615,-102.706512,0.082473,0.000000
123.690002,45.412689,-102.706512,-0.001069,0.003262,0.082854,202.005737,10.290663,0.828544,-102.706512,0.081857,0.000000
124.060005,42.941620,-102.750999,-0.001087,0.003237,0.082231,191.013870,9.730710,0.822306,-102.750999,0.081242,0.000000
124.430008,39.642776,-102.795479,-0.001087,0.003207,0.081459,176.339874,8.983182,0.814585,-102.795479,0.080626,0.000000
124.800003,37.117714,-102.839958,-0.001074,0.003186,0.080912,165.107834,8.410994,0.809120,-102.839958,0.080001,0.000000
125.170006,34.965034,-102.750999,-0.001087,0.003166,0.080409,155.532242,7.923190,0.804093,-102.750999,0.079386,0.000000
125.540009,32.748672,-102.795479,-0.001091,0.003141,0.079776,145.673370,7.420955,0.797757,-102.795479,0.078770,0.000000
125.910004,30.183022,-102.795479,-0.001078,0.003120,0.079247,134.260788,6.839571,0.792474,-102.795479,0.078154,0.000000
126.280006,27.136642,-102.795479,-0.001104,0.003093,0.078553,120.709816,6.149251,0.785532,-102.795479,0.077539,0.000000
126.650009,24.426895,-102.750999,-0.001104,0.003068,0.077929,108.656258,5.535214,0.779287,-102.750999,0.076923,0.000000
127.020004,21.731659,-102.750999,-0.001095,0.003041,0.077244,96.667244,4.924465,0.772436,-102.750999,0.076307,0.000000
127.390007,18.683044,-102.750999,-0.001112,0.003014,0.076550,83.106331,4.233638,0.765503,-102.750999,0.075691,0.000000
127.760010,17.021896,-102.795479,-0.001108,0.002999,0.076177,75.717178,3.857217,0.761771,-102.795479,0.075076,0.000000
128.130005,14.290169,-102.839958,-0.001117,0.002973,0.075518,63.565845,3.238199,0.755177,-102.839958,0.074451,0.000000
128.500000,11.053505,-102.839958,-0.001112,0.002943,0.074764,49.168446,2.504760,0.747638,-102.839958,0.073836,0.000000
128.870010,8.834915,-102.839958,-0.001121,0.002922,0.074226,39.299664,2.002020,0.742256,-102.839958,0.073220,0.000000
129.240005,6.359749,-102.839958,-0.001138,0.002900,0.073653,28.289576,1.441140,0.736533,-102.839958,0.072604,0.000000
129.610001,4.074127,-102.839958,-0.001147,0.002876,0.073055,18.122623,0.923210,0.730553,-102.839958,0.071989,0.000000
129.980011,1.590034,-102.839958,-0.001138,0.002851,0.072404,7.072827,0.360307,0.724043,-102.839958,0.071373,0.000000
130.350006,-0.910072,-102.839958,-0.001130,0.002825,0.071763,-4.048204,-0.206225,0.717631,-102.839958,0.070757,0.000000
130.720001,-3.425453,-102.795479,-0.001155,0.002796,0.071026,-15.237177,-0.776219,0.710258,-102.795479,0.070141,0.000000
131.090012,-0.263634,-102.839958,-0.001199,0.002777,0.070532,-1.172701,-0.059740,0.705315,-102.839958,0.069525,0.000000
131.460007,0.024582,-102.928925,-0.001216,0.002758,0.070063,0.109346,0.005570,0.700629,-102.928925,0.068901,0.000000
131.830002,0.002983,-102.928925,-0.001224,0.002734,0.069456,0.013269,0.000676,0.694559,-102.928925,0.068286,0.000000
132.200012,0.039474,-102.884438,-0.001250,0.002708,0.068788,0.175591,0.008945,0.687882,-102.884438,0.067669,0.000000
132.570007,0.038727,-102.884438,-0.001285,0.002679,0.068043,0.172265,0.008776,0.680426,-102.884438,0.067054,0.000000
132.940002,0.043198,-102.884438,-0.001298,0.002666,0.067704,0.192153,0.009789,0.677042,-102.884438,0.066438,0.000000
133.310013,-0.007072,-102.839958,-0.001319,0.002633,0.066872,-0.031460,-0.001603,0.668715,-102.839958,0.065822,0.000000
133.680008,-0.038727,-102.884438,-0.001341,0.002607,0.066230,-0.172265,-0.008776,0.662296,-102.884438,0.065207,0.000000
134.050003,-0.004097,-102.973404,-0.001358,0.002585,0.065657,-0.018224,-0.000928,0.656573,-102.973404,0.064591,0.000000
134.420013,0.026817,-102.928925,-0.001380,0.002567,0.065207,0.119289,0.006077,0.652069,-102.928925,0.063975,0.000000
134.790009,0.010803,-102.928925,-0.001414,0.002537,0.064435,0.048055,0.002448,0.644348,-102.928925,0.063351,0.000000
135.160004,0.017876,-102.973404,-0.001423,0.002516,0.063915,0.079515,0.004051,0.639148,-102.973404,0.062735,0.000000
135.530014,-0.033882,-102.973404,-0.001462,0.002489,0.063212,-0.150715,-0.007678,0.632123,-102.973404,0.062119,0.000000
135.900009,-0.046547,-102.928925,-0.001492,0.002462,0.062536,-0.207051,-0.010548,0.625355,-102.928925,0.061504,0.000000
136.270004,-0.008560,-102.928925,-0.001518,0.002435,0.061850,-0.038078,-0.001940,0.618505,-102.928925,0.060888,0.000000
136.639999,-0.029045,-102.928925,-0.001526,0.002411,0.061243,-0.129199,-0.006582,0.612434,-102.928925,0.060272,0.000000
137.010010,-0.030907,-102.973404,-0.001556,0.002389,0.060671,-0.137480,-0.007004,0.606711,-102.973404,0.059657,0.000000
137.380005,-0.025688,-102.928925,-0.001578,0.002374,0.060307,-0.114267,-0.005821,0.603070,-102.928925,0.059041,0.000000
137.750000,-0.030533,-102.973404,-0.001625,0.002339,0.059405,-0.135817,-0.006919,0.594047,-102.973404,0.058416,0.000000
138.120010,-0.035370,-102.928925,-0.001643,0.002323,0.059006,-0.157333,-0.008015,0.590058,-102.928925,0.057801,0.000000
138.490005,-0.050636,-102.973404,-0.001660,0.002296,0.058312,-0.225241,-0.011474,0.583124,-102.973404,0.057184,0.000000
138.860001,-0.061066,-103.017883,-0.001712,0.002268,0.057618,-0.271634,-0.013838,0.576182,-103.017883,0.056569,0.000000
139.230011,-0.027550,-103.017883,-0.001716,0.002247,0.057072,-0.122547,-0.006243,0.570724,-103.017883,0.055954,0.000000
139.600006,-0.001862,-102.973404,-0.001746,0.002216,0.056275,-0.008281,-0.000422,0.562746,-102.973404,0.055337,0.000000
139.970001,-0.004463,-103.017883,-0.001768,0.002192,0.055684,-0.019853,-0.001011,0.556841,-103.017883,0.054722,0.000000
140.340012,-0.026810,-102.973404,-0.001802,0.002175,0.055242,-0.119255,-0.006075,0.552421,-102.973404,0.054106,0.000000
140.710007,-0.022339,-102.973404,-0.001824,0.002147,0.054540,-0.099368,-0.005062,0.545396,-102.973404,0.053490,0.000000
141.080002,-0.025322,-103.106842,-0.001845,0.002127,0.054020,-0.112638,-0.005738,0.540195,-103.106842,0.052866,0.000000
141.450012,-0.070747,-103.017883,-0.001867,0.002096,0.053239,-0.314700,-0.016032,0.532391,-103.017883,0.052250,0.000000
141.820007,-0.065536,-102.973404,-0.001897,0.002070,0.052589,-0.291521,-0.014851,0.525888,-102.973404,0.051634,0.000000
142.190002,-0.058830,-103.062363,-0.001914,0.002048,0.052025,-0.261690,-0.013331,0.520249,-103.062363,0.051019,0.000000
142.560013,-0.060692,-103.062363,-0.001936,0.002028,0.051513,-0.269971,-0.013753,0.515132,-103.062363,0.050403,0.000000
142.930008,-0.065536,-103.106842,-0.001970,0.002001,0.050819,-0.291521,-0.014851,0.508190,-103.106842,0.049787,0.000000
143.300003,-0.056229,-103.106842,-0.001992,0.001978,0.050229,-0.250117,-0.012742,0.502293,-103.106842,0.049172,0.000000
143.670013,-0.086761,-103.062363,-0.002013,0.001952,0.049588,-0.385934,-0.019660,0.495882,-103.062363,0.048556,0.000000
144.040009,-0.064415,-103.062363,-0.002044,0.001927,0.048946,-0.286532,-0.014597,0.489463,-103.062363,0.047940,0.000000
144.410004,-0.061440,-103.062363,-0.002082,0.001895,0.048139,-0.273297,-0.013922,0.481393,-103.062363,0.047316,0.000000
144.780014,-0.049522,-103.151329,-0.002108,0.001886,0.047914,-0.220287,-0.011222,0.479145,-103.151329,0.046700,0.000000
145.150009,-0.071121,-103.106842,-0.002121,0.001854,0.047099,-0.316363,-0.016116,0.470992,-103.106842,0.046084,0.000000
145.520004,-0.065536,-103.106842,-0.002151,0.001829,0.046457,-0.291521,-0.014851,0.464573,-103.106842,0.045469,0.000000
145.889999,-0.053246,-103.062363,-0.002190,0.001801,0.045737,-0.236848,-0.012066,0.457374,-103.062363,0.044853,0.000000
146.260010,-0.059952,-103.106842,-0.002229,0.001779,0.045183,-0.266679,-0.013585,0.451826,-103.106842,0.044237,0.000000
146.630005,-0.041702,-103.106842,-0.002238,0.001755,0.044575,-0.185501,-0.009450,0.445755,-103.106842,0.043622,0.000000
147.000000,-0.071861,-103.106842,-0.002251,0.001733,0.044012,-0.319655,-0.016284,0.440115,-103.106842,0.043005,0.000000
147.370010,-0.045052,-103.106842,-0.002276,0.001703,0.043257,-0.200399,-0.010209,0.432568,-103.106842,0.042390,0.000000
147.740005,-0.035370,-103.195808,-0.002311,0.001677,0.042607,-0.157333,-0.008015,0.426066,-103.195808,0.041766,0.000000
148.110001,-0.060692,-103.106842,-0.002345,0.001660,0.042173,-0.269971,-0.013753,0.421728,-103.106842,0.041150,0.000000
148.480011,-0.050270,-103.195808,-0.002358,0.001634,0.041497,-0.223612,-0.011391,0.414968,-103.195808,0.040534,0.000000
148.850006,-0.051010,-103.195808,-0.002393,0.001611,0.040907,-0.226904,-0.011559,0.409071,-103.195808,0.039919,0.000000
149.220001,-0.050270,-103.106842,-0.002402,0.001589,0.040352,-0.223612,-0.011391,0.403523,-103.106842,0.039302,0.000000
149.590012,-0.046547,-103.151329,-0.002449,0.001557,0.039545,-0.207051,-0.010548,0.395453,-103.151329,0.038687,0.000000
149.960007,-0.059578,-103.195808,-0.002462,0.001533,0.038938,-0.265016,-0.013501,0.389382,-103.195808,0.038072,0.000000
150.330002,-0.055855,-103.240288,-0.002496,0.001512,0.038401,-0.248455,-0.012657,0.384008,-103.240288,0.037455,0.000000
150.700012,-0.042816,-103.240288,-0.002518,0.001484,0.037681,-0.190456,-0.009702,0.376809,-103.240288,0.036840,0.000000
151.070007,-0.063301,-103.195808,-0.002527,0.001466,0.037239,-0.281577,-0.014344,0.372388,-103.195808,0.036215,0.000000
151.440002,-0.045799,-103.195808,-0.002561,0.001443,0.036640,-0.203725,-0.010378,0.366401,-103.195808,0.035599,0.000000
151.810013,-0.035744,-103.240288,-0.002591,0.001414,0.035920,-0.158996,-0.008100,0.359202,-103.240288,0.034984,0.000000
152.180008,-0.059204,-103.284767,-0.002604,0.001391,0.035330,-0.263353,-0.013416,0.353305,-103.284767,0.034368,0.000000
152.550003,-0.058830,-103.240288,-0.002639,0.001368,0.034741,-0.261690,-0.013331,0.347408,-103.240288,0.033752,0.000000
152.900009,-0.013031,-103.240288,-0.002643,0.001365,0.034672,-0.057965,-0.002953,0.346719,-103.240288,0.034542,0.000000