File: Data/compression 22/AutoNoHeating-17-22-reverse-1-4_09172024_164831.csv
Time (sec),S:Load (lbs),S:HL1 (DIM),S:LVDT (in),S:Position (in),Ch:Position (mm),Ch:Load (N),Ch:Stress (MPa),Ch:Strain (mm/mm),Ch:HL1 (DIM),Set Point (),Cycles ()
0.110000,-0.018616,-59.782398,-0.005441,-0.005493,-0.139528,-0.082807,-0.004218,-1.395280,-59.782398,-0.139311,0.000000
0.540000,-0.030907,-59.782398,-0.005437,-0.005381,-0.136675,-0.137480,-0.007004,-1.366748,-59.782398,-0.135877,0.000000
0.970000,-0.020111,-59.737919,-0.005256,-0.005121,-0.130075,-0.089459,-0.004557,-1.300752,-59.737919,-0.128714,0.000000
1.400000,-0.056229,-59.782398,-0.004975,-0.004834,-0.122773,-0.250117,-0.012742,-1.227731,-59.782398,-0.121550,0.000000
1.830000,-0.062561,-59.782398,-0.004691,-0.004555,-0.115688,-0.278285,-0.014177,-1.156879,-59.782398,-0.114387,0.000000
2.260000,0.152672,-59.871361,-0.004613,-0.000000,-0.000009,0.679118,0.034596,-0.000087,-59.871361,0.000121,0.000000
2.690000,0.149323,-59.737919,-0.004605,-0.000000,-0.000009,0.664220,0.033837,-0.000087,-59.737919,0.000486,0.000000
3.120000,0.132935,-59.915840,-0.004600,0.000002,0.000061,0.591322,0.030123,0.000607,-59.915840,0.001205,0.000000
3.550000,0.283005,-59.871361,-0.004579,0.000042,0.001075,1.258868,0.064130,0.010754,-59.871361,0.001925,0.000000
3.980000,0.418915,-59.915840,-0.004566,0.000064,0.001630,1.863426,0.094927,0.016304,-59.915840,0.002636,0.000000
4.410000,0.566002,-59.871361,-0.004553,0.000076,0.001943,2.517702,0.128258,0.019426,-59.871361,0.003356,0.000000
4.840000,1.006149,-59.915840,-0.004514,0.000116,0.002957,4.475575,0.227997,0.029572,-59.915840,0.004076,0.000000
5.270000,1.318199,-59.915840,-0.004488,0.000147,0.003729,5.863643,0.298708,0.037291,-59.915840,0.004787,0.000000
5.700000,1.815315,-60.049282,-0.004462,0.000177,0.004484,8.074925,0.411356,0.044836,-60.049282,0.005507,0.000000
6.130000,2.430473,-59.960323,-0.004428,0.000208,0.005290,10.811285,0.550753,0.052901,-59.960323,0.006227,0.000000
6.560000,2.930199,-59.960323,-0.004428,0.000235,0.005967,13.034175,0.663992,0.059665,-59.960323,0.006938,0.000000
6.990000,3.248207,-59.915840,-0.004389,0.000253,0.006426,14.448747,0.736054,0.064261,-59.915840,0.007658,0.000000
7.420001,3.985504,-59.960323,-0.004359,0.000290,0.007354,17.728409,0.903128,0.073541,-59.960323,0.008369,0.000000
7.850000,4.555603,-60.004803,-0.004329,0.000316,0.008031,20.264334,1.032314,0.080305,-60.004803,0.009089,0.000000
8.280001,5.035217,-60.004803,-0.004329,0.000338,0.008577,22.397764,1.140996,0.085769,-60.004803,0.009808,0.000000
8.710000,5.801933,-60.004803,-0.004281,0.000371,0.009435,25.808289,1.314737,0.094354,-60.004803,0.010519,0.000000
9.140000,6.279320,-59.960323,-0.004264,0.000392,0.009956,27.931808,1.422914,0.099558,-59.960323,0.011239,0.000000
9.570001,7.038956,-60.049282,-0.004238,0.000429,0.010892,31.310839,1.595050,0.108924,-60.049282,0.011959,0.000000
10.000000,7.695076,-60.049282,-0.004212,0.000457,0.011612,34.229408,1.743729,0.116122,-60.049282,0.012670,0.000000
10.430000,8.298317,-60.049282,-0.004191,0.000486,0.012332,36.912758,1.880425,0.123319,-60.049282,0.013390,0.000000
10.860001,8.951836,-60.093765,-0.004156,0.000515,0.013069,39.819752,2.028515,0.130691,-60.093765,0.014110,0.000000
11.290001,9.310799,-60.049282,-0.004130,0.000538,0.013676,41.416500,2.109857,0.136762,-60.049282,0.014821,0.000000
11.720000,9.718918,-60.182728,-0.004109,0.000564,0.014327,43.231907,2.202338,0.143266,-60.182728,0.015541,0.000000
12.150001,10.547447,-60.138245,-0.004092,0.000599,0.015211,46.917389,2.390086,0.152111,-60.138245,0.016260,0.000000
12.580001,10.903809,-60.093765,-0.004057,0.000623,0.015827,48.502563,2.470838,0.158269,-60.093765,0.016972,0.000000
13.010000,11.472420,-60.138245,-0.004027,0.000652,0.016573,51.031872,2.599687,0.165727,-60.138245,0.017691,0.000000
13.440001,11.826180,-60.182728,-0.004005,0.000677,0.017206,52.605473,2.679851,0.172058,-60.182728,0.018403,0.000000
13.870001,12.511711,-60.227207,-0.003984,0.000710,0.018030,55.654869,2.835194,0.180296,-60.227207,0.019122,0.000000
14.300001,12.891533,-60.182728,-0.003954,0.000741,0.018810,57.344402,2.921263,0.188101,-60.182728,0.019842,0.000000
14.730000,13.050537,-60.182728,-0.003936,0.000760,0.019304,58.051689,2.957294,0.193044,-60.182728,0.020553,0.000000
15.160001,13.897682,-60.271690,-0.003893,0.000797,0.020241,61.819977,3.149260,0.202410,-60.271690,0.021273,0.000000
15.590001,13.931198,-60.227207,-0.003863,0.000817,0.020753,61.969063,3.156855,0.207527,-60.227207,0.021993,0.000000
16.020000,14.369110,-60.360649,-0.003842,0.000843,0.021420,63.916992,3.256087,0.214205,-60.360649,0.022704,0.000000
16.450001,14.968628,-60.271690,-0.003807,0.000877,0.022288,66.583786,3.391940,0.222877,-60.271690,0.023424,0.000000
16.880001,15.498512,-60.271690,-0.003755,0.000912,0.023172,68.940826,3.512013,0.231723,-60.271690,0.024144,0.000000
17.310001,15.544685,-60.271690,-0.003742,0.000935,0.023753,69.146217,3.522476,0.237533,-60.271690,0.024855,0.000000
17.740002,15.789337,-60.316170,-0.003712,0.000959,0.024360,70.234482,3.577915,0.243604,-60.316170,0.025574,0.000000
18.170000,16.545250,-60.316170,-0.003686,0.000993,0.025219,73.596947,3.749207,0.252189,-60.316170,0.026294,0.000000
18.600000,15.998238,-60.360649,-0.003652,0.001005,0.025522,71.163712,3.625252,0.255225,-60.360649,0.027005,0.000000
19.030001,16.925819,-60.360649,-0.003604,0.001049,0.026641,75.289803,3.835445,0.266412,-60.360649,0.027725,0.000000
19.460001,17.057266,-60.360649,-0.003570,0.001072,0.027231,75.874512,3.865232,0.272309,-60.360649,0.028445,0.000000
19.890001,17.517891,-60.405132,-0.003535,0.001107,0.028115,77.923470,3.969611,0.281155,-60.405132,0.029156,0.000000
20.320002,17.587898,-60.405132,-0.003510,0.001133,0.028766,78.234879,3.985475,0.287659,-60.405132,0.029876,0.000000
20.750002,17.872391,-60.494095,-0.003471,0.001161,0.029477,79.500366,4.049942,0.294770,-60.494095,0.030587,0.000000
21.180000,18.060806,-60.449612,-0.003428,0.001188,0.030179,80.338478,4.092637,0.301795,-60.449612,0.031307,0.000000
21.610001,17.776314,-60.449612,-0.003389,0.001207,0.030656,79.072990,4.028170,0.306564,-60.449612,0.032027,0.000000
22.040001,18.744858,-60.494095,-0.003363,0.001247,0.031680,83.381294,4.247645,0.316798,-60.494095,0.032738,0.000000
22.470001,18.341949,-60.449612,-0.003320,0.001270,0.032269,81.589066,4.156345,0.322695,-60.449612,0.033458,0.000000
22.900002,18.668144,-60.405132,-0.003281,0.001303,0.033085,83.040054,4.230262,0.330847,-60.405132,0.034177,0.000000
23.330002,18.705757,-60.494095,-0.003234,0.001326,0.033692,83.207367,4.238785,0.336917,-60.494095,0.034888,0.000000
23.760000,19.355179,-60.494095,-0.003199,0.001363,0.034628,86.096138,4.385946,0.346283,-60.494095,0.035608,0.000000
24.190001,19.169365,-60.538574,-0.003169,0.001386,0.035209,85.269592,4.343840,0.352094,-60.538574,0.036328,0.000000
24.620001,19.025253,-60.494095,-0.003134,0.001409,0.035782,84.628555,4.311184,0.357817,-60.494095,0.037039,0.000000
25.050001,19.755852,-60.583054,-0.003074,0.001450,0.036840,87.878418,4.476740,0.368397,-60.583054,0.037759,0.000000
25.480001,19.379005,-60.494095,-0.003044,0.001472,0.037386,86.202118,4.391345,0.373861,-60.494095,0.038479,0.000000
25.910002,19.933472,-60.627537,-0.003009,0.001503,0.038184,88.668510,4.516989,0.381839,-60.627537,0.039190,0.000000
26.340002,20.001617,-60.583054,-0.002971,0.001529,0.038843,88.971642,4.532432,0.388430,-60.583054,0.039910,0.000000
26.770000,20.186684,-60.627537,-0.002945,0.001559,0.039606,89.794853,4.574368,0.396062,-60.627537,0.040621,0.000000
27.200001,20.334518,-60.583054,-0.002884,0.001586,0.040291,90.452454,4.607868,0.402913,-60.583054,0.041341,0.000000
27.630001,20.254829,-60.627537,-0.002863,0.001615,0.041020,90.097984,4.589810,0.410198,-60.627537,0.042060,0.000000
28.060001,20.306587,-60.672016,-0.002824,0.001643,0.041722,90.328209,4.601539,0.417222,-60.672016,0.042772,0.000000
28.490002,20.251472,-60.716499,-0.002785,0.001665,0.042295,90.083046,4.589049,0.422946,-60.716499,0.043491,0.000000
28.920002,20.235840,-60.716499,-0.002755,0.001691,0.042954,90.013512,4.585507,0.429537,-60.716499,0.044211,0.000000
29.350002,20.146095,-60.627537,-0.002712,0.001712,0.043483,89.614311,4.565170,0.434827,-60.627537,0.044922,0.000000
29.780001,21.565208,-60.716499,-0.002669,0.001758,0.044653,95.926842,4.886746,0.446535,-60.716499,0.045642,0.000000
30.210001,21.227463,-60.716499,-0.002634,0.001785,0.045347,94.424469,4.810212,0.453472,-60.716499,0.046362,0.000000
30.640001,21.034203,-60.760979,-0.002591,0.001807,0.045902,93.564804,4.766418,0.459023,-60.760979,0.047073,0.000000
31.070002,21.227089,-60.716499,-0.002565,0.001838,0.046674,94.422806,4.810127,0.466741,-60.716499,0.047793,0.000000
31.500002,21.396149,-60.760979,-0.002509,0.001868,0.047455,95.174820,4.848436,0.474546,-60.760979,0.048513,0.000000
31.930002,21.387955,-60.805462,-0.002483,0.001893,0.048079,95.138374,4.846580,0.480790,-60.805462,0.049224,0.000000
32.360001,21.586060,-60.805462,-0.002449,0.001924,0.048868,96.019592,4.891471,0.488682,-60.805462,0.049944,0.000000
32.790001,21.825867,-60.805462,-0.002410,0.001953,0.049605,97.086304,4.945812,0.496053,-60.805462,0.050663,0.000000
33.220001,21.734634,-60.805462,-0.002380,0.001979,0.050256,96.680481,4.925138,0.502557,-60.805462,0.051374,0.000000
33.650002,21.921936,-60.805462,-0.002341,0.002009,0.051036,97.513641,4.967582,0.510362,-60.805462,0.052094,0.000000
34.080002,22.266754,-60.894421,-0.002302,0.002039,0.051799,99.047470,5.045719,0.517994,-60.894421,0.052805,0.000000
34.510002,22.379585,-60.849941,-0.002264,0.002065,0.052450,99.549370,5.071287,0.524498,-60.849941,0.053525,0.000000
34.940002,22.466347,-60.849941,-0.002233,0.002090,0.053074,99.935303,5.090947,0.530742,-60.849941,0.054245,0.000000
35.370003,23.261734,-60.849941,-0.002190,0.002126,0.053993,103.473358,5.271184,0.539935,-60.849941,0.054956,0.000000
35.800003,22.810043,-60.894421,-0.002169,0.002147,0.054540,101.464142,5.168829,0.545398,-60.894421,0.055676,0.000000
36.230003,23.374191,-60.938904,-0.002121,0.002177,0.055303,103.973595,5.296667,0.553030,-60.938904,0.056396,0.000000
36.660000,23.583092,-60.849941,-0.002091,0.002208,0.056075,104.902832,5.344005,0.560748,-60.849941,0.057107,0.000000
37.090000,22.891228,-60.938904,-0.002057,0.002221,0.056404,101.825264,5.187226,0.564044,-60.938904,0.057827,0.000000
37.520000,24.540833,-60.894421,-0.002031,0.002263,0.057471,109.163078,5.561032,0.574710,-60.894421,0.058546,0.000000
37.950001,24.343849,-61.027866,-0.001983,0.002288,0.058104,108.286850,5.516395,0.581041,-61.027866,0.059258,0.000000
38.380001,24.873734,-60.983383,-0.001953,0.002323,0.059006,110.643890,5.636468,0.590060,-60.983383,0.059977,0.000000
38.810001,24.528175,-60.938904,-0.001919,0.002343,0.059500,109.106773,5.558164,0.595004,-60.938904,0.060697,0.000000
39.240002,24.776543,-60.938904,-0.001906,0.002370,0.060185,110.211563,5.614445,0.601855,-60.938904,0.061408,0.000000
39.670002,25.534698,-61.027866,-0.001850,0.002400,0.060949,113.584015,5.786245,0.609486,-61.027866,0.062128,0.000000
40.100002,25.890312,-61.072346,-0.001828,0.002429,0.061694,115.165863,5.866829,0.616944,-61.072346,0.062839,0.000000
40.530003,26.403442,-61.072346,-0.001802,0.002460,0.062492,117.448380,5.983106,0.624923,-61.072346,0.063559,0.000000
40.960003,26.123421,-61.027866,-0.001768,0.002480,0.063004,116.202782,5.919652,0.630039,-61.027866,0.064279,0.000000
41.390003,27.342194,-61.027866,-0.001733,0.002520,0.064010,121.624153,6.195829,0.640099,-61.027866,0.064990,0.000000
41.820004,27.213348,-61.116825,-0.001699,0.002540,0.064504,121.051018,6.166633,0.645042,-61.116825,0.065710,0.000000
42.250004,28.137581,-61.072346,-0.001673,0.002573,0.065354,125.162209,6.376067,0.653541,-61.072346,0.066429,0.000000
42.680000,28.390793,-61.116825,-0.001656,0.002603,0.066126,126.288551,6.433445,0.661260,-61.116825,0.067141,0.000000
43.110001,28.205353,-61.161308,-0.001617,0.002618,0.066508,125.463676,6.391424,0.665075,-61.161308,0.067860,0.000000
43.540001,29.596161,-61.116825,-0.001569,0.002657,0.067496,131.650299,6.706586,0.674962,-61.116825,0.068580,0.000000
43.970001,29.137398,-61.161308,-0.001539,0.002676,0.067964,129.609619,6.602629,0.679645,-61.161308,0.069291,0.000000
44.400002,30.773605,-61.161308,-0.001522,0.002717,0.069014,136.887833,6.973399,0.690138,-61.161308,0.070011,0.000000
44.830002,30.527092,-61.161308,-0.001496,0.002734,0.069447,135.791290,6.917538,0.694474,-61.161308,0.070731,0.000000
45.260002,31.897049,-61.205788,-0.001466,0.002772,0.070410,141.885162,7.227975,0.704101,-61.205788,0.071442,0.000000
45.690002,32.450768,-61.161308,-0.001423,0.002798,0.071060,144.348221,7.353449,0.710605,-61.161308,0.072162,0.000000
46.120003,33.846420,-61.250271,-0.001418,0.002835,0.072014,150.556396,7.669708,0.720144,-61.250271,0.072873,0.000000
46.550003,34.055321,-61.250271,-0.001371,0.002860,0.072647,151.485626,7.717046,0.726475,-61.250271,0.073593,0.000000
46.980003,33.461761,-61.205788,-0.001341,0.002873,0.072968,148.845352,7.582543,0.729684,-61.205788,0.074313,0.000000
47.410004,34.659309,-61.294750,-0.001315,0.002909,0.073896,154.172302,7.853912,0.738963,-61.294750,0.075024,0.000000
47.840004,35.787971,-61.339233,-0.001285,0.002936,0.074573,159.192841,8.109671,0.745727,-61.339233,0.075743,0.000000
48.270000,36.740875,-61.294750,-0.001259,0.002966,0.075345,163.431580,8.325602,0.753446,-61.294750,0.076463,0.000000
48.700001,37.937309,-61.339233,-0.001246,0.003000,0.076203,168.753586,8.596717,0.762031,-61.339233,0.077174,0.000000
49.130001,38.547623,-61.294750,-0.001212,0.003025,0.076828,171.468384,8.735016,0.768275,-61.294750,0.077894,0.000000
49.560001,39.067459,-61.250271,-0.001199,0.003050,0.077469,173.780731,8.852813,0.774693,-61.250271,0.078614,0.000000
49.990002,40.026688,-61.339233,-0.001181,0.003079,0.078198,178.047592,9.070177,0.781977,-61.339233,0.079325,0.000000
50.420002,40.890594,-61.428192,-0.001155,0.003102,0.078796,181.890442,9.265942,0.787961,-61.428192,0.080045,0.000000
50.850002,42.146233,-61.339233,-0.001147,0.003133,0.079585,187.475800,9.550472,0.795853,-61.339233,0.080765,0.000000
51.280003,43.579865,-61.339233,-0.001108,0.003165,0.080383,193.852921,9.875339,0.803832,-61.339233,0.081476,0.000000
51.710003,44.269875,-61.294750,-0.001082,0.003187,0.080947,196.922241,10.031696,0.809468,-61.294750,0.082196,0.000000
52.140003,45.773514,-61.428192,-0.001065,0.003222,0.081840,203.610764,10.372427,0.818401,-61.428192,0.082915,0.000000
52.570004,47.103630,-61.428192,-0.001039,0.003251,0.082577,209.527405,10.673836,0.825772,-61.428192,0.083627,0.000000
53.000004,48.138824,-61.428192,-0.001022,0.003277,0.083245,214.132187,10.908413,0.832450,-61.428192,0.084346,0.000000
53.430004,49.495750,-61.383713,-0.000996,0.003306,0.083982,220.168091,11.215898,0.839821,-61.383713,0.085057,0.000000
53.860004,50.250549,-61.472675,-0.000992,0.003328,0.084537,223.525604,11.386937,0.845372,-61.472675,0.085777,0.000000
54.290001,51.287979,-61.517155,-0.000966,0.003352,0.085136,228.140320,11.622022,0.851355,-61.517155,0.086497,0.000000
54.720001,53.332672,-61.561638,-0.000944,0.003388,0.086046,237.235580,12.085356,0.860461,-61.561638,0.087208,0.000000
55.150002,54.973343,-61.517155,-0.000931,0.003419,0.086844,244.533646,12.457137,0.868440,-61.517155,0.087928,0.000000
55.580002,56.343307,-61.472675,-0.000923,0.003447,0.087546,250.627548,12.767576,0.875464,-61.472675,0.088648,0.000000
56.010002,57.921043,-61.517155,-0.000897,0.003474,0.088240,257.645660,13.125095,0.882402,-61.517155,0.089359,0.000000
56.440002,58.892197,-61.517155,-0.000880,0.003499,0.088882,261.965576,13.345162,0.888820,-61.517155,0.090079,0.000000
56.870003,60.958115,-61.606117,-0.000871,0.003533,0.089732,271.155243,13.813307,0.897318,-61.606117,0.090799,0.000000
57.300003,61.555031,-61.606117,-0.000854,0.003551,0.090183,273.810455,13.948569,0.901828,-61.606117,0.091510,0.000000
57.730003,63.371834,-61.606117,-0.000836,0.003580,0.090920,281.891998,14.360263,0.909199,-61.606117,0.092229,0.000000
58.160004,65.344292,-61.561638,-0.000828,0.003611,0.091718,290.665924,14.807228,0.917178,-61.561638,0.092949,0.000000
58.590004,66.078987,-61.695080,-0.000793,0.003620,0.091961,293.934021,14.973713,0.919606,-61.695080,0.092212,0.000000
59.020004,64.795418,-61.695080,-0.000806,0.003625,0.092082,288.224426,14.682852,0.920820,-61.695080,294.500488,0.000000
59.450005,65.600487,-61.650597,-0.000780,0.003643,0.092533,291.805542,14.865283,0.925330,-61.650597,294.500488,0.000000
59.880001,64.913078,-61.650597,-0.000780,0.003645,0.092576,288.747803,14.709514,0.925763,-61.650597,294.500488,0.000000
60.310001,65.132790,-61.695080,-0.000763,0.003653,0.092784,289.725128,14.759300,0.927845,-61.695080,294.500488,0.000000
60.740002,65.655968,-61.695080,-0.000767,0.003665,0.093088,292.052338,14.877855,0.930880,-61.695080,294.500488,0.000000
61.170002,65.129066,-61.695080,-0.000755,0.003665,0.093088,289.708557,14.758457,0.930880,-61.695080,294.500488,0.000000
61.600002,65.202415,-61.695080,-0.000767,0.003671,0.093253,290.034821,14.775078,0.932528,-61.695080,294.500488,0.000000
62.030003,65.371101,-61.739559,-0.000742,0.003680,0.093461,290.785187,14.813304,0.934609,-61.739559,294.500488,0.000000
62.460003,65.143959,-61.739559,-0.000742,0.003680,0.093461,289.774811,14.761832,0.934609,-61.739559,294.500488,0.000000
62.890003,65.281364,-61.739559,-0.000755,0.003685,0.093608,290.386017,14.792969,0.936083,-61.739559,294.500488,0.000000
63.320004,65.002083,-61.695080,-0.000737,0.003686,0.093617,289.143707,14.729683,0.936170,-61.695080,294.500488,0.000000
63.750004,65.369606,-61.739559,-0.000742,0.003693,0.093799,290.778534,14.812964,0.937991,-61.739559,294.500488,0.000000
64.180000,65.094429,-61.784042,-0.000729,0.003693,0.093799,289.554474,14.750608,0.937991,-61.784042,294.500488,0.000000
64.610001,64.882545,-61.784042,-0.000720,0.003694,0.093834,288.611969,14.702596,0.938338,-61.784042,294.500488,0.000000
65.040001,65.574791,-61.828522,-0.000729,0.003704,0.094077,291.691223,14.859460,0.940766,-61.828522,294.500488,0.000000
65.470001,65.352104,-61.828522,-0.000729,0.003704,0.094077,290.700684,14.808999,0.940766,-61.828522,294.500488,0.000000
65.900002,65.147682,-61.784042,-0.000733,0.003704,0.094085,289.791351,14.762676,0.940853,-61.784042,294.500488,0.000000
66.330002,65.582985,-61.828522,-0.000733,0.003712,0.094285,291.727692,14.861317,0.942848,-61.828522,294.500488,0.000000
66.760002,65.470894,-61.828522,-0.000703,0.003712,0.094285,291.229095,14.835917,0.942848,-61.828522,294.500488,0.000000
67.190002,65.264610,-61.917484,-0.000724,0.003712,0.094293,290.311493,14.789172,0.942935,-61.917484,294.500488,0.000000
67.620003,65.070976,-61.873001,-0.000711,0.003713,0.094302,289.450165,14.745294,0.943021,-61.873001,294.500488,0.000000
68.050003,65.060539,-61.873001,-0.000716,0.003721,0.094502,289.403748,14.742929,0.945016,-61.873001,294.500488,0.000000
68.480003,65.571434,-61.873001,-0.000720,0.003722,0.094528,291.676300,14.858700,0.945276,-61.873001,294.500488,0.000000
68.910004,65.440361,-61.961964,-0.000707,0.003722,0.094528,291.093262,14.828998,0.945276,-61.961964,294.500488,0.000000
69.340004,65.288811,-61.961964,-0.000720,0.003722,0.094528,290.419128,14.794656,0.945276,-61.961964,294.500488,0.000000
69.770004,65.178963,-62.006447,-0.000698,0.003723,0.094554,289.930511,14.769765,0.945536,-62.006447,294.500488,0.000000
70.200005,65.323814,-61.917484,-0.000703,0.003728,0.094684,290.574829,14.802588,0.946837,-61.917484,294.500488,0.000000
70.630005,65.345039,-61.917484,-0.000707,0.003727,0.094675,290.669250,14.807397,0.946750,-61.917484,294.500488,0.000000
71.060005,65.245613,-61.961964,-0.000703,0.003727,0.094675,290.226990,14.784867,0.946750,-61.961964,294.500488,0.000000
71.490005,65.126076,-62.050926,-0.000698,0.003727,0.094675,289.695251,14.757779,0.946750,-62.050926,294.500488,0.000000
71.920006,65.012138,-62.006447,-0.000694,0.003728,0.094684,289.188446,14.731961,0.946837,-62.006447,294.500488,0.000000
72.350006,64.892235,-62.006447,-0.000716,0.003728,0.094684,288.655090,14.704790,0.946837,-62.006447,294.500488,0.000000
72.780006,65.235558,-62.006447,-0.000694,0.003734,0.094831,290.182251,14.782589,0.948311,-62.006447,294.500488,0.000000
73.210007,65.179329,-62.095409,-0.000698,0.003734,0.094831,289.932129,14.769847,0.948311,-62.095409,294.500488,0.000000
73.640007,65.087730,-62.139889,-0.000698,0.003734,0.094831,289.524689,14.749090,0.948311,-62.139889,294.500488,0.000000
74.070007,65.002083,-62.050926,-0.000703,0.003734,0.094831,289.143707,14.729683,0.948311,-62.050926,294.500488,0.000000
74.500000,64.900047,-62.006447,-0.000698,0.003734,0.094831,288.689819,14.706561,0.948311,-62.006447,294.500488,0.000000
74.930000,64.781639,-62.139889,-0.000681,0.003734,0.094840,288.163116,14.679729,0.948398,-62.139889,294.500488,0.000000
75.360001,65.345039,-62.139889,-0.000703,0.003741,0.095031,290.669250,14.807397,0.950306,-62.139889,294.500488,0.000000
75.790001,65.316368,-62.184368,-0.000690,0.003741,0.095022,290.541718,14.800900,0.950219,-62.184368,294.500488,0.000000
76.220001,65.269814,-62.184368,-0.000694,0.003741,0.095022,290.334625,14.790351,0.950219,-62.184368,294.500488,0.000000
76.650002,65.217308,-62.139889,-0.000698,0.003741,0.095022,290.101074,14.778454,0.950219,-62.139889,294.500488,0.000000
77.080002,65.102623,-62.139889,-0.000677,0.003741,0.095031,289.590942,14.752465,0.950306,-62.139889,294.500488,0.000000
77.510002,65.036339,-62.184368,-0.000698,0.003741,0.095031,289.296082,14.737446,0.950306,-62.184368,294.500488,0.000000
77.940002,64.965218,-62.228851,-0.000694,0.003741,0.095031,288.979706,14.721329,0.950306,-62.228851,294.500488,0.000000
78.370003,64.878822,-62.184368,-0.000677,0.003741,0.095031,288.595428,14.701751,0.950306,-62.184368,294.500488,0.000000
78.800003,64.795036,-62.184368,-0.000677,0.003742,0.095039,288.222717,14.682765,0.950393,-62.184368,294.500488,0.000000
79.230003,64.727638,-62.228851,-0.000686,0.003742,0.095039,287.922913,14.667493,0.950393,-62.228851,294.500488,0.000000
79.660004,64.658379,-62.184368,-0.000686,0.003742,0.095039,287.614838,14.651798,0.950393,-62.184368,294.500488,0.000000
80.090004,65.763588,-62.228851,-0.000690,0.003754,0.095351,292.531036,14.902242,0.953515,-62.228851,294.500488,0.000000
80.520004,65.768791,-62.228851,-0.000686,0.003754,0.095351,292.554199,14.903420,0.953515,-62.228851,294.500488,0.000000
80.950005,65.661919,-62.228851,-0.000673,0.003754,0.095351,292.078796,14.879203,0.953515,-62.228851,294.500488,0.000000
81.380005,65.597130,-62.273331,-0.000690,0.003754,0.095351,291.790619,14.864522,0.953515,-62.273331,294.500488,0.000000
81.810005,65.573677,-62.273331,-0.000681,0.003754,0.095351,291.686279,14.859208,0.953515,-62.273331,294.500488,0.000000
82.240005,65.523033,-62.317814,-0.000686,0.003754,0.095351,291.460999,14.847732,0.953515,-62.317814,294.500488,0.000000
82.670006,65.474251,-62.273331,-0.000686,0.003754,0.095351,291.244019,14.836677,0.953515,-62.273331,294.500488,0.000000
83.100006,65.372597,-62.317814,-0.000677,0.003754,0.095351,290.791840,14.813643,0.953515,-62.317814,294.500488,0.000000
83.530006,65.317116,-62.362293,-0.000673,0.003754,0.095351,290.545044,14.801069,0.953515,-62.362293,294.500488,0.000000
83.960007,65.266472,-62.406773,-0.000694,0.003754,0.095351,290.319763,14.789594,0.953515,-62.406773,294.500488,0.000000
84.390007,65.209496,-62.406773,-0.000681,0.003754,0.095351,290.066315,14.776683,0.953515,-62.406773,294.500488,0.000000
84.820007,65.130547,-62.273331,-0.000668,0.003754,0.095351,289.715149,14.758793,0.953515,-62.273331,294.500488,0.000000
85.250008,65.078041,-62.451256,-0.000677,0.003754,0.095351,289.481598,14.746895,0.953515,-62.451256,294.500488,0.000000
85.680000,65.032616,-62.406773,-0.000673,0.003754,0.095351,289.279510,14.736601,0.953515,-62.406773,294.500488,0.000000
86.110001,64.992775,-62.451256,-0.000681,0.003754,0.095351,289.102295,14.727573,0.953515,-62.451256,294.500488,0.000000
86.540001,64.920525,-62.495735,-0.000681,0.003754,0.095360,288.780914,14.711201,0.953601,-62.495735,294.500488,0.000000
86.970001,64.857231,-62.451256,-0.000668,0.003754,0.095360,288.499359,14.696858,0.953601,-62.451256,294.500488,0.000000
87.400002,64.833397,-62.495735,-0.000673,0.003755,0.095386,288.393341,14.691458,0.953862,-62.495735,294.500488,0.000000
87.830002,64.801750,-62.451256,-0.000668,0.003755,0.095386,288.252594,14.684287,0.953862,-62.451256,294.500488,0.000000
88.260002,64.755196,-62.495735,-0.000686,0.003755,0.095386,288.045502,14.673737,0.953862,-62.495735,294.500488,0.000000
88.690002,64.728386,-62.495735,-0.000686,0.003755,0.095386,287.926239,14.667662,0.953862,-62.495735,294.500488,0.000000
89.120003,64.689293,-62.495735,-0.000681,0.003756,0.095395,287.752350,14.658804,0.953948,-62.495735,294.500488,0.000000
89.550003,64.655403,-62.540218,-0.000664,0.003756,0.095395,287.601593,14.651123,0.953948,-62.540218,294.500488,0.000000
89.980003,64.595818,-62.629181,-0.000681,0.003756,0.095395,287.336548,14.637621,0.953948,-62.629181,294.500488,0.000000
90.410004,65.345406,-62.584698,-0.000681,0.003767,0.095672,290.670868,14.807481,0.956723,-62.584698,294.500488,0.000000
90.840004,65.481697,-62.540218,-0.000681,0.003766,0.095664,291.277130,14.838365,0.956637,-62.540218,294.500488,0.000000
91.270004,65.494728,-62.629181,-0.000664,0.003766,0.095664,291.335114,14.841318,0.956637,-62.629181,294.500488,0.000000
91.700005,65.495476,-62.629181,-0.000681,0.003766,0.095664,291.338440,14.841487,0.956637,-62.629181,294.500488,0.000000
92.130005,65.453026,-62.673660,-0.000664,0.003766,0.095664,291.149597,14.831867,0.956637,-62.673660,294.500488,0.000000
92.560005,65.429939,-62.673660,-0.000664,0.003766,0.095664,291.046906,14.826636,0.956637,-62.673660,294.500488,0.000000
92.990005,65.387856,-62.673660,-0.000668,0.003766,0.095664,290.859711,14.817100,0.956637,-62.673660,294.500488,0.000000
93.420006,65.350243,-62.673660,-0.000664,0.003766,0.095664,290.692383,14.808577,0.956637,-62.673660,294.500488,0.000000
93.850006,65.316734,-62.629181,-0.000664,0.003766,0.095664,290.543335,14.800983,0.956637,-62.629181,294.500488,0.000000
94.280006,65.275780,-62.718140,-0.000668,0.003766,0.095664,290.361176,14.791703,0.956637,-62.718140,294.500488,0.000000
94.710007,65.258644,-62.718140,-0.000668,0.003766,0.095664,290.284943,14.787820,0.956637,-62.718140,294.500488,0.000000
95.140007,65.221413,-62.718140,-0.000660,0.003767,0.095672,290.119324,14.779383,0.956723,-62.718140,294.500488,0.000000
95.570007,65.195335,-62.718140,-0.000673,0.003767,0.095672,290.003326,14.773474,0.956723,-62.718140,294.500488,0.000000
96.000008,65.159599,-62.718140,-0.000673,0.003767,0.095672,289.844360,14.765376,0.956723,-62.718140,294.500488,0.000000
96.430008,65.115654,-62.762623,-0.000660,0.003767,0.095681,289.648895,14.755418,0.956810,-62.762623,294.500488,0.000000
96.860008,65.091072,-62.762623,-0.000673,0.003767,0.095681,289.539551,14.749847,0.956810,-62.762623,294.500488,0.000000
97.290001,65.047508,-62.762623,-0.000677,0.003767,0.095681,289.345764,14.739976,0.956810,-62.762623,294.500488,0.000000
97.720001,65.029640,-62.807102,-0.000668,0.003767,0.095681,289.266296,14.735928,0.956810,-62.807102,294.500488,0.000000
98.150002,65.002449,-62.851585,-0.000664,0.003767,0.095681,289.145325,14.729765,0.956810,-62.851585,294.500488,0.000000
98.580002,64.953300,-62.807102,-0.000673,0.003767,0.095681,288.926697,14.718629,0.956810,-62.807102,294.500488,0.000000
99.010002,64.932823,-62.851585,-0.000668,0.003767,0.095681,288.835632,14.713987,0.956810,-62.851585,294.500488,0.000000
99.440002,64.888878,-62.807102,-0.000673,0.003767,0.095681,288.640137,14.704030,0.956810,-62.807102,294.500488,0.000000
99.870003,64.844566,-62.807102,-0.000655,0.003767,0.095681,288.443024,14.693989,0.956810,-62.807102,294.500488,0.000000
100.300003,64.815529,-62.940544,-0.000660,0.003767,0.095681,288.313873,14.687408,0.956810,-62.940544,294.500488,0.000000
100.730003,64.782005,-62.940544,-0.000668,0.003767,0.095681,288.164764,14.679812,0.956810,-62.940544,294.500488,0.000000
101.160004,64.934685,-62.940544,-0.000673,0.003771,0.095776,288.843903,14.714410,0.957764,-62.940544,294.500488,0.000000
101.590004,64.947350,-62.896065,-0.000677,0.003771,0.095776,288.900238,14.717279,0.957764,-62.896065,294.500488,0.000000
102.020004,64.938774,-62.940544,-0.000664,0.003771,0.095776,288.862091,14.715337,0.957764,-62.940544,294.500488,0.000000
102.450005,64.924248,-62.940544,-0.000668,0.003771,0.095776,288.797485,14.712045,0.957764,-62.940544,294.500488,0.000000
102.880005,64.901543,-62.985027,-0.000664,0.003771,0.095776,288.696472,14.706901,0.957764,-62.985027,294.500488,0.000000
103.310005,64.892235,-63.029507,-0.000664,0.003771,0.095785,288.655090,14.704790,0.957851,-63.029507,294.500488,0.000000
103.740005,65.505150,-63.029507,-0.000660,0.003777,0.095941,291.381470,14.843679,0.959412,-63.029507,294.500488,0.000000
104.170006,65.473885,-62.985027,-0.000660,0.003777,0.095941,291.242371,14.836595,0.959412,-62.985027,294.500488,0.000000
104.600006,65.468285,-63.029507,-0.000651,0.003777,0.095941,291.217468,14.835325,0.959412,-63.029507,294.500488,0.000000
105.030006,65.441856,-63.118469,-0.000673,0.003777,0.095941,291.099915,14.829336,0.959412,-63.118469,294.500488,0.000000
105.460007,65.410576,-63.073990,-0.000673,0.003777,0.095941,290.960785,14.822248,0.959412,-63.073990,294.500488,0.000000
105.890007,65.395302,-63.029507,-0.000660,0.003777,0.095941,290.892822,14.818788,0.959412,-63.029507,294.500488,0.000000
106.320007,65.363289,-63.073990,-0.000660,0.003777,0.095941,290.750427,14.811533,0.959412,-63.073990,294.500488,0.000000
106.750008,65.337212,-63.118469,-0.000668,0.003777,0.095941,290.634430,14.805623,0.959412,-63.118469,294.500488,0.000000
107.180008,65.320091,-63.118469,-0.000655,0.003777,0.095941,290.558289,14.801744,0.959412,-63.118469,294.500488,0.000000
107.610008,65.296257,-63.073990,-0.000668,0.003777,0.095941,290.452271,14.796344,0.959412,-63.073990,294.500488,0.000000
108.040009,65.271675,-63.029507,-0.000660,0.003777,0.095941,290.342926,14.790773,0.959412,-63.029507,294.500488,0.000000
108.470009,65.253426,-63.118469,-0.000651,0.003777,0.095941,290.261719,14.786638,0.959412,-63.118469,294.500488,0.000000
108.900002,65.222893,-63.162949,-0.000673,0.003777,0.095941,290.125916,14.779719,0.959412,-63.162949,294.500488,0.000000
109.330002,65.203163,-63.207432,-0.000668,0.003777,0.095941,290.038147,14.775248,0.959412,-63.207432,294.500488,0.000000
109.760002,65.159218,-63.118469,-0.000668,0.003777,0.095941,289.842682,14.765290,0.959412,-63.118469,294.500488,0.000000
110.190002,65.123100,-63.162949,-0.000651,0.003777,0.095941,289.682007,14.757106,0.959412,-63.162949,294.500488,0.000000
110.620003,65.092567,-63.162949,-0.000655,0.003777,0.095941,289.546204,14.750187,0.959412,-63.162949,294.500488,0.000000
111.050003,65.082893,-63.251911,-0.000660,0.003777,0.095941,289.503174,14.747994,0.959412,-63.251911,294.500488,0.000000
111.480003,65.040810,-63.207432,-0.000660,0.003777,0.095941,289.315979,14.738459,0.959412,-63.207432,294.500488,0.000000
111.910004,65.019951,-63.207432,-0.000668,0.003777,0.095941,289.223175,14.733731,0.959412,-63.207432,294.500488,0.000000
112.340004,64.995384,-63.207432,-0.000651,0.003777,0.095941,289.113922,14.728165,0.959412,-63.207432,294.500488,0.000000
112.770004,64.984947,-63.207432,-0.000660,0.003777,0.095941,289.067474,14.725800,0.959412,-63.207432,294.500488,0.000000
113.200005,64.963356,-63.296394,-0.000664,0.003777,0.095941,288.971436,14.720907,0.959412,-63.296394,294.500488,0.000000
113.630005,64.940636,-63.251911,-0.000664,0.003777,0.095941,288.870361,14.715758,0.959412,-63.251911,294.500488,0.000000
114.060005,64.903404,-63.251911,-0.000660,0.003777,0.095941,288.704773,14.707321,0.959412,-63.251911,294.500488,0.000000
114.490005,64.878456,-63.296394,-0.000655,0.003777,0.095941,288.593781,14.701669,0.959412,-63.296394,294.500488,0.000000
114.920006,64.843071,-63.340874,-0.000647,0.003777,0.095941,288.436371,14.693649,0.959412,-63.340874,294.500488,0.000000
115.350006,64.820732,-63.385357,-0.000660,0.003777,0.095941,288.337006,14.688588,0.959412,-63.385357,294.500488,0.000000
115.780006,64.806953,-63.385357,-0.000668,0.003777,0.095941,288.275726,14.685465,0.959412,-63.385357,294.500488,0.000000
116.210007,64.784981,-63.296394,-0.000651,0.003777,0.095941,288.177979,14.680487,0.959412,-63.296394,294.500488,0.000000
116.640007,65.837685,-63.340874,-0.000651,0.003789,0.096236,292.860657,14.919033,0.962360,-63.340874,294.500488,0.000000
117.070007,65.826881,-63.385357,-0.000651,0.003789,0.096236,292.812592,14.916584,0.962360,-63.385357,294.500488,0.000000
117.500008,65.831352,-63.429836,-0.000655,0.003789,0.096236,292.832489,14.917598,0.962360,-63.429836,294.500488,0.000000
117.930008,65.847374,-63.474316,-0.000655,0.003789,0.096236,292.903748,14.921227,0.962360,-63.474316,294.500488,0.000000
118.360008,65.830238,-63.429836,-0.000664,0.003789,0.096236,292.827515,14.917345,0.962360,-63.429836,294.500488,0.000000
118.790009,65.820549,-63.385357,-0.000655,0.003789,0.096236,292.784424,14.915150,0.962360,-63.385357,294.500488,0.000000
119.220009,65.810509,-63.429836,-0.000664,0.003789,0.096236,292.739777,14.912875,0.962360,-63.429836,1681.640991,0.000000
119.650009,65.611656,-63.474316,-0.000664,0.003773,0.095828,291.855225,14.867814,0.958284,-63.474316,0.095603,0.000000
120.080009,65.572929,-63.518799,-0.000660,0.003752,0.095291,291.682953,14.859038,0.952908,-63.518799,0.094883,0.000000
120.510002,65.470528,-63.474316,-0.000638,0.003728,0.094692,291.227448,14.835834,0.946924,-63.474316,0.094172,0.000000
120.940002,65.496590,-63.474316,-0.000642,0.003704,0.094094,291.343384,14.841740,0.940940,-63.474316,0.093452,0.000000
121.370003,65.403877,-63.563278,-0.000638,0.003672,0.093279,290.930969,14.820731,0.932788,-63.563278,0.092732,0.000000
121.800003,65.377434,-63.563278,-0.000655,0.003644,0.092559,290.813354,14.814738,0.925590,-63.563278,0.092021,0.000000
122.230003,65.313377,-63.518799,-0.000642,0.003616,0.091848,290.528412,14.800222,0.918479,-63.518799,0.091302,0.000000
122.660004,65.284706,-63.518799,-0.000647,0.003596,0.091345,290.400879,14.793726,0.913449,-63.518799,0.090590,0.000000
123.090004,65.156242,-63.518799,-0.000638,0.003563,0.090512,289.829437,14.764615,0.905123,-63.518799,0.089871,0.000000
123.520004,64.435707,-63.563278,-0.000638,0.003537,0.089836,286.624329,14.601340,0.898359,-63.563278,0.089151,0.000000
123.950005,63.338692,-63.607761,-0.000634,0.003509,0.089116,281.744568,14.352753,0.891161,-63.607761,0.088440,0.000000
124.380005,62.090500,-63.607761,-0.000625,0.003485,0.088509,276.192352,14.069908,0.885091,-63.607761,0.087720,0.000000
124.810005,60.493393,-63.563278,-0.000625,0.003458,0.087833,269.088043,13.707999,0.878326,-63.563278,0.087000,0.000000
125.240005,58.471039,-63.607761,-0.000608,0.003431,0.087139,260.092163,13.249727,0.871388,-63.607761,0.086289,0.000000
125.670006,56.713074,-63.652241,-0.000612,0.003409,0.086601,252.272354,12.851366,0.866012,-63.652241,0.085569,0.000000
126.100006,54.224503,-63.696720,-0.000608,0.003377,0.085777,241.202637,12.287448,0.857773,-63.696720,0.084849,0.000000
126.530006,51.640244,-63.652241,-0.000621,0.003355,0.085214,229.707275,11.701847,0.852136,-63.652241,0.084138,0.000000
126.960007,48.448265,-63.652241,-0.000608,0.003323,0.084416,215.508652,10.978534,0.844157,-63.652241,0.083418,0.000000
127.390007,45.530350,-63.652241,-0.000595,0.003296,0.083731,202.529114,10.317325,0.837306,-63.652241,0.082699,0.000000
127.820007,43.809250,-63.785683,-0.000617,0.003281,0.083349,194.873276,9.927318,0.833491,-63.785683,0.081988,0.000000
128.250000,39.504623,-63.696720,-0.000621,0.003238,0.082239,175.725342,8.951876,0.822390,-63.696720,0.081268,0.000000
128.680008,36.388237,-63.785683,-0.000621,0.003210,0.081537,161.862961,8.245692,0.815366,-63.785683,0.080548,0.000000
129.110001,32.736382,-63.741203,-0.000612,0.003177,0.080695,145.618698,7.418170,0.806953,-63.741203,0.079837,0.000000
129.540009,29.982315,-63.696720,-0.000604,0.003152,0.080071,133.367996,6.794090,0.800709,-63.696720,0.079117,0.000000
129.970001,28.311852,-63.741203,-0.000608,0.003139,0.079724,125.937408,6.415557,0.797241,-63.741203,0.078406,0.000000
130.400009,24.467850,-63.785683,-0.000621,0.003101,0.078761,108.838432,5.544494,0.787614,-63.785683,0.077686,0.000000
130.830002,20.414948,-63.785683,-0.000599,0.003064,0.077816,90.810219,4.626093,0.778162,-63.785683,0.076966,0.000000
131.260010,17.683220,-63.785683,-0.000621,0.003039,0.077192,78.658890,4.007075,0.771918,-63.785683,0.076255,0.000000
131.690002,14.910164,-63.830166,-0.000604,0.003014,0.076567,66.323723,3.378691,0.765674,-63.830166,0.075535,0.000000
132.120010,12.235039,-63.830166,-0.000612,0.002985,0.075822,54.424171,2.772499,0.758215,-63.830166,0.074816,0.000000
132.550003,8.870659,-63.830166,-0.000617,0.002959,0.075154,39.458660,2.010120,0.751538,-63.830166,0.074104,0.000000
132.980011,5.178955,-63.830166,-0.000612,0.002922,0.074226,23.037142,1.173568,0.742258,-63.830166,0.073385,0.000000
133.410004,3.128670,-63.785683,-0.000608,0.002902,0.073723,13.917018,0.708967,0.737229,-63.785683,0.072665,0.000000
133.840012,0.007446,-63.874645,-0.000612,0.002869,0.072882,0.033123,0.001687,0.728816,-63.874645,0.071954,0.000000
134.270004,-2.391003,-63.919128,-0.000608,0.002844,0.072231,-10.635711,-0.541809,0.722312,-63.919128,0.071234,0.000000
134.700012,-0.338112,-63.874645,-0.000617,0.002813,0.071442,-1.503997,-0.076617,0.714420,-63.874645,0.070514,0.000000
135.130005,-0.082664,-63.874645,-0.000638,0.002786,0.070757,-0.367710,-0.018732,0.707569,-63.874645,0.069803,0.000000
135.560013,-0.051758,-63.963608,-0.000686,0.002759,0.070089,-0.230230,-0.011728,0.700892,-63.963608,0.069083,0.000000
135.990005,-0.040962,-63.963608,-0.000711,0.002729,0.069309,-0.182209,-0.009282,0.693087,-63.963608,0.068372,0.000000
136.420013,-0.053993,-63.963608,-0.000763,0.002703,0.068667,-0.240174,-0.012235,0.686669,-63.963608,0.067652,0.000000
136.850006,-0.052505,-63.963608,-0.000806,0.002670,0.067826,-0.233556,-0.011898,0.678257,-63.963608,0.066932,0.000000
137.280014,-0.026810,-63.919128,-0.000845,0.002647,0.067227,-0.119255,-0.006075,0.672273,-63.919128,0.066221,0.000000
137.710007,-0.051392,-63.963608,-0.000888,0.002620,0.066551,-0.228601,-0.011646,0.665509,-63.963608,0.065502,0.000000
138.139999,-0.022346,-64.097054,-0.000936,0.002597,0.065953,-0.099402,-0.005064,0.659525,-64.097054,0.064782,0.000000
138.570007,-0.065163,-64.052567,-0.000979,0.002563,0.065111,-0.289858,-0.014766,0.651113,-64.052567,0.064071,0.000000
139.000000,-0.082664,-64.008087,-0.001018,0.002534,0.064374,-0.367710,-0.018732,0.643742,-64.008087,0.063351,0.000000
139.430008,-0.056229,-64.008087,-0.001052,0.002509,0.063732,-0.250117,-0.012742,0.637324,-64.008087,0.062631,0.000000
139.860001,-0.081551,-64.097054,-0.001091,0.002481,0.063013,-0.362755,-0.018480,0.630126,-64.097054,0.061920,0.000000
140.290009,-0.087883,-64.097054,-0.001143,0.002451,0.062249,-0.390923,-0.019915,0.622495,-64.097054,0.061200,0.000000
140.720001,-0.054367,-64.097054,-0.001199,0.002416,0.061374,-0.241837,-0.012320,0.613736,-64.097054,0.060480,0.000000
141.150009,-0.110222,-64.097054,-0.001229,0.002392,0.060758,-0.490291,-0.024977,0.607578,-64.097054,0.059769,0.000000
141.580002,-0.086761,-64.141533,-0.001285,0.002363,0.060012,-0.385934,-0.019660,0.600120,-64.141533,0.059049,0.000000
142.010010,-0.102402,-64.097054,-0.001315,0.002336,0.059336,-0.455506,-0.023205,0.593356,-64.097054,0.058338,0.000000
142.440002,-0.088623,-64.141533,-0.001350,0.002309,0.058659,-0.394215,-0.020082,0.586591,-64.141533,0.057618,0.000000
142.870010,-0.074478,-64.141533,-0.001406,0.002278,0.057870,-0.331295,-0.016877,0.578700,-64.141533,0.056899,0.000000
143.300003,-0.091232,-64.186012,-0.001440,0.002263,0.057488,-0.405822,-0.020674,0.574884,-64.186012,0.056188,0.000000
143.730011,-0.070755,-64.141533,-0.001500,0.002220,0.056396,-0.314734,-0.016033,0.563957,-64.141533,0.055468,0.000000
144.160004,-0.087509,-64.230492,-0.001526,0.002202,0.055927,-0.389260,-0.019830,0.559274,-64.230492,0.054748,0.000000
144.590012,-0.103523,-64.230492,-0.001574,0.002166,0.055017,-0.460494,-0.023459,0.550168,-64.230492,0.054037,0.000000
145.020004,-0.106499,-64.274971,-0.001608,0.002137,0.054271,-0.473730,-0.024133,0.542710,-64.274971,0.053317,0.000000
145.450012,-0.111710,-64.186012,-0.001656,0.002109,0.053569,-0.496909,-0.025314,0.535685,-64.186012,0.052597,0.000000
145.880005,-0.118790,-64.230492,-0.001677,0.002080,0.052840,-0.528403,-0.026918,0.528401,-64.230492,0.051886,0.000000
146.310013,-0.113571,-64.274971,-0.001716,0.002050,0.052077,-0.505190,-0.025736,0.520769,-64.274971,0.051166,0.000000
146.740005,-0.108360,-64.319458,-0.001763,0.002024,0.051400,-0.482011,-0.024555,0.514005,-64.319458,0.050447,0.000000
147.170013,-0.075218,-64.230492,-0.001776,0.002005,0.050923,-0.334587,-0.017045,0.509235,-64.230492,0.049735,0.000000
147.600006,-0.121765,-64.186012,-0.001815,0.001974,0.050143,-0.541638,-0.027592,0.501430,-64.186012,0.049016,0.000000
148.030014,-0.117668,-64.319458,-0.001858,0.001944,0.049380,-0.523414,-0.026664,0.493798,-64.319458,0.048296,0.000000
148.460007,-0.131821,-64.319458,-0.001888,0.001912,0.048565,-0.586368,-0.029871,0.485646,-64.319458,0.047585,0.000000
148.890015,-0.116180,-64.274971,-0.001901,0.001889,0.047975,-0.516796,-0.026327,0.479749,-64.274971,0.046865,0.000000
149.320007,-0.136658,-64.363937,-0.001953,0.001858,0.047194,-0.607884,-0.030967,0.471944,-64.363937,0.046154,0.000000
149.750000,-0.140015,-64.363937,-0.001970,0.001829,0.046466,-0.622816,-0.031728,0.464660,-64.363937,0.045434,0.000000
150.180008,-0.118042,-64.408417,-0.002018,0.001793,0.045538,-0.525077,-0.026749,0.455380,-64.408417,0.044714,0.000000
150.610001,-0.102776,-64.452896,-0.002057,0.001768,0.044896,-0.457169,-0.023289,0.448963,-64.452896,0.044003,0.000000
151.040009,-0.103523,-64.363937,-0.002070,0.001744,0.044289,-0.460494,-0.023459,0.442892,-64.363937,0.043283,0.000000
151.470001,-0.107246,-64.408417,-0.002100,0.001713,0.043517,-0.477056,-0.024302,0.435174,-64.408417,0.042563,0.000000
151.900009,-0.132568,-64.408417,-0.002117,0.001693,0.042997,-0.589693,-0.030040,0.429971,-64.408417,0.041852,0.000000
152.330002,-0.099052,-64.497375,-0.002164,0.001652,0.041965,-0.440607,-0.022446,0.419651,-64.497375,0.041133,0.000000
152.760010,-0.115067,-64.497375,-0.002212,0.001624,0.041245,-0.511841,-0.026074,0.412453,-64.497375,0.040413,0.000000
153.190002,-0.133682,-64.497375,-0.002229,0.001604,0.040751,-0.594648,-0.030293,0.407509,-64.497375,0.039702,0.000000
153.620010,-0.130333,-64.452896,-0.002251,0.001577,0.040066,-0.579750,-0.029534,0.400658,-64.452896,0.038982,0.000000
154.050003,-0.130333,-64.497375,-0.002289,0.001538,0.039069,-0.579750,-0.029534,0.390685,-64.497375,0.038262,0.000000
154.480011,-0.082298,-64.586342,-0.002320,0.001515,0.038470,-0.366081,-0.018649,0.384701,-64.586342,0.037551,0.000000
154.910004,-0.089745,-64.586342,-0.002363,0.001483,0.037672,-0.399204,-0.020336,0.376723,-64.586342,0.036831,0.000000
155.340012,-0.096817,-64.497375,-0.002384,0.001458,0.037039,-0.430664,-0.021939,0.370392,-64.497375,0.036120,0.000000
155.770004,-0.119164,-64.497375,-0.002402,0.001443,0.036649,-0.530066,-0.027003,0.366490,-64.497375,0.035400,0.000000
156.200012,-0.091606,-64.541862,-0.002440,0.001401,0.035582,-0.407484,-0.020758,0.355823,-64.541862,0.034680,0.000000
156.630005,-0.056602,-64.541862,-0.002466,0.001372,0.034845,-0.251780,-0.012826,0.348451,-64.541862,0.033969,0.000000
157.060013,-0.061440,-64.541862,-0.002522,0.001346,0.034186,-0.273297,-0.013922,0.341860,-64.541862,0.033249,0.000000
157.490005,-0.059578,-64.541862,-0.002535,0.001318,0.033475,-0.265016,-0.013501,0.334749,-64.541862,0.032530,0.000000
157.920013,-0.093468,-64.630821,-0.002574,0.001287,0.032694,-0.415765,-0.021180,0.326944,-64.630821,0.031819,0.000000
158.350006,-0.083786,-64.630821,-0.002591,0.001261,0.032018,-0.372699,-0.018986,0.320180,-64.630821,0.031099,0.000000
158.780014,-0.071495,-64.719788,-0.002621,0.001240,0.031506,-0.318026,-0.016201,0.315063,-64.719788,0.030379,0.000000
159.210007,-0.067398,-64.630821,-0.002665,0.001210,0.030734,-0.299802,-0.015273,0.307345,-64.630821,0.029668,0.000000
159.640015,-0.091980,-64.675301,-0.002677,0.001181,0.029989,-0.409147,-0.020843,0.299887,-64.675301,0.028948,0.000000
160.070007,-0.091980,-64.675301,-0.002708,0.001148,0.029165,-0.409147,-0.020843,0.291648,-64.675301,0.028228,0.000000
160.500000,-0.089745,-64.719788,-0.002746,0.001121,0.028480,-0.399204,-0.020336,0.284797,-64.719788,0.027517,0.000000
160.930008,-0.094955,-64.719788,-0.002781,0.001094,0.027786,-0.422383,-0.021517,0.277859,-64.719788,0.026797,0.000000
161.360001,-0.067398,-64.764267,-0.002815,0.001063,0.027005,-0.299802,-0.015273,0.270054,-64.764267,0.026086,0.000000
161.790009,-0.082664,-64.675301,-0.002833,0.001037,0.026338,-0.367710,-0.018732,0.263376,-64.675301,0.025366,0.000000
162.220001,-0.088249,-64.719788,-0.002876,0.001010,0.025644,-0.392552,-0.019998,0.256439,-64.719788,0.024647,0.000000
162.650009,-0.106499,-64.764267,-0.002884,0.000982,0.024933,-0.473730,-0.024133,0.249327,-64.764267,0.023935,0.000000
163.080002,-0.111343,-64.764267,-0.002932,0.000955,0.024248,-0.495280,-0.025231,0.242476,-64.764267,0.023216,0.000000
163.510010,-0.115067,-64.764267,-0.002966,0.000928,0.023580,-0.511841,-0.026074,0.235799,-64.764267,0.022496,0.000000
163.940002,-0.074844,-64.808746,-0.002988,0.000894,0.022704,-0.332924,-0.016960,0.227040,-64.808746,0.021785,0.000000
164.370010,-0.103523,-64.808746,-0.003001,0.000867,0.022028,-0.460494,-0.023459,0.220275,-64.808746,0.021065,0.000000
164.800003,-0.112457,-64.853226,-0.003044,0.000845,0.021455,-0.500235,-0.025483,0.214552,-64.853226,0.020345,0.000000
165.230011,-0.097565,-64.853226,-0.003070,0.000811,0.020605,-0.433989,-0.022108,0.206053,-64.853226,0.019634,0.000000
165.660004,-0.087509,-64.808746,-0.003104,0.000789,0.020042,-0.389260,-0.019830,0.200416,-64.808746,0.018914,0.000000
166.090012,-0.119164,-64.808746,-0.003130,0.000754,0.019157,-0.530066,-0.027003,0.191570,-64.808746,0.018194,0.000000
166.520004,-0.123253,-64.853226,-0.003152,0.000732,0.018602,-0.548256,-0.027929,0.186020,-64.853226,0.017483,0.000000
166.950012,-0.113205,-64.897705,-0.003195,0.000693,0.017613,-0.503561,-0.025653,0.176134,-64.897705,0.016763,0.000000
167.380005,-0.122139,-64.942192,-0.003234,0.000675,0.017136,-0.543301,-0.027677,0.171364,-64.942192,0.016044,0.000000
167.810013,-0.119530,-64.897705,-0.003268,0.000638,0.016208,-0.531695,-0.027086,0.162084,-64.897705,0.015333,0.000000
168.240005,-0.136658,-64.897705,-0.003281,0.000616,0.015653,-0.607884,-0.030967,0.156534,-64.897705,0.014613,0.000000
168.670013,-0.132568,-64.942192,-0.003311,0.000606,0.015402,-0.589693,-0.030040,0.154019,-64.942192,0.013902,0.000000
169.100006,-0.123253,-64.942192,-0.003350,0.000558,0.014179,-0.548256,-0.027929,0.141791,-64.942192,0.013182,0.000000
169.530014,-0.128471,-64.942192,-0.003372,0.000529,0.013433,-0.571469,-0.029112,0.134333,-64.942192,0.012462,0.000000
169.960007,-0.119530,-64.942192,-0.003406,0.000500,0.012696,-0.531695,-0.027086,0.126962,-64.942192,0.011751,0.000000
170.390015,-0.145973,-65.031151,-0.003415,0.000486,0.012349,-0.649321,-0.033078,0.123493,-65.031151,0.011031,0.000000
170.820007,-0.132195,-65.031151,-0.003462,0.000446,0.011326,-0.588031,-0.029956,0.113260,-65.031151,0.010311,0.000000
171.250015,-0.135170,-65.031151,-0.003497,0.000420,0.010667,-0.601266,-0.030630,0.106669,-65.031151,0.009600,0.000000
171.680008,-0.126610,-64.986671,-0.003527,0.000383,0.009730,-0.563189,-0.028690,0.097303,-64.986671,0.008880,0.000000
172.110001,-0.114319,-65.031151,-0.003557,0.000355,0.009028,-0.508516,-0.025905,0.090278,-65.031151,0.008161,0.000000
172.540009,-0.139641,-65.075630,-0.003587,0.000334,0.008473,-0.621153,-0.031643,0.084728,-65.075630,0.007449,0.000000
172.970001,-0.133308,-65.120110,-0.003613,0.000306,0.007770,-0.592985,-0.030208,0.077703,-65.120110,0.006730,0.000000
173.400009,-0.119164,-65.075630,-0.003665,0.000270,0.006851,-0.530066,-0.027003,0.068511,-65.075630,0.006010,0.000000
173.830002,-0.100914,-65.075630,-0.003682,0.000244,0.006209,-0.448888,-0.022867,0.062093,-65.075630,0.005299,0.000000
174.260010,-0.105751,-65.031151,-0.003712,0.000216,0.005498,-0.470404,-0.023964,0.054982,-65.031151,0.004579,0.000000
174.690002,-0.125488,-65.075630,-0.003734,0.000199,0.005056,-0.558200,-0.028436,0.050559,-65.075630,0.003868,0.000000
175.120010,-0.113945,-65.164597,-0.003751,0.000161,0.004102,-0.506853,-0.025820,0.041020,-65.164597,0.003148,0.000000
175.550003,-0.119530,-65.164597,-0.003798,0.000129,0.003269,-0.531695,-0.027086,0.032694,-65.164597,0.002428,0.000000
175.980011,-0.112831,-65.120110,-0.003820,0.000108,0.002732,-0.501898,-0.025568,0.027318,-65.120110,0.001717,0.000000
176.410004,-0.107613,-65.120110,-0.003867,0.000075,0.001899,-0.478685,-0.024385,0.018992,-65.120110,0.000997,0.000000
176.840012,-0.122513,-65.164597,-0.003893,0.000055,0.001405,-0.544964,-0.027762,0.014049,-65.164597,0.000278,0.000000
177.270004,-0.096069,-65.209076,-0.003923,0.000020,0.000503,-0.427338,-0.021770,0.005030,-65.209076,-0.000434,0.000000
177.700012,-0.084160,-65.209076,-0.003954,0.000007,0.000182,-0.374362,-0.019071,0.001821,-65.209076,-0.000000,0.000000