File: Data/compression 35/ManualNoHeating-10-35-reverse-1-3_11182024_164242.csv
Time (sec),S:Load (lbs),S:HL1 (DIM),S:LVDT (in),S:Position (in),Ch:Position (mm),Ch:Load (N),Ch:Stress (MPa),Ch:Strain (mm/mm),Ch:HL1 (DIM),Set Point (),Cycles ()
0.110000,0.042450,-800.345764,-0.014530,-0.009429,-0.239485,0.188827,0.009619,-2.394855,-800.345764,-0.239216,0.000000
0.500000,0.001495,-800.434692,-0.014534,-0.009374,-0.238097,0.006652,0.000339,-2.380971,-800.434692,-0.237360,0.000000
0.890000,0.017502,-800.434692,-0.014409,-0.009141,-0.232182,0.077852,0.003966,-2.321821,-800.434692,-0.230856,0.000000
1.280000,0.009315,-800.390259,-0.014155,-0.008885,-0.225687,0.041437,0.002111,-2.256872,-800.390259,-0.224369,0.000000
1.670000,-0.011909,-800.479187,-0.013905,-0.008629,-0.219165,-0.052976,-0.002699,-2.191651,-800.479187,-0.217865,0.000000
2.060000,-0.040215,-800.523682,-0.013599,-0.008370,-0.212591,-0.178883,-0.009113,-2.125915,-800.523682,-0.211377,0.000000
2.450000,-0.038727,-800.479187,-0.013348,-0.008115,-0.206113,-0.172265,-0.008776,-2.061133,-800.479187,-0.204873,0.000000
2.840000,-0.007446,-800.479187,-0.013081,-0.007860,-0.199635,-0.033123,-0.001687,-1.996350,-800.479187,-0.198369,0.000000
3.230000,0.029045,-800.479187,-0.012814,-0.007607,-0.193219,0.129199,0.006582,-1.932189,-800.479187,-0.191882,0.000000
3.620000,0.006706,-800.523682,-0.012555,-0.007349,-0.186671,0.029831,0.001520,-1.866710,-800.523682,-0.185378,0.000000
4.010000,-0.017868,-800.479187,-0.012292,-0.007093,-0.180175,-0.079481,-0.004049,-1.801746,-800.479187,-0.178892,0.000000
4.400000,-0.038727,-800.568176,-0.012021,-0.006836,-0.173645,-0.172265,-0.008776,-1.736449,-800.568176,-0.172387,0.000000
4.790000,0.006332,-800.568176,-0.011753,-0.006584,-0.167236,0.028168,0.001435,-1.672363,-800.568176,-0.165883,0.000000
5.180000,0.030167,-800.434692,-0.011477,-0.006319,-0.160507,0.134188,0.006836,-1.605068,-800.434692,-0.159397,0.000000
5.570000,0.010803,-800.612610,-0.011227,-0.006076,-0.154340,0.048055,0.002448,-1.543404,-800.612610,-0.152892,0.000000
5.960001,-0.010796,-800.523682,-0.010964,-0.005817,-0.147758,-0.048021,-0.002446,-1.477578,-800.523682,-0.146388,0.000000
6.350000,-0.031273,-800.612610,-0.010705,-0.005557,-0.141149,-0.139109,-0.007087,-1.411493,-800.612610,-0.139902,0.000000
6.740000,-0.028297,-800.612610,-0.010434,-0.005298,-0.134568,-0.125873,-0.006412,-1.345682,-800.612610,-0.133396,0.000000
7.130000,-0.002602,-800.523682,-0.010167,-0.005048,-0.128228,-0.011573,-0.000590,-1.282277,-800.523682,-0.126911,0.000000
7.520000,0.047668,-800.568176,-0.009929,-0.004800,-0.121924,0.212040,0.010802,-1.219236,-800.568176,-0.120407,0.000000
7.910000,0.010056,-800.568176,-0.009649,-0.004541,-0.115333,0.044729,0.002279,-1.153333,-800.568176,-0.113901,0.000000
8.300000,-0.032394,-800.568176,-0.009382,-0.004283,-0.108795,-0.144098,-0.007341,-1.087945,-800.568176,-0.107415,0.000000
8.690001,-0.040955,-800.612610,-0.009119,-0.004028,-0.102324,-0.182175,-0.009280,-1.023239,-800.612610,-0.100911,0.000000
9.080001,0.016388,-800.523682,-0.008852,-0.003776,-0.095915,0.072897,0.003714,-0.959153,-800.523682,-0.094424,0.000000
9.470000,0.028679,-800.612610,-0.008580,-0.003505,-0.089039,0.127570,0.006499,-0.890389,-800.612610,-0.087920,0.000000
9.860001,0.027184,-800.612610,-0.008326,-0.003261,-0.082829,0.120918,0.006160,-0.828286,-800.612610,-0.081416,0.000000
10.250001,-0.002228,-800.612610,-0.008063,-0.003010,-0.076446,-0.009910,-0.000505,-0.764458,-800.612610,-0.074929,0.000000
10.640000,-0.026062,-800.657104,-0.007808,-0.002746,-0.069760,-0.115930,-0.005906,-0.697602,-800.657104,-0.068425,0.000000
11.030001,-0.023453,-800.657104,-0.007519,-0.002488,-0.063196,-0.104323,-0.005314,-0.631956,-800.657104,-0.061938,0.000000
11.420000,0.020859,-800.701599,-0.007269,-0.002238,-0.056839,0.092784,0.004727,-0.568385,-800.701599,-0.055434,0.000000
11.810000,0.056229,-800.612610,-0.007011,-0.001991,-0.050560,0.250117,0.012742,-0.505601,-800.612610,-0.048930,0.000000
12.200001,0.013039,-800.657104,-0.006756,-0.001724,-0.043796,0.057999,0.002955,-0.437958,-800.657104,-0.042442,0.000000
12.590000,-0.015266,-800.746094,-0.006472,-0.001471,-0.037360,-0.067908,-0.003459,-0.373599,-800.746094,-0.035938,0.000000
12.980000,-0.052132,-800.701599,-0.006222,-0.001212,-0.030779,-0.231893,-0.011813,-0.307788,-800.701599,-0.029451,0.000000
13.370001,0.017876,-800.746094,-0.005959,-0.000962,-0.024438,0.079515,0.004051,-0.244383,-800.746094,-0.022947,0.000000
13.760000,-0.005951,-800.701599,-0.005674,-0.000693,-0.017604,-0.026471,-0.001348,-0.176043,-800.701599,-0.016443,0.000000
14.150001,0.021225,-800.657104,-0.005428,-0.000449,-0.011396,0.094413,0.004810,-0.113956,-800.657104,-0.009956,0.000000
14.540001,-0.003723,-800.790588,-0.005161,-0.000191,-0.004840,-0.016561,-0.000844,-0.048401,-800.790588,-0.003452,0.000000
14.930000,-0.059578,-800.746094,-0.004894,0.000064,0.001638,-0.265016,-0.013501,0.016381,-800.746094,0.003035,0.000000
15.320001,-0.019730,-800.746094,-0.004639,0.000322,0.008169,-0.087762,-0.004471,0.081693,-800.746094,0.009539,0.000000
15.710001,0.150070,-800.790588,-0.004570,-0.000007,-0.000174,0.667546,0.034006,-0.001741,-800.790588,0.000033,0.000000
16.100000,0.150818,-800.746094,-0.004583,-0.000007,-0.000174,0.670871,0.034176,-0.001741,-800.746094,0.000329,0.000000
16.490002,0.155281,-800.790588,-0.004579,-0.000007,-0.000174,0.690725,0.035187,-0.001741,-800.790588,0.000980,0.000000
16.880001,0.224541,-800.790588,-0.004566,0.000018,0.000459,0.998807,0.050882,0.004587,-800.790588,0.001629,0.000000
17.270000,0.256943,-800.835022,-0.004527,0.000040,0.001014,1.142938,0.058224,0.010144,-800.835022,0.002280,0.000000
17.660002,0.358223,-800.879517,-0.004514,0.000069,0.001743,1.593455,0.081174,0.017426,-800.879517,0.002931,0.000000
18.050001,0.449081,-800.835022,-0.004501,0.000091,0.002306,1.997614,0.101763,0.023058,-800.835022,0.003581,0.000000
18.440001,0.641975,-800.879517,-0.004449,0.000121,0.003069,2.855649,0.145474,0.030688,-800.879517,0.004232,0.000000
18.830002,0.836349,-800.835022,-0.004424,0.000151,0.003824,3.720268,0.189520,0.038243,-800.835022,0.004881,0.000000
19.220001,1.006897,-800.879517,-0.004424,0.000175,0.004448,4.478901,0.228166,0.044480,-800.879517,0.005532,0.000000
19.610001,1.117119,-800.879517,-0.004381,0.000194,0.004934,4.969193,0.253143,0.049340,-800.879517,0.006183,0.000000
20.000000,1.261230,-800.790588,-0.004363,0.000214,0.005437,5.610233,0.285799,0.054366,-800.790588,0.006832,0.000000
20.390001,1.635834,-800.879517,-0.004342,0.000247,0.006278,7.276552,0.370685,0.062784,-800.879517,0.007483,0.000000
20.780001,1.965759,-800.924011,-0.004294,0.000283,0.007197,8.744134,0.445447,0.071974,-800.924011,0.008134,0.000000
21.170000,2.101677,-800.924011,-0.004268,0.000307,0.007795,9.348726,0.476247,0.077954,-800.924011,0.008784,0.000000
21.560001,2.378716,-800.924011,-0.004260,0.000335,0.008498,10.581055,0.539025,0.084978,-800.924011,0.009435,0.000000
21.950001,2.582779,-800.968506,-0.004234,0.000359,0.009131,11.488774,0.585266,0.091307,-800.968506,0.010084,0.000000
22.340000,2.834877,-800.968506,-0.004208,0.000383,0.009730,12.610163,0.642392,0.097302,-800.968506,0.010735,0.000000
22.730001,3.146179,-800.924011,-0.004182,0.000406,0.010319,13.994904,0.712934,0.103191,-800.924011,0.011386,0.000000
23.120001,3.233315,-800.879517,-0.004156,0.000422,0.010719,14.382502,0.732680,0.107188,-800.879517,0.012036,0.000000
23.510000,3.631752,-800.924011,-0.004135,0.000455,0.011559,16.154840,0.822967,0.115591,-800.924011,0.012687,0.000000
23.900002,3.588928,-800.924011,-0.004096,0.000468,0.011898,15.964350,0.813263,0.118982,-800.924011,0.013336,0.000000
24.290001,3.827248,-800.924011,-0.004074,0.000501,0.012722,17.024448,0.867267,0.127218,-800.924011,0.013987,0.000000
24.680000,4.273346,-800.924011,-0.004044,0.000533,0.013545,19.008793,0.968354,0.135454,-800.924011,0.014629,0.000000
25.070002,4.305000,-800.924011,-0.004018,0.000554,0.014074,19.149597,0.975527,0.140738,-800.924011,0.015280,0.000000
25.460001,4.538109,-800.968506,-0.003984,0.000575,0.014604,20.186516,1.028350,0.146036,-800.968506,0.015930,0.000000
25.850000,4.716476,-800.879517,-0.003958,0.000597,0.015176,20.979935,1.068769,0.151759,-800.879517,0.016581,0.000000
26.240002,5.157738,-801.057434,-0.003932,0.000636,0.016155,22.942762,1.168760,0.161554,-801.057434,0.017230,0.000000
26.630001,5.264603,-801.012939,-0.003880,0.000660,0.016753,23.418121,1.192976,0.167535,-801.012939,0.017881,0.000000
27.020000,5.383392,-801.012939,-0.003867,0.000681,0.017300,23.946526,1.219894,0.173000,-801.012939,0.018532,0.000000
27.410002,5.521545,-801.012939,-0.003833,0.000706,0.017942,24.561060,1.251200,0.179419,-801.012939,0.019182,0.000000
27.800001,5.569580,-801.057434,-0.003816,0.000727,0.018472,24.774729,1.262085,0.184718,-801.057434,0.019833,0.000000
28.190001,5.819809,-801.057434,-0.003786,0.000754,0.019156,25.887804,1.318787,0.191561,-801.057434,0.020484,0.000000
28.580002,5.999298,-801.057434,-0.003734,0.000782,0.019859,26.686211,1.359460,0.198586,-801.057434,0.021133,0.000000
28.970001,6.098351,-801.101929,-0.003725,0.000805,0.020457,27.126818,1.381906,0.204566,-801.101929,0.021784,0.000000
29.360001,6.442795,-801.101929,-0.003686,0.000839,0.021298,28.658983,1.459958,0.212984,-801.101929,0.022434,0.000000
29.750002,6.471840,-801.012939,-0.003643,0.000864,0.021940,28.788181,1.466540,0.219403,-801.012939,0.023085,0.000000
30.140001,6.374275,-801.146423,-0.003626,0.000876,0.022261,28.354193,1.444431,0.222612,-801.146423,0.023736,0.000000
30.530001,6.716484,-801.057434,-0.003587,0.000912,0.023164,29.876413,1.521977,0.231636,-801.057434,0.024385,0.000000
30.920002,6.886658,-801.101929,-0.003557,0.000941,0.023908,30.633383,1.560539,0.239084,-801.101929,0.025036,0.000000
31.310001,6.918312,-801.190918,-0.003510,0.000966,0.024534,30.774189,1.567712,0.245337,-801.190918,0.025686,0.000000
31.700001,7.012146,-801.146423,-0.003471,0.000996,0.025304,31.191584,1.588975,0.253043,-801.146423,0.026337,0.000000
32.090000,7.100777,-801.101929,-0.003454,0.001020,0.025911,31.585833,1.609059,0.259114,-801.101929,0.026988,0.000000
32.480003,7.096680,-801.101929,-0.003410,0.001047,0.026597,31.567608,1.608131,0.265972,-801.101929,0.027637,0.000000
32.870003,7.095932,-801.101929,-0.003376,0.001069,0.027153,31.564281,1.607961,0.271528,-801.101929,0.028288,0.000000
33.260002,7.060188,-801.190918,-0.003341,0.001091,0.027707,31.405287,1.599862,0.277069,-801.190918,0.028939,0.000000
33.650002,7.186050,-801.146423,-0.003320,0.001114,0.028305,31.965149,1.628382,0.283050,-801.146423,0.029580,0.000000
34.040001,7.687630,-801.235352,-0.003277,0.001148,0.029163,34.196285,1.742042,0.291634,-801.235352,0.030231,0.000000
34.430000,7.307816,-801.235352,-0.003221,0.001170,0.029710,32.506786,1.655975,0.297099,-801.235352,0.030882,0.000000
34.820004,7.559906,-801.235352,-0.003208,0.001202,0.030526,33.628143,1.713099,0.305259,-801.235352,0.031531,0.000000
35.210003,7.295151,-801.279846,-0.003165,0.001220,0.030977,32.450451,1.653105,0.309771,-801.279846,0.032182,0.000000
35.600002,7.117531,-801.235352,-0.003152,0.001240,0.031489,31.660358,1.612855,0.314888,-801.235352,0.032832,0.000000
35.990002,7.631775,-801.235352,-0.003104,0.001271,0.032278,33.947830,1.729385,0.322776,-801.235352,0.033483,0.000000
36.380001,7.572197,-801.324341,-0.003057,0.001302,0.033075,33.682816,1.715884,0.330754,-801.324341,0.034134,0.000000
36.770000,7.436653,-801.279846,-0.003022,0.001329,0.033760,33.079884,1.685170,0.337597,-801.279846,0.034783,0.000000
37.160004,7.356964,-801.324341,-0.002992,0.001347,0.034220,32.725410,1.667112,0.342200,-801.324341,0.035434,0.000000
37.550003,7.243393,-801.235352,-0.002962,0.001366,0.034688,32.220222,1.641376,0.346878,-801.235352,0.036085,0.000000
37.940002,7.806419,-801.324341,-0.002936,0.001401,0.035590,34.724689,1.768960,0.355901,-801.324341,0.036735,0.000000
38.330002,7.669388,-801.324341,-0.002871,0.001428,0.036267,34.115139,1.737908,0.362669,-801.324341,0.037386,0.000000
38.720001,7.476494,-801.279846,-0.002850,0.001445,0.036692,33.257107,1.694198,0.366923,-801.279846,0.038035,0.000000
39.110001,7.740135,-801.368835,-0.002815,0.001476,0.037481,34.429840,1.753940,0.374811,-801.368835,0.038686,0.000000
39.500000,7.434792,-801.279846,-0.002785,0.001490,0.037853,33.071606,1.684748,0.378535,-801.279846,0.039337,0.000000
39.890003,7.946060,-801.413269,-0.002746,0.001531,0.038886,35.345840,1.800603,0.388860,-801.413269,0.039987,0.000000
40.280003,7.804184,-801.368835,-0.002690,0.001558,0.039570,34.714745,1.768453,0.395703,-801.368835,0.040638,0.000000
40.670002,7.642944,-801.368835,-0.002686,0.001579,0.040100,33.997513,1.731916,0.401002,-801.368835,0.041287,0.000000
41.060001,7.860413,-801.457764,-0.002630,0.001605,0.040768,34.964863,1.781195,0.407679,-801.457764,0.041938,0.000000
41.450001,7.747955,-801.368835,-0.002596,0.001627,0.041322,34.464626,1.755712,0.413220,-801.368835,0.042589,0.000000
41.840000,7.760246,-801.457764,-0.002557,0.001646,0.041799,34.519299,1.758497,0.417989,-801.457764,0.043239,0.000000
42.230003,8.239861,-801.457764,-0.002518,0.001692,0.042978,36.652729,1.867179,0.429782,-801.457764,0.043890,0.000000
42.620003,8.145653,-801.324341,-0.002475,0.001718,0.043638,36.233673,1.845831,0.436383,-801.324341,0.044532,0.000000
43.010002,7.913666,-801.457764,-0.002453,0.001740,0.044202,35.201744,1.793262,0.442015,-801.457764,0.045181,0.000000
43.400002,8.139694,-801.413269,-0.002406,0.001768,0.044904,36.207169,1.844481,0.449040,-801.413269,0.045832,0.000000
43.790001,8.099480,-801.502258,-0.002389,0.001790,0.045460,36.028286,1.835368,0.454596,-801.502258,0.046483,0.000000
44.180000,8.074524,-801.502258,-0.002337,0.001812,0.046014,35.917274,1.829713,0.460137,-801.502258,0.047133,0.000000
44.570004,7.978081,-801.457764,-0.002315,0.001826,0.046370,35.488277,1.807859,0.463695,-801.457764,0.047784,0.000000
44.960003,8.376518,-801.502258,-0.002281,0.001861,0.047272,37.260612,1.898146,0.472718,-801.502258,0.048435,0.000000
45.350002,8.523979,-801.457764,-0.002251,0.001889,0.047991,37.916553,1.931561,0.479910,-801.457764,0.049084,0.000000
45.740002,8.700859,-801.591248,-0.002225,0.001917,0.048686,38.703354,1.971643,0.486859,-801.591248,0.049735,0.000000
46.130001,8.348595,-801.502258,-0.002164,0.001935,0.049145,37.136402,1.891819,0.491446,-801.502258,0.050385,0.000000
46.520000,8.321411,-801.502258,-0.002143,0.001957,0.049709,37.015484,1.885659,0.497093,-801.502258,0.051036,0.000000
46.910004,8.452110,-801.591248,-0.002121,0.001984,0.050403,37.596863,1.915275,0.504027,-801.591248,0.051687,0.000000
47.300003,8.761185,-801.591248,-0.002070,0.002014,0.051166,38.971695,1.985313,0.511657,-801.591248,0.052336,0.000000
47.690002,8.639046,-801.635681,-0.002035,0.002040,0.051817,38.428394,1.957636,0.518167,-801.635681,0.052987,0.000000
48.080002,8.558983,-801.502258,-0.001992,0.002066,0.052466,38.072258,1.939493,0.524662,-801.502258,0.053637,0.000000
48.470001,8.542603,-801.546753,-0.001957,0.002089,0.053057,37.999393,1.935781,0.530567,-801.546753,0.054288,0.000000
48.860001,8.558609,-801.591248,-0.001936,0.002115,0.053732,38.070595,1.939409,0.537319,-801.591248,0.054939,0.000000
49.250004,8.210068,-801.546753,-0.001901,0.002128,0.054053,36.520206,1.860428,0.540528,-801.546753,0.055588,0.000000
49.640003,8.916832,-801.591248,-0.001863,0.002167,0.055041,39.664051,2.020583,0.550415,-801.591248,0.056239,0.000000
50.030003,8.799911,-801.591248,-0.001815,0.002196,0.055788,39.143963,1.994088,0.557878,-801.591248,0.056890,0.000000
50.420002,9.068390,-801.591248,-0.001785,0.002222,0.056439,40.338211,2.054927,0.564388,-801.591248,0.057539,0.000000
50.810001,8.768631,-801.635681,-0.001755,0.002244,0.057002,39.004818,1.987000,0.570020,-801.635681,0.058190,0.000000
51.200001,8.738464,-801.635681,-0.001699,0.002267,0.057574,38.870632,1.980164,0.575743,-801.635681,0.058840,0.000000
51.590004,9.137650,-801.680176,-0.001677,0.002298,0.058372,40.646294,2.070621,0.583722,-801.680176,0.059482,0.000000
51.980003,8.962639,-801.635681,-0.001647,0.002323,0.059005,39.867809,2.030963,0.590050,-801.635681,0.060133,0.000000
52.370003,8.952583,-801.724670,-0.001617,0.002349,0.059656,39.823078,2.028684,0.596560,-801.724670,0.060782,0.000000
52.760002,8.756340,-801.724670,-0.001574,0.002368,0.060150,38.950146,1.984215,0.601496,-801.724670,0.061433,0.000000
53.150002,8.955185,-801.635681,-0.001535,0.002400,0.060947,39.834652,2.029274,0.609474,-801.635681,0.062084,0.000000
53.540001,9.270958,-801.724670,-0.001496,0.002430,0.061710,41.239281,2.100829,0.617104,-801.724670,0.062734,0.000000
53.930004,9.090729,-801.680176,-0.001444,0.002451,0.062249,40.437580,2.059988,0.622494,-801.680176,0.063385,0.000000
54.320004,8.967476,-801.724670,-0.001427,0.002472,0.062778,39.889324,2.032059,0.627778,-801.724670,0.064036,0.000000
54.710003,8.989822,-801.769165,-0.001397,0.002495,0.063376,39.988728,2.037123,0.633758,-801.769165,0.064685,0.000000
55.100002,9.034874,-801.769165,-0.001380,0.002517,0.063941,40.189125,2.047332,0.639405,-801.769165,0.065336,0.000000
55.490002,9.841064,-801.724670,-0.001324,0.002558,0.064972,43.775242,2.230017,0.649715,-801.724670,0.065986,0.000000
55.880001,9.469437,-801.813599,-0.001285,0.002581,0.065562,42.122158,2.145805,0.655620,-801.813599,0.066637,0.000000
56.270004,9.672005,-801.769165,-0.001250,0.002606,0.066195,43.023224,2.191708,0.661948,-801.769165,0.067288,0.000000
56.660004,9.330910,-801.858093,-0.001233,0.002622,0.066602,41.505959,2.114414,0.666020,-801.858093,0.067937,0.000000
57.050003,9.402405,-801.813599,-0.001190,0.002640,0.067062,41.823986,2.130615,0.670623,-801.813599,0.068588,0.000000
57.440002,10.095390,-801.769165,-0.001160,0.002680,0.068068,44.906540,2.287648,0.680676,-801.769165,0.069238,0.000000
57.830002,10.710556,-801.902588,-0.001104,0.002717,0.069005,47.642933,2.427047,0.690047,-801.902588,0.069889,0.000000
58.220001,10.013474,-801.858093,-0.001086,0.002729,0.069326,44.542156,2.269086,0.693256,-801.858093,0.070540,0.000000
58.610004,10.268173,-801.902588,-0.001069,0.002755,0.069968,45.675117,2.326801,0.699676,-801.902588,0.071189,0.000000
59.000004,10.650970,-801.858093,-0.001030,0.002779,0.070575,47.377884,2.413544,0.705747,-801.858093,0.071840,0.000000
59.390003,11.302628,-801.858093,-0.000987,0.002814,0.071475,50.276600,2.561212,0.714755,-801.858093,0.072491,0.000000
59.780003,10.908279,-801.902588,-0.000966,0.002833,0.071961,48.522449,2.471852,0.719615,-801.902588,0.073141,0.000000
60.170002,11.217354,-801.858093,-0.000936,0.002856,0.072552,49.897282,2.541889,0.725519,-801.858093,0.073792,0.000000
60.560001,11.239319,-801.947083,-0.000910,0.002880,0.073159,49.994987,2.546866,0.731590,-801.947083,0.074434,0.000000
60.950005,11.720055,-801.947083,-0.000871,0.002906,0.073818,52.133408,2.655802,0.738176,-801.947083,0.075083,0.000000
61.340004,12.212700,-801.902588,-0.000849,0.002941,0.074702,54.324802,2.767437,0.747017,-801.902588,0.075734,0.000000
61.730003,11.769577,-801.947083,-0.000798,0.002960,0.075179,52.353695,2.667024,0.751786,-801.947083,0.076385,0.000000
62.120003,12.079391,-801.902588,-0.000785,0.002983,0.075769,53.731815,2.737229,0.757691,-801.902588,0.077035,0.000000
62.510002,12.310265,-801.902588,-0.000755,0.003011,0.076472,54.758793,2.789546,0.764715,-801.902588,0.077686,0.000000
62.900002,12.630875,-801.902588,-0.000724,0.003032,0.077009,56.184937,2.862197,0.770090,-801.902588,0.078335,0.000000
63.290005,13.758049,-801.902588,-0.000698,0.003068,0.077919,61.198860,3.117619,0.779189,-801.902588,0.078986,0.000000
63.680004,13.425522,-801.902588,-0.000655,0.003092,0.078526,59.719704,3.042267,0.785260,-801.902588,0.079637,0.000000
64.070000,13.891357,-801.947083,-0.000629,0.003124,0.079359,61.791843,3.147827,0.793586,-801.947083,0.080287,0.000000
64.460007,14.090576,-801.991577,-0.000595,0.003151,0.080044,62.678013,3.192970,0.800445,-801.991577,0.080938,0.000000
64.850006,14.429810,-801.947083,-0.000573,0.003174,0.080608,64.186996,3.269842,0.806077,-801.947083,0.081587,0.000000
65.240005,14.649139,-801.991577,-0.000560,0.003196,0.081189,65.162628,3.319542,0.811890,-801.991577,0.082238,0.000000
65.630005,14.517319,-801.991577,-0.000530,0.003210,0.081545,64.576256,3.289671,0.815448,-801.991577,0.082889,0.000000
66.020004,15.622520,-801.991577,-0.000509,0.003241,0.082317,69.492439,3.540114,0.823169,-801.991577,0.083539,0.000000
66.410004,15.924881,-801.947083,-0.000479,0.003269,0.083027,70.837410,3.608630,0.830270,-801.947083,0.084190,0.000000
66.800003,16.337097,-802.036011,-0.000448,0.003291,0.083583,72.671036,3.702039,0.835826,-802.036011,0.084841,0.000000
67.190002,17.069183,-801.947083,-0.000427,0.003322,0.084371,75.927521,3.867932,0.843714,-801.947083,0.085490,0.000000
67.580002,16.834221,-801.991577,-0.000388,0.003338,0.084779,74.882355,3.814689,0.847786,-801.991577,0.086141,0.000000
67.970001,17.747650,-802.036011,-0.000371,0.003367,0.085516,78.945488,4.021675,0.855159,-802.036011,0.086791,0.000000
68.360001,18.314026,-802.036011,-0.000366,0.003392,0.086149,81.464859,4.150017,0.861488,-802.036011,0.087442,0.000000
68.750000,19.036804,-802.036011,-0.000328,0.003422,0.086921,84.679932,4.313801,0.869209,-802.036011,0.088093,0.000000
69.140007,19.989326,-801.991577,-0.000315,0.003450,0.087623,88.916962,4.529646,0.876233,-801.991577,0.088742,0.000000
69.530006,20.046677,-802.125000,-0.000276,0.003470,0.088135,89.172073,4.542642,0.881351,-802.125000,0.089384,0.000000
69.920006,21.281464,-802.036011,-0.000263,0.003502,0.088942,94.664680,4.822449,0.889420,-802.036011,0.090035,0.000000
70.310005,21.640053,-802.125000,-0.000233,0.003524,0.089498,96.259766,4.903706,0.894976,-802.125000,0.090685,0.000000
70.700005,22.214996,-802.125000,-0.000229,0.003547,0.090105,98.817238,5.033990,0.901047,-802.125000,0.091336,0.000000
71.090004,23.880249,-802.125000,-0.000207,0.003577,0.090868,106.224655,5.411342,0.908678,-802.125000,0.091987,0.000000
71.480003,24.082077,-802.125000,-0.000190,0.003597,0.091352,107.122429,5.457077,0.913522,-802.125000,0.092636,0.000000
71.870003,24.857727,-802.169495,-0.000142,0.003624,0.092038,110.572693,5.632842,0.920380,-802.169495,0.093287,0.000000
72.260002,26.098099,-802.125000,-0.000134,0.003650,0.092722,116.090141,5.913914,0.927224,-802.125000,0.093937,0.000000
72.650002,26.660385,-802.125000,-0.000125,0.003671,0.093234,118.591316,6.041330,0.932341,-802.125000,0.094588,0.000000
73.040001,28.473465,-802.125000,-0.000091,0.003705,0.094111,126.656296,6.452179,0.941107,-802.125000,0.095239,0.000000
73.430000,28.811577,-802.213928,-0.000086,0.003723,0.094562,128.160294,6.528797,0.945618,-802.213928,0.095888,0.000000
73.820000,30.073921,-802.169495,-0.000056,0.003755,0.095369,133.775482,6.814848,0.953688,-802.169495,0.096539,0.000000
74.210007,31.716080,-802.169495,-0.000060,0.003785,0.096148,141.080170,7.186966,0.961484,-802.169495,0.097189,0.000000
74.600006,32.029251,-802.258423,-0.000043,0.003804,0.096625,142.473221,7.257932,0.966253,-802.258423,0.097840,0.000000
74.990005,34.109695,-802.213928,-0.000004,0.003835,0.097407,151.727509,7.729368,0.974065,-802.213928,0.098491,0.000000
75.380005,35.169464,-802.302917,0.000013,0.003861,0.098074,156.441589,7.969514,0.980742,-802.302917,0.099140,0.000000
75.770004,36.197212,-802.213928,0.000030,0.003880,0.098542,161.013245,8.202405,0.985420,-802.213928,0.099791,0.000000
76.160004,37.513176,-802.213928,0.000039,0.003906,0.099201,166.866943,8.500607,0.992006,-802.213928,0.100442,0.000000
76.550003,39.017189,-802.302917,0.000034,0.003936,0.099973,173.557129,8.841421,0.999727,-802.302917,0.101092,0.000000
76.940002,41.116257,-802.258423,0.000060,0.003962,0.100640,182.894241,9.317077,1.006404,-802.258423,0.101743,0.000000
77.330002,42.004738,-802.302917,0.000060,0.003983,0.101170,186.846405,9.518410,1.011702,-802.302917,0.102392,0.000000
77.720001,43.980911,-802.302917,0.000091,0.004013,0.101942,195.636871,9.966217,1.019424,-802.302917,0.103043,0.000000
78.110001,44.790825,-802.258423,0.000095,0.004030,0.102366,199.239532,10.149746,1.023663,-802.258423,0.103694,0.000000
78.500000,45.604462,-802.347412,0.000116,0.004050,0.102861,202.858780,10.334119,1.028613,-802.347412,0.104343,0.000000
78.890007,48.969215,-802.302917,0.000121,0.004087,0.103806,217.825943,11.096582,1.038060,-802.302917,0.104985,0.000000
79.280006,51.273460,-802.302917,0.000147,0.004118,0.104604,228.075745,11.618731,1.046039,-802.302917,0.105636,0.000000
79.670006,52.410683,-802.347412,0.000155,0.004142,0.105194,233.134354,11.876431,1.051943,-802.347412,0.106286,0.000000
80.060005,53.069778,-802.347412,0.000168,0.004153,0.105497,236.066162,12.025784,1.054971,-802.347412,0.106937,0.000000
80.450005,54.806152,-802.436340,0.000164,0.004177,0.106104,243.789948,12.419252,1.061042,-802.436340,0.107588,0.000000
80.840004,58.182083,-802.391846,0.000177,0.004217,0.107119,258.806824,13.184249,1.071186,-802.391846,0.108237,0.000000
81.230003,59.114502,-802.302917,0.000185,0.004232,0.107493,262.954437,13.395538,1.074925,-802.302917,0.108888,0.000000
81.620003,61.254898,-802.391846,0.000203,0.004260,0.108203,272.475403,13.880559,1.082026,-802.391846,0.109538,0.000000
82.010002,62.867271,-802.391846,0.000190,0.004282,0.108767,279.647583,14.245928,1.087673,-802.391846,0.110189,0.000000
82.400002,65.655602,-802.480835,0.000216,0.004317,0.109642,292.050690,14.877772,1.096424,-802.480835,0.110840,0.000000
82.790001,65.852211,-802.436340,0.000237,0.004316,0.109617,292.925262,14.922324,1.096166,-802.436340,0.019239,0.000000
83.180000,65.238914,-802.436340,0.000224,0.004315,0.109608,290.197174,14.783349,1.096075,-802.436340,294.500488,0.000000
83.570007,64.690041,-802.480835,0.000237,0.004316,0.109617,287.755676,14.658973,1.096166,-802.480835,294.500488,0.000000
83.960007,66.227562,-802.391846,0.000246,0.004320,0.109721,294.594910,15.007380,1.097211,-802.391846,294.500488,0.000000
84.350006,65.851097,-802.569824,0.000250,0.004320,0.109721,292.920319,14.922072,1.097211,-802.569824,294.500488,0.000000
84.740005,65.478355,-802.569824,0.000241,0.004320,0.109738,291.262268,14.837607,1.097377,-802.569824,294.500488,0.000000
85.130005,65.164070,-802.480835,0.000246,0.004323,0.109807,289.864258,14.766389,1.098074,-802.480835,294.500488,0.000000
85.520004,65.185661,-802.569824,0.000250,0.004336,0.110137,289.960297,14.771281,1.101374,-802.569824,294.500488,0.000000
85.910004,65.203911,-802.525330,0.000246,0.004339,0.110215,290.041473,14.775417,1.102146,-802.525330,294.500488,0.000000
86.300003,65.050499,-802.525330,0.000241,0.004339,0.110215,289.359070,14.740654,1.102146,-802.525330,294.500488,0.000000
86.690002,65.513359,-802.480835,0.000254,0.004348,0.110431,291.417969,14.845539,1.104311,-802.480835,294.500488,0.000000
87.080002,65.513725,-802.525330,0.000263,0.004347,0.110424,291.419617,14.845622,1.104236,-802.525330,294.500488,0.000000
87.470001,65.405357,-802.569824,0.000250,0.004347,0.110424,290.937561,14.821066,1.104236,-802.569824,294.500488,0.000000
87.860001,65.299980,-802.569824,0.000272,0.004347,0.110424,290.468811,14.797187,1.104236,-802.569824,294.500488,0.000000
88.250008,65.216576,-802.569824,0.000254,0.004348,0.110431,290.097809,14.778287,1.104311,-802.569824,294.500488,0.000000
88.640007,65.073952,-802.614258,0.000263,0.004348,0.110431,289.463379,14.745968,1.104311,-802.614258,294.500488,0.000000
89.030006,65.122368,-802.614258,0.000267,0.004350,0.110493,289.678772,14.756939,1.104932,-802.614258,294.500488,0.000000
89.420006,65.057198,-802.614258,0.000259,0.004350,0.110493,289.388855,14.742171,1.104932,-802.614258,294.500488,0.000000
89.810005,65.095924,-802.569824,0.000276,0.004352,0.110536,289.561127,14.750948,1.105356,-802.569824,294.500488,0.000000
90.200005,65.101875,-802.614258,0.000263,0.004354,0.110589,289.587616,14.752295,1.105886,-802.614258,294.500488,0.000000
90.590004,65.177467,-802.614258,0.000276,0.004355,0.110605,289.923859,14.769425,1.106052,-802.614258,294.500488,0.000000
90.980003,65.145821,-802.569824,0.000263,0.004355,0.110605,289.783081,14.762254,1.106052,-802.569824,294.500488,0.000000
91.370003,65.114906,-802.614258,0.000259,0.004355,0.110614,289.645569,14.755248,1.106143,-802.614258,294.500488,0.000000
91.760002,65.059059,-802.614258,0.000272,0.004355,0.110622,289.397156,14.742594,1.106219,-802.614258,294.500488,0.000000
92.150002,65.011391,-802.569824,0.000267,0.004355,0.110622,289.185120,14.731791,1.106219,-802.569824,294.500488,0.000000
92.540001,64.975273,-802.658752,0.000276,0.004355,0.110622,289.024445,14.723607,1.106219,-802.658752,294.500488,0.000000
92.930008,64.967079,-802.569824,0.000259,0.004357,0.110666,288.988007,14.721750,1.106658,-802.569824,294.500488,0.000000
93.320007,64.948463,-802.658752,0.000272,0.004357,0.110666,288.905182,14.717532,1.106658,-802.658752,294.500488,0.000000
93.710007,64.899315,-802.658752,0.000280,0.004357,0.110666,288.686584,14.706395,1.106658,-802.658752,294.500488,0.000000
94.100006,64.877342,-802.658752,0.000276,0.004361,0.110770,288.588837,14.701416,1.107702,-802.658752,294.500488,0.000000
94.490005,65.094429,-802.658752,0.000280,0.004361,0.110770,289.554474,14.750608,1.107702,-802.658752,294.500488,0.000000
94.880005,65.104866,-802.658752,0.000267,0.004361,0.110770,289.600922,14.752974,1.107702,-802.658752,294.500488,0.000000
95.270004,65.059425,-802.747742,0.000263,0.004361,0.110770,289.398773,14.742677,1.107702,-802.747742,294.500488,0.000000
95.660004,65.037468,-802.658752,0.000276,0.004361,0.110770,289.301117,14.737701,1.107702,-802.658752,294.500488,0.000000
96.050003,65.009529,-802.658752,0.000272,0.004361,0.110770,289.176819,14.731370,1.107702,-802.658752,294.500488,0.000000
96.440002,64.971916,-802.747742,0.000267,0.004361,0.110770,289.009521,14.722846,1.107702,-802.747742,294.500488,0.000000
96.830002,65.604210,-802.703247,0.000280,0.004369,0.110961,291.822113,14.866126,1.109610,-802.703247,294.500488,0.000000
97.220001,65.610909,-802.747742,0.000276,0.004369,0.110961,291.851898,14.867644,1.109610,-802.747742,294.500488,0.000000
97.610008,65.604210,-802.792175,0.000285,0.004369,0.110961,291.822113,14.866126,1.109610,-802.792175,294.500488,0.000000
98.000008,65.587822,-802.703247,0.000272,0.004369,0.110961,291.749207,14.862412,1.109610,-802.703247,294.500488,0.000000
98.390007,65.563988,-802.792175,0.000285,0.004369,0.110961,291.643188,14.857012,1.109610,-802.792175,294.500488,0.000000
98.780006,65.537560,-802.747742,0.000280,0.004369,0.110961,291.525635,14.851024,1.109610,-802.747742,294.500488,0.000000
99.170006,65.527138,-802.747742,0.000285,0.004369,0.110961,291.479279,14.848661,1.109610,-802.747742,294.500488,0.000000
99.560005,65.502556,-802.836670,0.000280,0.004369,0.110961,291.369934,14.843092,1.109610,-802.836670,294.500488,0.000000
99.950005,65.462334,-802.703247,0.000276,0.004369,0.110961,291.191010,14.833977,1.109610,-802.703247,294.500488,0.000000
100.340004,65.415794,-802.747742,0.000272,0.004369,0.110961,290.983978,14.823431,1.109610,-802.747742,294.500488,0.000000
100.730003,65.372963,-802.792175,0.000293,0.004369,0.110961,290.793457,14.813725,1.109610,-802.792175,294.500488,0.000000
101.120003,65.339455,-802.792175,0.000272,0.004369,0.110961,290.644409,14.806131,1.109610,-802.792175,294.500488,0.000000
101.510002,65.331642,-802.836670,0.000285,0.004369,0.110961,290.609650,14.804361,1.109610,-802.836670,294.500488,0.000000
101.900002,65.305199,-802.792175,0.000285,0.004369,0.110961,290.492035,14.798369,1.109610,-802.792175,294.500488,0.000000
102.290009,65.272423,-802.836670,0.000285,0.004369,0.110961,290.346252,14.790943,1.109610,-802.836670,294.500488,0.000000
102.680008,65.251198,-802.836670,0.000280,0.004369,0.110961,290.251831,14.786133,1.109610,-802.836670,294.500488,0.000000
103.070007,65.231834,-802.792175,0.000285,0.004369,0.110961,290.165680,14.781745,1.109610,-802.792175,294.500488,0.000000
103.460007,65.201683,-802.881165,0.000267,0.004369,0.110961,290.031586,14.774913,1.109610,-802.881165,294.500488,0.000000
103.850006,65.161461,-802.836670,0.000276,0.004369,0.110961,289.852661,14.765799,1.109610,-802.836670,294.500488,0.000000
104.240005,65.121986,-802.836670,0.000276,0.004369,0.110961,289.677063,14.756853,1.109610,-802.836670,294.500488,0.000000
104.630005,65.082893,-802.881165,0.000280,0.004369,0.110961,289.503174,14.747994,1.109610,-802.881165,294.500488,0.000000
105.020004,65.059807,-802.836670,0.000276,0.004369,0.110961,289.400482,14.742763,1.109610,-802.836670,294.500488,0.000000
105.410004,65.043785,-802.925659,0.000276,0.004369,0.110961,289.329193,14.739132,1.109610,-802.925659,294.500488,0.000000
105.800003,65.014366,-802.881165,0.000297,0.004369,0.110961,289.198334,14.732466,1.109610,-802.881165,294.500488,0.000000
106.190002,64.991661,-802.881165,0.000285,0.004369,0.110961,289.097351,14.727321,1.109610,-802.881165,294.500488,0.000000
106.580002,64.973045,-802.970154,0.000280,0.004369,0.110970,289.014526,14.723103,1.109701,-802.970154,294.500488,0.000000
106.970009,64.949577,-802.881165,0.000267,0.004369,0.110970,288.910156,14.717784,1.109701,-802.881165,294.500488,0.000000
107.360008,64.890007,-802.970154,0.000267,0.004369,0.110970,288.645172,14.704286,1.109701,-802.970154,294.500488,0.000000
107.750008,64.882927,-802.881165,0.000289,0.004369,0.110970,288.613678,14.702682,1.109701,-802.881165,294.500488,0.000000
108.140007,64.852760,-802.970154,0.000276,0.004369,0.110970,288.479492,14.695846,1.109701,-802.970154,294.500488,0.000000
108.530006,64.818504,-802.970154,0.000289,0.004369,0.110970,288.327118,14.688084,1.109701,-802.970154,294.500488,0.000000
108.920006,64.786110,-802.881165,0.000280,0.004369,0.110970,288.183014,14.680742,1.109701,-802.881165,294.500488,0.000000
109.310005,64.783134,-803.014587,0.000272,0.004369,0.110970,288.169769,14.680068,1.109701,-803.014587,294.500488,0.000000
109.700005,64.754829,-802.970154,0.000272,0.004369,0.110970,288.043854,14.673655,1.109701,-802.970154,294.500488,0.000000
110.090004,64.721687,-802.881165,0.000276,0.004369,0.110970,287.896454,14.666143,1.109701,-802.881165,294.500488,0.000000
110.480003,64.720192,-803.014587,0.000293,0.004369,0.110970,287.889801,14.665805,1.109701,-803.014587,294.500488,0.000000
110.870003,64.683327,-802.970154,0.000289,0.004369,0.110978,287.725800,14.657451,1.109777,-802.970154,294.500488,0.000000
111.260002,64.652794,-803.014587,0.000285,0.004369,0.110978,287.589996,14.650533,1.109777,-803.014587,294.500488,0.000000
111.650002,64.628593,-802.970154,0.000285,0.004369,0.110978,287.482330,14.645049,1.109777,-802.970154,294.500488,0.000000
112.040009,65.872322,-803.014587,0.000289,0.004382,0.111308,293.014709,14.926882,1.113077,-803.014587,294.500488,0.000000
112.430008,65.858910,-803.014587,0.000285,0.004382,0.111308,292.955048,14.923842,1.113077,-803.014587,294.500488,0.000000
112.820007,65.864128,-802.970154,0.000285,0.004382,0.111308,292.978271,14.925024,1.113077,-802.970154,294.500488,0.000000
113.210007,65.866356,-803.014587,0.000267,0.004382,0.111308,292.988190,14.925529,1.113077,-803.014587,294.500488,0.000000
113.600006,65.886848,-803.059082,0.000293,0.004382,0.111308,293.079346,14.930174,1.113077,-803.059082,294.500488,0.000000
113.990005,65.908806,-803.014587,0.000285,0.004382,0.111308,293.177002,14.935149,1.113077,-803.014587,294.500488,0.000000
114.380005,65.857048,-803.059082,0.000289,0.004382,0.111308,292.946777,14.923420,1.113077,-803.059082,294.500488,0.000000
114.770004,65.876045,-803.014587,0.000276,0.004382,0.111308,293.031281,14.927725,1.113077,-803.014587,294.500488,0.000000
115.160004,65.860771,-803.059082,0.000289,0.004382,0.111308,292.963348,14.924264,1.113077,-803.059082,294.500488,0.000000
115.550003,65.853325,-803.103577,0.000293,0.004382,0.111308,292.930206,14.922577,1.113077,-803.103577,294.500488,0.000000
115.940002,65.827629,-803.059082,0.000293,0.004382,0.111308,292.815918,14.916754,1.113077,-803.059082,294.500488,0.000000
116.330002,65.838066,-803.103577,0.000289,0.004382,0.111308,292.862335,14.919119,1.113077,-803.103577,294.500488,0.000000
116.720009,65.857048,-803.059082,0.000285,0.004382,0.111308,292.946777,14.923420,1.113077,-803.059082,294.500488,0.000000
117.110008,65.855186,-803.103577,0.000272,0.004382,0.111308,292.938507,14.922998,1.113077,-803.103577,294.500488,0.000000
117.500008,65.849236,-803.103577,0.000289,0.004382,0.111308,292.912018,14.921650,1.113077,-803.103577,294.500488,0.000000
117.890007,65.842155,-803.148071,0.000280,0.004382,0.111308,292.880524,14.920046,1.113077,-803.148071,294.500488,0.000000
118.280006,65.804924,-803.059082,0.000297,0.004382,0.111308,292.714935,14.911610,1.113077,-803.059082,294.500488,0.000000
118.670006,65.781090,-803.103577,0.000293,0.004382,0.111308,292.608887,14.906208,1.113077,-803.103577,294.500488,0.000000
119.060005,65.764702,-803.148071,0.000289,0.004382,0.111308,292.536011,14.902494,1.113077,-803.148071,294.500488,0.000000
119.450005,65.758369,-803.192505,0.000289,0.004382,0.111308,292.507843,14.901059,1.113077,-803.192505,294.500488,0.000000
119.840004,65.759483,-803.103577,0.000293,0.004382,0.111308,292.512787,14.901312,1.113077,-803.103577,294.500488,0.000000
120.230003,65.752037,-803.192505,0.000302,0.004382,0.111308,292.479675,14.899625,1.113077,-803.192505,294.500488,0.000000
120.620003,65.674965,-803.103577,0.000302,0.004382,0.111308,292.136841,14.882160,1.113077,-803.103577,294.500488,0.000000
121.010002,65.670860,-803.148071,0.000285,0.004382,0.111308,292.118561,14.881229,1.113077,-803.148071,294.500488,0.000000
121.400009,65.661552,-803.192505,0.000297,0.004382,0.111308,292.077179,14.879121,1.113077,-803.192505,294.500488,0.000000
121.790009,65.639961,-803.192505,0.000276,0.004382,0.111308,291.981140,14.874228,1.113077,-803.192505,294.500488,0.000000
122.180008,65.613899,-803.192505,0.000289,0.004382,0.111308,291.865204,14.868322,1.113077,-803.192505,294.500488,0.000000
122.570007,65.595268,-803.237000,0.000285,0.004382,0.111308,291.782318,14.864100,1.113077,-803.237000,294.500488,0.000000
122.960007,65.586708,-803.192505,0.000302,0.004382,0.111308,291.744263,14.862160,1.113077,-803.192505,294.500488,0.000000
123.350006,65.578514,-803.237000,0.000302,0.004382,0.111308,291.707794,14.860304,1.113077,-803.237000,294.500488,0.000000
123.740005,65.577766,-803.192505,0.000297,0.004382,0.111308,291.704468,14.860134,1.113077,-803.192505,294.500488,0.000000
124.130005,65.560646,-803.281494,0.000302,0.004382,0.111308,291.628326,14.856255,1.113077,-803.281494,294.500488,0.000000
124.520004,65.568459,-803.192505,0.000293,0.004382,0.111308,291.663055,14.858025,1.113077,-803.192505,294.500488,0.000000
124.910004,65.545006,-803.281494,0.000289,0.004382,0.111308,291.558746,14.852711,1.113077,-803.281494,294.500488,0.000000
125.300003,65.548729,-803.192505,0.000306,0.004382,0.111308,291.575317,14.853555,1.113077,-803.192505,294.500488,0.000000
125.690002,65.528252,-803.237000,0.000297,0.004382,0.111308,291.484222,14.848913,1.113077,-803.237000,294.500488,0.000000
126.080009,65.504036,-803.325989,0.000285,0.004383,0.111317,291.376495,14.843427,1.113168,-803.325989,294.500488,0.000000
126.470009,65.501808,-803.237000,0.000306,0.004383,0.111317,291.366608,14.842922,1.113168,-803.237000,294.500488,0.000000
126.860008,65.486916,-803.237000,0.000306,0.004383,0.111317,291.300354,14.839547,1.113168,-803.237000,294.500488,0.000000
127.250008,65.466438,-803.325989,0.000285,0.004383,0.111317,291.209259,14.834907,1.113168,-803.325989,294.500488,0.000000
127.640007,65.470909,-803.281494,0.000306,0.004383,0.111317,291.229156,14.835919,1.113168,-803.281494,294.500488,0.000000
128.029999,65.457130,-803.281494,0.000285,0.004383,0.111317,291.167847,14.832798,1.113168,-803.281494,294.500488,0.000000
128.420013,65.428078,-803.237000,0.000302,0.004383,0.111317,291.038635,14.826214,1.113168,-803.237000,294.500488,0.000000
128.810013,65.395683,-803.281494,0.000306,0.004383,0.111317,290.894531,14.818873,1.113168,-803.281494,294.500488,0.000000
129.200012,65.391594,-803.325989,0.000297,0.004383,0.111317,290.876343,14.817947,1.113168,-803.325989,294.500488,0.000000
129.590012,65.367378,-803.325989,0.000302,0.004383,0.111317,290.768616,14.812459,1.113168,-803.325989,294.500488,0.000000
129.980011,65.347649,-803.370483,0.000297,0.004383,0.111317,290.680847,14.807989,1.113168,-803.370483,294.500488,0.000000
130.370010,65.337593,-803.370483,0.000297,0.004383,0.111317,290.636139,14.805711,1.113168,-803.370483,294.500488,0.000000
130.760010,65.318596,-803.370483,0.000280,0.004383,0.111317,290.551636,14.801406,1.113168,-803.370483,294.500488,0.000000
131.150009,65.304451,-803.370483,0.000293,0.004383,0.111317,290.488708,14.798200,1.113168,-803.370483,294.500488,0.000000
131.540009,65.306313,-803.370483,0.000310,0.004383,0.111317,290.496979,14.798622,1.113168,-803.370483,294.500488,0.000000
131.930008,65.280617,-803.414917,0.000293,0.004383,0.111317,290.382690,14.792799,1.113168,-803.414917,294.500488,0.000000
132.320007,65.274284,-803.370483,0.000302,0.004383,0.111317,290.354523,14.791364,1.113168,-803.370483,294.500488,0.000000
132.710007,65.256050,-803.370483,0.000293,0.004383,0.111317,290.273407,14.787232,1.113168,-803.370483,294.500488,0.000000
133.100006,65.249718,-803.370483,0.000285,0.004383,0.111317,290.245239,14.785798,1.113168,-803.370483,294.500488,0.000000
133.490005,65.227364,-803.325989,0.000306,0.004383,0.111317,290.145813,14.780732,1.113168,-803.325989,294.500488,0.000000
133.880005,65.212471,-803.459412,0.000302,0.004383,0.111317,290.079559,14.777357,1.113168,-803.459412,294.500488,0.000000
134.270004,65.199074,-803.414917,0.000306,0.004383,0.111317,290.019958,14.774321,1.113168,-803.414917,294.500488,0.000000
134.660004,65.185295,-803.370483,0.000289,0.004383,0.111317,289.958679,14.771199,1.113168,-803.370483,294.500488,0.000000
135.050003,65.165932,-803.414917,0.000302,0.004383,0.111317,289.872528,14.766811,1.113168,-803.414917,294.500488,0.000000
135.440002,65.130547,-803.414917,0.000302,0.004383,0.111317,289.715149,14.758793,1.113168,-803.414917,294.500488,0.000000
135.830002,65.106346,-803.503906,0.000302,0.004383,0.111317,289.607483,14.753309,1.113168,-803.503906,294.500488,0.000000
136.220001,65.117149,-803.459412,0.000293,0.004383,0.111317,289.655548,14.755756,1.113168,-803.459412,294.500488,0.000000
136.610001,65.084007,-803.459412,0.000293,0.004383,0.111317,289.508118,14.748247,1.113168,-803.459412,294.500488,0.000000
137.000000,65.079918,-803.503906,0.000297,0.004383,0.111317,289.489929,14.747320,1.113168,-803.503906,294.500488,0.000000
137.389999,65.073586,-803.503906,0.000289,0.004383,0.111317,289.461761,14.745886,1.113168,-803.503906,294.500488,0.000000
137.780014,65.046394,-803.548401,0.000285,0.004383,0.111317,289.340820,14.739723,1.113168,-803.548401,294.500488,0.000000
138.170013,65.051231,-803.459412,0.000302,0.004383,0.111317,289.362335,14.740820,1.113168,-803.459412,294.500488,0.000000
138.560013,65.050117,-803.503906,0.000302,0.004383,0.111317,289.357361,14.740567,1.113168,-803.503906,294.500488,0.000000
138.950012,65.023689,-803.503906,0.000306,0.004383,0.111317,289.239807,14.734578,1.113168,-803.503906,294.500488,0.000000
139.340012,65.014000,-803.503906,0.000285,0.004383,0.111317,289.196716,14.732384,1.113168,-803.503906,294.500488,0.000000
139.730011,65.012886,-803.548401,0.000310,0.004383,0.111317,289.191772,14.732131,1.113168,-803.548401,294.500488,0.000000
140.120010,65.011024,-803.548401,0.000306,0.004383,0.111317,289.183472,14.731709,1.113168,-803.548401,294.500488,0.000000
140.510010,64.994637,-803.592834,0.000297,0.004383,0.111317,289.110596,14.727995,1.113168,-803.592834,294.500488,0.000000
140.900009,64.987190,-803.548401,0.000302,0.004383,0.111317,289.077454,14.726308,1.113168,-803.548401,294.500488,0.000000
141.290009,64.988686,-803.592834,0.000306,0.004383,0.111317,289.084106,14.726646,1.113168,-803.592834,294.500488,0.000000
141.680008,64.974525,-803.592834,0.000289,0.004383,0.111317,289.021118,14.723438,1.113168,-803.592834,294.500488,0.000000
142.070007,64.961494,-803.592834,0.000297,0.004383,0.111317,288.963165,14.720485,1.113168,-803.592834,294.500488,0.000000
142.460007,64.950691,-803.637329,0.000285,0.004383,0.111317,288.915100,14.718037,1.113168,-803.637329,294.500488,0.000000
142.850006,64.951820,-803.592834,0.000310,0.004383,0.111317,288.920135,14.718292,1.113168,-803.592834,294.500488,0.000000
143.240005,64.943245,-803.548401,0.000289,0.004383,0.111317,288.881989,14.716350,1.113168,-803.548401,1681.640991,0.000000
143.630005,64.764137,-803.637329,0.000285,0.004370,0.111003,288.085266,14.675763,1.110034,-803.637329,0.110796,0.000000
144.020004,64.821480,-803.592834,0.000293,0.004354,0.110596,288.340332,14.688757,1.105961,-803.592834,0.110145,0.000000
144.410004,64.745522,-803.681824,0.000297,0.004331,0.110007,288.002472,14.671545,1.100072,-803.681824,0.109495,0.000000
144.800003,64.682594,-803.681824,0.000306,0.004306,0.109365,287.722534,14.657286,1.093653,-803.681824,0.108844,0.000000
145.190002,64.664711,-803.681824,0.000280,0.004281,0.108740,287.643005,14.653234,1.087400,-803.681824,0.108195,0.000000
145.580002,64.771217,-803.681824,0.000306,0.004251,0.107969,288.116760,14.677368,1.079694,-803.681824,0.107544,0.000000
145.970001,64.656517,-803.681824,0.000306,0.004230,0.107440,287.606537,14.651376,1.074395,-803.681824,0.106893,0.000000
146.360001,64.679237,-803.726318,0.000289,0.004209,0.106911,287.707611,14.656525,1.069112,-803.726318,0.106244,0.000000
146.750000,64.603279,-803.681824,0.000302,0.004181,0.106191,287.369751,14.639312,1.061905,-803.681824,0.105593,0.000000
147.139999,64.557106,-803.770813,0.000293,0.004158,0.105602,287.164337,14.628849,1.056016,-803.770813,0.104942,0.000000
147.530014,64.275963,-803.726318,0.000306,0.004136,0.105046,285.913757,14.565142,1.050460,-803.726318,0.104292,0.000000
147.920013,63.534569,-803.681824,0.000306,0.004110,0.104404,282.615875,14.397140,1.044041,-803.681824,0.103641,0.000000
148.310013,62.697098,-803.726318,0.000310,0.004089,0.103858,278.890625,14.207365,1.038575,-803.726318,0.102992,0.000000
148.700012,61.315224,-803.726318,0.000315,0.004062,0.103164,272.743744,13.894228,1.031641,-803.726318,0.102341,0.000000
149.090012,59.772858,-803.726318,0.000297,0.004039,0.102583,265.882965,13.544724,1.025828,-803.726318,0.101690,0.000000
149.480011,57.918816,-803.770813,0.000306,0.004015,0.101985,257.635773,13.124591,1.019848,-803.770813,0.101040,0.000000
149.870010,55.720703,-803.726318,0.000323,0.003987,0.101282,247.858063,12.626493,1.012823,-803.726318,0.100398,0.000000
150.260010,53.667068,-803.859741,0.000302,0.003967,0.100761,238.723038,12.161132,1.007615,-803.859741,0.099747,0.000000
150.650009,51.218719,-803.770813,0.000315,0.003943,0.100163,227.832245,11.606328,1.001635,-803.770813,0.099098,0.000000
151.040009,48.768883,-803.770813,0.000306,0.003923,0.099644,216.934830,11.051187,0.996442,-803.770813,0.098447,0.000000
151.430008,45.172134,-803.815247,0.000306,0.003890,0.098793,200.935684,10.236153,0.987933,-803.815247,0.097796,0.000000
151.820007,42.276939,-803.770813,0.000310,0.003863,0.098117,188.057220,9.580091,0.981166,-803.770813,0.097146,0.000000
152.210007,39.650597,-803.815247,0.000310,0.003839,0.097509,176.374664,8.984954,0.975095,-803.815247,0.096495,0.000000
152.600006,36.582619,-803.770813,0.000323,0.003811,0.096790,162.727615,8.289740,0.967904,-803.770813,0.095846,0.000000
152.990005,34.005798,-803.859741,0.000319,0.003788,0.096218,151.265350,7.705824,0.962181,-803.859741,0.095195,0.000000
153.380005,30.850693,-803.904236,0.000310,0.003760,0.095497,137.230728,6.990867,0.954974,-803.904236,0.094544,0.000000
153.770004,28.676407,-803.904236,0.000310,0.003739,0.094978,127.559029,6.498167,0.949782,-803.904236,0.093894,0.000000
154.160004,25.694450,-803.859741,0.000306,0.003713,0.094310,114.294624,5.822446,0.943105,-803.859741,0.093243,0.000000
154.550003,23.377174,-803.859741,0.000310,0.003688,0.093678,103.986862,5.297344,0.936777,-803.859741,0.092594,0.000000
154.940002,20.499855,-803.904236,0.000310,0.003667,0.093139,91.187912,4.645334,0.931387,-803.904236,0.091943,0.000000
155.330002,17.161903,-803.904236,0.000306,0.003637,0.092385,76.339958,3.888943,0.923847,-803.904236,0.091292,0.000000
155.720001,13.858215,-803.770813,0.000302,0.003606,0.091587,61.644421,3.140316,0.915869,-803.770813,0.090642,0.000000
156.110001,11.378960,-803.948730,0.000289,0.003586,0.091093,50.616142,2.578509,0.910933,-803.948730,0.089991,0.000000
156.500000,8.910507,-803.859741,0.000297,0.003564,0.090538,39.635914,2.019150,0.905377,-803.859741,0.089340,0.000000
156.890015,5.996689,-803.904236,0.000297,0.003534,0.089766,26.674604,1.358869,0.897656,-803.904236,0.088691,0.000000
157.280014,3.720001,-803.948730,0.000302,0.003517,0.089333,16.547392,0.842964,0.893326,-803.948730,0.088040,0.000000
157.670013,0.485207,-803.859741,0.000280,0.003482,0.088439,2.158307,0.109949,0.884394,-803.859741,0.087390,0.000000
158.060013,-0.837463,-803.948730,0.000285,0.003458,0.087840,-3.725223,-0.189772,0.878398,-803.948730,0.086739,0.000000
158.450012,-0.057716,-803.904236,0.000233,0.003432,0.087165,-0.256735,-0.013079,0.871646,-803.904236,0.086088,0.000000
158.840012,0.041336,-803.904236,0.000198,0.003407,0.086532,0.183872,0.009367,0.865318,-803.904236,0.085446,0.000000
159.230011,0.008194,-803.948730,0.000147,0.003382,0.085907,0.036449,0.001857,0.859065,-803.948730,0.084797,0.000000
159.620010,0.021225,-803.948730,0.000091,0.003355,0.085213,0.094413,0.004810,0.852131,-803.948730,0.084146,0.000000
160.010010,0.047668,-804.037659,0.000039,0.003330,0.084571,0.212040,0.010802,0.845712,-804.037659,0.083496,0.000000
160.400009,0.107994,-803.948730,-0.000034,0.003302,0.083860,0.480382,0.024472,0.838596,-803.948730,0.082845,0.000000
160.790009,0.087509,-803.993164,-0.000112,0.003277,0.083236,0.389260,0.019830,0.832359,-803.993164,0.082194,0.000000
161.180008,0.103149,-803.993164,-0.000164,0.003252,0.082611,0.458832,0.023374,0.826106,-803.993164,0.081545,0.000000
161.570007,0.101662,-803.993164,-0.000250,0.003228,0.081987,0.452214,0.023037,0.819869,-803.993164,0.080894,0.000000
161.960007,0.085274,-804.037659,-0.000332,0.003204,0.081380,0.379317,0.019323,0.813798,-804.037659,0.080244,0.000000
162.350006,0.075226,-803.993164,-0.000410,0.003177,0.080686,0.334621,0.017046,0.806864,-803.993164,0.079593,0.000000
162.740005,0.131454,-804.037659,-0.000513,0.003148,0.079958,0.584739,0.029788,0.799582,-804.037659,0.079879,0.000000
162.900009,0.145599,-804.037659,-0.000535,0.003148,0.079966,0.647658,0.032993,0.799657,-804.037659,0.079879,0.000000