File: Data/compression 35/ManualNoHeating-12-35-reverse-1-1_11182024_165017.csv
Time (sec),S:Load (lbs),S:HL1 (DIM),S:LVDT (in),S:Position (in),Ch:Position (mm),Ch:Load (N),Ch:Stress (MPa),Ch:Strain (mm/mm),Ch:HL1 (DIM),Set Point (),Cycles ()
0.110000,0.028679,-810.265015,-0.011503,-0.006985,-0.177409,0.127570,0.006499,-1.774086,-810.265015,-0.177139,0.000000
0.500000,0.007080,-810.309509,-0.011520,-0.006930,-0.176013,0.031494,0.001604,-1.760128,-810.309509,-0.175301,0.000000
0.890000,0.034264,-810.309509,-0.011365,-0.006700,-0.170184,0.152412,0.007764,-1.701840,-810.309509,-0.168797,0.000000
1.280000,-0.000000,-810.353943,-0.011111,-0.006445,-0.163698,-0.000000,-0.000000,-1.636982,-810.353943,-0.162310,0.000000
1.670000,-0.021225,-810.398437,-0.010839,-0.006188,-0.157185,-0.094413,-0.004810,-1.571852,-810.398437,-0.155806,0.000000
2.060000,-0.050270,-810.309509,-0.010580,-0.005932,-0.150681,-0.223612,-0.011391,-1.506812,-810.309509,-0.149319,0.000000
2.450000,0.012291,-810.309509,-0.010317,-0.005681,-0.144289,0.054673,0.002785,-1.442893,-810.309509,-0.142815,0.000000
2.840000,0.018250,-810.353943,-0.010046,-0.005420,-0.137664,0.081178,0.004135,-1.376642,-810.353943,-0.136311,0.000000
3.230000,0.010429,-810.353943,-0.009791,-0.005169,-0.131298,0.046392,0.002363,-1.312980,-810.353943,-0.129823,0.000000
3.620000,-0.011543,-810.442932,-0.009546,-0.004912,-0.124776,-0.051347,-0.002616,-1.247759,-810.442932,-0.123319,0.000000
4.010000,-0.023453,-810.398437,-0.009257,-0.004653,-0.118186,-0.104323,-0.005314,-1.181856,-810.398437,-0.116832,0.000000
4.400000,-0.036118,-810.265015,-0.009007,-0.004394,-0.111612,-0.160659,-0.008184,-1.116120,-810.265015,-0.110328,0.000000
4.790000,0.010429,-810.353943,-0.008718,-0.004143,-0.105220,0.046392,0.002363,-1.052201,-810.353943,-0.103824,0.000000
5.180000,0.039474,-810.353943,-0.008481,-0.003892,-0.098846,0.175591,0.008945,-0.988463,-810.353943,-0.097337,0.000000
5.570000,0.013779,-810.442932,-0.008205,-0.003631,-0.092230,0.061291,0.003122,-0.922303,-810.442932,-0.090833,0.000000
5.960001,-0.019730,-810.442932,-0.007938,-0.003374,-0.085708,-0.087762,-0.004471,-0.857082,-810.442932,-0.084347,0.000000
6.350000,-0.044678,-810.398437,-0.007683,-0.003117,-0.079160,-0.198736,-0.010124,-0.791603,-810.398437,-0.077842,0.000000
6.740000,0.001122,-810.442932,-0.007416,-0.002870,-0.072891,0.004989,0.000254,-0.728910,-810.442932,-0.071338,0.000000
7.130000,-0.016754,-810.442932,-0.007140,-0.002598,-0.065996,-0.074526,-0.003797,-0.659965,-810.442932,-0.064852,0.000000
7.520000,0.030540,-810.442932,-0.006885,-0.002352,-0.059751,0.135851,0.006921,-0.597514,-810.442932,-0.058346,0.000000
7.910000,-0.010796,-810.442932,-0.006631,-0.002098,-0.053300,-0.048021,-0.002446,-0.533004,-810.442932,-0.051842,0.000000
8.300000,-0.065163,-810.487427,-0.006342,-0.001840,-0.046734,-0.289858,-0.014766,-0.467344,-810.487427,-0.045357,0.000000
8.690001,-0.074097,-810.531860,-0.006088,-0.001583,-0.040196,-0.329598,-0.016791,-0.401956,-810.531860,-0.038851,0.000000
9.080001,-0.001862,-810.442932,-0.005833,-0.001329,-0.033752,-0.008281,-0.000422,-0.337522,-810.442932,-0.032365,0.000000
9.470000,0.011917,-810.487427,-0.005575,-0.001076,-0.027327,0.053010,0.002700,-0.273269,-810.487427,-0.025861,0.000000
9.860001,-0.018616,-810.531860,-0.005312,-0.000814,-0.020675,-0.082807,-0.004218,-0.206746,-810.531860,-0.019356,0.000000
10.250001,0.084908,-810.487427,-0.005053,-0.000561,-0.014249,0.377688,0.019240,-0.142494,-810.487427,-0.012870,0.000000
10.640000,0.253586,-810.531860,-0.005010,-0.000001,-0.000017,1.128006,0.057463,-0.000167,-810.531860,0.000244,0.000000
11.030001,0.151932,-810.487427,-0.005019,-0.000001,-0.000017,0.675826,0.034428,-0.000167,-810.487427,0.000590,0.000000
11.420000,0.117676,-810.531860,-0.005027,-0.000000,-0.000009,0.523448,0.026666,-0.000091,-810.531860,0.001240,0.000000
11.810000,0.223801,-810.576355,-0.005023,0.000034,0.000867,0.995515,0.050714,0.008675,-810.576355,0.001891,0.000000
12.200001,0.330299,-810.576355,-0.004993,0.000062,0.001570,1.469245,0.074847,0.015700,-810.576355,0.002533,0.000000
12.590000,0.389503,-810.576355,-0.004941,0.000085,0.002159,1.732598,0.088263,0.021589,-810.576355,0.003182,0.000000
12.980000,0.521698,-810.576355,-0.004937,0.000108,0.002749,2.320629,0.118218,0.027493,-810.576355,0.003833,0.000000
13.370001,0.514252,-810.665344,-0.004902,0.000127,0.003217,2.287506,0.116531,0.032172,-810.665344,0.004484,0.000000
13.760000,0.649796,-810.576355,-0.004889,0.000146,0.003712,2.890435,0.147246,0.037122,-810.576355,0.005134,0.000000
14.150001,1.004662,-810.531860,-0.004855,0.000189,0.004805,4.468958,0.227660,0.048053,-810.531860,0.005785,0.000000
14.540001,1.097015,-810.620850,-0.004825,0.000211,0.005350,4.879768,0.248587,0.053503,-810.620850,0.006434,0.000000
14.930000,1.338310,-810.576355,-0.004790,0.000234,0.005932,5.953101,0.303265,0.059317,-810.576355,0.007085,0.000000
15.320001,1.388580,-810.620850,-0.004799,0.000253,0.006434,6.176714,0.314657,0.064343,-810.620850,0.007736,0.000000
15.710001,1.686852,-810.620850,-0.004751,0.000276,0.007016,7.503490,0.382246,0.070157,-810.620850,0.008386,0.000000
16.100000,2.208916,-810.620850,-0.004747,0.000314,0.007969,9.825747,0.500547,0.079695,-810.620850,0.009037,0.000000
16.490002,2.599907,-810.665344,-0.004704,0.000345,0.008760,11.564963,0.589147,0.087598,-810.665344,0.009688,0.000000
16.880001,2.833755,-810.620850,-0.004665,0.000367,0.009314,12.605174,0.642138,0.093139,-810.620850,0.010337,0.000000
17.270000,3.020317,-810.665344,-0.004665,0.000385,0.009774,13.435041,0.684414,0.097741,-810.665344,0.010988,0.000000
17.660002,3.267944,-810.665344,-0.004631,0.000405,0.010295,14.536542,0.740527,0.102949,-810.665344,0.011638,0.000000
18.050001,3.926300,-810.709839,-0.004613,0.000443,0.011256,17.465055,0.889712,0.112563,-810.709839,0.012289,0.000000
18.440001,4.012688,-810.709839,-0.004583,0.000462,0.011742,17.849327,0.909288,0.117423,-810.709839,0.012940,0.000000
18.830002,4.262924,-810.620850,-0.004575,0.000483,0.012280,18.962435,0.965992,0.122797,-810.620850,0.013589,0.000000
19.220001,4.769722,-810.709839,-0.004553,0.000512,0.013008,21.216784,1.080834,0.130079,-810.709839,0.014240,0.000000
19.610001,5.205025,-810.709839,-0.004506,0.000539,0.013703,23.153107,1.179475,0.137028,-810.709839,0.014890,0.000000
20.000000,5.493240,-810.665344,-0.004484,0.000568,0.014431,24.435154,1.244786,0.144310,-810.665344,0.015541,0.000000
20.390001,5.714058,-810.798767,-0.004467,0.000587,0.014917,25.417398,1.294824,0.149170,-810.798767,0.016192,0.000000
20.780001,6.089409,-810.709839,-0.004445,0.000612,0.015550,27.087044,1.379880,0.155499,-810.709839,0.016841,0.000000
21.170000,6.414864,-810.709839,-0.004402,0.000638,0.016218,28.534739,1.453629,0.162175,-810.709839,0.017483,0.000000
21.560001,6.752235,-810.709839,-0.004385,0.000666,0.016929,30.035442,1.530078,0.169291,-810.709839,0.018134,0.000000
21.950001,7.178230,-810.709839,-0.004359,0.000693,0.017597,31.930363,1.626610,0.175967,-810.709839,0.018784,0.000000
22.340000,7.420639,-810.843262,-0.004329,0.000722,0.018351,33.008652,1.681541,0.183507,-810.843262,0.019435,0.000000
22.730001,7.804558,-810.754272,-0.004273,0.000754,0.019158,34.716408,1.768538,0.191576,-810.754272,0.020086,0.000000
23.120001,8.157570,-810.798767,-0.004277,0.000780,0.019816,36.286682,1.848532,0.198162,-810.798767,0.020735,0.000000
23.510000,8.344872,-810.709839,-0.004230,0.000802,0.020372,37.119843,1.890975,0.203718,-810.709839,0.021386,0.000000
23.900002,8.582069,-810.843262,-0.004208,0.000827,0.021005,38.174950,1.944725,0.210047,-810.843262,0.022037,0.000000
24.290001,8.748146,-810.843262,-0.004178,0.000846,0.021482,38.913696,1.982358,0.214815,-810.843262,0.022687,0.000000
24.680000,9.219200,-810.754272,-0.004165,0.000873,0.022184,41.009048,2.089101,0.221840,-810.754272,0.023338,0.000000
25.070002,9.366661,-810.843262,-0.004126,0.000898,0.022800,41.664989,2.122516,0.228002,-810.843262,0.023987,0.000000
25.460001,9.480232,-810.754272,-0.004109,0.000923,0.023433,42.170177,2.148251,0.234330,-810.754272,0.024638,0.000000
25.850000,9.699936,-810.843262,-0.004061,0.000951,0.024152,43.147469,2.198037,0.241522,-810.843262,0.025289,0.000000
26.240002,9.726372,-810.843262,-0.004036,0.000972,0.024699,43.265064,2.204027,0.246987,-810.843262,0.025939,0.000000
26.630001,9.904366,-810.843262,-0.004010,0.000995,0.025280,44.056820,2.244361,0.252801,-810.843262,0.026590,0.000000
27.020000,10.029854,-810.887756,-0.003980,0.001020,0.025913,44.615017,2.272797,0.259129,-810.887756,0.027239,0.000000
27.410002,10.049217,-810.843262,-0.003949,0.001043,0.026485,44.701149,2.277185,0.264852,-810.843262,0.027890,0.000000
27.800001,10.598099,-810.887756,-0.003911,0.001080,0.027430,47.142696,2.401563,0.274299,-810.887756,0.028541,0.000000
28.190001,10.423828,-810.887756,-0.003872,0.001101,0.027976,46.367504,2.362073,0.279764,-810.887756,0.029191,0.000000
28.580002,10.599586,-810.798767,-0.003833,0.001126,0.028611,47.149315,2.401901,0.286108,-810.798767,0.029842,0.000000
28.970001,10.676666,-810.843262,-0.003816,0.001152,0.029260,47.492184,2.419367,0.292603,-810.843262,0.030493,0.000000
29.360001,10.895996,-810.932190,-0.003773,0.001176,0.029858,48.467812,2.469068,0.298583,-810.932190,0.031142,0.000000
29.750002,11.256447,-810.887756,-0.003755,0.001206,0.030639,50.071175,2.550747,0.306395,-810.887756,0.031793,0.000000
30.140001,11.113831,-810.932190,-0.003708,0.001229,0.031221,49.436787,2.518430,0.312208,-810.932190,0.032435,0.000000
30.530001,11.241180,-810.843262,-0.003669,0.001254,0.031845,50.003269,2.547288,0.318446,-810.843262,0.033085,0.000000
30.920002,11.525307,-810.976685,-0.003648,0.001280,0.032503,51.267124,2.611672,0.325032,-810.976685,0.033736,0.000000
31.310001,11.557701,-810.887756,-0.003596,0.001302,0.033068,51.411221,2.619013,0.330679,-810.887756,0.034385,0.000000
31.700001,12.022049,-810.976685,-0.003591,0.001334,0.033875,53.476746,2.724235,0.338748,-810.976685,0.035036,0.000000
32.090000,11.858574,-810.976685,-0.003557,0.001353,0.034368,52.749573,2.687191,0.343684,-810.976685,0.035687,0.000000
32.480003,12.262604,-810.932190,-0.003518,0.001384,0.035166,54.546787,2.778746,0.351662,-810.932190,0.036337,0.000000
32.870003,12.941063,-810.976685,-0.003484,0.001417,0.035981,57.564724,2.932487,0.359807,-810.976685,0.036988,0.000000
33.260002,12.622688,-810.976685,-0.003462,0.001434,0.036415,56.148521,2.860342,0.364152,-810.976685,0.037639,0.000000
33.650002,13.095596,-811.021179,-0.003436,0.001465,0.037222,58.252121,2.967505,0.372222,-811.021179,0.038288,0.000000
34.040001,13.199493,-810.976685,-0.003380,0.001489,0.037829,58.714279,2.991048,0.378293,-810.976685,0.038939,0.000000
34.430000,13.296677,-811.021179,-0.003372,0.001508,0.038314,59.146572,3.013070,0.383137,-811.021179,0.039588,0.000000
34.820004,13.634796,-811.065674,-0.003341,0.001534,0.038965,60.650604,3.089689,0.389647,-811.065674,0.040239,0.000000
35.210003,13.958015,-811.021179,-0.003307,0.001561,0.039658,62.088352,3.162931,0.396581,-811.021179,0.040890,0.000000
35.600002,14.491623,-811.065674,-0.003285,0.001591,0.040421,64.461960,3.283849,0.404212,-811.065674,0.041540,0.000000
35.990002,14.358688,-811.021179,-0.003260,0.001614,0.041003,63.870636,3.253725,0.410025,-811.021179,0.042191,0.000000
36.380001,14.868462,-811.110168,-0.003234,0.001642,0.041714,66.138222,3.369241,0.417141,-811.110168,0.042840,0.000000
36.770000,14.701271,-811.110168,-0.003195,0.001659,0.042130,65.394516,3.331356,0.421304,-811.110168,0.043491,0.000000
37.160004,15.689919,-811.021179,-0.003173,0.001695,0.043040,69.792244,3.555386,0.430403,-811.021179,0.044142,0.000000
37.550003,15.695877,-811.154602,-0.003139,0.001719,0.043666,69.818748,3.556736,0.436656,-811.154602,0.044792,0.000000
37.940002,16.072716,-811.021179,-0.003096,0.001750,0.044454,71.495010,3.642129,0.444543,-811.021179,0.045443,0.000000
38.330002,16.078674,-811.065674,-0.003070,0.001771,0.044992,71.521515,3.643480,0.449918,-811.065674,0.046094,0.000000
38.720001,16.065269,-811.154602,-0.003044,0.001791,0.045494,71.461891,3.640442,0.454944,-811.154602,0.046743,0.000000
39.110001,16.194481,-811.110168,-0.003031,0.001812,0.046015,72.036652,3.669722,0.460152,-811.110168,0.047385,0.000000
39.500000,17.192436,-811.065674,-0.002984,0.001851,0.047013,76.475777,3.895862,0.470129,-811.065674,0.048036,0.000000
39.890003,16.802193,-811.110168,-0.002958,0.001866,0.047404,74.739883,3.807431,0.474035,-811.110168,0.048686,0.000000
40.280003,17.127647,-811.065674,-0.002932,0.001890,0.048009,76.187584,3.881180,0.480091,-811.065674,0.049337,0.000000
40.670002,17.329842,-811.154602,-0.002897,0.001915,0.048651,77.086983,3.926998,0.486510,-811.154602,0.049988,0.000000
41.060001,18.244766,-811.154602,-0.002880,0.001952,0.049572,81.156776,4.134323,0.495715,-811.154602,0.050637,0.000000
41.450001,18.225777,-811.199097,-0.002833,0.001975,0.050170,81.072304,4.130020,0.501695,-811.199097,0.051288,0.000000
41.840000,18.376213,-811.199097,-0.002794,0.001999,0.050777,81.741478,4.164109,0.507766,-811.199097,0.051938,0.000000
42.230003,18.225777,-811.199097,-0.002794,0.002022,0.051349,81.072304,4.130020,0.513489,-811.199097,0.052589,0.000000
42.620003,18.369141,-811.154602,-0.002746,0.002044,0.051921,81.710022,4.162507,0.519212,-811.154602,0.053240,0.000000
43.010002,19.212936,-811.154602,-0.002733,0.002076,0.052719,85.463409,4.353714,0.527190,-811.154602,0.053889,0.000000
43.400002,19.402840,-811.199097,-0.002695,0.002103,0.053422,86.308144,4.396747,0.534215,-811.199097,0.054540,0.000000
43.790001,19.846336,-811.199097,-0.002665,0.002136,0.054263,88.280914,4.497244,0.542633,-811.199097,0.055190,0.000000
44.180000,19.947250,-811.199097,-0.002626,0.002161,0.054878,88.729797,4.520112,0.548779,-811.199097,0.055841,0.000000
44.570004,20.053749,-811.288086,-0.002587,0.002185,0.055511,89.203529,4.544245,0.555108,-811.288086,0.056492,0.000000
44.960003,19.987099,-811.199097,-0.002565,0.002209,0.056101,88.907059,4.529141,0.561012,-811.199097,0.057141,0.000000
45.350002,20.118912,-811.288086,-0.002535,0.002231,0.056674,89.493385,4.559011,0.566735,-811.288086,0.057792,0.000000
45.740002,19.964005,-811.288086,-0.002496,0.002246,0.057046,88.804329,4.523908,0.570459,-811.288086,0.058443,0.000000
46.130001,21.159698,-811.288086,-0.002483,0.002283,0.057983,94.123039,4.794856,0.579831,-811.288086,0.059093,0.000000
46.520000,21.288910,-811.288086,-0.002458,0.002308,0.058634,94.697800,4.824136,0.586341,-811.288086,0.059744,0.000000
46.910004,21.396156,-811.199097,-0.002406,0.002336,0.059337,95.174858,4.848438,0.593366,-811.199097,0.060393,0.000000
47.300003,21.251297,-811.288086,-0.002380,0.002358,0.059891,94.530487,4.815613,0.598907,-811.288086,0.061044,0.000000
47.690002,21.016708,-811.288086,-0.002367,0.002380,0.060454,93.486984,4.762455,0.604539,-811.288086,0.061695,0.000000
48.080002,21.207733,-811.377014,-0.002324,0.002399,0.060923,94.336708,4.805741,0.609232,-811.377014,0.062336,0.000000
48.470001,21.415886,-811.377014,-0.002285,0.002423,0.061556,95.262619,4.852909,0.615560,-811.377014,0.062987,0.000000
48.860001,22.439911,-811.332520,-0.002268,0.002461,0.062501,99.817711,5.084956,0.625007,-811.332520,0.063638,0.000000
49.250004,22.422035,-811.377014,-0.002203,0.002489,0.063229,99.738197,5.080905,0.632289,-811.377014,0.064287,0.000000
49.640003,21.548080,-811.332520,-0.002173,0.002501,0.063517,95.850647,4.882865,0.635166,-811.332520,0.064938,0.000000
50.030003,22.484596,-811.421509,-0.002130,0.002537,0.064443,100.016479,5.095082,0.644431,-811.421509,0.065589,0.000000
50.420002,21.691071,-811.332520,-0.002104,0.002552,0.064817,96.486702,4.915267,0.648171,-811.332520,0.066239,0.000000
50.810001,21.869812,-811.421509,-0.002082,0.002575,0.065415,97.281784,4.955770,0.654151,-811.421509,0.066890,0.000000
51.200001,22.496140,-811.421509,-0.002026,0.002610,0.066292,100.067825,5.097698,0.662917,-811.421509,0.067539,0.000000
51.590004,22.156906,-811.332520,-0.001992,0.002634,0.066915,98.558838,5.020827,0.669154,-811.332520,0.068190,0.000000
51.980003,22.319633,-811.466003,-0.001962,0.002664,0.067669,99.282692,5.057701,0.676694,-811.466003,0.068841,0.000000
52.370003,22.916550,-811.466003,-0.001919,0.002694,0.068425,101.937904,5.192965,0.684248,-811.466003,0.069491,0.000000
52.760002,21.670219,-811.466003,-0.001901,0.002711,0.068849,96.393951,4.910542,0.688488,-811.466003,0.070142,0.000000
53.150002,22.026207,-811.421509,-0.001845,0.002738,0.069551,97.977463,4.991210,0.695512,-811.421509,0.070791,0.000000
53.540001,22.191544,-811.377014,-0.001807,0.002765,0.070228,98.712914,5.028676,0.702280,-811.377014,0.071442,0.000000
53.930004,21.787514,-811.510498,-0.001785,0.002792,0.070914,96.915703,4.937121,0.709138,-811.510498,0.072093,0.000000
54.320004,22.424644,-811.466003,-0.001720,0.002823,0.071693,99.749802,5.081497,0.716935,-811.466003,0.072743,0.000000
54.710003,22.282028,-811.510498,-0.001699,0.002846,0.072284,99.115410,5.049180,0.722839,-811.510498,0.073394,0.000000
55.100002,22.439911,-811.510498,-0.001669,0.002874,0.073012,99.817711,5.084956,0.730121,-811.510498,0.074045,0.000000
55.490002,22.026955,-811.510498,-0.001621,0.002891,0.073438,97.980789,4.991379,0.734376,-811.510498,0.074694,0.000000
55.880001,22.080200,-811.510498,-0.001608,0.002914,0.074026,98.217636,5.003445,0.740265,-811.510498,0.075345,0.000000
56.270004,22.599289,-811.599426,-0.001565,0.002941,0.074712,100.526657,5.121072,0.747123,-811.599426,0.075995,0.000000
56.660004,23.705978,-811.554932,-0.001539,0.002974,0.075536,105.449455,5.371851,0.755359,-811.554932,0.076646,0.000000
57.050003,23.367867,-811.510498,-0.001483,0.002996,0.076090,103.945465,5.295234,0.760900,-811.510498,0.077288,0.000000
57.440002,23.469147,-811.554932,-0.001457,0.003019,0.076680,104.395981,5.318185,0.766805,-811.554932,0.077939,0.000000
57.830002,23.759232,-811.599426,-0.001418,0.003044,0.077313,105.686340,5.383919,0.773133,-811.599426,0.078588,0.000000
58.220001,23.303818,-811.599426,-0.001401,0.003061,0.077755,103.660561,5.280720,0.777554,-811.599426,0.079239,0.000000
58.610004,25.174988,-811.643921,-0.001375,0.003098,0.078702,111.983940,5.704734,0.787016,-811.643921,0.079889,0.000000
59.000004,25.404739,-811.554932,-0.001341,0.003126,0.079404,113.005928,5.756796,0.794041,-811.554932,0.080540,0.000000
59.390003,25.200310,-811.554932,-0.001302,0.003153,0.080097,112.096573,5.710472,0.800975,-811.554932,0.081191,0.000000
59.780003,25.133286,-811.554932,-0.001246,0.003173,0.080600,111.798439,5.695284,0.806001,-811.554932,0.081840,0.000000
60.170002,24.712875,-811.554932,-0.001229,0.003190,0.081016,109.928360,5.600018,0.810164,-811.554932,0.082491,0.000000
60.560001,26.165123,-811.643921,-0.001199,0.003228,0.081996,116.388283,5.929101,0.819960,-811.643921,0.083141,0.000000
60.950005,26.304024,-811.643921,-0.001160,0.003254,0.082647,117.006142,5.960577,0.826470,-811.643921,0.083792,0.000000
61.340004,25.874680,-811.643921,-0.001125,0.003274,0.083159,115.096321,5.863286,0.831587,-811.643921,0.084443,0.000000
61.730003,26.412384,-811.643921,-0.001091,0.003301,0.083852,117.488152,5.985132,0.838521,-811.643921,0.085092,0.000000
62.120003,26.514038,-811.643921,-0.001061,0.003327,0.084494,117.940331,6.008167,0.844940,-811.643921,0.085743,0.000000
62.510002,27.201065,-811.732849,-0.001018,0.003359,0.085318,120.996384,6.163849,0.853176,-811.732849,0.086394,0.000000
62.900002,26.834656,-811.599426,-0.000979,0.003380,0.085847,119.366508,6.080820,0.858475,-811.599426,0.087044,0.000000
63.290005,26.525581,-811.688416,-0.000957,0.003403,0.086436,117.991676,6.010783,0.864364,-811.688416,0.087695,0.000000
63.680004,27.097923,-811.732849,-0.000923,0.003431,0.087157,120.537582,6.140477,0.871570,-811.732849,0.088344,0.000000
64.070000,26.820503,-811.643921,-0.000880,0.003454,0.087737,119.303558,6.077613,0.877369,-811.643921,0.088995,0.000000
64.460007,27.685524,-811.732849,-0.000845,0.003483,0.088474,123.151360,6.273630,0.884742,-811.732849,0.089646,0.000000
64.850006,28.339783,-811.688416,-0.000798,0.003516,0.089307,126.061653,6.421886,0.893069,-811.688416,0.090295,0.000000
65.240005,28.076515,-811.777344,-0.000755,0.003543,0.089984,124.890579,6.362229,0.899836,-811.777344,0.090946,0.000000
65.630005,27.911552,-811.688416,-0.000711,0.003568,0.090626,124.156784,6.324848,0.906255,-811.688416,0.091596,0.000000
66.020004,28.226952,-811.688416,-0.000686,0.003594,0.091293,125.559753,6.396318,0.912932,-811.688416,0.092238,0.000000
66.410004,28.124924,-811.732849,-0.000660,0.003614,0.091787,125.105911,6.373199,0.917867,-811.732849,0.092889,0.000000
66.800003,28.324142,-811.732849,-0.000638,0.003635,0.092333,125.992081,6.418342,0.923333,-811.732849,0.093540,0.000000
67.190002,28.328613,-811.688416,-0.000586,0.003659,0.092940,126.011963,6.419355,0.929404,-811.688416,0.094189,0.000000
67.580002,29.281143,-811.732849,-0.000569,0.003681,0.093505,130.249023,6.635202,0.935051,-811.732849,0.094840,0.000000
67.970001,30.359161,-811.777344,-0.000539,0.003712,0.094294,135.044296,6.879484,0.942938,-811.777344,0.095490,0.000000
68.360001,31.222321,-811.821838,-0.000517,0.003743,0.095074,138.883820,7.075079,0.950735,-811.821838,0.096141,0.000000
68.750000,31.185081,-811.777344,-0.000500,0.003762,0.095560,138.718170,7.066640,0.955595,-811.777344,0.096792,0.000000
69.140007,31.999832,-811.821838,-0.000448,0.003787,0.096192,142.342361,7.251266,0.961923,-811.821838,0.097441,0.000000
69.530006,32.940071,-811.777344,-0.000453,0.003814,0.096887,146.524750,7.464327,0.968873,-811.777344,0.098092,0.000000
69.920006,33.651306,-811.821838,-0.000418,0.003839,0.097511,149.688492,7.625495,0.975110,-811.821838,0.098742,0.000000
70.310005,34.456001,-811.866333,-0.000397,0.003865,0.098179,153.267944,7.807841,0.981787,-811.866333,0.099393,0.000000
70.700005,35.220856,-811.777344,-0.000362,0.003889,0.098769,156.670197,7.981160,0.987691,-811.777344,0.100044,0.000000
71.090004,36.708481,-811.866333,-0.000358,0.003923,0.099635,163.287476,8.318260,0.996351,-811.866333,0.100693,0.000000
71.480003,37.302414,-811.821838,-0.000323,0.003944,0.100174,165.929428,8.452848,1.001741,-811.821838,0.101344,0.000000
71.870003,37.115486,-811.821838,-0.000302,0.003956,0.100486,165.097931,8.410489,1.004859,-811.821838,0.101995,0.000000
72.260002,39.503510,-811.866333,-0.000280,0.003997,0.101526,175.720383,8.951623,1.015260,-811.866333,0.102645,0.000000
72.650002,40.639992,-811.821838,-0.000254,0.004019,0.102091,180.775711,9.209153,1.020907,-811.821838,0.103296,0.000000
73.040001,40.707016,-811.910828,-0.000246,0.004041,0.102636,181.073853,9.224341,1.026358,-811.910828,0.103945,0.000000
73.430000,42.749855,-811.866333,-0.000224,0.004073,0.103443,190.160858,9.687255,1.034427,-811.866333,0.104596,0.000000
73.820000,44.087044,-811.910828,-0.000216,0.004096,0.104033,196.108963,9.990267,1.040331,-811.910828,0.105247,0.000000
74.210007,45.660690,-811.910828,-0.000181,0.004126,0.104796,203.108902,10.346860,1.047962,-811.910828,0.105897,0.000000
74.600006,46.487350,-811.866333,-0.000181,0.004146,0.105299,206.786057,10.534184,1.052988,-811.866333,0.106548,0.000000
74.990005,47.616386,-811.910828,-0.000172,0.004173,0.106001,211.808258,10.790028,1.060013,-811.910828,0.107197,0.000000
75.380005,48.936821,-811.910828,-0.000134,0.004202,0.106729,217.681854,11.089242,1.067295,-811.910828,0.107839,0.000000
75.770004,50.939438,-811.955261,-0.000138,0.004230,0.107441,226.589935,11.543041,1.074411,-811.955261,0.108490,0.000000
76.160004,52.436378,-811.910828,-0.000103,0.004255,0.108065,233.248657,11.882253,1.080648,-811.910828,0.109141,0.000000
76.550003,53.469337,-811.910828,-0.000099,0.004277,0.108637,237.843491,12.116325,1.086371,-811.910828,0.109791,0.000000
76.940002,54.324303,-811.955261,-0.000091,0.004300,0.109228,241.646561,12.310063,1.092275,-811.955261,0.110442,0.000000
77.330002,55.823845,-811.910828,-0.000060,0.004321,0.109748,248.316864,12.649864,1.097483,-811.910828,0.111091,0.000000
77.720001,57.097359,-811.955261,-0.000060,0.004342,0.110277,253.981735,12.938446,1.102767,-811.955261,0.111742,0.000000
78.110001,60.131081,-812.044250,-0.000034,0.004380,0.111240,267.476410,13.625897,1.112396,-812.044250,0.112393,0.000000
78.500000,61.152870,-811.955261,-0.000026,0.004405,0.111889,272.021545,13.857438,1.118891,-811.955261,0.113043,0.000000
78.890007,63.031860,-812.044250,-0.000022,0.004429,0.112496,280.379730,14.283223,1.124962,-812.044250,0.113694,0.000000
79.280006,64.216759,-811.955261,-0.000009,0.004449,0.113000,285.650421,14.551725,1.130003,-811.955261,0.114345,0.000000
79.670006,65.230354,-812.044250,0.000000,0.004467,0.113459,290.159119,14.781409,1.134590,-812.044250,0.114994,0.000000
80.060005,66.077126,-812.044250,0.000022,0.004475,0.113668,293.925720,14.973290,1.136680,-812.044250,0.019947,0.000000
80.450005,65.269447,-812.044250,0.000004,0.004474,0.113650,290.333008,14.790268,1.136498,-812.044250,294.500488,0.000000
80.840004,64.630089,-812.044250,0.000030,0.004475,0.113676,287.488983,14.645388,1.136755,-812.044250,294.500488,0.000000
81.230003,65.755760,-812.044250,0.000030,0.004486,0.113945,292.496216,14.900469,1.139450,-812.044250,294.500488,0.000000
81.620003,65.208000,-812.044250,0.000034,0.004486,0.113945,290.059662,14.776343,1.139450,-812.044250,294.500488,0.000000
82.010002,64.759300,-812.133179,0.000043,0.004486,0.113954,288.063751,14.674667,1.139541,-812.133179,294.500488,0.000000
82.400002,65.860771,-812.044250,0.000039,0.004496,0.114205,292.963348,14.924264,1.142054,-812.044250,294.500488,0.000000
82.790001,65.462715,-812.044250,0.000052,0.004496,0.114205,291.192688,14.834064,1.142054,-812.044250,294.500488,0.000000
83.180000,65.093315,-811.999756,0.000043,0.004497,0.114215,289.549530,14.750356,1.142145,-811.999756,294.500488,0.000000
83.570007,64.796165,-812.133179,0.000060,0.004497,0.114215,288.227753,14.683022,1.142145,-812.133179,294.500488,0.000000
83.960007,66.243950,-812.088745,0.000060,0.004518,0.114769,294.667816,15.011093,1.147686,-812.088745,294.500488,0.000000
84.350006,65.858162,-812.133179,0.000056,0.004513,0.114638,292.951721,14.923673,1.146384,-812.133179,294.500488,0.000000
84.740005,65.663795,-812.088745,0.000065,0.004513,0.114638,292.087158,14.879629,1.146384,-812.088745,294.500488,0.000000
85.130005,65.445580,-812.133179,0.000065,0.004513,0.114638,291.116486,14.830180,1.146384,-812.133179,294.500488,0.000000
85.520004,65.260887,-812.177673,0.000047,0.004514,0.114647,290.294922,14.788328,1.146475,-812.177673,294.500488,0.000000
85.910004,65.047142,-812.177673,0.000060,0.004514,0.114647,289.344147,14.739893,1.146475,-812.177673,294.500488,0.000000
86.300003,64.905647,-812.088745,0.000060,0.004516,0.114708,288.714752,14.707829,1.147081,-812.088745,294.500488,0.000000
86.690002,65.558037,-812.133179,0.000073,0.004526,0.114959,291.616699,14.855663,1.149594,-812.133179,294.500488,0.000000
87.080002,65.477608,-812.088745,0.000078,0.004526,0.114959,291.258942,14.837438,1.149594,-812.088745,294.500488,0.000000
87.470001,65.343178,-812.222168,0.000069,0.004526,0.114959,290.660980,14.806976,1.149594,-812.222168,294.500488,0.000000
87.860001,65.257912,-812.133179,0.000073,0.004526,0.114959,290.281677,14.787654,1.149594,-812.133179,294.500488,0.000000
88.250008,65.170403,-812.177673,0.000069,0.004527,0.114978,289.892426,14.767824,1.149775,-812.177673,294.500488,0.000000
88.640007,65.072090,-812.222168,0.000082,0.004527,0.114978,289.455109,14.745546,1.149775,-812.222168,294.500488,0.000000
89.030006,65.600853,-812.266663,0.000065,0.004536,0.115220,291.807159,14.865366,1.152198,-812.266663,294.500488,0.000000
89.420006,65.668633,-812.177673,0.000082,0.004534,0.115176,292.108673,14.880725,1.151759,-812.177673,294.500488,0.000000
89.810005,65.598991,-812.222168,0.000073,0.004534,0.115176,291.798889,14.864944,1.151759,-812.222168,294.500488,0.000000
90.200005,65.539421,-812.222168,0.000069,0.004534,0.115176,291.533905,14.851445,1.151759,-812.222168,294.500488,0.000000
90.590004,65.468300,-812.355591,0.000082,0.004534,0.115176,291.217529,14.835329,1.151759,-812.355591,294.500488,0.000000
90.980003,65.352486,-812.177673,0.000086,0.004534,0.115176,290.702362,14.809085,1.151759,-812.177673,294.500488,0.000000
91.370003,65.296257,-812.222168,0.000078,0.004534,0.115176,290.452271,14.796344,1.151759,-812.222168,294.500488,0.000000
91.760002,65.225883,-812.311157,0.000086,0.004534,0.115176,290.139221,14.780396,1.151759,-812.311157,294.500488,0.000000
92.150002,65.123100,-812.222168,0.000078,0.004534,0.115176,289.682007,14.757106,1.151759,-812.222168,294.500488,0.000000
92.540001,65.053093,-812.311157,0.000078,0.004535,0.115185,289.370605,14.741241,1.151850,-812.311157,294.500488,0.000000
92.930008,64.985695,-812.266663,0.000078,0.004535,0.115185,289.070801,14.725968,1.151850,-812.266663,294.500488,0.000000
93.320007,64.930962,-812.311157,0.000078,0.004535,0.115185,288.827332,14.713567,1.151850,-812.311157,294.500488,0.000000
93.710007,64.833778,-812.311157,0.000073,0.004535,0.115185,288.395050,14.691544,1.151850,-812.311157,294.500488,0.000000
94.100006,64.770470,-812.266663,0.000073,0.004535,0.115185,288.113434,14.677198,1.151850,-812.266663,294.500488,0.000000
94.490005,64.717964,-812.400085,0.000082,0.004535,0.115185,287.879883,14.665300,1.151850,-812.400085,294.500488,0.000000
94.880005,64.641624,-812.355591,0.000082,0.004535,0.115194,287.540314,14.648002,1.151940,-812.355591,294.500488,0.000000
95.270004,64.558968,-812.355591,0.000073,0.004535,0.115194,287.172638,14.629272,1.151940,-812.355591,294.500488,0.000000
95.660004,64.514656,-812.355591,0.000082,0.004535,0.115194,286.975525,14.619230,1.151940,-812.355591,294.500488,0.000000
96.050003,64.443520,-812.355591,0.000078,0.004535,0.115194,286.659088,14.603110,1.151940,-812.355591,294.500488,0.000000
96.440002,64.404427,-812.355591,0.000095,0.004535,0.115194,286.485199,14.594252,1.151940,-812.355591,294.500488,0.000000
96.830002,64.337029,-812.400085,0.000095,0.004535,0.115194,286.185394,14.578979,1.151940,-812.400085,294.500488,0.000000
97.220001,64.276329,-812.355591,0.000082,0.004535,0.115194,285.915405,14.565225,1.151940,-812.355591,294.500488,0.000000
97.610008,64.233513,-812.444580,0.000095,0.004535,0.115194,285.724945,14.555522,1.151940,-812.444580,294.500488,0.000000
98.000008,66.890388,-812.355591,0.000099,0.004373,0.111075,297.543304,15.157578,1.110746,-812.355591,294.500488,0.000000
98.390007,66.750008,-812.444580,0.000095,0.004370,0.110996,296.918854,15.125768,1.109958,-812.444580,294.500488,0.000000
98.780006,66.684837,-812.444580,0.000086,0.004370,0.110996,296.628967,15.111000,1.109958,-812.444580,294.500488,0.000000
99.170006,66.642754,-812.444580,0.000099,0.004370,0.110996,296.441772,15.101463,1.109958,-812.444580,294.500488,0.000000
99.560005,66.578331,-812.400085,0.000103,0.004370,0.110996,296.155212,15.086865,1.109958,-812.400085,294.500488,0.000000
99.950005,66.452110,-812.355591,0.000108,0.004370,0.110996,295.593750,15.058264,1.109958,-812.355591,294.500488,0.000000
100.340004,66.383583,-812.533508,0.000112,0.004370,0.111005,295.288940,15.042735,1.110049,-812.533508,294.500488,0.000000
100.730003,66.383965,-812.489075,0.000103,0.004371,0.111014,295.290619,15.042821,1.110140,-812.489075,294.500488,0.000000
101.120003,66.347832,-812.489075,0.000108,0.004371,0.111014,295.129883,15.034634,1.110140,-812.489075,294.500488,0.000000
101.510002,66.284157,-812.533508,0.000103,0.004371,0.111014,294.846649,15.020205,1.110140,-812.533508,294.500488,0.000000
101.900002,66.245811,-812.444580,0.000103,0.004371,0.111014,294.676086,15.011516,1.110140,-812.444580,294.500488,0.000000
102.290009,66.181023,-812.489075,0.000099,0.004371,0.111014,294.387878,14.996834,1.110140,-812.489075,294.500488,0.000000
102.680008,66.140053,-812.578003,0.000108,0.004371,0.111014,294.205658,14.987550,1.110140,-812.578003,294.500488,0.000000
103.070007,66.104301,-812.533508,0.000103,0.004371,0.111014,294.046631,14.979448,1.110140,-812.533508,294.500488,0.000000
103.460007,66.054787,-812.533508,0.000112,0.004371,0.111014,293.826355,14.968228,1.110140,-812.533508,294.500488,0.000000
103.850006,65.992973,-812.489075,0.000112,0.004371,0.111014,293.551392,14.954222,1.110140,-812.489075,294.500488,0.000000
104.240005,65.959084,-812.533508,0.000108,0.004371,0.111023,293.400665,14.946542,1.110231,-812.533508,294.500488,0.000000
104.630005,65.896523,-812.489075,0.000099,0.004371,0.111031,293.122375,14.932365,1.110307,-812.489075,294.500488,0.000000
105.020004,65.833595,-812.533508,0.000095,0.004383,0.111326,292.842468,14.918106,1.113259,-812.533508,294.500488,0.000000
105.410004,65.848488,-812.533508,0.000103,0.004387,0.111421,292.908691,14.921480,1.114213,-812.533508,294.500488,0.000000
105.800003,65.823174,-812.578003,0.000108,0.004387,0.111430,292.796112,14.915745,1.114303,-812.578003,294.500488,0.000000
106.190002,65.780342,-812.533508,0.000112,0.004397,0.111673,292.605560,14.906039,1.116726,-812.533508,294.500488,0.000000
106.580002,65.690224,-812.622498,0.000112,0.004406,0.111907,292.204712,14.885618,1.119072,-812.622498,294.500488,0.000000
106.970009,65.676445,-812.533508,0.000112,0.004408,0.111951,292.143433,14.882495,1.119511,-812.533508,294.500488,0.000000
107.360008,65.586342,-812.622498,0.000086,0.004443,0.112861,291.742615,14.862078,1.128610,-812.622498,294.500488,0.000000
107.750008,65.551704,-812.622498,0.000108,0.004448,0.112973,291.588531,14.854228,1.129731,-812.622498,294.500488,0.000000
108.140007,65.541649,-812.622498,0.000103,0.004456,0.113173,291.543823,14.851950,1.131729,-812.622498,294.500488,0.000000
108.530006,65.493614,-812.666992,0.000121,0.004456,0.113191,291.330139,14.841065,1.131911,-812.666992,294.500488,0.000000
108.920006,65.469780,-812.666992,0.000116,0.004457,0.113217,291.224121,14.835664,1.132168,-812.666992,294.500488,0.000000
109.310005,65.400520,-812.666992,0.000103,0.004463,0.113364,290.916046,14.819970,1.133637,-812.666992,294.500488,0.000000
109.700005,65.440742,-812.666992,0.000099,0.004501,0.114327,291.094971,14.829084,1.143265,-812.666992,294.500488,0.000000
110.090004,65.422859,-812.711487,0.000099,0.004506,0.114457,291.015411,14.825032,1.144567,-812.711487,294.500488,0.000000
110.480003,65.397545,-812.711487,0.000108,0.004508,0.114492,290.902802,14.819296,1.144916,-812.711487,294.500488,0.000000
110.870003,65.364403,-812.666992,0.000112,0.004510,0.114561,290.755371,14.811786,1.145612,-812.666992,294.500488,0.000000
111.260002,65.321953,-812.666992,0.000108,0.004510,0.114561,290.566559,14.802166,1.145612,-812.666992,294.500488,0.000000
111.650002,65.310402,-812.711487,0.000103,0.004512,0.114613,290.515167,14.799548,1.146127,-812.711487,294.500488,0.000000
112.040009,65.274284,-812.666992,0.000112,0.004512,0.114613,290.354523,14.791364,1.146127,-812.666992,294.500488,0.000000
112.430008,65.259392,-812.755920,0.000086,0.004524,0.114917,290.288269,14.787990,1.149170,-812.755920,294.500488,0.000000
112.820007,65.240410,-812.755920,0.000112,0.004525,0.114925,290.203827,14.783688,1.149246,-812.755920,294.500488,0.000000
113.210007,65.208382,-812.711487,0.000112,0.004525,0.114925,290.061371,14.776431,1.149246,-812.711487,294.500488,0.000000
113.600006,65.181190,-812.800415,0.000108,0.004525,0.114925,289.940430,14.770268,1.149246,-812.800415,294.500488,0.000000
113.990005,65.201683,-812.666992,0.000121,0.004535,0.115185,290.031586,14.774913,1.151850,-812.666992,294.500488,0.000000
114.380005,65.269447,-812.755920,0.000103,0.004543,0.115394,290.333008,14.790268,1.153939,-812.755920,294.500488,0.000000
114.770004,65.233330,-812.800415,0.000103,0.004543,0.115401,290.172333,14.782084,1.154014,-812.800415,294.500488,0.000000
115.160004,65.228493,-812.755920,0.000112,0.004543,0.115401,290.150818,14.780988,1.154014,-812.755920,294.500488,0.000000
115.550003,65.201302,-812.800415,0.000108,0.004543,0.115401,290.029877,14.774826,1.154014,-812.800415,294.500488,0.000000
115.940002,65.178963,-812.755920,0.000112,0.004543,0.115401,289.930511,14.769765,1.154014,-812.755920,294.500488,0.000000
116.330002,65.138008,-812.800415,0.000121,0.004543,0.115401,289.748322,14.760484,1.154014,-812.800415,294.500488,0.000000
116.720009,65.160347,-812.844910,0.000121,0.004546,0.115480,289.847687,14.765546,1.154802,-812.844910,294.500488,0.000000
117.110008,65.177101,-812.755920,0.000103,0.004546,0.115480,289.922211,14.769342,1.154802,-812.755920,294.500488,0.000000
117.500008,65.153267,-812.800415,0.000108,0.004546,0.115480,289.816193,14.763942,1.154802,-812.800415,294.500488,0.000000
117.890007,65.139488,-812.800415,0.000116,0.004546,0.115480,289.754913,14.760818,1.154802,-812.800415,294.500488,0.000000
118.280006,65.099281,-812.800415,0.000108,0.004546,0.115480,289.576080,14.751708,1.154802,-812.800415,294.500488,0.000000
118.670006,65.097420,-812.889404,0.000112,0.004546,0.115480,289.567780,14.751287,1.154802,-812.889404,294.500488,0.000000
119.060005,65.075066,-812.889404,0.000108,0.004546,0.115480,289.468353,14.746221,1.154802,-812.889404,294.500488,0.000000
119.450005,65.058693,-812.933838,0.000103,0.004546,0.115480,289.395508,14.742510,1.154802,-812.933838,294.500488,0.000000
119.840004,65.061668,-812.889404,0.000103,0.004548,0.115532,289.408752,14.743185,1.155316,-812.889404,294.500488,0.000000
120.230003,65.095543,-812.933838,0.000125,0.004548,0.115532,289.559448,14.750860,1.155316,-812.933838,294.500488,0.000000
120.620003,65.055702,-812.978333,0.000112,0.004548,0.115532,289.382202,14.741833,1.155316,-812.978333,294.500488,0.000000
121.010002,65.078423,-812.978333,0.000121,0.004548,0.115532,289.483276,14.746982,1.155316,-812.978333,294.500488,0.000000
121.400009,65.072838,-812.933838,0.000116,0.004548,0.115532,289.458435,14.745716,1.155316,-812.933838,294.500488,0.000000
121.790009,65.049004,-812.933838,0.000108,0.004548,0.115532,289.352417,14.740315,1.155316,-812.933838,294.500488,0.000000
122.180008,65.034859,-812.933838,0.000108,0.004548,0.115532,289.289490,14.737109,1.155316,-812.933838,294.500488,0.000000
122.570007,65.038200,-812.978333,0.000103,0.004548,0.115532,289.304352,14.737866,1.155316,-812.978333,294.500488,0.000000
122.960007,65.022942,-812.978333,0.000116,0.004548,0.115532,289.236481,14.734409,1.155316,-812.978333,294.500488,0.000000
123.350006,65.138741,-812.978333,0.000116,0.004553,0.115636,289.751587,14.760650,1.156361,-812.978333,294.500488,0.000000
123.740005,65.238548,-812.978333,0.000112,0.004553,0.115636,290.195557,14.783267,1.156361,-812.978333,294.500488,0.000000
124.130005,65.257164,-812.933838,0.000116,0.004553,0.115636,290.278351,14.787484,1.156361,-812.933838,294.500488,0.000000
124.520004,65.262367,-812.978333,0.000099,0.004553,0.115636,290.301514,14.788664,1.156361,-812.978333,294.500488,0.000000
124.910004,65.260139,-812.978333,0.000116,0.004553,0.115636,290.291595,14.788159,1.156361,-812.978333,294.500488,0.000000
125.300003,65.251198,-813.022827,0.000108,0.004553,0.115636,290.251831,14.786133,1.156361,-813.022827,294.500488,0.000000
125.690002,65.255669,-812.978333,0.000103,0.004553,0.115636,290.271698,14.787147,1.156361,-812.978333,294.500488,0.000000
126.080009,65.239281,-813.022827,0.000116,0.004553,0.115636,290.198822,14.783432,1.156361,-813.022827,294.500488,0.000000
126.470009,65.230721,-813.111755,0.000095,0.004553,0.115636,290.160736,14.781493,1.156361,-813.111755,294.500488,0.000000
126.860008,65.226250,-813.111755,0.000108,0.004553,0.115636,290.140839,14.780479,1.156361,-813.111755,294.500488,0.000000
127.250008,65.206139,-812.978333,0.000116,0.004553,0.115636,290.051392,14.775923,1.156361,-812.978333,294.500488,0.000000
127.640007,65.182686,-813.067322,0.000116,0.004553,0.115636,289.947083,14.770608,1.156361,-813.067322,294.500488,0.000000
128.029999,65.180077,-813.022827,0.000129,0.004553,0.115636,289.935455,14.770016,1.156361,-813.022827,294.500488,0.000000
128.420013,65.142464,-813.111755,0.000112,0.004553,0.115636,289.768158,14.761494,1.156361,-813.111755,294.500488,0.000000
128.810013,65.147316,-813.111755,0.000103,0.004553,0.115636,289.789734,14.762592,1.156361,-813.111755,294.500488,0.000000
129.200012,65.113792,-813.156250,0.000112,0.004553,0.115636,289.640625,14.754995,1.156361,-813.156250,294.500488,0.000000
129.590012,65.101143,-813.111755,0.000112,0.004553,0.115636,289.584351,14.752130,1.156361,-813.111755,294.500488,0.000000
129.980011,65.084007,-813.067322,0.000112,0.004553,0.115636,289.508118,14.748247,1.156361,-813.067322,294.500488,0.000000
130.370010,65.077309,-813.111755,0.000112,0.004553,0.115636,289.478333,14.746729,1.156361,-813.111755,294.500488,0.000000
130.760010,65.048256,-813.156250,0.000121,0.004553,0.115636,289.349091,14.740146,1.156361,-813.156250,294.500488,0.000000
131.150009,65.042305,-813.111755,0.000125,0.004553,0.115636,289.322632,14.738797,1.156361,-813.111755,294.500488,0.000000
131.540009,65.029274,-813.200745,0.000125,0.004553,0.115636,289.264648,14.735844,1.156361,-813.200745,294.500488,0.000000
131.930008,65.000221,-813.111755,0.000138,0.004553,0.115636,289.135437,14.729260,1.156361,-813.111755,294.500488,0.000000
132.320007,64.998741,-813.156250,0.000112,0.004553,0.115636,289.128845,14.728925,1.156361,-813.156250,294.500488,0.000000
132.710007,64.983101,-813.156250,0.000112,0.004553,0.115636,289.059265,14.725381,1.156361,-813.156250,294.500488,0.000000
133.100006,64.964851,-813.111755,0.000125,0.004553,0.115636,288.978088,14.721246,1.156361,-813.111755,294.500488,0.000000
133.490005,64.954796,-813.245239,0.000125,0.004553,0.115645,288.933350,14.718967,1.156452,-813.245239,294.500488,0.000000
133.880005,64.940651,-813.200745,0.000121,0.004553,0.115645,288.870453,14.715761,1.156452,-813.200745,294.500488,0.000000
134.270004,65.591927,-813.200745,0.000125,0.004562,0.115887,291.767456,14.863343,1.158874,-813.200745,294.500488,0.000000
134.660004,65.640709,-813.289734,0.000129,0.004562,0.115887,291.984467,14.874397,1.158874,-813.289734,294.500488,0.000000
135.050003,65.667885,-813.245239,0.000125,0.004562,0.115887,292.105347,14.880556,1.158874,-813.245239,294.500488,0.000000
135.440002,65.692833,-813.245239,0.000121,0.004562,0.115887,292.216309,14.886209,1.158874,-813.245239,294.500488,0.000000
135.830002,65.700279,-813.245239,0.000134,0.004562,0.115887,292.249451,14.887896,1.158874,-813.245239,294.500488,0.000000
136.220001,65.720757,-813.200745,0.000125,0.004562,0.115887,292.340515,14.892536,1.158874,-813.200745,294.500488,0.000000
136.610001,65.720024,-813.245239,0.000125,0.004562,0.115887,292.337280,14.892370,1.158874,-813.245239,294.500488,0.000000
137.000000,65.693581,-813.200745,0.000125,0.004562,0.115887,292.219635,14.886378,1.158874,-813.200745,294.500488,0.000000
137.389999,65.681664,-813.289734,0.000112,0.004562,0.115887,292.166626,14.883677,1.158874,-813.289734,294.500488,0.000000
137.780014,65.674965,-813.289734,0.000125,0.004562,0.115887,292.136841,14.882160,1.158874,-813.289734,294.500488,0.000000
138.170013,65.673103,-813.289734,0.000129,0.004562,0.115887,292.128540,14.881738,1.158874,-813.289734,294.500488,0.000000
138.560013,65.669746,-813.334167,0.000125,0.004562,0.115887,292.113617,14.880977,1.158874,-813.334167,294.500488,0.000000
138.950012,65.657463,-813.289734,0.000125,0.004562,0.115887,292.058990,14.878194,1.158874,-813.289734,294.500488,0.000000
139.340012,65.639961,-813.289734,0.000125,0.004562,0.115887,291.981140,14.874228,1.158874,-813.289734,294.500488,0.000000
139.730011,65.629158,-813.378662,0.000134,0.004562,0.115887,291.933075,14.871779,1.158874,-813.378662,294.500488,0.000000
140.120010,65.611656,-813.334167,0.000125,0.004562,0.115887,291.855225,14.867814,1.158874,-813.334167,294.500488,0.000000
140.510010,65.632881,-813.334167,0.000125,0.004561,0.115862,291.949646,14.872623,1.158617,-813.334167,0.115887,0.000000
140.900009,65.629539,-813.334167,0.000134,0.004549,0.115541,291.934784,14.871866,1.155407,-813.334167,0.115298,0.000000
141.290009,65.521538,-813.334167,0.000121,0.004531,0.115099,291.454346,14.847392,1.150987,-813.334167,0.114647,0.000000
141.680008,65.464195,-813.423157,0.000129,0.004509,0.114535,291.199280,14.834398,1.145355,-813.423157,0.113996,0.000000
142.070007,65.424355,-813.334167,0.000129,0.004483,0.113875,291.022064,14.825371,1.138754,-813.334167,0.113347,0.000000
142.460007,65.431801,-813.334167,0.000108,0.004459,0.113259,291.055176,14.827059,1.132592,-813.334167,0.112696,0.000000
142.850006,65.403496,-813.334167,0.000129,0.004436,0.112679,290.929291,14.820643,1.126794,-813.334167,0.112047,0.000000
143.240005,65.367012,-813.423157,0.000129,0.004405,0.111881,290.766998,14.812377,1.118815,-813.423157,0.111396,0.000000
143.630005,65.362541,-813.467651,0.000129,0.004385,0.111377,290.747101,14.811363,1.113773,-813.467651,0.110745,0.000000
144.020004,65.346153,-813.334167,0.000134,0.004360,0.110737,290.674194,14.807650,1.107369,-813.334167,0.110095,0.000000
144.410004,65.134651,-813.423157,0.000116,0.004335,0.110112,289.733398,14.759723,1.101117,-813.423157,0.109444,0.000000
144.800003,64.540337,-813.378662,0.000129,0.004310,0.109470,287.089752,14.625050,1.094698,-813.378662,0.108793,0.000000
145.190002,63.599358,-813.423157,0.000134,0.004285,0.108846,282.904083,14.411821,1.088460,-813.423157,0.108144,0.000000
145.580002,62.529160,-813.467651,0.000129,0.004263,0.108274,278.143585,14.169311,1.082737,-813.467651,0.107493,0.000000
145.970001,61.015091,-813.423157,0.000147,0.004237,0.107632,271.408691,13.826217,1.076318,-813.423157,0.106843,0.000000
146.360001,59.643646,-813.423157,0.000134,0.004215,0.107069,265.308197,13.515444,1.070686,-813.423157,0.106192,0.000000
146.750000,57.830566,-813.423157,0.000138,0.004194,0.106539,257.243195,13.104594,1.065387,-813.423157,0.105550,0.000000
147.139999,55.453339,-813.467651,0.000125,0.004166,0.105811,246.668762,12.565907,1.058105,-813.467651,0.104899,0.000000
147.530014,53.258202,-813.512085,0.000134,0.004143,0.105220,236.904312,12.068481,1.052201,-813.512085,0.104250,0.000000
147.920013,50.770378,-813.512085,0.000138,0.004116,0.104552,225.837921,11.504732,1.045524,-813.512085,0.103599,0.000000
148.310013,48.505241,-813.512085,0.000129,0.004098,0.104094,215.762085,10.991445,1.040937,-813.512085,0.102949,0.000000
148.700012,45.443596,-813.556580,0.000125,0.004071,0.103408,202.143204,10.297666,1.034079,-813.556580,0.102298,0.000000
149.090012,42.127617,-813.512085,0.000125,0.004041,0.102636,187.393005,9.546255,1.026358,-813.512085,0.101647,0.000000
149.480011,39.364616,-813.556580,0.000138,0.004016,0.102003,175.102554,8.920149,1.020029,-813.556580,0.100998,0.000000
149.870010,37.080109,-813.512085,0.000121,0.003997,0.101517,164.940567,8.402472,1.015169,-813.512085,0.100347,0.000000
150.260010,34.271675,-813.512085,0.000121,0.003968,0.100789,152.448029,7.766073,1.007887,-813.512085,0.099697,0.000000
150.650009,31.238327,-813.512085,0.000129,0.003943,0.100147,138.955017,7.078706,1.001468,-813.512085,0.099046,0.000000
151.040009,28.541977,-813.512085,0.000138,0.003918,0.099514,126.961052,6.467704,0.995140,-813.512085,0.098395,0.000000
151.430008,25.224144,-813.645569,0.000134,0.003887,0.098734,112.202599,5.715873,0.987343,-813.645569,0.097746,0.000000
151.820007,22.915062,-813.556580,0.000125,0.003869,0.098283,101.931290,5.192627,0.982831,-813.556580,0.097095,0.000000
152.210007,19.811707,-813.556580,0.000116,0.003838,0.097485,88.126869,4.489397,0.974853,-813.556580,0.096444,0.000000
152.600006,17.113869,-813.601074,0.000125,0.003816,0.096939,76.126289,3.878058,0.969387,-813.601074,0.095794,0.000000
152.990005,13.963600,-813.556580,0.000121,0.003787,0.096201,62.113197,3.164197,0.962014,-813.556580,0.095143,0.000000
153.380005,11.200966,-813.601074,0.000121,0.003762,0.095550,49.824383,2.538175,0.955504,-813.601074,0.094494,0.000000
153.770004,8.755226,-813.556580,0.000125,0.003741,0.095022,38.945190,1.983963,0.950221,-813.556580,0.093843,0.000000
154.160004,5.609421,-813.556580,0.000112,0.003710,0.094242,24.951950,1.271113,0.942424,-813.556580,0.093192,0.000000
154.550003,3.513336,-813.690063,0.000112,0.003692,0.093773,15.628099,0.796133,0.937730,-813.690063,0.092542,0.000000
154.940002,0.266991,-813.601074,0.000116,0.003658,0.092906,1.187634,0.060501,0.929055,-813.601074,0.091891,0.000000
155.330002,-1.448154,-813.645569,0.000121,0.003635,0.092317,-6.441713,-0.328156,0.923166,-813.645569,0.091242,0.000000
155.720001,-0.166077,-813.690063,0.000056,0.003614,0.091787,-0.738746,-0.037634,0.917867,-813.690063,0.090600,0.000000
156.110001,0.032402,-813.601074,0.000000,0.003588,0.091146,0.144131,0.007342,0.911463,-813.601074,0.089949,0.000000
156.500000,0.035004,-813.645569,-0.000026,0.003565,0.090556,0.155704,0.007932,0.905559,-813.645569,0.089298,0.000000
156.890015,0.013779,-813.645569,-0.000095,0.003527,0.089593,0.061291,0.003122,0.895930,-813.645569,0.088648,0.000000
157.280014,0.025696,-813.734497,-0.000138,0.003506,0.089046,0.114301,0.005823,0.890465,-813.734497,0.087997,0.000000
157.670013,0.101662,-813.601074,-0.000211,0.003475,0.088276,0.452214,0.023037,0.882759,-813.601074,0.087348,0.000000
158.060013,0.102036,-813.734497,-0.000276,0.003459,0.087850,0.453877,0.023122,0.878504,-813.734497,0.086697,0.000000
158.450012,0.112091,-813.734497,-0.000354,0.003431,0.087139,0.498606,0.025400,0.871389,-813.734497,0.086046,0.000000
158.840012,0.117302,-813.690063,-0.000435,0.003399,0.086332,0.521785,0.026581,0.863319,-813.690063,0.085396,0.000000
159.230011,0.131081,-813.734497,-0.000500,0.003382,0.085899,0.583076,0.029703,0.858989,-813.734497,0.084745,0.000000
159.620010,0.104271,-813.690063,-0.000569,0.003354,0.085180,0.463820,0.023628,0.851798,-813.690063,0.084096,0.000000
160.010010,0.055862,-813.734497,-0.000651,0.003329,0.084545,0.248488,0.012659,0.845455,-813.734497,0.083445,0.000000
160.400009,0.072243,-813.778992,-0.000707,0.003305,0.083957,0.321352,0.016370,0.839565,-813.778992,0.082794,0.000000
160.790009,0.082298,-813.734497,-0.000819,0.003268,0.083003,0.366081,0.018649,0.830027,-813.734497,0.082144,0.000000
161.180008,0.061813,-813.734497,-0.000880,0.003250,0.082561,0.274960,0.014007,0.825607,-813.734497,0.081493,0.000000
161.500015,0.126610,-813.734497,-0.000888,0.003243,0.082377,0.563189,0.028690,0.823775,-813.734497,0.082282,0.000000