File: Data/compression 35/ManualNoHeating-10-35-reverse-1-4_11182024_164618.csv
Time (sec),S:Load (lbs),S:HL1 (DIM),S:LVDT (in),S:Position (in),Ch:Position (mm),Ch:Load (N),Ch:Stress (MPa),Ch:Strain (mm/mm),Ch:HL1 (DIM),Set Point (),Cycles ()
0.110000,-0.130325,-805.016235,-0.010072,-0.005498,-0.139651,-0.579716,-0.029532,-1.396505,-805.016235,-0.139355,0.000000
0.480000,0.009315,-805.105225,-0.010059,-0.005450,-0.138427,0.041437,0.002111,-1.384272,-805.105225,-0.137760,0.000000
0.850000,-0.017502,-805.149719,-0.009973,-0.005226,-0.132747,-0.077852,-0.003966,-1.327469,-805.149719,-0.131602,0.000000
1.220000,-0.008560,-805.105225,-0.009735,-0.004997,-0.126920,-0.038078,-0.001940,-1.269196,-805.105225,-0.125427,0.000000
1.590000,-0.035744,-805.105225,-0.009490,-0.004751,-0.120667,-0.158996,-0.008100,-1.206670,-805.105225,-0.119270,0.000000
1.960000,-0.045425,-805.149719,-0.009244,-0.004506,-0.114449,-0.202062,-0.010294,-1.144492,-805.149719,-0.113112,0.000000
2.330000,-0.025688,-805.149719,-0.008959,-0.004260,-0.108197,-0.114267,-0.005821,-1.081965,-805.149719,-0.106938,0.000000
2.700000,0.001495,-805.194153,-0.008735,-0.004020,-0.102116,0.006652,0.000339,-1.021165,-805.194153,-0.100781,0.000000
3.070000,0.037239,-805.105225,-0.008476,-0.003779,-0.095977,0.165648,0.008438,-0.959774,-805.105225,-0.094606,0.000000
3.440000,0.004471,-805.149719,-0.008231,-0.003533,-0.089732,0.019887,0.001013,-0.897323,-805.149719,-0.088448,0.000000
3.810000,-0.011909,-805.194153,-0.008002,-0.003295,-0.083696,-0.052976,-0.002699,-0.836961,-805.194153,-0.082291,0.000000
4.180000,-0.034256,-805.238647,-0.007735,-0.003055,-0.077609,-0.152378,-0.007763,-0.776085,-805.238647,-0.076117,0.000000
4.550000,-0.062927,-805.238647,-0.007502,-0.002814,-0.071477,-0.279914,-0.014260,-0.714770,-805.238647,-0.069960,0.000000
4.920000,-0.016006,-805.149719,-0.007230,-0.002569,-0.065259,-0.071200,-0.003627,-0.652592,-805.149719,-0.063785,0.000000
5.290000,-0.015266,-805.194153,-0.006976,-0.002325,-0.059067,-0.067908,-0.003459,-0.590671,-805.194153,-0.057627,0.000000
5.660000,-0.031273,-805.194153,-0.006748,-0.002078,-0.052780,-0.139109,-0.007087,-0.527796,-805.194153,-0.051470,0.000000
6.030000,-0.023827,-805.149719,-0.006476,-0.001838,-0.046675,-0.105986,-0.005399,-0.466753,-805.149719,-0.045296,0.000000
6.400000,-0.037979,-805.283142,-0.006230,-0.001594,-0.040500,-0.168940,-0.008606,-0.404999,-805.283142,-0.039139,0.000000
6.770000,0.012291,-805.238647,-0.005980,-0.001354,-0.034396,0.054673,0.002785,-0.343956,-805.238647,-0.032982,0.000000
7.140000,0.046921,-805.149719,-0.005734,-0.001101,-0.027978,0.208714,0.010632,-0.279779,-805.149719,-0.026806,0.000000
7.510000,0.037613,-805.327637,-0.005476,-0.000865,-0.021958,0.167311,0.008523,-0.219584,-805.327637,-0.020649,0.000000
7.880001,-0.016754,-805.327637,-0.005234,-0.000628,-0.015940,-0.074526,-0.003797,-0.159405,-805.327637,-0.014475,0.000000
8.250000,-0.013771,-805.372070,-0.004980,-0.000380,-0.009653,-0.061257,-0.003121,-0.096530,-805.372070,-0.008318,0.000000
8.620001,-0.078568,-805.238647,-0.004747,-0.000151,-0.003826,-0.349486,-0.017804,-0.038258,-805.238647,-0.002160,0.000000
8.990001,0.040222,-805.238647,-0.004506,0.000099,0.002522,0.178917,0.009114,0.025223,-805.238647,0.004015,0.000000
9.360001,0.035004,-805.283142,-0.004458,-0.000000,-0.000000,0.155704,0.007932,-0.000000,-805.283142,0.000235,0.000000
9.730000,0.112831,-805.283142,-0.004437,-0.000000,-0.000000,0.501898,0.025568,-0.000000,-805.283142,0.000477,0.000000
10.100000,0.088631,-805.327637,-0.004432,0.000000,0.000009,0.394249,0.020084,0.000091,-805.327637,0.001093,0.000000
10.470000,0.154541,-805.327637,-0.004424,0.000020,0.000503,0.687433,0.035019,0.005026,-805.327637,0.001708,0.000000
10.840000,0.195129,-805.327637,-0.004406,0.000040,0.001014,0.867979,0.044217,0.010144,-805.327637,0.002324,0.000000
11.210001,0.293808,-805.327637,-0.004381,0.000072,0.001830,1.306923,0.066578,0.018304,-805.327637,0.002940,0.000000
11.580001,0.424133,-805.327637,-0.004363,0.000093,0.002350,1.886639,0.096110,0.023497,-805.327637,0.003564,0.000000
11.950001,0.608086,-805.416565,-0.004324,0.000123,0.003122,2.704900,0.137794,0.031218,-805.416565,0.004180,0.000000
12.320001,0.859070,-805.372070,-0.004294,0.000154,0.003903,3.821333,0.194668,0.039030,-805.372070,0.004796,0.000000
12.690001,1.067223,-805.372070,-0.004251,0.000179,0.004543,4.747243,0.241836,0.045434,-805.372070,0.005411,0.000000
13.060000,1.173721,-805.416565,-0.004234,0.000201,0.005099,5.220973,0.265969,0.050990,-805.416565,0.006027,0.000000
13.430000,1.342781,-805.416565,-0.004230,0.000222,0.005636,5.972989,0.304279,0.056365,-805.416565,0.006643,0.000000
13.800000,1.577744,-805.372070,-0.004204,0.000246,0.006253,7.018154,0.357522,0.062526,-805.372070,0.007258,0.000000
14.170001,1.836174,-805.461060,-0.004169,0.000268,0.006808,8.167710,0.416083,0.068083,-805.461060,0.007874,0.000000
14.540001,1.966133,-805.461060,-0.004152,0.000285,0.007250,8.745797,0.445532,0.072503,-805.461060,0.008490,0.000000
14.910001,2.203331,-805.372070,-0.004152,0.000308,0.007823,9.800906,0.499282,0.078226,-805.372070,0.009114,0.000000
15.280001,2.433830,-805.461060,-0.004135,0.000336,0.008525,10.826218,0.551514,0.085251,-805.461060,0.009730,0.000000
15.650001,2.850517,-805.461060,-0.004079,0.000360,0.009149,12.679734,0.645936,0.091488,-805.461060,0.010346,0.000000
16.020000,3.011009,-805.461060,-0.004066,0.000389,0.009869,13.393638,0.682304,0.098695,-805.461060,0.010961,0.000000
16.390001,3.190865,-805.461060,-0.004040,0.000405,0.010277,14.193674,0.723060,0.102767,-805.461060,0.011577,0.000000
16.760000,3.378166,-805.416565,-0.004023,0.000425,0.010788,15.026834,0.765503,0.107885,-805.416565,0.012193,0.000000
17.130001,3.690956,-805.505554,-0.004005,0.000451,0.011465,16.418192,0.836383,0.114652,-805.505554,0.012808,0.000000
17.500000,4.127380,-805.416565,-0.003967,0.000483,0.012263,18.359505,0.935278,0.122631,-805.416565,0.013424,0.000000
17.870001,4.286758,-805.550049,-0.003932,0.000510,0.012956,19.068455,0.971393,0.129565,-805.550049,0.014040,0.000000
18.240002,4.506081,-805.461060,-0.003915,0.000531,0.013485,20.044048,1.021092,0.134848,-805.461060,0.014664,0.000000
18.610001,4.774567,-805.416565,-0.003902,0.000555,0.014101,21.238333,1.081932,0.141010,-805.416565,0.015280,0.000000
18.980001,4.884041,-805.505554,-0.003867,0.000578,0.014682,21.725298,1.106739,0.146824,-805.505554,0.015897,0.000000
19.350000,4.920906,-805.505554,-0.003837,0.000595,0.015124,21.889284,1.115093,0.151244,-805.505554,0.016511,0.000000
19.720001,5.161087,-805.505554,-0.003820,0.000620,0.015757,22.957663,1.169519,0.157573,-805.505554,0.017127,0.000000
20.090000,5.544258,-805.461060,-0.003786,0.000651,0.016538,24.662092,1.256347,0.165385,-805.461060,0.017744,0.000000
20.460001,5.582237,-805.550049,-0.003760,0.000671,0.017041,24.831032,1.264953,0.170411,-805.550049,0.018358,0.000000
20.830002,5.962433,-805.550049,-0.003729,0.000703,0.017848,26.522226,1.351107,0.178481,-805.550049,0.018974,0.000000
21.200001,6.062973,-805.638977,-0.003704,0.000721,0.018307,26.969452,1.373889,0.183068,-805.638977,0.019591,0.000000
21.570002,6.157555,-805.550049,-0.003682,0.000742,0.018837,27.390171,1.395322,0.188367,-805.550049,0.020214,0.000000
21.940001,6.519501,-805.505554,-0.003652,0.000774,0.019668,29.000187,1.477340,0.196678,-805.505554,0.020831,0.000000
22.310001,6.427155,-805.550049,-0.003617,0.000795,0.020198,28.589411,1.456414,0.201977,-805.550049,0.021447,0.000000
22.680000,6.863945,-805.550049,-0.003600,0.000827,0.020996,30.532352,1.555392,0.209956,-805.550049,0.022061,0.000000
23.050001,6.976028,-805.594482,-0.003561,0.000849,0.021577,31.030924,1.580791,0.215769,-805.594482,0.022678,0.000000
23.420002,7.093323,-805.594482,-0.003544,0.000873,0.022175,31.552675,1.607370,0.221749,-805.594482,0.023294,0.000000
23.790001,7.259407,-805.594482,-0.003488,0.000896,0.022756,32.291454,1.645005,0.227563,-805.594482,0.023910,0.000000
24.160002,7.403885,-805.550049,-0.003475,0.000925,0.023501,32.934124,1.677744,0.235012,-805.550049,0.024525,0.000000
24.530001,7.506287,-805.550049,-0.003436,0.000945,0.023996,33.389629,1.700949,0.239962,-805.550049,0.025141,0.000000
24.900002,7.441498,-805.683472,-0.003436,0.000966,0.024534,33.101437,1.686267,0.245337,-805.683472,0.025765,0.000000
25.270000,7.549110,-805.683472,-0.003410,0.000984,0.024994,33.580120,1.710653,0.249939,-805.683472,0.026381,0.000000
25.640001,8.168739,-805.683472,-0.003359,0.001023,0.025990,36.336369,1.851063,0.259901,-805.683472,0.026997,0.000000
26.010002,7.890205,-805.594482,-0.003324,0.001039,0.026390,35.097385,1.787946,0.263898,-805.594482,0.027612,0.000000
26.380001,8.316566,-805.727966,-0.003307,0.001071,0.027204,36.993935,1.884561,0.272043,-805.727966,0.028228,0.000000
26.750002,8.045486,-805.683472,-0.003255,0.001088,0.027630,35.788113,1.823133,0.276297,-805.683472,0.028844,0.000000
27.120001,8.013084,-805.727966,-0.003247,0.001106,0.028081,35.643978,1.815791,0.280809,-805.727966,0.029460,0.000000
27.490002,8.530312,-805.727966,-0.003203,0.001138,0.028914,37.944721,1.932996,0.289136,-805.727966,0.030075,0.000000
27.860001,8.571648,-805.683472,-0.003173,0.001164,0.029563,38.128593,1.942363,0.295631,-805.683472,0.030691,0.000000
28.230001,8.431259,-805.683472,-0.003143,0.001187,0.030153,37.504112,1.910551,0.301535,-805.683472,0.031315,0.000000
28.600002,8.524353,-805.727966,-0.003109,0.001211,0.030752,37.918217,1.931646,0.307515,-805.727966,0.031931,0.000000
28.970001,8.430885,-805.772400,-0.003091,0.001227,0.031159,37.502449,1.910466,0.311588,-805.772400,0.032547,0.000000
29.340002,8.928009,-805.772400,-0.003040,0.001262,0.032052,39.713768,2.023116,0.320520,-805.772400,0.033163,0.000000
29.710001,8.898216,-805.772400,-0.003009,0.001288,0.032720,39.581242,2.016365,0.327197,-805.772400,0.033778,0.000000
30.080002,8.718735,-805.683472,-0.002984,0.001306,0.033180,38.782867,1.975693,0.331799,-805.683472,0.034394,0.000000
30.450001,8.844963,-805.816895,-0.002953,0.001331,0.033796,39.344360,2.004297,0.337961,-805.816895,0.035010,0.000000
30.820002,8.796188,-805.816895,-0.002945,0.001350,0.034281,39.127399,1.993245,0.342806,-805.816895,0.035625,0.000000
31.190001,9.146217,-805.727966,-0.002893,0.001383,0.035131,40.684406,2.072562,0.351314,-805.727966,0.036241,0.000000
31.560001,9.051636,-805.861389,-0.002841,0.001407,0.035738,40.263687,2.051130,0.357385,-805.861389,0.036865,0.000000
31.930002,8.760063,-805.772400,-0.002815,0.001424,0.036181,38.966705,1.985059,0.361806,-805.772400,0.037481,0.000000
32.300003,9.022217,-805.772400,-0.002781,0.001453,0.036918,40.132824,2.044464,0.369179,-805.772400,0.038097,0.000000
32.670002,8.957054,-805.861389,-0.002742,0.001477,0.037507,39.842968,2.029697,0.375068,-805.861389,0.038713,0.000000
33.040001,8.897469,-805.905884,-0.002716,0.001500,0.038097,39.577915,2.016195,0.380972,-805.905884,0.039328,0.000000
33.410000,9.294792,-805.861389,-0.002665,0.001532,0.038921,41.345299,2.106230,0.389208,-805.861389,0.039944,0.000000
33.780003,9.131317,-805.772400,-0.002639,0.001558,0.039572,40.618126,2.069186,0.395718,-805.772400,0.040560,0.000000
34.150002,9.071739,-805.816895,-0.002591,0.001586,0.040274,40.353111,2.055686,0.402743,-805.816895,0.041175,0.000000
34.520000,8.840874,-805.905884,-0.002561,0.001607,0.040821,39.326172,2.003371,0.408208,-805.905884,0.041800,0.000000
34.890003,8.993172,-805.861389,-0.002535,0.001631,0.041436,40.003624,2.037882,0.414355,-805.861389,0.042417,0.000000
35.260002,8.897842,-805.905884,-0.002501,0.001654,0.042000,39.579578,2.016280,0.420002,-805.905884,0.043031,0.000000
35.630001,8.899330,-805.861389,-0.002466,0.001671,0.042450,39.586197,2.016617,0.424499,-805.861389,0.043647,0.000000
36.000000,8.738098,-805.816895,-0.002449,0.001685,0.042806,38.869003,1.980081,0.428056,-805.816895,0.044264,0.000000
36.370003,9.391609,-805.905884,-0.002402,0.001723,0.043752,41.775963,2.128169,0.437519,-805.905884,0.044878,0.000000
36.740002,8.913109,-805.950378,-0.002367,0.001735,0.044073,39.647488,2.019739,0.440728,-805.950378,0.045494,0.000000
37.110001,9.002853,-805.950378,-0.002337,0.001761,0.044731,40.046692,2.040076,0.447314,-805.950378,0.046111,0.000000
37.480003,9.086639,-805.905884,-0.002311,0.001789,0.045451,40.419392,2.059062,0.454505,-805.905884,0.046725,0.000000
37.850002,9.394218,-805.950378,-0.002289,0.001820,0.046232,41.787571,2.128760,0.462317,-805.950378,0.047351,0.000000
38.220001,9.204681,-805.905884,-0.002242,0.001837,0.046648,40.944469,2.085811,0.466481,-805.905884,0.047967,0.000000
38.590000,9.286598,-805.950378,-0.002216,0.001861,0.047281,41.308853,2.104373,0.472809,-805.950378,0.048581,0.000000
38.960003,9.616898,-805.994812,-0.002182,0.001893,0.048088,42.778095,2.179220,0.480878,-805.994812,0.049198,0.000000
39.330002,9.446724,-805.994812,-0.002117,0.001916,0.048669,42.021126,2.140658,0.486692,-805.994812,0.049814,0.000000
39.700001,9.262772,-806.039307,-0.002108,0.001936,0.049181,41.202866,2.098974,0.491809,-806.039307,0.050428,0.000000
40.070004,9.696213,-805.994812,-0.002082,0.001968,0.049977,43.130909,2.197193,0.499773,-805.994812,0.051045,0.000000
40.440002,9.480606,-805.994812,-0.002044,0.001989,0.050516,42.171841,2.148336,0.505162,-805.994812,0.051661,0.000000
40.810001,9.167068,-806.039307,-0.002018,0.002004,0.050898,40.777157,2.077287,0.508978,-806.039307,0.052275,0.000000
41.180000,10.022781,-805.994812,-0.001983,0.002041,0.051833,44.583557,2.271195,0.518334,-805.994812,0.052901,0.000000
41.550003,9.821327,-805.994812,-0.001923,0.002063,0.052389,43.687447,2.225545,0.523890,-805.994812,0.053517,0.000000
41.920002,9.953888,-806.039307,-0.001914,0.002086,0.052987,44.277103,2.255583,0.529870,-806.039307,0.054132,0.000000
42.290001,9.664185,-806.083801,-0.001888,0.002104,0.053447,42.988441,2.189935,0.534473,-806.083801,0.054748,0.000000
42.660004,9.848137,-806.083801,-0.001837,0.002132,0.054157,43.806702,2.231620,0.541573,-806.083801,0.055364,0.000000
43.030003,10.206360,-806.083801,-0.001802,0.002161,0.054887,45.400158,2.312794,0.548870,-806.083801,0.055979,0.000000
43.400002,10.104706,-806.039307,-0.001768,0.002186,0.055529,44.947975,2.289759,0.555290,-806.039307,0.056595,0.000000
43.770000,10.081245,-806.039307,-0.001733,0.002207,0.056057,44.843620,2.284443,0.560573,-806.039307,0.057211,0.000000
44.140003,9.975487,-806.083801,-0.001712,0.002231,0.056674,44.373180,2.260478,0.566735,-806.083801,0.057827,0.000000
44.510002,10.161301,-806.128296,-0.001673,0.002260,0.057402,45.199722,2.302584,0.574017,-806.128296,0.058451,0.000000
44.880001,10.205246,-806.128296,-0.001643,0.002284,0.058018,45.395203,2.312542,0.580179,-806.128296,0.059067,0.000000
45.250004,10.220512,-806.128296,-0.001591,0.002309,0.058642,45.463108,2.316001,0.586416,-806.128296,0.059682,0.000000
45.620003,10.074165,-806.128296,-0.001569,0.002331,0.059197,44.812126,2.282839,0.591973,-806.128296,0.060298,0.000000
45.990002,10.110291,-806.128296,-0.001544,0.002352,0.059742,44.972816,2.291025,0.597423,-806.128296,0.060914,0.000000
46.360001,10.336693,-806.172729,-0.001513,0.002377,0.060377,45.979904,2.342328,0.603766,-806.172729,0.061529,0.000000
46.730003,10.236519,-806.172729,-0.001483,0.002394,0.060801,45.534309,2.319628,0.608006,-806.172729,0.062145,0.000000
47.100002,10.608147,-806.128296,-0.001427,0.002428,0.061659,47.187393,2.403840,0.616590,-806.128296,0.062761,0.000000
47.470001,10.281204,-806.172729,-0.001401,0.002447,0.062145,45.733082,2.329754,0.621449,-806.172729,0.063377,0.000000
47.840004,10.675179,-806.172729,-0.001375,0.002479,0.062961,47.485565,2.419030,0.629610,-806.172729,0.064001,0.000000
48.210003,10.185509,-806.172729,-0.001354,0.002494,0.063342,45.307407,2.308069,0.633425,-806.172729,0.064617,0.000000
48.580002,10.009377,-806.217224,-0.001311,0.002508,0.063698,44.523930,2.268157,0.636983,-806.217224,0.065232,0.000000
48.950001,10.682999,-806.261719,-0.001268,0.002540,0.064513,47.520351,2.420802,0.645128,-806.261719,0.065848,0.000000
49.320004,11.311188,-806.128296,-0.001220,0.002582,0.065571,50.314674,2.563152,0.655710,-806.128296,0.066464,0.000000
49.690002,10.495697,-806.172729,-0.001181,0.002594,0.065883,46.687191,2.378359,0.658829,-806.172729,0.067080,0.000000
50.060001,10.267426,-806.172729,-0.001186,0.002610,0.066283,45.671791,2.326632,0.662826,-806.172729,0.067695,0.000000
50.430004,11.152931,-806.306213,-0.001143,0.002644,0.067167,49.610714,2.527290,0.671667,-806.306213,0.068311,0.000000
50.800003,11.207672,-806.350708,-0.001112,0.002671,0.067843,49.854214,2.539695,0.678435,-806.350708,0.068927,0.000000
51.170002,11.164101,-806.261719,-0.001069,0.002693,0.068407,49.660400,2.529821,0.684067,-806.261719,0.069551,0.000000
51.540001,10.809235,-806.261719,-0.001035,0.002710,0.068832,48.081879,2.449408,0.688321,-806.261719,0.070167,0.000000
51.910004,11.628075,-806.261719,-0.001009,0.002740,0.069595,51.724258,2.634959,0.695951,-806.261719,0.070782,0.000000
52.280003,11.433701,-806.350708,-0.000979,0.002761,0.070124,50.859642,2.590914,0.701235,-806.350708,0.071398,0.000000
52.650002,11.945709,-806.350708,-0.000940,0.002790,0.070870,53.137169,2.706936,0.708699,-806.350708,0.072014,0.000000
53.020004,12.020927,-806.261719,-0.000914,0.002817,0.071554,53.471756,2.723981,0.715542,-806.261719,0.072631,0.000000
53.390003,12.006409,-806.261719,-0.000884,0.002837,0.072066,53.407173,2.720691,0.720659,-806.261719,0.073245,0.000000
53.760002,12.474106,-806.261719,-0.000854,0.002865,0.072759,55.487595,2.826673,0.727593,-806.261719,0.073861,0.000000
54.130001,12.249565,-806.395142,-0.000819,0.002882,0.073203,54.488789,2.775791,0.732029,-806.395142,0.074478,0.000000
54.500004,12.776848,-806.439636,-0.000802,0.002907,0.073836,56.834259,2.895275,0.738357,-806.439636,0.075101,0.000000
54.870003,13.183479,-806.350708,-0.000755,0.002939,0.074650,58.643044,2.987419,0.746502,-806.350708,0.075718,0.000000
55.240002,12.920586,-806.350708,-0.000724,0.002956,0.075092,57.473637,2.927846,0.750923,-806.350708,0.076334,0.000000
55.610004,13.625481,-806.350708,-0.000707,0.002992,0.076004,60.609165,3.087578,0.760037,-806.350708,0.076948,0.000000
55.980003,13.904762,-806.350708,-0.000673,0.003017,0.076620,61.851471,3.150864,0.766199,-806.350708,0.077565,0.000000
56.350002,14.082756,-806.306213,-0.000634,0.003039,0.077183,62.643227,3.191198,0.771831,-806.306213,0.078181,0.000000
56.720001,14.337090,-806.395142,-0.000625,0.003061,0.077737,63.774559,3.248831,0.777372,-806.395142,0.078795,0.000000
57.090004,14.143829,-806.395142,-0.000586,0.003076,0.078128,62.914894,3.205038,0.781278,-806.395142,0.079412,0.000000
57.460003,14.316238,-806.350708,-0.000582,0.003091,0.078502,63.681808,3.244106,0.785017,-806.350708,0.080028,0.000000
57.830002,15.179398,-806.439636,-0.000560,0.003121,0.079272,67.521332,3.439701,0.792724,-806.439636,0.080652,0.000000
58.200005,16.426468,-806.484131,-0.000539,0.003156,0.080166,73.068581,3.722291,0.801656,-806.484131,0.081268,0.000000
58.570004,16.306190,-806.573059,-0.000496,0.003179,0.080756,72.533554,3.695035,0.807560,-806.573059,0.081884,0.000000
58.940002,16.561272,-806.484131,-0.000483,0.003200,0.081277,73.668213,3.752838,0.812768,-806.484131,0.082499,0.000000
59.310001,17.134720,-806.484131,-0.000461,0.003227,0.081961,76.219040,3.882783,0.819611,-806.484131,0.083115,0.000000
59.680004,17.591995,-806.439636,-0.000431,0.003248,0.082491,78.253105,3.986403,0.824910,-806.439636,0.083731,0.000000
60.050003,18.219818,-806.484131,-0.000405,0.003276,0.083201,81.045799,4.128670,0.832011,-806.484131,0.084346,0.000000
60.420002,18.966797,-806.528625,-0.000375,0.003302,0.083869,84.368523,4.297938,0.838687,-806.528625,0.084962,0.000000
60.790005,19.099358,-806.484131,-0.000354,0.003324,0.084424,84.958183,4.327977,0.844244,-806.484131,0.085586,0.000000
61.160004,19.771492,-806.484131,-0.000336,0.003351,0.085109,87.947990,4.480284,0.851087,-806.484131,0.086202,0.000000
61.530003,20.458519,-806.528625,-0.000302,0.003375,0.085734,91.004036,4.635967,0.857339,-806.528625,0.086818,0.000000
61.900002,20.504318,-806.528625,-0.000297,0.003389,0.086072,91.207764,4.646345,0.860715,-806.528625,0.087434,0.000000
62.270004,21.390938,-806.528625,-0.000285,0.003413,0.086688,95.151642,4.847256,0.866877,-806.528625,0.088049,0.000000
62.640003,22.732224,-806.617554,-0.000263,0.003445,0.087502,101.117981,5.151196,0.875022,-806.617554,0.088665,0.000000
63.010002,22.938148,-806.528625,-0.000233,0.003466,0.088049,102.033981,5.197859,0.880488,-806.528625,0.089281,0.000000
63.380005,23.894028,-806.528625,-0.000233,0.003491,0.088682,106.285942,5.414464,0.886816,-806.528625,0.089896,0.000000
63.750004,25.088226,-806.573059,-0.000203,0.003517,0.089324,111.598007,5.685073,0.893235,-806.573059,0.090512,0.000000
64.120003,25.517197,-806.573059,-0.000190,0.003538,0.089853,113.506157,5.782279,0.898534,-806.573059,0.091137,0.000000
64.490005,27.307190,-806.617554,-0.000151,0.003570,0.090677,121.468445,6.187898,0.906770,-806.617554,0.091752,0.000000
64.860001,27.475876,-806.573059,-0.000142,0.003588,0.091128,122.218803,6.226122,0.911282,-806.573059,0.092368,0.000000
65.230003,28.559113,-806.573059,-0.000108,0.003611,0.091717,127.037277,6.471588,0.917171,-806.573059,0.092984,0.000000
65.600006,29.816986,-806.573059,-0.000099,0.003639,0.092420,132.632584,6.756626,0.924196,-806.573059,0.093599,0.000000
65.970001,30.687965,-806.617554,-0.000091,0.003661,0.092984,136.506882,6.953992,0.929843,-806.617554,0.094215,0.000000
66.340004,32.436623,-806.662048,-0.000073,0.003693,0.093799,144.285309,7.350244,0.937988,-806.662048,0.094831,0.000000
66.710007,33.412613,-806.662048,-0.000047,0.003714,0.094345,148.626724,7.571406,0.943453,-806.662048,0.095446,0.000000
67.080002,34.132782,-806.662048,-0.000043,0.003735,0.094866,151.830200,7.734599,0.948661,-806.662048,0.096062,0.000000
67.450005,35.125900,-806.617554,-0.000026,0.003759,0.095473,156.247803,7.959643,0.954732,-806.617554,0.096687,0.000000
67.820000,36.126831,-806.617554,-0.000026,0.003777,0.095924,160.700165,8.186457,0.959244,-806.617554,0.097302,0.000000
68.190002,38.544647,-806.662048,-0.000004,0.003811,0.096799,171.455154,8.734342,0.967994,-806.662048,0.097918,0.000000
68.560005,39.514679,-806.706543,0.000009,0.003831,0.097311,175.770065,8.954154,0.973112,-806.706543,0.098534,0.000000
68.930000,40.036003,-806.662048,0.000026,0.003853,0.097858,178.089035,9.072289,0.978577,-806.662048,0.099149,0.000000
69.300003,42.486214,-806.617554,0.000043,0.003881,0.098569,188.988113,9.627514,0.985693,-806.617554,0.099765,0.000000
69.670006,42.962845,-806.706543,0.000043,0.003895,0.098942,191.108276,9.735519,0.989417,-806.706543,0.100381,0.000000
70.040001,44.646713,-806.706543,0.000060,0.003926,0.099714,198.598495,10.117090,0.997138,-806.706543,0.100998,0.000000
70.410004,47.276039,-806.706543,0.000073,0.003954,0.100424,210.294327,10.712903,1.004239,-806.706543,0.101612,0.000000
70.780006,49.452187,-806.617554,0.000099,0.003983,0.101179,219.974319,11.206025,1.011793,-806.617554,0.102238,0.000000
71.150002,49.854721,-806.706543,0.000099,0.004002,0.101647,221.764877,11.297241,1.016471,-806.706543,0.102852,0.000000
71.520004,51.268616,-806.706543,0.000103,0.004019,0.102073,228.054199,11.617635,1.020726,-806.706543,0.103468,0.000000
71.890007,53.697227,-806.751038,0.000103,0.004048,0.102817,238.857193,12.167966,1.028174,-806.751038,0.104085,0.000000
72.260002,56.027908,-806.706543,0.000134,0.004078,0.103573,249.224579,12.696105,1.035729,-806.706543,0.104699,0.000000
72.630005,57.118217,-806.706543,0.000134,0.004097,0.104066,254.074524,12.943173,1.040664,-806.706543,0.105315,0.000000
73.000000,58.189156,-806.706543,0.000155,0.004117,0.104571,258.838287,13.185851,1.045706,-806.706543,0.105932,0.000000
73.370003,60.402168,-806.795471,0.000155,0.004143,0.105238,268.682251,13.687327,1.052382,-806.795471,0.106548,0.000000
73.740005,62.777901,-806.795471,0.000168,0.004170,0.105906,279.250061,14.225676,1.059059,-806.795471,0.107162,0.000000
74.110001,64.751854,-806.839966,0.000181,0.004193,0.106495,288.030640,14.672979,1.064948,-806.839966,0.107788,0.000000
74.480003,65.822426,-806.795471,0.000194,0.004201,0.106711,292.792786,14.915575,1.067113,-806.795471,0.018732,0.000000
74.850006,65.160713,-806.795471,0.000194,0.004201,0.106704,289.849335,14.765629,1.067038,-806.795471,294.500488,0.000000
75.220001,65.074699,-806.751038,0.000185,0.004211,0.106964,289.466705,14.746138,1.069642,-806.751038,294.500488,0.000000
75.590004,65.508888,-806.795471,0.000207,0.004222,0.107241,291.398102,14.844526,1.072412,-806.795471,294.500488,0.000000
75.960007,65.428078,-806.795471,0.000203,0.004222,0.107232,291.038635,14.826214,1.072321,-806.795471,294.500488,0.000000
76.330002,65.189018,-806.839966,0.000211,0.004222,0.107241,289.975250,14.772042,1.072412,-806.839966,294.500488,0.000000
76.700005,64.993889,-806.795471,0.000216,0.004224,0.107284,289.107269,14.727826,1.072836,-806.795471,294.500488,0.000000
77.070007,65.505165,-806.839966,0.000211,0.004231,0.107467,291.381531,14.843682,1.074668,-806.839966,294.500488,0.000000
77.440002,65.371101,-806.928955,0.000224,0.004231,0.107467,290.785187,14.813304,1.074668,-806.928955,294.500488,0.000000
77.810005,65.244133,-806.928955,0.000220,0.004231,0.107474,290.220398,14.784533,1.074744,-806.928955,294.500488,0.000000
78.180000,65.057945,-806.928955,0.000211,0.004231,0.107474,289.392181,14.742341,1.074744,-806.928955,294.500488,0.000000
78.550003,64.933189,-806.928955,0.000220,0.004231,0.107474,288.837250,14.714071,1.074744,-806.928955,294.500488,0.000000
78.920006,64.782753,-806.884460,0.000220,0.004231,0.107474,288.168091,14.679982,1.074744,-806.884460,294.500488,0.000000
79.290001,65.532341,-806.928955,0.000220,0.004241,0.107718,291.502411,14.849841,1.077181,-806.928955,294.500488,0.000000
79.660004,65.480217,-806.928955,0.000229,0.004241,0.107718,291.270538,14.838030,1.077181,-806.928955,294.500488,0.000000
80.030006,65.385628,-806.928955,0.000233,0.004241,0.107718,290.849792,14.816595,1.077181,-806.928955,294.500488,0.000000
80.400002,65.305199,-806.884460,0.000237,0.004241,0.107718,290.492035,14.798369,1.077181,-806.884460,294.500488,0.000000
80.770004,65.238167,-806.973389,0.000211,0.004241,0.107718,290.193848,14.783179,1.077181,-806.973389,294.500488,0.000000
81.140007,65.129066,-806.928955,0.000229,0.004241,0.107718,289.708557,14.758457,1.077181,-806.928955,294.500488,0.000000
81.510002,65.048637,-806.928955,0.000233,0.004241,0.107718,289.350800,14.740232,1.077181,-806.928955,294.500488,0.000000
81.880005,64.977882,-806.973389,0.000229,0.004241,0.107718,289.036041,14.724199,1.077181,-806.973389,294.500488,0.000000
82.250008,64.903038,-806.973389,0.000220,0.004241,0.107727,288.703125,14.707239,1.077272,-806.973389,294.500488,0.000000
82.620003,64.830788,-806.973389,0.000216,0.004241,0.107727,288.381744,14.690866,1.077272,-806.973389,294.500488,0.000000
82.990005,65.660072,-807.062378,0.000233,0.004252,0.107995,292.070587,14.878785,1.079952,-807.062378,294.500488,0.000000
83.360001,65.679802,-807.017883,0.000241,0.004252,0.107995,292.158356,14.883256,1.079952,-807.017883,294.500488,0.000000
83.730003,65.666023,-806.973389,0.000229,0.004252,0.107995,292.097046,14.880134,1.079952,-806.973389,294.500488,0.000000
84.100006,65.621712,-807.062378,0.000233,0.004252,0.107995,291.899963,14.870092,1.079952,-807.062378,294.500488,0.000000
84.470001,65.582619,-806.973389,0.000237,0.004252,0.107995,291.726044,14.861234,1.079952,-806.973389,294.500488,0.000000
84.840004,65.552086,-807.017883,0.000237,0.004252,0.107995,291.590240,14.854316,1.079952,-807.017883,294.500488,0.000000
85.210007,65.489143,-807.017883,0.000254,0.004252,0.107995,291.310272,14.840053,1.079952,-807.017883,294.500488,0.000000
85.580002,65.444832,-807.017883,0.000246,0.004252,0.107995,291.113159,14.830010,1.079952,-807.017883,294.500488,0.000000
85.950005,65.359566,-807.062378,0.000233,0.004252,0.107995,290.733856,14.810689,1.079952,-807.062378,294.500488,0.000000
86.320007,65.324928,-807.062378,0.000229,0.004252,0.107995,290.579803,14.802840,1.079952,-807.062378,294.500488,0.000000
86.690002,65.275780,-807.062378,0.000233,0.004252,0.107995,290.361176,14.791703,1.079952,-807.062378,294.500488,0.000000
87.060005,65.244133,-807.062378,0.000237,0.004252,0.107995,290.220398,14.784533,1.079952,-807.062378,294.500488,0.000000
87.430008,65.189766,-807.062378,0.000237,0.004252,0.107995,289.978577,14.772212,1.079952,-807.062378,294.500488,0.000000
87.800003,65.140984,-807.017883,0.000246,0.004252,0.107995,289.761566,14.761158,1.079952,-807.017883,294.500488,0.000000
88.170006,65.090706,-807.106873,0.000233,0.004252,0.107995,289.537933,14.749764,1.079952,-807.106873,294.500488,0.000000
88.540001,65.051613,-807.151367,0.000233,0.004252,0.107995,289.364014,14.740906,1.079952,-807.151367,294.500488,0.000000
88.910004,65.011024,-807.151367,0.000237,0.004252,0.107995,289.183472,14.731709,1.079952,-807.151367,294.500488,0.000000
89.280006,64.991280,-807.106873,0.000250,0.004252,0.107995,289.095642,14.727234,1.079952,-807.106873,294.500488,0.000000
89.650002,64.939903,-807.062378,0.000241,0.004252,0.107995,288.867126,14.715592,1.079952,-807.062378,294.500488,0.000000
90.020004,64.915321,-807.151367,0.000224,0.004252,0.107995,288.757782,14.710022,1.079952,-807.151367,294.500488,0.000000
90.390007,64.958138,-807.195801,0.000241,0.004255,0.108065,288.948212,14.719725,1.080648,-807.195801,294.500488,0.000000
90.760002,64.972664,-807.106873,0.000237,0.004255,0.108065,289.012848,14.723016,1.080648,-807.106873,294.500488,0.000000
91.130005,64.962608,-807.151367,0.000250,0.004255,0.108065,288.968109,14.720737,1.080648,-807.151367,294.500488,0.000000
91.500008,64.947350,-807.062378,0.000233,0.004255,0.108065,288.900238,14.717279,1.080648,-807.062378,294.500488,0.000000
91.870003,64.919411,-807.062378,0.000233,0.004255,0.108065,288.775970,14.710948,1.080648,-807.062378,294.500488,0.000000
92.240005,64.901543,-807.151367,0.000237,0.004255,0.108065,288.696472,14.706901,1.080648,-807.151367,294.500488,0.000000
92.610001,65.416908,-807.240295,0.000237,0.004264,0.108299,290.988953,14.823683,1.082995,-807.240295,294.500488,0.000000
92.980003,65.578514,-807.151367,0.000246,0.004263,0.108272,291.707794,14.860304,1.082722,-807.151367,294.500488,0.000000
93.350006,65.594536,-807.195801,0.000250,0.004263,0.108272,291.779053,14.863934,1.082722,-807.195801,294.500488,0.000000
93.720001,65.608681,-807.151367,0.000233,0.004263,0.108272,291.841980,14.867140,1.082722,-807.151367,294.500488,0.000000
94.090004,65.596764,-807.240295,0.000237,0.004263,0.108272,291.788971,14.864439,1.082722,-807.240295,294.500488,0.000000
94.460007,65.591927,-807.240295,0.000241,0.004263,0.108272,291.767456,14.863343,1.082722,-807.240295,294.500488,0.000000
94.830002,65.577034,-807.195801,0.000250,0.004263,0.108272,291.701202,14.859968,1.082722,-807.195801,294.500488,0.000000
95.200005,65.572563,-807.151367,0.000241,0.004263,0.108272,291.681335,14.858955,1.082722,-807.151367,294.500488,0.000000
95.570007,65.571068,-807.195801,0.000241,0.004263,0.108272,291.674683,14.858616,1.082722,-807.195801,294.500488,0.000000
95.940002,65.546501,-807.240295,0.000233,0.004263,0.108272,291.565399,14.853050,1.082722,-807.240295,294.500488,0.000000
96.310005,65.521919,-807.329285,0.000241,0.004263,0.108272,291.456055,14.847479,1.082722,-807.329285,294.500488,0.000000
96.680008,65.510002,-807.240295,0.000246,0.004263,0.108272,291.403046,14.844778,1.082722,-807.240295,294.500488,0.000000
97.050003,65.474998,-807.284790,0.000254,0.004263,0.108272,291.247345,14.836846,1.082722,-807.284790,294.500488,0.000000
97.420006,65.477974,-807.240295,0.000254,0.004263,0.108272,291.260590,14.837522,1.082722,-807.240295,294.500488,0.000000
97.790001,65.444084,-807.373718,0.000250,0.004263,0.108272,291.109833,14.829841,1.082722,-807.373718,294.500488,0.000000
98.160004,65.405357,-807.373718,0.000233,0.004263,0.108272,290.937561,14.821066,1.082722,-807.373718,294.500488,0.000000
98.530006,65.365150,-807.329285,0.000246,0.004263,0.108272,290.758698,14.811954,1.082722,-807.329285,294.500488,0.000000
98.900002,65.355095,-807.240295,0.000250,0.004263,0.108272,290.713989,14.809676,1.082722,-807.240295,294.500488,0.000000
99.270004,65.339088,-807.329285,0.000237,0.004263,0.108272,290.642792,14.806049,1.082722,-807.329285,294.500488,0.000000
99.640007,65.314140,-807.284790,0.000233,0.004263,0.108272,290.531799,14.800396,1.082722,-807.284790,294.500488,0.000000
100.010002,65.300728,-807.329285,0.000241,0.004263,0.108272,290.472137,14.797357,1.082722,-807.329285,294.500488,0.000000
100.380005,65.288811,-807.284790,0.000259,0.004263,0.108272,290.419128,14.794656,1.082722,-807.284790,294.500488,0.000000
100.750008,65.277641,-807.329285,0.000259,0.004263,0.108272,290.369446,14.792125,1.082722,-807.329285,294.500488,0.000000
101.120003,65.260887,-807.329285,0.000250,0.004263,0.108272,290.294922,14.788328,1.082722,-807.329285,294.500488,0.000000
101.490005,65.248222,-807.418213,0.000246,0.004263,0.108272,290.238586,14.785459,1.082722,-807.418213,294.500488,0.000000
101.860008,65.222908,-807.418213,0.000233,0.004263,0.108272,290.125977,14.779722,1.082722,-807.418213,294.500488,0.000000
102.230003,65.208748,-807.418213,0.000241,0.004263,0.108272,290.062988,14.776513,1.082722,-807.418213,294.500488,0.000000
102.600006,65.189766,-807.418213,0.000250,0.004263,0.108272,289.978577,14.772212,1.082722,-807.418213,294.500488,0.000000
102.970001,65.158485,-807.418213,0.000241,0.004263,0.108272,289.839417,14.765123,1.082722,-807.418213,294.500488,0.000000
103.340004,65.140236,-807.418213,0.000250,0.004263,0.108272,289.758240,14.760988,1.082722,-807.418213,294.500488,0.000000
103.710007,65.105980,-807.373718,0.000241,0.004263,0.108272,289.605865,14.753226,1.082722,-807.373718,294.500488,0.000000
104.080002,65.097786,-807.373718,0.000246,0.004263,0.108272,289.569427,14.751369,1.082722,-807.373718,294.500488,0.000000
104.450005,65.073952,-807.418213,0.000250,0.004263,0.108272,289.463379,14.745968,1.082722,-807.418213,294.500488,0.000000
104.820007,65.055336,-807.462708,0.000241,0.004263,0.108272,289.380585,14.741750,1.082722,-807.462708,294.500488,0.000000
105.190002,65.026283,-807.507202,0.000241,0.004263,0.108272,289.251343,14.735167,1.082722,-807.507202,294.500488,0.000000
105.560005,65.019585,-807.551697,0.000246,0.004263,0.108281,289.221558,14.733649,1.082813,-807.551697,294.500488,0.000000
105.930008,65.009163,-807.418213,0.000250,0.004263,0.108281,289.175201,14.731286,1.082813,-807.418213,294.500488,0.000000
106.300003,64.984215,-807.418213,0.000254,0.004263,0.108281,289.064240,14.725634,1.082813,-807.418213,294.500488,0.000000
106.670006,64.980858,-807.462708,0.000241,0.004263,0.108281,289.049286,14.724873,1.082813,-807.462708,294.500488,0.000000
107.040009,64.966713,-807.507202,0.000241,0.004263,0.108281,288.986359,14.721668,1.082813,-807.507202,294.500488,0.000000
107.410004,64.936546,-807.507202,0.000259,0.004263,0.108281,288.852173,14.714832,1.082813,-807.507202,294.500488,0.000000
107.780006,64.926872,-807.462708,0.000254,0.004263,0.108281,288.809143,14.712640,1.082813,-807.462708,294.500488,0.000000
108.150002,64.898186,-807.507202,0.000241,0.004263,0.108281,288.681549,14.706140,1.082813,-807.507202,294.500488,0.000000
108.520004,64.881813,-807.596130,0.000241,0.004263,0.108281,288.608704,14.702429,1.082813,-807.596130,294.500488,0.000000
108.890007,64.849037,-807.551697,0.000241,0.004263,0.108290,288.462921,14.695002,1.082904,-807.551697,294.500488,0.000000
109.260002,64.841225,-807.596130,0.000254,0.004264,0.108316,288.428162,14.693232,1.083161,-807.596130,294.500488,0.000000
109.630005,64.995003,-807.551697,0.000254,0.004267,0.108377,289.112213,14.728079,1.083767,-807.551697,294.500488,0.000000
110.000008,65.003578,-807.596130,0.000254,0.004267,0.108377,289.150360,14.730021,1.083767,-807.596130,294.500488,0.000000
110.370003,65.018105,-807.596130,0.000267,0.004267,0.108377,289.214966,14.733313,1.083767,-807.596130,294.500488,0.000000
110.740005,65.024422,-807.596130,0.000254,0.004267,0.108377,289.243073,14.734745,1.083767,-807.596130,294.500488,0.000000
111.110008,65.012886,-807.596130,0.000250,0.004267,0.108377,289.191772,14.732131,1.083767,-807.596130,294.500488,0.000000
111.480003,65.009163,-807.596130,0.000263,0.004267,0.108377,289.175201,14.731286,1.083767,-807.596130,294.500488,0.000000
111.850006,65.000969,-807.596130,0.000254,0.004267,0.108377,289.138763,14.729430,1.083767,-807.596130,294.500488,0.000000
112.220009,64.999855,-807.640625,0.000254,0.004267,0.108377,289.133789,14.729177,1.083767,-807.640625,294.500488,0.000000
112.590004,64.995384,-807.685120,0.000254,0.004267,0.108377,289.113922,14.728165,1.083767,-807.685120,294.500488,0.000000
112.960007,64.983467,-807.685120,0.000246,0.004267,0.108377,289.060913,14.725465,1.083767,-807.685120,294.500488,0.000000
113.330002,64.963737,-807.596130,0.000259,0.004267,0.108377,288.973145,14.720993,1.083767,-807.596130,294.500488,0.000000
113.700005,64.962242,-807.640625,0.000250,0.004267,0.108377,288.966492,14.720654,1.083767,-807.640625,294.500488,0.000000
114.070007,64.960747,-807.685120,0.000250,0.004267,0.108377,288.959839,14.720315,1.083767,-807.685120,294.500488,0.000000
114.440002,64.943626,-807.685120,0.000254,0.004267,0.108377,288.883667,14.716436,1.083767,-807.685120,294.500488,0.000000
114.810005,64.936913,-807.685120,0.000250,0.004267,0.108377,288.853821,14.714914,1.083767,-807.685120,294.500488,0.000000
115.180008,64.916435,-807.685120,0.000259,0.004267,0.108377,288.762726,14.710275,1.083767,-807.685120,294.500488,0.000000
115.550003,64.908623,-807.729614,0.000250,0.004267,0.108377,288.727966,14.708505,1.083767,-807.729614,294.500488,0.000000
115.920006,64.905266,-807.729614,0.000241,0.004267,0.108377,288.713043,14.707744,1.083767,-807.729614,294.500488,0.000000
116.290009,64.879570,-807.685120,0.000250,0.004267,0.108377,288.598755,14.701921,1.083767,-807.685120,294.500488,0.000000
116.660004,64.873238,-807.774048,0.000246,0.004267,0.108377,288.570587,14.700485,1.083767,-807.774048,294.500488,0.000000
117.030006,64.850151,-807.729614,0.000259,0.004267,0.108377,288.467865,14.695254,1.083767,-807.729614,294.500488,0.000000
117.400009,64.911598,-807.685120,0.000254,0.004269,0.108421,288.741211,14.709179,1.084206,-807.685120,294.500488,0.000000
117.770004,64.938042,-807.729614,0.000246,0.004269,0.108421,288.858826,14.715171,1.084206,-807.729614,294.500488,0.000000
118.140007,64.930595,-807.818542,0.000237,0.004269,0.108421,288.825714,14.713483,1.084206,-807.818542,294.500488,0.000000
118.510002,64.914574,-807.818542,0.000259,0.004269,0.108421,288.754456,14.709852,1.084206,-807.818542,294.500488,0.000000
118.880005,64.922401,-807.818542,0.000259,0.004269,0.108421,288.789276,14.711626,1.084206,-807.818542,294.500488,0.000000
119.250008,64.925743,-807.774048,0.000259,0.004269,0.108421,288.804138,14.712383,1.084206,-807.774048,294.500488,0.000000
119.620003,64.925011,-807.729614,0.000237,0.004269,0.108421,288.800873,14.712217,1.084206,-807.729614,294.500488,0.000000
119.990005,64.916069,-807.863037,0.000254,0.004269,0.108421,288.761108,14.710192,1.084206,-807.863037,294.500488,0.000000
120.360008,64.906380,-807.818542,0.000241,0.004269,0.108421,288.717987,14.707996,1.084206,-807.818542,294.500488,0.000000
120.730003,64.890373,-807.774048,0.000254,0.004269,0.108421,288.646790,14.704370,1.084206,-807.774048,294.500488,0.000000
121.100006,64.893730,-807.774048,0.000263,0.004269,0.108421,288.661743,14.705130,1.084206,-807.774048,294.500488,0.000000
121.470009,64.866920,-807.818542,0.000250,0.004269,0.108421,288.542480,14.699055,1.084206,-807.818542,294.500488,0.000000
121.840004,64.857979,-807.863037,0.000259,0.004269,0.108421,288.502686,14.697028,1.084206,-807.863037,294.500488,0.000000
122.210007,64.852013,-807.818542,0.000254,0.004271,0.108481,288.476166,14.695676,1.084811,-807.818542,294.500488,0.000000
122.580009,65.218056,-807.907532,0.000259,0.004274,0.108551,290.104401,14.778623,1.085508,-807.907532,294.500488,0.000000
122.950005,65.267952,-807.863037,0.000254,0.004274,0.108551,290.326355,14.789929,1.085508,-807.863037,294.500488,0.000000
123.320007,65.272804,-807.818542,0.000237,0.004274,0.108551,290.347931,14.791029,1.085508,-807.818542,294.500488,0.000000
123.690002,65.280998,-807.863037,0.000259,0.004274,0.108551,290.384369,14.792886,1.085508,-807.863037,294.500488,0.000000
124.060005,65.273918,-807.907532,0.000233,0.004274,0.108551,290.352875,14.791282,1.085508,-807.907532,294.500488,0.000000
124.430008,65.282112,-807.907532,0.000263,0.004274,0.108551,290.389343,14.793138,1.085508,-807.907532,294.500488,0.000000
124.800003,65.298866,-807.818542,0.000263,0.004274,0.108551,290.463867,14.796934,1.085508,-807.818542,294.500488,0.000000
125.170006,65.290306,-807.907532,0.000259,0.004274,0.108551,290.425781,14.794995,1.085508,-807.907532,294.500488,0.000000
125.540009,65.287697,-807.907532,0.000259,0.004274,0.108551,290.414185,14.794403,1.085508,-807.907532,294.500488,0.000000
125.910004,65.279503,-807.951965,0.000246,0.004274,0.108551,290.377716,14.792547,1.085508,-807.951965,294.500488,0.000000
126.280006,65.282112,-807.951965,0.000259,0.004274,0.108551,290.389343,14.793138,1.085508,-807.951965,294.500488,0.000000
126.650009,65.277641,-807.907532,0.000246,0.004274,0.108551,290.369446,14.792125,1.085508,-807.907532,294.500488,0.000000
127.020004,65.284721,-807.951965,0.000259,0.004274,0.108551,290.400940,14.793730,1.085508,-807.951965,294.500488,0.000000
127.390007,65.285835,-807.951965,0.000254,0.004274,0.108551,290.405914,14.793983,1.085508,-807.951965,294.500488,0.000000
127.760010,65.277641,-807.996460,0.000259,0.004274,0.108551,290.369446,14.792125,1.085508,-807.996460,294.500488,0.000000
128.130005,65.268333,-807.951965,0.000250,0.004274,0.108551,290.328033,14.790016,1.085508,-807.951965,294.500488,0.000000
128.500000,65.264977,-807.951965,0.000259,0.004274,0.108551,290.313110,14.789255,1.085508,-807.951965,294.500488,0.000000
128.870010,65.274284,-807.951965,0.000241,0.004274,0.108551,290.354523,14.791364,1.085508,-807.951965,294.500488,0.000000
129.240005,65.251198,-807.996460,0.000237,0.004274,0.108551,290.251831,14.786133,1.085508,-807.996460,294.500488,0.000000
129.610001,65.254555,-807.996460,0.000259,0.004274,0.108551,290.266754,14.786894,1.085508,-807.996460,294.500488,0.000000
129.980011,65.253059,-807.996460,0.000250,0.004274,0.108551,290.260101,14.786554,1.085508,-807.996460,294.500488,0.000000
130.350006,65.248222,-807.996460,0.000241,0.004274,0.108551,290.238586,14.785459,1.085508,-807.996460,294.500488,0.000000
130.720001,65.234077,-807.996460,0.000267,0.004274,0.108551,290.175659,14.782253,1.085508,-807.996460,294.500488,0.000000
131.090012,65.216576,-808.040955,0.000254,0.004274,0.108551,290.097809,14.778287,1.085508,-808.040955,294.500488,0.000000
131.460007,65.227364,-808.040955,0.000259,0.004274,0.108551,290.145813,14.780732,1.085508,-808.040955,294.500488,0.000000
131.830002,65.215828,-808.040955,0.000250,0.004274,0.108551,290.094482,14.778117,1.085508,-808.040955,294.500488,0.000000
132.200012,65.220299,-807.996460,0.000259,0.004274,0.108551,290.114380,14.779131,1.085508,-807.996460,294.500488,0.000000
132.570007,65.228859,-808.040955,0.000254,0.004274,0.108551,290.152466,14.781071,1.085508,-808.040955,294.500488,0.000000
132.940002,65.207634,-808.129944,0.000250,0.004274,0.108551,290.058044,14.776261,1.085508,-808.129944,294.500488,0.000000
133.310013,65.204277,-808.129944,0.000250,0.004274,0.108551,290.043121,14.775500,1.085508,-808.129944,294.500488,0.000000
133.680008,65.187157,-808.129944,0.000263,0.004274,0.108551,289.966949,14.771621,1.085508,-808.129944,294.500488,0.000000
134.050003,65.177101,-807.996460,0.000250,0.004274,0.108551,289.922211,14.769342,1.085508,-807.996460,294.500488,0.000000
134.420013,65.184181,-808.085449,0.000259,0.004274,0.108551,289.953705,14.770947,1.085508,-808.085449,294.500488,0.000000
134.790009,65.184547,-808.129944,0.000263,0.004274,0.108551,289.955353,14.771029,1.085508,-808.129944,294.500488,0.000000
135.160004,65.166298,-808.129944,0.000259,0.004267,0.108377,289.874176,14.766894,1.083767,-808.129944,0.108377,0.000000
135.530014,65.091820,-808.174377,0.000267,0.004253,0.108030,289.542877,14.750017,1.080300,-808.174377,0.107762,0.000000
135.900009,65.052727,-808.129944,0.000276,0.004233,0.107509,289.368988,14.741158,1.075092,-808.129944,0.107146,0.000000
136.270004,65.052727,-808.129944,0.000254,0.004218,0.107146,289.368988,14.741158,1.071458,-808.129944,0.106530,0.000000
136.639999,64.982719,-808.129944,0.000263,0.004192,0.106478,289.057587,14.725295,1.064782,-808.129944,0.105913,0.000000
137.010010,64.938408,-808.218872,0.000254,0.004166,0.105818,288.860474,14.715253,1.058181,-808.218872,0.105299,0.000000
137.380005,64.947350,-808.129944,0.000276,0.004144,0.105246,288.900238,14.717279,1.052458,-808.129944,0.104683,0.000000
137.750000,65.008049,-808.129944,0.000272,0.004113,0.104466,289.170258,14.731034,1.044661,-808.129944,0.104066,0.000000
138.120010,64.910103,-808.129944,0.000263,0.004094,0.103997,288.734558,14.708839,1.039968,-808.129944,0.103452,0.000000
138.490005,64.922768,-808.174377,0.000254,0.004076,0.103529,288.790894,14.711709,1.035290,-808.174377,0.102827,0.000000
138.860001,64.807335,-808.174377,0.000263,0.004048,0.102827,288.277435,14.685553,1.028265,-808.174377,0.102210,0.000000
139.230011,64.622643,-808.218872,0.000276,0.004029,0.102333,287.455872,14.643700,1.023330,-808.218872,0.101596,0.000000
139.600006,64.021996,-808.174377,0.000267,0.004008,0.101812,284.784058,14.507592,1.018122,-808.174377,0.100979,0.000000
139.970001,62.953293,-808.263367,0.000263,0.003982,0.101145,280.030243,14.265420,1.011445,-808.263367,0.100363,0.000000
140.340012,61.962784,-808.218872,0.000259,0.003961,0.100607,275.624237,14.040968,1.006070,-808.218872,0.099749,0.000000
140.710007,60.955513,-808.263367,0.000276,0.003946,0.100233,271.143677,13.812716,1.002331,-808.263367,0.099132,0.000000
141.080002,58.687767,-808.174377,0.000272,0.003914,0.099419,261.056213,13.298839,0.994186,-808.174377,0.098516,0.000000
141.450012,57.414993,-808.218872,0.000280,0.003900,0.099063,255.394638,13.010424,0.990628,-808.218872,0.097893,0.000000
141.820007,54.750298,-808.218872,0.000280,0.003866,0.098195,243.541489,12.406595,0.981953,-808.218872,0.097276,0.000000
142.190002,52.169014,-808.307861,0.000276,0.003842,0.097581,232.059357,11.821667,0.975806,-808.307861,0.096660,0.000000
142.560013,50.170860,-808.263367,0.000280,0.003825,0.097146,223.171127,11.368879,0.971461,-808.263367,0.096045,0.000000
142.930008,47.437279,-808.307861,0.000276,0.003797,0.096444,211.011551,10.749441,0.964437,-808.307861,0.095429,0.000000
143.300003,44.645226,-808.174377,0.000285,0.003774,0.095855,198.591888,10.116754,0.958547,-808.174377,0.094813,0.000000
143.670013,41.327759,-808.263367,0.000276,0.003743,0.095064,183.835052,9.365005,0.950644,-808.263367,0.094198,0.000000
144.040009,38.954262,-808.352295,0.000276,0.003723,0.094571,173.277206,8.827162,0.945709,-808.352295,0.093582,0.000000
144.410004,36.500328,-808.352295,0.000276,0.003701,0.094015,162.361572,8.271092,0.940153,-808.352295,0.092966,0.000000
144.780014,33.602898,-808.307861,0.000267,0.003675,0.093357,149.473160,7.614526,0.933567,-808.307861,0.092342,0.000000
145.150009,31.196251,-808.307861,0.000285,0.003653,0.092775,138.767853,7.069171,0.927753,-808.307861,0.091726,0.000000
145.520004,28.005020,-808.307861,0.000280,0.003623,0.092030,124.572548,6.346028,0.920305,-808.307861,0.091110,0.000000
145.889999,25.745834,-808.396790,0.000280,0.003604,0.091552,114.523193,5.834090,0.915521,-808.396790,0.090495,0.000000
146.260010,22.965706,-808.396790,0.000259,0.003579,0.090903,102.156563,5.204103,0.909026,-808.396790,0.089879,0.000000
146.630005,20.364311,-808.396790,0.000272,0.003556,0.090312,90.584984,4.614619,0.903121,-808.396790,0.089263,0.000000
147.000000,18.060066,-808.352295,0.000276,0.003533,0.089749,80.335190,4.092469,0.897489,-808.352295,0.088648,0.000000
147.370010,15.314194,-808.352295,0.000267,0.003511,0.089168,68.120934,3.470246,0.891676,-808.352295,0.088032,0.000000
147.740005,12.096519,-808.352295,0.000254,0.003483,0.088458,53.808006,2.741110,0.884575,-808.352295,0.087416,0.000000
148.110001,9.311920,-808.396790,0.000259,0.003457,0.087797,41.421490,2.110111,0.877975,-808.396790,0.086792,0.000000
148.480011,7.131683,-808.396790,0.000272,0.003437,0.087295,31.723312,1.616063,0.872948,-808.396790,0.086176,0.000000
148.850006,4.771584,-808.352295,0.000259,0.003412,0.086671,21.225063,1.081256,0.866711,-808.352295,0.085560,0.000000
149.220001,2.008583,-808.441284,0.000246,0.003390,0.086097,8.934624,0.455151,0.860973,-808.441284,0.084945,0.000000
149.590012,-0.498230,-808.441284,0.000241,0.003361,0.085361,-2.216238,-0.112901,0.853615,-808.441284,0.084329,0.000000
149.960007,-0.546265,-808.485779,0.000233,0.003334,0.084692,-2.429907,-0.123785,0.846923,-808.485779,0.083713,0.000000
150.330002,-0.132935,-808.485779,0.000198,0.003315,0.084190,-0.591322,-0.030123,0.841897,-808.485779,0.083098,0.000000
150.700012,-0.024948,-808.441284,0.000142,0.003288,0.083513,-0.110975,-0.005653,0.835129,-808.441284,0.082482,0.000000
151.070007,0.083786,-808.441284,0.000073,0.003272,0.083098,0.372699,0.018986,0.830981,-808.441284,0.081866,0.000000
151.440002,0.056976,-808.574707,0.000065,0.003248,0.082499,0.253443,0.012911,0.824986,-808.574707,0.081242,0.000000
151.810013,0.090858,-808.530273,-0.000022,0.003220,0.081779,0.404159,0.020589,0.817795,-808.530273,0.080626,0.000000
152.180008,0.091232,-808.485779,-0.000069,0.003194,0.081128,0.405822,0.020674,0.811285,-808.485779,0.080010,0.000000
152.550003,0.086769,-808.530273,-0.000155,0.003166,0.080417,0.385968,0.019662,0.804169,-808.530273,0.079395,0.000000
152.920013,0.202576,-808.574707,-0.000207,0.003154,0.080123,0.901102,0.045904,0.801232,-808.574707,0.080002,0.000000
153.000000,0.193268,-808.574707,-0.000216,0.003155,0.080131,0.859698,0.043795,0.801308,-808.574707,0.080002,0.000000