File: Data/compression 35/ManualNoHeating-17-35-reverse-1-3_11182024_181047.csv
Time (sec),S:Load (lbs),S:HL1 (DIM),S:LVDT (in),S:Position (in),Ch:Position (mm),Ch:Load (N),Ch:Stress (MPa),Ch:Strain (mm/mm),Ch:HL1 (DIM),Set Point (),Cycles ()
0.110000,-0.019363,-895.223633,-0.012598,-0.007423,-0.188553,-0.086133,-0.004388,-1.885529,-895.223633,-0.188283,0.000000
0.480000,0.009682,-895.357056,-0.012598,-0.007372,-0.187251,0.043066,0.002194,-1.872509,-895.357056,-0.186567,0.000000
0.850000,-0.055107,-895.357056,-0.012538,-0.007170,-0.182117,-0.245129,-0.012487,-1.821170,-895.357056,-0.180409,0.000000
1.220000,-0.036491,-895.401550,-0.012253,-0.006914,-0.175613,-0.162322,-0.008269,-1.756131,-895.401550,-0.174234,0.000000
1.590000,-0.105377,-895.446045,-0.012012,-0.006682,-0.169716,-0.468741,-0.023879,-1.697162,-895.446045,-0.168077,0.000000
1.960000,-0.027924,-895.357056,-0.011783,-0.006437,-0.163498,-0.124210,-0.006328,-1.634984,-895.357056,-0.161919,0.000000
2.330000,-0.032394,-895.446045,-0.011499,-0.006176,-0.156881,-0.144098,-0.007341,-1.568809,-895.446045,-0.155745,0.000000
2.700000,-0.013771,-895.401550,-0.011244,-0.005944,-0.150975,-0.061257,-0.003121,-1.509749,-895.401550,-0.149588,0.000000
3.070000,-0.018990,-895.490479,-0.011029,-0.005704,-0.144878,-0.084470,-0.004303,-1.448782,-895.490479,-0.143413,0.000000
3.440000,-0.040588,-895.357056,-0.010766,-0.005455,-0.138548,-0.180546,-0.009197,-1.385484,-895.357056,-0.137255,0.000000
3.810000,-0.021591,-895.401550,-0.010503,-0.005213,-0.132400,-0.096042,-0.004893,-1.324002,-895.401550,-0.131098,0.000000
4.180000,0.008194,-895.401550,-0.010248,-0.004970,-0.126241,0.036449,0.001857,-1.262414,-895.401550,-0.124924,0.000000
4.550000,0.033142,-895.446045,-0.009998,-0.004727,-0.120077,0.147423,0.007510,-1.200765,-895.446045,-0.118767,0.000000
4.920000,0.001122,-895.401550,-0.009744,-0.004491,-0.114075,0.004989,0.000254,-1.140752,-895.401550,-0.112592,0.000000
5.290000,-0.008186,-895.357056,-0.009455,-0.004243,-0.107779,-0.036415,-0.001855,-1.077787,-895.357056,-0.106434,0.000000
5.660000,-0.080429,-895.401550,-0.009257,-0.004007,-0.101777,-0.357766,-0.018225,-1.017773,-895.401550,-0.100277,0.000000
6.030000,-0.095695,-895.446045,-0.008990,-0.003765,-0.095638,-0.425675,-0.021685,-0.956382,-895.446045,-0.094103,0.000000
6.400000,-0.022339,-895.490479,-0.008735,-0.003515,-0.089281,-0.099368,-0.005062,-0.892811,-895.490479,-0.087946,0.000000
6.770000,0.029793,-895.446045,-0.008472,-0.003286,-0.083454,0.132525,0.006751,-0.834539,-895.446045,-0.081770,0.000000
7.140000,-0.002602,-895.490479,-0.008248,-0.003034,-0.077053,-0.011573,-0.000590,-0.770529,-895.490479,-0.075613,0.000000
7.510000,-0.000366,-895.490479,-0.007959,-0.002787,-0.070800,-0.001629,-0.000083,-0.708002,-895.490479,-0.069456,0.000000
7.880001,-0.046913,-895.490479,-0.007743,-0.002544,-0.064608,-0.208680,-0.010631,-0.646082,-895.490479,-0.063282,0.000000
8.250000,0.011543,-895.534973,-0.007502,-0.002305,-0.058546,0.051347,0.002616,-0.585463,-895.534973,-0.057125,0.000000
8.620001,0.005959,-895.579468,-0.007256,-0.002064,-0.052433,0.026505,0.001350,-0.524329,-895.579468,-0.050967,0.000000
8.990001,-0.006325,-895.579468,-0.006993,-0.001817,-0.046145,-0.028134,-0.001433,-0.461454,-895.579468,-0.044792,0.000000
9.360001,-0.027550,-895.490479,-0.006760,-0.001593,-0.040474,-0.122547,-0.006243,-0.404742,-895.490479,-0.038635,0.000000
9.730000,-0.058090,-895.579468,-0.006493,-0.001325,-0.033666,-0.258398,-0.013163,-0.336659,-895.579468,-0.032461,0.000000
10.100000,-0.086761,-895.534973,-0.006247,-0.001091,-0.027716,-0.385934,-0.019660,-0.277160,-895.534973,-0.026304,0.000000
10.470000,0.012291,-895.534973,-0.006010,-0.000856,-0.021733,0.054673,0.002785,-0.217329,-895.534973,-0.020146,0.000000
10.840000,0.010429,-895.490479,-0.005739,-0.000595,-0.015124,0.046392,0.002363,-0.151244,-895.490479,-0.013971,0.000000
11.210001,0.025696,-895.534973,-0.005493,-0.000364,-0.009244,0.114301,0.005823,-0.092442,-895.534973,-0.007814,0.000000
11.580001,0.029045,-895.534973,-0.005243,-0.000118,-0.003001,0.129199,0.006582,-0.030007,-895.534973,-0.001640,0.000000
11.950001,0.044685,-895.623962,-0.005178,-0.000002,-0.000061,0.198770,0.010126,-0.000606,-895.623962,0.000173,0.000000
12.320001,0.164589,-895.579468,-0.005178,-0.000002,-0.000061,0.732128,0.037296,-0.000606,-895.579468,0.000391,0.000000
12.690001,0.106873,-895.579468,-0.005165,-0.000002,-0.000053,0.475393,0.024218,-0.000530,-895.579468,0.001005,0.000000
13.060000,0.166451,-895.534973,-0.005170,0.000013,0.000321,0.740409,0.037718,0.003210,-895.534973,0.001621,0.000000
13.430000,0.406265,-895.579468,-0.005152,0.000047,0.001188,1.807158,0.092061,0.011885,-895.579468,0.002238,0.000000
13.800000,0.528030,-895.623962,-0.005135,0.000064,0.001638,2.348797,0.119653,0.016381,-895.623962,0.002852,0.000000
14.170001,0.795761,-895.623962,-0.005113,0.000090,0.002280,3.539722,0.180322,0.022800,-895.623962,0.003468,0.000000
14.540001,1.202019,-895.668457,-0.005066,0.000123,0.003122,5.346847,0.272381,0.031218,-895.668457,0.004092,0.000000
14.910001,1.422096,-895.668457,-0.005057,0.000137,0.003468,6.325800,0.322252,0.034685,-895.668457,0.004708,0.000000
15.280001,2.048798,-895.668457,-0.005027,0.000170,0.004327,9.113507,0.464264,0.043269,-895.668457,0.005325,0.000000
15.650001,2.435318,-895.668457,-0.005014,0.000193,0.004908,10.832835,0.551851,0.049083,-895.668457,0.005941,0.000000
16.020000,2.657249,-895.712891,-0.004997,0.000206,0.005238,11.820036,0.602141,0.052383,-895.712891,0.006555,0.000000
16.390001,3.083618,-895.712891,-0.004988,0.000232,0.005897,13.716619,0.698758,0.058969,-895.712891,0.007172,0.000000
16.760000,3.639572,-895.623962,-0.004958,0.000255,0.006478,16.189625,0.824739,0.064782,-895.623962,0.007788,0.000000
17.130001,4.452087,-895.668457,-0.004950,0.000287,0.007302,19.803873,1.008857,0.073018,-895.668457,0.008402,0.000000
17.500000,4.677002,-895.712891,-0.004898,0.000307,0.007788,20.804344,1.059824,0.077878,-895.712891,0.009019,0.000000
17.870001,5.822044,-895.801880,-0.004876,0.000344,0.008742,25.897747,1.319294,0.087416,-895.801880,0.009644,0.000000
18.240002,5.966530,-895.712891,-0.004850,0.000363,0.009218,26.540451,1.352035,0.092185,-895.712891,0.010259,0.000000
18.610001,5.975838,-895.668457,-0.004850,0.000371,0.009435,26.581854,1.354144,0.094350,-895.668457,0.010875,0.000000
18.980001,6.537750,-895.712891,-0.004855,0.000392,0.009963,29.081366,1.481475,0.099634,-895.712891,0.011491,0.000000
19.350000,7.539429,-895.757385,-0.004820,0.000428,0.010866,33.537052,1.708459,0.108657,-895.757385,0.012106,0.000000
19.720001,8.207466,-895.757385,-0.004773,0.000462,0.011733,36.508633,1.859838,0.117332,-895.757385,0.012722,0.000000
20.090000,8.357155,-895.801880,-0.004769,0.000480,0.012184,37.174480,1.893758,0.121843,-895.801880,0.013338,0.000000
20.460001,8.673676,-895.712891,-0.004760,0.000497,0.012626,38.582436,1.965483,0.126264,-895.712891,0.013953,0.000000
20.830002,9.045303,-895.757385,-0.004734,0.000515,0.013068,40.235519,2.049695,0.130685,-895.757385,0.014569,0.000000
21.200001,10.225723,-895.801880,-0.004721,0.000556,0.014110,45.486290,2.317182,0.141101,-895.801880,0.015194,0.000000
21.570002,10.419357,-895.801880,-0.004687,0.000581,0.014750,46.347614,2.361060,0.147505,-895.801880,0.015809,0.000000
21.940001,10.591019,-895.846375,-0.004661,0.000597,0.015159,47.111202,2.399959,0.151593,-895.846375,0.016425,0.000000
22.310001,10.877373,-895.801880,-0.004656,0.000615,0.015618,48.384972,2.464848,0.156180,-895.801880,0.017041,0.000000
22.680000,11.689148,-895.712891,-0.004635,0.000646,0.016416,51.995926,2.648799,0.164158,-895.712891,0.017656,0.000000
23.050001,12.089447,-895.846375,-0.004596,0.000669,0.016997,53.776546,2.739508,0.169972,-895.846375,0.018272,0.000000
23.420002,12.557518,-895.801880,-0.004579,0.000697,0.017716,55.858631,2.845574,0.177163,-895.801880,0.018888,0.000000
23.790001,12.550819,-895.846375,-0.004549,0.000712,0.018090,55.828835,2.844056,0.180903,-895.846375,0.019503,0.000000
24.160002,13.291466,-895.801880,-0.004544,0.000743,0.018862,59.123394,3.011889,0.188624,-895.801880,0.020119,0.000000
24.530001,13.626602,-895.846375,-0.004518,0.000764,0.019417,60.614155,3.087832,0.194165,-895.846375,0.020744,0.000000
24.900002,14.497955,-895.757385,-0.004506,0.000795,0.020198,64.490128,3.285284,0.201977,-895.757385,0.021359,0.000000
25.270000,15.013313,-895.890808,-0.004462,0.000826,0.020970,66.782555,3.402065,0.209698,-895.890808,0.021975,0.000000
25.640001,15.415482,-895.890808,-0.004437,0.000854,0.021689,68.571487,3.493198,0.216890,-895.890808,0.022591,0.000000
26.010002,15.579697,-895.846375,-0.004406,0.000874,0.022210,69.301949,3.530410,0.222098,-895.846375,0.023206,0.000000
26.380001,16.260765,-895.846375,-0.004393,0.000904,0.022973,72.331497,3.684742,0.229728,-895.846375,0.023822,0.000000
26.750002,16.037338,-895.846375,-0.004381,0.000921,0.023389,71.337646,3.634113,0.233891,-895.846375,0.024438,0.000000
27.120001,16.452164,-895.846375,-0.004355,0.000940,0.023883,73.182877,3.728114,0.238827,-895.846375,0.025054,0.000000
27.490002,16.538551,-895.979797,-0.004346,0.000960,0.024385,73.567154,3.747689,0.243853,-895.979797,0.025669,0.000000
27.860001,17.135094,-895.935303,-0.004329,0.000980,0.024880,76.220703,3.882868,0.248804,-895.935303,0.026294,0.000000
28.230001,18.197098,-895.846375,-0.004290,0.001017,0.025825,80.944733,4.123521,0.258251,-895.846375,0.026909,0.000000
28.600002,18.004959,-895.935303,-0.004281,0.001032,0.026207,80.090057,4.079982,0.262066,-895.935303,0.027525,0.000000
28.970001,18.719170,-895.935303,-0.004251,0.001064,0.027032,83.267029,4.241825,0.270317,-895.935303,0.028141,0.000000
29.340002,18.565002,-895.979797,-0.004238,0.001081,0.027465,82.581253,4.206890,0.274647,-895.979797,0.028756,0.000000
29.710001,19.163033,-895.890808,-0.004208,0.001110,0.028184,85.241425,4.342405,0.281838,-895.890808,0.029372,0.000000
30.080002,19.353317,-895.801880,-0.004191,0.001129,0.028688,86.087852,4.385525,0.286880,-895.801880,0.029988,0.000000
30.450001,19.518654,-895.935303,-0.004174,0.001155,0.029330,86.823311,4.422990,0.293299,-895.935303,0.030605,0.000000
30.820002,20.643959,-895.935303,-0.004148,0.001189,0.030188,91.828918,4.677988,0.301883,-895.935303,0.031219,0.000000
31.190001,20.617897,-895.979797,-0.004122,0.001207,0.030665,91.712990,4.672082,0.306652,-895.979797,0.031845,0.000000
31.560001,20.306587,-895.935303,-0.004122,0.001221,0.031012,90.328209,4.601539,0.310119,-895.935303,0.032459,0.000000
31.930002,21.058411,-895.935303,-0.004070,0.001253,0.031836,93.672485,4.771904,0.318355,-895.935303,0.033075,0.000000
32.300003,20.639122,-895.979797,-0.004066,0.001265,0.032131,91.807404,4.676892,0.321307,-895.979797,0.033692,0.000000
32.670002,21.989716,-896.024292,-0.004044,0.001304,0.033119,97.815140,4.982941,0.331193,-896.024292,0.034308,0.000000
33.040001,22.235107,-896.024292,-0.004018,0.001329,0.033752,98.906700,5.038548,0.337522,-896.024292,0.034922,0.000000
33.410000,22.031792,-895.979797,-0.003992,0.001347,0.034212,98.002304,4.992476,0.342124,-895.979797,0.035539,0.000000
33.780003,22.304367,-895.935303,-0.003967,0.001372,0.034853,99.214783,5.054242,0.348528,-895.935303,0.036155,0.000000
34.150002,23.157104,-896.024292,-0.003949,0.001405,0.035686,103.007942,5.247475,0.356855,-896.024292,0.036779,0.000000
34.520000,22.379219,-896.113220,-0.003954,0.001413,0.035885,99.547737,5.071203,0.358853,-896.113220,0.037395,0.000000
34.890003,23.399513,-896.068787,-0.003915,0.001448,0.036788,104.086235,5.302406,0.367877,-896.068787,0.038009,0.000000
35.260002,23.859024,-896.068787,-0.003902,0.001476,0.037490,106.130241,5.406532,0.374901,-896.068787,0.038626,0.000000
35.630001,23.930145,-896.068787,-0.003876,0.001499,0.038072,106.446602,5.422648,0.380715,-896.068787,0.039242,0.000000
36.000000,24.593346,-896.024292,-0.003846,0.001531,0.038886,109.396667,5.572932,0.388860,-896.024292,0.039858,0.000000
36.370003,23.823647,-896.157715,-0.003824,0.001539,0.039086,105.972870,5.398516,0.390859,-896.157715,0.040473,0.000000
36.740002,24.808571,-896.068787,-0.003807,0.001574,0.039988,110.354034,5.621703,0.399882,-896.068787,0.041089,0.000000
37.110001,24.792931,-896.113220,-0.003786,0.001594,0.040482,110.284462,5.618158,0.404817,-896.113220,0.041705,0.000000
37.480003,25.138123,-896.113220,-0.003751,0.001618,0.041089,111.819954,5.696380,0.410888,-896.113220,0.042329,0.000000
37.850002,24.808571,-896.068787,-0.003755,0.001633,0.041470,110.354034,5.621703,0.414703,-896.068787,0.042945,0.000000
38.220001,25.158974,-896.113220,-0.003721,0.001655,0.042043,111.912704,5.701105,0.420426,-896.113220,0.043561,0.000000
38.590000,26.823112,-896.113220,-0.003704,0.001697,0.043110,119.315163,6.078204,0.431100,-896.113220,0.044176,0.000000
38.960003,26.397858,-896.113220,-0.003699,0.001714,0.043543,117.423538,5.981840,0.435429,-896.113220,0.044792,0.000000
39.330002,27.196968,-896.068787,-0.003678,0.001751,0.044480,120.978157,6.162921,0.444801,-896.068787,0.045408,0.000000
39.700001,26.566170,-896.113220,-0.003652,0.001762,0.044757,118.172226,6.019980,0.447571,-896.113220,0.046023,0.000000
40.070004,26.335304,-896.113220,-0.003639,0.001778,0.045157,117.145287,5.967665,0.451568,-896.113220,0.046639,0.000000
40.440002,27.815857,-896.113220,-0.003609,0.001813,0.046058,123.731110,6.303164,0.460576,-896.113220,0.047255,0.000000
40.810001,28.315948,-896.157715,-0.003587,0.001843,0.046821,125.955627,6.416486,0.468207,-896.157715,0.047879,0.000000
41.180000,28.439209,-896.113220,-0.003566,0.001865,0.047376,126.503922,6.444417,0.473763,-896.113220,0.048495,0.000000
41.550003,28.031830,-896.157715,-0.003566,0.001883,0.047827,124.691803,6.352103,0.478274,-896.157715,0.049111,0.000000
41.920002,27.876175,-896.202209,-0.003544,0.001900,0.048251,123.999420,6.316832,0.482514,-896.202209,0.049726,0.000000
42.290001,28.575493,-896.202209,-0.003518,0.001927,0.048946,127.110138,6.475299,0.489463,-896.202209,0.050342,0.000000
42.660004,29.766342,-896.246704,-0.003484,0.001960,0.049796,132.407303,6.745150,0.497956,-896.246704,0.050958,0.000000
43.030003,29.984924,-896.157715,-0.003466,0.001985,0.050412,133.379608,6.794681,0.504118,-896.157715,0.051573,0.000000
43.400002,29.697823,-896.202209,-0.003458,0.002002,0.050863,132.102509,6.729623,0.508629,-896.202209,0.052189,0.000000
43.770000,29.745117,-896.291138,-0.003454,0.002020,0.051296,132.312897,6.740340,0.512959,-896.291138,0.052805,0.000000
44.140003,31.236839,-896.246704,-0.003419,0.002055,0.052198,138.948395,7.078369,0.521982,-896.246704,0.053429,0.000000
44.510002,31.883652,-896.157715,-0.003393,0.002084,0.052926,141.825562,7.224939,0.529265,-896.157715,0.054045,0.000000
44.880001,31.410736,-896.202209,-0.003376,0.002102,0.053387,139.721939,7.117774,0.533867,-896.202209,0.054661,0.000000
45.250004,32.268684,-896.291138,-0.003372,0.002128,0.054045,143.538284,7.312188,0.540453,-896.291138,0.055276,0.000000
45.620003,32.297356,-896.291138,-0.003350,0.002149,0.054574,143.665817,7.318685,0.545736,-896.291138,0.055892,0.000000
45.990002,32.044891,-896.380127,-0.003333,0.002164,0.054955,142.542801,7.261476,0.549552,-896.380127,0.056508,0.000000
46.360001,34.174484,-896.335632,-0.003316,0.002206,0.056039,152.015701,7.744049,0.560392,-896.335632,0.057123,0.000000
46.730003,34.594521,-896.291138,-0.003298,0.002230,0.056630,153.884109,7.839231,0.566296,-896.291138,0.057739,0.000000
47.100002,35.344482,-896.291138,-0.003277,0.002259,0.057376,157.220108,8.009174,0.573760,-896.291138,0.058356,0.000000
47.470001,35.430870,-896.246704,-0.003264,0.002282,0.057965,157.604385,8.028749,0.579649,-896.246704,0.058979,0.000000
47.840004,36.145454,-896.291138,-0.003229,0.002309,0.058658,160.783005,8.190677,0.586583,-896.291138,0.059595,0.000000
48.210003,35.908997,-896.291138,-0.003212,0.002326,0.059093,159.731201,8.137094,0.590928,-896.291138,0.060212,0.000000
48.580002,36.178223,-896.291138,-0.003195,0.002348,0.059647,160.928772,8.198103,0.596469,-896.291138,0.060826,0.000000
48.950001,35.643867,-896.246704,-0.003182,0.002360,0.059933,158.551834,8.077016,0.599331,-896.246704,0.061442,0.000000
49.320004,37.225334,-896.335632,-0.003178,0.002394,0.060810,165.586563,8.435381,0.608096,-896.335632,0.062059,0.000000
49.690002,38.435173,-896.380127,-0.003147,0.002425,0.061598,170.968185,8.709535,0.615984,-896.380127,0.062673,0.000000
50.060001,38.599388,-896.335632,-0.003139,0.002448,0.062171,171.698654,8.746746,0.621707,-896.335632,0.063290,0.000000
50.430004,38.815361,-896.291138,-0.003109,0.002468,0.062691,172.659348,8.795686,0.626915,-896.291138,0.063906,0.000000
50.800003,39.691925,-896.291138,-0.003126,0.002496,0.063411,176.558502,8.994319,0.634106,-896.291138,0.064529,0.000000
51.170002,39.711288,-896.380127,-0.003087,0.002512,0.063801,176.644638,8.998707,0.638012,-896.380127,0.065146,0.000000
51.540001,40.365547,-896.424622,-0.003074,0.002540,0.064513,179.554916,9.146963,0.645128,-896.424622,0.065762,0.000000
51.910004,41.141945,-896.380127,-0.003053,0.002563,0.065102,183.008514,9.322898,0.651017,-896.380127,0.066376,0.000000
52.280003,42.359978,-896.380127,-0.003048,0.002592,0.065839,188.426590,9.598907,0.658390,-896.380127,0.066993,0.000000
52.650002,42.544678,-896.335632,-0.003022,0.002615,0.066420,189.248184,9.640762,0.664204,-896.335632,0.067609,0.000000
53.020004,43.512840,-896.380127,-0.003014,0.002643,0.067132,193.554779,9.860151,0.671319,-896.380127,0.068225,0.000000
53.390003,42.917046,-896.424622,-0.002984,0.002655,0.067444,190.904556,9.725142,0.674438,-896.424622,0.068840,0.000000
53.760002,42.408760,-896.424622,-0.002988,0.002667,0.067739,188.643585,9.609962,0.677390,-896.424622,0.069456,0.000000
54.130001,45.799210,-896.380127,-0.002979,0.002716,0.068979,203.725052,10.378249,0.689790,-896.380127,0.070080,0.000000
54.500004,45.815598,-896.424622,-0.002953,0.002735,0.069482,203.797958,10.381963,0.694816,-896.424622,0.070696,0.000000
54.870003,46.368942,-896.469116,-0.002949,0.002759,0.070080,206.259354,10.507353,0.700796,-896.469116,0.071312,0.000000
55.240002,47.572823,-896.469116,-0.002932,0.002788,0.070817,211.614487,10.780155,0.708169,-896.469116,0.071927,0.000000
55.610004,47.964554,-896.424622,-0.002915,0.002809,0.071338,213.356995,10.868923,0.713377,-896.424622,0.072543,0.000000
55.980003,48.574501,-896.469116,-0.002893,0.002834,0.071996,216.070175,11.007139,0.719963,-896.469116,0.073159,0.000000
56.350002,48.985229,-896.513550,-0.002889,0.002857,0.072569,217.897186,11.100212,0.725685,-896.513550,0.073775,0.000000
56.720001,49.509903,-896.469116,-0.002889,0.002881,0.073168,220.231049,11.219105,0.731681,-896.469116,0.074390,0.000000
57.090004,50.050583,-896.513550,-0.002854,0.002907,0.073843,222.636108,11.341624,0.738433,-896.513550,0.075006,0.000000
57.460003,51.690140,-896.469116,-0.002837,0.002933,0.074503,229.929230,11.713153,0.745034,-896.469116,0.075630,0.000000
57.830002,52.059906,-896.469116,-0.002841,0.002956,0.075085,231.574020,11.796943,0.750847,-896.469116,0.076246,0.000000
58.200005,52.510109,-896.513550,-0.002828,0.002978,0.075630,233.576630,11.898961,0.756298,-896.513550,0.076862,0.000000
58.570004,53.378105,-896.558044,-0.002798,0.003001,0.076229,237.437668,12.095652,0.762293,-896.558044,0.077478,0.000000
58.940002,53.918045,-896.558044,-0.002781,0.003024,0.076809,239.839447,12.218003,0.768091,-896.558044,0.078093,0.000000
59.310001,54.217430,-896.513550,-0.002772,0.003043,0.077304,241.171173,12.285846,0.773042,-896.513550,0.078709,0.000000
59.680004,55.776558,-896.513550,-0.002772,0.003077,0.078163,248.106522,12.639149,0.781626,-896.513550,0.079325,0.000000
60.050003,56.726479,-896.469116,-0.002746,0.003098,0.078700,252.331985,12.854403,0.787001,-896.469116,0.079940,0.000000
60.420002,57.190086,-896.602539,-0.002729,0.003119,0.079230,254.394211,12.959459,0.792300,-896.602539,0.080565,0.000000
60.790005,58.980453,-896.558044,-0.002721,0.003154,0.080123,262.358154,13.365162,0.801232,-896.558044,0.081180,0.000000
61.160004,58.397316,-896.513550,-0.002734,0.003167,0.080444,259.764221,13.233021,0.804442,-896.513550,0.081796,0.000000
61.530003,58.114685,-896.602539,-0.002699,0.003179,0.080738,258.507019,13.168976,0.807379,-896.602539,0.082412,0.000000
61.900002,60.964821,-896.558044,-0.002703,0.003223,0.081857,271.185059,13.814825,0.818567,-896.558044,0.083028,0.000000
62.270004,63.046761,-896.558044,-0.002690,0.003257,0.082724,280.445984,14.286600,0.827242,-896.558044,0.083643,0.000000
62.640003,62.469208,-896.647034,-0.002673,0.003265,0.082941,277.876923,14.155725,0.829407,-896.647034,0.084259,0.000000
63.010002,62.370529,-896.558044,-0.002652,0.003281,0.083349,277.437958,14.133364,0.833494,-896.558044,0.084876,0.000000
63.380005,62.752953,-896.558044,-0.002652,0.003307,0.084008,279.139069,14.220022,0.840080,-896.558044,0.085490,0.000000
63.750004,65.363289,-896.602539,-0.002652,0.003345,0.084953,290.750427,14.811533,0.849527,-896.602539,0.086115,0.000000
64.120003,66.190697,-896.602539,-0.002639,0.003358,0.085283,294.430939,14.999026,0.852828,-896.602539,0.085474,0.000000
64.490005,64.342979,-896.647034,-0.002613,0.003372,0.085646,286.211853,14.580327,0.856461,-896.647034,294.500488,0.000000
64.860001,65.172630,-896.558044,-0.002583,0.003357,0.085265,289.902344,14.768330,0.852646,-896.558044,294.500488,0.000000
65.230003,65.251579,-896.602539,-0.002591,0.003396,0.086262,290.253510,14.786219,0.862623,-896.602539,294.500488,0.000000
65.600006,65.221046,-896.602539,-0.002600,0.003410,0.086609,290.117706,14.779301,0.866090,-896.602539,294.500488,0.000000
65.970001,66.205971,-896.602539,-0.002583,0.003434,0.087225,294.498871,15.002488,0.872252,-896.602539,294.500488,0.000000
66.340004,64.687431,-896.691467,-0.002570,0.003422,0.086930,287.744080,14.658381,0.869300,-896.691467,294.500488,0.000000
66.710007,64.998741,-896.647034,-0.002570,0.003446,0.087537,289.128845,14.728925,0.875371,-896.647034,294.500488,0.000000
67.080002,67.634392,-896.647034,-0.002544,0.003401,0.086392,300.852814,15.326172,0.863925,-896.647034,294.500488,0.000000
67.450005,65.527870,-896.647034,-0.002552,0.003290,0.083557,291.482513,14.848827,0.835569,-896.647034,294.500488,0.000000
67.820000,65.272423,-896.691467,-0.002544,0.003482,0.088439,290.346252,14.790943,0.884394,-896.691467,294.500488,0.000000
68.190002,65.158852,-896.735962,-0.002535,0.003496,0.088804,289.841034,14.765207,0.888042,-896.735962,294.500488,0.000000
68.560005,65.340569,-896.691467,-0.002522,0.003507,0.089072,290.649353,14.806384,0.890722,-896.691467,294.500488,0.000000
68.930000,64.371284,-896.647034,-0.002527,0.003507,0.089090,286.337769,14.586742,0.890904,-896.647034,294.500488,0.000000
69.300003,65.990364,-896.691467,-0.002501,0.003467,0.088058,293.539795,14.953630,0.880579,-896.691467,294.500488,0.000000
69.670006,65.008415,-896.647034,-0.002505,0.003529,0.089635,289.171875,14.731118,0.896354,-896.647034,294.500488,0.000000
70.040001,64.937294,-896.735962,-0.002501,0.003540,0.089922,288.855499,14.715001,0.899215,-896.735962,294.500488,0.000000
70.410004,65.734535,-896.691467,-0.002492,0.003574,0.090781,292.401825,14.895658,0.907815,-896.691467,294.500488,0.000000
70.780006,65.569588,-896.691467,-0.002475,0.003534,0.089766,291.668091,14.858281,0.897656,-896.691467,294.500488,0.000000
71.150002,64.629707,-896.780457,-0.002492,0.003562,0.090477,287.487305,14.645302,0.904772,-896.780457,294.500488,0.000000
71.520004,65.214333,-896.780457,-0.002488,0.003579,0.090903,290.087830,14.777779,0.909026,-896.780457,294.500488,0.000000
71.890007,64.372780,-896.780457,-0.002471,0.003579,0.090912,286.344421,14.587080,0.909117,-896.780457,294.500488,0.000000
72.260002,66.693031,-896.691467,-0.002458,0.003459,0.087858,296.665405,15.112857,0.878580,-896.691467,294.500488,0.000000
72.630005,65.758369,-896.735962,-0.002462,0.003463,0.087972,292.507843,14.901059,0.879716,-896.735962,294.500488,0.000000
73.000000,65.060555,-896.824951,-0.002471,0.003604,0.091552,289.403809,14.742932,0.915521,-896.824951,294.500488,0.000000
73.370003,65.084007,-896.824951,-0.002453,0.003616,0.091847,289.508118,14.748247,0.918473,-896.824951,294.500488,0.000000
73.740005,65.187904,-896.780457,-0.002453,0.003627,0.092117,289.970276,14.771790,0.921168,-896.780457,294.500488,0.000000
74.110001,64.670296,-896.824951,-0.002458,0.003636,0.092342,287.667847,14.654499,0.923424,-896.824951,294.500488,0.000000
74.480003,65.569206,-896.735962,-0.002445,0.003639,0.092438,291.666382,14.858194,0.924377,-896.735962,294.500488,0.000000
74.850006,65.486916,-896.780457,-0.002462,0.003663,0.093036,291.300354,14.839547,0.930357,-896.780457,294.500488,0.000000
75.220001,65.520058,-896.869446,-0.002453,0.003652,0.092759,291.447784,14.847057,0.927587,-896.869446,294.500488,0.000000
75.590004,64.737694,-896.824951,-0.002445,0.003652,0.092766,287.967651,14.669771,0.927663,-896.824951,294.500488,0.000000
75.960007,66.888145,-896.780457,-0.002419,0.003498,0.088847,297.533325,15.157070,0.888466,-896.780457,294.500488,0.000000
76.330002,66.067818,-896.824951,-0.002414,0.003498,0.088856,293.884338,14.971182,0.888557,-896.824951,294.500488,0.000000
76.700005,65.308540,-896.869446,-0.002427,0.003565,0.090563,290.506897,14.799127,0.905635,-896.869446,294.500488,0.000000
77.070007,65.311150,-896.869446,-0.002427,0.003694,0.093815,290.518494,14.799718,0.938154,-896.869446,294.500488,0.000000
77.440002,65.228111,-896.869446,-0.002423,0.003692,0.093773,290.149139,14.780901,0.937730,-896.869446,294.500488,0.000000
77.810005,64.615196,-896.824951,-0.002427,0.003692,0.093773,287.422760,14.642013,0.937730,-896.824951,294.500488,0.000000
78.180000,66.967842,-896.824951,-0.002397,0.003531,0.089697,297.887848,15.175130,0.896975,-896.824951,294.500488,0.000000
78.550003,66.165382,-896.913879,-0.002397,0.003523,0.089472,294.318329,14.993290,0.894719,-896.913879,294.500488,0.000000
78.920006,65.549843,-896.913879,-0.002397,0.003549,0.090140,291.580261,14.853807,0.901395,-896.913879,294.500488,0.000000
79.290001,65.221413,-896.869446,-0.002393,0.003715,0.094362,290.119324,14.779383,0.943620,-896.869446,294.500488,0.000000
79.660004,65.295509,-896.869446,-0.002389,0.003726,0.094648,290.448944,14.796174,0.946481,-896.869446,294.500488,0.000000
80.030006,65.065010,-896.913879,-0.002389,0.003730,0.094753,289.423615,14.743942,0.947526,-896.913879,294.500488,0.000000
80.400002,65.029274,-896.958374,-0.002389,0.003734,0.094831,289.264648,14.735844,0.948313,-896.958374,294.500488,0.000000
80.770004,65.093681,-896.958374,-0.002389,0.003740,0.094995,289.551147,14.750440,0.949948,-896.958374,294.500488,0.000000
81.140007,65.193855,-896.869446,-0.002384,0.003747,0.095169,289.996765,14.773139,0.951689,-896.869446,294.500488,0.000000
81.510002,64.954048,-896.913879,-0.002389,0.003747,0.095169,288.930023,14.718798,0.951689,-896.913879,294.500488,0.000000
81.880005,64.886284,-896.913879,-0.002402,0.003752,0.095290,288.628601,14.703442,0.952900,-896.913879,294.500488,0.000000
82.250008,64.908623,-896.958374,-0.002389,0.003756,0.095411,288.727966,14.708505,0.954111,-896.958374,294.500488,0.000000
82.620003,64.529167,-897.002869,-0.002397,0.003757,0.095420,287.040070,14.622519,0.954202,-897.002869,294.500488,0.000000
82.990005,66.115486,-896.958374,-0.002376,0.003775,0.095897,294.096375,14.981983,0.958971,-896.958374,294.500488,0.000000
83.360001,65.581490,-896.958374,-0.002380,0.003770,0.095767,291.721039,14.860978,0.957669,-896.958374,294.500488,0.000000
83.730003,65.119011,-897.002869,-0.002380,0.003770,0.095767,289.663818,14.756179,0.957669,-897.002869,294.500488,0.000000
84.100006,65.184914,-897.047363,-0.002358,0.003782,0.096071,289.956970,14.771112,0.960712,-897.047363,294.500488,0.000000
84.470001,64.993523,-897.047363,-0.002376,0.003782,0.096071,289.105621,14.727742,0.960712,-897.047363,294.500488,0.000000
84.840004,65.553200,-897.002869,-0.002363,0.003792,0.096323,291.595184,14.854568,0.963225,-897.002869,294.500488,0.000000
85.210007,65.237053,-896.958374,-0.002384,0.003792,0.096323,290.188904,14.782928,0.963225,-896.958374,294.500488,0.000000
85.580002,64.902657,-897.047363,-0.002384,0.003793,0.096348,288.701447,14.707152,0.963483,-897.047363,294.500488,0.000000
85.950005,64.856117,-897.091797,-0.002376,0.003807,0.096695,288.494415,14.696606,0.966950,-897.091797,294.500488,0.000000
86.320007,65.570320,-897.047363,-0.002371,0.003806,0.096660,291.671356,14.858447,0.966602,-897.047363,294.500488,0.000000
86.690002,65.196465,-897.047363,-0.002358,0.003806,0.096669,290.008362,14.773730,0.966692,-897.047363,294.500488,0.000000
87.060005,65.322319,-897.047363,-0.002367,0.003814,0.096869,290.568176,14.802249,0.968691,-897.047363,294.500488,0.000000
87.430008,65.147682,-897.091797,-0.002367,0.003815,0.096904,289.791351,14.762676,0.969039,-897.091797,294.500488,0.000000
87.800003,65.041557,-897.047363,-0.002363,0.003817,0.096946,289.319305,14.738627,0.969463,-897.047363,294.500488,0.000000
88.170006,65.473885,-897.047363,-0.002367,0.003824,0.097120,291.242371,14.836595,0.971204,-897.047363,294.500488,0.000000
88.540001,65.167046,-897.091797,-0.002350,0.003824,0.097137,289.877502,14.767064,0.971371,-897.091797,294.500488,0.000000
88.910004,65.043419,-897.047363,-0.002354,0.003827,0.097207,289.327576,14.739050,0.972067,-897.047363,294.500488,0.000000
89.280006,64.860207,-897.091797,-0.002354,0.003829,0.097251,288.512604,14.697534,0.972506,-897.091797,294.500488,0.000000
89.650002,64.871376,-897.091797,-0.002350,0.003832,0.097320,288.562286,14.700065,0.973202,-897.091797,294.500488,0.000000
90.020004,65.110451,-897.091797,-0.002341,0.003848,0.097737,289.625763,14.754239,0.977366,-897.091797,294.500488,0.000000
90.390007,65.689857,-897.136292,-0.002354,0.003839,0.097502,292.203094,14.885534,0.975019,-897.136292,294.500488,0.000000
90.760002,65.316368,-897.091797,-0.002358,0.003839,0.097502,290.541718,14.800900,0.975019,-897.091797,294.500488,0.000000
91.130005,64.977882,-897.136292,-0.002341,0.003839,0.097502,289.036041,14.724199,0.975019,-897.136292,294.500488,0.000000
91.500008,64.684074,-897.180786,-0.002337,0.003839,0.097502,287.729126,14.657620,0.975019,-897.180786,294.500488,0.000000
91.870003,66.420448,-897.180786,-0.002328,0.003829,0.097267,295.452911,15.051089,0.972673,-897.180786,294.500488,0.000000
92.240005,66.066322,-897.091797,-0.002324,0.003829,0.097267,293.877686,14.970842,0.972673,-897.091797,294.500488,0.000000
92.610001,65.775505,-897.136292,-0.002333,0.003829,0.097267,292.584045,14.904942,0.972673,-897.136292,294.500488,0.000000
92.980003,65.413933,-897.180786,-0.002320,0.003830,0.097276,290.975708,14.823009,0.972763,-897.180786,294.500488,0.000000
93.350006,65.175240,-897.136292,-0.002328,0.003848,0.097737,289.913940,14.768920,0.977366,-897.136292,294.500488,0.000000
93.720001,65.091820,-897.180786,-0.002315,0.003861,0.098074,289.542877,14.750017,0.980742,-897.180786,294.500488,0.000000
94.090004,64.968941,-897.180786,-0.002307,0.003862,0.098091,288.996277,14.722173,0.980909,-897.180786,294.500488,0.000000
94.460007,65.051613,-897.180786,-0.002320,0.003866,0.098204,289.364014,14.740906,0.982044,-897.180786,294.500488,0.000000
94.830002,64.868034,-897.269714,-0.002320,0.003866,0.098204,288.547424,14.699306,0.982044,-897.269714,294.500488,0.000000
95.200005,65.503304,-897.269714,-0.002328,0.003878,0.098491,291.373260,14.843261,0.984905,-897.269714,294.500488,0.000000
95.570007,65.358818,-897.269714,-0.002328,0.003878,0.098491,290.730530,14.810520,0.984905,-897.269714,294.500488,0.000000
95.940002,65.170769,-897.136292,-0.002315,0.003878,0.098491,289.894043,14.767907,0.984905,-897.136292,294.500488,0.000000
96.310005,64.999474,-897.225281,-0.002307,0.003878,0.098500,289.132111,14.729092,0.984996,-897.225281,294.500488,0.000000
96.680008,64.759300,-897.225281,-0.002311,0.003878,0.098500,288.063751,14.674667,0.984996,-897.225281,294.500488,0.000000
97.050003,65.707359,-897.314209,-0.002311,0.003896,0.098958,292.280945,14.889501,0.989583,-897.314209,294.500488,0.000000
97.420006,65.832481,-897.269714,-0.002315,0.003893,0.098889,292.837494,14.917853,0.988887,-897.269714,294.500488,0.000000
97.790001,65.627678,-897.225281,-0.002320,0.003893,0.098889,291.926483,14.871445,0.988887,-897.225281,294.500488,0.000000
98.160004,65.454521,-897.225281,-0.002324,0.003893,0.098889,291.156250,14.832207,0.988887,-897.225281,294.500488,0.000000
98.530006,65.254921,-897.314209,-0.002311,0.003893,0.098889,290.268372,14.786977,0.988887,-897.314209,294.500488,0.000000
98.900002,65.037086,-897.314209,-0.002298,0.003893,0.098889,289.299408,14.737615,0.988887,-897.314209,294.500488,0.000000
99.270004,64.830421,-897.314209,-0.002328,0.003894,0.098898,288.380127,14.690784,0.988978,-897.314209,294.500488,0.000000
99.640007,64.637154,-897.314209,-0.002311,0.003894,0.098898,287.520416,14.646988,0.988978,-897.314209,294.500488,0.000000
100.010002,65.753532,-897.314209,-0.002311,0.003908,0.099263,292.486328,14.899963,0.992627,-897.314209,294.500488,0.000000
100.380005,65.613518,-897.403198,-0.002302,0.003908,0.099263,291.863495,14.868236,0.992627,-897.403198,294.500488,0.000000
100.750008,65.472023,-897.358704,-0.002298,0.003908,0.099263,291.234100,14.836172,0.992627,-897.358704,294.500488,0.000000
101.120003,65.291786,-897.314209,-0.002302,0.003908,0.099263,290.432373,14.795330,0.992627,-897.314209,294.500488,0.000000
101.490005,65.104118,-897.314209,-0.002302,0.003908,0.099263,289.597595,14.752804,0.992627,-897.314209,294.500488,0.000000
101.860008,64.933189,-897.358704,-0.002315,0.003908,0.099270,288.837250,14.714071,0.992702,-897.358704,294.500488,0.000000
102.230003,64.884041,-897.447693,-0.002315,0.003911,0.099332,288.618622,14.702934,0.993323,-897.447693,294.500488,0.000000
102.600006,64.955162,-897.403198,-0.002298,0.003914,0.099410,288.934998,14.719049,0.994095,-897.403198,294.500488,0.000000
102.970001,64.821480,-897.358704,-0.002298,0.003914,0.099410,288.340332,14.688757,0.994095,-897.358704,294.500488,0.000000
103.340004,65.271675,-897.358704,-0.002285,0.003921,0.099600,290.342926,14.790773,0.996003,-897.358704,294.500488,0.000000
103.710007,65.235939,-897.358704,-0.002302,0.003921,0.099600,290.183960,14.782675,0.996003,-897.358704,294.500488,0.000000
104.080002,65.080284,-897.447693,-0.002294,0.003921,0.099600,289.491577,14.747403,0.996003,-897.447693,294.500488,0.000000
104.450005,64.958519,-897.447693,-0.002302,0.003921,0.099600,288.949921,14.719810,0.996003,-897.447693,294.500488,0.000000
104.820007,64.792809,-897.358704,-0.002285,0.003922,0.099609,288.212799,14.682261,0.996094,-897.358704,294.500488,0.000000
105.190002,65.220299,-897.403198,-0.002294,0.003928,0.099782,290.114380,14.779131,0.997819,-897.403198,294.500488,0.000000
105.560005,65.133904,-897.358704,-0.002307,0.003928,0.099782,289.730072,14.759553,0.997819,-897.358704,294.500488,0.000000
105.930008,64.998741,-897.447693,-0.002285,0.003928,0.099782,289.128845,14.728925,0.997819,-897.447693,294.500488,0.000000
106.300003,64.881065,-897.403198,-0.002302,0.003929,0.099791,288.605408,14.702259,0.997910,-897.403198,294.500488,0.000000
106.670006,64.902657,-897.358704,-0.002298,0.003932,0.099870,288.701447,14.707152,0.998698,-897.358704,294.500488,0.000000
107.040009,64.854256,-897.447693,-0.002289,0.003932,0.099870,288.486145,14.696184,0.998698,-897.447693,294.500488,0.000000
107.410004,65.240028,-897.492126,-0.002294,0.003938,0.100035,290.202148,14.783602,1.000348,-897.492126,294.500488,0.000000
107.780006,65.202415,-897.447693,-0.002285,0.003938,0.100035,290.034821,14.775078,1.000348,-897.447693,294.500488,0.000000
108.150002,65.066139,-897.447693,-0.002276,0.003938,0.100035,289.428650,14.744198,1.000348,-897.447693,294.500488,0.000000
108.520004,64.963737,-897.447693,-0.002285,0.003938,0.100035,288.973145,14.720993,1.000348,-897.447693,294.500488,0.000000
108.890007,64.842339,-897.447693,-0.002272,0.003939,0.100061,288.433136,14.693484,1.000605,-897.447693,294.500488,0.000000
109.260002,64.745155,-897.492126,-0.002281,0.003940,0.100068,288.000824,14.671461,1.000681,-897.492126,294.500488,0.000000
109.630005,65.230354,-897.403198,-0.002268,0.003946,0.100233,290.159119,14.781409,1.002331,-897.403198,294.500488,0.000000
110.000008,65.148430,-897.536621,-0.002289,0.003946,0.100233,289.794678,14.762845,1.002331,-897.536621,294.500488,0.000000
110.370003,65.043785,-897.492126,-0.002281,0.003946,0.100233,289.329193,14.739132,1.002331,-897.492126,294.500488,0.000000
110.740005,64.942879,-897.492126,-0.002289,0.003946,0.100233,288.880341,14.716267,1.002331,-897.492126,294.500488,0.000000
111.110008,64.810692,-897.492126,-0.002276,0.003946,0.100233,288.292358,14.686313,1.002331,-897.492126,294.500488,0.000000
111.480003,65.237053,-897.536621,-0.002281,0.003952,0.100389,290.188904,14.782928,1.003890,-897.536621,294.500488,0.000000
111.850006,65.148430,-897.536621,-0.002281,0.003952,0.100389,289.794678,14.762845,1.003890,-897.536621,294.500488,0.000000
112.220009,65.056084,-897.492126,-0.002285,0.003952,0.100389,289.383911,14.741920,1.003890,-897.492126,294.500488,0.000000
112.590004,64.939156,-897.492126,-0.002276,0.003953,0.100398,288.863800,14.715423,1.003981,-897.492126,294.500488,0.000000
112.960007,64.818871,-897.492126,-0.002276,0.003953,0.100398,288.328735,14.688166,1.003981,-897.492126,294.500488,0.000000
113.330002,65.362541,-897.581116,-0.002281,0.003961,0.100607,290.747101,14.811363,1.006070,-897.581116,294.500488,0.000000
113.700005,65.361427,-897.581116,-0.002272,0.003961,0.100598,290.742157,14.811111,1.005980,-897.581116,294.500488,0.000000
114.070007,65.291420,-897.492126,-0.002268,0.003961,0.100598,290.430756,14.795248,1.005980,-897.492126,294.500488,0.000000
114.440002,65.207634,-897.536621,-0.002276,0.003961,0.100598,290.058044,14.776261,1.005980,-897.536621,294.500488,0.000000
114.810005,65.072456,-897.492126,-0.002285,0.003961,0.100607,289.456757,14.745629,1.006070,-897.492126,294.500488,0.000000
115.180008,64.973778,-897.581116,-0.002276,0.003961,0.100607,289.017792,14.723269,1.006070,-897.581116,294.500488,0.000000
115.550003,64.879570,-897.581116,-0.002264,0.003961,0.100615,288.598755,14.701921,1.006146,-897.581116,294.500488,0.000000
115.920006,64.807701,-897.536621,-0.002272,0.003962,0.100633,288.279053,14.685635,1.006328,-897.536621,294.500488,0.000000
116.290009,65.543892,-897.536621,-0.002268,0.003970,0.100849,291.553802,14.852458,1.008493,-897.536621,294.500488,0.000000
116.660004,65.492500,-897.536621,-0.002268,0.003970,0.100849,291.325195,14.840813,1.008493,-897.536621,294.500488,0.000000
117.030006,65.385262,-897.625610,-0.002276,0.003970,0.100849,290.848175,14.816512,1.008493,-897.625610,294.500488,0.000000
117.400009,65.302956,-897.581116,-0.002272,0.003970,0.100849,290.482056,14.797861,1.008493,-897.581116,294.500488,0.000000
117.770004,65.213966,-897.581116,-0.002255,0.003970,0.100849,290.086212,14.777697,1.008493,-897.581116,294.500488,0.000000
118.140007,65.110069,-897.536621,-0.002259,0.003970,0.100849,289.624054,14.754152,1.008493,-897.536621,294.500488,0.000000
118.510002,65.019585,-897.625610,-0.002264,0.003970,0.100849,289.221558,14.733649,1.008493,-897.625610,294.500488,0.000000
118.880005,64.934319,-897.625610,-0.002264,0.003970,0.100849,288.842285,14.714327,1.008493,-897.625610,294.500488,0.000000
119.250008,64.806221,-897.670044,-0.002272,0.003970,0.100849,288.272461,14.685300,1.008493,-897.670044,294.500488,0.000000
119.620003,64.721687,-897.625610,-0.002246,0.003970,0.100849,287.896454,14.666143,1.008493,-897.625610,294.500488,0.000000
119.990005,64.629707,-897.581116,-0.002251,0.003970,0.100849,287.487305,14.645302,1.008493,-897.581116,294.500488,0.000000
120.360008,66.140434,-897.670044,-0.002264,0.003979,0.101066,294.207336,14.987637,1.010658,-897.670044,294.500488,0.000000
120.730003,66.004143,-897.714539,-0.002259,0.003979,0.101058,293.601105,14.956753,1.010582,-897.714539,294.500488,0.000000
121.100006,65.861519,-897.670044,-0.002242,0.003978,0.101049,292.966675,14.924434,1.010491,-897.670044,294.500488,0.000000
121.470009,65.781456,-897.714539,-0.002255,0.003978,0.101049,292.610535,14.906291,1.010491,-897.714539,294.500488,0.000000
121.840004,65.676445,-897.670044,-0.002242,0.003978,0.101049,292.143433,14.882495,1.010491,-897.670044,294.500488,0.000000
122.210007,65.543144,-897.714539,-0.002272,0.003979,0.101058,291.550476,14.852289,1.010582,-897.714539,294.500488,0.000000
122.580009,65.433662,-897.759033,-0.002259,0.003979,0.101058,291.063477,14.827479,1.010582,-897.759033,294.500488,0.000000
122.950005,65.333504,-897.714539,-0.002242,0.003979,0.101058,290.617950,14.804784,1.010582,-897.714539,294.500488,0.000000
123.320007,65.238167,-897.670044,-0.002246,0.003979,0.101058,290.193848,14.783179,1.010582,-897.670044,294.500488,0.000000
123.690002,65.134651,-897.670044,-0.002246,0.003979,0.101058,289.733398,14.759723,1.010582,-897.670044,294.500488,0.000000
124.060005,65.034859,-897.803528,-0.002259,0.003979,0.101058,289.289490,14.737109,1.010582,-897.803528,294.500488,0.000000
124.430008,64.936546,-897.759033,-0.002259,0.003979,0.101058,288.852173,14.714832,1.010582,-897.759033,294.500488,0.000000
124.800003,64.836754,-897.803528,-0.002246,0.003979,0.101058,288.408295,14.692219,1.010582,-897.803528,1681.640991,0.000000
125.170006,64.714241,-897.848022,-0.002238,0.003970,0.100833,287.863312,14.664456,1.008326,-897.848022,0.100589,0.000000
125.540009,64.582420,-897.714539,-0.002238,0.003953,0.100398,287.276947,14.634586,1.003981,-897.714539,0.099973,0.000000
125.910004,64.412987,-897.714539,-0.002238,0.003933,0.099895,286.523285,14.596191,0.998955,-897.714539,0.099358,0.000000
126.280006,64.323616,-897.803528,-0.002233,0.003914,0.099410,286.125732,14.575939,0.994095,-897.803528,0.098742,0.000000
126.650009,64.213402,-897.848022,-0.002242,0.003885,0.098681,285.635468,14.550964,0.986813,-897.848022,0.098126,0.000000
127.020004,64.110619,-897.848022,-0.002246,0.003860,0.098039,285.178284,14.527675,0.980394,-897.848022,0.097502,0.000000
127.390007,64.033913,-897.803528,-0.002233,0.003839,0.097511,284.837067,14.510292,0.975110,-897.803528,0.096886,0.000000
127.760010,63.936348,-897.714539,-0.002251,0.003816,0.096921,284.403076,14.488183,0.969206,-897.714539,0.096271,0.000000
128.130005,63.804543,-897.848022,-0.002238,0.003793,0.096348,283.816772,14.458316,0.963483,-897.848022,0.095655,0.000000
128.500000,63.622810,-897.892456,-0.002229,0.003768,0.095706,283.008392,14.417134,0.957064,-897.892456,0.095039,0.000000
128.870010,63.182304,-897.848022,-0.002212,0.003746,0.095160,281.048920,14.317314,0.951598,-897.848022,0.094423,0.000000
129.240005,62.509048,-897.803528,-0.002212,0.003726,0.094648,278.054138,14.164753,0.946481,-897.803528,0.093808,0.000000
129.610001,61.687973,-897.848022,-0.002212,0.003704,0.094094,274.401794,13.978694,0.940940,-897.848022,0.093192,0.000000
129.980011,60.570480,-897.848022,-0.002225,0.003679,0.093452,269.430939,13.725468,0.934521,-897.848022,0.092575,0.000000
130.350006,59.025879,-897.936951,-0.002207,0.003656,0.092854,262.560211,13.375456,0.928541,-897.936951,0.091952,0.000000
130.720001,57.401215,-897.892456,-0.002207,0.003632,0.092247,255.333359,13.007301,0.922470,-897.892456,0.091336,0.000000
131.090012,55.801132,-897.848022,-0.002207,0.003613,0.091770,248.215836,12.644717,0.917701,-897.848022,0.090719,0.000000
131.460007,53.841339,-897.848022,-0.002207,0.003591,0.091214,239.498245,12.200622,0.912145,-897.848022,0.090105,0.000000
131.830002,51.428368,-897.892456,-0.002207,0.003564,0.090529,228.764801,11.653834,0.905286,-897.892456,0.089489,0.000000
132.200012,49.321480,-897.892456,-0.002203,0.003542,0.089965,219.392899,11.176407,0.899654,-897.892456,0.088872,0.000000
132.570007,46.336914,-897.848022,-0.002203,0.003514,0.089263,206.116882,10.500094,0.892630,-897.848022,0.088258,0.000000
132.940002,44.275085,-897.892456,-0.002199,0.003495,0.088760,196.945419,10.032878,0.887603,-897.892456,0.087642,0.000000
133.310013,42.313431,-897.892456,-0.002207,0.003476,0.088293,188.219543,9.588361,0.882925,-897.892456,0.087025,0.000000
133.680008,39.009369,-897.892456,-0.002212,0.003444,0.087486,173.522339,8.839649,0.874856,-897.892456,0.086402,0.000000
134.050003,36.890198,-897.936951,-0.002195,0.003427,0.087044,164.095795,8.359439,0.870435,-897.936951,0.085785,0.000000
134.420013,33.596939,-897.936951,-0.002203,0.003393,0.086193,149.446655,7.613175,0.861927,-897.936951,0.085169,0.000000
134.790009,30.807869,-897.892456,-0.002199,0.003371,0.085613,137.040253,6.981163,0.856128,-897.892456,0.084555,0.000000
135.160004,29.003723,-897.936951,-0.002195,0.003352,0.085143,129.014999,6.572338,0.851435,-897.936951,0.083938,0.000000
135.530014,25.899628,-897.981445,-0.002207,0.003325,0.084450,115.207298,5.868939,0.844501,-897.981445,0.083322,0.000000
135.900009,23.745819,-897.981445,-0.002203,0.003305,0.083955,105.626678,5.380879,0.839550,-897.981445,0.082708,0.000000
136.270004,21.169006,-897.936951,-0.002207,0.003281,0.083349,94.164444,4.796966,0.833494,-897.936951,0.082091,0.000000
136.639999,18.188911,-897.981445,-0.002203,0.003250,0.082552,80.908318,4.121666,0.825516,-897.981445,0.081466,0.000000
137.010010,16.044044,-897.936951,-0.002212,0.003230,0.082047,71.367477,3.635633,0.820474,-897.936951,0.080851,0.000000
137.380005,12.605553,-897.936951,-0.002216,0.003197,0.081198,56.072300,2.856459,0.811981,-897.936951,0.080235,0.000000
137.750000,10.405205,-897.936951,-0.002216,0.003175,0.080642,46.284664,2.357853,0.806425,-897.936951,0.079619,0.000000
138.120010,8.098358,-897.981445,-0.002212,0.003153,0.080088,36.023296,1.835114,0.800884,-897.981445,0.079004,0.000000
138.490005,5.640701,-897.981445,-0.002212,0.003127,0.079421,25.091093,1.278201,0.794207,-897.981445,0.078388,0.000000
138.860001,3.682770,-897.981445,-0.002203,0.003108,0.078944,16.381779,0.834528,0.789438,-897.981445,0.077772,0.000000
139.230011,1.380013,-897.981445,-0.002199,0.003083,0.078302,6.138602,0.312715,0.783019,-897.981445,0.077157,0.000000
139.600006,-0.472168,-897.981445,-0.002220,0.003062,0.077764,-2.100308,-0.106995,0.777645,-897.981445,0.076541,0.000000
139.970001,-3.045258,-898.025940,-0.002212,0.003029,0.076932,-13.545982,-0.690065,0.769318,-898.025940,0.075916,0.000000
140.340012,-0.469185,-897.981445,-0.002264,0.003003,0.076272,-2.087039,-0.106319,0.762717,-897.981445,0.075301,0.000000
140.710007,-0.264381,-897.981445,-0.002255,0.002981,0.075725,-1.176027,-0.059910,0.757252,-897.981445,0.074685,0.000000
141.080002,-0.212997,-898.070374,-0.002289,0.002953,0.075006,-0.947460,-0.048266,0.750060,-898.070374,0.074069,0.000000
141.450012,-0.053993,-897.981445,-0.002289,0.002935,0.074546,-0.240174,-0.012235,0.745458,-897.981445,0.073454,0.000000
141.820007,-0.004463,-898.070374,-0.002294,0.002915,0.074043,-0.019853,-0.001011,0.740431,-898.070374,0.072838,0.000000
142.190002,-0.037979,-897.981445,-0.002315,0.002884,0.073263,-0.168940,-0.008606,0.732635,-897.981445,0.072222,0.000000
142.560013,-0.047287,-897.936951,-0.002320,0.002859,0.072629,-0.210343,-0.010715,0.726291,-897.936951,0.071607,0.000000
142.930008,-0.004837,-897.981445,-0.002328,0.002839,0.072117,-0.021516,-0.001096,0.721174,-897.981445,0.070991,0.000000
143.300003,-0.009682,-898.159363,-0.002350,0.002817,0.071554,-0.043066,-0.002194,0.715542,-898.159363,0.070366,0.000000
143.670013,0.001862,-898.025940,-0.002341,0.002797,0.071042,0.008281,0.000422,0.710425,-898.025940,0.069751,0.000000
144.040009,0.008568,-898.070374,-0.002337,0.002768,0.070298,0.038112,0.001941,0.702976,-898.070374,0.069135,0.000000
144.410004,-0.010048,-898.025940,-0.002345,0.002737,0.069516,-0.044695,-0.002277,0.695164,-898.025940,0.068519,0.000000
144.780014,0.001122,-898.070374,-0.002350,0.002722,0.069144,0.004989,0.000254,0.691440,-898.070374,0.067904,0.000000
145.150009,-0.043564,-898.070374,-0.002367,0.002688,0.068286,-0.193782,-0.009872,0.682856,-898.070374,0.067288,0.000000
145.520004,-0.012283,-898.159363,-0.002367,0.002669,0.067790,-0.054639,-0.002783,0.677905,-898.159363,0.066672,0.000000
145.889999,-0.002228,-898.114868,-0.002367,0.002647,0.067244,-0.009910,-0.000505,0.672440,-898.114868,0.066055,0.000000
146.260010,-0.061440,-898.025940,-0.002371,0.002618,0.066507,-0.273297,-0.013922,0.665067,-898.025940,0.065441,0.000000
146.630005,-0.058456,-898.070374,-0.002371,0.002594,0.065883,-0.260027,-0.013246,0.658829,-898.070374,0.064816,0.000000
147.000000,-0.082664,-898.159363,-0.002393,0.002567,0.065190,-0.367710,-0.018732,0.651895,-898.159363,0.064201,0.000000
147.370010,-0.052132,-898.159363,-0.002406,0.002545,0.064634,-0.231893,-0.011813,0.646339,-898.159363,0.063585,0.000000
147.740005,-0.036491,-898.159363,-0.002410,0.002526,0.064157,-0.162322,-0.008269,0.641570,-898.159363,0.062969,0.000000
148.110001,-0.089363,-898.159363,-0.002436,0.002498,0.063455,-0.397507,-0.020250,0.634545,-898.159363,0.062354,0.000000
148.480011,-0.090111,-898.159363,-0.002432,0.002473,0.062822,-0.400833,-0.020419,0.628217,-898.159363,0.061738,0.000000
148.850006,-0.067398,-898.159363,-0.002471,0.002447,0.062154,-0.299802,-0.015273,0.621540,-898.159363,0.061122,0.000000
149.220001,-0.072609,-898.203857,-0.002471,0.002424,0.061582,-0.322981,-0.016453,0.615818,-898.203857,0.060505,0.000000
149.590012,-0.067024,-898.159363,-0.002466,0.002405,0.061087,-0.298139,-0.015188,0.610867,-898.159363,0.059891,0.000000
149.960007,-0.085640,-898.070374,-0.002501,0.002380,0.060463,-0.380946,-0.019406,0.604629,-898.070374,0.059265,0.000000
150.330002,-0.084900,-898.203857,-0.002544,0.002355,0.059812,-0.377654,-0.019239,0.598119,-898.203857,0.058651,0.000000
150.700012,-0.080803,-898.203857,-0.002539,0.002334,0.059284,-0.359429,-0.018310,0.592836,-898.203857,0.058035,0.000000
151.070007,-0.086014,-898.203857,-0.002570,0.002304,0.058528,-0.382608,-0.019491,0.585281,-898.203857,0.057418,0.000000
151.440002,-0.067398,-898.248352,-0.002578,0.002281,0.057939,-0.299802,-0.015273,0.579392,-898.248352,0.056802,0.000000
151.810013,-0.058090,-898.159363,-0.002604,0.002257,0.057323,-0.258398,-0.013163,0.573230,-898.159363,0.056188,0.000000
152.180008,-0.088249,-898.159363,-0.002626,0.002226,0.056534,-0.392552,-0.019998,0.565342,-898.159363,0.055571,0.000000
152.550003,-0.012657,-898.203857,-0.002652,0.002212,0.056178,-0.056302,-0.002868,0.561784,-898.203857,0.056066,0.000000
152.700012,-0.010422,-898.248352,-0.002647,0.002212,0.056197,-0.046358,-0.002362,0.561966,-898.248352,0.056066,0.000000