File: Data/compression 35/ManualNoHeating-10-35-reverse-1-1_11182024_163520.csv
Time (sec),S:Load (lbs),S:HL1 (DIM),S:LVDT (in),S:Position (in),Ch:Position (mm),Ch:Load (N),Ch:Stress (MPa),Ch:Strain (mm/mm),Ch:HL1 (DIM),Set Point (),Cycles ()
0.110000,-0.058830,-790.248596,-0.005670,-0.006253,-0.158823,-0.261690,-0.013331,-1.588233,-790.248596,-0.158589,0.000000
0.520000,0.038361,-790.382019,-0.005665,-0.006188,-0.157184,0.170636,0.008693,-1.571837,-790.382019,-0.156318,0.000000
0.930000,0.009682,-790.204102,-0.005514,-0.005940,-0.150889,0.043066,0.002194,-1.508886,-790.204102,-0.149484,0.000000
1.340000,-0.018242,-790.337524,-0.005234,-0.005679,-0.144236,-0.081144,-0.004134,-1.442363,-790.337524,-0.142666,0.000000
1.750000,0.016388,-790.293030,-0.004945,-0.005400,-0.137151,0.072897,0.003714,-1.371510,-790.293030,-0.135834,0.000000
2.160000,0.215233,-790.248596,-0.004721,-0.000004,-0.000104,0.957404,0.048772,-0.001045,-790.248596,0.000077,0.000000
2.570000,0.189911,-790.337524,-0.004721,-0.000005,-0.000121,0.844766,0.043034,-0.001211,-790.337524,0.000077,0.000000
2.980000,0.106133,-790.337524,-0.004721,-0.000005,-0.000121,0.472101,0.024050,-0.001211,-790.337524,0.000684,0.000000
3.390000,0.205551,-790.382019,-0.004725,0.000011,0.000268,0.914337,0.046579,0.002680,-790.382019,0.001370,0.000000
3.800000,0.325081,-790.337524,-0.004695,0.000034,0.000858,1.446032,0.073664,0.008584,-790.337524,0.002054,0.000000
4.210000,0.412964,-790.382019,-0.004665,0.000069,0.001743,1.836955,0.093579,0.017426,-790.382019,0.002731,0.000000
4.620000,0.480736,-790.426514,-0.004635,0.000093,0.002350,2.138420,0.108936,0.023497,-790.426514,0.003417,0.000000
5.030000,0.583511,-790.382019,-0.004609,0.000114,0.002887,2.595588,0.132226,0.028871,-790.382019,0.004101,0.000000
5.440000,0.841194,-790.426514,-0.004562,0.000145,0.003694,3.741818,0.190617,0.036941,-790.426514,0.004787,0.000000
5.850000,0.999077,-790.382019,-0.004562,0.000170,0.004319,4.444116,0.226394,0.043193,-790.382019,0.005471,0.000000
6.260000,1.149147,-790.426514,-0.004514,0.000197,0.004995,5.111661,0.260400,0.049945,-790.426514,0.006148,0.000000
6.670001,1.322670,-790.559937,-0.004497,0.000228,0.005785,5.883530,0.299721,0.057848,-790.559937,0.006834,0.000000
7.080000,1.381874,-790.426514,-0.004475,0.000242,0.006157,6.146883,0.313137,0.061573,-790.426514,0.007518,0.000000
7.490000,1.693550,-790.471008,-0.004424,0.000279,0.007085,7.533287,0.383764,0.070853,-790.471008,0.008204,0.000000
7.900001,1.878998,-790.515442,-0.004406,0.000306,0.007770,8.358200,0.425787,0.077696,-790.515442,0.008888,0.000000
8.310000,1.978043,-790.515442,-0.004368,0.000325,0.008265,8.798773,0.448231,0.082647,-790.515442,0.009565,0.000000
8.720000,2.169075,-790.559937,-0.004355,0.000354,0.008993,9.648527,0.491519,0.089929,-790.559937,0.010251,0.000000
9.130000,2.328819,-790.471008,-0.004324,0.000379,0.009626,10.359105,0.527718,0.096257,-790.471008,0.010935,0.000000
9.540001,2.650177,-790.559937,-0.004273,0.000414,0.010510,11.788576,0.600539,0.105099,-790.559937,0.011621,0.000000
9.950001,2.707527,-790.471008,-0.004247,0.000440,0.011187,12.043682,0.613534,0.111866,-790.471008,0.012305,0.000000
10.360001,2.926476,-790.515442,-0.004221,0.000467,0.011872,13.017613,0.663149,0.118725,-790.515442,0.012982,0.000000
10.770000,2.939880,-790.515442,-0.004186,0.000489,0.012427,13.077241,0.666186,0.124266,-790.515442,0.013668,0.000000
11.180000,3.154373,-790.515442,-0.004139,0.000521,0.013243,14.031353,0.714791,0.132426,-790.515442,0.014352,0.000000
11.590000,3.295502,-790.648926,-0.004122,0.000551,0.013989,14.659123,0.746771,0.139890,-790.648926,0.015038,0.000000
12.000001,3.313370,-790.559937,-0.004092,0.000570,0.014483,14.738605,0.750820,0.144825,-790.559937,0.015722,0.000000
12.410001,3.477592,-790.604431,-0.004044,0.000596,0.015134,15.469104,0.788034,0.151335,-790.604431,0.016399,0.000000
12.820001,3.509239,-790.604431,-0.004023,0.000623,0.015827,15.609876,0.795205,0.158269,-790.604431,0.017084,0.000000
13.230000,3.585205,-790.559937,-0.003962,0.000650,0.016504,15.947788,0.812419,0.165037,-790.559937,0.017769,0.000000
13.640000,3.696548,-790.604431,-0.003941,0.000677,0.017206,16.443069,0.837650,0.172061,-790.604431,0.018455,0.000000
14.050000,3.826134,-790.604431,-0.003902,0.000709,0.018012,17.019493,0.867014,0.180116,-790.604431,0.019139,0.000000
14.460001,3.797829,-790.693359,-0.003863,0.000729,0.018523,16.893585,0.860600,0.185233,-790.693359,0.019816,0.000000
14.870001,3.766922,-790.693359,-0.003859,0.000749,0.019018,16.756105,0.853597,0.190183,-790.693359,0.020501,0.000000
15.280001,4.037636,-790.693359,-0.003794,0.000791,0.020102,17.960300,0.914941,0.201023,-790.693359,0.021186,0.000000
15.690001,3.932259,-790.693359,-0.003760,0.000811,0.020596,17.491560,0.891063,0.205959,-790.693359,0.021871,0.000000
16.100000,3.971359,-790.648926,-0.003725,0.000839,0.021307,17.665487,0.899923,0.213074,-790.648926,0.022556,0.000000
16.510000,4.045082,-790.693359,-0.003691,0.000868,0.022045,17.993423,0.916629,0.220447,-790.693359,0.023233,0.000000
16.920000,3.913269,-790.693359,-0.003682,0.000882,0.022391,17.407089,0.886759,0.223914,-790.693359,0.023918,0.000000
17.330000,4.226059,-790.693359,-0.003613,0.000924,0.023475,18.798449,0.957639,0.234754,-790.693359,0.024603,0.000000
17.740002,4.264786,-790.826843,-0.003583,0.000951,0.024161,18.970715,0.966414,0.241613,-790.826843,0.025288,0.000000
18.150002,4.287125,-790.737854,-0.003553,0.000975,0.024776,19.070084,0.971476,0.247759,-790.737854,0.025973,0.000000
18.560001,4.287498,-790.737854,-0.003514,0.001001,0.025427,19.071745,0.971561,0.254269,-790.737854,0.026650,0.000000
18.970001,4.237602,-790.737854,-0.003471,0.001022,0.025948,18.849796,0.960254,0.259477,-790.737854,0.027335,0.000000
19.380001,4.509064,-790.737854,-0.003441,0.001059,0.026902,20.057318,1.021768,0.269015,-790.737854,0.028020,0.000000
19.790001,4.345215,-790.826843,-0.003397,0.001079,0.027395,19.328482,0.984640,0.273951,-790.826843,0.028705,0.000000
20.200001,4.430862,-790.782349,-0.003354,0.001111,0.028211,19.709461,1.004048,0.282111,-790.782349,0.029390,0.000000
20.610001,4.618164,-790.826843,-0.003328,0.001143,0.029035,20.542620,1.046491,0.290347,-790.826843,0.030067,0.000000
21.020000,4.393623,-790.826843,-0.003303,0.001155,0.029337,19.543814,0.995609,0.293375,-790.826843,0.030752,0.000000
21.430000,4.593590,-790.871338,-0.003251,0.001194,0.030335,20.433308,1.040922,0.303352,-790.871338,0.031437,0.000000
21.840000,4.706421,-790.871338,-0.003221,0.001224,0.031098,20.935205,1.066490,0.310982,-790.871338,0.032122,0.000000
22.250002,4.505707,-790.871338,-0.003186,0.001243,0.031568,20.042385,1.021008,0.315675,-790.871338,0.032807,0.000000
22.660002,4.675140,-790.915771,-0.003134,0.001272,0.032312,20.796062,1.059402,0.323124,-790.915771,0.033483,0.000000
23.070002,4.862442,-790.826843,-0.003100,0.001306,0.033171,21.629223,1.101845,0.331708,-790.826843,0.034169,0.000000
23.480001,4.802864,-790.960266,-0.003070,0.001332,0.033822,21.364206,1.088345,0.338218,-790.960266,0.034854,0.000000
23.890001,4.942505,-790.915771,-0.003035,0.001358,0.034489,21.985359,1.119988,0.344895,-790.915771,0.035539,0.000000
24.300001,4.830788,-790.871338,-0.002988,0.001384,0.035166,21.488417,1.094672,0.351662,-790.871338,0.036224,0.000000
24.710001,4.963730,-790.960266,-0.002958,0.001410,0.035825,22.079773,1.124797,0.358248,-790.960266,0.036900,0.000000
25.120001,5.053841,-790.915771,-0.002923,0.001438,0.036536,22.480606,1.145217,0.365363,-790.915771,0.037586,0.000000
25.530001,5.099648,-790.915771,-0.002876,0.001464,0.037178,22.684364,1.155597,0.371783,-790.915771,0.038270,0.000000
25.940001,5.093689,-790.915771,-0.002850,0.001491,0.037881,22.657860,1.154246,0.378807,-790.915771,0.038956,0.000000
26.350000,5.005432,-790.915771,-0.002820,0.001512,0.038409,22.265274,1.134247,0.384091,-790.915771,0.039641,0.000000
26.760002,5.224388,-791.049255,-0.002798,0.001544,0.039216,23.239239,1.183863,0.392161,-791.049255,0.040317,0.000000
27.170002,5.251572,-791.004761,-0.002742,0.001572,0.039935,23.360157,1.190023,0.399352,-791.004761,0.041003,0.000000
27.580002,5.188271,-791.049255,-0.002708,0.001592,0.040430,23.078581,1.175679,0.404302,-791.049255,0.041687,0.000000
27.990002,5.388977,-791.004761,-0.002695,0.001626,0.041305,23.971367,1.221160,0.413053,-791.004761,0.042373,0.000000
28.400002,5.215454,-791.049255,-0.002656,0.001641,0.041679,23.199499,1.181839,0.416793,-791.049255,0.043057,0.000000
28.810001,5.474625,-791.138184,-0.002608,0.001678,0.042624,24.352346,1.240568,0.426240,-791.138184,0.043734,0.000000
29.220001,5.438133,-791.049255,-0.002578,0.001705,0.043310,24.190025,1.232299,0.433098,-791.049255,0.044420,0.000000
29.630001,5.341316,-791.093689,-0.002527,0.001726,0.043838,23.759361,1.210359,0.438382,-791.093689,0.045104,0.000000
30.040001,5.389351,-791.049255,-0.002501,0.001753,0.044522,23.973030,1.221244,0.445225,-791.049255,0.045790,0.000000
30.450001,5.473877,-791.093689,-0.002466,0.001778,0.045173,24.349020,1.240398,0.451735,-791.093689,0.046474,0.000000
30.860001,5.748688,-791.093689,-0.002427,0.001816,0.046127,25.571440,1.302671,0.461273,-791.093689,0.047151,0.000000
31.270002,5.681664,-791.138184,-0.002371,0.001843,0.046804,25.273302,1.287483,0.468040,-791.138184,0.047837,0.000000
31.680002,5.659317,-791.138184,-0.002341,0.001866,0.047394,25.173899,1.282420,0.473945,-791.138184,0.048521,0.000000
32.090000,5.688362,-791.138184,-0.002294,0.001897,0.048183,25.303099,1.289001,0.481832,-791.138184,0.049207,0.000000
32.500000,5.511116,-791.227173,-0.002268,0.001915,0.048651,24.514668,1.248837,0.486510,-791.227173,0.049891,0.000000
32.910000,5.730072,-791.227173,-0.002242,0.001949,0.049509,25.488634,1.298453,0.495095,-791.227173,0.050568,0.000000
33.320000,5.604950,-791.182678,-0.002203,0.001969,0.050021,24.932062,1.270100,0.500212,-791.182678,0.051254,0.000000
33.730003,5.665649,-791.271667,-0.002164,0.001994,0.050637,25.202066,1.283854,0.506374,-791.271667,0.051938,0.000000
34.140003,5.615005,-791.182678,-0.002134,0.002019,0.051270,24.976791,1.272378,0.512702,-791.182678,0.052624,0.000000
34.550003,5.681290,-791.227173,-0.002095,0.002049,0.052033,25.271639,1.287399,0.520332,-791.227173,0.053308,0.000000
34.960003,5.804916,-791.227173,-0.002048,0.002078,0.052780,25.821558,1.315413,0.527796,-791.227173,0.053985,0.000000
35.370003,5.924080,-791.138184,-0.002009,0.002108,0.053534,26.351624,1.342416,0.535336,-791.138184,0.054669,0.000000
35.780003,5.760231,-791.227173,-0.001983,0.002127,0.054020,25.622787,1.305287,0.540195,-791.227173,0.055355,0.000000
36.190002,5.967644,-791.182678,-0.001953,0.002156,0.054757,26.545404,1.352287,0.547568,-791.182678,0.056041,0.000000
36.600002,6.142662,-791.271667,-0.001914,0.002190,0.055624,27.323925,1.391947,0.556243,-791.271667,0.056725,0.000000
37.010002,6.110260,-791.271667,-0.001867,0.002217,0.056318,27.179794,1.384605,0.563177,-791.271667,0.057402,0.000000
37.420002,6.185852,-791.227173,-0.001832,0.002244,0.056994,27.516045,1.401734,0.569945,-791.227173,0.058086,0.000000
37.830002,6.119942,-791.271667,-0.001802,0.002269,0.057636,27.222860,1.386799,0.576364,-791.271667,0.058772,0.000000
38.240002,5.950516,-791.227173,-0.001781,0.002284,0.058025,26.469215,1.348406,0.580255,-791.227173,0.059456,0.000000
38.650002,6.384331,-791.271667,-0.001733,0.002324,0.059032,28.398922,1.446710,0.590322,-791.271667,0.060142,0.000000
39.060001,6.398109,-791.316101,-0.001686,0.002351,0.059709,28.460213,1.449832,0.597090,-791.316101,0.060819,0.000000
39.470001,6.532532,-791.271667,-0.001656,0.002376,0.060349,29.058153,1.480293,0.603494,-791.271667,0.061503,0.000000
39.880001,6.453217,-791.316101,-0.001643,0.002400,0.060949,28.705341,1.462320,0.609489,-791.316101,0.062189,0.000000
40.290001,6.400345,-791.271667,-0.001595,0.002419,0.061452,28.470156,1.450339,0.614516,-791.271667,0.062873,0.000000
40.700001,6.904160,-791.316101,-0.001556,0.002458,0.062440,30.711235,1.564505,0.624402,-791.316101,0.063559,0.000000
41.110001,6.642754,-791.316101,-0.001526,0.002477,0.062917,29.548443,1.505270,0.629171,-791.316101,0.064236,0.000000
41.520000,6.922783,-791.405090,-0.001483,0.002512,0.063801,30.794077,1.568725,0.638012,-791.405090,0.064920,0.000000
41.930000,7.127213,-791.360596,-0.001449,0.002542,0.064557,31.703424,1.615049,0.645567,-791.360596,0.065606,0.000000
42.340000,6.833412,-791.316101,-0.001418,0.002561,0.065041,30.396536,1.548473,0.650411,-791.316101,0.066290,0.000000
42.750004,7.200569,-791.360596,-0.001380,0.002595,0.065901,32.029732,1.631672,0.659011,-791.360596,0.066976,0.000000
43.160004,7.402771,-791.316101,-0.001358,0.002623,0.066629,32.929169,1.677492,0.666293,-791.316101,0.067653,0.000000
43.570004,7.217697,-791.360596,-0.001324,0.002643,0.067132,32.105919,1.635554,0.671319,-791.360596,0.068337,0.000000
43.980003,7.473145,-791.405090,-0.001285,0.002671,0.067843,33.242207,1.693439,0.678435,-791.405090,0.069023,0.000000
44.390003,7.924088,-791.405090,-0.001242,0.002705,0.068719,35.248100,1.795624,0.687186,-791.405090,0.069707,0.000000
44.800003,7.772163,-791.449585,-0.001216,0.002726,0.069239,34.572308,1.761197,0.692394,-791.449585,0.070393,0.000000
45.210003,7.958351,-791.405090,-0.001186,0.002752,0.069907,35.400513,1.803388,0.699070,-791.405090,0.071070,0.000000
45.620003,8.119209,-791.449585,-0.001143,0.002782,0.070661,36.116047,1.839839,0.706610,-791.449585,0.071754,0.000000
46.030003,8.373917,-791.405090,-0.001130,0.002808,0.071312,37.249043,1.897557,0.713120,-791.405090,0.072440,0.000000
46.440002,8.630104,-791.494019,-0.001099,0.002837,0.072049,38.388618,1.955610,0.720493,-791.494019,0.073124,0.000000
46.850002,8.799538,-791.494019,-0.001052,0.002862,0.072699,39.142300,1.994004,0.726987,-791.494019,0.073810,0.000000
47.260002,9.004715,-791.405090,-0.001035,0.002892,0.073463,40.054974,2.040498,0.734633,-791.405090,0.074485,0.000000
47.670002,8.868057,-791.538513,-0.001000,0.002911,0.073931,39.447090,2.009531,0.739311,-791.538513,0.075171,0.000000
48.080002,9.438530,-791.538513,-0.000961,0.002942,0.074738,41.984676,2.138802,0.747380,-791.538513,0.075855,0.000000
48.490002,9.530502,-791.449585,-0.000927,0.002968,0.075388,42.393791,2.159643,0.753875,-791.449585,0.076541,0.000000
48.900002,9.634766,-791.538513,-0.000918,0.002994,0.076039,42.857578,2.183269,0.760385,-791.538513,0.077227,0.000000
49.310001,10.225349,-791.494019,-0.000892,0.003025,0.076827,45.484627,2.317097,0.768273,-791.494019,0.077902,0.000000
49.720001,10.004158,-791.627502,-0.000849,0.003039,0.077200,44.500717,2.266975,0.771997,-791.627502,0.078588,0.000000
50.130001,10.826729,-791.538513,-0.000811,0.003077,0.078163,48.159695,2.453372,0.781626,-791.538513,0.079272,0.000000
50.540001,10.923920,-791.538513,-0.000780,0.003105,0.078856,48.592022,2.475395,0.788560,-791.538513,0.079958,0.000000
50.950001,10.936211,-791.494019,-0.000755,0.003128,0.079456,48.646694,2.478181,0.794555,-791.494019,0.080642,0.000000
51.360001,11.266876,-791.538513,-0.000720,0.003154,0.080105,50.117569,2.553111,0.801050,-791.538513,0.081319,0.000000
51.770004,11.642601,-791.627502,-0.000703,0.003176,0.080677,51.788876,2.638251,0.806773,-791.627502,0.082005,0.000000
52.180004,12.640930,-791.583008,-0.000681,0.003212,0.081589,56.229664,2.864476,0.815887,-791.583008,0.082689,0.000000
52.590004,12.769775,-791.627502,-0.000647,0.003237,0.082222,56.802799,2.893672,0.822215,-791.627502,0.083375,0.000000
53.000004,13.105278,-791.627502,-0.000604,0.003264,0.082907,58.295189,2.969698,0.829074,-791.627502,0.084059,0.000000
53.410004,13.758049,-791.627502,-0.000595,0.003295,0.083705,61.198860,3.117619,0.837052,-791.627502,0.084736,0.000000
53.820004,13.544678,-791.716431,-0.000569,0.003314,0.084173,60.249737,3.069268,0.841730,-791.716431,0.085422,0.000000
54.230003,14.513962,-791.627502,-0.000539,0.003348,0.085041,64.561325,3.288911,0.850405,-791.627502,0.086106,0.000000
54.640003,14.649506,-791.671997,-0.000504,0.003368,0.085552,65.164253,3.319625,0.855523,-791.671997,0.086792,0.000000
55.050003,15.230408,-791.671997,-0.000496,0.003391,0.086125,67.748238,3.451260,0.861245,-791.671997,0.087476,0.000000
55.460003,15.693642,-791.716431,-0.000470,0.003417,0.086792,69.808807,3.556230,0.867922,-791.716431,0.088153,0.000000
55.870003,16.427216,-791.716431,-0.000440,0.003446,0.087520,73.071907,3.722460,0.875204,-791.716431,0.088839,0.000000
56.280003,17.184250,-791.716431,-0.000401,0.003477,0.088318,76.439362,3.894007,0.883183,-791.716431,0.089523,0.000000
56.690002,18.071983,-791.716431,-0.000388,0.003507,0.089072,80.388199,4.095170,0.890722,-791.716431,0.090209,0.000000
57.100002,18.441002,-791.627502,-0.000354,0.003530,0.089663,82.029671,4.178791,0.896626,-791.627502,0.090893,0.000000
57.510002,19.396515,-791.760925,-0.000332,0.003557,0.090347,86.280006,4.395313,0.903470,-791.760925,0.091570,0.000000
57.920002,20.476395,-791.760925,-0.000319,0.003589,0.091154,91.083549,4.640018,0.911539,-791.760925,0.092256,0.000000
58.330002,21.056549,-791.760925,-0.000280,0.003616,0.091847,93.664207,4.771482,0.918473,-791.760925,0.092940,0.000000
58.740002,21.843742,-791.805420,-0.000276,0.003641,0.092473,97.165817,4.949863,0.924726,-791.805420,0.093626,0.000000
59.150002,22.582161,-791.760925,-0.000259,0.003668,0.093157,100.450470,5.117191,0.931569,-791.760925,0.094310,0.000000
59.560001,22.703926,-791.760925,-0.000241,0.003682,0.093513,100.992104,5.144783,0.935126,-791.760925,0.094987,0.000000
59.970001,24.732613,-791.760925,-0.000211,0.003722,0.094536,110.016159,5.604490,0.945361,-791.760925,0.095672,0.000000
60.380001,25.903725,-791.805420,-0.000198,0.003749,0.095213,115.225525,5.869868,0.952128,-791.805420,0.096357,0.000000
60.790005,26.658890,-791.849915,-0.000177,0.003772,0.095811,118.584663,6.040991,0.958108,-791.849915,0.097042,0.000000
61.200005,27.652382,-791.760925,-0.000142,0.003798,0.096462,123.003937,6.266119,0.964618,-791.760925,0.097727,0.000000
61.610004,28.274986,-791.849915,-0.000138,0.003818,0.096974,125.773422,6.407204,0.969736,-791.849915,0.098404,0.000000
62.020004,30.566200,-791.805420,-0.000121,0.003856,0.097953,135.965256,6.926400,0.979531,-791.805420,0.099089,0.000000
62.430004,30.874519,-791.894348,-0.000091,0.003875,0.098430,137.336716,6.996266,0.984300,-791.894348,0.099774,0.000000
62.840004,32.305923,-791.983337,-0.000086,0.003907,0.099244,143.703918,7.320627,0.992445,-791.983337,0.100459,0.000000
63.250004,34.517067,-791.849915,-0.000069,0.003940,0.100086,153.539581,7.821679,1.000862,-791.849915,0.101145,0.000000
63.660004,34.441849,-791.983337,-0.000056,0.003952,0.100381,153.205002,7.804635,1.003815,-791.983337,0.101821,0.000000
64.070000,36.901741,-791.894348,-0.000030,0.003991,0.101379,164.147141,8.362054,1.013792,-791.894348,0.102506,0.000000
64.480003,38.717056,-791.938843,-0.000022,0.004022,0.102150,172.222061,8.773411,1.021498,-791.938843,0.103191,0.000000
64.889999,39.221252,-791.938843,-0.000017,0.004039,0.102584,174.464844,8.887663,1.025843,-791.938843,0.103876,0.000000
65.300003,41.229454,-791.894348,0.000009,0.004070,0.103373,183.397766,9.342728,1.033731,-791.894348,0.104562,0.000000
65.710007,43.277878,-791.938843,0.000030,0.004103,0.104206,192.509613,9.806907,1.042057,-791.938843,0.105238,0.000000
66.120003,44.692894,-791.894348,0.000034,0.004125,0.104769,198.803925,10.127555,1.047689,-791.894348,0.105923,0.000000
66.530006,46.287018,-791.938843,0.000060,0.004150,0.105411,205.894943,10.488789,1.054108,-791.938843,0.106608,0.000000
66.940002,48.209579,-791.938843,0.000047,0.004180,0.106183,214.446915,10.924447,1.061830,-791.938843,0.107293,0.000000
67.350006,49.999947,-791.938843,0.000078,0.004206,0.106834,222.410873,11.330150,1.068340,-791.938843,0.107979,0.000000
67.760002,51.502090,-792.027832,0.000086,0.004233,0.107509,229.092743,11.670541,1.075092,-792.027832,0.108655,0.000000
68.170006,53.846924,-791.938843,0.000099,0.004261,0.108221,239.523087,12.201887,1.082207,-791.938843,0.109340,0.000000
68.580002,55.495789,-791.983337,0.000116,0.004284,0.108802,246.857590,12.575526,1.088021,-791.983337,0.110025,0.000000
68.990005,56.796860,-792.072266,0.000121,0.004305,0.109358,252.645050,12.870353,1.093577,-792.072266,0.110710,0.000000
69.400002,59.761688,-791.938843,0.000147,0.004340,0.110224,265.833252,13.542192,1.102237,-791.938843,0.111396,0.000000
69.810005,61.718132,-792.027832,0.000138,0.004365,0.110875,274.535950,13.985529,1.108747,-792.027832,0.112071,0.000000
70.220001,62.847168,-791.938843,0.000134,0.004384,0.111343,279.558167,14.241372,1.113425,-791.938843,0.112757,0.000000
70.630005,65.307426,-792.072266,0.000160,0.004417,0.112193,290.501953,14.798875,1.121934,-792.072266,0.113442,0.000000
71.040001,65.811989,-792.072266,0.000172,0.004418,0.112210,292.746338,14.913210,1.122100,-792.072266,0.019694,0.000000
71.450005,65.147682,-792.027832,0.000185,0.004418,0.112219,289.791351,14.762676,1.122191,-792.027832,294.500488,0.000000
71.860001,65.012138,-792.027832,0.000172,0.004433,0.112592,289.188446,14.731961,1.125915,-792.027832,294.500488,0.000000
72.270004,65.213219,-792.072266,0.000185,0.004433,0.112592,290.082886,14.777527,1.125915,-792.072266,294.500488,0.000000
72.680000,64.906380,-792.072266,0.000198,0.004433,0.112592,288.717987,14.707996,1.125915,-792.072266,294.500488,0.000000
73.090004,65.019218,-792.116760,0.000185,0.004438,0.112713,289.219940,14.733565,1.127127,-792.116760,294.500488,0.000000
73.500000,64.796165,-792.027832,0.000194,0.004438,0.112713,288.227753,14.683022,1.127127,-792.027832,294.500488,0.000000
73.910004,64.681465,-792.116760,0.000194,0.004445,0.112896,287.717529,14.657030,1.128958,-792.116760,294.500488,0.000000
74.320007,65.346901,-792.116760,0.000190,0.004447,0.112956,290.677521,14.807819,1.129564,-792.116760,294.500488,0.000000
74.730003,65.226997,-792.116760,0.000203,0.004447,0.112956,290.144165,14.780648,1.129564,-792.116760,294.500488,0.000000
75.140007,65.053474,-792.072266,0.000198,0.004447,0.112956,289.372314,14.741328,1.129564,-792.072266,294.500488,0.000000
75.550003,64.929100,-792.116760,0.000203,0.004447,0.112956,288.819061,14.713144,1.129564,-792.116760,294.500488,0.000000
75.960007,64.767494,-792.116760,0.000211,0.004447,0.112956,288.100189,14.676524,1.129564,-792.116760,294.500488,0.000000
76.370003,65.611656,-792.205750,0.000216,0.004458,0.113243,291.855225,14.867814,1.132425,-792.205750,294.500488,0.000000
76.780006,65.594154,-792.205750,0.000203,0.004458,0.113243,291.777374,14.863848,1.132425,-792.205750,294.500488,0.000000
77.190002,65.543510,-792.161255,0.000211,0.004458,0.113243,291.552094,14.852372,1.132425,-792.161255,294.500488,0.000000
77.600006,65.438499,-792.161255,0.000203,0.004458,0.113243,291.084991,14.828575,1.132425,-792.161255,294.500488,0.000000
78.010002,65.328651,-792.161255,0.000194,0.004458,0.113243,290.596344,14.803684,1.132425,-792.161255,294.500488,0.000000
78.420006,65.259773,-792.116760,0.000229,0.004458,0.113243,290.289978,14.788075,1.132425,-792.116760,294.500488,0.000000
78.830002,65.152901,-792.205750,0.000216,0.004458,0.113243,289.814575,14.763858,1.132425,-792.205750,294.500488,0.000000
79.240005,65.056084,-792.161255,0.000211,0.004458,0.113243,289.383911,14.741920,1.132425,-792.161255,294.500488,0.000000
79.650002,64.997993,-792.250244,0.000220,0.004458,0.113243,289.125519,14.728755,1.132425,-792.250244,294.500488,0.000000
80.060005,64.914207,-792.250244,0.000216,0.004458,0.113243,288.752808,14.709770,1.132425,-792.250244,294.500488,0.000000
80.470001,64.806969,-792.205750,0.000229,0.004458,0.113243,288.275787,14.685469,1.132425,-792.205750,294.500488,0.000000
80.880005,64.748131,-792.205750,0.000207,0.004458,0.113243,288.014069,14.672136,1.132425,-792.205750,294.500488,0.000000
81.290001,64.702690,-792.294678,0.000216,0.004458,0.113243,287.811951,14.661839,1.132425,-792.294678,294.500488,0.000000
81.700005,64.613701,-792.294678,0.000216,0.004458,0.113243,287.416107,14.641673,1.132425,-792.294678,294.500488,0.000000
82.110001,65.967644,-792.339172,0.000216,0.004467,0.113468,293.438721,14.948482,1.134681,-792.339172,294.500488,0.000000
82.520004,65.871208,-792.205750,0.000220,0.004467,0.113468,293.009766,14.926629,1.134681,-792.205750,294.500488,0.000000
82.930000,65.839546,-792.339172,0.000220,0.004467,0.113468,292.868927,14.919454,1.134681,-792.339172,294.500488,0.000000
83.340004,65.773262,-792.294678,0.000220,0.004467,0.113468,292.574097,14.904434,1.134681,-792.294678,294.500488,0.000000
83.750008,65.680550,-792.294678,0.000224,0.004467,0.113468,292.161682,14.883426,1.134681,-792.294678,294.500488,0.000000
84.160004,65.618355,-792.339172,0.000211,0.004467,0.113468,291.885010,14.869332,1.134681,-792.339172,294.500488,0.000000
84.570007,65.558037,-792.294678,0.000216,0.004467,0.113468,291.616699,14.855663,1.134681,-792.294678,294.500488,0.000000
84.980003,65.517448,-792.339172,0.000233,0.004467,0.113468,291.436157,14.846466,1.134681,-792.339172,294.500488,0.000000
85.390007,65.454140,-792.339172,0.000224,0.004467,0.113468,291.154541,14.832120,1.134681,-792.339172,294.500488,0.000000
85.800003,65.370735,-792.339172,0.000229,0.004467,0.113468,290.783539,14.813220,1.134681,-792.339172,294.500488,0.000000
86.210007,65.325310,-792.339172,0.000229,0.004467,0.113468,290.581482,14.802927,1.134681,-792.339172,294.500488,0.000000
86.620003,65.294395,-792.339172,0.000237,0.004467,0.113468,290.443970,14.795921,1.134681,-792.339172,294.500488,0.000000
87.030006,65.235939,-792.383667,0.000211,0.004467,0.113468,290.183960,14.782675,1.134681,-792.383667,294.500488,0.000000
87.440002,65.201302,-792.339172,0.000241,0.004467,0.113468,290.029877,14.774826,1.134681,-792.339172,294.500488,0.000000
87.850006,65.143211,-792.472595,0.000229,0.004467,0.113468,289.771484,14.761663,1.134681,-792.472595,294.500488,0.000000
88.260002,65.075447,-792.383667,0.000216,0.004467,0.113468,289.470032,14.746306,1.134681,-792.383667,294.500488,0.000000
88.670006,65.027031,-792.383667,0.000229,0.004467,0.113468,289.254669,14.735335,1.134681,-792.383667,294.500488,0.000000
89.080002,65.007668,-792.472595,0.000207,0.004467,0.113468,289.168549,14.730948,1.134681,-792.472595,294.500488,0.000000
89.490005,64.960747,-792.428162,0.000224,0.004467,0.113468,288.959839,14.720315,1.134681,-792.428162,294.500488,0.000000
89.900002,64.914207,-792.428162,0.000229,0.004467,0.113468,288.752808,14.709770,1.134681,-792.428162,294.500488,0.000000
90.310005,64.889626,-792.472595,0.000237,0.004467,0.113468,288.643463,14.704200,1.134681,-792.472595,294.500488,0.000000
90.720001,64.828560,-792.472595,0.000237,0.004467,0.113468,288.371826,14.690362,1.134681,-792.472595,294.500488,0.000000
91.130005,64.793922,-792.428162,0.000220,0.004467,0.113468,288.217773,14.682513,1.134681,-792.428162,294.500488,0.000000
91.540001,64.764885,-792.472595,0.000224,0.004467,0.113468,288.088593,14.675933,1.134681,-792.472595,294.500488,0.000000
91.950005,64.725044,-792.517090,0.000229,0.004467,0.113468,287.911377,14.666904,1.134681,-792.517090,294.500488,0.000000
92.360001,64.699348,-792.517090,0.000211,0.004467,0.113468,287.797089,14.661082,1.134681,-792.517090,294.500488,0.000000
92.770004,64.682594,-792.472595,0.000224,0.004468,0.113476,287.722534,14.657286,1.134757,-792.472595,294.500488,0.000000
93.180008,65.921104,-792.517090,0.000233,0.004480,0.113789,293.231720,14.937936,1.137891,-792.517090,294.500488,0.000000
93.590004,65.848854,-792.472595,0.000233,0.004480,0.113789,292.910339,14.921564,1.137891,-792.472595,294.500488,0.000000
94.000008,65.873436,-792.472595,0.000229,0.004480,0.113789,293.019684,14.927135,1.137891,-792.472595,294.500488,0.000000
94.410004,65.849983,-792.517090,0.000229,0.004480,0.113789,292.915344,14.921820,1.137891,-792.517090,294.500488,0.000000
94.820007,65.830986,-792.517090,0.000237,0.004480,0.113789,292.830841,14.917515,1.137891,-792.517090,294.500488,0.000000
95.230003,65.785179,-792.606079,0.000233,0.004480,0.113789,292.627106,14.907135,1.137891,-792.606079,294.500488,0.000000
95.640007,65.767311,-792.606079,0.000237,0.004480,0.113789,292.547607,14.903086,1.137891,-792.606079,294.500488,0.000000
96.050003,65.737892,-792.606079,0.000233,0.004480,0.113789,292.416748,14.896420,1.137891,-792.606079,294.500488,0.000000
96.460007,65.672722,-792.606079,0.000229,0.004480,0.113789,292.126862,14.881652,1.137891,-792.606079,294.500488,0.000000
96.870003,65.631401,-792.606079,0.000220,0.004480,0.113789,291.943054,14.872288,1.137891,-792.606079,294.500488,0.000000
97.280006,65.608315,-792.606079,0.000224,0.004480,0.113789,291.840363,14.867057,1.137891,-792.606079,294.500488,0.000000
97.690002,65.589684,-792.606079,0.000229,0.004480,0.113789,291.757477,14.862835,1.137891,-792.606079,294.500488,0.000000
98.100006,65.553566,-792.650574,0.000246,0.004480,0.113789,291.596832,14.854650,1.137891,-792.650574,294.500488,0.000000
98.510002,65.542397,-792.606079,0.000224,0.004480,0.113789,291.547150,14.852119,1.137891,-792.606079,294.500488,0.000000
98.920006,65.522667,-792.695007,0.000224,0.004480,0.113789,291.459381,14.847648,1.137891,-792.695007,294.500488,0.000000
99.330002,65.502174,-792.650574,0.000229,0.004480,0.113789,291.368225,14.843005,1.137891,-792.650574,294.500488,0.000000
99.740005,65.456383,-792.650574,0.000237,0.004480,0.113789,291.164520,14.832628,1.137891,-792.650574,294.500488,0.000000
100.150002,65.422127,-792.739502,0.000237,0.004480,0.113789,291.012146,14.824866,1.137891,-792.739502,294.500488,0.000000
100.560005,65.395317,-792.695007,0.000224,0.004480,0.113789,290.892914,14.818790,1.137891,-792.695007,294.500488,0.000000
100.970001,65.367012,-792.783997,0.000216,0.004480,0.113789,290.766998,14.812377,1.137891,-792.783997,294.500488,0.000000
101.380005,65.346535,-792.695007,0.000237,0.004480,0.113797,290.675903,14.807736,1.137967,-792.695007,294.500488,0.000000
101.790009,65.333122,-792.783997,0.000229,0.004480,0.113797,290.616241,14.804697,1.137967,-792.783997,294.500488,0.000000
102.200005,65.302956,-792.783997,0.000224,0.004480,0.113797,290.482056,14.797861,1.137967,-792.783997,294.500488,0.000000
102.610008,65.290306,-792.739502,0.000241,0.004480,0.113797,290.425781,14.794995,1.137967,-792.739502,294.500488,0.000000
103.020004,65.278389,-792.783997,0.000229,0.004480,0.113797,290.372772,14.792295,1.137967,-792.783997,294.500488,0.000000
103.430008,65.260139,-792.783997,0.000224,0.004480,0.113797,290.291595,14.788159,1.137967,-792.783997,294.500488,0.000000
103.840004,65.235558,-792.783997,0.000224,0.004480,0.113797,290.182251,14.782589,1.137967,-792.783997,294.500488,0.000000
104.250008,65.217690,-792.783997,0.000241,0.004480,0.113797,290.102783,14.778540,1.137967,-792.783997,294.500488,0.000000
104.660004,65.190880,-792.828491,0.000220,0.004480,0.113797,289.983521,14.772465,1.137967,-792.828491,294.500488,0.000000
105.070007,65.154762,-792.872925,0.000246,0.004480,0.113797,289.822845,14.764280,1.137967,-792.872925,294.500488,0.000000
105.480003,65.122734,-792.739502,0.000224,0.004480,0.113797,289.680389,14.757022,1.137967,-792.739502,294.500488,0.000000
105.890007,65.098900,-792.917419,0.000246,0.004480,0.113797,289.574371,14.751621,1.137967,-792.917419,294.500488,0.000000
106.300003,65.082512,-792.872925,0.000229,0.004480,0.113797,289.501465,14.747909,1.137967,-792.872925,294.500488,0.000000
106.710007,65.058693,-792.872925,0.000229,0.004480,0.113797,289.395508,14.742510,1.137967,-792.872925,294.500488,0.000000
107.120003,65.048256,-792.917419,0.000224,0.004480,0.113797,289.349091,14.740146,1.137967,-792.917419,294.500488,0.000000
107.530006,65.035591,-792.872925,0.000229,0.004480,0.113797,289.292755,14.737276,1.137967,-792.872925,294.500488,0.000000
107.940002,65.001717,-792.917419,0.000237,0.004480,0.113797,289.142090,14.729600,1.137967,-792.917419,294.500488,0.000000
108.350006,64.993889,-792.917419,0.000233,0.004480,0.113797,289.107269,14.727826,1.137967,-792.917419,294.500488,0.000000
108.760002,64.997993,-792.961914,0.000237,0.004480,0.113797,289.125519,14.728755,1.137967,-792.961914,294.500488,0.000000
109.170006,64.986824,-793.006409,0.000233,0.004480,0.113797,289.075836,14.726225,1.137967,-793.006409,294.500488,0.000000
109.580002,64.964851,-792.917419,0.000233,0.004480,0.113797,288.978088,14.721246,1.137967,-792.917419,294.500488,0.000000
109.990005,64.950691,-793.050903,0.000246,0.004480,0.113797,288.915100,14.718037,1.137967,-793.050903,294.500488,0.000000
110.400002,64.937294,-793.050903,0.000241,0.004480,0.113797,288.855499,14.715001,1.137967,-793.050903,294.500488,0.000000
110.810005,64.915321,-792.917419,0.000250,0.004480,0.113797,288.757782,14.710022,1.137967,-792.917419,294.500488,0.000000
111.220009,64.896324,-792.961914,0.000241,0.004480,0.113797,288.673279,14.705717,1.137967,-792.961914,294.500488,0.000000
111.630005,64.861336,-792.917419,0.000267,0.004480,0.113797,288.517639,14.697789,1.137967,-792.917419,294.500488,0.000000
112.040009,64.827812,-793.006409,0.000250,0.004480,0.113797,288.368500,14.690192,1.137967,-793.006409,294.500488,0.000000
112.450005,64.824837,-793.050903,0.000246,0.004481,0.113806,288.355286,14.689518,1.138057,-793.050903,294.500488,0.000000
112.860008,64.808449,-793.050903,0.000250,0.004481,0.113806,288.282379,14.685804,1.138057,-793.050903,294.500488,0.000000
113.270004,65.842155,-793.095337,0.000241,0.004494,0.114136,292.880524,14.920046,1.141358,-793.095337,294.500488,0.000000
113.680008,65.856682,-793.050903,0.000259,0.004494,0.114136,292.945160,14.923338,1.141358,-793.050903,294.500488,0.000000
114.090004,65.878654,-793.095337,0.000276,0.004494,0.114136,293.042877,14.928316,1.141358,-793.095337,294.500488,0.000000
114.500008,65.911415,-793.095337,0.000254,0.004494,0.114136,293.188629,14.935740,1.141358,-793.095337,294.500488,0.000000
114.910004,65.949394,-793.095337,0.000272,0.004494,0.114136,293.357544,14.944346,1.141358,-793.095337,294.500488,0.000000
115.320007,65.941948,-793.139832,0.000246,0.004494,0.114136,293.324432,14.942659,1.141358,-793.139832,294.500488,0.000000
115.730003,65.943443,-793.095337,0.000263,0.004494,0.114136,293.331085,14.942998,1.141358,-793.095337,294.500488,0.000000
116.140007,65.924446,-793.184326,0.000250,0.004494,0.114136,293.246582,14.938693,1.141358,-793.184326,294.500488,0.000000
116.550003,65.934135,-793.095337,0.000259,0.004493,0.114127,293.289673,14.940889,1.141267,-793.095337,294.500488,0.000000
116.960007,65.892433,-793.184326,0.000267,0.004493,0.114127,293.104187,14.931439,1.141267,-793.184326,294.500488,0.000000
117.370003,65.890938,-793.184326,0.000250,0.004493,0.114127,293.097534,14.931100,1.141267,-793.184326,294.500488,0.000000
117.780006,65.876411,-793.184326,0.000254,0.004493,0.114127,293.032898,14.927808,1.141267,-793.184326,294.500488,0.000000
118.190002,65.863380,-793.184326,0.000259,0.004493,0.114127,292.974945,14.924855,1.141267,-793.184326,294.500488,0.000000
118.600006,65.881996,-793.095337,0.000254,0.004493,0.114127,293.057770,14.929073,1.141267,-793.095337,294.500488,0.000000
119.010002,65.863380,-793.228821,0.000263,0.004493,0.114127,292.974945,14.924855,1.141267,-793.228821,294.500488,0.000000
119.420006,65.872322,-793.184326,0.000263,0.004493,0.114127,293.014709,14.926882,1.141267,-793.184326,294.500488,0.000000
119.830009,65.841789,-793.228821,0.000263,0.004493,0.114127,292.878906,14.919962,1.141267,-793.228821,294.500488,0.000000
120.240005,65.849602,-793.228821,0.000259,0.004493,0.114127,292.913666,14.921733,1.141267,-793.228821,294.500488,0.000000
120.650009,65.835457,-793.184326,0.000259,0.004493,0.114127,292.850739,14.918528,1.141267,-793.184326,294.500488,0.000000
121.060005,65.832848,-793.273254,0.000259,0.004493,0.114127,292.839142,14.917937,1.141267,-793.273254,294.500488,0.000000
121.470009,65.803810,-793.228821,0.000259,0.004493,0.114127,292.709961,14.911357,1.141267,-793.228821,294.500488,0.000000
121.880005,65.785179,-793.228821,0.000259,0.004493,0.114127,292.627106,14.907135,1.141267,-793.228821,294.500488,0.000000
122.290009,65.785927,-793.273254,0.000259,0.004493,0.114127,292.630432,14.907305,1.141267,-793.273254,294.500488,0.000000
122.700005,65.764336,-793.273254,0.000267,0.004493,0.114127,292.534363,14.902411,1.141267,-793.273254,294.500488,0.000000
123.110008,65.714806,-793.317749,0.000319,0.004493,0.114127,292.314056,14.891188,1.141267,-793.317749,294.500488,0.000000
123.520004,65.742363,-793.228821,0.000259,0.004493,0.114127,292.436646,14.897432,1.141267,-793.228821,294.500488,0.000000
123.930008,65.740501,-793.362244,0.000267,0.004493,0.114127,292.428345,14.897010,1.141267,-793.362244,294.500488,0.000000
124.340004,65.673470,-793.362244,0.000263,0.004493,0.114127,292.130188,14.881822,1.141267,-793.362244,294.500488,0.000000
124.750008,65.689491,-793.362244,0.000272,0.004493,0.114127,292.201447,14.885451,1.141267,-793.362244,294.500488,0.000000
125.160004,65.665276,-793.406738,0.000272,0.004493,0.114127,292.093719,14.879964,1.141267,-793.406738,294.500488,0.000000
125.570007,65.652245,-793.317749,0.000254,0.004493,0.114127,292.035767,14.877011,1.141267,-793.317749,294.500488,0.000000
125.980003,65.638847,-793.362244,0.000267,0.004493,0.114127,291.976166,14.873976,1.141267,-793.362244,294.500488,0.000000
126.390007,65.627678,-793.362244,0.000254,0.004493,0.114127,291.926483,14.871445,1.141267,-793.362244,294.500488,0.000000
126.800003,65.613518,-793.362244,0.000263,0.004493,0.114127,291.863495,14.868236,1.141267,-793.362244,294.500488,0.000000
127.210007,65.591545,-793.406738,0.000272,0.004493,0.114127,291.765778,14.863256,1.141267,-793.406738,294.500488,0.000000
127.620003,65.594536,-793.362244,0.000263,0.004493,0.114127,291.779053,14.863934,1.141267,-793.362244,294.500488,0.000000
128.029999,65.588570,-793.406738,0.000263,0.004493,0.114127,291.752533,14.862582,1.141267,-793.406738,294.500488,0.000000
128.440002,65.586708,-793.406738,0.000263,0.004493,0.114127,291.744263,14.862160,1.141267,-793.406738,294.500488,0.000000
128.850006,65.569206,-793.451233,0.000259,0.004493,0.114127,291.666382,14.858194,1.141267,-793.451233,294.500488,0.000000
129.260010,65.565849,-793.451233,0.000267,0.004493,0.114127,291.651459,14.857434,1.141267,-793.451233,294.500488,0.000000
129.670013,65.576653,-793.406738,0.000263,0.004493,0.114127,291.699524,14.859881,1.141267,-793.406738,294.500488,0.000000
130.080002,65.562874,-793.495667,0.000263,0.004493,0.114127,291.638214,14.856759,1.141267,-793.495667,294.500488,0.000000
130.490005,65.543144,-793.451233,0.000276,0.004493,0.114127,291.550476,14.852289,1.141267,-793.451233,294.500488,0.000000
130.900009,65.542030,-793.495667,0.000267,0.004493,0.114127,291.545502,14.852036,1.141267,-793.495667,294.500488,0.000000
131.310013,65.533836,-793.540161,0.000267,0.004493,0.114127,291.509064,14.850180,1.141267,-793.540161,294.500488,0.000000
131.720001,65.496971,-793.451233,0.000272,0.004490,0.114048,291.345093,14.841826,1.140480,-793.451233,0.113971,0.000000
132.130005,65.429939,-793.540161,0.000276,0.004472,0.113598,291.046906,14.826636,1.135983,-793.540161,0.113285,0.000000
132.540009,65.344292,-793.495667,0.000267,0.004450,0.113034,290.665924,14.807228,1.130336,-793.495667,0.112601,0.000000
132.950012,65.282860,-793.540161,0.000263,0.004428,0.112461,290.392670,14.793307,1.124613,-793.540161,0.111915,0.000000
133.360001,65.301476,-793.540161,0.000259,0.004395,0.111621,290.475464,14.797526,1.116211,-793.540161,0.111240,0.000000
133.770004,65.272423,-793.451233,0.000267,0.004373,0.111075,290.346252,14.790943,1.110746,-793.451233,0.110554,0.000000
134.180008,65.225883,-793.584656,0.000272,0.004346,0.110389,290.139221,14.780396,1.103887,-793.584656,0.109869,0.000000
134.590012,65.188637,-793.584656,0.000263,0.004320,0.109739,289.973541,14.771956,1.097392,-793.584656,0.109184,0.000000
135.000000,65.179329,-793.540161,0.000267,0.004295,0.109105,289.932129,14.769847,1.091049,-793.540161,0.108498,0.000000
135.410004,65.136147,-793.629150,0.000259,0.004269,0.108437,289.740051,14.760061,1.084372,-793.629150,0.107823,0.000000
135.820007,64.719826,-793.584656,0.000272,0.004246,0.107848,287.888153,14.665722,1.078483,-793.584656,0.107137,0.000000
136.230011,63.923317,-793.629150,0.000272,0.004223,0.107267,284.345123,14.485230,1.072670,-793.629150,0.106452,0.000000
136.639999,62.657631,-793.584656,0.000267,0.004194,0.106539,278.715057,14.198421,1.065387,-793.584656,0.105767,0.000000
137.050003,61.519661,-793.629150,0.000280,0.004172,0.105976,273.653107,13.940554,1.059755,-793.629150,0.105082,0.000000
137.460007,59.635078,-793.673584,0.000280,0.004143,0.105238,265.270081,13.513502,1.052382,-793.673584,0.104406,0.000000
137.870010,57.607140,-793.584656,0.000280,0.004120,0.104657,256.249359,13.053965,1.046569,-793.584656,0.103720,0.000000
138.280014,55.446266,-793.718079,0.000272,0.004095,0.104015,246.637314,12.564304,1.040150,-793.718079,0.103035,0.000000
138.690002,53.208305,-793.629150,0.000267,0.004074,0.103487,236.682358,12.057174,1.034866,-793.629150,0.102350,0.000000
139.100006,49.776520,-793.629150,0.000259,0.004040,0.102627,221.417023,11.279521,1.026267,-793.629150,0.101665,0.000000
139.510010,46.888397,-793.673584,0.000276,0.004014,0.101968,208.570007,10.625063,1.019681,-793.673584,0.100989,0.000000
139.920013,44.177528,-793.673584,0.000267,0.003989,0.101326,196.511459,10.010771,1.013262,-793.673584,0.100303,0.000000
140.330002,41.067101,-793.673584,0.000259,0.003961,0.100616,182.675583,9.305939,1.006161,-793.673584,0.099618,0.000000
140.740005,38.311172,-793.629150,0.000272,0.003937,0.100009,170.416611,8.681437,1.000090,-793.629150,0.098933,0.000000
141.150009,35.196648,-793.762573,0.000272,0.003909,0.099288,156.562515,7.975675,0.992884,-793.762573,0.098248,0.000000
141.560013,32.656693,-793.673584,0.000259,0.003886,0.098707,145.264221,7.400112,0.987070,-793.673584,0.097572,0.000000
141.970001,29.638618,-793.673584,0.000254,0.003857,0.097979,131.839157,6.716207,0.979788,-793.673584,0.096886,0.000000
142.380005,26.457809,-793.762573,0.000254,0.003832,0.097329,117.690216,5.995425,0.973293,-793.762573,0.096201,0.000000
142.790009,23.543999,-793.673584,0.000250,0.003806,0.096678,104.728935,5.335146,0.966783,-793.673584,0.095516,0.000000
143.200012,20.576187,-793.762573,0.000241,0.003778,0.095967,91.527451,4.662631,0.959668,-793.762573,0.094831,0.000000
143.610001,16.835709,-793.718079,0.000229,0.003745,0.095127,74.888969,3.815026,0.951265,-793.718079,0.094155,0.000000
144.020004,14.344910,-793.762573,0.000241,0.003723,0.094571,63.809345,3.250603,0.945709,-793.762573,0.093469,0.000000
144.430008,11.094093,-793.807068,0.000237,0.003692,0.093782,49.348991,2.513958,0.937821,-793.807068,0.092784,0.000000
144.840012,8.121071,-793.718079,0.000241,0.003668,0.093175,36.124329,1.840261,0.931750,-793.718079,0.092099,0.000000
145.250000,5.697304,-793.851562,0.000229,0.003646,0.092619,25.342873,1.291027,0.926194,-793.851562,0.091414,0.000000
145.660004,2.179497,-793.851562,0.000233,0.003613,0.091761,9.694886,0.493881,0.917610,-793.851562,0.090738,0.000000
146.070007,0.030540,-793.807068,0.000229,0.003590,0.091198,0.135851,0.006921,0.911978,-793.807068,0.090053,0.000000
146.480011,-0.398437,-793.807068,0.000185,0.003558,0.090382,-1.772339,-0.090287,0.903818,-793.807068,0.089367,0.000000
146.889999,-0.019730,-793.807068,0.000168,0.003535,0.089800,-0.087762,-0.004471,0.898004,-793.807068,0.088683,0.000000
147.300003,-0.027550,-793.851562,0.000099,0.003506,0.089065,-0.122547,-0.006243,0.890646,-793.851562,0.087997,0.000000
147.710007,0.008194,-793.895996,0.000060,0.003480,0.088405,0.036449,0.001857,0.884045,-793.895996,0.087321,0.000000
148.120010,-0.029411,-793.851562,0.000004,0.003450,0.087642,-0.130828,-0.006665,0.876415,-793.851562,0.086636,0.000000
148.530014,0.026817,-793.851562,-0.000060,0.003424,0.086965,0.119289,0.006077,0.869648,-793.851562,0.085950,0.000000
148.940002,0.061447,-793.851562,-0.000103,0.003403,0.086445,0.273331,0.013924,0.864455,-793.851562,0.085266,0.000000
149.350006,0.045059,-793.940491,-0.000203,0.003368,0.085560,0.200433,0.010211,0.855598,-793.940491,0.084580,0.000000
149.760010,0.074104,-793.895996,-0.000254,0.003348,0.085048,0.329632,0.016792,0.850481,-793.895996,0.083904,0.000000
150.170013,0.085648,-793.895996,-0.000323,0.003328,0.084520,0.380979,0.019408,0.845197,-793.895996,0.083219,0.000000
150.580002,0.062561,-793.940491,-0.000414,0.003294,0.083678,0.278285,0.014177,0.836780,-793.940491,0.082533,0.000000
150.990005,0.062561,-793.940491,-0.000517,0.003259,0.082768,0.278285,0.014177,0.827681,-793.940491,0.081849,0.000000
151.400009,0.019737,-793.984985,-0.000569,0.003235,0.082178,0.087796,0.004473,0.821776,-793.984985,0.081163,0.000000
151.810013,0.043198,-793.940491,-0.000634,0.003203,0.081354,0.192153,0.009789,0.813540,-793.940491,0.080487,0.000000
152.220001,0.032768,-793.984985,-0.000694,0.003189,0.080991,0.145760,0.007425,0.809907,-793.984985,0.079802,0.000000
152.630005,0.003357,-794.073914,-0.000772,0.003155,0.080149,0.014932,0.000761,0.801489,-794.073914,0.079116,0.000000
153.040009,0.014153,-793.940491,-0.000845,0.003121,0.079265,0.062954,0.003207,0.792648,-793.940491,0.078432,0.000000
153.450012,0.002609,-793.984985,-0.000884,0.003103,0.078805,0.011607,0.000591,0.788045,-793.984985,0.077746,0.000000
153.860001,0.004471,-793.984985,-0.000927,0.003076,0.078120,0.019887,0.001013,0.781202,-793.984985,0.077070,0.000000
154.270004,-0.020103,-793.984985,-0.000970,0.003048,0.077425,-0.089425,-0.004556,0.774253,-793.984985,0.076385,0.000000
154.680008,-0.017868,-794.073914,-0.001013,0.003024,0.076818,-0.079481,-0.004049,0.768182,-794.073914,0.075699,0.000000
155.090012,-0.006699,-793.984985,-0.001086,0.002987,0.075864,-0.029797,-0.001518,0.758644,-793.984985,0.075015,0.000000
155.500000,-0.008186,-794.073914,-0.001104,0.002968,0.075388,-0.036415,-0.001855,0.753875,-794.073914,0.074329,0.000000
155.910004,-0.001488,-794.073914,-0.001147,0.002936,0.074573,-0.006618,-0.000337,0.745730,-794.073914,0.073654,0.000000
156.320007,0.011543,-794.029480,-0.001177,0.002919,0.074139,0.051347,0.002616,0.741385,-794.029480,0.072968,0.000000
156.730011,-0.003349,-794.118408,-0.001220,0.002885,0.073289,-0.014898,-0.000759,0.732892,-794.118408,0.072282,0.000000
157.140015,-0.021225,-794.118408,-0.001246,0.002859,0.072622,-0.094413,-0.004810,0.726215,-794.118408,0.071598,0.000000
157.550003,0.040222,-794.118408,-0.001268,0.002837,0.072058,0.178917,0.009114,0.720583,-794.118408,0.070912,0.000000
157.960007,0.033516,-794.073914,-0.001293,0.002809,0.071347,0.149086,0.007595,0.713468,-794.073914,0.070237,0.000000
158.370010,0.019363,-794.118408,-0.001345,0.002777,0.070523,0.086133,0.004388,0.705232,-794.118408,0.069551,0.000000
158.780014,0.015274,-794.162903,-0.001380,0.002750,0.069846,0.067942,0.003461,0.698465,-794.162903,0.068867,0.000000
159.190002,-0.016006,-794.162903,-0.001401,0.002723,0.069161,-0.071200,-0.003627,0.691606,-794.162903,0.068181,0.000000
159.600006,0.039848,-794.207397,-0.001427,0.002697,0.068502,0.177254,0.009030,0.685021,-794.207397,0.067497,0.000000
160.010010,0.057724,-794.162903,-0.001487,0.002676,0.067965,0.256769,0.013080,0.679646,-794.162903,0.066820,0.000000
160.420013,0.032768,-794.162903,-0.001487,0.002642,0.067114,0.145760,0.007425,0.671138,-794.162903,0.066134,0.000000
160.830002,-0.005585,-794.251892,-0.001518,0.002614,0.066404,-0.024842,-0.001266,0.664037,-794.251892,0.065450,0.000000
161.240005,-0.007820,-794.162903,-0.001561,0.002590,0.065778,-0.034786,-0.001772,0.657784,-794.162903,0.064764,0.000000
161.650009,0.037613,-794.207397,-0.001595,0.002561,0.065059,0.167311,0.008523,0.650593,-794.207397,0.064080,0.000000
162.060013,0.017136,-794.296326,-0.001613,0.002539,0.064478,0.076223,0.003883,0.644780,-794.296326,0.063403,0.000000
162.470001,-0.000366,-794.207397,-0.001647,0.002511,0.063785,-0.001629,-0.000083,0.637846,-794.207397,0.062717,0.000000
162.880005,0.008194,-794.251892,-0.001669,0.002485,0.063124,0.036449,0.001857,0.631245,-794.251892,0.062033,0.000000
163.290009,-0.024574,-794.251892,-0.001694,0.002456,0.062389,-0.109312,-0.005569,0.623887,-794.251892,0.061347,0.000000
163.700012,-0.033134,-794.296326,-0.001716,0.002428,0.061677,-0.147389,-0.007508,0.616771,-794.296326,0.060663,0.000000
164.110001,-0.010048,-794.251892,-0.001768,0.002406,0.061114,-0.044695,-0.002277,0.611139,-794.251892,0.059986,0.000000
164.520004,-0.005951,-794.340820,-0.001781,0.002380,0.060445,-0.026471,-0.001348,0.604448,-794.340820,0.059300,0.000000
164.930008,0.005959,-794.296326,-0.001819,0.002346,0.059579,0.026505,0.001350,0.595788,-794.296326,0.058616,0.000000
165.340012,-0.003349,-794.340820,-0.001824,0.002325,0.059049,-0.014898,-0.000759,0.590489,-794.340820,0.057930,0.000000
165.750015,-0.006325,-794.340820,-0.001854,0.002294,0.058260,-0.028134,-0.001433,0.582601,-794.340820,0.057246,0.000000
166.160004,-0.010422,-794.340820,-0.001893,0.002268,0.057609,-0.046358,-0.002362,0.576091,-794.340820,0.056569,0.000000
166.570007,0.004471,-794.340820,-0.001927,0.002245,0.057020,0.019887,0.001013,0.570202,-794.340820,0.055883,0.000000
166.980011,-0.056229,-794.385315,-0.001962,0.002213,0.056222,-0.250117,-0.012742,0.562223,-794.385315,0.055199,0.000000
167.390015,-0.058456,-794.296326,-0.001983,0.002185,0.055494,-0.260027,-0.013246,0.554941,-794.296326,0.054513,0.000000
167.800003,-0.025314,-794.474243,-0.002013,0.002160,0.054861,-0.112604,-0.005736,0.548613,-794.474243,0.053829,0.000000
168.100006,0.026070,-794.385315,-0.002035,0.002153,0.054678,0.115964,0.005907,0.546781,-794.385315,0.054601,0.000000