File: Data/compression 35/ManualNoHeating-15-35-reverse-1-2_11182024_175530.csv
Time (sec),S:Load (lbs),S:HL1 (DIM),S:LVDT (in),S:Position (in),Ch:Position (mm),Ch:Load (N),Ch:Stress (MPa),Ch:Strain (mm/mm),Ch:HL1 (DIM),Set Point (),Cycles ()
0.110000,-0.061066,-877.253296,-0.012706,-0.007416,-0.188361,-0.271634,-0.013838,-1.883606,-877.253296,-0.188135,0.000000
0.580000,0.011177,-877.253296,-0.012693,-0.007316,-0.185829,0.049718,0.002533,-1.858293,-877.253296,-0.184806,0.000000
1.050000,0.001122,-877.208862,-0.012452,-0.007018,-0.178267,0.004989,0.000254,-1.782670,-877.208862,-0.176967,0.000000
1.520000,-0.074097,-877.297791,-0.012133,-0.006715,-0.170566,-0.329598,-0.016791,-1.705655,-877.297791,-0.169144,0.000000
1.990000,0.004471,-877.342285,-0.011814,-0.006406,-0.162717,0.019887,0.001013,-1.627172,-877.342285,-0.161303,0.000000
2.460000,0.008194,-877.342285,-0.011512,-0.006086,-0.154583,0.036449,0.001857,-1.545827,-877.342285,-0.153482,0.000000
2.930000,0.018623,-877.342285,-0.011184,-0.005791,-0.147099,0.082841,0.004220,-1.470992,-877.342285,-0.145641,0.000000
3.400000,-0.013771,-877.297791,-0.010848,-0.005480,-0.139181,-0.061257,-0.003121,-1.391812,-877.297791,-0.137819,0.000000
3.870000,-0.105751,-877.297791,-0.010546,-0.005181,-0.131610,-0.470404,-0.023964,-1.316099,-877.297791,-0.129998,0.000000
4.340000,0.020859,-877.297791,-0.010227,-0.004859,-0.123415,0.092784,0.004727,-1.234148,-877.297791,-0.122157,0.000000
4.810000,0.033142,-877.342285,-0.009929,-0.004563,-0.115897,0.147423,0.007510,-1.158965,-877.342285,-0.114334,0.000000
5.280000,-0.007820,-877.297791,-0.009619,-0.004255,-0.108074,-0.034786,-0.001772,-1.080739,-877.297791,-0.106495,0.000000
5.750000,-0.014519,-877.342285,-0.009261,-0.003940,-0.100077,-0.064583,-0.003290,-1.000772,-877.342285,-0.098672,0.000000
6.220000,-0.053993,-877.297791,-0.008972,-0.003635,-0.092317,-0.240174,-0.012235,-0.923166,-877.297791,-0.090833,0.000000
6.690001,0.056229,-877.342285,-0.008645,-0.003312,-0.084120,0.250117,0.012742,-0.841200,-877.342285,-0.083010,0.000000
7.160000,0.028305,-877.431213,-0.008326,-0.003015,-0.076576,0.125907,0.006414,-0.765760,-877.431213,-0.075171,0.000000
7.630001,0.033142,-877.431213,-0.007998,-0.002706,-0.068728,0.147423,0.007510,-0.687276,-877.431213,-0.067348,0.000000
8.100000,-0.063675,-877.386780,-0.007670,-0.002389,-0.060670,-0.283240,-0.014429,-0.606704,-877.386780,-0.059526,0.000000
8.570001,0.013039,-877.386780,-0.007368,-0.002089,-0.053057,0.057999,0.002955,-0.530567,-877.386780,-0.051687,0.000000
9.040000,0.058464,-877.431213,-0.007045,-0.001791,-0.045504,0.260061,0.013248,-0.455035,-877.431213,-0.043864,0.000000
9.510000,-0.030159,-877.475708,-0.006735,-0.001484,-0.037698,-0.134154,-0.006834,-0.376976,-877.475708,-0.036025,0.000000
9.980000,-0.011169,-877.475708,-0.006390,-0.001158,-0.029407,-0.049684,-0.002531,-0.294071,-877.475708,-0.028202,0.000000
10.450001,-0.046913,-877.475708,-0.006101,-0.000857,-0.021759,-0.208680,-0.010631,-0.217586,-877.475708,-0.020363,0.000000
10.920000,0.066284,-877.431213,-0.005777,-0.000546,-0.013875,0.294847,0.015020,-0.138754,-877.431213,-0.012540,0.000000
11.390000,0.078201,-877.520203,-0.005463,-0.000242,-0.006157,0.347857,0.017721,-0.061573,-877.520203,-0.004701,0.000000
11.860001,0.101288,-877.520203,-0.005389,-0.000003,-0.000079,0.450551,0.022952,-0.000787,-877.520203,0.000130,0.000000
12.330001,0.115814,-877.520203,-0.005398,-0.000003,-0.000079,0.515167,0.026244,-0.000787,-877.520203,0.000675,0.000000
12.800000,0.096451,-877.520203,-0.005398,-0.000003,-0.000070,0.429035,0.021856,-0.000696,-877.520203,0.001456,0.000000
13.270000,0.136665,-877.520203,-0.005355,0.000045,0.001154,0.607918,0.030969,0.011536,-877.520203,0.002238,0.000000
13.740001,0.179115,-877.431213,-0.005325,0.000072,0.001829,0.796745,0.040588,0.018289,-877.431213,0.003026,0.000000
14.210001,0.183952,-877.520203,-0.005316,0.000098,0.002497,0.818261,0.041684,0.024965,-877.520203,0.003806,0.000000
14.680000,0.242790,-877.564697,-0.005273,0.000123,0.003131,1.079985,0.055017,0.031309,-877.564697,0.004587,0.000000
15.150001,0.388763,-877.564697,-0.005230,0.000168,0.004266,1.729306,0.088095,0.042663,-877.564697,0.005376,0.000000
15.620001,0.462120,-877.520203,-0.005187,0.000195,0.004943,2.055613,0.104718,0.049431,-877.520203,0.006157,0.000000
16.090000,0.564522,-877.564697,-0.005174,0.000229,0.005827,2.511118,0.127922,0.058272,-877.564697,0.006937,0.000000
16.560001,0.657242,-877.609192,-0.005152,0.000248,0.006304,2.923558,0.148933,0.063041,-877.609192,0.007727,0.000000
17.030001,0.779755,-877.609192,-0.005113,0.000285,0.007241,3.468522,0.176695,0.072413,-877.609192,0.008507,0.000000
17.500000,0.938751,-877.609192,-0.005092,0.000317,0.008039,4.175774,0.212724,0.080391,-877.609192,0.009288,0.000000
17.970001,1.103714,-877.609192,-0.005044,0.000360,0.009149,4.909565,0.250105,0.091488,-877.609192,0.010077,0.000000
18.440001,1.186378,-877.609192,-0.005010,0.000381,0.009670,5.277275,0.268837,0.096696,-877.609192,0.010857,0.000000
18.910002,1.333099,-877.698120,-0.004967,0.000416,0.010554,5.929922,0.302085,0.105538,-877.698120,0.011638,0.000000
19.380001,1.457840,-877.609192,-0.004941,0.000440,0.011170,6.484796,0.330351,0.111700,-877.609192,0.012427,0.000000
19.850000,1.566200,-877.698120,-0.004932,0.000467,0.011872,6.966807,0.354906,0.118725,-877.698120,0.013208,0.000000
20.320002,1.686852,-877.609192,-0.004907,0.000491,0.012470,7.503490,0.382246,0.124705,-877.609192,0.013987,0.000000
20.790001,2.111359,-877.653625,-0.004859,0.000538,0.013659,9.391792,0.478441,0.136589,-877.653625,0.014778,0.000000
21.260000,2.227165,-877.653625,-0.004833,0.000560,0.014222,9.906926,0.504683,0.142221,-877.653625,0.015557,0.000000
21.730001,2.481865,-877.742615,-0.004794,0.000599,0.015220,11.039886,0.562399,0.152198,-877.742615,0.016339,0.000000
22.200001,2.502716,-877.653625,-0.004777,0.000612,0.015557,11.132637,0.567124,0.155574,-877.653625,0.017127,0.000000
22.670002,3.214691,-877.787109,-0.004743,0.000661,0.016781,14.299661,0.728459,0.167807,-877.787109,0.017907,0.000000
23.140001,3.479820,-877.698120,-0.004700,0.000695,0.017665,15.479013,0.788539,0.176649,-877.698120,0.018688,0.000000
23.610001,3.622070,-877.698120,-0.004691,0.000718,0.018237,16.111773,0.820773,0.182371,-877.698120,0.019477,0.000000
24.080002,4.010826,-877.787109,-0.004674,0.000749,0.019018,17.841045,0.908866,0.190183,-877.787109,0.020258,0.000000
24.550001,4.616676,-877.742615,-0.004618,0.000787,0.019989,20.536001,1.046154,0.199888,-877.742615,0.021038,0.000000
25.020000,4.704559,-877.787109,-0.004592,0.000808,0.020535,20.926926,1.066068,0.205353,-877.787109,0.021828,0.000000
25.490002,5.315994,-877.698120,-0.004570,0.000845,0.021454,23.646723,1.204622,0.214543,-877.698120,0.022608,0.000000
25.960001,5.590431,-877.876038,-0.004540,0.000871,0.022122,24.867479,1.266810,0.221220,-877.876038,0.023389,0.000000
26.430000,6.137444,-877.876038,-0.004506,0.000909,0.023094,27.300713,1.390765,0.230939,-877.876038,0.024178,0.000000
26.900002,6.337036,-877.787109,-0.004480,0.000932,0.023666,28.188545,1.435993,0.236662,-877.787109,0.024958,0.000000
27.370001,6.790215,-877.831543,-0.004441,0.000965,0.024516,30.204382,1.538685,0.245155,-877.831543,0.025739,0.000000
27.840002,7.162216,-877.831543,-0.004415,0.000990,0.025157,31.859129,1.622981,0.251574,-877.831543,0.026528,0.000000
28.310001,8.091660,-877.920532,-0.004393,0.001032,0.026216,35.993500,1.833596,0.262157,-877.920532,0.027309,0.000000
28.780001,8.424561,-877.920532,-0.004350,0.001065,0.027048,37.474316,1.909033,0.270484,-877.920532,0.028088,0.000000
29.250002,8.898216,-877.876038,-0.004316,0.001101,0.027958,39.581242,2.016365,0.279583,-877.876038,0.028879,0.000000
29.720001,9.209892,-877.876038,-0.004294,0.001131,0.028739,40.967648,2.086992,0.287395,-877.876038,0.029658,0.000000
30.190001,9.440765,-877.920532,-0.004264,0.001157,0.029390,41.994621,2.139308,0.293905,-877.920532,0.030440,0.000000
30.660002,9.853348,-877.920532,-0.004230,0.001183,0.030058,43.829880,2.232800,0.300581,-877.920532,0.031228,0.000000
31.130001,9.798615,-877.965027,-0.004217,0.001198,0.030440,43.586414,2.220398,0.304396,-877.965027,0.032008,0.000000
31.600002,10.542984,-877.965027,-0.004182,0.001242,0.031549,46.897533,2.389074,0.315494,-877.965027,0.032789,0.000000
32.070000,10.967491,-878.009521,-0.004148,0.001269,0.032226,48.785839,2.485269,0.322261,-878.009521,0.033578,0.000000
32.540001,11.475037,-877.965027,-0.004113,0.001303,0.033092,51.043510,2.600281,0.330921,-877.965027,0.034359,0.000000
33.010002,11.805702,-878.009521,-0.004100,0.001332,0.033829,52.514385,2.675210,0.338294,-878.009521,0.035139,0.000000
33.480003,12.229088,-878.053955,-0.004057,0.001365,0.034671,54.397701,2.771151,0.346712,-878.053955,0.035929,0.000000
33.950001,12.580978,-878.053955,-0.004027,0.001398,0.035504,55.962986,2.850890,0.355038,-878.053955,0.036709,0.000000
34.420002,12.961174,-877.965027,-0.003997,0.001431,0.036337,57.654182,2.937044,0.363365,-877.965027,0.037490,0.000000
34.890003,13.407646,-878.009521,-0.003971,0.001461,0.037116,59.640190,3.038216,0.371162,-878.009521,0.038279,0.000000
35.360001,13.509300,-878.053955,-0.003923,0.001487,0.037767,60.092369,3.061251,0.377672,-878.053955,0.039060,0.000000
35.830002,13.589363,-878.053955,-0.003902,0.001511,0.038383,60.448505,3.079394,0.383834,-878.053955,0.039840,0.000000
36.300003,14.723236,-878.053955,-0.003863,0.001554,0.039484,65.492226,3.336333,0.394840,-878.053955,0.040629,0.000000
36.770000,14.571312,-878.009521,-0.003850,0.001581,0.040152,64.816429,3.301907,0.401517,-878.009521,0.041410,0.000000
37.240002,15.388298,-878.142944,-0.003803,0.001619,0.041124,68.450569,3.487038,0.411236,-878.142944,0.042189,0.000000
37.710003,15.408401,-878.053955,-0.003773,0.001644,0.041756,68.539993,3.491594,0.417565,-878.053955,0.042980,0.000000
38.180000,16.032875,-878.142944,-0.003738,0.001678,0.042633,71.317787,3.633101,0.426331,-878.142944,0.043759,0.000000
38.650002,15.629593,-878.098450,-0.003712,0.001701,0.043213,69.523903,3.541716,0.432129,-878.098450,0.044541,0.000000
39.120003,16.463333,-878.009521,-0.003678,0.001741,0.044211,73.232567,3.730645,0.442106,-878.009521,0.045320,0.000000
39.590000,16.822304,-878.098450,-0.003648,0.001775,0.045095,74.829346,3.811989,0.450948,-878.098450,0.046111,0.000000
40.060001,17.205849,-878.142944,-0.003622,0.001806,0.045867,76.535439,3.898901,0.458669,-878.142944,0.046890,0.000000
40.530003,17.329102,-878.142944,-0.003566,0.001833,0.046553,77.083694,3.926831,0.465527,-878.142944,0.047672,0.000000
41.000004,17.345856,-878.142944,-0.003548,0.001856,0.047151,77.158218,3.930627,0.471507,-878.142944,0.048460,0.000000
41.470001,17.697746,-878.098450,-0.003531,0.001885,0.047870,78.723511,4.010366,0.478698,-878.098450,0.049240,0.000000
41.940002,19.028610,-878.187439,-0.003484,0.001929,0.048998,84.643486,4.311945,0.489977,-878.187439,0.050021,0.000000
42.410004,18.404884,-878.187439,-0.003432,0.001950,0.049519,81.869011,4.170606,0.495185,-878.187439,0.050810,0.000000
42.880001,18.709114,-878.142944,-0.003432,0.001990,0.050542,83.222298,4.239546,0.505420,-878.142944,0.051591,0.000000
43.350002,18.489410,-878.187439,-0.003397,0.002003,0.050889,82.245003,4.189760,0.508887,-878.187439,0.052371,0.000000
43.820004,19.919693,-878.142944,-0.003372,0.002046,0.051964,88.607224,4.513867,0.519636,-878.142944,0.053161,0.000000
44.290001,20.880043,-878.276367,-0.003324,0.002088,0.053048,92.879066,4.731485,0.530476,-878.276367,0.053941,0.000000
44.760002,20.387024,-878.231873,-0.003298,0.002111,0.053611,90.686012,4.619766,0.536108,-878.231873,0.054722,0.000000
45.230003,20.154289,-878.276367,-0.003264,0.002136,0.054262,89.650757,4.567028,0.542618,-878.276367,0.055511,0.000000
45.700001,20.869987,-878.231873,-0.003234,0.002171,0.055138,92.834343,4.729207,0.551383,-878.231873,0.056290,0.000000
46.170002,21.463554,-878.231873,-0.003208,0.002201,0.055918,95.474655,4.863711,0.559180,-878.231873,0.057072,0.000000
46.640003,21.698143,-878.320862,-0.003165,0.002229,0.056621,96.518158,4.916870,0.566205,-878.320862,0.057860,0.000000
47.110001,21.632980,-878.365356,-0.003139,0.002254,0.057262,96.228302,4.902103,0.572624,-878.365356,0.058642,0.000000
47.580002,22.937775,-878.231873,-0.003100,0.002296,0.058312,102.032318,5.197774,0.583116,-878.231873,0.059421,0.000000
48.050003,23.120979,-878.231873,-0.003074,0.002329,0.059144,102.847252,5.239289,0.591443,-878.231873,0.060212,0.000000
48.520000,22.873352,-878.365356,-0.003040,0.002349,0.059665,101.745750,5.183176,0.596651,-878.365356,0.060991,0.000000
48.990002,23.181679,-878.365356,-0.003009,0.002379,0.060428,103.117256,5.253044,0.604281,-878.365356,0.061773,0.000000
49.460003,24.213150,-878.409851,-0.002988,0.002414,0.061312,107.705467,5.486778,0.613123,-878.409851,0.062561,0.000000
49.930004,25.358940,-878.365356,-0.002940,0.002458,0.062422,112.802200,5.746418,0.624220,-878.365356,0.063341,0.000000
50.400002,25.643059,-878.365356,-0.002902,0.002489,0.063212,114.066025,5.810801,0.632123,-878.365356,0.064122,0.000000
50.870003,25.365273,-878.409851,-0.002867,0.002517,0.063922,112.830368,5.747853,0.639223,-878.409851,0.064911,0.000000
51.340004,25.803925,-878.365356,-0.002824,0.002547,0.064694,114.781586,5.847253,0.646945,-878.365356,0.065692,0.000000
51.810001,25.951759,-878.365356,-0.002798,0.002574,0.065371,115.439194,5.880753,0.653712,-878.365356,0.066472,0.000000
52.280003,25.422241,-878.365356,-0.002759,0.002590,0.065778,113.083778,5.760762,0.657784,-878.365356,0.067262,0.000000
52.750004,27.132553,-878.454285,-0.002746,0.002631,0.066828,120.691628,6.148324,0.668276,-878.454285,0.068042,0.000000
53.220001,27.525772,-878.454285,-0.002712,0.002661,0.067583,122.440750,6.237429,0.675831,-878.454285,0.068823,0.000000
53.690002,28.374786,-878.498779,-0.002677,0.002695,0.068449,126.217354,6.429819,0.684491,-878.498779,0.069612,0.000000
54.160004,28.119339,-878.498779,-0.002656,0.002721,0.069126,125.081070,6.371933,0.691258,-878.498779,0.070391,0.000000
54.630001,28.781418,-878.454285,-0.002604,0.002749,0.069828,128.026138,6.521962,0.698283,-878.454285,0.071173,0.000000
55.100002,29.506424,-878.498779,-0.002587,0.002781,0.070635,131.251129,6.686251,0.706352,-878.498779,0.071961,0.000000
55.570004,30.891281,-878.498779,-0.002544,0.002822,0.071668,137.411285,7.000064,0.716677,-878.498779,0.072743,0.000000
56.040001,30.707695,-878.543274,-0.002518,0.002846,0.072282,136.594650,6.958463,0.722824,-878.543274,0.073522,0.000000
56.510002,31.373497,-878.498779,-0.002475,0.002879,0.073115,139.556290,7.109336,0.731151,-878.498779,0.074313,0.000000
56.980003,30.686844,-878.543274,-0.002449,0.002896,0.073557,136.501892,6.953738,0.735572,-878.543274,0.075092,0.000000
57.450005,32.762451,-878.587769,-0.002427,0.002943,0.074764,145.734665,7.424078,0.747638,-878.587769,0.075874,0.000000
57.920002,32.901718,-878.587769,-0.002380,0.002968,0.075397,146.354156,7.455636,0.753966,-878.587769,0.076662,0.000000
58.390003,32.924057,-878.632202,-0.002350,0.002999,0.076185,146.453522,7.460698,0.761854,-878.632202,0.077443,0.000000
58.860004,34.150658,-878.587769,-0.002320,0.003034,0.077070,151.909714,7.738650,0.770695,-878.587769,0.078223,0.000000
59.330002,34.176346,-878.587769,-0.002276,0.003063,0.077807,152.023972,7.744471,0.778068,-878.587769,0.079012,0.000000
59.800003,35.351181,-878.587769,-0.002238,0.003095,0.078605,157.249908,8.010692,0.786047,-878.587769,0.079793,0.000000
60.270004,35.419327,-878.587769,-0.002203,0.003120,0.079247,157.553040,8.026134,0.792466,-878.587769,0.080573,0.000000
60.740002,36.985527,-878.676697,-0.002160,0.003162,0.080322,164.519836,8.381041,0.803215,-878.676697,0.081363,0.000000
61.210003,36.968399,-878.587769,-0.002121,0.003190,0.081033,164.443649,8.377158,0.810331,-878.587769,0.082143,0.000000
61.680004,37.635689,-878.632202,-0.002100,0.003221,0.081822,167.411911,8.528369,0.818219,-878.632202,0.082924,0.000000
62.150002,37.206345,-878.676697,-0.002082,0.003242,0.082343,165.502090,8.431078,0.823427,-878.676697,0.083713,0.000000
62.620003,37.941032,-878.765686,-0.002035,0.003275,0.083175,168.770142,8.597561,0.831753,-878.765686,0.084494,0.000000
63.090004,39.178429,-878.676697,-0.001992,0.003313,0.084155,174.274353,8.877959,0.841549,-878.676697,0.085274,0.000000
63.560001,39.414886,-878.676697,-0.001940,0.003339,0.084806,175.326172,8.931540,0.848059,-878.676697,0.086062,0.000000
64.030006,41.007149,-878.632202,-0.001906,0.003378,0.085794,182.408905,9.292353,0.857945,-878.632202,0.086844,0.000000
64.500000,40.057228,-878.721191,-0.001867,0.003394,0.086211,178.183456,9.077098,0.862108,-878.721191,0.087623,0.000000
64.970001,39.113258,-878.721191,-0.001828,0.003410,0.086618,173.984467,8.863192,0.866181,-878.721191,0.088414,0.000000
65.440002,42.100807,-878.721191,-0.001802,0.003462,0.087944,187.273743,9.540179,0.879443,-878.721191,0.089193,0.000000
65.910004,43.036209,-878.721191,-0.001755,0.003498,0.088856,191.434616,9.752144,0.888557,-878.721191,0.089975,0.000000
66.380005,42.400192,-878.721191,-0.001720,0.003517,0.089342,188.605469,9.608021,0.893417,-878.721191,0.090763,0.000000
66.850006,42.604630,-878.810120,-0.001681,0.003545,0.090052,189.514862,9.654346,0.900517,-878.810120,0.091544,0.000000
67.320000,44.539848,-878.810120,-0.001643,0.003590,0.091196,198.123138,10.092875,0.911963,-878.810120,0.092324,0.000000
67.790001,44.355896,-878.810120,-0.001595,0.003617,0.091865,197.304886,10.051189,0.918655,-878.810120,0.093113,0.000000
68.260002,44.913712,-878.765686,-0.001565,0.003645,0.092585,199.786163,10.177593,0.925846,-878.765686,0.093894,0.000000
68.730003,45.937363,-878.765686,-0.001535,0.003681,0.093487,204.339600,10.409555,0.934869,-878.765686,0.094674,0.000000
69.200005,46.948723,-878.810120,-0.001483,0.003713,0.094310,208.838348,10.638733,0.943105,-878.810120,0.095464,0.000000
69.670006,47.107727,-878.810120,-0.001462,0.003742,0.095057,209.545639,10.674763,0.950569,-878.810120,0.096244,0.000000
70.140007,47.707619,-878.810120,-0.001418,0.003771,0.095793,212.214081,10.810700,0.957927,-878.810120,0.097025,0.000000
70.610001,47.579521,-878.765686,-0.001397,0.003795,0.096392,211.644287,10.781673,0.963922,-878.765686,0.097814,0.000000
71.080002,49.468567,-878.810120,-0.001354,0.003834,0.097388,220.047180,11.209738,0.973884,-878.810120,0.098595,0.000000
71.550003,49.798859,-878.765686,-0.001302,0.003862,0.098091,221.516388,11.284583,0.980909,-878.765686,0.099375,0.000000
72.020004,51.364319,-878.899109,-0.001268,0.003904,0.099158,228.479904,11.639321,0.991582,-878.899109,0.100163,0.000000
72.490005,52.128052,-878.810120,-0.001212,0.003937,0.100000,231.877151,11.812386,1.000000,-878.810120,0.100945,0.000000
72.960007,52.107201,-878.899109,-0.001190,0.003961,0.100615,231.784409,11.807660,1.006146,-878.899109,0.101724,0.000000
73.430000,51.851006,-878.854614,-0.001164,0.003984,0.101205,230.644791,11.749605,1.012051,-878.854614,0.102515,0.000000
73.900002,52.644531,-878.943604,-0.001130,0.004011,0.101882,234.174576,11.929421,1.018818,-878.943604,0.103294,0.000000
74.370003,53.330818,-878.899109,-0.001082,0.004041,0.102652,237.227325,12.084936,1.026524,-878.899109,0.104076,0.000000
74.840004,55.313324,-878.854614,-0.001056,0.004083,0.103703,246.045959,12.534178,1.037031,-878.854614,0.104864,0.000000
75.310005,55.715485,-878.899109,-0.001035,0.004108,0.104343,247.834854,12.625309,1.043435,-878.899109,0.105646,0.000000
75.780006,56.497101,-878.943604,-0.001005,0.004138,0.105116,251.311661,12.802426,1.051156,-878.943604,0.106425,0.000000
76.250000,57.472343,-878.943604,-0.000961,0.004173,0.105983,255.649750,13.023419,1.059831,-878.943604,0.107214,0.000000
76.720001,58.792770,-878.943604,-0.000931,0.004206,0.106842,261.523315,13.322632,1.068415,-878.943604,0.107995,0.000000
77.190002,60.176140,-878.899109,-0.000910,0.004237,0.107614,267.676849,13.636108,1.076136,-878.899109,0.108776,0.000000
77.660004,61.163673,-878.943604,-0.000875,0.004267,0.108393,272.069611,13.859887,1.083933,-878.943604,0.109565,0.000000
78.130005,61.444069,-878.943604,-0.000849,0.004292,0.109010,273.316864,13.923425,1.090095,-878.943604,0.110345,0.000000
78.600006,62.186951,-878.988098,-0.000824,0.004317,0.109642,276.621368,14.091764,1.096424,-878.988098,0.111126,0.000000
79.070007,64.614067,-878.988098,-0.000763,0.004361,0.110761,287.417725,14.641757,1.107612,-878.988098,0.111915,0.000000
79.540001,66.013069,-878.988098,-0.000759,0.004390,0.111508,293.640808,14.958776,1.115075,-878.988098,0.112696,0.000000
80.010002,65.661186,-878.988098,-0.000737,0.004397,0.111689,292.075531,14.879038,1.116892,-878.988098,0.019604,0.000000
80.480003,66.013451,-879.032532,-0.000716,0.004397,0.111680,293.642487,14.958861,1.116801,-879.032532,294.500488,0.000000
80.950005,64.810692,-879.077026,-0.000698,0.004431,0.112540,288.292358,14.686313,1.125401,-879.077026,294.500488,0.000000
81.420006,65.144325,-878.943604,-0.000686,0.004442,0.112834,289.776428,14.761915,1.128338,-878.943604,294.500488,0.000000
81.890007,65.481331,-879.032532,-0.000660,0.004457,0.113208,291.275513,14.838282,1.132077,-879.032532,294.500488,0.000000
82.360001,65.340202,-879.077026,-0.000655,0.004486,0.113953,290.647736,14.806301,1.139526,-879.077026,294.500488,0.000000
82.830002,65.399773,-879.121521,-0.000634,0.004443,0.112852,290.912720,14.819800,1.128519,-879.121521,294.500488,0.000000
83.300003,65.311897,-879.032532,-0.000625,0.004489,0.114013,290.521820,14.799888,1.140131,-879.032532,294.500488,0.000000
83.770004,64.924629,-879.077026,-0.000617,0.004490,0.114057,288.799164,14.712132,1.140571,-879.077026,294.500488,0.000000
84.240005,65.610909,-879.032532,-0.000608,0.004505,0.114439,291.851898,14.867644,1.144386,-879.032532,294.500488,0.000000
84.710007,64.872124,-879.121521,-0.000595,0.004506,0.114448,288.565613,14.700233,1.144477,-879.121521,294.500488,0.000000
85.180000,64.183983,-879.121521,-0.000586,0.004506,0.114464,285.504608,14.544298,1.144643,-879.121521,294.500488,0.000000
85.650002,66.307625,-879.166016,-0.000565,0.004324,0.109833,294.951050,15.025522,1.098331,-879.166016,294.500488,0.000000
86.120003,65.538307,-879.077026,-0.000573,0.004353,0.110570,291.528961,14.851192,1.105704,-879.077026,294.500488,0.000000
86.590004,65.022194,-879.121521,-0.000565,0.004514,0.114647,289.233154,14.734240,1.146475,-879.121521,294.500488,0.000000
87.060005,64.997612,-879.210449,-0.000582,0.004534,0.115176,289.123810,14.728669,1.151759,-879.210449,294.500488,0.000000
87.530006,65.749443,-879.254944,-0.000560,0.004536,0.115211,292.468140,14.899036,1.152107,-879.254944,294.500488,0.000000
88.000008,65.148796,-879.121521,-0.000552,0.004536,0.115220,289.796326,14.762929,1.152198,-879.121521,294.500488,0.000000
88.470001,66.387306,-879.210449,-0.000548,0.004540,0.115323,295.305481,15.043578,1.153227,-879.210449,294.500488,0.000000
88.940002,65.835823,-879.166016,-0.000539,0.004540,0.115323,292.852356,14.918611,1.153227,-879.166016,294.500488,0.000000
89.410004,65.369240,-879.210449,-0.000535,0.004541,0.115341,290.776886,14.812881,1.153409,-879.210449,294.500488,0.000000
89.880005,65.335732,-879.254944,-0.000526,0.004564,0.115922,290.627838,14.805288,1.159222,-879.254944,294.500488,0.000000
90.350006,65.099648,-879.210449,-0.000526,0.004565,0.115956,289.577698,14.751791,1.159556,-879.210449,294.500488,0.000000
90.820007,65.278389,-879.210449,-0.000535,0.004571,0.116104,290.372772,14.792295,1.161039,-879.210449,294.500488,0.000000
91.290001,65.220665,-879.254944,-0.000535,0.004575,0.116199,290.115997,14.779214,1.161993,-879.254944,294.500488,0.000000
91.760002,64.994637,-879.299438,-0.000530,0.004575,0.116199,289.110596,14.727995,1.161993,-879.299438,294.500488,0.000000
92.230003,65.752037,-879.210449,-0.000526,0.004586,0.116476,292.479675,14.899625,1.164764,-879.210449,294.500488,0.000000
92.700005,65.514091,-879.166016,-0.000517,0.004586,0.116476,291.421234,14.845706,1.164764,-879.166016,294.500488,0.000000
93.170006,65.269447,-879.254944,-0.000509,0.004586,0.116476,290.333008,14.790268,1.164764,-879.254944,294.500488,0.000000
93.640007,65.014366,-879.299438,-0.000522,0.004586,0.116476,289.198334,14.732466,1.164764,-879.299438,294.500488,0.000000
94.110008,64.753716,-879.254944,-0.000517,0.004586,0.116476,288.038910,14.673402,1.164764,-879.254944,294.500488,0.000000
94.580002,64.501610,-879.210449,-0.000513,0.004586,0.116485,286.917480,14.616274,1.164854,-879.210449,294.500488,0.000000
95.050003,67.157753,-879.299438,-0.000492,0.004560,0.115818,298.732605,15.218164,1.158178,-879.299438,294.500488,0.000000
95.520004,66.685585,-879.299438,-0.000487,0.004466,0.113424,296.632294,15.111170,1.134242,-879.299438,294.500488,0.000000
95.990005,66.402580,-879.343933,-0.000500,0.004466,0.113433,295.373444,15.047040,1.134333,-879.343933,294.500488,0.000000
96.460007,66.153465,-879.388428,-0.000492,0.004466,0.113433,294.265320,14.990589,1.134333,-879.388428,294.500488,0.000000
96.930008,65.917000,-879.343933,-0.000487,0.004467,0.113459,293.213470,14.937005,1.134590,-879.343933,294.500488,0.000000
97.400002,65.694695,-879.299438,-0.000483,0.004477,0.113719,292.224609,14.886631,1.137194,-879.299438,294.500488,0.000000
97.870003,65.508507,-879.343933,-0.000492,0.004567,0.115990,291.396393,14.844440,1.159904,-879.343933,294.500488,0.000000
98.340004,65.313759,-879.388428,-0.000474,0.004575,0.116208,290.530121,14.800309,1.162084,-879.388428,294.500488,0.000000
98.810005,65.180077,-879.388428,-0.000474,0.004589,0.116563,289.935455,14.770016,1.165627,-879.388428,294.500488,0.000000
99.280006,65.163689,-879.432861,-0.000474,0.004603,0.116928,289.862549,14.766303,1.169275,-879.432861,294.500488,0.000000
99.750008,65.097038,-879.343933,-0.000479,0.004607,0.117006,289.566101,14.751200,1.170062,-879.343933,294.500488,0.000000
100.220001,65.193108,-879.343933,-0.000470,0.004612,0.117144,289.993439,14.772969,1.171440,-879.343933,294.500488,0.000000
100.690002,65.173378,-879.477356,-0.000479,0.004612,0.117144,289.905670,14.768499,1.171440,-879.477356,294.500488,0.000000
101.160004,65.167793,-879.477356,-0.000492,0.004614,0.117188,289.880829,14.767234,1.171879,-879.477356,294.500488,0.000000
101.630005,65.126457,-879.388428,-0.000474,0.004616,0.117248,289.696960,14.757866,1.172485,-879.388428,294.500488,0.000000
102.100006,65.216576,-879.432861,-0.000479,0.004618,0.117292,290.097809,14.778287,1.172924,-879.432861,294.500488,0.000000
102.570007,65.253807,-879.477356,-0.000461,0.004620,0.117344,290.263428,14.786724,1.173439,-879.477356,294.500488,0.000000
103.040009,65.222908,-879.521851,-0.000461,0.004620,0.117344,290.125977,14.779722,1.173439,-879.521851,294.500488,0.000000
103.510002,65.120872,-879.566345,-0.000457,0.004620,0.117344,289.672119,14.756600,1.173439,-879.566345,294.500488,0.000000
103.980003,65.324562,-879.477356,-0.000466,0.004624,0.117448,290.578156,14.802757,1.174483,-879.477356,294.500488,0.000000
104.450005,65.260887,-879.432861,-0.000483,0.004624,0.117448,290.294922,14.788328,1.174483,-879.432861,294.500488,0.000000
104.920006,65.146187,-879.521851,-0.000470,0.004624,0.117448,289.784698,14.762337,1.174483,-879.521851,294.500488,0.000000
105.390007,65.151405,-879.566345,-0.000479,0.004628,0.117551,289.807922,14.763519,1.175513,-879.566345,294.500488,0.000000
105.860008,65.254189,-879.566345,-0.000470,0.004628,0.117551,290.265137,14.786810,1.175513,-879.566345,294.500488,0.000000
106.330002,65.200935,-879.521851,-0.000457,0.004628,0.117551,290.028259,14.774743,1.175513,-879.521851,294.500488,0.000000
106.800003,65.109703,-879.521851,-0.000466,0.004628,0.117560,289.622437,14.754069,1.175604,-879.521851,294.500488,0.000000
107.270004,65.041557,-879.610779,-0.000483,0.004629,0.117579,289.319305,14.738627,1.175785,-879.610779,294.500488,0.000000
107.740005,65.056084,-879.655273,-0.000470,0.004630,0.117613,289.383911,14.741920,1.176133,-879.655273,294.500488,0.000000
108.210007,65.006554,-879.610779,-0.000461,0.004630,0.117613,289.163605,14.730696,1.176133,-879.610779,294.500488,0.000000
108.680008,64.972298,-879.566345,-0.000466,0.004631,0.117621,289.011200,14.722934,1.176209,-879.566345,294.500488,0.000000
109.150002,65.149544,-879.655273,-0.000453,0.004635,0.117725,289.799652,14.763098,1.177254,-879.655273,294.500488,0.000000
109.620003,65.141350,-879.655273,-0.000461,0.004635,0.117725,289.763184,14.761241,1.177254,-879.655273,294.500488,0.000000
110.090004,65.091820,-879.699768,-0.000461,0.004635,0.117725,289.542877,14.750017,1.177254,-879.699768,294.500488,0.000000
110.560005,65.031136,-879.699768,-0.000461,0.004635,0.117725,289.272949,14.736266,1.177254,-879.699768,294.500488,0.000000
111.030006,64.972298,-879.655273,-0.000466,0.004635,0.117725,289.011200,14.722934,1.177254,-879.655273,294.500488,0.000000
111.500008,64.894463,-879.655273,-0.000466,0.004635,0.117725,288.664978,14.705296,1.177254,-879.655273,294.500488,0.000000
111.970009,65.072456,-879.744263,-0.000461,0.004640,0.117856,289.456757,14.745629,1.178556,-879.744263,294.500488,0.000000
112.440002,65.104485,-879.699768,-0.000466,0.004640,0.117856,289.599213,14.752887,1.178556,-879.699768,294.500488,0.000000
112.910004,65.074699,-879.699768,-0.000453,0.004640,0.117856,289.466705,14.746138,1.178556,-879.699768,294.500488,0.000000
113.380005,65.029640,-879.744263,-0.000444,0.004640,0.117856,289.266296,14.735928,1.178556,-879.744263,294.500488,0.000000
113.850006,64.978249,-879.699768,-0.000461,0.004640,0.117856,289.037689,14.724281,1.178556,-879.699768,294.500488,0.000000
114.320007,64.897820,-879.788757,-0.000466,0.004640,0.117856,288.679932,14.706056,1.178556,-879.788757,294.500488,0.000000
114.790009,64.867287,-879.788757,-0.000448,0.004640,0.117865,288.544098,14.699137,1.178647,-879.788757,294.500488,0.000000
115.260002,64.798027,-879.699768,-0.000453,0.004640,0.117865,288.236023,14.683442,1.178647,-879.699768,294.500488,0.000000
115.730003,65.666023,-879.788757,-0.000453,0.004650,0.118116,292.097046,14.880134,1.181160,-879.788757,294.500488,0.000000
116.200005,65.653740,-879.699768,-0.000461,0.004650,0.118116,292.042419,14.877350,1.181160,-879.699768,294.500488,0.000000
116.670006,65.602348,-879.744263,-0.000466,0.004650,0.118116,291.813812,14.865705,1.181160,-879.744263,294.500488,0.000000
117.140007,65.559532,-879.833191,-0.000440,0.004650,0.118116,291.623352,14.856002,1.181160,-879.833191,294.500488,0.000000
117.610008,65.508888,-879.788757,-0.000435,0.004650,0.118116,291.398102,14.844526,1.181160,-879.788757,294.500488,0.000000
118.080002,65.467171,-879.788757,-0.000440,0.004650,0.118116,291.212524,14.835073,1.181160,-879.788757,294.500488,0.000000
118.550003,65.393074,-879.833191,-0.000453,0.004650,0.118116,290.882935,14.818282,1.181160,-879.833191,294.500488,0.000000
119.020004,65.334618,-879.877686,-0.000457,0.004650,0.118116,290.622894,14.805036,1.181160,-879.877686,294.500488,0.000000
119.490005,65.278389,-879.877686,-0.000440,0.004650,0.118116,290.372772,14.792295,1.181160,-879.877686,294.500488,0.000000
119.960007,65.234825,-879.833191,-0.000440,0.004650,0.118116,290.178986,14.782422,1.181160,-879.833191,294.500488,0.000000
120.430008,65.161461,-879.833191,-0.000440,0.004650,0.118116,289.852661,14.765799,1.181160,-879.833191,294.500488,0.000000
120.900009,65.092949,-879.877686,-0.000440,0.004651,0.118125,289.547913,14.750273,1.181251,-879.877686,294.500488,0.000000
121.370003,65.026665,-879.877686,-0.000444,0.004651,0.118125,289.253052,14.735253,1.181251,-879.877686,294.500488,0.000000
121.840004,64.986443,-879.877686,-0.000435,0.004651,0.118125,289.074127,14.726138,1.181251,-879.877686,294.500488,0.000000
122.310005,64.933571,-879.922180,-0.000435,0.004651,0.118125,288.838959,14.714157,1.181251,-879.922180,294.500488,0.000000
122.780006,64.869148,-879.877686,-0.000435,0.004651,0.118125,288.552368,14.699559,1.181251,-879.877686,294.500488,0.000000
123.250008,64.800255,-879.922180,-0.000435,0.004651,0.118125,288.245941,14.683948,1.181251,-879.922180,294.500488,0.000000
123.720009,64.755943,-879.966675,-0.000431,0.004651,0.118125,288.048828,14.673906,1.181251,-879.966675,294.500488,0.000000
124.190002,64.709404,-879.966675,-0.000440,0.004651,0.118125,287.841797,14.663361,1.181251,-879.966675,294.500488,0.000000
124.660004,64.674400,-879.922180,-0.000440,0.004651,0.118125,287.686096,14.655428,1.181251,-879.922180,294.500488,0.000000
125.130005,64.632317,-879.966675,-0.000444,0.004651,0.118125,287.498901,14.645892,1.181251,-879.966675,294.500488,0.000000
125.600006,64.570885,-879.966675,-0.000431,0.004651,0.118125,287.225647,14.631971,1.181251,-879.966675,294.500488,0.000000
126.070007,65.843269,-879.966675,-0.000448,0.004665,0.118497,292.885498,14.920299,1.184975,-879.966675,294.500488,0.000000
126.540009,65.856300,-880.011108,-0.000440,0.004665,0.118497,292.943451,14.923250,1.184975,-880.011108,294.500488,0.000000
127.010010,65.871574,-879.966675,-0.000427,0.004665,0.118497,293.011383,14.926712,1.184975,-879.966675,294.500488,0.000000
127.480003,65.853325,-880.011108,-0.000418,0.004665,0.118497,292.930206,14.922577,1.184975,-880.011108,294.500488,0.000000
127.950005,65.810509,-880.011108,-0.000435,0.004665,0.118497,292.739777,14.912875,1.184975,-880.011108,294.500488,0.000000
128.420013,65.778847,-880.055603,-0.000427,0.004665,0.118497,292.598938,14.905700,1.184975,-880.055603,294.500488,0.000000
128.889999,65.760612,-880.100098,-0.000423,0.004665,0.118497,292.517822,14.901567,1.184975,-880.100098,294.500488,0.000000
129.360001,65.686134,-880.011108,-0.000418,0.004665,0.118497,292.186523,14.884691,1.184975,-880.011108,294.500488,0.000000
129.830002,65.670494,-880.055603,-0.000431,0.004665,0.118497,292.116943,14.881146,1.184975,-880.055603,294.500488,0.000000
130.300003,65.612770,-880.100098,-0.000431,0.004665,0.118497,291.860168,14.868067,1.184975,-880.100098,294.500488,0.000000
130.770004,65.591545,-880.144592,-0.000427,0.004665,0.118497,291.765778,14.863256,1.184975,-880.144592,294.500488,0.000000
131.240005,65.540901,-880.144592,-0.000431,0.004665,0.118497,291.540497,14.851781,1.184975,-880.144592,294.500488,0.000000
131.710007,65.510750,-880.144592,-0.000410,0.004665,0.118497,291.406372,14.844948,1.184975,-880.144592,294.500488,0.000000
132.180008,65.472023,-880.144592,-0.000427,0.004665,0.118497,291.234100,14.836172,1.184975,-880.144592,294.500488,0.000000
132.650009,65.396049,-880.144592,-0.000423,0.004665,0.118497,290.896149,14.818957,1.184975,-880.144592,294.500488,0.000000
133.120010,65.358070,-880.144592,-0.000418,0.004665,0.118497,290.727203,14.810350,1.184975,-880.144592,294.500488,0.000000
133.590012,65.335732,-880.189087,-0.000423,0.004665,0.118497,290.627838,14.805288,1.184975,-880.189087,294.500488,0.000000
134.060013,65.296638,-880.189087,-0.000423,0.004665,0.118497,290.453949,14.796430,1.184975,-880.189087,294.500488,0.000000
134.529999,65.264610,-880.189087,-0.000435,0.004665,0.118497,290.311493,14.789172,1.184975,-880.189087,294.500488,0.000000
135.000000,65.233696,-880.189087,-0.000423,0.004665,0.118497,290.173981,14.782166,1.184975,-880.189087,294.500488,0.000000
135.470001,65.186043,-880.189087,-0.000427,0.004665,0.118497,289.962006,14.771369,1.184975,-880.189087,294.500488,0.000000
135.940002,65.118263,-880.322510,-0.000427,0.004665,0.118497,289.660492,14.756009,1.184975,-880.322510,294.500488,0.000000
136.410004,65.087364,-880.233521,-0.000414,0.004665,0.118497,289.523041,14.749007,1.184975,-880.233521,294.500488,0.000000
136.880005,65.051231,-880.144592,-0.000431,0.004666,0.118507,289.362335,14.740820,1.185066,-880.144592,294.500488,0.000000
137.350006,65.022194,-880.233521,-0.000423,0.004666,0.118507,289.233154,14.734240,1.185066,-880.233521,294.500488,0.000000
137.820007,64.990166,-880.322510,-0.000427,0.004666,0.118507,289.090698,14.726981,1.185066,-880.322510,294.500488,0.000000
138.290009,64.951820,-880.322510,-0.000418,0.004666,0.118507,288.920135,14.718292,1.185066,-880.322510,294.500488,0.000000
138.760010,64.929466,-880.278015,-0.000423,0.004666,0.118507,288.820679,14.713227,1.185066,-880.278015,294.500488,0.000000
139.230011,64.887016,-880.278015,-0.000414,0.004666,0.118507,288.631866,14.703609,1.185066,-880.278015,294.500488,0.000000
139.700012,64.841225,-880.278015,-0.000418,0.004666,0.118507,288.428162,14.693232,1.185066,-880.278015,294.500488,0.000000
140.170013,64.803978,-880.367004,-0.000427,0.004666,0.118507,288.262482,14.684792,1.185066,-880.367004,294.500488,0.000000
140.639999,64.853874,-880.278015,-0.000414,0.004661,0.118384,288.484436,14.696098,1.183839,-880.278015,0.118342,0.000000
141.110001,64.779411,-880.367004,-0.000401,0.004640,0.117865,288.153198,14.679225,1.178647,-880.367004,0.117551,0.000000
141.580002,64.676262,-880.367004,-0.000410,0.004615,0.117214,287.694366,14.655850,1.172137,-880.367004,0.116772,0.000000
142.050003,64.650200,-880.367004,-0.000414,0.004584,0.116434,287.578461,14.649945,1.164340,-880.367004,0.115990,0.000000
142.520004,64.597313,-880.322510,-0.000414,0.004559,0.115800,287.343201,14.637960,1.157996,-880.322510,0.115202,0.000000
142.990005,64.530296,-880.411438,-0.000401,0.004527,0.114994,287.045105,14.622774,1.149942,-880.411438,0.114422,0.000000
143.460007,64.550026,-880.322510,-0.000410,0.004497,0.114213,287.132843,14.627245,1.142130,-880.322510,0.113641,0.000000
143.930008,64.464012,-880.367004,-0.000405,0.004470,0.113529,286.750244,14.607754,1.135287,-880.367004,0.112852,0.000000
144.400009,64.318031,-880.411438,-0.000423,0.004443,0.112861,286.100891,14.574674,1.128610,-880.411438,0.112071,0.000000
144.870010,63.790764,-880.411438,-0.000414,0.004413,0.112089,283.755493,14.455194,1.120889,-880.411438,0.111291,0.000000
145.340012,62.590599,-880.455933,-0.000410,0.004381,0.111273,278.416901,14.183233,1.112729,-880.455933,0.110501,0.000000
145.810013,61.263092,-880.455933,-0.000392,0.004355,0.110623,272.511841,13.882415,1.106234,-880.455933,0.109721,0.000000
146.280014,59.214302,-880.367004,-0.000388,0.004324,0.109826,263.398376,13.418152,1.098255,-880.367004,0.108940,0.000000
146.750000,57.085815,-880.367004,-0.000410,0.004295,0.109105,253.930389,12.935831,1.091049,-880.367004,0.108151,0.000000
147.220001,54.447929,-880.455933,-0.000410,0.004266,0.108351,242.196487,12.338078,1.083509,-880.455933,0.107371,0.000000
147.690002,51.503586,-880.455933,-0.000392,0.004235,0.107579,229.099396,11.670879,1.075788,-880.455933,0.106590,0.000000
148.160004,48.043495,-880.455933,-0.000401,0.004203,0.106764,213.708145,10.886811,1.067643,-880.455933,0.105801,0.000000
148.630005,45.219795,-880.455933,-0.000384,0.004179,0.106157,201.147690,10.246952,1.061572,-880.455933,0.105020,0.000000
149.100006,42.383438,-880.455933,-0.000414,0.004154,0.105515,188.530945,9.604224,1.055153,-880.455933,0.104241,0.000000
149.570007,38.266113,-880.544922,-0.000397,0.004116,0.104534,170.216171,8.671225,1.045343,-880.544922,0.103450,0.000000
150.040009,34.551697,-880.544922,-0.000397,0.004082,0.103685,153.693619,7.829526,1.036849,-880.544922,0.102671,0.000000
150.510010,31.709381,-880.500427,-0.000392,0.004057,0.103043,141.050369,7.185449,1.030430,-880.500427,0.101889,0.000000
150.980011,28.297707,-880.544922,-0.000392,0.004025,0.102245,125.874489,6.412352,1.022452,-880.544922,0.101101,0.000000
151.450012,24.522591,-880.500427,-0.000410,0.003990,0.101335,109.081932,5.556899,1.013353,-880.500427,0.100321,0.000000
151.920013,21.870186,-880.589417,-0.000414,0.003966,0.100736,97.283447,4.955855,1.007357,-880.589417,0.099540,0.000000
152.390015,18.359825,-880.633850,-0.000405,0.003931,0.099842,81.668579,4.160396,0.998425,-880.633850,0.098751,0.000000
152.860001,15.511925,-880.544922,-0.000427,0.003904,0.099167,69.000488,3.515052,0.991673,-880.544922,0.097970,0.000000
153.330002,10.888176,-880.589417,-0.000410,0.003864,0.098151,48.433025,2.467296,0.981514,-880.589417,0.097190,0.000000
153.800003,8.251404,-880.589417,-0.000431,0.003840,0.097544,36.704079,1.869795,0.975443,-880.589417,0.096400,0.000000
154.270004,4.903404,-880.633850,-0.000431,0.003810,0.096765,21.811432,1.111127,0.967646,-880.633850,0.095620,0.000000
154.740005,1.664879,-880.589417,-0.000440,0.003778,0.095950,7.405751,0.377267,0.959501,-880.589417,0.094839,0.000000
155.210007,-1.762436,-880.589417,-0.000431,0.003741,0.095030,-7.839706,-0.399374,0.950296,-880.589417,0.094050,0.000000
155.680008,-3.218410,-880.589417,-0.000457,0.003719,0.094457,-14.316205,-0.729302,0.944574,-880.589417,0.093269,0.000000
156.150009,-0.280022,-880.633850,-0.000526,0.003685,0.093608,-1.245599,-0.063454,0.936080,-880.633850,0.092489,0.000000
156.620010,-0.035370,-880.722839,-0.000569,0.003657,0.092896,-0.157333,-0.008015,0.928965,-880.722839,0.091700,0.000000
157.090012,-0.032021,-880.678345,-0.000625,0.003614,0.091803,-0.142435,-0.007256,0.918034,-880.678345,0.090919,0.000000
157.560013,0.001495,-880.678345,-0.000677,0.003592,0.091231,0.006652,0.000339,0.912311,-880.678345,0.090140,0.000000
158.030014,0.001495,-880.722839,-0.000746,0.003558,0.090365,0.006652,0.000339,0.903651,-880.722839,0.089349,0.000000
158.500000,-0.026062,-880.678345,-0.000815,0.003527,0.089575,-0.115930,-0.005906,0.895748,-880.678345,0.088570,0.000000
158.970001,-0.011169,-880.722839,-0.000862,0.003499,0.088872,-0.049684,-0.002531,0.888724,-880.722839,0.087788,0.000000
159.440002,0.017136,-880.722839,-0.000970,0.003467,0.088058,0.076223,0.003883,0.880579,-880.722839,0.087000,0.000000
159.910004,0.064049,-880.722839,-0.001039,0.003437,0.087311,0.284903,0.014514,0.873115,-880.722839,0.086218,0.000000
160.380005,0.061073,-880.722839,-0.001108,0.003407,0.086539,0.271668,0.013839,0.865394,-880.722839,0.085439,0.000000
160.850006,0.035751,-880.722839,-0.001173,0.003371,0.085620,0.159030,0.008101,0.856204,-880.722839,0.084650,0.000000
161.320007,-0.012283,-880.722839,-0.001246,0.003342,0.084892,-0.054639,-0.002783,0.848922,-880.722839,0.083869,0.000000
161.790009,0.072617,-880.722839,-0.001298,0.003316,0.084215,0.323015,0.016455,0.842154,-880.722839,0.083089,0.000000
162.260010,0.034637,-880.722839,-0.001367,0.003284,0.083401,0.154075,0.007849,0.834009,-880.722839,0.082299,0.000000
162.730011,0.039848,-880.767334,-0.001401,0.003247,0.082464,0.177254,0.009030,0.824638,-880.767334,0.081519,0.000000
163.200012,-0.024574,-880.767334,-0.001440,0.003218,0.081736,-0.109312,-0.005569,0.817356,-880.767334,0.080738,0.000000
163.670013,0.032768,-880.767334,-0.001487,0.003195,0.081154,0.145760,0.007425,0.811542,-880.767334,0.079949,0.000000
164.140015,0.007080,-880.767334,-0.001539,0.003160,0.080261,0.031494,0.001604,0.802610,-880.767334,0.079168,0.000000
164.610001,-0.012283,-880.856262,-0.001587,0.003124,0.079359,-0.054639,-0.002783,0.793586,-880.856262,0.078388,0.000000
165.080002,-0.023087,-880.856262,-0.001638,0.003095,0.078605,-0.102694,-0.005231,0.786047,-880.856262,0.077599,0.000000
165.550003,-0.022713,-880.900757,-0.001660,0.003067,0.077902,-0.101031,-0.005147,0.779022,-880.900757,0.076818,0.000000
166.020004,-0.032021,-880.856262,-0.001720,0.003038,0.077156,-0.142435,-0.007256,0.771558,-880.856262,0.076039,0.000000
166.490005,-0.002975,-880.811768,-0.001738,0.003008,0.076411,-0.013236,-0.000674,0.764110,-880.811768,0.075248,0.000000
166.960007,-0.020851,-880.900757,-0.001781,0.002970,0.075431,-0.092750,-0.004725,0.754314,-880.900757,0.074469,0.000000
167.430008,-0.015266,-880.900757,-0.001824,0.002944,0.074780,-0.067908,-0.003459,0.747804,-880.900757,0.073687,0.000000
167.900009,-0.021591,-880.945251,-0.001841,0.002911,0.073931,-0.096042,-0.004893,0.739311,-880.945251,0.072899,0.000000
168.370010,-0.022713,-880.900757,-0.001888,0.002889,0.073375,-0.101031,-0.005147,0.733755,-880.900757,0.072117,0.000000
168.840012,-0.065163,-880.856262,-0.001910,0.002848,0.072335,-0.289858,-0.014766,0.723354,-880.856262,0.071338,0.000000
169.310013,-0.065536,-880.856262,-0.001957,0.002819,0.071615,-0.291521,-0.014851,0.716148,-880.856262,0.070549,0.000000
169.780014,-0.058456,-880.989746,-0.001979,0.002787,0.070782,-0.260027,-0.013246,0.707821,-880.989746,0.069768,0.000000
170.250015,-0.068512,-881.034180,-0.002005,0.002759,0.070080,-0.304756,-0.015525,0.700796,-881.034180,0.068988,0.000000
170.720001,-0.083778,-880.900757,-0.002039,0.002726,0.069239,-0.372665,-0.018984,0.692394,-880.900757,0.068198,0.000000
171.190002,-0.064415,-880.900757,-0.002078,0.002696,0.068484,-0.286532,-0.014597,0.684839,-880.900757,0.067418,0.000000
171.660004,-0.048409,-880.945251,-0.002126,0.002672,0.067877,-0.215332,-0.010970,0.678768,-880.945251,0.066637,0.000000
172.130005,-0.049149,-880.989746,-0.002156,0.002637,0.066984,-0.218624,-0.011137,0.669836,-880.989746,0.065848,0.000000
172.600006,-0.096443,-880.945251,-0.002177,0.002602,0.066099,-0.429001,-0.021854,0.660994,-880.945251,0.065067,0.000000
173.070007,-0.070374,-880.989746,-0.002203,0.002575,0.065415,-0.313037,-0.015947,0.654151,-880.989746,0.064287,0.000000
173.540009,-0.055481,-881.034180,-0.002242,0.002546,0.064669,-0.246792,-0.012572,0.646687,-881.034180,0.063498,0.000000
174.010010,-0.067024,-881.034180,-0.002276,0.002520,0.064010,-0.298139,-0.015188,0.640101,-881.034180,0.062717,0.000000
174.480011,-0.051758,-881.034180,-0.002311,0.002475,0.062873,-0.230230,-0.011728,0.628732,-881.034180,0.061936,0.000000
174.950012,-0.071495,-881.034180,-0.002328,0.002450,0.062240,-0.318026,-0.016201,0.622403,-881.034180,0.061147,0.000000
175.420013,-0.026062,-880.989746,-0.002354,0.002424,0.061573,-0.115930,-0.005906,0.615727,-880.989746,0.060368,0.000000
175.890015,-0.049149,-881.034180,-0.002414,0.002388,0.060661,-0.218624,-0.011137,0.606613,-881.034180,0.059586,0.000000
176.360016,-0.047661,-881.078674,-0.002453,0.002351,0.059726,-0.212006,-0.010800,0.597256,-881.078674,0.058798,0.000000
176.830002,-0.049522,-881.078674,-0.002453,0.002326,0.059075,-0.220287,-0.011222,0.590746,-881.078674,0.058016,0.000000
177.300003,-0.039093,-881.123169,-0.002496,0.002296,0.058330,-0.173894,-0.008859,0.583298,-881.123169,0.057237,0.000000
177.770004,-0.046913,-881.078674,-0.002548,0.002263,0.057470,-0.208680,-0.010631,0.574698,-881.078674,0.056448,0.000000
178.240005,-0.044312,-881.123169,-0.002578,0.002227,0.056560,-0.197107,-0.010041,0.565600,-881.123169,0.055667,0.000000
178.710007,-0.047287,-881.212097,-0.002596,0.002200,0.055883,-0.210343,-0.010715,0.558832,-881.212097,0.054886,0.000000
179.180008,-0.029785,-881.212097,-0.002621,0.002169,0.055094,-0.132491,-0.006749,0.550944,-881.212097,0.054097,0.000000
179.650009,-0.053993,-881.123169,-0.002677,0.002140,0.054366,-0.240174,-0.012235,0.543662,-881.123169,0.053317,0.000000
180.120010,-0.037605,-881.123169,-0.002699,0.002114,0.053689,-0.167277,-0.008521,0.536895,-881.123169,0.052536,0.000000
180.590012,-0.040955,-881.167664,-0.002751,0.002078,0.052771,-0.182175,-0.009280,0.527705,-881.167664,0.051747,0.000000
181.060013,0.009315,-881.212097,-0.002759,0.002043,0.051903,0.041437,0.002111,0.519030,-881.212097,0.050966,0.000000
181.530014,0.011917,-881.256592,-0.002785,0.002013,0.051140,0.053010,0.002700,0.511400,-881.256592,0.050186,0.000000
182.000015,0.023087,-881.212097,-0.002824,0.001988,0.050498,0.102694,0.005231,0.504981,-881.212097,0.049397,0.000000
182.470001,-0.005951,-881.167664,-0.002863,0.001950,0.049519,-0.026471,-0.001348,0.495185,-881.167664,0.048616,0.000000
182.940002,0.030540,-881.167664,-0.002893,0.001926,0.048928,0.135851,0.006921,0.489281,-881.167664,0.047835,0.000000
183.410004,0.028305,-881.256592,-0.002923,0.001897,0.048174,0.125907,0.006414,0.481741,-881.256592,0.047046,0.000000
183.880005,0.004471,-881.212097,-0.002949,0.001863,0.047316,0.019887,0.001013,0.473157,-881.212097,0.046267,0.000000
184.350006,-0.034630,-881.256592,-0.002979,0.001831,0.046518,-0.154041,-0.007847,0.465179,-881.256592,0.045485,0.000000
184.820007,0.021599,-881.212097,-0.003022,0.001797,0.045632,0.096076,0.004894,0.456322,-881.212097,0.044697,0.000000
185.290009,0.007454,-881.256592,-0.003048,0.001771,0.044974,0.033157,0.001689,0.449736,-881.256592,0.043915,0.000000
185.760010,-0.014145,-881.301086,-0.003074,0.001750,0.044453,-0.062920,-0.003205,0.444528,-881.301086,0.043136,0.000000
186.230011,-0.011909,-881.345581,-0.003104,0.001712,0.043482,-0.052976,-0.002699,0.434824,-881.345581,0.042345,0.000000
186.700012,-0.045425,-881.256592,-0.003143,0.001678,0.042624,-0.202062,-0.010294,0.426240,-881.256592,0.041566,0.000000
187.170013,-0.002228,-881.301086,-0.003186,0.001649,0.041896,-0.009910,-0.000505,0.418958,-881.301086,0.040785,0.000000
187.640015,-0.038353,-881.301086,-0.003208,0.001616,0.041037,-0.170603,-0.008691,0.410373,-881.301086,0.039996,0.000000
188.110016,-0.029045,-881.345581,-0.003247,0.001583,0.040205,-0.129199,-0.006582,0.402047,-881.345581,0.039216,0.000000
188.580002,-0.017128,-881.345581,-0.003264,0.001558,0.039579,-0.076189,-0.003881,0.395794,-881.345581,0.038435,0.000000
189.050003,-0.020851,-881.345581,-0.003303,0.001525,0.038747,-0.092750,-0.004725,0.387467,-881.345581,0.037646,0.000000
189.520004,-0.033882,-881.345581,-0.003341,0.001491,0.037872,-0.150715,-0.007678,0.378717,-881.345581,0.036865,0.000000
189.990005,-0.043190,-881.345581,-0.003372,0.001462,0.037125,-0.192119,-0.009787,0.371253,-881.345581,0.036085,0.000000
190.460007,-0.069633,-881.390076,-0.003397,0.001432,0.036379,-0.309745,-0.015779,0.363789,-881.390076,0.035295,0.000000
190.930008,-0.072609,-881.390076,-0.003423,0.001398,0.035504,-0.322981,-0.016453,0.355038,-881.390076,0.034515,0.000000
191.400009,-0.058830,-881.345581,-0.003454,0.001369,0.034783,-0.261690,-0.013331,0.347832,-881.345581,0.033734,0.000000
191.870010,-0.052872,-881.345581,-0.003501,0.001338,0.033994,-0.235185,-0.011981,0.339944,-881.345581,0.032945,0.000000
192.340012,-0.086014,-881.434509,-0.003531,0.001309,0.033240,-0.382608,-0.019491,0.332405,-881.434509,0.032166,0.000000
192.810013,-0.089363,-881.434509,-0.003561,0.001275,0.032382,-0.397507,-0.020250,0.323820,-881.434509,0.031384,0.000000
193.280014,-0.064041,-881.479004,-0.003596,0.001249,0.031714,-0.284869,-0.014512,0.317144,-881.479004,0.030596,0.000000
193.600006,-0.009308,-881.479004,-0.003622,0.001235,0.031368,-0.041403,-0.002109,0.313677,-881.479004,0.031245,0.000000