File: Data/compression 35/ManualNoHeating-15-35-reverse-1-3_11182024_175935.csv
Time (sec),S:Load (lbs),S:HL1 (DIM),S:LVDT (in),S:Position (in),Ch:Position (mm),Ch:Load (N),Ch:Stress (MPa),Ch:Strain (mm/mm),Ch:HL1 (DIM),Set Point (),Cycles ()
0.110000,-0.008186,-882.457581,-0.013042,-0.007510,-0.190756,-0.036415,-0.001855,-1.907557,-882.457581,-0.190756,0.000000
0.490000,0.020111,-882.502075,-0.013038,-0.007464,-0.189585,0.089459,0.004557,-1.895854,-882.502075,-0.188916,0.000000
0.870000,0.017876,-882.413086,-0.012913,-0.007234,-0.183748,0.079515,0.004051,-1.837476,-882.413086,-0.182586,0.000000
1.250000,0.017136,-882.413086,-0.012654,-0.006995,-0.177669,0.076223,0.003883,-1.776690,-882.413086,-0.176255,0.000000
1.630000,-0.029411,-882.413086,-0.012396,-0.006742,-0.171235,-0.130828,-0.006665,-1.712347,-882.413086,-0.169925,0.000000
2.010000,-0.056595,-882.457581,-0.012141,-0.006497,-0.165034,-0.251746,-0.012825,-1.650335,-882.457581,-0.163594,0.000000
2.390000,-0.059204,-882.502075,-0.011895,-0.006249,-0.158720,-0.263353,-0.013416,-1.587203,-882.502075,-0.157264,0.000000
2.770000,-0.006325,-882.546570,-0.011632,-0.005999,-0.152363,-0.028134,-0.001433,-1.523632,-882.546570,-0.150933,0.000000
3.150000,-0.005951,-882.457581,-0.011365,-0.005748,-0.145989,-0.026471,-0.001348,-1.459895,-882.457581,-0.144601,0.000000
3.530000,-0.026436,-882.457581,-0.011119,-0.005498,-0.139651,-0.117593,-0.005990,-1.396505,-882.457581,-0.138271,0.000000
3.910000,-0.064415,-882.546570,-0.010856,-0.005244,-0.133198,-0.286532,-0.014597,-1.331980,-882.546570,-0.131940,0.000000
4.290000,-0.069260,-882.546570,-0.010602,-0.004994,-0.126858,-0.308082,-0.015694,-1.268576,-882.546570,-0.125610,0.000000
4.670000,0.004471,-882.502075,-0.010352,-0.004756,-0.120796,0.019887,0.001013,-1.207957,-882.502075,-0.119279,0.000000
5.050000,-0.008934,-882.457581,-0.010063,-0.004490,-0.114059,-0.039741,-0.002024,-1.140586,-882.457581,-0.112947,0.000000
5.430000,0.026817,-882.502075,-0.009826,-0.004255,-0.108065,0.119289,0.006077,-1.080648,-882.502075,-0.106617,0.000000
5.810000,0.000748,-882.546570,-0.009580,-0.004009,-0.101821,0.003326,0.000169,-1.018212,-882.546570,-0.100286,0.000000
6.190000,-0.025314,-882.679993,-0.009309,-0.003751,-0.095282,-0.112604,-0.005736,-0.952825,-882.679993,-0.093956,0.000000
6.570000,-0.018616,-882.546570,-0.009050,-0.003493,-0.088727,-0.082807,-0.004218,-0.887270,-882.546570,-0.087625,0.000000
6.950000,0.025322,-882.546570,-0.008800,-0.003253,-0.082630,0.112638,0.005738,-0.826303,-882.546570,-0.081293,0.000000
7.330000,0.050644,-882.591003,-0.008545,-0.003007,-0.076369,0.225275,0.011476,-0.763686,-882.591003,-0.074964,0.000000
7.710001,0.005219,-882.546570,-0.008261,-0.002753,-0.069925,0.023213,0.001183,-0.699252,-882.546570,-0.068632,0.000000
8.090000,0.018623,-882.635498,-0.008024,-0.002506,-0.063647,0.082841,0.004220,-0.636468,-882.635498,-0.062302,0.000000
8.470000,-0.001488,-882.635498,-0.007765,-0.002252,-0.057203,-0.006618,-0.000337,-0.572034,-882.635498,-0.055971,0.000000
8.850000,0.031654,-882.635498,-0.007506,-0.002009,-0.051028,0.140806,0.007173,-0.510280,-882.635498,-0.049641,0.000000
9.230000,0.020111,-882.546570,-0.007248,-0.001759,-0.044689,0.089459,0.004557,-0.446890,-882.546570,-0.043310,0.000000
9.610001,0.028305,-882.635498,-0.006976,-0.001509,-0.038341,0.125907,0.006414,-0.383410,-882.635498,-0.036978,0.000000
9.990001,-0.027924,-882.679993,-0.006739,-0.001274,-0.032365,-0.124210,-0.006328,-0.323654,-882.679993,-0.030649,0.000000
10.370001,-0.007820,-882.546570,-0.006472,-0.001009,-0.025636,-0.034786,-0.001772,-0.256359,-882.546570,-0.024317,0.000000
10.750001,-0.076706,-882.591003,-0.006239,-0.000777,-0.019730,-0.341205,-0.017382,-0.197299,-882.591003,-0.017987,0.000000
11.130000,0.002983,-882.679993,-0.005967,-0.000517,-0.013140,0.013269,0.000676,-0.131396,-882.679993,-0.011656,0.000000
11.510000,0.031654,-882.724487,-0.005696,-0.000252,-0.006409,0.140806,0.007173,-0.064086,-882.724487,-0.005325,0.000000
11.890000,0.049156,-882.724487,-0.005463,-0.000018,-0.000469,0.218658,0.011139,-0.004693,-882.724487,0.001005,0.000000
12.270000,0.110596,-882.724487,-0.005389,-0.000000,-0.000000,0.491954,0.025061,-0.000000,-882.724487,0.000226,0.000000
12.650001,0.142250,-882.724487,-0.005398,-0.000000,-0.000000,0.632760,0.032234,-0.000000,-882.724487,0.000477,0.000000
13.030001,0.131454,-882.679993,-0.005376,0.000000,0.000009,0.584739,0.029788,0.000091,-882.679993,0.001110,0.000000
13.410001,0.176506,-882.724487,-0.005381,0.000027,0.000684,0.785138,0.039997,0.006843,-882.724487,0.001743,0.000000
13.790001,0.211884,-882.768982,-0.005355,0.000037,0.000928,0.942505,0.048013,0.009281,-882.768982,0.002375,0.000000
14.170001,0.310562,-882.768982,-0.005342,0.000070,0.001786,1.381449,0.070374,0.017865,-882.768982,0.003010,0.000000
14.550001,0.353760,-882.768982,-0.005346,0.000085,0.002151,1.573602,0.080163,0.021513,-882.768982,0.003643,0.000000
14.930000,0.589470,-882.679993,-0.005312,0.000120,0.003052,2.622093,0.133576,0.030521,-882.679993,0.004275,0.000000
15.310000,0.769699,-882.768982,-0.005273,0.000149,0.003789,3.423793,0.174416,0.037894,-882.768982,0.004908,0.000000
15.690001,0.878059,-882.813416,-0.005247,0.000166,0.004224,3.905803,0.198971,0.042239,-882.813416,0.005541,0.000000
16.070002,1.169624,-882.768982,-0.005226,0.000202,0.005125,5.202749,0.265041,0.051247,-882.768982,0.006174,0.000000
16.450001,1.329742,-882.768982,-0.005204,0.000222,0.005629,5.914990,0.301324,0.056289,-882.768982,0.006808,0.000000
16.830000,1.424332,-882.724487,-0.005182,0.000235,0.005976,6.335744,0.322758,0.059756,-882.724487,0.007441,0.000000
17.210001,1.750900,-882.813416,-0.005144,0.000269,0.006825,7.788393,0.396760,0.068249,-882.813416,0.008074,0.000000
17.590000,2.028313,-882.857910,-0.005126,0.000295,0.007502,9.022386,0.459622,0.075017,-882.857910,0.008707,0.000000
17.970001,2.260307,-882.813416,-0.005096,0.000323,0.008204,10.054349,0.512193,0.082041,-882.813416,0.009340,0.000000
18.350000,2.603630,-882.857910,-0.005075,0.000353,0.008976,11.581525,0.589991,0.089763,-882.857910,0.009972,0.000000
18.730001,2.849770,-882.768982,-0.005070,0.000376,0.009549,12.676408,0.645767,0.095485,-882.768982,0.010605,0.000000
19.110001,3.042290,-882.768982,-0.005027,0.000398,0.010121,13.532781,0.689393,0.101208,-882.768982,0.011240,0.000000
19.490002,3.295502,-882.902405,-0.005010,0.000420,0.010658,14.659123,0.746771,0.106583,-882.902405,0.011882,0.000000
19.870001,3.416519,-882.813416,-0.005019,0.000443,0.011240,15.197436,0.774194,0.112396,-882.813416,0.012514,0.000000
20.250002,3.931137,-882.768982,-0.004971,0.000472,0.011984,17.486570,0.890808,0.119845,-882.768982,0.013147,0.000000
20.630001,4.381340,-882.857910,-0.004945,0.000500,0.012705,19.489174,0.992826,0.127051,-882.857910,0.013780,0.000000
21.010000,4.519119,-882.813416,-0.004919,0.000523,0.013277,20.102047,1.024047,0.132774,-882.813416,0.014413,0.000000
21.390001,4.684448,-882.857910,-0.004902,0.000540,0.013729,20.837467,1.061511,0.137286,-882.857910,0.015046,0.000000
21.770000,5.067619,-882.946899,-0.004868,0.000577,0.014664,22.541897,1.148339,0.146642,-882.946899,0.015679,0.000000
22.150002,5.160713,-882.902405,-0.004850,0.000589,0.014969,22.955999,1.169434,0.149685,-882.902405,0.016313,0.000000
22.530001,5.500687,-882.813416,-0.004838,0.000608,0.015454,24.468277,1.246473,0.154545,-882.813416,0.016946,0.000000
22.910002,6.236870,-882.857910,-0.004794,0.000646,0.016408,27.742983,1.413295,0.164083,-882.857910,0.017579,0.000000
23.290001,6.700470,-882.902405,-0.004769,0.000679,0.017258,29.805180,1.518348,0.172576,-882.902405,0.018211,0.000000
23.670002,6.768242,-882.946899,-0.004760,0.000701,0.017813,30.106644,1.533705,0.178132,-882.946899,0.018844,0.000000
24.050001,6.925385,-882.946899,-0.004756,0.000715,0.018160,30.805649,1.569315,0.181599,-882.946899,0.019477,0.000000
24.430000,7.347282,-882.946899,-0.004725,0.000741,0.018818,32.682343,1.664918,0.188185,-882.946899,0.020111,0.000000
24.810001,8.127403,-882.946899,-0.004691,0.000773,0.019625,36.152496,1.841696,0.196254,-882.946899,0.020744,0.000000
25.190001,8.186981,-882.991333,-0.004687,0.000791,0.020102,36.417511,1.855196,0.201023,-882.991333,0.021377,0.000000
25.570002,8.504242,-883.035828,-0.004648,0.000814,0.020675,37.828758,1.927089,0.206746,-883.035828,0.022010,0.000000
25.950001,8.682243,-882.991333,-0.004644,0.000836,0.021238,38.620548,1.967424,0.212378,-882.991333,0.022643,0.000000
26.330002,9.502579,-882.946899,-0.004600,0.000870,0.022105,42.269581,2.153315,0.221053,-882.946899,0.023276,0.000000
26.710001,9.432945,-882.946899,-0.004579,0.000888,0.022547,41.959835,2.137536,0.225474,-882.946899,0.023910,0.000000
27.090002,9.860054,-883.035828,-0.004557,0.000916,0.023259,43.859711,2.234320,0.232589,-883.035828,0.024543,0.000000
27.470001,10.353447,-883.080322,-0.004523,0.000943,0.023952,46.054432,2.346125,0.239523,-883.080322,0.025176,0.000000
27.850000,10.626022,-882.991333,-0.004510,0.000967,0.024559,47.266907,2.407891,0.245594,-882.991333,0.025808,0.000000
28.230001,10.650597,-882.946899,-0.004493,0.000983,0.024959,47.376221,2.413460,0.249591,-882.946899,0.026441,0.000000
28.610001,11.663826,-883.035828,-0.004449,0.001021,0.025939,51.883289,2.643061,0.259386,-883.035828,0.027074,0.000000
28.990002,11.815750,-883.080322,-0.004428,0.001049,0.026632,52.559082,2.677487,0.266320,-883.080322,0.027708,0.000000
29.370001,12.340424,-883.080322,-0.004398,0.001080,0.027430,54.892944,2.796380,0.274299,-883.080322,0.028341,0.000000
29.750002,12.391441,-883.080322,-0.004385,0.001105,0.028055,55.119884,2.807941,0.280552,-883.080322,0.028974,0.000000
30.130001,12.808868,-883.035828,-0.004350,0.001131,0.028723,56.976692,2.902531,0.287228,-883.035828,0.029616,0.000000
30.510002,12.823769,-883.080322,-0.004346,0.001149,0.029174,57.042973,2.905908,0.291740,-883.080322,0.030249,0.000000
30.890001,12.999153,-883.124817,-0.004324,0.001167,0.029651,57.823120,2.945650,0.296509,-883.124817,0.030882,0.000000
31.270002,13.007347,-883.124817,-0.004316,0.001188,0.030163,57.859570,2.947507,0.301626,-883.124817,0.031515,0.000000
31.650002,13.747993,-883.124817,-0.004281,0.001213,0.030821,61.154129,3.115340,0.308212,-883.124817,0.032147,0.000000
32.030003,14.401505,-883.080322,-0.004251,0.001247,0.031670,64.061089,3.263427,0.316705,-883.080322,0.032782,0.000000
32.410000,14.660309,-883.035828,-0.004225,0.001273,0.032331,65.212311,3.322073,0.323306,-883.035828,0.033415,0.000000
32.790001,14.647278,-883.080322,-0.004186,0.001294,0.032877,65.154343,3.319121,0.328771,-883.080322,0.034047,0.000000
33.170002,15.089653,-883.124817,-0.004178,0.001319,0.033492,67.122131,3.419364,0.334918,-883.124817,0.034680,0.000000
33.550003,15.294830,-883.124817,-0.004143,0.001340,0.034047,68.034805,3.465858,0.340474,-883.124817,0.035313,0.000000
33.930000,15.362976,-883.169312,-0.004126,0.001367,0.034715,68.337929,3.481300,0.347151,-883.169312,0.035946,0.000000
34.310001,16.181076,-883.124817,-0.004105,0.001395,0.035434,71.977020,3.666684,0.354342,-883.124817,0.036579,0.000000
34.690002,16.403755,-883.124817,-0.004079,0.001422,0.036129,72.967545,3.717144,0.361291,-883.124817,0.037213,0.000000
35.070004,16.096924,-883.213745,-0.004061,0.001435,0.036450,71.602692,3.647615,0.364501,-883.213745,0.037846,0.000000
35.450001,16.761978,-883.124817,-0.004036,0.001468,0.037281,74.561005,3.798319,0.372812,-883.124817,0.038479,0.000000
35.830002,16.368752,-883.169312,-0.004010,0.001480,0.037595,72.811844,3.709212,0.375946,-883.169312,0.039112,0.000000
36.210003,17.421822,-883.169312,-0.003997,0.001517,0.038539,77.496132,3.947841,0.385393,-883.169312,0.039744,0.000000
36.590000,17.858238,-883.213745,-0.003962,0.001547,0.039302,79.437408,4.046735,0.393023,-883.213745,0.040377,0.000000
36.970001,17.454216,-883.258240,-0.003932,0.001560,0.039632,77.640228,3.955182,0.396324,-883.258240,0.041012,0.000000
37.350002,17.588646,-883.169312,-0.003889,0.001581,0.040152,78.238205,3.985644,0.401517,-883.169312,0.041644,0.000000
37.730003,18.563889,-883.169312,-0.003876,0.001619,0.041133,82.576302,4.206637,0.411327,-883.169312,0.042277,0.000000
38.110001,18.022827,-883.169312,-0.003854,0.001632,0.041445,80.169540,4.084031,0.414446,-883.169312,0.042910,0.000000
38.490002,18.878166,-883.213745,-0.003850,0.001666,0.042329,83.974274,4.277854,0.423288,-883.213745,0.043543,0.000000
38.870003,19.279961,-883.258240,-0.003829,0.001694,0.043024,85.761551,4.368902,0.430237,-883.258240,0.044176,0.000000
39.250000,19.616959,-883.258240,-0.003790,0.001722,0.043726,87.260590,4.445266,0.437261,-883.258240,0.044810,0.000000
39.630001,20.020233,-883.258240,-0.003777,0.001752,0.044489,89.054443,4.536650,0.444892,-883.258240,0.045443,0.000000
40.010002,19.925278,-883.169312,-0.003747,0.001773,0.045027,88.632065,4.515132,0.450266,-883.169312,0.046076,0.000000
40.390003,20.083168,-883.302734,-0.003712,0.001794,0.045573,89.334396,4.550911,0.455732,-883.302734,0.046709,0.000000
40.770000,20.294678,-883.347229,-0.003691,0.001818,0.046180,90.275238,4.598839,0.461803,-883.347229,0.047341,0.000000
41.150002,20.257065,-883.258240,-0.003665,0.001837,0.046665,90.107925,4.590316,0.466647,-883.258240,0.047983,0.000000
41.530003,20.492401,-883.302734,-0.003669,0.001862,0.047307,91.154755,4.643644,0.473066,-883.302734,0.048616,0.000000
41.910004,21.658302,-883.302734,-0.003652,0.001895,0.048130,96.340942,4.907842,0.481302,-883.302734,0.049249,0.000000
42.290001,21.784538,-883.347229,-0.003626,0.001920,0.048756,96.902466,4.936447,0.487555,-883.347229,0.049883,0.000000
42.670002,21.653465,-883.436157,-0.003617,0.001940,0.049267,96.319427,4.906745,0.492672,-883.436157,0.050516,0.000000
43.050003,22.273834,-883.302734,-0.003570,0.001969,0.050012,99.078964,5.047323,0.500121,-883.302734,0.051149,0.000000
43.430000,21.926781,-883.302734,-0.003557,0.001987,0.050472,97.535194,4.968679,0.504723,-883.302734,0.051782,0.000000
43.810001,21.474350,-883.302734,-0.003544,0.002003,0.050889,95.522682,4.866157,0.508887,-883.302734,0.052415,0.000000
44.190002,23.296745,-883.347229,-0.003531,0.002044,0.051921,103.629097,5.279118,0.519212,-883.347229,0.053048,0.000000
44.570004,24.368431,-883.391663,-0.003497,0.002077,0.052754,108.396194,5.521965,0.527539,-883.391663,0.053680,0.000000
44.950001,23.875778,-883.391663,-0.003466,0.002094,0.053196,106.204765,5.410328,0.531959,-883.391663,0.054315,0.000000
45.330002,23.713425,-883.302734,-0.003449,0.002113,0.053673,105.482582,5.373538,0.536728,-883.302734,0.054948,0.000000
45.710003,24.142403,-883.391663,-0.003423,0.002138,0.054297,107.390770,5.470747,0.542966,-883.391663,0.055580,0.000000
46.090004,25.292656,-883.347229,-0.003402,0.002171,0.055147,112.507355,5.731398,0.551474,-883.347229,0.056213,0.000000
46.470001,25.023064,-883.391663,-0.003402,0.002189,0.055597,111.308144,5.670307,0.555971,-883.391663,0.056846,0.000000
46.850002,25.083755,-883.347229,-0.003372,0.002212,0.056188,111.578117,5.684060,0.561875,-883.347229,0.057479,0.000000
47.230003,25.326920,-883.391663,-0.003337,0.002232,0.056681,112.659767,5.739162,0.566811,-883.391663,0.058113,0.000000
47.610001,26.685707,-883.391663,-0.003320,0.002266,0.057567,118.703957,6.047068,0.575667,-883.391663,0.058746,0.000000
47.990002,26.208694,-883.480652,-0.003324,0.002282,0.057974,116.582092,5.938975,0.579740,-883.480652,0.059379,0.000000
48.370003,26.985092,-883.525146,-0.003307,0.002314,0.058772,120.035683,6.114910,0.587718,-883.525146,0.060012,0.000000
48.750004,27.284851,-883.391663,-0.003264,0.002342,0.059474,121.369080,6.182836,0.594743,-883.391663,0.060645,0.000000
49.130001,27.574181,-883.391663,-0.003242,0.002365,0.060081,122.656082,6.248398,0.600814,-883.391663,0.061277,0.000000
49.510002,27.430077,-883.480652,-0.003234,0.002381,0.060472,122.015076,6.215744,0.604720,-883.480652,0.061912,0.000000
49.890003,29.194008,-883.480652,-0.003208,0.002420,0.061461,129.861435,6.615457,0.614606,-883.480652,0.062545,0.000000
50.270004,29.624466,-883.480652,-0.003195,0.002447,0.062154,131.776199,6.713000,0.621540,-883.480652,0.063177,0.000000
50.650002,30.302559,-883.436157,-0.003160,0.002476,0.062900,134.792511,6.866658,0.629004,-883.436157,0.063810,0.000000
51.030003,30.097755,-883.480652,-0.003134,0.002498,0.063445,133.881500,6.820249,0.634454,-883.480652,0.064443,0.000000
51.410004,30.674561,-883.480652,-0.003104,0.002527,0.064192,136.447266,6.950955,0.641918,-883.480652,0.065076,0.000000
51.790001,30.331230,-883.525146,-0.003091,0.002545,0.064652,134.920044,6.873155,0.646521,-883.525146,0.065709,0.000000
52.170002,30.380013,-883.480652,-0.003087,0.002566,0.065171,135.137039,6.884209,0.651713,-883.480652,0.066351,0.000000
52.550003,30.077271,-883.480652,-0.003070,0.002581,0.065553,133.790375,6.815607,0.655529,-883.480652,0.066985,0.000000
52.930004,31.386536,-883.480652,-0.003057,0.002612,0.066334,139.614288,7.112290,0.663341,-883.480652,0.067618,0.000000
53.310001,31.467339,-883.525146,-0.003022,0.002632,0.066846,139.973709,7.130601,0.668458,-883.525146,0.068251,0.000000
53.690002,32.814583,-883.525146,-0.002997,0.002668,0.067756,145.966553,7.435891,0.677557,-883.525146,0.068884,0.000000
54.070004,32.729309,-883.614075,-0.002984,0.002686,0.068216,145.587234,7.416567,0.682159,-883.614075,0.069516,0.000000
54.450001,33.710884,-883.480652,-0.002966,0.002715,0.068962,149.953506,7.638996,0.689623,-883.480652,0.070149,0.000000
54.830002,33.523582,-883.525146,-0.002953,0.002736,0.069491,149.120346,7.596552,0.694907,-883.525146,0.070782,0.000000
55.210003,33.972290,-883.525146,-0.002932,0.002761,0.070142,151.116287,7.698231,0.701417,-883.525146,0.071416,0.000000
55.590004,35.174309,-883.569641,-0.002915,0.002791,0.070896,156.463135,7.970612,0.708956,-883.569641,0.072049,0.000000
55.970001,35.674400,-883.614075,-0.002893,0.002815,0.071494,158.687653,8.083935,0.714936,-883.614075,0.072682,0.000000
56.350002,35.518379,-883.614075,-0.002880,0.002833,0.071971,157.993637,8.048580,0.719705,-883.614075,0.073315,0.000000
56.730003,36.633263,-883.525146,-0.002815,0.002867,0.072829,162.952896,8.301216,0.728289,-883.525146,0.073948,0.000000
57.110004,35.938789,-883.569641,-0.002807,0.002877,0.073080,159.863724,8.143846,0.730803,-883.569641,0.074581,0.000000
57.490002,37.160538,-883.658569,-0.002790,0.002910,0.073905,165.298325,8.420698,0.739054,-883.658569,0.075215,0.000000
57.870003,38.240051,-883.658569,-0.002794,0.002940,0.074676,170.100250,8.665319,0.746760,-883.658569,0.075848,0.000000
58.250004,38.076202,-883.614075,-0.002759,0.002957,0.075120,169.371414,8.628190,0.751196,-883.614075,0.076481,0.000000
58.630001,38.383415,-883.614075,-0.002738,0.002979,0.075674,170.737961,8.697806,0.756737,-883.614075,0.077113,0.000000
59.010002,40.019241,-883.658569,-0.002734,0.003018,0.076662,178.014481,9.068490,0.766623,-883.658569,0.077746,0.000000
59.390003,39.385094,-883.658569,-0.002725,0.003030,0.076967,175.193649,8.924790,0.769666,-883.658569,0.078379,0.000000
59.770004,40.632172,-883.703064,-0.002708,0.003064,0.077825,180.740921,9.207382,0.778250,-883.703064,0.079013,0.000000
60.150002,41.591774,-883.703064,-0.002695,0.003092,0.078544,185.009445,9.424831,0.785441,-883.703064,0.079646,0.000000
60.530003,42.165596,-883.614075,-0.002682,0.003120,0.079238,187.561935,9.554860,0.792375,-883.614075,0.080279,0.000000
60.910004,43.044029,-883.703064,-0.002647,0.003147,0.079940,191.469406,9.753916,0.799400,-883.703064,0.080912,0.000000
61.290005,42.481743,-883.703064,-0.002630,0.003161,0.080279,188.968231,9.626501,0.802791,-883.703064,0.081545,0.000000
61.670002,43.498695,-883.747559,-0.002621,0.003192,0.081077,193.491867,9.856945,0.810770,-883.747559,0.082178,0.000000
62.050003,44.147362,-883.658569,-0.002604,0.003216,0.081693,196.377274,10.003935,0.816932,-883.658569,0.082812,0.000000
62.430004,44.219604,-883.703064,-0.002587,0.003235,0.082178,196.698624,10.020306,0.821776,-883.703064,0.083445,0.000000
62.810001,44.519737,-883.703064,-0.002570,0.003258,0.082750,198.033676,10.088317,0.827499,-883.703064,0.084078,0.000000
63.190002,45.696060,-883.747559,-0.002557,0.003291,0.083592,203.266220,10.354876,0.835917,-883.747559,0.084720,0.000000
63.570004,46.636673,-883.747559,-0.002535,0.003317,0.084250,207.450287,10.568021,0.842502,-883.747559,0.085352,0.000000
63.950005,46.943512,-883.747559,-0.002531,0.003337,0.084771,208.815170,10.637551,0.847710,-883.747559,0.085985,0.000000
64.330002,48.156326,-883.703064,-0.002496,0.003368,0.085543,214.210037,10.912380,0.855432,-883.703064,0.086618,0.000000
64.710007,47.447327,-883.791992,-0.002488,0.003384,0.085960,211.056244,10.751719,0.859595,-883.791992,0.087251,0.000000
65.090004,46.984474,-883.747559,-0.002471,0.003394,0.086202,208.997375,10.646834,0.862017,-883.747559,0.087885,0.000000
65.470001,49.739281,-883.747559,-0.002462,0.003438,0.087330,221.251373,11.271082,0.873296,-883.747559,0.088518,0.000000
65.850006,51.611198,-883.747559,-0.002440,0.003474,0.088249,229.578079,11.695265,0.882486,-883.747559,0.089151,0.000000
66.230003,51.058228,-883.747559,-0.002414,0.003493,0.088716,227.118332,11.569960,0.887164,-883.747559,0.089784,0.000000
66.610001,51.186325,-883.747559,-0.002410,0.003510,0.089142,227.688141,11.598988,0.891418,-883.747559,0.090417,0.000000
66.990005,51.784721,-883.836487,-0.002393,0.003535,0.089800,230.349945,11.734585,0.898004,-883.836487,0.091049,0.000000
67.370003,52.513832,-883.791992,-0.002371,0.003564,0.090530,233.593185,11.899804,0.905301,-883.791992,0.091682,0.000000
67.750000,52.401001,-883.791992,-0.002354,0.003576,0.090842,233.091293,11.874237,0.908420,-883.791992,0.092317,0.000000
68.130005,53.372520,-883.791992,-0.002341,0.003610,0.091682,237.412827,12.094386,0.916823,-883.791992,0.092949,0.000000
68.510002,53.628716,-883.836487,-0.002311,0.003629,0.092168,238.552444,12.152441,0.921682,-883.836487,0.093582,0.000000
68.890007,54.932762,-883.836487,-0.002298,0.003663,0.093036,244.353134,12.447942,0.930357,-883.836487,0.094215,0.000000
69.270004,55.209435,-883.880981,-0.002298,0.003681,0.093487,245.583832,12.510637,0.934869,-883.880981,0.094848,0.000000
69.650002,56.270699,-883.836487,-0.002285,0.003712,0.094276,250.304565,12.751122,0.942757,-883.836487,0.095481,0.000000
70.030006,56.377937,-883.791992,-0.002255,0.003738,0.094936,250.781586,12.775423,0.949358,-883.791992,0.096115,0.000000
70.410004,56.699669,-883.836487,-0.002246,0.003758,0.095446,252.212723,12.848329,0.954460,-883.836487,0.096748,0.000000
70.790001,56.247238,-883.880981,-0.002242,0.003778,0.095967,250.200211,12.745806,0.959668,-883.880981,0.097381,0.000000
71.170006,57.973930,-883.925476,-0.002225,0.003812,0.096818,257.880920,13.137080,0.968176,-883.925476,0.098014,0.000000
71.550003,59.610504,-883.925476,-0.002207,0.003845,0.097658,265.160767,13.507934,0.976579,-883.925476,0.098646,0.000000
71.930000,57.607887,-883.836487,-0.002182,0.003845,0.097667,256.252686,13.054134,0.976669,-883.836487,0.099279,0.000000
72.310005,60.170921,-883.925476,-0.002177,0.003893,0.098872,267.653625,13.634926,0.988721,-883.925476,0.099914,0.000000
72.690002,61.034081,-883.925476,-0.002143,0.003922,0.099626,271.493164,13.830521,0.996260,-883.925476,0.100546,0.000000
73.070000,60.473289,-883.880981,-0.002134,0.003939,0.100051,268.998627,13.703444,1.000514,-883.880981,0.101179,0.000000
73.450005,60.473663,-883.925476,-0.002126,0.003961,0.100598,269.000275,13.703527,1.005980,-883.925476,0.101812,0.000000
73.830002,60.092728,-883.836487,-0.002104,0.003974,0.100945,267.305817,13.617207,1.009447,-883.836487,0.102454,0.000000
74.210007,61.760582,-883.925476,-0.002078,0.004010,0.101856,274.724792,13.995148,1.018561,-883.925476,0.103087,0.000000
74.590004,62.552994,-884.014404,-0.002061,0.004041,0.102654,278.249603,14.174711,1.026539,-884.014404,0.103720,0.000000
74.970001,62.545914,-883.969971,-0.002065,0.004063,0.103200,278.218109,14.173107,1.032005,-883.969971,0.104353,0.000000
75.350006,63.186028,-883.969971,-0.002044,0.004084,0.103738,281.065491,14.318159,1.037379,-883.969971,0.104987,0.000000
75.730003,64.019020,-883.969971,-0.002022,0.004109,0.104371,284.770813,14.506917,1.043707,-883.969971,0.105620,0.000000
76.110001,64.335533,-883.969971,-0.002009,0.004131,0.104934,286.178741,14.578640,1.049339,-883.969971,0.106253,0.000000
76.490005,64.682961,-884.014404,-0.001983,0.004151,0.105429,287.724182,14.657369,1.054290,-884.014404,0.106885,0.000000
76.870003,66.120689,-883.969971,-0.001975,0.004187,0.106339,294.119507,14.983163,1.063389,-883.969971,0.107518,0.000000
77.250000,64.544060,-884.014404,-0.001970,0.004177,0.106104,287.106323,14.625893,1.061042,-884.014404,287.989227,0.000000
77.630005,65.099281,-883.969971,-0.001944,0.004175,0.106036,289.576080,14.751708,1.060361,-883.969971,294.500488,0.000000
78.010002,65.637352,-884.103394,-0.001953,0.004223,0.107276,291.969513,14.873637,1.072760,-884.103394,294.500488,0.000000
78.390007,64.339256,-884.014404,-0.001944,0.004230,0.107441,286.195312,14.579484,1.074411,-884.014404,294.500488,0.000000
78.770004,65.016609,-884.147888,-0.001923,0.004238,0.107648,289.208313,14.732974,1.076485,-884.147888,294.500488,0.000000
79.150002,65.307808,-884.103394,-0.001919,0.004252,0.108004,290.503632,14.798961,1.080042,-884.103394,294.500488,0.000000
79.530006,65.819069,-884.014404,-0.001910,0.004265,0.108325,292.777832,14.914814,1.083252,-884.014404,294.500488,0.000000
79.910004,64.863197,-884.014404,-0.001901,0.004282,0.108758,288.525909,14.698210,1.087582,-884.014404,294.500488,0.000000
80.290001,65.393822,-884.103394,-0.001867,0.004295,0.109088,290.886261,14.818452,1.090882,-884.103394,294.500488,0.000000
80.670006,64.410011,-884.103394,-0.001858,0.004296,0.109114,286.510040,14.595517,1.091140,-884.103394,294.500488,0.000000
81.050003,65.485802,-884.147888,-0.001850,0.004304,0.109314,291.295380,14.839295,1.093138,-884.147888,294.500488,0.000000
81.430000,64.453209,-884.103394,-0.001832,0.004305,0.109358,286.702179,14.605307,1.093577,-884.103394,294.500488,0.000000
81.810005,65.880516,-884.103394,-0.001828,0.004288,0.108907,293.051178,14.928739,1.089066,-884.103394,294.500488,0.000000
82.190002,64.936546,-884.147888,-0.001828,0.004318,0.109670,288.852173,14.714832,1.096696,-884.147888,294.500488,0.000000
82.570007,64.924629,-884.236816,-0.001824,0.004337,0.110163,288.799164,14.712132,1.101632,-884.236816,294.500488,0.000000
82.950005,64.808830,-884.103394,-0.001832,0.004346,0.110389,288.284088,14.685891,1.103887,-884.103394,294.500488,0.000000
83.330002,64.792061,-884.147888,-0.001815,0.004351,0.110528,288.209473,14.682091,1.105280,-884.147888,294.500488,0.000000
83.710007,65.017723,-884.103394,-0.001815,0.004362,0.110788,289.213287,14.733227,1.107884,-884.103394,294.500488,0.000000
84.090004,64.526939,-884.103394,-0.001802,0.004369,0.110970,287.030151,14.622013,1.109701,-884.103394,294.500488,0.000000
84.470001,65.447807,-884.192322,-0.001789,0.004376,0.111152,291.126373,14.830686,1.111518,-884.192322,294.500488,0.000000
84.850006,64.847557,-884.147888,-0.001802,0.004376,0.111161,288.456329,14.694667,1.111609,-884.147888,294.500488,0.000000
85.230003,66.459557,-884.147888,-0.001776,0.004394,0.111603,295.626862,15.059951,1.116029,-884.147888,294.500488,0.000000
85.610001,65.849602,-884.192322,-0.001763,0.004380,0.111247,292.913666,14.921733,1.112471,-884.192322,294.500488,0.000000
85.990005,65.226250,-884.192322,-0.001776,0.004381,0.111282,290.140839,14.780479,1.112820,-884.192322,294.500488,0.000000
86.370003,65.533455,-884.192322,-0.001763,0.004403,0.111838,291.507355,14.850093,1.118376,-884.192322,294.500488,0.000000
86.750008,65.115288,-884.192322,-0.001781,0.004403,0.111847,289.647278,14.755335,1.118467,-884.192322,294.500488,0.000000
87.130005,65.044167,-884.103394,-0.001772,0.004408,0.111968,289.330902,14.739220,1.119678,-884.103394,294.500488,0.000000
87.510002,65.035973,-884.147888,-0.001768,0.004413,0.112080,289.294464,14.737362,1.120798,-884.147888,294.500488,0.000000
87.890007,65.081398,-884.192322,-0.001763,0.004417,0.112193,289.496521,14.747656,1.121934,-884.192322,294.500488,0.000000
88.270004,64.846809,-884.236816,-0.001755,0.004427,0.112436,288.453003,14.694497,1.124356,-884.236816,294.500488,0.000000
88.650002,65.355095,-884.236816,-0.001755,0.004427,0.112445,290.713989,14.809676,1.124447,-884.236816,294.500488,0.000000
89.030006,65.078056,-884.192322,-0.001763,0.004428,0.112461,289.481659,14.746899,1.124613,-884.192322,294.500488,0.000000
89.410004,64.787971,-884.236816,-0.001746,0.004428,0.112470,288.191284,14.681164,1.124704,-884.236816,294.500488,0.000000
89.790001,65.763588,-884.192322,-0.001759,0.004441,0.112791,292.531036,14.902242,1.127914,-884.192322,294.500488,0.000000
90.170006,65.489143,-884.281311,-0.001763,0.004441,0.112791,291.310272,14.840053,1.127914,-884.281311,294.500488,0.000000
90.550003,65.201302,-884.281311,-0.001763,0.004441,0.112800,290.029877,14.774826,1.128005,-884.281311,294.500488,0.000000
90.930008,64.899315,-884.325806,-0.001742,0.004441,0.112800,288.686584,14.706395,1.128005,-884.325806,294.500488,0.000000
91.310005,64.620399,-884.281311,-0.001742,0.004441,0.112800,287.445892,14.643191,1.128005,-884.281311,294.500488,0.000000
91.690002,64.342979,-884.236816,-0.001746,0.004452,0.113087,286.211853,14.580327,1.130866,-884.236816,294.500488,0.000000
92.070007,66.325874,-884.281311,-0.001720,0.004423,0.112340,295.032227,15.029657,1.123402,-884.281311,294.500488,0.000000
92.450005,65.981804,-884.325806,-0.001733,0.004423,0.112340,293.501709,14.951691,1.123402,-884.325806,294.500488,0.000000
92.830002,65.702888,-884.281311,-0.001733,0.004423,0.112349,292.261047,14.888488,1.123493,-884.281311,294.500488,0.000000
93.210007,65.409462,-884.281311,-0.001725,0.004423,0.112349,290.955811,14.821997,1.123493,-884.281311,294.500488,0.000000
93.590004,65.140984,-884.236816,-0.001725,0.004431,0.112549,289.761566,14.761158,1.125491,-884.236816,294.500488,0.000000
93.970001,65.104118,-884.325806,-0.001729,0.004459,0.113268,289.597595,14.752804,1.132683,-884.325806,294.500488,0.000000
94.350006,64.955910,-884.414734,-0.001720,0.004459,0.113268,288.938324,14.719219,1.132683,-884.414734,294.500488,0.000000
94.730003,65.260506,-884.325806,-0.001729,0.004468,0.113485,290.293213,14.788242,1.134848,-884.325806,294.500488,0.000000
95.110008,65.168159,-884.325806,-0.001733,0.004468,0.113485,289.882446,14.767316,1.134848,-884.325806,294.500488,0.000000
95.490005,65.016609,-884.370239,-0.001725,0.004469,0.113511,289.208313,14.732974,1.135105,-884.370239,294.500488,0.000000
95.870003,64.920158,-884.325806,-0.001738,0.004470,0.113529,288.779297,14.711118,1.135287,-884.325806,294.500488,0.000000
96.250008,65.273552,-884.459229,-0.001733,0.004475,0.113676,290.351257,14.791199,1.136755,-884.459229,294.500488,0.000000
96.630005,65.095543,-884.414734,-0.001738,0.004476,0.113685,289.559448,14.750860,1.136846,-884.414734,294.500488,0.000000
97.010002,64.951439,-884.325806,-0.001725,0.004476,0.113685,288.918427,14.718206,1.136846,-884.325806,294.500488,0.000000
97.390007,64.872124,-884.370239,-0.001716,0.004477,0.113710,288.565613,14.700233,1.137104,-884.370239,294.500488,0.000000
97.770004,64.711632,-884.325806,-0.001720,0.004477,0.113710,287.851715,14.663866,1.137104,-884.325806,294.500488,0.000000
98.150002,65.794121,-884.459229,-0.001725,0.004491,0.114066,292.666870,14.909161,1.140661,-884.459229,294.500488,0.000000
98.530006,65.750175,-884.414734,-0.001725,0.004491,0.114066,292.471375,14.899202,1.140661,-884.414734,294.500488,0.000000
98.910004,65.593788,-884.414734,-0.001725,0.004491,0.114066,291.775757,14.863765,1.140661,-884.414734,294.500488,0.000000
99.290001,65.467171,-884.325806,-0.001712,0.004491,0.114066,291.212524,14.835073,1.140661,-884.325806,294.500488,0.000000
99.670006,65.305565,-884.414734,-0.001716,0.004491,0.114066,290.493652,14.798452,1.140661,-884.414734,294.500488,0.000000
100.050003,65.172630,-884.459229,-0.001712,0.004491,0.114066,289.902344,14.768330,1.140661,-884.459229,294.500488,0.000000
100.430008,65.015862,-884.503723,-0.001716,0.004491,0.114066,289.204987,14.732804,1.140661,-884.503723,294.500488,0.000000
100.810005,64.865059,-884.414734,-0.001699,0.004491,0.114066,288.534180,14.698632,1.140661,-884.414734,294.500488,0.000000
101.190002,64.755943,-884.459229,-0.001716,0.004492,0.114101,288.048828,14.673906,1.141010,-884.459229,294.500488,0.000000
101.570007,65.492867,-884.414734,-0.001716,0.004502,0.114343,291.326813,14.840896,1.143432,-884.414734,294.500488,0.000000
101.950005,65.440742,-884.548218,-0.001707,0.004502,0.114343,291.094971,14.829084,1.143432,-884.548218,294.500488,0.000000
102.330002,65.327904,-884.548218,-0.001703,0.004502,0.114343,290.593018,14.803514,1.143432,-884.548218,294.500488,0.000000
102.710007,65.262001,-884.548218,-0.001694,0.004502,0.114343,290.299866,14.788581,1.143432,-884.548218,294.500488,0.000000
103.090004,65.115288,-884.459229,-0.001699,0.004502,0.114343,289.647278,14.755335,1.143432,-884.459229,294.500488,0.000000
103.470001,65.010643,-884.503723,-0.001699,0.004502,0.114343,289.181793,14.731623,1.143432,-884.503723,294.500488,0.000000
103.850006,64.900063,-884.503723,-0.001694,0.004502,0.114343,288.689911,14.706564,1.143432,-884.503723,294.500488,0.000000
104.230003,64.772697,-884.548218,-0.001699,0.004502,0.114343,288.123352,14.677703,1.143432,-884.548218,294.500488,0.000000
104.610008,64.660622,-884.548218,-0.001703,0.004502,0.114352,287.624817,14.652307,1.143523,-884.548218,294.500488,0.000000
104.990005,64.538475,-884.459229,-0.001694,0.004502,0.114352,287.081482,14.624627,1.143523,-884.459229,294.500488,0.000000
105.370003,66.370552,-884.503723,-0.001690,0.004496,0.114196,295.230957,15.039782,1.141963,-884.503723,294.500488,0.000000
105.750008,66.217888,-884.592651,-0.001677,0.004496,0.114196,294.551880,15.005188,1.141963,-884.592651,294.500488,0.000000
106.130005,66.064842,-884.637146,-0.001690,0.004496,0.114196,293.871094,14.970508,1.141963,-884.637146,294.500488,0.000000
106.510002,65.965416,-884.592651,-0.001690,0.004496,0.114196,293.428833,14.947977,1.141963,-884.592651,294.500488,0.000000
106.890007,65.822792,-884.592651,-0.001686,0.004496,0.114196,292.794403,14.915658,1.141963,-884.592651,294.500488,0.000000
107.270004,65.757256,-884.681641,-0.001690,0.004496,0.114196,292.502869,14.900806,1.141963,-884.681641,294.500488,0.000000
107.650002,65.594902,-884.592651,-0.001690,0.004496,0.114196,291.780701,14.864017,1.141963,-884.592651,294.500488,0.000000
108.030006,65.528252,-884.592651,-0.001699,0.004496,0.114196,291.484222,14.848913,1.141963,-884.592651,294.500488,0.000000
108.410004,65.409828,-884.681641,-0.001681,0.004496,0.114196,290.957458,14.822079,1.141963,-884.681641,294.500488,0.000000
108.790009,65.297005,-884.637146,-0.001686,0.004497,0.114231,290.455597,14.796514,1.142312,-884.637146,294.500488,0.000000
109.170006,65.201683,-884.637146,-0.001690,0.004502,0.114361,290.031586,14.774913,1.143614,-884.637146,294.500488,0.000000
109.550003,65.072456,-884.637146,-0.001681,0.004517,0.114734,289.456757,14.745629,1.147338,-884.637146,294.500488,0.000000
109.930008,65.272804,-884.681641,-0.001677,0.004520,0.114813,290.347931,14.791029,1.148125,-884.681641,294.500488,0.000000
110.310005,65.201683,-884.726135,-0.001694,0.004520,0.114813,290.031586,14.774913,1.148125,-884.726135,294.500488,0.000000
110.690002,65.103737,-884.637146,-0.001690,0.004520,0.114813,289.595886,14.752718,1.148125,-884.637146,294.500488,0.000000
111.070007,65.025551,-884.592651,-0.001681,0.004520,0.114813,289.248108,14.735001,1.148125,-884.592651,294.500488,0.000000
111.450005,65.619850,-884.681641,-0.001681,0.004529,0.115046,291.891663,14.869671,1.150457,-884.681641,294.500488,0.000000
111.830002,65.602715,-884.726135,-0.001690,0.004529,0.115046,291.815460,14.865788,1.150457,-884.726135,294.500488,0.000000
112.210007,65.582237,-884.726135,-0.001677,0.004529,0.115046,291.724365,14.861147,1.150457,-884.726135,294.500488,0.000000
112.590004,65.524529,-884.770569,-0.001690,0.004529,0.115046,291.467651,14.848070,1.150457,-884.770569,294.500488,0.000000
112.970009,65.446327,-884.681641,-0.001681,0.004529,0.115046,291.119812,14.830349,1.150457,-884.681641,294.500488,0.000000
113.350006,65.360313,-884.726135,-0.001669,0.004529,0.115046,290.737183,14.810859,1.150457,-884.726135,294.500488,0.000000
113.730003,65.307808,-884.770569,-0.001690,0.004530,0.115055,290.503632,14.798961,1.150548,-884.770569,294.500488,0.000000
114.110008,65.248970,-884.859558,-0.001681,0.004530,0.115055,290.241913,14.785628,1.150548,-884.859558,294.500488,0.000000
114.490005,65.222527,-884.681641,-0.001673,0.004531,0.115099,290.124298,14.779635,1.150987,-884.681641,294.500488,0.000000
114.870003,65.287315,-884.726135,-0.001677,0.004533,0.115141,290.412476,14.794317,1.151410,-884.726135,294.500488,0.000000
115.250008,65.283592,-884.726135,-0.001677,0.004533,0.115141,290.395935,14.793474,1.151410,-884.726135,294.500488,0.000000
115.630005,65.238167,-884.815063,-0.001664,0.004533,0.115150,290.193848,14.783179,1.151501,-884.815063,294.500488,0.000000
116.010002,65.210991,-884.815063,-0.001686,0.004534,0.115159,290.072968,14.777021,1.151592,-884.815063,294.500488,0.000000
116.390007,65.211357,-884.815063,-0.001694,0.004535,0.115194,290.074615,14.777104,1.151940,-884.815063,294.500488,0.000000
116.770004,65.239662,-884.770569,-0.001690,0.004536,0.115220,290.200500,14.783519,1.152198,-884.770569,294.500488,0.000000
117.150009,65.269081,-884.770569,-0.001673,0.004537,0.115236,290.331360,14.790185,1.152364,-884.770569,294.500488,0.000000
117.530006,65.240410,-884.815063,-0.001664,0.004537,0.115236,290.203827,14.783688,1.152364,-884.815063,294.500488,0.000000
117.910004,65.212471,-884.904053,-0.001669,0.004537,0.115246,290.079559,14.777357,1.152455,-884.904053,294.500488,0.000000
118.290009,65.291039,-884.815063,-0.001686,0.004539,0.115297,290.429047,14.795160,1.152970,-884.815063,294.500488,0.000000
118.670006,65.267952,-884.859558,-0.001677,0.004539,0.115297,290.326355,14.789929,1.152970,-884.859558,294.500488,0.000000
119.050003,65.232948,-884.815063,-0.001677,0.004540,0.115315,290.170654,14.781998,1.153152,-884.815063,294.500488,0.000000
119.430008,65.251579,-884.859558,-0.001669,0.004541,0.115341,290.253510,14.786219,1.153409,-884.859558,294.500488,0.000000
119.810005,65.256050,-884.904053,-0.001677,0.004542,0.115358,290.273407,14.787232,1.153575,-884.904053,294.500488,0.000000
120.190002,65.252312,-884.904053,-0.001681,0.004542,0.115358,290.256775,14.786386,1.153575,-884.904053,294.500488,0.000000
120.570007,65.236687,-884.859558,-0.001694,0.004542,0.115376,290.187286,14.782845,1.153757,-884.859558,294.500488,0.000000
120.950005,65.263115,-884.859558,-0.001669,0.004543,0.115401,290.304840,14.788833,1.154014,-884.859558,294.500488,0.000000
121.330009,65.257164,-884.948547,-0.001681,0.004544,0.115411,290.278351,14.787484,1.154105,-884.948547,294.500488,0.000000
121.710007,65.253441,-884.904053,-0.001677,0.004544,0.115427,290.261810,14.786641,1.154272,-884.904053,294.500488,0.000000
122.090004,65.257530,-884.992981,-0.001664,0.004545,0.115436,290.279999,14.787567,1.154363,-884.992981,294.500488,0.000000
122.470009,65.245613,-884.992981,-0.001681,0.004545,0.115436,290.226990,14.784867,1.154363,-884.992981,294.500488,0.000000
122.850006,65.217323,-884.859558,-0.001673,0.004546,0.115471,290.101135,14.778457,1.154711,-884.859558,294.500488,0.000000
123.230003,65.221046,-884.948547,-0.001669,0.004546,0.115471,290.117706,14.779301,1.154711,-884.948547,294.500488,0.000000
123.610008,65.222908,-884.948547,-0.001669,0.004547,0.115488,290.125977,14.779722,1.154877,-884.948547,294.500488,0.000000
123.990005,65.215080,-884.948547,-0.001669,0.004547,0.115488,290.091156,14.777948,1.154877,-884.948547,294.500488,0.000000
124.370003,65.202049,-885.037476,-0.001673,0.004548,0.115523,290.033203,14.774996,1.155226,-885.037476,294.500488,0.000000
124.750008,65.188637,-884.948547,-0.001656,0.004548,0.115523,289.973541,14.771956,1.155226,-884.948547,294.500488,0.000000
125.130005,65.150658,-885.037476,-0.001673,0.004548,0.115523,289.804596,14.763350,1.155226,-885.037476,294.500488,0.000000
125.510010,65.098900,-884.992981,-0.001669,0.004548,0.115523,289.574371,14.751621,1.155226,-884.992981,294.500488,0.000000
125.890007,65.070976,-885.081970,-0.001677,0.004548,0.115523,289.450165,14.745294,1.155226,-885.081970,294.500488,0.000000
126.270004,65.081032,-884.992981,-0.001669,0.004549,0.115548,289.494873,14.747572,1.155483,-884.992981,294.500488,0.000000
126.650009,65.057945,-885.081970,-0.001669,0.004549,0.115548,289.392181,14.742341,1.155483,-885.081970,294.500488,0.000000
127.030006,65.023308,-884.948547,-0.001669,0.004549,0.115548,289.238129,14.734492,1.155483,-884.948547,294.500488,0.000000
127.410004,65.031136,-885.081970,-0.001669,0.004549,0.115548,289.272949,14.736266,1.155483,-885.081970,294.500488,0.000000
127.790009,64.991661,-885.126465,-0.001669,0.004549,0.115548,289.097351,14.727321,1.155483,-885.126465,294.500488,0.000000
128.170013,64.954048,-885.126465,-0.001669,0.004549,0.115548,288.930023,14.718798,1.155483,-885.126465,294.500488,0.000000
128.550003,64.903038,-885.081970,-0.001647,0.004549,0.115548,288.703125,14.707239,1.155483,-885.081970,294.500488,0.000000
128.930008,64.847923,-884.992981,-0.001656,0.004549,0.115548,288.457977,14.694750,1.155483,-884.992981,294.500488,0.000000
129.310013,65.677940,-885.081970,-0.001656,0.004560,0.115818,292.150055,14.882834,1.158178,-885.081970,294.500488,0.000000
129.690002,65.751305,-885.081970,-0.001660,0.004560,0.115818,292.476410,14.899459,1.158178,-885.081970,294.500488,0.000000
130.070007,65.678688,-885.126465,-0.001664,0.004560,0.115818,292.153381,14.883003,1.158178,-885.126465,294.500488,0.000000
130.450012,65.663795,-885.081970,-0.001660,0.004560,0.115818,292.087158,14.879629,1.158178,-885.081970,294.500488,0.000000
130.830002,65.661552,-884.992981,-0.001669,0.004560,0.115818,292.077179,14.879121,1.158178,-884.992981,294.500488,0.000000
131.210007,65.617622,-885.081970,-0.001647,0.004560,0.115818,291.881775,14.869165,1.158178,-885.081970,294.500488,0.000000
131.590012,65.594902,-885.126465,-0.001673,0.004560,0.115818,291.780701,14.864017,1.158178,-885.126465,294.500488,0.000000
131.970001,65.581871,-885.170898,-0.001673,0.004560,0.115818,291.722717,14.861064,1.158178,-885.170898,294.500488,0.000000
132.350006,65.551704,-885.170898,-0.001656,0.004560,0.115818,291.588531,14.854228,1.158178,-885.170898,294.500488,0.000000
132.730011,65.515953,-885.170898,-0.001660,0.004560,0.115818,291.429504,14.846127,1.158178,-885.170898,294.500488,0.000000
133.110001,65.482445,-885.126465,-0.001664,0.004560,0.115818,291.280457,14.838534,1.158178,-885.126465,294.500488,0.000000
133.490005,65.454887,-885.170898,-0.001660,0.004560,0.115818,291.157867,14.832290,1.158178,-885.170898,294.500488,0.000000
133.870010,65.402382,-885.170898,-0.001647,0.004560,0.115818,290.924316,14.820392,1.158178,-885.170898,294.500488,0.000000
134.250000,65.366631,-885.215393,-0.001651,0.004560,0.115818,290.765289,14.812291,1.158178,-885.215393,294.500488,0.000000
134.630005,65.322701,-885.215393,-0.001647,0.004560,0.115818,290.569885,14.802335,1.158178,-885.215393,294.500488,0.000000
135.010010,65.297005,-885.170898,-0.001647,0.004560,0.115818,290.455597,14.796514,1.158178,-885.170898,294.500488,0.000000
135.389999,65.262367,-885.215393,-0.001634,0.004560,0.115818,290.301514,14.788664,1.158178,-885.215393,294.500488,0.000000
135.770004,65.246361,-885.259888,-0.001651,0.004560,0.115818,290.230316,14.785036,1.158178,-885.259888,294.500488,0.000000
136.150009,65.212105,-885.215393,-0.001660,0.004560,0.115818,290.077942,14.777274,1.158178,-885.215393,294.500488,0.000000
136.530014,65.183800,-885.170898,-0.001656,0.004560,0.115818,289.952026,14.770861,1.158178,-885.170898,294.500488,0.000000
136.910004,65.136147,-885.215393,-0.001656,0.004560,0.115818,289.740051,14.760061,1.158178,-885.215393,294.500488,0.000000
137.290009,65.113792,-885.259888,-0.001647,0.004560,0.115818,289.640625,14.754995,1.158178,-885.259888,294.500488,0.000000
137.670013,65.070595,-885.215393,-0.001638,0.004555,0.115706,289.448456,14.745208,1.157058,-885.215393,0.115748,0.000000
138.050003,64.952934,-885.215393,-0.001664,0.004543,0.115385,288.925079,14.718545,1.153848,-885.215393,0.115115,0.000000
138.430008,64.916435,-885.215393,-0.001643,0.004525,0.114934,288.762726,14.710275,1.149336,-885.215393,0.114482,0.000000
138.810013,64.888878,-885.215393,-0.001647,0.004498,0.114248,288.640137,14.704030,1.142478,-885.215393,0.113850,0.000000
139.190002,64.812172,-885.259888,-0.001643,0.004477,0.113719,288.298950,14.686648,1.137194,-885.259888,0.113217,0.000000
139.570007,64.771217,-885.215393,-0.001647,0.004457,0.113199,288.116760,14.677368,1.131986,-885.215393,0.112582,0.000000
139.950012,64.739555,-885.304382,-0.001638,0.004431,0.112549,287.975922,14.670193,1.125491,-885.304382,0.111950,0.000000
140.330002,64.676262,-885.259888,-0.001630,0.004407,0.111942,287.694366,14.655850,1.119421,-885.259888,0.111308,0.000000
140.710007,64.600670,-885.259888,-0.001643,0.004387,0.111430,287.358124,14.638721,1.114303,-885.259888,0.110675,0.000000
141.090012,64.557106,-885.259888,-0.001638,0.004354,0.110598,287.164337,14.628849,1.105977,-885.259888,0.110042,0.000000
141.470001,64.486351,-885.259888,-0.001647,0.004338,0.110189,286.849609,14.612816,1.101889,-885.259888,0.109409,0.000000
141.850006,64.189201,-885.304382,-0.001638,0.004318,0.109677,285.527832,14.545482,1.096772,-885.304382,0.108776,0.000000
142.230011,63.373695,-885.304382,-0.001638,0.004290,0.108958,281.900269,14.360685,1.089580,-885.304382,0.108144,0.000000
142.610001,62.513519,-885.259888,-0.001625,0.004271,0.108490,278.074036,14.165766,1.084902,-885.259888,0.107509,0.000000
142.990005,61.334587,-885.259888,-0.001638,0.004245,0.107830,272.829865,13.898617,1.078301,-885.259888,0.106876,0.000000
143.370010,59.473473,-885.304382,-0.001617,0.004216,0.107076,264.551208,13.476881,1.070762,-885.304382,0.106244,0.000000
143.750000,57.986214,-885.348877,-0.001630,0.004199,0.106660,257.935547,13.139864,1.066599,-885.348877,0.105611,0.000000
144.130005,56.343681,-885.393311,-0.001630,0.004179,0.106139,250.629211,12.767660,1.061391,-885.393311,0.104978,0.000000
144.510010,53.845802,-885.348877,-0.001643,0.004148,0.105350,239.518097,12.201633,1.053503,-885.348877,0.104345,0.000000
144.889999,51.594444,-885.304382,-0.001634,0.004126,0.104804,229.503555,11.691468,1.048037,-885.304382,0.103711,0.000000
145.270004,48.761803,-885.348877,-0.001634,0.004099,0.104110,216.903336,11.049582,1.041103,-885.348877,0.103078,0.000000
145.650009,46.252014,-885.393311,-0.001630,0.004075,0.103494,205.739227,10.480857,1.034942,-885.393311,0.102445,0.000000
146.030014,43.770897,-885.437805,-0.001638,0.004056,0.103017,194.702667,9.918627,1.030173,-885.437805,0.101812,0.000000
146.410004,40.850380,-885.393311,-0.001634,0.004026,0.102263,181.711563,9.256828,1.022633,-885.393311,0.101179,0.000000
146.790009,38.413200,-885.393311,-0.001634,0.004007,0.101768,170.870453,8.704556,1.017683,-885.393311,0.100546,0.000000
147.170013,34.903961,-885.482300,-0.001630,0.003973,0.100902,155.260574,7.909351,1.009023,-885.482300,0.099914,0.000000
147.550003,33.095726,-885.482300,-0.001634,0.003957,0.100503,147.217148,7.499599,1.005026,-885.482300,0.099279,0.000000
147.930008,30.009499,-885.526794,-0.001651,0.003928,0.099783,133.488922,6.800250,0.997835,-885.526794,0.098646,0.000000
148.310013,28.016937,-885.393311,-0.001638,0.003902,0.099123,124.625565,6.348729,0.991234,-885.393311,0.098014,0.000000
148.690002,24.559830,-885.437805,-0.001634,0.003873,0.098369,109.247581,5.565337,0.983694,-885.437805,0.097381,0.000000
149.070007,21.319817,-885.437805,-0.001638,0.003848,0.097744,94.835281,4.831139,0.977442,-885.437805,0.096748,0.000000
149.450012,19.285545,-885.482300,-0.001647,0.003829,0.097260,85.786392,4.370167,0.972597,-885.482300,0.096115,0.000000
149.830002,16.397797,-885.571228,-0.001647,0.003804,0.096627,72.941040,3.715794,0.966269,-885.571228,0.095481,0.000000
150.210007,13.758423,-885.526794,-0.001664,0.003779,0.095976,61.200520,3.117703,0.959759,-885.526794,0.094848,0.000000
150.590012,10.579102,-885.437805,-0.001664,0.003748,0.095187,47.058193,2.397259,0.951871,-885.437805,0.094215,0.000000
150.970001,7.970634,-885.526794,-0.001656,0.003723,0.094553,35.455154,1.806172,0.945527,-885.526794,0.093573,0.000000
151.350006,5.970993,-885.615723,-0.001669,0.003703,0.094068,26.560303,1.353046,0.940683,-885.615723,0.092940,0.000000
151.730011,3.390083,-885.615723,-0.001669,0.003679,0.093443,15.079844,0.768204,0.934430,-885.615723,0.092308,0.000000
152.110001,1.432892,-885.571228,-0.001664,0.003660,0.092966,6.373821,0.324698,0.929661,-885.571228,0.091675,0.000000
152.490005,-1.008011,-885.571228,-0.001673,0.003629,0.092168,-4.483856,-0.228419,0.921682,-885.571228,0.091042,0.000000
152.870010,-0.519081,-885.615723,-0.001716,0.003594,0.091293,-2.308988,-0.117625,0.912932,-885.615723,0.090408,0.000000
153.250000,-0.240921,-885.571228,-0.001703,0.003577,0.090859,-1.071670,-0.054593,0.908587,-885.571228,0.089775,0.000000
153.630005,-0.231239,-885.615723,-0.001725,0.003551,0.090191,-1.028604,-0.052400,0.901910,-885.615723,0.089142,0.000000
154.010010,-0.007820,-885.704712,-0.001750,0.003531,0.089688,-0.034786,-0.001772,0.896884,-885.704712,0.088509,0.000000
154.390015,-0.006325,-885.615723,-0.001772,0.003504,0.089003,-0.028134,-0.001433,0.890026,-885.615723,0.087876,0.000000
154.770004,-0.061066,-885.660217,-0.001789,0.003476,0.088293,-0.271634,-0.013838,0.882925,-885.660217,0.087243,0.000000
155.150009,-0.033882,-885.660217,-0.001789,0.003452,0.087685,-0.150715,-0.007678,0.876854,-885.660217,0.086609,0.000000
155.530014,-0.002602,-885.660217,-0.001819,0.003425,0.087000,-0.011573,-0.000590,0.869996,-885.660217,0.085976,0.000000
155.910004,0.013779,-885.704712,-0.001828,0.003402,0.086402,0.061291,0.003122,0.864016,-885.704712,0.085343,0.000000
156.290009,0.002609,-885.704712,-0.001854,0.003377,0.085769,0.011607,0.000591,0.857687,-885.704712,0.084710,0.000000
156.670013,-0.029411,-885.660217,-0.001876,0.003351,0.085109,-0.130828,-0.006665,0.851087,-885.660217,0.084078,0.000000
157.050003,0.021225,-885.660217,-0.001884,0.003336,0.084745,0.094413,0.004810,0.847453,-885.660217,0.084536,0.000000
157.100006,0.035004,-885.660217,-0.001897,0.003336,0.084745,0.155704,0.007932,0.847453,-885.660217,0.084536,0.000000