File: Data/compression 35/ManualNoHeating-17-35-reverse-1-2_11182024_180726.csv
Time (sec),S:Load (lbs),S:HL1 (DIM),S:LVDT (in),S:Position (in),Ch:Position (mm),Ch:Load (N),Ch:Stress (MPa),Ch:Strain (mm/mm),Ch:HL1 (DIM),Set Point (),Cycles ()
0.110000,0.005592,-891.620667,-0.012684,-0.007577,-0.192447,0.024876,0.001267,-1.924468,-891.620667,-0.192230,0.000000
0.480000,0.016014,-891.620667,-0.012697,-0.007533,-0.191328,0.071234,0.003629,-1.913280,-891.620667,-0.190565,0.000000
0.850000,-0.002602,-891.620667,-0.012594,-0.007312,-0.185717,-0.011573,-0.000590,-1.857172,-891.620667,-0.184389,0.000000
1.220000,0.004097,-891.709656,-0.012340,-0.007070,-0.179568,0.018224,0.000928,-1.795675,-891.709656,-0.178232,0.000000
1.590000,-0.016006,-891.665161,-0.012102,-0.006828,-0.173419,-0.071200,-0.003627,-1.734193,-891.665161,-0.172058,0.000000
1.960000,-0.036118,-891.620667,-0.011848,-0.006593,-0.167462,-0.160659,-0.008184,-1.674619,-891.620667,-0.165901,0.000000
2.330000,-0.034996,-891.620667,-0.011598,-0.006352,-0.161339,-0.155670,-0.007930,-1.613395,-891.620667,-0.159744,0.000000
2.700000,-0.016380,-891.665161,-0.011344,-0.006100,-0.154938,-0.072863,-0.003712,-1.549385,-891.665161,-0.153568,0.000000
3.070000,-0.036118,-891.754089,-0.011098,-0.005861,-0.148860,-0.160659,-0.008184,-1.488599,-891.754089,-0.147411,0.000000
3.440000,-0.076706,-891.709656,-0.010826,-0.005611,-0.142512,-0.341205,-0.017382,-1.425119,-891.709656,-0.141237,0.000000
3.810000,-0.094208,-891.665161,-0.010606,-0.005367,-0.136329,-0.419057,-0.021348,-1.363289,-891.665161,-0.135080,0.000000
4.180000,0.008942,-891.665161,-0.010343,-0.005133,-0.130370,0.039774,0.002026,-1.303699,-891.665161,-0.128923,0.000000
4.550000,0.027557,-891.754089,-0.010080,-0.004877,-0.123875,0.122581,0.006245,-1.238751,-891.754089,-0.122747,0.000000
4.920000,0.033890,-891.798584,-0.009839,-0.004645,-0.117995,0.150749,0.007680,-1.179949,-891.798584,-0.116590,0.000000
5.290000,-0.000366,-891.798584,-0.009593,-0.004401,-0.111777,-0.001629,-0.000083,-1.117770,-891.798584,-0.110416,0.000000
5.660000,-0.008934,-891.798584,-0.009330,-0.004156,-0.105550,-0.039741,-0.002024,-1.055501,-891.798584,-0.104259,0.000000
6.030000,-0.065163,-891.754089,-0.009119,-0.003925,-0.099705,-0.289858,-0.014766,-0.997047,-891.754089,-0.098101,0.000000
6.400000,-0.014519,-891.798584,-0.008864,-0.003677,-0.093392,-0.064583,-0.003290,-0.933915,-891.798584,-0.091926,0.000000
6.770000,-0.001862,-891.798584,-0.008580,-0.003418,-0.086818,-0.008281,-0.000422,-0.868179,-891.798584,-0.085769,0.000000
7.140000,-0.002602,-891.798584,-0.008338,-0.003194,-0.081121,-0.011573,-0.000590,-0.811209,-891.798584,-0.079611,0.000000
7.510000,-0.023087,-891.843079,-0.008084,-0.002945,-0.074799,-0.102694,-0.005231,-0.747986,-891.843079,-0.073438,0.000000
7.880001,-0.033134,-891.843079,-0.007851,-0.002705,-0.068702,-0.147389,-0.007508,-0.687019,-891.843079,-0.067280,0.000000
8.250000,-0.006325,-891.887573,-0.007588,-0.002454,-0.062319,-0.028134,-0.001433,-0.623191,-891.887573,-0.061105,0.000000
8.620001,0.010429,-891.843079,-0.007338,-0.002217,-0.056309,0.046392,0.002363,-0.563086,-891.843079,-0.054948,0.000000
8.990001,0.058464,-891.843079,-0.007088,-0.001975,-0.050170,0.260061,0.013248,-0.501695,-891.843079,-0.048790,0.000000
9.360001,0.021225,-891.843079,-0.006829,-0.001728,-0.043899,0.094413,0.004810,-0.438987,-891.843079,-0.042616,0.000000
9.730000,-0.000366,-891.843079,-0.006597,-0.001490,-0.037855,-0.001629,-0.000083,-0.378550,-891.843079,-0.036459,0.000000
10.100000,-0.017502,-891.887573,-0.006338,-0.001248,-0.031707,-0.077852,-0.003966,-0.317068,-891.887573,-0.030284,0.000000
10.470000,-0.059204,-891.887573,-0.006084,-0.001014,-0.025757,-0.263353,-0.013416,-0.257570,-891.887573,-0.024126,0.000000
10.840000,-0.010422,-891.887573,-0.005833,-0.000769,-0.019530,-0.046358,-0.002362,-0.195301,-891.887573,-0.017969,0.000000
11.210001,-0.009308,-891.932007,-0.005588,-0.000522,-0.013252,-0.041403,-0.002109,-0.132517,-891.932007,-0.011795,0.000000
11.580001,-0.014893,-891.887573,-0.005338,-0.000276,-0.007008,-0.066245,-0.003375,-0.070081,-891.887573,-0.005638,0.000000
11.950001,0.145226,-891.976501,-0.005109,-0.000008,-0.000200,0.645995,0.032909,-0.001998,-891.976501,-0.000018,0.000000
12.320001,0.135918,-891.887573,-0.005113,-0.000009,-0.000216,0.604592,0.030799,-0.002165,-891.887573,-0.000018,0.000000
12.690001,0.134056,-891.932007,-0.005109,-0.000008,-0.000209,0.596311,0.030378,-0.002089,-891.932007,0.000398,0.000000
13.060000,0.128471,-891.932007,-0.005113,-0.000006,-0.000165,0.571469,0.029112,-0.001650,-891.932007,0.001014,0.000000
13.430000,0.153046,-891.976501,-0.005113,0.000014,0.000365,0.680781,0.034681,0.003649,-891.976501,0.001640,0.000000
13.800000,0.250610,-891.976501,-0.005057,0.000051,0.001291,1.114771,0.056789,0.012914,-891.976501,0.002254,0.000000
14.170001,0.376099,-892.020996,-0.005036,0.000072,0.001838,1.672970,0.085225,0.018379,-892.020996,0.002870,0.000000
14.540001,0.553352,-891.932007,-0.005014,0.000096,0.002437,2.461434,0.125391,0.024375,-891.932007,0.003487,0.000000
14.910001,0.645699,-891.976501,-0.005006,0.000116,0.002940,2.872211,0.146317,0.029401,-891.976501,0.004101,0.000000
15.280001,0.822205,-892.065491,-0.004988,0.000138,0.003512,3.657349,0.186314,0.035124,-892.065491,0.004717,0.000000
15.650001,0.967430,-892.020996,-0.004958,0.000157,0.003989,4.303344,0.219223,0.039893,-892.020996,0.005334,0.000000
16.020000,1.124565,-892.065491,-0.004928,0.000181,0.004596,5.002316,0.254830,0.045964,-892.065491,0.005948,0.000000
16.390001,1.469383,-891.976501,-0.004915,0.000215,0.005455,6.536143,0.332967,0.054548,-891.976501,0.006565,0.000000
16.760000,1.751274,-892.065491,-0.004885,0.000239,0.006062,7.790056,0.396844,0.060619,-892.065491,0.007190,0.000000
17.130001,1.986237,-892.065491,-0.004859,0.000260,0.006608,8.835221,0.450088,0.066084,-892.065491,0.007804,0.000000
17.500000,2.330681,-891.932007,-0.004829,0.000289,0.007346,10.367386,0.528140,0.073457,-891.932007,0.008421,0.000000
17.870001,2.393616,-892.020996,-0.004807,0.000300,0.007614,10.647334,0.542401,0.076137,-892.020996,0.009037,0.000000
18.240002,2.623741,-891.976501,-0.004803,0.000318,0.008065,11.670983,0.594548,0.080649,-891.976501,0.009651,0.000000
18.610001,3.628403,-892.065491,-0.004764,0.000360,0.009140,16.139942,0.822208,0.091398,-892.065491,0.010268,0.000000
18.980001,4.331070,-892.109924,-0.004734,0.000395,0.010033,19.265562,0.981435,0.100330,-892.109924,0.010884,0.000000
19.350000,4.313568,-892.065491,-0.004730,0.000405,0.010293,19.187710,0.977468,0.102934,-892.065491,0.011500,0.000000
19.720001,4.649818,-892.020996,-0.004700,0.000425,0.010788,20.683426,1.053664,0.107885,-892.020996,0.012115,0.000000
20.090000,4.970062,-892.020996,-0.004691,0.000441,0.011196,22.107941,1.126232,0.111957,-892.020996,0.012740,0.000000
20.460001,6.158669,-892.020996,-0.004665,0.000480,0.012184,27.395126,1.395574,0.121843,-892.020996,0.013355,0.000000
20.830002,6.333313,-892.154419,-0.004656,0.000498,0.012652,28.171984,1.435149,0.126521,-892.154419,0.013971,0.000000
21.200001,6.720581,-892.109924,-0.004635,0.000522,0.013252,29.894638,1.522905,0.132517,-892.109924,0.014587,0.000000
21.570002,7.417664,-892.109924,-0.004605,0.000550,0.013962,32.995415,1.680867,0.139617,-892.109924,0.015202,0.000000
21.940001,7.851852,-892.020996,-0.004596,0.000573,0.014561,34.926785,1.779255,0.145612,-892.020996,0.015818,0.000000
22.310001,8.204117,-892.109924,-0.004562,0.000594,0.015090,36.493732,1.859079,0.150896,-892.109924,0.016434,0.000000
22.680000,8.996895,-892.109924,-0.004536,0.000629,0.015966,40.020187,2.038725,0.159662,-892.109924,0.017050,0.000000
23.050001,9.272453,-892.020996,-0.004506,0.000646,0.016416,41.245934,2.101168,0.164158,-892.020996,0.017665,0.000000
23.420002,9.536087,-892.154419,-0.004493,0.000670,0.017023,42.418633,2.160908,0.170229,-892.154419,0.018290,0.000000
23.790001,10.136353,-892.065491,-0.004475,0.000692,0.017588,45.088749,2.296930,0.175876,-892.065491,0.018905,0.000000
24.160002,10.435371,-892.154419,-0.004467,0.000718,0.018246,46.418850,2.364689,0.182462,-892.154419,0.019521,0.000000
24.530001,11.618027,-892.109924,-0.004432,0.000757,0.019218,51.679565,2.632683,0.192182,-892.109924,0.020137,0.000000
24.900002,11.399445,-892.198914,-0.004389,0.000768,0.019495,50.707260,2.583151,0.194952,-892.198914,0.020753,0.000000
25.270000,12.235420,-892.109924,-0.004376,0.000805,0.020440,54.425869,2.772586,0.204399,-892.109924,0.021368,0.000000
25.640001,12.596245,-892.154419,-0.004363,0.000829,0.021047,56.030895,2.854350,0.210470,-892.154419,0.021984,0.000000
26.010002,12.985748,-892.198914,-0.004320,0.000853,0.021663,57.763493,2.942613,0.216632,-892.198914,0.022600,0.000000
26.380001,13.307106,-892.198914,-0.004303,0.000873,0.022166,59.192963,3.015433,0.221659,-892.198914,0.023224,0.000000
26.750002,13.349930,-892.243408,-0.004294,0.000886,0.022513,59.383453,3.025137,0.225126,-892.243408,0.023840,0.000000
27.120001,13.673523,-892.198914,-0.004281,0.000910,0.023120,60.822868,3.098464,0.231197,-892.198914,0.024455,0.000000
27.490002,14.357567,-892.198914,-0.004255,0.000934,0.023736,63.865646,3.253471,0.237358,-892.198914,0.025071,0.000000
27.860001,15.111252,-892.198914,-0.004234,0.000965,0.024508,67.218208,3.424259,0.245080,-892.198914,0.025687,0.000000
28.230001,15.609482,-892.243408,-0.004212,0.000993,0.025210,69.434441,3.537159,0.252104,-892.243408,0.026304,0.000000
28.600002,15.826576,-892.198914,-0.004178,0.001013,0.025722,70.400124,3.586354,0.257221,-892.198914,0.026918,0.000000
28.970001,15.902542,-892.243408,-0.004174,0.001030,0.026164,70.738037,3.603568,0.261642,-892.243408,0.027534,0.000000
29.340002,16.229485,-892.243408,-0.004161,0.001053,0.026746,72.192352,3.677654,0.267456,-892.243408,0.028151,0.000000
29.710001,16.330772,-892.243408,-0.004135,0.001079,0.027404,72.642906,3.700606,0.274042,-892.243408,0.028774,0.000000
30.080002,17.656792,-892.287903,-0.004105,0.001113,0.028263,78.541328,4.001086,0.282626,-892.287903,0.029390,0.000000
30.450001,17.694397,-892.332336,-0.004070,0.001137,0.028879,78.708611,4.009608,0.288787,-892.332336,0.030007,0.000000
30.820002,17.745415,-892.287903,-0.004049,0.001153,0.029286,78.935547,4.021168,0.292860,-892.287903,0.030621,0.000000
31.190001,18.459999,-892.332336,-0.004036,0.001186,0.030128,82.114174,4.183095,0.301278,-892.332336,0.031237,0.000000
31.560001,18.242157,-892.376831,-0.004018,0.001197,0.030414,81.145164,4.133732,0.304139,-892.376831,0.031854,0.000000
31.930002,18.841309,-892.376831,-0.004014,0.001222,0.031047,83.810326,4.269502,0.310467,-892.376831,0.032468,0.000000
32.300003,19.893631,-892.332336,-0.003971,0.001258,0.031966,88.491287,4.507961,0.319657,-892.332336,0.033085,0.000000
32.670002,19.801285,-892.332336,-0.003949,0.001278,0.032461,88.080513,4.487035,0.324608,-892.332336,0.033701,0.000000
33.040001,19.796814,-892.332336,-0.003932,0.001296,0.032929,88.060623,4.486022,0.329286,-892.332336,0.034324,0.000000
33.410000,20.744873,-892.376831,-0.003885,0.001335,0.033899,92.277802,4.700855,0.338990,-892.376831,0.034941,0.000000
33.780003,20.270844,-892.332336,-0.003872,0.001346,0.034178,90.169212,4.593439,0.341776,-892.332336,0.035557,0.000000
34.150002,21.258003,-892.376831,-0.003850,0.001380,0.035053,94.560318,4.817132,0.350527,-892.376831,0.036171,0.000000
34.520000,21.144432,-892.287903,-0.003829,0.001400,0.035557,94.055130,4.791397,0.355568,-892.287903,0.036788,0.000000
34.890003,21.193954,-892.332336,-0.003820,0.001423,0.036155,94.275421,4.802619,0.361548,-892.332336,0.037404,0.000000
35.260002,22.472305,-892.376831,-0.003786,0.001460,0.037074,99.961807,5.092297,0.370738,-892.376831,0.038019,0.000000
35.630001,21.988968,-892.465820,-0.003751,0.001471,0.037360,97.811813,4.982771,0.373599,-892.465820,0.038635,0.000000
36.000000,22.831650,-892.376831,-0.003729,0.001505,0.038218,101.560249,5.173726,0.382184,-892.376831,0.039251,0.000000
36.370003,23.021935,-892.332336,-0.003717,0.001528,0.038800,102.406677,5.216845,0.387997,-892.332336,0.039875,0.000000
36.740002,22.694244,-892.376831,-0.003699,0.001541,0.039137,100.949043,5.142589,0.391373,-892.376831,0.040491,0.000000
37.110001,22.952293,-892.421326,-0.003665,0.001564,0.039719,102.096901,5.201064,0.397187,-892.421326,0.041107,0.000000
37.480003,23.704491,-892.465820,-0.003656,0.001590,0.040395,105.442841,5.371515,0.403954,-892.465820,0.041722,0.000000
37.850002,24.763885,-892.376831,-0.003613,0.001622,0.041210,110.155266,5.611577,0.412099,-892.376831,0.042338,0.000000
38.220001,24.544189,-892.332336,-0.003613,0.001643,0.041722,109.178009,5.561793,0.417217,-892.332336,0.042954,0.000000
38.590000,24.289490,-892.421326,-0.003583,0.001659,0.042130,108.045044,5.504077,0.421304,-892.421326,0.043569,0.000000
38.960003,25.408096,-892.554749,-0.003548,0.001696,0.043066,113.020859,5.757557,0.430660,-892.554749,0.044185,0.000000
39.330002,24.666702,-892.421326,-0.003510,0.001706,0.043343,109.722969,5.589554,0.433431,-892.421326,0.044801,0.000000
39.700001,25.890312,-892.421326,-0.003518,0.001743,0.044280,115.165863,5.866829,0.442802,-892.421326,0.045425,0.000000
40.070004,26.242577,-892.376831,-0.003488,0.001766,0.044862,116.732811,5.946653,0.448616,-892.376831,0.046041,0.000000
40.440002,26.985466,-892.465820,-0.003445,0.001799,0.045685,120.037346,6.114994,0.456852,-892.465820,0.046657,0.000000
40.810001,26.482391,-892.465820,-0.003449,0.001814,0.046076,117.799561,6.000996,0.460758,-892.465820,0.047272,0.000000
41.180000,26.264549,-892.510254,-0.003423,0.001830,0.046492,116.830551,5.951632,0.464921,-892.510254,0.047888,0.000000
41.550003,26.812683,-892.465820,-0.003389,0.001857,0.047176,119.268768,6.075841,0.471764,-892.465820,0.048504,0.000000
41.920002,28.055664,-892.510254,-0.003372,0.001890,0.048002,124.797829,6.357504,0.480016,-892.510254,0.049119,0.000000
42.290001,27.996078,-892.510254,-0.003359,0.001913,0.048600,124.532776,6.344002,0.485996,-892.510254,0.049735,0.000000
42.660004,27.876923,-892.554749,-0.003328,0.001928,0.048981,124.002747,6.317001,0.489811,-892.554749,0.050351,0.000000
43.030003,28.047470,-892.554749,-0.003294,0.001953,0.049614,124.761375,6.355648,0.496139,-892.554749,0.050975,0.000000
43.400002,29.114319,-892.510254,-0.003290,0.001985,0.050428,129.506958,6.597399,0.504284,-892.510254,0.051591,0.000000
43.770000,29.692612,-892.554749,-0.003251,0.002013,0.051131,132.079330,6.728442,0.511309,-892.554749,0.052207,0.000000
44.140003,29.770065,-892.554749,-0.003221,0.002033,0.051635,132.423859,6.745993,0.516351,-892.554749,0.052822,0.000000
44.510002,29.853104,-892.554749,-0.003199,0.002056,0.052233,132.793243,6.764810,0.522331,-892.554749,0.053438,0.000000
44.880001,30.058281,-892.554749,-0.003178,0.002076,0.052719,133.705917,6.811304,0.527190,-892.554749,0.054054,0.000000
45.250004,30.330116,-892.510254,-0.003156,0.002099,0.053317,134.915100,6.872902,0.533171,-892.510254,0.054671,0.000000
45.620003,31.788322,-892.510254,-0.003139,0.002133,0.054185,141.401520,7.203337,0.541846,-892.510254,0.055285,0.000000
45.990002,32.754257,-892.599243,-0.003109,0.002164,0.054973,145.698212,7.422221,0.549733,-892.599243,0.055901,0.000000
46.360001,31.384674,-892.599243,-0.003096,0.002181,0.055399,139.606003,7.111869,0.553988,-892.599243,0.056525,0.000000
46.730003,32.927414,-892.554749,-0.003057,0.002211,0.056153,146.468445,7.461459,0.561527,-892.554749,0.057141,0.000000
47.100002,33.774933,-892.554749,-0.003044,0.002240,0.056907,150.238403,7.653509,0.569067,-892.554749,0.057757,0.000000
47.470001,33.304253,-892.599243,-0.003009,0.002256,0.057297,148.144714,7.546852,0.572973,-892.599243,0.058372,0.000000
47.840004,33.426018,-892.643738,-0.003005,0.002277,0.057827,148.686356,7.574444,0.578271,-892.643738,0.058988,0.000000
48.210003,33.601036,-892.643738,-0.002984,0.002296,0.058312,149.464874,7.614103,0.583116,-892.643738,0.059605,0.000000
48.580002,34.104851,-892.599243,-0.002953,0.002316,0.058816,151.705948,7.728270,0.588158,-892.599243,0.060221,0.000000
48.950001,35.639397,-892.599243,-0.002932,0.002351,0.059709,158.531952,8.076002,0.597090,-892.599243,0.060835,0.000000
49.320004,35.401451,-892.599243,-0.002919,0.002366,0.060098,157.473526,8.022083,0.600981,-892.599243,0.061461,0.000000
49.690002,36.174500,-892.643738,-0.002897,0.002391,0.060740,160.912216,8.197259,0.607400,-892.643738,0.062075,0.000000
50.060001,36.851097,-892.688232,-0.002876,0.002418,0.061408,163.921860,8.350578,0.614076,-892.688232,0.062691,0.000000
50.430004,37.294594,-892.688232,-0.002833,0.002438,0.061928,165.894638,8.451076,0.619285,-892.688232,0.063308,0.000000
50.800003,38.219193,-892.643738,-0.002833,0.002466,0.062631,170.007462,8.660593,0.626309,-892.643738,0.063924,0.000000
51.170002,38.588593,-892.643738,-0.002820,0.002484,0.063099,171.650635,8.744301,0.630987,-892.643738,0.064539,0.000000
51.540001,40.544662,-892.688232,-0.002781,0.002524,0.064106,180.351669,9.187552,0.641055,-892.688232,0.065155,0.000000
51.910004,40.759895,-892.732666,-0.002755,0.002543,0.064599,181.309067,9.236324,0.645991,-892.732666,0.065771,0.000000
52.280003,41.472610,-892.599243,-0.002751,0.002571,0.065302,184.479385,9.397828,0.653015,-892.599243,0.066386,0.000000
52.650002,41.645020,-892.643738,-0.002734,0.002588,0.065736,185.246292,9.436896,0.657361,-892.643738,0.067011,0.000000
53.020004,41.391434,-892.688232,-0.002699,0.002602,0.066092,184.118286,9.379433,0.660918,-892.688232,0.067625,0.000000
53.390003,41.788757,-892.688232,-0.002703,0.002621,0.066569,185.885681,9.469468,0.665687,-892.688232,0.068242,0.000000
53.760002,44.418823,-892.777161,-0.002677,0.002667,0.067730,197.584793,10.065449,0.677299,-892.777161,0.068858,0.000000
54.130001,43.993576,-892.688232,-0.002630,0.002677,0.067990,195.693207,9.969088,0.679903,-892.688232,0.069474,0.000000
54.500004,46.089287,-892.688232,-0.002634,0.002717,0.069023,205.015381,10.443982,0.690229,-892.688232,0.070089,0.000000
54.870003,46.954308,-892.732666,-0.002596,0.002742,0.069656,208.863190,10.639998,0.696557,-892.732666,0.070705,0.000000
55.240002,45.961189,-892.821655,-0.002583,0.002748,0.069812,204.445587,10.414954,0.698116,-892.821655,0.071321,0.000000
55.610004,47.849121,-892.777161,-0.002561,0.002783,0.070688,212.843521,10.842766,0.706882,-892.777161,0.071936,0.000000
55.980003,48.958046,-892.821655,-0.002535,0.002811,0.071398,217.776260,11.094051,0.713983,-892.821655,0.072561,0.000000
56.350002,50.002174,-892.732666,-0.002522,0.002839,0.072110,222.420776,11.330655,0.721098,-892.732666,0.073177,0.000000
56.720001,51.146103,-892.777161,-0.002505,0.002867,0.072821,227.509232,11.589872,0.728214,-892.777161,0.073792,0.000000
57.090004,50.900711,-892.821655,-0.002483,0.002880,0.073142,226.417664,11.534266,0.731423,-892.821655,0.074408,0.000000
57.460003,52.217796,-892.821655,-0.002458,0.002908,0.073871,232.276352,11.832722,0.738706,-892.821655,0.075024,0.000000
57.830002,52.708580,-892.777161,-0.002432,0.002930,0.074417,234.459473,11.943935,0.744171,-892.777161,0.075639,0.000000
58.200005,53.611954,-892.777161,-0.002427,0.002953,0.074997,238.477875,12.148643,0.749969,-892.777161,0.076255,0.000000
58.570004,53.883415,-892.777161,-0.002419,0.002973,0.075527,239.685394,12.210156,0.755268,-892.777161,0.076871,0.000000
58.940002,54.500435,-892.866150,-0.002384,0.002990,0.075943,242.430038,12.349976,0.759432,-892.866150,0.077486,0.000000
59.310001,57.201256,-892.821655,-0.002371,0.003031,0.076983,254.443893,12.961990,0.769832,-892.821655,0.078111,0.000000
59.680004,57.467125,-892.866150,-0.002345,0.003048,0.077418,255.626541,13.022237,0.774178,-892.866150,0.078727,0.000000
60.050003,59.348351,-892.821655,-0.002328,0.003080,0.078232,263.994659,13.448528,0.782323,-892.821655,0.079342,0.000000
60.420002,59.338669,-892.866150,-0.002311,0.003094,0.078579,263.951569,13.446335,0.785790,-892.866150,0.079958,0.000000
60.790005,59.696526,-892.910583,-0.002294,0.003113,0.079065,265.543396,13.527427,0.790649,-892.910583,0.080574,0.000000
61.160004,61.868195,-892.910583,-0.002276,0.003146,0.079914,275.203461,14.019534,0.799143,-892.910583,0.081189,0.000000
61.530003,62.384682,-892.821655,-0.002255,0.003163,0.080331,277.500916,14.136571,0.803306,-892.821655,0.081805,0.000000
61.900002,64.570137,-892.821655,-0.002220,0.003197,0.081198,287.222321,14.631803,0.811981,-892.821655,0.082421,0.000000
62.270004,65.051979,-892.910583,-0.002216,0.003218,0.081728,289.365662,14.740989,0.817280,-892.910583,0.083036,0.000000
62.640003,65.274666,-892.955078,-0.002199,0.003235,0.082161,290.356201,14.791451,0.821610,-892.955078,0.083661,0.000000
63.010002,66.290123,-892.955078,-0.002169,0.003246,0.082456,294.873199,15.021557,0.824562,-892.955078,0.014484,0.000000
63.380005,64.710518,-892.910583,-0.002160,0.003246,0.082438,287.846771,14.663613,0.824380,-892.910583,294.500488,0.000000
63.750004,65.826149,-892.866150,-0.002139,0.003239,0.082265,292.809326,14.916419,0.822654,-892.866150,294.500488,0.000000
64.120003,65.235558,-892.910583,-0.002134,0.003278,0.083271,290.182251,14.782589,0.832707,-892.910583,294.500488,0.000000
64.490005,65.271309,-892.999573,-0.002147,0.003288,0.083514,290.341278,14.790690,0.835145,-892.999573,294.500488,0.000000
64.860001,64.983101,-892.910583,-0.002121,0.003295,0.083696,289.059265,14.725381,0.836961,-892.910583,294.500488,0.000000
65.230003,64.792809,-892.910583,-0.002104,0.003305,0.083957,288.212799,14.682261,0.839565,-892.910583,294.500488,0.000000
65.600006,64.868034,-892.999573,-0.002108,0.003312,0.084129,288.547424,14.699306,0.841291,-892.999573,294.500488,0.000000
65.970001,65.271675,-892.955078,-0.002087,0.003326,0.084476,290.342926,14.790773,0.844758,-892.955078,294.500488,0.000000
66.340004,64.867653,-893.044067,-0.002091,0.003337,0.084762,288.545746,14.699220,0.847620,-893.044067,294.500488,0.000000
66.710007,64.735832,-892.999573,-0.002070,0.003336,0.084736,287.959351,14.669350,0.847362,-892.999573,294.500488,0.000000
67.080002,65.208748,-892.999573,-0.002070,0.003348,0.085048,290.062988,14.776513,0.850481,-892.999573,294.500488,0.000000
67.450005,64.456184,-892.955078,-0.002052,0.003349,0.085057,286.715424,14.605980,0.850572,-892.955078,294.500488,0.000000
67.820000,65.013252,-893.044067,-0.002044,0.003361,0.085369,289.193390,14.732214,0.853691,-893.044067,294.500488,0.000000
68.190002,65.223640,-893.088562,-0.002035,0.003381,0.085873,290.129242,14.779888,0.858732,-893.088562,294.500488,0.000000
68.560005,65.317116,-893.044067,-0.002018,0.003376,0.085760,290.545044,14.801069,0.857597,-893.044067,294.500488,0.000000
68.930000,64.703072,-892.955078,-0.002031,0.003376,0.085760,287.813629,14.661925,0.857597,-892.955078,294.500488,0.000000
69.300003,67.011406,-893.044067,-0.002013,0.003391,0.086125,298.081635,15.185002,0.861245,-893.044067,294.500488,0.000000
69.670006,66.054405,-893.044067,-0.002001,0.003343,0.084901,293.824677,14.968143,0.849012,-893.044067,294.500488,0.000000
70.040001,65.371101,-893.088562,-0.002005,0.003355,0.085222,290.785187,14.813304,0.852222,-893.088562,294.500488,0.000000
70.410004,64.937294,-893.088562,-0.001988,0.003390,0.086099,288.855499,14.715001,0.860988,-893.088562,294.500488,0.000000
70.780006,65.379295,-892.999573,-0.001983,0.003406,0.086514,290.821625,14.815161,0.865136,-892.999573,294.500488,0.000000
71.150002,64.837120,-893.088562,-0.001988,0.003406,0.086523,288.409912,14.692301,0.865227,-893.088562,294.500488,0.000000
71.520004,65.977333,-893.132996,-0.001979,0.003418,0.086809,293.481842,14.950677,0.868088,-893.132996,294.500488,0.000000
71.890007,65.406105,-893.044067,-0.001962,0.003418,0.086809,290.940887,14.821236,0.868088,-893.044067,294.500488,0.000000
72.260002,64.893349,-893.088562,-0.001970,0.003419,0.086835,288.660034,14.705043,0.868346,-893.088562,294.500488,0.000000
72.630005,65.628792,-893.044067,-0.001962,0.003435,0.087260,291.931458,14.871696,0.872600,-893.044067,294.500488,0.000000
73.000000,65.264977,-893.132996,-0.001966,0.003435,0.087260,290.313110,14.789255,0.872600,-893.132996,294.500488,0.000000
73.370003,64.835640,-893.177490,-0.001949,0.003436,0.087269,288.403320,14.691966,0.872691,-893.177490,294.500488,0.000000
73.740005,65.634743,-893.088562,-0.001940,0.003461,0.087919,291.957916,14.873045,0.879186,-893.088562,294.500488,0.000000
74.110001,65.928917,-893.132996,-0.001944,0.003448,0.087572,293.266479,14.939706,0.875719,-893.132996,294.500488,0.000000
74.480003,65.454521,-893.088562,-0.001940,0.003448,0.087572,291.156250,14.832207,0.875719,-893.088562,294.500488,0.000000
74.850006,65.001335,-893.132996,-0.001936,0.003448,0.087572,289.140381,14.729513,0.875719,-893.132996,294.500488,0.000000
75.220001,65.533836,-893.221985,-0.001932,0.003463,0.087953,291.509064,14.850180,0.879534,-893.221985,294.500488,0.000000
75.590004,65.200935,-893.132996,-0.001919,0.003463,0.087953,290.028259,14.774743,0.879534,-893.132996,294.500488,0.000000
75.960007,64.836006,-893.177490,-0.001923,0.003463,0.087953,288.404968,14.692049,0.879534,-893.177490,294.500488,0.000000
76.330002,65.528618,-893.132996,-0.001923,0.003474,0.088240,291.485840,14.848997,0.882395,-893.132996,294.500488,0.000000
76.700005,65.227364,-893.310913,-0.001914,0.003474,0.088240,290.145813,14.780732,0.882395,-893.310913,294.500488,0.000000
77.070007,64.912712,-893.266479,-0.001901,0.003474,0.088249,288.746155,14.709432,0.882486,-893.266479,294.500488,0.000000
77.440002,64.558220,-893.221985,-0.001901,0.003474,0.088249,287.169312,14.629102,0.882486,-893.221985,294.500488,0.000000
77.810005,64.246162,-893.221985,-0.001910,0.003475,0.088258,285.781189,14.558389,0.882577,-893.221985,294.500488,0.000000
78.180000,65.969887,-893.266479,-0.001888,0.003484,0.088483,293.448700,14.948991,0.884833,-893.266479,294.500488,0.000000
78.550003,65.570320,-893.310913,-0.001893,0.003484,0.088483,291.671356,14.858447,0.884833,-893.310913,294.500488,0.000000
78.920006,65.200188,-893.266479,-0.001884,0.003485,0.088509,290.024933,14.774573,0.885090,-893.266479,294.500488,0.000000
79.290001,64.863197,-893.177490,-0.001880,0.003486,0.088535,288.525909,14.698210,0.885347,-893.177490,294.500488,0.000000
79.660004,65.092201,-893.221985,-0.001888,0.003499,0.088881,289.544586,14.750103,0.888814,-893.221985,294.500488,0.000000
80.030006,64.993523,-893.266479,-0.001884,0.003499,0.088881,289.105621,14.727742,0.888814,-893.266479,294.500488,0.000000
80.400002,64.849037,-893.266479,-0.001888,0.003501,0.088925,288.462921,14.695002,0.889253,-893.266479,294.500488,0.000000
80.770004,64.700096,-893.266479,-0.001867,0.003507,0.089081,287.800415,14.661251,0.890813,-893.266479,294.500488,0.000000
81.140007,65.492867,-893.221985,-0.001880,0.003512,0.089195,291.326813,14.840896,0.891948,-893.221985,294.500488,0.000000
81.510002,65.251198,-893.266479,-0.001867,0.003512,0.089195,290.251831,14.786133,0.891948,-893.266479,294.500488,0.000000
81.880005,65.000221,-893.310913,-0.001858,0.003512,0.089195,289.135437,14.729260,0.891948,-893.310913,294.500488,0.000000
82.250008,64.755196,-893.310913,-0.001863,0.003512,0.089202,288.045502,14.673737,0.892024,-893.310913,294.500488,0.000000
82.620003,64.513527,-893.266479,-0.001854,0.003512,0.089202,286.970490,14.618974,0.892024,-893.266479,294.500488,0.000000
82.990005,64.318413,-893.266479,-0.001850,0.003512,0.089211,286.102600,14.574761,0.892115,-893.266479,294.500488,0.000000
83.360001,66.269646,-893.266479,-0.001845,0.003507,0.089072,294.782104,15.016916,0.890722,-893.266479,294.500488,0.000000
83.730003,65.974724,-893.310913,-0.001841,0.003507,0.089072,293.470215,14.950087,0.890722,-893.310913,294.500488,0.000000
84.100006,65.743111,-893.310913,-0.001832,0.003507,0.089072,292.439972,14.897602,0.890722,-893.310913,294.500488,0.000000
84.470001,65.513359,-893.310913,-0.001850,0.003507,0.089081,291.417969,14.845539,0.890813,-893.310913,294.500488,0.000000
84.840004,65.238914,-893.310913,-0.001850,0.003507,0.089081,290.197174,14.783349,0.890813,-893.310913,294.500488,0.000000
85.210007,65.050117,-893.310913,-0.001841,0.003528,0.089610,289.357361,14.740567,0.896097,-893.310913,294.500488,0.000000
85.580002,65.341682,-893.399902,-0.001837,0.003535,0.089800,290.654327,14.806637,0.898004,-893.399902,294.500488,0.000000
85.950005,65.190498,-893.310913,-0.001832,0.003535,0.089800,289.981812,14.772378,0.898004,-893.310913,294.500488,0.000000
86.320007,65.060173,-893.399902,-0.001824,0.003537,0.089835,289.402100,14.742846,0.898352,-893.399902,294.500488,0.000000
86.690002,64.922020,-893.310913,-0.001832,0.003537,0.089835,288.787567,14.711540,0.898352,-893.310913,294.500488,0.000000
87.060005,65.863762,-893.310913,-0.001828,0.003548,0.090114,292.976654,14.924942,0.901138,-893.310913,294.500488,0.000000
87.430008,65.698799,-893.399902,-0.001837,0.003548,0.090114,292.242859,14.887561,0.901138,-893.399902,294.500488,0.000000
87.800003,65.518944,-893.399902,-0.001819,0.003548,0.090121,291.442810,14.846805,0.901214,-893.399902,294.500488,0.000000
88.170006,65.313393,-893.266479,-0.001815,0.003548,0.090121,290.528473,14.800226,0.901214,-893.266479,294.500488,0.000000
88.540001,65.123848,-893.266479,-0.001824,0.003548,0.090130,289.685333,14.757275,0.901305,-893.266479,294.500488,0.000000
88.910004,65.759865,-893.399902,-0.001828,0.003558,0.090382,292.514496,14.901399,0.903818,-893.399902,294.500488,0.000000
89.280006,65.629158,-893.444397,-0.001815,0.003558,0.090382,291.933075,14.871779,0.903818,-893.444397,294.500488,0.000000
89.650002,65.504036,-893.399902,-0.001819,0.003558,0.090382,291.376495,14.843427,0.903818,-893.399902,294.500488,0.000000
90.020004,65.338707,-893.399902,-0.001807,0.003558,0.090382,290.641083,14.805963,0.903818,-893.399902,294.500488,0.000000
90.390007,65.203163,-893.399902,-0.001815,0.003559,0.090391,290.038147,14.775248,0.903909,-893.399902,294.500488,0.000000
90.760002,65.041924,-893.399902,-0.001811,0.003559,0.090391,289.320923,14.738711,0.903909,-893.399902,294.500488,0.000000
91.130005,64.891121,-893.444397,-0.001815,0.003559,0.090408,288.650116,14.704538,0.904075,-893.444397,294.500488,0.000000
91.500008,64.737694,-893.399902,-0.001824,0.003559,0.090408,287.967651,14.669771,0.904075,-893.399902,294.500488,0.000000
91.870003,64.579063,-893.444397,-0.001798,0.003559,0.090408,287.262024,14.633824,0.904075,-893.444397,294.500488,0.000000
92.240005,64.423042,-893.399902,-0.001802,0.003559,0.090408,286.567993,14.598471,0.904075,-893.399902,294.500488,0.000000
92.610001,66.906395,-893.399902,-0.001785,0.003407,0.086548,297.614502,15.161205,0.865484,-893.399902,294.500488,0.000000
92.980003,66.678871,-893.488892,-0.001768,0.003403,0.086427,296.602448,15.109649,0.864273,-893.488892,294.500488,0.000000
93.350006,66.433479,-893.488892,-0.001772,0.003403,0.086427,295.510864,15.054042,0.864273,-893.488892,294.500488,0.000000
93.720001,66.287148,-893.488892,-0.001781,0.003403,0.086427,294.859955,15.020883,0.864273,-893.488892,294.500488,0.000000
94.090004,66.097237,-893.488892,-0.001772,0.003403,0.086427,294.015198,14.977848,0.864273,-893.488892,294.500488,0.000000
94.460007,65.876045,-893.533325,-0.001772,0.003404,0.086453,293.031281,14.927725,0.864531,-893.533325,294.500488,0.000000
94.830002,65.757622,-893.488892,-0.001776,0.003408,0.086558,292.504517,14.900890,0.865575,-893.488892,294.500488,0.000000
95.200005,65.601601,-893.533325,-0.001772,0.003437,0.087295,291.810486,14.865536,0.872948,-893.533325,294.500488,0.000000
95.570007,65.456383,-893.488892,-0.001768,0.003480,0.088397,291.164520,14.832628,0.883970,-893.488892,294.500488,0.000000
95.940002,65.389351,-893.488892,-0.001781,0.003559,0.090391,290.866364,14.817439,0.903909,-893.488892,294.500488,0.000000
96.310005,65.286583,-893.577820,-0.001776,0.003564,0.090538,290.409210,14.794151,0.905377,-893.577820,294.500488,0.000000
96.680008,65.109703,-893.533325,-0.001763,0.003564,0.090538,289.622437,14.754069,0.905377,-893.533325,294.500488,0.000000
97.050003,64.989418,-893.488892,-0.001772,0.003564,0.090538,289.087372,14.726813,0.905377,-893.488892,294.500488,0.000000
97.420006,64.825203,-893.533325,-0.001759,0.003564,0.090538,288.356903,14.689601,0.905377,-893.533325,294.500488,0.000000
97.790001,65.848854,-893.577820,-0.001759,0.003587,0.091102,292.910339,14.921564,0.911024,-893.577820,294.500488,0.000000
98.160004,65.771400,-893.577820,-0.001759,0.003587,0.091102,292.565796,14.904013,0.911024,-893.577820,294.500488,0.000000
98.530006,65.582619,-893.577820,-0.001755,0.003587,0.091102,291.726044,14.861234,0.911024,-893.577820,294.500488,0.000000
98.900002,65.467918,-893.622314,-0.001772,0.003587,0.091102,291.215851,14.835242,0.911024,-893.622314,294.500488,0.000000
99.270004,65.294029,-893.622314,-0.001772,0.003587,0.091110,290.442352,14.795838,0.911100,-893.622314,294.500488,0.000000
99.640007,65.170403,-893.622314,-0.001768,0.003587,0.091110,289.892426,14.767824,0.911100,-893.622314,294.500488,0.000000
100.010002,65.023689,-893.666809,-0.001755,0.003587,0.091110,289.239807,14.734578,0.911100,-893.666809,294.500488,0.000000
100.380005,64.888878,-893.577820,-0.001755,0.003587,0.091110,288.640137,14.704030,0.911100,-893.577820,294.500488,0.000000
100.750008,64.754082,-893.622314,-0.001772,0.003587,0.091110,288.040527,14.673485,0.911100,-893.622314,294.500488,0.000000
101.120003,64.658760,-893.622314,-0.001768,0.003588,0.091137,287.616516,14.651884,0.911372,-893.622314,294.500488,0.000000
101.490005,66.569771,-893.711243,-0.001759,0.003570,0.090677,296.117126,15.084926,0.906770,-893.711243,294.500488,0.000000
101.860008,66.399605,-893.711243,-0.001750,0.003570,0.090677,295.360199,15.046366,0.906770,-893.711243,294.500488,0.000000
102.230003,66.233894,-893.622314,-0.001750,0.003570,0.090677,294.623077,15.008816,0.906770,-893.622314,294.500488,0.000000
102.600006,66.104683,-893.666809,-0.001746,0.003570,0.090677,294.048309,14.979536,0.906770,-893.666809,294.500488,0.000000
102.970001,65.975838,-893.711243,-0.001742,0.003570,0.090686,293.475189,14.950338,0.906861,-893.711243,294.500488,0.000000
103.340004,65.860405,-893.711243,-0.001746,0.003570,0.090686,292.961700,14.924181,0.906861,-893.711243,294.500488,0.000000
103.710007,65.759865,-893.711243,-0.001720,0.003570,0.090686,292.514496,14.901399,0.906861,-893.711243,294.500488,0.000000
104.080002,65.585213,-893.666809,-0.001733,0.003571,0.090694,291.737610,14.861821,0.906937,-893.666809,294.500488,0.000000
104.450005,65.491386,-893.666809,-0.001746,0.003571,0.090694,291.320251,14.840561,0.906937,-893.666809,294.500488,0.000000
104.820007,65.340202,-893.755737,-0.001750,0.003571,0.090694,290.647736,14.806301,0.906937,-893.755737,294.500488,0.000000
105.190002,65.248589,-893.755737,-0.001742,0.003571,0.090694,290.240204,14.785542,0.906937,-893.755737,294.500488,0.000000
105.560005,65.293648,-893.711243,-0.001733,0.003605,0.091579,290.440643,14.795753,0.915793,-893.711243,294.500488,0.000000
105.930008,65.215080,-893.800232,-0.001746,0.003607,0.091614,290.091156,14.777948,0.916141,-893.800232,294.500488,0.000000
106.300003,65.224770,-893.755737,-0.001742,0.003609,0.091666,290.134277,14.780144,0.916656,-893.755737,294.500488,0.000000
106.670006,65.310402,-893.755737,-0.001733,0.003613,0.091779,290.515167,14.799548,0.917792,-893.755737,294.500488,0.000000
107.040009,65.342812,-893.800232,-0.001729,0.003613,0.091779,290.659332,14.806892,0.917792,-893.800232,294.500488,0.000000
107.410004,65.278389,-893.755737,-0.001733,0.003613,0.091779,290.372772,14.792295,0.917792,-893.755737,294.500488,0.000000
107.780006,65.223640,-893.711243,-0.001746,0.003614,0.091796,290.129242,14.779888,0.917958,-893.711243,294.500488,0.000000
108.150002,65.168541,-893.755737,-0.001746,0.003615,0.091822,289.884155,14.767403,0.918216,-893.755737,294.500488,0.000000
108.520004,65.470909,-893.800232,-0.001733,0.003623,0.092012,291.229156,14.835919,0.920123,-893.800232,294.500488,0.000000
108.890007,65.603096,-893.711243,-0.001725,0.003622,0.092003,291.817139,14.865874,0.920032,-893.711243,294.500488,0.000000
109.260002,65.573311,-893.711243,-0.001729,0.003622,0.092003,291.684662,14.859125,0.920032,-893.711243,294.500488,0.000000
109.630005,65.492867,-893.755737,-0.001742,0.003622,0.092003,291.326813,14.840896,0.920032,-893.755737,294.500488,0.000000
110.000008,65.395317,-893.844727,-0.001729,0.003622,0.092003,290.892914,14.818790,0.920032,-893.844727,294.500488,0.000000
110.370003,65.307426,-893.800232,-0.001738,0.003623,0.092012,290.501953,14.798875,0.920123,-893.800232,294.500488,0.000000
110.740005,65.255669,-893.755737,-0.001720,0.003623,0.092030,290.271698,14.787147,0.920305,-893.755737,294.500488,0.000000
111.110008,65.184914,-893.755737,-0.001729,0.003623,0.092030,289.956970,14.771112,0.920305,-893.755737,294.500488,0.000000
111.480003,65.410957,-893.844727,-0.001720,0.003628,0.092143,290.962463,14.822334,0.921425,-893.844727,294.500488,0.000000
111.850006,65.370369,-893.800232,-0.001733,0.003628,0.092143,290.781921,14.813137,0.921425,-893.800232,294.500488,0.000000
112.220009,65.298866,-893.889221,-0.001729,0.003628,0.092143,290.463867,14.796934,0.921425,-893.889221,294.500488,0.000000
112.590004,65.309669,-893.844727,-0.001716,0.003630,0.092194,290.511932,14.799383,0.921940,-893.844727,294.500488,0.000000
112.960007,65.287697,-893.800232,-0.001729,0.003630,0.092194,290.414185,14.794403,0.921940,-893.800232,294.500488,0.000000
113.330002,65.489143,-893.800232,-0.001738,0.003633,0.092282,291.310272,14.840053,0.922818,-893.800232,294.500488,0.000000
113.700005,65.473503,-893.800232,-0.001725,0.003633,0.092282,291.240692,14.836508,0.922818,-893.800232,294.500488,0.000000
114.070007,65.394936,-893.800232,-0.001725,0.003633,0.092282,290.891205,14.818705,0.922818,-893.800232,294.500488,0.000000
114.440002,65.384880,-893.844727,-0.001712,0.003635,0.092317,290.846466,14.816426,0.923166,-893.844727,294.500488,0.000000
114.810005,65.353233,-893.844727,-0.001716,0.003636,0.092342,290.705688,14.809255,0.923424,-893.844727,294.500488,0.000000
115.180008,65.420998,-893.933655,-0.001725,0.003637,0.092368,291.007141,14.824610,0.923681,-893.933655,294.500488,0.000000
115.550003,65.374825,-893.933655,-0.001716,0.003637,0.092377,290.801758,14.814147,0.923772,-893.933655,294.500488,0.000000
115.920006,65.372231,-893.889221,-0.001716,0.003637,0.092377,290.790192,14.813560,0.923772,-893.889221,294.500488,0.000000
116.290009,65.284340,-893.889221,-0.001712,0.003638,0.092412,290.399261,14.793643,0.924120,-893.889221,294.500488,0.000000
116.660004,65.382271,-893.889221,-0.001729,0.003639,0.092438,290.834869,14.815834,0.924377,-893.889221,294.500488,0.000000
117.030006,65.355095,-893.933655,-0.001725,0.003640,0.092447,290.713989,14.809676,0.924468,-893.933655,294.500488,0.000000
117.400009,65.328651,-893.933655,-0.001712,0.003640,0.092454,290.596344,14.803684,0.924544,-893.933655,294.500488,0.000000
117.770004,65.343925,-893.978149,-0.001716,0.003641,0.092489,290.664307,14.807145,0.924892,-893.978149,294.500488,0.000000
118.140007,65.356956,-893.933655,-0.001707,0.003642,0.092507,290.722260,14.810098,0.925074,-893.933655,294.500488,0.000000
118.510002,65.323067,-893.933655,-0.001720,0.003642,0.092515,290.571503,14.802419,0.925149,-893.933655,294.500488,0.000000
118.880005,65.297752,-893.978149,-0.001720,0.003642,0.092515,290.458923,14.796682,0.925149,-893.978149,294.500488,0.000000
119.250008,65.270195,-893.978149,-0.001729,0.003643,0.092542,290.336334,14.790438,0.925422,-893.978149,294.500488,0.000000
119.620003,65.261253,-894.022644,-0.001716,0.003644,0.092559,290.296539,14.788412,0.925588,-894.022644,294.500488,0.000000
119.990005,65.222527,-893.933655,-0.001716,0.003644,0.092559,290.124298,14.779635,0.925588,-893.933655,294.500488,0.000000
120.360008,65.314140,-893.978149,-0.001703,0.003646,0.092610,290.531799,14.800396,0.926103,-893.978149,294.500488,0.000000
120.730003,65.263863,-894.022644,-0.001716,0.003646,0.092610,290.308167,14.789002,0.926103,-894.022644,294.500488,0.000000
121.100006,65.247856,-894.022644,-0.001716,0.003646,0.092610,290.236969,14.785376,0.926103,-894.022644,294.500488,0.000000
121.470009,65.200188,-894.067139,-0.001699,0.003646,0.092619,290.024933,14.774573,0.926194,-894.067139,294.500488,0.000000
121.840004,65.257164,-893.978149,-0.001707,0.003650,0.092698,290.278351,14.787484,0.926981,-893.978149,294.500488,0.000000
122.210007,65.292168,-893.978149,-0.001694,0.003650,0.092698,290.434082,14.795417,0.926981,-893.978149,294.500488,0.000000
122.580009,65.279503,-893.978149,-0.001694,0.003650,0.092698,290.377716,14.792547,0.926981,-893.978149,294.500488,0.000000
122.950005,65.229225,-894.067139,-0.001699,0.003650,0.092698,290.154083,14.781154,0.926981,-894.067139,294.500488,0.000000
123.320007,65.190132,-894.022644,-0.001707,0.003650,0.092698,289.980194,14.772295,0.926981,-894.022644,294.500488,0.000000
123.690002,65.093681,-894.022644,-0.001699,0.003642,0.092507,289.551147,14.750440,0.925074,-894.022644,0.092628,0.000000
124.060005,64.890373,-893.978149,-0.001690,0.003634,0.092308,288.646790,14.704370,0.923075,-893.978149,0.092012,0.000000
124.430008,64.823341,-894.022644,-0.001699,0.003616,0.091856,288.348633,14.689179,0.918564,-894.022644,0.091396,0.000000
124.800003,64.719826,-894.022644,-0.001694,0.003595,0.091301,287.888153,14.665722,0.913007,-894.022644,0.090781,0.000000
125.170006,64.628975,-894.022644,-0.001686,0.003571,0.090703,287.484039,14.645135,0.907027,-894.022644,0.090165,0.000000
125.540009,64.586891,-894.022644,-0.001690,0.003549,0.090140,287.296844,14.635599,0.901395,-894.022644,0.089549,0.000000
125.910004,64.535133,-894.111572,-0.001681,0.003526,0.089567,287.066620,14.623870,0.895673,-894.111572,0.088934,0.000000
126.280006,64.402199,-894.111572,-0.001690,0.003500,0.088891,286.475281,14.593747,0.888905,-894.111572,0.088318,0.000000
126.650009,64.349312,-894.111572,-0.001686,0.003478,0.088353,286.240021,14.581762,0.883531,-894.111572,0.087702,0.000000
127.020004,64.243568,-894.200562,-0.001690,0.003451,0.087651,285.769653,14.557800,0.876506,-894.200562,0.087078,0.000000
127.390007,64.122536,-894.111572,-0.001686,0.003433,0.087199,285.231293,14.530375,0.871994,-894.111572,0.086462,0.000000
127.760010,63.861885,-894.067139,-0.001681,0.003414,0.086723,284.071838,14.471310,0.867225,-894.067139,0.085846,0.000000
128.130005,63.105965,-894.111572,-0.001677,0.003388,0.086055,280.709351,14.300015,0.860549,-894.111572,0.085231,0.000000
128.500000,62.090508,-894.200562,-0.001677,0.003364,0.085439,276.192383,14.069911,0.854387,-894.200562,0.084615,0.000000
128.870010,60.987167,-894.156067,-0.001673,0.003344,0.084945,271.284454,13.819889,0.849452,-894.156067,0.083999,0.000000
129.240005,59.182274,-894.111572,-0.001660,0.003314,0.084182,263.255890,13.410895,0.841821,-894.111572,0.083384,0.000000
129.610001,57.854027,-894.111572,-0.001664,0.003298,0.083766,257.347565,13.109910,0.837658,-894.111572,0.082768,0.000000
129.980011,56.649773,-894.156067,-0.001681,0.003278,0.083262,251.990768,12.837022,0.832616,-894.156067,0.082152,0.000000
130.350006,53.886765,-894.200562,-0.001664,0.003250,0.082543,239.700302,12.210915,0.825425,-894.200562,0.081528,0.000000
130.720001,51.360222,-894.156067,-0.001651,0.003224,0.081891,228.461670,11.638393,0.818915,-894.156067,0.080912,0.000000
131.090012,49.556450,-894.156067,-0.001664,0.003204,0.081380,220.438095,11.229652,0.813798,-894.156067,0.080296,0.000000
131.460007,46.645981,-894.156067,-0.001660,0.003180,0.080765,207.491684,10.570130,0.807651,-894.156067,0.079681,0.000000
131.830002,44.381218,-894.200562,-0.001664,0.003159,0.080235,197.417511,10.056929,0.802352,-894.200562,0.079065,0.000000
132.200012,41.209717,-894.245056,-0.001664,0.003130,0.079490,183.309982,9.338256,0.794904,-894.245056,0.078449,0.000000
132.570007,39.267052,-894.289551,-0.001664,0.003108,0.078935,174.668564,8.898041,0.789347,-894.289551,0.077834,0.000000
132.940002,35.939156,-894.156067,-0.001664,0.003078,0.078188,159.865341,8.143929,0.781884,-894.156067,0.077218,0.000000
133.310013,33.358994,-894.156067,-0.001669,0.003056,0.077625,148.388214,7.559256,0.776252,-894.156067,0.076593,0.000000
133.680008,31.198486,-894.245056,-0.001673,0.003034,0.077053,138.777802,7.069678,0.770529,-894.245056,0.075978,0.000000
134.050003,29.008194,-894.245056,-0.001677,0.003011,0.076472,129.034897,6.573350,0.764715,-894.245056,0.075362,0.000000
134.420013,26.911362,-894.245056,-0.001673,0.002997,0.076134,119.707718,6.098202,0.761339,-894.245056,0.074746,0.000000
134.790009,22.773560,-894.245056,-0.001673,0.002957,0.075101,101.301849,5.160562,0.751014,-894.245056,0.074131,0.000000
135.160004,20.515862,-894.245056,-0.001694,0.002936,0.074573,91.259109,4.648961,0.745730,-894.245056,0.073515,0.000000
135.530014,18.048149,-894.245056,-0.001690,0.002911,0.073948,80.282173,4.089769,0.739478,-894.245056,0.072899,0.000000
135.900009,16.362793,-894.289551,-0.001690,0.002889,0.073385,72.785339,3.707862,0.733846,-894.289551,0.072284,0.000000
136.270004,13.028198,-894.289551,-0.001712,0.002864,0.072743,57.952320,2.952232,0.727427,-894.289551,0.071668,0.000000
136.639999,11.337997,-894.200562,-0.001707,0.002841,0.072170,50.433933,2.569227,0.721704,-894.200562,0.071042,0.000000
137.010010,7.873817,-894.289551,-0.001716,0.002813,0.071459,35.024490,1.784233,0.714588,-894.289551,0.070428,0.000000
137.380005,5.549469,-894.289551,-0.001742,0.002790,0.070861,24.685270,1.257528,0.708608,-894.289551,0.069812,0.000000
137.750000,2.957382,-894.378479,-0.001733,0.002763,0.070184,13.155093,0.670152,0.701841,-894.378479,0.069195,0.000000
138.120010,1.266441,-894.289551,-0.001759,0.002747,0.069777,5.633412,0.286980,0.697768,-894.289551,0.068581,0.000000
138.490005,-0.919384,-894.378479,-0.001759,0.002719,0.069074,-4.089624,-0.208335,0.690743,-894.378479,0.067965,0.000000
138.860001,-2.964455,-894.289551,-0.001768,0.002702,0.068623,-13.186553,-0.671755,0.686232,-894.289551,0.067348,0.000000
139.230011,-5.819435,-894.333984,-0.001798,0.002668,0.067756,-25.886141,-1.318703,0.677557,-894.333984,0.066732,0.000000
139.600006,-0.225281,-894.378479,-0.001871,0.002648,0.067262,-1.002099,-0.051049,0.672621,-894.378479,0.066118,0.000000
139.970001,-0.027924,-894.333984,-0.001888,0.002624,0.066646,-0.124210,-0.006328,0.666459,-894.333984,0.065492,0.000000
140.340012,-0.068886,-894.333984,-0.001910,0.002598,0.065978,-0.306419,-0.015610,0.659783,-894.333984,0.064878,0.000000
140.710007,-0.042450,-894.333984,-0.001936,0.002583,0.065615,-0.188827,-0.009619,0.656149,-894.333984,0.064261,0.000000
141.080002,-0.086388,-894.422974,-0.001979,0.002545,0.064634,-0.384271,-0.019576,0.646339,-894.422974,0.063645,0.000000
141.450012,-0.083038,-894.378479,-0.002001,0.002524,0.064115,-0.369373,-0.018817,0.641146,-894.378479,0.063031,0.000000
141.820007,-0.086014,-894.333984,-0.002026,0.002500,0.063508,-0.382608,-0.019491,0.635075,-894.333984,0.062414,0.000000
142.190002,-0.072983,-894.422974,-0.002044,0.002484,0.063082,-0.324644,-0.016538,0.630821,-894.422974,0.061798,0.000000
142.560013,-0.060692,-894.422974,-0.002095,0.002461,0.062519,-0.269971,-0.013753,0.625189,-894.422974,0.061182,0.000000
142.930008,-0.083038,-894.378479,-0.002143,0.002427,0.061642,-0.369373,-0.018817,0.616423,-894.378479,0.060567,0.000000
143.300003,-0.064041,-894.378479,-0.002186,0.002404,0.061070,-0.284869,-0.014512,0.610700,-894.378479,0.059942,0.000000
143.670013,-0.080803,-894.422974,-0.002195,0.002376,0.060351,-0.359429,-0.018310,0.603509,-894.422974,0.059327,0.000000
144.040009,-0.068886,-894.378479,-0.002216,0.002359,0.059925,-0.306419,-0.015610,0.599255,-894.378479,0.058711,0.000000
144.410004,-0.073357,-894.378479,-0.002233,0.002336,0.059327,-0.326307,-0.016623,0.593275,-894.378479,0.058095,0.000000
144.780014,-0.087875,-894.378479,-0.002268,0.002306,0.058572,-0.390889,-0.019913,0.585720,-894.378479,0.057479,0.000000
145.150009,-0.075218,-894.422974,-0.002272,0.002283,0.058000,-0.334587,-0.017045,0.579997,-894.422974,0.056864,0.000000
145.520004,-0.067024,-894.378479,-0.002320,0.002263,0.057488,-0.298139,-0.015188,0.574880,-894.378479,0.056248,0.000000
145.889999,-0.054359,-894.422974,-0.002350,0.002235,0.056769,-0.241803,-0.012318,0.567689,-894.422974,0.055632,0.000000
146.260010,-0.052132,-894.422974,-0.002363,0.002219,0.056353,-0.231893,-0.011813,0.563525,-894.422974,0.055017,0.000000
146.630005,-0.065163,-894.556396,-0.002402,0.002182,0.055434,-0.289858,-0.014766,0.554336,-894.556396,0.054392,0.000000
147.000000,-0.085274,-894.511902,-0.002419,0.002158,0.054817,-0.379317,-0.019323,0.548174,-894.511902,0.053777,0.000000
147.370010,-0.067772,-894.511902,-0.002453,0.002130,0.054097,-0.301465,-0.015357,0.540967,-894.511902,0.053161,0.000000
147.740005,-0.027184,-894.422974,-0.002466,0.002127,0.054020,-0.120918,-0.006160,0.540195,-894.422974,0.052545,0.000000
148.110001,-0.055481,-894.422974,-0.002509,0.002092,0.053143,-0.246792,-0.012572,0.531430,-894.422974,0.051929,0.000000
148.480011,-0.036491,-894.511902,-0.002544,0.002063,0.052406,-0.162322,-0.008269,0.524057,-894.511902,0.051314,0.000000
148.850006,-0.062180,-894.511902,-0.002557,0.002039,0.051782,-0.276589,-0.014090,0.517819,-894.511902,0.050698,0.000000
149.220001,-0.065910,-894.467468,-0.002583,0.002019,0.051270,-0.293184,-0.014935,0.512702,-894.467468,0.050082,0.000000
149.590012,-0.049149,-894.467468,-0.002613,0.001990,0.050551,-0.218624,-0.011137,0.505511,-894.467468,0.049467,0.000000
149.960007,-0.060692,-894.467468,-0.002639,0.001965,0.049917,-0.269971,-0.013753,0.499167,-894.467468,0.048842,0.000000
150.330002,-0.064041,-894.511902,-0.002656,0.001942,0.049337,-0.284869,-0.014512,0.493369,-894.511902,0.048226,0.000000
150.700012,-0.036491,-894.556396,-0.002682,0.001911,0.048539,-0.162322,-0.008269,0.485390,-894.556396,0.047611,0.000000
151.070007,-0.036865,-894.467468,-0.002708,0.001894,0.048097,-0.163985,-0.008354,0.480969,-894.467468,0.046995,0.000000
151.440002,-0.021591,-894.467468,-0.002742,0.001864,0.047351,-0.096042,-0.004893,0.473505,-894.467468,0.046379,0.000000
151.810013,-0.050270,-894.511902,-0.002777,0.001842,0.046778,-0.223612,-0.011391,0.467783,-894.511902,0.045764,0.000000
152.180008,-0.042450,-894.511902,-0.002781,0.001821,0.046248,-0.188827,-0.009619,0.462484,-894.511902,0.045148,0.000000
152.550003,-0.042816,-894.556396,-0.002807,0.001793,0.045546,-0.190456,-0.009702,0.455459,-894.556396,0.044532,0.000000
152.920013,-0.037231,-894.600891,-0.002846,0.001771,0.044974,-0.165614,-0.008437,0.449736,-894.600891,0.043917,0.000000
153.290009,-0.014145,-894.556396,-0.002880,0.001746,0.044350,-0.062920,-0.003205,0.443499,-894.556396,0.043292,0.000000
153.500000,-0.006325,-894.556396,-0.002889,0.001737,0.044124,-0.028134,-0.001433,0.441243,-894.556396,0.044003,0.000000