File: Data/compression 35/ManualNoHeating-12-35-reverse-1-2_11182024_165348.csv
Time (sec),S:Load (lbs),S:HL1 (DIM),S:LVDT (in),S:Position (in),Ch:Position (mm),Ch:Load (N),Ch:Stress (MPa),Ch:Strain (mm/mm),Ch:HL1 (DIM),Set Point (),Cycles ()
0.110000,-0.032768,-814.846558,-0.014400,-0.009226,-0.234333,-0.145760,-0.007425,-2.343334,-814.846558,-0.234081,0.000000
0.510000,-0.014145,-814.846558,-0.014396,-0.009171,-0.232945,-0.062920,-0.003205,-2.329452,-814.846558,-0.232191,0.000000
0.910000,0.036499,-814.846558,-0.014280,-0.008937,-0.226988,0.162356,0.008271,-2.269877,-814.846558,-0.225530,0.000000
1.310000,-0.012657,-814.802063,-0.013999,-0.008669,-0.220189,-0.056302,-0.002868,-2.201885,-814.802063,-0.218870,0.000000
1.710000,-0.037605,-814.846558,-0.013741,-0.008409,-0.213580,-0.167277,-0.008521,-2.135801,-814.846558,-0.212210,0.000000
2.110000,-0.127350,-814.891052,-0.013461,-0.008143,-0.206832,-0.566480,-0.028858,-2.068324,-814.891052,-0.205550,0.000000
2.510000,-0.031273,-814.891052,-0.013189,-0.007888,-0.200347,-0.139109,-0.007087,-2.003466,-814.891052,-0.198872,0.000000
2.910000,-0.024574,-814.935486,-0.012917,-0.007614,-0.193391,-0.109312,-0.005569,-1.933915,-814.935486,-0.192212,0.000000
3.310000,-0.007820,-814.846558,-0.012633,-0.007362,-0.187000,-0.034786,-0.001772,-1.869995,-814.846558,-0.185551,0.000000
3.710000,-0.043190,-814.846558,-0.012374,-0.007096,-0.180226,-0.192119,-0.009787,-1.802261,-814.846558,-0.178891,0.000000
4.110000,-0.067024,-814.891052,-0.012089,-0.006838,-0.173687,-0.298139,-0.015188,-1.736873,-814.891052,-0.172231,0.000000
4.510000,-0.066277,-814.935486,-0.011831,-0.006576,-0.167027,-0.294813,-0.015018,-1.670274,-814.935486,-0.165553,0.000000
4.910000,-0.008934,-814.935486,-0.011551,-0.006311,-0.160298,-0.039741,-0.002024,-1.602979,-814.935486,-0.158893,0.000000
5.310000,0.004845,-814.935486,-0.011292,-0.006045,-0.153550,0.021550,0.001098,-1.535502,-814.935486,-0.152233,0.000000
5.710000,-0.005585,-814.979980,-0.011007,-0.005782,-0.146865,-0.024842,-0.001266,-1.468645,-814.979980,-0.145572,0.000000
6.110000,-0.028671,-814.979980,-0.010736,-0.005516,-0.140109,-0.127536,-0.006497,-1.401092,-814.979980,-0.138912,0.000000
6.510000,-0.037605,-814.935486,-0.010468,-0.005255,-0.133483,-0.167277,-0.008521,-1.334826,-814.935486,-0.132234,0.000000
6.910000,0.007454,-814.935486,-0.010210,-0.004998,-0.126944,0.033157,0.001689,-1.269439,-814.935486,-0.125574,0.000000
7.310000,0.035004,-815.024475,-0.009934,-0.004742,-0.120440,0.155704,0.007932,-1.204399,-815.024475,-0.118914,0.000000
7.710001,-0.000740,-814.935486,-0.009662,-0.004471,-0.113564,-0.003292,-0.000168,-1.135635,-814.935486,-0.112254,0.000000
8.110001,-0.014893,-814.979980,-0.009386,-0.004212,-0.106981,-0.066245,-0.003375,-1.069808,-814.979980,-0.105576,0.000000
8.510000,-0.092720,-815.024475,-0.009106,-0.003945,-0.100191,-0.412439,-0.021011,-1.001907,-815.024475,-0.098916,0.000000
8.910001,-0.020477,-814.979980,-0.008852,-0.003690,-0.093738,-0.091088,-0.004640,-0.937382,-814.979980,-0.092255,0.000000
9.310000,-0.019363,-815.068970,-0.008571,-0.003416,-0.086757,-0.086133,-0.004388,-0.867574,-815.068970,-0.085595,0.000000
9.710000,0.001862,-814.979980,-0.008308,-0.003164,-0.080365,0.008281,0.000422,-0.803654,-814.979980,-0.078935,0.000000
10.110001,-0.026436,-815.024475,-0.008037,-0.002898,-0.073619,-0.117593,-0.005990,-0.736192,-815.024475,-0.072257,0.000000
10.510000,-0.067398,-815.024475,-0.007769,-0.002641,-0.067088,-0.299802,-0.015273,-0.670880,-815.024475,-0.065597,0.000000
10.910001,-0.051384,-814.979980,-0.007493,-0.002379,-0.060428,-0.228567,-0.011644,-0.604281,-814.979980,-0.058937,0.000000
11.310000,-0.000366,-815.113403,-0.007192,-0.002114,-0.053689,-0.001629,-0.000083,-0.536895,-815.113403,-0.052275,0.000000
11.710001,0.011917,-814.979980,-0.006942,-0.001847,-0.046908,0.053010,0.002700,-0.469085,-814.979980,-0.045616,0.000000
12.110001,0.007454,-815.113403,-0.006661,-0.001584,-0.040221,0.033157,0.001689,-0.402213,-815.113403,-0.038937,0.000000
12.510000,-0.025314,-815.113403,-0.006398,-0.001318,-0.033483,-0.112604,-0.005736,-0.334827,-815.113403,-0.032278,0.000000
12.910001,-0.027924,-815.113403,-0.006144,-0.001057,-0.026858,-0.124210,-0.006328,-0.268576,-815.113403,-0.025618,0.000000
13.310000,0.021973,-815.068970,-0.005868,-0.000800,-0.020319,0.097739,0.004979,-0.203188,-815.068970,-0.018958,0.000000
13.710001,0.052879,-815.068970,-0.005596,-0.000546,-0.013866,0.235219,0.011983,-0.138663,-815.068970,-0.012296,0.000000
14.110001,0.007080,-815.113403,-0.005320,-0.000272,-0.006902,0.031494,0.001604,-0.069021,-815.113403,-0.005620,0.000000
14.510000,0.028679,-815.113403,-0.005053,-0.000015,-0.000372,0.127570,0.006499,-0.003724,-815.113403,0.001042,0.000000
14.910001,0.118042,-815.157898,-0.004937,-0.000000,-0.000009,0.525077,0.026749,-0.000091,-815.157898,0.000156,0.000000
15.310000,0.096451,-815.157898,-0.004928,-0.000000,-0.000009,0.429035,0.021856,-0.000091,-815.157898,0.000372,0.000000
15.710001,0.125122,-815.157898,-0.004941,-0.000000,-0.000000,0.556571,0.028353,-0.000000,-815.157898,0.001040,0.000000
16.110001,0.118790,-815.113403,-0.004924,0.000025,0.000640,0.528403,0.026918,0.006404,-815.113403,0.001708,0.000000
16.510000,0.106133,-815.157898,-0.004889,0.000045,0.001152,0.472101,0.024050,0.011521,-815.157898,0.002366,0.000000
16.910002,0.135544,-815.113403,-0.004881,0.000062,0.001587,0.602929,0.030715,0.015866,-815.113403,0.003034,0.000000
17.310001,0.272949,-815.157898,-0.004833,0.000107,0.002705,1.214139,0.061851,0.027054,-815.157898,0.003703,0.000000
17.710001,0.285240,-815.157898,-0.004825,0.000128,0.003260,1.268812,0.064636,0.032596,-815.157898,0.004371,0.000000
18.110001,0.242416,-815.157898,-0.004786,0.000157,0.003980,1.078322,0.054932,0.039802,-815.157898,0.005038,0.000000
18.510000,0.266624,-815.202393,-0.004769,0.000169,0.004301,1.186005,0.060418,0.043012,-815.202393,0.005706,0.000000
18.910002,0.385033,-815.157898,-0.004751,0.000198,0.005029,1.712711,0.087250,0.050294,-815.157898,0.006374,0.000000
19.310001,0.579414,-815.157898,-0.004708,0.000233,0.005923,2.577364,0.131297,0.059226,-815.157898,0.007041,0.000000
19.710001,0.700066,-815.202393,-0.004674,0.000266,0.006746,3.114047,0.158637,0.067462,-815.202393,0.007700,0.000000
20.110001,0.793159,-815.246887,-0.004665,0.000288,0.007309,3.528150,0.179733,0.073094,-815.246887,0.008368,0.000000
20.510000,0.822571,-815.202393,-0.004644,0.000305,0.007744,3.658978,0.186397,0.077439,-815.202393,0.009035,0.000000
20.910002,1.094032,-815.202393,-0.004605,0.000331,0.008402,4.866498,0.247911,0.084025,-815.202393,0.009703,0.000000
21.310001,1.331238,-815.246887,-0.004592,0.000360,0.009149,5.921641,0.301663,0.091488,-815.246887,0.010372,0.000000
21.710001,1.496193,-815.291382,-0.004562,0.000385,0.009782,6.655398,0.339042,0.097817,-815.291382,0.011040,0.000000
22.110001,1.693184,-815.246887,-0.004527,0.000408,0.010372,7.531658,0.383681,0.103721,-815.246887,0.011707,0.000000
22.510000,1.928894,-815.335815,-0.004510,0.000436,0.011066,8.580150,0.437094,0.110655,-815.335815,0.012375,0.000000
22.910002,2.370155,-815.291382,-0.004480,0.000469,0.011915,10.542977,0.537085,0.119148,-815.291382,0.013043,0.000000
23.310001,2.640869,-815.335815,-0.004449,0.000493,0.012513,11.747172,0.598430,0.125129,-815.335815,0.013701,0.000000
23.710001,2.918655,-815.291382,-0.004441,0.000517,0.013129,12.982827,0.661377,0.131290,-815.291382,0.014369,0.000000
24.110001,3.348007,-815.380310,-0.004398,0.000548,0.013910,14.892680,0.758669,0.139102,-815.380310,0.015037,0.000000
24.510000,3.622444,-815.380310,-0.004385,0.000569,0.014455,16.113436,0.820858,0.144553,-815.380310,0.015704,0.000000
24.910002,4.124397,-815.291382,-0.004363,0.000600,0.015246,18.346235,0.934602,0.152456,-815.291382,0.016372,0.000000
25.310001,4.404053,-815.380310,-0.004337,0.000629,0.015965,19.590204,0.997973,0.159647,-815.380310,0.017040,0.000000
25.710001,4.966331,-815.335815,-0.004307,0.000661,0.016797,22.091345,1.125387,0.167974,-815.335815,0.017709,0.000000
26.110001,5.262367,-815.380310,-0.004277,0.000686,0.017423,23.408178,1.192469,0.174226,-815.380310,0.018376,0.000000
26.510002,5.652618,-815.380310,-0.004238,0.000714,0.018142,25.144102,1.280902,0.181418,-815.380310,0.019035,0.000000
26.910002,5.914764,-815.380310,-0.004243,0.000732,0.018602,26.310186,1.340305,0.186020,-815.380310,0.019703,0.000000
27.310001,6.191437,-815.424805,-0.004208,0.000757,0.019235,27.540886,1.403000,0.192348,-815.424805,0.020370,0.000000
27.710001,6.155693,-815.424805,-0.004212,0.000772,0.019598,27.381889,1.394900,0.195982,-815.424805,0.021038,0.000000
28.110001,6.968582,-815.424805,-0.004152,0.000810,0.020570,30.997801,1.579103,0.205701,-815.424805,0.021706,0.000000
28.510002,7.359947,-815.469299,-0.004139,0.000836,0.021229,32.738682,1.667788,0.212287,-815.469299,0.022373,0.000000
28.910002,7.779610,-815.424805,-0.004113,0.000866,0.022001,34.605431,1.762885,0.220008,-815.424805,0.023041,0.000000
29.310001,7.817963,-815.380310,-0.004079,0.000886,0.022496,34.776035,1.771576,0.224959,-815.380310,0.023709,0.000000
29.710001,8.269653,-815.469299,-0.004044,0.000912,0.023154,36.785255,1.873930,0.231545,-815.469299,0.024369,0.000000
30.110001,8.510201,-815.424805,-0.004010,0.000934,0.023736,37.855263,1.928439,0.237358,-815.424805,0.025036,0.000000
30.510002,8.992798,-815.424805,-0.004001,0.000967,0.024559,40.001965,2.037797,0.245594,-815.424805,0.025704,0.000000
30.910002,9.332405,-815.513733,-0.003967,0.000995,0.025262,41.512611,2.114753,0.252619,-815.513733,0.026372,0.000000
31.310001,9.648918,-815.469299,-0.003923,0.001024,0.026016,42.920532,2.186476,0.260159,-815.469299,0.027039,0.000000
31.710001,9.607956,-815.513733,-0.003915,0.001046,0.026581,42.738323,2.177194,0.265806,-815.513733,0.027707,0.000000
32.110001,9.884628,-815.513733,-0.003889,0.001069,0.027153,43.969021,2.239889,0.271528,-815.513733,0.028375,0.000000
32.510002,10.151993,-815.513733,-0.003850,0.001092,0.027725,45.158318,2.300474,0.277251,-815.513733,0.029042,0.000000
32.910000,10.674805,-815.513733,-0.003837,0.001124,0.028549,47.483902,2.418945,0.285487,-815.513733,0.029702,0.000000
33.310001,10.815559,-815.558228,-0.003807,0.001151,0.029225,48.110012,2.450841,0.292254,-815.558228,0.030370,0.000000
33.710003,10.769760,-815.513733,-0.003764,0.001173,0.029805,47.906284,2.440463,0.298053,-815.513733,0.031038,0.000000
34.110001,11.153305,-815.602722,-0.003751,0.001202,0.030535,49.612377,2.527375,0.305350,-815.602722,0.031705,0.000000
34.510002,11.211769,-815.558228,-0.003695,0.001225,0.031124,49.872440,2.540623,0.311239,-815.558228,0.032373,0.000000
34.910000,11.544670,-815.647217,-0.003682,0.001254,0.031852,51.353256,2.616060,0.318522,-815.647217,0.033041,0.000000
35.310001,11.979973,-815.558228,-0.003630,0.001283,0.032589,53.289581,2.714700,0.325895,-815.558228,0.033708,0.000000
35.710003,11.944221,-815.647217,-0.003622,0.001304,0.033119,53.130550,2.706599,0.331193,-815.647217,0.034376,0.000000
36.110001,12.442825,-815.602722,-0.003570,0.001342,0.034090,55.348450,2.819584,0.340898,-815.602722,0.035044,0.000000
36.510002,12.172859,-815.602722,-0.003548,0.001364,0.034636,54.147583,2.758409,0.346363,-815.602722,0.035704,0.000000
36.910000,12.456978,-815.647217,-0.003518,0.001391,0.035330,55.411404,2.822792,0.353297,-815.647217,0.036371,0.000000
37.310001,12.350105,-815.602722,-0.003501,0.001412,0.035876,54.936012,2.798574,0.358763,-815.602722,0.037039,0.000000
37.710003,12.564598,-815.647217,-0.003449,0.001434,0.036432,55.890125,2.847179,0.364319,-815.647217,0.037707,0.000000
38.110001,12.795090,-815.691650,-0.003423,0.001460,0.037074,56.915401,2.899409,0.370738,-815.691650,0.038374,0.000000
38.510002,13.536118,-815.647217,-0.003376,0.001498,0.038044,60.211658,3.067328,0.380443,-815.647217,0.039042,0.000000
38.910004,13.212898,-815.691650,-0.003372,0.001518,0.038565,58.773907,2.994086,0.385651,-815.691650,0.039710,0.000000
39.310001,13.718575,-815.691650,-0.003311,0.001551,0.039389,61.023266,3.108673,0.393886,-815.691650,0.040377,0.000000
39.710003,13.250130,-815.780640,-0.003290,0.001565,0.039754,58.939522,3.002522,0.397535,-815.780640,0.041036,0.000000
40.110001,13.336151,-815.691650,-0.003277,0.001583,0.040196,59.322163,3.022015,0.401956,-815.691650,0.041703,0.000000
40.510002,14.485664,-815.691650,-0.003247,0.001625,0.041280,64.435455,3.282499,0.412796,-815.691650,0.042373,0.000000
40.910004,14.949638,-815.736145,-0.003186,0.001660,0.042155,66.499313,3.387636,0.421546,-815.736145,0.043040,0.000000
41.310001,14.403000,-815.780640,-0.003169,0.001672,0.042476,64.067741,3.263766,0.424756,-815.780640,0.043708,0.000000
41.710003,14.751907,-815.736145,-0.003143,0.001698,0.043136,65.619759,3.342830,0.431357,-815.736145,0.044376,0.000000
42.110001,15.301163,-815.780640,-0.003122,0.001727,0.043864,68.062973,3.467293,0.438639,-815.780640,0.045043,0.000000
42.510002,16.035851,-815.780640,-0.003078,0.001758,0.044662,71.331024,3.633776,0.446618,-815.780640,0.045711,0.000000
42.910004,15.638161,-815.780640,-0.003053,0.001777,0.045148,69.562012,3.543658,0.451477,-815.780640,0.046370,0.000000
43.310001,15.794182,-815.780640,-0.003035,0.001801,0.045746,70.256027,3.579013,0.457458,-815.780640,0.047037,0.000000
43.710003,16.492004,-815.780640,-0.003009,0.001828,0.046439,73.360100,3.737142,0.464391,-815.780640,0.047705,0.000000
44.110001,16.788788,-815.780640,-0.002975,0.001858,0.047186,74.680260,3.804394,0.471855,-815.780640,0.048372,0.000000
44.510002,17.053543,-815.825134,-0.002949,0.001884,0.047853,75.857948,3.864388,0.478532,-815.825134,0.049042,0.000000
44.910004,17.357025,-815.869629,-0.002923,0.001914,0.048625,77.207901,3.933158,0.486253,-815.869629,0.049709,0.000000
45.310001,17.377884,-815.736145,-0.002884,0.001934,0.049119,77.300690,3.937885,0.491189,-815.736145,0.050377,0.000000
45.710003,17.403206,-815.825134,-0.002863,0.001954,0.049640,77.413322,3.943623,0.496397,-815.825134,0.051045,0.000000
46.110001,18.293915,-815.825134,-0.002841,0.001989,0.050515,81.375397,4.145461,0.505147,-815.825134,0.051703,0.000000
46.510002,18.686401,-815.869629,-0.002798,0.002021,0.051340,83.121262,4.234399,0.513398,-815.869629,0.052371,0.000000
46.910004,18.957855,-815.914062,-0.002777,0.002051,0.052094,84.328751,4.295912,0.520938,-815.914062,0.053038,0.000000
47.310001,19.104942,-815.825134,-0.002729,0.002076,0.052736,84.983025,4.329242,0.527357,-815.825134,0.053706,0.000000
47.710003,19.324646,-815.914062,-0.002721,0.002102,0.053385,85.960320,4.379027,0.533852,-815.914062,0.054374,0.000000
48.110001,19.054298,-815.825134,-0.002682,0.002123,0.053932,84.757751,4.317766,0.539317,-815.825134,0.055041,0.000000
48.510002,19.558121,-815.869629,-0.002669,0.002149,0.054574,86.998863,4.431933,0.545736,-815.869629,0.055711,0.000000
48.910004,19.405449,-815.914062,-0.002634,0.002162,0.054920,86.319748,4.397337,0.549203,-815.914062,0.056378,0.000000
49.310001,20.616776,-815.914062,-0.002608,0.002199,0.055857,91.708000,4.671828,0.558575,-815.914062,0.057046,0.000000
49.710003,20.956757,-815.869629,-0.002587,0.002228,0.056595,93.220306,4.748869,0.565948,-815.869629,0.057705,0.000000
50.110001,21.190605,-815.958557,-0.002544,0.002253,0.057228,94.260521,4.801859,0.572276,-815.958557,0.058372,0.000000
50.510002,21.316833,-815.914062,-0.002518,0.002278,0.057870,94.822014,4.830463,0.578695,-815.914062,0.059040,0.000000
50.910004,21.205872,-816.003052,-0.002479,0.002299,0.058390,94.328430,4.805319,0.583903,-816.003052,0.059707,0.000000
51.310001,21.394287,-815.914062,-0.002475,0.002324,0.059023,95.166542,4.848015,0.590232,-815.914062,0.060375,0.000000
51.710003,22.238831,-815.869629,-0.002445,0.002355,0.059829,98.923256,5.039391,0.598286,-815.869629,0.061043,0.000000
52.110001,22.573219,-815.914062,-0.002410,0.002387,0.060619,100.410698,5.115165,0.606189,-815.914062,0.061710,0.000000
52.510002,22.732224,-815.958557,-0.002389,0.002412,0.061261,101.117981,5.151196,0.612608,-815.958557,0.062380,0.000000
52.910004,23.208115,-815.958557,-0.002345,0.002441,0.061989,103.234848,5.259034,0.619890,-815.958557,0.063038,0.000000
53.310001,22.960114,-815.958557,-0.002324,0.002462,0.062526,102.131683,5.202836,0.625265,-815.958557,0.063706,0.000000
53.710003,23.310890,-816.003052,-0.002307,0.002487,0.063168,103.692017,5.282323,0.631684,-816.003052,0.064373,0.000000
54.110004,24.191551,-815.958557,-0.002268,0.002521,0.064027,107.609398,5.481884,0.640268,-815.958557,0.065041,0.000000
54.510002,24.116707,-816.003052,-0.002238,0.002541,0.064539,107.276466,5.464924,0.645385,-816.003052,0.065709,0.000000
54.910004,24.121178,-815.958557,-0.002207,0.002566,0.065180,107.296356,5.465937,0.651804,-815.958557,0.066376,0.000000
55.310001,24.280174,-815.958557,-0.002182,0.002590,0.065788,108.003609,5.501966,0.657875,-815.958557,0.067044,0.000000
55.710003,24.697983,-815.958557,-0.002139,0.002620,0.066551,109.862114,5.596643,0.665506,-815.958557,0.067712,0.000000
56.110004,25.025665,-816.047546,-0.002121,0.002647,0.067227,111.319717,5.670897,0.672273,-816.047546,0.068372,0.000000
56.510002,24.629837,-816.003052,-0.002091,0.002667,0.067739,109.558990,5.581201,0.677390,-816.003052,0.069040,0.000000
56.910004,24.852142,-816.047546,-0.002061,0.002696,0.068467,110.547852,5.631576,0.684672,-816.047546,0.069707,0.000000
57.310001,26.050438,-816.003052,-0.002009,0.002735,0.069472,115.878136,5.903114,0.694725,-816.003052,0.070375,0.000000
57.710003,25.335480,-816.003052,-0.001979,0.002754,0.069958,112.697845,5.741102,0.699585,-816.003052,0.071042,0.000000
58.110004,25.435280,-816.003052,-0.001936,0.002780,0.070617,113.141777,5.763717,0.706171,-816.003052,0.071710,0.000000
58.510002,25.482567,-816.091980,-0.001901,0.002806,0.071285,113.352119,5.774432,0.712847,-816.091980,0.072378,0.000000
58.910004,25.398781,-816.047546,-0.001893,0.002828,0.071840,112.979416,5.755446,0.718403,-816.047546,0.073045,0.000000
59.310001,25.437508,-816.136475,-0.001858,0.002849,0.072369,113.151688,5.764222,0.723687,-816.136475,0.073706,0.000000
59.710003,26.697617,-816.091980,-0.001828,0.002885,0.073280,118.756927,6.049767,0.732801,-816.091980,0.074373,0.000000
60.110004,26.361366,-816.091980,-0.001789,0.002908,0.073852,117.261215,5.973571,0.738524,-816.091980,0.075041,0.000000
60.510002,26.583298,-816.047546,-0.001746,0.002934,0.074511,118.248413,6.023861,0.745110,-816.047546,0.075708,0.000000
60.910004,26.592613,-816.136475,-0.001742,0.002963,0.075257,118.289848,6.025972,0.752573,-816.136475,0.076376,0.000000
61.310001,25.945801,-816.136475,-0.001690,0.002974,0.075543,115.412689,5.879403,0.755435,-816.136475,0.077044,0.000000
61.710003,27.804314,-816.136475,-0.001669,0.003013,0.076541,123.679764,6.300548,0.765412,-816.136475,0.077711,0.000000
62.110004,28.323769,-816.136475,-0.001630,0.003043,0.077286,125.990417,6.418258,0.772860,-816.136475,0.078379,0.000000
62.510002,28.257484,-816.180969,-0.001608,0.003066,0.077867,125.695572,6.403238,0.778674,-816.180969,0.079047,0.000000
62.910004,27.971130,-816.091980,-0.001574,0.003088,0.078423,124.421799,6.338349,0.784230,-816.091980,0.079705,0.000000
63.310001,28.632095,-816.180969,-0.001548,0.003115,0.079133,127.361923,6.488126,0.791331,-816.180969,0.080375,0.000000
63.710003,29.420776,-816.136475,-0.001509,0.003144,0.079863,130.870148,6.666843,0.798628,-816.136475,0.081042,0.000000
64.110001,29.622604,-816.180969,-0.001479,0.003168,0.080470,131.767929,6.712578,0.804699,-816.180969,0.081710,0.000000
64.510002,29.103516,-816.225464,-0.001453,0.003191,0.081050,129.458908,6.594951,0.810497,-816.225464,0.082377,0.000000
64.910004,30.167389,-816.225464,-0.001427,0.003218,0.081745,134.191254,6.836028,0.817446,-816.225464,0.083045,0.000000
65.310005,30.686844,-816.180969,-0.001410,0.003249,0.082524,136.501892,6.953738,0.825243,-816.180969,0.083713,0.000000
65.710007,31.285995,-816.180969,-0.001358,0.003278,0.083271,139.167053,7.089508,0.832707,-816.180969,0.084380,0.000000
66.110001,30.911758,-816.269958,-0.001328,0.003299,0.083782,137.502365,7.004704,0.837824,-816.269958,0.085039,0.000000
66.510002,31.328445,-816.225464,-0.001281,0.003329,0.084555,139.355881,7.099127,0.845546,-816.225464,0.085707,0.000000
66.910004,31.044327,-816.225464,-0.001263,0.003348,0.085048,138.092056,7.034745,0.850481,-816.225464,0.086374,0.000000
67.310005,30.671577,-816.269958,-0.001233,0.003366,0.085508,136.433990,6.950279,0.855083,-816.269958,0.087044,0.000000
67.710007,32.294380,-816.269958,-0.001190,0.003406,0.086514,143.652573,7.318011,0.865136,-816.269958,0.087711,0.000000
68.110001,32.415771,-816.269958,-0.001164,0.003433,0.087207,144.192551,7.345519,0.872070,-816.269958,0.088379,0.000000
68.510002,32.590042,-816.269958,-0.001130,0.003466,0.088040,144.967743,7.385009,0.880397,-816.269958,0.089046,0.000000
68.910004,32.707336,-816.314392,-0.001091,0.003494,0.088742,145.489502,7.411588,0.887422,-816.314392,0.089714,0.000000
69.310005,32.373695,-816.225464,-0.001074,0.003516,0.089307,144.005386,7.335984,0.893069,-816.225464,0.090373,0.000000
69.710007,32.532700,-816.314392,-0.001035,0.003541,0.089931,144.712677,7.372015,0.899306,-816.314392,0.091040,0.000000
70.110001,32.339066,-816.269958,-0.001022,0.003561,0.090442,143.851349,7.328137,0.904423,-816.269958,0.091708,0.000000
70.510002,32.598976,-816.225464,-0.000983,0.003584,0.091024,145.007492,7.387033,0.910237,-816.225464,0.092376,0.000000
70.910004,33.882545,-816.358887,-0.000953,0.003622,0.091987,150.717087,7.677894,0.919866,-816.358887,0.093043,0.000000
71.310005,32.815323,-816.403381,-0.000940,0.003636,0.092359,145.969849,7.436059,0.923590,-816.403381,0.093712,0.000000
71.710007,33.508308,-816.314392,-0.000892,0.003670,0.093226,149.052399,7.593091,0.932265,-816.314392,0.094380,0.000000
72.110001,34.215820,-816.358887,-0.000862,0.003697,0.093894,152.199570,7.753416,0.938942,-816.358887,0.095048,0.000000
72.510002,34.304817,-816.314392,-0.000841,0.003721,0.094518,152.595444,7.773582,0.945179,-816.314392,0.095706,0.000000
72.910004,34.013992,-816.403381,-0.000832,0.003738,0.094952,151.301788,7.707681,0.949524,-816.403381,0.096374,0.000000
73.310005,35.523964,-816.358887,-0.000798,0.003776,0.095923,158.018478,8.049846,0.959229,-816.358887,0.097042,0.000000
73.710007,36.185295,-816.358887,-0.000776,0.003804,0.096625,160.960236,8.199705,0.966253,-816.358887,0.097709,0.000000
74.110001,36.609802,-816.358887,-0.000742,0.003829,0.097258,162.848541,8.295899,0.972582,-816.358887,0.098377,0.000000
74.510002,36.951637,-816.403381,-0.000720,0.003854,0.097883,164.369095,8.373361,0.978834,-816.403381,0.099045,0.000000
74.910004,37.140060,-816.403381,-0.000698,0.003873,0.098386,165.207245,8.416058,0.983861,-816.403381,0.099712,0.000000
75.310005,38.402405,-816.403381,-0.000673,0.003903,0.099132,170.822433,8.702109,0.991325,-816.403381,0.100381,0.000000
75.710007,39.572395,-816.447876,-0.000651,0.003935,0.099938,176.026810,8.967233,0.999379,-816.447876,0.101049,0.000000
76.110001,40.881660,-816.447876,-0.000629,0.003961,0.100615,181.850708,9.263917,1.006146,-816.447876,0.101708,0.000000
76.510002,41.185516,-816.447876,-0.000612,0.003983,0.101179,183.202332,9.332771,1.011793,-816.447876,0.102375,0.000000
76.910004,43.024666,-816.447876,-0.000578,0.004014,0.101968,191.383270,9.749529,1.019681,-816.447876,0.103043,0.000000
77.310005,43.751907,-816.403381,-0.000582,0.004040,0.102610,194.618210,9.914324,1.026100,-816.403381,0.103711,0.000000
77.710007,44.787849,-816.492310,-0.000548,0.004062,0.103182,199.226303,10.149072,1.031823,-816.492310,0.104378,0.000000
78.110001,45.541153,-816.447876,-0.000543,0.004088,0.103824,202.577164,10.319773,1.038242,-816.447876,0.105046,0.000000
78.510002,47.903488,-816.447876,-0.000513,0.004121,0.104683,213.085358,10.855086,1.046826,-816.447876,0.105714,0.000000
78.910004,49.010925,-816.536804,-0.000504,0.004146,0.105297,218.011490,11.106034,1.052973,-816.536804,0.106381,0.000000
79.310005,50.213684,-816.492310,-0.000492,0.004173,0.105983,223.361618,11.378584,1.059831,-816.492310,0.107041,0.000000
79.710007,51.405647,-816.492310,-0.000457,0.004195,0.106564,228.663742,11.648686,1.065645,-816.492310,0.107709,0.000000
80.110001,52.615486,-816.581299,-0.000448,0.004221,0.107214,234.045364,11.922840,1.072140,-816.581299,0.108377,0.000000
80.510002,53.462631,-816.492310,-0.000444,0.004244,0.107795,237.813660,12.114805,1.077953,-816.492310,0.109044,0.000000
80.910004,54.338081,-816.492310,-0.000427,0.004258,0.108160,241.707855,12.313185,1.081602,-816.492310,0.109712,0.000000
81.310005,57.800774,-816.536804,-0.000401,0.004303,0.109287,257.110687,13.097842,1.092866,-816.536804,0.110380,0.000000
81.710007,58.973747,-816.581299,-0.000388,0.004324,0.109842,262.328339,13.363642,1.098422,-816.581299,0.111047,0.000000
82.110001,60.802841,-816.492310,-0.000384,0.004353,0.110561,270.464539,13.778120,1.105613,-816.492310,0.111715,0.000000
82.510002,61.044510,-816.581299,-0.000375,0.004368,0.110935,271.539551,13.832883,1.109353,-816.581299,0.112375,0.000000
82.910004,62.759285,-816.625793,-0.000354,0.004393,0.111585,279.167236,14.221457,1.115848,-816.625793,0.113043,0.000000
83.310005,66.015678,-816.581299,-0.000349,0.004429,0.112487,293.652405,14.959367,1.124871,-816.581299,0.113710,0.000000
83.710007,65.518562,-816.625793,-0.000319,0.004426,0.112427,291.441132,14.846719,1.124265,-816.625793,0.019731,0.000000
84.110001,65.169655,-816.581299,-0.000323,0.004437,0.112696,289.889099,14.767654,1.126960,-816.581299,294.500488,0.000000
84.510002,64.974159,-816.581299,-0.000315,0.004441,0.112799,289.019501,14.723354,1.127990,-816.581299,294.500488,0.000000
84.910004,65.576286,-816.625793,-0.000297,0.004452,0.113078,291.697876,14.859798,1.130775,-816.625793,294.500488,0.000000
85.310005,65.084007,-816.670288,-0.000297,0.004452,0.113078,289.508118,14.748247,1.130775,-816.670288,294.500488,0.000000
85.710007,64.693764,-816.625793,-0.000302,0.004452,0.113085,287.772247,14.659817,1.130851,-816.625793,294.500488,0.000000
86.110001,64.265907,-816.714722,-0.000297,0.004452,0.113085,285.869019,14.562863,1.130851,-816.714722,294.500488,0.000000
86.510002,66.664726,-816.670288,-0.000276,0.004284,0.108819,296.539520,15.106443,1.088188,-816.670288,294.500488,0.000000
86.910004,66.209694,-816.670288,-0.000293,0.004285,0.108828,294.515442,15.003331,1.088278,-816.670288,294.500488,0.000000
87.310005,65.830238,-816.625793,-0.000280,0.004289,0.108940,292.827515,14.917345,1.089399,-816.625793,294.500488,0.000000
87.710007,65.514091,-816.714722,-0.000263,0.004362,0.110805,291.421234,14.845706,1.108051,-816.714722,294.500488,0.000000
88.110001,65.295509,-816.670288,-0.000272,0.004429,0.112496,290.448944,14.796174,1.124962,-816.670288,294.500488,0.000000
88.510002,65.226997,-816.714722,-0.000276,0.004460,0.113294,290.144165,14.780648,1.132940,-816.714722,294.500488,0.000000
88.910004,64.970436,-816.670288,-0.000276,0.004460,0.113294,289.002930,14.722511,1.132940,-816.670288,294.500488,0.000000
89.310005,65.139122,-816.714722,-0.000276,0.004469,0.113520,289.753296,14.760736,1.135196,-816.714722,294.500488,0.000000
89.710007,64.987938,-816.759216,-0.000267,0.004469,0.113520,289.080780,14.726477,1.135196,-816.759216,294.500488,0.000000
90.110001,65.780708,-816.759216,-0.000263,0.004481,0.113822,292.607208,14.906121,1.138224,-816.759216,294.500488,0.000000
90.510002,65.740868,-816.803711,-0.000267,0.004481,0.113822,292.429993,14.897094,1.138224,-816.803711,294.500488,0.000000
90.910004,65.597878,-816.759216,-0.000259,0.004481,0.113822,291.793945,14.864691,1.138224,-816.759216,294.500488,0.000000
91.310005,65.487663,-816.759216,-0.000259,0.004481,0.113822,291.303680,14.839716,1.138224,-816.759216,294.500488,0.000000
91.710007,65.308174,-816.803711,-0.000263,0.004482,0.113831,290.505280,14.799045,1.138315,-816.803711,294.500488,0.000000
92.110001,65.209129,-816.803711,-0.000254,0.004482,0.113841,290.064697,14.776600,1.138406,-816.803711,294.500488,0.000000
92.510002,65.099648,-816.759216,-0.000259,0.004483,0.113866,289.577698,14.751791,1.138663,-816.759216,294.500488,0.000000
92.910004,65.009163,-816.803711,-0.000254,0.004483,0.113866,289.175201,14.731286,1.138663,-816.803711,294.500488,0.000000
93.310005,64.926872,-816.803711,-0.000272,0.004483,0.113866,288.809143,14.712640,1.138663,-816.803711,294.500488,0.000000
93.710007,65.011772,-816.848206,-0.000254,0.004486,0.113944,289.186798,14.731878,1.139435,-816.848206,294.500488,0.000000
94.110008,64.987190,-816.892639,-0.000263,0.004486,0.113944,289.077454,14.726308,1.139435,-816.892639,294.500488,0.000000
94.510002,64.919044,-816.937134,-0.000254,0.004486,0.113944,288.774323,14.710866,1.139435,-816.937134,294.500488,0.000000
94.910004,64.808449,-816.892639,-0.000254,0.004486,0.113953,288.282379,14.685804,1.139526,-816.892639,294.500488,0.000000
95.310005,65.321953,-816.892639,-0.000246,0.004495,0.114162,290.566559,14.802166,1.141615,-816.892639,294.500488,0.000000
95.710007,65.411690,-816.848206,-0.000254,0.004495,0.114162,290.965729,14.822501,1.141615,-816.848206,294.500488,0.000000
96.110008,65.364769,-816.892639,-0.000250,0.004495,0.114162,290.757019,14.811869,1.141615,-816.892639,294.500488,0.000000
96.510002,65.315254,-816.937134,-0.000259,0.004495,0.114162,290.536774,14.800649,1.141615,-816.937134,294.500488,0.000000
96.910004,65.266472,-816.892639,-0.000259,0.004495,0.114162,290.319763,14.789594,1.141615,-816.892639,294.500488,0.000000
97.310005,65.221046,-816.892639,-0.000241,0.004495,0.114162,290.117706,14.779301,1.141615,-816.892639,294.500488,0.000000
97.710007,65.124962,-816.937134,-0.000254,0.004495,0.114162,289.690308,14.757527,1.141615,-816.937134,294.500488,0.000000
98.110008,65.070229,-816.981628,-0.000237,0.004495,0.114169,289.446838,14.745125,1.141691,-816.981628,294.500488,0.000000
98.510002,65.030006,-816.892639,-0.000250,0.004495,0.114178,289.267914,14.736011,1.141782,-816.892639,294.500488,0.000000
98.910004,64.990547,-816.981628,-0.000250,0.004495,0.114178,289.092407,14.727069,1.141782,-816.981628,294.500488,0.000000
99.310005,64.948097,-816.937134,-0.000263,0.004495,0.114178,288.903564,14.717449,1.141782,-816.937134,294.500488,0.000000
99.710007,64.870644,-816.981628,-0.000250,0.004495,0.114178,288.559021,14.699898,1.141782,-816.981628,294.500488,0.000000
100.110008,64.904900,-816.937134,-0.000237,0.004498,0.114248,288.711426,14.707661,1.142478,-816.937134,294.500488,0.000000
100.510002,64.948830,-816.937134,-0.000246,0.004498,0.114248,288.906830,14.717615,1.142478,-816.937134,294.500488,0.000000
100.910004,64.916069,-816.937134,-0.000237,0.004498,0.114248,288.761108,14.710192,1.142478,-816.937134,294.500488,0.000000
101.310005,64.884041,-816.981628,-0.000241,0.004498,0.114248,288.618622,14.702934,1.142478,-816.981628,294.500488,0.000000
101.710007,64.833778,-817.026123,-0.000250,0.004498,0.114248,288.395050,14.691544,1.142478,-817.026123,294.500488,0.000000
102.110008,64.782005,-816.981628,-0.000246,0.004498,0.114248,288.164764,14.679812,1.142478,-816.981628,294.500488,0.000000
102.510002,64.751106,-817.026123,-0.000237,0.004498,0.114248,288.027313,14.672811,1.142478,-817.026123,294.500488,0.000000
102.910004,64.846809,-816.937134,-0.000250,0.004501,0.114317,288.453003,14.694497,1.143175,-816.937134,294.500488,0.000000
103.310005,64.857979,-816.981628,-0.000250,0.004501,0.114317,288.502686,14.697028,1.143175,-816.981628,294.500488,0.000000
103.710007,64.837120,-817.026123,-0.000250,0.004501,0.114317,288.409912,14.692301,1.143175,-817.026123,294.500488,0.000000
104.110008,64.805107,-817.026123,-0.000237,0.004501,0.114317,288.267517,14.685047,1.143175,-817.026123,294.500488,0.000000
104.510002,64.781273,-817.026123,-0.000233,0.004501,0.114317,288.161499,14.679646,1.143175,-817.026123,294.500488,0.000000
104.910004,64.749611,-817.026123,-0.000229,0.004501,0.114317,288.020660,14.672471,1.143175,-817.026123,294.500488,0.000000
105.310005,64.840477,-817.115051,-0.000250,0.004508,0.114516,288.424835,14.693062,1.145158,-817.115051,294.500488,0.000000
105.710007,65.554314,-817.115051,-0.000237,0.004510,0.114560,291.600159,14.854820,1.145597,-817.115051,294.500488,0.000000
106.110008,65.570702,-817.070618,-0.000237,0.004510,0.114560,291.673035,14.858533,1.145597,-817.070618,294.500488,0.000000
106.510002,65.562126,-817.070618,-0.000246,0.004510,0.114560,291.634888,14.856590,1.145597,-817.070618,294.500488,0.000000
106.910004,65.555428,-817.070618,-0.000229,0.004510,0.114560,291.605103,14.855073,1.145597,-817.070618,294.500488,0.000000
107.310005,65.531227,-817.026123,-0.000233,0.004510,0.114560,291.497467,14.849588,1.145597,-817.026123,294.500488,0.000000
107.710007,65.507027,-817.115051,-0.000229,0.004510,0.114560,291.389801,14.844105,1.145597,-817.115051,294.500488,0.000000
108.110008,65.492500,-817.115051,-0.000233,0.004510,0.114560,291.325195,14.840813,1.145597,-817.115051,294.500488,0.000000
108.510002,65.436272,-817.159546,-0.000233,0.004510,0.114560,291.075073,14.828072,1.145597,-817.159546,294.500488,0.000000
108.910004,65.379677,-817.070618,-0.000233,0.004510,0.114560,290.823334,14.815247,1.145597,-817.070618,294.500488,0.000000
109.310005,65.345787,-817.026123,-0.000233,0.004510,0.114560,290.672577,14.807567,1.145597,-817.026123,294.500488,0.000000
109.710007,65.326042,-817.159546,-0.000233,0.004510,0.114560,290.584747,14.803092,1.145597,-817.159546,294.500488,0.000000
110.110008,65.301094,-817.159546,-0.000229,0.004510,0.114560,290.473785,14.797440,1.145597,-817.159546,294.500488,0.000000
110.510002,65.269814,-817.115051,-0.000224,0.004510,0.114560,290.334625,14.790351,1.145597,-817.115051,294.500488,0.000000
110.910004,65.241524,-817.070618,-0.000233,0.004511,0.114569,290.208801,14.783940,1.145688,-817.070618,294.500488,0.000000
111.310005,65.237419,-817.159546,-0.000229,0.004511,0.114569,290.190521,14.783010,1.145688,-817.159546,294.500488,0.000000
111.710007,65.193108,-817.204041,-0.000233,0.004511,0.114569,289.993439,14.772969,1.145688,-817.204041,294.500488,0.000000
112.110008,65.163689,-817.159546,-0.000229,0.004511,0.114569,289.862549,14.766303,1.145688,-817.159546,294.500488,0.000000
112.510002,65.102623,-817.204041,-0.000229,0.004511,0.114569,289.590942,14.752465,1.145688,-817.204041,294.500488,0.000000
112.910004,65.083641,-817.159546,-0.000229,0.004511,0.114569,289.506500,14.748164,1.145688,-817.159546,294.500488,0.000000
113.310005,65.050117,-817.159546,-0.000224,0.004511,0.114569,289.357361,14.740567,1.145688,-817.159546,294.500488,0.000000
113.710007,65.021446,-817.204041,-0.000216,0.004511,0.114569,289.229828,14.734070,1.145688,-817.204041,294.500488,0.000000
114.110008,65.002464,-817.204041,-0.000229,0.004511,0.114569,289.145416,14.729769,1.145688,-817.204041,294.500488,0.000000
114.510002,64.967079,-817.248535,-0.000211,0.004511,0.114569,288.988007,14.721750,1.145688,-817.248535,294.500488,0.000000
114.910004,64.925743,-817.248535,-0.000216,0.004511,0.114569,288.804138,14.712383,1.145688,-817.248535,294.500488,0.000000
115.310005,64.902290,-817.204041,-0.000233,0.004511,0.114569,288.699799,14.707069,1.145688,-817.204041,294.500488,0.000000
115.710007,64.842339,-817.248535,-0.000224,0.004511,0.114569,288.433136,14.693484,1.145688,-817.248535,294.500488,0.000000
116.110008,64.808830,-817.248535,-0.000224,0.004511,0.114569,288.284088,14.685891,1.145688,-817.248535,294.500488,0.000000
116.510002,64.796165,-817.204041,-0.000224,0.004511,0.114569,288.227753,14.683022,1.145688,-817.204041,294.500488,0.000000
116.910004,64.760414,-817.248535,-0.000220,0.004511,0.114569,288.068695,14.674920,1.145688,-817.248535,294.500488,0.000000
117.310005,64.752968,-817.292969,-0.000229,0.004511,0.114569,288.035583,14.673232,1.145688,-817.292969,294.500488,0.000000
117.710007,64.726158,-817.337463,-0.000220,0.004511,0.114569,287.916321,14.667156,1.145688,-817.337463,294.500488,0.000000
118.110008,64.703072,-817.248535,-0.000224,0.004511,0.114569,287.813629,14.661925,1.145688,-817.248535,294.500488,0.000000
118.510002,64.682961,-817.248535,-0.000229,0.004511,0.114569,287.724182,14.657369,1.145688,-817.248535,294.500488,0.000000
118.910004,64.643867,-817.292969,-0.000224,0.004511,0.114569,287.550293,14.648510,1.145688,-817.292969,294.500488,0.000000
119.310005,64.630836,-817.292969,-0.000220,0.004511,0.114569,287.492310,14.645557,1.145688,-817.292969,294.500488,0.000000
119.710007,65.712944,-817.337463,-0.000211,0.004525,0.114925,292.305786,14.890766,1.149246,-817.337463,294.500488,0.000000
120.110008,65.843269,-817.292969,-0.000224,0.004524,0.114915,292.885498,14.920299,1.149155,-817.292969,294.500488,0.000000
120.510002,65.862267,-817.337463,-0.000224,0.004524,0.114915,292.970001,14.924603,1.149155,-817.337463,294.500488,0.000000
120.910004,65.839546,-817.292969,-0.000216,0.004524,0.114899,292.868927,14.919454,1.148988,-817.292969,294.500488,0.000000
121.310005,65.876411,-817.337463,-0.000220,0.004523,0.114881,293.032898,14.927808,1.148806,-817.337463,294.500488,0.000000
121.710007,65.804543,-817.381958,-0.000224,0.004523,0.114881,292.713226,14.911522,1.148806,-817.381958,294.500488,0.000000
122.110008,65.864876,-817.381958,-0.000220,0.004523,0.114881,292.981598,14.925194,1.148806,-817.381958,294.500488,0.000000
122.510002,65.803429,-817.381958,-0.000216,0.004523,0.114881,292.708282,14.911270,1.148806,-817.381958,294.500488,0.000000
122.910004,65.815346,-817.381958,-0.000211,0.004523,0.114881,292.761292,14.913971,1.148806,-817.381958,294.500488,0.000000
123.310005,65.773643,-817.381958,-0.000211,0.004523,0.114881,292.575775,14.904521,1.148806,-817.381958,294.500488,0.000000
123.710007,65.798592,-817.426453,-0.000229,0.004523,0.114881,292.686768,14.910174,1.148806,-817.426453,294.500488,0.000000
124.110008,65.778114,-817.470947,-0.000216,0.004523,0.114881,292.595673,14.905534,1.148806,-817.470947,294.500488,0.000000
124.510002,65.763954,-817.426453,-0.000224,0.004523,0.114881,292.532684,14.902325,1.148806,-817.426453,294.500488,0.000000
124.910004,65.680168,-817.470947,-0.000224,0.004523,0.114881,292.159973,14.883339,1.148806,-817.470947,294.500488,0.000000
125.310005,65.619484,-817.426453,-0.000220,0.004523,0.114881,291.890045,14.869588,1.148806,-817.426453,294.500488,0.000000
125.710007,65.612770,-817.470947,-0.000220,0.004523,0.114881,291.860168,14.868067,1.148806,-817.470947,294.500488,0.000000
126.110008,65.597130,-817.470947,-0.000216,0.004523,0.114881,291.790619,14.864522,1.148806,-817.470947,294.500488,0.000000
126.510010,65.584099,-817.470947,-0.000224,0.004523,0.114881,291.732635,14.861569,1.148806,-817.470947,294.500488,0.000000
126.910004,65.587822,-817.426453,-0.000207,0.004523,0.114881,291.749207,14.862412,1.148806,-817.426453,294.500488,0.000000
127.310005,65.567345,-817.470947,-0.000198,0.004523,0.114881,291.658112,14.857773,1.148806,-817.470947,294.500488,0.000000
127.710007,65.550591,-817.470947,-0.000207,0.004523,0.114881,291.583588,14.853976,1.148806,-817.470947,294.500488,0.000000
128.110001,65.536812,-817.515381,-0.000198,0.004523,0.114881,291.522308,14.850854,1.148806,-817.515381,294.500488,0.000000
128.510010,65.523399,-817.559875,-0.000207,0.004523,0.114881,291.462646,14.847815,1.148806,-817.559875,294.500488,0.000000
128.910004,65.502174,-817.515381,-0.000211,0.004523,0.114881,291.368225,14.843005,1.148806,-817.515381,294.500488,0.000000
129.310013,65.499947,-817.559875,-0.000203,0.004523,0.114881,291.358307,14.842500,1.148806,-817.559875,294.500488,0.000000
129.710007,65.449303,-817.515381,-0.000211,0.004523,0.114881,291.133026,14.831024,1.148806,-817.515381,294.500488,0.000000
130.110001,65.415047,-817.559875,-0.000207,0.004523,0.114881,290.980652,14.823262,1.148806,-817.559875,294.500488,0.000000
130.510010,65.388603,-817.559875,-0.000229,0.004523,0.114881,290.863037,14.817269,1.148806,-817.559875,294.500488,0.000000
130.910004,65.357323,-817.559875,-0.000198,0.004523,0.114881,290.723877,14.810181,1.148806,-817.559875,294.500488,0.000000
131.310013,65.338707,-817.559875,-0.000211,0.004523,0.114881,290.641083,14.805963,1.148806,-817.559875,294.500488,0.000000
131.710007,65.328651,-817.604370,-0.000207,0.004523,0.114881,290.596344,14.803684,1.148806,-817.604370,294.500488,0.000000
132.110001,65.317116,-817.604370,-0.000207,0.004523,0.114881,290.545044,14.801069,1.148806,-817.604370,294.500488,0.000000
132.510010,65.309669,-817.604370,-0.000203,0.004523,0.114881,290.511932,14.799383,1.148806,-817.604370,294.500488,0.000000
132.910004,65.296638,-817.648865,-0.000216,0.004523,0.114881,290.453949,14.796430,1.148806,-817.648865,294.500488,0.000000
133.310013,65.290672,-817.737793,-0.000220,0.004523,0.114881,290.427429,14.795078,1.148806,-817.737793,294.500488,0.000000
133.710007,65.263496,-817.693298,-0.000211,0.004523,0.114881,290.306519,14.788919,1.148806,-817.693298,294.500488,0.000000
134.110001,65.249718,-817.693298,-0.000211,0.004523,0.114881,290.245239,14.785798,1.148806,-817.693298,294.500488,0.000000
134.510010,65.234825,-817.737793,-0.000207,0.004523,0.114881,290.178986,14.782422,1.148806,-817.737793,294.500488,0.000000
134.910004,65.233330,-817.693298,-0.000203,0.004523,0.114881,290.172333,14.782084,1.148806,-817.693298,294.500488,0.000000
135.310013,65.206139,-817.782288,-0.000216,0.004523,0.114881,290.051392,14.775923,1.148806,-817.782288,294.500488,0.000000
135.710007,65.212471,-817.782288,-0.000216,0.004523,0.114881,290.079559,14.777357,1.148806,-817.782288,294.500488,0.000000
136.110001,65.179329,-817.693298,-0.000224,0.004523,0.114881,289.932129,14.769847,1.148806,-817.693298,294.500488,0.000000
136.510010,65.140236,-817.782288,-0.000220,0.004523,0.114881,289.758240,14.760988,1.148806,-817.782288,294.500488,0.000000
136.910004,65.123848,-817.826782,-0.000203,0.004523,0.114881,289.685333,14.757275,1.148806,-817.826782,294.500488,0.000000
137.310013,65.096672,-817.782288,-0.000203,0.004523,0.114881,289.564453,14.751117,1.148806,-817.782288,294.500488,0.000000
137.710007,65.092567,-817.782288,-0.000211,0.004523,0.114881,289.546204,14.750187,1.148806,-817.782288,294.500488,0.000000
138.110001,65.062035,-817.826782,-0.000203,0.004523,0.114881,289.410370,14.743267,1.148806,-817.826782,294.500488,0.000000
138.510010,65.063530,-817.782288,-0.000203,0.004523,0.114881,289.417023,14.743607,1.148806,-817.782288,294.500488,0.000000
138.910004,65.044533,-817.871277,-0.000207,0.004523,0.114881,289.332520,14.739302,1.148806,-817.871277,294.500488,0.000000
139.310013,65.033730,-817.782288,-0.000207,0.004523,0.114881,289.284485,14.736854,1.148806,-817.782288,294.500488,0.000000
139.710007,65.009163,-817.782288,-0.000207,0.004523,0.114881,289.175201,14.731286,1.148806,-817.782288,294.500488,0.000000
140.110001,65.018837,-817.826782,-0.000203,0.004523,0.114881,289.218231,14.733479,1.148806,-817.826782,294.500488,0.000000
140.510010,64.999855,-817.826782,-0.000203,0.004523,0.114881,289.133789,14.729177,1.148806,-817.826782,294.500488,0.000000
140.910004,65.001717,-817.826782,-0.000198,0.004523,0.114881,289.142090,14.729600,1.148806,-817.826782,294.500488,0.000000
141.310013,64.982719,-817.871277,-0.000203,0.004523,0.114881,289.057587,14.725295,1.148806,-817.871277,294.500488,0.000000
141.710007,64.980110,-817.871277,-0.000211,0.004523,0.114881,289.045959,14.724703,1.148806,-817.871277,294.500488,0.000000
142.110001,64.963356,-817.915710,-0.000207,0.004523,0.114881,288.971436,14.720907,1.148806,-817.915710,294.500488,0.000000
142.510010,64.960014,-817.871277,-0.000211,0.004523,0.114881,288.956573,14.720150,1.148806,-817.871277,294.500488,0.000000
142.910004,64.948097,-817.915710,-0.000207,0.004523,0.114881,288.903564,14.717449,1.148806,-817.915710,294.500488,0.000000
143.310013,64.933937,-817.915710,-0.000198,0.004523,0.114881,288.840576,14.714240,1.148806,-817.915710,294.500488,0.000000
143.710007,64.916069,-817.915710,-0.000198,0.004523,0.114881,288.761108,14.710192,1.148806,-817.915710,294.500488,0.000000
144.110001,64.930595,-817.915710,-0.000198,0.004522,0.114855,288.825714,14.713483,1.148549,-817.915710,0.114881,0.000000
144.510010,64.809944,-817.915710,-0.000194,0.004508,0.114499,288.289032,14.686143,1.144991,-817.915710,0.114274,0.000000
144.910004,64.802864,-817.915710,-0.000190,0.004490,0.114048,288.257538,14.684539,1.140480,-817.915710,0.113606,0.000000
145.310013,64.741798,-817.960205,-0.000194,0.004466,0.113441,287.985901,14.670701,1.134409,-817.960205,0.112938,0.000000
145.710007,64.736580,-818.049194,-0.000194,0.004443,0.112843,287.962677,14.669519,1.128429,-818.049194,0.112280,0.000000
146.110001,64.714607,-818.004700,-0.000203,0.004414,0.112106,287.864960,14.664539,1.121056,-818.004700,0.111612,0.000000
146.510010,64.694878,-818.004700,-0.000211,0.004390,0.111498,287.777191,14.660069,1.114985,-818.004700,0.110943,0.000000
146.910004,64.695625,-817.915710,-0.000207,0.004365,0.110875,287.780518,14.660238,1.108747,-817.915710,0.110275,0.000000
147.310013,64.631569,-818.004700,-0.000190,0.004338,0.110180,287.495575,14.645722,1.101798,-818.004700,0.109608,0.000000
147.710007,64.611473,-818.004700,-0.000194,0.004312,0.109530,287.406189,14.641169,1.095303,-818.004700,0.108940,0.000000
148.110001,64.461403,-818.004700,-0.000203,0.004290,0.108966,286.738647,14.607162,1.089656,-818.004700,0.108272,0.000000
148.510010,63.773994,-818.004700,-0.000190,0.004265,0.108325,283.680908,14.451394,1.083252,-818.004700,0.107605,0.000000
148.910004,62.824821,-818.004700,-0.000190,0.004240,0.107700,279.458771,14.236308,1.076999,-818.004700,0.106946,0.000000
149.310013,61.684990,-818.004700,-0.000198,0.004215,0.107058,274.388550,13.978019,1.070580,-818.004700,0.106278,0.000000
149.710007,60.473289,-818.004700,-0.000194,0.004197,0.106599,268.998627,13.703444,1.065993,-818.004700,0.105611,0.000000
150.110001,58.287094,-818.004700,-0.000190,0.004165,0.105792,259.273956,13.208044,1.057924,-818.004700,0.104943,0.000000
150.510010,56.390602,-818.004700,-0.000198,0.004141,0.105185,250.837921,12.778293,1.051853,-818.004700,0.104274,0.000000
150.910004,54.149292,-818.004700,-0.000194,0.004119,0.104613,240.868088,12.270405,1.046130,-818.004700,0.103606,0.000000
151.310013,51.536728,-818.049194,-0.000194,0.004091,0.103901,229.246811,11.678390,1.039014,-818.049194,0.102939,0.000000
151.710007,49.555702,-818.049194,-0.000211,0.004073,0.103443,220.434769,11.229483,1.034427,-818.049194,0.102271,0.000000
152.110001,46.309357,-818.049194,-0.000194,0.004043,0.102696,205.994308,10.493851,1.026963,-818.049194,0.101612,0.000000
152.510010,43.406715,-818.049194,-0.000198,0.004018,0.102063,193.082718,9.836102,1.020635,-818.049194,0.100945,0.000000
152.910004,40.562538,-818.049194,-0.000203,0.003990,0.101335,180.431183,9.191603,1.013353,-818.049194,0.100277,0.000000
153.310013,37.892624,-818.093628,-0.000198,0.003966,0.100736,168.554810,8.586592,1.007357,-818.093628,0.099609,0.000000
153.710007,34.427696,-818.049194,-0.000203,0.003935,0.099956,153.142044,7.801427,0.999560,-818.049194,0.098942,0.000000
154.110001,32.083984,-818.049194,-0.000211,0.003915,0.099444,142.716690,7.270335,0.994443,-818.049194,0.098274,0.000000
154.510010,29.172409,-818.093628,-0.000220,0.003888,0.098768,129.765350,6.610563,0.987676,-818.093628,0.097605,0.000000
154.910004,26.657402,-818.049194,-0.000207,0.003863,0.098117,118.578049,6.040654,0.981166,-818.049194,0.096937,0.000000
155.310013,23.346642,-818.138123,-0.000220,0.003837,0.097458,103.851051,5.290425,0.974580,-818.138123,0.096279,0.000000
155.710007,19.882828,-818.093628,-0.000216,0.003803,0.096591,88.443237,4.505513,0.965905,-818.093628,0.095611,0.000000
156.110001,17.700356,-818.138123,-0.000224,0.003787,0.096183,78.735115,4.010958,0.961833,-818.138123,0.094943,0.000000
156.510010,14.236923,-818.182617,-0.000233,0.003753,0.095334,63.328999,3.226133,0.953339,-818.182617,0.094276,0.000000
156.910004,11.577065,-818.138123,-0.000246,0.003727,0.094674,51.497356,2.623400,0.946738,-818.138123,0.093608,0.000000
157.310013,8.502754,-818.138123,-0.000254,0.003701,0.094015,37.822140,1.926752,0.940153,-818.138123,0.092940,0.000000
157.710007,5.787041,-818.182617,-0.000254,0.003675,0.093357,25.742043,1.311362,0.933567,-818.182617,0.092273,0.000000
158.110001,2.589851,-818.138123,-0.000254,0.003646,0.092619,11.520234,0.586869,0.926194,-818.138123,0.091605,0.000000
158.510010,0.438286,-818.182617,-0.000267,0.003627,0.092117,1.949593,0.099317,0.921168,-818.182617,0.090936,0.000000
158.910004,-2.169067,-818.138123,-0.000276,0.003597,0.091352,-9.648494,-0.491518,0.913522,-818.138123,0.090277,0.000000
159.310013,-0.166451,-818.182617,-0.000319,0.003570,0.090677,-0.740409,-0.037718,0.906770,-818.182617,0.089610,0.000000
159.710007,-0.010048,-818.138123,-0.000379,0.003546,0.090070,-0.044695,-0.002277,0.900699,-818.138123,0.088942,0.000000
160.110001,-0.027924,-818.182617,-0.000410,0.003520,0.089402,-0.124210,-0.006328,0.894022,-818.182617,0.088274,0.000000
160.510010,0.014153,-818.182617,-0.000461,0.003492,0.088707,0.062954,0.003207,0.887073,-818.182617,0.087607,0.000000
160.910004,-0.015266,-818.182617,-0.000517,0.003462,0.087928,-0.067908,-0.003459,0.879277,-818.182617,0.086939,0.000000
161.310013,0.018250,-818.182617,-0.000578,0.003435,0.087242,0.081178,0.004135,0.872418,-818.182617,0.086271,0.000000
161.710007,0.016388,-818.227112,-0.000634,0.003412,0.086653,0.072897,0.003714,0.866529,-818.227112,0.085604,0.000000
162.110001,0.044319,-818.227112,-0.000690,0.003392,0.086150,0.197141,0.010043,0.861503,-818.227112,0.084944,0.000000
162.510010,-0.002228,-818.271545,-0.000742,0.003360,0.085352,-0.009910,-0.000505,0.853524,-818.271545,0.084276,0.000000
162.910004,0.007454,-818.227112,-0.000780,0.003333,0.084667,0.033157,0.001689,0.846666,-818.227112,0.083608,0.000000
163.310013,0.010429,-818.316040,-0.000828,0.003307,0.084008,0.046392,0.002363,0.840080,-818.316040,0.082941,0.000000
163.710007,0.001122,-818.227112,-0.000867,0.003285,0.083427,0.004989,0.000254,0.834267,-818.227112,0.082273,0.000000
164.110001,0.002235,-818.227112,-0.000914,0.003256,0.082698,0.009944,0.000507,0.826984,-818.227112,0.081605,0.000000
164.510010,-0.034256,-818.227112,-0.000974,0.003229,0.082022,-0.152378,-0.007763,0.820217,-818.227112,0.080938,0.000000
164.910004,-0.016754,-818.405029,-0.001030,0.003197,0.081215,-0.074526,-0.003797,0.812148,-818.405029,0.080270,0.000000
165.310013,-0.040215,-818.360535,-0.001074,0.003173,0.080599,-0.178883,-0.009113,0.805986,-818.360535,0.079610,0.000000
165.700012,0.024582,-818.271545,-0.001108,0.003161,0.080296,0.109346,0.005570,0.802958,-818.271545,0.080191,0.000000