File: Data/compression 35/ManualNoHeating-17-35-reverse-1-1_11182024_180329.csv
Time (sec),S:Load (lbs),S:HL1 (DIM),S:LVDT (in),S:Position (in),Ch:Position (mm),Ch:Load (N),Ch:Stress (MPa),Ch:Strain (mm/mm),Ch:HL1 (DIM),Set Point (),Cycles ()
0.110000,-0.067024,-887.128113,-0.013517,-0.008020,-0.203703,-0.298139,-0.015188,-2.037030,-887.128113,-0.203459,0.000000
0.470000,-0.019730,-887.083618,-0.013517,-0.007975,-0.202566,-0.087762,-0.004471,-2.025661,-887.083618,-0.202003,0.000000
0.830000,-0.094955,-887.128113,-0.013473,-0.007787,-0.197788,-0.422383,-0.021517,-1.977880,-887.128113,-0.196002,0.000000
1.190000,-0.017128,-887.128113,-0.013223,-0.007538,-0.191475,-0.076189,-0.003881,-1.914748,-887.128113,-0.190000,0.000000
1.550000,-0.018990,-887.128113,-0.012956,-0.007289,-0.185143,-0.084470,-0.004303,-1.851434,-887.128113,-0.184017,0.000000
1.910000,0.016388,-887.172546,-0.012732,-0.007067,-0.179490,0.072897,0.003714,-1.794903,-887.172546,-0.178016,0.000000
2.270000,-0.018242,-887.128113,-0.012482,-0.006827,-0.173394,-0.081144,-0.004134,-1.733936,-887.128113,-0.172014,0.000000
2.630000,-0.022713,-887.128113,-0.012223,-0.006583,-0.167211,-0.101031,-0.005147,-1.672106,-887.128113,-0.166013,0.000000
2.990000,-0.067024,-887.217041,-0.012016,-0.006367,-0.161712,-0.298139,-0.015188,-1.617119,-887.217041,-0.160012,0.000000
3.350000,-0.014893,-887.172546,-0.011749,-0.006120,-0.155459,-0.066245,-0.003375,-1.554593,-887.172546,-0.154029,0.000000
3.710000,0.004471,-887.261536,-0.011507,-0.005872,-0.149137,0.019887,0.001013,-1.491370,-887.261536,-0.148027,0.000000
4.070000,-0.007446,-887.172546,-0.011262,-0.005649,-0.143491,-0.033123,-0.001687,-1.434914,-887.172546,-0.142026,0.000000
4.430000,-0.019363,-887.217041,-0.011012,-0.005410,-0.137420,-0.086133,-0.004388,-1.374205,-887.217041,-0.136025,0.000000
4.790000,-0.031647,-887.217041,-0.010762,-0.005171,-0.131333,-0.140772,-0.007171,-1.313328,-887.217041,-0.130040,0.000000
5.150000,0.011917,-887.172546,-0.010524,-0.004936,-0.125383,0.053010,0.002700,-1.253830,-887.172546,-0.124040,0.000000
5.510000,0.006332,-887.261536,-0.010261,-0.004698,-0.119330,0.028168,0.001435,-1.193302,-887.261536,-0.118039,0.000000
5.870000,0.015274,-887.261536,-0.010020,-0.004455,-0.113147,0.067942,0.003461,-1.131472,-887.261536,-0.112037,0.000000
6.230000,0.013779,-887.306030,-0.009796,-0.004233,-0.107518,0.061291,0.003122,-1.075183,-887.306030,-0.106036,0.000000
6.590000,-0.030159,-887.306030,-0.009546,-0.003991,-0.101379,-0.134154,-0.006834,-1.013792,-887.306030,-0.100051,0.000000
6.950000,-0.040215,-887.261536,-0.009300,-0.003758,-0.095464,-0.178883,-0.009113,-0.954641,-887.261536,-0.094050,0.000000
7.310000,-0.024200,-887.350464,-0.009067,-0.003509,-0.089134,-0.107649,-0.005484,-0.891343,-887.350464,-0.088050,0.000000
7.670001,0.022346,-887.306030,-0.008830,-0.003281,-0.083331,0.099402,0.005064,-0.833313,-887.306030,-0.082049,0.000000
8.030001,0.042824,-887.306030,-0.008580,-0.003043,-0.077297,0.190490,0.009704,-0.772966,-887.306030,-0.076048,0.000000
8.390000,0.014153,-887.350464,-0.008326,-0.002812,-0.071426,0.062954,0.003207,-0.714255,-887.350464,-0.070063,0.000000
8.750000,-0.010796,-887.350464,-0.008080,-0.002571,-0.065311,-0.048021,-0.002446,-0.653106,-887.350464,-0.064062,0.000000
9.110001,-0.075592,-887.350464,-0.007847,-0.002342,-0.059492,-0.336250,-0.017129,-0.594925,-887.350464,-0.058060,0.000000
9.470000,-0.032768,-887.350464,-0.007588,-0.002099,-0.053326,-0.145760,-0.007425,-0.533261,-887.350464,-0.052059,0.000000
9.830001,0.010056,-887.350464,-0.007360,-0.001867,-0.047429,0.044729,0.002279,-0.474293,-887.350464,-0.046059,0.000000
10.190001,0.043571,-887.439453,-0.007110,-0.001629,-0.041375,0.193816,0.009873,-0.413750,-887.439453,-0.040074,0.000000
10.550000,0.015274,-887.306030,-0.006860,-0.001393,-0.035374,0.067942,0.003461,-0.353736,-887.306030,-0.034073,0.000000
10.910001,-0.002228,-887.350464,-0.006627,-0.001166,-0.029607,-0.009910,-0.000505,-0.296070,-887.350464,-0.028072,0.000000
11.270000,-0.080803,-887.306030,-0.006372,-0.000926,-0.023510,-0.359429,-0.018310,-0.235103,-887.306030,-0.022070,0.000000
11.630000,-0.070374,-887.394958,-0.006131,-0.000685,-0.017388,-0.313037,-0.015947,-0.173878,-887.394958,-0.016087,0.000000
11.990001,0.017876,-887.394958,-0.005885,-0.000449,-0.011412,0.079515,0.004051,-0.114122,-887.394958,-0.010086,0.000000
12.350000,0.060699,-887.394958,-0.005661,-0.000220,-0.005576,0.270005,0.013755,-0.055759,-887.394958,-0.004085,0.000000
12.710001,0.031281,-887.394958,-0.005407,0.000025,0.000624,0.139143,0.007088,0.006238,-887.394958,0.001917,0.000000
13.070001,0.002609,-887.394958,-0.005191,0.000239,0.006062,0.011607,0.000591,0.060619,-887.394958,0.007918,0.000000
13.430000,0.150444,-887.394958,-0.005044,-0.000008,-0.000191,0.669208,0.034091,-0.001908,-887.394958,0.000042,0.000000
13.790001,0.209274,-887.439453,-0.005053,-0.000008,-0.000191,0.930899,0.047422,-0.001908,-887.439453,0.000130,0.000000
14.150001,0.184326,-887.439453,-0.005057,-0.000008,-0.000191,0.819924,0.041769,-0.001908,-887.439453,0.000737,0.000000
14.510000,0.233856,-887.439453,-0.005053,0.000007,0.000173,1.040244,0.052993,0.001726,-887.439453,0.001335,0.000000
14.870001,0.544411,-887.439453,-0.005036,0.000038,0.000963,2.421660,0.123365,0.009629,-887.439453,0.001933,0.000000
15.230000,0.791298,-887.394958,-0.004997,0.000059,0.001508,3.519869,0.179311,0.015079,-887.394958,0.002531,0.000000
15.590001,0.986046,-887.528442,-0.004988,0.000074,0.001873,4.386151,0.223441,0.018728,-887.528442,0.003131,0.000000
15.950001,1.276497,-887.483948,-0.004971,0.000098,0.002489,5.678142,0.289258,0.024889,-887.483948,0.003738,0.000000
16.310001,1.718506,-887.528442,-0.004958,0.000119,0.003026,7.644296,0.389419,0.030264,-887.528442,0.004336,0.000000
16.670000,2.397339,-887.528442,-0.004924,0.000151,0.003824,10.663896,0.543245,0.038243,-887.528442,0.004934,0.000000
17.030001,2.745880,-887.439453,-0.004898,0.000172,0.004362,12.214285,0.622225,0.043617,-887.439453,0.005532,0.000000
17.390001,3.122345,-887.528442,-0.004894,0.000190,0.004822,13.888885,0.707533,0.048220,-887.528442,0.006132,0.000000
17.750000,3.877144,-887.439453,-0.004859,0.000227,0.005767,17.246397,0.878573,0.057667,-887.439453,0.006739,0.000000
18.110001,3.955345,-887.528442,-0.004846,0.000238,0.006044,17.594254,0.896294,0.060437,-887.528442,0.007337,0.000000
18.470001,4.162384,-887.528442,-0.004829,0.000249,0.006330,18.515209,0.943210,0.063299,-887.528442,0.007935,0.000000
18.830002,5.417274,-887.528442,-0.004807,0.000292,0.007414,24.097240,1.227572,0.074139,-887.528442,0.008533,0.000000
19.190001,6.111008,-887.617371,-0.004773,0.000326,0.008281,27.183121,1.384774,0.082814,-887.617371,0.009132,0.000000
19.550001,6.076378,-887.528442,-0.004764,0.000341,0.008672,27.029079,1.376927,0.086720,-887.528442,0.009739,0.000000
19.910002,6.653923,-887.572876,-0.004730,0.000363,0.009209,29.598127,1.507800,0.092094,-887.572876,0.010337,0.000000
20.270000,6.902672,-887.572876,-0.004721,0.000380,0.009651,30.704618,1.564168,0.096515,-887.572876,0.010935,0.000000
20.630001,7.447083,-887.528442,-0.004712,0.000408,0.010354,33.126278,1.687533,0.103540,-887.528442,0.011533,0.000000
20.990002,7.963188,-887.617371,-0.004678,0.000429,0.010891,35.422031,1.804484,0.108914,-887.617371,0.012133,0.000000
21.350000,8.204857,-887.572876,-0.004656,0.000448,0.011386,36.497025,1.859247,0.113865,-887.572876,0.012731,0.000000
21.710001,8.760063,-887.617371,-0.004639,0.000475,0.012063,38.966705,1.985059,0.120632,-887.617371,0.013338,0.000000
22.070002,9.027802,-887.572876,-0.004622,0.000495,0.012566,40.157665,2.045729,0.125659,-887.572876,0.013936,0.000000
22.430000,9.706261,-887.483948,-0.004575,0.000526,0.013355,43.175602,2.199470,0.133546,-887.483948,0.014534,0.000000
22.790001,10.156090,-887.661865,-0.004587,0.000552,0.014022,45.176544,2.301403,0.140223,-887.661865,0.015132,0.000000
23.150002,10.261101,-887.617371,-0.004553,0.000574,0.014569,45.643658,2.325199,0.145688,-887.617371,0.015732,0.000000
23.510000,10.732147,-887.617371,-0.004523,0.000594,0.015090,47.738976,2.431939,0.150896,-887.617371,0.016339,0.000000
23.870001,10.870300,-887.617371,-0.004514,0.000613,0.015567,48.353512,2.463245,0.155665,-887.617371,0.016937,0.000000
24.230001,11.415825,-887.617371,-0.004501,0.000637,0.016174,50.780125,2.586863,0.161736,-887.617371,0.017535,0.000000
24.590002,12.339310,-887.617371,-0.004471,0.000671,0.017032,54.887989,2.796128,0.170320,-887.617371,0.018133,0.000000
24.950001,12.708328,-887.617371,-0.004419,0.000698,0.017725,56.529469,2.879748,0.177254,-887.617371,0.018732,0.000000
25.310001,13.145866,-887.661865,-0.004406,0.000724,0.018386,58.475735,2.978896,0.183855,-887.661865,0.019339,0.000000
25.670002,13.306732,-887.706360,-0.004393,0.000748,0.018993,59.191299,3.015349,0.189926,-887.706360,0.019937,0.000000
26.030001,13.809433,-887.617371,-0.004368,0.000774,0.019660,61.427425,3.129262,0.196603,-887.617371,0.020535,0.000000
26.390001,13.773315,-887.661865,-0.004346,0.000790,0.020077,61.266766,3.121078,0.200766,-887.661865,0.021133,0.000000
26.750002,14.129677,-887.661865,-0.004337,0.000811,0.020596,62.851940,3.201830,0.205959,-887.661865,0.021733,0.000000
27.110001,14.398903,-887.750793,-0.004312,0.000830,0.021082,64.049522,3.262838,0.210819,-887.750793,0.022340,0.000000
27.470001,14.690094,-887.750793,-0.004281,0.000853,0.021663,65.344803,3.328823,0.216632,-887.750793,0.022938,0.000000
27.830002,15.687683,-887.706360,-0.004251,0.000883,0.022426,69.782303,3.554880,0.224263,-887.706360,0.023536,0.000000
28.190001,15.596077,-887.795288,-0.004238,0.000898,0.022808,69.374817,3.534122,0.228078,-887.795288,0.024134,0.000000
28.550001,16.322952,-887.750793,-0.004217,0.000931,0.023640,72.608116,3.698834,0.236405,-887.750793,0.024734,0.000000
28.910002,16.265976,-887.795288,-0.004191,0.000947,0.024048,72.354675,3.685923,0.240477,-887.795288,0.025341,0.000000
29.270000,16.402267,-887.750793,-0.004169,0.000965,0.024516,72.960930,3.716807,0.245155,-887.750793,0.025939,0.000000
29.630001,17.001411,-887.795288,-0.004156,0.000996,0.025306,75.626053,3.852575,0.253058,-887.795288,0.026537,0.000000
29.990002,17.804245,-887.839783,-0.004126,0.001026,0.026069,79.197235,4.034500,0.260688,-887.839783,0.027135,0.000000
30.350002,17.922287,-887.750793,-0.004092,0.001049,0.026641,79.722313,4.061248,0.266411,-887.750793,0.027734,0.000000
30.710001,18.249977,-887.750793,-0.004066,0.001073,0.027265,81.179955,4.135504,0.272649,-887.750793,0.028332,0.000000
31.070002,18.143478,-887.795288,-0.004044,0.001093,0.027768,80.706223,4.111371,0.277675,-887.795288,0.028939,0.000000
31.430002,18.696083,-887.839783,-0.004018,0.001118,0.028402,83.164330,4.236593,0.284019,-887.839783,0.029537,0.000000
31.790001,18.402649,-887.884277,-0.004018,0.001130,0.028705,81.859070,4.170100,0.287046,-887.884277,0.030135,0.000000
32.150002,19.002914,-887.839783,-0.004005,0.001160,0.029468,84.529182,4.306122,0.294677,-887.839783,0.030735,0.000000
32.510002,19.831444,-887.839783,-0.003941,0.001189,0.030205,88.214668,4.493869,0.302050,-887.839783,0.031333,0.000000
32.870003,19.700737,-887.884277,-0.003928,0.001209,0.030708,87.633255,4.464251,0.307076,-887.884277,0.031940,0.000000
33.230003,19.905548,-887.884277,-0.003902,0.001231,0.031272,88.544304,4.510662,0.312723,-887.884277,0.032538,0.000000
33.590000,20.548264,-887.973206,-0.003876,0.001263,0.032078,91.403244,4.656303,0.320777,-887.973206,0.033136,0.000000
33.950001,20.242172,-887.839783,-0.003859,0.001277,0.032426,90.041679,4.586942,0.324260,-887.839783,0.033734,0.000000
34.310001,21.104584,-887.928772,-0.003829,0.001309,0.033250,93.877876,4.782367,0.332495,-887.928772,0.034334,0.000000
34.670002,21.218529,-887.884277,-0.003807,0.001329,0.033769,94.384727,4.808187,0.337688,-887.884277,0.034941,0.000000
35.030003,20.947441,-887.928772,-0.003786,0.001343,0.034117,93.178871,4.746758,0.341170,-887.928772,0.035539,0.000000
35.390003,22.059349,-887.928772,-0.003755,0.001382,0.035097,98.124886,4.998720,0.350966,-887.928772,0.036137,0.000000
35.750000,21.913002,-887.884277,-0.003712,0.001402,0.035599,97.473900,4.965557,0.355992,-887.884277,0.036735,0.000000
36.110001,22.110733,-887.928772,-0.003686,0.001426,0.036215,98.353455,5.010364,0.362154,-887.928772,0.037334,0.000000
36.470001,22.347939,-887.973206,-0.003691,0.001452,0.036874,99.408592,5.064116,0.368740,-887.973206,0.037941,0.000000
36.830002,22.235481,-887.928772,-0.003643,0.001467,0.037274,98.908363,5.038632,0.372736,-887.928772,0.038539,0.000000
37.190002,22.362831,-888.017700,-0.003626,0.001492,0.037888,99.474838,5.067490,0.378883,-888.017700,0.039137,0.000000
37.550003,22.778397,-887.928772,-0.003617,0.001516,0.038514,101.323372,5.161658,0.385136,-887.928772,0.039735,0.000000
37.910004,22.499123,-887.884277,-0.003579,0.001534,0.038956,100.081093,5.098374,0.389557,-887.884277,0.040335,0.000000
38.270000,24.028824,-888.017700,-0.003548,0.001568,0.039831,106.885544,5.445009,0.398307,-888.017700,0.040933,0.000000
38.630001,23.958817,-887.973206,-0.003523,0.001588,0.040342,106.574135,5.429145,0.403424,-887.973206,0.041540,0.000000
38.990002,24.654411,-887.973206,-0.003497,0.001620,0.041158,109.668297,5.586770,0.411585,-887.973206,0.042138,0.000000
39.350002,23.758484,-887.973206,-0.003479,0.001629,0.041375,105.683014,5.383749,0.413750,-887.973206,0.042736,0.000000
39.710003,23.510483,-887.973206,-0.003445,0.001645,0.041775,104.579849,5.327551,0.417746,-887.973206,0.043336,0.000000
40.070004,25.087852,-888.017700,-0.003419,0.001683,0.042736,111.596344,5.684988,0.427360,-888.017700,0.043934,0.000000
40.430000,24.688667,-888.017700,-0.003406,0.001701,0.043213,109.820679,5.594532,0.432129,-888.017700,0.044541,0.000000
40.790001,25.520920,-888.017700,-0.003359,0.001733,0.044029,113.522720,5.783123,0.440289,-888.017700,0.045139,0.000000
41.150002,25.704872,-887.973206,-0.003337,0.001760,0.044697,114.340981,5.824808,0.446966,-887.973206,0.045737,0.000000
41.510002,25.690727,-888.017700,-0.003316,0.001779,0.045190,114.278061,5.821602,0.451901,-888.017700,0.046336,0.000000
41.870003,25.472885,-888.062195,-0.003294,0.001791,0.045504,113.309052,5.772238,0.455035,-888.062195,0.046934,0.000000
42.230003,26.445152,-888.017700,-0.003268,0.001827,0.046413,117.633911,5.992557,0.464134,-888.017700,0.047541,0.000000
42.590000,26.637665,-888.106689,-0.003238,0.001846,0.046899,118.490250,6.036181,0.468994,-888.106689,0.048139,0.000000
42.950001,26.471588,-887.973206,-0.003208,0.001868,0.047446,117.751503,5.998548,0.474459,-887.973206,0.048737,0.000000
43.310001,26.893112,-888.017700,-0.003186,0.001892,0.048053,119.626541,6.094067,0.480530,-888.017700,0.049337,0.000000
43.670002,28.115616,-888.017700,-0.003160,0.001922,0.048816,125.064507,6.371089,0.488161,-888.017700,0.049935,0.000000
44.030003,28.371803,-888.017700,-0.003122,0.001946,0.049423,126.204086,6.429142,0.494232,-888.017700,0.050542,0.000000
44.390003,28.076515,-888.151123,-0.003109,0.001964,0.049874,124.890579,6.362229,0.498743,-888.151123,0.051140,0.000000
44.750004,28.839134,-888.062195,-0.003083,0.001993,0.050619,128.282883,6.535041,0.506192,-888.062195,0.051738,0.000000
45.110001,28.531555,-888.106689,-0.003070,0.002010,0.051054,126.914696,6.465343,0.510537,-888.106689,0.052336,0.000000
45.470001,28.813065,-888.062195,-0.003040,0.002031,0.051582,128.166916,6.529134,0.515821,-888.062195,0.052936,0.000000
45.830002,30.126053,-888.106689,-0.003005,0.002065,0.052440,134.007370,6.826661,0.524405,-888.106689,0.053534,0.000000
46.190002,30.984367,-888.151123,-0.002971,0.002095,0.053213,137.825348,7.021158,0.532126,-888.151123,0.054141,0.000000
46.550003,29.462860,-888.106689,-0.002958,0.002105,0.053464,131.057343,6.676380,0.534639,-888.106689,0.054739,0.000000
46.910004,31.145233,-888.106689,-0.002910,0.002139,0.054340,138.540909,7.057611,0.543405,-888.106689,0.055337,0.000000
47.270000,31.725021,-888.195618,-0.002884,0.002169,0.055085,141.119949,7.188993,0.550854,-888.195618,0.055936,0.000000
47.630001,31.338501,-888.151123,-0.002863,0.002183,0.055450,139.400620,7.101406,0.554502,-888.151123,0.056534,0.000000
47.990002,31.493774,-888.195618,-0.002841,0.002205,0.056004,140.091309,7.136591,0.560043,-888.195618,0.057141,0.000000
48.350002,31.112465,-888.195618,-0.002798,0.002218,0.056343,138.395157,7.050185,0.563435,-888.195618,0.057739,0.000000
48.710003,31.959618,-888.195618,-0.002790,0.002245,0.057011,142.163483,7.242153,0.570111,-888.195618,0.058337,0.000000
49.070004,31.911575,-888.195618,-0.002759,0.002268,0.057600,141.949783,7.231266,0.576000,-888.195618,0.058937,0.000000
49.430004,33.215996,-888.195618,-0.002738,0.002295,0.058303,147.752121,7.526852,0.583025,-888.195618,0.059535,0.000000
49.790001,33.991280,-888.240112,-0.002703,0.002324,0.059040,151.200760,7.702534,0.590398,-888.240112,0.060142,0.000000
50.150002,34.133156,-888.151123,-0.002686,0.002345,0.059561,151.831863,7.734684,0.595606,-888.151123,0.060740,0.000000
50.510002,34.550209,-888.195618,-0.002652,0.002366,0.060098,153.687012,7.829189,0.600981,-888.195618,0.061338,0.000000
50.870003,34.163689,-888.284607,-0.002639,0.002384,0.060558,151.967682,7.741602,0.605583,-888.284607,0.061938,0.000000
51.230003,35.603653,-888.240112,-0.002608,0.002414,0.061312,158.372955,8.067904,0.613123,-888.240112,0.062536,0.000000
51.590004,36.318977,-888.329102,-0.002583,0.002442,0.062024,161.554886,8.229998,0.620238,-888.329102,0.063143,0.000000
51.950001,36.536819,-888.240112,-0.002565,0.002466,0.062640,162.523895,8.279362,0.626400,-888.240112,0.063741,0.000000
52.310001,36.645180,-888.240112,-0.002518,0.002484,0.063082,163.005905,8.303917,0.630821,-888.240112,0.064339,0.000000
52.670002,36.797852,-888.329102,-0.002514,0.002509,0.063741,163.685013,8.338512,0.637407,-888.329102,0.064938,0.000000
53.030003,37.291245,-888.195618,-0.002471,0.002529,0.064236,165.879745,8.450317,0.642357,-888.195618,0.065536,0.000000
53.390003,36.842911,-888.240112,-0.002458,0.002541,0.064539,163.885452,8.348723,0.645385,-888.240112,0.066134,0.000000
53.750004,39.360146,-888.284607,-0.002423,0.002584,0.065632,175.082672,8.919136,0.656316,-888.284607,0.066741,0.000000
54.110004,39.157578,-888.240112,-0.002376,0.002602,0.066099,174.181610,8.873234,0.660994,-888.240112,0.067339,0.000000
54.470001,39.649849,-888.329102,-0.002367,0.002625,0.066672,176.371338,8.984784,0.666717,-888.329102,0.067939,0.000000
54.830002,40.557693,-888.329102,-0.002345,0.002655,0.067435,180.409637,9.190504,0.674347,-888.329102,0.068537,0.000000
55.190002,40.630310,-888.284607,-0.002307,0.002675,0.067946,180.732651,9.206960,0.679464,-888.284607,0.069135,0.000000
55.550003,40.517853,-888.373535,-0.002281,0.002698,0.068537,180.232407,9.181477,0.685369,-888.373535,0.069742,0.000000
55.910004,41.013107,-888.284607,-0.002242,0.002716,0.068979,182.435410,9.293703,0.689790,-888.284607,0.070340,0.000000
56.270004,41.832329,-888.329102,-0.002225,0.002742,0.069638,186.079498,9.479342,0.696375,-888.329102,0.070938,0.000000
56.630001,42.974022,-888.329102,-0.002195,0.002776,0.070514,191.157990,9.738052,0.705141,-888.329102,0.071538,0.000000
56.990002,43.679665,-888.373535,-0.002173,0.002800,0.071112,194.296844,9.897953,0.711121,-888.373535,0.072136,0.000000
57.350002,42.875710,-888.284607,-0.002151,0.002812,0.071416,190.720688,9.715775,0.714164,-888.284607,0.072743,0.000000
57.710003,44.021500,-888.329102,-0.002108,0.002842,0.072179,195.817413,9.975414,0.721795,-888.329102,0.073341,0.000000
58.070004,44.558090,-888.373535,-0.002091,0.002866,0.072787,198.204285,10.097008,0.727866,-888.373535,0.073939,0.000000
58.430004,44.644852,-888.284607,-0.002070,0.002885,0.073271,198.590225,10.116668,0.732710,-888.284607,0.074538,0.000000
58.790001,44.679489,-888.418030,-0.002026,0.002904,0.073766,198.744293,10.124516,0.737661,-888.418030,0.075136,0.000000
59.150002,44.682465,-888.284607,-0.002009,0.002921,0.074192,198.757523,10.125192,0.741915,-888.284607,0.075743,0.000000
59.510002,46.893242,-888.329102,-0.001970,0.002962,0.075232,208.591553,10.626160,0.752316,-888.329102,0.076341,0.000000
59.870003,46.819885,-888.329102,-0.001962,0.002979,0.075665,208.265244,10.609537,0.756646,-888.329102,0.076939,0.000000
60.230003,48.379379,-888.329102,-0.001927,0.003013,0.076541,215.202225,10.962924,0.765412,-888.329102,0.077539,0.000000
60.590004,48.021156,-888.373535,-0.001893,0.003027,0.076897,213.608765,10.881749,0.768970,-888.373535,0.078137,0.000000
60.950005,46.940155,-888.329102,-0.001888,0.003036,0.077113,208.800232,10.636791,0.771134,-888.329102,0.078735,0.000000
61.310001,47.214600,-888.373535,-0.001837,0.003058,0.077686,210.021027,10.698981,0.776857,-888.373535,0.079342,0.000000
61.670002,49.729599,-888.418030,-0.001811,0.003100,0.078744,221.208298,11.268888,0.787440,-888.418030,0.079940,0.000000
62.030003,51.185204,-888.373535,-0.001763,0.003128,0.079446,227.683151,11.598733,0.794465,-888.373535,0.080540,0.000000
62.390003,51.181854,-888.418030,-0.001738,0.003150,0.080010,227.668259,11.597974,0.800097,-888.418030,0.081138,0.000000
62.750004,51.042213,-888.418030,-0.001725,0.003170,0.080521,227.047104,11.566331,0.805214,-888.418030,0.081736,0.000000
63.110004,51.175896,-888.373535,-0.001690,0.003187,0.080947,227.641754,11.596623,0.809468,-888.373535,0.082343,0.000000
63.470001,52.815826,-888.418030,-0.001677,0.003219,0.081761,234.936523,11.968237,0.817613,-888.418030,0.082941,0.000000
63.830002,52.618095,-888.418030,-0.001643,0.003237,0.082212,234.056976,11.923430,0.822125,-888.418030,0.083540,0.000000
64.190002,53.144257,-888.418030,-0.001608,0.003260,0.082803,236.397461,12.042660,0.828029,-888.418030,0.084138,0.000000
64.550003,53.302513,-888.462524,-0.001595,0.003281,0.083349,237.101425,12.078522,0.833494,-888.462524,0.084736,0.000000
64.910004,54.896645,-888.418030,-0.001548,0.003315,0.084199,244.192474,12.439757,0.841988,-888.418030,0.085343,0.000000
65.270004,54.967392,-888.462524,-0.001522,0.003330,0.084589,244.507172,12.455789,0.845894,-888.462524,0.085941,0.000000
65.630005,56.118393,-888.462524,-0.001492,0.003360,0.085352,249.627075,12.716610,0.853524,-888.462524,0.086539,0.000000
65.990005,56.332878,-888.507019,-0.001462,0.003381,0.085890,250.581161,12.765213,0.858899,-888.507019,0.087139,0.000000
66.350006,57.004639,-888.507019,-0.001453,0.003407,0.086532,253.569290,12.917437,0.865318,-888.507019,0.087737,0.000000
66.710007,56.781219,-888.462524,-0.001418,0.003421,0.086895,252.575485,12.866809,0.868951,-888.462524,0.088344,0.000000
67.070000,57.913231,-888.551453,-0.001406,0.003451,0.087658,257.610931,13.123325,0.876582,-888.551453,0.088942,0.000000
67.430000,59.789612,-888.418030,-0.001380,0.003487,0.088560,265.957489,13.548519,0.885605,-888.418030,0.089540,0.000000
67.790001,59.550926,-888.462524,-0.001358,0.003495,0.088777,264.895752,13.494432,0.887770,-888.462524,0.090140,0.000000
68.150002,61.388954,-888.462524,-0.001328,0.003533,0.089749,273.071716,13.910935,0.897489,-888.462524,0.090738,0.000000
68.510002,62.051033,-888.551453,-0.001311,0.003555,0.090305,276.016785,14.060965,0.903046,-888.551453,0.091336,0.000000
68.870003,62.829292,-888.507019,-0.001268,0.003579,0.090903,279.478638,14.237321,0.909026,-888.507019,0.091943,0.000000
69.230003,63.165916,-888.418030,-0.001263,0.003600,0.091431,280.976044,14.313601,0.914310,-888.418030,0.092541,0.000000
69.590004,63.434776,-888.551453,-0.001229,0.003616,0.091838,282.171967,14.374526,0.918382,-888.551453,0.093140,0.000000
69.950005,63.154366,-888.551453,-0.001216,0.003627,0.092133,280.924652,14.310984,0.921334,-888.551453,0.093738,0.000000
70.310005,65.170769,-888.462524,-0.001181,0.003661,0.093001,289.894043,14.767907,0.930009,-888.462524,0.094336,0.000000
70.670006,65.298866,-888.595947,-0.001177,0.003669,0.093183,290.463867,14.796934,0.931826,-888.595947,0.016369,0.000000
71.030006,66.384331,-888.507019,-0.001125,0.003648,0.092671,295.292236,15.042904,0.926709,-888.507019,294.500488,0.000000
71.390007,64.961494,-888.640442,-0.001138,0.003688,0.093678,288.963165,14.720485,0.936777,-888.640442,294.500488,0.000000
71.750000,65.483192,-888.551453,-0.001130,0.003710,0.094224,291.283783,14.838703,0.942242,-888.551453,294.500488,0.000000
72.110001,64.220848,-888.551453,-0.001108,0.003710,0.094241,285.668610,14.552652,0.942409,-888.551453,294.500488,0.000000
72.470001,65.129814,-888.551453,-0.001074,0.003574,0.090781,289.711884,14.758627,0.907815,-888.551453,294.500488,0.000000
72.830002,65.032249,-888.507019,-0.001052,0.003728,0.094701,289.277893,14.736519,0.947011,-888.507019,294.500488,0.000000
73.190002,64.930214,-888.551453,-0.001039,0.003747,0.095178,288.824005,14.713397,0.951780,-888.551453,294.500488,0.000000
73.550003,65.467171,-888.595947,-0.001048,0.003760,0.095507,291.212524,14.835073,0.955065,-888.595947,294.500488,0.000000
73.910004,64.654289,-888.595947,-0.001026,0.003760,0.095516,287.596649,14.650872,0.955156,-888.595947,294.500488,0.000000
74.270004,65.425468,-888.595947,-0.001039,0.003776,0.095923,291.027008,14.825624,0.959229,-888.595947,294.500488,0.000000
74.630005,64.778664,-888.551453,-0.001022,0.003779,0.095993,288.149902,14.679055,0.959925,-888.551453,294.500488,0.000000
74.990005,65.340202,-888.684937,-0.001030,0.003792,0.096313,290.647736,14.806301,0.963135,-888.684937,294.500488,0.000000
75.350006,64.646095,-888.595947,-0.001026,0.003792,0.096323,287.560181,14.649014,0.963225,-888.595947,294.500488,0.000000
75.710007,65.927437,-888.640442,-0.001000,0.003803,0.096591,293.259888,14.939371,0.965905,-888.640442,294.500488,0.000000
76.070007,65.159233,-888.684937,-0.001005,0.003803,0.096600,289.842743,14.765293,0.965996,-888.684937,294.500488,0.000000
76.430000,64.461769,-888.640442,-0.000992,0.003803,0.096609,286.740265,14.607245,0.966087,-888.640442,294.500488,0.000000
76.790001,66.715736,-888.640442,-0.000970,0.003695,0.093843,296.766418,15.118002,0.938427,-888.640442,294.500488,0.000000
77.150002,66.048073,-888.640442,-0.000961,0.003695,0.093850,293.796509,14.966707,0.938503,-888.640442,294.500488,0.000000
77.510002,65.434776,-888.684937,-0.000961,0.003749,0.095229,291.068420,14.827732,0.952295,-888.684937,294.500488,0.000000
77.870003,65.093315,-888.684937,-0.000961,0.003834,0.097381,289.549530,14.750356,0.973808,-888.684937,294.500488,0.000000
78.230003,65.175987,-888.640442,-0.000953,0.003840,0.097546,289.917267,14.769090,0.975458,-888.640442,294.500488,0.000000
78.590004,65.319725,-888.729431,-0.000953,0.003848,0.097727,290.556641,14.801661,0.977275,-888.729431,294.500488,0.000000
78.950005,65.160347,-888.640442,-0.000953,0.003851,0.097814,289.847687,14.765546,0.978138,-888.640442,294.500488,0.000000
79.310005,65.051979,-888.729431,-0.000940,0.003854,0.097900,289.365662,14.740989,0.979001,-888.729431,294.500488,0.000000
79.670006,65.001717,-888.684937,-0.000940,0.003857,0.097979,289.142090,14.729600,0.979788,-888.684937,294.500488,0.000000
80.030006,65.406105,-888.595947,-0.000931,0.003866,0.098195,290.940887,14.821236,0.981953,-888.595947,294.500488,0.000000
80.390007,65.083641,-888.773865,-0.000923,0.003866,0.098195,289.506500,14.748164,0.981953,-888.773865,294.500488,0.000000
80.750008,65.205025,-888.729431,-0.000923,0.003871,0.098326,290.046448,14.775670,0.983255,-888.729431,294.500488,0.000000
81.110001,64.954048,-888.773865,-0.000931,0.003872,0.098351,288.930023,14.718798,0.983513,-888.773865,294.500488,0.000000
81.470001,65.298866,-888.729431,-0.000905,0.003880,0.098542,290.463867,14.796934,0.985420,-888.729431,294.500488,0.000000
81.830002,65.031502,-888.773865,-0.000918,0.003880,0.098542,289.274567,14.736349,0.985420,-888.773865,294.500488,0.000000
82.190002,65.136513,-888.818359,-0.000918,0.003888,0.098751,289.741669,14.760145,0.987509,-888.818359,294.500488,0.000000
82.550003,65.170403,-888.729431,-0.000914,0.003888,0.098751,289.892426,14.767824,0.987509,-888.729431,294.500488,0.000000
82.910004,64.904518,-888.773865,-0.000897,0.003888,0.098751,288.709717,14.707574,0.987509,-888.773865,294.500488,0.000000
83.270004,65.776619,-888.818359,-0.000901,0.003900,0.099063,292.589020,14.905194,0.990628,-888.818359,294.500488,0.000000
83.630005,65.582985,-888.818359,-0.000892,0.003900,0.099063,291.727692,14.861317,0.990628,-888.818359,294.500488,0.000000
83.990005,65.342064,-888.818359,-0.000892,0.003900,0.099063,290.656006,14.806724,0.990628,-888.818359,294.500488,0.000000
84.350006,65.092201,-888.773865,-0.000905,0.003900,0.099072,289.544586,14.750103,0.990719,-888.773865,294.500488,0.000000
84.710007,65.118645,-888.773865,-0.000880,0.003905,0.099175,289.662201,14.756096,0.991748,-888.773865,294.500488,0.000000
85.070007,65.231087,-888.818359,-0.000897,0.003909,0.099297,290.162354,14.781575,0.992975,-888.818359,294.500488,0.000000
85.430000,65.105980,-888.862854,-0.000888,0.003909,0.099297,289.605865,14.753226,0.992975,-888.862854,294.500488,0.000000
85.790001,64.912346,-888.862854,-0.000871,0.003909,0.099297,288.744537,14.709348,0.992975,-888.862854,294.500488,0.000000
86.150002,65.408348,-888.818359,-0.000849,0.003917,0.099496,290.950867,14.821744,0.994958,-888.818359,294.500488,0.000000
86.510002,65.297371,-888.818359,-0.000841,0.003917,0.099496,290.457214,14.796596,0.994958,-888.818359,294.500488,0.000000
86.870003,65.060173,-888.951782,-0.000867,0.003917,0.099496,289.402100,14.742846,0.994958,-888.951782,294.500488,0.000000
87.230003,64.863197,-888.818359,-0.000854,0.003918,0.099514,288.525909,14.698210,0.995140,-888.818359,294.500488,0.000000
87.590004,64.720192,-888.907349,-0.000836,0.003918,0.099523,287.889801,14.665805,0.995231,-888.907349,294.500488,0.000000
87.950005,65.288445,-888.907349,-0.000832,0.003928,0.099765,290.417511,14.794573,0.997653,-888.907349,294.500488,0.000000
88.310005,65.258278,-888.862854,-0.000819,0.003928,0.099765,290.283325,14.787737,0.997653,-888.862854,294.500488,0.000000
88.670006,65.095543,-888.862854,-0.000832,0.003928,0.099765,289.559448,14.750860,0.997653,-888.862854,294.500488,0.000000
89.030006,64.942879,-888.907349,-0.000832,0.003928,0.099765,288.880341,14.716267,0.997653,-888.907349,294.500488,0.000000
89.390007,64.815147,-888.951782,-0.000832,0.003928,0.099765,288.312164,14.687323,0.997653,-888.951782,294.500488,0.000000
89.750008,64.614067,-888.907349,-0.000824,0.003928,0.099765,287.417725,14.641757,0.997653,-888.907349,294.500488,0.000000
90.110001,64.516884,-888.907349,-0.000841,0.003930,0.099826,286.985443,14.619735,0.998258,-888.907349,294.500488,0.000000
90.470001,64.440926,-888.951782,-0.000832,0.003930,0.099826,286.647552,14.602523,0.998258,-888.951782,294.500488,0.000000
90.830002,65.633995,-888.951782,-0.000819,0.003944,0.100182,291.954590,14.872875,1.001816,-888.951782,294.500488,0.000000
91.190002,65.570320,-888.951782,-0.000811,0.003944,0.100182,291.671356,14.858447,1.001816,-888.951782,294.500488,0.000000
91.550003,65.526756,-888.951782,-0.000819,0.003944,0.100182,291.477570,14.848576,1.001816,-888.951782,294.500488,0.000000
91.910004,65.338341,-888.996277,-0.000828,0.003944,0.100182,290.639465,14.805880,1.001816,-888.996277,294.500488,0.000000
92.270004,65.248222,-888.996277,-0.000811,0.003945,0.100191,290.238586,14.785459,1.001907,-888.996277,294.500488,0.000000
92.630005,65.090340,-888.951782,-0.000815,0.003945,0.100191,289.536285,14.749682,1.001907,-888.951782,294.500488,0.000000
92.990005,64.967827,-888.996277,-0.000815,0.003945,0.100191,288.991333,14.721920,1.001907,-888.996277,294.500488,0.000000
93.350006,64.846062,-888.996277,-0.000815,0.003945,0.100191,288.449677,14.694327,1.001907,-888.996277,294.500488,0.000000
93.710007,64.709404,-888.996277,-0.000824,0.003945,0.100191,287.841797,14.663361,1.001907,-888.996277,294.500488,0.000000
94.070007,64.562309,-889.085266,-0.000832,0.003945,0.100191,287.187500,14.630029,1.001907,-889.085266,294.500488,0.000000
94.430008,64.445381,-889.040771,-0.000811,0.003945,0.100191,286.667358,14.603533,1.001907,-889.040771,294.500488,0.000000
94.790001,64.303886,-888.996277,-0.000802,0.003945,0.100191,286.037964,14.571469,1.001907,-888.996277,294.500488,0.000000
95.150002,64.187340,-888.996277,-0.000811,0.003945,0.100191,285.519562,14.545059,1.001907,-888.996277,294.500488,0.000000
95.510002,64.087914,-888.996277,-0.000802,0.003945,0.100198,285.077271,14.522529,1.001983,-888.996277,294.500488,0.000000
95.870003,66.996147,-889.085266,-0.000815,0.003807,0.096686,298.013733,15.181544,0.966859,-889.085266,294.500488,0.000000
96.230003,66.717232,-888.996277,-0.000798,0.003796,0.096409,296.773071,15.118341,0.964088,-888.996277,294.500488,0.000000
96.590004,66.595833,-889.040771,-0.000802,0.003796,0.096409,296.233063,15.090832,0.964088,-889.040771,294.500488,0.000000
96.950005,66.418221,-889.040771,-0.000819,0.003796,0.096418,295.442993,15.050584,0.964179,-889.040771,294.500488,0.000000
97.310005,66.282677,-889.085266,-0.000798,0.003796,0.096418,294.840057,15.019869,0.964179,-889.085266,294.500488,0.000000
97.670006,66.155327,-889.085266,-0.000793,0.003796,0.096418,294.273590,14.991012,0.964179,-889.085266,294.500488,0.000000
98.030006,66.018669,-889.129761,-0.000815,0.003796,0.096418,293.665710,14.960044,0.964179,-889.129761,294.500488,0.000000
98.390007,65.868599,-889.040771,-0.000793,0.003797,0.096435,292.998169,14.926038,0.964346,-889.040771,294.500488,0.000000
98.750008,65.856682,-889.040771,-0.000798,0.003797,0.096435,292.945160,14.923338,0.964346,-889.040771,294.500488,0.000000
99.110008,65.655220,-889.040771,-0.000785,0.003813,0.096851,292.049011,14.877686,0.968509,-889.040771,294.500488,0.000000
99.470001,65.566978,-889.174194,-0.000798,0.003882,0.098595,291.656494,14.857690,0.985950,-889.174194,294.500488,0.000000
99.830002,65.425468,-889.085266,-0.000793,0.003918,0.099505,291.027008,14.825624,0.995049,-889.085266,294.500488,0.000000
100.190002,65.306313,-889.085266,-0.000785,0.003925,0.099687,290.496979,14.798622,0.996866,-889.085266,294.500488,0.000000
100.550003,65.213966,-889.129761,-0.000802,0.003925,0.099696,290.086212,14.777697,0.996956,-889.129761,294.500488,0.000000
100.910004,65.076180,-889.129761,-0.000802,0.003928,0.099782,289.473297,14.746473,0.997819,-889.129761,294.500488,0.000000
101.270004,64.991661,-889.174194,-0.000802,0.003929,0.099791,289.097351,14.727321,0.997910,-889.174194,294.500488,0.000000
101.630005,64.902657,-889.085266,-0.000802,0.003930,0.099826,288.701447,14.707152,0.998258,-889.085266,294.500488,0.000000
101.990005,64.919411,-889.174194,-0.000793,0.003951,0.100356,288.775970,14.710948,1.003557,-889.174194,294.500488,0.000000
102.350006,64.823341,-889.218689,-0.000798,0.003952,0.100372,288.348633,14.689179,1.003724,-889.218689,294.500488,0.000000
102.710007,65.235558,-889.129761,-0.000802,0.003972,0.100893,290.182251,14.782589,1.008932,-889.129761,294.500488,0.000000
103.070007,65.181572,-889.174194,-0.000806,0.003972,0.100893,289.942108,14.770355,1.008932,-889.174194,294.500488,0.000000
103.430008,65.118645,-889.129761,-0.000793,0.003972,0.100893,289.662201,14.756096,1.008932,-889.129761,294.500488,0.000000
103.790009,65.221046,-889.218689,-0.000793,0.003977,0.101005,290.117706,14.779301,1.010052,-889.218689,294.500488,0.000000
104.150002,65.259026,-889.218689,-0.000798,0.003977,0.101005,290.286652,14.787907,1.010052,-889.218689,294.500488,0.000000
104.510002,65.213219,-889.174194,-0.000798,0.003977,0.101005,290.082886,14.777527,1.010052,-889.174194,294.500488,0.000000
104.870003,65.189384,-889.218689,-0.000789,0.003978,0.101049,289.976868,14.772126,1.010491,-889.218689,294.500488,0.000000
105.230003,65.360680,-889.218689,-0.000798,0.003980,0.101101,290.738831,14.810942,1.011006,-889.218689,294.500488,0.000000
105.590004,65.338707,-889.218689,-0.000802,0.003980,0.101101,290.641083,14.805963,1.011006,-889.218689,294.500488,0.000000
105.950005,65.293648,-889.263184,-0.000798,0.003980,0.101101,290.440643,14.795753,1.011006,-889.263184,294.500488,0.000000
106.310005,65.235558,-889.218689,-0.000793,0.003980,0.101101,290.182251,14.782589,1.011006,-889.218689,294.500488,0.000000
106.670006,65.180824,-889.263184,-0.000802,0.003981,0.101119,289.938782,14.770185,1.011188,-889.263184,294.500488,0.000000
107.030006,65.153267,-889.218689,-0.000767,0.003981,0.101126,289.816193,14.763942,1.011263,-889.218689,294.500488,0.000000
107.390007,65.129066,-889.263184,-0.000780,0.003982,0.101154,289.708557,14.758457,1.011536,-889.263184,294.500488,0.000000
107.750008,65.094429,-889.307678,-0.000772,0.003983,0.101161,289.554474,14.750608,1.011612,-889.307678,294.500488,0.000000
108.110008,65.072090,-889.263184,-0.000772,0.003983,0.101161,289.455109,14.745546,1.011612,-889.263184,294.500488,0.000000
108.470009,65.071342,-889.396606,-0.000772,0.003984,0.101205,289.451782,14.745378,1.012051,-889.396606,294.500488,0.000000
108.830002,65.090340,-889.263184,-0.000767,0.003985,0.101222,289.536285,14.749682,1.012217,-889.263184,294.500488,0.000000
109.190002,65.088097,-889.263184,-0.000759,0.003985,0.101231,289.526306,14.749174,1.012308,-889.263184,294.500488,0.000000
109.550003,65.025551,-889.307678,-0.000780,0.003986,0.101240,289.248108,14.735001,1.012399,-889.307678,294.500488,0.000000
109.910004,64.990166,-889.352112,-0.000763,0.003986,0.101240,289.090698,14.726981,1.012399,-889.352112,294.500488,0.000000
110.270004,65.247856,-889.396606,-0.000776,0.003991,0.101361,290.236969,14.785376,1.013610,-889.396606,294.500488,0.000000
110.630005,65.279869,-889.352112,-0.000767,0.003991,0.101361,290.379364,14.792629,1.013610,-889.352112,294.500488,0.000000
110.990005,65.280251,-889.352112,-0.000776,0.003991,0.101361,290.381042,14.792717,1.013610,-889.352112,294.500488,0.000000
111.350006,65.200188,-889.352112,-0.000767,0.003991,0.101361,290.024933,14.774573,1.013610,-889.352112,294.500488,0.000000
111.710007,65.195351,-889.396606,-0.000776,0.003991,0.101370,290.003418,14.773478,1.013701,-889.396606,294.500488,0.000000
112.070007,65.129814,-889.352112,-0.000759,0.003991,0.101370,289.711884,14.758627,1.013701,-889.352112,294.500488,0.000000
112.430008,65.079536,-889.307678,-0.000767,0.003991,0.101378,289.488251,14.747233,1.013777,-889.307678,294.500488,0.000000
112.790009,65.054222,-889.352112,-0.000746,0.003992,0.101387,289.375641,14.741497,1.013867,-889.352112,294.500488,0.000000
113.150009,65.107460,-889.396606,-0.000767,0.003994,0.101440,289.612457,14.753561,1.014397,-889.396606,294.500488,0.000000
113.510002,65.120872,-889.307678,-0.000742,0.003994,0.101440,289.672119,14.756600,1.014397,-889.307678,294.500488,0.000000
113.870003,65.097786,-889.396606,-0.000767,0.003994,0.101440,289.569427,14.751369,1.014397,-889.396606,294.500488,0.000000
114.230003,65.131294,-889.441101,-0.000755,0.003996,0.101500,289.718475,14.758963,1.015003,-889.441101,294.500488,0.000000
114.590004,65.162956,-889.396606,-0.000755,0.003996,0.101500,289.859314,14.766137,1.015003,-889.396606,294.500488,0.000000
114.950005,65.167046,-889.307678,-0.000755,0.003996,0.101500,289.877502,14.767064,1.015003,-889.307678,294.500488,0.000000
115.310005,65.068367,-889.396606,-0.000737,0.003996,0.101500,289.438538,14.744702,1.015003,-889.396606,294.500488,0.000000
115.670006,65.043053,-889.441101,-0.000750,0.003996,0.101500,289.325958,14.738967,1.015003,-889.441101,294.500488,0.000000
116.030006,65.031136,-889.441101,-0.000750,0.003996,0.101500,289.272949,14.736266,1.015003,-889.441101,294.500488,0.000000
116.390007,64.979744,-889.441101,-0.000742,0.003996,0.101500,289.044342,14.724620,1.015003,-889.441101,294.500488,0.000000
116.750008,64.925011,-889.441101,-0.000746,0.003996,0.101500,288.800873,14.712217,1.015003,-889.441101,294.500488,0.000000
117.110008,64.870262,-889.396606,-0.000750,0.003996,0.101500,288.557343,14.699812,1.015003,-889.396606,294.500488,0.000000
117.470009,64.816643,-889.485596,-0.000746,0.003996,0.101500,288.318817,14.687661,1.015003,-889.485596,294.500488,0.000000
117.830002,64.818504,-889.441101,-0.000755,0.003998,0.101543,288.327118,14.688084,1.015427,-889.441101,294.500488,0.000000
118.190002,65.084755,-889.485596,-0.000746,0.004003,0.101664,289.511444,14.748417,1.016638,-889.485596,294.500488,0.000000
118.550003,65.147682,-889.574524,-0.000755,0.004003,0.101664,289.791351,14.762676,1.016638,-889.574524,294.500488,0.000000
118.910004,65.153267,-889.396606,-0.000746,0.004003,0.101664,289.816193,14.763942,1.016638,-889.396606,294.500488,0.000000
119.270004,65.097038,-889.485596,-0.000742,0.004003,0.101664,289.566101,14.751200,1.016638,-889.485596,294.500488,0.000000
119.630005,65.067619,-889.485596,-0.000750,0.004003,0.101664,289.435211,14.744533,1.016638,-889.485596,294.500488,0.000000
119.990005,65.030006,-889.530029,-0.000750,0.004003,0.101664,289.267914,14.736011,1.016638,-889.530029,294.500488,0.000000
120.350006,65.005440,-889.574524,-0.000763,0.004003,0.101664,289.158630,14.730443,1.016638,-889.574524,294.500488,0.000000
120.710007,64.999855,-889.530029,-0.000750,0.004003,0.101673,289.133789,14.729177,1.016729,-889.530029,294.500488,0.000000
121.070007,64.967827,-889.574524,-0.000746,0.004003,0.101673,288.991333,14.721920,1.016729,-889.574524,294.500488,0.000000
121.430008,64.939903,-889.574524,-0.000759,0.004003,0.101682,288.867126,14.715592,1.016820,-889.574524,294.500488,0.000000
121.790009,64.919792,-889.530029,-0.000742,0.004004,0.101699,288.777649,14.711036,1.016986,-889.530029,294.500488,0.000000
122.150009,64.947716,-889.619019,-0.000742,0.004005,0.101717,288.901855,14.717363,1.017168,-889.619019,294.500488,0.000000
122.510002,64.931709,-889.619019,-0.000742,0.004005,0.101733,288.830658,14.713736,1.017334,-889.619019,294.500488,0.000000
122.870003,64.910851,-889.574524,-0.000742,0.004005,0.101733,288.737885,14.709009,1.017334,-889.574524,294.500488,0.000000
123.230003,64.881065,-889.619019,-0.000750,0.004005,0.101733,288.605408,14.702259,1.017334,-889.619019,294.500488,0.000000
123.590004,64.852394,-889.530029,-0.000746,0.004005,0.101733,288.477844,14.695763,1.017334,-889.530029,294.500488,0.000000
123.950005,64.824471,-889.663513,-0.000750,0.004005,0.101733,288.353638,14.689435,1.017334,-889.663513,294.500488,0.000000
124.310005,64.799141,-889.530029,-0.000750,0.004006,0.101743,288.240967,14.683695,1.017425,-889.530029,294.500488,0.000000
124.670006,64.767860,-889.530029,-0.000755,0.004006,0.101743,288.101837,14.676607,1.017425,-889.530029,294.500488,0.000000
125.030006,64.759666,-889.619019,-0.000750,0.004007,0.101768,288.065369,14.674750,1.017683,-889.619019,294.500488,0.000000
125.390007,64.748497,-889.574524,-0.000742,0.004007,0.101768,288.015686,14.672219,1.017683,-889.574524,294.500488,0.000000
125.750008,64.726906,-889.708008,-0.000750,0.004007,0.101768,287.919647,14.667326,1.017683,-889.708008,294.500488,0.000000
126.110008,64.694130,-889.619019,-0.000742,0.004009,0.101829,287.773865,14.659900,1.018288,-889.619019,294.500488,0.000000
126.470009,65.562508,-889.663513,-0.000755,0.004017,0.102020,291.636597,14.856677,1.020196,-889.663513,294.500488,0.000000
126.830009,65.548729,-889.708008,-0.000755,0.004016,0.102012,291.575317,14.853555,1.020120,-889.708008,294.500488,0.000000
127.190002,65.554314,-889.663513,-0.000750,0.004016,0.102012,291.600159,14.854820,1.020120,-889.663513,294.500488,0.000000
127.550003,65.527138,-889.708008,-0.000750,0.004016,0.102012,291.479279,14.848661,1.020120,-889.708008,294.500488,0.000000
127.910004,65.514091,-889.663513,-0.000755,0.004016,0.102012,291.421234,14.845706,1.020120,-889.663513,294.500488,0.000000
128.270004,65.482079,-889.663513,-0.000759,0.004016,0.102012,291.278839,14.838450,1.020120,-889.663513,294.500488,0.000000
128.630005,65.431053,-889.708008,-0.000746,0.004016,0.102012,291.051849,14.826889,1.020120,-889.708008,294.500488,0.000000
128.990005,65.400520,-889.663513,-0.000755,0.004016,0.102012,290.916046,14.819970,1.020120,-889.663513,294.500488,0.000000
129.350006,65.372597,-889.752441,-0.000742,0.004016,0.102012,290.791840,14.813643,1.020120,-889.752441,294.500488,0.000000
129.710007,65.334984,-889.619019,-0.000746,0.004016,0.102012,290.624512,14.805119,1.020120,-889.619019,294.500488,0.000000
130.070007,65.304451,-889.708008,-0.000737,0.004016,0.102012,290.488708,14.798200,1.020120,-889.708008,294.500488,0.000000
130.430008,65.272057,-889.752441,-0.000759,0.004016,0.102012,290.344604,14.790859,1.020120,-889.752441,294.500488,0.000000
130.790009,65.249718,-889.752441,-0.000724,0.004016,0.102012,290.245239,14.785798,1.020120,-889.752441,294.500488,0.000000
131.150009,65.212471,-889.752441,-0.000724,0.004016,0.102012,290.079559,14.777357,1.020120,-889.752441,1681.640991,0.000000
131.510010,65.088844,-889.663513,-0.000724,0.004009,0.101829,289.529633,14.749343,1.018288,-889.663513,0.101630,0.000000
131.870010,65.195717,-889.708008,-0.000716,0.003991,0.101370,290.005035,14.773561,1.013701,-889.708008,0.101023,0.000000
132.230011,64.995750,-889.752441,-0.000724,0.003975,0.100961,289.115540,14.728248,1.009613,-889.752441,0.100424,0.000000
132.590012,64.929848,-889.752441,-0.000711,0.003950,0.100328,288.822388,14.713314,1.003285,-889.752441,0.099826,0.000000
132.950012,64.892601,-889.796936,-0.000716,0.003927,0.099740,288.656708,14.704874,0.997396,-889.796936,0.099228,0.000000
133.310013,64.850899,-889.796936,-0.000720,0.003906,0.099202,288.471191,14.695423,0.992021,-889.796936,0.098630,0.000000
133.670013,64.857231,-889.796936,-0.000711,0.003882,0.098612,288.499359,14.696858,0.986117,-889.796936,0.098030,0.000000
134.029999,64.767494,-889.796936,-0.000737,0.003859,0.098030,288.100189,14.676524,0.980303,-889.796936,0.097423,0.000000
134.389999,64.705681,-889.796936,-0.000720,0.003837,0.097467,287.825256,14.662517,0.974671,-889.796936,0.096825,0.000000
134.750000,64.642006,-889.752441,-0.000716,0.003812,0.096816,287.541992,14.648088,0.968161,-889.752441,0.096227,0.000000
135.110001,64.535500,-889.841431,-0.000724,0.003795,0.096400,287.068237,14.623954,0.963998,-889.841431,0.095629,0.000000
135.470001,64.100197,-889.796936,-0.000733,0.003774,0.095855,285.131927,14.525312,0.958547,-889.796936,0.095030,0.000000
135.830002,63.302574,-889.885925,-0.000729,0.003747,0.095178,281.583923,14.344568,0.951780,-889.885925,0.094423,0.000000
136.190002,62.445000,-889.752441,-0.000716,0.003726,0.094641,277.769226,14.150239,0.946405,-889.752441,0.093825,0.000000
136.550003,61.256393,-889.841431,-0.000729,0.003705,0.094111,272.482056,13.880898,0.941107,-889.841431,0.093226,0.000000
136.910004,60.176880,-889.841431,-0.000724,0.003686,0.093625,267.680145,13.636275,0.936247,-889.841431,0.092628,0.000000
137.270004,58.772667,-889.841431,-0.000720,0.003669,0.093192,261.433868,13.318076,0.931917,-889.841431,0.092029,0.000000
137.630005,56.685143,-889.885925,-0.000711,0.003640,0.092445,252.148102,12.845037,0.924453,-889.885925,0.091422,0.000000
137.990005,54.519058,-889.885925,-0.000716,0.003616,0.091838,242.512878,12.354195,0.918382,-889.885925,0.090824,0.000000
138.350006,52.767044,-889.885925,-0.000716,0.003599,0.091422,234.719528,11.957184,0.914219,-889.885925,0.090226,0.000000
138.710007,50.545845,-889.930359,-0.000716,0.003576,0.090824,224.839142,11.453853,0.908239,-889.930359,0.089628,0.000000
139.070007,47.624207,-889.930359,-0.000716,0.003548,0.090130,211.843048,10.791800,0.901305,-889.930359,0.089028,0.000000
139.430008,44.870140,-889.974854,-0.000729,0.003523,0.089472,199.592346,10.167719,0.894719,-889.974854,0.088423,0.000000
139.790009,42.234489,-889.885925,-0.000729,0.003498,0.088847,187.868393,9.570473,0.888466,-889.885925,0.087823,0.000000
140.150009,40.152184,-889.885925,-0.000720,0.003480,0.088395,178.605835,9.098615,0.883955,-889.885925,0.087225,0.000000
140.510010,37.185493,-889.930359,-0.000720,0.003454,0.087720,165.409332,8.426353,0.877202,-889.930359,0.086627,0.000000
140.870010,34.689850,-889.885925,-0.000716,0.003428,0.087069,154.308151,7.860833,0.870692,-889.885925,0.086029,0.000000
141.230011,32.296982,-889.974854,-0.000724,0.003403,0.086436,143.664154,7.318601,0.864364,-889.974854,0.085430,0.000000
141.590012,29.266617,-889.885925,-0.000733,0.003379,0.085820,130.184418,6.631910,0.858202,-889.885925,0.084823,0.000000
141.950012,27.443108,-889.930359,-0.000724,0.003360,0.085343,122.073036,6.218697,0.853433,-889.930359,0.084225,0.000000
142.310013,24.667816,-889.974854,-0.000750,0.003333,0.084657,109.727928,5.589807,0.846575,-889.974854,0.083626,0.000000
142.670013,22.435814,-889.974854,-0.000755,0.003317,0.084259,99.799484,5.084028,0.842593,-889.974854,0.083028,0.000000
143.030014,19.823624,-889.974854,-0.000750,0.003290,0.083566,88.179886,4.492097,0.835659,-889.974854,0.082429,0.000000
143.389999,16.385139,-890.019348,-0.000763,0.003259,0.082776,72.884743,3.712926,0.827757,-890.019348,0.081822,0.000000
143.750000,13.770706,-889.974854,-0.000759,0.003237,0.082222,61.255161,3.120487,0.822215,-889.974854,0.081224,0.000000
144.110001,12.090569,-889.974854,-0.000767,0.003219,0.081770,53.781536,2.739762,0.817704,-889.974854,0.080626,0.000000
144.470001,9.226646,-889.974854,-0.000755,0.003194,0.081128,41.042171,2.090788,0.811285,-889.974854,0.080028,0.000000
144.830002,6.451729,-890.108337,-0.000759,0.003166,0.080426,28.698723,1.461983,0.804260,-890.108337,0.079428,0.000000
145.190002,4.429375,-889.974854,-0.000776,0.003147,0.079923,19.702843,1.003711,0.799234,-889.974854,0.078821,0.000000
145.550003,1.911766,-890.019348,-0.000780,0.003121,0.079272,8.503960,0.433212,0.792724,-890.019348,0.078223,0.000000
145.910004,-0.023087,-889.974854,-0.000793,0.003100,0.078744,-0.102694,-0.005231,0.787440,-889.974854,0.077625,0.000000
146.270004,-2.465847,-890.063843,-0.000785,0.003074,0.078084,-10.968636,-0.558769,0.780839,-890.063843,0.077027,0.000000
146.630005,-0.507538,-890.108337,-0.000845,0.003059,0.077702,-2.257641,-0.115010,0.777024,-890.108337,0.076428,0.000000
146.990005,-0.433807,-889.974854,-0.000871,0.003025,0.076844,-1.929672,-0.098302,0.768440,-889.974854,0.075821,0.000000
147.350006,-0.166077,-890.063843,-0.000918,0.003002,0.076246,-0.738746,-0.037634,0.762460,-890.063843,0.075223,0.000000
147.710007,-0.108727,-890.063843,-0.000961,0.002977,0.075613,-0.483640,-0.024638,0.756131,-890.063843,0.074625,0.000000
148.070007,-0.032021,-890.063843,-0.000983,0.002954,0.075023,-0.142435,-0.007256,0.750227,-890.063843,0.074026,0.000000
148.430008,0.058838,-890.063843,-0.001052,0.002940,0.074668,0.261724,0.013333,0.746684,-890.063843,0.074520,0.000000
148.500000,0.067772,-890.152771,-0.001043,0.002940,0.074676,0.301465,0.015357,0.746760,-890.152771,0.074520,0.000000