File: Data/compression 35/ManualNoHeating-12-35-reverse-1-3_11182024_165724.csv
Time (sec),S:Load (lbs),S:HL1 (DIM),S:LVDT (in),S:Position (in),Ch:Position (mm),Ch:Load (N),Ch:Stress (MPa),Ch:Strain (mm/mm),Ch:HL1 (DIM),Set Point (),Cycles ()
0.110000,0.074478,-819.428101,-0.012615,-0.007581,-0.192559,0.331295,0.016877,-1.925588,-819.428101,-0.192238,0.000000
0.500000,-0.005585,-819.383606,-0.012611,-0.007520,-0.190998,-0.024842,-0.001266,-1.909979,-819.383606,-0.190314,0.000000
0.890000,-0.045799,-819.428101,-0.012499,-0.007304,-0.185526,-0.203725,-0.010378,-1.855265,-819.428101,-0.183826,0.000000
1.280000,-0.037979,-819.383606,-0.012223,-0.007040,-0.178814,-0.168940,-0.008606,-1.788136,-819.383606,-0.177322,0.000000
1.670000,-0.102402,-819.428101,-0.011973,-0.006794,-0.172570,-0.455506,-0.023205,-1.725700,-819.428101,-0.170818,0.000000
2.060000,-0.002975,-819.517029,-0.011680,-0.006523,-0.165692,-0.013236,-0.000674,-1.656921,-819.517029,-0.164331,0.000000
2.450000,0.008194,-819.383606,-0.011421,-0.006261,-0.159023,0.036449,0.001857,-1.590231,-819.383606,-0.157827,0.000000
2.840000,-0.014893,-819.428101,-0.011145,-0.006016,-0.152805,-0.066245,-0.003375,-1.528053,-819.428101,-0.151340,0.000000
3.230000,-0.026062,-819.428101,-0.010908,-0.005760,-0.146292,-0.115930,-0.005906,-1.462922,-819.428101,-0.144836,0.000000
3.620000,-0.048775,-819.383606,-0.010649,-0.005503,-0.139788,-0.216961,-0.011053,-1.397883,-819.383606,-0.138332,0.000000
4.010000,0.005219,-819.428101,-0.010365,-0.005246,-0.133242,0.023213,0.001183,-1.332419,-819.428101,-0.131845,0.000000
4.400000,0.000374,-819.428101,-0.010106,-0.004991,-0.126771,0.001663,0.000085,-1.267713,-819.428101,-0.125341,0.000000
4.790000,0.001495,-819.561523,-0.009835,-0.004733,-0.120223,0.006652,0.000339,-1.202234,-819.561523,-0.118853,0.000000
5.180000,-0.025688,-819.472534,-0.009597,-0.004480,-0.113798,-0.114267,-0.005821,-1.137982,-819.472534,-0.112349,0.000000
5.570000,-0.020103,-819.472534,-0.009326,-0.004219,-0.107155,-0.089425,-0.004556,-1.071549,-819.472534,-0.105845,0.000000
5.960001,-0.049896,-819.517029,-0.009054,-0.003971,-0.100851,-0.221950,-0.011307,-1.008508,-819.517029,-0.099358,0.000000
6.350000,0.016014,-819.517029,-0.008778,-0.003705,-0.094112,0.071234,0.003629,-0.941122,-819.517029,-0.092854,0.000000
6.740000,0.036125,-819.561523,-0.008528,-0.003450,-0.087634,0.160693,0.008186,-0.876339,-819.561523,-0.086368,0.000000
7.130000,0.010429,-819.517029,-0.008239,-0.003196,-0.081172,0.046392,0.002363,-0.811724,-819.517029,-0.079863,0.000000
7.520000,0.002983,-819.517029,-0.008002,-0.002941,-0.074694,0.013269,0.000676,-0.746941,-819.517029,-0.073359,0.000000
7.910000,-0.006699,-819.561523,-0.007731,-0.002682,-0.068113,-0.029797,-0.001518,-0.681130,-819.561523,-0.066873,0.000000
8.300000,0.029793,-819.561523,-0.007463,-0.002428,-0.061660,0.132525,0.006751,-0.616605,-819.561523,-0.060368,0.000000
8.690001,0.026443,-819.606018,-0.007200,-0.002170,-0.055122,0.117626,0.005992,-0.551217,-819.606018,-0.053882,0.000000
9.080001,0.024956,-819.561523,-0.006924,-0.001917,-0.048687,0.111009,0.005655,-0.486874,-819.561523,-0.047378,0.000000
9.470000,-0.000366,-819.650513,-0.006670,-0.001658,-0.042114,-0.001629,-0.000083,-0.421138,-819.650513,-0.040872,0.000000
9.860001,-0.026810,-819.561523,-0.006390,-0.001400,-0.035548,-0.119255,-0.006075,-0.355477,-819.561523,-0.034387,0.000000
10.250001,-0.027924,-819.606018,-0.006140,-0.001148,-0.029157,-0.124210,-0.006328,-0.291573,-819.606018,-0.027883,0.000000
10.640000,0.008942,-819.650513,-0.005881,-0.000893,-0.022687,0.039774,0.002026,-0.226867,-819.650513,-0.021377,0.000000
11.030001,0.048782,-819.561523,-0.005631,-0.000641,-0.016278,0.216995,0.011054,-0.162781,-819.561523,-0.014891,0.000000
11.420000,0.013779,-819.650513,-0.005355,-0.000382,-0.009714,0.061291,0.003122,-0.097136,-819.650513,-0.008387,0.000000
11.810000,-0.004837,-819.650513,-0.005083,-0.000128,-0.003244,-0.021516,-0.001096,-0.032444,-819.650513,-0.001900,0.000000
12.200001,0.214859,-819.650513,-0.004894,-0.000008,-0.000200,0.955741,0.048688,-0.001998,-819.650513,0.000042,0.000000
12.590000,0.187675,-819.739441,-0.004885,-0.000008,-0.000200,0.834822,0.042528,-0.001998,-819.739441,0.000042,0.000000
12.980000,0.102036,-819.650513,-0.004902,-0.000008,-0.000200,0.453877,0.023122,-0.001998,-819.650513,0.000633,0.000000
13.370001,0.099426,-819.694946,-0.004898,-0.000008,-0.000191,0.442270,0.022530,-0.001908,-819.694946,0.001284,0.000000
13.760000,0.294548,-819.694946,-0.004850,0.000033,0.000840,1.310215,0.066746,0.008402,-819.694946,0.001933,0.000000
14.150001,0.329178,-819.694946,-0.004829,0.000057,0.001447,1.464256,0.074593,0.014473,-819.694946,0.002584,0.000000
14.540001,0.502335,-819.739441,-0.004777,0.000091,0.002315,2.234496,0.113831,0.023148,-819.739441,0.003234,0.000000
14.930000,0.528030,-819.650513,-0.004777,0.000111,0.002810,2.348797,0.119653,0.028099,-819.650513,0.003885,0.000000
15.320001,0.554466,-819.739441,-0.004760,0.000123,0.003131,2.466389,0.125644,0.031309,-819.739441,0.004536,0.000000
15.710001,0.921249,-819.650513,-0.004725,0.000158,0.004024,4.097922,0.208758,0.040241,-819.650513,0.005185,0.000000
16.100000,1.074295,-819.783936,-0.004708,0.000186,0.004734,4.778703,0.243439,0.047341,-819.783936,0.005827,0.000000
16.490002,1.287292,-819.783936,-0.004678,0.000209,0.005306,5.726163,0.291705,0.053064,-819.783936,0.006478,0.000000
16.880001,1.446671,-819.694946,-0.004652,0.000230,0.005853,6.435112,0.327820,0.058530,-819.694946,0.007128,0.000000
17.270000,1.764305,-819.828430,-0.004639,0.000257,0.006539,7.848021,0.399797,0.065388,-819.828430,0.007779,0.000000
17.660002,2.119545,-819.783936,-0.004596,0.000286,0.007276,9.428207,0.480296,0.072761,-819.783936,0.008430,0.000000
18.050001,2.446487,-819.783936,-0.004587,0.000314,0.007986,10.882520,0.554382,0.079861,-819.783936,0.009079,0.000000
18.440001,2.701195,-819.739441,-0.004544,0.000334,0.008481,12.015514,0.612100,0.084812,-819.739441,0.009730,0.000000
18.830002,2.985313,-819.739441,-0.004523,0.000358,0.009105,13.279337,0.676482,0.091049,-819.739441,0.010380,0.000000
19.220001,3.393059,-819.828430,-0.004510,0.000389,0.009868,15.093080,0.768878,0.098680,-819.828430,0.011031,0.000000
19.610001,3.776978,-819.739441,-0.004488,0.000414,0.010528,16.800835,0.855875,0.105281,-819.739441,0.011682,0.000000
20.000000,4.127754,-819.828430,-0.004462,0.000441,0.011212,18.361168,0.935362,0.112124,-819.828430,0.012331,0.000000
20.390001,4.419319,-819.783936,-0.004432,0.000462,0.011733,19.658113,1.001432,0.117332,-819.783936,0.012982,0.000000
20.780001,4.801376,-819.828430,-0.004424,0.000490,0.012452,21.357588,1.088007,0.124523,-819.828430,0.013632,0.000000
21.170000,5.068741,-819.872864,-0.004406,0.000509,0.012938,22.546885,1.148593,0.129383,-819.872864,0.014283,0.000000
21.560001,5.644798,-819.828430,-0.004363,0.000544,0.013806,25.109316,1.279130,0.138058,-819.828430,0.014934,0.000000
21.950001,6.165001,-819.872864,-0.004346,0.000576,0.014638,27.423294,1.397009,0.146385,-819.872864,0.015583,0.000000
22.340000,6.517265,-819.872864,-0.004303,0.000602,0.015280,28.990244,1.476833,0.152804,-819.872864,0.016234,0.000000
22.730001,6.701965,-819.872864,-0.004303,0.000627,0.015922,29.811831,1.518687,0.159223,-819.872864,0.016885,0.000000
23.120001,7.196098,-819.917358,-0.004273,0.000655,0.016641,32.009846,1.630659,0.166414,-819.917358,0.017535,0.000000
23.510000,7.328293,-819.783936,-0.004238,0.000673,0.017084,32.597874,1.660615,0.170835,-819.783936,0.018186,0.000000
23.900002,7.684280,-819.917358,-0.004212,0.000695,0.017648,34.181385,1.741283,0.176482,-819.917358,0.018835,0.000000
24.290001,7.757263,-819.872864,-0.004199,0.000714,0.018125,34.506031,1.757821,0.181251,-819.872864,0.019486,0.000000
24.680000,8.346733,-819.872864,-0.004178,0.000743,0.018862,37.128124,1.891397,0.188624,-819.872864,0.020137,0.000000
25.070002,8.930611,-819.917358,-0.004148,0.000774,0.019668,39.725342,2.023705,0.196678,-819.917358,0.020779,0.000000
25.460001,9.098183,-819.917358,-0.004130,0.000795,0.020205,40.470737,2.061678,0.202053,-819.917358,0.021429,0.000000
25.850000,9.345436,-819.961853,-0.004117,0.000821,0.020856,41.570576,2.117706,0.208563,-819.961853,0.022080,0.000000
26.240002,9.706261,-819.872864,-0.004074,0.000848,0.021542,43.175602,2.199470,0.215421,-819.872864,0.022729,0.000000
26.630001,10.036186,-819.961853,-0.004053,0.000875,0.022217,44.643185,2.274232,0.222173,-819.961853,0.023380,0.000000
27.020000,10.230934,-820.006348,-0.004049,0.000894,0.022712,45.509468,2.318363,0.227124,-820.006348,0.024031,0.000000
27.410002,10.891899,-819.917358,-0.004001,0.000931,0.023640,48.449589,2.468139,0.236405,-819.917358,0.024681,0.000000
27.800001,10.910141,-819.961853,-0.003971,0.000950,0.024134,48.530731,2.472273,0.241340,-819.961853,0.025332,0.000000
28.190001,11.511528,-819.961853,-0.003954,0.000982,0.024941,51.205833,2.608550,0.249409,-819.961853,0.025981,0.000000
28.580002,11.451576,-819.917358,-0.003928,0.001004,0.025497,50.939156,2.594964,0.254966,-819.917358,0.026632,0.000000
28.970001,11.186073,-819.961853,-0.003902,0.001012,0.025713,49.758141,2.534801,0.257131,-819.961853,0.027283,0.000000
29.360001,12.494965,-819.961853,-0.003872,0.001058,0.026874,55.580379,2.831399,0.268743,-819.961853,0.027933,0.000000
29.750002,12.381760,-820.050842,-0.003863,0.001080,0.027439,55.076817,2.805747,0.274390,-820.050842,0.028584,0.000000
30.140001,12.754135,-820.006348,-0.003811,0.001107,0.028107,56.733227,2.890128,0.281066,-820.006348,0.029235,0.000000
30.530001,12.654335,-820.095276,-0.003798,0.001125,0.028565,56.289295,2.867513,0.285654,-820.095276,0.029884,0.000000
30.920002,13.034904,-820.050842,-0.003773,0.001156,0.029356,57.982151,2.953752,0.293556,-820.050842,0.030535,0.000000
31.310001,13.733101,-820.050842,-0.003751,0.001185,0.030110,61.087883,3.111965,0.301096,-820.050842,0.031185,0.000000
31.700001,13.598297,-820.095276,-0.003729,0.001205,0.030612,60.488247,3.081418,0.306122,-820.095276,0.031836,0.000000
32.090000,13.944237,-820.050842,-0.003699,0.001233,0.031315,62.027061,3.159809,0.313147,-820.050842,0.032487,0.000000
32.480003,14.075310,-820.095276,-0.003669,0.001256,0.031914,62.610104,3.189511,0.319142,-820.095276,0.033136,0.000000
32.870003,14.150528,-820.139771,-0.003652,0.001277,0.032443,62.944691,3.206555,0.324426,-820.139771,0.033787,0.000000
33.260002,14.951500,-820.095276,-0.003613,0.001315,0.033396,66.507591,3.388058,0.333964,-820.095276,0.034436,0.000000
33.650002,14.885223,-820.228760,-0.003579,0.001339,0.034020,66.212784,3.373040,0.340201,-820.228760,0.035087,0.000000
34.040001,14.621208,-820.050842,-0.003561,0.001355,0.034411,65.038383,3.313213,0.344108,-820.050842,0.035729,0.000000
34.430000,15.116463,-820.095276,-0.003531,0.001384,0.035166,67.241386,3.425439,0.351662,-820.095276,0.036380,0.000000
34.820004,14.948524,-820.095276,-0.003505,0.001401,0.035590,66.494354,3.387384,0.355901,-820.095276,0.037030,0.000000
35.210003,16.014252,-820.139771,-0.003471,0.001441,0.036597,71.234947,3.628881,0.365969,-820.139771,0.037681,0.000000
35.600002,16.010902,-820.273193,-0.003441,0.001467,0.037265,71.220055,3.628122,0.372646,-820.273193,0.038330,0.000000
35.990002,15.878708,-820.139771,-0.003397,0.001491,0.037872,70.632019,3.598166,0.378717,-820.139771,0.038981,0.000000
36.380001,15.645973,-820.184265,-0.003363,0.001512,0.038409,69.596764,3.545428,0.384091,-820.184265,0.039632,0.000000
36.770000,15.357758,-820.139771,-0.003372,0.001523,0.038695,68.314720,3.480118,0.386953,-820.139771,0.040282,0.000000
37.160004,16.806664,-820.184265,-0.003333,0.001568,0.039840,74.759773,3.808444,0.398398,-820.184265,0.040933,0.000000
37.550003,17.247551,-820.228760,-0.003281,0.001602,0.040689,76.720940,3.908351,0.406891,-820.228760,0.041582,0.000000
37.940002,16.408592,-820.184265,-0.003255,0.001612,0.040950,72.989067,3.718240,0.409495,-820.184265,0.042233,0.000000
38.330002,16.708725,-820.228760,-0.003234,0.001638,0.041610,74.324120,3.786251,0.416096,-820.228760,0.042884,0.000000
38.720001,17.190208,-820.184265,-0.003208,0.001666,0.042312,76.465866,3.895357,0.423121,-820.184265,0.043534,0.000000
39.110001,17.969208,-820.184265,-0.003182,0.001699,0.043145,79.931030,4.071881,0.431448,-820.184265,0.044185,0.000000
39.500000,17.524971,-820.317688,-0.003139,0.001716,0.043587,77.954964,3.971215,0.435869,-820.317688,0.044836,0.000000
39.890003,17.847443,-820.184265,-0.003126,0.001741,0.044211,79.389389,4.044288,0.442106,-820.184265,0.045485,0.000000
40.280003,18.031769,-820.317688,-0.003113,0.001763,0.044783,80.209312,4.086057,0.447829,-820.317688,0.046136,0.000000
40.670002,18.839447,-820.273193,-0.003070,0.001797,0.045650,83.802048,4.269080,0.456504,-820.273193,0.046786,0.000000
41.060001,19.150749,-820.273193,-0.003035,0.001826,0.046370,85.186790,4.339622,0.463695,-820.273193,0.047437,0.000000
41.450001,18.753799,-820.317688,-0.002992,0.001842,0.046786,83.421066,4.249671,0.467858,-820.317688,0.048088,0.000000
41.840000,19.206978,-820.273193,-0.003001,0.001869,0.047472,85.436905,4.352363,0.474717,-820.273193,0.048737,0.000000
42.230003,19.408798,-820.362183,-0.002966,0.001894,0.048104,86.334648,4.398097,0.481045,-820.362183,0.049388,0.000000
42.620003,19.860489,-820.317688,-0.002936,0.001924,0.048858,88.343864,4.500452,0.488585,-820.317688,0.050038,0.000000
43.010002,20.642471,-820.317688,-0.002910,0.001952,0.049588,91.822296,4.677651,0.495882,-820.317688,0.050680,0.000000
43.400002,20.531876,-820.317688,-0.002897,0.001975,0.050160,91.330345,4.652590,0.501605,-820.317688,0.051331,0.000000
43.790001,21.134377,-820.317688,-0.002850,0.002009,0.051026,94.010399,4.789118,0.510264,-820.317688,0.051982,0.000000
44.180000,21.266563,-820.362183,-0.002828,0.002035,0.051677,94.598396,4.819072,0.516774,-820.362183,0.052631,0.000000
44.570004,21.301941,-820.273193,-0.002798,0.002058,0.052268,94.755768,4.827089,0.522679,-820.273193,0.053282,0.000000
44.960003,21.412910,-820.362183,-0.002785,0.002080,0.052822,95.249382,4.852235,0.528220,-820.362183,0.053932,0.000000
45.350002,21.554039,-820.317688,-0.002768,0.002102,0.053387,95.877151,4.884215,0.533867,-820.317688,0.054583,0.000000
45.740002,21.993813,-820.317688,-0.002746,0.002127,0.054036,97.833366,4.983869,0.540362,-820.317688,0.055234,0.000000
46.130001,21.840019,-820.317688,-0.002733,0.002150,0.054608,97.149254,4.949019,0.546085,-820.317688,0.055883,0.000000
46.520000,22.671158,-820.317688,-0.002703,0.002178,0.055311,100.846344,5.137358,0.553109,-820.317688,0.056534,0.000000
46.910004,23.365257,-820.406677,-0.002682,0.002208,0.056074,103.933853,5.294643,0.560740,-820.406677,0.057185,0.000000
47.300003,22.737068,-820.362183,-0.002656,0.002221,0.056413,101.139534,5.152293,0.564131,-820.362183,0.057835,0.000000
47.690002,23.113159,-820.406677,-0.002621,0.002251,0.057176,102.812469,5.237517,0.571761,-820.406677,0.058486,0.000000
48.080002,23.596870,-820.406677,-0.002596,0.002275,0.057774,104.964119,5.347127,0.577742,-820.406677,0.059135,0.000000
48.470001,23.914139,-820.362183,-0.002578,0.002301,0.058433,106.375404,5.419022,0.584327,-820.362183,0.059786,0.000000
48.860001,24.843575,-820.451172,-0.002557,0.002336,0.059326,110.509735,5.629634,0.593260,-820.451172,0.060437,0.000000
49.250004,24.312943,-820.406677,-0.002544,0.002353,0.059770,108.149368,5.509392,0.597695,-820.406677,0.061087,0.000000
49.640003,24.905762,-820.451172,-0.002522,0.002381,0.060489,110.786362,5.643726,0.604887,-820.451172,0.061738,0.000000
50.030003,24.809692,-820.495605,-0.002496,0.002407,0.061131,110.359024,5.621957,0.611306,-820.495605,0.062387,0.000000
50.420002,25.139244,-820.495605,-0.002470,0.002426,0.061624,111.824944,5.696634,0.616241,-820.495605,0.063038,0.000000
50.810001,26.241463,-820.451172,-0.002453,0.002461,0.062510,116.727859,5.946401,0.625098,-820.451172,0.063689,0.000000
51.200001,26.191940,-820.451172,-0.002419,0.002486,0.063152,116.507568,5.935179,0.631517,-820.451172,0.064339,0.000000
51.590004,26.158051,-820.495605,-0.002406,0.002508,0.063706,116.356819,5.927499,0.637058,-820.495605,0.064990,0.000000
51.980003,26.417969,-820.540100,-0.002389,0.002533,0.064348,117.512993,5.986397,0.643478,-820.540100,0.065632,0.000000
52.370003,26.467117,-820.540100,-0.002358,0.002559,0.064999,117.731621,5.997535,0.649988,-820.540100,0.066281,0.000000
52.760002,27.295280,-820.495605,-0.002345,0.002590,0.065778,121.415474,6.185199,0.657784,-820.495605,0.066932,0.000000
53.150002,26.835770,-820.540100,-0.002311,0.002611,0.066316,119.371468,6.081072,0.663159,-820.540100,0.067583,0.000000
53.540001,27.846016,-820.540100,-0.002289,0.002642,0.067114,123.865265,6.309997,0.671138,-820.540100,0.068233,0.000000
53.930004,27.503807,-820.540100,-0.002276,0.002663,0.067635,122.343040,6.232452,0.676346,-820.540100,0.068884,0.000000
54.320004,27.145210,-820.584595,-0.002251,0.002685,0.068190,120.747925,6.151193,0.681902,-820.584595,0.069533,0.000000
54.710003,28.382233,-820.584595,-0.002220,0.002720,0.069091,126.250473,6.431506,0.690910,-820.584595,0.070184,0.000000
55.100002,28.367706,-820.495605,-0.002216,0.002746,0.069759,126.185860,6.428214,0.697586,-820.495605,0.070835,0.000000
55.490002,28.074654,-820.629089,-0.002203,0.002765,0.070228,124.882294,6.361807,0.702280,-820.629089,0.071485,0.000000
55.880001,27.933899,-820.629089,-0.002190,0.002793,0.070930,124.256187,6.329912,0.709304,-820.629089,0.072136,0.000000
56.270004,28.547195,-820.629089,-0.002160,0.002822,0.071668,126.984268,6.468887,0.716677,-820.629089,0.072787,0.000000
56.660004,28.814926,-820.629089,-0.002147,0.002846,0.072282,128.175186,6.529556,0.722824,-820.629089,0.073436,0.000000
57.050003,29.185814,-820.584595,-0.002126,0.002880,0.073150,129.824982,6.613600,0.731499,-820.584595,0.074087,0.000000
57.440002,28.659279,-820.673523,-0.002100,0.002902,0.073713,127.482841,6.494286,0.737131,-820.673523,0.074737,0.000000
57.830002,27.260643,-820.629089,-0.002074,0.002913,0.073999,121.261398,6.177350,0.739992,-820.629089,0.075388,0.000000
58.220001,27.220055,-820.629089,-0.002070,0.002936,0.074573,121.080849,6.168153,0.745730,-820.629089,0.076039,0.000000
58.610004,28.610870,-820.673523,-0.002044,0.002970,0.075439,127.267509,6.483316,0.754390,-820.673523,0.076688,0.000000
59.000004,29.027557,-820.673523,-0.002039,0.003004,0.076297,129.121017,6.577739,0.762974,-820.673523,0.077339,0.000000
59.390003,28.303291,-820.673523,-0.002022,0.003025,0.076827,125.899330,6.413617,0.768273,-820.673523,0.077989,0.000000
59.780003,27.453537,-820.762512,-0.001983,0.003041,0.077235,122.119431,6.221061,0.772346,-820.762512,0.078640,0.000000
60.170002,27.978210,-820.673523,-0.001988,0.003068,0.077928,124.453293,6.339953,0.779280,-820.673523,0.079291,0.000000
60.560001,28.922546,-820.762512,-0.001966,0.003104,0.078839,128.653915,6.553943,0.788394,-820.762512,0.079940,0.000000
60.950005,28.379623,-820.718018,-0.001949,0.003124,0.079351,126.238869,6.430914,0.793511,-820.718018,0.080591,0.000000
61.340004,28.256744,-820.718018,-0.001919,0.003143,0.079845,125.692276,6.403069,0.798446,-820.718018,0.081233,0.000000
61.730003,28.502884,-820.762512,-0.001910,0.003172,0.080573,126.787163,6.458846,0.805728,-820.762512,0.081882,0.000000
62.120003,29.851990,-820.718018,-0.001888,0.003207,0.081449,132.788284,6.764557,0.814494,-820.718018,0.082533,0.000000
62.510002,29.828156,-820.807007,-0.001863,0.003230,0.082047,132.682266,6.759157,0.820474,-820.807007,0.083184,0.000000
62.900002,29.966301,-820.762512,-0.001850,0.003254,0.082664,133.296768,6.790461,0.826636,-820.762512,0.083834,0.000000
63.290005,29.517593,-820.718018,-0.001832,0.003272,0.083106,131.300812,6.688782,0.831057,-820.718018,0.084485,0.000000
63.680004,29.644203,-820.762512,-0.001824,0.003299,0.083792,131.863998,6.717472,0.837915,-820.762512,0.085134,0.000000
64.070000,29.400299,-820.762512,-0.001798,0.003312,0.084120,130.779068,6.662203,0.841200,-820.762512,0.085785,0.000000
64.460007,31.948441,-820.762512,-0.001776,0.003362,0.085387,142.113754,7.239620,0.853872,-820.762512,0.086436,0.000000
64.850006,32.142822,-820.807007,-0.001738,0.003391,0.086141,142.978409,7.283668,0.861412,-820.807007,0.087086,0.000000
65.240005,32.235168,-820.807007,-0.001725,0.003414,0.086723,143.389191,7.304594,0.867225,-820.807007,0.087737,0.000000
65.630005,32.611267,-820.807007,-0.001694,0.003444,0.087476,145.062164,7.389819,0.874765,-820.807007,0.088388,0.000000
66.020004,32.228470,-820.807007,-0.001673,0.003461,0.087902,143.359390,7.303076,0.879019,-820.807007,0.089037,0.000000
66.410004,32.439232,-820.762512,-0.001673,0.003485,0.088509,144.296906,7.350835,0.885090,-820.762512,0.089688,0.000000
66.800003,32.450401,-820.807007,-0.001656,0.003501,0.088916,144.346588,7.353366,0.889163,-820.807007,0.090338,0.000000
67.190002,34.054955,-820.762512,-0.001638,0.003538,0.089861,151.484009,7.716963,0.898610,-820.762512,0.090989,0.000000
67.580002,34.829865,-820.851440,-0.001600,0.003564,0.090538,154.930969,7.892560,0.905377,-820.851440,0.091640,0.000000
67.970001,34.317108,-820.851440,-0.001582,0.003579,0.090910,152.650116,7.776368,0.909101,-820.851440,0.092289,0.000000
68.360001,35.744781,-820.895935,-0.001578,0.003615,0.091831,159.000732,8.099883,0.918306,-820.895935,0.092940,0.000000
68.750000,36.117149,-820.851440,-0.001556,0.003637,0.092385,160.657104,8.184263,0.923847,-820.851440,0.093590,0.000000
69.140007,36.336479,-820.895935,-0.001539,0.003657,0.092880,161.632736,8.233964,0.928798,-820.895935,0.094241,0.000000
69.530006,37.240227,-820.895935,-0.001518,0.003685,0.093590,165.652802,8.438756,0.935899,-820.895935,0.094892,0.000000
69.920006,38.365166,-820.895935,-0.001509,0.003717,0.094415,170.656784,8.693671,0.944150,-820.895935,0.095541,0.000000
70.310005,38.908081,-820.940430,-0.001492,0.003743,0.095064,173.071793,8.816697,0.950644,-820.940430,0.096183,0.000000
70.700005,38.616890,-820.851440,-0.001462,0.003755,0.095385,171.776505,8.750712,0.953854,-820.851440,0.096834,0.000000
71.090004,40.441139,-820.851440,-0.001431,0.003793,0.096339,179.891174,9.164093,0.963392,-820.851440,0.097484,0.000000
71.480003,40.273949,-820.940430,-0.001414,0.003808,0.096730,179.147476,9.126207,0.967298,-820.940430,0.098135,0.000000
71.870003,40.886871,-820.940430,-0.001401,0.003830,0.097276,181.873886,9.265098,0.972763,-820.940430,0.098786,0.000000
72.260002,42.991524,-820.940430,-0.001393,0.003869,0.098282,191.235855,9.742019,0.982816,-820.940430,0.099435,0.000000
72.650002,43.282341,-820.984924,-0.001358,0.003887,0.098733,192.529465,9.807919,0.987328,-820.984924,0.100086,0.000000
73.040001,44.517876,-820.940430,-0.001341,0.003917,0.099488,198.025406,10.087894,0.994882,-820.940430,0.100737,0.000000
73.430000,45.599617,-821.029419,-0.001328,0.003944,0.100182,202.837219,10.333021,1.001816,-821.029419,0.101387,0.000000
73.820000,45.677818,-820.984924,-0.001319,0.003965,0.100710,203.185089,10.350742,1.007100,-820.984924,0.102038,0.000000
74.210007,47.515846,-821.029419,-0.001289,0.003992,0.101387,211.361038,10.767245,1.013867,-821.029419,0.102687,0.000000
74.600006,48.864952,-821.029419,-0.001281,0.004020,0.102098,217.362167,11.072956,1.020983,-821.029419,0.103338,0.000000
74.990005,50.029732,-820.940430,-0.001255,0.004047,0.102801,222.543365,11.336899,1.028008,-820.940430,0.103989,0.000000
75.380005,50.676918,-820.940430,-0.001250,0.004066,0.103287,225.422195,11.483554,1.032868,-820.940430,0.104639,0.000000
75.770004,52.736877,-821.029419,-0.001229,0.004101,0.104153,234.585342,11.950347,1.041527,-821.029419,0.105290,0.000000
76.160004,54.006302,-820.984924,-0.001216,0.004128,0.104855,240.232025,12.238003,1.048552,-820.984924,0.105939,0.000000
76.550003,54.741364,-821.029419,-0.001194,0.004145,0.105281,243.501740,12.404571,1.052806,-821.029419,0.106590,0.000000
76.940002,56.360809,-820.984924,-0.001173,0.004176,0.106078,250.705399,12.771543,1.060785,-820.984924,0.107241,0.000000
77.330002,57.312218,-821.073853,-0.001168,0.004195,0.106555,254.937469,12.987134,1.065554,-821.073853,0.107891,0.000000
77.720001,59.562096,-821.029419,-0.001168,0.004229,0.107406,264.945435,13.496964,1.074062,-821.029419,0.108542,0.000000
78.110001,60.373123,-820.984924,-0.001125,0.004246,0.107839,268.553070,13.680745,1.078392,-820.984924,0.109193,0.000000
78.500000,62.927223,-821.118347,-0.001125,0.004281,0.108732,279.914276,14.259512,1.087325,-821.118347,0.109842,0.000000
78.890007,64.158287,-821.073853,-0.001095,0.004304,0.109330,285.390320,14.538476,1.093305,-821.073853,0.110493,0.000000
79.280006,63.998909,-821.073853,-0.001095,0.004313,0.109547,284.681366,14.502360,1.095470,-821.073853,0.111135,0.000000
79.670006,66.690422,-821.118347,-0.001078,0.004339,0.110198,296.653809,15.112266,1.101980,-821.118347,0.110440,0.000000
80.060005,65.558784,-821.118347,-0.001069,0.004338,0.110181,291.620026,14.855833,1.101813,-821.118347,294.500488,0.000000
80.450005,64.697105,-821.118347,-0.001069,0.004338,0.110181,287.787109,14.660574,1.101813,-821.118347,294.500488,0.000000
80.840004,66.355659,-821.118347,-0.001048,0.004321,0.109747,295.164703,15.036407,1.097468,-821.118347,294.500488,0.000000
81.230003,65.591179,-821.118347,-0.001048,0.004321,0.109756,291.764130,14.863173,1.097559,-821.118347,294.500488,0.000000
81.620003,65.065010,-821.162842,-0.001048,0.004347,0.110424,289.423615,14.743942,1.104236,-821.162842,294.500488,0.000000
82.010002,65.305199,-821.118347,-0.001039,0.004362,0.110796,290.492035,14.798369,1.107960,-821.118347,294.500488,0.000000
82.400002,64.990166,-821.162842,-0.001052,0.004362,0.110796,289.090698,14.726981,1.107960,-821.162842,294.500488,0.000000
82.790001,65.496223,-821.118347,-0.001030,0.004372,0.111040,291.341766,14.841657,1.110397,-821.118347,294.500488,0.000000
83.180000,65.209129,-821.073853,-0.001039,0.004372,0.111040,290.064697,14.776600,1.110397,-821.073853,294.500488,0.000000
83.570007,64.922768,-821.162842,-0.001035,0.004372,0.111047,288.790894,14.711709,1.110473,-821.162842,294.500488,0.000000
83.960007,65.539421,-821.162842,-0.001022,0.004381,0.111282,291.533905,14.851445,1.112820,-821.162842,294.500488,0.000000
84.350006,65.319344,-821.162842,-0.001039,0.004381,0.111282,290.554962,14.801575,1.112820,-821.162842,294.500488,0.000000
84.740005,65.096291,-821.162842,-0.001022,0.004382,0.111308,289.562775,14.751030,1.113077,-821.162842,294.500488,0.000000
85.130005,65.567726,-821.162842,-0.001022,0.004390,0.111517,291.659821,14.857860,1.115166,-821.162842,294.500488,0.000000
85.520004,65.502922,-821.251770,-0.001026,0.004390,0.111517,291.371552,14.843175,1.115166,-821.251770,294.500488,0.000000
85.910004,65.333504,-821.251770,-0.001009,0.004390,0.111517,290.617950,14.804784,1.115166,-821.251770,294.500488,0.000000
86.300003,65.193489,-821.207336,-0.001022,0.004391,0.111524,289.995117,14.773055,1.115242,-821.207336,294.500488,0.000000
86.690002,65.034477,-821.251770,-0.001005,0.004391,0.111524,289.287811,14.737023,1.115242,-821.251770,294.500488,0.000000
87.080002,65.873070,-821.162842,-0.001026,0.004401,0.111777,293.018036,14.927051,1.117770,-821.162842,294.500488,0.000000
87.470001,65.765816,-821.340759,-0.001013,0.004401,0.111777,292.540955,14.902747,1.117770,-821.340759,294.500488,0.000000
87.860001,65.602715,-821.296265,-0.001009,0.004401,0.111777,291.815460,14.865788,1.117770,-821.296265,294.500488,0.000000
88.250008,65.506645,-821.207336,-0.001018,0.004401,0.111777,291.388123,14.844018,1.117770,-821.207336,294.500488,0.000000
88.640007,65.365898,-821.385254,-0.001018,0.004401,0.111777,290.762024,14.812124,1.117770,-821.385254,294.500488,0.000000
89.030006,65.262001,-821.207336,-0.001000,0.004401,0.111777,290.299866,14.788581,1.117770,-821.207336,294.500488,0.000000
89.420006,65.113045,-821.296265,-0.001009,0.004401,0.111785,289.637299,14.754827,1.117846,-821.296265,294.500488,0.000000
89.810005,64.995384,-821.340759,-0.001005,0.004401,0.111785,289.113922,14.728165,1.117846,-821.340759,294.500488,0.000000
90.200005,64.904518,-821.207336,-0.001009,0.004401,0.111785,288.709717,14.707574,1.117846,-821.207336,294.500488,0.000000
90.590004,65.389351,-821.340759,-0.000992,0.004409,0.111994,290.866364,14.817439,1.119935,-821.340759,294.500488,0.000000
90.980003,65.389351,-821.296265,-0.001005,0.004409,0.111994,290.866364,14.817439,1.119935,-821.296265,294.500488,0.000000
91.370003,65.333870,-821.296265,-0.000996,0.004409,0.111994,290.619568,14.804866,1.119935,-821.296265,294.500488,0.000000
91.760002,65.261635,-821.340759,-0.000992,0.004409,0.111994,290.298248,14.788498,1.119935,-821.340759,294.500488,0.000000
92.150002,65.193489,-821.296265,-0.001005,0.004409,0.111994,289.995117,14.773055,1.119935,-821.296265,294.500488,0.000000
92.540001,65.105598,-821.429749,-0.000992,0.004409,0.111994,289.604156,14.753139,1.119935,-821.429749,294.500488,0.000000
92.930008,65.016609,-821.340759,-0.000987,0.004409,0.111994,289.208313,14.732974,1.119935,-821.340759,294.500488,0.000000
93.320007,64.965599,-821.385254,-0.000992,0.004409,0.111994,288.981415,14.721416,1.119935,-821.385254,294.500488,0.000000
93.710007,64.876961,-821.385254,-0.000992,0.004409,0.111994,288.587128,14.701330,1.119935,-821.385254,294.500488,0.000000
94.100006,65.493996,-821.340759,-0.000992,0.004419,0.112236,291.331848,14.841151,1.122358,-821.340759,294.500488,0.000000
94.490005,65.593788,-821.429749,-0.001000,0.004418,0.112227,291.775757,14.863765,1.122267,-821.429749,294.500488,0.000000
94.880005,65.565483,-821.429749,-0.000979,0.004418,0.112227,291.649841,14.857351,1.122267,-821.429749,294.500488,0.000000
95.270004,65.529732,-821.429749,-0.001000,0.004418,0.112227,291.490814,14.849250,1.122267,-821.429749,294.500488,0.000000
95.660004,65.495476,-821.474182,-0.000996,0.004418,0.112227,291.338440,14.841487,1.122267,-821.474182,294.500488,0.000000
96.050003,65.416908,-821.474182,-0.000996,0.004418,0.112227,290.988953,14.823683,1.122267,-821.474182,294.500488,0.000000
96.440002,65.347649,-821.474182,-0.000996,0.004418,0.112227,290.680847,14.807989,1.122267,-821.474182,294.500488,0.000000
96.830002,65.308540,-821.518677,-0.000979,0.004418,0.112227,290.506897,14.799127,1.122267,-821.518677,294.500488,0.000000
97.220001,65.257164,-821.474182,-0.000983,0.004418,0.112227,290.278351,14.787484,1.122267,-821.474182,294.500488,0.000000
97.610008,65.200935,-821.518677,-0.000996,0.004418,0.112227,290.028259,14.774743,1.122267,-821.518677,294.500488,0.000000
98.000008,65.092201,-821.518677,-0.000979,0.004419,0.112236,289.544586,14.750103,1.122358,-821.518677,294.500488,0.000000
98.390007,65.046776,-821.563171,-0.000992,0.004419,0.112254,289.342499,14.739810,1.122539,-821.563171,294.500488,0.000000
98.780006,65.021080,-821.518677,-0.000983,0.004419,0.112254,289.228210,14.733988,1.122539,-821.518677,294.500488,0.000000
99.170006,65.006920,-821.474182,-0.000983,0.004419,0.112254,289.165222,14.730779,1.122539,-821.474182,294.500488,0.000000
99.560005,64.951820,-821.563171,-0.000992,0.004419,0.112254,288.920135,14.718292,1.122539,-821.563171,294.500488,0.000000
99.950005,64.895958,-821.518677,-0.000979,0.004419,0.112254,288.671631,14.705635,1.122539,-821.518677,294.500488,0.000000
100.340004,65.142464,-821.607666,-0.000987,0.004425,0.112384,289.768158,14.761494,1.123841,-821.607666,294.500488,0.000000
100.730003,65.240028,-821.563171,-0.000983,0.004424,0.112375,290.202148,14.783602,1.123750,-821.563171,294.500488,0.000000
101.120003,65.220665,-821.563171,-0.000979,0.004424,0.112375,290.115997,14.779214,1.123750,-821.563171,294.500488,0.000000
101.510002,65.193489,-821.607666,-0.000974,0.004424,0.112375,289.995117,14.773055,1.123750,-821.607666,294.500488,0.000000
101.900002,65.141350,-821.607666,-0.000983,0.004424,0.112375,289.763184,14.761241,1.123750,-821.607666,294.500488,0.000000
102.290009,65.106728,-821.518677,-0.000979,0.004424,0.112375,289.609192,14.753395,1.123750,-821.518677,294.500488,0.000000
102.680008,65.064644,-821.607666,-0.000974,0.004424,0.112375,289.421997,14.743859,1.123750,-821.607666,294.500488,0.000000
103.070007,65.032616,-821.563171,-0.000974,0.004424,0.112375,289.279510,14.736601,1.123750,-821.563171,294.500488,0.000000
103.460007,64.988686,-821.652100,-0.000983,0.004424,0.112375,289.084106,14.726646,1.123750,-821.652100,294.500488,0.000000
103.850006,64.984962,-821.607666,-0.000983,0.004424,0.112375,289.067535,14.725803,1.123750,-821.607666,294.500488,0.000000
104.240005,64.922401,-821.563171,-0.000983,0.004424,0.112375,288.789276,14.711626,1.123750,-821.563171,294.500488,0.000000
104.630005,64.876595,-821.696594,-0.000974,0.004424,0.112375,288.585510,14.701246,1.123750,-821.696594,294.500488,0.000000
105.020004,64.824837,-821.474182,-0.000987,0.004424,0.112375,288.355286,14.689518,1.123750,-821.474182,294.500488,0.000000
105.410004,64.784996,-821.607666,-0.000987,0.004425,0.112384,288.178070,14.680490,1.123841,-821.607666,294.500488,0.000000
105.800003,64.752968,-821.652100,-0.000974,0.004425,0.112392,288.035583,14.673232,1.123917,-821.652100,294.500488,0.000000
106.190002,64.716850,-821.652100,-0.000992,0.004425,0.112392,287.874939,14.665048,1.123917,-821.652100,294.500488,0.000000
106.580002,65.269081,-821.652100,-0.000979,0.004432,0.112566,290.331360,14.790185,1.125658,-821.652100,294.500488,0.000000
106.970009,65.302956,-821.607666,-0.000983,0.004432,0.112566,290.482056,14.797861,1.125658,-821.607666,294.500488,0.000000
107.360008,65.296638,-821.696594,-0.000987,0.004432,0.112566,290.453949,14.796430,1.125658,-821.696594,294.500488,0.000000
107.750008,65.292915,-821.652100,-0.000974,0.004432,0.112566,290.437378,14.795587,1.125658,-821.652100,294.500488,0.000000
108.140007,65.280998,-821.652100,-0.000983,0.004432,0.112566,290.384369,14.792886,1.125658,-821.652100,294.500488,0.000000
108.530006,65.264977,-821.696594,-0.000983,0.004432,0.112566,290.313110,14.789255,1.125658,-821.696594,294.500488,0.000000
108.920006,65.245247,-821.652100,-0.000974,0.004432,0.112566,290.225342,14.784784,1.125658,-821.652100,294.500488,0.000000
109.310005,65.228859,-821.741089,-0.000979,0.004432,0.112566,290.152466,14.781071,1.125658,-821.741089,294.500488,0.000000
109.700005,65.181938,-821.696594,-0.000979,0.004432,0.112566,289.943756,14.770438,1.125658,-821.696594,294.500488,0.000000
110.090004,65.155128,-821.652100,-0.000979,0.004432,0.112566,289.824493,14.764363,1.125658,-821.652100,294.500488,0.000000
110.480003,65.113045,-821.696594,-0.000979,0.004432,0.112566,289.637299,14.754827,1.125658,-821.696594,294.500488,0.000000
110.870003,65.072838,-821.652100,-0.000970,0.004432,0.112566,289.458435,14.745716,1.125658,-821.652100,294.500488,0.000000
111.260002,65.054955,-821.741089,-0.000992,0.004432,0.112566,289.378876,14.741663,1.125658,-821.741089,294.500488,0.000000
111.650002,65.041924,-821.696594,-0.000983,0.004432,0.112566,289.320923,14.738711,1.125658,-821.696594,294.500488,0.000000
112.040009,65.074699,-821.696594,-0.000966,0.004433,0.112608,289.466705,14.746138,1.126082,-821.696594,294.500488,0.000000
112.430008,65.069481,-821.785583,-0.000974,0.004433,0.112608,289.443512,14.744955,1.126082,-821.785583,294.500488,0.000000
112.820007,65.065010,-821.741089,-0.000957,0.004433,0.112608,289.423615,14.743942,1.126082,-821.741089,294.500488,0.000000
113.210007,65.049370,-821.785583,-0.000983,0.004433,0.112608,289.354034,14.740397,1.126082,-821.785583,294.500488,0.000000
113.600006,65.029640,-821.785583,-0.000961,0.004433,0.112608,289.266296,14.735928,1.126082,-821.785583,294.500488,0.000000
113.990005,65.024803,-821.785583,-0.000974,0.004433,0.112608,289.244781,14.734831,1.126082,-821.785583,294.500488,0.000000
114.380005,64.997246,-821.785583,-0.000983,0.004433,0.112608,289.122192,14.728586,1.126082,-821.785583,294.500488,0.000000
114.770004,64.986443,-821.696594,-0.000961,0.004433,0.112608,289.074127,14.726138,1.126082,-821.696594,294.500488,0.000000
115.160004,64.958138,-821.830078,-0.000974,0.004434,0.112617,288.948212,14.719725,1.126173,-821.830078,294.500488,0.000000
115.550003,64.931709,-821.830078,-0.000970,0.004434,0.112617,288.830658,14.713736,1.126173,-821.830078,294.500488,0.000000
115.940002,64.908241,-821.741089,-0.000970,0.004434,0.112617,288.726288,14.708417,1.126173,-821.741089,294.500488,0.000000
116.330002,64.867653,-821.874512,-0.000979,0.004434,0.112617,288.545746,14.699220,1.126173,-821.874512,294.500488,0.000000
116.720009,64.846062,-821.830078,-0.000979,0.004434,0.112617,288.449677,14.694327,1.126173,-821.830078,294.500488,0.000000
117.110008,64.821480,-821.830078,-0.000970,0.004434,0.112617,288.340332,14.688757,1.126173,-821.830078,294.500488,0.000000
117.500008,64.808083,-821.830078,-0.000974,0.004434,0.112617,288.280762,14.685721,1.126173,-821.830078,294.500488,0.000000
117.890007,64.784996,-821.785583,-0.000970,0.004434,0.112617,288.178070,14.680490,1.126173,-821.785583,294.500488,0.000000
118.280006,64.763771,-821.874512,-0.000970,0.004434,0.112626,288.083649,14.675680,1.126264,-821.874512,294.500488,0.000000
118.670006,65.002464,-821.830078,-0.000961,0.004438,0.112722,289.145416,14.729769,1.127217,-821.830078,294.500488,0.000000
119.060005,65.014000,-821.874512,-0.000970,0.004438,0.112722,289.196716,14.732384,1.127217,-821.874512,294.500488,0.000000
119.450005,65.022194,-821.874512,-0.000961,0.004438,0.112722,289.233154,14.734240,1.127217,-821.874512,294.500488,0.000000
119.840004,65.027031,-821.830078,-0.000966,0.004438,0.112722,289.254669,14.735335,1.127217,-821.830078,294.500488,0.000000
120.230003,64.999855,-821.919006,-0.000970,0.004438,0.112722,289.133789,14.729177,1.127217,-821.919006,294.500488,0.000000
120.620003,65.010643,-821.919006,-0.000970,0.004438,0.112722,289.181793,14.731623,1.127217,-821.919006,294.500488,0.000000
121.010002,65.000221,-821.874512,-0.000970,0.004438,0.112722,289.135437,14.729260,1.127217,-821.874512,294.500488,0.000000
121.400009,64.983833,-821.874512,-0.000966,0.004438,0.112722,289.062531,14.725547,1.127217,-821.874512,294.500488,0.000000
121.790009,64.974159,-821.919006,-0.000961,0.004438,0.112722,289.019501,14.723354,1.127217,-821.919006,294.500488,0.000000
122.180008,64.952553,-821.963501,-0.000970,0.004438,0.112722,288.923370,14.718459,1.127217,-821.963501,294.500488,0.000000
122.570007,64.937660,-821.963501,-0.000970,0.004438,0.112722,288.857147,14.715084,1.127217,-821.963501,294.500488,0.000000
122.960007,64.908241,-821.963501,-0.000974,0.004438,0.112722,288.726288,14.708417,1.127217,-821.963501,294.500488,0.000000
123.350006,64.906380,-822.007996,-0.000953,0.004438,0.112722,288.717987,14.707996,1.127217,-822.007996,294.500488,0.000000
123.740005,64.878090,-821.919006,-0.000966,0.004438,0.112722,288.592163,14.701586,1.127217,-821.919006,294.500488,0.000000
124.130005,64.854622,-822.007996,-0.000970,0.004438,0.112722,288.487762,14.696267,1.127217,-822.007996,294.500488,0.000000
124.520004,64.817009,-821.963501,-0.000961,0.004438,0.112722,288.320465,14.687744,1.127217,-821.963501,294.500488,0.000000
124.910004,64.818138,-822.007996,-0.000961,0.004438,0.112722,288.325470,14.688000,1.127217,-822.007996,294.500488,0.000000
125.300003,64.796913,-821.963501,-0.000970,0.004438,0.112722,288.231079,14.683190,1.127217,-821.963501,294.500488,0.000000
125.690002,64.774559,-821.919006,-0.000961,0.004438,0.112722,288.131622,14.678125,1.127217,-821.919006,294.500488,0.000000
126.080009,64.752602,-822.052429,-0.000957,0.004438,0.112722,288.033966,14.673149,1.127217,-822.052429,294.500488,0.000000
126.470009,64.763023,-822.007996,-0.000966,0.004446,0.112922,288.080322,14.675510,1.129216,-822.007996,294.500488,0.000000
126.860008,65.774010,-822.007996,-0.000970,0.004449,0.112999,292.577393,14.904604,1.129988,-822.007996,294.500488,0.000000
127.250008,65.809395,-822.052429,-0.000961,0.004449,0.112999,292.734802,14.912622,1.129988,-822.052429,294.500488,0.000000
127.640007,65.796730,-821.963501,-0.000970,0.004449,0.112999,292.678467,14.909752,1.129988,-821.963501,294.500488,0.000000
128.029999,65.793373,-822.141418,-0.000966,0.004449,0.112999,292.663544,14.908991,1.129988,-822.141418,294.500488,0.000000
128.420013,65.801949,-822.052429,-0.000966,0.004449,0.112999,292.701691,14.910934,1.129988,-822.052429,294.500488,0.000000
128.810013,65.790764,-822.141418,-0.000961,0.004449,0.112999,292.651947,14.908401,1.129988,-822.141418,294.500488,0.000000
129.200012,65.801567,-822.052429,-0.000953,0.004449,0.112999,292.699982,14.910849,1.129988,-822.052429,294.500488,0.000000
129.590012,65.779228,-822.052429,-0.000949,0.004449,0.112999,292.600616,14.905787,1.129988,-822.052429,294.500488,0.000000
129.980011,65.769539,-822.096924,-0.000961,0.004449,0.112999,292.557526,14.903590,1.129988,-822.096924,294.500488,0.000000
130.370010,65.785561,-822.096924,-0.000961,0.004449,0.112999,292.628784,14.907221,1.129988,-822.096924,294.500488,0.000000
130.760010,65.809013,-822.185913,-0.000966,0.004449,0.112999,292.733124,14.912536,1.129988,-822.185913,294.500488,0.000000
131.150009,65.772896,-822.141418,-0.000949,0.004449,0.112999,292.572449,14.904351,1.129988,-822.141418,294.500488,0.000000
131.540009,65.797478,-822.141418,-0.000957,0.004449,0.112999,292.681793,14.909922,1.129988,-822.141418,294.500488,0.000000
131.930008,65.767311,-822.185913,-0.000974,0.004449,0.112999,292.547607,14.903086,1.129988,-822.185913,294.500488,0.000000
132.320007,65.763588,-822.141418,-0.000970,0.004449,0.112999,292.531036,14.902242,1.129988,-822.141418,294.500488,0.000000
132.710007,65.766563,-822.185913,-0.000970,0.004449,0.112999,292.544281,14.902917,1.129988,-822.185913,294.500488,0.000000
133.100006,65.684639,-822.141418,-0.000957,0.004449,0.112999,292.179871,14.884353,1.129988,-822.141418,294.500488,0.000000
133.490005,65.677574,-822.141418,-0.000961,0.004449,0.112999,292.148437,14.882751,1.129988,-822.141418,294.500488,0.000000
133.880005,65.631020,-822.185913,-0.000961,0.004449,0.112999,291.941345,14.872202,1.129988,-822.185913,294.500488,0.000000
134.270004,65.610176,-822.096924,-0.000957,0.004449,0.112999,291.848633,14.867478,1.129988,-822.096924,294.500488,0.000000
134.660004,65.604958,-822.274841,-0.000966,0.004449,0.112999,291.825439,14.866296,1.129988,-822.274841,294.500488,0.000000
135.050003,65.601601,-822.185913,-0.000957,0.004449,0.112999,291.810486,14.865536,1.129988,-822.185913,294.500488,0.000000
135.440002,65.593040,-822.274841,-0.000966,0.004449,0.112999,291.772430,14.863595,1.129988,-822.274841,294.500488,0.000000
135.830002,65.588951,-822.274841,-0.000966,0.004449,0.112999,291.754211,14.862668,1.129988,-822.274841,294.500488,0.000000
136.220001,65.585960,-822.185913,-0.000961,0.004449,0.112999,291.740936,14.861991,1.129988,-822.185913,294.500488,0.000000
136.610001,65.571068,-822.319336,-0.000957,0.004449,0.112999,291.674683,14.858616,1.129988,-822.319336,294.500488,0.000000
137.000000,65.560646,-822.230408,-0.000944,0.004449,0.112999,291.628326,14.856255,1.129988,-822.230408,294.500488,0.000000
137.389999,65.544258,-822.230408,-0.000957,0.004449,0.112999,291.555420,14.852542,1.129988,-822.230408,294.500488,0.000000
137.780014,65.532722,-822.230408,-0.000949,0.004449,0.112999,291.504120,14.849927,1.129988,-822.230408,294.500488,0.000000
138.170013,65.522667,-822.230408,-0.000957,0.004449,0.112999,291.459381,14.847648,1.129988,-822.230408,294.500488,0.000000
138.560013,65.511864,-822.319336,-0.000961,0.004449,0.112999,291.411316,14.845201,1.129988,-822.319336,294.500488,0.000000
138.950012,65.496971,-822.274841,-0.000966,0.004449,0.112999,291.345093,14.841826,1.129988,-822.274841,294.500488,0.000000
139.340012,65.491753,-822.274841,-0.000966,0.004449,0.112999,291.321869,14.840643,1.129988,-822.274841,294.500488,0.000000
139.730011,65.471642,-822.319336,-0.000949,0.004449,0.112999,291.232422,14.836086,1.129988,-822.319336,294.500488,0.000000
140.120010,65.438881,-822.274841,-0.000961,0.004449,0.112999,291.086670,14.828663,1.129988,-822.274841,1681.640991,0.000000
140.510010,65.444466,-822.363831,-0.000966,0.004442,0.112834,291.111511,14.829928,1.128338,-822.363831,0.112722,0.000000
140.900009,65.378548,-822.363831,-0.000944,0.004427,0.112436,290.818298,14.814991,1.124356,-822.363831,0.112071,0.000000
141.290009,65.307060,-822.319336,-0.000957,0.004405,0.111898,290.500305,14.798792,1.118981,-822.319336,0.111421,0.000000
141.680008,65.259773,-822.319336,-0.000936,0.004383,0.111317,290.289978,14.788075,1.113168,-822.319336,0.110770,0.000000
142.070007,65.284721,-822.319336,-0.000949,0.004356,0.110649,290.400940,14.793730,1.106491,-822.319336,0.110119,0.000000
142.460007,65.260887,-822.363831,-0.000953,0.004332,0.110042,290.294922,14.788328,1.100420,-822.363831,0.109470,0.000000
142.850006,65.250832,-822.319336,-0.000949,0.004307,0.109409,290.250183,14.786049,1.094092,-822.319336,0.108819,0.000000
143.240005,65.194969,-822.319336,-0.000953,0.004280,0.108707,290.001709,14.773392,1.087067,-822.319336,0.108169,0.000000
143.630005,65.124229,-822.319336,-0.000957,0.004254,0.108047,289.687042,14.757361,1.080466,-822.319336,0.107518,0.000000
144.020004,65.149178,-822.363831,-0.000953,0.004236,0.107597,289.798004,14.763015,1.075970,-822.363831,0.106867,0.000000
144.410004,64.936180,-822.408325,-0.000949,0.004209,0.106911,288.850555,14.714748,1.069112,-822.408325,0.106218,0.000000
144.800003,64.233131,-822.408325,-0.000940,0.004183,0.106260,285.723236,14.555436,1.062602,-822.408325,0.105567,0.000000
145.190002,63.309654,-822.452759,-0.000957,0.004161,0.105680,281.615417,14.346173,1.056803,-822.452759,0.104917,0.000000
145.580002,62.299034,-822.452759,-0.000957,0.004139,0.105141,277.119934,14.117163,1.051414,-822.452759,0.104266,0.000000
145.970001,60.753319,-822.408325,-0.000953,0.004113,0.104466,270.244263,13.766898,1.044661,-822.408325,0.103615,0.000000
146.360001,59.013222,-822.452759,-0.000936,0.004091,0.103901,262.503906,13.372587,1.039014,-822.452759,0.102966,0.000000
146.750000,57.223595,-822.452759,-0.000940,0.004069,0.103355,254.543259,12.967052,1.033549,-822.452759,0.102324,0.000000
147.139999,54.810249,-822.497253,-0.000961,0.004041,0.102652,243.808167,12.420179,1.026524,-822.497253,0.101673,0.000000
147.530014,52.695549,-822.408325,-0.000936,0.004017,0.102038,234.401505,11.940982,1.020377,-822.408325,0.101023,0.000000
147.920013,50.029732,-822.408325,-0.000949,0.003994,0.101447,222.543365,11.336899,1.014473,-822.408325,0.100372,0.000000
148.310013,47.028038,-822.497253,-0.000940,0.003968,0.100780,209.191162,10.656705,1.007796,-822.497253,0.099721,0.000000
148.700012,44.548409,-822.452759,-0.000957,0.003941,0.100112,198.161224,10.094813,1.001120,-822.452759,0.099072,0.000000
149.090012,41.482666,-822.497253,-0.000953,0.003918,0.099514,184.524109,9.400107,0.995140,-822.497253,0.098421,0.000000
149.480011,38.122375,-822.497253,-0.000957,0.003885,0.098672,169.576797,8.638654,0.986722,-822.497253,0.097770,0.000000
149.870010,36.020340,-822.452759,-0.000970,0.003868,0.098239,160.226471,8.162326,0.982392,-822.452759,0.097120,0.000000
150.260010,33.658379,-822.497253,-0.000966,0.003841,0.097553,149.719940,7.627098,0.975534,-822.497253,0.096469,0.000000
150.650009,30.714027,-822.452759,-0.000966,0.003817,0.096964,136.622818,6.959898,0.969645,-822.452759,0.095820,0.000000
151.040009,27.993103,-822.586243,-0.000970,0.003793,0.096332,124.519539,6.343328,0.963316,-822.586243,0.095169,0.000000
151.430008,24.738197,-822.497253,-0.000979,0.003763,0.095585,110.041000,5.605756,0.955853,-822.497253,0.094518,0.000000
151.820007,21.934975,-822.586243,-0.000983,0.003740,0.094995,97.571640,4.970536,0.949948,-822.586243,0.093868,0.000000
152.210007,18.993233,-822.541748,-0.000979,0.003711,0.094259,84.486122,4.303928,0.942590,-822.541748,0.093217,0.000000
152.600006,16.147934,-822.497253,-0.001005,0.003689,0.093694,71.829597,3.659174,0.936943,-822.497253,0.092568,0.000000
152.990005,13.653786,-822.630737,-0.001000,0.003666,0.093113,60.735073,3.093992,0.931130,-822.630737,0.091917,0.000000
153.380005,10.461060,-822.541748,-0.001018,0.003634,0.092315,46.533115,2.370510,0.923151,-822.541748,0.091266,0.000000
153.770004,7.727852,-822.586243,-0.001035,0.003611,0.091708,34.375202,1.751156,0.917080,-822.586243,0.090616,0.000000
154.160004,4.604019,-822.586243,-0.001026,0.003583,0.091006,20.479700,1.043286,0.910055,-822.586243,0.089965,0.000000
154.550003,2.733215,-822.586243,-0.001013,0.003561,0.090442,12.157949,0.619355,0.904423,-822.586243,0.089314,0.000000
154.940002,0.176880,-822.630737,-0.001022,0.003541,0.089931,0.786801,0.040082,0.899306,-822.630737,0.088665,0.000000
155.330002,-2.369030,-822.586243,-0.001048,0.003507,0.089090,-10.537971,-0.536830,0.890904,-822.586243,0.088014,0.000000
155.720001,-0.106125,-822.675171,-0.001108,0.003486,0.088535,-0.472067,-0.024048,0.885347,-822.675171,0.087372,0.000000
156.110001,-0.015266,-822.586243,-0.001095,0.003461,0.087919,-0.067908,-0.003459,0.879186,-822.586243,0.086723,0.000000
156.500000,-0.016754,-822.586243,-0.001143,0.003433,0.087190,-0.074526,-0.003797,0.871904,-822.586243,0.086072,0.000000
156.890015,-0.030159,-822.675171,-0.001173,0.003402,0.086411,-0.134154,-0.006834,0.864107,-822.675171,0.085422,0.000000
157.280014,-0.032768,-822.630737,-0.001190,0.003375,0.085725,-0.145760,-0.007425,0.857248,-822.630737,0.084771,0.000000
157.670013,-0.058456,-822.630737,-0.001216,0.003352,0.085143,-0.260027,-0.013246,0.851435,-822.630737,0.084120,0.000000
158.060013,0.002609,-822.586243,-0.001212,0.003332,0.084632,0.011607,0.000591,0.846318,-822.586243,0.083471,0.000000
158.450012,-0.035744,-822.630737,-0.001268,0.003302,0.083869,-0.158996,-0.008100,0.838687,-822.630737,0.082820,0.000000
158.840012,-0.070374,-822.630737,-0.001276,0.003276,0.083210,-0.313037,-0.015947,0.832102,-822.630737,0.082169,0.000000
159.230011,0.012291,-822.675171,-0.001302,0.003251,0.082585,0.054673,0.002785,0.825849,-822.675171,0.082438,0.000000
159.400009,0.026443,-822.675171,-0.001315,0.003252,0.082603,0.117626,0.005992,0.826031,-822.675171,0.082438,0.000000