File: Data/compression 35/ManualNoHeating-10-35-reverse-1-2_11182024_163912.csv
Time (sec),S:Load (lbs),S:HL1 (DIM),S:LVDT (in),S:Position (in),Ch:Position (mm),Ch:Load (N),Ch:Stress (MPa),Ch:Strain (mm/mm),Ch:HL1 (DIM),Set Point (),Cycles ()
0.110000,-0.004089,-795.719727,-0.012559,-0.007742,-0.196653,-0.018190,-0.000927,-1.966525,-795.719727,-0.196383,0.000000
0.500000,0.017136,-795.630798,-0.012564,-0.007686,-0.195222,0.076223,0.003883,-1.952219,-795.630798,-0.194492,0.000000
0.890000,0.002983,-795.719727,-0.012426,-0.007452,-0.189290,0.013269,0.000676,-1.892902,-795.719727,-0.187988,0.000000
1.280000,-0.026062,-795.719727,-0.012150,-0.007194,-0.182724,-0.115930,-0.005906,-1.827241,-795.719727,-0.181502,0.000000
1.670000,0.008942,-795.719727,-0.011908,-0.006942,-0.176316,0.039774,0.002026,-1.763155,-795.719727,-0.174997,0.000000
2.060000,0.004097,-795.675232,-0.011637,-0.006683,-0.169760,0.018224,0.000928,-1.697601,-795.675232,-0.168511,0.000000
2.450000,0.023087,-795.675232,-0.011374,-0.006428,-0.163282,0.102694,0.005231,-1.632819,-795.675232,-0.162007,0.000000
2.840000,0.005592,-795.764221,-0.011098,-0.006173,-0.156785,0.024876,0.001267,-1.567855,-795.764221,-0.155502,0.000000
3.230000,-0.011543,-795.675232,-0.010865,-0.005917,-0.150282,-0.051347,-0.002616,-1.502815,-795.675232,-0.149016,0.000000
3.620000,-0.023827,-795.719727,-0.010580,-0.005661,-0.143778,-0.105986,-0.005399,-1.437776,-795.719727,-0.142512,0.000000
4.010000,0.004471,-795.764221,-0.010330,-0.005405,-0.137299,0.019887,0.001013,-1.372993,-795.764221,-0.136025,0.000000
4.400000,0.026070,-795.764221,-0.010054,-0.005149,-0.130777,0.115964,0.005907,-1.307772,-795.764221,-0.129521,0.000000
4.790000,0.024956,-795.764221,-0.009813,-0.004899,-0.124429,0.111009,0.005655,-1.244292,-795.764221,-0.123017,0.000000
5.180000,-0.000366,-795.808716,-0.009528,-0.004639,-0.117821,-0.001629,-0.000083,-1.178208,-795.808716,-0.116529,0.000000
5.570000,-0.027924,-795.808716,-0.009270,-0.004380,-0.111256,-0.124210,-0.006328,-1.112562,-795.808716,-0.110025,0.000000
5.960001,-0.034256,-795.808716,-0.008994,-0.004123,-0.104736,-0.152378,-0.007763,-1.047356,-795.808716,-0.103538,0.000000
6.350000,0.014526,-795.808716,-0.008761,-0.003874,-0.098388,0.064617,0.003292,-0.983876,-795.808716,-0.097034,0.000000
6.740000,0.042084,-795.853149,-0.008489,-0.003619,-0.091926,0.187198,0.009536,-0.919260,-795.853149,-0.090530,0.000000
7.130000,0.009315,-795.764221,-0.008231,-0.003364,-0.085439,0.041437,0.002111,-0.854387,-795.764221,-0.084043,0.000000
7.520000,-0.008186,-795.764221,-0.007950,-0.003106,-0.078900,-0.036415,-0.001855,-0.788999,-795.764221,-0.077539,0.000000
7.910000,-0.027184,-795.853149,-0.007696,-0.002851,-0.072414,-0.120918,-0.006160,-0.724141,-795.853149,-0.071052,0.000000
8.300000,0.007820,-795.808716,-0.007442,-0.002600,-0.066048,0.034786,0.001772,-0.660479,-795.808716,-0.064548,0.000000
8.690001,0.040962,-795.897644,-0.007170,-0.002333,-0.059249,0.182209,0.009282,-0.592487,-795.897644,-0.058044,0.000000
9.080001,0.040962,-795.853149,-0.006885,-0.002087,-0.053005,0.182209,0.009282,-0.530052,-795.853149,-0.051556,0.000000
9.470000,0.004845,-795.853149,-0.006648,-0.001832,-0.046527,0.021550,0.001098,-0.465270,-795.853149,-0.045052,0.000000
9.860001,-0.009682,-795.897644,-0.006377,-0.001570,-0.039875,-0.043066,-0.002194,-0.398746,-795.897644,-0.038565,0.000000
10.250001,-0.005211,-795.808716,-0.006118,-0.001312,-0.033319,-0.023179,-0.001181,-0.333192,-795.808716,-0.032061,0.000000
10.640000,0.018997,-795.897644,-0.005851,-0.001061,-0.026945,0.084504,0.004305,-0.269454,-795.897644,-0.025557,0.000000
11.030001,0.053627,-795.942139,-0.005588,-0.000813,-0.020649,0.238545,0.012152,-0.206489,-795.942139,-0.019070,0.000000
11.420000,0.023460,-795.897644,-0.005329,-0.000549,-0.013954,0.104357,0.005316,-0.139542,-795.897644,-0.012566,0.000000
11.810000,0.028679,-795.986633,-0.005062,-0.000292,-0.007423,0.127570,0.006499,-0.074229,-795.986633,-0.006080,0.000000
12.200001,0.091606,-795.897644,-0.004971,-0.000000,-0.000000,0.407484,0.020758,-0.000000,-795.897644,0.000216,0.000000
12.590000,0.099426,-795.897644,-0.004967,-0.000000,-0.000000,0.442270,0.022530,-0.000000,-795.897644,0.000416,0.000000
12.980000,0.086021,-795.942139,-0.004958,0.000002,0.000051,0.382642,0.019493,0.000515,-795.942139,0.001066,0.000000
13.370001,0.097191,-795.942139,-0.004941,0.000028,0.000702,0.432327,0.022024,0.007025,-795.942139,0.001717,0.000000
13.760000,0.122887,-795.942139,-0.004911,0.000051,0.001284,0.546627,0.027847,0.012838,-795.942139,0.002368,0.000000
14.150001,0.129959,-795.942139,-0.004885,0.000075,0.001899,0.578087,0.029449,0.018985,-795.942139,0.003017,0.000000
14.540001,0.148582,-795.986633,-0.004872,0.000090,0.002289,0.660928,0.033669,0.022891,-795.986633,0.003668,0.000000
14.930000,0.304230,-795.986633,-0.004825,0.000131,0.003338,1.353281,0.068939,0.033383,-795.986633,0.004318,0.000000
15.320001,0.296783,-795.986633,-0.004816,0.000153,0.003894,1.320159,0.067252,0.038939,-795.986633,0.004969,0.000000
15.710001,0.333649,-796.031128,-0.004794,0.000180,0.004562,1.484143,0.075606,0.045616,-796.031128,0.005620,0.000000
16.100000,0.325081,-796.075562,-0.004764,0.000196,0.004969,1.446032,0.073664,0.049688,-796.075562,0.006262,0.000000
16.490002,0.386902,-795.986633,-0.004764,0.000213,0.005402,1.721025,0.087673,0.054018,-795.986633,0.006911,0.000000
16.880001,0.591705,-796.031128,-0.004717,0.000247,0.006262,2.632037,0.134082,0.062617,-796.031128,0.007562,0.000000
17.270000,0.720543,-796.031128,-0.004682,0.000287,0.007284,3.205135,0.163277,0.072837,-796.031128,0.008212,0.000000
17.660002,0.747726,-796.075562,-0.004669,0.000301,0.007639,3.326053,0.169437,0.076394,-796.075562,0.008863,0.000000
18.050001,0.836723,-796.031128,-0.004622,0.000327,0.008316,3.721931,0.189604,0.083162,-796.031128,0.009514,0.000000
18.440001,0.965569,-796.075562,-0.004605,0.000350,0.008879,4.295063,0.218801,0.088794,-796.075562,0.010163,0.000000
18.830002,1.270538,-796.075562,-0.004570,0.000384,0.009765,5.651637,0.287908,0.097650,-796.075562,0.010814,0.000000
19.220001,1.332726,-796.031128,-0.004566,0.000403,0.010242,5.928259,0.302000,0.102419,-796.031128,0.011464,0.000000
19.610001,1.515190,-796.164551,-0.004531,0.000428,0.010866,6.739902,0.343347,0.108657,-796.164551,0.012115,0.000000
20.000000,1.598228,-796.075562,-0.004501,0.000448,0.011377,7.109275,0.362164,0.113774,-796.075562,0.012766,0.000000
20.390001,1.956078,-796.075562,-0.004471,0.000485,0.012315,8.701068,0.443254,0.123145,-796.075562,0.013415,0.000000
20.780001,2.121407,-796.164551,-0.004441,0.000512,0.012999,9.436487,0.480718,0.129988,-796.164551,0.014066,0.000000
21.170000,2.248390,-796.075562,-0.004411,0.000530,0.013459,10.001339,0.509493,0.134591,-796.075562,0.014717,0.000000
21.560001,2.576447,-796.164551,-0.004398,0.000559,0.014205,11.460607,0.583831,0.142055,-796.164551,0.015367,0.000000
21.950001,2.678108,-796.209045,-0.004359,0.000581,0.014769,11.912820,0.606868,0.147687,-796.209045,0.016018,0.000000
22.340000,2.828918,-796.164551,-0.004337,0.000602,0.015280,12.583658,0.641042,0.152804,-796.164551,0.016667,0.000000
22.730001,3.326408,-796.209045,-0.004307,0.000641,0.016269,14.796603,0.753775,0.162690,-796.209045,0.017318,0.000000
23.120001,3.375557,-796.209045,-0.004260,0.000663,0.016832,15.015227,0.764912,0.168322,-796.209045,0.017969,0.000000
23.510000,3.629890,-796.209045,-0.004243,0.000696,0.017691,16.146559,0.822545,0.176906,-796.209045,0.018619,0.000000
23.900002,3.829857,-796.253479,-0.004195,0.000723,0.018358,17.036055,0.867858,0.183583,-796.253479,0.019270,0.000000
24.290001,4.033913,-796.164551,-0.004182,0.000746,0.018958,17.943739,0.914098,0.189578,-796.164551,0.019919,0.000000
24.680000,4.154564,-796.253479,-0.004156,0.000770,0.019547,18.480423,0.941438,0.195467,-796.253479,0.020570,0.000000
25.070002,4.300529,-796.297974,-0.004117,0.000790,0.020077,19.129711,0.974514,0.200766,-796.297974,0.021212,0.000000
25.460001,4.457672,-796.297974,-0.004113,0.000811,0.020605,19.828716,1.010123,0.206050,-796.297974,0.021863,0.000000
25.850000,4.534012,-796.297974,-0.004044,0.000837,0.021264,20.168291,1.027422,0.212635,-796.297974,0.022513,0.000000
26.240002,4.686684,-796.209045,-0.004031,0.000863,0.021924,20.847410,1.062018,0.219236,-796.209045,0.023164,0.000000
26.630001,4.914948,-796.342468,-0.003997,0.000893,0.022678,21.862778,1.113743,0.226776,-796.342468,0.023813,0.000000
27.020000,4.863190,-796.253479,-0.003971,0.000912,0.023154,21.632547,1.102015,0.231545,-796.253479,0.024464,0.000000
27.410002,5.053101,-796.297974,-0.003949,0.000938,0.023831,22.477314,1.145049,0.238312,-796.297974,0.025115,0.000000
27.800001,5.154755,-796.297974,-0.003915,0.000964,0.024473,22.929493,1.168084,0.244731,-796.297974,0.025765,0.000000
28.190001,5.289185,-796.297974,-0.003872,0.000993,0.025227,23.527468,1.198546,0.252271,-796.297974,0.026416,0.000000
28.580002,5.455635,-796.297974,-0.003846,0.001021,0.025939,24.267878,1.236265,0.259386,-796.297974,0.027065,0.000000
28.970001,5.432549,-796.253479,-0.003803,0.001042,0.026476,24.165182,1.231033,0.264761,-796.253479,0.027716,0.000000
29.360001,5.575905,-796.342468,-0.003764,0.001072,0.027230,24.802864,1.263518,0.272300,-796.342468,0.028367,0.000000
29.750002,5.555054,-796.431458,-0.003717,0.001095,0.027820,24.710114,1.258793,0.278205,-796.431458,0.029017,0.000000
30.140001,5.706612,-796.386963,-0.003682,0.001118,0.028409,25.384275,1.293137,0.284094,-796.386963,0.029668,0.000000
30.530001,5.860397,-796.386963,-0.003673,0.001149,0.029191,26.068350,1.327985,0.291906,-796.386963,0.030319,0.000000
30.920002,5.837311,-796.342468,-0.003626,0.001173,0.029798,25.965654,1.322754,0.297977,-796.342468,0.030968,0.000000
31.310001,5.814972,-796.342468,-0.003591,0.001195,0.030352,25.866287,1.317691,0.303518,-796.342468,0.031619,0.000000
31.700001,5.881630,-796.431458,-0.003553,0.001222,0.031047,26.162796,1.332796,0.310467,-796.431458,0.032268,0.000000
32.090000,5.788902,-796.386963,-0.003540,0.001243,0.031575,25.750324,1.311784,0.315751,-796.386963,0.032920,0.000000
32.480003,6.037651,-796.386963,-0.003479,0.001277,0.032434,26.856813,1.368151,0.324335,-796.386963,0.033571,0.000000
32.870003,5.874176,-796.431458,-0.003454,0.001300,0.033015,26.129641,1.331107,0.330149,-796.431458,0.034220,0.000000
33.260002,6.005997,-796.386963,-0.003415,0.001326,0.033683,26.716007,1.360978,0.336825,-796.386963,0.034871,0.000000
33.650002,6.099838,-796.475891,-0.003380,0.001358,0.034489,27.133436,1.382243,0.344895,-796.475891,0.035520,0.000000
34.040001,5.928917,-796.386963,-0.003354,0.001375,0.034922,26.373140,1.343512,0.349225,-796.386963,0.036162,0.000000
34.430000,6.161278,-796.475891,-0.003316,0.001408,0.035764,27.406733,1.396165,0.357642,-796.475891,0.036813,0.000000
34.820004,6.153084,-796.475891,-0.003255,0.001434,0.036432,27.370283,1.394309,0.364319,-796.475891,0.037464,0.000000
35.210003,6.024246,-796.431458,-0.003255,0.001453,0.036900,26.797186,1.365114,0.368997,-796.431458,0.038114,0.000000
35.600002,5.989243,-796.475891,-0.003203,0.001475,0.037464,26.641481,1.357182,0.374644,-796.475891,0.038765,0.000000
35.990002,6.435341,-796.475891,-0.003165,0.001510,0.038365,28.625826,1.458269,0.383652,-796.475891,0.039414,0.000000
36.380001,6.274483,-796.520386,-0.003143,0.001535,0.038981,27.910294,1.421818,0.389814,-796.520386,0.040065,0.000000
36.770000,6.125900,-796.475891,-0.003091,0.001554,0.039476,27.249365,1.388149,0.394765,-796.475891,0.040716,0.000000
37.160004,6.267403,-796.475891,-0.003065,0.001587,0.040308,27.878799,1.420214,0.403076,-796.475891,0.041366,0.000000
37.550003,6.097229,-796.564880,-0.003022,0.001601,0.040663,27.121830,1.381652,0.406634,-796.564880,0.042017,0.000000
37.940002,6.335922,-796.475891,-0.003014,0.001629,0.041384,28.183590,1.435740,0.413840,-796.475891,0.042668,0.000000
38.330002,6.553383,-796.520386,-0.002953,0.001662,0.042208,29.150904,1.485018,0.422076,-796.520386,0.043317,0.000000
38.720001,6.452103,-796.475891,-0.002902,0.001687,0.042859,28.700386,1.462067,0.428586,-796.475891,0.043968,0.000000
39.110001,6.354912,-796.520386,-0.002880,0.001714,0.043526,28.268059,1.440044,0.435263,-796.520386,0.044618,0.000000
39.500000,6.268524,-796.564880,-0.002850,0.001728,0.043881,27.883789,1.420468,0.438806,-796.564880,0.045269,0.000000
39.890003,6.712013,-796.609375,-0.002798,0.001760,0.044706,29.856525,1.520964,0.447057,-796.609375,0.045920,0.000000
40.280003,6.744415,-796.564880,-0.002772,0.001791,0.045494,30.000658,1.528306,0.454944,-796.564880,0.046569,0.000000
40.670002,6.535515,-796.609375,-0.002746,0.001809,0.045946,29.071423,1.480969,0.459456,-796.609375,0.047220,0.000000
41.060001,6.687813,-796.609375,-0.002699,0.001834,0.046588,29.748877,1.515480,0.465875,-796.609375,0.047870,0.000000
41.450001,6.748878,-796.653809,-0.002665,0.001859,0.047229,30.020512,1.529318,0.472294,-796.653809,0.048521,0.000000
41.840000,6.971191,-796.609375,-0.002617,0.001889,0.047983,31.009409,1.579695,0.479834,-796.609375,0.049172,0.000000
42.230003,6.953316,-796.653809,-0.002596,0.001921,0.048781,30.929893,1.575644,0.487812,-796.653809,0.049821,0.000000
42.620003,6.884422,-796.609375,-0.002557,0.001942,0.049328,30.623440,1.560032,0.493278,-796.609375,0.050472,0.000000
43.010002,7.001724,-796.698303,-0.002527,0.001970,0.050030,31.145226,1.586613,0.500303,-796.698303,0.051114,0.000000
43.400002,6.678505,-796.742798,-0.002496,0.001985,0.050421,29.707474,1.513371,0.504209,-796.742798,0.051764,0.000000
43.790001,7.063164,-796.653809,-0.002453,0.002014,0.051166,31.418522,1.600536,0.511657,-796.653809,0.052415,0.000000
44.180000,7.050133,-796.653809,-0.002427,0.002046,0.051973,31.360558,1.597583,0.519727,-796.653809,0.053066,0.000000
44.570004,6.834526,-796.742798,-0.002376,0.002070,0.052580,30.401491,1.548726,0.525798,-796.742798,0.053715,0.000000
44.960003,7.131310,-796.698303,-0.002341,0.002104,0.053429,31.721649,1.615978,0.534291,-796.698303,0.054366,0.000000
45.350002,7.139503,-796.742798,-0.002311,0.002128,0.054062,31.758097,1.617835,0.540619,-796.742798,0.055016,0.000000
45.740002,7.086624,-796.742798,-0.002259,0.002152,0.054661,31.522879,1.605852,0.546615,-796.742798,0.055667,0.000000
46.130001,7.170410,-796.787292,-0.002242,0.002175,0.055241,31.895576,1.624838,0.552413,-796.787292,0.056318,0.000000
46.520000,6.995392,-796.742798,-0.002212,0.002189,0.055606,31.117058,1.585178,0.556062,-796.742798,0.056967,0.000000
46.910004,7.313400,-796.742798,-0.002160,0.002222,0.056448,32.531628,1.657240,0.564479,-796.742798,0.057618,0.000000
47.300003,7.381912,-796.831787,-0.002134,0.002250,0.057141,32.836384,1.672765,0.571413,-796.831787,0.058269,0.000000
47.690002,7.521179,-796.742798,-0.002100,0.002278,0.057853,33.455875,1.704324,0.578529,-796.742798,0.058919,0.000000
48.080002,7.205414,-796.742798,-0.002061,0.002299,0.058398,32.051281,1.632770,0.583979,-796.742798,0.059570,0.000000
48.470001,7.475006,-796.831787,-0.002026,0.002325,0.059067,33.250488,1.693861,0.590671,-796.831787,0.060219,0.000000
48.860001,7.411705,-796.831787,-0.002005,0.002350,0.059691,32.968910,1.679516,0.596908,-796.831787,0.060870,0.000000
49.250004,7.436653,-796.920715,-0.001966,0.002373,0.060263,33.079884,1.685170,0.602631,-796.920715,0.061521,0.000000
49.640003,7.631401,-796.876221,-0.001919,0.002405,0.061079,33.946167,1.729300,0.610791,-796.876221,0.062171,0.000000
50.030003,7.459740,-796.831787,-0.001897,0.002427,0.061633,33.182579,1.690401,0.616332,-796.831787,0.062822,0.000000
50.420002,7.479477,-796.876221,-0.001850,0.002450,0.062240,33.270374,1.694874,0.622403,-796.876221,0.063471,0.000000
50.810001,7.435165,-796.787292,-0.001807,0.002479,0.062969,33.073269,1.684833,0.629685,-796.787292,0.064122,0.000000
51.200001,7.300362,-796.920715,-0.001776,0.002496,0.063411,32.473629,1.654286,0.634106,-796.920715,0.064773,0.000000
51.590004,7.820946,-796.920715,-0.001746,0.002531,0.064278,34.789303,1.772252,0.642781,-796.920715,0.065423,0.000000
51.980003,7.612411,-796.920715,-0.001707,0.002554,0.064859,33.861698,1.724997,0.648595,-796.920715,0.066065,0.000000
52.370003,7.557678,-796.920715,-0.001673,0.002575,0.065415,33.618233,1.712594,0.654151,-796.920715,0.066716,0.000000
52.760002,7.845894,-796.920715,-0.001647,0.002607,0.066230,34.900280,1.777905,0.662296,-796.920715,0.067365,0.000000
53.150002,7.975105,-797.009705,-0.001595,0.002635,0.066923,35.475040,1.807185,0.669230,-797.009705,0.068016,0.000000
53.540001,7.914032,-796.920715,-0.001582,0.002658,0.067504,35.203373,1.793345,0.675044,-796.920715,0.068667,0.000000
53.930004,7.908073,-796.965210,-0.001526,0.002685,0.068207,35.176868,1.791995,0.682068,-796.965210,0.069317,0.000000
54.320004,7.929306,-796.965210,-0.001487,0.002707,0.068753,35.271317,1.796806,0.687534,-796.965210,0.069968,0.000000
54.710003,8.008247,-797.009705,-0.001453,0.002734,0.069438,35.622463,1.814695,0.694377,-797.009705,0.070619,0.000000
55.100002,8.014572,-797.009705,-0.001427,0.002759,0.070089,35.650597,1.816128,0.700887,-797.009705,0.071268,0.000000
55.490002,8.348595,-797.009705,-0.001388,0.002789,0.070835,37.136402,1.891819,0.708351,-797.009705,0.071919,0.000000
55.880001,8.445412,-797.054138,-0.001354,0.002817,0.071563,37.567066,1.913758,0.715633,-797.054138,0.072569,0.000000
56.270004,8.274117,-797.009705,-0.001319,0.002836,0.072022,36.805107,1.874942,0.720220,-797.009705,0.073220,0.000000
56.660004,8.464775,-797.054138,-0.001302,0.002861,0.072682,37.653198,1.918145,0.726821,-797.054138,0.073871,0.000000
57.050003,8.561592,-797.054138,-0.001263,0.002884,0.073263,38.083862,1.940084,0.732635,-797.054138,0.074520,0.000000
57.440002,9.025940,-796.965210,-0.001229,0.002917,0.074104,40.149387,2.045307,0.741037,-796.965210,0.075171,0.000000
57.830002,8.934334,-797.098633,-0.001203,0.002941,0.074694,39.741901,2.024549,0.746941,-797.098633,0.075821,0.000000
58.220001,9.267235,-797.098633,-0.001155,0.002969,0.075404,41.222721,2.099985,0.754042,-797.098633,0.076472,0.000000
58.610004,9.213989,-797.098633,-0.001134,0.002991,0.075978,40.985870,2.087920,0.759780,-797.098633,0.077123,0.000000
59.000004,8.806610,-797.143127,-0.001112,0.003003,0.076281,39.173759,1.995606,0.762808,-797.143127,0.077772,0.000000
59.390003,9.940117,-797.054138,-0.001065,0.003041,0.077244,44.215847,2.252463,0.772436,-797.054138,0.078423,0.000000
59.780003,9.963943,-797.187622,-0.001048,0.003069,0.077955,44.321835,2.257862,0.779552,-797.187622,0.079074,0.000000
60.170002,9.922615,-797.098633,-0.001009,0.003096,0.078630,44.137997,2.248497,0.786304,-797.098633,0.079724,0.000000
60.560001,9.713341,-797.143127,-0.000983,0.003113,0.079065,43.207096,2.201074,0.790649,-797.143127,0.080375,0.000000
60.950005,9.794144,-797.143127,-0.000953,0.003133,0.079568,43.566528,2.219385,0.795676,-797.143127,0.081016,0.000000
61.340004,10.748161,-797.143127,-0.000927,0.003170,0.080512,47.810211,2.435568,0.805123,-797.143127,0.081666,0.000000
61.730003,10.787262,-797.232056,-0.000897,0.003197,0.081198,47.984138,2.444428,0.811981,-797.232056,0.082317,0.000000
62.120003,10.476700,-797.187622,-0.000849,0.003211,0.081563,46.602688,2.374054,0.815630,-797.187622,0.082966,0.000000
62.510002,11.135429,-797.187622,-0.000836,0.003242,0.082352,49.532864,2.523324,0.823517,-797.187622,0.083617,0.000000
62.900002,11.260918,-797.187622,-0.000811,0.003266,0.082966,50.091064,2.551760,0.829664,-797.187622,0.084268,0.000000
63.290005,11.817986,-797.187622,-0.000780,0.003298,0.083764,52.569027,2.677994,0.837643,-797.187622,0.084918,0.000000
63.680004,11.908844,-797.276550,-0.000746,0.003325,0.084467,52.973183,2.698583,0.844667,-797.276550,0.085569,0.000000
64.070000,11.861557,-797.187622,-0.000703,0.003347,0.085006,52.762840,2.687867,0.850057,-797.187622,0.086220,0.000000
64.460007,12.315102,-797.187622,-0.000686,0.003374,0.085690,54.780308,2.790642,0.856900,-797.187622,0.086869,0.000000
64.850006,12.465919,-797.276550,-0.000668,0.003394,0.086202,55.451180,2.824818,0.862017,-797.276550,0.087520,0.000000
65.240005,13.410995,-797.187622,-0.000647,0.003427,0.087051,59.655087,3.038975,0.870511,-797.187622,0.088170,0.000000
65.630005,13.869759,-797.276550,-0.000604,0.003459,0.087867,61.695766,3.142932,0.878671,-797.276550,0.088821,0.000000
66.020004,14.121483,-797.232056,-0.000569,0.003485,0.088526,62.815495,3.199974,0.885257,-797.232056,0.089472,0.000000
66.410004,14.045891,-797.232056,-0.000539,0.003509,0.089133,62.479244,3.182844,0.891328,-797.232056,0.090121,0.000000
66.800003,14.512474,-797.232056,-0.000496,0.003535,0.089800,64.554710,3.288574,0.898004,-797.232056,0.090772,0.000000
67.190002,14.912033,-797.276550,-0.000496,0.003558,0.090382,66.332039,3.379115,0.903818,-797.276550,0.091422,0.000000
67.580002,15.187958,-797.321045,-0.000474,0.003578,0.090893,67.559410,3.441640,0.908935,-797.321045,0.092073,0.000000
67.970001,15.183121,-797.232056,-0.000457,0.003597,0.091361,67.537895,3.440544,0.913613,-797.232056,0.092724,0.000000
68.360001,16.275284,-797.321045,-0.000423,0.003628,0.092152,72.396080,3.688032,0.921516,-797.321045,0.093373,0.000000
68.750000,17.011093,-797.321045,-0.000397,0.003659,0.092949,75.669121,3.854769,0.929495,-797.321045,0.094024,0.000000
69.140007,17.726051,-797.321045,-0.000384,0.003686,0.093617,78.849411,4.016781,0.936171,-797.321045,0.094675,0.000000
69.530006,17.813187,-797.321045,-0.000341,0.003705,0.094111,79.237015,4.036526,0.941107,-797.321045,0.095325,0.000000
69.920006,18.041824,-797.321045,-0.000332,0.003724,0.094588,80.254044,4.088336,0.945876,-797.321045,0.095967,0.000000
70.310005,18.839447,-797.321045,-0.000306,0.003752,0.095290,83.802048,4.269080,0.952900,-797.321045,0.096618,0.000000
70.700005,19.851555,-797.365540,-0.000276,0.003782,0.096062,88.304123,4.498427,0.960621,-797.365540,0.097267,0.000000
71.090004,20.837219,-797.365540,-0.000259,0.003814,0.096886,92.688583,4.721781,0.968857,-797.365540,0.097918,0.000000
71.480003,21.171982,-797.365540,-0.000229,0.003834,0.097381,94.177681,4.797639,0.973808,-797.365540,0.098569,0.000000
71.870003,22.313675,-797.365540,-0.000211,0.003864,0.098135,99.256180,5.056351,0.981348,-797.365540,0.099219,0.000000
72.260002,22.515877,-797.454468,-0.000190,0.003882,0.098612,100.155624,5.102171,0.986117,-797.454468,0.099870,0.000000
72.650002,22.340118,-797.365540,-0.000177,0.003894,0.098916,99.373810,5.062343,0.989160,-797.365540,0.100519,0.000000
73.040001,24.610100,-797.410034,-0.000151,0.003935,0.099947,109.471191,5.576728,0.999470,-797.410034,0.101170,0.000000
73.430000,25.840790,-797.454468,-0.000134,0.003965,0.100710,114.945572,5.855607,1.007100,-797.454468,0.101821,0.000000
73.820000,26.231781,-797.365540,-0.000121,0.003990,0.101335,116.684792,5.944207,1.013353,-797.365540,0.102471,0.000000
74.210007,27.029778,-797.454468,-0.000095,0.004009,0.101829,120.234459,6.125035,1.018288,-797.454468,0.103122,0.000000
74.600006,28.474953,-797.454468,-0.000086,0.004039,0.102601,126.662918,6.452517,1.026009,-797.454468,0.103771,0.000000
74.990005,30.041893,-797.454468,-0.000060,0.004068,0.103338,133.633011,6.807590,1.033382,-797.454468,0.104422,0.000000
75.380005,30.938568,-797.498962,-0.000052,0.004091,0.103911,137.621628,7.010780,1.039105,-797.498962,0.105073,0.000000
75.770004,31.567505,-797.410034,-0.000030,0.004112,0.104448,140.419281,7.153299,1.044480,-797.410034,0.105723,0.000000
76.160004,33.183601,-797.543457,-0.000026,0.004142,0.105203,147.608032,7.519512,1.052034,-797.543457,0.106374,0.000000
76.550003,34.146927,-797.543457,-0.000004,0.004164,0.105776,151.893112,7.737804,1.057757,-797.543457,0.107025,0.000000
76.940002,36.037468,-797.498962,0.000013,0.004197,0.106608,160.302658,8.166207,1.066084,-797.498962,0.107674,0.000000
77.330002,37.256989,-797.543457,0.000026,0.004223,0.107267,165.727356,8.442554,1.072670,-797.543457,0.108325,0.000000
77.720001,38.418411,-797.498962,0.000047,0.004245,0.107830,170.893631,8.705736,1.078301,-797.498962,0.108975,0.000000
78.110001,39.624901,-797.587952,0.000073,0.004270,0.108463,176.260361,8.979131,1.084630,-797.587952,0.109626,0.000000
78.500000,40.361458,-797.498962,0.000082,0.004289,0.108949,179.536728,9.146037,1.089490,-797.498962,0.110277,0.000000
78.890007,43.246597,-797.543457,0.000091,0.004326,0.109886,192.370468,9.799819,1.098861,-797.543457,0.110926,0.000000
79.280006,44.323128,-797.543457,0.000108,0.004349,0.110467,197.159119,10.043764,1.104675,-797.543457,0.111568,0.000000
79.670006,46.052795,-797.543457,0.000112,0.004376,0.111143,204.853058,10.435712,1.111427,-797.543457,0.112219,0.000000
80.060005,46.917442,-797.632385,0.000108,0.004391,0.111524,208.699203,10.631644,1.115242,-797.632385,0.112869,0.000000
80.450005,47.721024,-797.498962,0.000134,0.004408,0.111968,212.273712,10.813738,1.119678,-797.498962,0.113520,0.000000
80.840004,50.673569,-797.543457,0.000147,0.004446,0.112938,225.407288,11.482795,1.129382,-797.543457,0.114171,0.000000
81.230003,53.260437,-797.587952,0.000164,0.004480,0.113789,236.914261,12.068988,1.137891,-797.587952,0.114820,0.000000
81.620003,54.334358,-797.587952,0.000172,0.004497,0.114222,241.691299,12.312342,1.142221,-797.587952,0.115471,0.000000
82.010002,55.918800,-797.587952,0.000168,0.004524,0.114915,248.739243,12.671381,1.149155,-797.587952,0.116121,0.000000
82.400002,56.452042,-797.587952,0.000185,0.004540,0.115315,251.111221,12.792215,1.153152,-797.587952,0.116772,0.000000
82.790001,60.550743,-797.632385,0.000185,0.004580,0.116339,269.343170,13.720995,1.163386,-797.632385,0.117423,0.000000
83.180000,61.923309,-797.676880,0.000211,0.004598,0.116797,275.448639,14.032022,1.167973,-797.676880,0.118072,0.000000
83.570007,62.922760,-797.676880,0.000224,0.004621,0.117362,279.894409,14.258501,1.173620,-797.676880,0.118723,0.000000
83.960007,65.252312,-797.721375,0.000216,0.004644,0.117960,290.256775,14.786386,1.179600,-797.721375,0.119373,0.000000
84.350006,65.835823,-797.632385,0.000241,0.004644,0.117969,292.852356,14.918611,1.179691,-797.632385,0.020705,0.000000
84.740005,65.029640,-797.676880,0.000246,0.004645,0.117977,289.266296,14.735928,1.179767,-797.676880,294.500488,0.000000
85.130005,65.013252,-797.721375,0.000254,0.004655,0.118246,289.193390,14.732214,1.182462,-797.721375,294.500488,0.000000
85.520004,64.952187,-797.676880,0.000254,0.004660,0.118376,288.921753,14.718376,1.183764,-797.676880,294.500488,0.000000
85.910004,64.836006,-797.721375,0.000259,0.004660,0.118376,288.404968,14.692049,1.183764,-797.721375,294.500488,0.000000
86.300003,64.962608,-797.721375,0.000246,0.004665,0.118479,288.968109,14.720737,1.184793,-797.721375,294.500488,0.000000
86.690002,64.758919,-797.765869,0.000241,0.004665,0.118479,288.062073,14.674582,1.184793,-797.765869,294.500488,0.000000
87.080002,65.931160,-797.765869,0.000250,0.004677,0.118793,293.276459,14.940214,1.187927,-797.765869,294.500488,0.000000
87.470001,65.755028,-797.721375,0.000254,0.004676,0.118775,292.492981,14.900302,1.187745,-797.721375,294.500488,0.000000
87.860001,65.523033,-797.765869,0.000254,0.004677,0.118784,291.460999,14.847732,1.187836,-797.765869,294.500488,0.000000
88.250008,65.328285,-797.765869,0.000263,0.004677,0.118784,290.594727,14.803600,1.187836,-797.765869,294.500488,0.000000
88.640007,65.191994,-797.810364,0.000276,0.004677,0.118784,289.988464,14.772717,1.187836,-797.810364,294.500488,0.000000
89.030006,65.028145,-797.810364,0.000259,0.004677,0.118784,289.259644,14.735588,1.187836,-797.810364,294.500488,0.000000
89.420006,64.895958,-797.765869,0.000259,0.004677,0.118784,288.671631,14.705635,1.187836,-797.765869,294.500488,0.000000
89.810005,64.765999,-797.854797,0.000280,0.004677,0.118784,288.093536,14.676186,1.187836,-797.854797,294.500488,0.000000
90.200005,64.640877,-797.810364,0.000276,0.004677,0.118784,287.536987,14.647833,1.187836,-797.810364,294.500488,0.000000
90.590004,64.510551,-797.854797,0.000272,0.004677,0.118793,286.957275,14.618300,1.187927,-797.854797,294.500488,0.000000
90.980003,66.130379,-797.854797,0.000276,0.004686,0.119026,294.162628,14.985357,1.190259,-797.854797,294.500488,0.000000
91.370003,66.007484,-797.854797,0.000272,0.004686,0.119018,293.615967,14.957510,1.190183,-797.854797,294.500488,0.000000
91.760002,65.852577,-797.854797,0.000276,0.004686,0.119018,292.926880,14.922407,1.190183,-797.854797,294.500488,0.000000
92.150002,65.787041,-797.854797,0.000293,0.004686,0.119018,292.635376,14.907557,1.190183,-797.854797,294.500488,0.000000
92.540001,65.656715,-797.899292,0.000267,0.004686,0.119018,292.055664,14.878025,1.190183,-797.899292,294.500488,0.000000
92.930008,65.568459,-797.854797,0.000289,0.004686,0.119018,291.663055,14.858025,1.190183,-797.854797,294.500488,0.000000
93.320007,65.491386,-797.854797,0.000272,0.004686,0.119018,291.320251,14.840561,1.190183,-797.854797,294.500488,0.000000
93.710007,65.390099,-797.943787,0.000276,0.004686,0.119018,290.869690,14.817608,1.190183,-797.943787,294.500488,0.000000
94.100006,65.320457,-797.854797,0.000276,0.004686,0.119018,290.559906,14.801826,1.190183,-797.854797,294.500488,0.000000
94.490005,65.240410,-797.943787,0.000276,0.004686,0.119018,290.203827,14.783688,1.190183,-797.943787,294.500488,0.000000
94.880005,65.186043,-797.899292,0.000285,0.004686,0.119026,289.962006,14.771369,1.190259,-797.899292,294.500488,0.000000
95.270004,65.079170,-797.854797,0.000267,0.004686,0.119026,289.486603,14.747151,1.190259,-797.854797,294.500488,0.000000
95.660004,65.023689,-797.943787,0.000280,0.004686,0.119026,289.239807,14.734578,1.190259,-797.943787,294.500488,0.000000
96.050003,64.966331,-797.899292,0.000276,0.004686,0.119035,288.984680,14.721581,1.190349,-797.899292,294.500488,0.000000
96.440002,64.919411,-797.943787,0.000289,0.004686,0.119035,288.775970,14.710948,1.190349,-797.943787,294.500488,0.000000
96.830002,64.840843,-797.943787,0.000293,0.004686,0.119035,288.426483,14.693146,1.190349,-797.943787,294.500488,0.000000
97.220001,64.792442,-797.988281,0.000280,0.004686,0.119035,288.211182,14.682177,1.190349,-797.988281,294.500488,0.000000
97.610008,64.732109,-797.988281,0.000285,0.004686,0.119035,287.942810,14.668506,1.190349,-797.988281,294.500488,0.000000
98.000008,64.682961,-797.943787,0.000289,0.004686,0.119035,287.724182,14.657369,1.190349,-797.943787,294.500488,0.000000
98.390007,64.612587,-798.032715,0.000280,0.004686,0.119035,287.411133,14.641421,1.190349,-798.032715,294.500488,0.000000
98.780006,65.558037,-797.988281,0.000267,0.004716,0.119798,291.616699,14.855663,1.197980,-797.988281,294.500488,0.000000
99.170006,66.442421,-797.988281,0.000280,0.004682,0.118914,295.550659,15.056067,1.189138,-797.988281,294.500488,0.000000
99.560005,66.398476,-798.032715,0.000293,0.004682,0.118914,295.355164,15.046110,1.189138,-798.032715,294.500488,0.000000
99.950005,66.341881,-798.032715,0.000289,0.004682,0.118914,295.103424,15.033285,1.189138,-798.032715,294.500488,0.000000
100.340004,66.282677,-798.077209,0.000285,0.004682,0.118914,294.840057,15.019869,1.189138,-798.077209,294.500488,0.000000
100.730003,66.228676,-798.032715,0.000302,0.004682,0.118914,294.599854,15.007632,1.189138,-798.032715,294.500488,0.000000
101.120003,66.184364,-798.032715,0.000285,0.004682,0.118914,294.402771,14.997591,1.189138,-798.032715,294.500488,0.000000
101.510002,66.151222,-798.032715,0.000289,0.004682,0.118914,294.255341,14.990082,1.189138,-798.032715,294.500488,0.000000
101.900002,66.101326,-798.077209,0.000297,0.004682,0.118914,294.033386,14.978774,1.189138,-798.077209,294.500488,0.000000
102.290009,66.065208,-798.121704,0.000297,0.004682,0.118914,293.872711,14.970590,1.189138,-798.121704,294.500488,0.000000
102.680008,66.010841,-798.077209,0.000297,0.004682,0.118914,293.630890,14.958270,1.189138,-798.077209,294.500488,0.000000
103.070007,65.988869,-798.077209,0.000293,0.004682,0.118914,293.533142,14.953291,1.189138,-798.077209,294.500488,0.000000
103.460007,65.898750,-798.077209,0.000293,0.004682,0.118914,293.132294,14.932870,1.189138,-798.077209,294.500488,0.000000
103.850006,65.866356,-798.032715,0.000289,0.004682,0.118914,292.988190,14.925529,1.189138,-798.032715,294.500488,0.000000
104.240005,65.865623,-798.166199,0.000289,0.004682,0.118914,292.984924,14.925364,1.189138,-798.166199,294.500488,0.000000
104.630005,65.831352,-798.121704,0.000302,0.004682,0.118914,292.832489,14.917598,1.189138,-798.121704,294.500488,0.000000
105.020004,65.824287,-798.121704,0.000280,0.004682,0.118914,292.801056,14.915997,1.189138,-798.121704,294.500488,0.000000
105.410004,65.776619,-798.166199,0.000306,0.004682,0.118914,292.589020,14.905194,1.189138,-798.166199,294.500488,0.000000
105.800003,65.744591,-798.121704,0.000297,0.004682,0.118914,292.446533,14.897937,1.189138,-798.121704,294.500488,0.000000
106.190002,65.660439,-798.166199,0.000297,0.004682,0.118914,292.072205,14.878868,1.189138,-798.166199,294.500488,0.000000
106.580002,65.642937,-798.121704,0.000310,0.004682,0.118914,291.994354,14.874902,1.189138,-798.121704,294.500488,0.000000
106.970009,65.602715,-798.210693,0.000285,0.004682,0.118914,291.815460,14.865788,1.189138,-798.210693,294.500488,0.000000
107.360008,65.572929,-798.255127,0.000302,0.004682,0.118914,291.682953,14.859038,1.189138,-798.255127,294.500488,0.000000
107.750008,65.558037,-798.210693,0.000297,0.004682,0.118914,291.616699,14.855663,1.189138,-798.210693,294.500488,0.000000
108.140007,65.540535,-798.210693,0.000302,0.004682,0.118914,291.538849,14.851697,1.189138,-798.210693,294.500488,0.000000
108.530006,65.517815,-798.166199,0.000293,0.004682,0.118914,291.437805,14.846549,1.189138,-798.166199,294.500488,0.000000
108.920006,65.497719,-798.255127,0.000276,0.004682,0.118923,291.348419,14.841995,1.189229,-798.255127,294.500488,0.000000
109.310005,65.470528,-798.255127,0.000285,0.004682,0.118923,291.227448,14.835834,1.189229,-798.255127,294.500488,0.000000
109.700005,65.414299,-798.255127,0.000297,0.004682,0.118923,290.977325,14.823092,1.189229,-798.255127,294.500488,0.000000
110.090004,65.378548,-798.255127,0.000297,0.004682,0.118923,290.818298,14.814991,1.189229,-798.255127,294.500488,0.000000
110.480003,65.354347,-798.255127,0.000302,0.004682,0.118923,290.710663,14.809507,1.189229,-798.255127,294.500488,0.000000
110.870003,65.326042,-798.255127,0.000297,0.004682,0.118923,290.584747,14.803092,1.189229,-798.255127,294.500488,0.000000
111.260002,65.303337,-798.299622,0.000297,0.004682,0.118923,290.483765,14.797948,1.189229,-798.299622,294.500488,0.000000
111.650002,65.289177,-798.255127,0.000280,0.004682,0.118923,290.420776,14.794740,1.189229,-798.255127,294.500488,0.000000
112.040009,65.275780,-798.344116,0.000306,0.004682,0.118923,290.361176,14.791703,1.189229,-798.344116,294.500488,0.000000
112.430008,65.269081,-798.344116,0.000297,0.004682,0.118930,290.331360,14.790185,1.189305,-798.344116,294.500488,0.000000
112.820007,65.237053,-798.388611,0.000293,0.004682,0.118930,290.188904,14.782928,1.189305,-798.388611,294.500488,0.000000
113.210007,65.217323,-798.299622,0.000293,0.004682,0.118930,290.101135,14.778457,1.189305,-798.299622,294.500488,0.000000
113.600006,65.221413,-798.299622,0.000302,0.004695,0.119244,290.119324,14.779383,1.192439,-798.299622,294.500488,0.000000
113.990005,65.204277,-798.388611,0.000297,0.004696,0.119270,290.043121,14.775500,1.192696,-798.388611,294.500488,0.000000
114.380005,65.175987,-798.344116,0.000302,0.004696,0.119270,289.917267,14.769090,1.192696,-798.344116,294.500488,0.000000
114.770004,65.154015,-798.344116,0.000285,0.004696,0.119277,289.819519,14.764111,1.192772,-798.344116,294.500488,0.000000
115.160004,65.223274,-798.299622,0.000306,0.004703,0.119451,290.127625,14.779805,1.194513,-798.299622,294.500488,0.000000
115.550003,65.245247,-798.433044,0.000302,0.004703,0.119451,290.225342,14.784784,1.194513,-798.433044,294.500488,0.000000
115.940002,65.235558,-798.388611,0.000302,0.004703,0.119451,290.182251,14.782589,1.194513,-798.388611,294.500488,0.000000
116.330002,65.221046,-798.388611,0.000289,0.004703,0.119451,290.117706,14.779301,1.194513,-798.388611,294.500488,0.000000
116.720009,65.201302,-798.433044,0.000280,0.004703,0.119451,290.029877,14.774826,1.194513,-798.433044,294.500488,0.000000
117.110008,65.187157,-798.344116,0.000297,0.004703,0.119451,289.966949,14.771621,1.194513,-798.344116,294.500488,0.000000
117.500008,65.164070,-798.433044,0.000285,0.004703,0.119451,289.864258,14.766389,1.194513,-798.433044,294.500488,0.000000
117.890007,65.154381,-798.433044,0.000293,0.004703,0.119451,289.821167,14.764194,1.194513,-798.433044,294.500488,0.000000
118.280006,65.139870,-798.433044,0.000280,0.004703,0.119451,289.756622,14.760905,1.194513,-798.433044,294.500488,0.000000
118.670006,65.119377,-798.433044,0.000289,0.004703,0.119451,289.665466,14.756262,1.194513,-798.433044,294.500488,0.000000
119.060005,65.352119,-798.388611,0.000293,0.004708,0.119581,290.700745,14.809002,1.195815,-798.388611,294.500488,0.000000
119.450005,65.382271,-798.477539,0.000289,0.004708,0.119581,290.834869,14.815834,1.195815,-798.477539,294.500488,0.000000
119.840004,65.387856,-798.433044,0.000293,0.004708,0.119581,290.859711,14.817100,1.195815,-798.433044,294.500488,0.000000
120.230003,65.389351,-798.433044,0.000302,0.004708,0.119581,290.866364,14.817439,1.195815,-798.433044,294.500488,0.000000
120.620003,65.387489,-798.566528,0.000297,0.004708,0.119581,290.858093,14.817017,1.195815,-798.566528,294.500488,0.000000
121.010002,65.389351,-798.477539,0.000285,0.004708,0.119581,290.866364,14.817439,1.195815,-798.477539,294.500488,0.000000
121.400009,65.385994,-798.522034,0.000293,0.004708,0.119581,290.851440,14.816678,1.195815,-798.522034,294.500488,0.000000
121.790009,65.368874,-798.433044,0.000297,0.004708,0.119581,290.775269,14.812799,1.195815,-798.433044,294.500488,0.000000
122.180008,65.373711,-798.477539,0.000297,0.004708,0.119581,290.796783,14.813894,1.195815,-798.477539,294.500488,0.000000
122.570007,65.354347,-798.522034,0.000297,0.004708,0.119581,290.710663,14.809507,1.195815,-798.522034,294.500488,0.000000
122.960007,65.359932,-798.477539,0.000302,0.004708,0.119581,290.735504,14.810773,1.195815,-798.477539,294.500488,0.000000
123.350006,65.332008,-798.566528,0.000280,0.004708,0.119581,290.611298,14.804445,1.195815,-798.566528,294.500488,0.000000
123.740005,65.334984,-798.566528,0.000302,0.004708,0.119581,290.624512,14.805119,1.195815,-798.566528,294.500488,0.000000
124.130005,65.320839,-798.477539,0.000302,0.004708,0.119581,290.561615,14.801914,1.195815,-798.477539,294.500488,0.000000
124.520004,65.315254,-798.566528,0.000285,0.004708,0.119581,290.536774,14.800649,1.195815,-798.566528,294.500488,0.000000
124.910004,65.314507,-798.522034,0.000310,0.004708,0.119581,290.533447,14.800479,1.195815,-798.522034,294.500488,0.000000
125.300003,65.296257,-798.566528,0.000289,0.004708,0.119581,290.452271,14.796344,1.195815,-798.566528,294.500488,0.000000
125.690002,65.305946,-798.566528,0.000310,0.004708,0.119581,290.495361,14.798539,1.195815,-798.566528,294.500488,0.000000
126.080009,65.273170,-798.611023,0.000297,0.004708,0.119581,290.349548,14.791112,1.195815,-798.611023,294.500488,0.000000
126.470009,65.273170,-798.611023,0.000302,0.004708,0.119581,290.349548,14.791112,1.195815,-798.611023,294.500488,0.000000
126.860008,65.250084,-798.566528,0.000297,0.004708,0.119581,290.246857,14.785880,1.195815,-798.566528,294.500488,0.000000
127.250008,65.237801,-798.655457,0.000293,0.004708,0.119581,290.192230,14.783097,1.195815,-798.655457,294.500488,0.000000
127.640007,65.222908,-798.655457,0.000297,0.004708,0.119581,290.125977,14.779722,1.195815,-798.655457,294.500488,0.000000
128.029999,65.208748,-798.655457,0.000289,0.004708,0.119581,290.062988,14.776513,1.195815,-798.655457,294.500488,0.000000
128.420013,65.208000,-798.611023,0.000302,0.004708,0.119581,290.059662,14.776343,1.195815,-798.611023,294.500488,0.000000
128.810013,65.198692,-798.611023,0.000302,0.004709,0.119616,290.018280,14.774235,1.196163,-798.611023,294.500488,0.000000
129.200012,65.211357,-798.611023,0.000293,0.004709,0.119616,290.074615,14.777104,1.196163,-798.611023,294.500488,0.000000
129.590012,65.208000,-798.699951,0.000297,0.004709,0.119616,290.059662,14.776343,1.196163,-798.699951,294.500488,0.000000
129.980011,65.197960,-798.655457,0.000297,0.004709,0.119616,290.015015,14.774069,1.196163,-798.655457,294.500488,0.000000
130.370010,65.199821,-798.699951,0.000302,0.004709,0.119616,290.023285,14.774490,1.196163,-798.699951,294.500488,0.000000
130.760010,65.184914,-798.655457,0.000280,0.004709,0.119616,289.956970,14.771112,1.196163,-798.655457,294.500488,0.000000
131.150009,65.181190,-798.699951,0.000285,0.004709,0.119616,289.940430,14.770268,1.196163,-798.699951,294.500488,0.000000
131.540009,65.173744,-798.699951,0.000306,0.004709,0.119616,289.907288,14.768581,1.196163,-798.699951,294.500488,0.000000
131.930008,65.154015,-798.744446,0.000293,0.004709,0.119616,289.819519,14.764111,1.196163,-798.744446,294.500488,0.000000
132.320007,65.149910,-798.744446,0.000297,0.004709,0.119616,289.801270,14.763181,1.196163,-798.744446,294.500488,0.000000
132.710007,65.132042,-798.744446,0.000293,0.004709,0.119616,289.721802,14.759132,1.196163,-798.744446,294.500488,0.000000
133.100006,65.138008,-798.699951,0.000289,0.004709,0.119616,289.748322,14.760484,1.196163,-798.699951,294.500488,0.000000
133.490005,65.115654,-798.699951,0.000302,0.004709,0.119616,289.648895,14.755418,1.196163,-798.699951,294.500488,0.000000
133.880005,65.113792,-798.699951,0.000297,0.004709,0.119616,289.640625,14.754995,1.196163,-798.699951,294.500488,0.000000
134.270004,65.097786,-798.833374,0.000302,0.004709,0.119616,289.569427,14.751369,1.196163,-798.833374,294.500488,0.000000
134.660004,65.082893,-798.788940,0.000293,0.004709,0.119616,289.503174,14.747994,1.196163,-798.788940,294.500488,0.000000
135.050003,65.305946,-798.833374,0.000289,0.004714,0.119747,290.495361,14.798539,1.197465,-798.833374,294.500488,0.000000
135.440002,65.349876,-798.788940,0.000302,0.004714,0.119747,290.690765,14.808494,1.197465,-798.788940,294.500488,0.000000
135.830002,65.374458,-798.788940,0.000289,0.004714,0.119747,290.800110,14.814064,1.197465,-798.788940,294.500488,0.000000
136.220001,65.381157,-798.788940,0.000306,0.004714,0.119747,290.829926,14.815581,1.197465,-798.788940,294.500488,0.000000
136.610001,65.393822,-798.788940,0.000306,0.004714,0.119747,290.886261,14.818452,1.197465,-798.788940,294.500488,0.000000
137.000000,65.383766,-798.833374,0.000293,0.004714,0.119747,290.841522,14.816174,1.197465,-798.833374,294.500488,0.000000
137.389999,65.388603,-798.833374,0.000302,0.004714,0.119747,290.863037,14.817269,1.197465,-798.833374,294.500488,0.000000
137.780014,65.377068,-798.833374,0.000289,0.004714,0.119747,290.811707,14.814655,1.197465,-798.833374,294.500488,0.000000
138.170013,65.392326,-798.877869,0.000302,0.004714,0.119747,290.879608,14.818112,1.197465,-798.877869,294.500488,0.000000
138.560013,65.384132,-798.877869,0.000302,0.004714,0.119747,290.843140,14.816257,1.197465,-798.877869,294.500488,0.000000
138.950012,65.377068,-798.966858,0.000293,0.004714,0.119747,290.811707,14.814655,1.197465,-798.966858,294.500488,0.000000
139.340012,65.367012,-798.877869,0.000297,0.004714,0.119747,290.766998,14.812377,1.197465,-798.877869,294.500488,0.000000
139.730011,65.353981,-798.877869,0.000285,0.004714,0.119747,290.709015,14.809423,1.197465,-798.877869,294.500488,0.000000
140.120010,65.357704,-798.922363,0.000310,0.004714,0.119747,290.725586,14.810267,1.197465,-798.922363,294.500488,0.000000
140.510010,65.351372,-798.833374,0.000297,0.004714,0.119747,290.697418,14.808832,1.197465,-798.833374,294.500488,0.000000
140.900009,65.341682,-798.922363,0.000289,0.004714,0.119747,290.654327,14.806637,1.197465,-798.922363,294.500488,0.000000
141.290009,65.340569,-798.966858,0.000306,0.004714,0.119747,290.649353,14.806384,1.197465,-798.966858,294.500488,0.000000
141.680008,65.320839,-798.922363,0.000302,0.004714,0.119747,290.561615,14.801914,1.197465,-798.922363,294.500488,0.000000
142.070007,65.308174,-798.966858,0.000289,0.004714,0.119747,290.505280,14.799045,1.197465,-798.966858,294.500488,0.000000
142.460007,65.303337,-798.922363,0.000289,0.004714,0.119747,290.483765,14.797948,1.197465,-798.922363,294.500488,0.000000
142.850006,65.288811,-799.055786,0.000306,0.004714,0.119747,290.419128,14.794656,1.197465,-799.055786,294.500488,0.000000
143.240005,65.279137,-799.011353,0.000293,0.004714,0.119747,290.376099,14.792464,1.197465,-799.011353,294.500488,0.000000
143.630005,65.277641,-798.966858,0.000293,0.004714,0.119747,290.369446,14.792125,1.197465,-798.966858,294.500488,0.000000
144.020004,65.266472,-799.055786,0.000297,0.004714,0.119747,290.319763,14.789594,1.197465,-799.055786,294.500488,0.000000
144.410004,65.255302,-799.011353,0.000302,0.004714,0.119747,290.270081,14.787063,1.197465,-799.011353,294.500488,0.000000
144.800003,65.257530,-799.100281,0.000302,0.004714,0.119747,290.279999,14.787567,1.197465,-799.100281,1681.640991,0.000000
145.190002,65.109322,-799.055786,0.000297,0.004702,0.119435,289.620728,14.753983,1.194346,-799.055786,0.119209,0.000000
145.580002,65.151772,-799.100281,0.000306,0.004685,0.118991,289.809540,14.763602,1.189910,-799.100281,0.118558,0.000000
145.970001,65.053093,-799.144775,0.000302,0.004662,0.118402,289.370605,14.741241,1.184021,-799.144775,0.117907,0.000000
146.360001,65.024803,-799.011353,0.000319,0.004638,0.117812,289.244781,14.734831,1.178117,-799.011353,0.117258,0.000000
146.750000,65.078423,-799.100281,0.000315,0.004607,0.117006,289.483276,14.746982,1.170062,-799.100281,0.116607,0.000000
147.139999,65.008781,-799.055786,0.000310,0.004587,0.116502,289.173492,14.731200,1.165021,-799.055786,0.115957,0.000000
147.530014,65.012505,-799.100281,0.000306,0.004562,0.115869,289.190063,14.732044,1.158693,-799.100281,0.115306,0.000000
147.920013,64.974907,-799.100281,0.000315,0.004538,0.115271,289.022827,14.723524,1.152712,-799.100281,0.114655,0.000000
148.310013,64.920158,-799.100281,0.000323,0.004513,0.114620,288.779297,14.711118,1.146202,-799.100281,0.114006,0.000000
148.700012,64.866920,-799.144775,0.000315,0.004488,0.114006,288.542480,14.699055,1.140056,-799.144775,0.113355,0.000000
149.090012,64.531029,-799.144775,0.000319,0.004467,0.113450,287.048340,14.622940,1.134500,-799.144775,0.112704,0.000000
149.480011,63.587822,-799.144775,0.000297,0.004440,0.112782,282.852753,14.409206,1.127823,-799.144775,0.112054,0.000000
149.870010,62.532135,-799.189270,0.000319,0.004417,0.112193,278.156830,14.169985,1.121934,-799.189270,0.111403,0.000000
150.260010,61.455238,-799.144775,0.000323,0.004397,0.111682,273.366547,13.925956,1.116817,-799.144775,0.110754,0.000000
150.650009,59.621300,-799.189270,0.000328,0.004368,0.110935,265.208801,13.510380,1.109353,-799.189270,0.110103,0.000000
151.040009,57.750130,-799.144775,0.000332,0.004344,0.110337,256.885406,13.086367,1.103373,-799.144775,0.109452,0.000000
151.430008,56.093071,-799.144775,0.000323,0.004326,0.109886,249.514435,12.710872,1.098861,-799.144775,0.108802,0.000000
151.820007,53.572487,-799.233704,0.000323,0.004299,0.109184,238.302322,12.139699,1.091836,-799.233704,0.108151,0.000000
152.210007,50.651970,-799.233704,0.000310,0.004270,0.108463,225.311218,11.477901,1.084630,-799.233704,0.107502,0.000000
152.600006,47.763847,-799.233704,0.000328,0.004243,0.107779,212.464203,10.823442,1.077787,-799.233704,0.106860,0.000000
152.990005,45.095428,-799.189270,0.000323,0.004219,0.107162,200.594482,10.218770,1.071625,-799.189270,0.106209,0.000000
153.380005,42.653038,-799.189270,0.000323,0.004199,0.106660,189.730194,9.665317,1.066599,-799.189270,0.105558,0.000000
153.770004,40.113823,-799.233704,0.000319,0.004177,0.106097,178.435196,9.089922,1.060967,-799.233704,0.104908,0.000000
154.160004,36.889450,-799.189270,0.000315,0.004145,0.105281,164.092468,8.359269,1.052806,-799.189270,0.104257,0.000000
154.550003,34.504784,-799.278198,0.000323,0.004122,0.104708,153.484940,7.818896,1.047084,-799.278198,0.103608,0.000000
154.940002,31.132576,-799.233704,0.000332,0.004092,0.103936,138.484619,7.054743,1.039362,-799.233704,0.102957,0.000000
155.330002,28.591507,-799.233704,0.000323,0.004069,0.103364,127.181374,6.478928,1.033640,-799.233704,0.102306,0.000000
155.720001,25.738762,-799.322693,0.000328,0.004045,0.102731,114.491730,5.832487,1.027311,-799.322693,0.101656,0.000000
156.110001,23.112793,-799.278198,0.000315,0.004024,0.102203,102.810837,5.237433,1.022028,-799.278198,0.101005,0.000000
156.500000,20.049278,-799.322693,0.000310,0.003995,0.101482,89.183647,4.543231,1.014821,-799.322693,0.100356,0.000000
156.890015,16.562012,-799.322693,0.000310,0.003964,0.100684,73.671509,3.753006,1.006843,-799.322693,0.099705,0.000000
157.280014,14.147552,-799.322693,0.000310,0.003942,0.100138,62.931458,3.205881,1.001377,-799.322693,0.099054,0.000000
157.670013,11.295547,-799.367187,0.000315,0.003916,0.099470,50.245106,2.559608,0.994701,-799.367187,0.098404,0.000000
158.060013,8.613724,-799.367187,0.000310,0.003891,0.098837,38.315758,1.951898,0.988372,-799.367187,0.097753,0.000000
158.450012,5.944557,-799.411682,0.000302,0.003864,0.098153,26.442711,1.347056,0.981529,-799.411682,0.097102,0.000000
158.840012,2.643478,-799.367187,0.000302,0.003836,0.097432,11.758780,0.599021,0.974323,-799.367187,0.096453,0.000000
159.230011,0.585373,-799.411682,0.000315,0.003811,0.096809,2.603869,0.132647,0.968085,-799.411682,0.095802,0.000000
159.620010,-0.927204,-799.367187,0.000315,0.003787,0.096183,-4.124410,-0.210107,0.961833,-799.367187,0.095152,0.000000
160.010010,-0.079681,-799.367187,0.000267,0.003762,0.095560,-0.354441,-0.018056,0.955595,-799.367187,0.094501,0.000000
160.400009,-0.049522,-799.411682,0.000216,0.003735,0.094866,-0.220287,-0.011222,0.948661,-799.411682,0.093850,0.000000
160.790009,0.000748,-799.367187,0.000172,0.003711,0.094259,0.003326,0.000169,0.942590,-799.367187,0.093201,0.000000
161.180008,0.018250,-799.367187,0.000108,0.003687,0.093652,0.081178,0.004135,0.936519,-799.367187,0.092550,0.000000
161.570007,0.052505,-799.367187,0.000060,0.003656,0.092871,0.233556,0.011898,0.928707,-799.367187,0.091900,0.000000
161.960007,0.107246,-799.322693,-0.000022,0.003636,0.092350,0.477056,0.024302,0.923499,-799.322693,0.091258,0.000000
162.200012,0.221939,-799.411682,-0.000034,0.003634,0.092315,0.987234,0.050292,0.923151,-799.411682,0.092203,0.000000