File: Data/compression 35/ManualNoHeating-15-35-reverse-1-1_11182024_175212.csv
Time (sec),S:Load (lbs),S:HL1 (DIM),S:LVDT (in),S:Position (in),Ch:Position (mm),Ch:Load (N),Ch:Stress (MPa),Ch:Strain (mm/mm),Ch:HL1 (DIM),Set Point (),Cycles ()
0.110000,0.014900,-872.671753,-0.006420,-0.006262,-0.159049,0.066279,0.003376,-1.590489,-872.671753,-0.158832,0.000000
0.470000,-0.001114,-872.671753,-0.006424,-0.006227,-0.158174,-0.004955,-0.000252,-1.581738,-872.671753,-0.157409,0.000000
0.830000,-0.012657,-872.627319,-0.006355,-0.006011,-0.152692,-0.056302,-0.002868,-1.526917,-872.627319,-0.151409,0.000000
1.190000,0.026817,-872.671753,-0.006127,-0.005777,-0.146734,0.119289,0.006077,-1.467343,-872.671753,-0.145408,0.000000
1.550000,0.043571,-872.671753,-0.005881,-0.005541,-0.140751,0.193816,0.009873,-1.407512,-872.671753,-0.139407,0.000000
1.910000,0.056976,-872.716248,-0.005644,-0.005297,-0.134541,0.253443,0.012911,-1.345409,-872.716248,-0.133405,0.000000
2.270000,0.042450,-872.627319,-0.005420,-0.005074,-0.128870,0.188827,0.009619,-1.288696,-872.627319,-0.127421,0.000000
2.630000,0.114693,-872.671753,-0.005148,0.000019,0.000495,0.510179,0.025990,0.004951,-872.671753,0.001908,0.000000
2.990000,0.121025,-872.671753,-0.005144,0.000010,0.000260,0.538346,0.027425,0.002604,-872.671753,0.000442,0.000000
3.350000,0.116928,-872.671753,-0.005157,0.000010,0.000251,0.520122,0.026496,0.002513,-872.671753,0.000754,0.000000
3.710000,0.098679,-872.716248,-0.005144,0.000010,0.000260,0.438944,0.022361,0.002604,-872.716248,0.001353,0.000000
4.070000,0.119904,-872.716248,-0.005157,0.000022,0.000556,0.533358,0.027171,0.005556,-872.716248,0.001951,0.000000
4.430000,0.193634,-872.716248,-0.005122,0.000052,0.001319,0.861327,0.043878,0.013187,-872.716248,0.002559,0.000000
4.790000,0.436798,-872.716248,-0.005092,0.000083,0.002098,1.942975,0.098980,0.020983,-872.716248,0.003157,0.000000
5.150000,0.583138,-872.671753,-0.005075,0.000102,0.002593,2.593925,0.132141,0.025934,-872.671753,0.003755,0.000000
5.510000,0.772301,-872.805237,-0.005044,0.000129,0.003270,3.435365,0.175006,0.032701,-872.805237,0.004354,0.000000
5.870000,0.951790,-872.716248,-0.005032,0.000148,0.003755,4.233773,0.215679,0.037546,-872.716248,0.004952,0.000000
6.230000,1.321182,-872.805237,-0.004988,0.000177,0.004492,5.876912,0.299384,0.044919,-872.805237,0.005550,0.000000
6.590000,1.630623,-872.805237,-0.004984,0.000200,0.005091,7.253373,0.369504,0.050914,-872.805237,0.006157,0.000000
6.950000,1.851440,-872.894165,-0.004950,0.000222,0.005646,8.235619,0.419542,0.056455,-872.894165,0.006755,0.000000
7.310000,2.233490,-872.805237,-0.004928,0.000245,0.006227,9.935060,0.506116,0.062269,-872.805237,0.007355,0.000000
7.670001,2.411118,-872.849731,-0.004924,0.000263,0.006678,10.725186,0.546367,0.066781,-872.849731,0.007953,0.000000
8.030001,2.724281,-872.805237,-0.004898,0.000285,0.007241,12.118209,0.617331,0.072413,-872.805237,0.008551,0.000000
8.390000,3.060905,-872.894165,-0.004885,0.000307,0.007797,13.615587,0.693611,0.077969,-872.894165,0.009158,0.000000
8.750000,3.647392,-872.760742,-0.004838,0.000342,0.008699,16.224411,0.826511,0.086992,-872.760742,0.009756,0.000000
9.110001,3.702873,-872.849731,-0.004825,0.000358,0.009097,16.471203,0.839083,0.090974,-872.849731,0.010355,0.000000
9.470000,4.286011,-872.805237,-0.004816,0.000388,0.009851,19.065128,0.971224,0.098513,-872.805237,0.010953,0.000000
9.830001,4.227547,-872.849731,-0.004777,0.000401,0.010198,18.805067,0.957976,0.101980,-872.849731,0.011551,0.000000
10.190001,4.501244,-872.849731,-0.004760,0.000420,0.010667,20.022532,1.019996,0.106673,-872.849731,0.012159,0.000000
10.550000,5.246735,-872.894165,-0.004747,0.000455,0.011570,23.338642,1.188927,0.115697,-872.894165,0.012757,0.000000
10.910001,5.561760,-872.894165,-0.004704,0.000482,0.012237,24.739944,1.260313,0.122373,-872.894165,0.013356,0.000000
11.270000,5.743477,-872.938660,-0.004687,0.000505,0.012826,25.548262,1.301490,0.128263,-872.938660,0.013954,0.000000
11.630000,5.994827,-872.894165,-0.004665,0.000528,0.013417,26.666323,1.358447,0.134167,-872.894165,0.014552,0.000000
11.990001,6.087921,-872.983154,-0.004652,0.000544,0.013806,27.080425,1.379543,0.138058,-872.983154,0.015159,0.000000
12.350000,6.498650,-872.894165,-0.004626,0.000566,0.014378,28.907436,1.472615,0.143781,-872.894165,0.015757,0.000000
12.710001,7.037842,-872.983154,-0.004587,0.000600,0.015238,31.305883,1.594798,0.152380,-872.983154,0.016357,0.000000
13.070001,7.065025,-872.938660,-0.004587,0.000616,0.015636,31.426802,1.600958,0.156362,-872.938660,0.016955,0.000000
13.430000,7.467560,-872.938660,-0.004549,0.000640,0.016260,33.217365,1.692173,0.162599,-872.938660,0.017553,0.000000
13.790001,7.599007,-873.027649,-0.004527,0.000661,0.016781,33.802071,1.721960,0.167807,-873.027649,0.018151,0.000000
14.150001,8.007500,-872.983154,-0.004501,0.000686,0.017423,35.619137,1.814525,0.174226,-872.983154,0.018758,0.000000
14.510000,8.557869,-873.027649,-0.004471,0.000719,0.018255,38.067303,1.939241,0.182553,-873.027649,0.019356,0.000000
14.870001,8.592499,-872.983154,-0.004458,0.000737,0.018732,38.221344,1.947088,0.187322,-872.983154,0.019955,0.000000
15.230000,8.806610,-872.938660,-0.004441,0.000759,0.019279,39.173759,1.995606,0.192787,-872.938660,0.020553,0.000000
15.590001,9.094086,-873.072083,-0.004424,0.000785,0.019930,40.452515,2.060749,0.199297,-873.072083,0.021152,0.000000
15.950001,9.305222,-872.938660,-0.004385,0.000805,0.020440,41.391693,2.108593,0.204399,-872.938660,0.021759,0.000000
16.310001,9.944580,-873.027649,-0.004350,0.000836,0.021230,44.235703,2.253474,0.212302,-873.027649,0.022357,0.000000
16.670000,10.385841,-873.072083,-0.004333,0.000867,0.022010,46.198528,2.353465,0.220099,-873.072083,0.022956,0.000000
17.030001,10.558250,-873.072083,-0.004303,0.000893,0.022670,46.965443,2.392534,0.226700,-873.072083,0.023554,0.000000
17.390001,10.565331,-873.161072,-0.004268,0.000914,0.023217,46.996937,2.394138,0.232165,-873.161072,0.024152,0.000000
17.750000,10.802528,-873.072083,-0.004260,0.000938,0.023822,48.052048,2.447888,0.238221,-873.072083,0.024759,0.000000
18.110001,10.876259,-873.027649,-0.004230,0.000955,0.024266,48.380016,2.464596,0.242657,-873.027649,0.025357,0.000000
18.470001,11.190544,-873.072083,-0.004221,0.000980,0.024899,49.778027,2.535814,0.248986,-873.072083,0.025957,0.000000
18.830002,11.263153,-873.116577,-0.004204,0.000998,0.025350,50.101006,2.552267,0.253497,-873.116577,0.026555,0.000000
19.190001,11.291084,-873.116577,-0.004182,0.001018,0.025861,50.225250,2.558596,0.258614,-873.116577,0.027153,0.000000
19.550001,11.720802,-873.161072,-0.004152,0.001040,0.026406,52.136734,2.655972,0.264065,-873.161072,0.027760,0.000000
19.910002,12.212334,-873.116577,-0.004118,0.001069,0.027153,54.323174,2.767354,0.271528,-873.116577,0.028358,0.000000
20.270000,12.625664,-873.161072,-0.004092,0.001098,0.027890,56.161758,2.861016,0.278901,-873.161072,0.028957,0.000000
20.630001,12.631996,-873.161072,-0.004061,0.001118,0.028393,56.189926,2.862451,0.283928,-873.161072,0.029555,0.000000
20.990002,12.619705,-873.205566,-0.004036,0.001135,0.028835,56.135254,2.859666,0.288348,-873.205566,0.030153,0.000000
21.350000,12.824883,-873.161072,-0.004005,0.001159,0.029434,57.047928,2.906160,0.294344,-873.161072,0.030752,0.000000
21.710001,13.098579,-873.116577,-0.003980,0.001183,0.030049,58.265392,2.968180,0.300490,-873.116577,0.031359,0.000000
22.070002,13.668304,-873.205566,-0.003971,0.001214,0.030830,60.799656,3.097282,0.308302,-873.205566,0.031958,0.000000
22.430000,13.631439,-873.161072,-0.003923,0.001236,0.031393,60.635670,3.088928,0.313934,-873.161072,0.032556,0.000000
22.790001,13.260933,-873.205566,-0.003911,0.001247,0.031672,58.987576,3.004970,0.316720,-873.205566,0.033154,0.000000
23.150002,13.866035,-873.250061,-0.003872,0.001278,0.032461,61.679207,3.142088,0.324608,-873.250061,0.033752,0.000000
23.510000,14.016846,-873.205566,-0.003850,0.001304,0.033128,62.350044,3.176263,0.331284,-873.205566,0.034359,0.000000
23.870001,14.235428,-873.250061,-0.003837,0.001323,0.033614,63.322346,3.225794,0.336144,-873.250061,0.034957,0.000000
24.230001,15.126892,-873.205566,-0.003811,0.001358,0.034499,67.287773,3.427803,0.344986,-873.205566,0.035557,0.000000
24.590002,14.821541,-873.338989,-0.003768,0.001375,0.034915,65.929504,3.358609,0.349149,-873.338989,0.036155,0.000000
24.950001,14.466301,-873.205566,-0.003738,0.001388,0.035262,64.349319,3.278111,0.352616,-873.205566,0.036753,0.000000
25.310001,15.063217,-873.250061,-0.003699,0.001419,0.036043,67.004539,3.413374,0.360428,-873.250061,0.037360,0.000000
25.670002,15.353668,-873.250061,-0.003695,0.001446,0.036727,68.296524,3.479191,0.367271,-873.250061,0.037958,0.000000
26.030001,15.671669,-873.250061,-0.003669,0.001470,0.037334,69.711067,3.551251,0.373342,-873.250061,0.038557,0.000000
26.390001,15.616188,-873.294495,-0.003626,0.001494,0.037950,69.464272,3.538679,0.379504,-873.294495,0.039155,0.000000
26.750002,15.928604,-873.338989,-0.003591,0.001517,0.038539,70.853973,3.609473,0.385393,-873.338989,0.039754,0.000000
27.110001,15.882431,-873.294495,-0.003579,0.001541,0.039146,70.648582,3.599010,0.391464,-873.294495,0.040361,0.000000
27.470001,16.686760,-873.294495,-0.003544,0.001573,0.039962,74.226418,3.781274,0.399624,-873.294495,0.040959,0.000000
27.830002,16.502808,-873.294495,-0.003514,0.001595,0.040517,73.408157,3.739589,0.405165,-873.294495,0.041558,0.000000
28.190001,16.726974,-873.338989,-0.003458,0.001617,0.041072,74.405296,3.790386,0.410722,-873.338989,0.042156,0.000000
28.550001,16.791023,-873.294495,-0.003449,0.001639,0.041635,74.690201,3.804900,0.416354,-873.294495,0.042754,0.000000
28.910002,16.372101,-873.294495,-0.003419,0.001651,0.041931,72.826744,3.709971,0.419306,-873.294495,0.043352,0.000000
29.270000,16.808899,-873.338989,-0.003402,0.001677,0.042589,74.769714,3.808951,0.425892,-873.338989,0.043959,0.000000
29.630001,16.901619,-873.294495,-0.003380,0.001699,0.043154,75.182159,3.829962,0.431539,-873.294495,0.044559,0.000000
29.990002,18.119644,-873.383484,-0.003337,0.001734,0.044055,80.600204,4.105970,0.440547,-873.383484,0.045157,0.000000
30.350002,17.743179,-873.472412,-0.003316,0.001752,0.044489,78.925606,4.020662,0.444892,-873.472412,0.045755,0.000000
30.710001,18.710228,-873.338989,-0.003285,0.001785,0.045348,83.227249,4.239799,0.453476,-873.338989,0.046353,0.000000
31.070002,18.124115,-873.427979,-0.003260,0.001800,0.045720,80.620087,4.106983,0.457200,-873.427979,0.046960,0.000000
31.430002,17.709663,-873.427979,-0.003234,0.001817,0.046145,78.776520,4.013067,0.461454,-873.427979,0.047559,0.000000
31.790001,19.181282,-873.383484,-0.003203,0.001852,0.047030,85.322601,4.346540,0.470296,-873.383484,0.048157,0.000000
32.150002,19.061005,-873.472412,-0.003178,0.001874,0.047611,84.787582,4.319285,0.476110,-873.472412,0.048756,0.000000
32.510002,19.319061,-873.472412,-0.003126,0.001901,0.048295,85.935478,4.377762,0.482953,-873.472412,0.049354,0.000000
32.870003,19.180908,-873.472412,-0.003109,0.001922,0.048816,85.320938,4.346456,0.488161,-873.472412,0.049961,0.000000
33.230003,18.943710,-873.427979,-0.003091,0.001940,0.049284,84.265831,4.292706,0.492839,-873.427979,0.050560,0.000000
33.590000,19.413643,-873.427979,-0.003065,0.001965,0.049900,86.356194,4.399194,0.499001,-873.427979,0.051158,0.000000
33.950001,20.175514,-873.516907,-0.003018,0.001994,0.050656,89.745171,4.571837,0.506555,-873.516907,0.051756,0.000000
34.310001,19.805008,-873.516907,-0.003005,0.002011,0.051079,88.097076,4.487879,0.510794,-873.516907,0.052354,0.000000
34.670002,20.197861,-873.561401,-0.002984,0.002035,0.051696,89.844574,4.576900,0.516956,-873.561401,0.052961,0.000000
35.030003,20.155037,-873.516907,-0.002971,0.002056,0.052216,89.654083,4.567197,0.522164,-873.516907,0.053559,0.000000
35.390003,20.923615,-873.516907,-0.002923,0.002084,0.052945,93.072884,4.741359,0.529446,-873.516907,0.054159,0.000000
35.750000,21.055435,-873.605896,-0.002893,0.002108,0.053552,93.659256,4.771230,0.535517,-873.605896,0.054757,0.000000
36.110001,21.412910,-873.516907,-0.002876,0.002136,0.054245,95.249382,4.852235,0.542451,-873.516907,0.055355,0.000000
36.470001,21.047981,-873.605896,-0.002837,0.002152,0.054652,93.626099,4.769540,0.546524,-873.605896,0.055962,0.000000
36.830002,21.392799,-873.605896,-0.002807,0.002179,0.055338,95.159927,4.847678,0.553382,-873.605896,0.056560,0.000000
37.190002,21.177200,-873.605896,-0.002764,0.002196,0.055780,94.200890,4.798822,0.557803,-873.605896,0.057159,0.000000
37.550003,21.794960,-873.650330,-0.002746,0.002225,0.056527,96.948822,4.938808,0.565266,-873.650330,0.057757,0.000000
37.910004,22.921761,-873.561401,-0.002708,0.002260,0.057393,101.961082,5.194145,0.573926,-873.561401,0.058356,0.000000
38.270000,22.732971,-873.561401,-0.002665,0.002284,0.058018,101.121307,5.151365,0.580179,-873.561401,0.058954,0.000000
38.630001,22.725891,-873.605896,-0.002630,0.002308,0.058625,101.089813,5.149760,0.586250,-873.605896,0.059561,0.000000
38.990002,22.844307,-873.650330,-0.002600,0.002330,0.059188,101.616554,5.176594,0.591882,-873.650330,0.060160,0.000000
39.350002,22.974640,-873.694824,-0.002583,0.002353,0.059779,102.196304,5.206128,0.597786,-873.694824,0.060758,0.000000
39.710003,22.460022,-873.605896,-0.002548,0.002367,0.060116,99.907166,5.089514,0.601162,-873.605896,0.061356,0.000000
40.070004,22.734833,-873.694824,-0.002535,0.002389,0.060689,101.129585,5.151786,0.606885,-873.694824,0.061954,0.000000
40.430000,22.412354,-873.605896,-0.002505,0.002404,0.061053,99.695129,5.078712,0.610534,-873.605896,0.062561,0.000000
40.790001,23.474739,-873.605896,-0.002453,0.002435,0.061842,104.420853,5.319452,0.618422,-873.605896,0.063161,0.000000
41.150002,24.213898,-873.694824,-0.002432,0.002464,0.062589,107.708794,5.486948,0.625885,-873.694824,0.063759,0.000000
41.510002,24.438805,-873.650330,-0.002402,0.002489,0.063212,108.709229,5.537912,0.632123,-873.650330,0.064357,0.000000
41.870003,23.926796,-873.739319,-0.002402,0.002504,0.063594,106.431702,5.421889,0.635938,-873.739319,0.064955,0.000000
42.230003,24.378113,-873.739319,-0.002345,0.002530,0.064252,108.439262,5.524159,0.642524,-873.739319,0.065562,0.000000
42.590000,24.789207,-873.739319,-0.002311,0.002557,0.064955,110.267899,5.617315,0.649549,-873.739319,0.066161,0.000000
42.950001,24.889748,-873.783813,-0.002298,0.002581,0.065562,110.715126,5.640097,0.655620,-873.783813,0.066759,0.000000
43.310001,24.885284,-873.739319,-0.002272,0.002603,0.066127,110.695274,5.639086,0.661267,-873.739319,0.067358,0.000000
43.670002,25.730568,-873.828308,-0.002229,0.002633,0.066872,114.455284,5.830630,0.668715,-873.828308,0.067956,0.000000
44.030003,25.549965,-873.739319,-0.002190,0.002652,0.067358,113.651917,5.789705,0.673575,-873.739319,0.068563,0.000000
44.390003,25.913773,-873.828308,-0.002164,0.002676,0.067974,115.270218,5.872145,0.679737,-873.828308,0.069162,0.000000
44.750004,25.697800,-873.828308,-0.002143,0.002698,0.068520,114.309525,5.823205,0.685202,-873.828308,0.069760,0.000000
45.110001,24.756439,-873.739319,-0.002104,0.002711,0.068849,110.122139,5.609889,0.688488,-873.739319,0.070358,0.000000
45.470001,26.381477,-873.783813,-0.002070,0.002744,0.069691,117.350670,5.978128,0.696905,-873.783813,0.070956,0.000000
45.830002,26.070175,-873.739319,-0.002035,0.002770,0.070358,115.965927,5.907586,0.703582,-873.739319,0.071556,0.000000
46.190002,26.052673,-873.828308,-0.001992,0.002786,0.070775,115.888077,5.903620,0.707745,-873.828308,0.072161,0.000000
46.550003,26.506218,-873.828308,-0.001970,0.002814,0.071477,117.905548,6.006395,0.714770,-873.828308,0.072761,0.000000
46.910004,26.819382,-873.783813,-0.001932,0.002842,0.072179,119.298569,6.077359,0.721795,-873.783813,0.073359,0.000000
47.270000,26.086929,-873.917236,-0.001910,0.002855,0.072510,116.040459,5.911383,0.725095,-873.917236,0.073957,0.000000
47.630001,26.867424,-873.783813,-0.001850,0.002888,0.073350,119.512268,6.088245,0.733498,-873.783813,0.074555,0.000000
47.990002,26.929977,-873.783813,-0.001832,0.002916,0.074070,119.790520,6.102420,0.740704,-873.783813,0.075162,0.000000
48.350002,26.909126,-873.917236,-0.001802,0.002936,0.074564,119.697769,6.097695,0.745639,-873.917236,0.075761,0.000000
48.710003,27.169785,-873.872742,-0.001750,0.002965,0.075319,120.857239,6.156761,0.753194,-873.872742,0.076359,0.000000
49.070004,27.019722,-873.872742,-0.001725,0.002983,0.075778,120.189728,6.122756,0.757781,-873.872742,0.076958,0.000000
49.430004,27.397682,-873.872742,-0.001690,0.003012,0.076506,121.870979,6.208404,0.765064,-873.872742,0.077556,0.000000
49.790001,27.160103,-873.872742,-0.001634,0.003034,0.077062,120.814171,6.154567,0.770620,-873.872742,0.078163,0.000000
50.150002,26.672668,-873.917236,-0.001630,0.003049,0.077434,118.645958,6.044113,0.774344,-873.917236,0.078762,0.000000
50.510002,26.863701,-873.872742,-0.001587,0.003072,0.078025,119.495712,6.087402,0.780249,-873.872742,0.079360,0.000000
50.870003,27.071854,-873.917236,-0.001574,0.003093,0.078553,120.421616,6.134570,0.785532,-873.917236,0.079958,0.000000
51.230003,28.342392,-873.828308,-0.001526,0.003126,0.079395,126.073257,6.422478,0.793950,-873.828308,0.080556,0.000000
51.590004,28.080612,-873.917236,-0.001496,0.003145,0.079889,124.908798,6.363158,0.798885,-873.917236,0.081163,0.000000
51.950001,28.270889,-873.917236,-0.001475,0.003177,0.080686,125.755196,6.406275,0.806864,-873.917236,0.081763,0.000000
52.310001,28.416489,-873.917236,-0.001431,0.003191,0.081042,126.402855,6.439269,0.810422,-873.917236,0.082361,0.000000
52.670002,28.184875,-873.961731,-0.001406,0.003209,0.081519,125.372589,6.386784,0.815191,-873.961731,0.082959,0.000000
53.030003,27.960709,-873.961731,-0.001393,0.003230,0.082040,124.375443,6.335987,0.820399,-873.961731,0.083557,0.000000
53.390003,30.085464,-874.006226,-0.001332,0.003264,0.082915,133.826828,6.817464,0.829149,-874.006226,0.084156,0.000000
53.750004,31.147469,-873.961731,-0.001315,0.003299,0.083782,138.550858,7.058117,0.837824,-873.961731,0.084763,0.000000
54.110004,30.609390,-873.917236,-0.001285,0.003318,0.084268,136.157364,6.936187,0.842684,-873.917236,0.085361,0.000000
54.470001,30.310753,-874.050659,-0.001263,0.003333,0.084668,134.828964,6.868515,0.846681,-874.050659,0.085960,0.000000
54.830002,30.326759,-873.961731,-0.001229,0.003356,0.085240,134.900162,6.872142,0.852404,-873.961731,0.086558,0.000000
55.190002,31.692627,-874.050659,-0.001181,0.003388,0.086055,140.975845,7.181652,0.860549,-874.050659,0.087157,0.000000
55.550003,31.751457,-874.050659,-0.001164,0.003407,0.086541,141.237534,7.194983,0.865409,-874.050659,0.087764,0.000000
55.910004,31.785713,-874.006226,-0.001147,0.003426,0.087009,141.389908,7.202746,0.870087,-874.006226,0.088362,0.000000
56.270004,32.374062,-874.095154,-0.001134,0.003450,0.087634,144.007019,7.336067,0.876339,-874.095154,0.088960,0.000000
56.630001,32.165161,-873.961731,-0.001104,0.003466,0.088041,143.077789,7.288730,0.880412,-873.961731,0.089558,0.000000
56.990002,33.883293,-874.139648,-0.001065,0.003504,0.089004,150.720413,7.678064,0.890041,-874.139648,0.090158,0.000000
57.350002,34.526009,-874.006226,-0.001035,0.003530,0.089654,153.579361,7.823705,0.896536,-874.006226,0.090763,0.000000
57.710003,33.639389,-874.095154,-0.001000,0.003546,0.090061,149.635483,7.622795,0.900608,-874.095154,0.091363,0.000000
58.070004,34.733414,-874.139648,-0.000983,0.003573,0.090747,154.501938,7.870704,0.907466,-874.139648,0.091961,0.000000
58.430004,34.979927,-874.095154,-0.000966,0.003590,0.091189,155.598480,7.926565,0.911887,-874.095154,0.092559,0.000000
58.790001,36.080658,-874.095154,-0.000931,0.003618,0.091891,160.494781,8.175994,0.918912,-874.095154,0.093157,0.000000
59.150002,37.439445,-874.139648,-0.000923,0.003649,0.092680,166.538971,8.483900,0.926800,-874.139648,0.093764,0.000000
59.510002,38.310051,-874.139648,-0.000875,0.003675,0.093357,170.411621,8.681182,0.933567,-874.139648,0.094363,0.000000
59.870003,39.143799,-874.139648,-0.000867,0.003702,0.094033,174.120316,8.870111,0.940334,-874.139648,0.094962,0.000000
60.230003,39.469254,-874.139648,-0.000832,0.003724,0.094589,175.568008,8.943860,0.945891,-874.139648,0.095560,0.000000
60.590004,40.375603,-874.184143,-0.000824,0.003750,0.095248,179.599655,9.149242,0.952476,-874.184143,0.096158,0.000000
60.950005,40.453430,-874.139648,-0.000789,0.003765,0.095638,179.945847,9.166878,0.956382,-874.139648,0.096757,0.000000
61.310001,40.859314,-874.139648,-0.000772,0.003786,0.096176,181.751312,9.258853,0.961757,-874.139648,0.097364,0.000000
61.670002,40.926712,-874.228638,-0.000763,0.003798,0.096471,182.051102,9.274126,0.964709,-874.228638,0.097962,0.000000
62.030003,42.661598,-874.139648,-0.000737,0.003829,0.097251,189.768265,9.667256,0.972506,-874.139648,0.098560,0.000000
62.390003,44.488083,-874.228638,-0.000703,0.003863,0.098109,197.892883,10.081144,0.981090,-874.228638,0.099158,0.000000
62.750004,44.845192,-874.139648,-0.000698,0.003880,0.098551,199.481369,10.162066,0.985511,-874.139648,0.099758,0.000000
63.110004,45.838684,-874.184143,-0.000681,0.003902,0.099116,203.900650,10.387195,0.991158,-874.184143,0.100365,0.000000
63.470001,46.884674,-874.228638,-0.000664,0.003927,0.099758,208.553452,10.624219,0.997577,-874.228638,0.100963,0.000000
63.830002,47.238060,-874.184143,-0.000642,0.003948,0.100277,210.125381,10.704297,1.002770,-874.184143,0.101561,0.000000
64.190002,48.762550,-874.273071,-0.000617,0.003972,0.100893,216.906662,11.049751,1.008932,-874.273071,0.102159,0.000000
64.550003,49.632042,-874.228638,-0.000625,0.003993,0.101414,220.774353,11.246781,1.014140,-874.228638,0.102758,0.000000
64.910004,51.770576,-874.317566,-0.000586,0.004027,0.102281,230.287033,11.731380,1.022815,-874.317566,0.103365,0.000000
65.270004,52.337700,-874.273071,-0.000582,0.004044,0.102724,232.809723,11.859893,1.027236,-874.273071,0.103963,0.000000
65.630005,53.228043,-874.184143,-0.000543,0.004066,0.103287,236.770157,12.061646,1.032868,-874.184143,0.104562,0.000000
65.990005,54.373459,-874.228638,-0.000535,0.004089,0.103868,241.865219,12.321202,1.038681,-874.228638,0.105160,0.000000
66.350006,54.626671,-874.273071,-0.000530,0.004104,0.104241,242.991562,12.378581,1.042405,-874.273071,0.105759,0.000000
66.710007,55.899071,-874.273071,-0.000500,0.004126,0.104796,248.651489,12.666911,1.047962,-874.273071,0.106366,0.000000
67.070000,58.412956,-874.273071,-0.000513,0.004160,0.105655,259.833801,13.236565,1.056546,-874.273071,0.106964,0.000000
67.430000,59.413147,-874.317566,-0.000487,0.004180,0.106183,264.282867,13.463211,1.061830,-874.317566,0.107562,0.000000
67.790001,60.981583,-874.317566,-0.000461,0.004207,0.106869,271.259613,13.818624,1.068688,-874.317566,0.108160,0.000000
68.150002,62.097206,-874.273071,-0.000453,0.004228,0.107380,276.222168,14.071427,1.073805,-874.273071,0.108758,0.000000
68.510002,63.500679,-874.317566,-0.000440,0.004251,0.107979,282.465118,14.389460,1.079785,-874.317566,0.109358,0.000000
68.870003,65.762474,-874.362061,-0.000423,0.004283,0.108793,292.526093,14.901990,1.087930,-874.362061,0.109965,0.000000
69.230003,65.834343,-874.362061,-0.000414,0.004286,0.108872,292.845795,14.918276,1.088717,-874.362061,0.019107,0.000000
69.590004,64.865059,-874.362061,-0.000392,0.004291,0.109002,288.534180,14.698632,1.090019,-874.362061,294.500488,0.000000
69.950005,64.855736,-874.362061,-0.000392,0.004300,0.109218,288.492706,14.696520,1.092184,-874.362061,294.500488,0.000000
70.310005,65.632515,-874.362061,-0.000379,0.004310,0.109470,291.947998,14.872540,1.094698,-874.362061,294.500488,0.000000
70.670006,65.274284,-874.362061,-0.000371,0.004320,0.109739,290.354523,14.791364,1.097392,-874.362061,294.500488,0.000000
71.030006,65.018471,-874.362061,-0.000375,0.004324,0.109835,289.216614,14.733397,1.098346,-874.362061,294.500488,0.000000
71.390007,64.715736,-874.406555,-0.000366,0.004328,0.109930,287.869965,14.664795,1.099300,-874.406555,294.500488,0.000000
71.750000,65.069115,-874.406555,-0.000366,0.004335,0.110103,289.441864,14.744872,1.101026,-874.406555,294.500488,0.000000
72.110001,65.189384,-874.406555,-0.000336,0.004341,0.110268,289.976868,14.772126,1.102676,-874.406555,294.500488,0.000000
72.470001,64.769722,-874.406555,-0.000349,0.004341,0.110268,288.110107,14.677029,1.102676,-874.406555,294.500488,0.000000
72.830002,65.524529,-874.406555,-0.000328,0.004353,0.110563,291.467651,14.848070,1.105628,-874.406555,294.500488,0.000000
73.190002,65.166679,-874.406555,-0.000341,0.004354,0.110579,289.875854,14.766981,1.105795,-874.406555,294.500488,0.000000
73.550003,65.078423,-874.406555,-0.000332,0.004357,0.110675,289.483276,14.746982,1.106749,-874.406555,294.500488,0.000000
73.910004,65.092567,-874.450989,-0.000319,0.004361,0.110779,289.546204,14.750187,1.107793,-874.450989,294.500488,0.000000
74.270004,65.224388,-874.406555,-0.000332,0.004365,0.110875,290.132568,14.780058,1.108747,-874.406555,294.500488,0.000000
74.630005,65.391212,-874.495483,-0.000293,0.004371,0.111023,290.874634,14.817861,1.110231,-874.495483,294.500488,0.000000
74.990005,65.224388,-874.495483,-0.000319,0.004371,0.111023,290.132568,14.780058,1.110231,-874.495483,294.500488,0.000000
75.350006,65.026283,-874.495483,-0.000310,0.004372,0.111049,289.251343,14.735167,1.110488,-874.495483,294.500488,0.000000
75.710007,65.329033,-874.495483,-0.000315,0.004378,0.111214,290.598053,14.803770,1.112138,-874.495483,294.500488,0.000000
76.070007,65.150658,-874.584473,-0.000319,0.004378,0.111214,289.804596,14.763350,1.112138,-874.584473,294.500488,0.000000
76.430000,65.186043,-874.495483,-0.000306,0.004382,0.111291,289.962006,14.771369,1.112911,-874.495483,294.500488,0.000000
76.790001,65.011772,-874.584473,-0.000306,0.004382,0.111291,289.186798,14.731878,1.112911,-874.584473,294.500488,0.000000
77.150002,64.899681,-874.584473,-0.000293,0.004383,0.111326,288.688202,14.706478,1.113259,-874.584473,294.500488,0.000000
77.510002,65.641075,-874.628967,-0.000297,0.004392,0.111551,291.986084,14.874480,1.115515,-874.628967,294.500488,0.000000
77.870003,65.469780,-874.584473,-0.000302,0.004392,0.111551,291.224121,14.835664,1.115515,-874.584473,294.500488,0.000000
78.230003,65.301094,-874.539978,-0.000289,0.004392,0.111551,290.473785,14.797440,1.115515,-874.539978,294.500488,0.000000
78.590004,65.121620,-874.628967,-0.000302,0.004392,0.111551,289.675446,14.756769,1.115515,-874.628967,294.500488,0.000000
78.950005,64.965218,-874.584473,-0.000285,0.004392,0.111551,288.979706,14.721329,1.115515,-874.584473,294.500488,0.000000
79.310005,64.760414,-874.628967,-0.000297,0.004392,0.111551,288.068695,14.674920,1.115515,-874.628967,294.500488,0.000000
79.670006,64.612206,-874.539978,-0.000302,0.004392,0.111561,287.409454,14.641335,1.115605,-874.539978,294.500488,0.000000
80.030006,64.468849,-874.673401,-0.000285,0.004392,0.111561,286.771759,14.608850,1.115605,-874.673401,294.500488,0.000000
80.390007,64.296440,-874.673401,-0.000293,0.004392,0.111561,286.004852,14.569781,1.115605,-874.673401,294.500488,0.000000
80.750008,66.777550,-874.584473,-0.000272,0.004278,0.108672,297.041382,15.132009,1.086719,-874.584473,294.500488,0.000000
81.110001,66.637550,-874.717896,-0.000267,0.004278,0.108672,296.418640,15.100285,1.086719,-874.717896,294.500488,0.000000
81.470001,66.422310,-874.628967,-0.000276,0.004279,0.108681,295.461182,15.051511,1.086810,-874.628967,294.500488,0.000000
81.830002,66.271873,-874.673401,-0.000259,0.004279,0.108681,294.792023,15.017421,1.086810,-874.673401,294.500488,0.000000
82.190002,66.108772,-874.717896,-0.000267,0.004279,0.108681,294.066498,14.980462,1.086810,-874.717896,294.500488,0.000000
82.550003,65.908806,-874.628967,-0.000267,0.004281,0.108725,293.177002,14.935149,1.087249,-874.628967,294.500488,0.000000
82.910004,65.803429,-874.717896,-0.000263,0.004283,0.108785,292.708282,14.911270,1.087855,-874.717896,294.500488,0.000000
83.270004,65.666405,-874.673401,-0.000267,0.004302,0.109279,292.098755,14.880219,1.092790,-874.673401,294.500488,0.000000
83.630005,65.546120,-874.717896,-0.000254,0.004346,0.110398,291.563690,14.852962,1.103978,-874.717896,294.500488,0.000000
83.990005,65.382271,-874.717896,-0.000267,0.004367,0.110910,290.834869,14.815834,1.109095,-874.717896,294.500488,0.000000
84.350006,65.286583,-874.673401,-0.000276,0.004373,0.111065,290.409210,14.794151,1.110655,-874.673401,294.500488,0.000000
84.710007,65.216942,-874.762390,-0.000267,0.004383,0.111317,290.099457,14.778370,1.113168,-874.762390,294.500488,0.000000
85.070007,65.208382,-874.717896,-0.000263,0.004397,0.111682,290.061371,14.776431,1.116817,-874.717896,294.500488,0.000000
85.430000,65.162956,-874.673401,-0.000267,0.004406,0.111907,289.859314,14.766137,1.119072,-874.673401,294.500488,0.000000
85.790001,65.180458,-874.851318,-0.000254,0.004410,0.112019,289.937164,14.770103,1.120193,-874.851318,294.500488,0.000000
86.150002,65.170021,-874.717896,-0.000259,0.004411,0.112028,289.890747,14.767738,1.120283,-874.717896,294.500488,0.000000
86.510002,65.144707,-874.851318,-0.000267,0.004413,0.112080,289.778137,14.762002,1.120798,-874.851318,294.500488,0.000000
86.870003,65.161095,-874.717896,-0.000263,0.004413,0.112098,289.851013,14.765716,1.120980,-874.717896,294.500488,0.000000
87.230003,65.083260,-874.806885,-0.000259,0.004414,0.112107,289.504791,14.748077,1.121071,-874.806885,294.500488,0.000000
87.590004,65.061287,-874.851318,-0.000259,0.004415,0.112133,289.407043,14.743098,1.121328,-874.851318,294.500488,0.000000
87.950005,65.124962,-874.851318,-0.000254,0.004417,0.112202,289.690308,14.757527,1.122025,-874.851318,294.500488,0.000000
88.310005,65.125710,-874.851318,-0.000259,0.004417,0.112202,289.693634,14.757697,1.122025,-874.851318,294.500488,0.000000
88.670006,65.102623,-874.895813,-0.000263,0.004419,0.112245,289.590942,14.752465,1.122448,-874.895813,294.500488,0.000000
89.030006,65.313393,-874.895813,-0.000263,0.004423,0.112333,290.528473,14.800226,1.123327,-874.895813,294.500488,0.000000
89.390007,65.320839,-874.851318,-0.000241,0.004423,0.112333,290.561615,14.801914,1.123327,-874.851318,294.500488,0.000000
89.750008,65.281364,-874.806885,-0.000263,0.004423,0.112333,290.386017,14.792969,1.123327,-874.806885,294.500488,0.000000
90.110001,65.230354,-874.895813,-0.000259,0.004423,0.112333,290.159119,14.781409,1.123327,-874.895813,294.500488,0.000000
90.470001,65.165184,-874.851318,-0.000259,0.004423,0.112333,289.869202,14.766642,1.123327,-874.851318,294.500488,0.000000
90.830002,65.096291,-874.895813,-0.000254,0.004423,0.112333,289.562775,14.751030,1.123327,-874.895813,294.500488,0.000000
91.190002,65.367012,-874.984802,-0.000250,0.004428,0.112470,290.766998,14.812377,1.124704,-874.984802,294.500488,0.000000
91.550003,65.392708,-874.851318,-0.000263,0.004428,0.112470,290.881287,14.818199,1.124704,-874.851318,294.500488,0.000000
91.910004,65.361427,-875.029297,-0.000254,0.004428,0.112470,290.742157,14.811111,1.124704,-875.029297,294.500488,0.000000
92.270004,65.325310,-874.851318,-0.000250,0.004428,0.112470,290.581482,14.802927,1.124704,-874.851318,294.500488,0.000000
92.630005,65.272804,-874.940308,-0.000259,0.004428,0.112470,290.347931,14.791029,1.124704,-874.940308,294.500488,0.000000
92.990005,65.234077,-874.984802,-0.000259,0.004428,0.112470,290.175659,14.782253,1.124704,-874.984802,294.500488,0.000000
93.350006,65.186775,-874.940308,-0.000250,0.004428,0.112470,289.965271,14.771534,1.124704,-874.940308,294.500488,0.000000
93.710007,65.105232,-875.029297,-0.000237,0.004428,0.112470,289.602539,14.753057,1.124704,-875.029297,294.500488,0.000000
94.070007,65.084007,-874.984802,-0.000250,0.004428,0.112480,289.508118,14.748247,1.124795,-874.984802,294.500488,0.000000
94.430008,65.034111,-874.940308,-0.000246,0.004430,0.112523,289.286163,14.736940,1.125234,-874.940308,294.500488,0.000000
94.790001,65.059059,-875.029297,-0.000246,0.004431,0.112540,289.397156,14.742594,1.125401,-875.029297,294.500488,0.000000
95.150002,65.054588,-874.940308,-0.000263,0.004431,0.112540,289.377258,14.741581,1.125401,-874.940308,294.500488,0.000000
95.510002,65.018837,-875.029297,-0.000254,0.004431,0.112540,289.218231,14.733479,1.125401,-875.029297,294.500488,0.000000
95.870003,65.229607,-874.984802,-0.000241,0.004434,0.112619,290.155792,14.781240,1.126188,-874.984802,294.500488,0.000000
96.230003,65.235939,-875.029297,-0.000241,0.004434,0.112619,290.183960,14.782675,1.126188,-875.029297,294.500488,0.000000
96.590004,65.198692,-875.029297,-0.000246,0.004434,0.112619,290.018280,14.774235,1.126188,-875.029297,294.500488,0.000000
96.950005,65.157372,-875.073730,-0.000259,0.004434,0.112619,289.834473,14.764872,1.126188,-875.073730,294.500488,0.000000
97.310005,65.094810,-875.073730,-0.000259,0.004434,0.112619,289.556183,14.750695,1.126188,-875.073730,294.500488,0.000000
97.670006,65.061668,-875.073730,-0.000246,0.004434,0.112619,289.408752,14.743185,1.126188,-875.073730,294.500488,0.000000
98.030006,64.997993,-875.029297,-0.000250,0.004435,0.112652,289.125519,14.728755,1.126521,-875.029297,294.500488,0.000000
98.390007,65.215080,-875.118225,-0.000241,0.004438,0.112714,290.091156,14.777948,1.127142,-875.118225,294.500488,0.000000
98.750008,65.219551,-875.029297,-0.000241,0.004438,0.112714,290.111053,14.778962,1.127142,-875.029297,294.500488,0.000000
99.110008,65.175606,-875.118225,-0.000254,0.004438,0.112714,289.915588,14.769003,1.127142,-875.118225,294.500488,0.000000
99.470001,65.154015,-875.118225,-0.000250,0.004438,0.112714,289.819519,14.764111,1.127142,-875.118225,294.500488,0.000000
99.830002,65.115654,-875.073730,-0.000233,0.004438,0.112714,289.648895,14.755418,1.127142,-875.073730,294.500488,0.000000
100.190002,65.073952,-875.118225,-0.000259,0.004438,0.112714,289.463379,14.745968,1.127142,-875.118225,294.500488,0.000000
100.550003,65.054588,-875.118225,-0.000246,0.004438,0.112722,289.377258,14.741581,1.127217,-875.118225,294.500488,0.000000
100.910004,65.029640,-875.162720,-0.000237,0.004438,0.112722,289.266296,14.735928,1.127217,-875.162720,294.500488,0.000000
101.270004,65.006554,-875.162720,-0.000259,0.004438,0.112722,289.163605,14.730696,1.127217,-875.162720,294.500488,0.000000
101.630005,64.966713,-875.162720,-0.000250,0.004438,0.112722,288.986359,14.721668,1.127217,-875.162720,294.500488,0.000000
101.990005,64.917549,-875.207214,-0.000233,0.004438,0.112722,288.767670,14.710527,1.127217,-875.207214,294.500488,0.000000
102.350006,64.850533,-875.162720,-0.000246,0.004438,0.112731,288.469574,14.695340,1.127308,-875.162720,294.500488,0.000000
102.710007,65.098534,-875.162720,-0.000233,0.004442,0.112835,289.572754,14.751538,1.128353,-875.162720,294.500488,0.000000
103.070007,65.107841,-875.162720,-0.000233,0.004442,0.112835,289.614136,14.753648,1.128353,-875.162720,294.500488,0.000000
103.430008,65.089958,-875.162720,-0.000229,0.004442,0.112835,289.534607,14.749595,1.128353,-875.162720,294.500488,0.000000
103.790009,65.067253,-875.251648,-0.000246,0.004442,0.112835,289.433594,14.744451,1.128353,-875.251648,294.500488,0.000000
104.150002,65.036720,-875.207214,-0.000237,0.004442,0.112835,289.297791,14.737532,1.128353,-875.207214,294.500488,0.000000
104.510002,65.017357,-875.207214,-0.000237,0.004442,0.112835,289.211639,14.733144,1.128353,-875.207214,294.500488,0.000000
104.870003,64.987938,-875.296143,-0.000241,0.004442,0.112835,289.080780,14.726477,1.128353,-875.296143,294.500488,0.000000
105.230003,64.959267,-875.296143,-0.000241,0.004442,0.112835,288.953247,14.719980,1.128353,-875.296143,294.500488,0.000000
105.590004,64.922768,-875.251648,-0.000250,0.004442,0.112835,288.790894,14.711709,1.128353,-875.251648,294.500488,0.000000
105.950005,64.890739,-875.207214,-0.000237,0.004442,0.112835,288.648437,14.704452,1.128353,-875.207214,294.500488,0.000000
106.310005,64.850533,-875.251648,-0.000250,0.004442,0.112835,288.469574,14.695340,1.128353,-875.251648,294.500488,0.000000
106.670006,64.819618,-875.251648,-0.000246,0.004443,0.112852,288.332062,14.688335,1.128519,-875.251648,294.500488,0.000000
107.030006,65.046776,-875.296143,-0.000220,0.004447,0.112947,289.342499,14.739810,1.129473,-875.296143,294.500488,0.000000
107.390007,65.058311,-875.296143,-0.000229,0.004447,0.112947,289.393829,14.742424,1.129473,-875.296143,294.500488,0.000000
107.750008,65.056831,-875.251648,-0.000237,0.004447,0.112947,289.387238,14.742089,1.129473,-875.251648,294.500488,0.000000
108.110008,65.035591,-875.296143,-0.000233,0.004447,0.112947,289.292755,14.737276,1.129473,-875.296143,294.500488,0.000000
108.470009,65.026283,-875.296143,-0.000229,0.004447,0.112947,289.251343,14.735167,1.129473,-875.296143,294.500488,0.000000
108.830002,65.009911,-875.296143,-0.000233,0.004447,0.112947,289.178528,14.731456,1.129473,-875.296143,294.500488,0.000000
109.190002,64.983833,-875.340637,-0.000237,0.004447,0.112947,289.062531,14.725547,1.129473,-875.340637,294.500488,0.000000
109.550003,64.956276,-875.296143,-0.000241,0.004447,0.112947,288.939941,14.719302,1.129473,-875.296143,294.500488,0.000000
109.910004,64.945488,-875.296143,-0.000224,0.004447,0.112947,288.891968,14.716858,1.129473,-875.296143,294.500488,0.000000
110.270004,64.896324,-875.340637,-0.000241,0.004447,0.112947,288.673279,14.705717,1.129473,-875.340637,294.500488,0.000000
110.630005,64.884789,-875.340637,-0.000229,0.004447,0.112947,288.621948,14.703104,1.129473,-875.340637,294.500488,0.000000
110.990005,64.838982,-875.385132,-0.000229,0.004447,0.112947,288.418182,14.692723,1.129473,-875.385132,294.500488,0.000000
111.350006,64.820000,-875.340637,-0.000229,0.004447,0.112947,288.333771,14.688422,1.129473,-875.340637,294.500488,0.000000
111.710007,64.804359,-875.340637,-0.000224,0.004447,0.112956,288.264191,14.684877,1.129564,-875.340637,294.500488,0.000000
112.070007,64.774559,-875.429626,-0.000233,0.004447,0.112956,288.131622,14.678125,1.129564,-875.429626,294.500488,0.000000
112.430008,64.762276,-875.385132,-0.000224,0.004447,0.112956,288.076996,14.675342,1.129564,-875.385132,294.500488,0.000000
112.790009,65.493996,-875.474060,-0.000216,0.004457,0.113217,291.331848,14.841151,1.132168,-875.474060,294.500488,0.000000
113.150009,65.579628,-875.429626,-0.000237,0.004457,0.113217,291.712769,14.860556,1.132168,-875.429626,294.500488,0.000000
113.510002,65.588203,-875.518555,-0.000229,0.004457,0.113217,291.750885,14.862499,1.132168,-875.518555,294.500488,0.000000
113.870003,65.601982,-875.385132,-0.000224,0.004457,0.113217,291.812195,14.865622,1.132168,-875.385132,294.500488,0.000000
114.230003,65.593040,-875.385132,-0.000233,0.004457,0.113217,291.772430,14.863595,1.132168,-875.385132,294.500488,0.000000
114.590004,65.578148,-875.474060,-0.000233,0.004457,0.113217,291.706177,14.860221,1.132168,-875.474060,294.500488,0.000000
114.950005,65.578148,-875.474060,-0.000224,0.004457,0.113217,291.706177,14.860221,1.132168,-875.474060,294.500488,0.000000
115.310005,65.564735,-875.429626,-0.000224,0.004457,0.113217,291.646515,14.857182,1.132168,-875.429626,294.500488,0.000000
115.670006,65.560265,-875.474060,-0.000237,0.004457,0.113217,291.626617,14.856169,1.132168,-875.474060,294.500488,0.000000
116.030006,65.528999,-875.429626,-0.000229,0.004457,0.113217,291.487549,14.849083,1.132168,-875.429626,294.500488,0.000000
116.390007,65.518562,-875.518555,-0.000229,0.004457,0.113217,291.441132,14.846719,1.132168,-875.518555,294.500488,0.000000
116.750008,65.490273,-875.563049,-0.000237,0.004457,0.113217,291.315277,14.840308,1.132168,-875.563049,294.500488,0.000000
117.110008,65.469048,-875.563049,-0.000224,0.004457,0.113217,291.220856,14.835499,1.132168,-875.563049,294.500488,0.000000
117.470009,65.443352,-875.563049,-0.000229,0.004457,0.113217,291.106567,14.829676,1.132168,-875.563049,294.500488,0.000000
117.830002,65.410210,-875.563049,-0.000229,0.004457,0.113217,290.959137,14.822165,1.132168,-875.563049,294.500488,0.000000
118.190002,65.386375,-875.518555,-0.000229,0.004457,0.113217,290.853119,14.816764,1.132168,-875.518555,294.500488,0.000000
118.550003,65.371849,-875.607544,-0.000224,0.004457,0.113217,290.788513,14.813473,1.132168,-875.607544,294.500488,0.000000
118.910004,65.343544,-875.563049,-0.000224,0.004457,0.113217,290.662598,14.807058,1.132168,-875.563049,294.500488,0.000000
119.270004,65.322701,-875.518555,-0.000224,0.004457,0.113217,290.569885,14.802335,1.132168,-875.518555,294.500488,0.000000
119.630005,65.302956,-875.563049,-0.000224,0.004457,0.113217,290.482056,14.797861,1.132168,-875.563049,294.500488,0.000000
119.990005,65.285454,-875.651978,-0.000229,0.004457,0.113217,290.404205,14.793895,1.132168,-875.651978,294.500488,0.000000
120.350006,65.261635,-875.607544,-0.000233,0.004457,0.113217,290.298248,14.788498,1.132168,-875.607544,294.500488,0.000000
120.710007,65.255302,-875.607544,-0.000216,0.004457,0.113217,290.270081,14.787063,1.132168,-875.607544,294.500488,0.000000
121.070007,65.215828,-875.607544,-0.000233,0.004457,0.113217,290.094482,14.778117,1.132168,-875.607544,294.500488,0.000000
121.430008,65.155128,-875.607544,-0.000224,0.004458,0.113226,289.824493,14.764363,1.132259,-875.607544,294.500488,0.000000
121.790009,65.141731,-875.696472,-0.000229,0.004458,0.113226,289.764893,14.761327,1.132259,-875.696472,294.500488,0.000000
122.150009,65.096672,-875.651978,-0.000229,0.004458,0.113226,289.564453,14.751117,1.132259,-875.651978,294.500488,0.000000
122.510002,65.057564,-875.696472,-0.000216,0.004458,0.113233,289.390503,14.742254,1.132335,-875.696472,294.500488,0.000000
122.870003,65.027779,-875.696472,-0.000237,0.004458,0.113233,289.257996,14.735505,1.132335,-875.696472,294.500488,0.000000
123.230003,65.008049,-875.651978,-0.000216,0.004458,0.113233,289.170258,14.731034,1.132335,-875.651978,294.500488,0.000000
123.590004,64.980858,-875.696472,-0.000220,0.004458,0.113233,289.049286,14.724873,1.132335,-875.696472,294.500488,0.000000
123.950005,64.974907,-875.651978,-0.000220,0.004458,0.113233,289.022827,14.723524,1.132335,-875.651978,294.500488,0.000000
124.310005,64.970055,-875.785461,-0.000220,0.004458,0.113233,289.001251,14.722425,1.132335,-875.785461,294.500488,0.000000
124.670006,64.957405,-875.740967,-0.000207,0.004458,0.113233,288.944977,14.719558,1.132335,-875.740967,294.500488,0.000000
125.030006,64.913826,-875.696472,-0.000211,0.004458,0.113233,288.751129,14.709682,1.132335,-875.696472,294.500488,0.000000
125.390007,64.887016,-875.740967,-0.000207,0.004458,0.113233,288.631866,14.703609,1.132335,-875.740967,294.500488,0.000000
125.750008,64.846062,-875.696472,-0.000229,0.004458,0.113233,288.449677,14.694327,1.132335,-875.696472,294.500488,0.000000
126.110008,64.832649,-875.740967,-0.000216,0.004458,0.113233,288.390015,14.691288,1.132335,-875.740967,294.500488,0.000000
126.470009,64.802498,-875.785461,-0.000224,0.004458,0.113233,288.255920,14.684456,1.132335,-875.785461,294.500488,0.000000
126.830009,64.804726,-875.740967,-0.000229,0.004458,0.113233,288.265808,14.684960,1.132335,-875.740967,294.500488,0.000000
127.190002,64.760048,-875.785461,-0.000211,0.004458,0.113233,288.067078,14.674837,1.132335,-875.785461,294.500488,0.000000
127.550003,64.741417,-875.785461,-0.000229,0.004458,0.113233,287.984192,14.670615,1.132335,-875.785461,294.500488,0.000000
127.910004,64.717598,-875.740967,-0.000216,0.004458,0.113243,287.878265,14.665217,1.132425,-875.740967,294.500488,0.000000
128.270004,64.720940,-875.829956,-0.000229,0.004458,0.113243,287.893127,14.665975,1.132425,-875.829956,294.500488,0.000000
128.630005,64.897072,-875.785461,-0.000229,0.004462,0.113347,288.676605,14.705887,1.133470,-875.785461,294.500488,0.000000
128.990005,64.950325,-875.829956,-0.000211,0.004462,0.113347,288.913483,14.717954,1.133470,-875.829956,294.500488,0.000000
129.350006,64.943993,-875.785461,-0.000220,0.004462,0.113347,288.885315,14.716518,1.133470,-875.785461,294.500488,0.000000
129.710007,64.955544,-875.829956,-0.000216,0.004462,0.113347,288.936676,14.719137,1.133470,-875.829956,1681.640991,0.000000
130.070007,64.977135,-875.829956,-0.000220,0.004456,0.113173,289.032745,14.724030,1.131729,-875.829956,0.112982,0.000000
130.430008,64.911232,-875.785461,-0.000203,0.004439,0.112747,288.739594,14.709095,1.127475,-875.785461,0.112384,0.000000
130.790009,64.820732,-875.874390,-0.000216,0.004418,0.112219,288.337006,14.688588,1.122191,-875.874390,0.111786,0.000000
131.150009,64.784996,-875.829956,-0.000224,0.004398,0.111698,288.178070,14.680490,1.116983,-875.829956,0.111187,0.000000
131.510010,64.730247,-875.829956,-0.000207,0.004374,0.111100,287.934509,14.668084,1.111003,-875.829956,0.110579,0.000000
131.870010,64.721321,-875.829956,-0.000198,0.004353,0.110554,287.894806,14.666060,1.105538,-875.829956,0.109981,0.000000
132.230011,64.704567,-875.829956,-0.000207,0.004327,0.109895,287.820282,14.662264,1.098952,-875.829956,0.109383,0.000000
132.590012,64.719078,-875.918884,-0.000207,0.004307,0.109409,287.884827,14.665552,1.094092,-875.918884,0.108785,0.000000
132.950012,64.674019,-875.874390,-0.000207,0.004285,0.108846,287.684418,14.655342,1.088460,-875.874390,0.108186,0.000000
133.310013,64.605873,-875.918884,-0.000207,0.004260,0.108204,287.381287,14.639900,1.082041,-875.918884,0.107579,0.000000
133.670013,64.501991,-875.918884,-0.000207,0.004239,0.107683,286.919189,14.616361,1.076833,-875.918884,0.106981,0.000000
134.029999,64.119942,-875.874390,-0.000190,0.004216,0.107094,285.219757,14.529786,1.070944,-875.874390,0.106383,0.000000
134.389999,63.487267,-875.963379,-0.000211,0.004193,0.106513,282.405457,14.386420,1.065130,-875.963379,0.105785,0.000000
134.750000,62.558952,-875.829956,-0.000185,0.004172,0.105976,278.276123,14.176061,1.059755,-875.829956,0.105185,0.000000
135.110001,61.854424,-875.963379,-0.000190,0.004154,0.105506,275.142212,14.016413,1.055062,-875.963379,0.104580,0.000000
135.470001,60.157150,-875.918884,-0.000203,0.004130,0.104908,267.592377,13.631805,1.049082,-875.918884,0.103980,0.000000
135.830002,58.583870,-875.918884,-0.000181,0.004108,0.104336,260.594055,13.275294,1.043359,-875.918884,0.103382,0.000000
136.190002,57.374779,-875.918884,-0.000177,0.004094,0.103998,255.215759,13.001310,1.039983,-875.918884,0.102784,0.000000
136.550003,54.810997,-875.963379,-0.000190,0.004062,0.103182,243.811493,12.420349,1.031823,-875.963379,0.102186,0.000000
136.910004,52.449783,-876.007874,-0.000198,0.004039,0.102584,233.308289,11.885290,1.025843,-876.007874,0.101587,0.000000
137.270004,49.964195,-875.918884,-0.000185,0.004014,0.101961,222.251846,11.322048,1.019605,-875.918884,0.100979,0.000000
137.630005,47.510635,-875.963379,-0.000190,0.003991,0.101370,211.337860,10.766064,1.013701,-875.963379,0.100381,0.000000
137.990005,44.972168,-876.007874,-0.000185,0.003969,0.100807,200.046188,10.190840,1.008069,-876.007874,0.099783,0.000000
138.350006,42.560310,-876.007874,-0.000185,0.003946,0.100226,189.317719,9.644304,1.002255,-876.007874,0.099185,0.000000
138.710007,39.864334,-876.052307,-0.000181,0.003923,0.099644,177.325409,9.033387,0.996442,-876.052307,0.098586,0.000000
139.070007,37.728783,-876.007874,-0.000181,0.003903,0.099132,167.826004,8.549464,0.991325,-876.007874,0.097979,0.000000
139.430008,34.928909,-876.007874,-0.000172,0.003879,0.098516,155.371552,7.915004,0.985163,-876.007874,0.097381,0.000000
139.790009,32.343529,-876.096802,-0.000177,0.003852,0.097849,143.871201,7.329149,0.978486,-876.096802,0.096783,0.000000
140.150009,30.165154,-876.007874,-0.000198,0.003836,0.097441,134.181305,6.835522,0.974414,-876.007874,0.096185,0.000000
140.510010,27.082283,-876.052307,-0.000190,0.003806,0.096678,120.468010,6.136933,0.966783,-876.052307,0.095585,0.000000
140.870010,24.756073,-876.052307,-0.000194,0.003786,0.096176,110.120514,5.609807,0.961757,-876.052307,0.094978,0.000000
141.230011,22.525932,-876.007874,-0.000181,0.003766,0.095655,100.200348,5.104449,0.956549,-876.007874,0.094380,0.000000
141.590012,19.581955,-876.141296,-0.000220,0.003738,0.094943,87.104889,4.437335,0.949433,-876.141296,0.093782,0.000000
141.950012,17.203613,-876.096802,-0.000203,0.003717,0.094415,76.525497,3.898395,0.944150,-876.096802,0.093184,0.000000
142.310013,13.817627,-876.096802,-0.000203,0.003685,0.093591,61.463875,3.131119,0.935914,-876.096802,0.092585,0.000000
142.670013,11.295174,-876.096802,-0.000207,0.003663,0.093028,50.243443,2.559523,0.930282,-876.096802,0.091977,0.000000
143.030014,9.324585,-876.096802,-0.000211,0.003642,0.092516,41.477825,2.112981,0.925165,-876.096802,0.091379,0.000000
143.389999,7.071732,-876.185791,-0.000220,0.003616,0.091856,31.456633,1.602477,0.918564,-876.185791,0.090781,0.000000
143.750000,4.106529,-876.141296,-0.000220,0.003592,0.091233,18.266754,0.930553,0.912326,-876.141296,0.090183,0.000000
144.110001,1.688713,-876.141296,-0.000224,0.003572,0.090721,7.511771,0.382668,0.907209,-876.141296,0.089584,0.000000
144.470001,-0.944706,-876.096802,-0.000237,0.003543,0.090000,-4.202262,-0.214073,0.900003,-876.096802,0.088986,0.000000
144.830002,-2.599529,-876.185791,-0.000220,0.003526,0.089558,-11.563284,-0.589062,0.895582,-876.185791,0.088379,0.000000
145.190002,-0.353004,-876.230225,-0.000289,0.003502,0.088951,-1.570242,-0.079992,0.889511,-876.230225,0.087781,0.000000
145.550003,-0.212997,-876.141296,-0.000336,0.003478,0.088344,-0.947460,-0.048266,0.883440,-876.141296,0.087183,0.000000
145.910004,-0.162354,-876.230225,-0.000375,0.003451,0.087660,-0.722184,-0.036790,0.876597,-876.230225,0.086583,0.000000
146.270004,-0.038727,-876.185791,-0.000423,0.003420,0.086878,-0.172265,-0.008776,0.868785,-876.185791,0.085985,0.000000
146.630005,-0.025314,-876.185791,-0.000470,0.003403,0.086436,-0.112604,-0.005736,0.864364,-876.185791,0.085378,0.000000
146.990005,0.021973,-876.185791,-0.000504,0.003386,0.085994,0.097739,0.004979,0.859943,-876.185791,0.084780,0.000000
147.350006,0.102776,-876.274719,-0.000586,0.003352,0.085153,0.457169,0.023289,0.851526,-876.274719,0.085050,0.000000
147.500000,0.121773,-876.230225,-0.000604,0.003353,0.085162,0.541672,0.027594,0.851617,-876.230225,0.085050,0.000000