File: Data/compression 13/AutoNoHeating-15-13-3-240724_07242024_170026.csv
Time (sec),S:Load (lbs),S:HL1 (DIM),S:LVDT (in),S:Position (in),Ch:Position (mm),Ch:Load (N),Ch:Stress (MPa),Ch:Strain (mm/mm),Ch:HL1 (DIM),Set Point (),Cycles ()
0.110000,-0.021599,-362.074951,-0.010675,-0.005859,-0.148807,-0.096076,-0.004894,-1.488073,-362.074951,-0.148590,0.000000
0.340000,-0.023087,-362.074951,-0.010710,-0.005859,-0.148807,-0.102694,-0.005231,-1.488073,-362.074951,-0.148590,0.000000
0.570000,-0.000374,-362.119415,-0.010680,-0.005774,-0.146665,-0.001663,-0.000085,-1.466651,-362.119415,-0.146075,0.000000
0.800000,-0.020851,-362.163910,-0.010606,-0.005645,-0.143378,-0.092750,-0.004725,-1.433783,-362.163910,-0.142242,0.000000
1.030000,-0.073357,-362.163910,-0.010477,-0.005499,-0.139684,-0.326307,-0.016623,-1.396842,-362.163910,-0.138409,0.000000
1.260000,-0.057343,-362.119415,-0.010317,-0.005346,-0.135790,-0.255072,-0.012994,-1.357903,-362.119415,-0.134576,0.000000
1.490000,-0.000000,-362.208374,-0.010149,-0.005191,-0.131853,-0.000000,-0.000000,-1.318529,-362.208374,-0.130743,0.000000
1.720000,0.008942,-362.208374,-0.009990,-0.005047,-0.128202,0.039774,0.002026,-1.282020,-362.208374,-0.126910,0.000000
1.950000,0.013031,-362.252869,-0.009822,-0.004883,-0.124031,0.057965,0.002953,-1.240306,-362.252869,-0.123077,0.000000
2.180000,-0.012657,-362.252869,-0.009666,-0.004745,-0.120527,-0.056302,-0.002868,-1.205270,-362.252869,-0.119243,0.000000
2.410000,-0.003349,-362.208374,-0.009494,-0.004591,-0.116616,-0.014898,-0.000759,-1.166160,-362.208374,-0.115411,0.000000
2.640000,-0.012283,-362.208374,-0.009360,-0.004439,-0.112748,-0.054639,-0.002783,-1.127479,-362.208374,-0.111577,0.000000
2.870000,-0.003349,-362.252869,-0.009214,-0.004295,-0.109088,-0.014898,-0.000759,-1.090882,-362.252869,-0.107744,0.000000
3.100000,-0.040588,-362.341827,-0.009028,-0.004130,-0.104908,-0.180546,-0.009197,-1.049082,-362.341827,-0.103911,0.000000
3.330000,-0.051010,-362.341827,-0.008873,-0.003985,-0.101222,-0.226904,-0.011559,-1.012225,-362.341827,-0.100095,0.000000
3.560000,-0.042450,-362.297333,-0.008718,-0.003837,-0.097459,-0.188827,-0.009619,-0.974588,-362.297333,-0.096262,0.000000
3.790000,-0.015266,-362.341827,-0.008541,-0.003679,-0.093435,-0.067908,-0.003459,-0.934351,-362.341827,-0.092429,0.000000
4.020000,0.023460,-362.297333,-0.008407,-0.003536,-0.089819,0.104357,0.005316,-0.898186,-362.297333,-0.088596,0.000000
4.250000,0.027557,-362.386322,-0.008252,-0.003389,-0.086072,0.122581,0.006245,-0.860723,-362.386322,-0.084763,0.000000
4.480000,0.025696,-362.386322,-0.008075,-0.003229,-0.082013,0.114301,0.005823,-0.820134,-362.386322,-0.080929,0.000000
4.710000,-0.020103,-362.475281,-0.007912,-0.003081,-0.078250,-0.089425,-0.004556,-0.782497,-362.475281,-0.077096,0.000000
4.940000,-0.024574,-362.475281,-0.007769,-0.002934,-0.074521,-0.109312,-0.005569,-0.745208,-362.475281,-0.073263,0.000000
5.170000,-0.018616,-362.386322,-0.007623,-0.002781,-0.070627,-0.082807,-0.004218,-0.706269,-362.386322,-0.069430,0.000000
5.400000,0.005959,-362.430786,-0.007459,-0.002633,-0.066872,0.026505,0.001350,-0.668715,-362.430786,-0.065597,0.000000
5.630000,-0.009682,-362.475281,-0.007269,-0.002466,-0.062648,-0.043066,-0.002194,-0.626483,-362.475281,-0.061764,0.000000
5.860000,-0.000374,-362.430786,-0.007118,-0.002328,-0.059119,-0.001663,-0.000085,-0.591185,-362.430786,-0.057931,0.000000
6.090000,-0.006332,-362.475281,-0.006967,-0.002176,-0.055277,-0.028168,-0.001435,-0.552769,-362.475281,-0.054115,0.000000
6.320000,0.013779,-362.430786,-0.006825,-0.002022,-0.051348,0.061291,0.003122,-0.513482,-362.430786,-0.050282,0.000000
6.550000,0.021225,-362.519745,-0.006683,-0.001884,-0.047862,0.094413,0.004810,-0.478623,-362.519745,-0.046449,0.000000
6.780000,0.011543,-362.564240,-0.006536,-0.001729,-0.043925,0.051347,0.002616,-0.439252,-362.564240,-0.042616,0.000000
7.010000,-0.016754,-362.564240,-0.006377,-0.001569,-0.039849,-0.074526,-0.003797,-0.398489,-362.564240,-0.038782,0.000000
7.240000,-0.032021,-362.475281,-0.006234,-0.001425,-0.036190,-0.142435,-0.007256,-0.361897,-362.475281,-0.034949,0.000000
7.470000,-0.010056,-362.608704,-0.006036,-0.001268,-0.032218,-0.044729,-0.002279,-0.322178,-362.608704,-0.031116,0.000000
7.700000,-0.009308,-362.608704,-0.005885,-0.001124,-0.028549,-0.041403,-0.002109,-0.285487,-362.608704,-0.027283,0.000000
7.930000,0.025696,-362.653198,-0.005743,-0.000968,-0.024577,0.114301,0.005823,-0.245768,-362.653198,-0.023450,0.000000
8.160001,0.028305,-362.697662,-0.005575,-0.000814,-0.020675,0.125907,0.006414,-0.206746,-362.697662,-0.019616,0.000000
8.390000,0.004845,-362.564240,-0.005415,-0.000668,-0.016971,0.021550,0.001098,-0.169715,-362.564240,-0.015784,0.000000
8.620001,0.009308,-362.608704,-0.005282,-0.000520,-0.013199,0.041403,0.002109,-0.131994,-362.608704,-0.011950,0.000000
8.850000,0.032768,-362.697662,-0.005096,-0.000364,-0.009245,0.145760,0.007425,-0.092450,-362.697662,-0.008117,0.000000
9.080001,0.036118,-362.697662,-0.004954,-0.000220,-0.005585,0.160659,0.008184,-0.055850,-362.697662,-0.004301,0.000000
9.310000,0.180603,-362.742157,-0.004825,-0.000067,-0.001691,0.803362,0.040925,-0.016911,-362.742157,-0.000469,0.000000
9.540001,0.725014,-362.742157,-0.004708,0.000020,0.000512,3.225022,0.164290,0.005117,-362.742157,0.000728,0.000000
9.770000,0.689636,-362.742157,-0.004695,0.000020,0.000512,3.067655,0.156274,0.005117,-362.742157,0.000728,0.000000
10.000000,0.675484,-362.786652,-0.004708,0.000020,0.000512,3.004702,0.153067,0.005117,-362.786652,0.000790,0.000000
10.230000,0.660591,-362.786652,-0.004712,0.000020,0.000512,2.938456,0.149692,0.005117,-362.786652,0.001171,0.000000
10.460000,0.626335,-362.831116,-0.004704,0.000021,0.000521,2.786078,0.141930,0.005208,-362.831116,0.001553,0.000000
10.690001,0.839699,-362.786652,-0.004691,0.000039,0.000998,3.735167,0.190278,0.009977,-362.786652,0.001942,0.000000
10.920000,0.992744,-362.786652,-0.004695,0.000057,0.001457,4.415948,0.224959,0.014572,-362.786652,0.002324,0.000000
11.150001,1.155472,-362.786652,-0.004695,0.000073,0.001856,5.139795,0.261834,0.018561,-362.786652,0.002706,0.000000
11.380000,1.253410,-362.831116,-0.004656,0.000083,0.002116,5.575448,0.284027,0.021158,-362.831116,0.003088,0.000000
11.610001,1.371078,-362.831116,-0.004665,0.000096,0.002446,6.098862,0.310691,0.024458,-362.831116,0.003469,0.000000
11.840000,1.526726,-362.831116,-0.004661,0.000110,0.002784,6.791215,0.345961,0.027842,-362.831116,0.003859,0.000000
12.070001,1.849945,-362.831116,-0.004626,0.000129,0.003278,8.228967,0.419204,0.032785,-362.831116,0.004241,0.000000
12.300000,2.004478,-362.831116,-0.004635,0.000141,0.003573,8.916366,0.454221,0.035729,-362.831116,0.004622,0.000000
12.530001,2.169067,-362.920074,-0.004613,0.000154,0.003903,9.648494,0.491518,0.039030,-362.920074,0.005004,0.000000
12.760000,2.716087,-362.964569,-0.004587,0.000182,0.004622,12.081759,0.615474,0.046221,-362.964569,0.005386,0.000000
12.990001,2.940628,-362.875610,-0.004575,0.000198,0.005038,13.080566,0.666356,0.050385,-362.875610,0.005776,0.000000
13.220000,3.090317,-362.964569,-0.004566,0.000208,0.005281,13.746415,0.700276,0.052814,-362.964569,0.006157,0.000000
13.450001,3.249695,-362.920074,-0.004536,0.000220,0.005585,14.455364,0.736391,0.055850,-362.920074,0.006539,0.000000
13.680000,3.646271,-362.964569,-0.004544,0.000235,0.005976,16.219423,0.826257,0.059756,-362.964569,0.006920,0.000000
13.910001,3.733406,-363.097992,-0.004523,0.000247,0.006279,16.607019,0.846002,0.062791,-363.097992,0.007302,0.000000
14.140000,4.302765,-363.053528,-0.004501,0.000267,0.006773,19.139654,0.975020,0.067734,-363.053528,0.007692,0.000000
14.370001,4.356018,-363.053528,-0.004510,0.000275,0.006982,19.376535,0.987088,0.069816,-363.053528,0.008074,0.000000
14.600000,4.624870,-363.053528,-0.004514,0.000286,0.007276,20.572451,1.048011,0.072761,-363.053528,0.008455,0.000000
14.830001,5.431053,-363.053528,-0.004449,0.000319,0.008109,24.158531,1.230694,0.081088,-363.053528,0.008837,0.000000
15.060000,5.528244,-363.142487,-0.004454,0.000332,0.008421,24.590858,1.252718,0.084206,-363.142487,0.009218,0.000000
15.290001,5.694695,-363.097992,-0.004471,0.000341,0.008673,25.331266,1.290436,0.086727,-363.097992,0.009609,0.000000
15.520000,5.987007,-363.053528,-0.004428,0.000356,0.009054,26.631538,1.356675,0.090542,-363.053528,0.009991,0.000000
15.750001,6.191811,-363.097992,-0.004419,0.000367,0.009314,27.542549,1.403084,0.093139,-363.097992,0.010372,0.000000
15.980000,6.825218,-363.142487,-0.004389,0.000387,0.009835,30.360086,1.546617,0.098347,-363.142487,0.010754,0.000000
16.210001,7.038216,-363.186951,-0.004385,0.000402,0.010199,31.307547,1.594882,0.101988,-363.186951,0.011135,0.000000
16.440001,7.304085,-363.231445,-0.004372,0.000414,0.010511,32.490192,1.655129,0.105107,-363.231445,0.011526,0.000000
16.670000,7.640709,-363.186951,-0.004368,0.000431,0.010944,33.987572,1.731409,0.109444,-363.186951,0.011907,0.000000
16.900002,8.262199,-363.231445,-0.004359,0.000452,0.011474,36.752098,1.872241,0.114735,-363.231445,0.012289,0.000000
17.130001,8.303535,-363.231445,-0.004329,0.000463,0.011751,36.935970,1.881608,0.117513,-363.231445,0.012670,0.000000
17.360001,8.537010,-363.231445,-0.004307,0.000476,0.012098,37.974518,1.934514,0.120980,-363.231445,0.013060,0.000000
17.590000,8.906776,-363.275940,-0.004303,0.000491,0.012470,39.619320,2.018304,0.124705,-363.275940,0.013442,0.000000
17.820002,9.440392,-363.275940,-0.004329,0.000512,0.013000,41.992958,2.139223,0.129996,-363.275940,0.013824,0.000000
18.050001,9.645569,-363.320404,-0.004299,0.000526,0.013355,42.905632,2.185717,0.133554,-363.320404,0.014205,0.000000
18.280001,9.762115,-363.231445,-0.004281,0.000536,0.013624,43.424057,2.212127,0.136241,-363.231445,0.014587,0.000000
18.510000,9.957985,-363.320404,-0.004255,0.000548,0.013928,44.295330,2.256512,0.139277,-363.320404,0.014977,0.000000
18.740002,10.488243,-363.409363,-0.004230,0.000566,0.014379,46.654034,2.376670,0.143788,-363.409363,0.015358,0.000000
18.970001,10.944771,-363.364899,-0.004221,0.000586,0.014881,48.684772,2.480121,0.148814,-363.364899,0.015740,0.000000
19.200001,11.017387,-363.364899,-0.004225,0.000598,0.015185,49.007786,2.496576,0.151850,-363.364899,0.016122,0.000000
19.430000,11.351402,-363.320404,-0.004217,0.000612,0.015549,50.493561,2.572264,0.155491,-363.320404,0.016504,0.000000
19.660002,11.577431,-363.364899,-0.004195,0.000627,0.015922,51.498985,2.623483,0.159223,-363.364899,0.016894,0.000000
19.890001,11.970284,-363.409363,-0.004165,0.000642,0.016313,53.246479,2.712505,0.163129,-363.409363,0.017275,0.000000
20.120001,12.233551,-363.453857,-0.004152,0.000657,0.016685,54.417553,2.772162,0.166853,-363.453857,0.017657,0.000000
20.350000,12.236160,-363.409363,-0.004135,0.000668,0.016963,54.429161,2.772753,0.169631,-363.409363,0.018038,0.000000
20.580002,13.175285,-363.453857,-0.004152,0.000694,0.017622,58.606598,2.985562,0.176225,-363.453857,0.018420,0.000000
20.810001,13.435570,-363.409363,-0.004096,0.000711,0.018055,59.764400,3.044544,0.180555,-363.409363,0.018810,0.000000
21.040001,13.383438,-363.542816,-0.004087,0.000720,0.018298,59.532505,3.032730,0.182985,-363.542816,0.019192,0.000000
21.270000,13.400566,-363.587280,-0.004083,0.000732,0.018602,59.608696,3.036612,0.186020,-363.587280,0.019573,0.000000
21.500002,13.871246,-363.498322,-0.004066,0.000748,0.019010,61.702385,3.143269,0.190100,-363.498322,0.019955,0.000000
21.730001,14.339691,-363.542816,-0.004070,0.000766,0.019452,63.786133,3.249420,0.194521,-363.542816,0.020336,0.000000
21.960001,14.513222,-363.542816,-0.004040,0.000779,0.019781,64.558037,3.288743,0.197814,-363.542816,0.020727,0.000000
22.190001,14.476357,-363.542816,-0.004023,0.000788,0.020024,64.394051,3.280389,0.200244,-363.542816,0.021108,0.000000
22.420002,14.740364,-363.631775,-0.004044,0.000801,0.020345,65.568413,3.340214,0.203453,-363.631775,0.021490,0.000000
22.650002,15.721191,-363.542816,-0.004027,0.000828,0.021030,69.931351,3.562473,0.210304,-363.542816,0.021871,0.000000
22.880001,15.655655,-363.587280,-0.004018,0.000840,0.021325,69.639832,3.547622,0.213249,-363.587280,0.022253,0.000000
23.110001,15.642250,-363.587280,-0.003975,0.000850,0.021585,69.580200,3.544585,0.215853,-363.587280,0.022644,0.000000
23.340002,15.787849,-363.676270,-0.003971,0.000863,0.021924,70.227859,3.577578,0.219236,-363.676270,0.023025,0.000000
23.570002,16.251083,-363.676270,-0.003958,0.000879,0.022331,72.288429,3.682548,0.223309,-363.676270,0.023407,0.000000
23.800001,16.754524,-363.676270,-0.003958,0.000899,0.022834,74.527847,3.796629,0.228343,-363.676270,0.023788,0.000000
24.030001,16.632019,-363.676270,-0.003919,0.000909,0.023077,73.982918,3.768869,0.230773,-363.676270,0.024170,0.000000
24.260000,16.603348,-363.676270,-0.003923,0.000917,0.023302,73.855377,3.762372,0.233021,-363.676270,0.024560,0.000000
24.490002,17.211800,-363.676270,-0.003902,0.000938,0.023823,76.561905,3.900250,0.238229,-363.676270,0.024942,0.000000
24.720001,17.841484,-363.765228,-0.003885,0.000959,0.024352,79.362885,4.042938,0.243520,-363.765228,0.025323,0.000000
24.950001,17.711525,-363.765228,-0.003863,0.000970,0.024646,78.784798,4.013489,0.246465,-363.765228,0.025705,0.000000
25.180000,18.045174,-363.765228,-0.003854,0.000987,0.025072,80.268944,4.089095,0.250719,-363.765228,0.026086,0.000000
25.410002,18.299873,-363.720734,-0.003829,0.001002,0.025444,81.401901,4.146811,0.254443,-363.720734,0.026477,0.000000
25.640001,18.709480,-363.765228,-0.003816,0.001021,0.025939,83.223923,4.239629,0.259386,-363.765228,0.026858,0.000000
25.870001,18.877426,-363.898651,-0.003803,0.001036,0.026312,83.970985,4.277686,0.263118,-363.898651,0.027240,0.000000
26.100000,18.722145,-363.854187,-0.003807,0.001044,0.026520,83.280258,4.242499,0.265200,-363.854187,0.027621,0.000000
26.330002,18.936630,-363.854187,-0.003786,0.001057,0.026858,84.234337,4.291102,0.268584,-363.854187,0.028011,0.000000
26.560001,19.924538,-363.854187,-0.003747,0.001083,0.027517,88.628769,4.514965,0.275169,-363.854187,0.028393,0.000000
26.790001,19.882088,-363.898651,-0.003764,0.001095,0.027803,88.439941,4.505345,0.278031,-363.898651,0.028774,0.000000
27.020000,19.690681,-363.943146,-0.003729,0.001105,0.028055,87.588524,4.461972,0.280552,-363.943146,0.029157,0.000000
27.250002,20.103645,-363.987610,-0.003717,0.001123,0.028515,89.425484,4.555551,0.285146,-363.987610,0.029538,0.000000
27.480001,20.487930,-363.898651,-0.003704,0.001140,0.028966,91.134865,4.642631,0.289658,-363.898651,0.029928,0.000000
27.710001,20.511765,-363.898651,-0.003699,0.001152,0.029269,91.240883,4.648032,0.292686,-363.898651,0.030309,0.000000
27.940001,20.658852,-363.898651,-0.003682,0.001165,0.029599,91.895164,4.681363,0.295986,-363.898651,0.030691,0.000000
28.170002,20.938507,-364.032104,-0.003660,0.001180,0.029963,93.139130,4.744734,0.299627,-364.032104,0.031072,0.000000
28.400002,21.502274,-364.032104,-0.003660,0.001199,0.030465,95.646889,4.872485,0.304654,-364.032104,0.031455,0.000000
28.630001,21.907417,-364.032104,-0.003639,0.001218,0.030943,97.449059,4.964292,0.309430,-364.032104,0.031845,0.000000
28.860001,21.701126,-364.032104,-0.003604,0.001229,0.031212,96.531433,4.917545,0.312118,-364.032104,0.032226,0.000000
29.090002,21.854912,-364.032104,-0.003600,0.001245,0.031611,97.215500,4.952394,0.316107,-364.032104,0.032608,0.000000
29.320002,21.972580,-364.076599,-0.003583,0.001256,0.031905,97.738914,4.979058,0.319052,-364.076599,0.032989,0.000000
29.550001,22.115204,-364.076599,-0.003583,0.001271,0.032296,98.373337,5.011377,0.322958,-364.076599,0.033371,0.000000
29.780001,22.200478,-364.076599,-0.003574,0.001280,0.032521,98.752655,5.030700,0.325213,-364.076599,0.033761,0.000000
30.010002,22.509544,-364.076599,-0.003557,0.001295,0.032894,100.127457,5.100736,0.328938,-364.076599,0.034143,0.000000
30.240002,22.929955,-364.076599,-0.003544,0.001314,0.033388,101.997528,5.196002,0.333881,-364.076599,0.034524,0.000000
30.470001,23.446434,-364.121063,-0.003523,0.001336,0.033935,104.294945,5.313038,0.339346,-364.121063,0.034906,0.000000
30.700001,23.762207,-364.254517,-0.003531,0.001350,0.034299,105.699577,5.384593,0.342987,-364.254517,0.035287,0.000000
30.930002,23.459465,-364.210022,-0.003492,0.001359,0.034507,104.352913,5.315990,0.345069,-364.210022,0.035678,0.000000
31.160002,23.840775,-364.210022,-0.003497,0.001379,0.035036,106.049065,5.402397,0.350360,-364.210022,0.036059,0.000000
31.390001,23.895889,-364.165558,-0.003454,0.001390,0.035314,106.294228,5.414886,0.353138,-364.165558,0.036441,0.000000
31.620001,24.083565,-364.254517,-0.003441,0.001403,0.035626,107.129044,5.457414,0.356257,-364.254517,0.036822,0.000000
31.850002,24.876717,-364.254517,-0.003428,0.001426,0.036233,110.657166,5.637145,0.362328,-364.254517,0.037204,0.000000
32.080002,25.018219,-364.254517,-0.003419,0.001446,0.036719,111.286598,5.669209,0.367188,-364.254517,0.037595,0.000000
32.310001,25.350372,-364.298981,-0.003397,0.001462,0.037126,112.764091,5.744476,0.371260,-364.298981,0.037976,0.000000
32.540001,25.301224,-364.210022,-0.003380,0.001474,0.037430,112.545464,5.733339,0.374296,-364.210022,0.038358,0.000000
32.770000,25.072586,-364.254517,-0.003363,0.001484,0.037681,111.528435,5.681529,0.376809,-364.254517,0.038739,0.000000
33.000000,25.456871,-364.343475,-0.003367,0.001500,0.038106,113.237816,5.768610,0.381063,-364.343475,0.039121,0.000000
33.230003,25.632263,-364.343475,-0.003341,0.001513,0.038436,114.017998,5.808354,0.384356,-364.343475,0.039511,0.000000
33.460003,26.171082,-364.343475,-0.003320,0.001532,0.038913,116.414787,5.930451,0.389125,-364.343475,0.039893,0.000000
33.690002,26.098473,-364.387939,-0.003307,0.001541,0.039146,116.091805,5.913998,0.391464,-364.387939,0.040274,0.000000
33.920002,26.169968,-364.343475,-0.003281,0.001554,0.039459,116.409828,5.930200,0.394590,-364.343475,0.040656,0.000000
34.150002,27.685890,-364.387939,-0.003264,0.001585,0.040265,123.152992,6.273712,0.402652,-364.387939,0.041046,0.000000
34.380001,27.673981,-364.476898,-0.003277,0.001599,0.040612,123.100014,6.271014,0.406119,-364.476898,0.041427,0.000000
34.610001,27.321342,-364.432434,-0.003242,0.001609,0.040872,121.531403,6.191104,0.408723,-364.432434,0.041809,0.000000
34.840000,27.383530,-364.476898,-0.003221,0.001622,0.041211,121.808022,6.205196,0.412107,-364.476898,0.042191,0.000000
35.070004,27.378685,-364.476898,-0.003212,0.001634,0.041514,121.786476,6.204099,0.415142,-364.476898,0.042572,0.000000
35.300003,27.965546,-364.432434,-0.003212,0.001654,0.042017,124.396957,6.337083,0.420169,-364.432434,0.042962,0.000000
35.530003,28.110397,-364.565887,-0.003195,0.001667,0.042347,125.041290,6.369907,0.423469,-364.565887,0.043344,0.000000
35.760002,27.882133,-364.521393,-0.003182,0.001675,0.042555,124.025925,6.318182,0.425551,-364.521393,0.043725,0.000000
35.990002,28.320419,-364.521393,-0.003173,0.001695,0.043049,125.975517,6.417499,0.430494,-364.521393,0.044107,0.000000
36.220001,29.781609,-364.565887,-0.003134,0.001723,0.043760,132.475204,6.748609,0.437602,-364.565887,0.044488,0.000000
36.450001,29.506798,-364.521393,-0.003109,0.001734,0.044038,131.252792,6.686336,0.440380,-364.521393,0.044879,0.000000
36.680000,29.444611,-364.654846,-0.003113,0.001745,0.044332,130.976166,6.672244,0.443325,-364.654846,0.045261,0.000000
36.910000,29.551849,-364.610352,-0.003074,0.001759,0.044688,131.453186,6.696545,0.446883,-364.610352,0.045642,0.000000
37.140003,29.338486,-364.565887,-0.003109,0.001769,0.044922,130.504105,6.648196,0.449222,-364.565887,0.046024,0.000000
37.370003,30.439964,-364.610352,-0.003048,0.001792,0.045529,135.403717,6.897795,0.455293,-364.610352,0.046405,0.000000
37.600002,30.230690,-364.610352,-0.003035,0.001802,0.045772,134.472824,6.850372,0.457722,-364.610352,0.046796,0.000000
37.830002,30.298088,-364.654846,-0.003031,0.001815,0.046102,134.772629,6.865645,0.461015,-364.654846,0.047177,0.000000
38.060001,31.005219,-364.654846,-0.003031,0.001836,0.046622,137.918106,7.025883,0.466223,-364.654846,0.047559,0.000000
38.290001,31.455795,-364.654846,-0.002997,0.001854,0.047099,139.922363,7.127985,0.470992,-364.654846,0.047940,0.000000
38.520000,31.242050,-364.699310,-0.002984,0.001863,0.047325,138.971573,7.079550,0.473248,-364.699310,0.048322,0.000000
38.750000,31.532501,-364.699310,-0.002992,0.001879,0.047715,140.263565,7.145367,0.477147,-364.699310,0.048712,0.000000
38.980003,31.671768,-364.788269,-0.002979,0.001892,0.048062,140.883057,7.176925,0.480621,-364.788269,0.049094,0.000000
39.210003,32.565834,-364.788269,-0.002958,0.001914,0.048625,144.860062,7.379523,0.486253,-364.788269,0.049475,0.000000
39.440002,32.552429,-364.788269,-0.002936,0.001926,0.048929,144.800430,7.376486,0.489289,-364.788269,0.049857,0.000000
39.670002,32.384865,-364.788269,-0.002915,0.001937,0.049198,144.055069,7.338515,0.491976,-364.788269,0.050238,0.000000
39.900002,32.572540,-364.699310,-0.002902,0.001952,0.049571,144.889893,7.381043,0.495708,-364.699310,0.050629,0.000000
40.130001,33.465858,-364.832764,-0.002893,0.001973,0.050117,148.863571,7.583472,0.501173,-364.832764,0.051011,0.000000
40.360001,33.759285,-364.832764,-0.002850,0.001988,0.050499,150.168793,7.649963,0.504988,-364.832764,0.051392,0.000000
40.590000,33.708275,-364.788269,-0.002884,0.002000,0.050802,149.941895,7.638404,0.508024,-364.788269,0.051774,0.000000
40.820004,34.024788,-364.877228,-0.002850,0.002015,0.051192,151.349823,7.710127,0.511922,-364.877228,0.052155,0.000000
41.050003,34.426582,-364.832764,-0.002807,0.002031,0.051591,153.137085,7.801175,0.515911,-364.832764,0.052545,0.000000
41.280003,34.665268,-364.921722,-0.002811,0.002047,0.051999,154.198807,7.855262,0.519992,-364.921722,0.052927,0.000000
41.510002,34.673462,-364.966217,-0.002798,0.002059,0.052294,154.235260,7.857119,0.522936,-364.966217,0.053309,0.000000
41.740002,34.788528,-364.921722,-0.002768,0.002070,0.052580,154.747101,7.883193,0.525798,-364.921722,0.053690,0.000000
41.970001,36.244499,-364.877228,-0.002751,0.002098,0.053282,161.223587,8.213121,0.532822,-364.877228,0.054072,0.000000
42.200001,36.440369,-364.966217,-0.002759,0.002113,0.053664,162.094849,8.257505,0.536638,-364.966217,0.054462,0.000000
42.430000,36.081406,-364.966217,-0.002729,0.002122,0.053898,160.498108,8.176164,0.538984,-364.966217,0.054843,0.000000
42.660004,36.063156,-365.010681,-0.002734,0.002134,0.054202,160.416931,8.172029,0.542020,-365.010681,0.055225,0.000000
42.890003,36.339828,-365.010681,-0.002708,0.002147,0.054540,161.647629,8.234723,0.545396,-365.010681,0.055607,0.000000
43.120003,37.064095,-365.010681,-0.002699,0.002168,0.055060,164.869324,8.398845,0.550604,-365.010681,0.055997,0.000000
43.350002,37.198151,-365.010681,-0.002669,0.002180,0.055372,165.465637,8.429221,0.553723,-365.010681,0.056378,0.000000
43.580002,37.059998,-365.055176,-0.002652,0.002190,0.055624,164.851105,8.397916,0.556243,-365.055176,0.056760,0.000000
43.810001,37.465141,-365.099640,-0.002652,0.002207,0.056066,166.653275,8.489723,0.560664,-365.099640,0.057141,0.000000
44.040001,38.697693,-365.144135,-0.002621,0.002230,0.056630,172.135941,8.769023,0.566296,-365.144135,0.057523,0.000000
44.270000,38.660080,-365.099640,-0.002608,0.002241,0.056933,171.968628,8.760499,0.569331,-365.099640,0.057913,0.000000
44.500004,38.316010,-365.055176,-0.002613,0.002250,0.057159,170.438126,8.682532,0.571587,-365.055176,0.058295,0.000000
44.730003,38.611671,-365.144135,-0.002583,0.002269,0.057627,171.753296,8.749530,0.576273,-365.144135,0.058676,0.000000
44.960003,39.264069,-365.144135,-0.002561,0.002286,0.058069,174.655304,8.897366,0.580694,-365.144135,0.059058,0.000000
45.190002,39.879601,-365.188599,-0.002552,0.002301,0.058433,177.393326,9.036847,0.584335,-365.188599,0.059440,0.000000
45.420002,39.515793,-365.144135,-0.002552,0.002310,0.058686,175.775024,8.954407,0.586856,-365.144135,0.059830,0.000000
45.650002,39.307266,-365.144135,-0.002531,0.002319,0.058910,174.847458,8.907154,0.589104,-365.144135,0.060212,0.000000
45.880001,40.812019,-365.188599,-0.002509,0.002347,0.059622,181.540924,9.248137,0.596219,-365.188599,0.060593,0.000000
46.110001,41.581345,-365.188599,-0.002514,0.002363,0.060021,184.963058,9.422467,0.600209,-365.188599,0.060975,0.000000
46.340004,41.331108,-365.233093,-0.002492,0.002372,0.060255,183.849945,9.365764,0.602548,-365.233093,0.061356,0.000000
46.570004,41.854668,-365.188599,-0.002458,0.002392,0.060749,186.178864,9.484404,0.607491,-365.188599,0.061747,0.000000
46.800003,41.991699,-365.322052,-0.002449,0.002404,0.061053,186.788406,9.515455,0.610526,-365.322052,0.062128,0.000000
47.030003,42.684311,-365.277557,-0.002432,0.002422,0.061521,189.869293,9.672403,0.615212,-365.277557,0.062510,0.000000
47.260002,42.950188,-365.322052,-0.002410,0.002435,0.061850,191.051971,9.732652,0.618505,-365.322052,0.062891,0.000000
47.490002,42.692131,-365.322052,-0.002402,0.002444,0.062076,189.904083,9.674175,0.620761,-365.322052,0.063273,0.000000
47.720001,42.866028,-365.366547,-0.002397,0.002458,0.062423,190.677612,9.713581,0.624228,-365.366547,0.063663,0.000000
47.950001,44.721931,-365.277557,-0.002393,0.002488,0.063195,198.933090,10.134134,0.631949,-365.277557,0.064045,0.000000
48.180004,44.290352,-365.322052,-0.002380,0.002497,0.063411,197.013321,10.036338,0.634114,-365.322052,0.064426,0.000000
48.410004,44.698845,-365.366547,-0.002350,0.002514,0.063854,198.830399,10.128902,0.638542,-365.366547,0.064808,0.000000
48.640003,44.903282,-365.411011,-0.002333,0.002528,0.064201,199.739777,10.175229,0.642009,-365.411011,0.065190,0.000000
48.870003,45.297623,-365.366547,-0.002328,0.002541,0.064548,201.493896,10.264587,0.645476,-365.366547,0.065579,0.000000
49.100002,45.590309,-365.322052,-0.002294,0.002555,0.064894,202.795822,10.330912,0.648943,-365.322052,0.065962,0.000000
49.330002,45.662918,-365.455505,-0.002272,0.002569,0.065250,203.118805,10.347364,0.652501,-365.455505,0.066343,0.000000
49.560001,46.050934,-365.366547,-0.002242,0.002583,0.065606,204.844788,10.435291,0.656059,-365.366547,0.066725,0.000000
49.790001,47.178101,-365.499969,-0.002238,0.002607,0.066230,209.858673,10.690710,0.662304,-365.499969,0.067106,0.000000
50.020004,47.649902,-365.499969,-0.002246,0.002620,0.066560,211.957352,10.797623,0.665596,-365.499969,0.067496,0.000000
50.250004,47.496483,-365.455505,-0.002207,0.002632,0.066846,211.274902,10.762856,0.668458,-365.455505,0.067878,0.000000
50.480003,47.666656,-365.499969,-0.002199,0.002645,0.067184,212.031876,10.801419,0.671842,-365.499969,0.068259,0.000000
50.710003,47.996208,-365.499969,-0.002177,0.002661,0.067583,213.497803,10.876096,0.675831,-365.499969,0.068641,0.000000
50.940002,48.319794,-365.544464,-0.002182,0.002673,0.067904,214.937180,10.949422,0.679040,-365.544464,0.069023,0.000000
51.170002,48.709671,-365.544464,-0.002182,0.002688,0.068286,216.671432,11.037769,0.682856,-365.544464,0.069413,0.000000
51.400002,48.949852,-365.544464,-0.002134,0.002701,0.068597,217.739822,11.092195,0.685974,-365.544464,0.069794,0.000000
51.630001,49.527031,-365.544464,-0.002147,0.002719,0.069066,220.307236,11.222986,0.690660,-365.544464,0.070176,0.000000
51.860001,50.919327,-365.588928,-0.002082,0.002743,0.069681,226.500473,11.538485,0.696814,-365.588928,0.070557,0.000000
52.090004,50.878365,-365.633423,-0.002108,0.002755,0.069985,226.318268,11.529202,0.699850,-365.633423,0.070948,0.000000
52.320004,50.846718,-365.722382,-0.002082,0.002765,0.070237,226.177490,11.522031,0.702371,-365.722382,0.071329,0.000000
52.550003,51.068649,-365.633423,-0.002044,0.002780,0.070609,227.164703,11.572321,0.706095,-365.633423,0.071711,0.000000
52.780003,51.714714,-365.633423,-0.002044,0.002797,0.071043,230.038544,11.718721,0.710432,-365.633423,0.072092,0.000000
53.010002,51.856964,-365.633423,-0.002026,0.002813,0.071460,230.671295,11.750957,0.714596,-365.633423,0.072474,0.000000
53.240002,52.745445,-365.722382,-0.001996,0.002829,0.071867,234.623459,11.952289,0.718668,-365.722382,0.072865,0.000000
53.470001,53.552376,-365.722382,-0.002005,0.002849,0.072370,238.212860,12.135142,0.723702,-365.722382,0.073246,0.000000
53.700001,54.011513,-365.766846,-0.001962,0.002865,0.072760,240.255203,12.239183,0.727601,-365.766846,0.073628,0.000000
53.930004,53.866287,-365.722382,-0.001940,0.002874,0.072995,239.609207,12.206275,0.729947,-365.722382,0.074009,0.000000
54.160004,53.639511,-365.766846,-0.001936,0.002885,0.073289,238.600464,12.154886,0.732892,-365.766846,0.074391,0.000000
54.390003,54.123222,-365.811340,-0.001936,0.002900,0.073653,240.752121,12.264498,0.736533,-365.811340,0.074781,0.000000
54.620003,54.492241,-365.766846,-0.001897,0.002913,0.074001,242.393600,12.348118,0.740008,-365.766846,0.075163,0.000000
54.850002,55.339020,-365.811340,-0.001901,0.002935,0.074556,246.160248,12.540001,0.745556,-365.811340,0.075544,0.000000
55.080002,55.055641,-365.766846,-0.001880,0.002943,0.074755,244.899719,12.475787,0.747547,-365.766846,0.075926,0.000000
55.310001,55.333435,-365.811340,-0.001863,0.002959,0.075163,246.135406,12.538735,0.751627,-365.811340,0.076307,0.000000
55.540001,57.474945,-365.900299,-0.001837,0.002988,0.075891,255.661331,13.024009,0.758909,-365.900299,0.076698,0.000000
55.770004,57.630226,-365.855835,-0.001828,0.003002,0.076255,256.352051,13.059196,0.762550,-365.855835,0.077079,0.000000
56.000004,57.338287,-365.900299,-0.001802,0.003009,0.076428,255.053436,12.993042,0.764284,-365.900299,0.077461,0.000000
56.230003,57.441803,-365.855835,-0.001798,0.003025,0.076845,255.513901,13.016499,0.768447,-365.855835,0.077842,0.000000
56.460003,57.610863,-365.855835,-0.001742,0.003037,0.077140,256.265930,13.054808,0.771399,-365.855835,0.078224,0.000000
56.690002,58.304222,-365.900299,-0.001755,0.003055,0.077608,259.350128,13.211926,0.776078,-365.900299,0.078614,0.000000
56.920002,58.497482,-365.944794,-0.001712,0.003068,0.077938,260.209808,13.255718,0.779378,-365.944794,0.078996,0.000000
57.150002,58.462852,-365.944794,-0.001707,0.003080,0.078232,260.055756,13.247872,0.782323,-365.944794,0.079378,0.000000
57.380001,59.270157,-365.989258,-0.001686,0.003102,0.078796,263.646820,13.430809,0.787962,-365.989258,0.079759,0.000000
57.610004,60.797997,-365.989258,-0.001651,0.003124,0.079360,270.442993,13.777023,0.793602,-365.989258,0.080141,0.000000
57.840004,60.573456,-365.989258,-0.001651,0.003134,0.079611,269.444183,13.726141,0.796115,-365.989258,0.080530,0.000000
58.070004,60.355621,-366.078217,-0.001617,0.003146,0.079898,268.475220,13.676779,0.798976,-366.078217,0.080912,0.000000
58.300003,60.441635,-366.078217,-0.001630,0.003158,0.080209,268.857819,13.696271,0.802095,-366.078217,0.081293,0.000000
58.530003,60.617767,-366.078217,-0.001617,0.003175,0.080635,269.641296,13.736183,0.806349,-366.078217,0.081676,0.000000
58.760002,61.392303,-366.078217,-0.001569,0.003191,0.081051,273.086609,13.911695,0.810513,-366.078217,0.082057,0.000000
58.990002,61.720734,-366.078217,-0.001552,0.003207,0.081468,274.547546,13.986118,0.814676,-366.078217,0.082447,0.000000
59.220001,61.400124,-366.122711,-0.001544,0.003217,0.081719,273.121399,13.913466,0.817189,-366.122711,0.082829,0.000000
59.450005,62.319885,-366.167175,-0.001513,0.003239,0.082265,277.212708,14.121888,0.822654,-366.167175,0.083210,0.000000
59.680004,62.931694,-366.122711,-0.001513,0.003256,0.082698,279.934143,14.260526,0.826984,-366.122711,0.083592,0.000000
59.910004,62.642357,-366.122711,-0.001470,0.003267,0.082976,278.647125,14.194962,0.829763,-366.122711,0.083973,0.000000
60.140003,62.682571,-366.122711,-0.001444,0.003279,0.083288,278.825989,14.204073,0.832881,-366.122711,0.084364,0.000000
60.370003,62.869881,-366.211670,-0.001431,0.003295,0.083696,279.659210,14.246518,0.836961,-366.211670,0.084745,0.000000
60.600002,63.962784,-366.256165,-0.001418,0.003316,0.084225,284.520660,14.494174,0.842253,-366.256165,0.085127,0.000000
60.830002,63.884964,-366.256165,-0.001406,0.003327,0.084502,284.174500,14.476540,0.845023,-366.256165,0.085508,0.000000
61.060001,63.752396,-366.211670,-0.001350,0.003339,0.084823,283.584808,14.446500,0.848233,-366.211670,0.085899,0.000000
61.290005,64.013428,-366.256165,-0.001358,0.003355,0.085222,284.745941,14.505651,0.852222,-366.256165,0.086280,0.000000
61.520004,64.767487,-366.256165,-0.001328,0.003374,0.085699,288.100159,14.676522,0.856991,-366.256165,0.086662,0.000000
61.750004,65.131302,-366.256165,-0.001311,0.003389,0.086072,289.718506,14.758964,0.860723,-366.256165,0.087044,0.000000
61.980003,65.114532,-366.300629,-0.001285,0.003402,0.086419,289.643921,14.755164,0.864190,-366.300629,0.087425,0.000000
62.210003,65.430313,-366.300629,-0.001272,0.003415,0.086749,291.048584,14.826720,0.867490,-366.300629,0.087816,0.000000
62.440002,65.849609,-366.256165,-0.001242,0.003432,0.087182,292.913696,14.921734,0.871820,-366.256165,0.088197,0.000000
62.670002,66.183243,-366.389587,-0.001229,0.003446,0.087529,294.397766,14.997336,0.875295,-366.389587,0.088579,0.000000
62.900002,66.286026,-366.389587,-0.001220,0.003458,0.087833,294.854980,15.020628,0.878330,-366.389587,0.088960,0.000000
63.130005,66.319534,-366.389587,-0.001220,0.003470,0.088127,295.004028,15.028221,0.881275,-366.389587,0.089342,0.000000
63.360004,67.172272,-366.389587,-0.001168,0.003483,0.088457,298.797180,15.221455,0.884568,-366.389587,0.088674,0.000000
63.590004,65.852951,-366.345123,-0.001151,0.003482,0.088448,292.928558,14.922492,0.884485,-366.345123,0.088674,0.000000
63.820004,64.682953,-366.434082,-0.001155,0.003481,0.088423,287.724152,14.657367,0.884227,-366.434082,0.088448,0.000000
64.050003,63.610535,-366.434082,-0.001155,0.003481,0.088414,282.953796,14.414352,0.884136,-366.434082,0.088448,0.000000
64.280006,62.629326,-366.478546,-0.001138,0.003481,0.088405,278.589142,14.192008,0.884053,-366.478546,0.088448,0.000000
64.510002,61.721481,-366.478546,-0.001125,0.003481,0.088405,274.550873,13.986287,0.884053,-366.478546,0.088448,0.000000
64.740005,60.900772,-366.478546,-0.001095,0.003480,0.088396,270.900177,13.800312,0.883962,-366.478546,0.088448,0.000000
64.970001,60.151932,-366.478546,-0.001099,0.003480,0.088396,267.569153,13.630623,0.883962,-366.478546,0.088448,0.000000
65.200005,59.443306,-366.523041,-0.001082,0.003480,0.088396,264.417023,13.470045,0.883962,-366.523041,0.088448,0.000000
65.430000,58.795380,-366.478546,-0.001082,0.003480,0.088396,261.534912,13.323224,0.883962,-366.478546,0.088448,0.000000
65.660004,58.200699,-366.567505,-0.001087,0.003480,0.088396,258.889648,13.188467,0.883962,-366.567505,0.088448,0.000000
65.889999,57.651451,-366.567505,-0.001056,0.003480,0.088396,256.446472,13.064005,0.883962,-366.567505,0.088448,0.000000
66.120003,57.141670,-366.523041,-0.001026,0.003480,0.088396,254.178848,12.948488,0.883962,-366.523041,0.088448,0.000000
66.350006,56.675461,-366.612000,-0.001056,0.003480,0.088396,252.105042,12.842843,0.883962,-366.612000,0.088448,0.000000
66.580002,56.220795,-366.612000,-0.001039,0.003480,0.088396,250.082581,12.739815,0.883962,-366.612000,0.088448,0.000000
66.810005,55.802620,-366.612000,-0.001035,0.003480,0.088396,248.222458,12.645055,0.883962,-366.612000,0.088448,0.000000
67.040001,55.416100,-366.612000,-0.001035,0.003480,0.088396,246.503128,12.557468,0.883962,-366.612000,0.088448,0.000000
67.270004,55.063461,-366.612000,-0.001039,0.003480,0.088396,244.934509,12.477559,0.883962,-366.612000,0.088448,0.000000
67.500000,54.707474,-366.700958,-0.001026,0.003480,0.088396,243.350998,12.396891,0.883962,-366.700958,0.088448,0.000000
67.730003,54.397659,-366.700958,-0.001005,0.003480,0.088396,241.972870,12.326686,0.883962,-366.700958,0.088448,0.000000
67.960007,54.090454,-366.700958,-0.001018,0.003480,0.088396,240.606354,12.257072,0.883962,-366.700958,0.088448,0.000000
68.190002,53.804474,-366.656494,-0.001022,0.003480,0.088396,239.334259,12.192268,0.883962,-366.656494,0.088448,0.000000
68.420006,53.532639,-366.745453,-0.001030,0.003480,0.088396,238.125076,12.130670,0.883962,-366.745453,0.088448,0.000000
68.650002,53.280540,-366.700958,-0.001000,0.003480,0.088396,237.003677,12.073544,0.883962,-366.700958,0.088448,0.000000
68.880005,53.039246,-366.834412,-0.001009,0.003480,0.088396,235.930344,12.018865,0.883962,-366.834412,0.088448,0.000000
69.110001,52.800179,-366.789917,-0.001018,0.003480,0.088396,234.866928,11.964691,0.883962,-366.789917,0.088448,0.000000
69.340004,52.576385,-366.789917,-0.001005,0.003480,0.088396,233.871445,11.913980,0.883962,-366.789917,0.088448,0.000000
69.570000,52.383499,-366.789917,-0.000983,0.003480,0.088396,233.013443,11.870271,0.883962,-366.789917,0.088448,0.000000
69.800003,52.165657,-366.834412,-0.000987,0.003480,0.088396,232.044434,11.820907,0.883962,-366.834412,0.088448,0.000000
70.030006,51.979843,-366.878876,-0.000987,0.003480,0.088396,231.217896,11.778801,0.883962,-366.878876,0.088448,0.000000
70.260002,51.799614,-366.878876,-0.001013,0.003480,0.088396,230.416183,11.737961,0.883962,-366.878876,0.088448,0.000000
70.490005,51.627953,-366.878876,-0.000996,0.003480,0.088396,229.652603,11.699061,0.883962,-366.878876,0.088448,0.000000
70.720001,51.456665,-366.834412,-0.000979,0.003480,0.088396,228.890671,11.660247,0.883962,-366.834412,0.088448,0.000000
70.950005,51.307716,-366.878876,-0.000987,0.003480,0.088396,228.228119,11.626495,0.883962,-366.878876,0.088448,0.000000
71.180000,51.147224,-366.967834,-0.001000,0.003480,0.088396,227.514221,11.590127,0.883962,-366.967834,0.088448,0.000000
71.410004,51.000137,-366.967834,-0.000992,0.003480,0.088396,226.859940,11.556796,0.883962,-366.967834,0.088448,0.000000
71.640007,50.854538,-366.923370,-0.000992,0.003480,0.088396,226.212280,11.523803,0.883962,-366.923370,0.088448,0.000000
71.870003,50.720108,-366.923370,-0.001000,0.003480,0.088396,225.614304,11.493341,0.883962,-366.923370,0.088448,0.000000
72.100006,50.583824,-367.012329,-0.001000,0.003480,0.088396,225.008087,11.462458,0.883962,-367.012329,0.088448,0.000000
72.330002,50.438225,-366.967834,-0.000979,0.003480,0.088396,224.360428,11.429465,0.883962,-366.967834,0.088448,0.000000
72.560005,50.319435,-366.967834,-0.000983,0.003480,0.088396,223.832031,11.402547,0.883962,-366.967834,0.088448,0.000000
72.790001,50.208099,-367.056793,-0.000966,0.003480,0.088396,223.336777,11.377318,0.883962,-367.056793,0.088448,0.000000
73.020004,50.096382,-367.012329,-0.000957,0.003480,0.088396,222.839844,11.352003,0.883962,-367.012329,0.088448,0.000000
73.250000,49.980202,-367.012329,-0.000966,0.003480,0.088396,222.323044,11.325675,0.883962,-367.012329,0.088448,0.000000
73.480003,49.869980,-367.056793,-0.000983,0.003480,0.088396,221.832748,11.300699,0.883962,-367.056793,0.088448,0.000000
73.710007,49.765717,-367.145782,-0.000979,0.003480,0.088396,221.368958,11.277072,0.883962,-367.145782,0.088448,0.000000
73.940002,49.665550,-367.145782,-0.000987,0.003480,0.088396,220.923401,11.254375,0.883962,-367.145782,0.088448,0.000000
74.170006,49.560173,-367.101288,-0.000974,0.003480,0.088396,220.454666,11.230495,0.883962,-367.101288,0.088448,0.000000
74.400002,49.465218,-367.056793,-0.000961,0.003480,0.088396,220.032272,11.208979,0.883962,-367.056793,0.088448,0.000000
74.630005,49.375099,-367.145782,-0.000983,0.003480,0.088396,219.631409,11.188558,0.883962,-367.145782,0.088448,0.000000
74.860001,49.280891,-367.190247,-0.000961,0.003480,0.088396,219.212357,11.167210,0.883962,-367.190247,0.088448,0.000000
75.090004,49.195244,-367.190247,-0.000953,0.003480,0.088396,218.831375,11.147801,0.883962,-367.190247,0.088448,0.000000
75.320007,49.105499,-367.190247,-0.000987,0.003480,0.088396,218.432175,11.127465,0.883962,-367.190247,0.088448,0.000000
75.550003,49.028793,-367.190247,-0.000953,0.003480,0.088396,218.090958,11.110083,0.883962,-367.190247,0.088448,0.000000
75.780006,48.942780,-367.234741,-0.000966,0.003480,0.088396,217.708359,11.090592,0.883962,-367.234741,0.088448,0.000000
76.010002,48.873512,-367.234741,-0.000970,0.003480,0.088396,217.400238,11.074896,0.883962,-367.234741,0.088448,0.000000
76.240005,48.773720,-367.234741,-0.000974,0.003480,0.088396,216.956345,11.052282,0.883962,-367.234741,0.088448,0.000000
76.470001,48.703339,-367.234741,-0.000961,0.003480,0.088396,216.643265,11.036335,0.883962,-367.234741,0.088448,0.000000
76.700005,48.635941,-367.279205,-0.000957,0.003480,0.088396,216.343475,11.021062,0.883962,-367.279205,0.088448,0.000000
76.930000,48.562584,-367.234741,-0.000970,0.003480,0.088396,216.017166,11.004438,0.883962,-367.234741,0.088448,0.000000
77.160004,48.497421,-367.323700,-0.000966,0.003480,0.088396,215.727310,10.989673,0.883962,-367.323700,0.088448,0.000000
77.390007,48.414749,-367.323700,-0.000961,0.003480,0.088396,215.359558,10.970940,0.883962,-367.323700,0.088448,0.000000
77.620003,48.358521,-367.323700,-0.000974,0.003480,0.088396,215.109436,10.958198,0.883962,-367.323700,0.088448,0.000000
77.850006,48.287399,-367.323700,-0.000953,0.003480,0.088396,214.793076,10.942080,0.883962,-367.323700,0.088448,0.000000
78.080002,48.206223,-367.368164,-0.000961,0.003480,0.088396,214.431992,10.923686,0.883962,-367.368164,0.088448,0.000000
78.310005,48.151482,-367.412659,-0.000931,0.003480,0.088396,214.188492,10.911282,0.883962,-367.412659,0.088448,0.000000
78.540001,48.083344,-367.457123,-0.000961,0.003480,0.088396,213.885391,10.895842,0.883962,-367.457123,0.088448,0.000000
78.770004,48.035675,-367.412659,-0.000961,0.003480,0.088396,213.673355,10.885039,0.883962,-367.412659,0.088448,0.000000
79.000000,47.967163,-367.412659,-0.000966,0.003480,0.088396,213.368591,10.869514,0.883962,-367.412659,0.088448,0.000000
79.230003,47.910934,-367.457123,-0.000944,0.003480,0.088396,213.118484,10.856772,0.883962,-367.457123,0.088448,0.000000
79.460007,47.851723,-367.501617,-0.000961,0.003480,0.088396,212.855087,10.843356,0.883962,-367.501617,0.088448,0.000000
79.690002,47.804436,-367.501617,-0.000931,0.003480,0.088396,212.644745,10.832641,0.883962,-367.501617,0.088448,0.000000
79.920006,47.751930,-367.546112,-0.000987,0.003480,0.088396,212.411194,10.820743,0.883962,-367.546112,0.088448,0.000000
80.150002,47.675964,-367.457123,-0.000944,0.003480,0.088396,212.073288,10.803528,0.883962,-367.457123,0.088448,0.000000
80.380005,47.640587,-367.501617,-0.000944,0.003480,0.088396,211.915909,10.795511,0.883962,-367.501617,0.088448,0.000000
80.610001,47.579521,-367.546112,-0.000953,0.003480,0.088396,211.644287,10.781673,0.883962,-367.546112,0.088448,0.000000
80.840004,47.524780,-367.590576,-0.000970,0.003480,0.088396,211.400787,10.769270,0.883962,-367.590576,0.088448,0.000000
81.070007,47.477119,-367.546112,-0.000961,0.003480,0.088396,211.188782,10.758469,0.883962,-367.546112,0.088448,0.000000
81.300003,47.426849,-367.590576,-0.000961,0.003480,0.088396,210.965164,10.747077,0.883962,-367.590576,0.088448,0.000000
81.530006,47.391846,-367.590576,-0.000931,0.003480,0.088396,210.809464,10.739145,0.883962,-367.590576,0.088448,0.000000
81.760002,47.334869,-367.635071,-0.000949,0.003480,0.088396,210.556015,10.726235,0.883962,-367.635071,0.088448,0.000000
81.990005,47.285347,-367.679535,-0.000957,0.003480,0.088396,210.335724,10.715013,0.883962,-367.679535,0.088448,0.000000
82.220001,47.226883,-367.635071,-0.000949,0.003480,0.088396,210.075668,10.701764,0.883962,-367.635071,0.088448,0.000000
82.450005,47.188156,-367.635071,-0.000944,0.003480,0.088396,209.903397,10.692989,0.883962,-367.635071,0.088448,0.000000
82.680000,47.152039,-367.590576,-0.000979,0.003480,0.088396,209.742737,10.684805,0.883962,-367.590576,0.088448,0.000000
82.910004,47.113312,-367.679535,-0.000953,0.003480,0.088396,209.570480,10.676028,0.883962,-367.679535,0.088448,0.000000
83.140007,47.058945,-367.768494,-0.000940,0.003480,0.088396,209.328644,10.663710,0.883962,-367.768494,0.088448,0.000000
83.370003,47.017235,-367.768494,-0.000944,0.003480,0.088396,209.143112,10.654258,0.883962,-367.768494,0.088448,0.000000
83.600006,46.978508,-367.724030,-0.000949,0.003480,0.088396,208.970840,10.645482,0.883962,-367.724030,0.088448,0.000000
83.830002,46.938667,-367.768494,-0.000931,0.003480,0.088396,208.793625,10.636455,0.883962,-367.768494,0.088448,0.000000
84.060005,46.893234,-367.812988,-0.000936,0.003480,0.088396,208.591522,10.626159,0.883962,-367.812988,0.088448,0.000000
84.290001,46.856377,-367.768494,-0.000944,0.003480,0.088396,208.427567,10.617807,0.883962,-367.768494,0.088448,0.000000
84.520004,46.824348,-367.857452,-0.000953,0.003480,0.088396,208.285110,10.610549,0.883962,-367.857452,0.088448,0.000000
84.750008,46.777054,-367.901947,-0.000953,0.003480,0.088396,208.074722,10.599832,0.883962,-367.901947,0.088448,0.000000
84.980003,46.730515,-367.812988,-0.000957,0.003480,0.088396,207.867706,10.589286,0.883962,-367.812988,0.088448,0.000000
85.210007,46.694763,-367.812988,-0.000953,0.003480,0.088396,207.708679,10.581184,0.883962,-367.812988,0.088448,0.000000
85.440002,46.666466,-367.857452,-0.000957,0.003480,0.088396,207.582809,10.574773,0.883962,-367.857452,0.088448,0.000000
85.670006,46.613586,-367.901947,-0.000936,0.003480,0.088396,207.347595,10.562790,0.883962,-367.901947,0.088448,0.000000
85.900002,46.600555,-367.946442,-0.000949,0.003480,0.088396,207.289627,10.559836,0.883962,-367.946442,0.088448,0.000000
86.130005,46.540604,-367.901947,-0.000940,0.003480,0.088396,207.022949,10.546252,0.883962,-367.901947,0.088448,0.000000
86.360001,46.514534,-367.901947,-0.000914,0.003480,0.088396,206.906982,10.540343,0.883962,-367.901947,0.088448,0.000000
86.590004,46.479156,-367.901947,-0.000949,0.003480,0.088396,206.749619,10.532328,0.883962,-367.901947,0.088448,0.000000
86.820007,46.448624,-367.946442,-0.000936,0.003480,0.088396,206.613800,10.525409,0.883962,-367.946442,0.088448,0.000000
87.050003,46.404686,-368.035400,-0.000931,0.003480,0.088396,206.418350,10.515452,0.883962,-368.035400,0.088448,0.000000
87.280006,46.396492,-367.990906,-0.000931,0.003480,0.088396,206.381897,10.513595,0.883962,-367.990906,0.088448,0.000000
87.510002,46.339890,-367.990906,-0.000944,0.003480,0.088396,206.130127,10.500770,0.883962,-367.990906,0.088448,0.000000
87.740005,46.309731,-367.990906,-0.000944,0.003480,0.088396,205.995972,10.493935,0.883962,-367.990906,0.088448,0.000000
87.970001,46.283661,-368.079865,-0.000953,0.003480,0.088396,205.880005,10.488028,0.883962,-368.079865,0.088448,0.000000
88.200005,46.246056,-368.035400,-0.000953,0.003480,0.088396,205.712723,10.479506,0.883962,-368.035400,0.088448,0.000000
88.430008,46.219246,-368.035400,-0.000931,0.003480,0.088396,205.593475,10.473432,0.883962,-368.035400,0.088448,0.000000
88.660004,46.187965,-368.035400,-0.000931,0.003480,0.088396,205.454330,10.466343,0.883962,-368.035400,0.088448,0.000000
88.890007,46.165253,-368.079865,-0.000940,0.003480,0.088396,205.353302,10.461195,0.883962,-368.079865,0.088448,0.000000
89.120003,46.128014,-368.168823,-0.000944,0.003480,0.088396,205.187653,10.452757,0.883962,-368.168823,0.088448,0.000000
89.350006,46.101570,-368.168823,-0.000927,0.003480,0.088396,205.070023,10.446765,0.883962,-368.168823,0.088448,0.000000
89.580002,46.074760,-368.168823,-0.000936,0.003480,0.088396,204.950775,10.440690,0.883962,-368.168823,0.088448,0.000000
89.810005,46.030823,-368.079865,-0.000936,0.003480,0.088396,204.755325,10.430734,0.883962,-368.079865,0.088448,0.000000
90.040001,46.005501,-368.213318,-0.000949,0.003480,0.088396,204.642685,10.424995,0.883962,-368.213318,0.088448,0.000000
90.270004,45.988373,-368.213318,-0.000931,0.003480,0.088396,204.566498,10.421114,0.883962,-368.213318,0.088448,0.000000
90.500008,45.945175,-368.213318,-0.000927,0.003480,0.088396,204.374344,10.411325,0.883962,-368.213318,0.088448,0.000000
90.730003,45.924698,-368.213318,-0.000931,0.003480,0.088396,204.283264,10.406685,0.883962,-368.213318,0.088448,0.000000
90.960007,45.900124,-368.213318,-0.000918,0.003480,0.088396,204.173950,10.401117,0.883962,-368.213318,0.088448,0.000000
91.190002,45.864372,-368.257782,-0.000931,0.003480,0.088396,204.014923,10.393016,0.883962,-368.257782,0.088448,0.000000
91.420006,45.845383,-368.257782,-0.000936,0.003480,0.088396,203.930450,10.388713,0.883962,-368.257782,0.088448,0.000000
91.650002,45.810379,-368.302277,-0.000936,0.003480,0.088396,203.774750,10.380780,0.883962,-368.302277,0.088448,0.000000
91.880005,45.780960,-368.257782,-0.000927,0.003480,0.088396,203.643875,10.374113,0.883962,-368.257782,0.088448,0.000000
92.110001,45.762718,-368.302277,-0.000953,0.003480,0.088396,203.562744,10.369980,0.883962,-368.302277,0.088448,0.000000
92.340004,45.736649,-368.302277,-0.000953,0.003480,0.088396,203.446777,10.364073,0.883962,-368.302277,0.088448,0.000000
92.570007,45.703133,-368.346741,-0.000936,0.003480,0.088396,203.297684,10.356478,0.883962,-368.346741,0.088448,0.000000
92.800003,45.667389,-368.391235,-0.000936,0.003480,0.088396,203.138687,10.348378,0.883962,-368.391235,0.088448,0.000000
93.030006,45.648026,-368.346741,-0.000931,0.003480,0.088396,203.052551,10.343990,0.883962,-368.346741,0.088448,0.000000
93.260002,45.621582,-368.302277,-0.000918,0.003480,0.088396,202.934937,10.337998,0.883962,-368.302277,0.088448,0.000000
93.490005,45.602219,-368.346741,-0.000931,0.003480,0.088396,202.848801,10.333611,0.883962,-368.346741,0.088448,0.000000
93.700005,45.574295,-368.435730,-0.000936,0.003480,0.088396,202.724594,10.327282,0.883962,-368.435730,0.088448,0.000000