File: Data/compression 13/AutoNoHeating-12-13-4-240724_07242024_164439.csv
Time (sec),S:Load (lbs),S:HL1 (DIM),S:LVDT (in),S:Position (in),Ch:Position (mm),Ch:Load (N),Ch:Stress (MPa),Ch:Strain (mm/mm),Ch:HL1 (DIM),Set Point (),Cycles ()
0.010000,0.035744,-292.061920,-0.008261,-0.004000,-0.101595,0.158996,0.008100,-1.015953,-292.061920,-0.101378,0.000000
0.250000,0.025696,-292.106415,-0.008282,-0.004000,-0.101595,0.114301,0.005823,-1.015953,-292.106415,-0.101378,0.000000
0.490000,-0.007820,-292.106415,-0.008274,-0.003909,-0.099288,-0.034786,-0.001772,-0.992884,-292.106415,-0.098534,0.000000
0.730000,0.042450,-292.106415,-0.008196,-0.003762,-0.095560,0.188827,0.009619,-0.955595,-292.106415,-0.094544,0.000000
0.970000,0.038727,-292.106415,-0.008067,-0.003619,-0.091934,0.172265,0.008776,-0.919343,-292.106415,-0.090538,0.000000
1.210000,0.028671,-292.150879,-0.007881,-0.003449,-0.087607,0.127536,0.006497,-0.876067,-292.150879,-0.086548,0.000000
1.450000,0.010056,-292.150879,-0.007709,-0.003300,-0.083808,0.044729,0.002279,-0.838082,-292.150879,-0.082543,0.000000
1.690000,0.020477,-292.195374,-0.007541,-0.003141,-0.079776,0.091088,0.004640,-0.797757,-292.195374,-0.078536,0.000000
1.930000,0.044312,-292.195374,-0.007381,-0.002983,-0.075769,0.197107,0.010041,-0.757691,-292.195374,-0.074547,0.000000
2.170000,0.023834,-292.195374,-0.007248,-0.002818,-0.071572,0.106020,0.005401,-0.715716,-292.195374,-0.070540,0.000000
2.410000,0.027924,-292.284332,-0.007062,-0.002667,-0.067747,0.124210,0.006328,-0.677473,-292.284332,-0.066551,0.000000
2.650000,0.028297,-292.284332,-0.006920,-0.002511,-0.063784,0.125873,0.006412,-0.637838,-292.284332,-0.062544,0.000000
2.890000,0.066650,-292.284332,-0.006739,-0.002356,-0.059847,0.296476,0.015103,-0.598468,-292.284332,-0.058555,0.000000
3.130000,0.061440,-292.328796,-0.006584,-0.002197,-0.055806,0.273297,0.013922,-0.558060,-292.328796,-0.054548,0.000000
3.370000,0.012657,-292.328796,-0.006428,-0.002036,-0.051704,0.056302,0.002868,-0.517039,-292.328796,-0.050559,0.000000
3.610000,0.023087,-292.417786,-0.006243,-0.001883,-0.047818,0.102694,0.005231,-0.478184,-292.417786,-0.046553,0.000000
3.850000,0.039101,-292.373291,-0.006079,-0.001720,-0.043699,0.173928,0.008860,-0.436989,-292.373291,-0.042563,0.000000
4.090000,0.020103,-292.373291,-0.005928,-0.001558,-0.039563,0.089425,0.004556,-0.395627,-292.373291,-0.038557,0.000000
4.330000,0.005585,-292.417786,-0.005764,-0.001401,-0.035582,0.024842,0.001266,-0.355818,-292.417786,-0.034567,0.000000
4.570000,0.039467,-292.462250,-0.005592,-0.001251,-0.031775,0.175557,0.008943,-0.317750,-292.462250,-0.030561,0.000000
4.810000,0.058090,-292.462250,-0.005441,-0.001092,-0.027743,0.258398,0.013163,-0.277425,-292.462250,-0.026571,0.000000
5.050000,0.072983,-292.417786,-0.005307,-0.000942,-0.023927,0.324644,0.016538,-0.239266,-292.417786,-0.022565,0.000000
5.290000,0.064423,-292.551208,-0.005101,-0.000774,-0.019651,0.286566,0.014598,-0.196512,-292.551208,-0.018576,0.000000
5.530000,0.033516,-292.506744,-0.004954,-0.000622,-0.015800,0.149086,0.007595,-0.158004,-292.506744,-0.014569,0.000000
5.770000,0.048782,-292.595703,-0.004790,-0.000466,-0.011846,0.216995,0.011054,-0.118460,-292.595703,-0.010580,0.000000
6.010000,0.049149,-292.551208,-0.004639,-0.000302,-0.007666,0.218624,0.011137,-0.076659,-292.551208,-0.006574,0.000000
6.250000,0.148949,-292.551208,-0.004454,-0.000142,-0.003599,0.662557,0.033752,-0.035987,-292.551208,-0.002567,0.000000
6.490000,0.757034,-292.595703,-0.004294,-0.000015,-0.000382,3.367457,0.171546,-0.003815,-292.595703,-0.000242,0.000000
6.730000,0.678093,-292.595703,-0.004312,-0.000000,-0.000008,3.016308,0.153658,-0.000083,-292.595703,0.000139,0.000000
6.970000,0.660957,-292.640167,-0.004281,-0.000001,-0.000017,2.940085,0.149775,-0.000174,-292.640167,0.000139,0.000000
7.210001,0.630798,-292.684662,-0.004299,-0.000001,-0.000017,2.805931,0.142941,-0.000174,-292.684662,0.000529,0.000000
7.450000,0.647179,-292.729126,-0.004324,-0.000000,-0.000008,2.878794,0.146653,-0.000083,-292.729126,0.000928,0.000000
7.690001,0.775276,-292.729126,-0.004312,0.000021,0.000529,3.448601,0.175680,0.005291,-292.729126,0.001327,0.000000
7.930000,0.935402,-292.684662,-0.004277,0.000032,0.000815,4.160875,0.211965,0.008153,-292.684662,0.001726,0.000000
8.170000,1.059029,-292.773621,-0.004264,0.000045,0.001145,4.710794,0.239979,0.011453,-292.773621,0.002134,0.000000
8.410001,1.230316,-292.729126,-0.004264,0.000061,0.001544,5.472720,0.278794,0.015442,-292.729126,0.002533,0.000000
8.650001,1.332344,-292.818115,-0.004264,0.000070,0.001786,5.926562,0.301913,0.017865,-292.818115,0.002932,0.000000
8.890000,1.677910,-292.862579,-0.004238,0.000100,0.002541,7.463716,0.380220,0.025412,-292.862579,0.003331,0.000000
9.130000,1.830582,-292.818115,-0.004204,0.000116,0.002940,8.142834,0.414816,0.029401,-292.818115,0.003730,0.000000
9.370001,1.985115,-292.862579,-0.004199,0.000128,0.003252,8.830233,0.449834,0.032520,-292.862579,0.004129,0.000000
9.610001,2.150078,-292.862579,-0.004169,0.000141,0.003582,9.564024,0.487215,0.035820,-292.862579,0.004527,0.000000
9.850000,2.275192,-292.862579,-0.004182,0.000152,0.003868,10.120561,0.515566,0.038682,-292.862579,0.004926,0.000000
10.090000,2.660599,-292.951538,-0.004161,0.000179,0.004536,11.834934,0.602900,0.045358,-292.951538,0.005334,0.000000
10.330001,2.731354,-292.862579,-0.004148,0.000188,0.004770,12.149669,0.618934,0.047697,-292.862579,0.005733,0.000000
10.570001,2.948074,-292.996033,-0.004135,0.000201,0.005100,13.113689,0.668043,0.050998,-292.996033,0.006132,0.000000
10.810000,3.163300,-292.996033,-0.004118,0.000215,0.005472,14.071059,0.716814,0.054722,-292.996033,0.006530,0.000000
11.050000,3.529716,-292.996033,-0.004126,0.000239,0.006079,15.700963,0.799845,0.060793,-292.996033,0.006929,0.000000
11.290001,3.746437,-292.996033,-0.004083,0.000255,0.006470,16.664984,0.848955,0.064699,-292.996033,0.007328,0.000000
11.530001,3.889801,-292.951538,-0.004083,0.000267,0.006782,17.302700,0.881442,0.067818,-292.951538,0.007727,0.000000
11.770000,4.079712,-293.040497,-0.004074,0.000280,0.007120,18.147465,0.924476,0.071201,-293.040497,0.008126,0.000000
12.010000,4.351173,-293.040497,-0.004023,0.000297,0.007536,19.354986,0.985990,0.075365,-293.040497,0.008533,0.000000
12.250001,4.658752,-293.084991,-0.004023,0.000314,0.007970,20.723166,1.055688,0.079702,-293.084991,0.008932,0.000000
12.490001,4.747375,-293.129456,-0.004044,0.000325,0.008265,21.117380,1.075771,0.082647,-293.129456,0.009331,0.000000
12.730000,5.015480,-293.129456,-0.003997,0.000340,0.008638,22.309969,1.136524,0.086379,-293.129456,0.009730,0.000000
12.970000,5.568832,-293.173950,-0.003971,0.000369,0.009375,24.771404,1.261915,0.093752,-293.173950,0.010129,0.000000
13.210001,5.606438,-293.173950,-0.003958,0.000381,0.009679,24.938681,1.270437,0.096787,-293.173950,0.010528,0.000000
13.450001,5.712936,-293.129456,-0.003967,0.000393,0.009991,25.412411,1.294570,0.099906,-293.129456,0.010927,0.000000
13.690001,6.005249,-293.218414,-0.003945,0.000407,0.010337,26.712683,1.360809,0.103373,-293.218414,0.011326,0.000000
13.930000,6.287132,-293.218414,-0.003928,0.000424,0.010780,27.966560,1.424685,0.107801,-293.218414,0.011734,0.000000
14.170001,6.612213,-293.262909,-0.003898,0.000443,0.011248,29.412594,1.498349,0.112480,-293.262909,0.012133,0.000000
14.410001,6.555244,-293.218414,-0.003898,0.000451,0.011448,29.159184,1.485440,0.114478,-293.218414,0.012532,0.000000
14.650001,6.845322,-293.262909,-0.003898,0.000466,0.011847,30.449511,1.551172,0.118467,-293.262909,0.012931,0.000000
14.890000,7.472771,-293.307404,-0.003872,0.000494,0.012540,33.240543,1.693354,0.125401,-293.307404,0.013330,0.000000
15.130001,7.364037,-293.262909,-0.003846,0.000504,0.012801,32.756870,1.668715,0.128005,-293.262909,0.013729,0.000000
15.370001,7.596024,-293.396362,-0.003859,0.000520,0.013199,33.788799,1.721284,0.131994,-293.396362,0.014127,0.000000
15.610001,7.896156,-293.307404,-0.003820,0.000534,0.013564,35.123856,1.789295,0.135635,-293.307404,0.014535,0.000000
15.850000,8.172455,-293.440826,-0.003816,0.000551,0.013997,36.352894,1.851905,0.139973,-293.440826,0.014934,0.000000
16.090000,8.243584,-293.396362,-0.003794,0.000564,0.014336,36.669292,1.868023,0.143357,-293.396362,0.015333,0.000000
16.330000,8.429764,-293.440826,-0.003773,0.000579,0.014708,37.497463,1.910212,0.147081,-293.440826,0.015732,0.000000
16.570002,8.465889,-293.529785,-0.003781,0.000590,0.014986,37.658154,1.918398,0.149859,-293.529785,0.016130,0.000000
16.810001,9.159615,-293.485321,-0.003751,0.000614,0.015584,40.743999,2.075598,0.155839,-293.485321,0.016529,0.000000
17.050001,9.149193,-293.485321,-0.003751,0.000627,0.015914,40.697643,2.073237,0.159140,-293.485321,0.016928,0.000000
17.290001,9.146210,-293.529785,-0.003742,0.000638,0.016208,40.684372,2.072561,0.162084,-293.529785,0.017327,0.000000
17.530001,9.551727,-293.485321,-0.003712,0.000659,0.016729,42.488205,2.164452,0.167292,-293.485321,0.017735,0.000000
17.770000,9.749825,-293.529785,-0.003691,0.000674,0.017111,43.369385,2.209342,0.171108,-293.529785,0.018134,0.000000
18.010000,10.167259,-293.574280,-0.003656,0.000697,0.017691,45.226227,2.303934,0.176914,-293.574280,0.018533,0.000000
18.250000,10.148262,-293.574280,-0.003648,0.000707,0.017969,45.141724,2.299629,0.179692,-293.574280,0.018932,0.000000
18.490002,10.091667,-293.618744,-0.003643,0.000716,0.018195,44.889977,2.286804,0.181947,-293.618744,0.019331,0.000000
18.730001,10.964508,-293.618744,-0.003630,0.000745,0.018915,48.772568,2.484593,0.189146,-293.618744,0.019730,0.000000
18.970001,10.772736,-293.663239,-0.003617,0.000754,0.019158,47.919521,2.441137,0.191576,-293.663239,0.020129,0.000000
19.210001,10.757469,-293.618744,-0.003574,0.000766,0.019452,47.851612,2.437677,0.194521,-293.618744,0.020528,0.000000
19.450001,11.075104,-293.752197,-0.003570,0.000784,0.019921,49.264523,2.509655,0.199207,-293.752197,0.020935,0.000000
19.690001,11.422523,-293.707733,-0.003553,0.000802,0.020363,50.809921,2.588381,0.203627,-293.707733,0.021334,0.000000
19.930000,11.435188,-293.707733,-0.003557,0.000813,0.020657,50.866257,2.591251,0.206572,-293.707733,0.021733,0.000000
20.170000,11.557320,-293.796692,-0.003531,0.000829,0.021065,51.409527,2.618926,0.210652,-293.796692,0.022132,0.000000
20.410002,11.930809,-293.752197,-0.003523,0.000846,0.021482,53.070889,2.703560,0.214815,-293.752197,0.022531,0.000000
20.650002,12.187378,-293.885651,-0.003514,0.000864,0.021941,54.212166,2.761699,0.219410,-293.885651,0.022930,0.000000
20.890001,12.417877,-293.796692,-0.003462,0.000883,0.022418,55.237476,2.813931,0.224179,-293.796692,0.023329,0.000000
21.130001,12.386223,-293.841156,-0.003484,0.000896,0.022756,55.096672,2.806758,0.227563,-293.841156,0.023728,0.000000
21.370001,12.468147,-293.841156,-0.003458,0.000909,0.023095,55.461090,2.825322,0.230947,-293.841156,0.024136,0.000000
21.610001,12.580231,-293.841156,-0.003454,0.000925,0.023502,55.959660,2.850721,0.235019,-293.841156,0.024534,0.000000
21.850000,12.909035,-293.930115,-0.003432,0.000939,0.023840,57.422253,2.925229,0.238403,-293.930115,0.024933,0.000000
22.090000,12.976059,-293.930115,-0.003393,0.000953,0.024196,57.720394,2.940417,0.241961,-293.930115,0.025332,0.000000
22.330002,13.191292,-293.974609,-0.003385,0.000966,0.024525,58.677795,2.989189,0.245254,-293.974609,0.025730,0.000000
22.570002,13.648567,-294.019073,-0.003376,0.000988,0.025107,60.711861,3.092809,0.251067,-294.019073,0.026129,0.000000
22.810001,14.035088,-293.841156,-0.003354,0.001010,0.025653,62.431187,3.180396,0.256525,-293.841156,0.026528,0.000000
23.050001,13.796402,-294.063568,-0.003316,0.001020,0.025905,61.369461,3.126309,0.259046,-294.063568,0.026927,0.000000
23.290001,14.019821,-293.974609,-0.003311,0.001038,0.026355,62.363277,3.176937,0.263550,-293.974609,0.027335,0.000000
23.530001,14.063019,-294.019073,-0.003311,0.001051,0.026702,62.555431,3.186726,0.267024,-294.019073,0.027734,0.000000
23.770000,14.613014,-294.063568,-0.003281,0.001073,0.027257,65.001930,3.311356,0.272573,-294.063568,0.028133,0.000000
24.010000,14.676689,-294.019073,-0.003255,0.001085,0.027561,65.285172,3.325785,0.275608,-294.019073,0.028532,0.000000
24.250002,14.798454,-294.108063,-0.003242,0.001102,0.028003,65.826813,3.353378,0.280029,-294.108063,0.028931,0.000000
24.490002,15.142151,-294.108063,-0.003208,0.001123,0.028515,67.355652,3.431261,0.285146,-294.108063,0.029330,0.000000
24.730001,15.128006,-294.152527,-0.003199,0.001135,0.028827,67.292732,3.428055,0.288265,-294.152527,0.029729,0.000000
24.970001,15.061348,-294.197021,-0.003199,0.001148,0.029147,66.996223,3.412950,0.291475,-294.197021,0.030128,0.000000
25.210001,15.280304,-294.152527,-0.003173,0.001162,0.029521,67.970184,3.462566,0.295207,-294.152527,0.030535,0.000000
25.450001,15.126144,-294.241486,-0.003165,0.001174,0.029815,67.284454,3.427633,0.298151,-294.241486,0.030934,0.000000
25.690001,15.915199,-294.197021,-0.003130,0.001195,0.030344,70.794342,3.606436,0.303443,-294.197021,0.031333,0.000000
25.930000,15.878334,-294.197021,-0.003126,0.001208,0.030674,70.630356,3.598082,0.306743,-294.197021,0.031732,0.000000
26.170002,16.350502,-294.197021,-0.003126,0.001228,0.031186,72.730667,3.705077,0.311860,-294.197021,0.032131,0.000000
26.410002,16.649147,-294.241486,-0.003091,0.001249,0.031723,74.059105,3.772751,0.317235,-294.241486,0.032530,0.000000
26.650002,16.537430,-294.330444,-0.003074,0.001262,0.032062,73.562164,3.747435,0.320618,-294.330444,0.032929,0.000000
26.890001,16.397789,-294.330444,-0.003048,0.001275,0.032383,72.941010,3.715792,0.323828,-294.330444,0.033328,0.000000
27.130001,16.893417,-294.330444,-0.003035,0.001294,0.032877,75.145676,3.828103,0.328771,-294.330444,0.033736,0.000000
27.370001,16.418648,-294.330444,-0.003027,0.001298,0.032981,73.033791,3.720519,0.329808,-294.330444,0.034134,0.000000
27.610001,17.095993,-294.285980,-0.003009,0.001321,0.033562,76.046776,3.874007,0.335622,-294.285980,0.034533,0.000000
27.850000,17.082214,-294.419403,-0.002975,0.001335,0.033917,75.985481,3.870885,0.339172,-294.419403,0.034932,0.000000
28.090002,17.111633,-294.419403,-0.002979,0.001346,0.034186,76.116348,3.877552,0.341859,-294.419403,0.035331,0.000000
28.330002,16.936615,-294.463898,-0.002958,0.001360,0.034542,75.337830,3.837892,0.345417,-294.463898,0.035730,0.000000
28.570002,18.174385,-294.419403,-0.002923,0.001390,0.035314,80.843704,4.118374,0.353138,-294.419403,0.036129,0.000000
28.810001,17.711899,-294.463898,-0.002902,0.001400,0.035548,78.786461,4.013574,0.355477,-294.463898,0.036536,0.000000
29.050001,17.833664,-294.508362,-0.002876,0.001416,0.035972,79.328102,4.041166,0.359724,-294.508362,0.036935,0.000000
29.290001,17.609123,-294.463898,-0.002863,0.001427,0.036242,78.329292,3.990284,0.362419,-294.463898,0.037334,0.000000
29.530001,18.169914,-294.552856,-0.002854,0.001449,0.036797,80.823814,4.117362,0.367967,-294.552856,0.037733,0.000000
29.770002,18.160233,-294.508362,-0.002820,0.001460,0.037074,80.780746,4.115168,0.370738,-294.508362,0.038132,0.000000
30.010002,18.393333,-294.552856,-0.002807,0.001477,0.037517,81.817635,4.167989,0.375166,-294.552856,0.038531,0.000000
30.250002,19.105316,-294.597351,-0.002777,0.001502,0.038141,84.984688,4.329327,0.381411,-294.597351,0.038930,0.000000
30.490002,18.966049,-294.552856,-0.002742,0.001517,0.038523,84.365204,4.297768,0.385227,-294.552856,0.039329,0.000000
30.730001,18.691238,-294.641815,-0.002738,0.001529,0.038826,83.142784,4.235495,0.388262,-294.641815,0.039737,0.000000
30.970001,18.574684,-294.686310,-0.002708,0.001541,0.039138,82.624321,4.209084,0.391381,-294.686310,0.040136,0.000000
31.210001,18.551598,-294.686310,-0.002686,0.001554,0.039467,82.521629,4.203852,0.394674,-294.686310,0.040535,0.000000
31.450001,19.305649,-294.775269,-0.002647,0.001579,0.040109,85.875816,4.374722,0.401093,-294.775269,0.040934,0.000000
31.690002,18.925453,-294.641815,-0.002656,0.001588,0.040344,84.184624,4.288569,0.403440,-294.641815,0.041333,0.000000
31.930002,19.009613,-294.686310,-0.002634,0.001603,0.040708,84.558983,4.307640,0.407081,-294.686310,0.041731,0.000000
32.170002,19.224846,-294.775269,-0.002604,0.001621,0.041185,85.516388,4.356412,0.411850,-294.775269,0.042130,0.000000
32.410000,19.619560,-294.775269,-0.002583,0.001639,0.041636,87.272163,4.445856,0.416361,-294.775269,0.042529,0.000000
32.650002,19.568169,-294.819733,-0.002570,0.001656,0.042052,87.043564,4.434210,0.420517,-294.819733,0.042937,0.000000
32.890003,19.242722,-294.730774,-0.002527,0.001667,0.042338,85.595901,4.360463,0.423378,-294.730774,0.043336,0.000000
33.130001,19.329109,-294.864227,-0.002518,0.001683,0.042746,85.980171,4.380039,0.427458,-294.864227,0.043734,0.000000
33.370003,19.518646,-294.864227,-0.002479,0.001700,0.043171,86.823273,4.422988,0.431705,-294.864227,0.044133,0.000000
33.610001,19.576736,-294.864227,-0.002471,0.001715,0.043552,87.081673,4.436152,0.435520,-294.864227,0.044532,0.000000
33.850002,19.589027,-294.953186,-0.002423,0.001730,0.043934,87.136345,4.438937,0.439335,-294.953186,0.044931,0.000000
34.090000,19.331345,-294.864227,-0.002423,0.001739,0.044168,85.990112,4.380545,0.441682,-294.864227,0.045330,0.000000
34.330002,20.390739,-294.997681,-0.002393,0.001771,0.044974,90.702538,4.620607,0.449744,-294.997681,0.045729,0.000000
34.570004,19.743561,-294.997681,-0.002328,0.001780,0.045209,87.823746,4.473955,0.452091,-294.997681,0.046136,0.000000
34.810001,19.442307,-294.953186,-0.002328,0.001794,0.045556,86.483696,4.405690,0.455558,-294.953186,0.046535,0.000000
35.050003,19.444542,-295.086639,-0.002320,0.001809,0.045937,86.493645,4.406196,0.459373,-295.086639,0.046934,0.000000
35.290001,20.079811,-294.997681,-0.002294,0.001830,0.046484,89.319458,4.550150,0.464838,-294.997681,0.047333,0.000000
35.530003,19.961021,-295.042145,-0.002251,0.001844,0.046831,88.791061,4.523232,0.468305,-295.042145,0.047732,0.000000
35.770000,19.493698,-295.086639,-0.002233,0.001852,0.047039,86.712303,4.417335,0.470387,-295.086639,0.048131,0.000000
36.010002,19.967354,-295.042145,-0.002229,0.001873,0.047585,88.819229,4.524667,0.475852,-295.042145,0.048530,0.000000
36.250000,20.579163,-295.175598,-0.002177,0.001895,0.048123,91.540688,4.663305,0.481227,-295.175598,0.048929,0.000000
36.490002,20.090607,-295.131104,-0.002182,0.001904,0.048374,89.367485,4.552597,0.483740,-295.131104,0.049337,0.000000
36.730003,20.089867,-295.220062,-0.002151,0.001920,0.048765,89.364189,4.552429,0.487646,-295.220062,0.049736,0.000000
36.970001,20.004967,-295.175598,-0.002121,0.001934,0.049120,88.986534,4.533190,0.491196,-295.175598,0.050135,0.000000
37.210003,20.319244,-295.220062,-0.002126,0.001952,0.049580,90.384514,4.604406,0.495799,-295.220062,0.050534,0.000000
37.450001,20.286476,-295.264557,-0.002082,0.001966,0.049927,90.238754,4.596982,0.499265,-295.264557,0.050933,0.000000
37.690002,20.285362,-295.264557,-0.002070,0.001980,0.050291,90.233795,4.596729,0.502907,-295.264557,0.051332,0.000000
37.930000,20.228760,-295.220062,-0.002074,0.001990,0.050551,89.982018,4.583902,0.505511,-295.220062,0.051730,0.000000
38.170002,21.327629,-295.220062,-0.002018,0.002017,0.051236,94.870033,4.832910,0.512361,-295.220062,0.052129,0.000000
38.410004,20.783226,-295.264557,-0.002018,0.002027,0.051487,92.448410,4.709546,0.514874,-295.264557,0.052537,0.000000
38.650002,20.843544,-295.398010,-0.001983,0.002044,0.051921,92.716713,4.723214,0.519212,-295.398010,0.052936,0.000000
38.890003,21.081863,-295.264557,-0.001970,0.002059,0.052303,93.776810,4.777219,0.523027,-295.264557,0.053334,0.000000
39.130001,21.056175,-295.398010,-0.001944,0.002076,0.052727,93.662544,4.771398,0.527274,-295.398010,0.053733,0.000000
39.370003,21.690323,-295.398010,-0.001906,0.002096,0.053239,96.483376,4.915097,0.532391,-295.398010,0.054132,0.000000
39.610001,21.443810,-295.398010,-0.001906,0.002109,0.053569,95.386826,4.859237,0.535691,-295.398010,0.054531,0.000000
39.850002,21.025635,-295.398010,-0.001876,0.002118,0.053803,93.526695,4.764477,0.538030,-295.398010,0.054930,0.000000
40.090000,22.273460,-295.398010,-0.001845,0.002146,0.054514,99.077301,5.047238,0.545138,-295.398010,0.055329,0.000000
40.330002,21.699631,-295.442474,-0.001828,0.002154,0.054714,96.524780,4.917206,0.547137,-295.442474,0.055737,0.000000
40.570004,21.646011,-295.442474,-0.001815,0.002170,0.055121,96.286270,4.905056,0.551209,-295.442474,0.056136,0.000000
40.810001,21.908157,-295.486969,-0.001802,0.002186,0.055529,97.452354,4.964459,0.555290,-295.486969,0.056535,0.000000
41.050003,22.128975,-295.531433,-0.001768,0.002201,0.055910,98.434593,5.014497,0.559105,-295.531433,0.056934,0.000000
41.290001,22.202705,-295.531433,-0.001746,0.002216,0.056275,98.762566,5.031205,0.562746,-295.531433,0.057333,0.000000
41.530003,22.403786,-295.575928,-0.001733,0.002233,0.056726,99.657013,5.076770,0.567257,-295.575928,0.057732,0.000000
41.770000,22.387779,-295.531433,-0.001712,0.002247,0.057072,99.585815,5.073143,0.570724,-295.531433,0.058131,0.000000
42.010002,22.838348,-295.620392,-0.001690,0.002268,0.057602,101.590050,5.175244,0.576016,-295.620392,0.058538,0.000000
42.250004,23.078529,-295.664886,-0.001656,0.002287,0.058087,102.658424,5.229670,0.580868,-295.664886,0.058937,0.000000
42.490002,22.709137,-295.620392,-0.001638,0.002298,0.058365,101.015289,5.145964,0.583646,-295.620392,0.059336,0.000000
42.730003,22.727005,-295.664886,-0.001625,0.002312,0.058720,101.094765,5.150013,0.587204,-295.664886,0.059735,0.000000
42.970001,22.795525,-295.664886,-0.001591,0.002324,0.059041,101.399559,5.165540,0.590413,-295.664886,0.060134,0.000000
43.210003,23.043900,-295.709351,-0.001574,0.002340,0.059440,102.504387,5.221822,0.594403,-295.709351,0.060533,0.000000
43.450001,23.158218,-295.664886,-0.001561,0.002355,0.059804,103.012901,5.247727,0.598044,-295.664886,0.060932,0.000000
43.690002,23.174973,-295.709351,-0.001535,0.002368,0.060142,103.087425,5.251524,0.601420,-295.709351,0.061330,0.000000
43.930000,24.220222,-295.753845,-0.001500,0.002398,0.060897,107.736931,5.488381,0.608967,-295.753845,0.061738,0.000000
44.170002,24.200859,-295.798309,-0.001475,0.002412,0.061252,107.650795,5.483993,0.612525,-295.798309,0.062137,0.000000
44.410004,23.935356,-295.798309,-0.001470,0.002425,0.061591,106.469780,5.423829,0.615908,-295.798309,0.062536,0.000000
44.650002,23.866470,-295.842804,-0.001431,0.002438,0.061938,106.163361,5.408219,0.619375,-295.842804,0.062934,0.000000
44.890003,23.918602,-295.798309,-0.001440,0.002454,0.062319,106.395256,5.420033,0.623191,-295.798309,0.063333,0.000000
45.130001,24.517746,-295.842804,-0.001393,0.002474,0.062848,109.060379,5.555800,0.628482,-295.842804,0.063732,0.000000
45.370003,24.288734,-295.842804,-0.001358,0.002486,0.063134,108.041687,5.503906,0.631343,-295.842804,0.064131,0.000000
45.610001,24.986565,-295.976257,-0.001345,0.002510,0.063750,111.145790,5.662036,0.637497,-295.976257,0.064530,0.000000
45.850002,25.043167,-295.931763,-0.001354,0.002524,0.064097,111.397568,5.674863,0.640972,-295.931763,0.064938,0.000000
46.090004,24.821976,-295.931763,-0.001306,0.002535,0.064392,110.413666,5.624740,0.643917,-295.931763,0.065337,0.000000
46.330002,24.666321,-295.976257,-0.001315,0.002548,0.064730,109.721275,5.589468,0.647300,-295.976257,0.065736,0.000000
46.570004,24.804474,-295.931763,-0.001293,0.002563,0.065112,110.335808,5.620774,0.651115,-295.931763,0.066135,0.000000
46.810001,25.456497,-296.020721,-0.001259,0.002585,0.065649,113.236153,5.768525,0.656490,-296.020721,0.066534,0.000000
47.050003,25.653854,-296.020721,-0.001229,0.002598,0.065979,114.114044,5.813247,0.659790,-296.020721,0.066933,0.000000
47.290001,25.362663,-296.020721,-0.001216,0.002609,0.066256,112.818764,5.747262,0.662561,-296.020721,0.067332,0.000000
47.530003,26.068680,-296.065216,-0.001207,0.002629,0.066785,115.959282,5.907247,0.667852,-296.065216,0.067731,0.000000
47.770000,26.734856,-296.020721,-0.001173,0.002652,0.067367,118.922577,6.058205,0.673666,-296.020721,0.068138,0.000000
48.010002,26.330826,-296.109680,-0.001138,0.002664,0.067670,117.125366,5.966650,0.676701,-296.109680,0.068537,0.000000
48.250004,26.159538,-296.154175,-0.001138,0.002677,0.067991,116.363441,5.927836,0.679911,-296.154175,0.068936,0.000000
48.490002,26.557976,-296.109680,-0.001099,0.002693,0.068398,118.135773,6.018123,0.683984,-296.109680,0.069335,0.000000
48.730003,26.050804,-296.154175,-0.001082,0.002704,0.068684,115.879761,5.903196,0.686845,-296.154175,0.069734,0.000000
48.970001,26.737457,-296.198639,-0.001069,0.002722,0.069136,118.934151,6.058794,0.691356,-296.198639,0.070133,0.000000
49.210003,26.807465,-296.243134,-0.001056,0.002735,0.069465,119.245560,6.074658,0.694649,-296.243134,0.070532,0.000000
49.450001,26.775444,-296.198639,-0.001009,0.002746,0.069743,119.103127,6.067402,0.697427,-296.198639,0.070930,0.000000
49.690002,28.617195,-296.243134,-0.001026,0.002779,0.070584,127.295639,6.484749,0.705837,-296.243134,0.071338,0.000000
49.930004,28.229927,-296.332092,-0.000992,0.002791,0.070896,125.572990,6.396993,0.708956,-296.332092,0.071737,0.000000
50.170002,27.673607,-296.243134,-0.000966,0.002804,0.071217,123.098351,6.270929,0.712166,-296.243134,0.072136,0.000000
50.410004,27.864258,-296.287628,-0.000940,0.002819,0.071598,123.946411,6.314131,0.715981,-296.287628,0.072535,0.000000
50.650002,27.503799,-296.332092,-0.000944,0.002826,0.071772,122.343010,6.232450,0.717722,-296.332092,0.072934,0.000000
50.890003,28.586662,-296.376587,-0.000892,0.002851,0.072422,127.159828,6.477830,0.724225,-296.376587,0.073333,0.000000
51.130001,28.400101,-296.421051,-0.000880,0.002859,0.072613,126.329956,6.435555,0.726132,-296.421051,0.073732,0.000000
51.370003,28.926636,-296.376587,-0.000858,0.002879,0.073125,128.672104,6.554869,0.731249,-296.376587,0.074131,0.000000
51.610001,30.049339,-296.376587,-0.000849,0.002904,0.073749,133.666138,6.809278,0.737494,-296.376587,0.074538,0.000000
51.850002,29.903740,-296.421051,-0.000824,0.002917,0.074096,133.018478,6.776284,0.740961,-296.421051,0.074937,0.000000
52.090004,29.523918,-296.465546,-0.000815,0.002928,0.074365,131.328949,6.690216,0.743649,-296.465546,0.075336,0.000000
52.330002,29.598770,-296.510010,-0.000780,0.002942,0.074729,131.661911,6.707177,0.747290,-296.510010,0.075735,0.000000
52.570004,29.876183,-296.421051,-0.000767,0.002961,0.075198,132.895905,6.770040,0.751975,-296.421051,0.076134,0.000000
52.810001,30.738976,-296.554504,-0.000776,0.002979,0.075665,136.733795,6.965551,0.756653,-296.554504,0.076533,0.000000
53.050003,30.298454,-296.465546,-0.000729,0.002988,0.075883,134.774261,6.865728,0.758826,-296.465546,0.076932,0.000000
53.290001,30.524857,-296.554504,-0.000742,0.003002,0.076255,135.781342,6.917031,0.762550,-296.554504,0.077331,0.000000
53.530003,31.158638,-296.554504,-0.000711,0.003024,0.076811,138.600540,7.060648,0.768107,-296.554504,0.077739,0.000000
53.770004,31.852737,-296.554504,-0.000698,0.003041,0.077244,141.688049,7.217934,0.772444,-296.554504,0.078138,0.000000
54.010002,31.981949,-296.598969,-0.000677,0.003056,0.077617,142.262817,7.247213,0.776168,-296.598969,0.078537,0.000000
54.250004,32.050095,-296.598969,-0.000655,0.003070,0.077973,142.565948,7.262655,0.779726,-296.598969,0.078935,0.000000
54.490002,32.144676,-296.687958,-0.000647,0.003083,0.078311,142.986664,7.284088,0.783110,-296.687958,0.079334,0.000000
54.730003,32.707336,-296.643463,-0.000604,0.003102,0.078796,145.489502,7.411588,0.787962,-296.643463,0.079733,0.000000
54.970001,32.842133,-296.643463,-0.000604,0.003114,0.079091,146.089096,7.442133,0.790914,-296.643463,0.080132,0.000000
55.210003,33.135933,-296.732422,-0.000578,0.003129,0.079473,147.395996,7.508709,0.794730,-296.732422,0.080540,0.000000
55.450001,33.600281,-296.687958,-0.000569,0.003149,0.079993,149.461517,7.613933,0.799930,-296.687958,0.080938,0.000000
55.690002,34.898003,-296.776917,-0.000530,0.003172,0.080565,155.234070,7.908000,0.805653,-296.776917,0.081337,0.000000
55.930004,34.495842,-296.821381,-0.000513,0.003181,0.080791,153.445175,7.816869,0.807909,-296.821381,0.081736,0.000000
56.170002,34.342796,-296.732422,-0.000496,0.003193,0.081103,152.764389,7.782189,0.811035,-296.732422,0.082135,0.000000
56.410004,34.625053,-296.821381,-0.000479,0.003207,0.081459,154.019928,7.846149,0.814585,-296.821381,0.082534,0.000000
56.650002,35.764885,-296.776917,-0.000474,0.003231,0.082075,159.090149,8.104439,0.820747,-296.776917,0.082933,0.000000
56.890003,35.809196,-296.821381,-0.000453,0.003243,0.082369,159.287262,8.114480,0.823692,-296.821381,0.083332,0.000000
57.130001,35.492310,-296.821381,-0.000418,0.003250,0.082560,157.877686,8.042672,0.825599,-296.821381,0.083739,0.000000
57.370003,36.811249,-296.821381,-0.000435,0.003277,0.083245,163.744614,8.341549,0.832450,-296.821381,0.084138,0.000000
57.610004,37.539986,-296.954834,-0.000410,0.003294,0.083661,166.986191,8.506682,0.836613,-296.954834,0.084537,0.000000
57.850002,37.308739,-296.865875,-0.000388,0.003305,0.083957,165.957565,8.454281,0.839565,-296.865875,0.084936,0.000000
58.090004,37.608871,-296.954834,-0.000375,0.003320,0.084338,167.292618,8.522291,0.843381,-296.954834,0.085335,0.000000
58.330002,37.988319,-296.910339,-0.000345,0.003337,0.084754,168.980484,8.608276,0.847544,-296.910339,0.085734,0.000000
58.570004,38.740883,-296.910339,-0.000341,0.003354,0.085179,172.328049,8.778810,0.851791,-296.910339,0.086133,0.000000
58.810001,39.033943,-297.043793,-0.000315,0.003367,0.085517,173.631653,8.845218,0.855174,-297.043793,0.086532,0.000000
59.050003,39.203743,-296.999298,-0.000302,0.003379,0.085821,174.386963,8.883695,0.858210,-296.999298,0.086940,0.000000
59.290001,39.430145,-297.132751,-0.000310,0.003393,0.086185,175.394043,8.934999,0.861851,-297.132751,0.087339,0.000000
59.530003,40.899529,-297.043793,-0.000276,0.003417,0.086784,181.930191,9.267965,0.867839,-297.043793,0.087738,0.000000
59.770004,40.768456,-296.999298,-0.000254,0.003428,0.087061,181.347153,9.238264,0.870609,-296.999298,0.088137,0.000000
60.010002,41.371696,-297.132751,-0.000250,0.003445,0.087495,184.030502,9.374961,0.874947,-297.132751,0.088536,0.000000
60.250004,42.081436,-297.088287,-0.000237,0.003462,0.087937,187.187576,9.535789,0.879367,-297.088287,0.088934,0.000000
60.490002,42.792671,-297.177246,-0.000233,0.003481,0.088423,190.351303,9.696959,0.884227,-297.177246,0.089333,0.000000
60.730003,43.319946,-297.132751,-0.000207,0.003495,0.088769,192.696747,9.816441,0.887694,-297.132751,0.089732,0.000000
60.970001,43.465172,-297.132751,-0.000181,0.003509,0.089116,193.342743,9.849349,0.891161,-297.132751,0.090140,0.000000
61.210003,43.351227,-297.221710,-0.000185,0.003517,0.089342,192.835892,9.823528,0.893417,-297.221710,0.090538,0.000000
61.450005,45.349754,-297.221710,-0.000142,0.003547,0.090105,201.725784,10.276402,0.901047,-297.221710,0.090937,0.000000
61.690002,44.982224,-297.221710,-0.000155,0.003553,0.090244,200.090927,10.193117,0.902440,-297.221710,0.091336,0.000000
61.930004,45.632385,-297.221710,-0.000138,0.003573,0.090756,202.982986,10.340446,0.907557,-297.221710,0.091735,0.000000
62.170002,46.145142,-297.310669,-0.000121,0.003585,0.091068,205.263840,10.456639,0.910676,-297.310669,0.092134,0.000000
62.410004,46.772583,-297.266205,-0.000112,0.003602,0.091492,208.054840,10.598819,0.914923,-297.266205,0.092533,0.000000
62.650002,47.239914,-297.266205,-0.000103,0.003614,0.091805,210.133636,10.704718,0.918049,-297.266205,0.092932,0.000000
62.890003,48.186859,-297.310669,-0.000091,0.003633,0.092273,214.345856,10.919298,0.922727,-297.310669,0.093340,0.000000
63.130005,48.841118,-297.310669,-0.000069,0.003650,0.092716,217.256149,11.067555,0.927155,-297.310669,0.093739,0.000000
63.370003,49.814499,-297.310669,-0.000060,0.003670,0.093210,221.585953,11.288127,0.932099,-297.310669,0.094138,0.000000
63.610004,50.759209,-297.444122,-0.000043,0.003686,0.093617,225.788239,11.502201,0.936171,-297.444122,0.094537,0.000000
63.850002,50.955818,-297.399628,-0.000056,0.003698,0.093930,226.662796,11.546754,0.939297,-297.399628,0.094936,0.000000
64.090004,51.406761,-297.533081,-0.000034,0.003711,0.094251,228.668701,11.648939,0.942507,-297.533081,0.095335,0.000000
64.330002,51.907234,-297.399628,-0.000009,0.003723,0.094563,230.894913,11.762347,0.945626,-297.399628,0.095734,0.000000
64.570000,52.656075,-297.444122,0.000017,0.003740,0.094987,234.225922,11.932037,0.949872,-297.444122,0.096133,0.000000
64.810005,53.334534,-297.444122,-0.000004,0.003756,0.095395,237.243851,12.085778,0.953952,-297.444122,0.096540,0.000000
65.050003,53.924744,-297.488586,0.000009,0.003770,0.095768,239.869232,12.219522,0.957677,-297.488586,0.096939,0.000000
65.290001,55.930344,-297.577576,0.000026,0.003798,0.096462,248.790588,12.673997,0.964618,-297.577576,0.097338,0.000000
65.530006,56.702271,-297.533081,0.000030,0.003810,0.096783,252.224289,12.848918,0.967828,-297.533081,0.097737,0.000000
65.770004,57.104057,-297.577576,0.000056,0.003823,0.097112,254.011536,12.939964,0.971121,-297.577576,0.098136,0.000000
66.010002,57.834656,-297.577576,0.000069,0.003837,0.097459,257.261383,13.105520,0.974588,-297.577576,0.098534,0.000000
66.250000,58.522797,-297.577576,0.000065,0.003852,0.097840,260.322388,13.261456,0.978403,-297.577576,0.098933,0.000000
66.490005,59.973190,-297.666534,0.000065,0.003873,0.098369,266.774078,13.590119,0.983694,-297.666534,0.099332,0.000000
66.730003,60.457649,-297.666534,0.000078,0.003887,0.098725,268.929047,13.699899,0.987252,-297.666534,0.099740,0.000000
66.970001,62.103905,-297.666534,0.000099,0.003910,0.099315,276.251953,14.072946,0.993149,-297.666534,0.100138,0.000000
67.210007,62.923500,-297.666534,0.000095,0.003923,0.099653,279.897705,14.258669,0.996533,-297.666534,0.100537,0.000000
67.450005,63.365501,-297.666534,0.000112,0.003935,0.099939,281.863831,14.358828,0.999394,-297.666534,0.100936,0.000000
67.690002,63.950127,-297.755493,0.000134,0.003949,0.100304,284.464355,14.491306,1.003035,-297.755493,0.101335,0.000000
67.930000,64.845314,-297.710999,0.000125,0.003963,0.100659,288.446350,14.694159,1.006593,-297.710999,0.101734,0.000000
68.170006,66.373161,-297.755493,0.000147,0.003983,0.101179,295.242554,15.040373,1.011793,-297.755493,0.102133,0.000000
68.410004,67.189400,-297.799957,0.000172,0.003996,0.101509,298.873383,15.225336,1.015094,-297.799957,0.102541,0.000000
68.650002,67.450798,-297.844452,0.000160,0.003997,0.101518,300.036133,15.284570,1.015177,-297.844452,0.101726,0.000000
68.890007,66.752602,-297.844452,0.000155,0.003996,0.101509,296.930389,15.126355,1.015094,-297.844452,0.101726,0.000000
69.130005,66.192558,-297.799957,0.000155,0.003996,0.101492,294.439209,14.999449,1.014920,-297.799957,0.101509,0.000000
69.370003,65.695442,-297.933411,0.000185,0.003995,0.101483,292.227936,14.886800,1.014829,-297.933411,0.101509,0.000000
69.610001,65.278374,-297.844452,0.000181,0.003995,0.101475,290.372711,14.792291,1.014745,-297.844452,0.101509,0.000000
69.850006,64.882545,-297.888916,0.000190,0.003995,0.101475,288.611969,14.702596,1.014745,-297.888916,0.101509,0.000000
70.090004,64.564919,-297.888916,0.000190,0.003995,0.101475,287.199097,14.630620,1.014745,-297.888916,0.101509,0.000000
70.330002,64.258446,-297.888916,0.000203,0.003995,0.101475,285.835846,14.561172,1.014745,-297.888916,0.101509,0.000000
70.570000,63.989967,-297.977905,0.000198,0.003995,0.101465,284.641602,14.500334,1.014655,-297.977905,0.101509,0.000000
70.810005,63.749794,-297.977905,0.000177,0.003995,0.101465,283.573242,14.445910,1.014655,-297.977905,0.101509,0.000000
71.050003,63.522270,-297.977905,0.000181,0.003995,0.101465,282.561157,14.394352,1.014655,-297.977905,0.101509,0.000000
71.290001,63.314117,-298.066864,0.000185,0.003995,0.101465,281.635254,14.347184,1.014655,-298.066864,0.101509,0.000000
71.530006,63.135376,-298.066864,0.000198,0.003995,0.101465,280.840179,14.306681,1.014655,-298.066864,0.101509,0.000000
71.770004,62.959618,-298.066864,0.000198,0.003995,0.101465,280.058380,14.266853,1.014655,-298.066864,0.101509,0.000000
72.010002,62.805458,-298.022369,0.000211,0.003995,0.101465,279.372620,14.231920,1.014655,-298.022369,0.101509,0.000000
72.250000,62.646080,-298.066864,0.000181,0.003995,0.101465,278.663696,14.195805,1.014655,-298.066864,0.101509,0.000000
72.490005,62.493782,-298.111328,0.000224,0.003995,0.101465,277.986237,14.161293,1.014655,-298.111328,0.101509,0.000000
72.730003,62.372757,-298.066864,0.000207,0.003995,0.101465,277.447876,14.133869,1.014655,-298.066864,0.101509,0.000000
72.970001,62.251740,-298.155823,0.000198,0.003995,0.101465,276.909576,14.106446,1.014655,-298.155823,0.101509,0.000000
73.210007,62.135185,-298.155823,0.000203,0.003995,0.101465,276.391113,14.080034,1.014655,-298.155823,0.101509,0.000000
73.450005,62.020119,-298.155823,0.000190,0.003995,0.101465,275.879272,14.053960,1.014655,-298.155823,0.101509,0.000000
73.690002,61.926659,-298.200287,0.000220,0.003995,0.101465,275.463531,14.032782,1.014655,-298.200287,0.101509,0.000000
73.930000,61.816063,-298.244781,0.000220,0.003995,0.101465,274.971588,14.007720,1.014655,-298.244781,0.101509,0.000000
74.170006,61.727066,-298.289246,0.000216,0.003995,0.101465,274.575714,13.987554,1.014655,-298.289246,0.101509,0.000000
74.410004,61.644768,-298.244781,0.000203,0.003995,0.101465,274.209625,13.968904,1.014655,-298.244781,0.101509,0.000000
74.650002,61.545349,-298.289246,0.000207,0.003995,0.101465,273.767395,13.946375,1.014655,-298.289246,0.101509,0.000000
74.890007,61.473106,-298.378235,0.000211,0.003995,0.101465,273.446045,13.930005,1.014655,-298.378235,0.101509,0.000000
75.130005,61.393791,-298.378235,0.000224,0.003995,0.101465,273.093231,13.912031,1.014655,-298.378235,0.101509,0.000000
75.370003,61.301445,-298.422699,0.000216,0.003995,0.101465,272.682434,13.891106,1.014655,-298.422699,0.101509,0.000000
75.610001,61.234787,-298.333740,0.000190,0.003995,0.101465,272.385925,13.876001,1.014655,-298.333740,0.101509,0.000000
75.850006,61.168877,-298.378235,0.000220,0.003995,0.101465,272.092743,13.861066,1.014655,-298.378235,0.101509,0.000000
76.090004,61.095894,-298.378235,0.000233,0.003995,0.101465,271.768097,13.844527,1.014655,-298.378235,0.101509,0.000000
76.330002,61.030357,-298.422699,0.000216,0.003995,0.101465,271.476593,13.829677,1.014655,-298.422699,0.101509,0.000000
76.570007,60.976738,-298.511658,0.000207,0.003995,0.101465,271.238068,13.817526,1.014655,-298.511658,0.101509,0.000000
76.810005,60.900024,-298.422699,0.000216,0.003995,0.101465,270.896851,13.800143,1.014655,-298.422699,0.101509,0.000000
77.050003,60.851616,-298.467194,0.000198,0.003995,0.101465,270.681519,13.789173,1.014655,-298.467194,0.101509,0.000000
77.290001,60.789055,-298.511658,0.000220,0.003995,0.101465,270.403229,13.774997,1.014655,-298.511658,0.101509,0.000000
77.530006,60.724640,-298.556152,0.000224,0.003995,0.101465,270.116699,13.760401,1.014655,-298.556152,0.101509,0.000000
77.770004,60.680695,-298.556152,0.000203,0.003995,0.101465,269.921204,13.750443,1.014655,-298.556152,0.101509,0.000000
78.010002,60.635643,-298.511658,0.000203,0.003995,0.101465,269.720825,13.740232,1.014655,-298.511658,0.101509,0.000000
78.250000,60.564522,-298.600616,0.000207,0.003995,0.101465,269.404449,13.724116,1.014655,-298.600616,0.101509,0.000000
78.490005,60.527283,-298.645111,0.000220,0.003995,0.101465,269.238800,13.715678,1.014655,-298.645111,0.101509,0.000000
78.730003,60.478127,-298.600616,0.000211,0.003995,0.101465,269.020142,13.704539,1.014655,-298.600616,0.101509,0.000000
78.970001,60.424133,-298.734070,0.000229,0.003995,0.101465,268.779968,13.692304,1.014655,-298.734070,0.101509,0.000000
79.210007,60.388390,-298.689575,0.000211,0.003995,0.101465,268.620972,13.684204,1.014655,-298.689575,0.101509,0.000000
79.450005,60.331413,-298.734070,0.000216,0.003995,0.101465,268.367523,13.671294,1.014655,-298.734070,0.101509,0.000000
79.690002,60.291573,-298.734070,0.000220,0.003995,0.101465,268.190308,13.662266,1.014655,-298.734070,0.101509,0.000000
79.930000,60.259171,-298.778534,0.000211,0.003995,0.101465,268.046173,13.654922,1.014655,-298.778534,0.101509,0.000000
80.170006,60.207787,-298.778534,0.000237,0.003995,0.101465,267.817596,13.643280,1.014655,-298.778534,0.101509,0.000000
80.410004,60.172035,-298.734070,0.000224,0.003995,0.101465,267.658569,13.635179,1.014655,-298.734070,0.101509,0.000000
80.650002,60.137405,-298.823029,0.000207,0.003995,0.101465,267.504547,13.627331,1.014655,-298.823029,0.101509,0.000000
80.890007,60.094582,-298.778534,0.000220,0.003995,0.101465,267.314056,13.617627,1.014655,-298.778534,0.101509,0.000000
81.130005,60.065910,-298.734070,0.000207,0.003995,0.101465,267.186523,13.611130,1.014655,-298.734070,0.101509,0.000000
81.370003,60.014893,-298.867523,0.000224,0.003995,0.101465,266.959564,13.599569,1.014655,-298.867523,0.101509,0.000000
81.610001,59.993301,-298.823029,0.000237,0.003995,0.101465,266.863525,13.594677,1.014655,-298.823029,0.101509,0.000000
81.850006,59.937813,-298.867523,0.000237,0.003995,0.101465,266.616699,13.582102,1.014655,-298.867523,0.101509,0.000000
82.090004,59.910629,-298.911987,0.000224,0.003995,0.101465,266.495789,13.575942,1.014655,-298.911987,0.101509,0.000000
82.330002,59.883820,-298.956482,0.000216,0.003995,0.101465,266.376526,13.569867,1.014655,-298.956482,0.101509,0.000000
82.570007,59.850311,-299.000946,0.000211,0.003995,0.101465,266.227478,13.562274,1.014655,-299.000946,0.101509,0.000000
82.810005,59.817535,-298.911987,0.000207,0.003995,0.101465,266.081696,13.554847,1.014655,-298.911987,0.101509,0.000000
83.050003,59.789612,-298.956482,0.000233,0.003995,0.101465,265.957489,13.548519,1.014655,-298.956482,0.101509,0.000000
83.290001,59.761314,-299.000946,0.000216,0.003995,0.101465,265.831604,13.542108,1.014655,-299.000946,0.101509,0.000000
83.530006,59.725937,-298.956482,0.000224,0.003995,0.101465,265.674225,13.534091,1.014655,-298.956482,0.101509,0.000000
83.770004,59.701355,-299.045441,0.000229,0.003995,0.101465,265.564880,13.528521,1.014655,-299.045441,0.101509,0.000000
84.010002,59.662628,-299.045441,0.000241,0.003995,0.101465,265.392639,13.519745,1.014655,-299.045441,0.101509,0.000000
84.250008,59.628746,-299.134399,0.000211,0.003995,0.101465,265.241913,13.512067,1.014655,-299.134399,0.101509,0.000000
84.490005,59.613480,-299.134399,0.000241,0.003995,0.101465,265.174011,13.508608,1.014655,-299.134399,0.101509,0.000000
84.730003,59.573631,-299.134399,0.000241,0.003995,0.101465,264.996735,13.499578,1.014655,-299.134399,0.101509,0.000000
84.970001,59.554642,-299.134399,0.000224,0.003995,0.101465,264.912262,13.495275,1.014655,-299.134399,0.101509,0.000000
85.210007,59.539375,-299.089905,0.000233,0.003995,0.101465,264.844360,13.491816,1.014655,-299.089905,0.101509,0.000000
85.450005,59.496178,-299.223358,0.000237,0.003995,0.101465,264.652222,13.482026,1.014655,-299.223358,0.101509,0.000000
85.690002,59.467880,-299.134399,0.000233,0.003995,0.101465,264.526337,13.475615,1.014655,-299.134399,0.101509,0.000000
85.930000,59.442184,-299.178864,0.000220,0.003995,0.101465,264.412048,13.469791,1.014655,-299.178864,0.101509,0.000000
86.170006,59.403091,-299.223358,0.000241,0.003995,0.101465,264.238159,13.460933,1.014655,-299.223358,0.101509,0.000000
86.410004,59.401230,-299.267853,0.000203,0.003995,0.101465,264.229858,13.460511,1.014655,-299.267853,0.101509,0.000000
86.650002,59.378510,-299.312317,0.000211,0.003995,0.101465,264.128815,13.455363,1.014655,-299.312317,0.101509,0.000000
86.890007,59.343880,-299.267853,0.000250,0.003995,0.101465,263.974762,13.447515,1.014655,-299.267853,0.101509,0.000000
87.130005,59.318558,-299.356812,0.000220,0.003995,0.101465,263.862122,13.441777,1.014655,-299.356812,0.101509,0.000000
87.370003,59.311485,-299.356812,0.000216,0.003995,0.101465,263.830658,13.440175,1.014655,-299.356812,0.101509,0.000000
87.610001,59.274994,-299.356812,0.000241,0.003995,0.101465,263.668335,13.431905,1.014655,-299.356812,0.101509,0.000000
87.850006,59.249672,-299.401276,0.000211,0.003995,0.101465,263.555695,13.426167,1.014655,-299.401276,0.101509,0.000000
88.090004,59.219505,-299.356812,0.000224,0.003995,0.101465,263.421509,13.419332,1.014655,-299.356812,0.101509,0.000000
88.330002,59.210197,-299.401276,0.000224,0.003995,0.101465,263.380127,13.417223,1.014655,-299.401276,0.101509,0.000000
88.570007,59.172592,-299.445770,0.000216,0.003995,0.101465,263.212830,13.408701,1.014655,-299.445770,0.101509,0.000000
88.810005,59.169983,-299.445770,0.000237,0.003995,0.101465,263.201233,13.408110,1.014655,-299.445770,0.101509,0.000000
89.050003,59.145409,-299.490234,0.000229,0.003995,0.101465,263.091919,13.402541,1.014655,-299.490234,0.101509,0.000000
89.290001,59.123810,-299.490234,0.000224,0.003995,0.101465,262.995850,13.397647,1.014655,-299.490234,0.101509,0.000000
89.530006,59.097000,-299.534729,0.000216,0.003995,0.101465,262.876587,13.391572,1.014655,-299.534729,0.101509,0.000000
89.770004,59.084335,-299.490234,0.000237,0.003995,0.101465,262.820251,13.388702,1.014655,-299.490234,0.101509,0.000000
90.010002,59.061249,-299.490234,0.000220,0.003995,0.101465,262.717560,13.383471,1.014655,-299.490234,0.101509,0.000000
90.250008,59.053802,-299.534729,0.000224,0.003995,0.101465,262.684418,13.381783,1.014655,-299.534729,0.101509,0.000000
90.490005,59.021782,-299.579193,0.000259,0.003995,0.101465,262.541992,13.374527,1.014655,-299.579193,0.101509,0.000000
90.730003,58.994598,-299.623688,0.000216,0.003995,0.101465,262.421082,13.368367,1.014655,-299.623688,0.101509,0.000000
90.970001,58.978958,-299.579193,0.000224,0.003995,0.101465,262.351501,13.364823,1.014655,-299.579193,0.101509,0.000000
91.210007,58.957733,-299.623688,0.000229,0.003995,0.101465,262.257080,13.360013,1.014655,-299.623688,0.101509,0.000000
91.450005,58.954376,-299.757141,0.000220,0.003995,0.101465,262.242157,13.359253,1.014655,-299.757141,0.101509,0.000000
91.690002,58.932037,-299.623688,0.000241,0.003995,0.101465,262.142792,13.354191,1.014655,-299.623688,0.101509,0.000000
91.930008,58.913048,-299.712646,0.000237,0.003995,0.101465,262.058319,13.349887,1.014655,-299.712646,0.101509,0.000000
92.170006,58.892197,-299.757141,0.000229,0.003995,0.101465,261.965576,13.345162,1.014655,-299.757141,0.101509,0.000000
92.410004,58.884003,-299.668182,0.000237,0.003995,0.101465,261.929138,13.343306,1.014655,-299.668182,0.101509,0.000000
92.650002,58.861656,-299.757141,0.000246,0.003995,0.101465,261.829712,13.338242,1.014655,-299.757141,0.101509,0.000000
92.890007,58.853836,-299.712646,0.000233,0.003995,0.101465,261.794952,13.336471,1.014655,-299.712646,0.101509,0.000000
93.130005,58.827400,-299.801605,0.000224,0.003995,0.101465,261.677338,13.330480,1.014655,-299.801605,0.101509,0.000000
93.370003,58.819580,-299.846100,0.000246,0.003995,0.101465,261.642548,13.328708,1.014655,-299.846100,0.101509,0.000000
93.610008,58.784203,-299.801605,0.000250,0.003995,0.101465,261.485199,13.320691,1.014655,-299.801605,0.101509,0.000000
93.850006,58.777130,-299.846100,0.000229,0.003995,0.101465,261.453735,13.319088,1.014655,-299.846100,0.101509,0.000000
94.090004,58.751060,-299.801605,0.000229,0.003995,0.101465,261.337769,13.313181,1.014655,-299.801605,0.101509,0.000000
94.330002,58.745110,-299.890564,0.000224,0.003995,0.101465,261.311310,13.311832,1.014655,-299.890564,0.101509,0.000000
94.570007,58.735428,-299.846100,0.000254,0.003995,0.101465,261.268219,13.309638,1.014655,-299.846100,0.101509,0.000000
94.810005,58.717178,-299.890564,0.000254,0.003995,0.101465,261.187042,13.305503,1.014655,-299.890564,0.101509,0.000000
95.050003,58.697067,-299.979523,0.000207,0.003995,0.101465,261.097595,13.300945,1.014655,-299.979523,0.101509,0.000000
95.290001,58.682175,-299.935059,0.000233,0.003995,0.101465,261.031342,13.297571,1.014655,-299.935059,0.101509,0.000000
95.530006,58.661697,-300.024017,0.000224,0.003995,0.101465,260.940277,13.292932,1.014655,-300.024017,0.101509,0.000000
95.770004,58.646797,-300.024017,0.000224,0.003995,0.101465,260.873993,13.289554,1.014655,-300.024017,0.101509,0.000000
96.010002,58.619614,-299.979523,0.000224,0.003995,0.101465,260.753052,13.283394,1.014655,-299.979523,0.101509,0.000000
96.250008,58.622223,-300.068481,0.000250,0.003995,0.101465,260.764679,13.283985,1.014655,-300.068481,0.101509,0.000000
96.490005,58.598022,-299.979523,0.000229,0.003995,0.101465,260.657013,13.278502,1.014655,-299.979523,0.101509,0.000000
96.730003,58.589828,-300.112976,0.000216,0.003995,0.101465,260.620575,13.276646,1.014655,-300.112976,0.101509,0.000000
96.970001,58.576797,-300.068481,0.000233,0.003995,0.101465,260.562622,13.273692,1.014655,-300.068481,0.101509,0.000000
97.210007,58.563385,-300.112976,0.000233,0.003995,0.101465,260.502960,13.270653,1.014655,-300.112976,0.101509,0.000000
97.450005,58.533226,-300.157471,0.000233,0.003995,0.101465,260.368805,13.263819,1.014655,-300.157471,0.101509,0.000000
97.690002,58.530617,-300.157471,0.000211,0.003995,0.101465,260.357178,13.263227,1.014655,-300.157471,0.101509,0.000000
97.930008,58.515724,-300.246429,0.000241,0.003995,0.101465,260.290955,13.259853,1.014655,-300.246429,0.101509,0.000000
98.170006,58.506042,-300.201935,0.000229,0.003995,0.101465,260.247864,13.257659,1.014655,-300.201935,0.101509,0.000000
98.410004,58.482956,-300.201935,0.000229,0.003995,0.101465,260.145172,13.252427,1.014655,-300.201935,0.101509,0.000000
98.650002,58.472900,-300.246429,0.000229,0.003995,0.101465,260.100464,13.250148,1.014655,-300.246429,0.101509,0.000000
98.890007,58.464340,-300.246429,0.000224,0.003995,0.101465,260.062378,13.248209,1.014655,-300.246429,0.101509,0.000000
99.000008,58.446838,-300.246429,0.000229,0.003995,0.101465,259.984528,13.244243,1.014655,-300.246429,0.101509,0.000000