File: Data/compression 13/AutoNoHeating-15-13-1-240724_07242024_165531.csv
Time (sec),S:Load (lbs),S:HL1 (DIM),S:LVDT (in),S:Position (in),Ch:Position (mm),Ch:Load (N),Ch:Stress (MPa),Ch:Strain (mm/mm),Ch:HL1 (DIM),Set Point (),Cycles ()
0.110000,-0.035744,-341.658173,-0.007114,-0.000000,-0.000000,-0.158996,-0.008100,-0.000000,-341.658173,0.000182,0.000000
0.340000,-0.033882,-341.613708,-0.007118,-0.000000,-0.000000,-0.150715,-0.007678,-0.000000,-341.613708,0.000182,0.000000
0.570000,-0.055481,-341.658173,-0.007123,0.000077,0.001951,-0.246792,-0.012572,0.019515,-341.658173,0.002732,0.000000
0.800000,0.008942,-341.613708,-0.007088,0.000207,0.005247,0.039774,0.002026,0.052466,-341.613708,0.006565,0.000000
1.030000,0.019363,-341.702667,-0.007036,0.000360,0.009149,0.086133,0.004388,0.091488,-341.702667,0.010398,0.000000
1.260000,0.007820,-341.747162,-0.006860,0.000519,0.013190,0.034786,0.001772,0.131904,-341.747162,0.014231,0.000000
1.490000,0.005211,-341.702667,-0.006726,0.000664,0.016876,0.023179,0.001181,0.168761,-341.702667,0.018065,0.000000
1.720000,0.012291,-341.702667,-0.006558,0.000821,0.020865,0.054673,0.002785,0.208654,-341.702667,0.021897,0.000000
1.950000,-0.007446,-341.702667,-0.006411,0.000962,0.024438,-0.033123,-0.001687,0.244383,-341.702667,0.025730,0.000000
2.180000,0.019737,-341.747162,-0.006256,0.001111,0.028211,0.087796,0.004473,0.282111,-341.747162,0.029564,0.000000
2.410000,-0.013779,-341.791626,-0.006105,0.001271,0.032287,-0.061291,-0.003122,0.322867,-341.791626,0.033396,0.000000
2.640000,-0.043938,-341.880585,-0.005959,0.001417,0.035990,-0.195445,-0.009956,0.359898,-341.880585,0.037230,0.000000
2.870000,-0.040588,-341.836121,-0.005795,0.001564,0.039728,-0.180546,-0.009197,0.397278,-341.836121,0.041046,0.000000
3.100000,0.009308,-341.836121,-0.005614,0.001724,0.043786,0.041403,0.002109,0.437859,-341.836121,0.044879,0.000000
3.330000,0.049896,-341.836121,-0.005476,0.001864,0.047333,0.221950,0.011307,0.473331,-341.836121,0.048712,0.000000
3.560000,0.039848,-341.880585,-0.005320,0.002024,0.051409,0.177254,0.009030,0.514087,-341.880585,0.052545,0.000000
3.790000,0.030533,-341.925079,-0.005170,0.002174,0.055216,0.135817,0.006919,0.552163,-341.925079,0.056378,0.000000
4.020000,-0.003349,-341.880585,-0.005023,0.002322,0.058971,-0.014898,-0.000759,0.589709,-341.880585,0.060212,0.000000
4.250000,0.030533,-341.880585,-0.004842,0.002470,0.062744,0.135817,0.006919,0.627437,-341.880585,0.064044,0.000000
4.480000,0.058838,-341.925079,-0.004682,0.002627,0.066733,0.261724,0.013333,0.667330,-341.925079,0.067878,0.000000
4.710000,0.287102,-342.014038,-0.004531,0.002780,0.070609,1.277092,0.065058,0.706095,-342.014038,0.071711,0.000000
4.940000,0.643837,-341.925079,-0.004462,-0.000011,-0.000269,2.863930,0.145896,-0.002687,-341.925079,-0.000034,0.000000
5.170000,0.615158,-341.969543,-0.004475,-0.000011,-0.000269,2.736360,0.139397,-0.002687,-341.969543,-0.000034,0.000000
5.400000,0.698196,-341.925079,-0.004454,-0.000011,-0.000269,3.105733,0.158214,-0.002687,-341.925079,0.000079,0.000000
5.630000,0.641968,-342.014038,-0.004462,-0.000010,-0.000260,2.855615,0.145472,-0.002596,-342.014038,0.000460,0.000000
5.860000,0.622604,-342.058502,-0.004471,-0.000010,-0.000260,2.769483,0.141084,-0.002596,-342.058502,0.000842,0.000000
6.090000,0.616653,-342.102997,-0.004467,-0.000010,-0.000260,2.743011,0.139736,-0.002596,-342.102997,0.001232,0.000000
6.320000,0.595795,-342.102997,-0.004454,-0.000010,-0.000251,2.650227,0.135009,-0.002513,-342.102997,0.001613,0.000000
6.550000,1.208725,-342.102997,-0.004462,0.000038,0.000963,5.376677,0.273901,0.009629,-342.102997,0.001995,0.000000
6.780000,1.305908,-342.102997,-0.004437,0.000045,0.001136,5.808970,0.295923,0.011362,-342.102997,0.002377,0.000000
7.010000,1.802284,-342.147461,-0.004385,0.000079,0.002012,8.016961,0.408403,0.020121,-342.147461,0.002758,0.000000
7.240000,1.976929,-342.102997,-0.004389,0.000092,0.002342,8.793818,0.447978,0.023421,-342.102997,0.003148,0.000000
7.470000,2.066666,-342.147461,-0.004368,0.000100,0.002533,9.192988,0.468313,0.025329,-342.147461,0.003530,0.000000
7.700000,2.333656,-342.102997,-0.004385,0.000114,0.002888,10.380622,0.528814,0.028879,-342.102997,0.003911,0.000000
7.930000,2.574211,-342.147461,-0.004363,0.000127,0.003226,11.450663,0.583325,0.032262,-342.147461,0.004293,0.000000
8.160001,3.016594,-342.191956,-0.004350,0.000148,0.003764,13.418480,0.683570,0.037645,-342.191956,0.004674,0.000000
8.390000,3.107819,-342.280914,-0.004346,0.000157,0.003981,13.824267,0.704242,0.039810,-342.280914,0.005065,0.000000
8.620001,3.441841,-342.191956,-0.004337,0.000172,0.004372,15.310074,0.779932,0.043716,-342.191956,0.005446,0.000000
8.850000,4.010078,-342.147461,-0.004320,0.000198,0.005039,17.837719,0.908697,0.050392,-342.147461,0.005828,0.000000
9.080001,4.188072,-342.236450,-0.004286,0.000211,0.005351,18.629475,0.949031,0.053511,-342.236450,0.006209,0.000000
9.310000,4.331810,-342.280914,-0.004286,0.000221,0.005611,19.268854,0.981602,0.056115,-342.280914,0.006591,0.000000
9.540001,4.598801,-342.236450,-0.004286,0.000234,0.005950,20.456488,1.042103,0.059499,-342.236450,0.006982,0.000000
9.770000,4.900795,-342.325409,-0.004281,0.000250,0.006340,21.799826,1.110536,0.063397,-342.325409,0.007363,0.000000
10.000000,5.441849,-342.280914,-0.004255,0.000272,0.006904,24.206553,1.233141,0.069036,-342.280914,0.007745,0.000000
10.230000,5.562500,-342.369873,-0.004221,0.000282,0.007163,24.743237,1.260481,0.071633,-342.369873,0.008126,0.000000
10.460000,5.696930,-342.414368,-0.004217,0.000290,0.007371,25.341209,1.290943,0.073715,-342.414368,0.008508,0.000000
10.690001,6.137070,-342.369873,-0.004208,0.000309,0.007840,27.299049,1.390680,0.078400,-342.369873,0.008898,0.000000
10.920000,6.634560,-342.369873,-0.004195,0.000327,0.008309,29.511995,1.503413,0.083086,-342.369873,0.009280,0.000000
11.150001,6.942886,-342.369873,-0.004178,0.000344,0.008733,30.883501,1.573281,0.087333,-342.369873,0.009661,0.000000
11.380000,7.193863,-342.503326,-0.004169,0.000357,0.009072,31.999901,1.630153,0.090716,-342.503326,0.010043,0.000000
11.610001,7.416916,-342.414368,-0.004156,0.000370,0.009393,32.992088,1.680697,0.093926,-342.414368,0.010433,0.000000
11.840000,7.931160,-342.458832,-0.004130,0.000391,0.009922,35.279560,1.797227,0.099217,-342.458832,0.010815,0.000000
12.070001,8.116600,-342.414368,-0.004118,0.000403,0.010234,36.104439,1.839248,0.102336,-342.414368,0.011196,0.000000
12.300000,8.267418,-342.458832,-0.004118,0.000414,0.010511,36.775311,1.873424,0.105114,-342.458832,0.011578,0.000000
12.530001,8.507965,-342.458832,-0.004079,0.000425,0.010806,37.845318,1.927932,0.108059,-342.458832,0.011960,0.000000
12.760000,9.329048,-342.458832,-0.004061,0.000455,0.011551,41.497677,2.113992,0.115515,-342.458832,0.012349,0.000000
12.990001,9.521194,-342.547791,-0.004074,0.000470,0.011950,42.352386,2.157533,0.119504,-342.547791,0.012731,0.000000
13.220000,9.472412,-342.547791,-0.004057,0.000479,0.012168,42.135395,2.146479,0.121677,-342.547791,0.013113,0.000000
13.450001,9.720039,-342.547791,-0.004049,0.000491,0.012480,43.236893,2.202592,0.124796,-342.547791,0.013495,0.000000
13.680000,10.252533,-342.547791,-0.004014,0.000511,0.012974,45.605545,2.323257,0.129739,-342.547791,0.013876,0.000000
13.910001,10.513939,-342.636780,-0.004005,0.000524,0.013312,46.768337,2.382493,0.133122,-342.636780,0.014266,0.000000
14.140000,10.702354,-342.681244,-0.003992,0.000537,0.013633,47.606449,2.425188,0.136332,-342.681244,0.014648,0.000000
14.370001,10.752258,-342.636780,-0.003997,0.000545,0.013841,47.828434,2.436496,0.138414,-342.636780,0.015029,0.000000
14.600000,10.756721,-342.681244,-0.003945,0.000551,0.014006,47.848286,2.437508,0.140064,-342.681244,0.015411,0.000000
14.830001,12.018692,-342.592285,-0.003958,0.000588,0.014925,53.461811,2.723475,0.149254,-342.592285,0.015793,0.000000
15.060000,11.828415,-342.681244,-0.003949,0.000597,0.015159,52.615417,2.680357,0.151593,-342.681244,0.016183,0.000000
15.290001,12.087585,-342.681244,-0.003898,0.000613,0.015567,53.768265,2.739086,0.155673,-342.681244,0.016564,0.000000
15.520000,12.255524,-342.681244,-0.003919,0.000626,0.015888,54.515293,2.777141,0.158882,-342.681244,0.016946,0.000000
15.750001,12.602203,-342.681244,-0.003885,0.000643,0.016330,56.057400,2.855700,0.163303,-342.681244,0.017327,0.000000
15.980000,12.855042,-342.725739,-0.003889,0.000656,0.016669,57.182079,2.912994,0.166687,-342.725739,0.017709,0.000000
16.210001,13.023727,-342.770203,-0.003885,0.000668,0.016972,57.932434,2.951219,0.169722,-342.770203,0.018099,0.000000
16.440001,13.009575,-342.814697,-0.003846,0.000677,0.017206,57.869480,2.948012,0.172061,-342.814697,0.018481,0.000000
16.670000,13.946838,-342.770203,-0.003842,0.000706,0.017934,62.038635,3.160399,0.179343,-342.770203,0.018862,0.000000
16.900002,14.072701,-342.770203,-0.003790,0.000720,0.018298,62.598499,3.188920,0.182985,-342.770203,0.019244,0.000000
17.130001,13.906624,-342.859161,-0.003798,0.000732,0.018594,61.859753,3.151286,0.185937,-342.859161,0.019625,0.000000
17.360001,14.276764,-342.859161,-0.003786,0.000748,0.018993,63.506218,3.235161,0.189926,-342.859161,0.020016,0.000000
17.590000,14.788773,-342.903656,-0.003751,0.000768,0.019504,65.783745,3.351184,0.195043,-342.903656,0.020398,0.000000
17.820002,14.831970,-342.859161,-0.003764,0.000782,0.019851,65.975899,3.360973,0.198510,-342.859161,0.020779,0.000000
18.050001,14.998795,-342.859161,-0.003734,0.000793,0.020155,66.717972,3.398776,0.201546,-342.859161,0.021161,0.000000
18.280001,15.021507,-342.859161,-0.003734,0.000804,0.020432,66.819000,3.403922,0.204324,-342.859161,0.021542,0.000000
18.510000,15.320892,-342.903656,-0.003686,0.000824,0.020927,68.150734,3.471764,0.209267,-342.903656,0.021933,0.000000
18.740002,16.063408,-342.948120,-0.003691,0.000845,0.021456,71.453606,3.640020,0.214558,-342.948120,0.022314,0.000000
18.970001,15.725288,-342.992615,-0.003695,0.000852,0.021629,69.949577,3.563401,0.216292,-342.992615,0.022696,0.000000
19.200001,16.122986,-342.948120,-0.003665,0.000870,0.022089,71.718620,3.653521,0.220886,-342.948120,0.023077,0.000000
19.430000,16.352364,-342.948120,-0.003613,0.000888,0.022566,72.738945,3.705499,0.225655,-342.948120,0.023459,0.000000
19.660002,16.617493,-343.081573,-0.003630,0.000902,0.022904,73.918297,3.765578,0.229039,-343.081573,0.023849,0.000000
19.890001,16.493126,-342.992615,-0.003596,0.000912,0.023155,73.365089,3.737396,0.231552,-342.992615,0.024231,0.000000
20.120001,16.351990,-343.037109,-0.003583,0.000916,0.023268,72.737282,3.705414,0.232680,-343.037109,0.024612,0.000000
20.350000,17.063225,-343.081573,-0.003561,0.000942,0.023918,75.901016,3.866582,0.239183,-343.081573,0.024994,0.000000
20.580002,17.762909,-343.081573,-0.003535,0.000965,0.024500,79.013367,4.025133,0.244996,-343.081573,0.025384,0.000000
20.810001,17.726051,-343.126068,-0.003531,0.000979,0.024864,78.849411,4.016781,0.248637,-343.126068,0.025765,0.000000
21.040001,17.644127,-343.170532,-0.003527,0.000990,0.025142,78.484993,3.998216,0.251415,-343.170532,0.026148,0.000000
21.270000,17.738335,-343.037109,-0.003497,0.001004,0.025497,78.904053,4.019564,0.254966,-343.037109,0.026529,0.000000
21.500002,17.973305,-343.126068,-0.003471,0.001017,0.025844,79.949249,4.072809,0.258440,-343.126068,0.026911,0.000000
21.730001,18.035118,-343.170532,-0.003445,0.001029,0.026148,80.224213,4.086816,0.261476,-343.170532,0.027300,0.000000
21.960001,18.480850,-343.170532,-0.003432,0.001047,0.026590,82.206924,4.187820,0.265896,-343.170532,0.027682,0.000000
22.190001,18.420151,-343.215027,-0.003415,0.001056,0.026833,81.936920,4.174066,0.268326,-343.215027,0.028063,0.000000
22.420002,18.819336,-343.215027,-0.003410,0.001075,0.027310,83.712585,4.264523,0.273095,-343.215027,0.028445,0.000000
22.650002,19.495934,-343.215027,-0.003397,0.001100,0.027934,86.722244,4.417841,0.279340,-343.215027,0.028827,0.000000
22.880001,19.272881,-343.259491,-0.003346,0.001111,0.028211,85.730057,4.367297,0.282111,-343.259491,0.029217,0.000000
23.110001,19.112762,-343.348450,-0.003350,0.001123,0.028515,85.017815,4.331014,0.285146,-343.348450,0.029599,0.000000
23.340002,19.438217,-343.259491,-0.003337,0.001139,0.028931,86.465508,4.404763,0.289310,-343.259491,0.029980,0.000000
23.570002,19.580093,-343.259491,-0.003307,0.001153,0.029287,87.096603,4.436913,0.292868,-343.259491,0.030362,0.000000
23.800001,19.929001,-343.303986,-0.003298,0.001171,0.029746,88.648621,4.515976,0.297462,-343.303986,0.030743,0.000000
24.030001,20.202324,-343.392944,-0.003281,0.001189,0.030206,89.864426,4.577912,0.302057,-343.392944,0.031134,0.000000
24.260000,20.537834,-343.348450,-0.003255,0.001206,0.030639,91.356850,4.653940,0.306395,-343.348450,0.031515,0.000000
24.490002,20.484581,-343.348450,-0.003234,0.001221,0.031013,91.119965,4.641872,0.310127,-343.348450,0.031897,0.000000
24.720001,20.230621,-343.303986,-0.003238,0.001229,0.031229,89.990295,4.584324,0.312292,-343.303986,0.032278,0.000000
24.950001,20.175888,-343.348450,-0.003199,0.001239,0.031472,89.746834,4.571922,0.314722,-343.348450,0.032660,0.000000
25.180000,20.578796,-343.437408,-0.003186,0.001257,0.031932,91.539055,4.663222,0.319316,-343.437408,0.033050,0.000000
25.410002,21.290771,-343.481903,-0.003160,0.001278,0.032461,94.706085,4.824558,0.324608,-343.481903,0.033432,0.000000
25.640001,21.327263,-343.481903,-0.003143,0.001291,0.032790,94.868401,4.832827,0.327901,-343.481903,0.033813,0.000000
25.870001,20.998459,-343.437408,-0.003134,0.001300,0.033007,93.405807,4.758318,0.330073,-343.437408,0.034195,0.000000
26.100000,21.705223,-343.437408,-0.003100,0.001322,0.033580,96.549652,4.918474,0.335796,-343.437408,0.034577,0.000000
26.330002,22.337135,-343.481903,-0.003083,0.001346,0.034187,99.360542,5.061667,0.341867,-343.481903,0.034967,0.000000
26.560001,21.846352,-343.526398,-0.003065,0.001354,0.034403,97.177429,4.950454,0.344032,-343.526398,0.035349,0.000000
26.790001,21.743576,-343.526398,-0.003040,0.001368,0.034759,96.720261,4.927165,0.347590,-343.526398,0.035730,0.000000
27.020000,22.282768,-343.526398,-0.003040,0.001386,0.035209,99.118706,5.049348,0.352094,-343.526398,0.036112,0.000000
27.250002,21.926033,-343.526398,-0.003005,0.001393,0.035392,97.531868,4.968510,0.353918,-343.526398,0.036493,0.000000
27.480001,22.462250,-343.526398,-0.002975,0.001413,0.035886,99.917076,5.090019,0.358861,-343.526398,0.036884,0.000000
27.710001,22.580292,-343.704315,-0.002975,0.001427,0.036250,100.442154,5.116767,0.362502,-343.704315,0.037265,0.000000
27.940001,22.531883,-343.659821,-0.002932,0.001438,0.036528,100.226822,5.105798,0.365280,-343.659821,0.037647,0.000000
28.170002,22.547897,-343.570862,-0.002940,0.001453,0.036918,100.298058,5.109427,0.369179,-343.570862,0.038028,0.000000
28.400002,23.738747,-343.570862,-0.002915,0.001481,0.037629,105.595222,5.379277,0.376294,-343.570862,0.038410,0.000000
28.630001,23.454628,-343.659821,-0.002897,0.001494,0.037941,104.331398,5.314895,0.379413,-343.659821,0.038800,0.000000
28.860001,23.377914,-343.748779,-0.002854,0.001506,0.038262,103.990158,5.297511,0.382623,-343.748779,0.039182,0.000000
29.090002,23.018204,-343.704315,-0.002863,0.001514,0.038453,102.390083,5.216000,0.384530,-343.704315,0.039564,0.000000
29.320002,23.497452,-343.659821,-0.002837,0.001533,0.038939,104.521889,5.324599,0.389390,-343.659821,0.039945,0.000000
29.550001,23.893654,-343.659821,-0.002828,0.001549,0.039338,106.284279,5.414379,0.393379,-343.659821,0.040335,0.000000
29.780001,23.762947,-343.748779,-0.002772,0.001560,0.039615,105.702866,5.384761,0.396150,-343.748779,0.040716,0.000000
30.010002,24.312569,-343.793274,-0.002794,0.001580,0.040136,108.147705,5.509307,0.401358,-343.793274,0.041098,0.000000
30.240002,25.015610,-343.793274,-0.002768,0.001602,0.040682,111.274986,5.668618,0.406816,-343.793274,0.041479,0.000000
30.470001,24.636909,-343.748779,-0.002734,0.001611,0.040916,109.590446,5.582803,0.409162,-343.748779,0.041862,0.000000
30.700001,24.398216,-343.748779,-0.002712,0.001622,0.041202,108.528687,5.528715,0.412024,-343.748779,0.042252,0.000000
30.930002,24.586639,-343.793274,-0.002703,0.001637,0.041584,109.366837,5.571412,0.415839,-343.793274,0.042633,0.000000
31.160002,25.195091,-343.837738,-0.002703,0.001658,0.042113,112.073364,5.709289,0.421130,-343.837738,0.043015,0.000000
31.390001,25.540657,-343.882233,-0.002686,0.001674,0.042529,113.610519,5.787595,0.425294,-343.882233,0.043396,0.000000
31.620001,25.088226,-343.882233,-0.002634,0.001682,0.042728,111.598007,5.685073,0.427284,-343.882233,0.043778,0.000000
31.850002,25.125458,-343.837738,-0.002621,0.001696,0.043067,111.763618,5.693510,0.430668,-343.837738,0.044168,0.000000
32.080002,25.602844,-343.837738,-0.002626,0.001714,0.043544,113.887138,5.801687,0.435437,-343.837738,0.044550,0.000000
32.310001,26.166611,-343.971191,-0.002578,0.001731,0.043977,116.394897,5.929439,0.439775,-343.971191,0.044931,0.000000
32.540001,26.104797,-343.926727,-0.002583,0.001746,0.044351,116.119942,5.915431,0.443506,-343.926727,0.045313,0.000000
32.770000,26.035164,-343.971191,-0.002561,0.001757,0.044637,115.810196,5.899652,0.446368,-343.971191,0.045694,0.000000
33.000000,26.224701,-343.926727,-0.002522,0.001774,0.045070,116.653297,5.942602,0.450698,-343.926727,0.046085,0.000000
33.230003,26.737465,-343.971191,-0.002509,0.001793,0.045530,118.934181,6.058796,0.455300,-343.971191,0.046466,0.000000
33.460003,26.661873,-343.971191,-0.002483,0.001805,0.045859,118.597931,6.041667,0.458593,-343.971191,0.046848,0.000000
33.690002,26.303276,-343.971191,-0.002492,0.001812,0.046033,117.002815,5.960408,0.460326,-343.971191,0.047229,0.000000
33.920002,27.360443,-344.060150,-0.002453,0.001838,0.046692,121.705330,6.199965,0.466920,-344.060150,0.047611,0.000000
34.150002,27.789787,-344.015686,-0.002449,0.001858,0.047195,123.615150,6.297256,0.471946,-344.015686,0.048002,0.000000
34.380001,27.660576,-344.060150,-0.002389,0.001870,0.047498,123.040390,6.267976,0.474982,-344.060150,0.048383,0.000000
34.610001,27.329536,-344.104645,-0.002393,0.001881,0.047784,121.567848,6.192962,0.477843,-344.104645,0.048765,0.000000
34.840000,27.267723,-344.104645,-0.002406,0.001897,0.048183,121.292892,6.178955,0.481832,-344.104645,0.049146,0.000000
35.070004,27.936874,-344.060150,-0.002358,0.001915,0.048643,124.269424,6.330586,0.486427,-344.060150,0.049528,0.000000
35.300003,27.650894,-344.060150,-0.002333,0.001923,0.048833,122.997322,6.265782,0.488335,-344.060150,0.049918,0.000000
35.530003,27.657967,-344.104645,-0.002294,0.001935,0.049154,123.028778,6.267385,0.491544,-344.104645,0.050300,0.000000
35.760002,27.839310,-344.149109,-0.002315,0.001950,0.049519,123.835434,6.308477,0.495193,-344.149109,0.050681,0.000000
35.990002,27.059937,-344.149109,-0.002289,0.001950,0.049528,120.368607,6.131869,0.495276,-344.149109,0.051063,0.000000
36.220001,29.451683,-344.193604,-0.002285,0.001990,0.050551,131.007629,6.673847,0.505511,-344.193604,0.051444,0.000000
36.450001,29.035744,-344.193604,-0.002259,0.002000,0.050811,129.157440,6.579594,0.508115,-344.193604,0.051834,0.000000
36.680000,29.094948,-344.193604,-0.002251,0.002015,0.051193,129.420792,6.593009,0.511930,-344.193604,0.052216,0.000000
36.910000,29.005211,-344.327057,-0.002233,0.002030,0.051557,129.021622,6.572675,0.515571,-344.327057,0.052598,0.000000
37.140003,29.257675,-344.238068,-0.002177,0.002045,0.051939,130.144638,6.629884,0.519386,-344.238068,0.052979,0.000000
37.370003,29.119904,-344.282562,-0.002177,0.002058,0.052285,129.531799,6.598664,0.522853,-344.282562,0.053361,0.000000
37.600002,29.221184,-344.282562,-0.002164,0.002072,0.052624,129.982315,6.621615,0.526237,-344.282562,0.053751,0.000000
37.830002,29.137032,-344.371521,-0.002130,0.002082,0.052884,129.607986,6.602545,0.528841,-344.371521,0.054132,0.000000
38.060001,30.668228,-344.327057,-0.002108,0.002114,0.053690,136.419098,6.949520,0.536902,-344.327057,0.054514,0.000000
38.290001,30.275375,-344.371521,-0.002082,0.002123,0.053924,134.671600,6.860498,0.539242,-344.371521,0.054896,0.000000
38.520000,30.102966,-344.327057,-0.002100,0.002136,0.054254,133.904678,6.821430,0.542542,-344.327057,0.055286,0.000000
38.750000,30.215790,-344.371521,-0.002039,0.002150,0.054618,134.406540,6.846996,0.546183,-344.371521,0.055667,0.000000
38.980003,30.684608,-344.327057,-0.002026,0.002171,0.055147,136.491959,6.953231,0.551474,-344.327057,0.056049,0.000000
39.210003,30.931122,-344.460480,-0.001996,0.002186,0.055529,137.588501,7.009092,0.555290,-344.460480,0.056431,0.000000
39.440002,30.522629,-344.416016,-0.001979,0.002196,0.055789,135.771439,6.916526,0.557894,-344.416016,0.056812,0.000000
39.670002,30.222870,-344.416016,-0.001975,0.002206,0.056041,134.438034,6.848600,0.560407,-344.416016,0.057203,0.000000
39.900002,31.813644,-344.460480,-0.001944,0.002236,0.056786,141.514160,7.209074,0.567863,-344.460480,0.057584,0.000000
40.130001,31.303490,-344.504974,-0.001923,0.002245,0.057020,139.244873,7.093472,0.570202,-344.504974,0.057966,0.000000
40.360001,30.877129,-344.549438,-0.001897,0.002254,0.057263,137.348328,6.996857,0.572632,-344.549438,0.058347,0.000000
40.590000,31.139648,-344.504974,-0.001897,0.002273,0.057732,138.516068,7.056345,0.577318,-344.504974,0.058729,0.000000
40.820004,31.617401,-344.549438,-0.001841,0.002290,0.058174,140.641220,7.164606,0.581738,-344.549438,0.059119,0.000000
41.050003,31.539574,-344.504974,-0.001837,0.002303,0.058486,140.295029,7.146969,0.584857,-344.504974,0.059501,0.000000
41.280003,31.399567,-344.549438,-0.001841,0.002314,0.058773,139.672241,7.115243,0.587726,-344.549438,0.059882,0.000000
41.510002,31.573090,-344.593933,-0.001807,0.002329,0.059162,140.444122,7.154564,0.591624,-344.593933,0.060264,0.000000
41.740002,31.947327,-344.593933,-0.001763,0.002348,0.059648,142.108810,7.239367,0.596484,-344.593933,0.060645,0.000000
41.970001,32.549454,-344.549438,-0.001746,0.002368,0.060143,144.787201,7.375812,0.601427,-344.549438,0.061036,0.000000
42.200001,32.199417,-344.638397,-0.001720,0.002379,0.060420,143.230164,7.296492,0.604198,-344.638397,0.061417,0.000000
42.430000,31.919395,-344.638397,-0.001694,0.002393,0.060776,141.984558,7.233038,0.607756,-344.638397,0.061799,0.000000
42.660004,31.768585,-344.638397,-0.001664,0.002405,0.061087,141.313721,7.198864,0.610874,-344.638397,0.062181,0.000000
42.890003,32.025146,-344.638397,-0.001669,0.002422,0.061513,142.454971,7.257002,0.615129,-344.638397,0.062562,0.000000
43.120003,31.803215,-344.682892,-0.001638,0.002434,0.061825,141.467773,7.206712,0.618247,-344.682892,0.062953,0.000000
43.350002,31.915298,-344.682892,-0.001613,0.002447,0.062146,141.966339,7.232110,0.621457,-344.682892,0.063334,0.000000
43.580002,31.927589,-344.727356,-0.001595,0.002464,0.062597,142.021011,7.234895,0.625969,-344.727356,0.063716,0.000000
43.810001,32.520409,-344.771851,-0.001591,0.002486,0.063143,144.658005,7.369230,0.631434,-344.771851,0.064097,0.000000
44.040001,32.860756,-344.727356,-0.001574,0.002501,0.063525,146.171936,7.446353,0.635249,-344.727356,0.064479,0.000000
44.270000,32.232933,-344.682892,-0.001505,0.002512,0.063811,143.379242,7.304087,0.638111,-344.682892,0.064869,0.000000
44.500004,32.345016,-344.771851,-0.001483,0.002527,0.064193,143.877823,7.329485,0.641926,-344.771851,0.065250,0.000000
44.730003,32.342781,-344.816345,-0.001496,0.002543,0.064600,143.867874,7.328979,0.645998,-344.816345,0.065632,0.000000
44.960003,32.431038,-344.860809,-0.001457,0.002560,0.065034,144.260468,7.348978,0.650336,-344.860809,0.066014,0.000000
45.190002,32.481682,-344.816345,-0.001427,0.002575,0.065398,144.485733,7.360455,0.653977,-344.816345,0.066395,0.000000
45.420002,32.461945,-344.860809,-0.001431,0.002589,0.065771,144.397934,7.355981,0.657709,-344.860809,0.066785,0.000000
45.650002,32.652222,-344.816345,-0.001371,0.002607,0.066213,145.244339,7.399099,0.662130,-344.816345,0.067167,0.000000
45.880001,32.755371,-344.860809,-0.001371,0.002624,0.066655,145.703171,7.422473,0.666550,-344.860809,0.067548,0.000000
46.110001,32.022919,-344.905304,-0.001332,0.002633,0.066872,142.445053,7.256497,0.668723,-344.905304,0.067930,0.000000
46.340004,31.771194,-344.905304,-0.001319,0.002644,0.067167,141.325333,7.199456,0.671667,-344.905304,0.068320,0.000000
46.570004,31.685173,-344.905304,-0.001306,0.002656,0.067462,140.942688,7.179963,0.674620,-344.905304,0.068702,0.000000
46.800003,32.446678,-344.905304,-0.001268,0.002679,0.068034,144.330032,7.352522,0.680342,-344.905304,0.069083,0.000000
47.030003,32.445183,-344.949768,-0.001246,0.002693,0.068407,144.323380,7.352184,0.684074,-344.949768,0.069465,0.000000
47.260002,32.002808,-344.994263,-0.001237,0.002701,0.068616,142.355591,7.251940,0.686156,-344.994263,0.069846,0.000000
47.490002,33.595444,-344.994263,-0.001194,0.002733,0.069413,149.440002,7.612836,0.694135,-344.994263,0.070237,0.000000
47.720001,33.681465,-344.994263,-0.001181,0.002748,0.069803,149.822647,7.632329,0.698033,-344.994263,0.070619,0.000000
47.950001,33.035767,-344.994263,-0.001155,0.002759,0.070072,146.950424,7.486012,0.700720,-344.994263,0.071000,0.000000
48.180004,32.792610,-345.083221,-0.001134,0.002771,0.070385,145.868820,7.430912,0.703847,-345.083221,0.071382,0.000000
48.410004,33.052895,-345.038727,-0.001117,0.002785,0.070740,147.026611,7.489893,0.707397,-345.038727,0.071763,0.000000
48.640003,32.440720,-345.038727,-0.001104,0.002793,0.070948,144.303528,7.351172,0.709479,-345.038727,0.072154,0.000000
48.870003,33.249138,-345.083221,-0.001087,0.002816,0.071520,147.899551,7.534362,0.715201,-345.083221,0.072535,0.000000
49.100002,33.244667,-345.083221,-0.001074,0.002826,0.071772,147.879669,7.533350,0.717722,-345.083221,0.072917,0.000000
49.330002,33.252487,-345.127686,-0.001026,0.002839,0.072110,147.914444,7.535121,0.721098,-345.127686,0.073298,0.000000
49.560001,34.942688,-345.172180,-0.001030,0.002871,0.072934,155.432846,7.918127,0.729342,-345.172180,0.073680,0.000000
49.790001,34.906197,-345.127686,-0.001018,0.002884,0.073246,155.270523,7.909857,0.732460,-345.127686,0.074070,0.000000
50.020004,34.604202,-345.172180,-0.000974,0.002895,0.073532,153.927185,7.841424,0.735322,-345.172180,0.074452,0.000000
50.250004,34.383759,-345.172180,-0.000949,0.002906,0.073810,152.946594,7.791471,0.738100,-345.172180,0.074833,0.000000
50.480003,34.156609,-345.216675,-0.000940,0.002918,0.074122,151.936188,7.739998,0.741219,-345.216675,0.075215,0.000000
50.710003,35.000778,-345.305634,-0.000910,0.002939,0.074643,155.691238,7.931290,0.746427,-345.305634,0.075596,0.000000
50.940002,35.059616,-345.261139,-0.000888,0.002950,0.074937,155.952957,7.944623,0.749371,-345.261139,0.075986,0.000000
51.170002,35.179886,-345.261139,-0.000875,0.002964,0.075293,156.487946,7.971876,0.752929,-345.261139,0.076369,0.000000
51.400002,35.920166,-345.261139,-0.000832,0.002983,0.075779,159.780884,8.139626,0.757789,-345.261139,0.076750,0.000000
51.630001,36.482079,-345.261139,-0.000815,0.003001,0.076221,162.280396,8.266957,0.762210,-345.261139,0.077132,0.000000
51.860001,36.076187,-345.350098,-0.000832,0.003012,0.076498,160.474899,8.174981,0.764980,-345.350098,0.077513,0.000000
52.090004,36.314133,-345.350098,-0.000811,0.003027,0.076889,161.533325,8.228900,0.768886,-345.350098,0.077903,0.000000
52.320004,36.633263,-345.394592,-0.000793,0.003040,0.077218,162.952896,8.301216,0.772179,-345.394592,0.078284,0.000000
52.550003,37.672554,-345.350098,-0.000789,0.003063,0.077799,167.575897,8.536722,0.777993,-345.350098,0.078667,0.000000
52.780003,37.820381,-345.350098,-0.000742,0.003076,0.078129,168.233459,8.570221,0.781286,-345.350098,0.079048,0.000000
53.010002,37.296082,-345.439056,-0.000724,0.003082,0.078284,165.901260,8.451413,0.782845,-345.439056,0.079430,0.000000
53.240002,37.640152,-345.483551,-0.000733,0.003098,0.078683,167.431763,8.529380,0.786834,-345.483551,0.079820,0.000000
53.470001,38.937500,-345.394592,-0.000724,0.003122,0.079300,173.202652,8.823363,0.792996,-345.394592,0.080201,0.000000
53.700001,39.194435,-345.483551,-0.000677,0.003135,0.079638,174.345551,8.881586,0.796380,-345.483551,0.080583,0.000000
53.930004,39.267426,-345.483551,-0.000673,0.003148,0.079959,174.670227,8.898126,0.799589,-345.483551,0.080964,0.000000
54.160004,39.549683,-345.528015,-0.000681,0.003164,0.080358,175.925781,8.962086,0.803579,-345.528015,0.081346,0.000000
54.390003,39.948120,-345.528015,-0.000655,0.003179,0.080739,177.698120,9.052374,0.807394,-345.528015,0.081736,0.000000
54.620003,40.622482,-345.483551,-0.000629,0.003194,0.081129,180.697830,9.205186,0.811292,-345.483551,0.082118,0.000000
54.850002,40.880913,-345.483551,-0.000608,0.003206,0.081442,181.847382,9.263747,0.814419,-345.483551,0.082499,0.000000
55.080002,40.933792,-345.572510,-0.000595,0.003220,0.081779,182.082596,9.275730,0.817795,-345.572510,0.082881,0.000000
55.310001,42.415085,-345.617004,-0.000586,0.003244,0.082404,188.671722,9.611395,0.824040,-345.617004,0.083271,0.000000
55.540001,43.372826,-345.617004,-0.000565,0.003262,0.082855,192.931961,9.828423,0.828551,-345.617004,0.083653,0.000000
55.770004,43.332611,-345.617004,-0.000543,0.003272,0.083106,192.753082,9.819310,0.831065,-345.617004,0.084035,0.000000
56.000004,43.293884,-345.528015,-0.000539,0.003283,0.083393,192.580811,9.810534,0.833926,-345.528015,0.084416,0.000000
56.230003,43.898994,-345.617004,-0.000535,0.003298,0.083774,195.272476,9.947654,0.837741,-345.617004,0.084798,0.000000
56.460003,44.870140,-345.705963,-0.000517,0.003318,0.084286,199.592346,10.167719,0.842858,-345.705963,0.085188,0.000000
56.690002,44.942749,-345.661469,-0.000504,0.003328,0.084529,199.915329,10.184173,0.845288,-345.661469,0.085570,0.000000
56.920002,45.222778,-345.617004,-0.000496,0.003341,0.084858,201.160965,10.247628,0.848581,-345.617004,0.085951,0.000000
57.150002,45.267456,-345.661469,-0.000479,0.003347,0.085023,201.359695,10.257751,0.850231,-345.661469,0.086333,0.000000
57.380001,47.864014,-345.705963,-0.000470,0.003382,0.085908,212.909760,10.846141,0.859080,-345.705963,0.086714,0.000000
57.610004,47.925079,-345.750427,-0.000466,0.003392,0.086150,213.181396,10.859979,0.861503,-345.750427,0.087105,0.000000
57.840004,47.904976,-345.794922,-0.000444,0.003401,0.086385,213.091980,10.855423,0.863849,-345.794922,0.087486,0.000000
58.070004,48.449013,-345.750427,-0.000427,0.003417,0.086784,215.511978,10.978703,0.867839,-345.750427,0.087868,0.000000
58.300003,49.397072,-345.794922,-0.000401,0.003436,0.087269,219.729156,11.193537,0.872691,-345.794922,0.088249,0.000000
58.530003,49.978714,-345.794922,-0.000405,0.003448,0.087573,222.316422,11.325338,0.875726,-345.794922,0.088631,0.000000
58.760002,50.512329,-345.883881,-0.000410,0.003462,0.087946,224.690063,11.446258,0.879458,-345.883881,0.089021,0.000000
58.990002,50.788254,-345.883881,-0.000397,0.003472,0.088197,225.917435,11.508782,0.881971,-345.883881,0.089403,0.000000
59.220001,51.308830,-345.839386,-0.000366,0.003484,0.088501,228.233078,11.626747,0.885007,-345.839386,0.089785,0.000000
59.450005,53.578072,-345.883881,-0.000366,0.003514,0.089255,238.327164,12.140965,0.892554,-345.883881,0.090166,0.000000
59.680004,53.643982,-345.883881,-0.000345,0.003523,0.089489,238.620346,12.155900,0.894893,-345.883881,0.090548,0.000000
59.910004,54.309776,-345.928345,-0.000345,0.003539,0.089888,241.581955,12.306771,0.898882,-345.928345,0.090937,0.000000
60.140003,54.864616,-345.972839,-0.000341,0.003556,0.090322,244.050003,12.432500,0.903220,-345.972839,0.091319,0.000000
60.370003,56.237923,-345.972839,-0.000310,0.003573,0.090756,250.158768,12.743695,0.907557,-345.972839,0.091700,0.000000
60.600002,56.790527,-345.972839,-0.000306,0.003587,0.091102,252.616882,12.868917,0.911024,-345.972839,0.092083,0.000000
60.830002,57.278336,-345.972839,-0.000306,0.003598,0.091398,254.786758,12.979456,0.913976,-345.972839,0.092464,0.000000
61.060001,57.327858,-346.061798,-0.000297,0.003608,0.091640,255.007050,12.990678,0.916399,-346.061798,0.092854,0.000000
61.290005,59.881592,-346.017303,-0.000280,0.003638,0.092412,266.366638,13.569363,0.924120,-346.017303,0.093236,0.000000
61.520004,59.849937,-345.972839,-0.000280,0.003644,0.092560,266.225830,13.562189,0.925596,-345.972839,0.093617,0.000000
61.750004,60.388016,-346.061798,-0.000280,0.003660,0.092959,268.619324,13.684120,0.929585,-346.061798,0.093999,0.000000
61.980003,61.175583,-346.061798,-0.000254,0.003672,0.093270,272.122589,13.862585,0.932704,-346.061798,0.094381,0.000000
62.210003,62.353401,-346.106293,-0.000259,0.003691,0.093739,277.361786,14.129482,0.937390,-346.106293,0.094771,0.000000
62.440002,62.943237,-346.106293,-0.000254,0.003701,0.094016,279.985504,14.263141,0.940160,-346.106293,0.095152,0.000000
62.670002,63.531204,-346.061798,-0.000229,0.003713,0.094311,282.600922,14.396377,0.943113,-346.061798,0.095534,0.000000
62.900002,64.681839,-346.106293,-0.000250,0.003732,0.094796,287.719177,14.657114,0.947965,-346.106293,0.095915,0.000000
63.130005,65.968018,-346.106293,-0.000233,0.003751,0.095274,293.440399,14.948566,0.952741,-346.106293,0.096297,0.000000
63.360004,67.272812,-346.150757,-0.000207,0.003768,0.095716,299.244415,15.244237,0.957162,-346.150757,0.096687,0.000000
63.590004,67.045670,-346.106293,-0.000207,0.003765,0.095638,298.234039,15.192766,0.956382,-346.106293,0.095837,0.000000
63.820004,66.353058,-346.239716,-0.000207,0.003765,0.095629,295.153137,15.035818,0.956292,-346.239716,0.095629,0.000000
64.050003,65.749802,-346.150757,-0.000177,0.003765,0.095621,292.469727,14.899118,0.956208,-346.150757,0.095629,0.000000
64.280006,65.218430,-346.150757,-0.000172,0.003765,0.095621,290.106049,14.778708,0.956208,-346.150757,0.095629,0.000000
64.510002,64.754089,-346.239716,-0.000168,0.003765,0.095621,288.040588,14.673486,0.956208,-346.239716,0.095629,0.000000
64.740005,64.311707,-346.284210,-0.000177,0.003765,0.095621,286.072754,14.573241,0.956208,-346.284210,0.095629,0.000000
64.970001,63.924438,-346.239716,-0.000177,0.003764,0.095612,284.350098,14.485485,0.956117,-346.239716,0.095629,0.000000
65.200005,63.591171,-346.284210,-0.000164,0.003764,0.095612,282.867645,14.409966,0.956117,-346.284210,0.095629,0.000000
65.430000,63.254913,-346.328674,-0.000151,0.003764,0.095612,281.371918,14.333768,0.956117,-346.328674,0.095629,0.000000
65.660004,62.981590,-346.328674,-0.000138,0.003764,0.095612,280.156097,14.271832,0.956117,-346.328674,0.095629,0.000000
65.889999,62.713112,-346.328674,-0.000155,0.003764,0.095612,278.961853,14.210995,0.956117,-346.328674,0.095629,0.000000
66.120003,62.468460,-346.373169,-0.000168,0.003764,0.095612,277.873596,14.155556,0.956117,-346.373169,0.095629,0.000000
66.350006,62.226418,-346.373169,-0.000172,0.003764,0.095612,276.796936,14.100707,0.956117,-346.373169,0.095629,0.000000
66.580002,62.033531,-346.373169,-0.000160,0.003764,0.095612,275.938934,14.056999,0.956117,-346.373169,0.095629,0.000000
66.810005,61.836548,-346.417633,-0.000155,0.003764,0.095612,275.062714,14.012362,0.956117,-346.417633,0.095629,0.000000
67.040001,61.633598,-346.462128,-0.000155,0.003764,0.095612,274.159943,13.966373,0.956117,-346.462128,0.095629,0.000000
67.270004,61.473854,-346.417633,-0.000160,0.003764,0.095612,273.449371,13.930175,0.956117,-346.417633,0.095629,0.000000
67.500000,61.306290,-346.417633,-0.000160,0.003764,0.095612,272.704010,13.892203,0.956117,-346.417633,0.095629,0.000000
67.730003,61.164413,-346.417633,-0.000151,0.003764,0.095612,272.072906,13.860054,0.956117,-346.417633,0.095629,0.000000
67.960007,61.015091,-346.551086,-0.000142,0.003764,0.095612,271.408691,13.826217,0.956117,-346.551086,0.095629,0.000000
68.190002,60.878799,-346.506622,-0.000147,0.003764,0.095612,270.802429,13.795333,0.956117,-346.506622,0.095629,0.000000
68.420006,60.750710,-346.551086,-0.000151,0.003764,0.095612,270.232666,13.766308,0.956117,-346.551086,0.095629,0.000000
68.650002,60.615906,-346.506622,-0.000164,0.003764,0.095612,269.633026,13.735761,0.956117,-346.506622,0.095629,0.000000
68.880005,60.513878,-346.506622,-0.000155,0.003764,0.095612,269.179169,13.712641,0.956117,-346.506622,0.095629,0.000000
69.110001,60.398071,-346.595581,-0.000138,0.003764,0.095612,268.664032,13.686399,0.956117,-346.595581,0.095629,0.000000
69.340004,60.301628,-346.551086,-0.000138,0.003764,0.095612,268.235046,13.664544,0.956117,-346.551086,0.095629,0.000000
69.570000,60.189545,-346.595581,-0.000125,0.003764,0.095612,267.736481,13.639145,0.956117,-346.595581,0.095629,0.000000
69.800003,60.090866,-346.595581,-0.000134,0.003764,0.095612,267.297516,13.616785,0.956117,-346.595581,0.095629,0.000000
70.030006,60.000748,-346.595581,-0.000121,0.003764,0.095612,266.896667,13.596363,0.956117,-346.595581,0.095629,0.000000
70.260002,59.906914,-346.640045,-0.000138,0.003764,0.095612,266.479248,13.575101,0.956117,-346.640045,0.095629,0.000000
70.490005,59.820892,-346.729004,-0.000151,0.003764,0.095612,266.096619,13.555608,0.956117,-346.729004,0.095629,0.000000
70.720001,59.740463,-346.773499,-0.000142,0.003764,0.095612,265.738861,13.537383,0.956117,-346.773499,0.095629,0.000000
70.950005,59.657791,-346.640045,-0.000125,0.003764,0.095612,265.371094,13.518648,0.956117,-346.640045,0.095629,0.000000
71.180000,59.581085,-346.640045,-0.000168,0.003764,0.095612,265.029907,13.501267,0.956117,-346.640045,0.095629,0.000000
71.410004,59.491714,-346.684540,-0.000138,0.003764,0.095612,264.632355,13.481015,0.956117,-346.684540,0.095629,0.000000
71.640007,59.429153,-346.817963,-0.000142,0.003764,0.095612,264.354065,13.466839,0.956117,-346.817963,0.095629,0.000000
71.870003,59.364365,-346.773499,-0.000142,0.003764,0.095612,264.065887,13.452157,0.956117,-346.773499,0.095629,0.000000
72.100006,59.295471,-346.729004,-0.000142,0.003764,0.095612,263.759430,13.436546,0.956117,-346.729004,0.095629,0.000000
72.330002,59.228073,-346.773499,-0.000138,0.003764,0.095612,263.459625,13.421273,0.956117,-346.773499,0.095629,0.000000
72.560005,59.155090,-346.773499,-0.000138,0.003764,0.095612,263.134979,13.404736,0.956117,-346.773499,0.095629,0.000000
72.790001,59.093277,-346.862457,-0.000134,0.003764,0.095612,262.860016,13.390728,0.956117,-346.862457,0.095629,0.000000
73.020004,59.033325,-346.906952,-0.000134,0.003764,0.095612,262.593353,13.377142,0.956117,-346.906952,0.095629,0.000000
73.250000,58.987526,-346.817963,-0.000142,0.003764,0.095612,262.389618,13.366765,0.956117,-346.817963,0.095629,0.000000
73.480003,58.917892,-346.817963,-0.000108,0.003764,0.095612,262.079865,13.350986,0.956117,-346.817963,0.095629,0.000000
73.710007,58.861290,-346.817963,-0.000134,0.003764,0.095612,261.828094,13.338159,0.956117,-346.817963,0.095629,0.000000
73.940002,58.809898,-346.906952,-0.000125,0.003764,0.095612,261.599487,13.326513,0.956117,-346.906952,0.095629,0.000000
74.170006,58.766708,-346.906952,-0.000125,0.003764,0.095612,261.407379,13.316727,0.956117,-346.906952,0.095629,0.000000
74.400002,58.716438,-346.951416,-0.000125,0.003764,0.095612,261.183777,13.305335,0.956117,-346.951416,0.095629,0.000000
74.630005,58.656853,-346.951416,-0.000116,0.003764,0.095612,260.918701,13.291833,0.956117,-346.951416,0.095629,0.000000
74.860001,58.600998,-346.951416,-0.000129,0.003764,0.095612,260.670258,13.279176,0.956117,-346.951416,0.095629,0.000000
75.090004,58.565628,-346.995911,-0.000121,0.003764,0.095612,260.512939,13.271161,0.956117,-346.995911,0.095629,0.000000
75.320007,58.516472,-347.084869,-0.000129,0.003764,0.095612,260.294281,13.260022,0.956117,-347.084869,0.095629,0.000000
75.550003,58.461357,-346.995911,-0.000125,0.003764,0.095612,260.049103,13.247533,0.956117,-346.995911,0.095629,0.000000
75.780006,58.424126,-346.995911,-0.000125,0.003764,0.095612,259.883484,13.239096,0.956117,-346.995911,0.095629,0.000000
76.010002,58.389122,-346.995911,-0.000125,0.003764,0.095612,259.727783,13.231164,0.956117,-346.995911,0.095629,0.000000
76.240005,58.355232,-347.084869,-0.000125,0.003764,0.095612,259.577026,13.223485,0.956117,-347.084869,0.095629,0.000000
76.470001,58.293045,-347.084869,-0.000112,0.003764,0.095612,259.300415,13.209393,0.956117,-347.084869,0.095629,0.000000
76.700005,58.255814,-347.040375,-0.000151,0.003764,0.095612,259.134796,13.200955,0.956117,-347.040375,0.095629,0.000000
76.930000,58.208893,-347.129333,-0.000134,0.003764,0.095612,258.926086,13.190323,0.956117,-347.129333,0.095629,0.000000
77.160004,58.175003,-347.129333,-0.000138,0.003764,0.095612,258.775330,13.182644,0.956117,-347.129333,0.095629,0.000000
77.390007,58.133675,-347.129333,-0.000125,0.003764,0.095612,258.591492,13.173280,0.956117,-347.129333,0.095629,0.000000
77.620003,58.108353,-347.173828,-0.000112,0.003764,0.095612,258.478851,13.167541,0.956117,-347.173828,0.095629,0.000000
77.850006,58.057335,-347.218292,-0.000116,0.003764,0.095612,258.251923,13.155980,0.956117,-347.218292,0.095629,0.000000
78.080002,58.034996,-347.173828,-0.000116,0.003764,0.095612,258.152557,13.150918,0.956117,-347.173828,0.095629,0.000000
78.310005,57.998871,-347.173828,-0.000116,0.003764,0.095612,257.991852,13.142733,0.956117,-347.173828,0.095629,0.000000
78.540001,57.957916,-347.218292,-0.000129,0.003764,0.095612,257.809692,13.133451,0.956117,-347.218292,0.095629,0.000000
78.770004,57.922913,-347.218292,-0.000108,0.003764,0.095612,257.653992,13.125520,0.956117,-347.218292,0.095629,0.000000
79.000000,57.890144,-347.307251,-0.000147,0.003764,0.095612,257.508209,13.118094,0.956117,-347.307251,0.095629,0.000000
79.230003,57.861099,-347.262787,-0.000129,0.003764,0.095612,257.379028,13.111512,0.956117,-347.262787,0.095629,0.000000
79.460007,57.834282,-347.262787,-0.000121,0.003764,0.095612,257.259735,13.105435,0.956117,-347.262787,0.095629,0.000000
79.690002,57.789230,-347.307251,-0.000129,0.003764,0.095612,257.059326,13.095227,0.956117,-347.307251,0.095629,0.000000
79.920006,57.771355,-347.396240,-0.000121,0.003764,0.095612,256.979828,13.091176,0.956117,-347.396240,0.095629,0.000000
80.150002,57.748642,-347.396240,-0.000112,0.003764,0.095612,256.878784,13.086029,0.956117,-347.396240,0.095629,0.000000
80.380005,57.687943,-347.396240,-0.000125,0.003764,0.095612,256.608795,13.072275,0.956117,-347.396240,0.095629,0.000000
80.610001,57.674164,-347.307251,-0.000125,0.003764,0.095612,256.547485,13.069152,0.956117,-347.307251,0.095629,0.000000
80.840004,57.643631,-347.396240,-0.000108,0.003764,0.095612,256.411682,13.062233,0.956117,-347.396240,0.095629,0.000000
81.070007,57.633949,-347.485199,-0.000112,0.003764,0.095612,256.368622,13.060040,0.956117,-347.485199,0.095629,0.000000
81.300003,57.588890,-347.440704,-0.000121,0.003764,0.095612,256.168182,13.049829,0.956117,-347.440704,0.095629,0.000000
81.530006,57.557983,-347.440704,-0.000116,0.003764,0.095612,256.030701,13.042826,0.956117,-347.440704,0.095629,0.000000
81.760002,57.554634,-347.396240,-0.000129,0.003764,0.095612,256.015808,13.042067,0.956117,-347.396240,0.095629,0.000000
81.990005,57.525589,-347.485199,-0.000099,0.003764,0.095612,255.886597,13.035484,0.956117,-347.485199,0.095629,0.000000
82.220001,57.487610,-347.485199,-0.000121,0.003764,0.095612,255.717667,13.026878,0.956117,-347.485199,0.095629,0.000000
82.450005,57.454094,-347.485199,-0.000099,0.003764,0.095612,255.568573,13.019284,0.956117,-347.485199,0.095629,0.000000
82.680000,57.432495,-347.529663,-0.000116,0.003764,0.095612,255.472504,13.014389,0.956117,-347.529663,0.095629,0.000000
82.910004,57.409409,-347.485199,-0.000116,0.003764,0.095612,255.369797,13.009158,0.956117,-347.485199,0.095629,0.000000
83.140007,57.373657,-347.529663,-0.000099,0.003764,0.095612,255.210770,13.001057,0.956117,-347.529663,0.095629,0.000000
83.370003,57.371429,-347.529663,-0.000121,0.003764,0.095612,255.200867,13.000551,0.956117,-347.529663,0.095629,0.000000
83.600006,57.351318,-347.618622,-0.000134,0.003764,0.095612,255.111404,12.995995,0.956117,-347.618622,0.095629,0.000000
83.830002,57.317802,-347.574158,-0.000125,0.003764,0.095612,254.962326,12.988400,0.956117,-347.574158,0.095629,0.000000
84.060005,57.288391,-347.574158,-0.000103,0.003764,0.095612,254.831497,12.981735,0.956117,-347.574158,0.095629,0.000000
84.290001,57.265671,-347.574158,-0.000116,0.003764,0.095612,254.730423,12.976586,0.956117,-347.574158,0.095629,0.000000
84.520004,57.251526,-347.663116,-0.000112,0.003764,0.095612,254.667511,12.973381,0.956117,-347.663116,0.095629,0.000000
84.750008,57.215401,-347.707581,-0.000125,0.003764,0.095612,254.506821,12.965195,0.956117,-347.707581,0.095629,0.000000
84.980003,57.201256,-347.663116,-0.000151,0.003764,0.095612,254.443893,12.961990,0.956117,-347.663116,0.095629,0.000000
85.210007,57.181145,-347.707581,-0.000103,0.003764,0.095612,254.354431,12.957433,0.956117,-347.707581,0.095629,0.000000
85.440002,57.146515,-347.707581,-0.000112,0.003764,0.095612,254.200394,12.949586,0.956117,-347.707581,0.095629,0.000000
85.670006,57.140930,-347.707581,-0.000112,0.003764,0.095612,254.175552,12.948320,0.956117,-347.707581,0.095629,0.000000
85.900002,57.113747,-347.752075,-0.000121,0.003764,0.095612,254.054626,12.942161,0.956117,-347.752075,0.095629,0.000000
86.130005,57.101456,-347.841034,-0.000142,0.003764,0.095612,253.999954,12.939375,0.956117,-347.841034,0.095629,0.000000
86.360001,57.070923,-347.841034,-0.000116,0.003764,0.095612,253.864151,12.932456,0.956117,-347.841034,0.095629,0.000000
86.590004,57.054909,-347.752075,-0.000099,0.003764,0.095612,253.792908,12.928827,0.956117,-347.752075,0.095629,0.000000
86.820007,57.042618,-347.796570,-0.000112,0.003764,0.095612,253.738235,12.926042,0.956117,-347.796570,0.095629,0.000000
87.050003,57.007988,-347.885529,-0.000112,0.003764,0.095612,253.584198,12.918195,0.956117,-347.885529,0.095629,0.000000
87.280006,56.997192,-347.841034,-0.000125,0.003764,0.095612,253.536179,12.915749,0.956117,-347.841034,0.095629,0.000000
87.510002,56.972984,-347.841034,-0.000112,0.003764,0.095612,253.428497,12.910262,0.956117,-347.841034,0.095629,0.000000
87.740005,56.953995,-347.841034,-0.000099,0.003764,0.095612,253.344025,12.905959,0.956117,-347.841034,0.095629,0.000000
87.970001,56.937988,-347.885529,-0.000112,0.003764,0.095612,253.272827,12.902332,0.956117,-347.885529,0.095629,0.000000
88.200005,56.911545,-347.974487,-0.000103,0.003764,0.095612,253.155197,12.896340,0.956117,-347.974487,0.095629,0.000000
88.430008,56.898140,-348.018951,-0.000095,0.003764,0.095612,253.095566,12.893303,0.956117,-348.018951,0.095629,0.000000
88.660004,56.879898,-347.929993,-0.000121,0.003764,0.095612,253.014420,12.889170,0.956117,-347.929993,0.095629,0.000000
88.890007,56.860535,-347.929993,-0.000108,0.003764,0.095612,252.928284,12.884781,0.956117,-347.929993,0.095629,0.000000
89.120003,56.846008,-347.929993,-0.000125,0.003764,0.095612,252.863678,12.881489,0.956117,-347.929993,0.095629,0.000000
89.350006,56.815102,-347.974487,-0.000125,0.003764,0.095612,252.726196,12.874486,0.956117,-347.974487,0.095629,0.000000
89.580002,56.802444,-347.929993,-0.000121,0.003764,0.095612,252.669891,12.871618,0.956117,-347.929993,0.095629,0.000000
89.810005,56.793877,-347.974487,-0.000116,0.003764,0.095612,252.631775,12.869677,0.956117,-347.974487,0.095629,0.000000
90.040001,56.769302,-348.063446,-0.000125,0.003764,0.095612,252.522476,12.864108,0.956117,-348.063446,0.095629,0.000000
90.270004,56.755524,-348.018951,-0.000095,0.003764,0.095612,252.461182,12.860986,0.956117,-348.018951,0.095629,0.000000
90.500008,56.744720,-348.107910,-0.000112,0.003764,0.095612,252.413116,12.858538,0.956117,-348.107910,0.095629,0.000000
90.730003,56.712700,-348.107910,-0.000125,0.003764,0.095612,252.270691,12.851282,0.956117,-348.107910,0.095629,0.000000
90.960007,56.695198,-348.107910,-0.000129,0.003764,0.095612,252.192841,12.847316,0.956117,-348.107910,0.095629,0.000000
91.190002,56.686264,-348.063446,-0.000129,0.003764,0.095612,252.153091,12.845291,0.956117,-348.063446,0.095629,0.000000
91.420006,56.665779,-348.063446,-0.000129,0.003764,0.095612,252.061981,12.840650,0.956117,-348.063446,0.095629,0.000000
91.650002,56.647163,-348.152405,-0.000121,0.003764,0.095612,251.979172,12.836431,0.956117,-348.152405,0.095629,0.000000
91.880005,56.629288,-348.196899,-0.000116,0.003764,0.095612,251.899658,12.832379,0.956117,-348.196899,0.095629,0.000000
92.110001,56.621468,-348.196899,-0.000125,0.003764,0.095612,251.864868,12.830607,0.956117,-348.196899,0.095629,0.000000
92.340004,56.595406,-348.196899,-0.000103,0.003764,0.095612,251.748932,12.824702,0.956117,-348.196899,0.095629,0.000000
92.570007,56.590561,-348.107910,-0.000108,0.003764,0.095612,251.727386,12.823605,0.956117,-348.107910,0.095629,0.000000
92.800003,56.568588,-348.196899,-0.000116,0.003764,0.095612,251.629654,12.818624,0.956117,-348.196899,0.095629,0.000000
93.030006,56.542900,-348.241364,-0.000108,0.003764,0.095612,251.515381,12.812804,0.956117,-348.241364,0.095629,0.000000
93.260002,56.524651,-348.241364,-0.000108,0.003764,0.095612,251.434204,12.808668,0.956117,-348.241364,0.095629,0.000000
93.490005,56.529495,-348.241364,-0.000125,0.003764,0.095612,251.455750,12.809767,0.956117,-348.241364,0.095629,0.000000
93.720001,56.516457,-348.285858,-0.000103,0.003764,0.095612,251.397751,12.806812,0.956117,-348.285858,0.095629,0.000000
93.900002,56.488159,-348.285858,-0.000103,0.003764,0.095612,251.271881,12.800400,0.956117,-348.285858,0.095629,0.000000