File: Data/compression 13/AutoNoHeating-12-13-1-240724_07242024_163643.csv
Time (sec),S:Load (lbs),S:HL1 (DIM),S:LVDT (in),S:Position (in),Ch:Position (mm),Ch:Load (N),Ch:Stress (MPa),Ch:Strain (mm/mm),Ch:HL1 (DIM),Set Point (),Cycles ()
0.110000,0.011543,-249.271255,-0.008890,-0.004198,-0.106617,0.051347,0.002616,-1.066167,-249.271255,-0.106391,0.000000
0.360000,0.013405,-249.271255,-0.008864,-0.004198,-0.106617,0.059628,0.003038,-1.066167,-249.271255,-0.106391,0.000000
0.610000,0.010422,-249.360214,-0.008908,-0.004103,-0.104206,0.046358,0.002362,-1.042057,-249.360214,-0.103252,0.000000
0.860000,-0.000748,-249.404694,-0.008817,-0.003951,-0.100347,-0.003326,-0.000169,-1.003466,-249.404694,-0.099089,0.000000
1.110000,0.073357,-249.360214,-0.008649,-0.003787,-0.096201,0.326307,0.016623,-0.962011,-249.360214,-0.094926,0.000000
1.360000,0.060326,-249.449173,-0.008494,-0.003615,-0.091830,0.268342,0.013670,-0.918303,-249.449173,-0.090764,0.000000
1.610000,0.032768,-249.449173,-0.008330,-0.003457,-0.087797,0.145760,0.007425,-0.877975,-249.449173,-0.086584,0.000000
1.860000,0.052132,-249.449173,-0.008136,-0.003294,-0.083679,0.231893,0.011813,-0.836787,-249.449173,-0.082421,0.000000
2.110000,0.053993,-249.493652,-0.007998,-0.003133,-0.079577,0.240174,0.012235,-0.795767,-249.493652,-0.078258,0.000000
2.360000,0.039467,-249.493652,-0.007800,-0.002965,-0.075310,0.175557,0.008943,-0.753096,-249.493652,-0.074095,0.000000
2.610000,0.033882,-249.582611,-0.007653,-0.002800,-0.071112,0.150715,0.007678,-0.711121,-249.582611,-0.069933,0.000000
2.860000,0.048409,-249.493652,-0.007463,-0.002640,-0.067045,0.215332,0.010970,-0.670449,-249.493652,-0.065770,0.000000
3.110000,0.037605,-249.582611,-0.007269,-0.002465,-0.062614,0.167277,0.008521,-0.626135,-249.582611,-0.061607,0.000000
3.360000,0.043938,-249.627090,-0.007114,-0.002311,-0.058711,0.195445,0.009956,-0.587113,-249.627090,-0.057445,0.000000
3.610000,0.066284,-249.538132,-0.006950,-0.002146,-0.054496,0.294847,0.015020,-0.544964,-249.538132,-0.053265,0.000000
3.860000,0.087509,-249.627090,-0.006782,-0.001972,-0.050099,0.389260,0.019830,-0.500991,-249.627090,-0.049102,0.000000
4.110000,0.065536,-249.671585,-0.006614,-0.001815,-0.046102,0.291521,0.014851,-0.461015,-249.671585,-0.044940,0.000000
4.360000,0.051758,-249.671585,-0.006428,-0.001652,-0.041956,0.230230,0.011728,-0.419563,-249.671585,-0.040777,0.000000
4.610000,0.075218,-249.760544,-0.006269,-0.001493,-0.037932,0.334587,0.017045,-0.379322,-249.760544,-0.036614,0.000000
4.860000,0.039101,-249.760544,-0.006066,-0.001323,-0.033596,0.173928,0.008860,-0.335962,-249.760544,-0.032452,0.000000
5.110000,0.015640,-249.760544,-0.005946,-0.001161,-0.029494,0.069571,0.003544,-0.294942,-249.760544,-0.028289,0.000000
5.360000,0.072243,-249.760544,-0.005752,-0.001000,-0.025392,0.321352,0.016370,-0.253921,-249.760544,-0.024126,0.000000
5.610000,0.074471,-249.849503,-0.005588,-0.000829,-0.021047,0.331261,0.016875,-0.210470,-249.849503,-0.019946,0.000000
5.860000,0.053246,-249.760544,-0.005415,-0.000668,-0.016963,0.236848,0.012066,-0.169631,-249.760544,-0.015783,0.000000
6.110000,0.074471,-249.849503,-0.005243,-0.000503,-0.012783,0.331261,0.016875,-0.127831,-249.849503,-0.011620,0.000000
6.360000,0.068886,-249.893982,-0.005066,-0.000347,-0.008802,0.306419,0.015610,-0.088022,-249.893982,-0.007458,0.000000
6.610000,0.087509,-249.938461,-0.004889,-0.000174,-0.004423,0.389260,0.019830,-0.044230,-249.938461,-0.003295,0.000000
6.860000,0.208527,-249.938461,-0.004721,-0.000014,-0.000364,0.927573,0.047253,-0.003641,-249.938461,0.000867,0.000000
7.110000,0.702667,-249.893982,-0.004557,-0.000003,-0.000070,3.125620,0.159227,-0.000696,-249.893982,0.000086,0.000000
7.360000,0.605103,-249.982941,-0.004549,-0.000005,-0.000121,2.691631,0.137118,-0.001211,-249.982941,0.000086,0.000000
7.610000,0.596169,-249.938461,-0.004549,-0.000005,-0.000121,2.651890,0.135094,-0.001211,-249.938461,0.000086,0.000000
7.860001,0.558182,-250.071899,-0.004536,-0.000005,-0.000121,2.482917,0.126486,-0.001211,-250.071899,0.000434,0.000000
8.110001,0.558929,-250.027420,-0.004557,-0.000005,-0.000121,2.486242,0.126655,-0.001211,-250.027420,0.000850,0.000000
8.360001,0.541428,-250.116394,-0.004553,0.000002,0.000061,2.408390,0.122689,0.000606,-250.116394,0.001266,0.000000
8.610001,0.802834,-250.071899,-0.004544,0.000033,0.000850,3.571182,0.181925,0.008501,-250.071899,0.001682,0.000000
8.860001,0.913803,-250.071899,-0.004514,0.000053,0.001335,4.064799,0.207071,0.013353,-250.071899,0.002107,0.000000
9.110001,0.993492,-250.160873,-0.004527,0.000064,0.001621,4.419274,0.225129,0.016214,-250.160873,0.002524,0.000000
9.360001,1.059395,-250.160873,-0.004514,0.000079,0.001995,4.712424,0.240062,0.019946,-250.160873,0.002940,0.000000
9.610001,1.129402,-250.205353,-0.004480,0.000091,0.002316,5.023832,0.255926,0.023156,-250.205353,0.003356,0.000000
9.860001,1.372566,-250.205353,-0.004462,0.000111,0.002818,6.105480,0.311028,0.028182,-250.205353,0.003772,0.000000
10.110001,1.359161,-250.249832,-0.004454,0.000115,0.002923,6.045852,0.307990,0.029227,-250.249832,0.004188,0.000000
10.360001,1.627266,-250.249832,-0.004462,0.000140,0.003547,7.238441,0.368744,0.035472,-250.249832,0.004605,0.000000
10.610001,1.855156,-250.294312,-0.004432,0.000162,0.004119,8.252146,0.420384,0.041195,-250.294312,0.005021,0.000000
10.860001,2.015648,-250.383270,-0.004376,0.000182,0.004631,8.966049,0.456752,0.046312,-250.383270,0.005437,0.000000
11.110001,2.112099,-250.338791,-0.004385,0.000193,0.004891,9.395084,0.478608,0.048908,-250.338791,0.005854,0.000000
11.360001,2.326584,-250.383270,-0.004355,0.000210,0.005325,10.349162,0.527211,0.053246,-250.383270,0.006270,0.000000
11.610001,2.463615,-250.338791,-0.004355,0.000223,0.005671,10.958709,0.558263,0.056713,-250.338791,0.006686,0.000000
11.860001,2.783112,-250.383270,-0.004359,0.000243,0.006175,12.379899,0.630662,0.061747,-250.383270,0.007103,0.000000
12.110001,2.860191,-250.427750,-0.004307,0.000253,0.006426,12.722767,0.648129,0.064260,-250.427750,0.007519,0.000000
12.360001,3.099258,-250.427750,-0.004303,0.000268,0.006817,13.786190,0.702302,0.068166,-250.427750,0.007935,0.000000
12.610001,3.494713,-250.472229,-0.004277,0.000292,0.007415,15.545259,0.791913,0.074146,-250.472229,0.008351,0.000000
12.860001,3.692444,-250.472229,-0.004264,0.000312,0.007918,16.424810,0.836720,0.079180,-250.472229,0.008767,0.000000
13.110001,3.731171,-250.561203,-0.004273,0.000322,0.008187,16.597076,0.845495,0.081867,-250.561203,0.009184,0.000000
13.360001,3.970978,-250.561203,-0.004234,0.000338,0.008577,17.663792,0.899836,0.085766,-250.561203,0.009600,0.000000
13.610001,4.232384,-250.561203,-0.004247,0.000355,0.009019,18.826584,0.959072,0.090194,-250.561203,0.010016,0.000000
13.860001,4.607735,-250.605682,-0.004212,0.000376,0.009539,20.496227,1.044128,0.095394,-250.605682,0.010441,0.000000
14.110001,4.666946,-250.650162,-0.004195,0.000387,0.009817,20.759615,1.057545,0.098173,-250.650162,0.010857,0.000000
14.360001,4.983086,-250.694641,-0.004195,0.000404,0.010259,22.165873,1.129183,0.102593,-250.694641,0.011274,0.000000
14.610001,5.327904,-250.650162,-0.004165,0.000423,0.010745,23.699699,1.207320,0.107446,-250.650162,0.011690,0.000000
14.860001,5.627663,-250.694641,-0.004135,0.000444,0.011274,25.033094,1.275247,0.112737,-250.694641,0.012106,0.000000
15.110001,5.670486,-250.739120,-0.004126,0.000456,0.011595,25.223583,1.284951,0.115946,-250.739120,0.012523,0.000000
15.360001,5.920349,-250.739120,-0.004092,0.000471,0.011968,26.335028,1.341570,0.119678,-250.739120,0.012939,0.000000
15.610001,6.226814,-250.828079,-0.004079,0.000488,0.012393,27.698254,1.411016,0.123925,-250.828079,0.013355,0.000000
15.860001,6.489708,-250.828079,-0.004074,0.000504,0.012809,28.867662,1.470589,0.128088,-250.828079,0.013772,0.000000
16.110001,6.559341,-250.783600,-0.004066,0.000517,0.013138,29.177408,1.486368,0.131381,-250.783600,0.014188,0.000000
16.360001,6.904900,-250.872559,-0.004083,0.000538,0.013667,30.714527,1.564673,0.136673,-250.872559,0.014604,0.000000
16.610001,7.352493,-250.872559,-0.004010,0.000562,0.014266,32.705524,1.666099,0.142660,-250.872559,0.015020,0.000000
16.860001,7.320099,-250.917038,-0.004005,0.000572,0.014535,32.561424,1.658758,0.145348,-250.917038,0.015436,0.000000
17.110001,7.494736,-250.917038,-0.004005,0.000588,0.014942,33.338249,1.698331,0.149420,-250.917038,0.015853,0.000000
17.360001,7.722260,-250.961533,-0.003975,0.000602,0.015298,34.350327,1.749889,0.152978,-250.961533,0.016269,0.000000
17.610001,8.059258,-250.917038,-0.003988,0.000623,0.015827,35.849369,1.826254,0.158269,-250.917038,0.016685,0.000000
17.860001,8.226082,-250.961533,-0.003915,0.000638,0.016199,36.591438,1.864057,0.161994,-250.961533,0.017102,0.000000
18.110001,8.164268,-251.006012,-0.003928,0.000645,0.016373,36.316479,1.850050,0.163735,-251.006012,0.017518,0.000000
18.360001,8.881454,-251.050491,-0.003906,0.000673,0.017093,39.506683,2.012566,0.170926,-251.050491,0.017934,0.000000
18.610001,8.917206,-251.094971,-0.003872,0.000690,0.017526,39.665714,2.020668,0.175263,-251.094971,0.018351,0.000000
18.860001,8.957047,-251.094971,-0.003863,0.000703,0.017856,39.842934,2.029696,0.178564,-251.094971,0.018767,0.000000
19.110001,9.037849,-251.094971,-0.003833,0.000717,0.018211,40.202362,2.048006,0.182114,-251.094971,0.019192,0.000000
19.360001,9.292923,-251.183929,-0.003824,0.000732,0.018593,41.336987,2.105806,0.185929,-251.183929,0.019608,0.000000
19.610001,9.570343,-251.139450,-0.003798,0.000751,0.019079,42.571011,2.168671,0.190789,-251.139450,0.020024,0.000000
19.860001,9.625084,-251.228409,-0.003781,0.000766,0.019460,42.814510,2.181075,0.194604,-251.228409,0.020441,0.000000
20.110001,9.708870,-251.228409,-0.003773,0.000778,0.019773,43.187210,2.200061,0.197730,-251.228409,0.020857,0.000000
20.360001,10.099487,-251.183929,-0.003751,0.000799,0.020284,44.924763,2.288577,0.202840,-251.183929,0.021273,0.000000
20.610001,10.369827,-251.272888,-0.003717,0.000817,0.020762,46.127296,2.349837,0.207617,-251.272888,0.021689,0.000000
20.860001,10.302803,-251.317368,-0.003712,0.000831,0.021108,45.829155,2.334649,0.211084,-251.317368,0.022105,0.000000
21.110001,10.550430,-251.361847,-0.003691,0.000850,0.021585,46.930656,2.390762,0.215853,-251.361847,0.022522,0.000000
21.360001,10.706825,-251.361847,-0.003673,0.000866,0.021993,47.626339,2.426201,0.219925,-251.361847,0.022938,0.000000
21.610001,10.884445,-251.361847,-0.003635,0.000886,0.022504,48.416431,2.466451,0.225042,-251.361847,0.023354,0.000000
21.860001,10.920197,-251.317368,-0.003609,0.000898,0.022817,48.575459,2.474552,0.228169,-251.317368,0.023771,0.000000
22.110001,10.900459,-251.361847,-0.003622,0.000910,0.023111,48.487663,2.470079,0.231113,-251.361847,0.024187,0.000000
22.360001,11.523437,-251.406342,-0.003561,0.000935,0.023762,51.258812,2.611248,0.237616,-251.406342,0.024603,0.000000
22.610001,11.409492,-251.450821,-0.003535,0.000948,0.024083,50.751957,2.585428,0.240825,-251.450821,0.025020,0.000000
22.860001,11.466461,-251.495300,-0.003544,0.000963,0.024464,51.005367,2.598337,0.244640,-251.495300,0.025436,0.000000
23.110001,11.485458,-251.539780,-0.003527,0.000978,0.024837,51.089870,2.602642,0.248372,-251.539780,0.025852,0.000000
23.360001,11.705902,-251.495300,-0.003497,0.000995,0.025279,52.070454,2.652596,0.252793,-251.495300,0.026268,0.000000
23.610001,11.699196,-251.539780,-0.003462,0.001010,0.025653,52.040623,2.651076,0.256525,-251.539780,0.026684,0.000000
23.860001,12.065239,-251.628738,-0.003445,0.001027,0.026095,53.668861,2.734022,0.260946,-251.628738,0.027101,0.000000
24.110001,11.879051,-251.584259,-0.003428,0.001039,0.026390,52.840660,2.691832,0.263898,-251.584259,0.027526,0.000000
24.360001,12.375801,-251.628738,-0.003389,0.001063,0.026988,55.050312,2.804397,0.269878,-251.628738,0.027942,0.000000
24.610001,12.468521,-251.628738,-0.003372,0.001081,0.027456,55.462753,2.825407,0.274564,-251.628738,0.028358,0.000000
24.860001,12.350479,-251.673218,-0.003328,0.001094,0.027786,54.937675,2.798658,0.277857,-251.673218,0.028774,0.000000
25.110001,12.295738,-251.762177,-0.003333,0.001106,0.028098,54.694176,2.786254,0.280983,-251.762177,0.029191,0.000000
25.360001,12.372818,-251.717697,-0.003294,0.001123,0.028515,55.037045,2.803721,0.285146,-251.717697,0.029607,0.000000
25.610001,12.626404,-251.762177,-0.003268,0.001140,0.028957,56.165051,2.861184,0.289567,-251.762177,0.030023,0.000000
25.860001,12.474480,-251.806671,-0.003264,0.001151,0.029243,55.489258,2.826757,0.292429,-251.806671,0.030440,0.000000
26.110001,12.753014,-251.762177,-0.003238,0.001168,0.029668,56.728237,2.889874,0.296675,-251.762177,0.030856,0.000000
26.360001,13.337639,-251.806671,-0.003221,0.001196,0.030387,59.328781,3.022352,0.303874,-251.806671,0.031272,0.000000
26.610001,13.145866,-251.851151,-0.003182,0.001212,0.030786,58.475735,2.978896,0.307863,-251.851151,0.031689,0.000000
26.860001,12.903076,-251.895630,-0.003152,0.001223,0.031064,57.395748,2.923879,0.310641,-251.895630,0.032105,0.000000
27.110001,13.094849,-251.940109,-0.003130,0.001241,0.031532,58.248795,2.967335,0.315320,-251.940109,0.032521,0.000000
27.360001,13.264648,-251.895630,-0.003113,0.001260,0.032010,59.004105,3.005812,0.320096,-251.895630,0.032937,0.000000
27.610001,13.378593,-251.940109,-0.003096,0.001277,0.032434,59.510956,3.031633,0.324343,-251.940109,0.033353,0.000000
27.860001,13.436317,-251.940109,-0.003048,0.001294,0.032859,59.767727,3.044713,0.328589,-251.940109,0.033770,0.000000
28.110001,13.383812,-252.029068,-0.003053,0.001309,0.033258,59.534168,3.032815,0.332579,-252.029068,0.034186,0.000000
28.360001,13.519730,-251.984589,-0.003022,0.001327,0.033709,60.138760,3.063614,0.337090,-251.984589,0.034602,0.000000
28.610001,13.283272,-252.029068,-0.002997,0.001339,0.034003,59.086945,3.010032,0.340035,-252.029068,0.035019,0.000000
28.860001,13.285507,-252.029068,-0.002958,0.001352,0.034342,59.096886,3.010539,0.343419,-252.029068,0.035435,0.000000
29.110001,13.404289,-252.073547,-0.002962,0.001368,0.034758,59.625256,3.037455,0.347582,-252.073547,0.035860,0.000000
29.360001,14.015724,-252.118027,-0.002902,0.001392,0.035348,62.345055,3.176008,0.353479,-252.118027,0.036276,0.000000
29.610001,13.626221,-252.118027,-0.002936,0.001401,0.035583,60.612457,3.087746,0.355826,-252.118027,0.036692,0.000000
29.860001,13.931198,-252.162506,-0.002854,0.001422,0.036120,61.969063,3.156855,0.361200,-252.162506,0.037109,0.000000
30.110001,14.288300,-252.206985,-0.002833,0.001448,0.036779,63.557529,3.237775,0.367793,-252.206985,0.037525,0.000000
30.360001,13.835495,-252.162506,-0.002807,0.001460,0.037074,61.543354,3.135168,0.370738,-252.162506,0.037941,0.000000
30.610001,13.665321,-252.251480,-0.002781,0.001472,0.037377,60.786385,3.096606,0.373774,-252.251480,0.038358,0.000000
30.860001,13.826187,-252.206985,-0.002751,0.001488,0.037802,61.501953,3.133059,0.378020,-252.206985,0.038774,0.000000
31.110001,13.543182,-252.251480,-0.002738,0.001495,0.037967,60.243084,3.068929,0.379670,-252.251480,0.039190,0.000000
31.360001,13.886139,-252.340439,-0.002708,0.001514,0.038444,61.768631,3.146644,0.384439,-252.340439,0.039606,0.000000
31.610001,14.295006,-252.340439,-0.002686,0.001536,0.039016,63.587360,3.239295,0.390162,-252.340439,0.040022,0.000000
31.860001,13.988167,-252.295959,-0.002660,0.001546,0.039277,62.222473,3.169764,0.392766,-252.295959,0.040439,0.000000
32.110001,14.664024,-252.429398,-0.002634,0.001577,0.040049,65.228836,3.322915,0.400487,-252.429398,0.040855,0.000000
32.360001,14.319206,-252.384918,-0.002604,0.001590,0.040378,63.695011,3.244779,0.403780,-252.384918,0.041271,0.000000
32.610001,14.277130,-252.429398,-0.002574,0.001605,0.040777,63.507847,3.235244,0.407769,-252.429398,0.041688,0.000000
32.860001,14.131531,-252.473877,-0.002544,0.001618,0.041106,62.860188,3.202251,0.411062,-252.473877,0.042104,0.000000
33.110001,14.513588,-252.429398,-0.002544,0.001640,0.041644,64.559662,3.288826,0.416444,-252.429398,0.042520,0.000000
33.360001,14.389587,-252.518356,-0.002509,0.001650,0.041921,64.008080,3.260727,0.419215,-252.518356,0.042937,0.000000
33.610001,14.532578,-252.473877,-0.002501,0.001667,0.042347,64.644135,3.293129,0.423469,-252.473877,0.043352,0.000000
33.860001,14.945168,-252.562836,-0.002453,0.001688,0.042884,66.479424,3.386623,0.428844,-252.562836,0.043769,0.000000
34.110001,14.977188,-252.607315,-0.002419,0.001707,0.043361,66.621857,3.393879,0.433613,-252.607315,0.044185,0.000000
34.360001,14.687111,-252.607315,-0.002402,0.001718,0.043639,65.331535,3.328147,0.436391,-252.607315,0.044610,0.000000
34.610001,14.614502,-252.607315,-0.002402,0.001732,0.044003,65.008553,3.311693,0.440032,-252.607315,0.045027,0.000000
34.860001,14.619713,-252.607315,-0.002363,0.001745,0.044332,65.031731,3.312874,0.443325,-252.607315,0.045442,0.000000
35.110001,15.230408,-252.696289,-0.002371,0.001772,0.045000,67.748238,3.451260,0.450001,-252.696289,0.045859,0.000000
35.360001,14.900856,-252.696289,-0.002333,0.001782,0.045269,66.282318,3.376582,0.452689,-252.696289,0.046275,0.000000
35.610001,14.961922,-252.696289,-0.002302,0.001798,0.045668,66.553955,3.390420,0.456678,-252.696289,0.046691,0.000000
35.860001,15.351051,-252.785248,-0.002289,0.001819,0.046197,68.284889,3.478598,0.461969,-252.785248,0.047108,0.000000
36.110001,15.475426,-252.785248,-0.002242,0.001837,0.046656,68.838135,3.506782,0.466564,-252.785248,0.047524,0.000000
36.360001,15.293335,-252.829727,-0.002220,0.001852,0.047030,68.028152,3.465519,0.470296,-252.829727,0.047940,0.000000
36.610001,15.308975,-252.829727,-0.002225,0.001868,0.047446,68.097725,3.469064,0.474459,-252.829727,0.048357,0.000000
36.860001,15.246788,-252.829727,-0.002190,0.001880,0.047758,67.821098,3.454972,0.477578,-252.829727,0.048773,0.000000
37.110001,15.621025,-252.785248,-0.002160,0.001901,0.048296,69.485786,3.539775,0.482960,-252.785248,0.049189,0.000000
37.360001,15.575592,-252.874207,-0.002169,0.001914,0.048617,69.283691,3.529480,0.486170,-252.874207,0.049606,0.000000
37.610001,15.472450,-252.918686,-0.002134,0.001928,0.048972,68.824898,3.506107,0.489720,-252.918686,0.050021,0.000000
37.860001,16.233208,-252.918686,-0.002100,0.001956,0.049692,72.208916,3.678497,0.496919,-252.918686,0.050438,0.000000
38.110001,15.972916,-253.007645,-0.002082,0.001970,0.050039,71.051079,3.619514,0.500386,-253.007645,0.050854,0.000000
38.360001,15.757683,-253.007645,-0.002057,0.001983,0.050360,70.093674,3.570742,0.503595,-253.007645,0.051270,0.000000
38.610001,15.894714,-253.007645,-0.002031,0.001998,0.050758,70.703224,3.601794,0.507585,-253.007645,0.051687,0.000000
38.860001,16.142342,-253.007645,-0.002005,0.002016,0.051201,71.804718,3.657907,0.512013,-253.007645,0.052103,0.000000
39.110001,16.229477,-253.096619,-0.001988,0.002033,0.051626,72.192322,3.677652,0.516260,-253.096619,0.052519,0.000000
39.360001,15.866791,-253.052124,-0.001979,0.002042,0.051869,70.579010,3.595466,0.518690,-253.052124,0.052944,0.000000
39.610001,16.462212,-253.096619,-0.001949,0.002067,0.052493,73.227577,3.730391,0.524935,-253.096619,0.053360,0.000000
39.860001,16.818199,-253.141098,-0.001906,0.002086,0.052996,74.811089,3.811058,0.529961,-253.141098,0.053777,0.000000
40.110001,16.435402,-253.141098,-0.001871,0.002097,0.053257,73.108322,3.724315,0.532565,-253.141098,0.054193,0.000000
40.360001,16.388481,-253.185577,-0.001871,0.002112,0.053646,72.899605,3.713683,0.536463,-253.185577,0.054609,0.000000
40.610001,16.459976,-253.185577,-0.001858,0.002129,0.054089,73.217628,3.729884,0.540892,-253.185577,0.055026,0.000000
40.860001,16.810753,-253.274536,-0.001824,0.002147,0.054531,74.777962,3.809371,0.545313,-253.274536,0.055442,0.000000
41.110001,16.611160,-253.274536,-0.001789,0.002160,0.054852,73.890129,3.764143,0.548522,-253.274536,0.055858,0.000000
41.360001,16.682655,-253.274536,-0.001794,0.002173,0.055199,74.208160,3.780344,0.551989,-253.274536,0.056275,0.000000
41.610001,16.604462,-253.319016,-0.001772,0.002188,0.055580,73.860336,3.762625,0.555804,-253.319016,0.056690,0.000000
41.860001,17.482513,-253.363495,-0.001742,0.002214,0.056248,77.766106,3.961594,0.562481,-253.363495,0.057106,0.000000
42.110001,17.138817,-253.407974,-0.001725,0.002226,0.056534,76.237267,3.883712,0.565342,-253.407974,0.057523,0.000000
42.360001,17.088173,-253.407974,-0.001690,0.002243,0.056960,76.011986,3.872235,0.569596,-253.407974,0.057939,0.000000
42.610001,17.071411,-253.407974,-0.001664,0.002256,0.057306,75.937431,3.868437,0.573063,-253.407974,0.058356,0.000000
42.860001,17.403572,-253.452454,-0.001630,0.002277,0.057826,77.414955,3.943706,0.578264,-253.452454,0.058772,0.000000
43.110001,17.202866,-253.452454,-0.001617,0.002291,0.058190,76.522171,3.898225,0.581905,-253.452454,0.059188,0.000000
43.360001,17.188713,-253.496933,-0.001608,0.002305,0.058555,76.459213,3.895018,0.585554,-253.496933,0.059605,0.000000
43.610001,17.656036,-253.496933,-0.001604,0.002326,0.059093,78.537971,4.000915,0.590928,-253.496933,0.060021,0.000000
43.860001,17.820625,-253.496933,-0.001556,0.002345,0.059552,79.270103,4.038211,0.595523,-253.496933,0.060437,0.000000
44.110001,17.526825,-253.585907,-0.001544,0.002357,0.059856,77.963211,3.971635,0.598558,-253.585907,0.060854,0.000000
44.360001,17.667580,-253.585907,-0.001505,0.002375,0.060315,78.589317,4.003531,0.603153,-253.585907,0.061278,0.000000
44.610001,17.853027,-253.630386,-0.001492,0.002390,0.060697,79.414230,4.045554,0.606968,-253.630386,0.061695,0.000000
44.860001,17.818024,-253.585907,-0.001466,0.002404,0.061070,79.258530,4.037622,0.610700,-253.585907,0.062111,0.000000
45.110001,17.938667,-253.630386,-0.001431,0.002424,0.061573,79.795174,4.064960,0.615727,-253.630386,0.062527,0.000000
45.360001,17.826210,-253.674866,-0.001410,0.002435,0.061842,79.294945,4.039477,0.618422,-253.674866,0.062944,0.000000
45.610001,18.389244,-253.719345,-0.001410,0.002458,0.062432,81.799446,4.167062,0.624318,-253.719345,0.063359,0.000000
45.860001,18.384026,-253.808304,-0.001393,0.002476,0.062891,81.776230,4.165880,0.628913,-253.808304,0.063775,0.000000
46.110001,18.000114,-253.719345,-0.001350,0.002488,0.063195,80.068504,4.078884,0.631949,-253.719345,0.064192,0.000000
46.360001,17.925636,-253.763824,-0.001328,0.002501,0.063533,79.737213,4.062007,0.635332,-253.763824,0.064608,0.000000
46.610001,18.124481,-253.763824,-0.001315,0.002517,0.063932,80.621719,4.107066,0.639322,-253.763824,0.065024,0.000000
46.860001,18.231728,-253.852783,-0.001268,0.002533,0.064339,81.098778,4.131369,0.643394,-253.852783,0.065441,0.000000
47.110001,18.193748,-253.897263,-0.001255,0.002547,0.064695,80.929832,4.122762,0.646952,-253.897263,0.065857,0.000000
47.360001,18.388123,-253.897263,-0.001233,0.002566,0.065172,81.794456,4.166808,0.651721,-253.897263,0.066274,0.000000
47.610001,18.980942,-253.897263,-0.001212,0.002589,0.065753,84.431442,4.301143,0.657527,-253.897263,0.066690,0.000000
47.860001,18.858429,-253.941757,-0.001186,0.002605,0.066178,83.886482,4.273381,0.661781,-253.941757,0.067106,0.000000
48.110001,18.541168,-253.941757,-0.001164,0.002619,0.066516,82.475235,4.201489,0.665165,-253.941757,0.067522,0.000000
48.360001,18.697937,-253.941757,-0.001134,0.002636,0.066967,83.172577,4.237013,0.669669,-253.941757,0.067938,0.000000
48.610001,18.524788,-253.941757,-0.001117,0.002649,0.067297,82.402374,4.197777,0.672969,-253.941757,0.068354,0.000000
48.860001,18.859917,-253.986237,-0.001082,0.002671,0.067834,83.893097,4.273718,0.678344,-253.986237,0.068771,0.000000
49.110001,18.966789,-253.986237,-0.001069,0.002688,0.068286,84.368492,4.297935,0.682856,-253.986237,0.069187,0.000000
49.360001,18.974609,-254.075195,-0.001048,0.002704,0.068684,84.403275,4.299708,0.686845,-254.075195,0.069603,0.000000
49.610001,18.989502,-254.075195,-0.001022,0.002721,0.069109,84.469521,4.303082,0.691092,-254.075195,0.070028,0.000000
49.860001,18.810768,-254.119675,-0.001009,0.002734,0.069456,83.674477,4.262581,0.694559,-254.119675,0.070444,0.000000
50.110001,18.697563,-254.075195,-0.000987,0.002749,0.069820,83.170914,4.236928,0.698200,-254.075195,0.070861,0.000000
50.360001,18.830505,-254.119675,-0.000944,0.002763,0.070185,83.762268,4.267054,0.701848,-254.119675,0.071277,0.000000
50.610001,19.559235,-254.208633,-0.000923,0.002787,0.070783,87.003822,4.432186,0.707828,-254.208633,0.071693,0.000000
50.860001,18.982056,-254.164154,-0.000892,0.002798,0.071078,84.436401,4.301395,0.710781,-254.164154,0.072110,0.000000
51.110001,19.460182,-254.208633,-0.000888,0.002816,0.071538,86.563217,4.409740,0.715375,-254.208633,0.072526,0.000000
51.360001,19.946129,-254.208633,-0.000845,0.002841,0.072162,88.724815,4.519857,0.721621,-254.208633,0.072942,0.000000
51.610001,19.564079,-254.253113,-0.000832,0.002854,0.072491,87.025368,4.433284,0.724913,-254.253113,0.073359,0.000000
51.860001,19.122818,-254.297592,-0.000802,0.002864,0.072752,85.062546,4.333292,0.727517,-254.297592,0.073775,0.000000
52.110001,19.611740,-254.297592,-0.000811,0.002885,0.073281,87.237373,4.444084,0.732809,-254.297592,0.074191,0.000000
52.360001,19.139198,-254.342072,-0.000767,0.002893,0.073488,85.135406,4.337004,0.734883,-254.342072,0.074607,0.000000
52.610001,19.717491,-254.342072,-0.000750,0.002912,0.073966,87.707779,4.468048,0.739659,-254.342072,0.075023,0.000000
52.860001,20.101410,-254.386566,-0.000716,0.002932,0.074469,89.415535,4.555045,0.744686,-254.386566,0.075440,0.000000
53.110004,19.825851,-254.520004,-0.000698,0.002942,0.074737,88.189789,4.492602,0.747373,-254.520004,0.075856,0.000000
53.360004,20.960098,-254.475525,-0.000664,0.002972,0.075492,93.235176,4.749626,0.754920,-254.475525,0.076272,0.000000
53.610004,20.516602,-254.475525,-0.000638,0.002986,0.075848,91.262405,4.649128,0.758478,-254.475525,0.076689,0.000000
53.860004,20.245148,-254.475525,-0.000621,0.003000,0.076203,90.054916,4.587616,0.762028,-254.475525,0.077105,0.000000
54.110004,20.137154,-254.520004,-0.000599,0.003011,0.076481,89.574532,4.563144,0.764806,-254.520004,0.077521,0.000000
54.360004,20.446968,-254.520004,-0.000565,0.003029,0.076932,90.952660,4.633349,0.769318,-254.520004,0.077938,0.000000
54.610004,20.914299,-254.564484,-0.000539,0.003048,0.077409,93.031448,4.739248,0.774087,-254.564484,0.078362,0.000000
54.860004,20.859932,-254.564484,-0.000560,0.003062,0.077773,92.789612,4.726928,0.777728,-254.564484,0.078779,0.000000
55.110004,21.167885,-254.564484,-0.000530,0.003077,0.078146,94.159454,4.796711,0.781460,-254.564484,0.079195,0.000000
55.360004,21.948746,-254.608963,-0.000483,0.003101,0.078761,97.632896,4.973657,0.787614,-254.608963,0.079611,0.000000
55.610004,21.657555,-254.653442,-0.000492,0.003113,0.079082,96.337616,4.907672,0.790824,-254.653442,0.080028,0.000000
55.860004,21.634094,-254.653442,-0.000466,0.003127,0.079429,96.233261,4.902356,0.794290,-254.653442,0.080444,0.000000
56.110004,21.984871,-254.697922,-0.000448,0.003141,0.079793,97.793587,4.981843,0.797932,-254.697922,0.080860,0.000000
56.360004,22.925484,-254.653442,-0.000440,0.003165,0.080392,101.977646,5.194989,0.803919,-254.653442,0.081276,0.000000
56.610004,22.921013,-254.786880,-0.000401,0.003178,0.080713,101.957756,5.193976,0.807129,-254.786880,0.081692,0.000000
56.860004,23.126938,-254.742401,-0.000371,0.003193,0.081112,102.873756,5.240639,0.811118,-254.742401,0.082109,0.000000
57.110004,23.202530,-254.786880,-0.000362,0.003208,0.081484,103.210007,5.257769,0.814842,-254.786880,0.082525,0.000000
57.360004,24.117447,-254.786880,-0.000345,0.003230,0.082031,107.279762,5.465092,0.820308,-254.786880,0.082941,0.000000
57.610004,24.382202,-254.920334,-0.000341,0.003246,0.082447,108.457451,5.525086,0.824471,-254.920334,0.083358,0.000000
57.860004,24.339378,-254.875854,-0.000319,0.003258,0.082742,108.266960,5.515382,0.827416,-254.875854,0.083774,0.000000
58.110004,24.713615,-254.875854,-0.000323,0.003275,0.083175,109.931648,5.600185,0.831753,-254.875854,0.084190,0.000000
58.360004,25.512726,-254.964813,-0.000289,0.003295,0.083687,113.486275,5.781267,0.836871,-254.964813,0.084607,0.000000
58.610004,26.048195,-254.964813,-0.000280,0.003312,0.084112,115.868156,5.902606,0.841125,-254.964813,0.085023,0.000000
58.860004,26.031441,-254.964813,-0.000246,0.003322,0.084390,115.793633,5.898809,0.843895,-254.964813,0.085439,0.000000
59.110004,27.236069,-254.964813,-0.000229,0.003348,0.085031,121.152084,6.171781,0.850314,-254.964813,0.085855,0.000000
59.360004,27.714935,-255.053772,-0.000216,0.003365,0.085483,123.282188,6.280294,0.854826,-255.053772,0.086271,0.000000
59.610004,27.641953,-255.053772,-0.000203,0.003377,0.085786,122.957542,6.263756,0.857862,-255.053772,0.086697,0.000000
59.860004,27.885483,-255.009293,-0.000198,0.003390,0.086115,124.040825,6.318941,0.861154,-255.009293,0.087113,0.000000
60.110004,28.268654,-255.142731,-0.000181,0.003410,0.086610,125.745255,6.405769,0.866098,-255.142731,0.087529,0.000000
60.360004,29.176498,-255.187210,-0.000172,0.003426,0.087026,129.783554,6.611489,0.870261,-255.187210,0.087945,0.000000
60.610004,29.390984,-255.098251,-0.000160,0.003438,0.087321,130.737625,6.660092,0.873206,-255.098251,0.088361,0.000000
60.860004,29.896294,-255.142731,-0.000134,0.003453,0.087703,132.985352,6.774597,0.877028,-255.142731,0.088778,0.000000
61.110004,31.599152,-255.187210,-0.000125,0.003482,0.088431,140.560043,7.160470,0.884310,-255.187210,0.089194,0.000000
61.360004,31.593567,-255.231705,-0.000108,0.003491,0.088674,140.535202,7.159205,0.886740,-255.231705,0.089610,0.000000
61.610004,31.654266,-255.276184,-0.000091,0.003506,0.089046,140.805206,7.172959,0.890465,-255.276184,0.090027,0.000000
61.860004,32.598602,-255.276184,-0.000103,0.003523,0.089480,145.005829,7.386949,0.894802,-255.276184,0.090443,0.000000
62.110004,33.358612,-255.231705,-0.000047,0.003542,0.089957,148.386520,7.559170,0.899571,-255.231705,0.090859,0.000000
62.360004,33.759659,-255.365143,-0.000047,0.003554,0.090278,150.170456,7.650048,0.902781,-255.365143,0.091276,0.000000
62.610004,34.138359,-255.320663,-0.000039,0.003568,0.090616,151.855011,7.735863,0.906164,-255.320663,0.091691,0.000000
62.860004,34.598244,-255.365143,-0.000043,0.003580,0.090928,153.900681,7.840074,0.909283,-255.365143,0.092108,0.000000
63.110004,36.282852,-255.409622,-0.000017,0.003608,0.091631,161.394180,8.221811,0.916308,-255.409622,0.092524,0.000000
63.360004,36.772896,-255.409622,-0.000013,0.003623,0.092030,163.574005,8.332857,0.920297,-255.409622,0.092940,0.000000
63.610004,37.229050,-255.454102,0.000013,0.003637,0.092368,165.603088,8.436223,0.923681,-255.454102,0.093357,0.000000
63.860004,38.048645,-255.454102,0.000004,0.003655,0.092828,169.248825,8.621946,0.928276,-255.454102,0.093773,0.000000
64.110001,39.043625,-255.454102,0.000009,0.003673,0.093304,173.674713,8.847412,0.933045,-255.454102,0.094189,0.000000
64.360001,39.673309,-255.498581,0.000022,0.003687,0.093660,176.475693,8.990100,0.936603,-255.498581,0.094606,0.000000
64.610001,40.149567,-255.543060,0.000039,0.003702,0.094024,178.594193,9.098022,0.940244,-255.543060,0.095022,0.000000
64.860001,40.216972,-255.543060,0.000043,0.003711,0.094250,178.894028,9.113297,0.942499,-255.543060,0.095447,0.000000
65.110001,42.381943,-255.587540,0.000060,0.003741,0.095030,188.524292,9.603886,0.950304,-255.587540,0.095863,0.000000
65.360001,42.374870,-255.632019,0.000086,0.003750,0.095248,188.492844,9.602283,0.952476,-255.632019,0.096279,0.000000
65.610001,43.400009,-255.632019,0.000073,0.003768,0.095698,193.052887,9.834582,0.956980,-255.632019,0.096696,0.000000
65.860001,43.796585,-255.632019,0.000091,0.003779,0.095993,194.816940,9.924448,0.959933,-255.632019,0.097112,0.000000
66.110001,45.069725,-255.676514,0.000086,0.003801,0.096557,200.480148,10.212945,0.965572,-255.676514,0.097528,0.000000
66.360001,45.354218,-255.720993,0.000138,0.003809,0.096756,201.745636,10.277413,0.967563,-255.720993,0.097945,0.000000
66.610001,46.658638,-255.720993,0.000121,0.003830,0.097294,207.547989,10.572999,0.972938,-255.720993,0.098360,0.000000
66.860001,47.771660,-255.765472,0.000134,0.003851,0.097805,212.498962,10.825212,0.978055,-255.765472,0.098777,0.000000
67.110001,49.158752,-255.809952,0.000134,0.003868,0.098257,218.669052,11.139532,0.982566,-255.809952,0.099193,0.000000
67.360001,49.545647,-255.854431,0.000160,0.003881,0.098586,220.390045,11.227203,0.985859,-255.854431,0.099609,0.000000
67.610001,50.479927,-255.854431,0.000155,0.003897,0.098977,224.545929,11.438915,0.989765,-255.854431,0.100026,0.000000
67.860001,51.109612,-255.809952,0.000172,0.003911,0.099332,227.346909,11.581603,0.993323,-255.809952,0.100442,0.000000
68.110001,52.235291,-255.898911,0.000151,0.003928,0.099765,232.354172,11.836686,0.997653,-255.898911,0.100858,0.000000
68.360001,53.084297,-255.898911,0.000168,0.003941,0.100104,236.130753,12.029074,1.001037,-255.898911,0.101275,0.000000
68.610001,53.919159,-255.898911,0.000181,0.003957,0.100512,239.844391,12.218256,1.005117,-255.898911,0.101691,0.000000
68.860001,55.074631,-255.987869,0.000190,0.003974,0.100928,244.984192,12.480090,1.009280,-255.987869,0.102107,0.000000
69.110001,57.036285,-255.943390,0.000207,0.003999,0.101569,253.710068,12.924607,1.015692,-255.943390,0.102524,0.000000
69.360001,57.538620,-256.076843,0.000207,0.004009,0.101830,255.944565,13.038438,1.018296,-256.076843,0.102939,0.000000
69.610001,58.571953,-256.076843,0.000237,0.004027,0.102289,260.541046,13.272594,1.022891,-256.076843,0.103356,0.000000
69.860001,59.666359,-256.032349,0.000237,0.004044,0.102723,265.409210,13.520591,1.027228,-256.032349,0.103781,0.000000
70.110001,60.965561,-256.076843,0.000237,0.004063,0.103200,271.188354,13.814994,1.031997,-256.076843,0.104197,0.000000
70.360001,61.929634,-256.165802,0.000237,0.004077,0.103555,275.476776,14.033456,1.035555,-256.165802,0.104614,0.000000
70.610001,63.215439,-256.121307,0.000254,0.004096,0.104041,281.196320,14.324823,1.040407,-256.121307,0.105029,0.000000
70.860001,64.595818,-256.121307,0.000259,0.004115,0.104527,287.336548,14.637621,1.045267,-256.121307,0.105446,0.000000
71.110001,65.370354,-256.165802,0.000267,0.004128,0.104856,290.781860,14.813134,1.048560,-256.165802,0.105862,0.000000
71.360001,66.121437,-256.210266,0.000276,0.004142,0.105212,294.122833,14.983332,1.052118,-256.210266,0.106278,0.000000
71.610001,67.012154,-256.121307,0.000267,0.004155,0.105541,298.084961,15.185171,1.055410,-256.121307,0.106695,0.000000
71.860001,67.496605,-256.254761,0.000285,0.004156,0.105558,300.239899,15.294949,1.055585,-256.254761,0.105801,0.000000
72.110001,66.920921,-256.299225,0.000302,0.004156,0.105558,297.679138,15.164497,1.055585,-256.299225,0.105801,0.000000
72.360001,66.525078,-256.254761,0.000302,0.004153,0.105498,295.918335,15.074799,1.054979,-256.254761,0.105558,0.000000
72.610001,66.128883,-256.299225,0.000293,0.004152,0.105472,294.155975,14.985019,1.054722,-256.299225,0.105558,0.000000
72.860001,65.786674,-256.343719,0.000293,0.004152,0.105463,292.633759,14.907474,1.054631,-256.343719,0.105558,0.000000
73.110001,65.480949,-256.388214,0.000319,0.004152,0.105463,291.273804,14.838195,1.054631,-256.388214,0.105558,0.000000
73.360001,65.233696,-256.432678,0.000293,0.004152,0.105455,290.173981,14.782166,1.054547,-256.432678,0.105558,0.000000
73.610001,64.982719,-256.432678,0.000323,0.004152,0.105455,289.057587,14.725295,1.054547,-256.432678,0.105558,0.000000
73.860001,64.761162,-256.432678,0.000310,0.004152,0.105455,288.072021,14.675090,1.054547,-256.432678,0.105558,0.000000
74.110001,64.564171,-256.432678,0.000332,0.004152,0.105455,287.195770,14.630450,1.054547,-256.432678,0.105558,0.000000
74.360001,64.382454,-256.477173,0.000332,0.004152,0.105455,286.387451,14.589273,1.054547,-256.477173,0.105558,0.000000
74.610001,64.223457,-256.566132,0.000310,0.004152,0.105455,285.680206,14.553244,1.054547,-256.566132,0.105558,0.000000
74.860001,64.065559,-256.610596,0.000315,0.004152,0.105455,284.977844,14.517463,1.054547,-256.610596,0.105558,0.000000
75.110001,63.937843,-256.566132,0.000306,0.004152,0.105455,284.409729,14.488523,1.054547,-256.566132,0.105558,0.000000
75.360001,63.794106,-256.610596,0.000323,0.004152,0.105455,283.770355,14.455951,1.054547,-256.610596,0.105558,0.000000
75.610001,63.661919,-256.610596,0.000310,0.004152,0.105455,283.182343,14.425997,1.054547,-256.610596,0.105558,0.000000
75.860001,63.550941,-256.610596,0.000315,0.004152,0.105455,282.688721,14.400848,1.054547,-256.610596,0.105558,0.000000
76.110001,63.431786,-256.655090,0.000319,0.004152,0.105455,282.158661,14.373848,1.054547,-256.655090,0.105558,0.000000
76.360001,63.341667,-256.655090,0.000332,0.004152,0.105455,281.757812,14.353427,1.054547,-256.655090,0.105558,0.000000
76.610001,63.240761,-256.655090,0.000341,0.004152,0.105455,281.308960,14.330561,1.054547,-256.655090,0.105558,0.000000
76.860001,63.159958,-256.699554,0.000328,0.004152,0.105455,280.949524,14.312251,1.054547,-256.699554,0.105558,0.000000
77.110001,63.070213,-256.788544,0.000323,0.004152,0.105455,280.550323,14.291914,1.054547,-256.788544,0.105558,0.000000
77.360001,62.970787,-256.744049,0.000332,0.004152,0.105455,280.108063,14.269384,1.054547,-256.744049,0.105558,0.000000
77.610001,62.897430,-256.833008,0.000323,0.004152,0.105455,279.781738,14.252762,1.054547,-256.833008,0.105558,0.000000
77.860001,62.824448,-256.833008,0.000341,0.004152,0.105455,279.457092,14.236223,1.054547,-256.833008,0.105558,0.000000
78.110001,62.749969,-256.833008,0.000323,0.004152,0.105455,279.125793,14.219346,1.054547,-256.833008,0.105558,0.000000
78.360001,62.681458,-256.877502,0.000336,0.004152,0.105455,278.821045,14.203821,1.054547,-256.877502,0.105558,0.000000
78.610001,62.603630,-256.877502,0.000323,0.004152,0.105455,278.474854,14.186185,1.054547,-256.877502,0.105558,0.000000
78.860001,62.537720,-256.966461,0.000323,0.004152,0.105455,278.181671,14.171250,1.054547,-256.966461,0.105558,0.000000
79.110001,62.492287,-256.921967,0.000302,0.004152,0.105455,277.979584,14.160954,1.054547,-256.921967,0.105558,0.000000
79.360001,62.426750,-256.966461,0.000323,0.004152,0.105455,277.688049,14.146104,1.054547,-256.966461,0.105558,0.000000
79.610001,62.367546,-257.010925,0.000319,0.004152,0.105455,277.424713,14.132688,1.054547,-257.010925,0.105558,0.000000
79.860001,62.293068,-256.966461,0.000349,0.004152,0.105455,277.093414,14.115811,1.054547,-256.966461,0.105558,0.000000
80.110001,62.255463,-257.099884,0.000302,0.004152,0.105455,276.926117,14.107289,1.054547,-257.099884,0.105558,0.000000
80.360001,62.202583,-257.099884,0.000341,0.004152,0.105455,276.690918,14.095306,1.054547,-257.099884,0.105558,0.000000
80.610001,62.154175,-257.099884,0.000341,0.004152,0.105455,276.475586,14.084337,1.054547,-257.099884,0.105558,0.000000
80.860001,62.100555,-257.144379,0.000328,0.004152,0.105455,276.237061,14.072186,1.054547,-257.144379,0.105558,0.000000
81.110001,62.048424,-257.099884,0.000332,0.004152,0.105455,276.005188,14.060374,1.054547,-257.099884,0.105558,0.000000
81.360001,62.001129,-257.144379,0.000315,0.004152,0.105455,275.794800,14.049657,1.054547,-257.144379,0.105558,0.000000
81.610001,61.959427,-257.188873,0.000328,0.004152,0.105455,275.609283,14.040207,1.054547,-257.188873,0.105558,0.000000
81.860001,61.923676,-257.188873,0.000323,0.004152,0.105455,275.450256,14.032105,1.054547,-257.188873,0.105558,0.000000
82.110001,61.877129,-257.233337,0.000328,0.004152,0.105455,275.243225,14.021558,1.054547,-257.233337,0.105558,0.000000
82.360001,61.832817,-257.322296,0.000332,0.004152,0.105455,275.046112,14.011517,1.054547,-257.322296,0.105558,0.000000
82.610001,61.798187,-257.322296,0.000323,0.004152,0.105455,274.892059,14.003669,1.054547,-257.322296,0.105558,0.000000
82.860001,61.752388,-257.277832,0.000336,0.004152,0.105455,274.688354,13.993292,1.054547,-257.277832,0.105558,0.000000
83.110001,61.727806,-257.366791,0.000328,0.004152,0.105455,274.579010,13.987721,1.054547,-257.366791,0.105558,0.000000
83.360001,61.670090,-257.322296,0.000332,0.004152,0.105455,274.322266,13.974642,1.054547,-257.322296,0.105558,0.000000
83.610001,61.642166,-257.366791,0.000358,0.004152,0.105455,274.198059,13.968314,1.054547,-257.366791,0.105558,0.000000
83.860001,61.600830,-257.411255,0.000328,0.004152,0.105455,274.014191,13.958948,1.054547,-257.411255,0.105558,0.000000
84.110001,61.564713,-257.366791,0.000332,0.004152,0.105455,273.853516,13.950763,1.054547,-257.366791,0.105558,0.000000
84.360001,61.536781,-257.500214,0.000319,0.004152,0.105455,273.729279,13.944434,1.054547,-257.500214,0.105558,0.000000
84.610001,61.508484,-257.500214,0.000349,0.004152,0.105455,273.603394,13.938022,1.054547,-257.500214,0.105558,0.000000
84.860001,61.471619,-257.544708,0.000319,0.004152,0.105455,273.439423,13.929668,1.054547,-257.544708,0.105558,0.000000
85.110001,61.423584,-257.500214,0.000345,0.004152,0.105455,273.225739,13.918783,1.054547,-257.500214,0.105558,0.000000
85.360001,61.399750,-257.500214,0.000323,0.004152,0.105455,273.119720,13.913383,1.054547,-257.500214,0.105558,0.000000
85.610001,61.372192,-257.544708,0.000332,0.004152,0.105455,272.997131,13.907138,1.054547,-257.544708,0.105558,0.000000
85.860001,61.338684,-257.633667,0.000315,0.004152,0.105455,272.848083,13.899544,1.054547,-257.633667,0.105558,0.000000
86.110001,61.303680,-257.633667,0.000315,0.004152,0.105455,272.692383,13.891612,1.054547,-257.633667,0.105558,0.000000
86.360001,61.280960,-257.633667,0.000336,0.004152,0.105455,272.591339,13.886464,1.054547,-257.633667,0.105558,0.000000
86.610001,61.242981,-257.678162,0.000345,0.004152,0.105455,272.422394,13.877858,1.054547,-257.678162,0.105558,0.000000
86.860001,61.223618,-257.722626,0.000354,0.004152,0.105455,272.336243,13.873470,1.054547,-257.722626,0.105558,0.000000
87.110001,61.198669,-257.678162,0.000345,0.004152,0.105455,272.225281,13.867817,1.054547,-257.678162,0.105558,0.000000
87.360001,61.165527,-257.722626,0.000345,0.004152,0.105455,272.077850,13.860307,1.054547,-257.722626,0.105558,0.000000
87.610001,61.144676,-257.767120,0.000310,0.004152,0.105455,271.985107,13.855582,1.054547,-257.767120,0.105558,0.000000
87.860001,61.120094,-257.722626,0.000332,0.004152,0.105455,271.875763,13.850012,1.054547,-257.722626,0.105558,0.000000
88.110001,61.082115,-257.811584,0.000319,0.004152,0.105455,271.706818,13.841405,1.054547,-257.811584,0.105558,0.000000
88.360001,61.069458,-257.811584,0.000323,0.004152,0.105455,271.650513,13.838537,1.054547,-257.811584,0.105558,0.000000
88.610001,61.041527,-257.856079,0.000332,0.004152,0.105455,271.526276,13.832208,1.054547,-257.856079,0.105558,0.000000
88.860001,61.017326,-257.856079,0.000349,0.004152,0.105455,271.418610,13.826723,1.054547,-257.856079,0.105558,0.000000
89.110001,61.004288,-257.811584,0.000345,0.004152,0.105455,271.360626,13.823770,1.054547,-257.811584,0.105558,0.000000
89.360001,60.965561,-257.900543,0.000315,0.004152,0.105455,271.188354,13.814994,1.054547,-257.900543,0.105558,0.000000
89.610001,60.947693,-257.900543,0.000341,0.004152,0.105455,271.108887,13.810945,1.054547,-257.900543,0.105558,0.000000
89.860001,60.934280,-257.945038,0.000341,0.004152,0.105455,271.049225,13.807905,1.054547,-257.945038,0.105558,0.000000
90.110001,60.905609,-257.900543,0.000323,0.004152,0.105455,270.921692,13.801409,1.054547,-257.900543,0.105558,0.000000
90.360001,60.882149,-257.989502,0.000319,0.004152,0.105455,270.817322,13.796092,1.054547,-257.989502,0.105558,0.000000
90.610001,60.852737,-258.033997,0.000332,0.004152,0.105455,270.686493,13.789428,1.054547,-258.033997,0.105558,0.000000
90.860001,60.845284,-257.989502,0.000332,0.004152,0.105455,270.653351,13.787738,1.054547,-257.989502,0.105558,0.000000
91.110001,60.819221,-258.033997,0.000336,0.004152,0.105455,270.537415,13.781833,1.054547,-258.033997,0.105558,0.000000
91.360001,60.808418,-258.078491,0.000358,0.004152,0.105455,270.489349,13.779385,1.054547,-258.078491,0.105558,0.000000
91.610001,60.797249,-258.078491,0.000315,0.004152,0.105455,270.439667,13.776854,1.054547,-258.078491,0.105558,0.000000
91.860001,60.765968,-258.033997,0.000332,0.004152,0.105455,270.300537,13.769765,1.054547,-258.033997,0.105558,0.000000
92.110001,60.749588,-258.122955,0.000336,0.004152,0.105455,270.227661,13.766053,1.054547,-258.122955,0.105558,0.000000
92.360001,60.719055,-258.167450,0.000328,0.004152,0.105455,270.091858,13.759135,1.054547,-258.167450,0.105558,0.000000
92.610001,60.709373,-258.167450,0.000332,0.004152,0.105455,270.048767,13.756941,1.054547,-258.167450,0.105558,0.000000
92.860001,60.692612,-258.211914,0.000315,0.004152,0.105455,269.974213,13.753142,1.054547,-258.211914,0.105558,0.000000
93.110001,60.671761,-258.256409,0.000354,0.004152,0.105455,269.881470,13.748418,1.054547,-258.256409,0.105558,0.000000
93.360008,60.659103,-258.256409,0.000332,0.004152,0.105455,269.825165,13.745549,1.054547,-258.256409,0.105558,0.000000
93.610008,60.630058,-258.300873,0.000332,0.004152,0.105455,269.695984,13.738968,1.054547,-258.300873,0.105558,0.000000
93.860008,60.611061,-258.389832,0.000349,0.004152,0.105455,269.611450,13.734663,1.054547,-258.389832,0.105558,0.000000
94.110008,60.587608,-258.345367,0.000306,0.004152,0.105455,269.507141,13.729348,1.054547,-258.345367,0.105558,0.000000
94.360008,60.570107,-258.345367,0.000354,0.004152,0.105455,269.429291,13.725382,1.054547,-258.345367,0.105558,0.000000
94.610008,60.558563,-258.345367,0.000328,0.004152,0.105455,269.377930,13.722767,1.054547,-258.345367,0.105558,0.000000
94.860008,60.540688,-258.389832,0.000349,0.004152,0.105455,269.298431,13.718716,1.054547,-258.389832,0.105558,0.000000
95.110008,60.530632,-258.478821,0.000315,0.004152,0.105455,269.253693,13.716437,1.054547,-258.478821,0.105558,0.000000
95.360008,60.507545,-258.478821,0.000319,0.004152,0.105455,269.151001,13.711205,1.054547,-258.478821,0.105558,0.000000
95.610008,60.498611,-258.434326,0.000328,0.004152,0.105455,269.111267,13.709182,1.054547,-258.434326,0.105558,0.000000
95.860008,60.476639,-258.478821,0.000341,0.004152,0.105455,269.013519,13.704203,1.054547,-258.478821,0.105558,0.000000
96.110008,60.461746,-258.523285,0.000315,0.004152,0.105455,268.947266,13.700828,1.054547,-258.523285,0.105558,0.000000
96.360008,60.448341,-258.567780,0.000341,0.004152,0.105455,268.887665,13.697790,1.054547,-258.567780,0.105558,0.000000
96.610008,60.430092,-258.567780,0.000328,0.004152,0.105455,268.806488,13.693655,1.054547,-258.567780,0.105558,0.000000
96.860008,60.412964,-258.523285,0.000345,0.004152,0.105455,268.730286,13.689773,1.054547,-258.523285,0.105558,0.000000
97.110008,60.398071,-258.612244,0.000349,0.004152,0.105455,268.664032,13.686399,1.054547,-258.612244,0.105558,0.000000
97.360008,60.382431,-258.656738,0.000345,0.004152,0.105455,268.594482,13.682855,1.054547,-258.656738,0.105558,0.000000
97.610008,60.376099,-258.656738,0.000328,0.004152,0.105455,268.566315,13.681419,1.054547,-258.656738,0.105558,0.000000
97.860008,60.361572,-258.656738,0.000328,0.004152,0.105455,268.501678,13.678128,1.054547,-258.656738,0.105558,0.000000
98.110008,60.337372,-258.745697,0.000332,0.004152,0.105455,268.394043,13.672644,1.054547,-258.745697,0.105558,0.000000
98.360008,60.342957,-258.745697,0.000328,0.004152,0.105455,268.418884,13.673909,1.054547,-258.745697,0.105558,0.000000
98.610008,60.316521,-258.790161,0.000319,0.004152,0.105455,268.301270,13.667918,1.054547,-258.790161,0.105558,0.000000
98.860008,60.306465,-258.790161,0.000341,0.004152,0.105455,268.256561,13.665640,1.054547,-258.790161,0.105558,0.000000
99.110008,60.275185,-258.790161,0.000332,0.004152,0.105455,268.117401,13.658552,1.054547,-258.790161,0.105558,0.000000
99.360008,60.269974,-258.790161,0.000354,0.004152,0.105455,268.094238,13.657372,1.054547,-258.790161,0.105558,0.000000
99.610008,60.260292,-258.879150,0.000341,0.004152,0.105455,268.051178,13.655177,1.054547,-258.879150,0.105558,0.000000
99.860008,60.237946,-258.879150,0.000345,0.004152,0.105455,267.951752,13.650113,1.054547,-258.879150,0.105558,0.000000
100.110008,60.242790,-258.879150,0.000323,0.004152,0.105455,267.973328,13.651212,1.054547,-258.879150,0.105558,0.000000
100.360008,60.211884,-258.879150,0.000336,0.004152,0.105455,267.835846,13.644208,1.054547,-258.879150,0.105558,0.000000
100.610008,60.205177,-258.968109,0.000332,0.004152,0.105455,267.806000,13.642688,1.054547,-258.968109,0.105558,0.000000
100.860008,60.182838,-258.968109,0.000328,0.004152,0.105455,267.706635,13.637626,1.054547,-258.968109,0.105558,0.000000
101.110008,60.179482,-258.968109,0.000328,0.004152,0.105455,267.691711,13.636865,1.054547,-258.968109,0.105558,0.000000
101.360008,60.162727,-259.057068,0.000345,0.004152,0.105455,267.617187,13.633069,1.054547,-259.057068,0.105558,0.000000
101.610008,60.140388,-259.057068,0.000332,0.004152,0.105455,267.517822,13.628007,1.054547,-259.057068,0.105558,0.000000
101.860008,60.128471,-259.012573,0.000341,0.004152,0.105455,267.464813,13.625306,1.054547,-259.012573,0.105558,0.000000
102.110008,60.124748,-259.101532,0.000341,0.004152,0.105455,267.448242,13.624463,1.054547,-259.101532,0.105558,0.000000
102.200005,60.107620,-259.146027,0.000306,0.004152,0.105455,267.372040,13.620582,1.054547,-259.146027,0.105558,0.000000