File: Data/compression 13/AutoNoHeating-10-13-1-240724_07242024_162246.csv
Time (sec),S:Load (lbs),S:HL1 (DIM),S:LVDT (in),S:Position (in),Ch:Position (mm),Ch:Load (N),Ch:Stress (MPa),Ch:Strain (mm/mm),Ch:HL1 (DIM),Set Point (),Cycles ()
0.110000,0.005959,-149.189117,-0.013116,0.000000,0.000009,0.026505,0.001350,0.000087,-149.189117,0.000234,0.000000
0.370000,-0.002983,-149.233597,-0.013107,0.000000,0.000009,-0.013269,-0.000676,0.000087,-149.233597,0.000234,0.000000
0.630000,0.019737,-149.233597,-0.013107,0.000114,0.002897,0.087796,0.004473,0.028966,-149.233597,0.003929,0.000000
0.890000,0.053993,-149.367035,-0.013016,0.000288,0.007320,0.240174,0.012235,0.073196,-149.367035,0.008247,0.000000
1.150000,0.042824,-149.322556,-0.012844,0.000450,0.011421,0.190490,0.009704,0.114213,-149.322556,0.012584,0.000000
1.410000,0.066650,-149.411514,-0.012667,0.000622,0.015792,0.296476,0.015103,0.157921,-149.411514,0.016920,0.000000
1.670000,0.071495,-149.455994,-0.012499,0.000782,0.019868,0.318026,0.016201,0.198680,-149.455994,0.021256,0.000000
1.930000,0.037239,-149.455994,-0.012322,0.000959,0.024369,0.165648,0.008438,0.243690,-149.455994,0.025575,0.000000
2.190000,0.049896,-149.544952,-0.012120,0.001125,0.028575,0.221950,0.011307,0.285752,-149.544952,0.029911,0.000000
2.450000,0.035004,-149.544952,-0.011939,0.001307,0.033206,0.155704,0.007932,0.332060,-149.544952,0.034247,0.000000
2.710000,-0.004097,-149.589432,-0.011770,0.001471,0.037352,-0.018224,-0.000928,0.373516,-149.589432,0.038583,0.000000
2.970000,0.077827,-149.678406,-0.011615,0.001642,0.041705,0.346194,0.017636,0.417050,-149.678406,0.042902,0.000000
3.230000,0.063301,-149.722885,-0.011443,0.001819,0.046197,0.281577,0.014344,0.461973,-149.722885,0.047238,0.000000
3.490000,0.061440,-149.811844,-0.011266,0.001984,0.050394,0.273297,0.013922,0.503944,-149.811844,0.051574,0.000000
3.750000,0.084526,-149.767365,-0.011076,0.002151,0.054627,0.375991,0.019154,0.546266,-149.767365,0.055910,0.000000
4.010000,0.071869,-149.856323,-0.010904,0.002328,0.059119,0.319689,0.016286,0.591189,-149.856323,0.060229,0.000000
4.270000,0.051384,-149.856323,-0.010710,0.002495,0.063368,0.228567,0.011644,0.633682,-149.856323,0.064565,0.000000
4.530000,0.078568,-149.900803,-0.010542,0.002666,0.067704,0.349486,0.017804,0.677042,-149.900803,0.068901,0.000000
4.790000,0.034256,-149.989761,-0.010374,0.002839,0.072119,0.152378,0.007763,0.721185,-149.989761,0.073237,0.000000
5.050000,0.020477,-149.900803,-0.010171,0.003004,0.076299,0.091088,0.004640,0.762986,-149.900803,0.077556,0.000000
5.310000,0.086014,-150.034241,-0.009985,0.003172,0.080574,0.382608,0.019491,0.805740,-150.034241,0.081892,0.000000
5.570000,0.072983,-150.034241,-0.009830,0.003356,0.085231,0.324644,0.016538,0.852309,-150.034241,0.086228,0.000000
5.830000,0.064049,-150.078735,-0.009671,0.003518,0.089368,0.284903,0.014514,0.893678,-150.078735,0.090547,0.000000
6.090000,0.086761,-150.167694,-0.009498,0.003689,0.093695,0.385934,0.019660,0.936951,-150.167694,0.094883,0.000000
6.350000,0.054741,-150.167694,-0.009296,0.003864,0.098144,0.243500,0.012404,0.981438,-150.167694,0.099220,0.000000
6.610000,0.067398,-150.212173,-0.009119,0.004033,0.102428,0.299802,0.015273,1.024280,-150.212173,0.103555,0.000000
6.870000,0.064423,-150.256653,-0.008959,0.004195,0.106565,0.286566,0.014598,1.065649,-150.256653,0.107874,0.000000
7.130000,0.014893,-150.256653,-0.008761,0.004375,0.111126,0.066245,0.003375,1.111264,-150.256653,0.112210,0.000000
7.390000,0.076332,-150.345612,-0.008610,0.004546,0.115462,0.339542,0.017297,1.154624,-150.345612,0.116546,0.000000
7.650001,0.100166,-150.390091,-0.008446,0.004710,0.119642,0.445562,0.022698,1.196424,-150.390091,0.120882,0.000000
7.910000,0.058830,-150.390091,-0.008248,0.004885,0.124091,0.261690,0.013331,1.240912,-150.390091,0.125202,0.000000
8.170000,0.086388,-150.479065,-0.008075,0.005060,0.128532,0.384271,0.019576,1.285316,-150.479065,0.129538,0.000000
8.430000,0.065163,-150.523544,-0.007894,0.005221,0.132616,0.289858,0.014766,1.326163,-150.523544,0.133874,0.000000
8.690001,0.035378,-150.568024,-0.007722,0.005396,0.137057,0.157367,0.008017,1.370567,-150.568024,0.138210,0.000000
8.950001,0.074104,-150.568024,-0.007532,0.005567,0.141401,0.329632,0.016792,1.414010,-150.568024,0.142529,0.000000
9.210000,0.055107,-150.656982,-0.007377,0.005735,0.145668,0.245129,0.012487,1.456681,-150.656982,0.146865,0.000000
9.470000,0.078941,-150.701462,-0.007174,0.005904,0.149961,0.351149,0.017888,1.499609,-150.701462,0.151201,0.000000
9.730000,0.086014,-150.656982,-0.007015,0.006082,0.154488,0.382608,0.019491,1.544877,-150.656982,0.155519,0.000000
9.990001,0.119904,-150.790421,-0.006842,0.006247,0.158676,0.533358,0.027171,1.586760,-150.790421,0.159855,0.000000
10.250001,0.096817,-150.790421,-0.006661,0.006418,0.163013,0.430664,0.021939,1.630128,-150.790421,0.164192,0.000000
10.510000,0.088623,-150.879379,-0.006489,0.006592,0.167435,0.394215,0.020082,1.674351,-150.879379,0.168528,0.000000
10.770000,0.078568,-150.879379,-0.006316,0.006758,0.171659,0.349486,0.017804,1.716590,-150.879379,0.172847,0.000000
11.030001,0.040588,-150.879379,-0.006092,0.006929,0.175995,0.180546,0.009197,1.759950,-150.879379,0.177183,0.000000
11.290001,0.073357,-150.968353,-0.005976,0.007103,0.180418,0.326307,0.016623,1.804180,-150.968353,0.181519,0.000000
11.550000,0.097191,-150.923874,-0.005777,0.007279,0.184875,0.432327,0.022024,1.848751,-150.923874,0.185855,0.000000
11.810000,0.072243,-151.057312,-0.005609,0.007442,0.189038,0.321352,0.016370,1.890377,-151.057312,0.190174,0.000000
12.070001,0.106873,-151.101791,-0.005394,0.007613,0.193383,0.475393,0.024218,1.933828,-151.101791,0.194510,0.000000
12.330001,0.108360,-151.146271,-0.005251,0.007783,0.197676,0.482011,0.024555,1.976756,-151.146271,0.198846,0.000000
12.590000,0.083786,-151.146271,-0.005088,0.007955,0.202064,0.372699,0.018986,2.020638,-151.146271,0.203183,0.000000
12.850000,0.102028,-151.146271,-0.004907,0.008121,0.206270,0.453843,0.023120,2.062696,-151.146271,0.207501,0.000000
13.110001,0.090858,-151.279709,-0.004687,0.008301,0.210840,0.404159,0.020589,2.108402,-151.279709,0.211837,0.000000
13.370001,0.062187,-151.324188,-0.004531,0.008464,0.214976,0.276622,0.014092,2.149764,-151.324188,0.216173,0.000000
13.630001,0.186928,-151.324188,-0.004312,0.008635,0.219321,0.831496,0.042358,2.193214,-151.324188,0.220510,0.000000
13.890000,0.749214,-151.368683,-0.004174,0.008799,0.223484,3.332671,0.169774,2.234840,-151.368683,0.223493,0.000000
14.150001,0.645691,-151.324188,-0.004135,-0.000003,-0.000079,2.872177,0.146316,-0.000787,-151.324188,0.000095,0.000000
14.410001,0.633034,-151.457642,-0.004178,-0.000003,-0.000079,2.815875,0.143448,-0.000787,-151.457642,0.000129,0.000000
14.670001,0.637871,-151.457642,-0.004148,-0.000003,-0.000079,2.837391,0.144544,-0.000787,-151.457642,0.000563,0.000000
14.930000,0.607338,-151.502121,-0.004126,-0.000003,-0.000070,2.701574,0.137625,-0.000696,-151.502121,0.000997,0.000000
15.190001,0.605103,-151.591080,-0.004178,-0.000003,-0.000070,2.691631,0.137118,-0.000696,-151.591080,0.001431,0.000000
15.450001,0.960350,-151.591080,-0.004126,0.000040,0.001005,4.271850,0.217618,0.010053,-151.591080,0.001864,0.000000
15.710001,1.096634,-151.680038,-0.004122,0.000057,0.001448,4.878071,0.248501,0.014481,-151.680038,0.002297,0.000000
15.970001,1.263832,-151.724518,-0.004113,0.000074,0.001873,5.621806,0.286388,0.018728,-151.724518,0.002731,0.000000
16.230001,1.356552,-151.724518,-0.004096,0.000086,0.002185,6.034245,0.307399,0.021854,-151.724518,0.003165,0.000000
16.490002,1.499542,-151.813492,-0.004083,0.000102,0.002601,6.670297,0.339801,0.026010,-151.813492,0.003599,0.000000
16.750000,1.793716,-151.813492,-0.004027,0.000129,0.003287,7.978849,0.406462,0.032868,-151.813492,0.004032,0.000000
17.010000,1.932983,-151.857971,-0.004057,0.000145,0.003686,8.598340,0.438020,0.036857,-151.857971,0.004466,0.000000
17.270000,2.023842,-151.813492,-0.004018,0.000157,0.003998,9.002499,0.458609,0.039976,-151.813492,0.004899,0.000000
17.530001,2.201836,-151.946930,-0.004010,0.000173,0.004387,9.794254,0.498943,0.043875,-151.946930,0.005333,0.000000
17.790001,2.439041,-151.946930,-0.004001,0.000194,0.004926,10.849397,0.552695,0.049257,-151.946930,0.005767,0.000000
18.050001,2.582031,-151.991409,-0.003980,0.000209,0.005298,11.485449,0.585097,0.052981,-151.991409,0.006200,0.000000
18.310001,2.637886,-152.124847,-0.003954,0.000215,0.005463,11.733903,0.597753,0.054631,-152.124847,0.006634,0.000000
18.570002,3.060158,-152.124847,-0.003958,0.000244,0.006191,13.612262,0.693442,0.061913,-152.124847,0.007068,0.000000
18.830002,3.183037,-152.169327,-0.003919,0.000262,0.006642,14.158854,0.721286,0.066425,-152.169327,0.007501,0.000000
19.090000,3.289536,-152.124847,-0.003906,0.000274,0.006972,14.632585,0.745419,0.069718,-152.124847,0.007926,0.000000
19.350000,3.450775,-152.258301,-0.003876,0.000292,0.007423,15.349814,0.781957,0.074229,-152.258301,0.008360,0.000000
19.610001,3.755005,-152.258301,-0.003898,0.000310,0.007882,16.703096,0.850896,0.078824,-152.258301,0.008793,0.000000
19.870001,3.901718,-152.347260,-0.003850,0.000327,0.008308,17.355709,0.884142,0.083078,-152.347260,0.009227,0.000000
20.130001,4.014549,-152.302780,-0.003833,0.000340,0.008637,17.857607,0.909710,0.086371,-152.302780,0.009661,0.000000
20.390001,4.208923,-152.391739,-0.003829,0.000356,0.009036,18.722225,0.953756,0.090361,-152.391739,0.010094,0.000000
20.650002,4.635292,-152.391739,-0.003798,0.000381,0.009669,20.618809,1.050372,0.096689,-152.391739,0.010528,0.000000
20.910002,4.725037,-152.525177,-0.003781,0.000397,0.010077,21.018013,1.070709,0.100769,-152.525177,0.010961,0.000000
21.170000,4.799881,-152.480698,-0.003790,0.000410,0.010424,21.350937,1.087669,0.104236,-152.480698,0.011395,0.000000
21.430000,5.081390,-152.569656,-0.003760,0.000431,0.010944,22.603153,1.151459,0.109444,-152.569656,0.011829,0.000000
21.690001,5.272797,-152.614136,-0.003734,0.000448,0.011369,23.454571,1.194833,0.113691,-152.614136,0.012262,0.000000
21.950001,5.432915,-152.658630,-0.003729,0.000464,0.011794,24.166811,1.231116,0.117937,-152.658630,0.012696,0.000000
22.210001,5.478714,-152.703110,-0.003725,0.000476,0.012097,24.370537,1.241494,0.120973,-152.703110,0.013130,0.000000
22.470001,5.754646,-152.703110,-0.003691,0.000494,0.012557,25.597944,1.304022,0.125568,-152.703110,0.013563,0.000000
22.730001,6.017914,-152.747589,-0.003652,0.000516,0.013103,26.769018,1.363679,0.131033,-152.747589,0.013997,0.000000
22.990002,6.139305,-152.792068,-0.003652,0.000533,0.013529,27.308992,1.391186,0.135287,-152.792068,0.014430,0.000000
23.250002,6.285271,-152.792068,-0.003643,0.000550,0.013962,27.958281,1.424263,0.139617,-152.792068,0.014864,0.000000
23.510000,6.433853,-152.925507,-0.003613,0.000566,0.014387,28.619207,1.457932,0.143871,-152.925507,0.015298,0.000000
23.770000,6.625992,-152.881027,-0.003600,0.000583,0.014821,29.473885,1.501471,0.148209,-152.881027,0.015731,0.000000
24.030001,6.723557,-152.969986,-0.003561,0.000596,0.015150,29.907873,1.523580,0.151502,-152.969986,0.016165,0.000000
24.290001,7.025551,-153.014465,-0.003566,0.000618,0.015688,31.251211,1.592013,0.156876,-153.014465,0.016598,0.000000
24.550001,7.289566,-153.058960,-0.003548,0.000638,0.016217,32.425610,1.651839,0.162168,-153.058960,0.017032,0.000000
24.810001,7.330521,-153.103439,-0.003505,0.000654,0.016616,32.607784,1.661120,0.166157,-153.103439,0.017466,0.000000
25.070002,7.316376,-153.103439,-0.003501,0.000666,0.016919,32.544865,1.657914,0.169192,-153.103439,0.017900,0.000000
25.330002,7.400528,-153.103439,-0.003475,0.000680,0.017275,32.919193,1.676984,0.172750,-153.103439,0.018333,0.000000
25.590002,7.753540,-153.192398,-0.003462,0.000700,0.017769,34.489468,1.756977,0.177693,-153.192398,0.018766,0.000000
25.850000,7.809395,-153.236877,-0.003445,0.000714,0.018133,34.737923,1.769634,0.181334,-153.236877,0.019200,0.000000
26.110001,7.850731,-153.325836,-0.003423,0.000727,0.018463,34.921795,1.779001,0.184627,-153.325836,0.019634,0.000000
26.370001,8.155701,-153.281357,-0.003385,0.000747,0.018984,36.278370,1.848108,0.189835,-153.281357,0.020068,0.000000
26.630001,8.469238,-153.370316,-0.003367,0.000773,0.019642,37.673054,1.919157,0.196421,-153.370316,0.020501,0.000000
26.890001,8.296082,-153.325836,-0.003354,0.000786,0.019972,36.902813,1.879919,0.199721,-153.325836,0.020934,0.000000
27.150002,8.408913,-153.414795,-0.003354,0.000802,0.020371,37.404713,1.905487,0.203711,-153.414795,0.021368,0.000000
27.410002,8.647980,-153.503769,-0.003328,0.000819,0.020804,38.468136,1.959660,0.208041,-153.503769,0.021802,0.000000
27.670002,9.106369,-153.503769,-0.003307,0.000843,0.021403,40.507153,2.063533,0.214028,-153.503769,0.022235,0.000000
27.930002,8.910500,-153.592728,-0.003277,0.000855,0.021706,39.635883,2.019148,0.217064,-153.592728,0.022660,0.000000
28.190001,9.238190,-153.592728,-0.003251,0.000878,0.022313,41.093521,2.093404,0.223135,-153.592728,0.023094,0.000000
28.450001,9.230370,-153.592728,-0.003212,0.000895,0.022730,41.058735,2.091632,0.227298,-153.592728,0.023528,0.000000
28.710001,9.079926,-153.770645,-0.003182,0.000905,0.022989,40.389526,2.057541,0.229895,-153.770645,0.023961,0.000000
28.970001,9.208023,-153.681686,-0.003178,0.000921,0.023406,40.959332,2.086568,0.234058,-153.681686,0.024394,0.000000
29.230001,9.360695,-153.770645,-0.003152,0.000935,0.023753,41.638451,2.121164,0.237532,-153.770645,0.024828,0.000000
29.490002,9.801590,-153.770645,-0.003122,0.000957,0.024316,43.599651,2.221072,0.243164,-153.770645,0.025262,0.000000
29.750002,9.775520,-153.815125,-0.003117,0.000973,0.024707,43.483685,2.215165,0.247070,-153.815125,0.025696,0.000000
30.010002,9.714081,-153.948578,-0.003100,0.000984,0.025002,43.210388,2.201242,0.250015,-153.948578,0.026129,0.000000
30.270002,10.388443,-153.859604,-0.003057,0.001016,0.025799,46.210102,2.354055,0.257994,-153.859604,0.026563,0.000000
30.530001,9.985542,-154.037537,-0.003053,0.001026,0.026060,44.417912,2.262756,0.260598,-154.037537,0.026996,0.000000
30.790001,10.046608,-153.948578,-0.003027,0.001042,0.026467,44.689545,2.276594,0.264670,-153.948578,0.027430,0.000000
31.050001,10.173218,-154.037537,-0.002997,0.001057,0.026858,45.252731,2.305284,0.268576,-154.037537,0.027864,0.000000
31.310001,10.157204,-154.082016,-0.002962,0.001075,0.027309,45.181499,2.301655,0.273088,-154.082016,0.028297,0.000000
31.570002,10.576118,-154.082016,-0.002945,0.001094,0.027786,47.044926,2.396583,0.277857,-154.082016,0.028731,0.000000
31.830002,10.484146,-154.170975,-0.002928,0.001107,0.028124,46.635811,2.375741,0.281240,-154.170975,0.029164,0.000000
32.090000,10.606285,-154.170975,-0.002897,0.001126,0.028601,47.179111,2.403419,0.286009,-154.170975,0.029598,0.000000
32.350002,10.960785,-154.215454,-0.002854,0.001149,0.029182,48.756008,2.483749,0.291815,-154.215454,0.030032,0.000000
32.610001,10.769753,-154.259933,-0.002854,0.001162,0.029512,47.906250,2.440461,0.295116,-154.259933,0.030465,0.000000
32.870003,10.916473,-154.304413,-0.002807,0.001179,0.029945,48.558899,2.473708,0.299446,-154.304413,0.030899,0.000000
33.130001,10.831566,-154.393387,-0.002802,0.001193,0.030300,48.181210,2.454468,0.303004,-154.393387,0.031333,0.000000
33.390003,11.413589,-154.393387,-0.002785,0.001218,0.030942,50.770180,2.586356,0.309423,-154.393387,0.031766,0.000000
33.650002,11.279907,-154.437866,-0.002768,0.001231,0.031263,50.175533,2.556064,0.312632,-154.437866,0.032200,0.000000
33.910000,11.175644,-154.571304,-0.002755,0.001241,0.031532,49.711746,2.532437,0.315320,-154.571304,0.032633,0.000000
34.170002,11.834366,-154.482346,-0.002703,0.001271,0.032287,52.641888,2.681706,0.322867,-154.482346,0.033067,0.000000
34.430000,11.649673,-154.615784,-0.002677,0.001285,0.032651,51.820335,2.639854,0.326508,-154.615784,0.033501,0.000000
34.690002,11.459389,-154.482346,-0.002643,0.001296,0.032929,50.973907,2.596735,0.329286,-154.482346,0.033934,0.000000
34.950001,11.688774,-154.615784,-0.002604,0.001314,0.033379,51.994263,2.648714,0.333790,-154.615784,0.034368,0.000000
35.210003,12.178444,-154.704742,-0.002600,0.001339,0.034003,54.172424,2.759675,0.340035,-154.704742,0.034801,0.000000
35.470001,12.012733,-154.660263,-0.002591,0.001353,0.034359,53.435307,2.722124,0.343593,-154.660263,0.035235,0.000000
35.730003,11.712975,-154.793716,-0.002544,0.001361,0.034576,52.101913,2.654198,0.345758,-154.793716,0.035669,0.000000
35.990002,12.128540,-154.749222,-0.002544,0.001383,0.035122,53.950439,2.748366,0.351223,-154.749222,0.036103,0.000000
36.250000,12.361275,-154.793716,-0.002496,0.001401,0.035591,54.985695,2.801105,0.355909,-154.793716,0.036536,0.000000
36.510002,12.413033,-154.882675,-0.002471,0.001420,0.036059,55.215927,2.812833,0.360587,-154.882675,0.036969,0.000000
36.770000,12.339302,-154.882675,-0.002471,0.001434,0.036423,54.887959,2.796126,0.364228,-154.882675,0.037403,0.000000
37.030003,12.624916,-154.971634,-0.002402,0.001455,0.036952,56.158432,2.860847,0.369519,-154.971634,0.037828,0.000000
37.290001,12.747429,-154.927155,-0.002402,0.001473,0.037403,56.703396,2.888609,0.374031,-154.927155,0.038262,0.000000
37.550003,12.560867,-155.016113,-0.002358,0.001485,0.037707,55.873528,2.846333,0.377066,-155.016113,0.038695,0.000000
37.810001,12.458092,-155.105072,-0.002363,0.001496,0.038001,55.416359,2.823044,0.380011,-155.105072,0.039129,0.000000
38.070004,13.231506,-155.060593,-0.002324,0.001527,0.038791,58.856678,2.998302,0.387906,-155.060593,0.039563,0.000000
38.330002,13.051285,-155.194031,-0.002289,0.001543,0.039190,58.055016,2.957464,0.391896,-155.194031,0.039996,0.000000
38.590000,12.853180,-155.149551,-0.002281,0.001556,0.039511,57.173801,2.912572,0.395105,-155.149551,0.040429,0.000000
38.850002,12.944412,-155.194031,-0.002255,0.001572,0.039918,57.579620,2.933246,0.399178,-155.194031,0.040863,0.000000
39.110001,13.268745,-155.238525,-0.002229,0.001592,0.040447,59.022327,3.006741,0.404469,-155.238525,0.041297,0.000000
39.370003,13.310822,-155.327484,-0.002207,0.001608,0.040838,59.209492,3.016275,0.408375,-155.327484,0.041731,0.000000
39.630001,12.944412,-155.371964,-0.002164,0.001614,0.040985,57.579620,2.933246,0.409851,-155.371964,0.042164,0.000000
39.890003,13.681709,-155.371964,-0.002160,0.001642,0.041696,60.859283,3.100320,0.416959,-155.371964,0.042597,0.000000
40.150002,13.684685,-155.505402,-0.002121,0.001660,0.042173,60.872517,3.100994,0.421728,-155.505402,0.043031,0.000000
40.410004,13.458282,-155.505402,-0.002091,0.001673,0.042494,59.865429,3.049690,0.424938,-155.505402,0.043465,0.000000
40.670002,13.477272,-155.505402,-0.002091,0.001692,0.042971,59.949902,3.053993,0.429707,-155.505402,0.043899,0.000000
40.930000,13.599785,-155.638855,-0.002057,0.001709,0.043404,60.494865,3.081755,0.434044,-155.638855,0.044332,0.000000
41.190002,13.807198,-155.549881,-0.002031,0.001726,0.043838,61.417480,3.128756,0.438382,-155.549881,0.044765,0.000000
41.450001,13.701813,-155.638855,-0.002001,0.001739,0.044167,60.948708,3.104875,0.441675,-155.638855,0.045199,0.000000
41.710003,13.585266,-155.683334,-0.001988,0.001752,0.044497,60.430283,3.078465,0.444967,-155.683334,0.045633,0.000000
41.970001,14.447304,-155.727814,-0.001953,0.001780,0.045208,64.264816,3.273806,0.452083,-155.727814,0.046067,0.000000
42.230003,14.242126,-155.772293,-0.001910,0.001795,0.045598,63.352142,3.227312,0.455981,-155.772293,0.046500,0.000000
42.490002,14.034714,-155.772293,-0.001888,0.001809,0.045954,62.429523,3.180312,0.459539,-155.772293,0.046934,0.000000
42.750004,14.211594,-155.861252,-0.001858,0.001828,0.046440,63.216324,3.220393,0.464399,-155.861252,0.047367,0.000000
43.010002,14.365753,-155.905731,-0.001850,0.001847,0.046908,63.902061,3.255326,0.469077,-155.905731,0.047801,0.000000
43.270000,14.293518,-155.861252,-0.001794,0.001862,0.047307,63.580746,3.238957,0.473066,-155.861252,0.048235,0.000000
43.530003,14.171005,-155.950211,-0.001794,0.001876,0.047653,63.035778,3.211196,0.476533,-155.950211,0.048668,0.000000
43.790001,14.479706,-155.950211,-0.001750,0.001897,0.048192,64.408951,3.281148,0.481916,-155.950211,0.049102,0.000000
44.050003,14.556786,-155.994690,-0.001725,0.001915,0.048634,64.751816,3.298615,0.486336,-155.994690,0.049536,0.000000
44.310001,14.605934,-156.083664,-0.001712,0.001931,0.049058,64.970444,3.309752,0.490583,-156.083664,0.049969,0.000000
44.570004,14.503159,-156.039169,-0.001712,0.001945,0.049397,64.513275,3.286463,0.493967,-156.039169,0.050403,0.000000
44.830002,14.623436,-156.172623,-0.001677,0.001963,0.049856,65.048294,3.313718,0.498562,-156.172623,0.050836,0.000000
45.090004,14.812233,-156.128143,-0.001656,0.001982,0.050342,65.888100,3.356500,0.503421,-156.128143,0.051270,0.000000
45.350002,14.691582,-156.217102,-0.001638,0.001994,0.050654,65.351418,3.329160,0.506540,-156.217102,0.051704,0.000000
45.610001,15.027092,-156.217102,-0.001600,0.002016,0.051210,66.843842,3.405188,0.512096,-156.217102,0.052137,0.000000
45.870003,15.397224,-156.306061,-0.001574,0.002037,0.051747,68.490273,3.489061,0.517471,-156.306061,0.052571,0.000000
46.130001,15.189819,-156.439499,-0.001556,0.002053,0.052154,67.567688,3.442062,0.521543,-156.439499,0.052996,0.000000
46.390003,14.940697,-156.395020,-0.001505,0.002067,0.052493,66.459541,3.385610,0.524927,-156.395020,0.053429,0.000000
46.650002,14.837555,-156.439499,-0.001487,0.002078,0.052788,66.000740,3.362238,0.527879,-156.439499,0.053863,0.000000
46.910004,15.217003,-156.439499,-0.001475,0.002098,0.053291,67.688606,3.448222,0.532906,-156.439499,0.054297,0.000000
47.170002,15.211784,-156.528473,-0.001462,0.002113,0.053664,67.665398,3.447040,0.536638,-156.528473,0.054730,0.000000
47.430004,15.161140,-156.617432,-0.001427,0.002126,0.054010,67.440125,3.435564,0.540105,-156.617432,0.055164,0.000000
47.690002,15.509682,-156.572952,-0.001388,0.002147,0.054530,68.990509,3.514544,0.545305,-156.572952,0.055598,0.000000
47.950001,15.972168,-156.661911,-0.001375,0.002173,0.055190,71.047752,3.619345,0.551898,-156.661911,0.056031,0.000000
48.210003,15.556229,-156.706390,-0.001367,0.002187,0.055554,69.197563,3.525092,0.555539,-156.706390,0.056465,0.000000
48.470001,15.436699,-156.661911,-0.001337,0.002200,0.055892,68.665863,3.498006,0.558923,-156.661911,0.056898,0.000000
48.730003,15.726036,-156.795349,-0.001332,0.002219,0.056369,69.952904,3.563571,0.563692,-156.795349,0.057332,0.000000
48.990002,16.013130,-156.750870,-0.001281,0.002240,0.056890,71.229958,3.628627,0.568900,-156.750870,0.057766,0.000000
49.250004,15.788589,-156.839828,-0.001242,0.002253,0.057219,70.231155,3.577745,0.572193,-156.839828,0.058199,0.000000
49.510002,16.239532,-156.884308,-0.001229,0.002276,0.057809,72.237045,3.679931,0.578090,-156.884308,0.058633,0.000000
49.770000,16.225754,-156.928802,-0.001199,0.002293,0.058251,72.175758,3.676808,0.582510,-156.928802,0.059066,0.000000
50.030003,15.867165,-156.973282,-0.001160,0.002305,0.058555,70.580673,3.595551,0.585546,-156.973282,0.059500,0.000000
50.290001,15.942009,-156.973282,-0.001168,0.002321,0.058945,70.913597,3.612511,0.589452,-156.973282,0.059934,0.000000
50.550003,15.969566,-157.017761,-0.001117,0.002334,0.059274,71.036179,3.618756,0.592745,-157.017761,0.060368,0.000000
50.810001,16.578766,-157.106720,-0.001117,0.002358,0.059890,73.746033,3.756802,0.598899,-157.106720,0.060801,0.000000
51.070004,16.462585,-157.062241,-0.001104,0.002371,0.060228,73.229240,3.730475,0.602283,-157.062241,0.061234,0.000000
51.330002,16.245491,-157.151199,-0.001082,0.002383,0.060532,72.263550,3.681281,0.605318,-157.151199,0.061668,0.000000
51.590004,17.277336,-157.151199,-0.001043,0.002414,0.061321,76.853432,3.915100,0.613214,-157.151199,0.062102,0.000000
51.850002,16.545250,-157.240158,-0.001013,0.002424,0.061581,73.596947,3.749207,0.615810,-157.240158,0.062536,0.000000
52.110001,16.529243,-157.284637,-0.000987,0.002440,0.061980,73.525749,3.745580,0.619799,-157.284637,0.062969,0.000000
52.370003,16.635742,-157.284637,-0.000970,0.002456,0.062379,73.999474,3.769713,0.623789,-157.284637,0.063402,0.000000
52.630001,16.201927,-157.418091,-0.000940,0.002466,0.062648,72.069771,3.671409,0.626483,-157.418091,0.063836,0.000000
52.890003,17.054283,-157.373611,-0.000927,0.002492,0.063299,75.861237,3.864556,0.632986,-157.373611,0.064270,0.000000
53.150002,16.877777,-157.373611,-0.000892,0.002505,0.063637,75.076103,3.824559,0.636370,-157.373611,0.064704,0.000000
53.410004,16.842033,-157.462570,-0.000897,0.002522,0.064053,74.917107,3.816459,0.640533,-157.462570,0.065137,0.000000
53.670002,17.537628,-157.551529,-0.000867,0.002548,0.064712,78.011269,3.974083,0.647119,-157.551529,0.065570,0.000000
53.930004,16.977577,-157.551529,-0.000828,0.002559,0.064998,75.520035,3.847174,0.649980,-157.551529,0.066004,0.000000
54.190002,17.150726,-157.551529,-0.000802,0.002577,0.065467,76.290237,3.886410,0.654666,-157.551529,0.066438,0.000000
54.450001,16.918739,-157.596008,-0.000772,0.002591,0.065822,75.258308,3.833841,0.658224,-157.596008,0.066872,0.000000
54.710003,17.565178,-157.729446,-0.000750,0.002614,0.066403,78.133812,3.980326,0.664030,-157.729446,0.067305,0.000000
54.970001,17.466873,-157.640488,-0.000720,0.002628,0.066759,77.696533,3.958050,0.667587,-157.640488,0.067730,0.000000
55.230003,17.219246,-157.773926,-0.000694,0.002640,0.067053,76.595032,3.901937,0.670532,-157.773926,0.068164,0.000000
55.490002,18.022453,-157.729446,-0.000673,0.002669,0.067800,80.167877,4.083946,0.677996,-157.729446,0.068597,0.000000
55.750004,17.868294,-157.773926,-0.000647,0.002684,0.068181,79.482140,4.049013,0.681811,-157.773926,0.069031,0.000000
56.010002,17.384209,-157.907379,-0.000629,0.002696,0.068467,77.328819,3.939318,0.684672,-157.907379,0.069464,0.000000
56.270004,17.551399,-157.907379,-0.000586,0.002712,0.068892,78.072525,3.977204,0.688919,-157.907379,0.069898,0.000000
56.530003,18.290565,-157.907379,-0.000565,0.002737,0.069525,81.360497,4.144701,0.695255,-157.907379,0.070332,0.000000
56.790001,17.976280,-157.951859,-0.000526,0.002751,0.069872,79.962486,4.073483,0.698722,-157.951859,0.070765,0.000000
57.050003,17.385323,-157.996338,-0.000535,0.002759,0.070071,77.333778,3.939570,0.700713,-157.996338,0.071199,0.000000
57.310001,18.091339,-157.996338,-0.000500,0.002783,0.070678,80.474297,4.099556,0.706784,-157.996338,0.071632,0.000000
57.570004,18.158371,-158.085297,-0.000466,0.002799,0.071086,80.772469,4.114746,0.710864,-158.085297,0.072066,0.000000
57.830002,18.264870,-158.085297,-0.000444,0.002817,0.071563,81.246201,4.138879,0.715633,-158.085297,0.072500,0.000000
58.090004,18.181831,-158.174255,-0.000427,0.002834,0.071980,80.876823,4.120062,0.719796,-158.174255,0.072933,0.000000
58.350002,18.525154,-158.129776,-0.000410,0.002854,0.072482,82.403999,4.197860,0.724823,-158.129776,0.073367,0.000000
58.610004,18.591812,-158.218750,-0.000384,0.002870,0.072908,82.700508,4.212965,0.729077,-158.218750,0.073801,0.000000
58.870003,18.465950,-158.218750,-0.000345,0.002883,0.073228,82.140648,4.184444,0.732279,-158.218750,0.074234,0.000000
59.130001,18.302475,-158.396667,-0.000341,0.002895,0.073523,81.413475,4.147400,0.735231,-158.396667,0.074668,0.000000
59.390003,19.495186,-158.352188,-0.000306,0.002926,0.074329,86.718918,4.417672,0.743293,-158.352188,0.075101,0.000000
59.650002,19.219627,-158.396667,-0.000293,0.002941,0.074711,85.493172,4.355230,0.747108,-158.396667,0.075535,0.000000
59.910004,19.025253,-158.396667,-0.000289,0.002954,0.075041,84.628555,4.311184,0.750408,-158.396667,0.075969,0.000000
60.170002,19.114998,-158.441147,-0.000246,0.002970,0.075440,85.027756,4.331520,0.754398,-158.441147,0.076402,0.000000
60.430004,19.877617,-158.574585,-0.000224,0.002992,0.075986,88.420059,4.504333,0.759863,-158.574585,0.076836,0.000000
60.690002,20.027679,-158.530106,-0.000194,0.003006,0.076350,89.087570,4.538337,0.763504,-158.530106,0.077269,0.000000
60.950005,19.661636,-158.574585,-0.000190,0.003012,0.076506,87.459328,4.455390,0.765064,-158.574585,0.077703,0.000000
61.210003,20.900146,-158.663559,-0.000168,0.003040,0.077217,92.968498,4.736041,0.772172,-158.663559,0.078137,0.000000
61.470001,21.235657,-158.619064,-0.000142,0.003058,0.077686,94.460922,4.812069,0.776857,-158.619064,0.078571,0.000000
61.730003,21.187248,-158.708038,-0.000142,0.003071,0.078015,94.245590,4.801099,0.780150,-158.708038,0.079004,0.000000
61.990002,21.520889,-158.752518,-0.000125,0.003091,0.078501,95.729698,4.876703,0.785010,-158.752518,0.079437,0.000000
62.250004,21.553665,-158.752518,-0.000069,0.003101,0.078770,95.875488,4.884130,0.787697,-158.752518,0.079871,0.000000
62.510002,22.551994,-158.841476,-0.000065,0.003124,0.079359,100.316284,5.110355,0.793594,-158.841476,0.080305,0.000000
62.770004,22.623489,-158.841476,-0.000060,0.003138,0.079706,100.634308,5.126556,0.797061,-158.841476,0.080739,0.000000
63.030003,22.851753,-158.930435,-0.000043,0.003153,0.080088,101.649673,5.178281,0.800876,-158.930435,0.081172,0.000000
63.290005,24.315552,-158.885956,-0.000030,0.003180,0.080782,108.160973,5.509983,0.807818,-158.885956,0.081605,0.000000
63.550003,24.508064,-159.019394,0.000004,0.003194,0.081120,109.017311,5.553607,0.811201,-159.019394,0.082039,0.000000
63.810001,24.615677,-158.930435,0.000026,0.003209,0.081502,109.496002,5.577992,0.815017,-158.930435,0.082473,0.000000
64.070000,25.389473,-159.063889,0.000030,0.003229,0.082022,112.938019,5.753337,0.820217,-159.063889,0.082898,0.000000
64.330002,25.943558,-159.108368,0.000039,0.003248,0.082490,115.402710,5.878894,0.824903,-159.108368,0.083331,0.000000
64.590004,26.349449,-159.152847,0.000060,0.003262,0.082846,117.208206,5.970870,0.828461,-159.152847,0.083765,0.000000
64.850006,26.536377,-159.197327,0.000082,0.003274,0.083166,118.039703,6.013229,0.831663,-159.197327,0.084199,0.000000
65.110001,27.439384,-159.197327,0.000108,0.003295,0.083704,122.056480,6.217853,0.837045,-159.197327,0.084633,0.000000
65.370003,28.174820,-159.197327,0.000112,0.003313,0.084147,125.327858,6.384506,0.841465,-159.197327,0.085066,0.000000
65.630005,28.730026,-159.286285,0.000108,0.003330,0.084580,127.797539,6.510317,0.845803,-159.286285,0.085499,0.000000
65.889999,29.079308,-159.286285,0.000134,0.003343,0.084919,129.351227,6.589466,0.849187,-159.286285,0.085933,0.000000
66.150002,29.872093,-159.330765,0.000160,0.003362,0.085404,132.877701,6.769113,0.854039,-159.330765,0.086367,0.000000
66.410004,30.677902,-159.375244,0.000164,0.003381,0.085872,136.462128,6.951712,0.858725,-159.375244,0.086801,0.000000
66.670006,31.151566,-159.375244,0.000172,0.003393,0.086184,138.569092,7.059046,0.861843,-159.375244,0.087234,0.000000
66.930000,32.105949,-159.464203,0.000194,0.003415,0.086731,142.814392,7.275312,0.867309,-159.464203,0.087667,0.000000
67.190002,33.381325,-159.508698,0.000207,0.003436,0.087277,148.487549,7.564316,0.872774,-159.508698,0.088101,0.000000
67.450005,34.000587,-159.597656,0.000229,0.003452,0.087676,151.242172,7.704643,0.876763,-159.597656,0.088535,0.000000
67.710007,34.260872,-159.597656,0.000224,0.003465,0.088006,152.399963,7.763625,0.880056,-159.597656,0.088968,0.000000
67.970001,34.735649,-159.597656,0.000224,0.003479,0.088361,154.511887,7.871211,0.883614,-159.597656,0.089402,0.000000
68.230003,35.868774,-159.686615,0.000216,0.003496,0.088803,159.552277,8.127980,0.888035,-159.686615,0.089835,0.000000
68.490005,36.489525,-159.686615,0.000254,0.003511,0.089185,162.313507,8.268644,0.891850,-159.686615,0.090269,0.000000
68.750000,37.103188,-159.775574,0.000272,0.003525,0.089541,165.043228,8.407702,0.895408,-159.775574,0.090703,0.000000
69.010002,38.146950,-159.775574,0.000289,0.003543,0.089992,169.686111,8.644222,0.899919,-159.775574,0.091136,0.000000
69.270004,40.101158,-159.775574,0.000289,0.003570,0.090677,178.378860,9.087052,0.906770,-159.775574,0.091570,0.000000
69.530006,40.500343,-159.864532,0.000302,0.003582,0.090989,180.154526,9.177509,0.909889,-159.864532,0.092004,0.000000
69.790001,41.136360,-159.864532,0.000306,0.003598,0.091397,182.983673,9.321632,0.913969,-159.864532,0.092437,0.000000
70.050003,42.127983,-159.997986,0.000315,0.003615,0.091830,187.394623,9.546337,0.918299,-159.997986,0.092871,0.000000
70.310005,43.650620,-159.953506,0.000328,0.003638,0.092394,194.167648,9.891372,0.923938,-159.953506,0.093304,0.000000
70.570000,44.258331,-159.953506,0.000336,0.003651,0.092732,196.870895,10.029081,0.927322,-159.953506,0.093738,0.000000
70.830002,45.736275,-160.086945,0.000345,0.003674,0.093313,203.445114,10.363988,0.933128,-160.086945,0.094172,0.000000
71.090004,46.891373,-160.131424,0.000358,0.003691,0.093764,208.583237,10.625737,0.937640,-160.131424,0.094605,0.000000
71.350006,47.290932,-160.175903,0.000379,0.003703,0.094068,210.360565,10.716278,0.940675,-160.175903,0.095039,0.000000
71.610001,48.089294,-160.175903,0.000388,0.003719,0.094466,213.911865,10.897190,0.944664,-160.175903,0.095472,0.000000
71.870003,48.963257,-160.264862,0.000375,0.003732,0.094796,217.799438,11.095233,0.947957,-160.264862,0.095906,0.000000
72.130005,50.687340,-160.309341,0.000405,0.003755,0.095369,225.468552,11.485916,0.953688,-160.309341,0.096340,0.000000
72.390007,51.630928,-160.264862,0.000392,0.003770,0.095750,229.665833,11.699735,0.957503,-160.264862,0.096774,0.000000
72.650002,51.897179,-160.398315,0.000431,0.003780,0.096010,230.850174,11.760068,0.960099,-160.398315,0.097207,0.000000
72.910004,54.818810,-160.398315,0.000418,0.003812,0.096834,243.846237,12.422120,0.968343,-160.398315,0.097640,0.000000
73.170006,55.316299,-160.353836,0.000418,0.003823,0.097094,246.059189,12.534853,0.970939,-160.353836,0.098066,0.000000
73.430000,56.307556,-160.487274,0.000435,0.003838,0.097476,250.468521,12.759475,0.974762,-160.487274,0.098499,0.000000
73.690002,57.546066,-160.442795,0.000427,0.003854,0.097901,255.977692,13.040125,0.979008,-160.442795,0.098933,0.000000
73.950005,57.904289,-160.531754,0.000444,0.003862,0.098083,257.571136,13.121299,0.980825,-160.531754,0.099366,0.000000
74.210007,60.116554,-160.576233,0.000453,0.003889,0.098785,267.411774,13.622605,0.987850,-160.576233,0.099800,0.000000
74.470001,61.159569,-160.620712,0.000474,0.003902,0.099106,272.051361,13.858956,0.991060,-160.620712,0.100234,0.000000
74.730003,61.686478,-160.665192,0.000466,0.003912,0.099358,274.395172,13.978355,0.993580,-160.665192,0.100667,0.000000
74.990005,64.670662,-160.620712,0.000487,0.003944,0.100190,287.669464,14.654581,1.001900,-160.620712,0.101101,0.000000
75.250000,65.407219,-160.754150,0.000466,0.003956,0.100476,290.945831,14.821488,1.004761,-160.754150,0.101534,0.000000
75.510002,66.901176,-160.754150,0.000479,0.003976,0.100979,297.591309,15.160023,1.009795,-160.754150,0.101968,0.000000
75.770004,67.557304,-160.843124,0.000509,0.003981,0.101127,300.509888,15.308703,1.011271,-160.843124,0.102384,0.000000
76.030006,66.982735,-160.843124,0.000500,0.003976,0.100979,297.954071,15.178505,1.009795,-160.843124,0.101231,0.000000
76.290001,66.581688,-160.798645,0.000500,0.003975,0.100962,296.170135,15.087626,1.009621,-160.798645,0.100979,0.000000
76.550003,66.215645,-160.887604,0.000522,0.003975,0.100954,294.541901,15.004680,1.009537,-160.887604,0.100979,0.000000
76.810005,65.905083,-160.887604,0.000513,0.003974,0.100945,293.160461,14.934305,1.009447,-160.887604,0.100979,0.000000
77.070007,65.630638,-160.932083,0.000492,0.003974,0.100945,291.939667,14.872115,1.009447,-160.932083,0.100979,0.000000
77.330002,65.374077,-161.065521,0.000535,0.003974,0.100945,290.798431,14.813977,1.009447,-161.065521,0.100979,0.000000
77.590004,65.179695,-160.976562,0.000504,0.003974,0.100945,289.933777,14.769930,1.009447,-160.976562,0.100979,0.000000
77.850006,64.990532,-161.065521,0.000535,0.003974,0.100945,289.092316,14.727065,1.009447,-161.065521,0.100979,0.000000
78.110001,64.816261,-161.154480,0.000517,0.003974,0.100945,288.317139,14.687575,1.009447,-161.154480,0.100979,0.000000
78.370003,64.663597,-161.110001,0.000530,0.003974,0.100945,287.638031,14.652981,1.009447,-161.110001,0.100979,0.000000
78.630005,64.508308,-161.198959,0.000530,0.003974,0.100945,286.947296,14.617791,1.009447,-161.198959,0.100979,0.000000
78.890007,64.385429,-161.198959,0.000539,0.003974,0.100945,286.400696,14.589947,1.009447,-161.198959,0.100979,0.000000
79.150002,64.267387,-161.243454,0.000522,0.003974,0.100945,285.875610,14.563198,1.009447,-161.243454,0.100979,0.000000
79.410004,64.152321,-161.243454,0.000513,0.003974,0.100945,285.363770,14.537124,1.009447,-161.243454,0.100979,0.000000
79.670006,64.051048,-161.332413,0.000548,0.003974,0.100945,284.913300,14.514175,1.009447,-161.332413,0.100979,0.000000
79.930000,63.937096,-161.421371,0.000517,0.003974,0.100945,284.406403,14.488353,1.009447,-161.421371,0.100979,0.000000
80.190002,63.846611,-161.465851,0.000530,0.003974,0.100945,284.003906,14.467850,1.009447,-161.465851,0.100979,0.000000
80.450005,63.766182,-161.465851,0.000556,0.003974,0.100945,283.646149,14.449623,1.009447,-161.465851,0.100979,0.000000
80.710007,63.678291,-161.510330,0.000543,0.003974,0.100945,283.255188,14.429708,1.009447,-161.510330,0.100979,0.000000
80.970001,63.609779,-161.510330,0.000526,0.003974,0.100945,282.950439,14.414183,1.009447,-161.510330,0.100979,0.000000
81.230003,63.536797,-161.599289,0.000548,0.003974,0.100945,282.625793,14.397644,1.009447,-161.599289,0.100979,0.000000
81.490005,63.455238,-161.510330,0.000530,0.003974,0.100945,282.263000,14.379163,1.009447,-161.510330,0.100979,0.000000
81.750008,63.380028,-161.643784,0.000552,0.003974,0.100945,281.928436,14.362120,1.009447,-161.643784,0.100979,0.000000
82.010002,63.333855,-161.643784,0.000535,0.003974,0.100945,281.723053,14.351657,1.009447,-161.643784,0.100979,0.000000
82.270004,63.272781,-161.732742,0.000556,0.003974,0.100945,281.451385,14.337817,1.009447,-161.732742,0.100979,0.000000
82.530006,63.192726,-161.777222,0.000552,0.003974,0.100945,281.095276,14.319676,1.009447,-161.777222,0.100979,0.000000
82.790001,63.148041,-161.821701,0.000522,0.003974,0.100945,280.896515,14.309551,1.009447,-161.821701,0.100979,0.000000
83.050003,63.090317,-161.777222,0.000535,0.003974,0.100945,280.639740,14.296470,1.009447,-161.777222,0.100979,0.000000
83.310005,63.046379,-161.821701,0.000517,0.003974,0.100945,280.444305,14.286513,1.009447,-161.821701,0.100979,0.000000
83.570007,62.996109,-161.821701,0.000556,0.003974,0.100945,280.220703,14.275123,1.009447,-161.821701,0.100979,0.000000
83.830002,62.952911,-161.955139,0.000556,0.003974,0.100945,280.028534,14.265333,1.009447,-161.955139,0.100979,0.000000
84.090004,62.897057,-161.955139,0.000552,0.003974,0.100945,279.780090,14.252676,1.009447,-161.955139,0.100979,0.000000
84.350006,62.856468,-161.999619,0.000530,0.003974,0.100945,279.599548,14.243479,1.009447,-161.999619,0.100979,0.000000
84.610001,62.803963,-162.088593,0.000522,0.003974,0.100945,279.365967,14.231581,1.009447,-162.088593,0.100979,0.000000
84.870003,62.779762,-162.088593,0.000530,0.003974,0.100945,279.258331,14.226097,1.009447,-162.088593,0.100979,0.000000
85.130005,62.725769,-162.133072,0.000526,0.003974,0.100945,279.018158,14.213862,1.009447,-162.133072,0.100979,0.000000
85.390007,62.692253,-162.177551,0.000543,0.003974,0.100945,278.869080,14.206267,1.009447,-162.177551,0.100979,0.000000
85.650002,62.646080,-162.222031,0.000517,0.003974,0.100945,278.663696,14.195805,1.009447,-162.222031,0.100979,0.000000
85.910004,62.610329,-162.222031,0.000535,0.003974,0.100945,278.504639,14.187703,1.009447,-162.222031,0.100979,0.000000
86.170006,62.574959,-162.266510,0.000535,0.003974,0.100945,278.347321,14.179688,1.009447,-162.266510,0.100979,0.000000
86.430000,62.527664,-162.399948,0.000509,0.003974,0.100945,278.136932,14.168972,1.009447,-162.399948,0.100979,0.000000
86.690002,62.515747,-162.355469,0.000560,0.003974,0.100945,278.083923,14.166271,1.009447,-162.355469,0.100979,0.000000
86.950005,62.469200,-162.355469,0.000548,0.003974,0.100945,277.876892,14.155724,1.009447,-162.355469,0.100979,0.000000
87.210007,62.439415,-162.444427,0.000552,0.003974,0.100945,277.744385,14.148973,1.009447,-162.444427,0.100979,0.000000
87.470001,62.415955,-162.444427,0.000530,0.003974,0.100945,277.640045,14.143658,1.009447,-162.444427,0.100979,0.000000
87.730003,62.371269,-162.533401,0.000560,0.003974,0.100945,277.441254,14.133532,1.009447,-162.533401,0.100979,0.000000
87.990005,62.337013,-162.533401,0.000548,0.003974,0.100945,277.288879,14.125770,1.009447,-162.533401,0.100979,0.000000
88.250008,62.299774,-162.622360,0.000535,0.003974,0.100945,277.123230,14.117331,1.009447,-162.622360,0.100979,0.000000
88.510002,62.277802,-162.622360,0.000535,0.003974,0.100945,277.025482,14.112351,1.009447,-162.622360,0.100979,0.000000
88.770004,62.267006,-162.622360,0.000535,0.003974,0.100945,276.977478,14.109905,1.009447,-162.622360,0.100979,0.000000
89.030006,62.218597,-162.711319,0.000517,0.003974,0.100945,276.762146,14.098935,1.009447,-162.711319,0.100979,0.000000
89.290001,62.195511,-162.711319,0.000535,0.003974,0.100945,276.659454,14.093704,1.009447,-162.711319,0.100979,0.000000
89.550003,62.173538,-162.755798,0.000552,0.003974,0.100945,276.561707,14.088725,1.009447,-162.755798,0.100979,0.000000
89.810005,62.136299,-162.800278,0.000530,0.003974,0.100945,276.396057,14.080286,1.009447,-162.800278,0.100979,0.000000
90.070007,62.112846,-162.844757,0.000548,0.003974,0.100945,276.291748,14.074972,1.009447,-162.844757,0.100979,0.000000
90.330002,62.085663,-162.933731,0.000543,0.003974,0.100945,276.170807,14.068812,1.009447,-162.933731,0.100979,0.000000
90.590004,62.058846,-162.889236,0.000535,0.003974,0.100945,276.051544,14.062736,1.009447,-162.889236,0.100979,0.000000
90.850006,62.051025,-162.978210,0.000513,0.003974,0.100945,276.016754,14.060963,1.009447,-162.978210,0.100979,0.000000
91.110001,62.020866,-162.978210,0.000530,0.003974,0.100945,275.882599,14.054129,1.009447,-162.978210,0.100979,0.000000
91.370003,61.989212,-163.067169,0.000548,0.003974,0.100945,275.741791,14.046956,1.009447,-163.067169,0.100979,0.000000
91.630005,61.973206,-163.111649,0.000556,0.003974,0.100945,275.670593,14.043329,1.009447,-163.111649,0.100979,0.000000
91.890007,61.945648,-163.111649,0.000560,0.003974,0.100945,275.548004,14.037085,1.009447,-163.111649,0.100979,0.000000
92.150002,61.911018,-163.156128,0.000539,0.003974,0.100945,275.393951,14.029238,1.009447,-163.156128,0.100979,0.000000
92.410004,61.900963,-163.200607,0.000548,0.003974,0.100945,275.349243,14.026958,1.009447,-163.200607,0.100979,0.000000
92.670006,61.884209,-163.289566,0.000539,0.003974,0.100945,275.274719,14.023162,1.009447,-163.289566,0.100979,0.000000
92.930008,61.851067,-163.289566,0.000552,0.003974,0.100945,275.127289,14.015652,1.009447,-163.289566,0.100979,0.000000
93.190002,61.842125,-163.289566,0.000543,0.003974,0.100945,275.087524,14.013625,1.009447,-163.289566,0.100979,0.000000
93.450005,61.817551,-163.378540,0.000556,0.003974,0.100945,274.978210,14.008057,1.009447,-163.378540,0.100979,0.000000
93.710007,61.792229,-163.378540,0.000522,0.003974,0.100945,274.865570,14.002319,1.009447,-163.378540,0.100979,0.000000
93.970001,61.780685,-163.334045,0.000539,0.003974,0.100945,274.814209,13.999703,1.009447,-163.334045,0.100979,0.000000
94.230003,61.760208,-163.467499,0.000552,0.003974,0.100945,274.723114,13.995063,1.009447,-163.467499,0.100979,0.000000
94.490005,61.746803,-163.467499,0.000543,0.003974,0.100945,274.663513,13.992026,1.009447,-163.467499,0.100979,0.000000
94.750008,61.711800,-163.556458,0.000539,0.003974,0.100945,274.507782,13.984094,1.009447,-163.556458,0.100979,0.000000
95.010002,61.713287,-163.511978,0.000530,0.003974,0.100945,274.514404,13.984431,1.009447,-163.511978,0.100979,0.000000
95.270004,61.690575,-163.556458,0.000535,0.003974,0.100945,274.413391,13.979283,1.009447,-163.556458,0.100979,0.000000
95.530006,61.676048,-163.645416,0.000539,0.003974,0.100945,274.348755,13.975993,1.009447,-163.645416,0.100979,0.000000
95.790001,61.651474,-163.689896,0.000543,0.003974,0.100945,274.239441,13.970424,1.009447,-163.689896,0.100979,0.000000
96.050003,61.621681,-163.778854,0.000517,0.003974,0.100945,274.106934,13.963673,1.009447,-163.778854,0.100979,0.000000
96.310005,61.622803,-163.778854,0.000548,0.003974,0.100945,274.111908,13.963926,1.009447,-163.778854,0.100979,0.000000
96.570007,61.609398,-163.823349,0.000530,0.003974,0.100945,274.052277,13.960889,1.009447,-163.823349,0.100979,0.000000
96.830002,61.580353,-163.867828,0.000530,0.003974,0.100945,273.923096,13.954307,1.009447,-163.867828,0.100979,0.000000
97.090004,61.576630,-163.778854,0.000535,0.003974,0.100945,273.906525,13.953464,1.009447,-163.778854,0.100979,0.000000
97.350006,61.558380,-163.867828,0.000552,0.003974,0.100945,273.825348,13.949328,1.009447,-163.867828,0.100979,0.000000
97.610008,61.523003,-163.956787,0.000530,0.003974,0.100945,273.667969,13.941312,1.009447,-163.956787,0.100979,0.000000
97.870003,61.518166,-163.956787,0.000543,0.003974,0.100945,273.646454,13.940215,1.009447,-163.956787,0.100979,0.000000
98.130005,61.507362,-164.045746,0.000535,0.003974,0.100945,273.598419,13.937767,1.009447,-164.045746,0.100979,0.000000
98.390007,61.486885,-164.001266,0.000530,0.003974,0.100945,273.507324,13.933127,1.009447,-164.001266,0.100979,0.000000
98.650002,61.464539,-164.090225,0.000552,0.003974,0.100945,273.407928,13.928063,1.009447,-164.090225,0.100979,0.000000
98.910004,61.465286,-164.134705,0.000548,0.003974,0.100945,273.411255,13.928233,1.009447,-164.134705,0.100979,0.000000
99.170006,61.439224,-164.179184,0.000517,0.003974,0.100945,273.295319,13.922327,1.009447,-164.179184,0.100979,0.000000
99.430008,61.425072,-164.223679,0.000560,0.003974,0.100945,273.232361,13.919120,1.009447,-164.223679,0.100979,0.000000
99.690002,61.411293,-164.223679,0.000539,0.003974,0.100945,273.171082,13.915998,1.009447,-164.223679,0.100979,0.000000
99.950005,61.393417,-164.268158,0.000543,0.003974,0.100945,273.091553,13.911947,1.009447,-164.268158,0.100979,0.000000
100.210007,61.376663,-164.312637,0.000535,0.003974,0.100945,273.017029,13.908151,1.009447,-164.312637,0.100979,0.000000
100.470001,61.366608,-164.312637,0.000565,0.003974,0.100945,272.972290,13.905872,1.009447,-164.312637,0.100979,0.000000
100.730003,61.350594,-164.446075,0.000565,0.003974,0.100945,272.901062,13.902244,1.009447,-164.446075,0.100979,0.000000
100.990005,61.330490,-164.401596,0.000552,0.003974,0.100945,272.811646,13.897688,1.009447,-164.401596,0.100979,0.000000
101.250008,61.327881,-164.535034,0.000552,0.003974,0.100945,272.800049,13.897097,1.009447,-164.535034,0.100979,0.000000
101.510002,61.310379,-164.446075,0.000543,0.003974,0.100945,272.722198,13.893130,1.009447,-164.446075,0.100979,0.000000
101.770004,61.298088,-164.535034,0.000548,0.003974,0.100945,272.667511,13.890346,1.009447,-164.535034,0.100979,0.000000
102.030006,61.283569,-164.623993,0.000535,0.003974,0.100945,272.602936,13.887055,1.009447,-164.623993,0.100979,0.000000
102.290009,61.279472,-164.623993,0.000535,0.003974,0.100945,272.584717,13.886127,1.009447,-164.623993,0.100979,0.000000
102.550003,61.261597,-164.668488,0.000522,0.003974,0.100945,272.505188,13.882076,1.009447,-164.668488,0.100979,0.000000
102.810005,61.235909,-164.668488,0.000530,0.003974,0.100945,272.390930,13.876255,1.009447,-164.668488,0.100979,0.000000
103.070007,61.240005,-164.757446,0.000548,0.003974,0.100945,272.409149,13.877183,1.009447,-164.757446,0.100979,0.000000
103.330002,61.231064,-164.757446,0.000535,0.003974,0.100945,272.369385,13.875157,1.009447,-164.757446,0.100979,0.000000
103.590004,61.208725,-164.801926,0.000548,0.003974,0.100945,272.270020,13.870095,1.009447,-164.801926,0.100979,0.000000
103.850006,61.186005,-164.801926,0.000526,0.003974,0.100945,272.168945,13.864946,1.009447,-164.801926,0.100979,0.000000
104.110008,61.191963,-164.935364,0.000530,0.003974,0.100945,272.195435,13.866298,1.009447,-164.935364,0.100979,0.000000
104.370003,61.164413,-164.846405,0.000526,0.003974,0.100945,272.072906,13.860054,1.009447,-164.846405,0.100979,0.000000
104.630005,61.151749,-164.890884,0.000526,0.003974,0.100945,272.016571,13.857184,1.009447,-164.890884,0.100979,0.000000
104.890007,61.165901,-164.890884,0.000548,0.003974,0.100945,272.079529,13.860391,1.009447,-164.890884,0.100979,0.000000
105.150002,61.131638,-164.979843,0.000530,0.003974,0.100945,271.927094,13.852627,1.009447,-164.979843,0.100979,0.000000
105.410004,61.124939,-164.979843,0.000552,0.003974,0.100945,271.897308,13.851110,1.009447,-164.979843,0.100979,0.000000
105.670006,61.129776,-165.068802,0.000539,0.003974,0.100945,271.918823,13.852205,1.009447,-165.068802,0.100979,0.000000
105.930008,61.101105,-165.157776,0.000539,0.003974,0.100945,271.791290,13.845709,1.009447,-165.157776,0.100979,0.000000
106.190002,61.099991,-165.113297,0.000539,0.003974,0.100945,271.786346,13.845456,1.009447,-165.113297,0.100979,0.000000
106.200005,61.096642,-165.202255,0.000539,0.003974,0.100945,271.771423,13.844697,1.009447,-165.202255,0.100979,0.000000