File: Data/compression 13/AutoNoHeating-10-13-2-240724_07242024_162540.csv
Time (sec),S:Load (lbs),S:HL1 (DIM),S:LVDT (in),S:Position (in),Ch:Position (mm),Ch:Load (N),Ch:Stress (MPa),Ch:Strain (mm/mm),Ch:HL1 (DIM),Set Point (),Cycles ()
0.110000,0.012291,-174.632217,-0.007351,-0.003464,-0.087981,0.054673,0.002785,-0.879806,-174.632217,-0.088119,0.000000
0.360000,0.016014,-174.632217,-0.007377,-0.003464,-0.087981,0.071234,0.003629,-0.879806,-174.632217,-0.088119,0.000000
0.610000,0.000740,-174.632217,-0.007368,-0.003368,-0.085535,0.003292,0.000168,-0.855348,-174.632217,-0.084650,0.000000
0.860000,0.027924,-174.721176,-0.007368,-0.003214,-0.081624,0.124210,0.006328,-0.816235,-174.721176,-0.080487,0.000000
1.110000,0.043198,-174.765656,-0.007317,-0.003059,-0.077704,0.192153,0.009789,-0.777039,-174.765656,-0.076325,0.000000
1.360000,0.052879,-174.765656,-0.007157,-0.002896,-0.073559,0.235219,0.011983,-0.735587,-174.765656,-0.072162,0.000000
1.610000,0.073730,-174.810135,-0.006950,-0.002722,-0.069144,0.327969,0.016708,-0.691440,-174.810135,-0.067982,0.000000
1.860000,0.099052,-174.899094,-0.006812,-0.002569,-0.065242,0.440607,0.022446,-0.652417,-174.899094,-0.063819,0.000000
2.110000,0.093834,-174.899094,-0.006631,-0.002396,-0.060863,0.417394,0.021263,-0.608626,-174.899094,-0.059657,0.000000
2.360000,0.065163,-174.988068,-0.006446,-0.002231,-0.056665,0.289858,0.014766,-0.566652,-174.988068,-0.055494,0.000000
2.610000,0.073730,-174.988068,-0.006299,-0.002075,-0.052693,0.327969,0.016708,-0.526933,-174.988068,-0.051332,0.000000
2.860000,0.053246,-174.988068,-0.006109,-0.001897,-0.048175,0.236848,0.012066,-0.481749,-174.988068,-0.047169,0.000000
3.110000,0.005585,-175.032547,-0.005941,-0.001742,-0.044255,0.024842,0.001266,-0.442545,-175.032547,-0.043006,0.000000
3.360000,0.060326,-175.121506,-0.005795,-0.001584,-0.040231,0.268342,0.013670,-0.402312,-175.121506,-0.038826,0.000000
3.610000,0.078941,-175.121506,-0.005609,-0.001415,-0.035938,0.351149,0.017888,-0.359383,-175.121506,-0.034664,0.000000
3.860000,0.072609,-175.121506,-0.005420,-0.001243,-0.031576,0.322981,0.016453,-0.315759,-175.121506,-0.030501,0.000000
4.110000,0.087509,-175.165985,-0.005260,-0.001084,-0.027535,0.389260,0.019830,-0.275351,-175.165985,-0.026338,0.000000
4.360000,0.115059,-175.254944,-0.005113,-0.000921,-0.023389,0.511808,0.026073,-0.233891,-175.254944,-0.022175,0.000000
4.610000,0.102028,-175.254944,-0.004937,-0.000754,-0.019140,0.453843,0.023120,-0.191402,-175.254944,-0.018012,0.000000
4.860000,0.196609,-175.210464,-0.004760,-0.000594,-0.015081,0.874563,0.044552,-0.150813,-175.210464,-0.013850,0.000000
5.110000,0.678459,-175.299423,-0.004631,-0.000004,-0.000104,3.017937,0.153741,-0.001037,-175.299423,0.000078,0.000000
5.360000,0.640106,-175.343903,-0.004644,-0.000004,-0.000113,2.847335,0.145050,-0.001128,-175.343903,0.000078,0.000000
5.610000,0.564888,-175.388397,-0.004639,-0.000005,-0.000121,2.512747,0.128005,-0.001211,-175.388397,0.000182,0.000000
5.860000,0.620369,-175.432877,-0.004626,-0.000005,-0.000121,2.759539,0.140578,-0.001211,-175.432877,0.000599,0.000000
6.110000,0.607712,-175.432877,-0.004635,-0.000004,-0.000113,2.703237,0.137709,-0.001128,-175.432877,0.001015,0.000000
6.360000,0.581276,-175.477356,-0.004648,-0.000004,-0.000113,2.585644,0.131719,-0.001128,-175.477356,0.001431,0.000000
6.610000,0.832253,-175.521835,-0.004609,0.000031,0.000790,3.702044,0.188591,0.007895,-175.521835,0.001847,0.000000
6.860000,1.030350,-175.477356,-0.004600,0.000052,0.001327,4.583224,0.233481,0.013270,-175.477356,0.002263,0.000000
7.110000,1.154724,-175.610794,-0.004587,0.000067,0.001700,5.136469,0.261664,0.017002,-175.610794,0.002680,0.000000
7.360000,1.256386,-175.655273,-0.004553,0.000078,0.001986,5.588683,0.284701,0.019863,-175.655273,0.003096,0.000000
7.610000,1.543114,-175.655273,-0.004536,0.000109,0.002767,6.864112,0.349675,0.027668,-175.655273,0.003512,0.000000
7.860001,1.558746,-175.655273,-0.004549,0.000118,0.003001,6.933650,0.353217,0.030007,-175.655273,0.003929,0.000000
8.110001,1.731903,-175.699753,-0.004527,0.000133,0.003382,7.703890,0.392455,0.033822,-175.699753,0.004345,0.000000
8.360001,1.801163,-175.699753,-0.004518,0.000146,0.003721,8.011971,0.408149,0.037206,-175.699753,0.004761,0.000000
8.610001,1.960541,-175.788712,-0.004510,0.000161,0.004094,8.720921,0.444265,0.040937,-175.788712,0.005178,0.000000
8.860001,2.175774,-175.833206,-0.004467,0.000180,0.004571,9.678325,0.493037,0.045706,-175.833206,0.005602,0.000000
9.110001,2.331047,-175.877686,-0.004449,0.000194,0.004926,10.369015,0.528223,0.049257,-175.877686,0.006019,0.000000
9.360001,2.513138,-175.922165,-0.004449,0.000209,0.005299,11.178995,0.569485,0.052989,-175.922165,0.006435,0.000000
9.610001,2.781990,-175.922165,-0.004437,0.000233,0.005906,12.374909,0.630408,0.059060,-175.922165,0.006851,0.000000
9.860001,2.928337,-175.966644,-0.004393,0.000251,0.006383,13.025894,0.663571,0.063828,-175.966644,0.007268,0.000000
10.110001,2.912323,-175.966644,-0.004381,0.000258,0.006548,12.954659,0.659942,0.065479,-175.966644,0.007684,0.000000
10.360001,3.130165,-176.011124,-0.004389,0.000276,0.007007,13.923670,0.709306,0.070074,-176.011124,0.008100,0.000000
10.610001,3.191978,-176.100082,-0.004393,0.000285,0.007250,14.198629,0.723313,0.072503,-176.100082,0.008516,0.000000
10.860001,3.570679,-176.055603,-0.004368,0.000308,0.007823,15.883172,0.809127,0.078226,-176.055603,0.008932,0.000000
11.110001,3.761703,-176.055603,-0.004337,0.000326,0.008282,16.732893,0.852414,0.082821,-176.055603,0.009349,0.000000
11.360001,4.002258,-176.100082,-0.004312,0.000346,0.008776,17.802935,0.906925,0.087764,-176.100082,0.009765,0.000000
11.610001,4.129608,-176.233521,-0.004312,0.000364,0.009245,18.369415,0.935783,0.092450,-176.233521,0.010181,0.000000
11.860001,4.334045,-176.233521,-0.004286,0.000380,0.009661,19.278797,0.982109,0.096613,-176.233521,0.010598,0.000000
12.110001,4.354897,-176.233521,-0.004255,0.000390,0.009904,19.371548,0.986834,0.099036,-176.233521,0.011014,0.000000
12.360001,4.640503,-176.322495,-0.004277,0.000409,0.010381,20.641989,1.051553,0.103812,-176.322495,0.011430,0.000000
12.610001,4.791313,-176.322495,-0.004247,0.000423,0.010745,21.312826,1.085727,0.107453,-176.322495,0.011847,0.000000
12.860001,5.094055,-176.278015,-0.004238,0.000445,0.011291,22.659489,1.154329,0.112911,-176.278015,0.012263,0.000000
13.110001,5.140976,-176.411453,-0.004221,0.000458,0.011621,22.868202,1.164962,0.116211,-176.411453,0.012679,0.000000
13.360001,5.396790,-176.411453,-0.004195,0.000477,0.012124,24.006119,1.222930,0.121238,-176.411453,0.013095,0.000000
13.610001,5.590057,-176.455933,-0.004178,0.000494,0.012540,24.865818,1.266725,0.125401,-176.455933,0.013511,0.000000
13.860001,5.834702,-176.455933,-0.004161,0.000515,0.013069,25.954048,1.322162,0.130692,-176.455933,0.013937,0.000000
14.110001,5.795235,-176.500412,-0.004139,0.000525,0.013330,25.778492,1.313219,0.133296,-176.500412,0.014353,0.000000
14.360001,6.033920,-176.544891,-0.004113,0.000542,0.013772,26.840218,1.367306,0.137717,-176.544891,0.014769,0.000000
14.610001,6.190315,-176.589371,-0.004113,0.000558,0.014171,27.535898,1.402745,0.141706,-176.589371,0.015185,0.000000
14.860001,6.296074,-176.633850,-0.004105,0.000569,0.014448,28.006336,1.426711,0.144485,-176.633850,0.015601,0.000000
15.110001,6.657272,-176.633850,-0.004109,0.000589,0.014951,29.613026,1.508559,0.149511,-176.633850,0.016018,0.000000
15.360001,7.103378,-176.678345,-0.004057,0.000614,0.015593,31.597404,1.609649,0.155930,-176.678345,0.016434,0.000000
15.610001,7.117157,-176.767303,-0.004040,0.000632,0.016061,31.658695,1.612771,0.160608,-176.767303,0.016850,0.000000
15.860001,6.985703,-176.767303,-0.004031,0.000643,0.016339,31.073957,1.582983,0.163386,-176.767303,0.017267,0.000000
16.110001,7.193489,-176.811783,-0.004031,0.000659,0.016729,31.998238,1.630068,0.167292,-176.811783,0.017683,0.000000
16.360001,7.452660,-176.856262,-0.004001,0.000676,0.017162,33.151085,1.688797,0.171622,-176.856262,0.018099,0.000000
16.610001,7.624329,-176.900742,-0.003997,0.000690,0.017527,33.914707,1.727697,0.175271,-176.900742,0.018516,0.000000
16.860001,7.684647,-176.945221,-0.003954,0.000704,0.017882,34.183014,1.741366,0.178821,-176.945221,0.018932,0.000000
17.110001,7.638847,-176.989700,-0.003949,0.000713,0.018099,33.979290,1.730988,0.180994,-176.989700,0.019348,0.000000
17.360001,8.383965,-176.900742,-0.003915,0.000742,0.018853,37.293736,1.899834,0.188533,-176.900742,0.019764,0.000000
17.610001,8.430885,-177.034180,-0.003902,0.000761,0.019322,37.502449,1.910466,0.193219,-177.034180,0.020180,0.000000
17.860001,8.236130,-177.034180,-0.003885,0.000770,0.019547,36.636135,1.866334,0.195475,-177.034180,0.020597,0.000000
18.110001,8.487114,-177.078659,-0.003893,0.000790,0.020077,37.752567,1.923208,0.200766,-177.078659,0.021013,0.000000
18.360001,8.822617,-177.078659,-0.003850,0.000808,0.020519,39.244957,1.999233,0.205187,-177.078659,0.021429,0.000000
18.610001,8.834908,-177.167633,-0.003842,0.000822,0.020874,39.299633,2.002019,0.208745,-177.167633,0.021846,0.000000
18.860001,8.761177,-177.123154,-0.003820,0.000832,0.021134,38.971661,1.985311,0.211341,-177.123154,0.022262,0.000000
19.110001,8.853523,-177.167633,-0.003820,0.000845,0.021472,39.382439,2.006237,0.214725,-177.167633,0.022687,0.000000
19.360001,9.564758,-177.256592,-0.003786,0.000870,0.022097,42.546169,2.167405,0.220970,-177.256592,0.023103,0.000000
19.610001,9.471291,-177.256592,-0.003760,0.000884,0.022444,42.130405,2.146225,0.224437,-177.256592,0.023519,0.000000
19.860001,9.525284,-177.345551,-0.003734,0.000900,0.022869,42.370579,2.158460,0.228691,-177.345551,0.023936,0.000000
20.110001,9.852974,-177.345551,-0.003747,0.000921,0.023389,43.828217,2.232716,0.233891,-177.345551,0.024352,0.000000
20.360001,9.976227,-177.390030,-0.003712,0.000938,0.023831,44.376472,2.260645,0.238312,-177.390030,0.024768,0.000000
20.610001,10.125175,-177.390030,-0.003669,0.000955,0.024265,45.039028,2.294397,0.242650,-177.390030,0.025185,0.000000
20.860001,9.943832,-177.434509,-0.003678,0.000964,0.024491,44.232376,2.253305,0.244905,-177.434509,0.025601,0.000000
21.110001,10.166512,-177.478989,-0.003665,0.000982,0.024942,45.222900,2.303765,0.249417,-177.478989,0.026017,0.000000
21.360001,10.804016,-177.523483,-0.003609,0.001008,0.025601,48.058662,2.448225,0.256010,-177.523483,0.026433,0.000000
21.610001,10.437973,-177.567963,-0.003604,0.001016,0.025808,46.430424,2.365278,0.258084,-177.567963,0.026849,0.000000
21.860001,10.762680,-177.612442,-0.003583,0.001035,0.026294,47.874790,2.438858,0.262944,-177.612442,0.027266,0.000000
22.110001,10.993553,-177.567963,-0.003579,0.001055,0.026789,48.901768,2.491175,0.267887,-177.567963,0.027682,0.000000
22.360001,11.064301,-177.612442,-0.003561,0.001069,0.027162,49.216465,2.507206,0.271619,-177.612442,0.028098,0.000000
22.610001,10.789490,-177.745880,-0.003561,0.001076,0.027335,47.994049,2.444933,0.273353,-177.745880,0.028515,0.000000
22.860001,11.088135,-177.745880,-0.003540,0.001093,0.027752,49.322487,2.512607,0.277516,-177.745880,0.028931,0.000000
23.110001,11.665314,-177.834839,-0.003492,0.001119,0.028419,51.889908,2.643398,0.284193,-177.834839,0.029347,0.000000
23.360001,11.628448,-177.790359,-0.003484,0.001134,0.028792,51.725922,2.635044,0.287917,-177.790359,0.029764,0.000000
23.610001,11.596046,-177.834839,-0.003488,0.001150,0.029200,51.581791,2.627702,0.291997,-177.834839,0.030179,0.000000
23.860001,11.707764,-177.879318,-0.003445,0.001165,0.029581,52.078735,2.653017,0.295812,-177.879318,0.030596,0.000000
24.110001,11.836975,-177.879318,-0.003428,0.001182,0.030015,52.653496,2.682297,0.300150,-177.879318,0.031021,0.000000
24.360001,11.987785,-177.879318,-0.003428,0.001196,0.030371,53.324333,2.716471,0.303708,-177.879318,0.031437,0.000000
24.610001,12.007523,-178.012772,-0.003389,0.001209,0.030717,53.412128,2.720943,0.307175,-178.012772,0.031854,0.000000
24.860001,12.102852,-178.012772,-0.003367,0.001225,0.031116,53.836174,2.742545,0.311164,-178.012772,0.032269,0.000000
25.110001,12.592148,-178.012772,-0.003359,0.001250,0.031758,56.012672,2.853421,0.317583,-178.012772,0.032686,0.000000
25.360001,12.687477,-178.057251,-0.003311,0.001268,0.032200,56.436718,2.875023,0.322004,-178.057251,0.033102,0.000000
25.610001,12.543365,-178.057251,-0.003311,0.001281,0.032539,55.795677,2.842367,0.325387,-178.057251,0.033518,0.000000
25.860001,12.575020,-178.146210,-0.003290,0.001296,0.032920,55.936481,2.849540,0.329203,-178.146210,0.033935,0.000000
26.110001,12.798813,-178.101730,-0.003251,0.001312,0.033337,56.931965,2.900253,0.333366,-178.101730,0.034351,0.000000
26.360001,13.100807,-178.146210,-0.003251,0.001333,0.033848,58.275299,2.968685,0.338483,-178.146210,0.034767,0.000000
26.610001,13.139534,-178.235168,-0.003229,0.001348,0.034247,58.447567,2.977461,0.342472,-178.235168,0.035184,0.000000
26.860001,13.439667,-178.235168,-0.003195,0.001370,0.034802,59.782623,3.045472,0.348021,-178.235168,0.035600,0.000000
27.110001,13.300400,-178.279648,-0.003182,0.001383,0.035123,59.163132,3.013914,0.351231,-178.279648,0.036016,0.000000
27.360001,13.253853,-178.324127,-0.003152,0.001397,0.035478,58.956081,3.003366,0.354781,-178.324127,0.036433,0.000000
27.610001,13.277313,-178.368607,-0.003160,0.001411,0.035843,59.060440,3.008682,0.358430,-178.368607,0.036848,0.000000
27.860001,13.327209,-178.368607,-0.003126,0.001423,0.036155,59.282387,3.019989,0.361548,-178.368607,0.037265,0.000000
28.110001,13.799751,-178.413101,-0.003091,0.001445,0.036692,61.384361,3.127068,0.366923,-178.413101,0.037681,0.000000
28.360001,13.895447,-178.457581,-0.003065,0.001461,0.037109,61.810036,3.148753,0.371086,-178.457581,0.038097,0.000000
28.610001,13.660484,-178.502060,-0.003074,0.001471,0.037352,60.764870,3.095510,0.373516,-178.502060,0.038514,0.000000
28.860001,13.852631,-178.457581,-0.003048,0.001491,0.037872,61.619579,3.139051,0.378717,-178.457581,0.038930,0.000000
29.110001,14.359428,-178.591019,-0.003018,0.001516,0.038496,63.873928,3.253893,0.384962,-178.591019,0.039355,0.000000
29.360001,13.866035,-178.591019,-0.002984,0.001525,0.038747,61.679207,3.142088,0.387475,-178.591019,0.039771,0.000000
29.610001,14.084984,-178.635498,-0.002958,0.001543,0.039190,62.653137,3.191703,0.391903,-178.635498,0.040187,0.000000
29.860001,14.031738,-178.679977,-0.002962,0.001555,0.039494,62.416290,3.179637,0.394939,-178.679977,0.040604,0.000000
30.110001,14.456612,-178.635498,-0.002915,0.001575,0.040014,64.306221,3.275915,0.400139,-178.635498,0.041020,0.000000
30.360001,14.373207,-178.724457,-0.002910,0.001589,0.040352,63.935219,3.257015,0.403523,-178.724457,0.041436,0.000000
30.610001,14.483795,-178.724457,-0.002867,0.001604,0.040751,64.427139,3.282075,0.407512,-178.724457,0.041853,0.000000
30.860001,14.229095,-178.813431,-0.002846,0.001614,0.040985,63.294178,3.224359,0.409851,-178.813431,0.042269,0.000000
31.110001,15.227798,-178.857910,-0.002824,0.001647,0.041835,67.736633,3.450669,0.418352,-178.857910,0.042685,0.000000
31.360001,14.560135,-178.857910,-0.002807,0.001655,0.042034,64.766716,3.299374,0.420343,-178.857910,0.043102,0.000000
31.610001,14.708336,-178.813431,-0.002794,0.001674,0.042511,65.425949,3.332957,0.425112,-178.813431,0.043517,0.000000
31.860001,14.461830,-178.902390,-0.002777,0.001684,0.042772,64.329430,3.277098,0.427716,-178.902390,0.043934,0.000000
32.110001,14.824150,-178.991348,-0.002751,0.001703,0.043248,65.941116,3.359200,0.432485,-178.991348,0.044350,0.000000
32.360001,15.056877,-178.991348,-0.002712,0.001721,0.043717,66.976334,3.411937,0.437171,-178.991348,0.044766,0.000000
32.610001,15.139915,-179.035828,-0.002686,0.001738,0.044142,67.345711,3.430754,0.441417,-179.035828,0.045183,0.000000
32.860001,15.201729,-179.080307,-0.002665,0.001755,0.044585,67.620667,3.444761,0.445845,-179.080307,0.045599,0.000000
33.110001,15.389778,-179.080307,-0.002639,0.001776,0.045113,68.457153,3.487374,0.451129,-179.080307,0.046015,0.000000
33.360001,15.062096,-179.124786,-0.002621,0.001787,0.045399,66.999550,3.413120,0.453991,-179.124786,0.046432,0.000000
33.610001,15.108269,-179.169266,-0.002600,0.001803,0.045798,67.204933,3.423583,0.457980,-179.169266,0.046848,0.000000
33.860001,15.081085,-179.169266,-0.002600,0.001816,0.046128,67.084015,3.417423,0.461280,-179.169266,0.047264,0.000000
34.110001,15.634804,-179.213745,-0.002561,0.001840,0.046726,69.547081,3.542897,0.467260,-179.213745,0.047681,0.000000
34.360001,15.402443,-179.258240,-0.002535,0.001853,0.047073,68.513489,3.490244,0.470735,-179.258240,0.048105,0.000000
34.610001,15.422180,-179.213745,-0.002505,0.001869,0.047472,68.601280,3.494716,0.474724,-179.213745,0.048522,0.000000
34.860001,15.720078,-179.347198,-0.002471,0.001889,0.047992,69.926399,3.562220,0.479925,-179.347198,0.048938,0.000000
35.110001,15.785614,-179.258240,-0.002466,0.001909,0.048487,70.217918,3.577071,0.484868,-179.258240,0.049354,0.000000
35.360001,15.385315,-179.391678,-0.002440,0.001919,0.048747,68.437302,3.486362,0.487472,-179.391678,0.049771,0.000000
35.610001,15.428879,-179.436157,-0.002414,0.001935,0.049137,68.631081,3.496234,0.491370,-179.436157,0.050186,0.000000
35.860001,15.499634,-179.436157,-0.002380,0.001950,0.049519,68.945816,3.512267,0.495185,-179.436157,0.050603,0.000000
36.110001,15.647461,-179.480637,-0.002371,0.001966,0.049935,69.603386,3.545765,0.499349,-179.480637,0.051019,0.000000
36.360001,15.800133,-179.436157,-0.002328,0.001984,0.050386,70.282501,3.580361,0.503860,-179.436157,0.051435,0.000000
36.610001,15.838860,-179.525116,-0.002311,0.002001,0.050837,70.454765,3.589137,0.508372,-179.525116,0.051852,0.000000
36.860001,16.433914,-179.569595,-0.002281,0.002027,0.051496,73.101700,3.723978,0.514958,-179.569595,0.052268,0.000000
37.110001,15.791946,-179.614075,-0.002251,0.002038,0.051774,70.246086,3.578506,0.517736,-179.614075,0.052684,0.000000
37.360001,15.788216,-179.614075,-0.002238,0.002055,0.052198,70.229492,3.577661,0.521982,-179.614075,0.053101,0.000000
37.610001,15.712257,-179.658554,-0.002199,0.002068,0.052519,69.891609,3.560448,0.525192,-179.658554,0.053517,0.000000
37.860001,16.079788,-179.703049,-0.002195,0.002088,0.053031,71.526474,3.643732,0.530309,-179.703049,0.053933,0.000000
38.110001,15.897324,-179.703049,-0.002190,0.002098,0.053282,70.714828,3.602385,0.532822,-179.703049,0.054349,0.000000
38.360001,15.672783,-179.792007,-0.002134,0.002108,0.053534,69.716019,3.551503,0.535343,-179.792007,0.054765,0.000000
38.610001,16.455139,-179.792007,-0.002091,0.002134,0.054193,73.196114,3.728788,0.541929,-179.792007,0.055181,0.000000
38.860001,16.735909,-179.836487,-0.002087,0.002155,0.054748,74.445038,3.792411,0.547477,-179.836487,0.055598,0.000000
39.110001,16.201180,-179.925446,-0.002074,0.002166,0.055026,72.066444,3.671240,0.550256,-179.925446,0.056014,0.000000
39.360001,16.198204,-179.925446,-0.002070,0.002183,0.055442,72.053207,3.670566,0.554419,-179.925446,0.056439,0.000000
39.610001,16.451416,-179.880966,-0.002035,0.002202,0.055919,73.179550,3.727944,0.559188,-179.880966,0.056855,0.000000
39.860001,16.519188,-179.880966,-0.001988,0.002218,0.056327,73.481018,3.743302,0.563268,-179.880966,0.057272,0.000000
40.110001,16.337837,-180.014404,-0.001975,0.002230,0.056630,72.674332,3.702207,0.566304,-180.014404,0.057688,0.000000
40.360001,15.968079,-180.014404,-0.001957,0.002235,0.056769,71.029564,3.618418,0.567689,-180.014404,0.058104,0.000000
40.610001,17.105675,-180.058884,-0.001966,0.002266,0.057549,76.089844,3.876201,0.575493,-180.058884,0.058521,0.000000
40.860001,16.932892,-180.192337,-0.001906,0.002278,0.057853,75.321266,3.837048,0.578529,-180.192337,0.058937,0.000000
41.110001,16.907196,-180.103378,-0.001914,0.002294,0.058278,75.206963,3.831225,0.582775,-180.103378,0.059353,0.000000
41.360001,17.134346,-180.147858,-0.001888,0.002314,0.058781,76.217377,3.882698,0.587809,-180.147858,0.059770,0.000000
41.610001,17.170837,-180.236816,-0.001845,0.002329,0.059162,76.379700,3.890967,0.591624,-180.236816,0.060186,0.000000
41.860001,17.198769,-180.236816,-0.001841,0.002348,0.059648,76.503944,3.897297,0.596477,-180.236816,0.060602,0.000000
42.110001,17.004013,-180.236816,-0.001802,0.002359,0.059925,75.637627,3.853164,0.599255,-180.236816,0.061018,0.000000
42.360001,17.128014,-180.281296,-0.001789,0.002375,0.060324,76.189209,3.881263,0.603244,-180.281296,0.061434,0.000000
42.610001,17.688805,-180.325775,-0.001772,0.002400,0.060966,78.683731,4.008340,0.609663,-180.325775,0.061850,0.000000
42.860001,17.410271,-180.370255,-0.001720,0.002412,0.061252,77.444756,3.945224,0.612525,-180.370255,0.062267,0.000000
43.110001,17.585289,-180.281296,-0.001746,0.002432,0.061764,78.223274,3.984883,0.617642,-180.281296,0.062683,0.000000
43.360001,17.442299,-180.370255,-0.001703,0.002445,0.062093,77.587219,3.952481,0.620935,-180.370255,0.063099,0.000000
43.610001,17.543953,-180.459213,-0.001690,0.002460,0.062492,78.039398,3.975517,0.624924,-180.459213,0.063516,0.000000
43.860001,17.523476,-180.503693,-0.001664,0.002473,0.062813,77.948311,3.970876,0.628134,-180.503693,0.063932,0.000000
44.110001,17.686577,-180.503693,-0.001638,0.002488,0.063187,78.673820,4.007835,0.631866,-180.503693,0.064349,0.000000
44.360001,18.404510,-180.592667,-0.001613,0.002512,0.063810,81.867348,4.170522,0.638103,-180.592667,0.064773,0.000000
44.610001,18.420891,-180.592667,-0.001587,0.002529,0.064236,81.940216,4.174234,0.642357,-180.592667,0.065190,0.000000
44.860001,18.415306,-180.637146,-0.001556,0.002545,0.064643,81.915375,4.172968,0.646430,-180.637146,0.065606,0.000000
45.110001,18.287956,-180.637146,-0.001535,0.002561,0.065051,81.348892,4.144110,0.650510,-180.637146,0.066022,0.000000
45.360001,18.191513,-180.592667,-0.001526,0.002575,0.065398,80.919891,4.122256,0.653977,-180.592667,0.066439,0.000000
45.610001,18.646919,-180.726105,-0.001496,0.002593,0.065875,82.945641,4.225452,0.658746,-180.726105,0.066855,0.000000
45.860001,18.566490,-180.770584,-0.001470,0.002606,0.066204,82.587875,4.207227,0.662039,-180.770584,0.067271,0.000000
46.110001,18.586967,-180.770584,-0.001457,0.002621,0.066569,82.678963,4.211867,0.665687,-180.770584,0.067687,0.000000
46.360001,18.996208,-180.859543,-0.001423,0.002641,0.067089,84.499352,4.304602,0.670888,-180.859543,0.068103,0.000000
46.610001,19.398369,-180.904022,-0.001410,0.002665,0.067678,86.288254,4.395733,0.676785,-180.904022,0.068519,0.000000
46.860001,19.054298,-180.904022,-0.001375,0.002679,0.068034,84.757751,4.317766,0.680342,-180.904022,0.068936,0.000000
47.110001,18.986900,-180.904022,-0.001380,0.002692,0.068389,84.457954,4.302493,0.683893,-180.904022,0.069352,0.000000
47.360001,19.152603,-180.948502,-0.001362,0.002710,0.068832,85.195030,4.340042,0.688321,-180.948502,0.069768,0.000000
47.610001,19.436722,-180.992996,-0.001319,0.002728,0.069292,86.458855,4.404424,0.692916,-180.992996,0.070185,0.000000
47.860001,19.240486,-180.992996,-0.001302,0.002741,0.069630,85.585960,4.359957,0.696300,-180.992996,0.070601,0.000000
48.110001,19.881340,-180.992996,-0.001289,0.002764,0.070211,88.436615,4.505176,0.702106,-180.992996,0.071017,0.000000
48.360001,19.854156,-181.081955,-0.001276,0.002780,0.070601,88.315697,4.499016,0.706012,-181.081955,0.071434,0.000000
48.610001,19.574501,-181.170914,-0.001233,0.002791,0.070887,87.071732,4.435645,0.708873,-181.170914,0.071850,0.000000
48.860001,19.552902,-181.170914,-0.001216,0.002806,0.071269,86.975655,4.430751,0.712688,-181.170914,0.072266,0.000000
49.110001,19.650093,-181.215393,-0.001186,0.002820,0.071633,87.407982,4.452775,0.716329,-181.215393,0.072682,0.000000
49.360001,20.328926,-181.170914,-0.001199,0.002840,0.072136,90.427582,4.606600,0.721363,-181.170914,0.073098,0.000000
49.610001,20.344566,-181.259872,-0.001134,0.002855,0.072509,90.497154,4.610145,0.725087,-181.259872,0.073524,0.000000
49.860001,20.095825,-181.304352,-0.001130,0.002866,0.072795,89.390694,4.553779,0.727949,-181.304352,0.073940,0.000000
50.110001,20.244026,-181.304352,-0.001108,0.002884,0.073246,90.049927,4.587362,0.732460,-181.304352,0.074356,0.000000
50.360001,21.358910,-181.348831,-0.001087,0.002913,0.073992,95.009178,4.839998,0.739917,-181.348831,0.074772,0.000000
50.610001,20.468567,-181.393326,-0.001035,0.002920,0.074157,91.048737,4.638244,0.741567,-181.393326,0.075188,0.000000
50.860001,20.644699,-181.393326,-0.001048,0.002938,0.074625,91.832207,4.678155,0.746253,-181.393326,0.075605,0.000000
51.110001,20.658104,-181.393326,-0.001043,0.002952,0.074972,91.891838,4.681193,0.749720,-181.393326,0.076021,0.000000
51.360001,20.884880,-181.437805,-0.000987,0.002969,0.075423,92.900589,4.732582,0.754231,-181.437805,0.076437,0.000000
51.610001,20.818230,-181.526764,-0.000987,0.002979,0.075665,92.604111,4.717478,0.756653,-181.526764,0.076854,0.000000
51.860001,21.174583,-181.526764,-0.000944,0.002997,0.076134,94.189255,4.798229,0.761339,-181.526764,0.077270,0.000000
52.110001,21.153732,-181.571243,-0.000961,0.003011,0.076472,94.096504,4.793504,0.764723,-181.571243,0.077686,0.000000
52.360001,22.360596,-181.571243,-0.000888,0.003041,0.077253,99.464897,5.066983,0.772527,-181.571243,0.078103,0.000000
52.610001,21.736122,-181.615723,-0.000880,0.003052,0.077513,96.687103,4.925476,0.775131,-181.615723,0.078518,0.000000
52.860001,21.753998,-181.660202,-0.000854,0.003068,0.077938,96.766617,4.929526,0.779378,-181.660202,0.078935,0.000000
53.110004,21.498177,-181.615723,-0.000845,0.003080,0.078224,95.628662,4.871557,0.782239,-181.615723,0.079351,0.000000
53.360004,21.648247,-181.749161,-0.000802,0.003096,0.078640,96.296211,4.905563,0.786403,-181.749161,0.079767,0.000000
53.610004,22.222816,-181.793640,-0.000824,0.003116,0.079143,98.852028,5.035762,0.791429,-181.793640,0.080184,0.000000
53.860004,22.070885,-181.793640,-0.000785,0.003128,0.079456,98.176201,5.001334,0.794555,-181.793640,0.080600,0.000000
54.110004,22.813026,-181.838135,-0.000750,0.003151,0.080028,101.477409,5.169506,0.800278,-181.838135,0.081016,0.000000
54.360004,23.004425,-181.882614,-0.000720,0.003170,0.080530,102.328796,5.212877,0.805305,-181.882614,0.081433,0.000000
54.610004,22.606361,-181.882614,-0.000711,0.003182,0.080826,100.558121,5.122675,0.808257,-181.882614,0.081857,0.000000
54.860004,22.560555,-181.882614,-0.000690,0.003198,0.081225,100.354355,5.112295,0.812246,-181.882614,0.082274,0.000000
55.110004,22.732590,-181.927094,-0.000668,0.003212,0.081580,101.119606,5.151278,0.815804,-181.927094,0.082690,0.000000
55.360004,23.233803,-181.971573,-0.000651,0.003232,0.082092,103.349113,5.264855,0.820921,-181.971573,0.083106,0.000000
55.610004,23.305672,-182.060532,-0.000629,0.003248,0.082491,103.668808,5.281140,0.824910,-182.060532,0.083523,0.000000
55.860004,23.315727,-182.060532,-0.000599,0.003263,0.082873,103.713531,5.283419,0.828725,-182.060532,0.083939,0.000000
56.110004,23.893654,-182.149490,-0.000573,0.003285,0.083436,106.284279,5.414379,0.834357,-182.149490,0.084355,0.000000
56.360004,24.129364,-182.193970,-0.000556,0.003304,0.083913,107.332771,5.467792,0.839126,-182.193970,0.084772,0.000000
56.610004,23.868332,-182.238449,-0.000526,0.003316,0.084225,106.171646,5.408641,0.842253,-182.238449,0.085187,0.000000
56.860004,23.954720,-182.105011,-0.000513,0.003332,0.084633,106.555916,5.428217,0.846325,-182.105011,0.085604,0.000000
57.110004,24.000519,-182.193970,-0.000483,0.003346,0.084997,106.759636,5.438595,0.849966,-182.193970,0.086020,0.000000
57.360004,24.022491,-182.238449,-0.000457,0.003360,0.085352,106.857376,5.443574,0.853524,-182.238449,0.086436,0.000000
57.610004,24.413109,-182.282944,-0.000453,0.003376,0.085760,108.594933,5.532090,0.857604,-182.282944,0.086853,0.000000
57.860004,24.531898,-182.327423,-0.000418,0.003391,0.086133,109.123337,5.559008,0.861329,-182.327423,0.087269,0.000000
58.110004,25.774506,-182.371902,-0.000388,0.003421,0.086896,114.650726,5.840587,0.868959,-182.371902,0.087685,0.000000
58.360004,25.395432,-182.460861,-0.000354,0.003433,0.087199,112.964523,5.754687,0.871994,-182.460861,0.088102,0.000000
58.610004,25.171631,-182.416382,-0.000341,0.003448,0.087573,111.969009,5.703973,0.875726,-182.416382,0.088518,0.000000
58.860004,25.274033,-182.460861,-0.000345,0.003461,0.087919,112.424515,5.727178,0.879193,-182.460861,0.088934,0.000000
59.110004,25.658699,-182.460861,-0.000341,0.003479,0.088370,114.135597,5.814344,0.883705,-182.460861,0.089351,0.000000
59.360004,25.906326,-182.505341,-0.000310,0.003496,0.088795,115.237091,5.870457,0.887951,-182.505341,0.089766,0.000000
59.610004,25.625557,-182.549820,-0.000267,0.003504,0.088995,113.988167,5.806834,0.889950,-182.549820,0.090192,0.000000
59.860004,26.072403,-182.594299,-0.000229,0.003518,0.089367,115.975838,5.908091,0.893674,-182.594299,0.090608,0.000000
60.110004,27.754784,-182.594299,-0.000229,0.003549,0.090157,123.459442,6.289324,0.901570,-182.594299,0.091024,0.000000
60.360004,27.395813,-182.638779,-0.000229,0.003560,0.090426,121.862663,6.207980,0.904257,-182.638779,0.091441,0.000000
60.610004,27.489655,-182.772232,-0.000207,0.003575,0.090816,122.280090,6.229245,0.908163,-182.772232,0.091856,0.000000
60.860004,27.881386,-182.727753,-0.000177,0.003595,0.091302,124.022598,6.318012,0.913015,-182.727753,0.092273,0.000000
61.110004,28.431381,-182.727753,-0.000160,0.003611,0.091710,126.469101,6.442643,0.917095,-182.727753,0.092689,0.000000
61.360004,28.630226,-182.727753,-0.000134,0.003625,0.092082,127.353607,6.487702,0.920820,-182.727753,0.093105,0.000000
61.610004,28.425797,-182.861191,-0.000129,0.003633,0.092282,126.444260,6.441378,0.922818,-182.861191,0.093522,0.000000
61.860004,29.363060,-182.861191,-0.000116,0.003655,0.092845,130.613419,6.653765,0.928450,-182.861191,0.093938,0.000000
62.110004,30.256752,-182.905670,-0.000086,0.003674,0.093331,134.588760,6.856278,0.933310,-182.905670,0.094354,0.000000
62.360004,30.590393,-182.861191,-0.000095,0.003690,0.093722,136.072861,6.931882,0.937216,-182.861191,0.094771,0.000000
62.610004,30.916595,-182.950150,-0.000073,0.003706,0.094129,137.523880,7.005800,0.941288,-182.950150,0.095187,0.000000
62.860004,31.372375,-182.994629,-0.000026,0.003721,0.094519,139.551300,7.109082,0.945194,-182.994629,0.095603,0.000000
63.110004,32.361771,-183.039108,-0.000047,0.003742,0.095048,143.952347,7.333282,0.950478,-183.039108,0.096020,0.000000
63.360004,32.539764,-183.039108,-0.000004,0.003756,0.095413,144.744095,7.373616,0.954127,-183.039108,0.096435,0.000000
63.610004,32.869690,-183.083588,0.000000,0.003769,0.095733,146.211685,7.448378,0.957329,-183.083588,0.096852,0.000000
63.860004,33.787216,-183.128082,0.000022,0.003791,0.096279,150.293045,7.656293,0.962794,-183.128082,0.097268,0.000000
64.110001,34.760223,-183.172562,0.000034,0.003808,0.096731,154.621201,7.876779,0.967306,-183.172562,0.097684,0.000000
64.360001,34.887199,-183.217041,0.000056,0.003825,0.097147,155.186020,7.905552,0.971469,-183.217041,0.098101,0.000000
64.610001,35.614815,-183.217041,0.000039,0.003838,0.097485,158.422607,8.070433,0.974853,-183.217041,0.098525,0.000000
64.860001,36.421379,-183.261520,0.000073,0.003857,0.097962,162.010391,8.253203,0.979622,-183.261520,0.098942,0.000000
65.110001,36.836945,-183.261520,0.000082,0.003870,0.098309,163.858917,8.347370,0.983089,-183.261520,0.099358,0.000000
65.360001,36.691345,-183.306000,0.000091,0.003882,0.098595,163.211258,8.314378,0.985950,-183.306000,0.099774,0.000000
65.610001,38.292549,-183.306000,0.000108,0.003900,0.099072,170.333771,8.677216,0.990719,-183.306000,0.100191,0.000000
65.860001,39.497543,-183.394958,0.000134,0.003923,0.099644,175.693848,8.950272,0.996442,-183.394958,0.100607,0.000000
66.110001,40.165955,-183.439438,0.000142,0.003939,0.100052,178.667084,9.101736,1.000522,-183.439438,0.101023,0.000000
66.360001,40.889473,-183.439438,0.000151,0.003955,0.100451,181.885452,9.265688,1.004511,-183.439438,0.101440,0.000000
66.610001,41.341904,-183.483917,0.000151,0.003967,0.100763,183.897980,9.368209,1.007630,-183.483917,0.101856,0.000000
66.860001,42.004356,-183.528397,0.000190,0.003984,0.101188,186.844711,9.518323,1.011884,-183.528397,0.102272,0.000000
67.110001,42.721550,-183.572891,0.000168,0.004001,0.101621,190.034943,9.680841,1.016214,-183.572891,0.102688,0.000000
67.360001,43.472626,-183.572891,0.000194,0.004010,0.101864,193.375900,9.851038,1.018644,-183.572891,0.103104,0.000000
67.610001,45.195587,-183.706329,0.000172,0.004037,0.102541,201.040009,10.241467,1.025411,-183.706329,0.103521,0.000000
67.860001,46.627365,-183.661850,0.000220,0.004059,0.103104,207.408875,10.565912,1.031043,-183.661850,0.103937,0.000000
68.110001,46.931221,-183.661850,0.000211,0.004070,0.103374,208.760498,10.634767,1.033738,-183.661850,0.104353,0.000000
68.360001,47.477486,-183.706329,0.000220,0.004084,0.103729,211.190399,10.758552,1.037288,-183.706329,0.104770,0.000000
68.610001,48.237869,-183.750809,0.000233,0.004100,0.104145,214.572754,10.930857,1.041452,-183.750809,0.105186,0.000000
68.860001,49.538940,-183.795288,0.000250,0.004119,0.104631,220.360214,11.225684,1.046311,-183.795288,0.105602,0.000000
69.110001,50.641533,-183.795288,0.000272,0.004135,0.105030,225.264786,11.475535,1.050301,-183.795288,0.106019,0.000000
69.360001,51.804825,-183.839767,0.000280,0.004152,0.105472,230.439377,11.739141,1.054722,-183.839767,0.106435,0.000000
69.610001,52.903702,-183.884247,0.000297,0.004171,0.105941,235.327423,11.988150,1.059407,-183.884247,0.106851,0.000000
69.860001,53.888626,-183.928726,0.000276,0.004187,0.106357,239.708588,12.211337,1.063571,-183.928726,0.107276,0.000000
70.110001,54.258018,-183.973221,0.000297,0.004197,0.106608,241.351715,12.295043,1.066084,-183.973221,0.107692,0.000000
70.360001,55.317047,-183.973221,0.000323,0.004214,0.107033,246.062515,12.535022,1.070331,-183.973221,0.108109,0.000000
70.610001,55.614944,-184.017700,0.000306,0.004223,0.107267,247.387634,12.602527,1.072670,-184.017700,0.108525,0.000000
70.860001,57.537506,-184.062180,0.000315,0.004246,0.107840,255.939606,13.038185,1.078400,-184.062180,0.108941,0.000000
71.110001,58.352623,-184.106659,0.000332,0.004261,0.108230,259.565430,13.222893,1.082298,-184.106659,0.109357,0.000000
71.360001,59.396011,-184.151138,0.000319,0.004275,0.108586,264.206665,13.459329,1.085856,-184.151138,0.109773,0.000000
71.610001,61.932983,-184.151138,0.000336,0.004306,0.109374,275.491669,14.034214,1.093744,-184.151138,0.110190,0.000000
71.860001,62.516869,-184.195618,0.000332,0.004315,0.109600,278.088928,14.166525,1.096000,-184.195618,0.110606,0.000000
72.110001,63.351357,-184.195618,0.000362,0.004328,0.109930,281.800903,14.355623,1.099300,-184.195618,0.111022,0.000000
72.360001,64.265526,-184.240097,0.000384,0.004343,0.110320,285.867340,14.562776,1.103199,-184.240097,0.111439,0.000000
72.610001,65.263863,-184.329056,0.000388,0.004356,0.110649,290.308167,14.789002,1.106491,-184.329056,0.111855,0.000000
72.860001,66.773827,-184.284576,0.000401,0.004375,0.111135,297.024811,15.131166,1.111351,-184.284576,0.112271,0.000000
73.110001,67.253441,-184.329056,0.000397,0.004377,0.111170,299.158234,15.239847,1.111699,-184.329056,0.111386,0.000000
73.360001,66.714622,-184.418030,0.000397,0.004377,0.111170,296.761475,15.117749,1.111699,-184.418030,0.111386,0.000000
73.610001,66.367577,-184.462509,0.000401,0.004375,0.111135,295.217712,15.039107,1.111351,-184.462509,0.111170,0.000000
73.860001,65.992226,-184.418030,0.000397,0.004375,0.111127,293.548096,14.954052,1.111268,-184.418030,0.111170,0.000000
74.110001,65.655968,-184.462509,0.000423,0.004375,0.111118,292.052338,14.877855,1.111177,-184.462509,0.111170,0.000000
74.360001,65.372597,-184.506989,0.000410,0.004375,0.111118,290.791840,14.813643,1.111177,-184.506989,0.111170,0.000000
74.610001,65.114159,-184.551468,0.000405,0.004375,0.111118,289.642242,14.755079,1.111177,-184.551468,0.111170,0.000000
74.860001,64.879204,-184.595947,0.000405,0.004375,0.111118,288.597107,14.701838,1.111177,-184.595947,0.111170,0.000000
75.110001,64.686302,-184.595947,0.000423,0.004375,0.111118,287.739044,14.658126,1.111177,-184.595947,0.111170,0.000000
75.360001,64.503471,-184.595947,0.000431,0.004375,0.111118,286.925781,14.616695,1.111177,-184.595947,0.111170,0.000000
75.610001,64.338509,-184.684906,0.000418,0.004375,0.111118,286.191986,14.579314,1.111177,-184.684906,0.111170,0.000000
75.860001,64.190681,-184.729385,0.000431,0.004375,0.111118,285.534424,14.545816,1.111177,-184.729385,0.111170,0.000000
76.110001,64.040611,-184.773865,0.000410,0.004375,0.111118,284.866852,14.511809,1.111177,-184.773865,0.111170,0.000000
76.360001,63.904701,-184.773865,0.000401,0.004375,0.111118,284.262299,14.481012,1.111177,-184.773865,0.111170,0.000000
76.610001,63.780693,-184.818344,0.000418,0.004375,0.111118,283.710693,14.452911,1.111177,-184.818344,0.111170,0.000000
76.860001,63.675316,-184.773865,0.000405,0.004375,0.111118,283.241943,14.429032,1.111177,-184.773865,0.111170,0.000000
77.110001,63.563972,-184.818344,0.000435,0.004375,0.111118,282.746674,14.403802,1.111177,-184.818344,0.111170,0.000000
77.360001,63.462700,-184.907318,0.000397,0.004375,0.111118,282.296173,14.380854,1.111177,-184.907318,0.111170,0.000000
77.610001,63.371834,-184.907318,0.000423,0.004375,0.111118,281.891998,14.360263,1.111177,-184.907318,0.111170,0.000000
77.860001,63.281349,-184.951797,0.000431,0.004375,0.111118,281.489502,14.339758,1.111177,-184.951797,0.111170,0.000000
78.110001,63.182297,-185.040756,0.000427,0.004375,0.111118,281.048889,14.317313,1.111177,-185.040756,0.111170,0.000000
78.360001,63.107079,-184.951797,0.000431,0.004375,0.111118,280.714294,14.300268,1.111177,-184.951797,0.111170,0.000000
78.610001,63.033722,-185.040756,0.000423,0.004375,0.111118,280.388000,14.283646,1.111177,-185.040756,0.111170,0.000000
78.860001,62.946213,-185.040756,0.000410,0.004375,0.111118,279.998749,14.263816,1.111177,-185.040756,0.111170,0.000000
79.110001,62.876953,-185.085236,0.000440,0.004375,0.111118,279.690643,14.248120,1.111177,-185.085236,0.111170,0.000000
79.360001,62.813278,-185.129715,0.000440,0.004375,0.111118,279.407410,14.233692,1.111177,-185.129715,0.111170,0.000000
79.610001,62.750343,-185.174194,0.000448,0.004375,0.111118,279.127472,14.219431,1.111177,-185.174194,0.111170,0.000000
79.860001,62.690765,-185.218674,0.000427,0.004375,0.111118,278.862457,14.205931,1.111177,-185.218674,0.111170,0.000000
80.110001,62.620384,-185.218674,0.000435,0.004375,0.111118,278.549377,14.189981,1.111177,-185.218674,0.111170,0.000000
80.360001,62.571236,-185.263168,0.000431,0.004375,0.111118,278.330750,14.178844,1.111177,-185.263168,0.111170,0.000000
80.610001,62.507927,-185.263168,0.000431,0.004375,0.111118,278.049133,14.164498,1.111177,-185.263168,0.111170,0.000000
80.860001,62.459152,-185.307648,0.000427,0.004375,0.111118,277.832184,14.153446,1.111177,-185.307648,0.111170,0.000000
81.110001,62.406273,-185.352127,0.000444,0.004375,0.111118,277.596954,14.141464,1.111177,-185.352127,0.111170,0.000000
81.360001,62.363075,-185.307648,0.000427,0.004375,0.111118,277.404816,14.131675,1.111177,-185.307648,0.111170,0.000000
81.610001,62.302383,-185.396606,0.000448,0.004375,0.111118,277.134857,14.117922,1.111177,-185.396606,0.111170,0.000000
81.860001,62.261421,-185.441086,0.000427,0.004375,0.111118,276.952637,14.108640,1.111177,-185.441086,0.111170,0.000000
82.110001,62.218597,-185.396606,0.000435,0.004375,0.111118,276.762146,14.098935,1.111177,-185.396606,0.111170,0.000000
82.360001,62.174660,-185.485565,0.000448,0.004375,0.111118,276.566711,14.088979,1.111177,-185.485565,0.111170,0.000000
82.610001,62.133324,-185.530045,0.000435,0.004375,0.111118,276.382812,14.079613,1.111177,-185.530045,0.111170,0.000000
82.860001,62.085663,-185.574524,0.000440,0.004375,0.111118,276.170807,14.068812,1.111177,-185.574524,0.111170,0.000000
83.110001,62.037621,-185.574524,0.000423,0.004375,0.111118,275.957123,14.057925,1.111177,-185.574524,0.111170,0.000000
83.360001,62.016029,-185.663483,0.000435,0.004375,0.111118,275.861084,14.053033,1.111177,-185.663483,0.111170,0.000000
83.610001,61.972084,-185.663483,0.000427,0.004375,0.111118,275.665588,14.043075,1.111177,-185.663483,0.111170,0.000000
83.860001,61.927773,-185.707977,0.000444,0.004375,0.111118,275.468475,14.033034,1.111177,-185.707977,0.111170,0.000000
84.110001,61.894630,-185.707977,0.000448,0.004375,0.111118,275.321075,14.025523,1.111177,-185.707977,0.111170,0.000000
84.360001,61.861862,-185.752457,0.000435,0.004375,0.111118,275.175293,14.018099,1.111177,-185.752457,0.111170,0.000000
84.610001,61.827606,-185.796936,0.000457,0.004375,0.111118,275.022919,14.010335,1.111177,-185.796936,0.111170,0.000000
84.860001,61.785530,-185.885895,0.000440,0.004375,0.111118,274.835754,14.000801,1.111177,-185.885895,0.111170,0.000000
85.110001,61.750526,-185.841415,0.000444,0.004375,0.111118,274.680054,13.992869,1.111177,-185.841415,0.111170,0.000000
85.360001,61.716263,-185.885895,0.000444,0.004375,0.111118,274.527649,13.985105,1.111177,-185.885895,0.111170,0.000000
85.610001,61.703606,-185.974854,0.000423,0.004375,0.111118,274.471344,13.982237,1.111177,-185.974854,0.111170,0.000000
85.860001,61.663391,-185.930374,0.000448,0.004375,0.111118,274.292450,13.973124,1.111177,-185.930374,0.111170,0.000000
86.110001,61.635460,-185.930374,0.000440,0.004375,0.111118,274.168213,13.966794,1.111177,-185.930374,0.111170,0.000000
86.360001,61.595619,-185.974854,0.000453,0.004375,0.111118,273.990997,13.957767,1.111177,-185.974854,0.111170,0.000000
86.610001,61.565826,-186.063812,0.000448,0.004375,0.111118,273.858459,13.951015,1.111177,-186.063812,0.111170,0.000000
86.860001,61.542366,-186.063812,0.000444,0.004375,0.111118,273.754120,13.945700,1.111177,-186.063812,0.111170,0.000000
87.110001,61.521141,-186.063812,0.000440,0.004375,0.111118,273.659698,13.940890,1.111177,-186.063812,0.111170,0.000000
87.360001,61.482040,-186.108292,0.000440,0.004375,0.111118,273.485779,13.932030,1.111177,-186.108292,0.111170,0.000000
87.610001,61.457840,-186.197266,0.000431,0.004375,0.111118,273.378113,13.926545,1.111177,-186.197266,0.111170,0.000000
87.860001,61.438850,-186.197266,0.000435,0.004375,0.111118,273.293671,13.922242,1.111177,-186.197266,0.111170,0.000000
88.110001,61.399376,-186.197266,0.000418,0.004375,0.111118,273.118073,13.913298,1.111177,-186.197266,0.111170,0.000000
88.360001,61.390442,-186.286224,0.000453,0.004375,0.111118,273.078339,13.911273,1.111177,-186.286224,0.111170,0.000000
88.610001,61.356926,-186.330704,0.000435,0.004375,0.111118,272.929230,13.903679,1.111177,-186.330704,0.111170,0.000000
88.860001,61.333466,-186.375183,0.000444,0.004375,0.111118,272.824890,13.898362,1.111177,-186.375183,0.111170,0.000000
89.110001,61.311501,-186.330704,0.000431,0.004375,0.111118,272.727173,13.893385,1.111177,-186.330704,0.111170,0.000000
89.360001,61.286919,-186.464142,0.000435,0.004375,0.111118,272.617828,13.887815,1.111177,-186.464142,0.111170,0.000000
89.610001,61.268303,-186.464142,0.000444,0.004375,0.111118,272.535034,13.883596,1.111177,-186.464142,0.111170,0.000000
89.860001,61.237396,-186.464142,0.000427,0.004375,0.111118,272.397552,13.876593,1.111177,-186.464142,0.111170,0.000000
90.110001,61.216171,-186.464142,0.000457,0.004375,0.111118,272.303131,13.871782,1.111177,-186.464142,0.111170,0.000000
90.360001,61.181915,-186.553116,0.000444,0.004375,0.111118,272.150757,13.864020,1.111177,-186.553116,0.111170,0.000000
90.610001,61.174461,-186.597595,0.000453,0.004375,0.111118,272.117584,13.862331,1.111177,-186.597595,0.111170,0.000000
90.860001,61.161057,-186.597595,0.000435,0.004375,0.111118,272.057953,13.859293,1.111177,-186.597595,0.111170,0.000000
91.110001,61.126053,-186.642075,0.000435,0.004375,0.111118,271.902252,13.851361,1.111177,-186.642075,0.111170,0.000000
91.360001,61.116005,-186.686554,0.000444,0.004375,0.111118,271.857574,13.849085,1.111177,-186.686554,0.111170,0.000000
91.610001,61.087326,-186.642075,0.000431,0.004375,0.111118,271.730011,13.842587,1.111177,-186.642075,0.111170,0.000000
91.860001,61.068710,-186.686554,0.000448,0.004375,0.111118,271.647186,13.838367,1.111177,-186.686554,0.111170,0.000000
92.110001,61.063126,-186.731033,0.000423,0.004375,0.111118,271.622345,13.837102,1.111177,-186.731033,0.111170,0.000000
92.360001,61.016205,-186.775513,0.000453,0.004375,0.111118,271.413635,13.826469,1.111177,-186.775513,0.111170,0.000000
92.610001,61.010246,-186.819992,0.000440,0.004375,0.111118,271.387115,13.825120,1.111177,-186.819992,0.111170,0.000000
92.860001,60.993866,-186.864471,0.000444,0.004375,0.111118,271.314270,13.821407,1.111177,-186.864471,0.111170,0.000000
93.110001,60.978226,-186.864471,0.000440,0.004375,0.111118,271.244690,13.817863,1.111177,-186.864471,0.111170,0.000000
93.360008,60.954765,-186.864471,0.000448,0.004375,0.111118,271.140350,13.812548,1.111177,-186.864471,0.111170,0.000000
93.610008,60.940987,-186.953430,0.000444,0.004375,0.111118,271.079041,13.809424,1.111177,-186.953430,0.111170,0.000000
93.860008,60.911568,-186.953430,0.000448,0.004375,0.111118,270.948181,13.802758,1.111177,-186.953430,0.111170,0.000000
94.110008,60.914917,-186.997925,0.000427,0.004375,0.111118,270.963074,13.803517,1.111177,-186.997925,0.111170,0.000000
94.360008,60.878799,-187.042404,0.000457,0.004375,0.111118,270.802429,13.795333,1.111177,-187.042404,0.111170,0.000000
94.610008,60.860184,-187.042404,0.000435,0.004375,0.111118,270.719604,13.791115,1.111177,-187.042404,0.111170,0.000000
94.860008,60.841560,-187.086884,0.000440,0.004375,0.111118,270.636780,13.786895,1.111177,-187.086884,0.111170,0.000000
95.110008,60.836349,-187.131363,0.000435,0.004375,0.111118,270.613586,13.785714,1.111177,-187.131363,0.111170,0.000000
95.360008,60.825180,-187.131363,0.000423,0.004375,0.111118,270.563904,13.783182,1.111177,-187.131363,0.111170,0.000000
95.610008,60.811401,-187.175842,0.000423,0.004375,0.111118,270.502625,13.780061,1.111177,-187.175842,0.111170,0.000000
95.860008,60.767830,-187.175842,0.000444,0.004375,0.111118,270.308807,13.770187,1.111177,-187.175842,0.111170,0.000000
96.110008,60.767464,-187.264801,0.000444,0.004375,0.111118,270.307190,13.770104,1.111177,-187.264801,0.111170,0.000000
96.360008,60.754799,-187.264801,0.000444,0.004375,0.111118,270.250854,13.767235,1.111177,-187.264801,0.111170,0.000000
96.610008,60.725754,-187.264801,0.000431,0.004375,0.111118,270.121643,13.760653,1.111177,-187.264801,0.111170,0.000000
96.860008,60.720169,-187.353760,0.000444,0.004375,0.111118,270.096802,13.759387,1.111177,-187.353760,0.111170,0.000000
97.110008,60.695969,-187.353760,0.000444,0.004375,0.111118,269.989166,13.753902,1.111177,-187.353760,0.111170,0.000000
97.360008,60.702667,-187.353760,0.000427,0.004375,0.111118,270.018951,13.755421,1.111177,-187.353760,0.111170,0.000000
97.610008,60.670273,-187.442734,0.000435,0.004375,0.111118,269.874847,13.748080,1.111177,-187.442734,0.111170,0.000000
97.860008,60.659103,-187.487213,0.000444,0.004375,0.111118,269.825165,13.745549,1.111177,-187.487213,0.111170,0.000000
98.110008,60.649048,-187.531693,0.000440,0.004375,0.111118,269.780426,13.743270,1.111177,-187.531693,0.111170,0.000000
98.360008,60.628937,-187.531693,0.000444,0.004375,0.111118,269.690979,13.738714,1.111177,-187.531693,0.111170,0.000000
98.610008,60.608459,-187.531693,0.000453,0.004375,0.111118,269.599884,13.734073,1.111177,-187.531693,0.111170,0.000000
98.860008,60.599892,-187.576172,0.000448,0.004375,0.111118,269.561768,13.732132,1.111177,-187.576172,0.111170,0.000000
99.110008,60.584999,-187.576172,0.000427,0.004375,0.111118,269.495544,13.728757,1.111177,-187.576172,0.111170,0.000000
99.360008,60.578667,-187.665131,0.000457,0.004375,0.111118,269.467377,13.727323,1.111177,-187.665131,0.111170,0.000000
99.610008,60.555954,-187.665131,0.000453,0.004375,0.111118,269.366333,13.722176,1.111177,-187.665131,0.111170,0.000000
99.860008,60.537338,-187.709610,0.000448,0.004375,0.111118,269.283539,13.717957,1.111177,-187.709610,0.111170,0.000000
100.110008,60.534729,-187.709610,0.000453,0.004375,0.111118,269.271912,13.717366,1.111177,-187.709610,0.111170,0.000000
100.360008,60.504936,-187.798569,0.000444,0.004375,0.111118,269.139404,13.710614,1.111177,-187.798569,0.111170,0.000000
100.610008,60.501961,-187.798569,0.000453,0.004375,0.111118,269.126160,13.709941,1.111177,-187.798569,0.111170,0.000000
100.860008,60.500839,-187.754089,0.000448,0.004375,0.111118,269.121185,13.709685,1.111177,-187.754089,0.111170,0.000000
101.110008,60.469566,-187.932022,0.000435,0.004375,0.111118,268.982056,13.702600,1.111177,-187.932022,0.111170,0.000000
101.360008,60.461372,-187.887543,0.000414,0.004375,0.111118,268.945618,13.700743,1.111177,-187.887543,0.111170,0.000000
101.610008,60.445732,-187.887543,0.000457,0.004375,0.111118,268.876038,13.697198,1.111177,-187.887543,0.111170,0.000000
101.860008,60.420036,-187.976501,0.000448,0.004375,0.111118,268.761749,13.691377,1.111177,-187.976501,0.111170,0.000000
102.110008,60.432327,-187.976501,0.000427,0.004375,0.111118,268.816406,13.694161,1.111177,-187.976501,0.111170,0.000000
102.360008,60.416687,-188.109940,0.000453,0.004375,0.111118,268.746857,13.690618,1.111177,-188.109940,0.111170,0.000000
102.610008,60.400299,-188.065460,0.000435,0.004375,0.111118,268.673950,13.686903,1.111177,-188.065460,0.111170,0.000000
102.860008,60.382057,-188.109940,0.000431,0.004375,0.111118,268.592804,13.682770,1.111177,-188.109940,0.111170,0.000000
103.110008,60.373116,-188.154419,0.000440,0.004375,0.111118,268.553040,13.680744,1.111177,-188.154419,0.111170,0.000000
103.360008,60.365295,-188.109940,0.000448,0.004375,0.111118,268.518250,13.678971,1.111177,-188.109940,0.111170,0.000000
103.500008,60.363434,-188.243378,0.000431,0.004375,0.111118,268.509979,13.678550,1.111177,-188.243378,0.111170,0.000000