File: Data/compression 13/AutoNoHeating-10-13-3-240724_07242024_162903.csv
Time (sec),S:Load (lbs),S:HL1 (DIM),S:LVDT (in),S:Position (in),Ch:Position (mm),Ch:Load (N),Ch:Stress (MPa),Ch:Strain (mm/mm),Ch:HL1 (DIM),Set Point (),Cycles ()
0.110000,-0.005211,-200.386688,-0.007541,-0.003151,-0.080036,-0.023179,-0.001181,-0.800361,-200.386688,-0.080184,0.000000
0.370000,0.014893,-200.342209,-0.007524,-0.003151,-0.080036,0.066245,0.003375,-0.800361,-200.342209,-0.080184,0.000000
0.630000,-0.004845,-200.431168,-0.007528,-0.003040,-0.077226,-0.021550,-0.001098,-0.772262,-200.431168,-0.076472,0.000000
0.890000,-0.005585,-200.386688,-0.007502,-0.002883,-0.073229,-0.024842,-0.001266,-0.732286,-200.386688,-0.072136,0.000000
1.150000,0.063675,-200.520126,-0.007498,-0.002718,-0.069031,0.283240,0.014429,-0.690312,-200.520126,-0.067800,0.000000
1.410000,0.038353,-200.564606,-0.007278,-0.002540,-0.064504,0.170603,0.008691,-0.645045,-200.564606,-0.063464,0.000000
1.670000,0.055481,-200.520126,-0.007131,-0.002375,-0.060333,0.246792,0.012572,-0.603327,-200.520126,-0.059144,0.000000
1.930000,0.093094,-200.653564,-0.006946,-0.002209,-0.056110,0.414102,0.021095,-0.561096,-200.653564,-0.054808,0.000000
2.190000,0.106873,-200.609085,-0.006760,-0.002029,-0.051531,0.475393,0.024218,-0.515306,-200.609085,-0.050472,0.000000
2.450000,0.075218,-200.609085,-0.006631,-0.001862,-0.047307,0.334587,0.017045,-0.473066,-200.609085,-0.046136,0.000000
2.710000,0.070007,-200.698044,-0.006428,-0.001699,-0.043144,0.311408,0.015864,-0.431440,-200.698044,-0.041818,0.000000
2.970000,0.060326,-200.698044,-0.006209,-0.001517,-0.038539,0.268342,0.013670,-0.385393,-200.698044,-0.037481,0.000000
3.230000,0.031281,-200.742538,-0.006071,-0.001350,-0.034299,0.139143,0.007088,-0.342987,-200.742538,-0.033145,0.000000
3.490000,0.081177,-200.787018,-0.005911,-0.001186,-0.030136,0.361092,0.018395,-0.301361,-200.787018,-0.028809,0.000000
3.750000,0.092720,-200.831497,-0.005700,-0.001009,-0.025635,0.412439,0.021011,-0.256351,-200.831497,-0.024491,0.000000
4.010000,0.078568,-200.787018,-0.005553,-0.000843,-0.021412,0.349486,0.017804,-0.214119,-200.787018,-0.020154,0.000000
4.270000,0.122513,-200.831497,-0.005342,-0.000681,-0.017292,0.544964,0.027762,-0.172924,-200.831497,-0.015818,0.000000
4.530000,0.202942,-200.920456,-0.005170,-0.000500,-0.012696,0.902731,0.045987,-0.126961,-200.920456,-0.011499,0.000000
4.790000,0.501961,-200.920456,-0.005010,-0.000328,-0.008325,2.232833,0.113746,-0.083253,-200.920456,-0.007163,0.000000
5.050000,0.667290,-200.964935,-0.004885,-0.000002,-0.000052,2.968253,0.151210,-0.000522,-200.964935,0.000043,0.000000
5.310000,0.619629,-201.009415,-0.004911,-0.000002,-0.000061,2.756247,0.140410,-0.000606,-201.009415,0.000043,0.000000
5.570000,0.623726,-201.009415,-0.004911,-0.000002,-0.000061,2.774471,0.141338,-0.000606,-201.009415,0.000294,0.000000
5.830000,0.598404,-201.098373,-0.004919,-0.000002,-0.000061,2.661834,0.135600,-0.000606,-201.098373,0.000728,0.000000
6.090000,0.663193,-201.053894,-0.004924,0.000010,0.000251,2.950029,0.150282,0.002513,-201.053894,0.001154,0.000000
6.350000,0.788681,-201.098373,-0.004902,0.000024,0.000615,3.508229,0.178718,0.006154,-201.098373,0.001587,0.000000
6.610000,0.864273,-201.142868,-0.004898,0.000042,0.001058,3.844479,0.195847,0.010583,-201.142868,0.002020,0.000000
6.870000,0.912308,-201.187347,-0.004907,0.000054,0.001378,4.058147,0.206732,0.013785,-201.187347,0.002454,0.000000
7.130000,1.022537,-201.187347,-0.004842,0.000073,0.001847,4.548473,0.231710,0.018470,-201.187347,0.002888,0.000000
7.390000,1.124565,-201.231827,-0.004838,0.000090,0.002298,5.002316,0.254830,0.022982,-201.231827,0.003322,0.000000
7.650001,1.204994,-201.276306,-0.004846,0.000107,0.002705,5.360082,0.273056,0.027054,-201.276306,0.003755,0.000000
7.910000,1.280586,-201.320786,-0.004846,0.000123,0.003122,5.696332,0.290185,0.031218,-201.320786,0.004188,0.000000
8.170000,1.448524,-201.320786,-0.004812,0.000146,0.003721,6.443359,0.328240,0.037206,-201.320786,0.004622,0.000000
8.430000,1.524117,-201.320786,-0.004790,0.000161,0.004102,6.779609,0.345370,0.041021,-201.320786,0.005056,0.000000
8.690001,1.575882,-201.276306,-0.004786,0.000176,0.004466,7.009873,0.357100,0.044662,-201.276306,0.005490,0.000000
8.950001,1.823883,-201.409744,-0.004751,0.000200,0.005091,8.113037,0.413298,0.050907,-201.409744,0.005923,0.000000
9.210000,1.937080,-201.498703,-0.004717,0.000216,0.005490,8.616564,0.438949,0.054896,-201.498703,0.006356,0.000000
9.470000,2.080818,-201.409744,-0.004717,0.000233,0.005906,9.255941,0.471520,0.059060,-201.409744,0.006790,0.000000
9.730000,2.228279,-201.498703,-0.004691,0.000252,0.006400,9.911880,0.504935,0.064003,-201.498703,0.007224,0.000000
9.990001,2.351906,-201.543182,-0.004691,0.000268,0.006799,10.461800,0.532950,0.067992,-201.543182,0.007658,0.000000
10.250001,2.398453,-201.543182,-0.004682,0.000279,0.007085,10.668851,0.543497,0.070853,-201.543182,0.008091,0.000000
10.510000,2.547768,-201.587677,-0.004661,0.000294,0.007475,11.333036,0.577332,0.074752,-201.587677,0.008525,0.000000
10.770000,2.880302,-201.587677,-0.004639,0.000318,0.008065,12.812225,0.652686,0.080649,-201.587677,0.008958,0.000000
11.030001,3.012489,-201.676636,-0.004631,0.000334,0.008481,13.400222,0.682640,0.084812,-201.676636,0.009392,0.000000
11.290001,3.010628,-201.632156,-0.004600,0.000345,0.008759,13.391941,0.682218,0.087590,-201.632156,0.009826,0.000000
11.550000,3.256767,-201.721115,-0.004566,0.000363,0.009218,14.486824,0.737994,0.092185,-201.721115,0.010259,0.000000
11.810000,3.562111,-201.765594,-0.004566,0.000390,0.009904,15.845060,0.807186,0.099036,-201.765594,0.010693,0.000000
12.070001,3.558022,-201.721115,-0.004544,0.000400,0.010155,15.826870,0.806259,0.101549,-201.721115,0.011126,0.000000
12.330001,3.752396,-201.810074,-0.004553,0.000418,0.010606,16.691490,0.850305,0.106060,-201.810074,0.011560,0.000000
12.590000,3.851822,-201.810074,-0.004506,0.000432,0.010962,17.133760,0.872835,0.109618,-201.810074,0.011994,0.000000
12.850000,4.108383,-201.854553,-0.004506,0.000449,0.011413,18.275002,0.930973,0.114130,-201.854553,0.012427,0.000000
13.110001,4.324364,-201.899033,-0.004480,0.000465,0.011820,19.235731,0.979915,0.118202,-201.899033,0.012861,0.000000
13.370001,4.522087,-201.943512,-0.004454,0.000483,0.012262,20.115248,1.024720,0.122623,-201.943512,0.013295,0.000000
13.630001,4.850899,-202.032486,-0.004458,0.000508,0.012904,21.577875,1.099229,0.129042,-202.032486,0.013728,0.000000
13.890000,4.881432,-202.032486,-0.004428,0.000524,0.013303,21.713692,1.106148,0.133031,-202.032486,0.014162,0.000000
14.150001,4.830414,-202.032486,-0.004437,0.000531,0.013486,21.486753,1.094587,0.134856,-202.032486,0.014595,0.000000
14.410001,5.117516,-202.076965,-0.004398,0.000551,0.013988,22.763845,1.159646,0.139882,-202.076965,0.015029,0.000000
14.670001,5.420250,-202.076965,-0.004385,0.000572,0.014517,24.110476,1.228246,0.145173,-202.076965,0.015463,0.000000
14.930000,5.544624,-202.121445,-0.004359,0.000586,0.014891,24.663721,1.256430,0.148905,-202.121445,0.015896,0.000000
15.190001,5.629898,-202.121445,-0.004355,0.000602,0.015298,25.043037,1.275753,0.152978,-202.121445,0.016321,0.000000
15.450001,5.985886,-202.165924,-0.004342,0.000621,0.015766,26.626549,1.356421,0.157664,-202.165924,0.016755,0.000000
15.710001,6.197021,-202.210403,-0.004320,0.000643,0.016339,27.565729,1.404265,0.163386,-202.210403,0.017188,0.000000
15.970001,6.267029,-202.254883,-0.004307,0.000659,0.016728,27.877136,1.420129,0.167285,-202.254883,0.017622,0.000000
16.230001,6.283783,-202.299362,-0.004299,0.000672,0.017059,27.951662,1.423926,0.170585,-202.299362,0.018055,0.000000
16.490002,6.531784,-202.254883,-0.004273,0.000689,0.017492,29.054827,1.480123,0.174915,-202.254883,0.018489,0.000000
16.750000,6.864311,-202.388321,-0.004243,0.000710,0.018038,30.533981,1.555475,0.180381,-202.388321,0.018923,0.000000
17.010000,6.888145,-202.432816,-0.004264,0.000724,0.018402,30.640001,1.560876,0.184022,-202.432816,0.019357,0.000000
17.270000,6.865433,-202.388321,-0.004199,0.000736,0.018688,30.538971,1.555729,0.186883,-202.388321,0.019790,0.000000
17.530001,7.367386,-202.432816,-0.004212,0.000761,0.019339,32.771770,1.669473,0.193393,-202.432816,0.020223,0.000000
17.790001,7.510376,-202.388321,-0.004204,0.000780,0.019816,33.407822,1.701875,0.198162,-202.388321,0.020657,0.000000
18.050001,7.476868,-202.521774,-0.004178,0.000793,0.020155,33.258770,1.694282,0.201546,-202.521774,0.021091,0.000000
18.310001,7.620972,-202.477295,-0.004165,0.000811,0.020597,33.899776,1.726937,0.205966,-202.477295,0.021525,0.000000
18.570002,7.736778,-202.521774,-0.004156,0.000822,0.020891,34.414909,1.753179,0.208911,-202.521774,0.021958,0.000000
18.830002,7.870834,-202.566254,-0.004130,0.000839,0.021317,35.011219,1.783557,0.213165,-202.566254,0.022391,0.000000
19.090000,8.109528,-202.610733,-0.004126,0.000855,0.021715,36.072979,1.837645,0.217155,-202.610733,0.022825,0.000000
19.350000,8.369812,-202.655212,-0.004096,0.000876,0.022261,37.230782,1.896626,0.222612,-202.655212,0.023259,0.000000
19.610001,8.721336,-202.610733,-0.004061,0.000902,0.022921,38.794441,1.976283,0.229206,-202.610733,0.023693,0.000000
19.870001,8.544083,-202.655212,-0.004053,0.000912,0.023164,38.005978,1.936117,0.231636,-202.655212,0.024126,0.000000
20.130001,8.713890,-202.744171,-0.004023,0.000932,0.023675,38.761318,1.974596,0.236753,-202.744171,0.024559,0.000000
20.390001,8.804001,-202.744171,-0.003997,0.000945,0.024005,39.162151,1.995015,0.240046,-202.744171,0.024993,0.000000
20.650002,9.107109,-202.744171,-0.004010,0.000965,0.024516,40.510445,2.063700,0.245163,-202.744171,0.025427,0.000000
20.910002,9.169296,-202.788651,-0.003975,0.000980,0.024880,40.787067,2.077792,0.248804,-202.788651,0.025861,0.000000
21.170000,9.051254,-202.788651,-0.003958,0.000985,0.025028,40.261990,2.051044,0.250280,-202.788651,0.026294,0.000000
21.430000,9.883133,-202.922104,-0.003954,0.001020,0.025895,43.962372,2.239550,0.258955,-202.922104,0.026728,0.000000
21.690001,9.795258,-202.922104,-0.003915,0.001035,0.026294,43.571484,2.219637,0.262944,-202.922104,0.027161,0.000000
21.950001,9.548744,-202.966583,-0.003893,0.001046,0.026563,42.474937,2.163776,0.265631,-202.966583,0.027595,0.000000
22.210001,9.959473,-203.011063,-0.003902,0.001066,0.027083,44.301949,2.256849,0.270832,-203.011063,0.028029,0.000000
22.470001,10.146400,-203.011063,-0.003893,0.001085,0.027552,45.133442,2.299207,0.275518,-203.011063,0.028462,0.000000
22.730001,10.172096,-203.055542,-0.003880,0.001099,0.027908,45.247746,2.305030,0.279075,-203.055542,0.028896,0.000000
22.990002,10.097626,-203.055542,-0.003859,0.001110,0.028185,44.916481,2.288155,0.281846,-203.055542,0.029329,0.000000
23.250002,10.058899,-203.055542,-0.003833,0.001118,0.028402,44.744217,2.279379,0.284019,-203.055542,0.029763,0.000000
23.510000,10.985359,-203.055542,-0.003790,0.001154,0.029312,48.865318,2.489318,0.293125,-203.055542,0.030197,0.000000
23.770000,10.631607,-203.144501,-0.003811,0.001164,0.029572,47.291752,2.409157,0.295721,-203.144501,0.030630,0.000000
24.030001,10.857262,-203.233459,-0.003773,0.001183,0.030041,48.295513,2.460291,0.300407,-203.233459,0.031064,0.000000
24.290001,10.944771,-203.144501,-0.003760,0.001198,0.030422,48.684772,2.480121,0.304222,-203.144501,0.031489,0.000000
24.550001,11.190163,-203.277939,-0.003729,0.001218,0.030942,49.776329,2.535727,0.309423,-203.277939,0.031923,0.000000
24.810001,11.174149,-203.233459,-0.003725,0.001234,0.031341,49.705093,2.532098,0.313412,-203.233459,0.032356,0.000000
25.070002,11.179741,-203.277939,-0.003712,0.001247,0.031680,49.729973,2.533365,0.316796,-203.277939,0.032790,0.000000
25.330002,11.397575,-203.411392,-0.003678,0.001266,0.032166,50.698948,2.582728,0.321656,-203.411392,0.033223,0.000000
25.590002,11.715950,-203.322433,-0.003648,0.001286,0.032660,52.115147,2.654872,0.326599,-203.322433,0.033657,0.000000
25.850000,11.794151,-203.455872,-0.003639,0.001304,0.033110,52.463005,2.672593,0.331103,-203.455872,0.034091,0.000000
26.110001,11.906609,-203.411392,-0.003630,0.001321,0.033553,52.963242,2.698076,0.335531,-203.411392,0.034524,0.000000
26.370001,11.955391,-203.411392,-0.003579,0.001336,0.033926,53.180233,2.709130,0.339255,-203.411392,0.034958,0.000000
26.630001,11.943848,-203.589310,-0.003596,0.001350,0.034290,53.128887,2.706515,0.342904,-203.589310,0.035391,0.000000
26.890001,12.151260,-203.500351,-0.003583,0.001367,0.034723,54.051506,2.753515,0.347234,-203.500351,0.035825,0.000000
27.150002,12.373940,-203.589310,-0.003540,0.001388,0.035253,55.042030,2.803975,0.352525,-203.589310,0.036259,0.000000
27.410002,12.536293,-203.633789,-0.003544,0.001407,0.035729,55.764217,2.840765,0.357294,-203.633789,0.036692,0.000000
27.670002,12.641296,-203.633789,-0.003501,0.001424,0.036163,56.231297,2.864559,0.361632,-203.633789,0.037126,0.000000
27.930002,12.633110,-203.722763,-0.003484,0.001440,0.036579,56.194881,2.862704,0.365795,-203.722763,0.037560,0.000000
28.190001,12.582092,-203.633789,-0.003475,0.001452,0.036891,55.967941,2.851143,0.368914,-203.633789,0.037993,0.000000
28.450001,12.837914,-203.722763,-0.003475,0.001471,0.037369,57.105892,2.909113,0.373690,-203.722763,0.038427,0.000000
28.710001,12.866211,-203.811722,-0.003454,0.001488,0.037802,57.231766,2.915525,0.378020,-203.811722,0.038860,0.000000
28.970001,13.062454,-203.811722,-0.003432,0.001506,0.038262,58.104698,2.959994,0.382623,-203.811722,0.039294,0.000000
29.230001,13.309708,-203.856201,-0.003397,0.001528,0.038808,59.204536,3.016023,0.388080,-203.856201,0.039728,0.000000
29.490002,13.433334,-203.856201,-0.003402,0.001545,0.039242,59.754456,3.044037,0.392418,-203.856201,0.040161,0.000000
29.750002,13.307846,-203.900681,-0.003346,0.001560,0.039615,59.196255,3.015601,0.396150,-203.900681,0.040595,0.000000
30.010002,13.216240,-203.900681,-0.003350,0.001574,0.039987,58.788773,2.994843,0.399874,-203.900681,0.041028,0.000000
30.270002,13.737564,-203.945160,-0.003328,0.001599,0.040621,61.107738,3.112977,0.406210,-203.945160,0.041462,0.000000
30.530001,13.629204,-203.945160,-0.003298,0.001614,0.041003,60.625725,3.088422,0.410025,-203.945160,0.041896,0.000000
30.790001,13.758415,-203.989639,-0.003272,0.001631,0.041427,61.200489,3.117702,0.414272,-203.989639,0.042330,0.000000
31.050001,13.952797,-204.034119,-0.003247,0.001651,0.041939,62.065140,3.161749,0.419389,-204.034119,0.042762,0.000000
31.310001,13.907364,-204.078598,-0.003260,0.001666,0.042320,61.863045,3.151453,0.423204,-204.078598,0.043196,0.000000
31.570002,13.735703,-204.078598,-0.003247,0.001677,0.042607,61.099457,3.112555,0.426066,-204.078598,0.043630,0.000000
31.830002,13.804222,-204.167572,-0.003212,0.001693,0.042997,61.404247,3.128081,0.429972,-204.167572,0.044064,0.000000
32.090000,14.232819,-204.123077,-0.003208,0.001715,0.043552,63.310738,3.225203,0.435520,-204.123077,0.044497,0.000000
32.350002,14.434273,-204.256531,-0.003160,0.001732,0.044003,64.206856,3.270853,0.440032,-204.256531,0.044931,0.000000
32.610001,14.143448,-204.167572,-0.003147,0.001744,0.044298,62.913197,3.204951,0.442977,-204.167572,0.045364,0.000000
32.870003,14.233932,-204.256531,-0.003139,0.001761,0.044740,63.315693,3.225455,0.447397,-204.256531,0.045798,0.000000
33.130001,14.923943,-204.345490,-0.003104,0.001790,0.045469,66.385010,3.381814,0.454687,-204.345490,0.046223,0.000000
33.390003,14.512840,-204.301010,-0.003104,0.001801,0.045755,64.556335,3.288656,0.457548,-204.301010,0.046656,0.000000
33.650002,14.478958,-204.434448,-0.003061,0.001817,0.046145,64.405624,3.280979,0.461447,-204.434448,0.047090,0.000000
33.910000,14.385490,-204.434448,-0.003061,0.001831,0.046518,63.989857,3.259799,0.465179,-204.434448,0.047524,0.000000
34.170002,14.737755,-204.345490,-0.003022,0.001851,0.047012,65.556808,3.339623,0.470122,-204.345490,0.047958,0.000000
34.430000,14.674080,-204.478928,-0.003018,0.001864,0.047351,65.273567,3.325194,0.473505,-204.478928,0.048391,0.000000
34.690002,14.858780,-204.434448,-0.002979,0.001883,0.047819,66.095154,3.367048,0.478191,-204.434448,0.048824,0.000000
34.950001,15.279182,-204.523407,-0.002971,0.001908,0.048452,67.965195,3.462312,0.484520,-204.523407,0.049258,0.000000
35.210003,15.102684,-204.523407,-0.002958,0.001923,0.048833,67.180092,3.422317,0.488335,-204.523407,0.049692,0.000000
35.470001,14.589180,-204.523407,-0.002932,0.001929,0.049007,64.895912,3.305955,0.490068,-204.523407,0.050126,0.000000
35.730003,14.826752,-204.612381,-0.002919,0.001949,0.049509,65.952682,3.359790,0.495095,-204.612381,0.050559,0.000000
35.990002,15.138054,-204.612381,-0.002884,0.001970,0.050039,67.337425,3.430332,0.500386,-204.612381,0.050993,0.000000
36.250000,15.236732,-204.656860,-0.002854,0.001988,0.050490,67.776375,3.452693,0.504897,-204.656860,0.051426,0.000000
36.510002,14.998047,-204.745819,-0.002841,0.002000,0.050811,66.714645,3.398606,0.508107,-204.745819,0.051860,0.000000
36.770000,15.518250,-204.745819,-0.002828,0.002023,0.051383,69.028618,3.516486,0.513830,-204.745819,0.052294,0.000000
37.030003,15.634804,-204.701340,-0.002772,0.002043,0.051886,69.547081,3.542897,0.518864,-204.701340,0.052727,0.000000
37.290001,15.469093,-204.745819,-0.002777,0.002057,0.052259,68.809967,3.505347,0.522588,-204.745819,0.053161,0.000000
37.550003,15.222954,-204.834778,-0.002768,0.002071,0.052615,67.715080,3.449571,0.526146,-204.834778,0.053594,0.000000
37.810001,15.362968,-204.834778,-0.002759,0.002086,0.052988,68.337898,3.481298,0.529878,-204.834778,0.054028,0.000000
38.070004,15.801994,-204.834778,-0.002703,0.002110,0.053586,70.290779,3.580783,0.535858,-204.834778,0.054462,0.000000
38.330002,15.581924,-204.834778,-0.002695,0.002123,0.053924,69.311859,3.530915,0.539242,-204.834778,0.054895,0.000000
38.590000,15.464996,-204.923737,-0.002665,0.002137,0.054271,68.791740,3.504418,0.542709,-204.923737,0.055329,0.000000
38.850002,15.988556,-204.968216,-0.002669,0.002161,0.054886,71.120651,3.623059,0.548863,-204.968216,0.055763,0.000000
39.110001,15.975151,-204.923737,-0.002626,0.002178,0.055329,71.061020,3.620021,0.553291,-204.923737,0.056196,0.000000
39.370003,15.753220,-205.057190,-0.002604,0.002192,0.055684,70.073822,3.569731,0.556841,-205.057190,0.056630,0.000000
39.630001,15.716721,-205.057190,-0.002583,0.002209,0.056118,69.911469,3.561460,0.561179,-205.057190,0.057063,0.000000
39.890003,15.673904,-205.057190,-0.002565,0.002219,0.056370,69.721008,3.551758,0.563700,-205.057190,0.057497,0.000000
40.150002,16.056702,-205.146149,-0.002548,0.002241,0.056925,71.423775,3.638501,0.569248,-205.146149,0.057931,0.000000
40.410004,16.015739,-205.057190,-0.002544,0.002254,0.057254,71.241570,3.629218,0.572541,-205.057190,0.058364,0.000000
40.670002,16.280121,-205.146149,-0.002496,0.002278,0.057861,72.417595,3.689128,0.578612,-205.146149,0.058798,0.000000
40.930000,16.703140,-205.279587,-0.002479,0.002302,0.058460,74.299278,3.784986,0.584600,-205.279587,0.059231,0.000000
41.190002,16.155754,-205.235107,-0.002453,0.002311,0.058694,71.864380,3.660946,0.586939,-205.235107,0.059665,0.000000
41.450001,16.293159,-205.324066,-0.002453,0.002331,0.059197,72.475594,3.692083,0.591965,-205.324066,0.060099,0.000000
41.710003,16.098404,-205.324066,-0.002423,0.002342,0.059483,71.609276,3.647950,0.594827,-205.324066,0.060533,0.000000
41.970001,16.535568,-205.279587,-0.002406,0.002364,0.060047,73.553879,3.747013,0.600466,-205.279587,0.060966,0.000000
42.230003,16.498703,-205.368546,-0.002389,0.002378,0.060411,73.389893,3.738660,0.604107,-205.368546,0.061391,0.000000
42.490002,16.006058,-205.368546,-0.002371,0.002383,0.060533,71.198502,3.627025,0.605326,-205.368546,0.061825,0.000000
42.750004,17.330215,-205.413025,-0.002341,0.002420,0.061469,77.088646,3.927083,0.614690,-205.413025,0.062258,0.000000
43.010002,17.047211,-205.501999,-0.002298,0.002434,0.061833,75.829781,3.862953,0.618331,-205.501999,0.062691,0.000000
43.270000,16.567970,-205.457520,-0.002294,0.002446,0.062128,73.698013,3.754356,0.621283,-205.457520,0.063125,0.000000
43.530003,16.902359,-205.546478,-0.002276,0.002465,0.062605,75.185448,3.830129,0.626052,-205.546478,0.063559,0.000000
43.790001,17.118706,-205.546478,-0.002246,0.002484,0.063082,76.147804,3.879154,0.630821,-205.546478,0.063993,0.000000
44.050003,16.991730,-205.590958,-0.002238,0.002497,0.063429,75.582993,3.850381,0.634288,-205.590958,0.064426,0.000000
44.310001,16.715057,-205.635437,-0.002216,0.002507,0.063672,74.352287,3.787686,0.636718,-205.635437,0.064859,0.000000
44.570004,16.575043,-205.635437,-0.002216,0.002517,0.063923,73.729469,3.755958,0.639231,-205.635437,0.065293,0.000000
44.830002,17.930481,-205.724396,-0.002195,0.002553,0.064842,79.758766,4.063105,0.648421,-205.724396,0.065727,0.000000
45.090004,17.107536,-205.679916,-0.002156,0.002561,0.065042,76.098122,3.876623,0.650419,-205.679916,0.066161,0.000000
45.350002,17.532036,-205.679916,-0.002147,0.002582,0.065571,77.986389,3.972816,0.655710,-205.679916,0.066594,0.000000
45.610001,17.496666,-205.724396,-0.002126,0.002597,0.065953,77.829056,3.964801,0.659526,-205.724396,0.067027,0.000000
45.870003,17.750992,-205.768875,-0.002100,0.002616,0.066455,78.960358,4.022432,0.664552,-205.768875,0.067461,0.000000
46.130001,17.603539,-205.813354,-0.002082,0.002631,0.066837,78.304451,3.989019,0.668367,-205.813354,0.067895,0.000000
46.390003,17.474319,-205.768875,-0.002044,0.002645,0.067184,77.729652,3.959737,0.671842,-205.768875,0.068329,0.000000
46.650002,18.006073,-205.902328,-0.002039,0.002668,0.067774,80.095016,4.080235,0.677738,-205.902328,0.068762,0.000000
46.910004,18.033623,-205.857849,-0.001992,0.002684,0.068173,80.217560,4.086477,0.681728,-205.857849,0.069196,0.000000
47.170002,18.152786,-205.946808,-0.001992,0.002703,0.068650,80.747627,4.113480,0.686497,-205.946808,0.069629,0.000000
47.430004,18.054108,-205.946808,-0.001983,0.002719,0.069074,80.308685,4.091119,0.690743,-205.946808,0.070063,0.000000
47.690002,18.152412,-205.946808,-0.001970,0.002734,0.069438,80.745964,4.113396,0.694384,-205.946808,0.070497,0.000000
47.950001,17.884674,-206.080246,-0.001953,0.002745,0.069716,79.555000,4.052725,0.697163,-206.080246,0.070930,0.000000
48.210003,18.244019,-206.035767,-0.001923,0.002767,0.070289,81.153450,4.134154,0.702885,-206.035767,0.071364,0.000000
48.470001,18.815231,-206.035767,-0.001910,0.002789,0.070852,83.694328,4.263593,0.708525,-206.035767,0.071797,0.000000
48.730003,18.785820,-206.124725,-0.001888,0.002806,0.071260,83.563499,4.256927,0.712597,-206.124725,0.072231,0.000000
48.990002,18.967163,-206.080246,-0.001858,0.002825,0.071754,84.370155,4.298020,0.717540,-206.080246,0.072665,0.000000
49.250004,18.753792,-206.169205,-0.001824,0.002839,0.072118,83.421036,4.249670,0.721181,-206.169205,0.073098,0.000000
49.510002,18.537819,-206.169205,-0.001815,0.002851,0.072422,82.460335,4.200730,0.724217,-206.169205,0.073532,0.000000
49.770000,18.940353,-206.213684,-0.001789,0.002872,0.072960,84.250900,4.291945,0.729599,-206.213684,0.073966,0.000000
50.030003,19.040146,-206.302658,-0.001802,0.002887,0.073341,84.694801,4.314559,0.733414,-206.302658,0.074399,0.000000
50.290001,19.232666,-206.302658,-0.001772,0.002906,0.073809,85.551170,4.358184,0.738092,-206.302658,0.074833,0.000000
50.550003,19.906288,-206.391617,-0.001725,0.002930,0.074434,88.547592,4.510829,0.744337,-206.391617,0.075266,0.000000
50.810001,19.711906,-206.302658,-0.001716,0.002945,0.074815,87.682938,4.466782,0.748153,-206.302658,0.075700,0.000000
51.070004,19.411400,-206.347137,-0.001712,0.002959,0.075163,86.346222,4.398686,0.751627,-206.347137,0.076134,0.000000
51.330002,19.325012,-206.436096,-0.001669,0.002977,0.075605,85.961945,4.379110,0.756048,-206.436096,0.076559,0.000000
51.590004,19.980019,-206.436096,-0.001647,0.002998,0.076151,88.875565,4.527537,0.761513,-206.436096,0.076992,0.000000
51.850002,19.845215,-206.480576,-0.001621,0.003012,0.076515,88.275925,4.496990,0.765154,-206.480576,0.077426,0.000000
52.110001,20.108109,-206.525055,-0.001625,0.003029,0.076949,89.445335,4.556562,0.769492,-206.525055,0.077859,0.000000
52.370003,20.296906,-206.569534,-0.001595,0.003049,0.077452,90.285149,4.599344,0.774518,-206.569534,0.078293,0.000000
52.630001,20.350899,-206.614014,-0.001574,0.003065,0.077851,90.525322,4.611579,0.778507,-206.614014,0.078727,0.000000
52.890003,20.090981,-206.614014,-0.001544,0.003076,0.078137,89.369148,4.552681,0.781369,-206.614014,0.079160,0.000000
53.150002,20.159874,-206.658493,-0.001552,0.003092,0.078536,89.675598,4.568293,0.785358,-206.658493,0.079594,0.000000
53.410004,20.841316,-206.658493,-0.001522,0.003114,0.079108,92.706802,4.722710,0.791081,-206.658493,0.080028,0.000000
53.670002,21.066223,-206.747467,-0.001496,0.003132,0.079542,93.707237,4.773674,0.795418,-206.747467,0.080461,0.000000
53.930004,20.722900,-206.747467,-0.001492,0.003142,0.079802,92.180061,4.695877,0.798022,-206.747467,0.080895,0.000000
54.190002,20.726624,-206.702972,-0.001444,0.003156,0.080175,92.196625,4.696720,0.801747,-206.702972,0.081328,0.000000
54.450001,21.967369,-206.791946,-0.001444,0.003188,0.080982,97.715736,4.977877,0.809816,-206.791946,0.081762,0.000000
54.710003,21.503761,-206.836426,-0.001397,0.003200,0.081276,95.653511,4.872822,0.812761,-206.836426,0.082196,0.000000
54.970001,21.415138,-206.836426,-0.001388,0.003215,0.081667,95.259293,4.852740,0.816667,-206.836426,0.082630,0.000000
55.230003,21.332848,-206.925385,-0.001388,0.003229,0.082013,94.893242,4.834093,0.820134,-206.925385,0.083063,0.000000
55.490002,21.680267,-206.836426,-0.001350,0.003249,0.082525,96.438644,4.912819,0.825251,-206.836426,0.083496,0.000000
55.750004,21.784157,-206.969864,-0.001350,0.003263,0.082889,96.900772,4.936360,0.828892,-206.969864,0.083930,0.000000
56.010002,22.208290,-206.925385,-0.001315,0.003281,0.083340,98.787407,5.032471,0.833404,-206.925385,0.084364,0.000000
56.270004,22.829407,-206.969864,-0.001302,0.003306,0.083982,101.550270,5.173218,0.839823,-206.969864,0.084798,0.000000
56.530003,22.713974,-207.014343,-0.001272,0.003321,0.084355,101.036804,5.147060,0.843547,-207.014343,0.085231,0.000000
56.790001,22.070145,-207.014343,-0.001246,0.003328,0.084537,98.172905,5.001166,0.845371,-207.014343,0.085664,0.000000
57.050003,22.461876,-207.147797,-0.001224,0.003348,0.085040,99.915413,5.089934,0.850398,-207.147797,0.086098,0.000000
57.310001,22.945587,-207.147797,-0.001220,0.003368,0.085551,102.067070,5.199544,0.855515,-207.147797,0.086532,0.000000
57.570004,22.977242,-207.192276,-0.001194,0.003384,0.085950,102.207878,5.206717,0.859504,-207.192276,0.086966,0.000000
57.830002,23.068474,-207.236755,-0.001203,0.003399,0.086332,102.613693,5.227391,0.863319,-207.236755,0.087399,0.000000
58.090004,23.465050,-207.192276,-0.001164,0.003417,0.086792,104.377754,5.317256,0.867922,-207.192276,0.087832,0.000000
58.350002,24.175163,-207.281235,-0.001155,0.003441,0.087399,107.536499,5.478170,0.873993,-207.281235,0.088266,0.000000
58.610004,24.040367,-207.281235,-0.001112,0.003456,0.087781,106.936897,5.447625,0.877808,-207.281235,0.088700,0.000000
58.870003,23.774490,-207.325714,-0.001104,0.003470,0.088136,105.754211,5.387376,0.881358,-207.325714,0.089134,0.000000
59.130001,23.967010,-207.370193,-0.001056,0.003484,0.088500,106.610588,5.431002,0.884999,-207.370193,0.089567,0.000000
59.390003,24.683083,-207.370193,-0.001052,0.003506,0.089046,109.795837,5.593266,0.890465,-207.370193,0.090000,0.000000
59.650002,24.652176,-207.414673,-0.001043,0.003521,0.089437,109.658356,5.586263,0.894371,-207.414673,0.090434,0.000000
59.910004,24.479767,-207.325714,-0.001000,0.003535,0.089792,108.891441,5.547194,0.897921,-207.325714,0.090868,0.000000
60.170002,25.295631,-207.414673,-0.001000,0.003559,0.090399,112.520592,5.732072,0.903992,-207.414673,0.091302,0.000000
60.430004,25.558159,-207.503632,-0.000992,0.003576,0.090842,113.688370,5.791562,0.908420,-207.503632,0.091726,0.000000
60.690002,25.338455,-207.503632,-0.000949,0.003589,0.091171,112.711075,5.741776,0.911713,-207.503632,0.092160,0.000000
60.950005,25.545494,-207.592606,-0.000949,0.003608,0.091640,113.632034,5.788692,0.916399,-207.592606,0.092594,0.000000
61.210003,25.910423,-207.548111,-0.000940,0.003624,0.092039,115.255318,5.871386,0.920388,-207.548111,0.093027,0.000000
61.470001,26.033302,-207.592606,-0.000905,0.003640,0.092446,115.801910,5.899230,0.924461,-207.592606,0.093461,0.000000
61.730003,26.206085,-207.637085,-0.000892,0.003653,0.092775,116.570488,5.938384,0.927753,-207.637085,0.093894,0.000000
61.990002,26.995140,-207.637085,-0.000862,0.003678,0.093409,120.080383,6.117186,0.934089,-207.637085,0.094328,0.000000
62.250004,27.792015,-207.681564,-0.000858,0.003700,0.093990,123.625061,6.297760,0.939895,-207.681564,0.094762,0.000000
62.510002,27.284843,-207.681564,-0.000819,0.003710,0.094224,121.369041,6.182834,0.942242,-207.681564,0.095195,0.000000
62.770004,27.552956,-207.770523,-0.000780,0.003729,0.094719,122.561668,6.243589,0.947185,-207.770523,0.095629,0.000000
63.030003,27.657967,-207.770523,-0.000789,0.003742,0.095039,123.028778,6.267385,0.950395,-207.770523,0.096062,0.000000
63.290005,28.355789,-207.815002,-0.000763,0.003763,0.095568,126.132851,6.425514,0.955678,-207.815002,0.096496,0.000000
63.550003,28.437340,-207.903961,-0.000746,0.003777,0.095933,126.495605,6.443994,0.959327,-207.903961,0.096930,0.000000
63.810001,28.085823,-207.903961,-0.000755,0.003782,0.096071,124.931984,6.364338,0.960712,-207.903961,0.097363,0.000000
64.070000,30.121582,-207.903961,-0.000733,0.003819,0.096990,133.987488,6.825648,0.969902,-207.903961,0.097797,0.000000
64.330002,30.349472,-207.948441,-0.000690,0.003833,0.097354,135.001190,6.877289,0.973543,-207.948441,0.098231,0.000000
64.590004,29.952522,-207.903961,-0.000686,0.003844,0.097641,133.235474,6.787338,0.976412,-207.903961,0.098664,0.000000
64.850006,30.658165,-208.037415,-0.000651,0.003863,0.098126,136.374329,6.947239,0.981264,-208.037415,0.099098,0.000000
65.110001,31.103523,-207.992920,-0.000651,0.003882,0.098603,138.355377,7.048159,0.986033,-207.992920,0.099531,0.000000
65.370003,31.413338,-208.081894,-0.000625,0.003896,0.098967,139.733505,7.118364,0.989674,-208.081894,0.099965,0.000000
65.630005,31.382431,-208.126373,-0.000604,0.003907,0.099237,139.596024,7.111361,0.992369,-208.126373,0.100399,0.000000
65.889999,31.293434,-208.126373,-0.000582,0.003915,0.099444,139.200150,7.091193,0.994443,-208.126373,0.100832,0.000000
66.150002,33.407394,-208.215332,-0.000608,0.003951,0.100347,148.603516,7.570224,1.003466,-208.215332,0.101266,0.000000
66.410004,33.597305,-208.126373,-0.000552,0.003964,0.100693,149.448273,7.613258,1.006933,-208.126373,0.101699,0.000000
66.670006,33.962975,-208.259811,-0.000535,0.003981,0.101127,151.074860,7.696120,1.011271,-208.259811,0.102133,0.000000
66.930000,34.387108,-208.259811,-0.000539,0.003999,0.101578,152.961502,7.792230,1.015783,-208.259811,0.102567,0.000000
67.190002,35.175049,-208.259811,-0.000509,0.004015,0.101986,156.466431,7.970780,1.019855,-208.259811,0.103001,0.000000
67.450005,35.527679,-208.304291,-0.000483,0.004031,0.102394,158.035004,8.050687,1.023935,-208.304291,0.103434,0.000000
67.710007,35.774940,-208.259811,-0.000492,0.004044,0.102705,159.134888,8.106717,1.027054,-208.259811,0.103867,0.000000
67.970001,36.859283,-208.348770,-0.000461,0.004068,0.103330,163.958282,8.352433,1.033299,-208.348770,0.104301,0.000000
68.230003,37.569031,-208.437744,-0.000474,0.004083,0.103720,167.115402,8.513264,1.037197,-208.437744,0.104735,0.000000
68.490005,38.251587,-208.393250,-0.000466,0.004102,0.104188,170.151550,8.667933,1.041883,-208.393250,0.105169,0.000000
68.750000,38.780357,-208.482224,-0.000431,0.004118,0.104596,172.503647,8.787754,1.045963,-208.482224,0.105602,0.000000
69.010002,39.386581,-208.437744,-0.000414,0.004133,0.104978,175.200272,8.925127,1.049778,-208.437744,0.106035,0.000000
69.270004,39.675171,-208.526703,-0.000410,0.004147,0.105342,176.483978,8.990522,1.053420,-208.526703,0.106461,0.000000
69.530006,40.740524,-208.526703,-0.000388,0.004164,0.105767,181.222900,9.231935,1.057666,-208.526703,0.106895,0.000000
69.790001,41.090179,-208.571182,-0.000366,0.004181,0.106200,182.778244,9.311168,1.062004,-208.571182,0.107328,0.000000
70.050003,42.785965,-208.615662,-0.000375,0.004204,0.106782,190.321472,9.695438,1.067817,-208.615662,0.107761,0.000000
70.310005,43.567574,-208.526703,-0.000371,0.004222,0.107241,193.798248,9.872553,1.072412,-208.526703,0.108195,0.000000
70.570000,44.253487,-208.615662,-0.000336,0.004237,0.107623,196.849335,10.027984,1.076227,-208.615662,0.108629,0.000000
70.830002,44.680595,-208.704620,-0.000319,0.004249,0.107935,198.749222,10.124767,1.079346,-208.704620,0.109063,0.000000
71.090004,45.747070,-208.704620,-0.000332,0.004268,0.108411,203.493134,10.366434,1.084115,-208.704620,0.109495,0.000000
71.350006,46.352554,-208.749100,-0.000349,0.004285,0.108837,206.186462,10.503639,1.088369,-208.749100,0.109929,0.000000
71.610001,47.229118,-208.793579,-0.000293,0.004302,0.109262,210.085617,10.702271,1.092616,-208.793579,0.110363,0.000000
71.870003,48.701477,-208.838058,-0.000297,0.004326,0.109869,216.634995,11.035913,1.098687,-208.838058,0.110797,0.000000
72.130005,49.938499,-208.882553,-0.000276,0.004343,0.110302,222.137543,11.316226,1.103024,-208.882553,0.111230,0.000000
72.390007,50.507858,-208.838058,-0.000254,0.004357,0.110658,224.670181,11.445245,1.106582,-208.838058,0.111664,0.000000
72.650002,51.036995,-208.882553,-0.000229,0.004369,0.110978,227.023895,11.565148,1.109784,-208.882553,0.112097,0.000000
72.910004,52.670967,-208.882553,-0.000246,0.004395,0.111638,234.292160,11.935411,1.116377,-208.882553,0.112531,0.000000
73.170006,53.638016,-208.971512,-0.000254,0.004411,0.112046,238.593811,12.154549,1.120458,-208.971512,0.112965,0.000000
73.430000,54.440109,-208.927032,-0.000237,0.004427,0.112453,242.161697,12.336306,1.124530,-208.927032,0.113398,0.000000
73.690002,55.772827,-209.015991,-0.000233,0.004447,0.112947,248.089920,12.638303,1.129473,-209.015991,0.113832,0.000000
73.950005,56.780098,-209.104950,-0.000207,0.004463,0.113364,252.570496,12.866554,1.133637,-209.104950,0.114265,0.000000
74.210007,57.231041,-209.104950,-0.000229,0.004474,0.113650,254.576385,12.968740,1.136498,-209.104950,0.114699,0.000000
74.470001,58.195854,-209.104950,-0.000190,0.004490,0.114058,258.868103,13.187369,1.140578,-209.104950,0.115133,0.000000
74.730003,59.084335,-209.104950,-0.000177,0.004510,0.114552,262.820251,13.388702,1.145521,-209.104950,0.115566,0.000000
74.990005,60.876190,-209.149429,-0.000164,0.004529,0.115037,270.790833,13.794743,1.150373,-209.149429,0.116000,0.000000
75.250000,61.523750,-209.238388,-0.000190,0.004540,0.115306,273.671295,13.941481,1.153061,-209.238388,0.116434,0.000000
75.510002,62.326210,-209.193909,-0.000181,0.004553,0.115653,277.240814,14.123321,1.156528,-209.193909,0.116867,0.000000
75.770004,65.162941,-209.282867,-0.000164,0.004585,0.116468,289.859253,14.766133,1.164680,-209.282867,0.117301,0.000000
76.030006,65.762840,-209.282867,-0.000155,0.004597,0.116763,292.527710,14.902072,1.167633,-209.282867,0.117734,0.000000
76.290001,66.677391,-209.327362,-0.000134,0.004613,0.117162,296.595856,15.109312,1.171622,-209.327362,0.118168,0.000000
76.550003,67.439262,-209.416321,-0.000155,0.004616,0.117240,299.984833,15.281955,1.172402,-209.416321,0.117466,0.000000
76.810005,66.846443,-209.327362,-0.000134,0.004616,0.117240,297.347839,15.147621,1.172402,-209.327362,0.117466,0.000000
77.070007,66.420082,-209.416321,-0.000095,0.004614,0.117197,295.451294,15.051005,1.171970,-209.416321,0.117240,0.000000
77.330002,65.991096,-209.460800,-0.000134,0.004614,0.117188,293.543060,14.953795,1.171879,-209.460800,0.117240,0.000000
77.590004,65.648521,-209.505280,-0.000108,0.004613,0.117180,292.019196,14.876167,1.171796,-209.505280,0.117240,0.000000
77.850006,65.312645,-209.505280,-0.000112,0.004613,0.117171,290.525146,14.800056,1.171705,-209.505280,0.117240,0.000000
78.110001,65.047508,-209.505280,-0.000112,0.004613,0.117171,289.345764,14.739976,1.171705,-209.505280,0.117240,0.000000
78.370003,64.790199,-209.594238,-0.000095,0.004613,0.117171,288.201202,14.681668,1.171705,-209.594238,0.117240,0.000000
78.630005,64.581306,-209.594238,-0.000112,0.004613,0.117171,287.272003,14.634334,1.171705,-209.594238,0.117240,0.000000
78.890007,64.383949,-209.638718,-0.000112,0.004613,0.117171,286.394104,14.589612,1.171705,-209.638718,0.117240,0.000000
79.150002,64.178764,-209.683197,-0.000125,0.004613,0.117171,285.481415,14.543116,1.171705,-209.683197,0.117240,0.000000
79.410004,64.039131,-209.727692,-0.000108,0.004613,0.117171,284.860291,14.511475,1.171705,-209.727692,0.117240,0.000000
79.670006,63.874168,-209.727692,-0.000103,0.004613,0.117171,284.126495,14.474093,1.171705,-209.727692,0.117240,0.000000
79.930000,63.723732,-209.772171,-0.000103,0.004613,0.117171,283.457306,14.440003,1.171705,-209.772171,0.117240,0.000000
80.190002,63.609413,-209.772171,-0.000091,0.004613,0.117171,282.948792,14.414099,1.171705,-209.772171,0.117240,0.000000
80.450005,63.471260,-209.861130,-0.000108,0.004613,0.117162,282.334259,14.382792,1.171622,-209.861130,0.117240,0.000000
80.710007,63.359550,-209.772171,-0.000078,0.004613,0.117162,281.837341,14.357479,1.171622,-209.772171,0.117240,0.000000
80.970001,63.259003,-209.861130,-0.000086,0.004613,0.117162,281.390106,14.334696,1.171622,-209.861130,0.117240,0.000000
81.230003,63.161072,-209.950089,-0.000078,0.004613,0.117162,280.954468,14.312503,1.171622,-209.950089,0.117240,0.000000
81.490005,63.067230,-209.950089,-0.000073,0.004613,0.117162,280.537048,14.291239,1.171622,-209.950089,0.117240,0.000000
81.750008,62.953285,-209.994568,-0.000099,0.004613,0.117162,280.030212,14.265418,1.171622,-209.994568,0.117240,0.000000
82.010002,62.880676,-209.950089,-0.000103,0.004613,0.117162,279.707214,14.248965,1.171622,-209.950089,0.117240,0.000000
82.270004,62.808060,-210.039047,-0.000121,0.004613,0.117162,279.384216,14.232510,1.171622,-210.039047,0.117240,0.000000
82.530006,62.701195,-210.039047,-0.000091,0.004613,0.117162,278.908844,14.208294,1.171622,-210.039047,0.117240,0.000000
82.790001,62.662834,-210.083527,-0.000086,0.004613,0.117162,278.738220,14.199601,1.171622,-210.083527,0.117240,0.000000
83.050003,62.586876,-210.128006,-0.000108,0.004613,0.117162,278.400330,14.182388,1.171622,-210.128006,0.117240,0.000000
83.310005,62.499741,-210.128006,-0.000086,0.004613,0.117162,278.012726,14.162644,1.171622,-210.128006,0.117240,0.000000
83.570007,62.443512,-210.172501,-0.000086,0.004613,0.117162,277.762604,14.149902,1.171622,-210.172501,0.117240,0.000000
83.830002,62.380577,-210.172501,-0.000108,0.004613,0.117162,277.482666,14.135641,1.171622,-210.172501,0.117240,0.000000
84.090004,62.309456,-210.261459,-0.000095,0.004613,0.117162,277.166290,14.119524,1.171622,-210.261459,0.117240,0.000000
84.350006,62.253227,-210.305939,-0.000091,0.004613,0.117162,276.916199,14.106783,1.171622,-210.305939,0.117240,0.000000
84.610001,62.212639,-210.216980,-0.000082,0.004613,0.117162,276.735626,14.097586,1.171622,-210.216980,0.117240,0.000000
84.870003,62.148216,-210.305939,-0.000086,0.004613,0.117162,276.449066,14.082987,1.171622,-210.305939,0.117240,0.000000
85.130005,62.091988,-210.350418,-0.000095,0.004613,0.117162,276.198944,14.070246,1.171622,-210.350418,0.117240,0.000000
85.390007,62.046188,-210.394897,-0.000082,0.004613,0.117162,275.995239,14.059867,1.171622,-210.394897,0.117240,0.000000
85.650002,61.997780,-210.439377,-0.000082,0.004613,0.117162,275.779907,14.048898,1.171622,-210.439377,0.117240,0.000000
85.910004,61.946396,-210.439377,-0.000082,0.004613,0.117162,275.551331,14.037253,1.171622,-210.439377,0.117240,0.000000
86.170006,61.895752,-210.483856,-0.000073,0.004613,0.117162,275.326050,14.025778,1.171622,-210.483856,0.117240,0.000000
86.430000,61.858513,-210.528336,-0.000121,0.004613,0.117162,275.160400,14.017340,1.171622,-210.528336,0.117240,0.000000
86.690002,61.816063,-210.528336,-0.000082,0.004613,0.117162,274.971588,14.007720,1.171622,-210.528336,0.117240,0.000000
86.950005,61.768768,-210.528336,-0.000069,0.004613,0.117162,274.761200,13.997003,1.171622,-210.528336,0.117240,0.000000
87.210007,61.727066,-210.528336,-0.000082,0.004613,0.117162,274.575714,13.987554,1.171622,-210.528336,0.117240,0.000000
87.470001,61.676796,-210.661789,-0.000095,0.004613,0.117162,274.352081,13.976162,1.171622,-210.661789,0.117240,0.000000
87.730003,61.643654,-210.617310,-0.000086,0.004613,0.117162,274.204681,13.968652,1.171622,-210.617310,0.117240,0.000000
87.990005,61.623917,-210.661789,-0.000069,0.004613,0.117162,274.116882,13.964179,1.171622,-210.661789,0.117240,0.000000
88.250008,61.563225,-210.706268,-0.000082,0.004613,0.117162,273.846893,13.950426,1.171622,-210.706268,0.117240,0.000000
88.510002,61.536407,-210.706268,-0.000091,0.004613,0.117162,273.727600,13.944349,1.171622,-210.706268,0.117240,0.000000
88.770004,61.499542,-210.750748,-0.000073,0.004613,0.117162,273.563629,13.935995,1.171622,-210.750748,0.117240,0.000000
89.030006,61.467148,-210.795227,-0.000086,0.004613,0.117162,273.419525,13.928656,1.171622,-210.795227,0.117240,0.000000
89.290001,61.431770,-210.884186,-0.000073,0.004613,0.117162,273.262177,13.920638,1.171622,-210.884186,0.117240,0.000000
89.550003,61.397888,-210.928665,-0.000086,0.004613,0.117162,273.111450,13.912960,1.171622,-210.928665,0.117240,0.000000
89.810005,61.363258,-210.839706,-0.000069,0.004613,0.117162,272.957397,13.905113,1.171622,-210.839706,0.117240,0.000000
90.070007,61.338684,-210.928665,-0.000091,0.004613,0.117162,272.848083,13.899544,1.171622,-210.928665,0.117240,0.000000
90.330002,61.307030,-210.928665,-0.000095,0.004613,0.117162,272.707275,13.892371,1.171622,-210.928665,0.117240,0.000000
90.590004,61.274635,-211.062119,-0.000099,0.004613,0.117162,272.563202,13.885031,1.171622,-211.062119,0.117240,0.000000
90.850006,61.244095,-211.062119,-0.000091,0.004613,0.117162,272.427338,13.878110,1.171622,-211.062119,0.117240,0.000000
91.110001,61.210213,-210.973145,-0.000086,0.004613,0.117162,272.276611,13.870433,1.171622,-210.973145,0.117240,0.000000
91.370003,61.184517,-211.106598,-0.000082,0.004613,0.117162,272.162323,13.864610,1.171622,-211.106598,0.117240,0.000000
91.630005,61.151001,-211.106598,-0.000073,0.004613,0.117162,272.013245,13.857015,1.171622,-211.106598,0.117240,0.000000
91.890007,61.128288,-211.106598,-0.000060,0.004613,0.117162,271.912201,13.851868,1.171622,-211.106598,0.117240,0.000000
92.150002,61.103714,-211.195557,-0.000099,0.004613,0.117162,271.802887,13.846299,1.171622,-211.195557,0.117240,0.000000
92.410004,61.073555,-211.240036,-0.000086,0.004613,0.117162,271.668732,13.839465,1.171622,-211.240036,0.117240,0.000000
92.670006,61.059776,-211.240036,-0.000069,0.004613,0.117162,271.607452,13.836343,1.171622,-211.240036,0.117240,0.000000
92.930008,61.028870,-211.195557,-0.000095,0.004613,0.117162,271.469971,13.829340,1.171622,-211.195557,0.117240,0.000000
93.190002,60.990509,-211.284515,-0.000073,0.004613,0.117162,271.299347,13.820646,1.171622,-211.284515,0.117240,0.000000
93.450005,60.985298,-211.373474,-0.000099,0.004613,0.117162,271.276154,13.819467,1.171622,-211.373474,0.117240,0.000000
93.710007,60.955139,-211.284515,-0.000086,0.004613,0.117162,271.141998,13.812632,1.171622,-211.284515,0.117240,0.000000
93.970001,60.924232,-211.417953,-0.000078,0.004613,0.117162,271.004517,13.805628,1.171622,-211.417953,0.117240,0.000000
94.230003,60.905235,-211.417953,-0.000082,0.004613,0.117162,270.920013,13.801323,1.171622,-211.417953,0.117240,0.000000
94.490005,60.874329,-211.417953,-0.000082,0.004613,0.117162,270.782532,13.794320,1.171622,-211.417953,0.117240,0.000000
94.750008,60.863533,-211.506927,-0.000091,0.004613,0.117162,270.734528,13.791873,1.171622,-211.506927,0.117240,0.000000
95.010002,60.840820,-211.462448,-0.000069,0.004613,0.117162,270.633484,13.786727,1.171622,-211.462448,0.117240,0.000000
95.270004,60.815125,-211.551407,-0.000086,0.004613,0.117162,270.519196,13.780904,1.171622,-211.551407,0.117240,0.000000
95.530006,60.790550,-211.506927,-0.000091,0.004613,0.117162,270.409882,13.775335,1.171622,-211.506927,0.117240,0.000000
95.790001,60.769325,-211.551407,-0.000069,0.004613,0.117162,270.315460,13.770527,1.171622,-211.551407,0.117240,0.000000
96.050003,60.753685,-211.595886,-0.000086,0.004613,0.117162,270.245880,13.766982,1.171622,-211.595886,0.117240,0.000000
96.310005,60.731712,-211.595886,-0.000073,0.004613,0.117162,270.148163,13.762003,1.171622,-211.595886,0.117240,0.000000
96.570007,60.727615,-211.684845,-0.000095,0.004613,0.117162,270.129913,13.761074,1.171622,-211.684845,0.117240,0.000000
96.830002,60.702667,-211.684845,-0.000069,0.004613,0.117162,270.018951,13.755421,1.171622,-211.684845,0.117240,0.000000
97.090004,60.673622,-211.729324,-0.000060,0.004613,0.117162,269.889740,13.748839,1.171622,-211.729324,0.117240,0.000000
97.350006,60.670647,-211.729324,-0.000086,0.004613,0.117162,269.876526,13.748165,1.171622,-211.729324,0.117240,0.000000
97.610008,60.636383,-211.729324,-0.000047,0.004613,0.117162,269.724091,13.740400,1.171622,-211.729324,0.117240,0.000000
97.870003,60.603241,-211.818283,-0.000069,0.004613,0.117162,269.576691,13.732891,1.171622,-211.818283,0.117240,0.000000
98.130005,60.599892,-211.818283,-0.000069,0.004613,0.117162,269.561768,13.732132,1.171622,-211.818283,0.117240,0.000000
98.390007,60.580902,-211.907257,-0.000069,0.004613,0.117162,269.477325,13.727829,1.171622,-211.907257,0.117240,0.000000
98.650002,60.558929,-211.907257,-0.000078,0.004613,0.117162,269.379578,13.722850,1.171622,-211.907257,0.117240,0.000000
98.910004,60.545525,-211.907257,-0.000082,0.004613,0.117162,269.319946,13.719811,1.171622,-211.907257,0.117240,0.000000
99.170006,60.526161,-211.951736,-0.000082,0.004613,0.117162,269.233826,13.715425,1.171622,-211.951736,0.117240,0.000000
99.430008,60.494881,-211.951736,-0.000073,0.004613,0.117162,269.094666,13.708336,1.171622,-211.951736,0.117240,0.000000
99.690002,60.495255,-211.996216,-0.000073,0.004613,0.117162,269.096344,13.708421,1.171622,-211.996216,0.117240,0.000000
99.950005,60.460999,-212.085175,-0.000099,0.004613,0.117162,268.943939,13.700658,1.171622,-212.085175,0.117240,0.000000
100.210007,60.444244,-212.040695,-0.000073,0.004613,0.117162,268.869415,13.696861,1.171622,-212.040695,0.117240,0.000000
100.470001,60.436798,-212.129654,-0.000086,0.004613,0.117162,268.836304,13.695174,1.171622,-212.129654,0.117240,0.000000
100.730003,60.419662,-212.040695,-0.000091,0.004613,0.117162,268.760071,13.691291,1.171622,-212.040695,0.117240,0.000000
100.990005,60.397324,-212.129654,-0.000060,0.004613,0.117162,268.660706,13.686229,1.171622,-212.129654,0.117240,0.000000
101.250008,60.375725,-212.218613,-0.000073,0.004613,0.117162,268.564636,13.681334,1.171622,-212.218613,0.117240,0.000000
101.510002,60.373116,-212.218613,-0.000078,0.004613,0.117162,268.553040,13.680744,1.171622,-212.218613,0.117240,0.000000
101.770004,60.344444,-212.307587,-0.000065,0.004613,0.117162,268.425507,13.674246,1.171622,-212.307587,0.117240,0.000000
102.030006,60.332161,-212.263092,-0.000073,0.004613,0.117162,268.370850,13.671463,1.171622,-212.263092,0.117240,0.000000
102.290009,60.320984,-212.307587,-0.000078,0.004613,0.117162,268.321136,13.668930,1.171622,-212.307587,0.117240,0.000000
102.550003,60.304604,-212.396545,-0.000086,0.004613,0.117162,268.248260,13.665218,1.171622,-212.396545,0.117240,0.000000
102.810005,60.291199,-212.307587,-0.000078,0.004613,0.117162,268.188660,13.662181,1.171622,-212.307587,0.117240,0.000000
103.070007,60.273697,-212.485504,-0.000069,0.004613,0.117162,268.110809,13.658215,1.171622,-212.485504,0.117240,0.000000
103.330002,60.263268,-212.396545,-0.000086,0.004613,0.117162,268.064392,13.655851,1.171622,-212.396545,0.117240,0.000000
103.590004,60.245766,-212.485504,-0.000060,0.004613,0.117162,267.986542,13.651885,1.171622,-212.485504,0.117240,0.000000
103.850006,60.239433,-212.396545,-0.000060,0.004613,0.117162,267.958374,13.650451,1.171622,-212.396545,0.117240,0.000000
104.110008,60.215981,-212.485504,-0.000082,0.004613,0.117162,267.854065,13.645136,1.171622,-212.485504,0.117240,0.000000
104.370003,60.202576,-212.574463,-0.000095,0.004613,0.117162,267.794434,13.642098,1.171622,-212.574463,0.117240,0.000000
104.630005,60.198105,-212.529984,-0.000073,0.004613,0.117162,267.774536,13.641086,1.171622,-212.529984,0.117240,0.000000
104.890007,60.163101,-212.663422,-0.000069,0.004613,0.117162,267.618835,13.633154,1.171622,-212.663422,0.117240,0.000000
105.150002,60.165337,-212.663422,-0.000091,0.004613,0.117162,267.628784,13.633660,1.171622,-212.663422,0.117240,0.000000
105.410004,60.140755,-212.618942,-0.000086,0.004613,0.117162,267.519440,13.628090,1.171622,-212.618942,0.117240,0.000000
105.670006,60.130707,-212.752396,-0.000078,0.004613,0.117162,267.474731,13.625813,1.171622,-212.752396,0.117240,0.000000
105.930008,60.122513,-212.663422,-0.000082,0.004613,0.117162,267.438293,13.623957,1.171622,-212.663422,0.117240,0.000000
106.190002,60.098679,-212.796875,-0.000065,0.004613,0.117162,267.332275,13.618556,1.171622,-212.796875,0.117240,0.000000
106.450005,60.080063,-212.796875,-0.000065,0.004613,0.117162,267.249481,13.614337,1.171622,-212.796875,0.117240,0.000000
106.710007,60.079689,-212.796875,-0.000078,0.004613,0.117162,267.247803,13.614252,1.171622,-212.796875,0.117240,0.000000
106.900002,60.064049,-212.796875,-0.000099,0.004613,0.117162,267.178223,13.610708,1.171622,-212.796875,0.117240,0.000000