File: Data/compression 13/AutoNoHeating-15-13-2-240724_07242024_165801.csv
Time (sec),S:Load (lbs),S:HL1 (DIM),S:LVDT (in),S:Position (in),Ch:Position (mm),Ch:Load (N),Ch:Stress (MPa),Ch:Strain (mm/mm),Ch:HL1 (DIM),Set Point (),Cycles ()
0.010000,-0.006332,-352.200165,-0.010145,-0.005604,-0.142337,-0.028168,-0.001435,-1.423374,-352.200165,-0.142129,0.000000
0.250000,-0.023460,-352.200165,-0.010141,-0.005604,-0.142337,-0.104357,-0.005316,-1.423374,-352.200165,-0.142129,0.000000
0.490000,-0.029045,-352.289124,-0.010141,-0.005504,-0.139814,-0.129199,-0.006582,-1.398136,-352.289124,-0.139215,0.000000
0.730000,-0.020103,-352.200165,-0.010067,-0.005366,-0.136302,-0.089425,-0.004556,-1.363016,-352.200165,-0.135226,0.000000
0.970000,-0.029419,-352.333618,-0.009908,-0.005215,-0.132468,-0.130862,-0.006666,-1.324683,-352.333618,-0.131220,0.000000
1.210000,0.006332,-352.289124,-0.009744,-0.005053,-0.128349,0.028168,0.001435,-1.283492,-352.289124,-0.127230,0.000000
1.450000,0.017876,-352.244659,-0.009593,-0.004910,-0.124707,0.079515,0.004051,-1.247066,-352.244659,-0.123224,0.000000
1.690000,0.004097,-352.378082,-0.009425,-0.004733,-0.120223,0.018224,0.000928,-1.202230,-352.378082,-0.119234,0.000000
1.930000,-0.019363,-352.289124,-0.009248,-0.004587,-0.116503,-0.086133,-0.004388,-1.165029,-352.289124,-0.115228,0.000000
2.170000,-0.014893,-352.378082,-0.009076,-0.004424,-0.112366,-0.066245,-0.003375,-1.123660,-352.378082,-0.111239,0.000000
2.410000,-0.005585,-352.333618,-0.008916,-0.004273,-0.108542,-0.024842,-0.001266,-1.085417,-352.333618,-0.107232,0.000000
2.650000,-0.018990,-352.378082,-0.008739,-0.004099,-0.104110,-0.084470,-0.004303,-1.041100,-352.378082,-0.103243,0.000000
2.890000,-0.005959,-352.422577,-0.008619,-0.003954,-0.100424,-0.026505,-0.001350,-1.004242,-352.422577,-0.099236,0.000000
3.130000,-0.005211,-352.378082,-0.008455,-0.003794,-0.096357,-0.023179,-0.001181,-0.963574,-352.378082,-0.095229,0.000000
3.370000,0.026070,-352.422577,-0.008269,-0.003643,-0.092541,0.115964,0.005907,-0.925414,-352.422577,-0.091240,0.000000
3.610000,0.007446,-352.422577,-0.008088,-0.003483,-0.088465,0.033123,0.001687,-0.884651,-352.422577,-0.087233,0.000000
3.850000,-0.026810,-352.422577,-0.007950,-0.003322,-0.084372,-0.119255,-0.006075,-0.843721,-352.422577,-0.083245,0.000000
4.090000,-0.020477,-352.511536,-0.007765,-0.003169,-0.080496,-0.091088,-0.004640,-0.804956,-352.511536,-0.079238,0.000000
4.330000,-0.001488,-352.467041,-0.007610,-0.003005,-0.076333,-0.006618,-0.000337,-0.763330,-352.467041,-0.075249,0.000000
4.570000,-0.030159,-352.511536,-0.007437,-0.002842,-0.072179,-0.134154,-0.006834,-0.721787,-352.511536,-0.071242,0.000000
4.810000,-0.051010,-352.511536,-0.007282,-0.002691,-0.068345,-0.226904,-0.011559,-0.683454,-352.511536,-0.067253,0.000000
5.050000,-0.007072,-352.511536,-0.007097,-0.002537,-0.064435,-0.031460,-0.001603,-0.644348,-352.511536,-0.063246,0.000000
5.290000,0.009308,-352.556030,-0.006959,-0.002378,-0.060411,0.041403,0.002109,-0.604107,-352.556030,-0.059257,0.000000
5.530000,0.039101,-352.556030,-0.006808,-0.002227,-0.056577,0.173928,0.008860,-0.565774,-352.556030,-0.055250,0.000000
5.770000,0.015640,-352.644989,-0.006618,-0.002061,-0.052354,0.069571,0.003544,-0.523542,-352.644989,-0.051261,0.000000
6.010000,-0.006332,-352.600494,-0.006459,-0.001907,-0.048425,-0.028168,-0.001435,-0.484255,-352.600494,-0.047254,0.000000
6.250000,0.003349,-352.644989,-0.006282,-0.001756,-0.044592,0.014898,0.000759,-0.445921,-352.644989,-0.043266,0.000000
6.490000,-0.018616,-352.644989,-0.006118,-0.001586,-0.040283,-0.082807,-0.004218,-0.402826,-352.644989,-0.039259,0.000000
6.730000,0.002235,-352.644989,-0.005959,-0.001430,-0.036310,0.009944,0.000507,-0.363100,-352.644989,-0.035270,0.000000
6.970000,-0.026436,-352.778412,-0.005812,-0.001278,-0.032468,-0.117593,-0.005990,-0.324683,-352.778412,-0.031263,0.000000
7.210001,0.011169,-352.644989,-0.005648,-0.001113,-0.028271,0.049684,0.002531,-0.282709,-352.644989,-0.027274,0.000000
7.450000,0.034630,-352.689453,-0.005484,-0.000967,-0.024569,0.154041,0.007847,-0.245685,-352.689453,-0.023267,0.000000
7.690001,0.044312,-352.689453,-0.005312,-0.000801,-0.020345,0.197107,0.010041,-0.203446,-352.689453,-0.019261,0.000000
7.930000,0.021973,-352.689453,-0.005174,-0.000648,-0.016468,0.097739,0.004979,-0.164681,-352.689453,-0.015271,0.000000
8.170000,0.033516,-352.778412,-0.004980,-0.000490,-0.012436,0.149086,0.007595,-0.124357,-352.778412,-0.011265,0.000000
8.410001,0.157516,-352.689453,-0.004846,-0.000339,-0.008620,0.700668,0.035694,-0.086197,-352.689453,-0.007275,0.000000
8.650001,0.739159,-352.822906,-0.004695,-0.000001,-0.000017,3.287942,0.167496,-0.000174,-352.822906,0.000148,0.000000
8.890000,0.692986,-352.822906,-0.004721,-0.000001,-0.000026,3.082554,0.157033,-0.000257,-352.822906,0.000148,0.000000
9.130000,0.705276,-352.778412,-0.004700,-0.000001,-0.000026,3.137227,0.159818,-0.000257,-352.778412,0.000243,0.000000
9.370001,0.650162,-352.822906,-0.004704,-0.000001,-0.000026,2.892064,0.147329,-0.000257,-352.822906,0.000642,0.000000
9.610001,0.621490,-352.822906,-0.004725,-0.000001,-0.000026,2.764528,0.140832,-0.000257,-352.822906,0.001041,0.000000
9.850000,0.792412,-352.867371,-0.004725,0.000022,0.000555,3.524824,0.179563,0.005549,-352.867371,0.001440,0.000000
10.090000,1.047485,-352.867371,-0.004700,0.000041,0.001032,4.659448,0.237364,0.010318,-352.867371,0.001839,0.000000
10.330001,1.208725,-352.867371,-0.004682,0.000057,0.001440,5.376677,0.273901,0.014398,-352.867371,0.002238,0.000000
10.570001,1.350227,-352.867371,-0.004648,0.000068,0.001726,6.006111,0.305966,0.017259,-352.867371,0.002637,0.000000
10.810000,1.495445,-352.911865,-0.004652,0.000080,0.002020,6.652073,0.338873,0.020204,-352.911865,0.003044,0.000000
11.050000,1.685356,-353.000824,-0.004656,0.000094,0.002394,7.496839,0.381907,0.023936,-353.000824,0.003443,0.000000
11.290001,1.906548,-352.911865,-0.004639,0.000112,0.002853,8.480747,0.432030,0.028531,-352.911865,0.003842,0.000000
11.530001,2.256577,-352.956360,-0.004596,0.000131,0.003330,10.037754,0.511348,0.033300,-352.956360,0.004241,0.000000
11.770000,2.337379,-353.000824,-0.004609,0.000139,0.003521,10.397183,0.529658,0.035207,-353.000824,0.004640,0.000000
12.010000,2.811417,-353.000824,-0.004609,0.000162,0.004119,12.505806,0.637076,0.041195,-353.000824,0.005038,0.000000
12.250001,3.109680,-353.000824,-0.004579,0.000183,0.004657,13.832548,0.704664,0.046569,-353.000824,0.005437,0.000000
12.490001,3.372581,-353.045319,-0.004536,0.000197,0.005013,15.001991,0.764238,0.050127,-353.045319,0.005836,0.000000
12.730000,3.508492,-353.089783,-0.004570,0.000206,0.005238,15.606549,0.795036,0.052383,-353.089783,0.006244,0.000000
12.970000,4.015663,-353.045319,-0.004540,0.000226,0.005750,17.862562,0.909962,0.057500,-353.045319,0.006643,0.000000
13.210001,4.039497,-353.089783,-0.004514,0.000234,0.005949,17.968582,0.915363,0.059491,-353.089783,0.007042,0.000000
13.450001,4.585770,-353.178741,-0.004497,0.000256,0.006513,20.398521,1.039150,0.065130,-353.178741,0.007441,0.000000
13.690001,4.754456,-353.089783,-0.004467,0.000267,0.006790,21.148874,1.077375,0.067901,-353.089783,0.007840,0.000000
13.930000,4.999474,-353.134277,-0.004484,0.000280,0.007103,22.238770,1.132897,0.071027,-353.134277,0.008239,0.000000
14.170001,5.821297,-353.178741,-0.004462,0.000312,0.007926,25.894421,1.319125,0.079263,-353.178741,0.008638,0.000000
14.410001,5.896149,-353.134277,-0.004480,0.000325,0.008256,26.227379,1.336086,0.082556,-353.134277,0.009037,0.000000
14.650001,6.105423,-353.178741,-0.004432,0.000337,0.008551,27.158278,1.383509,0.085508,-353.178741,0.009444,0.000000
14.890000,6.375763,-353.178741,-0.004424,0.000351,0.008915,28.360809,1.444769,0.089149,-353.178741,0.009843,0.000000
15.130001,6.551521,-353.223236,-0.004406,0.000361,0.009166,29.142622,1.484596,0.091663,-353.223236,0.010242,0.000000
15.370001,7.382286,-353.223236,-0.004376,0.000385,0.009791,32.838047,1.672850,0.097908,-353.223236,0.010641,0.000000
15.610001,7.425484,-353.223236,-0.004385,0.000398,0.010121,33.030201,1.682639,0.101208,-353.223236,0.011040,0.000000
15.850000,7.795990,-353.312195,-0.004368,0.000415,0.010537,34.678295,1.766597,0.105371,-353.312195,0.011439,0.000000
16.090000,8.352692,-353.312195,-0.004346,0.000437,0.011092,37.154629,1.892747,0.110920,-353.312195,0.011838,0.000000
16.330000,8.538506,-353.267700,-0.004324,0.000450,0.011439,37.981171,1.934853,0.114387,-353.267700,0.012237,0.000000
16.570002,8.581696,-353.401154,-0.004329,0.000460,0.011673,38.173290,1.944640,0.116726,-353.401154,0.012644,0.000000
16.810001,8.859856,-353.312195,-0.004299,0.000474,0.012028,39.410606,2.007672,0.120284,-353.312195,0.013043,0.000000
17.050001,9.314896,-353.401154,-0.004286,0.000492,0.012497,41.434727,2.110786,0.124970,-353.401154,0.013442,0.000000
17.290001,9.879784,-353.356689,-0.004277,0.000513,0.013026,43.947472,2.238791,0.130261,-353.356689,0.013841,0.000000
17.530001,9.962830,-353.445648,-0.004281,0.000525,0.013338,44.316879,2.257610,0.133380,-353.445648,0.014240,0.000000
17.770000,10.031342,-353.401154,-0.004264,0.000534,0.013572,44.621635,2.273134,0.135719,-353.401154,0.014638,0.000000
18.010000,10.810722,-353.401154,-0.004243,0.000557,0.014153,48.088493,2.449745,0.141532,-353.401154,0.015037,0.000000
18.250000,11.138779,-353.445648,-0.004234,0.000575,0.014613,49.547764,2.524083,0.146127,-353.445648,0.015436,0.000000
18.490002,11.201706,-353.445648,-0.004225,0.000588,0.014934,49.827675,2.538343,0.149337,-353.445648,0.015844,0.000000
18.730001,11.430344,-353.534607,-0.004186,0.000601,0.015272,50.844707,2.590153,0.152721,-353.534607,0.016243,0.000000
18.970001,11.690636,-353.490112,-0.004174,0.000616,0.015636,52.002544,2.649136,0.156362,-353.490112,0.016642,0.000000
19.210001,12.180305,-353.445648,-0.004152,0.000635,0.016121,54.180706,2.760097,0.161214,-353.445648,0.017041,0.000000
19.450001,12.399261,-353.579071,-0.004161,0.000649,0.016486,55.154671,2.809713,0.164862,-353.579071,0.017440,0.000000
19.690001,12.486023,-353.534607,-0.004139,0.000660,0.016763,55.540604,2.829373,0.167633,-353.534607,0.017839,0.000000
19.930000,13.285507,-353.579071,-0.004105,0.000686,0.017414,59.096886,3.010539,0.174135,-353.579071,0.018238,0.000000
20.170000,13.619522,-353.623566,-0.004100,0.000703,0.017865,60.582661,3.086228,0.178647,-353.623566,0.018637,0.000000
20.410002,13.525314,-353.579071,-0.004105,0.000714,0.018125,60.163605,3.064880,0.181251,-353.579071,0.019044,0.000000
20.650002,13.615799,-353.668030,-0.004092,0.000726,0.018446,60.566097,3.085384,0.184461,-353.668030,0.019443,0.000000
20.890001,13.929337,-353.579071,-0.004070,0.000740,0.018801,61.960785,3.156433,0.188011,-353.579071,0.019842,0.000000
21.130001,14.538536,-353.623566,-0.004044,0.000762,0.019365,64.670639,3.294479,0.193650,-353.623566,0.020241,0.000000
21.370001,14.707596,-353.668030,-0.004036,0.000776,0.019712,65.422653,3.332789,0.197117,-353.668030,0.020640,0.000000
21.610001,14.610031,-353.668030,-0.004018,0.000783,0.019886,64.988663,3.310680,0.198858,-353.668030,0.021039,0.000000
21.850000,15.203972,-353.712524,-0.003997,0.000805,0.020441,67.630646,3.445269,0.204407,-353.712524,0.021438,0.000000
22.090000,15.773697,-353.668030,-0.003988,0.000826,0.020978,70.164909,3.574371,0.209782,-353.668030,0.021837,0.000000
22.330002,15.646347,-353.756989,-0.003954,0.000836,0.021229,69.598427,3.545513,0.212295,-353.756989,0.022245,0.000000
22.570002,15.909241,-353.712524,-0.003971,0.000852,0.021637,70.767838,3.605085,0.216375,-353.712524,0.022644,0.000000
22.810001,16.066383,-353.712524,-0.003936,0.000865,0.021958,71.466843,3.640694,0.219584,-353.712524,0.023042,0.000000
23.050001,16.506897,-353.756989,-0.003941,0.000885,0.022470,73.426346,3.740516,0.224702,-353.756989,0.023441,0.000000
23.290001,16.736282,-353.801483,-0.003911,0.000899,0.022843,74.446701,3.792496,0.228426,-353.801483,0.023840,0.000000
23.530001,16.674843,-353.845978,-0.003898,0.000907,0.023042,74.173409,3.778574,0.230424,-353.845978,0.024239,0.000000
23.770000,17.063225,-353.801483,-0.003880,0.000926,0.023519,75.901016,3.866582,0.235193,-353.801483,0.024638,0.000000
24.010000,17.846321,-353.756989,-0.003842,0.000951,0.024152,79.384399,4.044034,0.241522,-353.756989,0.025045,0.000000
24.250002,17.816162,-353.890442,-0.003846,0.000963,0.024465,79.250244,4.037200,0.244648,-353.890442,0.025444,0.000000
24.490002,17.876862,-353.801483,-0.003833,0.000977,0.024820,79.520248,4.050955,0.248198,-353.801483,0.025843,0.000000
24.730001,18.096931,-353.890442,-0.003824,0.000993,0.025219,80.499168,4.100823,0.252188,-353.890442,0.026242,0.000000
24.970001,18.611176,-353.890442,-0.003773,0.001012,0.025705,82.786644,4.217352,0.257047,-353.890442,0.026641,0.000000
25.210001,18.785820,-353.934937,-0.003786,0.001028,0.026104,83.563499,4.256927,0.261037,-353.934937,0.027040,0.000000
25.450001,18.649902,-353.934937,-0.003760,0.001039,0.026398,82.958908,4.226128,0.263981,-353.934937,0.027439,0.000000
25.690001,18.731079,-353.979401,-0.003755,0.001049,0.026650,83.320000,4.244523,0.266502,-353.979401,0.027838,0.000000
25.930000,19.875755,-353.934937,-0.003734,0.001080,0.027422,88.411774,4.503911,0.274216,-353.934937,0.028246,0.000000
26.170002,19.571526,-353.934937,-0.003691,0.001089,0.027665,87.058495,4.434971,0.276646,-353.934937,0.028644,0.000000
26.410002,19.639671,-353.979401,-0.003695,0.001105,0.028063,87.361618,4.450413,0.280635,-353.979401,0.029043,0.000000
26.650002,19.911499,-354.023895,-0.003673,0.001119,0.028419,88.570770,4.512010,0.284193,-354.023895,0.029442,0.000000
26.890001,20.149818,-354.023895,-0.003682,0.001135,0.028818,89.630867,4.566014,0.288182,-354.023895,0.029841,0.000000
27.130001,20.121521,-354.112854,-0.003652,0.001148,0.029156,89.504997,4.559602,0.291558,-354.112854,0.030240,0.000000
27.370001,20.588478,-354.068359,-0.003609,0.001165,0.029599,91.582123,4.665416,0.295986,-354.068359,0.030639,0.000000
27.610001,20.951164,-354.068359,-0.003613,0.001184,0.030066,93.195435,4.747602,0.300664,-354.068359,0.031038,0.000000
27.850000,21.444183,-354.112854,-0.003587,0.001203,0.030552,95.388489,4.859322,0.305524,-354.112854,0.031446,0.000000
28.090002,21.612129,-354.068359,-0.003574,0.001219,0.030951,96.135551,4.897378,0.309514,-354.068359,0.031845,0.000000
28.330002,21.348114,-354.157318,-0.003561,0.001229,0.031220,94.961151,4.837552,0.312201,-354.157318,0.032244,0.000000
28.570002,21.557014,-354.112854,-0.003557,0.001244,0.031593,95.890388,4.884890,0.315933,-354.112854,0.032642,0.000000
28.810001,21.800171,-354.201813,-0.003557,0.001259,0.031975,96.972000,4.939989,0.319748,-354.201813,0.033041,0.000000
29.050001,21.933487,-354.112854,-0.003514,0.001271,0.032296,97.565025,4.970199,0.322958,-354.112854,0.033440,0.000000
29.290001,22.177391,-354.246307,-0.003492,0.001287,0.032677,98.649963,5.025469,0.326773,-354.246307,0.033839,0.000000
29.530001,22.367668,-354.290771,-0.003497,0.001304,0.033111,99.496361,5.068586,0.331110,-354.290771,0.034238,0.000000
29.770002,23.277000,-354.246307,-0.003475,0.001329,0.033761,103.541267,5.274643,0.337613,-354.246307,0.034645,0.000000
30.010002,23.398026,-354.246307,-0.003458,0.001345,0.034151,104.079613,5.302068,0.341511,-354.246307,0.035044,0.000000
30.250002,23.145927,-354.290771,-0.003436,0.001356,0.034437,102.958229,5.244942,0.344372,-354.290771,0.035443,0.000000
30.490002,23.176834,-354.246307,-0.003415,0.001368,0.034741,103.095711,5.251945,0.347408,-354.246307,0.035842,0.000000
30.730001,23.472130,-354.379730,-0.003402,0.001384,0.035166,104.409248,5.318861,0.351662,-354.379730,0.036241,0.000000
30.970001,24.182983,-354.290771,-0.003376,0.001406,0.035712,107.571281,5.479942,0.357120,-354.290771,0.036640,0.000000
31.210001,24.129364,-354.379730,-0.003380,0.001420,0.036077,107.332771,5.467792,0.360769,-354.379730,0.037039,0.000000
31.450001,24.690529,-354.335266,-0.003320,0.001442,0.036623,109.828957,5.594954,0.366226,-354.335266,0.037438,0.000000
31.690002,24.800377,-354.379730,-0.003324,0.001457,0.036996,110.317589,5.619845,0.369958,-354.379730,0.037846,0.000000
31.930002,24.614563,-354.424225,-0.003298,0.001467,0.037274,109.491043,5.577740,0.372736,-354.424225,0.038245,0.000000
32.170002,24.533760,-354.379730,-0.003277,0.001478,0.037551,109.131615,5.559430,0.375507,-354.379730,0.038644,0.000000
32.410000,24.834641,-354.424225,-0.003268,0.001496,0.038002,110.470001,5.627610,0.380019,-354.424225,0.039043,0.000000
32.650002,25.759987,-354.424225,-0.003242,0.001518,0.038557,114.586143,5.837296,0.385567,-354.424225,0.039442,0.000000
32.890003,25.744347,-354.513184,-0.003255,0.001530,0.038852,114.516571,5.833752,0.388519,-354.513184,0.039841,0.000000
33.130001,25.368622,-354.513184,-0.003212,0.001538,0.039060,112.845268,5.748612,0.390601,-354.513184,0.040239,0.000000
33.370003,26.272369,-354.424225,-0.003208,0.001565,0.039754,116.865334,5.953404,0.397535,-354.424225,0.040638,0.000000
33.610001,26.836143,-354.513184,-0.003173,0.001585,0.040257,119.373131,6.081157,0.402569,-354.513184,0.041046,0.000000
33.850002,26.706551,-354.513184,-0.003182,0.001598,0.040586,118.796669,6.051791,0.405862,-354.513184,0.041445,0.000000
34.090000,26.261200,-354.557648,-0.003152,0.001605,0.040777,116.815651,5.950873,0.407769,-354.557648,0.041844,0.000000
34.330002,26.793686,-354.557648,-0.003117,0.001625,0.041263,119.184265,6.071536,0.412629,-354.557648,0.042242,0.000000
34.570004,26.455574,-354.557648,-0.003091,0.001635,0.041540,117.680267,5.994919,0.415400,-354.557648,0.042641,0.000000
34.810001,27.404007,-354.646637,-0.003087,0.001658,0.042104,121.899109,6.209836,0.421039,-354.646637,0.043040,0.000000
35.050003,27.302719,-354.602142,-0.003061,0.001671,0.042451,121.448563,6.186884,0.424506,-354.602142,0.043439,0.000000
35.290001,27.343681,-354.602142,-0.003070,0.001681,0.042702,121.630768,6.196167,0.427019,-354.602142,0.043838,0.000000
35.530003,28.855141,-354.691101,-0.003022,0.001714,0.043526,128.354080,6.538669,0.435263,-354.691101,0.044246,0.000000
35.770000,28.648849,-354.691101,-0.003035,0.001727,0.043856,127.436447,6.491922,0.438556,-354.691101,0.044645,0.000000
36.010002,28.341270,-354.691101,-0.003009,0.001737,0.044116,126.068268,6.422224,0.441160,-354.691101,0.045044,0.000000
36.250000,28.404198,-354.646637,-0.002975,0.001750,0.044463,126.348183,6.436483,0.444627,-354.646637,0.045443,0.000000
36.490002,28.175194,-354.735596,-0.002979,0.001760,0.044697,125.329521,6.384590,0.446966,-354.735596,0.045842,0.000000
36.730003,29.253578,-354.735596,-0.002945,0.001786,0.045356,130.126419,6.628956,0.453559,-354.735596,0.046241,0.000000
36.970001,29.460991,-354.735596,-0.002936,0.001800,0.045720,131.049026,6.675956,0.457200,-354.735596,0.046640,0.000000
37.210003,29.529510,-354.824554,-0.002919,0.001816,0.046119,131.353821,6.691483,0.461189,-354.824554,0.047047,0.000000
37.450001,30.269043,-354.691101,-0.002902,0.001837,0.046665,134.643433,6.859063,0.466655,-354.691101,0.047446,0.000000
37.690002,30.245209,-354.913513,-0.002859,0.001851,0.047021,134.537415,6.853662,0.470213,-354.913513,0.047845,0.000000
37.930000,29.889595,-354.824554,-0.002841,0.001860,0.047255,132.955566,6.773079,0.472552,-354.824554,0.048244,0.000000
38.170002,29.935020,-354.869019,-0.002824,0.001874,0.047611,133.157623,6.783372,0.476110,-354.869019,0.048643,0.000000
38.410004,30.536407,-354.913513,-0.002811,0.001895,0.048123,135.832718,6.919649,0.481227,-354.913513,0.049042,0.000000
38.650002,31.124756,-354.869019,-0.002807,0.001913,0.048600,138.449829,7.052970,0.485996,-354.869019,0.049441,0.000000
38.890003,31.086029,-354.957977,-0.002785,0.001926,0.048929,138.277557,7.044195,0.489289,-354.957977,0.049839,0.000000
39.130001,30.836166,-354.869019,-0.002777,0.001936,0.049163,137.166122,6.987575,0.491628,-354.869019,0.050247,0.000000
39.370003,31.809174,-354.869019,-0.002755,0.001960,0.049787,141.494278,7.208062,0.497873,-354.869019,0.050646,0.000000
39.610001,32.075050,-354.957977,-0.002746,0.001976,0.050195,142.676956,7.268311,0.501953,-354.957977,0.051045,0.000000
39.850002,32.056427,-354.913513,-0.002712,0.001989,0.050533,142.594116,7.264091,0.505329,-354.913513,0.051444,0.000000
40.090000,31.992012,-355.002472,-0.002690,0.002003,0.050880,142.307571,7.249494,0.508803,-355.002472,0.051842,0.000000
40.330002,32.261230,-355.002472,-0.002673,0.002020,0.051297,143.505127,7.310499,0.512967,-355.002472,0.052241,0.000000
40.570004,32.362892,-354.957977,-0.002660,0.002035,0.051696,143.957336,7.333536,0.516956,-354.957977,0.052640,0.000000
40.810001,32.806389,-354.957977,-0.002652,0.002050,0.052077,145.930099,7.434034,0.520771,-354.957977,0.053039,0.000000
41.050003,32.862617,-355.046967,-0.002621,0.002062,0.052363,146.180222,7.446776,0.523633,-355.046967,0.053447,0.000000
41.290001,34.128685,-355.046967,-0.002578,0.002089,0.053048,151.811966,7.733671,0.530483,-355.046967,0.053846,0.000000
41.530003,34.280609,-355.046967,-0.002565,0.002104,0.053430,152.487762,7.768097,0.534298,-355.046967,0.054245,0.000000
41.770000,33.883286,-355.091431,-0.002565,0.002113,0.053681,150.720383,7.678062,0.536812,-355.091431,0.054644,0.000000
42.010002,33.922386,-355.180389,-0.002548,0.002128,0.054063,150.894302,7.686923,0.540627,-355.180389,0.055043,0.000000
42.250004,33.889992,-355.046967,-0.002535,0.002142,0.054401,150.750214,7.679582,0.544011,-355.046967,0.055442,0.000000
42.490002,34.793739,-355.224884,-0.002505,0.002162,0.054921,154.770279,7.884374,0.549211,-355.224884,0.055841,0.000000
42.730003,34.763580,-355.135925,-0.002488,0.002175,0.055234,154.636124,7.877540,0.552337,-355.135925,0.056240,0.000000
42.970001,34.367744,-355.180389,-0.002470,0.002182,0.055433,152.875366,7.787842,0.554328,-355.180389,0.056647,0.000000
43.210003,35.198135,-355.224884,-0.002445,0.002207,0.056066,156.569122,7.976011,0.560664,-355.224884,0.057046,0.000000
43.450001,35.990547,-355.180389,-0.002436,0.002225,0.056526,160.093948,8.155575,0.565259,-355.180389,0.057445,0.000000
43.690002,35.635300,-355.224884,-0.002432,0.002234,0.056751,158.513733,8.075074,0.567515,-355.224884,0.057844,0.000000
43.930000,35.949585,-355.269348,-0.002410,0.002253,0.057228,159.911743,8.146293,0.572284,-355.269348,0.058243,0.000000
44.170002,35.840477,-355.224884,-0.002363,0.002265,0.057523,159.426407,8.121568,0.575228,-355.224884,0.058642,0.000000
44.410004,36.563255,-355.269348,-0.002333,0.002285,0.058035,162.641479,8.285353,0.580346,-355.269348,0.059041,0.000000
44.650002,36.686508,-355.224884,-0.002320,0.002299,0.058399,163.189743,8.313281,0.583987,-355.224884,0.059440,0.000000
44.890003,36.328659,-355.313843,-0.002333,0.002310,0.058685,161.597946,8.232192,0.586848,-355.313843,0.059848,0.000000
45.130001,36.788910,-355.269348,-0.002294,0.002324,0.059041,163.645248,8.336487,0.590406,-355.269348,0.060246,0.000000
45.370003,38.262390,-355.313843,-0.002302,0.002354,0.059786,170.199615,8.670382,0.597862,-355.313843,0.060645,0.000000
45.610001,37.993538,-355.313843,-0.002276,0.002363,0.060029,169.003693,8.609459,0.600292,-355.313843,0.061044,0.000000
45.850002,38.110458,-355.313843,-0.002251,0.002379,0.060437,169.523788,8.635953,0.604372,-355.313843,0.061443,0.000000
46.090004,38.304466,-355.402802,-0.002233,0.002394,0.060801,170.386780,8.679916,0.608013,-355.402802,0.061842,0.000000
46.330002,38.970642,-355.358307,-0.002199,0.002414,0.061313,173.350067,8.830874,0.613130,-355.358307,0.062241,0.000000
46.570004,39.013092,-355.402802,-0.002195,0.002427,0.061642,173.538895,8.840492,0.616423,-355.402802,0.062640,0.000000
46.810001,38.927444,-355.402802,-0.002147,0.002440,0.061981,173.157928,8.821085,0.619807,-355.402802,0.063047,0.000000
47.050003,38.526031,-355.447266,-0.002139,0.002449,0.062197,171.372345,8.730124,0.621972,-355.447266,0.063446,0.000000
47.290001,40.240433,-355.447266,-0.002139,0.002479,0.062978,178.998383,9.118612,0.629776,-355.447266,0.063845,0.000000
47.530003,39.835289,-355.491760,-0.002108,0.002490,0.063238,177.196213,9.026805,0.632380,-355.491760,0.064244,0.000000
47.770000,40.083664,-355.536255,-0.002070,0.002506,0.063663,178.301041,9.083088,0.636627,-355.536255,0.064643,0.000000
48.010002,40.024452,-355.580719,-0.002044,0.002518,0.063958,178.037659,9.069671,0.639579,-355.580719,0.065042,0.000000
48.250004,40.380074,-355.536255,-0.002070,0.002536,0.064409,179.619537,9.150255,0.644091,-355.536255,0.065441,0.000000
48.490002,40.473534,-355.580719,-0.002026,0.002548,0.064721,180.035263,9.171433,0.647209,-355.580719,0.065840,0.000000
48.730003,40.977356,-355.536255,-0.002009,0.002568,0.065215,182.276382,9.285602,0.652153,-355.536255,0.066247,0.000000
48.970001,41.528839,-355.625214,-0.001996,0.002586,0.065692,184.729507,9.410570,0.656922,-355.625214,0.066646,0.000000
49.210003,41.971222,-355.536255,-0.001979,0.002604,0.066152,186.697327,9.510815,0.661516,-355.536255,0.067045,0.000000
49.450001,42.082184,-355.580719,-0.001936,0.002617,0.066473,187.190903,9.535959,0.664726,-355.580719,0.067444,0.000000
49.690002,41.886688,-355.669678,-0.001919,0.002631,0.066820,186.321289,9.491659,0.668200,-355.669678,0.067843,0.000000
49.930004,41.902328,-355.625214,-0.001901,0.002645,0.067192,186.390869,9.495203,0.671925,-355.625214,0.068242,0.000000
50.170002,42.273216,-355.669678,-0.001858,0.002661,0.067600,188.040665,9.579247,0.676005,-355.669678,0.068641,0.000000
50.410004,42.069527,-355.625214,-0.001854,0.002672,0.067869,187.134598,9.533092,0.678692,-355.625214,0.069049,0.000000
50.650002,42.311195,-355.714172,-0.001841,0.002691,0.068346,188.209595,9.587854,0.683461,-355.714172,0.069448,0.000000
50.890003,42.834007,-355.714172,-0.001807,0.002708,0.068771,190.535187,9.706325,0.687708,-355.714172,0.069846,0.000000
51.130001,44.254608,-355.714172,-0.001798,0.002734,0.069438,196.854324,10.028237,0.694384,-355.714172,0.070245,0.000000
51.370003,44.086670,-355.758636,-0.001789,0.002746,0.069759,196.107300,9.990182,0.697594,-355.758636,0.070644,0.000000
51.610001,43.604446,-355.803131,-0.001746,0.002756,0.070002,193.962265,9.880909,0.700024,-355.803131,0.071043,0.000000
51.850002,43.741852,-355.669678,-0.001738,0.002774,0.070454,194.573471,9.912045,0.704535,-355.669678,0.071442,0.000000
52.090004,43.684502,-355.803131,-0.001712,0.002787,0.070783,194.318375,9.899049,0.707828,-355.803131,0.071841,0.000000
52.330002,44.315674,-355.758636,-0.001656,0.002805,0.071242,197.125961,10.042075,0.712423,-355.758636,0.072248,0.000000
52.570004,44.449730,-355.892090,-0.001664,0.002822,0.071676,197.722275,10.072453,0.716761,-355.892090,0.072647,0.000000
52.810001,45.091698,-355.803131,-0.001617,0.002842,0.072188,200.577896,10.217925,0.721878,-355.803131,0.073046,0.000000
53.050003,45.108086,-355.892090,-0.001608,0.002857,0.072561,200.650787,10.221639,0.725610,-355.892090,0.073445,0.000000
53.290001,44.855240,-355.847595,-0.001604,0.002870,0.072890,199.526077,10.164342,0.728903,-355.847595,0.073844,0.000000
53.530003,44.416214,-355.892090,-0.001565,0.002881,0.073168,197.573181,10.064858,0.731681,-355.892090,0.074243,0.000000
53.770004,44.581177,-355.936584,-0.001535,0.002895,0.073532,198.306976,10.102239,0.735322,-355.936584,0.074642,0.000000
54.010002,45.451782,-355.847595,-0.001492,0.002917,0.074096,202.179626,10.299520,0.740961,-355.847595,0.075041,0.000000
54.250004,45.340820,-355.981049,-0.001518,0.002931,0.074451,201.686035,10.274377,0.744512,-355.981049,0.075449,0.000000
54.490002,44.448242,-355.936584,-0.001453,0.002939,0.074642,197.715652,10.072116,0.746419,-355.936584,0.075848,0.000000
54.730003,45.577271,-355.981049,-0.001436,0.002968,0.075388,202.737823,10.327957,0.753883,-355.981049,0.076247,0.000000
54.970001,46.407661,-355.981049,-0.001427,0.002986,0.075856,206.431595,10.516127,0.758561,-355.981049,0.076646,0.000000
55.210003,46.028587,-355.936584,-0.001388,0.002998,0.076151,204.745377,10.430227,0.761513,-355.936584,0.077045,0.000000
55.450001,45.149414,-356.070007,-0.001358,0.003007,0.076368,200.834625,10.231003,0.763678,-356.070007,0.077443,0.000000
55.690002,45.574669,-356.025543,-0.001341,0.003023,0.076792,202.726257,10.327368,0.767925,-356.025543,0.077842,0.000000
55.930004,44.849289,-356.025543,-0.001354,0.003031,0.076975,199.499603,10.162994,0.769749,-356.025543,0.078241,0.000000
56.170002,45.977943,-356.070007,-0.001293,0.003056,0.077625,204.520111,10.418751,0.776252,-356.070007,0.078649,0.000000
56.410004,45.525139,-356.070007,-0.001306,0.003069,0.077955,202.505936,10.316144,0.779552,-356.070007,0.079048,0.000000
56.650002,45.894165,-356.158966,-0.001272,0.003086,0.078380,204.147446,10.399766,0.783799,-356.158966,0.079446,0.000000
56.890003,47.436157,-356.158966,-0.001242,0.003114,0.079108,211.006561,10.749187,0.791081,-356.158966,0.079845,0.000000
57.130001,47.082031,-356.158966,-0.001216,0.003127,0.079421,209.431335,10.668941,0.794207,-356.158966,0.080244,0.000000
57.370003,46.481766,-356.158966,-0.001186,0.003136,0.079655,206.761215,10.532919,0.796546,-356.158966,0.080643,0.000000
57.610004,46.356651,-356.070007,-0.001138,0.003149,0.079984,206.204681,10.504567,0.799839,-356.070007,0.081042,0.000000
57.850002,45.881500,-356.203461,-0.001151,0.003158,0.080219,204.091110,10.396896,0.802186,-356.203461,0.081441,0.000000
58.090004,47.204544,-356.203461,-0.001112,0.003185,0.080895,209.976303,10.696703,0.808946,-356.203461,0.081849,0.000000
58.330002,47.389610,-356.158966,-0.001104,0.003201,0.081293,210.799515,10.738639,0.812935,-356.158966,0.082248,0.000000
58.570004,47.515846,-356.203461,-0.001074,0.003216,0.081692,211.361038,10.767245,0.816924,-356.203461,0.082647,0.000000
58.810001,48.367088,-356.247925,-0.001074,0.003239,0.082265,215.147552,10.960138,0.822647,-356.247925,0.083046,0.000000
59.050003,48.213669,-356.292419,-0.001052,0.003250,0.082560,214.465103,10.925374,0.825599,-356.292419,0.083445,0.000000
59.290001,47.770172,-356.247925,-0.001013,0.003261,0.082838,212.492340,10.824876,0.828377,-356.247925,0.083844,0.000000
59.530003,47.956360,-356.292419,-0.000987,0.003278,0.083262,213.320541,10.867066,0.832624,-356.292419,0.084243,0.000000
59.770004,48.480286,-356.336914,-0.000987,0.003297,0.083739,215.651077,10.985789,0.837393,-356.336914,0.084641,0.000000
60.010002,49.265251,-356.381378,-0.000961,0.003314,0.084181,219.142776,11.163666,0.841814,-356.381378,0.085049,0.000000
60.250004,49.085770,-356.336914,-0.000940,0.003325,0.084459,218.344406,11.122994,0.844592,-356.336914,0.085448,0.000000
60.490002,48.768135,-356.292419,-0.000901,0.003337,0.084754,216.931503,11.051017,0.847536,-356.292419,0.085847,0.000000
60.730003,50.155220,-356.381378,-0.000905,0.003362,0.085405,223.101562,11.365335,0.854046,-356.381378,0.086246,0.000000
60.970001,50.322418,-356.336914,-0.000858,0.003376,0.085751,223.845291,11.403223,0.857513,-356.336914,0.086645,0.000000
61.210003,50.217407,-356.425873,-0.000862,0.003389,0.086072,223.378189,11.379427,0.860723,-356.425873,0.087044,0.000000
61.450005,50.575256,-356.425873,-0.000854,0.003405,0.086480,224.969971,11.460517,0.864796,-356.425873,0.087442,0.000000
61.690002,50.873528,-356.425873,-0.000841,0.003422,0.086913,226.296753,11.528106,0.869133,-356.425873,0.087841,0.000000
61.930004,51.225792,-356.470337,-0.000828,0.003436,0.087269,227.863708,11.607930,0.872691,-356.470337,0.088249,0.000000
62.170002,51.527412,-356.470337,-0.000772,0.003449,0.087607,229.205383,11.676278,0.876074,-356.470337,0.088648,0.000000
62.410004,51.427620,-356.514832,-0.000763,0.003460,0.087885,228.761475,11.653665,0.878845,-356.514832,0.089046,0.000000
62.650002,53.155052,-356.559296,-0.000759,0.003489,0.088613,236.445480,12.045107,0.886135,-356.559296,0.089445,0.000000
62.890003,53.576210,-356.514832,-0.000763,0.003505,0.089029,238.318878,12.140543,0.890291,-356.514832,0.089844,0.000000
63.130005,53.320015,-356.603790,-0.000716,0.003515,0.089272,237.179276,12.082488,0.892720,-356.603790,0.090243,0.000000
63.370003,53.411621,-356.559296,-0.000716,0.003527,0.089585,237.586761,12.103246,0.895847,-356.559296,0.090642,0.000000
63.610004,53.851387,-356.603790,-0.000673,0.003547,0.090087,239.542938,12.202899,0.900873,-356.603790,0.091050,0.000000
63.850002,54.820305,-356.648254,-0.000655,0.003563,0.090512,243.852890,12.422459,0.905120,-356.648254,0.091449,0.000000
64.090004,54.819183,-356.648254,-0.000673,0.003573,0.090755,243.847900,12.422204,0.907550,-356.648254,0.091848,0.000000
64.330002,54.848602,-356.692749,-0.000638,0.003586,0.091093,243.978775,12.428870,0.910933,-356.692749,0.092247,0.000000
64.570000,56.233459,-356.737213,-0.000625,0.003610,0.091700,250.138916,12.742684,0.917004,-356.737213,0.092646,0.000000
64.810005,56.945435,-356.692749,-0.000604,0.003624,0.092047,253.305939,12.904020,0.920471,-356.692749,0.093045,0.000000
65.050003,56.840797,-356.737213,-0.000595,0.003633,0.092273,252.840500,12.880309,0.922727,-356.737213,0.093444,0.000000
65.290001,57.688316,-356.648254,-0.000591,0.003653,0.092784,256.610443,13.072359,0.927844,-356.648254,0.093843,0.000000
65.530006,57.740074,-356.781708,-0.000586,0.003667,0.093149,256.840668,13.084087,0.931485,-356.781708,0.094250,0.000000
65.770004,58.912674,-356.826202,-0.000548,0.003685,0.093608,262.056671,13.349803,0.936080,-356.826202,0.094649,0.000000
66.010002,59.354683,-356.781708,-0.000539,0.003700,0.093990,264.022827,13.449963,0.939895,-356.781708,0.095048,0.000000
66.250000,59.514801,-356.781708,-0.000517,0.003711,0.094259,264.735046,13.486247,0.942590,-356.781708,0.095447,0.000000
66.490005,60.061821,-356.737213,-0.000517,0.003726,0.094631,267.168335,13.610204,0.946315,-356.737213,0.095846,0.000000
66.730003,62.094971,-356.870667,-0.000504,0.003753,0.095334,276.212219,14.070921,0.953339,-356.870667,0.096245,0.000000
66.970001,62.156044,-356.781708,-0.000483,0.003762,0.095560,276.483887,14.084761,0.955595,-356.781708,0.096644,0.000000
67.210007,62.807693,-356.870667,-0.000461,0.003780,0.096019,279.382568,14.232427,0.960190,-356.870667,0.097042,0.000000
67.450005,63.561371,-356.915161,-0.000483,0.003796,0.096418,282.735107,14.403213,0.964179,-356.915161,0.097450,0.000000
67.690002,64.619278,-356.915161,-0.000466,0.003815,0.096895,287.440918,14.642938,0.968948,-356.915161,0.097849,0.000000
67.930000,65.078049,-356.915161,-0.000448,0.003827,0.097207,289.481628,14.746897,0.972075,-356.915161,0.098248,0.000000
68.170006,65.474625,-356.959625,-0.000418,0.003839,0.097502,291.245667,14.836762,0.975019,-356.959625,0.098647,0.000000
68.410004,65.559891,-356.959625,-0.000431,0.003847,0.097710,291.624969,14.856084,0.977101,-356.959625,0.099046,0.000000
68.650002,67.142105,-356.959625,-0.000384,0.003865,0.098161,298.662994,15.214619,0.981613,-356.959625,0.098378,0.000000
68.890007,66.217880,-356.915161,-0.000392,0.003865,0.098161,294.551849,15.005186,0.981613,-356.915161,0.098161,0.000000
69.130005,65.388229,-357.048584,-0.000384,0.003864,0.098144,290.861359,14.817184,0.981438,-357.048584,0.098161,0.000000
69.370003,64.656525,-357.004120,-0.000362,0.003864,0.098144,287.606598,14.651378,0.981438,-357.004120,0.098161,0.000000
69.610001,63.986252,-357.004120,-0.000379,0.003864,0.098136,284.625061,14.499492,0.981355,-357.004120,0.098161,0.000000
69.850006,63.393433,-357.093079,-0.000384,0.003864,0.098136,281.988068,14.365157,0.981355,-357.093079,0.098161,0.000000
70.090004,62.880302,-357.048584,-0.000341,0.003864,0.098136,279.705566,14.248879,0.981355,-357.048584,0.098161,0.000000
70.330002,62.389519,-357.093079,-0.000358,0.003863,0.098126,277.522430,14.137668,0.981264,-357.093079,0.098161,0.000000
70.570000,61.952354,-357.137543,-0.000336,0.003863,0.098126,275.577850,14.038605,0.981264,-357.137543,0.098161,0.000000
70.810005,61.560242,-357.137543,-0.000341,0.003863,0.098126,273.833618,13.949750,0.981264,-357.137543,0.098161,0.000000
71.050003,61.203514,-357.137543,-0.000341,0.003863,0.098126,272.246826,13.868915,0.981264,-357.137543,0.098161,0.000000
71.290001,60.862419,-357.137543,-0.000354,0.003863,0.098126,270.729553,13.791621,0.981264,-357.137543,0.098161,0.000000
71.530006,60.564896,-357.226532,-0.000349,0.003863,0.098126,269.406097,13.724202,0.981264,-357.226532,0.098161,0.000000
71.770004,60.281891,-357.182037,-0.000336,0.003863,0.098126,268.147247,13.660072,0.981264,-357.182037,0.098161,0.000000
72.010002,60.010803,-357.226532,-0.000349,0.003863,0.098126,266.941376,13.598642,0.981264,-357.226532,0.098161,0.000000
72.250000,59.766525,-357.226532,-0.000332,0.003863,0.098126,265.854797,13.543288,0.981264,-357.226532,0.098161,0.000000
72.490005,59.546082,-357.226532,-0.000336,0.003863,0.098126,264.874207,13.493335,0.981264,-357.226532,0.098161,0.000000
72.730003,59.325264,-357.270996,-0.000310,0.003863,0.098126,263.891968,13.443296,0.981264,-357.270996,0.098161,0.000000
72.970001,59.130890,-357.270996,-0.000332,0.003863,0.098126,263.027344,13.399251,0.981264,-357.270996,0.098161,0.000000
73.210007,58.943954,-357.315491,-0.000345,0.003863,0.098126,262.195801,13.356892,0.981264,-357.315491,0.098161,0.000000
73.450005,58.767822,-357.359955,-0.000310,0.003863,0.098126,261.412323,13.316978,0.981264,-357.359955,0.098161,0.000000
73.690002,58.591316,-357.315491,-0.000341,0.003863,0.098126,260.627197,13.276982,0.981264,-357.315491,0.098161,0.000000
73.930000,58.429337,-357.359955,-0.000332,0.003863,0.098126,259.906677,13.240277,0.981264,-357.359955,0.098161,0.000000
74.170006,58.281502,-357.315491,-0.000315,0.003863,0.098126,259.249054,13.206777,0.981264,-357.315491,0.098161,0.000000
74.410004,58.133301,-357.404449,-0.000332,0.003863,0.098126,258.589844,13.173194,0.981264,-357.404449,0.098161,0.000000
74.650002,58.009300,-357.404449,-0.000310,0.003863,0.098126,258.038269,13.145096,0.981264,-357.404449,0.098161,0.000000
74.890007,57.870781,-357.448914,-0.000302,0.003863,0.098126,257.422089,13.113707,0.981264,-357.448914,0.098161,0.000000
75.130005,57.747147,-357.448914,-0.000315,0.003863,0.098126,256.872131,13.085690,0.981264,-357.448914,0.098161,0.000000
75.370003,57.622032,-357.537872,-0.000319,0.003863,0.098126,256.315613,13.057339,0.981264,-357.537872,0.098161,0.000000
75.610001,57.518517,-357.537872,-0.000306,0.003863,0.098126,255.855133,13.033882,0.981264,-357.537872,0.098161,0.000000
75.850006,57.400841,-357.493408,-0.000293,0.003863,0.098126,255.331696,13.007216,0.981264,-357.493408,0.098161,0.000000
76.090004,57.298073,-357.493408,-0.000328,0.003863,0.098126,254.874557,12.983929,0.981264,-357.493408,0.098161,0.000000
76.330002,57.195297,-357.582367,-0.000310,0.003863,0.098126,254.417389,12.960639,0.981264,-357.582367,0.098161,0.000000
76.570007,57.089539,-357.537872,-0.000328,0.003863,0.098126,253.946945,12.936674,0.981264,-357.537872,0.098161,0.000000
76.810005,57.004639,-357.626862,-0.000315,0.003863,0.098126,253.569290,12.917437,0.981264,-357.626862,0.098161,0.000000
77.050003,56.912666,-357.582367,-0.000315,0.003863,0.098126,253.160187,12.896595,0.981264,-357.582367,0.098161,0.000000
77.290001,56.814728,-357.582367,-0.000289,0.003863,0.098126,252.724533,12.874402,0.981264,-357.582367,0.098161,0.000000
77.530006,56.737648,-357.582367,-0.000302,0.003863,0.098126,252.381668,12.856935,0.981264,-357.582367,0.098161,0.000000
77.770004,56.646790,-357.626862,-0.000315,0.003863,0.098126,251.977509,12.836346,0.981264,-357.626862,0.098161,0.000000
78.010002,56.572311,-357.671326,-0.000302,0.003863,0.098126,251.646210,12.819469,0.981264,-357.671326,0.098161,0.000000
78.250000,56.496353,-357.671326,-0.000310,0.003863,0.098126,251.308334,12.802257,0.981264,-357.671326,0.098161,0.000000
78.490005,56.422997,-357.671326,-0.000302,0.003863,0.098126,250.982025,12.785634,0.981264,-357.671326,0.098161,0.000000
78.730003,56.362671,-357.626862,-0.000297,0.003863,0.098126,250.713684,12.771964,0.981264,-357.626862,0.098161,0.000000
78.970001,56.284843,-357.671326,-0.000302,0.003863,0.098126,250.367493,12.754328,0.981264,-357.671326,0.098161,0.000000
79.210007,56.213722,-357.715820,-0.000332,0.003863,0.098126,250.051132,12.738212,0.981264,-357.715820,0.098161,0.000000
79.450005,56.146324,-357.715820,-0.000306,0.003863,0.098126,249.751328,12.722939,0.981264,-357.715820,0.098161,0.000000
79.690002,56.089722,-357.760284,-0.000302,0.003863,0.098126,249.499542,12.710113,0.981264,-357.760284,0.098161,0.000000
79.930000,56.017479,-357.715820,-0.000293,0.003863,0.098126,249.178192,12.693742,0.981264,-357.715820,0.098161,0.000000
80.170006,55.957153,-357.804779,-0.000280,0.003863,0.098126,248.909851,12.680072,0.981264,-357.804779,0.098161,0.000000
80.410004,55.893105,-357.804779,-0.000293,0.003863,0.098126,248.624939,12.665559,0.981264,-357.804779,0.098161,0.000000
80.650002,55.846558,-357.760284,-0.000276,0.003863,0.098126,248.417892,12.655011,0.981264,-357.760284,0.098161,0.000000
80.890007,55.769104,-357.849243,-0.000289,0.003863,0.098126,248.073364,12.637460,0.981264,-357.849243,0.098161,0.000000
81.130005,55.729637,-357.804779,-0.000302,0.003863,0.098126,247.897812,12.628516,0.981264,-357.804779,0.098161,0.000000
81.370003,55.664841,-357.893738,-0.000297,0.003863,0.098126,247.609573,12.613833,0.981264,-357.893738,0.098161,0.000000
81.610001,55.613457,-357.893738,-0.000315,0.003863,0.098126,247.381012,12.602189,0.981264,-357.893738,0.098161,0.000000
81.850006,55.570633,-357.849243,-0.000315,0.003863,0.098126,247.190521,12.592485,0.981264,-357.849243,0.098161,0.000000
82.090004,55.518127,-357.982697,-0.000306,0.003863,0.098126,246.956970,12.580587,0.981264,-357.982697,0.098161,0.000000
82.330002,55.461525,-357.938202,-0.000272,0.003863,0.098126,246.705185,12.567761,0.981264,-357.938202,0.098161,0.000000
82.570007,55.417213,-357.893738,-0.000315,0.003863,0.098126,246.508072,12.557720,0.981264,-357.893738,0.098161,0.000000
82.810005,55.363594,-357.982697,-0.000306,0.003863,0.098126,246.269562,12.545569,0.981264,-357.982697,0.098161,0.000000
83.050003,55.313698,-357.982697,-0.000302,0.003863,0.098126,246.047623,12.534263,0.981264,-357.982697,0.098161,0.000000
83.290001,55.289116,-358.027161,-0.000306,0.003863,0.098126,245.938278,12.528693,0.981264,-358.027161,0.098161,0.000000
83.530006,55.226562,-357.982697,-0.000297,0.003863,0.098126,245.660019,12.514518,0.981264,-357.982697,0.098161,0.000000
83.770004,55.189323,-358.071655,-0.000285,0.003863,0.098126,245.494370,12.506080,0.981264,-358.071655,0.098161,0.000000
84.010002,55.143524,-358.071655,-0.000280,0.003863,0.098126,245.290649,12.495701,0.981264,-358.071655,0.098161,0.000000
84.250008,55.104424,-358.027161,-0.000306,0.003863,0.098126,245.116714,12.486840,0.981264,-358.027161,0.098161,0.000000
84.490005,55.067558,-358.160614,-0.000289,0.003863,0.098126,244.952728,12.478487,0.981264,-358.160614,0.098161,0.000000
84.730003,55.027344,-358.116150,-0.000297,0.003863,0.098126,244.773849,12.469375,0.981264,-358.116150,0.098161,0.000000
84.970001,54.977448,-358.160614,-0.000306,0.003863,0.098126,244.551895,12.458068,0.981264,-358.160614,0.098161,0.000000
85.210007,54.945045,-358.116150,-0.000302,0.003863,0.098126,244.407776,12.450725,0.981264,-358.116150,0.098161,0.000000
85.450005,54.910789,-358.116150,-0.000302,0.003863,0.098126,244.255386,12.442963,0.981264,-358.116150,0.098161,0.000000
85.690002,54.859772,-358.249573,-0.000297,0.003863,0.098126,244.028458,12.431401,0.981264,-358.249573,0.098161,0.000000
85.930000,54.832588,-358.160614,-0.000302,0.003863,0.098126,243.907532,12.425241,0.981264,-358.160614,0.098161,0.000000
86.170006,54.792747,-358.249573,-0.000272,0.003863,0.098126,243.730316,12.416214,0.981264,-358.249573,0.098161,0.000000
86.410004,54.754768,-358.249573,-0.000263,0.003863,0.098126,243.561371,12.407608,0.981264,-358.249573,0.098161,0.000000
86.650002,54.722000,-358.160614,-0.000293,0.003863,0.098126,243.415619,12.400183,0.981264,-358.160614,0.098161,0.000000
86.890007,54.693321,-358.249573,-0.000285,0.003863,0.098126,243.288040,12.393683,0.981264,-358.249573,0.098161,0.000000
87.130005,54.651619,-358.294067,-0.000289,0.003863,0.098126,243.102539,12.384233,0.981264,-358.294067,0.098161,0.000000
87.370003,54.621086,-358.249573,-0.000276,0.003863,0.098126,242.966721,12.377315,0.981264,-358.249573,0.098161,0.000000
87.610001,54.584961,-358.338531,-0.000280,0.003863,0.098126,242.806030,12.369129,0.981264,-358.338531,0.098161,0.000000
87.850006,54.546982,-358.294067,-0.000306,0.003863,0.098126,242.637100,12.360522,0.981264,-358.294067,0.098161,0.000000
88.090004,54.520172,-358.338531,-0.000297,0.003863,0.098126,242.517838,12.354447,0.981264,-358.338531,0.098161,0.000000
88.330002,54.495590,-358.294067,-0.000306,0.003863,0.098126,242.408493,12.348877,0.981264,-358.294067,0.098161,0.000000
88.570007,54.457611,-358.471985,-0.000297,0.003863,0.098126,242.239548,12.340271,0.981264,-358.471985,0.098161,0.000000
88.810005,54.429314,-358.383026,-0.000285,0.003863,0.098126,242.113678,12.333858,0.981264,-358.383026,0.098161,0.000000
89.050003,54.399521,-358.383026,-0.000289,0.003863,0.098126,241.981155,12.327107,0.981264,-358.383026,0.098161,0.000000
89.290001,54.367126,-358.427490,-0.000293,0.003863,0.098126,241.837051,12.319767,0.981264,-358.427490,0.098161,0.000000
89.530006,54.339569,-358.427490,-0.000280,0.003863,0.098126,241.714478,12.313522,0.981264,-358.427490,0.098161,0.000000
89.770004,54.306053,-358.471985,-0.000276,0.003863,0.098126,241.565384,12.305928,0.981264,-358.471985,0.098161,0.000000
90.010002,54.288925,-358.427490,-0.000289,0.003863,0.098126,241.489197,12.302046,0.981264,-358.427490,0.098161,0.000000
90.250008,54.252434,-358.427490,-0.000306,0.003863,0.098126,241.326874,12.293777,0.981264,-358.427490,0.098161,0.000000
90.490005,54.231583,-358.427490,-0.000297,0.003863,0.098126,241.234131,12.289052,0.981264,-358.427490,0.098161,0.000000
90.730003,54.201416,-358.516479,-0.000293,0.003863,0.098126,241.099945,12.282216,0.981264,-358.516479,0.098161,0.000000
90.970001,54.174240,-358.605438,-0.000289,0.003863,0.098126,240.979050,12.276058,0.981264,-358.605438,0.098161,0.000000
91.210007,54.148918,-358.516479,-0.000285,0.003863,0.098126,240.866425,12.270321,0.981264,-358.516479,0.098161,0.000000
91.450005,54.115776,-358.560944,-0.000297,0.003863,0.098126,240.718994,12.262810,0.981264,-358.560944,0.098161,0.000000
91.690002,54.087471,-358.605438,-0.000289,0.003863,0.098126,240.593094,12.256396,0.981264,-358.605438,0.098161,0.000000
91.930008,54.077423,-358.605438,-0.000315,0.003863,0.098126,240.548386,12.254119,0.981264,-358.605438,0.098161,0.000000
92.170006,54.043159,-358.605438,-0.000267,0.003863,0.098126,240.395981,12.246355,0.981264,-358.605438,0.098161,0.000000
92.410004,54.007416,-358.560944,-0.000289,0.003863,0.098126,240.236984,12.238256,0.981264,-358.560944,0.098161,0.000000
92.650002,53.996239,-358.649902,-0.000285,0.003863,0.098126,240.187271,12.235723,0.981264,-358.649902,0.098161,0.000000
92.890007,53.970177,-358.649902,-0.000280,0.003863,0.098126,240.071335,12.229817,0.981264,-358.649902,0.098161,0.000000
93.130005,53.954163,-358.605438,-0.000293,0.003863,0.098126,240.000107,12.226188,0.981264,-358.605438,0.098161,0.000000
93.370003,53.929962,-358.694397,-0.000276,0.003863,0.098126,239.892456,12.220704,0.981264,-358.694397,0.098161,0.000000
93.610008,53.900169,-358.649902,-0.000293,0.003863,0.098126,239.759933,12.213953,0.981264,-358.649902,0.098161,0.000000
93.850006,53.871872,-358.738861,-0.000293,0.003863,0.098126,239.634048,12.207541,0.981264,-358.738861,0.098161,0.000000
94.090004,53.846550,-358.783356,-0.000302,0.003863,0.098126,239.521423,12.201803,0.981264,-358.783356,0.098161,0.000000
94.330002,53.825325,-358.738861,-0.000310,0.003863,0.098126,239.427002,12.196993,0.981264,-358.738861,0.098161,0.000000
94.570007,53.807823,-358.783356,-0.000285,0.003863,0.098126,239.349152,12.193027,0.981264,-358.783356,0.098161,0.000000
94.810005,53.787338,-358.738861,-0.000272,0.003863,0.098126,239.258026,12.188385,0.981264,-358.738861,0.098161,0.000000
95.050003,53.769470,-358.827820,-0.000302,0.003863,0.098126,239.178543,12.184336,0.981264,-358.827820,0.098161,0.000000
95.290001,53.741165,-358.827820,-0.000276,0.003863,0.098126,239.052643,12.177922,0.981264,-358.827820,0.098161,0.000000
95.530006,53.722176,-358.738861,-0.000272,0.003863,0.098126,238.968170,12.173619,0.981264,-358.738861,0.098161,0.000000
95.770004,53.698715,-358.872314,-0.000272,0.003863,0.098126,238.863815,12.168303,0.981264,-358.872314,0.098161,0.000000
96.010002,53.676376,-358.827820,-0.000289,0.003863,0.098126,238.764450,12.163240,0.981264,-358.827820,0.098161,0.000000
96.250008,53.653290,-358.872314,-0.000280,0.003863,0.098126,238.661758,12.158010,0.981264,-358.872314,0.098161,0.000000
96.490005,53.642860,-358.916809,-0.000289,0.003863,0.098126,238.615356,12.155645,0.981264,-358.916809,0.098161,0.000000
96.730003,53.611580,-358.916809,-0.000289,0.003863,0.098126,238.476212,12.148558,0.981264,-358.916809,0.098161,0.000000
96.970001,53.594452,-358.961273,-0.000280,0.003863,0.098126,238.400024,12.144676,0.981264,-358.961273,0.098161,0.000000
97.210007,53.575836,-358.916809,-0.000297,0.003863,0.098126,238.317215,12.140458,0.981264,-358.916809,0.098161,0.000000
97.450005,53.550514,-359.050232,-0.000315,0.003863,0.098126,238.204590,12.134720,0.981264,-359.050232,0.098161,0.000000
97.690002,53.541573,-358.961273,-0.000276,0.003863,0.098126,238.164810,12.132693,0.981264,-358.961273,0.098161,0.000000
97.930008,53.513275,-359.050232,-0.000297,0.003863,0.098126,238.038940,12.126282,0.981264,-359.050232,0.098161,0.000000
98.170006,53.498383,-359.005768,-0.000280,0.003863,0.098126,237.972687,12.122907,0.981264,-359.005768,0.098161,0.000000
98.410004,53.473434,-359.050232,-0.000297,0.003863,0.098126,237.861710,12.117253,0.981264,-359.050232,0.098161,0.000000
98.650002,53.446991,-359.094727,-0.000285,0.003863,0.098126,237.744095,12.111261,0.981264,-359.094727,0.098161,0.000000
98.890007,53.433586,-359.005768,-0.000259,0.003863,0.098126,237.684464,12.108224,0.981264,-359.005768,0.098161,0.000000
98.900002,53.434334,-359.094727,-0.000272,0.003863,0.098126,237.687790,12.108394,0.981264,-359.094727,0.098161,0.000000