File: Data/compression 13/AutoNoHeating-12-13-2-240724_07242024_163915.csv
Time (sec),S:Load (lbs),S:HL1 (DIM),S:LVDT (in),S:Position (in),Ch:Position (mm),Ch:Load (N),Ch:Stress (MPa),Ch:Strain (mm/mm),Ch:HL1 (DIM),Set Point (),Cycles ()
0.110000,0.030907,-263.638611,-0.009645,-0.005089,-0.129260,0.137480,0.007004,-1.292602,-263.638611,-0.129043,0.000000
0.350000,0.030907,-263.727570,-0.009666,-0.005089,-0.129260,0.137480,0.007004,-1.292602,-263.727570,-0.129043,0.000000
0.590000,0.006699,-263.772034,-0.009623,-0.005000,-0.126996,0.029797,0.001518,-1.269965,-263.772034,-0.126407,0.000000
0.830000,0.024948,-263.727570,-0.009662,-0.004874,-0.123796,0.110975,0.005653,-1.237963,-263.727570,-0.122418,0.000000
1.070000,0.034256,-263.860992,-0.009464,-0.004703,-0.119460,0.152378,0.007763,-1.194604,-263.860992,-0.118411,0.000000
1.310000,0.032021,-263.772034,-0.009317,-0.004555,-0.115697,0.142435,0.007256,-1.156967,-263.772034,-0.114422,0.000000
1.550000,0.023087,-263.860992,-0.009140,-0.004393,-0.111586,0.102694,0.005231,-1.115859,-263.860992,-0.110415,0.000000
1.790000,-0.032028,-263.860992,-0.008998,-0.004241,-0.107709,-0.142469,-0.007258,-1.077094,-263.860992,-0.106426,0.000000
2.030000,-0.002235,-263.816528,-0.008830,-0.004081,-0.103668,-0.009944,-0.000507,-1.036683,-263.816528,-0.102419,0.000000
2.270000,0.042824,-263.905487,-0.008653,-0.003928,-0.099766,0.190490,0.009704,-0.997657,-263.905487,-0.098413,0.000000
2.510000,0.045425,-263.905487,-0.008498,-0.003767,-0.095672,0.202062,0.010294,-0.956723,-263.905487,-0.094423,0.000000
2.750000,0.011917,-263.994446,-0.008326,-0.003605,-0.091579,0.053010,0.002700,-0.915793,-263.994446,-0.090417,0.000000
2.990000,0.043938,-263.994446,-0.008153,-0.003448,-0.087573,0.195445,0.009956,-0.875726,-263.994446,-0.086428,0.000000
3.230000,0.055855,-263.994446,-0.007972,-0.003294,-0.083661,0.248455,0.012657,-0.836613,-263.994446,-0.082421,0.000000
3.470000,0.033142,-264.038940,-0.007847,-0.003139,-0.079724,0.147423,0.007510,-0.797243,-264.038940,-0.078432,0.000000
3.710000,-0.010429,-264.038940,-0.007662,-0.002975,-0.075562,-0.046392,-0.002363,-0.755616,-264.038940,-0.074425,0.000000
3.950000,-0.001862,-264.038940,-0.007498,-0.002823,-0.071693,-0.008281,-0.000422,-0.716935,-264.038940,-0.070436,0.000000
4.190000,0.024574,-264.083405,-0.007317,-0.002665,-0.067696,0.109312,0.005569,-0.676959,-264.083405,-0.066429,0.000000
4.430000,0.052505,-264.083405,-0.007179,-0.002504,-0.063594,0.233556,0.011898,-0.635938,-264.083405,-0.062440,0.000000
4.670000,0.062927,-264.127899,-0.006980,-0.002343,-0.059517,0.279914,0.014260,-0.595175,-264.127899,-0.058433,0.000000
4.910000,0.046547,-264.127899,-0.006838,-0.002190,-0.055624,0.207051,0.010548,-0.556236,-264.127899,-0.054444,0.000000
5.150000,0.055481,-264.083405,-0.006670,-0.002033,-0.051626,0.246792,0.012572,-0.516260,-264.083405,-0.050438,0.000000
5.390000,0.063675,-264.172363,-0.006502,-0.001882,-0.047802,0.283240,0.014429,-0.478017,-264.172363,-0.046449,0.000000
5.630000,0.055481,-264.172363,-0.006364,-0.001714,-0.043526,0.246792,0.012572,-0.435263,-264.172363,-0.042442,0.000000
5.870000,0.011543,-264.261322,-0.006178,-0.001563,-0.039710,0.051347,0.002616,-0.397104,-264.261322,-0.038453,0.000000
6.110000,0.040962,-264.261322,-0.006015,-0.001403,-0.035626,0.182209,0.009282,-0.356257,-264.261322,-0.034446,0.000000
6.350000,0.059952,-264.261322,-0.005881,-0.001252,-0.031792,0.266679,0.013585,-0.317924,-264.261322,-0.030457,0.000000
6.590000,0.049896,-264.261322,-0.005670,-0.001082,-0.027482,0.221950,0.011307,-0.274821,-264.261322,-0.026450,0.000000
6.830000,0.048035,-264.305817,-0.005536,-0.000929,-0.023588,0.213669,0.010885,-0.235882,-264.305817,-0.022461,0.000000
7.070000,0.056969,-264.350281,-0.005381,-0.000771,-0.019573,0.253409,0.012909,-0.195732,-264.350281,-0.018454,0.000000
7.310000,0.060692,-264.305817,-0.005191,-0.000620,-0.015749,0.269971,0.013753,-0.157489,-264.305817,-0.014448,0.000000
7.550000,0.060692,-264.394775,-0.005027,-0.000460,-0.011690,0.269971,0.013753,-0.116900,-264.394775,-0.010458,0.000000
7.790000,0.040215,-264.394775,-0.004872,-0.000301,-0.007640,0.178883,0.009113,-0.076402,-264.394775,-0.006452,0.000000
8.030001,0.042450,-264.394775,-0.004704,-0.000145,-0.003686,0.188827,0.009619,-0.036857,-264.394775,-0.002463,0.000000
8.270000,0.060692,-264.439240,-0.004540,0.000008,0.000191,0.269971,0.013753,0.001908,-264.439240,0.001543,0.000000
8.510000,0.252098,-264.350281,-0.004381,0.000168,0.004275,1.121388,0.057126,0.042754,-264.350281,0.005533,0.000000
8.750000,0.684418,-264.483734,-0.004290,-0.000000,-0.000000,3.044442,0.155091,-0.000000,-264.483734,0.000200,0.000000
8.990001,0.641594,-264.439240,-0.004243,-0.000000,-0.000000,2.853952,0.145387,-0.000000,-264.439240,0.000200,0.000000
9.230000,0.577179,-264.528229,-0.004294,-0.000000,-0.000008,2.567420,0.130791,-0.000083,-264.528229,0.000278,0.000000
9.470000,0.612183,-264.528229,-0.004273,-0.000000,-0.000008,2.723124,0.138723,-0.000083,-264.528229,0.000677,0.000000
9.710000,0.577919,-264.572693,-0.004273,-0.000000,-0.000000,2.570712,0.130958,-0.000000,-264.572693,0.001076,0.000000
9.950001,0.574196,-264.572693,-0.004264,-0.000000,-0.000000,2.554151,0.130115,-0.000000,-264.572693,0.001475,0.000000
10.190001,0.872841,-264.661652,-0.004264,0.000033,0.000833,3.882590,0.197789,0.008327,-264.661652,0.001874,0.000000
10.430000,1.082855,-264.617187,-0.004230,0.000053,0.001353,4.816781,0.245379,0.013527,-264.617187,0.002281,0.000000
10.670000,1.227341,-264.661652,-0.004212,0.000072,0.001821,5.459484,0.278119,0.018213,-264.661652,0.002680,0.000000
10.910001,1.281708,-264.572693,-0.004230,0.000082,0.002090,5.701321,0.290439,0.020900,-264.572693,0.003079,0.000000
11.150001,1.436615,-264.706146,-0.004195,0.000097,0.002472,6.390383,0.325542,0.024715,-264.706146,0.003478,0.000000
11.390000,1.640297,-264.661652,-0.004195,0.000117,0.002966,7.296405,0.371697,0.029658,-264.661652,0.003876,0.000000
11.630000,1.855904,-264.706146,-0.004156,0.000134,0.003400,8.255471,0.420554,0.033996,-264.706146,0.004275,0.000000
11.870001,1.891281,-264.750610,-0.004165,0.000142,0.003616,8.412839,0.428570,0.036161,-264.750610,0.004674,0.000000
12.110001,2.173164,-264.750610,-0.004130,0.000159,0.004032,9.666718,0.492446,0.040324,-264.750610,0.005073,0.000000
12.350000,2.369034,-264.795105,-0.004126,0.000176,0.004466,10.537989,0.536831,0.044662,-264.795105,0.005481,0.000000
12.590000,2.695602,-264.839569,-0.004100,0.000199,0.005056,11.990639,0.610832,0.050559,-264.839569,0.005880,0.000000
12.830001,2.811035,-264.839569,-0.004096,0.000211,0.005351,12.504108,0.636990,0.053511,-264.839569,0.006279,0.000000
13.070001,3.065369,-264.928558,-0.004087,0.000229,0.005811,13.635441,0.694622,0.058106,-264.928558,0.006678,0.000000
13.310000,3.245598,-264.884064,-0.004057,0.000241,0.006122,14.437140,0.735463,0.061224,-264.884064,0.007077,0.000000
13.550000,3.514076,-264.884064,-0.004061,0.000257,0.006521,15.631392,0.796301,0.065214,-264.884064,0.007476,0.000000
13.790001,3.653343,-264.973022,-0.004031,0.000269,0.006834,16.250883,0.827859,0.068340,-264.973022,0.007875,0.000000
14.030001,3.934860,-264.884064,-0.004040,0.000284,0.007216,17.503132,0.891652,0.072155,-264.884064,0.008274,0.000000
14.270000,4.387665,-265.017517,-0.004010,0.000310,0.007875,19.517307,0.994259,0.078749,-265.017517,0.008681,0.000000
14.510000,4.583900,-265.017517,-0.003980,0.000327,0.008317,20.390207,1.038727,0.083169,-265.017517,0.009080,0.000000
14.750001,4.654282,-265.017517,-0.003992,0.000339,0.008603,20.703279,1.054675,0.086031,-265.017517,0.009479,0.000000
14.990001,4.863182,-265.017517,-0.003958,0.000351,0.008924,21.632515,1.102013,0.089240,-265.017517,0.009878,0.000000
15.230000,5.180817,-265.061981,-0.003945,0.000370,0.009392,23.045424,1.173990,0.093918,-265.061981,0.010277,0.000000
15.470000,5.429192,-265.106476,-0.003923,0.000384,0.009757,24.150249,1.230272,0.097567,-265.106476,0.010676,0.000000
15.710001,5.629898,-265.061981,-0.003915,0.000398,0.010103,25.043037,1.275753,0.101034,-265.061981,0.011075,0.000000
15.950001,5.574783,-265.106476,-0.003898,0.000404,0.010268,24.797874,1.263264,0.102684,-265.106476,0.011474,0.000000
16.190001,6.306496,-265.195435,-0.003898,0.000433,0.010988,28.052694,1.429072,0.109876,-265.195435,0.011881,0.000000
16.430000,6.417091,-265.106476,-0.003846,0.000449,0.011404,28.544647,1.454134,0.114039,-265.106476,0.012280,0.000000
16.670000,6.536995,-265.195435,-0.003850,0.000462,0.011725,29.078005,1.481304,0.117248,-265.195435,0.012679,0.000000
16.910002,6.757812,-265.195435,-0.003842,0.000477,0.012124,30.060251,1.531342,0.121238,-265.195435,0.013078,0.000000
17.150002,7.006187,-265.239899,-0.003833,0.000491,0.012480,31.165079,1.587625,0.124796,-265.239899,0.013476,0.000000
17.390001,7.321960,-265.195435,-0.003798,0.000510,0.012965,32.569706,1.659180,0.129648,-265.195435,0.013875,0.000000
17.630001,7.415794,-265.195435,-0.003811,0.000523,0.013295,32.987103,1.680443,0.132948,-265.195435,0.014274,0.000000
17.870001,7.582619,-265.328888,-0.003773,0.000535,0.013598,33.729172,1.718246,0.135984,-265.328888,0.014673,0.000000
18.110001,7.852592,-265.284393,-0.003777,0.000551,0.013988,34.930077,1.779423,0.139882,-265.284393,0.015081,0.000000
18.350000,8.370186,-265.328888,-0.003751,0.000576,0.014630,37.232445,1.896711,0.146301,-265.328888,0.015480,0.000000
18.590000,8.032074,-265.328888,-0.003725,0.000579,0.014708,35.728451,1.820094,0.147081,-265.328888,0.015879,0.000000
18.830002,8.510574,-265.373352,-0.003708,0.000602,0.015280,37.856926,1.928524,0.152804,-265.373352,0.016278,0.000000
19.070002,8.840866,-265.373352,-0.003682,0.000620,0.015749,39.326138,2.003369,0.157489,-265.373352,0.016677,0.000000
19.310001,9.035614,-265.417847,-0.003665,0.000637,0.016174,40.192417,2.047499,0.161736,-265.417847,0.017076,0.000000
19.550001,9.142487,-265.417847,-0.003648,0.000650,0.016521,40.667812,2.071717,0.165211,-265.417847,0.017475,0.000000
19.790001,9.230370,-265.506805,-0.003643,0.000663,0.016841,41.058735,2.091632,0.168413,-265.506805,0.017882,0.000000
20.030001,9.222549,-265.506805,-0.003635,0.000671,0.017049,41.023949,2.089860,0.170494,-265.506805,0.018281,0.000000
20.270000,9.990379,-265.595764,-0.003600,0.000701,0.017804,44.439426,2.263852,0.178041,-265.595764,0.018680,0.000000
20.510000,9.801216,-265.506805,-0.003596,0.000712,0.018082,43.597988,2.220987,0.180820,-265.506805,0.019079,0.000000
20.750002,10.141190,-265.506805,-0.003587,0.000730,0.018532,45.110264,2.298026,0.185324,-265.506805,0.019478,0.000000
20.990002,10.138214,-265.595764,-0.003548,0.000741,0.018819,45.097027,2.297352,0.188193,-265.595764,0.019877,0.000000
21.230001,10.379883,-265.551270,-0.003531,0.000760,0.019296,46.172024,2.352115,0.192962,-265.551270,0.020276,0.000000
21.470001,10.531807,-265.684723,-0.003501,0.000772,0.019608,46.847816,2.386542,0.196080,-265.684723,0.020675,0.000000
21.710001,10.798431,-265.595764,-0.003505,0.000787,0.019999,48.033821,2.446960,0.199986,-265.595764,0.021083,0.000000
21.950001,10.766777,-265.640228,-0.003501,0.000798,0.020267,47.893017,2.439787,0.202674,-265.640228,0.021482,0.000000
22.190001,11.261284,-265.773682,-0.003471,0.000823,0.020892,50.092693,2.551843,0.208919,-265.773682,0.021880,0.000000
22.430000,11.420288,-265.684723,-0.003449,0.000840,0.021334,50.799980,2.587874,0.213339,-265.684723,0.022279,0.000000
22.670002,11.364433,-265.773682,-0.003410,0.000853,0.021663,50.551525,2.575217,0.216632,-265.773682,0.022678,0.000000
22.910002,11.412842,-265.729187,-0.003410,0.000865,0.021976,50.766857,2.586187,0.219759,-265.729187,0.023077,0.000000
23.150002,11.557320,-265.729187,-0.003402,0.000880,0.022340,51.409527,2.618926,0.223400,-265.729187,0.023476,0.000000
23.390001,11.752815,-265.818176,-0.003380,0.000893,0.022687,52.279133,2.663226,0.226867,-265.818176,0.023875,0.000000
23.630001,11.877563,-265.773682,-0.003372,0.000908,0.023051,52.834042,2.691494,0.230508,-265.773682,0.024282,0.000000
23.870001,12.231316,-265.862640,-0.003346,0.000927,0.023545,54.407608,2.771656,0.235451,-265.862640,0.024681,0.000000
24.110001,12.805885,-265.818176,-0.003307,0.000953,0.024213,56.963425,2.901855,0.242127,-265.818176,0.025080,0.000000
24.350000,12.521393,-265.862640,-0.003285,0.000965,0.024508,55.697937,2.837388,0.245080,-265.862640,0.025479,0.000000
24.590002,12.474846,-265.907135,-0.003260,0.000978,0.024846,55.490887,2.826840,0.248463,-265.907135,0.025878,0.000000
24.830002,12.561241,-265.862640,-0.003260,0.000992,0.025193,55.875191,2.846418,0.251930,-265.862640,0.026277,0.000000
25.070002,12.789879,-265.951599,-0.003225,0.001009,0.025627,56.892223,2.898228,0.256268,-265.951599,0.026676,0.000000
25.310001,12.970100,-265.951599,-0.003191,0.001027,0.026095,57.693890,2.939067,0.260946,-265.951599,0.027075,0.000000
25.550001,13.196510,-265.996094,-0.003186,0.001045,0.026537,58.701008,2.990372,0.265374,-265.996094,0.027482,0.000000
25.790001,13.525681,-266.040558,-0.003152,0.001065,0.027057,60.165234,3.064963,0.270575,-266.040558,0.027881,0.000000
26.030001,13.388649,-266.040558,-0.003130,0.001078,0.027370,59.555687,3.033911,0.273701,-266.040558,0.028280,0.000000
26.270000,13.276192,-266.040558,-0.003126,0.001090,0.027682,59.055450,3.008428,0.276820,-266.040558,0.028679,0.000000
26.510002,13.369286,-266.085052,-0.003100,0.001105,0.028073,59.469551,3.029523,0.280726,-266.085052,0.029078,0.000000
26.750002,13.474297,-266.129517,-0.003074,0.001119,0.028428,59.936665,3.053319,0.284276,-266.129517,0.029477,0.000000
26.990002,14.016098,-266.129517,-0.003061,0.001139,0.028939,62.346718,3.176093,0.289393,-266.129517,0.029876,0.000000
27.230001,13.821716,-266.174011,-0.003035,0.001151,0.029225,61.482063,3.132046,0.292254,-266.174011,0.030275,0.000000
27.470001,13.745758,-266.174011,-0.003001,0.001162,0.029512,61.144184,3.114833,0.295116,-266.174011,0.030683,0.000000
27.710001,14.384750,-266.218506,-0.002997,0.001190,0.030223,63.986565,3.259631,0.302231,-266.218506,0.031082,0.000000
27.950001,14.500183,-266.218506,-0.002971,0.001210,0.030726,64.500038,3.285789,0.307258,-266.218506,0.031480,0.000000
28.190001,14.089081,-266.262970,-0.002945,0.001220,0.030977,62.671360,3.192631,0.309771,-266.262970,0.031879,0.000000
28.430002,14.008278,-266.262970,-0.002902,0.001234,0.031342,62.311932,3.174321,0.313420,-266.262970,0.032278,0.000000
28.670002,14.090942,-266.307465,-0.002889,0.001248,0.031689,62.679642,3.193053,0.316887,-266.307465,0.032677,0.000000
28.910002,14.298355,-266.262970,-0.002897,0.001264,0.032113,63.602261,3.240054,0.321133,-266.262970,0.033076,0.000000
29.150002,14.514336,-266.396423,-0.002867,0.001279,0.032477,64.562988,3.288996,0.324774,-266.396423,0.033475,0.000000
29.390001,14.465179,-266.396423,-0.002850,0.001292,0.032816,64.344330,3.277857,0.328158,-266.396423,0.033882,0.000000
29.630001,14.400383,-266.351929,-0.002815,0.001303,0.033102,64.056107,3.263174,0.331019,-266.351929,0.034281,0.000000
29.870001,15.364090,-266.396423,-0.002781,0.001335,0.033900,68.342888,3.481553,0.338998,-266.396423,0.034680,0.000000
30.110001,14.945915,-266.396423,-0.002725,0.001348,0.034238,66.482750,3.386793,0.342382,-266.396423,0.035079,0.000000
30.350002,14.629021,-266.440887,-0.002721,0.001361,0.034559,65.073135,3.314984,0.345591,-266.440887,0.035478,0.000000
30.590002,14.607430,-266.485382,-0.002695,0.001373,0.034863,64.977089,3.310091,0.348627,-266.485382,0.035877,0.000000
30.830002,14.816330,-266.529846,-0.002673,0.001389,0.035270,65.906326,3.357428,0.352699,-266.529846,0.036276,0.000000
31.070002,15.144012,-266.529846,-0.002656,0.001406,0.035721,67.363930,3.431682,0.357211,-266.529846,0.036675,0.000000
31.310001,14.885963,-266.529846,-0.002665,0.001418,0.036016,66.216072,3.373208,0.360163,-266.529846,0.037083,0.000000
31.550001,15.326103,-266.618835,-0.002626,0.001438,0.036528,68.173912,3.472945,0.365280,-266.618835,0.037482,0.000000
31.790001,15.443031,-266.618835,-0.002604,0.001456,0.036988,68.694031,3.499441,0.369875,-266.618835,0.037881,0.000000
32.030003,15.307487,-266.574341,-0.002561,0.001471,0.037369,68.091103,3.468726,0.373690,-266.574341,0.038280,0.000000
32.270000,15.065071,-266.618835,-0.002548,0.001483,0.037673,67.012787,3.413794,0.376726,-266.618835,0.038679,0.000000
32.510002,15.133591,-266.707794,-0.002501,0.001500,0.038106,67.317574,3.429321,0.381063,-266.707794,0.039078,0.000000
32.750000,15.480270,-266.618835,-0.002488,0.001518,0.038548,68.859680,3.507879,0.385484,-266.618835,0.039476,0.000000
32.990002,15.590118,-266.707794,-0.002479,0.001534,0.038965,69.348312,3.532771,0.389647,-266.707794,0.039884,0.000000
33.230003,15.245674,-266.707794,-0.002475,0.001544,0.039216,67.816147,3.454719,0.392161,-266.707794,0.040283,0.000000
33.470001,15.540222,-266.707794,-0.002432,0.001562,0.039667,69.126358,3.521465,0.396672,-266.707794,0.040682,0.000000
33.710003,15.615067,-266.752258,-0.002389,0.001577,0.040049,69.459282,3.538425,0.400487,-266.752258,0.041080,0.000000
33.950001,16.082024,-266.841217,-0.002371,0.001600,0.040638,71.536415,3.644239,0.406384,-266.841217,0.041479,0.000000
34.190002,15.814659,-266.796753,-0.002367,0.001612,0.040950,70.347115,3.583653,0.409503,-266.796753,0.041878,0.000000
34.430000,15.797897,-266.796753,-0.002324,0.001628,0.041341,70.272560,3.579854,0.413409,-266.796753,0.042277,0.000000
34.670002,15.672409,-266.885712,-0.002298,0.001641,0.041688,69.714355,3.551419,0.416876,-266.885712,0.042676,0.000000
34.910000,15.909241,-266.885712,-0.002281,0.001657,0.042096,70.767838,3.605085,0.420956,-266.885712,0.043084,0.000000
35.150002,15.959885,-266.885712,-0.002268,0.001672,0.042460,70.993111,3.616561,0.424597,-266.885712,0.043483,0.000000
35.390003,16.049255,-266.930176,-0.002264,0.001688,0.042876,71.390656,3.636813,0.428760,-266.930176,0.043882,0.000000
35.630001,16.630898,-266.974670,-0.002233,0.001712,0.043483,73.977928,3.768615,0.434831,-266.974670,0.044281,0.000000
35.870003,16.563873,-266.930176,-0.002207,0.001729,0.043908,73.679787,3.753428,0.439078,-266.930176,0.044680,0.000000
36.110001,16.203789,-267.019135,-0.002169,0.001741,0.044211,72.078049,3.671831,0.442114,-267.019135,0.045079,0.000000
36.350002,16.060051,-266.974670,-0.002139,0.001751,0.044480,71.438675,3.639260,0.444801,-266.974670,0.045478,0.000000
36.590000,16.424232,-267.063629,-0.002151,0.001771,0.044983,73.058632,3.721784,0.449835,-267.063629,0.045877,0.000000
36.830002,16.339699,-267.063629,-0.002104,0.001783,0.045286,72.682610,3.702629,0.452863,-267.063629,0.046284,0.000000
37.070004,16.496101,-267.108124,-0.002104,0.001797,0.045651,73.378326,3.738070,0.456511,-267.108124,0.046683,0.000000
37.310001,16.511368,-267.108124,-0.002082,0.001810,0.045980,73.446236,3.741529,0.459804,-267.108124,0.047082,0.000000
37.550003,17.339897,-267.108124,-0.002052,0.001838,0.046691,77.131714,3.929277,0.466912,-267.108124,0.047481,0.000000
37.790001,17.041626,-267.197083,-0.002026,0.001850,0.046977,75.804939,3.861688,0.469774,-267.197083,0.047880,0.000000
38.030003,16.764580,-267.152588,-0.002009,0.001860,0.047255,74.572578,3.798908,0.472552,-267.152588,0.048279,0.000000
38.270000,16.877037,-267.152588,-0.002013,0.001880,0.047749,75.072807,3.824391,0.477495,-267.152588,0.048678,0.000000
38.510002,16.844269,-267.241547,-0.001962,0.001890,0.048010,74.927048,3.816966,0.480099,-267.241547,0.049076,0.000000
38.750000,17.168976,-267.241547,-0.001927,0.001910,0.048513,76.371422,3.890546,0.485125,-267.241547,0.049484,0.000000
38.990002,17.300423,-267.330505,-0.001923,0.001926,0.048911,76.956123,3.920332,0.489114,-267.330505,0.049883,0.000000
39.230003,17.047211,-267.286041,-0.001884,0.001935,0.049137,75.829781,3.862953,0.491370,-267.286041,0.050282,0.000000
39.470001,17.577843,-267.286041,-0.001863,0.001956,0.049692,78.190147,3.983196,0.496919,-267.286041,0.050680,0.000000
39.710003,17.922661,-267.330505,-0.001828,0.001975,0.050169,79.723976,4.061333,0.501688,-267.330505,0.051079,0.000000
39.950001,17.674660,-267.330505,-0.001850,0.001987,0.050481,78.620811,4.005135,0.504814,-267.330505,0.051478,0.000000
40.190002,17.901802,-267.330505,-0.001819,0.002006,0.050950,79.631195,4.056606,0.509500,-267.330505,0.051877,0.000000
40.430000,17.820999,-267.375000,-0.001802,0.002020,0.051314,79.271767,4.038296,0.513141,-267.375000,0.052276,0.000000
40.670002,18.044052,-267.419464,-0.001768,0.002038,0.051756,80.263954,4.088840,0.517562,-267.419464,0.052684,0.000000
40.910004,17.850418,-267.463959,-0.001746,0.002052,0.052120,79.402626,4.044962,0.521203,-267.463959,0.053083,0.000000
41.150002,17.686203,-267.419464,-0.001738,0.002063,0.052406,78.672157,4.007751,0.524064,-267.419464,0.053482,0.000000
41.390003,17.570396,-267.552917,-0.001681,0.002079,0.052797,78.157028,3.981509,0.527970,-267.552917,0.053881,0.000000
41.630001,18.484940,-267.463959,-0.001686,0.002101,0.053360,82.225121,4.188747,0.533602,-267.463959,0.054280,0.000000
41.870003,18.341576,-267.597412,-0.001643,0.002115,0.053716,81.587402,4.156260,0.537160,-267.597412,0.054679,0.000000
42.110001,18.233589,-267.597412,-0.001595,0.002129,0.054080,81.107056,4.131790,0.540801,-267.597412,0.055078,0.000000
42.350002,18.071976,-267.552917,-0.001608,0.002144,0.054462,80.388161,4.095168,0.544616,-267.552917,0.055477,0.000000
42.590000,18.651764,-267.641876,-0.001582,0.002163,0.054948,82.967186,4.226550,0.549476,-267.641876,0.055884,0.000000
42.830002,18.496483,-267.597412,-0.001561,0.002175,0.055234,82.276466,4.191363,0.552337,-267.597412,0.056283,0.000000
43.070004,18.569466,-267.641876,-0.001552,0.002191,0.055658,82.601112,4.207901,0.556584,-267.641876,0.056682,0.000000
43.310001,18.143845,-267.686371,-0.001535,0.002205,0.055997,80.707855,4.111454,0.559968,-267.686371,0.057081,0.000000
43.550003,19.117226,-267.730835,-0.001500,0.002228,0.056604,85.037666,4.332025,0.566039,-267.730835,0.057480,0.000000
43.790001,18.813370,-267.775330,-0.001475,0.002239,0.056873,83.686050,4.263170,0.568726,-267.775330,0.057879,0.000000
44.030003,18.739273,-267.730835,-0.001449,0.002255,0.057289,83.356453,4.246380,0.572889,-267.730835,0.058278,0.000000
44.270000,18.654739,-267.730835,-0.001436,0.002269,0.057627,82.980423,4.227224,0.576273,-267.730835,0.058676,0.000000
44.510002,18.951897,-267.819794,-0.001423,0.002286,0.058061,84.302246,4.294561,0.580610,-267.819794,0.059084,0.000000
44.750004,19.017807,-267.775330,-0.001397,0.002300,0.058408,84.595428,4.309496,0.584077,-267.775330,0.059483,0.000000
44.990002,19.064728,-267.908783,-0.001375,0.002315,0.058807,84.804146,4.320129,0.588067,-267.908783,0.059882,0.000000
45.230003,19.056908,-267.864288,-0.001341,0.002325,0.059067,84.769356,4.318357,0.590671,-267.864288,0.060281,0.000000
45.470001,20.012039,-267.908783,-0.001319,0.002355,0.059813,89.017998,4.534793,0.598127,-267.908783,0.060680,0.000000
45.710003,19.520508,-267.997742,-0.001281,0.002367,0.060134,86.831558,4.423410,0.601337,-267.997742,0.061079,0.000000
45.950001,19.286285,-267.953247,-0.001272,0.002380,0.060463,85.789680,4.370335,0.604629,-267.953247,0.061478,0.000000
46.190002,19.422203,-267.953247,-0.001272,0.002396,0.060862,86.394272,4.401134,0.608619,-267.953247,0.061885,0.000000
46.430000,19.444168,-267.953247,-0.001229,0.002413,0.061278,86.491982,4.406111,0.612782,-267.953247,0.062284,0.000000
46.670002,19.656052,-267.997742,-0.001199,0.002429,0.061695,87.434486,4.454125,0.616945,-267.997742,0.062683,0.000000
46.910004,19.985603,-268.086700,-0.001190,0.002448,0.062181,88.900406,4.528802,0.621805,-268.086700,0.063082,0.000000
47.150002,20.174019,-267.997742,-0.001168,0.002464,0.062588,89.738518,4.571498,0.625878,-267.997742,0.063481,0.000000
47.390003,19.843727,-268.086700,-0.001125,0.002476,0.062891,88.269310,4.496653,0.628913,-268.086700,0.063880,0.000000
47.630001,19.742073,-268.042206,-0.001138,0.002491,0.063282,87.817123,4.473618,0.632819,-268.042206,0.064279,0.000000
47.870003,19.850060,-268.131165,-0.001095,0.002505,0.063629,88.297478,4.498088,0.636286,-268.131165,0.064678,0.000000
48.110001,19.790482,-268.131165,-0.001074,0.002517,0.063932,88.032455,4.484587,0.639322,-268.131165,0.065085,0.000000
48.350002,20.355370,-268.086700,-0.001039,0.002538,0.064461,90.545204,4.612593,0.644613,-268.086700,0.065484,0.000000
48.590004,20.054115,-268.220123,-0.001018,0.002549,0.064756,89.205162,4.544327,0.647558,-268.220123,0.065883,0.000000
48.830002,20.104385,-268.220123,-0.000992,0.002564,0.065129,89.428772,4.555719,0.651290,-268.220123,0.066282,0.000000
49.070004,21.246078,-268.220123,-0.000979,0.002593,0.065875,94.507278,4.814430,0.658746,-268.220123,0.066681,0.000000
49.310001,21.115753,-268.309082,-0.000957,0.002610,0.066282,93.927559,4.784898,0.662818,-268.309082,0.067080,0.000000
49.550003,20.457771,-268.220123,-0.000931,0.002619,0.066534,91.000710,4.635798,0.665339,-268.220123,0.067479,0.000000
49.790001,20.432076,-268.353577,-0.000910,0.002634,0.066906,90.886414,4.629974,0.669063,-268.353577,0.067878,0.000000
50.030003,20.362816,-268.309082,-0.000910,0.002647,0.067236,90.578331,4.614280,0.672364,-268.309082,0.068286,0.000000
50.270004,20.710236,-268.264618,-0.000892,0.002665,0.067696,92.123726,4.693007,0.676959,-268.264618,0.068684,0.000000
50.510002,20.802956,-268.398071,-0.000854,0.002677,0.068008,92.536171,4.714017,0.680077,-268.398071,0.069083,0.000000
50.750004,20.748222,-268.309082,-0.000819,0.002691,0.068346,92.292702,4.701614,0.683461,-268.309082,0.069482,0.000000
50.990002,20.782852,-268.353577,-0.000832,0.002705,0.068702,92.446747,4.709461,0.687019,-268.353577,0.069881,0.000000
51.230003,22.048920,-268.398071,-0.000772,0.002736,0.069500,98.078491,4.996356,0.694998,-268.398071,0.070280,0.000000
51.470001,21.419983,-268.442535,-0.000759,0.002747,0.069777,95.280846,4.853837,0.697768,-268.442535,0.070679,0.000000
51.710003,21.144798,-268.442535,-0.000737,0.002762,0.070158,94.056763,4.791480,0.701583,-268.442535,0.071078,0.000000
51.950001,20.863281,-268.487030,-0.000711,0.002773,0.070428,92.804512,4.727687,0.704278,-268.487030,0.071485,0.000000
52.190002,21.140701,-268.575989,-0.000703,0.002789,0.070835,94.038536,4.790551,0.708351,-268.575989,0.071884,0.000000
52.430004,21.532806,-268.531494,-0.000651,0.002806,0.071269,95.782707,4.879404,0.712688,-268.531494,0.072283,0.000000
52.670002,21.441208,-268.487030,-0.000642,0.002821,0.071659,95.375259,4.858647,0.716587,-268.487030,0.072682,0.000000
52.910004,21.793472,-268.620453,-0.000617,0.002838,0.072075,96.942207,4.938472,0.720750,-268.620453,0.073081,0.000000
53.150002,22.214996,-268.531494,-0.000586,0.002859,0.072613,98.817238,5.033990,0.726132,-268.531494,0.073480,0.000000
53.390003,21.910767,-268.575989,-0.000573,0.002871,0.072934,97.463959,4.965051,0.729342,-268.575989,0.073879,0.000000
53.630001,21.655319,-268.709412,-0.000552,0.002885,0.073272,96.327667,4.907166,0.732718,-268.709412,0.074278,0.000000
53.870003,21.944283,-268.664948,-0.000535,0.002900,0.073671,97.613045,4.972645,0.736707,-268.664948,0.074686,0.000000
54.110004,22.468208,-268.709412,-0.000526,0.002921,0.074192,99.943581,5.091369,0.741915,-268.709412,0.075085,0.000000
54.350002,22.376236,-268.664948,-0.000492,0.002934,0.074512,99.534470,5.070528,0.745125,-268.664948,0.075484,0.000000
54.590004,22.197495,-268.709412,-0.000496,0.002947,0.074859,98.739388,5.030024,0.748592,-268.709412,0.075883,0.000000
54.830002,22.419800,-268.709412,-0.000448,0.002961,0.075198,99.728249,5.080399,0.751975,-268.709412,0.076282,0.000000
55.070004,22.871490,-268.709412,-0.000435,0.002981,0.075726,101.737473,5.182754,0.757259,-268.709412,0.076680,0.000000
55.310001,23.559631,-268.798401,-0.000410,0.003001,0.076238,104.798477,5.338689,0.762376,-268.798401,0.077079,0.000000
55.550003,23.250565,-268.798401,-0.000388,0.003014,0.076559,103.423676,5.268653,0.765586,-268.798401,0.077478,0.000000
55.790001,23.348495,-268.798401,-0.000397,0.003027,0.076889,103.859299,5.290845,0.768886,-268.798401,0.077886,0.000000
56.030003,23.641556,-268.798401,-0.000349,0.003044,0.077313,105.162895,5.357253,0.773133,-268.798401,0.078284,0.000000
56.270004,23.829605,-268.887360,-0.000328,0.003059,0.077686,105.999374,5.399866,0.776865,-268.887360,0.078683,0.000000
56.510002,23.980415,-268.931824,-0.000315,0.003070,0.077990,106.670212,5.434040,0.779900,-268.931824,0.079082,0.000000
56.750004,24.469337,-268.887360,-0.000306,0.003089,0.078458,108.845047,5.544831,0.784578,-268.887360,0.079481,0.000000
56.990002,25.523895,-268.931824,-0.000293,0.003114,0.079091,113.535957,5.783797,0.790914,-268.931824,0.079880,0.000000
57.230003,25.665024,-268.976318,-0.000263,0.003128,0.079446,114.163727,5.815778,0.794465,-268.976318,0.080279,0.000000
57.470001,25.565605,-268.976318,-0.000250,0.003140,0.079759,113.721489,5.793249,0.797591,-268.976318,0.080678,0.000000
57.710003,25.738380,-269.020782,-0.000246,0.003155,0.080149,114.490036,5.832400,0.801489,-269.020782,0.081086,0.000000
57.950005,26.371048,-268.976318,-0.000229,0.003170,0.080530,117.304283,5.975765,0.805305,-268.976318,0.081485,0.000000
58.190002,26.445518,-268.976318,-0.000203,0.003184,0.080886,117.635544,5.992640,0.808862,-268.976318,0.081884,0.000000
58.430004,26.830551,-269.109741,-0.000207,0.003197,0.081207,119.348251,6.079890,0.812072,-269.109741,0.082283,0.000000
58.670002,26.604897,-269.109741,-0.000185,0.003202,0.081337,118.344490,6.028756,0.813374,-269.109741,0.082681,0.000000
58.910004,29.086388,-269.154236,-0.000168,0.003240,0.082300,129.382721,6.591070,0.822995,-269.154236,0.083080,0.000000
59.150002,28.886795,-269.109741,-0.000129,0.003250,0.082560,128.494888,6.545841,0.825599,-269.109741,0.083479,0.000000
59.390003,28.770241,-269.198730,-0.000138,0.003259,0.082785,127.976425,6.519430,0.827855,-269.198730,0.083887,0.000000
59.630001,29.773415,-269.198730,-0.000116,0.003281,0.083349,132.438766,6.746752,0.833494,-269.198730,0.084286,0.000000
59.870003,30.059769,-269.154236,-0.000112,0.003298,0.083774,133.712524,6.811641,0.837741,-269.154236,0.084685,0.000000
60.110004,30.500656,-269.243195,-0.000116,0.003309,0.084060,135.673691,6.911548,0.840602,-269.243195,0.085084,0.000000
60.350002,31.059959,-269.243195,-0.000069,0.003325,0.084459,138.161606,7.038288,0.844592,-269.243195,0.085483,0.000000
60.590004,31.065170,-269.243195,-0.000060,0.003334,0.084676,138.184784,7.039468,0.846757,-269.243195,0.085882,0.000000
60.830002,32.336449,-269.332153,-0.000056,0.003361,0.085361,143.839706,7.327544,0.853615,-269.332153,0.086280,0.000000
61.070004,33.147476,-269.243195,-0.000039,0.003374,0.085699,147.447342,7.511325,0.856991,-269.243195,0.086679,0.000000
61.310001,33.346329,-269.376648,-0.000030,0.003388,0.086055,148.331879,7.556386,0.860549,-269.376648,0.087087,0.000000
61.550003,34.191986,-269.332153,-0.000004,0.003406,0.086514,152.093552,7.748014,0.865144,-269.332153,0.087486,0.000000
61.790005,34.808258,-269.376648,0.000026,0.003421,0.086896,154.834869,7.887664,0.868959,-269.376648,0.087885,0.000000
62.030003,35.535873,-269.376648,0.000000,0.003441,0.087399,158.071457,8.052544,0.873993,-269.376648,0.088283,0.000000
62.270004,35.880692,-269.376648,0.000022,0.003451,0.087659,159.605286,8.130681,0.876589,-269.376648,0.088682,0.000000
62.510002,36.145821,-269.465607,0.000043,0.003463,0.087954,160.784637,8.190760,0.879541,-269.465607,0.089081,0.000000
62.750004,37.277092,-269.421112,0.000056,0.003486,0.088544,165.816788,8.447109,0.885438,-269.421112,0.089480,0.000000
62.990002,38.180840,-269.465607,0.000056,0.003501,0.088917,169.836853,8.651902,0.889170,-269.465607,0.089879,0.000000
63.230003,38.613907,-269.510071,0.000095,0.003514,0.089246,171.763229,8.750036,0.892463,-269.510071,0.090287,0.000000
63.470001,39.237999,-269.421112,0.000082,0.003530,0.089671,174.539337,8.891459,0.896710,-269.421112,0.090686,0.000000
63.710003,40.050888,-269.554565,0.000091,0.003547,0.090087,178.155243,9.075661,0.900873,-269.554565,0.091085,0.000000
63.950005,40.985176,-269.643524,0.000099,0.003562,0.090469,182.311172,9.287374,0.904688,-269.643524,0.091484,0.000000
64.190002,41.430534,-269.554565,0.000121,0.003574,0.090790,184.292221,9.388293,0.907898,-269.554565,0.091883,0.000000
64.430000,42.330559,-269.599030,0.000116,0.003591,0.091206,188.295731,9.592241,0.912061,-269.599030,0.092282,0.000000
64.670006,43.473366,-269.554565,0.000129,0.003611,0.091718,193.379196,9.851205,0.917178,-269.554565,0.092681,0.000000
64.910004,44.523087,-269.599030,0.000134,0.003628,0.092143,198.048584,10.089076,0.921425,-269.599030,0.093080,0.000000
65.150002,44.927109,-269.688019,0.000168,0.003641,0.092490,199.845764,10.180628,0.924900,-269.688019,0.093487,0.000000
65.389999,45.677071,-269.688019,0.000151,0.003655,0.092828,203.181763,10.350573,0.928276,-269.688019,0.093886,0.000000
65.630005,46.283661,-269.776978,0.000160,0.003668,0.093175,205.880005,10.488028,0.931750,-269.776978,0.094285,0.000000
65.870003,47.420517,-269.732483,0.000177,0.003685,0.093609,210.936996,10.745643,0.936088,-269.732483,0.094684,0.000000
66.110001,48.029343,-269.821442,0.000190,0.003699,0.093964,213.645187,10.883605,0.939638,-269.821442,0.095083,0.000000
66.350006,48.914101,-269.732483,0.000220,0.003714,0.094328,217.580780,11.084093,0.943279,-269.732483,0.095482,0.000000
66.590004,49.560165,-269.776978,0.000203,0.003724,0.094588,220.454620,11.230494,0.945883,-269.776978,0.095880,0.000000
66.830002,51.779137,-269.865936,0.000216,0.003754,0.095351,230.325104,11.733319,0.953513,-269.865936,0.096279,0.000000
67.070000,52.288170,-269.821442,0.000220,0.003766,0.095664,232.589401,11.848668,0.956640,-269.821442,0.096687,0.000000
67.310005,52.892899,-269.910400,0.000224,0.003779,0.095985,235.279358,11.985703,0.959849,-269.910400,0.097086,0.000000
67.550003,53.745262,-269.910400,0.000237,0.003795,0.096401,239.070862,12.178850,0.964013,-269.910400,0.097485,0.000000
67.790001,54.909668,-269.910400,0.000259,0.003813,0.096852,244.250397,12.442709,0.968517,-269.910400,0.097884,0.000000
68.030006,56.142967,-269.954895,0.000237,0.003829,0.097251,249.736389,12.722178,0.972506,-269.954895,0.098283,0.000000
68.270004,57.463402,-269.910400,0.000241,0.003847,0.097702,255.609970,13.021393,0.977018,-269.910400,0.098682,0.000000
68.510002,58.567482,-269.954895,0.000272,0.003863,0.098109,260.521179,13.271582,0.981090,-269.954895,0.099081,0.000000
68.750000,59.215042,-269.999359,0.000285,0.003875,0.098430,263.401672,13.418321,0.984300,-269.999359,0.099480,0.000000
68.990005,59.995529,-269.954895,0.000272,0.003890,0.098811,266.873444,13.595181,0.988115,-269.954895,0.099887,0.000000
69.230003,61.041153,-270.088348,0.000289,0.003904,0.099167,271.524597,13.832123,0.991673,-270.088348,0.100286,0.000000
69.470001,61.923676,-270.043854,0.000280,0.003917,0.099488,275.450256,14.032105,0.994882,-270.043854,0.100685,0.000000
69.710007,63.606056,-270.043854,0.000306,0.003938,0.100017,282.933868,14.413338,1.000174,-270.043854,0.101084,0.000000
69.950005,64.177269,-270.043854,0.000315,0.003948,0.100269,285.474762,14.542777,1.002687,-270.043854,0.101483,0.000000
70.190002,65.145073,-270.088348,0.000310,0.003964,0.100677,289.779755,14.762084,1.006767,-270.088348,0.101882,0.000000
70.430000,67.639961,-270.177307,0.000328,0.003983,0.101179,300.877563,15.327435,1.011793,-270.177307,0.102228,0.000000
70.670006,67.002098,-270.132812,0.000328,0.003983,0.101171,298.040222,15.182892,1.011710,-270.132812,0.101387,0.000000
70.910004,66.481895,-270.221771,0.000349,0.003983,0.101162,295.726227,15.065013,1.011619,-270.221771,0.101171,0.000000
71.150002,66.033180,-270.221771,0.000336,0.003982,0.101145,293.730255,14.963333,1.011445,-270.221771,0.101171,0.000000
71.390007,65.650749,-270.221771,0.000341,0.003982,0.101136,292.029114,14.876672,1.011362,-270.221771,0.101171,0.000000
71.630005,65.316734,-270.310730,0.000358,0.003982,0.101136,290.543335,14.800983,1.011362,-270.310730,0.101171,0.000000
71.870003,65.028526,-270.221771,0.000362,0.003982,0.101136,289.261322,14.735675,1.011362,-270.221771,0.101171,0.000000
72.110001,64.763390,-270.355225,0.000345,0.003981,0.101127,288.081940,14.675594,1.011271,-270.355225,0.101171,0.000000
72.350006,64.526558,-270.266266,0.000366,0.003981,0.101127,287.028473,14.621927,1.011271,-270.266266,0.101171,0.000000
72.590004,64.318779,-270.310730,0.000358,0.003981,0.101127,286.104218,14.574843,1.011271,-270.310730,0.101171,0.000000
72.830002,64.113976,-270.399689,0.000358,0.003981,0.101127,285.193207,14.528435,1.011271,-270.399689,0.101171,0.000000
73.070000,63.950508,-270.399689,0.000384,0.003981,0.101127,284.466064,14.491392,1.011271,-270.399689,0.101171,0.000000
73.310005,63.786659,-270.399689,0.000366,0.003981,0.101127,283.737244,14.454264,1.011271,-270.399689,0.101171,0.000000
73.550003,63.638084,-270.444183,0.000397,0.003981,0.101127,283.076324,14.420596,1.011271,-270.444183,0.101171,0.000000
73.790001,63.500298,-270.444183,0.000345,0.003981,0.101127,282.463440,14.389373,1.011271,-270.444183,0.101171,0.000000
74.030006,63.376305,-270.533142,0.000362,0.003981,0.101127,281.911896,14.361276,1.011271,-270.533142,0.101171,0.000000
74.270004,63.253044,-270.533142,0.000379,0.003981,0.101127,281.363586,14.333344,1.011271,-270.533142,0.101171,0.000000
74.510002,63.140221,-270.488678,0.000379,0.003981,0.101127,280.861725,14.307778,1.011271,-270.488678,0.101171,0.000000
74.750000,63.027763,-270.533142,0.000405,0.003981,0.101127,280.361481,14.282295,1.011271,-270.533142,0.101171,0.000000
74.990005,62.936531,-270.533142,0.000366,0.003981,0.101127,279.955658,14.261622,1.011271,-270.533142,0.101171,0.000000
75.230003,62.832268,-270.622101,0.000349,0.003981,0.101127,279.491882,14.237996,1.011271,-270.622101,0.101171,0.000000
75.470001,62.753693,-270.577637,0.000375,0.003981,0.101127,279.142365,14.220190,1.011271,-270.577637,0.101171,0.000000
75.710007,62.662468,-270.622101,0.000362,0.003981,0.101127,278.736572,14.199518,1.011271,-270.622101,0.101171,0.000000
75.950005,62.575333,-270.711060,0.000388,0.003981,0.101127,278.348969,14.179773,1.011271,-270.711060,0.101171,0.000000
76.190002,62.504578,-270.666595,0.000379,0.003981,0.101127,278.034241,14.163740,1.011271,-270.666595,0.101171,0.000000
76.430000,62.415581,-270.711060,0.000375,0.003981,0.101127,277.638367,14.143573,1.011271,-270.711060,0.101171,0.000000
76.670006,62.350418,-270.755554,0.000366,0.003981,0.101127,277.348511,14.128807,1.011271,-270.755554,0.101171,0.000000
76.910004,62.292328,-270.755554,0.000375,0.003981,0.101127,277.090118,14.115644,1.011271,-270.755554,0.101171,0.000000
77.150002,62.210777,-270.800018,0.000362,0.003981,0.101127,276.727356,14.097164,1.011271,-270.800018,0.101171,0.000000
77.390007,62.150452,-270.755554,0.000375,0.003981,0.101127,276.459015,14.083494,1.011271,-270.755554,0.101171,0.000000
77.630005,62.083054,-270.844513,0.000375,0.003981,0.101127,276.159210,14.068221,1.011271,-270.844513,0.101171,0.000000
77.870003,62.035393,-270.800018,0.000366,0.003981,0.101127,275.947205,14.057421,1.011271,-270.800018,0.101171,0.000000
78.110001,61.969482,-270.844513,0.000366,0.003981,0.101127,275.654022,14.042485,1.011271,-270.844513,0.101171,0.000000
78.350006,61.917351,-270.888977,0.000384,0.003981,0.101127,275.422119,14.030672,1.011271,-270.888977,0.101171,0.000000
78.590004,61.859627,-270.888977,0.000388,0.003981,0.101127,275.165375,14.017591,1.011271,-270.888977,0.101171,0.000000
78.830002,61.809357,-270.933472,0.000362,0.003981,0.101127,274.941742,14.006200,1.011271,-270.933472,0.101171,0.000000
79.070007,61.757599,-270.888977,0.000392,0.003981,0.101127,274.711517,13.994472,1.011271,-270.888977,0.101171,0.000000
79.310005,61.708443,-270.888977,0.000384,0.003981,0.101127,274.492859,13.983333,1.011271,-270.888977,0.101171,0.000000
79.550003,61.663017,-271.022430,0.000384,0.003981,0.101127,274.290802,13.973040,1.011271,-271.022430,0.101171,0.000000
79.790001,61.620941,-270.933472,0.000379,0.003981,0.101127,274.103638,13.963506,1.011271,-270.933472,0.101171,0.000000
80.030006,61.581093,-271.022430,0.000384,0.003981,0.101127,273.926392,13.954475,1.011271,-271.022430,0.101171,0.000000
80.270004,61.539764,-271.022430,0.000384,0.003981,0.101127,273.742554,13.945109,1.011271,-271.022430,0.101171,0.000000
80.510002,61.501404,-271.022430,0.000366,0.003981,0.101127,273.571899,13.936418,1.011271,-271.022430,0.101171,0.000000
80.750008,61.450394,-271.066925,0.000375,0.003981,0.101127,273.345001,13.924858,1.011271,-271.066925,0.101171,0.000000
80.990005,61.431770,-271.022430,0.000375,0.003981,0.101127,273.262177,13.920638,1.011271,-271.022430,0.101171,0.000000
81.230003,61.381134,-271.066925,0.000392,0.003981,0.101127,273.036926,13.909163,1.011271,-271.066925,0.101171,0.000000
81.470001,61.349480,-271.066925,0.000375,0.003981,0.101127,272.896118,13.901991,1.011271,-271.066925,0.101171,0.000000
81.710007,61.312614,-271.200348,0.000379,0.003981,0.101127,272.732117,13.893637,1.011271,-271.200348,0.101171,0.000000
81.950005,61.276863,-271.200348,0.000379,0.003981,0.101127,272.573090,13.885535,1.011271,-271.200348,0.101171,0.000000
82.190002,61.232185,-271.200348,0.000397,0.003981,0.101127,272.374359,13.875411,1.011271,-271.200348,0.101171,0.000000
82.430000,61.215424,-271.244843,0.000371,0.003981,0.101127,272.299805,13.871614,1.011271,-271.244843,0.101171,0.000000
82.670006,61.167763,-271.200348,0.000392,0.003981,0.101127,272.087799,13.860813,1.011271,-271.200348,0.101171,0.000000
82.910004,61.148399,-271.289307,0.000358,0.003981,0.101127,272.001678,13.856425,1.011271,-271.289307,0.101171,0.000000
83.150002,61.105949,-271.333801,0.000392,0.003981,0.101127,271.812836,13.846806,1.011271,-271.333801,0.101171,0.000000
83.390007,61.072433,-271.244843,0.000384,0.003981,0.101127,271.663757,13.839211,1.011271,-271.244843,0.101171,0.000000
83.630005,61.054932,-271.289307,0.000375,0.003981,0.101127,271.585907,13.835245,1.011271,-271.289307,0.101171,0.000000
83.870003,61.010994,-271.333801,0.000401,0.003981,0.101127,271.390442,13.825289,1.011271,-271.333801,0.101171,0.000000
84.110001,60.980087,-271.333801,0.000397,0.003981,0.101127,271.252991,13.818285,1.011271,-271.333801,0.101171,0.000000
84.350006,60.958488,-271.422760,0.000358,0.003981,0.101127,271.156891,13.813391,1.011271,-271.422760,0.101171,0.000000
84.590004,60.905235,-271.422760,0.000392,0.003981,0.101127,270.920013,13.801323,1.011271,-271.422760,0.101171,0.000000
84.830002,60.901146,-271.467255,0.000392,0.003981,0.101127,270.901825,13.800397,1.011271,-271.467255,0.101171,0.000000
85.070007,60.865768,-271.467255,0.000397,0.003981,0.101127,270.744446,13.792380,1.011271,-271.467255,0.101171,0.000000
85.310005,60.841560,-271.467255,0.000401,0.003981,0.101127,270.636780,13.786895,1.011271,-271.467255,0.101171,0.000000
85.550003,60.811028,-271.556213,0.000410,0.003981,0.101127,270.500946,13.779976,1.011271,-271.556213,0.101171,0.000000
85.790001,60.795013,-271.467255,0.000388,0.003981,0.101127,270.429718,13.776346,1.011271,-271.467255,0.101171,0.000000
86.030006,60.761131,-271.511719,0.000388,0.003981,0.101127,270.279022,13.768669,1.011271,-271.511719,0.101171,0.000000
86.270004,60.744743,-271.556213,0.000397,0.003981,0.101127,270.206116,13.764956,1.011271,-271.556213,0.101171,0.000000
86.510002,60.726501,-271.556213,0.000366,0.003981,0.101127,270.124969,13.760821,1.011271,-271.556213,0.101171,0.000000
86.750008,60.687401,-271.600677,0.000379,0.003981,0.101127,269.951050,13.751962,1.011271,-271.600677,0.101171,0.000000
86.990005,60.674370,-271.600677,0.000384,0.003981,0.101127,269.893066,13.749009,1.011271,-271.600677,0.101171,0.000000
87.230003,60.656120,-271.689636,0.000392,0.003981,0.101127,269.811890,13.744874,1.011271,-271.689636,0.101171,0.000000
87.470001,60.630058,-271.689636,0.000392,0.003981,0.101127,269.695984,13.738968,1.011271,-271.689636,0.101171,0.000000
87.710007,60.605850,-271.689636,0.000384,0.003981,0.101127,269.588287,13.733482,1.011271,-271.689636,0.101171,0.000000
87.950005,60.581650,-271.689636,0.000384,0.003981,0.101127,269.480652,13.727998,1.011271,-271.689636,0.101171,0.000000
88.190002,60.555954,-271.689636,0.000371,0.003981,0.101127,269.366333,13.722176,1.011271,-271.689636,0.101171,0.000000
88.430008,60.543289,-271.867584,0.000388,0.003981,0.101127,269.309998,13.719305,1.011271,-271.867584,0.101171,0.000000
88.670006,60.524673,-271.778625,0.000384,0.003981,0.101127,269.227203,13.715087,1.011271,-271.778625,0.101171,0.000000
88.910004,60.499725,-271.778625,0.000384,0.003981,0.101127,269.116211,13.709435,1.011271,-271.778625,0.101171,0.000000
89.150002,60.486694,-271.912048,0.000371,0.003981,0.101127,269.058258,13.706481,1.011271,-271.912048,0.101171,0.000000
89.390007,60.459885,-271.778625,0.000379,0.003981,0.101127,268.938995,13.700406,1.011271,-271.778625,0.101171,0.000000
89.630005,60.428604,-271.867584,0.000358,0.003981,0.101127,268.799866,13.693317,1.011271,-271.867584,0.101171,0.000000
89.870003,60.423759,-271.823090,0.000392,0.003981,0.101127,268.778320,13.692220,1.011271,-271.823090,0.101171,0.000000
90.110001,60.403656,-271.867584,0.000371,0.003981,0.101127,268.688873,13.687664,1.011271,-271.867584,0.101171,0.000000
90.350006,60.375725,-271.912048,0.000379,0.003981,0.101127,268.564636,13.681334,1.011271,-271.912048,0.101171,0.000000
90.590004,60.364182,-271.956543,0.000397,0.003981,0.101127,268.513275,13.678720,1.011271,-271.956543,0.101171,0.000000
90.830002,60.340721,-272.045502,0.000375,0.003981,0.101127,268.408936,13.673403,1.011271,-272.045502,0.101171,0.000000
91.070007,60.327316,-271.912048,0.000388,0.003981,0.101127,268.349304,13.670365,1.011271,-271.912048,0.101171,0.000000
91.310005,60.306839,-272.001007,0.000371,0.003981,0.101127,268.258209,13.665725,1.011271,-272.001007,0.101171,0.000000
91.550003,60.300880,-272.045502,0.000388,0.003981,0.101127,268.231720,13.664375,1.011271,-272.045502,0.101171,0.000000
91.790001,60.268112,-272.045502,0.000375,0.003981,0.101127,268.085937,13.656949,1.011271,-272.045502,0.101171,0.000000
92.030006,60.258057,-272.134460,0.000388,0.003981,0.101127,268.041229,13.654671,1.011271,-272.134460,0.101171,0.000000
92.270004,60.238693,-272.045502,0.000401,0.003981,0.101127,267.955078,13.650283,1.011271,-272.045502,0.101171,0.000000
92.510002,60.221939,-272.089966,0.000397,0.003981,0.101127,267.880554,13.646486,1.011271,-272.089966,0.101171,0.000000
92.750008,60.208900,-272.223419,0.000371,0.003981,0.101127,267.822571,13.643532,1.011271,-272.223419,0.101171,0.000000
92.990005,60.204803,-272.178925,0.000397,0.003981,0.101127,267.804352,13.642604,1.011271,-272.178925,0.101171,0.000000
93.230003,60.163849,-272.178925,0.000375,0.003981,0.101127,267.622162,13.633324,1.011271,-272.178925,0.101171,0.000000
93.470001,60.162727,-272.223419,0.000384,0.003981,0.101127,267.617187,13.633069,1.011271,-272.223419,0.101171,0.000000
93.710007,60.160118,-272.267914,0.000384,0.003981,0.101127,267.605560,13.632478,1.011271,-272.267914,0.101171,0.000000
93.950005,60.136292,-272.267914,0.000388,0.003981,0.101127,267.499573,13.627078,1.011271,-272.267914,0.101171,0.000000
94.190002,60.108734,-272.267914,0.000379,0.003981,0.101127,267.377014,13.620833,1.011271,-272.267914,0.101171,0.000000
94.430008,60.087135,-272.267914,0.000410,0.003981,0.101127,267.280914,13.615939,1.011271,-272.267914,0.101171,0.000000
94.670006,60.081551,-272.312378,0.000392,0.003981,0.101127,267.256073,13.614674,1.011271,-272.312378,0.101171,0.000000
94.910004,60.059578,-272.312378,0.000362,0.003981,0.101127,267.158356,13.609695,1.011271,-272.312378,0.101171,0.000000
95.150002,60.058838,-272.401337,0.000375,0.003981,0.101127,267.155060,13.609528,1.011271,-272.401337,0.101171,0.000000
95.390007,60.048035,-272.356873,0.000388,0.003981,0.101127,267.106995,13.607079,1.011271,-272.356873,0.101171,0.000000
95.630005,60.026443,-272.401337,0.000379,0.003981,0.101127,267.010956,13.602186,1.011271,-272.401337,0.101171,0.000000
95.870003,60.007820,-272.401337,0.000392,0.003981,0.101127,266.928101,13.597967,1.011271,-272.401337,0.101171,0.000000
96.110008,59.998512,-272.445831,0.000392,0.003981,0.101127,266.886719,13.595857,1.011271,-272.445831,0.101171,0.000000
96.350006,59.988083,-272.490295,0.000388,0.003981,0.101127,266.840332,13.593493,1.011271,-272.490295,0.101171,0.000000
96.590004,59.970955,-272.490295,0.000392,0.003981,0.101127,266.764130,13.589613,1.011271,-272.490295,0.101171,0.000000
96.830002,59.954575,-272.579254,0.000397,0.003981,0.101127,266.691254,13.585900,1.011271,-272.579254,0.101171,0.000000
97.070007,59.956802,-272.534790,0.000401,0.003981,0.101127,266.701172,13.586406,1.011271,-272.534790,0.101171,0.000000
97.310005,59.936325,-272.490295,0.000392,0.003981,0.101127,266.610077,13.581765,1.011271,-272.490295,0.101171,0.000000
97.550003,59.908401,-272.579254,0.000401,0.003981,0.101127,266.485870,13.575438,1.011271,-272.579254,0.101171,0.000000
97.790001,59.909515,-272.623749,0.000375,0.003981,0.101127,266.490845,13.575690,1.011271,-272.623749,0.101171,0.000000
98.030006,59.902809,-272.623749,0.000375,0.003981,0.101127,266.460999,13.574170,1.011271,-272.623749,0.101171,0.000000
98.270004,59.881218,-272.712708,0.000379,0.003981,0.101127,266.364960,13.569278,1.011271,-272.712708,0.101171,0.000000
98.510002,59.872276,-272.668243,0.000375,0.003981,0.101127,266.325195,13.567252,1.011271,-272.668243,0.101171,0.000000
98.750008,59.855522,-272.712708,0.000392,0.003981,0.101127,266.250671,13.563455,1.011271,-272.712708,0.101171,0.000000
98.990005,59.840630,-272.668243,0.000410,0.003981,0.101127,266.184418,13.560081,1.011271,-272.668243,0.101171,0.000000
99.230003,59.832062,-272.801666,0.000397,0.003981,0.101127,266.146301,13.558139,1.011271,-272.801666,0.101171,0.000000
99.470001,59.822006,-272.757202,0.000388,0.003981,0.101127,266.101562,13.555861,1.011271,-272.757202,0.101171,0.000000
99.710007,59.801155,-272.801666,0.000384,0.003981,0.101127,266.008820,13.551136,1.011271,-272.801666,0.101171,0.000000
99.950005,59.787003,-272.801666,0.000362,0.003981,0.101127,265.945862,13.547928,1.011271,-272.801666,0.101171,0.000000
100.190002,59.770622,-272.801666,0.000397,0.003981,0.101127,265.873016,13.544217,1.011271,-272.801666,0.101171,0.000000
100.430008,59.777695,-272.846161,0.000392,0.003981,0.101127,265.904480,13.545819,1.011271,-272.846161,0.101171,0.000000
100.670006,59.749763,-272.801666,0.000388,0.003981,0.101127,265.780212,13.539490,1.011271,-272.801666,0.101171,0.000000
100.910004,59.740456,-272.890625,0.000384,0.003981,0.101127,265.738831,13.537381,1.011271,-272.890625,0.101171,0.000000
101.000008,59.749023,-272.846161,0.000379,0.003981,0.101127,265.776917,13.539322,1.011271,-272.846161,0.101171,0.000000