File: Data/compression 13/AutoNoHeating-15-13-4-240724_07242024_170251.csv
Time (sec),S:Load (lbs),S:HL1 (DIM),S:LVDT (in),S:Position (in),Ch:Position (mm),Ch:Load (N),Ch:Stress (MPa),Ch:Strain (mm/mm),Ch:HL1 (DIM),Set Point (),Cycles ()
0.110000,-0.007072,-371.771790,-0.008847,-0.004118,-0.104605,-0.031460,-0.001603,-1.046047,-371.771790,-0.104440,0.000000
0.320000,-0.011543,-371.727295,-0.008830,-0.004118,-0.104605,-0.051347,-0.002616,-1.046047,-371.727295,-0.104440,0.000000
0.530000,-0.013779,-371.771790,-0.008852,-0.004054,-0.102966,-0.061291,-0.003122,-1.029658,-371.771790,-0.102376,0.000000
0.740000,-0.048035,-371.771790,-0.008817,-0.003937,-0.099991,-0.213669,-0.010885,-0.999909,-371.771790,-0.098872,0.000000
0.950000,-0.029785,-371.816284,-0.008679,-0.003800,-0.096522,-0.132491,-0.006749,-0.965220,-371.816284,-0.095369,0.000000
1.160000,-0.004471,-371.816284,-0.008550,-0.003656,-0.092871,-0.019887,-0.001013,-0.928711,-371.816284,-0.091882,0.000000
1.370000,0.010803,-371.816284,-0.008416,-0.003528,-0.089601,0.048055,0.002448,-0.896013,-371.816284,-0.088379,0.000000
1.580000,0.024208,-371.771790,-0.008261,-0.003394,-0.086219,0.107683,0.005486,-0.862191,-371.771790,-0.084876,0.000000
1.790000,0.022346,-371.905243,-0.008140,-0.003262,-0.082846,0.099402,0.005064,-0.828461,-371.905243,-0.081389,0.000000
2.000000,0.011543,-371.860748,-0.008006,-0.003119,-0.079221,0.051347,0.002616,-0.792209,-371.860748,-0.077886,0.000000
2.210000,0.002983,-371.860748,-0.007851,-0.002971,-0.075457,0.013269,0.000676,-0.754572,-371.860748,-0.074382,0.000000
2.420000,-0.021965,-371.860748,-0.007666,-0.002830,-0.071893,-0.097705,-0.004977,-0.718926,-371.860748,-0.070878,0.000000
2.630000,-0.056969,-371.816284,-0.007502,-0.002699,-0.068563,-0.253409,-0.012909,-0.685626,-371.816284,-0.067392,0.000000
2.840000,-0.065536,-371.860748,-0.007403,-0.002558,-0.064981,-0.291521,-0.014851,-0.649813,-371.860748,-0.063888,0.000000
3.050000,-0.029045,-371.860748,-0.007239,-0.002425,-0.061599,-0.129199,-0.006582,-0.615992,-371.860748,-0.060385,0.000000
3.260000,-0.000000,-371.949707,-0.007101,-0.002283,-0.057982,-0.000000,-0.000000,-0.579823,-371.949707,-0.056898,0.000000
3.470000,-0.000740,-371.905243,-0.006967,-0.002146,-0.054505,-0.003292,-0.000168,-0.545048,-371.905243,-0.053395,0.000000
3.680000,0.010429,-371.905243,-0.006808,-0.002007,-0.050967,0.046392,0.002363,-0.509666,-371.905243,-0.049892,0.000000
3.890000,0.026443,-371.994202,-0.006670,-0.001876,-0.047645,0.117626,0.005992,-0.476450,-371.994202,-0.046405,0.000000
4.100000,0.021599,-371.949707,-0.006528,-0.001741,-0.044211,0.096076,0.004894,-0.442114,-371.949707,-0.042902,0.000000
4.310000,0.002983,-372.083160,-0.006394,-0.001599,-0.040621,0.013269,0.000676,-0.406210,-372.083160,-0.039398,0.000000
4.520000,-0.006332,-371.994202,-0.006273,-0.001458,-0.037031,-0.028168,-0.001435,-0.370307,-371.994202,-0.035894,0.000000
4.730000,-0.015266,-371.994202,-0.006079,-0.001317,-0.033440,-0.067908,-0.003459,-0.334403,-371.994202,-0.032408,0.000000
4.940000,-0.029785,-372.038666,-0.005954,-0.001180,-0.029963,-0.132491,-0.006749,-0.299627,-372.038666,-0.028904,0.000000
5.150000,-0.048782,-372.038666,-0.005816,-0.001043,-0.026503,-0.216995,-0.011054,-0.265026,-372.038666,-0.025401,0.000000
5.360000,-0.000000,-372.172119,-0.005665,-0.000908,-0.023068,-0.000000,-0.000000,-0.230682,-372.172119,-0.021915,0.000000
5.570000,0.005959,-372.038666,-0.005540,-0.000770,-0.019556,0.026505,0.001350,-0.195558,-372.038666,-0.018411,0.000000
5.780000,0.007080,-372.038666,-0.005385,-0.000631,-0.016018,0.031494,0.001604,-0.160177,-372.038666,-0.014907,0.000000
5.990000,0.012291,-372.172119,-0.005238,-0.000495,-0.012575,0.054673,0.002785,-0.125749,-372.172119,-0.011404,0.000000
6.200000,0.019363,-372.083160,-0.005122,-0.000354,-0.008985,0.086133,0.004388,-0.089846,-372.083160,-0.007918,0.000000
6.410000,0.010056,-372.127625,-0.004984,-0.000223,-0.005654,0.044729,0.002279,-0.056539,-372.127625,-0.004414,0.000000
6.620000,0.035004,-372.172119,-0.004850,-0.000087,-0.002203,0.155704,0.007932,-0.022028,-372.172119,-0.000911,0.000000
6.830000,0.185440,-372.083160,-0.004678,0.000061,0.001553,0.824879,0.042021,0.015526,-372.083160,0.002576,0.000000
7.040000,0.744377,-372.216583,-0.004566,0.000004,0.000095,3.311155,0.168678,0.000954,-372.216583,0.000199,0.000000
7.250000,0.648674,-372.127625,-0.004570,0.000001,0.000017,2.885446,0.146992,0.000174,-372.127625,0.000199,0.000000
7.460001,0.643463,-372.127625,-0.004566,0.000000,0.000008,2.862267,0.145811,0.000083,-372.127625,0.000199,0.000000
7.670001,0.614792,-372.216583,-0.004566,0.000000,0.000008,2.734731,0.139314,0.000083,-372.216583,0.000416,0.000000
7.880001,0.592445,-372.216583,-0.004575,0.000000,0.000008,2.635329,0.134250,0.000083,-372.216583,0.000772,0.000000
8.090000,0.581650,-372.216583,-0.004579,0.000001,0.000017,2.587307,0.131804,0.000174,-372.216583,0.001119,0.000000
8.300000,0.818100,-372.261078,-0.004583,0.000031,0.000780,3.639091,0.185384,0.007804,-372.261078,0.001466,0.000000
8.510000,0.871353,-372.216583,-0.004523,0.000042,0.001067,3.875972,0.197451,0.010666,-372.216583,0.001821,0.000000
8.720000,0.920509,-372.305573,-0.004553,0.000053,0.001335,4.094630,0.208590,0.013353,-372.305573,0.002168,0.000000
8.930000,0.972641,-372.305573,-0.004531,0.000064,0.001621,4.326523,0.220404,0.016214,-372.305573,0.002515,0.000000
9.140000,1.069458,-372.305573,-0.004518,0.000077,0.001951,4.757187,0.242343,0.019515,-372.305573,0.002870,0.000000
9.350000,1.137970,-372.305573,-0.004514,0.000088,0.002238,5.061943,0.257868,0.022376,-372.305573,0.003217,0.000000
9.560000,1.303307,-372.305573,-0.004493,0.000104,0.002637,5.797397,0.295334,0.026366,-372.305573,0.003573,0.000000
9.770000,1.354691,-372.350037,-0.004480,0.000113,0.002879,6.025965,0.306977,0.028788,-372.350037,0.003920,0.000000
9.980000,1.495445,-372.350037,-0.004484,0.000125,0.003182,6.652073,0.338873,0.031823,-372.350037,0.004266,0.000000
10.190001,1.546837,-372.394531,-0.004454,0.000140,0.003556,6.880674,0.350518,0.035555,-372.394531,0.004622,0.000000
10.400001,1.837662,-372.394531,-0.004437,0.000169,0.004284,8.174328,0.416420,0.042837,-372.394531,0.004969,0.000000
10.610001,1.899475,-372.394531,-0.004437,0.000179,0.004553,8.449287,0.430427,0.045532,-372.394531,0.005316,0.000000
10.820001,1.969849,-372.438995,-0.004419,0.000189,0.004805,8.762324,0.446374,0.048045,-372.438995,0.005671,0.000000
11.030001,2.067039,-372.394531,-0.004411,0.000200,0.005091,9.194651,0.468398,0.050907,-372.394531,0.006019,0.000000
11.240001,2.170563,-372.483490,-0.004402,0.000208,0.005281,9.655146,0.491857,0.052814,-372.483490,0.006365,0.000000
11.450001,2.465851,-372.483490,-0.004368,0.000230,0.005836,10.968653,0.558770,0.058363,-372.483490,0.006721,0.000000
11.660001,2.570114,-372.438995,-0.004368,0.000241,0.006114,11.432439,0.582396,0.061141,-372.438995,0.007068,0.000000
11.870001,2.708267,-372.483490,-0.004363,0.000253,0.006426,12.046974,0.613702,0.064260,-372.483490,0.007424,0.000000
12.080001,2.901154,-372.438995,-0.004355,0.000269,0.006834,12.904976,0.657411,0.068340,-372.438995,0.007770,0.000000
12.290001,3.210594,-372.527954,-0.004312,0.000290,0.007371,14.281436,0.727531,0.073715,-372.527954,0.008117,0.000000
12.500001,3.306671,-372.572449,-0.004303,0.000301,0.007658,14.708808,0.749302,0.076576,-372.572449,0.008473,0.000000
12.710001,3.415398,-372.527954,-0.004307,0.000312,0.007935,15.192448,0.773940,0.079354,-372.527954,0.008820,0.000000
12.920001,3.573662,-372.527954,-0.004307,0.000323,0.008212,15.896441,0.809803,0.082125,-372.527954,0.009166,0.000000
13.130001,3.773621,-372.572449,-0.004277,0.000337,0.008559,16.785902,0.855115,0.085592,-372.572449,0.009522,0.000000
13.340001,4.182487,-372.527954,-0.004260,0.000358,0.009097,18.604633,0.947765,0.090974,-372.527954,0.009869,0.000000
13.550000,4.304253,-372.572449,-0.004247,0.000369,0.009384,19.146273,0.975358,0.093835,-372.572449,0.010216,0.000000
13.760000,4.458420,-372.616913,-0.004225,0.000378,0.009609,19.832043,1.010292,0.096091,-372.616913,0.010571,0.000000
13.970000,4.543694,-372.616913,-0.004212,0.000387,0.009834,20.211359,1.029616,0.098339,-372.616913,0.010919,0.000000
14.180000,5.036339,-372.616913,-0.004204,0.000407,0.010346,22.402754,1.141251,0.103456,-372.616913,0.011265,0.000000
14.390000,5.316360,-372.661407,-0.004182,0.000425,0.010797,23.648352,1.204704,0.107968,-372.661407,0.011620,0.000000
14.600000,5.463081,-372.661407,-0.004199,0.000435,0.011040,24.300999,1.237952,0.110398,-372.661407,0.011968,0.000000
14.810000,5.663040,-372.661407,-0.004174,0.000447,0.011352,25.190460,1.283263,0.113517,-372.661407,0.012323,0.000000
15.020000,5.925194,-372.705902,-0.004191,0.000460,0.011673,26.356579,1.342668,0.116726,-372.705902,0.012670,0.000000
15.230000,6.316185,-372.750366,-0.004152,0.000477,0.012106,28.095795,1.431268,0.121064,-372.750366,0.013017,0.000000
15.440001,6.645363,-372.661407,-0.004126,0.000493,0.012514,29.560051,1.505861,0.125136,-372.661407,0.013373,0.000000
15.650001,6.832291,-372.839325,-0.004139,0.000503,0.012783,30.391546,1.548219,0.127831,-372.839325,0.013719,0.000000
15.860001,6.935440,-372.705902,-0.004143,0.000512,0.013000,30.850378,1.571593,0.129996,-372.705902,0.014066,0.000000
16.070002,7.782959,-372.794861,-0.004126,0.000538,0.013676,34.620331,1.763644,0.136763,-372.794861,0.014422,0.000000
16.280001,7.920738,-372.794861,-0.004083,0.000553,0.014040,35.233204,1.794865,0.140404,-372.794861,0.014769,0.000000
16.490002,7.952385,-372.750366,-0.004079,0.000563,0.014292,35.373974,1.802036,0.142918,-372.750366,0.015115,0.000000
16.700001,8.070801,-372.883820,-0.004083,0.000572,0.014535,35.900715,1.828870,0.145348,-372.883820,0.015471,0.000000
16.910002,8.341888,-372.794861,-0.004079,0.000587,0.014899,37.106571,1.890299,0.148989,-372.794861,0.015818,0.000000
17.120001,8.913483,-372.883820,-0.004040,0.000603,0.015306,39.649151,2.019824,0.153061,-372.883820,0.016174,0.000000
17.330000,9.122757,-372.839325,-0.004036,0.000616,0.015636,40.580051,2.067246,0.156362,-372.839325,0.016520,0.000000
17.540001,9.357346,-372.794861,-0.004027,0.000628,0.015948,41.623550,2.120405,0.159480,-372.794861,0.016868,0.000000
17.750000,9.317505,-372.928284,-0.004018,0.000633,0.016078,41.446331,2.111377,0.160782,-372.928284,0.017223,0.000000
17.960001,9.467201,-372.883820,-0.003997,0.000646,0.016417,42.112213,2.145298,0.164166,-372.883820,0.017570,0.000000
18.170000,10.509842,-372.883820,-0.003992,0.000673,0.017093,46.750111,2.381564,0.170926,-372.883820,0.017917,0.000000
18.380001,10.498672,-372.928284,-0.003984,0.000683,0.017345,46.700428,2.379033,0.173447,-372.928284,0.018273,0.000000
18.590000,10.558998,-372.928284,-0.003980,0.000693,0.017596,46.968769,2.392703,0.175960,-372.928284,0.018619,0.000000
18.800001,10.833061,-372.972778,-0.003954,0.000706,0.017943,48.187862,2.454807,0.179427,-372.972778,0.018966,0.000000
19.010000,11.216606,-372.972778,-0.003945,0.000720,0.018289,49.893955,2.541719,0.182894,-372.972778,0.019322,0.000000
19.220001,11.641853,-372.972778,-0.003941,0.000737,0.018715,51.785549,2.638082,0.187148,-372.972778,0.019669,0.000000
19.430000,11.754684,-373.017242,-0.003902,0.000749,0.019027,52.287449,2.663650,0.190267,-373.017242,0.020024,0.000000
19.640001,11.859695,-373.017242,-0.003915,0.000757,0.019235,52.754559,2.687445,0.192348,-373.017242,0.020371,0.000000
19.850000,12.080505,-373.061737,-0.003885,0.000771,0.019582,53.736771,2.737482,0.195815,-373.061737,0.020718,0.000000
20.060001,12.545227,-373.017242,-0.003885,0.000788,0.020024,55.803955,2.842789,0.200244,-373.017242,0.021074,0.000000
20.270000,13.050537,-373.017242,-0.003885,0.000806,0.020466,58.051689,2.957294,0.204664,-373.017242,0.021420,0.000000
20.480001,13.031174,-373.061737,-0.003837,0.000815,0.020709,57.965557,2.952906,0.207094,-373.061737,0.021767,0.000000
20.690001,13.398705,-373.061737,-0.003859,0.000831,0.021108,59.600414,3.036190,0.211084,-373.061737,0.022123,0.000000
20.900002,13.511162,-373.150696,-0.003842,0.000842,0.021377,60.100651,3.061673,0.213771,-373.150696,0.022469,0.000000
21.110001,13.972534,-373.106232,-0.003824,0.000859,0.021819,62.152935,3.166222,0.218192,-373.106232,0.022817,0.000000
21.320002,14.454758,-373.106232,-0.003803,0.000877,0.022288,64.297974,3.275495,0.222877,-373.106232,0.023172,0.000000
21.530001,14.363152,-373.106232,-0.003803,0.000887,0.022531,63.890488,3.254737,0.225307,-373.106232,0.023519,0.000000
21.740002,14.333359,-373.106232,-0.003768,0.000895,0.022721,63.757965,3.247985,0.227215,-373.106232,0.023866,0.000000
21.950001,14.908676,-373.195190,-0.003786,0.000915,0.023233,66.317101,3.378354,0.232332,-373.195190,0.024222,0.000000
22.160002,15.476547,-373.150696,-0.003734,0.000933,0.023693,68.843117,3.507036,0.236927,-373.150696,0.024569,0.000000
22.370001,15.290359,-373.150696,-0.003717,0.000941,0.023901,68.014915,3.464845,0.239009,-373.150696,0.024924,0.000000
22.580002,15.654541,-373.195190,-0.003747,0.000957,0.024308,69.634880,3.547370,0.243081,-373.195190,0.025271,0.000000
22.790001,15.776680,-373.150696,-0.003695,0.000971,0.024664,70.178177,3.575047,0.246639,-373.150696,0.025618,0.000000
23.000002,16.154633,-373.239655,-0.003699,0.000984,0.024993,71.859398,3.660692,0.249932,-373.239655,0.025973,0.000000
23.210001,16.360558,-373.239655,-0.003712,0.000997,0.025332,72.775398,3.707355,0.253315,-373.239655,0.026320,0.000000
23.420002,16.550468,-373.284149,-0.003686,0.001009,0.025627,73.620163,3.750390,0.256268,-373.284149,0.026667,0.000000
23.630001,16.750801,-373.284149,-0.003673,0.001022,0.025947,74.511284,3.795786,0.259470,-373.284149,0.027023,0.000000
23.840002,17.376015,-373.195190,-0.003678,0.001041,0.026441,77.292374,3.937461,0.264413,-373.195190,0.027369,0.000000
24.050001,17.667961,-373.373108,-0.003652,0.001057,0.026849,78.591019,4.003617,0.268493,-373.373108,0.027717,0.000000
24.260000,17.740196,-373.328613,-0.003626,0.001069,0.027161,78.912331,4.019986,0.271612,-373.328613,0.028072,0.000000
24.470001,17.786369,-373.328613,-0.003635,0.001081,0.027465,79.117722,4.030449,0.274647,-373.328613,0.028419,0.000000
24.680000,17.815788,-373.373108,-0.003587,0.001092,0.027725,79.248581,4.037115,0.277251,-373.373108,0.028774,0.000000
24.890001,18.197472,-373.328613,-0.003609,0.001106,0.028089,80.946396,4.123606,0.280892,-373.328613,0.029122,0.000000
25.100000,18.400787,-373.328613,-0.003604,0.001119,0.028419,81.850792,4.169678,0.284193,-373.328613,0.029468,0.000000
25.310001,18.683044,-373.328613,-0.003579,0.001132,0.028757,83.106331,4.233638,0.287569,-373.328613,0.029823,0.000000
25.520000,18.902748,-373.417572,-0.003566,0.001145,0.029078,84.083626,4.283424,0.290778,-373.417572,0.030171,0.000000
25.730001,19.169365,-373.417572,-0.003557,0.001161,0.029494,85.269592,4.343840,0.294942,-373.417572,0.030518,0.000000
25.940001,20.042206,-373.373108,-0.003544,0.001184,0.030076,89.152184,4.541629,0.300755,-373.373108,0.030873,0.000000
26.150002,19.841125,-373.462067,-0.003518,0.001193,0.030309,88.257736,4.496063,0.303094,-373.462067,0.031220,0.000000
26.360001,19.587540,-373.462067,-0.003505,0.001200,0.030483,87.129730,4.438600,0.304828,-373.462067,0.031567,0.000000
26.570002,19.711540,-373.417572,-0.003488,0.001217,0.030908,87.681313,4.466699,0.309082,-373.417572,0.031923,0.000000
26.780001,20.138275,-373.506561,-0.003497,0.001230,0.031237,89.579521,4.563398,0.312375,-373.506561,0.032269,0.000000
26.990002,20.376968,-373.506561,-0.003466,0.001241,0.031532,90.641281,4.617487,0.315320,-373.506561,0.032625,0.000000
27.200001,20.958244,-373.506561,-0.003454,0.001263,0.032070,93.226929,4.749206,0.320702,-373.506561,0.032972,0.000000
27.410002,21.063995,-373.551025,-0.003484,0.001275,0.032374,93.697334,4.773170,0.323737,-373.551025,0.033318,0.000000
27.620001,21.462059,-373.506561,-0.003432,0.001292,0.032816,95.468010,4.863372,0.328158,-373.506561,0.033674,0.000000
27.830002,21.717133,-373.506561,-0.003419,0.001307,0.033197,96.602631,4.921173,0.331973,-373.506561,0.034021,0.000000
28.040001,21.685860,-373.506561,-0.003402,0.001319,0.033493,96.463524,4.914086,0.334925,-373.506561,0.034368,0.000000
28.250002,21.662399,-373.551025,-0.003389,0.001328,0.033744,96.359161,4.908770,0.337439,-373.551025,0.034723,0.000000
28.460001,21.780067,-373.639984,-0.003372,0.001341,0.034065,96.882576,4.935434,0.340648,-373.639984,0.035071,0.000000
28.670002,21.632233,-373.506561,-0.003350,0.001348,0.034246,96.224976,4.901934,0.342465,-373.506561,0.035418,0.000000
28.880001,22.580666,-373.639984,-0.003393,0.001370,0.034793,100.443817,5.116852,0.347930,-373.639984,0.035773,0.000000
29.090002,22.649559,-373.595520,-0.003376,0.001380,0.035062,100.750267,5.132463,0.350618,-373.595520,0.036120,0.000000
29.300001,22.439911,-373.551025,-0.003346,0.001388,0.035253,99.817711,5.084956,0.352525,-373.551025,0.036476,0.000000
29.510002,23.231201,-373.639984,-0.003346,0.001409,0.035799,103.337547,5.264266,0.357991,-373.639984,0.036822,0.000000
29.720001,24.167717,-373.595520,-0.003311,0.001435,0.036449,107.503372,5.476483,0.364493,-373.595520,0.037169,0.000000
29.930002,23.955093,-373.639984,-0.003294,0.001447,0.036745,106.557579,5.428302,0.367445,-373.639984,0.037525,0.000000
30.140001,23.612885,-373.684479,-0.003277,0.001454,0.036935,105.035355,5.350756,0.369353,-373.684479,0.037872,0.000000
30.350002,23.751778,-373.639984,-0.003277,0.001471,0.037360,105.653183,5.382230,0.373599,-373.639984,0.038218,0.000000
30.560001,23.864235,-373.728943,-0.003251,0.001479,0.037568,106.153419,5.407713,0.375681,-373.728943,0.038574,0.000000
30.770002,23.754387,-373.684479,-0.003277,0.001490,0.037854,105.664787,5.382821,0.378542,-373.684479,0.038921,0.000000
30.980001,24.558708,-373.817902,-0.003251,0.001508,0.038305,109.242592,5.565083,0.383054,-373.817902,0.039268,0.000000
31.190001,24.473434,-373.728943,-0.003216,0.001518,0.038557,108.863274,5.545759,0.385567,-373.728943,0.039623,0.000000
31.400002,24.599297,-373.728943,-0.003212,0.001529,0.038835,109.423134,5.574280,0.388345,-373.728943,0.039970,0.000000
31.610001,25.914520,-373.817902,-0.003216,0.001560,0.039615,115.273544,5.872314,0.396150,-373.817902,0.040317,0.000000
31.820002,26.200500,-373.684479,-0.003195,0.001573,0.039944,116.545647,5.937119,0.399443,-373.684479,0.040672,0.000000
32.030003,25.840790,-373.773437,-0.003178,0.001580,0.040127,114.945572,5.855607,0.401267,-373.773437,0.041020,0.000000
32.240002,25.956970,-373.862396,-0.003195,0.001595,0.040517,115.462372,5.881933,0.405165,-373.862396,0.041375,0.000000
32.450001,25.704872,-373.773437,-0.003147,0.001602,0.040682,114.340981,5.824808,0.406816,-373.773437,0.041722,0.000000
32.660000,26.148743,-373.817902,-0.003143,0.001617,0.041080,116.315414,5.925390,0.410805,-373.817902,0.042069,0.000000
32.870003,26.720703,-373.817902,-0.003139,0.001635,0.041523,118.859627,6.054998,0.415226,-373.817902,0.042425,0.000000
33.080002,27.107971,-373.773437,-0.003130,0.001650,0.041913,120.582275,6.142754,0.419132,-373.773437,0.042772,0.000000
33.290001,26.808960,-373.951355,-0.003113,0.001659,0.042139,119.252213,6.074997,0.421387,-373.951355,0.043118,0.000000
33.500000,27.259529,-373.862396,-0.003104,0.001675,0.042546,121.256439,6.177097,0.425460,-373.862396,0.043474,0.000000
33.710003,27.805801,-373.951355,-0.003078,0.001693,0.042997,123.686378,6.300885,0.429972,-373.951355,0.043821,0.000000
33.920002,27.769302,-373.995850,-0.003070,0.001703,0.043266,123.524025,6.292614,0.432659,-373.995850,0.044167,0.000000
34.130001,27.757759,-373.906860,-0.003061,0.001716,0.043587,123.472679,6.289998,0.435869,-373.906860,0.044523,0.000000
34.340000,28.084702,-373.951355,-0.003065,0.001730,0.043942,124.926994,6.364084,0.439419,-373.951355,0.044870,0.000000
34.550003,28.231422,-373.906860,-0.003027,0.001746,0.044341,125.579636,6.397332,0.443408,-373.906860,0.045226,0.000000
34.760002,28.983612,-373.995850,-0.003022,0.001762,0.044757,128.925552,6.567780,0.447571,-373.995850,0.045572,0.000000
34.970001,28.816414,-374.040314,-0.003031,0.001772,0.045000,128.181808,6.529893,0.450001,-374.040314,0.045920,0.000000
35.180000,28.650337,-373.995850,-0.002997,0.001781,0.045226,127.443062,6.492259,0.452257,-373.995850,0.046275,0.000000
35.390003,29.065903,-374.084808,-0.003005,0.001796,0.045616,129.291595,6.586428,0.456163,-374.084808,0.046622,0.000000
35.600002,29.727242,-373.995850,-0.002997,0.001815,0.046093,132.233368,6.736289,0.460932,-373.995850,0.046969,0.000000
35.810001,29.951035,-374.084808,-0.002962,0.001827,0.046414,133.228851,6.787002,0.464142,-374.084808,0.047324,0.000000
36.020000,29.771553,-374.040314,-0.002962,0.001837,0.046656,132.430481,6.746330,0.466564,-374.040314,0.047672,0.000000
36.230003,30.217651,-374.040314,-0.002953,0.001854,0.047090,134.414825,6.847418,0.470901,-374.040314,0.048018,0.000000
36.440002,30.365112,-374.129272,-0.002928,0.001865,0.047376,135.070770,6.880833,0.473763,-374.129272,0.048374,0.000000
36.650002,30.871910,-374.084808,-0.002923,0.001882,0.047810,137.325119,6.995675,0.478100,-374.084808,0.048721,0.000000
36.860001,31.174278,-374.129272,-0.002932,0.001896,0.048148,138.670120,7.064192,0.481484,-374.129272,0.049076,0.000000
37.070004,30.851807,-374.218231,-0.002902,0.001903,0.048330,137.235687,6.991119,0.483301,-374.218231,0.049423,0.000000
37.280003,30.888298,-374.129272,-0.002915,0.001915,0.048651,137.398010,6.999388,0.486510,-374.129272,0.049770,0.000000
37.490002,32.458221,-374.218231,-0.002884,0.001943,0.049345,144.381378,7.355138,0.493452,-374.218231,0.050126,0.000000
37.700001,32.588181,-374.173767,-0.002850,0.001957,0.049701,144.959473,7.384587,0.497010,-374.173767,0.050472,0.000000
37.910004,32.362892,-374.218231,-0.002867,0.001966,0.049943,143.957336,7.333536,0.499432,-374.218231,0.050819,0.000000
38.120003,32.210220,-374.218231,-0.002841,0.001976,0.050178,143.278214,7.298940,0.501779,-374.218231,0.051175,0.000000
38.330002,32.486145,-374.218231,-0.002811,0.001989,0.050525,144.505585,7.361466,0.505246,-374.218231,0.051522,0.000000
38.540001,32.986618,-374.307190,-0.002820,0.002006,0.050949,146.731812,7.474874,0.509492,-374.307190,0.051869,0.000000
38.750000,33.215256,-374.173767,-0.002815,0.002019,0.051288,147.748840,7.526685,0.512876,-374.173767,0.052224,0.000000
38.960003,33.272972,-374.262726,-0.002807,0.002031,0.051591,148.005569,7.539763,0.515911,-374.262726,0.052571,0.000000
39.170002,32.684998,-374.307190,-0.002785,0.002033,0.051643,145.390137,7.406527,0.516434,-374.307190,0.052918,0.000000
39.380001,34.144325,-374.218231,-0.002785,0.002062,0.052363,151.881546,7.737215,0.523633,-374.218231,0.053274,0.000000
39.590000,34.736397,-374.307190,-0.002755,0.002076,0.052718,154.515213,7.871380,0.527183,-374.307190,0.053621,0.000000
39.800003,34.571060,-374.351685,-0.002746,0.002084,0.052944,153.779755,7.833914,0.529439,-374.351685,0.053976,0.000000
40.010002,34.340187,-374.307190,-0.002725,0.002096,0.053239,152.752777,7.781598,0.532391,-374.307190,0.054323,0.000000
40.220001,34.826508,-374.440643,-0.002716,0.002112,0.053655,154.916046,7.891799,0.536554,-374.440643,0.054670,0.000000
40.430000,35.610352,-374.351685,-0.002695,0.002129,0.054080,158.402756,8.069421,0.540801,-374.351685,0.055026,0.000000
40.640003,35.583916,-374.396179,-0.002695,0.002140,0.054366,158.285156,8.063431,0.543662,-374.396179,0.055372,0.000000
40.850002,36.007675,-374.396179,-0.002703,0.002154,0.054713,160.170135,8.159456,0.547129,-374.396179,0.055719,0.000000
41.060001,35.522102,-374.351685,-0.002677,0.002158,0.054808,158.010208,8.049423,0.548083,-374.351685,0.056075,0.000000
41.270000,35.930962,-374.485138,-0.002682,0.002175,0.055242,159.828903,8.142072,0.552421,-374.485138,0.056421,0.000000
41.480003,37.297569,-374.396179,-0.002669,0.002198,0.055823,165.907867,8.451750,0.558234,-374.396179,0.056769,0.000000
41.690002,37.206337,-374.440643,-0.002656,0.002207,0.056057,165.502060,8.431076,0.560573,-374.440643,0.057124,0.000000
41.900002,37.009727,-374.485138,-0.002656,0.002216,0.056291,164.627487,8.386524,0.562912,-374.485138,0.057471,0.000000
42.110001,37.777191,-374.485138,-0.002647,0.002234,0.056742,168.041336,8.560433,0.567424,-374.485138,0.057826,0.000000
42.320004,37.958160,-374.529602,-0.002621,0.002249,0.057116,168.846329,8.601441,0.571156,-374.529602,0.058173,0.000000
42.530003,38.702530,-374.485138,-0.002617,0.002264,0.057515,172.157455,8.770119,0.575145,-374.485138,0.058521,0.000000
42.740002,39.006760,-374.529602,-0.002613,0.002278,0.057870,173.510727,8.839058,0.578695,-374.529602,0.058876,0.000000
42.950001,38.776634,-374.529602,-0.002600,0.002286,0.058052,172.487091,8.786911,0.580520,-374.529602,0.059223,0.000000
43.160004,38.875313,-374.529602,-0.002591,0.002298,0.058364,172.926025,8.809272,0.583638,-374.529602,0.059570,0.000000
43.370003,40.734200,-374.574097,-0.002561,0.002328,0.059128,181.194763,9.230501,0.591276,-374.574097,0.059925,0.000000
43.580002,40.402786,-374.529602,-0.002583,0.002335,0.059301,179.720566,9.155402,0.593010,-374.529602,0.060272,0.000000
43.790001,40.249741,-374.574097,-0.002552,0.002344,0.059535,179.039795,9.120722,0.595349,-374.574097,0.060619,0.000000
44.000004,40.686531,-374.618561,-0.002535,0.002361,0.059960,180.982727,9.219700,0.599595,-374.618561,0.060975,0.000000
44.210003,41.281212,-374.618561,-0.002531,0.002377,0.060368,183.628006,9.354456,0.603676,-374.618561,0.061321,0.000000
44.420002,41.378777,-374.663055,-0.002548,0.002387,0.060628,184.061996,9.376565,0.606280,-374.663055,0.061677,0.000000
44.630001,41.541504,-374.618561,-0.002518,0.002399,0.060922,184.785843,9.413440,0.609224,-374.618561,0.062024,0.000000
44.840004,41.961540,-374.663055,-0.002514,0.002414,0.061304,186.654251,9.508621,0.613039,-374.663055,0.062371,0.000000
45.050003,42.339867,-374.707520,-0.002509,0.002430,0.061712,188.337128,9.594352,0.617120,-374.707520,0.062726,0.000000
45.260002,42.932312,-374.618561,-0.002492,0.002445,0.062102,190.972458,9.728601,0.621018,-374.618561,0.063073,0.000000
45.470001,43.652107,-374.707520,-0.002466,0.002461,0.062518,194.174271,9.891709,0.625181,-374.707520,0.063420,0.000000
45.680000,43.817070,-374.707520,-0.002470,0.002474,0.062831,194.908066,9.929090,0.628308,-374.707520,0.063775,0.000000
45.890003,43.872551,-374.707520,-0.002427,0.002485,0.063125,195.154846,9.941663,0.631252,-374.707520,0.064123,0.000000
46.100002,43.801804,-374.796509,-0.002445,0.002495,0.063386,194.840149,9.925631,0.633856,-374.796509,0.064470,0.000000
46.310001,44.558464,-374.752014,-0.002427,0.002513,0.063836,198.205948,10.097092,0.638360,-374.752014,0.064825,0.000000
46.520000,44.580803,-374.796509,-0.002423,0.002524,0.064106,198.305313,10.102154,0.641055,-374.796509,0.065172,0.000000
46.730003,45.057068,-374.752014,-0.002419,0.002535,0.064400,200.423843,10.210077,0.644000,-374.752014,0.065519,0.000000
46.940002,45.099144,-374.796509,-0.002419,0.002547,0.064686,200.611008,10.219612,0.646861,-374.796509,0.065875,0.000000
47.150002,45.951508,-374.840973,-0.002397,0.002565,0.065146,204.402512,10.412760,0.651456,-374.840973,0.066221,0.000000
47.360001,47.324074,-374.752014,-0.002393,0.002587,0.065710,210.507996,10.723788,0.657096,-374.752014,0.066577,0.000000
47.570004,47.284225,-374.840973,-0.002376,0.002598,0.065996,210.330734,10.714758,0.659957,-374.840973,0.066924,0.000000
47.780003,47.143845,-374.840973,-0.002376,0.002606,0.066196,209.706299,10.682948,0.661955,-374.840973,0.067270,0.000000
47.990002,47.470413,-374.885468,-0.002363,0.002622,0.066603,211.158951,10.756949,0.666028,-374.885468,0.067626,0.000000
48.200001,47.768684,-374.974426,-0.002363,0.002634,0.066898,212.485718,10.824539,0.668980,-374.974426,0.067973,0.000000
48.410004,48.357780,-374.885468,-0.002350,0.002650,0.067323,215.106155,10.958030,0.673227,-374.885468,0.068320,0.000000
48.620003,49.250725,-374.929932,-0.002324,0.002667,0.067730,219.078171,11.160374,0.677299,-374.929932,0.068675,0.000000
48.830002,49.425369,-374.974426,-0.002328,0.002677,0.068008,219.855026,11.199948,0.680077,-374.974426,0.069022,0.000000
49.040001,50.087822,-374.974426,-0.002320,0.002694,0.068415,222.801758,11.350062,0.684150,-374.974426,0.069370,0.000000
49.250004,50.590523,-375.018890,-0.002298,0.002710,0.068831,225.037888,11.463976,0.688313,-375.018890,0.069725,0.000000
49.460003,50.794212,-374.974426,-0.002294,0.002722,0.069127,225.943939,11.510134,0.691266,-374.974426,0.070072,0.000000
49.670002,50.751389,-374.929932,-0.002268,0.002731,0.069370,225.753448,11.500429,0.693696,-374.929932,0.070427,0.000000
49.880001,50.815063,-375.018890,-0.002289,0.002742,0.069656,226.036697,11.514857,0.696557,-375.018890,0.070775,0.000000
50.090004,51.041840,-375.018890,-0.002289,0.002753,0.069915,227.045441,11.566246,0.699153,-375.018890,0.071121,0.000000
50.300003,52.170128,-375.063385,-0.002276,0.002774,0.070454,232.064316,11.821919,0.704535,-375.063385,0.071477,0.000000
50.510002,52.091927,-375.063385,-0.002268,0.002781,0.070627,231.716461,11.804199,0.706269,-375.063385,0.071824,0.000000
50.720001,52.241623,-375.063385,-0.002251,0.002793,0.070930,232.382339,11.838121,0.709304,-375.063385,0.072170,0.000000
50.930004,54.351112,-375.107849,-0.002242,0.002823,0.071711,241.765823,12.316138,0.717109,-375.107849,0.072526,0.000000
51.140003,55.127510,-375.063385,-0.002229,0.002838,0.072092,245.219406,12.492073,0.720924,-375.063385,0.072873,0.000000
51.350002,55.118942,-375.152344,-0.002229,0.002847,0.072326,245.181305,12.490130,0.723263,-375.152344,0.073220,0.000000
51.560001,54.992340,-375.107849,-0.002216,0.002858,0.072604,244.618149,12.461442,0.726041,-375.107849,0.073575,0.000000
51.770004,55.804855,-375.107849,-0.002220,0.002873,0.072977,248.232391,12.645561,0.729773,-375.107849,0.073922,0.000000
51.980003,55.343483,-375.196808,-0.002229,0.002880,0.073142,246.180115,12.541013,0.731416,-375.196808,0.074278,0.000000
52.190002,56.306068,-375.196808,-0.002177,0.002897,0.073584,250.461899,12.759138,0.735837,-375.196808,0.074625,0.000000
52.400002,56.603966,-375.196808,-0.002164,0.002910,0.073914,251.787018,12.826642,0.739137,-375.196808,0.074972,0.000000
52.610001,57.040016,-375.196808,-0.002195,0.002923,0.074243,253.726669,12.925452,0.742430,-375.196808,0.075327,0.000000
52.820004,57.288757,-375.152344,-0.002156,0.002939,0.074651,254.833115,12.981817,0.746510,-375.152344,0.075674,0.000000
53.030003,59.489853,-375.285797,-0.002147,0.002964,0.075292,264.624084,13.480594,0.752922,-375.285797,0.076021,0.000000
53.240002,59.609756,-375.241302,-0.002151,0.002975,0.075562,265.157440,13.507764,0.755616,-375.241302,0.076376,0.000000
53.450001,59.165146,-375.285797,-0.002126,0.002981,0.075718,263.179718,13.407014,0.757176,-375.285797,0.076724,0.000000
53.660004,59.736740,-375.285797,-0.002139,0.002995,0.076082,265.722290,13.536538,0.760817,-375.285797,0.077070,0.000000
53.870003,59.747536,-375.285797,-0.002126,0.003005,0.076325,265.770325,13.538985,0.763247,-375.285797,0.077426,0.000000
54.080002,60.638626,-375.330261,-0.002117,0.003023,0.076792,269.734070,13.740909,0.767925,-375.330261,0.077773,0.000000
54.290001,61.152496,-375.330261,-0.002108,0.003037,0.077131,272.019897,13.857354,0.771309,-375.330261,0.078119,0.000000
54.500004,61.766167,-375.330261,-0.002113,0.003050,0.077469,274.749634,13.996413,0.774692,-375.330261,0.078475,0.000000
54.710003,61.771004,-375.374756,-0.002095,0.003062,0.077773,274.771149,13.997509,0.777728,-375.374756,0.078822,0.000000
54.920002,62.570122,-375.285797,-0.002065,0.003078,0.078180,278.325806,14.178592,0.781800,-375.285797,0.079178,0.000000
55.130001,63.272041,-375.419220,-0.002078,0.003092,0.078536,281.448090,14.337649,0.785358,-375.419220,0.079524,0.000000
55.340004,63.577393,-375.285797,-0.002070,0.003104,0.078839,282.806366,14.406843,0.788394,-375.285797,0.079871,0.000000
55.550003,64.159027,-375.374756,-0.002074,0.003119,0.079213,285.393616,14.538644,0.792126,-375.374756,0.080227,0.000000
55.760002,64.438690,-375.463715,-0.002078,0.003130,0.079499,286.637604,14.602016,0.794987,-375.463715,0.080574,0.000000
55.970001,65.719650,-375.419220,-0.002065,0.003152,0.080062,292.335602,14.892285,0.800619,-375.419220,0.080921,0.000000
56.180004,66.217880,-375.419220,-0.002044,0.003165,0.080392,294.551849,15.005186,0.803919,-375.419220,0.081276,0.000000
56.390003,66.141922,-375.419220,-0.002039,0.003176,0.080661,294.213959,14.987974,0.806607,-375.419220,0.081624,0.000000
56.600002,66.118835,-375.463715,-0.002018,0.003183,0.080842,294.111267,14.982742,0.808423,-375.463715,0.081970,0.000000
56.810001,67.052734,-375.552673,-0.002035,0.003202,0.081328,298.265472,15.194366,0.813283,-375.552673,0.082326,0.000000
57.020004,67.138763,-375.463715,-0.002022,0.003201,0.081311,298.648132,15.213861,0.813109,-375.463715,0.081528,0.000000
57.230003,66.157562,-375.463715,-0.002005,0.003201,0.081311,294.283539,14.991518,0.813109,-375.463715,0.081528,0.000000
57.440002,65.244125,-375.552673,-0.002018,0.003201,0.081303,290.220367,14.784530,0.813026,-375.552673,0.081311,0.000000
57.650002,64.401443,-375.508179,-0.001979,0.003201,0.081293,286.471924,14.593575,0.812935,-375.508179,0.081311,0.000000
57.860004,63.632126,-375.552673,-0.002001,0.003201,0.081293,283.049835,14.419246,0.812935,-375.552673,0.081311,0.000000
58.070004,62.913071,-375.508179,-0.002009,0.003200,0.081285,279.851318,14.256306,0.812852,-375.508179,0.081311,0.000000
58.280003,62.241310,-375.552673,-0.001979,0.003200,0.081285,276.863190,14.104083,0.812852,-375.552673,0.081311,0.000000
58.490002,61.628014,-375.641632,-0.001983,0.003200,0.081285,274.135101,13.965108,0.812852,-375.641632,0.081311,0.000000
58.700005,61.053818,-375.641632,-0.001983,0.003200,0.081285,271.580933,13.834993,0.812852,-375.641632,0.081311,0.000000
58.910004,60.525795,-375.641632,-0.001983,0.003200,0.081285,269.232178,13.715342,0.812852,-375.641632,0.081311,0.000000
59.120003,60.010429,-375.641632,-0.001970,0.003200,0.081285,266.939728,13.598557,0.812852,-375.641632,0.081311,0.000000
59.330002,59.542732,-375.641632,-0.001975,0.003200,0.081285,264.859314,13.492577,0.812852,-375.641632,0.081311,0.000000
59.540005,59.109665,-375.641632,-0.001957,0.003200,0.081285,262.932922,13.394442,0.812852,-375.641632,0.081311,0.000000
59.750004,58.701172,-375.730591,-0.001949,0.003200,0.081285,261.115845,13.301876,0.812852,-375.730591,0.081311,0.000000
59.960003,58.309433,-375.775085,-0.001979,0.003200,0.081285,259.373322,13.213106,0.812852,-375.775085,0.081311,0.000000
60.170002,57.942276,-375.686127,-0.001953,0.003200,0.081285,257.740112,13.129908,0.812852,-375.686127,0.081311,0.000000
60.380001,57.581444,-375.641632,-0.001953,0.003200,0.081285,256.135040,13.048141,0.812852,-375.641632,0.081311,0.000000
60.590004,57.261948,-375.730591,-0.001949,0.003200,0.081285,254.713867,12.975743,0.812852,-375.730591,0.081311,0.000000
60.800003,56.950272,-375.730591,-0.001949,0.003200,0.081285,253.327454,12.905116,0.812852,-375.730591,0.081311,0.000000
61.010002,56.666153,-375.819550,-0.001970,0.003200,0.081285,252.063644,12.840734,0.812852,-375.819550,0.081311,0.000000
61.220001,56.386505,-375.730591,-0.001953,0.003200,0.081285,250.819702,12.777365,0.812852,-375.730591,0.081311,0.000000
61.430004,56.125099,-375.775085,-0.001957,0.003200,0.081285,249.656906,12.718129,0.812852,-375.775085,0.081311,0.000000
61.640003,55.867790,-375.775085,-0.001944,0.003200,0.081285,248.512344,12.659822,0.812852,-375.775085,0.081311,0.000000
61.850002,55.644737,-375.864044,-0.001970,0.003200,0.081285,247.520157,12.609278,0.812852,-375.864044,0.081311,0.000000
62.060001,55.404930,-375.864044,-0.001962,0.003200,0.081285,246.453445,12.554937,0.812852,-375.864044,0.081311,0.000000
62.270004,55.192307,-375.819550,-0.001953,0.003200,0.081285,245.507645,12.506755,0.812852,-375.819550,0.081311,0.000000
62.480003,54.980797,-375.864044,-0.001949,0.003200,0.081285,244.566803,12.458826,0.812852,-375.864044,0.081311,0.000000
62.690002,54.772270,-375.908508,-0.001932,0.003200,0.081285,243.639221,12.411574,0.812852,-375.908508,0.081311,0.000000
62.900002,54.595390,-375.819550,-0.001944,0.003200,0.081285,242.852432,12.371492,0.812852,-375.819550,0.081311,0.000000
63.110004,54.411064,-375.908508,-0.001944,0.003200,0.081285,242.032501,12.329723,0.812852,-375.908508,0.081311,0.000000
63.320004,54.223015,-375.864044,-0.001949,0.003200,0.081285,241.196014,12.287111,0.812852,-375.864044,0.081311,0.000000
63.530003,54.063644,-375.908508,-0.001919,0.003200,0.081285,240.487106,12.250998,0.812852,-375.908508,0.081311,0.000000
63.740002,53.902779,-375.953003,-0.001962,0.003200,0.081285,239.771530,12.214544,0.812852,-375.953003,0.081311,0.000000
63.950005,53.734467,-375.953003,-0.001936,0.003200,0.081285,239.022842,12.176404,0.812852,-375.953003,0.081311,0.000000
64.160004,53.593338,-375.953003,-0.001923,0.003200,0.081285,238.395081,12.144423,0.812852,-375.953003,0.081311,0.000000
64.370003,53.450348,-375.953003,-0.001944,0.003200,0.081285,237.759018,12.112022,0.812852,-375.953003,0.081311,0.000000
64.580002,53.320015,-375.997467,-0.001927,0.003200,0.081285,237.179276,12.082488,0.812852,-375.997467,0.081311,0.000000
64.790001,53.172554,-376.041962,-0.001957,0.003200,0.081285,236.523331,12.049073,0.812852,-376.041962,0.081311,0.000000
65.000000,53.040359,-375.997467,-0.001953,0.003200,0.081285,235.935303,12.019117,0.812852,-375.997467,0.081311,0.000000
65.210007,52.913383,-376.130920,-0.001932,0.003200,0.081285,235.370483,11.990344,0.812852,-376.130920,0.081311,0.000000
65.420006,52.795341,-375.997467,-0.001919,0.003200,0.081285,234.845413,11.963595,0.812852,-375.997467,0.081311,0.000000
65.630005,52.670593,-376.041962,-0.001923,0.003200,0.081285,234.290497,11.935328,0.812852,-376.041962,0.081311,0.000000
65.840004,52.556648,-376.041962,-0.001932,0.003200,0.081285,233.783646,11.909507,0.812852,-376.041962,0.081311,0.000000
66.050003,52.436371,-376.041962,-0.001953,0.003200,0.081285,233.248627,11.882251,0.812852,-376.041962,0.081311,0.000000
66.260002,52.330994,-376.130920,-0.001940,0.003200,0.081285,232.779892,11.858373,0.812852,-376.130920,0.081311,0.000000
66.470001,52.210716,-376.130920,-0.001949,0.003200,0.081285,232.244858,11.831118,0.812852,-376.130920,0.081311,0.000000
66.680000,52.125816,-376.086456,-0.001944,0.003200,0.081285,231.867218,11.811879,0.812852,-376.086456,0.081311,0.000000
66.889999,52.027512,-376.130920,-0.001932,0.003200,0.081285,231.429932,11.789602,0.812852,-376.130920,0.081311,0.000000
67.100006,51.930695,-376.175415,-0.001940,0.003200,0.081285,230.999268,11.767663,0.812852,-376.175415,0.081311,0.000000
67.310005,51.829033,-376.175415,-0.001927,0.003200,0.081285,230.547058,11.744627,0.812852,-376.175415,0.081311,0.000000
67.520004,51.746368,-376.175415,-0.001914,0.003200,0.081285,230.179337,11.725895,0.812852,-376.175415,0.081311,0.000000
67.730003,51.651787,-376.130920,-0.001923,0.003200,0.081285,229.758621,11.704462,0.812852,-376.130920,0.081311,0.000000
67.940002,51.569862,-376.264374,-0.001940,0.003200,0.081285,229.394211,11.685898,0.812852,-376.264374,0.081311,0.000000
68.150002,51.474533,-376.219879,-0.001932,0.003200,0.081285,228.970154,11.664296,0.812852,-376.219879,0.081311,0.000000
68.360001,51.415329,-376.219879,-0.001919,0.003200,0.081285,228.706802,11.650881,0.812852,-376.219879,0.081311,0.000000
68.570000,51.317398,-376.308838,-0.001923,0.003200,0.081285,228.271194,11.628688,0.812852,-376.308838,0.081311,0.000000
68.780006,51.247765,-376.219879,-0.001936,0.003200,0.081285,227.961441,11.612909,0.812852,-376.219879,0.081311,0.000000
68.990005,51.160629,-376.308838,-0.001919,0.003200,0.081285,227.573837,11.593164,0.812852,-376.308838,0.081311,0.000000
69.200005,51.086151,-376.219879,-0.001919,0.003200,0.081285,227.242554,11.576288,0.812852,-376.219879,0.081311,0.000000
69.410004,51.010185,-376.264374,-0.001940,0.003200,0.081285,226.904633,11.559073,0.812852,-376.264374,0.081311,0.000000
69.620003,50.935341,-376.353333,-0.001932,0.003200,0.081285,226.571716,11.542113,0.812852,-376.353333,0.081311,0.000000
69.830002,50.864220,-376.353333,-0.001919,0.003200,0.081285,226.255356,11.525997,0.812852,-376.353333,0.081311,0.000000
70.040001,50.803894,-376.353333,-0.001944,0.003200,0.081285,225.987015,11.512326,0.812852,-376.353333,0.081311,0.000000
70.250000,50.734634,-376.353333,-0.001923,0.003200,0.081285,225.678925,11.496633,0.812852,-376.353333,0.081311,0.000000
70.460007,50.660156,-376.353333,-0.001940,0.003200,0.081285,225.347626,11.479755,0.812852,-376.353333,0.081311,0.000000
70.670006,50.584190,-376.442291,-0.001932,0.003200,0.081285,225.009720,11.462542,0.812852,-376.442291,0.081311,0.000000
70.880005,50.526100,-376.397797,-0.001927,0.003200,0.081285,224.751312,11.449378,0.812852,-376.397797,0.081311,0.000000
71.090004,50.464661,-376.442291,-0.001914,0.003200,0.081285,224.478027,11.435455,0.812852,-376.442291,0.081311,0.000000
71.300003,50.399498,-376.486755,-0.001927,0.003200,0.081285,224.188171,11.420690,0.812852,-376.486755,0.081311,0.000000
71.510002,50.335075,-376.397797,-0.001914,0.003200,0.081285,223.901596,11.406091,0.812852,-376.397797,0.081311,0.000000
71.720001,50.283318,-376.486755,-0.001914,0.003200,0.081285,223.671371,11.394362,0.812852,-376.486755,0.081311,0.000000
71.930000,50.225601,-376.397797,-0.001932,0.003200,0.081285,223.414627,11.381285,0.812852,-376.397797,0.081311,0.000000
72.140007,50.167511,-376.486755,-0.001932,0.003200,0.081285,223.156235,11.368120,0.812852,-376.486755,0.081311,0.000000
72.350006,50.109795,-376.442291,-0.001936,0.003200,0.081285,222.899506,11.355042,0.812852,-376.442291,0.081311,0.000000
72.560005,50.044250,-376.486755,-0.001906,0.003200,0.081285,222.607941,11.340189,0.812852,-376.486755,0.081311,0.000000
72.770004,49.998825,-376.486755,-0.001936,0.003200,0.081285,222.405884,11.329896,0.812852,-376.486755,0.081311,0.000000
72.980003,49.946320,-376.486755,-0.001923,0.003200,0.081285,222.172333,11.317998,0.812852,-376.486755,0.081311,0.000000
73.190002,49.900520,-376.486755,-0.001936,0.003200,0.081285,221.968597,11.307619,0.812852,-376.486755,0.081311,0.000000
73.400002,49.842430,-376.531250,-0.001936,0.003200,0.081285,221.710205,11.294456,0.812852,-376.531250,0.081311,0.000000
73.610001,49.799606,-376.531250,-0.001932,0.003200,0.081285,221.519714,11.284752,0.812852,-376.531250,0.081311,0.000000
73.820000,49.743378,-376.575745,-0.001927,0.003200,0.081285,221.269592,11.272010,0.812852,-376.575745,0.081311,0.000000
74.030006,49.695709,-376.620209,-0.001910,0.003200,0.081285,221.057556,11.261209,0.812852,-376.620209,0.081311,0.000000
74.240005,49.649536,-376.620209,-0.001910,0.003200,0.081285,220.852173,11.250746,0.812852,-376.620209,0.081311,0.000000
74.450005,49.609695,-376.620209,-0.001923,0.003200,0.081285,220.674942,11.241717,0.812852,-376.620209,0.081311,0.000000
74.660004,49.544533,-376.664703,-0.001932,0.003200,0.081285,220.385086,11.226952,0.812852,-376.664703,0.081311,0.000000
74.870003,49.503944,-376.709167,-0.001932,0.003200,0.081285,220.204544,11.217754,0.812852,-376.709167,0.081311,0.000000
75.080002,49.456276,-376.620209,-0.001932,0.003200,0.081285,219.992508,11.206952,0.812852,-376.620209,0.081311,0.000000
75.290001,49.419411,-376.709167,-0.001919,0.003200,0.081285,219.828522,11.198599,0.812852,-376.709167,0.081311,0.000000
75.500000,49.368767,-376.664703,-0.001927,0.003200,0.081285,219.603241,11.187122,0.812852,-376.664703,0.081311,0.000000
75.710007,49.334137,-376.709167,-0.001901,0.003200,0.081285,219.449203,11.179276,0.812852,-376.709167,0.081311,0.000000
75.920006,49.293922,-376.753662,-0.001906,0.003200,0.081285,219.270325,11.170162,0.812852,-376.753662,0.081311,0.000000
76.130005,49.233971,-376.709167,-0.001914,0.003200,0.081285,219.003647,11.156577,0.812852,-376.709167,0.081311,0.000000
76.340004,49.208649,-376.709167,-0.001893,0.003200,0.081285,218.891006,11.150839,0.812852,-376.709167,0.081311,0.000000
76.550003,49.168808,-376.753662,-0.001914,0.003200,0.081285,218.713776,11.141811,0.812852,-376.753662,0.081311,0.000000
76.760002,49.122635,-376.709167,-0.001923,0.003200,0.081285,218.508392,11.131349,0.812852,-376.709167,0.081311,0.000000
76.970001,49.086136,-376.798126,-0.001927,0.003200,0.081285,218.346039,11.123077,0.812852,-376.798126,0.081311,0.000000
77.180000,49.056725,-376.709167,-0.001936,0.003200,0.081285,218.215210,11.116412,0.812852,-376.709167,0.081311,0.000000
77.390007,49.007568,-376.798126,-0.001923,0.003200,0.081285,217.996552,11.105273,0.812852,-376.798126,0.081311,0.000000
77.600006,48.971825,-376.842621,-0.001914,0.003200,0.081285,217.837555,11.097175,0.812852,-376.842621,0.081311,0.000000
77.810005,48.935326,-376.842621,-0.001927,0.003200,0.081285,217.675201,11.088903,0.812852,-376.842621,0.081311,0.000000
78.020004,48.894371,-376.798126,-0.001901,0.003200,0.081285,217.493027,11.079623,0.812852,-376.798126,0.081311,0.000000
78.230003,48.857872,-376.842621,-0.001919,0.003200,0.081285,217.330673,11.071352,0.812852,-376.842621,0.081311,0.000000
78.440002,48.826599,-376.887085,-0.001932,0.003200,0.081285,217.191559,11.064265,0.812852,-376.887085,0.081311,0.000000
78.650002,48.791222,-376.931580,-0.001919,0.003200,0.081285,217.034195,11.056249,0.812852,-376.931580,0.081311,0.000000
78.860001,48.751373,-376.887085,-0.001919,0.003200,0.081285,216.856934,11.047218,0.812852,-376.887085,0.081311,0.000000
79.070007,48.724190,-376.976074,-0.001919,0.003200,0.081285,216.736023,11.041059,0.812852,-376.976074,0.081311,0.000000
79.280006,48.690681,-376.887085,-0.001906,0.003200,0.081285,216.586975,11.033465,0.812852,-376.887085,0.081311,0.000000
79.490005,48.651955,-376.887085,-0.001919,0.003200,0.081285,216.414703,11.024691,0.812852,-376.887085,0.081311,0.000000
79.700005,48.615829,-376.931580,-0.001919,0.003200,0.081285,216.254013,11.016504,0.812852,-376.931580,0.081311,0.000000
79.910004,48.586418,-376.931580,-0.001906,0.003200,0.081285,216.123184,11.009840,0.812852,-376.931580,0.081311,0.000000
80.120003,48.534286,-377.020538,-0.001919,0.003200,0.081285,215.891281,10.998026,0.812852,-377.020538,0.081311,0.000000
80.330002,48.522369,-376.976074,-0.001910,0.003200,0.081285,215.838272,10.995326,0.812852,-376.976074,0.081311,0.000000
80.540001,48.489227,-376.931580,-0.001906,0.003200,0.081285,215.690857,10.987816,0.812852,-376.931580,0.081311,0.000000
80.750008,48.450127,-376.976074,-0.001919,0.003200,0.081285,215.516922,10.978955,0.812852,-376.976074,0.081311,0.000000
80.960007,48.421829,-377.020538,-0.001897,0.003200,0.081285,215.391052,10.972544,0.812852,-377.020538,0.081311,0.000000
81.170006,48.392784,-377.020538,-0.001897,0.003200,0.081285,215.261856,10.965961,0.812852,-377.020538,0.081311,0.000000
81.380005,48.358154,-377.020538,-0.001927,0.003200,0.081285,215.107819,10.958114,0.812852,-377.020538,0.081311,0.000000
81.590004,48.323517,-377.065033,-0.001932,0.003200,0.081285,214.953735,10.950266,0.812852,-377.065033,0.081311,0.000000
81.800003,48.307510,-377.109497,-0.001910,0.003200,0.081285,214.882538,10.946638,0.812852,-377.109497,0.081311,0.000000
82.010002,48.276604,-377.065033,-0.001927,0.003200,0.081285,214.745056,10.939635,0.812852,-377.065033,0.081311,0.000000
82.220001,48.233780,-377.153992,-0.001901,0.003200,0.081285,214.554565,10.929931,0.812852,-377.153992,0.081311,0.000000
82.430000,48.212555,-377.109497,-0.001914,0.003200,0.081285,214.460159,10.925121,0.812852,-377.109497,0.081311,0.000000
82.640007,48.196915,-377.109497,-0.001901,0.003200,0.081285,214.390579,10.921577,0.812852,-377.109497,0.081311,0.000000
82.850006,48.152603,-377.242950,-0.001932,0.003200,0.081285,214.193481,10.911535,0.812852,-377.242950,0.081311,0.000000
83.060005,48.131378,-377.153992,-0.001914,0.003200,0.081285,214.099060,10.906727,0.812852,-377.153992,0.081311,0.000000
83.270004,48.104568,-377.109497,-0.001897,0.003200,0.081285,213.979813,10.900651,0.812852,-377.109497,0.081311,0.000000
83.480003,48.078499,-377.242950,-0.001923,0.003200,0.081285,213.863846,10.894743,0.812852,-377.242950,0.081311,0.000000
83.690002,48.055038,-377.198456,-0.001927,0.003200,0.081285,213.759491,10.889428,0.812852,-377.198456,0.081311,0.000000
83.900002,48.030090,-377.198456,-0.001901,0.003200,0.081285,213.648514,10.883774,0.812852,-377.198456,0.081311,0.000000
84.110001,48.014824,-377.198456,-0.001923,0.003200,0.081285,213.580597,10.880315,0.812852,-377.198456,0.081311,0.000000
84.320007,47.964554,-377.242950,-0.001901,0.003200,0.081285,213.356995,10.868923,0.812852,-377.242950,0.081311,0.000000
84.530006,47.952263,-377.198456,-0.001932,0.003200,0.081285,213.302322,10.866138,0.812852,-377.198456,0.081311,0.000000
84.740005,47.928436,-377.198456,-0.001923,0.003200,0.081285,213.196335,10.860739,0.812852,-377.198456,0.081311,0.000000
84.950005,47.895668,-377.287415,-0.001910,0.003200,0.081285,213.050568,10.853313,0.812852,-377.287415,0.081311,0.000000
85.160004,47.872574,-377.242950,-0.001906,0.003200,0.081285,212.947845,10.848081,0.812852,-377.242950,0.081311,0.000000
85.370003,47.839066,-377.287415,-0.001940,0.003200,0.081285,212.798798,10.840487,0.812852,-377.287415,0.081311,0.000000
85.580002,47.828636,-377.287415,-0.001919,0.003200,0.081285,212.752396,10.838124,0.812852,-377.287415,0.081311,0.000000
85.790001,47.795494,-377.287415,-0.001906,0.003200,0.081285,212.604980,10.830614,0.812852,-377.287415,0.081311,0.000000
86.000008,47.771667,-377.331909,-0.001914,0.003200,0.081285,212.498993,10.825214,0.812852,-377.331909,0.081311,0.000000
86.210007,47.754166,-377.376404,-0.001944,0.003200,0.081285,212.421143,10.821249,0.812852,-377.376404,0.081311,0.000000
86.420006,47.737030,-377.287415,-0.001897,0.003200,0.081285,212.344910,10.817365,0.812852,-377.287415,0.081311,0.000000
86.630005,47.697563,-377.420868,-0.001910,0.003200,0.081285,212.169357,10.808422,0.812852,-377.420868,0.081311,0.000000
86.840004,47.683037,-377.331909,-0.001923,0.003200,0.081285,212.104736,10.805130,0.812852,-377.331909,0.081311,0.000000
87.050003,47.669266,-377.376404,-0.001906,0.003200,0.081285,212.043488,10.802010,0.812852,-377.376404,0.081311,0.000000
87.260002,47.627930,-377.376404,-0.001923,0.003200,0.081285,211.859619,10.792643,0.812852,-377.376404,0.081311,0.000000
87.400002,47.623459,-377.420868,-0.001906,0.003200,0.081285,211.839722,10.791630,0.812852,-377.420868,0.081311,0.000000