File: Data/compression 13/AutoNoHeating-10-13-4-240724_07242024_163219.csv
Time (sec),S:Load (lbs),S:HL1 (DIM),S:LVDT (in),S:Position (in),Ch:Position (mm),Ch:Load (N),Ch:Stress (MPa),Ch:Strain (mm/mm),Ch:HL1 (DIM),Set Point (),Cycles ()
0.110000,0.016380,-222.582672,-0.006385,-0.001761,-0.044731,0.072863,0.003712,-0.447314,-222.582672,-0.044922,0.000000
0.360000,0.013779,-222.582672,-0.006403,-0.001761,-0.044731,0.061291,0.003122,-0.447314,-222.582672,-0.044922,0.000000
0.610000,0.018242,-222.582672,-0.006394,-0.001673,-0.042485,0.081144,0.004134,-0.424854,-222.582672,-0.041401,0.000000
0.860000,0.042076,-222.582672,-0.006407,-0.001506,-0.038262,0.187164,0.009535,-0.382623,-222.582672,-0.037239,0.000000
1.110000,0.052879,-222.627167,-0.006342,-0.001349,-0.034264,0.235219,0.011983,-0.342639,-222.627167,-0.033059,0.000000
1.360000,0.047661,-222.671646,-0.006165,-0.001179,-0.029945,0.212006,0.010800,-0.299453,-222.671646,-0.028896,0.000000
1.610000,0.046921,-222.716125,-0.006023,-0.001022,-0.025956,0.208714,0.010632,-0.259561,-222.716125,-0.024734,0.000000
1.860000,0.027184,-222.760605,-0.005842,-0.000854,-0.021681,0.120918,0.006160,-0.216806,-222.760605,-0.020571,0.000000
2.110000,0.047287,-222.760605,-0.005644,-0.000695,-0.017648,0.210343,0.010715,-0.176482,-222.760605,-0.016408,0.000000
2.360000,0.088623,-222.760605,-0.005510,-0.000535,-0.013598,0.394215,0.020082,-0.135984,-222.760605,-0.012246,0.000000
2.610000,0.103149,-222.805084,-0.005282,-0.000357,-0.009072,0.458832,0.023374,-0.090716,-222.805084,-0.008082,0.000000
2.860000,0.082664,-222.849564,-0.005135,-0.000202,-0.005126,0.367710,0.018732,-0.051255,-222.849564,-0.003920,0.000000
3.110000,0.128838,-222.894043,-0.004980,-0.000040,-0.001006,0.573098,0.029195,-0.010060,-222.894043,0.000260,0.000000
3.360000,0.331039,-222.938522,-0.004807,0.000122,0.003096,1.472537,0.075015,0.030960,-222.938522,0.004423,0.000000
3.610000,0.669525,-222.938522,-0.004708,-0.000004,-0.000104,2.978197,0.151717,-0.001037,-222.938522,0.000078,0.000000
3.860000,0.639732,-222.938522,-0.004725,-0.000005,-0.000121,2.845672,0.144965,-0.001211,-222.938522,0.000078,0.000000
4.110000,0.594681,-222.983002,-0.004678,-0.000005,-0.000121,2.645272,0.134757,-0.001211,-222.983002,0.000269,0.000000
4.360000,0.571960,-223.027481,-0.004700,-0.000005,-0.000121,2.544207,0.129608,-0.001211,-223.027481,0.000685,0.000000
4.610000,0.586861,-222.983002,-0.004712,-0.000004,-0.000113,2.610487,0.132985,-0.001128,-222.983002,0.001101,0.000000
4.860000,0.828903,-223.071976,-0.004700,0.000029,0.000729,3.687145,0.187832,0.007290,-223.071976,0.001518,0.000000
5.110000,0.909706,-223.071976,-0.004665,0.000045,0.001145,4.046575,0.206142,0.011446,-223.071976,0.001934,0.000000
5.360000,1.010620,-223.116455,-0.004678,0.000058,0.001483,4.495463,0.229010,0.014829,-223.116455,0.002350,0.000000
5.610000,1.065353,-223.116455,-0.004626,0.000069,0.001761,4.738929,0.241413,0.017607,-223.116455,0.002767,0.000000
5.860000,1.149139,-223.205414,-0.004626,0.000085,0.002168,5.111628,0.260399,0.021680,-223.205414,0.003183,0.000000
6.110000,1.183769,-223.160934,-0.004635,0.000100,0.002532,5.265668,0.268246,0.025321,-223.160934,0.003599,0.000000
6.360000,1.468262,-223.205414,-0.004600,0.000125,0.003166,6.531154,0.332713,0.031657,-223.205414,0.004016,0.000000
6.610000,1.515556,-223.249893,-0.004579,0.000134,0.003400,6.741531,0.343430,0.033996,-223.249893,0.004431,0.000000
6.860000,1.698387,-223.249893,-0.004553,0.000152,0.003859,7.554803,0.384860,0.038591,-223.249893,0.004857,0.000000
7.110000,1.907661,-223.249893,-0.004536,0.000178,0.004510,8.485702,0.432282,0.045101,-223.249893,0.005273,0.000000
7.360000,1.954956,-223.294373,-0.004523,0.000189,0.004805,8.696079,0.442999,0.048045,-223.294373,0.005689,0.000000
7.610000,2.035759,-223.294373,-0.004501,0.000204,0.005178,9.055509,0.461310,0.051777,-223.294373,0.006106,0.000000
7.860001,2.248756,-223.383331,-0.004488,0.000221,0.005602,10.002968,0.509575,0.056024,-223.383331,0.006521,0.000000
8.110001,2.235352,-223.427811,-0.004501,0.000228,0.005802,9.943340,0.506538,0.058022,-223.427811,0.006938,0.000000
8.360001,2.473671,-223.472305,-0.004497,0.000247,0.006270,11.003438,0.560542,0.062701,-223.472305,0.007354,0.000000
8.610001,2.533623,-223.472305,-0.004475,0.000256,0.006513,11.270117,0.574127,0.065130,-223.472305,0.007770,0.000000
8.860001,2.933922,-223.472305,-0.004445,0.000282,0.007172,13.050736,0.664836,0.071724,-223.472305,0.008187,0.000000
9.110001,3.037437,-223.472305,-0.004441,0.000307,0.007805,13.511196,0.688293,0.078052,-223.472305,0.008603,0.000000
9.360001,3.118988,-223.516785,-0.004437,0.000320,0.008117,13.873952,0.706773,0.081171,-223.516785,0.009019,0.000000
9.610001,3.274643,-223.561264,-0.004411,0.000336,0.008525,14.566339,0.742045,0.085251,-223.561264,0.009436,0.000000
9.860001,3.463066,-223.605743,-0.004372,0.000351,0.008924,15.404488,0.784742,0.089240,-223.605743,0.009852,0.000000
10.110001,3.545731,-223.605743,-0.004355,0.000366,0.009288,15.772198,0.803474,0.092881,-223.605743,0.010268,0.000000
10.360001,3.721115,-223.650223,-0.004342,0.000380,0.009661,16.552347,0.843217,0.096613,-223.650223,0.010684,0.000000
10.610001,3.779205,-223.650223,-0.004381,0.000392,0.009965,16.810745,0.856380,0.099649,-223.650223,0.011100,0.000000
10.860001,4.025719,-223.650223,-0.004342,0.000410,0.010415,17.907291,0.912241,0.104153,-223.650223,0.011517,0.000000
11.110001,4.257332,-223.694702,-0.004307,0.000433,0.010988,18.937557,0.964725,0.109876,-223.694702,0.011933,0.000000
11.360001,4.347076,-223.783661,-0.004273,0.000449,0.011404,19.336761,0.985062,0.114039,-223.783661,0.012349,0.000000
11.610001,4.510918,-223.783661,-0.004290,0.000465,0.011803,20.065563,1.022189,0.118028,-223.783661,0.012766,0.000000
11.860001,4.624489,-223.783661,-0.004273,0.000478,0.012150,20.570753,1.047924,0.121503,-223.783661,0.013182,0.000000
12.110001,4.930214,-223.828140,-0.004255,0.000501,0.012723,21.930687,1.117202,0.127225,-223.828140,0.013607,0.000000
12.360001,4.937660,-223.872620,-0.004251,0.000515,0.013069,21.963810,1.118890,0.130692,-223.872620,0.014023,0.000000
12.610001,4.981224,-223.828140,-0.004208,0.000523,0.013295,22.157591,1.128762,0.132948,-223.828140,0.014439,0.000000
12.860001,5.315247,-223.917114,-0.004199,0.000545,0.013841,23.643398,1.204452,0.138414,-223.917114,0.014856,0.000000
13.110001,5.523773,-223.961594,-0.004161,0.000565,0.014344,24.570971,1.251705,0.143440,-223.961594,0.015272,0.000000
13.360001,5.591545,-223.917114,-0.004178,0.000579,0.014717,24.872435,1.267062,0.147172,-223.917114,0.015688,0.000000
13.610001,5.641441,-224.006073,-0.004156,0.000595,0.015116,25.094385,1.278369,0.151161,-224.006073,0.016105,0.000000
13.860001,5.867096,-223.961594,-0.004156,0.000611,0.015523,26.098146,1.329503,0.155234,-223.961594,0.016521,0.000000
14.110001,6.038391,-224.006073,-0.004143,0.000627,0.015931,26.860106,1.368319,0.159314,-224.006073,0.016937,0.000000
14.360001,6.141167,-224.050552,-0.004113,0.000642,0.016304,27.317274,1.391608,0.163038,-224.050552,0.017353,0.000000
14.610001,6.354538,-224.095032,-0.004100,0.000657,0.016694,28.266397,1.439959,0.166944,-224.095032,0.017769,0.000000
14.860001,6.784996,-224.095032,-0.004079,0.000685,0.017388,30.181170,1.537502,0.173878,-224.095032,0.018186,0.000000
15.110001,6.755951,-224.095032,-0.004040,0.000701,0.017796,30.051971,1.530920,0.177958,-224.095032,0.018602,0.000000
15.360001,6.701210,-224.183990,-0.004031,0.000714,0.018134,29.808472,1.518516,0.181342,-224.183990,0.019018,0.000000
15.610001,6.847183,-224.228470,-0.004023,0.000730,0.018533,30.457792,1.551594,0.185331,-224.228470,0.019435,0.000000
15.860001,7.136887,-224.228470,-0.003997,0.000747,0.018975,31.746458,1.617242,0.189752,-224.228470,0.019851,0.000000
16.110001,7.246368,-224.272949,-0.004001,0.000762,0.019365,32.233456,1.642051,0.193650,-224.272949,0.020267,0.000000
16.360001,7.222908,-224.228470,-0.004018,0.000773,0.019625,32.129101,1.636734,0.196254,-224.228470,0.020684,0.000000
16.610001,7.202431,-224.272949,-0.003980,0.000785,0.019929,32.038013,1.632094,0.199290,-224.272949,0.021100,0.000000
16.860001,7.997444,-224.317429,-0.003962,0.000818,0.020787,35.574409,1.812247,0.207874,-224.317429,0.021516,0.000000
17.110001,7.734177,-224.361923,-0.003928,0.000829,0.021056,34.403336,1.752589,0.210561,-224.361923,0.021941,0.000000
17.360001,7.851097,-224.406403,-0.003919,0.000844,0.021447,34.923424,1.779084,0.214467,-224.406403,0.022357,0.000000
17.610001,8.059631,-224.450882,-0.003906,0.000858,0.021793,35.851032,1.826339,0.217934,-224.450882,0.022774,0.000000
17.860001,8.271133,-224.495361,-0.003919,0.000877,0.022288,36.791840,1.874266,0.222877,-224.495361,0.023190,0.000000
18.110001,8.275230,-224.450882,-0.003867,0.000890,0.022609,36.810062,1.875194,0.226087,-224.450882,0.023606,0.000000
18.360001,8.264435,-224.495361,-0.003863,0.000901,0.022895,36.762043,1.872748,0.228948,-224.495361,0.024022,0.000000
18.610001,8.235390,-224.495361,-0.003846,0.000909,0.023095,36.632843,1.866166,0.230947,-224.495361,0.024438,0.000000
18.860001,9.052376,-224.539841,-0.003824,0.000945,0.024005,40.266979,2.051298,0.240053,-224.539841,0.024855,0.000000
19.110001,8.782776,-224.584320,-0.003803,0.000956,0.024282,39.067738,1.990205,0.242824,-224.584320,0.025271,0.000000
19.360001,8.944016,-224.584320,-0.003820,0.000972,0.024699,39.784969,2.026743,0.246987,-224.584320,0.025687,0.000000
19.610001,9.133179,-224.584320,-0.003803,0.000989,0.025123,40.626408,2.069608,0.251234,-224.584320,0.026104,0.000000
19.860001,9.282127,-224.628799,-0.003764,0.001009,0.025635,41.288963,2.103360,0.256351,-224.628799,0.026520,0.000000
20.110001,9.507782,-224.717758,-0.003751,0.001025,0.026034,42.292725,2.154494,0.260340,-224.717758,0.026936,0.000000
20.360001,9.419159,-224.717758,-0.003742,0.001036,0.026320,41.898510,2.134412,0.263202,-224.717758,0.027353,0.000000
20.610001,9.326439,-224.762253,-0.003734,0.001047,0.026590,41.486073,2.113401,0.265896,-224.762253,0.027769,0.000000
20.860001,9.969902,-224.717758,-0.003721,0.001077,0.027344,44.348339,2.259212,0.273436,-224.717758,0.028185,0.000000
21.110001,9.793396,-224.762253,-0.003721,0.001088,0.027647,43.563202,2.219215,0.276471,-224.762253,0.028601,0.000000
21.360001,9.921120,-224.806732,-0.003678,0.001104,0.028046,44.131344,2.248158,0.280461,-224.806732,0.029017,0.000000
21.610001,9.834724,-224.762253,-0.003695,0.001117,0.028384,43.747040,2.228580,0.283844,-224.762253,0.029434,0.000000
21.860001,10.208588,-224.851212,-0.003669,0.001137,0.028887,45.410065,2.313299,0.288871,-224.851212,0.029850,0.000000
22.110001,10.137093,-224.895691,-0.003643,0.001149,0.029182,45.092041,2.297098,0.291823,-224.895691,0.030275,0.000000
22.360001,10.411163,-224.895691,-0.003643,0.001166,0.029616,46.311169,2.359203,0.296160,-224.895691,0.030691,0.000000
22.610001,10.722839,-224.895691,-0.003617,0.001188,0.030171,47.697571,2.429830,0.301709,-224.895691,0.031107,0.000000
22.860001,10.766029,-224.984650,-0.003579,0.001205,0.030613,47.889690,2.439617,0.306130,-224.984650,0.031524,0.000000
23.110001,10.770874,-224.984650,-0.003579,0.001220,0.030995,47.911240,2.440715,0.309945,-224.984650,0.031940,0.000000
23.360001,10.744064,-224.984650,-0.003570,0.001233,0.031315,47.791985,2.434640,0.313155,-224.984650,0.032356,0.000000
23.610001,10.901947,-225.073608,-0.003557,0.001250,0.031749,48.494282,2.470417,0.317492,-225.073608,0.032773,0.000000
23.860001,11.114197,-225.029129,-0.003548,0.001266,0.032148,49.438416,2.518513,0.321481,-225.029129,0.033189,0.000000
24.110001,11.138405,-225.118088,-0.003523,0.001280,0.032512,49.546101,2.523999,0.325122,-225.118088,0.033605,0.000000
24.360001,10.990944,-225.162567,-0.003510,0.001291,0.032781,48.890160,2.490583,0.327810,-225.162567,0.034022,0.000000
24.610001,11.723030,-225.162567,-0.003488,0.001321,0.033545,52.146641,2.656476,0.335448,-225.162567,0.034438,0.000000
24.860001,11.649673,-225.162567,-0.003475,0.001335,0.033909,51.820335,2.639854,0.339089,-225.162567,0.034854,0.000000
25.110001,11.584137,-225.251541,-0.003454,0.001350,0.034299,51.528816,2.625003,0.342987,-225.251541,0.035270,0.000000
25.360001,11.548012,-225.251541,-0.003445,0.001363,0.034629,51.368122,2.616817,0.346288,-225.251541,0.035686,0.000000
25.610001,12.011993,-225.251541,-0.003410,0.001388,0.035244,53.432014,2.721956,0.352442,-225.251541,0.036103,0.000000
25.860001,11.969170,-225.296021,-0.003423,0.001403,0.035626,53.241524,2.712253,0.356257,-225.296021,0.036519,0.000000
26.110001,11.960228,-225.251541,-0.003419,0.001418,0.036007,53.201752,2.710227,0.360072,-225.251541,0.036935,0.000000
26.360001,12.255898,-225.340500,-0.003385,0.001439,0.036545,54.516956,2.777226,0.365447,-225.340500,0.037352,0.000000
26.610001,12.143806,-225.384979,-0.003380,0.001452,0.036883,54.018349,2.751826,0.368830,-225.384979,0.037768,0.000000
26.860001,12.086464,-225.473938,-0.003363,0.001466,0.037230,53.763275,2.738832,0.372305,-225.473938,0.038184,0.000000
27.110001,12.200035,-225.384979,-0.003346,0.001480,0.037595,54.268467,2.764568,0.375946,-225.384979,0.038601,0.000000
27.360001,12.150887,-225.429459,-0.003333,0.001490,0.037854,54.049843,2.753430,0.378542,-225.429459,0.039025,0.000000
27.610001,12.588051,-225.473938,-0.003294,0.001512,0.038392,55.994446,2.852493,0.383925,-225.473938,0.039442,0.000000
27.860001,12.676300,-225.473938,-0.003320,0.001529,0.038843,56.386997,2.872491,0.388429,-225.473938,0.039858,0.000000
28.110001,12.480431,-225.473938,-0.003294,0.001540,0.039112,55.515728,2.828106,0.391123,-225.473938,0.040274,0.000000
28.360001,13.202461,-225.562897,-0.003281,0.001569,0.039858,58.727482,2.991720,0.398580,-225.562897,0.040691,0.000000
28.610001,13.070648,-225.607391,-0.003260,0.001586,0.040292,58.141148,2.961851,0.402917,-225.607391,0.041107,0.000000
28.860001,12.662895,-225.607391,-0.003251,0.001594,0.040491,56.327370,2.869453,0.404908,-225.607391,0.041523,0.000000
29.110001,12.795837,-225.651871,-0.003238,0.001612,0.040950,56.918728,2.899578,0.409503,-225.651871,0.041939,0.000000
29.360001,12.712791,-225.651871,-0.003234,0.001626,0.041298,56.549320,2.880760,0.412977,-225.651871,0.042355,0.000000
29.610001,13.066551,-225.651871,-0.003212,0.001642,0.041714,58.122921,2.960923,0.417141,-225.651871,0.042772,0.000000
29.860001,13.027077,-225.785309,-0.003195,0.001655,0.042034,57.947330,2.951978,0.420343,-225.785309,0.043188,0.000000
30.110001,13.339500,-225.740829,-0.003169,0.001676,0.042563,59.337063,3.022774,0.425634,-225.740829,0.043604,0.000000
30.360001,13.831032,-225.696350,-0.003191,0.001703,0.043248,61.523502,3.134157,0.432485,-225.696350,0.044021,0.000000
30.610001,13.408386,-225.785309,-0.003147,0.001715,0.043569,59.643482,3.038384,0.435694,-225.785309,0.044437,0.000000
30.860001,12.964890,-225.785309,-0.003130,0.001724,0.043795,57.670708,2.937886,0.437950,-225.785309,0.044853,0.000000
31.110001,13.347321,-225.785309,-0.003126,0.001746,0.044342,59.371845,3.024546,0.443416,-225.785309,0.045270,0.000000
31.360001,13.395729,-225.874268,-0.003100,0.001762,0.044749,59.587177,3.035516,0.447488,-225.874268,0.045686,0.000000
31.610001,13.497009,-225.829788,-0.003074,0.001778,0.045165,60.037697,3.058466,0.451652,-225.829788,0.046102,0.000000
31.860001,13.226669,-225.874268,-0.003057,0.001788,0.045416,58.835163,2.997206,0.454165,-225.874268,0.046518,0.000000
32.110001,13.388649,-225.918747,-0.003074,0.001802,0.045781,59.555687,3.033911,0.457813,-225.918747,0.046934,0.000000
32.360001,13.689529,-226.007706,-0.003035,0.001825,0.046345,60.894070,3.102092,0.463445,-226.007706,0.047360,0.000000
32.610001,13.847412,-226.052200,-0.003035,0.001843,0.046821,61.596367,3.137868,0.468214,-226.052200,0.047776,0.000000
32.860001,13.575211,-226.007706,-0.003018,0.001857,0.047160,60.385551,3.076187,0.471598,-226.007706,0.048192,0.000000
33.110001,13.747993,-226.007706,-0.002988,0.001874,0.047602,61.154129,3.115340,0.476019,-226.007706,0.048608,0.000000
33.360001,13.901039,-226.052200,-0.002988,0.001894,0.048114,61.834911,3.150020,0.481136,-226.052200,0.049024,0.000000
33.610001,13.869011,-226.096680,-0.002975,0.001910,0.048504,61.692440,3.142763,0.485042,-226.096680,0.049441,0.000000
33.860001,13.629578,-226.096680,-0.002953,0.001921,0.048799,60.627388,3.088506,0.487987,-226.096680,0.049857,0.000000
34.110001,13.742035,-226.141159,-0.002949,0.001939,0.049241,61.127625,3.113990,0.492415,-226.141159,0.050273,0.000000
34.360001,14.124832,-226.141159,-0.002949,0.001960,0.049779,62.830391,3.200733,0.497789,-226.141159,0.050690,0.000000
34.610001,14.057434,-226.185638,-0.002928,0.001976,0.050186,62.530590,3.185460,0.501862,-226.185638,0.051106,0.000000
34.860001,13.899170,-226.230118,-0.002889,0.001990,0.050542,61.826595,3.149597,0.505420,-226.230118,0.051522,0.000000
35.110001,13.904015,-226.319077,-0.002871,0.002005,0.050933,61.848145,3.150695,0.509326,-226.319077,0.051939,0.000000
35.360001,14.132652,-226.319077,-0.002863,0.002023,0.051392,62.865177,3.202505,0.513921,-226.319077,0.052355,0.000000
35.610001,13.877945,-226.319077,-0.002859,0.002034,0.051661,61.732182,3.144787,0.516608,-226.319077,0.052771,0.000000
35.860001,14.201912,-226.319077,-0.002846,0.002054,0.052181,63.173260,3.218199,0.521808,-226.319077,0.053187,0.000000
36.110001,14.643921,-226.363556,-0.002828,0.002078,0.052780,65.139412,3.318360,0.527796,-226.363556,0.053603,0.000000
36.360001,14.515450,-226.363556,-0.002824,0.002096,0.053248,64.567947,3.289248,0.532482,-226.363556,0.054020,0.000000
36.610001,13.979980,-226.497009,-0.002790,0.002107,0.053525,62.186058,3.167909,0.535252,-226.497009,0.054436,0.000000
36.860001,14.140846,-226.408035,-0.002794,0.002123,0.053916,62.901627,3.204362,0.539158,-226.408035,0.054852,0.000000
37.110001,14.386978,-226.452515,-0.002781,0.002142,0.054418,63.996475,3.260136,0.544185,-226.452515,0.055269,0.000000
37.360001,14.353844,-226.452515,-0.002755,0.002155,0.054739,63.849087,3.252627,0.547394,-226.452515,0.055693,0.000000
37.610001,14.322937,-226.541489,-0.002759,0.002169,0.055104,63.711605,3.245624,0.551035,-226.541489,0.056110,0.000000
37.860001,13.895821,-226.541489,-0.002734,0.002174,0.055225,61.811699,3.148838,0.552254,-226.541489,0.056526,0.000000
38.110001,15.247910,-226.585968,-0.002738,0.002213,0.056214,67.826088,3.455226,0.562140,-226.585968,0.056942,0.000000
38.360001,14.676689,-226.630447,-0.002716,0.002224,0.056500,65.285172,3.325785,0.565002,-226.630447,0.057359,0.000000
38.610001,14.367615,-226.674927,-0.002690,0.002235,0.056760,63.910343,3.255748,0.567598,-226.674927,0.057775,0.000000
38.860001,14.532578,-226.674927,-0.002669,0.002255,0.057281,64.644135,3.293129,0.572806,-226.674927,0.058191,0.000000
39.110001,14.655464,-226.674927,-0.002686,0.002271,0.057688,65.190758,3.320976,0.576879,-226.674927,0.058608,0.000000
39.360001,14.704987,-226.674927,-0.002647,0.002285,0.058035,65.411049,3.332197,0.580346,-226.674927,0.059023,0.000000
39.610001,14.741852,-226.763885,-0.002639,0.002299,0.058390,65.575035,3.340551,0.583903,-226.763885,0.059440,0.000000
39.860001,14.568329,-226.763885,-0.002643,0.002307,0.058608,64.803162,3.301230,0.586076,-226.763885,0.059856,0.000000
40.110001,15.578575,-226.763885,-0.002630,0.002338,0.059379,69.296967,3.530156,0.593789,-226.763885,0.060272,0.000000
40.360001,15.189819,-226.897339,-0.002600,0.002349,0.059665,67.567688,3.442062,0.596651,-226.897339,0.060689,0.000000
40.610001,15.181252,-226.852844,-0.002570,0.002367,0.060134,67.529579,3.440121,0.601337,-226.852844,0.061105,0.000000
40.860001,15.149231,-226.852844,-0.002561,0.002381,0.060480,67.387146,3.432865,0.604804,-226.852844,0.061521,0.000000
41.110001,15.251999,-226.897339,-0.002552,0.002401,0.060975,67.844276,3.456152,0.609747,-226.897339,0.061938,0.000000
41.360001,15.635544,-226.897339,-0.002548,0.002421,0.061495,69.550369,3.543065,0.614955,-226.897339,0.062354,0.000000
41.610001,15.259819,-226.941818,-0.002531,0.002432,0.061773,67.879066,3.457925,0.617725,-226.941818,0.062770,0.000000
41.860001,15.167473,-226.941818,-0.002539,0.002442,0.062024,67.468292,3.436999,0.620238,-226.941818,0.063187,0.000000
42.110001,16.092819,-226.941818,-0.002488,0.002472,0.062796,71.584435,3.646685,0.627959,-226.941818,0.063602,0.000000
42.360001,15.511917,-226.986298,-0.002501,0.002480,0.062987,69.000450,3.515051,0.629867,-226.986298,0.064018,0.000000
42.610001,15.852264,-227.030777,-0.002483,0.002500,0.063507,70.514397,3.592175,0.635068,-227.030777,0.064444,0.000000
42.860001,15.621025,-227.075256,-0.002479,0.002512,0.063794,69.485786,3.539775,0.637936,-227.075256,0.064860,0.000000
43.110001,15.914825,-227.164215,-0.002458,0.002532,0.064305,70.792679,3.606351,0.643046,-227.164215,0.065277,0.000000
43.360001,15.640015,-227.164215,-0.002432,0.002541,0.064548,69.570259,3.544078,0.645476,-227.164215,0.065692,0.000000
43.610001,16.055206,-227.208694,-0.002445,0.002561,0.065051,71.417122,3.638162,0.650510,-227.208694,0.066108,0.000000
43.860001,16.346405,-227.208694,-0.002414,0.002582,0.065571,72.712440,3.704148,0.655710,-227.208694,0.066525,0.000000
44.110001,16.644302,-227.208694,-0.002402,0.002601,0.066065,74.037552,3.771653,0.660653,-227.208694,0.066941,0.000000
44.360001,16.194847,-227.253174,-0.002406,0.002612,0.066351,72.038277,3.669805,0.663515,-227.253174,0.067358,0.000000
44.610001,16.309540,-227.253174,-0.002389,0.002630,0.066794,72.548454,3.695795,0.667936,-227.253174,0.067774,0.000000
44.860001,16.276772,-227.297653,-0.002380,0.002644,0.067149,72.402695,3.688369,0.671493,-227.297653,0.068190,0.000000
45.110001,16.579880,-227.297653,-0.002350,0.002663,0.067644,73.750992,3.757055,0.676436,-227.297653,0.068607,0.000000
45.360001,16.706863,-227.342148,-0.002350,0.002678,0.068025,74.315842,3.785829,0.680252,-227.342148,0.069023,0.000000
45.610001,16.495354,-227.342148,-0.002337,0.002688,0.068276,73.375000,3.737901,0.682765,-227.342148,0.069439,0.000000
45.860001,17.000290,-227.386627,-0.002311,0.002711,0.068858,75.621063,3.852321,0.688578,-227.386627,0.069856,0.000000
46.110001,17.355164,-227.431107,-0.002307,0.002733,0.069413,77.199623,3.932736,0.694127,-227.431107,0.070271,0.000000
46.360001,16.933266,-227.431107,-0.002294,0.002745,0.069734,75.322929,3.837133,0.697337,-227.431107,0.070687,0.000000
46.610001,16.943321,-227.475586,-0.002281,0.002760,0.070107,75.367661,3.839411,0.701069,-227.475586,0.071104,0.000000
46.860001,17.373039,-227.520065,-0.002281,0.002780,0.070619,77.279137,3.936787,0.706186,-227.520065,0.071520,0.000000
47.110001,17.379738,-227.609024,-0.002272,0.002796,0.071008,77.308937,3.938305,0.710084,-227.609024,0.071936,0.000000
47.360001,17.442673,-227.609024,-0.002259,0.002811,0.071407,77.588882,3.952566,0.714073,-227.609024,0.072353,0.000000
47.610001,17.842598,-227.653503,-0.002255,0.002833,0.071954,79.367836,4.043190,0.719539,-227.653503,0.072777,0.000000
47.860001,17.768120,-227.653503,-0.002233,0.002847,0.072318,79.036545,4.026314,0.723180,-227.653503,0.073194,0.000000
48.110001,17.519753,-227.653503,-0.002225,0.002859,0.072631,77.931755,3.970033,0.726306,-227.653503,0.073610,0.000000
48.360001,17.811691,-227.653503,-0.002195,0.002877,0.073081,79.230362,4.036187,0.730810,-227.653503,0.074026,0.000000
48.610001,17.721947,-227.697983,-0.002207,0.002888,0.073367,78.831154,4.015851,0.733672,-227.697983,0.074443,0.000000
48.860001,18.358337,-227.742462,-0.002169,0.002909,0.073896,81.661964,4.160058,0.738963,-227.742462,0.074859,0.000000
49.110001,18.372856,-227.831436,-0.002177,0.002925,0.074295,81.726547,4.163349,0.742952,-227.831436,0.075276,0.000000
49.360001,18.090599,-227.786957,-0.002147,0.002936,0.074573,80.471001,4.099388,0.745730,-227.786957,0.075692,0.000000
49.610001,18.592926,-227.831436,-0.002173,0.002959,0.075154,82.705467,4.213217,0.751536,-227.831436,0.076108,0.000000
49.860001,19.128769,-227.875916,-0.002134,0.002982,0.075735,85.089012,4.334641,0.757350,-227.875916,0.076525,0.000000
50.110001,18.506912,-227.920395,-0.002126,0.002990,0.075951,82.322861,4.193727,0.759515,-227.920395,0.076940,0.000000
50.360001,18.570961,-227.920395,-0.002104,0.003007,0.076368,82.607758,4.208240,0.763678,-227.920395,0.077356,0.000000
50.610001,18.608940,-227.920395,-0.002108,0.003021,0.076741,82.776703,4.216846,0.767410,-227.920395,0.077773,0.000000
50.860001,18.853592,-227.920395,-0.002104,0.003037,0.077131,83.864967,4.272285,0.771309,-227.920395,0.078189,0.000000
51.110001,19.061371,-228.009354,-0.002082,0.003053,0.077556,84.789215,4.319368,0.775563,-228.009354,0.078605,0.000000
51.360001,19.493698,-228.009354,-0.002082,0.003071,0.077998,86.712303,4.417335,0.779984,-228.009354,0.079022,0.000000
51.610001,19.964005,-228.098312,-0.002082,0.003094,0.078588,88.804329,4.523908,0.785880,-228.098312,0.079438,0.000000
51.860001,19.911125,-228.098312,-0.002048,0.003111,0.079030,88.569107,4.511926,0.790301,-228.098312,0.079854,0.000000
52.110001,19.305649,-228.098312,-0.002052,0.003119,0.079221,85.875816,4.374722,0.792209,-228.098312,0.080271,0.000000
52.360001,19.638176,-228.187286,-0.002026,0.003139,0.079724,87.354973,4.450075,0.797243,-228.187286,0.080687,0.000000
52.610001,19.628120,-228.187286,-0.002022,0.003154,0.080106,87.310242,4.447796,0.801058,-228.187286,0.081112,0.000000
52.860001,19.823990,-228.142792,-0.002035,0.003170,0.080530,88.181511,4.492180,0.805305,-228.142792,0.081528,0.000000
53.110004,19.842239,-228.187286,-0.002013,0.003182,0.080834,88.262688,4.496316,0.808340,-228.187286,0.081944,0.000000
53.360004,20.100662,-228.187286,-0.001975,0.003197,0.081216,89.412209,4.554875,0.812155,-228.187286,0.082361,0.000000
53.610004,20.705399,-228.231766,-0.001979,0.003219,0.081771,92.102211,4.691911,0.817711,-228.231766,0.082777,0.000000
53.860004,21.034203,-228.231766,-0.001983,0.003240,0.082291,93.564804,4.766418,0.822912,-228.231766,0.083193,0.000000
54.110004,20.703537,-228.365204,-0.001957,0.003252,0.082595,92.093933,4.691488,0.825947,-228.365204,0.083609,0.000000
54.360004,20.747475,-228.409683,-0.001949,0.003266,0.082959,92.289375,4.701445,0.829588,-228.409683,0.084025,0.000000
54.610004,21.174583,-228.409683,-0.001923,0.003286,0.083462,94.189255,4.798229,0.834622,-228.409683,0.084442,0.000000
54.860004,21.516800,-228.409683,-0.001940,0.003305,0.083957,95.711510,4.875777,0.839565,-228.409683,0.084858,0.000000
55.110004,21.220764,-228.409683,-0.001932,0.003316,0.084234,94.394676,4.808694,0.842336,-228.409683,0.085274,0.000000
55.360004,21.450890,-228.454163,-0.001906,0.003333,0.084659,95.418320,4.860841,0.846590,-228.454163,0.085691,0.000000
55.610004,22.022110,-228.543121,-0.001927,0.003354,0.085187,97.959236,4.990282,0.851874,-228.543121,0.086107,0.000000
55.860004,22.336761,-228.498642,-0.001910,0.003372,0.085656,99.358879,5.061583,0.856560,-228.498642,0.086523,0.000000
56.110004,22.055992,-228.543121,-0.001884,0.003385,0.085977,98.109955,4.997959,0.859769,-228.543121,0.086940,0.000000
56.360004,22.338997,-228.543121,-0.001897,0.003400,0.086350,99.368820,5.062089,0.863501,-228.543121,0.087356,0.000000
56.610004,22.651047,-228.587601,-0.001858,0.003418,0.086818,100.756889,5.132801,0.868179,-228.587601,0.087772,0.000000
56.860004,22.736687,-228.632095,-0.001871,0.003432,0.087165,101.137833,5.152207,0.871654,-228.632095,0.088188,0.000000
57.110004,22.867393,-228.632095,-0.001863,0.003446,0.087520,101.719246,5.181825,0.875204,-228.632095,0.088604,0.000000
57.360004,23.379028,-228.676575,-0.001854,0.003469,0.088102,103.995110,5.297763,0.881018,-228.676575,0.089021,0.000000
57.610004,24.256340,-228.721054,-0.001832,0.003490,0.088657,107.897591,5.496565,0.886566,-228.721054,0.089437,0.000000
57.860004,23.841515,-228.721054,-0.001845,0.003501,0.088917,106.052353,5.402564,0.889170,-228.721054,0.089862,0.000000
58.110004,23.971107,-228.721054,-0.001832,0.003518,0.089351,106.628815,5.431931,0.893508,-228.721054,0.090278,0.000000
58.360004,24.152824,-228.721054,-0.001798,0.003532,0.089715,107.437126,5.473108,0.897149,-228.721054,0.090694,0.000000
58.610004,24.813408,-228.810013,-0.001798,0.003553,0.090235,110.375549,5.622799,0.902349,-228.810013,0.091111,0.000000
58.860004,24.853256,-228.854492,-0.001807,0.003566,0.090564,110.552803,5.631829,0.905642,-228.854492,0.091527,0.000000
59.110004,24.621635,-228.898972,-0.001781,0.003573,0.090747,109.522507,5.579342,0.907466,-228.898972,0.091943,0.000000
59.360004,26.128632,-228.854492,-0.001763,0.003603,0.091510,116.225960,5.920833,0.915097,-228.854492,0.092360,0.000000
59.610004,26.481270,-228.987930,-0.001776,0.003619,0.091926,117.794571,6.000741,0.919260,-228.987930,0.092776,0.000000
59.860004,26.163635,-228.854492,-0.001759,0.003630,0.092212,116.381660,5.928764,0.922122,-228.854492,0.093192,0.000000
60.110004,26.483498,-228.943451,-0.001755,0.003647,0.092628,117.804482,6.001246,0.926285,-228.943451,0.093609,0.000000
60.360004,26.839485,-228.987930,-0.001742,0.003661,0.092993,119.387993,6.081914,0.929926,-228.987930,0.094025,0.000000
60.610004,27.468430,-229.076904,-0.001742,0.003680,0.093479,122.185677,6.224435,0.934786,-229.076904,0.094441,0.000000
60.860004,27.541412,-229.032410,-0.001733,0.003694,0.093834,122.510323,6.240973,0.938336,-229.032410,0.094857,0.000000
61.110004,27.770050,-228.987930,-0.001712,0.003706,0.094129,123.527351,6.292783,0.941288,-228.987930,0.095273,0.000000
61.360004,28.789230,-229.121384,-0.001729,0.003729,0.094710,128.060898,6.523733,0.947102,-229.121384,0.095690,0.000000
61.610004,29.485199,-229.165863,-0.001681,0.003746,0.095143,131.156723,6.681441,0.951432,-229.165863,0.096106,0.000000
61.860004,29.507164,-229.121384,-0.001699,0.003759,0.095491,131.254425,6.686419,0.954906,-229.121384,0.096522,0.000000
62.110004,30.089928,-229.210342,-0.001664,0.003778,0.095968,133.846680,6.818475,0.959675,-229.210342,0.096939,0.000000
62.360004,30.631355,-229.165863,-0.001669,0.003794,0.096366,136.255066,6.941164,0.963665,-229.165863,0.097355,0.000000
62.610004,31.131454,-229.210342,-0.001643,0.003810,0.096765,138.479630,7.054489,0.967654,-229.210342,0.097771,0.000000
62.860004,31.634903,-229.299301,-0.001651,0.003826,0.097190,140.719070,7.168571,0.971900,-229.299301,0.098196,0.000000
63.110004,31.844543,-229.299301,-0.001634,0.003840,0.097528,141.651611,7.216076,0.975284,-229.299301,0.098612,0.000000
63.360004,33.249138,-229.254822,-0.001621,0.003866,0.098205,147.899551,7.534362,0.982052,-229.254822,0.099029,0.000000
63.610004,33.356010,-229.343781,-0.001604,0.003875,0.098430,148.374939,7.558580,0.984300,-229.343781,0.099445,0.000000
63.860004,33.869881,-229.343781,-0.001604,0.003892,0.098864,150.660751,7.675025,0.988637,-229.343781,0.099861,0.000000
64.110001,34.530098,-229.432739,-0.001591,0.003909,0.099289,153.597549,7.824632,0.992891,-229.432739,0.100278,0.000000
64.360001,35.059608,-229.432739,-0.001600,0.003924,0.099662,155.952927,7.944621,0.996616,-229.432739,0.100694,0.000000
64.610001,35.579071,-229.477234,-0.001578,0.003938,0.100026,158.263611,8.062333,1.000257,-229.477234,0.101110,0.000000
64.860001,36.471275,-229.521713,-0.001569,0.003956,0.100477,162.232330,8.264509,1.004768,-229.521713,0.101526,0.000000
65.110001,36.931900,-229.521713,-0.001565,0.003973,0.100902,164.281296,8.368888,1.009015,-229.521713,0.101942,0.000000
65.360001,38.052742,-229.521713,-0.001565,0.003991,0.101379,169.267044,8.622875,1.013792,-229.521713,0.102359,0.000000
65.610001,39.056282,-229.566193,-0.001561,0.004009,0.101839,173.731018,8.850280,1.018387,-229.566193,0.102775,0.000000
65.860001,39.480042,-229.566193,-0.001539,0.004024,0.102211,175.615997,8.946305,1.022111,-229.566193,0.103191,0.000000
66.110001,39.945137,-229.610672,-0.001500,0.004038,0.102567,177.684845,9.051698,1.025669,-229.610672,0.103608,0.000000
66.360001,40.978096,-229.699631,-0.001526,0.004058,0.103061,182.279678,9.285769,1.030612,-229.699631,0.104024,0.000000
66.610001,41.574638,-229.610672,-0.001518,0.004069,0.103356,184.933228,9.420947,1.033564,-229.610672,0.104440,0.000000
66.860001,42.306725,-229.744110,-0.001487,0.004084,0.103746,188.189713,9.586841,1.037462,-229.744110,0.104857,0.000000
67.110001,42.899544,-229.699631,-0.001483,0.004100,0.104137,190.826706,9.721176,1.041368,-229.699631,0.105272,0.000000
67.360001,45.011269,-229.744110,-0.001483,0.004128,0.104848,200.220123,10.199699,1.048476,-229.744110,0.105689,0.000000
67.610001,45.541893,-229.744110,-0.001500,0.004141,0.105186,202.580460,10.319941,1.051860,-229.744110,0.106105,0.000000
67.860001,45.861763,-229.788589,-0.001487,0.004152,0.105464,204.003311,10.392424,1.054638,-229.788589,0.106530,0.000000
68.110001,46.995636,-229.833069,-0.001457,0.004173,0.105992,209.047028,10.649364,1.059922,-229.833069,0.106947,0.000000
68.360001,48.171219,-229.922043,-0.001462,0.004190,0.106435,214.276291,10.915754,1.064350,-229.922043,0.107362,0.000000
68.610001,48.828827,-229.833069,-0.001436,0.004207,0.106851,217.201477,11.064770,1.068514,-229.833069,0.107779,0.000000
68.860001,50.044250,-229.922043,-0.001431,0.004225,0.107311,222.607941,11.340189,1.073109,-229.922043,0.108195,0.000000
69.110001,51.207169,-229.966522,-0.001427,0.004242,0.107745,227.780869,11.603710,1.077446,-229.966522,0.108611,0.000000
69.360001,51.902763,-229.966522,-0.001427,0.004255,0.108074,230.875015,11.761333,1.080739,-229.966522,0.109028,0.000000
69.610001,52.380142,-230.011002,-0.001423,0.004266,0.108360,232.998505,11.869510,1.083600,-230.011002,0.109444,0.000000
69.860001,53.368423,-230.011002,-0.001418,0.004282,0.108767,237.394608,12.093457,1.087673,-230.011002,0.109860,0.000000
70.110001,54.393562,-230.011002,-0.001406,0.004302,0.109279,241.954651,12.325757,1.092790,-230.011002,0.110277,0.000000
70.360001,55.639893,-230.055481,-0.001375,0.004318,0.109678,247.498596,12.608180,1.096779,-230.055481,0.110693,0.000000
70.610001,56.617371,-230.055481,-0.001375,0.004331,0.109999,251.846649,12.829679,1.099989,-230.055481,0.111109,0.000000
70.860001,57.418343,-230.144440,-0.001384,0.004344,0.110337,255.409546,13.011183,1.103373,-230.144440,0.111526,0.000000
71.110001,60.034630,-230.188919,-0.001371,0.004374,0.111109,267.047363,13.604042,1.111094,-230.188919,0.111941,0.000000
71.360001,60.784592,-230.144440,-0.001358,0.004386,0.111396,270.383362,13.773985,1.113955,-230.144440,0.112358,0.000000
71.610001,61.537155,-230.233398,-0.001362,0.004399,0.111734,273.730927,13.944519,1.117339,-230.233398,0.112774,0.000000
71.860001,62.813644,-230.233398,-0.001362,0.004416,0.112167,279.409058,14.233775,1.121669,-230.233398,0.113190,0.000000
72.110001,63.257889,-230.233398,-0.001358,0.004428,0.112480,281.385132,14.334443,1.124795,-230.233398,0.113607,0.000000
72.360001,64.691521,-230.233398,-0.001354,0.004442,0.112826,287.762268,14.659308,1.128262,-230.233398,0.114023,0.000000
72.610001,66.094627,-230.277878,-0.001315,0.004462,0.113329,294.003601,14.977257,1.133288,-230.277878,0.114439,0.000000
72.860001,67.356224,-230.277878,-0.001332,0.004478,0.113737,299.615448,15.263138,1.137369,-230.277878,0.114856,0.000000
73.110001,66.984596,-230.366852,-0.001319,0.004469,0.113511,297.962372,15.178926,1.135113,-230.366852,0.113763,0.000000
73.360001,66.513908,-230.366852,-0.001337,0.004468,0.113476,295.868652,15.072268,1.134765,-230.366852,0.113511,0.000000
73.610001,66.123665,-230.455811,-0.001315,0.004467,0.113451,294.132751,14.983836,1.134507,-230.455811,0.113511,0.000000
73.860001,65.789650,-230.411331,-0.001306,0.004466,0.113442,292.646973,14.908148,1.134416,-230.411331,0.113511,0.000000
74.110001,65.476112,-230.455811,-0.001315,0.004466,0.113433,291.252289,14.837099,1.134333,-230.455811,0.113511,0.000000
74.360001,65.210976,-230.455811,-0.001306,0.004466,0.113433,290.072906,14.777019,1.134333,-230.455811,0.113511,0.000000
74.610001,64.980858,-230.455811,-0.001293,0.004466,0.113433,289.049286,14.724873,1.134333,-230.455811,0.113511,0.000000
74.860001,64.767113,-230.500290,-0.001315,0.004466,0.113433,288.098511,14.676437,1.134333,-230.500290,0.113511,0.000000
75.110001,64.576836,-230.589249,-0.001328,0.004466,0.113433,287.252106,14.633321,1.134333,-230.589249,0.113511,0.000000
75.360001,64.402931,-230.589249,-0.001293,0.004466,0.113425,286.478546,14.593913,1.134250,-230.589249,0.113511,0.000000
75.610001,64.248405,-230.678207,-0.001302,0.004466,0.113425,285.791168,14.558897,1.134250,-230.678207,0.113511,0.000000
75.860001,64.096840,-230.633728,-0.001315,0.004466,0.113425,285.116974,14.524551,1.134250,-230.633728,0.113511,0.000000
76.110001,63.989601,-230.678207,-0.001298,0.004466,0.113425,284.639954,14.500251,1.134250,-230.678207,0.113511,0.000000
76.360001,63.854057,-230.767181,-0.001306,0.004466,0.113425,284.037018,14.469536,1.134250,-230.767181,0.113511,0.000000
76.610001,63.754265,-230.678207,-0.001289,0.004466,0.113425,283.593140,14.446922,1.134250,-230.678207,0.113511,0.000000
76.860001,63.633980,-230.767181,-0.001311,0.004466,0.113425,283.058075,14.419665,1.134250,-230.767181,0.113511,0.000000
77.110001,63.525627,-230.722687,-0.001315,0.004466,0.113425,282.576111,14.395113,1.134250,-230.722687,0.113511,0.000000
77.360001,63.436623,-230.767181,-0.001302,0.004466,0.113425,282.180176,14.374945,1.134250,-230.767181,0.113511,0.000000
77.610001,63.340187,-230.856140,-0.001285,0.004466,0.113425,281.751221,14.353092,1.134250,-230.856140,0.113511,0.000000
77.860001,63.260124,-230.856140,-0.001289,0.004466,0.113425,281.395081,14.334949,1.134250,-230.856140,0.113511,0.000000
78.110001,63.177452,-230.900620,-0.001311,0.004466,0.113425,281.027344,14.316216,1.134250,-230.900620,0.113511,0.000000
78.360001,63.101120,-230.856140,-0.001298,0.004466,0.113425,280.687805,14.298918,1.134250,-230.856140,0.113511,0.000000
78.610001,63.027763,-230.945099,-0.001319,0.004466,0.113425,280.361481,14.282295,1.134250,-230.945099,0.113511,0.000000
78.860001,62.956642,-230.989578,-0.001285,0.004466,0.113425,280.045135,14.266179,1.134250,-230.989578,0.113511,0.000000
79.110001,62.891846,-230.989578,-0.001285,0.004466,0.113425,279.756897,14.251496,1.134250,-230.989578,0.113511,0.000000
79.360001,62.825562,-230.989578,-0.001276,0.004466,0.113425,279.462067,14.236476,1.134250,-230.989578,0.113511,0.000000
79.610001,62.757790,-231.034058,-0.001285,0.004466,0.113425,279.160583,14.221118,1.134250,-231.034058,0.113511,0.000000
79.860001,62.691879,-231.078537,-0.001293,0.004466,0.113425,278.867401,14.206183,1.134250,-231.078537,0.113511,0.000000
80.110001,62.648689,-231.078537,-0.001276,0.004466,0.113425,278.675293,14.196396,1.134250,-231.078537,0.113511,0.000000
80.360001,62.602882,-231.078537,-0.001268,0.004466,0.113425,278.471527,14.186015,1.134250,-231.078537,0.113511,0.000000
80.610001,62.529526,-231.167496,-0.001289,0.004466,0.113425,278.145233,14.169393,1.134250,-231.167496,0.113511,0.000000
80.860001,62.477020,-231.123016,-0.001293,0.004466,0.113425,277.911652,14.157495,1.134250,-231.123016,0.113511,0.000000
81.110001,62.428612,-231.211990,-0.001289,0.004466,0.113425,277.696320,14.146525,1.134250,-231.211990,0.113511,0.000000
81.360001,62.381325,-231.211990,-0.001276,0.004466,0.113425,277.485992,14.135810,1.134250,-231.211990,0.113511,0.000000
81.610001,62.329933,-231.256470,-0.001289,0.004466,0.113425,277.257385,14.124166,1.134250,-231.256470,0.113511,0.000000
81.860001,62.284134,-231.300949,-0.001263,0.004466,0.113425,277.053650,14.113787,1.134250,-231.300949,0.113511,0.000000
82.110001,62.255089,-231.300949,-0.001281,0.004466,0.113425,276.924469,14.107204,1.134250,-231.300949,0.113511,0.000000
82.360001,62.204819,-231.345428,-0.001281,0.004466,0.113425,276.700867,14.095813,1.134250,-231.345428,0.113511,0.000000
82.610001,62.160881,-231.389908,-0.001281,0.004466,0.113425,276.505402,14.085856,1.134250,-231.389908,0.113511,0.000000
82.860001,62.116196,-231.434387,-0.001250,0.004466,0.113425,276.306641,14.075731,1.134250,-231.434387,0.113511,0.000000
83.110001,62.095345,-231.389908,-0.001293,0.004466,0.113425,276.213898,14.071007,1.134250,-231.389908,0.113511,0.000000
83.360001,62.055870,-231.478867,-0.001281,0.004466,0.113425,276.038300,14.062061,1.134250,-231.478867,0.113511,0.000000
83.610001,62.007462,-231.478867,-0.001298,0.004466,0.113425,275.822968,14.051092,1.134250,-231.478867,0.113511,0.000000
83.860001,61.977669,-231.478867,-0.001268,0.004466,0.113425,275.690430,14.044340,1.134250,-231.478867,0.113511,0.000000
84.110001,61.933357,-231.523346,-0.001289,0.004466,0.113425,275.493347,14.034300,1.134250,-231.523346,0.113511,0.000000
84.360001,61.899101,-231.567825,-0.001276,0.004466,0.113425,275.340942,14.026537,1.134250,-231.567825,0.113511,0.000000
84.610001,61.870804,-231.612305,-0.001289,0.004466,0.113425,275.215088,14.020124,1.134250,-231.612305,0.113511,0.000000
84.860001,61.837288,-231.612305,-0.001281,0.004466,0.113425,275.066010,14.012529,1.134250,-231.612305,0.113511,0.000000
85.110001,61.815689,-231.612305,-0.001276,0.004466,0.113425,274.969910,14.007635,1.134250,-231.612305,0.113511,0.000000
85.360001,61.782173,-231.701279,-0.001255,0.004466,0.113425,274.820831,14.000041,1.134250,-231.701279,0.113511,0.000000
85.610001,61.746803,-231.612305,-0.001263,0.004466,0.113425,274.663513,13.992026,1.134250,-231.612305,0.113511,0.000000
85.860001,61.715523,-231.701279,-0.001281,0.004466,0.113425,274.524353,13.984938,1.134250,-231.701279,0.113511,0.000000
86.110001,61.690575,-231.701279,-0.001293,0.004466,0.113425,274.413391,13.979283,1.134250,-231.701279,0.113511,0.000000
86.360001,61.654083,-231.745758,-0.001272,0.004466,0.113425,274.251068,13.971015,1.134250,-231.745758,0.113511,0.000000
86.610001,61.626900,-231.790237,-0.001263,0.004466,0.113425,274.130127,13.964855,1.134250,-231.790237,0.113511,0.000000
86.860001,61.598595,-231.790237,-0.001276,0.004466,0.113425,274.004242,13.958442,1.134250,-231.790237,0.113511,0.000000
87.110001,61.572899,-231.834717,-0.001311,0.004466,0.113425,273.889923,13.952619,1.134250,-231.834717,0.113511,0.000000
87.360001,61.535667,-231.834717,-0.001293,0.004466,0.113425,273.724335,13.944182,1.134250,-231.834717,0.113511,0.000000
87.610001,61.531944,-231.923676,-0.001272,0.004466,0.113425,273.707764,13.943337,1.134250,-231.923676,0.113511,0.000000
87.860001,61.487999,-231.923676,-0.001289,0.004466,0.113425,273.512268,13.933379,1.134250,-231.923676,0.113511,0.000000
88.110001,61.479813,-231.968155,-0.001276,0.004466,0.113425,273.475861,13.931525,1.134250,-231.968155,0.113511,0.000000
88.360001,61.440338,-232.012634,-0.001272,0.004466,0.113425,273.300262,13.922580,1.134250,-232.012634,0.113511,0.000000
88.610001,61.430656,-231.968155,-0.001285,0.004466,0.113425,273.257202,13.920385,1.134250,-231.968155,0.113511,0.000000
88.860001,61.396774,-232.012634,-0.001289,0.004466,0.113425,273.106506,13.912708,1.134250,-232.012634,0.113511,0.000000
89.110001,61.383362,-232.012634,-0.001281,0.004466,0.113425,273.046844,13.909669,1.134250,-232.012634,0.113511,0.000000
89.360001,61.353951,-232.057129,-0.001281,0.004466,0.113425,272.916016,13.903004,1.134250,-232.057129,0.113511,0.000000
89.610001,61.333092,-232.101608,-0.001285,0.004466,0.113425,272.823212,13.898277,1.134250,-232.101608,0.113511,0.000000
89.860001,61.311501,-232.101608,-0.001289,0.004466,0.113425,272.727173,13.893385,1.134250,-232.101608,0.113511,0.000000
90.110001,61.290276,-232.101608,-0.001255,0.004466,0.113425,272.632751,13.888575,1.134250,-232.101608,0.113511,0.000000
90.360001,61.260483,-232.146088,-0.001285,0.004466,0.113425,272.500244,13.881824,1.134250,-232.146088,0.113511,0.000000
90.610001,61.259361,-232.190567,-0.001293,0.004466,0.113425,272.495239,13.881570,1.134250,-232.190567,0.113511,0.000000
90.860001,61.216545,-232.235046,-0.001281,0.004466,0.113425,272.304779,13.871868,1.134250,-232.235046,0.113511,0.000000
91.110001,61.205742,-232.235046,-0.001285,0.004466,0.113425,272.256744,13.869419,1.134250,-232.235046,0.113511,0.000000
91.360001,61.183403,-232.279526,-0.001298,0.004466,0.113425,272.157379,13.864357,1.134250,-232.279526,0.113511,0.000000
91.610001,61.155098,-232.279526,-0.001276,0.004466,0.113425,272.031464,13.857944,1.134250,-232.279526,0.113511,0.000000
91.860001,61.134995,-232.324005,-0.001276,0.004466,0.113425,271.942047,13.853388,1.134250,-232.324005,0.113511,0.000000
92.110001,61.125313,-232.324005,-0.001268,0.004466,0.113425,271.898956,13.851193,1.134250,-232.324005,0.113511,0.000000
92.360001,61.107437,-232.324005,-0.001272,0.004466,0.113425,271.819458,13.847143,1.134250,-232.324005,0.113511,0.000000
92.610001,61.085464,-232.368484,-0.001285,0.004466,0.113425,271.721710,13.842164,1.134250,-232.368484,0.113511,0.000000
92.860001,61.065361,-232.368484,-0.001276,0.004466,0.113425,271.632294,13.837608,1.134250,-232.368484,0.113511,0.000000
93.110001,61.051582,-232.412964,-0.001281,0.004466,0.113425,271.571014,13.834487,1.134250,-232.412964,0.113511,0.000000
93.360008,61.027374,-232.457443,-0.001276,0.004466,0.113425,271.463318,13.829000,1.134250,-232.457443,0.113511,0.000000
93.610008,61.001312,-232.501938,-0.001285,0.004466,0.113425,271.347382,13.823095,1.134250,-232.501938,0.113511,0.000000
93.860008,60.994232,-232.501938,-0.001268,0.004466,0.113425,271.315887,13.821491,1.134250,-232.501938,0.113511,0.000000
94.110008,60.973381,-232.590897,-0.001289,0.004466,0.113425,271.223145,13.816766,1.134250,-232.590897,0.113511,0.000000
94.360008,60.962585,-232.590897,-0.001259,0.004466,0.113425,271.175110,13.814320,1.134250,-232.590897,0.113511,0.000000
94.610008,60.937263,-232.546417,-0.001276,0.004466,0.113425,271.062500,13.808581,1.134250,-232.546417,0.113511,0.000000
94.860008,60.928329,-232.635376,-0.001289,0.004466,0.113425,271.022736,13.806557,1.134250,-232.635376,0.113511,0.000000
95.110008,60.902260,-232.679855,-0.001276,0.004466,0.113425,270.906769,13.800650,1.134250,-232.679855,0.113511,0.000000
95.360008,60.880661,-232.635376,-0.001285,0.004466,0.113425,270.810699,13.795755,1.134250,-232.635376,0.113511,0.000000
95.610008,60.853104,-232.724335,-0.001285,0.004466,0.113425,270.688110,13.789511,1.134250,-232.724335,0.113511,0.000000
95.860008,60.849380,-232.724335,-0.001293,0.004466,0.113425,270.671570,13.788667,1.134250,-232.724335,0.113511,0.000000
96.110008,60.844917,-232.679855,-0.001268,0.004466,0.113425,270.651703,13.787656,1.134250,-232.679855,0.113511,0.000000
96.360008,60.829277,-232.768814,-0.001298,0.004466,0.113425,270.582153,13.784111,1.134250,-232.768814,0.113511,0.000000
96.610008,60.819221,-232.813293,-0.001255,0.004466,0.113425,270.537415,13.781833,1.134250,-232.813293,0.113511,0.000000
96.860008,60.795013,-232.813293,-0.001259,0.004466,0.113425,270.429718,13.776346,1.134250,-232.813293,0.113511,0.000000
97.110008,60.778259,-232.857773,-0.001276,0.004466,0.113425,270.355194,13.772550,1.134250,-232.857773,0.113511,0.000000
97.360008,60.770439,-232.813293,-0.001302,0.004466,0.113425,270.320404,13.770778,1.134250,-232.813293,0.113511,0.000000
97.610008,60.761131,-232.946747,-0.001263,0.004466,0.113425,270.279022,13.768669,1.134250,-232.946747,0.113511,0.000000
97.860008,60.742882,-232.902252,-0.001281,0.004466,0.113425,270.197845,13.764534,1.134250,-232.902252,0.113511,0.000000
98.110008,60.727989,-232.902252,-0.001285,0.004466,0.113425,270.131592,13.761159,1.134250,-232.902252,0.113511,0.000000
98.360008,60.727615,-232.946747,-0.001250,0.004466,0.113425,270.129913,13.761074,1.134250,-232.946747,0.113511,0.000000
98.610008,60.704903,-233.035706,-0.001293,0.004466,0.113425,270.028900,13.755927,1.134250,-233.035706,0.113511,0.000000
98.860008,60.688148,-232.991226,-0.001289,0.004466,0.113425,269.954376,13.752131,1.134250,-232.991226,0.113511,0.000000
99.110008,60.676605,-232.991226,-0.001268,0.004466,0.113425,269.903015,13.749516,1.134250,-232.991226,0.113511,0.000000
99.360008,60.668037,-233.080185,-0.001276,0.004466,0.113425,269.864899,13.747574,1.134250,-233.080185,0.113511,0.000000
99.610008,60.649422,-233.080185,-0.001255,0.004466,0.113425,269.782104,13.743356,1.134250,-233.080185,0.113511,0.000000
99.860008,60.643837,-233.169144,-0.001276,0.004466,0.113425,269.757263,13.742090,1.134250,-233.169144,0.113511,0.000000
100.110008,60.625587,-233.124664,-0.001285,0.004466,0.113425,269.676086,13.737955,1.134250,-233.124664,0.113511,0.000000
100.360008,60.608086,-233.124664,-0.001268,0.004466,0.113425,269.598236,13.733989,1.134250,-233.124664,0.113511,0.000000
100.610008,60.605110,-233.213623,-0.001255,0.004466,0.113425,269.584991,13.733314,1.134250,-233.213623,0.113511,0.000000
100.860008,60.592445,-233.258102,-0.001259,0.004466,0.113425,269.528656,13.730444,1.134250,-233.258102,0.113511,0.000000
101.110008,60.568611,-233.258102,-0.001281,0.004466,0.113425,269.422638,13.725043,1.134250,-233.258102,0.113511,0.000000
101.360008,60.564522,-233.347076,-0.001285,0.004466,0.113425,269.404449,13.724116,1.134250,-233.347076,0.113511,0.000000
101.610008,60.551483,-233.347076,-0.001298,0.004466,0.113425,269.346436,13.721163,1.134250,-233.347076,0.113511,0.000000
101.860008,60.537704,-233.347076,-0.001268,0.004466,0.113425,269.285156,13.718040,1.134250,-233.347076,0.113511,0.000000
102.110008,60.525795,-233.347076,-0.001272,0.004466,0.113425,269.232178,13.715342,1.134250,-233.347076,0.113511,0.000000
102.360008,60.516479,-233.347076,-0.001276,0.004466,0.113425,269.190735,13.713230,1.134250,-233.347076,0.113511,0.000000
102.610008,60.506432,-233.391556,-0.001281,0.004466,0.113425,269.146057,13.710953,1.134250,-233.391556,0.113511,0.000000
102.860008,60.491158,-233.480515,-0.001272,0.004466,0.113425,269.078094,13.707493,1.134250,-233.480515,0.113511,0.000000
103.110008,60.494514,-233.480515,-0.001259,0.004466,0.113425,269.093048,13.708253,1.134250,-233.480515,0.113511,0.000000
103.300003,60.477753,-233.436035,-0.001272,0.004466,0.113425,269.018494,13.704454,1.134250,-233.436035,0.113511,0.000000