File: Data/compression 13/AutoNoHeating-12-13-3-240724_07242024_164150.csv
Time (sec),S:Load (lbs),S:HL1 (DIM),S:LVDT (in),S:Position (in),Ch:Position (mm),Ch:Load (N),Ch:Stress (MPa),Ch:Strain (mm/mm),Ch:HL1 (DIM),Set Point (),Cycles ()
0.110000,-0.023834,-277.650085,-0.009071,-0.004808,-0.122131,-0.106020,-0.005401,-1.221314,-277.650085,-0.121888,0.000000
0.350000,-0.016388,-277.694580,-0.009063,-0.004808,-0.122131,-0.072897,-0.003714,-1.221314,-277.694580,-0.121888,0.000000
0.590000,0.007072,-277.694580,-0.009058,-0.004714,-0.119747,0.031460,0.001603,-1.197465,-277.694580,-0.118992,0.000000
0.830000,-0.000000,-277.739044,-0.009080,-0.004576,-0.116243,-0.000000,-0.000000,-1.162428,-277.739044,-0.115003,0.000000
1.070000,0.022339,-277.739044,-0.008873,-0.004420,-0.112280,0.099368,0.005062,-1.122797,-277.739044,-0.110996,0.000000
1.310000,0.010422,-277.694580,-0.008735,-0.004253,-0.108039,0.046358,0.002362,-1.080387,-277.694580,-0.107007,0.000000
1.550000,0.018990,-277.783539,-0.008554,-0.004102,-0.104197,0.084470,0.004303,-1.041970,-277.783539,-0.103000,0.000000
1.790000,0.028297,-277.783539,-0.008420,-0.003944,-0.100182,0.125873,0.006412,-1.001816,-277.783539,-0.099011,0.000000
2.030000,0.046547,-277.783539,-0.008248,-0.003791,-0.096279,0.207051,0.010548,-0.962794,-277.783539,-0.095005,0.000000
2.270000,0.055107,-277.872498,-0.008084,-0.003636,-0.092351,0.245129,0.012487,-0.923507,-277.872498,-0.091015,0.000000
2.510000,0.010056,-277.828033,-0.007916,-0.003469,-0.088118,0.044729,0.002279,-0.881184,-277.828033,-0.087009,0.000000
2.750000,0.013405,-277.916992,-0.007756,-0.003319,-0.084294,0.059628,0.003038,-0.842942,-277.916992,-0.083019,0.000000
2.990000,0.031654,-277.916992,-0.007580,-0.003156,-0.080175,0.140806,0.007173,-0.801747,-277.916992,-0.079013,0.000000
3.230000,0.010056,-277.916992,-0.007412,-0.002994,-0.076056,0.044729,0.002279,-0.760559,-277.916992,-0.075023,0.000000
3.470000,0.013031,-277.961456,-0.007243,-0.002836,-0.072032,0.057965,0.002953,-0.720318,-277.961456,-0.071017,0.000000
3.710000,0.027557,-277.961456,-0.007088,-0.002687,-0.068242,0.122581,0.006245,-0.682417,-277.961456,-0.067010,0.000000
3.950000,0.042450,-277.961456,-0.006937,-0.002529,-0.064235,0.188827,0.009619,-0.642350,-277.961456,-0.063022,0.000000
4.190000,0.075218,-277.916992,-0.006756,-0.002379,-0.060420,0.334587,0.017045,-0.604198,-277.916992,-0.059015,0.000000
4.430000,0.064423,-278.005951,-0.006588,-0.002209,-0.056110,0.286566,0.014598,-0.561096,-278.005951,-0.055026,0.000000
4.670000,0.036865,-278.005951,-0.006437,-0.002056,-0.052224,0.163985,0.008354,-0.522240,-278.005951,-0.051019,0.000000
4.910000,0.032394,-278.005951,-0.006278,-0.001903,-0.048330,0.144098,0.007341,-0.483301,-278.005951,-0.047030,0.000000
5.150000,0.045059,-278.050415,-0.006109,-0.001738,-0.044133,0.200433,0.010211,-0.441326,-278.050415,-0.043023,0.000000
5.390000,0.038727,-278.094910,-0.005928,-0.001574,-0.039987,0.172265,0.008776,-0.399874,-278.094910,-0.039034,0.000000
5.630000,0.005959,-278.139374,-0.005764,-0.001426,-0.036224,0.026505,0.001350,-0.362237,-278.139374,-0.035027,0.000000
5.870000,0.050644,-278.139374,-0.005639,-0.001264,-0.032113,0.225275,0.011476,-0.321133,-278.139374,-0.031038,0.000000
6.110000,0.057343,-278.139374,-0.005463,-0.001119,-0.028410,0.255072,0.012994,-0.284102,-278.139374,-0.027031,0.000000
6.350000,0.084526,-278.228363,-0.005286,-0.000949,-0.024109,0.375991,0.019154,-0.241090,-278.228363,-0.023042,0.000000
6.590000,0.059952,-278.228363,-0.005122,-0.000798,-0.020258,0.266679,0.013585,-0.202583,-278.228363,-0.019036,0.000000
6.830000,0.040962,-278.183868,-0.004971,-0.000639,-0.016226,0.182209,0.009282,-0.162258,-278.183868,-0.015046,0.000000
7.070000,0.061440,-278.228363,-0.004794,-0.000489,-0.012418,0.273297,0.013922,-0.124182,-278.228363,-0.011040,0.000000
7.310000,0.051758,-278.228363,-0.004626,-0.000317,-0.008039,0.230230,0.011728,-0.080391,-278.228363,-0.007051,0.000000
7.550000,0.139267,-278.272827,-0.004493,-0.000167,-0.004241,0.619490,0.031558,-0.042406,-278.272827,-0.003044,0.000000
7.790000,0.768204,-278.228363,-0.004299,-0.000032,-0.000806,3.417141,0.174077,-0.008062,-278.228363,0.000529,0.000000
8.030001,0.655373,-278.317322,-0.004303,-0.000001,-0.000017,2.915243,0.148510,-0.000167,-278.317322,0.000191,0.000000
8.270000,0.651649,-278.361786,-0.004299,-0.000001,-0.000017,2.898682,0.147666,-0.000167,-278.361786,0.000191,0.000000
8.510000,0.606964,-278.317322,-0.004312,-0.000001,-0.000017,2.699911,0.137540,-0.000167,-278.317322,0.000478,0.000000
8.750000,0.611061,-278.317322,-0.004320,-0.000001,-0.000017,2.718136,0.138468,-0.000167,-278.317322,0.000877,0.000000
8.990001,0.642715,-278.361786,-0.004307,0.000011,0.000269,2.858941,0.145641,0.002695,-278.361786,0.001276,0.000000
9.230000,0.815865,-278.406281,-0.004329,0.000024,0.000599,3.629147,0.184878,0.005988,-278.406281,0.001674,0.000000
9.470000,1.007637,-278.406281,-0.004290,0.000043,0.001093,4.482193,0.228334,0.010931,-278.406281,0.002073,0.000000
9.710000,1.032219,-278.406281,-0.004268,0.000047,0.001206,4.591539,0.233904,0.012059,-278.406281,0.002472,0.000000
9.950001,1.290268,-278.495239,-0.004264,0.000073,0.001865,5.739398,0.292379,0.018652,-278.495239,0.002870,0.000000
10.190001,1.524864,-278.450745,-0.004208,0.000097,0.002463,6.782935,0.345539,0.024632,-278.450745,0.003269,0.000000
10.430000,1.665993,-278.539703,-0.004217,0.000110,0.002802,7.410706,0.377519,0.028016,-278.539703,0.003677,0.000000
10.670000,1.780685,-278.539703,-0.004225,0.000122,0.003105,7.920884,0.403509,0.031051,-278.539703,0.004076,0.000000
10.910001,1.967987,-278.539703,-0.004204,0.000137,0.003478,8.754044,0.445952,0.034776,-278.539703,0.004475,0.000000
11.150001,2.281151,-278.628693,-0.004169,0.000160,0.004059,10.147065,0.516916,0.040589,-278.628693,0.004874,0.000000
11.390000,2.376106,-278.584198,-0.004152,0.000171,0.004354,10.569448,0.538433,0.043541,-278.584198,0.005273,0.000000
11.630000,2.426750,-278.628693,-0.004178,0.000178,0.004518,10.794724,0.549909,0.045184,-278.628693,0.005672,0.000000
11.870001,2.754440,-278.628693,-0.004143,0.000197,0.005004,12.252362,0.624165,0.050044,-278.628693,0.006071,0.000000
12.110001,3.135002,-278.628693,-0.004122,0.000221,0.005611,13.945186,0.710402,0.056115,-278.628693,0.006470,0.000000
12.350000,3.318581,-278.673157,-0.004096,0.000237,0.006019,14.761784,0.752001,0.060187,-278.673157,0.006877,0.000000
12.590000,3.478699,-278.628693,-0.004109,0.000251,0.006375,15.474025,0.788284,0.063745,-278.628693,0.007276,0.000000
12.830001,3.673828,-278.717651,-0.004074,0.000264,0.006704,16.342003,0.832501,0.067038,-278.717651,0.007675,0.000000
13.070001,3.961296,-278.762115,-0.004057,0.000280,0.007112,17.620726,0.897643,0.071118,-278.762115,0.008074,0.000000
13.310000,4.208549,-278.717651,-0.004044,0.000296,0.007511,18.720564,0.953671,0.075107,-278.717651,0.008473,0.000000
13.550000,4.195518,-278.806610,-0.004044,0.000303,0.007684,18.662598,0.950718,0.076841,-278.806610,0.008872,0.000000
13.790001,4.603638,-278.851074,-0.004027,0.000324,0.008231,20.478003,1.043199,0.082306,-278.851074,0.009271,0.000000
14.030001,5.114159,-278.851074,-0.003997,0.000352,0.008933,22.748913,1.158885,0.089331,-278.851074,0.009670,0.000000
14.270000,5.206886,-278.806610,-0.003967,0.000364,0.009253,23.161386,1.179897,0.092533,-278.806610,0.010078,0.000000
14.510000,5.316734,-278.851074,-0.003980,0.000377,0.009566,23.650015,1.204789,0.095659,-278.851074,0.010477,0.000000
14.750001,5.514832,-278.895569,-0.003975,0.000392,0.009956,24.531197,1.249679,0.099558,-278.895569,0.010876,0.000000
14.990001,5.913643,-278.895569,-0.003923,0.000407,0.010346,26.305197,1.340051,0.103464,-278.895569,0.011274,0.000000
15.230000,6.176170,-278.940033,-0.003949,0.000424,0.010763,27.472979,1.399540,0.107627,-278.940033,0.011673,0.000000
15.470000,6.170586,-278.984528,-0.003923,0.000433,0.010988,27.448135,1.398275,0.109883,-278.984528,0.012072,0.000000
15.710001,6.452843,-278.984528,-0.003915,0.000447,0.011361,28.703678,1.462235,0.113607,-278.984528,0.012471,0.000000
15.950001,7.087738,-279.028992,-0.003867,0.000477,0.012124,31.527834,1.606104,0.121238,-279.028992,0.012870,0.000000
16.190001,7.010284,-278.984528,-0.003863,0.000487,0.012376,31.183302,1.588553,0.123758,-278.984528,0.013277,0.000000
16.430000,7.079544,-278.984528,-0.003846,0.000500,0.012705,31.491385,1.604248,0.127051,-278.984528,0.013676,0.000000
16.670000,7.537933,-279.073486,-0.003842,0.000518,0.013156,33.530403,1.708120,0.131563,-279.073486,0.014075,0.000000
16.910002,7.810143,-279.073486,-0.003820,0.000534,0.013564,34.741249,1.769804,0.135635,-279.073486,0.014474,0.000000
17.150002,7.924828,-279.117981,-0.003798,0.000548,0.013919,35.251392,1.795792,0.139193,-279.117981,0.014873,0.000000
17.390001,8.062233,-279.117981,-0.003798,0.000562,0.014275,35.862602,1.826928,0.142751,-279.117981,0.015272,0.000000
17.630001,8.086815,-279.162445,-0.003777,0.000571,0.014501,35.971951,1.832498,0.145007,-279.162445,0.015671,0.000000
17.870001,8.756340,-279.162445,-0.003760,0.000599,0.015220,38.950146,1.984215,0.152198,-279.162445,0.016079,0.000000
18.110001,8.818893,-279.251404,-0.003760,0.000612,0.015532,39.228397,1.998390,0.155325,-279.251404,0.016478,0.000000
18.350000,8.766388,-279.162445,-0.003734,0.000622,0.015793,38.994843,1.986492,0.157929,-279.162445,0.016877,0.000000
18.590000,9.219566,-279.162445,-0.003704,0.000642,0.016295,41.010681,2.089184,0.162955,-279.162445,0.017276,0.000000
18.830002,9.429588,-279.340363,-0.003717,0.000658,0.016712,41.944904,2.136775,0.167118,-279.340363,0.017675,0.000000
19.070002,9.712593,-279.295898,-0.003678,0.000679,0.017241,43.203773,2.200905,0.172410,-279.295898,0.018074,0.000000
19.310001,9.673119,-279.295898,-0.003665,0.000690,0.017535,43.028179,2.191960,0.175354,-279.295898,0.018473,0.000000
19.550001,9.711472,-279.384857,-0.003669,0.000700,0.017787,43.198784,2.200651,0.177875,-279.384857,0.018871,0.000000
19.790001,10.286789,-279.340363,-0.003630,0.000725,0.018403,45.757923,2.331020,0.184029,-279.340363,0.019279,0.000000
20.030001,10.433502,-279.429321,-0.003600,0.000739,0.018759,46.410534,2.364265,0.187587,-279.429321,0.019678,0.000000
20.270000,10.397011,-279.340363,-0.003587,0.000750,0.019045,46.248215,2.355996,0.190448,-279.340363,0.020077,0.000000
20.510000,10.715759,-279.384857,-0.003604,0.000768,0.019504,47.666077,2.428226,0.195043,-279.384857,0.020476,0.000000
20.750002,10.952217,-279.429321,-0.003574,0.000786,0.019955,48.717896,2.481808,0.199555,-279.429321,0.020874,0.000000
20.990002,11.085526,-279.473816,-0.003548,0.000799,0.020285,49.310879,2.512016,0.202848,-279.473816,0.021273,0.000000
21.230001,10.798058,-279.518311,-0.003518,0.000802,0.020372,48.032158,2.446875,0.203718,-279.518311,0.021672,0.000000
21.470001,11.492157,-279.473816,-0.003501,0.000828,0.021022,51.119667,2.604160,0.210221,-279.473816,0.022071,0.000000
21.710001,11.927460,-279.518311,-0.003501,0.000849,0.021560,53.055992,2.702801,0.215595,-279.518311,0.022478,0.000000
21.950001,11.992996,-279.607269,-0.003445,0.000866,0.021984,53.347511,2.717652,0.219842,-279.607269,0.022877,0.000000
22.190001,11.904747,-279.518311,-0.003432,0.000879,0.022332,52.954960,2.697654,0.223316,-279.518311,0.023276,0.000000
22.430000,11.973633,-279.651733,-0.003441,0.000892,0.022661,53.261379,2.713264,0.226609,-279.651733,0.023675,0.000000
22.670002,12.038429,-279.562775,-0.003428,0.000906,0.023017,53.549606,2.727947,0.230167,-279.562775,0.024074,0.000000
22.910002,12.344894,-279.651733,-0.003389,0.000922,0.023424,54.912834,2.797393,0.234240,-279.651733,0.024473,0.000000
23.150002,12.355316,-279.651733,-0.003397,0.000933,0.023702,54.959190,2.799755,0.237018,-279.651733,0.024872,0.000000
23.390001,12.799187,-279.651733,-0.003376,0.000950,0.024136,56.933624,2.900337,0.241355,-279.651733,0.025271,0.000000
23.630001,13.103416,-279.651733,-0.003341,0.000970,0.024630,58.286907,2.969277,0.246298,-279.651733,0.025679,0.000000
23.870001,13.464615,-279.740692,-0.003316,0.000993,0.025220,59.893597,3.051125,0.252195,-279.740692,0.026078,0.000000
24.110001,13.184959,-279.785187,-0.003303,0.001004,0.025497,58.649628,2.987754,0.254966,-279.785187,0.026477,0.000000
24.350000,13.217735,-279.785187,-0.003307,0.001017,0.025827,58.795422,2.995182,0.258266,-279.785187,0.026876,0.000000
24.590002,13.431847,-279.785187,-0.003277,0.001033,0.026226,59.747837,3.043700,0.262255,-279.785187,0.027275,0.000000
24.830002,13.691017,-279.785187,-0.003281,0.001051,0.026693,60.900684,3.102429,0.266934,-279.785187,0.027674,0.000000
25.070002,13.889122,-279.785187,-0.003255,0.001067,0.027101,61.781898,3.147320,0.271014,-279.785187,0.028073,0.000000
25.310001,14.108078,-279.785187,-0.003216,0.001083,0.027518,62.755867,3.196936,0.275177,-279.785187,0.028471,0.000000
25.550001,14.266335,-279.874146,-0.003182,0.001103,0.028012,63.459824,3.232798,0.280120,-279.874146,0.028879,0.000000
25.790001,14.322937,-279.874146,-0.003156,0.001118,0.028394,63.711605,3.245624,0.283935,-279.874146,0.029278,0.000000
26.030001,14.151642,-279.918640,-0.003147,0.001128,0.028653,62.949646,3.206808,0.286532,-279.918640,0.029677,0.000000
26.270000,14.223511,-279.874146,-0.003126,0.001141,0.028974,63.269337,3.223094,0.289741,-279.874146,0.030076,0.000000
26.510002,14.386612,-279.918640,-0.003130,0.001154,0.029322,63.994846,3.260053,0.293216,-279.918640,0.030474,0.000000
26.750002,15.151093,-279.918640,-0.003126,0.001179,0.029954,67.395424,3.433287,0.299544,-279.918640,0.030873,0.000000
26.990002,14.760101,-279.918640,-0.003065,0.001187,0.030153,65.656212,3.344687,0.301535,-279.918640,0.031272,0.000000
27.230001,14.938835,-280.052063,-0.003057,0.001204,0.030579,66.451256,3.385189,0.305789,-280.052063,0.031671,0.000000
27.470001,15.720444,-280.052063,-0.003035,0.001231,0.031264,69.928024,3.562304,0.312640,-280.052063,0.032079,0.000000
27.710001,15.469093,-280.007599,-0.003035,0.001246,0.031636,68.809967,3.505347,0.316364,-280.007599,0.032478,0.000000
27.950001,15.258705,-280.052063,-0.002984,0.001257,0.031940,67.874107,3.457672,0.319400,-280.052063,0.032877,0.000000
28.190001,15.298920,-280.007599,-0.002988,0.001271,0.032296,68.052994,3.466785,0.322958,-280.007599,0.033276,0.000000
28.430002,15.257591,-280.096558,-0.002936,0.001283,0.032582,67.869156,3.457420,0.325819,-280.096558,0.033675,0.000000
28.670002,15.781143,-280.096558,-0.002915,0.001303,0.033103,70.198029,3.576058,0.331027,-280.096558,0.034074,0.000000
28.910002,15.748375,-280.141022,-0.002928,0.001318,0.033467,70.052269,3.568633,0.334668,-280.141022,0.034473,0.000000
29.150002,15.702942,-280.185516,-0.002876,0.001330,0.033788,69.850174,3.558337,0.337878,-280.185516,0.034872,0.000000
29.390001,15.645599,-280.141022,-0.002884,0.001340,0.034047,69.595100,3.545343,0.340474,-280.141022,0.035279,0.000000
29.630001,16.723618,-280.185516,-0.002837,0.001373,0.034880,74.390366,3.789626,0.348801,-280.185516,0.035678,0.000000
29.870001,16.267090,-280.229980,-0.002811,0.001384,0.035158,72.359627,3.686175,0.351579,-280.229980,0.036077,0.000000
30.110001,16.114418,-280.229980,-0.002790,0.001398,0.035513,71.680511,3.651579,0.355129,-280.229980,0.036476,0.000000
30.350002,15.784866,-280.274475,-0.002755,0.001408,0.035765,70.214592,3.576902,0.357650,-280.274475,0.036875,0.000000
30.590002,16.185913,-280.229980,-0.002751,0.001427,0.036250,71.998535,3.667780,0.362502,-280.229980,0.037274,0.000000
30.830002,16.428329,-280.318939,-0.002721,0.001443,0.036649,73.076859,3.722713,0.366491,-280.318939,0.037673,0.000000
31.070002,16.101753,-280.318939,-0.002703,0.001453,0.036910,71.624176,3.648709,0.369095,-280.318939,0.038080,0.000000
31.310001,16.899750,-280.452393,-0.002665,0.001479,0.037569,75.173843,3.829538,0.375689,-280.452393,0.038479,0.000000
31.550001,16.950020,-280.363434,-0.002630,0.001498,0.038037,75.397453,3.840929,0.380367,-280.363434,0.038878,0.000000
31.790001,16.605576,-280.407928,-0.002613,0.001510,0.038358,73.865288,3.762877,0.383576,-280.407928,0.039277,0.000000
32.030003,16.424232,-280.407928,-0.002578,0.001524,0.038704,73.058632,3.721784,0.387043,-280.407928,0.039676,0.000000
32.270000,16.386620,-280.407928,-0.002570,0.001536,0.039017,72.891327,3.713261,0.390170,-280.407928,0.040074,0.000000
32.510002,17.024124,-280.407928,-0.002548,0.001560,0.039624,75.727089,3.857722,0.396241,-280.407928,0.040473,0.000000
32.750000,16.619728,-280.496887,-0.002514,0.001571,0.039893,73.928246,3.766084,0.398928,-280.496887,0.040872,0.000000
32.990002,16.328903,-280.452393,-0.002509,0.001582,0.040187,72.634590,3.700182,0.401873,-280.452393,0.041280,0.000000
33.230003,16.565735,-280.496887,-0.002479,0.001597,0.040569,73.688072,3.753849,0.405688,-280.496887,0.041679,0.000000
33.470001,17.157059,-280.541351,-0.002458,0.001622,0.041202,76.318405,3.887845,0.412024,-280.541351,0.042078,0.000000
33.710003,17.161903,-280.630310,-0.002414,0.001639,0.041627,76.339958,3.888943,0.416270,-280.630310,0.042477,0.000000
33.950001,16.799583,-280.585846,-0.002393,0.001650,0.041913,74.728279,3.806840,0.419132,-280.585846,0.042876,0.000000
34.190002,16.871078,-280.541351,-0.002380,0.001666,0.042312,75.046303,3.823041,0.423121,-280.541351,0.043275,0.000000
34.430000,16.839798,-280.630310,-0.002358,0.001682,0.042711,74.907166,3.815953,0.427110,-280.630310,0.043674,0.000000
34.670002,16.916504,-280.630310,-0.002333,0.001697,0.043093,75.248367,3.833334,0.430925,-280.630310,0.044073,0.000000
34.910000,16.738884,-280.719269,-0.002345,0.001708,0.043379,74.458275,3.793085,0.433787,-280.719269,0.044480,0.000000
35.150002,17.598694,-280.719269,-0.002285,0.001733,0.044021,78.282898,3.987921,0.440206,-280.719269,0.044879,0.000000
35.390003,17.787483,-280.763763,-0.002268,0.001754,0.044541,79.122681,4.030702,0.445414,-280.763763,0.045278,0.000000
35.630001,17.264305,-280.763763,-0.002216,0.001765,0.044828,76.795464,3.912148,0.448275,-280.763763,0.045677,0.000000
35.870003,17.071785,-280.763763,-0.002233,0.001778,0.045157,75.939095,3.868522,0.451568,-280.763763,0.046076,0.000000
36.110001,17.096733,-280.808258,-0.002199,0.001791,0.045504,76.050064,3.874175,0.455035,-280.808258,0.046475,0.000000
36.350002,17.367081,-280.808258,-0.002151,0.001808,0.045920,77.252632,3.935437,0.459199,-280.808258,0.046874,0.000000
36.590000,17.536507,-280.763763,-0.002173,0.001824,0.046319,78.006279,3.973829,0.463188,-280.763763,0.047273,0.000000
36.830002,17.195412,-280.852722,-0.002117,0.001831,0.046510,76.489014,3.896536,0.465095,-280.852722,0.047681,0.000000
37.070004,17.792702,-280.808258,-0.002108,0.001855,0.047117,79.145889,4.031884,0.471166,-280.808258,0.048080,0.000000
37.310001,18.498718,-280.852722,-0.002100,0.001878,0.047698,82.286407,4.191869,0.476980,-280.852722,0.048478,0.000000
37.550003,17.952820,-280.897217,-0.002044,0.001889,0.047975,79.858131,4.068167,0.479751,-280.897217,0.048877,0.000000
37.790001,17.872017,-280.852722,-0.002044,0.001903,0.048339,79.498703,4.049857,0.483392,-280.852722,0.049276,0.000000
38.030003,17.969948,-280.986176,-0.002022,0.001917,0.048687,79.934319,4.072048,0.486866,-280.986176,0.049675,0.000000
38.270000,18.329292,-280.941681,-0.002001,0.001937,0.049189,81.532761,4.153477,0.491893,-280.941681,0.050074,0.000000
38.510002,18.102882,-281.030640,-0.001983,0.001947,0.049450,80.525642,4.102172,0.494497,-281.030640,0.050473,0.000000
38.750000,18.129700,-281.030640,-0.001988,0.001960,0.049796,80.644936,4.108249,0.497963,-281.030640,0.050880,0.000000
38.990002,18.149803,-281.030640,-0.001944,0.001973,0.050109,80.734360,4.112804,0.501090,-281.030640,0.051279,0.000000
39.230003,19.246811,-281.030640,-0.001932,0.002001,0.050820,85.614090,4.361390,0.508198,-281.030640,0.051678,0.000000
39.470001,18.686020,-281.075134,-0.001888,0.002010,0.051063,83.119568,4.234313,0.510628,-281.075134,0.052077,0.000000
39.710003,18.389610,-281.164093,-0.001884,0.002021,0.051340,81.801071,4.167145,0.513398,-281.164093,0.052476,0.000000
39.950001,18.901253,-281.119598,-0.001845,0.002042,0.051878,84.076973,4.283085,0.518780,-281.119598,0.052875,0.000000
40.190002,18.934769,-281.119598,-0.001828,0.002059,0.052294,84.226059,4.290679,0.522944,-281.119598,0.053274,0.000000
40.430000,19.446777,-281.164093,-0.001798,0.002080,0.052832,86.503586,4.406703,0.528318,-281.164093,0.053673,0.000000
40.670002,19.169357,-281.208588,-0.001794,0.002092,0.053144,85.269562,4.343838,0.531437,-281.208588,0.054081,0.000000
40.910004,18.801460,-281.253052,-0.001772,0.002100,0.053352,83.633072,4.260472,0.533519,-281.253052,0.054480,0.000000
41.150002,19.822128,-281.253052,-0.001729,0.002128,0.054054,88.173233,4.491758,0.540544,-281.253052,0.054879,0.000000
41.390003,19.460930,-281.208588,-0.001720,0.002138,0.054306,86.566536,4.409910,0.543057,-281.208588,0.055278,0.000000
41.630001,19.196541,-281.253052,-0.001707,0.002151,0.054627,85.390480,4.349998,0.546266,-281.253052,0.055677,0.000000
41.870003,19.460556,-281.297546,-0.001703,0.002167,0.055052,86.564880,4.409825,0.550521,-281.297546,0.056075,0.000000
42.110001,19.815796,-281.342010,-0.001656,0.002185,0.055494,88.145065,4.490324,0.554941,-281.342010,0.056474,0.000000
42.350002,19.762177,-281.297546,-0.001634,0.002200,0.055884,87.906555,4.478173,0.558840,-281.297546,0.056873,0.000000
42.590000,20.052628,-281.342010,-0.001647,0.002218,0.056327,89.198540,4.543990,0.563268,-281.342010,0.057281,0.000000
42.830002,19.943520,-281.342010,-0.001591,0.002229,0.056621,88.713203,4.519266,0.566213,-281.342010,0.057680,0.000000
43.070004,20.497986,-281.386505,-0.001582,0.002251,0.057185,91.179596,4.644910,0.571852,-281.386505,0.058078,0.000000
43.310001,20.491280,-281.386505,-0.001561,0.002266,0.057567,91.149765,4.643390,0.575667,-281.386505,0.058477,0.000000
43.550003,20.205299,-281.430969,-0.001535,0.002280,0.057905,89.877663,4.578586,0.579051,-281.430969,0.058876,0.000000
43.790001,20.050392,-281.475464,-0.001518,0.002293,0.058234,89.188599,4.543484,0.582344,-281.475464,0.059275,0.000000
44.030003,20.375473,-281.564423,-0.001483,0.002309,0.058642,90.634628,4.617148,0.586424,-281.564423,0.059674,0.000000
44.270000,20.394836,-281.475464,-0.001483,0.002321,0.058963,90.720764,4.621536,0.589634,-281.475464,0.060081,0.000000
44.510002,20.483093,-281.519928,-0.001470,0.002335,0.059318,91.113350,4.641535,0.593184,-281.519928,0.060480,0.000000
44.750004,20.646935,-281.519928,-0.001436,0.002351,0.059717,91.842148,4.678662,0.597173,-281.519928,0.060879,0.000000
44.990002,21.405830,-281.519928,-0.001393,0.002377,0.060385,95.217888,4.850630,0.603850,-281.519928,0.061278,0.000000
45.230003,21.497803,-281.653381,-0.001384,0.002393,0.060793,95.626999,4.871472,0.607930,-281.653381,0.061677,0.000000
45.470001,20.955635,-281.564423,-0.001345,0.002403,0.061027,93.215317,4.748615,0.610269,-281.564423,0.062076,0.000000
45.710003,21.208473,-281.653381,-0.001337,0.002420,0.061469,94.340004,4.805909,0.614690,-281.653381,0.062475,0.000000
45.950001,21.169373,-281.608887,-0.001311,0.002435,0.061842,94.166069,4.797048,0.618422,-281.608887,0.062874,0.000000
46.190002,21.680267,-281.653381,-0.001289,0.002455,0.062346,96.438644,4.912819,0.623455,-281.653381,0.063282,0.000000
46.430000,21.743202,-281.742340,-0.001289,0.002469,0.062701,96.718597,4.927080,0.627006,-281.742340,0.063681,0.000000
46.670002,21.730537,-281.697876,-0.001237,0.002485,0.063109,96.662254,4.924210,0.631086,-281.697876,0.064080,0.000000
46.910004,22.027695,-281.786835,-0.001229,0.002505,0.063620,97.984077,4.991547,0.636203,-281.786835,0.064479,0.000000
47.150002,21.970345,-281.697876,-0.001212,0.002517,0.063941,97.728973,4.978551,0.639405,-281.697876,0.064878,0.000000
47.390003,21.605797,-281.697876,-0.001173,0.002528,0.064210,96.107384,4.895943,0.642100,-281.697876,0.065277,0.000000
47.630001,21.760330,-281.742340,-0.001186,0.002543,0.064592,96.794785,4.930962,0.645915,-281.742340,0.065675,0.000000
47.870003,21.965134,-281.742340,-0.001151,0.002556,0.064921,97.705795,4.977370,0.649208,-281.742340,0.066074,0.000000
48.110001,22.779510,-281.920258,-0.001130,0.002581,0.065554,101.328323,5.161911,0.655536,-281.920258,0.066482,0.000000
48.350002,22.383682,-281.875793,-0.001095,0.002590,0.065788,99.567589,5.072215,0.657883,-281.875793,0.066881,0.000000
48.590004,23.037567,-281.875793,-0.001069,0.002611,0.066317,102.476219,5.220387,0.663174,-281.875793,0.067280,0.000000
48.830002,23.405472,-281.920258,-0.001048,0.002631,0.066828,104.112740,5.303756,0.668284,-281.920258,0.067678,0.000000
49.070004,23.169388,-281.875793,-0.001035,0.002645,0.067184,103.062584,5.250258,0.671842,-281.875793,0.068077,0.000000
49.310001,22.797012,-281.920258,-0.001009,0.002656,0.067470,101.406174,5.165877,0.674703,-281.920258,0.068476,0.000000
49.550003,22.930321,-281.875793,-0.000987,0.002675,0.067939,101.999161,5.196085,0.679389,-281.875793,0.068875,0.000000
49.790001,22.743767,-281.920258,-0.000992,0.002682,0.068112,101.169327,5.153811,0.681122,-281.920258,0.069274,0.000000
50.030003,23.427437,-282.053711,-0.000953,0.002703,0.068667,104.210442,5.308733,0.686671,-282.053711,0.069682,0.000000
50.270004,23.517929,-282.009216,-0.000923,0.002718,0.069031,104.612976,5.329239,0.690312,-282.009216,0.070081,0.000000
50.510002,23.408073,-282.098206,-0.000910,0.002729,0.069326,104.124313,5.304345,0.693264,-282.098206,0.070480,0.000000
50.750004,24.474548,-282.098206,-0.000910,0.002756,0.069994,108.868225,5.546012,0.699941,-282.098206,0.070879,0.000000
50.990002,24.814529,-282.053711,-0.000841,0.002774,0.070463,110.380539,5.623053,0.704626,-282.053711,0.071278,0.000000
51.230003,24.192665,-282.098206,-0.000836,0.002783,0.070697,107.614349,5.482137,0.706965,-282.098206,0.071677,0.000000
51.470001,24.262672,-282.142670,-0.000819,0.002800,0.071113,107.925758,5.498000,0.711129,-282.142670,0.072076,0.000000
51.710003,23.832954,-282.187164,-0.000802,0.002809,0.071347,106.014275,5.400625,0.713468,-282.187164,0.072475,0.000000
51.950001,24.385925,-282.098206,-0.000780,0.002828,0.071824,108.474014,5.525930,0.718237,-282.098206,0.072882,0.000000
52.190002,24.791443,-282.187164,-0.000767,0.002843,0.072214,110.277847,5.617822,0.722143,-282.187164,0.073281,0.000000
52.430004,25.009277,-282.187164,-0.000763,0.002859,0.072613,111.246819,5.667183,0.726132,-282.187164,0.073680,0.000000
52.670002,25.660187,-282.231628,-0.000716,0.002880,0.073160,114.142212,5.814682,0.731597,-282.231628,0.074079,0.000000
52.910004,25.806152,-282.231628,-0.000711,0.002897,0.073593,114.791496,5.847758,0.735927,-282.231628,0.074478,0.000000
53.150002,25.496712,-282.231628,-0.000668,0.002910,0.073905,113.415039,5.777637,0.739054,-282.231628,0.074877,0.000000
53.390003,25.437881,-282.276123,-0.000664,0.002923,0.074252,113.153351,5.764306,0.742521,-282.276123,0.075276,0.000000
53.630001,25.430801,-282.320587,-0.000621,0.002936,0.074581,113.121857,5.762702,0.745814,-282.320587,0.075674,0.000000
53.870003,26.393387,-282.320587,-0.000621,0.002961,0.075206,117.403648,5.980827,0.752059,-282.320587,0.076082,0.000000
54.110004,25.991600,-282.365082,-0.000595,0.002971,0.075466,115.616409,5.889781,0.754663,-282.365082,0.076481,0.000000
54.350002,26.021011,-282.365082,-0.000552,0.002985,0.075822,115.747238,5.896445,0.758220,-282.365082,0.076880,0.000000
54.590004,25.986755,-282.409546,-0.000552,0.002996,0.076108,115.594864,5.888683,0.761082,-282.409546,0.077278,0.000000
54.830002,27.074829,-282.454041,-0.000517,0.003022,0.076758,120.434853,6.135244,0.767584,-282.454041,0.077677,0.000000
55.070004,27.149300,-282.409546,-0.000487,0.003038,0.077175,120.766113,6.152119,0.771748,-282.409546,0.078076,0.000000
55.310001,26.975029,-282.498535,-0.000487,0.003053,0.077539,119.990921,6.112629,0.775389,-282.498535,0.078475,0.000000
55.550003,27.042435,-282.498535,-0.000466,0.003067,0.077895,120.290756,6.127903,0.778947,-282.498535,0.078874,0.000000
55.790001,26.839119,-282.542999,-0.000444,0.003078,0.078189,119.386360,6.081831,0.781891,-282.542999,0.079282,0.000000
56.030003,27.391342,-282.542999,-0.000414,0.003096,0.078640,121.842773,6.206967,0.786403,-282.542999,0.079681,0.000000
56.270004,27.117279,-282.498535,-0.000410,0.003106,0.078892,120.623680,6.144863,0.788916,-282.498535,0.080080,0.000000
56.510002,28.678261,-282.542999,-0.000392,0.003135,0.079638,127.567276,6.498587,0.796380,-282.542999,0.080479,0.000000
56.750004,29.201073,-282.542999,-0.000371,0.003155,0.080141,129.892853,6.617057,0.801406,-282.542999,0.080878,0.000000
56.990002,28.703217,-282.631958,-0.000328,0.003166,0.080409,127.678284,6.504242,0.804093,-282.631958,0.081277,0.000000
57.230003,28.429146,-282.631958,-0.000328,0.003178,0.080713,126.459160,6.442136,0.807129,-282.631958,0.081676,0.000000
57.470001,28.660019,-282.631958,-0.000315,0.003193,0.081094,127.486130,6.494453,0.810944,-282.631958,0.082083,0.000000
57.710003,29.133301,-282.676453,-0.000280,0.003212,0.081580,129.591400,6.601700,0.815804,-282.676453,0.082482,0.000000
57.950005,29.322838,-282.631958,-0.000250,0.003223,0.081867,130.434494,6.644650,0.818665,-282.631958,0.082881,0.000000
58.190002,29.126976,-282.720917,-0.000250,0.003233,0.082127,129.563263,6.600267,0.821269,-282.720917,0.083280,0.000000
58.430004,30.331223,-282.765411,-0.000207,0.003258,0.082751,134.920013,6.873153,0.827507,-282.765411,0.083679,0.000000
58.670002,31.264389,-282.676453,-0.000211,0.003278,0.083254,139.070953,7.084612,0.832541,-282.676453,0.084078,0.000000
58.910004,31.068520,-282.765411,-0.000194,0.003289,0.083540,138.199677,7.040227,0.835402,-282.765411,0.084477,0.000000
59.150002,31.176140,-282.765411,-0.000172,0.003303,0.083896,138.678391,7.064614,0.838960,-282.765411,0.084876,0.000000
59.390003,31.423019,-282.809875,-0.000168,0.003316,0.084234,139.776566,7.120558,0.842336,-282.809875,0.085284,0.000000
59.630001,32.236282,-282.854370,-0.000142,0.003337,0.084772,143.394150,7.304846,0.847718,-282.854370,0.085682,0.000000
59.870003,32.253784,-282.809875,-0.000134,0.003349,0.085058,143.472000,7.308812,0.850579,-282.809875,0.086081,0.000000
60.110004,32.452255,-282.898834,-0.000103,0.003361,0.085379,144.354843,7.353786,0.853789,-282.898834,0.086480,0.000000
60.350002,32.673820,-282.854370,-0.000095,0.003372,0.085656,145.340408,7.403994,0.856560,-282.854370,0.086879,0.000000
60.590004,34.349121,-282.898834,-0.000069,0.003401,0.086385,152.792526,7.783622,0.863849,-282.898834,0.087278,0.000000
60.830002,34.194962,-282.898834,-0.000069,0.003410,0.086619,152.106781,7.748689,0.866188,-282.898834,0.087677,0.000000
61.070004,34.562119,-282.943329,-0.000056,0.003428,0.087061,153.739975,7.831888,0.870609,-282.943329,0.088076,0.000000
61.310001,35.446503,-282.987823,-0.000039,0.003446,0.087529,157.673920,8.032292,0.875295,-282.987823,0.088483,0.000000
61.550003,36.342804,-282.898834,-0.000039,0.003464,0.087998,161.660873,8.235397,0.879981,-282.898834,0.088882,0.000000
61.790005,36.981422,-283.032288,-0.000009,0.003480,0.088388,164.501587,8.380110,0.883879,-283.032288,0.089281,0.000000
62.030003,37.153831,-283.032288,0.000013,0.003492,0.088701,165.268494,8.419178,0.887005,-283.032288,0.089680,0.000000
62.270004,37.015312,-283.032288,0.000022,0.003501,0.088925,164.652328,8.387790,0.889253,-283.032288,0.090079,0.000000
62.510002,38.906593,-283.076782,0.000013,0.003530,0.089663,173.065170,8.816360,0.896626,-283.076782,0.090478,0.000000
62.750004,38.959465,-283.032288,0.000047,0.003538,0.089862,173.300354,8.828341,0.898625,-283.032288,0.090877,0.000000
62.990002,39.259972,-283.121246,0.000022,0.003553,0.090252,174.637070,8.896437,0.902523,-283.121246,0.091276,0.000000
63.230003,40.149567,-283.121246,0.000052,0.003569,0.090660,178.594193,9.098022,0.906603,-283.121246,0.091684,0.000000
63.470001,40.893570,-283.121246,0.000052,0.003585,0.091050,181.903687,9.266615,0.910502,-283.121246,0.092083,0.000000
63.710003,41.550438,-283.165741,0.000095,0.003599,0.091406,184.825577,9.415464,0.914060,-283.165741,0.092482,0.000000
63.950005,42.518974,-283.165741,0.000091,0.003617,0.091865,189.133850,9.634937,0.918655,-283.165741,0.092881,0.000000
64.190002,42.904007,-283.210205,0.000108,0.003628,0.092143,190.846558,9.722187,0.921433,-283.210205,0.093279,0.000000
64.430000,44.387917,-283.210205,0.000108,0.003652,0.092750,197.447311,10.058445,0.927504,-283.210205,0.093678,0.000000
64.670006,45.092812,-283.299164,0.000142,0.003668,0.093175,200.582840,10.218177,0.931750,-283.299164,0.094077,0.000000
64.910004,45.535568,-283.299164,0.000125,0.003681,0.093504,202.552322,10.318507,0.935043,-283.299164,0.094476,0.000000
65.150002,45.999542,-283.254700,0.000151,0.003693,0.093808,204.616180,10.423645,0.938079,-283.254700,0.094884,0.000000
65.389999,46.833656,-283.343658,0.000147,0.003708,0.094173,208.326508,10.612658,0.941727,-283.343658,0.095282,0.000000
65.630005,47.489403,-283.299164,0.000168,0.003721,0.094510,211.243408,10.761252,0.945103,-283.299164,0.095681,0.000000
65.870003,48.179039,-283.388153,0.000168,0.003736,0.094892,214.311066,10.917526,0.948919,-283.388153,0.096080,0.000000
66.110001,49.042938,-283.477112,0.000172,0.003751,0.095273,218.153885,11.113289,0.952734,-283.477112,0.096479,0.000000
66.350006,50.861984,-283.388153,0.000172,0.003778,0.095950,226.245407,11.525491,0.959501,-283.388153,0.096878,0.000000
66.590004,52.005165,-283.477112,0.000229,0.003792,0.096323,231.330521,11.784539,0.963233,-283.477112,0.097277,0.000000
66.830002,52.266571,-283.388153,0.000224,0.003801,0.096549,232.493317,11.843774,0.965489,-283.388153,0.097676,0.000000
67.070000,53.279427,-283.477112,0.000211,0.003819,0.096991,236.998734,12.073291,0.969910,-283.477112,0.098083,0.000000
67.310005,54.031242,-283.521576,0.000241,0.003833,0.097363,240.342972,12.243654,0.973634,-283.521576,0.098482,0.000000
67.550003,55.338646,-283.521576,0.000237,0.003854,0.097884,246.158585,12.539917,0.978842,-283.521576,0.098881,0.000000
67.790001,56.277397,-283.610535,0.000237,0.003868,0.098248,250.334366,12.752640,0.982483,-283.610535,0.099280,0.000000
68.030006,57.278328,-283.521576,0.000250,0.003884,0.098656,254.786728,12.979454,0.986556,-283.521576,0.099679,0.000000
68.270004,58.784576,-283.610535,0.000241,0.003905,0.099185,261.486847,13.320776,0.991847,-283.610535,0.100078,0.000000
68.510002,59.515541,-283.655029,0.000263,0.003917,0.099488,264.738342,13.486414,0.994882,-283.655029,0.100477,0.000000
68.750000,59.919571,-283.610535,0.000276,0.003928,0.099783,266.535553,13.577969,0.997835,-283.610535,0.100876,0.000000
68.990005,60.797623,-283.655029,0.000263,0.003942,0.100122,270.441345,13.776938,1.001218,-283.655029,0.101284,0.000000
69.230003,61.630249,-283.655029,0.000302,0.003954,0.100442,274.145050,13.965614,1.004420,-283.655029,0.101683,0.000000
69.470001,63.582970,-283.655029,0.000289,0.003977,0.101023,282.831177,14.408107,1.010234,-283.655029,0.102082,0.000000
69.710007,64.252495,-283.699493,0.000297,0.003990,0.101335,285.809357,14.559824,1.013353,-283.699493,0.102481,0.000000
69.950005,65.696556,-283.699493,0.000297,0.004011,0.101873,292.232880,14.887053,1.018735,-283.699493,0.102880,0.000000
70.190002,67.316750,-283.788483,0.000319,0.004020,0.102116,299.439850,15.254193,1.021165,-283.788483,0.102307,0.000000
70.430000,66.674782,-283.743988,0.000332,0.004020,0.102099,296.584229,15.108722,1.020991,-283.743988,0.102307,0.000000
70.670006,66.131493,-283.788483,0.000310,0.004019,0.102090,294.167572,14.985610,1.020900,-283.788483,0.102099,0.000000
70.910004,65.682411,-283.788483,0.000332,0.004019,0.102090,292.169952,14.883847,1.020900,-283.788483,0.102099,0.000000
71.150002,65.289925,-283.832947,0.000336,0.004019,0.102082,290.424103,14.794909,1.020816,-283.832947,0.102099,0.000000
71.390007,64.950691,-283.877441,0.000332,0.004019,0.102082,288.915100,14.718037,1.020816,-283.877441,0.102099,0.000000
71.630005,64.656151,-283.832947,0.000345,0.004019,0.102082,287.604919,14.651293,1.020816,-283.832947,0.102099,0.000000
71.870003,64.392509,-283.877441,0.000362,0.004019,0.102082,286.432190,14.591551,1.020816,-283.877441,0.102099,0.000000
72.110001,64.151588,-283.921906,0.000345,0.004019,0.102082,285.360504,14.536958,1.020816,-283.921906,0.102099,0.000000
72.350006,63.932625,-283.877441,0.000358,0.004019,0.102082,284.386505,14.487340,1.020816,-283.877441,0.102099,0.000000
72.590004,63.740852,-284.010864,0.000345,0.004019,0.102082,283.533478,14.443883,1.020816,-284.010864,0.102099,0.000000
72.830002,63.553185,-283.966400,0.000354,0.004019,0.102082,282.698669,14.401357,1.020816,-283.966400,0.102099,0.000000
73.070000,63.388588,-283.966400,0.000345,0.004019,0.102082,281.966522,14.364059,1.020816,-283.966400,0.102099,0.000000
73.310005,63.238152,-284.010864,0.000354,0.004019,0.102082,281.297333,14.329970,1.020816,-284.010864,0.102099,0.000000
73.550003,63.091438,-284.010864,0.000362,0.004019,0.102082,280.644745,14.296724,1.020816,-284.010864,0.102099,0.000000
73.790001,62.966690,-284.055359,0.000349,0.004019,0.102082,280.089813,14.268456,1.020816,-284.055359,0.102099,0.000000
74.030006,62.832268,-284.010864,0.000354,0.004019,0.102082,279.491882,14.237996,1.020816,-284.010864,0.102099,0.000000
74.270004,62.733589,-284.099823,0.000362,0.004019,0.102082,279.052948,14.215634,1.020816,-284.099823,0.102099,0.000000
74.510002,62.610703,-284.144318,0.000345,0.004019,0.102082,278.506317,14.187788,1.020816,-284.144318,0.102099,0.000000
74.750000,62.531013,-284.099823,0.000358,0.004019,0.102082,278.151825,14.169730,1.020816,-284.099823,0.102099,0.000000
74.990005,62.412971,-284.144318,0.000371,0.004019,0.102082,277.626770,14.142982,1.020816,-284.144318,0.102099,0.000000
75.230003,62.332169,-284.099823,0.000358,0.004019,0.102082,277.267334,14.124672,1.020816,-284.099823,0.102099,0.000000
75.470001,62.243172,-284.233276,0.000362,0.004019,0.102082,276.871460,14.104504,1.020816,-284.233276,0.102099,0.000000
75.710007,62.160133,-284.233276,0.000341,0.004019,0.102082,276.502075,14.085687,1.020816,-284.233276,0.102099,0.000000
75.950005,62.074860,-284.277771,0.000362,0.004019,0.102082,276.122772,14.066364,1.020816,-284.277771,0.102099,0.000000
76.190002,61.998528,-284.322235,0.000384,0.004019,0.102082,275.783234,14.049067,1.020816,-284.322235,0.102099,0.000000
76.430000,61.926285,-284.233276,0.000332,0.004019,0.102082,275.461884,14.032697,1.020816,-284.233276,0.102099,0.000000
76.670006,61.861488,-284.366730,0.000366,0.004019,0.102082,275.173645,14.018014,1.020816,-284.366730,0.102099,0.000000
76.910004,61.798561,-284.322235,0.000384,0.004019,0.102082,274.893738,14.003755,1.020816,-284.322235,0.102099,0.000000
77.150002,61.748665,-284.366730,0.000366,0.004019,0.102082,274.671783,13.992447,1.020816,-284.366730,0.102099,0.000000
77.390007,61.686852,-284.366730,0.000362,0.004019,0.102082,274.396820,13.978440,1.020816,-284.366730,0.102099,0.000000
77.630005,61.619820,-284.366730,0.000349,0.004019,0.102082,274.098633,13.963250,1.020816,-284.366730,0.102099,0.000000
77.870003,61.573647,-284.455688,0.000375,0.004019,0.102082,273.893250,13.952787,1.020816,-284.455688,0.102099,0.000000
78.110001,61.493584,-284.411194,0.000362,0.004019,0.102082,273.537109,13.934645,1.020816,-284.411194,0.102099,0.000000
78.350006,61.461189,-284.411194,0.000379,0.004019,0.102082,273.393036,13.927304,1.020816,-284.411194,0.102099,0.000000
78.590004,61.396400,-284.455688,0.000379,0.004019,0.102082,273.104828,13.912623,1.020816,-284.455688,0.102099,0.000000
78.830002,61.365860,-284.411194,0.000362,0.004019,0.102082,272.968964,13.905703,1.020816,-284.411194,0.102099,0.000000
79.070007,61.291763,-284.544647,0.000354,0.004019,0.102082,272.639374,13.888911,1.020816,-284.544647,0.102099,0.000000
79.310005,61.266068,-284.500153,0.000375,0.004019,0.102082,272.525085,13.883090,1.020816,-284.500153,0.102099,0.000000
79.550003,61.228828,-284.544647,0.000336,0.004019,0.102082,272.359436,13.874650,1.020816,-284.544647,0.102099,0.000000
79.790001,61.163292,-284.544647,0.000379,0.004019,0.102082,272.067902,13.859800,1.020816,-284.544647,0.102099,0.000000
80.030006,61.147652,-284.589111,0.000345,0.004019,0.102082,271.998352,13.856256,1.020816,-284.589111,0.102099,0.000000
80.270004,61.086960,-284.589111,0.000379,0.004019,0.102082,271.728363,13.842503,1.020816,-284.589111,0.102099,0.000000
80.510002,61.054932,-284.589111,0.000375,0.004019,0.102082,271.585907,13.835245,1.020816,-284.589111,0.102099,0.000000
80.750008,61.019928,-284.678101,0.000371,0.004019,0.102082,271.430206,13.827313,1.020816,-284.678101,0.102099,0.000000
80.990005,60.980461,-284.633606,0.000354,0.004019,0.102082,271.254639,13.818370,1.020816,-284.633606,0.102099,0.000000
81.230003,60.948807,-284.678101,0.000366,0.004019,0.102082,271.113831,13.811196,1.020816,-284.678101,0.102099,0.000000
81.470001,60.899651,-284.767059,0.000384,0.004019,0.102082,270.895172,13.800057,1.020816,-284.767059,0.102099,0.000000
81.710007,60.848267,-284.722565,0.000384,0.004019,0.102082,270.666595,13.788415,1.020816,-284.722565,0.102099,0.000000
81.950005,60.818100,-284.722565,0.000375,0.004019,0.102082,270.532410,13.781579,1.020816,-284.722565,0.102099,0.000000
82.190002,60.782730,-284.767059,0.000375,0.004019,0.102082,270.375092,13.773563,1.020816,-284.767059,0.102099,0.000000
82.430000,60.749962,-284.767059,0.000375,0.004019,0.102082,270.229340,13.766138,1.020816,-284.767059,0.102099,0.000000
82.670006,60.719795,-284.811523,0.000392,0.004019,0.102082,270.095154,13.759302,1.020816,-284.811523,0.102099,0.000000
82.910004,60.693359,-284.722565,0.000397,0.004019,0.102082,269.977539,13.753312,1.020816,-284.722565,0.102099,0.000000
83.150002,60.657242,-284.811523,0.000366,0.004019,0.102082,269.816895,13.745128,1.020816,-284.811523,0.102099,0.000000
83.390007,60.636383,-284.856018,0.000371,0.004019,0.102082,269.724091,13.740400,1.020816,-284.856018,0.102099,0.000000
83.630005,60.608086,-284.856018,0.000366,0.004019,0.102082,269.598236,13.733989,1.020816,-284.856018,0.102099,0.000000
83.870003,60.575317,-284.856018,0.000375,0.004019,0.102082,269.452484,13.726563,1.020816,-284.856018,0.102099,0.000000
84.110001,60.546272,-284.856018,0.000379,0.004019,0.102082,269.323273,13.719981,1.020816,-284.856018,0.102099,0.000000
84.350006,60.514992,-284.944977,0.000371,0.004019,0.102082,269.184113,13.712893,1.020816,-284.944977,0.102099,0.000000
84.590004,60.498611,-284.944977,0.000379,0.004019,0.102082,269.111267,13.709182,1.020816,-284.944977,0.102099,0.000000
84.830002,60.465096,-284.944977,0.000375,0.004019,0.102082,268.962189,13.701587,1.020816,-284.944977,0.102099,0.000000
85.070007,60.444611,-285.033936,0.000384,0.004019,0.102082,268.871063,13.696944,1.020816,-285.033936,0.102099,0.000000
85.310005,60.407753,-284.989441,0.000358,0.004019,0.102082,268.707092,13.688593,1.020816,-284.989441,0.102099,0.000000
85.550003,60.386894,-285.033936,0.000358,0.004019,0.102082,268.614319,13.683866,1.020816,-285.033936,0.102099,0.000000
85.790001,60.364929,-285.033936,0.000375,0.004019,0.102082,268.516602,13.678889,1.020816,-285.033936,0.102099,0.000000
86.030006,60.330666,-285.078430,0.000371,0.004019,0.102082,268.364197,13.671124,1.020816,-285.078430,0.102099,0.000000
86.270004,60.306839,-285.078430,0.000366,0.004019,0.102082,268.258209,13.665725,1.020816,-285.078430,0.102099,0.000000
86.510002,60.281143,-285.078430,0.000366,0.004019,0.102082,268.143921,13.659903,1.020816,-285.078430,0.102099,0.000000
86.750008,60.260666,-285.167389,0.000366,0.004019,0.102082,268.052826,13.655262,1.020816,-285.167389,0.102099,0.000000
86.990005,60.233109,-285.211853,0.000362,0.004019,0.102082,267.930237,13.649017,1.020816,-285.211853,0.102099,0.000000
87.230003,60.218956,-285.167389,0.000375,0.004019,0.102082,267.867310,13.645811,1.020816,-285.167389,0.102099,0.000000
87.470001,60.182091,-285.256348,0.000362,0.004019,0.102082,267.703308,13.637457,1.020816,-285.256348,0.102099,0.000000
87.710007,60.154907,-285.211853,0.000358,0.004019,0.102082,267.582397,13.631297,1.020816,-285.211853,0.102099,0.000000
87.950005,60.134430,-285.256348,0.000349,0.004019,0.102082,267.491302,13.626657,1.020816,-285.256348,0.102099,0.000000
88.190002,60.120277,-285.211853,0.000375,0.004019,0.102082,267.428345,13.623450,1.020816,-285.211853,0.102099,0.000000
88.430008,60.102776,-285.256348,0.000379,0.004019,0.102082,267.350494,13.619483,1.020816,-285.256348,0.102099,0.000000
88.670006,60.075592,-285.345306,0.000366,0.004019,0.102082,267.229584,13.613324,1.020816,-285.345306,0.102099,0.000000
88.910004,60.058464,-285.256348,0.000354,0.004019,0.102082,267.153381,13.609443,1.020816,-285.256348,0.102099,0.000000
89.150002,60.027184,-285.389771,0.000371,0.004019,0.102082,267.014252,13.602354,1.020816,-285.389771,0.102099,0.000000
89.390007,60.016014,-285.389771,0.000384,0.004019,0.102082,266.964569,13.599823,1.020816,-285.389771,0.102099,0.000000
89.630005,59.993301,-285.389771,0.000392,0.004019,0.102082,266.863525,13.594677,1.020816,-285.389771,0.102099,0.000000
89.870003,59.965744,-285.389771,0.000375,0.004019,0.102082,266.740936,13.588431,1.020816,-285.389771,0.102099,0.000000
90.110001,59.945259,-285.389771,0.000384,0.004019,0.102082,266.649841,13.583790,1.020816,-285.389771,0.102099,0.000000
90.350006,59.926643,-285.523224,0.000366,0.004019,0.102082,266.567017,13.579571,1.020816,-285.523224,0.102099,0.000000
90.590004,59.911751,-285.434265,0.000371,0.004019,0.102082,266.500763,13.576197,1.020816,-285.434265,0.102099,0.000000
90.830002,59.892014,-285.434265,0.000366,0.004019,0.102082,266.412994,13.571725,1.020816,-285.434265,0.102099,0.000000
91.070007,59.872276,-285.612183,0.000392,0.004019,0.102082,266.325195,13.567252,1.020816,-285.612183,0.102099,0.000000
91.310005,59.855522,-285.523224,0.000375,0.004019,0.102082,266.250671,13.563455,1.020816,-285.523224,0.102099,0.000000
91.550003,59.836533,-285.567719,0.000379,0.004019,0.102082,266.166199,13.559152,1.020816,-285.567719,0.102099,0.000000
91.790001,59.817169,-285.523224,0.000379,0.004019,0.102082,266.080048,13.554765,1.020816,-285.523224,0.102099,0.000000
92.030006,59.794083,-285.567719,0.000379,0.004019,0.102082,265.977356,13.549532,1.020816,-285.567719,0.102099,0.000000
92.270004,59.799667,-285.656677,0.000375,0.004019,0.102082,266.002197,13.550797,1.020816,-285.656677,0.102099,0.000000
92.510002,59.763542,-285.656677,0.000379,0.004019,0.102082,265.841522,13.542612,1.020816,-285.656677,0.102099,0.000000
92.750008,59.751633,-285.701141,0.000388,0.004019,0.102082,265.788544,13.539914,1.020816,-285.701141,0.102099,0.000000
92.990005,59.738594,-285.656677,0.000392,0.004019,0.102082,265.730530,13.536959,1.020816,-285.656677,0.102099,0.000000
93.230003,59.714767,-285.656677,0.000358,0.004019,0.102082,265.624542,13.531560,1.020816,-285.656677,0.102099,0.000000
93.470001,59.706573,-285.701141,0.000384,0.004019,0.102082,265.588104,13.529703,1.020816,-285.701141,0.102099,0.000000
93.710007,59.698380,-285.701141,0.000384,0.004019,0.102082,265.551666,13.527846,1.020816,-285.701141,0.102099,0.000000
93.950005,59.673431,-285.701141,0.000366,0.004019,0.102082,265.440674,13.522193,1.020816,-285.701141,0.102099,0.000000
94.190002,59.664864,-285.745636,0.000384,0.004019,0.102082,265.402557,13.520251,1.020816,-285.745636,0.102099,0.000000
94.430008,59.641403,-285.745636,0.000354,0.004019,0.102082,265.298218,13.514935,1.020816,-285.745636,0.102099,0.000000
94.670006,59.628372,-285.790100,0.000375,0.004019,0.102082,265.240234,13.511982,1.020816,-285.790100,0.102099,0.000000
94.910004,59.614967,-285.790100,0.000384,0.004019,0.102082,265.180634,13.508945,1.020816,-285.790100,0.102099,0.000000
95.150002,59.607521,-285.879059,0.000366,0.004019,0.102082,265.147491,13.507257,1.020816,-285.879059,0.102099,0.000000
95.390007,59.585548,-285.879059,0.000384,0.004019,0.102082,265.049744,13.502278,1.020816,-285.879059,0.102099,0.000000
95.630005,59.584061,-285.879059,0.000397,0.004019,0.102082,265.043152,13.501941,1.020816,-285.879059,0.102099,0.000000
95.870003,59.565071,-285.968048,0.000379,0.004019,0.102082,264.958679,13.497639,1.020816,-285.968048,0.102099,0.000000
96.110008,59.553528,-285.879059,0.000384,0.004019,0.102082,264.907318,13.495022,1.020816,-285.879059,0.102099,0.000000
96.350006,59.537888,-285.968048,0.000384,0.004019,0.102082,264.837738,13.491478,1.020816,-285.968048,0.102099,0.000000
96.590004,59.514427,-285.968048,0.000375,0.004019,0.102082,264.733398,13.486161,1.020816,-285.968048,0.102099,0.000000
96.830002,59.514053,-285.968048,0.000397,0.004019,0.102082,264.731720,13.486077,1.020816,-285.968048,0.102099,0.000000
97.070007,59.499161,-285.968048,0.000366,0.004019,0.102082,264.665497,13.482702,1.020816,-285.968048,0.102099,0.000000
97.310005,59.489479,-286.012512,0.000379,0.004019,0.102082,264.622406,13.480509,1.020816,-286.012512,0.102099,0.000000
97.550003,59.475700,-286.012512,0.000397,0.004019,0.102082,264.561127,13.477386,1.020816,-286.012512,0.102099,0.000000
97.790001,59.458946,-286.057007,0.000397,0.004019,0.102082,264.486603,13.473590,1.020816,-286.057007,0.102099,0.000000
98.030006,59.446655,-286.057007,0.000384,0.004019,0.102082,264.431915,13.470804,1.020816,-286.057007,0.102099,0.000000
98.270004,59.435860,-286.101471,0.000392,0.004019,0.102082,264.383911,13.468359,1.020816,-286.101471,0.102099,0.000000
98.510002,59.422081,-286.101471,0.000401,0.004019,0.102082,264.322632,13.465236,1.020816,-286.101471,0.102099,0.000000
98.750008,59.404953,-286.101471,0.000397,0.004019,0.102082,264.246429,13.461354,1.020816,-286.101471,0.102099,0.000000
98.990005,59.396759,-286.145966,0.000384,0.004019,0.102082,264.209991,13.459498,1.020816,-286.145966,0.102099,0.000000
99.230003,59.382233,-286.145966,0.000384,0.004019,0.102082,264.145355,13.456206,1.020816,-286.145966,0.102099,0.000000
99.470001,59.368088,-286.190430,0.000379,0.004019,0.102082,264.082458,13.453001,1.020816,-286.190430,0.102099,0.000000
99.710007,59.359146,-286.190430,0.000392,0.004019,0.102082,264.042664,13.450974,1.020816,-286.190430,0.102099,0.000000
99.950005,59.334572,-286.234924,0.000388,0.004019,0.102082,263.933350,13.445406,1.020816,-286.234924,0.102099,0.000000
100.190002,59.340530,-286.234924,0.000379,0.004019,0.102082,263.959869,13.446756,1.020816,-286.234924,0.102099,0.000000
100.430008,59.317070,-286.234924,0.000354,0.004019,0.102082,263.855499,13.441441,1.020816,-286.234924,0.102099,0.000000
100.600006,59.317444,-286.323883,0.000371,0.004019,0.102082,263.857178,13.441525,1.020816,-286.323883,0.102099,0.000000