File: Data/compression 23/AutoNoHeating-12-23-reverse-2-4_09192024_184913.csv
Time (sec),S:Load (lbs),S:HL1 (DIM),S:LVDT (in),S:Position (in),Ch:Position (mm),Ch:Load (N),Ch:Stress (MPa),Ch:Strain (mm/mm),Ch:HL1 (DIM),Set Point (),Cycles ()
0.110000,-0.147827,-399.127563,-0.012766,-0.007875,-0.200026,-0.657568,-0.033498,-2.000257,-399.127563,-0.199774,0.000000
0.500000,-0.081543,-399.172058,-0.012762,-0.007824,-0.198724,-0.362721,-0.018478,-1.987244,-399.172058,-0.198022,0.000000
0.890000,-0.082664,-399.127563,-0.012637,-0.007593,-0.192853,-0.367710,-0.018732,-1.928533,-399.127563,-0.191535,0.000000
1.280000,-0.100906,-399.216522,-0.012400,-0.007337,-0.186349,-0.448854,-0.022866,-1.863493,-399.216522,-0.185031,0.000000
1.670000,-0.121391,-399.216522,-0.012107,-0.007077,-0.179750,-0.539975,-0.027508,-1.797500,-399.216522,-0.178544,0.000000
2.060000,-0.129211,-399.216522,-0.011857,-0.006825,-0.173350,-0.574761,-0.029280,-1.733497,-399.216522,-0.172040,0.000000
2.450000,-0.102768,-399.261017,-0.011602,-0.006568,-0.166828,-0.457135,-0.023288,-1.668283,-399.261017,-0.165536,0.000000
2.840000,-0.082291,-399.261017,-0.011318,-0.006308,-0.160228,-0.366047,-0.018647,-1.602282,-399.261017,-0.159049,0.000000
3.230000,-0.099792,-399.261017,-0.011059,-0.006059,-0.153889,-0.443899,-0.022613,-1.538893,-399.261017,-0.152545,0.000000
3.620000,-0.117668,-399.349976,-0.010800,-0.005802,-0.147359,-0.523414,-0.026664,-1.473588,-399.349976,-0.146058,0.000000
4.010000,-0.127724,-399.349976,-0.010524,-0.005538,-0.140664,-0.568143,-0.028943,-1.406641,-399.349976,-0.139554,0.000000
4.400000,-0.120644,-399.349976,-0.010261,-0.005282,-0.134151,-0.536650,-0.027338,-1.341511,-399.349976,-0.133050,0.000000
4.790000,-0.094582,-399.394470,-0.009998,-0.005029,-0.127733,-0.420720,-0.021432,-1.277334,-399.394470,-0.126563,0.000000
5.180000,-0.067772,-399.349976,-0.009753,-0.004778,-0.121368,-0.301465,-0.015357,-1.213680,-399.349976,-0.120058,0.000000
5.570000,-0.092346,-399.394470,-0.009481,-0.004526,-0.114950,-0.410776,-0.020926,-1.149503,-399.394470,-0.113554,0.000000
5.960001,-0.097183,-399.438934,-0.009209,-0.004257,-0.108117,-0.432293,-0.022022,-1.081170,-399.438934,-0.107068,0.000000
6.350000,-0.138893,-399.438934,-0.008964,-0.004013,-0.101925,-0.617827,-0.031474,-1.019250,-399.438934,-0.100563,0.000000
6.740000,-0.092346,-399.438934,-0.008666,-0.003747,-0.095178,-0.410776,-0.020926,-0.951780,-399.438934,-0.094077,0.000000
7.130000,-0.073723,-399.438934,-0.008425,-0.003493,-0.088735,-0.327936,-0.016706,-0.887346,-399.438934,-0.087573,0.000000
7.520000,-0.077820,-399.572388,-0.008175,-0.003244,-0.082404,-0.346160,-0.017634,-0.824040,-399.572388,-0.081068,0.000000
7.910000,-0.111336,-399.483429,-0.007899,-0.002988,-0.075891,-0.495246,-0.025229,-0.758909,-399.483429,-0.074581,0.000000
8.300000,-0.115059,-399.527893,-0.007627,-0.002724,-0.069187,-0.511808,-0.026073,-0.691871,-399.527893,-0.068077,0.000000
8.690001,-0.116180,-399.572388,-0.007360,-0.002468,-0.062691,-0.516796,-0.026327,-0.626915,-399.572388,-0.061590,0.000000
9.080001,-0.086761,-399.616852,-0.007097,-0.002221,-0.056421,-0.385934,-0.019660,-0.564214,-399.616852,-0.055086,0.000000
9.470000,-0.064415,-399.616852,-0.006829,-0.001959,-0.049762,-0.286532,-0.014597,-0.497615,-399.616852,-0.048582,0.000000
9.860001,-0.087875,-399.616852,-0.006579,-0.001707,-0.043361,-0.390889,-0.019913,-0.433613,-399.616852,-0.042095,0.000000
10.250001,-0.116547,-399.661346,-0.006299,-0.001444,-0.036667,-0.518425,-0.026410,-0.366665,-399.661346,-0.035591,0.000000
10.640000,-0.118408,-399.705841,-0.006058,-0.001195,-0.030362,-0.526706,-0.026832,-0.303617,-399.705841,-0.029104,0.000000
11.030001,-0.080803,-399.661346,-0.005786,-0.000933,-0.023710,-0.359429,-0.018310,-0.237101,-399.661346,-0.022600,0.000000
11.420000,-0.053619,-399.705841,-0.005527,-0.000684,-0.017370,-0.238511,-0.012150,-0.173704,-399.705841,-0.016096,0.000000
11.810000,-0.004463,-399.616852,-0.005269,-0.000427,-0.010857,-0.019853,-0.001011,-0.108573,-399.616852,-0.009609,0.000000
12.200001,0.066658,-399.794800,-0.005014,-0.000171,-0.004336,0.296510,0.015105,-0.043360,-399.794800,-0.003104,0.000000
12.590000,0.025322,-399.750305,-0.004902,-0.000005,-0.000129,0.112638,0.005738,-0.001294,-399.750305,0.000104,0.000000
12.980000,0.071129,-399.794800,-0.004924,-0.000005,-0.000129,0.316397,0.016118,-0.001294,-399.794800,0.000382,0.000000
13.370001,0.070755,-399.839264,-0.004911,-0.000005,-0.000129,0.314734,0.016033,-0.001294,-399.839264,0.001033,0.000000
13.760000,0.094215,-399.839264,-0.004894,0.000031,0.000790,0.419091,0.021350,0.007895,-399.839264,0.001683,0.000000
14.150001,0.097191,-399.883759,-0.004863,0.000056,0.001422,0.432327,0.022024,0.014224,-399.883759,0.002333,0.000000
14.540001,0.065544,-399.883759,-0.004842,0.000077,0.001943,0.291555,0.014853,0.019432,-399.883759,0.002983,0.000000
14.930000,0.156769,-399.839264,-0.004829,0.000106,0.002697,0.697342,0.035524,0.026971,-399.839264,0.003634,0.000000
15.320001,0.169060,-399.928223,-0.004781,0.000136,0.003443,0.752015,0.038309,0.034435,-399.928223,0.004285,0.000000
15.710001,0.177254,-399.883759,-0.004777,0.000158,0.004007,0.788464,0.040166,0.040067,-399.883759,0.004935,0.000000
16.100000,0.184326,-399.972717,-0.004747,0.000184,0.004674,0.819924,0.041769,0.046743,-399.972717,0.005585,0.000000
16.490002,0.180603,-399.928223,-0.004725,0.000209,0.005308,0.803362,0.040925,0.053079,-399.928223,0.006236,0.000000
16.880001,0.225662,-399.972717,-0.004682,0.000233,0.005906,1.003796,0.051136,0.059060,-399.972717,0.006886,0.000000
17.270000,0.256943,-400.061676,-0.004661,0.000252,0.006409,1.142938,0.058224,0.064093,-400.061676,0.007528,0.000000
17.660002,0.236832,-399.972717,-0.004639,0.000279,0.007094,1.053480,0.053667,0.070944,-399.972717,0.008178,0.000000
18.050001,0.264015,-400.061676,-0.004626,0.000308,0.007814,1.174398,0.059827,0.078143,-400.061676,0.008829,0.000000
18.440001,0.238693,-400.061676,-0.004596,0.000331,0.008404,1.061761,0.054089,0.084040,-400.061676,0.009479,0.000000
18.830002,0.236084,-400.106140,-0.004587,0.000348,0.008838,1.050154,0.053497,0.088377,-400.106140,0.010130,0.000000
19.220001,0.373123,-400.106140,-0.004544,0.000384,0.009748,1.659735,0.084551,0.097476,-400.106140,0.010780,0.000000
19.610001,0.357857,-400.106140,-0.004518,0.000409,0.010399,1.591826,0.081092,0.103986,-400.106140,0.011430,0.000000
20.000000,0.386528,-400.195129,-0.004488,0.000440,0.011179,1.719362,0.087589,0.111791,-400.195129,0.012081,0.000000
20.390001,0.397324,-400.195129,-0.004467,0.000462,0.011734,1.767384,0.090035,0.117339,-400.195129,0.012731,0.000000
20.780001,0.439774,-400.195129,-0.004432,0.000483,0.012280,1.956210,0.099654,0.122805,-400.195129,0.013382,0.000000
21.170000,0.537712,-400.150635,-0.004406,0.000505,0.012826,2.391863,0.121847,0.128263,-400.150635,0.014032,0.000000
21.560001,0.588722,-400.195129,-0.004376,0.000542,0.013772,2.618767,0.133406,0.137717,-400.195129,0.014682,0.000000
21.950001,0.614044,-400.195129,-0.004359,0.000566,0.014370,2.731405,0.139144,0.143705,-400.195129,0.015333,0.000000
22.340000,0.622612,-400.284088,-0.004333,0.000590,0.014986,2.769516,0.141086,0.149859,-400.284088,0.015984,0.000000
22.730001,0.698570,-400.239594,-0.004312,0.000618,0.015688,3.107396,0.158298,0.156884,-400.239594,0.016634,0.000000
23.120001,0.719803,-400.373047,-0.004286,0.000637,0.016183,3.201843,0.163110,0.161827,-400.373047,0.017284,0.000000
23.510000,0.806931,-400.284088,-0.004247,0.000666,0.016928,3.589406,0.182853,0.169283,-400.284088,0.017934,0.000000
23.900002,0.803955,-400.328552,-0.004238,0.000683,0.017354,3.576171,0.182179,0.173537,-400.328552,0.018585,0.000000
24.290001,0.886253,-400.417511,-0.004204,0.000715,0.018160,3.942252,0.200828,0.181599,-400.417511,0.019236,0.000000
24.680000,0.959976,-400.284088,-0.004169,0.000744,0.018889,4.270187,0.217534,0.188889,-400.284088,0.019886,0.000000
25.070002,1.038177,-400.417511,-0.004152,0.000767,0.019487,4.618044,0.235254,0.194869,-400.417511,0.020536,0.000000
25.460001,1.072067,-400.417511,-0.004118,0.000793,0.020137,4.768794,0.242934,0.201372,-400.417511,0.021186,0.000000
25.850000,1.124939,-400.417511,-0.004105,0.000820,0.020840,5.003978,0.254915,0.208396,-400.417511,0.021837,0.000000
26.240002,1.190475,-400.417511,-0.004066,0.000842,0.021394,5.295499,0.269766,0.213945,-400.417511,0.022478,0.000000
26.630001,1.316711,-400.462006,-0.004031,0.000870,0.022106,5.857025,0.298371,0.221061,-400.462006,0.023129,0.000000
27.020000,1.371078,-400.550964,-0.004031,0.000889,0.022591,6.098862,0.310691,0.225913,-400.550964,0.023780,0.000000
27.410002,1.536415,-400.506470,-0.003992,0.000925,0.023485,6.834316,0.348157,0.234845,-400.506470,0.024430,0.000000
27.800001,1.545349,-400.550964,-0.003962,0.000942,0.023918,6.874056,0.350181,0.239183,-400.550964,0.025080,0.000000
28.190001,1.655197,-400.550964,-0.003954,0.000972,0.024690,7.362685,0.375073,0.246904,-400.550964,0.025731,0.000000
28.580002,1.668602,-400.550964,-0.003911,0.000985,0.025020,7.422312,0.378111,0.250197,-400.550964,0.026381,0.000000
28.970001,1.896866,-400.595459,-0.003898,0.001023,0.025991,8.437680,0.429836,0.259909,-400.595459,0.027032,0.000000
29.360001,1.943413,-400.595459,-0.003867,0.001042,0.026468,8.644732,0.440384,0.264678,-400.595459,0.027682,0.000000
29.750002,2.181732,-400.595459,-0.003850,0.001078,0.027378,9.704829,0.494388,0.273784,-400.595459,0.028333,0.000000
30.140001,2.217857,-400.728882,-0.003811,0.001097,0.027864,9.865522,0.502574,0.278644,-400.728882,0.028983,0.000000
30.530001,2.161629,-400.684418,-0.003790,0.001107,0.028125,9.615405,0.489832,0.281248,-400.684418,0.029633,0.000000
30.920002,2.551125,-400.728882,-0.003760,0.001150,0.029217,11.347969,0.578093,0.292171,-400.728882,0.030284,0.000000
31.310001,2.541077,-400.728882,-0.003734,0.001165,0.029599,11.303273,0.575816,0.295986,-400.728882,0.030934,0.000000
31.700001,2.806572,-400.728882,-0.003717,0.001203,0.030562,12.484256,0.635978,0.305615,-400.728882,0.031585,0.000000
32.090000,2.882538,-400.773376,-0.003691,0.001224,0.031082,12.822168,0.653192,0.310816,-400.773376,0.032235,0.000000
32.480003,2.939140,-400.773376,-0.003656,0.001239,0.031463,13.073949,0.666019,0.314631,-400.773376,0.032885,0.000000
32.870003,3.336830,-400.817841,-0.003622,0.001277,0.032434,14.842961,0.756137,0.324343,-400.817841,0.033536,0.000000
33.260002,3.490250,-400.862335,-0.003596,0.001305,0.033154,15.525406,0.790902,0.331542,-400.862335,0.034187,0.000000
33.650002,3.556534,-400.862335,-0.003579,0.001328,0.033736,15.820252,0.805922,0.337355,-400.862335,0.034837,0.000000
34.040001,3.678299,-400.862335,-0.003561,0.001350,0.034290,16.361891,0.833514,0.342904,-400.862335,0.035487,0.000000
34.430000,3.886826,-400.862335,-0.003527,0.001377,0.034985,17.289463,0.880767,0.349845,-400.862335,0.036137,0.000000
34.820004,4.120308,-400.906799,-0.003505,0.001406,0.035721,18.328045,0.933675,0.357211,-400.906799,0.036788,0.000000
35.210003,4.343727,-400.906799,-0.003475,0.001438,0.036519,19.321863,0.984303,0.365189,-400.906799,0.037439,0.000000
35.600002,4.377617,-400.906799,-0.003454,0.001463,0.037153,19.472612,0.991982,0.371525,-400.906799,0.038081,0.000000
35.990002,4.531029,-400.951294,-0.003423,0.001484,0.037690,20.155022,1.026746,0.376900,-400.951294,0.038731,0.000000
36.380001,4.819244,-400.906799,-0.003385,0.001513,0.038427,21.437069,1.092056,0.384273,-400.906799,0.039381,0.000000
36.770000,5.008041,-401.040253,-0.003367,0.001542,0.039155,22.276880,1.134838,0.391555,-401.040253,0.040031,0.000000
37.160004,5.092567,-400.951294,-0.003341,0.001566,0.039788,22.652872,1.153992,0.397883,-400.951294,0.040682,0.000000
37.550003,5.299232,-400.995789,-0.003324,0.001592,0.040430,23.572163,1.200823,0.404302,-400.995789,0.041333,0.000000
37.940002,5.297005,-401.084747,-0.003307,0.001612,0.040942,23.562254,1.200318,0.409420,-401.084747,0.041983,0.000000
38.330002,5.673096,-401.084747,-0.003281,0.001641,0.041670,25.235189,1.285542,0.416702,-401.084747,0.042633,0.000000
38.720001,5.795235,-401.129211,-0.003251,0.001665,0.042295,25.778492,1.313219,0.422947,-401.129211,0.043283,0.000000
39.110001,5.841034,-401.129211,-0.003234,0.001682,0.042720,25.982216,1.323597,0.427201,-401.129211,0.043934,0.000000
39.500000,6.161652,-401.084747,-0.003208,0.001715,0.043561,27.408396,1.396250,0.435611,-401.084747,0.044585,0.000000
39.890003,6.197395,-401.173706,-0.003173,0.001736,0.044099,27.567390,1.404350,0.440986,-401.173706,0.045235,0.000000
40.280003,6.466995,-401.173706,-0.003152,0.001760,0.044715,28.766632,1.465442,0.447147,-401.173706,0.045885,0.000000
40.670002,6.677017,-401.173706,-0.003122,0.001791,0.045504,29.700855,1.513034,0.455035,-401.173706,0.046536,0.000000
41.060001,6.960014,-401.218170,-0.003091,0.001824,0.046319,30.959690,1.577162,0.463188,-401.218170,0.047186,0.000000
41.450001,7.055344,-401.218170,-0.003065,0.001848,0.046952,31.383736,1.598764,0.469516,-401.218170,0.047837,0.000000
41.840000,7.121628,-401.351624,-0.003044,0.001870,0.047507,31.678583,1.613784,0.475072,-401.351624,0.048487,0.000000
42.230003,6.938789,-401.262665,-0.003009,0.001887,0.047940,30.865276,1.572352,0.479402,-401.262665,0.049137,0.000000
42.620003,7.488411,-401.262665,-0.002988,0.001917,0.048687,33.310116,1.696898,0.486866,-401.262665,0.049788,0.000000
43.010002,7.855576,-401.307129,-0.002962,0.001950,0.049519,34.943344,1.780099,0.495193,-401.307129,0.050438,0.000000
43.400002,7.900627,-401.262665,-0.002940,0.001974,0.050143,35.143745,1.790308,0.501430,-401.262665,0.051089,0.000000
43.790001,8.016808,-401.351624,-0.002915,0.001999,0.050785,35.660542,1.816635,0.507850,-401.351624,0.051739,0.000000
44.180000,8.091286,-401.307129,-0.002893,0.002020,0.051297,35.991837,1.833511,0.512967,-401.307129,0.052390,0.000000
44.570004,8.353806,-401.440582,-0.002863,0.002045,0.051939,37.159584,1.892999,0.519386,-401.440582,0.053031,0.000000
44.960003,8.493820,-401.351624,-0.002815,0.002070,0.052581,37.782398,1.924727,0.525805,-401.351624,0.053682,0.000000
45.350002,8.703835,-401.396088,-0.002828,0.002094,0.053179,38.716591,1.972317,0.531785,-401.396088,0.054332,0.000000
45.740002,9.185684,-401.396088,-0.002777,0.002127,0.054020,40.859962,2.081506,0.540195,-401.396088,0.054982,0.000000
46.130001,8.896729,-401.396088,-0.002755,0.002146,0.054514,39.574623,2.016027,0.545138,-401.396088,0.055633,0.000000
46.520000,9.533112,-401.529541,-0.002721,0.002181,0.055399,42.405399,2.160234,0.553988,-401.529541,0.056284,0.000000
46.910004,9.441505,-401.485077,-0.002703,0.002203,0.055945,41.997913,2.139476,0.559453,-401.485077,0.056934,0.000000
47.300003,9.623596,-401.529541,-0.002690,0.002228,0.056596,42.807896,2.180738,0.565955,-401.529541,0.057584,0.000000
47.690002,9.465714,-401.574036,-0.002647,0.002242,0.056942,42.105598,2.144961,0.569422,-401.574036,0.058234,0.000000
48.080002,10.154976,-401.485077,-0.002630,0.002279,0.057888,45.171589,2.301151,0.578877,-401.485077,0.058885,0.000000
48.470001,10.302803,-401.574036,-0.002604,0.002303,0.058495,45.829155,2.334649,0.584948,-401.574036,0.059536,0.000000
48.860001,10.585060,-401.618500,-0.002557,0.002334,0.059284,47.084698,2.398609,0.592836,-401.618500,0.060186,0.000000
49.250004,10.132256,-401.574036,-0.002544,0.002346,0.059579,45.070522,2.296002,0.595788,-401.574036,0.060836,0.000000
49.640003,10.764175,-401.618500,-0.002522,0.002378,0.060394,47.881443,2.439197,0.603941,-401.618500,0.061486,0.000000
50.030003,11.025208,-401.618500,-0.002505,0.002406,0.061105,49.042572,2.498348,0.611049,-401.618500,0.062137,0.000000
50.420002,10.979774,-401.751953,-0.002488,0.002423,0.061548,48.840477,2.488052,0.615477,-401.751953,0.062788,0.000000
50.810001,11.638504,-401.662994,-0.002449,0.002458,0.062432,51.770653,2.637323,0.624318,-401.662994,0.063438,0.000000
51.200001,11.586746,-401.707458,-0.002427,0.002481,0.063013,51.540421,2.625594,0.630132,-401.707458,0.064088,0.000000
51.590004,11.475037,-401.707458,-0.002397,0.002499,0.063464,51.043510,2.600281,0.634636,-401.707458,0.064739,0.000000
51.980003,12.277870,-401.751953,-0.002371,0.002535,0.064383,54.614693,2.782205,0.643833,-401.751953,0.065389,0.000000
52.370003,12.103973,-401.796417,-0.002337,0.002554,0.064869,53.841164,2.742800,0.648686,-401.796417,0.066040,0.000000
52.760002,12.691948,-401.796417,-0.002320,0.002587,0.065701,56.456604,2.876036,0.657012,-401.796417,0.066690,0.000000
53.150002,12.684868,-401.840912,-0.002294,0.002609,0.066256,56.425110,2.874432,0.662561,-401.840912,0.067340,0.000000
53.540001,12.637955,-401.840912,-0.002259,0.002628,0.066742,56.216431,2.863801,0.667421,-401.840912,0.067982,0.000000
53.930004,12.818924,-401.840912,-0.002259,0.002648,0.067254,57.021423,2.904810,0.672538,-401.840912,0.068632,0.000000
54.320004,13.327217,-401.840912,-0.002220,0.002681,0.068104,59.282421,3.019990,0.681039,-401.840912,0.069283,0.000000
54.710003,13.754326,-401.885406,-0.002190,0.002713,0.068910,61.182297,3.116775,0.689101,-401.885406,0.069934,0.000000
55.100002,13.912209,-401.885406,-0.002156,0.002737,0.069525,61.884594,3.152552,0.695255,-401.885406,0.070584,0.000000
55.490002,13.997482,-401.974365,-0.002134,0.002760,0.070099,62.263912,3.171875,0.700985,-401.974365,0.071234,0.000000
55.880001,13.876839,-401.974365,-0.002108,0.002775,0.070497,61.727261,3.144536,0.704975,-401.974365,0.071885,0.000000
56.270004,14.762337,-402.018829,-0.002091,0.002816,0.071529,65.666153,3.345193,0.715292,-402.018829,0.072535,0.000000
56.660004,15.088165,-401.974365,-0.002044,0.002844,0.072249,67.115509,3.419027,0.722491,-401.974365,0.073185,0.000000
57.050003,15.168968,-401.974365,-0.002022,0.002869,0.072865,67.474937,3.437337,0.728645,-401.974365,0.073836,0.000000
57.440002,15.716728,-402.063324,-0.002005,0.002899,0.073628,69.911499,3.561462,0.736276,-402.063324,0.074487,0.000000
57.830002,15.641510,-402.063324,-0.001979,0.002920,0.074157,69.576912,3.544417,0.741567,-402.063324,0.075137,0.000000
58.220001,16.031380,-402.063324,-0.001949,0.002946,0.074833,71.311142,3.632763,0.748334,-402.063324,0.075787,0.000000
58.610004,16.492004,-402.107788,-0.001927,0.002974,0.075536,73.360100,3.737142,0.755359,-402.107788,0.076437,0.000000
59.000004,16.634628,-402.063324,-0.001897,0.002996,0.076091,73.994522,3.769461,0.760908,-402.063324,0.077088,0.000000
59.390003,17.217758,-402.063324,-0.001854,0.003025,0.076828,76.588417,3.901600,0.768281,-402.063324,0.077739,0.000000
59.780003,17.175308,-402.107788,-0.001850,0.003042,0.077278,76.399590,3.891981,0.772785,-402.107788,0.078389,0.000000
60.170002,17.543213,-402.196747,-0.001819,0.003066,0.077886,78.036110,3.975349,0.778856,-402.196747,0.079039,0.000000
60.560001,17.931602,-402.196747,-0.001798,0.003090,0.078475,79.763748,4.063359,0.784753,-402.196747,0.079689,0.000000
60.950005,18.569099,-402.241241,-0.001776,0.003121,0.079282,82.599480,4.207819,0.792822,-402.241241,0.080340,0.000000
61.340004,18.574684,-402.196747,-0.001738,0.003139,0.079742,82.624321,4.209084,0.797417,-402.196747,0.080991,0.000000
61.730003,19.513809,-402.196747,-0.001720,0.003172,0.080574,86.801758,4.421892,0.805744,-402.196747,0.081641,0.000000
62.120003,20.376595,-402.285736,-0.001690,0.003204,0.081381,90.639618,4.617402,0.813805,-402.285736,0.082291,0.000000
62.510002,20.244774,-402.285736,-0.001664,0.003225,0.081927,90.053253,4.587532,0.819271,-402.285736,0.082933,0.000000
62.900002,20.692368,-402.285736,-0.001647,0.003254,0.082647,92.044250,4.688957,0.826470,-402.285736,0.083583,0.000000
63.290005,20.972763,-402.285736,-0.001600,0.003278,0.083254,93.291512,4.752496,0.832541,-402.285736,0.084234,0.000000
63.680004,21.200661,-402.285736,-0.001591,0.003297,0.083739,94.305252,4.804138,0.837393,-402.285736,0.084885,0.000000
64.070000,22.342720,-402.374695,-0.001561,0.003330,0.084589,99.385384,5.062932,0.845894,-402.374695,0.085535,0.000000
64.460007,22.532631,-402.285736,-0.001548,0.003352,0.085153,100.230148,5.105967,0.851533,-402.285736,0.086185,0.000000
64.850006,23.101616,-402.419159,-0.001509,0.003381,0.085873,102.761116,5.234901,0.858732,-402.419159,0.086835,0.000000
65.240005,23.361160,-402.374695,-0.001492,0.003406,0.086515,103.915634,5.293715,0.865151,-402.374695,0.087486,0.000000
65.630005,23.269562,-402.374695,-0.001462,0.003420,0.086870,103.508179,5.272958,0.868702,-402.374695,0.088137,0.000000
66.020004,24.504349,-402.508118,-0.001436,0.003459,0.087850,109.000786,5.552764,0.878504,-402.508118,0.088787,0.000000
66.410004,24.363213,-402.419159,-0.001410,0.003473,0.088215,108.372986,5.520783,0.882145,-402.419159,0.089437,0.000000
66.800003,25.113922,-402.552612,-0.001397,0.003499,0.088874,111.712303,5.690896,0.888739,-402.552612,0.090088,0.000000
67.190002,26.661125,-402.508118,-0.001367,0.003534,0.089758,118.594604,6.041497,0.897580,-402.508118,0.090738,0.000000
67.580002,26.497658,-402.552612,-0.001345,0.003553,0.090235,117.867470,6.004455,0.902349,-402.552612,0.091389,0.000000
67.970001,27.976349,-402.508118,-0.001311,0.003586,0.091094,124.445015,6.339531,0.910941,-402.508118,0.092039,0.000000
68.360001,28.120079,-402.597076,-0.001298,0.003608,0.091640,125.084358,6.372101,0.916399,-402.597076,0.092690,0.000000
68.750000,28.654808,-402.641571,-0.001281,0.003632,0.092247,127.462952,6.493272,0.922470,-402.641571,0.093340,0.000000
69.140007,29.705643,-402.641571,-0.001250,0.003661,0.092984,132.137299,6.731395,0.929843,-402.641571,0.093990,0.000000
69.530006,29.986412,-402.686035,-0.001233,0.003681,0.093496,133.386215,6.795018,0.934960,-402.686035,0.094641,0.000000
69.920006,30.526352,-402.686035,-0.001207,0.003703,0.094051,135.787994,6.917370,0.940509,-402.686035,0.095291,0.000000
70.310005,31.742149,-402.686035,-0.001186,0.003736,0.094901,141.196136,7.192874,0.949009,-402.686035,0.095942,0.000000
70.700005,32.135002,-402.730530,-0.001168,0.003757,0.095430,142.943634,7.281895,0.954301,-402.730530,0.096592,0.000000
71.090004,32.971352,-402.730530,-0.001130,0.003782,0.096063,146.663895,7.471415,0.960629,-402.730530,0.097242,0.000000
71.480003,33.977127,-402.730530,-0.001121,0.003810,0.096774,151.137802,7.699327,0.967737,-402.730530,0.097884,0.000000
71.870003,34.394188,-402.775024,-0.001091,0.003835,0.097398,152.992996,7.793834,0.973982,-402.775024,0.098534,0.000000
72.260002,35.630463,-402.775024,-0.001069,0.003860,0.098049,158.492218,8.073978,0.980492,-402.775024,0.099185,0.000000
72.650002,36.603844,-402.730530,-0.001061,0.003888,0.098743,162.822021,8.294550,0.987426,-402.730530,0.099836,0.000000
73.040001,36.346161,-402.863983,-0.001026,0.003899,0.099029,161.675797,8.236158,0.990287,-402.863983,0.100486,0.000000
73.430000,38.580025,-402.819489,-0.001018,0.003937,0.100000,171.612518,8.742358,1.000000,-402.819489,0.101136,0.000000
73.820000,39.046608,-402.863983,-0.000987,0.003961,0.100607,173.687988,8.848087,1.006070,-402.863983,0.101786,0.000000
74.210007,40.324593,-402.863983,-0.000966,0.003986,0.101249,179.372742,9.137684,1.012490,-402.863983,0.102437,0.000000
74.600006,41.297600,-402.908447,-0.000953,0.004012,0.101917,183.700897,9.358171,1.019166,-402.908447,0.103088,0.000000
74.990005,41.332603,-402.952942,-0.000918,0.004026,0.102255,183.856598,9.366102,1.022550,-402.952942,0.103738,0.000000
75.380005,43.413422,-402.952942,-0.000914,0.004061,0.103139,193.112549,9.837622,1.031392,-402.952942,0.104388,0.000000
75.770004,44.589371,-402.952942,-0.000884,0.004090,0.103876,198.343430,10.104096,1.038764,-402.952942,0.105038,0.000000
76.160004,46.405807,-402.997406,-0.000871,0.004120,0.104639,206.423340,10.515707,1.046395,-402.997406,0.105689,0.000000
76.550003,47.014633,-403.041901,-0.000858,0.004140,0.105160,209.131531,10.653668,1.051603,-403.041901,0.106340,0.000000
76.940002,48.098236,-402.952942,-0.000823,0.004166,0.105828,213.951645,10.899216,1.058279,-402.952942,0.106990,0.000000
77.330002,49.775406,-403.041901,-0.000802,0.004192,0.106478,221.412064,11.279268,1.064782,-403.041901,0.107640,0.000000
77.720001,51.774673,-403.086365,-0.000798,0.004228,0.107389,230.305252,11.732308,1.073888,-403.086365,0.108291,0.000000
78.110001,53.078720,-403.041901,-0.000776,0.004252,0.107996,236.105942,12.027810,1.079959,-403.041901,0.108941,0.000000
78.500000,53.703934,-403.130859,-0.000767,0.004272,0.108499,238.887024,12.169486,1.084993,-403.130859,0.109592,0.000000
78.890007,55.667824,-403.086365,-0.000720,0.004302,0.109262,247.622849,12.614510,1.092623,-403.086365,0.110242,0.000000
79.280006,56.934639,-403.130859,-0.000720,0.004330,0.109973,253.257919,12.901573,1.099732,-403.130859,0.110892,0.000000
79.670006,58.181709,-403.175354,-0.000711,0.004352,0.110545,258.805176,13.184163,1.105454,-403.175354,0.111543,0.000000
80.060005,60.169807,-403.130859,-0.000690,0.004381,0.111274,267.648682,13.634673,1.112744,-403.130859,0.112193,0.000000
80.450005,61.438484,-403.175354,-0.000677,0.004404,0.111864,273.292023,13.922159,1.118641,-403.175354,0.112835,0.000000
80.840004,63.003563,-403.264313,-0.000651,0.004428,0.112471,280.253845,14.276812,1.124712,-403.264313,0.113486,0.000000
81.230003,63.869705,-403.264313,-0.000655,0.004448,0.112982,284.106628,14.473082,1.129821,-403.264313,0.114136,0.000000
81.620003,65.723373,-403.264313,-0.000625,0.004476,0.113685,292.352173,14.893129,1.136846,-403.264313,0.114786,0.000000
82.010002,65.934128,-403.219818,-0.000617,0.004476,0.113702,293.289642,14.940887,1.137020,-403.219818,0.019949,0.000000
82.400002,65.032242,-403.308777,-0.000617,0.004476,0.113702,289.277863,14.736517,1.137020,-403.308777,294.500519,0.000000
82.790001,67.168549,-403.353271,-0.000591,0.004504,0.114414,298.780640,15.220611,1.144136,-403.353271,294.500519,0.000000
83.180000,66.196655,-403.308777,-0.000582,0.004385,0.111387,294.457428,15.000376,1.113872,-403.308777,294.500519,0.000000
83.570007,65.589691,-403.353271,-0.000578,0.004448,0.112974,291.757507,14.862837,1.129738,-403.353271,294.500519,0.000000
83.960007,65.148804,-403.442230,-0.000582,0.004479,0.113772,289.796356,14.762930,1.137717,-403.442230,294.500519,0.000000
84.350006,65.129807,-403.442230,-0.000578,0.004500,0.114292,289.711853,14.758625,1.142917,-403.442230,294.500519,0.000000
84.740005,65.053848,-403.442230,-0.000569,0.004506,0.114457,289.373962,14.741412,1.144567,-403.442230,294.500519,0.000000
85.130005,65.321960,-403.486694,-0.000565,0.004508,0.114509,290.566589,14.802168,1.145090,-403.486694,294.500519,0.000000
85.520004,65.174866,-403.442230,-0.000569,0.004510,0.114552,289.912292,14.768836,1.145521,-403.442230,294.500519,0.000000
85.910004,65.086243,-403.442230,-0.000578,0.004512,0.114604,289.518066,14.748754,1.146044,-403.442230,294.500519,0.000000
86.300003,65.346909,-403.531189,-0.000552,0.004518,0.114760,290.677582,14.807821,1.147603,-403.531189,294.500519,0.000000
86.690002,65.227371,-403.531189,-0.000556,0.004518,0.114760,290.145844,14.780734,1.147603,-403.531189,294.500519,0.000000
87.080002,65.130188,-403.531189,-0.000565,0.004521,0.114821,289.713531,14.758712,1.148208,-403.531189,294.500519,0.000000
87.470001,65.031876,-403.575684,-0.000565,0.004525,0.114943,289.276245,14.736434,1.149427,-403.575684,294.500519,0.000000
87.860001,65.486542,-403.575684,-0.000552,0.004527,0.114994,291.298676,14.839462,1.149942,-403.575684,294.500519,0.000000
88.250008,65.314880,-403.664642,-0.000560,0.004527,0.114994,290.535095,14.800563,1.149942,-403.664642,294.500519,0.000000
88.640007,65.196091,-403.575684,-0.000543,0.004528,0.115003,290.006683,14.773645,1.150033,-403.575684,294.500519,0.000000
89.030006,65.029266,-403.664642,-0.000569,0.004528,0.115003,289.264618,14.735842,1.150033,-403.664642,294.500519,0.000000
89.420006,64.922394,-403.709106,-0.000548,0.004528,0.115021,288.789246,14.711624,1.150207,-403.709106,294.500519,0.000000
89.810005,65.204651,-403.620148,-0.000539,0.004533,0.115151,290.044769,14.775585,1.151509,-403.620148,294.500519,0.000000
90.200005,65.109695,-403.709106,-0.000552,0.004533,0.115151,289.622375,14.754068,1.151509,-403.709106,294.500519,0.000000
90.590004,65.016602,-403.753601,-0.000539,0.004533,0.115151,289.208282,14.732972,1.151509,-403.753601,294.500519,0.000000
90.980003,65.057190,-403.798065,-0.000543,0.004537,0.115229,289.388824,14.742170,1.152289,-403.798065,294.500519,0.000000
91.370003,65.024048,-403.798065,-0.000535,0.004537,0.115229,289.241425,14.734660,1.152289,-403.798065,294.500519,0.000000
91.760002,64.944733,-403.798065,-0.000552,0.004537,0.115229,288.888611,14.716687,1.152289,-403.798065,294.500519,0.000000
92.150002,64.931702,-403.842560,-0.000535,0.004538,0.115272,288.830627,14.713734,1.152720,-403.842560,294.500519,0.000000
92.540001,64.856491,-403.798065,-0.000535,0.004538,0.115272,288.496094,14.696691,1.152720,-403.798065,294.500519,0.000000
92.930008,64.799881,-403.842560,-0.000535,0.004539,0.115280,288.244263,14.683863,1.152803,-403.842560,294.500519,0.000000
93.320007,65.547241,-403.931519,-0.000535,0.004547,0.115506,291.568695,14.853217,1.155059,-403.931519,294.500519,0.000000
93.710007,65.543518,-403.842560,-0.000539,0.004547,0.115506,291.552124,14.852373,1.155059,-403.842560,294.500519,0.000000
94.100006,65.506271,-403.931519,-0.000539,0.004547,0.115506,291.386444,14.843933,1.155059,-403.931519,294.500519,0.000000
94.490005,65.410950,-403.931519,-0.000526,0.004547,0.115506,290.962433,14.822333,1.155059,-403.931519,294.500519,0.000000
94.880005,65.371857,-403.931519,-0.000526,0.004548,0.115515,290.788544,14.813475,1.155150,-403.931519,294.500519,0.000000
95.270004,65.287323,-404.020477,-0.000517,0.004548,0.115515,290.412506,14.794319,1.155150,-404.020477,294.500519,0.000000
95.660004,65.237427,-404.020477,-0.000539,0.004548,0.115515,290.190582,14.783012,1.155150,-404.020477,294.500519,0.000000
96.050003,65.152145,-404.020477,-0.000517,0.004548,0.115515,289.811218,14.763687,1.155150,-404.020477,294.500519,0.000000
96.440002,65.072464,-404.020477,-0.000522,0.004548,0.115515,289.456787,14.745631,1.155150,-404.020477,294.500519,0.000000
96.830002,65.023682,-404.109436,-0.000530,0.004548,0.115523,289.239777,14.734576,1.155233,-404.109436,294.500519,0.000000
97.220001,65.566971,-404.109436,-0.000522,0.004556,0.115723,291.656464,14.857688,1.157232,-404.109436,294.500519,0.000000
97.610008,65.567719,-404.064972,-0.000517,0.004556,0.115723,291.659790,14.857858,1.157232,-404.064972,294.500519,0.000000
98.000008,65.560638,-404.153931,-0.000513,0.004556,0.115723,291.628296,14.856253,1.157232,-404.153931,294.500519,0.000000
98.390007,65.523407,-404.153931,-0.000513,0.004556,0.115723,291.462677,14.847816,1.157232,-404.153931,294.500519,0.000000
98.780006,65.460846,-404.109436,-0.000526,0.004556,0.115723,291.184387,14.833639,1.157232,-404.109436,294.500519,0.000000
99.170006,65.374832,-404.242889,-0.000509,0.004556,0.115723,290.801788,14.814149,1.157232,-404.242889,294.500519,0.000000
99.560005,65.313019,-404.198395,-0.000517,0.004556,0.115723,290.526825,14.800141,1.157232,-404.198395,294.500519,0.000000
99.950005,65.274292,-404.242889,-0.000522,0.004556,0.115723,290.354553,14.791366,1.157232,-404.242889,294.500519,0.000000
100.340004,65.235565,-404.153931,-0.000522,0.004556,0.115723,290.182281,14.782591,1.157232,-404.153931,294.500519,0.000000
100.730003,65.168915,-404.331848,-0.000522,0.004556,0.115723,289.885803,14.767488,1.157232,-404.331848,294.500519,0.000000
101.120003,65.121994,-404.287354,-0.000526,0.004556,0.115723,289.677094,14.756855,1.157232,-404.287354,294.500519,0.000000
101.510002,65.066879,-404.287354,-0.000513,0.004556,0.115723,289.431946,14.744366,1.157232,-404.287354,294.500519,0.000000
101.900002,65.029266,-404.376312,-0.000522,0.004556,0.115723,289.264618,14.735842,1.157232,-404.376312,294.500519,0.000000
102.290009,64.979004,-404.287354,-0.000500,0.004556,0.115723,289.041046,14.724453,1.157232,-404.287354,294.500519,0.000000
102.680008,64.935425,-404.420807,-0.000517,0.004556,0.115723,288.847198,14.714578,1.157232,-404.420807,294.500519,0.000000
103.070007,64.874741,-404.420807,-0.000509,0.004556,0.115723,288.577271,14.700827,1.157232,-404.420807,294.500519,0.000000
103.460007,64.808075,-404.376312,-0.000522,0.004556,0.115723,288.280701,14.685719,1.157232,-404.376312,294.500519,0.000000
103.850006,64.760040,-404.465302,-0.000513,0.004556,0.115723,288.067047,14.674835,1.157232,-404.465302,294.500519,0.000000
104.240005,64.717590,-404.420807,-0.000522,0.004556,0.115723,287.878204,14.665215,1.157232,-404.420807,294.500519,0.000000
104.630005,64.678497,-404.465302,-0.000522,0.004556,0.115723,287.704315,14.656357,1.157232,-404.465302,294.500519,0.000000
105.020004,64.619659,-404.465302,-0.000509,0.004556,0.115723,287.442596,14.643024,1.157232,-404.465302,294.500519,0.000000
105.410004,64.549652,-404.465302,-0.000522,0.004556,0.115723,287.131195,14.627160,1.157232,-404.465302,294.500519,0.000000
105.800003,64.527313,-404.554260,-0.000504,0.004556,0.115723,287.031830,14.622098,1.157232,-404.554260,294.500519,0.000000
106.190002,64.482620,-404.509766,-0.000509,0.004556,0.115723,286.833008,14.611971,1.157232,-404.509766,294.500519,0.000000
106.580002,64.436447,-404.554260,-0.000509,0.004556,0.115723,286.627625,14.601508,1.157232,-404.554260,294.500519,0.000000
106.970009,66.592865,-404.554260,-0.000492,0.004393,0.111578,296.219849,15.090158,1.115780,-404.554260,294.500519,0.000000
107.360008,66.466629,-404.598724,-0.000492,0.004393,0.111578,295.658325,15.061554,1.115780,-404.598724,294.500519,0.000000
107.750008,66.456573,-404.643219,-0.000487,0.004393,0.111578,295.613617,15.059275,1.115780,-404.643219,294.500519,0.000000
108.140007,66.404816,-404.598724,-0.000483,0.004393,0.111586,295.383362,15.047546,1.115863,-404.598724,294.500519,0.000000
108.530006,66.349701,-404.687683,-0.000483,0.004393,0.111586,295.138214,15.035058,1.115863,-404.687683,294.500519,0.000000
108.920006,66.313202,-404.643219,-0.000470,0.004393,0.111586,294.975861,15.026786,1.115863,-404.643219,294.500519,0.000000
109.310005,66.255112,-404.687683,-0.000487,0.004393,0.111586,294.717468,15.013622,1.115863,-404.687683,294.500519,0.000000
109.700005,66.208939,-404.732178,-0.000487,0.004393,0.111586,294.512054,15.003160,1.115863,-404.732178,294.500519,0.000000
110.090004,66.154572,-404.687683,-0.000483,0.004393,0.111586,294.270233,14.990840,1.115863,-404.687683,294.500519,0.000000
110.480003,66.126282,-404.776642,-0.000487,0.004393,0.111586,294.144379,14.984430,1.115863,-404.776642,294.500519,0.000000
110.870003,66.080841,-404.687683,-0.000479,0.004393,0.111586,293.942261,14.974133,1.115863,-404.687683,294.500519,0.000000
111.260002,66.027969,-404.732178,-0.000492,0.004393,0.111586,293.707062,14.962152,1.115863,-404.732178,294.500519,0.000000
111.650002,65.998932,-404.776642,-0.000483,0.004393,0.111595,293.577911,14.955571,1.115946,-404.776642,294.500519,0.000000
112.040009,65.851089,-404.776642,-0.000479,0.004405,0.111890,292.920288,14.922071,1.118898,-404.776642,294.500519,0.000000
112.430008,65.896530,-404.910095,-0.000483,0.004412,0.112063,293.122406,14.932367,1.120632,-404.910095,294.500519,0.000000
112.820007,65.868591,-404.821136,-0.000487,0.004415,0.112150,292.998138,14.926036,1.121502,-404.821136,294.500519,0.000000
113.210007,65.795609,-404.910095,-0.000496,0.004418,0.112219,292.673492,14.909497,1.122191,-404.910095,294.500519,0.000000
113.600006,65.781464,-404.910095,-0.000492,0.004429,0.112488,292.610565,14.906293,1.124878,-404.910095,294.500519,0.000000
113.990005,65.759491,-404.910095,-0.000483,0.004429,0.112497,292.512817,14.901314,1.124969,-404.910095,294.500519,0.000000
114.380005,65.697311,-404.910095,-0.000479,0.004429,0.112505,292.236237,14.887223,1.125052,-404.910095,294.500519,0.000000
114.770004,65.670486,-404.910095,-0.000479,0.004451,0.113052,292.116913,14.881145,1.130518,-404.910095,294.500519,0.000000
115.160004,65.605331,-404.999054,-0.000496,0.004451,0.113052,291.827087,14.866381,1.130518,-404.999054,294.500519,0.000000
115.550003,65.566605,-404.910095,-0.000474,0.004473,0.113607,291.654816,14.857605,1.136067,-404.910095,294.500519,0.000000
115.940002,65.555054,-404.999054,-0.000487,0.004488,0.113997,291.603455,14.854987,1.139973,-404.999054,294.500519,0.000000
116.330002,65.530106,-405.088013,-0.000483,0.004488,0.114006,291.492462,14.849334,1.140056,-405.088013,294.500519,0.000000
116.720009,65.491013,-404.999054,-0.000483,0.004488,0.114006,291.318573,14.840475,1.140056,-404.999054,294.500519,0.000000
117.110008,65.424362,-405.043549,-0.000492,0.004488,0.114006,291.022095,14.825373,1.140056,-405.043549,294.500519,0.000000
117.500008,65.393448,-405.088013,-0.000479,0.004509,0.114535,290.884583,14.818367,1.145347,-405.088013,294.500519,0.000000
117.890007,65.338333,-405.088013,-0.000487,0.004536,0.115220,290.639435,14.805878,1.152198,-405.088013,294.500519,0.000000
118.280006,65.309662,-405.176971,-0.000474,0.004536,0.115220,290.511871,14.799381,1.152198,-405.176971,294.500519,0.000000
118.670006,65.291046,-405.088013,-0.000492,0.004536,0.115220,290.429077,14.795162,1.152198,-405.088013,294.500519,0.000000
119.060005,65.265350,-405.176971,-0.000483,0.004536,0.115220,290.314789,14.789339,1.152198,-405.176971,294.500519,0.000000
119.450005,65.239288,-405.176971,-0.000483,0.004538,0.115264,290.198853,14.783434,1.152637,-405.176971,294.500519,0.000000
119.840004,65.209122,-405.176971,-0.000470,0.004538,0.115264,290.064667,14.776598,1.152637,-405.176971,294.500519,0.000000
120.230003,65.176727,-405.221466,-0.000487,0.004539,0.115280,289.920563,14.769257,1.152803,-405.221466,294.500519,0.000000
120.620003,65.122726,-405.221466,-0.000483,0.004539,0.115280,289.680359,14.757020,1.152803,-405.221466,294.500519,0.000000
121.010002,65.097412,-405.265930,-0.000483,0.004539,0.115280,289.567749,14.751285,1.152803,-405.265930,294.500519,0.000000
121.400009,65.140610,-405.265930,-0.000487,0.004547,0.115488,289.759918,14.761073,1.154885,-405.265930,294.500519,0.000000
121.790009,65.206146,-405.354919,-0.000487,0.004557,0.115758,290.051422,14.775925,1.157580,-405.354919,294.500519,0.000000
122.180008,65.188644,-405.354919,-0.000483,0.004557,0.115758,289.973572,14.771957,1.157580,-405.354919,294.500519,0.000000
122.570007,65.131668,-405.354919,-0.000474,0.004557,0.115758,289.720123,14.759047,1.157580,-405.354919,294.500519,0.000000
122.960007,65.115280,-405.399384,-0.000487,0.004557,0.115758,289.647247,14.755334,1.157580,-405.399384,294.500519,0.000000
123.350006,65.159225,-405.399384,-0.000474,0.004564,0.115914,289.842712,14.765291,1.159139,-405.399384,294.500519,0.000000
123.740005,65.129807,-405.399384,-0.000470,0.004564,0.115914,289.711853,14.758625,1.159139,-405.399384,294.500519,0.000000
124.130005,65.094055,-405.399384,-0.000474,0.004564,0.115914,289.552826,14.750524,1.159139,-405.399384,294.500519,0.000000
124.520004,65.091080,-405.399384,-0.000470,0.004564,0.115931,289.539581,14.749849,1.159313,-405.399384,294.500519,0.000000
124.910004,65.060547,-405.488342,-0.000483,0.004565,0.115940,289.403778,14.742930,1.159397,-405.488342,294.500519,0.000000
125.300003,65.268326,-405.488342,-0.000479,0.004571,0.116105,290.328003,14.790014,1.161047,-405.488342,294.500519,0.000000
125.690002,65.270569,-405.532837,-0.000492,0.004571,0.116105,290.337982,14.790523,1.161047,-405.532837,294.500519,0.000000
126.080009,65.246735,-405.488342,-0.000492,0.004571,0.116105,290.231964,14.785122,1.161047,-405.488342,294.500519,0.000000
126.470009,65.238907,-405.488342,-0.000479,0.004571,0.116105,290.197144,14.783348,1.161047,-405.488342,294.500519,0.000000
126.860008,65.231094,-405.577301,-0.000483,0.004571,0.116105,290.162415,14.781577,1.161047,-405.577301,294.500519,0.000000
127.250008,65.234070,-405.532837,-0.000470,0.004572,0.116130,290.175629,14.782252,1.161304,-405.532837,294.500519,0.000000
127.640007,65.229599,-405.621796,-0.000487,0.004572,0.116130,290.155762,14.781239,1.161304,-405.621796,294.500519,0.000000
128.029999,65.215820,-405.577301,-0.000474,0.004572,0.116130,290.094452,14.778116,1.161304,-405.577301,294.500519,0.000000
128.420013,65.210983,-405.577301,-0.000492,0.004572,0.116130,290.072937,14.777020,1.161304,-405.577301,294.500519,0.000000
128.810013,65.187897,-405.710754,-0.000474,0.004572,0.116140,289.970245,14.771788,1.161395,-405.710754,294.500519,0.000000
129.200012,65.174118,-405.710754,-0.000492,0.004572,0.116140,289.908966,14.768666,1.161395,-405.710754,294.500519,0.000000
129.590012,65.157730,-405.710754,-0.000487,0.004573,0.116148,289.836060,14.764953,1.161478,-405.710754,294.500519,0.000000
129.980011,65.172638,-405.666260,-0.000470,0.004573,0.116165,289.902374,14.768331,1.161652,-405.666260,294.500519,0.000000
130.370010,65.223267,-405.666260,-0.000483,0.004575,0.116208,290.127594,14.779803,1.162084,-405.666260,294.500519,0.000000
130.760010,65.275040,-405.755249,-0.000483,0.004575,0.116208,290.357880,14.791535,1.162084,-405.755249,294.500519,0.000000
131.150009,65.287689,-405.755249,-0.000483,0.004575,0.116208,290.414154,14.794401,1.162084,-405.755249,294.500519,0.000000
131.540009,65.285828,-405.799713,-0.000474,0.004575,0.116208,290.405853,14.793981,1.162084,-405.799713,294.500519,0.000000
131.930008,65.283234,-405.888672,-0.000483,0.004575,0.116208,290.394318,14.793392,1.162084,-405.888672,294.500519,0.000000
132.320007,65.277634,-405.755249,-0.000487,0.004575,0.116208,290.369415,14.792123,1.162084,-405.755249,294.500519,0.000000
132.710007,65.266846,-405.888672,-0.000479,0.004575,0.116208,290.321442,14.789679,1.162084,-405.888672,294.500519,0.000000
133.100006,65.265732,-405.888672,-0.000474,0.004576,0.116226,290.316467,14.789427,1.162258,-405.888672,294.500519,0.000000
133.490005,65.254547,-405.933167,-0.000492,0.004576,0.116226,290.266724,14.786892,1.162258,-405.933167,294.500519,0.000000
133.880005,65.250824,-405.933167,-0.000483,0.004576,0.116226,290.250153,14.786048,1.162258,-405.933167,294.500519,0.000000
134.270004,65.245621,-405.977631,-0.000487,0.004576,0.116226,290.227020,14.784869,1.162258,-405.977631,294.500519,0.000000
134.660004,65.233704,-405.977631,-0.000470,0.004576,0.116235,290.174011,14.782168,1.162349,-405.977631,294.500519,0.000000
135.050003,65.234451,-405.888672,-0.000483,0.004576,0.116235,290.177338,14.782338,1.162349,-405.888672,294.500519,0.000000
135.440002,65.216949,-406.022125,-0.000474,0.004576,0.116235,290.099487,14.778372,1.162349,-406.022125,294.500519,0.000000
135.830002,65.198700,-405.933167,-0.000483,0.004576,0.116235,290.018311,14.774237,1.162349,-405.933167,294.500519,0.000000
136.220001,65.188644,-405.977631,-0.000474,0.004576,0.116235,289.973572,14.771957,1.162349,-405.977631,294.500519,0.000000
136.610001,65.170395,-406.066589,-0.000496,0.004576,0.116235,289.892395,14.767822,1.162349,-406.066589,294.500519,0.000000
137.000000,65.156998,-406.066589,-0.000479,0.004576,0.116235,289.832794,14.764787,1.162349,-406.066589,294.500519,0.000000
137.389999,65.131668,-406.155579,-0.000474,0.004577,0.116261,289.720123,14.759047,1.162606,-406.155579,294.500519,0.000000
137.780014,65.288437,-406.111084,-0.000474,0.004580,0.116321,290.417480,14.794571,1.163212,-406.111084,294.500519,0.000000
138.170013,65.294769,-406.200043,-0.000487,0.004580,0.116321,290.445648,14.796006,1.163212,-406.200043,294.500519,0.000000
138.560013,65.308182,-406.200043,-0.000483,0.004580,0.116321,290.505310,14.799046,1.163212,-406.200043,294.500519,0.000000
138.950012,65.312637,-406.066589,-0.000479,0.004580,0.116321,290.525116,14.800055,1.163212,-406.066589,294.500519,0.000000
139.340012,65.312271,-406.200043,-0.000483,0.004580,0.116321,290.523499,14.799972,1.163212,-406.200043,294.500519,0.000000
139.730011,65.313766,-406.155579,-0.000479,0.004580,0.116321,290.530151,14.800311,1.163212,-406.155579,294.500519,0.000000
140.120010,65.280243,-406.200043,-0.000474,0.004580,0.116321,290.381012,14.792715,1.163212,-406.200043,294.500519,0.000000
140.510010,65.283966,-406.289001,-0.000483,0.004580,0.116321,290.397583,14.793558,1.163212,-406.289001,294.500519,0.000000
140.900009,65.268707,-406.244537,-0.000474,0.004580,0.116321,290.329712,14.790100,1.163212,-406.244537,294.500519,0.000000
141.290009,65.269821,-406.333496,-0.000487,0.004580,0.116321,290.334656,14.790353,1.163212,-406.333496,294.500519,0.000000
141.680008,65.269455,-406.289001,-0.000470,0.004580,0.116321,290.333038,14.790270,1.163212,-406.289001,294.500519,0.000000
142.070007,65.271317,-406.289001,-0.000487,0.004580,0.116339,290.341309,14.790692,1.163386,-406.289001,294.500519,0.000000
142.460007,65.264603,-406.333496,-0.000483,0.004580,0.116339,290.311462,14.789170,1.163386,-406.333496,1681.641113,0.000000
142.850006,65.227371,-406.333496,-0.000474,0.004571,0.116096,290.145844,14.780734,1.160956,-406.333496,0.115905,0.000000
143.240005,65.128326,-406.422455,-0.000483,0.004549,0.115532,289.705261,14.758289,1.155324,-406.422455,0.115255,0.000000
143.630005,65.120499,-406.422455,-0.000461,0.004530,0.115072,289.670441,14.756516,1.150722,-406.422455,0.114604,0.000000
144.020004,65.084381,-406.466919,-0.000474,0.004509,0.114526,289.509796,14.748331,1.145264,-406.466919,0.113954,0.000000
144.410004,65.067993,-406.466919,-0.000461,0.004478,0.113737,289.436890,14.744618,1.137369,-406.466919,0.113303,0.000000
144.800003,65.047882,-406.466919,-0.000466,0.004455,0.113156,289.347443,14.740061,1.131562,-406.466919,0.112653,0.000000
145.190002,65.042679,-406.511414,-0.000479,0.004432,0.112567,289.324280,14.738881,1.125666,-406.511414,0.112003,0.000000
145.580002,64.988312,-406.511414,-0.000457,0.004402,0.111820,289.082458,14.726562,1.118202,-406.511414,0.111352,0.000000
145.970001,64.964096,-406.466919,-0.000453,0.004385,0.111370,288.974731,14.721074,1.113698,-406.466919,0.110701,0.000000
146.360001,64.791687,-406.600372,-0.000466,0.004354,0.110598,288.207825,14.682007,1.105977,-406.600372,0.110060,0.000000
146.750000,64.391769,-406.466919,-0.000457,0.004333,0.110060,286.428894,14.591384,1.100602,-406.466919,0.109409,0.000000
147.139999,63.203156,-406.644867,-0.000461,0.004307,0.109401,281.141663,14.322040,1.094009,-406.644867,0.108759,0.000000
147.530014,61.918839,-406.600372,-0.000440,0.004280,0.108724,275.428741,14.031010,1.087241,-406.600372,0.108109,0.000000
147.920013,60.714958,-406.644867,-0.000461,0.004262,0.108247,270.073608,13.758206,1.082472,-406.644867,0.107458,0.000000
148.310013,59.035934,-406.644867,-0.000457,0.004235,0.107580,262.604950,13.377734,1.075796,-406.644867,0.106808,0.000000
148.700012,57.229179,-406.600372,-0.000448,0.004212,0.106990,254.568100,12.968317,1.069899,-406.600372,0.106157,0.000000
149.090012,55.224327,-406.733826,-0.000466,0.004188,0.106383,245.650070,12.514011,1.063828,-406.733826,0.105507,0.000000
149.480011,53.784363,-406.689331,-0.000448,0.004171,0.105932,239.244797,12.187711,1.059316,-406.689331,0.104857,0.000000
149.870010,50.913376,-406.733826,-0.000448,0.004145,0.105281,226.474014,11.537136,1.052814,-406.733826,0.104206,0.000000
150.260010,48.866814,-406.778290,-0.000448,0.004120,0.104657,217.370438,11.073379,1.046569,-406.778290,0.103555,0.000000
150.650009,45.029884,-406.778290,-0.000457,0.004087,0.103798,200.302933,10.203918,1.037985,-406.778290,0.102905,0.000000
151.040009,43.027267,-406.733826,-0.000461,0.004071,0.103409,191.394852,9.750118,1.034086,-406.733826,0.102255,0.000000
151.430008,39.891891,-406.822784,-0.000461,0.004041,0.102637,177.447998,9.039632,1.026365,-406.822784,0.101605,0.000000
151.820007,36.928551,-406.778290,-0.000474,0.004015,0.101977,164.266403,8.368130,1.019772,-406.778290,0.100954,0.000000
152.210007,34.725594,-406.867249,-0.000487,0.003995,0.101465,154.467148,7.868932,1.014655,-406.867249,0.100304,0.000000
152.600006,31.148956,-406.822784,-0.000483,0.003960,0.100590,138.557480,7.058455,1.005896,-406.822784,0.099653,0.000000
152.990005,28.648109,-406.911743,-0.000500,0.003938,0.100026,127.433159,6.491755,1.000265,-406.911743,0.099003,0.000000
153.380005,26.240349,-406.867249,-0.000474,0.003916,0.099462,116.722900,5.946148,0.994625,-406.867249,0.098353,0.000000
153.770004,22.970543,-406.911743,-0.000492,0.003885,0.098690,102.178078,5.205199,0.986904,-406.911743,0.097702,0.000000
154.160004,19.932732,-407.000702,-0.000492,0.003857,0.097970,88.665222,4.516821,0.979705,-407.000702,0.097052,0.000000
154.550003,17.097488,-406.911743,-0.000509,0.003833,0.097355,76.053429,3.874346,0.973551,-406.911743,0.096401,0.000000
154.940002,14.124466,-407.000702,-0.000513,0.003806,0.096670,62.828762,3.200650,0.966700,-407.000702,0.095751,0.000000
155.330002,11.937523,-406.956207,-0.000509,0.003786,0.096158,53.100754,2.705081,0.961583,-406.956207,0.095109,0.000000
155.720001,8.450996,-407.045197,-0.000539,0.003755,0.095386,37.591911,1.915023,0.953862,-407.045197,0.094459,0.000000
156.110001,5.948654,-407.045197,-0.000530,0.003731,0.094771,26.460936,1.347984,0.947707,-407.045197,0.093808,0.000000
156.500000,4.231270,-407.000702,-0.000539,0.003716,0.094389,18.821629,0.958819,0.943892,-407.000702,0.093158,0.000000
156.890015,1.427681,-407.089661,-0.000556,0.003688,0.093687,6.350642,0.323517,0.936867,-407.089661,0.092507,0.000000
157.280014,0.017502,-407.089661,-0.000539,0.003672,0.093270,0.077852,0.003966,0.932704,-407.089661,0.091857,0.000000
157.670013,-0.277412,-407.089661,-0.000595,0.003639,0.092420,-1.233992,-0.062863,0.924203,-407.089661,0.091206,0.000000
158.060013,-0.183952,-407.089661,-0.000629,0.003602,0.091501,-0.818261,-0.041684,0.915013,-407.089661,0.090556,0.000000
158.450012,-0.134796,-407.089661,-0.000673,0.003577,0.090851,-0.599603,-0.030545,0.908511,-407.089661,0.089906,0.000000
158.840012,-0.119156,-407.178619,-0.000707,0.003550,0.090166,-0.530032,-0.027001,0.901660,-407.178619,0.089255,0.000000
159.230011,-0.108727,-407.134155,-0.000737,0.003531,0.089697,-0.483640,-0.024638,0.896975,-407.134155,0.088605,0.000000
159.620010,-0.120644,-407.178619,-0.000815,0.003504,0.089004,-0.536650,-0.027338,0.890041,-407.178619,0.087954,0.000000
160.010010,-0.091599,-407.267578,-0.000823,0.003473,0.088215,-0.407451,-0.020757,0.882145,-407.267578,0.087304,0.000000
160.400009,-0.100166,-407.178619,-0.000871,0.003449,0.087607,-0.445562,-0.022698,0.876074,-407.178619,0.086654,0.000000
160.790009,-0.111336,-407.312073,-0.000901,0.003420,0.086879,-0.495246,-0.025229,0.868792,-407.312073,0.086003,0.000000
161.180008,-0.105003,-407.267578,-0.000931,0.003406,0.086506,-0.467078,-0.023794,0.865060,-407.267578,0.085352,0.000000
161.570007,-0.125114,-407.267578,-0.000987,0.003372,0.085656,-0.556537,-0.028351,0.856560,-407.267578,0.084702,0.000000
161.700012,-0.072609,-407.267578,-0.000992,0.003375,0.085734,-0.322981,-0.016453,0.857339,-407.267578,0.085656,0.000000