File: Data/compression 23/AutoNoHeating-12-23-reverse-1-1_09192024_181609.csv
Time (sec),S:Load (lbs),S:HL1 (DIM),S:LVDT (in),S:Position (in),Ch:Position (mm),Ch:Load (N),Ch:Stress (MPa),Ch:Strain (mm/mm),Ch:HL1 (DIM),Set Point (),Cycles ()
0.110000,-0.028671,-280.852722,-0.004432,-0.004513,-0.114622,-0.127536,-0.006497,-1.146218,-280.852722,-0.114405,0.000000
0.490000,-0.038353,-280.897217,-0.004419,-0.004467,-0.113460,-0.170603,-0.008691,-1.134598,-280.897217,-0.112878,0.000000
0.870000,0.024582,-280.941681,-0.004350,-0.004249,-0.107935,0.109346,0.005570,-1.079354,-280.941681,-0.106548,0.000000
1.250000,0.070755,-280.941681,-0.004208,-0.000000,-0.000000,0.314734,0.016033,-0.000000,-280.941681,0.000252,0.000000
1.630000,0.097191,-281.030640,-0.004212,-0.000000,-0.000000,0.432327,0.022024,-0.000000,-281.030640,0.000347,0.000000
2.010000,0.093842,-281.030640,-0.004217,-0.000000,-0.000000,0.417428,0.021265,-0.000000,-281.030640,0.000980,0.000000
2.390000,0.080811,-281.030640,-0.004212,0.000000,0.000009,0.359463,0.018312,0.000091,-281.030640,0.001613,0.000000
2.770000,0.222679,-281.030640,-0.004174,0.000048,0.001232,0.990526,0.050460,0.012316,-281.030640,0.002247,0.000000
3.150000,0.224174,-281.119598,-0.004169,0.000072,0.001830,0.997178,0.050799,0.018304,-281.119598,0.002880,0.000000
3.530000,0.320992,-281.164093,-0.004148,0.000090,0.002298,1.427842,0.072738,0.022982,-281.164093,0.003512,0.000000
3.910000,0.456161,-281.164093,-0.004126,0.000122,0.003105,2.029108,0.103368,0.031051,-281.164093,0.004146,0.000000
4.290000,0.570847,-281.119598,-0.004109,0.000139,0.003530,2.539252,0.129356,0.035298,-281.119598,0.004779,0.000000
4.670000,0.723892,-281.208588,-0.004053,0.000173,0.004388,3.220033,0.164036,0.043882,-281.208588,0.005412,0.000000
5.050000,0.812149,-281.297546,-0.004036,0.000198,0.005022,3.612619,0.184036,0.050218,-281.297546,0.006045,0.000000
5.430000,0.939873,-281.342010,-0.004014,0.000222,0.005637,4.180763,0.212978,0.056372,-281.342010,0.006678,0.000000
5.810000,1.068336,-281.297546,-0.004001,0.000246,0.006253,4.752198,0.242089,0.062534,-281.297546,0.007311,0.000000
6.190000,1.227715,-281.253052,-0.003971,0.000268,0.006808,5.461147,0.278204,0.068083,-281.253052,0.007944,0.000000
6.570000,1.416138,-281.342010,-0.003941,0.000297,0.007536,6.299295,0.320901,0.075365,-281.342010,0.008577,0.000000
6.950000,1.501778,-281.386505,-0.003923,0.000320,0.008135,6.680241,0.340308,0.081353,-281.386505,0.009210,0.000000
7.330000,1.653336,-281.386505,-0.003885,0.000343,0.008708,7.354404,0.374651,0.087075,-281.386505,0.009844,0.000000
7.710001,1.806755,-281.430969,-0.003880,0.000373,0.009471,8.036848,0.409417,0.094706,-281.430969,0.010477,0.000000
8.090000,1.946396,-281.475464,-0.003846,0.000395,0.010035,8.658001,0.441060,0.100345,-281.475464,0.011109,0.000000
8.470000,2.088638,-281.519928,-0.003829,0.000422,0.010720,9.290728,0.473292,0.107196,-281.519928,0.011742,0.000000
8.850000,2.134071,-281.519928,-0.003807,0.000448,0.011370,9.492824,0.483588,0.113698,-281.519928,0.012376,0.000000
9.230000,2.227165,-281.653381,-0.003777,0.000471,0.011960,9.906926,0.504683,0.119595,-281.653381,0.013009,0.000000
9.610001,2.366432,-281.519928,-0.003755,0.000493,0.012523,10.526416,0.536241,0.125235,-281.519928,0.013642,0.000000
9.990001,2.508675,-281.564423,-0.003725,0.000521,0.013225,11.159142,0.568474,0.132252,-281.564423,0.014275,0.000000
10.370001,2.613686,-281.608887,-0.003699,0.000547,0.013885,11.626254,0.592270,0.138845,-281.608887,0.014908,0.000000
10.750001,2.702309,-281.608887,-0.003673,0.000576,0.014622,12.020470,0.612352,0.146218,-281.608887,0.015541,0.000000
11.130000,2.712364,-281.653381,-0.003656,0.000596,0.015134,12.065199,0.614630,0.151335,-281.653381,0.016174,0.000000
11.510000,2.825195,-281.697876,-0.003622,0.000617,0.015663,12.567097,0.640198,0.156627,-281.697876,0.016807,0.000000
11.890000,2.825195,-281.742340,-0.003609,0.000634,0.016113,12.567097,0.640198,0.161131,-281.742340,0.017449,0.000000
12.270000,3.102242,-281.786835,-0.003570,0.000674,0.017119,13.799459,0.702978,0.171191,-281.786835,0.018082,0.000000
12.650001,3.107452,-281.831299,-0.003548,0.000699,0.017761,13.822639,0.704159,0.177610,-281.831299,0.018715,0.000000
13.030001,3.092926,-281.786835,-0.003510,0.000718,0.018238,13.758022,0.700867,0.182379,-281.786835,0.019348,0.000000
13.410001,3.076546,-281.831299,-0.003505,0.000734,0.018637,13.685159,0.697155,0.186368,-281.831299,0.019981,0.000000
13.790001,3.360664,-281.875793,-0.003471,0.000775,0.019678,14.948981,0.761537,0.196777,-281.875793,0.020614,0.000000
14.170001,3.365509,-281.920258,-0.003445,0.000798,0.020267,14.970531,0.762635,0.202674,-281.920258,0.021248,0.000000
14.550001,3.496208,-281.920258,-0.003415,0.000824,0.020935,15.551910,0.792252,0.209350,-281.920258,0.021880,0.000000
14.930000,3.531960,-281.964752,-0.003380,0.000852,0.021647,15.710940,0.800353,0.216466,-281.964752,0.022513,0.000000
15.310000,3.616859,-281.964752,-0.003372,0.000873,0.022184,16.088594,0.819592,0.221840,-281.964752,0.023147,0.000000
15.690001,3.658188,-281.964752,-0.003324,0.000893,0.022687,16.272432,0.828957,0.226867,-281.964752,0.023780,0.000000
16.070002,3.731544,-282.053711,-0.003316,0.000919,0.023355,16.598740,0.845580,0.233551,-282.053711,0.024413,0.000000
16.450001,3.814590,-282.142670,-0.003290,0.000943,0.023945,16.968145,0.864399,0.239448,-282.142670,0.025046,0.000000
16.830000,3.781448,-282.142670,-0.003264,0.000967,0.024560,16.820723,0.856888,0.245602,-282.142670,0.025679,0.000000
17.210001,3.726334,-282.142670,-0.003238,0.000985,0.025029,16.575560,0.844399,0.250288,-282.142670,0.026312,0.000000
17.590000,4.208557,-282.142670,-0.003225,0.001025,0.026035,18.720596,0.953673,0.260348,-282.142670,0.026945,0.000000
17.970001,4.221962,-282.231628,-0.003169,0.001050,0.026668,18.780226,0.956710,0.266676,-282.231628,0.027578,0.000000
18.350000,4.320641,-282.231628,-0.003152,0.001077,0.027344,19.219170,0.979071,0.273444,-282.231628,0.028211,0.000000
18.730001,4.265900,-282.231628,-0.003126,0.001099,0.027925,18.975670,0.966667,0.279250,-282.231628,0.028844,0.000000
19.110001,4.243561,-282.276123,-0.003117,0.001120,0.028437,18.876301,0.961605,0.284367,-282.276123,0.029478,0.000000
19.490002,4.402565,-282.276123,-0.003074,0.001145,0.029079,19.583588,0.997635,0.290786,-282.276123,0.030110,0.000000
19.870001,4.698601,-282.365082,-0.003044,0.001179,0.029937,20.900419,1.064718,0.299370,-282.365082,0.030743,0.000000
20.250002,4.544067,-282.409546,-0.003031,0.001197,0.030414,20.213020,1.029700,0.304139,-282.409546,0.031377,0.000000
20.630001,4.612579,-282.409546,-0.003022,0.001219,0.030960,20.517778,1.045225,0.309604,-282.409546,0.032010,0.000000
21.010000,4.813660,-282.409546,-0.002984,0.001248,0.031698,21.412228,1.090791,0.316977,-282.409546,0.032642,0.000000
21.390001,4.754829,-282.454041,-0.002949,0.001266,0.032157,21.150537,1.077460,0.321572,-282.454041,0.033276,0.000000
21.770000,4.902657,-282.498535,-0.002932,0.001291,0.032799,21.808105,1.110958,0.327991,-282.498535,0.033909,0.000000
22.150002,4.992775,-282.498535,-0.002910,0.001317,0.033440,22.208973,1.131379,0.334403,-282.498535,0.034542,0.000000
22.530001,5.148056,-282.542999,-0.002897,0.001343,0.034109,22.899696,1.166566,0.341087,-282.542999,0.035175,0.000000
22.910002,5.265350,-282.542999,-0.002859,0.001370,0.034802,23.421448,1.193145,0.348021,-282.542999,0.035816,0.000000
23.290001,5.252319,-282.498535,-0.002833,0.001387,0.035236,23.363483,1.190193,0.352359,-282.498535,0.036450,0.000000
23.670002,5.512978,-282.631958,-0.002807,0.001420,0.036077,24.522949,1.249259,0.360769,-282.631958,0.037083,0.000000
24.050001,5.599739,-282.676453,-0.002772,0.001445,0.036693,24.908884,1.268919,0.366930,-282.676453,0.037716,0.000000
24.430000,5.639214,-282.676453,-0.002751,0.001469,0.037308,25.084475,1.277864,0.373085,-282.676453,0.038349,0.000000
24.810001,5.641449,-282.676453,-0.002725,0.001490,0.037838,25.094418,1.278371,0.378376,-282.676453,0.038982,0.000000
25.190001,5.900620,-282.676453,-0.002703,0.001518,0.038566,26.247267,1.337099,0.385658,-282.676453,0.039615,0.000000
25.570002,6.077866,-282.765411,-0.002682,0.001545,0.039251,27.035696,1.377264,0.392509,-282.765411,0.040249,0.000000
25.950001,6.122177,-282.809875,-0.002665,0.001568,0.039815,27.232803,1.387305,0.398148,-282.809875,0.040881,0.000000
26.330002,6.220856,-282.809875,-0.002617,0.001594,0.040482,27.671749,1.409666,0.404825,-282.809875,0.041514,0.000000
26.710001,6.345230,-282.854370,-0.002591,0.001620,0.041150,28.224993,1.437850,0.411501,-282.854370,0.042148,0.000000
27.090002,6.341507,-282.854370,-0.002565,0.001639,0.041636,28.208431,1.437006,0.416361,-282.854370,0.042781,0.000000
27.470001,6.567162,-282.987823,-0.002548,0.001664,0.042261,29.212194,1.488140,0.422606,-282.987823,0.043414,0.000000
27.850000,6.799522,-282.943329,-0.002531,0.001692,0.042971,30.245787,1.540794,0.429714,-282.943329,0.044047,0.000000
28.230001,6.924271,-282.943329,-0.002509,0.001717,0.043604,30.800694,1.569062,0.436043,-282.943329,0.044680,0.000000
28.610001,7.011032,-282.987823,-0.002471,0.001741,0.044220,31.186628,1.588723,0.442204,-282.987823,0.045313,0.000000
28.990002,7.268341,-283.032288,-0.002449,0.001771,0.044974,32.331196,1.647030,0.449744,-283.032288,0.045946,0.000000
29.370001,7.393089,-283.032288,-0.002432,0.001794,0.045564,32.886105,1.675298,0.455641,-283.032288,0.046579,0.000000
29.750002,7.594170,-283.121246,-0.002406,0.001819,0.046215,33.780552,1.720863,0.462151,-283.121246,0.047212,0.000000
30.130001,7.613159,-283.076782,-0.002380,0.001842,0.046778,33.865025,1.725167,0.467783,-283.076782,0.047845,0.000000
30.510002,7.763596,-283.121246,-0.002350,0.001868,0.047446,34.534199,1.759256,0.474459,-283.121246,0.048478,0.000000
30.890001,7.961327,-283.165741,-0.002341,0.001892,0.048045,35.413750,1.804062,0.480447,-283.165741,0.049111,0.000000
31.270002,8.122932,-283.165741,-0.002320,0.001916,0.048678,36.132607,1.840683,0.486775,-283.165741,0.049744,0.000000
31.650002,8.455833,-283.210205,-0.002285,0.001944,0.049380,37.613426,1.916119,0.493800,-283.210205,0.050378,0.000000
32.030003,8.651329,-283.210205,-0.002255,0.001972,0.050082,38.483032,1.960419,0.500825,-283.210205,0.051011,0.000000
32.410000,8.668831,-283.254700,-0.002225,0.001994,0.050637,38.560886,1.964385,0.506374,-283.254700,0.051643,0.000000
32.790001,8.839005,-283.299164,-0.002199,0.002015,0.051193,39.317856,2.002947,0.511930,-283.299164,0.052277,0.000000
33.170002,8.747032,-283.299164,-0.002190,0.002031,0.051583,38.908741,1.982106,0.515828,-283.299164,0.052910,0.000000
33.550003,9.660088,-283.343658,-0.002173,0.002072,0.052624,42.970215,2.189007,0.526237,-283.343658,0.053543,0.000000
33.930000,9.692856,-283.388153,-0.002130,0.002097,0.053257,43.115974,2.196432,0.532565,-283.388153,0.054185,0.000000
34.310001,9.669395,-283.388153,-0.002121,0.002117,0.053760,43.011620,2.191116,0.537599,-283.388153,0.054817,0.000000
34.690002,10.321053,-283.477112,-0.002078,0.002149,0.054593,45.910336,2.338784,0.545926,-283.477112,0.055451,0.000000
35.070004,10.407814,-283.477112,-0.002057,0.002171,0.055147,46.296268,2.358444,0.551474,-283.477112,0.056084,0.000000
35.450001,10.582458,-283.477112,-0.002044,0.002196,0.055780,47.073128,2.398020,0.557803,-283.477112,0.056717,0.000000
35.830002,10.893013,-283.477112,-0.002013,0.002222,0.056440,48.454540,2.468392,0.564396,-283.477112,0.057350,0.000000
36.210003,11.165962,-283.477112,-0.001992,0.002249,0.057133,49.668682,2.530243,0.571330,-283.477112,0.057983,0.000000
36.590000,11.368538,-283.566071,-0.001944,0.002271,0.057688,50.569782,2.576147,0.576879,-283.566071,0.058616,0.000000
36.970001,11.437424,-283.699493,-0.001936,0.002290,0.058174,50.876202,2.591757,0.581738,-283.699493,0.059250,0.000000
37.350002,11.617279,-283.610535,-0.001919,0.002310,0.058686,51.676239,2.632513,0.586856,-283.610535,0.059882,0.000000
37.730003,11.536102,-283.655029,-0.001906,0.002334,0.059293,51.315147,2.614118,0.592927,-283.655029,0.060515,0.000000
38.110001,12.458839,-283.655029,-0.001876,0.002365,0.060065,55.419685,2.823213,0.600648,-283.655029,0.061149,0.000000
38.490002,12.619331,-283.788483,-0.001845,0.002387,0.060620,56.133591,2.859581,0.606196,-283.788483,0.061782,0.000000
38.870003,13.422913,-283.743988,-0.001819,0.002419,0.061443,59.708096,3.041676,0.614432,-283.743988,0.062414,0.000000
39.250000,14.064140,-283.743988,-0.001794,0.002448,0.062189,62.560421,3.186980,0.621889,-283.743988,0.063048,0.000000
39.630001,14.334106,-283.788483,-0.001794,0.002474,0.062831,63.761292,3.248155,0.628308,-283.788483,0.063681,0.000000
40.010002,14.447685,-283.743988,-0.001742,0.002497,0.063430,64.266510,3.273892,0.634295,-283.743988,0.064314,0.000000
40.390003,14.389961,-283.832947,-0.001729,0.002515,0.063880,64.009743,3.260812,0.638799,-283.832947,0.064947,0.000000
40.770000,15.068428,-283.921906,-0.001699,0.002541,0.064548,67.027718,3.414555,0.645476,-283.921906,0.065580,0.000000
41.150002,15.412498,-283.966400,-0.001694,0.002567,0.065207,68.558220,3.492522,0.652069,-283.966400,0.066213,0.000000
41.530003,15.939781,-283.921906,-0.001660,0.002592,0.065831,70.903687,3.612006,0.658314,-283.921906,0.066846,0.000000
41.910004,16.342690,-283.966400,-0.001621,0.002617,0.066473,72.695915,3.703306,0.664734,-283.966400,0.067479,0.000000
42.290001,16.963432,-284.010864,-0.001604,0.002645,0.067193,75.457115,3.843969,0.671932,-284.010864,0.068112,0.000000
42.670002,17.126160,-284.055359,-0.001595,0.002664,0.067670,76.180962,3.880843,0.676701,-284.055359,0.068745,0.000000
43.050003,17.636681,-284.055359,-0.001574,0.002688,0.068286,78.451874,3.996529,0.682856,-284.055359,0.069379,0.000000
43.430000,18.458504,-284.010864,-0.001561,0.002715,0.068953,82.107529,4.182757,0.689532,-284.010864,0.070011,0.000000
43.810001,19.031212,-284.055359,-0.001539,0.002740,0.069595,84.655060,4.312534,0.695951,-284.055359,0.070644,0.000000
44.190002,19.456467,-284.144318,-0.001513,0.002767,0.070272,86.546684,4.408898,0.702719,-284.144318,0.071278,0.000000
44.570004,19.904800,-284.188782,-0.001492,0.002786,0.070757,88.540977,4.510492,0.707571,-284.188782,0.071911,0.000000
44.950001,19.869423,-284.188782,-0.001479,0.002803,0.071200,88.383606,4.502475,0.711999,-284.188782,0.072553,0.000000
45.330002,21.522011,-284.188782,-0.001449,0.002841,0.072154,95.734688,4.876957,0.721537,-284.188782,0.073185,0.000000
45.710003,21.969978,-284.233276,-0.001418,0.002865,0.072761,97.727341,4.978468,0.727608,-284.233276,0.073818,0.000000
46.090004,22.362457,-284.322235,-0.001410,0.002885,0.073281,99.473175,5.067405,0.732809,-284.322235,0.074452,0.000000
46.470001,23.486649,-284.277771,-0.001380,0.002915,0.074053,104.473831,5.322151,0.740530,-284.277771,0.075085,0.000000
46.850002,23.249825,-284.277771,-0.001371,0.002931,0.074443,103.420387,5.268486,0.744428,-284.277771,0.075718,0.000000
47.230003,24.893845,-284.366730,-0.001350,0.002965,0.075301,110.733353,5.641026,0.753012,-284.366730,0.076351,0.000000
47.610001,25.751045,-284.411194,-0.001315,0.002992,0.075986,114.546371,5.835270,0.759863,-284.411194,0.076984,0.000000
47.990002,26.375519,-284.411194,-0.001298,0.003015,0.076585,117.324165,5.976778,0.765851,-284.411194,0.077617,0.000000
48.370003,26.973923,-284.411194,-0.001285,0.003035,0.077097,119.986000,6.112379,0.770968,-284.411194,0.078250,0.000000
48.750004,27.949165,-284.455688,-0.001263,0.003062,0.077782,124.324097,6.333372,0.777819,-284.455688,0.078883,0.000000
49.130001,28.760933,-284.455688,-0.001259,0.003086,0.078389,127.935020,6.517321,0.783890,-284.455688,0.079516,0.000000
49.510002,30.025139,-284.544647,-0.001224,0.003115,0.079126,133.558487,6.803793,0.791263,-284.544647,0.080150,0.000000
49.890003,30.897606,-284.500153,-0.001212,0.003139,0.079742,137.439423,7.001498,0.797417,-284.500153,0.080783,0.000000
50.270004,32.085106,-284.589111,-0.001203,0.003168,0.080479,142.721680,7.270589,0.804790,-284.589111,0.081415,0.000000
50.650002,32.075424,-284.589111,-0.001181,0.003184,0.080878,142.678619,7.268395,0.808779,-284.589111,0.082049,0.000000
51.030003,33.442032,-284.633606,-0.001164,0.003215,0.081650,148.757584,7.578073,0.816500,-284.633606,0.082682,0.000000
51.410004,34.730812,-284.589111,-0.001147,0.003239,0.082265,154.490372,7.870115,0.822654,-284.589111,0.083315,0.000000
51.790001,35.684082,-284.722565,-0.001121,0.003264,0.082916,158.730728,8.086128,0.829157,-284.722565,0.083947,0.000000
52.170002,36.598633,-284.767059,-0.001117,0.003288,0.083505,162.798843,8.293368,0.835054,-284.767059,0.084581,0.000000
52.550003,37.361992,-284.678101,-0.001104,0.003305,0.083939,166.194443,8.466349,0.839391,-284.678101,0.085214,0.000000
52.930004,39.172844,-284.678101,-0.001082,0.003336,0.084745,174.249512,8.876694,0.847453,-284.678101,0.085847,0.000000
53.310001,40.744995,-284.767059,-0.001052,0.003365,0.085483,181.242783,9.232948,0.854826,-284.767059,0.086480,0.000000
53.690002,41.613747,-284.811523,-0.001039,0.003389,0.086072,185.107193,9.429810,0.860723,-284.811523,0.087113,0.000000
54.070004,42.991150,-284.900482,-0.001030,0.003414,0.086714,191.234192,9.741934,0.867142,-284.900482,0.087746,0.000000
54.450001,43.441719,-284.900482,-0.001026,0.003429,0.087105,193.238419,9.844034,0.871048,-284.900482,0.088380,0.000000
54.830002,45.301346,-284.900482,-0.001013,0.003463,0.087954,201.510452,10.265432,0.879541,-284.900482,0.089012,0.000000
55.210003,46.642632,-284.944977,-0.000996,0.003485,0.088510,207.476791,10.569371,0.885098,-284.944977,0.089645,0.000000
55.590004,48.255005,-284.989441,-0.000970,0.003513,0.089221,214.648987,10.934741,0.892206,-284.989441,0.090287,0.000000
55.970001,49.093590,-285.033936,-0.000961,0.003530,0.089672,218.379196,11.124766,0.896717,-285.033936,0.090920,0.000000
56.350002,51.407883,-284.989441,-0.000949,0.003567,0.090600,228.673676,11.649193,0.905998,-284.989441,0.091554,0.000000
56.730003,52.869446,-285.033936,-0.000931,0.003591,0.091224,235.175034,11.980388,0.912235,-285.033936,0.092186,0.000000
57.110004,53.851395,-285.033936,-0.000910,0.003612,0.091735,239.542969,12.202901,0.917353,-285.033936,0.092819,0.000000
57.490002,55.688675,-285.078430,-0.000905,0.003641,0.092482,247.715591,12.619234,0.924816,-285.078430,0.093453,0.000000
57.870003,57.537880,-285.122894,-0.000901,0.003669,0.093184,255.941269,13.038270,0.931841,-285.122894,0.094086,0.000000
58.250004,58.495995,-285.167389,-0.000888,0.003686,0.093626,260.203186,13.255382,0.936262,-285.167389,0.094719,0.000000
58.630001,60.053627,-285.122894,-0.000867,0.003709,0.094207,267.131866,13.608346,0.942068,-285.122894,0.095352,0.000000
59.010002,61.597115,-285.211853,-0.000862,0.003733,0.094814,273.997650,13.958105,0.948139,-285.211853,0.095985,0.000000
59.390003,63.316727,-285.256348,-0.000849,0.003758,0.095456,281.646881,14.347775,0.954558,-285.256348,0.096618,0.000000
59.770004,64.403687,-285.256348,-0.000849,0.003774,0.095872,286.481903,14.594084,0.958721,-285.256348,0.097251,0.000000
60.150002,66.051056,-285.300812,-0.000841,0.003791,0.096288,293.809784,14.967383,0.962885,-285.300812,0.016905,0.000000
60.530003,65.171143,-285.300812,-0.000819,0.003790,0.096271,289.895721,14.767992,0.962711,-285.300812,294.500519,0.000000
60.910004,66.921295,-285.389771,-0.000819,0.003796,0.096410,297.680786,15.164582,0.964096,-285.389771,294.500519,0.000000
61.290005,65.984772,-285.389771,-0.000798,0.003764,0.095594,293.514923,14.952363,0.955943,-285.389771,294.500519,0.000000
61.670002,65.381531,-285.389771,-0.000798,0.003774,0.095872,290.831573,14.815667,0.958721,-285.389771,294.500519,0.000000
62.050003,64.946976,-285.478729,-0.000798,0.003784,0.096106,288.898590,14.717196,0.961061,-285.478729,294.500519,0.000000
62.430004,65.367386,-285.389771,-0.000793,0.003814,0.096886,290.768646,14.812461,0.968865,-285.389771,294.500519,0.000000
62.810001,65.008789,-285.478729,-0.000811,0.003814,0.096886,289.173523,14.731202,0.968865,-285.478729,294.500519,0.000000
63.190002,64.677750,-285.523224,-0.000793,0.003814,0.096886,287.700989,14.656187,0.968865,-285.523224,294.500519,0.000000
63.570004,66.209686,-285.478729,-0.000789,0.003821,0.097061,294.515381,15.003329,0.970606,-285.478729,294.500519,0.000000
63.950005,65.879395,-285.567719,-0.000780,0.003821,0.097061,293.046173,14.928484,0.970606,-285.567719,294.500519,0.000000
64.330002,65.594162,-285.612183,-0.000767,0.003821,0.097061,291.777405,14.863850,0.970606,-285.612183,294.500519,0.000000
64.710007,65.331635,-285.612183,-0.000767,0.003822,0.097069,290.609619,14.804359,0.970689,-285.612183,294.500519,0.000000
65.090004,65.109695,-285.656677,-0.000789,0.003822,0.097069,289.622375,14.754068,0.970689,-285.656677,294.500519,0.000000
65.470001,65.456375,-285.701141,-0.000780,0.003838,0.097476,291.164490,14.832626,0.974762,-285.701141,294.500519,0.000000
65.850006,65.343185,-285.656677,-0.000780,0.003838,0.097476,290.661011,14.806977,0.974762,-285.656677,294.500519,0.000000
66.230003,65.213593,-285.701141,-0.000767,0.003838,0.097476,290.084534,14.777611,0.974762,-285.701141,294.500519,0.000000
66.610001,65.086990,-285.790100,-0.000772,0.003839,0.097503,289.521393,14.748923,0.975027,-285.790100,294.500519,0.000000
66.990005,65.541656,-285.834595,-0.000772,0.003846,0.097676,291.543854,14.851952,0.976760,-285.834595,294.500519,0.000000
67.370003,65.472763,-285.790100,-0.000767,0.003846,0.097676,291.237396,14.836340,0.976760,-285.790100,294.500519,0.000000
67.750000,65.335358,-285.790100,-0.000776,0.003846,0.097676,290.626190,14.805204,0.976760,-285.790100,294.500519,0.000000
68.130005,65.234818,-285.790100,-0.000759,0.003846,0.097676,290.178955,14.782421,0.976760,-285.790100,294.500519,0.000000
68.510002,65.210983,-285.923553,-0.000772,0.003847,0.097711,290.072937,14.777020,0.977108,-285.923553,294.500519,0.000000
68.890007,65.101501,-285.923553,-0.000776,0.003847,0.097711,289.585937,14.752212,0.977108,-285.923553,294.500519,0.000000
69.270004,64.997620,-285.968048,-0.000776,0.003848,0.097746,289.123840,14.728671,0.977457,-285.968048,294.500519,0.000000
69.650002,65.170776,-285.968048,-0.000772,0.003850,0.097797,289.894104,14.767909,0.977971,-285.968048,294.500519,0.000000
70.030006,65.098160,-286.012512,-0.000767,0.003850,0.097797,289.571075,14.751454,0.977971,-286.012512,294.500519,0.000000
70.410004,65.027771,-286.101471,-0.000763,0.003851,0.097806,289.257965,14.735503,0.978062,-286.101471,294.500519,0.000000
70.790001,64.970062,-286.101471,-0.000772,0.003851,0.097806,289.001282,14.722427,0.978062,-286.101471,294.500519,0.000000
71.170006,64.886642,-286.012512,-0.000767,0.003851,0.097815,288.630188,14.703523,0.978146,-286.012512,294.500519,0.000000
71.550003,64.810684,-286.145966,-0.000750,0.003851,0.097824,288.292328,14.686312,0.978236,-286.145966,294.500519,0.000000
71.930000,66.373901,-286.145966,-0.000755,0.003860,0.098040,295.245850,15.040541,0.980401,-286.145966,294.500519,0.000000
72.310005,66.260696,-286.145966,-0.000763,0.003860,0.098040,294.742310,15.014888,0.980401,-286.145966,294.500519,0.000000
72.690002,66.163147,-286.190430,-0.000763,0.003860,0.098040,294.308380,14.992784,0.980401,-286.190430,294.500519,0.000000
73.070000,66.081223,-286.234924,-0.000759,0.003860,0.098040,293.943970,14.974219,0.980401,-286.234924,294.500519,0.000000
73.450005,65.988495,-286.323883,-0.000763,0.003860,0.098040,293.531494,14.953207,0.980401,-286.323883,294.500519,0.000000
73.830002,65.903595,-286.323883,-0.000746,0.003860,0.098040,293.153839,14.933968,0.980401,-286.323883,294.500519,0.000000
74.210007,65.841415,-286.279388,-0.000750,0.003860,0.098040,292.877258,14.919878,0.980401,-286.279388,294.500519,0.000000
74.590004,65.773270,-286.368378,-0.000750,0.003860,0.098040,292.574127,14.904435,0.980401,-286.368378,294.500519,0.000000
74.970001,65.667145,-286.323883,-0.000763,0.003860,0.098040,292.102051,14.880387,0.980401,-286.323883,294.500519,0.000000
75.350006,65.593414,-286.323883,-0.000750,0.003860,0.098040,291.774078,14.863680,0.980401,-286.323883,294.500519,0.000000
75.730003,65.539047,-286.368378,-0.000759,0.003860,0.098040,291.532257,14.851360,0.980401,-286.368378,294.500519,0.000000
76.110001,65.474625,-286.457336,-0.000750,0.003860,0.098040,291.245667,14.836762,0.980401,-286.457336,294.500519,0.000000
76.490005,65.384888,-286.457336,-0.000763,0.003860,0.098040,290.846497,14.816427,0.980401,-286.457336,294.500519,0.000000
76.870003,65.317856,-286.412842,-0.000755,0.003860,0.098040,290.548340,14.801237,0.980401,-286.412842,294.500519,0.000000
77.250000,65.277267,-286.457336,-0.000755,0.003860,0.098040,290.367798,14.792040,0.980401,-286.457336,294.500519,0.000000
77.630005,65.227737,-286.457336,-0.000742,0.003860,0.098040,290.147461,14.780817,0.980401,-286.457336,294.500519,0.000000
78.010002,65.121994,-286.546295,-0.000746,0.003860,0.098040,289.677094,14.756855,0.980401,-286.546295,294.500519,0.000000
78.390007,65.067245,-286.590759,-0.000767,0.003860,0.098040,289.433563,14.744449,0.980401,-286.590759,294.500519,0.000000
78.770004,65.011017,-286.590759,-0.000750,0.003860,0.098040,289.183441,14.731707,0.980401,-286.590759,294.500519,0.000000
79.150002,64.988678,-286.635254,-0.000737,0.003860,0.098049,289.084076,14.726645,0.980492,-286.635254,294.500519,0.000000
79.530006,64.924637,-286.635254,-0.000737,0.003860,0.098049,288.799194,14.712132,0.980492,-286.635254,294.500519,0.000000
79.910004,64.856857,-286.724213,-0.000759,0.003860,0.098049,288.497711,14.696774,0.980492,-286.724213,294.500519,0.000000
80.290001,64.789459,-286.679718,-0.000763,0.003861,0.098058,288.197906,14.681501,0.980575,-286.679718,294.500519,0.000000
80.670006,66.601425,-286.679718,-0.000742,0.003845,0.097668,296.257935,15.092099,0.976677,-286.679718,294.500519,0.000000
81.050003,66.549667,-286.724213,-0.000737,0.003845,0.097668,296.027710,15.080371,0.976677,-286.724213,294.500519,0.000000
81.430000,66.373535,-286.724213,-0.000746,0.003845,0.097668,295.244232,15.040459,0.976677,-286.724213,294.500519,0.000000
81.810005,66.388062,-286.902130,-0.000742,0.003845,0.097668,295.308838,15.043750,0.976677,-286.902130,294.500519,0.000000
82.190002,66.345230,-286.857666,-0.000737,0.003845,0.097668,295.118317,15.034044,0.976677,-286.857666,294.500519,0.000000
82.570007,66.303528,-286.813171,-0.000742,0.003845,0.097668,294.932831,15.024593,0.976677,-286.813171,294.500519,0.000000
82.950005,66.246185,-286.902130,-0.000724,0.003845,0.097668,294.677734,15.011600,0.976677,-286.902130,294.500519,0.000000
83.330002,66.201492,-286.857666,-0.000737,0.003845,0.097668,294.478943,15.001472,0.976677,-286.857666,294.500519,0.000000
83.710007,66.142288,-286.946625,-0.000746,0.003845,0.097668,294.215607,14.988057,0.976677,-286.946625,294.500519,0.000000
84.090004,66.106171,-287.035583,-0.000742,0.003845,0.097668,294.054932,14.979873,0.976677,-287.035583,294.500519,0.000000
84.470001,66.064087,-286.991089,-0.000733,0.003845,0.097668,293.867737,14.970336,0.976677,-286.991089,294.500519,0.000000
84.850006,66.012711,-286.991089,-0.000742,0.003845,0.097668,293.639191,14.958694,0.976677,-286.991089,294.500519,0.000000
85.230003,65.937851,-286.991089,-0.000742,0.003846,0.097676,293.306213,14.941730,0.976760,-286.991089,294.500519,0.000000
85.610001,65.927795,-287.124542,-0.000742,0.003846,0.097676,293.261475,14.939452,0.976760,-287.124542,294.500519,0.000000
85.990005,65.889816,-287.124542,-0.000729,0.003846,0.097676,293.092529,14.930845,0.976760,-287.124542,294.500519,0.000000
86.370003,65.836945,-287.124542,-0.000733,0.003846,0.097676,292.857361,14.918864,0.976760,-287.124542,294.500519,0.000000
86.750008,65.833588,-287.080048,-0.000746,0.003846,0.097676,292.842438,14.918104,0.976760,-287.080048,294.500519,0.000000
87.130005,65.767685,-287.169006,-0.000733,0.003846,0.097676,292.549286,14.903171,0.976760,-287.169006,294.500519,0.000000
87.510002,65.748322,-287.213501,-0.000733,0.003846,0.097676,292.463135,14.898783,0.976760,-287.213501,294.500519,0.000000
87.890007,65.673096,-287.213501,-0.000746,0.003846,0.097684,292.128510,14.881736,0.976844,-287.213501,294.500519,0.000000
88.270004,65.635117,-287.257996,-0.000755,0.003846,0.097693,291.959595,14.873131,0.976934,-287.257996,294.500519,0.000000
88.650002,65.600861,-287.257996,-0.000729,0.003846,0.097693,291.807190,14.865368,0.976934,-287.257996,294.500519,0.000000
89.030006,65.571808,-287.346954,-0.000733,0.003846,0.097693,291.677979,14.858784,0.976934,-287.346954,294.500519,0.000000
89.410004,65.556915,-287.346954,-0.000737,0.003846,0.097693,291.611725,14.855410,0.976934,-287.346954,294.500519,0.000000
89.790001,65.533081,-287.435913,-0.000737,0.003847,0.097702,291.505707,14.850009,0.977018,-287.435913,294.500519,0.000000
90.170006,65.496964,-287.391418,-0.000729,0.003847,0.097702,291.345032,14.841825,0.977018,-287.391418,294.500519,0.000000
90.550003,65.447449,-287.302460,-0.000733,0.003849,0.097754,291.124786,14.830605,0.977540,-287.302460,294.500519,0.000000
90.930008,65.380417,-287.435913,-0.000737,0.003852,0.097832,290.826630,14.815414,0.978320,-287.435913,294.500519,0.000000
91.310005,65.467926,-287.524872,-0.000737,0.003868,0.098248,291.215881,14.835244,0.982483,-287.524872,294.500519,0.000000
91.690002,65.454895,-287.480377,-0.000729,0.003871,0.098326,291.157928,14.832291,0.983263,-287.480377,294.500519,0.000000
92.070007,65.410583,-287.480377,-0.000733,0.003871,0.098335,290.960815,14.822250,0.983354,-287.480377,294.500519,0.000000
92.450005,65.375580,-287.569336,-0.000729,0.003872,0.098353,290.805115,14.814319,0.983528,-287.569336,294.500519,0.000000
92.830002,65.365891,-287.569336,-0.000737,0.003873,0.098387,290.761993,14.812122,0.983868,-287.569336,294.500519,0.000000
93.210007,65.357330,-287.613831,-0.000746,0.003875,0.098422,290.723938,14.810183,0.984217,-287.613831,294.500519,0.000000
93.590004,65.517822,-287.658325,-0.000742,0.003878,0.098509,291.437836,14.846551,0.985087,-287.658325,294.500519,0.000000
93.970001,65.514099,-287.613831,-0.000742,0.003878,0.098509,291.421265,14.845707,0.985087,-287.613831,294.500519,0.000000
94.350006,65.491013,-287.613831,-0.000729,0.003878,0.098509,291.318573,14.840475,0.985087,-287.613831,294.500519,0.000000
94.730003,65.474625,-287.702789,-0.000746,0.003878,0.098509,291.245667,14.836762,0.985087,-287.702789,294.500519,0.000000
95.110008,65.451538,-287.747284,-0.000737,0.003878,0.098509,291.142975,14.831531,0.985087,-287.747284,294.500519,0.000000
95.490005,65.414307,-287.791748,-0.000742,0.003878,0.098509,290.977356,14.823093,0.985087,-287.791748,294.500519,0.000000
95.870003,65.397919,-287.791748,-0.000742,0.003879,0.098517,290.904480,14.819380,0.985170,-287.791748,294.500519,0.000000
96.250008,65.377808,-287.791748,-0.000742,0.003879,0.098517,290.815002,14.814822,0.985170,-287.791748,294.500519,0.000000
96.630005,65.356216,-287.836243,-0.000729,0.003879,0.098517,290.718964,14.809930,0.985170,-287.836243,294.500519,0.000000
97.010002,65.334244,-287.925201,-0.000733,0.003879,0.098526,290.621216,14.804952,0.985261,-287.925201,294.500519,0.000000
97.390007,65.352493,-287.880707,-0.000733,0.003880,0.098552,290.702423,14.809087,0.985519,-287.880707,294.500519,0.000000
97.770004,65.350250,-287.880707,-0.000729,0.003880,0.098552,290.692444,14.808578,0.985519,-287.880707,294.500519,0.000000
98.150002,65.335724,-287.969666,-0.000742,0.003881,0.098569,290.627808,14.805286,0.985693,-287.969666,294.500519,0.000000
98.530006,65.362167,-287.969666,-0.000724,0.003881,0.098578,290.745453,14.811279,0.985776,-287.969666,294.500519,0.000000
98.910004,65.372223,-288.014160,-0.000729,0.003881,0.098587,290.790161,14.813558,0.985867,-288.014160,294.500519,0.000000
99.290001,65.356216,-288.014160,-0.000742,0.003882,0.098595,290.718964,14.809930,0.985950,-288.014160,294.500519,0.000000
99.670006,65.433670,-288.014160,-0.000729,0.003884,0.098647,291.063507,14.827481,0.986472,-288.014160,294.500519,0.000000
100.050003,65.489517,-288.058624,-0.000733,0.003884,0.098647,291.311920,14.840137,0.986472,-288.058624,294.500519,0.000000
100.430008,65.501434,-288.147614,-0.000742,0.003884,0.098647,291.364929,14.842837,0.986472,-288.147614,294.500519,0.000000
100.810005,65.498459,-288.192078,-0.000733,0.003884,0.098647,291.351685,14.842163,0.986472,-288.192078,294.500519,0.000000
101.190002,65.478348,-288.192078,-0.000733,0.003884,0.098647,291.262238,14.837605,0.986472,-288.192078,294.500519,0.000000
101.570007,65.464203,-288.147614,-0.000733,0.003884,0.098647,291.199310,14.834400,0.986472,-288.147614,294.500519,0.000000
101.950005,65.435898,-288.236572,-0.000733,0.003884,0.098647,291.073425,14.827986,0.986472,-288.236572,294.500519,0.000000
102.330002,65.422501,-288.192078,-0.000729,0.003884,0.098647,291.013824,14.824950,0.986472,-288.192078,294.500519,0.000000
102.710007,65.410202,-288.325531,-0.000729,0.003884,0.098647,290.959106,14.822164,0.986472,-288.325531,294.500519,0.000000
103.090004,65.394562,-288.369995,-0.000724,0.003884,0.098647,290.889526,14.818619,0.986472,-288.369995,294.500519,0.000000
103.470001,65.390839,-288.325531,-0.000750,0.003884,0.098656,290.872986,14.817776,0.986563,-288.325531,294.500519,0.000000
103.850006,65.366272,-288.414490,-0.000733,0.003884,0.098665,290.763702,14.812209,0.986646,-288.414490,294.500519,0.000000
104.230003,65.401642,-288.369995,-0.000737,0.003885,0.098690,290.921021,14.820224,0.986904,-288.369995,294.500519,0.000000
104.610008,65.422867,-288.458954,-0.000733,0.003885,0.098690,291.015442,14.825034,0.986904,-288.458954,294.500519,0.000000
104.990005,65.408340,-288.414490,-0.000737,0.003885,0.098690,290.950836,14.821742,0.986904,-288.414490,294.500519,0.000000
105.370003,65.397919,-288.503448,-0.000742,0.003885,0.098690,290.904480,14.819380,0.986904,-288.503448,294.500519,0.000000
105.750008,65.401276,-288.458954,-0.000724,0.003885,0.098690,290.919403,14.820141,0.986904,-288.458954,294.500519,0.000000
106.130005,65.371475,-288.547943,-0.000724,0.003886,0.098699,290.786835,14.813388,0.986995,-288.547943,294.500519,0.000000
106.510002,65.401276,-288.636902,-0.000737,0.003887,0.098725,290.919403,14.820141,0.987252,-288.636902,294.500519,0.000000
106.890007,65.408722,-288.592407,-0.000737,0.003887,0.098725,290.952515,14.821828,0.987252,-288.592407,294.500519,0.000000
107.270004,65.407227,-288.547943,-0.000729,0.003887,0.098725,290.945862,14.821489,0.987252,-288.547943,294.500519,0.000000
107.650002,65.395309,-288.636902,-0.000733,0.003887,0.098725,290.892853,14.818789,0.987252,-288.636902,294.500519,0.000000
108.030006,65.428452,-288.681366,-0.000729,0.003888,0.098752,291.040283,14.826300,0.987517,-288.681366,294.500519,0.000000
108.410004,65.454514,-288.681366,-0.000737,0.003888,0.098752,291.156219,14.832205,0.987517,-288.681366,294.500519,0.000000
108.790009,65.452286,-288.770325,-0.000742,0.003888,0.098752,291.146301,14.831700,0.987517,-288.770325,294.500519,0.000000
109.170006,65.450790,-288.725861,-0.000742,0.003888,0.098752,291.139648,14.831361,0.987517,-288.725861,294.500519,0.000000
109.550003,65.427704,-288.770325,-0.000737,0.003888,0.098752,291.036957,14.826130,0.987517,-288.770325,294.500519,0.000000
109.930008,65.415787,-288.814819,-0.000733,0.003888,0.098752,290.983948,14.823429,0.987517,-288.814819,294.500519,0.000000
110.310005,65.404999,-288.859283,-0.000737,0.003888,0.098752,290.935974,14.820985,0.987517,-288.859283,294.500519,0.000000
110.690002,65.395676,-288.859283,-0.000733,0.003888,0.098752,290.894501,14.818871,0.987517,-288.859283,294.500519,0.000000
111.070007,65.376694,-288.859283,-0.000724,0.003888,0.098752,290.810059,14.814571,0.987517,-288.859283,294.500519,0.000000
111.450005,65.361801,-288.859283,-0.000733,0.003888,0.098752,290.743805,14.811195,0.987517,-288.859283,294.500519,0.000000
111.830002,65.360672,-288.948273,-0.000737,0.003888,0.098760,290.738800,14.810940,0.987600,-288.948273,294.500519,0.000000
112.210007,65.349136,-288.992737,-0.000724,0.003888,0.098760,290.687469,14.808326,0.987600,-288.992737,294.500519,0.000000
112.590004,65.322693,-289.037231,-0.000742,0.003889,0.098777,290.569855,14.802334,0.987774,-289.037231,294.500519,0.000000
112.970009,65.324554,-288.992737,-0.000729,0.003889,0.098777,290.578125,14.802755,0.987774,-288.992737,294.500519,0.000000
113.350006,65.343552,-289.037231,-0.000733,0.003889,0.098786,290.662628,14.807060,0.987858,-289.037231,294.500519,0.000000
113.730003,65.332748,-289.037231,-0.000729,0.003889,0.098786,290.614594,14.804612,0.987858,-289.037231,294.500519,0.000000
114.110008,65.326797,-289.126190,-0.000737,0.003889,0.098786,290.588104,14.803264,0.987858,-289.126190,294.500519,0.000000
114.490005,65.323074,-289.215149,-0.000724,0.003890,0.098795,290.571533,14.802421,0.987948,-289.215149,294.500519,0.000000
114.870003,65.328278,-289.126190,-0.000733,0.003890,0.098803,290.594696,14.803599,0.988032,-289.126190,294.500519,0.000000
115.250008,65.316360,-289.170654,-0.000737,0.003890,0.098812,290.541687,14.800900,0.988123,-289.170654,294.500519,0.000000
115.630005,65.340195,-289.170654,-0.000729,0.003891,0.098821,290.647705,14.806300,0.988206,-289.170654,294.500519,0.000000
116.010002,65.348770,-289.215149,-0.000733,0.003891,0.098821,290.685852,14.808244,0.988206,-289.215149,294.500519,0.000000
116.390007,65.340576,-289.259613,-0.000729,0.003891,0.098821,290.649414,14.806386,0.988206,-289.259613,294.500519,0.000000
116.770004,65.335724,-289.259613,-0.000737,0.003891,0.098821,290.627808,14.805286,0.988206,-289.259613,294.500519,0.000000
117.150009,65.330521,-289.304108,-0.000746,0.003891,0.098821,290.604675,14.804107,0.988206,-289.304108,294.500519,0.000000
117.530006,65.321213,-289.304108,-0.000720,0.003891,0.098821,290.563263,14.801998,0.988206,-289.304108,294.500519,0.000000
117.910004,65.330139,-289.393066,-0.000733,0.003891,0.098830,290.602966,14.804021,0.988297,-289.393066,294.500519,0.000000
118.290009,65.327545,-289.482025,-0.000720,0.003891,0.098830,290.591431,14.803433,0.988297,-289.482025,294.500519,0.000000
118.670006,65.311905,-289.437561,-0.000733,0.003891,0.098838,290.521851,14.799890,0.988380,-289.437561,294.500519,0.000000
119.050003,65.314133,-289.437561,-0.000733,0.003891,0.098838,290.531769,14.800394,0.988380,-289.437561,294.500519,0.000000
119.430008,65.304459,-289.482025,-0.000733,0.003892,0.098847,290.488739,14.798202,0.988471,-289.482025,294.500519,0.000000
119.810005,65.310776,-289.570984,-0.000746,0.003892,0.098855,290.516846,14.799634,0.988554,-289.570984,294.500519,0.000000
120.190002,65.304825,-289.570984,-0.000720,0.003892,0.098855,290.490356,14.798285,0.988554,-289.570984,294.500519,0.000000
120.570007,65.314133,-289.526520,-0.000724,0.003892,0.098855,290.531769,14.800394,0.988554,-289.526520,1681.641113,0.000000
120.950005,65.361420,-289.526520,-0.000729,0.003885,0.098682,290.742126,14.811110,0.986821,-289.526520,0.098578,0.000000
121.330009,65.322693,-289.615479,-0.000733,0.003870,0.098291,290.569855,14.802334,0.982915,-289.615479,0.097945,0.000000
121.710007,65.188644,-289.704437,-0.000729,0.003849,0.097754,289.973572,14.771957,0.977540,-289.704437,0.097312,0.000000
122.090004,65.149918,-289.659943,-0.000733,0.003827,0.097199,289.801300,14.763183,0.971991,-289.659943,0.096678,0.000000
122.470009,65.143585,-289.704437,-0.000729,0.003803,0.096600,289.773132,14.761747,0.966004,-289.704437,0.096045,0.000000
122.850006,65.107834,-289.748901,-0.000707,0.003778,0.095950,289.614105,14.753646,0.959501,-289.748901,0.095413,0.000000
123.230003,65.097412,-289.748901,-0.000716,0.003758,0.095465,289.567749,14.751285,0.954649,-289.748901,0.094780,0.000000
123.610008,65.102631,-289.748901,-0.000737,0.003730,0.094736,289.590973,14.752467,0.947359,-289.748901,0.094146,0.000000
123.990005,65.082138,-289.837891,-0.000733,0.003706,0.094120,289.499817,14.747823,0.941205,-289.837891,0.093513,0.000000
124.370003,65.010651,-289.793396,-0.000729,0.003685,0.093591,289.181824,14.731625,0.935914,-289.793396,0.092881,0.000000
124.750008,64.730255,-289.837891,-0.000716,0.003660,0.092976,287.934570,14.668085,0.929759,-289.837891,0.092247,0.000000
125.130005,64.079346,-289.882355,-0.000707,0.003639,0.092429,285.039154,14.520588,0.924294,-289.882355,0.091614,0.000000
125.510010,62.850891,-289.926849,-0.000716,0.003611,0.091727,279.574738,14.242215,0.917269,-289.926849,0.090972,0.000000
125.890007,61.387093,-289.971313,-0.000716,0.003584,0.091042,273.063416,13.910514,0.910419,-289.971313,0.090339,0.000000
126.270004,60.300140,-289.971313,-0.000694,0.003568,0.090616,268.228424,13.664207,0.906164,-289.971313,0.089707,0.000000
126.650009,58.923477,-290.015808,-0.000690,0.003549,0.090140,262.104706,13.352251,0.901395,-290.015808,0.089073,0.000000
127.030006,56.923836,-290.015808,-0.000698,0.003519,0.089386,253.209869,12.899126,0.893856,-290.015808,0.088440,0.000000
127.410004,54.955849,-290.104767,-0.000698,0.003498,0.088856,244.455826,12.453174,0.888565,-290.104767,0.087807,0.000000
127.790009,52.500053,-290.060272,-0.000694,0.003471,0.088171,233.531906,11.896682,0.881714,-290.060272,0.087174,0.000000
128.170013,50.409927,-290.104767,-0.000698,0.003453,0.087695,224.234558,11.423053,0.876945,-290.104767,0.086541,0.000000
128.550003,47.936630,-290.104767,-0.000711,0.003422,0.086914,213.232788,10.862596,0.869141,-290.104767,0.085908,0.000000
128.930008,44.464256,-290.193726,-0.000690,0.003397,0.086290,197.786896,10.075744,0.862895,-290.193726,0.085274,0.000000
129.310013,41.989464,-290.193726,-0.000703,0.003372,0.085648,186.778458,9.514949,0.856476,-290.193726,0.084642,0.000000
129.690002,38.862656,-290.238220,-0.000703,0.003345,0.084963,172.869720,8.806403,0.849626,-290.238220,0.084009,0.000000
130.070007,36.561020,-290.149231,-0.000703,0.003327,0.084511,162.631546,8.284845,0.845114,-290.149231,0.083375,0.000000
130.450012,34.695435,-290.238220,-0.000694,0.003301,0.083844,154.333008,7.862098,0.838437,-290.238220,0.082742,0.000000
130.830002,31.454674,-290.282684,-0.000698,0.003273,0.083141,139.917374,7.127731,0.831413,-290.282684,0.082110,0.000000
131.210007,28.661140,-290.371643,-0.000690,0.003250,0.082560,127.491119,6.494707,0.825599,-290.371643,0.081476,0.000000
131.590012,25.116524,-290.371643,-0.000707,0.003223,0.081875,111.723877,5.691485,0.818748,-290.371643,0.080843,0.000000
131.970001,22.507309,-290.371643,-0.000694,0.003201,0.081303,100.117508,5.100229,0.813026,-290.371643,0.080210,0.000000
132.350006,20.131950,-290.371643,-0.000677,0.003180,0.080773,89.551392,4.561965,0.807734,-290.371643,0.079577,0.000000
132.730011,17.543587,-290.416138,-0.000711,0.003155,0.080150,78.037773,3.975434,0.801497,-290.416138,0.078944,0.000000
133.110001,14.204521,-290.460602,-0.000690,0.003127,0.079430,63.184864,3.218791,0.794298,-290.460602,0.078311,0.000000
133.490005,12.046997,-290.416138,-0.000690,0.003101,0.078753,53.587719,2.729889,0.787531,-290.416138,0.077677,0.000000
133.870010,8.602180,-290.505096,-0.000698,0.003076,0.078129,38.264408,1.949282,0.781286,-290.505096,0.077045,0.000000
134.250000,5.806404,-290.505096,-0.000703,0.003050,0.077478,25.828175,1.315750,0.774783,-290.505096,0.076412,0.000000
134.630005,3.491737,-290.549561,-0.000686,0.003030,0.076958,15.532023,0.791239,0.769583,-290.549561,0.075779,0.000000
135.010010,0.722031,-290.594055,-0.000694,0.002998,0.076143,3.211753,0.163614,0.761430,-290.594055,0.075145,0.000000
135.389999,-1.950485,-290.594055,-0.000698,0.002973,0.075527,-8.676191,-0.441986,0.755268,-290.594055,0.074512,0.000000
135.770004,-0.281509,-290.638519,-0.000686,0.002952,0.074981,-1.252216,-0.063791,0.749810,-290.638519,0.073880,0.000000
136.150009,-0.181343,-290.683014,-0.000681,0.002924,0.074279,-0.806654,-0.041093,0.742786,-290.683014,0.073246,0.000000
136.530014,-0.089737,-290.771973,-0.000698,0.002908,0.073853,-0.399170,-0.020335,0.738531,-290.771973,0.072604,0.000000
136.910004,-0.123627,-290.727509,-0.000716,0.002874,0.073003,-0.549919,-0.028014,0.730031,-290.727509,0.071971,0.000000
137.290009,-0.131447,-290.727509,-0.000703,0.002851,0.072405,-0.584705,-0.029786,0.724050,-290.727509,0.071338,0.000000
137.670013,-0.148201,-290.727509,-0.000698,0.002825,0.071755,-0.659231,-0.033583,0.717548,-290.727509,0.070706,0.000000
138.050003,-0.122879,-290.816467,-0.000703,0.002797,0.071052,-0.546593,-0.027845,0.710523,-290.816467,0.070072,0.000000
138.430008,-0.145592,-290.816467,-0.000716,0.002774,0.070454,-0.647624,-0.032992,0.704535,-290.816467,0.069439,0.000000
138.810013,-0.132935,-290.860931,-0.000750,0.002753,0.069916,-0.591322,-0.030123,0.699161,-290.860931,0.068806,0.000000
139.190002,-0.147087,-290.860931,-0.000793,0.002724,0.069188,-0.654276,-0.033330,0.691879,-290.860931,0.068173,0.000000
139.570007,-0.129585,-290.860931,-0.000819,0.002700,0.068572,-0.576424,-0.029364,0.685717,-290.860931,0.067540,0.000000
139.950012,-0.109100,-290.949890,-0.000849,0.002670,0.067809,-0.485303,-0.024722,0.678087,-290.949890,0.066907,0.000000
140.330002,-0.145966,-290.905426,-0.000884,0.002648,0.067254,-0.649287,-0.033076,0.672538,-290.905426,0.066274,0.000000
140.710007,-0.124741,-290.994385,-0.000923,0.002630,0.066794,-0.554874,-0.028267,0.667943,-290.994385,0.065641,0.000000
141.090012,-0.126976,-290.994385,-0.000940,0.002603,0.066118,-0.564817,-0.028773,0.661176,-290.994385,0.065008,0.000000
141.470001,-0.110588,-290.949890,-0.000979,0.002570,0.065285,-0.491920,-0.025060,0.652849,-290.949890,0.064374,0.000000
141.850006,-0.105003,-291.038849,-0.001000,0.002554,0.064869,-0.467078,-0.023794,0.648686,-291.038849,0.063741,0.000000
142.230011,-0.103889,-291.172302,-0.001035,0.002520,0.064019,-0.462123,-0.023542,0.640192,-291.172302,0.063109,0.000000
142.610001,-0.093086,-291.172302,-0.001052,0.002506,0.063646,-0.414068,-0.021094,0.636460,-291.172302,0.062475,0.000000
142.990005,-0.113945,-291.127838,-0.001087,0.002474,0.062848,-0.506853,-0.025820,0.628482,-291.127838,0.061842,0.000000
143.370010,-0.091225,-291.127838,-0.001125,0.002447,0.062155,-0.405788,-0.020672,0.621548,-291.127838,0.061209,0.000000
143.750000,-0.055855,-291.216797,-0.001138,0.002420,0.061461,-0.248455,-0.012657,0.614606,-291.216797,0.060576,0.000000
144.130005,-0.075218,-291.261261,-0.001164,0.002396,0.060854,-0.334587,-0.017045,0.608535,-291.261261,0.059943,0.000000
144.510010,-0.081543,-291.261261,-0.001194,0.002377,0.060377,-0.362721,-0.018478,0.603766,-291.261261,0.059310,0.000000
144.889999,-0.110588,-291.172302,-0.001203,0.002358,0.059882,-0.491920,-0.025060,0.598823,-291.172302,0.058677,0.000000
145.270004,-0.079315,-291.261261,-0.001246,0.002321,0.058963,-0.352812,-0.017973,0.589634,-291.261261,0.058044,0.000000
145.650009,-0.066650,-291.305756,-0.001263,0.002301,0.058443,-0.296476,-0.015103,0.584426,-291.305756,0.057411,0.000000
146.030014,-0.056229,-291.305756,-0.001298,0.002276,0.057801,-0.250117,-0.012742,0.578006,-291.305756,0.056778,0.000000
146.410004,-0.070374,-291.350220,-0.001345,0.002250,0.057150,-0.313037,-0.015947,0.571504,-291.350220,0.056144,0.000000
146.790009,-0.092346,-291.350220,-0.001332,0.002236,0.056795,-0.410776,-0.020926,0.567946,-291.350220,0.055512,0.000000
147.170013,-0.080055,-291.394714,-0.001384,0.002196,0.055780,-0.356103,-0.018141,0.557803,-291.394714,0.054879,0.000000
147.550003,-0.081917,-291.439178,-0.001401,0.002169,0.055104,-0.364384,-0.018563,0.551035,-291.439178,0.054237,0.000000
147.930008,-0.091225,-291.483673,-0.001423,0.002153,0.054679,-0.405788,-0.020672,0.546789,-291.483673,0.053604,0.000000
148.310013,-0.086761,-291.528168,-0.001457,0.002122,0.053907,-0.385934,-0.019660,0.539067,-291.528168,0.052970,0.000000
148.690002,-0.081917,-291.439178,-0.001475,0.002107,0.053525,-0.364384,-0.018563,0.535252,-291.439178,0.052338,0.000000
149.070007,-0.096069,-291.528168,-0.001505,0.002073,0.052658,-0.427338,-0.021770,0.526585,-291.528168,0.051705,0.000000
149.450012,-0.128838,-291.528168,-0.001535,0.002054,0.052173,-0.573098,-0.029195,0.521725,-291.528168,0.051071,0.000000
149.830002,-0.128090,-291.572632,-0.001556,0.002025,0.051444,-0.569772,-0.029026,0.514443,-291.572632,0.050438,0.000000
150.210007,-0.103889,-291.617126,-0.001600,0.001998,0.050750,-0.462123,-0.023542,0.507501,-291.617126,0.049805,0.000000
150.590012,-0.120270,-291.572632,-0.001608,0.001978,0.050238,-0.534987,-0.027254,0.502384,-291.572632,0.049172,0.000000
150.970001,-0.074844,-291.661591,-0.001643,0.001946,0.049432,-0.332924,-0.016960,0.494322,-291.661591,0.048539,0.000000
151.350006,-0.110588,-291.661591,-0.001664,0.001929,0.048990,-0.491920,-0.025060,0.489902,-291.661591,0.047906,0.000000
151.730011,-0.124367,-291.706085,-0.001681,0.001906,0.048418,-0.553211,-0.028182,0.484179,-291.706085,0.047273,0.000000
152.110001,-0.082664,-291.750549,-0.001716,0.001872,0.047541,-0.367710,-0.018732,0.475413,-291.750549,0.046640,0.000000
152.490005,-0.115433,-291.706085,-0.001725,0.001850,0.046996,-0.513470,-0.026157,0.469955,-291.706085,0.046007,0.000000
152.870010,-0.128838,-291.839508,-0.001776,0.001825,0.046345,-0.573098,-0.029195,0.463453,-291.839508,0.045373,0.000000
153.250000,-0.137772,-291.884003,-0.001785,0.001802,0.045772,-0.612839,-0.031219,0.457722,-291.884003,0.044740,0.000000
153.630005,-0.134796,-291.839508,-0.001828,0.001776,0.045114,-0.599603,-0.030545,0.451137,-291.839508,0.044108,0.000000
154.010010,-0.129951,-291.839508,-0.001841,0.001748,0.044394,-0.578053,-0.029447,0.443938,-291.839508,0.043474,0.000000
154.390015,-0.117668,-291.839508,-0.001876,0.001731,0.043968,-0.523414,-0.026664,0.439684,-291.839508,0.042841,0.000000
154.770004,-0.127350,-291.972961,-0.001888,0.001700,0.043171,-0.566480,-0.028858,0.431705,-291.972961,0.042208,0.000000
155.150009,-0.144104,-291.972961,-0.001919,0.001677,0.042598,-0.641007,-0.032654,0.425982,-291.972961,0.041575,0.000000
155.530014,-0.136284,-291.972961,-0.001957,0.001653,0.041974,-0.606221,-0.030882,0.419737,-291.972961,0.040942,0.000000
155.910004,-0.127724,-291.928467,-0.001975,0.001640,0.041654,-0.568143,-0.028943,0.416535,-291.928467,0.040309,0.000000
156.200012,-0.074844,-292.017456,-0.001996,0.001613,0.040968,-0.332924,-0.016960,0.409685,-292.017456,0.040899,0.000000