File: Data/compression 23/AutoNoHeating-12-23-reverse-1-5_09192024_183037.csv
Time (sec),S:Load (lbs),S:HL1 (DIM),S:LVDT (in),S:Position (in),Ch:Position (mm),Ch:Load (N),Ch:Stress (MPa),Ch:Strain (mm/mm),Ch:HL1 (DIM),Set Point (),Cycles ()
0.110000,-0.132935,-338.055237,-0.010580,-0.005871,-0.149111,-0.591322,-0.030123,-1.491112,-338.055237,-0.148894,0.000000
0.510000,-0.084900,-338.099701,-0.010576,-0.005810,-0.147576,-0.377654,-0.019239,-1.475761,-338.099701,-0.146952,0.000000
0.910000,-0.102768,-338.099701,-0.010468,-0.005571,-0.141505,-0.457135,-0.023288,-1.415051,-338.099701,-0.140291,0.000000
1.310000,-0.059578,-338.099701,-0.010218,-0.005312,-0.134914,-0.265016,-0.013501,-1.349141,-338.099701,-0.133631,0.000000
1.710000,-0.048409,-338.144196,-0.009951,-0.005051,-0.128306,-0.215332,-0.010970,-1.283064,-338.144196,-0.126954,0.000000
2.110000,-0.067398,-338.188660,-0.009675,-0.004785,-0.121542,-0.299802,-0.015273,-1.215421,-338.188660,-0.120293,0.000000
2.510000,-0.080429,-338.188660,-0.009412,-0.004520,-0.114803,-0.357766,-0.018225,-1.148034,-338.188660,-0.113632,0.000000
2.910000,-0.096443,-338.233154,-0.009153,-0.004258,-0.108144,-0.429001,-0.021854,-1.081435,-338.233154,-0.106972,0.000000
3.310000,-0.095322,-338.277618,-0.008877,-0.003987,-0.101275,-0.424012,-0.021600,-1.012747,-338.277618,-0.100312,0.000000
3.710000,-0.056969,-338.233154,-0.008606,-0.003734,-0.094849,-0.253409,-0.012909,-0.948487,-338.233154,-0.093635,0.000000
4.110000,-0.064415,-338.277618,-0.008343,-0.003471,-0.088171,-0.286532,-0.014597,-0.881706,-338.277618,-0.086974,0.000000
4.510000,-0.090485,-338.277618,-0.008063,-0.003209,-0.081502,-0.402496,-0.020504,-0.815017,-338.277618,-0.080314,0.000000
4.910000,-0.096443,-338.322113,-0.007804,-0.002946,-0.074824,-0.429001,-0.021854,-0.748243,-338.322113,-0.073653,0.000000
5.310000,-0.142990,-338.411072,-0.007519,-0.002686,-0.068233,-0.636052,-0.032402,-0.682333,-338.411072,-0.066993,0.000000
5.710000,-0.065163,-338.366608,-0.007248,-0.002416,-0.061374,-0.289858,-0.014766,-0.613736,-338.366608,-0.060315,0.000000
6.110000,-0.067398,-338.411072,-0.006980,-0.002159,-0.054826,-0.299802,-0.015273,-0.548265,-338.411072,-0.053655,0.000000
6.510000,-0.066650,-338.411072,-0.006735,-0.001896,-0.048166,-0.296476,-0.015103,-0.481658,-338.411072,-0.046995,0.000000
6.910000,-0.070000,-338.455566,-0.006463,-0.001636,-0.041557,-0.311374,-0.015862,-0.415574,-338.455566,-0.040335,0.000000
7.310000,-0.050636,-338.411072,-0.006204,-0.001374,-0.034906,-0.225241,-0.011474,-0.349058,-338.411072,-0.033658,0.000000
7.710001,-0.026810,-338.455566,-0.005937,-0.001112,-0.028254,-0.119255,-0.006075,-0.282542,-338.455566,-0.026997,0.000000
8.110001,-0.019730,-338.544525,-0.005665,-0.000851,-0.021612,-0.087762,-0.004471,-0.216118,-338.544525,-0.020336,0.000000
8.510000,-0.045799,-338.588989,-0.005389,-0.000588,-0.014943,-0.203725,-0.010378,-0.149428,-338.588989,-0.013676,0.000000
8.910001,-0.061066,-338.544525,-0.005122,-0.000324,-0.008239,-0.271634,-0.013838,-0.082390,-338.544525,-0.007016,0.000000
9.310000,-0.065910,-338.588989,-0.004855,-0.000059,-0.001492,-0.293184,-0.014935,-0.014920,-338.588989,-0.000338,0.000000
9.710000,-0.076332,-338.588989,-0.004570,0.000210,0.005342,-0.339542,-0.017297,0.053420,-338.588989,0.006322,0.000000
10.110001,-0.035370,-338.633484,-0.004324,0.000462,0.011725,-0.157333,-0.008015,0.117248,-338.633484,0.012982,0.000000
10.510000,0.063309,-338.633484,-0.004053,0.000725,0.018420,0.281611,0.014346,0.184196,-338.633484,0.019643,0.000000
10.910001,0.094589,-338.677948,-0.003980,-0.000005,-0.000130,0.420754,0.021434,-0.001302,-338.677948,0.000070,0.000000
11.310000,0.091606,-338.722443,-0.003992,-0.000005,-0.000130,0.407484,0.020758,-0.001302,-338.722443,0.000390,0.000000
11.710001,0.119904,-338.722443,-0.003984,-0.000005,-0.000130,0.533358,0.027171,-0.001302,-338.722443,0.001058,0.000000
12.110001,0.137039,-338.766937,-0.003971,0.000025,0.000633,0.609581,0.031054,0.006328,-338.766937,0.001726,0.000000
12.510000,0.179489,-338.811401,-0.003954,0.000057,0.001448,0.798408,0.040673,0.014481,-338.811401,0.002394,0.000000
12.910001,0.191772,-338.766937,-0.003919,0.000082,0.002073,0.853047,0.043456,0.020726,-338.766937,0.003061,0.000000
13.310000,0.212997,-338.811401,-0.003898,0.000106,0.002680,0.947460,0.048266,0.026797,-338.811401,0.003729,0.000000
13.710001,0.268486,-338.811401,-0.003854,0.000137,0.003468,1.194286,0.060840,0.034685,-338.811401,0.004388,0.000000
14.110001,0.280029,-338.855896,-0.003842,0.000160,0.004076,1.245633,0.063456,0.040756,-338.855896,0.005056,0.000000
14.510000,0.351151,-338.944855,-0.003824,0.000188,0.004778,1.561996,0.079572,0.047781,-338.944855,0.005724,0.000000
14.910001,0.342216,-338.944855,-0.003781,0.000213,0.005403,1.522255,0.077547,0.054026,-338.944855,0.006391,0.000000
15.310000,0.385406,-338.944855,-0.003777,0.000234,0.005932,1.714374,0.087334,0.059317,-338.944855,0.007059,0.000000
15.710001,0.444618,-339.033813,-0.003729,0.000262,0.006643,1.977761,0.100752,0.066432,-339.033813,0.007727,0.000000
16.110001,0.506058,-339.033813,-0.003708,0.000289,0.007337,2.251057,0.114674,0.073366,-339.033813,0.008395,0.000000
16.510000,0.593567,-339.033813,-0.003686,0.000317,0.008047,2.640317,0.134504,0.080474,-339.033813,0.009063,0.000000
16.910002,0.642715,-339.078278,-0.003660,0.000341,0.008672,2.858941,0.145641,0.086720,-339.078278,0.009730,0.000000
17.310001,0.759644,-339.078278,-0.003639,0.000367,0.009331,3.379063,0.172138,0.093313,-339.078278,0.010390,0.000000
17.710001,0.871353,-339.122772,-0.003613,0.000394,0.010008,3.875972,0.197451,0.100080,-339.122772,0.011057,0.000000
18.110001,1.038925,-339.122772,-0.003579,0.000425,0.010806,4.621370,0.235424,0.108059,-339.122772,0.011725,0.000000
18.510000,1.158081,-339.167267,-0.003544,0.000451,0.011456,5.151402,0.262425,0.114561,-339.167267,0.012393,0.000000
18.910002,1.260483,-339.167267,-0.003514,0.000474,0.012037,5.606907,0.285629,0.120367,-339.167267,0.013060,0.000000
19.310001,1.497688,-339.167267,-0.003479,0.000506,0.012852,6.662050,0.339381,0.128520,-339.167267,0.013728,0.000000
19.710001,1.690948,-339.256226,-0.003471,0.000533,0.013529,7.521715,0.383174,0.135287,-339.256226,0.014396,0.000000
20.110001,1.843994,-339.211731,-0.003445,0.000558,0.014162,8.202496,0.417855,0.141616,-339.211731,0.015064,0.000000
20.510000,2.040604,-339.256226,-0.003419,0.000582,0.014778,9.077059,0.462407,0.147777,-339.256226,0.015722,0.000000
20.910002,2.232376,-339.256226,-0.003389,0.000611,0.015523,9.930105,0.505864,0.155234,-339.256226,0.016391,0.000000
21.310001,2.423775,-339.345184,-0.003363,0.000634,0.016113,10.781488,0.549235,0.161131,-339.345184,0.017059,0.000000
21.710001,2.658745,-339.389648,-0.003341,0.000661,0.016781,11.826688,0.602480,0.167807,-339.389648,0.017726,0.000000
22.110001,2.849396,-339.389648,-0.003328,0.000685,0.017388,12.674746,0.645682,0.173878,-339.389648,0.018394,0.000000
22.510000,3.041916,-339.345184,-0.003303,0.000711,0.018047,13.531117,0.689308,0.180471,-339.345184,0.019061,0.000000
22.910002,3.181557,-339.434143,-0.003268,0.000733,0.018619,14.152271,0.720951,0.186194,-339.434143,0.019729,0.000000
23.310001,3.590790,-339.478607,-0.003225,0.000768,0.019495,15.972631,0.813685,0.194952,-339.478607,0.020397,0.000000
23.710001,3.795967,-339.434143,-0.003212,0.000792,0.020120,16.885305,0.860178,0.201197,-339.434143,0.021056,0.000000
24.110001,4.033539,-339.523102,-0.003173,0.000825,0.020943,17.942078,0.914013,0.209433,-339.523102,0.021724,0.000000
24.510000,4.172440,-339.567566,-0.003152,0.000848,0.021550,18.559938,0.945488,0.215504,-339.567566,0.022391,0.000000
24.910002,4.430489,-339.567566,-0.003126,0.000874,0.022210,19.707798,1.003963,0.222098,-339.567566,0.023059,0.000000
25.310001,4.613701,-339.567566,-0.003109,0.000896,0.022756,20.522766,1.045480,0.227563,-339.567566,0.023728,0.000000
25.710001,4.706795,-339.567566,-0.003091,0.000915,0.023242,20.936869,1.066575,0.232415,-339.567566,0.024395,0.000000
26.110001,5.050117,-339.656555,-0.003048,0.000952,0.024178,22.464045,1.144373,0.241779,-339.656555,0.025063,0.000000
26.510002,5.197205,-339.612061,-0.003014,0.000975,0.024777,23.118320,1.177703,0.247767,-339.612061,0.025730,0.000000
26.910002,5.474998,-339.701019,-0.002975,0.001006,0.025548,24.354010,1.240652,0.255480,-339.701019,0.026390,0.000000
27.310001,5.405365,-339.701019,-0.002966,0.001021,0.025930,24.044264,1.224873,0.259303,-339.701019,0.027057,0.000000
27.710001,5.752785,-339.701019,-0.002940,0.001052,0.026728,25.589664,1.303600,0.267282,-339.701019,0.027725,0.000000
28.110001,5.877159,-339.745514,-0.002919,0.001079,0.027396,26.142910,1.331783,0.273958,-339.745514,0.028393,0.000000
28.510002,6.129997,-339.745514,-0.002884,0.001107,0.028116,27.267590,1.389077,0.281157,-339.745514,0.029060,0.000000
28.910002,6.409279,-339.834473,-0.002850,0.001134,0.028809,28.509897,1.452363,0.288091,-339.834473,0.029728,0.000000
29.310001,6.316559,-339.834473,-0.002833,0.001153,0.029286,28.097458,1.431353,0.292860,-339.834473,0.030396,0.000000
29.710001,6.804741,-339.878937,-0.002790,0.001188,0.030171,30.268999,1.541976,0.301709,-339.878937,0.031064,0.000000
30.110001,6.800270,-339.923431,-0.002768,0.001210,0.030734,30.249111,1.540963,0.307341,-339.923431,0.031732,0.000000
30.510002,6.875862,-339.878937,-0.002742,0.001235,0.031376,30.585361,1.558093,0.313760,-339.878937,0.032391,0.000000
30.910002,7.183815,-339.923431,-0.002721,0.001264,0.032105,31.955206,1.627876,0.321050,-339.923431,0.033059,0.000000
31.310001,7.139870,-339.967896,-0.002677,0.001285,0.032642,31.759727,1.617918,0.326424,-339.967896,0.033726,0.000000
31.710001,7.571823,-340.012390,-0.002665,0.001316,0.033423,33.681152,1.715800,0.334229,-340.012390,0.034394,0.000000
32.110001,7.552086,-340.012390,-0.002626,0.001340,0.034030,33.593357,1.711327,0.340300,-340.012390,0.035062,0.000000
32.510002,7.739761,-340.012390,-0.002604,0.001367,0.034715,34.428177,1.753855,0.347151,-340.012390,0.035729,0.000000
32.910000,7.879028,-340.056885,-0.002570,0.001392,0.035357,35.047668,1.785413,0.353570,-340.056885,0.036397,0.000000
33.310001,7.782959,-340.056885,-0.002552,0.001412,0.035860,34.620331,1.763644,0.358596,-340.056885,0.037065,0.000000
33.710003,8.399979,-340.145844,-0.002522,0.001447,0.036762,37.364971,1.903462,0.367619,-340.145844,0.037724,0.000000
34.110001,8.366096,-340.145844,-0.002471,0.001472,0.037377,37.214256,1.895784,0.373774,-340.145844,0.038392,0.000000
34.510002,8.532547,-340.190308,-0.002453,0.001499,0.038072,37.954666,1.933503,0.380715,-340.190308,0.039060,0.000000
34.910000,8.852417,-340.190308,-0.002427,0.001528,0.038808,39.377518,2.005986,0.388080,-340.190308,0.039728,0.000000
35.310001,8.914230,-340.234802,-0.002410,0.001552,0.039433,39.652477,2.019994,0.394325,-340.234802,0.040395,0.000000
35.710003,9.030777,-340.234802,-0.002371,0.001578,0.040092,40.170902,2.046403,0.400919,-340.234802,0.041063,0.000000
36.110001,9.154037,-340.279266,-0.002350,0.001604,0.040734,40.719193,2.074335,0.407338,-340.279266,0.041731,0.000000
36.510002,9.130203,-340.279266,-0.002320,0.001623,0.041236,40.613171,2.068934,0.412364,-340.279266,0.042398,0.000000
36.910000,9.459755,-340.368225,-0.002298,0.001653,0.041974,42.079090,2.143611,0.419737,-340.368225,0.043058,0.000000
37.310001,9.717064,-340.323761,-0.002264,0.001679,0.042641,43.223660,2.201918,0.426414,-340.323761,0.043725,0.000000
37.710003,10.021660,-340.412720,-0.002220,0.001710,0.043422,44.578571,2.270941,0.434218,-340.412720,0.044393,0.000000
38.110001,10.016823,-340.457214,-0.002199,0.001735,0.044081,44.557053,2.269845,0.440812,-340.457214,0.045061,0.000000
38.510002,10.111778,-340.457214,-0.002164,0.001757,0.044636,44.979435,2.291362,0.446360,-340.457214,0.045729,0.000000
38.910004,10.503510,-340.501678,-0.002134,0.001788,0.045416,46.721943,2.380129,0.454165,-340.501678,0.046397,0.000000
39.310001,10.558250,-340.457214,-0.002117,0.001812,0.046032,46.965443,2.392534,0.460319,-340.457214,0.047064,0.000000
39.710003,10.697517,-340.457214,-0.002074,0.001837,0.046656,47.584934,2.424092,0.466564,-340.457214,0.047732,0.000000
40.110001,11.075851,-340.501678,-0.002057,0.001869,0.047481,49.267849,2.509824,0.474808,-340.501678,0.048391,0.000000
40.510002,11.421036,-340.590637,-0.002031,0.001899,0.048235,50.803303,2.588044,0.482347,-340.590637,0.049059,0.000000
40.910004,11.355499,-340.590637,-0.001988,0.001920,0.048764,50.511784,2.573193,0.487638,-340.590637,0.049727,0.000000
41.310001,11.740906,-340.635132,-0.001970,0.001950,0.049536,52.226158,2.660527,0.495359,-340.635132,0.050394,0.000000
41.710003,11.892464,-340.679596,-0.001932,0.001974,0.050143,52.900322,2.694871,0.501430,-340.679596,0.051062,0.000000
42.110001,12.016464,-340.635132,-0.001910,0.002001,0.050819,53.451904,2.722970,0.508190,-340.635132,0.051730,0.000000
42.510002,12.328880,-340.635132,-0.001867,0.002026,0.051453,54.841599,2.793764,0.514526,-340.635132,0.052397,0.000000
42.910004,12.290527,-340.679596,-0.001854,0.002047,0.051982,54.670998,2.785073,0.519817,-340.679596,0.053066,0.000000
43.310001,12.768654,-340.679596,-0.001811,0.002075,0.052701,56.797810,2.893418,0.527009,-340.679596,0.053733,0.000000
43.710003,12.950371,-340.768555,-0.001785,0.002099,0.053325,57.606125,2.934596,0.533254,-340.768555,0.054392,0.000000
44.110001,13.350304,-340.768555,-0.001750,0.002128,0.054054,59.385117,3.025222,0.540544,-340.768555,0.055060,0.000000
44.510002,13.804222,-340.813049,-0.001733,0.002158,0.054817,61.404247,3.128081,0.548174,-340.813049,0.055728,0.000000
44.910004,13.620644,-340.813049,-0.001699,0.002177,0.055285,60.587650,3.086482,0.552852,-340.813049,0.056396,0.000000
45.310001,14.632378,-340.857513,-0.001681,0.002217,0.056300,65.088066,3.315744,0.563003,-340.857513,0.057063,0.000000
45.710003,14.391823,-340.946503,-0.001647,0.002238,0.056855,64.018028,3.261234,0.568552,-340.946503,0.057731,0.000000
46.110001,14.489014,-340.857513,-0.001591,0.002260,0.057402,64.450348,3.283257,0.574017,-340.857513,0.058399,0.000000
46.510002,14.557159,-340.857513,-0.001574,0.002279,0.057887,64.753479,3.298699,0.578869,-340.857513,0.059066,0.000000
46.910004,15.436707,-340.902008,-0.001561,0.002312,0.058729,68.665901,3.498008,0.587287,-340.902008,0.059726,0.000000
47.310001,16.222412,-340.990967,-0.001518,0.002346,0.059595,72.160896,3.676051,0.595954,-340.990967,0.060393,0.000000
47.710003,16.125221,-340.946503,-0.001487,0.002368,0.060159,71.728569,3.654027,0.601594,-340.946503,0.061061,0.000000
48.110001,16.737770,-340.990967,-0.001470,0.002398,0.060897,74.453323,3.792833,0.608967,-340.990967,0.061729,0.000000
48.510002,16.778732,-341.035461,-0.001436,0.002418,0.061426,74.635529,3.802115,0.614258,-341.035461,0.062397,0.000000
48.910004,17.065460,-340.990967,-0.001414,0.002442,0.062024,75.910957,3.867089,0.620238,-340.990967,0.063065,0.000000
49.310001,17.695518,-341.079926,-0.001362,0.002470,0.062744,78.713600,4.009861,0.627437,-341.079926,0.063732,0.000000
49.710003,18.055595,-341.124420,-0.001367,0.002497,0.063420,80.315300,4.091456,0.634205,-341.124420,0.064400,0.000000
50.110001,18.579529,-341.079926,-0.001337,0.002526,0.064166,82.645874,4.210181,0.641661,-341.079926,0.065059,0.000000
50.510002,18.589584,-341.124420,-0.001298,0.002543,0.064582,82.690598,4.212460,0.645824,-341.124420,0.065727,0.000000
50.910004,19.610626,-341.124420,-0.001276,0.002576,0.065441,87.232422,4.443831,0.654408,-341.124420,0.066395,0.000000
51.310001,19.894745,-341.213379,-0.001237,0.002599,0.066022,88.496246,4.508214,0.660222,-341.213379,0.067062,0.000000
51.710003,20.258179,-341.168884,-0.001216,0.002627,0.066716,90.112877,4.590569,0.667156,-341.168884,0.067730,0.000000
52.110001,20.989151,-341.257843,-0.001190,0.002654,0.067418,93.364410,4.756210,0.674181,-341.257843,0.068398,0.000000
52.510002,21.499298,-341.257843,-0.001177,0.002679,0.068051,95.633652,4.871810,0.680509,-341.257843,0.069066,0.000000
52.910004,22.004608,-341.257843,-0.001130,0.002704,0.068675,97.881386,4.986315,0.686754,-341.257843,0.069734,0.000000
53.310001,22.566521,-341.346832,-0.001125,0.002729,0.069317,100.380898,5.113647,0.693173,-341.346832,0.070393,0.000000
53.710003,23.300468,-341.302338,-0.001087,0.002758,0.070046,103.645660,5.279962,0.700455,-341.302338,0.071061,0.000000
54.110004,23.946533,-341.346832,-0.001074,0.002783,0.070687,106.519501,5.426362,0.706875,-341.346832,0.071728,0.000000
54.510002,24.472694,-341.391296,-0.001035,0.002807,0.071295,108.859985,5.545592,0.712946,-341.391296,0.072396,0.000000
54.910004,25.389473,-341.435791,-0.001030,0.002836,0.072023,112.938019,5.753337,0.720228,-341.435791,0.073064,0.000000
55.310001,26.155441,-341.391296,-0.000983,0.002865,0.072777,116.345215,5.926908,0.727775,-341.391296,0.073731,0.000000
55.710003,26.801140,-341.435791,-0.000970,0.002892,0.073454,119.217422,6.073225,0.734542,-341.435791,0.074399,0.000000
56.110004,27.699303,-341.480255,-0.000944,0.002919,0.074139,123.212654,6.276752,0.741393,-341.480255,0.075067,0.000000
56.510002,28.161789,-341.480255,-0.000923,0.002940,0.074677,125.269890,6.381552,0.746767,-341.480255,0.075735,0.000000
56.910004,28.935204,-341.435791,-0.000910,0.002967,0.075353,128.710220,6.556811,0.753535,-341.435791,0.076394,0.000000
57.310001,30.218025,-341.480255,-0.000871,0.002995,0.076082,134.416489,6.847502,0.760817,-341.480255,0.077062,0.000000
57.710003,30.587051,-341.569214,-0.000862,0.003017,0.076637,136.057999,6.931125,0.766366,-341.569214,0.077730,0.000000
58.110004,31.479256,-341.569214,-0.000849,0.003041,0.077235,140.026718,7.133301,0.772353,-341.569214,0.078397,0.000000
58.510002,32.620575,-341.613708,-0.000819,0.003069,0.077946,145.103561,7.391928,0.779461,-341.613708,0.079065,0.000000
58.910004,33.924622,-341.613708,-0.000806,0.003095,0.078623,150.904251,7.687429,0.786229,-341.613708,0.079733,0.000000
59.310001,35.017540,-341.613708,-0.000785,0.003122,0.079291,155.765793,7.935088,0.792905,-341.613708,0.080400,0.000000
59.710003,35.634560,-341.658173,-0.000772,0.003144,0.079845,158.510437,8.074906,0.798454,-341.658173,0.081068,0.000000
60.110004,37.234642,-341.702667,-0.000746,0.003175,0.080643,165.627960,8.437490,0.806432,-341.702667,0.081727,0.000000
60.510002,38.472038,-341.702667,-0.000733,0.003202,0.081337,171.132172,8.717889,0.813374,-341.702667,0.082395,0.000000
60.910004,40.367409,-341.747162,-0.000716,0.003235,0.082169,179.563202,9.147386,0.821693,-341.747162,0.083063,0.000000
61.310001,41.085716,-341.791626,-0.000681,0.003257,0.082733,182.758392,9.310156,0.827333,-341.791626,0.083730,0.000000
61.710003,42.378227,-341.791626,-0.000677,0.003284,0.083401,188.507767,9.603044,0.834009,-341.791626,0.084399,0.000000
62.110004,44.033791,-341.791626,-0.000673,0.003314,0.084164,195.872086,9.978199,0.841640,-341.791626,0.085066,0.000000
62.510002,45.112556,-341.747162,-0.000642,0.003337,0.084771,200.670670,10.222651,0.847710,-341.747162,0.085734,0.000000
62.910004,46.411392,-341.836121,-0.000621,0.003365,0.085465,206.448181,10.516973,0.854652,-341.836121,0.086402,0.000000
63.310001,47.990623,-341.880585,-0.000617,0.003389,0.086090,213.472961,10.874830,0.860897,-341.880585,0.087061,0.000000
63.710003,50.004036,-341.925079,-0.000599,0.003420,0.086878,222.429062,11.331077,0.868785,-341.925079,0.087729,0.000000
64.110001,51.111847,-341.836121,-0.000582,0.003442,0.087425,227.356857,11.582109,0.874250,-341.836121,0.088396,0.000000
64.510002,52.484787,-341.969543,-0.000573,0.003465,0.088023,233.463989,11.893222,0.880230,-341.969543,0.089064,0.000000
64.910004,53.883041,-341.925079,-0.000560,0.003489,0.088622,239.683746,12.210072,0.886218,-341.925079,0.089732,0.000000
65.310005,55.639153,-341.969543,-0.000556,0.003517,0.089324,247.495316,12.608012,0.893243,-341.969543,0.090399,0.000000
65.710007,57.483887,-342.014038,-0.000548,0.003545,0.090035,255.701096,13.026034,0.900351,-342.014038,0.091068,0.000000
66.110001,59.461929,-342.014038,-0.000530,0.003571,0.090694,264.499878,13.474266,0.906944,-342.014038,0.091735,0.000000
66.510002,62.033157,-342.058502,-0.000522,0.003603,0.091518,275.937256,14.056914,0.915180,-342.058502,0.092394,0.000000
66.910004,63.980301,-342.058502,-0.000513,0.003630,0.092203,284.598602,14.498144,0.922031,-342.058502,0.093062,0.000000
67.310005,65.221405,-342.058502,-0.000487,0.003654,0.092802,290.119293,14.779382,0.928018,-342.058502,0.093730,0.000000
67.710007,66.297943,-342.058502,-0.000483,0.003659,0.092940,294.907990,15.023329,0.929404,-342.058502,0.016322,0.000000
68.110001,65.310043,-342.191956,-0.000483,0.003658,0.092915,290.513580,14.799467,0.929146,-342.191956,294.500519,0.000000
68.510002,64.621521,-342.147461,-0.000479,0.003658,0.092923,287.450867,14.643446,0.929230,-342.147461,294.500519,0.000000
68.910004,66.111008,-342.236450,-0.000453,0.003479,0.088361,294.076447,14.980968,0.883614,-342.236450,294.500519,0.000000
69.310005,65.538300,-342.191956,-0.000453,0.003548,0.090113,291.528931,14.851191,0.901130,-342.191956,294.500519,0.000000
69.710007,65.235931,-342.191956,-0.000453,0.003658,0.092923,290.183929,14.782673,0.929230,-342.191956,294.500519,0.000000
70.110001,65.289932,-342.280914,-0.000444,0.003676,0.093382,290.424133,14.794909,0.933824,-342.280914,294.500519,0.000000
70.510002,65.132782,-342.325409,-0.000448,0.003683,0.093539,289.725098,14.759299,0.935391,-342.325409,294.500519,0.000000
70.910004,65.300354,-342.369873,-0.000461,0.003685,0.093591,290.470490,14.797272,0.935906,-342.369873,294.500519,0.000000
71.310005,65.259018,-342.325409,-0.000435,0.003687,0.093643,290.286621,14.787905,0.936428,-342.325409,294.500519,0.000000
71.710007,65.508881,-342.369873,-0.000440,0.003692,0.093773,291.398041,14.844524,0.937730,-342.369873,294.500519,0.000000
72.110001,65.336105,-342.369873,-0.000453,0.003692,0.093773,290.629517,14.805373,0.937730,-342.369873,294.500519,0.000000
72.510002,65.216568,-342.414368,-0.000448,0.003693,0.093799,290.097778,14.778286,0.937988,-342.414368,294.500519,0.000000
72.910004,65.220673,-342.414368,-0.000444,0.003695,0.093851,290.116028,14.779216,0.938510,-342.414368,294.500519,0.000000
73.310005,65.216568,-342.458832,-0.000435,0.003698,0.093921,290.097778,14.778286,0.939207,-342.458832,294.500519,0.000000
73.710007,65.257538,-342.503326,-0.000448,0.003698,0.093938,290.280029,14.787569,0.939381,-342.503326,294.500519,0.000000
74.110001,65.234070,-342.458832,-0.000440,0.003699,0.093964,290.175629,14.782252,0.939638,-342.458832,294.500519,0.000000
74.510002,65.228119,-342.503326,-0.000427,0.003701,0.093999,290.149170,14.780903,0.939986,-342.503326,294.500519,0.000000
74.910004,65.207642,-342.592285,-0.000440,0.003702,0.094042,290.058075,14.776262,0.940418,-342.592285,294.500519,0.000000
75.310005,65.289185,-342.547791,-0.000427,0.003704,0.094077,290.420807,14.794741,0.940766,-342.547791,294.500519,0.000000
75.710007,65.212479,-342.636780,-0.000440,0.003704,0.094077,290.079590,14.777359,0.940766,-342.636780,294.500519,0.000000
76.110001,65.178589,-342.681244,-0.000427,0.003705,0.094111,289.928833,14.769679,0.941114,-342.681244,294.500519,0.000000
76.510002,65.254547,-342.681244,-0.000423,0.003709,0.094198,290.266724,14.786892,0.941977,-342.681244,294.500519,0.000000
76.910004,65.339081,-342.681244,-0.000427,0.003709,0.094198,290.642761,14.806047,0.941977,-342.681244,294.500519,0.000000
77.310005,65.280991,-342.725739,-0.000448,0.003709,0.094198,290.384338,14.792884,0.941977,-342.725739,294.500519,0.000000
77.710007,65.232590,-342.681244,-0.000427,0.003709,0.094207,290.169037,14.781916,0.942068,-342.681244,294.500519,0.000000
78.110001,65.241516,-342.725739,-0.000431,0.003710,0.094233,290.208771,14.783938,0.942325,-342.725739,294.500519,0.000000
78.510002,65.197586,-342.814697,-0.000427,0.003711,0.094250,290.013336,14.773984,0.942499,-342.814697,294.500519,0.000000
78.910004,65.157730,-342.770203,-0.000431,0.003711,0.094250,289.836060,14.764953,0.942499,-342.770203,294.500519,0.000000
79.310005,65.110443,-342.859161,-0.000427,0.003711,0.094259,289.625702,14.754238,0.942590,-342.859161,294.500519,0.000000
79.710007,65.162201,-342.859161,-0.000431,0.003713,0.094302,289.855957,14.765966,0.943022,-342.859161,294.500519,0.000000
80.110001,65.133163,-342.859161,-0.000423,0.003713,0.094302,289.726776,14.759386,0.943022,-342.859161,294.500519,0.000000
80.510002,65.087738,-342.948120,-0.000418,0.003713,0.094302,289.524719,14.749092,0.943022,-342.948120,294.500519,0.000000
80.910004,65.046768,-342.948120,-0.000431,0.003713,0.094302,289.342468,14.739808,0.943022,-342.948120,294.500519,0.000000
81.310005,64.998367,-342.992615,-0.000418,0.003718,0.094432,289.127167,14.728841,0.944324,-342.992615,294.500519,0.000000
81.710007,65.658203,-342.992615,-0.000418,0.003721,0.094501,292.062286,14.878362,0.945013,-342.992615,294.500519,0.000000
82.110001,65.634750,-343.037109,-0.000418,0.003721,0.094501,291.957947,14.873047,0.945013,-343.037109,294.500519,0.000000
82.510002,65.596390,-343.037109,-0.000418,0.003721,0.094501,291.787323,14.864354,0.945013,-343.037109,294.500519,0.000000
82.910004,65.573303,-343.081573,-0.000431,0.003721,0.094501,291.684631,14.859122,0.945013,-343.081573,294.500519,0.000000
83.310005,65.536804,-343.081573,-0.000435,0.003721,0.094501,291.522278,14.850852,0.945013,-343.081573,294.500519,0.000000
83.710007,65.480591,-343.081573,-0.000423,0.003721,0.094501,291.272217,14.838114,0.945013,-343.081573,294.500519,0.000000
84.110001,65.428818,-343.170532,-0.000427,0.003721,0.094501,291.041931,14.826382,0.945013,-343.170532,294.500519,0.000000
84.510002,65.370361,-343.126068,-0.000410,0.003721,0.094501,290.781891,14.813136,0.945013,-343.126068,294.500519,0.000000
84.910004,65.318604,-343.215027,-0.000410,0.003721,0.094501,290.551666,14.801407,0.945013,-343.215027,294.500519,0.000000
85.310005,65.287323,-343.215027,-0.000423,0.003721,0.094501,290.412506,14.794319,0.945013,-343.215027,294.500519,0.000000
85.710007,65.254929,-343.259491,-0.000405,0.003721,0.094510,290.268433,14.786978,0.945103,-343.259491,294.500519,0.000000
86.110001,65.211731,-343.303986,-0.000423,0.003721,0.094510,290.076263,14.777190,0.945103,-343.303986,294.500519,0.000000
86.510002,65.180817,-343.303986,-0.000414,0.003721,0.094510,289.938751,14.770185,0.945103,-343.303986,294.500519,0.000000
86.910004,65.123474,-343.303986,-0.000418,0.003721,0.094510,289.683685,14.757190,0.945103,-343.303986,294.500519,0.000000
87.310005,65.075821,-343.303986,-0.000418,0.003721,0.094510,289.471710,14.746392,0.945103,-343.303986,294.500519,0.000000
87.710007,65.060181,-343.348450,-0.000414,0.003721,0.094510,289.402130,14.742847,0.945103,-343.348450,294.500519,0.000000
88.110001,65.009537,-343.392944,-0.000410,0.003721,0.094510,289.176849,14.731372,0.945103,-343.392944,294.500519,0.000000
88.510002,64.987183,-343.392944,-0.000418,0.003721,0.094519,289.077423,14.726306,0.945187,-343.392944,294.500519,0.000000
88.910004,65.225876,-343.437408,-0.000418,0.003738,0.094952,290.139191,14.780395,0.949524,-343.437408,294.500519,0.000000
89.310005,66.359756,-343.481903,-0.000418,0.003727,0.094658,295.182953,15.037336,0.946580,-343.481903,294.500519,0.000000
89.710007,66.319534,-343.526398,-0.000414,0.003727,0.094658,295.004028,15.028221,0.946580,-343.526398,294.500519,0.000000
90.110001,66.274475,-343.437408,-0.000410,0.003727,0.094658,294.803589,15.018011,0.946580,-343.437408,294.500519,0.000000
90.510002,66.224213,-343.526398,-0.000414,0.003727,0.094658,294.580017,15.006621,0.946580,-343.526398,294.500519,0.000000
90.910004,66.179153,-343.481903,-0.000414,0.003727,0.094658,294.379578,14.996410,0.946580,-343.481903,294.500519,0.000000
91.310005,66.139679,-343.615356,-0.000414,0.003727,0.094658,294.203979,14.987466,0.946580,-343.615356,294.500519,0.000000
91.710007,66.093140,-343.570862,-0.000410,0.003727,0.094658,293.996979,14.976919,0.946580,-343.570862,294.500519,0.000000
92.110001,66.064835,-343.615356,-0.000414,0.003727,0.094658,293.871063,14.970506,0.946580,-343.615356,294.500519,0.000000
92.510002,66.014938,-343.659821,-0.000414,0.003727,0.094658,293.649109,14.959199,0.946580,-343.659821,294.500519,0.000000
92.910004,65.988876,-343.704315,-0.000418,0.003727,0.094658,293.533173,14.953293,0.946580,-343.704315,294.500519,0.000000
93.310005,65.895035,-343.748779,-0.000405,0.003727,0.094658,293.115753,14.932029,0.946580,-343.748779,294.500519,0.000000
93.710007,65.874924,-343.748779,-0.000414,0.003727,0.094658,293.026306,14.927471,0.946580,-343.748779,294.500519,0.000000
94.110008,65.860031,-343.704315,-0.000414,0.003727,0.094658,292.960052,14.924097,0.946580,-343.704315,294.500519,0.000000
94.510002,65.872314,-343.748779,-0.000405,0.003727,0.094658,293.014679,14.926880,0.946580,-343.748779,294.500519,0.000000
94.910004,65.841782,-343.748779,-0.000427,0.003727,0.094658,292.878876,14.919961,0.946580,-343.748779,294.500519,0.000000
95.310005,65.765076,-343.837738,-0.000410,0.003727,0.094658,292.537659,14.902579,0.946580,-343.837738,294.500519,0.000000
95.710007,65.763580,-343.837738,-0.000427,0.003727,0.094658,292.531006,14.902241,0.946580,-343.837738,294.500519,0.000000
96.110008,65.737152,-343.837738,-0.000418,0.003727,0.094658,292.413452,14.896252,0.946580,-343.837738,294.500519,0.000000
96.510002,65.680923,-343.837738,-0.000410,0.003727,0.094658,292.163330,14.883510,0.946580,-343.837738,294.500519,0.000000
96.910004,65.651123,-343.926727,-0.000414,0.003727,0.094658,292.030792,14.876758,0.946580,-343.926727,294.500519,0.000000
97.310005,65.611282,-343.882233,-0.000423,0.003727,0.094658,291.853546,14.867729,0.946580,-343.882233,294.500519,0.000000
97.710007,65.597885,-343.926727,-0.000414,0.003727,0.094658,291.793976,14.864693,0.946580,-343.926727,294.500519,0.000000
98.110008,65.567352,-343.971191,-0.000414,0.003727,0.094658,291.658142,14.857774,0.946580,-343.971191,294.500519,0.000000
98.510002,65.539413,-344.015686,-0.000410,0.003727,0.094658,291.533875,14.851443,0.946580,-344.015686,294.500519,0.000000
98.910004,65.514847,-344.015686,-0.000414,0.003727,0.094658,291.424591,14.845876,0.946580,-344.015686,294.500519,0.000000
99.310005,65.475372,-343.971191,-0.000405,0.003727,0.094658,291.248993,14.836931,0.946580,-343.971191,294.500519,0.000000
99.710007,65.453400,-344.015686,-0.000418,0.003727,0.094658,291.151276,14.831953,0.946580,-344.015686,294.500519,0.000000
100.110008,65.416168,-344.104645,-0.000405,0.003727,0.094658,290.985657,14.823516,0.946580,-344.104645,294.500519,0.000000
100.510002,65.372223,-344.015686,-0.000418,0.003727,0.094658,290.790161,14.813558,0.946580,-344.015686,294.500519,0.000000
100.910004,65.345047,-344.149109,-0.000414,0.003727,0.094658,290.669281,14.807399,0.946580,-344.149109,294.500519,0.000000
101.310005,65.331268,-344.149109,-0.000414,0.003727,0.094658,290.608002,14.804276,0.946580,-344.149109,294.500519,0.000000
101.710007,65.308182,-344.193604,-0.000410,0.003727,0.094658,290.505310,14.799046,0.946580,-344.193604,294.500519,0.000000
102.110008,65.279495,-344.193604,-0.000414,0.003727,0.094658,290.377686,14.792545,0.946580,-344.193604,294.500519,0.000000
102.510002,65.248962,-344.238068,-0.000418,0.003727,0.094666,290.241882,14.785626,0.946663,-344.238068,294.500519,0.000000
102.910004,65.245621,-344.282562,-0.000414,0.003727,0.094675,290.227020,14.784869,0.946746,-344.282562,294.500519,0.000000
103.310005,65.205780,-344.238068,-0.000410,0.003727,0.094675,290.049805,14.775841,0.946746,-344.238068,294.500519,0.000000
103.710007,65.186035,-344.282562,-0.000414,0.003727,0.094675,289.961975,14.771367,0.946746,-344.282562,294.500519,0.000000
104.110008,65.140610,-344.282562,-0.000405,0.003727,0.094675,289.759918,14.761073,0.946746,-344.282562,294.500519,0.000000
104.510002,65.117523,-344.282562,-0.000427,0.003727,0.094675,289.657196,14.755842,0.946746,-344.282562,294.500519,0.000000
104.910004,65.089600,-344.371521,-0.000414,0.003727,0.094675,289.532990,14.749514,0.946746,-344.371521,294.500519,0.000000
105.310005,65.069107,-344.327057,-0.000405,0.003727,0.094675,289.441833,14.744871,0.946746,-344.327057,294.500519,0.000000
105.710007,66.143402,-344.371521,-0.000401,0.003739,0.094962,294.220551,14.988309,0.949615,-344.371521,294.500519,0.000000
106.110008,66.090530,-344.416016,-0.000410,0.003738,0.094952,293.985352,14.976328,0.949524,-344.416016,294.500519,0.000000
106.510002,66.070053,-344.460480,-0.000401,0.003738,0.094944,293.894287,14.971688,0.949441,-344.460480,294.500519,0.000000
106.910004,66.045837,-344.504974,-0.000414,0.003738,0.094944,293.786560,14.966201,0.949441,-344.504974,294.500519,0.000000
107.310005,66.025742,-344.504974,-0.000414,0.003738,0.094944,293.697174,14.961647,0.949441,-344.504974,294.500519,0.000000
107.710007,66.019028,-344.549438,-0.000423,0.003738,0.094944,293.667297,14.960125,0.949441,-344.549438,294.500519,0.000000
108.110008,65.975098,-344.504974,-0.000401,0.003738,0.094944,293.471893,14.950171,0.949441,-344.504974,294.500519,0.000000
108.510002,65.968018,-344.593933,-0.000405,0.003738,0.094944,293.440399,14.948566,0.949441,-344.593933,294.500519,0.000000
108.910004,65.937485,-344.549438,-0.000405,0.003738,0.094944,293.304596,14.941648,0.949441,-344.549438,294.500519,0.000000
109.310005,65.895782,-344.638397,-0.000401,0.003738,0.094944,293.119080,14.932199,0.949441,-344.638397,294.500519,0.000000
109.710007,65.864868,-344.638397,-0.000401,0.003738,0.094944,292.981567,14.925193,0.949441,-344.638397,294.500519,0.000000
110.110008,65.877899,-344.638397,-0.000414,0.003738,0.094944,293.039520,14.928145,0.949441,-344.638397,294.500519,0.000000
110.510002,65.874924,-344.727356,-0.000418,0.003738,0.094944,293.026306,14.927471,0.949441,-344.727356,294.500519,0.000000
110.910004,65.866730,-344.682892,-0.000423,0.003738,0.094944,292.989838,14.925614,0.949441,-344.682892,294.500519,0.000000
111.310005,65.834335,-344.638397,-0.000405,0.003738,0.094944,292.845764,14.918274,0.949441,-344.638397,294.500519,0.000000
111.710007,65.844757,-344.771851,-0.000414,0.003738,0.094944,292.892120,14.920635,0.949441,-344.771851,294.500519,0.000000
112.110008,65.770294,-344.771851,-0.000405,0.003738,0.094944,292.560883,14.903762,0.949441,-344.771851,294.500519,0.000000
112.510002,65.787415,-344.771851,-0.000397,0.003738,0.094944,292.637024,14.907641,0.949441,-344.771851,294.500519,0.000000
112.910004,65.767685,-344.816345,-0.000410,0.003738,0.094944,292.549286,14.903171,0.949441,-344.816345,294.500519,0.000000
113.310005,65.759125,-344.816345,-0.000397,0.003738,0.094944,292.511200,14.901231,0.949441,-344.816345,294.500519,0.000000
113.710007,65.727463,-344.860809,-0.000410,0.003738,0.094944,292.370361,14.894056,0.949441,-344.860809,294.500519,0.000000
114.110008,65.680923,-344.860809,-0.000418,0.003738,0.094944,292.163330,14.883510,0.949441,-344.860809,294.500519,0.000000
114.510002,65.663422,-344.860809,-0.000414,0.003738,0.094944,292.085480,14.879544,0.949441,-344.860809,294.500519,0.000000
114.910004,65.654480,-344.949768,-0.000418,0.003738,0.094944,292.045715,14.877518,0.949441,-344.949768,294.500519,0.000000
115.310005,65.631393,-345.038727,-0.000401,0.003738,0.094944,291.943024,14.872286,0.949441,-345.038727,294.500519,0.000000
115.710007,65.601974,-344.949768,-0.000410,0.003738,0.094944,291.812164,14.865620,0.949441,-344.949768,294.500519,0.000000
116.110008,65.583725,-345.038727,-0.000397,0.003738,0.094944,291.730988,14.861485,0.949441,-345.038727,294.500519,0.000000
116.510002,65.572556,-344.994263,-0.000401,0.003738,0.094952,291.681305,14.858953,0.949524,-344.994263,294.500519,0.000000
116.910004,65.564743,-345.083221,-0.000401,0.003738,0.094952,291.646545,14.857183,0.949524,-345.083221,294.500519,0.000000
117.310005,65.568085,-345.038727,-0.000410,0.003738,0.094952,291.661407,14.857941,0.949524,-345.038727,294.500519,0.000000
117.710007,65.539047,-345.083221,-0.000414,0.003738,0.094952,291.532257,14.851360,0.949524,-345.083221,294.500519,0.000000
118.110008,65.536438,-345.127686,-0.000388,0.003738,0.094952,291.520630,14.850769,0.949524,-345.127686,294.500519,0.000000
118.510002,65.504791,-345.127686,-0.000401,0.003738,0.094952,291.379852,14.843598,0.949524,-345.127686,294.500519,0.000000
118.910004,65.501816,-345.172180,-0.000405,0.003738,0.094952,291.366638,14.842924,0.949524,-345.172180,294.500519,0.000000
119.310005,65.472397,-345.172180,-0.000410,0.003738,0.094952,291.235779,14.836258,0.949524,-345.172180,294.500519,0.000000
119.710007,65.460098,-345.216675,-0.000405,0.003738,0.094952,291.181061,14.833470,0.949524,-345.216675,294.500519,0.000000
120.110008,65.437012,-345.261139,-0.000405,0.003738,0.094952,291.078369,14.828238,0.949524,-345.261139,294.500519,0.000000
120.510002,65.422119,-345.261139,-0.000410,0.003738,0.094952,291.012115,14.824864,0.949524,-345.261139,294.500519,0.000000
120.910004,65.409836,-345.261139,-0.000401,0.003738,0.094952,290.957489,14.822081,0.949524,-345.261139,294.500519,0.000000
121.310005,65.378174,-345.305634,-0.000410,0.003738,0.094952,290.816650,14.814906,0.949524,-345.305634,294.500519,0.000000
121.710007,65.365143,-345.350098,-0.000414,0.003738,0.094952,290.758667,14.811953,0.949524,-345.350098,294.500519,0.000000
122.110008,65.339828,-345.394592,-0.000401,0.003738,0.094952,290.646088,14.806217,0.949524,-345.394592,294.500519,0.000000
122.510002,65.344299,-345.394592,-0.000405,0.003738,0.094952,290.665955,14.807230,0.949524,-345.394592,294.500519,0.000000
122.910004,65.305939,-345.439056,-0.000410,0.003738,0.094952,290.495331,14.798536,0.949524,-345.439056,294.500519,0.000000
123.310005,65.318970,-345.439056,-0.000397,0.003738,0.094952,290.553284,14.801490,0.949524,-345.439056,294.500519,0.000000
123.710007,65.299988,-345.483551,-0.000397,0.003738,0.094952,290.468842,14.797189,0.949524,-345.483551,294.500519,0.000000
124.110008,65.294769,-345.439056,-0.000405,0.003738,0.094952,290.445648,14.796006,0.949524,-345.439056,294.500519,0.000000
124.510002,65.282104,-345.483551,-0.000418,0.003738,0.094952,290.389313,14.793136,0.949524,-345.483551,294.500519,0.000000
124.910004,65.271683,-345.483551,-0.000410,0.003738,0.094952,290.342957,14.790774,0.949524,-345.483551,294.500519,0.000000
125.310005,65.255676,-345.528015,-0.000401,0.003738,0.094952,290.271759,14.787148,0.949524,-345.528015,294.500519,0.000000
125.710007,65.258270,-345.572510,-0.000410,0.003738,0.094952,290.283295,14.787735,0.949524,-345.572510,294.500519,0.000000
126.110008,65.227371,-345.617004,-0.000410,0.003738,0.094952,290.145844,14.780734,0.949524,-345.617004,294.500519,0.000000
126.510010,65.217682,-345.617004,-0.000401,0.003738,0.094952,290.102753,14.778538,0.949524,-345.617004,294.500519,0.000000
126.910004,65.202042,-345.705963,-0.000392,0.003738,0.094952,290.033173,14.774994,0.949524,-345.705963,294.500519,0.000000
127.310005,65.200180,-345.617004,-0.000405,0.003738,0.094952,290.024872,14.774571,0.949524,-345.617004,294.500519,0.000000
127.710007,65.154755,-345.750427,-0.000401,0.003738,0.094952,289.822815,14.764278,0.949524,-345.750427,294.500519,0.000000
128.110001,65.146942,-345.705963,-0.000401,0.003738,0.094952,289.788086,14.762508,0.949524,-345.705963,1681.641113,0.000000
128.510010,65.078415,-345.750427,-0.000401,0.003736,0.094883,289.483246,14.746980,0.948828,-345.750427,0.094675,0.000000
128.910004,65.058319,-345.750427,-0.000405,0.003715,0.094363,289.393860,14.742426,0.943627,-345.750427,0.094007,0.000000
129.310013,64.942871,-345.750427,-0.000405,0.003690,0.093721,288.880310,14.716265,0.937208,-345.750427,0.093339,0.000000
129.710007,64.914581,-345.794922,-0.000397,0.003670,0.093218,288.754486,14.709854,0.932182,-345.794922,0.092680,0.000000
130.110001,64.879196,-345.839386,-0.000388,0.003643,0.092533,288.597076,14.701837,0.925331,-345.839386,0.092012,0.000000
130.510010,64.886276,-345.883881,-0.000388,0.003618,0.091891,288.628571,14.703441,0.918912,-345.883881,0.091345,0.000000
130.910004,64.876221,-345.883881,-0.000392,0.003587,0.091111,288.583832,14.701161,0.911107,-345.883881,0.090677,0.000000
131.310013,64.839355,-345.883881,-0.000388,0.003563,0.090504,288.419861,14.692808,0.905037,-345.883881,0.090009,0.000000
131.710007,64.766739,-345.883881,-0.000388,0.003538,0.089871,288.096832,14.676353,0.898708,-345.883881,0.089342,0.000000
132.110001,64.548904,-345.972839,-0.000392,0.003516,0.089315,287.127869,14.626991,0.893152,-345.972839,0.088674,0.000000
132.510010,63.848846,-345.972839,-0.000379,0.003490,0.088639,284.013855,14.468356,0.886392,-345.972839,0.088006,0.000000
132.910004,62.845673,-346.017303,-0.000375,0.003466,0.088040,279.551514,14.241034,0.880404,-346.017303,0.087347,0.000000
133.310013,61.800056,-346.061798,-0.000371,0.003447,0.087546,274.900391,14.004093,0.875461,-346.061798,0.086679,0.000000
133.710007,60.248009,-346.017303,-0.000371,0.003421,0.086905,267.996521,13.652393,0.869050,-346.017303,0.086012,0.000000
134.110001,58.448700,-346.106293,-0.000362,0.003394,0.086211,259.992798,13.244665,0.862108,-346.106293,0.085343,0.000000
134.510010,56.487419,-346.150757,-0.000358,0.003369,0.085561,251.268585,12.800232,0.855606,-346.150757,0.084676,0.000000
134.910004,54.025291,-346.106293,-0.000362,0.003342,0.084893,240.316498,12.242307,0.848929,-346.106293,0.084008,0.000000
135.310013,51.883034,-346.061798,-0.000375,0.003317,0.084251,230.787262,11.756864,0.842510,-346.061798,0.083340,0.000000
135.710007,49.179237,-346.150757,-0.000354,0.003292,0.083626,218.760178,11.144175,0.836265,-346.150757,0.082673,0.000000
136.110001,46.126900,-346.150757,-0.000366,0.003264,0.082916,205.182693,10.452504,0.829157,-346.150757,0.082013,0.000000
136.510010,43.826378,-346.195251,-0.000371,0.003243,0.082377,194.949463,9.931199,0.823775,-346.195251,0.081346,0.000000
136.910004,40.662331,-346.239716,-0.000354,0.003216,0.081675,180.875076,9.214215,0.816750,-346.239716,0.080678,0.000000
137.310013,37.811447,-346.239716,-0.000366,0.003190,0.081025,168.193710,8.568196,0.810248,-346.239716,0.080010,0.000000
137.710007,35.133720,-346.284210,-0.000362,0.003164,0.080357,156.282593,7.961415,0.803571,-346.284210,0.079343,0.000000
138.110001,32.036697,-346.328674,-0.000375,0.003136,0.079646,142.506348,7.259619,0.796463,-346.328674,0.078674,0.000000
138.510010,29.909332,-346.284210,-0.000371,0.003117,0.079178,133.043350,6.777551,0.791777,-346.284210,0.078007,0.000000
138.910004,26.442917,-346.284210,-0.000354,0.003087,0.078415,117.623970,5.992050,0.784147,-346.284210,0.077339,0.000000
139.310013,23.319832,-346.284210,-0.000362,0.003058,0.077677,103.731796,5.284349,0.776774,-346.284210,0.076671,0.000000
139.710007,20.017258,-346.373169,-0.000366,0.003028,0.076923,89.041206,4.535975,0.769227,-346.373169,0.076012,0.000000
140.110001,17.644127,-346.373169,-0.000379,0.003008,0.076403,78.484993,3.998216,0.764026,-346.373169,0.075344,0.000000
140.510010,14.258888,-346.417633,-0.000354,0.002978,0.075631,63.426704,3.231110,0.756305,-346.417633,0.074677,0.000000
140.910004,11.437424,-346.506622,-0.000371,0.002953,0.075006,50.876202,2.591757,0.750060,-346.506622,0.074009,0.000000
141.310013,9.164833,-346.462128,-0.000366,0.002934,0.074512,40.767212,2.076781,0.745117,-346.462128,0.073341,0.000000
141.710007,6.128510,-346.462128,-0.000375,0.002906,0.073809,27.260971,1.388740,0.738092,-346.462128,0.072674,0.000000
142.110001,2.655762,-346.462128,-0.000349,0.002871,0.072933,11.813418,0.601804,0.729334,-346.462128,0.072005,0.000000
142.510010,0.326576,-346.506622,-0.000362,0.002848,0.072344,1.452684,0.074003,0.723437,-346.506622,0.071338,0.000000
142.910004,-1.499912,-346.551086,-0.000358,0.002825,0.071763,-6.671943,-0.339885,0.717631,-346.551086,0.070679,0.000000
143.310013,-0.312416,-346.551086,-0.000384,0.002800,0.071112,-1.389696,-0.070794,0.711121,-346.551086,0.070011,0.000000
143.710007,-0.233475,-346.551086,-0.000405,0.002771,0.070376,-1.038548,-0.052906,0.703756,-346.551086,0.069343,0.000000
144.110001,-0.123253,-346.551086,-0.000453,0.002741,0.069612,-0.548256,-0.027929,0.696118,-346.551086,0.068675,0.000000
144.510010,-0.152672,-346.640045,-0.000487,0.002720,0.069083,-0.679118,-0.034596,0.690834,-346.640045,0.068008,0.000000
144.910004,-0.131447,-346.684540,-0.000526,0.002688,0.068268,-0.584705,-0.029786,0.682682,-346.684540,0.067340,0.000000
145.310013,-0.146339,-346.773499,-0.000569,0.002666,0.067722,-0.650950,-0.033161,0.677216,-346.773499,0.066672,0.000000
145.710007,-0.127724,-346.729004,-0.000595,0.002641,0.067089,-0.568143,-0.028943,0.670888,-346.729004,0.066005,0.000000
146.110001,-0.134048,-346.729004,-0.000629,0.002613,0.066377,-0.596277,-0.030376,0.663772,-346.729004,0.065345,0.000000
146.510010,-0.132561,-346.773499,-0.000677,0.002584,0.065640,-0.589660,-0.030039,0.656399,-346.773499,0.064678,0.000000
146.910004,-0.106125,-346.729004,-0.000707,0.002555,0.064894,-0.472067,-0.024048,0.648943,-346.729004,0.064010,0.000000
147.310013,-0.119904,-346.817963,-0.000733,0.002537,0.064435,-0.533358,-0.027171,0.644348,-346.817963,0.063342,0.000000
147.710007,-0.139267,-346.817963,-0.000767,0.002510,0.063750,-0.619490,-0.031558,0.637497,-346.817963,0.062674,0.000000
148.110001,-0.107986,-346.817963,-0.000815,0.002477,0.062917,-0.480348,-0.024470,0.629171,-346.817963,0.062006,0.000000
148.510010,-0.115807,-346.862457,-0.000836,0.002452,0.062293,-0.515133,-0.026242,0.622926,-346.862457,0.061339,0.000000
148.910004,-0.106865,-346.862457,-0.000867,0.002427,0.061651,-0.475359,-0.024216,0.616506,-346.862457,0.060671,0.000000
149.310013,-0.147827,-346.862457,-0.000897,0.002402,0.061000,-0.657568,-0.033498,0.610004,-346.862457,0.060012,0.000000
149.710007,-0.126976,-346.906952,-0.000927,0.002372,0.060246,-0.564817,-0.028773,0.602464,-346.906952,0.059344,0.000000
150.110001,-0.119904,-346.906952,-0.000949,0.002347,0.059605,-0.533358,-0.027171,0.596045,-346.906952,0.058676,0.000000
150.510010,-0.124367,-346.951416,-0.000979,0.002322,0.058988,-0.553211,-0.028182,0.589883,-346.951416,0.058009,0.000000
150.910004,-0.118782,-346.995911,-0.001035,0.002289,0.058130,-0.528369,-0.026916,0.581299,-346.995911,0.057341,0.000000
151.310013,-0.128090,-346.995911,-0.001052,0.002270,0.057670,-0.569772,-0.029026,0.576704,-346.995911,0.056673,0.000000
151.710007,-0.123627,-347.040375,-0.001078,0.002242,0.056942,-0.549919,-0.028014,0.569422,-347.040375,0.056005,0.000000
152.110001,-0.122131,-347.084869,-0.001104,0.002218,0.056343,-0.543267,-0.027675,0.563435,-347.084869,0.055337,0.000000
152.510010,-0.103516,-347.084869,-0.001121,0.002191,0.055650,-0.460460,-0.023457,0.556501,-347.084869,0.054670,0.000000
152.910004,-0.067772,-347.129333,-0.001160,0.002164,0.054973,-0.301465,-0.015357,0.549733,-347.129333,0.054010,0.000000
153.310013,-0.078568,-347.173828,-0.001194,0.002137,0.054271,-0.349486,-0.017804,0.542709,-347.173828,0.053343,0.000000
153.710007,-0.091599,-347.173828,-0.001224,0.002117,0.053768,-0.407451,-0.020757,0.537682,-347.173828,0.052675,0.000000
154.110001,-0.096069,-347.173828,-0.001242,0.002082,0.052892,-0.427338,-0.021770,0.528924,-347.173828,0.052007,0.000000
154.510010,-0.078568,-347.218292,-0.001272,0.002062,0.052381,-0.349486,-0.017804,0.523807,-347.218292,0.051340,0.000000
154.910004,-0.053246,-347.262787,-0.001302,0.002042,0.051860,-0.236848,-0.012066,0.518599,-347.262787,0.050672,0.000000
155.310013,-0.071861,-347.262787,-0.001332,0.002007,0.050984,-0.319655,-0.016284,0.509840,-347.262787,0.050005,0.000000
155.710007,-0.087502,-347.307251,-0.001345,0.001981,0.050325,-0.389226,-0.019828,0.503247,-347.307251,0.049336,0.000000
156.110001,-0.098679,-347.351746,-0.001393,0.001950,0.049527,-0.438944,-0.022361,0.495269,-347.351746,0.048678,0.000000
156.510010,-0.087135,-347.262787,-0.001431,0.001926,0.048911,-0.387597,-0.019745,0.489114,-347.262787,0.048010,0.000000
156.910004,-0.107986,-347.307251,-0.001423,0.001902,0.048304,-0.480348,-0.024470,0.483043,-347.307251,0.047341,0.000000
157.310013,-0.099792,-347.307251,-0.001457,0.001878,0.047706,-0.443899,-0.022613,0.477063,-347.307251,0.046674,0.000000
157.710007,-0.106125,-347.396240,-0.001500,0.001850,0.046986,-0.472067,-0.024048,0.469864,-347.396240,0.046006,0.000000
158.110001,-0.091972,-347.440704,-0.001535,0.001820,0.046223,-0.409113,-0.020841,0.462234,-347.440704,0.045339,0.000000
158.510010,-0.111710,-347.396240,-0.001548,0.001792,0.045529,-0.496909,-0.025314,0.455293,-347.396240,0.044671,0.000000
158.910004,-0.126602,-347.440704,-0.001578,0.001772,0.045018,-0.563155,-0.028688,0.450175,-347.440704,0.044003,0.000000
159.310013,-0.128838,-347.529663,-0.001613,0.001747,0.044376,-0.573098,-0.029195,0.443756,-347.529663,0.043344,0.000000
159.710007,-0.096817,-347.485199,-0.001634,0.001726,0.043846,-0.430664,-0.021939,0.438465,-347.485199,0.042676,0.000000
160.110001,-0.093834,-347.529663,-0.001664,0.001691,0.042962,-0.417394,-0.021263,0.429623,-347.529663,0.042009,0.000000
160.510010,-0.121765,-347.529663,-0.001690,0.001674,0.042511,-0.541638,-0.027592,0.425112,-347.529663,0.041341,0.000000
160.910004,-0.104637,-347.618622,-0.001716,0.001637,0.041592,-0.465449,-0.023711,0.415922,-347.618622,0.040672,0.000000
161.310013,-0.114319,-347.618622,-0.001742,0.001617,0.041080,-0.508516,-0.025905,0.410805,-347.618622,0.040005,0.000000
161.710007,-0.096443,-347.663116,-0.001768,0.001597,0.040560,-0.429001,-0.021854,0.405597,-347.663116,0.039337,0.000000
162.110001,-0.116920,-347.663116,-0.001802,0.001559,0.039606,-0.520088,-0.026495,0.396059,-347.663116,0.038670,0.000000
162.510010,-0.146713,-347.752075,-0.001815,0.001538,0.039060,-0.652613,-0.033246,0.390601,-347.752075,0.038010,0.000000
162.910004,-0.130699,-347.707581,-0.001845,0.001507,0.038288,-0.581379,-0.029617,0.382880,-347.707581,0.037343,0.000000
163.100006,-0.096069,-347.752075,-0.001867,0.001499,0.038062,-0.427338,-0.021770,0.380624,-347.752075,0.037993,0.000000