File: Data/compression 23/AutoNoHeating-12-23-reverse-1-3_09192024_182358.csv
Time (sec),S:Load (lbs),S:HL1 (DIM),S:LVDT (in),S:Position (in),Ch:Position (mm),Ch:Load (N),Ch:Stress (MPa),Ch:Strain (mm/mm),Ch:HL1 (DIM),Set Point (),Cycles ()
0.110000,-0.056969,-313.145905,-0.009904,-0.005783,-0.146883,-0.253409,-0.012909,-1.468827,-313.145905,-0.146613,0.000000
0.500000,-0.058830,-313.145905,-0.009904,-0.005725,-0.145408,-0.261690,-0.013331,-1.454081,-313.145905,-0.144809,0.000000
0.890000,-0.030533,-313.145905,-0.009791,-0.005488,-0.139398,-0.135817,-0.006919,-1.393984,-313.145905,-0.138305,0.000000
1.280000,-0.059578,-313.234863,-0.009520,-0.005232,-0.132894,-0.265016,-0.013501,-1.328937,-313.234863,-0.131819,0.000000
1.670000,-0.077820,-313.190369,-0.009274,-0.004978,-0.126433,-0.346160,-0.017634,-1.264329,-313.190369,-0.125314,0.000000
2.060000,-0.114685,-313.323822,-0.009015,-0.004729,-0.120120,-0.510145,-0.025988,-1.201197,-313.323822,-0.118828,0.000000
2.450000,-0.049896,-313.323822,-0.008752,-0.004465,-0.113416,-0.221950,-0.011307,-1.134159,-313.323822,-0.112324,0.000000
2.840000,-0.031647,-313.279327,-0.008476,-0.004209,-0.106920,-0.140772,-0.007171,-1.069203,-313.279327,-0.105819,0.000000
3.230000,-0.034256,-313.323822,-0.008231,-0.003954,-0.100425,-0.152378,-0.007763,-1.004254,-313.323822,-0.099332,0.000000
3.620000,-0.061440,-313.368286,-0.007968,-0.003697,-0.093903,-0.273297,-0.013922,-0.939032,-313.368286,-0.092828,0.000000
4.010000,-0.077080,-313.412781,-0.007713,-0.003443,-0.087452,-0.342868,-0.017467,-0.874515,-313.412781,-0.086341,0.000000
4.400000,-0.089737,-313.412781,-0.007429,-0.003183,-0.080843,-0.399170,-0.020335,-0.808431,-313.412781,-0.079837,0.000000
4.790000,-0.044312,-313.457275,-0.007170,-0.002933,-0.074486,-0.197107,-0.010041,-0.744860,-313.457275,-0.073333,0.000000
5.180000,-0.013771,-313.501740,-0.006907,-0.002677,-0.067999,-0.061257,-0.003121,-0.679994,-313.501740,-0.066846,0.000000
5.570000,-0.053993,-313.501740,-0.006653,-0.002419,-0.061452,-0.240174,-0.012235,-0.614516,-313.501740,-0.060342,0.000000
5.960001,-0.067772,-313.546234,-0.006390,-0.002163,-0.054930,-0.301465,-0.015357,-0.549302,-313.546234,-0.053855,0.000000
6.350000,-0.076332,-313.546234,-0.006135,-0.001912,-0.048556,-0.339542,-0.017297,-0.485564,-313.546234,-0.047351,0.000000
6.740000,-0.029045,-313.546234,-0.005881,-0.001654,-0.042000,-0.129199,-0.006582,-0.420002,-313.546234,-0.040847,0.000000
7.130000,-0.035370,-313.635193,-0.005605,-0.001397,-0.035487,-0.157333,-0.008015,-0.354872,-313.635193,-0.034360,0.000000
7.520000,-0.025688,-313.590698,-0.005346,-0.001144,-0.029070,-0.114267,-0.005821,-0.290695,-313.590698,-0.027855,0.000000
7.910000,-0.063675,-313.679657,-0.005092,-0.000882,-0.022410,-0.283240,-0.014429,-0.224096,-313.679657,-0.021369,0.000000
8.300000,-0.069633,-313.724152,-0.004829,-0.000628,-0.015957,-0.309745,-0.015779,-0.159571,-313.724152,-0.014865,0.000000
8.690001,0.077087,-313.724152,-0.004592,-0.000371,-0.009418,0.342902,0.017468,-0.094183,-313.724152,-0.008360,0.000000
9.080001,0.050270,-313.724152,-0.004514,-0.000000,-0.000000,0.223612,0.011391,-0.000000,-313.724152,0.000216,0.000000
9.470000,0.075966,-313.724152,-0.004540,-0.000000,-0.000000,0.337913,0.017214,-0.000000,-313.724152,0.000555,0.000000
9.860001,0.099052,-313.857605,-0.004531,-0.000000,-0.000000,0.440607,0.022446,-0.000000,-313.857605,0.001205,0.000000
10.250001,0.193268,-313.768616,-0.004514,0.000033,0.000850,0.859698,0.043795,0.008501,-313.768616,0.001855,0.000000
10.640000,0.207413,-313.813110,-0.004488,0.000066,0.001665,0.922618,0.047000,0.016646,-313.813110,0.002506,0.000000
11.030001,0.222679,-313.857605,-0.004462,0.000082,0.002090,0.990526,0.050460,0.020900,-313.857605,0.003157,0.000000
11.420000,0.247261,-313.813110,-0.004419,0.000112,0.002836,1.099872,0.056030,0.028356,-313.813110,0.003807,0.000000
11.810000,0.263268,-313.902069,-0.004411,0.000138,0.003503,1.171072,0.059657,0.035033,-313.902069,0.004449,0.000000
12.200001,0.310562,-313.902069,-0.004376,0.000158,0.004007,1.381449,0.070374,0.040067,-313.902069,0.005099,0.000000
12.590000,0.346680,-313.902069,-0.004376,0.000190,0.004839,1.542108,0.078559,0.048386,-313.902069,0.005749,0.000000
12.980000,0.354126,-313.991028,-0.004329,0.000214,0.005428,1.575231,0.080246,0.054283,-313.991028,0.006400,0.000000
13.370001,0.379822,-313.991028,-0.004307,0.000239,0.006070,1.689532,0.086069,0.060702,-313.991028,0.007051,0.000000
13.760000,0.386902,-314.035522,-0.004273,0.000265,0.006720,1.721025,0.087673,0.067205,-314.035522,0.007701,0.000000
14.150001,0.458397,-314.035522,-0.004260,0.000286,0.007259,2.039051,0.103874,0.072587,-314.035522,0.008351,0.000000
14.540001,0.509407,-314.079987,-0.004225,0.000318,0.008065,2.265956,0.115433,0.080649,-314.079987,0.009002,0.000000
14.930000,0.509407,-314.124481,-0.004208,0.000344,0.008733,2.265956,0.115433,0.087325,-314.124481,0.009652,0.000000
15.320001,0.534729,-314.035522,-0.004178,0.000368,0.009340,2.378593,0.121171,0.093396,-314.035522,0.010302,0.000000
15.710001,0.590958,-314.124481,-0.004161,0.000396,0.010051,2.628711,0.133913,0.100512,-314.124481,0.010953,0.000000
16.100000,0.622238,-314.168945,-0.004130,0.000413,0.010502,2.767853,0.141001,0.105016,-314.168945,0.011603,0.000000
16.490002,0.678093,-314.213440,-0.004100,0.000446,0.011326,3.016308,0.153658,0.113259,-314.213440,0.012254,0.000000
16.880001,0.691124,-314.213440,-0.004079,0.000468,0.011890,3.074273,0.156611,0.118899,-314.213440,0.012904,0.000000
17.270000,0.707886,-314.213440,-0.004057,0.000495,0.012566,3.148833,0.160409,0.125659,-314.213440,0.013554,0.000000
17.660002,0.735809,-314.257904,-0.004027,0.000519,0.013190,3.273043,0.166737,0.131904,-314.257904,0.014205,0.000000
18.050001,0.783478,-314.257904,-0.004014,0.000544,0.013806,3.485083,0.177539,0.138058,-314.257904,0.014856,0.000000
18.440001,0.843796,-314.346893,-0.003980,0.000566,0.014378,3.753391,0.191207,0.143781,-314.346893,0.015506,0.000000
18.830002,0.912689,-314.346893,-0.003945,0.000596,0.015142,4.059844,0.206818,0.151419,-314.346893,0.016156,0.000000
19.220001,0.968544,-314.302399,-0.003936,0.000622,0.015800,4.308299,0.219475,0.158004,-314.302399,0.016806,0.000000
19.610001,1.091431,-314.435852,-0.003898,0.000651,0.016547,4.854926,0.247322,0.165468,-314.435852,0.017457,0.000000
20.000000,1.108925,-314.391357,-0.003876,0.000670,0.017024,4.932744,0.251286,0.170237,-314.391357,0.018108,0.000000
20.390001,1.222130,-314.435852,-0.003850,0.000699,0.017760,5.436305,0.276939,0.177602,-314.435852,0.018758,0.000000
20.780001,1.337563,-314.480316,-0.003820,0.000723,0.018376,5.949775,0.303096,0.183764,-314.480316,0.019400,0.000000
21.170000,1.394913,-314.480316,-0.003803,0.000748,0.019009,6.204882,0.316092,0.190093,-314.480316,0.020050,0.000000
21.560001,1.555031,-314.480316,-0.003781,0.000773,0.019625,6.917122,0.352375,0.196254,-314.480316,0.020700,0.000000
21.950001,1.692810,-314.524811,-0.003755,0.000800,0.020319,7.529995,0.383596,0.203188,-314.524811,0.021351,0.000000
22.340000,1.868568,-314.613770,-0.003734,0.000827,0.021013,8.311808,0.423424,0.210130,-314.613770,0.022002,0.000000
22.730001,2.008209,-314.658234,-0.003682,0.000856,0.021750,8.932961,0.455067,0.217495,-314.658234,0.022652,0.000000
23.120001,2.068535,-314.613770,-0.003682,0.000875,0.022227,9.201303,0.468737,0.222272,-314.613770,0.023302,0.000000
23.510000,2.276688,-314.702728,-0.003660,0.000902,0.022921,10.127213,0.515905,0.229206,-314.702728,0.023952,0.000000
23.900002,2.261795,-314.658234,-0.003626,0.000915,0.023250,10.060966,0.512530,0.232499,-314.658234,0.024603,0.000000
24.290001,2.619644,-314.702728,-0.003587,0.000959,0.024369,11.652760,0.593620,0.243687,-314.702728,0.025254,0.000000
24.680000,2.711990,-314.747223,-0.003561,0.000985,0.025011,12.063536,0.614546,0.250106,-314.747223,0.025904,0.000000
25.070002,2.792053,-314.702728,-0.003557,0.001007,0.025575,12.419673,0.632688,0.255745,-314.702728,0.026554,0.000000
25.460001,3.046013,-314.791687,-0.003510,0.001038,0.026355,13.549342,0.690236,0.263550,-314.791687,0.027205,0.000000
25.850000,3.200172,-314.747223,-0.003492,0.001062,0.026979,14.235078,0.725169,0.269795,-314.747223,0.027855,0.000000
26.240002,3.217674,-314.880646,-0.003466,0.001083,0.027500,14.312930,0.729135,0.274995,-314.880646,0.028506,0.000000
26.630001,3.387474,-314.880646,-0.003445,0.001114,0.028289,15.068237,0.767613,0.282891,-314.880646,0.029156,0.000000
27.020000,3.406837,-314.836182,-0.003410,0.001135,0.028817,15.154370,0.772000,0.288174,-314.836182,0.029806,0.000000
27.410002,3.625046,-314.925140,-0.003385,0.001166,0.029607,16.125010,0.821447,0.296070,-314.925140,0.030457,0.000000
27.800001,3.721863,-314.880646,-0.003385,0.001186,0.030127,16.555672,0.843386,0.301270,-314.880646,0.031107,0.000000
28.190001,3.786659,-315.014099,-0.003363,0.001211,0.030752,16.843901,0.858069,0.307515,-315.014099,0.031758,0.000000
28.580002,3.950127,-314.969604,-0.003324,0.001239,0.031463,17.571041,0.895112,0.314631,-314.969604,0.032408,0.000000
28.970001,3.917732,-315.014099,-0.003290,0.001256,0.031913,17.426943,0.887771,0.319135,-315.014099,0.033059,0.000000
29.360001,4.062958,-315.058563,-0.003272,0.001288,0.032711,18.072939,0.920679,0.327113,-315.058563,0.033709,0.000000
29.750002,4.238716,-315.014099,-0.003247,0.001310,0.033284,18.854752,0.960507,0.332836,-315.014099,0.034351,0.000000
30.140001,4.468475,-315.147552,-0.003216,0.001347,0.034203,19.876772,1.012571,0.342033,-315.147552,0.035001,0.000000
30.530001,4.424530,-315.147552,-0.003186,0.001371,0.034828,19.681292,1.002613,0.348278,-315.147552,0.035651,0.000000
30.920002,4.513161,-315.147552,-0.003173,0.001396,0.035452,20.075541,1.022697,0.354524,-315.147552,0.036302,0.000000
31.310001,4.621887,-315.192017,-0.003139,0.001418,0.036016,20.559181,1.047335,0.360155,-315.192017,0.036953,0.000000
31.700001,4.676628,-315.147552,-0.003113,0.001438,0.036536,20.802681,1.059739,0.365363,-315.147552,0.037603,0.000000
32.090000,4.927979,-315.280975,-0.003091,0.001473,0.037421,21.920744,1.116696,0.374205,-315.280975,0.038253,0.000000
32.480003,4.933197,-315.280975,-0.003061,0.001495,0.037975,21.943956,1.117878,0.379754,-315.280975,0.038903,0.000000
32.870003,5.082146,-315.280975,-0.003044,0.001522,0.038652,22.606514,1.151631,0.386521,-315.280975,0.039554,0.000000
33.260002,5.068367,-315.280975,-0.003018,0.001543,0.039190,22.545223,1.148508,0.391896,-315.280975,0.040205,0.000000
33.650002,5.160339,-315.325470,-0.002992,0.001566,0.039788,22.954336,1.169350,0.397883,-315.325470,0.040855,0.000000
34.040001,5.377434,-315.325470,-0.002971,0.001598,0.040595,23.920019,1.218544,0.405945,-315.325470,0.041505,0.000000
34.430000,5.423981,-315.325470,-0.002932,0.001623,0.041228,24.127071,1.229092,0.412281,-315.325470,0.042155,0.000000
34.820004,5.493614,-315.369934,-0.002906,0.001649,0.041887,24.436817,1.244871,0.418867,-315.369934,0.042806,0.000000
35.210003,5.510368,-315.503387,-0.002897,0.001672,0.042459,24.511343,1.248667,0.424590,-315.503387,0.043457,0.000000
35.600002,5.691345,-315.369934,-0.002859,0.001695,0.043040,25.316368,1.289677,0.430403,-315.369934,0.044107,0.000000
35.990002,5.842903,-315.414429,-0.002846,0.001722,0.043743,25.990532,1.324021,0.437428,-315.414429,0.044757,0.000000
36.380001,5.989990,-315.503387,-0.002807,0.001751,0.044480,26.644808,1.357351,0.444801,-315.503387,0.045408,0.000000
36.770000,6.074516,-315.503387,-0.002798,0.001776,0.045121,27.020798,1.376505,0.451212,-315.503387,0.046058,0.000000
37.160004,6.119576,-315.547852,-0.002759,0.001801,0.045746,27.221231,1.386716,0.457458,-315.547852,0.046709,0.000000
37.550003,6.188835,-315.547852,-0.002742,0.001826,0.046379,27.529314,1.402410,0.463793,-315.547852,0.047359,0.000000
37.940002,6.420074,-315.547852,-0.002725,0.001852,0.047047,28.557917,1.454810,0.470470,-315.547852,0.048009,0.000000
38.330002,6.521736,-315.636841,-0.002677,0.001879,0.047715,29.010132,1.477847,0.477147,-315.636841,0.048660,0.000000
38.720001,6.659142,-315.592346,-0.002665,0.001905,0.048391,29.621342,1.508983,0.483914,-315.592346,0.049301,0.000000
39.110001,6.543335,-315.681305,-0.002643,0.001924,0.048868,29.106207,1.482741,0.488683,-315.681305,0.049952,0.000000
39.500000,6.763031,-315.636841,-0.002630,0.001948,0.049475,30.083464,1.532525,0.494754,-315.636841,0.050603,0.000000
39.890003,7.089233,-315.770264,-0.002596,0.001980,0.050282,31.534485,1.606443,0.502816,-315.770264,0.051253,0.000000
40.280003,7.167053,-315.681305,-0.002552,0.002004,0.050897,31.880646,1.624077,0.508970,-315.681305,0.051903,0.000000
40.670002,7.252327,-315.725800,-0.002539,0.002027,0.051487,32.259960,1.643401,0.514867,-315.725800,0.052554,0.000000
41.060001,7.484688,-315.814758,-0.002514,0.002057,0.052241,33.293552,1.696055,0.522414,-315.814758,0.053204,0.000000
41.450001,7.547623,-315.814758,-0.002488,0.002081,0.052866,33.573502,1.710316,0.528659,-315.814758,0.053855,0.000000
41.840000,7.735298,-315.859222,-0.002466,0.002108,0.053551,34.408325,1.752844,0.535510,-315.859222,0.054505,0.000000
42.230003,7.902863,-315.859222,-0.002436,0.002135,0.054219,35.153687,1.790814,0.542186,-315.859222,0.055156,0.000000
42.620003,7.843285,-315.903717,-0.002423,0.002153,0.054687,34.888672,1.777314,0.546872,-315.903717,0.055806,0.000000
43.010002,8.273003,-315.948181,-0.002393,0.002184,0.055468,36.800152,1.874689,0.554676,-315.948181,0.056456,0.000000
43.400002,8.297577,-315.948181,-0.002358,0.002206,0.056032,36.909466,1.880258,0.560316,-315.948181,0.057106,0.000000
43.790001,8.770119,-315.948181,-0.002337,0.002239,0.056864,39.011436,1.987337,0.568635,-315.948181,0.057757,0.000000
44.180000,8.708679,-315.992676,-0.002298,0.002262,0.057462,38.738140,1.973415,0.574623,-315.992676,0.058408,0.000000
44.570004,8.774590,-315.948181,-0.002289,0.002285,0.058043,39.031322,1.988350,0.580429,-315.948181,0.059058,0.000000
44.960003,9.103020,-316.081635,-0.002255,0.002311,0.058711,40.492252,2.062774,0.587113,-316.081635,0.059708,0.000000
45.350002,9.258301,-316.037170,-0.002242,0.002335,0.059309,41.182980,2.097961,0.593093,-316.037170,0.060358,0.000000
45.740002,9.392723,-316.081635,-0.002216,0.002361,0.059960,41.780918,2.128422,0.599595,-316.081635,0.061009,0.000000
46.130001,9.760628,-316.170593,-0.002190,0.002392,0.060766,43.417442,2.211790,0.607665,-316.170593,0.061660,0.000000
46.520000,9.862289,-316.170593,-0.002160,0.002418,0.061425,43.869656,2.234827,0.614251,-316.170593,0.062310,0.000000
46.910004,10.105446,-316.215088,-0.002143,0.002442,0.062024,44.951267,2.289927,0.620238,-316.215088,0.062960,0.000000
47.300003,10.380257,-316.215088,-0.002117,0.002469,0.062701,46.173687,2.352200,0.627006,-316.215088,0.063610,0.000000
47.690002,10.084595,-316.259552,-0.002095,0.002481,0.063012,44.858517,2.285202,0.630124,-316.259552,0.064252,0.000000
48.080002,10.840881,-316.304047,-0.002048,0.002519,0.063993,48.222649,2.456579,0.639927,-316.304047,0.064903,0.000000
48.470001,11.160378,-316.259552,-0.002026,0.002546,0.064669,49.643837,2.528978,0.646687,-316.259552,0.065554,0.000000
48.860001,11.260178,-316.348511,-0.002013,0.002568,0.065224,50.087772,2.551593,0.652236,-316.348511,0.066204,0.000000
49.250004,11.473541,-316.348511,-0.001992,0.002591,0.065813,51.036861,2.599941,0.658133,-316.348511,0.066854,0.000000
49.640003,11.781120,-316.393005,-0.001970,0.002615,0.066420,52.405041,2.669640,0.664204,-316.393005,0.067504,0.000000
50.030003,12.144562,-316.393005,-0.001940,0.002643,0.067132,54.021709,2.751997,0.671319,-316.393005,0.068155,0.000000
50.420002,12.080879,-316.348511,-0.001914,0.002661,0.067583,53.738434,2.737566,0.675831,-316.348511,0.068806,0.000000
50.810001,12.821533,-316.437500,-0.001897,0.002693,0.068407,57.033028,2.905401,0.684067,-316.437500,0.069456,0.000000
51.200001,13.046074,-316.437500,-0.001854,0.002720,0.069083,58.031834,2.956283,0.690827,-316.437500,0.070106,0.000000
51.590004,13.896942,-316.437500,-0.001828,0.002755,0.069976,61.816685,3.149092,0.699759,-316.437500,0.070757,0.000000
51.980003,13.709267,-316.481964,-0.001807,0.002775,0.070497,60.981865,3.106564,0.704967,-316.481964,0.071407,0.000000
52.370003,14.208992,-316.481964,-0.001781,0.002802,0.071182,63.204754,3.219804,0.711818,-316.481964,0.072058,0.000000
52.760002,14.275650,-316.570923,-0.001768,0.002820,0.071633,63.501263,3.234909,0.716329,-316.570923,0.072708,0.000000
53.150002,15.004753,-316.570923,-0.001738,0.002851,0.072422,66.744476,3.400126,0.724217,-316.570923,0.073358,0.000000
53.540001,15.284401,-316.570923,-0.001720,0.002874,0.073003,67.988411,3.463495,0.730031,-316.570923,0.074009,0.000000
53.930004,15.751358,-316.615417,-0.001694,0.002903,0.073749,70.065536,3.569309,0.737487,-316.615417,0.074659,0.000000
54.320004,16.227997,-316.526459,-0.001669,0.002927,0.074356,72.185738,3.677317,0.743558,-316.526459,0.075310,0.000000
54.710003,16.082771,-316.659882,-0.001651,0.002943,0.074763,71.539742,3.644408,0.747630,-316.659882,0.075960,0.000000
55.100002,17.059128,-316.659882,-0.001621,0.002978,0.075648,75.882790,3.865654,0.756479,-316.659882,0.076611,0.000000
55.490002,17.533157,-316.704376,-0.001608,0.003001,0.076238,77.991379,3.973070,0.762376,-316.704376,0.077261,0.000000
55.880001,18.331902,-316.748840,-0.001578,0.003032,0.077010,81.544373,4.154068,0.770097,-316.748840,0.077911,0.000000
56.270004,18.741135,-316.704376,-0.001556,0.003057,0.077643,83.364731,4.246802,0.776426,-316.704376,0.078562,0.000000
56.660004,18.733315,-316.748840,-0.001548,0.003075,0.078111,83.329948,4.245030,0.781111,-316.748840,0.079203,0.000000
57.050003,19.828461,-316.793335,-0.001505,0.003105,0.078857,88.201401,4.493193,0.788568,-316.793335,0.079854,0.000000
57.440002,20.235092,-316.793335,-0.001496,0.003130,0.079490,90.010185,4.585337,0.794896,-316.793335,0.080505,0.000000
57.830002,20.820839,-316.837830,-0.001483,0.003156,0.080157,92.615715,4.718070,0.801573,-316.837830,0.081155,0.000000
58.220001,21.478073,-316.882294,-0.001457,0.003182,0.080834,95.539238,4.867001,0.808340,-316.882294,0.081805,0.000000
58.610004,21.920082,-316.926788,-0.001418,0.003205,0.081398,97.505394,4.967162,0.813980,-316.926788,0.082455,0.000000
59.000004,22.902397,-316.926788,-0.001410,0.003234,0.082144,101.874954,5.189757,0.821436,-316.926788,0.083106,0.000000
59.390003,23.565598,-316.926788,-0.001388,0.003258,0.082742,104.825012,5.340041,0.827416,-316.926788,0.083757,0.000000
59.780003,24.359123,-317.060211,-0.001362,0.003285,0.083444,108.354790,5.519856,0.834441,-317.060211,0.084407,0.000000
60.170002,24.803734,-317.015747,-0.001341,0.003309,0.084051,110.332520,5.620606,0.840512,-317.015747,0.085057,0.000000
60.560001,25.534698,-317.060211,-0.001337,0.003332,0.084633,113.584015,5.786245,0.846325,-317.060211,0.085707,0.000000
60.950005,26.524094,-317.104706,-0.001298,0.003359,0.085318,117.985062,6.010446,0.853176,-317.104706,0.086358,0.000000
61.340004,27.340332,-317.104706,-0.001281,0.003384,0.085950,121.615868,6.195408,0.859504,-317.104706,0.087009,0.000000
61.730003,28.127533,-317.104706,-0.001281,0.003409,0.086584,125.117516,6.373790,0.865840,-317.104706,0.087659,0.000000
62.120003,29.187675,-317.104706,-0.001250,0.003439,0.087347,129.833267,6.614022,0.873470,-317.104706,0.088309,0.000000
62.510002,29.973755,-317.193665,-0.001237,0.003461,0.087902,133.329926,6.792150,0.879019,-317.193665,0.088960,0.000000
62.900002,30.679398,-317.193665,-0.001212,0.003486,0.088544,136.468781,6.952051,0.885438,-317.193665,0.089610,0.000000
63.290005,31.998344,-317.193665,-0.001207,0.003515,0.089280,142.335739,7.250928,0.892804,-317.193665,0.090261,0.000000
63.680004,32.877144,-317.282623,-0.001181,0.003539,0.089887,146.244843,7.450068,0.898875,-317.282623,0.090911,0.000000
64.070000,33.136681,-317.238129,-0.001164,0.003554,0.090278,147.399323,7.508879,0.902781,-317.238129,0.091561,0.000000
64.460007,34.842522,-317.282623,-0.001147,0.003585,0.091059,154.987274,7.895428,0.910585,-317.282623,0.092212,0.000000
64.850006,36.173752,-317.371582,-0.001125,0.003615,0.091822,160.908890,8.197089,0.918216,-317.371582,0.092862,0.000000
65.240005,37.817780,-317.327118,-0.001104,0.003644,0.092567,168.221878,8.569631,0.925672,-317.327118,0.093513,0.000000
65.630005,38.301491,-317.416077,-0.001095,0.003663,0.093036,170.373535,8.679242,0.930357,-317.416077,0.094155,0.000000
66.020004,39.717621,-317.371582,-0.001074,0.003694,0.093834,176.672806,9.000141,0.938336,-317.371582,0.094805,0.000000
66.410004,40.572960,-317.460541,-0.001069,0.003712,0.094276,180.477539,9.193964,0.942757,-317.460541,0.095455,0.000000
66.800003,42.650429,-317.416077,-0.001035,0.003748,0.095195,189.718582,9.664725,0.951954,-317.416077,0.096106,0.000000
67.190002,43.857658,-317.416077,-0.001030,0.003773,0.095846,195.088608,9.938287,0.958457,-317.416077,0.096756,0.000000
67.580002,44.933441,-317.549500,-0.001022,0.003795,0.096383,199.873932,10.182063,0.963831,-317.549500,0.097407,0.000000
67.970001,46.555122,-317.505035,-0.001000,0.003822,0.097077,207.087524,10.549542,0.970773,-317.505035,0.098057,0.000000
68.360001,47.498718,-317.549500,-0.000996,0.003843,0.097624,211.284851,10.763363,0.976238,-317.549500,0.098708,0.000000
68.750000,49.127106,-317.593994,-0.000974,0.003870,0.098309,218.528275,11.132361,0.983089,-317.593994,0.099358,0.000000
69.140007,50.925659,-317.638458,-0.000957,0.003901,0.099089,226.528641,11.539920,0.990893,-317.638458,0.100008,0.000000
69.530006,52.106079,-317.638458,-0.000936,0.003925,0.099705,231.779419,11.807405,0.997047,-317.638458,0.100659,0.000000
69.920006,53.869637,-317.638458,-0.000931,0.003950,0.100338,239.624115,12.207034,1.003376,-317.638458,0.101309,0.000000
70.310005,54.900368,-317.682953,-0.000923,0.003969,0.100814,244.209030,12.440601,1.008145,-317.682953,0.101960,0.000000
70.700005,56.804306,-317.727448,-0.000914,0.003997,0.101534,252.678177,12.872040,1.015344,-317.727448,0.102610,0.000000
71.090004,58.294914,-317.682953,-0.000905,0.004020,0.102116,259.308716,13.209816,1.021157,-317.682953,0.103260,0.000000
71.480003,60.172417,-317.816406,-0.000884,0.004050,0.102861,267.660278,13.635264,1.028613,-317.816406,0.103911,0.000000
71.870003,61.854424,-317.771912,-0.000871,0.004074,0.103468,275.142212,14.016413,1.034684,-317.771912,0.104562,0.000000
72.260002,63.557281,-317.860870,-0.000871,0.004096,0.104041,282.716919,14.402286,1.040407,-317.860870,0.105212,0.000000
72.650002,66.059998,-317.816406,-0.000849,0.004128,0.104848,293.849548,14.969410,1.048476,-317.816406,0.105862,0.000000
73.040001,65.453400,-317.860870,-0.000836,0.004123,0.104717,291.151276,14.831953,1.047174,-317.860870,291.192657,0.000000
73.430000,66.485245,-317.905365,-0.000823,0.004112,0.104449,295.741150,15.065772,1.044487,-317.905365,294.500519,0.000000
73.820000,65.733047,-317.905365,-0.000832,0.004112,0.104440,292.395203,14.895322,1.044396,-317.905365,294.500519,0.000000
74.210007,65.695450,-317.905365,-0.000823,0.004147,0.105342,292.227966,14.886802,1.053420,-317.905365,294.500519,0.000000
74.600006,65.391953,-317.949829,-0.000823,0.004145,0.105281,290.877930,14.818028,1.052814,-317.949829,294.500519,0.000000
74.990005,64.992783,-317.905365,-0.000815,0.004145,0.105281,289.102325,14.727575,1.052814,-317.905365,294.500519,0.000000
75.380005,66.388062,-317.994324,-0.000811,0.004130,0.104891,295.308838,15.043750,1.048908,-317.994324,294.500519,0.000000
75.770004,65.998550,-318.038788,-0.000802,0.004130,0.104891,293.576202,14.955485,1.048908,-318.038788,294.500519,0.000000
76.160004,65.663422,-318.038788,-0.000802,0.004130,0.104899,292.085480,14.879544,1.048991,-318.038788,294.500519,0.000000
76.550003,65.361053,-318.127777,-0.000793,0.004131,0.104917,290.740479,14.811027,1.049165,-318.127777,294.500519,0.000000
76.940002,65.108963,-318.083282,-0.000798,0.004131,0.104926,289.619141,14.753901,1.049256,-318.083282,294.500519,0.000000
77.330002,66.080841,-318.172241,-0.000798,0.004162,0.105723,293.942261,14.974133,1.057235,-318.172241,294.500519,0.000000
77.720001,65.809753,-318.216736,-0.000798,0.004162,0.105723,292.736389,14.912704,1.057235,-318.216736,294.500519,0.000000
78.110001,65.593414,-318.172241,-0.000785,0.004162,0.105723,291.774078,14.863680,1.057235,-318.172241,294.500519,0.000000
78.500000,65.384506,-318.261200,-0.000793,0.004162,0.105723,290.844818,14.816340,1.057235,-318.261200,294.500519,0.000000
78.890007,65.240768,-318.216736,-0.000789,0.004163,0.105732,290.205444,14.783769,1.057318,-318.216736,294.500519,0.000000
79.280006,65.028900,-318.305695,-0.000785,0.004163,0.105732,289.263000,14.735760,1.057318,-318.305695,294.500519,0.000000
79.670006,64.870270,-318.350159,-0.000798,0.004163,0.105732,288.557373,14.699814,1.057318,-318.350159,294.500519,0.000000
80.060005,66.470718,-318.261200,-0.000798,0.004156,0.105568,295.676514,15.062480,1.055675,-318.261200,294.500519,0.000000
80.450005,66.334427,-318.350159,-0.000776,0.004156,0.105568,295.070282,15.031596,1.055675,-318.350159,294.500519,0.000000
80.840004,66.188843,-318.350159,-0.000780,0.004156,0.105568,294.422668,14.998606,1.055675,-318.350159,294.500519,0.000000
81.230003,66.038391,-318.394653,-0.000789,0.004156,0.105568,293.753448,14.964513,1.055675,-318.394653,294.500519,0.000000
81.620003,65.864502,-318.439117,-0.000776,0.004156,0.105568,292.979950,14.925110,1.055675,-318.439117,294.500519,0.000000
82.010002,65.801193,-318.439117,-0.000785,0.004156,0.105568,292.698334,14.910763,1.055675,-318.439117,294.500519,0.000000
82.400002,65.655975,-318.483612,-0.000776,0.004156,0.105568,292.052368,14.877856,1.055675,-318.483612,294.500519,0.000000
82.790001,65.564362,-318.483612,-0.000767,0.004157,0.105593,291.644836,14.857098,1.055933,-318.483612,294.500519,0.000000
83.180000,65.476120,-318.572571,-0.000780,0.004170,0.105923,291.252319,14.837101,1.059226,-318.572571,294.500519,0.000000
83.570007,65.358810,-318.572571,-0.000776,0.004176,0.106070,290.730499,14.810518,1.060702,-318.572571,294.500519,0.000000
83.960007,65.302216,-318.483612,-0.000772,0.004179,0.106140,290.478760,14.797693,1.061398,-318.483612,294.500519,0.000000
84.350006,65.231461,-318.661530,-0.000776,0.004179,0.106148,290.164032,14.781660,1.061481,-318.661530,294.500519,0.000000
84.740005,65.367752,-318.617065,-0.000776,0.004185,0.106287,290.770294,14.812545,1.062867,-318.617065,294.500519,0.000000
85.130005,65.321213,-318.661530,-0.000767,0.004185,0.106287,290.563263,14.801998,1.062867,-318.661530,294.500519,0.000000
85.520004,65.274658,-318.706024,-0.000785,0.004185,0.106287,290.356171,14.791450,1.062867,-318.706024,294.500519,0.000000
85.910004,65.222900,-318.661530,-0.000785,0.004185,0.106296,290.125946,14.779721,1.062958,-318.661530,294.500519,0.000000
86.300003,65.318970,-318.750488,-0.000785,0.004188,0.106374,290.553284,14.801490,1.063737,-318.750488,294.500519,0.000000
86.690002,65.296265,-318.706024,-0.000759,0.004188,0.106374,290.452301,14.796345,1.063737,-318.706024,294.500519,0.000000
87.080002,65.307434,-318.706024,-0.000776,0.004189,0.106409,290.501984,14.798876,1.064085,-318.706024,294.500519,0.000000
87.470001,65.275040,-318.794983,-0.000776,0.004189,0.106409,290.357880,14.791535,1.064085,-318.794983,294.500519,0.000000
87.860001,65.253815,-318.794983,-0.000772,0.004189,0.106409,290.263458,14.786726,1.064085,-318.794983,294.500519,0.000000
88.250008,65.245621,-318.883942,-0.000767,0.004191,0.106452,290.227020,14.784869,1.064517,-318.883942,294.500519,0.000000
88.640007,65.253067,-318.794983,-0.000772,0.004191,0.106452,290.260132,14.786556,1.064517,-318.794983,294.500519,0.000000
89.030006,65.226624,-318.883942,-0.000776,0.004191,0.106452,290.142517,14.780564,1.064517,-318.883942,294.500519,0.000000
89.420006,65.224396,-318.972900,-0.000772,0.004192,0.106469,290.132599,14.780060,1.064691,-318.972900,294.500519,0.000000
89.810005,65.190140,-318.883942,-0.000772,0.004192,0.106469,289.980225,14.772296,1.064691,-318.883942,294.500519,0.000000
90.200005,65.148804,-318.972900,-0.000772,0.004192,0.106469,289.796356,14.762930,1.064691,-318.972900,294.500519,0.000000
90.590004,65.703629,-319.061859,-0.000776,0.004200,0.106686,292.264343,14.888655,1.066856,-319.061859,294.500519,0.000000
90.980003,65.753540,-318.972900,-0.000776,0.004199,0.106642,292.486359,14.899965,1.066424,-318.972900,294.500519,0.000000
91.370003,65.662674,-319.061859,-0.000763,0.004199,0.106642,292.082153,14.879375,1.066424,-319.061859,294.500519,0.000000
91.760002,65.612030,-319.061859,-0.000772,0.004199,0.106642,291.856873,14.867899,1.066424,-319.061859,294.500519,0.000000
92.150002,65.590057,-319.150818,-0.000776,0.004199,0.106642,291.759155,14.862919,1.066424,-319.150818,294.500519,0.000000
92.540001,65.561020,-319.150818,-0.000763,0.004199,0.106642,291.629974,14.856339,1.066424,-319.150818,294.500519,0.000000
92.930008,65.533829,-319.150818,-0.000755,0.004199,0.106642,291.509033,14.850178,1.066424,-319.150818,294.500519,0.000000
93.320007,65.491379,-319.150818,-0.000767,0.004199,0.106642,291.320190,14.840559,1.066424,-319.150818,294.500519,0.000000
93.710007,65.416901,-319.150818,-0.000763,0.004199,0.106642,290.988922,14.823681,1.066424,-319.150818,294.500519,0.000000
94.100006,65.373718,-319.150818,-0.000780,0.004199,0.106642,290.796814,14.813896,1.066424,-319.150818,294.500519,0.000000
94.490005,65.336105,-319.239777,-0.000767,0.004199,0.106642,290.629517,14.805373,1.066424,-319.239777,294.500519,0.000000
94.880005,65.311157,-319.239777,-0.000776,0.004199,0.106642,290.518524,14.799720,1.066424,-319.239777,294.500519,0.000000
95.270004,65.271683,-319.328735,-0.000772,0.004199,0.106642,290.342957,14.790774,1.066424,-319.328735,294.500519,0.000000
95.660004,65.267593,-319.239777,-0.000759,0.004199,0.106642,290.324768,14.789847,1.066424,-319.239777,294.500519,0.000000
96.050003,65.224396,-319.328735,-0.000767,0.004199,0.106642,290.132599,14.780060,1.066424,-319.328735,294.500519,0.000000
96.440002,65.171509,-319.328735,-0.000763,0.004199,0.106652,289.897339,14.768075,1.066515,-319.328735,294.500519,0.000000
96.830002,65.155502,-319.373230,-0.000772,0.004199,0.106652,289.826141,14.764448,1.066515,-319.373230,294.500519,0.000000
97.220001,65.104111,-319.417725,-0.000772,0.004199,0.106652,289.597534,14.752803,1.066515,-319.417725,294.500519,0.000000
97.610008,65.062775,-319.462189,-0.000763,0.004199,0.106652,289.413666,14.743436,1.066515,-319.462189,294.500519,0.000000
98.000008,65.046021,-319.462189,-0.000780,0.004199,0.106652,289.339142,14.739638,1.066515,-319.462189,294.500519,0.000000
98.390007,65.027771,-319.551147,-0.000772,0.004199,0.106652,289.257965,14.735503,1.066515,-319.551147,294.500519,0.000000
98.780006,64.985703,-319.462189,-0.000763,0.004199,0.106652,289.070831,14.725970,1.066515,-319.462189,294.500519,0.000000
99.170006,64.977875,-319.551147,-0.000772,0.004199,0.106652,289.036011,14.724196,1.066515,-319.551147,294.500519,0.000000
99.560005,64.941757,-319.551147,-0.000763,0.004199,0.106652,288.875366,14.716012,1.066515,-319.551147,294.500519,0.000000
99.950005,64.922028,-319.551147,-0.000763,0.004199,0.106652,288.787598,14.711542,1.066515,-319.551147,294.500519,0.000000
100.340004,64.874359,-319.551147,-0.000767,0.004199,0.106652,288.575562,14.700740,1.066515,-319.551147,294.500519,0.000000
100.730003,64.830414,-319.595642,-0.000763,0.004199,0.106652,288.380096,14.690782,1.066515,-319.595642,294.500519,0.000000
101.120003,64.799881,-319.640106,-0.000780,0.004199,0.106652,288.244263,14.683863,1.066515,-319.640106,294.500519,0.000000
101.510002,64.779404,-319.640106,-0.000767,0.004199,0.106652,288.153168,14.679223,1.066515,-319.640106,294.500519,0.000000
101.900002,64.746262,-319.729065,-0.000767,0.004199,0.106652,288.005768,14.671712,1.066515,-319.729065,294.500519,0.000000
102.290009,64.720200,-319.729065,-0.000759,0.004199,0.106652,287.889832,14.665807,1.066515,-319.729065,294.500519,0.000000
102.680008,64.704559,-319.729065,-0.000772,0.004199,0.106652,287.820251,14.662263,1.066515,-319.729065,294.500519,0.000000
103.070007,64.672913,-319.818024,-0.000763,0.004199,0.106652,287.679474,14.655091,1.066515,-319.818024,294.500519,0.000000
103.460007,64.638657,-319.818024,-0.000755,0.004199,0.106652,287.527100,14.647329,1.066515,-319.818024,294.500519,0.000000
103.850006,64.610352,-319.818024,-0.000763,0.004199,0.106652,287.401184,14.640915,1.066515,-319.818024,294.500519,0.000000
104.240005,64.580566,-319.862518,-0.000759,0.004199,0.106652,287.268707,14.634166,1.066515,-319.862518,294.500519,0.000000
104.630005,64.548538,-319.907013,-0.000763,0.004199,0.106652,287.126251,14.626907,1.066515,-319.907013,294.500519,0.000000
105.020004,64.521347,-319.907013,-0.000780,0.004199,0.106652,287.005280,14.620746,1.066515,-319.907013,294.500519,0.000000
105.410004,64.481888,-319.951477,-0.000772,0.004199,0.106652,286.829773,14.611805,1.066515,-319.951477,294.500519,0.000000
105.800003,64.473312,-319.951477,-0.000772,0.004199,0.106652,286.791626,14.609861,1.066515,-319.951477,294.500519,0.000000
106.190002,64.458054,-319.995972,-0.000759,0.004199,0.106652,286.723755,14.606404,1.066515,-319.995972,294.500519,0.000000
106.580002,64.418945,-319.951477,-0.000767,0.004199,0.106652,286.549774,14.597542,1.066515,-319.951477,294.500519,0.000000
106.970009,64.391022,-319.995972,-0.000767,0.004199,0.106652,286.425568,14.591214,1.066515,-319.995972,294.500519,0.000000
107.360008,64.391388,-319.995972,-0.000755,0.004199,0.106652,286.427185,14.591296,1.066515,-319.995972,294.500519,0.000000
107.750008,64.350433,-320.040436,-0.000767,0.004199,0.106652,286.245026,14.582017,1.066515,-320.040436,294.500519,0.000000
108.140007,64.316544,-320.084930,-0.000763,0.004199,0.106652,286.094269,14.574337,1.066515,-320.084930,294.500519,0.000000
108.530006,64.301651,-320.084930,-0.000767,0.004199,0.106652,286.028015,14.570963,1.066515,-320.084930,294.500519,0.000000
108.920006,64.268509,-320.129395,-0.000772,0.004199,0.106652,285.880615,14.563452,1.066515,-320.129395,294.500519,0.000000
109.310005,64.247284,-320.173889,-0.000763,0.004199,0.106652,285.786194,14.558642,1.066515,-320.173889,294.500519,0.000000
109.700005,64.223831,-320.084930,-0.000776,0.004199,0.106652,285.681854,14.553328,1.066515,-320.084930,294.500519,0.000000
110.090004,64.214890,-320.218353,-0.000763,0.004199,0.106652,285.642090,14.551302,1.066515,-320.218353,294.500519,0.000000
110.480003,64.194778,-320.262848,-0.000746,0.004199,0.106652,285.552643,14.546744,1.066515,-320.262848,294.500519,0.000000
110.870003,64.159027,-320.307343,-0.000767,0.004199,0.106652,285.393616,14.538644,1.066515,-320.307343,294.500519,0.000000
111.260002,64.156052,-320.307343,-0.000763,0.004199,0.106652,285.380371,14.537969,1.066515,-320.307343,294.500519,0.000000
111.650002,64.138931,-320.351807,-0.000755,0.004199,0.106652,285.304230,14.534090,1.066515,-320.351807,294.500519,0.000000
112.040009,68.309875,-320.351807,-0.000767,0.004186,0.106313,303.857513,15.479239,1.063132,-320.351807,294.500519,0.000000
112.430008,65.953125,-320.351807,-0.000733,0.004019,0.102090,293.374146,14.945192,1.020900,-320.351807,294.500519,0.000000
112.820007,65.924454,-320.396301,-0.000733,0.004021,0.102133,293.246613,14.938695,1.021331,-320.396301,294.500519,0.000000
113.210007,65.870453,-320.485260,-0.000729,0.004039,0.102584,293.006409,14.926458,1.025843,-320.485260,294.500519,0.000000
113.600006,65.818329,-320.351807,-0.000729,0.004043,0.102688,292.774536,14.914647,1.026880,-320.351807,294.500519,0.000000
113.990005,65.788162,-320.440765,-0.000724,0.004043,0.102697,292.640350,14.907811,1.026971,-320.440765,294.500519,0.000000
114.380005,65.778488,-320.529724,-0.000729,0.004050,0.102870,292.597321,14.905619,1.028704,-320.529724,294.500519,0.000000
114.770004,65.785187,-320.440765,-0.000729,0.004050,0.102870,292.627136,14.907136,1.028704,-320.440765,294.500519,0.000000
115.160004,65.768051,-320.618683,-0.000724,0.004051,0.102888,292.550903,14.903254,1.028878,-320.618683,294.500519,0.000000
115.550003,65.757629,-320.529724,-0.000733,0.004051,0.102888,292.504547,14.900892,1.028878,-320.529724,294.500519,0.000000
115.940002,65.686874,-320.618683,-0.000733,0.004061,0.103147,292.189819,14.884859,1.031475,-320.618683,294.500519,0.000000
116.330002,65.687256,-320.529724,-0.000729,0.004095,0.104006,292.191498,14.884945,1.040059,-320.529724,294.500519,0.000000
116.720009,65.653366,-320.574219,-0.000724,0.004096,0.104050,292.040771,14.877266,1.040498,-320.574219,294.500519,0.000000
117.110008,65.634003,-320.618683,-0.000742,0.004096,0.104050,291.954620,14.872878,1.040498,-320.618683,294.500519,0.000000
117.500008,65.598633,-320.663177,-0.000733,0.004096,0.104050,291.797302,14.864862,1.040498,-320.663177,294.500519,0.000000
117.890007,65.579269,-320.707672,-0.000733,0.004096,0.104050,291.711151,14.860475,1.040498,-320.707672,294.500519,0.000000
118.280006,65.581497,-320.663177,-0.000729,0.004096,0.104050,291.721069,14.860980,1.040498,-320.663177,294.500519,0.000000
118.670006,65.566971,-320.752136,-0.000724,0.004096,0.104050,291.656464,14.857688,1.040498,-320.752136,294.500519,0.000000
119.060005,65.557297,-320.796631,-0.000724,0.004109,0.104379,291.613434,14.855495,1.043791,-320.796631,294.500519,0.000000
119.450005,65.539047,-320.796631,-0.000733,0.004109,0.104379,291.532257,14.851360,1.043791,-320.796631,294.500519,0.000000
119.840004,65.546494,-320.841095,-0.000729,0.004175,0.106053,291.565369,14.853048,1.060528,-320.841095,294.500519,0.000000
120.230003,65.531219,-320.885590,-0.000716,0.004176,0.106070,291.497437,14.849586,1.060702,-320.885590,294.500519,0.000000
120.620003,65.514465,-320.885590,-0.000729,0.004177,0.106088,291.422882,14.845790,1.060876,-320.885590,294.500519,0.000000
121.010002,65.513351,-320.974548,-0.000742,0.004178,0.106131,291.417938,14.845537,1.061307,-320.974548,294.500519,0.000000
121.400009,65.495102,-320.930054,-0.000742,0.004178,0.106131,291.336761,14.841402,1.061307,-320.930054,294.500519,0.000000
121.790009,65.460480,-320.974548,-0.000733,0.004179,0.106140,291.182770,14.833556,1.061398,-320.974548,294.500519,0.000000
122.180008,65.451172,-321.063507,-0.000729,0.004179,0.106148,291.141357,14.831448,1.061481,-321.063507,294.500519,0.000000
122.570007,65.428085,-321.019012,-0.000746,0.004180,0.106175,291.038666,14.826216,1.061746,-321.019012,294.500519,0.000000
122.960007,65.427338,-321.107971,-0.000733,0.004182,0.106218,291.035339,14.826047,1.062178,-321.107971,294.500519,0.000000
123.350006,65.407227,-321.063507,-0.000733,0.004182,0.106226,290.945862,14.821489,1.062261,-321.063507,294.500519,0.000000
123.740005,65.385635,-321.063507,-0.000720,0.004182,0.106235,290.849823,14.816596,1.062352,-321.063507,294.500519,0.000000
124.130005,65.468292,-321.107971,-0.000724,0.004192,0.106469,291.217499,14.835327,1.064691,-321.107971,294.500519,0.000000
124.520004,65.433289,-321.107971,-0.000729,0.004193,0.106495,291.061798,14.827395,1.064948,-321.107971,294.500519,0.000000
124.910004,65.410950,-321.196960,-0.000746,0.004193,0.106495,290.962433,14.822333,1.064948,-321.196960,294.500519,0.000000
125.300003,65.393448,-321.196960,-0.000729,0.004193,0.106495,290.884583,14.818367,1.064948,-321.196960,294.500519,0.000000
125.690002,65.371475,-321.152466,-0.000733,0.004193,0.106495,290.786835,14.813388,1.064948,-321.152466,294.500519,0.000000
126.080009,65.362915,-321.374878,-0.000737,0.004193,0.106504,290.748779,14.811448,1.065039,-321.374878,294.500519,0.000000
126.470009,65.367004,-321.196960,-0.000742,0.004198,0.106625,290.766968,14.812375,1.066250,-321.196960,294.500519,0.000000
126.860008,65.403137,-321.285919,-0.000737,0.004199,0.106652,290.927673,14.820562,1.066515,-321.285919,294.500519,0.000000
127.250008,65.401642,-321.374878,-0.000742,0.004199,0.106652,290.921021,14.820224,1.066515,-321.374878,294.500519,0.000000
127.640007,65.378555,-321.285919,-0.000729,0.004199,0.106652,290.818329,14.814992,1.066515,-321.285919,294.500519,0.000000
128.029999,65.361801,-321.330383,-0.000737,0.004199,0.106652,290.743805,14.811195,1.066515,-321.330383,294.500519,0.000000
128.420013,65.349136,-321.374878,-0.000724,0.004201,0.106695,290.687469,14.808326,1.066947,-321.374878,294.500519,0.000000
128.810013,65.367004,-321.374878,-0.000742,0.004201,0.106703,290.766968,14.812375,1.067030,-321.374878,294.500519,0.000000
129.200012,65.352112,-321.463837,-0.000729,0.004201,0.106703,290.700714,14.809001,1.067030,-321.463837,294.500519,0.000000
129.590012,65.345779,-321.419342,-0.000729,0.004201,0.106703,290.672546,14.807566,1.067030,-321.419342,294.500519,0.000000
129.980011,65.337967,-321.463837,-0.000737,0.004201,0.106703,290.637787,14.805795,1.067030,-321.463837,294.500519,0.000000
130.370010,65.324936,-321.463837,-0.000711,0.004201,0.106703,290.579834,14.802841,1.067030,-321.463837,294.500519,0.000000
130.760010,65.318970,-321.508301,-0.000746,0.004201,0.106703,290.553284,14.801490,1.067030,-321.508301,294.500519,0.000000
131.150009,65.304459,-321.597290,-0.000729,0.004201,0.106703,290.488739,14.798202,1.067030,-321.597290,294.500519,0.000000
131.540009,65.298859,-321.552795,-0.000733,0.004201,0.106703,290.463837,14.796933,1.067030,-321.552795,294.500519,0.000000
131.930008,65.295135,-321.641754,-0.000724,0.004201,0.106712,290.447266,14.796089,1.067121,-321.641754,294.500519,0.000000
132.320007,65.273911,-321.597290,-0.000729,0.004201,0.106712,290.352844,14.791280,1.067121,-321.597290,294.500519,0.000000
132.710007,65.264984,-321.552795,-0.000729,0.004202,0.106729,290.313141,14.789257,1.067295,-321.552795,294.500519,0.000000
133.100006,65.269073,-321.730713,-0.000742,0.004202,0.106738,290.331329,14.790184,1.067378,-321.730713,294.500519,0.000000
133.490005,65.264236,-321.686249,-0.000720,0.004196,0.106574,290.309814,14.789087,1.065736,-321.686249,0.106712,0.000000
133.880005,65.174500,-321.686249,-0.000724,0.004187,0.106339,289.910645,14.768753,1.063389,-321.686249,0.106062,0.000000
134.270004,65.135773,-321.730713,-0.000733,0.004172,0.105966,289.738373,14.759977,1.059665,-321.730713,0.105411,0.000000
134.660004,65.099640,-321.730713,-0.000724,0.004146,0.105307,289.577667,14.751789,1.053071,-321.730713,0.104770,0.000000
135.050003,65.080658,-321.819672,-0.000733,0.004117,0.104579,289.493225,14.747488,1.045789,-321.819672,0.104119,0.000000
135.440002,65.092194,-321.819672,-0.000729,0.004093,0.103954,289.544525,14.750102,1.039544,-321.819672,0.103468,0.000000
135.830002,65.061295,-321.819672,-0.000729,0.004070,0.103390,289.407104,14.743100,1.033905,-321.819672,0.102818,0.000000
136.220001,65.057938,-321.819672,-0.000724,0.004046,0.102758,289.392151,14.742340,1.027576,-321.819672,0.102168,0.000000
136.610001,65.028900,-321.864166,-0.000733,0.004019,0.102090,289.263000,14.735760,1.020900,-321.864166,0.101517,0.000000
137.000000,64.956284,-321.953125,-0.000729,0.003995,0.101474,288.939972,14.719304,1.014738,-321.953125,0.100867,0.000000
137.389999,64.659882,-321.864166,-0.000729,0.003973,0.100902,287.621521,14.652138,1.009015,-321.864166,0.100216,0.000000
137.780014,63.626175,-321.908630,-0.000733,0.003951,0.100347,283.023376,14.417897,1.003466,-321.908630,0.099566,0.000000
138.170013,62.403297,-321.997620,-0.000724,0.003928,0.099765,277.583740,14.140789,0.997653,-321.997620,0.098916,0.000000
138.560013,61.291763,-321.997620,-0.000729,0.003909,0.099280,272.639374,13.888911,0.992801,-321.997620,0.098265,0.000000
138.950012,59.025505,-322.042084,-0.000707,0.003874,0.098395,262.558563,13.375370,0.983952,-322.042084,0.097615,0.000000
139.340012,57.505852,-321.997620,-0.000720,0.003854,0.097893,255.798798,13.031013,0.978925,-321.997620,0.096964,0.000000
139.730011,55.335670,-322.131042,-0.000716,0.003830,0.097285,246.145355,12.539242,0.972854,-322.131042,0.096314,0.000000
140.120010,53.499496,-322.131042,-0.000711,0.003811,0.096791,237.977646,12.123159,0.967911,-322.131042,0.095663,0.000000
140.510010,50.774475,-322.086578,-0.000724,0.003779,0.095993,225.856140,11.505660,0.959933,-322.086578,0.095013,0.000000
140.900009,47.947052,-322.131042,-0.000716,0.003752,0.095299,213.279144,10.864957,0.952991,-322.131042,0.094363,0.000000
141.290009,45.592545,-322.131042,-0.000716,0.003733,0.094822,202.805771,10.331419,0.948222,-322.131042,0.093712,0.000000
141.680008,42.604630,-322.175537,-0.000711,0.003704,0.094094,189.514862,9.654346,0.940940,-322.175537,0.093061,0.000000
142.070007,39.728790,-322.220001,-0.000716,0.003678,0.093417,176.722488,9.002672,0.934173,-322.220001,0.092411,0.000000
142.460007,37.366837,-322.175537,-0.000711,0.003659,0.092949,166.215988,8.467446,0.929495,-322.175537,0.091761,0.000000
142.850006,33.917175,-322.308960,-0.000716,0.003625,0.092082,150.871124,7.685742,0.920820,-322.308960,0.091111,0.000000
143.240005,31.608841,-322.264496,-0.000707,0.003608,0.091631,140.603149,7.162666,0.916308,-322.264496,0.090461,0.000000
143.630005,28.281693,-322.308960,-0.000711,0.003577,0.090868,125.803253,6.408723,0.908678,-322.308960,0.089819,0.000000
144.020004,25.240898,-322.353455,-0.000716,0.003550,0.090165,112.277122,5.719669,0.901653,-322.353455,0.089168,0.000000
144.410004,23.078903,-322.353455,-0.000724,0.003531,0.089697,102.660088,5.229754,0.896967,-322.353455,0.088517,0.000000
144.800003,19.319801,-322.486908,-0.000724,0.003496,0.088795,85.938766,4.377930,0.887951,-322.486908,0.087867,0.000000
145.190002,16.975716,-322.442413,-0.000716,0.003477,0.088309,75.511757,3.846752,0.883092,-322.442413,0.087217,0.000000
145.580002,14.751907,-322.353455,-0.000707,0.003458,0.087824,65.619759,3.342830,0.878239,-322.353455,0.086567,0.000000
145.970001,10.871788,-322.442413,-0.000711,0.003422,0.086913,48.360130,2.463583,0.869133,-322.442413,0.085916,0.000000
146.360001,8.190704,-322.442413,-0.000716,0.003395,0.086228,36.434074,1.856040,0.862282,-322.442413,0.085265,0.000000
146.750000,4.971550,-322.575867,-0.000711,0.003367,0.085517,22.114559,1.126569,0.855167,-322.575867,0.084615,0.000000
147.139999,2.874344,-322.575867,-0.000716,0.003347,0.085022,12.785720,0.651336,0.850224,-322.575867,0.083965,0.000000
147.530014,0.025322,-322.531372,-0.000711,0.003320,0.084337,0.112638,0.005738,0.843373,-322.531372,0.083314,0.000000
147.920013,-0.959229,-322.620331,-0.000724,0.003305,0.083956,-4.266861,-0.217364,0.839558,-322.620331,0.082664,0.000000
148.310013,-0.158630,-322.575867,-0.000711,0.003272,0.083106,-0.705623,-0.035946,0.831057,-322.575867,0.082013,0.000000
148.700012,-0.149315,-322.664825,-0.000729,0.003245,0.082412,-0.664186,-0.033835,0.824123,-322.664825,0.081363,0.000000
149.090012,-0.141869,-322.709290,-0.000729,0.003219,0.081762,-0.631063,-0.032148,0.817621,-322.709290,0.080713,0.000000
149.480011,-0.097183,-322.664825,-0.000720,0.003197,0.081198,-0.432293,-0.022022,0.811981,-322.664825,0.080062,0.000000
149.870010,-0.117294,-322.709290,-0.000724,0.003170,0.080513,-0.521751,-0.026579,0.805130,-322.709290,0.079412,0.000000
150.260010,-0.129585,-322.753784,-0.000720,0.003139,0.079741,-0.576424,-0.029364,0.797409,-322.753784,0.078761,0.000000
150.650009,-0.143364,-322.798248,-0.000737,0.003113,0.079073,-0.637715,-0.032487,0.790733,-322.798248,0.078111,0.000000
151.040009,-0.162727,-322.798248,-0.000737,0.003088,0.078440,-0.723847,-0.036875,0.784404,-322.798248,0.077460,0.000000
151.430008,-0.098305,-322.842743,-0.000759,0.003070,0.077972,-0.437281,-0.022276,0.779719,-322.842743,0.076810,0.000000
151.820007,-0.147827,-322.798248,-0.000785,0.003042,0.077278,-0.657568,-0.033498,0.772785,-322.798248,0.076160,0.000000
152.210007,-0.150810,-322.931702,-0.000811,0.003023,0.076792,-0.670837,-0.034174,0.767925,-322.931702,0.075509,0.000000
152.600006,-0.117294,-322.887238,-0.000849,0.002983,0.075778,-0.521751,-0.026579,0.757781,-322.887238,0.074867,0.000000
152.990005,-0.151176,-322.976196,-0.000871,0.002960,0.075188,-0.672466,-0.034257,0.751885,-322.976196,0.074217,0.000000
153.380005,-0.138145,-322.931702,-0.000914,0.002933,0.074486,-0.614502,-0.031304,0.744860,-322.931702,0.073566,0.000000
153.770004,-0.149315,-323.020660,-0.000944,0.002921,0.074182,-0.664186,-0.033835,0.741824,-323.020660,0.072916,0.000000
154.160004,-0.146339,-323.020660,-0.000966,0.002888,0.073367,-0.650950,-0.033161,0.733672,-323.020660,0.072266,0.000000
154.550003,-0.119904,-322.976196,-0.001013,0.002855,0.072517,-0.533358,-0.027171,0.725171,-322.976196,0.071616,0.000000
154.940002,-0.132187,-323.109619,-0.001035,0.002835,0.072014,-0.587997,-0.029954,0.720144,-323.109619,0.070965,0.000000
155.330002,-0.126976,-323.065155,-0.001048,0.002815,0.071503,-0.564817,-0.028773,0.715027,-323.065155,0.070314,0.000000
155.720001,-0.135910,-323.154114,-0.001082,0.002779,0.070583,-0.604558,-0.030798,0.705830,-323.154114,0.069664,0.000000
156.110001,-0.118408,-323.154114,-0.001108,0.002761,0.070133,-0.526706,-0.026832,0.701326,-323.154114,0.069014,0.000000
156.500000,-0.106125,-323.109619,-0.001151,0.002729,0.069308,-0.472067,-0.024048,0.693082,-323.109619,0.068364,0.000000
156.890015,-0.086014,-323.287567,-0.001173,0.002699,0.068563,-0.382608,-0.019491,0.685626,-323.287567,0.067713,0.000000
157.280014,-0.071121,-323.198578,-0.001216,0.002675,0.067956,-0.316363,-0.016116,0.679555,-323.198578,0.067062,0.000000
157.670013,-0.092720,-323.243073,-0.001224,0.002656,0.067470,-0.412439,-0.021011,0.674703,-323.243073,0.066412,0.000000
158.060013,-0.093086,-323.243073,-0.001263,0.002626,0.066707,-0.414068,-0.021094,0.667065,-323.243073,0.065762,0.000000
158.450012,-0.099045,-323.287567,-0.001302,0.002600,0.066039,-0.440573,-0.022444,0.660388,-323.287567,0.065111,0.000000
158.840012,-0.078941,-323.332031,-0.001319,0.002579,0.065519,-0.351149,-0.017888,0.655188,-323.332031,0.064461,0.000000
159.230011,-0.083405,-323.420990,-0.001332,0.002552,0.064825,-0.371002,-0.018900,0.648247,-323.420990,0.063810,0.000000
159.500000,-0.100906,-323.332031,-0.001362,0.002543,0.064600,-0.448854,-0.022866,0.645998,-323.332031,0.064513,0.000000