File: Data/compression 23/AutoNoHeating-12-23-reverse-2-5_09192024_185240.csv
Time (sec),S:Load (lbs),S:HL1 (DIM),S:LVDT (in),S:Position (in),Ch:Position (mm),Ch:Load (N),Ch:Stress (MPa),Ch:Strain (mm/mm),Ch:HL1 (DIM),Set Point (),Cycles ()
0.110000,-0.180969,-409.580597,-0.011042,-0.006117,-0.155381,-0.804991,-0.041008,-1.553805,-409.580597,-0.155147,0.000000
0.540000,-0.082291,-409.580597,-0.011046,-0.006058,-0.153880,-0.366047,-0.018647,-1.538802,-409.580597,-0.153169,0.000000
0.970000,-0.110588,-409.536102,-0.010908,-0.005800,-0.147315,-0.491920,-0.025060,-1.473149,-409.536102,-0.146006,0.000000
1.400000,-0.142990,-409.580597,-0.010611,-0.005514,-0.140048,-0.636052,-0.032402,-1.400479,-409.580597,-0.138843,0.000000
1.830000,-0.165703,-409.714050,-0.010330,-0.005243,-0.133171,-0.737083,-0.037549,-1.331708,-409.714050,-0.131680,0.000000
2.260000,-0.086014,-409.669556,-0.010037,-0.004954,-0.125842,-0.382608,-0.019491,-1.258425,-409.669556,-0.124516,0.000000
2.690000,-0.062553,-409.669556,-0.009766,-0.004675,-0.118749,-0.278251,-0.014175,-1.187488,-409.669556,-0.117353,0.000000
3.120000,-0.106865,-409.669556,-0.009468,-0.004386,-0.111412,-0.475359,-0.024216,-1.114122,-409.669556,-0.110190,0.000000
3.550000,-0.129585,-409.714050,-0.009166,-0.004104,-0.104241,-0.576424,-0.029364,-1.042405,-409.714050,-0.103026,0.000000
3.980000,-0.129211,-409.803009,-0.008890,-0.003830,-0.097285,-0.574761,-0.029280,-0.972847,-409.803009,-0.095863,0.000000
4.410000,-0.097557,-409.803009,-0.008589,-0.003542,-0.089975,-0.433956,-0.022107,-0.899745,-409.803009,-0.088700,0.000000
4.840000,-0.070374,-409.803009,-0.008304,-0.003261,-0.082829,-0.313037,-0.015947,-0.828286,-409.803009,-0.081536,0.000000
5.270000,-0.127724,-409.803009,-0.008006,-0.002977,-0.075621,-0.568143,-0.028943,-0.756214,-409.803009,-0.074373,0.000000
5.700000,-0.137032,-409.803009,-0.007718,-0.002688,-0.068267,-0.609547,-0.031052,-0.682674,-409.803009,-0.067210,0.000000
6.130000,-0.119530,-409.758514,-0.007416,-0.002417,-0.061382,-0.531695,-0.027086,-0.613819,-409.758514,-0.060047,0.000000
6.560000,-0.096443,-409.936432,-0.007127,-0.002128,-0.054063,-0.429001,-0.021854,-0.540627,-409.936432,-0.052883,0.000000
6.990000,-0.071121,-409.891968,-0.006838,-0.001852,-0.047047,-0.316363,-0.016116,-0.470470,-409.891968,-0.045720,0.000000
7.420001,-0.117668,-409.980927,-0.006554,-0.001570,-0.039884,-0.523414,-0.026664,-0.398837,-409.980927,-0.038557,0.000000
7.850000,-0.112823,-409.891968,-0.006247,-0.001277,-0.032443,-0.501864,-0.025566,-0.324426,-409.891968,-0.031393,0.000000
8.280001,-0.097183,-409.936432,-0.005967,-0.001007,-0.025583,-0.432293,-0.022022,-0.255829,-409.936432,-0.024230,0.000000
8.710000,-0.071861,-410.025421,-0.005674,-0.000718,-0.018229,-0.319655,-0.016284,-0.182288,-410.025421,-0.017067,0.000000
9.140000,-0.084526,-410.069885,-0.005398,-0.000446,-0.011326,-0.375991,-0.019154,-0.113259,-410.069885,-0.009904,0.000000
9.570001,-0.108360,-410.069885,-0.005101,-0.000162,-0.004119,-0.482011,-0.024555,-0.041187,-410.069885,-0.002740,0.000000
10.000000,-0.090111,-410.025421,-0.004807,0.000128,0.003253,-0.400833,-0.020419,0.032527,-410.025421,0.004423,0.000000
10.430000,-0.091599,-410.069885,-0.004527,0.000401,0.010181,-0.407451,-0.020757,0.101814,-410.069885,0.011586,0.000000
10.860001,-0.076332,-410.114380,-0.004255,0.000686,0.017432,-0.339542,-0.017297,0.174317,-410.114380,0.018750,0.000000
11.290001,-0.086761,-410.114380,-0.003967,0.000966,0.024534,-0.385934,-0.019660,0.245344,-410.114380,0.025913,0.000000
11.720000,0.119537,-410.114380,-0.003678,0.001243,0.031576,0.531729,0.027088,0.315759,-410.114380,0.033024,0.000000
12.150001,0.071495,-410.203339,-0.003665,-0.000000,-0.000000,0.318026,0.016201,-0.000000,-410.203339,0.000242,0.000000
12.580001,0.085274,-410.158844,-0.003673,0.000000,0.000008,0.379317,0.019323,0.000083,-410.158844,0.000763,0.000000
13.010000,0.082298,-410.203339,-0.003673,0.000001,0.000017,0.366081,0.018649,0.000167,-410.203339,0.001483,0.000000
13.440001,0.197357,-410.203339,-0.003635,0.000043,0.001101,0.877889,0.044722,0.011006,-410.203339,0.002202,0.000000
13.870001,0.274445,-410.292297,-0.003617,0.000074,0.001882,1.220791,0.062190,0.018818,-410.292297,0.002914,0.000000
14.300001,0.335510,-410.292297,-0.003596,0.000103,0.002618,1.492424,0.076028,0.026184,-410.292297,0.003633,0.000000
14.730000,0.437538,-410.203339,-0.003557,0.000130,0.003295,1.946267,0.099148,0.032951,-410.203339,0.004353,0.000000
15.160001,0.535103,-410.381256,-0.003518,0.000158,0.004006,2.380256,0.121256,0.040059,-410.381256,0.005064,0.000000
15.590001,0.698944,-410.336761,-0.003497,0.000193,0.004891,3.109059,0.158383,0.048908,-410.336761,0.005784,0.000000
16.020000,0.785339,-410.381256,-0.003475,0.000222,0.005636,3.493364,0.177960,0.056365,-410.381256,0.006504,0.000000
16.450001,0.829651,-410.336761,-0.003449,0.000245,0.006218,3.690471,0.188002,0.062178,-410.336761,0.007215,0.000000
16.880001,1.035942,-410.381256,-0.003410,0.000278,0.007059,4.608100,0.234748,0.070588,-410.381256,0.007935,0.000000
17.310001,1.199043,-410.381256,-0.003393,0.000308,0.007814,5.333611,0.271707,0.078135,-410.381256,0.008646,0.000000
17.740002,1.286552,-410.425720,-0.003359,0.000332,0.008421,5.722871,0.291537,0.084206,-410.425720,0.009365,0.000000
18.170000,1.417625,-410.425720,-0.003346,0.000362,0.009184,6.305913,0.321239,0.091837,-410.425720,0.010085,0.000000
18.600000,1.592644,-410.514709,-0.003307,0.000389,0.009886,7.084433,0.360898,0.098861,-410.514709,0.010797,0.000000
19.030001,1.735634,-410.514709,-0.003285,0.000414,0.010519,7.720485,0.393300,0.105190,-410.514709,0.011517,0.000000
19.460001,1.916977,-410.470215,-0.003255,0.000443,0.011256,8.527140,0.434393,0.112563,-410.470215,0.012237,0.000000
19.890001,2.027199,-410.603668,-0.003221,0.000464,0.011794,9.017430,0.459370,0.117937,-410.603668,0.012947,0.000000
20.320002,2.192535,-410.603668,-0.003216,0.000498,0.012661,9.752885,0.496836,0.126612,-410.603668,0.013667,0.000000
20.750002,2.328445,-410.603668,-0.003195,0.000518,0.013164,10.357443,0.527633,0.131639,-410.603668,0.014387,0.000000
21.180000,2.588737,-410.603668,-0.003152,0.000552,0.014023,11.515280,0.586616,0.140230,-410.603668,0.015098,0.000000
21.610001,2.843811,-410.559174,-0.003122,0.000587,0.014899,12.649903,0.644417,0.148989,-410.559174,0.015818,0.000000
22.040001,2.939880,-410.692627,-0.003083,0.000615,0.015610,13.077241,0.666186,0.156097,-410.692627,0.016538,0.000000
22.470001,3.054947,-410.648132,-0.003061,0.000638,0.016217,13.589083,0.692261,0.162168,-410.648132,0.017249,0.000000
22.900002,3.281349,-410.692627,-0.003044,0.000665,0.016902,14.596170,0.743564,0.169018,-410.692627,0.017968,0.000000
23.330002,3.695053,-410.692627,-0.003027,0.000703,0.017856,16.436417,0.837311,0.178556,-410.692627,0.018680,0.000000
23.760000,3.669365,-410.692627,-0.002984,0.000728,0.018498,16.322151,0.831490,0.184975,-410.692627,0.019400,0.000000
24.190001,3.841400,-410.737091,-0.002979,0.000755,0.019165,17.087400,0.870474,0.191652,-410.737091,0.020119,0.000000
24.620001,4.093124,-410.781586,-0.002932,0.000786,0.019963,18.207127,0.927515,0.199630,-410.781586,0.020831,0.000000
25.050001,4.238350,-410.781586,-0.002928,0.000808,0.020535,18.853123,0.960424,0.205353,-410.781586,0.021550,0.000000
25.480001,4.397346,-410.781586,-0.002893,0.000837,0.021255,19.560373,0.996453,0.212552,-410.781586,0.022270,0.000000
25.910002,4.488205,-410.826050,-0.002863,0.000861,0.021862,19.964533,1.017042,0.218623,-410.826050,0.022981,0.000000
26.340002,4.833771,-410.826050,-0.002820,0.000896,0.022747,21.501686,1.095348,0.227472,-410.826050,0.023701,0.000000
26.770000,4.767860,-410.915039,-0.002811,0.000918,0.023310,21.208502,1.080413,0.233104,-410.915039,0.024421,0.000000
27.200001,5.154007,-410.915039,-0.002772,0.000954,0.024238,22.926168,1.167915,0.242385,-410.915039,0.025132,0.000000
27.630001,5.128693,-410.915039,-0.002751,0.000977,0.024820,22.813564,1.162178,0.248198,-410.915039,0.025852,0.000000
28.060001,5.249336,-410.959503,-0.002725,0.001005,0.025531,23.350214,1.189517,0.255306,-410.959503,0.026571,0.000000
28.490002,5.536438,-410.915039,-0.002682,0.001036,0.026320,24.627306,1.254575,0.263202,-410.915039,0.027282,0.000000
28.920002,5.538300,-411.048462,-0.002682,0.001060,0.026927,24.635588,1.254997,0.269273,-411.048462,0.028002,0.000000
29.350002,5.546494,-411.003998,-0.002652,0.001078,0.027387,24.672035,1.256853,0.273867,-411.003998,0.028714,0.000000
29.780001,5.621712,-411.048462,-0.002634,0.001106,0.028080,25.006622,1.273898,0.280801,-411.048462,0.029434,0.000000
30.210001,6.076752,-411.048462,-0.002600,0.001144,0.029051,27.030741,1.377012,0.290513,-411.048462,0.030153,0.000000
30.640001,6.237244,-411.003998,-0.002557,0.001171,0.029745,27.744646,1.413380,0.297455,-411.003998,0.030864,0.000000
31.070002,6.290489,-411.181915,-0.002531,0.001198,0.030431,27.981493,1.425445,0.304306,-411.181915,0.031584,0.000000
31.500002,6.551155,-411.092957,-0.002514,0.001227,0.031168,29.140993,1.484513,0.311679,-411.092957,0.032304,0.000000
31.930002,6.658768,-411.137421,-0.002483,0.001254,0.031853,29.619678,1.508898,0.318529,-411.137421,0.033015,0.000000
32.360001,6.667336,-411.092957,-0.002483,0.001280,0.032521,29.657789,1.510840,0.325206,-411.092957,0.033735,0.000000
32.790001,7.106735,-411.137421,-0.002436,0.001317,0.033440,31.612337,1.610409,0.334395,-411.137421,0.034455,0.000000
33.220001,7.081413,-411.226379,-0.002423,0.001340,0.034047,31.499699,1.604671,0.340466,-411.226379,0.035165,0.000000
33.650002,7.142105,-411.270874,-0.002384,0.001365,0.034671,31.769670,1.618424,0.346712,-411.270874,0.035885,0.000000
34.080002,7.210251,-411.270874,-0.002354,0.001390,0.035305,32.072796,1.633866,0.353047,-411.270874,0.036605,0.000000
34.510002,7.400536,-411.270874,-0.002350,0.001414,0.035912,32.919228,1.676985,0.359118,-411.270874,0.037316,0.000000
34.940002,7.770302,-411.270874,-0.002307,0.001449,0.036813,34.564030,1.760776,0.368134,-411.270874,0.038036,0.000000
35.370003,8.219009,-411.270874,-0.002276,0.001488,0.037794,36.559978,1.862454,0.377937,-411.270874,0.038756,0.000000
35.800003,8.106552,-411.404327,-0.002251,0.001510,0.038349,36.059746,1.836971,0.383486,-411.404327,0.039467,0.000000
36.230003,8.496429,-411.404327,-0.002225,0.001541,0.039146,37.794006,1.925318,0.391464,-411.404327,0.040187,0.000000
36.660000,8.556007,-411.359833,-0.002195,0.001565,0.039744,38.059021,1.938819,0.397444,-411.359833,0.040898,0.000000
37.090000,9.045677,-411.359833,-0.002169,0.001603,0.040716,40.237183,2.049780,0.407156,-411.359833,0.041618,0.000000
37.520000,9.031151,-411.448792,-0.002139,0.001630,0.041410,40.172565,2.046488,0.414098,-411.448792,0.042338,0.000000
37.950001,9.415810,-411.493286,-0.002104,0.001661,0.042199,41.883614,2.133653,0.421986,-411.493286,0.043049,0.000000
38.380001,9.375595,-411.537750,-0.002095,0.001684,0.042772,41.704731,2.124540,0.427716,-411.537750,0.043769,0.000000
38.810001,9.786697,-411.493286,-0.002057,0.001714,0.043543,43.533405,2.217697,0.435429,-411.493286,0.044488,0.000000
39.240002,10.238754,-411.493286,-0.002026,0.001746,0.044341,45.544254,2.320135,0.443408,-411.493286,0.045199,0.000000
39.670002,10.172844,-411.582245,-0.001996,0.001769,0.044922,45.251068,2.305199,0.449222,-411.582245,0.045919,0.000000
40.100002,10.613365,-411.582245,-0.001975,0.001800,0.045728,47.210606,2.405023,0.457283,-411.582245,0.046639,0.000000
40.530003,10.796570,-411.626709,-0.001957,0.001825,0.046361,48.025539,2.446538,0.463612,-411.626709,0.047350,0.000000
40.960003,10.834923,-411.671204,-0.001932,0.001845,0.046855,48.196144,2.455229,0.468555,-411.671204,0.048070,0.000000
41.390003,11.569984,-411.582245,-0.001919,0.001881,0.047766,51.465862,2.621796,0.477661,-411.582245,0.048790,0.000000
41.820004,11.503334,-411.626709,-0.001867,0.001902,0.048313,51.169384,2.606693,0.483127,-411.626709,0.049501,0.000000
42.250004,12.399261,-411.715698,-0.001854,0.001936,0.049180,55.154671,2.809713,0.491802,-411.715698,0.050221,0.000000
42.680000,12.784294,-411.715698,-0.001828,0.001967,0.049969,56.867382,2.896962,0.499689,-411.715698,0.050932,0.000000
43.110001,13.192039,-411.760162,-0.001785,0.001999,0.050784,58.681122,2.989359,0.507842,-411.760162,0.051652,0.000000
43.540001,13.089264,-411.671204,-0.001763,0.002023,0.051383,58.223953,2.966070,0.513830,-411.671204,0.052372,0.000000
43.970001,13.416954,-411.760162,-0.001733,0.002047,0.051998,59.681591,3.040325,0.519984,-411.760162,0.053082,0.000000
44.400002,13.882790,-411.760162,-0.001729,0.002076,0.052727,61.753731,3.145885,0.527266,-411.760162,0.053802,0.000000
44.830002,14.684509,-411.849121,-0.001681,0.002109,0.053577,65.319962,3.327557,0.535767,-411.849121,0.054522,0.000000
45.260002,14.919853,-411.760162,-0.001664,0.002137,0.054271,66.366821,3.380887,0.542709,-411.760162,0.055233,0.000000
45.690002,15.432236,-411.760162,-0.001634,0.002165,0.054991,68.646011,3.496995,0.549907,-411.760162,0.055953,0.000000
46.120003,15.492935,-411.849121,-0.001613,0.002187,0.055554,68.916016,3.510749,0.555539,-411.849121,0.056673,0.000000
46.550003,16.178101,-411.893616,-0.001582,0.002218,0.056334,71.963783,3.666010,0.563344,-411.893616,0.057384,0.000000
46.980003,16.311035,-411.893616,-0.001561,0.002244,0.056985,72.555107,3.696134,0.569854,-411.893616,0.058103,0.000000
47.410004,17.169724,-411.893616,-0.001552,0.002272,0.057705,76.374748,3.890715,0.577045,-411.893616,0.058823,0.000000
47.840004,18.466698,-411.938080,-0.001522,0.002305,0.058537,82.143974,4.184613,0.585372,-411.938080,0.059535,0.000000
48.270000,18.324455,-411.938080,-0.001505,0.002329,0.059144,81.511246,4.152381,0.591443,-411.938080,0.060255,0.000000
48.700001,19.159309,-412.027039,-0.001466,0.002361,0.059960,85.224861,4.341561,0.599595,-412.027039,0.060975,0.000000
49.130001,19.554024,-412.071533,-0.001444,0.002385,0.060576,86.980644,4.431005,0.605757,-412.071533,0.061685,0.000000
49.560001,19.893257,-412.027039,-0.001436,0.002411,0.061234,88.489624,4.507876,0.612343,-412.027039,0.062405,0.000000
49.990002,20.923241,-412.027039,-0.001397,0.002444,0.062075,93.071220,4.741274,0.620753,-412.027039,0.063116,0.000000
50.420002,21.587555,-412.071533,-0.001384,0.002467,0.062657,96.026237,4.891810,0.626567,-412.071533,0.063836,0.000000
50.850002,22.709137,-412.160492,-0.001350,0.002500,0.063498,101.015289,5.145964,0.634977,-412.160492,0.064556,0.000000
51.280003,22.953789,-412.160492,-0.001332,0.002518,0.063966,102.103554,5.201403,0.639662,-412.160492,0.065267,0.000000
51.710003,23.697044,-412.204987,-0.001324,0.002545,0.064651,105.409721,5.369827,0.646513,-412.204987,0.065987,0.000000
52.140003,25.045029,-412.071533,-0.001298,0.002584,0.065632,111.405853,5.675285,0.656316,-412.071533,0.066707,0.000000
52.570004,25.411446,-412.160492,-0.001276,0.002603,0.066126,113.035759,5.758316,0.661259,-412.160492,0.067418,0.000000
53.000004,26.474197,-412.249451,-0.001263,0.002633,0.066889,117.763115,5.999139,0.668889,-412.249451,0.068137,0.000000
53.430004,26.670807,-412.249451,-0.001233,0.002659,0.067548,118.637672,6.043691,0.675475,-412.249451,0.068857,0.000000
53.860004,29.132187,-412.249451,-0.001220,0.002699,0.068554,129.586441,6.601448,0.685535,-412.249451,0.069569,0.000000
54.290001,29.477753,-412.249451,-0.001199,0.002719,0.069065,131.123596,6.679754,0.690652,-412.249451,0.070289,0.000000
54.720001,30.919205,-412.293945,-0.001168,0.002753,0.069915,137.535492,7.006392,0.699153,-412.293945,0.071008,0.000000
55.150002,31.606232,-412.249451,-0.001147,0.002777,0.070540,140.591537,7.162075,0.705398,-412.249451,0.071719,0.000000
55.580002,32.025154,-412.382904,-0.001138,0.002797,0.071034,142.455002,7.257004,0.710342,-412.382904,0.072439,0.000000
56.010002,34.226990,-412.382904,-0.001130,0.002837,0.072058,152.249252,7.755947,0.720576,-412.382904,0.073150,0.000000
56.440002,35.460663,-412.427368,-0.001095,0.002864,0.072734,157.736908,8.035501,0.727336,-412.427368,0.073870,0.000000
56.870003,36.709969,-412.382904,-0.001087,0.002894,0.073497,163.294098,8.318598,0.734974,-412.382904,0.074590,0.000000
57.300003,37.303535,-412.471863,-0.001074,0.002917,0.074095,165.934418,8.453102,0.740954,-412.471863,0.075300,0.000000
57.730003,39.086449,-412.516327,-0.001048,0.002951,0.074945,173.865204,8.857116,0.749455,-412.516327,0.076020,0.000000
58.160004,40.199097,-412.471863,-0.001030,0.002977,0.075613,178.814514,9.109245,0.756131,-412.471863,0.076740,0.000000
58.590004,42.295181,-412.471863,-0.001013,0.003010,0.076463,188.138367,9.584226,0.764632,-412.471863,0.077452,0.000000
59.020004,43.395546,-412.471863,-0.001000,0.003037,0.077131,193.033035,9.833571,0.771309,-412.471863,0.078172,0.000000
59.450005,45.425720,-412.516327,-0.000974,0.003070,0.077981,202.063690,10.293615,0.779809,-412.516327,0.078891,0.000000
59.880001,46.872383,-412.605316,-0.000974,0.003099,0.078727,208.498779,10.621434,0.787266,-412.605316,0.079602,0.000000
60.310001,48.150368,-412.516327,-0.000940,0.003122,0.079307,214.183533,10.911029,0.793072,-412.516327,0.080322,0.000000
60.740002,50.019310,-412.560822,-0.000936,0.003153,0.080097,222.497009,11.334538,0.800967,-412.560822,0.081042,0.000000
61.170002,51.473419,-412.560822,-0.000931,0.003182,0.080817,228.965210,11.664043,0.808166,-412.560822,0.081753,0.000000
61.600002,53.097710,-412.649780,-0.000901,0.003207,0.081459,236.190414,12.032113,0.814585,-412.649780,0.082473,0.000000
62.030003,55.020271,-412.738739,-0.000901,0.003236,0.082195,244.742386,12.467772,0.821950,-412.738739,0.083184,0.000000
62.460003,56.100151,-412.694275,-0.000888,0.003255,0.082681,249.545929,12.712477,0.826810,-412.694275,0.083904,0.000000
62.890003,58.277039,-412.738739,-0.000880,0.003288,0.083514,259.229218,13.205766,0.835137,-412.738739,0.084623,0.000000
63.320004,59.393784,-412.649780,-0.000867,0.003306,0.083964,264.196747,13.458823,0.839641,-412.649780,0.085335,0.000000
63.750004,61.879372,-412.783234,-0.000862,0.003338,0.084788,275.253204,14.022066,0.847885,-412.783234,0.086054,0.000000
64.180000,65.013260,-412.783234,-0.000841,0.003379,0.085838,289.193420,14.732215,0.858376,-412.783234,0.086774,0.000000
64.610001,66.117706,-412.872192,-0.000828,0.003389,0.086081,294.106232,14.982487,0.860806,-412.872192,0.015113,0.000000
65.040001,65.104111,-412.783234,-0.000828,0.003390,0.086098,289.597534,14.752803,0.860980,-412.783234,294.500519,0.000000
65.470001,65.724487,-412.827698,-0.000819,0.003399,0.086324,292.357117,14.893382,0.863236,-412.827698,294.500519,0.000000
65.900002,65.027039,-412.827698,-0.000815,0.003399,0.086332,289.254700,14.735337,0.863319,-412.827698,294.500519,0.000000
66.330002,65.904709,-412.827698,-0.000811,0.003409,0.086583,293.158783,14.934220,0.865833,-412.827698,294.500519,0.000000
66.760002,65.361801,-412.916656,-0.000802,0.003409,0.086592,290.743805,14.811195,0.865923,-412.916656,294.500519,0.000000
67.190002,64.948090,-412.961151,-0.000798,0.003421,0.086904,288.903534,14.717447,0.869042,-412.961151,294.500519,0.000000
67.620003,65.623581,-412.916656,-0.000806,0.003417,0.086801,291.908264,14.870516,0.868005,-412.916656,294.500519,0.000000
68.050003,65.279877,-413.005646,-0.000785,0.003417,0.086801,290.379395,14.792631,0.868005,-413.005646,294.500519,0.000000
68.480003,64.999481,-413.005646,-0.000789,0.003418,0.086809,289.132141,14.729094,0.868088,-413.005646,294.500519,0.000000
68.910004,66.218246,-413.050110,-0.000785,0.003428,0.087069,294.553467,15.005270,0.870692,-413.050110,294.500519,0.000000
69.340004,65.950516,-413.094604,-0.000789,0.003428,0.087060,293.362549,14.944600,0.870602,-413.094604,294.500519,0.000000
69.770004,65.730438,-412.961151,-0.000780,0.003428,0.087069,292.383606,14.894730,0.870692,-412.961151,294.500519,0.000000
70.200005,65.482071,-413.050110,-0.000789,0.003428,0.087069,291.278809,14.838449,0.870692,-413.050110,294.500519,0.000000
70.630005,65.263489,-413.183563,-0.000785,0.003428,0.087069,290.306488,14.788918,0.870692,-413.183563,294.500519,0.000000
71.060005,65.044159,-413.139069,-0.000789,0.003428,0.087069,289.330872,14.739217,0.870692,-413.139069,294.500519,0.000000
71.490005,64.928360,-413.139069,-0.000789,0.003428,0.087078,288.815765,14.712976,0.870776,-413.139069,294.500519,0.000000
71.920006,64.750366,-413.139069,-0.000785,0.003428,0.087078,288.024017,14.672643,0.870776,-413.139069,294.500519,0.000000
72.350006,66.455826,-413.183563,-0.000759,0.003417,0.086791,295.610291,15.059105,0.867914,-413.183563,294.500519,0.000000
72.780006,66.294586,-413.228027,-0.000763,0.003417,0.086791,294.893036,15.022568,0.867914,-413.228027,294.500519,0.000000
73.210007,66.144897,-413.272522,-0.000767,0.003417,0.086791,294.227203,14.988647,0.867914,-413.272522,294.500519,0.000000
73.640007,66.010101,-413.228027,-0.000767,0.003417,0.086791,293.627594,14.958102,0.867914,-413.228027,294.500519,0.000000
74.070007,65.849609,-413.228027,-0.000767,0.003417,0.086791,292.913696,14.921734,0.867914,-413.228027,294.500519,0.000000
74.500000,65.744965,-413.228027,-0.000759,0.003417,0.086791,292.448212,14.898022,0.867914,-413.228027,294.500519,0.000000
74.930000,65.593414,-413.316986,-0.000763,0.003417,0.086801,291.774078,14.863680,0.868005,-413.316986,294.500519,0.000000
75.360001,65.530487,-413.316986,-0.000772,0.003417,0.086801,291.494171,14.849421,0.868005,-413.316986,294.500519,0.000000
75.790001,65.413925,-413.361481,-0.000772,0.003417,0.086801,290.975677,14.823008,0.868005,-413.361481,294.500519,0.000000
76.220001,65.305191,-413.361481,-0.000767,0.003418,0.086809,290.492004,14.798368,0.868088,-413.361481,294.500519,0.000000
76.650002,65.296265,-413.361481,-0.000763,0.003443,0.087442,290.452301,14.796345,0.874417,-413.361481,294.500519,0.000000
77.080002,65.239655,-413.405945,-0.000763,0.003444,0.087486,290.200470,14.783518,0.874856,-413.405945,294.500519,0.000000
77.510002,65.236679,-413.494934,-0.000759,0.003445,0.087503,290.187256,14.782843,0.875030,-413.494934,294.500519,0.000000
77.940002,65.145081,-413.450439,-0.000776,0.003445,0.087511,289.779785,14.762086,0.875113,-413.450439,294.500519,0.000000
78.370003,65.094437,-413.450439,-0.000767,0.003445,0.087511,289.554504,14.750610,0.875113,-413.450439,294.500519,0.000000
78.800003,65.565857,-413.450439,-0.000763,0.003453,0.087711,291.651489,14.857435,0.877112,-413.450439,294.500519,0.000000
79.230003,65.559158,-413.494934,-0.000763,0.003453,0.087711,291.621704,14.855918,0.877112,-413.494934,294.500519,0.000000
79.660004,65.528625,-413.583893,-0.000759,0.003453,0.087711,291.485870,14.848999,0.877112,-413.583893,294.500519,0.000000
80.090004,65.482452,-413.583893,-0.000767,0.003453,0.087711,291.280487,14.838536,0.877112,-413.583893,294.500519,0.000000
80.520004,65.414307,-413.539398,-0.000776,0.003453,0.087711,290.977356,14.823093,0.877112,-413.539398,294.500519,0.000000
80.950005,65.375198,-413.583893,-0.000772,0.003454,0.087719,290.803406,14.814232,0.877195,-413.583893,294.500519,0.000000
81.380005,65.332001,-413.628357,-0.000750,0.003454,0.087729,290.611267,14.804443,0.877286,-413.628357,294.500519,0.000000
81.810005,65.306320,-413.672852,-0.000767,0.003454,0.087737,290.497009,14.798624,0.877369,-413.672852,294.500519,0.000000
82.240005,65.283966,-413.672852,-0.000767,0.003454,0.087737,290.397583,14.793558,0.877369,-413.672852,294.500519,0.000000
82.670006,65.237793,-413.628357,-0.000759,0.003454,0.087737,290.192200,14.783095,0.877369,-413.628357,294.500519,0.000000
83.100006,65.545746,-413.717316,-0.000767,0.003460,0.087875,291.562042,14.852879,0.878754,-413.717316,294.500519,0.000000
83.530006,65.556168,-413.717316,-0.000759,0.003459,0.087867,291.608398,14.855240,0.878671,-413.717316,294.500519,0.000000
83.960007,65.525269,-413.761810,-0.000772,0.003458,0.087832,291.470947,14.848238,0.878323,-413.761810,294.500519,0.000000
84.390007,65.478729,-413.761810,-0.000759,0.003458,0.087832,291.263947,14.837692,0.878323,-413.761810,294.500519,0.000000
84.820007,65.400146,-413.761810,-0.000767,0.003458,0.087832,290.914368,14.819884,0.878323,-413.761810,294.500519,0.000000
85.250008,65.349503,-413.806274,-0.000763,0.003458,0.087841,290.689117,14.808409,0.878406,-413.806274,294.500519,0.000000
85.680000,65.303329,-413.806274,-0.000755,0.003458,0.087841,290.483704,14.797946,0.878406,-413.806274,294.500519,0.000000
86.110001,65.265350,-413.850769,-0.000759,0.003458,0.087841,290.314789,14.789339,0.878406,-413.850769,294.500519,0.000000
86.540001,65.235931,-413.850769,-0.000776,0.003458,0.087841,290.183929,14.782673,0.878406,-413.850769,294.500519,0.000000
86.970001,65.196838,-413.895264,-0.000776,0.003458,0.087841,290.010010,14.773814,0.878406,-413.895264,294.500519,0.000000
87.400002,65.149551,-413.850769,-0.000759,0.003458,0.087841,289.799683,14.763099,0.878406,-413.850769,294.500519,0.000000
87.830002,65.094803,-413.895264,-0.000750,0.003458,0.087841,289.556152,14.750693,0.878406,-413.895264,294.500519,0.000000
88.260002,65.057571,-413.939728,-0.000755,0.003458,0.087841,289.390533,14.742256,0.878406,-413.939728,294.500519,0.000000
88.690002,65.020706,-413.984222,-0.000759,0.003458,0.087841,289.226532,14.733903,0.878406,-413.984222,294.500519,0.000000
89.120003,64.998367,-413.939728,-0.000763,0.003458,0.087841,289.127167,14.728841,0.878406,-413.939728,294.500519,0.000000
89.550003,64.967453,-413.984222,-0.000763,0.003458,0.087841,288.989655,14.721835,0.878406,-413.984222,294.500519,0.000000
89.980003,64.939896,-414.028687,-0.000755,0.003458,0.087841,288.867096,14.715591,0.878406,-414.028687,294.500519,0.000000
90.410004,64.894470,-414.073181,-0.000776,0.003458,0.087841,288.665009,14.705297,0.878406,-414.073181,294.500519,0.000000
90.840004,64.833771,-414.117645,-0.000776,0.003458,0.087841,288.395020,14.691543,0.878406,-414.117645,294.500519,0.000000
91.270004,64.806213,-414.073181,-0.000763,0.003459,0.087850,288.272430,14.685298,0.878497,-414.073181,294.500519,0.000000
91.700005,64.773453,-414.028687,-0.000759,0.003459,0.087850,288.126709,14.677875,0.878497,-414.028687,294.500519,0.000000
92.130005,64.734344,-414.117645,-0.000763,0.003459,0.087850,287.952759,14.669012,0.878497,-414.117645,294.500519,0.000000
92.560005,64.725418,-414.206604,-0.000759,0.003459,0.087850,287.913025,14.666989,0.878497,-414.206604,294.500519,0.000000
92.990005,64.688171,-414.162140,-0.000772,0.003459,0.087850,287.747345,14.658549,0.878497,-414.162140,294.500519,0.000000
93.420006,64.660995,-414.206604,-0.000785,0.003459,0.087850,287.626465,14.652390,0.878497,-414.206604,294.500519,0.000000
93.850006,64.628967,-414.162140,-0.000746,0.003459,0.087850,287.484009,14.645133,0.878497,-414.162140,294.500519,0.000000
94.280006,64.604767,-414.295593,-0.000767,0.003459,0.087850,287.376343,14.639649,0.878497,-414.295593,294.500519,0.000000
94.710007,64.570877,-414.295593,-0.000767,0.003459,0.087850,287.225616,14.631969,0.878497,-414.295593,294.500519,0.000000
95.140007,64.520233,-414.340057,-0.000763,0.003459,0.087850,287.000336,14.620494,0.878497,-414.340057,294.500519,0.000000
95.570007,64.504227,-414.251099,-0.000767,0.003459,0.087850,286.929138,14.616867,0.878497,-414.251099,294.500519,0.000000
96.000008,64.486343,-414.340057,-0.000772,0.003459,0.087850,286.849579,14.612814,0.878497,-414.340057,294.500519,0.000000
96.430008,64.444641,-414.384552,-0.000750,0.003459,0.087850,286.664093,14.603365,0.878497,-414.384552,294.500519,0.000000
96.860008,64.424911,-414.473511,-0.000763,0.003459,0.087850,286.576324,14.598893,0.878497,-414.473511,294.500519,0.000000
97.290001,67.230728,-414.384552,-0.000755,0.003331,0.084606,299.057220,15.234701,0.846060,-414.384552,294.500519,0.000000
97.720001,66.681854,-414.340057,-0.000737,0.003287,0.083496,296.615692,15.110324,0.834963,-414.340057,294.500519,0.000000
98.150002,66.660263,-414.384552,-0.000729,0.003287,0.083496,296.519653,15.105432,0.834963,-414.384552,294.500519,0.000000
98.580002,66.593231,-414.473511,-0.000724,0.003287,0.083496,296.221497,15.090241,0.834963,-414.473511,294.500519,0.000000
99.010002,66.591003,-414.517975,-0.000729,0.003287,0.083496,296.211578,15.089737,0.834963,-414.517975,294.500519,0.000000
99.440002,66.481888,-414.429016,-0.000733,0.003287,0.083496,295.726196,15.065011,0.834963,-414.429016,294.500519,0.000000
99.870003,66.494186,-414.429016,-0.000733,0.003287,0.083496,295.780914,15.067798,0.834963,-414.429016,294.500519,0.000000
100.300003,66.448013,-414.517975,-0.000742,0.003288,0.083505,295.575531,15.057335,0.835046,-414.517975,294.500519,0.000000
100.730003,66.418961,-414.473511,-0.000733,0.003288,0.083505,295.446289,15.050752,0.835046,-414.473511,294.500519,0.000000
101.160004,66.389175,-414.606934,-0.000733,0.003288,0.083505,295.313812,15.044003,0.835046,-414.606934,294.500519,0.000000
101.590004,66.369064,-414.562469,-0.000729,0.003288,0.083505,295.224335,15.039445,0.835046,-414.562469,294.500519,0.000000
102.020004,66.348206,-414.606934,-0.000724,0.003288,0.083505,295.131561,15.034719,0.835046,-414.606934,294.500519,0.000000
102.450005,66.306885,-414.606934,-0.000733,0.003288,0.083505,294.947754,15.025354,0.835046,-414.606934,294.500519,0.000000
102.880005,66.278198,-414.651428,-0.000737,0.003288,0.083505,294.820160,15.018854,0.835046,-414.651428,294.500519,0.000000
103.310005,66.255859,-414.651428,-0.000737,0.003288,0.083505,294.720795,15.013792,0.835046,-414.651428,294.500519,0.000000
103.740005,66.222351,-414.740387,-0.000742,0.003288,0.083505,294.571716,15.006199,0.835046,-414.740387,294.500519,0.000000
104.170006,66.204102,-414.651428,-0.000737,0.003288,0.083505,294.490540,15.002064,0.835046,-414.651428,294.500519,0.000000
104.600006,66.191437,-414.695892,-0.000729,0.003288,0.083505,294.434204,14.999194,0.835046,-414.695892,294.500519,0.000000
105.030006,66.162399,-414.784882,-0.000733,0.003288,0.083505,294.305054,14.992614,0.835046,-414.784882,294.500519,0.000000
105.460007,66.134476,-414.784882,-0.000733,0.003288,0.083505,294.180847,14.986286,0.835046,-414.784882,294.500519,0.000000
105.890007,66.099091,-414.784882,-0.000733,0.003288,0.083505,294.023437,14.978268,0.835046,-414.784882,294.500519,0.000000
106.320007,66.094620,-414.784882,-0.000729,0.003288,0.083505,294.003540,14.977256,0.835046,-414.784882,294.500519,0.000000
106.750008,66.065948,-414.784882,-0.000724,0.003288,0.083505,293.876007,14.970757,0.835046,-414.784882,294.500519,0.000000
107.180008,66.043976,-414.918304,-0.000737,0.003288,0.083505,293.778290,14.965778,0.835046,-414.918304,294.500519,0.000000
107.610008,66.001526,-414.873840,-0.000733,0.003288,0.083505,293.589447,14.956160,0.835046,-414.873840,294.500519,0.000000
108.040009,65.907700,-414.918304,-0.000733,0.003288,0.083514,293.172089,14.934898,0.835137,-414.918304,294.500519,0.000000
108.470009,65.865616,-414.962799,-0.000729,0.003289,0.083549,292.984894,14.925363,0.835485,-414.962799,294.500519,0.000000
108.900002,65.890198,-414.918304,-0.000733,0.003290,0.083565,293.094238,14.930933,0.835652,-414.918304,294.500519,0.000000
109.330002,65.816086,-414.962799,-0.000720,0.003293,0.083644,292.764557,14.914139,0.836439,-414.962799,294.500519,0.000000
109.760002,65.858170,-415.051758,-0.000729,0.003295,0.083695,292.951782,14.923675,0.836954,-415.051758,294.500519,0.000000
110.190002,65.857803,-415.007263,-0.000733,0.003295,0.083695,292.950134,14.923592,0.836954,-415.007263,294.500519,0.000000
110.620003,65.851837,-415.007263,-0.000716,0.003295,0.083695,292.923615,14.922239,0.836954,-415.007263,294.500519,0.000000
111.050003,65.790024,-415.007263,-0.000737,0.003295,0.083704,292.648651,14.908232,0.837045,-415.007263,294.500519,0.000000
111.480003,65.788910,-415.096222,-0.000720,0.003295,0.083704,292.643677,14.907980,0.837045,-415.096222,294.500519,0.000000
111.910004,65.785934,-415.096222,-0.000724,0.003295,0.083704,292.630463,14.907306,0.837045,-415.096222,294.500519,0.000000
112.340004,65.762848,-415.140717,-0.000742,0.003296,0.083713,292.527771,14.902074,0.837128,-415.140717,294.500519,0.000000
112.770004,65.744965,-415.185211,-0.000733,0.003296,0.083713,292.448212,14.898022,0.837128,-415.185211,294.500519,0.000000
113.200005,65.676086,-415.096222,-0.000737,0.003300,0.083826,292.141815,14.882414,0.838256,-415.096222,294.500519,0.000000
113.630005,65.626175,-415.140717,-0.000729,0.003300,0.083826,291.919800,14.871104,0.838256,-415.140717,294.500519,0.000000
114.060005,65.609421,-415.274170,-0.000724,0.003306,0.083973,291.845276,14.867308,0.839732,-415.274170,294.500519,0.000000
114.490005,65.611282,-415.229675,-0.000729,0.003306,0.083973,291.853546,14.867729,0.839732,-415.229675,294.500519,0.000000
114.920006,65.604218,-415.229675,-0.000724,0.003306,0.083973,291.822144,14.866128,0.839732,-415.229675,294.500519,0.000000
115.350006,65.574051,-415.229675,-0.000720,0.003306,0.083973,291.687958,14.859292,0.839732,-415.229675,294.500519,0.000000
115.780006,65.577026,-415.274170,-0.000737,0.003310,0.084069,291.701172,14.859967,0.840686,-415.274170,294.500519,0.000000
116.210007,65.567719,-415.363129,-0.000733,0.003429,0.087087,291.659790,14.857858,0.870866,-415.363129,294.500519,0.000000
116.640007,65.557297,-415.363129,-0.000733,0.003433,0.087208,291.613434,14.855495,0.872078,-415.363129,294.500519,0.000000
117.070007,65.536804,-415.363129,-0.000742,0.003433,0.087208,291.522278,14.850852,0.872078,-415.363129,294.500519,0.000000
117.500008,65.537186,-415.363129,-0.000720,0.003433,0.087208,291.523956,14.850938,0.872078,-415.363129,294.500519,0.000000
117.930008,65.518188,-415.318634,-0.000724,0.003433,0.087208,291.439453,14.846633,0.872078,-415.318634,294.500519,0.000000
118.360008,65.500687,-415.407593,-0.000720,0.003434,0.087225,291.361603,14.842668,0.872252,-415.407593,294.500519,0.000000
118.790009,65.485428,-415.541046,-0.000733,0.003434,0.087225,291.293732,14.839210,0.872252,-415.541046,294.500519,0.000000
119.220009,65.458984,-415.496552,-0.000737,0.003434,0.087225,291.176117,14.833219,0.872252,-415.496552,294.500519,0.000000
119.650009,65.422119,-415.452087,-0.000737,0.003434,0.087234,291.012115,14.824864,0.872343,-415.452087,294.500519,0.000000
120.080009,65.431808,-415.496552,-0.000742,0.003443,0.087451,291.055206,14.827060,0.874508,-415.496552,294.500519,0.000000
120.510002,65.433670,-415.585541,-0.000729,0.003444,0.087468,291.063507,14.827481,0.874682,-415.585541,294.500519,0.000000
120.940002,65.399033,-415.585541,-0.000729,0.003444,0.087476,290.909424,14.819633,0.874765,-415.585541,294.500519,0.000000
121.370003,65.369614,-415.585541,-0.000729,0.003444,0.087486,290.778564,14.812966,0.874856,-415.585541,294.500519,0.000000
121.800003,65.358444,-415.585541,-0.000733,0.003444,0.087486,290.728882,14.810435,0.874856,-415.585541,294.500519,0.000000
122.230003,65.337967,-415.585541,-0.000724,0.003444,0.087486,290.637787,14.805795,0.874856,-415.585541,294.500519,0.000000
122.660004,65.362915,-415.630005,-0.000724,0.003445,0.087503,290.748779,14.811448,0.875030,-415.630005,294.500519,0.000000
123.090004,65.368866,-415.674500,-0.000737,0.003445,0.087503,290.775238,14.812798,0.875030,-415.674500,294.500519,0.000000
123.520004,65.364410,-415.674500,-0.000729,0.003445,0.087503,290.755432,14.811788,0.875030,-415.674500,294.500519,0.000000
123.950005,65.329407,-415.585541,-0.000733,0.003445,0.087503,290.599701,14.803855,0.875030,-415.585541,294.500519,0.000000
124.380005,65.315628,-415.674500,-0.000720,0.003445,0.087503,290.538422,14.800733,0.875030,-415.674500,294.500519,0.000000
124.810005,65.302597,-415.718964,-0.000746,0.003445,0.087503,290.480469,14.797780,0.875030,-415.718964,294.500519,0.000000
125.240005,65.286209,-415.763458,-0.000733,0.003442,0.087433,290.407562,14.794066,0.874333,-415.763458,0.087416,0.000000
125.670006,65.264603,-415.763458,-0.000737,0.003429,0.087095,290.311462,14.789170,0.870950,-415.763458,0.086696,0.000000
126.100006,65.228485,-415.718964,-0.000742,0.003404,0.086453,290.150787,14.780987,0.864531,-415.718964,0.085985,0.000000
126.530006,65.194595,-415.807922,-0.000720,0.003375,0.085717,290.000031,14.773306,0.857165,-415.807922,0.085265,0.000000
126.960007,65.207260,-415.807922,-0.000733,0.003348,0.085048,290.056366,14.776176,0.850481,-415.807922,0.084554,0.000000
127.390007,65.160339,-415.807922,-0.000724,0.003322,0.084372,289.847656,14.765544,0.843721,-415.807922,0.083835,0.000000
127.820007,65.167786,-415.896881,-0.000733,0.003295,0.083704,289.880798,14.767232,0.837045,-415.896881,0.083115,0.000000
128.250000,65.149551,-415.852417,-0.000733,0.003264,0.082898,289.799683,14.763099,0.828975,-415.852417,0.082403,0.000000
128.680008,64.713120,-415.852417,-0.000720,0.003240,0.082300,287.858337,14.664203,0.822995,-415.852417,0.081683,0.000000
129.110001,64.068542,-415.941376,-0.000716,0.003215,0.081658,284.991119,14.518139,0.816576,-415.941376,0.080964,0.000000
129.540009,62.966698,-415.985840,-0.000716,0.003192,0.081076,280.089874,14.268457,0.810762,-415.985840,0.080253,0.000000
129.970001,61.387093,-416.030334,-0.000711,0.003166,0.080418,273.063416,13.910514,0.804177,-416.030334,0.079533,0.000000
130.400009,59.534538,-415.985840,-0.000711,0.003135,0.079637,264.822845,13.490719,0.796372,-415.985840,0.078813,0.000000
130.830002,57.288765,-415.985840,-0.000690,0.003107,0.078926,254.833160,12.981819,0.789257,-415.985840,0.078102,0.000000
131.260010,55.325615,-416.030334,-0.000686,0.003081,0.078250,246.100632,12.536963,0.782497,-416.030334,0.077382,0.000000
131.690002,53.413483,-416.119293,-0.000694,0.003057,0.077660,237.595032,12.103668,0.776600,-416.119293,0.076662,0.000000
132.120010,50.079262,-416.163788,-0.000707,0.003028,0.076905,222.763687,11.348123,0.769053,-416.163788,0.075951,0.000000
132.550003,46.985962,-416.074829,-0.000698,0.002998,0.076160,209.003998,10.647171,0.761597,-416.074829,0.075232,0.000000
132.980011,44.151459,-416.074829,-0.000698,0.002975,0.075570,196.395493,10.004864,0.755700,-416.074829,0.074512,0.000000
133.410004,41.160568,-416.119293,-0.000690,0.002946,0.074841,183.091354,9.327118,0.748410,-416.119293,0.073801,0.000000
133.840012,37.833420,-416.208252,-0.000703,0.002917,0.074095,168.291458,8.573175,0.740954,-416.208252,0.073081,0.000000
134.270004,35.010086,-416.208252,-0.000703,0.002893,0.073488,155.732635,7.933399,0.734883,-416.208252,0.072369,0.000000
134.700012,31.257317,-416.208252,-0.000703,0.002858,0.072595,139.039490,7.083009,0.725950,-416.208252,0.071650,0.000000
135.130005,28.929993,-416.208252,-0.000694,0.002837,0.072058,128.687027,6.555630,0.720576,-416.208252,0.070930,0.000000
135.560013,25.644180,-416.252747,-0.000698,0.002808,0.071312,114.071014,5.811055,0.713120,-416.252747,0.070219,0.000000
135.990005,22.642487,-416.252747,-0.000694,0.002779,0.070592,100.718811,5.130861,0.705921,-416.252747,0.069499,0.000000
136.420013,19.999008,-416.297211,-0.000694,0.002754,0.069958,88.960030,4.531840,0.699585,-416.297211,0.068779,0.000000
136.850006,15.860832,-416.297211,-0.000690,0.002722,0.069127,70.552505,3.594116,0.691266,-416.297211,0.068068,0.000000
137.280014,12.697533,-416.341705,-0.000707,0.002690,0.068337,56.481445,2.877302,0.683370,-416.341705,0.067348,0.000000
137.710007,9.898033,-416.341705,-0.000698,0.002663,0.067643,44.028652,2.242926,0.676429,-416.341705,0.066629,0.000000
138.139999,7.294411,-416.386169,-0.000681,0.002641,0.067071,32.447159,1.652937,0.670706,-416.386169,0.065918,0.000000
138.570007,3.355453,-416.341705,-0.000694,0.002605,0.066160,14.925802,0.760357,0.661600,-416.341705,0.065198,0.000000
139.000000,0.668785,-416.475159,-0.000698,0.002574,0.065389,2.974905,0.151549,0.653886,-416.475159,0.064478,0.000000
139.430008,-1.084347,-416.341705,-0.000698,0.002559,0.065007,-4.823415,-0.245716,0.650071,-416.341705,0.063766,0.000000
139.860001,-0.233475,-416.430664,-0.000690,0.002521,0.064027,-1.038548,-0.052906,0.640268,-416.430664,0.063047,0.000000
140.290009,-0.147087,-416.519623,-0.000703,0.002497,0.063420,-0.654276,-0.033330,0.634197,-416.519623,0.062336,0.000000
140.720001,-0.173523,-416.564117,-0.000703,0.002463,0.062570,-0.771869,-0.039321,0.625696,-416.564117,0.061616,0.000000
141.150009,-0.145226,-416.519623,-0.000716,0.002436,0.061876,-0.645995,-0.032909,0.618762,-416.519623,0.060896,0.000000
141.580002,-0.132561,-416.519623,-0.000750,0.002410,0.061217,-0.589660,-0.030039,0.612169,-416.519623,0.060185,0.000000
142.010010,-0.135170,-416.564117,-0.000785,0.002380,0.060454,-0.601266,-0.030630,0.604539,-416.564117,0.059465,0.000000
142.440002,-0.152298,-416.653076,-0.000819,0.002351,0.059708,-0.677455,-0.034511,0.597082,-416.653076,0.058745,0.000000
142.870010,-0.116920,-416.608582,-0.000871,0.002321,0.058945,-0.520088,-0.026495,0.589452,-416.608582,0.058035,0.000000
143.300003,-0.137405,-416.653076,-0.000897,0.002298,0.058381,-0.611210,-0.031137,0.583812,-416.653076,0.057315,0.000000
143.730011,-0.129211,-416.608582,-0.000927,0.002264,0.057514,-0.574761,-0.029280,0.575137,-416.608582,0.056595,0.000000
144.160004,-0.107239,-416.697540,-0.000949,0.002237,0.056811,-0.477022,-0.024301,0.568113,-416.697540,0.055884,0.000000
144.590012,-0.147827,-416.697540,-0.000983,0.002212,0.056196,-0.657568,-0.033498,0.561958,-416.697540,0.055164,0.000000
145.020004,-0.129585,-416.697540,-0.001030,0.002183,0.055459,-0.576424,-0.029364,0.554586,-416.697540,0.054444,0.000000
145.450012,-0.173523,-416.697540,-0.001039,0.002154,0.054705,-0.771869,-0.039321,0.547046,-416.697540,0.053733,0.000000
145.880005,-0.145226,-416.742035,-0.001056,0.002125,0.053985,-0.645995,-0.032909,0.539847,-416.742035,0.053014,0.000000
146.310013,-0.134048,-416.786499,-0.001112,0.002095,0.053221,-0.596277,-0.030376,0.532209,-416.786499,0.052302,0.000000
146.740005,-0.124741,-416.742035,-0.001130,0.002068,0.052536,-0.554874,-0.028267,0.525359,-416.742035,0.051582,0.000000
147.170013,-0.125114,-416.786499,-0.001168,0.002043,0.051886,-0.556537,-0.028351,0.518856,-416.786499,0.050862,0.000000
147.600006,-0.127350,-416.830994,-0.001194,0.002016,0.051201,-0.566480,-0.028858,0.512005,-416.830994,0.050151,0.000000
148.030014,-0.111710,-416.875488,-0.001207,0.001989,0.050525,-0.496909,-0.025314,0.505246,-416.875488,0.049431,0.000000
148.460007,-0.095322,-416.830994,-0.001242,0.001957,0.049718,-0.424012,-0.021600,0.497176,-416.830994,0.048712,0.000000
148.890015,-0.076706,-416.964447,-0.001285,0.001927,0.048937,-0.341205,-0.017382,0.489372,-416.964447,0.048001,0.000000
149.320007,-0.083405,-416.919952,-0.001328,0.001898,0.048217,-0.371002,-0.018900,0.482173,-416.919952,0.047281,0.000000
149.750000,-0.088623,-416.964447,-0.001332,0.001874,0.047602,-0.394215,-0.020082,0.476019,-416.964447,0.046561,0.000000
150.180008,-0.098305,-417.008911,-0.001371,0.001841,0.046769,-0.437281,-0.022276,0.467692,-417.008911,0.045850,0.000000
150.610001,-0.078568,-416.919952,-0.001397,0.001815,0.046102,-0.349486,-0.017804,0.461015,-416.919952,0.045130,0.000000
151.040009,-0.068886,-417.053406,-0.001444,0.001794,0.045555,-0.306419,-0.015610,0.455550,-417.053406,0.044410,0.000000
151.470001,-0.084900,-417.142365,-0.001470,0.001758,0.044662,-0.377654,-0.019239,0.446618,-417.142365,0.043699,0.000000
151.900009,-0.102028,-417.053406,-0.001509,0.001729,0.043916,-0.453843,-0.023120,0.439161,-417.053406,0.042979,0.000000
152.330002,-0.088249,-417.053406,-0.001522,0.001703,0.043248,-0.392552,-0.019998,0.432485,-417.053406,0.042260,0.000000
152.760010,-0.088997,-417.053406,-0.001552,0.001671,0.042442,-0.395878,-0.020167,0.424415,-417.053406,0.041548,0.000000
153.190002,-0.116547,-417.186829,-0.001582,0.001649,0.041887,-0.518425,-0.026410,0.418867,-417.186829,0.040828,0.000000
153.620010,-0.076706,-417.186829,-0.001625,0.001615,0.041028,-0.341205,-0.017382,0.410283,-417.186829,0.040118,0.000000
154.050003,-0.092720,-417.142365,-0.001651,0.001585,0.040256,-0.412439,-0.021011,0.402561,-417.142365,0.039398,0.000000
154.480011,-0.104263,-417.142365,-0.001694,0.001559,0.039588,-0.463786,-0.023626,0.395885,-417.142365,0.038678,0.000000
154.910004,-0.122879,-417.142365,-0.001694,0.001533,0.038938,-0.546593,-0.027845,0.389382,-417.142365,0.037967,0.000000
155.340012,-0.125114,-417.231323,-0.001733,0.001506,0.038262,-0.556537,-0.028351,0.382615,-417.231323,0.037247,0.000000
155.770004,-0.095322,-417.231323,-0.001755,0.001475,0.037455,-0.424012,-0.021600,0.374553,-417.231323,0.036527,0.000000
156.200012,-0.111336,-417.275787,-0.001794,0.001451,0.036857,-0.495246,-0.025229,0.368565,-417.275787,0.035816,0.000000
156.630005,-0.122131,-417.231323,-0.001819,0.001421,0.036085,-0.543267,-0.027675,0.360852,-417.231323,0.035097,0.000000
157.060013,-0.098305,-417.364777,-0.001845,0.001392,0.035348,-0.437281,-0.022276,0.353479,-417.364777,0.034377,0.000000
157.490005,-0.111336,-417.364777,-0.001884,0.001364,0.034636,-0.495246,-0.025229,0.346363,-417.364777,0.033665,0.000000
157.920013,-0.118408,-417.320282,-0.001906,0.001331,0.033813,-0.526706,-0.026832,0.338127,-417.320282,0.032945,0.000000
158.350006,-0.124001,-417.409241,-0.001927,0.001306,0.033180,-0.551582,-0.028099,0.331799,-417.409241,0.032226,0.000000
158.780014,-0.135170,-417.364777,-0.001957,0.001280,0.032512,-0.601266,-0.030630,0.325122,-417.364777,0.031515,0.000000
159.210007,-0.134048,-417.453735,-0.001992,0.001254,0.031853,-0.596277,-0.030376,0.318529,-417.453735,0.030795,0.000000
159.640015,-0.122131,-417.498199,-0.002022,0.001221,0.031012,-0.543267,-0.027675,0.310119,-417.498199,0.030084,0.000000
160.070007,-0.148949,-417.542694,-0.002057,0.001195,0.030361,-0.662557,-0.033752,0.303609,-417.542694,0.029364,0.000000
160.500000,-0.123627,-417.453735,-0.002074,0.001175,0.029833,-0.549919,-0.028014,0.298325,-417.453735,0.028644,0.000000
160.930008,-0.135910,-417.498199,-0.002104,0.001143,0.029043,-0.604558,-0.030798,0.290430,-417.498199,0.027933,0.000000
161.360001,-0.161232,-417.542694,-0.002134,0.001110,0.028185,-0.717196,-0.036536,0.281846,-417.542694,0.027213,0.000000
161.790009,-0.150810,-417.542694,-0.002160,0.001087,0.027612,-0.670837,-0.034174,0.276123,-417.542694,0.026494,0.000000
162.220001,-0.151176,-417.631653,-0.002203,0.001056,0.026832,-0.672466,-0.034257,0.268319,-417.631653,0.025782,0.000000
162.650009,-0.144852,-417.587158,-0.002229,0.001027,0.026077,-0.644332,-0.032824,0.260772,-417.587158,0.025063,0.000000
163.080002,-0.140007,-417.542694,-0.002255,0.001000,0.025410,-0.622782,-0.031726,0.254095,-417.542694,0.024343,0.000000
163.510010,-0.142242,-417.631653,-0.002285,0.000969,0.024612,-0.632726,-0.032233,0.246117,-417.631653,0.023631,0.000000
163.940002,-0.140007,-417.676117,-0.002311,0.000942,0.023918,-0.622782,-0.031726,0.239175,-417.676117,0.022911,0.000000
164.370010,-0.115807,-417.676117,-0.002354,0.000909,0.023094,-0.515133,-0.026242,0.230939,-417.676117,0.022192,0.000000
164.800003,-0.142242,-417.631653,-0.002371,0.000886,0.022504,-0.632726,-0.032233,0.225042,-417.631653,0.021481,0.000000
165.230011,-0.113571,-417.720612,-0.002397,0.000855,0.021715,-0.505190,-0.025736,0.217147,-417.720612,0.020761,0.000000
165.660004,-0.110222,-417.720612,-0.002419,0.000826,0.020969,-0.490291,-0.024977,0.209691,-417.720612,0.020050,0.000000
166.090012,-0.145226,-417.765106,-0.002471,0.000793,0.020154,-0.645995,-0.032909,0.201538,-417.765106,0.019330,0.000000
166.520004,-0.142990,-417.720612,-0.002483,0.000772,0.019616,-0.636052,-0.032402,0.196164,-417.720612,0.018610,0.000000
166.950012,-0.152298,-417.765106,-0.002522,0.000742,0.018836,-0.677455,-0.034511,0.188359,-417.765106,0.017900,0.000000
167.380005,-0.114319,-417.854065,-0.002557,0.000712,0.018073,-0.508516,-0.025905,0.180729,-417.854065,0.017180,0.000000
167.810013,-0.126602,-417.809570,-0.002574,0.000687,0.017457,-0.563155,-0.028688,0.174567,-417.809570,0.016460,0.000000
168.240005,-0.105751,-417.809570,-0.002621,0.000654,0.016624,-0.470404,-0.023964,0.166240,-417.809570,0.015748,0.000000
168.670013,-0.120270,-417.854065,-0.002643,0.000628,0.015956,-0.534987,-0.027254,0.159564,-417.854065,0.015028,0.000000
169.100006,-0.135910,-417.854065,-0.002660,0.000615,0.015627,-0.604558,-0.030798,0.156271,-417.854065,0.014309,0.000000
169.530014,-0.108360,-417.854065,-0.002695,0.000572,0.014526,-0.482011,-0.024555,0.145257,-417.854065,0.013598,0.000000
169.960007,-0.071861,-417.943024,-0.002721,0.000544,0.013823,-0.319655,-0.016284,0.138232,-417.943024,0.012878,0.000000
170.390015,-0.086388,-417.943024,-0.002751,0.000518,0.013164,-0.384271,-0.019576,0.131639,-417.943024,0.012158,0.000000
170.820007,-0.105751,-417.987488,-0.002785,0.000491,0.012470,-0.470404,-0.023964,0.124705,-417.987488,0.011447,0.000000
171.250015,-0.108360,-417.943024,-0.002798,0.000461,0.011707,-0.482011,-0.024555,0.117074,-417.943024,0.010727,0.000000
171.680008,-0.095695,-417.987488,-0.002824,0.000434,0.011013,-0.425675,-0.021685,0.110133,-417.987488,0.010007,0.000000
172.110001,-0.064415,-417.987488,-0.002850,0.000410,0.010406,-0.286532,-0.014597,0.104062,-417.987488,0.009296,0.000000
172.540009,-0.066650,-418.120941,-0.002897,0.000375,0.009522,-0.296476,-0.015103,0.095220,-418.120941,0.008577,0.000000
172.970001,-0.099045,-418.076447,-0.002928,0.000348,0.008828,-0.440573,-0.022444,0.088279,-418.076447,0.007865,0.000000
173.400009,-0.103142,-418.031982,-0.002962,0.000316,0.008022,-0.458798,-0.023372,0.080217,-418.031982,0.007146,0.000000
173.830002,-0.099045,-418.076447,-0.002984,0.000293,0.007449,-0.440573,-0.022444,0.074494,-418.076447,0.006426,0.000000
174.260010,-0.087875,-418.165436,-0.002997,0.000263,0.006669,-0.390889,-0.019913,0.066690,-418.165436,0.005714,0.000000
174.690002,-0.085274,-418.209900,-0.003022,0.000232,0.005888,-0.379317,-0.019323,0.058878,-418.209900,0.004995,0.000000
175.120010,-0.097183,-418.209900,-0.003061,0.000203,0.005169,-0.432293,-0.022022,0.051687,-418.209900,0.004275,0.000000
175.550003,-0.114319,-418.120941,-0.003104,0.000178,0.004518,-0.508516,-0.025905,0.045177,-418.120941,0.003564,0.000000
175.980011,-0.123627,-418.165436,-0.003117,0.000150,0.003798,-0.549919,-0.028014,0.037978,-418.165436,0.002844,0.000000
176.410004,-0.125862,-418.209900,-0.003143,0.000124,0.003157,-0.559863,-0.028521,0.031566,-418.209900,0.002124,0.000000
176.840012,-0.144478,-418.298859,-0.003191,0.000096,0.002445,-0.642670,-0.032739,0.024450,-418.298859,0.001413,0.000000
177.270004,-0.100166,-418.343353,-0.003221,0.000061,0.001552,-0.445562,-0.022698,0.015518,-418.343353,0.000693,0.000000
177.700012,-0.111336,-418.298859,-0.003251,0.000041,0.001049,-0.495246,-0.025229,0.010492,-418.298859,-0.000026,0.000000
178.130005,-0.107613,-418.298859,-0.003264,0.000009,0.000234,-0.478685,-0.024385,0.002339,-418.298859,-0.000737,0.000000
178.400009,-0.105751,-418.298859,-0.003303,0.000001,0.000026,-0.470404,-0.023964,0.000257,-418.298859,-0.000026,0.000000