File: Data/compression 23/AutoNoHeating-12-23-reverse-2-1_09192024_183858.csv
Time (sec),S:Load (lbs),S:HL1 (DIM),S:LVDT (in),S:Position (in),Ch:Position (mm),Ch:Load (N),Ch:Stress (MPa),Ch:Strain (mm/mm),Ch:HL1 (DIM),Set Point (),Cycles ()
0.110000,-0.205177,-366.345123,-0.009796,-0.005994,-0.152241,-0.912674,-0.046494,-1.522413,-366.345123,-0.151947,0.000000
0.520000,-0.083405,-366.389587,-0.009804,-0.005932,-0.150680,-0.371002,-0.018900,-1.506805,-366.389587,-0.149917,0.000000
0.930000,-0.064789,-366.389587,-0.009684,-0.005684,-0.144376,-0.288195,-0.014681,-1.443756,-366.389587,-0.143083,0.000000
1.340000,-0.087875,-366.478546,-0.009421,-0.005409,-0.137386,-0.390889,-0.019913,-1.373856,-366.478546,-0.136250,0.000000
1.750000,-0.092346,-366.434082,-0.009136,-0.005139,-0.130543,-0.410776,-0.020926,-1.305433,-366.434082,-0.129416,0.000000
2.160000,-0.147827,-366.389587,-0.008869,-0.004877,-0.123883,-0.657568,-0.033498,-1.238834,-366.389587,-0.122582,0.000000
2.570000,-0.103889,-366.478546,-0.008597,-0.004607,-0.117006,-0.462123,-0.023542,-1.170062,-366.478546,-0.115749,0.000000
2.980000,-0.097557,-366.478546,-0.008326,-0.004338,-0.110181,-0.433956,-0.022107,-1.101813,-366.478546,-0.108932,0.000000
3.390000,-0.072609,-366.523041,-0.008037,-0.004062,-0.103165,-0.322981,-0.016453,-1.031649,-366.523041,-0.102098,0.000000
3.800000,-0.087502,-366.523041,-0.007774,-0.003799,-0.096505,-0.389226,-0.019828,-0.965050,-366.523041,-0.095265,0.000000
4.210000,-0.086014,-366.612000,-0.007502,-0.003533,-0.089741,-0.382608,-0.019491,-0.897406,-366.612000,-0.088431,0.000000
4.620000,-0.079315,-366.612000,-0.007222,-0.003261,-0.082829,-0.352812,-0.017973,-0.828286,-366.612000,-0.081597,0.000000
5.030000,-0.049896,-366.612000,-0.006916,-0.002990,-0.075934,-0.221950,-0.011307,-0.759341,-366.612000,-0.074781,0.000000
5.440000,-0.074471,-366.656494,-0.006666,-0.002718,-0.069031,-0.331261,-0.016875,-0.690312,-366.656494,-0.067947,0.000000
5.850000,-0.094582,-366.612000,-0.006381,-0.002456,-0.062388,-0.420720,-0.021432,-0.623879,-366.612000,-0.061113,0.000000
6.260000,-0.141129,-366.656494,-0.006114,-0.002177,-0.055303,-0.627771,-0.031980,-0.553034,-366.656494,-0.054280,0.000000
6.670001,-0.107986,-366.745453,-0.005842,-0.001913,-0.048590,-0.480348,-0.024470,-0.485905,-366.745453,-0.047446,0.000000
7.080000,-0.070747,-366.656494,-0.005562,-0.001648,-0.041861,-0.314700,-0.016032,-0.418609,-366.656494,-0.040629,0.000000
7.490000,-0.054359,-366.789917,-0.005286,-0.001385,-0.035184,-0.241803,-0.012318,-0.351836,-366.789917,-0.033796,0.000000
7.900001,-0.061813,-366.789917,-0.005023,-0.001115,-0.028315,-0.274960,-0.014007,-0.283148,-366.789917,-0.026962,0.000000
8.310000,-0.080803,-366.789917,-0.004717,-0.000835,-0.021212,-0.359429,-0.018310,-0.212121,-366.789917,-0.020128,0.000000
8.720000,0.211884,-366.834412,-0.004518,0.000011,0.000286,0.942505,0.048013,0.002861,-366.834412,0.000451,0.000000
9.130000,0.184700,-366.789917,-0.004510,0.000011,0.000269,0.821587,0.041854,0.002687,-366.789917,0.000451,0.000000
9.540001,0.116554,-366.834412,-0.004510,0.000011,0.000269,0.518459,0.026412,0.002687,-366.834412,0.001058,0.000000
9.950001,0.264389,-366.878876,-0.004497,0.000033,0.000833,1.176061,0.059911,0.008327,-366.878876,0.001743,0.000000
10.360001,0.347054,-366.923370,-0.004475,0.000058,0.001466,1.543771,0.078643,0.014655,-366.923370,0.002428,0.000000
10.770000,0.485947,-366.923370,-0.004449,0.000089,0.002255,2.161599,0.110117,0.022550,-366.923370,0.003113,0.000000
11.180000,0.594681,-366.923370,-0.004432,0.000113,0.002862,2.645272,0.134757,0.028621,-366.923370,0.003799,0.000000
11.590000,0.773796,-367.012329,-0.004393,0.000138,0.003512,3.442017,0.175345,0.035124,-367.012329,0.004475,0.000000
12.000001,0.854973,-367.056793,-0.004389,0.000158,0.004015,3.803109,0.193740,0.040150,-367.056793,0.005160,0.000000
12.410001,1.095894,-367.012329,-0.004324,0.000195,0.004952,4.874779,0.248333,0.049522,-367.012329,0.005845,0.000000
12.820001,1.134247,-367.056793,-0.004342,0.000208,0.005290,5.045382,0.257024,0.052898,-367.056793,0.006530,0.000000
13.230000,1.220642,-367.012329,-0.004303,0.000231,0.005871,5.429687,0.276601,0.058711,-367.012329,0.007216,0.000000
13.640000,1.521515,-367.101288,-0.004264,0.000273,0.006929,6.768036,0.344780,0.069294,-367.101288,0.007892,0.000000
14.050000,1.597107,-367.101288,-0.004251,0.000295,0.007484,7.104287,0.361910,0.074843,-367.101288,0.008577,0.000000
14.460001,1.757973,-367.145782,-0.004204,0.000325,0.008256,7.819853,0.398362,0.082556,-367.145782,0.009262,0.000000
14.870001,1.864098,-367.145782,-0.004191,0.000346,0.008785,8.291921,0.422411,0.087847,-367.145782,0.009947,0.000000
15.280001,1.961288,-367.190247,-0.004156,0.000370,0.009409,8.724247,0.444434,0.094092,-367.190247,0.010633,0.000000
15.690001,2.110611,-367.279205,-0.004135,0.000400,0.010164,9.388467,0.478271,0.101640,-367.279205,0.011309,0.000000
16.100000,2.325096,-367.234741,-0.004100,0.000436,0.011075,10.342545,0.526874,0.110746,-367.234741,0.011994,0.000000
16.510000,2.353394,-367.279205,-0.004066,0.000462,0.011725,10.468417,0.533287,0.117248,-367.279205,0.012679,0.000000
16.920000,2.423775,-367.323700,-0.004044,0.000489,0.012419,10.781488,0.549235,0.124190,-367.323700,0.013364,0.000000
17.330000,2.444260,-367.279205,-0.004014,0.000514,0.013052,10.872610,0.553877,0.130518,-367.279205,0.014049,0.000000
17.740002,2.552986,-367.368164,-0.003992,0.000538,0.013676,11.356250,0.578515,0.136763,-367.368164,0.014726,0.000000
18.150002,2.742897,-367.279205,-0.003958,0.000572,0.014526,12.201015,0.621549,0.145257,-367.279205,0.015411,0.000000
18.560001,2.763748,-367.368164,-0.003941,0.000595,0.015115,12.293766,0.626274,0.151154,-367.368164,0.016096,0.000000
18.970001,2.820724,-367.368164,-0.003893,0.000624,0.015853,12.547209,0.639185,0.158527,-367.368164,0.016781,0.000000
19.380001,2.888123,-367.368164,-0.003872,0.000650,0.016512,12.847011,0.654458,0.165120,-367.368164,0.017466,0.000000
19.790001,2.889984,-367.501617,-0.003872,0.000669,0.016981,12.855291,0.654880,0.169806,-367.501617,0.018143,0.000000
20.200001,3.126816,-367.412659,-0.003829,0.000708,0.017977,13.908772,0.708547,0.179775,-367.412659,0.018828,0.000000
20.610001,3.123093,-367.501617,-0.003790,0.000734,0.018654,13.892210,0.707703,0.186542,-367.501617,0.019513,0.000000
21.020000,3.171127,-367.457123,-0.003777,0.000760,0.019295,14.105879,0.718588,0.192954,-367.457123,0.020198,0.000000
21.430000,3.269806,-367.501617,-0.003742,0.000788,0.020007,14.544823,0.740949,0.200070,-367.501617,0.020883,0.000000
21.840000,3.270920,-367.590576,-0.003729,0.000807,0.020492,14.549778,0.741201,0.204922,-367.590576,0.021560,0.000000
22.250002,3.423599,-367.546112,-0.003678,0.000842,0.021385,15.228930,0.775799,0.213854,-367.546112,0.022245,0.000000
22.660002,3.441467,-367.590576,-0.003669,0.000867,0.022027,15.308411,0.779848,0.220273,-367.590576,0.022930,0.000000
23.070002,3.480194,-367.546112,-0.003643,0.000891,0.022644,15.480677,0.788623,0.226435,-367.546112,0.023615,0.000000
23.480001,3.538658,-367.590576,-0.003613,0.000917,0.023285,15.740738,0.801871,0.232847,-367.590576,0.024300,0.000000
23.890001,3.544991,-367.635071,-0.003583,0.000936,0.023762,15.768906,0.803306,0.237623,-367.635071,0.024976,0.000000
24.300001,3.768044,-367.635071,-0.003557,0.000978,0.024829,16.761095,0.853851,0.248289,-367.635071,0.025661,0.000000
24.710001,3.682770,-367.768494,-0.003527,0.000993,0.025228,16.381779,0.834528,0.252278,-367.768494,0.026347,0.000000
25.120001,3.779213,-367.724030,-0.003523,0.001017,0.025843,16.810780,0.856382,0.258433,-367.724030,0.027032,0.000000
25.530001,3.861877,-367.679535,-0.003475,0.001045,0.026546,17.178490,0.875114,0.265457,-367.679535,0.027717,0.000000
25.940001,4.094986,-367.768494,-0.003445,0.001084,0.027526,18.215406,0.927937,0.275260,-367.768494,0.028393,0.000000
26.350000,4.097214,-367.724030,-0.003415,0.001110,0.028202,18.225317,0.928442,0.282020,-367.724030,0.029078,0.000000
26.760002,4.099083,-367.768494,-0.003406,0.001135,0.028827,18.233631,0.928865,0.288265,-367.768494,0.029763,0.000000
27.170002,4.268135,-367.768494,-0.003363,0.001166,0.029616,18.985613,0.967173,0.296160,-367.768494,0.030448,0.000000
27.580002,4.303886,-367.857452,-0.003328,0.001192,0.030266,19.144644,0.975275,0.302663,-367.857452,0.031133,0.000000
27.990002,4.309845,-367.812988,-0.003307,0.001214,0.030839,19.171148,0.976625,0.308386,-367.812988,0.031810,0.000000
28.400002,4.431984,-367.812988,-0.003285,0.001245,0.031611,19.714449,1.004302,0.316107,-367.812988,0.032495,0.000000
28.810001,4.517624,-367.946442,-0.003277,0.001273,0.032339,20.095394,1.023708,0.323389,-367.946442,0.033180,0.000000
29.220001,4.604759,-367.946442,-0.003221,0.001297,0.032954,20.482992,1.043453,0.329543,-367.946442,0.033865,0.000000
29.630001,4.682961,-367.990906,-0.003195,0.001322,0.033579,20.830849,1.061174,0.335788,-367.990906,0.034550,0.000000
30.040001,4.758179,-367.990906,-0.003173,0.001347,0.034203,21.165436,1.078219,0.342033,-367.990906,0.035227,0.000000
30.450001,4.831909,-367.946442,-0.003147,0.001373,0.034880,21.493406,1.094926,0.348801,-367.946442,0.035912,0.000000
30.860001,4.730995,-367.990906,-0.003134,0.001390,0.035305,21.044518,1.072059,0.353047,-367.990906,0.036597,0.000000
31.270002,5.115654,-367.990906,-0.003100,0.001431,0.036337,22.755566,1.159224,0.363365,-367.990906,0.037282,0.000000
31.680002,5.176353,-368.035400,-0.003070,0.001459,0.037048,23.025570,1.172979,0.370481,-368.035400,0.037967,0.000000
32.090000,5.304451,-368.124359,-0.003044,0.001488,0.037785,23.595377,1.202006,0.377854,-368.124359,0.038644,0.000000
32.500000,5.307426,-368.124359,-0.003009,0.001511,0.038392,23.608612,1.202680,0.383917,-368.124359,0.039329,0.000000
32.910000,5.426216,-368.168823,-0.002992,0.001539,0.039094,24.137014,1.229598,0.390942,-368.168823,0.040014,0.000000
33.320000,5.416161,-368.168823,-0.002971,0.001557,0.039554,24.092285,1.227319,0.395544,-368.168823,0.040699,0.000000
33.730003,5.808640,-368.213318,-0.002923,0.001594,0.040491,25.838120,1.316257,0.404908,-368.213318,0.041384,0.000000
34.140003,5.644798,-368.168823,-0.002906,0.001615,0.041011,25.109316,1.279130,0.410109,-368.168823,0.042061,0.000000
34.550003,5.949028,-368.257782,-0.002880,0.001646,0.041809,26.462599,1.348069,0.418087,-368.257782,0.042746,0.000000
34.960003,6.126648,-368.257782,-0.002859,0.001674,0.042511,27.252691,1.388318,0.425112,-368.257782,0.043431,0.000000
35.370003,6.185852,-368.257782,-0.002828,0.001695,0.043058,27.516045,1.401734,0.430577,-368.257782,0.044116,0.000000
35.780003,6.267776,-368.302277,-0.002802,0.001721,0.043708,27.880463,1.420298,0.437080,-368.302277,0.044801,0.000000
36.190002,6.272247,-368.302277,-0.002772,0.001740,0.044202,27.900349,1.421311,0.442023,-368.302277,0.045477,0.000000
36.600002,6.509071,-368.346741,-0.002738,0.001769,0.044931,28.953794,1.474977,0.449312,-368.346741,0.046162,0.000000
37.010002,6.730637,-368.346741,-0.002729,0.001799,0.045703,29.939367,1.525184,0.457026,-368.346741,0.046847,0.000000
37.420002,7.090347,-368.302277,-0.002695,0.001836,0.046631,31.539440,1.606696,0.466307,-368.302277,0.047533,0.000000
37.830002,7.047897,-368.391235,-0.002669,0.001862,0.047290,31.350613,1.597076,0.472900,-368.391235,0.048218,0.000000
38.240002,7.146576,-368.435730,-0.002647,0.001888,0.047949,31.789557,1.619437,0.479486,-368.435730,0.048894,0.000000
38.650002,7.265732,-368.435730,-0.002596,0.001915,0.048634,32.319588,1.646438,0.486336,-368.435730,0.049579,0.000000
39.060001,7.361061,-368.480194,-0.002578,0.001937,0.049198,32.743633,1.668040,0.491976,-368.480194,0.050264,0.000000
39.470001,7.796364,-368.435730,-0.002565,0.001971,0.050073,34.679958,1.766681,0.500734,-368.435730,0.050949,0.000000
39.880001,7.773277,-368.569153,-0.002522,0.001996,0.050690,34.577263,1.761450,0.506896,-368.569153,0.051634,0.000000
40.290001,7.939354,-368.569153,-0.002509,0.002024,0.051400,35.316010,1.799083,0.514004,-368.569153,0.052311,0.000000
40.700001,8.084953,-368.613647,-0.002462,0.002049,0.052033,35.963669,1.832077,0.520332,-368.613647,0.052996,0.000000
41.110001,8.037292,-368.613647,-0.002458,0.002068,0.052528,35.751663,1.821277,0.525275,-368.613647,0.053681,0.000000
41.520000,8.733253,-368.613647,-0.002419,0.002107,0.053516,38.847450,1.978984,0.535161,-368.613647,0.054366,0.000000
41.930000,8.786133,-368.658112,-0.002397,0.002133,0.054185,39.082672,1.990966,0.541846,-368.658112,0.055051,0.000000
42.340000,8.858368,-368.747070,-0.002367,0.002157,0.054800,39.403988,2.007335,0.548000,-368.747070,0.055728,0.000000
42.750004,9.181221,-368.658112,-0.002345,0.002186,0.055528,40.840111,2.080494,0.555282,-368.658112,0.056413,0.000000
43.160004,9.158875,-368.702606,-0.002328,0.002206,0.056040,40.740707,2.075431,0.560399,-368.702606,0.057098,0.000000
43.570004,9.704033,-368.702606,-0.002285,0.002241,0.056933,43.165695,2.198965,0.569331,-368.702606,0.057783,0.000000
43.980003,9.799355,-368.747070,-0.002268,0.002266,0.057549,43.589706,2.220565,0.575493,-368.747070,0.058468,0.000000
44.390003,9.905479,-368.747070,-0.002242,0.002290,0.058156,44.061771,2.244614,0.581564,-368.747070,0.059145,0.000000
44.800003,10.167633,-368.836060,-0.002207,0.002316,0.058815,45.227890,2.304019,0.588150,-368.836060,0.059830,0.000000
45.210003,10.201523,-368.836060,-0.002195,0.002336,0.059327,45.378639,2.311698,0.593267,-368.836060,0.060515,0.000000
45.620003,10.971588,-368.836060,-0.002169,0.002376,0.060342,48.804062,2.486197,0.603418,-368.836060,0.061200,0.000000
46.030003,10.734756,-368.880524,-0.002134,0.002392,0.060749,47.750580,2.432531,0.607491,-368.880524,0.061885,0.000000
46.440002,11.017761,-368.880524,-0.002117,0.002418,0.061417,49.009449,2.496660,0.614167,-368.880524,0.062561,0.000000
46.850002,11.355125,-368.925018,-0.002095,0.002445,0.062093,50.510120,2.573108,0.620935,-368.925018,0.063247,0.000000
47.260002,12.203018,-368.925018,-0.002061,0.002483,0.063073,54.281734,2.765243,0.630730,-368.925018,0.063932,0.000000
47.670002,12.292389,-368.925018,-0.002044,0.002509,0.063724,54.679276,2.785495,0.637240,-368.925018,0.064617,0.000000
48.080002,12.416763,-369.058441,-0.002022,0.002534,0.064365,55.232521,2.813679,0.643652,-369.058441,0.065302,0.000000
48.490002,12.919838,-368.969482,-0.001988,0.002564,0.065137,57.470310,2.927677,0.651373,-368.969482,0.065978,0.000000
48.900002,13.240822,-369.013977,-0.001957,0.002590,0.065797,58.898117,3.000413,0.657966,-369.013977,0.066663,0.000000
49.310001,13.319763,-369.102936,-0.001940,0.002613,0.066360,59.249268,3.018301,0.663598,-369.102936,0.067348,0.000000
49.720001,13.880928,-369.102936,-0.001914,0.002643,0.067132,61.745453,3.145463,0.671319,-369.102936,0.068033,0.000000
50.130001,14.362038,-369.058441,-0.001888,0.002674,0.067912,63.885532,3.254484,0.679124,-369.058441,0.068719,0.000000
50.540001,14.183296,-369.102936,-0.001850,0.002689,0.068303,63.090454,3.213981,0.683030,-369.102936,0.069395,0.000000
50.950001,14.916130,-369.058441,-0.001837,0.002721,0.069109,66.350258,3.380043,0.691092,-369.058441,0.070080,0.000000
51.360001,15.282913,-369.236389,-0.001811,0.002745,0.069725,67.981796,3.463158,0.697246,-369.236389,0.070765,0.000000
51.770004,15.632202,-369.102936,-0.001789,0.002769,0.070341,69.535507,3.542308,0.703408,-369.102936,0.071450,0.000000
52.180004,15.595337,-369.236389,-0.001759,0.002787,0.070792,69.371521,3.533954,0.707919,-369.236389,0.072136,0.000000
52.590004,16.949654,-369.236389,-0.001729,0.002828,0.071832,75.395828,3.840846,0.718320,-369.236389,0.072812,0.000000
53.000004,17.313087,-369.280853,-0.001707,0.002857,0.072561,77.012459,3.923202,0.725610,-369.280853,0.073497,0.000000
53.410004,17.871277,-369.280853,-0.001677,0.002886,0.073298,79.495407,4.049689,0.732975,-369.280853,0.074182,0.000000
53.820004,18.081291,-369.280853,-0.001656,0.002910,0.073914,80.429604,4.097279,0.739137,-369.280853,0.074867,0.000000
54.230003,18.659958,-369.369812,-0.001634,0.002936,0.074581,83.003639,4.228407,0.745814,-369.369812,0.075553,0.000000
54.640003,18.702034,-369.325348,-0.001634,0.002954,0.075023,83.190804,4.237941,0.750234,-369.325348,0.076229,0.000000
55.050003,20.267860,-369.325348,-0.001591,0.002993,0.076012,90.155945,4.592763,0.760120,-369.325348,0.076914,0.000000
55.460003,20.299889,-369.414307,-0.001578,0.003019,0.076671,90.298416,4.600021,0.766714,-369.414307,0.077599,0.000000
55.870003,21.075539,-369.369812,-0.001539,0.003045,0.077331,93.748680,4.775785,0.773307,-369.369812,0.078284,0.000000
56.280003,21.869064,-369.503265,-0.001522,0.003072,0.078024,97.278458,4.955601,0.780241,-369.503265,0.078970,0.000000
56.690002,22.257080,-369.458771,-0.001505,0.003094,0.078579,99.004440,5.043527,0.785790,-369.458771,0.079646,0.000000
57.100002,23.132156,-369.458771,-0.001479,0.003122,0.079299,102.896973,5.241822,0.792988,-369.458771,0.080331,0.000000
57.510002,23.595009,-369.547729,-0.001462,0.003147,0.079923,104.955841,5.346705,0.799234,-369.547729,0.081016,0.000000
57.920002,24.188202,-369.503265,-0.001436,0.003167,0.080452,107.594498,5.481125,0.804525,-369.503265,0.081701,0.000000
58.330002,25.236427,-369.547729,-0.001418,0.003200,0.081268,112.257233,5.718657,0.812678,-369.547729,0.082387,0.000000
58.740002,26.567657,-369.592224,-0.001406,0.003233,0.082118,118.178841,6.020317,0.821178,-369.592224,0.083063,0.000000
59.150002,27.093452,-369.592224,-0.001367,0.003260,0.082803,120.517693,6.139464,0.828029,-369.592224,0.083748,0.000000
59.560001,27.791649,-369.636688,-0.001350,0.003286,0.083461,123.623428,6.297678,0.834615,-369.636688,0.084433,0.000000
59.970001,28.411278,-369.636688,-0.001324,0.003313,0.084147,126.379677,6.438088,0.841465,-369.636688,0.085119,0.000000
60.380001,29.140381,-369.725677,-0.001298,0.003335,0.084720,129.622894,6.603304,0.847196,-369.725677,0.085804,0.000000
60.790005,30.595245,-369.725677,-0.001293,0.003368,0.085551,136.094452,6.932981,0.855515,-369.725677,0.086480,0.000000
61.200005,31.269981,-369.681183,-0.001276,0.003392,0.086159,139.095825,7.085879,0.861586,-369.681183,0.087165,0.000000
61.610004,32.240753,-369.725677,-0.001250,0.003421,0.086888,143.414032,7.305859,0.868876,-369.725677,0.087850,0.000000
62.020004,33.358994,-369.770142,-0.001233,0.003447,0.087555,148.388214,7.559256,0.875552,-369.770142,0.088535,0.000000
62.430004,33.555229,-369.814636,-0.001224,0.003466,0.088040,149.261108,7.603724,0.880404,-369.814636,0.089220,0.000000
62.840004,35.783508,-369.859100,-0.001212,0.003504,0.088995,159.172989,8.108659,0.889950,-369.859100,0.089897,0.000000
63.250004,36.571823,-369.859100,-0.001168,0.003531,0.089688,162.679596,8.287293,0.896884,-369.859100,0.090582,0.000000
63.660004,37.640526,-369.859100,-0.001164,0.003556,0.090313,167.433426,8.529466,0.903129,-369.859100,0.091267,0.000000
64.070000,39.124802,-369.814636,-0.001125,0.003585,0.091050,174.035812,8.865807,0.910502,-369.814636,0.091952,0.000000
64.480003,39.630486,-369.903595,-0.001125,0.003604,0.091544,176.285202,8.980396,0.915445,-369.903595,0.092637,0.000000
64.889999,41.511337,-369.859100,-0.001117,0.003639,0.092438,184.651657,9.406604,0.924377,-369.859100,0.093314,0.000000
65.300003,42.611702,-369.948059,-0.001095,0.003664,0.093071,189.546310,9.655951,0.930706,-369.948059,0.093999,0.000000
65.710007,43.545982,-369.992554,-0.001082,0.003688,0.093669,193.702209,9.867661,0.936693,-369.992554,0.094684,0.000000
66.120003,45.054092,-369.992554,-0.001069,0.003714,0.094328,200.410614,10.209403,0.943279,-369.992554,0.095369,0.000000
66.530006,46.272491,-370.037018,-0.001039,0.003741,0.095030,205.830322,10.485497,0.950304,-370.037018,0.096054,0.000000
66.940002,48.136589,-370.037018,-0.001022,0.003772,0.095820,214.122238,10.907907,0.958199,-370.037018,0.096731,0.000000
67.350006,48.994911,-370.037018,-0.001000,0.003790,0.096271,217.940247,11.102406,0.962711,-370.037018,0.097416,0.000000
67.760002,50.167885,-370.170471,-0.000987,0.003817,0.096947,223.157898,11.368205,0.969471,-370.170471,0.098101,0.000000
68.170006,51.919899,-370.081512,-0.000987,0.003842,0.097597,230.951248,11.765218,0.975973,-370.081512,0.098786,0.000000
68.580002,53.954536,-370.126007,-0.000970,0.003878,0.098508,240.001770,12.226273,0.985079,-370.126007,0.099471,0.000000
68.990005,55.751610,-370.126007,-0.000961,0.003906,0.099210,247.995544,12.633495,0.992104,-370.126007,0.100148,0.000000
69.400002,56.835213,-370.126007,-0.000931,0.003927,0.099757,252.815659,12.879044,0.997570,-370.126007,0.100833,0.000000
69.810005,59.223984,-370.126007,-0.000905,0.003963,0.100650,263.441437,13.420346,1.006502,-370.126007,0.101518,0.000000
70.220001,60.591331,-370.170471,-0.000901,0.003988,0.101283,269.523712,13.730192,1.012830,-370.170471,0.102203,0.000000
70.630005,61.986610,-370.214966,-0.000897,0.004011,0.101873,275.730225,14.046367,1.018727,-370.214966,0.102888,0.000000
71.040001,64.089401,-370.259430,-0.000897,0.004041,0.102653,285.083893,14.522866,1.026532,-370.259430,0.103564,0.000000
71.450005,65.769547,-370.214966,-0.000867,0.004069,0.103356,292.557556,14.903592,1.033556,-370.214966,0.104249,0.000000
71.860001,65.372971,-370.303925,-0.000858,0.004063,0.103209,290.793488,14.813726,1.032088,-370.303925,290.695770,0.000000
72.270004,67.871582,-370.303925,-0.000849,0.004084,0.103746,301.907867,15.379920,1.037462,-370.303925,294.500519,0.000000
72.680000,65.798218,-370.348389,-0.000815,0.003893,0.098872,292.685089,14.910089,0.988721,-370.348389,294.500519,0.000000
73.090004,65.405731,-370.348389,-0.000811,0.004080,0.103625,290.939209,14.821150,1.036251,-370.348389,294.500519,0.000000
73.500000,65.205780,-370.348389,-0.000815,0.004088,0.103842,290.049805,14.775841,1.038416,-370.348389,294.500519,0.000000
73.910004,65.206512,-370.437347,-0.000815,0.004095,0.104024,290.053040,14.776007,1.040241,-370.437347,294.500519,0.000000
74.320007,65.159225,-370.392883,-0.000828,0.004099,0.104110,289.842712,14.765291,1.041103,-370.392883,294.500519,0.000000
74.730003,64.925751,-370.481842,-0.000811,0.004100,0.104136,288.804169,14.712385,1.041361,-370.481842,294.500519,0.000000
75.140007,65.607193,-370.437347,-0.000819,0.004109,0.104371,291.835358,14.866803,1.043707,-370.437347,294.500519,0.000000
75.550003,65.308914,-370.526337,-0.000811,0.004109,0.104371,290.508545,14.799212,1.043707,-370.526337,294.500519,0.000000
75.960007,65.027039,-370.570801,-0.000815,0.004109,0.104379,289.254700,14.735337,1.043791,-370.570801,294.500519,0.000000
76.370003,65.970993,-370.526337,-0.000815,0.004116,0.104535,293.453644,14.949241,1.045350,-370.526337,294.500519,0.000000
76.780006,65.722992,-370.615295,-0.000793,0.004116,0.104535,292.350464,14.893044,1.045350,-370.615295,294.500519,0.000000
77.190002,65.450790,-370.615295,-0.000793,0.004116,0.104535,291.139648,14.831361,1.045350,-370.615295,294.500519,0.000000
77.600006,65.232590,-370.570801,-0.000798,0.004116,0.104544,290.169037,14.781916,1.045441,-370.570801,294.500519,0.000000
78.010002,65.652252,-370.659760,-0.000798,0.004126,0.104813,292.035797,14.877013,1.048128,-370.659760,294.500519,0.000000
78.420006,65.524902,-370.659760,-0.000798,0.004126,0.104813,291.469330,14.848155,1.048128,-370.659760,294.500519,0.000000
78.830002,65.345047,-370.748718,-0.000789,0.004126,0.104813,290.669281,14.807399,1.048128,-370.748718,294.500519,0.000000
79.240005,65.211731,-370.704254,-0.000789,0.004127,0.104822,290.076263,14.777190,1.048219,-370.704254,294.500519,0.000000
79.650002,65.030380,-370.659760,-0.000798,0.004127,0.104830,289.269592,14.736094,1.048302,-370.659760,294.500519,0.000000
80.060005,64.930969,-370.837677,-0.000793,0.004128,0.104839,288.827362,14.713568,1.048386,-370.837677,294.500519,0.000000
80.470001,65.864868,-370.748718,-0.000780,0.004139,0.105125,292.981567,14.925193,1.051247,-370.748718,294.500519,0.000000
80.880005,65.837692,-370.837677,-0.000802,0.004139,0.105125,292.860687,14.919034,1.051247,-370.837677,294.500519,0.000000
81.290001,65.754654,-370.837677,-0.000789,0.004139,0.105125,292.491302,14.900218,1.051247,-370.837677,294.500519,0.000000
81.700005,65.600113,-370.793213,-0.000785,0.004139,0.105125,291.803864,14.865198,1.051247,-370.793213,294.500519,0.000000
82.110001,65.511124,-370.882172,-0.000785,0.004139,0.105134,291.408020,14.845033,1.051338,-370.882172,294.500519,0.000000
82.520004,65.394196,-370.882172,-0.000793,0.004139,0.105134,290.887909,14.818537,1.051338,-370.882172,294.500519,0.000000
82.930000,65.298859,-370.926636,-0.000776,0.004139,0.105134,290.463837,14.796933,1.051338,-370.926636,294.500519,0.000000
83.340004,65.199448,-370.971130,-0.000798,0.004139,0.105134,290.021637,14.774406,1.051338,-370.971130,294.500519,0.000000
83.750008,65.097778,-370.926636,-0.000776,0.004139,0.105134,289.569366,14.751368,1.051338,-370.926636,294.500519,0.000000
84.160004,64.996872,-371.015625,-0.000789,0.004139,0.105134,289.120514,14.728501,1.051338,-371.015625,294.500519,0.000000
84.570007,64.911224,-370.971130,-0.000780,0.004139,0.105134,288.739532,14.709093,1.051338,-370.971130,294.500519,0.000000
84.980003,64.798401,-371.015625,-0.000759,0.004139,0.105134,288.237671,14.683528,1.051338,-371.015625,294.500519,0.000000
85.390007,64.729874,-371.015625,-0.000780,0.004139,0.105134,287.932861,14.667999,1.051338,-371.015625,294.500519,0.000000
85.800003,64.642746,-371.015625,-0.000785,0.004139,0.105134,287.545288,14.648255,1.051338,-371.015625,294.500519,0.000000
86.210007,64.564545,-371.104584,-0.000785,0.004139,0.105134,287.197449,14.630535,1.051338,-371.104584,294.500519,0.000000
86.620003,64.472946,-371.060089,-0.000789,0.004139,0.105142,286.789978,14.609778,1.051421,-371.060089,294.500519,0.000000
87.030006,64.408524,-371.149048,-0.000780,0.004139,0.105142,286.503418,14.595181,1.051421,-371.149048,294.500519,0.000000
87.440002,64.322876,-371.149048,-0.000785,0.004139,0.105142,286.122437,14.575771,1.051421,-371.149048,294.500519,0.000000
87.850006,66.872879,-371.193542,-0.000780,0.004042,0.102671,297.465424,15.153611,1.026706,-371.193542,294.500519,0.000000
88.260002,66.695267,-371.238007,-0.000767,0.004041,0.102645,296.675354,15.113363,1.026448,-371.238007,294.500519,0.000000
88.670006,66.653549,-371.193542,-0.000767,0.004041,0.102645,296.489807,15.103910,1.026448,-371.193542,294.500519,0.000000
89.080002,66.551147,-371.193542,-0.000759,0.004041,0.102645,296.034302,15.080706,1.026448,-371.193542,294.500519,0.000000
89.490005,66.405563,-371.326965,-0.000763,0.004041,0.102653,295.386688,15.047715,1.026532,-371.326965,294.500519,0.000000
89.900002,66.383591,-371.326965,-0.000755,0.004042,0.102662,295.288971,15.042737,1.026623,-371.326965,294.500519,0.000000
90.310005,66.310226,-371.415955,-0.000750,0.004042,0.102662,294.962616,15.026112,1.026623,-371.415955,294.500519,0.000000
90.720001,66.233521,-371.371460,-0.000767,0.004042,0.102662,294.621399,15.008730,1.026623,-371.371460,294.500519,0.000000
91.130005,66.163513,-371.326965,-0.000750,0.004042,0.102662,294.309998,14.992867,1.026623,-371.326965,294.500519,0.000000
91.540001,66.089783,-371.415955,-0.000750,0.004042,0.102662,293.982025,14.976159,1.026623,-371.415955,294.500519,0.000000
91.950005,66.023132,-371.371460,-0.000750,0.004042,0.102662,293.685547,14.961056,1.026623,-371.371460,294.500519,0.000000
92.360001,65.886093,-371.415955,-0.000759,0.004044,0.102723,293.075989,14.930002,1.027228,-371.415955,294.500519,0.000000
92.770004,65.873810,-371.504913,-0.000759,0.004070,0.103373,293.021332,14.927218,1.033731,-371.504913,294.500519,0.000000
93.180008,65.836197,-371.460419,-0.000750,0.004083,0.103721,292.854034,14.918696,1.037205,-371.460419,294.500519,0.000000
93.590004,65.779602,-371.549377,-0.000763,0.004087,0.103816,292.602295,14.905870,1.038159,-371.549377,294.500519,0.000000
94.000008,65.715179,-371.460419,-0.000750,0.004101,0.104171,292.315704,14.891273,1.041709,-371.460419,294.500519,0.000000
94.410004,65.673843,-371.593872,-0.000750,0.004113,0.104466,292.131836,14.881906,1.044661,-371.593872,294.500519,0.000000
94.820007,65.594894,-371.593872,-0.000746,0.004114,0.104484,291.780670,14.864016,1.044835,-371.593872,294.500519,0.000000
95.230003,65.562881,-371.593872,-0.000750,0.004114,0.104501,291.638275,14.856761,1.045009,-371.593872,294.500519,0.000000
95.640007,65.497711,-371.638336,-0.000755,0.004125,0.104770,291.348358,14.841993,1.047697,-371.638336,294.500519,0.000000
96.050003,65.459732,-371.638336,-0.000755,0.004128,0.104839,291.179443,14.833387,1.048386,-371.638336,294.500519,0.000000
96.460007,65.396057,-371.727295,-0.000746,0.004128,0.104839,290.896179,14.818958,1.048386,-371.727295,294.500519,0.000000
96.870003,65.332001,-371.682831,-0.000767,0.004128,0.104839,290.611267,14.804443,1.048386,-371.682831,294.500519,0.000000
97.280006,65.290680,-371.727295,-0.000746,0.004129,0.104865,290.427460,14.795079,1.048651,-371.727295,294.500519,0.000000
97.690002,65.254181,-371.727295,-0.000755,0.004129,0.104865,290.265106,14.786808,1.048651,-371.727295,294.500519,0.000000
98.100006,65.257156,-371.771790,-0.000759,0.004141,0.105186,290.278320,14.787483,1.051860,-371.771790,294.500519,0.000000
98.510002,65.212097,-371.771790,-0.000755,0.004144,0.105247,290.077881,14.777272,1.052466,-371.771790,294.500519,0.000000
98.920006,65.187149,-371.771790,-0.000767,0.004144,0.105247,289.966919,14.771620,1.052466,-371.771790,294.500519,0.000000
99.330002,65.136887,-371.771790,-0.000759,0.004144,0.105247,289.743347,14.760229,1.052466,-371.771790,294.500519,0.000000
99.740005,65.160721,-371.860748,-0.000746,0.004150,0.105420,289.849365,14.765630,1.054199,-371.860748,294.500519,0.000000
100.150002,65.135025,-371.860748,-0.000755,0.004151,0.105437,289.735077,14.759808,1.054373,-371.860748,294.500519,0.000000
100.560005,65.098907,-371.816284,-0.000750,0.004153,0.105498,289.574402,14.751623,1.054979,-371.816284,294.500519,0.000000
100.970001,65.142471,-371.949707,-0.000759,0.004155,0.105541,289.768188,14.761495,1.055410,-371.949707,294.500519,0.000000
101.380005,65.106354,-371.905243,-0.000755,0.004155,0.105541,289.607513,14.753311,1.055410,-371.905243,294.500519,0.000000
101.790009,65.067245,-371.905243,-0.000755,0.004155,0.105541,289.433563,14.744449,1.055410,-371.905243,294.500519,0.000000
102.200005,65.051605,-371.905243,-0.000767,0.004155,0.105541,289.363983,14.740905,1.055410,-371.905243,294.500519,0.000000
102.610008,65.019958,-371.905243,-0.000750,0.004155,0.105541,289.223206,14.733733,1.055410,-371.905243,294.500519,0.000000
103.020004,64.989059,-371.994202,-0.000750,0.004155,0.105541,289.085785,14.726732,1.055410,-371.994202,294.500519,0.000000
103.430008,64.949585,-371.994202,-0.000750,0.004155,0.105541,288.910187,14.717786,1.055410,-371.994202,294.500519,0.000000
103.840004,64.913834,-372.038666,-0.000746,0.004155,0.105541,288.751160,14.709685,1.055410,-372.038666,294.500519,0.000000
104.250008,65.665283,-372.038666,-0.000772,0.004166,0.105819,292.093781,14.879966,1.058189,-372.038666,294.500519,0.000000
104.660004,65.661926,-371.949707,-0.000746,0.004166,0.105819,292.078827,14.879205,1.058189,-371.949707,294.500519,0.000000
105.070007,65.653366,-372.038666,-0.000759,0.004166,0.105819,292.040771,14.877266,1.058189,-372.038666,294.500519,0.000000
105.480003,65.621719,-372.038666,-0.000750,0.004166,0.105819,291.899994,14.870094,1.058189,-372.038666,294.500519,0.000000
105.890007,65.591919,-372.127625,-0.000746,0.004166,0.105819,291.767426,14.863341,1.058189,-372.127625,294.500519,0.000000
106.300003,65.598633,-372.127625,-0.000763,0.004166,0.105819,291.797302,14.864862,1.058189,-372.127625,294.500519,0.000000
106.710007,65.582611,-372.172119,-0.000746,0.004166,0.105819,291.726013,14.861233,1.058189,-372.172119,294.500519,0.000000
107.120003,65.581497,-372.172119,-0.000759,0.004166,0.105819,291.721069,14.860980,1.058189,-372.172119,294.500519,0.000000
107.530006,65.552826,-372.216583,-0.000763,0.004166,0.105819,291.593536,14.854483,1.058189,-372.216583,294.500519,0.000000
107.940002,65.537552,-372.172119,-0.000755,0.004166,0.105819,291.525604,14.851022,1.058189,-372.172119,294.500519,0.000000
108.350006,65.505157,-372.261078,-0.000750,0.004166,0.105819,291.381500,14.843681,1.058189,-372.261078,294.500519,0.000000
108.760002,65.488037,-372.261078,-0.000750,0.004166,0.105819,291.305328,14.839802,1.058189,-372.261078,294.500519,0.000000
109.170006,65.436264,-372.394531,-0.000750,0.004166,0.105819,291.075043,14.828069,1.058189,-372.394531,294.500519,0.000000
109.580002,65.378555,-372.305573,-0.000755,0.004166,0.105819,290.818329,14.814992,1.058189,-372.305573,294.500519,0.000000
109.990005,65.342056,-372.394531,-0.000759,0.004166,0.105819,290.655975,14.806722,1.058189,-372.394531,294.500519,0.000000
110.400002,65.338715,-372.350037,-0.000746,0.004166,0.105819,290.641113,14.805964,1.058189,-372.350037,294.500519,0.000000
110.810005,65.326416,-372.394531,-0.000755,0.004166,0.105819,290.586426,14.803178,1.058189,-372.394531,294.500519,0.000000
111.220009,65.290680,-372.438995,-0.000755,0.004166,0.105819,290.427460,14.795079,1.058189,-372.438995,294.500519,0.000000
111.630005,65.270935,-372.438995,-0.000742,0.004166,0.105819,290.339630,14.790605,1.058189,-372.438995,294.500519,0.000000
112.040009,65.226624,-372.438995,-0.000750,0.004167,0.105845,290.142517,14.780564,1.058446,-372.438995,294.500519,0.000000
112.450005,65.218063,-372.527954,-0.000767,0.004167,0.105845,290.104431,14.778625,1.058446,-372.527954,294.500519,0.000000
112.860008,65.197952,-372.438995,-0.000755,0.004167,0.105845,290.014984,14.774067,1.058446,-372.438995,294.500519,0.000000
113.270004,65.178589,-372.527954,-0.000750,0.004167,0.105845,289.928833,14.769679,1.058446,-372.527954,294.500519,0.000000
113.680008,65.139114,-372.483490,-0.000767,0.004167,0.105845,289.753265,14.760735,1.058446,-372.483490,294.500519,0.000000
114.090004,65.124588,-372.527954,-0.000767,0.004167,0.105845,289.688629,14.757442,1.058446,-372.527954,294.500519,0.000000
114.500008,65.090332,-372.616913,-0.000759,0.004167,0.105845,289.536255,14.749681,1.058446,-372.616913,294.500519,0.000000
114.910004,65.076187,-372.572449,-0.000742,0.004167,0.105845,289.473328,14.746475,1.058446,-372.572449,294.500519,0.000000
115.320007,65.047882,-372.616913,-0.000759,0.004167,0.105845,289.347443,14.740061,1.058446,-372.616913,294.500519,0.000000
115.730003,65.034851,-372.572449,-0.000750,0.004167,0.105854,289.289459,14.737107,1.058537,-372.572449,294.500519,0.000000
116.140007,64.998734,-372.705902,-0.000755,0.004167,0.105854,289.128815,14.728924,1.058537,-372.705902,294.500519,0.000000
116.550003,64.986069,-372.750366,-0.000767,0.004167,0.105854,289.072479,14.726054,1.058537,-372.750366,294.500519,0.000000
116.960007,64.986069,-372.705902,-0.000750,0.004168,0.105862,289.072479,14.726054,1.058620,-372.705902,294.500519,0.000000
117.370003,64.969315,-372.750366,-0.000759,0.004168,0.105862,288.997955,14.722258,1.058620,-372.750366,294.500519,0.000000
117.780006,64.955917,-372.750366,-0.000750,0.004168,0.105862,288.938354,14.719221,1.058620,-372.750366,294.500519,0.000000
118.190002,64.919052,-372.750366,-0.000742,0.004168,0.105862,288.774353,14.710867,1.058620,-372.750366,294.500519,0.000000
118.600006,64.898941,-372.794861,-0.000755,0.004168,0.105862,288.684906,14.706310,1.058620,-372.794861,294.500519,0.000000
119.010002,65.741623,-372.750366,-0.000759,0.004176,0.106079,292.433350,14.897264,1.060793,-372.750366,294.500519,0.000000
119.420006,65.692841,-372.839325,-0.000746,0.004176,0.106079,292.216339,14.886210,1.060793,-372.839325,294.500519,0.000000
119.830009,65.666031,-372.883820,-0.000750,0.004176,0.106079,292.097107,14.880136,1.060793,-372.883820,294.500519,0.000000
120.240005,65.658585,-372.839325,-0.000737,0.004176,0.106079,292.063965,14.878448,1.060793,-372.839325,294.500519,0.000000
120.650009,65.642944,-372.928284,-0.000750,0.004176,0.106079,291.994385,14.874905,1.060793,-372.928284,294.500519,0.000000
121.060005,65.624695,-372.928284,-0.000746,0.004176,0.106079,291.913208,14.870769,1.060793,-372.928284,294.500519,0.000000
121.470009,65.607559,-372.972778,-0.000746,0.004176,0.106079,291.837006,14.866885,1.060793,-372.972778,294.500519,0.000000
121.880005,65.591171,-372.972778,-0.000746,0.004176,0.106079,291.764099,14.863172,1.060793,-372.972778,294.500519,0.000000
122.290009,65.585968,-372.928284,-0.000759,0.004176,0.106079,291.740967,14.861993,1.060793,-372.928284,294.500519,0.000000
122.700005,65.565109,-373.017242,-0.000750,0.004176,0.106079,291.648163,14.857265,1.060793,-373.017242,294.500519,0.000000
123.110008,65.556915,-373.017242,-0.000759,0.004176,0.106079,291.611725,14.855410,1.060793,-373.017242,294.500519,0.000000
123.520004,65.542023,-373.106232,-0.000746,0.004176,0.106079,291.545471,14.852035,1.060793,-373.106232,294.500519,0.000000
123.930008,65.544632,-373.106232,-0.000755,0.004176,0.106079,291.557098,14.852626,1.060793,-373.106232,294.500519,0.000000
124.340004,65.514099,-373.150696,-0.000759,0.004176,0.106079,291.421265,14.845707,1.060793,-373.150696,294.500519,0.000000
124.750008,65.501434,-373.106232,-0.000750,0.004176,0.106079,291.364929,14.842837,1.060793,-373.106232,294.500519,0.000000
125.160004,65.480209,-373.150696,-0.000750,0.004176,0.106079,291.270508,14.838028,1.060793,-373.150696,294.500519,0.000000
125.570007,65.451172,-373.195190,-0.000746,0.004176,0.106079,291.141357,14.831448,1.060793,-373.195190,294.500519,0.000000
125.980003,65.416168,-373.239655,-0.000742,0.004176,0.106079,290.985657,14.823516,1.060793,-373.239655,294.500519,0.000000
126.390007,65.407974,-373.195190,-0.000742,0.004176,0.106079,290.949188,14.821658,1.060793,-373.195190,294.500519,0.000000
126.800003,65.355087,-373.284149,-0.000755,0.004176,0.106079,290.713959,14.809674,1.060793,-373.284149,294.500519,0.000000
127.210007,65.358810,-373.239655,-0.000746,0.004176,0.106079,290.730499,14.810518,1.060793,-373.239655,294.500519,0.000000
127.620003,65.334991,-373.284149,-0.000750,0.004176,0.106079,290.624542,14.805120,1.060793,-373.284149,294.500519,0.000000
128.029999,65.318970,-373.328613,-0.000742,0.004176,0.106079,290.553284,14.801490,1.060793,-373.328613,294.500519,0.000000
128.440002,65.304825,-373.328613,-0.000755,0.004176,0.106079,290.490356,14.798285,1.060793,-373.328613,294.500519,0.000000
128.850006,65.282852,-373.417572,-0.000746,0.004176,0.106079,290.392639,14.793305,1.060793,-373.417572,294.500519,0.000000
129.260010,65.270935,-373.373108,-0.000750,0.004176,0.106079,290.339630,14.790605,1.060793,-373.373108,294.500519,0.000000
129.670013,65.257156,-373.373108,-0.000750,0.004176,0.106079,290.278320,14.787483,1.060793,-373.373108,294.500519,0.000000
130.080002,65.247849,-373.462067,-0.000746,0.004176,0.106079,290.236938,14.785374,1.060793,-373.462067,294.500519,0.000000
130.490005,65.243011,-373.462067,-0.000742,0.004176,0.106079,290.215424,14.784278,1.060793,-373.462067,294.500519,0.000000
130.900009,65.214706,-373.506561,-0.000746,0.004176,0.106079,290.089508,14.777864,1.060793,-373.506561,294.500519,0.000000
131.310013,65.221039,-373.551025,-0.000755,0.004176,0.106079,290.117676,14.779299,1.060793,-373.551025,294.500519,0.000000
131.720001,65.124222,-373.506561,-0.000733,0.004177,0.106088,289.687012,14.757360,1.060876,-373.506561,294.500519,0.000000
132.130005,65.097778,-373.639984,-0.000759,0.004177,0.106105,289.569366,14.751368,1.061050,-373.639984,1681.641113,0.000000
132.540009,65.136139,-373.595520,-0.000737,0.004168,0.105879,289.740021,14.760059,1.058794,-373.595520,0.105671,0.000000
132.950012,65.087357,-373.639984,-0.000737,0.004148,0.105368,289.523010,14.749006,1.053677,-373.639984,0.104995,0.000000
133.360001,65.013626,-373.684479,-0.000729,0.004124,0.104743,289.195038,14.732298,1.047432,-373.684479,0.104310,0.000000
133.770004,64.988678,-373.684479,-0.000746,0.004098,0.104093,289.084076,14.726645,1.040929,-373.684479,0.103625,0.000000
134.180008,65.007675,-373.728943,-0.000720,0.004068,0.103338,289.168579,14.730949,1.033382,-373.728943,0.102939,0.000000
134.590012,64.947342,-373.773437,-0.000720,0.004048,0.102827,288.900208,14.717278,1.028273,-373.773437,0.102254,0.000000
135.000000,64.932083,-373.728943,-0.000716,0.004019,0.102073,288.832336,14.713820,1.020726,-373.728943,0.101578,0.000000
135.410004,64.856110,-373.728943,-0.000742,0.003992,0.101387,288.494385,14.696605,1.013875,-373.728943,0.100893,0.000000
135.820007,64.789825,-373.728943,-0.000720,0.003963,0.100659,288.199524,14.681584,1.006585,-373.728943,0.100208,0.000000
136.230011,64.437943,-373.817902,-0.000729,0.003940,0.100069,286.634277,14.601847,1.000688,-373.817902,0.099523,0.000000
136.639999,63.887939,-373.773437,-0.000729,0.003919,0.099531,284.187744,14.477214,0.995314,-373.773437,0.098838,0.000000
137.050003,62.616295,-373.817902,-0.000711,0.003891,0.098821,278.531189,14.189054,0.988206,-373.817902,0.098161,0.000000
137.460007,61.210213,-373.862396,-0.000703,0.003867,0.098213,272.276611,13.870433,0.982135,-373.862396,0.097476,0.000000
137.870010,59.460442,-373.906860,-0.000690,0.003840,0.097528,264.493256,13.473928,0.975284,-373.906860,0.096791,0.000000
138.280014,57.692413,-373.995850,-0.000690,0.003815,0.096912,256.628662,13.073288,0.969122,-373.995850,0.096106,0.000000
138.690002,55.795547,-373.995850,-0.000686,0.003794,0.096357,248.190994,12.643452,0.963574,-373.995850,0.095421,0.000000
139.100006,53.884163,-373.951355,-0.000686,0.003769,0.095742,239.688721,12.210326,0.957419,-373.951355,0.094744,0.000000
139.510010,51.011681,-373.995850,-0.000707,0.003741,0.095022,226.911285,11.559412,0.950221,-373.995850,0.094059,0.000000
139.920013,48.126907,-373.951355,-0.000690,0.003712,0.094285,214.079178,10.905713,0.942848,-373.951355,0.093374,0.000000
140.330002,45.048134,-373.995850,-0.000694,0.003683,0.093557,200.384109,10.208053,0.935565,-373.995850,0.092689,0.000000
140.740005,42.942741,-374.040314,-0.000698,0.003662,0.093018,191.018860,9.730964,0.930183,-374.040314,0.092004,0.000000
141.150009,39.577614,-374.084808,-0.000707,0.003635,0.092333,176.050018,8.968415,0.923333,-374.084808,0.091327,0.000000
141.560013,36.575172,-374.129272,-0.000703,0.003607,0.091622,162.694489,8.288053,0.916225,-374.129272,0.090642,0.000000
141.970001,34.683891,-374.084808,-0.000694,0.003593,0.091258,154.281647,7.859482,0.912584,-374.084808,0.089957,0.000000
142.380005,30.786270,-374.173767,-0.000694,0.003554,0.090270,136.944168,6.976268,0.902697,-374.173767,0.089272,0.000000
142.790009,28.204987,-374.173767,-0.000694,0.003534,0.089758,125.462044,6.391341,0.897580,-374.173767,0.088587,0.000000
143.200012,24.340500,-374.173767,-0.000686,0.003497,0.088830,108.271950,5.515636,0.888300,-374.173767,0.087911,0.000000
143.610001,21.899971,-374.262726,-0.000694,0.003476,0.088283,97.415939,4.962605,0.882834,-374.262726,0.087225,0.000000
144.020004,19.540993,-374.218231,-0.000690,0.003457,0.087816,86.922676,4.428052,0.878156,-374.218231,0.086540,0.000000
144.430008,16.027283,-374.218231,-0.000698,0.003420,0.086870,71.292915,3.631834,0.868702,-374.218231,0.085855,0.000000
144.840012,12.263718,-374.262726,-0.000703,0.003391,0.086125,54.551739,2.778998,0.861245,-374.262726,0.085170,0.000000
145.250000,10.048843,-374.307190,-0.000703,0.003370,0.085586,44.699490,2.277101,0.855863,-374.307190,0.084494,0.000000
145.660004,6.655792,-374.351685,-0.000698,0.003335,0.084710,29.606443,1.508224,0.847105,-374.351685,0.083809,0.000000
146.070007,3.781448,-374.307190,-0.000690,0.003309,0.084060,16.820723,0.856888,0.840602,-374.307190,0.083124,0.000000
146.480011,1.413155,-374.396179,-0.000694,0.003289,0.083549,6.286026,0.320225,0.835485,-374.396179,0.082439,0.000000
146.889999,-1.682003,-374.351685,-0.000698,0.003258,0.082751,-7.481923,-0.381147,0.827507,-374.351685,0.081753,0.000000
147.300003,-0.345932,-374.396179,-0.000703,0.003230,0.082048,-1.538782,-0.078389,0.820482,-374.396179,0.081068,0.000000
147.710007,-0.145966,-374.440643,-0.000711,0.003202,0.081337,-0.649287,-0.033076,0.813374,-374.440643,0.080392,0.000000
148.120010,-0.145592,-374.440643,-0.000720,0.003174,0.080618,-0.647624,-0.032992,0.806175,-374.440643,0.079707,0.000000
148.530014,-0.150810,-374.485138,-0.000742,0.003151,0.080028,-0.670837,-0.034174,0.800278,-374.485138,0.079022,0.000000
148.940002,-0.132561,-374.485138,-0.000798,0.003120,0.079247,-0.589660,-0.030039,0.792474,-374.485138,0.078337,0.000000
149.350006,-0.145966,-374.529602,-0.000819,0.003096,0.078640,-0.649287,-0.033076,0.786403,-374.529602,0.077652,0.000000
149.760010,-0.112083,-374.574097,-0.000849,0.003076,0.078137,-0.498572,-0.025398,0.781369,-374.574097,0.076975,0.000000
150.170013,-0.140755,-374.574097,-0.000884,0.003048,0.077409,-0.626108,-0.031895,0.774087,-374.574097,0.076290,0.000000
150.580002,-0.138893,-374.618561,-0.000927,0.003019,0.076689,-0.617827,-0.031474,0.766888,-374.618561,0.075605,0.000000
150.990005,-0.123253,-374.618561,-0.000944,0.002986,0.075848,-0.548256,-0.027929,0.758478,-374.618561,0.074920,0.000000
151.400009,-0.113571,-374.618561,-0.000979,0.002966,0.075336,-0.505190,-0.025736,0.753361,-374.618561,0.074235,0.000000
151.810013,-0.111336,-374.752014,-0.001018,0.002932,0.074460,-0.495246,-0.025229,0.744602,-374.752014,0.073558,0.000000
152.220001,-0.121017,-374.663055,-0.001061,0.002909,0.073896,-0.538313,-0.027423,0.738963,-374.663055,0.072873,0.000000
152.630005,-0.116920,-374.752014,-0.001065,0.002892,0.073445,-0.520088,-0.026495,0.734451,-374.752014,0.072188,0.000000
153.040009,-0.115807,-374.752014,-0.001099,0.002854,0.072483,-0.515133,-0.026242,0.724830,-374.752014,0.071503,0.000000
153.450012,-0.093460,-374.707520,-0.001138,0.002829,0.071849,-0.415731,-0.021178,0.718494,-374.707520,0.070818,0.000000
153.860001,-0.086014,-374.796509,-0.001168,0.002799,0.071104,-0.382608,-0.019491,0.711038,-374.796509,0.070141,0.000000
154.270004,-0.089363,-374.840973,-0.001203,0.002777,0.070532,-0.397507,-0.020250,0.705315,-374.840973,0.069456,0.000000
154.680008,-0.094208,-374.840973,-0.001233,0.002745,0.069716,-0.419057,-0.021348,0.697163,-374.840973,0.068771,0.000000
155.090012,-0.072609,-374.840973,-0.001263,0.002719,0.069066,-0.322981,-0.016453,0.690660,-374.840973,0.068086,0.000000
155.500000,-0.061440,-374.885468,-0.001289,0.002696,0.068467,-0.273297,-0.013922,0.684672,-374.885468,0.067401,0.000000
155.910004,-0.067772,-374.885468,-0.001315,0.002663,0.067635,-0.301465,-0.015357,0.676346,-374.885468,0.066725,0.000000
156.320007,-0.083038,-374.885468,-0.001337,0.002641,0.067071,-0.369373,-0.018817,0.670714,-374.885468,0.066039,0.000000
156.730011,-0.116547,-374.929932,-0.001380,0.002606,0.066204,-0.518425,-0.026410,0.662039,-374.929932,0.065354,0.000000
157.140015,-0.079681,-374.974426,-0.001418,0.002581,0.065554,-0.354441,-0.018056,0.655536,-374.974426,0.064669,0.000000
157.550003,-0.091599,-374.929932,-0.001436,0.002551,0.064791,-0.407451,-0.020757,0.647906,-374.929932,0.063984,0.000000
157.960007,-0.083405,-375.063385,-0.001466,0.002529,0.064227,-0.371002,-0.018900,0.642266,-375.063385,0.063308,0.000000
158.370010,-0.100540,-375.018890,-0.001509,0.002503,0.063567,-0.447225,-0.022783,0.635673,-375.018890,0.062623,0.000000
158.780014,-0.084526,-375.063385,-0.001513,0.002472,0.062796,-0.375991,-0.019154,0.627959,-375.063385,0.061938,0.000000
159.190002,-0.096443,-375.107849,-0.001548,0.002447,0.062154,-0.429001,-0.021854,0.621540,-375.107849,0.061252,0.000000
159.600006,-0.115433,-375.063385,-0.001591,0.002423,0.061556,-0.513470,-0.026157,0.615560,-375.063385,0.060567,0.000000
160.010010,-0.124367,-375.107849,-0.001621,0.002399,0.060940,-0.553211,-0.028182,0.609398,-375.107849,0.059891,0.000000
160.420013,-0.118782,-375.152344,-0.001647,0.002374,0.060307,-0.528369,-0.026916,0.603070,-375.152344,0.059206,0.000000
160.830002,-0.086014,-375.152344,-0.001660,0.002342,0.059474,-0.382608,-0.019491,0.594743,-375.152344,0.058521,0.000000
161.240005,-0.115807,-375.241302,-0.001699,0.002320,0.058937,-0.515133,-0.026242,0.589369,-375.241302,0.057835,0.000000
161.650009,-0.097183,-375.196808,-0.001725,0.002283,0.057991,-0.432293,-0.022022,0.579914,-375.196808,0.057150,0.000000
162.060013,-0.108727,-375.196808,-0.001733,0.002263,0.057471,-0.483640,-0.024638,0.574714,-375.196808,0.056474,0.000000
162.470001,-0.122131,-375.196808,-0.001781,0.002230,0.056647,-0.543267,-0.027675,0.566470,-375.196808,0.055789,0.000000
162.880005,-0.153412,-375.241302,-0.001807,0.002208,0.056075,-0.682410,-0.034764,0.560747,-375.241302,0.055104,0.000000
163.290009,-0.144852,-375.285797,-0.001832,0.002177,0.055294,-0.644332,-0.032824,0.552943,-375.285797,0.054418,0.000000
163.700012,-0.107239,-375.285797,-0.001867,0.002150,0.054618,-0.477022,-0.024301,0.546175,-375.285797,0.053733,0.000000
164.110001,-0.129585,-375.419220,-0.001884,0.002124,0.053942,-0.576424,-0.029364,0.539416,-375.419220,0.053057,0.000000
164.520004,-0.130699,-375.374756,-0.001927,0.002096,0.053230,-0.581379,-0.029617,0.532300,-375.374756,0.052372,0.000000
164.930008,-0.145966,-375.330261,-0.001962,0.002074,0.052684,-0.649287,-0.033076,0.526842,-375.330261,0.051687,0.000000
165.340012,-0.139633,-375.463715,-0.001966,0.002047,0.051990,-0.621119,-0.031641,0.519901,-375.463715,0.051001,0.000000
165.750015,-0.126228,-375.374756,-0.002001,0.002014,0.051157,-0.561492,-0.028604,0.511574,-375.374756,0.050316,0.000000
166.160004,-0.127350,-375.463715,-0.002031,0.001992,0.050585,-0.566480,-0.028858,0.505851,-375.463715,0.049640,0.000000
166.570007,-0.155647,-375.508179,-0.002061,0.001969,0.050013,-0.692354,-0.035270,0.500128,-375.508179,0.048955,0.000000
166.980011,-0.145592,-375.508179,-0.002087,0.001937,0.049189,-0.647624,-0.032992,0.491893,-375.508179,0.048270,0.000000
167.390015,-0.118782,-375.508179,-0.002113,0.001921,0.048790,-0.528369,-0.026916,0.487903,-375.508179,0.047584,0.000000
167.800003,-0.135544,-375.508179,-0.002147,0.001890,0.048018,-0.602929,-0.030715,0.480182,-375.508179,0.046899,0.000000
168.100006,-0.092346,-375.597137,-0.002182,0.001868,0.047454,-0.410776,-0.020926,0.474543,-375.597137,0.047341,0.000000