File: Data/compression 23/AutoNoHeating-12-23-reverse-2-3_09192024_184554.csv
Time (sec),S:Load (lbs),S:HL1 (DIM),S:LVDT (in),S:Position (in),Ch:Position (mm),Ch:Load (N),Ch:Stress (MPa),Ch:Strain (mm/mm),Ch:HL1 (DIM),Set Point (),Cycles ()
0.110000,-0.049522,-388.807983,-0.009356,-0.004911,-0.124750,-0.220287,-0.011222,-1.247501,-388.807983,-0.124395,0.000000
0.500000,-0.076706,-388.852478,-0.009369,-0.004850,-0.123198,-0.341205,-0.017382,-1.231983,-388.852478,-0.122522,0.000000
0.890000,-0.109848,-388.807983,-0.009257,-0.004620,-0.117345,-0.488628,-0.024892,-1.173446,-388.807983,-0.116018,0.000000
1.280000,-0.105377,-388.852478,-0.008985,-0.004367,-0.110910,-0.468741,-0.023879,-1.109095,-388.852478,-0.109531,0.000000
1.670000,-0.075958,-388.852478,-0.008718,-0.004109,-0.104371,-0.337879,-0.017212,-1.043707,-388.852478,-0.103026,0.000000
2.060000,-0.064415,-388.896942,-0.008455,-0.003854,-0.097884,-0.286532,-0.014597,-0.978842,-388.896942,-0.096522,0.000000
2.450000,-0.072235,-388.896942,-0.008192,-0.003597,-0.091362,-0.321318,-0.016369,-0.913621,-388.896942,-0.090036,0.000000
2.840000,-0.094582,-388.896942,-0.007942,-0.003344,-0.084936,-0.420720,-0.021432,-0.849361,-388.896942,-0.083531,0.000000
3.230000,-0.099419,-388.941437,-0.007649,-0.003080,-0.078224,-0.442236,-0.022529,-0.782239,-388.941437,-0.077045,0.000000
3.620000,-0.082291,-388.941437,-0.007394,-0.002833,-0.071962,-0.366047,-0.018647,-0.719622,-388.941437,-0.070541,0.000000
4.010000,-0.083405,-389.030396,-0.007140,-0.002572,-0.065337,-0.371002,-0.018900,-0.653371,-389.030396,-0.064036,0.000000
4.400000,-0.063675,-389.030396,-0.006873,-0.002318,-0.058876,-0.283240,-0.014429,-0.588763,-389.030396,-0.057549,0.000000
4.790000,-0.084152,-388.985931,-0.006597,-0.002063,-0.052389,-0.374328,-0.019069,-0.523890,-388.985931,-0.051045,0.000000
5.180000,-0.090858,-389.074890,-0.006342,-0.001803,-0.045798,-0.404159,-0.020589,-0.457980,-389.074890,-0.044558,0.000000
5.570000,-0.114685,-389.074890,-0.006096,-0.001549,-0.039355,-0.510145,-0.025988,-0.393546,-389.074890,-0.038054,0.000000
5.960001,-0.083038,-389.119354,-0.005825,-0.001292,-0.032816,-0.369373,-0.018817,-0.328158,-389.119354,-0.031550,0.000000
6.350000,-0.059952,-389.074890,-0.005553,-0.001034,-0.026260,-0.266679,-0.013585,-0.262596,-389.074890,-0.025063,0.000000
6.740000,-0.048409,-389.208313,-0.005303,-0.000784,-0.019912,-0.215332,-0.010970,-0.199116,-389.208313,-0.018559,0.000000
7.130000,-0.003723,-389.119354,-0.005036,-0.000530,-0.013451,-0.016561,-0.000844,-0.134508,-389.119354,-0.012072,0.000000
7.520000,0.124748,-389.119354,-0.004803,-0.000000,-0.000000,0.554908,0.028268,-0.000000,-389.119354,0.000208,0.000000
7.910000,0.089745,-389.252808,-0.004803,-0.000000,-0.000008,0.399204,0.020336,-0.000083,-389.252808,0.000208,0.000000
8.300000,0.078575,-389.252808,-0.004807,-0.000000,-0.000000,0.349520,0.017805,-0.000000,-389.252808,0.000728,0.000000
8.690001,0.054001,-389.252808,-0.004803,-0.000000,-0.000000,0.240208,0.012237,-0.000000,-389.252808,0.001379,0.000000
9.080001,0.098679,-389.252808,-0.004777,0.000041,0.001049,0.438944,0.022361,0.010492,-389.252808,0.002029,0.000000
9.470000,0.096077,-389.208313,-0.004751,0.000069,0.001761,0.427372,0.021771,0.017607,-389.208313,0.002680,0.000000
9.860001,0.084160,-389.386230,-0.004717,0.000092,0.002333,0.374362,0.019071,0.023330,-389.386230,0.003330,0.000000
10.250001,0.100540,-389.297272,-0.004695,0.000114,0.002888,0.447225,0.022783,0.028879,-389.297272,0.003981,0.000000
10.640000,0.154167,-389.341766,-0.004678,0.000140,0.003556,0.685770,0.034935,0.035555,-389.341766,0.004631,0.000000
11.030001,0.152679,-389.386230,-0.004652,0.000162,0.004110,0.679152,0.034598,0.041104,-389.386230,0.005281,0.000000
11.420000,0.176880,-389.386230,-0.004639,0.000191,0.004848,0.786801,0.040082,0.048477,-389.386230,0.005932,0.000000
11.810000,0.132942,-389.430725,-0.004613,0.000217,0.005507,0.591356,0.030125,0.055070,-389.430725,0.006583,0.000000
12.200001,0.201454,-389.386230,-0.004583,0.000243,0.006175,0.896113,0.045650,0.061747,-389.386230,0.007233,0.000000
12.590000,0.195129,-389.475220,-0.004544,0.000259,0.006583,0.867979,0.044217,0.065827,-389.475220,0.007883,0.000000
12.980000,0.266991,-389.430725,-0.004514,0.000299,0.007597,1.187634,0.060501,0.075970,-389.430725,0.008533,0.000000
13.370001,0.278542,-389.475220,-0.004480,0.000326,0.008282,1.239015,0.063118,0.082821,-389.475220,0.009184,0.000000
13.760000,0.266624,-389.519684,-0.004458,0.000350,0.008880,1.186005,0.060418,0.088801,-389.519684,0.009835,0.000000
14.150001,0.266991,-389.475220,-0.004445,0.000374,0.009496,1.187634,0.060501,0.094963,-389.475220,0.010485,0.000000
14.540001,0.326942,-389.608643,-0.004419,0.000393,0.009973,1.454313,0.074086,0.099732,-389.608643,0.011135,0.000000
14.930000,0.356735,-389.608643,-0.004389,0.000425,0.010797,1.586838,0.080837,0.107968,-389.608643,0.011777,0.000000
15.320001,0.374611,-389.519684,-0.004372,0.000446,0.011335,1.666353,0.084888,0.113350,-389.519684,0.012427,0.000000
15.710001,0.391365,-389.653137,-0.004329,0.000476,0.012081,1.740879,0.088685,0.120806,-389.653137,0.013078,0.000000
16.100000,0.438286,-389.608643,-0.004316,0.000504,0.012791,1.949593,0.099317,0.127914,-389.608643,0.013729,0.000000
16.490002,0.416687,-389.653137,-0.004312,0.000519,0.013190,1.853516,0.094423,0.131904,-389.653137,0.014379,0.000000
16.880001,0.530258,-389.653137,-0.004260,0.000556,0.014110,2.358706,0.120158,0.141101,-389.653137,0.015029,0.000000
17.270000,0.527657,-389.608643,-0.004243,0.000575,0.014595,2.347134,0.119569,0.145953,-389.608643,0.015679,0.000000
17.660002,0.582397,-389.742096,-0.004212,0.000600,0.015229,2.590633,0.131973,0.152289,-389.742096,0.016330,0.000000
18.050001,0.735435,-389.697601,-0.004186,0.000631,0.016018,3.271380,0.166652,0.160177,-389.697601,0.016981,0.000000
18.440001,0.790176,-389.786560,-0.004161,0.000651,0.016529,3.514880,0.179057,0.165294,-389.786560,0.017631,0.000000
18.830002,0.940613,-389.786560,-0.004126,0.000684,0.017379,4.184055,0.213146,0.173795,-389.786560,0.018281,0.000000
19.220001,0.954765,-389.786560,-0.004113,0.000696,0.017683,4.247008,0.216353,0.176830,-389.786560,0.018931,0.000000
19.610001,1.078018,-389.831055,-0.004074,0.000727,0.018472,4.795264,0.244282,0.184718,-389.831055,0.019582,0.000000
20.000000,1.102974,-389.831055,-0.004066,0.000738,0.018750,4.906273,0.249937,0.187496,-389.831055,0.020233,0.000000
20.390001,1.382622,-389.920013,-0.004014,0.000778,0.019764,6.150209,0.313307,0.197640,-389.920013,0.020883,0.000000
20.780001,1.538643,-389.875549,-0.004001,0.000806,0.020476,6.844225,0.348661,0.204755,-389.875549,0.021533,0.000000
21.170000,1.676796,-389.875549,-0.003984,0.000829,0.021048,7.458761,0.379967,0.210478,-389.875549,0.022184,0.000000
21.560001,1.785156,-389.920013,-0.003954,0.000852,0.021637,7.940772,0.404522,0.216375,-389.920013,0.022834,0.000000
21.950001,1.954216,-389.831055,-0.003928,0.000883,0.022418,8.692787,0.442832,0.224179,-389.831055,0.023485,0.000000
22.340000,2.090500,-389.964508,-0.003911,0.000906,0.023008,9.299007,0.473714,0.230076,-389.964508,0.024135,0.000000
22.730001,2.209290,-389.964508,-0.003876,0.000932,0.023667,9.827411,0.500632,0.236669,-389.964508,0.024786,0.000000
23.120001,2.307968,-389.964508,-0.003854,0.000954,0.024239,10.266355,0.522993,0.242392,-389.964508,0.025436,0.000000
23.510000,2.437553,-390.008972,-0.003829,0.000980,0.024889,10.842779,0.552357,0.248895,-390.008972,0.026086,0.000000
23.900002,2.627464,-390.008972,-0.003794,0.001014,0.025757,11.687545,0.595392,0.257570,-390.008972,0.026728,0.000000
24.290001,2.688164,-390.142426,-0.003790,0.001036,0.026303,11.957550,0.609147,0.263027,-390.142426,0.027378,0.000000
24.680000,2.770081,-390.053467,-0.003747,0.001058,0.026884,12.321934,0.627709,0.268841,-390.053467,0.028029,0.000000
25.070002,2.859077,-390.053467,-0.003729,0.001081,0.027448,12.717812,0.647876,0.274481,-390.053467,0.028679,0.000000
25.460001,2.971909,-390.186890,-0.003686,0.001111,0.028229,13.219709,0.673444,0.282285,-390.186890,0.029330,0.000000
25.850000,2.947334,-390.097931,-0.003695,0.001130,0.028696,13.110397,0.667875,0.286963,-390.097931,0.029980,0.000000
26.240002,3.240013,-390.231384,-0.003673,0.001162,0.029512,14.412298,0.734197,0.295116,-390.231384,0.030630,0.000000
26.630001,3.322311,-390.186890,-0.003622,0.001189,0.030197,14.778379,0.752847,0.301966,-390.186890,0.031281,0.000000
27.020000,3.381142,-390.231384,-0.003596,0.001214,0.030839,15.040070,0.766178,0.308386,-390.231384,0.031932,0.000000
27.410002,3.422104,-390.231384,-0.003579,0.001239,0.031471,15.222279,0.775460,0.314714,-390.231384,0.032582,0.000000
27.800001,3.559509,-390.275879,-0.003548,0.001265,0.032122,15.833488,0.806596,0.321224,-390.275879,0.033232,0.000000
28.190001,3.667870,-390.275879,-0.003523,0.001291,0.032798,16.315498,0.831151,0.327984,-390.275879,0.033882,0.000000
28.580002,3.833946,-390.275879,-0.003475,0.001326,0.033674,17.054245,0.868785,0.336742,-390.275879,0.034533,0.000000
28.970001,3.801178,-390.320343,-0.003471,0.001348,0.034246,16.908484,0.861359,0.342465,-390.320343,0.035184,0.000000
29.360001,3.806396,-390.364838,-0.003449,0.001371,0.034828,16.931698,0.862542,0.348278,-390.364838,0.035834,0.000000
29.750002,4.031311,-390.364838,-0.003419,0.001402,0.035617,17.932167,0.913508,0.356174,-390.364838,0.036484,0.000000
30.140001,4.072639,-390.409302,-0.003385,0.001425,0.036190,18.116005,0.922873,0.361897,-390.409302,0.037134,0.000000
30.530001,4.140411,-390.364838,-0.003354,0.001450,0.036840,18.417469,0.938231,0.368399,-390.364838,0.037785,0.000000
30.920002,4.197762,-390.409302,-0.003333,0.001480,0.037603,18.672575,0.951226,0.376029,-390.409302,0.038436,0.000000
31.310001,4.151955,-390.453796,-0.003311,0.001501,0.038123,18.468817,0.940846,0.381230,-390.453796,0.039086,0.000000
31.700001,4.349312,-390.409302,-0.003285,0.001525,0.038730,19.346704,0.985568,0.387301,-390.409302,0.039736,0.000000
32.090000,4.426765,-390.498260,-0.003260,0.001549,0.039337,19.691236,1.003119,0.393372,-390.498260,0.040387,0.000000
32.480003,4.470711,-390.453796,-0.003225,0.001572,0.039919,19.886715,1.013077,0.399185,-390.453796,0.041037,0.000000
32.870003,4.575714,-390.542755,-0.003212,0.001601,0.040656,20.353792,1.036872,0.406558,-390.542755,0.041679,0.000000
33.260002,4.584282,-390.587219,-0.003186,0.001623,0.041236,20.391905,1.038813,0.412364,-390.587219,0.042330,0.000000
33.650002,4.644608,-390.587219,-0.003156,0.001644,0.041757,20.660246,1.052483,0.417572,-390.587219,0.042980,0.000000
34.040001,4.861328,-390.631714,-0.003139,0.001674,0.042511,21.624268,1.101593,0.425112,-390.631714,0.043630,0.000000
34.430000,5.089966,-390.542755,-0.003091,0.001711,0.043466,22.641298,1.153403,0.434657,-390.542755,0.044281,0.000000
34.820004,5.032990,-390.631714,-0.003061,0.001735,0.044073,22.387856,1.140492,0.440728,-390.631714,0.044931,0.000000
35.210003,5.059799,-390.676178,-0.003053,0.001758,0.044663,22.507111,1.146567,0.446625,-390.676178,0.045581,0.000000
35.600002,5.104485,-390.631714,-0.003031,0.001779,0.045191,22.705881,1.156693,0.451909,-390.631714,0.046232,0.000000
35.990002,5.265350,-390.765167,-0.003001,0.001803,0.045790,23.421448,1.193145,0.457897,-390.765167,0.046882,0.000000
36.380001,5.483932,-390.631714,-0.002975,0.001833,0.046570,24.393749,1.242677,0.465701,-390.631714,0.047533,0.000000
36.770000,5.501808,-390.765167,-0.002940,0.001858,0.047186,24.473265,1.246727,0.471855,-390.765167,0.048183,0.000000
37.160004,5.524147,-390.809631,-0.002928,0.001881,0.047767,24.572634,1.251790,0.477669,-390.809631,0.048833,0.000000
37.550003,5.760605,-390.765167,-0.002897,0.001910,0.048522,25.624451,1.305372,0.485216,-390.765167,0.049484,0.000000
37.940002,5.809761,-390.854126,-0.002867,0.001931,0.049059,25.843107,1.316511,0.490591,-390.854126,0.050135,0.000000
38.330002,5.976578,-390.809631,-0.002837,0.001962,0.049831,26.585146,1.354312,0.498312,-390.809631,0.050785,0.000000
38.720001,5.860031,-390.809631,-0.002820,0.001977,0.050204,26.066721,1.327902,0.502036,-390.809631,0.051435,0.000000
39.110001,6.202614,-390.854126,-0.002802,0.002008,0.051011,27.590605,1.405532,0.510105,-390.854126,0.052085,0.000000
39.500000,6.245438,-390.898590,-0.002772,0.002034,0.051669,27.781094,1.415236,0.516691,-390.898590,0.052736,0.000000
39.890003,6.311714,-390.943085,-0.002755,0.002058,0.052268,28.075907,1.430255,0.522679,-390.943085,0.053387,0.000000
40.280003,6.479660,-390.898590,-0.002708,0.002089,0.053048,28.822968,1.468312,0.530483,-390.898590,0.054037,0.000000
40.670002,6.256981,-390.943085,-0.002708,0.002104,0.053439,27.832441,1.417852,0.534389,-390.943085,0.054687,0.000000
41.060001,6.458801,-390.987549,-0.002677,0.002126,0.054011,28.730183,1.463585,0.540112,-390.987549,0.055337,0.000000
41.450001,6.941399,-390.943085,-0.002639,0.002166,0.055017,30.876883,1.572943,0.550172,-390.943085,0.055988,0.000000
41.840000,6.773834,-390.987549,-0.002621,0.002180,0.055364,30.131519,1.534973,0.553639,-390.987549,0.056630,0.000000
42.230003,7.156631,-390.987549,-0.002591,0.002215,0.056257,31.834288,1.621716,0.562572,-390.987549,0.057281,0.000000
42.620003,7.020714,-391.076508,-0.002574,0.002230,0.056639,31.229694,1.590917,0.566387,-391.076508,0.057931,0.000000
43.010002,7.346169,-391.121002,-0.002544,0.002263,0.057480,32.677391,1.664665,0.574797,-391.121002,0.058581,0.000000
43.400002,7.469048,-391.076508,-0.002509,0.002287,0.058096,33.223984,1.692510,0.580959,-391.076508,0.059231,0.000000
43.790001,7.679443,-391.076508,-0.002505,0.002314,0.058764,34.159870,1.740187,0.587635,-391.076508,0.059882,0.000000
44.180000,7.534958,-391.165497,-0.002466,0.002331,0.059197,33.517166,1.707446,0.591973,-391.165497,0.060533,0.000000
44.570004,8.011971,-391.121002,-0.002449,0.002367,0.060125,35.639027,1.815539,0.601246,-391.121002,0.061183,0.000000
44.960003,8.182144,-391.209961,-0.002414,0.002392,0.060766,36.395996,1.854100,0.607665,-391.209961,0.061833,0.000000
45.350002,8.354553,-391.121002,-0.002393,0.002419,0.061434,37.162910,1.893169,0.614341,-391.121002,0.062484,0.000000
45.740002,8.406685,-391.254456,-0.002363,0.002443,0.062050,37.394802,1.904982,0.620503,-391.254456,0.063134,0.000000
46.130001,8.598083,-391.209961,-0.002345,0.002469,0.062718,38.246185,1.948354,0.627180,-391.209961,0.063785,0.000000
46.520000,8.636436,-391.254456,-0.002324,0.002489,0.063230,38.416786,1.957044,0.632297,-391.254456,0.064435,0.000000
46.910004,8.796928,-391.254456,-0.002285,0.002515,0.063872,39.130692,1.993412,0.638716,-391.254456,0.065085,0.000000
47.300003,8.910133,-391.298920,-0.002276,0.002534,0.064374,39.634254,2.019065,0.643743,-391.298920,0.065736,0.000000
47.690002,9.457520,-391.298920,-0.002251,0.002568,0.065215,42.069149,2.143105,0.652153,-391.298920,0.066386,0.000000
48.080002,9.683922,-391.298920,-0.002225,0.002598,0.065978,43.076237,2.194408,0.659783,-391.298920,0.067037,0.000000
48.470001,9.808662,-391.343414,-0.002186,0.002623,0.066620,43.631111,2.222675,0.666202,-391.343414,0.067687,0.000000
48.860001,9.890213,-391.343414,-0.002173,0.002647,0.067227,43.993866,2.241154,0.672273,-391.343414,0.068338,0.000000
49.250004,10.018311,-391.343414,-0.002151,0.002667,0.067748,44.563671,2.270182,0.677481,-391.343414,0.068988,0.000000
49.640003,10.432014,-391.387878,-0.002126,0.002697,0.068502,46.403919,2.363928,0.685021,-391.387878,0.069638,0.000000
50.030003,10.787262,-391.476837,-0.002087,0.002731,0.069370,47.984138,2.444428,0.693696,-391.476837,0.070289,0.000000
50.420002,10.872536,-391.432373,-0.002052,0.002755,0.069977,48.363453,2.463752,0.699767,-391.432373,0.070940,0.000000
50.810001,10.836411,-391.476837,-0.002044,0.002774,0.070454,48.202763,2.455566,0.704535,-391.476837,0.071590,0.000000
51.200001,11.351402,-391.521332,-0.002005,0.002804,0.071234,50.493561,2.572264,0.712340,-391.521332,0.072232,0.000000
51.590004,11.784477,-391.432373,-0.001992,0.002832,0.071928,52.419971,2.670401,0.719281,-391.432373,0.072882,0.000000
51.980003,12.069336,-391.521332,-0.001957,0.002858,0.072604,53.687088,2.734951,0.726041,-391.521332,0.073532,0.000000
52.370003,12.306541,-391.521332,-0.001932,0.002885,0.073289,54.742229,2.788702,0.732892,-391.521332,0.074182,0.000000
52.760002,12.657318,-391.521332,-0.001906,0.002911,0.073931,56.302563,2.868189,0.739311,-391.521332,0.074833,0.000000
53.150002,12.621567,-391.521332,-0.001880,0.002928,0.074382,56.143532,2.860088,0.743823,-391.521332,0.075484,0.000000
53.540001,13.009949,-391.565826,-0.001871,0.002955,0.075050,57.871143,2.948097,0.750499,-391.565826,0.076134,0.000000
53.930004,13.577820,-391.610291,-0.001837,0.002982,0.075735,60.397160,3.076778,0.757350,-391.610291,0.076784,0.000000
54.320004,13.761024,-391.610291,-0.001828,0.003006,0.076342,61.212093,3.118293,0.763421,-391.610291,0.077434,0.000000
54.710003,13.836250,-391.699249,-0.001811,0.003026,0.076871,61.546715,3.135339,0.768712,-391.699249,0.078085,0.000000
55.100002,14.438004,-391.654785,-0.001776,0.003056,0.077634,64.223450,3.271698,0.776343,-391.654785,0.078736,0.000000
55.490002,14.885963,-391.743744,-0.001755,0.003080,0.078241,66.216072,3.373208,0.782413,-391.743744,0.079386,0.000000
55.880001,15.643745,-391.743744,-0.001720,0.003118,0.079187,69.586853,3.544924,0.791868,-391.743744,0.080036,0.000000
56.270004,15.761787,-391.788208,-0.001699,0.003140,0.079767,70.111931,3.571672,0.797674,-391.788208,0.080687,0.000000
56.660004,15.954300,-391.788208,-0.001686,0.003162,0.080322,70.968269,3.615296,0.803223,-391.788208,0.081337,0.000000
57.050003,16.459984,-391.832703,-0.001656,0.003186,0.080929,73.217667,3.729886,0.809294,-391.832703,0.081988,0.000000
57.440002,17.089294,-391.788208,-0.001643,0.003212,0.081589,76.016975,3.872490,0.815887,-391.788208,0.082638,0.000000
57.830002,17.778183,-391.877167,-0.001604,0.003241,0.082326,79.081306,4.028594,0.823260,-391.877167,0.083288,0.000000
58.220001,17.997513,-391.832703,-0.001578,0.003264,0.082907,80.056938,4.078295,0.829066,-391.832703,0.083939,0.000000
58.610004,18.478989,-391.788208,-0.001574,0.003289,0.083549,82.198647,4.187398,0.835485,-391.788208,0.084589,0.000000
59.000004,18.688629,-391.921661,-0.001552,0.003310,0.084086,83.131172,4.234904,0.840860,-391.921661,0.085240,0.000000
59.390003,19.343262,-391.966125,-0.001513,0.003337,0.084754,86.043129,4.383246,0.847544,-391.966125,0.085890,0.000000
59.780003,19.842239,-392.010620,-0.001496,0.003360,0.085352,88.262688,4.496316,0.853524,-392.010620,0.086541,0.000000
60.170002,19.987099,-391.921661,-0.001475,0.003387,0.086029,88.907059,4.529141,0.860291,-391.921661,0.087182,0.000000
60.560001,21.687721,-391.966125,-0.001453,0.003419,0.086853,96.471802,4.914508,0.868527,-391.966125,0.087833,0.000000
60.950005,21.699265,-392.055115,-0.001431,0.003438,0.087330,96.523148,4.917124,0.873296,-392.055115,0.088483,0.000000
61.340004,22.935165,-392.010620,-0.001431,0.003472,0.088180,102.020714,5.197183,0.881797,-392.010620,0.089134,0.000000
61.730003,23.098267,-392.055115,-0.001393,0.003493,0.088735,102.746223,5.234142,0.887346,-392.055115,0.089784,0.000000
62.120003,23.906685,-392.055115,-0.001367,0.003520,0.089402,106.342247,5.417332,0.894022,-392.055115,0.090435,0.000000
62.510002,24.661858,-392.055115,-0.001367,0.003547,0.090096,109.701424,5.588457,0.900964,-392.055115,0.091085,0.000000
62.900002,25.247971,-392.099579,-0.001324,0.003569,0.090642,112.308578,5.721272,0.906422,-392.099579,0.091735,0.000000
63.290005,26.051926,-392.144073,-0.001311,0.003592,0.091249,115.884750,5.903450,0.912493,-392.144073,0.092386,0.000000
63.680004,26.594475,-392.188538,-0.001289,0.003614,0.091796,118.298134,6.026394,0.917958,-392.188538,0.093036,0.000000
64.070000,26.957909,-392.188538,-0.001281,0.003635,0.092317,119.914764,6.108749,0.923166,-392.188538,0.093687,0.000000
64.460007,28.461548,-392.144073,-0.001250,0.003670,0.093210,126.603287,6.449479,0.932099,-392.144073,0.094337,0.000000
64.850006,29.723145,-392.233032,-0.001233,0.003697,0.093895,132.215149,6.735361,0.938949,-392.233032,0.094987,0.000000
65.240005,30.145790,-392.233032,-0.001212,0.003720,0.094476,134.095169,6.831133,0.944755,-392.233032,0.095637,0.000000
65.630005,31.211143,-392.233032,-0.001199,0.003745,0.095126,138.834106,7.072546,0.951258,-392.233032,0.096288,0.000000
66.020004,32.186760,-392.277496,-0.001173,0.003772,0.095820,143.173859,7.293624,0.958199,-392.277496,0.096939,0.000000
66.410004,32.835434,-392.277496,-0.001147,0.003794,0.096366,146.059311,7.440616,0.963665,-392.277496,0.097589,0.000000
66.800003,34.365883,-392.366455,-0.001151,0.003826,0.097190,152.867081,7.787420,0.971900,-392.366455,0.098239,0.000000
67.190002,34.688362,-392.321991,-0.001117,0.003846,0.097684,154.301544,7.860495,0.976844,-392.321991,0.098890,0.000000
67.580002,35.579819,-392.366455,-0.001108,0.003868,0.098239,158.266937,8.062502,0.982392,-392.366455,0.099540,0.000000
67.970001,36.738274,-392.410950,-0.001074,0.003894,0.098916,163.419998,8.325012,0.989160,-392.410950,0.100191,0.000000
68.360001,37.812195,-392.366455,-0.001087,0.003919,0.099549,168.197037,8.568365,0.995488,-392.366455,0.100841,0.000000
68.750000,38.276917,-392.410950,-0.001061,0.003943,0.100156,170.264221,8.673673,1.001559,-392.410950,0.101491,0.000000
69.140007,40.422523,-392.455444,-0.001052,0.003970,0.100833,179.808365,9.159875,1.008326,-392.455444,0.102133,0.000000
69.530006,42.087776,-392.455444,-0.001022,0.004004,0.101691,187.215775,9.537227,1.016910,-392.455444,0.102783,0.000000
69.920006,43.310646,-392.455444,-0.001009,0.004028,0.102316,192.655380,9.814333,1.023156,-392.455444,0.103434,0.000000
70.310005,44.025970,-392.455444,-0.001005,0.004048,0.102827,195.837296,9.976427,1.028273,-392.455444,0.104085,0.000000
70.700005,44.875351,-392.633362,-0.000983,0.004066,0.103287,199.615524,10.168900,1.032868,-392.633362,0.104735,0.000000
71.090004,47.589951,-392.499908,-0.000974,0.004110,0.104406,211.690674,10.784038,1.044056,-392.499908,0.105385,0.000000
71.480003,49.069016,-392.633362,-0.000949,0.004134,0.105013,218.269882,11.119198,1.050127,-392.633362,0.106036,0.000000
71.870003,50.264702,-392.588867,-0.000936,0.004160,0.105655,223.588562,11.390143,1.056546,-392.588867,0.106686,0.000000
72.260002,52.119484,-392.544403,-0.000923,0.004190,0.106435,231.839050,11.810444,1.064350,-392.544403,0.107337,0.000000
72.650002,52.982277,-392.633362,-0.000901,0.004209,0.106912,235.676941,12.005956,1.069119,-392.633362,0.107987,0.000000
73.040001,54.747322,-392.588867,-0.000892,0.004237,0.107632,243.528244,12.405920,1.076318,-392.588867,0.108638,0.000000
73.430000,56.369377,-392.677826,-0.000880,0.004266,0.108360,250.743515,12.773483,1.083600,-392.677826,0.109288,0.000000
73.820000,57.676399,-392.722321,-0.000884,0.004287,0.108889,256.557434,13.069658,1.088892,-392.722321,0.109938,0.000000
74.210007,59.168869,-392.677826,-0.000862,0.004314,0.109565,263.196289,13.407858,1.095651,-392.677826,0.110589,0.000000
74.600006,60.536591,-392.722321,-0.000854,0.004335,0.110112,269.280212,13.717787,1.101117,-392.722321,0.111239,0.000000
74.990005,62.061462,-392.677826,-0.000819,0.004357,0.110658,276.063171,14.063329,1.106582,-392.677826,0.111890,0.000000
75.380005,64.300156,-392.722321,-0.000836,0.004386,0.111413,286.021362,14.570623,1.114129,-392.722321,0.112540,0.000000
75.770004,65.848114,-392.766785,-0.000815,0.004411,0.112028,292.907043,14.921396,1.120283,-392.766785,0.113190,0.000000
76.160004,65.705490,-392.766785,-0.000815,0.004408,0.111959,292.272614,14.889077,1.119587,-392.766785,0.019651,0.000000
76.550003,64.782379,-392.811279,-0.000798,0.004408,0.111959,288.166412,14.679896,1.119587,-392.811279,294.500519,0.000000
76.940002,66.812927,-392.766785,-0.000767,0.004375,0.111135,297.198730,15.140026,1.111351,-392.766785,294.500519,0.000000
77.330002,66.072281,-392.855774,-0.000772,0.004361,0.110771,293.904175,14.972193,1.107710,-392.855774,294.500519,0.000000
77.720001,65.533829,-392.855774,-0.000755,0.004391,0.111542,291.509033,14.850178,1.115424,-392.855774,294.500519,0.000000
78.110001,65.091827,-392.766785,-0.000767,0.004420,0.112262,289.542908,14.750019,1.122623,-392.766785,294.500519,0.000000
78.500000,64.999481,-392.900238,-0.000780,0.004430,0.112514,289.132141,14.729094,1.125143,-392.900238,294.500519,0.000000
78.890007,65.232590,-392.855774,-0.000759,0.004436,0.112679,290.169037,14.781916,1.126786,-392.855774,294.500519,0.000000
79.280006,65.092194,-392.900238,-0.000780,0.004438,0.112731,289.544525,14.750102,1.127308,-392.900238,294.500519,0.000000
79.670006,65.009155,-392.989197,-0.000759,0.004440,0.112774,289.175171,14.731285,1.127740,-392.989197,294.500519,0.000000
80.060005,65.429199,-392.989197,-0.000772,0.004447,0.112956,291.043610,14.826468,1.129564,-392.989197,294.500519,0.000000
80.450005,65.257156,-393.078156,-0.000763,0.004447,0.112956,290.278320,14.787483,1.129564,-393.078156,294.500519,0.000000
80.840004,65.035233,-392.989197,-0.000750,0.004447,0.112956,289.291168,14.737195,1.129564,-392.989197,294.500519,0.000000
81.230003,64.849777,-393.033691,-0.000759,0.004447,0.112956,288.466217,14.695169,1.129564,-393.033691,294.500519,0.000000
81.620003,64.715363,-393.167114,-0.000750,0.004447,0.112956,287.868317,14.664711,1.129564,-393.167114,294.500519,0.000000
82.010002,65.534943,-393.078156,-0.000750,0.004473,0.113607,291.513977,14.850430,1.136067,-393.078156,294.500519,0.000000
82.400002,66.310226,-393.122650,-0.000746,0.004434,0.112618,294.962616,15.026112,1.126180,-393.122650,294.500519,0.000000
82.790001,66.122559,-393.122650,-0.000724,0.004434,0.112618,294.127838,14.983585,1.126180,-393.122650,294.500519,0.000000
83.180000,65.962067,-393.211609,-0.000742,0.004434,0.112618,293.413940,14.947218,1.126180,-393.211609,294.500519,0.000000
83.570007,65.766937,-393.167114,-0.000737,0.004434,0.112618,292.545959,14.903001,1.126180,-393.167114,294.500519,0.000000
83.960007,65.590439,-393.167114,-0.000746,0.004434,0.112618,291.760834,14.863006,1.126180,-393.167114,294.500519,0.000000
84.350006,65.488770,-393.256104,-0.000737,0.004434,0.112618,291.308594,14.839967,1.126180,-393.256104,294.500519,0.000000
84.740005,65.327164,-393.211609,-0.000724,0.004434,0.112626,290.589752,14.803347,1.126264,-393.211609,294.500519,0.000000
85.130005,65.231842,-393.256104,-0.000733,0.004434,0.112626,290.165710,14.781747,1.126264,-393.256104,294.500519,0.000000
85.520004,65.064636,-393.256104,-0.000742,0.004434,0.112626,289.421967,14.743857,1.126264,-393.256104,294.500519,0.000000
85.910004,64.960754,-393.211609,-0.000737,0.004434,0.112635,288.959869,14.720317,1.126354,-393.211609,294.500519,0.000000
86.300003,65.590057,-393.300568,-0.000746,0.004467,0.113451,291.759155,14.862919,1.134507,-393.300568,294.500519,0.000000
86.690002,65.516327,-393.345062,-0.000733,0.004467,0.113451,291.431183,14.846212,1.134507,-393.345062,294.500519,0.000000
87.080002,65.380783,-393.256104,-0.000742,0.004467,0.113459,290.828247,14.815497,1.134590,-393.256104,294.500519,0.000000
87.470001,65.283966,-393.389526,-0.000724,0.004467,0.113459,290.397583,14.793558,1.134590,-393.389526,294.500519,0.000000
87.860001,65.203903,-393.389526,-0.000733,0.004467,0.113459,290.041443,14.775416,1.134590,-393.389526,294.500519,0.000000
88.250008,65.102631,-393.434021,-0.000742,0.004467,0.113459,289.590973,14.752467,1.134590,-393.434021,294.500519,0.000000
88.640007,65.026291,-393.389526,-0.000742,0.004467,0.113459,289.251373,14.735168,1.134590,-393.389526,294.500519,0.000000
89.030006,64.961121,-393.389526,-0.000737,0.004467,0.113459,288.961487,14.720401,1.134590,-393.389526,294.500519,0.000000
89.420006,64.857605,-393.522980,-0.000737,0.004467,0.113459,288.501038,14.696943,1.134590,-393.522980,294.500519,0.000000
89.810005,64.783508,-393.389526,-0.000729,0.004467,0.113468,288.171448,14.680153,1.134681,-393.389526,294.500519,0.000000
90.200005,64.713501,-393.434021,-0.000742,0.004467,0.113468,287.860016,14.664289,1.134681,-393.434021,294.500519,0.000000
90.590004,64.659134,-393.567444,-0.000729,0.004467,0.113468,287.618195,14.651969,1.134681,-393.567444,294.500519,0.000000
90.980003,64.579819,-393.478485,-0.000742,0.004467,0.113468,287.265381,14.633996,1.134681,-393.478485,294.500519,0.000000
91.370003,64.502365,-393.611938,-0.000737,0.004467,0.113468,286.920837,14.616445,1.134681,-393.611938,294.500519,0.000000
91.760002,65.597885,-393.522980,-0.000729,0.004494,0.114153,291.793976,14.864693,1.141532,-393.522980,294.500519,0.000000
92.150002,66.377258,-393.611938,-0.000724,0.004469,0.113511,295.260803,15.041302,1.135113,-393.611938,294.500519,0.000000
92.540001,66.300171,-393.567444,-0.000720,0.004469,0.113511,294.917877,15.023833,1.135113,-393.567444,294.500519,0.000000
92.930008,66.218994,-393.611938,-0.000711,0.004469,0.113511,294.556793,15.005439,1.135113,-393.611938,294.500519,0.000000
93.320007,66.140793,-393.656403,-0.000720,0.004469,0.113511,294.208954,14.987719,1.135113,-393.656403,294.500519,0.000000
93.710007,66.073776,-393.700897,-0.000716,0.004469,0.113511,293.910828,14.972531,1.135113,-393.700897,294.500519,0.000000
94.100006,66.026855,-393.700897,-0.000724,0.004469,0.113511,293.702118,14.961899,1.135113,-393.700897,294.500519,0.000000
94.490005,65.890945,-393.700897,-0.000720,0.004469,0.113511,293.097565,14.931102,1.135113,-393.700897,294.500519,0.000000
94.880005,65.895401,-393.700897,-0.000716,0.004469,0.113511,293.117371,14.932111,1.135113,-393.700897,294.500519,0.000000
95.270004,65.858170,-393.789856,-0.000724,0.004469,0.113511,292.951782,14.923675,1.135113,-393.789856,294.500519,0.000000
95.660004,65.776245,-393.745392,-0.000703,0.004469,0.113511,292.587341,14.905110,1.135113,-393.745392,294.500519,0.000000
96.050003,65.746826,-393.789856,-0.000707,0.004469,0.113511,292.456482,14.898444,1.135113,-393.789856,294.500519,0.000000
96.440002,65.656342,-393.834351,-0.000724,0.004469,0.113511,292.053986,14.877939,1.135113,-393.834351,294.500519,0.000000
96.830002,65.592300,-393.834351,-0.000716,0.004469,0.113511,291.769135,14.863427,1.135113,-393.834351,294.500519,0.000000
97.220001,65.565109,-393.923309,-0.000729,0.004469,0.113511,291.648163,14.857265,1.135113,-393.923309,294.500519,0.000000
97.610008,65.519318,-393.878815,-0.000724,0.004469,0.113520,291.444489,14.846889,1.135196,-393.878815,294.500519,0.000000
98.000008,65.471268,-393.923309,-0.000720,0.004469,0.113520,291.230743,14.836001,1.135196,-393.923309,294.500519,0.000000
98.390007,65.400894,-393.923309,-0.000703,0.004469,0.113520,290.917694,14.820054,1.135196,-393.923309,294.500519,0.000000
98.780006,65.344666,-393.923309,-0.000724,0.004469,0.113520,290.667603,14.807313,1.135196,-393.923309,294.500519,0.000000
99.170006,65.311905,-394.012268,-0.000724,0.004469,0.113520,290.521851,14.799890,1.135196,-394.012268,294.500519,0.000000
99.560005,65.282486,-393.967773,-0.000716,0.004469,0.113520,290.390991,14.793223,1.135196,-393.967773,294.500519,0.000000
99.950005,65.240036,-394.012268,-0.000724,0.004469,0.113520,290.202179,14.783604,1.135196,-394.012268,294.500519,0.000000
100.340004,65.194977,-394.056732,-0.000729,0.004469,0.113520,290.001740,14.773393,1.135196,-394.056732,294.500519,0.000000
100.730003,65.136887,-394.056732,-0.000711,0.004469,0.113520,289.743347,14.760229,1.135196,-394.056732,294.500519,0.000000
101.120003,65.100388,-394.012268,-0.000720,0.004470,0.113529,289.580994,14.751959,1.135287,-394.012268,294.500519,0.000000
101.510002,65.039688,-394.056732,-0.000716,0.004470,0.113529,289.310974,14.738203,1.135287,-394.056732,294.500519,0.000000
101.900002,65.038208,-394.101227,-0.000720,0.004476,0.113694,289.304413,14.737868,1.136937,-394.101227,294.500519,0.000000
102.290009,65.473877,-394.145721,-0.000729,0.004490,0.114049,291.242340,14.836593,1.140487,-394.145721,294.500519,0.000000
102.680008,65.496216,-394.101227,-0.000724,0.004490,0.114049,291.341705,14.841655,1.140487,-394.101227,294.500519,0.000000
103.070007,65.505905,-394.145721,-0.000720,0.004490,0.114049,291.384827,14.843851,1.140487,-394.145721,294.500519,0.000000
103.460007,65.474991,-394.234680,-0.000703,0.004490,0.114049,291.247314,14.836845,1.140487,-394.234680,294.500519,0.000000
103.850006,65.447067,-394.190186,-0.000711,0.004490,0.114049,291.123108,14.830518,1.140487,-394.190186,294.500519,0.000000
104.240005,65.423233,-394.234680,-0.000720,0.004490,0.114049,291.017090,14.825116,1.140487,-394.234680,294.500519,0.000000
104.630005,65.384506,-394.145721,-0.000711,0.004490,0.114049,290.844818,14.816340,1.140487,-394.145721,294.500519,0.000000
105.020004,65.353973,-394.279144,-0.000716,0.004490,0.114049,290.708984,14.809422,1.140487,-394.279144,294.500519,0.000000
105.410004,65.330139,-394.279144,-0.000716,0.004490,0.114049,290.602966,14.804021,1.140487,-394.279144,294.500519,0.000000
105.800003,65.307800,-394.279144,-0.000711,0.004490,0.114049,290.503601,14.798959,1.140487,-394.279144,294.500519,0.000000
106.190002,65.268707,-394.323639,-0.000716,0.004490,0.114049,290.329712,14.790100,1.140487,-394.323639,294.500519,0.000000
106.580002,65.248962,-394.323639,-0.000724,0.004490,0.114049,290.241882,14.785626,1.140487,-394.323639,294.500519,0.000000
106.970009,65.224396,-394.412598,-0.000724,0.004490,0.114049,290.132599,14.780060,1.140487,-394.412598,294.500519,0.000000
107.360008,65.212097,-394.412598,-0.000711,0.004490,0.114049,290.077881,14.777272,1.140487,-394.412598,294.500519,0.000000
107.750008,65.167419,-394.412598,-0.000737,0.004490,0.114049,289.879150,14.767148,1.140487,-394.412598,294.500519,0.000000
108.140007,65.344299,-394.501556,-0.000724,0.004499,0.114266,290.665955,14.807230,1.142660,-394.501556,294.500519,0.000000
108.530006,65.737518,-394.368103,-0.000716,0.004497,0.114231,292.415100,14.896335,1.142312,-394.368103,294.500519,0.000000
108.920006,65.690598,-394.501556,-0.000716,0.004497,0.114231,292.206360,14.885702,1.142312,-394.501556,294.500519,0.000000
109.310005,65.677567,-394.457062,-0.000724,0.004497,0.114231,292.148407,14.882749,1.142312,-394.457062,294.500519,0.000000
109.700005,65.669754,-394.457062,-0.000720,0.004497,0.114231,292.113647,14.880979,1.142312,-394.457062,294.500519,0.000000
110.090004,65.642563,-394.501556,-0.000716,0.004497,0.114231,291.992706,14.874817,1.142312,-394.501556,294.500519,0.000000
110.480003,65.627670,-394.546051,-0.000716,0.004497,0.114231,291.926453,14.871443,1.142312,-394.546051,294.500519,0.000000
110.870003,65.588943,-394.590515,-0.000716,0.004497,0.114231,291.754181,14.862667,1.142312,-394.590515,294.500519,0.000000
111.260002,65.578522,-394.590515,-0.000716,0.004497,0.114231,291.707825,14.860305,1.142312,-394.590515,294.500519,0.000000
111.650002,65.559158,-394.590515,-0.000711,0.004497,0.114231,291.621704,14.855918,1.142312,-394.590515,294.500519,0.000000
112.040009,65.546494,-394.679474,-0.000703,0.004497,0.114231,291.565369,14.853048,1.142312,-394.679474,294.500519,0.000000
112.430008,65.526764,-394.590515,-0.000703,0.004497,0.114231,291.477600,14.848577,1.142312,-394.590515,294.500519,0.000000
112.820007,65.499207,-394.635010,-0.000716,0.004497,0.114231,291.355011,14.842333,1.142312,-394.635010,294.500519,0.000000
113.210007,65.472763,-394.723969,-0.000707,0.004497,0.114231,291.237396,14.836340,1.142312,-394.723969,294.500519,0.000000
113.600006,65.447815,-394.679474,-0.000729,0.004497,0.114231,291.126434,14.830687,1.142312,-394.679474,294.500519,0.000000
113.990005,65.428452,-394.768433,-0.000716,0.004497,0.114231,291.040283,14.826300,1.142312,-394.768433,294.500519,0.000000
114.380005,65.392700,-394.723969,-0.000729,0.004497,0.114231,290.881256,14.818198,1.142312,-394.723969,294.500519,0.000000
114.770004,65.362167,-394.768433,-0.000711,0.004497,0.114231,290.745453,14.811279,1.142312,-394.768433,294.500519,0.000000
115.160004,65.341309,-394.768433,-0.000698,0.004497,0.114231,290.652649,14.806552,1.142312,-394.768433,294.500519,0.000000
115.550003,65.320084,-394.812927,-0.000707,0.004497,0.114231,290.558258,14.801743,1.142312,-394.812927,294.500519,0.000000
115.940002,65.292542,-394.857391,-0.000711,0.004497,0.114231,290.435730,14.795502,1.142312,-394.857391,294.500519,0.000000
116.330002,65.294403,-394.768433,-0.000716,0.004497,0.114231,290.444000,14.795923,1.142312,-394.768433,294.500519,0.000000
116.720009,65.286957,-394.901886,-0.000707,0.004497,0.114231,290.410889,14.794236,1.142312,-394.901886,294.500519,0.000000
117.110008,65.240402,-394.857391,-0.000703,0.004497,0.114231,290.203796,14.783687,1.142312,-394.857391,294.500519,0.000000
117.500008,65.237793,-394.901886,-0.000698,0.004497,0.114231,290.192200,14.783095,1.142312,-394.901886,294.500519,0.000000
117.890007,65.208008,-394.946350,-0.000703,0.004497,0.114231,290.059692,14.776345,1.142312,-394.946350,294.500519,0.000000
118.280006,65.194595,-394.901886,-0.000716,0.004497,0.114231,290.000031,14.773306,1.142312,-394.901886,294.500519,0.000000
118.670006,65.151779,-394.990845,-0.000703,0.004497,0.114231,289.809601,14.763604,1.142312,-394.990845,294.500519,0.000000
119.060005,65.130920,-394.990845,-0.000707,0.004497,0.114231,289.716797,14.758878,1.142312,-394.990845,294.500519,0.000000
119.450005,65.104111,-394.990845,-0.000720,0.004497,0.114231,289.597534,14.752803,1.142312,-394.990845,294.500519,0.000000
119.840004,65.085495,-395.035339,-0.000711,0.004497,0.114231,289.514740,14.748584,1.142312,-395.035339,294.500519,0.000000
120.230003,65.058319,-395.035339,-0.000711,0.004497,0.114231,289.393860,14.742426,1.142312,-395.035339,294.500519,0.000000
120.620003,65.047516,-395.124298,-0.000707,0.004497,0.114231,289.345795,14.739977,1.142312,-395.124298,294.500519,0.000000
121.010002,65.020706,-395.124298,-0.000703,0.004497,0.114231,289.226532,14.733903,1.142312,-395.124298,294.500519,0.000000
121.400009,65.007294,-395.079803,-0.000698,0.004498,0.114239,289.166870,14.730864,1.142395,-395.079803,294.500519,0.000000
121.790009,64.996124,-395.124298,-0.000694,0.004498,0.114239,289.117187,14.728333,1.142395,-395.124298,294.500519,0.000000
122.180008,64.993515,-395.124298,-0.000707,0.004498,0.114239,289.105591,14.727740,1.142395,-395.124298,294.500519,0.000000
122.570007,64.964844,-395.124298,-0.000720,0.004498,0.114239,288.978058,14.721244,1.142395,-395.124298,294.500519,0.000000
122.960007,64.945480,-395.168762,-0.000694,0.004498,0.114239,288.891937,14.716857,1.142395,-395.168762,294.500519,0.000000
123.350006,64.918304,-395.213257,-0.000720,0.004498,0.114239,288.771027,14.710697,1.142395,-395.213257,294.500519,0.000000
123.740005,64.897827,-395.213257,-0.000703,0.004498,0.114239,288.679962,14.706058,1.142395,-395.213257,294.500519,0.000000
124.130005,64.889999,-395.213257,-0.000707,0.004498,0.114239,288.645142,14.704284,1.142395,-395.213257,294.500519,0.000000
124.520004,64.864304,-395.302216,-0.000703,0.004498,0.114239,288.530823,14.698461,1.142395,-395.302216,294.500519,0.000000
124.910004,64.835266,-395.257721,-0.000694,0.004498,0.114239,288.401672,14.691882,1.142395,-395.257721,294.500519,0.000000
125.300003,64.814041,-395.302216,-0.000720,0.004498,0.114239,288.307251,14.687072,1.142395,-395.302216,294.500519,0.000000
125.690002,64.789459,-395.346680,-0.000707,0.004498,0.114239,288.197906,14.681501,1.142395,-395.346680,294.500519,0.000000
126.080009,64.784988,-395.302216,-0.000724,0.004498,0.114239,288.178009,14.680489,1.142395,-395.302216,294.500519,0.000000
126.470009,64.770096,-395.435669,-0.000711,0.004498,0.114239,288.111786,14.677114,1.142395,-395.435669,294.500519,0.000000
126.860008,64.753708,-395.391174,-0.000707,0.004498,0.114249,288.038879,14.673400,1.142486,-395.391174,294.500519,0.000000
127.250008,64.738815,-395.435669,-0.000703,0.004498,0.114249,287.972626,14.670026,1.142486,-395.435669,294.500519,0.000000
127.640007,64.723923,-395.435669,-0.000703,0.004498,0.114249,287.906403,14.666650,1.142486,-395.435669,294.500519,0.000000
128.029999,64.696747,-395.480133,-0.000716,0.004498,0.114249,287.785492,14.660492,1.142486,-395.480133,294.500519,0.000000
128.420013,64.688553,-395.569092,-0.000707,0.004498,0.114249,287.749054,14.658635,1.142486,-395.569092,294.500519,0.000000
128.810013,64.672913,-395.435669,-0.000716,0.004498,0.114249,287.679474,14.655091,1.142486,-395.435669,294.500519,0.000000
129.200012,64.647964,-395.569092,-0.000707,0.004498,0.114249,287.568512,14.649438,1.142486,-395.569092,294.500519,0.000000
129.590012,64.630463,-395.480133,-0.000703,0.004498,0.114249,287.490662,14.645472,1.142486,-395.480133,294.500519,0.000000
129.980011,64.606995,-395.524628,-0.000711,0.004498,0.114257,287.386261,14.640154,1.142569,-395.524628,294.500519,0.000000
130.370010,64.607742,-395.658051,-0.000698,0.004498,0.114257,287.389587,14.640324,1.142569,-395.658051,294.500519,0.000000
130.760010,64.593216,-395.569092,-0.000703,0.004498,0.114257,287.324982,14.637032,1.142569,-395.569092,294.500519,0.000000
131.150009,64.552261,-395.702545,-0.000698,0.004498,0.114257,287.142792,14.627751,1.142569,-395.702545,294.500519,0.000000
131.540009,64.546295,-395.613586,-0.000698,0.004498,0.114257,287.116272,14.626399,1.142569,-395.613586,294.500519,0.000000
131.930008,64.537369,-395.747009,-0.000711,0.004498,0.114257,287.076569,14.624376,1.142569,-395.747009,294.500519,0.000000
132.320007,64.519119,-395.702545,-0.000698,0.004498,0.114257,286.995361,14.620241,1.142569,-395.702545,294.500519,0.000000
132.710007,64.490067,-395.702545,-0.000707,0.004498,0.114257,286.866150,14.613658,1.142569,-395.702545,294.500519,0.000000
133.100006,64.474426,-395.747009,-0.000724,0.004498,0.114257,286.796570,14.610113,1.142569,-395.747009,294.500519,0.000000
133.490005,64.480759,-395.658051,-0.000707,0.004498,0.114257,286.824738,14.611548,1.142569,-395.658051,294.500519,0.000000
133.880005,66.668823,-395.791504,-0.000677,0.004326,0.109886,296.557739,15.107371,1.098861,-395.791504,294.500519,0.000000
134.270004,66.605515,-395.791504,-0.000668,0.004326,0.109886,296.276123,15.093025,1.098861,-395.791504,294.500519,0.000000
134.660004,66.581696,-395.747009,-0.000673,0.004326,0.109886,296.170166,15.087627,1.098861,-395.747009,294.500519,0.000000
135.050003,66.597336,-395.835999,-0.000677,0.004326,0.109886,296.239746,15.091172,1.098861,-395.835999,294.500519,0.000000
135.440002,66.580566,-395.835999,-0.000677,0.004326,0.109886,296.165161,15.087372,1.098861,-395.835999,294.500519,0.000000
135.830002,66.476303,-395.880463,-0.000681,0.004326,0.109886,295.701355,15.063745,1.098861,-395.880463,294.500519,0.000000
136.220001,66.498657,-395.835999,-0.000668,0.004327,0.109895,295.800812,15.068810,1.098952,-395.835999,294.500519,0.000000
136.610001,66.477417,-395.924957,-0.000677,0.004327,0.109895,295.706329,15.063998,1.098952,-395.924957,0.109869,0.000000
137.000000,66.482269,-395.969421,-0.000668,0.004326,0.109869,295.727905,15.065098,1.098687,-395.969421,0.109218,0.000000
137.389999,66.433105,-395.924957,-0.000668,0.004302,0.109271,295.509216,15.053957,1.092707,-395.924957,0.108568,0.000000
137.780014,65.851089,-396.013916,-0.000681,0.004278,0.108664,292.920288,14.922071,1.086636,-396.013916,0.107918,0.000000
138.170013,64.786102,-395.969421,-0.000655,0.004247,0.107883,288.182983,14.680740,1.078831,-395.969421,0.107267,0.000000
138.560013,63.709579,-396.013916,-0.000664,0.004226,0.107346,283.394348,14.436797,1.073457,-396.013916,0.106617,0.000000
138.950012,62.096832,-396.102875,-0.000660,0.004198,0.106617,276.220520,14.071343,1.066167,-396.102875,0.105966,0.000000
139.340012,60.870239,-396.058380,-0.000651,0.004180,0.106175,270.764343,13.793393,1.061746,-396.058380,0.105316,0.000000
139.730011,58.992737,-396.102875,-0.000651,0.004153,0.105498,262.412811,13.367945,1.054979,-396.102875,0.104665,0.000000
140.120010,57.099968,-396.058380,-0.000642,0.004129,0.104882,253.993347,12.939037,1.048825,-396.058380,0.104015,0.000000
140.510010,54.850098,-396.102875,-0.000655,0.004105,0.104266,243.985413,12.429210,1.042663,-396.102875,0.103365,0.000000
140.900009,52.491859,-396.147339,-0.000655,0.004080,0.103643,233.495453,11.894826,1.036425,-396.147339,0.102714,0.000000
141.290009,50.821396,-396.147339,-0.000660,0.004065,0.103252,226.064865,11.516293,1.032519,-396.147339,0.102064,0.000000
141.680008,47.754913,-396.236298,-0.000651,0.004037,0.102532,212.424469,10.821418,1.025321,-396.236298,0.101413,0.000000
142.070007,45.543762,-396.147339,-0.000651,0.004013,0.101942,202.588776,10.320364,1.019424,-396.147339,0.100772,0.000000
142.460007,41.645393,-396.191833,-0.000655,0.003978,0.101049,185.247955,9.436980,1.010491,-396.191833,0.100121,0.000000
142.850006,39.243217,-396.280792,-0.000651,0.003954,0.100425,174.562546,8.892640,1.004246,-396.280792,0.099471,0.000000
143.240005,36.410957,-396.147339,-0.000660,0.003931,0.099835,161.964020,8.250840,0.998349,-396.147339,0.098821,0.000000
143.630005,33.590607,-396.280792,-0.000651,0.003905,0.099185,149.418488,7.611741,0.991847,-396.280792,0.098170,0.000000
144.020004,31.321365,-396.280792,-0.000651,0.003887,0.098725,139.324387,7.097523,0.987252,-396.280792,0.097519,0.000000
144.410004,27.614403,-396.325287,-0.000660,0.003851,0.097823,122.834999,6.257513,0.978229,-396.325287,0.096869,0.000000
144.800003,24.998108,-396.325287,-0.000660,0.003829,0.097260,111.197136,5.664652,0.972597,-396.325287,0.096219,0.000000
145.190002,22.478638,-396.369751,-0.000660,0.003807,0.096687,99.989975,5.093732,0.966874,-396.369751,0.095569,0.000000
145.580002,19.834419,-396.369751,-0.000660,0.003782,0.096063,88.227905,4.494544,0.960629,-396.369751,0.094918,0.000000
145.970001,16.411201,-396.369751,-0.000642,0.003750,0.095256,73.000671,3.718831,0.952560,-396.369751,0.094267,0.000000
146.360001,13.466110,-396.369751,-0.000668,0.003725,0.094623,59.900249,3.051464,0.946231,-396.369751,0.093617,0.000000
146.750000,10.552292,-396.458710,-0.000647,0.003699,0.093955,46.938938,2.391183,0.939555,-396.458710,0.092967,0.000000
147.139999,8.097618,-396.503204,-0.000655,0.003678,0.093409,36.020004,1.834946,0.934089,-396.503204,0.092317,0.000000
147.530014,4.522469,-396.503204,-0.000642,0.003646,0.092603,20.116945,1.024806,0.926028,-396.503204,0.091666,0.000000
147.920013,2.351166,-396.458710,-0.000660,0.003625,0.092065,10.458508,0.532782,0.920645,-396.458710,0.091015,0.000000
148.310013,-0.039467,-396.592163,-0.000668,0.003599,0.091406,-0.175557,-0.008943,0.914060,-396.592163,0.090365,0.000000
148.700012,-1.455601,-396.547668,-0.000647,0.003580,0.090920,-6.474835,-0.329844,0.909200,-396.547668,0.089715,0.000000
149.090012,-0.291939,-396.547668,-0.000681,0.003547,0.090087,-1.298609,-0.066154,0.900873,-396.547668,0.089064,0.000000
149.480011,-0.221931,-396.636627,-0.000681,0.003525,0.089524,-0.987200,-0.050290,0.895241,-396.636627,0.088414,0.000000
149.870010,-0.134796,-396.547668,-0.000746,0.003494,0.088752,-0.599603,-0.030545,0.887520,-396.547668,0.087763,0.000000
150.260010,-0.138893,-396.636627,-0.000772,0.003469,0.088119,-0.617827,-0.031474,0.881192,-396.636627,0.087113,0.000000
150.650009,-0.104637,-396.636627,-0.000811,0.003445,0.087512,-0.465449,-0.023711,0.875121,-396.636627,0.086462,0.000000
151.040009,-0.086388,-396.636627,-0.000819,0.003445,0.087503,-0.384271,-0.019576,0.875030,-396.636627,0.085821,0.000000
151.430008,-0.125862,-396.681122,-0.000849,0.003403,0.086436,-0.559863,-0.028521,0.864364,-396.681122,0.085170,0.000000
151.820007,-0.115059,-396.592163,-0.000897,0.003365,0.085474,-0.511808,-0.026073,0.854735,-396.592163,0.084520,0.000000
152.210007,-0.124367,-396.770081,-0.000923,0.003342,0.084876,-0.553211,-0.028182,0.848755,-396.770081,0.083869,0.000000
152.600006,-0.088249,-396.725616,-0.000957,0.003313,0.084138,-0.392552,-0.019998,0.841382,-396.725616,0.083219,0.000000
152.990005,-0.141129,-396.814575,-0.000992,0.003289,0.083540,-0.627771,-0.031980,0.835402,-396.814575,0.082569,0.000000
153.380005,-0.124001,-396.725616,-0.001009,0.003272,0.083097,-0.551582,-0.028099,0.830974,-396.725616,0.081918,0.000000
153.770004,-0.118782,-396.770081,-0.001039,0.003235,0.082178,-0.528369,-0.026916,0.821784,-396.770081,0.081268,0.000000
154.160004,-0.120270,-396.859039,-0.001065,0.003212,0.081597,-0.534987,-0.027254,0.815970,-396.859039,0.080618,0.000000
154.550003,-0.100906,-396.814575,-0.001099,0.003181,0.080808,-0.448854,-0.022866,0.808083,-396.814575,0.079967,0.000000
154.940002,-0.107986,-396.859039,-0.001125,0.003167,0.080444,-0.480348,-0.024470,0.804442,-396.859039,0.079316,0.000000
155.330002,-0.110588,-396.859039,-0.001147,0.003146,0.079898,-0.491920,-0.025060,0.798976,-396.859039,0.078666,0.000000
155.720001,-0.116547,-396.903534,-0.001181,0.003110,0.079004,-0.518425,-0.026410,0.790044,-396.903534,0.078016,0.000000
156.110001,-0.111710,-396.903534,-0.001207,0.003088,0.078432,-0.496909,-0.025314,0.784321,-396.903534,0.077366,0.000000
156.500000,-0.062180,-396.903534,-0.001242,0.003057,0.077660,-0.276589,-0.014090,0.776600,-396.903534,0.076715,0.000000
156.890015,-0.093086,-396.947998,-0.001255,0.003034,0.077070,-0.414068,-0.021094,0.770703,-396.947998,0.076064,0.000000
157.280014,-0.093460,-396.992493,-0.001281,0.003009,0.076437,-0.415731,-0.021178,0.764375,-396.992493,0.075414,0.000000
157.670013,-0.103516,-396.992493,-0.001328,0.002982,0.075752,-0.460460,-0.023457,0.757524,-396.992493,0.074764,0.000000
158.060013,-0.115059,-397.081451,-0.001328,0.002959,0.075154,-0.511808,-0.026073,0.751536,-397.081451,0.074114,0.000000
158.450012,-0.040588,-397.036957,-0.001371,0.002937,0.074599,-0.180546,-0.009197,0.745988,-397.036957,0.073463,0.000000
158.840012,-0.056229,-397.036957,-0.001427,0.002914,0.074018,-0.250117,-0.012742,0.740182,-397.036957,0.072812,0.000000
159.230011,-0.087135,-397.036957,-0.001440,0.002880,0.073151,-0.387597,-0.019745,0.731507,-397.036957,0.072162,0.000000
159.620010,-0.094955,-397.036957,-0.001457,0.002852,0.072448,-0.422383,-0.021517,0.724482,-397.036957,0.071512,0.000000
160.010010,-0.096817,-397.170410,-0.001483,0.002828,0.071824,-0.430664,-0.021939,0.718237,-397.170410,0.070870,0.000000
160.400009,-0.077820,-397.125946,-0.001518,0.002799,0.071086,-0.346160,-0.017634,0.710864,-397.125946,0.070220,0.000000
160.600006,-0.093460,-397.125946,-0.001544,0.002795,0.071000,-0.415731,-0.021178,0.710001,-397.125946,0.070870,0.000000