File: Data/compression 23/AutoNoHeating-12-23-reverse-2-2_09192024_184237.csv
Time (sec),S:Load (lbs),S:HL1 (DIM),S:LVDT (in),S:Position (in),Ch:Position (mm),Ch:Load (N),Ch:Stress (MPa),Ch:Strain (mm/mm),Ch:HL1 (DIM),Set Point (),Cycles ()
0.110000,-0.166817,-378.310486,-0.011270,-0.006705,-0.170314,-0.742038,-0.037801,-1.703142,-378.310486,-0.170072,0.000000
0.480000,-0.060692,-378.310486,-0.011283,-0.006672,-0.169465,-0.269971,-0.013753,-1.694649,-378.310486,-0.168771,0.000000
0.850000,-0.080803,-378.354980,-0.011188,-0.006451,-0.163845,-0.359429,-0.018310,-1.638451,-378.354980,-0.162613,0.000000
1.220000,-0.099792,-378.399445,-0.010938,-0.006203,-0.157549,-0.443899,-0.022613,-1.575493,-378.399445,-0.156456,0.000000
1.590000,-0.114685,-378.399445,-0.010701,-0.005973,-0.151704,-0.510145,-0.025988,-1.517039,-378.399445,-0.150282,0.000000
1.960000,-0.151176,-378.443939,-0.010434,-0.005714,-0.145148,-0.672466,-0.034257,-1.451477,-378.443939,-0.144124,0.000000
2.330000,-0.151550,-378.399445,-0.010188,-0.005476,-0.139086,-0.674129,-0.034342,-1.390858,-378.399445,-0.137950,0.000000
2.700000,-0.093460,-378.399445,-0.009955,-0.005242,-0.133154,-0.415731,-0.021178,-1.331541,-378.399445,-0.131792,0.000000
3.070000,-0.071861,-378.532898,-0.009710,-0.004995,-0.126884,-0.319655,-0.016284,-1.268841,-378.532898,-0.125635,0.000000
3.440000,-0.083038,-378.532898,-0.009442,-0.004748,-0.120588,-0.369373,-0.018817,-1.205875,-378.532898,-0.119460,0.000000
3.810000,-0.113571,-378.577362,-0.009196,-0.004508,-0.114491,-0.505190,-0.025736,-1.144908,-378.577362,-0.113303,0.000000
4.180000,-0.106125,-378.532898,-0.008955,-0.004268,-0.108412,-0.472067,-0.024048,-1.084123,-378.532898,-0.107128,0.000000
4.550000,-0.068138,-378.577362,-0.008701,-0.004026,-0.102254,-0.303093,-0.015440,-1.022542,-378.577362,-0.100971,0.000000
4.920000,-0.079681,-378.577362,-0.008451,-0.003783,-0.096097,-0.354441,-0.018056,-0.960970,-378.577362,-0.094814,0.000000
5.290000,-0.083038,-378.621857,-0.008183,-0.003538,-0.089853,-0.369373,-0.018817,-0.898534,-378.621857,-0.088639,0.000000
5.660000,-0.116180,-378.621857,-0.007946,-0.003295,-0.083687,-0.516796,-0.026327,-0.836871,-378.621857,-0.082482,0.000000
6.030000,-0.131073,-378.621857,-0.007705,-0.003051,-0.077487,-0.583042,-0.029702,-0.774866,-378.621857,-0.076307,0.000000
6.400000,-0.158997,-378.666351,-0.007446,-0.002813,-0.071450,-0.707252,-0.036029,-0.714505,-378.666351,-0.070150,0.000000
6.770000,-0.102028,-378.666351,-0.007192,-0.002565,-0.065163,-0.453843,-0.023120,-0.651630,-378.666351,-0.063993,0.000000
7.140000,-0.066277,-378.755310,-0.006933,-0.002323,-0.059006,-0.294813,-0.015018,-0.590058,-378.755310,-0.057818,0.000000
7.510000,-0.064789,-378.755310,-0.006679,-0.002076,-0.052736,-0.288195,-0.014681,-0.527357,-378.755310,-0.051661,0.000000
7.880001,-0.103142,-378.710815,-0.006437,-0.001838,-0.046674,-0.458798,-0.023372,-0.466738,-378.710815,-0.045486,0.000000
8.250000,-0.107986,-378.755310,-0.006196,-0.001589,-0.040352,-0.480348,-0.024470,-0.403523,-378.755310,-0.039329,0.000000
8.620001,-0.064041,-378.799774,-0.005954,-0.001351,-0.034316,-0.284869,-0.014512,-0.343161,-378.799774,-0.033172,0.000000
8.990001,-0.069260,-378.799774,-0.005713,-0.001112,-0.028246,-0.308082,-0.015694,-0.282459,-378.799774,-0.026997,0.000000
9.360001,-0.060692,-378.844269,-0.005441,-0.000866,-0.022002,-0.269971,-0.013753,-0.220016,-378.844269,-0.020840,0.000000
9.730000,-0.075592,-378.844269,-0.005208,-0.000621,-0.015784,-0.336250,-0.017129,-0.157838,-378.844269,-0.014665,0.000000
10.100000,-0.106499,-378.799774,-0.004954,-0.000389,-0.009878,-0.473730,-0.024133,-0.098778,-378.799774,-0.008508,0.000000
10.470000,-0.130699,-378.844269,-0.004704,-0.000134,-0.003408,-0.581379,-0.029617,-0.034079,-378.844269,-0.002350,0.000000
10.840000,0.170547,-378.888733,-0.004449,0.000084,0.002133,0.758633,0.038647,0.021332,-378.888733,0.003304,0.000000
11.210001,0.135544,-378.977692,-0.004441,-0.000000,-0.000000,0.602929,0.030715,-0.000000,-378.977692,0.000165,0.000000
11.580001,0.110970,-378.933228,-0.004454,-0.000000,-0.000000,0.493617,0.025146,-0.000000,-378.933228,0.000503,0.000000
11.950001,0.109856,-378.933228,-0.004458,-0.000000,-0.000000,0.488662,0.024894,-0.000000,-378.933228,0.001119,0.000000
12.320001,0.192520,-378.977692,-0.004437,0.000035,0.000902,0.856372,0.043626,0.009016,-378.977692,0.001743,0.000000
12.690001,0.315399,-379.022186,-0.004411,0.000055,0.001405,1.402966,0.071470,0.014050,-379.022186,0.002359,0.000000
13.060000,0.411102,-379.022186,-0.004381,0.000074,0.001882,1.828674,0.093157,0.018818,-379.022186,0.002974,0.000000
13.430000,0.591705,-378.977692,-0.004363,0.000106,0.002697,2.632037,0.134082,0.026971,-378.977692,0.003590,0.000000
13.800000,0.669899,-379.022186,-0.004346,0.000125,0.003182,2.979860,0.151801,0.031823,-379.022186,0.004206,0.000000
14.170001,0.786453,-379.066650,-0.004312,0.000148,0.003755,3.498319,0.178213,0.037554,-379.066650,0.004822,0.000000
14.540001,0.928329,-379.111145,-0.004290,0.000173,0.004406,4.129416,0.210362,0.044056,-379.111145,0.005437,0.000000
14.910001,1.048233,-379.111145,-0.004281,0.000195,0.004960,4.662774,0.237533,0.049605,-379.111145,0.006053,0.000000
15.280001,1.216545,-379.155640,-0.004264,0.000219,0.005558,5.411463,0.275673,0.055585,-379.155640,0.006669,0.000000
15.650001,1.337936,-379.111145,-0.004225,0.000245,0.006218,5.951438,0.303181,0.062178,-379.111145,0.007293,0.000000
16.020000,1.473480,-379.155640,-0.004212,0.000269,0.006825,6.554368,0.333895,0.068249,-379.155640,0.007909,0.000000
16.390001,1.584076,-379.244598,-0.004174,0.000289,0.007345,7.046322,0.358957,0.073450,-379.244598,0.008525,0.000000
16.760000,1.753502,-379.244598,-0.004152,0.000317,0.008057,7.799966,0.397349,0.080565,-379.244598,0.009141,0.000000
17.130001,1.937454,-379.244598,-0.004126,0.000347,0.008802,8.618227,0.439033,0.088022,-379.244598,0.009756,0.000000
17.500000,2.061081,-379.244598,-0.004100,0.000374,0.009496,9.168146,0.467048,0.094963,-379.244598,0.010372,0.000000
17.870001,2.091248,-379.244598,-0.004083,0.000395,0.010042,9.302334,0.473883,0.100421,-379.244598,0.010988,0.000000
18.240002,2.161255,-379.289062,-0.004061,0.000417,0.010580,9.613742,0.489747,0.105803,-379.289062,0.011604,0.000000
18.610001,2.333664,-379.289062,-0.004027,0.000446,0.011317,10.380655,0.528816,0.113168,-379.289062,0.012227,0.000000
18.980001,2.344460,-379.289062,-0.004014,0.000459,0.011655,10.428677,0.531262,0.116552,-379.289062,0.012844,0.000000
19.350000,2.557457,-379.333557,-0.003975,0.000496,0.012592,11.376137,0.579528,0.125923,-379.333557,0.013459,0.000000
19.720001,2.569374,-379.333557,-0.003967,0.000516,0.013112,11.429147,0.582228,0.131124,-379.333557,0.014075,0.000000
20.090000,2.617783,-379.378021,-0.003919,0.000540,0.013710,11.644479,0.593198,0.137104,-379.378021,0.014691,0.000000
20.460001,2.713112,-379.511475,-0.003911,0.000567,0.014396,12.068524,0.614800,0.143962,-379.511475,0.015306,0.000000
20.830002,2.653526,-379.422516,-0.003889,0.000579,0.014708,11.803474,0.601298,0.147081,-379.422516,0.015922,0.000000
21.200001,2.895943,-379.511475,-0.003880,0.000615,0.015627,12.881797,0.656230,0.156271,-379.511475,0.016538,0.000000
21.570002,2.911957,-379.511475,-0.003833,0.000637,0.016183,12.953031,0.659859,0.161827,-379.511475,0.017154,0.000000
21.940001,2.986427,-379.511475,-0.003807,0.000664,0.016868,13.284292,0.676734,0.168678,-379.511475,0.017778,0.000000
22.310001,3.081383,-379.555969,-0.003773,0.000690,0.017535,13.706675,0.698251,0.175354,-379.555969,0.018394,0.000000
22.680000,3.034096,-379.466980,-0.003755,0.000709,0.018021,13.496332,0.687536,0.180206,-379.466980,0.019009,0.000000
23.050001,3.160698,-379.511475,-0.003729,0.000733,0.018628,14.059486,0.716224,0.186277,-379.511475,0.019625,0.000000
23.420002,3.244858,-379.600433,-0.003717,0.000761,0.019339,14.433848,0.735295,0.193393,-379.600433,0.020241,0.000000
23.790001,3.268318,-379.644928,-0.003699,0.000786,0.019955,14.538205,0.740611,0.199547,-379.644928,0.020857,0.000000
24.160002,3.285446,-379.689392,-0.003660,0.000807,0.020510,14.614394,0.744493,0.205096,-379.689392,0.021472,0.000000
24.530001,3.370346,-379.644928,-0.003639,0.000832,0.021143,14.992048,0.763731,0.211432,-379.644928,0.022088,0.000000
24.900002,3.404236,-379.689392,-0.003630,0.000850,0.021603,15.142797,0.771411,0.216027,-379.689392,0.022704,0.000000
25.270000,3.557648,-379.644928,-0.003574,0.000882,0.022409,15.825208,0.806174,0.224088,-379.644928,0.023329,0.000000
25.640001,3.547226,-379.733887,-0.003561,0.000905,0.022999,15.778849,0.803813,0.229985,-379.733887,0.023944,0.000000
26.010002,3.532326,-379.733887,-0.003540,0.000922,0.023415,15.712569,0.800436,0.234149,-379.733887,0.024559,0.000000
26.380001,3.696175,-379.778351,-0.003505,0.000952,0.024187,16.441406,0.837565,0.241870,-379.778351,0.025176,0.000000
26.750002,3.715904,-379.733887,-0.003492,0.000974,0.024734,16.529167,0.842036,0.247335,-379.733887,0.025791,0.000000
27.120001,3.869324,-379.822845,-0.003454,0.001005,0.025522,17.211611,0.876801,0.255223,-379.822845,0.026407,0.000000
27.490002,3.864487,-379.867310,-0.003436,0.001028,0.026104,17.190096,0.875705,0.261037,-379.867310,0.027023,0.000000
27.860001,3.816078,-379.822845,-0.003415,0.001049,0.026632,16.974764,0.864736,0.266320,-379.822845,0.027638,0.000000
28.230001,4.023117,-379.822845,-0.003393,0.001078,0.027387,17.895718,0.911651,0.273867,-379.822845,0.028254,0.000000
28.600002,4.047318,-379.822845,-0.003372,0.001100,0.027942,18.003366,0.917135,0.279416,-379.822845,0.028879,0.000000
28.970001,4.128128,-379.822845,-0.003337,0.001127,0.028627,18.362831,0.935447,0.286267,-379.822845,0.029494,0.000000
29.340002,4.169456,-379.911804,-0.003316,0.001150,0.029217,18.546669,0.944812,0.292171,-379.911804,0.030110,0.000000
29.710001,4.176529,-380.000763,-0.003285,0.001173,0.029798,18.578129,0.946415,0.297977,-380.000763,0.030726,0.000000
30.080002,4.334793,-379.911804,-0.003251,0.001201,0.030509,19.282124,0.982278,0.305093,-379.911804,0.031341,0.000000
30.450001,4.321754,-379.956299,-0.003229,0.001219,0.030969,19.224123,0.979324,0.309688,-379.956299,0.031957,0.000000
30.820002,4.393257,-380.000763,-0.003216,0.001244,0.031602,19.542183,0.995526,0.316016,-380.000763,0.032573,0.000000
31.190001,4.473686,-380.000763,-0.003186,0.001263,0.032088,19.899950,1.013752,0.320876,-380.000763,0.033189,0.000000
31.560001,4.528053,-380.045258,-0.003169,0.001288,0.032711,20.141787,1.026072,0.327113,-380.045258,0.033804,0.000000
31.930002,4.521721,-380.000763,-0.003143,0.001306,0.033162,20.113619,1.024637,0.331625,-380.000763,0.034429,0.000000
32.300003,4.844566,-380.045258,-0.003122,0.001342,0.034091,21.549707,1.097794,0.340905,-380.045258,0.035044,0.000000
32.670002,4.866165,-380.089722,-0.003091,0.001363,0.034628,21.645784,1.102689,0.346280,-380.089722,0.035661,0.000000
33.040001,5.068367,-380.134216,-0.003061,0.001396,0.035452,22.545223,1.148508,0.354524,-380.134216,0.036276,0.000000
33.410000,5.028145,-380.089722,-0.003027,0.001418,0.036025,22.366304,1.139394,0.360246,-380.089722,0.036891,0.000000
33.780003,5.085869,-380.089722,-0.003018,0.001439,0.036562,22.623074,1.152474,0.365621,-380.089722,0.037508,0.000000
34.150002,5.240028,-380.134216,-0.002992,0.001464,0.037178,23.308811,1.187407,0.371775,-380.134216,0.038123,0.000000
34.520000,5.308174,-380.134216,-0.002979,0.001486,0.037733,23.611938,1.202849,0.377331,-380.134216,0.038739,0.000000
34.890003,5.479462,-380.223175,-0.002958,0.001512,0.038401,24.373863,1.241664,0.384008,-380.223175,0.039355,0.000000
35.260002,5.473137,-380.223175,-0.002919,0.001538,0.039068,24.345728,1.240231,0.390684,-380.223175,0.039979,0.000000
35.630001,5.577026,-380.178680,-0.002893,0.001558,0.039571,24.807852,1.263772,0.395711,-380.178680,0.040595,0.000000
36.000000,5.733047,-380.223175,-0.002871,0.001587,0.040300,25.501869,1.299127,0.403000,-380.223175,0.041211,0.000000
36.370003,5.627670,-380.312134,-0.002863,0.001603,0.040716,25.033127,1.275248,0.407164,-380.312134,0.041826,0.000000
36.740002,6.022011,-380.401093,-0.002820,0.001634,0.041497,26.787241,1.364607,0.414968,-380.401093,0.042442,0.000000
37.110001,5.840668,-380.267639,-0.002798,0.001650,0.041921,25.980587,1.323514,0.419215,-380.267639,0.043058,0.000000
37.480003,6.004883,-380.312134,-0.002790,0.001671,0.042433,26.711052,1.360726,0.424332,-380.312134,0.043673,0.000000
37.850002,6.504608,-380.356598,-0.002768,0.001707,0.043361,28.933943,1.473965,0.433613,-380.356598,0.044289,0.000000
38.220001,6.359009,-380.401093,-0.002729,0.001725,0.043821,28.286283,1.440972,0.438208,-380.401093,0.044905,0.000000
38.590000,6.661743,-380.401093,-0.002690,0.001758,0.044644,29.632914,1.509573,0.446443,-380.401093,0.045529,0.000000
38.960003,6.714996,-380.445587,-0.002660,0.001782,0.045251,29.869795,1.521640,0.452514,-380.445587,0.046145,0.000000
39.330002,6.747765,-380.401093,-0.002652,0.001804,0.045824,30.015556,1.529065,0.458245,-380.401093,0.046761,0.000000
39.700001,6.815910,-380.356598,-0.002626,0.001827,0.046397,30.318684,1.544507,0.463968,-380.356598,0.047376,0.000000
40.070004,6.891129,-380.490051,-0.002608,0.001847,0.046917,30.653271,1.561552,0.469168,-380.490051,0.047992,0.000000
40.440002,7.233337,-380.490051,-0.002574,0.001875,0.047619,32.175491,1.639098,0.476193,-380.490051,0.048608,0.000000
40.810001,7.356590,-380.490051,-0.002557,0.001903,0.048347,32.723747,1.667027,0.483475,-380.490051,0.049223,0.000000
41.180000,7.404999,-380.490051,-0.002518,0.001926,0.048911,32.939079,1.677997,0.489114,-380.490051,0.049839,0.000000
41.550003,7.541290,-380.490051,-0.002505,0.001950,0.049536,33.545334,1.708881,0.495359,-380.490051,0.050464,0.000000
41.920002,7.539429,-380.579010,-0.002492,0.001969,0.050013,33.537052,1.708459,0.500128,-380.579010,0.051079,0.000000
42.290001,7.785568,-380.623505,-0.002462,0.001994,0.050655,34.631939,1.764235,0.506548,-380.623505,0.051696,0.000000
42.660004,8.295341,-380.667969,-0.002432,0.002025,0.051444,36.899521,1.879751,0.514435,-380.667969,0.052311,0.000000
43.030003,8.141556,-380.579010,-0.002423,0.002045,0.051955,36.215450,1.844903,0.519553,-380.579010,0.052926,0.000000
43.400002,8.346733,-380.623505,-0.002402,0.002070,0.052589,37.128124,1.891397,0.525888,-380.623505,0.053543,0.000000
43.770000,8.602554,-380.623505,-0.002354,0.002098,0.053300,38.266071,1.949367,0.532996,-380.623505,0.054158,0.000000
44.140003,8.524727,-380.712463,-0.002337,0.002114,0.053707,37.919880,1.931731,0.537069,-380.712463,0.054774,0.000000
44.510002,8.911995,-380.667969,-0.002311,0.002144,0.054453,39.642532,2.019487,0.544533,-380.667969,0.055390,0.000000
44.880001,9.186432,-380.667969,-0.002298,0.002169,0.055086,40.863289,2.081675,0.550861,-380.667969,0.056014,0.000000
45.250004,9.184570,-380.756927,-0.002272,0.002191,0.055650,40.855011,2.081254,0.556501,-380.756927,0.056630,0.000000
45.620003,9.390121,-380.801422,-0.002259,0.002215,0.056257,41.769348,2.127832,0.562572,-380.801422,0.057246,0.000000
45.990002,9.477631,-380.801422,-0.002225,0.002234,0.056742,42.158607,2.147662,0.567424,-380.801422,0.057861,0.000000
46.360001,10.065605,-380.801422,-0.002199,0.002266,0.057566,44.774048,2.280899,0.575660,-380.801422,0.058477,0.000000
46.730003,10.294243,-380.756927,-0.002182,0.002293,0.058243,45.791080,2.332709,0.582427,-380.756927,0.059093,0.000000
47.100002,10.130768,-380.890381,-0.002173,0.002309,0.058659,45.063908,2.295665,0.586591,-380.890381,0.059708,0.000000
47.470001,10.274879,-380.845917,-0.002147,0.002329,0.059145,45.704945,2.328321,0.591450,-380.845917,0.060324,0.000000
47.840004,10.799179,-380.934875,-0.002104,0.002359,0.059916,48.037148,2.447129,0.599164,-380.934875,0.060940,0.000000
48.210003,10.917221,-380.845917,-0.002074,0.002381,0.060471,48.562225,2.473878,0.604713,-380.845917,0.061564,0.000000
48.580002,11.341721,-380.890381,-0.002070,0.002411,0.061235,50.450493,2.570071,0.612351,-380.890381,0.062180,0.000000
48.950001,11.537590,-380.979340,-0.002031,0.002435,0.061859,51.321762,2.614455,0.618588,-380.979340,0.062796,0.000000
49.320004,11.748352,-381.023834,-0.002009,0.002460,0.062483,52.259281,2.662215,0.624833,-381.023834,0.063411,0.000000
49.690002,11.979973,-380.979340,-0.001992,0.002483,0.063065,53.289581,2.714700,0.630647,-380.979340,0.064028,0.000000
50.060001,12.449158,-380.979340,-0.001957,0.002511,0.063767,55.376617,2.821019,0.637672,-380.979340,0.064643,0.000000
50.430004,12.578003,-381.023834,-0.001944,0.002533,0.064330,55.949753,2.850216,0.643303,-381.023834,0.065258,0.000000
50.800003,13.051285,-381.068298,-0.001936,0.002560,0.065016,58.055016,2.957464,0.650162,-381.068298,0.065875,0.000000
51.170002,13.259445,-381.068298,-0.001901,0.002583,0.065597,58.980957,3.004633,0.655968,-381.068298,0.066490,0.000000
51.540001,13.593086,-381.068298,-0.001876,0.002606,0.066196,60.465069,3.080237,0.661955,-381.068298,0.067115,0.000000
51.910004,13.489571,-381.112793,-0.001858,0.002623,0.066620,60.004608,3.056780,0.666202,-381.112793,0.067730,0.000000
52.280003,14.102119,-381.157257,-0.001828,0.002651,0.067331,62.729359,3.195586,0.673310,-381.157257,0.068346,0.000000
52.650002,14.364273,-381.112793,-0.001824,0.002669,0.067782,63.895477,3.254991,0.677822,-381.112793,0.068962,0.000000
53.020004,14.835320,-381.201752,-0.001794,0.002698,0.068519,65.990799,3.361731,0.685195,-381.201752,0.069578,0.000000
53.390003,15.563309,-381.201752,-0.001772,0.002724,0.069196,69.229057,3.526696,0.691962,-381.201752,0.070193,0.000000
53.760002,15.950203,-381.201752,-0.001746,0.002747,0.069768,70.950043,3.614368,0.697685,-381.201752,0.070809,0.000000
54.130001,16.484184,-381.246246,-0.001733,0.002774,0.070462,73.325317,3.735369,0.704619,-381.246246,0.071425,0.000000
54.500004,16.970505,-381.290710,-0.001716,0.002803,0.071208,75.488579,3.845572,0.712075,-381.290710,0.072040,0.000000
54.870003,16.940346,-381.246246,-0.001673,0.002823,0.071711,75.354424,3.838737,0.717109,-381.246246,0.072665,0.000000
55.240002,17.292610,-381.335205,-0.001656,0.002846,0.072291,76.921371,3.918561,0.722915,-381.335205,0.073280,0.000000
55.610004,17.848190,-381.335205,-0.001617,0.002868,0.072838,79.392715,4.044458,0.728380,-381.335205,0.073896,0.000000
55.980003,18.334503,-381.290710,-0.001621,0.002893,0.073472,81.555946,4.154658,0.734716,-381.290710,0.074512,0.000000
56.350002,19.314964,-381.335205,-0.001595,0.002922,0.074217,85.917252,4.376833,0.742172,-381.335205,0.075128,0.000000
56.720001,19.413269,-381.379669,-0.001574,0.002941,0.074712,86.354530,4.399109,0.747116,-381.379669,0.075743,0.000000
57.090004,20.362076,-381.335205,-0.001569,0.002969,0.075414,90.575035,4.614112,0.754140,-381.335205,0.076359,0.000000
57.460003,20.649544,-381.379669,-0.001535,0.002990,0.075943,91.853760,4.679254,0.759432,-381.379669,0.076975,0.000000
57.830002,21.094902,-381.468628,-0.001518,0.003014,0.076559,93.834808,4.780173,0.765586,-381.468628,0.077590,0.000000
58.200005,21.809860,-381.468628,-0.001492,0.003039,0.077191,97.015106,4.942185,0.771914,-381.468628,0.078215,0.000000
58.570004,21.898109,-381.557587,-0.001475,0.003056,0.077617,97.407654,4.962183,0.776168,-381.557587,0.078831,0.000000
58.940002,22.848404,-381.513123,-0.001449,0.003084,0.078345,101.634773,5.177523,0.783451,-381.513123,0.079446,0.000000
59.310001,23.751411,-381.513123,-0.001431,0.003109,0.078978,105.651558,5.382147,0.789779,-381.513123,0.080062,0.000000
59.680004,24.022865,-381.513123,-0.001418,0.003128,0.079455,106.859039,5.443659,0.794548,-381.513123,0.080678,0.000000
60.050003,25.346649,-381.513123,-0.001388,0.003162,0.080322,112.747528,5.743633,0.803223,-381.513123,0.081293,0.000000
60.420002,25.795731,-381.602081,-0.001375,0.003187,0.080955,114.745140,5.845396,0.809551,-381.602081,0.081910,0.000000
60.790005,26.401581,-381.557587,-0.001341,0.003210,0.081545,117.440094,5.982684,0.815448,-381.557587,0.082525,0.000000
61.160004,27.056213,-381.557587,-0.001337,0.003234,0.082144,120.352051,6.131025,0.821436,-381.557587,0.083141,0.000000
61.530003,27.497849,-381.646545,-0.001328,0.003254,0.082646,122.316536,6.231102,0.826462,-381.646545,0.083765,0.000000
61.900002,28.997017,-381.646545,-0.001306,0.003287,0.083479,128.985168,6.570818,0.834789,-381.646545,0.084381,0.000000
62.270004,29.555206,-381.735535,-0.001281,0.003308,0.084017,131.468124,6.697306,0.840171,-381.735535,0.084997,0.000000
62.640003,30.447037,-381.691040,-0.001255,0.003332,0.084641,135.435181,6.899397,0.846408,-381.691040,0.085612,0.000000
63.010002,31.192528,-381.735535,-0.001255,0.003358,0.085292,138.751297,7.068328,0.852919,-381.735535,0.086228,0.000000
63.380005,31.673264,-381.735535,-0.001224,0.003375,0.085725,140.889709,7.177264,0.857248,-381.735535,0.086844,0.000000
63.750004,32.326775,-381.735535,-0.001216,0.003393,0.086193,143.796677,7.325352,0.861934,-381.735535,0.087460,0.000000
64.120003,34.285454,-381.779999,-0.001199,0.003430,0.087130,152.509308,7.769195,0.871298,-381.779999,0.088075,0.000000
64.490005,35.056633,-381.779999,-0.001190,0.003454,0.087719,155.939697,7.943946,0.877195,-381.779999,0.088700,0.000000
64.860001,35.837875,-381.824493,-0.001151,0.003475,0.088258,159.414825,8.120978,0.882577,-381.824493,0.089315,0.000000
65.230003,37.104683,-381.824493,-0.001155,0.003502,0.088951,165.049866,8.408042,0.889511,-381.824493,0.089931,0.000000
65.600006,37.656540,-381.824493,-0.001138,0.003522,0.089454,167.504654,8.533094,0.894545,-381.824493,0.090547,0.000000
65.970001,39.236519,-381.913452,-0.001117,0.003551,0.090191,174.532745,8.891122,0.901910,-381.913452,0.091163,0.000000
66.340004,40.118294,-381.824493,-0.001095,0.003575,0.090807,178.455078,9.090935,0.908072,-381.824493,0.091778,0.000000
66.710007,40.924110,-381.868958,-0.001078,0.003594,0.091276,182.039536,9.273536,0.912758,-381.868958,0.092394,0.000000
67.080002,42.317154,-381.913452,-0.001091,0.003622,0.091987,188.236099,9.589204,0.919866,-381.913452,0.093010,0.000000
67.450005,42.906624,-382.002411,-0.001078,0.003640,0.092463,190.858200,9.722780,0.924635,-382.002411,0.093625,0.000000
67.820000,45.285332,-382.002411,-0.001048,0.003674,0.093331,201.439209,10.261803,0.933310,-382.002411,0.094250,0.000000
68.190002,46.240845,-382.002411,-0.001039,0.003695,0.093843,205.689545,10.478326,0.938427,-382.002411,0.094865,0.000000
68.560005,46.979630,-382.002411,-0.001026,0.003714,0.094328,208.975830,10.645736,0.943279,-382.002411,0.095482,0.000000
68.930000,48.691795,-381.957916,-0.000996,0.003742,0.095057,216.591919,11.033718,0.950569,-381.957916,0.096097,0.000000
69.300003,49.704277,-382.091370,-0.001000,0.003763,0.095585,221.095673,11.263150,0.955853,-382.091370,0.096713,0.000000
69.670006,51.605240,-382.091370,-0.000992,0.003794,0.096366,229.551575,11.693915,0.963657,-382.091370,0.097329,0.000000
70.040001,52.896629,-382.046875,-0.000961,0.003815,0.096904,235.295959,11.986547,0.969039,-382.046875,0.097945,0.000000
70.410004,54.270309,-382.091370,-0.000961,0.003840,0.097537,241.406387,12.297828,0.975367,-382.091370,0.098560,0.000000
70.780006,56.161591,-382.046875,-0.000944,0.003870,0.098300,249.819229,12.726398,0.982998,-382.046875,0.099176,0.000000
71.150002,56.857925,-382.135864,-0.000923,0.003885,0.098690,252.916687,12.884190,0.986904,-382.135864,0.099800,0.000000
71.520004,58.988640,-382.180328,-0.000918,0.003918,0.099523,262.394562,13.367018,0.995231,-382.180328,0.100416,0.000000
71.890007,60.068893,-382.135864,-0.000914,0.003938,0.100017,267.199768,13.611806,1.000174,-382.135864,0.101032,0.000000
72.260002,61.741966,-382.180328,-0.000910,0.003964,0.100685,274.641968,13.990930,1.006850,-382.180328,0.101647,0.000000
72.630005,63.727448,-382.269287,-0.000884,0.003992,0.101405,283.473846,14.440845,1.014049,-382.269287,0.102263,0.000000
73.000000,64.853516,-382.224823,-0.000884,0.004011,0.101890,288.482849,14.696017,1.018901,-382.224823,0.102879,0.000000
73.370003,66.131485,-382.358246,-0.000858,0.004031,0.102384,294.167542,14.985608,1.023844,-382.358246,0.103495,0.000000
73.740005,65.502182,-382.313782,-0.000841,0.004025,0.102237,291.368256,14.843006,1.022368,-382.313782,0.017947,0.000000
74.110001,65.746460,-382.269287,-0.000849,0.004038,0.102567,292.454865,14.898361,1.025669,-382.269287,294.500519,0.000000
74.480003,65.110825,-382.313782,-0.000836,0.004039,0.102584,289.627411,14.754324,1.025843,-382.313782,294.500519,0.000000
74.850006,66.041748,-382.358246,-0.000841,0.004048,0.102810,293.768372,14.965274,1.028099,-382.358246,294.500519,0.000000
75.220001,65.520050,-382.402740,-0.000832,0.004048,0.102810,291.447723,14.847055,1.028099,-382.402740,294.500519,0.000000
75.590004,65.027039,-382.358246,-0.000819,0.004048,0.102827,289.254700,14.735337,1.028265,-382.358246,294.500519,0.000000
75.960007,65.980682,-382.402740,-0.000823,0.004058,0.103079,293.496735,14.951436,1.030786,-382.402740,294.500519,0.000000
76.330002,65.579269,-382.358246,-0.000823,0.004058,0.103079,291.711151,14.860475,1.030786,-382.358246,294.500519,0.000000
76.700005,65.250458,-382.447205,-0.000819,0.004059,0.103087,290.248535,14.785965,1.030869,-382.447205,294.500519,0.000000
77.070007,64.927979,-382.536194,-0.000823,0.004059,0.103087,288.814087,14.712891,1.030869,-382.536194,294.500519,0.000000
77.440002,65.837692,-382.447205,-0.000819,0.004073,0.103460,292.860687,14.919034,1.034601,-382.447205,294.500519,0.000000
77.810005,65.603470,-382.447205,-0.000815,0.004073,0.103460,291.818817,14.865958,1.034601,-382.447205,294.500519,0.000000
78.180000,65.425476,-382.536194,-0.000811,0.004073,0.103460,291.027039,14.825624,1.034601,-382.536194,294.500519,0.000000
78.550003,65.237793,-382.580658,-0.000819,0.004073,0.103460,290.192200,14.783095,1.034601,-382.580658,294.500519,0.000000
78.920006,65.022934,-382.625153,-0.000806,0.004073,0.103460,289.236450,14.734407,1.034601,-382.625153,294.500519,0.000000
79.290001,64.853882,-382.625153,-0.000811,0.004073,0.103460,288.484467,14.696099,1.034601,-382.625153,294.500519,0.000000
79.660004,65.600113,-382.536194,-0.000798,0.004083,0.103711,291.803864,14.865198,1.037114,-382.536194,294.500519,0.000000
80.030006,65.498093,-382.580658,-0.000802,0.004083,0.103711,291.350067,14.842080,1.037114,-382.580658,294.500519,0.000000
80.400002,65.309662,-382.625153,-0.000811,0.004083,0.103711,290.511871,14.799381,1.037114,-382.625153,294.500519,0.000000
80.770004,65.216949,-382.714111,-0.000806,0.004084,0.103737,290.099487,14.778372,1.037372,-382.714111,294.500519,0.000000
81.140007,65.085861,-382.669617,-0.000789,0.004084,0.103737,289.516357,14.748668,1.037372,-382.669617,294.500519,0.000000
81.510002,64.985321,-382.669617,-0.000811,0.004085,0.103755,289.069153,14.725884,1.037546,-382.669617,294.500519,0.000000
81.880005,65.317108,-382.669617,-0.000798,0.004091,0.103902,290.545013,14.801068,1.039022,-382.669617,294.500519,0.000000
82.250008,65.292908,-382.758575,-0.000811,0.004091,0.103902,290.437347,14.795585,1.039022,-382.758575,294.500519,0.000000
82.620003,65.236679,-382.758575,-0.000806,0.004091,0.103902,290.187256,14.782843,1.039022,-382.758575,294.500519,0.000000
82.990005,65.140610,-382.758575,-0.000793,0.004091,0.103902,289.759918,14.761073,1.039022,-382.758575,294.500519,0.000000
83.360001,65.054962,-382.803070,-0.000793,0.004091,0.103920,289.378937,14.741665,1.039196,-382.803070,294.500519,0.000000
83.730003,65.355087,-382.803070,-0.000780,0.004096,0.104041,290.713959,14.809674,1.040407,-382.803070,294.500519,0.000000
84.100006,65.309296,-382.803070,-0.000793,0.004096,0.104041,290.510254,14.799298,1.040407,-382.803070,294.500519,0.000000
84.470001,65.271317,-382.847534,-0.000785,0.004096,0.104041,290.341309,14.790692,1.040407,-382.847534,294.500519,0.000000
84.840004,65.204651,-382.892029,-0.000780,0.004096,0.104041,290.044769,14.775585,1.040407,-382.892029,294.500519,0.000000
85.210007,65.109329,-382.847534,-0.000793,0.004096,0.104041,289.620758,14.753985,1.040407,-382.847534,294.500519,0.000000
85.580002,65.118637,-382.892029,-0.000789,0.004099,0.104102,289.662170,14.756094,1.041020,-382.892029,294.500519,0.000000
85.950005,65.129440,-382.892029,-0.000811,0.004100,0.104128,289.710205,14.758542,1.041278,-382.892029,294.500519,0.000000
86.320007,65.199066,-382.980988,-0.000780,0.004100,0.104145,290.019928,14.774320,1.041452,-382.980988,294.500519,0.000000
86.690002,65.165924,-382.980988,-0.000806,0.004100,0.104145,289.872498,14.766809,1.041452,-382.980988,294.500519,0.000000
87.060005,65.116409,-382.980988,-0.000793,0.004101,0.104163,289.652252,14.755589,1.041626,-382.980988,294.500519,0.000000
87.430008,65.061661,-383.025482,-0.000793,0.004101,0.104163,289.408722,14.743183,1.041626,-383.025482,294.500519,0.000000
87.800003,65.050873,-383.069946,-0.000789,0.004102,0.104197,289.360748,14.740739,1.041974,-383.069946,294.500519,0.000000
88.170006,65.047134,-383.025482,-0.000780,0.004102,0.104197,289.344116,14.739891,1.041974,-383.025482,294.500519,0.000000
88.540001,65.000961,-383.158905,-0.000789,0.004102,0.104197,289.138702,14.729428,1.041974,-383.158905,294.500519,0.000000
88.910004,64.977142,-383.114441,-0.000785,0.004102,0.104197,289.032776,14.724031,1.041974,-383.114441,294.500519,0.000000
89.280006,64.914948,-383.114441,-0.000780,0.004102,0.104197,288.756104,14.709937,1.041974,-383.114441,294.500519,0.000000
89.650002,64.845688,-383.114441,-0.000780,0.004102,0.104197,288.448029,14.694243,1.041974,-383.114441,294.500519,0.000000
90.020004,65.060547,-383.203400,-0.000793,0.004107,0.104310,289.403778,14.742930,1.043102,-383.203400,294.500519,0.000000
90.390007,65.089218,-383.203400,-0.000793,0.004107,0.104310,289.531311,14.749428,1.043102,-383.203400,294.500519,0.000000
90.760002,65.062042,-383.158905,-0.000793,0.004107,0.104310,289.410431,14.743269,1.043102,-383.158905,294.500519,0.000000
91.130005,65.037460,-383.203400,-0.000798,0.004107,0.104310,289.301086,14.737700,1.043102,-383.203400,294.500519,0.000000
91.500008,64.989792,-383.247864,-0.000780,0.004107,0.104310,289.089020,14.726897,1.043102,-383.247864,294.500519,0.000000
91.870003,64.965225,-383.292358,-0.000780,0.004107,0.104319,288.979767,14.721331,1.043185,-383.292358,294.500519,0.000000
92.240005,64.925369,-383.292358,-0.000767,0.004107,0.104319,288.802460,14.712299,1.043185,-383.292358,294.500519,0.000000
92.610001,64.932449,-383.292358,-0.000776,0.004109,0.104371,288.833954,14.713903,1.043707,-383.292358,294.500519,0.000000
92.980003,65.579269,-383.247864,-0.000767,0.004116,0.104544,291.711151,14.860475,1.045441,-383.247864,294.500519,0.000000
93.350006,65.603088,-383.336823,-0.000785,0.004116,0.104544,291.817108,14.865872,1.045441,-383.336823,294.500519,0.000000
93.720001,65.599365,-383.381317,-0.000780,0.004116,0.104544,291.800537,14.865029,1.045441,-383.381317,294.500519,0.000000
94.090004,65.568466,-383.425812,-0.000763,0.004116,0.104544,291.663116,14.858027,1.045441,-383.425812,294.500519,0.000000
94.460007,65.570328,-383.381317,-0.000785,0.004116,0.104544,291.671387,14.858449,1.045441,-383.381317,294.500519,0.000000
94.830002,65.543884,-383.425812,-0.000776,0.004116,0.104544,291.553772,14.852456,1.045441,-383.425812,294.500519,0.000000
95.200005,65.505905,-383.425812,-0.000785,0.004116,0.104544,291.384827,14.843851,1.045441,-383.425812,294.500519,0.000000
95.570007,65.458618,-383.514771,-0.000772,0.004116,0.104544,291.174469,14.833135,1.045441,-383.514771,294.500519,0.000000
95.940002,65.402008,-383.470276,-0.000772,0.004116,0.104544,290.922668,14.820307,1.045441,-383.470276,294.500519,0.000000
96.310005,65.375580,-383.381317,-0.000772,0.004116,0.104544,290.805115,14.814319,1.045441,-383.381317,294.500519,0.000000
96.680008,65.344299,-383.425812,-0.000767,0.004116,0.104544,290.665955,14.807230,1.045441,-383.425812,294.500519,0.000000
97.050003,65.297379,-383.470276,-0.000776,0.004116,0.104544,290.457245,14.796597,1.045441,-383.470276,294.500519,0.000000
97.420006,65.266464,-383.514771,-0.000776,0.004116,0.104544,290.319733,14.789592,1.045441,-383.514771,294.500519,0.000000
97.790001,65.240036,-383.603729,-0.000776,0.004116,0.104544,290.202179,14.783604,1.045441,-383.603729,294.500519,0.000000
98.160004,65.226257,-383.603729,-0.000772,0.004116,0.104544,290.140869,14.780481,1.045441,-383.603729,294.500519,0.000000
98.530006,65.164444,-383.648193,-0.000772,0.004116,0.104544,289.865936,14.766475,1.045441,-383.648193,294.500519,0.000000
98.900002,65.453766,-383.603729,-0.000767,0.004122,0.104708,291.152893,14.832035,1.047084,-383.603729,294.500519,0.000000
99.270004,65.574051,-383.692688,-0.000772,0.004122,0.104708,291.687958,14.859292,1.047084,-383.692688,294.500519,0.000000
99.640007,65.586334,-383.692688,-0.000763,0.004122,0.104708,291.742584,14.862076,1.047084,-383.692688,294.500519,0.000000
100.010002,65.571442,-383.648193,-0.000763,0.004122,0.104708,291.676331,14.858701,1.047084,-383.648193,294.500519,0.000000
100.380005,65.588196,-383.692688,-0.000767,0.004122,0.104708,291.750854,14.862498,1.047084,-383.692688,294.500519,0.000000
100.750008,65.571808,-383.648193,-0.000776,0.004122,0.104708,291.677979,14.858784,1.047084,-383.648193,294.500519,0.000000
101.120003,65.543137,-383.781647,-0.000772,0.004122,0.104708,291.550446,14.852287,1.047084,-383.781647,294.500519,0.000000
101.490005,65.521179,-383.781647,-0.000776,0.004122,0.104708,291.452759,14.847311,1.047084,-383.781647,294.500519,0.000000
101.860008,65.501068,-383.781647,-0.000772,0.004122,0.104708,291.363312,14.842754,1.047084,-383.781647,294.500519,0.000000
102.230003,65.490631,-383.737152,-0.000767,0.004122,0.104708,291.316864,14.840389,1.047084,-383.737152,294.500519,0.000000
102.600006,65.478348,-383.737152,-0.000767,0.004122,0.104708,291.262238,14.837605,1.047084,-383.737152,294.500519,0.000000
102.970001,65.443344,-383.826141,-0.000767,0.004122,0.104708,291.106537,14.829674,1.047084,-383.826141,294.500519,0.000000
103.340004,65.411697,-383.870605,-0.000767,0.004122,0.104708,290.965759,14.822503,1.047084,-383.870605,294.500519,0.000000
103.710007,65.385254,-383.826141,-0.000772,0.004123,0.104717,290.848145,14.816510,1.047174,-383.826141,294.500519,0.000000
104.080002,65.324936,-383.870605,-0.000759,0.004123,0.104717,290.579834,14.802841,1.047174,-383.870605,294.500519,0.000000
104.450005,65.323822,-383.870605,-0.000780,0.004123,0.104717,290.574860,14.802589,1.047174,-383.870605,294.500519,0.000000
104.820007,65.301102,-383.915100,-0.000763,0.004123,0.104717,290.473816,14.797441,1.047174,-383.915100,294.500519,0.000000
105.190002,65.269821,-383.959564,-0.000776,0.004123,0.104717,290.334656,14.790353,1.047174,-383.959564,294.500519,0.000000
105.560005,65.241898,-383.959564,-0.000772,0.004123,0.104717,290.210449,14.784026,1.047174,-383.959564,294.500519,0.000000
105.930008,65.235565,-384.004059,-0.000767,0.004123,0.104717,290.182281,14.782591,1.047174,-384.004059,294.500519,0.000000
106.300003,65.203171,-384.004059,-0.000780,0.004123,0.104717,290.038177,14.775249,1.047174,-384.004059,294.500519,0.000000
106.670006,65.515579,-384.048523,-0.000780,0.004128,0.104839,291.427856,14.846043,1.048386,-384.048523,294.500519,0.000000
107.040009,65.502548,-384.137482,-0.000759,0.004128,0.104839,291.369873,14.843089,1.048386,-384.137482,294.500519,0.000000
107.410004,65.503677,-384.048523,-0.000759,0.004128,0.104839,291.374908,14.843346,1.048386,-384.048523,294.500519,0.000000
107.780006,65.493240,-384.048523,-0.000763,0.004128,0.104839,291.328491,14.840981,1.048386,-384.048523,294.500519,0.000000
108.150002,65.460846,-384.048523,-0.000759,0.004128,0.104839,291.184387,14.833639,1.048386,-384.048523,294.500519,0.000000
108.520004,65.450424,-384.137482,-0.000767,0.004128,0.104839,291.138031,14.831278,1.048386,-384.137482,294.500519,0.000000
108.890007,65.410950,-384.093018,-0.000767,0.004128,0.104839,290.962433,14.822333,1.048386,-384.093018,294.500519,0.000000
109.260002,65.382278,-384.181976,-0.000772,0.004128,0.104839,290.834900,14.815836,1.048386,-384.181976,294.500519,0.000000
109.630005,65.363281,-384.181976,-0.000755,0.004128,0.104839,290.750397,14.811532,1.048386,-384.181976,294.500519,0.000000
110.000008,65.339081,-384.181976,-0.000767,0.004128,0.104839,290.642761,14.806047,1.048386,-384.181976,294.500519,0.000000
110.370003,65.333496,-384.181976,-0.000763,0.004128,0.104839,290.617920,14.804782,1.048386,-384.181976,294.500519,0.000000
110.740005,65.312637,-384.270935,-0.000776,0.004128,0.104839,290.525116,14.800055,1.048386,-384.270935,294.500519,0.000000
111.110008,65.280243,-384.226440,-0.000759,0.004128,0.104839,290.381012,14.792715,1.048386,-384.226440,294.500519,0.000000
111.480003,65.278381,-384.270935,-0.000759,0.004128,0.104839,290.372742,14.792293,1.048386,-384.270935,294.500519,0.000000
111.850006,65.266098,-384.270935,-0.000763,0.004128,0.104839,290.318115,14.789509,1.048386,-384.270935,294.500519,0.000000
112.220009,65.243011,-384.404388,-0.000767,0.004128,0.104839,290.215424,14.784278,1.048386,-384.404388,294.500519,0.000000
112.590004,65.221039,-384.315430,-0.000763,0.004128,0.104839,290.117676,14.779299,1.048386,-384.315430,294.500519,0.000000
112.960007,65.206894,-384.359894,-0.000763,0.004128,0.104839,290.054749,14.776093,1.048386,-384.359894,294.500519,0.000000
113.330002,65.192001,-384.315430,-0.000767,0.004128,0.104839,289.988495,14.772718,1.048386,-384.315430,294.500519,0.000000
113.700005,65.146942,-384.404388,-0.000772,0.004128,0.104839,289.788086,14.762508,1.048386,-384.404388,294.500519,0.000000
114.070007,65.125336,-384.493347,-0.000763,0.004128,0.104839,289.691956,14.757612,1.048386,-384.493347,294.500519,0.000000
114.440002,65.101883,-384.493347,-0.000772,0.004128,0.104839,289.587646,14.752297,1.048386,-384.493347,294.500519,0.000000
114.810005,65.078415,-384.448853,-0.000763,0.004128,0.104839,289.483246,14.746980,1.048386,-384.448853,294.500519,0.000000
115.180008,65.059052,-384.448853,-0.000767,0.004128,0.104839,289.397125,14.742592,1.048386,-384.448853,294.500519,0.000000
115.550003,65.048630,-384.448853,-0.000763,0.004128,0.104839,289.350769,14.740230,1.048386,-384.448853,294.500519,0.000000
115.920006,65.019592,-384.582306,-0.000763,0.004128,0.104839,289.221588,14.733650,1.048386,-384.582306,294.500519,0.000000
116.290009,65.023315,-384.537811,-0.000759,0.004128,0.104839,289.238159,14.734494,1.048386,-384.537811,294.500519,0.000000
116.660004,64.979004,-384.537811,-0.000759,0.004128,0.104839,289.041046,14.724453,1.048386,-384.537811,294.500519,0.000000
117.030006,64.979736,-384.582306,-0.000772,0.004128,0.104839,289.044312,14.724619,1.048386,-384.582306,294.500519,0.000000
117.400009,64.960373,-384.582306,-0.000776,0.004128,0.104839,288.958160,14.720231,1.048386,-384.582306,294.500519,0.000000
117.770004,64.939529,-384.671265,-0.000780,0.004128,0.104839,288.865448,14.715508,1.048386,-384.671265,294.500519,0.000000
118.140007,64.908249,-384.715759,-0.000750,0.004128,0.104839,288.726318,14.708420,1.048386,-384.715759,294.500519,0.000000
118.510002,64.892242,-384.626770,-0.000767,0.004128,0.104839,288.655121,14.704792,1.048386,-384.626770,294.500519,0.000000
118.880005,64.865417,-384.626770,-0.000759,0.004128,0.104839,288.535797,14.698713,1.048386,-384.626770,294.500519,0.000000
119.250008,64.825577,-384.715759,-0.000776,0.004128,0.104839,288.358582,14.689686,1.048386,-384.715759,294.500519,0.000000
119.620003,64.824829,-384.760223,-0.000772,0.004128,0.104839,288.355255,14.689516,1.048386,-384.760223,294.500519,0.000000
119.990005,64.804352,-384.715759,-0.000772,0.004128,0.104839,288.264160,14.684876,1.048386,-384.715759,294.500519,0.000000
120.360008,64.773453,-384.804718,-0.000750,0.004128,0.104839,288.126709,14.677875,1.048386,-384.804718,294.500519,0.000000
120.730003,64.752960,-384.760223,-0.000755,0.004128,0.104839,288.035553,14.673230,1.048386,-384.760223,294.500519,0.000000
121.100006,64.747757,-384.849182,-0.000772,0.004128,0.104839,288.012421,14.672051,1.048386,-384.849182,294.500519,0.000000
121.470009,64.733231,-384.893677,-0.000767,0.004128,0.104839,287.947784,14.668760,1.048386,-384.893677,294.500519,0.000000
121.840004,64.722809,-384.893677,-0.000767,0.004128,0.104839,287.901428,14.666399,1.048386,-384.893677,294.500519,0.000000
122.210007,64.701584,-384.849182,-0.000772,0.004128,0.104839,287.807007,14.661589,1.048386,-384.849182,294.500519,0.000000
122.580009,64.688919,-384.849182,-0.000759,0.004128,0.104839,287.750671,14.658718,1.048386,-384.849182,294.500519,0.000000
122.950005,64.683334,-384.893677,-0.000776,0.004128,0.104839,287.725830,14.657453,1.048386,-384.893677,294.500519,0.000000
123.320007,64.668442,-384.893677,-0.000759,0.004128,0.104839,287.659607,14.654078,1.048386,-384.893677,294.500519,0.000000
123.690002,64.637527,-384.893677,-0.000767,0.004128,0.104839,287.522095,14.647074,1.048386,-384.893677,294.500519,0.000000
124.060005,64.620026,-384.982635,-0.000750,0.004128,0.104839,287.444244,14.643107,1.048386,-384.982635,294.500519,0.000000
124.430008,64.605133,-384.938141,-0.000759,0.004128,0.104839,287.377991,14.639732,1.048386,-384.938141,294.500519,0.000000
124.800003,64.594330,-385.027100,-0.000767,0.004128,0.104839,287.329926,14.637284,1.048386,-385.027100,294.500519,0.000000
125.170006,64.570877,-385.027100,-0.000750,0.004128,0.104839,287.225616,14.631969,1.048386,-385.027100,294.500519,0.000000
125.540009,64.544815,-385.071594,-0.000763,0.004128,0.104839,287.109680,14.626064,1.048386,-385.071594,294.500519,0.000000
125.910004,64.522476,-385.027100,-0.000750,0.004128,0.104839,287.010315,14.621002,1.048386,-385.027100,294.500519,0.000000
126.280006,64.510178,-385.071594,-0.000763,0.004128,0.104839,286.955597,14.618215,1.048386,-385.071594,294.500519,0.000000
126.650009,64.499390,-385.116089,-0.000772,0.004128,0.104839,286.907623,14.615771,1.048386,-385.116089,294.500519,0.000000
127.020004,64.481506,-385.205048,-0.000759,0.004128,0.104839,286.828064,14.611718,1.048386,-385.205048,294.500519,0.000000
127.390007,64.458054,-385.160553,-0.000750,0.004128,0.104839,286.723755,14.606404,1.048386,-385.160553,294.500519,0.000000
127.760010,64.442780,-385.160553,-0.000759,0.004128,0.104839,286.655792,14.602942,1.048386,-385.160553,294.500519,0.000000
128.130005,64.435333,-385.160553,-0.000763,0.004128,0.104839,286.622681,14.601255,1.048386,-385.160553,294.500519,0.000000
128.500000,64.425659,-385.205048,-0.000763,0.004128,0.104839,286.579651,14.599063,1.048386,-385.205048,294.500519,0.000000
128.870010,66.950333,-385.338470,-0.000737,0.003977,0.101014,297.809967,15.171162,1.010143,-385.338470,294.500519,0.000000
129.240005,66.813675,-385.205048,-0.000733,0.003965,0.100711,297.202057,15.140196,1.007108,-385.205048,294.500519,0.000000
129.610001,66.770111,-385.294006,-0.000742,0.003965,0.100711,297.008301,15.130323,1.007108,-385.294006,294.500519,0.000000
129.980011,66.751114,-385.294006,-0.000733,0.003965,0.100711,296.923798,15.126019,1.007108,-385.294006,294.500519,0.000000
130.350006,66.735107,-385.294006,-0.000742,0.003965,0.100711,296.852570,15.122392,1.007108,-385.294006,294.500519,0.000000
130.720001,66.709412,-385.382965,-0.000729,0.003965,0.100711,296.738281,15.116569,1.007108,-385.382965,294.500519,0.000000
131.090012,66.706802,-385.338470,-0.000729,0.003965,0.100711,296.726685,15.115977,1.007108,-385.338470,294.500519,0.000000
131.460007,66.691910,-385.427429,-0.000720,0.003965,0.100711,296.660431,15.112602,1.007108,-385.427429,294.500519,0.000000
131.830002,66.685211,-385.382965,-0.000737,0.003965,0.100711,296.630646,15.111085,1.007108,-385.382965,294.500519,0.000000
132.200012,66.671051,-385.427429,-0.000733,0.003965,0.100711,296.567657,15.107877,1.007108,-385.427429,294.500519,0.000000
132.570007,66.655426,-385.427429,-0.000729,0.003965,0.100711,296.498138,15.104336,1.007108,-385.427429,294.500519,0.000000
132.940002,66.609985,-385.471924,-0.000724,0.003965,0.100711,296.296021,15.094038,1.007108,-385.471924,294.500519,0.000000
133.310013,66.601059,-385.471924,-0.000733,0.003965,0.100711,296.256317,15.092015,1.007108,-385.471924,294.500519,0.000000
133.680008,66.584290,-385.471924,-0.000737,0.003965,0.100711,296.181702,15.088215,1.007108,-385.471924,294.500519,0.000000
134.050003,66.573502,-385.516388,-0.000750,0.003965,0.100711,296.133728,15.085772,1.007108,-385.516388,1681.641113,0.000000
134.420013,66.547806,-385.605377,-0.000729,0.003965,0.100711,296.019409,15.079948,1.007108,-385.605377,0.100304,0.000000
134.790009,66.548172,-385.516388,-0.000724,0.003951,0.100355,296.021057,15.080031,1.003550,-385.516388,0.099687,0.000000
135.160004,66.386932,-385.560883,-0.000729,0.003921,0.099592,295.303833,15.043494,0.995919,-385.560883,0.099072,0.000000
135.530014,65.972488,-385.471924,-0.000742,0.003898,0.099020,293.460297,14.949580,0.990197,-385.471924,0.098456,0.000000
135.900009,65.237793,-385.649841,-0.000716,0.003879,0.098517,290.192200,14.783095,0.985170,-385.649841,0.097840,0.000000
136.270004,64.356018,-385.649841,-0.000711,0.003861,0.098057,286.269867,14.583282,0.980568,-385.649841,0.097225,0.000000
136.639999,63.028885,-385.649841,-0.000703,0.003835,0.097407,280.366486,14.282550,0.974065,-385.649841,0.096609,0.000000
137.010010,61.602325,-385.605377,-0.000711,0.003809,0.096748,274.020844,13.959287,0.967480,-385.605377,0.095984,0.000000
137.380005,60.020111,-385.694336,-0.000698,0.003786,0.096175,266.982788,13.600752,0.961749,-385.694336,0.095369,0.000000
137.750000,58.077446,-385.738800,-0.000711,0.003763,0.095577,258.341370,13.160537,0.955769,-385.738800,0.094753,0.000000
138.120010,56.751427,-385.694336,-0.000707,0.003747,0.095186,252.442947,12.860057,0.951863,-385.694336,0.094137,0.000000
138.490005,54.291908,-385.694336,-0.000686,0.003720,0.094484,241.502472,12.302722,0.944838,-385.694336,0.093522,0.000000
138.860001,52.277000,-385.738800,-0.000690,0.003698,0.093938,232.539719,11.846138,0.939381,-385.738800,0.092906,0.000000
139.230011,49.191147,-385.783295,-0.000694,0.003668,0.093166,218.813156,11.146873,0.931659,-385.783295,0.092290,0.000000
139.600006,47.276039,-385.827759,-0.000711,0.003653,0.092784,210.294327,10.712903,0.927844,-385.827759,0.091675,0.000000
139.970001,44.703690,-385.872253,-0.000703,0.003623,0.092030,198.851944,10.130001,0.920297,-385.872253,0.091059,0.000000
140.340012,41.292389,-385.827759,-0.000694,0.003598,0.091397,183.677719,9.356989,0.913969,-385.827759,0.090434,0.000000
140.710007,39.504623,-385.827759,-0.000698,0.003584,0.091024,175.725342,8.951876,0.910237,-385.827759,0.089819,0.000000
141.080002,36.436279,-385.827759,-0.000686,0.003550,0.090165,162.076660,8.256579,0.901653,-385.827759,0.089202,0.000000
141.450012,33.611458,-385.916718,-0.000694,0.003528,0.089619,149.511230,7.616465,0.896187,-385.916718,0.088587,0.000000
141.820007,30.943779,-385.916718,-0.000694,0.003503,0.088978,137.644806,7.011961,0.889776,-385.916718,0.087972,0.000000
142.190002,29.341461,-385.872253,-0.000694,0.003487,0.088579,130.517334,6.648870,0.885787,-385.872253,0.087355,0.000000
142.560013,25.742485,-385.916718,-0.000698,0.003458,0.087824,114.508293,5.833331,0.878239,-385.916718,0.086740,0.000000
142.930008,22.827179,-386.005707,-0.000698,0.003428,0.087069,101.540359,5.172713,0.870692,-386.005707,0.086124,0.000000
143.300003,19.974060,-386.050171,-0.000690,0.003405,0.086497,88.849060,4.526187,0.864970,-386.050171,0.085508,0.000000
143.670013,17.847816,-386.050171,-0.000711,0.003382,0.085907,79.391052,4.044373,0.859073,-386.050171,0.084884,0.000000
144.040009,15.780029,-386.050171,-0.000694,0.003370,0.085604,70.193077,3.575806,0.856037,-386.050171,0.084268,0.000000
144.410004,11.728249,-385.961212,-0.000686,0.003330,0.084589,52.169857,2.657659,0.845894,-385.961212,0.083652,0.000000
144.780014,9.130203,-386.050171,-0.000703,0.003307,0.084008,40.613171,2.068934,0.840080,-386.050171,0.083037,0.000000
145.150009,7.097794,-386.094666,-0.000711,0.003289,0.083539,31.572563,1.608383,0.835394,-386.094666,0.082421,0.000000
145.520004,3.923317,-386.139130,-0.000707,0.003260,0.082803,17.451786,0.889036,0.828029,-386.139130,0.081805,0.000000
145.889999,1.629135,-386.094666,-0.000690,0.003237,0.082213,7.246755,0.369167,0.822132,-386.094666,0.081190,0.000000
146.260010,-0.696335,-386.094666,-0.000707,0.003216,0.081692,-3.097452,-0.157792,0.816924,-386.094666,0.080574,0.000000
146.630005,-0.469933,-386.139130,-0.000707,0.003185,0.080904,-2.090364,-0.106488,0.809036,-386.139130,0.079958,0.000000
147.000000,-0.183205,-386.183624,-0.000755,0.003159,0.080227,-0.814935,-0.041515,0.802269,-386.183624,0.079334,0.000000
147.370010,-0.188789,-386.228088,-0.000780,0.003133,0.079577,-0.839777,-0.042780,0.795767,-386.228088,0.078718,0.000000
147.740005,-0.083778,-386.228088,-0.000798,0.003118,0.079186,-0.372665,-0.018984,0.791861,-386.228088,0.078102,0.000000
148.110001,-0.070000,-386.183624,-0.000806,0.003118,0.079186,-0.311374,-0.015862,0.791861,-386.183624,0.077487,0.000000
148.480011,-0.110962,-386.228088,-0.000849,0.003074,0.078067,-0.493583,-0.025144,0.780672,-386.228088,0.076870,0.000000
148.850006,-0.099792,-386.317047,-0.000892,0.003037,0.077131,-0.443899,-0.022613,0.771309,-386.317047,0.076255,0.000000
149.220001,-0.130699,-386.272583,-0.000961,0.003016,0.076611,-0.581379,-0.029617,0.766108,-386.272583,0.075640,0.000000
149.590012,-0.102028,-386.317047,-0.000957,0.002989,0.075926,-0.453843,-0.023120,0.759257,-386.317047,0.075023,0.000000
149.960007,-0.122505,-386.317047,-0.000966,0.002975,0.075562,-0.544930,-0.027760,0.755616,-386.317047,0.074399,0.000000
150.330002,-0.119904,-386.361542,-0.001005,0.002952,0.074980,-0.533358,-0.027171,0.749803,-386.361542,0.073783,0.000000
150.700012,-0.109474,-386.494995,-0.001022,0.002915,0.074052,-0.486965,-0.024807,0.740522,-386.494995,0.073168,0.000000
151.070007,-0.112450,-386.361542,-0.001056,0.002894,0.073497,-0.500201,-0.025481,0.734974,-386.361542,0.072552,0.000000
151.440002,-0.111710,-386.406036,-0.001082,0.002866,0.072795,-0.496909,-0.025314,0.727949,-386.406036,0.071936,0.000000
151.800003,-0.086388,-386.406036,-0.001104,0.002854,0.072483,-0.384271,-0.019576,0.724830,-386.406036,0.072387,0.000000