File: Data/compression 23/AutoNoHeating-12-23-reverse-1-4_09192024_182719.csv
Time (sec),S:Load (lbs),S:HL1 (DIM),S:LVDT (in),S:Position (in),Ch:Position (mm),Ch:Load (N),Ch:Stress (MPa),Ch:Strain (mm/mm),Ch:HL1 (DIM),Set Point (),Cycles ()
0.110000,-0.080055,-325.956421,-0.008606,-0.004169,-0.105888,-0.356103,-0.018141,-1.058885,-325.956421,-0.105663,0.000000
0.490000,-0.059952,-325.956421,-0.008610,-0.004120,-0.104639,-0.266679,-0.013585,-1.046395,-325.956421,-0.104085,0.000000
0.870000,-0.044678,-325.956421,-0.008502,-0.003901,-0.099081,-0.198736,-0.010124,-0.990810,-325.956421,-0.097754,0.000000
1.250000,-0.050636,-326.045380,-0.008231,-0.003650,-0.092698,-0.225241,-0.011474,-0.926981,-326.045380,-0.091423,0.000000
1.630000,-0.087875,-326.045380,-0.008011,-0.003405,-0.086480,-0.390889,-0.019913,-0.864796,-326.045380,-0.085092,0.000000
2.010000,-0.069260,-326.045380,-0.007743,-0.003145,-0.079880,-0.308082,-0.015694,-0.798802,-326.045380,-0.078761,0.000000
2.390000,-0.078194,-326.089844,-0.007493,-0.002897,-0.073575,-0.347823,-0.017719,-0.735753,-326.089844,-0.072431,0.000000
2.770000,-0.052498,-326.089844,-0.007209,-0.002648,-0.067262,-0.233522,-0.011896,-0.672621,-326.089844,-0.066100,0.000000
3.150000,-0.061440,-326.089844,-0.006993,-0.002400,-0.060949,-0.273297,-0.013922,-0.609489,-326.089844,-0.059770,0.000000
3.530000,-0.052498,-326.134338,-0.006739,-0.002156,-0.054765,-0.233522,-0.011896,-0.547652,-326.134338,-0.053439,0.000000
3.910000,-0.079315,-326.223297,-0.006502,-0.001911,-0.048539,-0.352812,-0.017973,-0.485390,-326.223297,-0.047108,0.000000
4.290000,-0.095322,-326.134338,-0.006226,-0.001644,-0.041766,-0.424012,-0.021600,-0.417656,-326.134338,-0.040777,0.000000
4.670000,-0.102402,-326.178802,-0.005971,-0.001401,-0.035583,-0.455506,-0.023205,-0.355826,-326.178802,-0.034446,0.000000
5.050000,-0.068512,-326.178802,-0.005704,-0.001153,-0.029295,-0.304756,-0.015525,-0.292951,-326.178802,-0.028116,0.000000
5.430000,-0.067772,-326.312256,-0.005463,-0.000906,-0.023008,-0.301465,-0.015357,-0.230076,-326.312256,-0.021785,0.000000
5.810000,-0.060318,-326.312256,-0.005204,-0.000657,-0.016677,-0.268308,-0.013668,-0.166770,-326.312256,-0.015454,0.000000
6.190000,-0.026810,-326.267761,-0.004954,-0.000403,-0.010234,-0.119255,-0.006075,-0.102336,-326.267761,-0.009123,0.000000
6.570000,0.116180,-326.312256,-0.004760,-0.000000,-0.000000,0.516796,0.026327,-0.000000,-326.312256,0.000199,0.000000
6.950000,0.106133,-326.401215,-0.004764,-0.000000,-0.000009,0.472101,0.024050,-0.000091,-326.401215,0.000199,0.000000
7.330000,0.064423,-326.356750,-0.004769,-0.000000,-0.000009,0.286566,0.014598,-0.000091,-326.356750,0.000780,0.000000
7.710001,0.088631,-326.356750,-0.004773,-0.000000,-0.000000,0.394249,0.020084,-0.000000,-326.356750,0.001413,0.000000
8.090000,0.134056,-326.445709,-0.004738,0.000040,0.001023,0.596311,0.030378,0.010234,-326.445709,0.002047,0.000000
8.470000,0.161987,-326.445709,-0.004725,0.000065,0.001639,0.720556,0.036707,0.016389,-326.445709,0.002680,0.000000
8.850000,0.147835,-326.445709,-0.004695,0.000090,0.002289,0.657602,0.033500,0.022891,-326.445709,0.003313,0.000000
9.230000,0.193634,-326.534668,-0.004687,0.000112,0.002853,0.861327,0.043878,0.028531,-326.534668,0.003945,0.000000
9.610001,0.297531,-326.534668,-0.004639,0.000141,0.003590,1.323485,0.067422,0.035904,-326.534668,0.004579,0.000000
9.990001,0.343330,-326.534668,-0.004626,0.000165,0.004188,1.527210,0.077800,0.041884,-326.534668,0.005212,0.000000
10.370001,0.424881,-326.534668,-0.004575,0.000200,0.005073,1.889965,0.096279,0.050733,-326.534668,0.005845,0.000000
10.750001,0.458397,-326.579132,-0.004553,0.000221,0.005602,2.039051,0.103874,0.056024,-326.579132,0.006478,0.000000
11.130000,0.537712,-326.668091,-0.004531,0.000246,0.006253,2.391863,0.121847,0.062526,-326.668091,0.007111,0.000000
11.510000,0.657982,-326.623627,-0.004527,0.000267,0.006773,2.926850,0.149101,0.067727,-326.623627,0.007744,0.000000
11.890000,0.730972,-326.623627,-0.004506,0.000287,0.007293,3.251527,0.165641,0.072935,-326.623627,0.008377,0.000000
12.270000,0.836723,-326.712585,-0.004462,0.000322,0.008169,3.721931,0.189604,0.081693,-326.712585,0.009010,0.000000
12.650001,0.860931,-326.757080,-0.004449,0.000340,0.008646,3.829614,0.195090,0.086462,-326.757080,0.009643,0.000000
13.030001,1.028122,-326.757080,-0.004411,0.000371,0.009418,4.573315,0.232976,0.094176,-326.757080,0.010277,0.000000
13.410001,1.097755,-326.801544,-0.004398,0.000391,0.009929,4.883060,0.248755,0.099293,-326.801544,0.010910,0.000000
13.790001,1.196060,-326.757080,-0.004372,0.000413,0.010485,5.320342,0.271031,0.104849,-326.757080,0.011542,0.000000
14.170001,1.349480,-326.757080,-0.004350,0.000442,0.011231,6.002785,0.305796,0.112305,-326.757080,0.012176,0.000000
14.550001,1.380760,-326.890503,-0.004320,0.000463,0.011751,6.141928,0.312885,0.117506,-326.890503,0.012809,0.000000
14.930000,1.510719,-326.801544,-0.004294,0.000489,0.012427,6.720015,0.342334,0.124273,-326.801544,0.013442,0.000000
15.310000,1.636581,-326.934998,-0.004273,0.000515,0.013078,7.279878,0.370855,0.130776,-326.934998,0.014075,0.000000
15.690001,1.737862,-326.890503,-0.004264,0.000533,0.013546,7.730395,0.393805,0.135461,-326.890503,0.014708,0.000000
16.070002,1.946396,-326.890503,-0.004225,0.000564,0.014318,8.658001,0.441060,0.143175,-326.890503,0.015350,0.000000
16.450001,2.035019,-326.979462,-0.004204,0.000589,0.014959,9.052217,0.461142,0.149594,-326.979462,0.015983,0.000000
16.830000,2.161995,-327.023956,-0.004174,0.000615,0.015610,9.617034,0.489915,0.156097,-327.023956,0.016616,0.000000
17.210001,2.352654,-327.023956,-0.004135,0.000642,0.016304,10.465125,0.533119,0.163038,-327.023956,0.017249,0.000000
17.590000,2.398827,-327.023956,-0.004126,0.000658,0.016720,10.670514,0.543582,0.167202,-327.023956,0.017882,0.000000
17.970001,2.611450,-327.023956,-0.004087,0.000688,0.017474,11.616311,0.591763,0.174741,-327.023956,0.018515,0.000000
18.350000,2.720932,-327.023956,-0.004070,0.000713,0.018099,12.103310,0.616572,0.180986,-327.023956,0.019149,0.000000
18.730001,2.843063,-327.157410,-0.004044,0.000739,0.018766,12.646578,0.644247,0.187663,-327.157410,0.019781,0.000000
19.110001,3.046379,-327.112915,-0.004036,0.000765,0.019443,13.550971,0.690319,0.194430,-327.112915,0.020414,0.000000
19.490002,3.116013,-327.157410,-0.004001,0.000784,0.019920,13.860716,0.706099,0.199199,-327.157410,0.021047,0.000000
19.870001,3.308159,-327.157410,-0.003980,0.000809,0.020544,14.715425,0.749640,0.205444,-327.157410,0.021681,0.000000
20.250002,3.450409,-327.246368,-0.003949,0.000834,0.021177,15.348186,0.781874,0.211772,-327.246368,0.022313,0.000000
20.630001,3.593399,-327.246368,-0.003923,0.000859,0.021811,15.984238,0.814276,0.218108,-327.246368,0.022946,0.000000
21.010000,3.762825,-327.246368,-0.003902,0.000887,0.022522,16.737881,0.852668,0.225216,-327.246368,0.023580,0.000000
21.390001,3.890923,-327.290833,-0.003880,0.000911,0.023146,17.307688,0.881696,0.231461,-327.290833,0.024213,0.000000
21.770000,4.006729,-327.290833,-0.003846,0.000936,0.023779,17.822821,0.907938,0.237790,-327.290833,0.024846,0.000000
22.150002,4.226059,-327.379791,-0.003820,0.000964,0.024491,18.798449,0.957639,0.244905,-327.379791,0.025479,0.000000
22.530001,4.316544,-327.424286,-0.003794,0.000987,0.025080,19.200945,0.978143,0.250802,-327.424286,0.026112,0.000000
22.910002,4.447990,-327.424286,-0.003786,0.001008,0.025592,19.785650,1.007929,0.255919,-327.424286,0.026745,0.000000
23.290001,4.698601,-327.379791,-0.003755,0.001035,0.026285,20.900419,1.064718,0.262853,-327.379791,0.027378,0.000000
23.670002,4.866913,-327.468750,-0.003708,0.001063,0.026997,21.649109,1.102858,0.269969,-327.468750,0.028011,0.000000
24.050001,4.963730,-327.424286,-0.003686,0.001088,0.027630,22.079773,1.124797,0.276297,-327.424286,0.028644,0.000000
24.430000,5.025169,-327.557709,-0.003669,0.001111,0.028219,22.353069,1.138720,0.282194,-327.557709,0.029278,0.000000
24.810001,5.161087,-327.468750,-0.003648,0.001132,0.028757,22.957663,1.169519,0.287569,-327.468750,0.029911,0.000000
25.190001,5.462334,-327.513245,-0.003613,0.001162,0.029502,24.297674,1.237782,0.295025,-327.513245,0.030543,0.000000
25.570002,5.559151,-327.468750,-0.003579,0.001187,0.030162,24.728338,1.259722,0.301618,-327.468750,0.031177,0.000000
25.950001,5.711449,-327.646698,-0.003557,0.001215,0.030864,25.405792,1.294233,0.308643,-327.646698,0.031810,0.000000
26.330002,5.803429,-327.602203,-0.003548,0.001240,0.031506,25.814939,1.315076,0.315062,-327.602203,0.032443,0.000000
26.710001,5.905830,-327.602203,-0.003518,0.001267,0.032183,26.270445,1.338280,0.321830,-327.602203,0.033076,0.000000
27.090002,6.059624,-327.602203,-0.003479,0.001291,0.032781,26.954552,1.373130,0.327810,-327.602203,0.033717,0.000000
27.470001,6.217880,-327.646698,-0.003449,0.001318,0.033483,27.658512,1.408992,0.334835,-327.646698,0.034351,0.000000
27.850000,6.351936,-327.691162,-0.003432,0.001340,0.034030,28.254824,1.439369,0.340300,-327.691162,0.034984,0.000000
28.230001,6.389915,-327.780121,-0.003406,0.001366,0.034689,28.423763,1.447976,0.346886,-327.780121,0.035617,0.000000
28.610001,6.717232,-327.646698,-0.003380,0.001395,0.035426,29.879740,1.522146,0.354259,-327.646698,0.036250,0.000000
28.990002,6.735474,-327.735657,-0.003346,0.001415,0.035929,29.960882,1.526280,0.359293,-327.735657,0.036883,0.000000
29.370001,6.884056,-327.735657,-0.003320,0.001438,0.036519,30.621811,1.559949,0.365189,-327.735657,0.037516,0.000000
29.750002,6.948845,-327.780121,-0.003298,0.001460,0.037091,30.910006,1.574631,0.370912,-327.780121,0.038149,0.000000
30.130001,7.119019,-327.824615,-0.003285,0.001486,0.037733,31.666977,1.613193,0.377331,-327.824615,0.038782,0.000000
30.510002,6.971191,-327.824615,-0.003264,0.001502,0.038140,31.009409,1.579695,0.381404,-327.824615,0.039415,0.000000
30.890001,7.500702,-327.824615,-0.003234,0.001538,0.039059,33.364788,1.699683,0.390594,-327.824615,0.040048,0.000000
31.270002,7.465698,-327.869080,-0.003203,0.001558,0.039580,33.209084,1.691751,0.395802,-327.869080,0.040682,0.000000
31.650002,7.860413,-327.913574,-0.003165,0.001595,0.040526,34.964863,1.781195,0.405256,-327.913574,0.041314,0.000000
32.030003,7.734924,-327.913574,-0.003134,0.001618,0.041106,34.406662,1.752759,0.411062,-327.913574,0.041947,0.000000
32.410000,7.936752,-327.958038,-0.003117,0.001644,0.041766,35.304436,1.798494,0.417656,-327.958038,0.042581,0.000000
32.790001,8.016441,-328.002533,-0.003087,0.001665,0.042286,35.658913,1.816552,0.422856,-328.002533,0.043214,0.000000
33.170002,8.056656,-328.002533,-0.003074,0.001684,0.042762,35.837795,1.825664,0.427625,-328.002533,0.043846,0.000000
33.550003,8.478180,-328.002533,-0.003031,0.001719,0.043673,37.712830,1.921183,0.436731,-328.002533,0.044480,0.000000
33.930000,8.382111,-328.091492,-0.003005,0.001738,0.044142,37.285492,1.899413,0.441417,-328.091492,0.045113,0.000000
34.310001,8.709419,-328.002533,-0.002997,0.001768,0.044914,38.741432,1.973583,0.449138,-328.002533,0.045746,0.000000
34.690002,8.738098,-328.047028,-0.002958,0.001789,0.045451,38.869003,1.980081,0.454513,-328.047028,0.046379,0.000000
35.070004,8.666229,-328.047028,-0.002940,0.001810,0.045963,38.549313,1.963796,0.459630,-328.047028,0.047012,0.000000
35.450001,9.148453,-328.180450,-0.002910,0.001840,0.046726,40.694351,2.073069,0.467260,-328.180450,0.047645,0.000000
35.830002,9.031151,-328.180450,-0.002880,0.001860,0.047255,40.172565,2.046488,0.472552,-328.180450,0.048279,0.000000
36.210003,9.185318,-328.135986,-0.002863,0.001886,0.047905,40.858334,2.081423,0.479054,-328.135986,0.048911,0.000000
36.590000,9.342827,-328.091492,-0.002815,0.001912,0.048573,41.558968,2.117115,0.485731,-328.091492,0.049544,0.000000
36.970001,9.304474,-328.224945,-0.002802,0.001929,0.048998,41.388367,2.108424,0.489977,-328.224945,0.050178,0.000000
37.350002,9.728981,-328.269409,-0.002768,0.001962,0.049839,43.276669,2.204619,0.498395,-328.269409,0.050811,0.000000
37.730003,9.727859,-328.224945,-0.002755,0.001982,0.050342,43.271679,2.204365,0.503421,-328.224945,0.051444,0.000000
38.110001,9.999321,-328.313904,-0.002716,0.002012,0.051097,44.479202,2.265878,0.510968,-328.313904,0.052085,0.000000
38.490002,10.225349,-328.269409,-0.002699,0.002039,0.051790,45.484627,2.317097,0.517902,-328.269409,0.052718,0.000000
38.870003,10.083481,-328.358368,-0.002669,0.002056,0.052224,44.853561,2.284949,0.522240,-328.358368,0.053352,0.000000
39.250000,10.378769,-328.358368,-0.002652,0.002086,0.052979,46.167068,2.351862,0.529787,-328.358368,0.053985,0.000000
39.630001,10.440208,-328.402863,-0.002626,0.002107,0.053508,46.440365,2.365785,0.535078,-328.402863,0.054618,0.000000
40.010002,10.650230,-328.313904,-0.002583,0.002134,0.054193,47.374592,2.413377,0.541929,-328.313904,0.055251,0.000000
40.390003,10.828598,-328.358368,-0.002557,0.002159,0.054843,48.168011,2.453795,0.548431,-328.358368,0.055884,0.000000
40.770000,10.869186,-328.447357,-0.002544,0.002182,0.055415,48.348557,2.462993,0.554154,-328.447357,0.056517,0.000000
41.150002,11.046432,-328.491821,-0.002514,0.002207,0.056066,49.136986,2.503157,0.560656,-328.491821,0.057150,0.000000
41.530003,11.335022,-328.447357,-0.002488,0.002232,0.056690,50.420696,2.568553,0.566902,-328.447357,0.057783,0.000000
41.910004,11.441521,-328.447357,-0.002462,0.002255,0.057289,50.894424,2.592686,0.572889,-328.447357,0.058416,0.000000
42.290001,11.557701,-328.491821,-0.002427,0.002279,0.057896,51.411221,2.619013,0.578960,-328.491821,0.059049,0.000000
42.670002,11.932678,-328.536316,-0.002397,0.002309,0.058659,53.079205,2.703984,0.586591,-328.536316,0.059682,0.000000
43.050003,11.939751,-328.625275,-0.002371,0.002333,0.059257,53.110664,2.705586,0.592571,-328.625275,0.060315,0.000000
43.430000,12.234673,-328.625275,-0.002358,0.002359,0.059916,54.422543,2.772416,0.599164,-328.625275,0.060948,0.000000
43.810001,12.354950,-328.625275,-0.002341,0.002383,0.060532,54.957561,2.799672,0.605318,-328.625275,0.061582,0.000000
44.190002,12.364632,-328.669739,-0.002294,0.002402,0.061018,55.000629,2.801866,0.610178,-328.669739,0.062215,0.000000
44.570004,12.947395,-328.625275,-0.002272,0.002432,0.061773,57.592892,2.933922,0.617725,-328.625275,0.062847,0.000000
44.950001,13.135811,-328.714233,-0.002251,0.002459,0.062458,58.431004,2.976617,0.624576,-328.714233,0.063481,0.000000
45.330002,13.268005,-328.669739,-0.002229,0.002485,0.063117,59.019035,3.006573,0.631169,-328.669739,0.064114,0.000000
45.710003,13.402435,-328.669739,-0.002203,0.002508,0.063698,59.617008,3.037035,0.636975,-328.669739,0.064747,0.000000
46.090004,13.484352,-328.714233,-0.002156,0.002531,0.064279,59.981396,3.055598,0.642789,-328.714233,0.065380,0.000000
46.470001,14.054085,-328.714233,-0.002121,0.002560,0.065015,62.515690,3.184701,0.650154,-328.714233,0.066013,0.000000
46.850002,14.211227,-328.803192,-0.002113,0.002583,0.065614,63.214695,3.220310,0.656142,-328.803192,0.066646,0.000000
47.230003,14.309532,-328.803192,-0.002087,0.002611,0.066317,63.651978,3.242586,0.663167,-328.803192,0.067280,0.000000
47.610001,14.656212,-328.803192,-0.002052,0.002639,0.067019,65.194084,3.321145,0.670191,-328.803192,0.067912,0.000000
47.990002,14.544128,-328.847656,-0.002026,0.002660,0.067557,64.695511,3.295747,0.675566,-328.847656,0.068545,0.000000
48.370003,15.066566,-328.892151,-0.001992,0.002687,0.068251,67.019432,3.414133,0.682507,-328.892151,0.069179,0.000000
48.750004,15.179024,-328.981110,-0.001970,0.002710,0.068823,67.519669,3.439616,0.688230,-328.981110,0.069820,0.000000
49.130001,15.440796,-328.981110,-0.001944,0.002738,0.069534,68.684090,3.498934,0.695338,-328.981110,0.070454,0.000000
49.510002,15.842590,-328.936646,-0.001914,0.002762,0.070167,70.471359,3.589982,0.701674,-328.936646,0.071086,0.000000
49.890003,16.443596,-328.981110,-0.001893,0.002792,0.070921,73.144768,3.726172,0.709214,-328.981110,0.071719,0.000000
50.270004,16.386253,-328.981110,-0.001854,0.002811,0.071407,72.889694,3.713178,0.714073,-328.981110,0.072353,0.000000
50.650002,16.832359,-329.070068,-0.001841,0.002836,0.072023,74.874077,3.814267,0.720228,-329.070068,0.072986,0.000000
51.030003,16.874809,-329.070068,-0.001824,0.002857,0.072569,75.062897,3.823886,0.725693,-329.070068,0.073618,0.000000
51.410004,17.484009,-329.159027,-0.001798,0.002883,0.073237,77.772758,3.961933,0.732370,-329.159027,0.074252,0.000000
51.790001,17.333199,-329.114563,-0.001759,0.002900,0.073653,77.101921,3.927759,0.736533,-329.114563,0.074885,0.000000
52.170002,18.273064,-329.114563,-0.001746,0.002935,0.074555,81.282646,4.140736,0.745549,-329.114563,0.075518,0.000000
52.550003,18.242531,-329.203522,-0.001712,0.002953,0.074998,81.146828,4.133816,0.749977,-329.203522,0.076151,0.000000
52.930004,19.395767,-329.159027,-0.001686,0.002992,0.075995,86.276680,4.395144,0.759946,-329.159027,0.076784,0.000000
53.310001,19.230431,-329.203522,-0.001660,0.003014,0.076550,85.541229,4.357678,0.765495,-329.203522,0.077417,0.000000
53.690002,19.344749,-329.203522,-0.001625,0.003038,0.077174,86.049744,4.383583,0.771740,-329.203522,0.078050,0.000000
54.070004,19.912247,-329.247986,-0.001595,0.003063,0.077790,88.574097,4.512180,0.777902,-329.247986,0.078683,0.000000
54.450001,20.187431,-329.336975,-0.001578,0.003083,0.078302,89.798180,4.574538,0.783019,-329.336975,0.079316,0.000000
54.830002,21.173103,-329.336975,-0.001569,0.003116,0.079143,94.182671,4.797894,0.791429,-329.336975,0.079949,0.000000
55.210003,21.186882,-329.247986,-0.001522,0.003135,0.079637,94.243958,4.801016,0.796372,-329.247986,0.080583,0.000000
55.590004,21.734268,-329.336975,-0.001505,0.003164,0.080365,96.678856,4.925056,0.803654,-329.336975,0.081216,0.000000
55.970001,22.111107,-329.425934,-0.001475,0.003186,0.080912,98.355118,5.010448,0.809120,-329.425934,0.081848,0.000000
56.350002,22.268250,-329.425934,-0.001462,0.003206,0.081441,99.054123,5.046058,0.814411,-329.425934,0.082482,0.000000
56.730003,23.100502,-329.381439,-0.001423,0.003235,0.082178,102.756165,5.234648,0.821784,-329.381439,0.083115,0.000000
57.110004,23.094170,-329.425934,-0.001410,0.003256,0.082690,102.727997,5.233213,0.826901,-329.425934,0.083748,0.000000
57.490002,24.058617,-329.470398,-0.001380,0.003283,0.083384,107.018074,5.451760,0.833835,-329.470398,0.084381,0.000000
57.870003,24.571373,-329.514893,-0.001354,0.003307,0.084008,109.298927,5.567953,0.840080,-329.514893,0.085014,0.000000
58.250004,24.730377,-329.514893,-0.001350,0.003327,0.084511,110.006210,5.603984,0.845106,-329.514893,0.085647,0.000000
58.630001,25.858665,-329.559357,-0.001311,0.003357,0.085274,115.025085,5.859657,0.852744,-329.559357,0.086280,0.000000
59.010002,26.015808,-329.603851,-0.001298,0.003380,0.085847,115.724091,5.895267,0.858467,-329.603851,0.086913,0.000000
59.390003,26.832794,-329.559357,-0.001263,0.003407,0.086540,119.358231,6.080398,0.865401,-329.559357,0.087546,0.000000
59.770004,27.613281,-329.648315,-0.001224,0.003434,0.087217,122.830009,6.257259,0.872168,-329.648315,0.088188,0.000000
60.150002,27.911179,-329.692810,-0.001207,0.003454,0.087719,124.155121,6.324763,0.877195,-329.692810,0.088821,0.000000
60.530003,28.851425,-329.603851,-0.001194,0.003482,0.088439,128.337555,6.537827,0.884394,-329.603851,0.089454,0.000000
60.910004,29.320610,-329.648315,-0.001160,0.003504,0.089003,130.424591,6.644145,0.890033,-329.648315,0.090087,0.000000
61.290005,30.359528,-329.692810,-0.001143,0.003532,0.089706,135.045929,6.879568,0.897058,-329.692810,0.090720,0.000000
61.670002,30.884575,-329.781769,-0.001108,0.003555,0.090304,137.381454,6.998545,0.903038,-329.781769,0.091354,0.000000
62.050003,31.509415,-329.826263,-0.001099,0.003578,0.090876,140.160873,7.140136,0.908761,-329.826263,0.091987,0.000000
62.430004,32.209106,-329.781769,-0.001074,0.003604,0.091535,143.273254,7.298687,0.915354,-329.781769,0.092619,0.000000
62.810001,33.214134,-329.781769,-0.001061,0.003628,0.092152,147.743851,7.526430,0.921516,-329.781769,0.093253,0.000000
63.190002,34.017342,-329.870728,-0.001030,0.003653,0.092775,151.316696,7.708440,0.927753,-329.870728,0.093886,0.000000
63.570004,34.627663,-329.870728,-0.001022,0.003674,0.093322,154.031540,7.846741,0.933219,-329.870728,0.094519,0.000000
63.950005,36.221786,-329.915222,-0.001000,0.003707,0.094146,161.122559,8.207974,0.941462,-329.915222,0.095151,0.000000
64.330002,36.876045,-329.915222,-0.000983,0.003730,0.094744,164.032837,8.356231,0.947442,-329.915222,0.095785,0.000000
64.710007,37.838631,-329.915222,-0.000961,0.003757,0.095429,168.314636,8.574356,0.954293,-329.915222,0.096418,0.000000
65.090004,38.690994,-329.915222,-0.000936,0.003779,0.095993,172.106140,8.767505,0.959933,-329.915222,0.097051,0.000000
65.470001,39.134857,-330.004181,-0.000905,0.003799,0.096496,174.080536,8.868086,0.964959,-330.004181,0.097684,0.000000
65.850006,40.669037,-330.093140,-0.000897,0.003828,0.097233,180.904907,9.215735,0.972332,-330.093140,0.098317,0.000000
66.230003,41.840149,-330.048645,-0.000880,0.003851,0.097805,186.114273,9.481113,0.978055,-330.048645,0.098950,0.000000
66.610001,43.337830,-330.093140,-0.000858,0.003880,0.098543,192.776291,9.820493,0.985428,-330.093140,0.099584,0.000000
66.990005,44.324615,-330.093140,-0.000832,0.003906,0.099202,197.165741,10.044102,0.992021,-330.093140,0.100216,0.000000
67.370003,44.920410,-330.137604,-0.000823,0.003925,0.099705,199.815964,10.179110,0.997047,-330.137604,0.100849,0.000000
67.750000,46.239357,-330.182098,-0.000811,0.003950,0.100338,205.682938,10.477987,1.003376,-330.182098,0.101483,0.000000
68.130005,48.008492,-330.182098,-0.000798,0.003978,0.101049,213.552429,10.878880,1.010491,-330.182098,0.102116,0.000000
68.510002,49.653633,-330.137604,-0.000767,0.004006,0.101752,220.870392,11.251674,1.017516,-330.137604,0.102749,0.000000
68.890007,50.686974,-330.182098,-0.000763,0.004032,0.102402,225.466919,11.485832,1.024019,-330.182098,0.103382,0.000000
69.270004,51.622368,-330.226593,-0.000737,0.004053,0.102939,229.627762,11.697796,1.029393,-330.226593,0.104015,0.000000
69.650002,53.555725,-330.315552,-0.000733,0.004083,0.103711,238.227768,12.135901,1.037114,-330.315552,0.104648,0.000000
70.030006,54.866478,-330.226593,-0.000711,0.004106,0.104301,244.058289,12.432921,1.043011,-330.226593,0.105281,0.000000
70.410004,55.931839,-330.271057,-0.000698,0.004128,0.104848,248.797241,12.674336,1.048476,-330.271057,0.105914,0.000000
70.790001,57.915840,-330.315552,-0.000677,0.004158,0.105602,257.622528,13.123918,1.056016,-330.315552,0.106556,0.000000
71.170006,59.232544,-330.360016,-0.000677,0.004182,0.106235,263.479523,13.422287,1.062352,-330.360016,0.107189,0.000000
71.550003,60.326576,-330.448975,-0.000660,0.004202,0.106720,268.346008,13.670197,1.067204,-330.448975,0.107822,0.000000
71.930000,62.096466,-330.404510,-0.000642,0.004230,0.107449,276.218872,14.071260,1.074494,-330.404510,0.108455,0.000000
72.310005,63.479828,-330.404510,-0.000634,0.004251,0.107969,282.372375,14.384734,1.079694,-330.404510,0.109088,0.000000
72.690002,65.092941,-330.448975,-0.000621,0.004276,0.108602,289.547852,14.750272,1.086023,-330.448975,0.109721,0.000000
73.070000,65.843643,-330.493469,-0.000604,0.004281,0.108742,292.887146,14.920382,1.087415,-330.493469,0.019083,0.000000
73.450005,65.007294,-330.537933,-0.000608,0.004281,0.108742,289.166870,14.730864,1.087415,-330.537933,294.500519,0.000000
73.830002,65.257904,-330.493469,-0.000591,0.004294,0.109063,290.281647,14.787653,1.090625,-330.493469,294.500519,0.000000
74.210007,64.706055,-330.537933,-0.000586,0.004303,0.109296,287.826904,14.662602,1.092964,-330.537933,294.500519,0.000000
74.590004,65.267960,-330.537933,-0.000586,0.004306,0.109366,290.326385,14.789931,1.093661,-330.537933,294.500519,0.000000
74.970001,64.950699,-330.582428,-0.000578,0.004307,0.109409,288.915131,14.718039,1.094092,-330.582428,294.500519,0.000000
75.350006,66.039886,-330.626923,-0.000578,0.004314,0.109573,293.760101,14.964852,1.095735,-330.626923,294.500519,0.000000
75.730003,65.548721,-330.626923,-0.000573,0.004314,0.109573,291.575287,14.853553,1.095735,-330.626923,294.500519,0.000000
76.110001,65.210983,-330.626923,-0.000569,0.004314,0.109573,290.072937,14.777020,1.095735,-330.626923,294.500519,0.000000
76.490005,64.853882,-330.626923,-0.000548,0.004314,0.109573,288.484467,14.696099,1.095735,-330.626923,294.500519,0.000000
76.870003,64.547043,-330.760345,-0.000560,0.004314,0.109573,287.119598,14.626569,1.095735,-330.760345,294.500519,0.000000
77.250000,64.293091,-330.804840,-0.000565,0.004314,0.109583,285.989960,14.569022,1.095826,-330.804840,294.500519,0.000000
77.630005,66.875870,-330.671387,-0.000535,0.004118,0.104587,297.478729,15.154288,1.045872,-330.671387,294.500519,0.000000
78.010002,65.482452,-330.760345,-0.000522,0.004260,0.108203,291.280487,14.838536,1.082033,-330.760345,294.500519,0.000000
78.390007,65.292160,-330.804840,-0.000530,0.004291,0.109001,290.434021,14.795415,1.090012,-330.804840,294.500519,0.000000
78.770004,65.086609,-330.849304,-0.000535,0.004298,0.109166,289.519684,14.748837,1.091662,-330.849304,294.500519,0.000000
79.150002,65.281738,-330.893799,-0.000539,0.004320,0.109721,290.387665,14.793054,1.097211,-330.893799,294.500519,0.000000
79.530006,65.314133,-330.938263,-0.000522,0.004323,0.109816,290.531769,14.800394,1.098165,-330.938263,294.500519,0.000000
79.910004,65.232956,-330.893799,-0.000526,0.004325,0.109860,290.170685,14.782000,1.098604,-330.893799,294.500519,0.000000
80.290001,65.423233,-330.893799,-0.000522,0.004331,0.110016,291.017090,14.825116,1.100163,-330.893799,294.500519,0.000000
80.670006,65.324554,-330.982758,-0.000513,0.004331,0.110016,290.578125,14.802755,1.100163,-330.982758,294.500519,0.000000
81.050003,65.238174,-330.982758,-0.000522,0.004332,0.110042,290.193878,14.783181,1.100420,-330.982758,294.500519,0.000000
81.430000,65.132416,-330.982758,-0.000522,0.004333,0.110051,289.723450,14.759216,1.100511,-330.982758,294.500519,0.000000
81.810005,65.019211,-331.027252,-0.000530,0.004333,0.110059,289.219879,14.733563,1.100595,-331.027252,294.500519,0.000000
82.190002,65.211365,-331.071716,-0.000517,0.004339,0.110198,290.074646,14.777106,1.101980,-331.071716,294.500519,0.000000
82.570007,65.250824,-331.160675,-0.000522,0.004340,0.110242,290.250153,14.786048,1.102419,-331.160675,294.500519,0.000000
82.950005,65.250092,-331.160675,-0.000522,0.004341,0.110250,290.246918,14.785882,1.102502,-331.160675,294.500519,0.000000
83.330002,65.159225,-331.071716,-0.000522,0.004341,0.110259,289.842712,14.765291,1.102593,-331.071716,294.500519,0.000000
83.710007,65.117523,-331.116211,-0.000535,0.004341,0.110268,289.657196,14.755842,1.102676,-331.116211,294.500519,0.000000
84.090004,65.191254,-331.205170,-0.000513,0.004344,0.110328,289.985168,14.772549,1.103282,-331.205170,294.500519,0.000000
84.470001,65.121613,-331.205170,-0.000530,0.004344,0.110328,289.675415,14.756768,1.103282,-331.205170,294.500519,0.000000
84.850006,65.081406,-331.160675,-0.000522,0.004344,0.110337,289.496552,14.747658,1.103373,-331.160675,294.500519,0.000000
85.230003,65.016235,-331.205170,-0.000530,0.004344,0.110346,289.206665,14.732890,1.103456,-331.205170,294.500519,0.000000
85.610001,65.245239,-331.160675,-0.000517,0.004348,0.110433,290.225311,14.784782,1.104326,-331.160675,294.500519,0.000000
85.990005,65.215088,-331.249634,-0.000517,0.004348,0.110433,290.091187,14.777950,1.104326,-331.249634,294.500519,0.000000
86.370003,65.168533,-331.338593,-0.000517,0.004348,0.110441,289.884125,14.767401,1.104410,-331.338593,294.500519,0.000000
86.750008,65.112686,-331.338593,-0.000539,0.004348,0.110441,289.635681,14.754746,1.104410,-331.338593,294.500519,0.000000
87.130005,65.053848,-331.294128,-0.000522,0.004348,0.110450,289.373962,14.741412,1.104501,-331.294128,294.500519,0.000000
87.510002,65.151413,-331.383087,-0.000535,0.004351,0.110511,289.807953,14.763521,1.105106,-331.383087,294.500519,0.000000
87.890007,65.117889,-331.294128,-0.000526,0.004351,0.110511,289.658844,14.755924,1.105106,-331.294128,294.500519,0.000000
88.270004,65.075073,-331.472046,-0.000509,0.004351,0.110511,289.468384,14.746222,1.105106,-331.472046,294.500519,0.000000
88.650002,65.033371,-331.427551,-0.000522,0.004351,0.110519,289.282867,14.736773,1.105189,-331.427551,294.500519,0.000000
89.030006,65.025543,-331.427551,-0.000530,0.004352,0.110536,289.248077,14.734999,1.105363,-331.427551,294.500519,0.000000
89.410004,65.018097,-331.427551,-0.000522,0.004352,0.110536,289.214935,14.733311,1.105363,-331.427551,294.500519,0.000000
89.790001,65.099274,-331.561005,-0.000526,0.004356,0.110632,289.576019,14.751707,1.106317,-331.561005,294.500519,0.000000
90.170006,65.209122,-331.605499,-0.000522,0.004356,0.110632,290.064667,14.776598,1.106317,-331.605499,294.500519,0.000000
90.550003,65.187149,-331.605499,-0.000522,0.004356,0.110632,289.966919,14.771620,1.106317,-331.605499,294.500519,0.000000
90.930008,65.145828,-331.561005,-0.000539,0.004356,0.110632,289.783112,14.762256,1.106317,-331.561005,294.500519,0.000000
91.310005,65.121246,-331.605499,-0.000513,0.004356,0.110641,289.673767,14.756685,1.106408,-331.605499,294.500519,0.000000
91.690002,65.230347,-331.649963,-0.000509,0.004358,0.110701,290.159088,14.781407,1.107014,-331.649963,294.500519,0.000000
92.070007,65.226257,-331.694458,-0.000513,0.004358,0.110701,290.140869,14.780481,1.107014,-331.694458,294.500519,0.000000
92.450005,65.213593,-331.649963,-0.000522,0.004358,0.110701,290.084534,14.777611,1.107014,-331.649963,294.500519,0.000000
92.830002,65.193863,-331.738922,-0.000517,0.004359,0.110710,289.996796,14.773141,1.107097,-331.738922,294.500519,0.000000
93.210007,65.180084,-331.694458,-0.000526,0.004359,0.110719,289.935486,14.770019,1.107188,-331.694458,294.500519,0.000000
93.590004,65.143585,-331.738922,-0.000500,0.004360,0.110736,289.773132,14.761747,1.107362,-331.738922,294.500519,0.000000
93.970001,65.234818,-331.827881,-0.000517,0.004361,0.110770,290.178955,14.782421,1.107702,-331.827881,294.500519,0.000000
94.350006,65.239655,-331.783417,-0.000513,0.004361,0.110779,290.200470,14.783518,1.107793,-331.783417,294.500519,0.000000
94.730003,65.227005,-331.827881,-0.000526,0.004361,0.110779,290.144196,14.780650,1.107793,-331.827881,294.500519,0.000000
95.110008,65.222153,-331.738922,-0.000504,0.004362,0.110805,290.122620,14.779552,1.108051,-331.738922,294.500519,0.000000
95.490005,65.244125,-331.872375,-0.000517,0.004363,0.110814,290.220367,14.784530,1.108142,-331.872375,294.500519,0.000000
95.870003,65.231094,-331.916870,-0.000504,0.004363,0.110822,290.162415,14.781577,1.108225,-331.916870,294.500519,0.000000
96.250008,65.267960,-331.961334,-0.000522,0.004364,0.110857,290.326385,14.789931,1.108573,-331.961334,294.500519,0.000000
96.630005,65.323822,-331.916870,-0.000504,0.004365,0.110875,290.574860,14.802589,1.108747,-331.916870,294.500519,0.000000
97.010002,65.324554,-331.916870,-0.000509,0.004365,0.110875,290.578125,14.802755,1.108747,-331.916870,294.500519,0.000000
97.390007,65.351746,-332.005829,-0.000513,0.004366,0.110900,290.699097,14.808917,1.109004,-332.005829,294.500519,0.000000
97.770004,65.358444,-332.005829,-0.000522,0.004367,0.110910,290.728882,14.810435,1.109095,-332.005829,294.500519,0.000000
98.150002,65.349884,-332.005829,-0.000509,0.004367,0.110910,290.690796,14.808496,1.109095,-332.005829,294.500519,0.000000
98.530006,65.349136,-332.050293,-0.000513,0.004367,0.110927,290.687469,14.808326,1.109269,-332.050293,294.500519,0.000000
98.910004,65.339828,-332.094788,-0.000513,0.004367,0.110927,290.646088,14.806217,1.109269,-332.094788,294.500519,0.000000
99.290001,65.350250,-332.050293,-0.000496,0.004368,0.110953,290.692444,14.808578,1.109527,-332.050293,294.500519,0.000000
99.670006,65.355835,-332.139252,-0.000504,0.004368,0.110953,290.717285,14.809844,1.109527,-332.139252,294.500519,0.000000
100.050003,65.347641,-332.139252,-0.000509,0.004369,0.110961,290.680817,14.807987,1.109610,-332.139252,294.500519,0.000000
100.430008,65.315628,-332.139252,-0.000509,0.004369,0.110970,290.538422,14.800733,1.109701,-332.139252,294.500519,0.000000
100.810005,65.340942,-332.183746,-0.000509,0.004369,0.110978,290.651031,14.806470,1.109784,-332.183746,294.500519,0.000000
101.190002,65.326797,-332.183746,-0.000517,0.004370,0.110987,290.588104,14.803264,1.109875,-332.183746,294.500519,0.000000
101.570007,65.349136,-332.272705,-0.000509,0.004370,0.110996,290.687469,14.808326,1.109958,-332.272705,294.500519,0.000000
101.950005,65.340195,-332.272705,-0.000526,0.004370,0.111005,290.647705,14.806300,1.110049,-332.272705,294.500519,0.000000
102.330002,65.331268,-332.272705,-0.000500,0.004370,0.111005,290.608002,14.804276,1.110049,-332.272705,294.500519,0.000000
102.710007,65.305939,-332.272705,-0.000504,0.004370,0.111005,290.495331,14.798536,1.110049,-332.272705,294.500519,0.000000
103.090004,65.299988,-332.272705,-0.000504,0.004370,0.111005,290.468842,14.797189,1.110049,-332.272705,294.500519,0.000000
103.470001,65.285095,-332.450623,-0.000504,0.004370,0.111005,290.402618,14.793814,1.110049,-332.450623,294.500519,0.000000
103.850006,65.257538,-332.406158,-0.000517,0.004370,0.111005,290.280029,14.787569,1.110049,-332.406158,294.500519,0.000000
104.230003,65.339081,-332.361664,-0.000500,0.004373,0.111065,290.642761,14.806047,1.110655,-332.361664,294.500519,0.000000
104.610008,65.366272,-332.361664,-0.000522,0.004373,0.111065,290.763702,14.812209,1.110655,-332.361664,294.500519,0.000000
104.990005,65.361801,-332.495117,-0.000504,0.004373,0.111065,290.743805,14.811195,1.110655,-332.495117,294.500519,0.000000
105.370003,65.339828,-332.450623,-0.000496,0.004373,0.111074,290.646088,14.806217,1.110738,-332.450623,294.500519,0.000000
105.750008,65.348022,-332.495117,-0.000496,0.004373,0.111074,290.682526,14.808074,1.110738,-332.495117,294.500519,0.000000
106.130005,65.344299,-332.495117,-0.000509,0.004373,0.111083,290.665955,14.807230,1.110829,-332.495117,294.500519,0.000000
106.510002,65.338715,-332.539581,-0.000504,0.004373,0.111083,290.641113,14.805964,1.110829,-332.539581,294.500519,0.000000
106.890007,65.326797,-332.584076,-0.000504,0.004373,0.111083,290.588104,14.803264,1.110829,-332.584076,294.500519,0.000000
107.270004,65.308182,-332.628540,-0.000504,0.004373,0.111083,290.505310,14.799046,1.110829,-332.628540,294.500519,0.000000
107.650002,65.277634,-332.584076,-0.000513,0.004373,0.111083,290.369415,14.792123,1.110829,-332.584076,294.500519,0.000000
108.030006,65.267960,-332.628540,-0.000500,0.004374,0.111091,290.326385,14.789931,1.110912,-332.628540,294.500519,0.000000
108.410004,65.261261,-332.584076,-0.000496,0.004374,0.111091,290.296600,14.788413,1.110912,-332.584076,294.500519,0.000000
108.790009,65.234451,-332.628540,-0.000487,0.004374,0.111091,290.177338,14.782338,1.110912,-332.628540,294.500519,0.000000
109.170006,65.235184,-332.761993,-0.000496,0.004375,0.111126,290.180603,14.782503,1.111260,-332.761993,294.500519,0.000000
109.550003,65.253433,-332.761993,-0.000500,0.004375,0.111126,290.261780,14.786639,1.111260,-332.761993,294.500519,0.000000
109.930008,65.253815,-332.717499,-0.000509,0.004375,0.111126,290.263458,14.786726,1.111260,-332.717499,294.500519,0.000000
110.310005,65.231842,-332.761993,-0.000500,0.004375,0.111126,290.165710,14.781747,1.111260,-332.761993,294.500519,0.000000
110.690002,65.213226,-332.806488,-0.000492,0.004375,0.111135,290.082916,14.777528,1.111351,-332.806488,294.500519,0.000000
111.070007,65.205399,-332.806488,-0.000492,0.004375,0.111135,290.048096,14.775755,1.111351,-332.806488,294.500519,0.000000
111.450005,65.189011,-332.850952,-0.000500,0.004375,0.111135,289.975189,14.772040,1.111351,-332.850952,294.500519,0.000000
111.830002,65.196838,-332.806488,-0.000500,0.004376,0.111153,290.010010,14.773814,1.111525,-332.806488,294.500519,0.000000
112.210007,65.204651,-332.939911,-0.000496,0.004376,0.111153,290.044769,14.775585,1.111525,-332.939911,294.500519,0.000000
112.590004,65.215820,-332.939911,-0.000504,0.004377,0.111178,290.094452,14.778116,1.111783,-332.939911,294.500519,0.000000
112.970009,65.227737,-332.984406,-0.000509,0.004377,0.111178,290.147461,14.780817,1.111783,-332.984406,294.500519,0.000000
113.350006,65.221405,-332.939911,-0.000517,0.004377,0.111178,290.119293,14.779382,1.111783,-332.939911,294.500519,0.000000
113.730003,65.214340,-333.028870,-0.000509,0.004377,0.111178,290.087860,14.777781,1.111783,-333.028870,294.500519,0.000000
114.110008,65.202042,-333.028870,-0.000500,0.004377,0.111178,290.033173,14.774994,1.111783,-333.028870,294.500519,0.000000
114.490005,65.183426,-333.028870,-0.000487,0.004377,0.111178,289.950348,14.770775,1.111783,-333.028870,294.500519,0.000000
114.870003,65.153641,-333.073364,-0.000504,0.004377,0.111178,289.817871,14.764026,1.111783,-333.073364,294.500519,0.000000
115.250008,65.142090,-333.117828,-0.000504,0.004377,0.111178,289.766479,14.761409,1.111783,-333.117828,294.500519,0.000000
115.630005,66.011963,-333.073364,-0.000500,0.004383,0.111317,293.635864,14.958525,1.113168,-333.073364,294.500519,0.000000
116.010002,65.981430,-333.117828,-0.000500,0.004382,0.111308,293.500061,14.951606,1.113085,-333.117828,294.500519,0.000000
116.390007,65.927063,-333.117828,-0.000492,0.004382,0.111308,293.258209,14.939285,1.113085,-333.117828,294.500519,0.000000
116.770004,65.909180,-333.162323,-0.000513,0.004382,0.111308,293.178680,14.935233,1.113085,-333.162323,294.500519,0.000000
117.150009,65.874176,-333.162323,-0.000513,0.004382,0.111308,293.022980,14.927301,1.113085,-333.162323,294.500519,0.000000
117.530006,65.878647,-333.206818,-0.000492,0.004382,0.111308,293.042847,14.928314,1.113085,-333.206818,294.500519,0.000000
117.910004,65.879761,-333.251282,-0.000496,0.004382,0.111308,293.047821,14.928567,1.113085,-333.251282,294.500519,0.000000
118.290009,65.865982,-333.295776,-0.000496,0.004382,0.111308,292.986511,14.925445,1.113085,-333.295776,294.500519,0.000000
118.670006,65.860779,-333.295776,-0.000500,0.004382,0.111308,292.963379,14.924266,1.113085,-333.295776,294.500519,0.000000
119.050003,65.821671,-333.340240,-0.000492,0.004382,0.111308,292.789429,14.915404,1.113085,-333.340240,294.500519,0.000000
119.430008,65.775497,-333.295776,-0.000509,0.004382,0.111308,292.584015,14.904941,1.113085,-333.295776,294.500519,0.000000
119.810005,65.768051,-333.340240,-0.000504,0.004382,0.111308,292.550903,14.903254,1.113085,-333.340240,294.500519,0.000000
120.190002,65.755402,-333.340240,-0.000496,0.004382,0.111308,292.494629,14.900388,1.113085,-333.340240,294.500519,0.000000
120.570007,65.745712,-333.429199,-0.000504,0.004382,0.111308,292.451538,14.898191,1.113085,-333.429199,294.500519,0.000000
120.950005,65.680923,-333.384735,-0.000487,0.004382,0.111308,292.163330,14.883510,1.113085,-333.384735,294.500519,0.000000
121.330009,65.670868,-333.429199,-0.000492,0.004382,0.111308,292.118622,14.881231,1.113085,-333.429199,294.500519,0.000000
121.710007,65.654480,-333.429199,-0.000492,0.004382,0.111308,292.045715,14.877518,1.113085,-333.429199,294.500519,0.000000
122.090004,65.609055,-333.473694,-0.000487,0.004382,0.111308,291.843658,14.867224,1.113085,-333.473694,294.500519,0.000000
122.470009,65.598633,-333.562653,-0.000504,0.004382,0.111308,291.797302,14.864862,1.113085,-333.562653,294.500519,0.000000
122.850006,65.582993,-333.518158,-0.000487,0.004382,0.111308,291.727722,14.861319,1.113085,-333.518158,294.500519,0.000000
123.230003,65.562134,-333.607147,-0.000492,0.004382,0.111308,291.634949,14.856592,1.113085,-333.607147,294.500519,0.000000
123.610008,65.556168,-333.562653,-0.000496,0.004382,0.111308,291.608398,14.855240,1.113085,-333.562653,294.500519,0.000000
123.990005,65.541275,-333.607147,-0.000479,0.004382,0.111308,291.542145,14.851865,1.113085,-333.607147,294.500519,0.000000
124.370003,65.511856,-333.651611,-0.000500,0.004382,0.111308,291.411285,14.845199,1.113085,-333.651611,294.500519,0.000000
124.750008,65.503296,-333.651611,-0.000500,0.004382,0.111308,291.373199,14.843259,1.113085,-333.651611,294.500519,0.000000
125.130005,65.485046,-333.651611,-0.000504,0.004382,0.111308,291.292023,14.839124,1.113085,-333.651611,294.500519,0.000000
125.510010,65.475739,-333.740570,-0.000492,0.004382,0.111308,291.250641,14.837015,1.113085,-333.740570,294.500519,0.000000
125.890007,65.456757,-333.696106,-0.000500,0.004382,0.111308,291.166199,14.832713,1.113085,-333.696106,294.500519,0.000000
126.270004,65.423615,-333.829529,-0.000504,0.004382,0.111308,291.018768,14.825203,1.113085,-333.829529,294.500519,0.000000
126.650009,65.394562,-333.740570,-0.000492,0.004382,0.111308,290.889526,14.818619,1.113085,-333.740570,294.500519,0.000000
127.030006,65.377060,-333.785065,-0.000487,0.004382,0.111308,290.811676,14.814653,1.113085,-333.785065,294.500519,0.000000
127.410004,65.358444,-333.874023,-0.000492,0.004382,0.111308,290.728882,14.810435,1.113085,-333.874023,294.500519,0.000000
127.790009,65.343918,-333.829529,-0.000492,0.004382,0.111308,290.664276,14.807143,1.113085,-333.829529,294.500519,0.000000
128.170013,65.337585,-333.874023,-0.000487,0.004382,0.111308,290.636108,14.805709,1.113085,-333.874023,294.500519,0.000000
128.550003,65.332382,-333.962982,-0.000504,0.004382,0.111308,290.612946,14.804529,1.113085,-333.962982,294.500519,0.000000
128.930008,65.304825,-333.874023,-0.000479,0.004382,0.111308,290.490356,14.798285,1.113085,-333.874023,294.500519,0.000000
129.310013,65.307053,-333.962982,-0.000500,0.004382,0.111308,290.500275,14.798789,1.113085,-333.962982,294.500519,0.000000
129.690002,65.267593,-334.051941,-0.000487,0.004382,0.111308,290.324768,14.789847,1.113085,-334.051941,294.500519,0.000000
130.070007,65.260132,-334.007446,-0.000496,0.004383,0.111317,290.291565,14.788157,1.113168,-334.007446,294.500519,0.000000
130.450012,65.234818,-334.007446,-0.000479,0.004383,0.111317,290.178955,14.782421,1.113168,-334.007446,294.500519,0.000000
130.830002,65.244873,-334.007446,-0.000496,0.004383,0.111317,290.223694,14.784699,1.113168,-334.007446,294.500519,0.000000
131.210007,65.226257,-334.051941,-0.000483,0.004383,0.111317,290.140869,14.780481,1.113168,-334.051941,294.500519,0.000000
131.590012,65.200562,-334.051941,-0.000479,0.004383,0.111317,290.026581,14.774658,1.113168,-334.051941,294.500519,0.000000
131.970001,65.196457,-334.140900,-0.000487,0.004383,0.111317,290.008331,14.773728,1.113168,-334.140900,294.500519,0.000000
132.350006,65.173752,-334.140900,-0.000479,0.004383,0.111317,289.907318,14.768583,1.113168,-334.140900,294.500519,0.000000
132.730011,65.161087,-334.140900,-0.000487,0.004383,0.111317,289.850983,14.765714,1.113168,-334.140900,294.500519,0.000000
133.110001,65.129807,-334.185394,-0.000483,0.004383,0.111317,289.711853,14.758625,1.113168,-334.185394,294.500519,0.000000
133.490005,65.123108,-334.185394,-0.000496,0.004383,0.111317,289.682037,14.757108,1.113168,-334.185394,1681.641113,0.000000
133.870010,65.086243,-334.274353,-0.000487,0.004379,0.111221,289.518066,14.748754,1.112214,-334.274353,0.111013,0.000000
134.250000,64.972290,-334.274353,-0.000492,0.004357,0.110667,289.011169,14.722932,1.106665,-334.274353,0.110380,0.000000
134.630005,64.956650,-334.229858,-0.000504,0.004337,0.110172,288.941620,14.719388,1.101722,-334.229858,0.109748,0.000000
135.010010,64.885910,-334.274353,-0.000487,0.004317,0.109661,288.626953,14.703358,1.096605,-334.274353,0.109114,0.000000
135.389999,64.843079,-334.363312,-0.000479,0.004292,0.109019,288.436432,14.693652,1.090186,-334.363312,0.108481,0.000000
135.770004,64.832657,-334.363312,-0.000487,0.004265,0.108325,288.390076,14.691290,1.083252,-334.363312,0.107848,0.000000
136.150009,64.808456,-334.363312,-0.000492,0.004240,0.107692,288.282410,14.685806,1.076916,-334.363312,0.107215,0.000000
136.530014,64.826324,-334.363312,-0.000479,0.004218,0.107137,288.361908,14.689856,1.071368,-334.363312,0.106582,0.000000
136.910004,64.802124,-334.363312,-0.000487,0.004198,0.106617,288.254242,14.684371,1.066167,-334.363312,0.105949,0.000000
137.290009,64.713867,-334.496765,-0.000487,0.004173,0.105992,287.861664,14.664372,1.059922,-334.496765,0.105315,0.000000
137.670013,64.351181,-334.541229,-0.000487,0.004149,0.105377,286.248352,14.582187,1.053768,-334.541229,0.104683,0.000000
138.050003,63.452271,-334.496765,-0.000470,0.004120,0.104657,282.249786,14.378490,1.046569,-334.496765,0.104050,0.000000
138.430008,62.361961,-334.452271,-0.000470,0.004097,0.104058,277.399872,14.131422,1.040581,-334.452271,0.103416,0.000000
138.810013,61.085098,-334.496765,-0.000466,0.004077,0.103546,271.720093,13.842081,1.035464,-334.496765,0.102783,0.000000
139.190002,59.938194,-334.541229,-0.000466,0.004058,0.103061,266.618408,13.582190,1.030612,-334.541229,0.102151,0.000000
139.570007,57.771355,-334.674683,-0.000470,0.004027,0.102298,256.979828,13.091176,1.022981,-334.674683,0.101517,0.000000
139.950012,56.018600,-334.585724,-0.000457,0.004005,0.101734,249.183182,12.693996,1.017342,-334.585724,0.100884,0.000000
140.330002,53.676750,-334.585724,-0.000466,0.003978,0.101049,238.766113,12.163325,1.010491,-334.585724,0.100242,0.000000
140.710007,51.689766,-334.585724,-0.000461,0.003960,0.100581,229.927567,11.713069,1.005806,-334.585724,0.099609,0.000000
141.090012,49.725876,-334.719147,-0.000453,0.003941,0.100113,221.191742,11.268044,1.001127,-334.719147,0.098977,0.000000
141.470001,46.969948,-334.763641,-0.000470,0.003913,0.099393,208.932770,10.643542,0.993929,-334.763641,0.098343,0.000000
141.850006,44.391640,-334.719147,-0.000466,0.003892,0.098846,197.463882,10.059290,0.988463,-334.719147,0.097710,0.000000
142.230011,41.018318,-334.674683,-0.000461,0.003859,0.098014,182.458588,9.294884,0.980136,-334.674683,0.097077,0.000000
142.610001,38.696953,-334.763641,-0.000470,0.003838,0.097485,172.132645,8.768855,0.974845,-334.763641,0.096444,0.000000
142.990005,35.762283,-334.808105,-0.000461,0.003811,0.096791,159.078583,8.103849,0.967911,-334.808105,0.095811,0.000000
143.370010,33.140038,-334.763641,-0.000453,0.003787,0.096192,147.414246,7.509640,0.961923,-334.763641,0.095178,0.000000
143.750000,31.824074,-334.897095,-0.000466,0.003773,0.095846,141.560547,7.211438,0.958457,-334.897095,0.094545,0.000000
144.130005,27.397682,-334.808105,-0.000448,0.003734,0.094848,121.870979,6.208404,0.948480,-334.808105,0.093912,0.000000
144.510010,24.838737,-334.852600,-0.000457,0.003712,0.094293,110.488220,5.628539,0.942931,-334.852600,0.093279,0.000000
144.889999,22.314423,-334.941559,-0.000457,0.003690,0.093730,99.259506,5.056520,0.937299,-334.941559,0.092646,0.000000
145.270004,19.465775,-334.897095,-0.000466,0.003664,0.093071,86.588089,4.411007,0.930706,-334.897095,0.092012,0.000000
145.650009,17.147758,-334.986053,-0.000470,0.003638,0.092411,76.277039,3.885738,0.924112,-334.986053,0.091379,0.000000
146.030014,13.756187,-334.941559,-0.000461,0.003612,0.091753,61.190578,3.117197,0.917527,-334.941559,0.090747,0.000000
146.410004,11.772934,-334.986053,-0.000470,0.003595,0.091310,52.368626,2.667785,0.913098,-334.986053,0.090113,0.000000
146.790009,8.765648,-335.030518,-0.000457,0.003568,0.090616,38.991550,1.986324,0.906164,-335.030518,0.089480,0.000000
147.170013,5.632881,-335.030518,-0.000466,0.003540,0.089914,25.056307,1.276429,0.899140,-335.030518,0.088847,0.000000
147.550003,3.798203,-335.119476,-0.000470,0.003524,0.089515,16.895248,0.860685,0.895150,-335.119476,0.088214,0.000000
147.930008,0.680702,-335.075012,-0.000461,0.003491,0.088674,3.027915,0.154249,0.886740,-335.075012,0.087581,0.000000
148.310013,-1.457836,-335.119476,-0.000483,0.003465,0.088006,-6.484779,-0.330350,0.880056,-335.119476,0.086948,0.000000
148.690002,-0.351517,-335.163971,-0.000492,0.003440,0.087382,-1.563625,-0.079655,0.873819,-335.163971,0.086315,0.000000
149.070007,-0.113945,-335.208435,-0.000509,0.003416,0.086775,-0.506853,-0.025820,0.867748,-335.208435,0.085682,0.000000
149.450012,-0.131447,-335.208435,-0.000578,0.003386,0.086003,-0.584705,-0.029786,0.860027,-335.208435,0.085049,0.000000
149.830002,-0.125488,-335.208435,-0.000599,0.003361,0.085361,-0.558200,-0.028436,0.853607,-335.208435,0.084415,0.000000
150.210007,-0.107239,-335.252930,-0.000642,0.003342,0.084893,-0.477022,-0.024301,0.848929,-335.252930,0.083782,0.000000
150.590012,-0.075958,-335.252930,-0.000655,0.003316,0.084234,-0.337879,-0.017212,0.842336,-335.252930,0.083150,0.000000
150.970001,-0.142616,-335.297424,-0.000703,0.003288,0.083522,-0.634389,-0.032317,0.835220,-335.297424,0.082516,0.000000
151.350006,-0.124367,-335.297424,-0.000746,0.003267,0.082976,-0.553211,-0.028182,0.829763,-335.297424,0.081875,0.000000
151.730011,-0.096069,-335.297424,-0.000785,0.003235,0.082178,-0.427338,-0.021770,0.821784,-335.297424,0.081241,0.000000
152.110001,-0.139267,-335.297424,-0.000819,0.003213,0.081623,-0.619490,-0.031558,0.816228,-335.297424,0.080608,0.000000
152.490005,-0.106125,-335.386383,-0.000841,0.003188,0.080982,-0.472067,-0.024048,0.809816,-335.386383,0.079976,0.000000
152.870010,-0.134048,-335.430847,-0.000884,0.003168,0.080461,-0.596277,-0.030376,0.804608,-335.430847,0.079342,0.000000
153.250000,-0.151550,-335.475342,-0.000914,0.003147,0.079923,-0.674129,-0.034342,0.799234,-335.475342,0.078709,0.000000
153.630005,-0.122131,-335.475342,-0.000957,0.003111,0.079013,-0.543267,-0.027675,0.790127,-335.475342,0.078076,0.000000
154.010010,-0.134422,-335.430847,-0.000974,0.003089,0.078466,-0.597940,-0.030461,0.784662,-335.430847,0.077443,0.000000
154.390015,-0.117294,-335.519806,-0.001018,0.003057,0.077651,-0.521751,-0.026579,0.776509,-335.519806,0.076810,0.000000
154.770004,-0.107986,-335.519806,-0.001087,0.003041,0.077235,-0.480348,-0.024470,0.772353,-335.519806,0.076177,0.000000
155.150009,-0.126976,-335.564301,-0.001082,0.003012,0.076506,-0.564817,-0.028773,0.765064,-335.564301,0.075544,0.000000
155.530014,-0.122879,-335.519806,-0.001117,0.002991,0.075977,-0.546593,-0.027845,0.759772,-335.519806,0.074911,0.000000
155.900009,-0.089737,-335.608765,-0.001130,0.002970,0.075440,-0.399170,-0.020335,0.754398,-335.608765,0.075292,0.000000