File: Data/compression 23/AutoNoHeating-12-23-reverse-1-2_09192024_182029.csv
Time (sec),S:Load (lbs),S:HL1 (DIM),S:LVDT (in),S:Position (in),Ch:Position (mm),Ch:Load (N),Ch:Stress (MPa),Ch:Strain (mm/mm),Ch:HL1 (DIM),Set Point (),Cycles ()
0.110000,-0.163467,-299.134399,-0.010391,-0.006285,-0.159639,-0.727139,-0.037042,-1.596385,-299.134399,-0.159872,0.000000
0.510000,-0.108360,-299.223358,-0.010391,-0.006270,-0.159257,-0.482011,-0.024555,-1.592570,-299.223358,-0.158416,0.000000
0.910000,-0.121391,-299.178864,-0.010386,-0.006022,-0.152952,-0.539975,-0.027508,-1.529521,-299.178864,-0.151755,0.000000
1.310000,-0.073723,-299.267853,-0.010102,-0.005755,-0.146179,-0.327936,-0.016706,-1.461795,-299.267853,-0.145078,0.000000
1.710000,-0.064041,-299.223358,-0.009856,-0.005496,-0.139597,-0.284869,-0.014512,-1.395968,-299.223358,-0.138417,0.000000
2.110000,-0.058456,-299.312317,-0.009580,-0.005231,-0.132859,-0.260027,-0.013246,-1.328589,-299.312317,-0.131757,0.000000
2.510000,-0.077080,-299.312317,-0.009326,-0.004974,-0.126346,-0.342868,-0.017467,-1.263458,-299.312317,-0.125097,0.000000
2.910000,-0.068512,-299.312317,-0.009050,-0.004709,-0.119599,-0.304756,-0.015525,-1.195989,-299.312317,-0.118420,0.000000
3.310000,-0.046547,-299.401276,-0.008795,-0.004448,-0.112973,-0.207051,-0.010548,-1.129731,-299.401276,-0.111759,0.000000
3.710000,-0.060692,-299.445770,-0.008532,-0.004190,-0.106434,-0.269971,-0.013753,-1.064343,-299.445770,-0.105099,0.000000
4.110000,-0.030907,-299.490234,-0.008282,-0.003930,-0.099818,-0.137480,-0.007004,-0.998175,-299.490234,-0.098438,0.000000
4.510000,-0.052132,-299.445770,-0.008002,-0.003667,-0.093149,-0.231893,-0.011813,-0.931485,-299.445770,-0.091778,0.000000
4.910000,-0.072609,-299.534729,-0.007731,-0.003394,-0.086219,-0.322981,-0.016453,-0.862191,-299.534729,-0.085100,0.000000
5.310000,-0.058456,-299.534729,-0.007455,-0.003132,-0.079559,-0.260027,-0.013246,-0.795592,-299.534729,-0.078440,0.000000
5.710000,-0.035744,-299.490234,-0.007179,-0.002871,-0.072933,-0.158996,-0.008100,-0.729334,-299.490234,-0.071780,0.000000
6.110000,-0.017868,-299.534729,-0.006924,-0.002614,-0.066403,-0.079481,-0.004049,-0.664030,-299.534729,-0.065120,0.000000
6.510000,-0.056229,-299.623688,-0.006648,-0.002347,-0.059621,-0.250117,-0.012742,-0.596212,-299.623688,-0.058459,0.000000
6.910000,-0.083405,-299.623688,-0.006390,-0.002086,-0.052979,-0.371002,-0.018900,-0.529787,-299.623688,-0.051782,0.000000
7.310000,-0.122131,-299.712646,-0.006127,-0.001829,-0.046448,-0.543267,-0.027675,-0.464482,-299.712646,-0.045121,0.000000
7.710001,-0.051758,-299.668182,-0.005851,-0.001560,-0.039632,-0.230230,-0.011728,-0.396316,-299.668182,-0.038461,0.000000
8.110001,-0.056229,-299.623688,-0.005592,-0.001300,-0.033015,-0.250117,-0.012742,-0.330149,-299.623688,-0.031801,0.000000
8.510000,-0.037979,-299.668182,-0.005295,-0.001035,-0.026285,-0.168940,-0.008606,-0.262853,-299.668182,-0.025141,0.000000
8.910001,-0.059578,-299.757141,-0.005032,-0.000777,-0.019737,-0.265016,-0.013501,-0.197375,-299.757141,-0.018463,0.000000
9.310000,-0.036491,-299.757141,-0.004777,-0.000512,-0.013000,-0.162322,-0.008269,-0.129996,-299.757141,-0.011803,0.000000
9.710000,-0.017868,-299.801605,-0.004523,-0.000251,-0.006382,-0.079481,-0.004049,-0.063821,-299.801605,-0.005142,0.000000
10.110001,0.026443,-299.801605,-0.004268,0.000007,0.000182,0.117626,0.005992,0.001824,-299.801605,0.001518,0.000000
10.510000,0.214119,-299.801605,-0.004161,0.000016,0.000399,0.952449,0.048520,0.003989,-299.801605,0.000650,0.000000
10.910001,0.114319,-299.846100,-0.004135,0.000016,0.000399,0.508516,0.025905,0.003989,-299.846100,0.000893,0.000000
11.310000,0.115814,-299.890564,-0.004152,0.000016,0.000407,0.515167,0.026244,0.004073,-299.890564,0.001561,0.000000
11.710001,0.221565,-299.890564,-0.004148,0.000051,0.001283,0.985571,0.050207,0.012831,-299.890564,0.002229,0.000000
12.110001,0.301994,-299.890564,-0.004126,0.000072,0.001838,1.343338,0.068433,0.018379,-299.890564,0.002896,0.000000
12.510000,0.418175,-299.979523,-0.004100,0.000099,0.002515,1.860134,0.094760,0.025147,-299.979523,0.003564,0.000000
12.910001,0.507919,-299.979523,-0.004070,0.000128,0.003260,2.259338,0.115096,0.032603,-299.979523,0.004232,0.000000
13.310000,0.649796,-300.068481,-0.004049,0.000153,0.003876,2.890435,0.147246,0.038765,-300.068481,0.004891,0.000000
13.710001,0.750710,-300.068481,-0.004027,0.000172,0.004371,3.339323,0.170113,0.043708,-300.068481,0.005558,0.000000
14.110001,0.930931,-300.068481,-0.003988,0.000198,0.005038,4.140988,0.210952,0.050385,-300.068481,0.006226,0.000000
14.510000,1.114883,-300.024017,-0.003975,0.000228,0.005784,4.959249,0.252636,0.057841,-300.024017,0.006894,0.000000
14.910001,1.278358,-300.112976,-0.003941,0.000261,0.006625,5.686422,0.289680,0.066251,-300.112976,0.007562,0.000000
15.310000,1.363258,-300.157471,-0.003928,0.000280,0.007102,6.064076,0.308919,0.071020,-300.157471,0.008230,0.000000
15.710001,1.539764,-300.201935,-0.003880,0.000310,0.007874,6.849214,0.348916,0.078741,-300.201935,0.008898,0.000000
16.110001,1.680893,-300.246429,-0.003876,0.000330,0.008377,7.476985,0.380896,0.083767,-300.246429,0.009565,0.000000
16.510000,1.857025,-300.201935,-0.003824,0.000365,0.009270,8.260461,0.420808,0.092700,-300.201935,0.010233,0.000000
16.910002,1.946396,-300.290894,-0.003798,0.000390,0.009904,8.658001,0.441060,0.099036,-300.290894,0.010892,0.000000
17.310001,2.022728,-300.246429,-0.003786,0.000408,0.010363,8.997543,0.458357,0.103630,-300.246429,0.011560,0.000000
17.710001,2.171677,-300.290894,-0.003764,0.000437,0.011100,9.660100,0.492109,0.111003,-300.290894,0.012227,0.000000
18.110001,2.284508,-300.335388,-0.003734,0.000466,0.011838,10.161998,0.517677,0.118376,-300.335388,0.012895,0.000000
18.510000,2.473671,-300.379852,-0.003699,0.000498,0.012644,11.003438,0.560542,0.126438,-300.379852,0.013563,0.000000
18.910002,2.475906,-300.335388,-0.003669,0.000520,0.013199,11.013382,0.561048,0.131987,-300.335388,0.014231,0.000000
19.310001,2.626717,-300.424347,-0.003639,0.000548,0.013910,11.684219,0.595223,0.139102,-300.424347,0.014899,0.000000
19.710001,2.671028,-300.468811,-0.003630,0.000565,0.014361,11.881327,0.605264,0.143606,-300.468811,0.015567,0.000000
20.110001,2.898178,-300.513306,-0.003600,0.000603,0.015306,12.891740,0.656737,0.153061,-300.513306,0.016226,0.000000
20.510000,2.885887,-300.557800,-0.003587,0.000628,0.015948,12.837068,0.653951,0.159480,-300.557800,0.016894,0.000000
20.910002,2.871742,-300.557800,-0.003548,0.000647,0.016442,12.774147,0.650746,0.164423,-300.557800,0.017561,0.000000
21.310001,3.102982,-300.602264,-0.003523,0.000681,0.017310,13.802752,0.703146,0.173098,-300.602264,0.018229,0.000000
21.710001,3.147667,-300.602264,-0.003484,0.000707,0.017968,14.001522,0.713272,0.179684,-300.602264,0.018896,0.000000
22.110001,3.136497,-300.602264,-0.003462,0.000731,0.018576,13.951838,0.710741,0.185755,-300.602264,0.019564,0.000000
22.510000,3.195702,-300.646759,-0.003445,0.000755,0.019165,14.215191,0.724156,0.191652,-300.646759,0.020232,0.000000
22.910002,3.299599,-300.735718,-0.003415,0.000784,0.019911,14.677348,0.747700,0.199108,-300.735718,0.020900,0.000000
23.310001,3.276138,-300.691223,-0.003385,0.000799,0.020301,14.572991,0.742384,0.203014,-300.691223,0.021559,0.000000
23.710001,3.527489,-300.735718,-0.003367,0.000836,0.021238,15.691053,0.799340,0.212378,-300.735718,0.022226,0.000000
24.110001,3.469025,-300.824677,-0.003333,0.000855,0.021715,15.430992,0.786092,0.217147,-300.824677,0.022894,0.000000
24.510000,3.587814,-300.824677,-0.003316,0.000887,0.022530,15.959395,0.813010,0.225300,-300.824677,0.023562,0.000000
24.910002,3.596748,-300.780182,-0.003281,0.000906,0.023016,15.999136,0.815035,0.230159,-300.780182,0.024230,0.000000
25.310001,3.856667,-300.913635,-0.003247,0.000941,0.023900,17.155310,0.873933,0.239001,-300.913635,0.024898,0.000000
25.710001,3.857407,-300.869141,-0.003234,0.000968,0.024585,17.158602,0.874101,0.245852,-300.869141,0.025565,0.000000
26.110001,3.966888,-300.913635,-0.003199,0.000999,0.025383,17.645601,0.898910,0.253830,-300.913635,0.026233,0.000000
26.510002,3.971359,-300.958130,-0.003169,0.001024,0.026017,17.665487,0.899923,0.260166,-300.958130,0.026892,0.000000
26.910002,3.995934,-300.958130,-0.003152,0.001046,0.026563,17.774799,0.905492,0.265631,-300.958130,0.027560,0.000000
27.310001,4.140785,-301.047089,-0.003117,0.001072,0.027222,18.419132,0.938315,0.272217,-301.047089,0.028228,0.000000
27.710001,4.260315,-301.091553,-0.003109,0.001100,0.027933,18.950827,0.965401,0.279333,-301.091553,0.028895,0.000000
28.110001,4.323250,-301.002594,-0.003061,0.001126,0.028592,19.230776,0.979662,0.285919,-301.002594,0.029563,0.000000
28.510002,4.399956,-301.047089,-0.003044,0.001153,0.029277,19.571981,0.997044,0.292769,-301.047089,0.030231,0.000000
28.910002,4.532524,-301.136047,-0.003018,0.001179,0.029936,20.161674,1.027085,0.299362,-301.136047,0.030899,0.000000
29.310001,4.459908,-301.180511,-0.002984,0.001198,0.030440,19.838659,1.010630,0.304396,-301.180511,0.031567,0.000000
29.710001,4.684822,-301.269470,-0.002958,0.001230,0.031246,20.839128,1.061596,0.312458,-301.269470,0.032234,0.000000
30.110001,4.790947,-301.269470,-0.002923,0.001256,0.031913,21.311197,1.085644,0.319135,-301.269470,0.032894,0.000000
30.510002,4.940643,-301.313965,-0.002906,0.001285,0.032633,21.977079,1.119566,0.326334,-301.313965,0.033561,0.000000
30.910002,5.005806,-301.225006,-0.002889,0.001312,0.033328,22.266937,1.134332,0.333275,-301.225006,0.034229,0.000000
31.310001,4.968941,-301.269470,-0.002863,0.001331,0.033804,22.102953,1.125978,0.338044,-301.269470,0.034897,0.000000
31.710001,5.262741,-301.358429,-0.002833,0.001362,0.034593,23.409842,1.192554,0.345932,-301.358429,0.035564,0.000000
32.110001,5.290672,-301.358429,-0.002807,0.001387,0.035227,23.534086,1.198884,0.352268,-301.358429,0.036232,0.000000
32.510002,5.477600,-301.358429,-0.002777,0.001416,0.035972,24.365582,1.241242,0.359724,-301.358429,0.036900,0.000000
32.910000,5.548355,-301.402924,-0.002755,0.001442,0.036623,24.680317,1.257275,0.366226,-301.402924,0.037568,0.000000
33.310001,5.572929,-301.402924,-0.002738,0.001462,0.037143,24.789627,1.262844,0.371427,-301.402924,0.038227,0.000000
33.710003,5.757629,-301.491882,-0.002712,0.001489,0.037828,25.611216,1.304698,0.378278,-301.491882,0.038895,0.000000
34.110001,5.830612,-301.447418,-0.002682,0.001515,0.038487,25.935858,1.321236,0.384871,-301.447418,0.039563,0.000000
34.510002,5.968018,-301.491882,-0.002643,0.001545,0.039233,26.547068,1.352372,0.392327,-301.491882,0.040230,0.000000
34.910000,6.030205,-301.536377,-0.002621,0.001568,0.039831,26.823690,1.366464,0.398315,-301.536377,0.040898,0.000000
35.310001,6.275970,-301.491882,-0.002613,0.001594,0.040491,27.916910,1.422155,0.404908,-301.491882,0.041566,0.000000
35.710003,6.345230,-301.580841,-0.002574,0.001620,0.041158,28.224993,1.437850,0.411585,-301.580841,0.042233,0.000000
36.110001,6.667336,-301.625336,-0.002535,0.001654,0.041999,29.657789,1.510840,0.419995,-301.625336,0.042901,0.000000
36.510002,6.677757,-301.625336,-0.002518,0.001677,0.042597,29.704147,1.513201,0.425975,-301.625336,0.043560,0.000000
36.910000,6.720955,-301.625336,-0.002496,0.001700,0.043187,29.896301,1.522990,0.431872,-301.625336,0.044228,0.000000
37.310001,6.925011,-301.714294,-0.002471,0.001727,0.043856,30.803986,1.569230,0.438556,-301.714294,0.044896,0.000000
37.710003,7.244141,-301.758759,-0.002440,0.001759,0.044671,32.223545,1.641546,0.446708,-301.758759,0.045564,0.000000
38.110001,7.280632,-301.714294,-0.002406,0.001783,0.045286,32.385868,1.649815,0.452863,-301.714294,0.046232,0.000000
38.510002,7.421013,-301.714294,-0.002410,0.001806,0.045868,33.010315,1.681625,0.458676,-301.714294,0.046899,0.000000
38.910004,7.581505,-301.758759,-0.002363,0.001831,0.046500,33.724216,1.717993,0.465005,-301.758759,0.047567,0.000000
39.310001,7.676834,-301.803253,-0.002337,0.001854,0.047081,34.148262,1.739595,0.470811,-301.803253,0.048235,0.000000
39.710003,8.142296,-301.803253,-0.002328,0.001887,0.047940,36.218742,1.845071,0.479402,-301.803253,0.048894,0.000000
40.110001,8.199272,-301.847748,-0.002289,0.001913,0.048599,36.472183,1.857982,0.485988,-301.847748,0.049562,0.000000
40.510002,8.261459,-301.892212,-0.002272,0.001935,0.049154,36.748806,1.872073,0.491537,-301.892212,0.050229,0.000000
40.910004,8.538506,-301.892212,-0.002229,0.001961,0.049822,37.981171,1.934853,0.498221,-301.892212,0.050897,0.000000
41.310001,8.679260,-301.981171,-0.002220,0.001983,0.050360,38.607277,1.966748,0.503595,-301.981171,0.051565,0.000000
41.710003,8.858002,-301.936707,-0.002177,0.002012,0.051097,39.402359,2.007252,0.510968,-301.936707,0.052233,0.000000
42.110001,9.212502,-301.981171,-0.002151,0.002044,0.051912,40.979252,2.087583,0.519121,-301.981171,0.052901,0.000000
42.510002,9.383415,-302.070129,-0.002143,0.002071,0.052597,41.739517,2.126312,0.525972,-302.070129,0.053568,0.000000
42.910004,9.723396,-302.070129,-0.002104,0.002098,0.053300,43.251827,2.203353,0.532996,-302.070129,0.054236,0.000000
43.310001,9.918518,-302.114624,-0.002070,0.002122,0.053898,44.119770,2.247568,0.538977,-302.114624,0.054895,0.000000
43.710003,10.241737,-302.070129,-0.002057,0.002151,0.054635,45.557522,2.320811,0.546350,-302.070129,0.055563,0.000000
44.110001,10.303925,-302.159088,-0.002035,0.002173,0.055199,45.834145,2.334903,0.551989,-302.159088,0.056231,0.000000
44.510002,10.640549,-302.203583,-0.001988,0.002198,0.055832,47.331524,2.411183,0.558317,-302.203583,0.056898,0.000000
44.910004,10.804764,-302.203583,-0.001979,0.002221,0.056404,48.061989,2.448395,0.564040,-302.203583,0.057566,0.000000
45.310001,11.349915,-302.203583,-0.001962,0.002252,0.057210,50.486942,2.571927,0.572102,-302.203583,0.058234,0.000000
45.710003,11.752823,-302.248077,-0.001923,0.002276,0.057817,52.279167,2.663228,0.578173,-302.248077,0.058901,0.000000
46.110001,11.899910,-302.203583,-0.001901,0.002302,0.058477,52.933445,2.696558,0.584766,-302.203583,0.059570,0.000000
46.510002,12.287178,-302.292542,-0.001888,0.002324,0.059031,54.656097,2.784314,0.590315,-302.292542,0.060228,0.000000
46.910004,12.898613,-302.337036,-0.001863,0.002357,0.059864,57.375896,2.922868,0.598642,-302.337036,0.060896,0.000000
47.310001,13.412117,-302.425995,-0.001819,0.002389,0.060689,59.660076,3.039229,0.606885,-302.425995,0.061564,0.000000
47.710003,13.612823,-302.337036,-0.001815,0.002417,0.061382,60.552864,3.084710,0.613819,-302.337036,0.062232,0.000000
48.110001,13.569626,-302.337036,-0.001776,0.002436,0.061876,60.360710,3.074921,0.618762,-302.337036,0.062900,0.000000
48.510002,13.814651,-302.381500,-0.001763,0.002463,0.062570,61.450638,3.130445,0.625704,-302.381500,0.063567,0.000000
48.910004,14.721748,-302.425995,-0.001729,0.002488,0.063203,65.485611,3.335996,0.632032,-302.425995,0.064235,0.000000
49.310001,15.455322,-302.425995,-0.001703,0.002522,0.064053,68.748711,3.502226,0.640533,-302.425995,0.064903,0.000000
49.710003,15.634804,-302.514954,-0.001681,0.002543,0.064599,69.547081,3.542897,0.645991,-302.514954,0.065562,0.000000
50.110001,16.240280,-302.559418,-0.001660,0.002571,0.065293,72.240372,3.680100,0.652932,-302.559418,0.066230,0.000000
50.510002,16.415298,-302.559418,-0.001630,0.002592,0.065840,73.018898,3.719760,0.658398,-302.559418,0.066897,0.000000
50.910004,16.769798,-302.559418,-0.001604,0.002617,0.066473,74.595787,3.800091,0.664726,-302.559418,0.067565,0.000000
51.310001,17.835152,-302.648376,-0.001587,0.002649,0.067279,79.334717,4.041503,0.672788,-302.648376,0.068233,0.000000
51.710003,18.289078,-302.559418,-0.001574,0.002675,0.067947,81.353882,4.144364,0.679472,-302.559418,0.068901,0.000000
52.110001,18.835716,-302.692871,-0.001552,0.002701,0.068606,83.785454,4.268234,0.686058,-302.692871,0.069569,0.000000
52.510002,18.993607,-302.603912,-0.001518,0.002723,0.069161,84.487785,4.304013,0.691606,-302.603912,0.070236,0.000000
52.910004,20.225410,-302.692871,-0.001509,0.002754,0.069950,89.967117,4.583144,0.699502,-302.692871,0.070896,0.000000
53.310001,20.582146,-302.737366,-0.001479,0.002776,0.070522,91.553955,4.663981,0.705224,-302.737366,0.071563,0.000000
53.710003,21.078888,-302.737366,-0.001449,0.002806,0.071277,93.763573,4.776544,0.712771,-302.737366,0.072231,0.000000
54.110004,21.861618,-302.781830,-0.001431,0.002827,0.071815,97.245331,4.953914,0.718146,-302.781830,0.072899,0.000000
54.510002,22.603386,-302.826324,-0.001414,0.002856,0.072534,100.544884,5.122000,0.725345,-302.826324,0.073566,0.000000
54.910004,23.301582,-302.826324,-0.001401,0.002881,0.073176,103.650612,5.280214,0.731764,-302.826324,0.074234,0.000000
55.310001,24.155060,-302.870789,-0.001367,0.002907,0.073835,107.447075,5.473615,0.738350,-302.870789,0.074902,0.000000
55.710003,25.182434,-302.915283,-0.001358,0.002938,0.074615,112.017059,5.706421,0.746154,-302.915283,0.075570,0.000000
56.110004,26.100334,-302.959747,-0.001315,0.002965,0.075310,116.100082,5.914421,0.753096,-302.959747,0.076229,0.000000
56.510002,26.188957,-302.915283,-0.001306,0.002984,0.075786,116.494301,5.934502,0.757865,-302.915283,0.076897,0.000000
56.910004,27.657227,-302.959747,-0.001289,0.003013,0.076532,123.025490,6.267217,0.765321,-302.959747,0.077565,0.000000
57.310001,28.804504,-303.048706,-0.001263,0.003043,0.077287,128.128830,6.527194,0.772868,-303.048706,0.078232,0.000000
57.710003,29.411095,-303.004242,-0.001246,0.003068,0.077929,130.827087,6.664649,0.779287,-303.004242,0.078900,0.000000
58.110004,30.725571,-303.048706,-0.001229,0.003098,0.078683,136.674164,6.962513,0.786834,-303.048706,0.079568,0.000000
58.510002,30.890533,-303.048706,-0.001207,0.003117,0.079160,137.407959,6.999895,0.791603,-303.048706,0.080235,0.000000
58.910004,32.749786,-303.093201,-0.001186,0.003150,0.080001,145.678329,7.421208,0.800013,-303.093201,0.080903,0.000000
59.310001,33.304626,-303.137695,-0.001181,0.003170,0.080513,148.146378,7.546937,0.805130,-303.137695,0.081571,0.000000
59.710003,34.341309,-303.137695,-0.001151,0.003196,0.081172,152.757767,7.781852,0.811724,-303.137695,0.082230,0.000000
60.110004,35.496780,-303.182159,-0.001160,0.003221,0.081805,157.897568,8.043686,0.818052,-303.182159,0.082898,0.000000
60.510002,36.717789,-303.226654,-0.001125,0.003248,0.082499,163.328888,8.320370,0.824986,-303.226654,0.083565,0.000000
60.910004,38.301491,-303.271118,-0.001108,0.003277,0.083236,170.373535,8.679242,0.832359,-303.271118,0.084234,0.000000
61.310001,39.513191,-303.360077,-0.001099,0.003303,0.083886,175.763458,8.953817,0.838861,-303.360077,0.084901,0.000000
61.710003,40.342461,-303.315613,-0.001065,0.003327,0.084511,179.452225,9.141732,0.845106,-303.315613,0.085569,0.000000
62.110004,41.625290,-303.315613,-0.001061,0.003349,0.085075,185.158539,9.432426,0.850746,-303.315613,0.086237,0.000000
62.510002,43.007164,-303.360077,-0.001048,0.003378,0.085803,191.305420,9.745564,0.858028,-303.360077,0.086904,0.000000
62.910004,45.119255,-303.404572,-0.001030,0.003409,0.086583,200.700470,10.224169,0.865833,-303.404572,0.087564,0.000000
63.310001,46.123177,-303.404572,-0.001005,0.003434,0.087225,205.166138,10.451661,0.872252,-303.404572,0.088231,0.000000
63.710003,46.891747,-303.449036,-0.000996,0.003458,0.087824,208.584900,10.625821,0.878239,-303.449036,0.088899,0.000000
64.110001,49.230621,-303.493530,-0.000983,0.003488,0.088595,218.988739,11.155818,0.885953,-303.493530,0.089567,0.000000
64.510002,50.752136,-303.538025,-0.000970,0.003515,0.089272,225.756775,11.500598,0.892720,-303.538025,0.090234,0.000000
64.910004,51.490921,-303.538025,-0.000961,0.003531,0.089679,229.043060,11.668010,0.896793,-303.538025,0.090903,0.000000
65.310005,53.626480,-303.538025,-0.000949,0.003564,0.090529,238.542496,12.151935,0.905294,-303.538025,0.091570,0.000000
65.710007,55.708786,-303.582489,-0.000927,0.003594,0.091292,247.805054,12.623791,0.912924,-303.582489,0.092238,0.000000
66.110001,56.804306,-303.582489,-0.000923,0.003616,0.091839,252.678177,12.872040,0.918390,-303.582489,0.092897,0.000000
66.510002,58.373856,-303.626984,-0.000910,0.003639,0.092429,259.659882,13.227704,0.924286,-303.626984,0.093565,0.000000
66.910004,59.737854,-303.671448,-0.000897,0.003661,0.092984,265.727234,13.536791,0.929835,-303.671448,0.094233,0.000000
67.310005,61.821281,-303.671448,-0.000884,0.003691,0.093756,274.994781,14.008903,0.937556,-303.671448,0.094900,0.000000
67.710007,62.892593,-303.760406,-0.000871,0.003708,0.094180,279.760223,14.251665,0.941803,-303.760406,0.095568,0.000000
68.110001,65.928177,-303.760406,-0.000862,0.003746,0.095143,293.263184,14.939538,0.951432,-303.760406,0.096235,0.000000
68.510002,65.445206,-303.760406,-0.000849,0.003739,0.094970,291.114807,14.830095,0.949698,-303.760406,0.016677,0.000000
68.910004,64.604385,-303.804901,-0.000841,0.003739,0.094961,287.374664,14.639563,0.949607,-303.804901,294.500519,0.000000
69.310005,66.101334,-303.849365,-0.000828,0.003712,0.094293,294.033417,14.978777,0.942931,-303.849365,294.500519,0.000000
69.710007,65.452286,-303.849365,-0.000811,0.003714,0.094328,291.146301,14.831700,0.943279,-303.849365,294.500519,0.000000
70.110001,65.172256,-303.893860,-0.000823,0.003757,0.095420,289.900665,14.768245,0.954202,-303.893860,294.500519,0.000000
70.510002,65.262375,-303.938324,-0.000823,0.003767,0.095672,290.301544,14.788666,0.956723,-303.938324,294.500519,0.000000
70.910004,65.133530,-303.938324,-0.000811,0.003774,0.095871,289.728424,14.759469,0.958714,-303.938324,294.500519,0.000000
71.310005,65.572189,-303.938324,-0.000806,0.003776,0.095915,291.679657,14.858871,0.959145,-303.938324,294.500519,0.000000
71.710007,65.317490,-304.027313,-0.000815,0.003777,0.095924,290.546692,14.801155,0.959236,-304.027313,294.500519,0.000000
72.110001,65.084000,-304.027313,-0.000793,0.003777,0.095924,289.508087,14.748245,0.959236,-304.027313,294.500519,0.000000
72.510002,66.033554,-304.071777,-0.000802,0.003785,0.096149,293.731934,14.963417,0.961492,-304.071777,294.500519,0.000000
72.910004,65.773270,-304.116272,-0.000793,0.003785,0.096149,292.574127,14.904435,0.961492,-304.116272,294.500519,0.000000
73.310005,65.542770,-304.160736,-0.000798,0.003785,0.096149,291.548798,14.852203,0.961492,-304.160736,294.500519,0.000000
73.710007,65.314133,-304.116272,-0.000789,0.003785,0.096149,290.531769,14.800394,0.961492,-304.116272,294.500519,0.000000
74.110001,65.086990,-304.116272,-0.000785,0.003786,0.096158,289.521393,14.748923,0.961575,-304.116272,294.500519,0.000000
74.510002,64.927231,-304.205231,-0.000798,0.003786,0.096158,288.810760,14.712721,0.961575,-304.205231,294.500519,0.000000
74.910004,64.745895,-304.249695,-0.000789,0.003786,0.096158,288.004120,14.671630,0.961575,-304.249695,294.500519,0.000000
75.310005,64.586884,-304.294189,-0.000780,0.003786,0.096158,287.296814,14.635596,0.961575,-304.294189,294.500519,0.000000
75.710007,64.442413,-304.294189,-0.000793,0.003786,0.096167,286.654175,14.602859,0.961666,-304.294189,294.500519,0.000000
76.110001,66.418961,-304.338654,-0.000767,0.003603,0.091518,295.446289,15.050752,0.915180,-304.338654,294.500519,0.000000
76.510002,66.320648,-304.294189,-0.000763,0.003603,0.091526,295.008972,15.028474,0.915263,-304.294189,294.500519,0.000000
76.910004,66.158676,-304.383148,-0.000767,0.003603,0.091526,294.288483,14.991771,0.915263,-304.383148,294.500519,0.000000
77.310005,66.009354,-304.472107,-0.000763,0.003603,0.091526,293.624268,14.957933,0.915263,-304.472107,294.500519,0.000000
77.710007,65.893539,-304.516602,-0.000767,0.003608,0.091631,293.109100,14.931690,0.916308,-304.516602,294.500519,0.000000
78.110001,65.757629,-304.472107,-0.000763,0.003647,0.092645,292.504547,14.900892,0.926451,-304.472107,294.500519,0.000000
78.510002,65.615005,-304.472107,-0.000763,0.003659,0.092949,291.870117,14.868573,0.929487,-304.472107,294.500519,0.000000
78.910004,65.526016,-304.516602,-0.000759,0.003660,0.092975,291.474274,14.848407,0.929752,-304.516602,294.500519,0.000000
79.310005,65.388977,-304.561066,-0.000767,0.003731,0.094779,290.864685,14.817353,0.947791,-304.561066,294.500519,0.000000
79.710007,65.437012,-304.561066,-0.000767,0.003778,0.095949,291.078369,14.828238,0.959494,-304.561066,294.500519,0.000000
80.110001,65.315994,-304.650024,-0.000767,0.003778,0.095958,290.540039,14.800816,0.959584,-304.650024,294.500519,0.000000
80.510002,65.235184,-304.650024,-0.000776,0.003779,0.095976,290.180603,14.782503,0.959759,-304.650024,294.500519,0.000000
80.910004,65.136505,-304.694519,-0.000759,0.003779,0.095976,289.741638,14.760143,0.959759,-304.694519,294.500519,0.000000
81.310005,65.358078,-304.694519,-0.000767,0.003801,0.096539,290.727264,14.810352,0.965390,-304.694519,294.500519,0.000000
81.710007,65.372589,-304.650024,-0.000763,0.003803,0.096600,290.791809,14.813641,0.965996,-304.650024,294.500519,0.000000
82.110001,65.341690,-304.738983,-0.000767,0.003804,0.096617,290.654358,14.806639,0.966170,-304.738983,294.500519,0.000000
82.510002,65.278763,-304.783478,-0.000767,0.003805,0.096634,290.374451,14.792378,0.966344,-304.783478,294.500519,0.000000
82.910004,65.375946,-304.738983,-0.000776,0.003809,0.096739,290.806732,14.814402,0.967389,-304.738983,294.500519,0.000000
83.310005,65.366638,-304.872437,-0.000776,0.003809,0.096739,290.765320,14.812292,0.967389,-304.872437,294.500519,0.000000
83.710007,65.332001,-304.916931,-0.000763,0.003809,0.096756,290.611267,14.804443,0.967563,-304.916931,294.500519,0.000000
84.110001,65.313766,-304.872437,-0.000763,0.003810,0.096782,290.530151,14.800311,0.967820,-304.872437,294.500519,0.000000
84.510002,65.359192,-304.961395,-0.000767,0.003811,0.096808,290.732208,14.810605,0.968078,-304.961395,294.500519,0.000000
84.910004,65.348389,-304.916931,-0.000759,0.003812,0.096817,290.684143,14.808156,0.968169,-304.916931,294.500519,0.000000
85.310005,65.364029,-304.961395,-0.000767,0.003814,0.096869,290.753723,14.811701,0.968691,-304.961395,294.500519,0.000000
85.710007,65.389359,-304.961395,-0.000763,0.003814,0.096869,290.866394,14.817441,0.968691,-304.961395,294.500519,0.000000
86.110001,65.384506,-305.050354,-0.000772,0.003814,0.096877,290.844818,14.816340,0.968774,-305.050354,294.500519,0.000000
86.510002,65.369247,-305.094849,-0.000767,0.003814,0.096877,290.776947,14.812883,0.968774,-305.094849,294.500519,0.000000
86.910004,65.348389,-305.050354,-0.000759,0.003814,0.096886,290.684143,14.808156,0.968865,-305.050354,294.500519,0.000000
87.310005,65.305939,-305.050354,-0.000763,0.003815,0.096895,290.495331,14.798536,0.968948,-305.050354,294.500519,0.000000
87.710007,65.352112,-305.094849,-0.000772,0.003816,0.096930,290.700714,14.809001,0.969296,-305.094849,294.500519,0.000000
88.110001,65.373718,-305.139313,-0.000767,0.003817,0.096955,290.796814,14.813896,0.969554,-305.139313,294.500519,0.000000
88.510002,65.381531,-305.228271,-0.000759,0.003817,0.096964,290.831573,14.815667,0.969645,-305.228271,294.500519,0.000000
88.910004,65.393448,-305.228271,-0.000767,0.003817,0.096964,290.884583,14.818367,0.969645,-305.228271,294.500519,0.000000
89.310005,65.390091,-305.183807,-0.000767,0.003818,0.096982,290.869659,14.817606,0.969819,-305.183807,294.500519,0.000000
89.710007,65.397537,-305.272766,-0.000780,0.003819,0.096990,290.902771,14.819294,0.969902,-305.272766,294.500519,0.000000
90.110001,65.367004,-305.228271,-0.000763,0.003819,0.096990,290.766968,14.812375,0.969902,-305.228271,294.500519,0.000000
90.510002,65.355087,-305.317261,-0.000767,0.003819,0.096990,290.713959,14.809674,0.969902,-305.317261,294.500519,0.000000
90.910004,65.305939,-305.317261,-0.000767,0.003819,0.096999,290.495331,14.798536,0.969985,-305.317261,294.500519,0.000000
91.310005,65.302597,-305.361725,-0.000763,0.003819,0.097008,290.480469,14.797780,0.970076,-305.361725,294.500519,0.000000
91.710007,65.295517,-305.406219,-0.000759,0.003820,0.097016,290.448975,14.796175,0.970159,-305.406219,294.500519,0.000000
92.110001,65.281357,-305.406219,-0.000755,0.003821,0.097042,290.385986,14.792967,0.970424,-305.406219,294.500519,0.000000
92.510002,65.317856,-305.361725,-0.000767,0.003821,0.097051,290.548340,14.801237,0.970508,-305.361725,294.500519,0.000000
92.910004,65.312271,-305.450684,-0.000763,0.003821,0.097060,290.523499,14.799972,0.970598,-305.450684,294.500519,0.000000
93.310005,65.311157,-305.495178,-0.000772,0.003821,0.097060,290.518524,14.799720,0.970598,-305.495178,294.500519,0.000000
93.710007,65.292542,-305.495178,-0.000759,0.003822,0.097068,290.435730,14.795502,0.970682,-305.495178,294.500519,0.000000
94.110008,65.267593,-305.539642,-0.000759,0.003822,0.097068,290.324768,14.789847,0.970682,-305.539642,294.500519,0.000000
94.510002,65.291794,-305.539642,-0.000776,0.003823,0.097094,290.432404,14.795332,0.970939,-305.539642,294.500519,0.000000
94.910004,65.292542,-305.584137,-0.000767,0.003823,0.097094,290.435730,14.795502,0.970939,-305.584137,294.500519,0.000000
95.310005,65.273544,-305.584137,-0.000759,0.003823,0.097094,290.351227,14.791197,0.970939,-305.584137,294.500519,0.000000
95.710007,65.380035,-305.628601,-0.000750,0.003826,0.097173,290.824921,14.815328,0.971726,-305.628601,294.500519,0.000000
96.110008,65.469406,-305.673096,-0.000776,0.003826,0.097173,291.222473,14.835580,0.971726,-305.673096,294.500519,0.000000
96.510002,65.494354,-305.673096,-0.000755,0.003826,0.097173,291.333435,14.841232,0.971726,-305.673096,294.500519,0.000000
96.910004,65.460098,-305.717590,-0.000759,0.003826,0.097173,291.181061,14.833470,0.971726,-305.717590,294.500519,0.000000
97.310005,65.441483,-305.762054,-0.000759,0.003826,0.097173,291.098267,14.829251,0.971726,-305.762054,294.500519,0.000000
97.710007,65.396805,-305.806549,-0.000759,0.003826,0.097173,290.899506,14.819127,0.971726,-305.806549,294.500519,0.000000
98.110008,65.375946,-305.851013,-0.000759,0.003826,0.097173,290.806732,14.814402,0.971726,-305.851013,294.500519,0.000000
98.510002,65.352112,-305.851013,-0.000767,0.003826,0.097173,290.700714,14.809001,0.971726,-305.851013,294.500519,0.000000
98.910004,65.317108,-305.851013,-0.000755,0.003826,0.097181,290.545013,14.801068,0.971810,-305.851013,294.500519,0.000000
99.310005,65.302597,-305.895508,-0.000750,0.003826,0.097181,290.480469,14.797780,0.971810,-305.895508,294.500519,0.000000
99.710007,65.296265,-305.939972,-0.000759,0.003826,0.097190,290.452301,14.796345,0.971900,-305.939972,294.500519,0.000000
100.110008,65.268707,-305.984467,-0.000767,0.003826,0.097190,290.329712,14.790100,0.971900,-305.984467,294.500519,0.000000
100.510002,65.278763,-305.939972,-0.000767,0.003827,0.097198,290.374451,14.792378,0.971984,-305.939972,294.500519,0.000000
100.910004,65.323074,-306.028931,-0.000772,0.003828,0.097242,290.571533,14.802421,0.972415,-306.028931,294.500519,0.000000
101.310005,65.332748,-306.028931,-0.000759,0.003828,0.097242,290.614594,14.804612,0.972415,-306.028931,294.500519,0.000000
101.710007,65.330887,-306.117920,-0.000755,0.003828,0.097242,290.606293,14.804191,0.972415,-306.117920,294.500519,0.000000
102.110008,65.325684,-306.117920,-0.000763,0.003828,0.097242,290.583160,14.803011,0.972415,-306.117920,294.500519,0.000000
102.510002,65.315247,-306.073425,-0.000763,0.003828,0.097242,290.536713,14.800647,0.972415,-306.073425,294.500519,0.000000
102.910004,65.282104,-306.117920,-0.000763,0.003828,0.097242,290.389313,14.793136,0.972415,-306.117920,294.500519,0.000000
103.310005,65.280624,-306.206879,-0.000772,0.003828,0.097242,290.382721,14.792801,0.972415,-306.206879,294.500519,0.000000
103.710007,65.255295,-306.162384,-0.000763,0.003829,0.097251,290.270050,14.787061,0.972506,-306.162384,294.500519,0.000000
104.110008,65.239288,-306.206879,-0.000759,0.003829,0.097251,290.198853,14.783434,0.972506,-306.206879,294.500519,0.000000
104.510002,65.226257,-306.251343,-0.000767,0.003829,0.097259,290.140869,14.780481,0.972589,-306.251343,294.500519,0.000000
104.910004,65.222153,-306.384796,-0.000763,0.003829,0.097259,290.122620,14.779552,0.972589,-306.384796,294.500519,0.000000
105.310005,65.218063,-306.340302,-0.000759,0.003829,0.097268,290.104431,14.778625,0.972680,-306.340302,294.500519,0.000000
105.710007,65.269821,-306.384796,-0.000767,0.003831,0.097319,290.334656,14.790353,0.973195,-306.384796,294.500519,0.000000
106.110008,65.293655,-306.295837,-0.000767,0.003831,0.097319,290.440674,14.795754,0.973195,-306.295837,294.500519,0.000000
106.510002,65.299606,-306.340302,-0.000759,0.003831,0.097319,290.467163,14.797102,0.973195,-306.340302,294.500519,0.000000
106.910004,65.298492,-306.384796,-0.000763,0.003831,0.097319,290.462189,14.796850,0.973195,-306.384796,294.500519,0.000000
107.310005,65.280624,-306.473755,-0.000759,0.003831,0.097319,290.382721,14.792801,0.973195,-306.473755,294.500519,0.000000
107.710007,65.286209,-306.429260,-0.000755,0.003831,0.097319,290.407562,14.794066,0.973195,-306.429260,294.500519,0.000000
108.110008,65.268326,-306.429260,-0.000767,0.003831,0.097319,290.328003,14.790014,0.973195,-306.429260,294.500519,0.000000
108.510002,65.253433,-306.473755,-0.000759,0.003831,0.097319,290.261780,14.786639,0.973195,-306.473755,294.500519,0.000000
108.910004,65.252686,-306.518219,-0.000759,0.003831,0.097319,290.258453,14.786469,0.973195,-306.518219,294.500519,0.000000
109.310005,65.249710,-306.607208,-0.000755,0.003832,0.097329,290.245209,14.785795,0.973286,-306.607208,294.500519,0.000000
109.710007,65.249344,-306.562714,-0.000755,0.003832,0.097329,290.243591,14.785712,0.973286,-306.562714,294.500519,0.000000
110.110008,65.211731,-306.607208,-0.000750,0.003832,0.097329,290.076263,14.777190,0.973286,-306.607208,294.500519,0.000000
110.510002,65.203171,-306.651672,-0.000755,0.003832,0.097329,290.038177,14.775249,0.973286,-306.651672,294.500519,0.000000
110.910004,65.189011,-306.651672,-0.000759,0.003832,0.097337,289.975189,14.772040,0.973369,-306.651672,294.500519,0.000000
111.310005,65.196091,-306.651672,-0.000763,0.003832,0.097337,290.006683,14.773645,0.973369,-306.651672,294.500519,0.000000
111.710007,65.184921,-306.785126,-0.000776,0.003833,0.097363,289.957001,14.771114,0.973634,-306.785126,294.500519,0.000000
112.110008,65.215088,-306.740631,-0.000763,0.003833,0.097363,290.091187,14.777950,0.973634,-306.740631,294.500519,0.000000
112.510002,65.197952,-306.829590,-0.000750,0.003833,0.097363,290.014984,14.774067,0.973634,-306.829590,294.500519,0.000000
112.910004,65.199448,-306.829590,-0.000759,0.003833,0.097363,290.021637,14.774406,0.973634,-306.829590,294.500519,0.000000
113.310005,65.173370,-306.785126,-0.000763,0.003833,0.097363,289.905640,14.768497,0.973634,-306.785126,294.500519,0.000000
113.710007,65.166306,-306.874084,-0.000759,0.003833,0.097363,289.874207,14.766895,0.973634,-306.874084,294.500519,0.000000
114.110008,65.144699,-306.829590,-0.000767,0.003834,0.097372,289.778107,14.762000,0.973717,-306.829590,294.500519,0.000000
114.510002,65.520050,-306.918549,-0.000750,0.003839,0.097510,291.447723,14.847055,0.975102,-306.918549,294.500519,0.000000
114.910004,65.588196,-306.918549,-0.000763,0.003839,0.097510,291.750854,14.862498,0.975102,-306.918549,294.500519,0.000000
115.310005,65.600113,-306.963043,-0.000755,0.003839,0.097510,291.803864,14.865198,0.975102,-306.963043,294.500519,0.000000
115.710007,65.603088,-306.963043,-0.000755,0.003839,0.097510,291.817108,14.865872,0.975102,-306.963043,294.500519,0.000000
116.110008,65.598999,-307.007538,-0.000755,0.003839,0.097510,291.798920,14.864945,0.975102,-307.007538,294.500519,0.000000
116.510002,65.607559,-307.096497,-0.000767,0.003839,0.097510,291.837006,14.866885,0.975102,-307.096497,294.500519,0.000000
116.910004,65.587448,-307.052002,-0.000759,0.003839,0.097510,291.747528,14.862329,0.975102,-307.052002,294.500519,0.000000
117.310005,65.583359,-307.096497,-0.000772,0.003839,0.097510,291.729340,14.861402,0.975102,-307.096497,294.500519,0.000000
117.710007,65.573303,-307.140961,-0.000755,0.003839,0.097510,291.684631,14.859122,0.975102,-307.140961,294.500519,0.000000
118.110008,65.577408,-307.140961,-0.000759,0.003839,0.097510,291.702881,14.860053,0.975102,-307.140961,294.500519,0.000000
118.510002,65.579269,-307.185455,-0.000772,0.003839,0.097510,291.711151,14.860475,0.975102,-307.185455,294.500519,0.000000
118.910004,65.556549,-307.185455,-0.000763,0.003839,0.097510,291.610107,14.855327,0.975102,-307.185455,294.500519,0.000000
119.310005,65.553192,-307.185455,-0.000759,0.003839,0.097510,291.595154,14.854566,0.975102,-307.185455,294.500519,0.000000
119.710007,65.544632,-307.229919,-0.000750,0.003839,0.097510,291.557098,14.852626,0.975102,-307.229919,294.500519,0.000000
120.110008,65.518936,-307.274414,-0.000763,0.003839,0.097510,291.442780,14.846803,0.975102,-307.274414,294.500519,0.000000
120.510002,65.517441,-307.318878,-0.000750,0.003839,0.097510,291.436127,14.846464,0.975102,-307.318878,294.500519,0.000000
120.910004,65.514099,-307.318878,-0.000746,0.003839,0.097510,291.421265,14.845707,0.975102,-307.318878,294.500519,0.000000
121.310005,65.492126,-307.363373,-0.000759,0.003839,0.097510,291.323517,14.840728,0.975102,-307.363373,294.500519,0.000000
121.710007,65.469040,-307.452332,-0.000750,0.003839,0.097510,291.220825,14.835497,0.975102,-307.452332,294.500519,0.000000
122.110008,65.447449,-307.407867,-0.000755,0.003839,0.097510,291.124786,14.830605,0.975102,-307.407867,294.500519,0.000000
122.510002,65.409836,-307.452332,-0.000746,0.003839,0.097510,290.957489,14.822081,0.975102,-307.452332,294.500519,0.000000
122.910004,65.404999,-307.452332,-0.000746,0.003839,0.097510,290.935974,14.820985,0.975102,-307.452332,294.500519,0.000000
123.310005,65.393082,-307.496826,-0.000755,0.003839,0.097510,290.882965,14.818284,0.975102,-307.496826,294.500519,0.000000
123.710007,65.382278,-307.496826,-0.000755,0.003839,0.097510,290.834900,14.815836,0.975102,-307.496826,294.500519,0.000000
124.110008,65.354355,-307.452332,-0.000746,0.003839,0.097510,290.710693,14.809509,0.975102,-307.452332,294.500519,0.000000
124.510002,65.342056,-307.585785,-0.000750,0.003839,0.097519,290.655975,14.806722,0.975193,-307.585785,294.500519,0.000000
124.910004,65.324554,-307.541290,-0.000755,0.003839,0.097519,290.578125,14.802755,0.975193,-307.541290,294.500519,0.000000
125.310005,65.311157,-307.630249,-0.000746,0.003839,0.097519,290.518524,14.799720,0.975193,-307.630249,294.500519,0.000000
125.710007,65.305573,-307.630249,-0.000772,0.003839,0.097519,290.493683,14.798454,0.975193,-307.630249,294.500519,0.000000
126.110008,65.292908,-307.630249,-0.000759,0.003839,0.097519,290.437347,14.795585,0.975193,-307.630249,294.500519,0.000000
126.510010,65.281357,-307.674744,-0.000763,0.003839,0.097519,290.385986,14.792967,0.975193,-307.674744,294.500519,0.000000
126.910004,65.272797,-307.763702,-0.000763,0.003839,0.097519,290.347900,14.791027,0.975193,-307.763702,294.500519,0.000000
127.310005,65.262375,-307.763702,-0.000746,0.003839,0.097519,290.301544,14.788666,0.975193,-307.763702,294.500519,0.000000
127.710007,65.280243,-307.719208,-0.000750,0.003841,0.097562,290.381012,14.792715,0.975625,-307.719208,294.500519,0.000000
128.110001,65.309296,-307.808167,-0.000755,0.003841,0.097562,290.510254,14.799298,0.975625,-307.808167,294.500519,0.000000
128.510010,65.291412,-307.808167,-0.000755,0.003841,0.097562,290.430695,14.795246,0.975625,-307.808167,294.500519,0.000000
128.910004,65.282104,-307.852661,-0.000755,0.003841,0.097562,290.389313,14.793136,0.975625,-307.852661,1681.641113,0.000000
129.310013,65.256409,-307.852661,-0.000742,0.003827,0.097216,290.274994,14.787313,0.972158,-307.852661,0.097008,0.000000
129.710007,65.240036,-307.897156,-0.000750,0.003810,0.096774,290.202179,14.783604,0.967737,-307.897156,0.096340,0.000000
130.110001,65.148056,-307.986115,-0.000755,0.003786,0.096158,289.793030,14.762760,0.961575,-307.986115,0.095672,0.000000
130.510010,65.114548,-307.986115,-0.000759,0.003758,0.095464,289.643982,14.755167,0.954641,-307.986115,0.095004,0.000000
130.910004,65.101135,-307.986115,-0.000742,0.003737,0.094909,289.584320,14.752128,0.949085,-307.986115,0.094336,0.000000
131.310013,65.072464,-307.986115,-0.000746,0.003709,0.094215,289.456787,14.745631,0.942151,-307.986115,0.093669,0.000000
131.710007,65.059799,-307.986115,-0.000737,0.003687,0.093643,289.400452,14.742761,0.936428,-307.986115,0.093010,0.000000
132.110001,64.987930,-307.986115,-0.000750,0.003657,0.092897,289.080750,14.726475,0.928972,-307.986115,0.092342,0.000000
132.510010,65.006927,-308.075073,-0.000746,0.003633,0.092273,289.165253,14.730780,0.922727,-308.075073,0.091674,0.000000
132.910004,64.855743,-308.075073,-0.000750,0.003613,0.091778,288.492767,14.696522,0.917784,-308.075073,0.091006,0.000000
133.310013,64.171326,-308.164032,-0.000724,0.003588,0.091145,285.448303,14.541430,0.911448,-308.164032,0.090339,0.000000
133.710007,63.239639,-308.164032,-0.000755,0.003564,0.090529,281.303955,14.330307,0.905294,-308.164032,0.089671,0.000000
134.110001,61.826118,-308.119537,-0.000729,0.003538,0.089862,275.016296,14.009998,0.898617,-308.119537,0.089003,0.000000
134.510010,59.965004,-308.208496,-0.000707,0.003511,0.089177,266.737671,13.588264,0.891767,-308.208496,0.088336,0.000000
134.910004,58.098671,-308.208496,-0.000711,0.003485,0.088526,258.435791,13.165347,0.885264,-308.208496,0.087676,0.000000
135.310013,56.190636,-308.252991,-0.000711,0.003462,0.087928,249.948425,12.732980,0.879277,-308.252991,0.087009,0.000000
135.710007,53.941505,-308.297485,-0.000716,0.003439,0.087338,239.943802,12.223320,0.873380,-308.297485,0.086341,0.000000
136.110001,51.497627,-308.297485,-0.000707,0.003412,0.086653,229.072891,11.669529,0.866529,-308.297485,0.085673,0.000000
136.510010,48.765526,-308.341949,-0.000729,0.003387,0.086020,216.919891,11.050426,0.860201,-308.341949,0.085005,0.000000
136.910004,45.734047,-308.386444,-0.000720,0.003360,0.085335,203.435196,10.363483,0.853350,-308.386444,0.084337,0.000000
137.310013,42.698837,-308.341949,-0.000711,0.003332,0.084641,189.933914,9.675694,0.846408,-308.341949,0.083670,0.000000
137.710007,40.102280,-308.430908,-0.000724,0.003309,0.084060,178.383850,9.087307,0.840602,-308.430908,0.083002,0.000000
138.110001,37.154953,-308.430908,-0.000707,0.003280,0.083323,165.273483,8.419433,0.833229,-308.430908,0.082343,0.000000
138.510010,34.259384,-308.430908,-0.000720,0.003258,0.082742,152.393356,7.763287,0.827416,-308.430908,0.081675,0.000000
138.910004,31.059219,-308.475403,-0.000716,0.003228,0.081987,138.158310,7.038119,0.819869,-308.475403,0.081007,0.000000
139.310013,28.126411,-308.519867,-0.000720,0.003201,0.081311,125.112526,6.373536,0.813109,-308.519867,0.080340,0.000000
139.710007,25.807648,-308.564362,-0.000720,0.003182,0.080825,114.798149,5.848097,0.808249,-308.564362,0.079672,0.000000
140.110001,22.586624,-308.564362,-0.000720,0.003149,0.079992,100.470322,5.118202,0.799922,-308.564362,0.079004,0.000000
140.510010,19.816177,-308.608826,-0.000724,0.003127,0.079429,88.146759,4.490410,0.794290,-308.608826,0.078336,0.000000
140.910004,16.313644,-308.608826,-0.000711,0.003095,0.078614,72.566711,3.696725,0.786138,-308.608826,0.077668,0.000000
141.310013,13.664207,-308.653320,-0.000716,0.003069,0.077964,60.781429,3.096354,0.779635,-308.653320,0.077009,0.000000
141.710007,11.419922,-308.653320,-0.000711,0.003053,0.077538,50.798351,2.587791,0.775381,-308.653320,0.076341,0.000000
142.110001,7.728592,-308.697815,-0.000716,0.003017,0.076637,34.378494,1.751324,0.766366,-308.697815,0.075674,0.000000
142.510010,5.353233,-308.742279,-0.000716,0.002995,0.076064,23.812370,1.213060,0.760643,-308.742279,0.075006,0.000000
142.910004,3.260124,-308.742279,-0.000724,0.002978,0.075639,14.501757,0.738755,0.756389,-308.742279,0.074338,0.000000
143.310013,-0.413704,-308.786774,-0.000724,0.002941,0.074694,-1.840247,-0.093747,0.746941,-308.786774,0.073671,0.000000
143.710007,-1.317451,-308.786774,-0.000716,0.002923,0.074234,-5.860317,-0.298539,0.742339,-308.786774,0.073003,0.000000
144.110001,-0.180595,-308.786774,-0.000707,0.002891,0.073419,-0.803328,-0.040924,0.734194,-308.786774,0.072335,0.000000
144.510010,-0.109848,-308.875732,-0.000724,0.002865,0.072777,-0.488628,-0.024892,0.727775,-308.875732,0.071667,0.000000
144.910004,-0.108727,-308.875732,-0.000707,0.002838,0.072083,-0.483640,-0.024638,0.720833,-308.875732,0.071008,0.000000
145.310013,-0.111710,-308.920197,-0.000711,0.002812,0.071433,-0.496909,-0.025314,0.714331,-308.920197,0.070340,0.000000
145.710007,-0.142242,-308.920197,-0.000711,0.002785,0.070748,-0.632726,-0.032233,0.707480,-308.920197,0.069672,0.000000
146.110001,-0.148201,-308.920197,-0.000724,0.002757,0.070028,-0.659231,-0.033583,0.700281,-308.920197,0.069005,0.000000
146.510010,-0.128090,-309.009155,-0.000724,0.002728,0.069291,-0.569772,-0.029026,0.692908,-309.009155,0.068337,0.000000
146.910004,-0.157509,-309.053650,-0.000742,0.002707,0.068753,-0.700634,-0.035692,0.687534,-309.053650,0.067669,0.000000
147.310013,-0.162727,-309.053650,-0.000755,0.002679,0.068051,-0.723847,-0.036875,0.680509,-309.053650,0.067002,0.000000
147.710007,-0.138519,-309.053650,-0.000802,0.002649,0.067288,-0.616165,-0.031389,0.672879,-309.053650,0.066334,0.000000
148.110001,-0.145226,-309.053650,-0.000832,0.002626,0.066689,-0.645995,-0.032909,0.666891,-309.053650,0.065675,0.000000
148.510010,-0.134796,-309.098114,-0.000871,0.002600,0.066039,-0.599603,-0.030545,0.660388,-309.098114,0.065007,0.000000
148.910004,-0.150436,-309.098114,-0.000905,0.002571,0.065293,-0.669175,-0.034089,0.652932,-309.098114,0.064339,0.000000
149.310013,-0.145966,-309.187103,-0.000927,0.002559,0.065007,-0.649287,-0.033076,0.650071,-309.187103,0.063672,0.000000
149.710007,-0.120270,-309.187103,-0.000966,0.002515,0.063888,-0.534987,-0.027254,0.638883,-309.187103,0.063003,0.000000
150.110001,-0.144104,-309.187103,-0.000992,0.002495,0.063368,-0.641007,-0.032654,0.633682,-309.187103,0.062336,0.000000
150.510010,-0.121017,-309.276062,-0.001000,0.002478,0.062943,-0.538313,-0.027423,0.629428,-309.276062,0.061668,0.000000
150.910004,-0.128464,-309.276062,-0.001052,0.002444,0.062084,-0.571435,-0.029110,0.620844,-309.276062,0.061000,0.000000
151.310013,-0.130699,-309.231567,-0.001061,0.002424,0.061564,-0.581379,-0.029617,0.615643,-309.231567,0.060341,0.000000
151.710007,-0.123627,-309.365021,-0.001112,0.002389,0.060679,-0.549919,-0.028014,0.606794,-309.365021,0.059673,0.000000
152.110001,-0.109100,-309.409485,-0.001125,0.002363,0.060020,-0.485303,-0.024722,0.600201,-309.409485,0.059006,0.000000
152.510010,-0.087875,-309.320526,-0.001160,0.002336,0.059327,-0.390889,-0.019913,0.593267,-309.320526,0.058338,0.000000
152.910004,-0.091972,-309.365021,-0.001194,0.002310,0.058667,-0.409113,-0.020841,0.586674,-309.365021,0.057670,0.000000
153.310013,-0.120644,-309.409485,-0.001224,0.002283,0.057982,-0.536650,-0.027338,0.579823,-309.409485,0.057003,0.000000
153.710007,-0.102402,-309.453979,-0.001259,0.002255,0.057272,-0.455506,-0.023205,0.572715,-309.453979,0.056334,0.000000
154.110001,-0.088249,-309.542938,-0.001272,0.002232,0.056682,-0.392552,-0.019998,0.566818,-309.542938,0.055667,0.000000
154.510010,-0.080429,-309.542938,-0.001302,0.002204,0.055979,-0.357766,-0.018225,0.559794,-309.542938,0.055008,0.000000
154.910004,-0.085640,-309.587433,-0.001332,0.002178,0.055328,-0.380946,-0.019406,0.553284,-309.587433,0.054340,0.000000
155.310013,-0.083405,-309.542938,-0.001358,0.002154,0.054713,-0.371002,-0.018900,0.547129,-309.542938,0.053672,0.000000
155.710007,-0.105751,-309.631897,-0.001388,0.002123,0.053924,-0.470404,-0.023964,0.539242,-309.631897,0.053004,0.000000
156.110001,-0.085274,-309.587433,-0.001423,0.002100,0.053334,-0.379317,-0.019323,0.533337,-309.587433,0.052337,0.000000
156.510010,-0.106125,-309.631897,-0.001436,0.002073,0.052649,-0.472067,-0.024048,0.526486,-309.631897,0.051669,0.000000
156.910004,-0.094208,-309.631897,-0.001470,0.002046,0.051973,-0.419057,-0.021348,0.519727,-309.631897,0.051001,0.000000
157.310013,-0.105003,-309.676392,-0.001496,0.002020,0.051305,-0.467078,-0.023794,0.513050,-309.676392,0.050334,0.000000
157.710007,-0.087135,-309.676392,-0.001544,0.001992,0.050603,-0.387597,-0.019745,0.506025,-309.676392,0.049665,0.000000
158.110001,-0.101280,-309.765350,-0.001569,0.001965,0.049917,-0.450517,-0.022950,0.499175,-309.765350,0.049007,0.000000
158.510010,-0.123627,-309.720856,-0.001578,0.001940,0.049284,-0.549919,-0.028014,0.492839,-309.720856,0.048339,0.000000
158.910004,-0.133308,-309.809814,-0.001604,0.001916,0.048668,-0.592985,-0.030208,0.486685,-309.809814,0.047671,0.000000
159.310013,-0.129951,-309.854309,-0.001638,0.001891,0.048044,-0.578053,-0.029447,0.480439,-309.854309,0.047003,0.000000
159.710007,-0.099792,-309.854309,-0.001664,0.001862,0.047298,-0.443899,-0.022613,0.472983,-309.854309,0.046335,0.000000
160.110001,-0.096443,-309.943268,-0.001681,0.001845,0.046856,-0.429001,-0.021854,0.468562,-309.943268,0.045668,0.000000
160.510010,-0.104637,-309.898773,-0.001716,0.001805,0.045859,-0.465449,-0.023711,0.458585,-309.898773,0.045000,0.000000
160.910004,-0.107986,-309.943268,-0.001755,0.001784,0.045304,-0.480348,-0.024470,0.453037,-309.943268,0.044332,0.000000
161.310013,-0.117294,-309.943268,-0.001776,0.001757,0.044636,-0.521751,-0.026579,0.446360,-309.943268,0.043673,0.000000
161.710007,-0.127350,-309.987762,-0.001785,0.001730,0.043942,-0.566480,-0.028858,0.439419,-309.987762,0.043005,0.000000
162.110001,-0.142990,-309.987762,-0.001819,0.001704,0.043283,-0.636052,-0.032402,0.432833,-309.987762,0.042338,0.000000
162.510010,-0.131447,-310.032227,-0.001854,0.001680,0.042685,-0.584705,-0.029786,0.426845,-310.032227,0.041670,0.000000
162.910004,-0.143730,-310.032227,-0.001871,0.001654,0.042017,-0.639344,-0.032570,0.420169,-310.032227,0.041002,0.000000
163.310013,-0.132561,-310.076721,-0.001901,0.001623,0.041236,-0.589660,-0.030039,0.412364,-310.076721,0.040334,0.000000
163.710007,-0.166451,-310.076721,-0.001940,0.001601,0.040672,-0.740409,-0.037718,0.406725,-310.076721,0.039666,0.000000
164.110001,-0.109474,-310.121185,-0.001970,0.001579,0.040118,-0.486965,-0.024807,0.401176,-310.121185,0.038999,0.000000
164.510010,-0.142616,-310.121185,-0.001966,0.001559,0.039606,-0.634389,-0.032317,0.396059,-310.121185,0.038339,0.000000
164.910004,-0.142616,-310.121185,-0.002035,0.001524,0.038713,-0.634389,-0.032317,0.387127,-310.121185,0.037672,0.000000
165.310013,-0.163841,-310.254639,-0.002057,0.001496,0.038002,-0.728802,-0.037127,0.380019,-310.254639,0.037004,0.000000
165.500015,-0.095695,-310.254639,-0.002065,0.001497,0.038019,-0.425675,-0.021685,0.380185,-310.254639,0.037854,0.000000