File: Data/sima compression 500bar/P1-15-500bar-3_11072024_172849.csv
Time (sec),S:Load (lbs),S:HL1 (DIM),S:LVDT (in),S:Position (in),Ch:Position (mm),Ch:Load (N),Ch:Stress (MPa),Ch:Strain (mm/mm),Ch:HL1 (DIM),Set Point (),Cycles ()
0.010000,-0.201080,-449.746887,-0.008739,-0.006066,-0.154079,-0.894450,-0.045565,-1.540785,-449.746887,-0.153792,0.000000
0.450000,-0.080429,-449.746887,-0.008735,-0.005990,-0.152145,-0.357766,-0.018225,-1.521452,-449.746887,-0.151521,0.000000
0.890000,-0.053246,-449.746887,-0.008597,-0.005723,-0.145364,-0.236848,-0.012066,-1.453642,-449.746887,-0.144201,0.000000
1.330000,-0.099792,-449.791382,-0.008287,-0.005433,-0.137993,-0.443899,-0.022613,-1.379927,-449.791382,-0.136865,0.000000
1.770000,-0.063301,-449.702423,-0.007994,-0.005144,-0.130656,-0.281577,-0.014344,-1.306561,-449.702423,-0.129528,0.000000
2.210000,-0.075218,-449.791382,-0.007709,-0.004859,-0.123422,-0.334587,-0.017045,-1.234224,-449.791382,-0.122208,0.000000
2.650000,-0.104263,-449.746887,-0.007416,-0.004567,-0.115999,-0.463786,-0.023626,-1.159995,-449.746887,-0.114872,0.000000
3.090000,-0.068512,-449.835846,-0.007101,-0.004280,-0.108723,-0.304756,-0.015525,-1.087234,-449.835846,-0.107535,0.000000
3.530000,-0.072609,-449.791382,-0.006808,-0.003991,-0.101361,-0.322981,-0.016453,-1.013610,-449.791382,-0.100216,0.000000
3.970000,-0.050270,-449.835846,-0.006523,-0.003707,-0.094145,-0.223612,-0.011391,-0.941455,-449.835846,-0.092880,0.000000
4.410000,-0.084152,-449.880341,-0.006196,-0.003411,-0.086627,-0.374328,-0.019069,-0.866272,-449.880341,-0.085560,0.000000
4.850000,-0.162354,-449.924835,-0.005915,-0.003125,-0.079368,-0.722184,-0.036790,-0.793677,-449.924835,-0.078223,0.000000
5.290000,-0.060692,-449.924835,-0.005605,-0.002834,-0.071996,-0.269971,-0.013753,-0.719963,-449.924835,-0.070887,0.000000
5.730000,-0.031647,-449.969299,-0.005320,-0.002552,-0.064816,-0.140772,-0.007171,-0.648156,-449.969299,-0.063567,0.000000
6.170000,-0.064049,-450.013794,-0.005014,-0.002261,-0.057418,-0.284903,-0.014514,-0.574184,-450.013794,-0.056230,0.000000
6.610000,-0.111710,-450.058258,-0.004725,-0.001972,-0.050091,-0.496909,-0.025314,-0.500908,-450.058258,-0.048893,0.000000
7.050000,-0.091972,-449.924835,-0.004432,-0.001689,-0.042901,-0.409113,-0.020841,-0.429010,-449.924835,-0.041575,0.000000
7.490000,-0.042450,-450.013794,-0.004139,-0.001391,-0.035339,-0.188827,-0.009619,-0.353388,-450.013794,-0.034237,0.000000
7.930000,-0.070007,-450.102753,-0.003846,-0.001106,-0.028098,-0.311408,-0.015864,-0.280975,-450.102753,-0.026900,0.000000
8.370001,-0.082664,-450.013794,-0.003548,-0.000821,-0.020847,-0.367710,-0.018732,-0.208472,-450.013794,-0.019582,0.000000
8.810000,-0.064415,-450.102753,-0.003247,-0.000532,-0.013501,-0.286532,-0.014597,-0.135015,-450.102753,-0.012245,0.000000
9.250000,-0.058464,-450.058258,-0.002949,-0.000239,-0.006062,-0.260061,-0.013248,-0.060619,-450.058258,-0.004925,0.000000
9.690001,0.144485,-450.147217,-0.002669,0.000018,0.000469,0.642703,0.032741,0.004693,-450.147217,0.001874,0.000000
10.130000,0.114319,-450.191711,-0.002665,-0.000001,-0.000035,0.508516,0.025905,-0.000348,-450.191711,0.000165,0.000000
10.570001,0.118416,-450.147217,-0.002673,-0.000001,-0.000026,0.526740,0.026833,-0.000257,-450.147217,0.000790,0.000000
11.010000,0.266991,-450.280670,-0.002673,0.000023,0.000581,1.187634,0.060501,0.005814,-450.280670,0.001528,0.000000
11.450001,0.590210,-450.191711,-0.002643,0.000050,0.001267,2.625385,0.133743,0.012672,-450.191711,0.002256,0.000000
11.890000,1.172600,-450.236176,-0.002617,0.000075,0.001900,5.215984,0.265715,0.019000,-450.236176,0.002993,0.000000
12.330001,2.326584,-450.236176,-0.002587,0.000116,0.002940,10.349162,0.527211,0.029401,-450.236176,0.003721,0.000000
12.770000,2.934296,-450.236176,-0.002570,0.000137,0.003478,13.052399,0.664921,0.034776,-450.236176,0.004459,0.000000
13.210001,3.897995,-450.325134,-0.002557,0.000164,0.004172,17.339148,0.883298,0.041725,-450.325134,0.005187,0.000000
13.650001,5.078789,-450.325134,-0.002527,0.000194,0.004936,22.591581,1.150870,0.049355,-450.325134,0.005924,0.000000
14.090001,6.176918,-450.369629,-0.002514,0.000223,0.005673,27.476303,1.399710,0.056728,-450.369629,0.006661,0.000000
14.530001,7.641083,-450.369629,-0.002492,0.000255,0.006478,33.989235,1.731494,0.064782,-450.369629,0.007390,0.000000
14.970000,8.720222,-450.325134,-0.002471,0.000281,0.007146,38.789486,1.976031,0.071459,-450.325134,0.008127,0.000000
15.410001,9.782600,-450.414124,-0.002475,0.000309,0.007841,43.515179,2.216769,0.078408,-450.414124,0.008855,0.000000
15.850000,10.761192,-450.414124,-0.002440,0.000329,0.008360,47.868176,2.438521,0.083601,-450.414124,0.009592,0.000000
16.290001,12.229462,-450.503082,-0.002440,0.000361,0.009158,54.399361,2.771236,0.091579,-450.503082,0.010321,0.000000
16.730001,13.571114,-450.414124,-0.002410,0.000392,0.009948,60.367329,3.075258,0.099482,-450.414124,0.011058,0.000000
17.170000,15.133591,-450.414124,-0.002397,0.000424,0.010763,67.317574,3.429321,0.107627,-450.414124,0.011795,0.000000
17.610001,16.091331,-450.503082,-0.002376,0.000447,0.011361,71.577820,3.646348,0.113607,-450.503082,0.012523,0.000000
18.050001,17.596466,-450.503082,-0.002350,0.000480,0.012203,78.272987,3.987416,0.122025,-450.503082,0.013261,0.000000
18.490002,18.959717,-450.592041,-0.002328,0.000511,0.012975,84.337036,4.296333,0.129746,-450.592041,0.013989,0.000000
18.930000,19.896233,-450.547546,-0.002311,0.000540,0.013712,88.502861,4.508551,0.137119,-450.547546,0.014726,0.000000
19.370001,21.288162,-450.547546,-0.002294,0.000572,0.014536,94.694473,4.823967,0.145355,-450.547546,0.015454,0.000000
19.810001,21.678406,-450.636505,-0.002259,0.000598,0.015177,96.430367,4.912397,0.151774,-450.636505,0.016192,0.000000
20.250002,23.186142,-450.592041,-0.002255,0.000629,0.015966,103.137108,5.254055,0.159662,-450.592041,0.016929,0.000000
20.690001,23.666130,-450.681000,-0.002225,0.000654,0.016608,105.272202,5.362822,0.166081,-450.681000,0.017657,0.000000
21.130001,24.600792,-450.681000,-0.002203,0.000684,0.017362,109.429787,5.574619,0.173621,-450.681000,0.018395,0.000000
21.570002,25.328033,-450.636505,-0.002186,0.000710,0.018022,112.664719,5.739415,0.180222,-450.636505,0.019123,0.000000
22.010000,26.572128,-450.725464,-0.002143,0.000748,0.018993,118.198730,6.021330,0.189926,-450.725464,0.019860,0.000000
22.450001,26.785126,-450.681000,-0.002121,0.000775,0.019678,119.146187,6.069596,0.196784,-450.681000,0.020588,0.000000
22.890001,27.284851,-450.769958,-0.002095,0.000800,0.020320,121.369080,6.182836,0.203203,-450.769958,0.021326,0.000000
23.330002,27.788666,-450.814453,-0.002100,0.000826,0.020970,123.610161,6.297002,0.209698,-450.814453,0.022063,0.000000
23.770000,28.978401,-450.769958,-0.002048,0.000863,0.021924,128.902359,6.566599,0.219236,-450.769958,0.022791,0.000000
24.210001,29.318748,-450.858917,-0.002035,0.000891,0.022626,130.416306,6.643723,0.226261,-450.858917,0.023528,0.000000
24.650002,29.247993,-450.858917,-0.002013,0.000916,0.023259,130.101578,6.627690,0.232589,-450.858917,0.024257,0.000000
25.090002,29.556320,-450.858917,-0.001975,0.000941,0.023910,131.473083,6.697558,0.239099,-450.858917,0.024994,0.000000
25.530001,30.107430,-450.858917,-0.001953,0.000968,0.024578,133.924530,6.822441,0.245776,-450.858917,0.025722,0.000000
25.970001,30.843239,-450.858917,-0.001923,0.001002,0.025462,137.197586,6.989178,0.254617,-450.858917,0.026459,0.000000
26.410002,31.593201,-450.903412,-0.001897,0.001033,0.026234,140.533569,7.159122,0.262339,-450.903412,0.027188,0.000000
26.850000,31.352272,-450.947876,-0.001880,0.001054,0.026771,139.461868,7.104527,0.267713,-450.947876,0.027925,0.000000
27.290001,31.827797,-450.992371,-0.001858,0.001078,0.027371,141.577118,7.212282,0.273708,-450.992371,0.028662,0.000000
27.730001,33.099442,-450.947876,-0.001850,0.001113,0.028264,147.233673,7.500441,0.282641,-450.947876,0.029390,0.000000
28.170002,34.680168,-450.992371,-0.001819,0.001151,0.029235,154.265091,7.858638,0.292345,-450.992371,0.030128,0.000000
28.610001,34.183792,-451.036835,-0.001794,0.001173,0.029807,152.057098,7.746158,0.298068,-451.036835,0.030856,0.000000
29.050001,34.396049,-451.081329,-0.001772,0.001195,0.030362,153.001266,7.794256,0.303624,-451.081329,0.031593,0.000000
29.490002,34.920349,-451.036835,-0.001738,0.001224,0.031082,155.333466,7.913064,0.310816,-451.036835,0.032321,0.000000
29.930002,36.329407,-451.036835,-0.001716,0.001263,0.032070,161.601273,8.232362,0.320702,-451.036835,0.033059,0.000000
30.370001,36.759865,-451.125793,-0.001699,0.001290,0.032764,163.516052,8.329905,0.327636,-451.125793,0.033796,0.000000
30.810001,37.562332,-451.170288,-0.001677,0.001322,0.033580,167.085602,8.511746,0.335796,-451.170288,0.034524,0.000000
31.250002,37.370186,-451.214783,-0.001656,0.001341,0.034073,166.230896,8.468205,0.340731,-451.214783,0.035262,0.000000
31.690002,38.479858,-451.170288,-0.001638,0.001377,0.034975,171.166962,8.719661,0.349755,-451.170288,0.035990,0.000000
32.130001,39.077888,-451.125793,-0.001595,0.001406,0.035704,173.827133,8.855176,0.357037,-451.125793,0.036727,0.000000
32.570000,39.525101,-451.214783,-0.001578,0.001433,0.036389,175.816422,8.956515,0.363895,-451.214783,0.037455,0.000000
33.010002,40.194633,-451.170288,-0.001552,0.001462,0.037127,178.794662,9.108234,0.371268,-451.170288,0.038193,0.000000
33.450001,41.151253,-451.259247,-0.001552,0.001492,0.037890,183.049911,9.325007,0.378898,-451.259247,0.038930,0.000000
33.890003,42.454185,-451.303741,-0.001531,0.001528,0.038809,188.845642,9.620255,0.388088,-451.303741,0.039658,0.000000
34.330002,42.265762,-451.259247,-0.001483,0.001549,0.039355,188.007507,9.577559,0.393553,-451.259247,0.040395,0.000000
34.770000,42.865654,-451.303741,-0.001466,0.001579,0.040109,190.675949,9.713495,0.401093,-451.303741,0.041124,0.000000
35.210003,43.143448,-451.303741,-0.001470,0.001601,0.040656,191.911636,9.776445,0.406558,-451.303741,0.041861,0.000000
35.650002,44.324615,-451.348206,-0.001427,0.001632,0.041463,197.165741,10.044102,0.414628,-451.348206,0.042591,0.000000
36.090000,44.917427,-451.392700,-0.001414,0.001662,0.042217,199.802689,10.178434,0.422167,-451.392700,0.043326,0.000000
36.530003,45.590309,-451.348206,-0.001397,0.001692,0.042980,202.795822,10.330912,0.429798,-451.348206,0.044064,0.000000
36.970001,46.535759,-451.437164,-0.001380,0.001720,0.043682,207.001389,10.545154,0.436822,-451.437164,0.044793,0.000000
37.410004,47.682297,-451.437164,-0.001345,0.001750,0.044445,212.101456,10.804963,0.444453,-451.437164,0.045529,0.000000
37.850002,48.112755,-451.392700,-0.001341,0.001778,0.045166,214.016220,10.902506,0.451659,-451.392700,0.046259,0.000000
38.290001,49.260040,-451.526123,-0.001311,0.001807,0.045894,219.119598,11.162484,0.458941,-451.526123,0.046995,0.000000
38.730003,49.919136,-451.481659,-0.001298,0.001834,0.046588,222.051407,11.311838,0.465875,-451.481659,0.047724,0.000000
39.170002,50.872040,-451.481659,-0.001272,0.001866,0.047394,226.290131,11.527769,0.473945,-451.481659,0.048462,0.000000
39.610001,51.650665,-451.526123,-0.001250,0.001892,0.048053,229.753632,11.704208,0.480530,-451.526123,0.049190,0.000000
40.050003,52.768532,-451.526123,-0.001224,0.001923,0.048834,234.726151,11.957520,0.488342,-451.526123,0.049927,0.000000
40.490002,53.500618,-451.570618,-0.001212,0.001949,0.049502,237.982635,12.123414,0.495019,-451.570618,0.050665,0.000000
40.930000,54.506020,-451.526123,-0.001203,0.001975,0.050160,242.454880,12.351241,0.501605,-451.526123,0.051393,0.000000
41.370003,56.215958,-451.615082,-0.001173,0.002011,0.051089,250.061066,12.738718,0.510885,-451.615082,0.052130,0.000000
41.810001,57.034431,-451.570618,-0.001151,0.002039,0.051791,253.701828,12.924187,0.517910,-451.570618,0.052858,0.000000
42.250004,58.100533,-451.659576,-0.001138,0.002070,0.052580,258.444061,13.165769,0.525798,-451.659576,0.053596,0.000000
42.690002,59.079124,-451.748535,-0.001104,0.002097,0.053275,262.797058,13.387521,0.532747,-451.748535,0.054324,0.000000
43.130001,60.353760,-451.659576,-0.001087,0.002131,0.054115,268.466919,13.676358,0.541149,-451.659576,0.055061,0.000000
43.570004,61.592270,-451.748535,-0.001078,0.002160,0.054852,273.976105,13.957007,0.548522,-451.748535,0.055798,0.000000
44.010002,62.092361,-451.704071,-0.001048,0.002185,0.055503,276.200623,14.070330,0.555032,-451.704071,0.056527,0.000000
44.450001,62.767845,-451.793030,-0.001039,0.002209,0.056101,279.205322,14.223396,0.561012,-451.793030,0.057264,0.000000
44.890003,63.962418,-451.793030,-0.001030,0.002238,0.056839,284.519043,14.494091,0.568385,-451.793030,0.057992,0.000000
45.330002,65.683151,-451.748535,-0.000987,0.002272,0.057697,292.173248,14.884014,0.576969,-451.748535,0.058729,0.000000
45.770000,66.655792,-451.837494,-0.000979,0.002297,0.058348,296.499786,15.104419,0.583479,-451.837494,0.059458,0.000000
46.210003,68.154221,-451.793030,-0.000957,0.002330,0.059188,303.165100,15.443968,0.591882,-451.793030,0.060195,0.000000
46.650002,68.529572,-451.881989,-0.000944,0.002349,0.059674,304.834747,15.529023,0.596742,-451.881989,0.060932,0.000000
47.090004,71.085159,-451.881989,-0.000918,0.002389,0.060681,316.202576,16.108128,0.606809,-451.881989,0.061660,0.000000
47.530003,72.635345,-451.837494,-0.000897,0.002421,0.061495,323.098145,16.459404,0.614955,-451.837494,0.062398,0.000000
47.970001,73.688782,-451.926453,-0.000884,0.002446,0.062137,327.784058,16.698116,0.621374,-451.926453,0.063126,0.000000
48.410004,73.903275,-451.881989,-0.000871,0.002463,0.062570,328.738190,16.746721,0.625704,-451.881989,0.063863,0.000000
48.850002,75.149231,-451.970947,-0.000854,0.002488,0.063187,334.280487,17.029058,0.631866,-451.970947,0.064592,0.000000
49.290001,77.450500,-451.970947,-0.000841,0.002521,0.064036,344.517029,17.550533,0.640359,-451.970947,0.065329,0.000000
49.730003,79.581955,-452.015411,-0.000832,0.002556,0.064929,353.998230,18.033529,0.649291,-452.015411,0.066066,0.000000
50.170002,80.743011,-452.059906,-0.000824,0.002582,0.065580,359.162842,18.296627,0.655801,-452.059906,0.066794,0.000000
50.610001,82.886383,-452.015411,-0.000802,0.002612,0.066343,368.697052,18.782322,0.663432,-452.015411,0.067532,0.000000
51.050003,85.284836,-452.059906,-0.000763,0.002646,0.067211,379.365906,19.325821,0.672107,-452.059906,0.068260,0.000000
51.490002,86.625000,-452.104401,-0.000767,0.002673,0.067895,385.327240,19.629505,0.678950,-452.104401,0.068997,0.000000
51.930004,88.441818,-452.104401,-0.000755,0.002703,0.068660,393.408844,20.041203,0.686595,-452.104401,0.069725,0.000000
52.370003,90.746796,-452.148865,-0.000742,0.002734,0.069439,403.661896,20.563519,0.694392,-452.148865,0.070463,0.000000
52.810001,92.938217,-452.193359,-0.000724,0.002766,0.070255,413.409851,21.060101,0.702552,-452.193359,0.071191,0.000000
53.250004,93.960373,-452.104401,-0.000724,0.002786,0.070765,417.956604,21.291725,0.707654,-452.104401,0.071928,0.000000
53.690002,96.244125,-452.237823,-0.000690,0.002817,0.071563,428.115265,21.809231,0.715633,-452.237823,0.072665,0.000000
54.130001,98.117538,-452.193359,-0.000690,0.002845,0.072258,436.448608,22.233751,0.722582,-452.193359,0.073394,0.000000
54.570004,99.764175,-452.282318,-0.000668,0.002868,0.072856,443.773224,22.606886,0.728562,-452.282318,0.074131,0.000000
55.010002,102.990784,-452.193359,-0.000664,0.002910,0.073905,458.125885,23.338045,0.739054,-452.193359,0.074859,0.000000
55.450001,104.698471,-452.282318,-0.000647,0.002931,0.074452,465.722046,23.725014,0.744519,-452.282318,0.075596,0.000000
55.890003,106.648224,-452.237823,-0.000625,0.002958,0.075145,474.394989,24.166834,0.751453,-452.237823,0.076325,0.000000
56.330002,109.273819,-452.237823,-0.000612,0.002991,0.075969,486.074219,24.761801,0.759689,-452.237823,0.077062,0.000000
56.770004,110.942795,-452.282318,-0.000621,0.003014,0.076550,493.498199,25.139997,0.765503,-452.282318,0.077799,0.000000
57.210003,114.113174,-452.282318,-0.000591,0.003051,0.077496,507.600739,25.858416,0.774965,-452.282318,0.078527,0.000000
57.650002,116.025299,-452.415741,-0.000586,0.003078,0.078172,516.106323,26.291710,0.781717,-452.415741,0.079265,0.000000
58.090004,118.318741,-452.371277,-0.000591,0.003104,0.078839,526.308044,26.811409,0.788394,-452.371277,0.079993,0.000000
58.530003,120.013046,-452.371277,-0.000582,0.003125,0.079369,533.844666,27.195345,0.793692,-452.371277,0.080730,0.000000
58.970001,123.054199,-452.460236,-0.000556,0.003160,0.080253,547.372437,27.884480,0.802534,-452.460236,0.081459,0.000000
59.410004,125.286209,-452.415741,-0.000560,0.003186,0.080912,557.300903,28.390261,0.809120,-452.415741,0.082196,0.000000
59.850002,128.227203,-452.460236,-0.000548,0.003221,0.081814,570.383118,29.056700,0.818143,-452.460236,0.082933,0.000000
60.290005,130.160934,-452.504730,-0.000539,0.003243,0.082379,578.984741,29.494890,0.823790,-452.504730,0.083661,0.000000
60.730003,132.863617,-452.460236,-0.000522,0.003276,0.083203,591.006897,30.107327,0.832026,-452.460236,0.084399,0.000000
61.170002,135.909241,-452.504730,-0.000513,0.003308,0.084035,604.554504,30.797474,0.840353,-452.504730,0.085127,0.000000
61.610004,138.135284,-452.504730,-0.000513,0.003335,0.084710,614.456421,31.301903,0.847105,-452.504730,0.085864,0.000000
62.050003,140.813766,-452.549194,-0.000513,0.003367,0.085517,626.370911,31.908855,0.855174,-452.549194,0.086592,0.000000
62.490002,142.163986,-452.549194,-0.000504,0.003380,0.085847,632.377014,32.214821,0.858475,-452.549194,0.087330,0.000000
62.930004,146.331955,-452.593689,-0.000492,0.003424,0.086957,650.917053,33.159294,0.869572,-452.593689,0.088067,0.000000
63.370003,148.646622,-452.727112,-0.000496,0.003449,0.087608,661.213196,33.683804,0.876082,-452.727112,0.088795,0.000000
63.810001,151.126617,-452.638153,-0.000466,0.003477,0.088318,672.244751,34.245781,0.883183,-452.638153,0.089532,0.000000
64.250000,153.602524,-452.682648,-0.000483,0.003502,0.088960,683.258179,34.806831,0.889602,-452.682648,0.090261,0.000000
64.690002,157.052933,-452.682648,-0.000461,0.003540,0.089906,698.606323,35.588707,0.899064,-452.682648,0.090998,0.000000
65.130005,159.735504,-452.727112,-0.000466,0.003567,0.090609,710.539001,36.196579,0.906089,-452.727112,0.091728,0.000000
65.570000,162.036758,-452.727112,-0.000470,0.003595,0.091302,720.775513,36.718056,0.913023,-452.727112,0.092463,0.000000
66.010002,164.444153,-452.771606,-0.000453,0.003621,0.091961,731.484131,37.263580,0.919608,-452.771606,0.093193,0.000000
66.450005,167.835342,-452.860565,-0.000457,0.003655,0.092845,746.568909,38.032032,0.928450,-452.860565,0.093930,0.000000
66.889999,170.709686,-452.816071,-0.000440,0.003685,0.093600,759.354614,38.683369,0.936005,-452.816071,0.094666,0.000000
67.330002,172.835556,-452.816071,-0.000435,0.003707,0.094164,768.810974,39.165100,0.941636,-452.816071,0.095396,0.000000
67.770004,175.657028,-452.816071,-0.000427,0.003735,0.094866,781.361511,39.804451,0.948661,-452.816071,0.096132,0.000000
68.210007,176.908569,-452.905029,-0.000427,0.003748,0.095196,786.928589,40.088055,0.951962,-452.905029,0.096862,0.000000
68.650002,181.150269,-452.905029,-0.000414,0.003791,0.096280,805.796631,41.049236,0.962802,-452.905029,0.097599,0.000000
69.090004,184.308731,-452.949524,-0.000410,0.003826,0.097182,819.846191,41.764954,0.971825,-452.949524,0.098327,0.000000
69.530006,186.807724,-452.905029,-0.000405,0.003849,0.097762,830.962280,42.331238,0.977623,-452.905029,0.099064,0.000000
69.970001,188.967850,-452.949524,-0.000410,0.003876,0.098439,840.570984,42.820728,0.984391,-452.949524,0.099800,0.000000
70.410004,192.124084,-452.994019,-0.000397,0.003906,0.099220,854.610596,43.535938,0.992203,-452.994019,0.100530,0.000000
70.850006,196.217194,-453.038483,-0.000388,0.003945,0.100209,872.817688,44.463451,1.002089,-453.038483,0.101267,0.000000
71.290001,198.145355,-452.994019,-0.000384,0.003963,0.100651,881.394531,44.900379,1.006510,-452.994019,0.101995,0.000000
71.730003,201.014465,-453.038483,-0.000388,0.003994,0.101458,894.156982,45.550529,1.014579,-453.038483,0.102733,0.000000
72.170006,203.513855,-453.082977,-0.000392,0.004015,0.101977,905.274841,46.116898,1.019772,-453.082977,0.103461,0.000000
72.610001,207.198090,-453.038483,-0.000371,0.004051,0.102905,921.663147,46.951759,1.029052,-453.038483,0.104198,0.000000
73.050003,210.158813,-453.038483,-0.000384,0.004081,0.103661,934.833069,47.622665,1.036607,-453.038483,0.104935,0.000000
73.490005,212.746063,-453.127441,-0.000371,0.004108,0.104345,946.341736,48.208946,1.043450,-453.127441,0.105664,0.000000
73.930000,216.194977,-453.038483,-0.000354,0.004137,0.105082,961.683289,48.990482,1.050823,-453.038483,0.106401,0.000000
74.370003,219.490112,-453.216400,-0.000358,0.004169,0.105889,976.340759,49.737171,1.058892,-453.216400,0.107129,0.000000
74.810005,220.654877,-453.171936,-0.000349,0.004171,0.105950,981.521912,50.001106,1.059498,-453.171936,0.018606,0.000000
75.250000,220.377838,-453.216400,-0.000345,0.004169,0.105889,980.289612,49.938332,1.058892,-453.216400,982.000671,0.000000
75.690002,220.052765,-453.216400,-0.000341,0.004169,0.105889,978.843567,49.864670,1.058892,-453.216400,982.000671,0.000000
76.130005,219.788391,-453.216400,-0.000354,0.004169,0.105897,977.667603,49.804760,1.058968,-453.216400,982.000671,0.000000
76.570007,219.528839,-453.349854,-0.000349,0.004175,0.106045,976.513062,49.745945,1.060452,-453.349854,982.000671,0.000000
77.010002,219.625275,-453.260895,-0.000336,0.004181,0.106192,976.942017,49.767799,1.061920,-453.260895,982.000671,0.000000
77.450005,219.507996,-453.305359,-0.000354,0.004182,0.106210,976.420349,49.741222,1.062102,-453.305359,982.000671,0.000000
77.890007,219.487488,-453.394348,-0.000341,0.004184,0.106271,976.329102,49.736576,1.062708,-453.394348,982.000671,0.000000
78.330002,219.445435,-453.305359,-0.000354,0.004185,0.106306,976.142029,49.727043,1.063056,-453.305359,982.000671,0.000000
78.770004,219.672943,-453.438812,-0.000358,0.004190,0.106418,977.154053,49.778599,1.064176,-453.438812,982.000671,0.000000
79.210007,219.591034,-453.394348,-0.000341,0.004190,0.106418,976.789673,49.760040,1.064176,-453.394348,982.000671,0.000000
79.650002,219.534790,-453.438812,-0.000349,0.004191,0.106452,976.539490,49.747295,1.064524,-453.438812,982.000671,0.000000
80.090004,219.426422,-453.438812,-0.000349,0.004191,0.106452,976.057495,49.722740,1.064524,-453.438812,982.000671,0.000000
80.530006,219.716125,-453.438812,-0.000345,0.004196,0.106574,977.346130,49.788387,1.065736,-453.438812,982.000671,0.000000
80.970001,219.622681,-453.527771,-0.000341,0.004196,0.106574,976.930481,49.767212,1.065736,-453.527771,982.000671,0.000000
81.410004,219.525482,-453.483307,-0.000336,0.004196,0.106583,976.498108,49.745186,1.065826,-453.483307,982.000671,0.000000
81.850006,219.449158,-453.483307,-0.000341,0.004198,0.106617,976.158630,49.727890,1.066175,-453.483307,982.000671,0.000000
82.290001,219.772736,-453.483307,-0.000354,0.004202,0.106729,977.597961,49.801216,1.067295,-453.483307,982.000671,0.000000
82.730003,219.745941,-453.527771,-0.000323,0.004202,0.106729,977.478760,49.795143,1.067295,-453.527771,982.000671,0.000000
83.170006,219.655457,-453.572266,-0.000341,0.004202,0.106729,977.076294,49.774639,1.067295,-453.572266,982.000671,0.000000
83.610001,219.566071,-453.572266,-0.000323,0.004202,0.106729,976.678650,49.754383,1.067295,-453.572266,982.000671,0.000000
84.050003,219.471863,-453.572266,-0.000332,0.004202,0.106729,976.259583,49.733036,1.067295,-453.572266,982.000671,0.000000
84.490005,219.590271,-453.572266,-0.000345,0.004207,0.106860,976.786316,49.759865,1.068597,-453.572266,982.000671,0.000000
84.930000,219.672211,-453.705688,-0.000328,0.004207,0.106860,977.150818,49.778435,1.068597,-453.705688,982.000671,0.000000
85.370003,219.616730,-453.616730,-0.000336,0.004207,0.106860,976.903992,49.765862,1.068597,-453.616730,982.000671,0.000000
85.810005,219.559753,-453.750183,-0.000310,0.004207,0.106860,976.650574,49.752949,1.068597,-453.750183,982.000671,0.000000
86.250008,219.509857,-453.705688,-0.000328,0.004207,0.106869,976.428589,49.741646,1.068688,-453.705688,982.000671,0.000000
86.690002,219.603668,-453.750183,-0.000323,0.004210,0.106929,976.845886,49.762901,1.069293,-453.750183,982.000671,0.000000
87.130005,219.564575,-453.750183,-0.000336,0.004211,0.106948,976.671997,49.754044,1.069475,-453.750183,982.000671,0.000000
87.570007,219.678894,-453.794678,-0.000328,0.004213,0.107008,977.180542,49.779949,1.070081,-453.794678,982.000671,0.000000
88.010002,219.677795,-453.883636,-0.000332,0.004213,0.107008,977.175659,49.779701,1.070081,-453.883636,982.000671,0.000000
88.450005,219.636444,-453.750183,-0.000315,0.004213,0.107008,976.991699,49.770329,1.070081,-453.750183,982.000671,0.000000
88.890007,219.572418,-453.883636,-0.000341,0.004213,0.107008,976.706909,49.755821,1.070081,-453.883636,982.000671,0.000000
89.330002,219.513184,-453.794678,-0.000315,0.004213,0.107016,976.443420,49.742397,1.070156,-453.794678,982.000671,0.000000
89.770004,219.537018,-453.839142,-0.000310,0.004215,0.107050,976.549438,49.747799,1.070505,-453.839142,982.000671,0.000000
90.210007,219.601807,-453.883636,-0.000319,0.004216,0.107094,976.837646,49.762482,1.070944,-453.883636,982.000671,0.000000
90.650002,219.600342,-453.883636,-0.000332,0.004216,0.107094,976.831116,49.762150,1.070944,-453.883636,982.000671,0.000000
91.090004,219.596222,-453.928101,-0.000310,0.004217,0.107103,976.812805,49.761215,1.071034,-453.928101,982.000671,0.000000
91.530006,219.581726,-453.928101,-0.000306,0.004218,0.107129,976.748291,49.757931,1.071292,-453.928101,982.000671,0.000000
91.970001,219.590271,-453.928101,-0.000328,0.004218,0.107138,976.786316,49.759865,1.071383,-453.928101,982.000671,0.000000
92.410004,219.565338,-454.017059,-0.000323,0.004218,0.107138,976.675415,49.754215,1.071383,-454.017059,982.000671,0.000000
92.850006,219.575012,-453.972595,-0.000302,0.004219,0.107172,976.718445,49.756409,1.071716,-453.972595,982.000671,0.000000
93.290001,219.572784,-454.017059,-0.000302,0.004219,0.107172,976.708496,49.755905,1.071716,-454.017059,982.000671,0.000000
93.730003,219.551544,-454.106018,-0.000315,0.004219,0.107172,976.614075,49.751091,1.071716,-454.106018,982.000671,0.000000
94.170006,219.514679,-454.061554,-0.000310,0.004219,0.107172,976.450073,49.742737,1.071716,-454.061554,982.000671,0.000000
94.610008,219.466644,-454.061554,-0.000315,0.004222,0.107250,976.236389,49.731853,1.072503,-454.061554,982.000671,0.000000
95.050003,219.664001,-454.106018,-0.000310,0.004223,0.107267,977.114258,49.776573,1.072670,-454.106018,982.000671,0.000000
95.490005,219.671814,-454.061554,-0.000319,0.004223,0.107267,977.149048,49.778347,1.072670,-454.061554,982.000671,0.000000
95.930008,219.653198,-454.194977,-0.000319,0.004223,0.107267,977.066223,49.774128,1.072670,-454.194977,982.000671,0.000000
96.370003,219.628632,-454.150513,-0.000310,0.004223,0.107267,976.956970,49.768559,1.072670,-454.150513,982.000671,0.000000
96.810005,219.597717,-454.239471,-0.000302,0.004223,0.107267,976.819458,49.761555,1.072670,-454.239471,982.000671,0.000000
97.250008,219.565704,-454.239471,-0.000306,0.004223,0.107267,976.677002,49.754303,1.072670,-454.239471,982.000671,0.000000
97.690002,219.537781,-454.194977,-0.000319,0.004223,0.107267,976.552795,49.747974,1.072670,-454.194977,982.000671,0.000000
98.130005,219.503143,-454.239471,-0.000306,0.004223,0.107267,976.398743,49.740124,1.072670,-454.239471,982.000671,0.000000
98.570007,219.483765,-454.239471,-0.000302,0.004223,0.107276,976.312561,49.735729,1.072760,-454.239471,982.000671,0.000000
99.010002,219.455475,-454.239471,-0.000306,0.004223,0.107276,976.186707,49.729321,1.072760,-454.239471,982.000671,0.000000
99.450005,219.414154,-454.328430,-0.000306,0.004223,0.107276,976.002930,49.719955,1.072760,-454.328430,982.000671,0.000000
99.890007,219.487488,-454.328430,-0.000302,0.004226,0.107337,976.329102,49.736576,1.073366,-454.328430,982.000671,0.000000
100.330002,219.491211,-454.328430,-0.000319,0.004226,0.107337,976.345642,49.737419,1.073366,-454.328430,982.000671,0.000000
100.770004,219.475586,-454.328430,-0.000310,0.004226,0.107337,976.276184,49.733879,1.073366,-454.328430,982.000671,0.000000
101.210007,219.454346,-454.372925,-0.000297,0.004226,0.107337,976.181702,49.729065,1.073366,-454.372925,982.000671,0.000000
101.650002,219.410797,-454.372925,-0.000306,0.004226,0.107337,975.987976,49.719196,1.073366,-454.372925,982.000671,0.000000
102.090004,219.518768,-454.417389,-0.000302,0.004228,0.107390,976.468262,49.743664,1.073896,-454.417389,982.000671,0.000000
102.530006,219.530701,-454.461884,-0.000310,0.004228,0.107390,976.521301,49.746368,1.073896,-454.461884,982.000671,0.000000
102.970001,219.526978,-454.506348,-0.000293,0.004228,0.107390,976.504761,49.745525,1.073896,-454.506348,982.000671,0.000000
103.410004,219.502014,-454.461884,-0.000306,0.004228,0.107390,976.393738,49.739868,1.073896,-454.461884,982.000671,0.000000
103.850006,219.483765,-454.506348,-0.000306,0.004228,0.107390,976.312561,49.735729,1.073896,-454.506348,982.000671,0.000000
104.290009,219.466644,-454.461884,-0.000297,0.004228,0.107390,976.236389,49.731853,1.073896,-454.461884,982.000671,0.000000
104.730003,219.442078,-454.595306,-0.000306,0.004229,0.107406,976.127136,49.726284,1.074062,-454.595306,982.000671,0.000000
105.170006,219.431641,-454.550842,-0.000293,0.004229,0.107415,976.080688,49.723923,1.074153,-454.550842,982.000671,0.000000
105.610008,219.424957,-454.595306,-0.000289,0.004229,0.107415,976.050964,49.722404,1.074153,-454.595306,982.000671,0.000000
106.050003,219.410034,-454.639801,-0.000306,0.004229,0.107415,975.984558,49.719025,1.074153,-454.639801,982.000671,0.000000
106.490005,219.384735,-454.550842,-0.000302,0.004229,0.107415,975.872070,49.713291,1.074153,-454.550842,982.000671,0.000000
106.930008,219.477448,-454.684296,-0.000289,0.004233,0.107520,976.284424,49.734299,1.075198,-454.684296,982.000671,0.000000
107.370003,219.620819,-454.728760,-0.000293,0.004233,0.107520,976.922180,49.766788,1.075198,-454.728760,982.000671,0.000000
107.810005,219.637207,-454.639801,-0.000323,0.004233,0.107520,976.995117,49.770504,1.075198,-454.639801,982.000671,0.000000
108.250008,219.633850,-454.684296,-0.000306,0.004233,0.107520,976.980164,49.769741,1.075198,-454.684296,982.000671,0.000000
108.690002,219.634583,-454.684296,-0.000302,0.004233,0.107520,976.983398,49.769905,1.075198,-454.684296,982.000671,0.000000
109.130005,219.616333,-454.728760,-0.000306,0.004233,0.107520,976.902222,49.765774,1.075198,-454.728760,982.000671,0.000000
109.570007,219.607391,-454.817719,-0.000289,0.004233,0.107520,976.862488,49.763748,1.075198,-454.817719,982.000671,0.000000
110.010002,219.581329,-454.728760,-0.000302,0.004233,0.107520,976.746521,49.757839,1.075198,-454.728760,982.000671,0.000000
110.450005,219.572784,-454.817719,-0.000306,0.004233,0.107520,976.708496,49.755905,1.075198,-454.817719,982.000671,0.000000
110.890007,219.553406,-454.817719,-0.000285,0.004233,0.107520,976.622314,49.751511,1.075198,-454.817719,982.000671,0.000000
111.330002,219.532562,-454.817719,-0.000302,0.004233,0.107520,976.529602,49.746792,1.075198,-454.817719,982.000671,0.000000
111.770004,219.513947,-454.951172,-0.000293,0.004233,0.107520,976.446777,49.742573,1.075198,-454.951172,982.000671,0.000000
112.210007,219.499054,-454.862213,-0.000306,0.004233,0.107520,976.380554,49.739197,1.075198,-454.862213,982.000671,0.000000
112.650009,219.481171,-454.995636,-0.000297,0.004233,0.107520,976.301025,49.735142,1.075198,-454.995636,982.000671,0.000000
113.090004,219.449524,-454.951172,-0.000285,0.004233,0.107520,976.160217,49.727974,1.075198,-454.951172,982.000671,0.000000
113.530006,219.452881,-454.951172,-0.000289,0.004235,0.107562,976.175171,49.728733,1.075622,-454.951172,982.000671,0.000000
113.970009,219.496063,-455.040131,-0.000289,0.004235,0.107571,976.367249,49.738522,1.075713,-455.040131,982.000671,0.000000
114.410004,219.487488,-454.995636,-0.000293,0.004235,0.107571,976.329102,49.736576,1.075713,-454.995636,982.000671,0.000000
114.850006,219.480438,-455.040131,-0.000302,0.004235,0.107571,976.297729,49.734978,1.075713,-455.040131,982.000671,0.000000
115.290009,219.476715,-454.951172,-0.000289,0.004235,0.107571,976.281189,49.734135,1.075713,-454.951172,982.000671,0.000000
115.730003,219.454346,-455.040131,-0.000289,0.004235,0.107571,976.181702,49.729065,1.075713,-455.040131,982.000671,0.000000
116.170006,219.441315,-455.084625,-0.000306,0.004235,0.107580,976.123718,49.726112,1.075803,-455.084625,982.000671,0.000000
116.610008,219.433136,-455.084625,-0.000280,0.004235,0.107580,976.087341,49.724258,1.075803,-455.084625,982.000671,0.000000
117.050003,219.449890,-455.218048,-0.000302,0.004236,0.107606,976.161865,49.728054,1.076061,-455.218048,982.000671,0.000000
117.490005,219.464050,-455.084625,-0.000285,0.004236,0.107606,976.224854,49.731262,1.076061,-455.084625,982.000671,0.000000
117.930008,219.466278,-455.173584,-0.000302,0.004236,0.107606,976.234741,49.731770,1.076061,-455.173584,982.000671,0.000000
118.370003,219.448395,-455.173584,-0.000297,0.004236,0.107606,976.155212,49.727718,1.076061,-455.173584,982.000671,0.000000
118.810005,219.444672,-455.218048,-0.000280,0.004237,0.107615,976.138672,49.726871,1.076152,-455.218048,982.000671,0.000000
119.250008,219.443939,-455.218048,-0.000285,0.004237,0.107615,976.135376,49.726707,1.076152,-455.218048,982.000671,0.000000
119.690002,219.413757,-455.307007,-0.000272,0.004237,0.107615,976.001160,49.719868,1.076152,-455.307007,982.000671,0.000000
120.130005,219.420837,-455.262543,-0.000297,0.004237,0.107615,976.032654,49.721474,1.076152,-455.262543,982.000671,0.000000
120.570007,219.401855,-455.262543,-0.000293,0.004237,0.107615,975.948181,49.717171,1.076152,-455.262543,982.000671,0.000000
121.010002,219.611877,-455.351501,-0.000276,0.004241,0.107718,976.882446,49.764763,1.077181,-455.351501,982.000671,0.000000
121.450005,219.692322,-455.351501,-0.000285,0.004241,0.107718,977.240234,49.782993,1.077181,-455.351501,982.000671,0.000000
121.890007,219.722107,-455.395966,-0.000293,0.004241,0.107718,977.372742,49.789738,1.077181,-455.395966,982.000671,0.000000
122.330009,219.734375,-455.351501,-0.000285,0.004241,0.107718,977.427307,49.792522,1.077181,-455.351501,982.000671,0.000000
122.770004,219.732513,-455.529419,-0.000306,0.004241,0.107718,977.419006,49.792099,1.077181,-455.529419,982.000671,0.000000
123.210007,219.734375,-455.395966,-0.000293,0.004241,0.107718,977.427307,49.792522,1.077181,-455.395966,982.000671,0.000000
123.650009,219.726562,-455.484924,-0.000285,0.004241,0.107718,977.392578,49.790749,1.077181,-455.484924,982.000671,0.000000
124.090004,219.730286,-455.484924,-0.000289,0.004241,0.107718,977.409119,49.791595,1.077181,-455.484924,982.000671,0.000000
124.530006,219.707581,-455.484924,-0.000272,0.004241,0.107718,977.308105,49.786449,1.077181,-455.484924,982.000671,0.000000
124.970009,219.692688,-455.573914,-0.000306,0.004241,0.107718,977.241882,49.783073,1.077181,-455.573914,982.000671,0.000000
125.410004,219.677399,-455.573914,-0.000297,0.004241,0.107718,977.173889,49.779610,1.077181,-455.573914,982.000671,0.000000
125.850006,219.680389,-455.573914,-0.000276,0.004241,0.107718,977.187195,49.780289,1.077181,-455.573914,982.000671,0.000000
126.290009,219.651733,-455.573914,-0.000285,0.004241,0.107718,977.059692,49.773792,1.077181,-455.573914,982.000671,0.000000
126.730003,219.641296,-455.484924,-0.000289,0.004241,0.107718,977.013306,49.771431,1.077181,-455.484924,982.000671,0.000000
127.170006,219.622314,-455.662872,-0.000285,0.004241,0.107718,976.928833,49.767128,1.077181,-455.662872,982.000671,0.000000
127.610008,219.614105,-455.618378,-0.000289,0.004241,0.107718,976.892334,49.765266,1.077181,-455.618378,982.000671,0.000000
128.050003,219.608154,-455.618378,-0.000293,0.004241,0.107718,976.865845,49.763920,1.077181,-455.618378,982.000671,0.000000
128.490005,219.583954,-455.707336,-0.000285,0.004241,0.107718,976.758240,49.758434,1.077181,-455.707336,982.000671,0.000000
128.930008,219.577240,-455.662872,-0.000297,0.004241,0.107718,976.728333,49.756916,1.077181,-455.662872,982.000671,0.000000
129.370010,219.561218,-455.751831,-0.000306,0.004241,0.107718,976.657104,49.753284,1.077181,-455.751831,982.000671,0.000000
129.810013,219.554901,-455.751831,-0.000285,0.004241,0.107718,976.628967,49.751854,1.077181,-455.751831,982.000671,0.000000
130.250000,219.533295,-455.751831,-0.000310,0.004241,0.107718,976.532837,49.746956,1.077181,-455.751831,982.000671,0.000000
130.690002,219.525482,-455.885254,-0.000285,0.004241,0.107727,976.498108,49.745186,1.077272,-455.885254,982.000671,0.000000
131.130005,219.511322,-455.751831,-0.000285,0.004241,0.107727,976.435120,49.741974,1.077272,-455.751831,982.000671,0.000000
131.570007,219.496826,-455.929749,-0.000289,0.004241,0.107727,976.370667,49.738693,1.077272,-455.929749,982.000671,0.000000
132.010010,219.491211,-455.840790,-0.000276,0.004242,0.107736,976.345642,49.737419,1.077363,-455.840790,982.000671,0.000000
132.450012,219.474457,-455.840790,-0.000289,0.004242,0.107736,976.271118,49.733624,1.077363,-455.840790,982.000671,0.000000
132.889999,219.458832,-455.929749,-0.000276,0.004242,0.107736,976.201660,49.730080,1.077363,-455.929749,982.000671,0.000000
133.330002,219.448029,-455.885254,-0.000280,0.004242,0.107736,976.153564,49.727631,1.077363,-455.885254,982.000671,0.000000
133.770004,219.426819,-455.929749,-0.000280,0.004242,0.107736,976.059265,49.722828,1.077363,-455.929749,982.000671,0.000000
134.210007,219.413757,-455.885254,-0.000297,0.004242,0.107736,976.001160,49.719868,1.077363,-455.885254,982.000671,0.000000
134.650009,219.403351,-455.974243,-0.000285,0.004242,0.107736,975.954834,49.717506,1.077363,-455.974243,982.000671,0.000000
135.090012,219.389954,-456.063202,-0.000289,0.004242,0.107736,975.895264,49.714478,1.077363,-456.063202,982.000671,0.000000
135.530014,219.365356,-455.974243,-0.000272,0.004226,0.107346,975.785828,49.708900,1.073457,-455.974243,0.107536,0.000000
135.970001,219.196320,-456.063202,-0.000285,0.004213,0.107016,975.033936,49.670593,1.070156,-456.063202,0.106808,0.000000
136.410004,218.885376,-456.063202,-0.000263,0.004187,0.106340,973.650757,49.600136,1.063404,-456.063202,0.106071,0.000000
136.850006,218.300018,-456.107666,-0.000259,0.004167,0.105845,971.046997,49.467491,1.058453,-456.107666,0.105334,0.000000
137.290009,217.136719,-456.152161,-0.000267,0.004135,0.105038,965.872375,49.203884,1.050384,-456.152161,0.104605,0.000000
137.730011,216.686157,-456.063202,-0.000259,0.004106,0.104284,963.868164,49.101784,1.042845,-456.063202,0.103868,0.000000
138.170013,216.451538,-456.196625,-0.000250,0.004088,0.103824,962.824524,49.048618,1.038242,-456.196625,0.103140,0.000000
138.610001,216.151794,-456.152161,-0.000259,0.004052,0.102931,961.491211,48.980698,1.029310,-456.152161,0.102403,0.000000
139.050003,215.882935,-456.196625,-0.000250,0.004025,0.102238,960.295227,48.919773,1.022376,-456.196625,0.101674,0.000000
139.490005,215.138550,-456.285583,-0.000276,0.003993,0.101414,956.984070,48.751091,1.014140,-456.285583,0.100937,0.000000
139.930008,214.331635,-456.196625,-0.000263,0.003973,0.100902,953.394714,48.568241,1.009023,-456.196625,0.100200,0.000000
140.370010,213.280792,-456.285583,-0.000250,0.003946,0.100216,948.720337,48.330116,1.002164,-456.285583,0.099472,0.000000
140.810013,211.975647,-456.374573,-0.000267,0.003914,0.099411,942.914795,48.034367,0.994110,-456.374573,0.098734,0.000000
141.250000,209.743256,-456.330078,-0.000259,0.003881,0.098569,932.984619,47.528503,0.985693,-456.330078,0.098006,0.000000
141.690002,207.749207,-456.374573,-0.000259,0.003858,0.097988,924.114624,47.076645,0.979879,-456.374573,0.097269,0.000000
142.130005,205.826263,-456.374573,-0.000246,0.003835,0.097399,915.560974,46.640900,0.973990,-456.374573,0.096541,0.000000
142.570007,202.420197,-456.374573,-0.000250,0.003802,0.096575,900.410034,45.869072,0.965754,-456.374573,0.095803,0.000000
143.010010,199.585297,-456.463531,-0.000254,0.003777,0.095941,887.799744,45.226673,0.959410,-456.463531,0.095075,0.000000
143.450012,196.565002,-456.374573,-0.000267,0.003750,0.095248,874.364807,44.542263,0.952476,-456.374573,0.094338,0.000000
143.889999,193.802734,-456.419037,-0.000267,0.003726,0.094631,862.077637,43.916328,0.946315,-456.419037,0.093600,0.000000
144.330002,190.173218,-456.463531,-0.000233,0.003693,0.093800,845.932739,43.093868,0.938003,-456.463531,0.092872,0.000000
144.770004,186.830063,-456.463531,-0.000267,0.003660,0.092968,831.061646,42.336300,0.929676,-456.463531,0.092135,0.000000
145.210007,183.218796,-456.552490,-0.000263,0.003627,0.092126,814.997925,41.517971,0.921259,-456.552490,0.091407,0.000000
145.650009,180.824066,-456.507996,-0.000250,0.003603,0.091528,804.345642,40.975319,0.915278,-456.507996,0.090669,0.000000
146.090012,177.796677,-456.552490,-0.000285,0.003577,0.090851,790.879089,40.289303,0.908511,-456.552490,0.089941,0.000000
146.530014,173.740433,-456.596954,-0.000263,0.003543,0.089984,772.836060,39.370144,0.899836,-456.596954,0.089204,0.000000
146.970001,169.939987,-456.507996,-0.000259,0.003512,0.089211,755.930847,38.508949,0.892115,-456.507996,0.088467,0.000000
147.410004,167.729599,-456.596954,-0.000280,0.003493,0.088727,746.098511,38.008068,0.887270,-456.596954,0.087738,0.000000
147.850006,163.417145,-456.596954,-0.000276,0.003453,0.087704,726.915771,37.030853,0.877036,-456.596954,0.087001,0.000000
148.290009,160.523437,-456.641449,-0.000280,0.003431,0.087139,714.043884,36.375134,0.871389,-456.641449,0.086273,0.000000
148.730011,157.061493,-456.641449,-0.000285,0.003402,0.086402,698.644409,35.590645,0.864016,-456.641449,0.085536,0.000000
149.170013,152.296616,-456.596954,-0.000293,0.003363,0.085413,677.449158,34.510906,0.854130,-456.596954,0.084806,0.000000
149.610001,149.994614,-456.730408,-0.000297,0.003342,0.084894,667.209351,33.989265,0.848937,-456.730408,0.084070,0.000000
150.050003,146.883804,-456.685913,-0.000293,0.003317,0.084261,653.371765,33.284344,0.842608,-456.685913,0.083333,0.000000
150.490005,143.223389,-456.730408,-0.000289,0.003285,0.083445,637.089478,32.454884,0.834448,-456.730408,0.082603,0.000000
150.930008,139.476944,-456.774872,-0.000302,0.003250,0.082561,620.424438,31.605928,0.825607,-456.774872,0.081867,0.000000
151.370010,136.652130,-456.730408,-0.000315,0.003228,0.081979,607.859009,30.965816,0.819793,-456.730408,0.081138,0.000000
151.810013,132.385483,-456.774872,-0.000306,0.003193,0.081103,588.880066,29.998980,0.811027,-456.774872,0.080402,0.000000
152.250000,129.457153,-456.819366,-0.000323,0.003162,0.080314,575.854187,29.335411,0.803140,-456.819366,0.079672,0.000000
152.690002,126.524338,-456.730408,-0.000310,0.003142,0.079802,562.808350,28.670824,0.798022,-456.730408,0.078935,0.000000
153.130005,122.870255,-456.908325,-0.000332,0.003114,0.079092,546.554199,27.842798,0.790922,-456.908325,0.078199,0.000000
153.570007,119.595612,-456.819366,-0.000328,0.003083,0.078320,531.987854,27.100754,0.783201,-456.819366,0.077469,0.000000
154.010010,116.650513,-456.908325,-0.000336,0.003059,0.077704,518.887390,26.433384,0.777039,-456.908325,0.076732,0.000000
154.450012,113.227295,-456.952820,-0.000341,0.003028,0.076915,503.660156,25.657673,0.769151,-456.952820,0.076004,0.000000
154.890015,109.512131,-456.908325,-0.000345,0.002995,0.076073,487.134277,24.815804,0.760734,-456.908325,0.075266,0.000000
155.330002,106.486603,-456.863861,-0.000336,0.002967,0.075371,473.676056,24.130209,0.753709,-456.863861,0.074538,0.000000
155.770004,103.136749,-456.952820,-0.000358,0.002938,0.074617,458.775177,23.371122,0.746169,-456.952820,0.073801,0.000000
156.210007,99.614471,-456.908325,-0.000349,0.002908,0.073854,443.107300,22.572962,0.738539,-456.908325,0.073073,0.000000
156.650009,97.135223,-456.997284,-0.000362,0.002886,0.073298,432.079041,22.011156,0.732983,-456.997284,0.072335,0.000000
157.090012,93.472565,-456.997284,-0.000362,0.002852,0.072449,415.786743,21.181187,0.724489,-456.997284,0.071598,0.000000
157.530014,90.006516,-456.997284,-0.000375,0.002825,0.071754,400.368988,20.395767,0.717540,-456.997284,0.070870,0.000000
157.970001,86.910614,-457.086243,-0.000375,0.002796,0.071018,386.597717,19.694225,0.710183,-457.086243,0.070133,0.000000
158.410004,83.831848,-457.086243,-0.000362,0.002769,0.070323,372.902679,18.996569,0.703233,-457.086243,0.069404,0.000000
158.850006,79.877625,-457.130737,-0.000397,0.002736,0.069483,355.313416,18.100527,0.694831,-457.130737,0.068667,0.000000
159.290009,76.512482,-457.086243,-0.000375,0.002706,0.068720,340.344513,17.337976,0.687201,-457.086243,0.067939,0.000000
159.730011,73.387161,-457.130737,-0.000384,0.002677,0.067990,326.442383,16.629768,0.679903,-457.130737,0.067202,0.000000
160.170013,70.159821,-457.175201,-0.000397,0.002650,0.067306,312.086456,15.898442,0.673060,-457.175201,0.066464,0.000000
160.610001,67.677200,-457.130737,-0.000388,0.002629,0.066769,301.043213,15.335873,0.667686,-457.130737,0.065736,0.000000
161.050003,63.681656,-457.175201,-0.000397,0.002594,0.065875,283.270142,14.430470,0.658753,-457.175201,0.064999,0.000000
161.490005,61.076530,-457.219696,-0.000397,0.002568,0.065215,271.681976,13.840139,0.652153,-457.219696,0.064271,0.000000
161.930008,58.196236,-457.130737,-0.000414,0.002541,0.064531,258.869781,13.187455,0.645309,-457.130737,0.063533,0.000000
162.370010,54.526505,-457.219696,-0.000414,0.002511,0.063768,242.546005,12.355883,0.637679,-457.219696,0.062805,0.000000
162.810013,50.748039,-457.219696,-0.000423,0.002476,0.062900,225.738556,11.499670,0.629004,-457.219696,0.062068,0.000000
163.250015,48.101959,-457.219696,-0.000423,0.002454,0.062337,213.968201,10.900060,0.623372,-457.219696,0.061330,0.000000
163.690002,44.590111,-457.353149,-0.000423,0.002420,0.061479,198.346725,10.104263,0.614788,-457.353149,0.060602,0.000000
164.130005,41.522507,-457.264191,-0.000423,0.002393,0.060793,184.701340,9.409135,0.607930,-457.264191,0.059865,0.000000
164.570007,38.234459,-457.308655,-0.000435,0.002360,0.059935,170.075363,8.664052,0.599346,-457.308655,0.059137,0.000000
165.010010,35.453583,-457.353149,-0.000444,0.002336,0.059327,157.705414,8.033896,0.593275,-457.353149,0.058399,0.000000
165.450012,32.301453,-457.353149,-0.000431,0.002310,0.058686,143.684036,7.319614,0.586856,-457.353149,0.057671,0.000000
165.890015,28.736359,-457.442108,-0.000444,0.002279,0.057879,127.825706,6.511752,0.578786,-457.442108,0.056934,0.000000
166.330002,26.053040,-457.397614,-0.000440,0.002254,0.057255,115.889709,5.903703,0.572549,-457.397614,0.056197,0.000000
166.770004,22.698708,-457.486572,-0.000457,0.002224,0.056492,100.968895,5.143600,0.564918,-457.486572,0.055468,0.000000
167.210007,19.681374,-457.486572,-0.000457,0.002196,0.055780,87.547119,4.459863,0.557803,-457.486572,0.054731,0.000000
167.650009,15.777794,-457.486572,-0.000474,0.002158,0.054801,70.183136,3.575299,0.548007,-457.486572,0.054003,0.000000
168.090012,13.274338,-457.531067,-0.000479,0.002136,0.054263,59.047203,3.008008,0.542633,-457.531067,0.053266,0.000000
168.530014,9.956497,-457.486572,-0.000470,0.002105,0.053473,44.288712,2.256175,0.534730,-457.486572,0.052537,0.000000
168.970001,7.425484,-457.575531,-0.000466,0.002082,0.052875,33.030201,1.682639,0.528750,-457.575531,0.051800,0.000000
169.410004,3.893158,-457.575531,-0.000466,0.002050,0.052068,17.317631,0.882202,0.520680,-457.575531,0.051072,0.000000
169.850006,1.106689,-457.486572,-0.000457,0.002021,0.051340,4.922801,0.250779,0.513398,-457.486572,0.050335,0.000000
170.290009,-1.684982,-457.575531,-0.000492,0.001987,0.050465,-7.495176,-0.381822,0.504648,-457.575531,0.049597,0.000000
170.730011,-0.231239,-457.575531,-0.000487,0.001962,0.049832,-1.028604,-0.052400,0.498319,-457.575531,0.048869,0.000000
171.170013,-0.102028,-457.620026,-0.000535,0.001939,0.049251,-0.453843,-0.023120,0.492506,-457.620026,0.048132,0.000000
171.610001,-0.076706,-457.708984,-0.000539,0.001911,0.048548,-0.341205,-0.017382,0.485481,-457.708984,0.047404,0.000000
172.050003,-0.110222,-457.664520,-0.000578,0.001878,0.047690,-0.490291,-0.024977,0.476897,-457.664520,0.046666,0.000000
172.490005,-0.053246,-457.708984,-0.000608,0.001845,0.046874,-0.236848,-0.012066,0.468737,-457.708984,0.045938,0.000000
172.930008,-0.097557,-457.797943,-0.000612,0.001815,0.046111,-0.433956,-0.022107,0.461106,-457.797943,0.045201,0.000000
173.370010,-0.067772,-457.708984,-0.000634,0.001786,0.045373,-0.301465,-0.015357,0.453733,-457.708984,0.044463,0.000000
173.810013,-0.102028,-457.842438,-0.000681,0.001760,0.044706,-0.453843,-0.023120,0.447057,-457.842438,0.043735,0.000000
174.250015,-0.113197,-457.842438,-0.000651,0.001732,0.043996,-0.503527,-0.025651,0.439956,-457.842438,0.042998,0.000000
174.690002,-0.115807,-457.797943,-0.000686,0.001702,0.043240,-0.515133,-0.026242,0.432402,-457.797943,0.042270,0.000000
175.130005,-0.132935,-457.886902,-0.000698,0.001676,0.042563,-0.591322,-0.030123,0.425634,-457.886902,0.041532,0.000000
175.570007,-0.136658,-457.797943,-0.000698,0.001642,0.041705,-0.607884,-0.030967,0.417050,-457.797943,0.040804,0.000000
176.010010,-0.146713,-457.931396,-0.000733,0.001621,0.041177,-0.652613,-0.033246,0.411766,-457.931396,0.040067,0.000000
176.450012,-0.138893,-457.931396,-0.000742,0.001589,0.040353,-0.617827,-0.031474,0.403530,-457.931396,0.039330,0.000000
176.890015,-0.131073,-457.886902,-0.000780,0.001565,0.039754,-0.583042,-0.029702,0.397535,-457.886902,0.038601,0.000000
177.330002,-0.142616,-458.020355,-0.000802,0.001531,0.038888,-0.634389,-0.032317,0.388875,-458.020355,0.037864,0.000000
177.770004,-0.153419,-457.886902,-0.000811,0.001503,0.038176,-0.682444,-0.034765,0.381760,-457.886902,0.037136,0.000000
178.210007,-0.116554,-457.975861,-0.000858,0.001468,0.037283,-0.518459,-0.026412,0.372827,-457.975861,0.036399,0.000000
178.650009,-0.147461,-457.975861,-0.000862,0.001442,0.036624,-0.655939,-0.033415,0.366242,-457.975861,0.035669,0.000000
179.090012,-0.153046,-457.975861,-0.000875,0.001409,0.035799,-0.680781,-0.034681,0.357991,-457.975861,0.034933,0.000000
179.500015,-0.116180,-458.020355,-0.000901,0.001389,0.035287,-0.516796,-0.026327,0.352873,-458.020355,0.035150,0.000000