File: Data/sima compression 500bar/P1-15-500bar-2_11072024_172505.csv
Time (sec),S:Load (lbs),S:HL1 (DIM),S:LVDT (in),S:Position (in),Ch:Position (mm),Ch:Load (N),Ch:Stress (MPa),Ch:Strain (mm/mm),Ch:HL1 (DIM),Set Point (),Cycles ()
0.010000,-0.093094,-439.338348,-0.009084,-0.006409,-0.162796,-0.414102,-0.021095,-1.627959,-439.338348,-0.162336,0.000000
0.440000,-0.098305,-439.338348,-0.009080,-0.006341,-0.161070,-0.437281,-0.022276,-1.610700,-439.338348,-0.160463,0.000000
0.870000,-0.099419,-439.204926,-0.008959,-0.006085,-0.154557,-0.442236,-0.022529,-1.545569,-439.204926,-0.153299,0.000000
1.300000,-0.127350,-439.293884,-0.008675,-0.005802,-0.147376,-0.566480,-0.028858,-1.473762,-439.293884,-0.146136,0.000000
1.730000,-0.091599,-439.382843,-0.008373,-0.005520,-0.140205,-0.407451,-0.020757,-1.402046,-439.382843,-0.138972,0.000000
2.160000,-0.060326,-439.382843,-0.008071,-0.005235,-0.132971,-0.268342,-0.013670,-1.329709,-439.382843,-0.131810,0.000000
2.590000,-0.080429,-439.382843,-0.007808,-0.004959,-0.125964,-0.357766,-0.018225,-1.259643,-439.382843,-0.124646,0.000000
3.020000,-0.092346,-439.427307,-0.007506,-0.004671,-0.118644,-0.410776,-0.020926,-1.186443,-439.427307,-0.117483,0.000000
3.450000,-0.132561,-439.471802,-0.007222,-0.004396,-0.111654,-0.589660,-0.030039,-1.116544,-439.471802,-0.110319,0.000000
3.880000,-0.074844,-439.471802,-0.006916,-0.004107,-0.104318,-0.332924,-0.016960,-1.043178,-439.471802,-0.103157,0.000000
4.310000,-0.052132,-439.471802,-0.006601,-0.003826,-0.097181,-0.231893,-0.011813,-0.971810,-439.471802,-0.095993,0.000000
4.740000,-0.091599,-439.516266,-0.006334,-0.003547,-0.090105,-0.407451,-0.020757,-0.901047,-439.516266,-0.088830,0.000000
5.170000,-0.125488,-439.516266,-0.006036,-0.003263,-0.082871,-0.558200,-0.028436,-0.828710,-439.516266,-0.081666,0.000000
5.600000,-0.131073,-439.560760,-0.005773,-0.002985,-0.075830,-0.583042,-0.029702,-0.758296,-439.560760,-0.074503,0.000000
6.030000,-0.049522,-439.516266,-0.005458,-0.002698,-0.068519,-0.220287,-0.011222,-0.685187,-439.516266,-0.067339,0.000000
6.460001,-0.033882,-439.605225,-0.005178,-0.002416,-0.061356,-0.150715,-0.007678,-0.613562,-439.605225,-0.060177,0.000000
6.890000,-0.077080,-439.605225,-0.004881,-0.002136,-0.054253,-0.342868,-0.017467,-0.542527,-439.605225,-0.053013,0.000000
7.320000,-0.159370,-439.560760,-0.004600,-0.001855,-0.047116,-0.708915,-0.036114,-0.471159,-439.560760,-0.045850,0.000000
7.750000,-0.112457,-439.649719,-0.004307,-0.001574,-0.039987,-0.500235,-0.025483,-0.399867,-439.649719,-0.038686,0.000000
8.180000,-0.016380,-439.649719,-0.004010,-0.001293,-0.032833,-0.072863,-0.003712,-0.328332,-439.649719,-0.031524,0.000000
8.610001,-0.034630,-439.694214,-0.003725,-0.001008,-0.025600,-0.154041,-0.007847,-0.255995,-439.694214,-0.024360,0.000000
9.040000,-0.077080,-439.738678,-0.003441,-0.000723,-0.018376,-0.342868,-0.017467,-0.183764,-439.738678,-0.017179,0.000000
9.470000,-0.138145,-439.738678,-0.003156,-0.000442,-0.011231,-0.614502,-0.031304,-0.112305,-439.738678,-0.010016,0.000000
9.900001,-0.051010,-439.694214,-0.002859,-0.000163,-0.004136,-0.226904,-0.011559,-0.041361,-439.694214,-0.002852,0.000000
10.330001,0.192146,-439.738678,-0.002669,-0.000000,-0.000008,0.854709,0.043541,-0.000076,-439.738678,0.000165,0.000000
10.760000,0.131447,-439.783173,-0.002682,-0.000001,-0.000017,0.584705,0.029786,-0.000167,-439.783173,0.000226,0.000000
11.190001,0.180603,-439.827637,-0.002690,-0.000001,-0.000017,0.803362,0.040925,-0.000167,-439.827637,0.000946,0.000000
11.620001,0.414825,-439.872131,-0.002669,0.000027,0.000686,1.845236,0.094001,0.006858,-439.872131,0.001658,0.000000
12.050000,0.811775,-439.783173,-0.002634,0.000053,0.001353,3.610956,0.183951,0.013535,-439.783173,0.002377,0.000000
12.480000,1.534546,-439.872131,-0.002621,0.000085,0.002151,6.826001,0.347733,0.021513,-439.872131,0.003096,0.000000
12.910001,2.272964,-439.827637,-0.002600,0.000111,0.002828,10.110651,0.515061,0.028281,-439.827637,0.003808,0.000000
13.340001,3.258636,-439.916595,-0.002583,0.000143,0.003635,14.495139,0.738418,0.036350,-439.916595,0.004528,0.000000
13.770000,4.105782,-439.916595,-0.002557,0.000168,0.004268,18.263428,0.930383,0.042678,-439.916595,0.005247,0.000000
14.200001,5.346901,-439.872131,-0.002557,0.000201,0.005101,23.784203,1.211625,0.051005,-439.872131,0.005959,0.000000
14.630001,6.292351,-439.916595,-0.002514,0.000225,0.005724,27.989775,1.425867,0.057243,-439.916595,0.006678,0.000000
15.060000,7.336113,-440.005554,-0.002496,0.000248,0.006287,32.632660,1.662387,0.062875,-440.005554,0.007390,0.000000
15.490001,8.678886,-440.005554,-0.002479,0.000279,0.007078,38.605614,1.966664,0.070778,-440.005554,0.008109,0.000000
15.920001,9.825424,-440.005554,-0.002471,0.000306,0.007762,43.705669,2.226473,0.077621,-440.005554,0.008829,0.000000
16.350000,11.412102,-440.050049,-0.002440,0.000339,0.008620,50.763565,2.586019,0.086205,-440.050049,0.009541,0.000000
16.780001,12.476341,-440.094543,-0.002414,0.000363,0.009220,55.497540,2.827179,0.092200,-440.094543,0.010260,0.000000
17.210001,13.629951,-440.094543,-0.002410,0.000387,0.009818,60.629051,3.088591,0.098180,-440.094543,0.010979,0.000000
17.640001,15.108269,-440.094543,-0.002389,0.000417,0.010598,67.204933,3.423583,0.105977,-440.094543,0.011691,0.000000
18.070002,16.500946,-440.050049,-0.002380,0.000447,0.011361,73.399872,3.739168,0.113607,-440.050049,0.012411,0.000000
18.500000,17.389053,-440.050049,-0.002354,0.000472,0.011995,77.350372,3.940416,0.119951,-440.050049,0.013131,0.000000
18.930000,18.923599,-440.094543,-0.002324,0.000501,0.012714,84.176376,4.288149,0.127142,-440.094543,0.013842,0.000000
19.360001,20.617149,-440.183502,-0.002302,0.000534,0.013573,91.709663,4.671913,0.135726,-440.183502,0.014561,0.000000
19.790001,21.408440,-440.183502,-0.002289,0.000558,0.014163,95.229492,4.851222,0.141631,-440.183502,0.015282,0.000000
20.220001,22.954529,-440.227966,-0.002272,0.000589,0.014961,102.106842,5.201571,0.149609,-440.227966,0.015992,0.000000
20.650002,24.085052,-440.183502,-0.002238,0.000617,0.015680,107.135666,5.457751,0.156801,-440.183502,0.016713,0.000000
21.080002,24.837616,-440.272461,-0.002220,0.000642,0.016296,110.483231,5.628284,0.162962,-440.272461,0.017423,0.000000
21.510000,26.044479,-440.316925,-0.002186,0.000672,0.017076,115.851631,5.901763,0.170759,-440.316925,0.018143,0.000000
21.940001,26.741554,-440.361420,-0.002169,0.000695,0.017641,118.952377,6.059723,0.176406,-440.361420,0.018862,0.000000
22.370001,28.054916,-440.272461,-0.002151,0.000729,0.018516,124.794502,6.357335,0.185157,-440.272461,0.019574,0.000000
22.800001,29.317627,-440.272461,-0.002121,0.000759,0.019288,130.411316,6.643469,0.192878,-440.272461,0.020293,0.000000
23.230001,30.124191,-440.405884,-0.002100,0.000788,0.020007,133.999100,6.826240,0.200070,-440.405884,0.021014,0.000000
23.660002,30.715141,-440.450378,-0.002078,0.000815,0.020693,136.627777,6.960151,0.206928,-440.450378,0.021725,0.000000
24.090002,31.491165,-440.450378,-0.002044,0.000842,0.021379,140.079697,7.136000,0.213786,-440.450378,0.022444,0.000000
24.520000,32.652596,-440.405884,-0.002031,0.000874,0.022210,145.246002,7.399184,0.222098,-440.405884,0.023165,0.000000
24.950001,32.772873,-440.450378,-0.001988,0.000896,0.022749,145.781021,7.426439,0.227487,-440.450378,0.023875,0.000000
25.380001,33.675133,-440.583832,-0.001979,0.000927,0.023538,149.794479,7.630894,0.235375,-440.583832,0.024596,0.000000
25.810001,34.315987,-440.494873,-0.001936,0.000954,0.024222,152.645126,7.776114,0.242218,-440.494873,0.025315,0.000000
26.240002,34.448547,-440.539337,-0.001910,0.000980,0.024882,153.234787,7.806152,0.248819,-440.539337,0.026026,0.000000
26.670002,35.530663,-440.494873,-0.001888,0.001007,0.025575,158.048279,8.051363,0.255753,-440.494873,0.026746,0.000000
27.100000,36.697678,-440.494873,-0.001858,0.001044,0.026529,163.239426,8.315812,0.265291,-440.494873,0.027457,0.000000
27.530001,36.571075,-440.539337,-0.001824,0.001066,0.027076,162.676270,8.287125,0.270756,-440.539337,0.028176,0.000000
27.960001,36.463829,-440.717255,-0.001811,0.001085,0.027562,162.199219,8.262821,0.275616,-440.717255,0.028897,0.000000
28.390001,37.980133,-440.628296,-0.001781,0.001121,0.028481,168.944077,8.606421,0.284806,-440.628296,0.029608,0.000000
28.820002,37.795807,-440.628296,-0.001759,0.001144,0.029070,168.124146,8.564652,0.290695,-440.628296,0.030328,0.000000
29.250002,38.920372,-440.628296,-0.001720,0.001179,0.029946,173.126465,8.819483,0.299461,-440.628296,0.031047,0.000000
29.680002,39.331474,-440.672791,-0.001681,0.001208,0.030683,174.955139,8.912640,0.306834,-440.672791,0.031758,0.000000
30.110001,39.745918,-440.761749,-0.001651,0.001235,0.031360,176.798676,9.006555,0.313601,-440.761749,0.032479,0.000000
30.540001,40.075096,-440.761749,-0.001621,0.001259,0.031967,178.262924,9.081147,0.319672,-440.761749,0.033198,0.000000
30.970001,41.274879,-440.761749,-0.001604,0.001292,0.032826,183.599838,9.353022,0.328256,-440.761749,0.033910,0.000000
31.400002,41.574272,-440.761749,-0.001561,0.001319,0.033510,184.931595,9.420865,0.335099,-440.761749,0.034629,0.000000
31.830002,41.985741,-440.806213,-0.001544,0.001346,0.034196,186.761902,9.514105,0.341958,-440.806213,0.035349,0.000000
32.260002,42.240814,-440.806213,-0.001509,0.001377,0.034968,187.896530,9.571905,0.349679,-440.806213,0.036059,0.000000
32.690002,43.519547,-440.895172,-0.001487,0.001410,0.035808,193.584610,9.861670,0.358081,-440.895172,0.036780,0.000000
33.120003,43.994316,-440.850708,-0.001462,0.001437,0.036494,195.696487,9.969254,0.364940,-440.850708,0.037499,0.000000
33.550003,44.491806,-440.806213,-0.001449,0.001465,0.037213,197.909439,10.081987,0.372131,-440.806213,0.038211,0.000000
33.980003,44.853012,-440.939667,-0.001423,0.001489,0.037820,199.516159,10.163837,0.378202,-440.939667,0.038930,0.000000
34.410000,45.649513,-440.984161,-0.001380,0.001518,0.038557,203.059174,10.344327,0.385575,-440.984161,0.039641,0.000000
34.840000,46.856003,-440.939667,-0.001362,0.001550,0.039381,208.425903,10.617722,0.393811,-440.939667,0.040362,0.000000
35.270000,47.292046,-440.939667,-0.001332,0.001577,0.040058,210.365524,10.716530,0.400578,-440.939667,0.041081,0.000000
35.700001,48.357033,-440.984161,-0.001298,0.001610,0.040881,215.102829,10.957860,0.408814,-440.984161,0.041793,0.000000
36.130001,48.427788,-441.028625,-0.001263,0.001630,0.041402,215.417557,10.973893,0.414022,-441.028625,0.042512,0.000000
36.560001,48.340652,-440.984161,-0.001263,0.001649,0.041879,215.029968,10.954148,0.418791,-440.984161,0.043233,0.000000
36.990002,50.570786,-441.117584,-0.001224,0.001690,0.042919,224.950089,11.459504,0.429192,-441.117584,0.043943,0.000000
37.420002,51.441025,-441.028625,-0.001212,0.001716,0.043596,228.821106,11.656702,0.435959,-441.028625,0.044663,0.000000
37.850002,52.202896,-441.073120,-0.001164,0.001742,0.044255,232.210083,11.829346,0.442545,-441.073120,0.045382,0.000000
38.280003,53.304749,-441.117584,-0.001147,0.001772,0.045019,237.111359,12.079028,0.450191,-441.117584,0.046094,0.000000
38.710003,54.218178,-441.162079,-0.001138,0.001799,0.045703,241.174500,12.286015,0.457034,-441.162079,0.046813,0.000000
39.140003,55.273483,-441.117584,-0.001117,0.001828,0.046424,245.868729,12.525150,0.464240,-441.117584,0.047534,0.000000
39.570004,56.357086,-441.117584,-0.001095,0.001859,0.047222,250.688843,12.770699,0.472219,-441.117584,0.048244,0.000000
40.000000,57.212799,-441.162079,-0.001061,0.001885,0.047890,254.495239,12.964605,0.478895,-441.162079,0.048964,0.000000
40.430000,58.078194,-441.162079,-0.001043,0.001909,0.048488,258.344696,13.160707,0.484875,-441.162079,0.049676,0.000000
40.860001,59.347237,-441.251038,-0.001035,0.001939,0.049251,263.989685,13.448277,0.492506,-441.251038,0.050395,0.000000
41.290001,60.126236,-441.206543,-0.001013,0.001966,0.049927,267.454865,13.624800,0.499273,-441.206543,0.051116,0.000000
41.720001,61.293251,-441.251038,-0.000983,0.001992,0.050595,272.645996,13.889250,0.505950,-441.251038,0.051826,0.000000
42.150002,63.162933,-441.251038,-0.000970,0.002026,0.051470,280.962769,14.312925,0.514700,-441.251038,0.052546,0.000000
42.580002,63.983643,-441.295502,-0.000923,0.002056,0.052233,284.613464,14.498901,0.522331,-441.295502,0.053266,0.000000
43.010002,65.435150,-441.339996,-0.000914,0.002085,0.052963,291.070099,14.827816,0.529628,-441.339996,0.053977,0.000000
43.440002,65.753525,-441.339996,-0.000884,0.002102,0.053396,292.486298,14.899961,0.533958,-441.339996,0.054696,0.000000
43.870003,67.682800,-441.339996,-0.000867,0.002139,0.054333,301.068146,15.337142,0.543329,-441.339996,0.055417,0.000000
44.300003,69.058334,-441.339996,-0.000849,0.002168,0.055061,307.186798,15.648842,0.550611,-441.339996,0.056127,0.000000
44.730003,70.114380,-441.428955,-0.000824,0.002195,0.055764,311.884338,15.888145,0.557636,-441.428955,0.056848,0.000000
45.160004,70.920944,-441.428955,-0.000806,0.002219,0.056362,315.472107,16.070915,0.563616,-441.428955,0.057567,0.000000
45.590004,72.255157,-441.473450,-0.000785,0.002248,0.057108,321.406982,16.373253,0.571080,-441.473450,0.058278,0.000000
46.020000,74.247726,-441.384491,-0.000759,0.002282,0.057966,330.270386,16.824776,0.579664,-441.384491,0.058997,0.000000
46.450001,75.300049,-441.473450,-0.000742,0.002310,0.058676,334.951355,17.063234,0.586765,-441.473450,0.059718,0.000000
46.880001,76.489029,-441.562408,-0.000716,0.002338,0.059379,340.240204,17.332661,0.593789,-441.562408,0.060430,0.000000
47.310001,77.485504,-441.562408,-0.000703,0.002360,0.059935,344.672729,17.558466,0.599346,-441.562408,0.061149,0.000000
47.740002,79.215546,-441.517914,-0.000686,0.002393,0.060784,352.368347,17.950500,0.607839,-441.517914,0.061860,0.000000
48.170002,80.379211,-441.517914,-0.000651,0.002417,0.061391,357.544586,18.214190,0.613910,-441.517914,0.062579,0.000000
48.600002,82.297302,-441.606873,-0.000625,0.002450,0.062224,366.076691,18.648834,0.622237,-441.606873,0.063300,0.000000
49.030003,82.945969,-441.651367,-0.000621,0.002471,0.062761,368.962097,18.795826,0.627611,-441.651367,0.064010,0.000000
49.460003,84.041122,-441.606873,-0.000608,0.002501,0.063533,373.833588,19.043989,0.635332,-441.606873,0.064731,0.000000
49.890003,86.234756,-441.651367,-0.000591,0.002527,0.064184,383.591370,19.541077,0.641842,-441.651367,0.065450,0.000000
50.320004,89.040222,-441.606873,-0.000552,0.002567,0.065199,396.070679,20.176802,0.651986,-441.606873,0.066161,0.000000
50.750004,89.439026,-441.651367,-0.000552,0.002585,0.065666,397.844666,20.267174,0.656664,-441.651367,0.066881,0.000000
51.180004,91.178375,-441.740326,-0.000548,0.002612,0.066336,405.581665,20.661316,0.663356,-441.740326,0.067601,0.000000
51.610001,93.025711,-441.740326,-0.000522,0.002643,0.067141,413.799042,21.079927,0.671410,-441.740326,0.068313,0.000000
52.040001,94.862625,-441.695831,-0.000513,0.002673,0.067887,421.970032,21.496178,0.678874,-441.695831,0.069032,0.000000
52.470001,97.322891,-441.740326,-0.000474,0.002704,0.068676,432.913849,22.053682,0.686762,-441.740326,0.069751,0.000000
52.900002,98.736420,-441.740326,-0.000474,0.002732,0.069397,439.201538,22.373991,0.693968,-441.740326,0.070463,0.000000
53.330002,100.400558,-441.740326,-0.000448,0.002756,0.070011,446.604004,22.751091,0.700115,-441.740326,0.071183,0.000000
53.760002,102.386414,-441.829285,-0.000435,0.002787,0.070784,455.437500,23.201094,0.707836,-441.829285,0.071893,0.000000
54.190002,103.954483,-441.829285,-0.000418,0.002811,0.071400,462.412628,23.556423,0.713998,-441.829285,0.072614,0.000000
54.620003,106.165253,-441.873779,-0.000405,0.002842,0.072198,472.246643,24.057390,0.721976,-441.873779,0.073333,0.000000
55.050003,107.944443,-441.829285,-0.000397,0.002870,0.072900,480.160858,24.460560,0.729001,-441.829285,0.074045,0.000000
55.480003,109.031036,-441.873779,-0.000375,0.002890,0.073412,484.994263,24.706785,0.734118,-441.873779,0.074764,0.000000
55.910004,112.280350,-441.873779,-0.000375,0.002931,0.074452,499.447937,25.443090,0.744519,-441.873779,0.075484,0.000000
56.340004,113.984695,-441.918243,-0.000345,0.002957,0.075110,507.029236,25.829302,0.751105,-441.918243,0.076194,0.000000
56.770004,115.955673,-441.873779,-0.000323,0.002985,0.075822,515.796570,26.275932,0.758220,-441.873779,0.076915,0.000000
57.200005,118.114319,-442.007202,-0.000328,0.003013,0.076543,525.398743,26.765089,0.765427,-442.007202,0.077634,0.000000
57.630001,119.340912,-442.007202,-0.000323,0.003036,0.077123,530.854858,27.043036,0.771225,-442.007202,0.078346,0.000000
58.060001,121.972092,-442.096161,-0.000315,0.003067,0.077913,542.558960,27.639271,0.779128,-442.096161,0.079066,0.000000
58.490002,124.330322,-442.007202,-0.000297,0.003097,0.078658,553.048889,28.173655,0.786577,-442.007202,0.079786,0.000000
58.920002,126.263687,-442.007202,-0.000280,0.003122,0.079291,561.648926,28.611759,0.792905,-442.007202,0.080497,0.000000
59.350002,127.830261,-442.096161,-0.000254,0.003144,0.079863,568.617371,28.966751,0.798628,-442.096161,0.081216,0.000000
59.780003,130.471497,-442.140656,-0.000263,0.003178,0.080714,580.366211,29.565264,0.807136,-442.140656,0.081928,0.000000
60.210003,132.852814,-442.140656,-0.000267,0.003205,0.081398,590.958801,30.104877,0.813980,-442.140656,0.082647,0.000000
60.640003,135.300797,-442.096161,-0.000229,0.003237,0.082223,601.848022,30.659597,0.822231,-442.096161,0.083368,0.000000
61.070004,137.351440,-442.140656,-0.000216,0.003261,0.082838,610.969727,31.124281,0.828377,-442.140656,0.084078,0.000000
61.500004,139.830322,-442.229614,-0.000211,0.003291,0.083601,621.996338,31.686003,0.836008,-442.229614,0.084798,0.000000
61.930004,142.320755,-442.140656,-0.000207,0.003324,0.084433,633.074341,32.250343,0.844334,-442.140656,0.085517,0.000000
62.360004,144.124161,-442.185120,-0.000190,0.003346,0.084989,641.096313,32.659004,0.849891,-442.185120,0.086229,0.000000
62.790005,146.189331,-442.229614,-0.000185,0.003370,0.085605,650.282593,33.126976,0.856052,-442.229614,0.086948,0.000000
63.220001,148.329361,-442.274109,-0.000177,0.003396,0.086255,659.801941,33.611916,0.862547,-442.274109,0.087669,0.000000
63.650002,151.356750,-442.274109,-0.000160,0.003429,0.087087,673.268433,34.297928,0.870874,-442.274109,0.088380,0.000000
64.080002,154.312637,-442.318573,-0.000160,0.003463,0.087964,686.416870,34.967743,0.879640,-442.318573,0.089099,0.000000
64.510002,156.569962,-442.363068,-0.000160,0.003488,0.088606,696.457947,35.479263,0.886059,-442.363068,0.089819,0.000000
64.940002,157.547440,-442.274109,-0.000142,0.003501,0.088918,700.806030,35.700760,0.889178,-442.274109,0.090530,0.000000
65.370003,161.483414,-442.363068,-0.000134,0.003546,0.090071,718.314087,36.592663,0.900714,-442.363068,0.091251,0.000000
65.800003,164.260193,-442.407532,-0.000134,0.003575,0.090816,730.665833,37.221893,0.908163,-442.407532,0.091970,0.000000
66.230003,166.640778,-442.363068,-0.000134,0.003602,0.091493,741.255188,37.761341,0.914930,-442.363068,0.092681,0.000000
66.660004,168.535782,-442.452026,-0.000112,0.003625,0.092074,749.684570,38.190754,0.920744,-442.452026,0.093401,0.000000
67.090004,171.117813,-442.407532,-0.000095,0.003653,0.092794,761.170044,38.775852,0.927935,-442.407532,0.094112,0.000000
67.520004,174.200684,-442.407532,-0.000099,0.003684,0.093575,774.883362,39.474438,0.935747,-442.407532,0.094831,0.000000
67.950005,176.948044,-442.496490,-0.000108,0.003713,0.094320,787.104187,40.097000,0.943196,-442.496490,0.095552,0.000000
68.380005,179.729660,-442.452026,-0.000108,0.003744,0.095110,799.477478,40.727325,0.951099,-442.452026,0.096264,0.000000
68.810005,181.583344,-442.496490,-0.000095,0.003766,0.095664,807.723022,41.147373,0.956640,-442.496490,0.096983,0.000000
69.240005,185.141357,-442.540985,-0.000065,0.003803,0.096592,823.549866,41.953629,0.965920,-442.540985,0.097702,0.000000
69.670006,187.200943,-442.540985,-0.000069,0.003827,0.097217,832.711365,42.420338,0.972173,-442.540985,0.098413,0.000000
70.100006,189.790054,-442.585449,-0.000060,0.003853,0.097859,844.228333,43.007042,0.978592,-442.585449,0.099134,0.000000
70.530006,191.520844,-442.629944,-0.000060,0.003873,0.098369,851.927246,43.399242,0.983694,-442.629944,0.099853,0.000000
70.960007,194.240662,-442.540985,-0.000069,0.003899,0.099039,864.025635,44.015564,0.990386,-442.540985,0.100565,0.000000
71.390007,197.257996,-442.585449,-0.000039,0.003932,0.099870,877.447388,44.699299,0.998698,-442.585449,0.101284,0.000000
71.820000,201.039795,-442.629944,-0.000034,0.003968,0.100790,894.269653,45.556271,1.007902,-442.629944,0.102004,0.000000
72.250000,203.083740,-442.674438,-0.000056,0.003991,0.101379,903.361572,46.019432,1.013792,-442.674438,0.102714,0.000000
72.680000,204.983582,-442.674438,-0.000043,0.004009,0.101830,911.812500,46.449944,1.018303,-442.674438,0.103435,0.000000
73.110001,208.670441,-442.674438,-0.000039,0.004048,0.102810,928.212463,47.285400,1.028099,-442.674438,0.104145,0.000000
73.540001,211.439789,-442.718903,-0.000022,0.004078,0.103591,940.531128,47.912941,1.035911,-442.718903,0.104866,0.000000
73.970001,214.504791,-442.718903,-0.000026,0.004105,0.104268,954.164978,48.607479,1.042678,-442.718903,0.105585,0.000000
74.400002,217.921295,-442.763397,-0.000026,0.004139,0.105126,969.362305,49.381672,1.051262,-442.763397,0.106297,0.000000
74.830002,219.769379,-442.763397,-0.000022,0.004156,0.105550,977.583008,49.800453,1.055501,-442.763397,0.107016,0.000000
75.260002,221.283813,-442.763397,-0.000004,0.004163,0.105733,984.319580,50.143631,1.057333,-442.763397,0.018573,0.000000
75.690002,220.799011,-442.807861,0.000004,0.004147,0.105325,982.163025,50.033772,1.053245,-442.807861,982.000671,0.000000
76.120003,220.397949,-442.896820,0.000026,0.004147,0.105325,980.379028,49.942886,1.053245,-442.896820,982.000671,0.000000
76.550003,220.090759,-442.896820,0.000000,0.004147,0.105325,979.012573,49.873276,1.053245,-442.896820,982.000671,0.000000
76.980003,219.762299,-442.896820,0.000004,0.004147,0.105325,977.551514,49.798847,1.053245,-442.896820,982.000671,0.000000
77.410004,219.445435,-442.896820,0.000004,0.004147,0.105325,976.142029,49.727043,1.053245,-442.896820,982.000671,0.000000
77.840004,220.014038,-442.896820,0.000004,0.004176,0.106062,978.671326,49.855892,1.060618,-442.896820,982.000671,0.000000
78.270004,219.831940,-442.941315,0.000017,0.004174,0.106027,977.861328,49.814629,1.060270,-442.941315,982.000671,0.000000
78.700005,219.596985,-442.985779,-0.000009,0.004174,0.106027,976.816162,49.761391,1.060270,-442.985779,982.000671,0.000000
79.130005,219.372070,-442.985779,0.000009,0.004174,0.106027,975.815735,49.710423,1.060270,-442.985779,982.000671,0.000000
79.560005,219.154602,-442.985779,0.000017,0.004174,0.106027,974.848328,49.661140,1.060270,-442.985779,982.000671,0.000000
79.990005,220.308960,-442.985779,0.000013,0.004188,0.106383,979.983215,49.922726,1.063828,-442.985779,982.000671,0.000000
80.420006,220.163727,-443.119232,-0.000004,0.004188,0.106383,979.337158,49.889816,1.063828,-443.119232,982.000671,0.000000
80.850006,220.012543,-443.119232,0.000013,0.004188,0.106383,978.664673,49.855556,1.063828,-443.119232,982.000671,0.000000
81.280006,219.850555,-443.074768,0.000017,0.004188,0.106383,977.944092,49.818848,1.063828,-443.074768,982.000671,0.000000
81.710007,219.669586,-443.074768,0.000009,0.004189,0.106392,977.139099,49.777840,1.063919,-443.074768,982.000671,0.000000
82.140007,219.514313,-443.119232,0.000026,0.004189,0.106392,976.448425,49.742653,1.063919,-443.119232,982.000671,0.000000
82.570007,219.345245,-443.163727,0.000009,0.004189,0.106392,975.696411,49.704346,1.063919,-443.163727,982.000671,0.000000
83.000008,219.189606,-443.163727,0.000017,0.004189,0.106392,975.004089,49.669075,1.063919,-443.163727,982.000671,0.000000
83.430000,220.800873,-443.119232,0.000013,0.004193,0.106496,982.171326,50.034195,1.064963,-443.119232,982.000671,0.000000
83.860001,220.626953,-443.208191,0.000009,0.004192,0.106478,981.397705,49.994781,1.064782,-443.208191,982.000671,0.000000
84.290001,220.451935,-443.297150,0.000022,0.004192,0.106478,980.619202,49.955124,1.064782,-443.297150,982.000671,0.000000
84.720001,220.319763,-443.297150,0.000022,0.004192,0.106478,980.031250,49.925171,1.064782,-443.297150,982.000671,0.000000
85.150002,220.151825,-443.341644,0.000017,0.004192,0.106478,979.284241,49.887115,1.064782,-443.341644,982.000671,0.000000
85.580002,220.020355,-443.208191,0.000030,0.004192,0.106478,978.699402,49.857323,1.064782,-443.208191,982.000671,0.000000
86.010002,219.869171,-443.297150,0.000047,0.004192,0.106478,978.026917,49.823067,1.064782,-443.297150,982.000671,0.000000
86.440002,219.756714,-443.386108,0.000034,0.004192,0.106487,977.526672,49.797585,1.064873,-443.386108,982.000671,0.000000
86.870003,219.596619,-443.386108,0.000039,0.004192,0.106487,976.814575,49.761307,1.064873,-443.386108,982.000671,0.000000
87.300003,219.482666,-443.430603,0.000034,0.004192,0.106487,976.307678,49.735485,1.064873,-443.430603,982.000671,0.000000
87.730003,219.915344,-443.341644,0.000034,0.004209,0.106920,978.232300,49.833530,1.069203,-443.341644,982.000671,0.000000
88.160004,219.857635,-443.430603,0.000026,0.004209,0.106920,977.975586,49.820454,1.069203,-443.430603,982.000671,0.000000
88.590004,219.800293,-443.475067,0.000034,0.004209,0.106920,977.720520,49.807461,1.069203,-443.475067,982.000671,0.000000
89.020004,219.688568,-443.519562,0.000026,0.004209,0.106920,977.223572,49.782143,1.069203,-443.519562,982.000671,0.000000
89.450005,219.609253,-443.475067,0.000017,0.004209,0.106920,976.870728,49.764168,1.069203,-443.475067,982.000671,0.000000
89.880005,219.536285,-443.475067,0.000034,0.004211,0.106955,976.546143,49.747635,1.069551,-443.475067,982.000671,0.000000
90.310005,219.538879,-443.475067,0.000034,0.004212,0.106982,976.557678,49.748222,1.069823,-443.475067,982.000671,0.000000
90.740005,219.492340,-443.608521,0.000030,0.004212,0.106982,976.350708,49.737675,1.069823,-443.608521,982.000671,0.000000
91.170006,219.499054,-443.564056,0.000034,0.004214,0.107034,976.380554,49.739197,1.070338,-443.564056,982.000671,0.000000
91.600006,219.527344,-443.608521,0.000034,0.004214,0.107043,976.506409,49.745609,1.070429,-443.608521,982.000671,0.000000
92.030006,219.490479,-443.608521,0.000047,0.004214,0.107043,976.342407,49.737255,1.070429,-443.608521,982.000671,0.000000
92.460007,219.419739,-443.653015,0.000043,0.004214,0.107043,976.027771,49.721222,1.070429,-443.653015,982.000671,0.000000
92.890007,219.812225,-443.741974,0.000039,0.004220,0.107199,977.773621,49.810162,1.071988,-443.741974,982.000671,0.000000
93.320007,219.817413,-443.741974,0.000034,0.004220,0.107199,977.796692,49.811340,1.071988,-443.741974,982.000671,0.000000
93.750008,219.796936,-443.653015,0.000034,0.004220,0.107199,977.705627,49.806698,1.071988,-443.653015,982.000671,0.000000
94.180008,219.758209,-443.697479,0.000043,0.004220,0.107199,977.533325,49.797924,1.071988,-443.697479,982.000671,0.000000
94.610008,219.683380,-443.741974,0.000039,0.004220,0.107199,977.200500,49.780968,1.071988,-443.741974,982.000671,0.000000
95.040001,219.633484,-443.741974,0.000047,0.004220,0.107199,976.978516,49.769661,1.071988,-443.741974,982.000671,0.000000
95.470001,219.570526,-443.741974,0.000043,0.004220,0.107199,976.698486,49.755390,1.071988,-443.741974,982.000671,0.000000
95.900002,219.520630,-443.741974,0.000043,0.004221,0.107208,976.476501,49.744087,1.072079,-443.741974,982.000671,0.000000
96.330002,219.487122,-443.786438,0.000052,0.004222,0.107234,976.327454,49.736496,1.072336,-443.786438,982.000671,0.000000
96.760002,219.452484,-443.830933,0.000052,0.004225,0.107311,976.173401,49.728642,1.073109,-443.830933,982.000671,0.000000
97.190002,219.624176,-443.830933,0.000056,0.004225,0.107311,976.937134,49.767548,1.073109,-443.830933,982.000671,0.000000
97.620003,219.604797,-443.875397,0.000034,0.004225,0.107311,976.850952,49.763161,1.073109,-443.875397,982.000671,0.000000
98.050003,219.582458,-443.830933,0.000043,0.004225,0.107320,976.751587,49.758099,1.073199,-443.830933,982.000671,0.000000
98.480003,219.534424,-443.875397,0.000069,0.004225,0.107320,976.537903,49.747211,1.073199,-443.875397,982.000671,0.000000
98.910004,219.549683,-443.964386,0.000052,0.004226,0.107346,976.605774,49.750671,1.073457,-443.964386,982.000671,0.000000
99.340004,219.613373,-444.053345,0.000056,0.004228,0.107399,976.889099,49.765102,1.073987,-444.053345,982.000671,0.000000
99.770004,219.607788,-444.008850,0.000056,0.004228,0.107399,976.864258,49.763836,1.073987,-444.008850,982.000671,0.000000
100.200005,219.591400,-443.919891,0.000030,0.004228,0.107399,976.791321,49.760124,1.073987,-443.919891,982.000671,0.000000
100.630005,219.699371,-443.964386,0.000065,0.004230,0.107450,977.271606,49.784592,1.074501,-443.964386,982.000671,0.000000
101.060005,219.697906,-444.097809,0.000060,0.004230,0.107450,977.265076,49.784260,1.074501,-444.097809,982.000671,0.000000
101.490005,219.669952,-444.142303,0.000060,0.004230,0.107450,977.140747,49.777924,1.074501,-444.142303,982.000671,0.000000
101.920006,219.636810,-444.053345,0.000056,0.004230,0.107450,976.993347,49.770412,1.074501,-444.053345,982.000671,0.000000
102.350006,219.605164,-444.053345,0.000052,0.004230,0.107450,976.852539,49.763241,1.074501,-444.053345,982.000671,0.000000
102.780006,219.573883,-444.053345,0.000056,0.004231,0.107459,976.713440,49.756153,1.074592,-444.053345,982.000671,0.000000
103.210007,219.523254,-444.142303,0.000047,0.004231,0.107467,976.488220,49.744678,1.074668,-444.142303,982.000671,0.000000
103.640007,219.544098,-444.186768,0.000056,0.004232,0.107494,976.580933,49.749405,1.074940,-444.186768,982.000671,0.000000
104.070007,219.540375,-444.097809,0.000052,0.004232,0.107494,976.564331,49.748562,1.074940,-444.097809,982.000671,0.000000
104.500008,219.576508,-444.142303,0.000052,0.004234,0.107555,976.725098,49.756748,1.075546,-444.142303,982.000671,0.000000
104.930008,219.657318,-444.186768,0.000056,0.004235,0.107562,977.084534,49.775059,1.075622,-444.186768,982.000671,0.000000
105.360008,219.668488,-444.275726,0.000047,0.004235,0.107562,977.134216,49.777588,1.075622,-444.275726,982.000671,0.000000
105.790009,219.640930,-444.275726,0.000060,0.004235,0.107562,977.011658,49.771343,1.075622,-444.275726,982.000671,0.000000
106.220009,219.631226,-444.275726,0.000052,0.004235,0.107562,976.968506,49.769146,1.075622,-444.275726,982.000671,0.000000
106.650002,219.598083,-444.320221,0.000069,0.004235,0.107580,976.821045,49.761635,1.075803,-444.320221,982.000671,0.000000
107.080002,219.613373,-444.320221,0.000060,0.004236,0.107589,976.889099,49.765102,1.075894,-444.320221,982.000671,0.000000
107.510002,219.599213,-444.364716,0.000060,0.004236,0.107589,976.826111,49.761894,1.075894,-444.364716,982.000671,0.000000
107.940002,219.574646,-444.364716,0.000047,0.004236,0.107597,976.716797,49.756329,1.075970,-444.364716,982.000671,0.000000
108.370003,219.605530,-444.364716,0.000056,0.004237,0.107623,976.854187,49.763325,1.076227,-444.364716,982.000671,0.000000
108.800003,219.588409,-444.409180,0.000060,0.004237,0.107623,976.778015,49.759445,1.076227,-444.409180,982.000671,0.000000
109.230003,219.576508,-444.409180,0.000056,0.004237,0.107623,976.725098,49.756748,1.076227,-444.409180,982.000671,0.000000
109.660004,219.558258,-444.542633,0.000060,0.004237,0.107623,976.643921,49.752613,1.076227,-444.542633,982.000671,0.000000
110.090004,219.589172,-444.453674,0.000069,0.004238,0.107658,976.781433,49.759617,1.076576,-444.453674,982.000671,0.000000
110.520004,219.596985,-444.498138,0.000073,0.004238,0.107658,976.816162,49.761391,1.076576,-444.498138,982.000671,0.000000
110.950005,219.582458,-444.453674,0.000069,0.004239,0.107667,976.751587,49.758099,1.076666,-444.453674,982.000671,0.000000
111.380005,219.550446,-444.587097,0.000069,0.004239,0.107667,976.609131,49.750843,1.076666,-444.587097,982.000671,0.000000
111.810005,219.539642,-444.587097,0.000065,0.004239,0.107667,976.561096,49.748394,1.076666,-444.587097,982.000671,0.000000
112.240005,219.569794,-444.587097,0.000073,0.004240,0.107692,976.695251,49.755226,1.076924,-444.587097,982.000671,0.000000
112.670006,219.560486,-444.587097,0.000056,0.004240,0.107692,976.653809,49.753117,1.076924,-444.587097,982.000671,0.000000
113.100006,219.547821,-444.676056,0.000056,0.004240,0.107692,976.597473,49.750248,1.076924,-444.676056,982.000671,0.000000
113.530006,219.507996,-444.676056,0.000073,0.004241,0.107711,976.420349,49.741222,1.077105,-444.676056,982.000671,0.000000
113.960007,219.530701,-444.720551,0.000060,0.004241,0.107718,976.521301,49.746368,1.077181,-444.720551,982.000671,0.000000
114.390007,219.543732,-444.720551,0.000056,0.004241,0.107727,976.579285,49.749321,1.077272,-444.720551,982.000671,0.000000
114.820007,219.549316,-444.720551,0.000086,0.004241,0.107727,976.604126,49.750587,1.077272,-444.720551,982.000671,0.000000
115.250008,219.522125,-444.720551,0.000082,0.004241,0.107727,976.483154,49.744423,1.077272,-444.720551,982.000671,0.000000
115.680008,219.506866,-444.720551,0.000065,0.004241,0.107727,976.415283,49.740971,1.077272,-444.720551,982.000671,0.000000
116.110008,219.482666,-444.765015,0.000073,0.004241,0.107727,976.307678,49.735485,1.077272,-444.765015,982.000671,0.000000
116.540009,219.462921,-444.809509,0.000082,0.004241,0.107727,976.219849,49.731010,1.077272,-444.809509,982.000671,0.000000
116.970009,219.442444,-444.765015,0.000082,0.004241,0.107727,976.128723,49.726368,1.077272,-444.765015,982.000671,0.000000
117.400009,219.410431,-444.854004,0.000073,0.004241,0.107727,975.986328,49.719116,1.077272,-444.854004,982.000671,0.000000
117.830002,219.395905,-444.898468,0.000060,0.004243,0.107762,975.921753,49.715824,1.077620,-444.898468,982.000671,0.000000
118.260002,219.641296,-444.942963,0.000060,0.004246,0.107841,977.013306,49.771431,1.078407,-444.942963,982.000671,0.000000
118.690002,219.671814,-444.898468,0.000078,0.004246,0.107841,977.149048,49.778347,1.078407,-444.898468,982.000671,0.000000
119.120003,219.676300,-444.898468,0.000078,0.004246,0.107841,977.169006,49.779362,1.078407,-444.898468,982.000671,0.000000
119.550003,219.665863,-444.942963,0.000065,0.004246,0.107841,977.122559,49.776993,1.078407,-444.942963,982.000671,0.000000
119.980003,219.674072,-445.031921,0.000069,0.004246,0.107841,977.159058,49.778854,1.078407,-445.031921,982.000671,0.000000
120.410004,219.639435,-444.987427,0.000065,0.004246,0.107841,977.005005,49.771008,1.078407,-444.987427,982.000671,0.000000
120.840004,219.626038,-445.031921,0.000086,0.004246,0.107841,976.945435,49.767971,1.078407,-445.031921,982.000671,0.000000
121.270004,219.602570,-444.987427,0.000078,0.004246,0.107841,976.841003,49.762653,1.078407,-444.987427,982.000671,0.000000
121.700005,219.597717,-445.120880,0.000082,0.004246,0.107841,976.819458,49.761555,1.078407,-445.120880,982.000671,0.000000
122.130005,219.582458,-445.120880,0.000065,0.004246,0.107841,976.751587,49.758099,1.078407,-445.120880,982.000671,0.000000
122.560005,219.564209,-445.120880,0.000069,0.004246,0.107841,976.670410,49.753960,1.078407,-445.120880,982.000671,0.000000
122.990005,219.545959,-445.165344,0.000073,0.004246,0.107841,976.589172,49.749828,1.078407,-445.165344,982.000671,0.000000
123.420006,219.529205,-445.120880,0.000078,0.004246,0.107841,976.514648,49.746029,1.078407,-445.120880,982.000671,0.000000
123.850006,219.512085,-445.209839,0.000069,0.004246,0.107841,976.438538,49.742149,1.078407,-445.209839,982.000671,0.000000
124.280006,219.502777,-445.209839,0.000073,0.004246,0.107841,976.397095,49.740040,1.078407,-445.209839,982.000671,0.000000
124.710007,219.480042,-445.209839,0.000060,0.004246,0.107841,976.295959,49.734890,1.078407,-445.209839,982.000671,0.000000
125.140007,219.436127,-445.254333,0.000073,0.004246,0.107848,976.100647,49.724937,1.078483,-445.254333,982.000671,0.000000
125.570007,219.439850,-445.298798,0.000095,0.004246,0.107857,976.117187,49.725780,1.078574,-445.298798,982.000671,0.000000
126.000008,219.421234,-445.298798,0.000073,0.004246,0.107857,976.034424,49.721561,1.078574,-445.298798,982.000671,0.000000
126.430008,219.404449,-445.343292,0.000069,0.004247,0.107866,975.959717,49.717758,1.078665,-445.343292,982.000671,0.000000
126.860008,219.404846,-445.298798,0.000078,0.004247,0.107866,975.961487,49.717850,1.078665,-445.298798,982.000671,0.000000
127.290009,219.394775,-445.298798,0.000082,0.004247,0.107866,975.916687,49.715565,1.078665,-445.298798,982.000671,0.000000
127.720009,219.392914,-445.432251,0.000082,0.004248,0.107892,975.908447,49.715145,1.078922,-445.432251,982.000671,0.000000
128.150009,219.398132,-445.432251,0.000078,0.004248,0.107892,975.931641,49.716328,1.078922,-445.432251,982.000671,0.000000
128.580002,219.401123,-445.432251,0.000069,0.004250,0.107944,975.944946,49.717007,1.079437,-445.432251,982.000671,0.000000
129.010010,219.560852,-445.432251,0.000073,0.004250,0.107962,976.655457,49.753201,1.079619,-445.432251,982.000671,0.000000
129.440002,219.587677,-445.432251,0.000073,0.004250,0.107962,976.774780,49.759277,1.079619,-445.432251,982.000671,0.000000
129.870010,219.592133,-445.432251,0.000095,0.004250,0.107962,976.794617,49.760288,1.079619,-445.432251,982.000671,0.000000
130.300003,219.592133,-445.521210,0.000073,0.004250,0.107962,976.794617,49.760288,1.079619,-445.521210,982.000671,0.000000
130.730011,219.586182,-445.565674,0.000078,0.004250,0.107962,976.768127,49.758942,1.079619,-445.565674,982.000671,0.000000
131.160004,219.590637,-445.521210,0.000069,0.004250,0.107962,976.787964,49.759953,1.079619,-445.521210,982.000671,0.000000
131.590012,219.565704,-445.521210,0.000078,0.004250,0.107962,976.677002,49.754303,1.079619,-445.521210,982.000671,0.000000
132.020004,219.572418,-445.610168,0.000078,0.004250,0.107962,976.706909,49.755821,1.079619,-445.610168,982.000671,0.000000
132.450012,219.560852,-445.610168,0.000082,0.004250,0.107962,976.655457,49.753201,1.079619,-445.610168,982.000671,0.000000
132.880005,219.539642,-445.565674,0.000073,0.004250,0.107962,976.561096,49.748394,1.079619,-445.565674,982.000671,0.000000
133.310013,219.531799,-445.654663,0.000082,0.004250,0.107962,976.526245,49.746620,1.079619,-445.654663,982.000671,0.000000
133.740005,219.524353,-445.610168,0.000091,0.004251,0.107971,976.493103,49.744930,1.079709,-445.610168,982.000671,0.000000
134.170013,219.504272,-445.699127,0.000082,0.004251,0.107971,976.403748,49.740376,1.079709,-445.699127,982.000671,0.000000
134.600006,219.496429,-445.699127,0.000069,0.004251,0.107971,976.368896,49.738602,1.079709,-445.699127,982.000671,0.000000
135.030014,219.474091,-445.743622,0.000091,0.004251,0.107971,976.269531,49.733540,1.079709,-445.743622,982.000671,0.000000
135.460007,219.468506,-445.788086,0.000078,0.004251,0.107971,976.244690,49.732273,1.079709,-445.788086,982.000671,0.000000
135.889999,219.357178,-445.699127,0.000086,0.004239,0.107676,975.749451,49.707047,1.076757,-445.699127,0.107953,0.000000
136.320007,219.358276,-445.832581,0.000082,0.004230,0.107432,975.754333,49.707294,1.074320,-445.832581,0.107234,0.000000
136.750000,219.096497,-445.832581,0.000078,0.004204,0.106792,974.589905,49.647976,1.067916,-445.832581,0.106522,0.000000
137.180008,218.790436,-445.788086,0.000099,0.004183,0.106253,973.228455,49.578621,1.062526,-445.788086,0.105803,0.000000
137.610001,217.501648,-445.832581,0.000112,0.004155,0.105543,967.495667,49.286579,1.055426,-445.832581,0.105082,0.000000
138.040009,217.007141,-445.832581,0.000099,0.004130,0.104892,965.295959,49.174522,1.048916,-445.832581,0.104371,0.000000
138.470001,216.769562,-445.921539,0.000091,0.004107,0.104328,964.239197,49.120686,1.043284,-445.921539,0.103652,0.000000
138.900009,216.570343,-445.921539,0.000099,0.004071,0.103409,963.353027,49.075542,1.034094,-445.921539,0.102932,0.000000
139.330002,216.155151,-445.921539,0.000103,0.004047,0.102784,961.506165,48.981457,1.027841,-445.921539,0.102221,0.000000
139.760010,215.987213,-445.877045,0.000121,0.004016,0.102012,960.759094,48.943401,1.020120,-445.877045,0.101500,0.000000
140.190002,215.366455,-445.921539,0.000112,0.004000,0.101588,957.997864,48.802738,1.015881,-445.921539,0.100781,0.000000
140.620010,214.429199,-446.054962,0.000108,0.003966,0.100730,953.828735,48.590351,1.007297,-446.054962,0.100070,0.000000
141.050003,213.255859,-446.054962,0.000116,0.003938,0.100035,948.609436,48.324467,1.000348,-446.054962,0.099350,0.000000
141.480011,211.459534,-446.010498,0.000121,0.003907,0.099246,940.618958,47.917416,0.992460,-446.010498,0.098639,0.000000
141.910004,209.913818,-446.010498,0.000116,0.003888,0.098760,933.743286,47.567150,0.987600,-446.010498,0.097920,0.000000
142.340012,208.031830,-446.054962,0.000116,0.003866,0.098197,925.371765,47.140686,0.981968,-446.054962,0.097199,0.000000
142.770004,204.767609,-446.099457,0.000116,0.003830,0.097278,910.851807,46.401005,0.972779,-446.099457,0.096488,0.000000
143.200012,201.942444,-446.099457,0.000121,0.003803,0.096601,898.284851,45.760815,0.966011,-446.099457,0.095768,0.000000
143.630005,198.734070,-446.099457,0.000108,0.003775,0.095880,884.013306,45.033787,0.958805,-446.099457,0.095049,0.000000
144.060013,195.908508,-446.054962,0.000125,0.003748,0.095205,871.444580,44.393505,0.952052,-446.054962,0.094338,0.000000
144.490005,192.777222,-446.188416,0.000116,0.003720,0.094494,857.515930,43.683945,0.944937,-446.188416,0.093617,0.000000
144.920013,189.463486,-446.188416,0.000108,0.003691,0.093756,842.775696,42.933041,0.937564,-446.188416,0.092898,0.000000
145.350006,185.819443,-446.188416,0.000103,0.003659,0.092933,826.566162,42.107288,0.929328,-446.188416,0.092186,0.000000
145.780014,183.387848,-446.232910,0.000108,0.003639,0.092421,815.749878,41.556282,0.924211,-446.232910,0.091467,0.000000
146.210007,180.344452,-446.232910,0.000103,0.003611,0.091728,802.212158,40.866638,0.917277,-446.232910,0.090747,0.000000
146.639999,177.110764,-446.232910,0.000116,0.003580,0.090937,787.828003,40.133873,0.909374,-446.232910,0.090037,0.000000
147.070007,173.511414,-446.321869,0.000125,0.003551,0.090183,771.817322,39.318245,0.901834,-446.321869,0.089316,0.000000
147.500000,169.726624,-446.321869,0.000095,0.003519,0.089377,754.981750,38.460602,0.893765,-446.321869,0.088606,0.000000
147.930008,167.160980,-446.277374,0.000099,0.003498,0.088839,743.569153,37.879219,0.888391,-446.277374,0.087885,0.000000
148.360001,163.160583,-446.321869,0.000091,0.003464,0.087990,725.774536,36.972717,0.879897,-446.321869,0.087166,0.000000
148.790009,160.285492,-446.410828,0.000099,0.003439,0.087348,712.985474,36.321209,0.873478,-446.410828,0.086455,0.000000
149.220001,155.865799,-446.410828,0.000095,0.003401,0.086385,693.325684,35.319695,0.863849,-446.410828,0.085734,0.000000
149.650009,153.000778,-446.410828,0.000082,0.003379,0.085838,680.581482,34.670471,0.858384,-446.410828,0.085015,0.000000
150.080002,150.693176,-446.455292,0.000095,0.003357,0.085266,670.316711,34.147564,0.852661,-446.455292,0.084303,0.000000
150.510010,147.241653,-446.410828,0.000099,0.003330,0.084589,654.963562,33.365433,0.845894,-446.410828,0.083584,0.000000
150.940002,143.278122,-446.499786,0.000078,0.003294,0.083670,637.332947,32.467285,0.836704,-446.499786,0.082863,0.000000
151.370010,139.615097,-446.499786,0.000078,0.003265,0.082926,621.038940,31.637232,0.829255,-446.499786,0.082153,0.000000
151.800003,137.222229,-446.499786,0.000056,0.003244,0.082387,610.394958,31.095001,0.823866,-446.499786,0.081433,0.000000
152.230011,133.124268,-446.455292,0.000078,0.003206,0.081442,592.166321,30.166391,0.814419,-446.455292,0.080714,0.000000
152.660004,129.876816,-446.455292,0.000086,0.003179,0.080758,577.720947,29.430506,0.807575,-446.455292,0.080002,0.000000
153.090012,127.062057,-446.544281,0.000056,0.003154,0.080107,565.200256,28.792675,0.801065,-446.544281,0.079283,0.000000
153.520004,123.481689,-446.588745,0.000056,0.003127,0.079430,549.273987,27.981350,0.794298,-446.588745,0.078562,0.000000
153.950012,120.636765,-446.544281,0.000043,0.003101,0.078771,536.619141,27.336681,0.787712,-446.544281,0.077852,0.000000
154.380005,117.199020,-446.588745,0.000039,0.003071,0.078016,521.327271,26.557678,0.780158,-446.588745,0.077132,0.000000
154.810013,113.995132,-446.588745,0.000043,0.003043,0.077297,507.075684,25.831665,0.772966,-446.588745,0.076420,0.000000
155.240005,109.958984,-446.677704,0.000039,0.003008,0.076412,489.121979,24.917063,0.764125,-446.677704,0.075701,0.000000
155.670013,107.772781,-446.633240,0.000017,0.002990,0.075943,479.397278,24.421661,0.759432,-446.633240,0.074982,0.000000
156.100006,104.347336,-446.677704,0.000026,0.002958,0.075145,464.160126,23.645445,0.751453,-446.677704,0.074270,0.000000
156.530014,100.646317,-446.588745,0.000026,0.002927,0.074340,447.697174,22.806780,0.743399,-446.588745,0.073550,0.000000
156.960007,98.190903,-446.677704,0.000034,0.002904,0.073768,436.774963,22.250378,0.737676,-446.677704,0.072830,0.000000
157.390015,94.975830,-446.766663,0.000022,0.002877,0.073065,422.473602,21.521832,0.730651,-446.766663,0.072119,0.000000
157.820007,91.487076,-446.766663,0.000013,0.002846,0.072284,406.954834,20.731268,0.722839,-446.766663,0.071400,0.000000
158.250000,88.275742,-446.722198,0.000000,0.002819,0.071600,392.670105,20.003569,0.715996,-446.722198,0.070679,0.000000
158.680008,85.326172,-446.766663,0.000009,0.002791,0.070888,379.549774,19.335186,0.708881,-446.766663,0.069969,0.000000
159.110001,81.259125,-446.811157,0.000009,0.002756,0.070011,361.458649,18.413580,0.700115,-446.811157,0.069248,0.000000
159.540009,78.902740,-446.900116,-0.000004,0.002736,0.069483,350.976929,17.879616,0.694831,-446.900116,0.068529,0.000000
159.970001,75.760300,-446.855621,0.000000,0.002708,0.068781,336.998657,17.167530,0.687806,-446.855621,0.067818,0.000000
160.400009,71.815384,-446.900116,0.000000,0.002673,0.067896,319.450775,16.273598,0.678965,-446.900116,0.067099,0.000000
160.830002,69.539062,-446.855621,-0.000004,0.002653,0.067376,309.325195,15.757776,0.673757,-446.855621,0.066387,0.000000
161.260010,66.192932,-446.900116,-0.000009,0.002622,0.066594,294.440857,14.999533,0.665945,-446.900116,0.065666,0.000000
161.690002,63.346893,-446.900116,-0.000013,0.002598,0.065980,281.781067,14.354611,0.659798,-446.900116,0.064947,0.000000
162.120010,60.298271,-446.944611,-0.000030,0.002567,0.065199,268.220093,13.663783,0.651986,-446.944611,0.064236,0.000000
162.550003,56.800949,-446.944611,-0.000026,0.002538,0.064461,252.663239,12.871279,0.644613,-446.944611,0.063517,0.000000
162.980011,53.566528,-446.944611,-0.000030,0.002509,0.063724,238.275818,12.138349,0.637240,-446.944611,0.062796,0.000000
163.410004,50.194321,-447.033569,-0.000030,0.002478,0.062953,223.275482,11.374196,0.629534,-447.033569,0.062086,0.000000
163.840012,47.652878,-447.078033,-0.000030,0.002456,0.062372,211.970581,10.798297,0.623720,-447.078033,0.061365,0.000000
164.270004,44.066185,-447.122528,-0.000052,0.002422,0.061530,196.016174,9.985540,0.615303,-447.122528,0.060646,0.000000
164.700012,41.292015,-447.033569,-0.000047,0.002398,0.060914,183.676056,9.356904,0.609141,-447.033569,0.059935,0.000000
165.130005,38.429588,-447.078033,-0.000047,0.002373,0.060265,170.943344,8.708269,0.602646,-447.078033,0.059215,0.000000
165.560013,35.623756,-447.122528,-0.000052,0.002348,0.059648,158.462387,8.072459,0.596484,-447.122528,0.058495,0.000000
165.990005,31.917160,-447.166992,-0.000047,0.002315,0.058790,141.974625,7.232532,0.587900,-447.166992,0.057783,0.000000
166.420013,28.763542,-447.166992,-0.000065,0.002285,0.058036,127.946625,6.517912,0.580361,-447.166992,0.057064,0.000000
166.850006,25.675453,-447.122528,-0.000082,0.002255,0.057281,114.210121,5.818141,0.572806,-447.122528,0.056345,0.000000
167.280014,22.593330,-447.122528,-0.000073,0.002229,0.056622,100.500153,5.119721,0.566220,-447.122528,0.055633,0.000000
167.710007,19.729782,-447.166992,-0.000060,0.002203,0.055945,87.762451,4.470833,0.559453,-447.166992,0.054913,0.000000
168.140015,16.178467,-447.211487,-0.000073,0.002171,0.055131,71.965416,3.666093,0.551308,-447.211487,0.054203,0.000000
168.570007,12.757858,-447.211487,-0.000069,0.002138,0.054298,56.749786,2.890972,0.542981,-447.211487,0.053482,0.000000
169.000015,10.401108,-447.255951,-0.000069,0.002117,0.053761,46.266438,2.356925,0.537606,-447.255951,0.052763,0.000000
169.430008,7.757637,-447.211487,-0.000060,0.002092,0.053126,34.507694,1.757906,0.531263,-447.211487,0.052051,0.000000
169.860001,4.524696,-447.300446,-0.000082,0.002061,0.052356,20.126854,1.025311,0.523557,-447.300446,0.051332,0.000000
170.290009,2.018631,-447.344910,-0.000103,0.002035,0.051696,8.979319,0.457428,0.516956,-447.344910,0.050612,0.000000
170.720001,-1.314102,-447.300446,-0.000082,0.001997,0.050716,-5.845418,-0.297780,0.507161,-447.300446,0.049902,0.000000
171.150009,-0.457642,-447.344910,-0.000095,0.001979,0.050274,-2.035691,-0.103703,0.502740,-447.344910,0.049181,0.000000
171.580002,-0.257683,-447.344910,-0.000125,0.001950,0.049528,-1.146230,-0.058392,0.495276,-447.344910,0.048462,0.000000
172.010010,-0.119530,-447.433899,-0.000164,0.001918,0.048730,-0.531695,-0.027086,0.487298,-447.433899,0.047750,0.000000
172.440002,-0.082291,-447.478363,-0.000207,0.001894,0.048106,-0.366047,-0.018647,0.481060,-447.478363,0.047031,0.000000
172.870010,-0.066650,-447.344910,-0.000237,0.001863,0.047325,-0.296476,-0.015103,0.473248,-447.344910,0.046310,0.000000
173.300003,-0.071869,-447.389404,-0.000267,0.001837,0.046666,-0.319689,-0.016286,0.466662,-447.389404,0.045599,0.000000
173.730011,-0.052505,-447.389404,-0.000306,0.001806,0.045868,-0.233556,-0.011898,0.458684,-447.389404,0.044880,0.000000
174.160004,-0.090858,-447.522858,-0.000345,0.001778,0.045149,-0.404159,-0.020589,0.451493,-447.522858,0.044168,0.000000
174.590012,-0.095329,-447.567322,-0.000366,0.001745,0.044324,-0.424046,-0.021602,0.443241,-447.567322,0.043449,0.000000
175.000015,-0.027924,-447.567322,-0.000397,0.001732,0.043987,-0.124210,-0.006328,0.439865,-447.567322,0.043847,0.000000