File: Data/sima compression 500bar/P1-17-500bar-1_11072024_165534.csv
Time (sec),S:Load (lbs),S:HL1 (DIM),S:LVDT (in),S:Position (in),Ch:Position (mm),Ch:Load (N),Ch:Stress (MPa),Ch:Strain (mm/mm),Ch:HL1 (DIM),Set Point (),Cycles ()
0.010000,-0.105751,-344.727356,-0.012732,-0.007387,-0.187634,-0.470404,-0.023964,-1.876339,-344.727356,-0.187495,0.000000
0.460000,-0.095329,-344.771851,-0.012728,-0.007308,-0.185631,-0.424046,-0.021602,-1.856309,-344.771851,-0.185153,0.000000
0.910000,-0.055855,-344.727356,-0.012542,-0.007035,-0.178692,-0.248455,-0.012657,-1.786925,-344.727356,-0.177660,0.000000
1.360000,-0.088997,-344.816345,-0.012232,-0.006733,-0.171026,-0.395878,-0.020167,-1.710258,-344.816345,-0.170151,0.000000
1.810000,-0.151924,-344.771851,-0.011960,-0.006444,-0.163672,-0.675792,-0.034427,-1.636725,-344.771851,-0.162658,0.000000
2.260000,-0.111336,-344.816345,-0.011641,-0.006152,-0.156266,-0.495246,-0.025229,-1.562662,-344.816345,-0.155164,0.000000
2.710000,-0.070007,-344.860809,-0.011344,-0.005854,-0.148704,-0.311408,-0.015864,-1.487040,-344.860809,-0.147671,0.000000
3.160000,-0.106125,-344.860809,-0.011025,-0.005562,-0.141272,-0.472067,-0.024048,-1.412720,-344.860809,-0.140179,0.000000
3.610000,-0.090111,-344.949768,-0.010718,-0.005263,-0.133675,-0.400833,-0.020419,-1.336749,-344.949768,-0.132668,0.000000
4.060000,-0.115059,-344.949768,-0.010425,-0.004968,-0.126190,-0.511808,-0.026073,-1.261899,-344.949768,-0.125176,0.000000
4.510000,-0.162727,-344.994263,-0.010123,-0.004677,-0.118785,-0.723847,-0.036875,-1.187851,-344.994263,-0.117683,0.000000
4.960000,-0.082291,-344.994263,-0.009813,-0.004377,-0.111188,-0.366047,-0.018647,-1.111881,-344.994263,-0.110190,0.000000
5.410000,-0.052132,-344.994263,-0.009507,-0.004099,-0.104110,-0.231893,-0.011813,-1.041103,-344.994263,-0.102680,0.000000
5.860000,-0.113571,-345.038727,-0.009188,-0.003787,-0.096194,-0.505190,-0.025736,-0.961939,-345.038727,-0.095187,0.000000
6.310000,-0.105011,-345.083221,-0.008903,-0.003491,-0.088674,-0.467112,-0.023796,-0.886740,-345.083221,-0.087695,0.000000
6.760000,-0.074097,-345.127686,-0.008597,-0.003210,-0.081546,-0.329598,-0.016791,-0.815463,-345.127686,-0.080202,0.000000
7.210001,-0.094582,-345.083221,-0.008274,-0.002904,-0.073749,-0.420720,-0.021432,-0.737494,-345.083221,-0.072691,0.000000
7.660000,-0.080055,-345.172180,-0.007981,-0.002608,-0.066231,-0.356103,-0.018141,-0.662311,-345.172180,-0.065199,0.000000
8.110001,-0.091972,-345.172180,-0.007675,-0.002322,-0.058972,-0.409113,-0.020841,-0.589717,-345.172180,-0.057706,0.000000
8.560000,-0.149689,-345.216675,-0.007364,-0.002015,-0.051184,-0.665849,-0.033920,-0.511839,-345.216675,-0.050213,0.000000
9.010000,-0.077080,-345.261139,-0.007075,-0.001726,-0.043847,-0.342868,-0.017467,-0.438473,-345.261139,-0.042703,0.000000
9.460000,-0.035378,-345.305634,-0.006778,-0.001437,-0.036494,-0.157367,-0.008017,-0.364940,-345.305634,-0.035210,0.000000
9.910001,-0.086761,-345.350098,-0.006454,-0.001131,-0.028723,-0.385934,-0.019660,-0.287228,-345.350098,-0.027718,0.000000
10.360001,-0.115059,-345.394592,-0.006135,-0.000838,-0.021274,-0.511808,-0.026073,-0.212741,-345.394592,-0.020225,0.000000
10.810000,-0.063675,-345.350098,-0.005842,-0.000549,-0.013954,-0.283240,-0.014429,-0.139542,-345.350098,-0.012731,0.000000
11.260000,-0.052505,-345.394592,-0.005558,-0.000249,-0.006322,-0.233556,-0.011898,-0.063223,-345.394592,-0.005222,0.000000
11.710001,-0.066650,-345.439056,-0.005230,0.000044,0.001110,-0.296476,-0.015103,0.011097,-345.439056,0.002271,0.000000
12.160001,-0.069633,-345.439056,-0.004919,0.000340,0.008646,-0.309745,-0.015779,0.086462,-345.439056,0.009765,0.000000
12.610001,-0.087509,-345.439056,-0.004622,0.000643,0.016330,-0.389260,-0.019830,0.163296,-345.439056,0.017258,0.000000
13.060000,-0.115807,-345.483551,-0.004333,0.000928,0.023562,-0.515133,-0.026242,0.235617,-345.483551,0.024767,0.000000
13.510000,-0.021225,-345.528015,-0.004018,0.001225,0.031107,-0.094413,-0.004810,0.311073,-345.528015,0.032261,0.000000
13.960001,-0.027184,-345.528015,-0.003729,0.001524,0.038704,-0.120918,-0.006160,0.387043,-345.528015,0.039754,0.000000
14.410001,-0.082664,-345.528015,-0.003432,0.001819,0.046197,-0.367710,-0.018732,0.461969,-345.528015,0.047246,0.000000
14.860001,0.040962,-345.528015,-0.003109,0.002112,0.053638,0.182209,0.009282,0.536380,-345.528015,0.054755,0.000000
15.310000,0.227524,-345.617004,-0.003053,0.000015,0.000372,1.012076,0.051558,0.003724,-345.617004,0.000547,0.000000
15.760001,0.225662,-345.617004,-0.003070,0.000015,0.000372,1.003796,0.051136,0.003724,-345.617004,0.001023,0.000000
16.210001,0.329552,-345.661469,-0.003061,0.000036,0.000910,1.465919,0.074677,0.009099,-345.661469,0.001777,0.000000
16.660000,0.697456,-345.705963,-0.003031,0.000061,0.001543,3.102441,0.158046,0.015427,-345.705963,0.002524,0.000000
17.110001,1.384109,-345.705963,-0.003005,0.000090,0.002289,6.156826,0.313644,0.022891,-345.705963,0.003278,0.000000
17.560001,2.089012,-345.705963,-0.002992,0.000114,0.002896,9.292390,0.473377,0.028962,-345.705963,0.004024,0.000000
18.010000,3.386726,-345.794922,-0.002949,0.000154,0.003920,15.064911,0.767443,0.039196,-345.794922,0.004778,0.000000
18.460001,4.342979,-345.794922,-0.002940,0.000182,0.004622,19.318537,0.984133,0.046221,-345.794922,0.005524,0.000000
18.910002,5.705864,-345.794922,-0.002923,0.000216,0.005481,25.380951,1.292967,0.054805,-345.794922,0.006278,0.000000
19.360001,6.874001,-345.794922,-0.002880,0.000239,0.006062,30.577082,1.557671,0.060619,-345.794922,0.007025,0.000000
19.810001,8.292366,-345.794922,-0.002884,0.000269,0.006825,36.886288,1.879077,0.068249,-345.794922,0.007770,0.000000
20.260000,9.631416,-345.883881,-0.002859,0.000298,0.007571,42.842678,2.182510,0.075713,-345.883881,0.008525,0.000000
20.710001,11.179367,-345.928345,-0.002854,0.000331,0.008402,49.728310,2.533281,0.084025,-345.928345,0.009270,0.000000
21.160002,12.387718,-345.883881,-0.002820,0.000354,0.008984,55.103321,2.807097,0.089838,-345.883881,0.010025,0.000000
21.610001,13.253113,-345.928345,-0.002824,0.000376,0.009556,58.952789,3.003198,0.095561,-345.928345,0.010770,0.000000
22.060001,15.548790,-345.972839,-0.002785,0.000415,0.010537,69.164474,3.523406,0.105371,-345.972839,0.011526,0.000000
22.510000,17.184990,-345.972839,-0.002785,0.000447,0.011343,76.442650,3.894174,0.113426,-345.972839,0.012271,0.000000
22.960001,18.619370,-346.061798,-0.002759,0.000474,0.012037,82.823090,4.219209,0.120375,-346.061798,0.013026,0.000000
23.410002,19.561844,-346.061798,-0.002746,0.000496,0.012592,87.015427,4.432777,0.125916,-346.061798,0.013771,0.000000
23.860001,21.851936,-346.106293,-0.002725,0.000536,0.013606,97.202271,4.951720,0.136059,-346.106293,0.014526,0.000000
24.310001,23.096031,-346.150757,-0.002686,0.000564,0.014327,102.736275,5.233635,0.143266,-346.150757,0.015271,0.000000
24.760000,24.512535,-346.195251,-0.002665,0.000594,0.015081,109.037201,5.554620,0.150805,-346.195251,0.016027,0.000000
25.210001,25.780464,-346.239716,-0.002652,0.000621,0.015766,114.677231,5.841937,0.157664,-346.239716,0.016772,0.000000
25.660002,27.480347,-346.195251,-0.002617,0.000657,0.016676,122.238686,6.227136,0.166762,-346.195251,0.017526,0.000000
26.110001,28.511818,-346.239716,-0.002617,0.000685,0.017388,126.826897,6.460871,0.173878,-346.239716,0.018272,0.000000
26.560001,29.729843,-346.284210,-0.002591,0.000713,0.018099,132.244949,6.736879,0.180994,-346.284210,0.019026,0.000000
27.010002,30.419853,-346.328674,-0.002570,0.000734,0.018653,135.314270,6.893237,0.186535,-346.328674,0.019772,0.000000
27.460001,32.149147,-346.328674,-0.002557,0.000770,0.019547,143.006546,7.285101,0.195467,-346.328674,0.020526,0.000000
27.910002,33.047310,-346.373169,-0.002522,0.000800,0.020319,147.001770,7.488628,0.203188,-346.373169,0.021273,0.000000
28.360001,34.398651,-346.373169,-0.002496,0.000833,0.021152,153.012848,7.794846,0.211515,-346.373169,0.022027,0.000000
28.810001,35.086426,-346.417633,-0.002483,0.000858,0.021801,156.072220,7.950698,0.218010,-346.417633,0.022773,0.000000
29.260002,35.526939,-346.417633,-0.002445,0.000883,0.022426,158.031723,8.050519,0.224263,-346.417633,0.023527,0.000000
29.710001,37.146759,-346.506622,-0.002440,0.000917,0.023285,165.237030,8.417576,0.232847,-346.506622,0.024273,0.000000
30.160002,37.895973,-346.506622,-0.002397,0.000947,0.024066,168.569702,8.587350,0.240659,-346.506622,0.025027,0.000000
30.610001,38.867867,-346.551086,-0.002389,0.000980,0.024880,172.892899,8.807585,0.248804,-346.551086,0.025774,0.000000
31.060001,39.284554,-346.551086,-0.002358,0.001002,0.025444,174.746414,8.902007,0.254436,-346.551086,0.026528,0.000000
31.510002,40.564026,-346.595581,-0.002333,0.001040,0.026425,180.437805,9.191939,0.264246,-346.595581,0.027274,0.000000
31.960001,40.972885,-346.640045,-0.002315,0.001065,0.027057,182.256500,9.284589,0.270575,-346.640045,0.028028,0.000000
32.410000,41.671089,-346.640045,-0.002285,0.001096,0.027837,185.362259,9.442803,0.278371,-346.640045,0.028774,0.000000
32.860001,42.384552,-346.640045,-0.002251,0.001126,0.028600,188.535904,9.604477,0.286002,-346.640045,0.029528,0.000000
33.310001,42.888748,-346.773499,-0.002238,0.001154,0.029303,190.778687,9.718729,0.293027,-346.773499,0.030275,0.000000
33.760002,43.664398,-346.729004,-0.002186,0.001186,0.030135,194.228943,9.894495,0.301353,-346.729004,0.031029,0.000000
34.210003,43.907181,-346.729004,-0.002160,0.001214,0.030847,195.308899,9.949510,0.308469,-346.729004,0.031775,0.000000
34.660000,44.594208,-346.773499,-0.002160,0.001241,0.031524,198.364944,10.105192,0.315236,-346.773499,0.032529,0.000000
35.110001,45.082016,-346.862457,-0.002117,0.001267,0.032173,200.534821,10.215731,0.321731,-346.862457,0.033275,0.000000
35.560001,46.447884,-346.906952,-0.002082,0.001305,0.033154,206.610504,10.525241,0.331542,-346.906952,0.034029,0.000000
36.010002,47.068253,-346.817963,-0.002065,0.001334,0.033891,209.370041,10.665818,0.338915,-346.817963,0.034776,0.000000
36.460003,48.002533,-346.906952,-0.002039,0.001365,0.034680,213.525925,10.877529,0.346802,-346.906952,0.035530,0.000000
36.910000,47.928802,-346.906952,-0.002005,0.001384,0.035148,213.197968,10.860822,0.351480,-346.906952,0.036276,0.000000
37.360001,49.453674,-346.995911,-0.001975,0.001421,0.036094,219.980927,11.206364,0.360943,-346.995911,0.037030,0.000000
37.810001,50.004036,-346.995911,-0.001957,0.001451,0.036848,222.429062,11.331077,0.368482,-346.995911,0.037776,0.000000
38.260002,50.700005,-347.084869,-0.001940,0.001482,0.037637,225.524887,11.488786,0.376370,-347.084869,0.038530,0.000000
38.710003,50.765915,-347.084869,-0.001897,0.001499,0.038072,225.818069,11.503721,0.380715,-347.084869,0.039277,0.000000
39.160004,50.655693,-347.084869,-0.001897,0.001517,0.038530,225.327774,11.478744,0.385302,-347.084869,0.040021,0.000000
39.610001,53.533760,-347.129333,-0.001880,0.001568,0.039831,238.130051,12.130923,0.398307,-347.129333,0.040777,0.000000
40.060001,53.567268,-347.173828,-0.001832,0.001592,0.040447,238.279114,12.138516,0.404469,-347.173828,0.041522,0.000000
40.510002,54.997551,-347.173828,-0.001794,0.001626,0.041296,244.641327,12.462624,0.412962,-347.173828,0.042277,0.000000
40.960003,54.751785,-347.218292,-0.001781,0.001646,0.041800,243.548111,12.406932,0.418004,-347.218292,0.043022,0.000000
41.410004,56.425972,-347.218292,-0.001750,0.001688,0.042875,250.995255,12.786307,0.428753,-347.218292,0.043778,0.000000
41.860001,57.148003,-347.262787,-0.001738,0.001712,0.043491,254.207016,12.949923,0.434915,-347.262787,0.044522,0.000000
42.310001,58.488914,-347.218292,-0.001699,0.001745,0.044315,260.171692,13.253778,0.443151,-347.218292,0.045278,0.000000
42.760002,58.622597,-347.262787,-0.001681,0.001765,0.044836,260.766327,13.284071,0.448359,-347.262787,0.046023,0.000000
43.210003,60.346680,-347.307251,-0.001673,0.001801,0.045755,268.435425,13.674753,0.457548,-347.307251,0.046778,0.000000
43.660004,61.558014,-347.307251,-0.001630,0.001832,0.046544,273.823730,13.949245,0.465436,-347.307251,0.047523,0.000000
44.110001,62.608849,-347.440704,-0.001600,0.001861,0.047281,278.498077,14.187368,0.472809,-347.440704,0.048279,0.000000
44.560001,63.700638,-347.351746,-0.001600,0.001890,0.048000,283.354584,14.434772,0.480000,-347.351746,0.049023,0.000000
45.010002,65.272797,-347.396240,-0.001561,0.001924,0.048868,290.347900,14.791027,0.488675,-347.396240,0.049779,0.000000
45.460003,65.915878,-347.440704,-0.001539,0.001949,0.049509,293.208466,14.936751,0.495095,-347.440704,0.050524,0.000000
45.910004,67.274673,-347.485199,-0.001526,0.001981,0.050307,299.252686,15.244659,0.503073,-347.485199,0.051279,0.000000
46.360001,68.116974,-347.529663,-0.001505,0.002006,0.050958,302.999420,15.435527,0.509583,-347.529663,0.052024,0.000000
46.810001,68.802139,-347.574158,-0.001492,0.002039,0.051791,306.047211,15.590787,0.517910,-347.574158,0.052780,0.000000
47.260002,70.727310,-347.574158,-0.001449,0.002067,0.052501,314.610779,16.027039,0.525010,-347.574158,0.053524,0.000000
47.710003,71.332794,-347.529663,-0.001436,0.002091,0.053101,317.304108,16.164242,0.531006,-347.529663,0.054280,0.000000
48.160004,72.995438,-347.618622,-0.001431,0.002125,0.053985,324.699921,16.541002,0.539847,-347.618622,0.055025,0.000000
48.610001,73.703690,-347.707581,-0.001401,0.002148,0.054566,327.850372,16.701496,0.545661,-347.707581,0.055780,0.000000
49.060001,75.964355,-347.707581,-0.001397,0.002187,0.055546,337.906342,17.213770,0.555456,-347.707581,0.056525,0.000000
49.510002,77.131744,-347.707581,-0.001362,0.002215,0.056257,343.099121,17.478302,0.562572,-347.707581,0.057281,0.000000
49.960003,78.245132,-347.752075,-0.001341,0.002242,0.056951,348.051727,17.730600,0.569506,-347.752075,0.058025,0.000000
50.410004,78.670761,-347.707581,-0.001319,0.002262,0.057462,349.945038,17.827049,0.574623,-347.707581,0.058781,0.000000
50.860001,80.769073,-347.752075,-0.001315,0.002302,0.058460,359.278778,18.302534,0.584600,-347.752075,0.059526,0.000000
51.310001,82.367294,-347.885529,-0.001289,0.002333,0.059265,366.388031,18.664696,0.592654,-347.885529,0.060281,0.000000
51.760002,83.403244,-347.841034,-0.001276,0.002361,0.059960,370.996155,18.899445,0.599603,-347.841034,0.061026,0.000000
52.210003,85.284836,-347.929993,-0.001246,0.002393,0.060784,379.365906,19.325821,0.607839,-347.929993,0.061782,0.000000
52.660004,85.430817,-347.885529,-0.001242,0.002407,0.061147,380.015259,19.358900,0.611472,-347.885529,0.062526,0.000000
53.110004,88.541611,-347.929993,-0.001212,0.002454,0.062327,393.852753,20.063816,0.623266,-347.929993,0.063280,0.000000
53.560001,89.611801,-347.929993,-0.001199,0.002478,0.062934,398.613190,20.306326,0.629337,-347.929993,0.064027,0.000000
54.010002,91.408127,-348.018951,-0.001181,0.002510,0.063766,406.603668,20.713377,0.637664,-348.018951,0.064781,0.000000
54.460003,91.998718,-348.063446,-0.001147,0.002530,0.064261,409.230743,20.847208,0.642615,-348.063446,0.065527,0.000000
54.910004,94.987747,-348.063446,-0.001147,0.002573,0.065355,422.526611,21.524530,0.653545,-348.063446,0.066281,0.000000
55.360004,95.835648,-348.063446,-0.001117,0.002601,0.066057,426.298248,21.716667,0.660570,-348.063446,0.067027,0.000000
55.810001,97.822998,-348.063446,-0.001117,0.002630,0.066802,435.138428,22.167007,0.668019,-348.063446,0.067781,0.000000
56.260002,99.023148,-348.196899,-0.001095,0.002654,0.067409,440.476959,22.438967,0.674090,-348.196899,0.068528,0.000000
56.710003,101.231323,-348.196899,-0.001065,0.002689,0.068311,450.299408,22.939346,0.683113,-348.196899,0.069282,0.000000
57.160004,102.717453,-348.196899,-0.001048,0.002718,0.069049,456.910065,23.276108,0.690486,-348.196899,0.070028,0.000000
57.610004,104.523087,-348.196899,-0.001035,0.002749,0.069821,464.941925,23.685270,0.698207,-348.196899,0.070782,0.000000
58.060001,105.626801,-348.285858,-0.001022,0.002770,0.070349,469.851471,23.935375,0.703491,-348.285858,0.071528,0.000000
58.510002,107.669632,-348.241364,-0.001005,0.002805,0.071242,478.938446,24.398287,0.712423,-348.241364,0.072282,0.000000
58.960003,109.501709,-348.285858,-0.001005,0.002832,0.071936,487.087921,24.813440,0.719357,-348.285858,0.073029,0.000000
59.410004,110.961044,-348.374817,-0.000979,0.002858,0.072603,493.579376,25.144133,0.726034,-348.374817,0.073775,0.000000
59.860004,113.178146,-348.374817,-0.000957,0.002891,0.073427,503.441528,25.646536,0.734270,-348.374817,0.074529,0.000000
60.310001,114.108704,-348.374817,-0.000953,0.002909,0.073896,507.580872,25.857403,0.738963,-348.374817,0.075276,0.000000
60.760002,117.323395,-348.419281,-0.000940,0.002953,0.075015,521.880554,26.585863,0.750151,-348.419281,0.076029,0.000000
61.210003,118.974869,-348.463776,-0.000927,0.002979,0.075674,529.226624,26.960089,0.756737,-348.463776,0.076776,0.000000
61.660004,121.515564,-348.508240,-0.000931,0.003014,0.076558,540.528198,27.535820,0.765578,-348.508240,0.077530,0.000000
62.110004,122.983078,-348.463776,-0.000901,0.003036,0.077104,547.056030,27.868362,0.771044,-348.463776,0.078276,0.000000
62.560001,125.015121,-348.552734,-0.000897,0.003068,0.077928,556.095032,28.328833,0.779280,-348.552734,0.079030,0.000000
63.010002,127.037476,-348.597198,-0.000892,0.003097,0.078658,565.090942,28.787104,0.786577,-348.597198,0.079777,0.000000
63.460003,129.550247,-348.552734,-0.000867,0.003131,0.079516,576.268311,29.356506,0.795161,-348.552734,0.080530,0.000000
63.910004,130.937698,-348.641693,-0.000854,0.003155,0.080131,582.439941,29.670908,0.801308,-348.641693,0.081275,0.000000
64.360001,132.813721,-348.597198,-0.000832,0.003188,0.080973,590.784912,30.096018,0.809725,-348.597198,0.082031,0.000000
64.810005,135.335800,-348.641693,-0.000832,0.003215,0.081666,602.003723,30.667530,0.816659,-348.641693,0.082776,0.000000
65.260002,137.565186,-348.775146,-0.000824,0.003244,0.082387,611.920532,31.172716,0.823866,-348.775146,0.083531,0.000000
65.710007,139.535416,-348.730652,-0.000806,0.003273,0.083141,620.684509,31.619177,0.831405,-348.730652,0.084276,0.000000
66.160004,141.071823,-348.775146,-0.000819,0.003296,0.083731,627.518799,31.967333,0.837310,-348.775146,0.085031,0.000000
66.610001,144.393005,-348.775146,-0.000776,0.003337,0.084754,642.292175,32.719921,0.847544,-348.775146,0.085776,0.000000
67.060005,146.526337,-348.775146,-0.000763,0.003364,0.085439,651.781677,33.203342,0.854387,-348.775146,0.086532,0.000000
67.510002,148.698013,-348.864105,-0.000759,0.003391,0.086125,661.441772,33.695454,0.861245,-348.864105,0.087277,0.000000
67.960007,150.686111,-348.775146,-0.000737,0.003418,0.086809,670.285278,34.145962,0.868088,-348.775146,0.088032,0.000000
68.410004,153.595444,-348.864105,-0.000742,0.003454,0.087737,683.226685,34.805225,0.877369,-348.864105,0.088777,0.000000
68.860001,155.565308,-348.953064,-0.000724,0.003483,0.088456,691.989075,35.251602,0.884560,-348.953064,0.089532,0.000000
69.310005,158.022217,-348.953064,-0.000724,0.003510,0.089142,702.917908,35.808346,0.891418,-348.953064,0.090277,0.000000
69.760002,159.601074,-348.997528,-0.000724,0.003532,0.089705,709.941040,36.166119,0.897050,-348.997528,0.091033,0.000000
70.210007,162.855988,-348.997528,-0.000703,0.003571,0.090694,724.419617,36.903694,0.906937,-348.997528,0.091778,0.000000
70.660004,164.789337,-349.042023,-0.000698,0.003597,0.091370,733.019592,37.341797,0.913704,-349.042023,0.092533,0.000000
71.110001,167.686768,-349.130981,-0.000698,0.003631,0.092220,745.908020,37.998363,0.922197,-349.130981,0.093278,0.000000
71.560005,169.703903,-349.130981,-0.000690,0.003657,0.092889,754.880676,38.455456,0.928889,-349.130981,0.094033,0.000000
72.010002,171.245911,-349.086517,-0.000664,0.003676,0.093366,761.739868,38.804878,0.933658,-349.086517,0.094778,0.000000
72.460007,174.660934,-349.175476,-0.000668,0.003714,0.094327,776.930664,39.578735,0.943272,-349.175476,0.095534,0.000000
72.910004,177.092148,-349.175476,-0.000651,0.003746,0.095143,787.745239,40.129654,0.951432,-349.175476,0.096279,0.000000
73.360001,179.784775,-349.175476,-0.000655,0.003777,0.095932,799.722595,40.739811,0.959319,-349.175476,0.097034,0.000000
73.810005,181.762451,-349.175476,-0.000634,0.003799,0.096488,808.519775,41.187958,0.964876,-349.175476,0.097779,0.000000
74.260002,184.408905,-349.219940,-0.000625,0.003830,0.097285,820.291748,41.787655,0.972854,-349.219940,0.098534,0.000000
74.710007,187.060928,-349.308899,-0.000634,0.003862,0.098091,832.088562,42.388611,0.980909,-349.308899,0.099279,0.000000
75.160004,189.394592,-349.308899,-0.000617,0.003890,0.098802,842.469238,42.917427,0.988024,-349.308899,0.100035,0.000000
75.610001,192.247711,-349.353394,-0.000621,0.003922,0.099626,855.160522,43.563953,0.996260,-349.353394,0.100780,0.000000
76.060005,194.684509,-349.442352,-0.000595,0.003949,0.100312,865.999939,44.116142,1.003118,-349.442352,0.101535,0.000000
76.510002,197.625153,-349.397858,-0.000604,0.003983,0.101170,879.080566,44.782501,1.011702,-349.397858,0.102280,0.000000
76.960007,199.437103,-349.397858,-0.000591,0.004004,0.101708,887.140564,45.193092,1.017077,-349.397858,0.103035,0.000000
77.410004,202.416473,-349.442352,-0.000582,0.004037,0.102540,900.393433,45.868225,1.025404,-349.442352,0.103780,0.000000
77.860001,204.775818,-349.442352,-0.000586,0.004064,0.103217,910.888306,46.402866,1.032171,-349.442352,0.104536,0.000000
78.310005,207.837097,-349.486847,-0.000565,0.004100,0.104136,924.505554,47.096558,1.041361,-349.486847,0.105281,0.000000
78.760002,210.683502,-349.486847,-0.000578,0.004131,0.104925,937.167053,47.741566,1.049249,-349.486847,0.106027,0.000000
79.210007,213.616669,-349.620270,-0.000560,0.004161,0.105680,950.214417,48.406231,1.056803,-349.620270,0.106781,0.000000
79.660004,215.533661,-349.575806,-0.000548,0.004181,0.106209,958.741577,48.840626,1.062087,-349.575806,0.107527,0.000000
80.110001,218.486938,-349.620270,-0.000548,0.004215,0.107050,971.878418,49.509850,1.070505,-349.620270,0.108281,0.000000
80.560005,220.812408,-349.709229,-0.000548,0.004227,0.107353,982.222656,50.036808,1.073532,-349.709229,0.107692,0.000000
81.010002,220.119049,-349.664764,-0.000535,0.004224,0.107302,979.138428,49.879692,1.073018,-349.664764,982.000671,0.000000
81.460007,219.483765,-349.709229,-0.000526,0.004227,0.107362,976.312561,49.735729,1.073623,-349.709229,982.000671,0.000000
81.910004,219.875519,-349.709229,-0.000539,0.004242,0.107753,978.055176,49.824505,1.077529,-349.709229,982.000671,0.000000
82.360001,219.321808,-349.709229,-0.000517,0.004242,0.107753,975.592102,49.699032,1.077529,-349.709229,982.000671,0.000000
82.810005,221.218292,-349.798187,-0.000504,0.004262,0.108256,984.028137,50.128780,1.082556,-349.798187,982.000671,0.000000
83.260002,220.427002,-349.753723,-0.000496,0.004223,0.107276,980.508301,49.949474,1.072760,-349.753723,982.000671,0.000000
83.710007,219.863586,-349.798187,-0.000509,0.004238,0.107658,978.002075,49.821800,1.076576,-349.798187,982.000671,0.000000
84.160004,219.542603,-349.842682,-0.000500,0.004254,0.108047,976.574280,49.749062,1.080466,-349.842682,982.000671,0.000000
84.610001,219.815186,-349.842682,-0.000509,0.004269,0.108437,977.786804,49.810833,1.084372,-349.842682,982.000671,0.000000
85.060005,219.764923,-349.931641,-0.000500,0.004269,0.108428,977.563171,49.799442,1.084282,-349.931641,982.000671,0.000000
85.510002,219.367218,-349.887146,-0.000496,0.004269,0.108428,975.794128,49.709324,1.084282,-349.887146,982.000671,0.000000
85.960007,219.784668,-349.931641,-0.000500,0.004277,0.108628,977.651001,49.803917,1.086280,-349.931641,982.000671,0.000000
86.410004,219.519531,-349.976135,-0.000496,0.004278,0.108654,976.471619,49.743835,1.086537,-349.976135,982.000671,0.000000
86.860001,219.691193,-350.020599,-0.000492,0.004284,0.108811,977.235229,49.782734,1.088112,-350.020599,982.000671,0.000000
87.310005,219.499420,-350.065094,-0.000483,0.004284,0.108811,976.382202,49.739281,1.088112,-350.065094,982.000671,0.000000
87.760002,219.348969,-350.020599,-0.000496,0.004286,0.108854,975.712952,49.705185,1.088536,-350.020599,982.000671,0.000000
88.210007,219.546722,-350.109558,-0.000496,0.004290,0.108975,976.592590,49.750000,1.089747,-350.109558,982.000671,0.000000
88.660004,219.306915,-350.109558,-0.000474,0.004291,0.108993,975.525879,49.695660,1.089929,-350.109558,982.000671,0.000000
89.110001,219.377289,-350.065094,-0.000492,0.004295,0.109097,975.838928,49.711605,1.090973,-350.065094,982.000671,0.000000
89.560005,219.202271,-350.109558,-0.000479,0.004295,0.109097,975.060425,49.671944,1.090973,-350.109558,982.000671,0.000000
90.010002,220.225159,-350.243011,-0.000487,0.004308,0.109435,979.610413,49.903736,1.094349,-350.243011,982.000671,0.000000
90.460007,220.099304,-350.243011,-0.000470,0.004308,0.109435,979.050598,49.875217,1.094349,-350.243011,982.000671,0.000000
90.910004,219.863220,-350.243011,-0.000474,0.004308,0.109435,978.000427,49.821716,1.094349,-350.243011,982.000671,0.000000
91.360001,219.632355,-350.243011,-0.000483,0.004308,0.109435,976.973511,49.769402,1.094349,-350.243011,982.000671,0.000000
91.810005,219.388458,-350.331970,-0.000474,0.004309,0.109444,975.888611,49.714134,1.094440,-350.331970,982.000671,0.000000
92.260002,219.244720,-350.331970,-0.000466,0.004310,0.109470,975.249207,49.681564,1.094698,-350.331970,982.000671,0.000000
92.710007,219.066345,-350.376465,-0.000461,0.004310,0.109486,974.455750,49.641144,1.094864,-350.376465,982.000671,0.000000
93.160004,219.060028,-350.420929,-0.000466,0.004314,0.109574,974.427673,49.639713,1.095742,-350.420929,982.000671,0.000000
93.610008,219.049591,-350.420929,-0.000461,0.004316,0.109617,974.381226,49.637348,1.096166,-350.420929,982.000671,0.000000
94.060005,218.901001,-350.420929,-0.000474,0.004316,0.109626,973.720276,49.603676,1.096257,-350.420929,982.000671,0.000000
94.510002,220.194641,-350.509888,-0.000457,0.004276,0.108620,979.474670,49.896820,1.086204,-350.509888,982.000671,0.000000
94.960007,219.930267,-350.509888,-0.000448,0.004284,0.108819,978.298706,49.836910,1.088188,-350.509888,982.000671,0.000000
95.410004,219.781311,-350.554382,-0.000448,0.004294,0.109079,977.636108,49.803158,1.090792,-350.554382,982.000671,0.000000
95.860008,219.543365,-350.598846,-0.000440,0.004295,0.109097,976.577637,49.749241,1.090973,-350.598846,982.000671,0.000000
96.310005,219.491974,-350.598846,-0.000435,0.004309,0.109452,976.349060,49.737591,1.094516,-350.598846,982.000671,0.000000
96.760002,219.284180,-350.598846,-0.000431,0.004309,0.109461,975.424744,49.690506,1.094607,-350.598846,982.000671,0.000000
97.210007,219.133759,-350.643341,-0.000448,0.004316,0.109626,974.755615,49.656418,1.096257,-350.643341,982.000671,0.000000
97.660004,220.653412,-350.687805,-0.000440,0.004332,0.110024,981.515381,50.000778,1.100239,-350.687805,982.000671,0.000000
98.110008,220.453796,-350.732300,-0.000435,0.004332,0.110024,980.627441,49.955547,1.100239,-350.732300,982.000671,0.000000
98.560005,220.304871,-350.776794,-0.000435,0.004332,0.110024,979.965027,49.921799,1.100239,-350.776794,982.000671,0.000000
99.010002,220.099670,-350.821259,-0.000435,0.004332,0.110024,979.052246,49.875298,1.100239,-350.821259,982.000671,0.000000
99.460007,219.878479,-350.776794,-0.000435,0.004332,0.110024,978.068298,49.825176,1.100239,-350.776794,982.000671,0.000000
99.910004,219.687469,-350.821259,-0.000440,0.004333,0.110068,977.218689,49.781891,1.100678,-350.821259,982.000671,0.000000
100.360008,219.552307,-350.821259,-0.000444,0.004339,0.110216,976.617432,49.751266,1.102161,-350.821259,982.000671,0.000000
100.810005,219.619690,-350.865753,-0.000440,0.004345,0.110354,976.917175,49.766533,1.103539,-350.865753,982.000671,0.000000
101.260002,219.540741,-350.910217,-0.000427,0.004345,0.110372,976.565979,49.748646,1.103721,-350.910217,982.000671,0.000000
101.710007,219.506134,-350.910217,-0.000431,0.004347,0.110414,976.412048,49.740799,1.104145,-350.910217,982.000671,0.000000
102.160004,219.535553,-350.910217,-0.000427,0.004349,0.110467,976.542908,49.747467,1.104675,-350.910217,982.000671,0.000000
102.610008,219.523987,-350.999176,-0.000431,0.004350,0.110502,976.491455,49.744846,1.105023,-350.999176,982.000671,0.000000
103.060005,220.011444,-351.043671,-0.000418,0.004358,0.110684,978.659790,49.855305,1.106840,-351.043671,982.000671,0.000000
103.510002,219.933990,-351.088135,-0.000423,0.004357,0.110675,978.315247,49.837753,1.106749,-351.088135,982.000671,0.000000
103.960007,219.856537,-351.043671,-0.000423,0.004357,0.110675,977.970703,49.820206,1.106749,-351.043671,982.000671,0.000000
104.410004,219.762299,-351.132629,-0.000427,0.004358,0.110684,977.551514,49.798847,1.106840,-351.132629,982.000671,0.000000
104.860008,219.645020,-351.132629,-0.000423,0.004358,0.110693,977.029846,49.772274,1.106930,-351.132629,982.000671,0.000000
105.310005,219.627136,-351.177094,-0.000414,0.004360,0.110735,976.950317,49.768223,1.107354,-351.177094,982.000671,0.000000
105.760002,219.686340,-351.177094,-0.000423,0.004362,0.110796,977.213623,49.781635,1.107960,-351.177094,982.000671,0.000000
106.210007,219.649475,-351.221588,-0.000431,0.004362,0.110796,977.049683,49.773285,1.107960,-351.221588,982.000671,0.000000
106.660004,219.619690,-351.266083,-0.000423,0.004363,0.110831,976.917175,49.766533,1.108308,-351.266083,982.000671,0.000000
107.110008,219.558258,-351.266083,-0.000423,0.004364,0.110840,976.643921,49.752613,1.108399,-351.266083,982.000671,0.000000
107.560005,219.544098,-351.266083,-0.000423,0.004366,0.110884,976.580933,49.749405,1.108838,-351.266083,982.000671,0.000000
108.010002,219.592896,-351.310547,-0.000431,0.004367,0.110917,976.797974,49.760460,1.109171,-351.310547,982.000671,0.000000
108.460007,219.555267,-351.355042,-0.000427,0.004367,0.110917,976.630615,49.751934,1.109171,-351.355042,982.000671,0.000000
108.910004,219.542999,-351.399506,-0.000423,0.004368,0.110944,976.576050,49.749153,1.109444,-351.399506,982.000671,0.000000
109.360008,219.471497,-351.399506,-0.000427,0.004368,0.110952,976.257996,49.732952,1.109519,-351.399506,982.000671,0.000000
109.810005,219.526978,-351.444000,-0.000435,0.004370,0.110996,976.504761,49.745525,1.109958,-351.444000,982.000671,0.000000
110.260002,219.481171,-351.488464,-0.000427,0.004370,0.111005,976.301025,49.735142,1.110049,-351.488464,982.000671,0.000000
110.710007,219.617462,-351.444000,-0.000427,0.004375,0.111126,976.907288,49.766029,1.111260,-351.444000,982.000671,0.000000
111.160004,219.734375,-351.577423,-0.000410,0.004375,0.111126,977.427307,49.792522,1.111260,-351.577423,982.000671,0.000000
111.610008,219.668091,-351.488464,-0.000418,0.004375,0.111126,977.132446,49.777500,1.111260,-351.488464,982.000671,0.000000
112.060005,219.624908,-351.532959,-0.000423,0.004376,0.111143,976.940369,49.767715,1.111427,-351.532959,982.000671,0.000000
112.510002,219.595856,-351.577423,-0.000414,0.004376,0.111143,976.811157,49.761131,1.111427,-351.577423,982.000671,0.000000
112.960007,219.518402,-351.710876,-0.000431,0.004376,0.111152,976.466614,49.743584,1.111518,-351.710876,982.000671,0.000000
113.410004,219.611115,-351.666412,-0.000414,0.004379,0.111221,976.879028,49.764591,1.112214,-351.666412,982.000671,0.000000
113.860008,219.575012,-351.710876,-0.000423,0.004379,0.111221,976.718445,49.756409,1.112214,-351.710876,982.000671,0.000000
114.310005,219.538879,-351.755371,-0.000427,0.004379,0.111221,976.557678,49.748222,1.112214,-351.755371,982.000671,0.000000
114.760002,219.460693,-351.710876,-0.000418,0.004379,0.111230,976.209900,49.730503,1.112305,-351.710876,982.000671,0.000000
115.210007,219.462921,-351.710876,-0.000410,0.004383,0.111333,976.219849,49.731010,1.113334,-351.710876,982.000671,0.000000
115.660004,219.681122,-351.844330,-0.000410,0.004384,0.111343,977.190430,49.780453,1.113425,-351.844330,982.000671,0.000000
116.110008,219.643158,-351.799835,-0.000423,0.004384,0.111343,977.021545,49.771851,1.113425,-351.799835,982.000671,0.000000
116.560005,219.597351,-351.888794,-0.000427,0.004384,0.111343,976.817810,49.761471,1.113425,-351.888794,982.000671,0.000000
117.010002,219.539276,-351.888794,-0.000414,0.004384,0.111343,976.559448,49.748310,1.113425,-351.888794,982.000671,0.000000
117.460007,219.509094,-351.933289,-0.000435,0.004385,0.111386,976.425232,49.741470,1.113864,-351.933289,982.000671,0.000000
117.910004,219.487122,-351.933289,-0.000427,0.004385,0.111386,976.327454,49.736496,1.113864,-351.933289,982.000671,0.000000
118.360008,219.445038,-351.933289,-0.000414,0.004386,0.111396,976.140259,49.726959,1.113955,-351.933289,982.000671,0.000000
118.810005,219.443176,-351.977753,-0.000427,0.004387,0.111438,976.132019,49.726536,1.114379,-351.977753,982.000671,0.000000
119.260002,219.416382,-352.022247,-0.000418,0.004387,0.111438,976.012817,49.720463,1.114379,-352.022247,982.000671,0.000000
119.710007,219.840515,-352.066742,-0.000427,0.004393,0.111594,977.899475,49.816574,1.115938,-352.066742,982.000671,0.000000
120.160004,219.893402,-352.022247,-0.000427,0.004393,0.111594,978.134705,49.828560,1.115938,-352.022247,982.000671,0.000000
120.610008,219.878876,-352.066742,-0.000427,0.004393,0.111594,978.070068,49.825268,1.115938,-352.066742,982.000671,0.000000
121.060005,219.844238,-352.111206,-0.000431,0.004393,0.111594,977.916016,49.817417,1.115938,-352.111206,982.000671,0.000000
121.510002,219.786896,-352.155701,-0.000418,0.004393,0.111594,977.660950,49.804424,1.115938,-352.155701,982.000671,0.000000
121.960007,219.720245,-352.200165,-0.000401,0.004393,0.111594,977.364441,49.789322,1.115938,-352.200165,982.000671,0.000000
122.410004,219.651733,-352.244659,-0.000397,0.004393,0.111594,977.059692,49.773792,1.115938,-352.244659,982.000671,0.000000
122.860008,219.588776,-352.200165,-0.000423,0.004393,0.111594,976.779663,49.759529,1.115938,-352.200165,982.000671,0.000000
123.310005,219.538879,-352.244659,-0.000410,0.004393,0.111594,976.557678,49.748222,1.115938,-352.244659,982.000671,0.000000
123.760002,219.471130,-352.244659,-0.000410,0.004393,0.111594,976.256348,49.732872,1.115938,-352.244659,982.000671,0.000000
124.210007,219.527344,-352.289124,-0.000414,0.004396,0.111663,976.506409,49.745609,1.116635,-352.289124,982.000671,0.000000
124.660004,219.526978,-352.289124,-0.000423,0.004396,0.111663,976.504761,49.745525,1.116635,-352.289124,982.000671,0.000000
125.110008,219.569427,-352.289124,-0.000414,0.004399,0.111724,976.693604,49.755142,1.117240,-352.289124,982.000671,0.000000
125.560005,219.598083,-352.333618,-0.000423,0.004399,0.111724,976.821045,49.761635,1.117240,-352.333618,982.000671,0.000000
126.010010,219.586182,-352.378082,-0.000423,0.004399,0.111724,976.768127,49.758942,1.117240,-352.378082,982.000671,0.000000
126.460007,219.538879,-352.378082,-0.000401,0.004399,0.111733,976.557678,49.748222,1.117331,-352.378082,982.000671,0.000000
126.910004,219.520264,-352.422577,-0.000418,0.004399,0.111742,976.474915,49.743999,1.117422,-352.422577,982.000671,0.000000
127.360008,219.497192,-352.467041,-0.000418,0.004400,0.111759,976.372253,49.738773,1.117589,-352.467041,982.000671,0.000000
127.810005,219.499786,-352.467041,-0.000405,0.004401,0.111794,976.383789,49.739361,1.117937,-352.467041,982.000671,0.000000
128.260010,219.550812,-352.511536,-0.000401,0.004402,0.111803,976.610779,49.750923,1.118028,-352.511536,982.000671,0.000000
128.710007,219.537415,-352.556030,-0.000423,0.004402,0.111803,976.551208,49.747887,1.118028,-352.556030,982.000671,0.000000
129.160004,219.506500,-352.556030,-0.000414,0.004402,0.111810,976.413696,49.740883,1.118103,-352.556030,982.000671,0.000000
129.610001,219.640533,-352.644989,-0.000414,0.004405,0.111889,977.009888,49.771255,1.118891,-352.644989,982.000671,0.000000
130.060013,219.690063,-352.644989,-0.000410,0.004405,0.111889,977.230225,49.782478,1.118891,-352.644989,982.000671,0.000000
130.510010,219.652100,-352.644989,-0.000405,0.004405,0.111889,977.061340,49.773876,1.118891,-352.644989,982.000671,0.000000
130.960007,219.619690,-352.644989,-0.000405,0.004405,0.111889,976.917175,49.766533,1.118891,-352.644989,982.000671,0.000000
131.410004,219.650970,-352.689453,-0.000414,0.004406,0.111924,977.056335,49.773621,1.119239,-352.689453,982.000671,0.000000
131.860001,219.634216,-352.733948,-0.000397,0.004406,0.111924,976.981812,49.769825,1.119239,-352.733948,982.000671,0.000000
132.310013,219.605530,-352.733948,-0.000410,0.004406,0.111924,976.854187,49.763325,1.119239,-352.733948,982.000671,0.000000
132.760010,219.608887,-352.778412,-0.000414,0.004407,0.111933,976.869141,49.764084,1.119330,-352.778412,982.000671,0.000000
133.210007,219.575378,-352.822906,-0.000401,0.004407,0.111933,976.720093,49.756493,1.119330,-352.822906,982.000671,0.000000
133.660004,219.607788,-352.822906,-0.000405,0.004408,0.111975,976.864258,49.763836,1.119754,-352.822906,982.000671,0.000000
134.110001,219.628998,-352.867371,-0.000414,0.004408,0.111975,976.958557,49.768642,1.119754,-352.867371,982.000671,0.000000
134.560013,219.604065,-352.911865,-0.000401,0.004408,0.111975,976.847656,49.762993,1.119754,-352.911865,982.000671,0.000000
135.010010,219.593994,-352.956360,-0.000418,0.004409,0.111984,976.802856,49.760712,1.119844,-352.956360,982.000671,0.000000
135.460007,219.570923,-352.911865,-0.000414,0.004410,0.112003,976.700256,49.755482,1.120026,-352.911865,982.000671,0.000000
135.910004,219.610748,-352.867371,-0.000401,0.004411,0.112028,976.877380,49.764507,1.120283,-352.867371,982.000671,0.000000
136.360001,219.624542,-352.956360,-0.000418,0.004411,0.112028,976.938782,49.767635,1.120283,-352.956360,982.000671,0.000000
136.810013,219.596619,-353.000824,-0.000410,0.004411,0.112036,976.814575,49.761307,1.120359,-353.000824,982.000671,0.000000
137.260010,219.636444,-353.000824,-0.000423,0.004414,0.112106,976.991699,49.770329,1.121056,-353.000824,982.000671,0.000000
137.710007,219.743683,-353.089783,-0.000414,0.004414,0.112106,977.468750,49.794628,1.121056,-353.089783,982.000671,0.000000
138.160004,219.748901,-353.134277,-0.000418,0.004414,0.112106,977.491943,49.795811,1.121056,-353.134277,982.000671,0.000000
138.610001,219.719482,-353.134277,-0.000405,0.004414,0.112106,977.361084,49.789146,1.121056,-353.134277,982.000671,0.000000
139.060013,219.686707,-353.178741,-0.000401,0.004414,0.112106,977.215271,49.781719,1.121056,-353.178741,982.000671,0.000000
139.510010,219.677795,-353.178741,-0.000410,0.004414,0.112124,977.175659,49.779701,1.121237,-353.178741,982.000671,0.000000
139.960007,219.654327,-353.223236,-0.000414,0.004414,0.112124,977.071228,49.774380,1.121237,-353.223236,982.000671,0.000000
140.410004,219.630493,-353.223236,-0.000405,0.004415,0.112131,976.965210,49.768982,1.121313,-353.223236,982.000671,0.000000
140.860001,219.599945,-353.223236,-0.000410,0.004415,0.112140,976.829346,49.762058,1.121404,-353.223236,982.000671,0.000000
141.310013,219.514313,-353.356689,-0.000410,0.004405,0.111880,976.448425,49.742653,1.118800,-353.356689,0.112089,0.000000
141.760010,219.391815,-353.267700,-0.000401,0.004394,0.111603,975.903564,49.714893,1.116029,-353.267700,0.111333,0.000000
142.210007,219.077148,-353.312195,-0.000423,0.004365,0.110875,974.503845,49.643593,1.108747,-353.312195,0.110589,0.000000
142.660004,218.513733,-353.312195,-0.000405,0.004345,0.110354,971.997620,49.515919,1.103539,-353.312195,0.109833,0.000000
143.110001,217.118469,-353.356689,-0.000414,0.004315,0.109609,965.791199,49.199749,1.096090,-353.356689,0.109088,0.000000
143.560013,216.479095,-353.401154,-0.000384,0.004288,0.108923,962.947083,49.054863,1.089232,-353.401154,0.108333,0.000000
144.010010,216.160736,-353.401154,-0.000371,0.004264,0.108307,961.531006,48.982723,1.083070,-353.401154,0.107588,0.000000
144.460007,215.835266,-353.445648,-0.000362,0.004226,0.107337,960.083191,48.908970,1.073366,-353.445648,0.106834,0.000000
144.910004,215.381714,-353.534607,-0.000354,0.004197,0.106599,958.065735,48.806194,1.065993,-353.534607,0.106088,0.000000
145.360001,214.927063,-353.534607,-0.000375,0.004168,0.105879,956.043335,48.703171,1.058787,-353.534607,0.105341,0.000000
145.810013,214.396423,-353.534607,-0.000341,0.004140,0.105160,953.682922,48.582924,1.051595,-353.534607,0.104587,0.000000
146.260010,213.242432,-353.623566,-0.000341,0.004115,0.104509,948.549683,48.321426,1.045085,-353.623566,0.103841,0.000000
146.710007,211.605865,-353.579071,-0.000349,0.004084,0.103738,941.269897,47.950573,1.037379,-353.579071,0.103087,0.000000
147.160004,210.127167,-353.712524,-0.000332,0.004062,0.103182,934.692322,47.615498,1.031823,-353.712524,0.102341,0.000000
147.610001,207.714935,-353.623566,-0.000345,0.004033,0.102428,923.962158,47.068878,1.024283,-353.623566,0.101587,0.000000
148.060013,204.908386,-353.668030,-0.000349,0.004001,0.101621,911.478027,46.432903,1.016214,-353.668030,0.100840,0.000000
148.510010,201.854553,-353.756989,-0.000345,0.003972,0.100901,897.893921,45.740894,1.009008,-353.756989,0.100086,0.000000
148.960007,198.334869,-353.712524,-0.000341,0.003942,0.100130,882.237549,44.943325,1.001302,-353.712524,0.099340,0.000000
149.410004,194.942932,-353.801483,-0.000341,0.003912,0.099367,867.149475,44.174698,0.993671,-353.801483,0.098586,0.000000
149.860001,192.065613,-353.801483,-0.000336,0.003887,0.098733,854.350525,43.522690,0.987328,-353.801483,0.097840,0.000000
150.310013,188.394775,-353.845978,-0.000336,0.003854,0.097900,838.021790,42.690868,0.979001,-353.845978,0.097086,0.000000
150.760010,185.760239,-353.890442,-0.000354,0.003829,0.097251,826.302795,42.093872,0.972506,-353.890442,0.096339,0.000000
151.210007,181.838043,-353.845978,-0.000349,0.003789,0.096244,808.856018,41.205090,0.962438,-353.845978,0.095585,0.000000
151.660004,178.880661,-353.934937,-0.000349,0.003767,0.095681,795.700928,40.534939,0.956806,-353.934937,0.094839,0.000000
152.110001,176.142227,-353.934937,-0.000349,0.003740,0.095004,783.519775,39.914398,0.950039,-353.934937,0.094085,0.000000
152.560013,173.077606,-353.934937,-0.000341,0.003715,0.094362,769.887634,39.219944,0.943620,-353.934937,0.093339,0.000000
153.010010,168.645996,-354.023895,-0.000358,0.003680,0.093469,750.174866,38.215729,0.934687,-354.023895,0.092585,0.000000
153.460007,164.748383,-353.979401,-0.000345,0.003647,0.092636,732.837402,37.332516,0.926361,-353.979401,0.091838,0.000000
153.910004,161.885956,-354.023895,-0.000349,0.003622,0.091996,720.104675,36.683880,0.919957,-354.023895,0.091084,0.000000
154.360001,157.849808,-354.023895,-0.000336,0.003591,0.091214,702.151001,35.769279,0.912145,-354.023895,0.090338,0.000000
154.810013,154.162949,-354.157318,-0.000345,0.003559,0.090391,685.751038,34.933823,0.903909,-354.157318,0.089584,0.000000
155.260010,149.947693,-354.068359,-0.000341,0.003524,0.089498,667.000671,33.978634,0.894976,-354.068359,0.088838,0.000000
155.710007,147.309052,-354.112854,-0.000341,0.003501,0.088916,655.263367,33.380711,0.889163,-354.112854,0.088084,0.000000
156.160004,143.124344,-354.157318,-0.000319,0.003465,0.088006,636.648865,32.432442,0.880064,-354.157318,0.087339,0.000000
156.610001,140.335266,-354.201813,-0.000345,0.003441,0.087407,624.242432,31.800426,0.874068,-354.201813,0.086583,0.000000
157.060013,136.216461,-354.157318,-0.000349,0.003405,0.086479,605.921082,30.867092,0.864788,-354.157318,0.085838,0.000000
157.510010,133.660110,-354.290771,-0.000358,0.003385,0.085967,594.549866,30.287813,0.859671,-354.290771,0.085083,0.000000
157.960007,130.088318,-354.246307,-0.000336,0.003351,0.085127,578.661743,29.478434,0.851268,-354.246307,0.084338,0.000000
158.410004,126.959274,-354.290771,-0.000345,0.003321,0.084364,564.743042,28.769382,0.843638,-354.290771,0.083583,0.000000
158.860001,123.509613,-354.379730,-0.000345,0.003295,0.083704,549.398193,27.987679,0.837037,-354.379730,0.082838,0.000000
159.310013,119.868561,-354.335266,-0.000336,0.003265,0.082924,533.201965,27.162603,0.829240,-354.335266,0.082082,0.000000
159.760010,116.952515,-354.379730,-0.000345,0.003237,0.082231,520.230774,26.501818,0.822306,-354.379730,0.081337,0.000000
160.210007,113.317413,-354.379730,-0.000345,0.003208,0.081475,504.061035,25.678093,0.814752,-354.379730,0.080582,0.000000
160.660004,110.084839,-354.424225,-0.000332,0.003178,0.080721,489.681824,24.945581,0.807212,-354.424225,0.079837,0.000000
161.110001,105.981308,-354.468689,-0.000323,0.003143,0.079828,471.428406,24.015709,0.798280,-354.468689,0.079082,0.000000
161.560013,103.702011,-354.513184,-0.000341,0.003123,0.079325,461.289581,23.499210,0.793253,-354.513184,0.078337,0.000000
162.010010,99.740707,-354.513184,-0.000336,0.003087,0.078414,443.668823,22.601566,0.784139,-354.513184,0.077581,0.000000
162.460007,96.135025,-354.557648,-0.000332,0.003057,0.077642,427.629944,21.784508,0.776418,-354.557648,0.076836,0.000000
162.910004,93.623383,-354.557648,-0.000349,0.003036,0.077104,416.457611,21.215363,0.771044,-354.557648,0.076081,0.000000
163.360001,89.872833,-354.646637,-0.000332,0.003001,0.076229,399.774323,20.365477,0.762293,-354.646637,0.075336,0.000000
163.810013,87.313522,-354.557648,-0.000341,0.002977,0.075604,388.389954,19.785528,0.756040,-354.557648,0.074581,0.000000
164.260010,84.357635,-354.602142,-0.000341,0.002950,0.074927,375.241516,19.115713,0.749273,-354.602142,0.073836,0.000000
164.710007,80.369522,-354.735596,-0.000354,0.002916,0.074069,357.501495,18.211994,0.740689,-354.735596,0.073080,0.000000
165.160004,77.155197,-354.691101,-0.000345,0.002887,0.073324,343.203461,17.483618,0.733240,-354.691101,0.072335,0.000000
165.610001,74.212341,-354.691101,-0.000332,0.002861,0.072664,330.112976,16.816757,0.726639,-354.691101,0.071589,0.000000
166.060013,70.523621,-354.780060,-0.000345,0.002826,0.071780,313.704742,15.980881,0.717798,-354.780060,0.070835,0.000000
166.510010,67.058319,-354.735596,-0.000345,0.002795,0.070991,298.290314,15.195632,0.709910,-354.735596,0.070089,0.000000
166.960007,64.039124,-354.780060,-0.000336,0.002768,0.070305,284.860260,14.511473,0.703052,-354.780060,0.069335,0.000000
167.410004,60.842682,-354.869019,-0.000345,0.002739,0.069577,270.641754,13.787149,0.695770,-354.869019,0.068588,0.000000
167.860001,57.663742,-354.824554,-0.000332,0.002710,0.068823,256.501129,13.066791,0.688230,-354.824554,0.067834,0.000000
168.310013,54.063271,-354.913513,-0.000341,0.002677,0.068007,240.485443,12.250912,0.680070,-354.913513,0.067088,0.000000
168.760010,51.334152,-354.913513,-0.000328,0.002651,0.067339,228.345718,11.632484,0.673393,-354.913513,0.066334,0.000000
169.210007,48.567795,-354.957977,-0.000345,0.002628,0.066750,216.040344,11.005620,0.667504,-354.957977,0.065588,0.000000
169.660004,44.092995,-354.957977,-0.000336,0.002587,0.065701,196.135437,9.991615,0.657012,-354.957977,0.064834,0.000000
170.110001,40.902138,-354.957977,-0.000345,0.002557,0.064955,181.941803,9.268558,0.649549,-354.957977,0.064087,0.000000
170.560013,38.445221,-355.046967,-0.000341,0.002535,0.064399,171.012878,8.711812,0.643992,-355.046967,0.063333,0.000000
171.010010,35.296814,-355.091431,-0.000341,0.002506,0.063645,157.008072,7.998373,0.636453,-355.091431,0.062587,0.000000
171.460007,31.828163,-355.046967,-0.000328,0.002476,0.062899,141.578735,7.212365,0.628989,-355.046967,0.061833,0.000000
171.910004,28.712151,-355.135925,-0.000336,0.002447,0.062145,127.718025,6.506266,0.621449,-355.135925,0.061087,0.000000
172.360001,25.753281,-355.135925,-0.000341,0.002419,0.061442,114.556313,5.835777,0.614425,-355.135925,0.060333,0.000000
172.810013,21.625534,-355.180389,-0.000341,0.002381,0.060480,96.195183,4.900416,0.604796,-355.180389,0.059586,0.000000
173.260010,19.464653,-355.224884,-0.000328,0.002358,0.059882,86.583099,4.410754,0.598816,-355.224884,0.058832,0.000000
173.710007,16.560150,-355.180389,-0.000345,0.002331,0.059214,73.663223,3.752584,0.592139,-355.180389,0.058086,0.000000
174.160004,12.825630,-355.224884,-0.000332,0.002296,0.058330,57.051254,2.906329,0.583298,-355.224884,0.057332,0.000000
174.610016,9.351761,-355.269348,-0.000332,0.002262,0.057453,41.598709,2.119139,0.574532,-355.269348,0.056586,0.000000
175.060013,6.797287,-355.358307,-0.000341,0.002239,0.056881,30.235842,1.540287,0.568809,-355.358307,0.055832,0.000000
175.510010,3.717766,-355.313843,-0.000345,0.002208,0.056083,16.537449,0.842458,0.560831,-355.313843,0.055085,0.000000
175.960007,0.792412,-355.358307,-0.000341,0.002177,0.055285,3.524824,0.179563,0.552852,-355.358307,0.054331,0.000000
176.410004,-1.319313,-355.402802,-0.000332,0.002151,0.054627,-5.868598,-0.298961,0.546266,-355.402802,0.053585,0.000000
176.860016,-0.169426,-355.358307,-0.000345,0.002120,0.053855,-0.753644,-0.038392,0.538545,-355.358307,0.052831,0.000000
177.310013,-0.060692,-355.447266,-0.000341,0.002085,0.052970,-0.269971,-0.013753,0.529704,-355.447266,0.052085,0.000000
177.760010,-0.059578,-355.447266,-0.000332,0.002059,0.052310,-0.265016,-0.013501,0.523103,-355.447266,0.051331,0.000000
178.210007,-0.066650,-355.447266,-0.000319,0.002031,0.051591,-0.296476,-0.015103,0.515911,-355.447266,0.050584,0.000000
178.660004,-0.056602,-355.536255,-0.000319,0.001995,0.050680,-0.251780,-0.012826,0.506797,-355.536255,0.049830,0.000000
179.110016,-0.069260,-355.491760,-0.000319,0.001977,0.050221,-0.308082,-0.015694,0.502210,-355.491760,0.049084,0.000000
179.560013,-0.107239,-355.536255,-0.000341,0.001938,0.049223,-0.477022,-0.024301,0.492233,-355.536255,0.048330,0.000000
180.010010,-0.106125,-355.580719,-0.000384,0.001910,0.048521,-0.472067,-0.024048,0.485208,-355.580719,0.047584,0.000000
180.460007,-0.099419,-355.580719,-0.000479,0.001874,0.047593,-0.442236,-0.022529,0.475928,-355.580719,0.046830,0.000000
180.910004,-0.113945,-355.580719,-0.000509,0.001856,0.047151,-0.506853,-0.025820,0.471507,-355.580719,0.046083,0.000000
181.360016,-0.124374,-355.714172,-0.000573,0.001816,0.046127,-0.553245,-0.028184,0.461273,-355.714172,0.045329,0.000000
181.810013,-0.091599,-355.669678,-0.000625,0.001790,0.045460,-0.407451,-0.020757,0.454596,-355.669678,0.044583,0.000000
182.260010,-0.134796,-355.714172,-0.000651,0.001764,0.044801,-0.599603,-0.030545,0.448010,-355.714172,0.043829,0.000000
182.710007,-0.110596,-355.714172,-0.000707,0.001735,0.044064,-0.491954,-0.025061,0.440637,-355.714172,0.043083,0.000000
183.160004,-0.112823,-355.803131,-0.000776,0.001710,0.043438,-0.501864,-0.025566,0.434385,-355.803131,0.042329,0.000000
183.610016,-0.141502,-355.803131,-0.000802,0.001679,0.042659,-0.629434,-0.032065,0.426588,-355.803131,0.041584,0.000000
184.060013,-0.128838,-355.803131,-0.000841,0.001648,0.041852,-0.573098,-0.029195,0.418519,-355.803131,0.040828,0.000000
184.510010,-0.071121,-355.803131,-0.000871,0.001615,0.041019,-0.316363,-0.016116,0.410192,-355.803131,0.040942,0.000000
184.600006,-0.071121,-355.892090,-0.000888,0.001615,0.041028,-0.316363,-0.016116,0.410283,-355.892090,0.040942,0.000000