File: Data/sima compression 500bar/P1-17-500bar-3_11072024_170332.csv
Time (sec),S:Load (lbs),S:HL1 (DIM),S:LVDT (in),S:Position (in),Ch:Position (mm),Ch:Load (N),Ch:Stress (MPa),Ch:Strain (mm/mm),Ch:HL1 (DIM),Set Point (),Cycles ()
0.010000,-0.087875,-372.616913,-0.010421,-0.007271,-0.184676,-0.390889,-0.019913,-1.846756,-372.616913,-0.184494,0.000000
0.460000,-0.134056,-372.705902,-0.010404,-0.007196,-0.182777,-0.596311,-0.030378,-1.827771,-372.705902,-0.182205,0.000000
0.910000,-0.158630,-372.705902,-0.010210,-0.006916,-0.175657,-0.705623,-0.035946,-1.756570,-372.705902,-0.174711,0.000000
1.360000,-0.063301,-372.705902,-0.009904,-0.006624,-0.168242,-0.281577,-0.014344,-1.682416,-372.705902,-0.167218,0.000000
1.810000,-0.037979,-372.750366,-0.009602,-0.006327,-0.160698,-0.168940,-0.008606,-1.606976,-372.750366,-0.159726,0.000000
2.260000,-0.113197,-372.794861,-0.009309,-0.006034,-0.153266,-0.503527,-0.025651,-1.532655,-372.794861,-0.152215,0.000000
2.710000,-0.076706,-372.794861,-0.009002,-0.005737,-0.145729,-0.341205,-0.017382,-1.457291,-372.794861,-0.144722,0.000000
3.160000,-0.106499,-372.839325,-0.008701,-0.005439,-0.138158,-0.473730,-0.024133,-1.381577,-372.839325,-0.137230,0.000000
3.610000,-0.094582,-372.794861,-0.008403,-0.005153,-0.130891,-0.420720,-0.021432,-1.308908,-372.794861,-0.129737,0.000000
4.060000,-0.056969,-372.794861,-0.008084,-0.004851,-0.123215,-0.253409,-0.012909,-1.232150,-372.794861,-0.122226,0.000000
4.510000,-0.095329,-372.883820,-0.007787,-0.004569,-0.116062,-0.424046,-0.021602,-1.160615,-372.883820,-0.114734,0.000000
4.960000,-0.156395,-372.972778,-0.007450,-0.004263,-0.108290,-0.695680,-0.035440,-1.082904,-372.972778,-0.107241,0.000000
5.410000,-0.047661,-372.883820,-0.007161,-0.003964,-0.100693,-0.212006,-0.010800,-1.006933,-372.883820,-0.099749,0.000000
5.860000,-0.040215,-373.017242,-0.006877,-0.003685,-0.093591,-0.178883,-0.009113,-0.935914,-373.017242,-0.092238,0.000000
6.310000,-0.065910,-373.017242,-0.006558,-0.003377,-0.085778,-0.293184,-0.014935,-0.857778,-373.017242,-0.084745,0.000000
6.760000,-0.062553,-373.017242,-0.006256,-0.003078,-0.078188,-0.278251,-0.014175,-0.781884,-373.017242,-0.077253,0.000000
7.210001,-0.112457,-373.017242,-0.005954,-0.002790,-0.070861,-0.500235,-0.025483,-0.708608,-373.017242,-0.069760,0.000000
7.660000,-0.068146,-373.017242,-0.005631,-0.002493,-0.063317,-0.303127,-0.015442,-0.633168,-373.017242,-0.062249,0.000000
8.110001,-0.051010,-373.061737,-0.005325,-0.002193,-0.055702,-0.226904,-0.011559,-0.557015,-373.061737,-0.054757,0.000000
8.560000,-0.056229,-373.106232,-0.005040,-0.001909,-0.048495,-0.250117,-0.012742,-0.484951,-373.106232,-0.047264,0.000000
9.010000,-0.102402,-373.150696,-0.004725,-0.001605,-0.040777,-0.455506,-0.023205,-0.407769,-373.150696,-0.039772,0.000000
9.460000,-0.125488,-373.106232,-0.004424,-0.001308,-0.033224,-0.558200,-0.028436,-0.332238,-373.106232,-0.032278,0.000000
9.910001,-0.029045,-373.195190,-0.004126,-0.001027,-0.026085,-0.129199,-0.006582,-0.260855,-373.195190,-0.024768,0.000000
10.360001,-0.075592,-373.239655,-0.003824,-0.000721,-0.018307,-0.336250,-0.017129,-0.183068,-373.239655,-0.017276,0.000000
10.810000,-0.077080,-373.150696,-0.003518,-0.000425,-0.010788,-0.342868,-0.017467,-0.107885,-373.150696,-0.009782,0.000000
11.260000,-0.032768,-373.239655,-0.003229,-0.000135,-0.003434,-0.145760,-0.007425,-0.034337,-373.239655,-0.002289,0.000000
11.710001,0.032028,-373.239655,-0.003087,0.000008,0.000209,0.142469,0.007258,0.002089,-373.239655,0.000435,0.000000
12.160001,0.051392,-373.328613,-0.003096,0.000008,0.000209,0.228601,0.011646,0.002089,-373.328613,0.000755,0.000000
12.610001,0.114319,-373.328613,-0.003078,0.000022,0.000547,0.508516,0.025905,0.005465,-373.328613,0.001500,0.000000
13.060000,0.407753,-373.373108,-0.003048,0.000059,0.001509,1.813776,0.092398,0.015094,-373.373108,0.002256,0.000000
13.510000,0.829277,-373.373108,-0.003040,0.000085,0.002160,3.688808,0.187917,0.021604,-373.373108,0.003001,0.000000
13.960001,1.640305,-373.417572,-0.003018,0.000118,0.003010,7.296439,0.371698,0.030097,-373.417572,0.003756,0.000000
14.410001,2.594696,-373.462067,-0.002984,0.000147,0.003729,11.541784,0.587967,0.037289,-373.462067,0.004501,0.000000
14.860001,3.791122,-373.462067,-0.002988,0.000179,0.004554,16.863754,0.859081,0.045540,-373.462067,0.005256,0.000000
15.310000,4.739555,-373.462067,-0.002966,0.000204,0.005187,21.082596,1.073999,0.051868,-373.462067,0.006001,0.000000
15.760001,5.813850,-373.462067,-0.002945,0.000231,0.005864,25.861298,1.317437,0.058636,-373.462067,0.006757,0.000000
16.210001,7.338715,-373.551025,-0.002919,0.000263,0.006669,32.644234,1.662977,0.066690,-373.551025,0.007502,0.000000
16.660000,8.228691,-373.551025,-0.002902,0.000284,0.007225,36.603046,1.864648,0.072246,-373.551025,0.008257,0.000000
17.110001,10.080124,-373.551025,-0.002889,0.000322,0.008187,44.838631,2.284189,0.081875,-373.551025,0.009002,0.000000
17.560001,11.433701,-373.595520,-0.002889,0.000347,0.008820,50.859642,2.590914,0.088203,-373.595520,0.009757,0.000000
18.010000,13.251617,-373.639984,-0.002876,0.000383,0.009739,58.946136,3.002860,0.097393,-373.639984,0.010502,0.000000
18.460001,14.213455,-373.684479,-0.002846,0.000405,0.010286,63.224606,3.220815,0.102858,-373.684479,0.011258,0.000000
18.910002,15.991913,-373.684479,-0.002828,0.000436,0.011067,71.135582,3.623819,0.110670,-373.684479,0.012003,0.000000
19.360001,17.401337,-373.728943,-0.002815,0.000465,0.011812,77.405014,3.943199,0.118119,-373.728943,0.012758,0.000000
19.810001,19.263199,-373.728943,-0.002790,0.000500,0.012705,85.686989,4.365103,0.127051,-373.728943,0.013503,0.000000
20.260000,20.651405,-373.773437,-0.002781,0.000529,0.013433,91.862038,4.679675,0.134333,-373.773437,0.014249,0.000000
20.710001,22.122276,-373.817902,-0.002768,0.000557,0.014145,98.404800,5.012980,0.141449,-373.817902,0.015003,0.000000
21.160002,23.271416,-373.862396,-0.002746,0.000584,0.014838,103.516426,5.273378,0.148383,-373.862396,0.015750,0.000000
21.610001,24.730743,-373.862396,-0.002734,0.000617,0.015680,110.007843,5.604066,0.156801,-373.862396,0.016504,0.000000
22.060001,26.002396,-373.862396,-0.002712,0.000646,0.016399,115.664429,5.892227,0.163992,-373.862396,0.017250,0.000000
22.510000,26.853271,-373.906860,-0.002703,0.000675,0.017136,119.449318,6.085038,0.171365,-373.906860,0.018004,0.000000
22.960001,28.312225,-373.906860,-0.002686,0.000703,0.017857,125.939072,6.415642,0.178571,-373.906860,0.018750,0.000000
23.410002,29.509773,-373.951355,-0.002660,0.000733,0.018620,131.266022,6.687010,0.186202,-373.951355,0.019504,0.000000
23.860001,30.679398,-373.995850,-0.002660,0.000766,0.019444,136.468781,6.952051,0.194438,-373.995850,0.020251,0.000000
24.310001,30.990326,-373.995850,-0.002621,0.000783,0.019886,137.851852,7.022509,0.198858,-373.995850,0.021005,0.000000
24.760000,32.954964,-373.995850,-0.002596,0.000826,0.020979,146.591003,7.467701,0.209789,-373.995850,0.021751,0.000000
25.210001,33.091629,-374.084808,-0.002600,0.000846,0.021491,147.198914,7.498670,0.214906,-374.084808,0.022505,0.000000
25.660002,34.595634,-374.084808,-0.002574,0.000883,0.022426,153.889069,7.839483,0.224263,-374.084808,0.023251,0.000000
26.110001,35.396980,-374.040314,-0.002544,0.000911,0.023138,157.453629,8.021070,0.231378,-374.040314,0.024005,0.000000
26.560001,36.311531,-374.084808,-0.002531,0.000942,0.023919,161.521759,8.228311,0.239190,-374.084808,0.024752,0.000000
27.010002,36.601982,-374.173767,-0.002501,0.000967,0.024561,162.813751,8.294127,0.245609,-374.173767,0.025506,0.000000
27.460001,37.463654,-374.173767,-0.002496,0.000999,0.025366,166.646652,8.489385,0.253664,-374.173767,0.026252,0.000000
27.910002,38.118652,-374.218231,-0.002488,0.001030,0.026157,169.560242,8.637810,0.261567,-374.218231,0.027006,0.000000
28.360001,37.540733,-374.218231,-0.002458,0.001044,0.026520,166.989517,8.506852,0.265200,-374.218231,0.027752,0.000000
28.810001,39.649475,-374.218231,-0.002432,0.001092,0.027725,176.369675,8.984699,0.277251,-374.218231,0.028506,0.000000
29.260002,39.810715,-374.262726,-0.002436,0.001118,0.028385,177.086899,9.021236,0.283852,-374.262726,0.029253,0.000000
29.710001,40.410606,-374.351685,-0.002414,0.001148,0.029148,179.755356,9.157174,0.291482,-374.351685,0.030007,0.000000
30.160002,40.164093,-374.396179,-0.002389,0.001166,0.029625,178.658813,9.101314,0.296251,-374.396179,0.030753,0.000000
30.610001,41.627144,-374.351685,-0.002389,0.001209,0.030709,185.166779,9.432845,0.307091,-374.351685,0.031507,0.000000
31.060001,41.450272,-374.396179,-0.002367,0.001232,0.031281,184.380020,9.392766,0.312814,-374.396179,0.032253,0.000000
31.510002,42.410988,-374.440643,-0.002358,0.001267,0.032175,188.653503,9.610467,0.321746,-374.440643,0.033007,0.000000
31.960001,42.731606,-374.440643,-0.002337,0.001292,0.032807,190.079681,9.683120,0.328075,-374.440643,0.033752,0.000000
32.410000,43.764565,-374.485138,-0.002337,0.001327,0.033710,194.674500,9.917192,0.337098,-374.485138,0.034508,0.000000
32.860001,43.811859,-374.485138,-0.002320,0.001352,0.034352,194.884888,9.927910,0.343517,-374.485138,0.035253,0.000000
33.310001,44.653793,-374.574097,-0.002289,0.001386,0.035192,198.629990,10.118694,0.351920,-374.574097,0.036008,0.000000
33.760002,44.686562,-374.529602,-0.002276,0.001406,0.035713,198.775757,10.126120,0.357128,-374.529602,0.036753,0.000000
34.210003,45.704254,-374.574097,-0.002264,0.001445,0.036692,203.302673,10.356731,0.366923,-374.574097,0.037508,0.000000
34.660000,46.503365,-374.618561,-0.002246,0.001474,0.037448,206.857300,10.537812,0.374478,-374.618561,0.038253,0.000000
35.110001,46.723434,-374.663055,-0.002238,0.001499,0.038081,207.836212,10.587681,0.380806,-374.663055,0.039009,0.000000
35.560001,47.679687,-374.663055,-0.002216,0.001530,0.038869,212.089844,10.804371,0.388694,-374.663055,0.039754,0.000000
36.010002,47.527016,-374.618561,-0.002195,0.001551,0.039390,211.410721,10.769776,0.393902,-374.618561,0.040509,0.000000
36.460003,49.191895,-374.707520,-0.002182,0.001591,0.040414,218.816483,11.147042,0.404136,-374.707520,0.041254,0.000000
36.910000,49.489418,-374.707520,-0.002169,0.001619,0.041116,220.139923,11.214462,0.411161,-374.707520,0.042009,0.000000
37.360001,50.850067,-374.752014,-0.002151,0.001651,0.041931,226.192398,11.522790,0.419306,-374.752014,0.042754,0.000000
37.810001,51.165840,-374.752014,-0.002134,0.001673,0.042495,227.597031,11.594345,0.424953,-374.752014,0.043510,0.000000
38.260002,51.998466,-374.796509,-0.002117,0.001704,0.043293,231.300735,11.783021,0.432931,-374.796509,0.044255,0.000000
38.710003,52.917480,-374.796509,-0.002104,0.001732,0.043994,235.388702,11.991273,0.439941,-374.796509,0.045010,0.000000
39.160004,54.580124,-374.885468,-0.002082,0.001769,0.044922,242.784515,12.368033,0.449222,-374.885468,0.045755,0.000000
39.610001,55.155441,-374.885468,-0.002070,0.001793,0.045547,245.343658,12.498402,0.455474,-374.885468,0.046510,0.000000
40.060001,56.380173,-374.929932,-0.002061,0.001823,0.046310,250.791534,12.775930,0.463105,-374.929932,0.047255,0.000000
40.510002,57.611610,-374.885468,-0.002048,0.001851,0.047022,256.269257,13.054977,0.470220,-374.885468,0.048002,0.000000
40.960003,58.922356,-374.929932,-0.002035,0.001881,0.047767,262.099731,13.351997,0.477669,-374.929932,0.048756,0.000000
41.410004,60.544411,-374.974426,-0.002026,0.001912,0.048574,269.315002,13.719560,0.485738,-374.974426,0.049502,0.000000
41.860001,60.943596,-374.974426,-0.002001,0.001932,0.049076,271.090668,13.810017,0.490765,-374.974426,0.050256,0.000000
42.310001,63.485779,-375.018890,-0.002005,0.001974,0.050144,282.398834,14.386083,0.501438,-375.018890,0.051002,0.000000
42.760002,64.484863,-375.018890,-0.001983,0.002001,0.050821,286.842987,14.612479,0.508205,-375.018890,0.051756,0.000000
43.210003,66.153091,-375.018890,-0.001962,0.002035,0.051679,294.263641,14.990505,0.516790,-375.018890,0.052503,0.000000
43.660004,66.720581,-375.107849,-0.001949,0.002055,0.052191,296.787964,15.119100,0.521907,-375.107849,0.053257,0.000000
44.110001,68.198151,-375.107849,-0.001936,0.002089,0.053057,303.360535,15.453922,0.530567,-375.107849,0.054003,0.000000
44.560001,69.434433,-375.152344,-0.001923,0.002116,0.053752,308.859772,15.734067,0.537516,-375.152344,0.054757,0.000000
45.010002,71.334274,-375.196808,-0.001919,0.002152,0.054671,317.310699,16.164577,0.546705,-375.196808,0.055503,0.000000
45.460003,72.197067,-375.196808,-0.001906,0.002179,0.055355,321.148590,16.360090,0.553548,-375.196808,0.056257,0.000000
45.910004,73.735336,-375.196808,-0.001906,0.002211,0.056171,327.991150,16.708666,0.561709,-375.196808,0.057004,0.000000
46.360001,75.033051,-375.241302,-0.001880,0.002236,0.056804,333.763672,17.002731,0.568037,-375.241302,0.057757,0.000000
46.810001,76.199326,-375.285797,-0.001867,0.002265,0.057532,338.951538,17.267014,0.575319,-375.285797,0.058504,0.000000
47.260002,77.670944,-375.285797,-0.001876,0.002296,0.058321,345.497620,17.600487,0.583207,-375.285797,0.059258,0.000000
47.710003,77.925644,-375.285797,-0.001841,0.002313,0.058746,346.630585,17.658203,0.587461,-375.285797,0.060004,0.000000
48.160004,80.720291,-375.374756,-0.001819,0.002356,0.059848,359.061798,18.291479,0.598483,-375.374756,0.060758,0.000000
48.610001,81.858643,-375.374756,-0.001828,0.002384,0.060558,364.125427,18.549433,0.605583,-375.374756,0.061505,0.000000
49.060001,83.621445,-375.374756,-0.001815,0.002415,0.061349,371.966766,18.948891,0.613486,-375.374756,0.062258,0.000000
49.510002,84.480881,-375.419220,-0.001819,0.002436,0.061877,375.789734,19.143641,0.618770,-375.419220,0.063005,0.000000
49.960003,86.921783,-375.419220,-0.001798,0.002476,0.062900,386.647400,19.696756,0.629004,-375.419220,0.063759,0.000000
50.410004,87.773773,-375.419220,-0.001794,0.002499,0.063482,390.437256,19.889820,0.634818,-375.419220,0.064505,0.000000
50.860001,89.988281,-375.463715,-0.001776,0.002535,0.064384,400.287872,20.391636,0.643841,-375.463715,0.065259,0.000000
51.310001,91.186935,-375.508179,-0.001781,0.002560,0.065034,405.619751,20.663256,0.650336,-375.508179,0.066006,0.000000
51.760002,93.049927,-375.508179,-0.001781,0.002594,0.065883,413.906738,21.085415,0.658829,-375.508179,0.066759,0.000000
52.210003,94.585953,-375.552673,-0.001755,0.002619,0.066525,420.739319,21.433483,0.665248,-375.552673,0.067506,0.000000
52.660004,96.171143,-375.552673,-0.001750,0.002650,0.067315,427.790619,21.792692,0.673151,-375.552673,0.068260,0.000000
53.110004,97.692291,-375.597137,-0.001750,0.002676,0.067974,434.557007,22.137390,0.679737,-375.597137,0.069006,0.000000
53.560001,99.300201,-375.641632,-0.001742,0.002710,0.068823,441.709351,22.501747,0.688230,-375.641632,0.069760,0.000000
54.010002,101.595871,-375.641632,-0.001733,0.002741,0.069630,451.920990,23.021954,0.696300,-375.641632,0.070507,0.000000
54.460003,102.912582,-375.686127,-0.001720,0.002767,0.070281,457.778015,23.320324,0.702810,-375.686127,0.071260,0.000000
54.910004,105.281982,-375.775085,-0.001716,0.002800,0.071121,468.317657,23.857237,0.711212,-375.775085,0.072007,0.000000
55.360004,106.123550,-375.730591,-0.001712,0.002820,0.071616,472.061127,24.047939,0.716163,-375.730591,0.072761,0.000000
55.810001,108.753616,-375.730591,-0.001699,0.002858,0.072605,483.760254,24.643923,0.726049,-375.730591,0.073507,0.000000
56.260002,110.034195,-375.775085,-0.001686,0.002883,0.073221,489.456543,24.934105,0.732211,-375.775085,0.074261,0.000000
56.710003,112.518295,-375.864044,-0.001686,0.002918,0.074105,500.506378,25.497009,0.741052,-375.864044,0.075008,0.000000
57.160004,114.254303,-375.819550,-0.001669,0.002944,0.074790,508.228516,25.890396,0.747895,-375.819550,0.075761,0.000000
57.610004,116.310913,-375.819550,-0.001669,0.002977,0.075615,517.376770,26.356430,0.756146,-375.819550,0.076508,0.000000
58.060001,118.031647,-375.908508,-0.001647,0.003001,0.076229,525.031006,26.746353,0.762293,-375.908508,0.077262,0.000000
58.510002,119.646255,-375.908508,-0.001651,0.003031,0.076985,532.213135,27.112228,0.769848,-375.908508,0.078008,0.000000
58.960003,122.070023,-375.997467,-0.001647,0.003060,0.077721,542.994568,27.661463,0.777205,-375.997467,0.078762,0.000000
59.410004,123.029251,-375.953003,-0.001634,0.003080,0.078225,547.261414,27.878826,0.782247,-375.953003,0.079507,0.000000
59.860004,126.411148,-375.997467,-0.001630,0.003124,0.079351,562.304871,28.645176,0.793511,-375.997467,0.080253,0.000000
60.310001,127.820938,-376.041962,-0.001621,0.003146,0.079898,568.575928,28.964638,0.798976,-376.041962,0.081007,0.000000
60.760002,130.672577,-376.086456,-0.001643,0.003182,0.080835,581.260681,29.610830,0.808348,-376.086456,0.081754,0.000000
61.210003,131.536484,-375.997467,-0.001625,0.003199,0.081251,585.103516,29.806593,0.812511,-375.997467,0.082508,0.000000
61.660004,134.210480,-376.041962,-0.001604,0.003234,0.082153,596.998047,30.412529,0.821534,-376.041962,0.083254,0.000000
62.110004,136.210129,-376.041962,-0.001600,0.003265,0.082924,605.892883,30.865656,0.829240,-376.041962,0.084008,0.000000
62.560001,138.727356,-376.130920,-0.001595,0.003295,0.083705,617.090088,31.436068,0.837052,-376.130920,0.084754,0.000000
63.010002,140.745621,-376.130920,-0.001582,0.003325,0.084452,626.067810,31.893412,0.844516,-376.130920,0.085508,0.000000
63.460003,143.135132,-376.219879,-0.001587,0.003354,0.085187,636.696838,32.434883,0.851874,-376.219879,0.086255,0.000000
63.910004,145.049133,-376.175415,-0.001574,0.003381,0.085882,645.210754,32.868603,0.858823,-376.175415,0.087009,0.000000
64.360001,147.287460,-376.219879,-0.001574,0.003412,0.086671,655.167358,33.375816,0.866711,-376.219879,0.087755,0.000000
64.810005,149.774902,-376.264374,-0.001556,0.003440,0.087383,666.232056,33.939476,0.873826,-376.264374,0.088509,0.000000
65.260002,150.693558,-376.264374,-0.001556,0.003461,0.087920,670.318420,34.147648,0.879201,-376.264374,0.089255,0.000000
65.710007,154.259384,-376.308838,-0.001544,0.003498,0.088848,686.179993,34.955677,0.888481,-376.308838,0.090009,0.000000
66.160004,156.338348,-376.264374,-0.001544,0.003527,0.089585,695.427734,35.426777,0.895854,-376.264374,0.090756,0.000000
66.610001,159.388443,-376.353333,-0.001539,0.003563,0.090504,708.995178,36.117935,0.905044,-376.353333,0.091510,0.000000
67.060005,160.597916,-376.353333,-0.001539,0.003580,0.090921,714.375183,36.392006,0.909207,-376.353333,0.092256,0.000000
67.510002,164.087051,-376.397797,-0.001518,0.003623,0.092030,729.895630,37.182659,0.920305,-376.397797,0.093010,0.000000
67.960007,165.672241,-376.486755,-0.001505,0.003644,0.092559,736.946960,37.541866,0.925588,-376.486755,0.093756,0.000000
68.410004,168.717865,-376.442291,-0.001505,0.003680,0.093470,750.494568,38.232014,0.934703,-376.442291,0.094510,0.000000
68.860001,170.106445,-376.486755,-0.001505,0.003701,0.094008,756.671265,38.546673,0.940077,-376.486755,0.095257,0.000000
69.310005,173.511047,-376.531250,-0.001496,0.003739,0.094971,771.815674,39.318165,0.949706,-376.531250,0.096011,0.000000
69.760002,175.674896,-376.442291,-0.001462,0.003764,0.095594,781.440979,39.808502,0.955943,-376.442291,0.096757,0.000000
70.210007,178.279282,-376.575745,-0.001487,0.003796,0.096410,793.025879,40.398663,0.964104,-376.575745,0.097511,0.000000
70.660004,180.678467,-376.575745,-0.001466,0.003823,0.097095,803.697937,40.942326,0.970947,-376.575745,0.098257,0.000000
71.110001,181.632492,-376.575745,-0.001466,0.003837,0.097450,807.941650,41.158512,0.974504,-376.575745,0.099011,0.000000
71.560005,186.198151,-376.664703,-0.001479,0.003888,0.098751,828.250732,42.193108,0.987509,-376.664703,0.099758,0.000000
72.010002,188.537399,-376.709167,-0.001462,0.003915,0.099437,838.656250,42.723186,0.994368,-376.709167,0.100512,0.000000
72.460007,191.241943,-376.664703,-0.001436,0.003945,0.100191,850.686646,43.336040,1.001907,-376.664703,0.101258,0.000000
72.910004,192.648376,-376.709167,-0.001440,0.003962,0.100625,856.942749,43.654747,1.006252,-376.709167,0.102012,0.000000
73.360001,196.637604,-376.798126,-0.001436,0.004006,0.101752,874.687744,44.558720,1.017516,-376.798126,0.102758,0.000000
73.810005,198.360962,-376.753662,-0.001449,0.004027,0.102298,882.353638,44.949238,1.022981,-376.753662,0.103512,0.000000
74.260002,201.681030,-376.798126,-0.001418,0.004064,0.103217,897.122009,45.701572,1.032171,-376.798126,0.104259,0.000000
74.710007,203.803925,-376.887085,-0.001440,0.004089,0.103851,906.565125,46.182629,1.038515,-376.887085,0.105013,0.000000
75.160004,207.018250,-376.842621,-0.001410,0.004124,0.104752,920.863159,46.911007,1.047523,-376.842621,0.105759,0.000000
75.610001,209.280396,-376.931580,-0.001410,0.004148,0.105352,930.925720,47.423615,1.053518,-376.931580,0.106513,0.000000
76.060005,211.852753,-376.887085,-0.001410,0.004180,0.106166,942.368103,48.006519,1.061663,-376.887085,0.107259,0.000000
76.510002,214.394928,-376.976074,-0.001410,0.004203,0.106755,953.676270,48.582584,1.067552,-376.976074,0.108013,0.000000
76.960007,216.127594,-376.976074,-0.001397,0.004223,0.107276,961.383545,48.975212,1.072760,-376.976074,0.108760,0.000000
77.410004,220.389374,-377.020538,-0.001388,0.004271,0.108481,980.340881,49.940945,1.084811,-377.020538,0.109514,0.000000
77.860001,220.465729,-377.020538,-0.001380,0.004263,0.108274,980.680542,49.958248,1.082737,-377.020538,0.019016,0.000000
78.310005,219.855042,-377.109497,-0.001380,0.004260,0.108195,977.964050,49.819862,1.081950,-377.109497,982.000671,0.000000
78.760002,219.779083,-377.109497,-0.001375,0.004275,0.108586,977.626160,49.802654,1.085856,-377.109497,982.000671,0.000000
79.210007,219.662506,-377.065033,-0.001362,0.004279,0.108699,977.107605,49.776234,1.086992,-377.065033,982.000671,0.000000
79.660004,220.043091,-377.109497,-0.001397,0.004288,0.108907,978.800537,49.862476,1.089066,-377.109497,982.000671,0.000000
80.110001,219.652832,-377.109497,-0.001380,0.004288,0.108916,977.064575,49.774044,1.089157,-377.109497,982.000671,0.000000
80.560005,219.538513,-377.109497,-0.001384,0.004293,0.109046,976.556091,49.748138,1.090459,-377.109497,982.000671,0.000000
81.010002,219.522888,-377.242950,-0.001362,0.004296,0.109115,976.486572,49.744598,1.091155,-377.242950,982.000671,0.000000
81.460007,219.678528,-377.287415,-0.001362,0.004301,0.109237,977.178894,49.779865,1.092366,-377.287415,982.000671,0.000000
81.910004,219.482300,-377.287415,-0.001362,0.004302,0.109279,976.306030,49.735401,1.092790,-377.287415,982.000671,0.000000
82.360001,220.068787,-377.287415,-0.001384,0.004310,0.109479,978.914856,49.868301,1.094788,-377.287415,982.000671,0.000000
82.810005,219.743683,-377.287415,-0.001367,0.004310,0.109479,977.468750,49.794628,1.094788,-377.287415,982.000671,0.000000
83.260002,219.889679,-377.376404,-0.001362,0.004316,0.109635,978.118164,49.827713,1.096348,-377.376404,982.000671,0.000000
83.710007,219.640167,-377.420868,-0.001367,0.004317,0.109653,977.008240,49.771172,1.096529,-377.420868,982.000671,0.000000
84.160004,219.700134,-377.420868,-0.001375,0.004321,0.109765,977.275024,49.784763,1.097650,-377.420868,982.000671,0.000000
84.610001,219.691559,-377.420868,-0.001358,0.004324,0.109826,977.236877,49.782822,1.098255,-377.420868,982.000671,0.000000
85.060005,219.601807,-377.554321,-0.001358,0.004325,0.109860,976.837646,49.762482,1.098604,-377.554321,982.000671,0.000000
85.510002,219.469269,-377.509827,-0.001380,0.004326,0.109886,976.248047,49.732449,1.098861,-377.509827,982.000671,0.000000
85.960007,219.539276,-377.509827,-0.001337,0.004330,0.109981,976.559448,49.748310,1.099815,-377.509827,982.000671,0.000000
86.410004,219.431274,-377.554321,-0.001367,0.004331,0.110016,976.079041,49.723835,1.100163,-377.554321,982.000671,0.000000
86.860001,219.959656,-377.598785,-0.001354,0.004338,0.110190,978.429443,49.843571,1.101904,-377.598785,982.000671,0.000000
87.310005,219.727295,-377.598785,-0.001332,0.004338,0.110190,977.395813,49.790920,1.101904,-377.598785,982.000671,0.000000
87.760002,219.575012,-377.687744,-0.001358,0.004340,0.110225,976.718445,49.756409,1.102252,-377.687744,982.000671,0.000000
88.210007,219.590271,-377.643280,-0.001358,0.004343,0.110302,976.786316,49.759865,1.103024,-377.643280,982.000671,0.000000
88.660004,219.443176,-377.687744,-0.001345,0.004343,0.110302,976.132019,49.726536,1.103024,-377.687744,982.000671,0.000000
89.110001,219.238373,-377.687744,-0.001332,0.004343,0.110312,975.221008,49.680126,1.103115,-377.687744,982.000671,0.000000
89.560005,219.337433,-377.687744,-0.001341,0.004347,0.110416,975.661621,49.702572,1.104160,-377.687744,982.000671,0.000000
90.010002,219.165405,-377.776703,-0.001341,0.004349,0.110467,974.896423,49.663589,1.104675,-377.776703,982.000671,0.000000
90.460007,219.166138,-377.776703,-0.001341,0.004350,0.110486,974.899658,49.663757,1.104856,-377.776703,982.000671,0.000000
90.910004,219.005280,-377.821198,-0.001337,0.004353,0.110554,974.184143,49.627304,1.105538,-377.821198,982.000671,0.000000
91.360001,220.663818,-377.821198,-0.001328,0.004325,0.109844,981.561707,50.003136,1.098437,-377.821198,982.000671,0.000000
91.810005,220.439667,-377.865692,-0.001345,0.004325,0.109844,980.564636,49.952343,1.098437,-377.865692,982.000671,0.000000
92.260002,220.197601,-377.865692,-0.001332,0.004325,0.109844,979.487854,49.897491,1.098437,-377.865692,982.000671,0.000000
92.710007,219.994659,-377.954651,-0.001324,0.004327,0.109895,978.585144,49.851501,1.098952,-377.954651,982.000671,0.000000
93.160004,219.860626,-377.865692,-0.001324,0.004340,0.110225,977.988892,49.821129,1.102252,-377.865692,982.000671,0.000000
93.610008,219.680756,-377.954651,-0.001324,0.004343,0.110312,977.188782,49.780373,1.103115,-377.954651,982.000671,0.000000
94.060005,219.497559,-378.043610,-0.001319,0.004349,0.110458,976.373901,49.738857,1.104584,-378.043610,982.000671,0.000000
94.510002,219.300201,-377.954651,-0.001324,0.004350,0.110493,975.496033,49.694138,1.104932,-377.954651,982.000671,0.000000
94.960007,220.798248,-377.999115,-0.001315,0.004365,0.110867,982.159668,50.033600,1.108671,-377.999115,982.000671,0.000000
95.410004,220.606842,-378.088074,-0.001315,0.004365,0.110867,981.308228,49.990223,1.108671,-378.088074,982.000671,0.000000
95.860008,220.406525,-378.088074,-0.001319,0.004365,0.110867,980.417175,49.944832,1.108671,-378.088074,982.000671,0.000000
96.310005,220.291840,-378.088074,-0.001311,0.004365,0.110867,979.907043,49.918842,1.108671,-378.088074,982.000671,0.000000
96.760002,220.087402,-378.132568,-0.001311,0.004365,0.110867,978.997681,49.872517,1.108671,-378.132568,982.000671,0.000000
97.210007,219.911621,-378.177032,-0.001319,0.004365,0.110867,978.215759,49.832684,1.108671,-378.177032,982.000671,0.000000
97.660004,219.721710,-378.177032,-0.001324,0.004369,0.110979,977.370972,49.789654,1.109792,-378.177032,982.000671,0.000000
98.110008,219.602570,-378.221527,-0.001311,0.004375,0.111128,976.841003,49.762653,1.111275,-378.221527,982.000671,0.000000
98.560005,219.583954,-378.266022,-0.001319,0.004380,0.111240,976.758240,49.758434,1.112396,-378.266022,982.000671,0.000000
99.010002,219.635345,-378.310486,-0.001311,0.004381,0.111265,976.986816,49.770081,1.112653,-378.310486,982.000671,0.000000
99.460007,219.671448,-378.266022,-0.001293,0.004383,0.111326,977.147400,49.778259,1.113259,-378.266022,982.000671,0.000000
99.910004,219.599213,-378.221527,-0.001306,0.004383,0.111326,976.826111,49.761894,1.113259,-378.221527,982.000671,0.000000
100.360008,219.532562,-378.354980,-0.001315,0.004385,0.111370,976.529602,49.746792,1.113698,-378.354980,982.000671,0.000000
100.810005,220.314545,-378.310486,-0.001311,0.004390,0.111517,980.008057,49.923992,1.115166,-378.310486,982.000671,0.000000
101.260002,220.127991,-378.399445,-0.001306,0.004390,0.111517,979.178223,49.881718,1.115166,-378.399445,982.000671,0.000000
101.710007,220.024078,-378.399445,-0.001315,0.004390,0.111517,978.716003,49.858170,1.115166,-378.399445,982.000671,0.000000
102.160004,219.871033,-378.399445,-0.001315,0.004390,0.111517,978.035217,49.823490,1.115166,-378.399445,982.000671,0.000000
102.610008,219.774963,-378.443939,-0.001306,0.004390,0.111517,977.607849,49.801720,1.115166,-378.443939,982.000671,0.000000
103.060005,219.609253,-378.399445,-0.001306,0.004390,0.111517,976.870728,49.764168,1.115166,-378.399445,982.000671,0.000000
103.510002,219.516907,-378.488403,-0.001306,0.004390,0.111517,976.459961,49.743240,1.115166,-378.488403,982.000671,0.000000
103.960007,219.491608,-378.532898,-0.001311,0.004394,0.111612,976.347412,49.737511,1.116120,-378.532898,982.000671,0.000000
104.410004,219.446167,-378.532898,-0.001302,0.004394,0.111612,976.145325,49.727215,1.116120,-378.532898,982.000671,0.000000
104.860008,219.330353,-378.621857,-0.001328,0.004395,0.111621,975.630127,49.700966,1.116211,-378.621857,982.000671,0.000000
105.310005,219.257385,-378.577362,-0.001302,0.004395,0.111621,975.305542,49.684433,1.116211,-378.577362,982.000671,0.000000
105.760002,220.332794,-378.577362,-0.001298,0.004404,0.111872,980.089233,49.928123,1.118724,-378.577362,982.000671,0.000000
106.210007,220.206177,-378.621857,-0.001315,0.004404,0.111872,979.526001,49.899433,1.118724,-378.621857,982.000671,0.000000
106.660004,220.125763,-378.666351,-0.001302,0.004404,0.111872,979.168274,49.881210,1.118724,-378.666351,982.000671,0.000000
107.110008,220.044586,-378.710815,-0.001298,0.004404,0.111872,978.807190,49.862816,1.118724,-378.710815,982.000671,0.000000
107.560005,219.914612,-378.666351,-0.001289,0.004404,0.111872,978.229065,49.833363,1.118724,-378.666351,982.000671,0.000000
108.010002,219.843109,-378.755310,-0.001298,0.004404,0.111872,977.911011,49.817162,1.118724,-378.755310,982.000671,0.000000
108.460007,219.748169,-378.755310,-0.001285,0.004404,0.111872,977.488647,49.795647,1.118724,-378.755310,982.000671,0.000000
108.910004,219.635712,-378.755310,-0.001302,0.004404,0.111872,976.988464,49.770164,1.118724,-378.755310,982.000671,0.000000
109.360008,219.560486,-378.799774,-0.001281,0.004404,0.111872,976.653809,49.753117,1.118724,-378.799774,982.000671,0.000000
109.810005,219.462555,-378.844269,-0.001289,0.004404,0.111872,976.218201,49.730927,1.118724,-378.844269,982.000671,0.000000
110.260002,219.346741,-378.799774,-0.001302,0.004405,0.111881,975.703003,49.704681,1.118815,-378.799774,982.000671,0.000000
110.710007,219.269653,-378.799774,-0.001306,0.004405,0.111881,975.360107,49.687214,1.118815,-378.799774,982.000671,0.000000
111.160004,220.635162,-378.933228,-0.001306,0.004401,0.111786,981.434204,49.996643,1.117861,-378.933228,982.000671,0.000000
111.610008,220.543182,-378.977692,-0.001311,0.004401,0.111786,981.025085,49.975800,1.117861,-378.977692,982.000671,0.000000
112.060005,220.402039,-378.888733,-0.001293,0.004401,0.111786,980.397217,49.943817,1.117861,-378.888733,982.000671,0.000000
112.510002,220.389008,-379.022186,-0.001293,0.004401,0.111786,980.339294,49.940861,1.117861,-379.022186,982.000671,0.000000
112.960007,220.309692,-378.977692,-0.001293,0.004401,0.111786,979.986450,49.922890,1.117861,-378.977692,982.000671,0.000000
113.410004,220.148834,-379.022186,-0.001289,0.004401,0.111786,979.270935,49.886436,1.117861,-379.022186,982.000671,0.000000
113.860008,220.077698,-379.066650,-0.001289,0.004401,0.111786,978.954468,49.870319,1.117861,-379.066650,982.000671,0.000000
114.310005,219.967865,-378.977692,-0.001298,0.004401,0.111786,978.465942,49.845428,1.117861,-378.977692,982.000671,0.000000
114.760002,219.869171,-379.022186,-0.001289,0.004401,0.111786,978.026917,49.823067,1.117861,-379.022186,982.000671,0.000000
115.210007,219.797302,-379.111145,-0.001293,0.004401,0.111786,977.707214,49.806782,1.117861,-379.111145,982.000671,0.000000
115.660004,219.691559,-379.155640,-0.001289,0.004401,0.111786,977.236877,49.782822,1.117861,-379.155640,982.000671,0.000000
116.110008,219.601440,-379.155640,-0.001285,0.004401,0.111786,976.835999,49.762398,1.117861,-379.155640,982.000671,0.000000
116.560005,219.874023,-379.155640,-0.001306,0.004422,0.112324,978.048523,49.824165,1.123236,-379.155640,982.000671,0.000000
117.010002,220.017761,-379.244598,-0.001281,0.004422,0.112324,978.687866,49.856735,1.123236,-379.244598,982.000671,0.000000
117.460007,219.970459,-379.244598,-0.001293,0.004422,0.112324,978.477478,49.846020,1.123236,-379.244598,982.000671,0.000000
117.910004,219.897491,-379.244598,-0.001293,0.004422,0.112324,978.152893,49.829483,1.123236,-379.244598,982.000671,0.000000
118.360008,219.843109,-379.289062,-0.001276,0.004422,0.112324,977.911011,49.817162,1.123236,-379.289062,982.000671,0.000000
118.810005,219.798065,-379.244598,-0.001293,0.004422,0.112324,977.710632,49.806953,1.123236,-379.244598,982.000671,0.000000
119.260002,219.717621,-379.244598,-0.001293,0.004422,0.112324,977.352783,49.788723,1.123236,-379.244598,982.000671,0.000000
119.710007,219.664368,-379.333557,-0.001298,0.004423,0.112333,977.115906,49.776657,1.123327,-379.333557,982.000671,0.000000
120.160004,219.599945,-379.422516,-0.001289,0.004423,0.112340,976.829346,49.762058,1.123402,-379.422516,982.000671,0.000000
120.610008,219.554169,-379.422516,-0.001289,0.004423,0.112340,976.625732,49.751686,1.123402,-379.422516,982.000671,0.000000
121.060005,219.491211,-379.422516,-0.001293,0.004423,0.112340,976.345642,49.737419,1.123402,-379.422516,982.000671,0.000000
121.510002,219.914612,-379.466980,-0.001276,0.004430,0.112523,978.229065,49.833363,1.125234,-379.466980,982.000671,0.000000
121.960007,219.965271,-379.511475,-0.001276,0.004430,0.112523,978.454407,49.844841,1.125234,-379.511475,982.000671,0.000000
122.410004,219.933594,-379.422516,-0.001285,0.004430,0.112523,978.313477,49.837662,1.125234,-379.422516,982.000671,0.000000
122.860008,219.884827,-379.511475,-0.001293,0.004430,0.112523,978.096558,49.826614,1.125234,-379.511475,982.000671,0.000000
123.310005,219.855408,-379.511475,-0.001289,0.004430,0.112523,977.965698,49.819946,1.125234,-379.511475,982.000671,0.000000
123.760002,219.815948,-379.555969,-0.001285,0.004430,0.112523,977.790161,49.811005,1.125234,-379.555969,982.000671,0.000000
124.210007,219.769379,-379.555969,-0.001285,0.004430,0.112523,977.583008,49.800453,1.125234,-379.555969,982.000671,0.000000
124.660004,219.699768,-379.555969,-0.001281,0.004430,0.112523,977.273376,49.784676,1.125234,-379.555969,982.000671,0.000000
125.110008,219.729553,-379.644928,-0.001285,0.004432,0.112566,977.405884,49.791428,1.125658,-379.644928,982.000671,0.000000
125.560005,219.711670,-379.689392,-0.001285,0.004432,0.112575,977.326294,49.787376,1.125749,-379.689392,982.000671,0.000000
126.010010,219.682983,-379.689392,-0.001281,0.004433,0.112593,977.198730,49.780876,1.125931,-379.689392,982.000671,0.000000
126.460007,219.747040,-379.733887,-0.001281,0.004433,0.112610,977.483643,49.795391,1.126097,-379.733887,982.000671,0.000000
126.910004,219.739960,-379.778351,-0.001272,0.004434,0.112626,977.452148,49.793785,1.126264,-379.778351,982.000671,0.000000
127.360008,219.723572,-379.778351,-0.001293,0.004434,0.112635,977.379272,49.790073,1.126354,-379.778351,982.000671,0.000000
127.810005,219.724701,-379.778351,-0.001276,0.004435,0.112654,977.384277,49.790329,1.126536,-379.778351,982.000671,0.000000
128.260010,219.751129,-379.867310,-0.001293,0.004436,0.112670,977.501831,49.796318,1.126703,-379.867310,982.000671,0.000000
128.710007,219.737366,-379.778351,-0.001276,0.004436,0.112670,977.440613,49.793198,1.126703,-379.778351,982.000671,0.000000
129.160004,219.721710,-379.867310,-0.001285,0.004436,0.112679,977.370972,49.789654,1.126794,-379.867310,982.000671,0.000000
129.610001,219.732147,-379.911804,-0.001276,0.004438,0.112714,977.417419,49.792015,1.127142,-379.911804,982.000671,0.000000
130.060013,219.754486,-379.911804,-0.001276,0.004438,0.112714,977.516785,49.797077,1.127142,-379.911804,982.000671,0.000000
130.510010,219.732910,-379.956299,-0.001272,0.004438,0.112714,977.420776,49.792187,1.127142,-379.956299,982.000671,0.000000
130.960007,219.738495,-379.956299,-0.001276,0.004439,0.112740,977.445618,49.793453,1.127399,-379.956299,982.000671,0.000000
131.410004,219.753387,-380.000763,-0.001293,0.004439,0.112749,977.511902,49.796829,1.127490,-380.000763,982.000671,0.000000
131.860001,219.730286,-380.000763,-0.001281,0.004440,0.112766,977.409119,49.791595,1.127656,-380.000763,982.000671,0.000000
132.310013,219.736237,-380.089722,-0.001268,0.004440,0.112775,977.435608,49.792946,1.127747,-380.089722,982.000671,0.000000
132.760010,219.730286,-380.089722,-0.001285,0.004440,0.112784,977.409119,49.791595,1.127838,-380.089722,982.000671,0.000000
133.210007,219.712036,-380.134216,-0.001272,0.004441,0.112800,977.327942,49.787460,1.128005,-380.134216,982.000671,0.000000
133.660004,219.739227,-380.134216,-0.001268,0.004441,0.112810,977.448914,49.793621,1.128096,-380.134216,982.000671,0.000000
134.110001,219.738861,-380.178680,-0.001276,0.004442,0.112819,977.447266,49.793537,1.128186,-380.178680,982.000671,0.000000
134.560013,219.700867,-380.223175,-0.001276,0.004442,0.112826,977.278259,49.784927,1.128262,-380.223175,982.000671,0.000000
135.010010,219.704590,-380.267639,-0.001272,0.004443,0.112844,977.294800,49.785770,1.128444,-380.267639,982.000671,0.000000
135.460007,219.751129,-380.223175,-0.001276,0.004443,0.112844,977.501831,49.796318,1.128444,-380.223175,982.000671,0.000000
135.910004,219.735138,-380.267639,-0.001259,0.004443,0.112844,977.430725,49.792694,1.128444,-380.267639,982.000671,0.000000
136.360001,219.733643,-380.267639,-0.001272,0.004444,0.112879,977.424072,49.792355,1.128792,-380.267639,982.000671,0.000000
136.810013,219.752258,-380.267639,-0.001276,0.004444,0.112879,977.506836,49.796574,1.128792,-380.267639,982.000671,0.000000
137.260010,219.722839,-380.312134,-0.001285,0.004444,0.112887,977.375977,49.789909,1.128868,-380.312134,982.000671,0.000000
137.710007,219.720612,-380.356598,-0.001276,0.004445,0.112896,977.366089,49.789402,1.128958,-380.356598,982.000671,0.000000
138.160004,219.708679,-380.356598,-0.001272,0.004445,0.112905,977.312988,49.786697,1.129049,-380.356598,5607.367676,0.000000
138.610001,219.626404,-380.401093,-0.001276,0.004430,0.112523,976.947021,49.768055,1.125234,-380.401093,0.112480,0.000000
139.060013,219.496063,-380.445587,-0.001272,0.004415,0.112133,976.367249,49.738522,1.121328,-380.445587,0.111726,0.000000
139.510010,219.097260,-380.356598,-0.001276,0.004390,0.111500,974.593262,49.648148,1.115000,-380.356598,0.110979,0.000000
139.960007,217.753723,-380.445587,-0.001259,0.004359,0.110728,968.616943,49.343697,1.107279,-380.445587,0.110225,0.000000
140.410004,216.909576,-380.534546,-0.001272,0.004327,0.109904,964.862000,49.152412,1.099043,-380.534546,0.109479,0.000000
140.860001,216.412811,-380.534546,-0.001250,0.004303,0.109288,962.652283,49.039841,1.092881,-380.534546,0.108725,0.000000
141.310013,216.171143,-380.534546,-0.001242,0.004275,0.108586,961.577271,48.985081,1.085856,-380.534546,0.107979,0.000000
141.760010,215.690033,-380.623505,-0.001233,0.004242,0.107745,959.437195,48.876060,1.077454,-380.623505,0.107225,0.000000
142.210007,215.493439,-380.667969,-0.001242,0.004215,0.107069,958.562683,48.831509,1.070686,-380.667969,0.106478,0.000000
142.660004,214.558411,-380.623505,-0.001242,0.004189,0.106392,954.403503,48.619633,1.063919,-380.623505,0.105724,0.000000
143.110001,214.232208,-380.623505,-0.001229,0.004163,0.105741,952.952454,48.545712,1.057409,-380.623505,0.104978,0.000000
143.560013,212.528595,-380.712463,-0.001237,0.004131,0.104926,945.374390,48.159668,1.049264,-380.712463,0.104224,0.000000
144.010010,210.966125,-380.667969,-0.001220,0.004104,0.104233,938.424194,47.805607,1.042330,-380.667969,0.103478,0.000000
144.460007,208.485016,-380.712463,-0.001242,0.004070,0.103365,927.387695,47.243378,1.033655,-380.712463,0.102724,0.000000
144.910004,206.369202,-380.756927,-0.001224,0.004045,0.102749,917.976074,46.763931,1.027493,-380.756927,0.101977,0.000000
145.360001,203.223022,-380.801422,-0.001220,0.004015,0.101970,903.981140,46.050995,1.019696,-380.801422,0.101223,0.000000
145.810013,199.814331,-380.756927,-0.001246,0.003984,0.101188,888.818542,45.278572,1.011884,-380.756927,0.100477,0.000000
146.260010,196.640228,-380.801422,-0.001224,0.003954,0.100425,874.699402,44.559311,1.004254,-380.801422,0.099723,0.000000
146.710007,194.159851,-380.845917,-0.001237,0.003934,0.099914,863.666138,43.997253,0.999137,-380.845917,0.098977,0.000000
147.160004,190.789871,-380.845917,-0.001233,0.003902,0.099107,848.675720,43.233604,0.991067,-380.845917,0.098223,0.000000
147.610001,187.861542,-380.890381,-0.001229,0.003877,0.098474,835.649902,42.570034,0.984739,-380.890381,0.097476,0.000000
148.060013,184.988312,-380.934875,-0.001237,0.003849,0.097771,822.869080,41.918953,0.977714,-380.934875,0.096722,0.000000
148.510010,181.118622,-380.890381,-0.001233,0.003812,0.096827,805.655884,41.042068,0.968267,-380.890381,0.095976,0.000000
148.960007,178.059570,-380.934875,-0.001233,0.003785,0.096141,792.048523,40.348873,0.961409,-380.934875,0.095222,0.000000
149.410004,175.107773,-380.979340,-0.001220,0.003760,0.095491,778.918274,39.679989,0.954914,-380.979340,0.094476,0.000000
149.860001,171.018005,-380.979340,-0.001216,0.003723,0.094571,760.726074,38.753235,0.945709,-380.979340,0.093722,0.000000
150.310013,166.882446,-381.023834,-0.001237,0.003689,0.093705,742.330200,37.816101,0.937049,-381.023834,0.092975,0.000000
150.760010,164.826569,-381.023834,-0.001233,0.003673,0.093289,733.185181,37.350231,0.932886,-381.023834,0.092221,0.000000
151.210007,160.720047,-381.068298,-0.001233,0.003637,0.092377,714.918457,36.419685,0.923772,-381.068298,0.091475,0.000000
151.660004,156.180466,-381.112793,-0.001224,0.003602,0.091502,694.725403,35.390999,0.915021,-381.112793,0.090721,0.000000
152.110001,152.916611,-381.112793,-0.001229,0.003572,0.090739,680.207031,34.651398,0.907391,-381.112793,0.089975,0.000000
152.560013,149.530640,-381.157257,-0.001220,0.003547,0.090088,665.145508,33.884129,0.900881,-381.157257,0.089221,0.000000
153.010010,145.674713,-381.157257,-0.001229,0.003513,0.089221,647.993469,33.010365,0.892206,-381.157257,0.088474,0.000000
153.460007,142.232880,-381.246246,-0.001224,0.003484,0.088492,632.683472,32.230431,0.884924,-381.246246,0.087720,0.000000
153.910004,139.419968,-381.201752,-0.001229,0.003461,0.087902,620.170959,31.593018,0.879019,-381.201752,0.086974,0.000000
154.360001,135.591248,-381.246246,-0.001224,0.003429,0.087087,603.140015,30.725416,0.870874,-381.246246,0.086220,0.000000
154.810013,133.066559,-381.290710,-0.001224,0.003404,0.086471,591.909607,30.153313,0.864712,-381.290710,0.085474,0.000000
155.260010,129.060577,-381.290710,-0.001229,0.003372,0.085639,574.090149,29.245544,0.856385,-381.290710,0.084720,0.000000
155.710007,125.365524,-381.290710,-0.001224,0.003338,0.084789,557.653687,28.408234,0.847892,-381.290710,0.083975,0.000000
156.160004,121.626526,-381.335205,-0.001237,0.003307,0.084008,541.021790,27.560965,0.840080,-381.335205,0.083219,0.000000
156.610001,118.953262,-381.379669,-0.001224,0.003282,0.083359,529.130554,26.955194,0.833585,-381.379669,0.082474,0.000000
157.060013,114.943192,-381.379669,-0.001224,0.003247,0.082465,511.292847,26.046499,0.824653,-381.379669,0.081719,0.000000
157.510010,111.794403,-381.379669,-0.001229,0.003220,0.081798,497.286346,25.332973,0.817976,-381.379669,0.080974,0.000000
157.960007,107.818588,-381.379669,-0.001242,0.003184,0.080886,479.601044,24.432041,0.808862,-381.379669,0.080228,0.000000
158.410004,105.672974,-381.424164,-0.001220,0.003168,0.080470,470.056854,23.945837,0.804699,-381.424164,0.079474,0.000000
158.860001,102.892838,-381.513123,-0.001220,0.003145,0.079881,457.690186,23.315849,0.798810,-381.513123,0.078727,0.000000
159.310013,98.039719,-381.513123,-0.001229,0.003100,0.078744,436.102448,22.216118,0.787440,-381.513123,0.077973,0.000000
159.760010,95.322510,-381.557587,-0.001237,0.003077,0.078164,424.015686,21.600389,0.781641,-381.557587,0.077227,0.000000
160.210007,91.965942,-381.602081,-0.001233,0.003047,0.077401,409.084930,20.839781,0.774011,-381.602081,0.076473,0.000000
160.660004,88.961639,-381.646545,-0.001224,0.003022,0.076767,395.721130,20.158995,0.767668,-381.646545,0.075727,0.000000
161.110001,85.575287,-381.602081,-0.001224,0.002992,0.075996,380.657898,19.391638,0.759961,-381.602081,0.074973,0.000000
161.560013,81.920074,-381.646545,-0.001220,0.002959,0.075163,364.398682,18.563354,0.751635,-381.646545,0.074226,0.000000
162.010010,78.608200,-381.646545,-0.001233,0.002929,0.074391,349.666748,17.812872,0.743914,-381.646545,0.073472,0.000000
162.460007,75.584915,-381.691040,-0.001237,0.002902,0.073706,336.218506,17.127787,0.737055,-381.691040,0.072726,0.000000
162.910004,72.610764,-381.691040,-0.001233,0.002874,0.072995,322.988800,16.453835,0.729955,-381.691040,0.071972,0.000000
163.360001,68.575363,-381.735535,-0.001229,0.002837,0.072067,305.038452,15.539400,0.720674,-381.735535,0.071226,0.000000
163.810013,66.363480,-381.691040,-0.001224,0.002819,0.071591,295.199493,15.038179,0.715905,-381.691040,0.070472,0.000000
164.260010,63.200180,-381.824493,-0.001229,0.002787,0.070793,281.128448,14.321365,0.707927,-381.824493,0.069725,0.000000
164.710007,59.241478,-381.824493,-0.001233,0.002753,0.069934,263.519257,13.424312,0.699343,-381.824493,0.068971,0.000000
165.160004,55.851402,-381.824493,-0.001233,0.002721,0.069102,248.439438,12.656109,0.691016,-381.824493,0.068225,0.000000
165.610001,52.992699,-381.868958,-0.001233,0.002697,0.068502,235.723297,12.008318,0.685021,-381.868958,0.067471,0.000000
166.060013,49.526657,-381.913452,-0.001229,0.002667,0.067748,220.305573,11.222900,0.677481,-381.913452,0.066725,0.000000
166.510010,46.187592,-381.868958,-0.001233,0.002632,0.066855,205.452667,10.466257,0.668549,-381.868958,0.065971,0.000000
166.960007,42.782249,-381.868958,-0.001229,0.002601,0.066057,190.304947,9.694596,0.660570,-381.868958,0.065224,0.000000
167.410004,39.745918,-381.913452,-0.001233,0.002575,0.065415,176.798676,9.006555,0.654151,-381.913452,0.064470,0.000000
167.860001,36.582619,-382.002411,-0.001233,0.002548,0.064722,162.727615,8.289740,0.647217,-382.002411,0.063724,0.000000
168.310013,33.844559,-382.046875,-0.001246,0.002524,0.064106,150.548111,7.669287,0.641055,-382.046875,0.062970,0.000000
168.760010,30.105202,-382.002411,-0.001207,0.002489,0.063230,133.914627,6.821936,0.632305,-382.002411,0.062224,0.000000
169.210007,26.881943,-382.046875,-0.001233,0.002459,0.062458,119.576851,6.091535,0.624583,-382.046875,0.061470,0.000000
169.660004,24.208679,-382.046875,-0.001220,0.002434,0.061833,107.685585,5.485765,0.618331,-382.046875,0.060723,0.000000
170.110001,20.960106,-382.091370,-0.001220,0.002405,0.061079,93.235207,4.749628,0.610791,-382.091370,0.059969,0.000000
170.560013,17.732376,-382.091370,-0.001224,0.002373,0.060265,78.877548,4.018214,0.602646,-382.091370,0.059223,0.000000
171.010010,14.297241,-382.135864,-0.001229,0.002342,0.059483,63.597305,3.239801,0.594834,-382.135864,0.058469,0.000000
171.460007,11.437050,-382.135864,-0.001229,0.002315,0.058790,50.874538,2.591672,0.587900,-382.135864,0.057723,0.000000
171.910004,8.339279,-382.224823,-0.001229,0.002285,0.058035,37.094967,1.889708,0.580346,-382.224823,0.056969,0.000000
172.360001,5.905457,-382.224823,-0.001224,0.002258,0.057359,26.268784,1.338196,0.573593,-382.224823,0.056222,0.000000
172.810013,2.738060,-382.224823,-0.001224,0.002227,0.056569,12.179500,0.620453,0.565690,-382.224823,0.055468,0.000000
173.260010,-0.102028,-382.224823,-0.001220,0.002194,0.055720,-0.453843,-0.023120,0.557197,-382.224823,0.054722,0.000000
173.710007,-0.080429,-382.269287,-0.001242,0.002160,0.054861,-0.357766,-0.018225,0.548613,-382.269287,0.053968,0.000000
174.160004,0.086761,-382.313782,-0.001229,0.002138,0.054315,0.385934,0.019660,0.543148,-382.313782,0.053222,0.000000
174.610016,0.076714,-382.358246,-0.001220,0.002103,0.053412,0.341239,0.017384,0.534124,-382.358246,0.052468,0.000000
175.060013,0.029045,-382.313782,-0.001207,0.002076,0.052737,0.129199,0.006582,0.527372,-382.313782,0.051721,0.000000
175.510010,0.016762,-382.358246,-0.001212,0.002040,0.051817,0.074560,0.003798,0.518167,-382.358246,0.050967,0.000000
175.960007,0.023460,-382.402740,-0.001203,0.002023,0.051393,0.104357,0.005316,0.513928,-382.402740,0.050221,0.000000
176.410004,-0.028671,-382.402740,-0.001224,0.001997,0.050725,-0.127536,-0.006497,0.507252,-382.402740,0.049467,0.000000
176.860016,-0.048035,-382.491699,-0.001199,0.001951,0.049562,-0.213669,-0.010885,0.495624,-382.491699,0.048721,0.000000
177.310013,-0.068886,-382.491699,-0.001224,0.001916,0.048678,-0.306419,-0.015610,0.486783,-382.491699,0.047967,0.000000
177.760010,-0.036118,-382.536194,-0.001190,0.001902,0.048313,-0.160659,-0.008184,0.483134,-382.536194,0.047220,0.000000
178.210007,-0.096443,-382.491699,-0.001207,0.001872,0.047541,-0.429001,-0.021854,0.475413,-382.491699,0.046475,0.000000
178.660004,-0.085274,-382.536194,-0.001190,0.001840,0.046727,-0.379317,-0.019323,0.467268,-382.536194,0.045720,0.000000
179.110016,-0.094208,-382.536194,-0.001207,0.001809,0.045946,-0.419057,-0.021348,0.459456,-382.536194,0.044975,0.000000
179.560013,-0.082664,-382.580658,-0.001194,0.001777,0.045148,-0.367710,-0.018732,0.451477,-382.580658,0.044220,0.000000
180.010010,-0.124001,-382.625153,-0.001190,0.001754,0.044541,-0.551582,-0.028099,0.445406,-382.625153,0.043475,0.000000
180.460007,-0.125862,-382.625153,-0.001212,0.001720,0.043691,-0.559863,-0.028521,0.436913,-382.625153,0.042719,0.000000
180.910004,-0.112457,-382.714111,-0.001203,0.001690,0.042928,-0.500235,-0.025483,0.429283,-382.714111,0.041974,0.000000
181.360016,-0.074844,-382.714111,-0.001224,0.001659,0.042147,-0.332924,-0.016960,0.421471,-382.714111,0.041219,0.000000
181.810013,-0.096443,-382.758575,-0.001242,0.001635,0.041540,-0.429001,-0.021854,0.415400,-382.758575,0.040474,0.000000
182.260010,-0.104263,-382.803070,-0.001233,0.001607,0.040812,-0.463786,-0.023626,0.408118,-382.803070,0.039719,0.000000
182.710007,-0.118042,-382.714111,-0.001276,0.001574,0.039988,-0.525077,-0.026749,0.399882,-382.714111,0.038974,0.000000
183.160004,-0.054733,-382.803070,-0.001281,0.001550,0.039372,-0.243466,-0.012403,0.393720,-382.803070,0.038220,0.000000
183.400009,-0.068886,-382.803070,-0.001285,0.001536,0.039025,-0.306419,-0.015610,0.390253,-382.803070,0.038956,0.000000