File: Data/sima compression 500bar/P1-17-500bar-2_11072024_165932.csv
Time (sec),S:Load (lbs),S:HL1 (DIM),S:LVDT (in),S:Position (in),Ch:Position (mm),Ch:Load (N),Ch:Stress (MPa),Ch:Strain (mm/mm),Ch:HL1 (DIM),Set Point (),Cycles ()
0.110000,-0.090858,-358.961273,-0.009783,-0.006660,-0.169162,-0.404159,-0.020589,-1.691621,-358.961273,-0.168970,0.000000
0.540000,-0.076706,-358.916809,-0.009787,-0.006598,-0.167600,-0.341205,-0.017382,-1.675997,-358.916809,-0.167062,0.000000
0.970000,-0.047661,-359.005768,-0.009615,-0.006341,-0.161053,-0.212006,-0.010800,-1.610533,-359.005768,-0.159900,0.000000
1.400000,-0.111710,-359.005768,-0.009317,-0.006054,-0.153759,-0.496909,-0.025314,-1.537591,-359.005768,-0.152736,0.000000
1.830000,-0.132561,-359.050232,-0.009046,-0.005775,-0.146692,-0.589660,-0.030039,-1.466919,-359.050232,-0.145573,0.000000
2.260000,-0.096069,-359.005768,-0.008739,-0.005488,-0.139398,-0.427338,-0.021770,-1.393977,-359.005768,-0.138409,0.000000
2.690000,-0.060326,-359.094727,-0.008472,-0.005221,-0.132617,-0.268342,-0.013670,-1.326167,-359.094727,-0.131247,0.000000
3.120000,-0.046547,-359.183685,-0.008162,-0.004925,-0.125089,-0.207051,-0.010548,-1.250893,-359.183685,-0.124082,0.000000
3.550000,-0.122879,-359.139191,-0.007864,-0.004646,-0.118021,-0.546593,-0.027845,-1.180206,-359.139191,-0.116920,0.000000
3.980000,-0.110962,-359.139191,-0.007593,-0.004362,-0.110798,-0.493583,-0.025144,-1.107975,-359.139191,-0.109756,0.000000
4.410000,-0.055107,-359.183685,-0.007291,-0.004080,-0.103643,-0.245129,-0.012487,-1.036425,-359.183685,-0.102593,0.000000
4.840000,-0.065163,-359.183685,-0.007006,-0.003806,-0.096678,-0.289858,-0.014766,-0.966783,-359.183685,-0.095429,0.000000
5.270000,-0.093460,-359.272644,-0.006691,-0.003516,-0.089299,-0.415731,-0.021178,-0.892993,-359.272644,-0.088267,0.000000
5.700000,-0.099052,-359.317108,-0.006411,-0.003237,-0.082222,-0.440607,-0.022446,-0.822215,-359.317108,-0.081103,0.000000
6.130000,-0.081551,-359.272644,-0.006109,-0.002953,-0.074998,-0.362755,-0.018480,-0.749985,-359.272644,-0.073940,0.000000
6.560000,-0.074471,-359.228149,-0.005825,-0.002679,-0.068051,-0.331261,-0.016875,-0.680509,-359.228149,-0.066776,0.000000
6.990000,-0.048035,-359.317108,-0.005545,-0.002390,-0.060707,-0.213669,-0.010885,-0.607067,-359.317108,-0.059614,0.000000
7.420001,-0.089371,-359.317108,-0.005251,-0.002109,-0.053568,-0.397541,-0.020252,-0.535684,-359.317108,-0.052450,0.000000
7.850000,-0.094208,-359.450562,-0.004963,-0.001827,-0.046406,-0.419057,-0.021348,-0.464058,-359.450562,-0.045287,0.000000
8.280001,-0.063675,-359.406097,-0.004669,-0.001546,-0.039260,-0.283240,-0.014429,-0.392600,-359.406097,-0.038123,0.000000
8.710000,-0.094955,-359.450562,-0.004376,-0.001277,-0.032426,-0.422383,-0.021517,-0.324260,-359.450562,-0.030960,0.000000
9.140000,-0.054733,-359.495056,-0.004087,-0.000981,-0.024915,-0.243466,-0.012403,-0.249152,-359.495056,-0.023796,0.000000
9.570001,-0.072609,-359.495056,-0.003807,-0.000698,-0.017735,-0.322981,-0.016453,-0.177345,-359.495056,-0.016634,0.000000
10.000000,-0.063675,-359.495056,-0.003514,-0.000417,-0.010581,-0.283240,-0.014429,-0.105811,-359.495056,-0.009470,0.000000
10.430000,-0.022339,-359.450562,-0.003247,-0.000139,-0.003538,-0.099368,-0.005062,-0.035381,-359.450562,-0.002307,0.000000
10.860001,0.172035,-359.539520,-0.003065,-0.000000,-0.000009,0.765251,0.038984,-0.000091,-359.539520,0.000174,0.000000
11.290001,0.143738,-359.628479,-0.003065,-0.000001,-0.000017,0.639378,0.032571,-0.000167,-359.628479,0.000365,0.000000
11.720000,0.218208,-359.672974,-0.003087,0.000012,0.000312,0.970639,0.049447,0.003119,-359.672974,0.001075,0.000000
12.150001,0.503075,-359.628479,-0.003057,0.000040,0.001005,2.237788,0.113998,0.010053,-359.628479,0.001796,0.000000
12.580001,0.984924,-359.628479,-0.003035,0.000066,0.001665,4.381162,0.223187,0.016654,-359.628479,0.002515,0.000000
13.010000,1.850319,-359.628479,-0.003014,0.000097,0.002454,8.230630,0.419288,0.024541,-359.628479,0.003226,0.000000
13.440001,2.377602,-359.717438,-0.002988,0.000113,0.002870,10.576100,0.538772,0.028705,-359.717438,0.003945,0.000000
13.870001,3.779213,-359.806427,-0.002953,0.000154,0.003911,16.810780,0.856382,0.039106,-359.806427,0.004666,0.000000
14.300001,4.546669,-359.717438,-0.002953,0.000174,0.004431,20.224594,1.030290,0.044314,-359.717438,0.005376,0.000000
14.730000,6.014191,-359.761932,-0.002928,0.000209,0.005308,26.752457,1.362835,0.053079,-359.761932,0.006097,0.000000
15.160001,7.164818,-359.717438,-0.002910,0.000235,0.005957,31.870701,1.623571,0.059574,-359.717438,0.006816,0.000000
15.590001,8.538132,-359.850891,-0.002880,0.000262,0.006652,37.979507,1.934768,0.066523,-359.850891,0.007527,0.000000
16.020000,10.115128,-359.850891,-0.002884,0.000294,0.007467,44.994335,2.292121,0.074668,-359.850891,0.008247,0.000000
16.450001,10.957062,-359.895386,-0.002867,0.000313,0.007944,48.739445,2.482906,0.079437,-359.895386,0.008967,0.000000
16.880001,12.769402,-359.850891,-0.002833,0.000347,0.008820,56.801136,2.893588,0.088203,-359.850891,0.009679,0.000000
17.310001,13.684319,-359.939850,-0.002824,0.000366,0.009288,60.870888,3.100911,0.092881,-359.939850,0.010398,0.000000
17.740002,15.616188,-359.939850,-0.002811,0.000400,0.010172,69.464272,3.538679,0.101723,-359.939850,0.011109,0.000000
18.170000,17.077377,-359.939850,-0.002802,0.000431,0.010944,75.963966,3.869789,0.109444,-359.939850,0.011829,0.000000
18.600000,18.759750,-359.984344,-0.002790,0.000460,0.011691,83.447540,4.251020,0.116908,-359.984344,0.012549,0.000000
19.030001,19.803139,-359.984344,-0.002751,0.000484,0.012298,88.088760,4.487455,0.122979,-359.984344,0.013259,0.000000
19.460001,21.684364,-360.028809,-0.002738,0.000517,0.013138,96.456871,4.913747,0.131381,-360.028809,0.013980,0.000000
19.890001,22.900162,-360.117767,-0.002729,0.000544,0.013806,101.865005,5.189251,0.138058,-360.117767,0.014699,0.000000
20.320002,24.061966,-360.117767,-0.002708,0.000567,0.014405,107.032967,5.452519,0.144053,-360.117767,0.015411,0.000000
20.750002,25.930527,-360.073303,-0.002686,0.000603,0.015306,115.344742,5.875941,0.153061,-360.073303,0.016130,0.000000
21.180000,26.518509,-360.117767,-0.002652,0.000619,0.015732,117.960220,6.009180,0.157315,-360.117767,0.016850,0.000000
21.610001,28.577354,-360.117767,-0.002652,0.000660,0.016755,127.118423,6.475721,0.167550,-360.117767,0.017562,0.000000
22.040001,29.577171,-360.162262,-0.002639,0.000686,0.017414,131.565826,6.702283,0.174135,-360.162262,0.018281,0.000000
22.470001,30.832443,-360.251221,-0.002626,0.000713,0.018107,137.149551,6.986732,0.181069,-360.251221,0.019000,0.000000
22.900002,31.979721,-360.162262,-0.002604,0.000742,0.018853,142.252899,7.246708,0.188533,-360.162262,0.019712,0.000000
23.330002,33.328827,-360.251221,-0.002591,0.000770,0.019565,148.254028,7.552420,0.195649,-360.251221,0.020432,0.000000
23.760000,34.527122,-360.295715,-0.002548,0.000801,0.020337,153.584305,7.823958,0.203370,-360.295715,0.021142,0.000000
24.190001,35.316177,-360.340179,-0.002552,0.000826,0.020986,157.094208,8.002760,0.209865,-360.340179,0.021863,0.000000
24.620001,36.412445,-360.340179,-0.002522,0.000855,0.021715,161.970642,8.251179,0.217147,-360.340179,0.022582,0.000000
25.050001,37.003769,-360.340179,-0.002505,0.000878,0.022305,164.600983,8.385174,0.223051,-360.340179,0.023294,0.000000
25.480001,38.527893,-360.340179,-0.002488,0.000913,0.023180,171.380630,8.730546,0.231802,-360.340179,0.024013,0.000000
25.910002,38.896538,-360.429138,-0.002462,0.000935,0.023745,173.020447,8.814082,0.237449,-360.429138,0.024734,0.000000
26.340002,39.963387,-360.429138,-0.002423,0.000965,0.024517,177.766022,9.055833,0.245170,-360.429138,0.025445,0.000000
26.770000,40.987038,-360.473633,-0.002427,0.000995,0.025271,182.319443,9.287795,0.252710,-360.473633,0.026164,0.000000
27.200001,40.696960,-360.473633,-0.002402,0.001010,0.025662,181.029114,9.222063,0.256616,-360.473633,0.026883,0.000000
27.630001,42.754318,-360.518097,-0.002358,0.001054,0.026771,190.180710,9.688267,0.267713,-360.518097,0.027595,0.000000
28.060001,43.272285,-360.562592,-0.002345,0.001079,0.027413,192.484741,9.805639,0.274132,-360.562592,0.028316,0.000000
28.490002,43.912766,-360.607056,-0.002328,0.001107,0.028107,195.333740,9.950775,0.281066,-360.607056,0.029035,0.000000
28.920002,44.178642,-360.651550,-0.002311,0.001128,0.028653,196.516418,10.011024,0.286532,-360.651550,0.029746,0.000000
29.350002,45.775002,-360.607056,-0.002285,0.001169,0.029686,203.617371,10.372764,0.296857,-360.607056,0.030465,0.000000
29.780001,45.722870,-360.651550,-0.002259,0.001191,0.030240,203.385483,10.360950,0.302398,-360.651550,0.031186,0.000000
30.210001,46.724556,-360.696045,-0.002255,0.001223,0.031063,207.841202,10.587935,0.310634,-360.696045,0.031896,0.000000
30.640001,46.893608,-360.740509,-0.002233,0.001243,0.031584,208.593185,10.626244,0.315842,-360.740509,0.032617,0.000000
31.070002,48.029350,-360.696045,-0.002207,0.001280,0.032503,213.645218,10.883607,0.325032,-360.696045,0.033327,0.000000
31.500002,48.613968,-360.740509,-0.002195,0.001305,0.033136,216.245728,11.016083,0.331360,-360.740509,0.034047,0.000000
31.930002,49.278282,-360.740509,-0.002151,0.001334,0.033873,219.200745,11.166618,0.338733,-360.740509,0.034767,0.000000
32.360001,50.200653,-360.829468,-0.002139,0.001363,0.034629,223.303650,11.375630,0.346288,-360.829468,0.035478,0.000000
32.790001,50.417374,-360.873962,-0.002139,0.001383,0.035140,224.267685,11.424740,0.351405,-360.873962,0.036197,0.000000
33.220001,51.872978,-360.829468,-0.002117,0.001420,0.036059,230.742538,11.754585,0.360595,-360.829468,0.036918,0.000000
33.650002,52.297852,-360.873962,-0.002082,0.001445,0.036709,232.632462,11.850863,0.367089,-360.873962,0.037629,0.000000
34.080002,53.694992,-360.962921,-0.002061,0.001477,0.037525,238.847260,12.167459,0.375250,-360.962921,0.038349,0.000000
34.510002,54.239403,-360.918427,-0.002057,0.001502,0.038149,241.268921,12.290824,0.381487,-360.918427,0.039069,0.000000
34.940002,53.921768,-360.962921,-0.002031,0.001515,0.038470,239.856003,12.218848,0.384697,-360.962921,0.039779,0.000000
35.370003,56.584976,-361.007385,-0.002001,0.001559,0.039598,251.702545,12.822339,0.395976,-361.007385,0.040500,0.000000
35.800003,56.938354,-360.962921,-0.001983,0.001583,0.040196,253.274445,12.902416,0.401956,-360.962921,0.041219,0.000000
36.230003,58.491524,-361.007385,-0.001979,0.001616,0.041046,260.183289,13.254369,0.410464,-361.007385,0.041931,0.000000
36.660000,58.965179,-361.051880,-0.001975,0.001636,0.041566,262.290222,13.361701,0.415657,-361.051880,0.042650,0.000000
37.090000,60.006332,-361.096375,-0.001962,0.001666,0.042312,266.921509,13.597629,0.423121,-361.096375,0.043361,0.000000
37.520000,61.203140,-361.096375,-0.001932,0.001695,0.043057,272.245178,13.868830,0.430570,-361.096375,0.044080,0.000000
37.950001,62.299774,-361.140839,-0.001906,0.001727,0.043855,277.123230,14.117331,0.438548,-361.140839,0.044801,0.000000
38.380001,63.396790,-361.185333,-0.001893,0.001751,0.044471,282.002991,14.365917,0.444710,-361.185333,0.045513,0.000000
38.810001,63.899857,-361.185333,-0.001893,0.001773,0.045036,284.240753,14.479915,0.450357,-361.185333,0.046232,0.000000
39.240002,65.876419,-361.229797,-0.001858,0.001811,0.045997,293.032959,14.927810,0.459971,-361.229797,0.046951,0.000000
39.670002,66.677017,-361.185333,-0.001850,0.001837,0.046665,296.594177,15.109228,0.466647,-361.185333,0.047662,0.000000
40.100002,68.317322,-361.229797,-0.001841,0.001869,0.047472,303.890625,15.480927,0.474717,-361.229797,0.048383,0.000000
40.530003,69.141373,-361.229797,-0.001819,0.001890,0.048018,307.556183,15.667659,0.480182,-361.229797,0.049102,0.000000
40.960003,70.834930,-361.363251,-0.001785,0.001925,0.048895,315.089508,16.051424,0.488948,-361.363251,0.049814,0.000000
41.390003,71.740906,-361.363251,-0.001798,0.001951,0.049544,319.119476,16.256721,0.495443,-361.363251,0.050533,0.000000
41.820004,73.737198,-361.363251,-0.001772,0.001986,0.050438,327.999451,16.709089,0.504375,-361.363251,0.051254,0.000000
42.250004,74.329269,-361.407715,-0.001759,0.002006,0.050949,330.633118,16.843252,0.509492,-361.407715,0.051964,0.000000
42.680000,74.506149,-361.407715,-0.001750,0.002028,0.051522,331.419891,16.883335,0.515215,-361.407715,0.052684,0.000000
43.110001,77.390167,-361.407715,-0.001729,0.002065,0.052450,344.248657,17.536861,0.524496,-361.407715,0.053403,0.000000
43.540001,78.421646,-361.496704,-0.001720,0.002091,0.053117,348.836914,17.770597,0.531172,-361.496704,0.054115,0.000000
43.970001,79.929001,-361.452209,-0.001707,0.002121,0.053873,355.541962,18.112169,0.538727,-361.452209,0.054834,0.000000
44.400002,81.063995,-361.496704,-0.001686,0.002144,0.054453,360.590668,18.369364,0.544525,-361.496704,0.055546,0.000000
44.830002,82.880432,-361.541168,-0.001694,0.002179,0.055338,368.670563,18.780975,0.553382,-361.541168,0.056266,0.000000
45.260002,84.057495,-361.674622,-0.001677,0.002203,0.055953,373.906403,19.047701,0.559529,-361.674622,0.056985,0.000000
45.690002,85.862015,-361.585663,-0.001673,0.002234,0.056751,381.933319,19.456612,0.567507,-361.585663,0.057697,0.000000
46.120003,87.228989,-361.630127,-0.001669,0.002261,0.057418,388.013916,19.766371,0.574184,-361.630127,0.058416,0.000000
46.550003,87.462097,-361.630127,-0.001634,0.002276,0.057809,389.050842,19.819195,0.578090,-361.630127,0.059137,0.000000
46.980003,90.628387,-361.719086,-0.001625,0.002319,0.058911,403.135193,20.536686,0.589111,-361.719086,0.059847,0.000000
47.410004,91.953278,-361.763580,-0.001617,0.002347,0.059621,409.028595,20.836912,0.596212,-361.763580,0.060567,0.000000
47.840004,93.610336,-361.719086,-0.001617,0.002375,0.060324,416.399567,21.212406,0.603237,-361.719086,0.061287,0.000000
48.270000,95.023865,-361.763580,-0.001595,0.002399,0.060940,422.687256,21.532715,0.609398,-361.763580,0.061998,0.000000
48.700001,96.890198,-361.808044,-0.001595,0.002431,0.061738,430.989136,21.955633,0.617377,-361.808044,0.062717,0.000000
49.130001,98.286591,-361.852539,-0.001561,0.002457,0.062405,437.200592,22.272058,0.624053,-361.852539,0.063438,0.000000
49.560001,99.915359,-361.941498,-0.001569,0.002486,0.063134,444.445709,22.641144,0.631336,-361.941498,0.064148,0.000000
49.990002,101.381760,-361.852539,-0.001552,0.002510,0.063759,450.968597,22.973436,0.637588,-361.852539,0.064869,0.000000
50.420002,102.286255,-361.808044,-0.001548,0.002535,0.064383,454.991974,23.178396,0.643826,-361.808044,0.065580,0.000000
50.850002,105.688995,-361.897003,-0.001535,0.002575,0.065397,470.128143,23.949469,0.653969,-361.897003,0.066299,0.000000
51.280003,106.896957,-361.985992,-0.001526,0.002601,0.066065,475.501404,24.223196,0.660646,-361.985992,0.067020,0.000000
51.710003,108.799408,-361.985992,-0.001513,0.002629,0.066785,483.963928,24.654299,0.667852,-361.985992,0.067730,0.000000
52.140003,110.120590,-361.985992,-0.001535,0.002653,0.067383,489.840851,24.953682,0.673832,-361.985992,0.068451,0.000000
52.570004,112.645645,-362.030457,-0.001492,0.002688,0.068286,501.072845,25.525869,0.682856,-362.030457,0.069170,0.000000
53.000004,113.901291,-361.985992,-0.001500,0.002711,0.068867,506.658234,25.810400,0.688669,-361.985992,0.069881,0.000000
53.430004,115.681976,-362.074951,-0.001483,0.002740,0.069604,514.579102,26.213911,0.696042,-362.074951,0.070600,0.000000
53.860004,117.543091,-362.119415,-0.001487,0.002767,0.070272,522.857788,26.635645,0.702719,-362.119415,0.071321,0.000000
54.290001,118.974121,-362.074951,-0.001487,0.002793,0.070930,529.223328,26.959921,0.709304,-362.074951,0.072031,0.000000
54.720001,121.703232,-362.074951,-0.001475,0.002828,0.071824,541.363037,27.578346,0.718237,-362.074951,0.072752,0.000000
55.150002,123.267944,-362.163910,-0.001470,0.002854,0.072500,548.323181,27.932915,0.725004,-362.163910,0.073471,0.000000
55.580002,125.585220,-362.208374,-0.001462,0.002884,0.073263,558.630981,28.458017,0.732635,-362.208374,0.074182,0.000000
56.010002,127.206161,-362.208374,-0.001453,0.002908,0.073852,565.841248,28.825329,0.738524,-362.208374,0.074902,0.000000
56.440002,128.633835,-362.252869,-0.001427,0.002942,0.074720,572.191895,29.148844,0.747199,-362.252869,0.075613,0.000000
56.870003,131.167831,-362.208374,-0.001427,0.002965,0.075318,583.463684,29.723055,0.753179,-362.208374,0.076334,0.000000
57.300003,132.510239,-362.297333,-0.001427,0.002988,0.075883,589.434998,30.027248,0.758826,-362.297333,0.077053,0.000000
57.730003,135.318298,-362.386322,-0.001427,0.003022,0.076750,601.925842,30.663565,0.767501,-362.386322,0.077764,0.000000
58.160004,136.282364,-362.341827,-0.001410,0.003041,0.077253,606.214233,30.882025,0.772527,-362.341827,0.078484,0.000000
58.590004,138.822311,-362.386322,-0.001401,0.003072,0.078032,617.512512,31.457586,0.780324,-362.386322,0.079204,0.000000
59.020004,141.155609,-362.386322,-0.001414,0.003104,0.078848,627.891479,31.986319,0.788484,-362.386322,0.079914,0.000000
59.450005,143.332123,-362.386322,-0.001384,0.003133,0.079577,637.573120,32.479523,0.795767,-362.386322,0.080635,0.000000
59.880001,145.400650,-362.475281,-0.001371,0.003161,0.080296,646.774414,32.948261,0.802958,-362.475281,0.081354,0.000000
60.310001,147.526520,-362.475281,-0.001393,0.003189,0.080998,656.230713,33.429985,0.809983,-362.475281,0.082066,0.000000
60.740002,149.450943,-362.519745,-0.001371,0.003214,0.081640,664.791016,33.866066,0.816402,-362.519745,0.082785,0.000000
61.170002,151.550003,-362.564240,-0.001380,0.003243,0.082361,674.128052,34.341721,0.823608,-362.564240,0.083505,0.000000
61.600002,153.963730,-362.564240,-0.001362,0.003274,0.083150,684.864868,34.888680,0.831496,-362.564240,0.084217,0.000000
62.030003,155.309113,-362.653198,-0.001367,0.003294,0.083678,690.849426,35.193546,0.836780,-362.653198,0.084936,0.000000
62.460003,158.553955,-362.608704,-0.001341,0.003332,0.084641,705.283203,35.928841,0.846408,-362.608704,0.085655,0.000000
62.890003,160.079193,-362.564240,-0.001345,0.003356,0.085239,712.067810,36.274464,0.852389,-362.564240,0.086367,0.000000
63.320004,163.191864,-362.608704,-0.001324,0.003391,0.086125,725.913696,36.979805,0.861245,-362.608704,0.087087,0.000000
63.750004,164.625122,-362.653198,-0.001337,0.003412,0.086671,732.289124,37.304585,0.866711,-362.653198,0.087797,0.000000
64.180000,167.031387,-362.742157,-0.001311,0.003442,0.087425,742.992737,37.849854,0.874250,-362.742157,0.088518,0.000000
64.610001,168.851547,-362.786652,-0.001319,0.003465,0.088006,751.089172,38.262306,0.880064,-362.786652,0.089237,0.000000
65.040001,170.964386,-362.786652,-0.001293,0.003494,0.088751,760.487549,38.741085,0.887512,-362.786652,0.089949,0.000000
65.470001,173.675262,-362.742157,-0.001293,0.003526,0.089549,772.546143,39.355377,0.895491,-362.742157,0.090668,0.000000
65.900002,175.284653,-362.786652,-0.001293,0.003546,0.090070,779.705078,39.720070,0.900699,-362.786652,0.091389,0.000000
66.330002,178.703781,-362.875610,-0.001272,0.003586,0.091093,794.914124,40.494858,0.910933,-362.875610,0.092099,0.000000
66.760002,180.173538,-362.875610,-0.001272,0.003609,0.091657,801.451904,40.827908,0.916565,-362.875610,0.092819,0.000000
67.190002,182.858337,-362.875610,-0.001276,0.003638,0.092403,813.394531,41.436291,0.924029,-362.875610,0.093538,0.000000
67.620003,184.561203,-362.875610,-0.001268,0.003660,0.092959,820.969238,41.822166,0.929585,-362.875610,0.094250,0.000000
68.050003,187.331284,-362.964569,-0.001263,0.003696,0.093868,833.291138,42.449875,0.938684,-362.964569,0.094971,0.000000
68.480003,189.440765,-362.964569,-0.001255,0.003721,0.094519,842.674622,42.927891,0.945194,-362.964569,0.095690,0.000000
68.910004,191.842957,-363.009033,-0.001255,0.003750,0.095239,853.360107,43.472237,0.952386,-363.009033,0.096401,0.000000
69.340004,194.239899,-363.009033,-0.001233,0.003780,0.096002,864.022217,44.015388,0.960016,-363.009033,0.097120,0.000000
69.770004,195.872772,-363.009033,-0.001233,0.003798,0.096462,871.285583,44.385406,0.964618,-363.009033,0.097832,0.000000
70.200005,199.144043,-363.009033,-0.001220,0.003839,0.097502,885.836975,45.126682,0.975019,-363.009033,0.098551,0.000000
70.630005,200.979095,-363.097992,-0.001203,0.003861,0.098065,893.999695,45.542515,0.980651,-363.097992,0.099272,0.000000
71.060005,203.767792,-363.097992,-0.001233,0.003893,0.098872,906.404419,46.174442,0.988721,-363.097992,0.099982,0.000000
71.490005,205.469910,-363.142487,-0.001224,0.003914,0.099428,913.975830,46.560146,0.994277,-363.142487,0.100702,0.000000
71.920006,207.773041,-363.142487,-0.001224,0.003947,0.100251,924.220642,47.082043,1.002513,-363.142487,0.101422,0.000000
72.350006,211.262177,-363.142487,-0.001199,0.003979,0.101075,939.741089,47.872692,1.010749,-363.142487,0.102133,0.000000
72.780006,213.137054,-363.186951,-0.001186,0.004004,0.101700,948.080994,48.297546,1.017001,-363.186951,0.102852,0.000000
73.210007,215.728760,-363.231445,-0.001186,0.004033,0.102428,959.609436,48.884838,1.024283,-363.231445,0.103573,0.000000
73.640007,217.379517,-363.231445,-0.001186,0.004051,0.102905,966.952393,49.258904,1.029052,-363.231445,0.104284,0.000000
74.070007,220.752075,-363.275940,-0.001168,0.004078,0.103582,981.954285,50.023136,1.035820,-363.275940,0.104934,0.000000
74.500000,219.993561,-363.320404,-0.001155,0.004076,0.103529,978.580261,49.851254,1.035290,-363.320404,982.000671,0.000000
74.930000,219.728790,-363.409363,-0.001151,0.004090,0.103876,977.402466,49.791256,1.038757,-363.409363,982.000671,0.000000
75.360001,219.656189,-363.364899,-0.001143,0.004096,0.104041,977.079529,49.774803,1.040407,-363.364899,982.000671,0.000000
75.790001,219.563477,-363.409363,-0.001151,0.004101,0.104154,976.667114,49.753796,1.041543,-363.409363,982.000671,0.000000
76.220001,219.811829,-363.364899,-0.001160,0.004107,0.104319,977.771851,49.810074,1.043193,-363.364899,982.000671,0.000000
76.650002,220.355865,-363.409363,-0.001138,0.004116,0.104543,980.191833,49.933350,1.045433,-363.409363,982.000671,0.000000
77.080002,219.681122,-363.498322,-0.001138,0.004115,0.104518,977.190430,49.780453,1.045176,-363.498322,982.000671,0.000000
77.510002,219.064484,-363.498322,-0.001143,0.004115,0.104518,974.447510,49.640720,1.045176,-363.498322,982.000671,0.000000
77.940002,219.164276,-363.542816,-0.001117,0.004134,0.104994,974.891418,49.663334,1.049945,-363.542816,982.000671,0.000000
78.370003,220.122406,-363.498322,-0.001082,0.004091,0.103920,979.153381,49.880451,1.039196,-363.498322,982.000671,0.000000
78.800003,219.724335,-363.542816,-0.001087,0.004118,0.104596,977.382629,49.790245,1.045963,-363.542816,982.000671,0.000000
79.230003,219.604797,-363.542816,-0.001065,0.004133,0.104978,976.850952,49.763161,1.049778,-363.542816,982.000671,0.000000
79.660004,219.881836,-363.676270,-0.001061,0.004145,0.105273,978.083252,49.825935,1.052731,-363.676270,982.000671,0.000000
80.090004,219.816681,-363.631775,-0.001078,0.004149,0.105394,977.793457,49.811169,1.053942,-363.631775,982.000671,0.000000
80.520004,219.791718,-363.631775,-0.001082,0.004153,0.105490,977.682373,49.805515,1.054896,-363.631775,982.000671,0.000000
80.950005,219.623413,-363.676270,-0.001069,0.004157,0.105585,976.933716,49.767376,1.055849,-363.676270,982.000671,0.000000
81.380005,219.646515,-363.720734,-0.001056,0.004161,0.105680,977.036499,49.772610,1.056803,-363.720734,982.000671,0.000000
81.810005,219.509460,-363.765228,-0.001074,0.004163,0.105750,976.426819,49.741558,1.057500,-363.765228,982.000671,0.000000
82.240005,219.399994,-363.809692,-0.001065,0.004166,0.105811,975.939941,49.716747,1.058105,-363.809692,982.000671,0.000000
82.670006,219.225739,-363.809692,-0.001061,0.004171,0.105941,975.164795,49.677261,1.059407,-363.809692,982.000671,0.000000
83.100006,220.095581,-363.720734,-0.001056,0.004175,0.106036,979.034058,49.874371,1.060361,-363.720734,982.000671,0.000000
83.530006,219.636810,-363.854187,-0.001056,0.004175,0.106044,976.993347,49.770412,1.060437,-363.854187,982.000671,0.000000
83.960007,219.562347,-363.854187,-0.001065,0.004180,0.106183,976.662109,49.753536,1.061830,-363.854187,982.000671,0.000000
84.390007,219.739227,-363.898651,-0.001069,0.004187,0.106348,977.448914,49.793621,1.063480,-363.898651,982.000671,0.000000
84.820007,219.469269,-363.943146,-0.001061,0.004187,0.106348,976.248047,49.732449,1.063480,-363.943146,982.000671,0.000000
85.250008,220.108612,-363.898651,-0.001074,0.004195,0.106564,979.091980,49.877323,1.065645,-363.898651,982.000671,0.000000
85.680000,219.824860,-363.987610,-0.001056,0.004195,0.106564,977.829834,49.813023,1.065645,-363.987610,982.000671,0.000000
86.110001,219.493835,-363.987610,-0.001052,0.004196,0.106574,976.357361,49.738014,1.065736,-363.987610,982.000671,0.000000
86.540001,220.318268,-364.032104,-0.001048,0.004195,0.106564,980.024597,49.924835,1.065645,-364.032104,982.000671,0.000000
86.970001,219.936951,-364.032104,-0.001065,0.004195,0.106564,978.328430,49.838425,1.065645,-364.032104,982.000671,0.000000
87.400002,220.023346,-364.032104,-0.001065,0.004210,0.106946,978.712708,49.858002,1.069460,-364.032104,982.000671,0.000000
87.830002,219.826721,-364.032104,-0.001052,0.004210,0.106946,977.838074,49.813446,1.069460,-364.032104,982.000671,0.000000
88.260002,219.705353,-364.032104,-0.001039,0.004213,0.107016,977.298218,49.785942,1.070156,-364.032104,982.000671,0.000000
88.690002,219.710175,-364.121063,-0.001043,0.004216,0.107094,977.319641,49.787037,1.070944,-364.121063,982.000671,0.000000
89.120003,219.819672,-364.165558,-0.001048,0.004220,0.107197,977.806763,49.811848,1.071973,-364.165558,982.000671,0.000000
89.550003,219.708679,-364.121063,-0.001039,0.004221,0.107223,977.312988,49.786697,1.072230,-364.121063,982.000671,0.000000
89.980003,219.699371,-364.121063,-0.001039,0.004224,0.107302,977.271606,49.784592,1.073018,-364.121063,982.000671,0.000000
90.410004,219.752258,-364.210022,-0.001026,0.004227,0.107371,977.506836,49.796574,1.073714,-364.210022,982.000671,0.000000
90.840004,219.589172,-364.254517,-0.001035,0.004228,0.107397,976.781433,49.759617,1.073972,-364.254517,982.000671,0.000000
91.270004,220.062073,-364.343475,-0.001030,0.004233,0.107518,978.885010,49.866779,1.075183,-364.343475,982.000671,0.000000
91.700005,219.788757,-364.298981,-0.001026,0.004233,0.107518,977.669250,49.804844,1.075183,-364.298981,982.000671,0.000000
92.130005,219.536285,-364.343475,-0.001035,0.004233,0.107518,976.546143,49.747635,1.075183,-364.343475,982.000671,0.000000
92.560005,219.284180,-364.298981,-0.001022,0.004233,0.107518,975.424744,49.690506,1.075183,-364.298981,982.000671,0.000000
92.990005,220.796387,-364.343475,-0.001000,0.004259,0.108169,982.151367,50.033176,1.081693,-364.343475,982.000671,0.000000
93.420006,220.637756,-364.432434,-0.001022,0.004210,0.106946,981.445740,49.997231,1.069460,-364.432434,982.000671,0.000000
93.850006,220.409882,-364.432434,-0.001030,0.004210,0.106946,980.432129,49.945595,1.069460,-364.432434,982.000671,0.000000
94.280006,220.126495,-364.387939,-0.001018,0.004210,0.106946,979.171570,49.881374,1.069460,-364.387939,982.000671,0.000000
94.710007,219.904175,-364.476898,-0.001018,0.004229,0.107406,978.182617,49.830997,1.074062,-364.476898,982.000671,0.000000
95.140007,219.732910,-364.476898,-0.001018,0.004237,0.107632,977.420776,49.792187,1.076318,-364.476898,982.000671,0.000000
95.570007,219.587311,-364.565887,-0.001005,0.004245,0.107813,976.773132,49.759193,1.078135,-364.565887,982.000671,0.000000
96.000008,219.966003,-364.565887,-0.001030,0.004254,0.108056,978.457642,49.845009,1.080557,-364.565887,982.000671,0.000000
96.430008,219.803284,-364.521393,-0.001005,0.004255,0.108065,977.733826,49.808136,1.080648,-364.521393,982.000671,0.000000
96.860008,219.654327,-364.565887,-0.001009,0.004256,0.108109,977.071228,49.774380,1.081087,-364.565887,982.000671,0.000000
97.290001,219.583588,-364.610352,-0.000996,0.004257,0.108125,976.756592,49.758354,1.081254,-364.610352,982.000671,0.000000
97.720001,219.939178,-364.654846,-0.000996,0.004263,0.108290,978.338318,49.838928,1.082904,-364.654846,982.000671,0.000000
98.150002,219.860626,-364.654846,-0.001000,0.004263,0.108290,977.988892,49.821129,1.082904,-364.654846,982.000671,0.000000
98.580002,219.718384,-364.654846,-0.000987,0.004264,0.108299,977.356201,49.788898,1.082995,-364.654846,982.000671,0.000000
99.010002,219.643158,-364.654846,-0.001009,0.004265,0.108342,977.021545,49.771851,1.083419,-364.654846,982.000671,0.000000
99.440002,219.919067,-364.743805,-0.001000,0.004270,0.108464,978.248840,49.834373,1.084645,-364.743805,982.000671,0.000000
99.870003,219.823761,-364.743805,-0.001009,0.004270,0.108464,977.824951,49.812778,1.084645,-364.743805,982.000671,0.000000
100.300003,219.696777,-364.788269,-0.000987,0.004271,0.108490,977.260071,49.784000,1.084902,-364.788269,982.000671,0.000000
100.730003,219.725830,-364.788269,-0.001000,0.004273,0.108533,977.389282,49.790585,1.085326,-364.788269,982.000671,0.000000
101.160004,219.729919,-364.788269,-0.000987,0.004275,0.108577,977.407471,49.791512,1.085765,-364.788269,982.000671,0.000000
101.590004,219.661041,-364.788269,-0.000983,0.004276,0.108602,977.101135,49.775906,1.086023,-364.788269,982.000671,0.000000
102.020004,219.688202,-364.832764,-0.000979,0.004277,0.108646,977.221924,49.782055,1.086462,-364.832764,982.000671,0.000000
102.450005,219.712402,-364.921722,-0.000996,0.004278,0.108672,977.329590,49.787540,1.086719,-364.921722,982.000671,0.000000
102.880005,219.719482,-364.921722,-0.001005,0.004280,0.108723,977.361084,49.789146,1.087234,-364.921722,982.000671,0.000000
103.310005,219.713531,-364.921722,-0.000992,0.004282,0.108767,977.334595,49.787796,1.087673,-364.921722,982.000671,0.000000
103.740005,219.641296,-364.921722,-0.000979,0.004283,0.108785,977.013306,49.771431,1.087855,-364.921722,982.000671,0.000000
104.170006,219.656189,-365.010681,-0.000983,0.004284,0.108819,977.079529,49.774803,1.088188,-365.010681,982.000671,0.000000
104.600006,219.610748,-365.010681,-0.000992,0.004285,0.108846,976.877380,49.764507,1.088460,-365.010681,982.000671,0.000000
105.030006,219.888184,-365.055176,-0.000987,0.004290,0.108976,978.111511,49.827374,1.089762,-365.055176,982.000671,0.000000
105.460007,219.850952,-365.010681,-0.001000,0.004290,0.108976,977.945862,49.818939,1.089762,-365.010681,982.000671,0.000000
105.890007,219.778687,-365.010681,-0.000983,0.004290,0.108976,977.624451,49.802563,1.089762,-365.010681,982.000671,0.000000
106.320007,219.651337,-365.144135,-0.000987,0.004291,0.108993,977.057922,49.773705,1.089929,-365.144135,982.000671,0.000000
106.750008,219.636078,-365.099640,-0.000983,0.004292,0.109028,976.990051,49.770248,1.090277,-365.099640,982.000671,0.000000
107.180008,219.587311,-365.188599,-0.000979,0.004293,0.109053,976.773132,49.759193,1.090534,-365.188599,982.000671,0.000000
107.610008,219.518402,-365.188599,-0.000974,0.004294,0.109072,976.466614,49.743584,1.090716,-365.188599,982.000671,0.000000
108.040009,219.542603,-365.233093,-0.000979,0.004295,0.109088,976.574280,49.749062,1.090882,-365.233093,982.000671,0.000000
108.470009,220.137665,-365.233093,-0.000970,0.004301,0.109244,979.221252,49.883907,1.092442,-365.233093,982.000671,0.000000
108.900002,220.013672,-365.277557,-0.000983,0.004301,0.109244,978.669678,49.855812,1.092442,-365.277557,982.000671,0.000000
109.330002,219.868805,-365.277557,-0.000974,0.004301,0.109244,978.025269,49.822983,1.092442,-365.277557,982.000671,0.000000
109.760002,219.763794,-365.322052,-0.000983,0.004301,0.109244,977.558167,49.799191,1.092442,-365.322052,982.000671,0.000000
110.190002,219.620453,-365.277557,-0.000966,0.004301,0.109244,976.920593,49.766705,1.092442,-365.277557,982.000671,0.000000
110.620003,219.592133,-365.322052,-0.000970,0.004302,0.109270,976.794617,49.760288,1.092699,-365.322052,982.000671,0.000000
111.050003,219.484528,-365.366547,-0.000953,0.004302,0.109279,976.315918,49.735909,1.092790,-365.366547,982.000671,0.000000
111.480003,219.750397,-365.411011,-0.000966,0.004307,0.109393,977.498596,49.796154,1.093925,-365.411011,982.000671,0.000000
111.910004,219.684845,-365.411011,-0.000983,0.004307,0.109393,977.206970,49.781296,1.093925,-365.411011,982.000671,0.000000
112.340004,219.593628,-365.499969,-0.000966,0.004307,0.109393,976.801270,49.760628,1.093925,-365.499969,982.000671,0.000000
112.770004,219.500153,-365.411011,-0.000957,0.004307,0.109393,976.385437,49.739445,1.093925,-365.411011,982.000671,0.000000
113.200005,219.417511,-365.499969,-0.000970,0.004307,0.109409,976.017822,49.720718,1.094092,-365.499969,982.000671,0.000000
113.630005,219.311005,-365.588928,-0.000966,0.004308,0.109418,975.544067,49.696583,1.094183,-365.588928,982.000671,0.000000
114.060005,219.270782,-365.544464,-0.000970,0.004308,0.109435,975.365173,49.687469,1.094349,-365.544464,982.000671,0.000000
114.490005,219.235046,-365.499969,-0.000966,0.004310,0.109470,975.206177,49.679371,1.094698,-365.499969,982.000671,0.000000
114.920006,219.177673,-365.588928,-0.000974,0.004310,0.109470,974.950989,49.666370,1.094698,-365.588928,982.000671,0.000000
115.350006,219.232788,-365.633423,-0.000966,0.004313,0.109548,975.196167,49.678864,1.095485,-365.633423,982.000671,0.000000
115.780006,219.213806,-365.722382,-0.000970,0.004313,0.109548,975.111694,49.674561,1.095485,-365.722382,982.000671,0.000000
116.210007,219.153870,-365.677887,-0.000974,0.004313,0.109548,974.845093,49.660976,1.095485,-365.677887,982.000671,0.000000
116.640007,219.235413,-365.722382,-0.000970,0.004315,0.109609,975.207825,49.679455,1.096090,-365.722382,982.000671,0.000000
117.070007,219.174713,-365.677887,-0.000957,0.004315,0.109609,974.937805,49.665703,1.096090,-365.677887,982.000671,0.000000
117.500008,219.088318,-365.766846,-0.000961,0.004315,0.109609,974.553528,49.646122,1.096090,-365.766846,982.000671,0.000000
117.930008,220.127625,-365.811340,-0.000957,0.004272,0.108516,979.176575,49.881634,1.085160,-365.811340,982.000671,0.000000
118.360008,220.031525,-365.900299,-0.000957,0.004289,0.108949,978.749084,49.859856,1.089490,-365.900299,982.000671,0.000000
118.790009,219.951843,-365.855835,-0.000961,0.004294,0.109079,978.394653,49.841801,1.090792,-365.855835,982.000671,0.000000
119.220009,219.897858,-365.811340,-0.000944,0.004304,0.109314,978.154541,49.829563,1.093138,-365.811340,982.000671,0.000000
119.650009,219.844238,-365.900299,-0.000931,0.004306,0.109365,977.916016,49.817417,1.093653,-365.900299,982.000671,0.000000
120.080009,219.741455,-365.944794,-0.000940,0.004306,0.109374,977.458801,49.794128,1.093744,-365.944794,982.000671,0.000000
120.510002,219.630493,-365.944794,-0.000940,0.004306,0.109374,976.965210,49.768982,1.093744,-365.944794,982.000671,0.000000
120.940002,219.536652,-365.944794,-0.000953,0.004308,0.109435,976.547791,49.747715,1.094349,-365.944794,982.000671,0.000000
121.370003,219.475586,-365.944794,-0.000944,0.004309,0.109461,976.276184,49.733879,1.094607,-365.944794,982.000671,0.000000
121.800003,219.375427,-365.989258,-0.000944,0.004310,0.109470,975.830627,49.711182,1.094698,-365.989258,982.000671,0.000000
122.230003,219.344147,-366.033752,-0.000936,0.004315,0.109609,975.691467,49.704094,1.096090,-366.033752,982.000671,0.000000
122.660004,220.868622,-366.122711,-0.000931,0.004335,0.110121,982.472717,50.049545,1.101208,-366.122711,982.000671,0.000000
123.090004,220.704041,-366.122711,-0.000931,0.004327,0.109912,981.740601,50.012249,1.099118,-366.122711,982.000671,0.000000
123.520004,220.606110,-366.033752,-0.000944,0.004327,0.109912,981.304993,49.990059,1.099118,-366.033752,982.000671,0.000000
123.950005,220.513031,-366.122711,-0.000931,0.004327,0.109912,980.890930,49.968964,1.099118,-366.122711,982.000671,0.000000
124.380005,220.431091,-366.122711,-0.000923,0.004327,0.109912,980.526489,49.950397,1.099118,-366.122711,982.000671,0.000000
124.810005,220.317902,-366.167175,-0.000936,0.004327,0.109912,980.022949,49.924751,1.099118,-366.167175,982.000671,0.000000
125.240005,220.219574,-366.211670,-0.000927,0.004327,0.109912,979.585571,49.902470,1.099118,-366.211670,982.000671,0.000000
125.670006,220.127625,-366.256165,-0.000940,0.004327,0.109912,979.176575,49.881634,1.099118,-366.256165,982.000671,0.000000
126.100006,220.052399,-366.256165,-0.000936,0.004327,0.109912,978.841980,49.864586,1.099118,-366.256165,982.000671,0.000000
126.530006,219.941437,-366.300629,-0.000944,0.004328,0.109921,978.348389,49.839443,1.099209,-366.300629,982.000671,0.000000
126.960007,219.859863,-366.345123,-0.000923,0.004328,0.109921,977.985535,49.820957,1.099209,-366.345123,982.000671,0.000000
127.390007,219.792114,-366.389587,-0.000923,0.004328,0.109921,977.684143,49.805607,1.099209,-366.389587,982.000671,0.000000
127.820007,220.009583,-366.389587,-0.000931,0.004344,0.110328,978.651489,49.854881,1.103282,-366.389587,982.000671,0.000000
128.250000,220.078461,-366.389587,-0.000931,0.004344,0.110328,978.957886,49.870491,1.103282,-366.389587,982.000671,0.000000
128.680008,220.020355,-366.345123,-0.000923,0.004344,0.110328,978.699402,49.857323,1.103282,-366.345123,982.000671,0.000000
129.110001,219.960052,-366.434082,-0.000931,0.004344,0.110328,978.431152,49.843662,1.103282,-366.434082,982.000671,0.000000
129.540009,219.873657,-366.434082,-0.000923,0.004344,0.110328,978.046875,49.824085,1.103282,-366.434082,982.000671,0.000000
129.970001,219.809601,-366.478546,-0.000931,0.004344,0.110328,977.761963,49.809566,1.103282,-366.478546,982.000671,0.000000
130.400009,219.754852,-366.434082,-0.000949,0.004344,0.110337,977.518433,49.797161,1.103373,-366.434082,982.000671,0.000000
130.830002,219.733643,-366.434082,-0.000940,0.004346,0.110398,977.424072,49.792355,1.103978,-366.434082,982.000671,0.000000
131.260010,219.808868,-366.567505,-0.000927,0.004347,0.110414,977.758667,49.809402,1.104145,-366.567505,982.000671,0.000000
131.690002,219.761566,-366.523041,-0.000931,0.004347,0.110414,977.548279,49.798683,1.104145,-366.523041,982.000671,0.000000
132.120010,219.739594,-366.612000,-0.000944,0.004348,0.110433,977.450500,49.793705,1.104326,-366.612000,982.000671,0.000000
132.550003,219.825256,-366.567505,-0.000936,0.004350,0.110493,977.831604,49.813114,1.104932,-366.567505,982.000671,0.000000
132.980011,219.820404,-366.612000,-0.000923,0.004350,0.110493,977.809998,49.812016,1.104932,-366.612000,982.000671,0.000000
133.410004,219.776093,-366.656494,-0.000923,0.004350,0.110493,977.612915,49.801975,1.104932,-366.656494,982.000671,0.000000
133.840012,219.739960,-366.700958,-0.000918,0.004350,0.110502,977.452148,49.793785,1.105023,-366.700958,982.000671,0.000000
134.270004,219.702728,-366.789917,-0.000914,0.004351,0.110510,977.286560,49.785351,1.105098,-366.789917,982.000671,0.000000
134.700012,219.717987,-366.745453,-0.000923,0.004352,0.110537,977.354431,49.788807,1.105371,-366.745453,5607.367676,0.000000
135.130005,219.658051,-366.745453,-0.000918,0.004340,0.110242,977.087830,49.775227,1.102419,-366.745453,0.110068,0.000000
135.560013,219.512085,-366.745453,-0.000936,0.004318,0.109686,976.438538,49.742149,1.096863,-366.745453,0.109358,0.000000
135.990005,218.985931,-366.834412,-0.000923,0.004292,0.109019,974.098083,49.622921,1.090186,-366.834412,0.108637,0.000000
136.420013,218.199829,-366.923370,-0.000923,0.004274,0.108567,970.601318,49.444790,1.085674,-366.923370,0.107918,0.000000
136.850006,216.896149,-366.878876,-0.000923,0.004245,0.107823,964.802246,49.149368,1.078226,-366.878876,0.107206,0.000000
137.280014,216.201324,-366.878876,-0.000905,0.004211,0.106972,961.711548,48.991920,1.069717,-366.878876,0.106487,0.000000
137.710007,215.870636,-366.878876,-0.000914,0.004188,0.106374,960.240540,48.916985,1.063737,-366.878876,0.105776,0.000000
138.139999,215.516907,-366.923370,-0.000910,0.004164,0.105776,958.667053,48.836830,1.057757,-366.923370,0.105055,0.000000
138.570007,215.067444,-367.012329,-0.000910,0.004136,0.105055,956.667786,48.734982,1.050551,-367.012329,0.104336,0.000000
139.000000,214.797852,-367.012329,-0.000905,0.004114,0.104492,955.468567,48.673889,1.044919,-367.012329,0.103624,0.000000
139.430008,213.852386,-367.056793,-0.000897,0.004075,0.103512,951.262939,48.459644,1.035123,-367.056793,0.102905,0.000000
139.860001,212.442596,-366.967834,-0.000901,0.004046,0.102775,944.991882,48.140179,1.027750,-366.967834,0.102185,0.000000
140.290009,211.249512,-367.056793,-0.000897,0.004026,0.102272,939.684753,47.869823,1.022724,-367.056793,0.101475,0.000000
140.720001,209.612915,-367.145782,-0.000892,0.003998,0.101552,932.404785,47.498966,1.015518,-367.145782,0.100754,0.000000
141.150009,207.566010,-367.145782,-0.000884,0.003971,0.100875,923.299744,47.035130,1.008750,-367.145782,0.100035,0.000000
141.580002,204.928864,-367.145782,-0.000905,0.003941,0.100095,911.569092,46.437546,1.000953,-367.145782,0.099323,0.000000
142.010010,202.002747,-367.145782,-0.000897,0.003912,0.099367,898.553101,45.774475,0.993671,-367.145782,0.098604,0.000000
142.440002,199.227844,-367.234741,-0.000892,0.003887,0.098734,886.209717,45.145672,0.987343,-367.234741,0.097883,0.000000
142.870010,196.103638,-367.279205,-0.000871,0.003861,0.098074,872.312561,44.437717,0.980742,-367.279205,0.097172,0.000000
143.300003,193.218872,-367.279205,-0.000880,0.003833,0.097355,859.480469,43.784023,0.973551,-367.279205,0.096453,0.000000
143.730011,189.661957,-367.234741,-0.000905,0.003800,0.096522,843.658508,42.978012,0.965224,-367.234741,0.095734,0.000000
144.160004,186.281555,-367.234741,-0.000897,0.003772,0.095802,828.621765,42.212002,0.958017,-367.234741,0.095022,0.000000
144.590012,184.241699,-367.279205,-0.000880,0.003749,0.095229,819.548035,41.749763,0.952295,-367.279205,0.094301,0.000000
145.020004,181.813843,-367.368164,-0.000897,0.003733,0.094806,808.748352,41.199608,0.948056,-367.368164,0.093591,0.000000
145.450012,177.455963,-367.412659,-0.000892,0.003692,0.093782,789.363525,40.212097,0.937821,-367.412659,0.092871,0.000000
145.880005,173.848038,-367.323700,-0.000880,0.003662,0.093010,773.314697,39.394527,0.930100,-367.323700,0.092152,0.000000
146.310013,171.034027,-367.368164,-0.000888,0.003639,0.092420,760.797363,38.756866,0.924196,-367.368164,0.091440,0.000000
146.740005,167.400040,-367.368164,-0.000875,0.003607,0.091614,744.632568,37.933388,0.916141,-367.368164,0.090721,0.000000
147.170013,164.424042,-367.501617,-0.000871,0.003581,0.090946,731.394653,37.259018,0.909465,-367.501617,0.090000,0.000000
147.600006,160.366669,-367.501617,-0.000888,0.003551,0.090183,713.346558,36.339603,0.901834,-367.501617,0.089290,0.000000
148.030014,156.331268,-367.590576,-0.000880,0.003517,0.089342,695.396240,35.425171,0.893417,-367.590576,0.088570,0.000000
148.460007,153.958893,-367.501617,-0.000901,0.003494,0.088751,684.843384,34.887585,0.887512,-367.501617,0.087850,0.000000
148.890015,149.862411,-367.501617,-0.000875,0.003463,0.087972,666.621277,33.959305,0.879716,-367.501617,0.087139,0.000000
149.320007,146.675659,-367.546112,-0.000867,0.003435,0.087243,652.445923,33.237179,0.872433,-367.546112,0.086420,0.000000
149.750000,142.671158,-367.635071,-0.000875,0.003400,0.086367,634.632996,32.329746,0.863668,-367.635071,0.085699,0.000000
150.180008,140.522568,-367.635071,-0.000884,0.003384,0.085960,625.075623,31.842869,0.859595,-367.635071,0.084988,0.000000
150.610001,137.706696,-367.635071,-0.000884,0.003358,0.085292,612.549988,31.204782,0.852919,-367.635071,0.084268,0.000000
151.040009,133.540955,-367.679535,-0.000884,0.003316,0.084234,594.019836,30.260813,0.842336,-367.679535,0.083557,0.000000
151.470001,130.189972,-367.679535,-0.000888,0.003293,0.083652,579.113892,29.501471,0.836522,-367.679535,0.082838,0.000000
151.900009,126.939545,-367.768494,-0.000888,0.003266,0.082950,564.655273,28.764912,0.829498,-367.768494,0.082117,0.000000
152.330002,123.908432,-367.768494,-0.000875,0.003237,0.082222,551.172241,28.078053,0.822215,-367.768494,0.081407,0.000000
152.760010,120.281143,-367.724030,-0.000892,0.003208,0.081484,535.037231,27.256098,0.814842,-367.724030,0.080686,0.000000
153.190002,117.177795,-367.724030,-0.000875,0.003180,0.080765,521.232849,26.552868,0.807651,-367.724030,0.079967,0.000000
153.620010,113.286880,-367.768494,-0.000884,0.003146,0.079914,503.925201,25.671173,0.799143,-367.768494,0.079256,0.000000
154.050003,111.281647,-367.857452,-0.000875,0.003130,0.079507,495.005493,25.216782,0.795070,-367.857452,0.078537,0.000000
154.480011,108.220749,-367.946442,-0.000880,0.003103,0.078823,481.389923,24.523172,0.788227,-367.946442,0.077816,0.000000
154.910004,104.056885,-367.946442,-0.000905,0.003066,0.077876,462.868134,23.579626,0.778765,-367.946442,0.077104,0.000000
155.340012,101.314728,-367.946442,-0.000905,0.003042,0.077278,450.670410,22.958246,0.772785,-367.946442,0.076385,0.000000
155.770004,97.935074,-367.901947,-0.000888,0.003012,0.076515,435.636963,22.192406,0.765154,-367.901947,0.075666,0.000000
156.200012,95.210052,-367.946442,-0.000901,0.002989,0.075925,423.515472,21.574905,0.759250,-367.946442,0.074955,0.000000
156.630005,91.927597,-367.990906,-0.000892,0.002960,0.075180,408.914368,20.831091,0.751801,-367.990906,0.074234,0.000000
157.060013,88.861481,-368.035400,-0.000897,0.002932,0.074478,395.275604,20.136301,0.744776,-368.035400,0.073524,0.000000
157.490005,85.838181,-368.035400,-0.000897,0.002906,0.073818,381.827301,19.451210,0.738176,-368.035400,0.072803,0.000000
157.920013,83.194717,-368.035400,-0.000884,0.002885,0.073273,370.068573,18.852194,0.732725,-368.035400,0.072084,0.000000
158.350006,79.890656,-368.035400,-0.000875,0.002848,0.072335,355.371399,18.103481,0.723354,-368.035400,0.071373,0.000000
158.780014,76.080170,-368.168823,-0.000880,0.002818,0.071572,338.421509,17.240013,0.715724,-368.168823,0.070653,0.000000
159.210007,73.084061,-368.124359,-0.000888,0.002792,0.070912,325.094147,16.561085,0.709123,-368.124359,0.069933,0.000000
159.640015,70.312119,-368.124359,-0.000888,0.002767,0.070289,312.763916,15.932953,0.702885,-368.124359,0.069221,0.000000
160.070007,67.105988,-368.213318,-0.000884,0.002737,0.069525,298.502350,15.206434,0.695255,-368.213318,0.068502,0.000000
160.500000,63.833572,-368.168823,-0.000871,0.002707,0.068762,283.945923,14.464894,0.687625,-368.168823,0.067783,0.000000
160.930008,60.314285,-368.302277,-0.000867,0.002676,0.067965,268.291351,13.667412,0.679646,-368.302277,0.067071,0.000000
161.360001,57.176674,-368.257782,-0.000888,0.002646,0.067218,254.334549,12.956420,0.672182,-368.257782,0.066351,0.000000
161.790009,55.128624,-368.302277,-0.000892,0.002630,0.066811,245.224365,12.492325,0.668110,-368.302277,0.065632,0.000000
162.220001,51.332664,-368.302277,-0.000884,0.002589,0.065753,228.339096,11.632148,0.657527,-368.302277,0.064920,0.000000
162.650009,48.112015,-368.302277,-0.000897,0.002563,0.065094,214.012924,10.902338,0.650941,-368.302277,0.064201,0.000000
163.080002,44.899925,-368.346741,-0.000867,0.002532,0.064313,199.724838,10.174468,0.643129,-368.346741,0.063480,0.000000
163.510010,42.040855,-368.435730,-0.000880,0.002508,0.063715,187.007065,9.526593,0.637149,-368.435730,0.062770,0.000000
163.940002,39.595856,-368.480194,-0.000897,0.002487,0.063177,176.131165,8.972549,0.631775,-368.480194,0.062050,0.000000
164.370010,35.751106,-368.435730,-0.000884,0.002451,0.062249,159.028870,8.101316,0.622494,-368.435730,0.061340,0.000000
164.800003,33.013802,-368.435730,-0.000892,0.002424,0.061582,146.852722,7.481034,0.615818,-368.435730,0.060619,0.000000
165.230011,29.820709,-368.524689,-0.000884,0.002392,0.060758,132.649139,6.757470,0.607582,-368.524689,0.059900,0.000000
165.660004,27.175743,-368.524689,-0.000888,0.002373,0.060263,120.883743,6.158112,0.602631,-368.524689,0.059188,0.000000
166.090012,24.735214,-368.524689,-0.000888,0.002349,0.059674,110.027725,5.605080,0.596742,-368.524689,0.058469,0.000000
166.520004,21.273643,-368.524689,-0.000880,0.002311,0.058702,94.629890,4.820676,0.587022,-368.524689,0.057748,0.000000
166.950012,18.142357,-368.524689,-0.000884,0.002284,0.058018,80.701233,4.111117,0.580179,-368.524689,0.057037,0.000000
167.380005,14.920219,-368.613647,-0.000888,0.002252,0.057193,66.368454,3.380970,0.571928,-368.613647,0.056318,0.000000
167.810013,12.955215,-368.702606,-0.000892,0.002233,0.056716,57.627678,2.935694,0.567159,-368.702606,0.055597,0.000000
168.240005,10.104698,-368.658112,-0.000897,0.002209,0.056109,44.947941,2.289757,0.561088,-368.658112,0.054887,0.000000
168.670013,6.472954,-368.658112,-0.000892,0.002170,0.055129,28.793137,1.466792,0.551293,-368.658112,0.054166,0.000000
169.100006,4.494537,-368.747070,-0.000888,0.002150,0.054608,19.992701,1.018477,0.546085,-368.747070,0.053447,0.000000
169.530014,1.541252,-368.747070,-0.000901,0.002115,0.053715,6.855832,0.349253,0.537152,-368.747070,0.052736,0.000000
169.960007,-0.967422,-368.747070,-0.000884,0.002087,0.053005,-4.303310,-0.219221,0.530052,-368.747070,0.052017,0.000000
170.390015,-0.246140,-368.880524,-0.000884,0.002061,0.052338,-1.094883,-0.055776,0.523375,-368.880524,0.051305,0.000000
170.820007,-0.075218,-368.747070,-0.000892,0.002032,0.051609,-0.334587,-0.017045,0.516093,-368.747070,0.050586,0.000000
171.250015,0.014526,-368.836060,-0.000884,0.001996,0.050698,0.064617,0.003292,0.506979,-368.836060,0.049865,0.000000
171.680008,0.041710,-368.880524,-0.000875,0.001981,0.050325,0.185535,0.009452,0.503255,-368.880524,0.049154,0.000000
172.110001,-0.004097,-368.880524,-0.000854,0.001941,0.049302,-0.018224,-0.000928,0.493020,-368.880524,0.048435,0.000000
172.540009,-0.003723,-368.880524,-0.000867,0.001914,0.048609,-0.016561,-0.000844,0.486086,-368.880524,0.047715,0.000000
172.970001,-0.052505,-368.925018,-0.000871,0.001881,0.047776,-0.233556,-0.011898,0.477760,-368.925018,0.047004,0.000000
173.400009,-0.055481,-368.969482,-0.000854,0.001864,0.047341,-0.246792,-0.012572,0.473415,-368.969482,0.046283,0.000000
173.830002,-0.091972,-368.925018,-0.000871,0.001836,0.046631,-0.409113,-0.020841,0.466314,-368.925018,0.045564,0.000000
174.260010,-0.105377,-369.013977,-0.000858,0.001806,0.045885,-0.468741,-0.023879,0.458850,-369.013977,0.044853,0.000000
174.690002,-0.101654,-369.013977,-0.000862,0.001777,0.045139,-0.452180,-0.023035,0.451387,-369.013977,0.044133,0.000000
175.120010,-0.092346,-369.102936,-0.000880,0.001744,0.044306,-0.410776,-0.020926,0.443060,-369.102936,0.043413,0.000000
175.550003,-0.118416,-369.058441,-0.000905,0.001726,0.043847,-0.526740,-0.026833,0.438473,-369.058441,0.042703,0.000000
175.980011,-0.135170,-369.058441,-0.000923,0.001696,0.043066,-0.601266,-0.030630,0.430660,-369.058441,0.041982,0.000000
176.410004,-0.096069,-369.147400,-0.000931,0.001662,0.042208,-0.427338,-0.021770,0.422076,-369.147400,0.041263,0.000000
176.800003,-0.063301,-369.191895,-0.000961,0.001649,0.041887,-0.281577,-0.014344,0.418867,-369.191895,0.041766,0.000000