File: Data/sima compression 500bar/P1-15-500bar-1_11072024_172124.csv
Time (sec),S:Load (lbs),S:HL1 (DIM),S:LVDT (in),S:Position (in),Ch:Position (mm),Ch:Load (N),Ch:Stress (MPa),Ch:Strain (mm/mm),Ch:HL1 (DIM),Set Point (),Cycles ()
0.010000,-0.090485,-428.618439,-0.008873,-0.006034,-0.153256,-0.402496,-0.020504,-1.532565,-428.618439,-0.153117,0.000000
0.440000,-0.106125,-428.618439,-0.008886,-0.005968,-0.151582,-0.472067,-0.024048,-1.515820,-428.618439,-0.151088,0.000000
0.870000,-0.088997,-428.573975,-0.008757,-0.005709,-0.145001,-0.395878,-0.020167,-1.450008,-428.573975,-0.143924,0.000000
1.300000,-0.078194,-428.707397,-0.008481,-0.005430,-0.137925,-0.347823,-0.017719,-1.379246,-428.707397,-0.136762,0.000000
1.730000,-0.072235,-428.751892,-0.008166,-0.005140,-0.130553,-0.321318,-0.016369,-1.305531,-428.751892,-0.129598,0.000000
2.160000,-0.118416,-428.707397,-0.007881,-0.004863,-0.123528,-0.526740,-0.026833,-1.235284,-428.707397,-0.122419,0.000000
2.590000,-0.092346,-428.662933,-0.007588,-0.004576,-0.116234,-0.410776,-0.020926,-1.162341,-428.662933,-0.115255,0.000000
3.020000,-0.081917,-428.707397,-0.007278,-0.004302,-0.109279,-0.364384,-0.018563,-1.092790,-428.707397,-0.108092,0.000000
3.450000,-0.071121,-428.840851,-0.007006,-0.004015,-0.101977,-0.316363,-0.016116,-1.019772,-428.840851,-0.100928,0.000000
3.880000,-0.099792,-428.840851,-0.006713,-0.003735,-0.094866,-0.443899,-0.022613,-0.948661,-428.840851,-0.093765,0.000000
4.310000,-0.096817,-428.796356,-0.006424,-0.003453,-0.087704,-0.430664,-0.021939,-0.877036,-428.796356,-0.086601,0.000000
4.740000,-0.075218,-428.840851,-0.006118,-0.003168,-0.080479,-0.334587,-0.017045,-0.804790,-428.840851,-0.079439,0.000000
5.170000,-0.101280,-428.840851,-0.005833,-0.002899,-0.073645,-0.450517,-0.022950,-0.736450,-428.840851,-0.072275,0.000000
5.600000,-0.075592,-428.885315,-0.005553,-0.002605,-0.066178,-0.336250,-0.017129,-0.661781,-428.885315,-0.065112,0.000000
6.030000,-0.086388,-428.885315,-0.005260,-0.002327,-0.059111,-0.384271,-0.019576,-0.591110,-428.885315,-0.057948,0.000000
6.460001,-0.086388,-428.929810,-0.004958,-0.002039,-0.051800,-0.384271,-0.019576,-0.518001,-428.929810,-0.050786,0.000000
6.890000,-0.071495,-428.885315,-0.004678,-0.001760,-0.044715,-0.318026,-0.016201,-0.447147,-428.885315,-0.043622,0.000000
7.320000,-0.096443,-428.929810,-0.004393,-0.001488,-0.037802,-0.429001,-0.021854,-0.378020,-428.929810,-0.036459,0.000000
7.750000,-0.086014,-428.974304,-0.004092,-0.001197,-0.030414,-0.382608,-0.019491,-0.304139,-428.974304,-0.029295,0.000000
8.180000,-0.061813,-428.974304,-0.003798,-0.000917,-0.023294,-0.274960,-0.014007,-0.232938,-428.974304,-0.022133,0.000000
8.610001,-0.081917,-429.018768,-0.003510,-0.000629,-0.015983,-0.364384,-0.018563,-0.159829,-429.018768,-0.014969,0.000000
9.040000,-0.080055,-429.063263,-0.003229,-0.000355,-0.009020,-0.356103,-0.018141,-0.090202,-429.063263,-0.007806,0.000000
9.470000,-0.076332,-429.018768,-0.002936,-0.000065,-0.001640,-0.339542,-0.017297,-0.016396,-429.018768,-0.000642,0.000000
9.900001,0.202942,-429.107727,-0.002682,0.000160,0.004066,0.902731,0.045987,0.040665,-429.107727,0.004232,0.000000
10.330001,0.170174,-429.152222,-0.002703,-0.000000,-0.000008,0.756970,0.038562,-0.000076,-429.152222,0.000165,0.000000
10.760000,0.191032,-429.152222,-0.002686,0.000004,0.000114,0.849755,0.043289,0.001135,-429.152222,0.000824,0.000000
11.190001,0.414078,-429.107727,-0.002677,0.000024,0.000616,1.841910,0.093831,0.006162,-429.107727,0.001544,0.000000
11.620001,0.757782,-429.152222,-0.002647,0.000051,0.001293,3.370783,0.171716,0.012929,-429.152222,0.002256,0.000000
12.050000,1.546463,-429.196686,-0.002613,0.000087,0.002203,6.879011,0.350434,0.022028,-429.196686,0.002975,0.000000
12.480000,2.205566,-429.196686,-0.002604,0.000109,0.002775,9.810849,0.499788,0.027751,-429.196686,0.003696,0.000000
12.910001,3.166283,-429.196686,-0.002591,0.000141,0.003582,14.084329,0.717490,0.035820,-429.196686,0.004406,0.000000
13.340001,4.046204,-429.241180,-0.002548,0.000167,0.004250,17.998413,0.916883,0.042497,-429.241180,0.005126,0.000000
13.770000,5.171509,-429.196686,-0.002535,0.000198,0.005022,23.004021,1.171881,0.050218,-429.196686,0.005845,0.000000
14.200001,6.284157,-429.285645,-0.002522,0.000224,0.005699,27.953325,1.424010,0.056985,-429.285645,0.006557,0.000000
14.630001,7.151413,-429.285645,-0.002492,0.000246,0.006253,31.811073,1.620533,0.062526,-429.285645,0.007276,0.000000
15.060000,8.672928,-429.330139,-0.002471,0.000280,0.007120,38.579109,1.965314,0.071201,-429.330139,0.007997,0.000000
15.490001,9.673866,-429.330139,-0.002445,0.000304,0.007718,43.031506,2.192130,0.077182,-429.330139,0.008707,0.000000
15.920001,11.132820,-429.285645,-0.002427,0.000336,0.008525,49.521255,2.522733,0.085251,-429.285645,0.009427,0.000000
16.350000,12.211212,-429.330139,-0.002410,0.000363,0.009211,54.318184,2.767100,0.092109,-429.330139,0.010139,0.000000
16.780001,13.715599,-429.463593,-0.002402,0.000392,0.009948,61.010033,3.107999,0.099482,-429.463593,0.010858,0.000000
17.210001,14.929901,-429.419098,-0.002376,0.000420,0.010658,66.411514,3.383164,0.106583,-429.419098,0.011577,0.000000
17.640001,16.084633,-429.419098,-0.002354,0.000447,0.011353,71.548019,3.644830,0.113532,-429.419098,0.012289,0.000000
18.070002,17.406555,-429.508057,-0.002328,0.000478,0.012142,77.428223,3.944382,0.121419,-429.508057,0.013009,0.000000
18.500000,18.160606,-429.508057,-0.002307,0.000500,0.012705,80.782410,4.115252,0.127051,-429.508057,0.013729,0.000000
18.930000,20.088379,-429.552551,-0.002285,0.000537,0.013633,89.357574,4.552092,0.136332,-429.552551,0.014440,0.000000
19.360001,20.581398,-429.552551,-0.002276,0.000558,0.014180,91.550629,4.663812,0.141797,-429.552551,0.015159,0.000000
19.790001,22.259308,-429.552551,-0.002225,0.000593,0.015064,99.014343,5.044031,0.150639,-429.552551,0.015880,0.000000
20.220001,23.078529,-429.597015,-0.002233,0.000618,0.015706,102.658424,5.229670,0.157058,-429.597015,0.016590,0.000000
20.650002,24.268257,-429.597015,-0.002182,0.000648,0.016469,107.950600,5.499266,0.164688,-429.597015,0.017311,0.000000
21.080002,25.067368,-429.641510,-0.002147,0.000676,0.017171,111.505219,5.680347,0.171713,-429.641510,0.018030,0.000000
21.510000,25.637474,-429.641510,-0.002130,0.000700,0.017787,114.041183,5.809535,0.177875,-429.641510,0.018741,0.000000
21.940001,26.706184,-429.685974,-0.002095,0.000732,0.018585,118.795044,6.051708,0.185853,-429.685974,0.019460,0.000000
22.370001,26.661873,-429.597015,-0.002078,0.000748,0.019011,118.597931,6.041667,0.190108,-429.597015,0.020172,0.000000
22.800001,28.491333,-429.685974,-0.002044,0.000791,0.020086,126.735779,6.456228,0.200857,-429.685974,0.020893,0.000000
23.230001,28.874504,-429.774963,-0.002013,0.000818,0.020779,128.440216,6.543056,0.207791,-429.774963,0.021612,0.000000
23.660002,29.538445,-429.774963,-0.001966,0.000847,0.021507,131.393570,6.693507,0.215073,-429.774963,0.022323,0.000000
24.090002,29.287842,-429.730469,-0.001957,0.000868,0.022045,130.278824,6.636720,0.220447,-429.730469,0.023042,0.000000
24.520000,30.772865,-429.774963,-0.001919,0.000902,0.022912,136.884537,6.973231,0.229122,-429.774963,0.023763,0.000000
24.950001,31.086029,-429.819427,-0.001863,0.000930,0.023615,138.277557,7.044195,0.236147,-429.819427,0.024473,0.000000
25.380001,31.494522,-429.819427,-0.001837,0.000957,0.024308,140.094635,7.136761,0.243081,-429.819427,0.025194,0.000000
25.810001,31.834869,-429.863922,-0.001815,0.000985,0.025029,141.608566,7.213884,0.250288,-429.863922,0.025913,0.000000
26.240002,31.856468,-429.863922,-0.001798,0.001008,0.025610,141.704651,7.218779,0.256101,-429.863922,0.026624,0.000000
26.670002,33.013428,-429.908386,-0.001733,0.001044,0.026529,146.851059,7.480949,0.265291,-429.908386,0.027344,0.000000
27.100000,32.899857,-429.908386,-0.001690,0.001070,0.027188,146.345871,7.455214,0.271877,-429.908386,0.028064,0.000000
27.530001,33.658379,-429.952881,-0.001673,0.001099,0.027925,149.719940,7.627098,0.279250,-429.952881,0.028774,0.000000
27.960001,34.069099,-429.952881,-0.001630,0.001126,0.028611,151.546921,7.720168,0.286108,-429.952881,0.029495,0.000000
28.390001,33.139664,-429.997345,-0.001600,0.001137,0.028870,147.412582,7.509555,0.288697,-429.997345,0.030206,0.000000
28.820002,35.007484,-430.041840,-0.001561,0.001183,0.030041,155.721069,7.932809,0.300415,-430.041840,0.030926,0.000000
29.250002,35.232765,-429.997345,-0.001535,0.001208,0.030683,156.723160,7.983859,0.306834,-429.997345,0.031645,0.000000
29.680002,35.974533,-430.086304,-0.001500,0.001239,0.031481,160.022720,8.151946,0.314812,-430.086304,0.032356,0.000000
30.110001,35.488586,-430.130798,-0.001457,0.001254,0.031845,157.861115,8.041829,0.318446,-430.130798,0.033077,0.000000
30.540001,37.362740,-430.086304,-0.001423,0.001296,0.032929,166.197769,8.466517,0.329286,-430.086304,0.033796,0.000000
30.970001,37.355659,-430.130798,-0.001393,0.001321,0.033561,166.166275,8.464913,0.335614,-430.130798,0.034508,0.000000
31.400002,38.127220,-430.175262,-0.001354,0.001351,0.034308,169.598343,8.639751,0.343078,-430.175262,0.035227,0.000000
31.830002,37.951088,-430.219757,-0.001337,0.001373,0.034880,168.814865,8.599839,0.348801,-430.219757,0.035947,0.000000
32.260002,39.376526,-430.175262,-0.001306,0.001408,0.035757,175.155533,8.922849,0.357567,-430.175262,0.036657,0.000000
32.690002,39.633461,-430.175262,-0.001268,0.001435,0.036450,176.298447,8.981071,0.364501,-430.175262,0.037378,0.000000
33.120003,40.176384,-430.264252,-0.001250,0.001462,0.037127,178.713486,9.104099,0.371268,-430.264252,0.038097,0.000000
33.550003,40.725258,-430.219757,-0.001194,0.001489,0.037829,181.154999,9.228475,0.378293,-430.219757,0.038809,0.000000
33.980003,40.790428,-430.264252,-0.001168,0.001512,0.038402,181.444885,9.243243,0.384015,-430.264252,0.039528,0.000000
34.410000,42.324226,-430.308716,-0.001151,0.001549,0.039346,188.267563,9.590807,0.393463,-430.308716,0.040249,0.000000
34.840000,42.591965,-430.308716,-0.001104,0.001575,0.040005,189.458527,9.651477,0.400048,-430.308716,0.040960,0.000000
35.270000,43.551941,-430.353210,-0.001082,0.001604,0.040751,193.728714,9.869011,0.407512,-430.353210,0.041679,0.000000
35.700001,44.094116,-430.353210,-0.001043,0.001633,0.041479,196.140427,9.991870,0.414794,-430.353210,0.042391,0.000000
36.130001,44.928970,-430.353210,-0.001000,0.001661,0.042200,199.854034,10.181050,0.422001,-430.353210,0.043110,0.000000
36.560001,45.350502,-430.486633,-0.000987,0.001689,0.042910,201.729111,10.276570,0.429101,-430.486633,0.043831,0.000000
36.990002,45.791763,-430.442169,-0.000961,0.001711,0.043466,203.691940,10.376562,0.434657,-430.442169,0.044541,0.000000
37.420002,46.867920,-430.442169,-0.000927,0.001744,0.044298,208.478928,10.620422,0.442984,-430.442169,0.045261,0.000000
37.850002,47.132675,-430.486633,-0.000914,0.001765,0.044819,209.656616,10.680417,0.448192,-430.486633,0.045980,0.000000
38.280003,48.686584,-430.486633,-0.000875,0.001801,0.045738,216.568741,11.032538,0.457382,-430.486633,0.046692,0.000000
38.710003,49.159866,-430.531128,-0.000862,0.001827,0.046415,218.674011,11.139785,0.464149,-430.531128,0.047411,0.000000
39.140003,50.283691,-430.486633,-0.000832,0.001858,0.047186,223.673035,11.394447,0.471855,-430.486633,0.048132,0.000000
39.570004,50.608772,-430.486633,-0.000793,0.001878,0.047697,225.119064,11.468112,0.476972,-430.486633,0.048843,0.000000
40.000000,51.705406,-430.531128,-0.000759,0.001911,0.048539,229.997131,11.716613,0.485390,-430.531128,0.049562,0.000000
40.430000,52.752144,-430.575592,-0.000724,0.001939,0.049258,234.653259,11.953806,0.492581,-430.575592,0.050282,0.000000
40.860001,53.502846,-430.575592,-0.000720,0.001967,0.049970,237.992538,12.123919,0.499697,-430.575592,0.050993,0.000000
41.290001,55.025856,-430.709045,-0.000686,0.002000,0.050793,244.767227,12.469037,0.507933,-430.709045,0.051714,0.000000
41.720001,55.111130,-430.664581,-0.000651,0.002018,0.051263,245.146545,12.488360,0.512626,-430.664581,0.052424,0.000000
42.150002,57.305519,-430.664581,-0.000629,0.002060,0.052328,254.907684,12.985616,0.523284,-430.664581,0.053144,0.000000
42.580002,57.571022,-430.709045,-0.000586,0.002081,0.052849,256.088684,13.045780,0.528492,-430.709045,0.053864,0.000000
43.010002,58.493759,-430.798004,-0.000573,0.002108,0.053543,260.193237,13.254875,0.535426,-430.798004,0.054575,0.000000
43.440002,59.881966,-430.842499,-0.000543,0.002141,0.054384,266.368286,13.569448,0.543844,-430.842499,0.055294,0.000000
43.870003,60.876198,-430.753540,-0.000517,0.002173,0.055191,270.790863,13.794744,0.551913,-430.753540,0.056015,0.000000
44.300003,62.188065,-430.753540,-0.000487,0.002198,0.055824,276.626312,14.092016,0.558242,-430.753540,0.056725,0.000000
44.730003,62.892593,-430.798004,-0.000461,0.002224,0.056492,279.760223,14.251665,0.564918,-430.798004,0.057446,0.000000
45.160004,64.147110,-430.842499,-0.000453,0.002253,0.057220,285.340607,14.535943,0.572200,-430.842499,0.058165,0.000000
45.590004,64.516144,-430.886963,-0.000410,0.002275,0.057776,286.982147,14.619568,0.577757,-430.886963,0.058876,0.000000
46.020000,66.640900,-430.931458,-0.000392,0.002311,0.058702,296.433533,15.101044,0.587022,-430.931458,0.059595,0.000000
46.450001,67.508148,-430.842499,-0.000358,0.002336,0.059344,300.291229,15.297565,0.593441,-430.842499,0.060316,0.000000
46.880001,68.920929,-430.931458,-0.000349,0.002367,0.060125,306.575592,15.617705,0.601253,-430.931458,0.061028,0.000000
47.310001,69.524551,-430.975922,-0.000319,0.002386,0.060602,309.260651,15.754489,0.606022,-430.975922,0.061747,0.000000
47.740002,71.419174,-430.931458,-0.000306,0.002421,0.061505,317.688354,16.183815,0.615045,-430.931458,0.062458,0.000000
48.170002,73.236359,-430.931458,-0.000272,0.002453,0.062302,325.771606,16.595596,0.623024,-430.931458,0.063177,0.000000
48.600002,73.957642,-430.975922,-0.000250,0.002475,0.062866,328.980011,16.759041,0.628656,-430.975922,0.063898,0.000000
49.030003,75.931595,-430.975922,-0.000229,0.002506,0.063663,337.760590,17.206345,0.636634,-430.975922,0.064608,0.000000
49.460003,76.681168,-431.064911,-0.000211,0.002526,0.064159,341.094879,17.376202,0.641585,-431.064911,0.065329,0.000000
49.890003,79.233780,-431.064911,-0.000177,0.002566,0.065180,352.449463,17.954632,0.651804,-431.064911,0.066048,0.000000
50.320004,80.218704,-431.064911,-0.000177,0.002588,0.065745,356.830627,18.177818,0.657451,-431.064911,0.066759,0.000000
50.750004,82.378098,-431.109375,-0.000147,0.002621,0.066569,366.436066,18.667143,0.665687,-431.109375,0.067479,0.000000
51.180004,83.553680,-431.109375,-0.000121,0.002644,0.067167,371.665344,18.933535,0.671667,-431.109375,0.068199,0.000000
51.610001,84.107025,-431.153870,-0.000121,0.002660,0.067557,374.126740,19.058926,0.675573,-431.153870,0.068911,0.000000
52.040001,87.547745,-431.153870,-0.000108,0.002706,0.068720,389.431824,19.838602,0.687201,-431.153870,0.069630,0.000000
52.470001,88.858871,-431.198334,-0.000091,0.002727,0.069258,395.264008,20.135708,0.692575,-431.198334,0.070349,0.000000
52.900002,91.205566,-431.198334,-0.000060,0.002759,0.070081,405.702637,20.667477,0.700811,-431.198334,0.071061,0.000000
53.330002,92.307785,-431.198334,-0.000056,0.002780,0.070602,410.605530,20.917242,0.706019,-431.198334,0.071781,0.000000
53.760002,94.688354,-431.287292,-0.000026,0.002814,0.071468,421.194824,21.456688,0.714679,-431.287292,0.072500,0.000000
54.190002,96.738647,-431.287292,-0.000009,0.002842,0.072189,430.315002,21.921289,0.721885,-431.287292,0.073212,0.000000
54.620003,98.843658,-431.287292,0.000000,0.002872,0.072961,439.678558,22.398293,0.729607,-431.287292,0.073931,0.000000
55.050003,100.297409,-431.287292,0.000013,0.002894,0.073515,446.145172,22.727718,0.735148,-431.287292,0.074643,0.000000
55.480003,101.681885,-431.287292,0.000022,0.002920,0.074166,452.303619,23.041445,0.741658,-431.287292,0.075362,0.000000
55.910004,105.063400,-431.331787,0.000030,0.002955,0.075059,467.345337,23.807707,0.750590,-431.331787,0.076082,0.000000
56.340004,106.911865,-431.376251,0.000056,0.002981,0.075708,475.567719,24.226576,0.757085,-431.376251,0.076794,0.000000
56.770004,109.510651,-431.420746,0.000056,0.003014,0.076550,487.127716,24.815468,0.765503,-431.420746,0.077513,0.000000
57.200005,111.155792,-431.376251,0.000086,0.003034,0.077053,494.445648,25.188263,0.770529,-431.376251,0.078232,0.000000
57.630001,113.838730,-431.376251,0.000099,0.003067,0.077911,506.379974,25.796227,0.779113,-431.376251,0.078944,0.000000
58.060001,115.820877,-431.376251,0.000095,0.003092,0.078546,515.197021,26.245386,0.785457,-431.376251,0.079664,0.000000
58.490002,118.110596,-431.509705,0.000121,0.003119,0.079230,525.382141,26.764244,0.792300,-431.509705,0.080384,0.000000
58.920002,120.401794,-431.509705,0.000108,0.003148,0.079958,535.573914,27.283438,0.799582,-431.509705,0.081095,0.000000
59.350002,122.548523,-431.465240,0.000134,0.003178,0.080721,545.123047,27.769892,0.807212,-431.465240,0.081814,0.000000
59.780003,125.724121,-431.509705,0.000147,0.003208,0.081493,559.248840,28.489492,0.814933,-431.509705,0.082535,0.000000
60.210003,127.550598,-431.509705,0.000151,0.003232,0.082084,567.373413,28.903379,0.820838,-431.509705,0.083245,0.000000
60.640003,130.224976,-431.643158,0.000168,0.003264,0.082898,579.269592,29.509401,0.828983,-431.643158,0.083966,0.000000
61.070004,132.318085,-431.598663,0.000172,0.003289,0.083531,588.580261,29.983707,0.835311,-431.598663,0.084676,0.000000
61.500004,134.847992,-431.643158,0.000177,0.003318,0.084268,599.833801,30.556992,0.842684,-431.643158,0.085396,0.000000
61.930004,137.495560,-431.598663,0.000177,0.003346,0.084989,611.610779,31.156939,0.849891,-431.598663,0.086115,0.000000
62.360004,139.874268,-431.598663,0.000198,0.003374,0.085708,622.191833,31.695963,0.857082,-431.598663,0.086827,0.000000
62.790005,142.621262,-431.643158,0.000203,0.003402,0.086420,634.411072,32.318439,0.864197,-431.643158,0.087546,0.000000
63.220001,143.956223,-431.687622,0.000224,0.003418,0.086827,640.349243,32.620945,0.868270,-431.687622,0.088267,0.000000
63.650002,147.978210,-431.732117,0.000216,0.003460,0.087885,658.239929,33.532341,0.878853,-431.732117,0.088978,0.000000
64.080002,150.550934,-431.687622,0.000233,0.003489,0.088632,669.684021,34.115330,0.886316,-431.687622,0.089697,0.000000
64.510002,153.294571,-431.687622,0.000233,0.003518,0.089367,681.888306,34.737049,0.893674,-431.687622,0.090418,0.000000
64.940002,155.544449,-431.821075,0.000241,0.003542,0.089967,691.896240,35.246876,0.899670,-431.821075,0.091128,0.000000
65.370003,158.715942,-431.865540,0.000233,0.003577,0.090860,706.003784,35.965549,0.908602,-431.865540,0.091849,0.000000
65.800003,160.971039,-431.821075,0.000254,0.003602,0.091502,716.034912,36.476559,0.915021,-431.821075,0.092568,0.000000
66.230003,163.449173,-431.732117,0.000254,0.003627,0.092135,727.058228,37.038109,0.921349,-431.732117,0.093279,0.000000
66.660004,166.231903,-431.821075,0.000272,0.003655,0.092845,739.436462,37.668686,0.928450,-431.821075,0.093999,0.000000
67.090004,168.420715,-431.865540,0.000263,0.003684,0.093582,749.172729,38.164680,0.935823,-431.865540,0.094719,0.000000
67.520004,171.931442,-431.865540,0.000280,0.003717,0.094424,764.789246,38.960220,0.944240,-431.865540,0.095429,0.000000
67.950005,174.077805,-431.954529,0.000263,0.003743,0.095066,774.336731,39.446594,0.950660,-431.954529,0.096150,0.000000
68.380005,177.496170,-431.910034,0.000276,0.003773,0.095838,789.542419,40.221207,0.958381,-431.910034,0.096862,0.000000
68.810005,179.682373,-431.954529,0.000293,0.003798,0.096480,799.267090,40.716610,0.964800,-431.954529,0.097581,0.000000
69.240005,182.708267,-431.998993,0.000297,0.003828,0.097234,812.726990,41.402287,0.972340,-431.998993,0.098300,0.000000
69.670006,185.265350,-431.998993,0.000297,0.003854,0.097885,824.101440,41.981728,0.978850,-431.998993,0.099011,0.000000
70.100006,187.458633,-431.998993,0.000319,0.003877,0.098474,833.857666,42.478737,0.984739,-431.998993,0.099732,0.000000
70.530006,190.893387,-431.998993,0.000302,0.003911,0.099332,849.136169,43.257061,0.993323,-431.998993,0.100451,0.000000
70.960007,192.473755,-432.043488,0.000306,0.003928,0.099767,856.166016,43.615177,0.997668,-432.043488,0.101163,0.000000
71.390007,196.782471,-432.087952,0.000332,0.003971,0.100858,875.332153,44.591545,1.008584,-432.087952,0.101882,0.000000
71.820000,198.596649,-432.176910,0.000323,0.003989,0.101328,883.402039,45.002644,1.013277,-432.176910,0.102602,0.000000
72.250000,202.427643,-432.087952,0.000328,0.004025,0.102247,900.443115,45.870758,1.022467,-432.087952,0.103312,0.000000
72.680000,204.721802,-432.132446,0.000332,0.004047,0.102793,910.648071,46.390625,1.027932,-432.132446,0.104033,0.000000
73.110001,206.882324,-432.176910,0.000341,0.004077,0.103556,920.258545,46.880207,1.035562,-432.176910,0.104752,0.000000
73.540001,211.028687,-432.221405,0.000354,0.004107,0.104310,938.702454,47.819786,1.043102,-432.221405,0.105464,0.000000
73.970001,213.342224,-432.176910,0.000341,0.004134,0.105013,948.993591,48.344040,1.050127,-432.176910,0.106183,0.000000
74.400002,216.593781,-432.221405,0.000349,0.004161,0.105680,963.457275,49.080853,1.056803,-432.221405,0.106895,0.000000
74.830002,218.826904,-432.265869,0.000341,0.004184,0.106262,973.390686,49.586884,1.062617,-432.265869,0.107615,0.000000
75.260002,220.596802,-432.176910,0.000354,0.004191,0.106462,981.263611,49.987953,1.064615,-432.176910,0.018696,0.000000
75.690002,220.313416,-432.354858,0.000362,0.004189,0.106392,980.002991,49.923733,1.063919,-432.354858,982.000671,0.000000
76.120003,220.007721,-432.354858,0.000362,0.004189,0.106392,978.643250,49.854462,1.063919,-432.354858,982.000671,0.000000
76.550003,219.725830,-432.354858,0.000362,0.004192,0.106469,977.389282,49.790585,1.064691,-432.354858,982.000671,0.000000
76.980003,219.747803,-432.310364,0.000358,0.004199,0.106660,977.487061,49.795567,1.066599,-432.310364,982.000671,0.000000
77.410004,219.706085,-432.399323,0.000358,0.004202,0.106722,977.301453,49.786110,1.067219,-432.399323,982.000671,0.000000
77.840004,219.682251,-432.399323,0.000358,0.004203,0.106764,977.195435,49.780708,1.067643,-432.399323,982.000671,0.000000
78.270004,219.681519,-432.354858,0.000366,0.004205,0.106817,977.192200,49.780544,1.068173,-432.354858,982.000671,0.000000
78.700005,219.662506,-432.443817,0.000354,0.004207,0.106860,977.107605,49.776234,1.068597,-432.443817,982.000671,0.000000
79.130005,219.641663,-432.399323,0.000379,0.004209,0.106920,977.014893,49.771515,1.069203,-432.399323,982.000671,0.000000
79.560005,219.652832,-432.488281,0.000366,0.004210,0.106946,977.064575,49.774044,1.069460,-432.488281,982.000671,0.000000
79.990005,219.621918,-432.532776,0.000366,0.004212,0.106973,976.927063,49.767040,1.069732,-432.532776,982.000671,0.000000
80.420006,219.519165,-432.532776,0.000366,0.004212,0.106973,976.470032,49.743755,1.069732,-432.532776,982.000671,0.000000
80.850006,219.550446,-432.488281,0.000379,0.004214,0.107034,976.609131,49.750843,1.070338,-432.488281,982.000671,0.000000
81.280006,219.478943,-432.577240,0.000371,0.004214,0.107041,976.291077,49.734638,1.070414,-432.577240,982.000671,0.000000
81.710007,219.793976,-432.621735,0.000358,0.004219,0.107172,977.692444,49.806026,1.071716,-432.621735,982.000671,0.000000
82.140007,219.746674,-432.577240,0.000388,0.004219,0.107172,977.481995,49.795307,1.071716,-432.577240,982.000671,0.000000
82.570007,219.645020,-432.710693,0.000366,0.004219,0.107172,977.029846,49.772274,1.071716,-432.710693,982.000671,0.000000
83.000008,219.557892,-432.621735,0.000379,0.004220,0.107181,976.642273,49.752529,1.071807,-432.621735,982.000671,0.000000
83.430000,219.479309,-432.621735,0.000379,0.004220,0.107181,976.292725,49.734722,1.071807,-432.621735,982.000671,0.000000
83.860001,219.860992,-432.710693,0.000379,0.004226,0.107329,977.990540,49.821213,1.073290,-432.710693,982.000671,0.000000
84.290001,219.829346,-432.755188,0.000384,0.004226,0.107329,977.849792,49.814041,1.073290,-432.755188,982.000671,0.000000
84.720001,219.757843,-432.755188,0.000371,0.004226,0.107329,977.531677,49.797836,1.073290,-432.755188,982.000671,0.000000
85.150002,219.661407,-432.755188,0.000366,0.004226,0.107329,977.102722,49.775986,1.073290,-432.755188,982.000671,0.000000
85.580002,219.593628,-432.799652,0.000362,0.004226,0.107337,976.801270,49.760628,1.073366,-432.799652,982.000671,0.000000
86.010002,219.511719,-432.755188,0.000371,0.004226,0.107346,976.436890,49.742065,1.073457,-432.755188,982.000671,0.000000
86.440002,219.585052,-432.844147,0.000366,0.004229,0.107415,976.763123,49.758686,1.074153,-432.844147,982.000671,0.000000
86.870003,219.586548,-432.844147,0.000371,0.004229,0.107424,976.769775,49.759022,1.074244,-432.844147,982.000671,0.000000
87.300003,219.562714,-432.933105,0.000371,0.004230,0.107432,976.663757,49.753624,1.074320,-432.933105,982.000671,0.000000
87.730003,219.535156,-432.844147,0.000379,0.004232,0.107485,976.541138,49.747379,1.074850,-432.844147,982.000671,0.000000
88.160004,219.895264,-432.933105,0.000379,0.004235,0.107562,978.143005,49.828976,1.075622,-432.933105,982.000671,0.000000
88.590004,219.879974,-433.022064,0.000384,0.004235,0.107562,978.074951,49.825516,1.075622,-433.022064,982.000671,0.000000
89.020004,219.840881,-432.977570,0.000379,0.004235,0.107562,977.901062,49.816654,1.075622,-432.977570,982.000671,0.000000
89.450005,219.806610,-432.933105,0.000362,0.004235,0.107562,977.748657,49.808891,1.075622,-432.933105,982.000671,0.000000
89.880005,219.743683,-433.022064,0.000392,0.004235,0.107562,977.468750,49.794628,1.075622,-433.022064,982.000671,0.000000
90.310005,219.675171,-433.066528,0.000388,0.004235,0.107562,977.163940,49.779106,1.075622,-433.066528,982.000671,0.000000
90.740005,219.621552,-433.111023,0.000379,0.004235,0.107571,976.925476,49.766956,1.075713,-433.111023,982.000671,0.000000
91.170006,219.605164,-433.111023,0.000384,0.004236,0.107606,976.852539,49.763241,1.076061,-433.111023,982.000671,0.000000
91.600006,219.594360,-433.066528,0.000375,0.004236,0.107606,976.804504,49.760792,1.076061,-433.066528,982.000671,0.000000
92.030006,219.561218,-433.111023,0.000388,0.004237,0.107615,976.657104,49.753284,1.076152,-433.111023,982.000671,0.000000
92.460007,219.624176,-433.155487,0.000397,0.004240,0.107701,976.937134,49.767548,1.077015,-433.155487,982.000671,0.000000
92.890007,219.763428,-433.155487,0.000366,0.004241,0.107711,977.556580,49.799103,1.077105,-433.155487,982.000671,0.000000
93.320007,219.755615,-433.155487,0.000379,0.004241,0.107711,977.521790,49.797337,1.077105,-433.155487,982.000671,0.000000
93.750008,219.717621,-433.199982,0.000397,0.004241,0.107711,977.352783,49.788723,1.077105,-433.199982,982.000671,0.000000
94.180008,219.691193,-433.244476,0.000397,0.004241,0.107711,977.235229,49.782734,1.077105,-433.244476,982.000671,0.000000
94.610008,219.639801,-433.288940,0.000392,0.004241,0.107711,977.006653,49.771091,1.077105,-433.288940,982.000671,0.000000
95.040001,219.617096,-433.377899,0.000388,0.004241,0.107711,976.905640,49.765945,1.077105,-433.377899,982.000671,0.000000
95.470001,219.583954,-433.333435,0.000392,0.004241,0.107718,976.758240,49.758434,1.077181,-433.333435,982.000671,0.000000
95.900002,219.679260,-433.288940,0.000388,0.004243,0.107779,977.182129,49.780029,1.077787,-433.288940,982.000671,0.000000
96.330002,219.685242,-433.333435,0.000397,0.004243,0.107779,977.208740,49.781387,1.077787,-433.333435,982.000671,0.000000
96.760002,219.661774,-433.377899,0.000401,0.004243,0.107779,977.104370,49.776070,1.077787,-433.377899,982.000671,0.000000
97.190002,219.637573,-433.422394,0.000379,0.004243,0.107779,976.996704,49.770584,1.077787,-433.422394,982.000671,0.000000
97.620003,219.606293,-433.377899,0.000392,0.004243,0.107779,976.857605,49.763496,1.077787,-433.377899,982.000671,0.000000
98.050003,219.579102,-433.422394,0.000384,0.004243,0.107779,976.736633,49.757336,1.077787,-433.422394,982.000671,0.000000
98.480003,219.539642,-433.466858,0.000401,0.004244,0.107788,976.561096,49.748394,1.077878,-433.466858,982.000671,0.000000
98.910004,219.510956,-433.422394,0.000397,0.004245,0.107832,976.433472,49.741894,1.078317,-433.422394,982.000671,0.000000
99.340004,219.572418,-433.511353,0.000392,0.004246,0.107839,976.706909,49.755821,1.078392,-433.511353,982.000671,0.000000
99.770004,219.554535,-433.555817,0.000401,0.004246,0.107839,976.627319,49.751770,1.078392,-433.555817,982.000671,0.000000
100.200005,219.550812,-433.511353,0.000384,0.004246,0.107839,976.610779,49.750923,1.078392,-433.511353,982.000671,0.000000
100.630005,219.535156,-433.555817,0.000388,0.004246,0.107839,976.541138,49.747379,1.078392,-433.555817,982.000671,0.000000
101.060005,219.520264,-433.644806,0.000401,0.004246,0.107848,976.474915,49.743999,1.078483,-433.644806,982.000671,0.000000
101.490005,219.490479,-433.644806,0.000388,0.004246,0.107848,976.342407,49.737255,1.078483,-433.644806,982.000671,0.000000
101.920006,219.461426,-433.644806,0.000384,0.004246,0.107848,976.213196,49.730667,1.078483,-433.644806,982.000671,0.000000
102.350006,219.442444,-433.600311,0.000397,0.004246,0.107848,976.128723,49.726368,1.078483,-433.600311,982.000671,0.000000
102.780006,219.398865,-433.600311,0.000397,0.004246,0.107848,975.934875,49.716492,1.078483,-433.600311,982.000671,0.000000
103.210007,219.573517,-433.689270,0.000397,0.004251,0.107969,976.711792,49.756069,1.079694,-433.689270,982.000671,0.000000
103.640007,219.689331,-433.733765,0.000397,0.004251,0.107969,977.226929,49.782314,1.079694,-433.733765,982.000671,0.000000
104.070007,219.704956,-433.778229,0.000401,0.004251,0.107969,977.296448,49.785858,1.079694,-433.778229,982.000671,0.000000
104.500008,219.713531,-433.733765,0.000397,0.004251,0.107969,977.334595,49.787796,1.079694,-433.733765,982.000671,0.000000
104.930008,219.704224,-433.600311,0.000405,0.004251,0.107969,977.293213,49.785686,1.079694,-433.600311,982.000671,0.000000
105.360008,219.679260,-433.822723,0.000410,0.004251,0.107969,977.182129,49.780029,1.079694,-433.822723,982.000671,0.000000
105.790009,219.655060,-433.867187,0.000401,0.004251,0.107969,977.074524,49.774548,1.079694,-433.867187,982.000671,0.000000
106.220009,219.633850,-433.822723,0.000384,0.004251,0.107969,976.980164,49.769741,1.079694,-433.822723,982.000671,0.000000
106.650002,219.611877,-433.911682,0.000397,0.004251,0.107969,976.882446,49.764763,1.079694,-433.911682,982.000671,0.000000
107.080002,219.598083,-433.867187,0.000405,0.004251,0.107969,976.821045,49.761635,1.079694,-433.867187,982.000671,0.000000
107.510002,219.578735,-434.000641,0.000392,0.004251,0.107969,976.734985,49.757252,1.079694,-434.000641,982.000671,0.000000
107.940002,219.547821,-434.000641,0.000414,0.004251,0.107969,976.597473,49.750248,1.079694,-434.000641,982.000671,0.000000
108.370003,219.532562,-433.911682,0.000397,0.004251,0.107969,976.529602,49.746792,1.079694,-433.911682,982.000671,0.000000
108.800003,219.513580,-433.956146,0.000384,0.004251,0.107969,976.445190,49.742489,1.079694,-433.956146,982.000671,0.000000
109.230003,219.484528,-433.956146,0.000410,0.004251,0.107979,976.315918,49.735909,1.079785,-433.956146,982.000671,0.000000
109.660004,219.460327,-434.000641,0.000410,0.004251,0.107979,976.208313,49.730423,1.079785,-434.000641,982.000671,0.000000
110.090004,219.449524,-434.045135,0.000410,0.004252,0.107997,976.160217,49.727974,1.079967,-434.045135,982.000671,0.000000
110.520004,219.588776,-434.045135,0.000401,0.004255,0.108083,976.779663,49.759529,1.080830,-434.045135,982.000671,0.000000
110.950005,219.668488,-433.956146,0.000405,0.004255,0.108083,977.134216,49.777588,1.080830,-433.956146,982.000671,0.000000
111.380005,219.672943,-434.089600,0.000405,0.004255,0.108083,977.154053,49.778599,1.080830,-434.089600,982.000671,0.000000
111.810005,219.666626,-434.045135,0.000410,0.004255,0.108083,977.125977,49.777172,1.080830,-434.045135,982.000671,0.000000
112.240005,219.662903,-434.134094,0.000397,0.004255,0.108083,977.109375,49.776325,1.080830,-434.134094,982.000671,0.000000
112.670006,219.647980,-434.134094,0.000401,0.004255,0.108083,977.043030,49.772942,1.080830,-434.134094,982.000671,0.000000
113.100006,219.639069,-434.178558,0.000410,0.004255,0.108083,977.003357,49.770924,1.080830,-434.178558,982.000671,0.000000
113.530006,219.622314,-434.178558,0.000418,0.004255,0.108083,976.928833,49.767128,1.080830,-434.178558,982.000671,0.000000
113.960007,219.615601,-434.223053,0.000405,0.004255,0.108083,976.898987,49.765606,1.080830,-434.223053,982.000671,0.000000
114.390007,219.599213,-434.223053,0.000405,0.004255,0.108083,976.826111,49.761894,1.080830,-434.223053,982.000671,0.000000
114.820007,219.587677,-434.267517,0.000401,0.004255,0.108083,976.774780,49.759277,1.080830,-434.267517,982.000671,0.000000
115.250008,219.568665,-434.223053,0.000401,0.004255,0.108083,976.690186,49.754971,1.080830,-434.223053,982.000671,0.000000
115.680008,219.547455,-434.223053,0.000405,0.004255,0.108083,976.595825,49.750164,1.080830,-434.223053,982.000671,0.000000
116.110008,219.534790,-434.356476,0.000401,0.004255,0.108083,976.539490,49.747295,1.080830,-434.356476,982.000671,0.000000
116.540009,219.520264,-434.312012,0.000414,0.004255,0.108083,976.474915,49.743999,1.080830,-434.312012,982.000671,0.000000
116.970009,219.496063,-434.356476,0.000392,0.004255,0.108083,976.367249,49.738522,1.080830,-434.356476,982.000671,0.000000
117.400009,219.479309,-434.312012,0.000384,0.004256,0.108092,976.292725,49.734722,1.080921,-434.312012,982.000671,0.000000
117.830002,219.460693,-434.356476,0.000410,0.004256,0.108092,976.209900,49.730503,1.080921,-434.356476,982.000671,0.000000
118.260002,219.517303,-434.400970,0.000397,0.004258,0.108153,976.461731,49.743332,1.081526,-434.400970,982.000671,0.000000
118.690002,219.554901,-434.400970,0.000401,0.004258,0.108153,976.628967,49.751854,1.081526,-434.400970,982.000671,0.000000
119.120003,219.567932,-434.400970,0.000392,0.004258,0.108153,976.686951,49.754803,1.081526,-434.400970,982.000671,0.000000
119.550003,219.567566,-434.489929,0.000405,0.004258,0.108153,976.685303,49.754723,1.081526,-434.489929,982.000671,0.000000
119.980003,219.558624,-434.445435,0.000405,0.004258,0.108153,976.645508,49.752697,1.081526,-434.445435,982.000671,0.000000
120.410004,219.542999,-434.489929,0.000405,0.004258,0.108153,976.576050,49.749153,1.081526,-434.489929,982.000671,0.000000
120.840004,219.531433,-434.534424,0.000401,0.004258,0.108153,976.524597,49.746532,1.081526,-434.534424,982.000671,0.000000
121.270004,219.525116,-434.489929,0.000388,0.004259,0.108178,976.496460,49.745102,1.081784,-434.489929,982.000671,0.000000
121.700005,219.535156,-434.534424,0.000405,0.004259,0.108178,976.541138,49.747379,1.081784,-434.534424,982.000671,0.000000
122.130005,219.526215,-434.534424,0.000401,0.004259,0.108178,976.501343,49.745354,1.081784,-434.534424,982.000671,0.000000
122.560005,219.526215,-434.578888,0.000431,0.004259,0.108178,976.501343,49.745354,1.081784,-434.578888,982.000671,0.000000
122.990005,219.506134,-434.667847,0.000414,0.004259,0.108178,976.412048,49.740799,1.081784,-434.667847,982.000671,0.000000
123.420006,219.502777,-434.667847,0.000405,0.004259,0.108178,976.397095,49.740040,1.081784,-434.667847,982.000671,0.000000
123.850006,219.523621,-434.667847,0.000414,0.004260,0.108195,976.489807,49.744766,1.081950,-434.667847,982.000671,0.000000
124.280006,219.514313,-434.667847,0.000410,0.004260,0.108195,976.448425,49.742653,1.081950,-434.667847,982.000671,0.000000
124.710007,219.518036,-434.712341,0.000410,0.004260,0.108195,976.464966,49.743500,1.081950,-434.712341,982.000671,0.000000
125.140007,219.502777,-434.712341,0.000405,0.004260,0.108195,976.397095,49.740040,1.081950,-434.712341,982.000671,0.000000
125.570007,219.502014,-434.756805,0.000414,0.004260,0.108195,976.393738,49.739868,1.081950,-434.756805,982.000671,0.000000
126.000008,219.484894,-434.756805,0.000405,0.004260,0.108195,976.317566,49.735989,1.081950,-434.756805,982.000671,0.000000
126.430008,219.687836,-434.845764,0.000418,0.004264,0.108299,977.220276,49.781975,1.082995,-434.845764,982.000671,0.000000
126.860008,219.757843,-434.890259,0.000405,0.004264,0.108299,977.531677,49.797836,1.082995,-434.890259,982.000671,0.000000
127.290009,219.777588,-434.845764,0.000410,0.004264,0.108299,977.619507,49.802311,1.082995,-434.845764,982.000671,0.000000
127.720009,219.790619,-434.890259,0.000414,0.004264,0.108299,977.677490,49.805267,1.082995,-434.890259,982.000671,0.000000
128.150009,219.779083,-434.845764,0.000401,0.004264,0.108299,977.626160,49.802654,1.082995,-434.845764,982.000671,0.000000
128.580002,219.780182,-434.890259,0.000414,0.004264,0.108299,977.631104,49.802898,1.082995,-434.890259,982.000671,0.000000
129.010010,219.785400,-434.934753,0.000405,0.004264,0.108299,977.654297,49.804081,1.082995,-434.934753,982.000671,0.000000
129.440002,219.776825,-435.023712,0.000392,0.004264,0.108299,977.616150,49.802139,1.082995,-435.023712,982.000671,0.000000
129.870010,219.768646,-435.023712,0.000423,0.004264,0.108299,977.579773,49.800285,1.082995,-435.023712,982.000671,0.000000
130.300003,219.759338,-434.979218,0.000410,0.004264,0.108299,977.538330,49.798180,1.082995,-434.979218,982.000671,0.000000
130.730011,219.748901,-435.023712,0.000427,0.004264,0.108299,977.491943,49.795811,1.082995,-435.023712,982.000671,0.000000
131.160004,219.737732,-435.023712,0.000431,0.004264,0.108299,977.442261,49.793282,1.082995,-435.023712,982.000671,0.000000
131.590012,219.731781,-435.068176,0.000410,0.004264,0.108299,977.415771,49.791935,1.082995,-435.068176,982.000671,0.000000
132.020004,219.704956,-435.068176,0.000410,0.004264,0.108299,977.296448,49.785858,1.082995,-435.068176,982.000671,0.000000
132.450012,219.690826,-435.068176,0.000410,0.004264,0.108299,977.233582,49.782650,1.082995,-435.068176,982.000671,0.000000
132.880005,219.684845,-435.112671,0.000401,0.004264,0.108299,977.206970,49.781296,1.082995,-435.112671,982.000671,0.000000
133.310013,219.667725,-435.157135,0.000405,0.004264,0.108299,977.130859,49.777416,1.082995,-435.157135,982.000671,0.000000
133.740005,219.652100,-435.157135,0.000414,0.004264,0.108299,977.061340,49.773876,1.082995,-435.157135,982.000671,0.000000
134.170013,219.635345,-435.246094,0.000401,0.004264,0.108299,976.986816,49.770081,1.082995,-435.246094,982.000671,0.000000
134.600006,219.632355,-435.157135,0.000397,0.004264,0.108299,976.973511,49.769402,1.082995,-435.157135,982.000671,0.000000
135.030014,219.609253,-435.201630,0.000423,0.004264,0.108299,976.870728,49.764168,1.082995,-435.201630,982.000671,0.000000
135.460007,219.606659,-435.246094,0.000418,0.004264,0.108299,976.859192,49.763580,1.082995,-435.246094,982.000671,0.000000
135.889999,219.569061,-435.246094,0.000414,0.004249,0.107918,976.691956,49.755062,1.079180,-435.246094,0.108127,0.000000
136.320007,219.433502,-435.335083,0.000435,0.004237,0.107615,976.088989,49.724342,1.076152,-435.335083,0.107406,0.000000
136.750000,219.162048,-435.246094,0.000431,0.004212,0.106973,974.881470,49.662830,1.069732,-435.246094,0.106687,0.000000
137.180008,218.598267,-435.335083,0.000423,0.004190,0.106436,972.373657,49.535072,1.064358,-435.335083,0.105976,0.000000
137.610001,217.424561,-435.335083,0.000435,0.004160,0.105671,967.152771,49.269108,1.056712,-435.335083,0.105255,0.000000
138.040009,216.928192,-435.379547,0.000440,0.004135,0.105038,964.944763,49.156631,1.050384,-435.379547,0.104545,0.000000
138.470001,216.672363,-435.424042,0.000457,0.004110,0.104389,963.806824,49.098660,1.043889,-435.424042,0.103824,0.000000
138.900009,216.448212,-435.424042,0.000431,0.004078,0.103582,962.809753,49.047867,1.035820,-435.424042,0.103105,0.000000
139.330002,216.105255,-435.424042,0.000444,0.004052,0.102914,961.284180,48.970150,1.029143,-435.424042,0.102394,0.000000
139.760010,215.747406,-435.379547,0.000466,0.004022,0.102160,959.692383,48.889061,1.021604,-435.379547,0.101674,0.000000
140.190002,215.025726,-435.513000,0.000440,0.004002,0.101640,956.482178,48.725525,1.016396,-435.513000,0.100954,0.000000
140.620010,213.616302,-435.468506,0.000448,0.003971,0.100858,950.212769,48.406147,1.008584,-435.468506,0.100244,0.000000
141.050003,212.945282,-435.601959,0.000453,0.003946,0.100235,947.227905,48.254089,1.002346,-435.601959,0.099523,0.000000
141.480011,210.717773,-435.513000,0.000423,0.003910,0.099316,937.319458,47.749329,0.993156,-435.513000,0.098804,0.000000
141.910004,209.063293,-435.513000,0.000453,0.003889,0.098778,929.959961,47.374420,0.987782,-435.513000,0.098092,0.000000
142.340012,207.280762,-435.601959,0.000435,0.003869,0.098266,922.030884,46.970490,0.982665,-435.601959,0.097373,0.000000
142.770004,204.009460,-435.601959,0.000448,0.003836,0.097425,907.479431,46.229206,0.974247,-435.601959,0.096653,0.000000
143.200012,201.190979,-435.646423,0.000448,0.003810,0.096774,894.942200,45.590527,0.967737,-435.646423,0.095941,0.000000
143.630005,197.524597,-435.646423,0.000440,0.003778,0.095959,878.633301,44.759712,0.959592,-435.646423,0.095222,0.000000
144.060013,195.072144,-435.646423,0.000453,0.003757,0.095422,867.724243,44.203979,0.954217,-435.646423,0.094510,0.000000
144.490005,191.420288,-435.735382,0.000448,0.003724,0.094589,851.479980,43.376457,0.945891,-435.735382,0.093791,0.000000
144.920013,188.585052,-435.735382,0.000457,0.003698,0.093929,838.868225,42.733986,0.939290,-435.735382,0.093071,0.000000
145.350006,185.424362,-435.779877,0.000444,0.003666,0.093124,824.808777,42.017761,0.931236,-435.779877,0.092361,0.000000
145.780014,182.157166,-435.779877,0.000444,0.003639,0.092421,810.275513,41.277401,0.924211,-435.779877,0.091640,0.000000
146.210007,179.594864,-435.824371,0.000440,0.003616,0.091849,798.877869,40.696781,0.918488,-435.824371,0.090921,0.000000
146.639999,176.305695,-435.779877,0.000453,0.003588,0.091137,784.246887,39.951439,0.911372,-435.779877,0.090209,0.000000
147.070007,172.526123,-435.868835,0.000444,0.003553,0.090244,767.434509,39.094978,0.902440,-435.868835,0.089490,0.000000
147.500000,169.260788,-435.824371,0.000435,0.003528,0.089611,752.909607,38.355042,0.896112,-435.824371,0.088769,0.000000
147.930008,166.420700,-435.824371,0.000440,0.003503,0.088969,740.276245,37.711472,0.889693,-435.824371,0.088058,0.000000
148.360001,162.457916,-435.868835,0.000448,0.003469,0.088111,722.648926,36.813492,0.881108,-435.868835,0.087339,0.000000
148.790009,159.787628,-435.913330,0.000435,0.003446,0.087539,710.770874,36.208393,0.875386,-435.913330,0.086620,0.000000
149.220001,155.680740,-436.002289,0.000431,0.003412,0.086671,692.502502,35.277760,0.866711,-436.002289,0.085908,0.000000
149.650009,152.098511,-436.002289,0.000410,0.003384,0.085950,676.567993,34.466019,0.859504,-436.002289,0.085187,0.000000
150.080002,149.379822,-436.002289,0.000423,0.003358,0.085301,664.474609,33.849953,0.853009,-436.002289,0.084468,0.000000
150.510010,146.462662,-436.046753,0.000431,0.003335,0.084720,651.498474,33.188915,0.847196,-436.046753,0.083757,0.000000
150.940002,143.002197,-435.957794,0.000427,0.003305,0.083940,636.105530,32.404762,0.839399,-435.957794,0.083038,0.000000
151.370010,138.846527,-436.046753,0.000414,0.003270,0.083047,617.620178,31.463072,0.830467,-436.046753,0.082326,0.000000
151.800003,136.369873,-436.046753,0.000397,0.003248,0.082508,606.603516,30.901855,0.825077,-436.046753,0.081607,0.000000
152.230011,132.313614,-436.091248,0.000392,0.003214,0.081642,588.560364,29.982695,0.816417,-436.091248,0.080886,0.000000
152.660004,129.030777,-436.091248,0.000410,0.003186,0.080921,573.957581,29.238792,0.809211,-436.091248,0.080176,0.000000
153.090012,125.731186,-436.135712,0.000401,0.003158,0.080202,559.280273,28.491093,0.802019,-436.135712,0.079456,0.000000
153.520004,122.840836,-436.180206,0.000401,0.003133,0.079586,546.423340,27.836132,0.795857,-436.180206,0.078736,0.000000
153.950012,119.683487,-436.180206,0.000388,0.003105,0.078874,532.378723,27.120667,0.788742,-436.180206,0.078025,0.000000
154.380005,116.711960,-436.224701,0.000379,0.003080,0.078241,519.160706,26.447308,0.782413,-436.224701,0.077304,0.000000
154.810013,113.485718,-436.224701,0.000379,0.003052,0.077513,504.809692,25.716232,0.775131,-436.224701,0.076585,0.000000
155.240005,109.255569,-436.224701,0.000392,0.003014,0.076550,485.993042,24.757666,0.765503,-436.224701,0.075874,0.000000
155.670013,106.906647,-436.269165,0.000379,0.002993,0.076029,475.544525,24.225393,0.760295,-436.269165,0.075154,0.000000
156.100006,103.849472,-436.313660,0.000366,0.002964,0.075276,461.945526,23.532627,0.752755,-436.313660,0.074434,0.000000
156.530014,99.985733,-436.180206,0.000384,0.002932,0.074461,444.758759,22.657089,0.744610,-436.180206,0.073724,0.000000
156.960007,97.582809,-436.358124,0.000366,0.002911,0.073931,434.070007,22.112581,0.739311,-436.358124,0.073003,0.000000
157.390015,94.049744,-436.358124,0.000349,0.002880,0.073151,418.354156,21.311977,0.731514,-436.358124,0.072293,0.000000
157.820007,90.852173,-436.313660,0.000371,0.002851,0.072423,404.130646,20.587397,0.724232,-436.313660,0.071572,0.000000
158.250000,87.659454,-436.447083,0.000341,0.002825,0.071763,389.928741,19.863916,0.717631,-436.447083,0.070853,0.000000
158.680008,84.752716,-436.402618,0.000354,0.002798,0.071079,376.998901,19.205240,0.710788,-436.402618,0.070142,0.000000
159.110001,80.670029,-436.358124,0.000349,0.002762,0.070167,358.838196,18.280090,0.701674,-436.358124,0.069423,0.000000
159.540009,78.112198,-436.358124,0.000341,0.002740,0.069586,347.460419,17.700478,0.695861,-436.358124,0.068702,0.000000
159.970001,74.997299,-436.491577,0.000341,0.002713,0.068902,333.604645,16.994631,0.689017,-436.491577,0.067990,0.000000
160.400009,71.227036,-436.447083,0.000332,0.002679,0.068034,316.833679,16.140276,0.680342,-436.447083,0.067271,0.000000
160.830002,68.929871,-436.491577,0.000319,0.002658,0.067523,306.615387,15.619732,0.675225,-436.491577,0.066552,0.000000
161.260010,65.521164,-436.491577,0.000319,0.002627,0.066734,291.452698,14.847308,0.667338,-436.491577,0.065841,0.000000
161.690002,62.756676,-436.536041,0.000319,0.002603,0.066108,279.155640,14.220865,0.661085,-436.536041,0.065120,0.000000
162.120010,59.188232,-436.536041,0.000319,0.002573,0.065345,263.282410,13.412245,0.653455,-436.536041,0.064401,0.000000
162.550003,56.348892,-436.625031,0.000323,0.002546,0.064678,250.652390,12.768842,0.646778,-436.625031,0.063689,0.000000
162.980011,52.313118,-436.625031,0.000306,0.002508,0.063715,232.700363,11.854322,0.637149,-436.625031,0.062970,0.000000
163.410004,49.575066,-436.536041,0.000302,0.002486,0.063143,220.520905,11.233871,0.631426,-436.536041,0.062258,0.000000
163.840012,47.225769,-436.625031,0.000285,0.002462,0.062536,210.070709,10.701511,0.625355,-436.625031,0.061539,0.000000
164.270004,43.568321,-436.669495,0.000319,0.002431,0.061756,193.801575,9.872723,0.617559,-436.669495,0.060819,0.000000
164.700012,40.706268,-436.713989,0.000297,0.002405,0.061096,181.070526,9.224172,0.610958,-436.713989,0.060107,0.000000
165.130005,37.300179,-436.713989,0.000285,0.002376,0.060351,165.919479,8.452341,0.603509,-436.713989,0.059388,0.000000
165.560013,34.820175,-436.713989,0.000276,0.002353,0.059779,154.887878,7.890365,0.597786,-436.713989,0.058669,0.000000
165.990005,30.974312,-436.669495,0.000293,0.002319,0.058902,137.780624,7.018879,0.589020,-436.669495,0.057957,0.000000
166.420013,28.215034,-436.713989,0.000285,0.002292,0.058225,125.506744,6.393618,0.582253,-436.713989,0.057237,0.000000
166.850006,24.516258,-436.847412,0.000276,0.002258,0.057341,109.053764,5.555464,0.573412,-436.847412,0.056518,0.000000
167.280014,22.193771,-436.847412,0.000263,0.002236,0.056804,98.722824,5.029181,0.568037,-436.847412,0.055806,0.000000
167.710007,19.348099,-436.758453,0.000259,0.002212,0.056197,86.064644,4.384342,0.561966,-436.758453,0.055087,0.000000
168.140015,15.483994,-436.802948,0.000259,0.002176,0.055259,68.876244,3.508723,0.552595,-436.802948,0.054366,0.000000
168.570007,12.090187,-436.847412,0.000263,0.002145,0.054471,53.779839,2.739676,0.544707,-436.847412,0.053656,0.000000
169.000015,9.757652,-436.891907,0.000254,0.002123,0.053917,43.404205,2.211116,0.539166,-436.891907,0.052936,0.000000
169.430008,7.028908,-436.936371,0.000254,0.002097,0.053266,31.266144,1.592773,0.532656,-436.936371,0.052216,0.000000
169.860001,3.505516,-436.936371,0.000241,0.002064,0.052416,15.593314,0.794361,0.524163,-436.936371,0.051505,0.000000
170.290009,1.522263,-436.936371,0.000246,0.002042,0.051861,6.771362,0.344950,0.518606,-436.936371,0.050786,0.000000
170.720001,-1.754616,-436.980865,0.000250,0.002003,0.050872,-7.804921,-0.397602,0.508720,-436.980865,0.050074,0.000000
171.150009,-0.367905,-436.980865,0.000233,0.001985,0.050412,-1.636522,-0.083368,0.504118,-436.980865,0.049354,0.000000
171.580002,-0.414818,-437.025330,0.000207,0.001958,0.049727,-1.845202,-0.093999,0.497275,-437.025330,0.048634,0.000000
172.010010,-0.103516,-436.980865,0.000134,0.001929,0.048999,-0.460460,-0.023457,0.489992,-436.980865,0.047923,0.000000
172.440002,-0.129959,-437.069824,0.000103,0.001899,0.048244,-0.578087,-0.029449,0.482438,-437.069824,0.047204,0.000000
172.870010,-0.087875,-437.069824,0.000073,0.001867,0.047420,-0.390889,-0.019913,0.474202,-437.069824,0.046483,0.000000
173.300003,-0.100166,-437.114319,0.000022,0.001842,0.046796,-0.445562,-0.022698,0.467964,-437.114319,0.045773,0.000000
173.730011,-0.076706,-437.114319,-0.000017,0.001824,0.046320,-0.341205,-0.017382,0.463195,-437.114319,0.045052,0.000000
174.160004,-0.105751,-437.158783,-0.000069,0.001783,0.045278,-0.470404,-0.023964,0.452779,-437.158783,0.044333,0.000000
174.590012,-0.114319,-437.114319,-0.000116,0.001749,0.044420,-0.508516,-0.025905,0.444195,-437.114319,0.043622,0.000000
175.020004,-0.100166,-437.158783,-0.000134,0.001730,0.043952,-0.445562,-0.022698,0.439517,-437.158783,0.042903,0.000000
175.450012,-0.097191,-437.158783,-0.000190,0.001699,0.043163,-0.432327,-0.022024,0.431629,-437.158783,0.042182,0.000000
175.800003,-0.041702,-437.203278,-0.000220,0.001689,0.042903,-0.185501,-0.009450,0.429025,-437.203278,0.042763,0.000000