File: Data/sima compression 500bar/P1-21-500bar-2_11072024_162442.csv
Time (sec),S:Load (lbs),S:HL1 (DIM),S:LVDT (in),S:Position (in),Ch:Position (mm),Ch:Load (N),Ch:Stress (MPa),Ch:Strain (mm/mm),Ch:HL1 (DIM),Set Point (),Cycles ()
0.010000,-0.000374,-203.411392,-0.005575,-0.005528,-0.140421,-0.001663,-0.000085,-1.404211,-203.411392,-0.140551,0.000000
0.450000,-0.003723,-203.411392,-0.005570,-0.005473,-0.139025,-0.016561,-0.000844,-1.390252,-203.411392,-0.138436,0.000000
0.890000,0.049530,-203.455872,-0.005450,-0.005211,-0.132356,0.220321,0.011224,-1.323563,-203.455872,-0.131100,0.000000
1.330000,0.005219,-203.500351,-0.005161,-0.004910,-0.124717,0.023213,0.001183,-1.247168,-203.500351,-0.123780,0.000000
1.770000,-0.068146,-203.500351,-0.004838,-0.004624,-0.117457,-0.303127,-0.015442,-1.174574,-203.500351,-0.116443,0.000000
2.210000,0.024582,-203.500351,-0.004557,-0.004335,-0.110104,0.109346,0.005570,-1.101041,-203.500351,-0.109106,0.000000
2.650000,0.063309,-203.722763,-0.004277,-0.004059,-0.103105,0.281611,0.014346,-1.031051,-203.722763,-0.101786,0.000000
3.090000,0.029793,-203.767242,-0.003958,-0.003760,-0.095491,0.132525,0.006751,-0.954914,-203.767242,-0.094450,0.000000
3.530000,0.020851,-203.722763,-0.003652,-0.003473,-0.088223,0.092750,0.004725,-0.882229,-203.722763,-0.087113,0.000000
3.970000,0.193260,-203.811722,-0.003518,0.000001,0.000027,0.859664,0.043793,0.000273,-203.811722,0.000269,0.000000
4.410000,0.143738,-203.856201,-0.003518,0.000001,0.000027,0.639378,0.032571,0.000273,-203.856201,0.000504,0.000000
4.850000,0.204063,-203.900681,-0.003505,0.000018,0.000460,0.907719,0.046241,0.004602,-203.900681,0.001240,0.000000
5.290000,0.519463,-203.945160,-0.003505,0.000041,0.001049,2.310685,0.117712,0.010492,-203.945160,0.001977,0.000000
5.730000,0.943222,-203.945160,-0.003475,0.000072,0.001830,4.195661,0.213737,0.018304,-203.945160,0.002707,0.000000
6.170000,1.973946,-204.034119,-0.003462,0.000104,0.002654,8.780549,0.447302,0.026540,-204.034119,0.003443,0.000000
6.610000,2.908974,-203.989639,-0.003436,0.000131,0.003322,12.939761,0.659183,0.033216,-203.989639,0.004172,0.000000
7.050000,4.345963,-204.123077,-0.003432,0.000164,0.004154,19.331806,0.984809,0.041543,-204.123077,0.004910,0.000000
7.490000,5.199440,-204.034119,-0.003415,0.000184,0.004666,23.128263,1.178210,0.046660,-204.034119,0.005638,0.000000
7.930000,6.848305,-204.123077,-0.003380,0.000219,0.005550,30.462780,1.551848,0.055502,-204.123077,0.006375,0.000000
8.370001,8.090912,-204.167572,-0.003363,0.000245,0.006227,35.990173,1.833427,0.062269,-204.167572,0.007111,0.000000
8.810000,9.763611,-204.301010,-0.003359,0.000277,0.007043,43.430710,2.212466,0.070429,-204.301010,0.007841,0.000000
9.250000,10.868813,-204.345490,-0.003346,0.000297,0.007555,48.346893,2.462908,0.075547,-204.345490,0.008578,0.000000
9.690001,11.809425,-204.389969,-0.003324,0.000318,0.008066,52.530949,2.676054,0.080664,-204.389969,0.009306,0.000000
10.130000,14.718399,-204.345490,-0.003307,0.000365,0.009262,65.470711,3.335237,0.092624,-204.345490,0.010044,0.000000
10.570001,16.083138,-204.478928,-0.003285,0.000390,0.009904,71.541367,3.644491,0.099043,-204.478928,0.010772,0.000000
11.010000,17.893990,-204.478928,-0.003290,0.000422,0.010711,79.596443,4.054836,0.107113,-204.478928,0.011509,0.000000
11.450001,18.815239,-204.612381,-0.003260,0.000440,0.011179,83.694366,4.263594,0.111791,-204.612381,0.012246,0.000000
11.890000,20.962334,-204.612381,-0.003251,0.000476,0.012098,93.245117,4.750133,0.120980,-204.612381,0.012975,0.000000
12.330001,22.207176,-204.612381,-0.003242,0.000501,0.012723,98.782455,5.032218,0.127233,-204.612381,0.013712,0.000000
12.770000,24.207565,-204.656860,-0.003203,0.000535,0.013582,107.680626,5.485513,0.135817,-204.656860,0.014440,0.000000
13.210001,25.642685,-204.656860,-0.003203,0.000560,0.014215,114.064362,5.810716,0.142146,-204.656860,0.015177,0.000000
13.650001,27.355598,-204.834778,-0.003182,0.000592,0.015029,121.683777,6.198867,0.150291,-204.834778,0.015906,0.000000
14.090001,28.756462,-204.790298,-0.003165,0.000619,0.015724,127.915131,6.516307,0.157240,-204.790298,0.016643,0.000000
14.530001,29.962952,-204.790298,-0.003147,0.000644,0.016357,133.281860,6.789702,0.163568,-204.790298,0.017371,0.000000
14.970000,31.686661,-204.879257,-0.003143,0.000676,0.017180,140.949310,7.180300,0.171804,-204.879257,0.018108,0.000000
15.410001,32.190483,-204.923737,-0.003104,0.000698,0.017718,143.190414,7.294467,0.177179,-204.923737,0.018846,0.000000
15.850000,34.824646,-204.968216,-0.003100,0.000738,0.018750,154.907761,7.891378,0.187504,-204.968216,0.019574,0.000000
16.290001,35.595085,-205.101669,-0.003061,0.000761,0.019339,158.334854,8.065962,0.193393,-205.101669,0.020311,0.000000
16.730001,37.165382,-205.101669,-0.003044,0.000796,0.020207,165.319870,8.421796,0.202068,-205.101669,0.021039,0.000000
17.170000,37.899696,-205.190628,-0.003031,0.000817,0.020753,168.586273,8.588194,0.207533,-205.190628,0.021777,0.000000
17.610001,39.482651,-205.101669,-0.003014,0.000849,0.021577,175.627609,8.946897,0.215769,-205.101669,0.022505,0.000000
18.050001,40.410980,-205.235107,-0.002997,0.000879,0.022323,179.757019,9.157259,0.223233,-205.235107,0.023242,0.000000
18.490002,41.257751,-205.324066,-0.002962,0.000905,0.022991,183.523651,9.349140,0.229910,-205.324066,0.023980,0.000000
18.930000,42.136551,-205.324066,-0.002936,0.000931,0.023659,187.432739,9.548280,0.236586,-205.324066,0.024708,0.000000
19.370001,42.378593,-205.457520,-0.002928,0.000955,0.024257,188.509399,9.603127,0.242566,-205.457520,0.025445,0.000000
19.810001,44.396851,-205.413025,-0.002880,0.000995,0.025271,197.487061,10.060470,0.252710,-205.413025,0.026173,0.000000
20.250002,45.247353,-205.413025,-0.002893,0.001020,0.025896,201.270279,10.253196,0.258963,-205.413025,0.026911,0.000000
20.690001,46.821373,-205.546478,-0.002859,0.001056,0.026815,208.271866,10.609876,0.268152,-205.546478,0.027639,0.000000
21.130001,46.858604,-205.546478,-0.002811,0.001074,0.027275,208.437485,10.618312,0.272755,-205.546478,0.028376,0.000000
21.570002,48.194679,-205.635437,-0.002802,0.001108,0.028151,214.380646,10.921070,0.281505,-205.635437,0.029113,0.000000
22.010000,48.941284,-205.635437,-0.002772,0.001138,0.028904,217.701706,11.090253,0.289045,-205.635437,0.029842,0.000000
22.450001,50.039787,-205.679916,-0.002734,0.001170,0.029711,222.588089,11.339178,0.297114,-205.679916,0.030579,0.000000
22.890001,50.682503,-205.724396,-0.002734,0.001196,0.030388,225.447037,11.484819,0.303882,-205.724396,0.031307,0.000000
23.330002,51.615295,-205.768875,-0.002673,0.001225,0.031107,229.596298,11.696194,0.311073,-205.768875,0.032044,0.000000
23.770000,52.355942,-205.813354,-0.002669,0.001254,0.031863,232.890854,11.864026,0.318628,-205.813354,0.032773,0.000000
24.210001,52.672089,-205.857849,-0.002634,0.001280,0.032512,234.297150,11.935666,0.325122,-205.857849,0.033510,0.000000
24.650002,53.750481,-205.857849,-0.002621,0.001310,0.033284,239.094086,12.180033,0.332844,-205.857849,0.034247,0.000000
25.090002,53.490189,-205.946808,-0.002587,0.001328,0.033736,237.936249,12.121050,0.337355,-205.946808,0.034975,0.000000
25.530001,55.367317,-206.035767,-0.002552,0.001373,0.034871,246.286133,12.546413,0.348710,-206.035767,0.035713,0.000000
25.970001,55.945610,-206.035767,-0.002527,0.001399,0.035531,248.858505,12.677457,0.355311,-206.035767,0.036441,0.000000
26.410002,57.019165,-206.080246,-0.002505,0.001430,0.036320,253.633911,12.920728,0.363199,-206.080246,0.037178,0.000000
26.850000,57.316689,-206.080246,-0.002479,0.001452,0.036892,254.957367,12.988147,0.368921,-206.080246,0.037906,0.000000
27.290001,58.412956,-206.213684,-0.002445,0.001486,0.037741,259.833801,13.236565,0.377415,-206.213684,0.038644,0.000000
27.730001,59.086205,-206.213684,-0.002419,0.001514,0.038444,262.828552,13.389125,0.384439,-206.213684,0.039372,0.000000
28.170002,59.684975,-206.258163,-0.002389,0.001540,0.039113,265.492035,13.524808,0.391131,-206.258163,0.040109,0.000000
28.610001,60.311310,-206.258163,-0.002358,0.001565,0.039754,268.278107,13.666739,0.397535,-206.258163,0.040847,0.000000
29.050001,61.236282,-206.302658,-0.002324,0.001601,0.040674,272.392578,13.876340,0.406740,-206.302658,0.041575,0.000000
29.490002,62.675125,-206.391617,-0.002298,0.001633,0.041479,278.792877,14.202387,0.414794,-206.391617,0.042312,0.000000
29.930002,63.152878,-206.391617,-0.002276,0.001657,0.042087,280.918030,14.310647,0.420865,-206.391617,0.043040,0.000000
30.370001,64.320648,-206.436096,-0.002246,0.001688,0.042877,286.112518,14.575268,0.428768,-206.436096,0.043778,0.000000
30.810001,64.550766,-206.480576,-0.002220,0.001707,0.043370,287.136139,14.627413,0.433704,-206.480576,0.044506,0.000000
31.250002,65.974716,-206.525055,-0.002203,0.001743,0.044273,293.470184,14.950085,0.442727,-206.525055,0.045243,0.000000
31.690002,67.002472,-206.614014,-0.002182,0.001771,0.044975,298.041870,15.182978,0.449751,-206.614014,0.045980,0.000000
32.130001,68.029465,-206.614014,-0.002130,0.001800,0.045720,302.610168,15.415697,0.457200,-206.614014,0.046709,0.000000
32.570000,68.977539,-206.702972,-0.002121,0.001829,0.046457,306.827423,15.630534,0.464573,-206.702972,0.047446,0.000000
33.010002,70.996170,-206.614014,-0.002108,0.001862,0.047282,315.806732,16.087963,0.472824,-206.614014,0.048176,0.000000
33.450001,72.441711,-206.747467,-0.002082,0.001888,0.047967,322.236816,16.415527,0.479667,-206.747467,0.048911,0.000000
33.890003,73.458282,-206.836426,-0.002052,0.001914,0.048618,326.758759,16.645884,0.486177,-206.836426,0.049641,0.000000
34.330002,75.734970,-206.836426,-0.002031,0.001947,0.049450,336.885986,17.161791,0.494504,-206.836426,0.050377,0.000000
34.770000,76.236557,-206.880905,-0.002031,0.001962,0.049823,339.117157,17.275452,0.498228,-206.880905,0.051114,0.000000
35.210003,78.729218,-206.925385,-0.001992,0.001999,0.050786,350.205048,17.840296,0.507857,-206.925385,0.051844,0.000000
35.650002,80.626083,-206.969864,-0.001979,0.002028,0.051523,358.642731,18.270130,0.515230,-206.969864,0.052580,0.000000
36.090000,82.591476,-207.014343,-0.001983,0.002060,0.052312,367.385223,18.715496,0.523118,-207.014343,0.053309,0.000000
36.530003,83.409943,-207.103302,-0.001962,0.002078,0.052771,371.025940,18.900963,0.527705,-207.103302,0.054047,0.000000
36.970001,86.632080,-207.103302,-0.001953,0.002121,0.053864,385.358734,19.631109,0.538636,-207.103302,0.054775,0.000000
37.410004,88.144653,-207.192276,-0.001927,0.002146,0.054496,392.087006,19.973866,0.544964,-207.192276,0.055512,0.000000
37.850002,90.035568,-207.192276,-0.001901,0.002175,0.055243,400.498199,20.402351,0.552428,-207.192276,0.056248,0.000000
38.290001,91.994995,-207.281235,-0.001876,0.002202,0.055936,409.214172,20.846363,0.559362,-207.281235,0.056978,0.000000
38.730003,92.563232,-207.281235,-0.001845,0.002219,0.056353,411.741821,20.975128,0.563525,-207.281235,0.057715,0.000000
39.170002,96.150299,-207.325714,-0.001841,0.002262,0.057455,427.697876,21.787968,0.574547,-207.325714,0.058443,0.000000
39.610001,97.604034,-207.414673,-0.001837,0.002287,0.058088,434.164429,22.117390,0.580875,-207.414673,0.059181,0.000000
40.050003,100.173401,-207.370193,-0.001807,0.002323,0.058997,445.593536,22.699617,0.589974,-207.370193,0.059909,0.000000
40.490002,101.388458,-207.548111,-0.001811,0.002342,0.059483,450.998383,22.974953,0.594834,-207.548111,0.060646,0.000000
40.930000,103.541519,-207.548111,-0.001776,0.002375,0.060333,460.575684,23.462843,0.603327,-207.548111,0.061374,0.000000
41.370003,105.712814,-207.503632,-0.001785,0.002403,0.061035,470.234070,23.954866,0.610352,-207.503632,0.062112,0.000000
41.810001,107.945572,-207.592606,-0.001763,0.002436,0.061877,480.165894,24.460815,0.618770,-207.592606,0.062849,0.000000
42.250004,109.834610,-207.592606,-0.001746,0.002459,0.062458,488.568756,24.888880,0.624583,-207.592606,0.063577,0.000000
42.690002,110.476959,-207.726044,-0.001738,0.002478,0.062935,491.426056,25.034437,0.629352,-207.726044,0.064314,0.000000
43.130001,114.569702,-207.726044,-0.001699,0.002524,0.064106,509.631500,25.961866,0.641055,-207.726044,0.065043,0.000000
43.570004,115.859970,-207.815002,-0.001725,0.002544,0.064626,515.370911,26.254244,0.646263,-207.815002,0.065780,0.000000
44.010002,118.663193,-207.859482,-0.001690,0.002581,0.065545,527.840271,26.889463,0.655453,-207.859482,0.066508,0.000000
44.450001,119.918823,-207.815002,-0.001669,0.002598,0.065996,533.425537,27.173994,0.659965,-207.815002,0.067245,0.000000
44.890003,122.783859,-207.992920,-0.001651,0.002634,0.066906,546.169861,27.823221,0.669063,-207.992920,0.067983,0.000000
45.330002,124.802124,-207.992920,-0.001638,0.002666,0.067704,555.147583,28.280565,0.677042,-207.992920,0.068711,0.000000
45.770000,127.525650,-207.948441,-0.001634,0.002698,0.068520,567.262451,28.897726,0.685202,-207.948441,0.069448,0.000000
46.210003,128.605530,-208.037415,-0.001625,0.002719,0.069058,572.065979,29.142431,0.690577,-208.037415,0.070176,0.000000
46.650002,131.400558,-208.037415,-0.001621,0.002757,0.070021,584.498901,29.775791,0.700206,-208.037415,0.070914,0.000000
47.090004,133.768112,-208.170853,-0.001604,0.002779,0.070584,595.030273,30.312286,0.705837,-208.170853,0.071642,0.000000
47.530003,135.682098,-208.215332,-0.001582,0.002807,0.071304,603.544128,30.746002,0.713044,-208.215332,0.072379,0.000000
47.970001,138.112579,-208.259811,-0.001578,0.002836,0.072033,614.355408,31.296759,0.720326,-208.259811,0.073117,0.000000
48.410004,139.499298,-208.304291,-0.001556,0.002856,0.072552,620.523865,31.610992,0.725519,-208.304291,0.073845,0.000000
48.850002,142.484970,-208.259811,-0.001539,0.002894,0.073515,633.804810,32.287556,0.735148,-208.259811,0.074582,0.000000
49.290001,144.868530,-208.393250,-0.001531,0.002924,0.074278,644.407410,32.827679,0.742778,-208.393250,0.075310,0.000000
49.730003,147.611420,-208.437744,-0.001526,0.002957,0.075110,656.608398,33.449226,0.751105,-208.437744,0.076048,0.000000
50.170002,149.261414,-208.393250,-0.001539,0.002979,0.075675,663.947937,33.823120,0.756752,-208.393250,0.076776,0.000000
50.610001,151.932434,-208.482224,-0.001496,0.003012,0.076499,675.829224,34.428383,0.764988,-208.482224,0.077513,0.000000
51.050003,153.851273,-208.526703,-0.001492,0.003037,0.077148,684.364624,34.863197,0.771483,-208.526703,0.078250,0.000000
51.490002,156.098541,-208.615662,-0.001492,0.003065,0.077843,694.360962,35.372437,0.778432,-208.615662,0.078979,0.000000
51.930004,158.435181,-208.615662,-0.001483,0.003092,0.078546,704.754883,35.901924,0.785457,-208.615662,0.079716,0.000000
52.370003,159.701981,-208.660141,-0.001462,0.003111,0.079030,710.389893,36.188988,0.790301,-208.660141,0.080444,0.000000
52.810001,163.865112,-208.793579,-0.001457,0.003157,0.080193,728.908447,37.132362,0.801928,-208.793579,0.081181,0.000000
53.250004,165.697556,-208.749100,-0.001440,0.003180,0.080774,737.059509,37.547604,0.807742,-208.749100,0.081910,0.000000
53.690002,168.877243,-208.838058,-0.001440,0.003215,0.081658,751.203491,38.268131,0.816584,-208.838058,0.082647,0.000000
54.130001,170.419983,-208.838058,-0.001436,0.003233,0.082110,758.065918,38.617722,0.821095,-208.838058,0.083375,0.000000
54.570004,173.347580,-208.882553,-0.001427,0.003268,0.083012,771.088562,39.281124,0.830118,-208.882553,0.084112,0.000000
55.010002,175.448135,-208.971512,-0.001406,0.003292,0.083619,780.432312,39.757114,0.836189,-208.971512,0.084850,0.000000
55.450001,178.525040,-208.971512,-0.001410,0.003327,0.084512,794.119019,40.454353,0.845122,-208.971512,0.085578,0.000000
55.890003,180.260300,-209.060471,-0.001388,0.003347,0.085015,801.837830,40.847569,0.850148,-209.060471,0.086315,0.000000
56.330002,182.803970,-209.015991,-0.001388,0.003381,0.085890,813.152649,41.423973,0.858899,-209.015991,0.087044,0.000000
56.770004,185.826889,-209.060471,-0.001380,0.003411,0.086636,826.599304,42.108974,0.866362,-209.060471,0.087781,0.000000
57.210003,187.389374,-209.149429,-0.001367,0.003432,0.087174,833.549561,42.463039,0.871737,-209.149429,0.088509,0.000000
57.650002,190.657684,-209.193909,-0.001367,0.003466,0.088041,848.087708,43.203648,0.880412,-209.193909,0.089246,0.000000
58.090004,192.329254,-209.282867,-0.001358,0.003487,0.088570,855.523254,43.582432,0.885696,-209.282867,0.089984,0.000000
58.530003,195.981476,-209.282867,-0.001332,0.003527,0.089593,871.769165,44.410038,0.895930,-209.282867,0.090712,0.000000
58.970001,198.231354,-209.327362,-0.001328,0.003555,0.090295,881.777100,44.919868,0.902955,-209.327362,0.091449,0.000000
59.410004,200.760895,-209.371841,-0.001328,0.003585,0.091051,893.029053,45.493069,0.910509,-209.371841,0.092177,0.000000
59.850002,202.728882,-209.460800,-0.001337,0.003603,0.091519,901.783081,45.939018,0.915188,-209.460800,0.092915,0.000000
60.290005,204.268280,-209.505280,-0.001315,0.003623,0.092014,908.630676,46.287853,0.920138,-209.505280,0.093643,0.000000
60.730003,208.422821,-209.416321,-0.001306,0.003669,0.093193,927.111023,47.229286,0.931932,-209.416321,0.094380,0.000000
61.170002,211.189941,-209.594238,-0.001298,0.003699,0.093947,939.419800,47.856323,0.939471,-209.594238,0.095117,0.000000
61.610004,213.914215,-209.594238,-0.001276,0.003727,0.094659,951.537964,48.473656,0.946587,-209.594238,0.095846,0.000000
62.050003,215.244324,-209.683197,-0.001285,0.003743,0.095075,957.454590,48.775059,0.950750,-209.683197,0.096583,0.000000
62.490002,218.818726,-209.683197,-0.001276,0.003783,0.096089,973.354309,49.585030,0.960894,-209.683197,0.097313,0.000000
62.930004,220.814270,-209.683197,-0.001259,0.003793,0.096341,982.230957,50.037228,0.963407,-209.683197,0.016930,0.000000
63.370003,220.052765,-209.816650,-0.001250,0.003790,0.096254,978.843567,49.864670,0.962544,-209.816650,982.000671,0.000000
63.810001,219.332214,-209.861130,-0.001246,0.003790,0.096262,975.638428,49.701389,0.962620,-209.861130,982.000671,0.000000
64.250000,220.595306,-209.861130,-0.001242,0.003765,0.095629,981.256958,49.987610,0.956292,-209.861130,982.000671,0.000000
64.690002,219.983124,-209.950089,-0.001246,0.003776,0.095915,978.533813,49.848888,0.959153,-209.950089,982.000671,0.000000
65.130005,219.573151,-209.950089,-0.001224,0.003806,0.096671,976.710144,49.755985,0.966708,-209.950089,982.000671,0.000000
65.570000,219.642792,-209.994568,-0.001207,0.003822,0.097087,977.019958,49.771767,0.970871,-209.994568,982.000671,0.000000
66.010002,219.690460,-210.128006,-0.001224,0.003829,0.097251,977.231995,49.782570,0.972506,-210.128006,982.000671,0.000000
66.450005,219.866943,-210.039047,-0.001199,0.003836,0.097425,978.017029,49.822559,0.974247,-210.039047,982.000671,0.000000
66.889999,219.489746,-210.128006,-0.001220,0.003836,0.097434,976.339172,49.737087,0.974338,-210.128006,982.000671,0.000000
67.330002,219.674072,-210.216980,-0.001194,0.003842,0.097599,977.159058,49.778854,0.975988,-210.216980,982.000671,0.000000
67.770004,219.691925,-210.216980,-0.001190,0.003848,0.097737,977.238464,49.782902,0.977366,-210.216980,982.000671,0.000000
68.210007,219.687469,-210.305939,-0.001194,0.003852,0.097850,977.218689,49.781891,0.978501,-210.305939,982.000671,0.000000
68.650002,219.511322,-210.350418,-0.001194,0.003855,0.097927,976.435120,49.741974,0.979273,-210.350418,982.000671,0.000000
69.090004,219.371704,-210.394897,-0.001194,0.003857,0.097980,975.814087,49.710339,0.979803,-210.394897,982.000671,0.000000
69.530006,219.996521,-210.439377,-0.001190,0.003867,0.098223,978.593384,49.851925,0.982226,-210.439377,982.000671,0.000000
69.970001,219.613007,-210.483856,-0.001186,0.003867,0.098223,976.887451,49.765018,0.982226,-210.483856,982.000671,0.000000
70.410004,219.234650,-210.528336,-0.001173,0.003867,0.098223,975.204407,49.679279,0.982226,-210.528336,982.000671,0.000000
70.850006,219.468872,-210.528336,-0.001164,0.003875,0.098413,976.246277,49.732357,0.984133,-210.528336,982.000671,0.000000
71.290001,219.135620,-210.572815,-0.001164,0.003875,0.098422,974.763916,49.656841,0.984224,-210.572815,982.000671,0.000000
71.730003,220.218475,-210.617310,-0.001173,0.003875,0.098422,979.580688,49.902218,0.984224,-210.617310,982.000671,0.000000
72.170006,219.801422,-210.706268,-0.001143,0.003875,0.098430,977.725586,49.807716,0.984300,-210.706268,982.000671,0.000000
72.610001,219.376160,-210.795227,-0.001168,0.003876,0.098457,975.833923,49.711349,0.984572,-210.795227,982.000671,0.000000
73.050003,220.212128,-210.795227,-0.001147,0.003895,0.098925,979.552490,49.900780,0.989250,-210.795227,982.000671,0.000000
73.490005,219.829712,-210.839706,-0.001147,0.003895,0.098925,977.851379,49.814125,0.989250,-210.839706,982.000671,0.000000
73.930000,219.440216,-210.839706,-0.001138,0.003897,0.098995,976.118835,49.725864,0.989947,-210.839706,982.000671,0.000000
74.370003,219.754120,-210.928665,-0.001147,0.003904,0.099151,977.515137,49.796997,0.991506,-210.928665,982.000671,0.000000
74.810005,219.459961,-210.928665,-0.001138,0.003904,0.099160,976.206665,49.730339,0.991597,-210.928665,982.000671,0.000000
75.250000,219.889679,-210.928665,-0.001130,0.003913,0.099402,978.118164,49.827713,0.994019,-210.928665,982.000671,0.000000
75.690002,219.767517,-211.062119,-0.001138,0.003913,0.099402,977.574768,49.800030,0.994019,-211.062119,982.000671,0.000000
76.130005,219.690460,-211.106598,-0.001130,0.003917,0.099497,977.231995,49.782570,0.994973,-211.106598,982.000671,0.000000
76.570007,219.852051,-211.106598,-0.001134,0.003922,0.099628,977.950745,49.819187,0.996275,-211.106598,982.000671,0.000000
77.010002,219.722473,-211.151077,-0.001121,0.003922,0.099628,977.374390,49.789825,0.996275,-211.151077,982.000671,0.000000
77.450005,219.554901,-211.195557,-0.001121,0.003924,0.099671,976.628967,49.751854,0.996714,-211.195557,982.000671,0.000000
77.890007,219.608521,-211.240036,-0.001125,0.003928,0.099774,976.867493,49.764004,0.997744,-211.240036,982.000671,0.000000
78.330002,219.491211,-211.328995,-0.001104,0.003929,0.099800,976.345642,49.737419,0.998001,-211.328995,982.000671,0.000000
78.770004,219.558990,-211.328995,-0.001125,0.003933,0.099888,976.647156,49.752777,0.998879,-211.328995,982.000671,0.000000
79.210007,219.573517,-211.417953,-0.001112,0.003936,0.099983,976.711792,49.756069,0.999833,-211.417953,982.000671,0.000000
79.650002,219.519897,-211.373474,-0.001104,0.003937,0.100009,976.473267,49.743919,1.000090,-211.373474,982.000671,0.000000
80.090004,219.386963,-211.506927,-0.001130,0.003939,0.100061,975.881958,49.713799,1.000605,-211.506927,982.000671,0.000000
80.530006,219.552307,-211.595886,-0.001104,0.003943,0.100148,976.617432,49.751266,1.001483,-211.595886,982.000671,0.000000
80.970001,219.393280,-211.551407,-0.001104,0.003946,0.100216,975.910034,49.715229,1.002164,-211.551407,982.000671,0.000000
81.410004,219.398865,-211.595886,-0.001095,0.003946,0.100235,975.934875,49.716492,1.002346,-211.595886,982.000671,0.000000
81.850006,219.472595,-211.640366,-0.001104,0.003950,0.100321,976.262878,49.733200,1.003209,-211.640366,982.000671,0.000000
82.290001,219.853180,-211.684845,-0.001095,0.003956,0.100486,977.955811,49.819443,1.004859,-211.684845,982.000671,0.000000
82.730003,219.716888,-211.729324,-0.001082,0.003956,0.100486,977.349548,49.788559,1.004859,-211.729324,982.000671,0.000000
83.170006,219.511322,-211.773804,-0.001082,0.003959,0.100546,976.435120,49.741974,1.005465,-211.773804,982.000671,0.000000
83.610001,219.646881,-211.862762,-0.001082,0.003961,0.100598,977.038147,49.772697,1.005980,-211.862762,982.000671,0.000000
84.050003,219.750031,-211.907257,-0.001099,0.003965,0.100702,977.496948,49.796070,1.007024,-211.907257,982.000671,0.000000
84.490005,219.649109,-211.951736,-0.001095,0.003965,0.100712,977.048035,49.773197,1.007115,-211.951736,982.000671,0.000000
84.930000,219.615234,-212.040695,-0.001069,0.003967,0.100772,976.897339,49.765522,1.007721,-212.040695,982.000671,0.000000
85.370003,219.731415,-211.996216,-0.001095,0.003971,0.100851,977.414124,49.791851,1.008508,-211.996216,982.000671,0.000000
85.810005,219.684113,-212.040695,-0.001061,0.003972,0.100886,977.203735,49.781132,1.008856,-212.040695,982.000671,0.000000
86.250008,219.684113,-212.085175,-0.001082,0.003975,0.100954,977.203735,49.781132,1.009537,-212.085175,982.000671,0.000000
86.690002,219.601440,-212.085175,-0.001074,0.003976,0.100981,976.835999,49.762398,1.009810,-212.085175,982.000671,0.000000
87.130005,219.743683,-212.218613,-0.001074,0.003979,0.101067,977.468750,49.794628,1.010673,-212.218613,982.000671,0.000000
87.570007,219.629364,-212.174133,-0.001052,0.003980,0.101102,976.960205,49.768723,1.011021,-212.174133,982.000671,0.000000
88.010002,219.549316,-212.263092,-0.001065,0.003981,0.101119,976.604126,49.750587,1.011188,-212.263092,982.000671,0.000000
88.450005,219.437592,-212.263092,-0.001043,0.003982,0.101137,976.107178,49.725269,1.011369,-212.263092,982.000671,0.000000
88.890007,219.719849,-212.352066,-0.001056,0.003992,0.101396,977.362671,49.789230,1.013958,-212.352066,982.000671,0.000000
89.330002,219.903076,-212.307587,-0.001039,0.003990,0.101344,978.177734,49.830750,1.013443,-212.307587,982.000671,0.000000
89.770004,219.773499,-212.441025,-0.001061,0.003990,0.101344,977.601318,49.801388,1.013443,-212.441025,982.000671,0.000000
90.210007,219.572784,-212.485504,-0.001052,0.003990,0.101344,976.708496,49.755905,1.013443,-212.485504,982.000671,0.000000
90.650002,219.393677,-212.485504,-0.001048,0.003990,0.101344,975.911804,49.715317,1.013443,-212.485504,982.000671,0.000000
91.090004,219.826721,-212.485504,-0.001061,0.003997,0.101518,977.838074,49.813446,1.015185,-212.485504,982.000671,0.000000
91.530006,219.711304,-212.618942,-0.001052,0.003997,0.101518,977.324707,49.787296,1.015185,-212.618942,982.000671,0.000000
91.970001,219.542236,-212.574463,-0.001048,0.003997,0.101518,976.572632,49.748981,1.015185,-212.574463,982.000671,0.000000
92.410004,219.367218,-212.707901,-0.001039,0.003997,0.101526,975.794128,49.709324,1.015260,-212.707901,982.000671,0.000000
92.850006,219.199646,-212.707901,-0.001039,0.003997,0.101526,975.048706,49.671352,1.015260,-212.707901,982.000671,0.000000
93.290001,219.135620,-212.796875,-0.001039,0.004005,0.101717,974.763916,49.656841,1.017168,-212.796875,982.000671,0.000000
93.730003,220.324585,-212.796875,-0.001043,0.004009,0.101830,980.052673,49.926262,1.018303,-212.796875,982.000671,0.000000
94.170006,220.146606,-212.841354,-0.001026,0.004009,0.101830,979.260986,49.885933,1.018303,-212.841354,982.000671,0.000000
94.610008,219.935455,-212.974792,-0.001043,0.004009,0.101830,978.321777,49.838085,1.018303,-212.974792,982.000671,0.000000
95.050003,219.780548,-212.930313,-0.001030,0.004009,0.101830,977.632690,49.802986,1.018303,-212.930313,982.000671,0.000000
95.490005,219.578735,-212.974792,-0.001026,0.004009,0.101839,976.734985,49.757252,1.018394,-212.974792,982.000671,0.000000
95.930008,219.918335,-213.019272,-0.001039,0.004017,0.102021,978.245605,49.834209,1.020211,-213.019272,982.000671,0.000000
96.370003,219.838654,-213.063751,-0.001018,0.004017,0.102021,977.891174,49.816151,1.020211,-213.063751,982.000671,0.000000
96.810005,219.695282,-213.152710,-0.001030,0.004017,0.102030,977.253418,49.783661,1.020302,-213.152710,982.000671,0.000000
97.250008,219.611877,-213.152710,-0.001026,0.004018,0.102056,976.882446,49.764763,1.020559,-213.152710,982.000671,0.000000
97.690002,219.628998,-213.197205,-0.001030,0.004020,0.102116,976.958557,49.768642,1.021165,-213.197205,982.000671,0.000000
98.130005,219.623047,-213.241684,-0.001018,0.004022,0.102151,976.932129,49.767292,1.021513,-213.241684,982.000671,0.000000
98.570007,219.515045,-213.241684,-0.001013,0.004022,0.102160,976.451660,49.742821,1.021604,-213.241684,982.000671,0.000000
99.010002,219.735870,-213.375122,-0.001022,0.004026,0.102256,977.433960,49.792862,1.022557,-213.375122,982.000671,0.000000
99.450005,219.624908,-213.375122,-0.001005,0.004026,0.102256,976.940369,49.767715,1.022557,-213.375122,982.000671,0.000000
99.890007,219.538879,-213.375122,-0.001009,0.004028,0.102307,976.557678,49.748222,1.023072,-213.375122,982.000671,0.000000
100.330002,219.595490,-213.508560,-0.001018,0.004029,0.102333,976.809509,49.761047,1.023330,-213.508560,982.000671,0.000000
100.770004,219.566803,-213.508560,-0.001013,0.004030,0.102351,976.681946,49.754547,1.023511,-213.508560,982.000671,0.000000
101.210007,219.627502,-213.597534,-0.001005,0.004033,0.102428,976.951904,49.768303,1.024283,-213.597534,982.000671,0.000000
101.650002,219.596222,-213.597534,-0.001005,0.004033,0.102428,976.812805,49.761215,1.024283,-213.597534,982.000671,0.000000
102.090004,219.536285,-213.597534,-0.000996,0.004039,0.102593,976.546143,49.747635,1.025934,-213.597534,982.000671,0.000000
102.530006,219.945892,-213.686493,-0.001000,0.004039,0.102584,978.368164,49.840454,1.025843,-213.686493,982.000671,0.000000
102.970001,219.844238,-213.730972,-0.001005,0.004039,0.102584,977.916016,49.817417,1.025843,-213.730972,982.000671,0.000000
103.410004,219.715027,-213.819931,-0.001009,0.004039,0.102584,977.341248,49.788136,1.025843,-213.819931,982.000671,0.000000
103.850006,219.613373,-213.775452,-0.001000,0.004039,0.102593,976.889099,49.765102,1.025934,-213.775452,982.000671,0.000000
104.290009,219.502014,-213.819931,-0.001005,0.004039,0.102593,976.393738,49.739868,1.025934,-213.819931,982.000671,0.000000
104.730003,220.116821,-213.908890,-0.000992,0.004047,0.102793,979.128540,49.879185,1.027932,-213.908890,982.000671,0.000000
105.170006,220.012909,-213.908890,-0.000979,0.004047,0.102793,978.666321,49.855640,1.027932,-213.908890,982.000671,0.000000
105.610008,219.886322,-213.997849,-0.000996,0.004047,0.102793,978.103210,49.826950,1.027932,-213.997849,982.000671,0.000000
106.050003,219.784668,-213.997849,-0.000996,0.004047,0.102793,977.651001,49.803917,1.027932,-213.997849,982.000671,0.000000
106.490005,219.640533,-214.042343,-0.000996,0.004047,0.102793,977.009888,49.771255,1.027932,-214.042343,982.000671,0.000000
106.930008,219.525848,-214.131302,-0.000992,0.004047,0.102793,976.499756,49.745266,1.027932,-214.131302,982.000671,0.000000
107.370003,219.389954,-214.086823,-0.000970,0.004047,0.102793,975.895264,49.714478,1.027932,-214.086823,982.000671,0.000000
107.810005,219.284180,-214.175781,-0.000983,0.004047,0.102793,975.424744,49.690506,1.027932,-214.175781,982.000671,0.000000
108.250008,220.321991,-214.220261,-0.000983,0.004058,0.103079,980.041138,49.925674,1.030793,-214.220261,982.000671,0.000000
108.690002,220.160370,-214.220261,-0.001000,0.004058,0.103079,979.322266,49.889050,1.030793,-214.220261,982.000671,0.000000
109.130005,220.078094,-214.353699,-0.000992,0.004058,0.103079,978.956238,49.870411,1.030793,-214.353699,982.000671,0.000000
109.570007,219.951111,-214.353699,-0.000970,0.004058,0.103079,978.391418,49.841633,1.030793,-214.353699,982.000671,0.000000
110.010002,219.840149,-214.353699,-0.000979,0.004058,0.103079,977.897827,49.816490,1.030793,-214.353699,982.000671,0.000000
110.450005,219.741089,-214.442657,-0.000987,0.004058,0.103079,977.457153,49.794041,1.030793,-214.442657,982.000671,0.000000
110.890007,219.601807,-214.487152,-0.000970,0.004058,0.103079,976.837646,49.762482,1.030793,-214.487152,982.000671,0.000000
111.330002,219.497559,-214.576111,-0.000979,0.004058,0.103079,976.373901,49.738857,1.030793,-214.576111,982.000671,0.000000
111.770004,219.363495,-214.620590,-0.000966,0.004058,0.103079,975.777588,49.708477,1.030793,-214.620590,982.000671,0.000000
112.210007,219.257385,-214.620590,-0.000970,0.004058,0.103079,975.305542,49.684433,1.030793,-214.620590,982.000671,0.000000
112.650009,219.123322,-214.709549,-0.000974,0.004058,0.103079,974.709229,49.654053,1.030793,-214.709549,982.000671,0.000000
113.090004,219.012726,-214.665070,-0.000974,0.004058,0.103079,974.217285,49.628994,1.030793,-214.665070,982.000671,0.000000
113.530006,218.876434,-214.798508,-0.000970,0.004058,0.103079,973.611023,49.598110,1.030793,-214.798508,982.000671,0.000000
113.970009,218.763611,-214.798508,-0.000957,0.004058,0.103079,973.109131,49.572544,1.030793,-214.798508,982.000671,0.000000
114.410004,218.662689,-214.842987,-0.000983,0.004058,0.103079,972.660217,49.549671,1.030793,-214.842987,982.000671,0.000000
114.850006,220.596069,-214.931961,-0.000961,0.004056,0.103010,981.260315,49.987782,1.030097,-214.931961,982.000671,0.000000
115.290009,220.459015,-214.887482,-0.000961,0.004056,0.103010,980.650696,49.956726,1.030097,-214.887482,982.000671,0.000000
115.730003,220.328308,-214.931961,-0.000944,0.004056,0.103010,980.069275,49.927109,1.030097,-214.931961,982.000671,0.000000
116.170006,220.216980,-215.109879,-0.000953,0.004056,0.103010,979.574036,49.901882,1.030097,-215.109879,982.000671,0.000000
116.610008,220.108246,-215.020920,-0.000966,0.004056,0.103010,979.090393,49.877243,1.030097,-215.020920,982.000671,0.000000
117.050003,219.958557,-215.109879,-0.000940,0.004056,0.103010,978.424500,49.843323,1.030097,-215.109879,982.000671,0.000000
117.490005,219.851318,-215.109879,-0.000936,0.004056,0.103010,977.947510,49.819023,1.030097,-215.109879,982.000671,0.000000
117.930008,219.728424,-215.243317,-0.000940,0.004056,0.103010,977.400818,49.791172,1.030097,-215.243317,982.000671,0.000000
118.370003,219.587311,-215.287796,-0.000953,0.004056,0.103010,976.773132,49.759193,1.030097,-215.287796,982.000671,0.000000
118.810005,219.499420,-215.243317,-0.000944,0.004056,0.103010,976.382202,49.739281,1.030097,-215.243317,982.000671,0.000000
119.250008,220.075470,-215.332291,-0.000949,0.004081,0.103661,978.944580,49.869816,1.036607,-215.332291,982.000671,0.000000
119.690002,220.041229,-215.243317,-0.000953,0.004081,0.103661,978.792297,49.862057,1.036607,-215.243317,982.000671,0.000000
120.130005,219.912750,-215.421249,-0.000931,0.004081,0.103661,978.220764,49.832943,1.036607,-215.421249,982.000671,0.000000
120.570007,219.835297,-215.465729,-0.000940,0.004081,0.103661,977.876221,49.815392,1.036607,-215.465729,982.000671,0.000000
121.010002,219.735504,-215.421249,-0.000940,0.004081,0.103661,977.432312,49.792774,1.036607,-215.421249,982.000671,0.000000
121.450005,219.628998,-215.510208,-0.000936,0.004081,0.103668,976.958557,49.768642,1.036683,-215.510208,982.000671,0.000000
121.890007,219.675934,-215.599167,-0.000940,0.004084,0.103729,977.167358,49.779278,1.037288,-215.599167,982.000671,0.000000
122.330009,219.734375,-215.643646,-0.000931,0.004086,0.103782,977.427307,49.792522,1.037818,-215.643646,982.000671,0.000000
122.770004,219.706818,-215.643646,-0.000918,0.004086,0.103782,977.304749,49.786274,1.037818,-215.643646,982.000671,0.000000
123.210007,219.668091,-215.599167,-0.000931,0.004087,0.103798,977.132446,49.777500,1.037985,-215.599167,982.000671,0.000000
123.650009,219.703491,-215.777100,-0.000944,0.004079,0.103599,977.289917,49.785522,1.035986,-215.777100,0.103894,0.000000
124.090004,219.586914,-215.732620,-0.000940,0.004069,0.103356,976.771362,49.759106,1.033564,-215.732620,0.103166,0.000000
124.530006,219.344879,-215.777100,-0.000936,0.004047,0.102784,975.694763,49.704262,1.027841,-215.777100,0.102428,0.000000
124.970009,218.780731,-215.866058,-0.000936,0.004023,0.102186,973.185303,49.576424,1.021861,-215.866058,0.101700,0.000000
125.410004,217.154205,-215.910538,-0.000936,0.003992,0.101388,965.950134,49.207848,1.013883,-215.910538,0.100963,0.000000
125.850006,216.157745,-215.910538,-0.000936,0.003962,0.100625,961.517700,48.982044,1.006252,-215.910538,0.100226,0.000000
126.290009,215.585785,-216.043976,-0.000914,0.003938,0.100035,958.973450,48.852436,1.000348,-216.043976,0.099497,0.000000
126.730003,215.285278,-215.999496,-0.000923,0.003909,0.099297,957.636719,48.784344,0.992975,-215.999496,0.098760,0.000000
127.170006,214.883850,-216.088455,-0.000897,0.003883,0.098630,955.851074,48.693375,0.986298,-216.088455,0.098032,0.000000
127.610008,214.469421,-216.088455,-0.000875,0.003850,0.097797,954.007629,48.599468,0.977971,-216.088455,0.097295,0.000000
128.050003,213.753326,-216.177429,-0.000897,0.003826,0.097173,950.822266,48.437199,0.971734,-216.177429,0.096566,0.000000
128.490005,212.844757,-216.221909,-0.000897,0.003792,0.096315,946.780762,48.231312,0.963150,-216.221909,0.095829,0.000000
128.930008,211.343353,-216.221909,-0.000901,0.003767,0.095690,940.102173,47.891087,0.956897,-216.221909,0.095092,0.000000
129.370010,210.187866,-216.355347,-0.000901,0.003742,0.095040,934.962341,47.629253,0.950402,-216.355347,0.094363,0.000000
129.810013,207.557068,-216.310867,-0.000910,0.003708,0.094189,923.259949,47.033104,0.941894,-216.310867,0.093626,0.000000
130.250000,205.474762,-216.399826,-0.000892,0.003685,0.093610,913.997375,46.561249,0.936095,-216.399826,0.092898,0.000000
130.690002,202.608978,-216.355347,-0.000888,0.003660,0.092975,901.249756,45.911850,0.929752,-216.355347,0.092161,0.000000
131.130005,199.452362,-216.488785,-0.000892,0.003630,0.092212,887.208435,45.196552,0.922122,-216.488785,0.091432,0.000000
131.570007,195.612091,-216.577744,-0.000897,0.003595,0.091311,870.126038,44.326336,0.913113,-216.577744,0.090695,0.000000
132.010010,192.945526,-216.577744,-0.000871,0.003571,0.090712,858.264587,43.722080,0.907118,-216.577744,0.089967,0.000000
132.450012,189.531631,-216.622238,-0.000901,0.003540,0.089914,843.078796,42.948479,0.899140,-216.622238,0.089230,0.000000
132.889999,186.537003,-216.622238,-0.000880,0.003513,0.089221,829.758057,42.269890,0.892206,-216.622238,0.088492,0.000000
133.330002,183.498825,-216.666718,-0.000901,0.003482,0.088432,816.243530,41.581429,0.884318,-216.666718,0.087764,0.000000
133.770004,180.348923,-216.755676,-0.000888,0.003456,0.087781,802.232056,40.867649,0.877808,-216.755676,0.087027,0.000000
134.210007,177.831314,-216.711197,-0.000880,0.003430,0.087113,791.033203,40.297150,0.871131,-216.711197,0.086299,0.000000
134.650009,174.007050,-216.844635,-0.000892,0.003403,0.086436,774.022034,39.430561,0.864364,-216.844635,0.085561,0.000000
135.090012,170.605057,-216.844635,-0.000880,0.003374,0.085699,758.889221,38.659657,0.856991,-216.844635,0.084833,0.000000
135.530014,166.592361,-216.800156,-0.000884,0.003342,0.084876,741.039856,37.750366,0.848755,-216.800156,0.084096,0.000000
135.970001,163.744461,-216.978073,-0.000884,0.003317,0.084243,728.371765,37.105026,0.842427,-216.978073,0.083359,0.000000
136.410004,159.332962,-216.933594,-0.000875,0.003282,0.083359,708.748413,36.105362,0.833585,-216.933594,0.082630,0.000000
136.850006,155.964478,-217.022568,-0.000888,0.003253,0.082638,693.764648,35.342056,0.826379,-217.022568,0.081893,0.000000
137.290009,152.119370,-217.067047,-0.000875,0.003220,0.081779,676.660767,34.470741,0.817795,-217.067047,0.081165,0.000000
137.730011,149.141876,-217.022568,-0.000871,0.003197,0.081207,663.416199,33.796032,0.812072,-217.022568,0.080428,0.000000
138.170013,146.089539,-217.156006,-0.000897,0.003171,0.080549,649.838745,33.104362,0.805486,-217.156006,0.079699,0.000000
138.610001,143.171997,-217.200485,-0.000892,0.003143,0.079837,636.860840,32.443237,0.798371,-217.200485,0.078962,0.000000
139.050003,139.510468,-217.200485,-0.000897,0.003114,0.079100,620.573547,31.613523,0.790998,-217.200485,0.078225,0.000000
139.490005,135.444901,-217.289444,-0.000897,0.003079,0.078216,602.489014,30.692253,0.782156,-217.289444,0.077496,0.000000
139.930008,133.040497,-217.289444,-0.000892,0.003058,0.077678,591.793701,30.147408,0.776782,-217.289444,0.076759,0.000000
140.370010,129.202072,-217.378403,-0.000884,0.003027,0.076880,574.719543,29.277607,0.768803,-217.378403,0.076029,0.000000
140.810013,125.683151,-217.378403,-0.000875,0.002995,0.076073,559.066589,28.480209,0.760734,-217.378403,0.075294,0.000000
141.250000,122.433456,-217.378403,-0.000897,0.002966,0.075336,544.611206,27.743818,0.753361,-217.378403,0.074564,0.000000
141.690002,119.359894,-217.556335,-0.000888,0.002940,0.074677,530.939331,27.047338,0.746775,-217.556335,0.073828,0.000000
142.130005,115.855133,-217.511856,-0.000875,0.002909,0.073896,515.349365,26.253149,0.738963,-217.511856,0.073091,0.000000
142.570007,112.742462,-217.556335,-0.000897,0.002881,0.073186,501.503510,25.547808,0.731862,-217.556335,0.072361,0.000000
143.010010,109.869614,-217.556335,-0.000884,0.002857,0.072579,488.724457,24.896811,0.725791,-217.556335,0.071625,0.000000
143.450012,105.810013,-217.600815,-0.000884,0.002821,0.071659,470.666443,23.976892,0.716587,-217.600815,0.070896,0.000000
143.889999,102.980728,-217.689774,-0.000897,0.002796,0.071018,458.081146,23.335766,0.710183,-217.689774,0.070160,0.000000
144.330002,99.840500,-217.689774,-0.000897,0.002769,0.070332,444.112732,22.624182,0.703324,-217.689774,0.069430,0.000000
144.770004,96.342438,-217.823212,-0.000884,0.002738,0.069544,428.552582,21.831509,0.695437,-217.823212,0.068693,0.000000
145.210007,93.215622,-217.823212,-0.000888,0.002712,0.068876,414.643799,21.122961,0.688760,-217.823212,0.067965,0.000000
145.650009,90.246323,-217.823212,-0.000884,0.002687,0.068243,401.435699,20.450109,0.682432,-217.823212,0.067227,0.000000
146.090012,86.372543,-217.912186,-0.000884,0.002650,0.067323,384.204254,19.572298,0.673227,-217.912186,0.066490,0.000000
146.530014,83.360046,-217.956665,-0.000880,0.002623,0.066629,370.804016,18.889656,0.666293,-217.956665,0.065762,0.000000
146.970001,79.518280,-218.045624,-0.000884,0.002590,0.065788,353.714966,18.019098,0.657875,-218.045624,0.065024,0.000000
147.410004,76.312149,-218.045624,-0.000905,0.002561,0.065059,339.453400,17.292582,0.650593,-218.045624,0.064296,0.000000
147.850006,73.791565,-218.001144,-0.000888,0.002539,0.064496,328.241272,16.721409,0.644961,-218.001144,0.063559,0.000000
148.290009,70.012360,-218.090103,-0.000888,0.002504,0.063612,311.430542,15.865027,0.636120,-218.090103,0.062831,0.000000
148.730011,67.370743,-218.090103,-0.000875,0.002481,0.063022,299.680023,15.266428,0.630215,-218.090103,0.062093,0.000000
149.170013,63.900238,-218.179062,-0.000905,0.002448,0.062189,284.242462,14.480000,0.621889,-218.179062,0.061356,0.000000
149.610001,61.079514,-218.268021,-0.000875,0.002425,0.061591,271.695251,13.840816,0.615908,-218.268021,0.060628,0.000000
150.050003,57.207214,-218.223541,-0.000880,0.002389,0.060681,254.470398,12.963340,0.606809,-218.223541,0.059891,0.000000
150.490005,54.420006,-218.312515,-0.000888,0.002364,0.060047,242.072281,12.331750,0.600466,-218.312515,0.059162,0.000000
150.930008,51.495018,-218.312515,-0.000867,0.002335,0.059302,229.061279,11.668938,0.593017,-218.312515,0.058425,0.000000
151.370010,47.909439,-218.356995,-0.000875,0.002304,0.058530,213.111832,10.856434,0.585296,-218.356995,0.057697,0.000000
151.810013,45.296509,-218.445953,-0.000884,0.002279,0.057888,201.488937,10.264336,0.578877,-218.445953,0.056960,0.000000
152.250000,42.070641,-218.445953,-0.000888,0.002247,0.057073,187.139557,9.533343,0.570732,-218.445953,0.056222,0.000000
152.690002,39.386208,-218.490433,-0.000888,0.002223,0.056474,175.198608,8.925042,0.564737,-218.490433,0.055494,0.000000
153.130005,35.512421,-218.490433,-0.000884,0.002187,0.055546,157.967133,8.047230,0.555456,-218.490433,0.054757,0.000000
153.570007,33.261429,-218.623871,-0.000888,0.002164,0.054957,147.954224,7.537148,0.549567,-218.623871,0.054029,0.000000
154.010010,29.845284,-218.623871,-0.000880,0.002134,0.054203,132.758453,6.763038,0.542027,-218.623871,0.053291,0.000000
154.450012,27.111694,-218.668350,-0.000888,0.002106,0.053500,120.598839,6.143598,0.535002,-218.668350,0.052563,0.000000
154.890015,23.361534,-218.757324,-0.000888,0.002071,0.052598,103.917297,5.293799,0.525979,-218.757324,0.051826,0.000000
155.330002,21.195442,-218.801804,-0.000875,0.002049,0.052035,94.282036,4.802956,0.520347,-218.801804,0.051089,0.000000
155.770004,17.542839,-218.757324,-0.000897,0.002013,0.051123,78.034447,3.975264,0.511233,-218.757324,0.050360,0.000000
156.210007,14.772758,-218.890762,-0.000888,0.001986,0.050447,65.712509,3.347555,0.504466,-218.890762,0.049623,0.000000
156.650009,13.135071,-218.846283,-0.000880,0.001969,0.050014,58.427711,2.976449,0.500136,-218.846283,0.048895,0.000000
157.090012,9.405754,-218.979721,-0.000888,0.001932,0.049069,41.838882,2.131374,0.490689,-218.979721,0.048157,0.000000
157.530014,9.014763,-218.935242,-0.000897,0.001929,0.048990,40.099667,2.042774,0.489902,-218.935242,0.047429,0.000000
157.970001,4.007103,-219.024200,-0.000897,0.001877,0.047681,17.824484,0.908022,0.476806,-219.024200,0.046692,0.000000
158.410004,1.451134,-219.068680,-0.000875,0.001848,0.046943,6.454965,0.328832,0.469433,-219.068680,0.045964,0.000000
158.850006,-1.276489,-219.024200,-0.000884,0.001817,0.046155,-5.678108,-0.289257,0.461545,-219.024200,0.045226,0.000000
159.290009,-2.427120,-219.157639,-0.000880,0.001794,0.045557,-10.796370,-0.549993,0.455565,-219.157639,0.044489,0.000000
159.730011,-0.228638,-219.113159,-0.000875,0.001761,0.044731,-1.017031,-0.051810,0.447314,-219.113159,0.043761,0.000000
160.170013,-0.170914,-219.202133,-0.000897,0.001732,0.044003,-0.760262,-0.038730,0.440032,-219.202133,0.043024,0.000000
160.610001,-0.117294,-219.380051,-0.000884,0.001710,0.043422,-0.521751,-0.026579,0.434218,-219.380051,0.042295,0.000000
161.050003,-0.092720,-219.335571,-0.000875,0.001674,0.042521,-0.412439,-0.021011,0.425210,-219.335571,0.041558,0.000000
161.490005,-0.094955,-219.380051,-0.000901,0.001652,0.041956,-0.422383,-0.021517,0.419563,-219.380051,0.040830,0.000000
161.930008,-0.126602,-219.380051,-0.000892,0.001614,0.041003,-0.563155,-0.028688,0.410025,-219.380051,0.040093,0.000000
162.370010,-0.164963,-219.424530,-0.000905,0.001591,0.040405,-0.733791,-0.037381,0.404045,-219.424530,0.039355,0.000000
162.810013,-0.072609,-219.557968,-0.000897,0.001557,0.039537,-0.322981,-0.016453,0.395370,-219.557968,0.038627,0.000000
163.250015,-0.096817,-219.469009,-0.000905,0.001532,0.038913,-0.430664,-0.021939,0.389133,-219.469009,0.037890,0.000000
163.690002,-0.117294,-219.557968,-0.000918,0.001499,0.038081,-0.521751,-0.026579,0.380806,-219.557968,0.037162,0.000000
164.130005,-0.179108,-219.557968,-0.000897,0.001474,0.037430,-0.796711,-0.040586,0.374296,-219.557968,0.036424,0.000000
164.570007,-0.148575,-219.602463,-0.000914,0.001444,0.036685,-0.660894,-0.033668,0.366847,-219.602463,0.035696,0.000000
165.010010,-0.169426,-219.691422,-0.000910,0.001416,0.035964,-0.753644,-0.038392,0.359641,-219.691422,0.034959,0.000000
165.450012,-0.157143,-219.691422,-0.000940,0.001385,0.035175,-0.699005,-0.035609,0.351753,-219.691422,0.034222,0.000000
165.890015,-0.169426,-219.780380,-0.000927,0.001355,0.034421,-0.753644,-0.038392,0.344213,-219.780380,0.033493,0.000000
166.330002,-0.208527,-219.780380,-0.000923,0.001323,0.033596,-0.927573,-0.047253,0.335962,-219.780380,0.032756,0.000000
166.770004,-0.221184,-219.869339,-0.000961,0.001303,0.033085,-0.983875,-0.050121,0.330845,-219.869339,0.032028,0.000000
167.210007,-0.210388,-219.958298,-0.000974,0.001275,0.032374,-0.935853,-0.047675,0.323745,-219.958298,0.031290,0.000000
167.650009,-0.210762,-219.958298,-0.001043,0.001244,0.031593,-0.937516,-0.047759,0.315933,-219.958298,0.030562,0.000000
168.090012,-0.196236,-220.091751,-0.001082,0.001214,0.030830,-0.872900,-0.044468,0.308302,-220.091751,0.029825,0.000000
168.530014,-0.193634,-220.002777,-0.001099,0.001178,0.029920,-0.861327,-0.043878,0.299204,-220.002777,0.029088,0.000000
168.970001,-0.177246,-220.047272,-0.001138,0.001152,0.029260,-0.788430,-0.040165,0.292603,-220.047272,0.028359,0.000000
169.410004,-0.191772,-220.136230,-0.001160,0.001129,0.028688,-0.853047,-0.043456,0.286880,-220.136230,0.027622,0.000000
169.850006,-0.224541,-220.180710,-0.001212,0.001097,0.027873,-0.998807,-0.050882,0.278735,-220.180710,0.026894,0.000000
170.290009,-0.234222,-220.225189,-0.001224,0.001076,0.027336,-1.041873,-0.053076,0.273360,-220.225189,0.026157,0.000000
170.730011,-0.213737,-220.269669,-0.001268,0.001039,0.026390,-0.950752,-0.048434,0.263898,-220.269669,0.025427,0.000000
171.170013,-0.214111,-220.314148,-0.001289,0.001014,0.025766,-0.952415,-0.048518,0.257661,-220.314148,0.024691,0.000000
171.610001,-0.234222,-220.314148,-0.001324,0.000983,0.024959,-1.041873,-0.053076,0.249591,-220.314148,0.023961,0.000000
172.050003,-0.242043,-220.403107,-0.001345,0.000955,0.024248,-1.076659,-0.054848,0.242476,-220.403107,0.023224,0.000000
172.490005,-0.230499,-220.403107,-0.001410,0.000917,0.023303,-1.025312,-0.052232,0.233028,-220.403107,0.022488,0.000000
172.930008,-0.217461,-220.447586,-0.001414,0.000895,0.022740,-0.967313,-0.049277,0.227396,-220.447586,0.021759,0.000000
173.370010,-0.225281,-220.536560,-0.001453,0.000865,0.021958,-1.002099,-0.051049,0.219584,-220.536560,0.021023,0.000000
173.810013,-0.248741,-220.581039,-0.001479,0.000837,0.021256,-1.106456,-0.056366,0.212560,-220.581039,0.020293,0.000000
174.250015,-0.231613,-220.581039,-0.001513,0.000808,0.020519,-1.030267,-0.052484,0.205187,-220.581039,0.019556,0.000000
174.690002,-0.196609,-220.625519,-0.001552,0.000779,0.019790,-0.874563,-0.044552,0.197905,-220.625519,0.018828,0.000000
175.130005,-0.224541,-220.625519,-0.001561,0.000749,0.019018,-0.998807,-0.050882,0.190183,-220.625519,0.018090,0.000000
175.570007,-0.215233,-220.714478,-0.001630,0.000716,0.018186,-0.957404,-0.048772,0.181857,-220.714478,0.017353,0.000000
176.010010,-0.218208,-220.758957,-0.001638,0.000695,0.017641,-0.970639,-0.049447,0.176406,-220.758957,0.016625,0.000000
176.450012,-0.202568,-220.803436,-0.001660,0.000663,0.016834,-0.901068,-0.045903,0.168337,-220.803436,0.015887,0.000000
176.890015,-0.199219,-220.847916,-0.001690,0.000645,0.016392,-0.886169,-0.045144,0.163916,-220.847916,0.015159,0.000000
177.300003,-0.167564,-220.847916,-0.001725,0.000614,0.015601,-0.745364,-0.037971,0.156013,-220.847916,0.015498,0.000000