File: Data/sima compression 500bar/P1-21-500bar-3_11072024_162858.csv
Time (sec),S:Load (lbs),S:HL1 (DIM),S:LVDT (in),S:Position (in),Ch:Position (mm),Ch:Load (N),Ch:Stress (MPa),Ch:Strain (mm/mm),Ch:HL1 (DIM),Set Point (),Cycles ()
0.010000,-0.017876,-228.276245,-0.007269,-0.003853,-0.097874,-0.079515,-0.004051,-0.978744,-228.276245,-0.097753,0.000000
0.440000,-0.047661,-228.320724,-0.007274,-0.003785,-0.096132,-0.212006,-0.010800,-0.961318,-228.320724,-0.095655,0.000000
0.870000,-0.003349,-228.409683,-0.007166,-0.003523,-0.089479,-0.014898,-0.000759,-0.894795,-228.409683,-0.088491,0.000000
1.300000,0.031281,-228.365204,-0.006868,-0.003248,-0.082499,0.139143,0.007088,-0.824986,-228.365204,-0.081328,0.000000
1.730000,-0.010422,-228.454163,-0.006592,-0.002958,-0.075127,-0.046358,-0.002362,-0.751271,-228.454163,-0.074164,0.000000
2.160000,-0.067398,-228.409683,-0.006321,-0.002676,-0.067981,-0.299802,-0.015273,-0.679813,-228.409683,-0.067002,0.000000
2.590000,-0.055107,-228.498642,-0.006053,-0.002394,-0.060819,-0.245129,-0.012487,-0.608187,-228.498642,-0.059838,0.000000
3.020000,0.027931,-228.543121,-0.005764,-0.002116,-0.053741,0.124244,0.006329,-0.537410,-228.543121,-0.052675,0.000000
3.450000,0.039474,-228.632095,-0.005493,-0.001844,-0.046839,0.175591,0.008945,-0.468388,-228.632095,-0.045511,0.000000
3.880000,0.018250,-228.676575,-0.005174,-0.001546,-0.039258,0.081178,0.004135,-0.392584,-228.676575,-0.038349,0.000000
4.310000,-0.060326,-228.676575,-0.004894,-0.001268,-0.032199,-0.268342,-0.013670,-0.321989,-228.676575,-0.031185,0.000000
4.740000,0.003723,-228.676575,-0.004596,-0.000983,-0.024958,0.016561,0.000844,-0.249576,-228.676575,-0.024022,0.000000
5.170000,0.061813,-228.765533,-0.004307,-0.000710,-0.018030,0.274960,0.014007,-0.180297,-228.765533,-0.016858,0.000000
5.600000,0.059578,-228.810013,-0.004018,-0.000430,-0.010926,0.265016,0.013501,-0.109262,-228.810013,-0.009695,0.000000
6.030000,0.058090,-228.854492,-0.003725,-0.000138,-0.003512,0.258398,0.013163,-0.035124,-228.854492,-0.002531,0.000000
6.460001,0.089371,-228.854492,-0.003635,-0.000007,-0.000182,0.397541,0.020252,-0.001817,-228.854492,0.000035,0.000000
6.890000,0.056602,-228.898972,-0.003648,-0.000007,-0.000182,0.251780,0.012826,-0.001817,-228.898972,0.000398,0.000000
7.320000,0.108360,-229.032410,-0.003660,0.000016,0.000398,0.482011,0.024555,0.003982,-229.032410,0.001119,0.000000
7.750000,0.221565,-229.032410,-0.003639,0.000040,0.001023,0.985571,0.050207,0.010234,-229.032410,0.001830,0.000000
8.180000,0.486694,-229.032410,-0.003613,0.000068,0.001726,2.164925,0.110287,0.017259,-229.032410,0.002550,0.000000
8.610001,1.006523,-229.121384,-0.003587,0.000096,0.002428,4.477239,0.228081,0.024284,-229.121384,0.003269,0.000000
9.040000,1.869682,-229.076904,-0.003553,0.000126,0.003208,8.316762,0.423676,0.032081,-229.076904,0.003980,0.000000
9.470000,2.629700,-229.210342,-0.003544,0.000150,0.003799,11.697489,0.595898,0.037985,-229.210342,0.004701,0.000000
9.900001,3.887573,-229.254822,-0.003523,0.000181,0.004587,17.292789,0.880937,0.045873,-229.254822,0.005420,0.000000
10.330001,4.999100,-229.254822,-0.003505,0.000207,0.005255,22.237106,1.132812,0.052549,-229.254822,0.006132,0.000000
10.760000,6.609985,-229.254822,-0.003471,0.000238,0.006053,29.402683,1.497844,0.060528,-229.254822,0.006851,0.000000
11.190001,7.677208,-229.343781,-0.003462,0.000260,0.006608,34.149925,1.739680,0.066084,-229.343781,0.007571,0.000000
11.620001,9.529388,-229.432739,-0.003449,0.000295,0.007493,42.388836,2.159390,0.074926,-229.432739,0.008281,0.000000
12.050000,10.976799,-229.477234,-0.003423,0.000322,0.008186,48.827240,2.487378,0.081860,-229.477234,0.009002,0.000000
12.480000,12.470009,-229.477234,-0.003428,0.000350,0.008881,55.469368,2.825744,0.088809,-229.477234,0.009721,0.000000
12.910001,14.086105,-229.521713,-0.003402,0.000379,0.009626,62.658127,3.191957,0.096257,-229.521713,0.010433,0.000000
13.340001,15.329460,-229.521713,-0.003380,0.000400,0.010163,68.188843,3.473705,0.101632,-229.521713,0.011152,0.000000
13.770000,17.296333,-229.610672,-0.003354,0.000435,0.011040,76.937935,3.919405,0.110398,-229.610672,0.011863,0.000000
14.200001,18.589577,-229.655151,-0.003367,0.000460,0.011691,82.690567,4.212458,0.116908,-229.655151,0.012584,0.000000
14.630001,20.414574,-229.610672,-0.003341,0.000492,0.012505,90.808556,4.626009,0.125053,-229.610672,0.013303,0.000000
15.060000,21.710808,-229.655151,-0.003320,0.000515,0.013068,96.574493,4.919739,0.130685,-229.655151,0.014015,0.000000
15.490001,22.707275,-229.744110,-0.003311,0.000536,0.013606,101.007004,5.145542,0.136059,-229.744110,0.014734,0.000000
15.920001,24.978745,-229.788589,-0.003285,0.000577,0.014648,111.111008,5.660264,0.146475,-229.788589,0.015454,0.000000
16.350000,26.260826,-229.744110,-0.003281,0.000600,0.015229,116.813988,5.950788,0.152289,-229.744110,0.016165,0.000000
16.780001,28.009117,-229.833069,-0.003247,0.000632,0.016052,124.590775,6.346957,0.160525,-229.833069,0.016885,0.000000
17.210001,29.185814,-229.877548,-0.003247,0.000653,0.016590,129.824982,6.613600,0.165900,-229.877548,0.017604,0.000000
17.640001,30.968361,-229.922043,-0.003238,0.000685,0.017397,137.754150,7.017531,0.173969,-229.922043,0.018316,0.000000
18.070002,32.310387,-230.011002,-0.003225,0.000712,0.018081,143.723785,7.321639,0.180812,-230.011002,0.019035,0.000000
18.500000,33.295311,-229.966522,-0.003221,0.000736,0.018706,148.104935,7.544825,0.187065,-229.966522,0.019756,0.000000
18.930000,35.039505,-230.055481,-0.003199,0.000768,0.019512,155.863510,7.940065,0.195119,-230.055481,0.020466,0.000000
19.360001,35.850159,-230.099960,-0.003165,0.000794,0.020163,159.469467,8.123762,0.201629,-230.099960,0.021186,0.000000
19.790001,37.942520,-230.055481,-0.003139,0.000828,0.021030,168.776764,8.597898,0.210304,-230.055481,0.021898,0.000000
20.220001,38.842918,-230.144440,-0.003126,0.000855,0.021707,172.781937,8.801931,0.217071,-230.144440,0.022617,0.000000
20.650002,40.019241,-230.099960,-0.003104,0.000882,0.022401,178.014481,9.068490,0.224005,-230.099960,0.023338,0.000000
21.080002,40.304108,-230.188919,-0.003096,0.000898,0.022817,179.281631,9.133040,0.228169,-230.188919,0.024048,0.000000
21.510000,42.575211,-230.188919,-0.003053,0.000940,0.023875,189.384003,9.647680,0.238751,-230.188919,0.024768,0.000000
21.940001,43.458473,-230.322357,-0.003035,0.000967,0.024550,193.312943,9.847831,0.245503,-230.322357,0.025487,0.000000
22.370001,44.479523,-230.411331,-0.003035,0.000996,0.025288,197.854797,10.079204,0.252876,-230.411331,0.026199,0.000000
22.800001,45.323685,-230.322357,-0.003005,0.001022,0.025948,201.609818,10.270494,0.259477,-230.322357,0.026918,0.000000
23.230001,45.814850,-230.411331,-0.002979,0.001043,0.026494,203.794632,10.381794,0.264943,-230.411331,0.027639,0.000000
23.660002,47.395569,-230.366852,-0.002932,0.001080,0.027421,210.826019,10.739990,0.274208,-230.366852,0.028349,0.000000
24.090002,48.317192,-230.500290,-0.002940,0.001106,0.028081,214.925598,10.948833,0.280809,-230.500290,0.029070,0.000000
24.520000,49.564262,-230.500290,-0.002919,0.001138,0.028904,220.472855,11.231422,0.289045,-230.500290,0.029789,0.000000
24.950001,50.336937,-230.455811,-0.002897,0.001164,0.029572,223.909882,11.406513,0.295721,-230.455811,0.030500,0.000000
25.380001,51.257812,-230.544769,-0.002876,0.001194,0.030319,228.006134,11.615186,0.303185,-230.544769,0.031219,0.000000
25.810001,52.041290,-230.589249,-0.002859,0.001220,0.030986,231.491226,11.792726,0.309862,-230.589249,0.031940,0.000000
26.240002,52.758476,-230.678207,-0.002815,0.001249,0.031714,234.681427,11.955241,0.317144,-230.678207,0.032652,0.000000
26.670002,53.718079,-230.767181,-0.002807,0.001276,0.032408,238.949951,12.172690,0.324078,-230.767181,0.033371,0.000000
27.100000,53.679726,-230.767181,-0.002790,0.001298,0.032963,238.779343,12.164000,0.329634,-230.767181,0.034082,0.000000
27.530001,55.596329,-230.767181,-0.002746,0.001338,0.033987,247.304825,12.598309,0.339868,-230.767181,0.034801,0.000000
27.960001,56.239418,-230.811661,-0.002712,0.001363,0.034629,250.165421,12.744034,0.346288,-230.811661,0.035522,0.000000
28.390001,57.158806,-230.900620,-0.002708,0.001393,0.035383,254.255066,12.952371,0.353827,-230.900620,0.036232,0.000000
28.820002,57.531174,-230.945099,-0.002673,0.001416,0.035964,255.911438,13.036750,0.359641,-230.945099,0.036953,0.000000
29.250002,59.004654,-230.989578,-0.002665,0.001451,0.036848,262.465820,13.370646,0.368482,-230.989578,0.037672,0.000000
29.680002,59.273132,-230.945099,-0.002634,0.001474,0.037446,263.660065,13.431484,0.374462,-230.945099,0.038383,0.000000
30.110001,60.182465,-230.989578,-0.002630,0.001506,0.038244,267.704987,13.637541,0.382441,-230.989578,0.039103,0.000000
30.540001,60.761505,-231.078537,-0.002583,0.001529,0.038825,270.280670,13.768754,0.388255,-231.078537,0.039823,0.000000
30.970001,61.155479,-231.123016,-0.002565,0.001551,0.039407,272.033173,13.858029,0.394068,-231.123016,0.040535,0.000000
31.400002,62.794289,-231.123016,-0.002544,0.001591,0.040405,279.322937,14.229389,0.404045,-231.123016,0.041254,0.000000
31.830002,63.472000,-231.211990,-0.002522,0.001618,0.041098,282.337555,14.382960,0.410979,-231.211990,0.041973,0.000000
32.260002,64.458420,-231.211990,-0.002492,0.001647,0.041843,286.725372,14.606486,0.418428,-231.211990,0.042685,0.000000
32.690002,65.070221,-231.211990,-0.002466,0.001672,0.042459,289.446808,14.745123,0.424590,-231.211990,0.043405,0.000000
33.120003,66.075638,-231.300949,-0.002449,0.001701,0.043214,293.919128,14.972954,0.432144,-231.300949,0.044115,0.000000
33.550003,66.826706,-231.300949,-0.002414,0.001728,0.043882,297.260040,15.143147,0.438821,-231.300949,0.044836,0.000000
33.980003,67.668640,-231.345428,-0.002414,0.001757,0.044627,301.005157,15.333934,0.446269,-231.345428,0.045555,0.000000
34.410000,68.599197,-231.478867,-0.002363,0.001785,0.045348,305.144470,15.544801,0.453476,-231.478867,0.046267,0.000000
34.840000,68.682617,-231.434387,-0.002354,0.001803,0.045790,305.515533,15.563704,0.457897,-231.434387,0.046986,0.000000
35.270000,70.653580,-231.612305,-0.002324,0.001844,0.046830,314.282806,16.010330,0.468297,-231.612305,0.047706,0.000000
35.700001,71.025208,-231.523346,-0.002302,0.001867,0.047420,315.935913,16.094542,0.474202,-231.523346,0.048416,0.000000
36.130001,72.716156,-231.478867,-0.002272,0.001901,0.048288,323.457611,16.477716,0.482877,-231.478867,0.049137,0.000000
36.560001,73.426270,-231.656799,-0.002251,0.001925,0.048902,326.616364,16.638630,0.489024,-231.656799,0.049856,0.000000
36.990002,74.646896,-231.701279,-0.002233,0.001957,0.049709,332.045990,16.915228,0.497093,-231.701279,0.050568,0.000000
37.420002,75.260574,-231.701279,-0.002207,0.001982,0.050333,334.775757,17.054291,0.503330,-231.701279,0.051288,0.000000
37.850002,76.259277,-231.745758,-0.002186,0.002010,0.051045,339.218201,17.280600,0.510446,-231.745758,0.052007,0.000000
38.280003,77.411774,-231.745758,-0.002164,0.002038,0.051773,344.344757,17.541759,0.517728,-231.745758,0.052719,0.000000
38.710003,77.384216,-231.790237,-0.002139,0.002056,0.052233,344.222198,17.535515,0.522331,-231.790237,0.053438,0.000000
39.140003,79.383102,-231.879196,-0.002100,0.002094,0.053187,353.113678,17.988468,0.531869,-231.879196,0.054150,0.000000
39.570004,80.371017,-231.923676,-0.002104,0.002120,0.053838,357.508148,18.212334,0.538379,-231.923676,0.054869,0.000000
40.000000,81.687347,-231.879196,-0.002074,0.002150,0.054601,363.363464,18.510618,0.546009,-231.879196,0.055590,0.000000
40.430000,81.994934,-231.923676,-0.002057,0.002168,0.055069,364.731689,18.580318,0.550687,-231.923676,0.056300,0.000000
40.860001,84.271988,-232.012634,-0.002031,0.002208,0.056083,374.860535,19.096306,0.560831,-232.012634,0.057020,0.000000
41.290001,85.169403,-232.101608,-0.002009,0.002234,0.056751,378.852417,19.299662,0.567507,-232.101608,0.057739,0.000000
41.720001,85.670624,-232.101608,-0.001996,0.002256,0.057306,381.081970,19.413242,0.573063,-232.101608,0.058451,0.000000
42.150002,87.615891,-232.101608,-0.001975,0.002291,0.058190,389.734955,19.854044,0.581905,-232.101608,0.059170,0.000000
42.580002,87.993103,-232.146088,-0.001936,0.002308,0.058633,391.412872,19.939522,0.586326,-232.146088,0.059891,0.000000
43.010002,90.483902,-232.190567,-0.001923,0.002351,0.059709,402.492493,20.503946,0.597090,-232.190567,0.060602,0.000000
43.440002,91.442764,-232.235046,-0.001901,0.002376,0.060349,406.757721,20.721226,0.603494,-232.235046,0.061321,0.000000
43.870003,92.703247,-232.324005,-0.001880,0.002402,0.061019,412.364624,21.006855,0.610186,-232.324005,0.062040,0.000000
44.300003,93.292709,-232.279526,-0.001867,0.002423,0.061538,414.986694,21.140430,0.615378,-232.279526,0.062752,0.000000
44.730003,95.623383,-232.324005,-0.001824,0.002461,0.062519,425.354034,21.668568,0.625189,-232.324005,0.063473,0.000000
45.160004,96.678314,-232.324005,-0.001811,0.002488,0.063194,430.046631,21.907618,0.631941,-232.324005,0.064192,0.000000
45.590004,98.033005,-232.412964,-0.001807,0.002516,0.063897,436.072571,22.214596,0.638966,-232.412964,0.064903,0.000000
46.020000,99.850189,-232.501938,-0.001798,0.002546,0.064660,444.155823,22.626375,0.646596,-232.501938,0.065623,0.000000
46.450001,100.320129,-232.457443,-0.001785,0.002563,0.065103,446.246216,22.732866,0.651032,-232.457443,0.066334,0.000000
46.880001,102.445251,-232.501938,-0.001750,0.002599,0.066013,455.699249,23.214426,0.660131,-232.501938,0.067053,0.000000
47.310001,103.708710,-232.590897,-0.001725,0.002627,0.066716,461.319366,23.500729,0.667156,-232.590897,0.067774,0.000000
47.740002,105.790268,-232.590897,-0.001712,0.002659,0.067548,470.578613,23.972418,0.675483,-232.590897,0.068485,0.000000
48.170002,107.462219,-232.635376,-0.001716,0.002688,0.068267,478.015839,24.351288,0.682674,-232.635376,0.069205,0.000000
48.600002,109.005341,-232.635376,-0.001686,0.002714,0.068944,484.879974,24.700964,0.689441,-232.635376,0.069924,0.000000
49.030003,110.828476,-232.679855,-0.001656,0.002743,0.069681,492.989685,25.114092,0.696814,-232.679855,0.070635,0.000000
49.460003,112.163422,-232.724335,-0.001651,0.002768,0.070314,498.927826,25.416595,0.703143,-232.724335,0.071356,0.000000
49.890003,114.415543,-232.768814,-0.001630,0.002800,0.071112,508.945740,25.926931,0.711121,-232.768814,0.072075,0.000000
50.320004,115.304016,-232.813293,-0.001634,0.002816,0.071538,512.897888,26.128263,0.715375,-232.813293,0.072787,0.000000
50.750004,118.294907,-232.857773,-0.001613,0.002854,0.072482,526.202026,26.806009,0.724823,-232.857773,0.073506,0.000000
51.180004,120.264389,-232.946747,-0.001595,0.002882,0.073203,534.962708,27.252300,0.732029,-232.946747,0.074226,0.000000
51.610001,123.046387,-232.902252,-0.001600,0.002913,0.074001,547.337646,27.882711,0.740008,-232.902252,0.074936,0.000000
52.040001,124.387299,-233.035706,-0.001582,0.002936,0.074573,553.302368,28.186563,0.745730,-233.035706,0.075657,0.000000
52.470001,127.460114,-233.035706,-0.001574,0.002968,0.075397,566.970886,28.882875,0.753966,-233.035706,0.076367,0.000000
52.900002,129.971771,-233.080185,-0.001574,0.002999,0.076169,578.143311,29.452024,0.761687,-233.080185,0.077088,0.000000
53.330002,132.363144,-233.080185,-0.001548,0.003026,0.076862,588.780640,29.993917,0.768621,-233.080185,0.077807,0.000000
53.760002,135.120560,-233.124664,-0.001556,0.003054,0.077581,601.046265,30.618757,0.775813,-233.124664,0.078518,0.000000
54.190002,136.868103,-233.213623,-0.001535,0.003075,0.078111,608.819702,31.014755,0.781111,-233.213623,0.079238,0.000000
54.620003,139.841873,-233.213623,-0.001548,0.003107,0.078909,622.047729,31.688622,0.789090,-233.213623,0.079958,0.000000
55.050003,142.501724,-233.258102,-0.001526,0.003137,0.079689,633.879333,32.291351,0.796887,-233.258102,0.080670,0.000000
55.480003,145.177231,-233.302582,-0.001505,0.003164,0.080375,645.780579,32.897633,0.803745,-233.302582,0.081389,0.000000
55.910004,147.362305,-233.302582,-0.001500,0.003185,0.080895,655.500244,33.392776,0.808953,-233.302582,0.082110,0.000000
56.340004,149.255829,-233.347076,-0.001492,0.003206,0.081424,663.923096,33.821854,0.814237,-233.347076,0.082820,0.000000
56.770004,153.574600,-233.436035,-0.001496,0.003249,0.082533,683.133911,34.800503,0.825334,-233.436035,0.083540,0.000000
57.200005,156.233337,-233.480515,-0.001487,0.003276,0.083210,694.960571,35.402981,0.832102,-233.480515,0.084259,0.000000
57.630001,159.440948,-233.480515,-0.001487,0.003306,0.083982,709.228760,36.129833,0.839823,-233.480515,0.084971,0.000000
58.060001,161.418243,-233.524994,-0.001466,0.003325,0.084450,718.024231,36.577896,0.844501,-233.524994,0.085690,0.000000
58.490002,164.930099,-233.569473,-0.001462,0.003359,0.085327,733.645752,37.373692,0.853267,-233.569473,0.086411,0.000000
58.920002,167.257797,-233.658432,-0.001470,0.003383,0.085916,743.999817,37.901157,0.859156,-233.658432,0.087121,0.000000
59.350002,170.500046,-233.658432,-0.001457,0.003416,0.086774,758.422058,38.635864,0.867740,-233.658432,0.087841,0.000000
59.780003,173.204208,-233.702911,-0.001453,0.003439,0.087346,770.450806,39.248638,0.873463,-233.702911,0.088553,0.000000
60.210003,174.898514,-233.702911,-0.001453,0.003455,0.087755,777.987427,39.632572,0.877551,-233.702911,0.089272,0.000000
60.640003,178.364548,-233.791885,-0.001449,0.003487,0.088579,793.405151,40.417984,0.885787,-233.791885,0.089991,0.000000
61.070004,181.753510,-233.880844,-0.001431,0.003521,0.089437,808.479980,41.185932,0.894371,-233.880844,0.090703,0.000000
61.500004,184.870636,-233.925323,-0.001457,0.003552,0.090217,822.345642,41.892288,0.902168,-233.925323,0.091423,0.000000
61.930004,187.569595,-233.880844,-0.001427,0.003578,0.090893,834.351257,42.503876,0.908935,-233.880844,0.092143,0.000000
62.360004,191.464600,-233.969803,-0.001427,0.003613,0.091778,851.677063,43.386497,0.917776,-233.969803,0.092854,0.000000
62.790005,193.852264,-234.014282,-0.001423,0.003637,0.092385,862.297913,43.927551,0.923847,-234.014282,0.093573,0.000000
63.220001,197.202881,-234.014282,-0.001423,0.003667,0.093140,877.202209,44.686813,0.931402,-234.014282,0.094294,0.000000
63.650002,199.890289,-234.058762,-0.001427,0.003692,0.093773,889.156433,45.295784,0.937730,-234.058762,0.095004,0.000000
64.080002,201.523499,-234.103241,-0.001440,0.003708,0.094171,896.421265,45.665878,0.941712,-234.103241,0.095725,0.000000
64.510002,206.176300,-234.147720,-0.001427,0.003751,0.095282,917.117981,46.720219,0.952825,-234.147720,0.096444,0.000000
64.940002,208.716248,-234.192200,-0.001397,0.003776,0.095906,928.416260,47.295776,0.959062,-234.192200,0.097155,0.000000
65.370003,211.700073,-234.281174,-0.001406,0.003806,0.096669,941.688965,47.971924,0.966692,-234.281174,0.097874,0.000000
65.800003,214.497711,-234.281174,-0.001423,0.003832,0.097329,954.133484,48.605877,0.973293,-234.281174,0.098586,0.000000
66.230003,217.910492,-234.281174,-0.001406,0.003865,0.098179,969.314270,49.379223,0.981787,-234.281174,0.099307,0.000000
66.660004,220.429230,-234.325653,-0.001406,0.003889,0.098777,980.518188,49.949978,0.987767,-234.325653,0.100026,0.000000
67.090004,220.609833,-234.414612,-0.001410,0.003876,0.098456,981.321533,49.990902,0.984557,-234.414612,982.000671,0.000000
67.520004,220.329071,-234.459091,-0.001397,0.003875,0.098413,980.072632,49.927280,0.984133,-234.459091,982.000671,0.000000
67.950005,220.068787,-234.548050,-0.001384,0.003875,0.098413,978.914856,49.868301,0.984133,-234.548050,982.000671,0.000000
68.380005,219.822266,-234.548050,-0.001397,0.003875,0.098421,977.818298,49.812435,0.984209,-234.548050,982.000671,0.000000
68.810005,219.577240,-234.548050,-0.001393,0.003875,0.098421,976.728333,49.756916,0.984209,-234.548050,982.000671,0.000000
69.240005,219.324402,-234.637024,-0.001384,0.003875,0.098421,975.603638,49.699619,0.984209,-234.637024,982.000671,0.000000
69.670006,219.348236,-234.592529,-0.001393,0.003903,0.099142,975.709656,49.705021,0.991415,-234.592529,982.000671,0.000000
70.100006,220.530151,-234.681503,-0.001375,0.003884,0.098665,980.967102,49.972847,0.986646,-234.681503,982.000671,0.000000
70.530006,220.316772,-234.681503,-0.001384,0.003884,0.098665,980.017944,49.924492,0.986646,-234.681503,982.000671,0.000000
70.960007,220.059845,-234.681503,-0.001371,0.003884,0.098665,978.875061,49.866272,0.986646,-234.681503,982.000671,0.000000
71.390007,219.835663,-234.725983,-0.001380,0.003884,0.098665,977.877869,49.815472,0.986646,-234.725983,982.000671,0.000000
71.820000,219.602203,-234.814941,-0.001367,0.003884,0.098665,976.839417,49.762573,0.986646,-234.814941,982.000671,0.000000
72.250000,219.614471,-234.948380,-0.001388,0.003901,0.099098,976.893982,49.765350,0.990976,-234.948380,982.000671,0.000000
72.680000,219.516541,-234.859421,-0.001384,0.003902,0.099107,976.458313,49.743160,0.991067,-234.859421,982.000671,0.000000
73.110001,219.621552,-234.903900,-0.001380,0.003906,0.099219,976.925476,49.766956,0.992187,-234.903900,982.000671,0.000000
73.540001,219.527710,-234.903900,-0.001358,0.003906,0.099219,976.507996,49.745689,0.992187,-234.903900,982.000671,0.000000
73.970001,219.645020,-235.037338,-0.001380,0.003910,0.099323,977.029846,49.772274,0.993232,-235.037338,982.000671,0.000000
74.400002,219.556396,-235.081833,-0.001367,0.003911,0.099349,976.635620,49.752190,0.993490,-235.081833,982.000671,0.000000
74.830002,219.560120,-235.126312,-0.001362,0.003912,0.099375,976.652161,49.753036,0.993747,-235.126312,982.000671,0.000000
75.260002,219.442444,-235.081833,-0.001371,0.003913,0.099384,976.128723,49.726368,0.993838,-235.081833,982.000671,0.000000
75.690002,219.747406,-235.126312,-0.001358,0.003918,0.099514,977.485291,49.795475,0.995140,-235.126312,982.000671,0.000000
76.120003,219.638306,-235.126312,-0.001380,0.003918,0.099514,977.000000,49.770752,0.995140,-235.126312,982.000671,0.000000
76.550003,219.545593,-235.304230,-0.001350,0.003920,0.099565,976.587585,49.749741,0.995654,-235.304230,982.000671,0.000000
76.980003,219.511322,-235.348709,-0.001375,0.003920,0.099575,976.435120,49.741974,0.995745,-235.348709,982.000671,0.000000
77.410004,219.958923,-235.304230,-0.001350,0.003926,0.099730,978.426147,49.843403,0.997305,-235.304230,982.000671,0.000000
77.840004,219.860992,-235.304230,-0.001367,0.003926,0.099730,977.990540,49.821213,0.997305,-235.304230,982.000671,0.000000
78.270004,219.745178,-235.437668,-0.001358,0.003927,0.099740,977.475342,49.794971,0.997396,-235.437668,982.000671,0.000000
78.700005,219.613739,-235.393188,-0.001362,0.003927,0.099749,976.890686,49.765186,0.997486,-235.393188,982.000671,0.000000
79.130005,219.690460,-235.482162,-0.001350,0.003932,0.099861,977.231995,49.782570,0.998607,-235.482162,982.000671,0.000000
79.560005,219.706818,-235.482162,-0.001350,0.003932,0.099861,977.304749,49.786274,0.998607,-235.482162,982.000671,0.000000
79.990005,219.664001,-235.526642,-0.001354,0.003933,0.099895,977.114258,49.776573,0.998955,-235.526642,982.000671,0.000000
80.420006,219.621918,-235.571121,-0.001354,0.003934,0.099914,976.927063,49.767040,0.999137,-235.571121,982.000671,0.000000
80.850006,219.744080,-235.615601,-0.001341,0.003937,0.100000,977.470459,49.794720,1.000000,-235.615601,982.000671,0.000000
81.280006,219.724335,-235.704559,-0.001358,0.003937,0.100009,977.382629,49.790245,1.000090,-235.704559,982.000671,0.000000
81.710007,219.684845,-235.660080,-0.001345,0.003939,0.100042,977.206970,49.781296,1.000423,-235.660080,982.000671,0.000000
82.140007,219.621185,-235.749039,-0.001341,0.003940,0.100077,976.923828,49.766869,1.000772,-235.749039,982.000671,0.000000
82.570007,219.713165,-235.749039,-0.001332,0.003941,0.100112,977.332947,49.787712,1.001120,-235.749039,982.000671,0.000000
83.000008,219.697144,-235.793518,-0.001354,0.003944,0.100173,977.261719,49.784084,1.001725,-235.793518,982.000671,0.000000
83.430000,219.663269,-235.837997,-0.001341,0.003944,0.100173,977.111023,49.776405,1.001725,-235.837997,982.000671,0.000000
83.860001,219.616730,-235.882477,-0.001332,0.003945,0.100200,976.903992,49.765862,1.001998,-235.882477,982.000671,0.000000
84.290001,219.613373,-235.971451,-0.001350,0.003946,0.100226,976.889099,49.765102,1.002255,-235.971451,982.000671,0.000000
84.720001,219.572418,-235.971451,-0.001332,0.003947,0.100251,976.706909,49.755821,1.002513,-235.971451,982.000671,0.000000
85.150002,219.529938,-236.060410,-0.001328,0.003948,0.100268,976.517944,49.746197,1.002679,-236.060410,982.000671,0.000000
85.580002,219.483398,-236.060410,-0.001350,0.003948,0.100286,976.310913,49.735649,1.002861,-236.060410,982.000671,0.000000
86.010002,219.388458,-236.060410,-0.001345,0.003948,0.100286,975.888611,49.714134,1.002861,-236.060410,982.000671,0.000000
86.440002,220.311920,-236.104889,-0.001332,0.003960,0.100581,979.996338,49.923397,1.005813,-236.104889,982.000671,0.000000
86.870003,220.317139,-236.149368,-0.001315,0.003960,0.100572,980.019592,49.924580,1.005722,-236.149368,982.000671,0.000000
87.300003,220.207306,-236.193848,-0.001341,0.003960,0.100572,979.531006,49.899689,1.005722,-236.193848,982.000671,0.000000
87.730003,220.119415,-236.193848,-0.001311,0.003960,0.100572,979.140076,49.879772,1.005722,-236.193848,982.000671,0.000000
88.160004,220.024841,-236.327286,-0.001315,0.003960,0.100572,978.719360,49.858341,1.005722,-236.327286,982.000671,0.000000
88.590004,219.881104,-236.327286,-0.001328,0.003960,0.100572,978.080017,49.825768,1.005722,-236.327286,982.000671,0.000000
89.020004,219.780945,-236.371780,-0.001315,0.003960,0.100572,977.634460,49.803078,1.005722,-236.371780,982.000671,0.000000
89.450005,219.627502,-236.371780,-0.001319,0.003960,0.100581,976.951904,49.768303,1.005813,-236.371780,982.000671,0.000000
89.880005,219.518768,-236.460739,-0.001315,0.003960,0.100581,976.468262,49.743664,1.005813,-236.460739,982.000671,0.000000
90.310005,219.399628,-236.505219,-0.001319,0.003960,0.100581,975.938293,49.716667,1.005813,-236.505219,982.000671,0.000000
90.740005,219.270050,-236.549698,-0.001306,0.003960,0.100589,975.361877,49.687305,1.005889,-236.549698,982.000671,0.000000
91.170006,219.164276,-236.549698,-0.001319,0.003960,0.100589,974.891418,49.663334,1.005889,-236.549698,982.000671,0.000000
91.600006,219.213806,-236.505219,-0.001328,0.003963,0.100668,975.111694,49.674561,1.006676,-236.505219,982.000671,0.000000
92.030006,219.157196,-236.594177,-0.001302,0.003964,0.100677,974.859924,49.661728,1.006767,-236.594177,982.000671,0.000000
92.460007,220.237091,-236.683136,-0.001315,0.003976,0.100989,979.663513,49.906441,1.009886,-236.683136,982.000671,0.000000
92.890007,220.244537,-236.727615,-0.001315,0.003976,0.100989,979.696655,49.908127,1.009886,-236.727615,982.000671,0.000000
93.320007,220.167450,-236.772110,-0.001285,0.003976,0.100989,979.353760,49.890656,1.009886,-236.772110,982.000671,0.000000
93.750008,220.107880,-236.727615,-0.001302,0.003976,0.100989,979.088745,49.877159,1.009886,-236.727615,982.000671,0.000000
94.180008,220.036011,-236.772110,-0.001302,0.003976,0.100989,978.769043,49.860874,1.009886,-236.772110,982.000671,0.000000
94.610008,219.906433,-236.905548,-0.001306,0.003976,0.100998,978.192688,49.831509,1.009977,-236.905548,982.000671,0.000000
95.040001,219.820404,-236.861069,-0.001311,0.003976,0.100998,977.809998,49.812016,1.009977,-236.861069,982.000671,0.000000
95.470001,219.712799,-236.905548,-0.001298,0.003976,0.100998,977.331360,49.787632,1.009977,-236.905548,982.000671,0.000000
95.900002,219.606293,-236.905548,-0.001302,0.003976,0.100998,976.857605,49.763496,1.009977,-236.905548,982.000671,0.000000
96.330002,219.510223,-236.994507,-0.001293,0.003976,0.100998,976.430237,49.741730,1.009977,-236.994507,982.000671,0.000000
96.760002,219.382111,-237.038986,-0.001293,0.003976,0.100998,975.860352,49.712696,1.009977,-237.038986,982.000671,0.000000
97.190002,219.283081,-237.083466,-0.001311,0.003976,0.100998,975.419861,49.690254,1.009977,-237.083466,982.000671,0.000000
97.620003,220.373383,-237.083466,-0.001293,0.003986,0.101240,980.269775,49.937325,1.012399,-237.083466,982.000671,0.000000
98.050003,220.231506,-237.127945,-0.001306,0.003986,0.101240,979.638672,49.905174,1.012399,-237.127945,982.000671,0.000000
98.480003,220.144745,-237.172424,-0.001285,0.003986,0.101240,979.252747,49.885513,1.012399,-237.172424,982.000671,0.000000
98.910004,220.050537,-237.261398,-0.001306,0.003986,0.101240,978.833679,49.864162,1.012399,-237.261398,982.000671,0.000000
99.340004,219.929871,-237.261398,-0.001285,0.003986,0.101240,978.296936,49.836823,1.012399,-237.261398,982.000671,0.000000
99.770004,219.821533,-237.261398,-0.001302,0.003986,0.101240,977.815002,49.812271,1.012399,-237.261398,982.000671,0.000000
100.200005,219.710541,-237.305878,-0.001298,0.003986,0.101240,977.321289,49.787121,1.012399,-237.305878,982.000671,0.000000
100.630005,219.602570,-237.350357,-0.001272,0.003986,0.101240,976.841003,49.762653,1.012399,-237.350357,982.000671,0.000000
101.060005,219.772369,-237.439316,-0.001298,0.003991,0.101361,977.596313,49.801132,1.013610,-237.439316,982.000671,0.000000
101.490005,219.715759,-237.483795,-0.001285,0.003991,0.101361,977.344482,49.788300,1.013610,-237.483795,982.000671,0.000000
101.920006,219.655823,-237.483795,-0.001302,0.003991,0.101370,977.077881,49.774723,1.013701,-237.483795,982.000671,0.000000
102.350006,219.588043,-237.483795,-0.001285,0.003991,0.101379,976.776428,49.759365,1.013792,-237.483795,982.000671,0.000000
102.780006,219.524353,-237.572754,-0.001281,0.003992,0.101387,976.493103,49.744930,1.013867,-237.572754,982.000671,0.000000
103.210007,219.570160,-237.572754,-0.001298,0.003994,0.101456,976.696838,49.755310,1.014564,-237.572754,982.000671,0.000000
103.640007,219.580231,-237.617233,-0.001289,0.003994,0.101456,976.741638,49.757591,1.014564,-237.617233,982.000671,0.000000
104.070007,219.521027,-237.661728,-0.001293,0.003995,0.101465,976.478271,49.744179,1.014655,-237.661728,982.000671,0.000000
104.500008,219.478577,-237.661728,-0.001285,0.003996,0.101491,976.289490,49.734554,1.014912,-237.661728,982.000671,0.000000
104.930008,219.475952,-237.750687,-0.001285,0.003996,0.101500,976.277771,49.733963,1.015003,-237.750687,982.000671,0.000000
105.360008,219.490112,-237.750687,-0.001276,0.003997,0.101535,976.340759,49.737171,1.015351,-237.750687,982.000671,0.000000
105.790009,219.471863,-237.839645,-0.001276,0.003998,0.101552,976.259583,49.733036,1.015518,-237.839645,982.000671,0.000000
106.220009,219.451385,-237.884125,-0.001289,0.003999,0.101587,976.168518,49.728397,1.015866,-237.884125,982.000671,0.000000
106.650002,219.579102,-237.884125,-0.001289,0.004001,0.101638,976.736633,49.757336,1.016381,-237.884125,982.000671,0.000000
107.080002,219.563080,-237.973083,-0.001276,0.004001,0.101638,976.665344,49.753708,1.016381,-237.973083,982.000671,0.000000
107.510002,219.656921,-237.928604,-0.001272,0.004004,0.101700,977.082764,49.774967,1.017001,-237.928604,982.000671,0.000000
107.940002,219.634583,-237.973083,-0.001276,0.004004,0.101700,976.983398,49.769905,1.017001,-237.973083,982.000671,0.000000
108.370003,219.581726,-238.017563,-0.001268,0.004004,0.101708,976.748291,49.757931,1.017077,-238.017563,982.000671,0.000000
108.800003,219.631226,-238.017563,-0.001276,0.004008,0.101803,976.968506,49.769146,1.018031,-238.017563,982.000671,0.000000
109.230003,219.753387,-238.106537,-0.001263,0.004008,0.101812,977.511902,49.796829,1.018122,-238.106537,982.000671,0.000000
109.660004,219.711670,-238.151016,-0.001272,0.004008,0.101812,977.326294,49.787376,1.018122,-238.151016,982.000671,0.000000
110.090004,219.639435,-238.239975,-0.001276,0.004008,0.101812,977.005005,49.771008,1.018122,-238.239975,982.000671,0.000000
110.520004,219.605927,-238.239975,-0.001276,0.004009,0.101829,976.855957,49.763416,1.018288,-238.239975,982.000671,0.000000
110.950005,219.803284,-238.284454,-0.001281,0.004013,0.101933,977.733826,49.808136,1.019333,-238.284454,982.000671,0.000000
111.380005,219.852417,-238.284454,-0.001268,0.004013,0.101933,977.952393,49.819267,1.019333,-238.284454,982.000671,0.000000
111.810005,219.815948,-238.328934,-0.001255,0.004013,0.101933,977.790161,49.811005,1.019333,-238.328934,982.000671,0.000000
112.240005,219.765656,-238.417892,-0.001285,0.004013,0.101933,977.566467,49.799610,1.019333,-238.417892,982.000671,0.000000
112.670006,219.696777,-238.417892,-0.001250,0.004014,0.101951,977.260071,49.784000,1.019514,-238.417892,982.000671,0.000000
113.100006,219.648743,-238.417892,-0.001281,0.004014,0.101951,977.046387,49.773117,1.019514,-238.417892,982.000671,0.000000
113.530006,219.603668,-238.506866,-0.001259,0.004014,0.101968,976.845886,49.762901,1.019681,-238.506866,982.000671,0.000000
113.960007,219.562714,-238.506866,-0.001259,0.004015,0.101977,976.663757,49.753624,1.019772,-238.506866,982.000671,0.000000
114.390007,219.526978,-238.595825,-0.001237,0.004015,0.101986,976.504761,49.745525,1.019863,-238.595825,982.000671,0.000000
114.820007,219.503143,-238.595825,-0.001281,0.004016,0.102012,976.398743,49.740124,1.020120,-238.595825,982.000671,0.000000
115.250008,219.479309,-238.640305,-0.001263,0.004017,0.102029,976.292725,49.734722,1.020287,-238.640305,982.000671,0.000000
115.680008,219.589539,-238.640305,-0.001255,0.004019,0.102082,976.783081,49.759701,1.020816,-238.640305,982.000671,0.000000
116.110008,219.569794,-238.773743,-0.001268,0.004019,0.102082,976.695251,49.755226,1.020816,-238.773743,982.000671,0.000000
116.540009,219.517303,-238.818222,-0.001259,0.004019,0.102089,976.461731,49.743332,1.020892,-238.818222,982.000671,0.000000
116.970009,219.488617,-238.818222,-0.001255,0.004020,0.102115,976.334106,49.736832,1.021150,-238.818222,982.000671,0.000000
117.400009,219.493469,-238.862701,-0.001268,0.004021,0.102142,976.355713,49.737934,1.021422,-238.862701,982.000671,0.000000
117.830002,219.637573,-238.862701,-0.001242,0.004023,0.102185,976.996704,49.770584,1.021846,-238.862701,982.000671,0.000000
118.260002,219.592133,-238.862701,-0.001255,0.004023,0.102194,976.794617,49.760288,1.021937,-238.862701,982.000671,0.000000
118.690002,219.561981,-238.951675,-0.001250,0.004023,0.102194,976.660461,49.753456,1.021937,-238.951675,982.000671,0.000000
119.120003,219.617462,-239.040634,-0.001263,0.004028,0.102307,976.907288,49.766029,1.023072,-239.040634,982.000671,0.000000
119.550003,219.802521,-239.040634,-0.001246,0.004028,0.102307,977.730469,49.807961,1.023072,-239.040634,982.000671,0.000000
119.980003,219.774963,-239.040634,-0.001259,0.004028,0.102307,977.607849,49.801720,1.023072,-239.040634,982.000671,0.000000
120.410004,219.730286,-239.129593,-0.001242,0.004028,0.102307,977.409119,49.791595,1.023072,-239.129593,982.000671,0.000000
120.840004,219.684845,-239.174072,-0.001255,0.004028,0.102315,977.206970,49.781296,1.023148,-239.174072,982.000671,0.000000
121.270004,219.630493,-239.129593,-0.001255,0.004028,0.102324,976.965210,49.768982,1.023239,-239.129593,982.000671,0.000000
121.700005,219.611115,-239.263031,-0.001255,0.004029,0.102333,976.879028,49.764591,1.023330,-239.263031,982.000671,0.000000
122.130005,219.576874,-239.218552,-0.001246,0.004030,0.102350,976.726746,49.756832,1.023496,-239.218552,982.000671,0.000000
122.560005,219.529938,-239.352005,-0.001224,0.004030,0.102350,976.517944,49.746197,1.023496,-239.352005,982.000671,0.000000
122.990005,219.499420,-239.352005,-0.001246,0.004031,0.102375,976.382202,49.739281,1.023754,-239.352005,982.000671,0.000000
123.420006,219.497925,-239.396484,-0.001246,0.004031,0.102384,976.375549,49.738941,1.023844,-239.396484,982.000671,0.000000
123.850006,219.545593,-239.440964,-0.001250,0.004033,0.102428,976.587585,49.749741,1.024283,-239.440964,982.000671,0.000000
124.280006,219.543365,-239.485443,-0.001259,0.004033,0.102428,976.577637,49.749241,1.024283,-239.485443,982.000671,0.000000
124.710007,219.531433,-239.485443,-0.001250,0.004034,0.102454,976.524597,49.746532,1.024541,-239.485443,982.000671,0.000000
125.140007,219.509857,-239.574402,-0.001250,0.004034,0.102463,976.428589,49.741646,1.024632,-239.574402,982.000671,0.000000
125.570007,219.455475,-239.618881,-0.001229,0.004034,0.102463,976.186707,49.729321,1.024632,-239.618881,982.000671,0.000000
126.000008,219.417511,-239.574402,-0.001246,0.004035,0.102480,976.017822,49.720718,1.024798,-239.574402,982.000671,0.000000
126.430008,219.429779,-239.618881,-0.001246,0.004035,0.102498,976.072388,49.723499,1.024980,-239.618881,982.000671,0.000000
126.860008,219.395905,-239.707840,-0.001220,0.004035,0.102498,975.921753,49.715824,1.024980,-239.707840,982.000671,0.000000
127.290009,219.489349,-239.752319,-0.001224,0.004038,0.102559,976.337402,49.736996,1.025585,-239.752319,5607.367676,0.000000
127.720009,219.404083,-239.796814,-0.001233,0.004020,0.102107,975.958130,49.717678,1.021074,-239.796814,0.102133,0.000000
128.150009,219.245453,-239.841293,-0.001233,0.004007,0.101768,975.252502,49.681728,1.017683,-239.841293,0.101414,0.000000
128.580002,218.913300,-239.796814,-0.001216,0.003986,0.101240,973.774963,49.606461,1.012399,-239.796814,0.100702,0.000000
129.010010,217.768250,-239.885773,-0.001229,0.003954,0.100424,968.681580,49.346989,1.004239,-239.885773,0.099982,0.000000
129.440002,216.496979,-239.974731,-0.001233,0.003926,0.099730,963.026672,49.058914,0.997305,-239.974731,0.099263,0.000000
129.870010,215.927979,-239.974731,-0.001212,0.003902,0.099116,960.495605,48.929981,0.991158,-239.974731,0.098551,0.000000
130.300003,215.610352,-239.974731,-0.001203,0.003877,0.098474,959.082764,48.858002,0.984739,-239.974731,0.097832,0.000000
130.730011,215.319550,-239.974731,-0.001203,0.003849,0.097762,957.789185,48.792107,0.977623,-239.974731,0.097111,0.000000
131.160004,214.881256,-240.108170,-0.001190,0.003813,0.096860,955.839539,48.692787,0.968600,-240.108170,0.096401,0.000000
131.590012,214.486542,-240.197128,-0.001177,0.003789,0.096253,954.083801,48.603344,0.962529,-240.197128,0.095681,0.000000
132.020004,213.699341,-240.197128,-0.001177,0.003763,0.095569,950.582153,48.424961,0.955686,-240.197128,0.094962,0.000000
132.450012,212.802307,-240.197128,-0.001177,0.003738,0.094952,946.591919,48.221691,0.949524,-240.197128,0.094250,0.000000
132.880005,211.296417,-240.152649,-0.001181,0.003713,0.094310,939.893433,47.880451,0.943105,-240.152649,0.093531,0.000000
133.310013,209.267365,-240.286102,-0.001173,0.003677,0.093408,930.867737,47.420662,0.934082,-240.286102,0.092810,0.000000
133.740005,207.183929,-240.330582,-0.001181,0.003652,0.092750,921.600159,46.948551,0.927496,-240.330582,0.092099,0.000000
134.170013,204.529663,-240.375061,-0.001164,0.003624,0.092047,909.793396,46.347084,0.920471,-240.375061,0.091379,0.000000
134.600006,201.846344,-240.375061,-0.001181,0.003599,0.091414,897.857361,45.739037,0.914143,-240.375061,0.090660,0.000000
135.030014,197.997894,-240.375061,-0.001177,0.003564,0.090521,880.738647,44.866962,0.905211,-240.375061,0.089949,0.000000
135.460007,195.536133,-240.419540,-0.001164,0.003543,0.090000,869.788147,44.309120,0.900003,-240.419540,0.089228,0.000000
135.889999,192.263733,-240.508499,-0.001164,0.003512,0.089193,855.231812,43.567585,0.891933,-240.508499,0.088518,0.000000
136.320007,189.349915,-240.552979,-0.001181,0.003486,0.088553,842.270508,42.907303,0.885529,-240.552979,0.087797,0.000000
136.750000,186.587280,-240.597458,-0.001203,0.003464,0.087981,829.981689,42.281284,0.879806,-240.597458,0.087078,0.000000
137.180008,183.092560,-240.597458,-0.001181,0.003432,0.087183,814.436401,41.489365,0.871828,-240.597458,0.086367,0.000000
137.610001,180.395096,-240.641953,-0.001164,0.003408,0.086567,802.437439,40.878113,0.865666,-240.641953,0.085648,0.000000
138.040009,176.356720,-240.730911,-0.001173,0.003371,0.085629,784.473877,39.963005,0.856295,-240.730911,0.084927,0.000000
138.470001,173.374008,-240.730911,-0.001173,0.003347,0.085022,771.206116,39.287109,0.850224,-240.730911,0.084215,0.000000
138.900009,170.228210,-240.775391,-0.001168,0.003317,0.084259,757.212891,38.574261,0.842593,-240.775391,0.083496,0.000000
139.330002,166.370056,-240.775391,-0.001164,0.003290,0.083566,740.050964,37.699993,0.835659,-240.775391,0.082777,0.000000
139.760010,163.908310,-240.819870,-0.001181,0.003266,0.082950,729.100586,37.142155,0.829498,-240.819870,0.082066,0.000000
140.190002,160.363327,-240.908829,-0.001168,0.003240,0.082291,713.331726,36.338848,0.822912,-240.908829,0.081345,0.000000
140.620010,156.687637,-240.864349,-0.001186,0.003207,0.081468,696.981445,35.505928,0.814676,-240.864349,0.080626,0.000000
141.050003,152.593765,-240.908829,-0.001186,0.003173,0.080591,678.770996,34.578243,0.805910,-240.908829,0.079914,0.000000
141.480011,150.912140,-240.953308,-0.001190,0.003155,0.080140,671.290710,34.197182,0.801399,-240.953308,0.079195,0.000000
141.910004,146.123047,-241.042267,-0.001168,0.003118,0.079195,649.987793,33.111954,0.791951,-241.042267,0.078484,0.000000
142.340012,142.983582,-241.131241,-0.001160,0.003091,0.078518,636.022766,32.400543,0.785184,-241.131241,0.077764,0.000000
142.770004,140.199356,-241.131241,-0.001186,0.003062,0.077781,623.637878,31.769627,0.777811,-241.131241,0.077044,0.000000
143.200012,136.495728,-241.131241,-0.001173,0.003037,0.077139,607.163330,30.930374,0.771392,-241.131241,0.076334,0.000000
143.630005,133.525696,-241.131241,-0.001164,0.003008,0.076394,593.951965,30.257355,0.763943,-241.131241,0.075613,0.000000
144.060013,130.753754,-241.131241,-0.001173,0.002988,0.075883,581.621765,29.629225,0.758826,-241.131241,0.074894,0.000000
144.490005,127.009171,-241.264679,-0.001168,0.002954,0.075041,564.965027,28.780689,0.750408,-241.264679,0.074182,0.000000
144.920013,123.101120,-241.264679,-0.001164,0.002920,0.074173,547.581116,27.895113,0.741733,-241.264679,0.073463,0.000000
145.350006,120.506805,-241.353638,-0.001168,0.002899,0.073636,536.041016,27.307232,0.736359,-241.353638,0.072743,0.000000
145.780014,117.449631,-241.353638,-0.001164,0.002870,0.072899,522.442078,26.614468,0.728986,-241.353638,0.072031,0.000000
146.210007,114.182434,-241.353638,-0.001164,0.002840,0.072145,507.908844,25.874109,0.721446,-241.353638,0.071312,0.000000
146.639999,110.262833,-241.487076,-0.001173,0.002806,0.071277,490.473572,24.985914,0.712771,-241.487076,0.070591,0.000000
147.070007,108.056152,-241.487076,-0.001168,0.002788,0.070826,480.657776,24.485874,0.708260,-241.487076,0.069881,0.000000
147.500000,105.009415,-241.487076,-0.001190,0.002760,0.070114,467.105194,23.795473,0.701144,-241.487076,0.069161,0.000000
147.930008,101.560501,-241.531570,-0.001173,0.002732,0.069395,451.763672,23.013939,0.693953,-241.531570,0.068451,0.000000
148.360001,97.989822,-241.531570,-0.001173,0.002698,0.068528,435.880493,22.204811,0.685278,-241.531570,0.067730,0.000000
148.790009,93.989410,-241.576050,-0.001164,0.002665,0.067678,418.085785,21.298306,0.676785,-241.576050,0.067011,0.000000
149.220001,92.137238,-241.665009,-0.001177,0.002650,0.067323,409.846893,20.878595,0.673227,-241.665009,0.066299,0.000000
149.650009,89.440887,-241.709488,-0.001181,0.002626,0.066707,397.852936,20.267593,0.667065,-241.709488,0.065580,0.000000
150.080002,85.570816,-241.709488,-0.001177,0.002590,0.065788,380.638000,19.390623,0.657875,-241.709488,0.064859,0.000000
150.510010,82.959366,-241.753967,-0.001173,0.002567,0.065206,369.021698,18.798861,0.652062,-241.753967,0.064148,0.000000
150.940002,79.292252,-241.798447,-0.001181,0.002533,0.064348,352.709564,17.967882,0.643478,-241.798447,0.063429,0.000000
151.370010,77.250153,-241.887405,-0.001190,0.002509,0.063732,343.625854,17.505135,0.637316,-241.887405,0.062710,0.000000
151.800003,72.949997,-241.931900,-0.001181,0.002478,0.062943,324.497803,16.530704,0.629428,-241.931900,0.061998,0.000000
152.230011,69.963577,-241.931900,-0.001190,0.002450,0.062240,311.213531,15.853973,0.622403,-241.931900,0.061277,0.000000
152.660004,65.995941,-241.976379,-0.001181,0.002415,0.061338,293.564606,14.954894,0.613380,-241.976379,0.060558,0.000000
153.090012,63.225494,-241.931900,-0.001181,0.002391,0.060723,281.241058,14.327102,0.607233,-241.931900,0.059847,0.000000
153.520004,59.664871,-242.065338,-0.001168,0.002358,0.059882,265.402588,13.520252,0.598816,-242.065338,0.059128,0.000000
153.950012,56.763344,-242.065338,-0.001186,0.002333,0.059249,252.495956,12.862758,0.592487,-242.065338,0.058407,0.000000
154.380005,54.667259,-242.154297,-0.001177,0.002311,0.058702,243.172119,12.387778,0.587022,-242.154297,0.057697,0.000000
154.810013,50.689575,-242.109818,-0.001173,0.002277,0.057827,225.478485,11.486423,0.578271,-242.109818,0.056976,0.000000
155.240005,48.331711,-242.198776,-0.001168,0.002253,0.057237,214.990189,10.952123,0.572367,-242.198776,0.056265,0.000000
155.670013,45.032494,-242.243256,-0.001186,0.002226,0.056534,200.314529,10.204509,0.565342,-242.243256,0.055546,0.000000
156.100006,42.008827,-242.332214,-0.001186,0.002195,0.055762,186.864594,9.519337,0.557621,-242.332214,0.054826,0.000000
156.530014,38.407616,-242.243256,-0.001181,0.002162,0.054904,170.845612,8.703290,0.549037,-242.243256,0.054115,0.000000
156.960007,36.535698,-242.243256,-0.001177,0.002142,0.054410,162.518906,8.279107,0.544101,-242.243256,0.053394,0.000000
157.390015,32.536049,-242.332214,-0.001186,0.002104,0.053429,144.727570,7.372774,0.534291,-242.332214,0.052675,0.000000
157.820007,30.059021,-242.376709,-0.001155,0.002080,0.052840,133.709198,6.811471,0.528402,-242.376709,0.051964,0.000000
158.250000,28.125664,-242.465668,-0.001177,0.002061,0.052354,125.109200,6.373366,0.523542,-242.465668,0.051244,0.000000
158.680008,24.657387,-242.465668,-0.001168,0.002026,0.051461,109.681534,5.587444,0.514609,-242.465668,0.050524,0.000000
159.110001,22.404160,-242.421188,-0.001173,0.002005,0.050923,99.658676,5.076855,0.509235,-242.421188,0.049814,0.000000
159.540009,18.501328,-242.510147,-0.001177,0.001970,0.050047,82.298012,4.192461,0.500469,-242.510147,0.049093,0.000000
159.970001,15.861954,-242.554626,-0.001160,0.001943,0.049363,70.557495,3.594370,0.493626,-242.554626,0.048374,0.000000
160.400009,12.601089,-242.599106,-0.001173,0.001909,0.048478,56.052444,2.855448,0.484784,-242.599106,0.047662,0.000000
160.830002,10.449890,-242.688065,-0.001186,0.001890,0.048018,46.483433,2.367979,0.480182,-242.688065,0.046943,0.000000
161.260010,7.198708,-242.643585,-0.001168,0.001856,0.047151,32.021450,1.631250,0.471507,-242.643585,0.046232,0.000000
161.690002,5.021820,-242.688065,-0.001173,0.001833,0.046569,22.338171,1.137961,0.465693,-242.688065,0.045513,0.000000
162.120010,2.191788,-242.777023,-0.001168,0.001806,0.045867,9.749558,0.496666,0.458669,-242.777023,0.044792,0.000000
162.550003,-0.927208,-242.821518,-0.001164,0.001769,0.044922,-4.124427,-0.210108,0.449222,-242.821518,0.044080,0.000000
162.980011,-1.928886,-242.821518,-0.001173,0.001745,0.044332,-8.580115,-0.437092,0.443317,-242.821518,0.043361,0.000000
163.410004,-0.150810,-242.865997,-0.001168,0.001715,0.043569,-0.670837,-0.034174,0.435687,-242.865997,0.042641,0.000000
163.840012,-0.130325,-242.910477,-0.001168,0.001688,0.042875,-0.579716,-0.029532,0.428753,-242.910477,0.041931,0.000000
164.270004,-0.161232,-242.954956,-0.001190,0.001656,0.042061,-0.717196,-0.036536,0.420608,-242.954956,0.041210,0.000000
164.700012,-0.151184,-242.954956,-0.001194,0.001635,0.041531,-0.672500,-0.034259,0.415309,-242.954956,0.040491,0.000000
165.130005,-0.176506,-243.043915,-0.001177,0.001605,0.040777,-0.785138,-0.039997,0.407769,-243.043915,0.039779,0.000000
165.560013,-0.195496,-243.043915,-0.001164,0.001578,0.040084,-0.869608,-0.044300,0.400836,-243.043915,0.039060,0.000000
165.990005,-0.166824,-243.043915,-0.001177,0.001551,0.039389,-0.742072,-0.037803,0.393886,-243.043915,0.038339,0.000000
166.420013,-0.153786,-243.088394,-0.001181,0.001514,0.038444,-0.684073,-0.034848,0.384439,-243.088394,0.037629,0.000000
166.850006,-0.147087,-243.132874,-0.001186,0.001493,0.037916,-0.654276,-0.033330,0.379156,-243.132874,0.036909,0.000000
167.280014,-0.161980,-243.266327,-0.001190,0.001466,0.037230,-0.720522,-0.036705,0.372297,-243.266327,0.036190,0.000000
167.710007,-0.152672,-243.221848,-0.001186,0.001434,0.036423,-0.679118,-0.034596,0.364228,-243.221848,0.035478,0.000000
168.140015,-0.141502,-243.221848,-0.001194,0.001404,0.035669,-0.629434,-0.032065,0.356688,-243.221848,0.034759,0.000000
168.570007,-0.180969,-243.266327,-0.001194,0.001379,0.035036,-0.804991,-0.041008,0.350360,-243.266327,0.034047,0.000000
169.000015,-0.194008,-243.399765,-0.001199,0.001349,0.034264,-0.862990,-0.043963,0.342639,-243.399765,0.033327,0.000000
169.430008,-0.188789,-243.444244,-0.001194,0.001344,0.034134,-0.839777,-0.042780,0.341337,-243.444244,0.032608,0.000000
169.860001,-0.188789,-243.399765,-0.001216,0.001290,0.032764,-0.839777,-0.042780,0.327636,-243.399765,0.031896,0.000000
170.290009,-0.183205,-243.444244,-0.001229,0.001260,0.032010,-0.814935,-0.041515,0.320096,-243.444244,0.031177,0.000000
170.720001,-0.182465,-243.444244,-0.001220,0.001236,0.031393,-0.811643,-0.041347,0.313934,-243.444244,0.030456,0.000000
171.150009,-0.196236,-243.488724,-0.001237,0.001207,0.030665,-0.872900,-0.044468,0.306652,-243.488724,0.029746,0.000000
171.580002,-0.221184,-243.622162,-0.001237,0.001181,0.029998,-0.983875,-0.050121,0.299976,-243.622162,0.029026,0.000000
172.010010,-0.227516,-243.577682,-0.001263,0.001149,0.029191,-1.012043,-0.051556,0.291906,-243.577682,0.028306,0.000000
172.440002,-0.229752,-243.622162,-0.001315,0.001129,0.028670,-1.021986,-0.052062,0.286698,-243.622162,0.027595,0.000000
172.870010,-0.218956,-243.622162,-0.001345,0.001095,0.027811,-0.973965,-0.049616,0.278114,-243.622162,0.026876,0.000000
173.200012,-0.177246,-243.755615,-0.001384,0.001083,0.027509,-0.788430,-0.040165,0.275086,-243.755615,0.027387,0.000000