File: Data/sima compression 500bar/P1-21-300bar-1_11072024_161733.csv
Time (sec),S:Load (lbs),S:HL1 (DIM),S:LVDT (in),S:Position (in),Ch:Position (mm),Ch:Load (N),Ch:Stress (MPa),Ch:Strain (mm/mm),Ch:HL1 (DIM),Set Point (),Cycles ()
0.010000,0.028305,-155.505402,-0.004945,-0.004774,-0.121256,0.125907,0.006414,-1.212559,-155.505402,-0.121098,0.000000
0.380000,0.001122,-155.594360,-0.004954,-0.004747,-0.120579,0.004989,0.000254,-1.205792,-155.594360,-0.120042,0.000000
0.750000,0.024582,-155.594360,-0.004898,-0.004523,-0.114881,0.109346,0.005570,-1.148806,-155.594360,-0.113866,0.000000
1.120000,0.025696,-155.683334,-0.004678,-0.004293,-0.109044,0.114301,0.005823,-1.090443,-155.683334,-0.107709,0.000000
1.490000,0.069267,-155.683334,-0.004419,-0.004051,-0.102887,0.308116,0.015696,-1.028871,-155.683334,-0.101552,0.000000
1.860000,0.093468,-155.816772,-0.004156,-0.003801,-0.096539,0.415765,0.021180,-0.965390,-155.816772,-0.095378,0.000000
2.230000,0.061813,-155.816772,-0.004130,-0.000005,-0.000121,0.274960,0.014007,-0.001211,-155.816772,-0.000017,0.000000
2.600000,0.055489,-155.816772,-0.004109,-0.000005,-0.000130,0.246826,0.012574,-0.001302,-155.816772,0.000244,0.000000
2.970000,0.103149,-155.905731,-0.004122,-0.000000,-0.000000,0.458832,0.023374,-0.000000,-155.905731,0.000867,0.000000
3.340000,0.098312,-155.994690,-0.004130,0.000026,0.000660,0.437315,0.022278,0.006601,-155.994690,0.001484,0.000000
3.710000,0.052505,-156.083664,-0.004109,0.000044,0.001119,0.233556,0.011898,0.011188,-156.083664,0.002098,0.000000
4.080000,0.064423,-156.039169,-0.004079,0.000073,0.001865,0.286566,0.014598,0.018652,-156.039169,0.002715,0.000000
4.450000,0.055489,-156.172623,-0.004057,0.000093,0.002368,0.246826,0.012574,0.023678,-156.172623,0.003331,0.000000
4.820000,0.088257,-156.128143,-0.004061,0.000108,0.002749,0.392586,0.019999,0.027493,-156.128143,0.003947,0.000000
5.190000,0.104637,-156.261581,-0.004023,0.000146,0.003703,0.465449,0.023711,0.037031,-156.261581,0.004562,0.000000
5.560000,0.059212,-156.306061,-0.003997,0.000163,0.004138,0.263387,0.013418,0.041376,-156.306061,0.005178,0.000000
5.930000,0.085274,-156.306061,-0.003967,0.000192,0.004883,0.379317,0.019323,0.048825,-156.306061,0.005801,0.000000
6.300000,0.084160,-156.350540,-0.003928,0.000220,0.005576,0.374362,0.019071,0.055759,-156.350540,0.006418,0.000000
6.670001,0.086395,-156.395020,-0.003928,0.000236,0.005985,0.384305,0.019577,0.059847,-156.395020,0.007034,0.000000
7.040000,0.091232,-156.395020,-0.003902,0.000268,0.006799,0.405822,0.020674,0.067992,-156.395020,0.007649,0.000000
7.410000,0.055489,-156.528473,-0.003872,0.000290,0.007371,0.246826,0.012574,0.073715,-156.528473,0.008265,0.000000
7.780000,0.050270,-156.528473,-0.003850,0.000313,0.007944,0.223612,0.011391,0.079437,-156.528473,0.008881,0.000000
8.150001,0.066284,-156.528473,-0.003833,0.000341,0.008672,0.294847,0.015020,0.086720,-156.528473,0.009497,0.000000
8.520000,0.094589,-156.617432,-0.003807,0.000362,0.009184,0.420754,0.021434,0.091837,-156.617432,0.010112,0.000000
8.890000,0.083046,-156.661911,-0.003790,0.000389,0.009886,0.369407,0.018818,0.098861,-156.661911,0.010728,0.000000
9.260000,0.051765,-156.750870,-0.003734,0.000414,0.010528,0.230264,0.011730,0.105281,-156.750870,0.011352,0.000000
9.630000,0.070755,-156.795349,-0.003725,0.000436,0.011075,0.314734,0.016033,0.110746,-156.795349,0.011968,0.000000
10.000000,0.103149,-156.839828,-0.003695,0.000464,0.011786,0.458832,0.023374,0.117862,-156.839828,0.012584,0.000000
10.370001,0.111343,-156.795349,-0.003673,0.000483,0.012263,0.495280,0.025231,0.122631,-156.795349,0.013200,0.000000
10.740001,0.091606,-156.884308,-0.003660,0.000502,0.012749,0.407484,0.020758,0.127490,-156.884308,0.013815,0.000000
11.110001,0.103523,-157.017761,-0.003609,0.000535,0.013582,0.460494,0.023459,0.135817,-157.017761,0.014431,0.000000
11.480000,0.084160,-156.973282,-0.003604,0.000552,0.014015,0.374362,0.019071,0.140147,-156.973282,0.015047,0.000000
11.850000,0.166451,-157.017761,-0.003587,0.000582,0.014787,0.740409,0.037718,0.147868,-157.017761,0.015662,0.000000
12.220000,0.262901,-157.106720,-0.003548,0.000601,0.015264,1.169443,0.059574,0.152637,-157.106720,0.016278,0.000000
12.590000,0.412216,-157.151199,-0.003540,0.000623,0.015827,1.833629,0.093410,0.158269,-157.151199,0.016902,0.000000
12.960001,0.874336,-157.195679,-0.003492,0.000657,0.016685,3.889242,0.198127,0.166853,-157.195679,0.017518,0.000000
13.330001,1.237396,-157.195679,-0.003479,0.000676,0.017171,5.504213,0.280398,0.171713,-157.195679,0.018134,0.000000
13.700001,1.927773,-157.284637,-0.003471,0.000700,0.017778,8.575160,0.436839,0.177784,-157.284637,0.018750,0.000000
14.070001,2.836739,-157.240158,-0.003449,0.000725,0.018420,12.618443,0.642814,0.184203,-157.240158,0.019365,0.000000
14.440001,3.526367,-157.418091,-0.003432,0.000746,0.018949,15.686065,0.799086,0.189487,-157.418091,0.019981,0.000000
14.810000,4.980110,-157.462570,-0.003423,0.000781,0.019834,22.152636,1.128509,0.198344,-157.462570,0.020597,0.000000
15.180000,5.705124,-157.507050,-0.003402,0.000799,0.020293,25.377659,1.292800,0.202931,-157.507050,0.021212,0.000000
15.550001,6.659142,-157.462570,-0.003389,0.000821,0.020865,29.621342,1.508983,0.208654,-157.462570,0.021828,0.000000
15.920001,8.129265,-157.596008,-0.003372,0.000850,0.021603,36.160774,1.842118,0.216027,-157.596008,0.022452,0.000000
16.290001,8.975296,-157.684967,-0.003359,0.000870,0.022089,39.924110,2.033831,0.220886,-157.684967,0.023068,0.000000
16.660000,10.439835,-157.729446,-0.003341,0.000900,0.022868,46.438705,2.365700,0.228683,-157.729446,0.023684,0.000000
17.030001,12.027260,-157.773926,-0.003320,0.000924,0.023468,53.499924,2.725416,0.234679,-157.773926,0.024301,0.000000
17.400002,12.977554,-157.773926,-0.003303,0.000945,0.023996,57.727043,2.940756,0.239962,-157.773926,0.024915,0.000000
17.770000,14.681534,-157.818420,-0.003294,0.000974,0.024734,65.306725,3.326883,0.247335,-157.818420,0.025531,0.000000
18.140001,15.232269,-157.862900,-0.003272,0.000991,0.025176,67.756516,3.451682,0.251756,-157.862900,0.026148,0.000000
18.510000,16.626060,-157.951859,-0.003277,0.001018,0.025869,73.956413,3.767519,0.258690,-157.951859,0.026762,0.000000
18.880001,18.398926,-157.951859,-0.003242,0.001045,0.026546,81.842506,4.169256,0.265457,-157.951859,0.027378,0.000000
19.250000,19.148514,-158.040817,-0.003229,0.001063,0.026988,85.176842,4.339115,0.269878,-158.040817,0.028004,0.000000
19.620001,20.988029,-158.085297,-0.003225,0.001092,0.027725,93.359421,4.755956,0.277251,-158.085297,0.028618,0.000000
19.990002,22.006844,-158.129776,-0.003203,0.001111,0.028220,97.891327,4.986822,0.282202,-158.129776,0.029235,0.000000
20.360001,22.659241,-158.129776,-0.003182,0.001128,0.028662,100.793335,5.134657,0.286623,-158.129776,0.029851,0.000000
20.730001,24.678619,-158.218750,-0.003182,0.001159,0.029451,109.775978,5.592255,0.294510,-158.218750,0.030465,0.000000
21.100000,26.018784,-158.218750,-0.003160,0.001185,0.030102,115.737328,5.895940,0.301020,-158.218750,0.031082,0.000000
21.470001,27.039459,-158.263229,-0.003165,0.001209,0.030700,120.277519,6.127229,0.307000,-158.263229,0.031698,0.000000
21.840000,28.649971,-158.307709,-0.003113,0.001236,0.031386,127.441437,6.492176,0.313859,-158.307709,0.032312,0.000000
22.210001,29.194008,-158.441147,-0.003109,0.001250,0.031758,129.861435,6.615457,0.317583,-158.441147,0.032929,0.000000
22.580002,31.293442,-158.441147,-0.003087,0.001284,0.032626,139.200180,7.091195,0.326258,-158.441147,0.033554,0.000000
22.950001,32.169258,-158.441147,-0.003083,0.001307,0.033198,143.096008,7.289658,0.331981,-158.441147,0.034169,0.000000
23.320002,32.873047,-158.530106,-0.003070,0.001325,0.033666,146.226608,7.449139,0.336659,-158.530106,0.034785,0.000000
23.690001,34.822411,-158.574585,-0.003048,0.001360,0.034533,154.897812,7.890871,0.345334,-158.574585,0.035401,0.000000
24.060001,35.183243,-158.619064,-0.003018,0.001378,0.034992,156.502884,7.972637,0.349921,-158.619064,0.036016,0.000000
24.430000,36.731194,-158.708038,-0.002992,0.001406,0.035722,163.388504,8.323407,0.357218,-158.708038,0.036632,0.000000
24.800001,37.534775,-158.708038,-0.002992,0.001429,0.036302,166.963013,8.505502,0.363017,-158.708038,0.037248,0.000000
25.170002,38.214355,-158.752518,-0.002971,0.001450,0.036822,169.985947,8.659496,0.368225,-158.752518,0.037864,0.000000
25.540001,39.651337,-158.841476,-0.002966,0.001480,0.037595,176.377960,8.985121,0.375946,-158.841476,0.038479,0.000000
25.910002,39.841621,-158.930435,-0.002928,0.001495,0.037967,177.224380,9.028240,0.379670,-158.930435,0.039104,0.000000
26.280001,40.007332,-158.885956,-0.002906,0.001509,0.038341,177.961502,9.065790,0.383410,-158.885956,0.039719,0.000000
26.650002,42.329071,-158.974915,-0.002906,0.001549,0.039346,188.289108,9.591905,0.393463,-158.974915,0.040335,0.000000
27.020000,42.812035,-158.974915,-0.002867,0.001571,0.039902,190.437439,9.701345,0.399019,-158.974915,0.040951,0.000000
27.390001,43.862129,-159.108368,-0.002854,0.001597,0.040560,195.108490,9.939301,0.405604,-159.108368,0.041566,0.000000
27.760002,44.963234,-159.108368,-0.002824,0.001619,0.041133,200.006454,10.188815,0.411327,-159.108368,0.042182,0.000000
28.130001,45.161339,-159.108368,-0.002815,0.001636,0.041558,200.887665,10.233706,0.415581,-159.108368,0.042798,0.000000
28.500002,47.291679,-159.197327,-0.002768,0.001676,0.042563,210.363892,10.716448,0.425634,-159.197327,0.043414,0.000000
28.870001,47.580269,-159.241806,-0.002768,0.001694,0.043024,211.647614,10.781843,0.430237,-159.241806,0.044038,0.000000
29.240002,48.374535,-159.330765,-0.002755,0.001718,0.043638,215.180679,10.961826,0.436383,-159.330765,0.044654,0.000000
29.610001,49.639862,-159.330765,-0.002721,0.001745,0.044324,220.809128,11.248553,0.443241,-159.330765,0.045269,0.000000
29.980001,49.678589,-159.375244,-0.002699,0.001761,0.044731,220.981400,11.257329,0.447314,-159.375244,0.045885,0.000000
30.350002,51.198982,-159.375244,-0.002677,0.001792,0.045529,227.744446,11.601855,0.455293,-159.375244,0.046501,0.000000
30.720001,51.978355,-159.508698,-0.002652,0.001815,0.046094,231.211273,11.778464,0.460940,-159.508698,0.047117,0.000000
31.090002,52.633362,-159.553177,-0.002647,0.001838,0.046692,234.124893,11.926890,0.466920,-159.553177,0.047732,0.000000
31.460001,54.014862,-159.597656,-0.002596,0.001867,0.047429,240.270111,12.239943,0.474293,-159.597656,0.048348,0.000000
31.830002,54.521286,-159.553177,-0.002570,0.001887,0.047923,242.522797,12.354700,0.479228,-159.553177,0.048964,0.000000
32.200001,54.666145,-159.642136,-0.002548,0.001912,0.048556,243.167160,12.387526,0.485557,-159.642136,0.049588,0.000000
32.570000,56.772278,-159.686615,-0.002539,0.001942,0.049319,252.535706,12.864782,0.493187,-159.686615,0.050204,0.000000
32.940002,57.172585,-159.820053,-0.002505,0.001962,0.049839,254.316360,12.955493,0.498395,-159.820053,0.050819,0.000000
33.310001,58.414070,-159.820053,-0.002496,0.001988,0.050507,259.838776,13.236817,0.505072,-159.820053,0.051435,0.000000
33.680000,58.403648,-159.820053,-0.002449,0.002003,0.050889,259.792389,13.234456,0.508887,-159.820053,0.052051,0.000000
34.050003,60.192520,-159.864532,-0.002432,0.002038,0.051774,267.749695,13.639820,0.517743,-159.864532,0.052668,0.000000
34.420002,61.187874,-159.953506,-0.002432,0.002061,0.052338,272.177246,13.865371,0.523375,-159.953506,0.053282,0.000000
34.790001,61.615730,-160.042465,-0.002397,0.002080,0.052840,274.080444,13.962324,0.528402,-160.042465,0.053898,0.000000
35.160000,62.345207,-160.042465,-0.002371,0.002105,0.053473,277.325317,14.127625,0.534730,-160.042465,0.054515,0.000000
35.530003,63.285828,-160.042465,-0.002350,0.002127,0.054020,281.509430,14.340773,0.540195,-160.042465,0.055138,0.000000
35.900002,63.801559,-160.131424,-0.002328,0.002146,0.054506,283.803497,14.457641,0.545055,-160.131424,0.055755,0.000000
36.270000,66.174316,-160.131424,-0.002320,0.002184,0.055468,294.358063,14.995314,0.554684,-160.131424,0.056369,0.000000
36.640003,66.350815,-160.220383,-0.002294,0.002205,0.055997,295.143158,15.035310,0.559968,-160.220383,0.056985,0.000000
37.010002,67.185303,-160.309341,-0.002259,0.002227,0.056578,298.855164,15.224407,0.565781,-160.309341,0.057602,0.000000
37.380001,68.499786,-160.353836,-0.002251,0.002252,0.057194,304.702271,15.522273,0.571943,-160.353836,0.058218,0.000000
37.750000,68.864334,-160.353836,-0.002216,0.002269,0.057627,306.323853,15.604881,0.576273,-160.353836,0.058832,0.000000
38.120003,70.893768,-160.398315,-0.002195,0.002305,0.058539,315.351227,16.064758,0.585387,-160.398315,0.059449,0.000000
38.490002,71.758041,-160.442795,-0.002186,0.002326,0.059093,319.195709,16.260605,0.590928,-160.442795,0.060065,0.000000
38.860001,72.862488,-160.531754,-0.002151,0.002353,0.059760,324.108521,16.510876,0.597605,-160.531754,0.060689,0.000000
39.230003,74.038452,-160.531754,-0.002134,0.002377,0.060377,329.339478,16.777353,0.603766,-160.531754,0.061305,0.000000
39.600002,74.540771,-160.620712,-0.002117,0.002395,0.060844,331.573914,16.891180,0.608445,-160.620712,0.061921,0.000000
39.970001,76.111816,-160.620712,-0.002091,0.002425,0.061591,338.562256,17.247183,0.615908,-160.620712,0.062536,0.000000
40.340000,76.899765,-160.665192,-0.002070,0.002448,0.062172,342.067230,17.425735,0.621722,-160.665192,0.063152,0.000000
40.710003,77.396881,-160.798645,-0.002048,0.002465,0.062623,344.278534,17.538383,0.626234,-160.798645,0.063768,0.000000
41.080002,79.110901,-160.798645,-0.002022,0.002497,0.063421,351.902863,17.926786,0.634212,-160.798645,0.064383,0.000000
41.450001,79.414017,-160.843124,-0.002022,0.002513,0.063828,353.251190,17.995474,0.638285,-160.843124,0.064999,0.000000
41.820004,79.605423,-160.932083,-0.002009,0.002529,0.064236,354.102600,18.038847,0.642357,-160.932083,0.065615,0.000000
42.190002,81.886948,-160.932083,-0.001970,0.002565,0.065146,364.251343,18.555849,0.651456,-160.932083,0.066239,0.000000
42.560001,83.227859,-161.021042,-0.001940,0.002590,0.065788,370.216003,18.859701,0.657875,-161.021042,0.066855,0.000000
42.930000,84.569885,-161.021042,-0.001914,0.002615,0.066429,376.185638,19.163811,0.664294,-161.021042,0.067471,0.000000
43.300003,85.492249,-161.065521,-0.001901,0.002637,0.066976,380.288513,19.372820,0.669760,-161.065521,0.068086,0.000000
43.670002,85.531723,-161.154480,-0.001867,0.002650,0.067306,380.464111,19.381765,0.673060,-161.154480,0.068702,0.000000
44.040001,88.271637,-161.198959,-0.001880,0.002690,0.068329,392.651855,20.002638,0.683295,-161.198959,0.069318,0.000000
44.410004,88.893875,-161.287933,-0.001863,0.002710,0.068832,395.419708,20.143641,0.688321,-161.287933,0.069933,0.000000
44.780003,90.221756,-161.243454,-0.001832,0.002733,0.069413,401.326416,20.444542,0.694135,-161.243454,0.070549,0.000000
45.150002,92.094421,-161.287933,-0.001815,0.002763,0.070176,409.656433,20.868893,0.701765,-161.287933,0.071165,0.000000
45.520000,92.376678,-161.332413,-0.001807,0.002777,0.070523,410.911987,20.932854,0.705232,-161.332413,0.071789,0.000000
45.890003,94.501801,-161.421371,-0.001802,0.002810,0.071373,420.364990,21.414415,0.713725,-161.421371,0.072405,0.000000
46.260002,95.835648,-161.465851,-0.001781,0.002835,0.072005,426.298248,21.716667,0.720054,-161.465851,0.073021,0.000000
46.630001,96.888718,-161.510330,-0.001750,0.002859,0.072612,430.982544,21.955297,0.726125,-161.510330,0.073636,0.000000
47.000004,98.911072,-161.510330,-0.001738,0.002886,0.073315,439.978424,22.413568,0.733149,-161.510330,0.074252,0.000000
47.370003,99.269287,-161.599289,-0.001716,0.002901,0.073696,441.571838,22.494743,0.736964,-161.599289,0.074868,0.000000
47.740002,101.215683,-161.643784,-0.001720,0.002932,0.074469,450.229858,22.935802,0.744686,-161.643784,0.075483,0.000000
48.110001,102.388657,-161.821701,-0.001707,0.002953,0.075015,455.447479,23.201601,0.750151,-161.821701,0.076099,0.000000
48.480003,103.573547,-161.777222,-0.001686,0.002976,0.075587,460.718140,23.470100,0.755874,-161.777222,0.076715,0.000000
48.850002,105.528503,-161.777222,-0.001647,0.003007,0.076376,469.414215,23.913099,0.763762,-161.777222,0.077339,0.000000
49.220001,106.152588,-161.821701,-0.001647,0.003023,0.076776,472.190308,24.054520,0.767758,-161.821701,0.077955,0.000000
49.590004,106.658279,-161.910660,-0.001647,0.003036,0.077106,474.439728,24.169111,0.771059,-161.910660,0.078571,0.000000
49.960003,109.946320,-162.044098,-0.001621,0.003079,0.078207,489.065643,24.914192,0.782065,-162.044098,0.079186,0.000000
50.330002,110.694794,-161.955139,-0.001613,0.003097,0.078667,492.395020,25.083797,0.786668,-161.955139,0.079802,0.000000
50.700001,112.536545,-161.955139,-0.001578,0.003126,0.079395,500.587555,25.501144,0.793950,-161.955139,0.080418,0.000000
51.070004,113.933319,-162.044098,-0.001582,0.003145,0.079881,506.800720,25.817659,0.798810,-162.044098,0.081035,0.000000
51.440002,114.571198,-162.177551,-0.001569,0.003160,0.080270,509.638153,25.962206,0.802701,-162.177551,0.081649,0.000000
51.810001,117.169983,-162.177551,-0.001565,0.003195,0.081156,521.198120,26.551098,0.811557,-162.177551,0.082265,0.000000
52.180004,118.446091,-162.266510,-0.001522,0.003218,0.081728,526.874512,26.840267,0.817280,-162.266510,0.082889,0.000000
52.550003,120.027557,-162.177551,-0.001535,0.003243,0.082377,533.909241,27.198633,0.823775,-162.177551,0.083505,0.000000
52.920002,122.212280,-162.310989,-0.001518,0.003271,0.083072,543.627380,27.693699,0.830724,-162.310989,0.084122,0.000000
53.290001,123.127197,-162.355469,-0.001518,0.003288,0.083514,547.697144,27.901020,0.835145,-162.355469,0.084736,0.000000
53.660004,125.966904,-162.444427,-0.001500,0.003325,0.084443,560.328796,28.544508,0.844425,-162.444427,0.085352,0.000000
54.030003,126.871017,-162.444427,-0.001487,0.003341,0.084866,564.350464,28.749384,0.848664,-162.444427,0.085969,0.000000
54.400002,128.229813,-162.444427,-0.001466,0.003364,0.085457,570.394714,29.057291,0.854569,-162.444427,0.086585,0.000000
54.770004,130.335571,-162.577881,-0.001444,0.003392,0.086159,579.761597,29.534464,0.861593,-162.577881,0.087199,0.000000
55.140003,131.595322,-162.622360,-0.001449,0.003412,0.086662,585.365234,29.819925,0.866620,-162.622360,0.087825,0.000000
55.510002,132.594025,-162.622360,-0.001436,0.003420,0.086878,589.807678,30.046236,0.868785,-162.622360,0.015262,0.000000
55.880001,131.522324,-162.666840,-0.001423,0.003419,0.086853,585.040527,29.803385,0.868527,-162.666840,588.999268,0.000000
56.250004,132.065994,-162.666840,-0.001418,0.003430,0.087122,587.458862,29.926582,0.871222,-162.666840,588.999268,0.000000
56.620003,131.853363,-162.800278,-0.001427,0.003446,0.087539,586.513062,29.878399,0.875386,-162.800278,588.999268,0.000000
56.990002,131.146973,-162.844757,-0.001406,0.003446,0.087529,583.370850,29.718330,0.875295,-162.844757,588.999268,0.000000
57.360004,131.400940,-162.889236,-0.001397,0.003457,0.087816,584.500549,29.775879,0.878156,-162.889236,588.999268,0.000000
57.730003,131.386414,-162.844757,-0.001380,0.003465,0.088015,584.435974,29.772587,0.880155,-162.844757,588.999268,0.000000
58.100002,131.222198,-162.933731,-0.001384,0.003471,0.088171,583.705505,29.735374,0.881714,-162.933731,588.999268,0.000000
58.470001,131.414337,-162.978210,-0.001375,0.003478,0.088353,584.560181,29.778915,0.883531,-162.978210,588.999268,0.000000
58.840004,131.675369,-163.111649,-0.001362,0.003487,0.088579,585.721313,29.838066,0.885787,-163.111649,588.999268,0.000000
59.210003,131.300400,-163.111649,-0.001362,0.003491,0.088665,584.053345,29.753096,0.886649,-163.111649,588.999268,0.000000
59.580002,131.281784,-163.111649,-0.001345,0.003497,0.088830,583.970520,29.748878,0.888300,-163.111649,588.999268,0.000000
59.950005,131.574829,-163.111649,-0.001328,0.003506,0.089046,585.274048,29.815283,0.890465,-163.111649,588.999268,0.000000
60.320004,131.391998,-163.245087,-0.001341,0.003510,0.089151,584.460815,29.773853,0.891509,-163.245087,588.999268,0.000000
60.690002,131.389771,-163.334045,-0.001332,0.003515,0.089281,584.450867,29.773348,0.892811,-163.334045,588.999268,0.000000
61.060001,131.415451,-163.378540,-0.001319,0.003521,0.089437,584.565125,29.779167,0.894371,-163.378540,588.999268,0.000000
61.430004,131.231506,-163.378540,-0.001324,0.003525,0.089532,583.746887,29.737484,0.895324,-163.378540,588.999268,0.000000
61.800003,131.133194,-163.423019,-0.001319,0.003528,0.089619,583.309570,29.715208,0.896187,-163.423019,588.999268,0.000000
62.170002,131.703674,-163.467499,-0.001302,0.003538,0.089853,585.847229,29.844479,0.898534,-163.467499,588.999268,0.000000
62.540005,131.223312,-163.556458,-0.001306,0.003538,0.089853,583.710449,29.735628,0.898534,-163.556458,588.999268,0.000000
62.910004,130.754501,-163.600937,-0.001289,0.003538,0.089862,581.625061,29.629393,0.898625,-163.600937,588.999268,0.000000
63.280003,132.239883,-163.645416,-0.001281,0.003484,0.088483,588.232361,29.965986,0.884833,-163.645416,588.999268,0.000000
63.650002,131.688034,-163.645416,-0.001281,0.003514,0.089255,585.777649,29.840935,0.892554,-163.645416,588.999268,0.000000
64.020004,131.343964,-163.778854,-0.001281,0.003541,0.089949,584.247131,29.762966,0.899488,-163.778854,588.999268,0.000000
64.389999,131.969925,-163.778854,-0.001276,0.003564,0.090530,587.031555,29.904812,0.905301,-163.778854,588.999268,0.000000
64.760002,131.511154,-163.823349,-0.001255,0.003564,0.090530,584.990845,29.800854,0.905301,-163.823349,588.999268,0.000000
65.130005,131.075104,-163.912308,-0.001259,0.003565,0.090539,583.051208,29.702044,0.905392,-163.912308,588.999268,0.000000
65.500000,132.067108,-163.823349,-0.001233,0.003569,0.090651,587.463867,29.926834,0.906513,-163.823349,588.999268,0.000000
65.870003,131.653030,-163.956787,-0.001263,0.003569,0.090651,585.621948,29.833004,0.906513,-163.956787,588.999268,0.000000
66.240005,131.790817,-164.045746,-0.001250,0.003585,0.091059,586.234863,29.864225,0.910585,-164.045746,588.999268,0.000000
66.610001,131.530899,-164.045746,-0.001263,0.003585,0.091059,585.078674,29.805328,0.910585,-164.045746,588.999268,0.000000
66.980003,131.367798,-164.134705,-0.001237,0.003588,0.091137,584.353149,29.768368,0.911372,-164.134705,588.999268,0.000000
67.350006,131.492905,-164.090225,-0.001229,0.003594,0.091284,584.909668,29.796719,0.912841,-164.090225,588.999268,0.000000
67.720001,131.317902,-164.223679,-0.001242,0.003596,0.091328,584.131226,29.757063,0.913280,-164.223679,588.999268,0.000000
68.090004,131.243423,-164.312637,-0.001233,0.003600,0.091432,583.799927,29.740185,0.914325,-164.312637,588.999268,0.000000
68.460007,131.365555,-164.312637,-0.001216,0.003603,0.091519,584.343201,29.767860,0.915188,-164.312637,588.999268,0.000000
68.830002,131.583771,-164.312637,-0.001212,0.003609,0.091675,585.313843,29.817308,0.916747,-164.312637,588.999268,0.000000
69.200005,131.354767,-164.357117,-0.001233,0.003610,0.091700,584.295166,29.765415,0.917004,-164.357117,588.999268,0.000000
69.570000,131.352524,-164.401596,-0.001207,0.003614,0.091796,584.285217,29.764908,0.917958,-164.401596,588.999268,0.000000
69.940002,131.301880,-164.446075,-0.001212,0.003616,0.091856,584.059937,29.753431,0.918564,-164.446075,588.999268,0.000000
70.310005,131.312683,-164.535034,-0.001212,0.003620,0.091944,584.107971,29.755878,0.919442,-164.535034,588.999268,0.000000
70.680000,131.440781,-164.535034,-0.001212,0.003624,0.092047,584.677795,29.784906,0.920471,-164.535034,588.999268,0.000000
71.050003,131.316772,-164.579514,-0.001194,0.003626,0.092100,584.126160,29.756805,0.921001,-164.579514,588.999268,0.000000
71.420006,131.348434,-164.579514,-0.001207,0.003629,0.092177,584.267029,29.763981,0.921773,-164.579514,588.999268,0.000000
71.790001,131.339874,-164.757446,-0.001194,0.003632,0.092247,584.228943,29.762041,0.922470,-164.757446,588.999268,0.000000
72.160004,131.357361,-164.801926,-0.001203,0.003635,0.092333,584.306702,29.766003,0.923333,-164.801926,588.999268,0.000000
72.530006,131.462372,-164.801926,-0.001177,0.003639,0.092421,584.773865,29.789799,0.924211,-164.801926,588.999268,0.000000
72.900002,131.413589,-164.846405,-0.001173,0.003641,0.092473,584.556824,29.778744,0.924726,-164.846405,588.999268,0.000000
73.270004,131.443008,-164.846405,-0.001177,0.003643,0.092542,584.687683,29.785410,0.925422,-164.846405,588.999268,0.000000
73.640007,131.454926,-164.935364,-0.001190,0.003646,0.092603,584.740723,29.788113,0.926028,-164.935364,588.999268,0.000000
74.010002,131.400192,-165.024323,-0.001181,0.003648,0.092663,584.497253,29.775709,0.926633,-165.024323,588.999268,0.000000
74.380005,131.341354,-165.068802,-0.001173,0.003651,0.092724,584.235535,29.762377,0.927239,-165.068802,588.999268,0.000000
74.750000,131.297409,-164.979843,-0.001160,0.003653,0.092775,584.040039,29.752419,0.927753,-164.979843,588.999268,0.000000
75.120003,131.192413,-165.068802,-0.001190,0.003654,0.092803,583.572998,29.728626,0.928026,-165.068802,588.999268,0.000000
75.490005,131.033783,-165.157776,-0.001168,0.003654,0.092819,582.867371,29.692678,0.928192,-165.157776,588.999268,0.000000
75.860001,131.775909,-165.202255,-0.001155,0.003665,0.093080,586.168518,29.860849,0.930797,-165.202255,588.999268,0.000000
76.230003,131.622131,-165.246735,-0.001177,0.003665,0.093080,585.484497,29.826000,0.930797,-165.246735,588.999268,0.000000
76.600006,131.433701,-165.335693,-0.001173,0.003665,0.093080,584.646301,29.783302,0.930797,-165.335693,588.999268,0.000000
76.970001,131.197998,-165.291214,-0.001138,0.003665,0.093080,583.597839,29.729891,0.930797,-165.291214,588.999268,0.000000
77.340004,130.983139,-165.380173,-0.001151,0.003665,0.093080,582.642090,29.681204,0.930797,-165.380173,588.999268,0.000000
77.710007,130.737366,-165.469131,-0.001151,0.003665,0.093080,581.548828,29.625509,0.930797,-165.469131,588.999268,0.000000
78.080002,132.605927,-165.513626,-0.001134,0.003678,0.093410,589.860596,30.048933,0.934097,-165.513626,588.999268,0.000000
78.450005,132.308411,-165.513626,-0.001147,0.003672,0.093279,588.537231,29.981516,0.932795,-165.513626,588.999268,0.000000
78.820007,132.044022,-165.558105,-0.001160,0.003672,0.093270,587.361145,29.921604,0.932704,-165.558105,588.999268,0.000000
79.190002,131.784103,-165.602585,-0.001143,0.003672,0.093270,586.204956,29.862705,0.932704,-165.602585,588.999268,0.000000
79.560005,131.518982,-165.691544,-0.001143,0.003672,0.093279,585.025635,29.802628,0.932795,-165.691544,588.999268,0.000000
79.930000,131.325714,-165.691544,-0.001125,0.003673,0.093296,584.165955,29.758831,0.932961,-165.691544,588.999268,0.000000
80.300003,131.077713,-165.736023,-0.001138,0.003676,0.093375,583.062805,29.702635,0.933749,-165.736023,588.999268,0.000000
80.670006,132.287933,-165.824982,-0.001121,0.003686,0.093635,588.446106,29.976873,0.936353,-165.824982,588.999268,0.000000
81.040001,132.077530,-165.869461,-0.001138,0.003686,0.093635,587.510193,29.929197,0.936353,-165.869461,588.999268,0.000000
81.410004,131.803848,-165.913940,-0.001125,0.003686,0.093635,586.292786,29.867178,0.936353,-165.913940,588.999268,0.000000
81.780006,131.581161,-165.958435,-0.001112,0.003686,0.093635,585.302246,29.816717,0.936353,-165.958435,588.999268,0.000000
82.150002,131.532761,-165.958435,-0.001125,0.003696,0.093878,585.086914,29.805748,0.938775,-165.958435,588.999268,0.000000
82.520004,131.473541,-166.002914,-0.001108,0.003696,0.093878,584.823547,29.792330,0.938775,-166.002914,588.999268,0.000000
82.890007,131.444504,-166.047394,-0.001134,0.003699,0.093956,584.694336,29.785749,0.939562,-166.047394,588.999268,0.000000
83.260002,131.413589,-166.091873,-0.001117,0.003700,0.093990,584.556824,29.778744,0.939895,-166.091873,588.999268,0.000000
83.630005,131.467224,-166.136353,-0.001112,0.003703,0.094059,584.795410,29.790899,0.940592,-166.136353,588.999268,0.000000
84.000008,131.365936,-166.269791,-0.001104,0.003703,0.094059,584.344849,29.767946,0.940592,-166.269791,588.999268,0.000000
84.370003,131.393860,-166.225311,-0.001104,0.003706,0.094129,584.469055,29.774275,0.941288,-166.225311,588.999268,0.000000
84.740005,131.459396,-166.225311,-0.001095,0.003710,0.094233,584.760620,29.789125,0.942333,-166.225311,588.999268,0.000000
85.110001,131.486206,-166.358749,-0.001104,0.003710,0.094233,584.879883,29.795200,0.942333,-166.358749,588.999268,0.000000
85.480003,131.464233,-166.403244,-0.001117,0.003713,0.094303,584.782104,29.790222,0.943029,-166.403244,588.999268,0.000000
85.850006,131.460144,-166.447723,-0.001087,0.003714,0.094338,584.763916,29.789295,0.943377,-166.447723,588.999268,0.000000
86.220001,131.476532,-166.447723,-0.001117,0.003716,0.094380,584.836853,29.793007,0.943801,-166.447723,588.999268,0.000000
86.590004,131.502594,-166.536682,-0.001099,0.003718,0.094450,584.952759,29.798914,0.944498,-166.536682,588.999268,0.000000
86.960007,131.478394,-166.536682,-0.001099,0.003720,0.094485,584.845093,29.793430,0.944846,-166.536682,588.999268,0.000000
87.330002,131.489563,-166.625641,-0.001099,0.003721,0.094519,584.894775,29.795961,0.945194,-166.625641,588.999268,0.000000
87.700005,131.475784,-166.714600,-0.001104,0.003723,0.094554,584.833496,29.792839,0.945542,-166.714600,588.999268,0.000000
88.070007,131.421051,-166.714600,-0.001087,0.003723,0.094562,584.590027,29.780436,0.945618,-166.714600,588.999268,0.000000
88.440002,131.333160,-166.714600,-0.001091,0.003724,0.094597,584.199097,29.760521,0.945966,-166.714600,588.999268,0.000000
88.810005,131.421783,-166.803574,-0.001095,0.003727,0.094666,584.593262,29.780602,0.946663,-166.803574,588.999268,0.000000
89.180008,131.361832,-166.892532,-0.001091,0.003727,0.094666,584.326599,29.767015,0.946663,-166.892532,588.999268,0.000000
89.550003,131.402802,-166.892532,-0.001082,0.003729,0.094727,584.508850,29.776300,0.947268,-166.892532,588.999268,0.000000
89.920006,131.305984,-166.937012,-0.001095,0.003730,0.094736,584.078186,29.754360,0.947359,-166.937012,588.999268,0.000000
90.290001,131.472427,-166.937012,-0.001087,0.003734,0.094840,584.818542,29.792076,0.948404,-166.937012,588.999268,0.000000
90.660004,131.441895,-166.981491,-0.001082,0.003734,0.094840,584.682739,29.785160,0.948404,-166.981491,588.999268,0.000000
91.030006,131.390884,-167.070450,-0.001074,0.003735,0.094866,584.455872,29.773600,0.948661,-167.070450,588.999268,0.000000
91.400002,131.461639,-167.114929,-0.001087,0.003738,0.094945,584.770569,29.789635,0.949448,-167.114929,588.999268,0.000000
91.770004,131.430359,-167.159409,-0.001069,0.003738,0.094945,584.631409,29.782545,0.949448,-167.159409,588.999268,0.000000
92.140007,131.381195,-167.248383,-0.001069,0.003739,0.094971,584.412720,29.771404,0.949706,-167.248383,588.999268,0.000000
92.510002,131.464615,-167.203888,-0.001078,0.003742,0.095057,584.783813,29.790308,0.950569,-167.203888,588.999268,0.000000
92.880005,131.469452,-167.292862,-0.001087,0.003742,0.095057,584.805359,29.791403,0.950569,-167.292862,588.999268,0.000000
93.250008,131.404282,-167.381821,-0.001078,0.003743,0.095083,584.515442,29.776636,0.950826,-167.381821,588.999268,0.000000
93.620003,131.419189,-167.426300,-0.001065,0.003745,0.095127,584.581726,29.780014,0.951265,-167.426300,588.999268,0.000000
93.990005,131.417694,-167.381821,-0.001065,0.003747,0.095161,584.575073,29.779675,0.951613,-167.381821,588.999268,0.000000
94.360008,131.430725,-167.470779,-0.001074,0.003747,0.095178,584.633057,29.782629,0.951780,-167.470779,588.999268,0.000000
94.730003,131.410995,-167.515259,-0.001069,0.003749,0.095213,584.545288,29.778156,0.952128,-167.515259,588.999268,0.000000
95.100006,131.374863,-167.604218,-0.001065,0.003750,0.095248,584.384583,29.769970,0.952476,-167.604218,588.999268,0.000000
95.470001,131.432220,-167.693192,-0.001056,0.003752,0.095292,584.639709,29.782969,0.952915,-167.693192,588.999268,0.000000
95.840004,131.380463,-167.648712,-0.001069,0.003752,0.095299,584.409485,29.771238,0.952991,-167.648712,588.999268,0.000000
96.210007,131.366302,-167.737671,-0.001078,0.003754,0.095343,584.346497,29.768028,0.953430,-167.737671,588.999268,0.000000
96.580002,131.350662,-167.737671,-0.001065,0.003754,0.095360,584.276917,29.764484,0.953597,-167.737671,588.999268,0.000000
96.950005,131.342850,-167.782150,-0.001061,0.003756,0.095394,584.242187,29.762716,0.953945,-167.782150,588.999268,0.000000
97.320007,131.294434,-167.871109,-0.001065,0.003756,0.095404,584.026794,29.751743,0.954036,-167.871109,588.999268,0.000000
97.690002,131.383438,-167.915588,-0.001078,0.003758,0.095457,584.422729,29.771914,0.954566,-167.915588,588.999268,0.000000
98.060005,131.362579,-167.915588,-0.001061,0.003760,0.095499,584.329956,29.767187,0.954990,-167.915588,588.999268,0.000000
98.430008,131.382690,-167.871109,-0.001052,0.003760,0.095508,584.419373,29.771744,0.955080,-167.871109,588.999268,0.000000
98.800003,131.352524,-168.049026,-0.001074,0.003762,0.095552,584.285217,29.764908,0.955519,-168.049026,588.999268,0.000000
99.170006,131.350296,-168.093521,-0.001048,0.003763,0.095578,584.275269,29.764402,0.955777,-168.093521,588.999268,0.000000
99.540001,131.447113,-168.138000,-0.001035,0.003765,0.095620,584.705933,29.786341,0.956201,-168.138000,588.999268,0.000000
99.910004,131.429230,-168.182480,-0.001061,0.003766,0.095647,584.626404,29.782290,0.956473,-168.182480,588.999268,0.000000
100.280006,131.446732,-168.226959,-0.001061,0.003767,0.095673,584.704285,29.786255,0.956731,-168.226959,588.999268,0.000000
100.650002,131.460892,-168.271439,-0.001043,0.003767,0.095681,584.767273,29.789463,0.956806,-168.271439,588.999268,0.000000
101.020004,131.412476,-168.315918,-0.001052,0.003768,0.095708,584.551880,29.778494,0.957079,-168.315918,588.999268,0.000000
101.390007,131.418442,-168.404877,-0.001030,0.003769,0.095734,584.578430,29.779844,0.957336,-168.404877,588.999268,0.000000
101.760002,131.423279,-168.404877,-0.001043,0.003770,0.095768,584.599915,29.780941,0.957684,-168.404877,588.999268,0.000000
102.130005,131.460144,-168.449356,-0.001052,0.003772,0.095803,584.763916,29.789295,0.958033,-168.449356,588.999268,0.000000
102.500008,131.431473,-168.538330,-0.001039,0.003772,0.095820,584.636414,29.782797,0.958199,-168.538330,588.999268,0.000000
102.870003,131.448975,-168.538330,-0.001035,0.003774,0.095855,584.714233,29.786764,0.958547,-168.538330,588.999268,0.000000
103.240005,131.440033,-168.582809,-0.001035,0.003775,0.095880,584.674438,29.784737,0.958805,-168.582809,588.999268,0.000000
103.610008,131.433334,-168.671768,-0.001043,0.003776,0.095899,584.644653,29.783218,0.958986,-168.671768,588.999268,0.000000
103.980003,131.452316,-168.671768,-0.001026,0.003777,0.095933,584.729126,29.787521,0.959335,-168.671768,588.999268,0.000000
104.350006,131.459778,-168.716248,-0.001035,0.003778,0.095959,584.762268,29.789211,0.959592,-168.716248,588.999268,0.000000
104.720001,131.426254,-168.805206,-0.001030,0.003779,0.095976,584.613159,29.781614,0.959759,-168.805206,588.999268,0.000000
105.090004,131.446732,-168.805206,-0.001039,0.003780,0.096011,584.704285,29.786255,0.960107,-168.805206,588.999268,0.000000
105.460007,131.403168,-168.894165,-0.001030,0.003780,0.096020,584.510498,29.776384,0.960198,-168.894165,588.999268,0.000000
105.830002,131.361099,-168.894165,-0.001030,0.003781,0.096029,584.323364,29.766851,0.960288,-168.894165,588.999268,0.000000
106.200005,131.291824,-168.938660,-0.001035,0.003781,0.096029,584.015198,29.751152,0.960288,-168.938660,588.999268,0.000000
106.570007,131.227783,-169.072098,-0.001048,0.003781,0.096036,583.730347,29.736641,0.960364,-169.072098,588.999268,0.000000
106.940002,131.177887,-169.072098,-0.001030,0.003782,0.096055,583.508362,29.725334,0.960546,-169.072098,588.999268,0.000000
107.310005,131.186081,-169.072098,-0.001026,0.003783,0.096080,583.544861,29.727190,0.960803,-169.072098,588.999268,0.000000
107.680008,131.576691,-169.116577,-0.001030,0.003790,0.096262,585.282349,29.815704,0.962620,-169.116577,588.999268,0.000000
108.050003,131.682083,-169.161057,-0.001018,0.003789,0.096253,585.751160,29.839586,0.962529,-169.161057,588.999268,0.000000
108.420006,131.616547,-169.250015,-0.001048,0.003789,0.096253,585.459656,29.824736,0.962529,-169.250015,588.999268,0.000000
108.790009,131.555466,-169.294495,-0.001026,0.003789,0.096253,585.187927,29.810894,0.962529,-169.294495,588.999268,0.000000
109.160004,131.495514,-169.338974,-0.001022,0.003789,0.096253,584.921265,29.797310,0.962529,-169.338974,588.999268,0.000000
109.530006,131.414337,-169.338974,-0.001009,0.003790,0.096262,584.560181,29.778915,0.962620,-169.338974,588.999268,0.000000
109.900002,131.416580,-169.383469,-0.001026,0.003791,0.096297,584.570129,29.779423,0.962968,-169.383469,588.999268,0.000000
110.270004,131.397217,-169.472427,-0.001013,0.003792,0.096315,584.484009,29.775034,0.963150,-169.472427,588.999268,0.000000
110.640007,131.356995,-169.561386,-0.001018,0.003793,0.096341,584.305115,29.765921,0.963407,-169.561386,588.999268,0.000000
111.010002,131.393112,-169.561386,-0.001005,0.003794,0.096357,584.465759,29.774105,0.963574,-169.561386,588.999268,0.000000
111.380005,131.327576,-169.561386,-0.001005,0.003794,0.096357,584.174255,29.759254,0.963574,-169.561386,588.999268,0.000000
111.750008,131.258316,-169.605865,-0.001022,0.003794,0.096366,583.866150,29.743559,0.963665,-169.605865,588.999268,0.000000
112.120003,131.196869,-169.739304,-0.001035,0.003794,0.096366,583.592834,29.729635,0.963665,-169.739304,588.999268,0.000000
112.490005,131.140274,-169.739304,-0.001009,0.003794,0.096376,583.341064,29.716812,0.963755,-169.739304,588.999268,0.000000
112.860008,131.284378,-169.872757,-0.001009,0.003797,0.096453,583.982056,29.749466,0.964527,-169.872757,588.999268,0.000000
113.230003,131.244919,-169.917236,-0.001009,0.003797,0.096453,583.806580,29.740522,0.964527,-169.917236,588.999268,0.000000
113.600006,131.186081,-169.917236,-0.001018,0.003797,0.096453,583.544861,29.727190,0.964527,-169.917236,588.999268,0.000000
113.970009,131.143997,-169.961716,-0.001018,0.003798,0.096471,583.357605,29.717653,0.964709,-169.961716,588.999268,0.000000
114.340004,131.256821,-169.961716,-0.001013,0.003801,0.096541,583.859497,29.743221,0.965406,-169.961716,588.999268,0.000000
114.710007,131.233734,-170.006195,-0.001000,0.003801,0.096541,583.756775,29.737989,0.965406,-170.006195,588.999268,0.000000
115.080002,131.190552,-170.006195,-0.001005,0.003801,0.096541,583.564697,29.728205,0.965406,-170.006195,588.999268,0.000000
115.450005,131.132462,-170.095154,-0.001009,0.003801,0.096548,583.306335,29.715040,0.965481,-170.095154,588.999268,0.000000
115.820007,131.823578,-170.139633,-0.000996,0.003810,0.096765,586.380554,29.871651,0.967646,-170.139633,588.999268,0.000000
116.190002,131.780762,-170.273087,-0.000987,0.003800,0.096513,586.190125,29.861948,0.965133,-170.273087,0.096722,0.000000
116.560005,131.648941,-170.317566,-0.000987,0.003791,0.096297,585.603760,29.832077,0.962968,-170.317566,0.096106,0.000000
116.930008,131.386414,-170.317566,-0.000996,0.003770,0.095768,584.435974,29.772587,0.957684,-170.317566,0.095490,0.000000
117.300003,131.197998,-170.317566,-0.000996,0.003750,0.095257,583.597839,29.729891,0.952567,-170.317566,0.094866,0.000000
117.670006,130.885941,-170.362045,-0.000987,0.003733,0.094806,582.209717,29.659178,0.948056,-170.362045,0.094250,0.000000
118.040009,130.611511,-170.451004,-0.000979,0.003713,0.094303,580.989014,29.596991,0.943029,-170.451004,0.093635,0.000000
118.410004,130.357178,-170.451004,-0.000979,0.003693,0.093799,579.857666,29.539358,0.937988,-170.451004,0.093019,0.000000
118.780006,130.203018,-170.495483,-0.000966,0.003656,0.092863,579.171936,29.504427,0.928632,-170.495483,0.092403,0.000000
119.150009,129.992996,-170.584442,-0.000970,0.003634,0.092298,578.237732,29.456833,0.922984,-170.584442,0.091787,0.000000
119.520004,129.800858,-170.584442,-0.000992,0.003608,0.091631,577.383057,29.413296,0.916308,-170.584442,0.091172,0.000000
119.890007,129.421036,-170.717896,-0.000966,0.003589,0.091154,575.693542,29.327227,0.911539,-170.717896,0.090556,0.000000
120.260002,129.119034,-170.717896,-0.000974,0.003565,0.090539,574.350159,29.258791,0.905392,-170.717896,0.089940,0.000000
120.630005,128.702728,-170.762375,-0.000966,0.003548,0.090114,572.498352,29.164455,0.901138,-170.762375,0.089316,0.000000
121.000008,127.582626,-170.806854,-0.000979,0.003517,0.089325,567.515869,28.910635,0.893250,-170.806854,0.088700,0.000000
121.370003,126.405930,-170.851334,-0.000961,0.003495,0.088760,562.281677,28.643993,0.887603,-170.851334,0.088085,0.000000
121.740005,125.197586,-170.940292,-0.000949,0.003476,0.088302,556.906677,28.370178,0.883016,-170.940292,0.087469,0.000000
122.110008,123.823532,-170.984772,-0.000940,0.003456,0.087790,550.794556,28.058813,0.877899,-170.984772,0.086853,0.000000
122.480003,121.876770,-170.940292,-0.000944,0.003429,0.087087,542.134949,27.617670,0.870874,-170.940292,0.086237,0.000000
122.850006,119.715149,-170.984772,-0.000949,0.003403,0.086445,532.519592,27.127840,0.864455,-170.984772,0.085622,0.000000
123.220009,116.946548,-171.029251,-0.000949,0.003377,0.085769,520.204224,26.500467,0.857687,-171.029251,0.085006,0.000000
123.590004,114.921585,-171.162704,-0.000936,0.003355,0.085222,511.196747,26.041605,0.852222,-171.162704,0.084390,0.000000
123.960007,112.154495,-171.207184,-0.000936,0.003331,0.084615,498.888123,25.414572,0.846151,-171.207184,0.083766,0.000000
124.330009,109.129715,-171.251663,-0.000957,0.003307,0.084008,485.433228,24.729147,0.840080,-171.251663,0.083150,0.000000
124.700005,106.540985,-171.251663,-0.000949,0.003282,0.083366,473.917969,24.142532,0.833661,-171.251663,0.082533,0.000000
125.070007,104.318283,-171.340622,-0.000940,0.003266,0.082950,464.030884,23.638861,0.829498,-171.340622,0.081919,0.000000
125.440002,101.609650,-171.340622,-0.000957,0.003238,0.082256,451.982300,23.025076,0.822564,-171.340622,0.081303,0.000000
125.810005,98.575928,-171.385101,-0.000944,0.003213,0.081598,438.487640,22.337624,0.815978,-171.385101,0.080686,0.000000
126.180008,96.879776,-171.385101,-0.000953,0.003193,0.081112,430.942780,21.953270,0.811118,-171.385101,0.080072,0.000000
126.550003,94.174118,-171.474060,-0.000936,0.003172,0.080574,418.907410,21.340160,0.805744,-171.474060,0.079456,0.000000
126.920006,89.963699,-171.563034,-0.000944,0.003135,0.079637,400.178528,20.386065,0.796372,-171.563034,0.078839,0.000000
127.290009,87.636749,-171.563034,-0.000931,0.003115,0.079126,389.827728,19.858772,0.791255,-171.563034,0.078216,0.000000
127.660004,86.601547,-171.607513,-0.000953,0.003102,0.078788,385.222931,19.624191,0.787879,-171.607513,0.077599,0.000000
128.029999,81.847473,-171.651993,-0.000944,0.003067,0.077904,364.075745,18.546902,0.779037,-171.651993,0.076983,0.000000
128.400009,79.089676,-171.651993,-0.000944,0.003042,0.077278,351.808441,17.921978,0.772785,-171.651993,0.076369,0.000000
128.770004,75.664230,-171.696472,-0.000949,0.003014,0.076550,336.571320,17.145760,0.765503,-171.696472,0.075752,0.000000
129.139999,74.165421,-171.829910,-0.000949,0.003001,0.076229,329.904266,16.806124,0.762293,-171.829910,0.075136,0.000000
129.510010,70.678528,-171.918869,-0.000953,0.002970,0.075431,314.393799,16.015984,0.754314,-171.918869,0.074522,0.000000
129.880005,67.504807,-171.918869,-0.000944,0.002944,0.074790,300.276367,15.296808,0.747895,-171.918869,0.073905,0.000000
130.250000,65.105606,-171.874390,-0.000944,0.002924,0.074270,289.604187,14.753141,0.742702,-171.874390,0.073289,0.000000
130.620010,62.580544,-171.918869,-0.000949,0.002900,0.073654,278.372162,14.180954,0.736541,-171.918869,0.072665,0.000000
130.990005,59.227707,-172.007843,-0.000953,0.002873,0.072968,263.458008,13.421190,0.729682,-172.007843,0.072049,0.000000
131.360001,56.529121,-172.096802,-0.000940,0.002844,0.072249,251.454086,12.809682,0.722491,-172.096802,0.071433,0.000000
131.730011,53.684196,-172.096802,-0.000957,0.002824,0.071728,238.799225,12.165012,0.717283,-172.096802,0.070818,0.000000
132.100006,51.034019,-172.141281,-0.000944,0.002799,0.071105,227.010651,11.564474,0.711046,-172.141281,0.070202,0.000000
132.470001,48.997887,-172.141281,-0.000966,0.002779,0.070575,217.953491,11.103080,0.705747,-172.141281,0.069586,0.000000
132.840012,45.801819,-172.185760,-0.000949,0.002750,0.069856,203.736664,10.378840,0.698555,-172.185760,0.068971,0.000000
133.210007,44.138054,-172.230240,-0.000949,0.002731,0.069379,196.335876,10.001826,0.693786,-172.230240,0.068355,0.000000
133.580002,41.309143,-172.274719,-0.000953,0.002704,0.068693,183.752243,9.360785,0.686928,-172.274719,0.067739,0.000000
133.950012,38.108971,-172.319199,-0.000953,0.002676,0.067974,169.517166,8.635616,0.679737,-172.319199,0.067115,0.000000
134.320007,36.233704,-172.363678,-0.000949,0.002661,0.067583,161.175568,8.210674,0.675831,-172.363678,0.066499,0.000000
134.690002,33.029068,-172.497131,-0.000957,0.002631,0.066829,146.920639,7.484494,0.668291,-172.497131,0.065883,0.000000
135.060013,31.138535,-172.497131,-0.000949,0.002611,0.066325,138.511124,7.056093,0.663250,-172.497131,0.065268,0.000000
135.430008,29.387634,-172.541611,-0.000953,0.002597,0.065962,130.722733,6.659333,0.659616,-172.541611,0.064652,0.000000
135.800003,25.743973,-172.497131,-0.000936,0.002558,0.064973,114.514908,5.833668,0.649730,-172.497131,0.064036,0.000000
136.170013,23.346268,-172.586090,-0.000936,0.002537,0.064443,103.849388,5.290340,0.644431,-172.586090,0.063421,0.000000
136.540009,20.158012,-172.675049,-0.000953,0.002507,0.063673,89.667320,4.567871,0.636725,-172.675049,0.062805,0.000000
136.910004,18.763855,-172.719528,-0.000936,0.002493,0.063326,83.465797,4.251950,0.633258,-172.719528,0.062189,0.000000
137.280014,15.708908,-172.675049,-0.000944,0.002464,0.062596,69.876717,3.559690,0.625961,-172.675049,0.061565,0.000000
137.650009,13.355515,-172.764008,-0.000949,0.002442,0.062033,59.408295,3.026403,0.620329,-172.764008,0.060949,0.000000
138.020004,10.679642,-172.808502,-0.000953,0.002415,0.061330,47.505421,2.420042,0.613304,-172.808502,0.060333,0.000000
138.389999,8.790970,-172.941940,-0.000961,0.002393,0.060793,39.104187,1.992062,0.607930,-172.941940,0.059718,0.000000
138.760010,6.558601,-172.986420,-0.000944,0.002370,0.060195,29.174116,1.486200,0.601950,-172.986420,0.059102,0.000000
139.130005,4.080460,-172.986420,-0.000940,0.002346,0.059579,18.150791,0.924645,0.595788,-172.986420,0.058486,0.000000
139.500000,1.817184,-172.986420,-0.000940,0.002322,0.058981,8.083241,0.411780,0.589808,-172.986420,0.057870,0.000000
139.870010,-0.141129,-173.030899,-0.000953,0.002298,0.058365,-0.627771,-0.031980,0.583646,-173.030899,0.057255,0.000000
140.240005,-1.814194,-173.075378,-0.000940,0.002276,0.057818,-8.069937,-0.411102,0.578181,-173.075378,0.056630,0.000000
140.610001,-0.096817,-173.119858,-0.000953,0.002246,0.057046,-0.430664,-0.021939,0.570459,-173.119858,0.056015,0.000000
140.980011,-0.173897,-173.164337,-0.000944,0.002221,0.056422,-0.773532,-0.039406,0.564222,-173.164337,0.055399,0.000000
141.350006,-0.108727,-173.208817,-0.000940,0.002199,0.055859,-0.483640,-0.024638,0.558590,-173.208817,0.054783,0.000000
141.720001,-0.151176,-173.342270,-0.000944,0.002172,0.055157,-0.672466,-0.034257,0.551565,-173.342270,0.054168,0.000000
142.090012,-0.121765,-173.297791,-0.000944,0.002152,0.054671,-0.541638,-0.027592,0.546705,-173.297791,0.053552,0.000000
142.460007,-0.066277,-173.386749,-0.000961,0.002124,0.053959,-0.294813,-0.015018,0.539590,-173.386749,0.052936,0.000000
142.830002,-0.057716,-173.386749,-0.000957,0.002097,0.053266,-0.256735,-0.013079,0.532656,-173.386749,0.052319,0.000000
143.200012,-0.067772,-173.431229,-0.000957,0.002080,0.052824,-0.301465,-0.015357,0.528235,-173.431229,0.051705,0.000000
143.570007,-0.094208,-173.431229,-0.000949,0.002054,0.052182,-0.419057,-0.021348,0.521816,-173.431229,0.051079,0.000000
143.940002,-0.146339,-173.564667,-0.000961,0.002026,0.051470,-0.650950,-0.033161,0.514700,-173.564667,0.050465,0.000000
144.310013,-0.124741,-173.564667,-0.000961,0.002006,0.050942,-0.554874,-0.028267,0.509417,-173.564667,0.049849,0.000000
144.680008,-0.113945,-173.653625,-0.000966,0.001977,0.050221,-0.506853,-0.025820,0.502210,-173.653625,0.049232,0.000000
145.050003,-0.126228,-173.609146,-0.000970,0.001951,0.049562,-0.561492,-0.028604,0.495624,-173.609146,0.048616,0.000000
145.420013,-0.135170,-173.698120,-0.000987,0.001928,0.048981,-0.601266,-0.030630,0.489811,-173.698120,0.048002,0.000000
145.790009,-0.153038,-173.787079,-0.000992,0.001904,0.048365,-0.680747,-0.034679,0.483649,-173.787079,0.047385,0.000000
146.160004,-0.185814,-173.831558,-0.000987,0.001882,0.047802,-0.826542,-0.042106,0.478017,-173.831558,0.046769,0.000000
146.530014,-0.148575,-173.831558,-0.000996,0.001862,0.047299,-0.660894,-0.033668,0.472991,-173.831558,0.046155,0.000000
146.900009,-0.170540,-173.876038,-0.001043,0.001830,0.046492,-0.758599,-0.038645,0.464921,-173.876038,0.045529,0.000000
147.270004,-0.159744,-173.920517,-0.001117,0.001811,0.045999,-0.710578,-0.036199,0.459986,-173.920517,0.044915,0.000000
147.639999,-0.167564,-173.964996,-0.001130,0.001786,0.045364,-0.745364,-0.037971,0.453642,-173.964996,0.044298,0.000000
148.010010,-0.167938,-174.098450,-0.001143,0.001760,0.044697,-0.747027,-0.038055,0.446966,-174.098450,0.043682,0.000000
148.380005,-0.129951,-174.009476,-0.001203,0.001729,0.043917,-0.578053,-0.029447,0.439169,-174.009476,0.043066,0.000000
148.750000,-0.151924,-174.053955,-0.001212,0.001711,0.043457,-0.675792,-0.034427,0.434566,-174.053955,0.042451,0.000000
149.120010,-0.140007,-174.187408,-0.001229,0.001690,0.042928,-0.622782,-0.031726,0.429283,-174.187408,0.042842,0.000000
149.200012,-0.131447,-174.231888,-0.001246,0.001690,0.042928,-0.584705,-0.029786,0.429283,-174.231888,0.042842,0.000000