File: Data/sima compression 500bar/P1-75DMF-25NMP-1_11142024_185536.csv
Time (sec),S:Load (lbs),S:HL1 (DIM),S:LVDT (in),S:Position (in),Ch:Position (mm),Ch:Load (N),Ch:Stress (MPa),Ch:Strain (mm/mm),Ch:HL1 (DIM),Set Point (),Cycles ()
0.110000,-0.093468,-232.368484,-0.009278,-0.008869,-0.225262,-0.415765,-0.021180,-2.252619,-232.368484,-0.225028,0.000000
0.530000,-0.061066,-232.279526,-0.009278,-0.008789,-0.223241,-0.271634,-0.013838,-2.232412,-232.279526,-0.222495,0.000000
0.950000,-0.076706,-232.324005,-0.009102,-0.008533,-0.216746,-0.341205,-0.017382,-2.167457,-232.324005,-0.215506,0.000000
1.370000,-0.040962,-232.368484,-0.008817,-0.008258,-0.209756,-0.182209,-0.009282,-2.097559,-232.368484,-0.208498,0.000000
1.790000,-0.015266,-232.412964,-0.008528,-0.007981,-0.202723,-0.067908,-0.003459,-2.027227,-232.412964,-0.201509,0.000000
2.210000,-0.006699,-232.457443,-0.008244,-0.007709,-0.195820,-0.029797,-0.001518,-1.958196,-232.457443,-0.194501,0.000000
2.630000,-0.048409,-232.457443,-0.007968,-0.007434,-0.188812,-0.215332,-0.010970,-1.888124,-232.457443,-0.187512,0.000000
3.050000,-0.049522,-232.457443,-0.007679,-0.007158,-0.181805,-0.220287,-0.011222,-1.818052,-232.457443,-0.180522,0.000000
3.470000,-0.048035,-232.546417,-0.007403,-0.006881,-0.174781,-0.213669,-0.010885,-1.747807,-232.546417,-0.173515,0.000000
3.890000,-0.033142,-232.501938,-0.007105,-0.006606,-0.167782,-0.147423,-0.007510,-1.677822,-232.501938,-0.166525,0.000000
4.310000,-0.032021,-232.546417,-0.006821,-0.006330,-0.160792,-0.142435,-0.007256,-1.607923,-232.546417,-0.159517,0.000000
4.730000,-0.013405,-232.590897,-0.006523,-0.006054,-0.153768,-0.059628,-0.003038,-1.537678,-232.590897,-0.152528,0.000000
5.150000,-0.040588,-232.501938,-0.006260,-0.005780,-0.146804,-0.180546,-0.009197,-1.468040,-232.501938,-0.145538,0.000000
5.570000,0.001122,-232.546417,-0.005967,-0.005501,-0.139719,0.004989,0.000254,-1.397187,-232.546417,-0.138531,0.000000
5.990000,-0.015640,-232.635376,-0.005678,-0.005225,-0.132720,-0.069571,-0.003544,-1.327202,-232.635376,-0.131541,0.000000
6.410000,-0.039101,-232.635376,-0.005407,-0.004954,-0.125826,-0.173928,-0.008860,-1.258258,-232.635376,-0.124534,0.000000
6.830000,-0.027924,-232.590897,-0.005126,-0.004682,-0.118931,-0.124210,-0.006328,-1.189313,-232.590897,-0.117544,0.000000
7.250000,-0.002235,-232.635376,-0.004838,-0.004403,-0.111837,-0.009944,-0.000507,-1.118374,-232.635376,-0.110537,0.000000
7.670001,0.005219,-232.679855,-0.004562,-0.004124,-0.104752,0.023213,0.001183,-1.047522,-232.679855,-0.103547,0.000000
8.090000,0.030907,-232.768814,-0.004268,-0.003850,-0.097797,0.137480,0.007004,-0.977970,-232.768814,-0.096557,0.000000
8.510000,-0.024200,-232.768814,-0.003980,-0.003571,-0.090712,-0.107649,-0.005484,-0.907118,-232.768814,-0.089550,0.000000
8.930000,-0.064789,-232.768814,-0.003708,-0.003307,-0.083991,-0.288195,-0.014681,-0.839908,-232.768814,-0.082560,0.000000
9.350000,-0.025322,-232.768814,-0.003428,-0.003024,-0.076819,-0.112638,-0.005738,-0.768189,-232.768814,-0.075553,0.000000
9.770000,0.034264,-232.768814,-0.003134,-0.002749,-0.069829,0.152412,0.007764,-0.698290,-232.768814,-0.068563,0.000000
10.190001,0.099052,-232.857773,-0.002867,-0.002476,-0.062883,0.440607,0.022446,-0.628825,-232.857773,-0.061556,0.000000
10.610001,0.058090,-232.768814,-0.002820,0.000012,0.000304,0.258398,0.013163,0.003035,-232.768814,0.000494,0.000000
11.030001,0.091606,-232.813293,-0.002820,0.000012,0.000304,0.407484,0.020758,0.003035,-232.813293,0.000980,0.000000
11.450001,0.092346,-232.857773,-0.002828,0.000012,0.000312,0.410776,0.020926,0.003122,-232.857773,0.001674,0.000000
11.870001,0.124374,-232.946747,-0.002807,0.000057,0.001457,0.553245,0.028184,0.014569,-232.946747,0.002376,0.000000
12.290001,0.188049,-232.902252,-0.002764,0.000081,0.002064,0.836485,0.042613,0.020640,-232.902252,0.003079,0.000000
12.710001,0.397324,-232.946747,-0.002742,0.000110,0.002784,1.767384,0.090035,0.027838,-232.946747,0.003781,0.000000
13.130001,0.647186,-232.946747,-0.002712,0.000128,0.003261,2.878828,0.146655,0.032608,-232.946747,0.004475,0.000000
13.550000,1.330116,-232.946747,-0.002695,0.000163,0.004137,5.916653,0.301409,0.041367,-232.946747,0.005177,0.000000
13.970000,2.078209,-232.991226,-0.002690,0.000189,0.004813,9.244335,0.470929,0.048131,-232.991226,0.005880,0.000000
14.390000,3.113411,-233.080185,-0.002656,0.000222,0.005637,13.849144,0.705509,0.056370,-233.080185,0.006582,0.000000
14.810000,4.089394,-233.035706,-0.002630,0.000251,0.006383,18.190531,0.926670,0.063828,-233.035706,0.007276,0.000000
15.230000,5.282104,-232.991226,-0.002613,0.000278,0.007068,23.495974,1.196942,0.070679,-232.991226,0.007978,0.000000
15.650001,6.075630,-233.035706,-0.002591,0.000297,0.007545,27.025753,1.376758,0.075449,-233.035706,0.008681,0.000000
16.070002,7.209503,-233.080185,-0.002596,0.000322,0.008178,32.069473,1.633697,0.081779,-233.080185,0.009375,0.000000
16.490002,8.749634,-233.124664,-0.002574,0.000354,0.009002,38.920315,1.982695,0.090018,-233.124664,0.010077,0.000000
16.910002,10.185135,-233.124664,-0.002535,0.000387,0.009826,45.305744,2.307985,0.098257,-233.124664,0.010780,0.000000
17.330000,11.404655,-233.080185,-0.002518,0.000412,0.010476,50.730442,2.584332,0.104761,-233.080185,0.011482,0.000000
17.750000,12.720619,-233.124664,-0.002518,0.000441,0.011205,56.584141,2.882534,0.112046,-233.124664,0.012176,0.000000
18.170000,13.823959,-233.169144,-0.002501,0.000464,0.011786,61.492043,3.132554,0.117856,-233.169144,0.012878,0.000000
18.590000,15.366699,-233.169144,-0.002458,0.000491,0.012471,68.354492,3.482144,0.124707,-233.169144,0.013581,0.000000
19.010000,16.019463,-233.213623,-0.002449,0.000508,0.012896,71.258125,3.630062,0.128956,-233.213623,0.014275,0.000000
19.430000,17.962135,-233.213623,-0.002445,0.000546,0.013867,79.899567,4.070278,0.138669,-233.213623,0.014977,0.000000
19.850000,18.927322,-233.213623,-0.002419,0.000572,0.014517,84.192932,4.288992,0.145174,-233.213623,0.015679,0.000000
20.270000,20.939621,-233.302582,-0.002414,0.000602,0.015298,93.144089,4.744986,0.152979,-233.302582,0.016382,0.000000
20.690001,22.313301,-233.302582,-0.002384,0.000633,0.016070,99.254517,5.056266,0.160697,-233.302582,0.017076,0.000000
21.110001,23.383873,-233.258102,-0.002367,0.000659,0.016746,104.016663,5.298862,0.167461,-233.258102,0.017778,0.000000
21.530001,24.560944,-233.347076,-0.002358,0.000686,0.017414,109.252533,5.565589,0.174139,-233.347076,0.018481,0.000000
21.950001,25.913033,-233.258102,-0.002337,0.000713,0.018116,115.266922,5.871977,0.181163,-233.258102,0.019183,0.000000
22.370001,26.978012,-233.347076,-0.002302,0.000740,0.018784,120.004189,6.113305,0.187841,-233.347076,0.019877,0.000000
22.790001,28.450745,-233.391556,-0.002276,0.000768,0.019504,126.555229,6.447031,0.195039,-233.391556,0.020579,0.000000
23.210001,29.544029,-233.391556,-0.002272,0.000796,0.020206,131.418411,6.694773,0.202064,-233.391556,0.021282,0.000000
23.630001,30.795578,-233.347076,-0.002233,0.000823,0.020909,136.985565,6.978378,0.209088,-233.347076,0.021975,0.000000
24.050001,31.934288,-233.436035,-0.002216,0.000851,0.021611,142.050812,7.236413,0.216113,-233.436035,0.022678,0.000000
24.470001,32.852188,-233.391556,-0.002203,0.000874,0.022192,146.133835,7.444412,0.221923,-233.391556,0.023380,0.000000
24.890001,34.329391,-233.436035,-0.002164,0.000906,0.023007,152.704758,7.779151,0.230075,-233.436035,0.024083,0.000000
25.310001,35.089401,-233.480515,-0.002156,0.000929,0.023597,156.085449,7.951372,0.235972,-233.480515,0.024777,0.000000
25.730001,36.195724,-233.436035,-0.002151,0.000957,0.024317,161.006622,8.202068,0.243170,-233.436035,0.025479,0.000000
26.150002,38.189034,-233.480515,-0.002104,0.000993,0.025228,169.873306,8.653759,0.252276,-233.480515,0.026182,0.000000
26.570002,38.403893,-233.524994,-0.002091,0.001012,0.025705,170.829041,8.702446,0.257046,-233.524994,0.026875,0.000000
26.990002,39.607399,-233.524994,-0.002074,0.001043,0.026502,176.182510,8.975164,0.265024,-233.524994,0.027578,0.000000
27.410002,41.119972,-233.569473,-0.002039,0.001076,0.027335,182.910767,9.317919,0.273350,-233.569473,0.028280,0.000000
27.830002,41.665871,-233.524994,-0.002031,0.001099,0.027916,185.339050,9.441622,0.279160,-233.524994,0.028983,0.000000
28.250002,42.921516,-233.613953,-0.002001,0.001130,0.028705,190.924438,9.726154,0.287052,-233.613953,0.029676,0.000000
28.670002,43.871811,-233.658432,-0.002001,0.001158,0.029416,195.151566,9.941494,0.294163,-233.658432,0.030379,0.000000
29.090002,44.450478,-233.702911,-0.001962,0.001182,0.030015,197.725601,10.072622,0.300147,-233.702911,0.031081,0.000000
29.510002,45.433914,-233.613953,-0.001944,0.001208,0.030674,202.100143,10.295472,0.306738,-233.613953,0.031784,0.000000
29.930002,46.251640,-233.613953,-0.001906,0.001231,0.031263,205.737564,10.480771,0.312635,-233.613953,0.032478,0.000000
30.350002,48.017799,-233.658432,-0.001893,0.001265,0.032131,213.593842,10.880988,0.321307,-233.658432,0.033180,0.000000
30.770002,49.176254,-233.702911,-0.001880,0.001297,0.032937,218.746902,11.143499,0.329372,-233.702911,0.033883,0.000000
31.190001,50.106071,-233.791885,-0.001832,0.001324,0.033631,222.882935,11.354198,0.336310,-233.791885,0.034576,0.000000
31.610001,50.941673,-233.747391,-0.001811,0.001349,0.034255,226.599884,11.543549,0.342554,-233.747391,0.035279,0.000000
32.030003,51.789932,-233.702911,-0.001794,0.001372,0.034836,230.373123,11.735766,0.348365,-233.702911,0.035981,0.000000
32.450001,53.046318,-233.791885,-0.001768,0.001401,0.035591,235.961807,12.020467,0.355909,-233.791885,0.036684,0.000000
32.870003,54.605072,-233.836365,-0.001755,0.001433,0.036406,242.895493,12.373687,0.364061,-233.836365,0.037377,0.000000
33.290001,55.674896,-233.836365,-0.001733,0.001461,0.037109,247.654312,12.616112,0.371086,-233.836365,0.038080,0.000000
33.710003,56.347404,-233.791885,-0.001712,0.001481,0.037620,250.645767,12.768505,0.376203,-233.791885,0.038782,0.000000
34.130001,57.662994,-233.880844,-0.001694,0.001509,0.038340,256.497803,13.066622,0.383401,-233.880844,0.039476,0.000000
34.550003,58.396194,-233.880844,-0.001677,0.001538,0.039077,259.759247,13.232767,0.390772,-233.880844,0.040179,0.000000
34.970001,59.883827,-233.969803,-0.001647,0.001565,0.039754,266.376556,13.569869,0.397536,-233.969803,0.040881,0.000000
35.390003,61.356186,-233.969803,-0.001621,0.001594,0.040491,272.925934,13.903511,0.404908,-233.969803,0.041583,0.000000
35.810001,62.908981,-233.925323,-0.001595,0.001624,0.041254,279.833130,14.255379,0.412539,-233.925323,0.042277,0.000000
36.230003,64.402557,-233.969803,-0.001587,0.001653,0.041982,286.476868,14.593828,0.419824,-233.969803,0.042980,0.000000
36.650002,65.512604,-233.880844,-0.001574,0.001681,0.042685,291.414612,14.845367,0.426849,-233.880844,0.043682,0.000000
37.070004,66.030945,-233.969803,-0.001535,0.001702,0.043231,293.720306,14.962826,0.432312,-233.969803,0.044385,0.000000
37.490002,67.633636,-234.058762,-0.001505,0.001730,0.043934,300.849426,15.326001,0.439337,-234.058762,0.045078,0.000000
37.910004,68.977905,-234.014282,-0.001492,0.001758,0.044653,306.829041,15.630617,0.446535,-234.014282,0.045781,0.000000
38.330002,71.246399,-234.014282,-0.001475,0.001791,0.045486,316.919800,16.144665,0.454860,-234.014282,0.046483,0.000000
38.750000,72.332611,-234.103241,-0.001457,0.001815,0.046102,321.751526,16.390804,0.461017,-234.103241,0.047177,0.000000
39.170002,73.863434,-234.103241,-0.001436,0.001842,0.046795,328.560974,16.737694,0.467955,-234.103241,0.047880,0.000000
39.590000,75.317169,-234.147720,-0.001414,0.001870,0.047498,335.027496,17.067116,0.474980,-234.147720,0.048582,0.000000
40.010002,76.387375,-234.147720,-0.001401,0.001889,0.047992,339.788025,17.309626,0.479923,-234.147720,0.049284,0.000000
40.430000,77.478058,-234.103241,-0.001384,0.001922,0.048825,344.639618,17.556778,0.488248,-234.103241,0.049978,0.000000
40.850002,79.515305,-234.147720,-0.001375,0.001944,0.049389,353.701752,18.018425,0.493885,-234.147720,0.050681,0.000000
41.270000,81.340302,-234.236694,-0.001362,0.001974,0.050152,361.819733,18.431974,0.501517,-234.236694,0.051383,0.000000
41.690002,83.129181,-234.192200,-0.001332,0.002005,0.050915,369.777069,18.837341,0.509148,-234.192200,0.052077,0.000000
42.110001,85.106094,-234.236694,-0.001319,0.002032,0.051617,378.570801,19.285316,0.516173,-234.236694,0.052779,0.000000
42.530003,86.715866,-234.236694,-0.001302,0.002060,0.052328,385.731445,19.650097,0.523284,-234.236694,0.053482,0.000000
42.950001,88.236267,-234.236694,-0.001293,0.002084,0.052944,392.494507,19.994623,0.529441,-234.236694,0.054184,0.000000
43.370003,89.482224,-234.325653,-0.001289,0.002106,0.053482,398.036804,20.276962,0.534818,-234.325653,0.054878,0.000000
43.790001,91.755920,-234.325653,-0.001246,0.002138,0.054314,408.150726,20.792189,0.543144,-234.325653,0.055580,0.000000
44.210003,93.814774,-234.325653,-0.001242,0.002169,0.055104,417.308960,21.258732,0.551035,-234.325653,0.056283,0.000000
44.630001,95.850906,-234.325653,-0.001229,0.002198,0.055832,426.366119,21.720125,0.558320,-234.325653,0.056985,0.000000
45.050003,97.395874,-234.370132,-0.001220,0.002222,0.056430,433.238495,22.070221,0.564304,-234.370132,0.057679,0.000000
45.470001,99.489365,-234.414612,-0.001207,0.002253,0.057228,442.550781,22.544613,0.572282,-234.414612,0.058382,0.000000
45.890003,100.962463,-234.414612,-0.001181,0.002280,0.057905,449.103455,22.878422,0.579047,-234.414612,0.059084,0.000000
46.310001,103.391083,-234.370132,-0.001164,0.002306,0.058581,459.906494,23.428755,0.585811,-234.370132,0.059778,0.000000
46.730003,104.750977,-234.414612,-0.001160,0.002329,0.059145,465.955627,23.736910,0.591448,-234.414612,0.060480,0.000000
47.150002,105.385132,-234.503571,-0.001143,0.002349,0.059665,468.776489,23.880611,0.596651,-234.503571,0.061183,0.000000
47.570004,110.218521,-234.548050,-0.001121,0.002396,0.060871,490.276459,24.975872,0.608706,-234.548050,0.061885,0.000000
47.990002,111.037003,-234.548050,-0.001104,0.002416,0.061374,493.917267,25.161345,0.613736,-234.548050,0.062579,0.000000
48.410004,113.230652,-234.592529,-0.001108,0.002442,0.062024,503.675110,25.658432,0.620240,-234.592529,0.063281,0.000000
48.830002,115.893112,-234.459091,-0.001091,0.002476,0.062883,515.518311,26.261755,0.628825,-234.459091,0.063984,0.000000
49.250004,117.452972,-234.503571,-0.001065,0.002498,0.063446,522.456909,26.615223,0.634462,-234.503571,0.064678,0.000000
49.670002,120.096451,-234.592529,-0.001061,0.002533,0.064331,534.215698,27.214245,0.643308,-234.592529,0.065380,0.000000
50.090004,122.012314,-234.637024,-0.001035,0.002558,0.064981,542.737854,27.648384,0.649812,-234.637024,0.066083,0.000000
50.510002,123.679413,-234.637024,-0.001035,0.002583,0.065614,550.153503,28.026155,0.656143,-234.637024,0.066785,0.000000
50.930004,125.526016,-234.548050,-0.001022,0.002606,0.066195,558.367615,28.444601,0.661953,-234.548050,0.067479,0.000000
51.350002,127.181580,-234.637024,-0.001005,0.002629,0.066785,565.731934,28.819757,0.667850,-234.637024,0.068181,0.000000
51.770004,130.086090,-234.681503,-0.000987,0.002663,0.067652,578.651855,29.477930,0.676523,-234.681503,0.068884,0.000000
52.190002,132.555664,-234.681503,-0.000979,0.002697,0.068493,589.637024,30.037544,0.684935,-234.681503,0.069586,0.000000
52.610001,134.634247,-234.681503,-0.000957,0.002723,0.069153,598.883057,30.508556,0.691526,-234.681503,0.070280,0.000000
53.030003,136.679687,-234.725983,-0.000944,0.002748,0.069812,607.981628,30.972059,0.698117,-234.725983,0.070982,0.000000
53.450001,138.004959,-234.725983,-0.000944,0.002767,0.070289,613.876709,31.272371,0.702886,-234.725983,0.071685,0.000000
53.870003,140.649918,-234.770462,-0.000931,0.002801,0.071147,625.642090,31.871727,0.711472,-234.770462,0.072379,0.000000
54.290001,143.306061,-234.770462,-0.000914,0.002833,0.071954,637.457214,32.473618,0.719537,-234.770462,0.073081,0.000000
54.710003,145.559647,-234.814941,-0.000923,0.002860,0.072639,647.481628,32.984287,0.726388,-234.814941,0.073784,0.000000
55.130001,147.034241,-234.770462,-0.000888,0.002880,0.073142,654.040955,33.318436,0.731418,-234.770462,0.074486,0.000000
55.550003,149.463226,-234.814941,-0.000880,0.002913,0.073992,664.845642,33.868855,0.739917,-234.814941,0.075180,0.000000
55.970001,151.869125,-234.859421,-0.000867,0.002939,0.074651,675.547607,34.414032,0.746508,-234.859421,0.075882,0.000000
56.390003,153.886642,-234.859421,-0.000849,0.002966,0.075345,684.521973,34.871208,0.753446,-234.859421,0.076585,0.000000
56.810001,156.254562,-234.859421,-0.000849,0.002993,0.076021,695.054993,35.407791,0.760210,-234.859421,0.077287,0.000000
57.230003,157.966736,-234.903900,-0.000836,0.003021,0.076741,702.671143,35.795776,0.767408,-234.903900,0.077981,0.000000
57.650002,161.189621,-234.903900,-0.000819,0.003051,0.077504,717.007263,36.526093,0.775040,-234.903900,0.078683,0.000000
58.070004,163.506516,-234.992859,-0.000806,0.003081,0.078258,727.313293,37.051105,0.782584,-234.992859,0.079386,0.000000
58.490002,165.227997,-234.948380,-0.000806,0.003106,0.078900,734.970825,37.441200,0.789002,-234.948380,0.080080,0.000000
58.910004,166.542847,-234.948380,-0.000780,0.003120,0.079247,740.819580,37.739151,0.792471,-234.948380,0.080782,0.000000
59.330002,170.134369,-234.992859,-0.000780,0.003163,0.080348,756.795471,38.552998,0.803485,-234.992859,0.081485,0.000000
59.750004,172.733536,-234.948380,-0.000780,0.003192,0.081068,768.357117,39.141979,0.810683,-234.948380,0.082187,0.000000
60.170002,174.549973,-235.081833,-0.000763,0.003214,0.081632,776.437073,39.553589,0.816320,-235.081833,0.082881,0.000000
60.590004,176.845642,-235.081833,-0.000746,0.003241,0.082317,786.648682,40.073795,0.823171,-235.081833,0.083583,0.000000
61.010002,178.976730,-235.037338,-0.000737,0.003270,0.083046,796.128235,40.556705,0.830455,-235.037338,0.084286,0.000000
61.430004,180.750717,-235.037338,-0.000733,0.003288,0.083523,804.019348,40.958698,0.835225,-235.037338,0.084979,0.000000
61.850002,182.020874,-235.126312,-0.000737,0.003306,0.083973,809.669312,41.246521,0.839735,-235.126312,0.085682,0.000000
62.270004,185.300735,-235.126312,-0.000711,0.003343,0.084919,824.258850,41.989746,0.849187,-235.126312,0.086384,0.000000
62.690002,187.840683,-235.170792,-0.000698,0.003373,0.085682,835.557068,42.565308,0.856819,-235.170792,0.087087,0.000000
63.110004,190.314346,-235.170792,-0.000694,0.003399,0.086341,846.560486,43.125847,0.863410,-235.170792,0.087781,0.000000
63.530003,193.275818,-235.215271,-0.000690,0.003434,0.087217,859.733765,43.796928,0.872169,-235.215271,0.088483,0.000000
63.950005,195.309357,-235.215271,-0.000673,0.003460,0.087885,868.779419,44.257732,0.878847,-235.215271,0.089185,0.000000
64.370003,197.510437,-235.215271,-0.000673,0.003483,0.088466,878.570312,44.756504,0.884657,-235.215271,0.089888,0.000000
64.790001,199.393921,-235.259750,-0.000642,0.003509,0.089125,886.948486,45.183308,0.891248,-235.259750,0.090582,0.000000
65.210007,202.358734,-235.215271,-0.000647,0.003540,0.089923,900.136597,45.855145,0.899226,-235.215271,0.091284,0.000000
65.630005,205.086365,-235.215271,-0.000629,0.003572,0.090729,912.269714,46.473236,0.907291,-235.215271,0.091987,0.000000
66.050003,207.509033,-235.304230,-0.000638,0.003597,0.091354,923.046265,47.022221,0.913536,-235.304230,0.092680,0.000000
66.470001,209.833008,-235.259750,-0.000634,0.003624,0.092039,933.383850,47.548840,0.920387,-235.259750,0.093383,0.000000
66.889999,212.309662,-235.348709,-0.000612,0.003653,0.092776,944.400513,48.110058,0.927758,-235.348709,0.094085,0.000000
67.310005,214.556549,-235.259750,-0.000608,0.003676,0.093374,954.395203,48.619209,0.933742,-235.259750,0.094788,0.000000
67.730003,217.158691,-235.304230,-0.000604,0.003705,0.094103,965.970093,49.208862,0.941027,-235.304230,0.095482,0.000000
68.150002,219.423096,-235.437668,-0.000595,0.003734,0.094848,976.042664,49.721981,0.948485,-235.437668,0.096184,0.000000
68.570000,220.089264,-235.393188,-0.000582,0.003740,0.094996,979.005920,49.872940,0.949959,-235.393188,0.096886,0.000000
68.990005,222.023743,-235.437668,-0.000569,0.003752,0.095308,987.610962,50.311298,0.953081,-235.437668,0.016759,0.000000
69.410004,220.080322,-235.437668,-0.000573,0.003686,0.093626,978.966187,49.870914,0.936257,-235.437668,982.000671,0.000000
69.830002,219.550446,-235.482162,-0.000556,0.003716,0.094380,976.609131,49.750843,0.943802,-235.482162,982.000671,0.000000
70.250000,219.315094,-235.482162,-0.000565,0.003745,0.095126,975.562256,49.697510,0.951260,-235.482162,982.000671,0.000000
70.670006,218.940491,-235.526642,-0.000556,0.003745,0.095126,973.895935,49.612625,0.951260,-235.526642,982.000671,0.000000
71.090004,220.134308,-235.526642,-0.000539,0.003746,0.095152,979.206299,49.883148,0.951520,-235.526642,982.000671,0.000000
71.510002,219.599213,-235.437668,-0.000556,0.003746,0.095152,976.826111,49.761894,0.951520,-235.437668,982.000671,0.000000
71.930000,219.121826,-235.526642,-0.000548,0.003746,0.095161,974.702576,49.653717,0.951607,-235.526642,982.000671,0.000000
72.350006,220.534973,-235.571121,-0.000543,0.003757,0.095430,980.988525,49.973942,0.954295,-235.571121,982.000671,0.000000
72.770004,220.097076,-235.571121,-0.000535,0.003757,0.095430,979.040710,49.874710,0.954295,-235.571121,982.000671,0.000000
73.190002,219.637573,-235.615601,-0.000526,0.003758,0.095447,976.996704,49.770584,0.954469,-235.615601,982.000671,0.000000
73.610001,219.649475,-235.615601,-0.000530,0.003783,0.096080,977.049683,49.773285,0.960799,-235.615601,982.000671,0.000000
74.030006,219.700867,-235.660080,-0.000543,0.003788,0.096210,977.278259,49.784927,0.962100,-235.660080,982.000671,0.000000
74.450005,219.493835,-235.704559,-0.000530,0.003788,0.096227,976.357361,49.738014,0.962274,-235.704559,982.000671,0.000000
74.870003,219.811462,-235.704559,-0.000526,0.003795,0.096401,977.770203,49.809990,0.964008,-235.704559,982.000671,0.000000
75.290001,219.578735,-235.660080,-0.000517,0.003797,0.096453,976.734985,49.757252,0.964528,-235.660080,982.000671,0.000000
75.710007,219.599213,-235.704559,-0.000526,0.003800,0.096531,976.826111,49.761894,0.965309,-235.704559,982.000671,0.000000
76.130005,219.458099,-235.704559,-0.000513,0.003802,0.096566,976.198364,49.729916,0.965656,-235.704559,982.000671,0.000000
76.550003,219.719116,-235.749039,-0.000509,0.003807,0.096704,977.359436,49.789066,0.967043,-235.749039,982.000671,0.000000
76.970001,219.553040,-235.793518,-0.000504,0.003809,0.096748,976.620667,49.751431,0.967477,-235.793518,982.000671,0.000000
77.390007,219.348602,-235.749039,-0.000509,0.003809,0.096748,975.711304,49.705105,0.967477,-235.749039,982.000671,0.000000
77.810005,219.573151,-235.749039,-0.000504,0.003814,0.096886,976.710144,49.755985,0.968865,-235.749039,982.000671,0.000000
78.230003,219.384369,-235.749039,-0.000500,0.003815,0.096895,975.870422,49.713211,0.968951,-235.749039,982.000671,0.000000
78.650002,219.812958,-235.793518,-0.000517,0.003822,0.097086,977.776855,49.810329,0.970859,-235.793518,982.000671,0.000000
79.070007,219.650604,-235.837997,-0.000487,0.003822,0.097086,977.054687,49.773537,0.970859,-235.837997,982.000671,0.000000
79.490005,219.460693,-235.882477,-0.000483,0.003822,0.097086,976.209900,49.730503,0.970859,-235.882477,982.000671,0.000000
79.910004,219.322540,-235.926971,-0.000504,0.003828,0.097242,975.595398,49.699200,0.972420,-235.926971,982.000671,0.000000
80.330002,219.669586,-235.971451,-0.000492,0.003830,0.097277,977.139099,49.777840,0.972767,-235.971451,982.000671,0.000000
80.750008,219.517670,-235.882477,-0.000487,0.003831,0.097303,976.463379,49.743412,0.973027,-235.882477,982.000671,0.000000
81.170006,219.568298,-235.971451,-0.000479,0.003834,0.097381,976.688599,49.754890,0.973808,-235.971451,982.000671,0.000000
81.590004,219.445801,-235.882477,-0.000487,0.003834,0.097381,976.143677,49.727131,0.973808,-235.882477,982.000671,0.000000
82.010002,219.626770,-235.926971,-0.000496,0.003838,0.097494,976.948669,49.768135,0.974935,-235.926971,982.000671,0.000000
82.430000,219.516541,-235.971451,-0.000487,0.003838,0.097494,976.458313,49.743160,0.974935,-235.971451,982.000671,0.000000
82.850006,219.432404,-236.015930,-0.000474,0.003840,0.097537,976.084106,49.724094,0.975369,-236.015930,982.000671,0.000000
83.270004,219.296844,-236.060410,-0.000487,0.003840,0.097537,975.481079,49.693375,0.975369,-236.060410,982.000671,0.000000
83.690002,219.114380,-235.971451,-0.000479,0.003840,0.097537,974.669434,49.652027,0.975369,-235.971451,982.000671,0.000000
84.110001,220.501099,-236.060410,-0.000470,0.003835,0.097398,980.837891,49.966263,0.973981,-236.060410,982.000671,0.000000
84.530006,220.345825,-236.104889,-0.000479,0.003835,0.097398,980.147156,49.931080,0.973981,-236.104889,982.000671,0.000000
84.950005,220.114563,-236.149368,-0.000479,0.003835,0.097398,979.118469,49.878674,0.973981,-236.149368,982.000671,0.000000
85.370003,219.893768,-236.149368,-0.000474,0.003835,0.097398,978.136353,49.828640,0.973981,-236.149368,982.000671,0.000000
85.790001,219.704590,-236.149368,-0.000470,0.003835,0.097407,977.294800,49.785770,0.974068,-236.149368,982.000671,0.000000
86.210007,219.518036,-236.193848,-0.000461,0.003835,0.097407,976.464966,49.743500,0.974068,-236.193848,982.000671,0.000000
86.630005,219.350098,-236.193848,-0.000470,0.003853,0.097875,975.717957,49.705441,0.978751,-236.193848,982.000671,0.000000
87.050003,219.899353,-236.238327,-0.000474,0.003859,0.098031,978.161194,49.829906,0.980312,-236.238327,982.000671,0.000000
87.470001,219.811462,-236.193848,-0.000453,0.003859,0.098031,977.770203,49.809990,0.980312,-236.193848,982.000671,0.000000
87.890007,219.649475,-236.193848,-0.000466,0.003859,0.098031,977.049683,49.773285,0.980312,-236.193848,982.000671,0.000000
88.310005,219.515442,-236.193848,-0.000470,0.003859,0.098031,976.453430,49.742912,0.980312,-236.193848,982.000671,0.000000
88.730003,219.513580,-236.282806,-0.000466,0.003862,0.098101,976.445190,49.742489,0.981006,-236.282806,982.000671,0.000000
89.150002,219.481903,-236.282806,-0.000457,0.003864,0.098153,976.304260,49.735310,0.981526,-236.282806,982.000671,0.000000
89.570007,219.663635,-236.282806,-0.000448,0.003867,0.098213,977.112671,49.776493,0.982133,-236.282806,982.000671,0.000000
89.990005,219.586182,-236.327286,-0.000461,0.003867,0.098213,976.768127,49.758942,0.982133,-236.327286,982.000671,0.000000
90.410004,219.509460,-236.282806,-0.000457,0.003868,0.098248,976.426819,49.741558,0.982480,-236.282806,982.000671,0.000000
90.830002,219.858002,-236.460739,-0.000461,0.003872,0.098361,977.977234,49.820534,0.983607,-236.460739,982.000671,0.000000
91.250008,219.790619,-236.460739,-0.000453,0.003872,0.098361,977.677490,49.805267,0.983607,-236.460739,982.000671,0.000000
91.670006,219.698273,-236.327286,-0.000444,0.003872,0.098361,977.266724,49.784340,0.983607,-236.327286,982.000671,0.000000
92.090004,219.584320,-236.416260,-0.000457,0.003873,0.098369,976.759827,49.758518,0.983694,-236.416260,982.000671,0.000000
92.510002,219.513947,-236.416260,-0.000448,0.003873,0.098378,976.446777,49.742573,0.983781,-236.416260,982.000671,0.000000
92.930008,219.899719,-236.505219,-0.000444,0.003880,0.098552,978.162781,49.829987,0.985515,-236.505219,982.000671,0.000000
93.350006,219.907898,-236.416260,-0.000461,0.003880,0.098552,978.199158,49.831841,0.985515,-236.416260,982.000671,0.000000
93.770004,219.850555,-236.460739,-0.000440,0.003880,0.098552,977.944092,49.818848,0.985515,-236.460739,982.000671,0.000000
94.190002,219.761200,-236.505219,-0.000444,0.003880,0.098552,977.546631,49.798603,0.985515,-236.505219,982.000671,0.000000
94.610008,219.675934,-236.594177,-0.000453,0.003880,0.098560,977.167358,49.779278,0.985602,-236.594177,982.000671,0.000000
95.030006,219.585052,-236.505219,-0.000435,0.003881,0.098569,976.763123,49.758686,0.985689,-236.505219,982.000671,0.000000
95.450005,219.504272,-236.594177,-0.000457,0.003881,0.098569,976.403748,49.740376,0.985689,-236.594177,982.000671,0.000000
95.870003,219.396637,-236.594177,-0.000440,0.003881,0.098569,975.924988,49.715988,0.985689,-236.594177,982.000671,0.000000
96.290001,220.010681,-236.549698,-0.000457,0.003888,0.098751,978.656372,49.855133,0.987510,-236.549698,982.000671,0.000000
96.710007,219.923920,-236.594177,-0.000448,0.003888,0.098751,978.270447,49.835472,0.987510,-236.594177,982.000671,0.000000
97.130005,219.850555,-236.638657,-0.000444,0.003888,0.098751,977.944092,49.818848,0.987510,-236.638657,982.000671,0.000000
97.550003,219.771637,-236.683136,-0.000444,0.003888,0.098751,977.593079,49.800964,0.987510,-236.683136,982.000671,0.000000
97.970001,219.689331,-236.638657,-0.000435,0.003888,0.098751,977.226929,49.782314,0.987510,-236.638657,982.000671,0.000000
98.390007,219.600342,-236.683136,-0.000431,0.003888,0.098760,976.831116,49.762150,0.987597,-236.683136,982.000671,0.000000
98.810005,219.528839,-236.727615,-0.000440,0.003888,0.098760,976.513062,49.745945,0.987597,-236.727615,982.000671,0.000000
99.230003,219.432404,-236.727615,-0.000431,0.003888,0.098760,976.084106,49.724094,0.987597,-236.727615,982.000671,0.000000
99.650002,219.336304,-236.816589,-0.000435,0.003888,0.098760,975.656616,49.702320,0.987597,-236.816589,982.000671,0.000000
100.070007,219.259247,-236.727615,-0.000435,0.003888,0.098760,975.313843,49.684856,0.987597,-236.727615,982.000671,0.000000
100.490005,219.178070,-236.683136,-0.000431,0.003888,0.098760,974.952759,49.666462,0.987597,-236.683136,982.000671,0.000000
100.910004,219.092407,-236.816589,-0.000461,0.003888,0.098760,974.571716,49.647049,0.987597,-236.816589,982.000671,0.000000
101.330002,218.985931,-236.905548,-0.000444,0.003888,0.098760,974.098083,49.622921,0.987597,-236.905548,982.000671,0.000000
101.750008,218.911438,-236.816589,-0.000418,0.003888,0.098760,973.766724,49.606037,0.987597,-236.816589,982.000671,0.000000
102.170006,218.813507,-236.816589,-0.000440,0.003888,0.098760,973.331116,49.583847,0.987597,-236.816589,982.000671,0.000000
102.590004,218.742767,-236.816589,-0.000457,0.003888,0.098760,973.016418,49.567818,0.987597,-236.816589,982.000671,0.000000
103.010002,220.769592,-236.861069,-0.000427,0.003863,0.098118,982.032166,50.027103,0.981179,-236.861069,982.000671,0.000000
103.430008,220.665314,-236.905548,-0.000427,0.003863,0.098118,981.568359,50.003475,0.981179,-236.905548,982.000671,0.000000
103.850006,220.572968,-236.905548,-0.000410,0.003863,0.098118,981.157532,49.982548,0.981179,-236.905548,982.000671,0.000000
104.270004,220.405762,-236.905548,-0.000414,0.003863,0.098118,980.413818,49.944660,0.981179,-236.905548,982.000671,0.000000
104.690002,220.380066,-236.905548,-0.000423,0.003863,0.098118,980.299500,49.938835,0.981179,-236.905548,982.000671,0.000000
105.110008,220.321991,-236.994507,-0.000423,0.003863,0.098118,980.041138,49.925674,0.981179,-236.994507,982.000671,0.000000
105.530006,220.240448,-237.038986,-0.000418,0.003863,0.098118,979.678467,49.907200,0.981179,-237.038986,982.000671,0.000000
105.950005,220.125366,-236.994507,-0.000427,0.003863,0.098127,979.166504,49.881123,0.981266,-236.994507,982.000671,0.000000
106.370003,220.054260,-237.038986,-0.000414,0.003863,0.098127,978.850220,49.865005,0.981266,-237.038986,982.000671,0.000000
106.790009,219.971222,-236.994507,-0.000414,0.003863,0.098127,978.480835,49.846191,0.981266,-236.994507,982.000671,0.000000
107.210007,219.910522,-237.083466,-0.000427,0.003864,0.098144,978.210876,49.832436,0.981439,-237.083466,982.000671,0.000000
107.630005,219.839386,-237.038986,-0.000418,0.003864,0.098144,977.894409,49.816319,0.981439,-237.038986,982.000671,0.000000
108.050003,219.764557,-237.038986,-0.000423,0.003864,0.098144,977.561584,49.799362,0.981439,-237.038986,982.000671,0.000000
108.470009,219.674072,-237.083466,-0.000423,0.003864,0.098144,977.159058,49.778854,0.981439,-237.083466,982.000671,0.000000
108.890007,219.606659,-237.172424,-0.000414,0.003864,0.098144,976.859192,49.763580,0.981439,-237.172424,982.000671,0.000000
109.310005,219.524750,-237.216919,-0.000423,0.003864,0.098153,976.494873,49.745022,0.981526,-237.216919,982.000671,0.000000
109.730003,219.430908,-237.216919,-0.000423,0.003864,0.098153,976.077454,49.723755,0.981526,-237.216919,982.000671,0.000000
110.150002,219.346008,-237.216919,-0.000431,0.003864,0.098153,975.699768,49.704517,0.981526,-237.216919,982.000671,0.000000
110.570007,219.285675,-237.216919,-0.000405,0.003864,0.098153,975.431396,49.690842,0.981526,-237.216919,982.000671,0.000000
110.990005,219.815948,-237.216919,-0.000414,0.003908,0.099263,977.790161,49.811005,0.992627,-237.216919,982.000671,0.000000
111.410004,219.777588,-237.261398,-0.000423,0.003908,0.099263,977.619507,49.802311,0.992627,-237.261398,982.000671,0.000000
111.830002,219.705353,-237.305878,-0.000418,0.003908,0.099263,977.298218,49.785942,0.992627,-237.305878,982.000671,0.000000
112.250008,219.649841,-237.261398,-0.000414,0.003908,0.099263,977.051270,49.773365,0.992627,-237.261398,982.000671,0.000000
112.670006,219.589539,-237.216919,-0.000423,0.003908,0.099263,976.783081,49.759701,0.992627,-237.216919,982.000671,0.000000
113.090004,219.552307,-237.350357,-0.000410,0.003908,0.099263,976.617432,49.751266,0.992627,-237.350357,982.000671,0.000000
113.510002,219.487488,-237.350357,-0.000418,0.003908,0.099263,976.329102,49.736576,0.992627,-237.350357,982.000671,0.000000
113.930008,219.420471,-237.394836,-0.000423,0.003908,0.099263,976.031006,49.721390,0.992627,-237.394836,982.000671,0.000000
114.350006,219.360901,-237.350357,-0.000405,0.003908,0.099263,975.765991,49.707890,0.992627,-237.350357,982.000671,0.000000
114.770004,219.316589,-237.350357,-0.000418,0.003908,0.099263,975.568909,49.697849,0.992627,-237.350357,982.000671,0.000000
115.190002,219.258484,-237.394836,-0.000423,0.003908,0.099263,975.310425,49.684685,0.992627,-237.394836,982.000671,0.000000
115.610008,219.184387,-237.439316,-0.000410,0.003908,0.099263,974.980835,49.667892,0.992627,-237.439316,982.000671,0.000000
116.030006,220.445984,-237.483795,-0.000410,0.003924,0.099670,980.592712,49.953773,0.996703,-237.483795,982.000671,0.000000
116.450005,220.428864,-237.439316,-0.000423,0.003924,0.099662,980.516541,49.949894,0.996616,-237.439316,982.000671,0.000000
116.870003,220.399811,-237.439316,-0.000405,0.003924,0.099662,980.387329,49.943310,0.996616,-237.439316,982.000671,0.000000
117.290009,220.392731,-237.483795,-0.000405,0.003924,0.099662,980.355835,49.941708,0.996616,-237.483795,982.000671,0.000000
117.710007,220.395721,-237.528275,-0.000418,0.003924,0.099662,980.369141,49.942387,0.996616,-237.528275,982.000671,0.000000
118.130005,220.335388,-237.617233,-0.000423,0.003924,0.099662,980.100769,49.928711,0.996616,-237.617233,982.000671,0.000000
118.550003,220.323120,-237.572754,-0.000401,0.003924,0.099662,980.046204,49.925934,0.996616,-237.572754,982.000671,0.000000
118.970009,220.243042,-237.528275,-0.000405,0.003924,0.099662,979.690002,49.907787,0.996616,-237.528275,982.000671,0.000000
119.390007,220.200958,-237.572754,-0.000405,0.003924,0.099662,979.502808,49.898251,0.996616,-237.572754,982.000671,0.000000
119.810005,220.147339,-237.617233,-0.000405,0.003924,0.099662,979.264282,49.886101,0.996616,-237.617233,982.000671,0.000000
120.230003,220.112335,-237.572754,-0.000410,0.003924,0.099662,979.108582,49.878166,0.996616,-237.572754,982.000671,0.000000
120.650009,220.070251,-237.661728,-0.000410,0.003924,0.099662,978.921387,49.868629,0.996616,-237.661728,982.000671,0.000000
121.070007,220.033020,-237.617233,-0.000405,0.003924,0.099662,978.755737,49.860195,0.996616,-237.617233,982.000671,0.000000
121.490005,219.965637,-237.661728,-0.000414,0.003924,0.099670,978.455994,49.844929,0.996703,-237.661728,982.000671,0.000000
121.910004,219.936584,-237.661728,-0.000405,0.003924,0.099670,978.326782,49.838341,0.996703,-237.661728,982.000671,0.000000
122.330009,219.871033,-237.750687,-0.000401,0.003924,0.099670,978.035217,49.823490,0.996703,-237.750687,982.000671,0.000000
122.750008,219.836426,-237.750687,-0.000401,0.003924,0.099670,977.881287,49.815643,0.996703,-237.750687,982.000671,0.000000
123.170006,219.781311,-237.706207,-0.000405,0.003924,0.099670,977.636108,49.803158,0.996703,-237.706207,982.000671,0.000000
123.590004,219.767883,-237.706207,-0.000397,0.003924,0.099670,977.576355,49.800114,0.996703,-237.706207,982.000671,0.000000
124.010002,219.710175,-237.795166,-0.000414,0.003924,0.099670,977.319641,49.787037,0.996703,-237.795166,982.000671,0.000000
124.430008,219.665863,-237.795166,-0.000401,0.003924,0.099670,977.122559,49.776993,0.996703,-237.795166,982.000671,0.000000
124.850006,219.617462,-237.795166,-0.000401,0.003924,0.099670,976.907288,49.766029,0.996703,-237.795166,982.000671,0.000000
125.270004,219.570160,-237.839645,-0.000410,0.003924,0.099670,976.696838,49.755310,0.996703,-237.839645,982.000671,0.000000
125.690002,219.528076,-237.839645,-0.000414,0.003924,0.099670,976.509644,49.745773,0.996703,-237.839645,982.000671,0.000000
126.110008,219.484528,-237.884125,-0.000410,0.003924,0.099679,976.315918,49.735909,0.996789,-237.884125,982.000671,0.000000
126.530006,219.449158,-237.928604,-0.000410,0.003924,0.099679,976.158630,49.727890,0.996789,-237.928604,982.000671,0.000000
126.950005,219.405945,-237.973083,-0.000410,0.003924,0.099679,975.966370,49.718098,0.996789,-237.973083,982.000671,0.000000
127.370003,219.357910,-237.928604,-0.000397,0.003924,0.099679,975.752747,49.707211,0.996789,-237.928604,982.000671,0.000000
127.790009,219.316223,-237.973083,-0.000392,0.003924,0.099679,975.567261,49.697765,0.996789,-237.973083,982.000671,0.000000
128.210007,219.271912,-237.928604,-0.000418,0.003924,0.099679,975.370178,49.687725,0.996789,-237.928604,982.000671,0.000000
128.630005,219.238373,-238.017563,-0.000405,0.003924,0.099679,975.221008,49.680126,0.996789,-238.017563,982.000671,0.000000
129.050003,220.298157,-238.017563,-0.000405,0.003940,0.100069,979.935120,49.920277,1.000692,-238.017563,982.000671,0.000000
129.470001,220.384552,-238.062057,-0.000401,0.003934,0.099922,980.319458,49.939854,0.999217,-238.062057,0.100043,0.000000
129.889999,220.233734,-238.017563,-0.000410,0.003921,0.099592,979.648560,49.905678,0.995922,-238.017563,0.099393,0.000000
130.310013,220.125366,-238.017563,-0.000392,0.003899,0.099028,979.166504,49.881123,0.990285,-238.017563,0.098690,0.000000
130.730011,219.714661,-238.106537,-0.000397,0.003879,0.098517,977.339600,49.788055,0.985168,-238.106537,0.097997,0.000000
131.150009,218.416199,-238.151016,-0.000392,0.003851,0.097823,971.563782,49.493816,0.978231,-238.151016,0.097294,0.000000
131.570007,217.568298,-238.062057,-0.000384,0.003818,0.096982,967.792114,49.301682,0.969819,-238.062057,0.096592,0.000000
131.990005,217.029846,-238.151016,-0.000388,0.003795,0.096383,965.396973,49.179665,0.963835,-238.151016,0.095889,0.000000
132.410004,216.744232,-238.151016,-0.000379,0.003769,0.095724,964.126526,49.114944,0.957244,-238.151016,0.095195,0.000000
132.830002,216.436646,-238.151016,-0.000392,0.003743,0.095065,962.758301,49.045246,0.950653,-238.151016,0.094493,0.000000
133.250000,216.107483,-238.284454,-0.000384,0.003716,0.094389,961.294067,48.970657,0.943888,-238.284454,0.093790,0.000000
133.670013,215.738831,-238.195496,-0.000379,0.003689,0.093695,959.654236,48.887119,0.936951,-238.195496,0.093097,0.000000
134.090012,215.159790,-238.284454,-0.000366,0.003662,0.093027,957.078552,48.755905,0.930273,-238.284454,0.092394,0.000000
134.510010,214.127960,-238.239975,-0.000375,0.003636,0.092360,952.488708,48.522087,0.923595,-238.239975,0.091692,0.000000
134.930008,212.754639,-238.239975,-0.000379,0.003609,0.091657,946.379883,48.210888,0.916571,-238.239975,0.090989,0.000000
135.350006,211.219727,-238.328934,-0.000379,0.003586,0.091093,939.552246,47.863075,0.910934,-238.328934,0.090296,0.000000
135.770004,209.002228,-238.373413,-0.000379,0.003555,0.090304,929.688354,47.360580,0.903042,-238.373413,0.089593,0.000000
136.190002,206.873749,-238.328934,-0.000388,0.003532,0.089714,920.220398,46.878262,0.897145,-238.328934,0.088891,0.000000
136.610001,203.965149,-238.328934,-0.000375,0.003502,0.088951,907.282288,46.219166,0.889513,-238.328934,0.088197,0.000000
137.030014,201.131042,-238.417892,-0.000379,0.003476,0.088284,894.675537,45.576942,0.882836,-238.417892,0.087494,0.000000
137.450012,198.551605,-238.373413,-0.000384,0.003453,0.087711,883.201660,44.992435,0.877112,-238.373413,0.086792,0.000000
137.870010,194.976837,-238.373413,-0.000375,0.003420,0.086870,867.300293,44.182381,0.868700,-238.373413,0.086089,0.000000
138.290009,192.088715,-238.417892,-0.000379,0.003391,0.086124,854.453247,43.527927,0.861242,-238.417892,0.085396,0.000000
138.710007,189.619141,-238.506866,-0.000379,0.003371,0.085621,843.468079,42.968311,0.856212,-238.506866,0.084693,0.000000
139.130005,186.862091,-238.506866,-0.000384,0.003342,0.084875,831.204102,42.343555,0.848754,-238.506866,0.083991,0.000000
139.550003,183.625427,-238.506866,-0.000388,0.003313,0.084156,816.806702,41.610119,0.841556,-238.506866,0.083288,0.000000
139.970001,180.409241,-238.506866,-0.000375,0.003286,0.083453,802.500366,40.881317,0.834531,-238.506866,0.082595,0.000000
140.389999,177.201263,-238.462372,-0.000384,0.003258,0.082759,788.230591,40.154381,0.827594,-238.462372,0.081892,0.000000
140.810013,174.086365,-238.506866,-0.000414,0.003234,0.082135,774.374817,39.448532,0.821350,-238.506866,0.081190,0.000000
141.230011,170.880600,-238.595825,-0.000397,0.003207,0.081459,760.114868,38.722095,0.814585,-238.595825,0.080496,0.000000
141.650009,167.154282,-238.595825,-0.000410,0.003173,0.080600,743.539368,37.877701,0.806000,-238.595825,0.079793,0.000000
142.070007,163.630508,-238.595825,-0.000401,0.003147,0.079924,727.864868,37.079201,0.799235,-238.595825,0.079091,0.000000
142.490005,159.740707,-238.595825,-0.000418,0.003113,0.079082,710.562134,36.197762,0.790823,-238.595825,0.078389,0.000000
142.910004,157.032074,-238.595825,-0.000410,0.003092,0.078536,698.513550,35.583977,0.785360,-238.595825,0.077695,0.000000
143.330002,154.018845,-238.640305,-0.000423,0.003066,0.077868,685.110046,34.901169,0.778682,-238.640305,0.076992,0.000000
143.750000,150.324524,-238.684784,-0.000427,0.003034,0.077053,668.676880,34.064026,0.770530,-238.684784,0.076290,0.000000
144.170013,147.018234,-238.684784,-0.000418,0.003006,0.076351,653.969788,33.314808,0.763506,-238.684784,0.075596,0.000000
144.590012,144.284271,-238.684784,-0.000431,0.002984,0.075796,641.808472,32.695282,0.757955,-238.684784,0.074894,0.000000
145.010010,141.077026,-238.773743,-0.000440,0.002957,0.075102,627.541931,31.968512,0.751018,-238.773743,0.074191,0.000000
145.430008,137.521255,-238.729263,-0.000444,0.002924,0.074278,611.725098,31.162764,0.742779,-238.729263,0.073489,0.000000
145.850006,134.461456,-238.818222,-0.000440,0.002900,0.073671,598.114441,30.469402,0.736708,-238.818222,0.072795,0.000000
146.270004,132.332611,-238.773743,-0.000453,0.002881,0.073168,588.644836,29.986998,0.731678,-238.773743,0.072092,0.000000
146.690002,128.492340,-238.773743,-0.000444,0.002851,0.072405,571.562500,29.116779,0.724047,-238.773743,0.071390,0.000000
147.110001,125.324936,-238.818222,-0.000453,0.002822,0.071676,557.473145,28.399036,0.716762,-238.818222,0.070688,0.000000
147.530014,122.281906,-238.907181,-0.000457,0.002795,0.070982,543.937073,27.709475,0.709824,-238.907181,0.069994,0.000000
147.950012,118.278152,-238.862701,-0.000466,0.002760,0.070115,526.127502,26.802212,0.701152,-238.862701,0.069291,0.000000
148.370010,115.651062,-238.818222,-0.000453,0.002740,0.069586,514.441589,26.206905,0.695862,-238.818222,0.068589,0.000000
148.790009,112.236420,-238.862701,-0.000483,0.002710,0.068823,499.252533,25.433138,0.688230,-238.862701,0.067895,0.000000
149.210007,108.723816,-238.862701,-0.000483,0.002677,0.067990,483.627686,24.637169,0.679905,-238.862701,0.067193,0.000000
149.630005,105.245865,-238.907181,-0.000474,0.002648,0.067253,468.156982,23.849052,0.672534,-238.907181,0.066490,0.000000
150.050003,102.373749,-238.951675,-0.000470,0.002623,0.066612,455.381165,23.198223,0.666116,-238.951675,0.065788,0.000000
150.470001,100.785965,-238.951675,-0.000483,0.002611,0.066325,448.318359,22.838427,0.663254,-238.951675,0.065094,0.000000
150.890015,96.966904,-238.951675,-0.000496,0.002576,0.065432,431.330322,21.973015,0.654322,-238.951675,0.064392,0.000000
151.310013,93.030182,-238.951675,-0.000492,0.002539,0.064496,413.818909,21.080940,0.644956,-238.951675,0.063689,0.000000
151.730011,90.521881,-239.040634,-0.000492,0.002518,0.063967,402.661438,20.512552,0.639666,-239.040634,0.062987,0.000000
152.150009,87.164948,-239.040634,-0.000492,0.002489,0.063212,387.729065,19.751860,0.632121,-239.040634,0.062293,0.000000
152.570007,83.832581,-239.040634,-0.000500,0.002461,0.062518,372.905945,18.996733,0.625183,-239.040634,0.061590,0.000000
152.990005,80.744873,-239.085114,-0.000522,0.002432,0.061764,359.171143,18.297049,0.617638,-239.085114,0.060888,0.000000
153.410004,77.090790,-239.085114,-0.000517,0.002402,0.061001,342.916962,17.469023,0.610007,-239.085114,0.060194,0.000000
153.830002,74.227234,-239.129593,-0.000513,0.002374,0.060290,330.179230,16.820133,0.602895,-239.129593,0.059492,0.000000
154.250000,71.429230,-239.174072,-0.000522,0.002350,0.059700,317.733093,16.186094,0.596998,-239.174072,0.058789,0.000000
154.670013,68.562332,-239.129593,-0.000517,0.002325,0.059049,304.980499,15.536447,0.590494,-239.129593,0.058087,0.000000
155.090012,65.340195,-239.085114,-0.000535,0.002296,0.058312,290.647705,14.806300,0.583123,-239.085114,0.057393,0.000000
155.510010,62.359352,-239.174072,-0.000539,0.002269,0.057644,277.388245,14.130832,0.576445,-239.174072,0.056691,0.000000
155.930008,59.121574,-239.218552,-0.000548,0.002238,0.056847,262.985901,13.397141,0.568466,-239.218552,0.055988,0.000000
156.350006,56.900749,-239.263031,-0.000539,0.002222,0.056430,253.107178,12.893894,0.564304,-239.263031,0.055294,0.000000
156.770004,53.378479,-239.218552,-0.000535,0.002188,0.055572,237.439331,12.095737,0.555718,-239.218552,0.054592,0.000000
157.190002,50.286293,-239.218552,-0.000548,0.002157,0.054791,223.684601,11.395038,0.547913,-239.218552,0.053889,0.000000
157.610001,47.475998,-239.263031,-0.000565,0.002134,0.054193,211.183792,10.758215,0.541929,-239.263031,0.053187,0.000000
158.030014,44.044220,-239.307510,-0.000548,0.002104,0.053430,195.918472,9.980563,0.534298,-239.307510,0.052493,0.000000
158.450012,41.181786,-239.352005,-0.000569,0.002077,0.052753,183.185730,9.331926,0.527533,-239.352005,0.051791,0.000000
158.870010,38.352135,-239.307510,-0.000560,0.002052,0.052120,170.598816,8.690718,0.521203,-239.307510,0.051088,0.000000
159.290009,34.998169,-239.307510,-0.000565,0.002021,0.051331,155.679626,7.930698,0.513311,-239.307510,0.050386,0.000000
159.710007,31.930939,-239.352005,-0.000578,0.001994,0.050646,142.035904,7.235654,0.506460,-239.352005,0.049692,0.000000
160.130005,28.961273,-239.396484,-0.000582,0.001964,0.049874,128.826172,6.562718,0.498742,-239.396484,0.048990,0.000000
160.550003,26.239227,-239.396484,-0.000565,0.001940,0.049284,116.717911,5.945894,0.492844,-239.396484,0.048287,0.000000
160.970001,23.157845,-239.396484,-0.000591,0.001911,0.048530,103.011238,5.247643,0.485300,-239.396484,0.047593,0.000000
161.390015,20.210518,-239.396484,-0.000591,0.001884,0.047862,89.900871,4.579769,0.478622,-239.396484,0.046891,0.000000
161.810013,17.370804,-239.396484,-0.000595,0.001856,0.047142,77.269196,3.936280,0.471424,-239.396484,0.046188,0.000000
162.230011,14.657326,-239.529922,-0.000591,0.001835,0.046613,65.199043,3.321398,0.466134,-239.529922,0.045486,0.000000
162.650009,11.872353,-239.529922,-0.000595,0.001809,0.045946,52.810863,2.690314,0.459456,-239.529922,0.044792,0.000000
163.070007,8.458817,-239.485443,-0.000591,0.001774,0.045052,37.626694,1.916795,0.450524,-239.485443,0.044090,0.000000
163.490005,5.519302,-239.529922,-0.000599,0.001743,0.044281,24.551083,1.250692,0.442805,-239.529922,0.043387,0.000000
163.910004,2.301262,-239.574402,-0.000604,0.001715,0.043569,10.236525,0.521473,0.435694,-239.574402,0.042694,0.000000
164.330002,0.463974,-239.574402,-0.000608,0.001691,0.042962,2.063859,0.105138,0.429624,-239.574402,0.041991,0.000000
164.750015,-1.946388,-239.529922,-0.000595,0.001665,0.042303,-8.657968,-0.441058,0.423033,-239.529922,0.041289,0.000000
165.170013,-0.246506,-239.574402,-0.000638,0.001635,0.041540,-1.096512,-0.055859,0.415401,-239.574402,0.040586,0.000000
165.590012,-0.113945,-239.574402,-0.000668,0.001607,0.040820,-0.506853,-0.025820,0.408203,-239.574402,0.039892,0.000000
166.010010,-0.069633,-239.663361,-0.000703,0.001586,0.040274,-0.309745,-0.015779,0.402740,-239.663361,0.039190,0.000000
166.430008,-0.064049,-239.663361,-0.000733,0.001562,0.039676,-0.284903,-0.014514,0.396756,-239.663361,0.038487,0.000000
166.850006,-0.088249,-239.707840,-0.000772,0.001526,0.038756,-0.392552,-0.019998,0.387563,-239.707840,0.037785,0.000000
167.270004,-0.078941,-239.663361,-0.000798,0.001502,0.038149,-0.351149,-0.017888,0.381493,-239.663361,0.037091,0.000000
167.690002,-0.055481,-239.663361,-0.000836,0.001474,0.037447,-0.246792,-0.012572,0.374468,-239.663361,0.036389,0.000000
168.110001,-0.028297,-239.752319,-0.000875,0.001449,0.036814,-0.125873,-0.006412,0.368137,-239.752319,0.035686,0.000000
168.530014,-0.035378,-239.752319,-0.000910,0.001423,0.036146,-0.157367,-0.008017,0.361460,-239.752319,0.034993,0.000000
168.950012,-0.083038,-239.752319,-0.000949,0.001389,0.035270,-0.369373,-0.018817,0.352701,-239.752319,0.034290,0.000000
169.370010,-0.063675,-239.752319,-0.000979,0.001360,0.034533,-0.283240,-0.014429,0.345329,-239.752319,0.033588,0.000000
169.790009,-0.026436,-239.752319,-0.001022,0.001341,0.034056,-0.117593,-0.005990,0.340560,-239.752319,0.032885,0.000000
170.210007,-0.048035,-239.841293,-0.001065,0.001310,0.033284,-0.213669,-0.010885,0.332841,-239.841293,0.032191,0.000000
170.630005,-0.053993,-239.841293,-0.001078,0.001285,0.032634,-0.240174,-0.012235,0.326337,-239.841293,0.031489,0.000000
171.050003,-0.030533,-239.885773,-0.001117,0.001249,0.031714,-0.135817,-0.006919,0.317144,-239.885773,0.030787,0.000000
171.470001,-0.014145,-239.841293,-0.001147,0.001224,0.031081,-0.062920,-0.003205,0.310814,-239.841293,0.030093,0.000000
171.890015,-0.040588,-239.841293,-0.001181,0.001197,0.030396,-0.180546,-0.009197,0.303963,-239.841293,0.029390,0.000000
172.200012,0.015266,-239.885773,-0.001194,0.001189,0.030188,0.067908,0.003459,0.301881,-239.885773,0.030110,0.000000