File: Data/sima compression 500bar/P1-75DMF-25NMP-2_11142024_185954.csv
Time (sec),S:Load (lbs),S:HL1 (DIM),S:LVDT (in),S:Position (in),Ch:Position (mm),Ch:Load (N),Ch:Stress (MPa),Ch:Strain (mm/mm),Ch:HL1 (DIM),Set Point (),Cycles ()
0.110000,-0.071121,-243.577682,-0.012258,-0.009266,-0.235365,-0.316363,-0.016116,-2.353651,-243.577682,-0.235140,0.000000
0.550000,-0.039841,-243.444244,-0.012253,-0.009177,-0.233093,-0.177220,-0.009028,-2.330929,-243.444244,-0.232295,0.000000
0.990000,-0.045059,-243.488724,-0.012042,-0.008907,-0.226242,-0.200433,-0.010211,-2.262418,-243.488724,-0.224958,0.000000
1.430000,-0.043564,-243.533203,-0.011740,-0.008615,-0.218827,-0.193782,-0.009872,-2.188271,-243.533203,-0.217622,0.000000
1.870000,-0.013031,-243.577682,-0.011447,-0.008326,-0.211473,-0.057965,-0.002953,-2.114730,-243.577682,-0.210302,0.000000
2.310000,-0.029045,-243.577682,-0.011137,-0.008041,-0.204240,-0.129199,-0.006582,-2.042403,-243.577682,-0.202966,0.000000
2.750000,-0.055107,-243.577682,-0.010852,-0.007753,-0.196921,-0.245129,-0.012487,-1.969209,-243.577682,-0.195646,0.000000
3.190000,-0.072983,-243.666656,-0.010550,-0.007461,-0.189506,-0.324644,-0.016538,-1.895061,-243.666656,-0.188309,0.000000
3.630000,-0.010056,-243.622162,-0.010240,-0.007171,-0.182152,-0.044729,-0.002279,-1.821521,-243.622162,-0.180973,0.000000
4.070000,0.004845,-243.622162,-0.009955,-0.006887,-0.174928,0.021550,0.001098,-1.749281,-243.622162,-0.173653,0.000000
4.510000,-0.029045,-243.622162,-0.009649,-0.006595,-0.167522,-0.129199,-0.006582,-1.675220,-243.622162,-0.166317,0.000000
4.950000,-0.096069,-243.666656,-0.009360,-0.006312,-0.160315,-0.427338,-0.021770,-1.603153,-243.666656,-0.158980,0.000000
5.390000,-0.042450,-243.711136,-0.009080,-0.006027,-0.153091,-0.188827,-0.009619,-1.530913,-243.711136,-0.151660,0.000000
5.830000,0.025322,-243.711136,-0.008748,-0.005727,-0.145468,0.112638,0.005738,-1.454684,-243.711136,-0.144324,0.000000
6.270000,-0.010056,-243.711136,-0.008468,-0.005441,-0.138192,-0.044729,-0.002279,-1.381924,-243.711136,-0.136987,0.000000
6.710001,-0.042824,-243.844574,-0.008162,-0.005159,-0.131029,-0.190490,-0.009704,-1.310291,-243.844574,-0.129668,0.000000
7.150001,-0.013779,-243.666656,-0.007864,-0.004865,-0.123571,-0.061291,-0.003122,-1.235710,-243.666656,-0.122331,0.000000
7.590000,0.001488,-243.844574,-0.007554,-0.004574,-0.116174,0.006618,0.000337,-1.161736,-243.844574,-0.115011,0.000000
8.030001,-0.019737,-243.889053,-0.007265,-0.004283,-0.108793,-0.087796,-0.004473,-1.087935,-243.889053,-0.107675,0.000000
8.470000,-0.009682,-243.844574,-0.006963,-0.003998,-0.101561,-0.043066,-0.002194,-1.015608,-243.844574,-0.100338,0.000000
8.910001,0.002983,-243.889053,-0.006674,-0.003711,-0.094267,0.013269,0.000676,-0.942674,-243.889053,-0.093019,0.000000
9.350000,-0.054741,-243.800095,-0.006385,-0.003422,-0.086922,-0.243500,-0.012404,-0.869220,-243.800095,-0.085682,0.000000
9.790001,-0.003723,-243.844574,-0.006084,-0.003132,-0.079542,-0.016561,-0.000844,-0.795419,-243.844574,-0.078345,0.000000
10.230000,0.004845,-243.978012,-0.005786,-0.002843,-0.072205,0.021550,0.001098,-0.722052,-243.978012,-0.071026,0.000000
10.670000,0.000374,-243.889053,-0.005493,-0.002555,-0.064894,0.001663,0.000085,-0.648945,-243.889053,-0.063689,0.000000
11.110001,-0.028671,-243.978012,-0.005178,-0.002269,-0.057636,-0.127536,-0.006497,-0.576358,-243.978012,-0.056370,0.000000
11.550000,-0.107986,-243.933533,-0.004889,-0.001980,-0.050290,-0.480348,-0.024470,-0.502904,-243.933533,-0.049033,0.000000
11.990001,0.025322,-243.978012,-0.004605,-0.001691,-0.042954,0.112638,0.005738,-0.429537,-243.978012,-0.041696,0.000000
12.430000,0.040588,-244.066986,-0.004286,-0.001403,-0.035634,0.180546,0.009197,-0.356343,-244.066986,-0.034377,0.000000
12.870001,-0.022339,-243.978012,-0.003992,-0.001109,-0.028176,-0.099368,-0.005062,-0.281762,-243.978012,-0.027040,0.000000
13.310000,-0.047287,-244.111465,-0.003721,-0.000832,-0.021134,-0.210343,-0.010715,-0.211343,-244.111465,-0.019703,0.000000
13.750001,0.007446,-244.022491,-0.003410,-0.000537,-0.013650,0.033123,0.001687,-0.136501,-244.022491,-0.012384,0.000000
14.190001,0.027557,-244.066986,-0.003126,-0.000245,-0.006218,0.122581,0.006245,-0.062180,-244.066986,-0.005047,0.000000
14.630001,0.052879,-244.066986,-0.002807,0.000046,0.001162,0.235219,0.011983,0.011621,-244.066986,0.002272,0.000000
15.070001,0.052132,-244.022491,-0.002746,-0.000000,-0.000000,0.231893,0.011813,-0.000000,-244.022491,0.000251,0.000000
15.510001,0.084900,-244.155945,-0.002772,-0.000000,-0.000000,0.377654,0.019239,-0.000000,-244.155945,0.000650,0.000000
15.950001,0.092346,-244.155945,-0.002764,0.000000,0.000009,0.410776,0.020926,0.000087,-244.155945,0.001388,0.000000
16.390001,0.312050,-244.155945,-0.002725,0.000045,0.001145,1.388067,0.070712,0.011447,-244.155945,0.002125,0.000000
16.830000,0.649422,-244.200424,-0.002708,0.000073,0.001865,2.888772,0.147161,0.018645,-244.200424,0.002853,0.000000
17.270000,1.235161,-244.155945,-0.002695,0.000103,0.002628,5.494270,0.279891,0.026277,-244.155945,0.003590,0.000000
17.710001,1.876015,-244.244904,-0.002647,0.000129,0.003278,8.344931,0.425111,0.032781,-244.244904,0.004319,0.000000
18.150002,2.715340,-244.200424,-0.002634,0.000155,0.003937,12.078434,0.615305,0.039372,-244.200424,0.005056,0.000000
18.590000,3.934860,-244.244904,-0.002634,0.000193,0.004900,17.503132,0.891652,0.048998,-244.244904,0.005784,0.000000
19.030001,4.791687,-244.244904,-0.002596,0.000214,0.005446,21.314487,1.085812,0.054462,-244.244904,0.006522,0.000000
19.470001,5.865242,-244.289383,-0.002578,0.000240,0.006105,26.089899,1.329083,0.061053,-244.289383,0.007259,0.000000
19.910002,7.224403,-244.333862,-0.002561,0.000272,0.006903,32.135750,1.637073,0.069031,-244.333862,0.007987,0.000000
20.350000,8.561218,-244.333862,-0.002535,0.000304,0.007710,38.082199,1.940000,0.077096,-244.333862,0.008724,0.000000
20.790001,9.979584,-244.289383,-0.002531,0.000334,0.008473,44.391407,2.261406,0.084728,-244.289383,0.009453,0.000000
21.230001,11.367043,-244.422821,-0.002501,0.000361,0.009167,50.563129,2.575809,0.091666,-244.422821,0.010190,0.000000
21.670000,12.794350,-244.378342,-0.002488,0.000390,0.009895,56.912109,2.899241,0.098950,-244.378342,0.010918,0.000000
22.110001,13.688789,-244.422821,-0.002462,0.000414,0.010519,60.890778,3.101924,0.105194,-244.422821,0.011656,0.000000
22.550001,15.424789,-244.378342,-0.002436,0.000444,0.011265,68.612892,3.495307,0.112653,-244.378342,0.012393,0.000000
22.990002,16.116280,-244.422821,-0.002432,0.000463,0.011751,71.688789,3.652001,0.117509,-244.422821,0.013121,0.000000
23.430000,18.275299,-244.511795,-0.002402,0.000503,0.012766,81.292587,4.141242,0.127656,-244.511795,0.013858,0.000000
23.870001,19.505615,-244.467300,-0.002389,0.000530,0.013451,86.765312,4.420036,0.134507,-244.467300,0.014587,0.000000
24.310001,20.737427,-244.600754,-0.002371,0.000554,0.014084,92.244682,4.699168,0.140837,-244.600754,0.015324,0.000000
24.750002,22.280907,-244.511795,-0.002345,0.000589,0.014968,99.110420,5.048925,0.149683,-244.511795,0.016052,0.000000
25.190001,24.012070,-244.511795,-0.002324,0.000620,0.015740,106.811020,5.441213,0.157401,-244.511795,0.016789,0.000000
25.630001,25.291908,-244.556274,-0.002298,0.000648,0.016469,112.504028,5.731228,0.164686,-244.556274,0.017518,0.000000
26.070002,26.407913,-244.556274,-0.002307,0.000674,0.017110,117.468262,5.984118,0.171104,-244.556274,0.018255,0.000000
26.510002,28.279083,-244.645233,-0.002255,0.000710,0.018038,125.791641,6.408132,0.180383,-244.645233,0.018992,0.000000
26.950001,29.228264,-244.645233,-0.002242,0.000738,0.018749,130.013809,6.623219,0.187494,-244.645233,0.019721,0.000000
27.390001,29.746231,-244.645233,-0.002242,0.000758,0.019244,132.317841,6.740592,0.192437,-244.645233,0.020458,0.000000
27.830002,31.700439,-244.689713,-0.002207,0.000791,0.020085,141.010605,7.183423,0.200849,-244.689713,0.021186,0.000000
28.270000,33.222702,-244.645233,-0.002182,0.000822,0.020883,147.781952,7.528372,0.208828,-244.645233,0.021923,0.000000
28.710001,34.079529,-244.734192,-0.002169,0.000848,0.021533,151.593323,7.722532,0.215332,-244.734192,0.022652,0.000000
29.150002,34.229225,-244.689713,-0.002143,0.000863,0.021932,152.259201,7.756454,0.219321,-244.689713,0.023389,0.000000
29.590002,37.227196,-244.689713,-0.002121,0.000913,0.023190,165.594833,8.435803,0.231896,-244.689713,0.024126,0.000000
30.030001,37.663239,-244.778671,-0.002100,0.000935,0.023745,167.534454,8.534612,0.237446,-244.778671,0.024855,0.000000
30.470001,39.080116,-244.689713,-0.002078,0.000967,0.024569,173.837036,8.855680,0.245685,-244.689713,0.025592,0.000000
30.910002,40.026314,-244.778671,-0.002057,0.000995,0.025271,178.045929,9.070092,0.252710,-244.778671,0.026320,0.000000
31.350002,40.602005,-244.734192,-0.002026,0.001019,0.025878,180.606735,9.200546,0.258780,-244.734192,0.027057,0.000000
31.790001,42.237465,-244.823151,-0.002018,0.001054,0.026780,187.881622,9.571146,0.267799,-244.823151,0.027786,0.000000
32.230003,43.172119,-244.912109,-0.001996,0.001082,0.027491,192.039185,9.782942,0.274911,-244.912109,0.028523,0.000000
32.670002,44.386803,-244.823151,-0.001953,0.001114,0.028306,197.442352,10.058194,0.283062,-244.823151,0.029260,0.000000
33.110001,45.173248,-244.956604,-0.001953,0.001135,0.028835,200.940643,10.236403,0.288353,-244.956604,0.029989,0.000000
33.550003,46.533157,-244.912109,-0.001910,0.001170,0.029728,206.989822,10.544564,0.297285,-244.912109,0.030726,0.000000
33.990002,47.982430,-244.912109,-0.001884,0.001202,0.030535,213.436508,10.872974,0.305350,-244.912109,0.031454,0.000000
34.430000,48.650093,-245.001083,-0.001884,0.001226,0.031142,216.406418,11.024268,0.311421,-245.001083,0.032191,0.000000
34.870003,49.843544,-244.956604,-0.001845,0.001256,0.031905,221.715164,11.294709,0.319052,-244.956604,0.032920,0.000000
35.310001,50.828468,-245.045563,-0.001837,0.001283,0.032582,226.096313,11.517896,0.325817,-245.045563,0.033657,0.000000
35.750000,51.890846,-245.001083,-0.001811,0.001307,0.033189,230.822006,11.758634,0.331887,-245.001083,0.034385,0.000000
36.190002,53.911713,-244.956604,-0.001802,0.001345,0.034169,239.811279,12.216569,0.341687,-244.956604,0.035123,0.000000
36.630001,54.629272,-245.090042,-0.001781,0.001368,0.034741,243.003143,12.379169,0.347411,-245.090042,0.035860,0.000000
37.070004,55.846191,-245.090042,-0.001746,0.001398,0.035504,248.416260,12.654927,0.355042,-245.090042,0.036588,0.000000
37.510002,57.302536,-245.134521,-0.001729,0.001431,0.036345,254.894409,12.984941,0.363454,-245.134521,0.037325,0.000000
37.950001,58.540680,-245.045563,-0.001707,0.001458,0.037022,260.401947,13.265508,0.370219,-245.045563,0.038054,0.000000
38.390003,59.279839,-245.179001,-0.001699,0.001482,0.037655,263.689880,13.433003,0.376549,-245.179001,0.038791,0.000000
38.830002,61.066475,-245.134521,-0.001651,0.001511,0.038383,271.637238,13.837861,0.383834,-245.134521,0.039519,0.000000
39.270000,62.853119,-245.179001,-0.001651,0.001546,0.039268,279.584625,14.242720,0.392680,-245.179001,0.040257,0.000000
39.710003,63.981781,-245.267960,-0.001621,0.001572,0.039936,284.605164,14.498479,0.399357,-245.267960,0.040994,0.000000
40.150002,65.569580,-245.223480,-0.001608,0.001604,0.040742,291.668060,14.858279,0.407423,-245.223480,0.041722,0.000000
40.590000,66.516891,-245.267960,-0.001587,0.001627,0.041332,295.881897,15.072943,0.413320,-245.267960,0.042459,0.000000
41.030003,67.538681,-245.267960,-0.001574,0.001649,0.041887,300.427063,15.304484,0.418870,-245.267960,0.043188,0.000000
41.470001,69.737549,-245.179001,-0.001561,0.001683,0.042754,310.208099,15.802754,0.427542,-245.179001,0.043925,0.000000
41.910004,71.588608,-245.312439,-0.001526,0.001718,0.043639,318.442017,16.222210,0.436388,-245.312439,0.044653,0.000000
42.350002,72.608170,-245.356934,-0.001522,0.001741,0.044211,322.977264,16.453247,0.442112,-245.356934,0.045391,0.000000
42.790001,74.055954,-245.356934,-0.001492,0.001766,0.044862,329.417328,16.781319,0.448616,-245.356934,0.046128,0.000000
43.230003,76.051498,-245.401413,-0.001479,0.001799,0.045694,338.293945,17.233517,0.456941,-245.401413,0.046856,0.000000
43.670002,77.457947,-245.356934,-0.001466,0.001824,0.046327,344.550140,17.552221,0.463272,-245.356934,0.047593,0.000000
44.110001,79.403595,-245.490372,-0.001462,0.001856,0.047142,353.204834,17.993111,0.471424,-245.490372,0.048322,0.000000
44.550003,80.188171,-245.356934,-0.001431,0.001875,0.047619,356.694794,18.170900,0.476194,-245.356934,0.049059,0.000000
44.990002,83.218170,-245.445892,-0.001427,0.001916,0.048669,370.172913,18.857508,0.486687,-245.445892,0.049787,0.000000
45.430000,85.123596,-245.490372,-0.001406,0.001947,0.049449,378.648682,19.289282,0.494492,-245.490372,0.050525,0.000000
45.870003,86.766876,-245.490372,-0.001388,0.001973,0.050108,385.958344,19.661654,0.501083,-245.490372,0.051262,0.000000
46.310001,88.331223,-245.534851,-0.001380,0.002001,0.050837,392.916901,20.016142,0.508368,-245.534851,0.051990,0.000000
46.750004,90.484650,-245.445892,-0.001362,0.002031,0.051600,402.495819,20.504114,0.515999,-245.445892,0.052727,0.000000
47.190002,92.056427,-245.534851,-0.001345,0.002057,0.052250,409.487427,20.860283,0.522503,-245.534851,0.053456,0.000000
47.630001,93.524704,-245.534851,-0.001328,0.002090,0.053092,416.018646,21.193001,0.530916,-245.534851,0.054193,0.000000
48.070004,96.374832,-245.534851,-0.001311,0.002118,0.053785,428.696655,21.838848,0.537853,-245.534851,0.054921,0.000000
48.510002,97.711273,-245.579330,-0.001319,0.002140,0.054358,434.641449,22.141691,0.543577,-245.579330,0.055659,0.000000
48.950001,100.181229,-245.623810,-0.001285,0.002172,0.055173,445.628357,22.701389,0.551729,-245.623810,0.056387,0.000000
49.390003,101.963028,-245.623810,-0.001289,0.002198,0.055841,453.554199,23.105152,0.558407,-245.623810,0.057124,0.000000
49.830002,104.807205,-245.623810,-0.001259,0.002237,0.056829,466.205719,23.749651,0.568293,-245.623810,0.057861,0.000000
50.270004,106.550293,-245.623810,-0.001250,0.002260,0.057402,473.959381,24.144642,0.574017,-245.623810,0.058590,0.000000
50.710003,106.151474,-245.712769,-0.001237,0.002278,0.057853,472.185333,24.054268,0.578526,-245.712769,0.059327,0.000000
51.150002,111.516617,-245.712769,-0.001220,0.002324,0.059023,496.050690,25.270025,0.590234,-245.712769,0.060055,0.000000
51.590004,113.079086,-245.801743,-0.001224,0.002348,0.059630,503.000885,25.624088,0.596304,-245.801743,0.060793,0.000000
52.030003,115.267899,-245.668289,-0.001173,0.002379,0.060420,512.737244,26.120079,0.604196,-245.668289,0.061521,0.000000
52.470001,117.599319,-245.757248,-0.001181,0.002405,0.061096,523.107910,26.648386,0.610961,-245.757248,0.062258,0.000000
52.910004,119.061996,-245.801743,-0.001168,0.002427,0.061642,529.614197,26.979834,0.616424,-245.801743,0.062995,0.000000
53.350002,122.012314,-245.712769,-0.001160,0.002465,0.062622,542.737854,27.648384,0.626224,-245.712769,0.063724,0.000000
53.790001,124.234253,-245.846222,-0.001151,0.002495,0.063368,552.621582,28.151884,0.633682,-245.846222,0.064461,0.000000
54.230003,125.665283,-245.801743,-0.001134,0.002513,0.063836,558.987122,28.476160,0.638365,-245.801743,0.065189,0.000000
54.670002,128.205978,-245.846222,-0.001125,0.002546,0.064678,570.288696,29.051891,0.646777,-245.846222,0.065926,0.000000
55.110004,131.146225,-245.935181,-0.001117,0.002582,0.065571,583.367554,29.718159,0.655709,-245.935181,0.066655,0.000000
55.550003,133.263535,-245.846222,-0.001091,0.002610,0.066299,592.785828,30.197948,0.662994,-245.846222,0.067392,0.000000
55.990002,135.510803,-245.935181,-0.001087,0.002639,0.067037,602.782166,30.707188,0.670365,-245.935181,0.068129,0.000000
56.430004,137.693649,-245.890701,-0.001065,0.002666,0.067713,612.491943,31.201826,0.677130,-245.890701,0.068858,0.000000
56.870003,139.127289,-245.935181,-0.001061,0.002688,0.068285,618.869080,31.526693,0.682854,-245.935181,0.069595,0.000000
57.310001,141.316101,-245.979660,-0.001039,0.002720,0.069101,628.605408,32.022686,0.691005,-245.979660,0.070323,0.000000
57.750004,144.638397,-245.979660,-0.001048,0.002752,0.069890,643.383728,32.775528,0.698897,-245.979660,0.071060,0.000000
58.190002,146.946365,-246.024139,-0.001035,0.002781,0.070627,653.650085,33.298523,0.706269,-246.024139,0.071789,0.000000
58.630001,149.120285,-245.935181,-0.001022,0.002808,0.071329,663.320129,33.791142,0.713293,-245.935181,0.072526,0.000000
59.070004,152.045639,-246.068619,-0.000996,0.002842,0.072179,676.332764,34.454037,0.721792,-246.068619,0.073263,0.000000
59.510002,153.928345,-246.113098,-0.001005,0.002868,0.072847,684.707458,34.880661,0.728470,-246.113098,0.073992,0.000000
59.950005,156.027039,-245.979660,-0.001000,0.002896,0.073549,694.042908,35.356232,0.735494,-245.979660,0.074729,0.000000
60.390003,158.370377,-246.113098,-0.000961,0.002923,0.074235,704.466614,35.887241,0.742345,-246.113098,0.075457,0.000000
60.830002,160.949066,-246.068619,-0.000970,0.002952,0.074989,715.937195,36.471581,0.749890,-246.068619,0.076194,0.000000
61.270004,163.510239,-246.202057,-0.000970,0.002984,0.075787,727.329895,37.051949,0.757869,-246.202057,0.076923,0.000000
61.710003,165.487167,-246.157578,-0.000953,0.003011,0.076489,736.123657,37.499928,0.764893,-246.157578,0.077660,0.000000
62.150002,167.647675,-246.113098,-0.000944,0.003037,0.077131,745.734131,37.989506,0.771311,-246.113098,0.078389,0.000000
62.590004,168.282944,-246.202057,-0.000927,0.003048,0.077409,748.559937,38.133457,0.774086,-246.202057,0.079126,0.000000
63.030003,172.683258,-246.157578,-0.000923,0.003097,0.078666,768.133484,39.130585,0.786660,-246.157578,0.079863,0.000000
63.470001,174.944305,-246.202057,-0.000905,0.003125,0.079386,778.191162,39.642944,0.793858,-246.202057,0.080591,0.000000
63.910004,177.162537,-246.202057,-0.000918,0.003154,0.080114,788.058350,40.145603,0.801143,-246.202057,0.081328,0.000000
64.350006,179.132751,-246.246552,-0.000892,0.003176,0.080669,796.822266,40.592060,0.806693,-246.246552,0.082057,0.000000
64.790001,181.675690,-246.291031,-0.000880,0.003205,0.081415,808.133850,41.168301,0.814151,-246.291031,0.082794,0.000000
65.230003,184.160522,-246.291031,-0.000871,0.003242,0.082334,819.186890,41.731369,0.823344,-246.291031,0.083523,0.000000
65.670006,186.159790,-246.335510,-0.000867,0.003262,0.082846,828.080078,42.184410,0.828461,-246.335510,0.084260,0.000000
66.110001,188.892258,-246.379990,-0.000862,0.003295,0.083696,840.234741,42.803600,0.836959,-246.379990,0.084997,0.000000
66.550003,191.284393,-246.379990,-0.000845,0.003322,0.084390,850.875488,43.345665,0.843897,-246.379990,0.085725,0.000000
66.990005,194.208984,-246.379990,-0.000841,0.003354,0.085196,863.884705,44.008385,0.851963,-246.379990,0.086462,0.000000
67.430000,196.337860,-246.379990,-0.000832,0.003381,0.085881,873.354431,44.490795,0.858814,-246.379990,0.087191,0.000000
67.870003,199.494812,-246.424469,-0.000815,0.003414,0.086723,887.397217,45.206169,0.867226,-246.424469,0.087928,0.000000
68.310005,201.821777,-246.468948,-0.000811,0.003442,0.087434,897.748108,45.733471,0.874337,-246.468948,0.088656,0.000000
68.750000,203.951019,-246.424469,-0.000806,0.003470,0.088145,907.219421,46.215961,0.881448,-246.424469,0.089394,0.000000
69.190002,207.061798,-246.468948,-0.000780,0.003502,0.088951,921.056885,46.920876,0.889513,-246.468948,0.090131,0.000000
69.630005,208.840271,-246.468948,-0.000785,0.003527,0.089584,928.967896,47.323879,0.895844,-246.468948,0.090859,0.000000
70.070000,211.253967,-246.557907,-0.000780,0.003553,0.090252,939.704590,47.870834,0.902522,-246.557907,0.091596,0.000000
70.510002,213.779785,-246.513428,-0.000776,0.003580,0.090929,950.940002,48.443192,0.909286,-246.513428,0.092325,0.000000
70.950005,216.919983,-246.557907,-0.000767,0.003614,0.091796,964.908264,49.154770,0.917958,-246.557907,0.093062,0.000000
71.390007,219.285309,-246.646881,-0.000763,0.003640,0.092446,975.429749,49.690762,0.924463,-246.646881,0.093790,0.000000
71.830002,220.560669,-246.557907,-0.000755,0.003643,0.092542,981.102844,49.979763,0.925417,-246.557907,0.016272,0.000000
72.270004,219.792114,-246.646881,-0.000742,0.003638,0.092394,977.684143,49.805607,0.923942,-246.646881,982.000671,0.000000
72.710007,219.778320,-246.602386,-0.000733,0.003659,0.092932,977.622803,49.802479,0.929319,-246.602386,982.000671,0.000000
73.150002,219.319550,-246.646881,-0.000746,0.003659,0.092941,975.582092,49.698521,0.929406,-246.646881,982.000671,0.000000
73.590004,218.888367,-246.691360,-0.000737,0.003660,0.092975,973.664062,49.600811,0.929753,-246.691360,982.000671,0.000000
74.030006,220.424011,-246.691360,-0.000720,0.003658,0.092906,980.494995,49.948795,0.929059,-246.691360,982.000671,0.000000
74.470001,219.816681,-246.735840,-0.000720,0.003658,0.092915,977.793457,49.811169,0.929146,-246.735840,982.000671,0.000000
74.910004,219.237640,-246.691360,-0.000716,0.003658,0.092915,975.217712,49.679958,0.929146,-246.691360,982.000671,0.000000
75.350006,218.682800,-246.691360,-0.000707,0.003679,0.093435,972.749695,49.554234,0.934349,-246.691360,982.000671,0.000000
75.790001,219.456604,-246.824799,-0.000703,0.003658,0.092923,976.191711,49.729576,0.929232,-246.824799,982.000671,0.000000
76.230003,218.934906,-246.735840,-0.000703,0.003659,0.092932,973.871094,49.611359,0.929319,-246.735840,982.000671,0.000000
76.670006,220.281403,-246.824799,-0.000694,0.003675,0.093348,979.860596,49.916481,0.933482,-246.824799,982.000671,0.000000
77.110001,219.780945,-246.824799,-0.000711,0.003675,0.093348,977.634460,49.803078,0.933482,-246.824799,982.000671,0.000000
77.550003,219.314362,-246.869278,-0.000690,0.003675,0.093348,975.559021,49.697346,0.933482,-246.869278,982.000671,0.000000
77.990005,220.814270,-246.824799,-0.000677,0.003675,0.093340,982.230957,50.037228,0.933395,-246.824799,982.000671,0.000000
78.430000,220.396088,-246.869278,-0.000690,0.003675,0.093340,980.370789,49.942467,0.933395,-246.869278,982.000671,0.000000
78.870003,219.954071,-246.869278,-0.000681,0.003675,0.093340,978.404602,49.842308,0.933395,-246.869278,982.000671,0.000000
79.310005,219.548950,-246.869278,-0.000681,0.003675,0.093348,976.602478,49.750504,0.933482,-246.869278,982.000671,0.000000
79.750000,219.797302,-246.869278,-0.000698,0.003718,0.094450,977.707214,49.806782,0.944495,-246.869278,982.000671,0.000000
80.190002,219.472229,-246.958237,-0.000677,0.003719,0.094458,976.261230,49.733116,0.944582,-246.958237,982.000671,0.000000
80.630005,219.737366,-246.958237,-0.000694,0.003726,0.094640,977.440613,49.793198,0.946403,-246.958237,982.000671,0.000000
81.070007,219.482300,-247.002716,-0.000681,0.003726,0.094640,976.306030,49.735401,0.946403,-247.002716,982.000671,0.000000
81.510002,219.534790,-247.002716,-0.000673,0.003731,0.094762,976.539490,49.747295,0.947618,-247.002716,982.000671,0.000000
81.950005,219.354553,-247.002716,-0.000690,0.003732,0.094788,975.737793,49.706451,0.947878,-247.002716,982.000671,0.000000
82.390007,219.102081,-247.047195,-0.000677,0.003732,0.094788,974.614746,49.649242,0.947878,-247.047195,982.000671,0.000000
82.830002,220.618774,-247.047195,-0.000673,0.003732,0.094805,981.361328,49.992928,0.948051,-247.047195,982.000671,0.000000
83.270004,220.317505,-247.136169,-0.000677,0.003732,0.094796,980.021179,49.924660,0.947964,-247.136169,982.000671,0.000000
83.710007,220.010681,-247.002716,-0.000655,0.003732,0.094796,978.656372,49.855133,0.947964,-247.002716,982.000671,0.000000
84.150002,219.709076,-247.136169,-0.000673,0.003732,0.094796,977.314758,49.786789,0.947964,-247.136169,982.000671,0.000000
84.590004,219.461060,-247.091690,-0.000664,0.003747,0.095169,976.211548,49.730587,0.951693,-247.091690,982.000671,0.000000
85.030006,219.741089,-247.047195,-0.000686,0.003752,0.095308,977.457153,49.794041,0.953081,-247.047195,982.000671,0.000000
85.470001,219.539276,-247.180649,-0.000664,0.003752,0.095308,976.559448,49.748310,0.953081,-247.180649,982.000671,0.000000
85.910004,219.591034,-247.180649,-0.000655,0.003756,0.095412,976.789673,49.760040,0.954122,-247.180649,982.000671,0.000000
86.350006,219.503510,-247.180649,-0.000664,0.003757,0.095430,976.400391,49.740204,0.954295,-247.180649,982.000671,0.000000
86.790001,219.837158,-247.180649,-0.000642,0.003764,0.095603,977.884521,49.815815,0.956030,-247.180649,982.000671,0.000000
87.230003,219.772369,-247.269608,-0.000655,0.003764,0.095603,977.596313,49.801132,0.956030,-247.269608,982.000671,0.000000
87.670006,219.568298,-247.225128,-0.000651,0.003764,0.095603,976.688599,49.754890,0.956030,-247.225128,982.000671,0.000000
88.110001,219.553406,-247.225128,-0.000638,0.003767,0.095681,976.622314,49.751511,0.956810,-247.225128,982.000671,0.000000
88.550003,219.505005,-247.269608,-0.000660,0.003768,0.095698,976.407043,49.740547,0.956984,-247.269608,982.000671,0.000000
88.990005,219.509460,-247.269608,-0.000642,0.003771,0.095785,976.426819,49.741558,0.957851,-247.269608,982.000671,0.000000
89.430008,219.497559,-247.314087,-0.000655,0.003771,0.095785,976.373901,49.738857,0.957851,-247.314087,982.000671,0.000000
89.870003,219.792847,-247.314087,-0.000642,0.003777,0.095924,977.687439,49.805771,0.959238,-247.314087,982.000671,0.000000
90.310005,219.704956,-247.314087,-0.000642,0.003777,0.095924,977.296448,49.785858,0.959238,-247.314087,982.000671,0.000000
90.750008,219.574280,-247.403046,-0.000647,0.003777,0.095924,976.715149,49.756245,0.959238,-247.403046,982.000671,0.000000
91.190002,219.573517,-247.358566,-0.000638,0.003780,0.096011,976.711792,49.756069,0.960106,-247.358566,982.000671,0.000000
91.630005,219.524750,-247.403046,-0.000642,0.003780,0.096011,976.494873,49.745022,0.960106,-247.403046,982.000671,0.000000
92.070007,219.692322,-247.447525,-0.000625,0.003784,0.096106,977.240234,49.782993,0.961060,-247.447525,982.000671,0.000000
92.510002,219.600342,-247.492004,-0.000634,0.003784,0.096115,976.831116,49.762150,0.961146,-247.492004,982.000671,0.000000
92.950005,219.499420,-247.447525,-0.000642,0.003784,0.096123,976.382202,49.739281,0.961233,-247.447525,982.000671,0.000000
93.390007,219.907166,-247.492004,-0.000634,0.003790,0.096271,978.195923,49.831676,0.962707,-247.492004,982.000671,0.000000
93.830002,219.844604,-247.536499,-0.000642,0.003790,0.096271,977.917664,49.817497,0.962707,-247.536499,982.000671,0.000000
94.270004,219.698273,-247.492004,-0.000638,0.003790,0.096271,977.266724,49.784340,0.962707,-247.492004,982.000671,0.000000
94.710007,219.587677,-247.492004,-0.000642,0.003790,0.096271,976.774780,49.759277,0.962707,-247.492004,982.000671,0.000000
95.150002,219.624908,-247.625458,-0.000629,0.003794,0.096375,976.940369,49.767715,0.963748,-247.625458,982.000671,0.000000
95.590004,219.630859,-247.536499,-0.000612,0.003794,0.096375,976.966858,49.769066,0.963748,-247.536499,982.000671,0.000000
96.030006,219.608154,-247.580978,-0.000638,0.003798,0.096470,976.865845,49.763920,0.964702,-247.580978,982.000671,0.000000
96.470001,219.738098,-247.580978,-0.000617,0.003798,0.096470,977.443848,49.793362,0.964702,-247.580978,982.000671,0.000000
96.910004,219.640167,-247.625458,-0.000625,0.003798,0.096470,977.008240,49.771172,0.964702,-247.625458,982.000671,0.000000
97.350006,219.604431,-247.669937,-0.000629,0.003799,0.096505,976.849304,49.763073,0.965049,-247.669937,982.000671,0.000000
97.790001,219.570526,-247.625458,-0.000608,0.003800,0.096514,976.698486,49.755390,0.965135,-247.625458,982.000671,0.000000
98.230003,219.594360,-247.714417,-0.000629,0.003804,0.096609,976.804504,49.760792,0.966089,-247.714417,982.000671,0.000000
98.670006,219.649475,-247.669937,-0.000625,0.003804,0.096609,977.049683,49.773285,0.966089,-247.669937,982.000671,0.000000
99.110008,219.586182,-247.714417,-0.000625,0.003804,0.096609,976.768127,49.758942,0.966089,-247.714417,982.000671,0.000000
99.550003,219.497559,-247.714417,-0.000625,0.003806,0.096661,976.373901,49.738857,0.966610,-247.714417,982.000671,0.000000
99.990005,219.706085,-247.669937,-0.000608,0.003807,0.096704,977.301453,49.786110,0.967043,-247.669937,982.000671,0.000000
100.430008,219.636078,-247.803375,-0.000625,0.003807,0.096704,976.990051,49.770248,0.967043,-247.803375,982.000671,0.000000
100.870003,219.593262,-247.847855,-0.000621,0.003808,0.096730,976.799622,49.760544,0.967304,-247.847855,982.000671,0.000000
101.310005,219.537415,-247.803375,-0.000638,0.003809,0.096756,976.551208,49.747887,0.967564,-247.803375,982.000671,0.000000
101.750008,219.510956,-247.847855,-0.000621,0.003810,0.096765,976.433472,49.741894,0.967650,-247.847855,982.000671,0.000000
102.190002,219.457703,-247.803375,-0.000608,0.003810,0.096774,976.196594,49.729828,0.967737,-247.803375,982.000671,0.000000
102.630005,219.415253,-247.892334,-0.000629,0.003811,0.096808,976.007812,49.720207,0.968084,-247.892334,982.000671,0.000000
103.070007,219.490479,-247.892334,-0.000608,0.003813,0.096860,976.342407,49.737255,0.968604,-247.892334,982.000671,0.000000
103.510002,219.485260,-247.892334,-0.000629,0.003813,0.096860,976.319214,49.736073,0.968604,-247.892334,982.000671,0.000000
103.950005,219.418976,-247.981308,-0.000612,0.003813,0.096860,976.024353,49.721050,0.968604,-247.981308,982.000671,0.000000
104.390007,219.353821,-247.936829,-0.000608,0.003813,0.096860,975.734497,49.706287,0.968604,-247.936829,982.000671,0.000000
104.830002,219.278961,-247.981308,-0.000617,0.003814,0.096869,975.401550,49.689323,0.968691,-247.981308,982.000671,0.000000
105.270004,219.940308,-248.025787,-0.000608,0.003821,0.097060,978.343323,49.839188,0.970599,-248.025787,982.000671,0.000000
105.710007,219.890045,-248.025787,-0.000621,0.003821,0.097060,978.119751,49.827797,0.970599,-248.025787,982.000671,0.000000
106.150002,219.835297,-248.025787,-0.000612,0.003821,0.097060,977.876221,49.815392,0.970599,-248.025787,982.000671,0.000000
106.590004,219.779816,-248.025787,-0.000617,0.003821,0.097060,977.629456,49.802818,0.970599,-248.025787,982.000671,0.000000
107.030006,219.681885,-248.159225,-0.000612,0.003821,0.097060,977.193848,49.780624,0.970599,-248.159225,982.000671,0.000000
107.470009,219.622681,-248.114746,-0.000617,0.003822,0.097069,976.930481,49.767212,0.970686,-248.114746,982.000671,0.000000
107.910004,219.558990,-248.114746,-0.000612,0.003822,0.097069,976.647156,49.752777,0.970686,-248.114746,982.000671,0.000000
108.350006,219.528473,-248.159225,-0.000617,0.003823,0.097103,976.511414,49.745861,0.971033,-248.159225,982.000671,0.000000
108.790009,219.499786,-248.114746,-0.000599,0.003823,0.097112,976.383789,49.739361,0.971119,-248.114746,982.000671,0.000000
109.230003,219.461060,-248.159225,-0.000608,0.003825,0.097147,976.211548,49.730587,0.971466,-248.159225,982.000671,0.000000
109.670006,219.464417,-248.114746,-0.000608,0.003825,0.097147,976.226501,49.731346,0.971466,-248.114746,982.000671,0.000000
110.110008,219.402222,-248.248184,-0.000617,0.003825,0.097147,975.949829,49.717255,0.971466,-248.248184,982.000671,0.000000
110.550003,219.359406,-248.248184,-0.000604,0.003825,0.097164,975.759338,49.707554,0.971640,-248.248184,982.000671,0.000000
110.990005,219.313599,-248.203705,-0.000621,0.003825,0.097164,975.555603,49.697170,0.971640,-248.203705,982.000671,0.000000
111.430008,219.802887,-248.292664,-0.000625,0.003835,0.097407,977.732056,49.808048,0.974068,-248.292664,982.000671,0.000000
111.870003,220.050171,-248.248184,-0.000599,0.003835,0.097398,978.832031,49.864082,0.973981,-248.248184,982.000671,0.000000
112.310005,220.057220,-248.337143,-0.000599,0.003835,0.097398,978.863403,49.865681,0.973981,-248.337143,982.000671,0.000000
112.750008,220.019257,-248.292664,-0.000599,0.003835,0.097398,978.694519,49.857079,0.973981,-248.292664,982.000671,0.000000
113.190002,219.959290,-248.292664,-0.000608,0.003835,0.097398,978.427795,49.843491,0.973981,-248.292664,982.000671,0.000000
113.630005,219.903809,-248.381638,-0.000608,0.003835,0.097398,978.180969,49.830917,0.973981,-248.381638,982.000671,0.000000
114.070007,219.845337,-248.381638,-0.000604,0.003835,0.097398,977.920898,49.817665,0.973981,-248.381638,982.000671,0.000000
114.510002,219.798798,-248.470596,-0.000612,0.003835,0.097398,977.713867,49.807117,0.973981,-248.470596,982.000671,0.000000
114.950005,219.733643,-248.381638,-0.000608,0.003835,0.097398,977.424072,49.792355,0.973981,-248.381638,982.000671,0.000000
115.390007,219.659180,-248.426117,-0.000591,0.003835,0.097398,977.092834,49.775482,0.973981,-248.426117,982.000671,0.000000
115.830002,219.587311,-248.470596,-0.000595,0.003835,0.097407,976.773132,49.759193,0.974068,-248.470596,982.000671,0.000000
116.270004,219.538513,-248.426117,-0.000599,0.003835,0.097407,976.556091,49.748138,0.974068,-248.426117,982.000671,0.000000
116.710007,219.491974,-248.470596,-0.000608,0.003835,0.097407,976.349060,49.737591,0.974068,-248.470596,982.000671,0.000000
117.150009,219.442444,-248.515076,-0.000604,0.003835,0.097415,976.128723,49.726368,0.974155,-248.515076,982.000671,0.000000
117.590004,219.369843,-248.470596,-0.000608,0.003835,0.097407,975.805786,49.709915,0.974068,-248.470596,982.000671,0.000000
118.030006,219.323669,-248.515076,-0.000599,0.003835,0.097407,975.600403,49.699455,0.974068,-248.515076,982.000671,0.000000
118.470009,220.329437,-248.515076,-0.000604,0.003847,0.097710,980.074280,49.927364,0.977103,-248.515076,982.000671,0.000000
118.910004,220.348419,-248.648514,-0.000612,0.003847,0.097710,980.158691,49.931667,0.977103,-248.648514,982.000671,0.000000
119.350006,220.343597,-248.604034,-0.000595,0.003847,0.097710,980.137268,49.930573,0.977103,-248.604034,982.000671,0.000000
119.790009,220.330566,-248.559555,-0.000591,0.003847,0.097710,980.079285,49.927620,0.977103,-248.559555,982.000671,0.000000
120.230003,220.298157,-248.648514,-0.000586,0.003847,0.097710,979.935120,49.920277,0.977103,-248.648514,982.000671,0.000000
120.670006,220.233368,-248.604034,-0.000599,0.003847,0.097710,979.646973,49.905594,0.977103,-248.604034,982.000671,0.000000
121.110008,220.167084,-248.692993,-0.000586,0.003847,0.097710,979.352112,49.890575,0.977103,-248.692993,982.000671,0.000000
121.550003,220.139526,-248.692993,-0.000586,0.003847,0.097710,979.229492,49.884331,0.977103,-248.692993,982.000671,0.000000
121.990005,220.102295,-248.692993,-0.000582,0.003847,0.097710,979.063904,49.875896,0.977103,-248.692993,982.000671,0.000000
122.430008,220.054626,-248.781952,-0.000599,0.003847,0.097710,978.851868,49.865093,0.977103,-248.781952,982.000671,0.000000
122.870003,219.985748,-248.781952,-0.000604,0.003847,0.097710,978.545471,49.849483,0.977103,-248.781952,982.000671,0.000000
123.310005,219.906799,-248.781952,-0.000599,0.003847,0.097719,978.194275,49.831596,0.977190,-248.781952,982.000671,0.000000
123.750008,219.850555,-248.781952,-0.000599,0.003847,0.097719,977.944092,49.818848,0.977190,-248.781952,982.000671,0.000000
124.190002,219.822998,-248.870926,-0.000599,0.003847,0.097719,977.821533,49.812603,0.977190,-248.870926,982.000671,0.000000
124.630005,219.762695,-248.870926,-0.000591,0.003847,0.097719,977.553284,49.798939,0.977190,-248.870926,982.000671,0.000000
125.070007,219.720978,-248.826447,-0.000599,0.003847,0.097719,977.367737,49.789486,0.977190,-248.826447,982.000671,0.000000
125.510010,219.644653,-248.915405,-0.000591,0.003847,0.097719,977.028198,49.772190,0.977190,-248.915405,982.000671,0.000000
125.950005,219.612244,-248.870926,-0.000591,0.003847,0.097719,976.884033,49.764843,0.977190,-248.870926,982.000671,0.000000
126.390007,219.560486,-248.870926,-0.000599,0.003847,0.097719,976.653809,49.753117,0.977190,-248.870926,982.000671,0.000000
126.830009,219.515442,-248.959885,-0.000582,0.003847,0.097719,976.453430,49.742912,0.977190,-248.959885,982.000671,0.000000
127.270004,219.455841,-248.915405,-0.000604,0.003847,0.097719,976.188354,49.729404,0.977190,-248.915405,982.000671,0.000000
127.710007,219.402985,-249.004364,-0.000591,0.003847,0.097719,975.953247,49.717426,0.977190,-249.004364,982.000671,0.000000
128.150009,219.359406,-248.959885,-0.000595,0.003847,0.097719,975.759338,49.707554,0.977190,-248.959885,982.000671,0.000000
128.590012,219.302795,-248.959885,-0.000591,0.003847,0.097719,975.507568,49.694725,0.977190,-248.959885,982.000671,0.000000
129.029999,219.257751,-249.048843,-0.000582,0.003847,0.097719,975.307190,49.684517,0.977190,-249.048843,982.000671,0.000000
129.470001,219.230194,-249.048843,-0.000591,0.003847,0.097719,975.184631,49.678272,0.977190,-249.048843,982.000671,0.000000
129.910004,219.171356,-249.093323,-0.000586,0.003847,0.097719,974.922913,49.664936,0.977190,-249.093323,982.000671,0.000000
130.350006,219.114746,-249.048843,-0.000586,0.003847,0.097719,974.671082,49.652111,0.977190,-249.048843,982.000671,0.000000
130.790009,219.079742,-249.048843,-0.000604,0.003847,0.097719,974.515381,49.644180,0.977190,-249.048843,982.000671,0.000000
131.230011,219.039917,-249.093323,-0.000586,0.003847,0.097719,974.338196,49.635155,0.977190,-249.093323,982.000671,0.000000
131.670013,218.995972,-249.093323,-0.000586,0.003847,0.097719,974.142761,49.625198,0.977190,-249.093323,982.000671,0.000000
132.110001,218.953156,-249.182281,-0.000591,0.003847,0.097719,973.952271,49.615494,0.977190,-249.182281,5607.367676,0.000000
132.550003,218.874573,-249.182281,-0.000578,0.003836,0.097424,973.602722,49.597687,0.974241,-249.182281,0.097415,0.000000
132.990005,218.669403,-249.182281,-0.000578,0.003817,0.096947,972.690063,49.551197,0.969472,-249.182281,0.096678,0.000000
133.430008,218.480225,-249.226776,-0.000573,0.003796,0.096427,971.848572,49.508327,0.964268,-249.226776,0.095950,0.000000
133.870010,217.505737,-249.182281,-0.000573,0.003769,0.095724,967.513855,49.287502,0.957244,-249.182281,0.095213,0.000000
134.310013,216.632507,-249.315735,-0.000578,0.003733,0.094822,963.629517,49.089626,0.948225,-249.315735,0.094484,0.000000
134.750000,216.161835,-249.226776,-0.000578,0.003710,0.094224,961.535889,48.982975,0.942241,-249.226776,0.093747,0.000000
135.190002,215.905273,-249.226776,-0.000573,0.003684,0.093574,960.394592,48.924835,0.935736,-249.226776,0.093010,0.000000
135.630005,215.579468,-249.271255,-0.000565,0.003653,0.092793,958.945374,48.851006,0.927931,-249.271255,0.092281,0.000000
136.070007,215.353424,-249.271255,-0.000565,0.003629,0.092169,957.939880,48.799782,0.921687,-249.271255,0.091544,0.000000
136.510010,214.756134,-249.360214,-0.000573,0.003599,0.091406,955.283020,48.664433,0.914056,-249.360214,0.090816,0.000000
136.950012,214.292908,-249.404694,-0.000573,0.003573,0.090755,953.222473,48.559467,0.907552,-249.404694,0.090079,0.000000
137.389999,213.187714,-249.315735,-0.000591,0.003546,0.090070,948.306335,48.309025,0.900701,-249.315735,0.089350,0.000000
137.830002,211.680725,-249.449173,-0.000556,0.003519,0.089376,941.602905,47.967541,0.893763,-249.449173,0.088613,0.000000
138.270004,209.953278,-249.404694,-0.000560,0.003490,0.088648,933.918823,47.576096,0.886478,-249.404694,0.087885,0.000000
138.710007,207.439758,-249.449173,-0.000552,0.003460,0.087885,922.738159,47.006519,0.878847,-249.449173,0.087148,0.000000
139.150009,205.320221,-249.404694,-0.000565,0.003439,0.087338,913.309937,46.526230,0.873383,-249.404694,0.086410,0.000000
139.590012,202.549774,-249.449173,-0.000556,0.003406,0.086506,900.986389,45.898434,0.865058,-249.449173,0.085682,0.000000
140.030014,199.107941,-249.493652,-0.000565,0.003376,0.085751,885.676331,45.118504,0.857513,-249.493652,0.084945,0.000000
140.470001,195.579712,-249.538132,-0.000552,0.003346,0.084997,869.981995,44.318996,0.849968,-249.538132,0.084216,0.000000
140.910004,192.732178,-249.538132,-0.000586,0.003320,0.084320,857.315552,43.673737,0.843203,-249.538132,0.083479,0.000000
141.350006,189.674240,-249.538132,-0.000586,0.003294,0.083670,843.713135,42.980801,0.836699,-249.538132,0.082751,0.000000
141.790009,186.476685,-249.493652,-0.000565,0.003264,0.082898,829.489746,42.256218,0.828981,-249.493652,0.082014,0.000000
142.230011,184.020142,-249.582611,-0.000586,0.003240,0.082308,818.562500,41.699558,0.823084,-249.582611,0.081276,0.000000
142.670013,179.778824,-249.582611,-0.000578,0.003203,0.081346,799.696167,40.738464,0.813458,-249.582611,0.080548,0.000000
143.110001,176.449814,-249.627090,-0.000586,0.003175,0.080643,784.888000,39.984100,0.806433,-249.627090,0.079811,0.000000
143.550003,173.942627,-249.671585,-0.000578,0.003147,0.079941,773.735474,39.415962,0.799409,-249.671585,0.079082,0.000000
143.990005,170.292252,-249.582611,-0.000586,0.003124,0.079351,757.497742,38.588776,0.793512,-249.582611,0.078345,0.000000
144.430008,165.821548,-249.716064,-0.000586,0.003084,0.078328,737.611084,37.575703,0.783278,-249.716064,0.077617,0.000000
144.870010,162.414719,-249.671585,-0.000595,0.003059,0.077686,722.456726,36.803699,0.776861,-249.671585,0.076880,0.000000
145.310013,158.753922,-249.760544,-0.000612,0.003026,0.076871,706.172729,35.974152,0.768709,-249.760544,0.076142,0.000000
145.750000,156.037842,-249.716064,-0.000604,0.003004,0.076290,694.091003,35.358681,0.762898,-249.716064,0.075414,0.000000
146.190002,152.502914,-249.716064,-0.000608,0.002973,0.075509,678.366821,34.557655,0.755093,-249.716064,0.074677,0.000000
146.630005,148.767273,-249.760544,-0.000617,0.002944,0.074781,661.749878,33.711143,0.747809,-249.760544,0.073948,0.000000
147.070007,145.557785,-249.760544,-0.000608,0.002913,0.074000,647.473389,32.983868,0.740004,-249.760544,0.073211,0.000000
147.510010,142.529663,-249.760544,-0.000604,0.002892,0.073445,634.003601,32.297684,0.734453,-249.760544,0.072483,0.000000
147.950012,139.272141,-249.805023,-0.000612,0.002864,0.072743,619.513428,31.559519,0.727429,-249.805023,0.071746,0.000000
148.390015,134.860275,-249.760544,-0.000617,0.002826,0.071780,599.888489,30.559774,0.717803,-249.760544,0.071008,0.000000
148.830002,131.937515,-249.893982,-0.000629,0.002802,0.071173,586.887390,29.897467,0.711732,-249.893982,0.070280,0.000000
149.270004,128.907150,-249.893982,-0.000634,0.002776,0.070514,573.407654,29.210777,0.705141,-249.893982,0.069543,0.000000
149.710007,125.429199,-249.893982,-0.000642,0.002745,0.069716,557.936951,28.422663,0.697163,-249.893982,0.068814,0.000000
150.150009,122.064072,-249.938461,-0.000647,0.002714,0.068936,542.968079,27.660114,0.689358,-249.938461,0.068077,0.000000
150.590012,118.771179,-249.938461,-0.000655,0.002686,0.068233,528.320618,26.913935,0.682333,-249.938461,0.067349,0.000000
151.030014,115.264542,-249.893982,-0.000655,0.002658,0.067522,512.722290,26.119318,0.675222,-249.893982,0.066612,0.000000
151.470001,111.839844,-249.938461,-0.000660,0.002627,0.066716,497.488464,25.343271,0.667157,-249.938461,0.065883,0.000000
151.910004,109.344940,-249.982941,-0.000660,0.002601,0.066065,486.390594,24.777918,0.660653,-249.982941,0.065146,0.000000
152.350006,104.648956,-249.982941,-0.000660,0.002565,0.065163,465.501801,23.713793,0.651633,-249.982941,0.064409,0.000000
152.790009,101.893402,-249.938461,-0.000664,0.002540,0.064513,453.244476,23.089375,0.645129,-249.938461,0.063680,0.000000
153.230011,98.690613,-250.116394,-0.000673,0.002514,0.063845,438.997772,22.363613,0.638452,-250.116394,0.062943,0.000000
153.670013,95.603287,-250.071899,-0.000677,0.002486,0.063143,425.264648,21.664015,0.631427,-250.071899,0.062215,0.000000
154.110001,91.783859,-249.982941,-0.000681,0.002452,0.062284,408.274994,20.798519,0.622841,-249.982941,0.061478,0.000000
154.550003,89.283371,-250.116394,-0.000690,0.002431,0.061738,397.152283,20.231901,0.617378,-250.116394,0.060749,0.000000
154.990005,86.142044,-250.116394,-0.000686,0.002406,0.061105,383.178955,19.520065,0.611047,-250.116394,0.060012,0.000000
155.430008,82.326340,-250.205353,-0.000698,0.002370,0.060203,366.205841,18.655415,0.602028,-250.205353,0.059275,0.000000
155.870010,78.025070,-250.116394,-0.000698,0.002332,0.059223,347.072845,17.680735,0.592228,-250.116394,0.058546,0.000000
156.310013,75.278824,-250.116394,-0.000711,0.002309,0.058642,334.856934,17.058426,0.586418,-250.116394,0.057809,0.000000
156.750000,72.592529,-250.205353,-0.000707,0.002281,0.057931,322.907684,16.449701,0.579307,-250.205353,0.057081,0.000000
157.190002,68.950348,-250.160873,-0.000703,0.002251,0.057176,306.706451,15.624372,0.571762,-250.160873,0.056344,0.000000
157.630005,65.810501,-250.249832,-0.000716,0.002223,0.056474,292.739716,14.912873,0.564737,-250.249832,0.055615,0.000000
158.070007,62.484474,-250.294312,-0.000707,0.002195,0.055745,277.944824,14.159184,0.557453,-250.294312,0.054878,0.000000
158.510010,59.775093,-250.249832,-0.000724,0.002170,0.055112,265.892883,13.545230,0.551122,-250.249832,0.054141,0.000000
158.950012,56.455017,-250.338791,-0.000729,0.002140,0.054366,251.124451,12.792890,0.543664,-250.338791,0.053412,0.000000
159.390015,53.356506,-250.249832,-0.000720,0.002110,0.053586,237.341599,12.090756,0.535859,-250.249832,0.052675,0.000000
159.830002,50.120964,-250.338791,-0.000746,0.002081,0.052857,222.949188,11.357573,0.528574,-250.338791,0.051947,0.000000
160.270004,47.022453,-250.383270,-0.000729,0.002054,0.052181,209.166321,10.655439,0.521810,-250.383270,0.051210,0.000000
160.710007,43.599228,-250.338791,-0.000746,0.002021,0.051340,193.939056,9.879725,0.513398,-250.338791,0.050481,0.000000
161.150009,40.521202,-250.383270,-0.000746,0.001995,0.050681,180.247314,9.182236,0.506807,-250.383270,0.049744,0.000000
161.590012,37.805115,-250.427750,-0.000742,0.001971,0.050074,168.165543,8.566761,0.500736,-250.427750,0.049007,0.000000
162.030014,34.152885,-250.383270,-0.000750,0.001938,0.049215,151.919617,7.739155,0.492151,-250.383270,0.048278,0.000000
162.470001,31.478134,-250.516724,-0.000750,0.001914,0.048625,140.021729,7.133047,0.486253,-250.516724,0.047541,0.000000
162.910004,28.270515,-250.427750,-0.000759,0.001885,0.047888,125.753532,6.406190,0.478882,-250.427750,0.046813,0.000000
163.350006,25.281113,-250.472229,-0.000755,0.001855,0.047108,112.456009,5.728782,0.471077,-250.472229,0.046076,0.000000
163.790009,21.692932,-250.516724,-0.000763,0.001821,0.046258,96.494980,4.915689,0.462578,-250.516724,0.045347,0.000000
164.230011,18.724007,-250.516724,-0.000772,0.001795,0.045599,83.288544,4.242920,0.455987,-250.516724,0.044610,0.000000
164.670013,15.732735,-250.516724,-0.000772,0.001769,0.044922,69.982697,3.565089,0.449223,-250.516724,0.043882,0.000000
165.110001,12.796951,-250.516724,-0.000793,0.001741,0.044229,56.923683,2.899831,0.442285,-250.516724,0.043144,0.000000
165.550003,10.268173,-250.561203,-0.000785,0.001718,0.043639,45.675117,2.326801,0.436388,-250.561203,0.042407,0.000000
165.990005,5.985519,-250.605682,-0.000780,0.001675,0.042546,26.624920,1.356338,0.425461,-250.605682,0.041679,0.000000
166.430008,2.874718,-250.650162,-0.000772,0.001643,0.041731,12.787383,0.651420,0.417309,-250.650162,0.040942,0.000000
166.870010,0.951416,-250.650162,-0.000798,0.001626,0.041289,4.232110,0.215594,0.412886,-250.650162,0.040213,0.000000
167.310013,-1.310379,-250.650162,-0.000785,0.001600,0.040630,-5.828857,-0.296936,0.406295,-250.650162,0.039476,0.000000
167.750015,-0.464722,-250.739120,-0.000832,0.001563,0.039693,-2.067185,-0.105307,0.396929,-250.739120,0.038748,0.000000
168.190002,-0.147461,-250.739120,-0.000832,0.001537,0.039051,-0.655939,-0.033415,0.390512,-250.739120,0.038011,0.000000
168.630005,-0.064423,-250.694641,-0.000888,0.001505,0.038219,-0.286566,-0.014598,0.382186,-250.694641,0.037273,0.000000
169.070007,-0.046921,-250.694641,-0.000905,0.001482,0.037638,-0.208714,-0.010632,0.376376,-250.694641,0.036545,0.000000
169.510010,-0.064789,-250.694641,-0.000940,0.001449,0.036805,-0.288195,-0.014681,0.368051,-250.694641,0.035808,0.000000
169.950012,-0.067024,-250.739120,-0.000970,0.001421,0.036103,-0.298139,-0.015188,0.361026,-250.739120,0.035079,0.000000
170.390015,-0.059952,-250.783600,-0.000983,0.001391,0.035339,-0.266679,-0.013585,0.353394,-250.783600,0.034342,0.000000
170.830002,-0.033508,-250.739120,-0.001026,0.001376,0.034949,-0.149052,-0.007593,0.349492,-250.739120,0.033614,0.000000
171.270004,-0.062927,-250.917038,-0.001069,0.001333,0.033865,-0.279914,-0.014260,0.338652,-250.917038,0.032877,0.000000
171.710007,-0.050270,-250.917038,-0.001069,0.001302,0.033076,-0.223612,-0.011391,0.330760,-250.917038,0.032139,0.000000
172.150009,-0.042076,-250.917038,-0.001108,0.001276,0.032400,-0.187164,-0.009535,0.323996,-250.917038,0.031411,0.000000
172.590012,-0.047287,-250.917038,-0.001130,0.001251,0.031766,-0.210343,-0.010715,0.317665,-250.917038,0.030674,0.000000
173.030014,-0.042450,-250.917038,-0.001155,0.001228,0.031185,-0.188827,-0.009619,0.311854,-250.917038,0.029945,0.000000
173.470001,-0.070747,-250.961533,-0.001190,0.001182,0.030032,-0.314700,-0.016032,0.300320,-250.961533,0.029208,0.000000
173.910004,-0.036118,-250.917038,-0.001216,0.001158,0.029416,-0.160659,-0.008184,0.294163,-250.917038,0.028480,0.000000
174.350006,-0.032394,-250.917038,-0.001237,0.001144,0.029069,-0.144098,-0.007341,0.290694,-250.917038,0.027743,0.000000
174.790009,-0.049149,-251.094971,-0.001285,0.001106,0.028098,-0.218624,-0.011137,0.280981,-251.094971,0.027005,0.000000
175.230011,-0.050644,-251.006012,-0.001289,0.001073,0.027266,-0.225275,-0.011476,0.272656,-251.006012,0.026277,0.000000
175.670013,-0.020851,-251.050491,-0.001341,0.001042,0.026468,-0.092750,-0.004725,0.264677,-251.050491,0.025540,0.000000
176.110016,-0.037979,-251.050491,-0.001367,0.001015,0.025791,-0.168940,-0.008606,0.257913,-251.050491,0.024811,0.000000
176.550003,-0.049149,-251.094971,-0.001401,0.000990,0.025141,-0.218624,-0.011137,0.251409,-251.094971,0.024074,0.000000
176.990005,-0.048782,-251.094971,-0.001410,0.000961,0.024412,-0.216995,-0.011054,0.244124,-251.094971,0.023346,0.000000
177.430008,-0.043190,-251.139450,-0.001449,0.000922,0.023415,-0.192119,-0.009787,0.234151,-251.139450,0.022609,0.000000
177.870010,-0.016014,-251.094971,-0.001475,0.000905,0.022981,-0.071234,-0.003629,0.229815,-251.094971,0.021880,0.000000
178.310013,-0.020851,-251.139450,-0.001500,0.000869,0.022080,-0.092750,-0.004725,0.220796,-251.139450,0.021143,0.000000
178.750015,0.012665,-251.183929,-0.001522,0.000851,0.021620,0.056336,0.002870,0.216199,-251.183929,0.021542,0.000000
178.800003,0.009308,-251.183929,-0.001531,0.000851,0.021620,0.041403,0.002109,0.216199,-251.183929,0.021542,0.000000