File: Data/sima compression 500bar/P1-75DMF-25NMP-3_11142024_190406.csv
Time (sec),S:Load (lbs),S:HL1 (DIM),S:LVDT (in),S:Position (in),Ch:Position (mm),Ch:Load (N),Ch:Stress (MPa),Ch:Strain (mm/mm),Ch:HL1 (DIM),Set Point (),Cycles ()
0.110000,-0.040962,-254.119675,-0.012327,-0.009410,-0.239016,-0.182209,-0.009282,-2.390161,-254.119675,-0.238765,0.000000
0.550000,-0.063675,-254.208633,-0.012331,-0.009323,-0.236813,-0.283240,-0.014429,-2.368133,-254.208633,-0.235955,0.000000
0.990000,-0.117668,-254.164154,-0.012124,-0.009049,-0.229850,-0.523414,-0.026664,-2.298495,-254.164154,-0.228635,0.000000
1.430000,0.015640,-254.208633,-0.011809,-0.008761,-0.222539,0.069571,0.003544,-2.225388,-254.208633,-0.221299,0.000000
1.870000,0.011917,-254.208633,-0.011503,-0.008476,-0.215289,0.053010,0.002700,-2.152888,-254.208633,-0.213962,0.000000
2.310000,-0.046921,-254.208633,-0.011197,-0.008184,-0.207865,-0.208714,-0.010632,-2.078653,-254.208633,-0.206643,0.000000
2.750000,-0.054367,-254.253113,-0.010921,-0.007902,-0.200702,-0.241837,-0.012320,-2.007020,-254.253113,-0.199306,0.000000
3.190000,-0.022339,-254.253113,-0.010615,-0.007609,-0.193261,-0.099368,-0.005062,-1.932612,-254.253113,-0.191969,0.000000
3.630000,0.000748,-254.253113,-0.010300,-0.007314,-0.185777,0.003326,0.000169,-1.857771,-254.253113,-0.184650,0.000000
4.070000,-0.016380,-254.342072,-0.010011,-0.007026,-0.178458,-0.072863,-0.003712,-1.784577,-254.342072,-0.177313,0.000000
4.510000,-0.027557,-254.253113,-0.009727,-0.006741,-0.171225,-0.122581,-0.006245,-1.712250,-254.253113,-0.169994,0.000000
4.950000,-0.048782,-254.386566,-0.009429,-0.006456,-0.163992,-0.216995,-0.011054,-1.639924,-254.386566,-0.162657,0.000000
5.390000,-0.043190,-254.386566,-0.009136,-0.006162,-0.156526,-0.192119,-0.009787,-1.565256,-254.386566,-0.155320,0.000000
5.830000,-0.021599,-254.342072,-0.008839,-0.005872,-0.149145,-0.096076,-0.004894,-1.491455,-254.342072,-0.148001,0.000000
6.270000,-0.002602,-254.342072,-0.008537,-0.005588,-0.141930,-0.011573,-0.000590,-1.419302,-254.342072,-0.140664,0.000000
6.710001,-0.017502,-254.431046,-0.008231,-0.005297,-0.134541,-0.077852,-0.003966,-1.345414,-254.431046,-0.133327,0.000000
7.150001,-0.088623,-254.431046,-0.007938,-0.005009,-0.127231,-0.394215,-0.020082,-1.272307,-254.431046,-0.126008,0.000000
7.590000,-0.077080,-254.431046,-0.007644,-0.004724,-0.119998,-0.342868,-0.017467,-1.199980,-254.431046,-0.118671,0.000000
8.030001,0.027931,-254.475525,-0.007343,-0.004433,-0.112601,0.124244,0.006329,-1.126006,-254.475525,-0.111352,0.000000
8.470000,0.028305,-254.475525,-0.007028,-0.004139,-0.105142,0.125907,0.006414,-1.051424,-254.475525,-0.104015,0.000000
8.910001,-0.035378,-254.475525,-0.006748,-0.003854,-0.097901,-0.157367,-0.008017,-0.979011,-254.475525,-0.096678,0.000000
9.350000,-0.023087,-254.520004,-0.006437,-0.003566,-0.090573,-0.102694,-0.005231,-0.905730,-254.520004,-0.089359,0.000000
9.790001,0.008942,-254.475525,-0.006140,-0.003274,-0.083158,0.039774,0.002026,-0.831583,-254.475525,-0.082022,0.000000
10.230000,0.013779,-254.564484,-0.005838,-0.002984,-0.075796,0.061291,0.003122,-0.757955,-254.564484,-0.074685,0.000000
10.670000,-0.006332,-254.564484,-0.005549,-0.002702,-0.068632,-0.028168,-0.001435,-0.686322,-254.564484,-0.067366,0.000000
11.110001,-0.013405,-254.564484,-0.005251,-0.002415,-0.061330,-0.059628,-0.003038,-0.613302,-254.564484,-0.060029,0.000000
11.550000,-0.047287,-254.653442,-0.004967,-0.002127,-0.054028,-0.210343,-0.010715,-0.540282,-254.653442,-0.052693,0.000000
11.990001,-0.008194,-254.608963,-0.004661,-0.001836,-0.046639,-0.036449,-0.001857,-0.466394,-254.608963,-0.045373,0.000000
12.430000,0.003723,-254.653442,-0.004376,-0.001545,-0.039233,0.016561,0.000844,-0.392333,-254.653442,-0.038037,0.000000
12.870001,0.027184,-254.653442,-0.004070,-0.001258,-0.031949,0.120918,0.006160,-0.319486,-254.653442,-0.030717,0.000000
13.310000,-0.012283,-254.653442,-0.003764,-0.000972,-0.024681,-0.054639,-0.002783,-0.246812,-254.653442,-0.023380,0.000000
13.750001,-0.075966,-254.697922,-0.003488,-0.000676,-0.017171,-0.337913,-0.017214,-0.171711,-254.697922,-0.016044,0.000000
14.190001,0.046547,-254.742401,-0.003173,-0.000387,-0.009826,0.207051,0.010548,-0.098257,-254.742401,-0.008724,0.000000
14.630001,0.087509,-254.742401,-0.002893,0.000002,0.000061,0.389260,0.019830,0.000607,-254.742401,0.000156,0.000000
15.070001,0.057716,-254.786880,-0.002893,-0.000004,-0.000095,0.256735,0.013079,-0.000954,-254.786880,0.000156,0.000000
15.510001,0.068520,-254.742401,-0.002893,-0.000004,-0.000095,0.304790,0.015527,-0.000954,-254.742401,0.000789,0.000000
15.950001,0.094582,-254.786880,-0.002893,0.000021,0.000529,0.420720,0.021432,0.005290,-254.786880,0.001518,0.000000
16.390001,0.140015,-254.786880,-0.002846,0.000055,0.001405,0.622816,0.031728,0.014049,-254.786880,0.002255,0.000000
16.830000,0.099800,-254.786880,-0.002811,0.000080,0.002021,0.443933,0.022615,0.020206,-254.786880,0.002983,0.000000
17.270000,0.129211,-254.831375,-0.002785,0.000110,0.002784,0.574761,0.029280,0.027838,-254.831375,0.003720,0.000000
17.710001,0.203316,-254.875854,-0.002746,0.000135,0.003426,0.904394,0.046072,0.034255,-254.875854,0.004449,0.000000
18.150002,0.268852,-254.920334,-0.002755,0.000166,0.004206,1.195915,0.060923,0.042060,-254.920334,0.005186,0.000000
18.590000,0.545525,-254.875854,-0.002708,0.000196,0.004987,2.426615,0.123618,0.049865,-254.875854,0.005923,0.000000
19.030001,1.002052,-254.920334,-0.002695,0.000225,0.005715,4.457351,0.227068,0.057150,-254.920334,0.006652,0.000000
19.470001,1.562851,-254.964813,-0.002665,0.000250,0.006348,6.951908,0.354147,0.063481,-254.964813,0.007389,0.000000
19.910002,2.454308,-254.964813,-0.002639,0.000278,0.007068,10.917305,0.556154,0.070679,-254.964813,0.008117,0.000000
20.350000,3.569191,-255.009293,-0.002617,0.000310,0.007874,15.876554,0.808790,0.078744,-255.009293,0.008854,0.000000
20.790001,4.359367,-254.920334,-0.002587,0.000335,0.008499,19.391434,0.987847,0.084988,-254.920334,0.009583,0.000000
21.230001,5.631020,-255.053772,-0.002583,0.000365,0.009271,25.048027,1.276007,0.092706,-255.053772,0.010320,0.000000
21.670000,7.003212,-255.053772,-0.002561,0.000395,0.010034,31.151842,1.586950,0.100338,-255.053772,0.011057,0.000000
22.110001,8.202248,-255.009293,-0.002531,0.000421,0.010702,36.485420,1.858656,0.107016,-255.009293,0.011786,0.000000
22.550001,9.639977,-255.098251,-0.002527,0.000454,0.011525,42.880756,2.184450,0.115254,-255.098251,0.012523,0.000000
22.990002,10.834923,-255.098251,-0.002496,0.000477,0.012115,48.196144,2.455229,0.121151,-255.098251,0.013251,0.000000
23.430000,11.993004,-255.098251,-0.002492,0.000502,0.012740,53.347546,2.717654,0.127395,-255.098251,0.013988,0.000000
23.870001,13.526428,-255.142731,-0.002479,0.000532,0.013503,60.168556,3.065132,0.135027,-255.142731,0.014717,0.000000
24.310001,15.300789,-255.098251,-0.002449,0.000567,0.014396,68.061310,3.467208,0.143959,-255.098251,0.015454,0.000000
24.750002,15.844078,-255.142731,-0.002440,0.000590,0.014977,70.477982,3.590319,0.149770,-255.142731,0.016182,0.000000
25.190001,17.747643,-255.187210,-0.002414,0.000617,0.015671,78.945457,4.021673,0.156708,-255.187210,0.016920,0.000000
25.630001,18.914291,-255.231705,-0.002402,0.000643,0.016321,84.134972,4.286040,0.163212,-255.231705,0.017657,0.000000
26.070002,20.689384,-255.320663,-0.002380,0.000679,0.017249,92.030975,4.688282,0.172491,-255.320663,0.018385,0.000000
26.510002,22.081688,-255.231705,-0.002354,0.000709,0.018021,98.224251,5.003782,0.180209,-255.231705,0.019122,0.000000
26.950001,23.783432,-255.276184,-0.002345,0.000742,0.018845,105.793991,5.389403,0.188448,-255.276184,0.019851,0.000000
27.390001,25.058060,-255.276184,-0.002320,0.000769,0.019539,111.463814,5.678237,0.195386,-255.276184,0.020588,0.000000
27.830002,26.305885,-255.320663,-0.002289,0.000796,0.020224,117.014420,5.960999,0.202237,-255.320663,0.021316,0.000000
28.270000,28.053429,-255.320663,-0.002272,0.000832,0.021134,124.787880,6.356997,0.211343,-255.320663,0.022054,0.000000
28.710001,28.993668,-255.276184,-0.002251,0.000859,0.021811,128.970276,6.570059,0.218107,-255.276184,0.022791,0.000000
29.150002,29.888847,-255.365143,-0.002233,0.000880,0.022340,132.952240,6.772910,0.223397,-255.365143,0.023519,0.000000
29.590002,31.066292,-255.365143,-0.002207,0.000912,0.023155,138.189774,7.039722,0.231549,-255.365143,0.024256,0.000000
30.030001,32.887192,-255.365143,-0.002203,0.000945,0.024005,146.289536,7.452344,0.240048,-255.365143,0.024985,0.000000
30.470001,33.780144,-255.409622,-0.002182,0.000969,0.024612,150.261581,7.654690,0.246119,-255.409622,0.025722,0.000000
30.910002,34.178955,-255.409622,-0.002147,0.000987,0.025071,152.035583,7.745062,0.250715,-255.409622,0.026450,0.000000
31.350002,36.828011,-255.498581,-0.002134,0.001031,0.026199,163.819168,8.345346,0.261989,-255.498581,0.027188,0.000000
31.790001,37.528816,-255.454102,-0.002108,0.001059,0.026910,166.936508,8.504151,0.269100,-255.454102,0.027925,0.000000
32.230003,38.861160,-255.498581,-0.002074,0.001089,0.027673,172.863068,8.806065,0.276732,-255.498581,0.028653,0.000000
32.670002,40.126114,-255.543060,-0.002070,0.001120,0.028445,178.489868,9.092708,0.284450,-255.543060,0.029390,0.000000
33.110001,40.514496,-255.454102,-0.002039,0.001143,0.029026,180.217484,9.180717,0.290260,-255.454102,0.030119,0.000000
33.550003,42.053139,-255.543060,-0.002026,0.001175,0.029841,187.061707,9.529377,0.298412,-255.543060,0.030856,0.000000
33.990002,42.810173,-255.543060,-0.001992,0.001202,0.030535,190.429153,9.700924,0.305350,-255.543060,0.031584,0.000000
34.430000,44.040123,-255.543060,-0.001988,0.001233,0.031307,195.900253,9.979634,0.313068,-255.543060,0.032322,0.000000
34.870003,44.845558,-255.587540,-0.001966,0.001258,0.031957,199.483002,10.162148,0.319573,-255.587540,0.033059,0.000000
35.310001,46.157433,-255.543060,-0.001949,0.001290,0.032772,205.318512,10.459424,0.327725,-255.543060,0.033787,0.000000
35.750000,47.709480,-255.632019,-0.001914,0.001323,0.033596,212.222366,10.811123,0.335963,-255.632019,0.034524,0.000000
36.190002,48.281441,-255.632019,-0.001897,0.001349,0.034273,214.766571,10.940731,0.342728,-255.632019,0.035253,0.000000
36.630001,49.359833,-255.676514,-0.001876,0.001378,0.034993,219.563507,11.185098,0.349926,-255.676514,0.035990,0.000000
37.070004,50.183891,-255.676514,-0.001863,0.001403,0.035643,223.229095,11.371832,0.356430,-255.676514,0.036718,0.000000
37.510002,51.477142,-255.676514,-0.001841,0.001431,0.036354,228.981766,11.664887,0.363541,-255.676514,0.037455,0.000000
37.950001,53.473801,-255.720993,-0.001811,0.001467,0.037265,237.863342,12.117336,0.372647,-255.720993,0.038184,0.000000
38.390003,54.288925,-255.720993,-0.001807,0.001494,0.037950,241.489197,12.302046,0.379498,-255.720993,0.038921,0.000000
38.830002,55.290237,-255.720993,-0.001798,0.001519,0.038592,245.943253,12.528947,0.385915,-255.720993,0.039658,0.000000
39.270000,56.878403,-255.809952,-0.001755,0.001551,0.039407,253.007767,12.888830,0.394067,-255.809952,0.040387,0.000000
39.710003,57.938553,-255.720993,-0.001729,0.001577,0.040057,257.723541,13.129064,0.400572,-255.720993,0.041124,0.000000
40.150002,59.076889,-255.765472,-0.001733,0.001607,0.040812,262.787140,13.387014,0.408116,-255.765472,0.041852,0.000000
40.590000,60.670647,-255.809952,-0.001712,0.001636,0.041557,269.876526,13.748165,0.415575,-255.809952,0.042589,0.000000
41.030003,62.063316,-255.809952,-0.001707,0.001667,0.042329,276.071411,14.063748,0.423293,-255.809952,0.043318,0.000000
41.470001,63.282471,-255.854431,-0.001673,0.001693,0.042997,281.494476,14.340013,0.429970,-255.854431,0.044055,0.000000
41.910004,64.573105,-255.854431,-0.001660,0.001720,0.043682,287.235504,14.632475,0.436822,-255.854431,0.044792,0.000000
42.350002,65.882751,-255.943390,-0.001647,0.001751,0.044471,293.061127,14.929245,0.444713,-255.943390,0.045521,0.000000
42.790001,67.158493,-255.854431,-0.001613,0.001772,0.045018,298.735901,15.218331,0.450177,-255.854431,0.046258,0.000000
43.230003,69.348785,-255.898911,-0.001613,0.001809,0.045954,308.478790,15.714660,0.459543,-255.898911,0.046986,0.000000
43.670002,70.795456,-255.898911,-0.001582,0.001838,0.046691,314.913910,16.042479,0.466914,-255.898911,0.047723,0.000000
44.110001,72.058914,-255.898911,-0.001569,0.001864,0.047342,320.534058,16.328783,0.473419,-255.898911,0.048452,0.000000
44.550003,73.692505,-256.032349,-0.001565,0.001893,0.048079,327.800629,16.698961,0.480790,-256.032349,0.049189,0.000000
44.990002,75.213287,-255.987869,-0.001539,0.001921,0.048790,334.565399,17.043575,0.487901,-255.987869,0.049926,0.000000
45.430000,76.168045,-255.987869,-0.001531,0.001949,0.049493,338.812378,17.259926,0.494926,-255.987869,0.050655,0.000000
45.870003,77.988205,-256.032349,-0.001505,0.001976,0.050195,346.908875,17.672379,0.501950,-256.032349,0.051392,0.000000
46.310001,79.490356,-255.987869,-0.001496,0.002003,0.050871,353.590759,18.012772,0.508715,-255.987869,0.052120,0.000000
46.750004,82.370651,-256.032349,-0.001483,0.002038,0.051756,366.402954,18.665457,0.517560,-256.032349,0.052857,0.000000
47.190002,84.021011,-256.032349,-0.001462,0.002069,0.052554,373.744110,19.039433,0.525539,-256.032349,0.053586,0.000000
47.630001,85.325058,-256.032349,-0.001453,0.002085,0.052970,379.544800,19.334934,0.529701,-256.032349,0.054323,0.000000
48.070004,87.692978,-256.121307,-0.001449,0.002122,0.053898,390.077850,19.871513,0.538981,-256.121307,0.055060,0.000000
48.510002,89.707886,-256.121307,-0.001418,0.002151,0.054635,399.040619,20.328096,0.546352,-256.121307,0.055789,0.000000
48.950001,91.382065,-256.121307,-0.001423,0.002179,0.055338,406.487732,20.707472,0.553377,-256.121307,0.056526,0.000000
49.390003,93.882172,-256.210266,-0.001397,0.002215,0.056266,417.608765,21.274004,0.562656,-256.210266,0.057254,0.000000
49.830002,95.741806,-256.165802,-0.001406,0.002240,0.056907,425.880829,21.695404,0.569073,-256.165802,0.057991,0.000000
50.270004,97.204483,-256.210266,-0.001384,0.002263,0.057471,432.387146,22.026852,0.574710,-256.210266,0.058720,0.000000
50.710003,99.448395,-256.165802,-0.001367,0.002294,0.058278,442.368561,22.535328,0.582776,-256.165802,0.059457,0.000000
51.150002,101.471863,-256.210266,-0.001362,0.002323,0.059006,451.369385,22.993853,0.590060,-256.210266,0.060185,0.000000
51.590004,104.046082,-256.210266,-0.001354,0.002357,0.059865,462.820099,23.577179,0.598646,-256.210266,0.060923,0.000000
52.030003,105.328156,-256.254761,-0.001341,0.002377,0.060368,468.523041,23.867701,0.603676,-256.254761,0.061660,0.000000
52.470001,107.678574,-256.343719,-0.001319,0.002411,0.061235,478.978210,24.400312,0.612348,-256.343719,0.062388,0.000000
52.910004,110.713409,-256.299225,-0.001319,0.002443,0.062059,492.477844,25.088018,0.620587,-256.299225,0.063125,0.000000
53.350002,112.114655,-256.388214,-0.001306,0.002467,0.062674,498.710876,25.405542,0.626744,-256.388214,0.063854,0.000000
53.790001,114.907074,-256.299225,-0.001289,0.002501,0.063533,511.132202,26.038315,0.635329,-256.299225,0.064591,0.000000
54.230003,117.073166,-256.388214,-0.001298,0.002528,0.064218,520.767456,26.529158,0.642181,-256.388214,0.065319,0.000000
54.670002,119.084717,-256.432678,-0.001263,0.002559,0.064990,529.715271,26.984982,0.649899,-256.432678,0.066057,0.000000
55.110004,121.411667,-256.343719,-0.001263,0.002586,0.065675,540.066040,27.512278,0.656750,-256.343719,0.066794,0.000000
55.550003,123.567703,-256.477173,-0.001250,0.002617,0.066464,549.656616,28.000843,0.664642,-256.477173,0.067522,0.000000
55.990002,125.182693,-256.388214,-0.001237,0.002637,0.066967,556.840454,28.366804,0.669672,-256.388214,0.068259,0.000000
56.430004,127.448944,-256.477173,-0.001246,0.002669,0.067791,566.921204,28.880344,0.677910,-256.477173,0.068988,0.000000
56.870003,130.589157,-256.432678,-0.001229,0.002704,0.068676,580.889587,29.591925,0.686756,-256.432678,0.069725,0.000000
57.310001,132.681152,-256.432678,-0.001224,0.002732,0.069387,590.195251,30.065977,0.693867,-256.432678,0.070453,0.000000
57.750004,134.661423,-256.477173,-0.001199,0.002760,0.070098,599.003906,30.514715,0.700979,-256.477173,0.071191,0.000000
58.190002,136.993973,-256.566132,-0.001186,0.002786,0.070774,609.379639,31.043278,0.707743,-256.566132,0.071928,0.000000
58.630001,138.693481,-256.521637,-0.001190,0.002811,0.071407,616.939392,31.428392,0.714074,-256.521637,0.072656,0.000000
59.070004,141.398758,-256.566132,-0.001181,0.002841,0.072171,628.973083,32.041416,0.721705,-256.566132,0.073393,0.000000
59.510002,144.078354,-256.610596,-0.001177,0.002874,0.073003,640.892517,32.648621,0.730031,-256.610596,0.074122,0.000000
59.950005,146.288757,-256.655090,-0.001186,0.002902,0.073723,650.724915,33.149506,0.737229,-256.655090,0.074859,0.000000
60.390003,148.466766,-256.655090,-0.001143,0.002930,0.074425,660.413147,33.643051,0.744253,-256.655090,0.075587,0.000000
60.830002,151.102051,-256.699554,-0.001147,0.002964,0.075275,672.135498,34.240215,0.752752,-256.699554,0.076325,0.000000
61.270004,153.344467,-256.655090,-0.001134,0.002989,0.075917,682.110229,34.748352,0.759169,-256.655090,0.077062,0.000000
61.710003,155.388794,-256.699554,-0.001130,0.003017,0.076637,691.203857,35.211605,0.766367,-256.699554,0.077790,0.000000
62.150002,157.709793,-256.699554,-0.001117,0.003042,0.077278,701.528198,35.737553,0.772785,-256.699554,0.078527,0.000000
62.590004,160.297409,-256.699554,-0.001104,0.003075,0.078111,713.038513,36.323914,0.781110,-256.699554,0.079256,0.000000
63.030003,162.065063,-256.699554,-0.001117,0.003098,0.078683,720.901428,36.724468,0.786834,-256.699554,0.079993,0.000000
63.470001,164.586029,-256.744049,-0.001104,0.003127,0.079438,732.115234,37.295727,0.794379,-256.744049,0.080721,0.000000
63.910004,167.133057,-256.744049,-0.001095,0.003159,0.080244,743.444946,37.872894,0.802444,-256.744049,0.081459,0.000000
64.350006,169.494644,-256.833008,-0.001087,0.003189,0.080999,753.949829,38.408035,0.809989,-256.833008,0.082187,0.000000
64.790001,172.112793,-256.788544,-0.001074,0.003218,0.081745,765.595947,39.001316,0.817447,-256.788544,0.082924,0.000000
65.230003,174.380905,-256.833008,-0.001074,0.003247,0.082464,775.684998,39.515278,0.824645,-256.833008,0.083661,0.000000
65.670006,176.383148,-256.877502,-0.001061,0.003274,0.083150,784.591431,39.968990,0.831496,-256.877502,0.084390,0.000000
66.110001,178.428223,-256.833008,-0.001052,0.003299,0.083783,793.688354,40.432415,0.837827,-256.833008,0.085127,0.000000
66.550003,181.227356,-256.921967,-0.001048,0.003328,0.084528,806.139526,41.066708,0.845285,-256.921967,0.085855,0.000000
66.990005,183.896515,-256.833008,-0.001030,0.003360,0.085335,818.012573,41.671547,0.853350,-256.833008,0.086592,0.000000
67.430000,185.671234,-256.966461,-0.001030,0.003383,0.085925,825.906921,42.073704,0.859247,-256.966461,0.087321,0.000000
67.870003,188.048843,-256.966461,-0.001022,0.003414,0.086705,836.483032,42.612476,0.867052,-256.966461,0.088058,0.000000
68.310005,190.691574,-256.966461,-0.001022,0.003440,0.087364,848.238464,43.211330,0.873643,-256.966461,0.088795,0.000000
68.750000,193.678009,-257.144379,-0.001018,0.003474,0.088249,861.522827,43.888062,0.882489,-257.144379,0.089524,0.000000
69.190002,195.937927,-257.010925,-0.000987,0.003502,0.088960,871.575439,44.400169,0.889600,-257.010925,0.090261,0.000000
69.630005,198.075714,-257.055420,-0.000992,0.003526,0.089550,881.084778,44.884598,0.895497,-257.055420,0.090989,0.000000
70.070000,200.979095,-257.099884,-0.000974,0.003563,0.090495,893.999695,45.542515,0.904950,-257.099884,0.091726,0.000000
70.510002,202.504700,-257.010925,-0.000979,0.003582,0.090972,900.785889,45.888222,0.909720,-257.010925,0.092455,0.000000
70.950005,206.450745,-257.099884,-0.000987,0.003623,0.092030,918.338806,46.782406,0.920300,-257.099884,0.093192,0.000000
71.390007,208.375549,-257.144379,-0.000970,0.003647,0.092637,926.900757,47.218575,0.926371,-257.144379,0.093929,0.000000
71.830002,210.977295,-257.099884,-0.000966,0.003677,0.093392,938.473877,47.808136,0.933915,-257.099884,0.094658,0.000000
72.270004,212.747192,-257.144379,-0.000961,0.003704,0.094077,946.346802,48.209202,0.940766,-257.144379,0.095395,0.000000
72.710007,216.258301,-257.144379,-0.000940,0.003736,0.094892,961.964966,49.004833,0.948918,-257.144379,0.096123,0.000000
73.150002,218.677216,-257.144379,-0.000949,0.003762,0.095560,972.724854,49.552967,0.955596,-257.144379,0.096860,0.000000
73.590004,220.608337,-257.233337,-0.000944,0.003785,0.096132,981.314880,49.990566,0.961320,-257.233337,0.097589,0.000000
74.030006,220.348053,-257.188873,-0.000936,0.003773,0.095828,980.157104,49.931583,0.958284,-257.188873,980.302856,0.000000
74.470001,219.601807,-257.277832,-0.000923,0.003772,0.095811,976.837646,49.762482,0.958111,-257.277832,982.000671,0.000000
74.910004,219.184753,-257.233337,-0.000923,0.003788,0.096210,974.982483,49.667973,0.962100,-257.233337,982.000671,0.000000
75.350006,219.532196,-257.322296,-0.000940,0.003795,0.096401,976.527954,49.746708,0.964008,-257.322296,982.000671,0.000000
75.790001,219.030609,-257.322296,-0.000931,0.003795,0.096401,974.296814,49.633045,0.964008,-257.322296,982.000671,0.000000
76.230003,218.507782,-257.277832,-0.000923,0.003796,0.096418,971.971130,49.514572,0.964181,-257.277832,982.000671,0.000000
76.670006,220.561798,-257.322296,-0.000884,0.003794,0.096366,981.107849,49.980019,0.963661,-257.322296,982.000671,0.000000
77.110001,220.005096,-257.366791,-0.000897,0.003794,0.096366,978.631531,49.853867,0.963661,-257.366791,982.000671,0.000000
77.550003,219.462555,-257.366791,-0.000905,0.003794,0.096366,976.218201,49.730927,0.963661,-257.366791,982.000671,0.000000
77.990005,218.928558,-257.455750,-0.000901,0.003794,0.096375,973.842834,49.609921,0.963748,-257.455750,982.000671,0.000000
78.430000,219.584320,-257.411255,-0.000897,0.003810,0.096774,976.759827,49.758518,0.967737,-257.411255,982.000671,0.000000
78.870003,219.589905,-257.455750,-0.000884,0.003822,0.097077,976.784668,49.759781,0.970772,-257.455750,982.000671,0.000000
79.310005,219.742950,-257.411255,-0.000884,0.003833,0.097355,977.465454,49.794464,0.973548,-257.411255,982.000671,0.000000
79.750000,219.559753,-257.455750,-0.000897,0.003837,0.097467,976.650574,49.752949,0.974675,-257.455750,982.000671,0.000000
80.190002,219.655457,-257.455750,-0.000880,0.003842,0.097589,977.076294,49.774639,0.975889,-257.455750,982.000671,0.000000
80.630005,219.366486,-257.455750,-0.000888,0.003842,0.097589,975.790833,49.709156,0.975889,-257.455750,982.000671,0.000000
81.070007,220.011444,-257.544708,-0.000884,0.003852,0.097832,978.659790,49.855305,0.978317,-257.544708,982.000671,0.000000
81.510002,219.684113,-257.589172,-0.000884,0.003852,0.097840,977.203735,49.781132,0.978404,-257.589172,982.000671,0.000000
81.950005,219.358673,-257.589172,-0.000892,0.003852,0.097840,975.756104,49.707386,0.978404,-257.589172,982.000671,0.000000
82.390007,218.995239,-257.589172,-0.000871,0.003852,0.097840,974.139465,49.625031,0.978404,-257.589172,982.000671,0.000000
82.830002,218.689880,-257.589172,-0.000875,0.003852,0.097849,972.781189,49.555836,0.978491,-257.589172,982.000671,0.000000
83.270004,219.733276,-257.678162,-0.000867,0.003854,0.097892,977.422424,49.792271,0.978924,-257.678162,982.000671,0.000000
83.710007,219.388458,-257.633667,-0.000867,0.003855,0.097910,975.888611,49.714134,0.979098,-257.633667,982.000671,0.000000
84.150002,220.450073,-257.589172,-0.000862,0.003875,0.098421,980.610901,49.954700,0.984214,-257.589172,982.000671,0.000000
84.590004,220.114197,-257.678162,-0.000854,0.003874,0.098395,979.116821,49.878590,0.983954,-257.678162,982.000671,0.000000
85.030006,219.786133,-257.678162,-0.000854,0.003874,0.098395,977.657532,49.804253,0.983954,-257.678162,982.000671,0.000000
85.470001,219.489746,-257.722626,-0.000854,0.003874,0.098395,976.339172,49.737087,0.983954,-257.722626,982.000671,0.000000
85.910004,219.192200,-257.767120,-0.000845,0.003874,0.098404,975.015625,49.669662,0.984041,-257.767120,982.000671,0.000000
86.350006,218.901764,-257.767120,-0.000867,0.003874,0.098404,973.723694,49.603848,0.984041,-257.767120,982.000671,0.000000
86.790001,220.625458,-257.856079,-0.000845,0.003848,0.097728,981.391052,49.994442,0.977277,-257.856079,982.000671,0.000000
87.230003,220.382324,-257.811584,-0.000836,0.003848,0.097736,980.309509,49.939350,0.977363,-257.811584,982.000671,0.000000
87.670006,220.095581,-257.811584,-0.000845,0.003848,0.097736,979.034058,49.874371,0.977363,-257.811584,982.000671,0.000000
88.110001,219.821136,-257.856079,-0.000849,0.003848,0.097736,977.813232,49.812180,0.977363,-257.856079,982.000671,0.000000
88.550003,219.572784,-257.811584,-0.000845,0.003848,0.097745,976.708496,49.755905,0.977450,-257.811584,982.000671,0.000000
88.990005,219.685242,-257.856079,-0.000849,0.003892,0.098864,977.208740,49.781387,0.988637,-257.856079,982.000671,0.000000
89.430008,219.527344,-257.900543,-0.000854,0.003894,0.098898,976.506409,49.745609,0.988984,-257.900543,982.000671,0.000000
89.870003,219.840881,-257.900543,-0.000841,0.003901,0.099089,977.901062,49.816654,0.990892,-257.900543,982.000671,0.000000
90.310005,219.747803,-257.945038,-0.000836,0.003901,0.099089,977.487061,49.795567,0.990892,-257.945038,982.000671,0.000000
90.750008,219.566803,-257.900543,-0.000849,0.003901,0.099089,976.681946,49.754547,0.990892,-257.900543,982.000671,0.000000
91.190002,219.866943,-258.033997,-0.000849,0.003910,0.099306,978.017029,49.822559,0.993060,-258.033997,982.000671,0.000000
91.630005,219.915344,-257.945038,-0.000845,0.003909,0.099297,978.232300,49.833530,0.992973,-257.945038,982.000671,0.000000
92.070007,219.807373,-257.989502,-0.000849,0.003909,0.099297,977.752014,49.809063,0.992973,-257.989502,982.000671,0.000000
92.510002,219.606659,-258.033997,-0.000836,0.003909,0.099297,976.859192,49.763580,0.992973,-258.033997,982.000671,0.000000
92.950005,219.761200,-257.989502,-0.000823,0.003914,0.099410,977.546631,49.798603,0.994101,-257.989502,982.000671,0.000000
93.390007,219.648743,-258.078491,-0.000854,0.003914,0.099410,977.046387,49.773117,0.994101,-258.078491,982.000671,0.000000
93.830002,219.565338,-258.033997,-0.000849,0.003914,0.099427,976.675415,49.754215,0.994274,-258.033997,982.000671,0.000000
94.270004,220.011810,-258.122955,-0.000841,0.003923,0.099653,978.661438,49.855389,0.996529,-258.122955,982.000671,0.000000
94.710007,219.928772,-258.122955,-0.000832,0.003921,0.099601,978.292053,49.836571,0.996009,-258.122955,982.000671,0.000000
95.150002,219.809967,-258.167450,-0.000832,0.003921,0.099601,977.763550,49.809650,0.996009,-258.167450,982.000671,0.000000
95.590004,219.669220,-258.167450,-0.000849,0.003921,0.099601,977.137512,49.777760,0.996009,-258.167450,982.000671,0.000000
96.030006,219.522125,-258.211914,-0.000841,0.003921,0.099601,976.483154,49.744423,0.996009,-258.211914,982.000671,0.000000
96.470001,219.383240,-258.211914,-0.000841,0.003921,0.099601,975.865417,49.712952,0.996009,-258.211914,982.000671,0.000000
96.910004,219.251038,-258.256409,-0.000832,0.003922,0.099610,975.277344,49.682995,0.996096,-258.256409,982.000671,0.000000
97.350006,219.109558,-258.122955,-0.000841,0.003922,0.099610,974.648010,49.650936,0.996096,-258.122955,982.000671,0.000000
97.790001,218.967285,-258.256409,-0.000832,0.003922,0.099610,974.015137,49.618698,0.996096,-258.256409,982.000671,0.000000
98.230003,218.832886,-258.256409,-0.000832,0.003934,0.099922,973.417297,49.588242,0.999217,-258.256409,982.000671,0.000000
98.670006,220.718933,-258.211914,-0.000823,0.003900,0.099063,981.806824,50.015625,0.990632,-258.211914,982.000671,0.000000
99.110008,220.557709,-258.345367,-0.000819,0.003900,0.099063,981.089661,49.979092,0.990632,-258.345367,982.000671,0.000000
99.550003,220.388641,-258.345367,-0.000806,0.003900,0.099063,980.337646,49.940781,0.990632,-258.345367,982.000671,0.000000
99.990005,220.349182,-258.345367,-0.000815,0.003900,0.099063,980.162109,49.931839,0.990632,-258.345367,982.000671,0.000000
100.430008,220.129089,-258.345367,-0.000802,0.003900,0.099063,979.183105,49.881962,0.990632,-258.345367,982.000671,0.000000
100.870003,220.017761,-258.345367,-0.000823,0.003900,0.099063,978.687866,49.856735,0.990632,-258.345367,982.000671,0.000000
101.310005,219.852417,-258.434326,-0.000828,0.003900,0.099072,977.952393,49.819267,0.990719,-258.434326,982.000671,0.000000
101.750008,219.707947,-258.345367,-0.000815,0.003900,0.099072,977.309753,49.786530,0.990719,-258.345367,982.000671,0.000000
102.190002,219.582092,-258.434326,-0.000832,0.003900,0.099072,976.749939,49.758011,0.990719,-258.434326,982.000671,0.000000
102.630005,219.680023,-258.567780,-0.000815,0.003933,0.099904,977.185547,49.780205,0.999044,-258.567780,982.000671,0.000000
103.070007,219.570923,-258.434326,-0.000823,0.003934,0.099930,976.700256,49.755482,0.999304,-258.434326,982.000671,0.000000
103.510002,219.486389,-258.478821,-0.000819,0.003937,0.099991,976.324219,49.736324,0.999911,-258.478821,982.000671,0.000000
103.950005,219.404846,-258.478821,-0.000815,0.003937,0.099991,975.961487,49.717850,0.999911,-258.478821,982.000671,0.000000
104.390007,219.744080,-258.523285,-0.000828,0.003944,0.100182,977.470459,49.794720,1.001819,-258.523285,982.000671,0.000000
104.830002,219.703491,-258.523285,-0.000811,0.003944,0.100182,977.289917,49.785522,1.001819,-258.523285,982.000671,0.000000
105.270004,219.599213,-258.523285,-0.000815,0.003945,0.100191,976.826111,49.761894,1.001906,-258.523285,982.000671,0.000000
105.710007,219.537018,-258.612244,-0.000823,0.003945,0.100191,976.549438,49.747799,1.001906,-258.612244,982.000671,0.000000
106.150002,219.540009,-258.656738,-0.000811,0.003946,0.100234,976.562744,49.748474,1.002339,-258.656738,982.000671,0.000000
106.590004,219.497192,-258.612244,-0.000849,0.003947,0.100251,976.372253,49.738773,1.002513,-258.612244,982.000671,0.000000
107.030006,219.562714,-258.612244,-0.000815,0.003951,0.100347,976.663757,49.753624,1.003467,-258.612244,982.000671,0.000000
107.470009,219.612244,-258.612244,-0.000806,0.003951,0.100347,976.884033,49.764843,1.003467,-258.612244,982.000671,0.000000
107.910004,219.570160,-258.656738,-0.000828,0.003951,0.100347,976.696838,49.755310,1.003467,-258.656738,982.000671,0.000000
108.350006,219.528839,-258.745697,-0.000811,0.003951,0.100355,976.513062,49.745945,1.003554,-258.745697,982.000671,0.000000
108.790009,219.593628,-258.656738,-0.000811,0.003953,0.100416,976.801270,49.760628,1.004161,-258.656738,982.000671,0.000000
109.230003,219.547455,-258.790161,-0.000819,0.003953,0.100416,976.595825,49.750164,1.004161,-258.790161,982.000671,0.000000
109.670006,219.520264,-258.701202,-0.000815,0.003954,0.100442,976.474915,49.743999,1.004421,-258.701202,982.000671,0.000000
110.110008,219.679260,-258.745697,-0.000819,0.003957,0.100511,977.182129,49.780029,1.005115,-258.745697,982.000671,0.000000
110.550003,219.662903,-258.745697,-0.000806,0.003957,0.100511,977.109375,49.776325,1.005115,-258.745697,982.000671,0.000000
110.990005,219.607025,-258.745697,-0.000819,0.003957,0.100511,976.860840,49.763660,1.005115,-258.745697,982.000671,0.000000
111.430008,219.554535,-258.834656,-0.000811,0.003957,0.100511,976.627319,49.751770,1.005115,-258.834656,982.000671,0.000000
111.870003,219.535553,-258.834656,-0.000815,0.003959,0.100555,976.542908,49.747467,1.005548,-258.834656,982.000671,0.000000
112.310005,220.012177,-258.834656,-0.000815,0.003964,0.100694,978.663025,49.855469,1.006936,-258.834656,982.000671,0.000000
112.750008,220.001740,-258.923615,-0.000811,0.003964,0.100694,978.616638,49.853107,1.006936,-258.923615,982.000671,0.000000
113.190002,219.946625,-258.879150,-0.000811,0.003964,0.100694,978.371460,49.840618,1.006936,-258.879150,982.000671,0.000000
113.630005,219.879242,-258.968109,-0.000819,0.003964,0.100694,978.071716,49.825348,1.006936,-258.968109,982.000671,0.000000
114.070007,219.838654,-258.923615,-0.000811,0.003964,0.100694,977.891174,49.816151,1.006936,-258.923615,982.000671,0.000000
114.510002,219.783905,-258.968109,-0.000811,0.003964,0.100694,977.647644,49.803745,1.006936,-258.968109,982.000671,0.000000
114.950005,219.708313,-258.968109,-0.000811,0.003964,0.100694,977.311401,49.786617,1.006936,-258.968109,982.000671,0.000000
115.390007,219.645020,-258.968109,-0.000806,0.003964,0.100694,977.029846,49.772274,1.006936,-258.968109,982.000671,0.000000
115.830002,219.570923,-259.057068,-0.000806,0.003964,0.100694,976.700256,49.755482,1.006936,-259.057068,982.000671,0.000000
116.270004,219.613739,-258.968109,-0.000806,0.003967,0.100754,976.890686,49.765186,1.007543,-258.968109,982.000671,0.000000
116.710007,219.635345,-259.057068,-0.000806,0.003968,0.100780,976.986816,49.770081,1.007803,-259.057068,982.000671,0.000000
117.150009,219.621185,-259.101532,-0.000815,0.003968,0.100780,976.923828,49.766869,1.007803,-259.101532,982.000671,0.000000
117.590004,219.601440,-259.101532,-0.000802,0.003968,0.100789,976.835999,49.762398,1.007890,-259.101532,982.000671,0.000000
118.030006,219.682617,-259.146027,-0.000798,0.003970,0.100841,977.197083,49.780792,1.008410,-259.146027,982.000671,0.000000
118.470009,219.658783,-259.101532,-0.000785,0.003970,0.100841,977.091064,49.775391,1.008410,-259.101532,982.000671,0.000000
118.910004,219.626038,-259.057068,-0.000819,0.003970,0.100841,976.945435,49.767971,1.008410,-259.057068,982.000671,0.000000
119.350006,219.595856,-259.190491,-0.000815,0.003971,0.100858,976.811157,49.761131,1.008584,-259.190491,982.000671,0.000000
119.790009,219.573517,-259.190491,-0.000789,0.003971,0.100858,976.711792,49.756069,1.008584,-259.190491,982.000671,0.000000
120.230003,219.553772,-259.234985,-0.000798,0.003971,0.100876,976.623962,49.751595,1.008757,-259.234985,982.000671,0.000000
120.670006,219.524750,-259.234985,-0.000802,0.003971,0.100876,976.494873,49.745022,1.008757,-259.234985,982.000671,0.000000
121.110008,219.529205,-259.234985,-0.000811,0.003975,0.100971,976.514648,49.746029,1.009711,-259.234985,982.000671,0.000000
121.550003,219.719849,-259.279449,-0.000811,0.003975,0.100971,977.362671,49.789230,1.009711,-259.279449,982.000671,0.000000
121.990005,219.697144,-259.234985,-0.000811,0.003975,0.100971,977.261719,49.784084,1.009711,-259.234985,982.000671,0.000000
122.430008,219.673676,-259.368439,-0.000798,0.003975,0.100971,977.157288,49.778767,1.009711,-259.368439,982.000671,0.000000
122.870003,219.630127,-259.323944,-0.000798,0.003975,0.100971,976.963623,49.768898,1.009711,-259.323944,982.000671,0.000000
123.310005,219.609253,-259.279449,-0.000793,0.003975,0.100971,976.870728,49.764168,1.009711,-259.279449,982.000671,0.000000
123.750008,219.559753,-259.323944,-0.000806,0.003976,0.100988,976.650574,49.752949,1.009884,-259.323944,982.000671,0.000000
124.190002,219.557892,-259.279449,-0.000789,0.003976,0.100988,976.642273,49.752529,1.009884,-259.279449,982.000671,0.000000
124.630005,219.493835,-259.368439,-0.000798,0.003976,0.100988,976.357361,49.738014,1.009884,-259.368439,982.000671,0.000000
125.070007,219.463287,-259.412903,-0.000798,0.003976,0.100988,976.221436,49.731091,1.009884,-259.412903,982.000671,0.000000
125.510010,219.399261,-259.368439,-0.000793,0.003976,0.100988,975.936646,49.716583,1.009884,-259.368439,982.000671,0.000000
125.950005,220.042694,-259.501862,-0.000785,0.003983,0.101171,978.798767,49.862385,1.011706,-259.501862,982.000671,0.000000
126.390007,220.022980,-259.368439,-0.000802,0.003983,0.101171,978.711121,49.857918,1.011706,-259.368439,982.000671,0.000000
126.830009,219.983124,-259.457397,-0.000793,0.003983,0.101171,978.533813,49.848888,1.011706,-259.457397,982.000671,0.000000
127.270004,219.953339,-259.501862,-0.000789,0.003983,0.101171,978.401306,49.842136,1.011706,-259.501862,982.000671,0.000000
127.710007,219.912384,-259.546356,-0.000798,0.003983,0.101171,978.219116,49.832859,1.011706,-259.546356,982.000671,0.000000
128.150009,219.873291,-259.590820,-0.000785,0.003983,0.101171,978.045227,49.824001,1.011706,-259.590820,982.000671,0.000000
128.590012,219.836426,-259.546356,-0.000776,0.003983,0.101171,977.881287,49.815643,1.011706,-259.546356,982.000671,0.000000
129.029999,219.795074,-259.590820,-0.000802,0.003983,0.101171,977.697327,49.806278,1.011706,-259.590820,982.000671,0.000000
129.470001,219.766418,-259.546356,-0.000789,0.003983,0.101171,977.569824,49.799782,1.011706,-259.546356,982.000671,0.000000
129.910004,219.716888,-259.635315,-0.000798,0.003983,0.101179,977.349548,49.788559,1.011792,-259.635315,982.000671,0.000000
130.350006,219.670349,-259.635315,-0.000793,0.003983,0.101179,977.142517,49.778011,1.011792,-259.635315,982.000671,0.000000
130.790009,219.608521,-259.635315,-0.000789,0.003983,0.101179,976.867493,49.764004,1.011792,-259.635315,982.000671,0.000000
131.230011,219.570526,-259.679779,-0.000793,0.003983,0.101179,976.698486,49.755390,1.011792,-259.679779,982.000671,0.000000
131.670013,219.529205,-259.679779,-0.000780,0.003983,0.101179,976.514648,49.746029,1.011792,-259.679779,982.000671,0.000000
132.110001,219.501282,-259.679779,-0.000793,0.003983,0.101179,976.390442,49.739704,1.011792,-259.679779,982.000671,0.000000
132.550003,219.441711,-259.724274,-0.000798,0.003983,0.101179,976.125488,49.726204,1.011792,-259.724274,982.000671,0.000000
132.990005,219.389954,-259.724274,-0.000789,0.003983,0.101179,975.895264,49.714478,1.011792,-259.724274,982.000671,0.000000
133.430008,219.337433,-259.813232,-0.000793,0.003983,0.101179,975.661621,49.702572,1.011792,-259.813232,982.000671,0.000000
133.870010,219.971954,-259.768768,-0.000789,0.003993,0.101413,978.484131,49.846355,1.014134,-259.768768,982.000671,0.000000
134.310013,219.978668,-259.768768,-0.000789,0.003991,0.101370,978.513977,49.847878,1.013700,-259.768768,5607.367676,0.000000
134.750000,219.885193,-259.857727,-0.000785,0.003978,0.101032,978.098206,49.826698,1.010318,-259.857727,0.100858,0.000000
135.190002,219.670715,-259.813232,-0.000772,0.003954,0.100425,977.144165,49.778095,1.004247,-259.813232,0.100121,0.000000
135.630005,219.397003,-259.857727,-0.000789,0.003935,0.099948,975.926636,49.716072,0.999478,-259.857727,0.099393,0.000000
136.070007,218.151062,-259.902191,-0.000767,0.003905,0.099185,970.384399,49.433735,0.991846,-259.902191,0.098656,0.000000
136.510010,217.272644,-259.857727,-0.000763,0.003876,0.098456,966.476990,49.234684,0.984561,-259.857727,0.097927,0.000000
136.950012,216.969879,-259.946686,-0.000772,0.003843,0.097615,965.130249,49.166077,0.976149,-259.946686,0.097190,0.000000
137.389999,216.713715,-259.902191,-0.000767,0.003814,0.096886,963.990723,49.108028,0.968865,-259.902191,0.096453,0.000000
137.830002,216.378571,-259.946686,-0.000772,0.003793,0.096331,962.499939,49.032085,0.963314,-259.946686,0.095724,0.000000
138.270004,216.120880,-259.991150,-0.000780,0.003759,0.095473,961.353699,48.973694,0.954729,-259.991150,0.094987,0.000000
138.710007,215.392883,-259.946686,-0.000776,0.003737,0.094918,958.115417,48.808723,0.949179,-259.946686,0.094259,0.000000
139.150009,214.846985,-260.035645,-0.000780,0.003709,0.094215,955.687134,48.685024,0.942154,-260.035645,0.093522,0.000000
139.590012,213.389160,-259.991150,-0.000772,0.003677,0.093400,949.202393,48.354675,0.934002,-259.991150,0.092793,0.000000
140.030014,211.843811,-260.035645,-0.000780,0.003653,0.092784,942.328308,48.004494,0.927845,-260.035645,0.092056,0.000000
140.470001,209.937256,-260.035645,-0.000750,0.003627,0.092117,933.847534,47.572464,0.921167,-260.035645,0.091319,0.000000
140.910004,207.643066,-260.035645,-0.000767,0.003596,0.091328,923.642517,47.052593,0.913275,-260.035645,0.090590,0.000000
141.350006,205.322449,-260.124603,-0.000776,0.003570,0.090668,913.319885,46.526730,0.906684,-260.124603,0.089853,0.000000
141.790009,202.006104,-260.124603,-0.000767,0.003538,0.089853,898.568054,45.775238,0.898533,-260.124603,0.089125,0.000000
142.230011,199.043152,-260.080109,-0.000776,0.003512,0.089194,885.388184,45.103821,0.891942,-260.080109,0.088388,0.000000
142.670013,196.175507,-260.124603,-0.000776,0.003485,0.088526,872.632263,44.454006,0.885264,-260.124603,0.087659,0.000000
143.110001,192.464813,-260.124603,-0.000776,0.003455,0.087755,856.126221,43.613152,0.877546,-260.124603,0.086922,0.000000
143.550003,189.491409,-260.213562,-0.000776,0.003427,0.087035,842.899902,42.939365,0.870348,-260.213562,0.086185,0.000000
143.990005,186.327728,-260.169098,-0.000772,0.003398,0.086298,828.827148,42.222466,0.862976,-260.169098,0.085456,0.000000
144.430008,183.027771,-260.169098,-0.000780,0.003368,0.085552,814.148193,41.474686,0.855518,-260.169098,0.084719,0.000000
144.870010,179.825363,-260.169098,-0.000772,0.003338,0.084789,799.903137,40.749008,0.847887,-260.169098,0.083991,0.000000
145.310013,177.140182,-260.213562,-0.000780,0.003317,0.084242,787.958862,40.140537,0.842423,-260.213562,0.083254,0.000000
145.750000,173.077972,-260.302521,-0.000785,0.003281,0.083332,769.889282,39.220028,0.833317,-260.302521,0.082525,0.000000
146.190002,170.183151,-260.258057,-0.000785,0.003259,0.082768,757.012451,38.564053,0.827680,-260.258057,0.081788,0.000000
146.630005,166.516769,-260.347015,-0.000798,0.003225,0.081918,740.703613,37.733238,0.819181,-260.347015,0.081051,0.000000
147.070007,162.505951,-260.347015,-0.000802,0.003194,0.081138,722.862549,36.824375,0.811376,-260.347015,0.080322,0.000000
147.510010,158.673126,-260.302521,-0.000811,0.003161,0.080288,705.813293,35.955845,0.802878,-260.302521,0.079585,0.000000
147.950012,155.390656,-260.347015,-0.000815,0.003135,0.079620,691.212158,35.212029,0.796200,-260.347015,0.078857,0.000000
148.390015,152.561005,-260.347015,-0.000819,0.003109,0.078961,678.625244,34.570816,0.789609,-260.347015,0.078120,0.000000
148.830002,148.571396,-260.435974,-0.000828,0.003078,0.078172,660.878601,33.666759,0.781717,-260.435974,0.077391,0.000000
149.270004,145.465073,-260.391479,-0.000823,0.003049,0.077452,647.060974,32.962856,0.774519,-260.391479,0.076654,0.000000
149.710007,142.279800,-260.480438,-0.000836,0.003024,0.076819,632.892151,32.241062,0.768188,-260.480438,0.075926,0.000000
150.150009,139.359283,-260.391479,-0.000828,0.003001,0.076220,619.901062,31.579266,0.762205,-260.391479,0.075188,0.000000
150.590012,135.237854,-260.435974,-0.000845,0.002963,0.075258,601.567993,30.645336,0.752578,-260.435974,0.074451,0.000000
151.030014,132.150146,-260.480438,-0.000845,0.002938,0.074633,587.833191,29.945650,0.746334,-260.480438,0.073723,0.000000
151.470001,128.405945,-260.435974,-0.000845,0.002906,0.073810,571.178162,29.097204,0.738096,-260.435974,0.072986,0.000000
151.910004,125.319351,-260.480438,-0.000832,0.002878,0.073098,557.448303,28.397770,0.730985,-260.480438,0.072257,0.000000
152.350006,122.220459,-260.435974,-0.000849,0.002852,0.072448,543.663757,27.695553,0.724480,-260.435974,0.071520,0.000000
152.790009,118.672501,-260.524933,-0.000854,0.002822,0.071685,527.881653,26.891573,0.716849,-260.524933,0.070792,0.000000
153.230011,115.137939,-260.569397,-0.000849,0.002792,0.070904,512.159119,26.090630,0.709044,-260.569397,0.070054,0.000000
153.670013,111.625717,-260.613892,-0.000858,0.002760,0.070115,496.535980,25.294750,0.701152,-260.613892,0.069317,0.000000
154.110001,108.670197,-260.613892,-0.000884,0.002734,0.069456,483.389191,24.625017,0.694561,-260.613892,0.068589,0.000000
154.550003,104.690292,-260.658386,-0.000875,0.002700,0.068580,465.685669,23.723160,0.685802,-260.658386,0.067852,0.000000
154.990005,101.472244,-260.569397,-0.000875,0.002671,0.067834,451.371094,22.993938,0.678344,-260.569397,0.067123,0.000000
155.430008,98.722641,-260.702850,-0.000867,0.002647,0.067245,439.140228,22.370871,0.672447,-260.702850,0.066386,0.000000
155.870010,95.627106,-260.658386,-0.000884,0.002623,0.066612,425.370605,21.669413,0.666116,-260.658386,0.065658,0.000000
156.310013,92.219528,-260.658386,-0.000897,0.002591,0.065822,410.212952,20.897243,0.658224,-260.658386,0.064921,0.000000
156.750000,88.843231,-260.747345,-0.000884,0.002562,0.065068,395.194427,20.132162,0.650679,-260.747345,0.064183,0.000000
157.190002,85.495224,-260.702850,-0.000888,0.002531,0.064296,380.301758,19.373493,0.642961,-260.702850,0.063455,0.000000
157.630005,82.756424,-260.747345,-0.000897,0.002502,0.063550,368.118958,18.752874,0.635503,-260.747345,0.062718,0.000000
158.070007,79.453857,-260.747345,-0.000914,0.002477,0.062909,353.428406,18.004501,0.629085,-260.747345,0.061989,0.000000
158.510010,75.024490,-260.836304,-0.000901,0.002442,0.062024,333.725586,17.000792,0.620240,-260.836304,0.061252,0.000000
158.950012,72.294250,-260.791809,-0.000905,0.002412,0.061252,321.580902,16.382111,0.612521,-260.791809,0.060524,0.000000
159.390015,68.922043,-260.791809,-0.000918,0.002386,0.060593,306.580566,15.617958,0.605931,-260.791809,0.059787,0.000000
159.830002,66.255493,-260.880768,-0.000918,0.002366,0.060099,294.719147,15.013710,0.600987,-260.880768,0.059049,0.000000
160.270004,62.772316,-260.836304,-0.000918,0.002332,0.059232,279.225220,14.224410,0.592315,-260.836304,0.058321,0.000000
160.710007,59.639549,-260.925262,-0.000940,0.002306,0.058572,265.289978,13.514515,0.585724,-260.925262,0.057584,0.000000
161.150009,56.220055,-260.925262,-0.000936,0.002274,0.057749,250.079300,12.739646,0.577486,-260.925262,0.056855,0.000000
161.590012,52.904076,-260.925262,-0.000949,0.002242,0.056951,235.329086,11.988235,0.569507,-260.925262,0.056118,0.000000
162.030014,50.801659,-260.969727,-0.000940,0.002221,0.056404,225.977066,11.511820,0.564044,-260.969727,0.055390,0.000000
162.470001,47.012024,-260.925262,-0.000944,0.002189,0.055607,209.119934,10.653077,0.556065,-260.925262,0.054653,0.000000
162.910004,43.642799,-261.058716,-0.000940,0.002158,0.054809,194.132874,9.889600,0.548087,-261.058716,0.053924,0.000000
163.350006,40.949059,-260.969727,-0.000957,0.002136,0.054254,182.150513,9.279190,0.542536,-260.969727,0.053187,0.000000
163.790009,37.649467,-261.014221,-0.000957,0.002106,0.053490,167.473190,8.531491,0.534905,-261.014221,0.052450,0.000000
164.230011,34.273537,-261.058716,-0.000957,0.002073,0.052649,152.456299,7.766494,0.526493,-261.058716,0.051721,0.000000
164.670013,31.379456,-261.014221,-0.000974,0.002045,0.051955,139.582794,7.110686,0.519555,-261.014221,0.050984,0.000000
165.110001,28.054169,-261.147675,-0.000970,0.002018,0.051253,124.791176,6.357166,0.512530,-261.147675,0.050256,0.000000
165.550003,24.906136,-261.058716,-0.000966,0.001985,0.050412,110.788025,5.643811,0.504118,-261.058716,0.049519,0.000000
165.990005,22.089134,-261.058716,-0.000974,0.001961,0.049813,98.257378,5.005469,0.498134,-261.058716,0.048790,0.000000
166.430008,18.694962,-261.147675,-0.000983,0.001928,0.048972,83.159340,4.236339,0.489722,-261.147675,0.048053,0.000000
166.870010,15.410637,-261.103180,-0.000987,0.001898,0.048200,68.549934,3.492100,0.482004,-261.103180,0.047316,0.000000
167.310013,12.600716,-261.192139,-0.000996,0.001872,0.047559,56.050781,2.855363,0.475587,-261.192139,0.046587,0.000000
167.750015,9.437408,-261.058716,-0.000983,0.001842,0.046795,41.979691,2.138547,0.467955,-261.058716,0.045850,0.000000
168.190002,6.485611,-261.281097,-0.001000,0.001813,0.046050,28.849438,1.469660,0.460497,-261.281097,0.045122,0.000000
168.630005,3.016220,-261.192139,-0.000987,0.001778,0.045174,13.416817,0.683485,0.451738,-261.192139,0.044385,0.000000
169.070007,0.821083,-261.192139,-0.001000,0.001758,0.044653,3.652360,0.186060,0.446535,-261.192139,0.043656,0.000000
169.510010,-1.609764,-261.236633,-0.000996,0.001728,0.043882,-7.160588,-0.364778,0.438816,-261.236633,0.042919,0.000000
169.950012,-0.404770,-261.281097,-0.001013,0.001701,0.043214,-1.800506,-0.091722,0.432139,-261.281097,0.042182,0.000000
170.390015,-0.123627,-261.236633,-0.001043,0.001670,0.042425,-0.549919,-0.028014,0.424247,-261.236633,0.041453,0.000000
170.830002,-0.078941,-261.281097,-0.001065,0.001640,0.041662,-0.351149,-0.017888,0.416615,-261.281097,0.040716,0.000000
171.270004,-0.047287,-261.281097,-0.001095,0.001617,0.041063,-0.210343,-0.010715,0.410631,-261.281097,0.039988,0.000000
171.710007,-0.067772,-261.325592,-0.001104,0.001594,0.040491,-0.301465,-0.015357,0.404908,-261.325592,0.039251,0.000000
172.150009,-0.057343,-261.325592,-0.001160,0.001554,0.039476,-0.255072,-0.012994,0.394761,-261.325592,0.038522,0.000000
172.590012,-0.071869,-261.370056,-0.001168,0.001527,0.038774,-0.319689,-0.016286,0.387737,-261.370056,0.037785,0.000000
173.030014,-0.056969,-261.281097,-0.001194,0.001500,0.038089,-0.253409,-0.012909,0.380886,-261.281097,0.037048,0.000000
173.470001,-0.039841,-261.370056,-0.001220,0.001476,0.037499,-0.177220,-0.009028,0.374988,-261.370056,0.036319,0.000000
173.910004,-0.088623,-261.370056,-0.001250,0.001443,0.036640,-0.394215,-0.020082,0.366403,-261.370056,0.035582,0.000000
174.350006,-0.071869,-261.414551,-0.001276,0.001415,0.035946,-0.319689,-0.016286,0.359465,-261.414551,0.034854,0.000000
174.790009,-0.079689,-261.503510,-0.001319,0.001384,0.035149,-0.354474,-0.018058,0.351487,-261.503510,0.034117,0.000000
175.230011,-0.045059,-261.414551,-0.001315,0.001351,0.034316,-0.200433,-0.010211,0.343161,-261.414551,0.033388,0.000000
175.670013,-0.030907,-261.459045,-0.001375,0.001322,0.033570,-0.137480,-0.007004,0.335703,-261.459045,0.032651,0.000000
176.110016,-0.041328,-261.503510,-0.001380,0.001291,0.032798,-0.183838,-0.009365,0.327985,-261.503510,0.031923,0.000000
176.550003,-0.016380,-261.503510,-0.001436,0.001263,0.032087,-0.072863,-0.003712,0.320873,-261.503510,0.031185,0.000000
176.990005,-0.035744,-261.548004,-0.001440,0.001238,0.031454,-0.158996,-0.008100,0.314543,-261.548004,0.030448,0.000000
177.430008,-0.044685,-261.548004,-0.001475,0.001204,0.030587,-0.198770,-0.010126,0.305871,-261.548004,0.029720,0.000000
177.700012,0.017876,-261.592468,-0.001466,0.001207,0.030665,0.079515,0.004051,0.306651,-261.592468,0.030552,0.000000