File: Data/sima compression 500bar/P2-15-500bar-3_11072024_174329.csv
Time (sec),S:Load (lbs),S:HL1 (DIM),S:LVDT (in),S:Position (in),Ch:Position (mm),Ch:Load (N),Ch:Stress (MPa),Ch:Strain (mm/mm),Ch:HL1 (DIM),Set Point (),Cycles ()
0.010000,-0.079315,-488.445312,-0.008485,-0.005461,-0.138712,-0.352812,-0.017973,-1.387119,-488.445312,-0.138539,0.000000
0.460000,-0.090111,-488.445312,-0.008489,-0.005383,-0.136718,-0.400833,-0.020419,-1.367180,-488.445312,-0.136162,0.000000
0.910000,-0.078194,-488.489807,-0.008304,-0.005112,-0.129842,-0.347823,-0.017719,-1.298416,-488.489807,-0.128670,0.000000
1.360000,-0.069260,-488.534271,-0.007981,-0.004814,-0.122279,-0.308082,-0.015694,-1.222794,-488.534271,-0.121161,0.000000
1.810000,-0.124001,-488.534271,-0.007666,-0.004512,-0.114613,-0.551582,-0.028099,-1.146127,-488.534271,-0.113666,0.000000
2.260000,-0.084900,-488.534271,-0.007373,-0.004227,-0.107371,-0.377654,-0.019239,-1.073714,-488.534271,-0.106174,0.000000
2.710000,-0.038727,-488.489807,-0.007049,-0.003926,-0.099721,-0.172265,-0.008776,-0.997214,-488.489807,-0.098681,0.000000
3.160000,-0.063675,-488.578766,-0.006752,-0.003633,-0.092273,-0.283240,-0.014429,-0.922727,-488.578766,-0.091189,0.000000
3.610000,-0.143364,-488.623260,-0.006454,-0.003338,-0.084780,-0.637715,-0.032487,-0.847801,-488.623260,-0.083678,0.000000
4.060000,-0.088249,-488.578766,-0.006157,-0.003041,-0.077244,-0.392552,-0.019998,-0.772436,-488.578766,-0.076185,0.000000
4.510000,-0.064415,-488.623260,-0.005851,-0.002747,-0.069786,-0.286532,-0.014597,-0.697859,-488.623260,-0.068693,0.000000
4.960000,-0.076332,-488.623260,-0.005540,-0.002454,-0.062336,-0.339542,-0.017297,-0.623357,-488.623260,-0.061200,0.000000
5.410000,-0.091972,-488.712219,-0.005243,-0.002154,-0.054713,-0.409113,-0.020841,-0.547129,-488.712219,-0.053689,0.000000
5.860000,-0.096817,-488.712219,-0.004937,-0.001859,-0.047211,-0.430664,-0.021939,-0.472113,-488.712219,-0.046197,0.000000
6.310000,-0.140755,-488.712219,-0.004635,-0.001568,-0.039840,-0.626108,-0.031895,-0.398398,-488.712219,-0.038704,0.000000
6.760000,-0.074097,-488.756683,-0.004329,-0.001270,-0.032270,-0.329598,-0.016791,-0.322700,-488.756683,-0.031212,0.000000
7.210001,-0.036491,-488.756683,-0.004044,-0.000976,-0.024794,-0.162322,-0.008269,-0.247941,-488.756683,-0.023701,0.000000
7.660000,-0.095329,-488.712219,-0.003721,-0.000680,-0.017274,-0.424046,-0.021602,-0.172743,-488.712219,-0.016208,0.000000
8.110001,-0.087875,-488.756683,-0.003415,-0.000383,-0.009730,-0.390889,-0.019913,-0.097302,-488.756683,-0.008716,0.000000
8.560000,-0.028297,-488.801178,-0.003126,-0.000096,-0.002445,-0.125873,-0.006412,-0.024450,-488.801178,-0.001223,0.000000
9.010000,0.185074,-488.890137,-0.003022,-0.000010,-0.000242,0.823250,0.041938,-0.002422,-488.890137,-0.000026,0.000000
9.460000,0.151184,-488.845642,-0.003018,-0.000010,-0.000242,0.672500,0.034259,-0.002422,-488.845642,0.000321,0.000000
9.910001,0.213371,-488.845642,-0.003005,0.000001,0.000026,0.949123,0.048351,0.000257,-488.845642,0.001066,0.000000
10.360001,0.690010,-488.890137,-0.002992,0.000039,0.000980,3.069318,0.156359,0.009795,-488.890137,0.001821,0.000000
10.810000,1.292877,-488.845642,-0.002979,0.000065,0.001640,5.751005,0.292970,0.016396,-488.845642,0.002566,0.000000
11.260000,2.021988,-488.890137,-0.002940,0.000091,0.002315,8.994251,0.458189,0.023148,-488.890137,0.003322,0.000000
11.710001,3.212090,-488.890137,-0.002910,0.000125,0.003182,14.288088,0.727870,0.031823,-488.890137,0.004066,0.000000
12.160001,4.015297,-488.890137,-0.002902,0.000149,0.003773,17.860933,0.909879,0.037728,-488.890137,0.004822,0.000000
12.610001,5.495850,-488.979095,-0.002867,0.000184,0.004683,24.446760,1.245377,0.046827,-488.979095,0.005567,0.000000
13.060000,6.450607,-488.934601,-0.002854,0.000211,0.005350,28.693735,1.461728,0.053503,-488.934601,0.006322,0.000000
13.510000,8.067078,-488.934601,-0.002841,0.000246,0.006244,35.884155,1.828026,0.062436,-488.934601,0.007067,0.000000
13.960001,9.257553,-488.979095,-0.002811,0.000271,0.006876,41.179653,2.097791,0.068764,-488.979095,0.007823,0.000000
14.410001,10.722466,-489.068054,-0.002794,0.000302,0.007683,47.695908,2.429745,0.076833,-489.068054,0.008567,0.000000
14.860001,11.881660,-489.068054,-0.002794,0.000331,0.008412,52.852264,2.692423,0.084116,-489.068054,0.009323,0.000000
15.310000,13.482117,-489.068054,-0.002781,0.000362,0.009202,59.971451,3.055091,0.092018,-489.068054,0.010068,0.000000
15.760001,14.344910,-489.068054,-0.002746,0.000384,0.009756,63.809345,3.250603,0.097559,-489.068054,0.010823,0.000000
16.210001,16.286827,-489.068054,-0.002742,0.000422,0.010719,72.447426,3.690648,0.107188,-489.068054,0.011568,0.000000
16.660000,17.164886,-489.157013,-0.002721,0.000447,0.011361,76.353226,3.889619,0.113607,-489.157013,0.012324,0.000000
17.110001,18.854706,-489.157013,-0.002699,0.000481,0.012228,83.869919,4.272537,0.122282,-489.157013,0.013068,0.000000
17.560001,20.054123,-489.201508,-0.002686,0.000510,0.012947,89.205193,4.544329,0.129474,-489.201508,0.013815,0.000000
18.010000,20.916161,-489.201508,-0.002669,0.000536,0.013615,93.039726,4.739670,0.136150,-489.201508,0.014569,0.000000
18.460001,22.710625,-489.245972,-0.002639,0.000571,0.014508,101.021904,5.146301,0.145083,-489.245972,0.015315,0.000000
18.910002,23.497078,-489.201508,-0.002608,0.000598,0.015185,104.520226,5.324514,0.151850,-489.201508,0.016069,0.000000
19.360001,24.757187,-489.334930,-0.002613,0.000629,0.015966,110.125465,5.610059,0.159662,-489.334930,0.016816,0.000000
19.810001,25.459480,-489.201508,-0.002583,0.000652,0.016573,113.249428,5.769201,0.165733,-489.201508,0.017569,0.000000
20.260000,27.031265,-489.245972,-0.002570,0.000690,0.017527,120.241074,6.125372,0.175271,-489.245972,0.018316,0.000000
20.710001,27.129944,-489.334930,-0.002535,0.000711,0.018055,120.680016,6.147733,0.180555,-489.334930,0.019070,0.000000
21.160002,28.187851,-489.334930,-0.002518,0.000744,0.018888,125.385826,6.387458,0.188881,-489.334930,0.019816,0.000000
21.610001,28.555382,-489.334930,-0.002483,0.000766,0.019460,127.020683,6.470742,0.194604,-489.334930,0.020570,0.000000
22.060001,30.259735,-489.379425,-0.002479,0.000808,0.020528,134.602020,6.856954,0.205278,-489.379425,0.021317,0.000000
22.510000,30.638809,-489.379425,-0.002488,0.000833,0.021168,136.288223,6.942853,0.211682,-489.379425,0.022070,0.000000
22.960001,31.074486,-489.379425,-0.002449,0.000862,0.021898,138.226212,7.041579,0.218979,-489.379425,0.022817,0.000000
23.410002,31.522820,-489.379425,-0.002410,0.000889,0.022573,140.220505,7.143173,0.225731,-489.379425,0.023571,0.000000
23.860001,32.492104,-489.379425,-0.002406,0.000924,0.023475,144.532089,7.362816,0.234754,-489.379425,0.024317,0.000000
24.310001,33.124763,-489.512878,-0.002384,0.000954,0.024231,147.346313,7.506178,0.242309,-489.512878,0.025071,0.000000
24.760000,33.369789,-489.557343,-0.002358,0.000983,0.024976,148.436234,7.561702,0.249758,-489.557343,0.025818,0.000000
25.210001,33.993141,-489.468384,-0.002337,0.001014,0.025748,151.209045,7.702956,0.257479,-489.468384,0.026571,0.000000
25.660002,34.150284,-489.557343,-0.002320,0.001038,0.026364,151.908051,7.738565,0.263641,-489.557343,0.027318,0.000000
26.110001,35.282661,-489.512878,-0.002307,0.001074,0.027283,156.945114,7.995165,0.272830,-489.512878,0.028072,0.000000
26.560001,35.093124,-489.512878,-0.002294,0.001098,0.027881,156.102020,7.952216,0.278811,-489.512878,0.028818,0.000000
27.010002,35.897827,-489.557343,-0.002268,0.001129,0.028688,159.681503,8.134564,0.286880,-489.557343,0.029572,0.000000
27.460001,35.617424,-489.601837,-0.002242,0.001149,0.029182,158.434219,8.071024,0.291815,-489.601837,0.030319,0.000000
27.910002,37.594727,-489.601837,-0.002233,0.001193,0.030309,167.229691,8.519087,0.303094,-489.601837,0.031072,0.000000
28.360001,37.128891,-489.601837,-0.002212,0.001217,0.030917,165.157562,8.413527,0.309165,-489.601837,0.031819,0.000000
28.810001,37.324753,-489.646301,-0.002195,0.001242,0.031558,166.028793,8.457911,0.315585,-489.646301,0.032573,0.000000
29.260002,38.317871,-489.557343,-0.002156,0.001274,0.032347,170.446396,8.682954,0.323472,-489.557343,0.033319,0.000000
29.710001,38.254944,-489.690796,-0.002143,0.001294,0.032859,170.166489,8.668694,0.328589,-489.690796,0.034073,0.000000
30.160002,39.360886,-489.646301,-0.002121,0.001330,0.033778,175.085968,8.919304,0.337779,-489.646301,0.034820,0.000000
30.610001,39.848320,-489.735260,-0.002113,0.001360,0.034550,177.254181,9.029758,0.345500,-489.735260,0.035573,0.000000
31.060001,40.856339,-489.735260,-0.002091,0.001393,0.035374,181.738068,9.258179,0.353736,-489.735260,0.036320,0.000000
31.510002,41.020554,-489.735260,-0.002078,0.001416,0.035973,182.468536,9.295390,0.359732,-489.735260,0.037074,0.000000
31.960001,41.902702,-489.779755,-0.002048,0.001448,0.036788,186.392532,9.495288,0.367877,-489.779755,0.037820,0.000000
32.410000,42.590477,-489.779755,-0.002026,0.001481,0.037629,189.451904,9.651140,0.376294,-489.779755,0.038574,0.000000
32.860001,43.613380,-489.913208,-0.002022,0.001513,0.038435,194.001999,9.882934,0.384349,-489.913208,0.039321,0.000000
33.310001,43.143448,-489.868713,-0.001983,0.001530,0.038869,191.911636,9.776445,0.388694,-489.868713,0.040074,0.000000
33.760002,45.200432,-489.824219,-0.001992,0.001574,0.039970,201.061569,10.242564,0.399700,-489.824219,0.040821,0.000000
34.210003,45.190010,-489.868713,-0.001962,0.001598,0.040595,201.015198,10.240202,0.405953,-489.868713,0.041575,0.000000
34.660000,46.146255,-489.913208,-0.001936,0.001631,0.041428,205.268799,10.456891,0.414279,-489.913208,0.042321,0.000000
35.110001,46.495544,-489.913208,-0.001919,0.001655,0.042043,206.822510,10.536040,0.420426,-489.913208,0.043075,0.000000
35.560001,47.211617,-489.913208,-0.001910,0.001686,0.042833,210.007751,10.698305,0.428329,-489.913208,0.043822,0.000000
36.010002,48.222237,-489.957672,-0.001880,0.001716,0.043578,214.503220,10.927315,0.435778,-489.957672,0.044575,0.000000
36.460003,48.915962,-489.957672,-0.001880,0.001745,0.044315,217.589066,11.084516,0.443151,-489.957672,0.045322,0.000000
36.910000,50.067711,-489.913208,-0.001867,0.001779,0.045183,222.712296,11.345506,0.451826,-489.913208,0.046067,0.000000
37.360001,50.330978,-490.002167,-0.001845,0.001802,0.045764,223.883377,11.405163,0.457639,-490.002167,0.046821,0.000000
37.810001,52.112785,-490.002167,-0.001828,0.001841,0.046760,231.809250,11.808926,0.467601,-490.002167,0.047567,0.000000
38.260002,52.081505,-490.046631,-0.001798,0.001862,0.047299,231.670105,11.801838,0.472991,-490.046631,0.048321,0.000000
38.710003,53.686058,-490.091125,-0.001781,0.001898,0.048218,238.807510,12.165435,0.482180,-490.091125,0.049067,0.000000
39.160004,54.400642,-490.046631,-0.001776,0.001923,0.048833,241.986145,12.327362,0.488327,-490.046631,0.049821,0.000000
39.610001,55.670799,-490.046631,-0.001755,0.001957,0.049700,247.636078,12.615183,0.497002,-490.046631,0.050568,0.000000
40.060001,56.138504,-490.135590,-0.001746,0.001979,0.050265,249.716537,12.721168,0.502649,-490.135590,0.051322,0.000000
40.510002,57.354668,-490.091125,-0.001733,0.002010,0.051054,255.126297,12.996754,0.510537,-490.091125,0.052068,0.000000
40.960003,58.268471,-490.091125,-0.001686,0.002037,0.051747,259.191101,13.203824,0.517471,-490.091125,0.052822,0.000000
41.410004,59.182648,-490.135590,-0.001694,0.002071,0.052605,263.257568,13.410979,0.526055,-490.135590,0.053568,0.000000
41.860001,61.067223,-490.180084,-0.001673,0.002104,0.053438,271.640564,13.838031,0.534382,-490.180084,0.054322,0.000000
42.310001,62.124390,-490.180084,-0.001664,0.002132,0.054159,276.343079,14.077588,0.541588,-490.180084,0.055069,0.000000
42.760002,63.179321,-490.180084,-0.001647,0.002160,0.054861,281.035645,14.316639,0.548613,-490.180084,0.055823,0.000000
43.210003,63.350616,-490.224548,-0.001630,0.002179,0.055338,281.797607,14.355454,0.553382,-490.224548,0.056569,0.000000
43.660004,65.939346,-490.269043,-0.001604,0.002223,0.056465,293.312866,14.942069,0.564646,-490.269043,0.057323,0.000000
44.110001,66.552643,-490.269043,-0.001591,0.002249,0.057132,296.040955,15.081044,0.571322,-490.269043,0.058069,0.000000
44.560001,67.992233,-490.224548,-0.001578,0.002278,0.057870,302.444550,15.407261,0.578695,-490.224548,0.058823,0.000000
45.010002,68.902313,-490.313538,-0.001569,0.002304,0.058511,306.492798,15.613487,0.585114,-490.313538,0.059570,0.000000
45.460003,71.110107,-490.269043,-0.001548,0.002343,0.059509,316.313568,16.113781,0.595091,-490.269043,0.060324,0.000000
45.910004,71.598282,-490.269043,-0.001531,0.002366,0.060091,318.485077,16.224403,0.600905,-490.269043,0.061070,0.000000
46.360001,73.548782,-490.269043,-0.001518,0.002400,0.060956,327.161316,16.666393,0.609565,-490.269043,0.061824,0.000000
46.810001,73.942001,-490.358002,-0.001518,0.002418,0.061426,328.910461,16.755497,0.614258,-490.358002,0.062570,0.000000
47.260002,75.307114,-490.358002,-0.001500,0.002454,0.062319,334.982758,17.064835,0.623191,-490.358002,0.063324,0.000000
47.710003,77.659393,-490.358002,-0.001466,0.002487,0.063168,345.446228,17.597870,0.631684,-490.358002,0.064071,0.000000
48.160004,78.999939,-490.402496,-0.001457,0.002513,0.063836,351.409271,17.901642,0.638360,-490.402496,0.064825,0.000000
48.610001,80.955643,-490.402496,-0.001449,0.002544,0.064625,360.108673,18.344810,0.646248,-490.402496,0.065571,0.000000
49.060001,81.719376,-490.491455,-0.001431,0.002565,0.065155,363.505951,18.517876,0.651547,-490.491455,0.066325,0.000000
49.510002,84.713989,-490.446960,-0.001427,0.002606,0.066195,376.826630,19.196465,0.661948,-490.446960,0.067071,0.000000
49.960003,85.841537,-490.491455,-0.001397,0.002632,0.066855,381.842224,19.451971,0.668549,-490.491455,0.067825,0.000000
50.410004,88.106674,-490.446960,-0.001397,0.002663,0.067644,391.918060,19.965258,0.676436,-490.446960,0.068572,0.000000
50.860001,89.325821,-490.535919,-0.001375,0.002686,0.068225,397.341095,20.241520,0.682250,-490.535919,0.069326,0.000000
51.310001,91.655014,-490.580414,-0.001367,0.002721,0.069118,407.701874,20.769323,0.691182,-490.580414,0.070072,0.000000
51.760002,93.110626,-490.624878,-0.001371,0.002745,0.069733,414.176758,21.099171,0.697329,-490.624878,0.070826,0.000000
52.210003,95.464020,-490.580414,-0.001341,0.002780,0.070609,424.645172,21.632456,0.706095,-490.580414,0.071572,0.000000
52.660004,96.677948,-490.535919,-0.001332,0.002800,0.071112,430.044983,21.907536,0.711121,-490.535919,0.072326,0.000000
53.110004,99.081238,-490.669373,-0.001328,0.002837,0.072066,440.735352,22.452129,0.720659,-490.669373,0.073073,0.000000
53.560001,101.059280,-490.624878,-0.001315,0.002865,0.072761,449.534119,22.900360,0.727608,-490.624878,0.073827,0.000000
54.010002,102.775543,-490.624878,-0.001298,0.002890,0.073410,457.168457,23.289270,0.734103,-490.624878,0.074573,0.000000
54.460003,105.446579,-490.713867,-0.001276,0.002923,0.074234,469.049805,23.894537,0.742339,-490.713867,0.075327,0.000000
54.910004,106.947235,-490.669373,-0.001281,0.002947,0.074850,475.725067,24.234591,0.748501,-490.669373,0.076073,0.000000
55.360004,110.282196,-490.758331,-0.001272,0.002987,0.075874,490.559723,24.990303,0.758735,-490.758331,0.076827,0.000000
55.810001,112.081131,-490.713867,-0.001255,0.003013,0.076541,498.561768,25.397947,0.765412,-490.713867,0.077574,0.000000
56.260002,114.860519,-490.758331,-0.001233,0.003047,0.077383,510.925110,26.027765,0.773829,-490.758331,0.078328,0.000000
56.710003,116.420013,-490.802826,-0.001212,0.003067,0.077911,517.862061,26.381151,0.779113,-490.802826,0.079074,0.000000
57.160004,119.181152,-490.802826,-0.001212,0.003102,0.078795,530.144226,27.006834,0.787955,-490.802826,0.079819,0.000000
57.610004,121.317093,-490.802826,-0.001203,0.003129,0.079472,539.645386,27.490847,0.794722,-490.802826,0.080574,0.000000
58.060001,124.096481,-490.847290,-0.001199,0.003163,0.080331,552.008728,28.120665,0.803306,-490.847290,0.081319,0.000000
58.510002,125.546494,-490.891785,-0.001177,0.003181,0.080808,558.458679,28.449242,0.808075,-490.891785,0.082075,0.000000
58.960003,128.982376,-490.936249,-0.001181,0.003222,0.081831,573.742249,29.227823,0.818309,-490.936249,0.082820,0.000000
59.410004,131.333160,-490.936249,-0.001173,0.003249,0.082533,584.199097,29.760521,0.825334,-490.936249,0.083575,0.000000
59.860004,134.012375,-490.980743,-0.001160,0.003282,0.083357,596.116821,30.367638,0.833570,-490.980743,0.084320,0.000000
60.310001,136.285339,-490.936249,-0.001155,0.003308,0.084025,606.227478,30.882698,0.840247,-490.936249,0.085075,0.000000
60.760002,138.324081,-490.980743,-0.001143,0.003335,0.084720,615.296265,31.344685,0.847196,-490.980743,0.085820,0.000000
61.210003,141.555161,-491.025208,-0.001117,0.003368,0.085560,629.668823,32.076859,0.855598,-491.025208,0.086576,0.000000
61.660004,143.788269,-491.025208,-0.001130,0.003398,0.086297,639.602173,32.582886,0.862971,-491.025208,0.087321,0.000000
62.110004,146.595963,-491.025208,-0.001108,0.003428,0.087060,652.091431,33.219120,0.870602,-491.025208,0.088076,0.000000
62.560001,148.557617,-491.025208,-0.001099,0.003449,0.087616,660.817261,33.663635,0.876158,-491.025208,0.088821,0.000000
63.010002,152.045639,-491.025208,-0.001108,0.003489,0.088630,676.332764,34.454037,0.886301,-491.025208,0.089576,0.000000
63.460003,153.806213,-491.069702,-0.001091,0.003512,0.089202,684.164185,34.852989,0.892024,-491.069702,0.090321,0.000000
63.910004,157.038773,-491.158661,-0.001078,0.003545,0.090044,698.543335,35.585495,0.900442,-491.158661,0.091077,0.000000
64.360001,159.411911,-491.069702,-0.001074,0.003571,0.090694,709.099609,36.123257,0.906937,-491.069702,0.091822,0.000000
64.810005,162.639633,-491.069702,-0.001078,0.003606,0.091596,723.457214,36.854668,0.915960,-491.069702,0.092575,0.000000
65.260002,165.056702,-491.114166,-0.001056,0.003631,0.092221,734.208862,37.402386,0.922212,-491.114166,0.093322,0.000000
65.710007,167.554199,-491.158661,-0.001056,0.003659,0.092949,745.318298,37.968327,0.929495,-491.158661,0.094076,0.000000
66.160004,170.456100,-491.158661,-0.001052,0.003688,0.093687,758.226624,38.625904,0.936867,-491.158661,0.094822,0.000000
66.610001,173.461899,-491.247620,-0.001030,0.003722,0.094527,771.597046,39.307030,0.945270,-491.247620,0.095576,0.000000
67.060005,176.393951,-491.203156,-0.001026,0.003751,0.095282,784.639465,39.971439,0.952825,-491.203156,0.096323,0.000000
67.510002,179.000565,-491.247620,-0.001030,0.003781,0.096045,796.234253,40.562107,0.960455,-491.247620,0.097076,0.000000
67.960007,181.964279,-491.336578,-0.001022,0.003811,0.096790,809.417542,41.233692,0.967904,-491.336578,0.097823,0.000000
68.410004,184.350433,-491.247620,-0.001013,0.003835,0.097416,820.031677,41.774403,0.974156,-491.247620,0.098577,0.000000
68.860001,187.849243,-491.381073,-0.001000,0.003872,0.098344,835.595154,42.567245,0.983437,-491.381073,0.099323,0.000000
69.310005,189.800858,-491.381073,-0.000992,0.003895,0.098933,844.276367,43.009491,0.989326,-491.381073,0.100077,0.000000
69.760002,193.196899,-491.381073,-0.001013,0.003928,0.099783,859.382751,43.779041,0.997835,-491.381073,0.100824,0.000000
70.210007,195.054291,-491.381073,-0.001000,0.003946,0.100216,867.644836,44.199936,1.002164,-491.381073,0.101577,0.000000
70.660004,199.381989,-491.381073,-0.001009,0.003990,0.101344,886.895386,45.180607,1.013443,-491.381073,0.102324,0.000000
71.110001,201.353333,-491.381073,-0.001005,0.004013,0.101924,895.664368,45.627316,1.019242,-491.381073,0.103078,0.000000
71.560005,203.945801,-491.425537,-0.000992,0.004039,0.102584,907.196228,46.214779,1.025843,-491.425537,0.103824,0.000000
72.010002,207.369751,-491.470032,-0.000979,0.004070,0.103382,922.426697,46.990658,1.033821,-491.470032,0.104578,0.000000
72.460007,209.410736,-491.470032,-0.000957,0.004090,0.103885,931.505493,47.453148,1.038848,-491.470032,0.105325,0.000000
72.910004,213.133331,-491.514496,-0.000961,0.004126,0.104804,948.064392,48.296703,1.048037,-491.514496,0.106078,0.000000
73.360001,216.059448,-491.558990,-0.000970,0.004155,0.105524,961.080444,48.959770,1.055244,-491.558990,0.106825,0.000000
73.810005,219.565338,-491.514496,-0.000974,0.004190,0.106418,976.675415,49.754215,1.064176,-491.514496,0.107579,0.000000
74.260002,220.995239,-491.558990,-0.000961,0.004193,0.106513,983.035950,50.078236,1.065130,-491.558990,0.018709,0.000000
74.710007,220.593445,-491.603485,-0.000970,0.004187,0.106339,981.248657,49.987186,1.063389,-491.603485,982.000671,0.000000
75.160004,220.257568,-491.603485,-0.000944,0.004186,0.106330,979.754578,49.911079,1.063298,-491.603485,982.000671,0.000000
75.610001,219.861725,-491.603485,-0.000953,0.004187,0.106339,977.993774,49.821381,1.063389,-491.603485,982.000671,0.000000
76.060005,219.585449,-491.603485,-0.000953,0.004195,0.106548,976.764832,49.758778,1.065478,-491.603485,982.000671,0.000000
76.510002,219.363129,-491.692444,-0.000944,0.004198,0.106634,975.775940,49.708397,1.066341,-491.692444,982.000671,0.000000
76.960007,220.022980,-491.692444,-0.000944,0.004208,0.106895,978.711121,49.857918,1.068945,-491.692444,982.000671,0.000000
77.410004,219.852814,-491.692444,-0.000957,0.004208,0.106895,977.954163,49.819359,1.068945,-491.692444,982.000671,0.000000
77.860001,219.675537,-491.647949,-0.000957,0.004209,0.106902,977.165588,49.779190,1.069021,-491.647949,982.000671,0.000000
78.310005,219.538879,-491.781403,-0.000936,0.004210,0.106937,976.557678,49.748222,1.069369,-491.781403,982.000671,0.000000
78.760002,219.417511,-491.781403,-0.000944,0.004211,0.106964,976.017822,49.720718,1.069642,-491.781403,982.000671,0.000000
79.210007,219.474091,-491.736908,-0.000953,0.004215,0.107060,976.269531,49.733540,1.070595,-491.736908,982.000671,0.000000
79.660004,219.412659,-491.781403,-0.000953,0.004215,0.107067,975.996277,49.719620,1.070671,-491.781403,982.000671,0.000000
80.110001,219.454742,-491.736908,-0.000944,0.004219,0.107162,976.183472,49.729156,1.071625,-491.736908,982.000671,0.000000
80.560005,219.454346,-491.781403,-0.000953,0.004219,0.107162,976.181702,49.729065,1.071625,-491.781403,982.000671,0.000000
81.010002,219.323273,-491.825867,-0.000949,0.004219,0.107162,975.598633,49.699364,1.071625,-491.825867,982.000671,0.000000
81.460007,219.281952,-491.870361,-0.000949,0.004221,0.107206,975.414856,49.689999,1.072064,-491.870361,982.000671,0.000000
81.910004,219.976807,-491.781403,-0.000931,0.004229,0.107406,978.505676,49.847458,1.074062,-491.781403,982.000671,0.000000
82.360001,219.907166,-491.825867,-0.000931,0.004229,0.107406,978.195923,49.831676,1.074062,-491.825867,982.000671,0.000000
82.810005,219.806610,-491.914825,-0.000949,0.004229,0.107406,977.748657,49.808891,1.074062,-491.914825,982.000671,0.000000
83.260002,219.710175,-491.914825,-0.000918,0.004229,0.107406,977.319641,49.787037,1.074062,-491.914825,982.000671,0.000000
83.710007,219.579468,-491.870361,-0.000940,0.004229,0.107414,976.738281,49.757420,1.074138,-491.870361,982.000671,0.000000
84.160004,219.604797,-491.959320,-0.000936,0.004232,0.107493,976.850952,49.763161,1.074925,-491.959320,982.000671,0.000000
84.610001,219.590637,-491.959320,-0.000931,0.004232,0.107493,976.787964,49.759953,1.074925,-491.959320,982.000671,0.000000
85.060005,219.568298,-491.959320,-0.000931,0.004233,0.107527,976.688599,49.754890,1.075274,-491.959320,982.000671,0.000000
85.510002,219.512817,-492.048279,-0.000944,0.004233,0.107527,976.441772,49.742317,1.075274,-492.048279,982.000671,0.000000
85.960007,219.643890,-491.959320,-0.000936,0.004237,0.107614,977.024841,49.772018,1.076136,-491.959320,982.000671,0.000000
86.410004,219.612610,-492.003815,-0.000923,0.004237,0.107614,976.885681,49.764927,1.076136,-492.003815,982.000671,0.000000
86.860001,219.545593,-492.048279,-0.000940,0.004237,0.107614,976.587585,49.749741,1.076136,-492.048279,982.000671,0.000000
87.310005,219.512451,-492.048279,-0.000931,0.004241,0.107709,976.440125,49.742233,1.077090,-492.048279,982.000671,0.000000
87.760002,219.719116,-492.092773,-0.000931,0.004241,0.107718,977.359436,49.789066,1.077181,-492.092773,982.000671,0.000000
88.210007,219.669952,-492.092773,-0.000931,0.004241,0.107718,977.140747,49.777924,1.077181,-492.092773,982.000671,0.000000
88.660004,219.591766,-492.137238,-0.000940,0.004241,0.107727,976.792969,49.760204,1.077272,-492.137238,982.000671,0.000000
89.110001,219.566071,-492.137238,-0.000923,0.004242,0.107735,976.678650,49.754383,1.077348,-492.137238,982.000671,0.000000
89.560005,219.517670,-492.092773,-0.000918,0.004242,0.107744,976.463379,49.743412,1.077438,-492.092773,982.000671,0.000000
90.010002,219.477814,-492.226196,-0.000931,0.004242,0.107753,976.286072,49.734383,1.077529,-492.226196,982.000671,0.000000
90.460007,219.750397,-492.137238,-0.000914,0.004247,0.107883,977.498596,49.796154,1.078831,-492.137238,982.000671,0.000000
90.910004,219.800293,-492.181732,-0.000914,0.004247,0.107883,977.720520,49.807461,1.078831,-492.181732,982.000671,0.000000
91.360001,219.757843,-492.226196,-0.000931,0.004247,0.107883,977.531677,49.797836,1.078831,-492.226196,982.000671,0.000000
91.810005,219.713898,-492.226196,-0.000918,0.004247,0.107883,977.336243,49.787884,1.078831,-492.226196,982.000671,0.000000
92.260002,219.631226,-492.270691,-0.000918,0.004247,0.107883,976.968506,49.769146,1.078831,-492.270691,982.000671,0.000000
92.710007,219.585449,-492.315155,-0.000914,0.004247,0.107883,976.764832,49.758778,1.078831,-492.315155,982.000671,0.000000
93.160004,219.540741,-492.270691,-0.000914,0.004248,0.107891,976.565979,49.748646,1.078907,-492.270691,982.000671,0.000000
93.610008,219.699005,-492.315155,-0.000914,0.004251,0.107979,977.269958,49.784504,1.079785,-492.315155,982.000671,0.000000
94.060005,219.687469,-492.270691,-0.000918,0.004251,0.107979,977.218689,49.781891,1.079785,-492.270691,982.000671,0.000000
94.510002,219.666992,-492.315155,-0.000918,0.004251,0.107979,977.127563,49.777252,1.079785,-492.315155,982.000671,0.000000
94.960007,219.613373,-492.359650,-0.000914,0.004251,0.107979,976.889099,49.765102,1.079785,-492.359650,982.000671,0.000000
95.410004,219.585449,-492.359650,-0.000931,0.004251,0.107979,976.764832,49.758778,1.079785,-492.359650,982.000671,0.000000
95.860008,219.539642,-492.448608,-0.000914,0.004251,0.107986,976.561096,49.748394,1.079861,-492.448608,982.000671,0.000000
96.310005,219.508362,-492.359650,-0.000914,0.004251,0.107986,976.421936,49.741306,1.079861,-492.359650,982.000671,0.000000
96.760002,219.913116,-492.404114,-0.000901,0.004258,0.108160,978.222412,49.833023,1.081602,-492.404114,982.000671,0.000000
97.210007,220.024475,-492.448608,-0.000905,0.004258,0.108160,978.717773,49.858261,1.081602,-492.448608,982.000671,0.000000
97.660004,219.979767,-492.448608,-0.000905,0.004258,0.108151,978.518860,49.848129,1.081511,-492.448608,982.000671,0.000000
98.110008,219.926910,-492.493103,-0.000914,0.004258,0.108151,978.283752,49.836151,1.081511,-492.493103,982.000671,0.000000
98.560005,219.898590,-492.493103,-0.000910,0.004258,0.108151,978.157776,49.829735,1.081511,-492.493103,982.000671,0.000000
99.010002,219.859863,-492.582062,-0.000914,0.004258,0.108151,977.985535,49.820957,1.081511,-492.582062,982.000671,0.000000
99.460007,219.825989,-492.493103,-0.000905,0.004258,0.108151,977.834839,49.813282,1.081511,-492.493103,982.000671,0.000000
99.910004,219.792847,-492.582062,-0.000918,0.004258,0.108151,977.687439,49.805771,1.081511,-492.582062,982.000671,0.000000
100.360008,219.744446,-492.626526,-0.000910,0.004258,0.108151,977.472107,49.794800,1.081511,-492.626526,982.000671,0.000000
100.810005,219.701996,-492.582062,-0.000914,0.004258,0.108160,977.283264,49.785183,1.081602,-492.582062,982.000671,0.000000
101.260002,219.668488,-492.582062,-0.000910,0.004258,0.108160,977.134216,49.777588,1.081602,-492.582062,982.000671,0.000000
101.710007,219.633087,-492.671021,-0.000905,0.004259,0.108169,976.976746,49.769569,1.081693,-492.671021,982.000671,0.000000
102.160004,219.593994,-492.671021,-0.000897,0.004259,0.108169,976.802856,49.760712,1.081693,-492.671021,982.000671,0.000000
102.610008,219.561981,-492.715485,-0.000914,0.004259,0.108169,976.660461,49.753456,1.081693,-492.715485,982.000671,0.000000
103.060005,219.516907,-492.715485,-0.000905,0.004259,0.108178,976.459961,49.743240,1.081784,-492.715485,982.000671,0.000000
103.510002,219.480804,-492.759979,-0.000892,0.004259,0.108178,976.299377,49.735062,1.081784,-492.759979,982.000671,0.000000
103.960007,219.459961,-492.715485,-0.000914,0.004259,0.108178,976.206665,49.730339,1.081784,-492.715485,982.000671,0.000000
104.410004,219.843109,-492.759979,-0.000905,0.004265,0.108342,977.911011,49.817162,1.083419,-492.759979,982.000671,0.000000
104.860008,219.895630,-492.759979,-0.000914,0.004265,0.108342,978.144592,49.829063,1.083419,-492.759979,982.000671,0.000000
105.310005,219.905670,-492.759979,-0.000905,0.004265,0.108342,978.189270,49.831337,1.083419,-492.759979,982.000671,0.000000
105.760002,219.898590,-492.893433,-0.000901,0.004265,0.108342,978.157776,49.829735,1.083419,-492.893433,982.000671,0.000000
106.210007,219.881104,-492.848938,-0.000892,0.004265,0.108342,978.080017,49.825768,1.083419,-492.848938,982.000671,0.000000
106.660004,219.858765,-492.893433,-0.000892,0.004265,0.108342,977.980652,49.820705,1.083419,-492.893433,982.000671,0.000000
107.110008,219.857269,-492.893433,-0.000918,0.004265,0.108342,977.973999,49.820370,1.083419,-492.893433,982.000671,0.000000
107.560005,219.822266,-492.848938,-0.000897,0.004265,0.108342,977.818298,49.812435,1.083419,-492.848938,982.000671,0.000000
108.010002,219.799561,-492.893433,-0.000905,0.004265,0.108342,977.717285,49.807293,1.083419,-492.893433,982.000671,0.000000
108.460007,219.770508,-492.982391,-0.000897,0.004265,0.108342,977.588013,49.800709,1.083419,-492.982391,982.000671,0.000000
108.910004,219.739227,-492.982391,-0.000910,0.004265,0.108342,977.448914,49.793621,1.083419,-492.982391,982.000671,0.000000
109.360008,219.696411,-493.026855,-0.000897,0.004265,0.108342,977.258423,49.783916,1.083419,-493.026855,982.000671,0.000000
109.810005,219.662506,-493.115814,-0.000901,0.004265,0.108342,977.107605,49.776234,1.083419,-493.115814,982.000671,0.000000
110.260002,219.627899,-493.026855,-0.000905,0.004265,0.108342,976.953674,49.768394,1.083419,-493.026855,982.000671,0.000000
110.710007,219.605927,-492.982391,-0.000918,0.004265,0.108342,976.855957,49.763416,1.083419,-492.982391,982.000671,0.000000
111.160004,219.579865,-493.071350,-0.000884,0.004265,0.108342,976.739990,49.757511,1.083419,-493.071350,982.000671,0.000000
111.610008,219.548584,-493.115814,-0.000897,0.004265,0.108342,976.600891,49.750420,1.083419,-493.115814,982.000671,0.000000
112.060005,219.539642,-493.071350,-0.000910,0.004266,0.108351,976.561096,49.748394,1.083509,-493.071350,982.000671,0.000000
112.510002,219.744080,-493.115814,-0.000884,0.004270,0.108446,977.470459,49.794720,1.084463,-493.115814,982.000671,0.000000
112.960007,219.773102,-493.160309,-0.000910,0.004270,0.108446,977.599609,49.801296,1.084463,-493.160309,982.000671,0.000000
113.410004,219.774963,-493.160309,-0.000901,0.004270,0.108446,977.607849,49.801720,1.084463,-493.160309,982.000671,0.000000
113.860008,219.761932,-493.204773,-0.000892,0.004270,0.108446,977.549927,49.798767,1.084463,-493.204773,982.000671,0.000000
114.310005,219.738495,-493.204773,-0.000888,0.004270,0.108446,977.445618,49.793453,1.084463,-493.204773,982.000671,0.000000
114.760002,219.719849,-493.204773,-0.000888,0.004270,0.108446,977.362671,49.789230,1.084463,-493.204773,982.000671,0.000000
115.210007,219.699371,-493.293762,-0.000888,0.004270,0.108446,977.271606,49.784592,1.084463,-493.293762,982.000671,0.000000
115.660004,219.666229,-493.293762,-0.000892,0.004270,0.108446,977.124207,49.777081,1.084463,-493.293762,982.000671,0.000000
116.110008,219.648376,-493.249268,-0.000888,0.004270,0.108446,977.044800,49.773033,1.084463,-493.249268,982.000671,0.000000
116.560005,219.631989,-493.293762,-0.000897,0.004270,0.108455,976.971863,49.769318,1.084554,-493.293762,982.000671,0.000000
117.010002,219.610382,-493.338226,-0.000901,0.004270,0.108455,976.875793,49.764427,1.084554,-493.338226,982.000671,0.000000
117.460007,219.593262,-493.382721,-0.000901,0.004270,0.108455,976.799622,49.760544,1.084554,-493.382721,982.000671,0.000000
117.910004,219.570526,-493.382721,-0.000888,0.004270,0.108464,976.698486,49.755390,1.084645,-493.382721,982.000671,0.000000
118.360008,219.547455,-493.427185,-0.000888,0.004270,0.108464,976.595825,49.750164,1.084645,-493.427185,982.000671,0.000000
118.810005,219.547455,-493.427185,-0.000888,0.004270,0.108464,976.595825,49.750164,1.084645,-493.427185,982.000671,0.000000
119.260002,219.502014,-493.427185,-0.000888,0.004271,0.108472,976.393738,49.739868,1.084721,-493.427185,982.000671,0.000000
119.710007,219.673309,-493.471680,-0.000897,0.004274,0.108551,977.155701,49.778683,1.085508,-493.471680,982.000671,0.000000
120.160004,219.706085,-493.471680,-0.000884,0.004274,0.108551,977.301453,49.786110,1.085508,-493.471680,982.000671,0.000000
120.610008,219.705719,-493.471680,-0.000897,0.004274,0.108551,977.299866,49.786030,1.085508,-493.471680,982.000671,0.000000
121.060005,219.699768,-493.471680,-0.000905,0.004274,0.108551,977.273376,49.784676,1.085508,-493.471680,982.000671,0.000000
121.510002,219.678162,-493.516144,-0.000905,0.004274,0.108551,977.177246,49.779785,1.085508,-493.516144,982.000671,0.000000
121.960007,219.671082,-493.560638,-0.000888,0.004274,0.108551,977.145752,49.778179,1.085508,-493.560638,982.000671,0.000000
122.410004,219.661041,-493.516144,-0.000880,0.004274,0.108551,977.101135,49.775906,1.085508,-493.516144,982.000671,0.000000
122.860008,219.644257,-493.649597,-0.000897,0.004274,0.108551,977.026428,49.772102,1.085508,-493.649597,982.000671,0.000000
123.310005,219.621918,-493.649597,-0.000901,0.004274,0.108551,976.927063,49.767040,1.085508,-493.649597,982.000671,0.000000
123.760002,219.613007,-493.605103,-0.000918,0.004274,0.108551,976.887451,49.765018,1.085508,-493.605103,982.000671,0.000000
124.210007,219.594757,-493.605103,-0.000905,0.004274,0.108551,976.806274,49.760883,1.085508,-493.605103,982.000671,0.000000
124.660004,219.580597,-493.694061,-0.000897,0.004274,0.108567,976.743286,49.757675,1.085674,-493.694061,982.000671,0.000000
125.110008,219.622314,-493.649597,-0.000892,0.004275,0.108593,976.928833,49.767128,1.085932,-493.649597,982.000671,0.000000
125.560005,219.706818,-493.738556,-0.000884,0.004277,0.108628,977.304749,49.786274,1.086280,-493.738556,982.000671,0.000000
126.010010,219.721344,-493.738556,-0.000880,0.004277,0.108628,977.369324,49.789566,1.086280,-493.738556,982.000671,0.000000
126.460007,219.733276,-493.738556,-0.000901,0.004277,0.108628,977.422424,49.792271,1.086280,-493.738556,982.000671,0.000000
126.910004,219.723969,-493.738556,-0.000892,0.004277,0.108628,977.381042,49.790161,1.086280,-493.738556,982.000671,0.000000
127.360008,219.715759,-493.783051,-0.000871,0.004277,0.108628,977.344482,49.788300,1.086280,-493.783051,982.000671,0.000000
127.810005,219.706451,-493.827515,-0.000880,0.004277,0.108628,977.303101,49.786194,1.086280,-493.827515,982.000671,0.000000
128.260010,219.690826,-493.827515,-0.000884,0.004277,0.108628,977.233582,49.782650,1.086280,-493.827515,982.000671,0.000000
128.710007,219.676666,-493.827515,-0.000897,0.004277,0.108628,977.170593,49.779442,1.086280,-493.827515,982.000671,0.000000
129.160004,219.665863,-493.916473,-0.000892,0.004277,0.108628,977.122559,49.776993,1.086280,-493.916473,982.000671,0.000000
129.610001,219.651733,-493.916473,-0.000875,0.004277,0.108628,977.059692,49.773792,1.086280,-493.916473,982.000671,0.000000
130.060013,219.640167,-493.916473,-0.000901,0.004277,0.108628,977.008240,49.771172,1.086280,-493.916473,982.000671,0.000000
130.510010,219.619324,-493.872009,-0.000880,0.004277,0.108628,976.915527,49.766453,1.086280,-493.872009,982.000671,0.000000
130.960007,219.612244,-493.960968,-0.000901,0.004277,0.108628,976.884033,49.764843,1.086280,-493.960968,982.000671,0.000000
131.410004,219.605530,-493.960968,-0.000897,0.004277,0.108628,976.854187,49.763325,1.086280,-493.960968,982.000671,0.000000
131.860001,219.585052,-493.960968,-0.000897,0.004277,0.108628,976.763123,49.758686,1.086280,-493.960968,982.000671,0.000000
132.310013,219.584686,-494.005432,-0.000892,0.004277,0.108628,976.761475,49.758598,1.086280,-494.005432,982.000671,0.000000
132.760010,219.559753,-494.049927,-0.000884,0.004277,0.108628,976.650574,49.752949,1.086280,-494.049927,982.000671,0.000000
133.210007,219.558990,-494.049927,-0.000888,0.004277,0.108628,976.647156,49.752777,1.086280,-494.049927,982.000671,0.000000
133.660004,219.541504,-494.049927,-0.000888,0.004277,0.108628,976.569397,49.748817,1.086280,-494.049927,982.000671,0.000000
134.110001,219.532928,-494.094391,-0.000888,0.004277,0.108628,976.531250,49.746872,1.086280,-494.094391,982.000671,0.000000
134.560013,219.514313,-494.094391,-0.000884,0.004277,0.108637,976.448425,49.742653,1.086371,-494.094391,982.000671,0.000000
135.010010,219.472595,-494.138885,-0.000888,0.004263,0.108274,976.262878,49.733200,1.082737,-494.138885,0.108395,0.000000
135.460007,219.324036,-494.183380,-0.000880,0.004246,0.107848,975.602051,49.699535,1.078483,-494.183380,0.107639,0.000000
135.910004,219.177673,-494.227844,-0.000871,0.004224,0.107293,974.950989,49.666370,1.072927,-494.227844,0.106895,0.000000
136.360001,217.950714,-494.227844,-0.000875,0.004195,0.106555,969.493225,49.388340,1.065554,-494.227844,0.106139,0.000000
136.810013,217.022034,-494.183380,-0.000849,0.004171,0.105941,965.362244,49.177895,1.059407,-494.183380,0.105394,0.000000
137.260010,216.546875,-494.361298,-0.000845,0.004150,0.105411,963.248596,49.070221,1.054108,-494.361298,0.104639,0.000000
137.710007,216.302979,-494.227844,-0.000845,0.004109,0.104362,962.163696,49.014957,1.043617,-494.227844,0.103894,0.000000
138.160004,215.948486,-494.316803,-0.000862,0.004078,0.103573,960.586853,48.934628,1.035729,-494.316803,0.103138,0.000000
138.610001,215.696381,-494.361298,-0.000849,0.004054,0.102975,959.465393,48.877499,1.029749,-494.361298,0.102394,0.000000
139.060013,215.212280,-494.361298,-0.000854,0.004031,0.102375,957.312012,48.767799,1.023754,-494.361298,0.101638,0.000000
139.510010,213.984222,-494.361298,-0.000862,0.004002,0.101647,951.849365,48.489517,1.016471,-494.361298,0.100893,0.000000
139.960007,213.062592,-494.405762,-0.000858,0.003969,0.100824,947.749756,48.280670,1.008235,-494.405762,0.100138,0.000000
140.410004,210.993683,-494.405762,-0.000880,0.003934,0.099914,938.546753,47.811852,0.999137,-494.405762,0.099393,0.000000
140.860001,209.279297,-494.405762,-0.000845,0.003912,0.099375,930.920776,47.423367,0.993747,-494.405762,0.098646,0.000000
141.310013,206.485382,-494.450256,-0.000858,0.003877,0.098481,918.492859,46.790257,0.984815,-494.450256,0.097893,0.000000
141.760010,203.999054,-494.494720,-0.000841,0.003854,0.097883,907.433105,46.226849,0.978834,-494.494720,0.097146,0.000000
142.210007,200.309937,-494.539215,-0.000854,0.003819,0.096990,891.023071,45.390881,0.969902,-494.539215,0.096392,0.000000
142.660004,197.939789,-494.494720,-0.000836,0.003798,0.096462,880.480164,44.853798,0.964618,-494.494720,0.095646,0.000000
143.110001,194.628662,-494.539215,-0.000845,0.003767,0.095690,865.751526,44.103489,0.956897,-494.539215,0.094892,0.000000
143.560013,191.534607,-494.583710,-0.000849,0.003736,0.094901,851.988464,43.402359,0.949009,-494.583710,0.094145,0.000000
144.010010,188.963013,-494.583710,-0.000849,0.003713,0.094310,840.549438,42.819630,0.943105,-494.583710,0.093392,0.000000
144.460007,185.471283,-494.539215,-0.000849,0.003679,0.093452,825.017456,42.028393,0.934521,-494.539215,0.092645,0.000000
144.910004,182.677002,-494.628174,-0.000858,0.003652,0.092759,812.587891,41.395199,0.927587,-494.628174,0.091891,0.000000
145.360001,178.899277,-494.628174,-0.000854,0.003618,0.091891,795.783752,40.539158,0.918912,-494.628174,0.091145,0.000000
145.810013,176.066635,-494.717133,-0.000849,0.003594,0.091293,783.183533,39.897270,0.912932,-494.717133,0.090391,0.000000
146.260010,171.755676,-494.717133,-0.000845,0.003558,0.090374,764.007385,38.920391,0.903742,-494.717133,0.089644,0.000000
146.710007,169.309189,-494.717133,-0.000854,0.003539,0.089888,753.124878,38.366013,0.898882,-494.717133,0.088891,0.000000
147.160004,164.978500,-494.717133,-0.000858,0.003501,0.088934,733.861023,37.384663,0.889344,-494.717133,0.088144,0.000000
147.610001,161.508743,-494.717133,-0.000858,0.003473,0.088214,718.426758,36.598404,0.882138,-494.717133,0.087390,0.000000
148.060013,157.133362,-494.717133,-0.000880,0.003434,0.087234,698.964111,35.606926,0.872343,-494.717133,0.086644,0.000000
148.510010,154.262741,-494.806091,-0.000892,0.003414,0.086704,686.194946,34.956436,0.867044,-494.806091,0.085890,0.000000
148.960007,150.824631,-494.806091,-0.000871,0.003385,0.085976,670.901489,34.177353,0.859762,-494.806091,0.085143,0.000000
149.410004,147.062546,-494.806091,-0.000875,0.003353,0.085162,654.166870,33.324848,0.851617,-494.806091,0.084390,0.000000
149.860001,144.088043,-494.850586,-0.000888,0.003328,0.084520,640.935608,32.650818,0.845197,-494.850586,0.083643,0.000000
150.310013,140.299149,-494.850586,-0.000892,0.003296,0.083713,624.081787,31.792242,0.837128,-494.850586,0.082889,0.000000
150.760010,137.023010,-494.895050,-0.000888,0.003264,0.082898,609.508789,31.049858,0.828983,-494.895050,0.082143,0.000000
151.210007,133.668686,-494.895050,-0.000884,0.003238,0.082238,594.588013,30.289757,0.822382,-494.895050,0.081389,0.000000
151.660004,130.120712,-494.939545,-0.000905,0.003208,0.081484,578.805847,29.485775,0.814842,-494.939545,0.080642,0.000000
152.110001,125.851089,-494.895050,-0.000910,0.003172,0.080565,559.813599,28.518265,0.805653,-494.895050,0.079889,0.000000
152.560013,123.260880,-494.895050,-0.000914,0.003150,0.080002,548.291748,27.931314,0.800021,-494.895050,0.079142,0.000000
153.010010,119.296967,-494.895050,-0.000914,0.003116,0.079135,530.659424,27.033079,0.791346,-494.895050,0.078388,0.000000
153.460007,116.454269,-494.895050,-0.000918,0.003091,0.078518,518.014465,26.388916,0.785184,-494.895050,0.077643,0.000000
153.910004,113.260071,-494.984009,-0.000923,0.003056,0.077634,503.805969,25.665098,0.776343,-494.984009,0.076888,0.000000
154.360001,109.952652,-494.984009,-0.000944,0.003034,0.077070,489.093811,24.915627,0.770695,-494.984009,0.076143,0.000000
154.810013,106.582687,-495.072998,-0.000931,0.003004,0.076290,474.103485,24.151981,0.762899,-495.072998,0.075388,0.000000
155.260010,102.540207,-495.072998,-0.000944,0.002968,0.075397,456.121613,23.235943,0.753966,-495.072998,0.074643,0.000000
155.710007,99.898590,-495.028503,-0.000949,0.002946,0.074824,444.371124,22.637344,0.748243,-495.028503,0.073887,0.000000
156.160004,96.508896,-495.028503,-0.000953,0.002918,0.074113,429.292999,21.869228,0.741128,-495.028503,0.073142,0.000000
156.610001,92.974335,-495.028503,-0.000944,0.002886,0.073298,413.570496,21.068285,0.732983,-495.028503,0.072387,0.000000
157.060013,89.641968,-495.072998,-0.000961,0.002856,0.072543,398.747375,20.313160,0.725428,-495.072998,0.071642,0.000000
157.510010,86.203857,-495.161957,-0.000957,0.002826,0.071780,383.453918,19.534073,0.717798,-495.161957,0.070887,0.000000
157.960007,82.444748,-495.161957,-0.000970,0.002794,0.070956,366.732544,18.682247,0.709562,-495.161957,0.070142,0.000000
158.410004,79.227081,-495.161957,-0.000974,0.002764,0.070202,352.419647,17.953114,0.702022,-495.161957,0.069386,0.000000
158.860001,78.085022,-495.206421,-0.000979,0.002755,0.069977,347.339539,17.694319,0.699767,-495.206421,0.068641,0.000000
159.310013,72.344528,-495.206421,-0.000979,0.002706,0.068728,321.804535,16.393505,0.687276,-495.206421,0.067886,0.000000
159.760010,69.816864,-495.206421,-0.000987,0.002685,0.068199,310.560913,15.820727,0.681993,-495.206421,0.067141,0.000000
160.210007,66.030579,-495.250916,-0.000987,0.002649,0.067279,293.718689,14.962744,0.672788,-495.250916,0.066395,0.000000
160.660004,63.701752,-495.250916,-0.000992,0.002630,0.066811,283.359558,14.435023,0.668110,-495.250916,0.065641,0.000000
161.110001,59.161049,-495.250916,-0.001000,0.002589,0.065762,263.161499,13.406085,0.657618,-495.250916,0.064894,0.000000
161.560013,56.287827,-495.295380,-0.000987,0.002564,0.065120,250.380753,12.755004,0.651199,-495.295380,0.064140,0.000000
162.010010,52.449783,-495.295380,-0.001009,0.002531,0.064278,233.308289,11.885290,0.642781,-495.295380,0.063394,0.000000
162.460007,49.998825,-495.339874,-0.001005,0.002508,0.063706,222.405884,11.329896,0.637058,-495.339874,0.062640,0.000000
162.910004,46.283295,-495.339874,-0.001030,0.002474,0.062831,205.878372,10.487945,0.628308,-495.339874,0.061894,0.000000
163.360001,43.098763,-495.339874,-0.001009,0.002444,0.062084,191.712875,9.766319,0.620844,-495.339874,0.061140,0.000000
163.810013,39.673309,-495.339874,-0.001026,0.002414,0.061321,176.475693,8.990100,0.613214,-495.339874,0.060393,0.000000
164.260010,36.790398,-495.384338,-0.001018,0.002387,0.060628,163.651855,8.336823,0.606280,-495.384338,0.059639,0.000000
164.710007,33.889992,-495.384338,-0.001030,0.002358,0.059882,150.750214,7.679582,0.598816,-495.384338,0.058893,0.000000
165.160004,30.053436,-495.428833,-0.001035,0.002326,0.059084,133.684357,6.810206,0.590837,-495.428833,0.058139,0.000000
165.610001,26.451111,-495.428833,-0.001043,0.002292,0.058225,117.660416,5.993907,0.582253,-495.428833,0.057393,0.000000
166.060013,24.247780,-495.428833,-0.001035,0.002274,0.057757,107.859512,5.494626,0.577575,-495.428833,0.056639,0.000000
166.510010,20.345314,-495.428833,-0.001052,0.002239,0.056864,90.500473,4.610314,0.568643,-495.428833,0.055892,0.000000
166.960007,16.928055,-495.428833,-0.001052,0.002205,0.056013,75.299751,3.835952,0.560134,-495.428833,0.055138,0.000000
167.410004,13.679848,-495.517792,-0.001056,0.002174,0.055208,60.851002,3.099898,0.552080,-495.517792,0.054392,0.000000
167.860001,11.104149,-495.562286,-0.001069,0.002152,0.054661,49.393723,2.516236,0.546615,-495.562286,0.053638,0.000000
168.310013,8.169479,-495.517792,-0.001074,0.002122,0.053906,36.339661,1.851231,0.539060,-495.517792,0.052892,0.000000
168.760010,5.094803,-495.562286,-0.001087,0.002097,0.053266,22.662815,1.154499,0.532656,-495.562286,0.052138,0.000000
169.210007,2.188438,-495.562286,-0.001078,0.002066,0.052475,9.734660,0.495907,0.524753,-495.562286,0.051391,0.000000
169.660004,-1.019180,-495.606750,-0.001091,0.002030,0.051565,-4.533540,-0.230950,0.515654,-495.606750,0.050637,0.000000
170.110001,-0.543663,-495.606750,-0.001095,0.002002,0.050863,-2.418334,-0.123196,0.508629,-495.606750,0.049891,0.000000
170.560013,-0.144104,-495.606750,-0.001121,0.001977,0.050221,-0.641007,-0.032654,0.502210,-495.606750,0.049137,0.000000
171.010010,-0.116554,-495.651245,-0.001125,0.001948,0.049467,-0.518459,-0.026412,0.494671,-495.651245,0.048391,0.000000
171.460007,-0.135544,-495.651245,-0.001160,0.001911,0.048539,-0.602929,-0.030715,0.485390,-495.651245,0.047637,0.000000
171.910004,-0.078941,-495.606750,-0.001177,0.001887,0.047932,-0.351149,-0.017888,0.479319,-495.606750,0.046890,0.000000
172.360001,-0.093834,-495.740204,-0.001164,0.001857,0.047169,-0.417394,-0.021263,0.471689,-495.740204,0.046136,0.000000
172.810013,-0.111336,-495.695709,-0.001216,0.001822,0.046276,-0.495246,-0.025229,0.462756,-495.695709,0.045390,0.000000
173.260010,-0.110222,-495.695709,-0.001207,0.001803,0.045790,-0.490291,-0.024977,0.457897,-495.695709,0.044636,0.000000
173.710007,-0.089737,-495.740204,-0.001216,0.001767,0.044871,-0.399170,-0.020335,0.448707,-495.740204,0.043890,0.000000
174.160004,-0.102776,-495.740204,-0.001233,0.001740,0.044203,-0.457169,-0.023289,0.442030,-495.740204,0.043136,0.000000
174.610016,-0.106499,-495.784668,-0.001255,0.001705,0.043301,-0.473730,-0.024133,0.433007,-495.784668,0.042389,0.000000
175.060013,-0.119530,-495.829163,-0.001255,0.001683,0.042754,-0.531695,-0.027086,0.427542,-495.829163,0.041635,0.000000
175.510010,-0.091232,-495.784668,-0.001272,0.001646,0.041800,-0.405822,-0.020674,0.418004,-495.784668,0.040889,0.000000
175.960007,-0.102776,-495.829163,-0.001289,0.001625,0.041263,-0.457169,-0.023289,0.412629,-495.829163,0.040135,0.000000
176.410004,-0.109100,-495.784668,-0.001315,0.001589,0.040352,-0.485303,-0.024722,0.403515,-495.784668,0.039389,0.000000
176.860016,-0.125114,-495.829163,-0.001319,0.001561,0.039649,-0.556537,-0.028351,0.396490,-495.829163,0.038635,0.000000
177.310013,-0.092346,-495.873657,-0.001341,0.001526,0.038748,-0.410776,-0.020926,0.387482,-495.873657,0.037888,0.000000
177.760010,-0.119904,-495.873657,-0.001367,0.001501,0.038123,-0.533358,-0.027171,0.381230,-495.873657,0.037134,0.000000
178.210007,-0.105011,-495.962616,-0.001375,0.001466,0.037239,-0.467112,-0.023796,0.372388,-495.962616,0.036388,0.000000
178.660004,-0.090111,-495.873657,-0.001393,0.001437,0.036511,-0.400833,-0.020419,0.365106,-495.873657,0.035634,0.000000
179.110016,-0.117668,-495.829163,-0.001423,0.001408,0.035764,-0.523414,-0.026664,0.357642,-495.829163,0.034888,0.000000
179.560013,-0.113197,-495.918121,-0.001427,0.001381,0.035087,-0.503527,-0.025651,0.350875,-495.918121,0.034134,0.000000
180.010010,-0.089737,-495.962616,-0.001436,0.001362,0.034585,-0.399170,-0.020335,0.345849,-495.962616,0.033389,0.000000
180.460007,-0.102402,-495.962616,-0.001466,0.001320,0.033518,-0.455506,-0.023205,0.335175,-495.962616,0.032642,0.000000
180.910004,-0.106873,-495.962616,-0.001475,0.001296,0.032910,-0.475393,-0.024218,0.329104,-495.962616,0.031888,0.000000
181.360016,-0.068512,-495.918121,-0.001509,0.001261,0.032035,-0.304756,-0.015525,0.320354,-495.918121,0.031142,0.000000
181.810013,-0.090858,-496.051575,-0.001500,0.001241,0.031524,-0.404159,-0.020589,0.315236,-496.051575,0.030388,0.000000
182.000015,-0.060692,-496.051575,-0.001505,0.001236,0.031384,-0.269971,-0.013753,0.313843,-496.051575,0.031298,0.000000