File: Data/sima compression 500bar/P2-17-500bar-2_11072024_171155.csv
Time (sec),S:Load (lbs),S:HL1 (DIM),S:LVDT (in),S:Position (in),Ch:Position (mm),Ch:Load (N),Ch:Stress (MPa),Ch:Strain (mm/mm),Ch:HL1 (DIM),Set Point (),Cycles ()
0.110000,-0.093094,-399.972717,-0.011141,-0.008265,-0.209939,-0.414102,-0.021095,-2.099391,-399.972717,-0.209809,0.000000
0.580000,-0.086388,-399.883759,-0.011132,-0.008179,-0.207753,-0.384271,-0.019576,-2.077529,-399.883759,-0.207259,0.000000
1.050000,-0.065910,-399.883759,-0.010951,-0.007902,-0.200711,-0.293184,-0.014935,-2.007115,-399.883759,-0.199437,0.000000
1.520000,-0.109100,-399.928223,-0.010611,-0.007581,-0.192559,-0.485303,-0.024722,-1.925588,-399.928223,-0.191597,0.000000
1.990000,-0.081917,-399.972717,-0.010305,-0.007274,-0.184763,-0.364384,-0.018563,-1.847634,-399.972717,-0.183775,0.000000
2.460000,-0.072235,-400.017181,-0.009998,-0.006962,-0.176845,-0.321318,-0.016369,-1.768454,-400.017181,-0.175936,0.000000
2.930000,-0.053619,-399.972717,-0.009658,-0.006654,-0.169023,-0.238511,-0.012150,-1.690228,-399.972717,-0.168113,0.000000
3.400000,-0.056969,-399.928223,-0.009365,-0.006353,-0.161374,-0.253409,-0.012909,-1.613743,-399.928223,-0.160272,0.000000
3.870000,-0.125862,-400.150635,-0.009058,-0.006041,-0.153440,-0.559863,-0.028521,-1.534396,-400.150635,-0.152451,0.000000
4.340000,-0.103142,-400.150635,-0.008739,-0.005745,-0.145929,-0.458798,-0.023372,-1.459289,-400.150635,-0.144628,0.000000
4.810000,-0.101280,-400.106140,-0.008403,-0.005429,-0.137899,-0.450517,-0.022950,-1.378989,-400.106140,-0.136788,0.000000
5.280000,-0.054367,-400.106140,-0.008067,-0.005118,-0.129988,-0.241837,-0.012320,-1.299884,-400.106140,-0.128967,0.000000
5.750000,-0.077827,-400.150635,-0.007752,-0.004805,-0.122054,-0.346194,-0.017636,-1.220538,-400.150635,-0.121126,0.000000
6.220000,-0.090485,-400.195129,-0.007442,-0.004499,-0.114275,-0.402496,-0.020504,-1.142751,-400.195129,-0.113303,0.000000
6.690001,-0.068146,-400.195129,-0.007153,-0.004201,-0.106696,-0.303127,-0.015442,-1.066962,-400.195129,-0.105464,0.000000
7.160000,-0.078941,-400.239594,-0.006808,-0.003889,-0.098769,-0.351149,-0.017888,-0.987691,-400.239594,-0.097641,0.000000
7.630001,-0.062927,-400.195129,-0.006502,-0.003586,-0.091077,-0.279914,-0.014260,-0.910767,-400.195129,-0.089802,0.000000
8.100000,-0.127724,-400.239594,-0.006178,-0.003269,-0.083038,-0.568143,-0.028943,-0.830376,-400.239594,-0.081979,0.000000
8.570001,-0.072235,-400.373047,-0.005872,-0.002957,-0.075120,-0.321318,-0.016369,-0.751196,-400.373047,-0.074157,0.000000
9.040000,-0.048409,-400.328552,-0.005549,-0.002655,-0.067436,-0.215332,-0.010970,-0.674362,-400.328552,-0.066317,0.000000
9.510000,-0.071495,-400.284088,-0.005217,-0.002343,-0.059502,-0.318026,-0.016201,-0.595016,-400.284088,-0.058495,0.000000
9.980000,-0.059952,-400.373047,-0.004911,-0.002051,-0.052095,-0.266679,-0.013585,-0.520953,-400.373047,-0.050656,0.000000
10.450001,-0.148575,-400.417511,-0.004587,-0.001728,-0.043891,-0.660894,-0.033668,-0.438912,-400.417511,-0.042833,0.000000
10.920000,-0.041702,-400.506470,-0.004277,-0.001426,-0.036208,-0.185501,-0.009450,-0.362078,-400.506470,-0.034994,0.000000
11.390000,-0.078941,-400.462006,-0.003958,-0.001110,-0.028204,-0.351149,-0.017888,-0.282035,-400.462006,-0.027171,0.000000
11.860001,-0.059952,-400.462006,-0.003635,-0.000802,-0.020381,-0.266679,-0.013585,-0.203809,-400.462006,-0.019332,0.000000
12.330001,-0.067024,-400.506470,-0.003311,-0.000494,-0.012549,-0.298139,-0.015188,-0.125492,-400.506470,-0.011509,0.000000
12.800000,-0.122879,-400.550964,-0.003022,-0.000188,-0.004770,-0.546593,-0.027845,-0.047705,-400.550964,-0.003686,0.000000
13.270000,0.105759,-400.595459,-0.002854,0.000002,0.000051,0.470438,0.023965,0.000515,-400.595459,0.000303,0.000000
13.740001,0.090858,-400.550964,-0.002854,0.000002,0.000051,0.404159,0.020589,0.000515,-400.550964,0.000598,0.000000
14.210001,0.213371,-400.595459,-0.002828,0.000020,0.000503,0.949123,0.048351,0.005026,-400.595459,0.001387,0.000000
14.680000,0.546272,-400.639923,-0.002824,0.000049,0.001248,2.429940,0.123787,0.012475,-400.639923,0.002168,0.000000
15.150001,1.136482,-400.684418,-0.002798,0.000080,0.002020,5.055326,0.257531,0.020196,-400.684418,0.002948,0.000000
15.620001,2.257324,-400.728882,-0.002764,0.000118,0.002992,10.041080,0.511517,0.029916,-400.728882,0.003736,0.000000
16.090000,3.104469,-400.728882,-0.002734,0.000141,0.003581,13.809369,0.703483,0.035805,-400.728882,0.004518,0.000000
16.560001,3.558762,-400.684418,-0.002729,0.000157,0.003997,15.830162,0.806427,0.039968,-400.684418,0.005297,0.000000
17.030001,5.636230,-400.728882,-0.002703,0.000206,0.005220,25.071205,1.277188,0.052201,-400.728882,0.006088,0.000000
17.500000,6.974907,-400.817841,-0.002699,0.000234,0.005948,31.025936,1.580537,0.059483,-400.817841,0.006867,0.000000
17.970001,8.297203,-400.773376,-0.002665,0.000263,0.006669,36.907803,1.880173,0.066690,-400.773376,0.007649,0.000000
18.440001,9.363678,-400.817841,-0.002652,0.000291,0.007379,41.651718,2.121840,0.073790,-400.817841,0.008437,0.000000
18.910002,11.630684,-400.862335,-0.002621,0.000329,0.008351,51.735867,2.635551,0.083510,-400.862335,0.009218,0.000000
19.380001,13.091125,-400.862335,-0.002621,0.000358,0.009096,58.232235,2.966491,0.090959,-400.862335,0.009998,0.000000
19.850000,14.646530,-400.906799,-0.002600,0.000388,0.009851,65.151016,3.318951,0.098513,-400.906799,0.010787,0.000000
20.320002,15.643372,-400.951294,-0.002574,0.000409,0.010398,69.585190,3.544839,0.103979,-400.951294,0.011568,0.000000
20.790001,17.847069,-400.951294,-0.002552,0.000449,0.011394,79.387726,4.044204,0.113940,-400.951294,0.012349,0.000000
21.260000,19.062866,-400.995789,-0.002531,0.000477,0.012115,84.795860,4.319707,0.121147,-400.995789,0.013138,0.000000
21.730001,21.002922,-400.951294,-0.002522,0.000513,0.013034,93.425667,4.759330,0.130337,-400.951294,0.013918,0.000000
22.200001,21.670593,-401.084747,-0.002522,0.000532,0.013520,96.395615,4.910627,0.135196,-401.084747,0.014699,0.000000
22.670002,24.232513,-401.040253,-0.002483,0.000578,0.014681,107.791603,5.491166,0.146809,-401.040253,0.015488,0.000000
23.140001,25.385002,-401.084747,-0.002475,0.000606,0.015392,112.918129,5.752324,0.153924,-401.084747,0.016269,0.000000
23.610001,26.891624,-401.084747,-0.002458,0.000638,0.016216,119.619919,6.093729,0.162160,-401.084747,0.017049,0.000000
24.080002,27.500824,-401.129211,-0.002432,0.000658,0.016711,122.329773,6.231776,0.167111,-401.129211,0.017837,0.000000
24.550001,29.847885,-401.218170,-0.002410,0.000702,0.017821,132.770020,6.763628,0.178208,-401.218170,0.018619,0.000000
25.020000,30.667107,-401.218170,-0.002380,0.000729,0.018507,136.414108,6.949265,0.185066,-401.218170,0.019400,0.000000
25.490002,32.003555,-401.173706,-0.002350,0.000761,0.019321,142.358917,7.252109,0.193211,-401.173706,0.020189,0.000000
25.960001,32.741966,-401.218170,-0.002345,0.000785,0.019937,145.643539,7.419436,0.199373,-401.218170,0.020968,0.000000
26.430000,34.580368,-401.262665,-0.002328,0.000825,0.020943,153.821167,7.836024,0.209426,-401.262665,0.021750,0.000000
26.900002,34.946411,-401.307129,-0.002298,0.000847,0.021515,155.449402,7.918970,0.215149,-401.307129,0.022538,0.000000
27.370001,36.354355,-401.218170,-0.002255,0.000883,0.022434,161.712250,8.238014,0.224338,-401.218170,0.023319,0.000000
27.840002,37.088669,-401.262665,-0.002259,0.000910,0.023111,164.978638,8.404412,0.231106,-401.262665,0.024099,0.000000
28.310001,38.453415,-401.307129,-0.002242,0.000945,0.024013,171.049332,8.713668,0.240129,-401.307129,0.024889,0.000000
28.780001,38.967293,-401.440582,-0.002199,0.000972,0.024681,173.335175,8.830115,0.246805,-401.440582,0.025669,0.000000
29.250002,40.188301,-401.440582,-0.002186,0.001007,0.025574,178.766495,9.106799,0.255738,-401.440582,0.026450,0.000000
29.720001,40.740898,-401.396088,-0.002156,0.001034,0.026276,181.224564,9.232019,0.262763,-401.396088,0.027239,0.000000
30.190001,42.119423,-401.351624,-0.002143,0.001070,0.027179,187.356552,9.544397,0.271786,-401.351624,0.028019,0.000000
30.660002,42.463120,-401.440582,-0.002117,0.001096,0.027828,188.885391,9.622280,0.278281,-401.440582,0.028800,0.000000
31.130001,43.458847,-401.529541,-0.002108,0.001129,0.028686,193.314606,9.847916,0.286865,-401.529541,0.029589,0.000000
31.600002,43.795845,-401.529541,-0.002074,0.001152,0.029268,194.813644,9.924280,0.292678,-401.529541,0.030370,0.000000
32.070000,45.201920,-401.485077,-0.002057,0.001191,0.030249,201.068176,10.242902,0.302489,-401.485077,0.031150,0.000000
32.540001,46.082581,-401.529541,-0.002031,0.001220,0.030994,204.985550,10.442462,0.309937,-401.529541,0.031940,0.000000
33.010002,46.265793,-401.574036,-0.002026,0.001245,0.031636,205.800522,10.483978,0.316357,-401.574036,0.032720,0.000000
33.480003,47.645432,-401.662994,-0.002001,0.001280,0.032512,211.937469,10.796609,0.325122,-401.662994,0.033501,0.000000
33.950001,47.395943,-401.662994,-0.001979,0.001298,0.032971,210.827682,10.740074,0.329710,-401.662994,0.034290,0.000000
34.420002,50.032341,-401.618500,-0.001944,0.001348,0.034229,222.554962,11.337491,0.342291,-401.618500,0.035069,0.000000
34.890003,50.373062,-401.707458,-0.001923,0.001373,0.034879,224.070572,11.414700,0.348786,-401.707458,0.035851,0.000000
35.360001,51.648064,-401.707458,-0.001910,0.001406,0.035711,229.742065,11.703619,0.357112,-401.707458,0.036639,0.000000
35.830002,51.471558,-401.707458,-0.001871,0.001426,0.036215,228.956924,11.663622,0.362154,-401.707458,0.037421,0.000000
36.300003,53.711754,-401.751953,-0.001863,0.001470,0.037342,238.921814,12.171258,0.373418,-401.751953,0.038200,0.000000
36.770000,53.992516,-401.751953,-0.001828,0.001493,0.037923,240.170700,12.234879,0.379231,-401.751953,0.038990,0.000000
37.240002,55.578827,-401.796417,-0.001815,0.001531,0.038886,247.226974,12.594341,0.388860,-401.796417,0.039770,0.000000
37.710003,55.411629,-401.796417,-0.001807,0.001549,0.039354,246.483231,12.556455,0.393538,-401.796417,0.040551,0.000000
38.180000,56.850479,-401.840912,-0.001772,0.001589,0.040368,252.883560,12.882503,0.403682,-401.840912,0.041340,0.000000
38.650002,57.911369,-401.840912,-0.001750,0.001617,0.041063,257.602631,13.122904,0.410631,-401.840912,0.042120,0.000000
39.120003,59.700615,-401.885406,-0.001738,0.001654,0.042017,265.561584,13.528353,0.420169,-401.885406,0.042901,0.000000
39.590000,59.767273,-401.929871,-0.001720,0.001674,0.042520,265.858093,13.543458,0.425195,-401.929871,0.043690,0.000000
40.060001,61.807129,-401.974365,-0.001699,0.001714,0.043534,274.931854,14.005695,0.435339,-401.974365,0.044471,0.000000
40.530003,62.802483,-401.974365,-0.001707,0.001744,0.044306,279.359406,14.231246,0.443060,-401.974365,0.045251,0.000000
41.000004,64.419693,-401.974365,-0.001660,0.001779,0.045190,286.553101,14.597712,0.451901,-401.974365,0.046041,0.000000
41.470001,64.780899,-401.974365,-0.001664,0.001800,0.045720,288.159821,14.679562,0.457200,-401.974365,0.046821,0.000000
41.940002,66.417099,-402.018829,-0.001634,0.001838,0.046674,295.438019,15.050330,0.466738,-402.018829,0.047602,0.000000
42.410004,67.802322,-402.107788,-0.001617,0.001868,0.047437,301.599792,15.364226,0.474368,-402.107788,0.048391,0.000000
42.880001,69.494751,-402.063324,-0.001608,0.001901,0.048286,309.128082,15.747736,0.482862,-402.063324,0.049170,0.000000
43.350002,70.494583,-402.152283,-0.001595,0.001926,0.048928,313.575562,15.974301,0.489281,-402.152283,0.049952,0.000000
43.820004,72.433517,-402.152283,-0.001591,0.001963,0.049873,322.200378,16.413670,0.498728,-402.152283,0.050740,0.000000
44.290001,73.021118,-402.241241,-0.001587,0.001985,0.050419,324.814148,16.546822,0.504193,-402.241241,0.051522,0.000000
44.760002,75.079971,-402.196747,-0.001548,0.002022,0.051366,333.972382,17.013365,0.513656,-402.196747,0.052301,0.000000
45.230003,76.513229,-402.241241,-0.001556,0.002053,0.052154,340.347839,17.338146,0.521543,-402.241241,0.053091,0.000000
45.700001,77.496292,-402.152283,-0.001522,0.002083,0.052901,344.720734,17.560911,0.529007,-402.152283,0.053871,0.000000
46.170002,79.142929,-402.285736,-0.001522,0.002110,0.053603,352.045319,17.934044,0.536032,-402.285736,0.054652,0.000000
46.640003,80.603378,-402.374695,-0.001513,0.002140,0.054366,358.541748,18.264986,0.543662,-402.374695,0.055441,0.000000
47.110001,82.479385,-402.330200,-0.001505,0.002176,0.055276,366.886627,18.690096,0.552761,-402.330200,0.056222,0.000000
47.580002,83.824768,-402.330200,-0.001470,0.002203,0.055962,372.871185,18.994965,0.559619,-402.330200,0.057002,0.000000
48.050003,85.989746,-402.419159,-0.001470,0.002236,0.056802,382.501495,19.485556,0.568022,-402.419159,0.057791,0.000000
48.520000,87.519821,-402.419159,-0.001462,0.002268,0.057609,389.307617,19.832273,0.576091,-402.419159,0.058572,0.000000
48.990002,89.122131,-402.552612,-0.001449,0.002295,0.058303,396.435028,20.195364,0.583025,-402.552612,0.059352,0.000000
49.460003,90.535294,-402.508118,-0.001449,0.002326,0.059084,402.721100,20.515593,0.590837,-402.508118,0.060142,0.000000
49.930004,92.743454,-402.508118,-0.001423,0.002361,0.059977,412.543488,21.015966,0.599770,-402.508118,0.060922,0.000000
50.400002,94.301834,-402.463654,-0.001418,0.002391,0.060722,419.475494,21.369101,0.607218,-402.463654,0.061703,0.000000
50.870003,96.164810,-402.508118,-0.001414,0.002419,0.061442,427.762451,21.791258,0.614425,-402.508118,0.062492,0.000000
51.340004,97.366837,-402.552612,-0.001388,0.002446,0.062136,433.109314,22.063641,0.621359,-402.552612,0.063273,0.000000
51.810001,100.190170,-402.597076,-0.001384,0.002485,0.063108,445.668121,22.703417,0.631078,-402.597076,0.064053,0.000000
52.280003,101.719131,-402.641571,-0.001362,0.002514,0.063853,452.469299,23.049885,0.638527,-402.641571,0.064841,0.000000
52.750004,103.871445,-402.552612,-0.001358,0.002545,0.064651,462.043274,23.537607,0.646505,-402.552612,0.065623,0.000000
53.220001,104.955780,-402.730530,-0.001354,0.002570,0.065267,466.866638,23.783319,0.652667,-402.730530,0.066402,0.000000
53.690002,107.933273,-402.686035,-0.001350,0.002609,0.066281,480.111176,24.458029,0.662811,-402.686035,0.067192,0.000000
54.160004,109.450317,-402.641571,-0.001319,0.002636,0.066949,486.859314,24.801798,0.669487,-402.641571,0.067972,0.000000
54.630001,111.918777,-402.730530,-0.001328,0.002671,0.067834,497.839600,25.361156,0.678344,-402.730530,0.068753,0.000000
55.100002,113.056381,-402.730530,-0.001328,0.002690,0.068328,502.899902,25.618940,0.683280,-402.730530,0.069542,0.000000
55.570004,116.091217,-402.775024,-0.001311,0.002732,0.069386,516.399536,26.306646,0.693862,-402.775024,0.070323,0.000000
56.040001,117.311478,-402.908447,-0.001285,0.002754,0.069949,521.827515,26.583160,0.699494,-402.908447,0.071103,0.000000
56.510002,120.442383,-402.908447,-0.001298,0.002794,0.070956,535.754456,27.292635,0.709562,-402.908447,0.071892,0.000000
56.980003,122.047318,-402.819489,-0.001276,0.002817,0.071545,542.893555,27.656317,0.715451,-402.819489,0.072673,0.000000
57.450005,124.030197,-402.863983,-0.001272,0.002849,0.072352,551.713867,28.105644,0.723521,-402.863983,0.073453,0.000000
57.920002,126.113617,-402.952942,-0.001272,0.002877,0.073080,560.981384,28.577755,0.730803,-402.952942,0.074243,0.000000
58.390003,129.396454,-402.997406,-0.001246,0.002918,0.074122,575.584167,29.321657,0.741219,-402.997406,0.075023,0.000000
58.860004,130.936584,-403.041901,-0.001242,0.002943,0.074746,582.434998,29.670654,0.747456,-403.041901,0.075804,0.000000
59.330002,133.289978,-402.908447,-0.001250,0.002976,0.075578,592.903442,30.203939,0.755783,-402.908447,0.076593,0.000000
59.800003,135.307495,-402.997406,-0.001212,0.003003,0.076281,601.877808,30.661116,0.762808,-402.997406,0.077374,0.000000
60.270004,137.520508,-403.086365,-0.001233,0.003037,0.077139,611.721741,31.162592,0.771392,-403.086365,0.078154,0.000000
60.740002,139.796448,-403.086365,-0.001212,0.003065,0.077842,621.845642,31.678328,0.778417,-403.086365,0.078942,0.000000
61.210003,142.113724,-403.086365,-0.001190,0.003097,0.078674,632.153442,32.203430,0.786743,-403.086365,0.079724,0.000000
61.680004,144.340881,-403.130859,-0.001190,0.003126,0.079403,642.060303,32.708111,0.794026,-403.130859,0.080503,0.000000
62.150002,146.800766,-403.175354,-0.001199,0.003157,0.080200,653.002441,33.265530,0.802004,-403.175354,0.081293,0.000000
62.620003,149.269592,-403.219818,-0.001181,0.003187,0.080947,663.984314,33.824974,0.809468,-403.219818,0.082073,0.000000
63.090004,150.578110,-403.219818,-0.001173,0.003207,0.081449,669.804871,34.121487,0.814494,-403.219818,0.082854,0.000000
63.560001,153.888885,-403.219818,-0.001147,0.003246,0.082455,684.531921,34.871719,0.824547,-403.219818,0.083643,0.000000
64.030006,155.866547,-403.175354,-0.001147,0.003273,0.083122,693.329041,35.319866,0.831223,-403.175354,0.084424,0.000000
64.500000,159.099487,-403.219818,-0.001143,0.003311,0.084111,707.709839,36.052460,0.841110,-403.219818,0.085204,0.000000
64.970001,160.257935,-403.308777,-0.001125,0.003329,0.084562,712.862915,36.314968,0.845621,-403.308777,0.085993,0.000000
65.440002,164.405792,-403.353271,-0.001138,0.003377,0.085776,731.313477,37.254887,0.857763,-403.353271,0.086774,0.000000
65.910004,166.542099,-403.308777,-0.001112,0.003406,0.086505,740.816284,37.738979,0.865045,-403.308777,0.087554,0.000000
66.380005,168.918198,-403.353271,-0.001121,0.003435,0.087260,751.385681,38.277412,0.872600,-403.353271,0.088344,0.000000
66.850006,170.460205,-403.353271,-0.001112,0.003455,0.087763,758.244873,38.626831,0.877626,-403.353271,0.089124,0.000000
67.320000,174.275162,-403.442230,-0.001091,0.003500,0.088891,775.214661,39.491318,0.888905,-403.442230,0.089905,0.000000
67.790001,176.345551,-403.397736,-0.001078,0.003527,0.089593,784.424194,39.960476,0.895930,-403.397736,0.090694,0.000000
68.260002,179.130890,-403.442230,-0.001069,0.003560,0.090417,796.813965,40.591637,0.904166,-403.442230,0.091475,0.000000
68.730003,180.979355,-403.442230,-0.001087,0.003582,0.090980,805.036377,41.010509,0.909798,-403.442230,0.092255,0.000000
69.200005,184.418213,-403.442230,-0.001091,0.003623,0.092029,820.333191,41.789764,0.920290,-403.442230,0.093043,0.000000
69.670006,186.120697,-403.575684,-0.001061,0.003644,0.092566,827.906189,42.175552,0.925664,-403.575684,0.093825,0.000000
70.140007,189.450073,-403.620148,-0.001048,0.003682,0.093529,842.716003,42.930000,0.935293,-403.620148,0.094606,0.000000
70.610001,191.427002,-403.531189,-0.001039,0.003706,0.094136,851.509827,43.377979,0.941364,-403.531189,0.095394,0.000000
71.080002,194.283478,-403.620148,-0.001035,0.003743,0.095064,864.216064,44.025265,0.950644,-403.620148,0.096174,0.000000
71.550003,196.699066,-403.575684,-0.001043,0.003769,0.095723,874.961121,44.572643,0.957230,-403.575684,0.096955,0.000000
72.020004,199.869049,-403.664642,-0.001030,0.003805,0.096644,889.061951,45.290974,0.966435,-403.664642,0.097744,0.000000
72.490005,201.629639,-403.709106,-0.001018,0.003830,0.097285,896.893433,45.689930,0.972854,-403.709106,0.098525,0.000000
72.960007,205.403259,-403.709106,-0.001013,0.003868,0.098239,913.679321,46.545044,0.982392,-403.709106,0.099305,0.000000
73.430000,207.616638,-403.709106,-0.001005,0.003893,0.098872,923.524902,47.046600,0.988721,-403.709106,0.100094,0.000000
73.900002,210.505890,-403.753601,-0.001009,0.003927,0.099740,936.376953,47.701317,0.997396,-403.753601,0.100875,0.000000
74.370003,212.678680,-403.842560,-0.001013,0.003949,0.100294,946.041992,48.193680,1.002937,-403.842560,0.101656,0.000000
74.840004,215.844940,-403.798065,-0.000992,0.003988,0.101300,960.126221,48.911163,1.013004,-403.798065,0.102445,0.000000
75.310005,218.790802,-403.798065,-0.000983,0.004017,0.102038,973.230103,49.578705,1.020377,-403.798065,0.103225,0.000000
75.780006,220.693604,-403.887024,-0.000996,0.004042,0.102678,981.694153,50.009884,1.026781,-403.887024,0.104006,0.000000
76.250000,220.144379,-403.842560,-0.000979,0.004023,0.102185,979.251099,49.885429,1.021846,-403.842560,982.000671,0.000000
76.720001,219.473358,-403.975983,-0.000983,0.004036,0.102522,976.266235,49.733372,1.025222,-403.975983,982.000671,0.000000
77.190002,219.787628,-403.975983,-0.000949,0.004047,0.102801,977.664185,49.804588,1.028008,-403.975983,982.000671,0.000000
77.660004,220.154419,-404.020477,-0.000940,0.004058,0.103061,979.295776,49.887703,1.030612,-404.020477,982.000671,0.000000
78.130005,219.707581,-403.931519,-0.000961,0.004056,0.103017,977.308105,49.786449,1.030173,-403.931519,982.000671,0.000000
78.600006,220.018127,-403.975983,-0.000953,0.004064,0.103234,978.689514,49.856823,1.032338,-403.975983,982.000671,0.000000
79.070007,219.604431,-404.064972,-0.000949,0.004066,0.103269,976.849304,49.763073,1.032686,-404.064972,982.000671,0.000000
79.540001,219.533295,-404.064972,-0.000957,0.004070,0.103381,976.532837,49.746956,1.033806,-404.064972,982.000671,0.000000
80.010002,219.474091,-404.153931,-0.000944,0.004074,0.103468,976.269531,49.733540,1.034684,-404.153931,982.000671,0.000000
80.480003,219.497192,-404.109436,-0.000949,0.004078,0.103580,976.372253,49.738773,1.035805,-404.109436,982.000671,0.000000
80.950005,219.693420,-404.109436,-0.000940,0.004084,0.103736,977.245117,49.783241,1.037364,-404.109436,982.000671,0.000000
81.420006,219.544098,-404.198395,-0.000953,0.004087,0.103815,976.580933,49.749405,1.038151,-404.198395,982.000671,0.000000
81.890007,219.386230,-404.242889,-0.000940,0.004088,0.103841,975.878662,49.713631,1.038409,-404.242889,982.000671,0.000000
82.360001,219.312103,-404.242889,-0.000944,0.004092,0.103936,975.548950,49.696835,1.039362,-404.242889,982.000671,0.000000
82.830002,219.026520,-404.242889,-0.000936,0.004093,0.103954,974.278625,49.632122,1.039544,-404.242889,982.000671,0.000000
83.300003,219.086456,-404.242889,-0.000931,0.004097,0.104076,974.545227,49.645699,1.040755,-404.242889,982.000671,0.000000
83.770004,221.419739,-404.376312,-0.000923,0.004124,0.104743,984.924194,50.174431,1.047432,-404.376312,982.000671,0.000000
84.240005,219.996918,-404.331848,-0.000897,0.004070,0.103373,978.595154,49.852016,1.033731,-404.331848,982.000671,0.000000
84.710007,219.733643,-404.376312,-0.000901,0.004084,0.103736,977.424072,49.792355,1.037364,-404.376312,982.000671,0.000000
85.180000,219.436859,-404.376312,-0.000897,0.004092,0.103927,976.103882,49.725101,1.039272,-404.376312,982.000671,0.000000
85.650002,220.666443,-404.420807,-0.000888,0.004123,0.104717,981.573364,50.003731,1.047174,-404.420807,982.000671,0.000000
86.120003,220.289215,-404.509766,-0.000905,0.004109,0.104378,979.895386,49.918251,1.043783,-404.509766,982.000671,0.000000
86.590004,219.937714,-404.465302,-0.000901,0.004110,0.104387,978.331787,49.838600,1.043874,-404.465302,982.000671,0.000000
87.060005,219.604797,-404.465302,-0.000892,0.004119,0.104630,976.850952,49.763161,1.046296,-404.465302,982.000671,0.000000
87.530006,219.845337,-404.465302,-0.000884,0.004128,0.104855,977.920898,49.817665,1.048552,-404.465302,982.000671,0.000000
88.000008,219.656189,-404.509766,-0.000888,0.004128,0.104855,977.079529,49.774803,1.048552,-404.509766,982.000671,0.000000
88.470001,219.516907,-404.554260,-0.000888,0.004132,0.104943,976.459961,49.743240,1.049430,-404.554260,982.000671,0.000000
88.940002,219.801788,-404.598724,-0.000875,0.004135,0.105038,977.727173,49.807796,1.050384,-404.598724,982.000671,0.000000
89.410004,219.692322,-404.598724,-0.000875,0.004138,0.105099,977.240234,49.782993,1.050990,-404.598724,982.000671,0.000000
89.880005,219.664001,-404.598724,-0.000884,0.004140,0.105167,977.114258,49.776573,1.051671,-404.598724,982.000671,0.000000
90.350006,219.702362,-404.598724,-0.000888,0.004143,0.105237,977.284912,49.785263,1.052367,-404.598724,982.000671,0.000000
90.820007,219.681519,-404.732178,-0.000880,0.004145,0.105272,977.192200,49.780544,1.052716,-404.732178,982.000671,0.000000
91.290001,219.534058,-404.732178,-0.000892,0.004145,0.105272,976.536255,49.747128,1.052716,-404.732178,982.000671,0.000000
91.760002,219.633087,-404.821136,-0.000875,0.004149,0.105376,976.976746,49.769569,1.053760,-404.821136,982.000671,0.000000
92.230003,219.513580,-404.732178,-0.000892,0.004149,0.105376,976.445190,49.742489,1.053760,-404.732178,982.000671,0.000000
92.700005,219.521759,-404.776642,-0.000892,0.004151,0.105446,976.481567,49.744343,1.054457,-404.776642,982.000671,0.000000
93.170006,219.360138,-404.776642,-0.000871,0.004153,0.105497,975.762634,49.707718,1.054971,-404.776642,982.000671,0.000000
93.640007,219.829346,-404.910095,-0.000875,0.004158,0.105618,977.849792,49.814041,1.056183,-404.910095,982.000671,0.000000
94.110008,219.694916,-404.821136,-0.000867,0.004158,0.105618,977.251770,49.783581,1.056183,-404.821136,982.000671,0.000000
94.580002,219.567932,-404.865631,-0.000880,0.004159,0.105646,976.686951,49.754803,1.056455,-404.865631,982.000671,0.000000
95.050003,219.446533,-404.865631,-0.000875,0.004160,0.105662,976.146912,49.727295,1.056622,-404.865631,982.000671,0.000000
95.520004,219.491211,-404.999054,-0.000888,0.004163,0.105732,976.345642,49.737419,1.057318,-404.999054,982.000671,0.000000
95.990005,219.541870,-404.954590,-0.000867,0.004165,0.105783,976.570984,49.748898,1.057833,-404.954590,982.000671,0.000000
96.460007,219.507599,-404.954590,-0.000867,0.004166,0.105818,976.418579,49.741135,1.058181,-404.954590,982.000671,0.000000
96.930008,219.499786,-404.999054,-0.000871,0.004168,0.105862,976.383789,49.739361,1.058620,-404.999054,982.000671,0.000000
97.400002,219.423462,-405.043549,-0.000892,0.004168,0.105879,976.044312,49.722069,1.058787,-405.043549,982.000671,0.000000
97.870003,219.595123,-405.043549,-0.000880,0.004172,0.105957,976.807922,49.760967,1.059574,-405.043549,982.000671,0.000000
98.340004,219.505737,-405.088013,-0.000871,0.004172,0.105965,976.410278,49.740711,1.059649,-405.088013,982.000671,0.000000
98.810005,219.691559,-405.043549,-0.000862,0.004176,0.106060,977.236877,49.782822,1.060603,-405.043549,982.000671,0.000000
99.280006,219.599213,-405.088013,-0.000862,0.004176,0.106060,976.826111,49.761894,1.060603,-405.088013,982.000671,0.000000
99.750008,219.735504,-405.176971,-0.000867,0.004180,0.106174,977.432312,49.792774,1.061739,-405.176971,982.000671,0.000000
100.220001,219.745544,-405.221466,-0.000858,0.004180,0.106174,977.476990,49.795052,1.061739,-405.221466,982.000671,0.000000
100.690002,219.673676,-405.176971,-0.000867,0.004181,0.106209,977.157288,49.778767,1.062087,-405.176971,982.000671,0.000000
101.160004,219.679260,-405.221466,-0.000867,0.004182,0.106234,977.182129,49.780029,1.062344,-405.221466,982.000671,0.000000
101.630005,219.655060,-405.221466,-0.000854,0.004184,0.106269,977.074524,49.774548,1.062693,-405.221466,982.000671,0.000000
102.100006,219.653198,-405.265930,-0.000862,0.004185,0.106304,977.066223,49.774128,1.063041,-405.265930,982.000671,0.000000
102.570007,219.657318,-405.354919,-0.000849,0.004187,0.106348,977.084534,49.775059,1.063480,-405.354919,982.000671,0.000000
103.040009,219.646515,-405.354919,-0.000854,0.004188,0.106374,977.036499,49.772610,1.063737,-405.354919,982.000671,0.000000
103.510002,219.638672,-405.310425,-0.000867,0.004188,0.106381,977.001587,49.770836,1.063813,-405.310425,982.000671,0.000000
103.980003,219.677032,-405.310425,-0.000858,0.004189,0.106409,977.172241,49.779526,1.064085,-405.310425,982.000671,0.000000
104.450005,219.661041,-405.310425,-0.000854,0.004191,0.106451,977.101135,49.775906,1.064509,-405.310425,982.000671,0.000000
104.920006,219.646881,-405.488342,-0.000871,0.004192,0.106469,977.038147,49.772697,1.064691,-405.488342,982.000671,0.000000
105.390007,219.642029,-405.488342,-0.000854,0.004193,0.106504,977.016541,49.771595,1.065039,-405.488342,982.000671,0.000000
105.860008,219.634216,-405.443878,-0.000849,0.004194,0.106530,976.981812,49.769825,1.065297,-405.443878,982.000671,0.000000
106.330002,219.634583,-405.399384,-0.000858,0.004195,0.106564,976.983398,49.769905,1.065645,-405.399384,982.000671,0.000000
106.800003,219.607391,-405.443878,-0.000867,0.004196,0.106572,976.862488,49.763748,1.065720,-405.443878,982.000671,0.000000
107.270004,219.612244,-405.532837,-0.000871,0.004197,0.106616,976.884033,49.764843,1.066159,-405.532837,982.000671,0.000000
107.740005,219.604797,-405.577301,-0.000858,0.004198,0.106634,976.850952,49.763161,1.066341,-405.577301,982.000671,0.000000
108.210007,219.583954,-405.577301,-0.000836,0.004199,0.106651,976.758240,49.758434,1.066508,-405.577301,982.000671,0.000000
108.680008,219.594757,-405.532837,-0.000845,0.004201,0.106702,976.806274,49.760883,1.067022,-405.532837,982.000671,0.000000
109.150002,219.592133,-405.621796,-0.000854,0.004201,0.106702,976.794617,49.760288,1.067022,-405.621796,982.000671,0.000000
109.620003,219.557129,-405.621796,-0.000854,0.004201,0.106711,976.638916,49.752357,1.067113,-405.621796,982.000671,0.000000
110.090004,219.487122,-405.710754,-0.000854,0.004202,0.106729,976.327454,49.736496,1.067295,-405.710754,982.000671,0.000000
110.560005,219.471497,-405.755249,-0.000836,0.004203,0.106755,976.257996,49.732952,1.067552,-405.755249,982.000671,0.000000
111.030006,219.429047,-405.710754,-0.000845,0.004204,0.106772,976.069153,49.723335,1.067719,-405.710754,982.000671,0.000000
111.500008,219.458466,-405.755249,-0.000841,0.004204,0.106790,976.200012,49.730000,1.067901,-405.755249,982.000671,0.000000
111.970009,219.575378,-405.844208,-0.000849,0.004207,0.106858,976.720093,49.756493,1.068582,-405.844208,982.000671,0.000000
112.440002,219.551178,-405.799713,-0.000836,0.004207,0.106858,976.612427,49.751007,1.068582,-405.799713,982.000671,0.000000
112.910004,219.529205,-405.799713,-0.000854,0.004208,0.106885,976.514648,49.746029,1.068854,-405.799713,982.000671,0.000000
113.380005,219.624908,-405.844208,-0.000819,0.004210,0.106928,976.940369,49.767715,1.069278,-405.844208,982.000671,0.000000
113.850006,219.573883,-405.844208,-0.000849,0.004210,0.106928,976.713440,49.756153,1.069278,-405.844208,982.000671,0.000000
114.320007,219.553040,-405.888672,-0.000841,0.004210,0.106946,976.620667,49.751431,1.069460,-405.888672,982.000671,0.000000
114.790009,219.518402,-405.977631,-0.000832,0.004211,0.106972,976.466614,49.743584,1.069717,-405.977631,982.000671,0.000000
115.260002,219.534790,-405.977631,-0.000836,0.004212,0.106988,976.539490,49.747295,1.069884,-405.977631,982.000671,0.000000
115.730003,219.550446,-405.933167,-0.000841,0.004214,0.107023,976.609131,49.750843,1.070232,-405.933167,982.000671,0.000000
116.200005,219.568298,-406.022125,-0.000845,0.004214,0.107041,976.688599,49.754890,1.070414,-406.022125,982.000671,0.000000
116.670006,219.536285,-406.066589,-0.000849,0.004214,0.107041,976.546143,49.747635,1.070414,-406.066589,982.000671,0.000000
117.140007,219.517303,-406.066589,-0.000836,0.004215,0.107067,976.461731,49.743332,1.070671,-406.066589,982.000671,0.000000
117.610008,219.485626,-406.066589,-0.000828,0.004215,0.107067,976.320801,49.736153,1.070671,-406.066589,982.000671,0.000000
118.080002,219.447296,-406.111084,-0.000832,0.004215,0.107067,976.150330,49.727467,1.070671,-406.111084,982.000671,0.000000
118.550003,219.379517,-406.155579,-0.000836,0.004215,0.107067,975.848816,49.712109,1.070671,-406.155579,982.000671,0.000000
119.020004,219.298706,-406.155579,-0.000824,0.004216,0.107076,975.489380,49.693798,1.070762,-406.155579,982.000671,0.000000
119.490005,219.233917,-406.200043,-0.000845,0.004216,0.107076,975.201172,49.679115,1.070762,-406.200043,982.000671,0.000000
119.960007,219.389557,-406.200043,-0.000841,0.004221,0.107223,975.893494,49.714386,1.072230,-406.200043,982.000671,0.000000
120.430008,219.551178,-406.244537,-0.000819,0.004221,0.107223,976.612427,49.751007,1.072230,-406.244537,982.000671,0.000000
120.900009,219.540375,-406.289001,-0.000836,0.004221,0.107223,976.564331,49.748562,1.072230,-406.289001,982.000671,0.000000
121.370003,219.499420,-406.333496,-0.000832,0.004221,0.107223,976.382202,49.739281,1.072230,-406.333496,982.000671,0.000000
121.840004,219.445038,-406.289001,-0.000815,0.004221,0.107223,976.140259,49.726959,1.072230,-406.289001,982.000671,0.000000
122.310005,219.370575,-406.377960,-0.000832,0.004221,0.107223,975.809082,49.710083,1.072230,-406.377960,982.000671,0.000000
122.780006,219.305420,-406.333496,-0.000836,0.004221,0.107223,975.519226,49.695316,1.072230,-406.333496,982.000671,0.000000
123.250008,219.254761,-406.377960,-0.000828,0.004221,0.107223,975.293884,49.683838,1.072230,-406.377960,982.000671,0.000000
123.720009,219.184021,-406.422455,-0.000836,0.004221,0.107223,974.979248,49.667809,1.072230,-406.422455,982.000671,0.000000
124.190002,219.112518,-406.422455,-0.000824,0.004221,0.107223,974.661133,49.651604,1.072230,-406.422455,982.000671,0.000000
124.660004,219.307648,-406.422455,-0.000819,0.004235,0.107561,975.529114,49.695824,1.075607,-406.422455,982.000671,0.000000
125.130005,220.151428,-406.511414,-0.000824,0.004233,0.107527,979.282471,49.887024,1.075274,-406.511414,982.000671,0.000000
125.600006,220.149567,-406.511414,-0.000824,0.004233,0.107527,979.274170,49.886608,1.075274,-406.511414,982.000671,0.000000
126.070007,220.127625,-406.555878,-0.000836,0.004233,0.107527,979.176575,49.881634,1.075274,-406.555878,982.000671,0.000000
126.540009,220.086273,-406.511414,-0.000815,0.004233,0.107527,978.992615,49.872261,1.075274,-406.511414,982.000671,0.000000
127.010010,220.038605,-406.555878,-0.000806,0.004233,0.107527,978.780579,49.861462,1.075274,-406.555878,982.000671,0.000000
127.480003,219.972717,-406.555878,-0.000811,0.004233,0.107527,978.487488,49.846531,1.075274,-406.555878,982.000671,0.000000
127.950005,219.919464,-406.644867,-0.000849,0.004233,0.107527,978.250610,49.834461,1.075274,-406.644867,982.000671,0.000000
128.420013,219.868439,-406.689331,-0.000836,0.004233,0.107527,978.023682,49.822899,1.075274,-406.689331,982.000671,0.000000
128.889999,219.817047,-406.644867,-0.000815,0.004233,0.107527,977.795044,49.811256,1.075274,-406.644867,982.000671,0.000000
129.360001,219.776459,-406.733826,-0.000819,0.004233,0.107527,977.614502,49.802055,1.075274,-406.733826,982.000671,0.000000
129.830002,219.704956,-406.689331,-0.000811,0.004233,0.107527,977.296448,49.785858,1.075274,-406.689331,982.000671,0.000000
130.300003,219.639435,-406.778290,-0.000819,0.004233,0.107527,977.005005,49.771008,1.075274,-406.778290,982.000671,0.000000
130.770004,219.599579,-406.733826,-0.000819,0.004233,0.107527,976.827698,49.761978,1.075274,-406.733826,982.000671,0.000000
131.240005,219.546722,-406.733826,-0.000815,0.004233,0.107527,976.592590,49.750000,1.075274,-406.733826,982.000671,0.000000
131.710007,219.488983,-406.778290,-0.000824,0.004234,0.107535,976.335754,49.736916,1.075349,-406.778290,982.000671,0.000000
132.180008,219.434265,-406.822784,-0.000815,0.004234,0.107535,976.092346,49.724514,1.075349,-406.822784,982.000671,0.000000
132.650009,219.449158,-406.867249,-0.000815,0.004236,0.107588,976.158630,49.727890,1.075879,-406.867249,982.000671,0.000000
133.120010,219.456604,-406.956207,-0.000819,0.004236,0.107605,976.191711,49.729576,1.076046,-406.956207,982.000671,0.000000
133.590012,219.483765,-406.867249,-0.000819,0.004238,0.107639,976.312561,49.735729,1.076394,-406.867249,982.000671,0.000000
134.060013,219.489349,-406.911743,-0.000802,0.004238,0.107639,976.337402,49.736996,1.076394,-406.911743,982.000671,0.000000
134.529999,219.459961,-406.911743,-0.000824,0.004238,0.107639,976.206665,49.730339,1.076394,-406.911743,982.000671,0.000000
135.000000,219.430145,-407.000702,-0.000824,0.004238,0.107639,976.074036,49.723579,1.076394,-407.000702,982.000671,0.000000
135.470001,219.473358,-407.045197,-0.000811,0.004239,0.107683,976.266235,49.733372,1.076833,-407.045197,982.000671,0.000000
135.940002,219.459198,-406.956207,-0.000811,0.004239,0.107683,976.203247,49.730167,1.076833,-406.956207,982.000671,0.000000
136.410004,219.475220,-407.045197,-0.000819,0.004241,0.107718,976.274536,49.733795,1.077181,-407.045197,5607.367676,0.000000
136.880005,219.393677,-407.089661,-0.000802,0.004225,0.107309,975.911804,49.715317,1.073093,-407.089661,0.107206,0.000000
137.350006,219.187378,-407.178619,-0.000802,0.004200,0.106686,974.994141,49.668568,1.066856,-407.178619,0.106425,0.000000
137.820007,218.814636,-407.134155,-0.000819,0.004180,0.106183,973.336121,49.584106,1.061830,-407.134155,0.105636,0.000000
138.290009,217.639038,-407.045197,-0.000811,0.004156,0.105558,968.106812,49.317711,1.055577,-407.045197,0.104855,0.000000
138.760010,216.646667,-407.089661,-0.000789,0.004126,0.104795,963.692505,49.092838,1.047947,-407.089661,0.104076,0.000000
139.230011,216.202789,-407.223114,-0.000789,0.004095,0.104023,961.718018,48.992252,1.040225,-407.223114,0.103285,0.000000
139.700012,215.930237,-407.267578,-0.000793,0.004059,0.103094,960.505676,48.930492,1.030945,-407.267578,0.102506,0.000000
140.170013,215.497528,-407.267578,-0.000776,0.004033,0.102436,958.580872,48.832439,1.024359,-407.267578,0.101724,0.000000
140.639999,214.987762,-407.267578,-0.000772,0.003996,0.101491,956.313354,48.716923,1.014912,-407.267578,0.100936,0.000000
141.110001,213.848663,-407.267578,-0.000763,0.003971,0.100866,951.246338,48.458801,1.008659,-407.267578,0.100156,0.000000
141.580002,213.201843,-407.356537,-0.000763,0.003939,0.100051,948.369141,48.312225,1.000514,-407.356537,0.099375,0.000000
142.050003,211.918274,-407.356537,-0.000763,0.003914,0.099419,942.659546,48.021366,0.994186,-407.356537,0.098586,0.000000
142.520004,209.557831,-407.445526,-0.000759,0.003881,0.098568,932.159790,47.486485,0.985677,-407.445526,0.097805,0.000000
142.990005,206.950836,-407.356537,-0.000763,0.003848,0.097744,920.563293,46.895729,0.977442,-407.356537,0.097025,0.000000
143.460007,203.797577,-407.401031,-0.000737,0.003815,0.096895,906.536926,46.181190,0.968948,-407.401031,0.096235,0.000000
143.930008,201.241241,-407.489990,-0.000763,0.003790,0.096279,895.165771,45.601917,0.962786,-407.489990,0.095455,0.000000
144.400009,197.393890,-407.489990,-0.000755,0.003756,0.095394,878.051880,44.730095,0.953945,-407.489990,0.094674,0.000000
144.870010,193.693268,-407.534485,-0.000750,0.003725,0.094613,861.590698,43.891521,0.946133,-407.534485,0.093885,0.000000
145.340012,190.103958,-407.489990,-0.000759,0.003695,0.093841,845.624634,43.078171,0.938412,-407.489990,0.093105,0.000000
145.810013,187.653381,-407.578949,-0.000755,0.003670,0.093208,834.723938,42.522861,0.932083,-407.578949,0.092324,0.000000
146.280014,183.845505,-407.578949,-0.000759,0.003636,0.092359,817.785645,41.659988,0.923590,-407.578949,0.091535,0.000000
146.750000,180.722778,-407.623444,-0.000767,0.003605,0.091570,803.895081,40.952366,0.915702,-407.623444,0.090754,0.000000
147.220001,177.591507,-407.623444,-0.000750,0.003578,0.090893,789.966492,40.242813,0.908935,-407.623444,0.089975,0.000000
147.690002,173.951569,-407.667908,-0.000772,0.003545,0.090052,773.775208,39.417988,0.900517,-407.667908,0.089184,0.000000
148.160004,170.836670,-407.623444,-0.000759,0.003520,0.089402,759.919434,38.712143,0.894022,-407.623444,0.088405,0.000000
148.630005,166.790100,-407.756866,-0.000763,0.003484,0.088500,741.919434,37.795177,0.884999,-407.756866,0.087623,0.000000
149.100006,162.240814,-407.756866,-0.000763,0.003446,0.087520,721.683167,36.764294,0.875204,-407.756866,0.086835,0.000000
149.570007,159.170990,-407.756866,-0.000759,0.003420,0.086869,708.027954,36.068661,0.868694,-407.756866,0.086055,0.000000
150.040009,154.746826,-407.712402,-0.000759,0.003383,0.085932,688.348267,35.066132,0.859323,-407.712402,0.085274,0.000000
150.510010,152.245605,-407.756866,-0.000759,0.003362,0.085404,677.222290,34.499348,0.854039,-407.756866,0.084485,0.000000
150.980011,147.662064,-407.756866,-0.000763,0.003320,0.084329,656.833679,33.460701,0.843290,-407.756866,0.083704,0.000000
151.450012,143.939087,-407.845825,-0.000763,0.003293,0.083652,640.273010,32.617062,0.836522,-407.845825,0.082924,0.000000
151.920013,141.048355,-407.890320,-0.000767,0.003270,0.083054,627.414429,31.962013,0.830542,-407.890320,0.082134,0.000000
152.390015,137.362244,-407.890320,-0.000759,0.003233,0.082126,611.017761,31.126730,0.821262,-407.890320,0.081354,0.000000
152.860001,133.708160,-407.934814,-0.000759,0.003206,0.081424,594.763611,30.298702,0.814237,-407.934814,0.080573,0.000000
153.330002,129.876068,-407.934814,-0.000767,0.003175,0.080633,577.717590,29.430338,0.806334,-407.934814,0.079784,0.000000
153.800003,126.932465,-407.934814,-0.000759,0.003148,0.079966,564.623779,28.763308,0.799657,-407.934814,0.079003,0.000000
154.270004,123.222885,-407.979279,-0.000755,0.003117,0.079160,548.122742,27.922705,0.791603,-407.979279,0.078223,0.000000
154.740005,119.607147,-407.979279,-0.000750,0.003084,0.078328,532.039185,27.103367,0.783276,-407.979279,0.077434,0.000000
155.210007,115.845078,-407.979279,-0.000767,0.003053,0.077537,515.304626,26.250870,0.775374,-407.979279,0.076653,0.000000
155.680008,113.159149,-408.068237,-0.000755,0.003027,0.076897,503.357025,25.642229,0.768970,-408.068237,0.075874,0.000000
156.150009,108.748032,-408.112732,-0.000759,0.002989,0.075908,483.735413,24.642656,0.759083,-408.112732,0.075083,0.000000
156.620010,105.621582,-408.157196,-0.000763,0.002961,0.075206,469.828247,23.934193,0.752059,-408.157196,0.074304,0.000000
157.090012,101.539276,-408.157196,-0.000759,0.002926,0.074329,451.669250,23.009129,0.743293,-408.157196,0.073522,0.000000
157.560013,99.041016,-408.112732,-0.000737,0.002903,0.073739,440.556427,22.443014,0.737388,-408.112732,0.072734,0.000000
158.030014,95.190323,-408.157196,-0.000755,0.002867,0.072820,423.427704,21.570435,0.728199,-408.157196,0.071952,0.000000
158.500000,91.232376,-408.157196,-0.000763,0.002836,0.072040,405.821869,20.673552,0.720402,-408.157196,0.071173,0.000000
158.970001,87.475510,-408.246155,-0.000763,0.002803,0.071198,389.110504,19.822235,0.711984,-408.246155,0.070384,0.000000
159.440002,84.583282,-408.246155,-0.000746,0.002777,0.070547,376.245239,19.166847,0.705474,-408.246155,0.069603,0.000000
159.910004,80.915787,-408.201691,-0.000746,0.002745,0.069733,359.931396,18.335779,0.697329,-408.201691,0.068823,0.000000
160.380005,77.553268,-408.246155,-0.000750,0.002715,0.068961,344.974182,17.573822,0.689608,-408.246155,0.068033,0.000000
160.850006,74.609665,-408.379608,-0.000767,0.002688,0.068276,331.880371,16.906792,0.682765,-408.379608,0.067253,0.000000
161.320007,71.388641,-408.335144,-0.000763,0.002658,0.067521,317.552551,16.176897,0.675210,-408.335144,0.066472,0.000000
161.790009,67.420273,-408.424103,-0.000759,0.002622,0.066602,299.900360,15.277652,0.666020,-408.424103,0.065683,0.000000
162.260010,63.995926,-408.379608,-0.000742,0.002590,0.065788,284.668091,14.501683,0.657875,-408.379608,0.064902,0.000000
162.730011,61.102600,-408.379608,-0.000755,0.002565,0.065146,271.797943,13.846047,0.651456,-408.379608,0.064122,0.000000
163.200012,57.982491,-408.379608,-0.000759,0.002536,0.064417,257.919006,13.139020,0.644174,-408.379608,0.063333,0.000000
163.670013,53.726273,-408.468567,-0.000759,0.002497,0.063429,238.986389,12.174548,0.634288,-408.468567,0.062552,0.000000
164.140015,50.320557,-408.468567,-0.000759,0.002466,0.062631,223.837021,11.402801,0.626309,-408.468567,0.061773,0.000000
164.610001,46.880577,-408.513062,-0.000737,0.002431,0.061745,208.535217,10.623290,0.617453,-408.513062,0.060982,0.000000
165.080002,44.522713,-408.513062,-0.000742,0.002416,0.061364,198.046921,10.088990,0.613637,-408.513062,0.060203,0.000000
165.550003,40.510773,-408.557526,-0.000755,0.002377,0.060368,180.200912,9.179872,0.603676,-408.557526,0.059421,0.000000
166.020004,37.106171,-408.646484,-0.000755,0.002343,0.059500,165.056488,8.408379,0.595001,-408.646484,0.058633,0.000000
166.490005,32.807877,-408.646484,-0.000755,0.002305,0.058537,145.936722,7.434371,0.585372,-408.646484,0.057851,0.000000
166.960007,31.250992,-408.646484,-0.000724,0.002293,0.058251,139.011353,7.081576,0.582510,-408.646484,0.057072,0.000000
167.430008,27.655731,-408.646484,-0.000750,0.002259,0.057384,123.018837,6.266878,0.573835,-408.646484,0.056290,0.000000
167.900009,24.118568,-408.646484,-0.000763,0.002225,0.056525,107.284752,5.465346,0.565251,-408.646484,0.055502,0.000000
168.370010,21.156342,-408.735474,-0.000750,0.002197,0.055814,94.108109,4.794096,0.558136,-408.735474,0.054722,0.000000
168.840012,16.847618,-408.824432,-0.000746,0.002157,0.054783,74.941948,3.817725,0.547826,-408.824432,0.053941,0.000000
169.310013,14.944054,-408.690979,-0.000750,0.002137,0.054271,66.474472,3.386371,0.542709,-408.690979,0.053152,0.000000
169.780014,11.597168,-408.779938,-0.000742,0.002105,0.053455,51.586781,2.627956,0.534548,-408.779938,0.052371,0.000000
170.250015,8.279327,-408.779938,-0.000763,0.002073,0.052648,36.828289,1.876122,0.526479,-408.779938,0.051591,0.000000
170.720001,4.503105,-408.779938,-0.000750,0.002034,0.051652,20.030811,1.020418,0.516517,-408.779938,0.050801,0.000000
171.190002,2.228653,-408.824432,-0.000759,0.002007,0.050966,9.913544,0.505020,0.509659,-408.824432,0.050021,0.000000
171.660004,-0.573448,-408.913391,-0.000755,0.001974,0.050151,-2.550825,-0.129945,0.501514,-408.913391,0.049240,0.000000
172.130005,-1.425442,-408.868896,-0.000737,0.001947,0.049449,-6.340682,-0.323010,0.494489,-408.868896,0.048451,0.000000
172.600006,-0.043564,-408.957855,-0.000746,0.001908,0.048468,-0.193782,-0.009872,0.484679,-408.957855,0.047670,0.000000
173.070007,0.033516,-408.913391,-0.000750,0.001882,0.047793,0.149086,0.007595,0.477926,-408.913391,0.046890,0.000000
173.540009,-0.017502,-408.913391,-0.000746,0.001848,0.046951,-0.077852,-0.003966,0.469509,-408.913391,0.046102,0.000000
174.010010,-0.026810,-408.957855,-0.000737,0.001823,0.046292,-0.119255,-0.006075,0.462923,-408.957855,0.045320,0.000000
174.480011,-0.035378,-409.046814,-0.000733,0.001795,0.045597,-0.157367,-0.008017,0.455974,-409.046814,0.044541,0.000000
174.950012,-0.045052,-409.002350,-0.000737,0.001769,0.044922,-0.200399,-0.010209,0.449222,-409.002350,0.043750,0.000000
175.420013,-0.084526,-409.046814,-0.000720,0.001727,0.043855,-0.375991,-0.019154,0.438548,-409.046814,0.042971,0.000000
175.890015,-0.102402,-409.046814,-0.000733,0.001699,0.043143,-0.455506,-0.023205,0.431433,-409.046814,0.042189,0.000000
176.360016,-0.119904,-409.135773,-0.000733,0.001671,0.042441,-0.533358,-0.027171,0.424408,-409.135773,0.041401,0.000000
176.830002,-0.099419,-409.135773,-0.000742,0.001646,0.041800,-0.442236,-0.022529,0.418004,-409.135773,0.040619,0.000000
177.300003,-0.128464,-409.135773,-0.000755,0.001609,0.040872,-0.571435,-0.029110,0.408723,-409.135773,0.039840,0.000000
177.770004,-0.103516,-409.224762,-0.000798,0.001573,0.039961,-0.460460,-0.023457,0.399609,-409.224762,0.039051,0.000000
178.240005,-0.135918,-409.224762,-0.000815,0.001552,0.039423,-0.604592,-0.030799,0.394235,-409.224762,0.038270,0.000000
178.710007,-0.144478,-409.269226,-0.000849,0.001517,0.038521,-0.642670,-0.032739,0.385211,-409.269226,0.037490,0.000000
179.180008,-0.155281,-409.269226,-0.000854,0.001496,0.037993,-0.690725,-0.035187,0.379928,-409.269226,0.036700,0.000000
179.650009,-0.132935,-409.224762,-0.000905,0.001447,0.036760,-0.591322,-0.030123,0.367604,-409.224762,0.035920,0.000000
180.120010,-0.124374,-409.269226,-0.000953,0.001426,0.036215,-0.553245,-0.028184,0.362154,-409.269226,0.035139,0.000000
180.590012,-0.121765,-409.358185,-0.000966,0.001391,0.035339,-0.541638,-0.027592,0.353388,-409.358185,0.034350,0.000000
181.060013,-0.103516,-409.358185,-0.000996,0.001368,0.034748,-0.460460,-0.023457,0.347484,-409.358185,0.033569,0.000000
181.530014,-0.115807,-409.358185,-0.001026,0.001338,0.033985,-0.515133,-0.026242,0.339853,-409.358185,0.032789,0.000000
182.000015,-0.121017,-409.313721,-0.001043,0.001304,0.033127,-0.538313,-0.027423,0.331269,-409.313721,0.032001,0.000000
182.470001,-0.081551,-409.358185,-0.001074,0.001271,0.032294,-0.362755,-0.018480,0.322942,-409.358185,0.031219,0.000000
182.940002,-0.061813,-409.402679,-0.001112,0.001244,0.031610,-0.274960,-0.014007,0.316099,-409.402679,0.030440,0.000000
183.410004,-0.097931,-409.491638,-0.001138,0.001208,0.030682,-0.435618,-0.022191,0.306819,-409.491638,0.029649,0.000000
183.880005,-0.130325,-409.536102,-0.001164,0.001178,0.029910,-0.579716,-0.029532,0.299098,-409.536102,0.028870,0.000000
184.350006,-0.069633,-409.491638,-0.001207,0.001150,0.029198,-0.309745,-0.015779,0.291982,-409.491638,0.028088,0.000000
184.820007,-0.057716,-409.447144,-0.001233,0.001121,0.028479,-0.256735,-0.013079,0.284791,-409.447144,0.027300,0.000000
185.290009,-0.106873,-409.580597,-0.001268,0.001084,0.027534,-0.475393,-0.024218,0.275344,-409.580597,0.026518,0.000000
185.760010,-0.137779,-409.580597,-0.001302,0.001053,0.026744,-0.612873,-0.031221,0.267441,-409.580597,0.025739,0.000000
186.230011,-0.090485,-409.625092,-0.001319,0.001019,0.025886,-0.402496,-0.020504,0.258857,-409.625092,0.024950,0.000000
186.700012,-0.095695,-409.580597,-0.001358,0.000993,0.025227,-0.425675,-0.021685,0.252271,-409.580597,0.024169,0.000000
187.170013,-0.102776,-409.625092,-0.001393,0.000961,0.024403,-0.457169,-0.023289,0.244035,-409.625092,0.023389,0.000000
187.640015,-0.099052,-409.669556,-0.001431,0.000927,0.023553,-0.440607,-0.022446,0.235526,-409.669556,0.022599,0.000000
188.110016,-0.116554,-409.669556,-0.001453,0.000897,0.022773,-0.518459,-0.026412,0.227730,-409.669556,0.021819,0.000000
188.580002,-0.124001,-409.758514,-0.001483,0.000871,0.022122,-0.551582,-0.028099,0.221220,-409.758514,0.021038,0.000000
189.050003,-0.118042,-409.803009,-0.001509,0.000835,0.021220,-0.525077,-0.026749,0.212196,-409.803009,0.020249,0.000000
189.520004,-0.107239,-409.758514,-0.001552,0.000804,0.020431,-0.477022,-0.024301,0.204309,-409.758514,0.019468,0.000000
189.800003,-0.090485,-409.803009,-0.001535,0.000804,0.020422,-0.402496,-0.020504,0.204218,-409.803009,0.020275,0.000000