File: Data/sima compression 500bar/P2-17-500bar-1_11072024_170752.csv
Time (sec),S:Load (lbs),S:HL1 (DIM),S:LVDT (in),S:Position (in),Ch:Position (mm),Ch:Load (N),Ch:Stress (MPa),Ch:Strain (mm/mm),Ch:HL1 (DIM),Set Point (),Cycles ()
0.010000,-0.093094,-386.984283,-0.010977,-0.007793,-0.197944,-0.414102,-0.021095,-1.979439,-386.984283,-0.197744,0.000000
0.470000,-0.040215,-386.984283,-0.010973,-0.007711,-0.195862,-0.178883,-0.009113,-1.958623,-386.984283,-0.195246,0.000000
0.930000,-0.100166,-387.028748,-0.010774,-0.007421,-0.188500,-0.445562,-0.022698,-1.884999,-387.028748,-0.187581,0.000000
1.390000,-0.103142,-387.073242,-0.010455,-0.007121,-0.180877,-0.458798,-0.023372,-1.808771,-387.073242,-0.179914,0.000000
1.850000,-0.107613,-387.117706,-0.010179,-0.006835,-0.173610,-0.478685,-0.024385,-1.736101,-387.117706,-0.172248,0.000000
2.310000,-0.109100,-387.117706,-0.009856,-0.006523,-0.165692,-0.485303,-0.024722,-1.656921,-387.117706,-0.164599,0.000000
2.770000,-0.078568,-387.073242,-0.009537,-0.006218,-0.157939,-0.349486,-0.017804,-1.579391,-387.073242,-0.156932,0.000000
3.230000,-0.096817,-387.162201,-0.009257,-0.005925,-0.150498,-0.430664,-0.021939,-1.504980,-387.162201,-0.149266,0.000000
3.690000,-0.148575,-387.117706,-0.008938,-0.005618,-0.142694,-0.660894,-0.033668,-1.426936,-387.117706,-0.141600,0.000000
4.150000,-0.041702,-387.251160,-0.008614,-0.005314,-0.134974,-0.185501,-0.009450,-1.349739,-387.251160,-0.133934,0.000000
4.610000,-0.047661,-387.162201,-0.008304,-0.005011,-0.127281,-0.212006,-0.010800,-1.272815,-387.162201,-0.126267,0.000000
5.070000,-0.061066,-387.206665,-0.007981,-0.004710,-0.119633,-0.271634,-0.013838,-1.196330,-387.206665,-0.118619,0.000000
5.530000,-0.079315,-387.251160,-0.007683,-0.004420,-0.112280,-0.352812,-0.017973,-1.122797,-387.251160,-0.110952,0.000000
5.990000,-0.142242,-387.295654,-0.007364,-0.004106,-0.104292,-0.632726,-0.032233,-1.042920,-387.295654,-0.103287,0.000000
6.450000,-0.063301,-387.384613,-0.007049,-0.003802,-0.096574,-0.281577,-0.014344,-0.965739,-387.384613,-0.095620,0.000000
6.910000,-0.038353,-387.295654,-0.006765,-0.003508,-0.089107,-0.170603,-0.008691,-0.891070,-387.295654,-0.087953,0.000000
7.370000,-0.105377,-387.384613,-0.006428,-0.003206,-0.081424,-0.468741,-0.023879,-0.814237,-387.384613,-0.080287,0.000000
7.830000,-0.072983,-387.384613,-0.006118,-0.002900,-0.073662,-0.324644,-0.016538,-0.736616,-387.384613,-0.072638,0.000000
8.290000,-0.102028,-387.384613,-0.005812,-0.002602,-0.066090,-0.453843,-0.023120,-0.660903,-387.384613,-0.064972,0.000000
8.750000,-0.077080,-387.429077,-0.005514,-0.002300,-0.058425,-0.342868,-0.017467,-0.584252,-387.429077,-0.057306,0.000000
9.210000,-0.049522,-387.473572,-0.005204,-0.002006,-0.050949,-0.220287,-0.011222,-0.509492,-387.473572,-0.049640,0.000000
9.670000,-0.087509,-387.518036,-0.004868,-0.001692,-0.042980,-0.389260,-0.019830,-0.429798,-387.518036,-0.041973,0.000000
10.130000,-0.087135,-387.518036,-0.004575,-0.001388,-0.035262,-0.387597,-0.019745,-0.352616,-387.518036,-0.034306,0.000000
10.590000,-0.053246,-387.473572,-0.004286,-0.001105,-0.028072,-0.236848,-0.012066,-0.280718,-387.473572,-0.026658,0.000000
11.050000,-0.085648,-387.518036,-0.003949,-0.000791,-0.020084,-0.380979,-0.019408,-0.200842,-387.518036,-0.018991,0.000000
11.510000,-0.049896,-387.562531,-0.003652,-0.000492,-0.012487,-0.221950,-0.011307,-0.124871,-387.562531,-0.011326,0.000000
11.970000,-0.071869,-387.562531,-0.003328,-0.000183,-0.004648,-0.319689,-0.016286,-0.046479,-387.562531,-0.003659,0.000000
12.430000,-0.143738,-387.695984,-0.003035,0.000110,0.002793,-0.639378,-0.032571,0.027933,-387.695984,0.004007,0.000000
12.890000,0.107246,-387.651489,-0.002798,-0.000000,-0.000000,0.477056,0.024302,-0.000000,-387.651489,0.000224,0.000000
13.350000,0.173897,-387.695984,-0.002790,-0.000000,-0.000000,0.773532,0.039406,-0.000000,-387.695984,0.000354,0.000000
13.810000,0.185814,-387.740448,-0.002811,0.000011,0.000286,0.826542,0.042106,0.002861,-387.740448,0.001117,0.000000
14.270000,0.529518,-387.695984,-0.002772,0.000038,0.000970,2.355414,0.119991,0.009704,-387.695984,0.001889,0.000000
14.730000,1.217659,-387.740448,-0.002742,0.000073,0.001847,5.416418,0.275925,0.018470,-387.740448,0.002652,0.000000
15.190001,1.877129,-387.829407,-0.002746,0.000095,0.002419,8.349885,0.425363,0.024193,-387.829407,0.003415,0.000000
15.650001,2.873970,-387.784943,-0.002721,0.000130,0.003303,12.784058,0.651251,0.033035,-387.784943,0.004188,0.000000
16.110001,3.969116,-387.873901,-0.002690,0.000160,0.004057,17.655510,0.899415,0.040574,-387.873901,0.004951,0.000000
16.570002,5.275406,-387.873901,-0.002686,0.000189,0.004813,23.466177,1.195424,0.048129,-387.873901,0.005723,0.000000
17.030001,6.551147,-387.918365,-0.002639,0.000222,0.005636,29.140959,1.484511,0.056365,-387.918365,0.006486,0.000000
17.490002,8.086441,-387.918365,-0.002608,0.000251,0.006365,35.970287,1.832414,0.063647,-387.918365,0.007249,0.000000
17.950001,9.300377,-387.918365,-0.002600,0.000280,0.007102,41.370144,2.107496,0.071020,-387.918365,0.008021,0.000000
18.410002,10.588783,-387.962860,-0.002596,0.000306,0.007779,47.101261,2.399452,0.077787,-387.962860,0.008784,0.000000
18.870001,12.257385,-387.962860,-0.002578,0.000339,0.008619,54.523571,2.777563,0.086190,-387.962860,0.009556,0.000000
19.330002,13.877205,-388.007324,-0.002557,0.000373,0.009470,61.728889,3.144619,0.094698,-388.007324,0.010319,0.000000
19.790001,15.165611,-388.051819,-0.002522,0.000399,0.010137,67.460007,3.436577,0.101375,-388.051819,0.011091,0.000000
20.250002,16.315132,-388.096283,-0.002509,0.000426,0.010814,72.573334,3.697062,0.108142,-388.096283,0.011854,0.000000
20.710001,18.135658,-388.140778,-0.002501,0.000459,0.011664,80.671440,4.109599,0.116635,-388.140778,0.012617,0.000000
21.170000,19.094521,-388.051819,-0.002462,0.000480,0.012201,84.936668,4.326880,0.122010,-388.051819,0.013389,0.000000
21.630001,21.196556,-388.185272,-0.002440,0.000521,0.013224,94.286987,4.803208,0.132244,-388.185272,0.014152,0.000000
22.090000,22.632057,-388.140778,-0.002436,0.000553,0.014048,100.672417,5.128497,0.140480,-388.140778,0.014925,0.000000
22.550001,23.949509,-388.185272,-0.002427,0.000580,0.014741,106.532738,5.427036,0.147414,-388.185272,0.015688,0.000000
23.010000,25.078545,-388.229736,-0.002397,0.000604,0.015349,111.554939,5.682879,0.153485,-388.229736,0.016451,0.000000
23.470001,27.012642,-388.185272,-0.002393,0.000643,0.016320,120.158234,6.121152,0.163205,-388.185272,0.017223,0.000000
23.930000,27.963684,-388.274231,-0.002345,0.000671,0.017040,124.388680,6.336661,0.170396,-388.274231,0.017986,0.000000
24.390001,28.941162,-388.318695,-0.002337,0.000696,0.017674,128.736725,6.558161,0.176739,-388.318695,0.018758,0.000000
24.850000,30.587051,-388.274231,-0.002307,0.000731,0.018575,136.057999,6.931125,0.185748,-388.274231,0.019521,0.000000
25.310001,31.493027,-388.363190,-0.002285,0.000758,0.019261,140.087982,7.136422,0.192606,-388.363190,0.020284,0.000000
25.770000,32.724091,-388.318695,-0.002259,0.000792,0.020110,145.564026,7.415385,0.201099,-388.318695,0.021056,0.000000
26.230001,33.307228,-388.363190,-0.002246,0.000818,0.020787,148.157944,7.547526,0.207866,-388.363190,0.021819,0.000000
26.690001,34.877525,-388.318695,-0.002216,0.000852,0.021645,155.142975,7.903360,0.216451,-388.318695,0.022590,0.000000
27.150002,36.079170,-388.363190,-0.002190,0.000886,0.022513,160.488159,8.175656,0.225126,-388.363190,0.023354,0.000000
27.610001,36.768806,-388.496613,-0.002160,0.000914,0.023206,163.555817,8.331931,0.232059,-388.496613,0.024125,0.000000
28.070002,37.011589,-388.363190,-0.002108,0.000937,0.023796,164.635773,8.386946,0.237964,-388.363190,0.024888,0.000000
28.530001,38.250847,-388.541107,-0.002104,0.000972,0.024690,170.148270,8.667766,0.246896,-388.541107,0.025653,0.000000
28.990002,39.256248,-388.496613,-0.002087,0.001005,0.025522,174.620514,8.895594,0.255223,-388.496613,0.026423,0.000000
29.450001,39.972694,-388.541107,-0.002052,0.001036,0.026320,177.807419,9.057942,0.263202,-388.541107,0.027186,0.000000
29.910002,40.874954,-388.585602,-0.002018,0.001065,0.027048,181.820877,9.262398,0.270484,-388.585602,0.027958,0.000000
30.370001,41.750778,-388.585602,-0.002001,0.001097,0.027855,185.716736,9.460861,0.278553,-388.585602,0.028721,0.000000
30.830002,41.909035,-388.674561,-0.001962,0.001122,0.028488,186.420700,9.496723,0.284881,-388.674561,0.029484,0.000000
31.290001,43.054451,-388.630066,-0.001940,0.001155,0.029337,191.515762,9.756278,0.293375,-388.630066,0.030256,0.000000
31.750002,43.631630,-388.674561,-0.001884,0.001185,0.030091,194.083176,9.887069,0.300914,-388.674561,0.031019,0.000000
32.210003,43.941444,-388.719025,-0.001876,0.001211,0.030752,195.461304,9.957273,0.307515,-388.719025,0.031792,0.000000
32.670002,44.739807,-388.674561,-0.001863,0.001240,0.031496,199.012604,10.138186,0.314964,-388.674561,0.032555,0.000000
33.130001,44.001022,-388.763519,-0.001828,0.001261,0.032035,195.726318,9.970774,0.320354,-388.763519,0.033318,0.000000
33.590000,46.616936,-388.763519,-0.001789,0.001303,0.033092,207.362488,10.563549,0.330921,-388.763519,0.034090,0.000000
34.050003,47.872948,-388.852478,-0.001750,0.001339,0.034020,212.949509,10.848165,0.340201,-388.852478,0.034853,0.000000
34.510002,48.393524,-388.896942,-0.001712,0.001366,0.034697,215.265152,10.966129,0.346969,-388.896942,0.035625,0.000000
34.970001,48.891762,-388.896942,-0.001703,0.001393,0.035374,217.481415,11.079031,0.353736,-388.896942,0.036388,0.000000
35.430000,49.869987,-388.896942,-0.001673,0.001424,0.036162,221.832779,11.300700,0.361624,-388.896942,0.037151,0.000000
35.890003,50.702606,-388.852478,-0.001647,0.001458,0.037039,225.536453,11.489375,0.370390,-388.852478,0.037923,0.000000
36.350002,51.106636,-388.896942,-0.001608,0.001482,0.037637,227.333664,11.580930,0.376370,-388.896942,0.038686,0.000000
36.810001,52.081505,-389.030396,-0.001600,0.001515,0.038479,231.670105,11.801838,0.384788,-389.030396,0.039458,0.000000
37.270000,52.852318,-388.985931,-0.001552,0.001545,0.039242,235.098846,11.976507,0.392418,-388.985931,0.040221,0.000000
37.730003,53.684937,-389.030396,-0.001526,0.001575,0.039996,238.802521,12.165181,0.399957,-389.030396,0.040993,0.000000
38.190002,54.678802,-389.074890,-0.001505,0.001604,0.040742,243.223465,12.390393,0.407421,-389.074890,0.041756,0.000000
38.650002,54.847488,-389.030396,-0.001483,0.001625,0.041287,243.973816,12.428619,0.412871,-389.030396,0.042520,0.000000
39.110001,56.905220,-389.163849,-0.001449,0.001668,0.042373,253.127060,12.894907,0.423727,-389.163849,0.043292,0.000000
39.570004,57.743797,-389.074890,-0.001414,0.001695,0.043057,256.857239,13.084931,0.430570,-389.074890,0.044055,0.000000
40.030003,59.325264,-389.119354,-0.001406,0.001730,0.043950,263.891968,13.443296,0.439502,-389.119354,0.044827,0.000000
40.490002,59.520386,-389.119354,-0.001380,0.001748,0.044410,264.759888,13.487513,0.444104,-389.119354,0.045590,0.000000
40.950001,61.320808,-389.163849,-0.001375,0.001789,0.045434,272.768585,13.895494,0.454339,-389.163849,0.046353,0.000000
41.410004,62.619270,-389.208313,-0.001350,0.001817,0.046144,278.544434,14.189730,0.461439,-389.208313,0.047125,0.000000
41.870003,63.800064,-389.297272,-0.001324,0.001846,0.046899,283.796844,14.457301,0.468994,-389.297272,0.047888,0.000000
42.330002,64.809570,-389.252808,-0.001289,0.001875,0.047619,288.287354,14.686059,0.476185,-389.252808,0.048659,0.000000
42.790001,66.101334,-389.297272,-0.001276,0.001905,0.048391,294.033417,14.978777,0.483906,-389.297272,0.049423,0.000000
43.250004,67.285843,-389.297272,-0.001250,0.001933,0.049110,299.302368,15.247190,0.491098,-389.297272,0.050186,0.000000
43.710003,68.741074,-389.341766,-0.001237,0.001967,0.049952,305.775574,15.576950,0.499515,-389.341766,0.050957,0.000000
44.170002,69.714462,-389.341766,-0.001207,0.001993,0.050619,310.105408,15.797523,0.506192,-389.341766,0.051721,0.000000
44.630001,70.616348,-389.430725,-0.001177,0.002024,0.051417,314.117218,16.001894,0.514170,-389.430725,0.052492,0.000000
45.090004,72.593262,-389.386230,-0.001177,0.002059,0.052294,322.910950,16.449867,0.522936,-389.386230,0.053255,0.000000
45.550003,73.637405,-389.386230,-0.001138,0.002084,0.052934,327.555542,16.686474,0.529340,-389.386230,0.054027,0.000000
46.010002,75.505219,-389.519684,-0.001112,0.002117,0.053776,335.863983,17.109726,0.537758,-389.519684,0.054790,0.000000
46.470001,75.761414,-389.430725,-0.001095,0.002136,0.054262,337.003601,17.167780,0.542618,-389.430725,0.055553,0.000000
46.930004,78.659210,-389.519684,-0.001074,0.002183,0.055441,349.893646,17.824432,0.554411,-389.519684,0.056325,0.000000
47.390003,79.856766,-389.564178,-0.001056,0.002207,0.056065,355.220642,18.095802,0.560649,-389.564178,0.057088,0.000000
47.850002,81.370834,-389.564178,-0.001035,0.002238,0.056837,361.955536,18.438894,0.568370,-389.564178,0.057860,0.000000
48.310001,81.995300,-389.608643,-0.001035,0.002259,0.057367,364.733307,18.580400,0.573669,-389.608643,0.058623,0.000000
48.770000,84.731873,-389.608643,-0.000992,0.002302,0.058477,376.906189,19.200518,0.584766,-389.608643,0.059387,0.000000
49.230003,86.040009,-389.608643,-0.000987,0.002330,0.059170,382.725067,19.496944,0.591700,-389.608643,0.060159,0.000000
49.690002,87.603226,-389.697601,-0.000974,0.002360,0.059942,389.678619,19.851175,0.599421,-389.697601,0.060922,0.000000
50.150002,88.806732,-389.653137,-0.000953,0.002383,0.060540,395.032074,20.123892,0.605402,-389.653137,0.061694,0.000000
50.610001,91.008209,-389.786560,-0.000914,0.002421,0.061485,404.824738,20.622755,0.614849,-389.786560,0.062457,0.000000
51.070004,92.326401,-389.742096,-0.000910,0.002449,0.062206,410.688354,20.921463,0.622055,-389.742096,0.063220,0.000000
51.530003,94.390839,-389.697601,-0.000897,0.002483,0.063081,419.871429,21.389269,0.630806,-389.697601,0.063992,0.000000
51.990002,96.177109,-389.831055,-0.000871,0.002512,0.063801,427.817139,21.794044,0.638012,-389.831055,0.064755,0.000000
52.450001,97.756332,-389.742096,-0.000858,0.002541,0.064539,434.841888,22.151901,0.645385,-389.742096,0.065527,0.000000
52.910004,99.545212,-389.831055,-0.000841,0.002569,0.065241,442.799225,22.557266,0.652410,-389.831055,0.066290,0.000000
53.370003,100.454544,-389.875549,-0.000828,0.002592,0.065830,446.844116,22.763325,0.658299,-389.875549,0.067053,0.000000
53.830002,102.923370,-389.875549,-0.000815,0.002626,0.066707,457.826019,23.322769,0.667065,-389.875549,0.067825,0.000000
54.290001,103.707596,-390.008972,-0.000806,0.002643,0.067132,461.314423,23.500477,0.671319,-390.008972,0.068588,0.000000
54.750004,107.724747,-389.920013,-0.000785,0.002694,0.068440,479.183594,24.410778,0.684400,-389.920013,0.069360,0.000000
55.210003,109.068634,-389.920013,-0.000759,0.002716,0.068987,485.161530,24.715305,0.689865,-389.920013,0.070124,0.000000
55.670002,111.744888,-389.920013,-0.000750,0.002752,0.069907,497.066101,25.321754,0.699070,-389.920013,0.070896,0.000000
56.130001,112.357437,-389.964508,-0.000733,0.002770,0.070357,499.790833,25.460558,0.703567,-389.964508,0.071659,0.000000
56.590004,115.086548,-390.097931,-0.000716,0.002809,0.071354,511.930542,26.078985,0.713544,-390.097931,0.072422,0.000000
57.050003,117.242584,-390.008972,-0.000729,0.002836,0.072022,521.521057,26.567551,0.720220,-390.008972,0.073194,0.000000
57.510002,120.000381,-390.142426,-0.000677,0.002872,0.072950,533.788330,27.192476,0.729501,-390.142426,0.073957,0.000000
57.970001,121.362152,-390.186890,-0.000681,0.002896,0.073566,539.845825,27.501057,0.735662,-390.186890,0.074727,0.000000
58.430004,123.818680,-390.142426,-0.000651,0.002928,0.074373,550.773010,28.057714,0.743732,-390.142426,0.075492,0.000000
58.890003,126.141174,-390.186890,-0.000655,0.002961,0.075197,561.103943,28.584000,0.751968,-390.186890,0.076255,0.000000
59.350002,128.325134,-390.186890,-0.000655,0.002991,0.075960,570.818726,29.078892,0.759598,-390.186890,0.077026,0.000000
59.810001,130.472244,-390.275879,-0.000629,0.003020,0.076705,580.369507,29.565432,0.767047,-390.275879,0.077789,0.000000
60.270004,132.872543,-390.231384,-0.000634,0.003052,0.077530,591.046570,30.109350,0.775298,-390.231384,0.078561,0.000000
60.730003,134.677811,-390.275879,-0.000612,0.003078,0.078179,599.076843,30.518429,0.781793,-390.275879,0.079324,0.000000
61.190002,137.147018,-390.364838,-0.000608,0.003110,0.078995,610.060425,31.077959,0.789953,-390.364838,0.080087,0.000000
61.650002,139.288162,-390.409302,-0.000599,0.003136,0.079654,619.584717,31.563148,0.796539,-390.409302,0.080859,0.000000
62.110004,141.943909,-390.320343,-0.000582,0.003171,0.080547,631.398010,32.164948,0.805471,-390.320343,0.081622,0.000000
62.570004,143.820679,-390.453796,-0.000569,0.003197,0.081198,639.746338,32.590233,0.811981,-390.453796,0.082394,0.000000
63.030003,145.882874,-390.409302,-0.000569,0.003227,0.081978,648.919434,33.057529,0.819778,-390.409302,0.083157,0.000000
63.490002,148.715134,-390.498260,-0.000543,0.003258,0.082750,661.517944,33.699333,0.827499,-390.498260,0.083929,0.000000
63.950005,150.193085,-390.453796,-0.000543,0.003278,0.083253,668.092224,34.034241,0.832525,-390.453796,0.084692,0.000000
64.410004,154.123474,-390.542755,-0.000526,0.003323,0.084415,685.575439,34.924877,0.844153,-390.542755,0.085455,0.000000
64.870003,156.356216,-390.587219,-0.000535,0.003352,0.085153,695.507202,35.430824,0.851526,-390.587219,0.086227,0.000000
65.330002,158.786697,-390.587219,-0.000509,0.003381,0.085890,706.318481,35.981579,0.858899,-390.587219,0.086991,0.000000
65.790001,160.416565,-390.631714,-0.000504,0.003402,0.086402,713.568542,36.350910,0.864016,-390.631714,0.087763,0.000000
66.250000,163.650620,-390.587219,-0.000496,0.003442,0.087416,727.954285,37.083763,0.874159,-390.587219,0.088526,0.000000
66.710007,166.040878,-390.587219,-0.000492,0.003471,0.088161,738.586731,37.625401,0.881608,-390.587219,0.089289,0.000000
67.170006,168.714523,-390.676178,-0.000470,0.003504,0.089012,750.479675,38.231258,0.890116,-390.676178,0.090061,0.000000
67.630005,171.123764,-390.676178,-0.000492,0.003528,0.089619,761.196533,38.777199,0.896187,-390.676178,0.090824,0.000000
68.090004,173.242569,-390.720673,-0.000466,0.003558,0.090373,770.621460,39.257328,0.903727,-390.720673,0.091596,0.000000
68.550003,176.228622,-390.720673,-0.000466,0.003590,0.091196,783.904053,39.933979,0.911963,-390.720673,0.092359,0.000000
69.010002,178.415939,-390.765167,-0.000444,0.003618,0.091908,793.633728,40.429630,0.919078,-390.765167,0.093122,0.000000
69.470001,181.549072,-390.809631,-0.000440,0.003649,0.092689,807.570618,41.139606,0.926890,-390.809631,0.093894,0.000000
69.930000,184.520615,-390.809631,-0.000444,0.003686,0.093625,820.788696,41.812969,0.936247,-390.809631,0.094657,0.000000
70.390007,186.980133,-390.898590,-0.000444,0.003711,0.094267,831.729187,42.370304,0.942666,-390.898590,0.095429,0.000000
70.850006,189.104141,-390.854126,-0.000448,0.003737,0.094918,841.177246,42.851612,0.949176,-390.854126,0.096192,0.000000
71.310005,192.067841,-390.854126,-0.000431,0.003769,0.095732,854.360413,43.523193,0.957321,-390.854126,0.096964,0.000000
71.770004,194.971252,-391.032043,-0.000427,0.003802,0.096565,867.275452,44.181118,0.965648,-391.032043,0.097727,0.000000
72.230003,197.833679,-390.898590,-0.000418,0.003837,0.097467,880.008179,44.829750,0.974671,-390.898590,0.098491,0.000000
72.690002,200.445129,-390.943085,-0.000405,0.003863,0.098117,891.624451,45.421516,0.981166,-390.943085,0.099263,0.000000
73.150002,203.438995,-390.943085,-0.000414,0.003895,0.098924,904.941833,46.099934,0.989235,-390.943085,0.100026,0.000000
73.610001,205.390961,-390.943085,-0.000423,0.003918,0.099522,913.624634,46.542255,0.995215,-390.943085,0.100796,0.000000
74.070007,208.639160,-391.076508,-0.000414,0.003955,0.100450,928.073364,47.278309,1.004496,-391.076508,0.101559,0.000000
74.530006,211.255463,-391.032043,-0.000397,0.003982,0.101135,939.711243,47.871174,1.011354,-391.032043,0.102324,0.000000
74.990005,213.712372,-391.076508,-0.000405,0.004009,0.101829,950.640137,48.427917,1.018288,-391.076508,0.103094,0.000000
75.450005,216.491028,-391.076508,-0.000388,0.004037,0.102531,963.000183,49.057568,1.025313,-391.076508,0.103858,0.000000
75.910004,219.621918,-391.076508,-0.000379,0.004071,0.103415,976.927063,49.767040,1.034154,-391.076508,0.104630,0.000000
76.370003,220.937531,-391.209961,-0.000379,0.004074,0.103468,982.779236,50.065159,1.034684,-391.209961,0.018187,0.000000
76.830002,220.377838,-391.165497,-0.000379,0.004071,0.103399,980.289612,49.938332,1.033988,-391.165497,982.000671,0.000000
77.290001,219.788391,-391.165497,-0.000379,0.004072,0.103425,977.667603,49.804760,1.034245,-391.165497,982.000671,0.000000
77.750000,220.050537,-391.165497,-0.000375,0.004089,0.103858,978.833679,49.864162,1.038575,-391.165497,982.000671,0.000000
78.210007,219.680023,-391.209961,-0.000375,0.004090,0.103876,977.185547,49.780205,1.038757,-391.209961,982.000671,0.000000
78.670006,219.610382,-391.209961,-0.000375,0.004093,0.103971,976.875793,49.764427,1.039711,-391.209961,982.000671,0.000000
79.130005,219.558258,-391.254456,-0.000371,0.004097,0.104066,976.643921,49.752613,1.040664,-391.254456,982.000671,0.000000
79.590004,219.488617,-391.254456,-0.000366,0.004100,0.104145,976.334106,49.736832,1.041452,-391.254456,982.000671,0.000000
80.050003,219.687469,-391.343414,-0.000349,0.004106,0.104283,977.218689,49.781891,1.042829,-391.343414,982.000671,0.000000
80.510002,219.478180,-391.343414,-0.000375,0.004107,0.104327,976.287720,49.734467,1.043268,-391.343414,982.000671,0.000000
80.970001,219.448761,-391.343414,-0.000358,0.004110,0.104396,976.156860,49.727802,1.043965,-391.343414,982.000671,0.000000
81.430000,219.369446,-391.387878,-0.000366,0.004118,0.104587,975.804016,49.709824,1.045872,-391.387878,982.000671,0.000000
81.890007,219.869934,-391.387878,-0.000384,0.004119,0.104630,978.030334,49.823238,1.046296,-391.387878,982.000671,0.000000
82.350006,219.612610,-391.476837,-0.000354,0.004119,0.104630,976.885681,49.764927,1.046296,-391.476837,982.000671,0.000000
82.810005,219.610382,-391.521332,-0.000354,0.004123,0.104734,976.875793,49.764427,1.047341,-391.521332,982.000671,0.000000
83.270004,219.452118,-391.521332,-0.000354,0.004124,0.104743,976.171753,49.728561,1.047432,-391.521332,982.000671,0.000000
83.730003,219.922424,-391.565826,-0.000362,0.004130,0.104908,978.263794,49.835133,1.049082,-391.565826,982.000671,0.000000
84.190002,219.693420,-391.521332,-0.000349,0.004130,0.104908,977.245117,49.783241,1.049082,-391.521332,982.000671,0.000000
84.650002,219.884827,-391.610291,-0.000341,0.004136,0.105055,978.096558,49.826614,1.050551,-391.610291,982.000671,0.000000
85.110001,219.792114,-391.610291,-0.000354,0.004136,0.105055,977.684143,49.805607,1.050551,-391.610291,982.000671,0.000000
85.570007,219.721344,-391.521332,-0.000358,0.004138,0.105107,977.369324,49.789566,1.051065,-391.521332,982.000671,0.000000
86.030006,219.725067,-391.699249,-0.000345,0.004140,0.105160,977.385925,49.790413,1.051595,-391.699249,982.000671,0.000000
86.490005,219.681519,-391.610291,-0.000345,0.004143,0.105220,977.192200,49.780544,1.052201,-391.610291,982.000671,0.000000
86.950005,219.662903,-391.743744,-0.000349,0.004144,0.105255,977.109375,49.776325,1.052549,-391.743744,982.000671,0.000000
87.410004,219.598480,-391.699249,-0.000349,0.004145,0.105290,976.822815,49.761726,1.052897,-391.699249,982.000671,0.000000
87.870003,219.589539,-391.699249,-0.000336,0.004147,0.105341,976.783081,49.759701,1.053412,-391.699249,982.000671,0.000000
88.330002,219.570526,-391.788208,-0.000349,0.004149,0.105385,976.698486,49.755390,1.053851,-391.788208,982.000671,0.000000
88.790001,219.527344,-391.788208,-0.000358,0.004150,0.105402,976.506409,49.745609,1.054018,-391.788208,982.000671,0.000000
89.250008,219.445435,-391.832703,-0.000358,0.004151,0.105437,976.142029,49.727043,1.054366,-391.832703,982.000671,0.000000
89.710007,219.335937,-391.921661,-0.000341,0.004151,0.105446,975.654968,49.702232,1.054457,-391.921661,982.000671,0.000000
90.170006,219.231323,-391.877167,-0.000336,0.004152,0.105462,975.189636,49.678528,1.054623,-391.877167,982.000671,0.000000
90.630005,220.057220,-391.877167,-0.000336,0.004161,0.105697,978.863403,49.865681,1.056970,-391.877167,982.000671,0.000000
91.090004,219.928772,-391.877167,-0.000349,0.004161,0.105697,978.292053,49.836571,1.056970,-391.877167,982.000671,0.000000
91.550003,219.812958,-391.877167,-0.000332,0.004161,0.105697,977.776855,49.810329,1.056970,-391.877167,982.000671,0.000000
92.010002,219.680389,-391.966125,-0.000336,0.004162,0.105714,977.187195,49.780289,1.057136,-391.966125,982.000671,0.000000
92.470001,219.583954,-391.966125,-0.000345,0.004162,0.105714,976.758240,49.758434,1.057136,-391.966125,982.000671,0.000000
92.930008,219.503510,-392.010620,-0.000354,0.004163,0.105748,976.400391,49.740204,1.057485,-392.010620,982.000671,0.000000
93.390007,219.433136,-392.055115,-0.000336,0.004164,0.105758,976.087341,49.724258,1.057575,-392.055115,982.000671,0.000000
93.850006,219.320679,-392.010620,-0.000332,0.004164,0.105758,975.587097,49.698776,1.057575,-392.010620,982.000671,0.000000
94.310005,219.172089,-392.099579,-0.000336,0.004164,0.105767,974.926147,49.665104,1.057666,-392.099579,982.000671,0.000000
94.770004,219.542999,-392.099579,-0.000336,0.004170,0.105923,976.576050,49.749153,1.059226,-392.099579,982.000671,0.000000
95.230003,219.486755,-392.099579,-0.000332,0.004170,0.105923,976.325867,49.736408,1.059226,-392.099579,982.000671,0.000000
95.690002,219.381012,-392.144073,-0.000323,0.004170,0.105923,975.855469,49.712444,1.059226,-392.144073,982.000671,0.000000
96.150002,219.282318,-392.188538,-0.000328,0.004170,0.105923,975.416443,49.690083,1.059226,-392.188538,982.000671,0.000000
96.610008,219.155731,-392.188538,-0.000328,0.004170,0.105923,974.853394,49.661400,1.059226,-392.188538,982.000671,0.000000
97.070007,219.084229,-392.277496,-0.000349,0.004173,0.105983,974.535339,49.645195,1.059831,-392.277496,982.000671,0.000000
97.530006,220.318268,-392.233032,-0.000328,0.004182,0.106234,980.024597,49.924835,1.062344,-392.233032,982.000671,0.000000
97.990005,220.180115,-392.233032,-0.000336,0.004182,0.106234,979.410095,49.893524,1.062344,-392.233032,982.000671,0.000000
98.450005,220.111603,-392.277496,-0.000341,0.004182,0.106234,979.105286,49.878002,1.062344,-392.277496,982.000671,0.000000
98.910004,220.024078,-392.321991,-0.000310,0.004182,0.106234,978.716003,49.858170,1.062344,-392.321991,982.000671,0.000000
99.370003,219.893768,-392.366455,-0.000323,0.004182,0.106234,978.136353,49.828640,1.062344,-392.366455,982.000671,0.000000
99.830002,219.811096,-392.366455,-0.000319,0.004183,0.106244,977.768616,49.809906,1.062435,-392.366455,982.000671,0.000000
100.290009,219.699371,-392.366455,-0.000328,0.004183,0.106244,977.271606,49.784592,1.062435,-392.366455,982.000671,0.000000
100.750008,219.602936,-392.410950,-0.000323,0.004183,0.106244,976.842651,49.762737,1.062435,-392.410950,982.000671,0.000000
101.210007,219.485626,-392.455444,-0.000315,0.004183,0.106260,976.320801,49.736153,1.062602,-392.455444,982.000671,0.000000
101.670006,219.607788,-392.499908,-0.000310,0.004187,0.106346,976.864258,49.763836,1.063465,-392.499908,982.000671,0.000000
102.130005,219.587311,-392.499908,-0.000323,0.004187,0.106346,976.773132,49.759193,1.063465,-392.499908,982.000671,0.000000
102.590004,219.528076,-392.544403,-0.000310,0.004187,0.106346,976.509644,49.745773,1.063465,-392.544403,982.000671,0.000000
103.050003,219.466278,-392.544403,-0.000319,0.004189,0.106399,976.234741,49.731770,1.063995,-392.544403,982.000671,0.000000
103.510002,219.542603,-392.544403,-0.000323,0.004190,0.106416,976.574280,49.749062,1.064161,-392.544403,982.000671,0.000000
103.970001,219.529205,-392.588867,-0.000319,0.004190,0.106434,976.514648,49.746029,1.064343,-392.588867,982.000671,0.000000
104.430008,219.498688,-392.588867,-0.000306,0.004190,0.106434,976.378906,49.739113,1.064343,-392.588867,982.000671,0.000000
104.890007,219.519165,-392.633362,-0.000310,0.004192,0.106486,976.470032,49.743755,1.064857,-392.633362,982.000671,0.000000
105.350006,219.496826,-392.677826,-0.000306,0.004192,0.106486,976.370667,49.738693,1.064857,-392.677826,982.000671,0.000000
105.810005,219.444305,-392.677826,-0.000336,0.004192,0.106486,976.137024,49.726791,1.064857,-392.677826,982.000671,0.000000
106.270004,219.486023,-392.677826,-0.000319,0.004195,0.106564,976.322571,49.736244,1.065645,-392.677826,982.000671,0.000000
106.730003,219.530701,-392.722321,-0.000310,0.004195,0.106564,976.521301,49.746368,1.065645,-392.722321,982.000671,0.000000
107.190002,219.515442,-392.766785,-0.000310,0.004195,0.106564,976.453430,49.742912,1.065645,-392.766785,982.000671,0.000000
107.650002,219.466278,-392.811279,-0.000332,0.004196,0.106590,976.234741,49.731770,1.065902,-392.811279,982.000671,0.000000
108.110008,219.455841,-392.722321,-0.000319,0.004197,0.106607,976.188354,49.729404,1.066069,-392.722321,982.000671,0.000000
108.570007,219.616730,-392.855774,-0.000328,0.004200,0.106667,976.903992,49.765862,1.066674,-392.855774,982.000671,0.000000
109.030006,219.599945,-392.855774,-0.000315,0.004200,0.106667,976.829346,49.762058,1.066674,-392.855774,982.000671,0.000000
109.490005,219.551910,-392.900238,-0.000302,0.004200,0.106667,976.615662,49.751175,1.066674,-392.900238,982.000671,0.000000
109.950005,219.489746,-392.944733,-0.000302,0.004200,0.106667,976.339172,49.737087,1.066674,-392.944733,982.000671,0.000000
110.410004,219.430908,-392.944733,-0.000323,0.004200,0.106667,976.077454,49.723755,1.066674,-392.944733,982.000671,0.000000
110.870003,219.399994,-392.944733,-0.000302,0.004200,0.106677,975.939941,49.716747,1.066765,-392.944733,982.000671,0.000000
111.330002,219.356415,-392.900238,-0.000315,0.004200,0.106677,975.746094,49.706875,1.066765,-392.900238,982.000671,0.000000
111.790009,219.298706,-392.989197,-0.000306,0.004200,0.106677,975.489380,49.693798,1.066765,-392.989197,982.000671,0.000000
112.250008,220.262421,-393.078156,-0.000315,0.004211,0.106954,979.776184,49.912178,1.069536,-393.078156,982.000671,0.000000
112.710007,220.203217,-393.033691,-0.000310,0.004207,0.106867,979.512817,49.898762,1.068673,-393.033691,982.000671,0.000000
113.170006,220.135071,-393.078156,-0.000310,0.004207,0.106867,979.209717,49.883320,1.068673,-393.078156,982.000671,0.000000
113.630005,220.082550,-393.167114,-0.000302,0.004207,0.106867,978.976074,49.871422,1.068673,-393.167114,982.000671,0.000000
114.090004,220.010315,-393.122650,-0.000306,0.004207,0.106867,978.654785,49.855053,1.068673,-393.122650,982.000671,0.000000
114.550003,219.919830,-393.167114,-0.000310,0.004207,0.106867,978.252258,49.834545,1.068673,-393.167114,982.000671,0.000000
115.010002,219.862488,-393.256104,-0.000302,0.004207,0.106867,977.997192,49.821552,1.068673,-393.256104,982.000671,0.000000
115.470009,219.805511,-393.256104,-0.000310,0.004207,0.106867,977.743774,49.808640,1.068673,-393.256104,982.000671,0.000000
115.930008,219.743683,-393.256104,-0.000323,0.004207,0.106867,977.468750,49.794628,1.068673,-393.256104,982.000671,0.000000
116.390007,219.664368,-393.211609,-0.000319,0.004208,0.106876,977.115906,49.776657,1.068763,-393.211609,982.000671,0.000000
116.850006,219.612610,-393.345062,-0.000315,0.004208,0.106885,976.885681,49.764927,1.068854,-393.345062,982.000671,0.000000
117.310005,219.552673,-393.300568,-0.000310,0.004208,0.106885,976.619080,49.751347,1.068854,-393.300568,982.000671,0.000000
117.770004,219.494965,-393.389526,-0.000302,0.004209,0.106911,976.362366,49.738270,1.069112,-393.389526,982.000671,0.000000
118.230003,219.919067,-393.389526,-0.000310,0.004217,0.107111,978.248840,49.834373,1.071110,-393.389526,982.000671,0.000000
118.690002,220.104156,-393.345062,-0.000315,0.004217,0.107111,979.072205,49.876312,1.071110,-393.345062,982.000671,0.000000
119.150009,220.119415,-393.434021,-0.000306,0.004217,0.107111,979.140076,49.879772,1.071110,-393.434021,982.000671,0.000000
119.610008,220.088898,-393.389526,-0.000319,0.004217,0.107111,979.004333,49.872860,1.071110,-393.389526,982.000671,0.000000
120.070007,220.066925,-393.478485,-0.000306,0.004217,0.107111,978.906555,49.867878,1.071110,-393.478485,982.000671,0.000000
120.530006,220.033020,-393.522980,-0.000310,0.004217,0.107111,978.755737,49.860195,1.071110,-393.522980,982.000671,0.000000
120.990005,219.970459,-393.478485,-0.000319,0.004217,0.107111,978.477478,49.846020,1.071110,-393.478485,982.000671,0.000000
121.450005,219.929504,-393.567444,-0.000297,0.004217,0.107111,978.295288,49.836739,1.071110,-393.567444,982.000671,0.000000
121.910004,219.877747,-393.478485,-0.000297,0.004217,0.107111,978.065063,49.825008,1.071110,-393.478485,982.000671,0.000000
122.370003,219.844604,-393.567444,-0.000306,0.004217,0.107111,977.917664,49.817497,1.071110,-393.567444,982.000671,0.000000
122.830009,219.809601,-393.611938,-0.000285,0.004217,0.107111,977.761963,49.809566,1.071110,-393.611938,982.000671,0.000000
123.290009,219.760437,-393.656403,-0.000306,0.004217,0.107111,977.543274,49.798424,1.071110,-393.656403,982.000671,0.000000
123.750008,219.703491,-393.700897,-0.000293,0.004217,0.107119,977.289917,49.785522,1.071186,-393.700897,982.000671,0.000000
124.210007,219.651733,-393.656403,-0.000306,0.004218,0.107137,977.059692,49.773792,1.071368,-393.656403,982.000671,0.000000
124.670006,219.680023,-393.656403,-0.000306,0.004219,0.107153,977.185547,49.780205,1.071534,-393.656403,982.000671,0.000000
125.130005,219.659546,-393.745392,-0.000293,0.004219,0.107172,977.094482,49.775562,1.071716,-393.745392,982.000671,0.000000
125.590004,219.677032,-393.745392,-0.000310,0.004220,0.107179,977.172241,49.779526,1.071791,-393.745392,982.000671,0.000000
126.050003,219.675171,-393.789856,-0.000310,0.004220,0.107188,977.163940,49.779106,1.071882,-393.789856,982.000671,0.000000
126.510010,219.653595,-393.745392,-0.000319,0.004220,0.107188,977.067993,49.774216,1.071882,-393.745392,982.000671,0.000000
126.970009,219.623779,-393.834351,-0.000302,0.004220,0.107188,976.935364,49.767456,1.071882,-393.834351,982.000671,0.000000
127.430008,219.591400,-393.923309,-0.000319,0.004220,0.107188,976.791321,49.760124,1.071882,-393.923309,982.000671,0.000000
127.890007,219.563843,-393.878815,-0.000302,0.004220,0.107188,976.668762,49.753880,1.071882,-393.878815,982.000671,0.000000
128.350006,219.523621,-393.967773,-0.000289,0.004220,0.107188,976.489807,49.744766,1.071882,-393.967773,982.000671,0.000000
128.810013,219.494568,-393.967773,-0.000302,0.004220,0.107188,976.360596,49.738178,1.071882,-393.967773,982.000671,0.000000
129.270004,219.458466,-393.923309,-0.000302,0.004220,0.107197,976.200012,49.730000,1.071973,-393.923309,982.000671,0.000000
129.730011,219.413391,-394.056732,-0.000310,0.004220,0.107197,975.999512,49.719784,1.071973,-394.056732,982.000671,0.000000
130.190002,219.426819,-393.967773,-0.000306,0.004222,0.107240,976.059265,49.722828,1.072397,-393.967773,982.000671,0.000000
130.650009,219.473724,-394.012268,-0.000302,0.004223,0.107258,976.267883,49.733459,1.072579,-394.012268,982.000671,0.000000
131.110001,219.461060,-393.967773,-0.000302,0.004223,0.107258,976.211548,49.730587,1.072579,-393.967773,982.000671,0.000000
131.570007,219.444305,-394.012268,-0.000293,0.004223,0.107258,976.137024,49.726791,1.072579,-394.012268,982.000671,0.000000
132.029999,219.415649,-394.145721,-0.000302,0.004223,0.107267,976.009583,49.720299,1.072670,-394.145721,982.000671,0.000000
132.490005,219.427917,-394.145721,-0.000310,0.004224,0.107284,976.064148,49.723076,1.072836,-394.145721,982.000671,0.000000
132.950012,219.408936,-394.145721,-0.000306,0.004224,0.107302,975.979675,49.718773,1.073018,-394.145721,982.000671,0.000000
133.410004,219.516174,-394.145721,-0.000319,0.004226,0.107335,976.456726,49.743076,1.073351,-394.145721,982.000671,0.000000
133.870010,219.512451,-394.190186,-0.000293,0.004226,0.107335,976.440125,49.742233,1.073351,-394.190186,982.000671,0.000000
134.330002,219.514313,-394.190186,-0.000310,0.004226,0.107344,976.448425,49.742653,1.073442,-394.190186,982.000671,0.000000
134.790009,219.499054,-394.234680,-0.000306,0.004226,0.107344,976.380554,49.739197,1.073442,-394.234680,982.000671,0.000000
135.250000,219.492340,-394.279144,-0.000293,0.004226,0.107344,976.350708,49.737675,1.073442,-394.279144,982.000671,0.000000
135.710007,219.532196,-394.323639,-0.000306,0.004228,0.107388,976.527954,49.746708,1.073881,-394.323639,982.000671,0.000000
136.170013,219.548187,-394.368103,-0.000293,0.004228,0.107388,976.599121,49.750328,1.073881,-394.368103,982.000671,0.000000
136.630005,219.552673,-394.457062,-0.000302,0.004228,0.107388,976.619080,49.751347,1.073881,-394.457062,5607.367676,0.000000
137.090012,219.497559,-394.323639,-0.000315,0.004214,0.107032,976.373901,49.738857,1.070323,-394.323639,0.107023,0.000000
137.550003,219.344147,-394.412598,-0.000297,0.004193,0.106511,975.691467,49.704094,1.065115,-394.412598,0.106260,0.000000
138.010010,219.047729,-394.457062,-0.000289,0.004170,0.105913,974.372986,49.636925,1.059135,-394.457062,0.105497,0.000000
138.470001,217.728424,-394.457062,-0.000289,0.004143,0.105220,968.504395,49.337967,1.052201,-394.457062,0.104725,0.000000
138.930008,216.909210,-394.546051,-0.000276,0.004118,0.104604,964.860352,49.152328,1.046039,-394.546051,0.103962,0.000000
139.389999,216.451935,-394.457062,-0.000224,0.004092,0.103927,962.826294,49.048710,1.039272,-394.457062,0.103190,0.000000
139.850006,216.205414,-394.546051,-0.000190,0.004055,0.103008,961.729736,48.992847,1.030082,-394.546051,0.102427,0.000000
140.310013,215.793182,-394.590515,-0.000216,0.004022,0.102159,959.895996,48.899437,1.021589,-394.590515,0.101656,0.000000
140.770004,215.558228,-394.590515,-0.000185,0.004001,0.101621,958.850891,48.846191,1.016214,-394.590515,0.100892,0.000000
141.230011,214.676453,-394.723969,-0.000194,0.003969,0.100805,954.928528,48.646381,1.008054,-394.723969,0.100129,0.000000
141.690002,213.704926,-394.635010,-0.000216,0.003935,0.099947,950.606995,48.426228,0.999470,-394.635010,0.099358,0.000000
142.150009,212.276123,-394.635010,-0.000211,0.003909,0.099296,944.251343,48.102455,0.992960,-394.635010,0.098593,0.000000
142.610001,210.876404,-394.723969,-0.000203,0.003883,0.098628,938.025085,47.785278,0.986283,-394.723969,0.097823,0.000000
143.070007,208.582581,-394.679474,-0.000216,0.003853,0.097865,927.821655,47.265488,0.978653,-394.679474,0.097060,0.000000
143.530014,205.664673,-394.768433,-0.000203,0.003820,0.097025,914.842163,46.604282,0.970250,-394.768433,0.096295,0.000000
143.990005,202.819733,-394.768433,-0.000211,0.003794,0.096357,902.187256,45.959610,0.963574,-394.768433,0.095525,0.000000
144.450012,199.066956,-394.901886,-0.000198,0.003760,0.095497,885.494019,45.109219,0.954974,-394.901886,0.094762,0.000000
144.910004,196.272308,-394.812927,-0.000211,0.003733,0.094822,873.062805,44.475941,0.948222,-394.812927,0.093990,0.000000
145.370010,192.737000,-394.857391,-0.000203,0.003701,0.093999,857.336975,43.674831,0.939986,-394.857391,0.093226,0.000000
145.830002,189.129089,-394.946350,-0.000198,0.003672,0.093261,841.288208,42.857262,0.932613,-394.946350,0.092463,0.000000
146.290009,185.871582,-394.857391,-0.000211,0.003642,0.092506,826.798096,42.119102,0.925059,-394.857391,0.091691,0.000000
146.750000,183.931152,-394.946350,-0.000203,0.003617,0.091873,818.166626,41.679394,0.918730,-394.946350,0.090928,0.000000
147.210007,179.877502,-394.946350,-0.000194,0.003585,0.091049,800.135071,40.760826,0.910494,-394.946350,0.090156,0.000000
147.670013,176.147446,-394.990845,-0.000185,0.003552,0.090217,783.542969,39.915585,0.902168,-394.990845,0.089393,0.000000
148.130005,173.152451,-394.990845,-0.000211,0.003527,0.089575,770.220581,39.236908,0.895748,-394.990845,0.088621,0.000000
148.590012,169.740402,-394.990845,-0.000203,0.003497,0.088828,755.043030,38.463726,0.888285,-394.990845,0.087858,0.000000
149.050003,166.143661,-395.035339,-0.000198,0.003466,0.088049,739.043945,37.648693,0.880488,-395.035339,0.087095,0.000000
149.510010,162.287735,-395.124298,-0.000203,0.003433,0.087207,721.891907,36.774925,0.872070,-395.124298,0.086323,0.000000
149.970001,158.113068,-395.079803,-0.000198,0.003399,0.086332,703.322021,35.828934,0.863319,-395.079803,0.085560,0.000000
150.430008,155.201126,-395.168762,-0.000203,0.003376,0.085741,690.369080,35.169079,0.857415,-395.168762,0.084788,0.000000
150.890015,151.347809,-395.124298,-0.000198,0.003341,0.084866,673.228699,34.295902,0.848664,-395.124298,0.084025,0.000000
151.350006,147.884369,-395.213257,-0.000185,0.003313,0.084155,657.822510,33.511074,0.841549,-395.213257,0.083262,0.000000
151.810013,143.977814,-395.213257,-0.000211,0.003281,0.083340,640.445312,32.625839,0.833404,-395.213257,0.082490,0.000000
152.270004,140.166962,-395.257721,-0.000198,0.003250,0.082543,623.493774,31.762287,0.825425,-395.257721,0.081726,0.000000
152.730011,137.221481,-395.302216,-0.000224,0.003220,0.081778,610.391663,31.094831,0.817780,-395.302216,0.080954,0.000000
153.190002,133.378983,-395.302216,-0.000203,0.003190,0.081033,593.299316,30.224110,0.810331,-395.302216,0.080191,0.000000
153.650009,129.947571,-395.346680,-0.000185,0.003160,0.080261,578.035645,29.446541,0.802610,-395.346680,0.079428,0.000000
154.110001,125.875671,-395.302216,-0.000198,0.003124,0.079359,559.922974,28.523836,0.793586,-395.302216,0.078656,0.000000
154.570007,123.864853,-395.346680,-0.000211,0.003105,0.078865,550.978394,28.068178,0.788651,-395.346680,0.077893,0.000000
155.030014,119.533798,-395.435669,-0.000198,0.003066,0.077886,531.712891,27.086746,0.778856,-395.435669,0.077121,0.000000
155.490005,116.013016,-395.391174,-0.000203,0.003038,0.077174,516.051697,26.288925,0.771740,-395.391174,0.076358,0.000000
155.950012,111.988785,-395.391174,-0.000211,0.003003,0.076281,498.151001,25.377020,0.762808,-395.391174,0.075595,0.000000
156.410004,109.956375,-395.435669,-0.000207,0.002984,0.075795,489.110382,24.916471,0.757948,-395.435669,0.074823,0.000000
156.870010,106.924896,-395.435669,-0.000203,0.002955,0.075057,475.625702,24.229528,0.750575,-395.435669,0.074060,0.000000
157.330002,102.379715,-395.569092,-0.000198,0.002918,0.074120,455.407715,23.199575,0.741204,-395.569092,0.073289,0.000000
157.790009,99.061127,-395.524628,-0.000194,0.002884,0.073262,440.645905,22.447573,0.732619,-395.524628,0.072525,0.000000
158.250000,95.952560,-395.524628,-0.000203,0.002863,0.072717,426.818298,21.743160,0.727169,-395.524628,0.071754,0.000000
158.710007,93.119186,-395.569092,-0.000190,0.002838,0.072092,414.214844,21.101109,0.720917,-395.569092,0.070991,0.000000
159.170013,88.380371,-395.569092,-0.000203,0.002795,0.070991,393.135529,20.027277,0.709910,-395.569092,0.070228,0.000000
159.630005,85.637482,-395.702545,-0.000190,0.002772,0.070419,380.934540,19.405731,0.704187,-395.702545,0.069456,0.000000
160.090012,82.238831,-395.613586,-0.000185,0.002741,0.069621,365.816589,18.635586,0.696209,-395.613586,0.068693,0.000000
160.550003,79.243469,-395.658051,-0.000198,0.002716,0.068987,352.492554,17.956827,0.689865,-395.658051,0.067921,0.000000
161.010010,75.860840,-395.702545,-0.000203,0.002685,0.068198,337.445862,17.190313,0.681978,-395.702545,0.067158,0.000000
161.470001,72.251801,-395.658051,-0.000198,0.002652,0.067365,321.392059,16.372492,0.673651,-395.658051,0.066395,0.000000
161.930008,68.846832,-395.791504,-0.000172,0.002619,0.066532,306.246002,15.600915,0.665324,-395.791504,0.065623,0.000000
162.390015,65.962799,-395.747009,-0.000207,0.002596,0.065943,293.417175,14.947384,0.659435,-395.747009,0.064859,0.000000
162.850006,62.151199,-395.835999,-0.000190,0.002557,0.064955,276.462341,14.083664,0.649549,-395.835999,0.064087,0.000000
163.310013,58.656487,-395.880463,-0.000194,0.002528,0.064208,260.917084,13.291750,0.642085,-395.880463,0.063324,0.000000
163.770004,55.427269,-395.835999,-0.000194,0.002497,0.063429,246.552811,12.559999,0.634288,-395.835999,0.062561,0.000000
164.230011,52.400627,-395.880463,-0.000203,0.002470,0.062743,233.089630,11.874152,0.627430,-395.880463,0.061789,0.000000
164.690002,49.404518,-395.924957,-0.000185,0.002444,0.062075,219.762268,11.195224,0.620753,-395.924957,0.061026,0.000000
165.150009,45.402260,-395.924957,-0.000203,0.002408,0.061156,201.959335,10.288299,0.611563,-395.924957,0.060254,0.000000
165.610001,42.593826,-395.924957,-0.000220,0.002381,0.060489,189.466797,9.651899,0.604887,-395.924957,0.059491,0.000000
166.070007,39.799911,-396.013916,-0.000194,0.002357,0.059863,177.038849,9.018789,0.598634,-396.013916,0.058719,0.000000
166.530014,35.899689,-396.058380,-0.000203,0.002319,0.058910,159.689789,8.134986,0.589096,-396.058380,0.057956,0.000000
166.990005,32.229958,-396.013916,-0.000198,0.002287,0.058086,143.366013,7.303412,0.580860,-396.013916,0.057193,0.000000
167.450012,28.458191,-396.058380,-0.000194,0.002251,0.057184,126.588356,6.448718,0.571837,-396.058380,0.056421,0.000000
167.910004,26.482018,-396.102875,-0.000207,0.002234,0.056751,117.797897,6.000911,0.567507,-396.102875,0.055658,0.000000
168.370010,23.278122,-396.013916,-0.000190,0.002205,0.056013,103.546257,5.274898,0.560134,-396.013916,0.054886,0.000000
168.830002,20.114449,-396.147339,-0.000207,0.002174,0.055216,89.473534,4.558000,0.552156,-396.147339,0.054122,0.000000
169.290009,16.894539,-396.102875,-0.000181,0.002145,0.054478,75.150665,3.828357,0.544783,-396.102875,0.053359,0.000000
169.750015,13.124641,-396.147339,-0.000198,0.002110,0.053585,58.381321,2.974086,0.535850,-396.147339,0.052587,0.000000
170.210007,10.657303,-396.236298,-0.000198,0.002085,0.052952,47.406052,2.414979,0.529522,-396.236298,0.051824,0.000000
170.670013,8.029099,-396.236298,-0.000198,0.002054,0.052171,35.715214,1.819420,0.521710,-396.236298,0.051052,0.000000
171.130005,4.065933,-396.236298,-0.000194,0.002020,0.051313,18.086174,0.921354,0.513126,-396.236298,0.050289,0.000000
171.590012,0.609573,-396.280792,-0.000198,0.001982,0.050350,2.711518,0.138131,0.503497,-396.280792,0.049526,0.000000
172.050003,-0.619629,-396.325287,-0.000185,0.001969,0.050021,-2.756247,-0.140410,0.500212,-396.325287,0.048754,0.000000
172.510010,-0.468071,-396.325287,-0.000203,0.001936,0.049179,-2.082084,-0.106066,0.491794,-396.325287,0.047991,0.000000
172.970001,-0.129585,-396.280792,-0.000190,0.001897,0.048191,-0.576424,-0.029364,0.481908,-396.280792,0.047220,0.000000
173.430008,-0.133682,-396.414246,-0.000185,0.001873,0.047575,-0.594648,-0.030293,0.475746,-396.414246,0.046457,0.000000
173.890015,-0.086388,-396.369751,-0.000177,0.001839,0.046700,-0.384271,-0.019576,0.466995,-396.369751,0.045693,0.000000
174.350006,-0.078568,-396.458710,-0.000181,0.001812,0.046023,-0.349486,-0.017804,0.460228,-396.458710,0.044922,0.000000
174.810013,-0.124374,-396.414246,-0.000220,0.001774,0.045069,-0.553245,-0.028184,0.450690,-396.414246,0.044159,0.000000
175.270004,-0.139267,-396.458710,-0.000211,0.001752,0.044497,-0.619490,-0.031558,0.444967,-396.458710,0.043387,0.000000
175.730011,-0.110596,-396.503204,-0.000293,0.001723,0.043769,-0.491954,-0.025061,0.437685,-396.503204,0.042624,0.000000
176.190002,-0.106125,-396.503204,-0.000341,0.001698,0.043136,-0.472067,-0.024048,0.431357,-396.503204,0.041852,0.000000
176.650009,-0.124001,-396.503204,-0.000401,0.001661,0.042189,-0.551582,-0.028099,0.421895,-396.503204,0.041089,0.000000
177.110016,-0.134422,-396.592163,-0.000453,0.001629,0.041375,-0.597940,-0.030461,0.413750,-396.592163,0.040326,0.000000
177.570007,-0.117294,-396.547668,-0.000513,0.001598,0.040594,-0.521751,-0.026579,0.405938,-396.547668,0.039554,0.000000
178.030014,-0.133308,-396.636627,-0.000548,0.001566,0.039788,-0.592985,-0.030208,0.397883,-396.636627,0.038791,0.000000
178.490005,-0.125114,-396.636627,-0.000595,0.001538,0.039059,-0.556537,-0.028351,0.390586,-396.636627,0.038019,0.000000
178.950012,-0.113197,-396.592163,-0.000638,0.001507,0.038279,-0.503527,-0.025651,0.382789,-396.592163,0.037255,0.000000
179.410004,-0.086014,-396.681122,-0.000681,0.001473,0.037402,-0.382608,-0.019491,0.374023,-396.681122,0.036492,0.000000
179.870010,-0.115807,-396.681122,-0.000729,0.001452,0.036883,-0.515133,-0.026242,0.368830,-396.681122,0.035720,0.000000
180.330002,-0.129211,-396.725616,-0.000780,0.001414,0.035920,-0.574761,-0.029280,0.359202,-396.725616,0.034957,0.000000
180.790009,-0.121765,-396.725616,-0.000819,0.001384,0.035148,-0.541638,-0.027592,0.351480,-396.725616,0.034185,0.000000
181.250015,-0.084526,-396.725616,-0.000862,0.001353,0.034367,-0.375991,-0.019154,0.343668,-396.725616,0.033422,0.000000
181.710007,-0.101280,-396.814575,-0.000884,0.001330,0.033787,-0.450517,-0.022950,0.337870,-396.814575,0.032659,0.000000
182.170013,-0.108734,-396.814575,-0.000936,0.001297,0.032936,-0.483674,-0.024640,0.329362,-396.814575,0.031887,0.000000
182.630005,-0.115059,-396.859039,-0.000961,0.001265,0.032138,-0.511808,-0.026073,0.321383,-396.859039,0.031124,0.000000
183.090012,-0.062553,-396.859039,-0.000987,0.001242,0.031540,-0.278251,-0.014175,0.315403,-396.859039,0.030352,0.000000
183.550003,-0.048409,-396.814575,-0.001000,0.001213,0.030803,-0.215332,-0.010970,0.308030,-396.814575,0.029589,0.000000
184.010010,-0.069260,-396.947998,-0.001043,0.001178,0.029910,-0.308082,-0.015694,0.299098,-396.947998,0.028817,0.000000
184.470001,-0.116920,-396.903534,-0.001082,0.001143,0.029026,-0.520088,-0.026495,0.290256,-396.903534,0.028054,0.000000
184.930008,-0.074097,-396.947998,-0.001121,0.001119,0.028435,-0.329598,-0.016791,0.284352,-396.947998,0.027291,0.000000
185.390015,-0.053993,-396.992493,-0.001181,0.001091,0.027716,-0.240174,-0.012235,0.277160,-396.992493,0.026518,0.000000
185.850006,-0.045425,-396.992493,-0.001194,0.001062,0.026970,-0.202062,-0.010294,0.269696,-396.992493,0.025755,0.000000
186.310013,-0.092720,-397.036957,-0.001229,0.001023,0.025981,-0.412439,-0.021011,0.259810,-397.036957,0.024983,0.000000
186.770004,-0.093834,-397.036957,-0.001268,0.000996,0.025304,-0.417394,-0.021263,0.253043,-397.036957,0.024220,0.000000
187.230011,-0.067772,-396.947998,-0.001268,0.000963,0.024464,-0.301465,-0.015357,0.244640,-396.947998,0.023457,0.000000
187.500015,-0.081551,-397.081451,-0.001285,0.000964,0.024481,-0.362755,-0.018480,0.244807,-397.081451,0.024378,0.000000