File: Data/sima compression 500bar/P2-15-500bar-4_11072024_174722.csv
Time (sec),S:Load (lbs),S:HL1 (DIM),S:LVDT (in),S:Position (in),Ch:Position (mm),Ch:Load (N),Ch:Stress (MPa),Ch:Strain (mm/mm),Ch:HL1 (DIM),Set Point (),Cycles ()
0.010000,-0.071495,-498.142181,-0.008817,-0.005768,-0.146509,-0.318026,-0.016201,-1.465087,-498.142181,-0.146318,0.000000
0.450000,-0.074844,-498.186646,-0.008830,-0.005695,-0.144653,-0.332924,-0.016960,-1.446526,-498.186646,-0.144029,0.000000
0.890000,-0.058090,-498.186646,-0.008645,-0.005431,-0.137941,-0.258398,-0.013163,-1.379413,-498.186646,-0.136692,0.000000
1.330000,-0.054367,-498.186646,-0.008313,-0.005133,-0.130379,-0.241837,-0.012320,-1.303790,-498.186646,-0.129356,0.000000
1.770000,-0.090485,-498.275604,-0.008019,-0.004844,-0.123042,-0.402496,-0.020504,-1.230424,-498.275604,-0.122036,0.000000
2.210000,-0.071869,-498.320099,-0.007722,-0.004556,-0.115713,-0.319689,-0.016286,-1.157133,-498.320099,-0.114699,0.000000
2.650000,-0.064049,-498.364563,-0.007424,-0.004268,-0.108395,-0.284903,-0.014514,-1.083948,-498.364563,-0.107362,0.000000
3.090000,-0.091599,-498.320099,-0.007118,-0.003982,-0.101145,-0.407451,-0.020757,-1.011445,-498.320099,-0.100044,0.000000
3.530000,-0.062187,-498.409058,-0.006829,-0.003687,-0.093652,-0.276622,-0.014092,-0.936519,-498.409058,-0.092707,0.000000
3.970000,-0.083778,-498.409058,-0.006506,-0.003410,-0.086611,-0.372665,-0.018984,-0.866105,-498.409058,-0.085387,0.000000
4.410000,-0.109474,-498.364563,-0.006222,-0.003109,-0.078979,-0.486965,-0.024807,-0.789786,-498.364563,-0.078051,0.000000
4.850000,-0.080803,-498.453552,-0.005954,-0.002829,-0.071868,-0.359429,-0.018310,-0.718676,-498.453552,-0.070714,0.000000
5.290000,-0.055855,-498.453552,-0.005622,-0.002534,-0.064357,-0.248455,-0.012657,-0.643568,-498.453552,-0.063394,0.000000
5.730000,-0.059578,-498.453552,-0.005355,-0.002255,-0.057290,-0.265016,-0.013501,-0.572897,-498.453552,-0.056057,0.000000
6.170000,-0.099052,-498.453552,-0.005036,-0.001956,-0.049693,-0.440607,-0.022446,-0.496926,-498.453552,-0.048721,0.000000
6.610000,-0.148575,-498.453552,-0.004756,-0.001670,-0.042424,-0.660894,-0.033668,-0.424241,-498.453552,-0.041402,0.000000
7.050000,-0.048035,-498.498016,-0.004449,-0.001383,-0.035122,-0.213669,-0.010885,-0.351223,-498.498016,-0.034064,0.000000
7.490000,-0.025322,-498.409058,-0.004148,-0.001095,-0.027820,-0.112638,-0.005738,-0.278205,-498.409058,-0.026746,0.000000
7.930000,-0.094582,-498.586975,-0.003846,-0.000808,-0.020519,-0.420720,-0.021432,-0.205187,-498.586975,-0.019409,0.000000
8.370001,-0.094582,-498.542511,-0.003557,-0.000515,-0.013087,-0.420720,-0.021432,-0.130867,-498.542511,-0.012072,0.000000
8.810000,-0.052505,-498.586975,-0.003264,-0.000233,-0.005915,-0.233556,-0.011898,-0.059150,-498.586975,-0.004752,0.000000
9.250000,0.088623,-498.631470,-0.003001,-0.000001,-0.000017,0.394215,0.020082,-0.000167,-498.631470,0.000226,0.000000
9.690001,0.086395,-498.586975,-0.002997,-0.000001,-0.000017,0.384305,0.019577,-0.000167,-498.586975,0.000226,0.000000
10.130000,0.125862,-498.631470,-0.003005,0.000002,0.000061,0.559863,0.028521,0.000606,-498.631470,0.000902,0.000000
10.570001,0.280769,-498.675934,-0.002992,0.000020,0.000512,1.248924,0.063623,0.005117,-498.675934,0.001640,0.000000
11.010000,0.699692,-498.586975,-0.002984,0.000051,0.001293,3.112385,0.158552,0.012929,-498.586975,0.002377,0.000000
11.450001,1.392677,-498.720428,-0.002940,0.000084,0.002126,6.194938,0.315585,0.021256,-498.720428,0.003105,0.000000
11.890000,2.463989,-498.675934,-0.002923,0.000120,0.003054,10.960372,0.558348,0.030537,-498.675934,0.003842,0.000000
12.330001,3.253044,-498.720428,-0.002902,0.000142,0.003617,14.470263,0.737150,0.036168,-498.720428,0.004571,0.000000
12.770000,4.426018,-498.764893,-0.002889,0.000174,0.004431,19.687910,1.002950,0.044314,-498.764893,0.005308,0.000000
13.210001,5.353226,-498.764893,-0.002884,0.000201,0.005117,23.812338,1.213058,0.051172,-498.764893,0.006036,0.000000
13.650001,6.652809,-498.764893,-0.002846,0.000232,0.005880,29.593174,1.507548,0.058802,-498.764893,0.006773,0.000000
14.090001,7.910309,-498.764893,-0.002811,0.000264,0.006696,35.186810,1.792502,0.066962,-498.764893,0.007511,0.000000
14.530001,8.830444,-498.853851,-0.002820,0.000285,0.007241,39.279778,2.001007,0.072413,-498.853851,0.008239,0.000000
14.970000,10.319931,-498.809387,-0.002785,0.000318,0.008074,45.905346,2.338530,0.080739,-498.809387,0.008976,0.000000
15.410001,11.456413,-498.764893,-0.002768,0.000345,0.008760,50.960670,2.596060,0.087598,-498.764893,0.009704,0.000000
15.850000,12.779823,-498.809387,-0.002751,0.000378,0.009592,56.847492,2.895949,0.095924,-498.809387,0.010442,0.000000
16.290001,13.466850,-498.809387,-0.002729,0.000396,0.010069,59.903542,3.051632,0.100693,-498.809387,0.011170,0.000000
16.730001,15.443779,-498.898346,-0.002721,0.000439,0.011162,68.697357,3.499610,0.111624,-498.898346,0.011907,0.000000
17.170000,15.748009,-498.942841,-0.002690,0.000459,0.011647,70.050644,3.568550,0.116469,-498.942841,0.012645,0.000000
17.610001,17.328354,-498.898346,-0.002686,0.000492,0.012498,77.080368,3.926661,0.124977,-498.898346,0.013373,0.000000
18.050001,18.273811,-498.987305,-0.002673,0.000522,0.013252,81.285973,4.140905,0.132517,-498.987305,0.014110,0.000000
18.490002,19.034935,-498.898346,-0.002660,0.000546,0.013868,84.671623,4.313378,0.138679,-498.898346,0.014838,0.000000
18.930000,20.159874,-498.987305,-0.002647,0.000578,0.014691,89.675598,4.568293,0.146914,-498.987305,0.015576,0.000000
19.370001,20.904991,-498.987305,-0.002617,0.000607,0.015411,92.990044,4.737139,0.154106,-498.987305,0.016304,0.000000
19.810001,21.733521,-498.987305,-0.002591,0.000637,0.016183,96.675529,4.924886,0.161827,-498.987305,0.017041,0.000000
20.250002,21.579727,-499.031799,-0.002583,0.000652,0.016573,95.991417,4.890036,0.165733,-499.031799,0.017778,0.000000
20.690001,23.329880,-499.031799,-0.002552,0.000698,0.017727,103.776489,5.286626,0.177269,-499.031799,0.018507,0.000000
21.130001,23.590546,-499.165222,-0.002552,0.000725,0.018404,104.935989,5.345694,0.184037,-499.165222,0.019244,0.000000
21.570002,24.178146,-499.120758,-0.002531,0.000754,0.019149,107.549767,5.478847,0.191485,-499.120758,0.019972,0.000000
22.010000,24.423538,-499.120758,-0.002518,0.000777,0.019747,108.641327,5.534453,0.197466,-499.120758,0.020709,0.000000
22.450001,25.504166,-499.209717,-0.002492,0.000813,0.020658,113.448196,5.779326,0.206580,-499.209717,0.021438,0.000000
22.890001,25.399155,-499.165222,-0.002488,0.000836,0.021239,112.981079,5.755530,0.212393,-499.165222,0.022175,0.000000
23.330002,26.019531,-499.254181,-0.002466,0.000868,0.022054,115.740654,5.896110,0.220538,-499.254181,0.022905,0.000000
23.770000,26.512550,-499.209717,-0.002427,0.000898,0.022800,117.933716,6.007830,0.228002,-499.209717,0.023640,0.000000
24.210001,27.117279,-499.254181,-0.002414,0.000924,0.023477,120.623680,6.144863,0.234769,-499.254181,0.024378,0.000000
24.650002,27.691849,-499.298676,-0.002397,0.000954,0.024240,123.179497,6.275063,0.242400,-499.298676,0.025107,0.000000
25.090002,28.251900,-499.254181,-0.002380,0.000985,0.025012,125.670723,6.401972,0.250121,-499.254181,0.025843,0.000000
25.530001,28.932968,-499.254181,-0.002358,0.001015,0.025783,128.700272,6.556304,0.257827,-499.254181,0.026573,0.000000
25.970001,28.813812,-499.254181,-0.002333,0.001035,0.026278,128.170242,6.529303,0.262778,-499.254181,0.027309,0.000000
26.410002,30.298462,-499.298676,-0.002350,0.001073,0.027257,134.774292,6.865729,0.272573,-499.298676,0.028039,0.000000
26.850000,30.252289,-499.298676,-0.002311,0.001097,0.027873,134.568909,6.855267,0.278735,-499.298676,0.028776,0.000000
27.290001,31.246147,-499.298676,-0.002298,0.001130,0.028706,138.989807,7.080478,0.287062,-499.298676,0.029512,0.000000
27.730001,31.860191,-499.343170,-0.002281,0.001157,0.029400,141.721207,7.219623,0.293995,-499.343170,0.030241,0.000000
28.170002,32.861130,-499.343170,-0.002251,0.001189,0.030206,146.173599,7.446438,0.302065,-499.343170,0.030979,0.000000
28.610001,33.027946,-499.343170,-0.002229,0.001216,0.030883,146.915649,7.484240,0.308832,-499.343170,0.031707,0.000000
29.050001,33.205574,-499.432129,-0.002207,0.001238,0.031437,147.705765,7.524490,0.314373,-499.432129,0.032444,0.000000
29.490002,34.358437,-499.343170,-0.002203,0.001273,0.032331,152.833954,7.785733,0.323306,-499.343170,0.033172,0.000000
29.930002,34.099266,-499.476593,-0.002199,0.001291,0.032798,151.681107,7.727004,0.327984,-499.476593,0.033910,0.000000
30.370001,35.137436,-499.521088,-0.002173,0.001324,0.033631,156.299118,7.962256,0.336311,-499.521088,0.034647,0.000000
30.810001,35.844574,-499.476593,-0.002156,0.001356,0.034438,159.444626,8.122497,0.344380,-499.476593,0.035375,0.000000
31.250002,36.973610,-499.476593,-0.002143,0.001390,0.035306,164.466827,8.378340,0.353055,-499.476593,0.036112,0.000000
31.690002,36.926689,-499.476593,-0.002130,0.001413,0.035878,164.258118,8.367707,0.358778,-499.476593,0.036841,0.000000
32.130001,37.677391,-499.565552,-0.002100,0.001442,0.036615,167.597412,8.537818,0.366151,-499.565552,0.037578,0.000000
32.570000,38.350266,-499.521088,-0.002070,0.001472,0.037395,170.590500,8.690294,0.373948,-499.521088,0.038306,0.000000
33.010002,38.632156,-499.521088,-0.002065,0.001495,0.037976,171.844421,8.754171,0.379761,-499.521088,0.039043,0.000000
33.450001,39.599953,-499.610046,-0.002048,0.001529,0.038835,176.149384,8.973477,0.388345,-499.610046,0.039781,0.000000
33.890003,39.449883,-499.610046,-0.002044,0.001548,0.039321,175.481842,8.939471,0.393205,-499.610046,0.040509,0.000000
34.330002,41.259613,-499.654510,-0.002009,0.001589,0.040353,183.531921,9.349562,0.403530,-499.654510,0.041246,0.000000
34.770000,41.460327,-499.565552,-0.002005,0.001617,0.041063,184.424744,9.395044,0.410631,-499.565552,0.041974,0.000000
35.210003,42.552864,-499.610046,-0.001975,0.001648,0.041870,189.284592,9.642616,0.418700,-499.610046,0.042712,0.000000
35.650002,42.478760,-499.699005,-0.001957,0.001668,0.042365,188.954956,9.625824,0.423651,-499.699005,0.043440,0.000000
36.090000,43.709824,-499.743500,-0.001953,0.001702,0.043240,194.431000,9.904788,0.432402,-499.743500,0.044177,0.000000
36.530003,44.277321,-499.743500,-0.001944,0.001730,0.043934,196.955353,10.033384,0.439335,-499.743500,0.044906,0.000000
36.970001,45.143463,-499.699005,-0.001923,0.001760,0.044715,200.808151,10.229655,0.447147,-499.699005,0.045643,0.000000
37.410004,45.945923,-499.743500,-0.001888,0.001790,0.045478,204.377670,10.411494,0.454778,-499.743500,0.046380,0.000000
37.850002,46.818016,-499.787964,-0.001884,0.001821,0.046241,208.256943,10.609114,0.462408,-499.787964,0.047108,0.000000
38.290001,47.654366,-499.787964,-0.001867,0.001850,0.046987,211.977203,10.798634,0.469872,-499.787964,0.047846,0.000000
38.730003,48.366341,-499.832458,-0.001871,0.001880,0.047750,215.144226,10.959970,0.477502,-499.832458,0.048574,0.000000
39.170002,48.961395,-499.787964,-0.001837,0.001907,0.048427,217.791168,11.094810,0.484270,-499.787964,0.049311,0.000000
39.610001,48.818405,-499.876923,-0.001832,0.001924,0.048878,217.155106,11.062408,0.488781,-499.876923,0.050039,0.000000
40.050003,51.027321,-499.876923,-0.001824,0.001967,0.049962,226.980865,11.562956,0.499621,-499.876923,0.050777,0.000000
40.490002,50.955818,-499.876923,-0.001789,0.001988,0.050490,226.662796,11.546754,0.504905,-499.876923,0.051514,0.000000
40.930000,52.491112,-499.921417,-0.001789,0.002023,0.051384,233.492126,11.894656,0.513837,-499.921417,0.052242,0.000000
41.370003,53.003868,-499.921417,-0.001763,0.002047,0.052000,235.772980,12.010848,0.519999,-499.921417,0.052979,0.000000
41.810001,54.042419,-499.965881,-0.001759,0.002076,0.052719,240.392685,12.246187,0.527190,-499.965881,0.053708,0.000000
42.250004,55.309227,-500.010376,-0.001742,0.002106,0.053482,246.027725,12.533250,0.534821,-500.010376,0.054445,0.000000
42.690002,56.245369,-499.965881,-0.001720,0.002137,0.054271,250.191895,12.745383,0.542709,-499.965881,0.055173,0.000000
43.130001,57.421326,-500.010376,-0.001707,0.002166,0.055008,255.422806,13.011858,0.550081,-500.010376,0.055910,0.000000
43.570004,57.106300,-500.010376,-0.001681,0.002179,0.055355,254.021515,12.940473,0.553548,-500.010376,0.056648,0.000000
44.010002,59.805252,-500.054840,-0.001703,0.002226,0.056536,266.027039,13.552064,0.565357,-500.054840,0.057376,0.000000
44.450001,60.653145,-500.054840,-0.001677,0.002253,0.057220,269.798676,13.744199,0.572200,-500.054840,0.058113,0.000000
44.890003,61.923683,-500.010376,-0.001673,0.002282,0.057974,275.450287,14.032107,0.579740,-500.010376,0.058841,0.000000
45.330002,62.478516,-500.099335,-0.001643,0.002304,0.058513,277.918304,14.157834,0.585130,-500.099335,0.059579,0.000000
45.770000,64.518372,-500.054840,-0.001630,0.002342,0.059483,286.992065,14.620072,0.594834,-500.054840,0.060307,0.000000
46.210003,65.205399,-500.099335,-0.001630,0.002364,0.060047,290.048096,14.775755,0.600466,-500.099335,0.061044,0.000000
46.650002,67.027420,-500.188293,-0.001604,0.002400,0.060958,298.152863,15.188631,0.609580,-500.188293,0.061782,0.000000
47.090004,68.262207,-500.188293,-0.001600,0.002427,0.061635,303.645447,15.468437,0.616347,-500.188293,0.062510,0.000000
47.530003,68.604050,-500.188293,-0.001587,0.002443,0.062059,305.166046,15.545899,0.620587,-500.188293,0.063247,0.000000
47.970001,71.011429,-500.188293,-0.001556,0.002483,0.063075,315.874603,16.091419,0.630745,-500.188293,0.063975,0.000000
48.410004,72.340424,-500.232788,-0.001556,0.002510,0.063742,321.786285,16.392574,0.637422,-500.232788,0.064713,0.000000
48.850002,74.346771,-500.277252,-0.001544,0.002542,0.064566,330.710968,16.847219,0.645658,-500.277252,0.065441,0.000000
49.290001,75.001404,-500.188293,-0.001526,0.002560,0.065017,333.622894,16.995560,0.650169,-500.188293,0.066178,0.000000
49.730003,77.763657,-500.321747,-0.001505,0.002600,0.066048,345.910034,17.621498,0.660479,-500.321747,0.066906,0.000000
50.170002,78.721771,-500.277252,-0.001487,0.002622,0.066604,350.171936,17.838608,0.666036,-500.277252,0.067644,0.000000
50.610001,81.284439,-500.277252,-0.001487,0.002658,0.067523,361.571228,18.419317,0.675225,-500.277252,0.068381,0.000000
51.050003,83.038315,-500.277252,-0.001466,0.002685,0.068190,369.372864,18.816751,0.681902,-500.277252,0.069109,0.000000
51.490002,84.662979,-500.321747,-0.001470,0.002713,0.068902,376.599731,19.184906,0.689017,-500.321747,0.069846,0.000000
51.930004,86.761673,-500.321747,-0.001436,0.002741,0.069630,385.935211,19.660477,0.696300,-500.321747,0.070575,0.000000
52.370003,87.806915,-500.366211,-0.001444,0.002769,0.070323,390.584656,19.897331,0.703233,-500.366211,0.071312,0.000000
52.810001,90.602692,-500.410706,-0.001431,0.002799,0.071086,403.020905,20.530865,0.710864,-500.410706,0.072042,0.000000
53.250004,91.489304,-500.410706,-0.001414,0.002817,0.071556,406.964752,20.731771,0.715557,-500.410706,0.072777,0.000000
53.690002,93.839355,-500.366211,-0.001418,0.002848,0.072328,417.418304,21.264301,0.723278,-500.366211,0.073515,0.000000
54.130001,96.302963,-500.455170,-0.001380,0.002880,0.073151,428.376984,21.822563,0.731514,-500.455170,0.074244,0.000000
54.570004,99.012726,-500.410706,-0.001406,0.002916,0.074061,440.430603,22.436604,0.740613,-500.410706,0.074980,0.000000
55.010002,100.686157,-500.499664,-0.001371,0.002939,0.074659,447.874390,22.815809,0.746593,-500.499664,0.075710,0.000000
55.450001,103.079407,-500.544128,-0.001354,0.002971,0.075466,458.520111,23.358128,0.754663,-500.544128,0.076446,0.000000
55.890003,105.170273,-500.499664,-0.001354,0.002997,0.076117,467.820740,23.831924,0.761173,-500.499664,0.077176,0.000000
56.330002,107.688629,-500.633118,-0.001345,0.003028,0.076915,479.022949,24.402594,0.769151,-500.633118,0.077913,0.000000
56.770004,110.056168,-500.588623,-0.001324,0.003057,0.077643,489.554291,24.939083,0.776433,-500.588623,0.078649,0.000000
57.210003,111.659607,-500.588623,-0.001324,0.003081,0.078260,496.686737,25.302429,0.782595,-500.588623,0.079378,0.000000
57.650002,114.773758,-500.633118,-0.001306,0.003113,0.079074,510.539185,26.008106,0.790740,-500.633118,0.080116,0.000000
58.090004,117.054169,-500.633118,-0.001306,0.003142,0.079802,520.682922,26.524855,0.798022,-500.633118,0.080844,0.000000
58.530003,119.635452,-500.722076,-0.001293,0.003173,0.080600,532.165100,27.109779,0.806001,-500.722076,0.081581,0.000000
58.970001,121.567688,-500.677582,-0.001285,0.003193,0.081104,540.760071,27.547630,0.811042,-500.677582,0.082309,0.000000
59.410004,125.228867,-500.677582,-0.001268,0.003235,0.082161,557.045837,28.377268,0.821610,-500.677582,0.083047,0.000000
59.850002,126.586151,-500.722076,-0.001272,0.003253,0.082630,563.083313,28.684832,0.826303,-500.722076,0.083784,0.000000
60.290005,129.911072,-500.722076,-0.001259,0.003288,0.083524,577.873291,29.438271,0.835235,-500.722076,0.084512,0.000000
60.730003,132.181427,-500.722076,-0.001250,0.003317,0.084252,587.972351,29.952740,0.842518,-500.722076,0.085249,0.000000
61.170002,134.195221,-500.811035,-0.001250,0.003340,0.084841,596.930176,30.409071,0.848407,-500.811035,0.085978,0.000000
61.610004,137.393524,-500.766541,-0.001229,0.003374,0.085699,611.156921,31.133818,0.856991,-500.766541,0.086715,0.000000
62.050003,140.003113,-500.811035,-0.001224,0.003402,0.086420,622.764954,31.725159,0.864197,-500.811035,0.087443,0.000000
62.490002,142.816010,-500.899994,-0.001216,0.003432,0.087183,635.277344,32.362568,0.871828,-500.899994,0.088180,0.000000
62.930004,144.325607,-500.899994,-0.001212,0.003449,0.087599,641.992371,32.704651,0.875991,-500.899994,0.088909,0.000000
63.370003,148.298447,-500.855499,-0.001199,0.003492,0.088692,659.664429,33.604908,0.886922,-500.855499,0.089646,0.000000
63.810001,150.607162,-500.899994,-0.001194,0.003519,0.089377,669.934143,34.128071,0.893765,-500.899994,0.090383,0.000000
64.250000,153.594711,-500.944458,-0.001203,0.003549,0.090132,683.223389,34.805058,0.901320,-500.944458,0.091112,0.000000
64.690002,156.137268,-500.944458,-0.001186,0.003575,0.090800,694.533264,35.381210,0.907996,-500.944458,0.091849,0.000000
65.130005,159.126663,-500.944458,-0.001186,0.003607,0.091623,707.830750,36.058617,0.916232,-500.944458,0.092577,0.000000
65.570000,161.462570,-500.944458,-0.001147,0.003630,0.092205,718.221375,36.587944,0.922046,-500.944458,0.093314,0.000000
66.010002,164.030441,-500.988953,-0.001164,0.003659,0.092942,729.643860,37.169830,0.929419,-500.988953,0.094043,0.000000
66.450005,167.183701,-501.033447,-0.001155,0.003690,0.093722,743.670227,37.884369,0.937216,-501.033447,0.094780,0.000000
66.889999,169.373245,-500.944458,-0.001151,0.003718,0.094450,753.409851,38.380527,0.944498,-500.944458,0.095517,0.000000
67.330002,173.035156,-501.122406,-0.001147,0.003751,0.095282,769.698792,39.210327,0.952825,-501.122406,0.096245,0.000000
67.770004,175.505844,-501.033447,-0.001134,0.003778,0.095968,780.688965,39.770191,0.959683,-501.033447,0.096983,0.000000
68.210007,178.668030,-501.077911,-0.001125,0.003808,0.096731,794.755066,40.486755,0.967313,-501.077911,0.097711,0.000000
68.650002,180.959610,-501.122406,-0.001134,0.003829,0.097260,804.948547,41.006035,0.972597,-501.122406,0.098448,0.000000
69.090004,184.168716,-501.033447,-0.001125,0.003865,0.098171,819.223389,41.733227,0.981711,-501.033447,0.099176,0.000000
69.530006,186.430130,-501.122406,-0.001125,0.003888,0.098751,829.282654,42.245674,0.987509,-501.122406,0.099914,0.000000
69.970001,189.330917,-501.211365,-0.001091,0.003917,0.099497,842.185974,42.903000,0.994973,-501.211365,0.100651,0.000000
70.410004,192.370972,-501.166870,-0.001095,0.003947,0.100244,855.708801,43.591888,1.002437,-501.166870,0.101379,0.000000
70.850006,194.764191,-501.211365,-0.001099,0.003978,0.101049,866.354370,44.134197,1.010491,-501.211365,0.102116,0.000000
71.290001,198.429108,-501.211365,-0.001099,0.004006,0.101761,882.656738,44.964676,1.017607,-501.211365,0.102845,0.000000
71.730003,201.037933,-501.300323,-0.001099,0.004033,0.102437,894.261414,45.555847,1.024374,-501.300323,0.103582,0.000000
72.170006,204.354279,-501.211365,-0.001078,0.004065,0.103252,909.013245,46.307343,1.032519,-501.211365,0.104310,0.000000
72.610001,206.544586,-501.255829,-0.001074,0.004086,0.103782,918.756226,46.803673,1.037818,-501.255829,0.105047,0.000000
73.050003,209.633026,-501.300323,-0.001061,0.004116,0.104545,932.494263,47.503521,1.045449,-501.300323,0.105785,0.000000
73.490005,212.429932,-501.255829,-0.001074,0.004143,0.105229,944.935547,48.137310,1.052292,-501.255829,0.106513,0.000000
73.930000,216.305206,-501.344788,-0.001087,0.004182,0.106218,962.173584,49.015461,1.062178,-501.344788,0.107250,0.000000
74.370003,218.803070,-501.300323,-0.001048,0.004205,0.106817,973.284668,49.581486,1.068173,-501.300323,0.107979,0.000000
74.810005,221.188507,-501.389282,-0.001065,0.004223,0.107276,983.895630,50.122032,1.072760,-501.389282,0.108690,0.000000
75.250000,220.785950,-501.389282,-0.001048,0.004211,0.106948,982.104980,50.030811,1.069475,-501.389282,982.000671,0.000000
75.690002,220.453796,-501.344788,-0.001056,0.004208,0.106885,980.627441,49.955547,1.068854,-501.344788,982.000671,0.000000
76.130005,220.161499,-501.478241,-0.001056,0.004208,0.106885,979.327271,49.889309,1.068854,-501.478241,982.000671,0.000000
76.570007,219.910156,-501.389282,-0.001039,0.004208,0.106895,978.209229,49.832355,1.068945,-501.389282,982.000671,0.000000
77.010002,219.661774,-501.433746,-0.001043,0.004212,0.106973,977.104370,49.776070,1.069732,-501.433746,982.000671,0.000000
77.450005,219.452118,-501.522736,-0.001056,0.004216,0.107076,976.171753,49.728561,1.070762,-501.522736,982.000671,0.000000
77.890007,219.992065,-501.478241,-0.001048,0.004229,0.107415,978.573608,49.850914,1.074153,-501.478241,982.000671,0.000000
78.330002,219.858002,-501.567200,-0.001039,0.004229,0.107415,977.977234,49.820534,1.074153,-501.567200,982.000671,0.000000
78.770004,219.728790,-501.522736,-0.001052,0.004229,0.107415,977.402466,49.791256,1.074153,-501.522736,982.000671,0.000000
79.210007,219.596619,-501.522736,-0.001056,0.004230,0.107450,976.814575,49.761307,1.074501,-501.522736,982.000671,0.000000
79.650002,219.625641,-501.522736,-0.001048,0.004233,0.107511,976.943665,49.767879,1.075107,-501.522736,982.000671,0.000000
80.090004,219.594757,-501.656158,-0.001056,0.004234,0.107546,976.806274,49.760883,1.075455,-501.656158,982.000671,0.000000
80.530006,219.616333,-501.567200,-0.001048,0.004236,0.107588,976.902222,49.765774,1.075879,-501.567200,982.000671,0.000000
80.970001,219.659546,-501.567200,-0.001039,0.004237,0.107632,977.094482,49.775562,1.076318,-501.567200,982.000671,0.000000
81.410004,219.603668,-501.611694,-0.001048,0.004238,0.107650,976.845886,49.762901,1.076500,-501.611694,982.000671,0.000000
81.850006,219.637573,-501.656158,-0.001043,0.004240,0.107692,976.996704,49.770584,1.076924,-501.656158,982.000671,0.000000
82.290001,219.579468,-501.656158,-0.001039,0.004240,0.107692,976.738281,49.757420,1.076924,-501.656158,982.000671,0.000000
82.730003,219.561981,-501.745117,-0.001035,0.004241,0.107727,976.660461,49.753456,1.077272,-501.745117,982.000671,0.000000
83.170006,219.500153,-501.700653,-0.001030,0.004243,0.107762,976.385437,49.739445,1.077620,-501.700653,982.000671,0.000000
83.610001,219.674805,-501.789612,-0.001039,0.004245,0.107813,977.162354,49.779022,1.078135,-501.789612,982.000671,0.000000
84.050003,219.617828,-501.700653,-0.001035,0.004245,0.107813,976.908875,49.766109,1.078135,-501.700653,982.000671,0.000000
84.490005,219.556763,-501.789612,-0.001035,0.004245,0.107813,976.637268,49.752274,1.078135,-501.789612,982.000671,0.000000
84.930000,219.505737,-501.789612,-0.001043,0.004246,0.107841,976.410278,49.740711,1.078407,-501.789612,982.000671,0.000000
85.370003,219.462921,-501.789612,-0.001035,0.004246,0.107841,976.219849,49.731010,1.078407,-501.789612,982.000671,0.000000
85.810005,219.376923,-501.878571,-0.001030,0.004246,0.107841,975.837280,49.711521,1.078407,-501.878571,982.000671,0.000000
86.250008,219.924652,-501.834076,-0.001035,0.004259,0.108178,978.273682,49.835636,1.081784,-501.834076,982.000671,0.000000
86.690002,220.201721,-501.878571,-0.001039,0.004256,0.108092,979.506165,49.898422,1.080921,-501.878571,982.000671,0.000000
87.130005,220.161499,-501.878571,-0.001035,0.004256,0.108092,979.327271,49.889309,1.080921,-501.878571,982.000671,0.000000
87.570007,220.119781,-501.878571,-0.001026,0.004256,0.108092,979.141663,49.879856,1.080921,-501.878571,982.000671,0.000000
88.010002,220.064301,-501.967529,-0.001026,0.004256,0.108092,978.894897,49.867283,1.080921,-501.967529,982.000671,0.000000
88.450005,219.982025,-502.012024,-0.001018,0.004256,0.108092,978.528931,49.848637,1.080921,-502.012024,982.000671,0.000000
88.890007,219.901215,-502.012024,-0.001035,0.004256,0.108092,978.169434,49.830330,1.080921,-502.012024,982.000671,0.000000
89.330002,219.850555,-502.012024,-0.001030,0.004256,0.108092,977.944092,49.818848,1.080921,-502.012024,982.000671,0.000000
89.770004,219.795074,-502.012024,-0.001022,0.004256,0.108092,977.697327,49.806278,1.080921,-502.012024,982.000671,0.000000
90.210007,219.715393,-502.056488,-0.001022,0.004256,0.108092,977.342896,49.788219,1.080921,-502.056488,982.000671,0.000000
90.650002,219.640930,-502.100983,-0.001013,0.004256,0.108092,977.011658,49.771343,1.080921,-502.100983,982.000671,0.000000
91.090004,219.583588,-502.056488,-0.001043,0.004256,0.108092,976.756592,49.758354,1.080921,-502.056488,982.000671,0.000000
91.530006,219.526978,-502.145447,-0.001026,0.004256,0.108092,976.504761,49.745525,1.080921,-502.145447,982.000671,0.000000
91.970001,219.462189,-502.056488,-0.001026,0.004256,0.108092,976.216553,49.730843,1.080921,-502.056488,982.000671,0.000000
92.410004,219.388824,-502.189941,-0.001009,0.004256,0.108092,975.890259,49.714218,1.080921,-502.189941,982.000671,0.000000
92.850006,219.338562,-502.189941,-0.001009,0.004256,0.108092,975.666626,49.702827,1.080921,-502.189941,982.000671,0.000000
93.290001,219.276001,-502.189941,-0.001018,0.004256,0.108092,975.388367,49.688652,1.080921,-502.189941,982.000671,0.000000
93.730003,220.142883,-502.189941,-0.001013,0.004266,0.108352,979.244446,49.885090,1.083525,-502.189941,982.000671,0.000000
94.170006,220.151825,-502.234406,-0.001022,0.004266,0.108352,979.284241,49.887115,1.083525,-502.234406,982.000671,0.000000
94.610008,220.136536,-502.234406,-0.001018,0.004266,0.108352,979.216187,49.883652,1.083525,-502.234406,982.000671,0.000000
95.050003,220.111969,-502.189941,-0.001026,0.004266,0.108352,979.106934,49.878086,1.083525,-502.189941,982.000671,0.000000
95.490005,220.089996,-502.278900,-0.001035,0.004266,0.108352,979.009216,49.873104,1.083525,-502.278900,982.000671,0.000000
95.930008,220.068787,-502.278900,-0.001009,0.004266,0.108352,978.914856,49.868301,1.083525,-502.278900,982.000671,0.000000
96.370003,220.013306,-502.278900,-0.001022,0.004266,0.108352,978.668091,49.855728,1.083525,-502.278900,982.000671,0.000000
96.810005,219.946625,-502.323395,-0.001018,0.004266,0.108352,978.371460,49.840618,1.083525,-502.323395,982.000671,0.000000
97.250008,219.904572,-502.323395,-0.001030,0.004266,0.108352,978.184387,49.831089,1.083525,-502.323395,982.000671,0.000000
97.690002,219.869171,-502.412354,-0.001035,0.004266,0.108352,978.026917,49.823067,1.083525,-502.412354,982.000671,0.000000
98.130005,219.840515,-502.412354,-0.001009,0.004266,0.108352,977.899475,49.816574,1.083525,-502.412354,982.000671,0.000000
98.570007,219.795074,-502.412354,-0.001013,0.004266,0.108352,977.697327,49.806278,1.083525,-502.412354,982.000671,0.000000
99.010002,219.772003,-502.456818,-0.001009,0.004266,0.108352,977.594666,49.801048,1.083525,-502.456818,982.000671,0.000000
99.450005,219.692688,-502.456818,-0.001009,0.004266,0.108352,977.241882,49.783073,1.083525,-502.456818,982.000671,0.000000
99.890007,219.639801,-502.456818,-0.001022,0.004266,0.108352,977.006653,49.771091,1.083525,-502.456818,982.000671,0.000000
100.330002,219.609650,-502.412354,-0.001009,0.004266,0.108352,976.872498,49.764256,1.083525,-502.412354,982.000671,0.000000
100.770004,219.578369,-502.456818,-0.001009,0.004266,0.108352,976.733337,49.757168,1.083525,-502.456818,982.000671,0.000000
101.210007,219.547821,-502.501312,-0.001035,0.004266,0.108352,976.597473,49.750248,1.083525,-502.501312,982.000671,0.000000
101.650002,219.520264,-502.545776,-0.001018,0.004266,0.108352,976.474915,49.743999,1.083525,-502.545776,982.000671,0.000000
102.090004,219.482300,-502.501312,-0.001018,0.004266,0.108352,976.306030,49.735401,1.083525,-502.501312,982.000671,0.000000
102.530006,219.437225,-502.545776,-0.001018,0.004266,0.108352,976.105530,49.725189,1.083525,-502.545776,982.000671,0.000000
102.970001,219.385468,-502.501312,-0.001018,0.004266,0.108352,975.875305,49.713455,1.083525,-502.501312,982.000671,0.000000
103.410004,219.356812,-502.634735,-0.001009,0.004266,0.108360,975.747803,49.706966,1.083600,-502.634735,982.000671,0.000000
103.850006,219.320312,-502.590271,-0.001000,0.004266,0.108360,975.585449,49.698696,1.083600,-502.590271,982.000671,0.000000
104.290009,219.309143,-502.679230,-0.001022,0.004266,0.108360,975.535767,49.696163,1.083600,-502.679230,982.000671,0.000000
104.730003,219.268921,-502.723694,-0.001013,0.004266,0.108360,975.356873,49.687046,1.083600,-502.723694,982.000671,0.000000
105.170006,219.271149,-502.590271,-0.001018,0.004266,0.108360,975.366760,49.687553,1.083600,-502.590271,982.000671,0.000000
105.610008,219.223877,-502.723694,-0.001009,0.004266,0.108360,975.156494,49.676842,1.083600,-502.723694,982.000671,0.000000
106.050003,219.192963,-502.634735,-0.001013,0.004266,0.108360,975.018982,49.669834,1.083600,-502.634735,982.000671,0.000000
106.490005,219.144165,-502.768188,-0.001026,0.004266,0.108360,974.801941,49.658779,1.083600,-502.768188,982.000671,0.000000
106.930008,219.113281,-502.723694,-0.000992,0.004266,0.108360,974.664551,49.651779,1.083600,-502.723694,982.000671,0.000000
107.370003,219.077515,-502.723694,-0.001005,0.004266,0.108360,974.505432,49.643673,1.083600,-502.723694,982.000671,0.000000
107.810005,219.041412,-502.812683,-0.001018,0.004266,0.108360,974.344849,49.635494,1.083600,-502.812683,982.000671,0.000000
108.250008,219.021301,-502.768188,-0.001013,0.004266,0.108360,974.255432,49.630936,1.083600,-502.768188,982.000671,0.000000
108.690002,218.988159,-502.812683,-0.001022,0.004266,0.108360,974.107971,49.623428,1.083600,-502.812683,982.000671,0.000000
109.130005,218.965057,-502.812683,-0.001013,0.004266,0.108360,974.005249,49.618191,1.083600,-502.812683,982.000671,0.000000
109.570007,218.940125,-502.812683,-0.001013,0.004266,0.108360,973.894287,49.612541,1.083600,-502.812683,982.000671,0.000000
110.010002,218.907715,-502.946106,-0.001013,0.004266,0.108360,973.750122,49.605198,1.083600,-502.946106,982.000671,0.000000
110.450005,220.856720,-502.857147,-0.001000,0.004251,0.107969,982.419739,50.046848,1.079694,-502.857147,982.000671,0.000000
110.890007,220.817993,-502.946106,-0.001005,0.004251,0.107969,982.247498,50.038074,1.079694,-502.946106,982.000671,0.000000
111.330002,220.785950,-502.990601,-0.000992,0.004251,0.107969,982.104980,50.030811,1.079694,-502.990601,982.000671,0.000000
111.770004,220.758789,-502.901642,-0.000996,0.004251,0.107969,981.984131,50.024654,1.079694,-502.901642,982.000671,0.000000
112.210007,220.723419,-502.946106,-0.001000,0.004251,0.107969,981.826782,50.016644,1.079694,-502.946106,982.000671,0.000000
112.650009,220.694366,-502.901642,-0.001005,0.004251,0.107969,981.697571,50.010056,1.079694,-502.901642,982.000671,0.000000
113.090004,220.672028,-503.035065,-0.001000,0.004251,0.107969,981.598206,50.004993,1.079694,-503.035065,982.000671,0.000000
113.530006,220.634399,-502.946106,-0.001013,0.004251,0.107969,981.430847,49.996468,1.079694,-502.946106,982.000671,0.000000
113.970009,220.613922,-502.990601,-0.001000,0.004251,0.107969,981.339722,49.991829,1.079694,-502.990601,982.000671,0.000000
114.410004,220.586365,-503.035065,-0.001000,0.004251,0.107969,981.217163,49.985584,1.079694,-503.035065,982.000671,0.000000
114.850006,220.558807,-503.079559,-0.001009,0.004251,0.107969,981.094604,49.979340,1.079694,-503.079559,982.000671,0.000000
115.290009,220.532745,-503.079559,-0.000996,0.004251,0.107969,980.978638,49.973434,1.079694,-503.079559,982.000671,0.000000
115.730003,220.488800,-503.079559,-0.000987,0.004251,0.107969,980.783142,49.963474,1.079694,-503.079559,982.000671,0.000000
116.170006,220.461639,-503.035065,-0.001013,0.004251,0.107969,980.662354,49.957321,1.079694,-503.035065,982.000671,0.000000
116.610008,220.422516,-503.168518,-0.000996,0.004251,0.107969,980.488342,49.948456,1.079694,-503.168518,982.000671,0.000000
117.050003,220.445984,-503.079559,-0.001000,0.004251,0.107969,980.592712,49.953773,1.079694,-503.079559,982.000671,0.000000
117.490005,220.431091,-503.213013,-0.001009,0.004251,0.107969,980.526489,49.950397,1.079694,-503.213013,982.000671,0.000000
117.930008,220.426239,-503.168518,-0.001005,0.004251,0.107969,980.504883,49.949303,1.079694,-503.168518,982.000671,0.000000
118.370003,220.420288,-503.213013,-0.001000,0.004251,0.107969,980.478394,49.947948,1.079694,-503.213013,982.000671,0.000000
118.810005,220.375610,-503.301971,-0.000987,0.004251,0.107969,980.279663,49.937824,1.079694,-503.301971,982.000671,0.000000
119.250008,220.378204,-503.257477,-0.000992,0.004251,0.107969,980.291199,49.938412,1.079694,-503.257477,982.000671,0.000000
119.690002,220.332794,-503.257477,-0.001013,0.004251,0.107969,980.089233,49.928123,1.079694,-503.257477,982.000671,0.000000
120.130005,220.323853,-503.257477,-0.000983,0.004251,0.107969,980.049438,49.926098,1.079694,-503.257477,982.000671,0.000000
120.570007,220.321259,-503.257477,-0.000992,0.004251,0.107969,980.037903,49.925510,1.079694,-503.257477,982.000671,0.000000
121.010002,220.289215,-503.346436,-0.000996,0.004251,0.107969,979.895386,49.918251,1.079694,-503.346436,982.000671,0.000000
121.450005,220.227783,-503.257477,-0.000992,0.004251,0.107969,979.622131,49.904327,1.079694,-503.257477,982.000671,0.000000
121.890007,220.205811,-503.390930,-0.000996,0.004251,0.107969,979.524353,49.899353,1.079694,-503.390930,982.000671,0.000000
122.330009,220.166718,-503.390930,-0.000992,0.004251,0.107969,979.350464,49.890491,1.079694,-503.390930,982.000671,0.000000
122.770004,220.151428,-503.390930,-0.000992,0.004251,0.107969,979.282471,49.887024,1.079694,-503.390930,982.000671,0.000000
123.210007,220.142517,-503.435394,-0.001009,0.004251,0.107969,979.242798,49.885006,1.079694,-503.435394,982.000671,0.000000
123.650009,220.115692,-503.390930,-0.000987,0.004251,0.107969,979.123474,49.878925,1.079694,-503.390930,982.000671,0.000000
124.090004,220.110107,-503.435394,-0.000996,0.004251,0.107969,979.098633,49.877663,1.079694,-503.435394,982.000671,0.000000
124.530006,220.101532,-503.435394,-0.000987,0.004251,0.107969,979.060486,49.875717,1.079694,-503.435394,982.000671,0.000000
124.970009,220.077332,-503.435394,-0.000987,0.004251,0.107969,978.952881,49.870235,1.079694,-503.435394,982.000671,0.000000
125.410004,220.054993,-503.524353,-0.000992,0.004251,0.107969,978.853516,49.865173,1.079694,-503.524353,982.000671,0.000000
125.850006,220.049042,-503.479889,-0.000987,0.004251,0.107969,978.827026,49.863827,1.079694,-503.479889,982.000671,0.000000
126.290009,220.025574,-503.568848,-0.001000,0.004251,0.107969,978.722656,49.858505,1.079694,-503.568848,982.000671,0.000000
126.730003,220.009186,-503.524353,-0.000983,0.004251,0.107969,978.649719,49.854794,1.079694,-503.524353,982.000671,0.000000
127.170006,219.962646,-503.568848,-0.001009,0.004251,0.107969,978.442749,49.844250,1.079694,-503.568848,982.000671,0.000000
127.610008,219.934357,-503.657806,-0.000996,0.004251,0.107969,978.316895,49.837837,1.079694,-503.657806,982.000671,0.000000
128.050003,219.909027,-503.613342,-0.000996,0.004251,0.107969,978.204224,49.832096,1.079694,-503.613342,982.000671,0.000000
128.490005,219.887817,-503.613342,-0.001000,0.004251,0.107969,978.109863,49.827293,1.079694,-503.613342,982.000671,0.000000
128.930008,219.879608,-503.657806,-0.000987,0.004251,0.107969,978.073364,49.825432,1.079694,-503.657806,982.000671,0.000000
129.370010,219.864716,-503.702301,-0.001000,0.004261,0.108230,978.007080,49.822060,1.082298,-503.702301,982.000671,0.000000
129.810013,219.866577,-503.702301,-0.000996,0.004266,0.108360,978.015381,49.822479,1.083600,-503.702301,982.000671,0.000000
130.250000,219.869568,-503.702301,-0.000992,0.004268,0.108404,978.028687,49.823154,1.084039,-503.702301,982.000671,0.000000
130.690002,219.860992,-503.746765,-0.000996,0.004268,0.108404,977.990540,49.821213,1.084039,-503.746765,982.000671,0.000000
131.130005,219.860992,-503.791260,-0.001005,0.004268,0.108404,977.990540,49.821213,1.084039,-503.791260,982.000671,0.000000
131.570007,219.826721,-503.702301,-0.000992,0.004268,0.108404,977.838074,49.813446,1.084039,-503.702301,982.000671,0.000000
132.010010,219.828979,-503.835724,-0.001000,0.004268,0.108413,977.848145,49.813961,1.084130,-503.835724,982.000671,0.000000
132.450012,219.808868,-503.791260,-0.001000,0.004268,0.108413,977.758667,49.809402,1.084130,-503.791260,982.000671,0.000000
132.889999,219.786530,-503.791260,-0.001000,0.004268,0.108413,977.659302,49.804340,1.084130,-503.791260,982.000671,0.000000
133.330002,219.776093,-503.835724,-0.000992,0.004269,0.108430,977.612915,49.801975,1.084297,-503.835724,982.000671,0.000000
133.770004,219.771637,-503.791260,-0.001000,0.004270,0.108448,977.593079,49.800964,1.084478,-503.791260,982.000671,0.000000
134.210007,219.759338,-503.835724,-0.000996,0.004270,0.108448,977.538330,49.798180,1.084478,-503.835724,982.000671,0.000000
134.650009,219.739227,-503.835724,-0.000983,0.004270,0.108464,977.448914,49.793621,1.084645,-503.835724,982.000671,0.000000
135.090012,219.746307,-503.880219,-0.000987,0.004273,0.108543,977.480408,49.795223,1.085432,-503.880219,982.000671,0.000000
135.530014,219.741821,-503.924683,-0.000996,0.004273,0.108543,977.460449,49.794209,1.085432,-503.924683,5607.367676,0.000000
135.970001,219.588043,-503.880219,-0.001009,0.004256,0.108100,976.776428,49.759365,1.080996,-503.880219,0.107883,0.000000
136.410004,219.414154,-503.924683,-0.000996,0.004233,0.107527,976.002930,49.719955,1.075274,-503.924683,0.107155,0.000000
136.850006,218.187927,-503.969177,-0.000987,0.004203,0.106748,970.548401,49.442089,1.067477,-503.969177,0.106418,0.000000
137.290009,217.293854,-503.924683,-0.000979,0.004184,0.106262,966.571350,49.239494,1.062617,-503.924683,0.105689,0.000000
137.730011,216.764343,-504.058136,-0.000983,0.004162,0.105724,964.215942,49.119503,1.057242,-504.058136,0.104952,0.000000
138.170013,216.502197,-503.924683,-0.000983,0.004121,0.104675,963.049866,49.060097,1.046751,-503.924683,0.104224,0.000000
138.610001,216.154022,-504.013641,-0.000992,0.004095,0.104007,961.501099,48.981201,1.040074,-504.013641,0.103487,0.000000
139.050003,215.808472,-504.013641,-0.000974,0.004066,0.103270,959.964050,48.902901,1.032701,-504.013641,0.102758,0.000000
139.490005,215.570129,-504.058136,-0.000987,0.004045,0.102740,958.903809,48.848888,1.027402,-504.058136,0.102021,0.000000
139.930008,214.737885,-504.058136,-0.000979,0.004024,0.102221,955.201843,48.660301,1.022209,-504.058136,0.101284,0.000000
140.370010,213.409637,-504.013641,-0.000974,0.003983,0.101179,949.293457,48.359318,1.011793,-504.013641,0.100556,0.000000
140.810013,212.355438,-504.102631,-0.000974,0.003961,0.100607,944.604187,48.120430,1.006070,-504.102631,0.099818,0.000000
141.250000,210.318573,-504.102631,-0.000987,0.003932,0.099870,935.543762,47.658867,0.998698,-504.102631,0.099090,0.000000
141.690002,208.419098,-504.147095,-0.000974,0.003907,0.099237,927.094421,47.228443,0.992369,-504.147095,0.098353,0.000000
142.130005,205.335480,-504.191589,-0.000970,0.003873,0.098362,913.377808,46.529686,0.983618,-504.191589,0.097625,0.000000
142.570007,202.592590,-504.147095,-0.000992,0.003845,0.097667,901.176880,45.908138,0.976669,-504.147095,0.096887,0.000000
143.010010,199.441589,-504.191589,-0.000966,0.003816,0.096930,887.160522,45.194111,0.969296,-504.191589,0.096150,0.000000
143.450012,197.008484,-504.191589,-0.000974,0.003792,0.096324,876.337524,44.642761,0.963241,-504.191589,0.095422,0.000000
143.889999,193.711884,-504.280548,-0.000979,0.003761,0.095534,861.673523,43.895741,0.955338,-504.280548,0.094684,0.000000
144.330002,190.534424,-504.236053,-0.000974,0.003730,0.094745,847.539429,43.175716,0.947450,-504.236053,0.093956,0.000000
144.770004,187.742004,-504.191589,-0.000970,0.003702,0.094033,835.118164,42.542946,0.940334,-504.191589,0.093219,0.000000
145.210007,184.696747,-504.236053,-0.000996,0.003677,0.093401,821.572144,41.852879,0.934006,-504.236053,0.092491,0.000000
145.650009,181.962036,-504.236053,-0.000983,0.003652,0.092759,809.407532,41.233189,0.927587,-504.236053,0.091753,0.000000
146.090012,178.088242,-504.236053,-0.001000,0.003618,0.091891,792.176086,40.355370,0.918912,-504.236053,0.091016,0.000000
146.530014,174.600235,-504.280548,-0.000970,0.003587,0.091112,776.660645,39.564980,0.911115,-504.280548,0.090288,0.000000
146.970001,171.012421,-504.325012,-0.000987,0.003559,0.090400,760.701233,38.751968,0.903999,-504.325012,0.089551,0.000000
147.410004,168.139572,-504.369507,-0.001000,0.003534,0.089776,747.922180,38.100971,0.897762,-504.369507,0.088822,0.000000
147.850006,164.456070,-504.325012,-0.000992,0.003502,0.088960,731.537109,37.266277,0.889602,-504.325012,0.088085,0.000000
148.290009,160.564774,-504.369507,-0.001009,0.003473,0.088206,714.227783,36.384495,0.882062,-504.369507,0.087357,0.000000
148.730011,156.171524,-504.413971,-0.001005,0.003434,0.087234,694.685608,35.388973,0.872343,-504.413971,0.086620,0.000000
149.170013,153.592850,-504.413971,-0.001013,0.003416,0.086766,683.215088,34.804638,0.867664,-504.413971,0.085882,0.000000
149.610001,150.791107,-504.413971,-0.001022,0.003391,0.086125,670.752319,34.169754,0.861245,-504.413971,0.085154,0.000000
150.050003,148.533051,-504.458466,-0.001022,0.003370,0.085604,660.708008,33.658073,0.856037,-504.458466,0.084417,0.000000
150.490005,143.250198,-504.458466,-0.001026,0.003327,0.084512,637.208679,32.460960,0.845122,-504.458466,0.083689,0.000000
150.930008,139.808365,-504.502960,-0.001035,0.003298,0.083775,621.898682,31.681028,0.837749,-504.502960,0.082951,0.000000
151.370010,137.187973,-504.502960,-0.001022,0.003274,0.083159,610.242554,31.087238,0.831587,-504.502960,0.082222,0.000000
151.810013,133.667572,-504.591919,-0.001039,0.003245,0.082430,594.583069,30.289503,0.824305,-504.591919,0.081486,0.000000
152.250000,129.679077,-504.502960,-0.001043,0.003211,0.081572,576.841370,29.385698,0.815721,-504.502960,0.080756,0.000000
152.690002,126.085693,-504.502960,-0.001043,0.003179,0.080739,560.857178,28.571426,0.807394,-504.502960,0.080020,0.000000
153.130005,123.375183,-504.636383,-0.001056,0.003158,0.080211,548.800232,27.957216,0.802110,-504.636383,0.079283,0.000000
153.570007,119.985489,-504.636383,-0.001061,0.003128,0.079439,533.722107,27.189100,0.794389,-504.636383,0.078553,0.000000
154.010010,116.895538,-504.636383,-0.001065,0.003103,0.078814,519.977295,26.488907,0.788136,-504.636383,0.077817,0.000000
154.450012,113.797775,-504.636383,-0.001052,0.003075,0.078104,506.197784,25.786943,0.781036,-504.636383,0.077088,0.000000
154.890015,109.795883,-504.636383,-0.001069,0.003040,0.077210,488.396484,24.880102,0.772103,-504.636383,0.076350,0.000000
155.330002,107.270447,-504.769836,-0.001061,0.003017,0.076638,477.162781,24.307829,0.766381,-504.769836,0.075622,0.000000
155.770004,103.405228,-504.725342,-0.001069,0.002984,0.075787,459.969421,23.431959,0.757872,-504.725342,0.074885,0.000000
156.210007,100.098557,-504.725342,-0.001087,0.002955,0.075050,445.260620,22.682657,0.750499,-504.725342,0.074149,0.000000
156.650009,96.396439,-504.814301,-0.001069,0.002923,0.074235,428.792786,21.843744,0.742354,-504.814301,0.073419,0.000000
157.090012,94.383759,-504.769836,-0.001091,0.002906,0.073819,419.839935,21.387665,0.738191,-504.769836,0.072682,0.000000
157.530014,91.041351,-504.814301,-0.001099,0.002873,0.072986,404.972168,20.630266,0.729864,-504.814301,0.071954,0.000000
157.970001,86.534897,-504.769836,-0.001087,0.002836,0.072033,384.926453,19.609087,0.720326,-504.769836,0.071217,0.000000
158.410004,84.115585,-504.858795,-0.001121,0.002814,0.071486,374.164825,19.060863,0.714861,-504.858795,0.070488,0.000000
158.850006,81.021545,-504.858795,-0.001121,0.002788,0.070818,360.401825,18.359743,0.708184,-504.858795,0.069751,0.000000
159.290009,77.600555,-504.858795,-0.001125,0.002759,0.070081,345.184509,17.584538,0.700811,-504.858795,0.069014,0.000000
159.730011,73.943863,-504.947754,-0.001104,0.002725,0.069223,328.918732,16.755920,0.692227,-504.947754,0.068286,0.000000
160.170013,70.277481,-504.858795,-0.001112,0.002694,0.068434,312.609863,15.925105,0.684339,-504.858795,0.067548,0.000000
160.610001,66.804001,-504.947754,-0.001134,0.002665,0.067678,297.159027,15.138003,0.676785,-504.947754,0.066820,0.000000
161.050003,64.480392,-504.947754,-0.001134,0.002643,0.067141,286.823120,14.611466,0.671410,-504.947754,0.066083,0.000000
161.490005,61.543114,-504.947754,-0.001151,0.002618,0.066508,273.757446,13.945868,0.665082,-504.947754,0.065355,0.000000
161.930008,57.553520,-504.992249,-0.001138,0.002584,0.065624,256.010834,13.041814,0.656240,-504.992249,0.064617,0.000000
162.370010,54.702263,-504.992249,-0.001138,0.002558,0.064964,243.327820,12.395710,0.649639,-504.992249,0.063880,0.000000
162.810013,51.498367,-505.081207,-0.001168,0.002530,0.064254,229.076172,11.669697,0.642539,-505.081207,0.063152,0.000000
163.250015,48.688072,-505.036713,-0.001138,0.002501,0.063517,216.575363,11.032875,0.635166,-505.036713,0.062414,0.000000
163.690002,44.788589,-505.036713,-0.001155,0.002466,0.062649,199.229599,10.149240,0.626491,-505.036713,0.061686,0.000000
164.130005,41.742210,-505.036713,-0.001160,0.002440,0.061981,185.678619,9.458920,0.619814,-505.036713,0.060949,0.000000
164.570007,38.609810,-505.081207,-0.001164,0.002412,0.061270,171.745010,8.749107,0.612699,-505.081207,0.060221,0.000000
165.010010,35.869896,-505.125671,-0.001177,0.002386,0.060611,159.557266,8.128235,0.606113,-505.125671,0.059483,0.000000
165.450012,31.939880,-505.170166,-0.001168,0.002350,0.059700,142.075684,7.237680,0.596999,-505.170166,0.058755,0.000000
165.890015,28.941536,-505.125671,-0.001181,0.002323,0.059016,128.738388,6.558246,0.590156,-505.125671,0.058018,0.000000
166.330002,25.534325,-505.170166,-0.001177,0.002290,0.058157,113.582352,5.786160,0.581572,-505.170166,0.057281,0.000000
166.770004,23.061401,-505.125671,-0.001181,0.002270,0.057662,102.582237,5.225789,0.576621,-505.125671,0.056552,0.000000
167.210007,19.178673,-505.214630,-0.001194,0.002233,0.056726,85.310997,4.345950,0.567265,-505.214630,0.055815,0.000000
167.650009,16.105484,-505.259125,-0.001194,0.002205,0.056015,71.640770,3.649555,0.560149,-505.259125,0.055087,0.000000
168.090012,13.968063,-505.214630,-0.001212,0.002186,0.055529,62.133049,3.165209,0.555290,-505.214630,0.054350,0.000000
168.530014,10.402596,-505.259125,-0.001199,0.002154,0.054722,46.273056,2.357262,0.547220,-505.259125,0.053621,0.000000
168.970001,7.553207,-505.214630,-0.001212,0.002124,0.053959,33.598343,1.711581,0.539590,-505.214630,0.052884,0.000000
169.410004,4.241699,-505.214630,-0.001212,0.002096,0.053240,18.868021,0.961183,0.532398,-505.214630,0.052147,0.000000
169.850006,1.523750,-505.303589,-0.001212,0.002067,0.052512,6.777980,0.345287,0.525116,-505.303589,0.051419,0.000000
170.290009,-1.902451,-505.259125,-0.001220,0.002030,0.051565,-8.462523,-0.431101,0.515654,-505.259125,0.050681,0.000000
170.730011,-0.493767,-505.437042,-0.001229,0.002011,0.051072,-2.196384,-0.111889,0.510719,-505.437042,0.049953,0.000000
171.170013,-0.218582,-505.303589,-0.001242,0.001982,0.050344,-0.972302,-0.049531,0.503436,-505.303589,0.049216,0.000000
171.610001,-0.134796,-505.392578,-0.001263,0.001953,0.049614,-0.599603,-0.030545,0.496139,-505.392578,0.048488,0.000000
172.050003,-0.148201,-505.348083,-0.001298,0.001925,0.048904,-0.659231,-0.033583,0.489039,-505.348083,0.047750,0.000000
172.490005,-0.136658,-505.392578,-0.001328,0.001897,0.048176,-0.607884,-0.030967,0.481757,-505.392578,0.047013,0.000000
172.930008,-0.147461,-505.392578,-0.001337,0.001866,0.047385,-0.655939,-0.033415,0.473854,-505.392578,0.046285,0.000000
173.370010,-0.112823,-505.392578,-0.001362,0.001838,0.046692,-0.501864,-0.025566,0.466920,-505.392578,0.045547,0.000000
173.810013,-0.150436,-505.437042,-0.001397,0.001805,0.045850,-0.669175,-0.034089,0.458502,-505.437042,0.044819,0.000000
174.250015,-0.142242,-505.481537,-0.001418,0.001774,0.045071,-0.632726,-0.032233,0.450705,-505.481537,0.044082,0.000000
174.690002,-0.090111,-505.481537,-0.001453,0.001752,0.044489,-0.400833,-0.020419,0.444892,-505.481537,0.043354,0.000000
175.130005,-0.149689,-505.570496,-0.001462,0.001716,0.043579,-0.665849,-0.033920,0.435793,-505.570496,0.042616,0.000000
175.570007,-0.138893,-505.481537,-0.001475,0.001693,0.043007,-0.617827,-0.031474,0.430070,-505.481537,0.041879,0.000000
176.010010,-0.135170,-505.526001,-0.001513,0.001660,0.042156,-0.601266,-0.030630,0.421562,-505.526001,0.041151,0.000000
176.450012,-0.105011,-505.526001,-0.001539,0.001635,0.041523,-0.467112,-0.023796,0.415233,-505.526001,0.040414,0.000000
176.890015,-0.088623,-505.570496,-0.001526,0.001611,0.040916,-0.394215,-0.020082,0.409162,-505.570496,0.039685,0.000000
177.100006,-0.061066,-505.614960,-0.001544,0.001613,0.040977,-0.271634,-0.013838,0.409768,-505.614960,0.040916,0.000000