File: Data/sima compression 500bar/P2-15-500bar-2_11072024_173956.csv
Time (sec),S:Load (lbs),S:HL1 (DIM),S:LVDT (in),S:Position (in),Ch:Position (mm),Ch:Load (N),Ch:Stress (MPa),Ch:Strain (mm/mm),Ch:HL1 (DIM),Set Point (),Cycles ()
0.110000,-0.063301,-479.326721,-0.005678,-0.005513,-0.140023,-0.281577,-0.014344,-1.400229,-479.326721,-0.139814,0.000000
0.520000,-0.064415,-479.326721,-0.005687,-0.005463,-0.138765,-0.286532,-0.014597,-1.387648,-479.326721,-0.138271,0.000000
0.930000,-0.032768,-479.326721,-0.005523,-0.005213,-0.132417,-0.145760,-0.007425,-1.324168,-479.326721,-0.131437,0.000000
1.340000,-0.084526,-479.326721,-0.005256,-0.004944,-0.125583,-0.375991,-0.019154,-1.255828,-479.326721,-0.124603,0.000000
1.750000,-0.133308,-479.282257,-0.004967,-0.004682,-0.118923,-0.592985,-0.030208,-1.189229,-479.282257,-0.117769,0.000000
2.160000,-0.153786,-479.371216,-0.004704,-0.004412,-0.112072,-0.684073,-0.034848,-1.120723,-479.371216,-0.110935,0.000000
2.570000,-0.081551,-479.371216,-0.004424,-0.004141,-0.105187,-0.362755,-0.018480,-1.051868,-479.371216,-0.104119,0.000000
2.980000,-0.058090,-479.460175,-0.004143,-0.003869,-0.098265,-0.258398,-0.013163,-0.982650,-479.460175,-0.097285,0.000000
3.390000,-0.056229,-479.415680,-0.003902,-0.003605,-0.091579,-0.250117,-0.012742,-0.915793,-479.415680,-0.090451,0.000000
3.800000,-0.068886,-479.460175,-0.003609,-0.003338,-0.084789,-0.306419,-0.015610,-0.847892,-479.460175,-0.083619,0.000000
4.210000,-0.094955,-479.504639,-0.003324,-0.003066,-0.077869,-0.422383,-0.021517,-0.778689,-479.504639,-0.076785,0.000000
4.620000,-0.027184,-479.460175,-0.003044,-0.002793,-0.070949,-0.120918,-0.006160,-0.709486,-479.460175,-0.069968,0.000000
5.030000,0.171295,-479.415680,-0.002966,-0.000000,-0.000000,0.761959,0.038816,-0.000000,-479.415680,0.000216,0.000000
5.440000,0.160492,-479.549133,-0.002971,-0.000000,-0.000000,0.713904,0.036368,-0.000000,-479.549133,0.000503,0.000000
5.850000,0.183952,-479.504639,-0.002966,-0.000000,-0.000000,0.818261,0.041684,-0.000000,-479.504639,0.001188,0.000000
6.260000,0.621490,-479.593628,-0.002949,0.000043,0.001093,2.764528,0.140832,0.010931,-479.593628,0.001873,0.000000
6.670001,0.949554,-479.549133,-0.002945,0.000061,0.001544,4.223829,0.215172,0.015442,-479.549133,0.002559,0.000000
7.080000,1.699883,-479.549133,-0.002902,0.000088,0.002238,7.561455,0.385199,0.022376,-479.549133,0.003235,0.000000
7.490000,2.818489,-479.549133,-0.002906,0.000122,0.003105,12.537266,0.638679,0.031051,-479.549133,0.003920,0.000000
7.900001,3.261986,-479.593628,-0.002863,0.000135,0.003417,14.510037,0.739177,0.034170,-479.593628,0.004605,0.000000
8.310000,4.894463,-479.682587,-0.002846,0.000177,0.004492,21.771656,1.109101,0.044919,-479.682587,0.005290,0.000000
8.720000,5.595268,-479.638092,-0.002833,0.000199,0.005064,24.888996,1.267906,0.050642,-479.638092,0.005976,0.000000
9.130000,6.641640,-479.638092,-0.002802,0.000222,0.005646,29.543489,1.505017,0.056455,-479.638092,0.006652,0.000000
9.540001,8.291245,-479.727051,-0.002811,0.000256,0.006513,36.881298,1.878823,0.065130,-479.727051,0.007337,0.000000
9.950001,9.080673,-479.638092,-0.002785,0.000273,0.006946,40.392853,2.057710,0.069460,-479.638092,0.008022,0.000000
10.360001,10.835670,-479.771545,-0.002751,0.000310,0.007883,48.199471,2.455398,0.078832,-479.771545,0.008707,0.000000
10.770000,11.730476,-479.682587,-0.002729,0.000332,0.008421,52.179764,2.658164,0.084206,-479.682587,0.009393,0.000000
11.180000,13.189064,-479.727051,-0.002725,0.000363,0.009209,58.667889,2.988685,0.092094,-479.727051,0.010069,0.000000
11.590000,14.238411,-479.860504,-0.002716,0.000384,0.009765,63.335613,3.226470,0.097650,-479.860504,0.010754,0.000000
12.000001,15.691032,-479.771545,-0.002690,0.000414,0.010511,69.797195,3.555639,0.105114,-479.771545,0.011439,0.000000
12.410001,17.186111,-479.816010,-0.002665,0.000446,0.011317,76.447639,3.894428,0.113168,-479.816010,0.012124,0.000000
12.820001,17.764778,-479.771545,-0.002665,0.000464,0.011786,79.021683,4.025556,0.117862,-479.771545,0.012810,0.000000
13.230000,19.541733,-479.816010,-0.002634,0.000497,0.012626,86.925972,4.428220,0.126264,-479.816010,0.013485,0.000000
13.640000,20.134552,-479.816010,-0.002604,0.000515,0.013078,89.562958,4.562554,0.130776,-479.816010,0.014171,0.000000
14.050000,21.476585,-479.816010,-0.002596,0.000543,0.013789,95.532623,4.866663,0.137891,-479.816010,0.014856,0.000000
14.460001,23.004425,-479.904968,-0.002574,0.000575,0.014604,102.328796,5.212877,0.146036,-479.904968,0.015541,0.000000
14.870001,24.042229,-479.860504,-0.002578,0.000603,0.015324,106.945175,5.448047,0.153243,-479.860504,0.016227,0.000000
15.280001,25.239037,-479.949463,-0.002539,0.000631,0.016036,112.268845,5.719247,0.160358,-479.949463,0.016902,0.000000
15.690001,25.281860,-479.949463,-0.002522,0.000646,0.016399,112.459328,5.728951,0.163992,-479.949463,0.017588,0.000000
16.100000,27.686638,-479.904968,-0.002496,0.000689,0.017501,123.156319,6.273881,0.175014,-479.904968,0.018272,0.000000
16.510000,28.042252,-479.993958,-0.002488,0.000709,0.018004,124.738167,6.354465,0.180040,-479.993958,0.018958,0.000000
16.920000,28.965363,-480.038422,-0.002453,0.000737,0.018723,128.844360,6.563645,0.187231,-480.038422,0.019642,0.000000
17.330000,29.797249,-479.949463,-0.002436,0.000762,0.019348,132.544785,6.752153,0.193484,-479.949463,0.020319,0.000000
17.740002,30.325272,-479.993958,-0.002410,0.000783,0.019886,134.893539,6.871805,0.198858,-479.993958,0.021005,0.000000
18.150002,32.003181,-479.993958,-0.002402,0.000822,0.020874,142.357254,7.252025,0.208745,-479.993958,0.021689,0.000000
18.560001,32.011002,-480.127380,-0.002354,0.000841,0.021368,142.392044,7.253797,0.213680,-480.127380,0.022375,0.000000
18.970001,32.922569,-480.127380,-0.002345,0.000871,0.022114,146.446899,7.460361,0.221144,-480.127380,0.023059,0.000000
19.380001,33.297546,-480.082916,-0.002328,0.000891,0.022643,148.114883,7.545332,0.226428,-480.082916,0.023736,0.000000
19.790001,34.715912,-480.171875,-0.002307,0.000927,0.023536,154.424088,7.866738,0.235360,-480.171875,0.024422,0.000000
20.200001,35.407784,-480.127380,-0.002289,0.000956,0.024273,157.501694,8.023519,0.242733,-480.127380,0.025106,0.000000
20.610001,35.344109,-480.171875,-0.002246,0.000976,0.024785,157.218445,8.009089,0.247850,-480.171875,0.025792,0.000000
21.020000,36.389725,-480.216339,-0.002251,0.001007,0.025583,161.869583,8.246029,0.255829,-480.216339,0.026476,0.000000
21.430000,36.289932,-480.127380,-0.002212,0.001026,0.026060,161.425674,8.223415,0.260598,-480.127380,0.027153,0.000000
21.840000,37.522858,-480.305298,-0.002207,0.001062,0.026971,166.910004,8.502801,0.269712,-480.305298,0.027839,0.000000
22.250002,38.097054,-480.216339,-0.002182,0.001088,0.027630,169.464157,8.632915,0.276297,-480.216339,0.028523,0.000000
22.660002,38.348038,-480.260834,-0.002147,0.001111,0.028211,170.580597,8.689789,0.282111,-480.260834,0.029209,0.000000
23.070002,39.211197,-480.305298,-0.002139,0.001141,0.028974,174.420120,8.885385,0.289741,-480.305298,0.029893,0.000000
23.480001,39.677032,-480.260834,-0.002108,0.001164,0.029572,176.492249,8.990944,0.295721,-480.260834,0.030570,0.000000
23.890001,39.092033,-480.305298,-0.002100,0.001177,0.029893,173.890045,8.858381,0.298931,-480.305298,0.031256,0.000000
24.300001,40.847771,-480.305298,-0.002091,0.001220,0.030995,181.699951,9.256237,0.309953,-480.305298,0.031940,0.000000
24.710001,40.784470,-480.305298,-0.002039,0.001241,0.031533,181.418381,9.241893,0.315327,-480.305298,0.032626,0.000000
25.120001,42.039360,-480.349792,-0.002009,0.001275,0.032373,187.000412,9.526255,0.323730,-480.349792,0.033310,0.000000
25.530001,42.119423,-480.349792,-0.001996,0.001296,0.032912,187.356552,9.544397,0.329119,-480.349792,0.033987,0.000000
25.940001,43.318466,-480.394257,-0.001962,0.001330,0.033778,192.690155,9.816105,0.337779,-480.394257,0.034671,0.000000
26.350000,43.182175,-480.349792,-0.001949,0.001350,0.034299,192.083908,9.785220,0.342987,-480.349792,0.035357,0.000000
26.760002,44.495529,-480.438751,-0.001923,0.001386,0.035201,197.925995,10.082830,0.352010,-480.438751,0.036043,0.000000
27.170002,44.352165,-480.483246,-0.001910,0.001404,0.035660,197.288284,10.050344,0.356598,-480.483246,0.036727,0.000000
27.580002,45.247353,-480.438751,-0.001876,0.001436,0.036485,201.270279,10.253196,0.364849,-480.438751,0.037404,0.000000
27.990002,45.456253,-480.483246,-0.001863,0.001459,0.037065,202.199509,10.300534,0.370647,-480.483246,0.038088,0.000000
28.400002,46.041252,-480.438751,-0.001841,0.001485,0.037725,204.801712,10.433097,0.377248,-480.438751,0.038774,0.000000
28.810001,47.070862,-480.483246,-0.001819,0.001517,0.038532,209.381653,10.666410,0.385317,-480.483246,0.039458,0.000000
29.220001,46.791954,-480.527710,-0.001794,0.001533,0.038930,208.141006,10.603208,0.389299,-480.527710,0.040144,0.000000
29.630001,48.846703,-480.527710,-0.001776,0.001575,0.039997,217.280991,11.068821,0.399973,-480.527710,0.040821,0.000000
30.040001,48.756966,-480.572205,-0.001742,0.001595,0.040517,216.881821,11.048486,0.405165,-480.572205,0.041505,0.000000
30.450001,49.174019,-480.572205,-0.001733,0.001618,0.041107,218.736954,11.142992,0.411070,-480.572205,0.042191,0.000000
30.860001,50.589783,-480.661163,-0.001703,0.001654,0.042000,225.034592,11.463809,0.420002,-480.661163,0.042875,0.000000
31.270002,50.713036,-480.616669,-0.001690,0.001672,0.042459,225.582855,11.491737,0.424590,-480.616669,0.043561,0.000000
31.680002,52.393921,-480.616669,-0.001677,0.001708,0.043379,233.059799,11.872633,0.433794,-480.616669,0.044238,0.000000
32.090000,52.638199,-480.661163,-0.001656,0.001730,0.043934,234.146408,11.927986,0.439335,-480.661163,0.044922,0.000000
32.500000,53.442894,-480.616669,-0.001630,0.001760,0.044706,237.725861,12.110332,0.447057,-480.616669,0.045608,0.000000
32.910000,54.329514,-480.661163,-0.001604,0.001783,0.045278,241.669739,12.311243,0.452779,-480.661163,0.046292,0.000000
33.320000,55.178902,-480.705627,-0.001578,0.001812,0.046024,245.448013,12.503718,0.460243,-480.705627,0.046978,0.000000
33.730003,56.582001,-480.661163,-0.001569,0.001843,0.046813,251.689316,12.821664,0.468131,-480.661163,0.047655,0.000000
34.140003,56.412193,-480.750122,-0.001552,0.001861,0.047273,250.933975,12.783186,0.472733,-480.750122,0.048339,0.000000
34.550003,58.108353,-480.705627,-0.001526,0.001895,0.048132,258.478851,13.167541,0.481318,-480.705627,0.049025,0.000000
34.960003,58.183571,-480.794586,-0.001505,0.001913,0.048590,258.813446,13.184586,0.485905,-480.794586,0.049709,0.000000
35.370003,59.197540,-480.750122,-0.001483,0.001941,0.049302,263.323822,13.414354,0.493020,-480.750122,0.050395,0.000000
35.780003,60.702301,-480.794586,-0.001453,0.001973,0.050126,270.017334,13.755338,0.501256,-480.794586,0.051070,0.000000
36.190002,61.215431,-480.883575,-0.001453,0.002000,0.050811,272.299835,13.871615,0.508115,-480.883575,0.051756,0.000000
36.600002,62.553734,-480.883575,-0.001436,0.002028,0.051514,278.252899,14.174879,0.515139,-480.883575,0.052442,0.000000
37.010002,62.370529,-480.883575,-0.001410,0.002041,0.051842,277.437958,14.133364,0.518425,-480.883575,0.053126,0.000000
37.420002,65.034485,-480.839081,-0.001388,0.002085,0.052954,289.287842,14.737025,0.529537,-480.839081,0.053812,0.000000
37.830002,65.842163,-480.883575,-0.001371,0.002107,0.053526,292.880554,14.920048,0.535260,-480.883575,0.054487,0.000000
38.240002,66.574234,-480.928040,-0.001375,0.002133,0.054185,296.136993,15.085937,0.541846,-480.928040,0.055173,0.000000
38.650002,67.857056,-480.928040,-0.001350,0.002160,0.054861,301.843262,15.376629,0.548613,-480.928040,0.055857,0.000000
39.060001,68.369446,-480.972534,-0.001337,0.002181,0.055399,304.122498,15.492738,0.553988,-480.972534,0.056543,0.000000
39.470001,70.602188,-481.016998,-0.001302,0.002219,0.056353,314.054230,15.998685,0.563525,-481.016998,0.057229,0.000000
39.880001,70.794708,-481.016998,-0.001289,0.002237,0.056829,314.910583,16.042311,0.568294,-481.016998,0.057904,0.000000
40.290001,72.211212,-481.061493,-0.001268,0.002267,0.057576,321.211517,16.363295,0.575758,-481.061493,0.058590,0.000000
40.700001,73.159271,-481.061493,-0.001259,0.002289,0.058139,325.428680,16.578127,0.581390,-481.061493,0.059274,0.000000
41.110001,74.987991,-481.061493,-0.001237,0.002324,0.059032,333.563232,16.992521,0.590322,-481.061493,0.059960,0.000000
41.520000,76.507278,-481.105957,-0.001216,0.002353,0.059760,340.321381,17.336796,0.597605,-481.105957,0.060645,0.000000
41.930000,77.049820,-481.061493,-0.001212,0.002373,0.060281,342.734711,17.459740,0.602813,-481.061493,0.061321,0.000000
42.340000,78.859558,-481.150452,-0.001186,0.002405,0.061088,350.784821,17.869831,0.610882,-481.150452,0.062007,0.000000
42.750004,79.275864,-481.061493,-0.001160,0.002423,0.061547,352.636658,17.964169,0.615469,-481.061493,0.062691,0.000000
43.160004,81.182419,-481.194916,-0.001143,0.002458,0.062440,361.117432,18.396198,0.624402,-481.194916,0.063377,0.000000
43.570004,82.869629,-481.194916,-0.001151,0.002485,0.063126,368.622528,18.778526,0.631260,-481.194916,0.064062,0.000000
43.980003,83.952866,-481.150452,-0.001134,0.002508,0.063715,373.441010,19.023991,0.637149,-481.150452,0.064738,0.000000
44.390003,85.402878,-481.239410,-0.001112,0.002535,0.064401,379.890961,19.352568,0.644007,-481.239410,0.065424,0.000000
44.800003,87.031265,-481.239410,-0.001082,0.002563,0.065111,387.134399,19.721567,0.651108,-481.239410,0.066108,0.000000
45.210003,89.170166,-481.283905,-0.001065,0.002595,0.065909,396.648712,20.206249,0.659086,-481.283905,0.066794,0.000000
45.620003,89.904114,-481.194916,-0.001056,0.002614,0.066395,399.913483,20.372564,0.663946,-481.194916,0.067479,0.000000
46.030003,91.151947,-481.239410,-0.001043,0.002636,0.066967,405.464111,20.655327,0.669669,-481.239410,0.068155,0.000000
46.440002,93.560074,-481.239410,-0.001035,0.002671,0.067843,416.175995,21.201015,0.678435,-481.239410,0.068841,0.000000
46.850002,94.647034,-481.239410,-0.001039,0.002693,0.068407,421.011047,21.447323,0.684067,-481.239410,0.069525,0.000000
47.260002,97.038773,-481.372864,-0.001000,0.002726,0.069248,431.650024,21.989300,0.692484,-481.372864,0.070211,0.000000
47.670002,98.195740,-481.372864,-0.000983,0.002748,0.069795,436.796478,22.251472,0.697950,-481.372864,0.070896,0.000000
48.080002,100.444122,-481.372864,-0.000974,0.002781,0.070635,446.797760,22.760963,0.706352,-481.372864,0.071572,0.000000
48.490002,101.857269,-481.417328,-0.000953,0.002802,0.071182,453.083771,23.081186,0.711818,-481.417328,0.072257,0.000000
48.900002,103.707962,-481.372864,-0.000953,0.002831,0.071902,461.316040,23.500561,0.719024,-481.372864,0.072942,0.000000
49.310001,105.021332,-481.461823,-0.000931,0.002855,0.072510,467.158203,23.798176,0.725095,-481.461823,0.073628,0.000000
49.720001,107.210129,-481.417328,-0.000918,0.002883,0.073238,476.894470,24.294163,0.732377,-481.417328,0.074313,0.000000
50.130001,109.071625,-481.417328,-0.000905,0.002913,0.073992,485.174805,24.715982,0.739917,-481.417328,0.074989,0.000000
50.540001,110.325775,-481.461823,-0.000918,0.002930,0.074434,490.753571,25.000177,0.744337,-481.461823,0.075674,0.000000
50.950001,113.244431,-481.506287,-0.000875,0.002969,0.075415,503.736389,25.661554,0.754148,-481.506287,0.076359,0.000000
51.360001,114.933884,-481.506287,-0.000867,0.002990,0.075934,511.251434,26.044390,0.759341,-481.506287,0.077044,0.000000
51.770004,116.654617,-481.595245,-0.000858,0.003017,0.076620,518.905640,26.434315,0.766199,-481.595245,0.077730,0.000000
52.180004,119.162170,-481.550781,-0.000849,0.003048,0.077409,530.059814,27.002535,0.774087,-481.550781,0.078406,0.000000
52.590004,120.772308,-481.550781,-0.000832,0.003070,0.077972,537.222046,27.367395,0.779719,-481.550781,0.079091,0.000000
53.000004,123.394180,-481.506287,-0.000819,0.003103,0.078814,548.884705,27.961521,0.788136,-481.506287,0.079777,0.000000
53.410004,124.942139,-481.595245,-0.000819,0.003124,0.079351,555.770386,28.312292,0.793511,-481.595245,0.080461,0.000000
53.820004,126.649460,-481.595245,-0.000806,0.003148,0.079958,563.364929,28.699177,0.799582,-481.595245,0.081147,0.000000
54.230003,129.322723,-481.684204,-0.000793,0.003180,0.080774,575.256226,29.304949,0.807742,-481.684204,0.081823,0.000000
54.640003,131.412109,-481.639740,-0.000793,0.003206,0.081424,584.550232,29.778410,0.814237,-481.639740,0.082508,0.000000
55.050003,134.236923,-481.595245,-0.000767,0.003238,0.082256,597.115662,30.418522,0.822564,-481.595245,0.083194,0.000000
55.460003,135.281433,-481.773193,-0.000772,0.003255,0.082682,601.761841,30.655212,0.826818,-481.773193,0.083878,0.000000
55.870003,138.363190,-481.684204,-0.000746,0.003290,0.083575,615.470215,31.353546,0.835750,-481.684204,0.084564,0.000000
56.280003,140.093231,-481.773193,-0.000737,0.003311,0.084094,623.165833,31.745579,0.840943,-481.773193,0.085240,0.000000
56.690002,142.222076,-481.773193,-0.000733,0.003338,0.084797,632.635376,32.227982,0.847968,-481.773193,0.085925,0.000000
57.100002,145.131058,-481.728699,-0.000729,0.003371,0.085622,645.575195,32.887169,0.856219,-481.728699,0.086611,0.000000
57.510002,146.409409,-481.817657,-0.000716,0.003390,0.086106,651.261597,33.176849,0.861064,-481.817657,0.087295,0.000000
57.920002,149.159378,-481.773193,-0.000711,0.003423,0.086939,663.494080,33.799999,0.869390,-481.773193,0.087981,0.000000
58.330002,150.757233,-481.906616,-0.000694,0.003439,0.087339,670.601685,34.162075,0.873387,-481.906616,0.088657,0.000000
58.740002,154.109329,-481.906616,-0.000707,0.003478,0.088336,685.512512,34.921673,0.883364,-481.906616,0.089342,0.000000
59.150002,156.689499,-481.862152,-0.000690,0.003506,0.089046,696.989685,35.506348,0.890465,-481.862152,0.090028,0.000000
59.560001,158.621368,-481.951111,-0.000686,0.003529,0.089637,705.583069,35.944118,0.896369,-481.951111,0.090712,0.000000
59.970001,161.099503,-481.862152,-0.000677,0.003556,0.090330,716.606384,36.505669,0.903303,-481.862152,0.091398,0.000000
60.380001,162.829544,-481.951111,-0.000660,0.003577,0.090851,724.302002,36.897701,0.908511,-481.951111,0.092073,0.000000
60.790005,166.149612,-481.906616,-0.000660,0.003614,0.091787,739.070374,37.650040,0.917867,-481.906616,0.092759,0.000000
61.200005,167.989502,-481.906616,-0.000660,0.003633,0.092273,747.254639,38.066963,0.922727,-481.906616,0.093443,0.000000
61.610004,170.253525,-482.040070,-0.000655,0.003660,0.092966,757.325500,38.580002,0.929661,-482.040070,0.094129,0.000000
62.020004,172.969620,-481.951111,-0.000642,0.003689,0.093696,769.407288,39.195477,0.936958,-481.951111,0.094815,0.000000
62.430004,175.197144,-482.040070,-0.000629,0.003714,0.094345,779.315796,39.700241,0.943453,-482.040070,0.095490,0.000000
62.840004,178.378326,-481.995575,-0.000638,0.003747,0.095178,793.466431,40.421104,0.951780,-481.995575,0.096176,0.000000
63.250004,180.036499,-482.040070,-0.000621,0.003766,0.095664,800.842346,40.796856,0.956640,-482.040070,0.096860,0.000000
63.660004,182.965576,-482.084534,-0.000608,0.003799,0.096497,813.871521,41.460594,0.964967,-482.084534,0.097546,0.000000
64.070000,185.044907,-482.084534,-0.000612,0.003818,0.096983,823.120850,41.931774,0.969826,-482.084534,0.098230,0.000000
64.480003,187.433685,-482.129028,-0.000604,0.003846,0.097685,833.746643,42.473080,0.976851,-482.129028,0.098907,0.000000
64.889999,190.664017,-482.084534,-0.000604,0.003880,0.098551,848.115906,43.205086,0.985511,-482.084534,0.099593,0.000000
65.300003,192.646881,-482.129028,-0.000599,0.003904,0.099167,856.936096,43.654404,0.991673,-482.129028,0.100277,0.000000
65.710007,195.222595,-482.129028,-0.000586,0.003929,0.099800,868.393494,44.238071,0.998001,-482.129028,0.100963,0.000000
66.120003,197.133606,-482.173523,-0.000582,0.003948,0.100286,876.894104,44.671112,1.002861,-482.173523,0.101647,0.000000
66.530006,201.078888,-482.173523,-0.000573,0.003989,0.101326,894.443542,45.565128,1.013262,-482.173523,0.102324,0.000000
66.940002,203.232697,-482.217987,-0.000565,0.004010,0.101856,904.024170,46.053188,1.018561,-482.217987,0.103010,0.000000
67.350006,205.484802,-482.306946,-0.000565,0.004035,0.102489,914.042053,46.563522,1.024889,-482.306946,0.103694,0.000000
67.760002,208.612000,-482.262482,-0.000578,0.004065,0.103261,927.952515,47.272156,1.032610,-482.262482,0.104380,0.000000
68.170006,209.989410,-482.262482,-0.000543,0.004088,0.103833,934.079529,47.584278,1.038333,-482.262482,0.105064,0.000000
68.580002,213.818878,-482.217987,-0.000556,0.004119,0.104613,951.113892,48.452049,1.046130,-482.217987,0.105741,0.000000
68.990005,216.548004,-482.306946,-0.000543,0.004144,0.105255,963.253601,49.070480,1.052549,-482.306946,0.106427,0.000000
69.400002,218.280640,-482.306946,-0.000539,0.004161,0.105697,970.960754,49.463100,1.056970,-482.306946,0.107111,0.000000
69.810005,220.555084,-482.351440,-0.000526,0.004176,0.106071,981.078003,49.978497,1.060709,-482.351440,0.018626,0.000000
70.220001,220.279175,-482.262482,-0.000522,0.004172,0.105966,979.850708,49.915974,1.059665,-482.262482,982.000671,0.000000
70.630005,219.839386,-482.395905,-0.000530,0.004172,0.105976,977.894409,49.816319,1.059755,-482.395905,982.000671,0.000000
71.040001,219.509460,-482.306946,-0.000517,0.004172,0.105976,976.426819,49.741558,1.059755,-482.306946,982.000671,0.000000
71.450005,219.128174,-482.440399,-0.000526,0.004172,0.105976,974.730774,49.655155,1.059755,-482.440399,982.000671,0.000000
71.860001,220.720062,-482.440399,-0.000504,0.004172,0.105976,981.811890,50.015881,1.059755,-482.440399,982.000671,0.000000
72.270004,220.380066,-482.440399,-0.000504,0.004172,0.105976,980.299500,49.938835,1.059755,-482.440399,982.000671,0.000000
72.680000,220.131348,-482.395905,-0.000522,0.004172,0.105976,979.193115,49.882477,1.059755,-482.395905,982.000671,0.000000
73.090004,219.858765,-482.440399,-0.000513,0.004172,0.105976,977.980652,49.820705,1.059755,-482.440399,982.000671,0.000000
73.500000,219.575378,-482.529358,-0.000513,0.004172,0.105976,976.720093,49.756493,1.059755,-482.529358,982.000671,0.000000
73.910004,219.305420,-482.618317,-0.000522,0.004173,0.105983,975.519226,49.695316,1.059831,-482.618317,982.000671,0.000000
74.320007,220.402039,-482.573853,-0.000513,0.004203,0.106764,980.397217,49.943817,1.067643,-482.573853,982.000671,0.000000
74.730003,220.164093,-482.573853,-0.000509,0.004203,0.106764,979.338806,49.889896,1.067643,-482.573853,982.000671,0.000000
75.140007,219.942169,-482.573853,-0.000513,0.004203,0.106764,978.351624,49.839607,1.067643,-482.573853,982.000671,0.000000
75.550003,219.735138,-482.573853,-0.000504,0.004204,0.106790,977.430725,49.792694,1.067901,-482.573853,982.000671,0.000000
75.960007,219.568298,-482.573853,-0.000504,0.004205,0.106808,976.688599,49.754890,1.068082,-482.573853,982.000671,0.000000
76.370003,219.592499,-482.618317,-0.000500,0.004209,0.106904,976.796204,49.760372,1.069036,-482.618317,982.000671,0.000000
76.780006,219.630493,-482.618317,-0.000504,0.004212,0.106981,976.965210,49.768982,1.069808,-482.618317,982.000671,0.000000
77.190002,219.566803,-482.529358,-0.000509,0.004212,0.106981,976.681946,49.754547,1.069808,-482.529358,982.000671,0.000000
77.600006,219.513580,-482.662811,-0.000500,0.004213,0.107016,976.445190,49.742489,1.070156,-482.662811,982.000671,0.000000
78.010002,219.409302,-482.662811,-0.000522,0.004214,0.107034,975.981323,49.718861,1.070338,-482.662811,982.000671,0.000000
78.420006,219.394043,-482.662811,-0.000496,0.004216,0.107076,975.913452,49.715401,1.070762,-482.662811,982.000671,0.000000
78.830002,219.434265,-482.751770,-0.000509,0.004218,0.107129,976.092346,49.724514,1.071292,-482.751770,982.000671,0.000000
79.240005,219.334839,-482.707275,-0.000483,0.004218,0.107129,975.650085,49.701984,1.071292,-482.707275,982.000671,0.000000
79.650002,219.746674,-482.796234,-0.000500,0.004224,0.107285,977.481995,49.795307,1.072851,-482.796234,982.000671,0.000000
80.060005,219.692322,-482.707275,-0.000487,0.004224,0.107285,977.240234,49.782993,1.072851,-482.707275,982.000671,0.000000
80.470001,219.583191,-482.796234,-0.000483,0.004224,0.107285,976.754822,49.758263,1.072851,-482.796234,982.000671,0.000000
80.880005,219.498291,-482.796234,-0.000500,0.004224,0.107285,976.377136,49.739025,1.072851,-482.796234,982.000671,0.000000
81.290001,219.653961,-482.796234,-0.000504,0.004228,0.107388,977.069641,49.774300,1.073881,-482.796234,982.000671,0.000000
81.700005,219.609253,-482.885193,-0.000504,0.004228,0.107388,976.870728,49.764168,1.073881,-482.885193,982.000671,0.000000
82.110001,219.542236,-482.885193,-0.000483,0.004228,0.107397,976.572632,49.748981,1.073972,-482.885193,982.000671,0.000000
82.520004,219.534790,-482.885193,-0.000496,0.004230,0.107441,976.539490,49.747295,1.074411,-482.885193,982.000671,0.000000
82.930000,219.486389,-482.885193,-0.000474,0.004230,0.107441,976.324219,49.736324,1.074411,-482.885193,982.000671,0.000000
83.340004,219.647247,-482.840729,-0.000479,0.004234,0.107536,977.039734,49.772778,1.075364,-482.840729,982.000671,0.000000
83.750008,219.638306,-482.929687,-0.000496,0.004234,0.107536,977.000000,49.770752,1.075364,-482.929687,982.000671,0.000000
84.160004,219.566803,-482.885193,-0.000492,0.004234,0.107536,976.681946,49.754547,1.075364,-482.885193,982.000671,0.000000
84.570007,219.514313,-483.063141,-0.000474,0.004234,0.107553,976.448425,49.742653,1.075531,-483.063141,982.000671,0.000000
84.980003,219.863983,-483.063141,-0.000483,0.004239,0.107683,978.003845,49.821888,1.076833,-483.063141,982.000671,0.000000
85.390007,219.850189,-482.974152,-0.000483,0.004239,0.107683,977.942505,49.818764,1.076833,-482.974152,982.000671,0.000000
85.800003,219.799561,-483.018646,-0.000479,0.004239,0.107683,977.717285,49.807293,1.076833,-483.018646,982.000671,0.000000
86.210007,219.740356,-482.974152,-0.000479,0.004239,0.107683,977.453918,49.793877,1.076833,-482.974152,982.000671,0.000000
86.620003,219.652100,-483.107605,-0.000483,0.004240,0.107692,977.061340,49.773876,1.076924,-483.107605,982.000671,0.000000
87.030006,219.661041,-483.063141,-0.000487,0.004242,0.107736,977.101135,49.775906,1.077363,-483.063141,982.000671,0.000000
87.440002,219.648743,-483.107605,-0.000479,0.004242,0.107744,977.046387,49.773117,1.077438,-483.107605,982.000671,0.000000
87.850006,219.662903,-483.107605,-0.000474,0.004243,0.107770,977.109375,49.776325,1.077696,-483.107605,982.000671,0.000000
88.260002,219.633484,-483.107605,-0.000470,0.004243,0.107770,976.978516,49.769661,1.077696,-483.107605,982.000671,0.000000
88.670006,219.594360,-483.152100,-0.000474,0.004244,0.107788,976.804504,49.760792,1.077878,-483.152100,982.000671,0.000000
89.080002,219.561615,-483.152100,-0.000483,0.004244,0.107797,976.658813,49.753372,1.077968,-483.152100,982.000671,0.000000
89.490005,219.532196,-483.152100,-0.000470,0.004244,0.107804,976.527954,49.746708,1.078044,-483.152100,982.000671,0.000000
89.900002,219.600708,-483.196564,-0.000470,0.004246,0.107857,976.832764,49.762230,1.078574,-483.196564,982.000671,0.000000
90.310005,219.632355,-483.196564,-0.000492,0.004247,0.107874,976.973511,49.769402,1.078740,-483.196564,982.000671,0.000000
90.720001,219.597351,-483.285522,-0.000466,0.004247,0.107874,976.817810,49.761471,1.078740,-483.285522,982.000671,0.000000
91.130005,219.582825,-483.241058,-0.000479,0.004248,0.107892,976.753174,49.758179,1.078922,-483.241058,982.000671,0.000000
91.540001,219.544861,-483.196564,-0.000470,0.004248,0.107892,976.584290,49.749577,1.078922,-483.196564,982.000671,0.000000
91.950005,219.522491,-483.241058,-0.000470,0.004248,0.107892,976.484802,49.744507,1.078922,-483.241058,982.000671,0.000000
92.360001,219.468506,-483.330017,-0.000483,0.004248,0.107892,976.244690,49.732273,1.078922,-483.330017,982.000671,0.000000
92.770004,219.570526,-483.374481,-0.000474,0.004250,0.107960,976.698486,49.755390,1.079603,-483.374481,982.000671,0.000000
93.180008,219.563843,-483.285522,-0.000483,0.004250,0.107960,976.668762,49.753880,1.079603,-483.285522,982.000671,0.000000
93.590004,219.538513,-483.330017,-0.000470,0.004250,0.107960,976.556091,49.748138,1.079603,-483.330017,982.000671,0.000000
94.000008,219.613007,-483.507935,-0.000470,0.004253,0.108022,976.887451,49.765018,1.080224,-483.507935,982.000671,0.000000
94.410004,219.633087,-483.374481,-0.000457,0.004253,0.108022,976.976746,49.769569,1.080224,-483.374481,982.000671,0.000000
94.820007,219.592499,-483.463470,-0.000461,0.004253,0.108022,976.796204,49.760372,1.080224,-483.463470,982.000671,0.000000
95.230003,219.576141,-483.463470,-0.000457,0.004253,0.108022,976.723450,49.756664,1.080224,-483.463470,982.000671,0.000000
95.640007,219.528839,-483.418976,-0.000474,0.004253,0.108022,976.513062,49.745945,1.080224,-483.418976,982.000671,0.000000
96.050003,219.532562,-483.463470,-0.000466,0.004254,0.108056,976.529602,49.746792,1.080557,-483.463470,982.000671,0.000000
96.460007,219.522125,-483.463470,-0.000466,0.004254,0.108056,976.483154,49.744423,1.080557,-483.463470,982.000671,0.000000
96.870003,219.499786,-483.552429,-0.000470,0.004254,0.108056,976.383789,49.739361,1.080557,-483.552429,982.000671,0.000000
97.280006,219.451019,-483.507935,-0.000461,0.004254,0.108056,976.166870,49.728310,1.080557,-483.507935,982.000671,0.000000
97.690002,219.405945,-483.596893,-0.000457,0.004254,0.108056,975.966370,49.718098,1.080557,-483.596893,982.000671,0.000000
98.100006,219.938080,-483.596893,-0.000466,0.004261,0.108230,978.333435,49.838680,1.082298,-483.596893,982.000671,0.000000
98.510002,219.965637,-483.596893,-0.000470,0.004261,0.108230,978.455994,49.844929,1.082298,-483.596893,982.000671,0.000000
98.920006,219.966736,-483.641388,-0.000470,0.004261,0.108230,978.460937,49.845173,1.082298,-483.641388,982.000671,0.000000
99.330002,219.926544,-483.596893,-0.000466,0.004261,0.108230,978.282104,49.836067,1.082298,-483.596893,982.000671,0.000000
99.740005,219.906433,-483.685852,-0.000453,0.004261,0.108230,978.192688,49.831509,1.082298,-483.685852,982.000671,0.000000
100.150002,219.876251,-483.730347,-0.000453,0.004261,0.108230,978.058411,49.824673,1.082298,-483.730347,982.000671,0.000000
100.560005,219.839752,-483.641388,-0.000466,0.004261,0.108230,977.896057,49.816402,1.082298,-483.641388,982.000671,0.000000
100.970001,219.812225,-483.730347,-0.000453,0.004261,0.108230,977.773621,49.810162,1.082298,-483.730347,982.000671,0.000000
101.380005,219.790253,-483.685852,-0.000470,0.004261,0.108230,977.675842,49.805183,1.082298,-483.685852,982.000671,0.000000
101.790009,219.758575,-483.774811,-0.000466,0.004261,0.108230,977.534973,49.798008,1.082298,-483.774811,982.000671,0.000000
102.200005,219.723572,-483.819305,-0.000474,0.004261,0.108230,977.379272,49.790073,1.082298,-483.819305,982.000671,0.000000
102.610008,219.665497,-483.774811,-0.000453,0.004261,0.108230,977.120911,49.776913,1.082298,-483.774811,982.000671,0.000000
103.020004,219.640930,-483.819305,-0.000457,0.004261,0.108239,977.011658,49.771343,1.082389,-483.819305,982.000671,0.000000
103.430008,219.605164,-483.774811,-0.000453,0.004261,0.108239,976.852539,49.763241,1.082389,-483.774811,982.000671,0.000000
103.840004,219.583954,-483.819305,-0.000457,0.004261,0.108239,976.758240,49.758434,1.082389,-483.819305,982.000671,0.000000
104.250008,219.566437,-483.819305,-0.000470,0.004261,0.108239,976.680298,49.754467,1.082389,-483.819305,982.000671,0.000000
104.660004,219.534790,-483.863800,-0.000448,0.004261,0.108239,976.539490,49.747295,1.082389,-483.863800,982.000671,0.000000
105.070007,219.496063,-483.908264,-0.000457,0.004262,0.108248,976.367249,49.738522,1.082480,-483.908264,982.000671,0.000000
105.480003,219.449158,-483.952759,-0.000457,0.004262,0.108256,976.158630,49.727890,1.082556,-483.952759,982.000671,0.000000
105.890007,219.411530,-483.952759,-0.000466,0.004262,0.108256,975.991211,49.719360,1.082556,-483.952759,982.000671,0.000000
106.300003,219.826355,-483.952759,-0.000457,0.004268,0.108411,977.836487,49.813366,1.084115,-483.952759,982.000671,0.000000
106.710007,219.872894,-483.908264,-0.000457,0.004268,0.108411,978.043457,49.823910,1.084115,-483.908264,982.000671,0.000000
107.120003,219.889282,-483.997223,-0.000457,0.004268,0.108411,978.116394,49.827621,1.084115,-483.997223,982.000671,0.000000
107.530006,219.876251,-483.997223,-0.000453,0.004268,0.108411,978.058411,49.824673,1.084115,-483.997223,982.000671,0.000000
107.940002,219.869171,-483.997223,-0.000448,0.004268,0.108411,978.026917,49.823067,1.084115,-483.997223,982.000671,0.000000
108.350006,219.858398,-484.086182,-0.000448,0.004268,0.108411,977.979004,49.820625,1.084115,-484.086182,982.000671,0.000000
108.760002,219.851685,-484.041718,-0.000453,0.004268,0.108411,977.949158,49.819103,1.084115,-484.041718,982.000671,0.000000
109.170006,219.831940,-484.086182,-0.000461,0.004268,0.108411,977.861328,49.814629,1.084115,-484.086182,982.000671,0.000000
109.580002,219.812592,-484.041718,-0.000444,0.004268,0.108411,977.775269,49.810246,1.084115,-484.041718,982.000671,0.000000
109.990005,219.789124,-484.130676,-0.000457,0.004268,0.108411,977.670837,49.804928,1.084115,-484.130676,982.000671,0.000000
110.400002,219.748169,-484.130676,-0.000457,0.004268,0.108411,977.488647,49.795647,1.084115,-484.130676,982.000671,0.000000
110.810005,219.721710,-484.130676,-0.000444,0.004268,0.108411,977.370972,49.789654,1.084115,-484.130676,982.000671,0.000000
111.220009,219.696411,-484.130676,-0.000453,0.004268,0.108411,977.258423,49.783916,1.084115,-484.130676,982.000671,0.000000
111.630005,219.659546,-484.130676,-0.000448,0.004268,0.108411,977.094482,49.775562,1.084115,-484.130676,982.000671,0.000000
112.040009,219.633484,-484.219635,-0.000448,0.004268,0.108411,976.978516,49.769661,1.084115,-484.219635,982.000671,0.000000
112.450005,219.608521,-484.264099,-0.000457,0.004268,0.108411,976.867493,49.764004,1.084115,-484.264099,982.000671,0.000000
112.860008,219.598846,-484.175140,-0.000440,0.004268,0.108411,976.824463,49.761806,1.084115,-484.175140,982.000671,0.000000
113.270004,219.553040,-484.264099,-0.000466,0.004268,0.108411,976.620667,49.751431,1.084115,-484.264099,982.000671,0.000000
113.680008,219.546326,-484.219635,-0.000453,0.004269,0.108421,976.590820,49.749908,1.084206,-484.219635,982.000671,0.000000
114.090004,219.730652,-484.308594,-0.000444,0.004272,0.108516,977.410767,49.791679,1.085160,-484.308594,982.000671,0.000000
114.500008,219.769379,-484.308594,-0.000461,0.004272,0.108516,977.583008,49.800453,1.085160,-484.308594,982.000671,0.000000
114.910004,219.769379,-484.308594,-0.000440,0.004272,0.108516,977.583008,49.800453,1.085160,-484.308594,982.000671,0.000000
115.320007,219.762695,-484.397552,-0.000466,0.004272,0.108516,977.553284,49.798939,1.085160,-484.397552,982.000671,0.000000
115.730003,219.745178,-484.308594,-0.000440,0.004272,0.108516,977.475342,49.794971,1.085160,-484.308594,982.000671,0.000000
116.140007,219.734772,-484.397552,-0.000444,0.004272,0.108516,977.429077,49.792610,1.085160,-484.397552,982.000671,0.000000
116.550003,219.702362,-484.397552,-0.000435,0.004272,0.108516,977.284912,49.785263,1.085160,-484.397552,982.000671,0.000000
116.960007,219.676300,-484.397552,-0.000453,0.004272,0.108516,977.169006,49.779362,1.085160,-484.397552,982.000671,0.000000
117.370003,219.669586,-484.486511,-0.000440,0.004272,0.108516,977.139099,49.777840,1.085160,-484.486511,982.000671,0.000000
117.780006,219.638306,-484.397552,-0.000440,0.004272,0.108516,977.000000,49.770752,1.085160,-484.397552,982.000671,0.000000
118.190002,219.630859,-484.486511,-0.000448,0.004272,0.108516,976.966858,49.769066,1.085160,-484.486511,982.000671,0.000000
118.600006,219.620056,-484.486511,-0.000457,0.004273,0.108525,976.918823,49.766617,1.085250,-484.486511,982.000671,0.000000
119.010002,219.609253,-484.531006,-0.000440,0.004273,0.108525,976.870728,49.764168,1.085250,-484.531006,982.000671,0.000000
119.420006,219.582825,-484.575470,-0.000457,0.004273,0.108534,976.753174,49.758179,1.085341,-484.575470,982.000671,0.000000
119.830009,219.562347,-484.486511,-0.000440,0.004273,0.108534,976.662109,49.753536,1.085341,-484.486511,982.000671,0.000000
120.240005,219.549683,-484.531006,-0.000440,0.004273,0.108534,976.605774,49.750671,1.085341,-484.531006,982.000671,0.000000
120.650009,219.530701,-484.575470,-0.000448,0.004273,0.108534,976.521301,49.746368,1.085341,-484.575470,982.000671,0.000000
121.060005,219.573517,-484.531006,-0.000448,0.004276,0.108620,976.711792,49.756069,1.086204,-484.531006,982.000671,0.000000
121.470009,219.699371,-484.619965,-0.000431,0.004276,0.108620,977.271606,49.784592,1.086204,-484.619965,982.000671,0.000000
121.880005,219.732910,-484.619965,-0.000448,0.004276,0.108620,977.420776,49.792187,1.086204,-484.619965,982.000671,0.000000
122.290009,219.741089,-484.664429,-0.000431,0.004276,0.108620,977.457153,49.794041,1.086204,-484.664429,982.000671,0.000000
122.700005,219.731781,-484.619965,-0.000444,0.004276,0.108620,977.415771,49.791935,1.086204,-484.619965,982.000671,0.000000
123.110008,219.719849,-484.664429,-0.000448,0.004276,0.108620,977.362671,49.789230,1.086204,-484.664429,982.000671,0.000000
123.520004,219.709076,-484.664429,-0.000444,0.004276,0.108620,977.314758,49.786789,1.086204,-484.664429,982.000671,0.000000
123.930008,219.697906,-484.753418,-0.000427,0.004276,0.108620,977.265076,49.784260,1.086204,-484.753418,982.000671,0.000000
124.340004,219.688965,-484.708923,-0.000431,0.004276,0.108620,977.225342,49.782234,1.086204,-484.708923,982.000671,0.000000
124.750008,219.667725,-484.753418,-0.000440,0.004276,0.108620,977.130859,49.777416,1.086204,-484.753418,982.000671,0.000000
125.160004,219.642395,-484.753418,-0.000431,0.004276,0.108620,977.018188,49.771679,1.086204,-484.753418,982.000671,0.000000
125.570007,219.645020,-484.842377,-0.000453,0.004277,0.108630,977.029846,49.772274,1.086295,-484.842377,982.000671,0.000000
125.980003,219.636444,-484.753418,-0.000448,0.004277,0.108630,976.991699,49.770329,1.086295,-484.753418,982.000671,0.000000
126.390007,219.610016,-484.753418,-0.000440,0.004277,0.108637,976.874146,49.764339,1.086371,-484.753418,982.000671,0.000000
126.800003,219.610748,-484.886841,-0.000431,0.004277,0.108637,976.877380,49.764507,1.086371,-484.886841,982.000671,0.000000
127.210007,219.664368,-484.797882,-0.000444,0.004279,0.108698,977.115906,49.776657,1.086976,-484.797882,982.000671,0.000000
127.620003,219.730286,-484.931335,-0.000435,0.004279,0.108698,977.409119,49.791595,1.086976,-484.931335,982.000671,0.000000
128.029999,219.745178,-484.886841,-0.000448,0.004279,0.108698,977.475342,49.794971,1.086976,-484.886841,982.000671,0.000000
128.440002,219.752258,-484.931335,-0.000423,0.004279,0.108698,977.506836,49.796574,1.086976,-484.931335,982.000671,0.000000
128.850006,219.732910,-484.931335,-0.000448,0.004279,0.108698,977.420776,49.792187,1.086976,-484.931335,982.000671,0.000000
129.260010,219.737366,-484.886841,-0.000440,0.004279,0.108698,977.440613,49.793198,1.086976,-484.886841,982.000671,0.000000
129.670013,219.732513,-485.020294,-0.000448,0.004279,0.108698,977.419006,49.792099,1.086976,-485.020294,982.000671,0.000000
130.080002,219.710937,-484.931335,-0.000457,0.004279,0.108698,977.323059,49.787209,1.086976,-484.931335,982.000671,0.000000
130.490005,219.675537,-485.020294,-0.000453,0.004266,0.108351,977.165588,49.779190,1.083509,-485.020294,0.108507,0.000000
130.900009,219.557129,-484.931335,-0.000444,0.004253,0.108030,976.638916,49.752357,1.080300,-484.931335,0.107823,0.000000
131.310013,219.434998,-484.975800,-0.000431,0.004231,0.107476,976.095642,49.724682,1.074759,-484.975800,0.107146,0.000000
131.720001,218.417664,-485.020294,-0.000423,0.004203,0.106755,971.570312,49.494152,1.067552,-485.020294,0.106462,0.000000
132.130005,217.865814,-485.064758,-0.000423,0.004194,0.106522,969.115540,49.369099,1.065221,-485.064758,0.105776,0.000000
132.540009,217.013824,-485.064758,-0.000414,0.004164,0.105759,965.325684,49.176033,1.057590,-485.064758,0.105090,0.000000
132.950012,216.631409,-485.064758,-0.000423,0.004132,0.104961,963.624634,49.089378,1.049612,-485.064758,0.104406,0.000000
133.360001,216.413208,-485.109253,-0.000392,0.004102,0.104189,962.654053,49.039932,1.041891,-485.109253,0.103729,0.000000
133.770004,216.071716,-485.109253,-0.000401,0.004073,0.103452,961.135010,48.962551,1.034518,-485.109253,0.103045,0.000000
134.180008,215.885162,-485.109253,-0.000427,0.004050,0.102880,960.305176,48.920280,1.028795,-485.109253,0.102359,0.000000
134.590012,215.510559,-485.198212,-0.000401,0.004035,0.102489,958.638855,48.835388,1.024889,-485.198212,0.101674,0.000000
135.000000,214.149536,-485.198212,-0.000410,0.004005,0.101735,952.584717,48.526978,1.017349,-485.198212,0.100989,0.000000
135.410004,213.318420,-485.153748,-0.000401,0.003974,0.100937,948.887695,48.338646,1.009371,-485.153748,0.100312,0.000000
135.820007,211.644958,-485.242706,-0.000405,0.003943,0.100156,941.443787,47.959435,1.001559,-485.242706,0.099628,0.000000
136.230011,209.968170,-485.242706,-0.000401,0.003919,0.099532,933.985046,47.579468,0.995321,-485.242706,0.098942,0.000000
136.639999,208.876740,-485.287170,-0.000414,0.003905,0.099193,929.130127,47.332146,0.991930,-485.287170,0.098257,0.000000
137.050003,205.778229,-485.287170,-0.000397,0.003869,0.098283,915.347290,46.630016,0.982831,-485.287170,0.097572,0.000000
137.460007,203.034607,-485.287170,-0.000388,0.003844,0.097632,903.143066,46.008301,0.976321,-485.287170,0.096895,0.000000
137.870010,199.774841,-485.287170,-0.000397,0.003812,0.096825,888.642883,45.269627,0.968252,-485.287170,0.096211,0.000000
138.280014,197.454956,-485.331665,-0.000410,0.003792,0.096306,878.323486,44.743931,0.963059,-485.331665,0.095525,0.000000
138.690002,194.819702,-485.376129,-0.000405,0.003767,0.095690,866.601318,44.146778,0.956897,-485.376129,0.094840,0.000000
139.100006,191.675385,-485.331665,-0.000401,0.003739,0.094978,852.614685,43.434265,0.949782,-485.331665,0.094155,0.000000
139.510010,188.726562,-485.420624,-0.000397,0.003713,0.094303,839.497681,42.766048,0.943029,-485.420624,0.093478,0.000000
139.920013,185.501434,-485.376129,-0.000397,0.003682,0.093531,825.151611,42.035225,0.935308,-485.376129,0.092794,0.000000
140.330002,183.076172,-485.376129,-0.000392,0.003659,0.092933,814.363464,41.485653,0.929328,-485.376129,0.092108,0.000000
140.740005,180.241302,-485.420624,-0.000410,0.003632,0.092264,801.753357,40.843262,0.922636,-485.420624,0.091423,0.000000
141.150009,176.819199,-485.420624,-0.000410,0.003604,0.091535,786.531067,40.067802,0.915354,-485.420624,0.090738,0.000000
141.560013,173.412735,-485.509583,-0.000397,0.003571,0.090712,771.378357,39.295887,0.907118,-485.509583,0.090061,0.000000
141.970001,170.781555,-485.465088,-0.000397,0.003554,0.090270,759.674316,38.699654,0.902697,-485.465088,0.089377,0.000000
142.380005,167.845032,-485.420624,-0.000401,0.003528,0.089611,746.612000,38.034229,0.896112,-485.420624,0.088691,0.000000
142.790009,164.147003,-485.598541,-0.000397,0.003498,0.088839,730.162354,37.196243,0.888391,-485.598541,0.088006,0.000000
143.200012,160.749847,-485.554047,-0.000410,0.003469,0.088111,715.051025,36.426434,0.881108,-485.554047,0.087321,0.000000
143.610001,157.167252,-485.598541,-0.000405,0.003435,0.087260,699.114868,35.614605,0.872600,-485.598541,0.086645,0.000000
144.020004,154.717407,-485.598541,-0.000427,0.003418,0.086827,688.217407,35.059467,0.868270,-485.598541,0.085960,0.000000
144.430008,151.225677,-485.554047,-0.000414,0.003389,0.086081,672.685425,34.268227,0.860806,-485.554047,0.085275,0.000000
144.840012,149.966675,-485.598541,-0.000427,0.003380,0.085847,667.085083,33.982937,0.858475,-485.598541,0.084589,0.000000
145.250000,145.628906,-485.643036,-0.000414,0.003338,0.084797,647.789734,32.999981,0.847968,-485.643036,0.083904,0.000000
145.660004,142.049667,-485.687500,-0.000418,0.003306,0.083966,631.868469,32.188915,0.839656,-485.687500,0.083228,0.000000
146.070007,139.093781,-485.643036,-0.000431,0.003282,0.083366,618.720032,31.519100,0.833661,-485.643036,0.082543,0.000000
146.480011,136.070862,-485.731995,-0.000427,0.003258,0.082751,605.273437,30.834099,0.827514,-485.731995,0.081858,0.000000
146.889999,132.542633,-485.731995,-0.000435,0.003223,0.081866,589.579102,30.034590,0.818658,-485.731995,0.081172,0.000000
147.300003,129.709244,-485.687500,-0.000440,0.003206,0.081424,576.975525,29.392534,0.814237,-485.687500,0.080488,0.000000
147.710007,126.058884,-485.776459,-0.000444,0.003174,0.080617,560.737915,28.565351,0.806167,-485.776459,0.079811,0.000000
148.120010,123.260880,-485.731995,-0.000457,0.003151,0.080028,548.291748,27.931314,0.800278,-485.731995,0.079126,0.000000
148.530014,120.477386,-485.731995,-0.000461,0.003122,0.079309,535.910156,27.300566,0.793087,-485.731995,0.078441,0.000000
148.940002,116.878784,-485.776459,-0.000457,0.003095,0.078614,519.902771,26.485111,0.786138,-485.776459,0.077755,0.000000
149.350006,114.044647,-485.776459,-0.000448,0.003069,0.077964,507.295929,25.842886,0.779643,-485.776459,0.077071,0.000000
149.760010,111.131577,-485.820953,-0.000466,0.003044,0.077313,494.337952,25.182775,0.773133,-485.820953,0.076394,0.000000
150.170013,108.697006,-485.820953,-0.000466,0.003024,0.076811,483.508423,24.631094,0.768107,-485.820953,0.075708,0.000000
150.580002,105.020950,-485.820953,-0.000461,0.002989,0.075927,467.156525,23.798086,0.759265,-485.820953,0.075024,0.000000
150.990005,101.790253,-485.820953,-0.000470,0.002962,0.075232,452.785645,23.066002,0.752316,-485.820953,0.074338,0.000000
151.400009,97.940292,-485.820953,-0.000466,0.002928,0.074382,435.660187,22.193586,0.743823,-485.820953,0.073654,0.000000
151.810013,96.059814,-485.909912,-0.000487,0.002910,0.073922,427.295410,21.767466,0.739220,-485.909912,0.072977,0.000000
152.220001,93.161255,-485.909912,-0.000487,0.002886,0.073315,414.401947,21.110641,0.733149,-485.909912,0.072291,0.000000
152.630005,89.179108,-485.865417,-0.000487,0.002847,0.072319,396.688477,20.208275,0.723187,-485.865417,0.071607,0.000000
153.040009,86.500641,-485.998871,-0.000504,0.002827,0.071807,384.774078,19.601326,0.718070,-485.998871,0.070921,0.000000
153.450012,82.985062,-485.865417,-0.000483,0.002797,0.071052,369.135986,18.804684,0.710516,-485.865417,0.070237,0.000000
153.860001,79.961777,-485.954376,-0.000487,0.002771,0.070384,355.687744,18.119598,0.703839,-485.954376,0.069560,0.000000
154.270004,78.454407,-485.954376,-0.000492,0.002752,0.069907,348.982635,17.778023,0.699070,-485.954376,0.068874,0.000000
154.680008,73.542816,-485.998871,-0.000509,0.002714,0.068937,327.134796,16.665041,0.689366,-485.998871,0.068190,0.000000
155.090012,71.348053,-485.998871,-0.000513,0.002694,0.068425,317.371979,16.167700,0.684248,-485.998871,0.067504,0.000000
155.500000,67.802322,-486.043365,-0.000522,0.002662,0.067627,301.599792,15.364226,0.676270,-486.043365,0.066820,0.000000
155.910004,65.748322,-486.087830,-0.000517,0.002645,0.067192,292.463135,14.898783,0.671925,-486.087830,0.066143,0.000000
156.320007,63.820175,-486.043365,-0.000509,0.002624,0.066646,283.886322,14.461859,0.666459,-486.043365,0.065459,0.000000
156.730011,59.115616,-486.087830,-0.000522,0.002585,0.065666,262.959381,13.395790,0.656664,-486.087830,0.064773,0.000000
157.140015,56.561890,-486.132324,-0.000548,0.002562,0.065068,251.599854,12.817107,0.650684,-486.132324,0.064089,0.000000
157.550003,53.095848,-486.043365,-0.000526,0.002532,0.064305,236.182129,12.031691,0.643054,-486.043365,0.063403,0.000000
157.960007,50.857887,-486.176788,-0.000560,0.002511,0.063785,226.227188,11.524562,0.637846,-486.176788,0.062726,0.000000
158.370010,47.166931,-486.132324,-0.000539,0.002478,0.062952,209.808990,10.688179,0.629519,-486.132324,0.062042,0.000000
158.780014,44.151085,-486.132324,-0.000543,0.002450,0.062240,196.393829,10.004779,0.622403,-486.132324,0.061356,0.000000
159.190002,40.632538,-486.221283,-0.000548,0.002419,0.061452,180.742554,9.207465,0.614516,-486.221283,0.060672,0.000000
159.600006,39.073418,-486.132324,-0.000560,0.002405,0.061079,173.807236,8.854163,0.610791,-486.132324,0.059986,0.000000
160.010010,36.320839,-486.265747,-0.000543,0.002379,0.060437,161.563156,8.230420,0.604372,-486.265747,0.059309,0.000000
160.420013,32.549820,-486.221283,-0.000569,0.002344,0.059526,144.788834,7.375895,0.595258,-486.221283,0.058625,0.000000
160.830002,29.704529,-486.221283,-0.000582,0.002319,0.058902,132.132339,6.731143,0.589020,-486.221283,0.057939,0.000000
161.240005,26.024742,-486.221283,-0.000569,0.002286,0.058060,115.763832,5.897291,0.580603,-486.221283,0.057255,0.000000
161.650009,23.539154,-486.221283,-0.000578,0.002262,0.057462,104.707390,5.334048,0.574623,-486.221283,0.056569,0.000000
162.060013,20.716202,-486.310242,-0.000591,0.002237,0.056829,92.150269,4.694358,0.568294,-486.310242,0.055892,0.000000
162.470001,17.667213,-486.265747,-0.000582,0.002209,0.056118,78.587692,4.003448,0.561179,-486.265747,0.055208,0.000000
162.880005,15.619164,-486.399200,-0.000573,0.002188,0.055580,69.477509,3.539353,0.555804,-486.399200,0.054522,0.000000
163.290009,12.124825,-486.354706,-0.000586,0.002157,0.054792,53.933914,2.747524,0.547917,-486.354706,0.053838,0.000000
163.700012,9.626572,-486.354706,-0.000578,0.002133,0.054185,42.821129,2.181412,0.541846,-486.354706,0.053152,0.000000
164.110001,6.649826,-486.443695,-0.000591,0.002105,0.053473,29.579903,1.506872,0.534730,-486.443695,0.052475,0.000000
164.520004,3.944916,-486.399200,-0.000599,0.002078,0.052780,17.547861,0.893931,0.527796,-486.399200,0.051791,0.000000
164.930008,1.217285,-486.399200,-0.000599,0.002050,0.052077,5.414755,0.275841,0.520771,-486.399200,0.051105,0.000000
165.340012,-1.092167,-486.488159,-0.000599,0.002024,0.051419,-4.858201,-0.247489,0.514186,-486.488159,0.050421,0.000000
165.750015,-0.428230,-486.443695,-0.000634,0.002002,0.050846,-1.904863,-0.097038,0.508463,-486.443695,0.049735,0.000000
166.160004,-0.118042,-486.488159,-0.000638,0.001980,0.050282,-0.525077,-0.026749,0.502816,-486.488159,0.049060,0.000000
166.570007,-0.018616,-486.488159,-0.000668,0.001949,0.049509,-0.082807,-0.004218,0.495095,-486.488159,0.048374,0.000000
166.980011,-0.010796,-486.532654,-0.000677,0.001919,0.048746,-0.048021,-0.002446,0.487464,-486.532654,0.047688,0.000000
167.390015,0.002235,-486.532654,-0.000720,0.001896,0.048167,0.009944,0.000507,0.481666,-486.532654,0.047004,0.000000
167.800003,-0.012283,-486.577118,-0.000733,0.001868,0.047446,-0.054639,-0.002783,0.474459,-486.577118,0.046318,0.000000
168.210007,0.005219,-486.577118,-0.000767,0.001830,0.046492,0.023213,0.001183,0.464921,-486.577118,0.046292,0.000000
168.400009,-0.025696,-486.577118,-0.000776,0.001831,0.046501,-0.114301,-0.005823,0.465012,-486.577118,0.046292,0.000000