File: Data/sima compression 500bar/P2-17-500bar-3_11072024_171554.csv
Time (sec),S:Load (lbs),S:HL1 (DIM),S:LVDT (in),S:Position (in),Ch:Position (mm),Ch:Load (N),Ch:Stress (MPa),Ch:Strain (mm/mm),Ch:HL1 (DIM),Set Point (),Cycles ()
0.010000,-0.088249,-412.293945,-0.011921,-0.008918,-0.226520,-0.392552,-0.019998,-2.265199,-412.293945,-0.226347,0.000000
0.460000,-0.090485,-412.293945,-0.011917,-0.008844,-0.224629,-0.402496,-0.020504,-2.246290,-412.293945,-0.224005,0.000000
0.910000,-0.154160,-412.338409,-0.011693,-0.008560,-0.217432,-0.685736,-0.034933,-2.174316,-412.338409,-0.216494,0.000000
1.360000,-0.094208,-412.338409,-0.011387,-0.008269,-0.210034,-0.419057,-0.021348,-2.100344,-412.338409,-0.209002,0.000000
1.810000,-0.052872,-412.382904,-0.011094,-0.007980,-0.202698,-0.235185,-0.011981,-2.026978,-412.382904,-0.201509,0.000000
2.260000,-0.088249,-412.382904,-0.010774,-0.007675,-0.194936,-0.392552,-0.019998,-1.949357,-412.382904,-0.194017,0.000000
2.710000,-0.138145,-412.427368,-0.010473,-0.007383,-0.187520,-0.614502,-0.031304,-1.875203,-412.427368,-0.186506,0.000000
3.160000,-0.077454,-412.427368,-0.010171,-0.007094,-0.180184,-0.344531,-0.017551,-1.801837,-412.427368,-0.179013,0.000000
3.610000,-0.065536,-412.471863,-0.009869,-0.006795,-0.172596,-0.291521,-0.014851,-1.725958,-412.471863,-0.171521,0.000000
4.060000,-0.085274,-412.471863,-0.009572,-0.006504,-0.165199,-0.379317,-0.019323,-1.651986,-412.471863,-0.164028,0.000000
4.510000,-0.078941,-412.471863,-0.009248,-0.006204,-0.157585,-0.351149,-0.017888,-1.575849,-412.471863,-0.156518,0.000000
4.960000,-0.107239,-412.516327,-0.008959,-0.005903,-0.149935,-0.477022,-0.024301,-1.499348,-412.516327,-0.149025,0.000000
5.410000,-0.135918,-412.516327,-0.008662,-0.005615,-0.142616,-0.604592,-0.030799,-1.426164,-412.516327,-0.141532,0.000000
5.860000,-0.043564,-412.560822,-0.008360,-0.005320,-0.135124,-0.193782,-0.009872,-1.351238,-412.560822,-0.134040,0.000000
6.310000,-0.047661,-412.605316,-0.008058,-0.005024,-0.127613,-0.212006,-0.010800,-1.276130,-412.605316,-0.126529,0.000000
6.760000,-0.106873,-412.605316,-0.007726,-0.004726,-0.120033,-0.475393,-0.024218,-1.200326,-412.605316,-0.119036,0.000000
7.210001,-0.071495,-412.605316,-0.007429,-0.004432,-0.112566,-0.318026,-0.016201,-1.125658,-412.605316,-0.111544,0.000000
7.660000,-0.065163,-412.560822,-0.007148,-0.004143,-0.105222,-0.289858,-0.014766,-1.052216,-412.560822,-0.104050,0.000000
8.110001,-0.088249,-412.694275,-0.006838,-0.003845,-0.097659,-0.392552,-0.019998,-0.976594,-412.694275,-0.096557,0.000000
8.560000,-0.068512,-412.783234,-0.006510,-0.003548,-0.090114,-0.304756,-0.015525,-0.901138,-412.783234,-0.089048,0.000000
9.010000,-0.078194,-412.738739,-0.006222,-0.003253,-0.082638,-0.347823,-0.017719,-0.826379,-412.738739,-0.081554,0.000000
9.460000,-0.164963,-412.783234,-0.005920,-0.002957,-0.075103,-0.733791,-0.037381,-0.751029,-412.783234,-0.074061,0.000000
9.910001,-0.071869,-412.783234,-0.005614,-0.002663,-0.067636,-0.319689,-0.016286,-0.676361,-412.783234,-0.066569,0.000000
10.360001,-0.023460,-412.783234,-0.005312,-0.002371,-0.060221,-0.104357,-0.005316,-0.602207,-412.783234,-0.059058,0.000000
10.810000,-0.102402,-412.872192,-0.004993,-0.002074,-0.052668,-0.455506,-0.023205,-0.526676,-412.872192,-0.051565,0.000000
11.260000,-0.083412,-412.783234,-0.004695,-0.001773,-0.045036,-0.371036,-0.018901,-0.450357,-412.783234,-0.044073,0.000000
11.710001,-0.093834,-412.872192,-0.004424,-0.001495,-0.037985,-0.417394,-0.021263,-0.379852,-412.872192,-0.036580,0.000000
12.160001,-0.077827,-412.916656,-0.004087,-0.001189,-0.030206,-0.346194,-0.017636,-0.302065,-412.916656,-0.029070,0.000000
12.610001,-0.059204,-412.916656,-0.003786,-0.000891,-0.022635,-0.263353,-0.013416,-0.226352,-412.916656,-0.021577,0.000000
13.060000,-0.057716,-412.961151,-0.003505,-0.000609,-0.015464,-0.256735,-0.013079,-0.154636,-412.961151,-0.014084,0.000000
13.510000,-0.112457,-412.961151,-0.003182,-0.000298,-0.007562,-0.500235,-0.025483,-0.075622,-412.961151,-0.006592,0.000000
13.960001,-0.002235,-413.005646,-0.002893,-0.000007,-0.000174,-0.009944,-0.000507,-0.001741,-413.005646,0.000919,0.000000
14.410001,0.086761,-412.961151,-0.002854,-0.000005,-0.000139,0.385934,0.019660,-0.001393,-412.961151,0.000104,0.000000
14.860001,0.135170,-412.961151,-0.002867,-0.000004,-0.000095,0.601266,0.030630,-0.000954,-412.961151,0.000615,0.000000
15.310000,0.307205,-413.050110,-0.002850,0.000015,0.000391,1.366517,0.069614,0.003906,-413.050110,0.001370,0.000000
15.760001,0.834862,-413.094604,-0.002828,0.000051,0.001291,3.713650,0.189182,0.012914,-413.094604,0.002115,0.000000
16.210001,1.432518,-413.094604,-0.002798,0.000076,0.001924,6.372159,0.324613,0.019242,-413.094604,0.002870,0.000000
16.660000,2.463249,-413.139069,-0.002802,0.000109,0.002775,10.957080,0.558180,0.027751,-413.139069,0.003615,0.000000
17.110001,3.335342,-413.139069,-0.002772,0.000134,0.003399,14.836344,0.755799,0.033988,-413.139069,0.004371,0.000000
17.560001,4.722054,-413.139069,-0.002755,0.000168,0.004266,21.004744,1.070033,0.042663,-413.139069,0.005116,0.000000
18.010000,5.831726,-413.228027,-0.002734,0.000195,0.004943,25.940813,1.321488,0.049431,-413.228027,0.005871,0.000000
18.460001,7.155510,-413.228027,-0.002703,0.000225,0.005706,31.829298,1.621462,0.057061,-413.228027,0.006616,0.000000
18.910002,8.512436,-413.228027,-0.002703,0.000254,0.006443,37.865208,1.928946,0.064434,-413.228027,0.007371,0.000000
19.360001,9.553589,-413.228027,-0.002669,0.000275,0.006998,42.496487,2.164874,0.069975,-413.228027,0.008116,0.000000
19.810001,11.707390,-413.228027,-0.002647,0.000317,0.008056,52.077072,2.652932,0.080558,-413.228027,0.008872,0.000000
20.260000,12.843124,-413.316986,-0.002639,0.000340,0.008646,57.129070,2.910294,0.086462,-413.316986,0.009617,0.000000
20.710001,14.652115,-413.361481,-0.002626,0.000376,0.009556,65.175865,3.320217,0.095561,-413.361481,0.010372,0.000000
21.160002,15.694756,-413.316986,-0.002600,0.000397,0.010077,69.813759,3.556482,0.100769,-413.316986,0.011117,0.000000
21.610001,17.531296,-413.316986,-0.002578,0.000434,0.011031,77.983101,3.972648,0.110307,-413.316986,0.011872,0.000000
22.060001,18.821198,-413.361481,-0.002570,0.000462,0.011733,83.720871,4.264944,0.117332,-413.361481,0.012617,0.000000
22.510000,20.521820,-413.405945,-0.002552,0.000494,0.012557,91.285614,4.650311,0.125568,-413.405945,0.013373,0.000000
22.960001,21.590530,-413.450439,-0.002531,0.000520,0.013199,96.039474,4.892484,0.131987,-413.450439,0.014118,0.000000
23.410002,23.214447,-413.494934,-0.002522,0.000551,0.013987,103.263016,5.260469,0.139875,-413.494934,0.014873,0.000000
23.860001,24.484978,-413.494934,-0.002505,0.000578,0.014690,108.914619,5.548375,0.146899,-413.494934,0.015618,0.000000
24.310001,25.987877,-413.450439,-0.002488,0.000612,0.015541,115.599854,5.888937,0.155408,-413.450439,0.016373,0.000000
24.760000,27.035362,-413.539398,-0.002479,0.000639,0.016234,120.259300,6.126301,0.162342,-413.539398,0.017118,0.000000
25.210001,27.786804,-413.494934,-0.002466,0.000665,0.016893,123.601875,6.296580,0.168927,-413.494934,0.017874,0.000000
25.660002,29.586487,-413.539398,-0.002436,0.000700,0.017769,131.607269,6.704394,0.177693,-413.539398,0.018619,0.000000
26.110001,30.538643,-413.583893,-0.002419,0.000728,0.018488,135.842667,6.920156,0.184885,-413.583893,0.019374,0.000000
26.560001,31.706398,-413.583893,-0.002397,0.000758,0.019261,141.037109,7.184772,0.192606,-413.583893,0.020119,0.000000
27.010002,32.133881,-413.583893,-0.002380,0.000780,0.019807,142.938644,7.281641,0.198071,-413.583893,0.020865,0.000000
27.460001,34.105225,-413.717316,-0.002363,0.000821,0.020847,151.707611,7.728354,0.208472,-413.717316,0.021619,0.000000
27.910002,34.217308,-413.628357,-0.002358,0.000842,0.021386,152.206192,7.753753,0.213862,-413.628357,0.022366,0.000000
28.360001,35.590988,-413.717316,-0.002337,0.000878,0.022313,158.316620,8.065033,0.223127,-413.717316,0.023120,0.000000
28.810001,36.099648,-413.717316,-0.002307,0.000903,0.022938,160.579254,8.180297,0.229380,-413.717316,0.023866,0.000000
29.260002,36.933762,-413.761810,-0.002276,0.000933,0.023710,164.289581,8.369310,0.237101,-413.761810,0.024620,0.000000
29.710001,37.678513,-413.761810,-0.002294,0.000964,0.024490,167.602402,8.538073,0.244898,-413.761810,0.025366,0.000000
30.160002,38.122375,-413.761810,-0.002259,0.000993,0.025210,169.576797,8.638654,0.252104,-413.761810,0.026120,0.000000
30.610001,38.767700,-413.850769,-0.002238,0.001019,0.025878,172.447342,8.784886,0.258781,-413.850769,0.026867,0.000000
31.060001,39.895241,-413.850769,-0.002225,0.001055,0.026788,177.462891,9.040391,0.267880,-413.850769,0.027621,0.000000
31.510002,40.458267,-413.806274,-0.002216,0.001082,0.027474,179.967361,9.167974,0.274738,-413.806274,0.028367,0.000000
31.960001,40.915543,-413.895264,-0.002203,0.001111,0.028219,182.001419,9.271595,0.282187,-413.895264,0.029121,0.000000
32.410000,41.656937,-413.895264,-0.002186,0.001141,0.028991,185.299301,9.439597,0.289908,-413.895264,0.029867,0.000000
32.860001,41.585442,-414.028687,-0.002164,0.001161,0.029493,184.981277,9.423396,0.294934,-414.028687,0.030621,0.000000
33.310001,43.149780,-413.939728,-0.002151,0.001204,0.030570,191.939804,9.777880,0.305698,-413.939728,0.031368,0.000000
33.760002,43.478958,-413.984222,-0.002126,0.001230,0.031245,193.404068,9.852472,0.312451,-413.984222,0.032122,0.000000
34.210003,44.173805,-413.984222,-0.002113,0.001258,0.031948,196.494904,10.009928,0.319475,-413.984222,0.032868,0.000000
34.660000,44.435951,-413.984222,-0.002104,0.001284,0.032617,197.660980,10.069330,0.326167,-413.984222,0.033622,0.000000
35.110001,46.037895,-414.028687,-0.002091,0.001324,0.033631,204.786789,10.432336,0.336311,-414.028687,0.034368,0.000000
35.560001,46.325371,-414.073181,-0.002070,0.001345,0.034169,206.065536,10.497479,0.341685,-414.073181,0.035122,0.000000
36.010002,46.899940,-414.073181,-0.002065,0.001373,0.034871,208.621353,10.627678,0.348710,-414.073181,0.035869,0.000000
36.460003,47.686768,-414.028687,-0.002035,0.001403,0.035643,212.121338,10.805976,0.356431,-414.028687,0.036623,0.000000
36.910000,47.325188,-414.117645,-0.002026,0.001420,0.036076,210.512955,10.724041,0.360761,-414.117645,0.037369,0.000000
37.360001,49.941109,-414.162140,-0.002005,0.001469,0.037316,222.149139,11.316816,0.373160,-414.162140,0.038123,0.000000
37.810001,49.798859,-414.206604,-0.001983,0.001489,0.037811,221.516388,11.284583,0.378111,-414.206604,0.038869,0.000000
38.260002,50.933853,-414.206604,-0.001975,0.001521,0.038644,226.565094,11.541776,0.386438,-414.206604,0.039623,0.000000
38.710003,50.951355,-414.162140,-0.001957,0.001545,0.039251,226.642944,11.545742,0.392509,-414.162140,0.040370,0.000000
39.160004,52.490372,-414.206604,-0.001940,0.001581,0.040161,233.488831,11.894487,0.401608,-414.206604,0.041124,0.000000
39.610001,53.318527,-414.251099,-0.001936,0.001609,0.040872,237.172653,12.082151,0.408723,-414.251099,0.041870,0.000000
40.060001,54.335472,-414.295593,-0.001927,0.001642,0.041696,241.696259,12.312594,0.416959,-414.295593,0.042624,0.000000
40.510002,54.935364,-414.340057,-0.001914,0.001668,0.042364,244.364700,12.448532,0.423636,-414.340057,0.043370,0.000000
40.960003,56.370865,-414.295593,-0.001893,0.001701,0.043196,250.750137,12.773820,0.431962,-414.295593,0.044124,0.000000
41.410004,56.889946,-414.384552,-0.001871,0.001728,0.043890,253.059113,12.891445,0.438896,-414.384552,0.044869,0.000000
41.860001,58.378319,-414.340057,-0.001863,0.001762,0.044766,259.679718,13.228716,0.447662,-414.340057,0.045625,0.000000
42.310001,59.451500,-414.429016,-0.001837,0.001791,0.045485,264.453491,13.471903,0.454854,-414.429016,0.046370,0.000000
42.760002,60.558563,-414.429016,-0.001832,0.001818,0.046188,269.377930,13.722767,0.461878,-414.429016,0.047125,0.000000
43.210003,61.283203,-414.473511,-0.001828,0.001844,0.046848,272.601288,13.886972,0.468479,-414.473511,0.047870,0.000000
43.660004,61.977676,-414.473511,-0.001819,0.001871,0.047516,275.690460,14.044342,0.475156,-414.473511,0.048625,0.000000
44.110001,64.112106,-414.473511,-0.001802,0.001908,0.048451,285.184906,14.528011,0.484512,-414.473511,0.049370,0.000000
44.560001,64.187698,-414.562469,-0.001776,0.001926,0.048921,285.521149,14.545140,0.489205,-414.562469,0.050126,0.000000
45.010002,66.845322,-414.517975,-0.001776,0.001970,0.050047,297.342834,15.147367,0.500469,-414.517975,0.050871,0.000000
45.460003,67.396805,-414.562469,-0.001750,0.001995,0.050672,299.795959,15.272335,0.506722,-414.562469,0.051626,0.000000
45.910004,69.056854,-414.562469,-0.001750,0.002028,0.051505,307.180237,15.648506,0.515049,-414.562469,0.052371,0.000000
46.360001,69.814255,-414.606934,-0.001729,0.002050,0.052068,310.549316,15.820136,0.520680,-414.606934,0.053117,0.000000
46.810001,71.087769,-414.651428,-0.001729,0.002086,0.052996,316.214172,16.108719,0.529961,-414.651428,0.053871,0.000000
47.260002,72.314362,-414.695892,-0.001720,0.002110,0.053585,321.670349,16.386669,0.535850,-414.695892,0.054618,0.000000
47.710003,73.791183,-414.651428,-0.001703,0.002141,0.054383,328.239563,16.721321,0.543829,-414.651428,0.055371,0.000000
48.160004,75.504105,-414.651428,-0.001686,0.002173,0.055199,335.859039,17.109474,0.551989,-414.651428,0.056118,0.000000
48.610001,75.148865,-414.740387,-0.001677,0.002186,0.055520,334.278839,17.028976,0.555199,-414.740387,0.056872,0.000000
49.060001,78.541168,-414.740387,-0.001673,0.002232,0.056681,349.368561,17.797684,0.566811,-414.740387,0.057618,0.000000
49.510002,79.678772,-414.829346,-0.001651,0.002259,0.057376,354.428894,18.055468,0.573760,-414.829346,0.058372,0.000000
49.960003,81.470261,-414.740387,-0.001664,0.002291,0.058181,362.397827,18.461424,0.581814,-414.740387,0.059119,0.000000
50.410004,81.654587,-414.829346,-0.001647,0.002307,0.058598,363.217743,18.503193,0.585977,-414.829346,0.059872,0.000000
50.860001,84.787354,-414.829346,-0.001634,0.002352,0.059751,377.152985,19.213089,0.597514,-414.829346,0.060619,0.000000
51.310001,85.946915,-414.829346,-0.001621,0.002379,0.060428,382.310974,19.475849,0.604281,-414.829346,0.061373,0.000000
51.760002,87.816605,-414.918304,-0.001625,0.002411,0.061243,390.627777,19.899529,0.612426,-414.918304,0.062119,0.000000
52.210003,88.590012,-414.829346,-0.001595,0.002431,0.061738,394.068054,20.074783,0.617377,-414.829346,0.062873,0.000000
52.660004,91.103897,-414.918304,-0.001595,0.002470,0.062743,405.250366,20.644440,0.627430,-414.918304,0.063620,0.000000
53.110004,92.314865,-414.962799,-0.001565,0.002496,0.063403,410.637024,20.918848,0.634030,-414.962799,0.064373,0.000000
53.560001,94.428070,-415.007263,-0.001578,0.002529,0.064243,420.037048,21.397707,0.642433,-415.007263,0.065120,0.000000
54.010002,95.026474,-415.007263,-0.001565,0.002547,0.064685,422.698853,21.533306,0.646854,-415.007263,0.065874,0.000000
54.460003,97.678146,-415.007263,-0.001556,0.002587,0.065701,434.494110,22.134184,0.657012,-415.007263,0.066620,0.000000
54.910004,99.438339,-415.051758,-0.001544,0.002614,0.066404,442.323822,22.533051,0.664037,-415.051758,0.067374,0.000000
55.360004,100.412476,-415.051758,-0.001535,0.002637,0.066984,446.657013,22.753792,0.669836,-415.051758,0.068121,0.000000
55.810001,102.797516,-415.051758,-0.001522,0.002670,0.067825,457.266174,23.294250,0.678253,-415.051758,0.068874,0.000000
56.260002,103.686371,-415.140717,-0.001526,0.002689,0.068293,461.220001,23.495667,0.682931,-415.140717,0.069621,0.000000
56.710003,107.324081,-415.096222,-0.001513,0.002734,0.069456,477.401367,24.319984,0.694559,-415.096222,0.070375,0.000000
57.160004,108.505615,-415.140717,-0.001518,0.002758,0.070054,482.657074,24.587723,0.700539,-415.140717,0.071121,0.000000
57.610004,110.709320,-415.140717,-0.001513,0.002789,0.070852,492.459656,25.087091,0.708517,-415.140717,0.071875,0.000000
58.060001,112.194336,-415.229675,-0.001475,0.002812,0.071433,499.065338,25.423601,0.714331,-415.229675,0.072622,0.000000
58.510002,114.810257,-415.229675,-0.001500,0.002849,0.072370,510.701538,26.016376,0.723702,-415.229675,0.073375,0.000000
58.960003,116.389114,-415.229675,-0.001487,0.002875,0.073020,517.724609,26.374151,0.730197,-415.229675,0.074122,0.000000
59.410004,118.844910,-415.274170,-0.001483,0.002907,0.073836,528.648560,26.930641,0.738357,-415.274170,0.074876,0.000000
59.860004,120.602127,-415.318634,-0.001457,0.002936,0.074564,536.465027,27.328833,0.745639,-415.318634,0.075622,0.000000
60.310001,122.938400,-415.318634,-0.001470,0.002966,0.075327,546.857300,27.858238,0.753270,-415.318634,0.076376,0.000000
60.760002,124.911606,-415.363129,-0.001449,0.002994,0.076055,555.634583,28.305376,0.760552,-415.363129,0.077123,0.000000
61.210003,127.040085,-415.318634,-0.001457,0.003025,0.076836,565.102539,28.787695,0.768364,-415.318634,0.077876,0.000000
61.660004,129.116425,-415.407593,-0.001436,0.003052,0.077512,574.338562,29.258200,0.775116,-415.407593,0.078623,0.000000
62.110004,130.532196,-415.452087,-0.001414,0.003073,0.078058,580.636230,29.579018,0.780582,-415.452087,0.079377,0.000000
62.560001,134.066742,-415.541046,-0.001427,0.003114,0.079107,596.358643,30.379957,0.791073,-415.541046,0.080123,0.000000
63.010002,135.739441,-415.496552,-0.001410,0.003141,0.079775,603.799194,30.758995,0.797750,-415.496552,0.080877,0.000000
63.460003,138.647308,-415.452087,-0.001414,0.003176,0.080661,616.734009,31.417931,0.806607,-415.452087,0.081624,0.000000
63.910004,140.018372,-415.496552,-0.001406,0.003194,0.081119,622.832825,31.728617,0.811194,-415.496552,0.082377,0.000000
64.360001,143.025284,-415.496552,-0.001388,0.003231,0.082073,636.208252,32.409992,0.820732,-415.496552,0.083124,0.000000
64.810005,145.148178,-415.541046,-0.001393,0.003261,0.082838,645.651367,32.891045,0.828377,-415.541046,0.083878,0.000000
65.260002,147.811386,-415.585541,-0.001375,0.003293,0.083636,657.497864,33.494537,0.836356,-415.585541,0.084624,0.000000
65.710007,150.039291,-415.541046,-0.001362,0.003319,0.084311,667.408081,33.999390,0.843108,-415.541046,0.085378,0.000000
66.160004,152.326035,-415.674500,-0.001367,0.003347,0.085022,677.580017,34.517574,0.850224,-415.674500,0.086125,0.000000
66.610001,154.741241,-415.630005,-0.001350,0.003377,0.085769,688.323425,35.064865,0.857687,-415.630005,0.086869,0.000000
67.060005,157.471100,-415.585541,-0.001350,0.003409,0.086583,700.466431,35.683460,0.865833,-415.585541,0.087625,0.000000
67.510002,159.605545,-415.763458,-0.001345,0.003436,0.087286,709.960937,36.167133,0.872857,-415.763458,0.088370,0.000000
67.960007,160.521957,-415.718964,-0.001341,0.003450,0.087642,714.037354,36.374794,0.876415,-415.718964,0.089124,0.000000
68.410004,164.686935,-415.674500,-0.001328,0.003497,0.088821,732.564087,37.318592,0.888209,-415.674500,0.089870,0.000000
68.860001,167.007935,-415.718964,-0.001328,0.003526,0.089549,742.888367,37.844540,0.895491,-415.718964,0.090624,0.000000
69.310005,169.687149,-415.763458,-0.001315,0.003557,0.090338,754.806152,38.451656,0.903379,-415.763458,0.091370,0.000000
69.760002,171.366180,-415.807922,-0.001302,0.003576,0.090833,762.274841,38.832134,0.908329,-415.807922,0.092124,0.000000
70.210007,175.093628,-415.896881,-0.001298,0.003619,0.091917,778.855347,39.676785,0.919169,-415.896881,0.092871,0.000000
70.660004,176.728348,-415.852417,-0.001319,0.003639,0.092429,786.126953,40.047218,0.924286,-415.852417,0.093625,0.000000
71.110001,180.125122,-415.896881,-0.001298,0.003677,0.093399,801.236572,40.816936,0.933991,-415.896881,0.094371,0.000000
71.560005,182.350418,-415.852417,-0.001293,0.003702,0.094033,811.135193,41.321198,0.940334,-415.852417,0.095125,0.000000
72.010002,184.895218,-415.941376,-0.001281,0.003732,0.094787,822.455017,41.897854,0.947874,-415.941376,0.095871,0.000000
72.460007,187.508148,-415.941376,-0.001289,0.003761,0.095525,834.077881,42.489952,0.955247,-415.941376,0.096625,0.000000
72.910004,189.497375,-415.941376,-0.001272,0.003785,0.096141,842.926453,42.940720,0.961409,-415.941376,0.097372,0.000000
73.360001,192.540405,-416.030334,-0.001259,0.003816,0.096921,856.462524,43.630280,0.969206,-416.030334,0.098126,0.000000
73.810005,195.467987,-415.985840,-0.001259,0.003853,0.097858,869.485046,44.293678,0.978577,-415.985840,0.098872,0.000000
74.260002,198.339722,-416.030334,-0.001259,0.003879,0.098516,882.259155,44.944424,0.985163,-416.030334,0.099626,0.000000
74.710007,200.875946,-416.074829,-0.001250,0.003908,0.099263,893.540833,45.519138,0.992627,-416.074829,0.100372,0.000000
75.160004,203.790527,-416.030334,-0.001250,0.003939,0.100042,906.505554,46.179592,1.000423,-416.030334,0.101126,0.000000
75.610001,205.756256,-416.119293,-0.001246,0.003961,0.100607,915.249512,46.625034,1.006070,-416.119293,0.101873,0.000000
76.060005,209.422272,-416.119293,-0.001233,0.004001,0.101630,931.556763,47.455765,1.016305,-416.119293,0.102627,0.000000
76.510002,211.673279,-416.119293,-0.001237,0.004027,0.102289,941.569763,47.965851,1.022891,-416.119293,0.103373,0.000000
76.960007,214.743103,-416.163788,-0.001224,0.004059,0.103087,955.225037,48.661484,1.030869,-416.163788,0.104127,0.000000
77.410004,216.975464,-416.163788,-0.001229,0.004083,0.103703,965.155090,49.167343,1.037031,-416.163788,0.104873,0.000000
77.860001,217.734741,-416.252747,-0.001212,0.004093,0.103962,968.532471,49.339397,1.039620,-416.252747,0.105627,0.000000
78.310005,220.847046,-416.208252,-0.001203,0.004113,0.104483,982.376709,50.044655,1.044828,-416.208252,982.394897,0.000000
78.760002,220.297424,-416.341705,-0.001203,0.004111,0.104422,979.931885,49.920109,1.044222,-416.341705,982.000671,0.000000
79.210007,219.741089,-416.252747,-0.001199,0.004113,0.104474,977.457153,49.794041,1.044737,-416.252747,982.000671,0.000000
79.660004,219.932129,-416.297211,-0.001207,0.004125,0.104778,978.306946,49.837334,1.047780,-416.297211,982.000671,0.000000
80.110001,219.558624,-416.341705,-0.001181,0.004126,0.104813,976.645508,49.752697,1.048128,-416.341705,982.000671,0.000000
80.560005,220.310455,-416.386169,-0.001203,0.004135,0.105029,979.989868,49.923061,1.050293,-416.386169,982.000671,0.000000
81.010002,219.830444,-416.386169,-0.001194,0.004135,0.105029,977.854675,49.814289,1.050293,-416.386169,982.000671,0.000000
81.460007,219.793976,-416.386169,-0.001199,0.004140,0.105169,977.692444,49.806026,1.051686,-416.386169,982.000671,0.000000
81.910004,219.515808,-416.430664,-0.001190,0.004141,0.105185,976.455078,49.742996,1.051853,-416.430664,982.000671,0.000000
82.360001,219.582458,-416.519623,-0.001190,0.004145,0.105290,976.751587,49.758099,1.052897,-416.519623,982.000671,0.000000
82.810005,219.551544,-416.519623,-0.001199,0.004148,0.105367,976.614075,49.751091,1.053669,-416.519623,982.000671,0.000000
83.260002,219.607788,-416.519623,-0.001177,0.004152,0.105455,976.864258,49.763836,1.054547,-416.519623,982.000671,0.000000
83.710007,219.558258,-416.519623,-0.001194,0.004154,0.105515,976.643921,49.752613,1.055153,-416.519623,982.000671,0.000000
84.160004,219.542603,-416.564117,-0.001181,0.004158,0.105602,976.574280,49.749062,1.056016,-416.564117,982.000671,0.000000
84.610001,219.704590,-416.564117,-0.001181,0.004161,0.105697,977.294800,49.785770,1.056970,-416.564117,982.000671,0.000000
85.060005,219.548584,-416.653076,-0.001168,0.004162,0.105706,976.600891,49.750420,1.057061,-416.653076,982.000671,0.000000
85.510002,219.738495,-416.564117,-0.001177,0.004169,0.105897,977.445618,49.793453,1.058968,-416.564117,982.000671,0.000000
85.960007,219.814087,-416.653076,-0.001177,0.004169,0.105897,977.781921,49.810581,1.058968,-416.653076,982.000671,0.000000
86.410004,219.611877,-416.697540,-0.001164,0.004169,0.105897,976.882446,49.764763,1.058968,-416.697540,982.000671,0.000000
86.860001,219.495331,-416.653076,-0.001168,0.004171,0.105932,976.364014,49.738350,1.059316,-416.653076,982.000671,0.000000
87.310005,219.467407,-416.697540,-0.001164,0.004173,0.105983,976.239807,49.732025,1.059831,-416.697540,982.000671,0.000000
87.760002,219.861725,-416.830994,-0.001164,0.004178,0.106130,977.993774,49.821381,1.061300,-416.830994,982.000671,0.000000
88.210007,219.717621,-416.786499,-0.001173,0.004178,0.106130,977.352783,49.788723,1.061300,-416.786499,982.000671,0.000000
88.660004,219.554169,-416.786499,-0.001155,0.004179,0.106148,976.625732,49.751686,1.061481,-416.786499,982.000671,0.000000
89.110001,219.703094,-416.830994,-0.001155,0.004183,0.106244,977.288147,49.785435,1.062435,-416.830994,982.000671,0.000000
89.560005,219.594360,-416.830994,-0.001181,0.004183,0.106260,976.804504,49.760792,1.062602,-416.830994,982.000671,0.000000
90.010002,219.644653,-416.875488,-0.001164,0.004186,0.106322,977.028198,49.772190,1.063222,-416.875488,982.000671,0.000000
90.460007,219.647247,-416.919952,-0.001155,0.004187,0.106356,977.039734,49.772778,1.063555,-416.919952,982.000671,0.000000
90.910004,219.613007,-416.919952,-0.001160,0.004189,0.106399,976.887451,49.765018,1.063995,-416.919952,982.000671,0.000000
91.360001,219.604065,-416.919952,-0.001168,0.004190,0.106425,976.847656,49.762993,1.064252,-416.919952,982.000671,0.000000
91.810005,219.571289,-417.008911,-0.001147,0.004192,0.106469,976.701904,49.755566,1.064691,-417.008911,982.000671,0.000000
92.260002,219.557129,-417.008911,-0.001164,0.004193,0.106504,976.638916,49.752357,1.065039,-417.008911,982.000671,0.000000
92.710007,219.535919,-417.008911,-0.001155,0.004194,0.106530,976.544556,49.747551,1.065297,-417.008911,982.000671,0.000000
93.160004,219.608154,-417.008911,-0.001160,0.004197,0.106599,976.865845,49.763920,1.065993,-417.008911,982.000671,0.000000
93.610008,219.537415,-417.053406,-0.001151,0.004197,0.106608,976.551208,49.747887,1.066084,-417.053406,982.000671,0.000000
94.060005,219.473724,-417.097870,-0.001151,0.004198,0.106625,976.267883,49.733459,1.066250,-417.097870,982.000671,0.000000
94.510002,219.504272,-417.142365,-0.001155,0.004200,0.106669,976.403748,49.740376,1.066689,-417.142365,982.000671,0.000000
94.960007,219.520630,-417.186829,-0.001151,0.004202,0.106720,976.476501,49.744087,1.067204,-417.186829,982.000671,0.000000
95.410004,219.532196,-417.142365,-0.001147,0.004203,0.106755,976.527954,49.746708,1.067552,-417.142365,982.000671,0.000000
95.860008,219.601807,-417.186829,-0.001143,0.004205,0.106799,976.837646,49.762482,1.067991,-417.186829,982.000671,0.000000
96.310005,219.558624,-417.275787,-0.001160,0.004205,0.106799,976.645508,49.752697,1.067991,-417.275787,982.000671,0.000000
96.760002,219.538147,-417.231323,-0.001151,0.004206,0.106832,976.554443,49.748055,1.068324,-417.231323,982.000671,0.000000
97.210007,219.533691,-417.231323,-0.001160,0.004208,0.106885,976.534607,49.747044,1.068854,-417.231323,982.000671,0.000000
97.660004,219.691193,-417.275787,-0.001138,0.004210,0.106928,977.235229,49.782734,1.069278,-417.275787,982.000671,0.000000
98.110008,219.618591,-417.320282,-0.001143,0.004210,0.106928,976.912292,49.766281,1.069278,-417.320282,982.000671,0.000000
98.560005,219.533691,-417.275787,-0.001151,0.004210,0.106937,976.534607,49.747044,1.069369,-417.275787,982.000671,0.000000
99.010002,219.489349,-417.275787,-0.001155,0.004210,0.106946,976.337402,49.736996,1.069460,-417.275787,982.000671,0.000000
99.460007,219.391815,-417.409241,-0.001164,0.004210,0.106946,975.903564,49.714893,1.069460,-417.409241,982.000671,0.000000
99.910004,219.305054,-417.364777,-0.001151,0.004211,0.106972,975.517578,49.695236,1.069717,-417.364777,982.000671,0.000000
100.360008,219.297211,-417.453735,-0.001138,0.004213,0.107007,975.482727,49.693459,1.070065,-417.453735,982.000671,0.000000
100.810005,219.244720,-417.453735,-0.001151,0.004213,0.107007,975.249207,49.681564,1.070065,-417.453735,982.000671,0.000000
101.260002,219.237640,-417.453735,-0.001138,0.004215,0.107050,975.217712,49.679958,1.070505,-417.453735,982.000671,0.000000
101.710007,219.327393,-417.453735,-0.001138,0.004217,0.107102,975.616943,49.700298,1.071019,-417.453735,982.000671,0.000000
102.160004,219.318817,-417.498199,-0.001155,0.004217,0.107102,975.578796,49.698353,1.071019,-417.498199,982.000671,0.000000
102.610008,219.255890,-417.542694,-0.001143,0.004217,0.107102,975.298889,49.684097,1.071019,-417.542694,982.000671,0.000000
103.060005,219.171722,-417.587158,-0.001151,0.004217,0.107102,974.924500,49.665024,1.071019,-417.587158,982.000671,0.000000
103.510002,219.091309,-417.498199,-0.001151,0.004218,0.107128,974.566833,49.646801,1.071277,-417.498199,982.000671,0.000000
103.960007,219.076782,-417.542694,-0.001143,0.004218,0.107137,974.502197,49.643509,1.071368,-417.542694,982.000671,0.000000
104.410004,219.016449,-417.587158,-0.001147,0.004218,0.107146,974.233826,49.629837,1.071458,-417.587158,982.000671,0.000000
104.860008,220.695099,-417.631653,-0.001130,0.004218,0.107128,981.700806,50.010223,1.071277,-417.631653,982.000671,0.000000
105.310005,220.576324,-417.676117,-0.001125,0.004217,0.107111,981.172485,49.983307,1.071110,-417.676117,982.000671,0.000000
105.760002,220.460876,-417.676117,-0.001134,0.004217,0.107111,980.658936,49.957150,1.071110,-417.676117,982.000671,0.000000
106.210007,220.415466,-417.720612,-0.001130,0.004217,0.107111,980.456970,49.946861,1.071110,-417.720612,982.000671,0.000000
106.660004,220.318634,-417.720612,-0.001134,0.004217,0.107111,980.026245,49.924915,1.071110,-417.720612,982.000671,0.000000
107.110008,220.215485,-417.765106,-0.001130,0.004217,0.107111,979.567383,49.901543,1.071110,-417.765106,982.000671,0.000000
107.560005,220.124268,-417.854065,-0.001125,0.004217,0.107111,979.161621,49.880871,1.071110,-417.854065,982.000671,0.000000
108.010002,220.051270,-417.809570,-0.001138,0.004217,0.107111,978.836914,49.864330,1.071110,-417.809570,982.000671,0.000000
108.460007,219.939178,-417.854065,-0.001130,0.004217,0.107120,978.338318,49.838928,1.071201,-417.854065,982.000671,0.000000
108.910004,219.852814,-417.854065,-0.001121,0.004218,0.107128,977.954163,49.819359,1.071277,-417.854065,982.000671,0.000000
109.360008,219.776459,-417.854065,-0.001121,0.004218,0.107128,977.614502,49.802055,1.071277,-417.854065,982.000671,0.000000
109.810005,219.678894,-417.854065,-0.001143,0.004218,0.107128,977.180542,49.779949,1.071277,-417.854065,982.000671,0.000000
110.260002,219.593994,-417.898529,-0.001125,0.004218,0.107128,976.802856,49.760712,1.071277,-417.898529,982.000671,0.000000
110.710007,219.522125,-417.943024,-0.001138,0.004218,0.107137,976.483154,49.744423,1.071368,-417.943024,982.000671,0.000000
111.160004,219.440948,-417.943024,-0.001112,0.004218,0.107146,976.122070,49.726028,1.071458,-417.943024,982.000671,0.000000
111.610008,219.350464,-417.943024,-0.001125,0.004219,0.107153,975.719604,49.705528,1.071534,-417.943024,982.000671,0.000000
112.060005,220.152924,-417.987488,-0.001117,0.004238,0.107658,979.289124,49.887367,1.076576,-417.987488,982.000671,0.000000
112.510002,220.131714,-418.031982,-0.001121,0.004238,0.107658,979.194763,49.882561,1.076576,-418.031982,982.000671,0.000000
112.960007,220.075470,-418.031982,-0.001117,0.004238,0.107658,978.944580,49.869816,1.076576,-418.031982,982.000671,0.000000
113.410004,220.031525,-418.120941,-0.001117,0.004238,0.107658,978.749084,49.859856,1.076576,-418.120941,982.000671,0.000000
113.860008,219.956329,-418.120941,-0.001125,0.004238,0.107658,978.414612,49.842815,1.076576,-418.120941,982.000671,0.000000
114.310005,219.894135,-418.165436,-0.001117,0.004238,0.107658,978.137939,49.828724,1.076576,-418.165436,982.000671,0.000000
114.760002,219.840881,-418.165436,-0.001130,0.004238,0.107658,977.901062,49.816654,1.076576,-418.165436,982.000671,0.000000
115.210007,219.782806,-418.209900,-0.001130,0.004239,0.107665,977.642761,49.803493,1.076651,-418.209900,982.000671,0.000000
115.660004,219.711670,-418.209900,-0.001125,0.004239,0.107665,977.326294,49.787376,1.076651,-418.209900,982.000671,0.000000
116.110008,219.612610,-418.209900,-0.001117,0.004239,0.107683,976.885681,49.764927,1.076833,-418.209900,982.000671,0.000000
116.560005,219.592133,-418.254395,-0.001104,0.004240,0.107692,976.794617,49.760288,1.076924,-418.254395,982.000671,0.000000
117.010002,219.557892,-418.254395,-0.001134,0.004240,0.107692,976.642273,49.752529,1.076924,-418.254395,982.000671,0.000000
117.460007,219.510956,-418.343353,-0.001130,0.004240,0.107700,976.433472,49.741894,1.076999,-418.343353,982.000671,0.000000
117.910004,219.675537,-418.343353,-0.001117,0.004246,0.107856,977.165588,49.779190,1.078559,-418.343353,982.000671,0.000000
118.360008,219.875519,-418.343353,-0.001112,0.004246,0.107856,978.055176,49.824505,1.078559,-418.343353,982.000671,0.000000
118.810005,219.877380,-418.343353,-0.001121,0.004246,0.107856,978.063416,49.824924,1.078559,-418.343353,982.000671,0.000000
119.260002,219.858002,-418.432312,-0.001112,0.004246,0.107856,977.977234,49.820534,1.078559,-418.432312,982.000671,0.000000
119.710007,219.821533,-418.387817,-0.001134,0.004246,0.107856,977.815002,49.812271,1.078559,-418.387817,982.000671,0.000000
120.160004,219.788757,-418.476776,-0.001117,0.004246,0.107856,977.669250,49.804844,1.078559,-418.476776,982.000671,0.000000
120.610008,219.753387,-418.476776,-0.001117,0.004246,0.107856,977.511902,49.796829,1.078559,-418.476776,982.000671,0.000000
121.060005,219.707214,-418.521271,-0.001121,0.004246,0.107856,977.306519,49.786366,1.078559,-418.521271,982.000671,0.000000
121.510002,219.662140,-418.565735,-0.001130,0.004246,0.107856,977.106018,49.776154,1.078559,-418.565735,982.000671,0.000000
121.960007,219.629364,-418.521271,-0.001112,0.004247,0.107865,976.960205,49.768723,1.078650,-418.521271,982.000671,0.000000
122.410004,219.615967,-418.476776,-0.001121,0.004248,0.107891,976.900635,49.765690,1.078907,-418.476776,982.000671,0.000000
122.860008,219.613007,-418.565735,-0.001125,0.004248,0.107900,976.887451,49.765018,1.078998,-418.565735,982.000671,0.000000
123.310005,219.591400,-418.654724,-0.001112,0.004248,0.107900,976.791321,49.760124,1.078998,-418.654724,982.000671,0.000000
123.760002,219.610016,-418.654724,-0.001117,0.004249,0.107935,976.874146,49.764339,1.079346,-418.654724,982.000671,0.000000
124.210007,219.609253,-418.699188,-0.001112,0.004249,0.107935,976.870728,49.764168,1.079346,-418.699188,982.000671,0.000000
124.660004,219.592499,-418.699188,-0.001112,0.004249,0.107935,976.796204,49.760372,1.079346,-418.699188,982.000671,0.000000
125.110008,219.569794,-418.788147,-0.001121,0.004250,0.107960,976.695251,49.755226,1.079603,-418.788147,982.000671,0.000000
125.560005,219.614471,-418.699188,-0.001121,0.004251,0.107979,976.893982,49.765350,1.079785,-418.699188,982.000671,0.000000
126.010010,219.605927,-418.788147,-0.001125,0.004251,0.107979,976.855957,49.763416,1.079785,-418.788147,982.000671,0.000000
126.460007,219.587677,-418.743683,-0.001134,0.004251,0.107979,976.774780,49.759277,1.079785,-418.743683,982.000671,0.000000
126.910004,219.558258,-418.832642,-0.001130,0.004252,0.108004,976.643921,49.752613,1.080042,-418.832642,982.000671,0.000000
127.360008,219.649841,-418.877106,-0.001112,0.004253,0.108030,977.051270,49.773365,1.080300,-418.877106,982.000671,0.000000
127.810005,219.653198,-418.877106,-0.001117,0.004253,0.108030,977.066223,49.774128,1.080300,-418.877106,982.000671,0.000000
128.260010,219.625641,-418.877106,-0.001117,0.004253,0.108030,976.943665,49.767879,1.080300,-418.877106,982.000671,0.000000
128.710007,219.610748,-418.921600,-0.001121,0.004253,0.108030,976.877380,49.764507,1.080300,-418.921600,982.000671,0.000000
129.160004,219.573883,-418.966064,-0.001121,0.004253,0.108030,976.713440,49.756153,1.080300,-418.966064,982.000671,0.000000
129.610001,219.537781,-418.966064,-0.001108,0.004253,0.108030,976.552795,49.747974,1.080300,-418.966064,982.000671,0.000000
130.060013,219.557129,-418.966064,-0.001117,0.004257,0.108125,976.638916,49.752357,1.081254,-418.966064,982.000671,0.000000
130.510010,220.073608,-419.010559,-0.001125,0.004260,0.108212,978.936279,49.869392,1.082117,-419.010559,982.000671,0.000000
130.960007,220.093353,-419.055054,-0.001112,0.004260,0.108212,979.024109,49.873867,1.082117,-419.055054,982.000671,0.000000
131.410004,220.090363,-419.055054,-0.001108,0.004260,0.108212,979.010803,49.873188,1.082117,-419.055054,982.000671,0.000000
131.860001,220.089630,-419.055054,-0.001099,0.004260,0.108212,979.007568,49.873024,1.082117,-419.055054,982.000671,0.000000
132.310013,220.065430,-419.099518,-0.001121,0.004260,0.108212,978.899902,49.867538,1.082117,-419.099518,982.000671,0.000000
132.760010,220.028564,-419.099518,-0.001104,0.004260,0.108212,978.735962,49.859184,1.082117,-419.099518,982.000671,0.000000
133.210007,220.010315,-419.099518,-0.001117,0.004260,0.108212,978.654785,49.855053,1.082117,-419.099518,982.000671,0.000000
133.660004,219.974182,-419.099518,-0.001108,0.004260,0.108212,978.494019,49.846863,1.082117,-419.099518,982.000671,0.000000
134.110001,219.928772,-419.232971,-0.001099,0.004260,0.108212,978.292053,49.836571,1.082117,-419.232971,982.000671,0.000000
134.560013,219.896362,-419.188477,-0.001104,0.004260,0.108212,978.147888,49.829227,1.082117,-419.188477,982.000671,0.000000
135.010010,219.868073,-419.277435,-0.001125,0.004260,0.108212,978.022034,49.822819,1.082117,-419.277435,982.000671,0.000000
135.460007,219.839386,-419.277435,-0.001117,0.004260,0.108212,977.894409,49.816319,1.082117,-419.277435,982.000671,0.000000
135.910004,219.809601,-419.277435,-0.001108,0.004260,0.108212,977.761963,49.809566,1.082117,-419.277435,982.000671,0.000000
136.360001,219.781677,-419.277435,-0.001121,0.004261,0.108221,977.637756,49.803242,1.082207,-419.277435,982.000671,0.000000
136.810013,219.761566,-419.321930,-0.001108,0.004262,0.108256,977.548279,49.798683,1.082556,-419.321930,982.000671,0.000000
137.260010,219.783173,-419.321930,-0.001117,0.004262,0.108265,977.644409,49.803577,1.082646,-419.321930,982.000671,0.000000
137.710007,219.778687,-419.366394,-0.001125,0.004262,0.108265,977.624451,49.802563,1.082646,-419.366394,982.000671,0.000000
138.160004,219.766022,-419.321930,-0.001099,0.004262,0.108265,977.568115,49.799690,1.082646,-419.321930,982.000671,0.000000
138.610001,219.771637,-419.455383,-0.001104,0.004263,0.108281,977.593079,49.800964,1.082813,-419.455383,5607.367676,0.000000
139.060013,219.707214,-419.410889,-0.001099,0.004248,0.107891,977.306519,49.786366,1.078907,-419.410889,0.107770,0.000000
139.510010,219.613373,-419.455383,-0.001104,0.004227,0.107353,976.889099,49.765102,1.073532,-419.455383,0.107025,0.000000
139.960007,218.991119,-419.455383,-0.001099,0.004198,0.106625,974.121155,49.624096,1.066250,-419.455383,0.106269,0.000000
140.410004,217.839020,-419.455383,-0.001095,0.004174,0.106018,968.996338,49.363029,1.060179,-419.455383,0.105524,0.000000
140.860001,217.002289,-419.544342,-0.001087,0.004152,0.105471,965.274414,49.173420,1.054714,-419.544342,0.104769,0.000000
141.310013,216.624695,-419.544342,-0.001099,0.004119,0.104622,963.594788,49.087856,1.046221,-419.544342,0.104024,0.000000
141.760010,216.421753,-419.588806,-0.001091,0.004091,0.103901,962.692017,49.041870,1.039014,-419.588806,0.103269,0.000000
142.210007,215.936554,-419.588806,-0.001074,0.004057,0.103035,960.533752,48.931923,1.030354,-419.588806,0.102524,0.000000
142.660004,215.710907,-419.588806,-0.001048,0.004029,0.102341,959.530029,48.880791,1.023405,-419.588806,0.101768,0.000000
143.110001,214.720032,-419.633301,-0.001061,0.004000,0.101596,955.122375,48.656254,1.015957,-419.633301,0.101023,0.000000
143.560013,214.135773,-419.633301,-0.001061,0.003974,0.100945,952.523499,48.523857,1.009447,-419.633301,0.100268,0.000000
144.010010,212.266449,-419.677765,-0.001065,0.003940,0.100077,944.208313,48.100266,1.000772,-419.677765,0.099523,0.000000
144.460007,211.023834,-419.722260,-0.001056,0.003918,0.099505,938.680908,47.818684,0.995049,-419.722260,0.098768,0.000000
144.910004,208.468628,-419.722260,-0.001078,0.003884,0.098646,927.314758,47.239666,0.986465,-419.722260,0.098023,0.000000
145.360001,206.185974,-419.766724,-0.001061,0.003860,0.098048,917.161011,46.722412,0.980485,-419.766724,0.097267,0.000000
145.810013,203.116882,-419.766724,-0.001048,0.003826,0.097190,903.509033,46.026943,0.971900,-419.766724,0.096522,0.000000
146.260010,199.907410,-419.811218,-0.001048,0.003800,0.096522,889.232544,45.299667,0.965224,-419.811218,0.095767,0.000000
146.710007,197.164520,-419.811218,-0.001052,0.003775,0.095888,877.031616,44.678120,0.958880,-419.811218,0.095022,0.000000
147.160004,193.628845,-419.855682,-0.001065,0.003742,0.095039,861.304138,43.876926,0.950387,-419.855682,0.094267,0.000000
147.610001,189.923737,-419.855682,-0.001043,0.003710,0.094224,844.822998,43.037334,0.942242,-419.855682,0.093522,0.000000
148.060013,186.999863,-419.900177,-0.001061,0.003683,0.093557,831.816956,42.374771,0.935565,-419.900177,0.092766,0.000000
148.510010,184.643127,-419.855682,-0.001052,0.003663,0.093045,821.333679,41.840733,0.930448,-419.855682,0.092021,0.000000
148.960007,180.710495,-419.900177,-0.001056,0.003622,0.091996,803.840454,40.949585,0.919957,-419.900177,0.091266,0.000000
149.410004,177.866318,-419.900177,-0.001061,0.003598,0.091389,791.188904,40.305084,0.913886,-419.900177,0.090521,0.000000
149.860001,173.723297,-419.989136,-0.001065,0.003561,0.090442,772.759827,39.366261,0.904423,-419.989136,0.089775,0.000000
150.310013,171.290222,-420.033630,-0.001069,0.003541,0.089931,761.936951,38.814922,0.899306,-420.033630,0.089021,0.000000
150.760010,168.037537,-420.033630,-0.001048,0.003514,0.089254,747.468323,38.077850,0.892539,-420.033630,0.088274,0.000000
151.210007,164.157425,-420.033630,-0.001052,0.003480,0.088395,730.208679,37.198605,0.883955,-420.033630,0.087520,0.000000
151.660004,159.775711,-420.078094,-0.001048,0.003445,0.087495,710.717834,36.205692,0.874947,-420.078094,0.086774,0.000000
152.110001,156.647415,-420.122589,-0.001069,0.003418,0.086818,696.802490,35.496811,0.868179,-420.122589,0.086020,0.000000
152.560013,152.496582,-420.078094,-0.001052,0.003383,0.085934,678.338684,34.556221,0.859338,-420.078094,0.085274,0.000000
153.010010,150.186752,-420.078094,-0.001065,0.003367,0.085517,668.064026,34.032803,0.855174,-420.078094,0.084520,0.000000
153.460007,146.036285,-420.122589,-0.001061,0.003330,0.084589,649.601868,33.092297,0.845894,-420.122589,0.083773,0.000000
153.910004,141.942795,-420.078094,-0.001048,0.003296,0.083731,631.393066,32.164696,0.837310,-420.078094,0.083019,0.000000
154.360001,139.206238,-420.122589,-0.001061,0.003271,0.083089,619.220276,31.544584,0.830890,-420.122589,0.082273,0.000000
154.810013,135.603531,-420.211548,-0.001056,0.003242,0.082343,603.194641,30.728199,0.823427,-420.211548,0.081519,0.000000
155.260010,132.315857,-420.167053,-0.001048,0.003213,0.081605,588.570312,29.983202,0.816054,-420.167053,0.080773,0.000000
155.710007,128.462921,-420.256012,-0.001048,0.003179,0.080738,571.431641,29.110113,0.807379,-420.256012,0.080019,0.000000
156.160004,125.842163,-420.256012,-0.001052,0.003156,0.080166,559.773926,28.516243,0.801656,-420.256012,0.079272,0.000000
156.610001,122.628586,-420.300507,-0.001061,0.003126,0.079412,545.479187,27.788036,0.794116,-420.300507,0.078518,0.000000
157.060013,118.508652,-420.345001,-0.001048,0.003092,0.078535,527.152832,26.854445,0.785351,-420.345001,0.077772,0.000000
157.510010,115.331573,-420.345001,-0.001065,0.003059,0.077702,513.020447,26.134508,0.777024,-420.345001,0.077018,0.000000
157.960007,112.235291,-420.345001,-0.001039,0.003036,0.077123,499.247498,25.432880,0.771225,-420.345001,0.076272,0.000000
158.410004,109.071243,-420.345001,-0.001061,0.003010,0.076455,485.173126,24.715897,0.764549,-420.345001,0.075518,0.000000
158.860001,105.552322,-420.389465,-0.001052,0.002979,0.075657,469.520172,23.918499,0.756570,-420.389465,0.074771,0.000000
159.310013,102.443390,-420.433960,-0.001061,0.002952,0.074980,455.690948,23.214005,0.749803,-420.433960,0.074017,0.000000
159.760010,98.635132,-420.433960,-0.001052,0.002920,0.074164,438.750977,22.351040,0.741643,-420.433960,0.073271,0.000000
160.210007,95.274841,-420.433960,-0.001052,0.002889,0.073375,423.803650,21.589588,0.733755,-420.433960,0.072517,0.000000
160.660004,92.447800,-420.478424,-0.001052,0.002859,0.072629,411.228363,20.948971,0.726291,-420.478424,0.071771,0.000000
161.110001,88.493942,-420.522919,-0.001039,0.002830,0.071893,393.640717,20.053015,0.718933,-420.522919,0.071017,0.000000
161.560013,85.010773,-420.522919,-0.001056,0.002800,0.071121,378.146790,19.263718,0.711212,-420.522919,0.070270,0.000000
162.010010,82.428375,-420.522919,-0.001039,0.002775,0.070488,366.659729,18.678537,0.704884,-420.522919,0.069516,0.000000
162.460007,79.628494,-420.567383,-0.001030,0.002751,0.069872,354.205231,18.044073,0.698722,-420.567383,0.068770,0.000000
162.910004,75.393875,-420.611877,-0.001056,0.002713,0.068918,335.368713,17.084497,0.689184,-420.611877,0.068016,0.000000
163.360001,72.844986,-420.611877,-0.001048,0.002691,0.068346,324.030670,16.506908,0.683461,-420.611877,0.067270,0.000000
163.810013,69.129837,-420.656342,-0.001048,0.002658,0.067513,307.504883,15.665045,0.675134,-420.656342,0.066516,0.000000
164.260010,66.173187,-420.656342,-0.001056,0.002630,0.066793,294.353027,14.995058,0.667928,-420.656342,0.065769,0.000000
164.710007,62.455803,-420.700836,-0.001043,0.002597,0.065953,277.817291,14.152688,0.659526,-420.700836,0.065015,0.000000
165.160004,59.549805,-420.700836,-0.001061,0.002571,0.065302,264.890747,13.494179,0.653015,-420.700836,0.064269,0.000000
165.610001,56.186539,-420.745331,-0.001056,0.002539,0.064495,249.930206,12.732051,0.644946,-420.745331,0.063515,0.000000
166.060013,53.361717,-420.789795,-0.001048,0.002516,0.063897,237.364777,12.091938,0.638966,-420.789795,0.062769,0.000000
166.510010,49.310310,-420.789795,-0.001052,0.002478,0.062952,219.343216,11.173876,0.629519,-420.789795,0.062015,0.000000
166.960007,46.200256,-420.745331,-0.001048,0.002449,0.062206,205.509003,10.469128,0.622055,-420.745331,0.061270,0.000000
167.410004,42.301888,-420.834290,-0.001061,0.002415,0.061338,188.168198,9.585745,0.613380,-420.834290,0.060514,0.000000
167.860001,40.081802,-420.834290,-0.001052,0.002394,0.060810,178.292755,9.082666,0.608096,-420.834290,0.059770,0.000000
168.310013,36.835457,-420.834290,-0.001061,0.002363,0.060021,163.852295,8.347034,0.600209,-420.834290,0.059014,0.000000
168.760010,33.162750,-420.878754,-0.001061,0.002329,0.059144,147.515274,7.514787,0.591443,-420.878754,0.058269,0.000000
169.210007,29.352631,-420.923248,-0.001048,0.002295,0.058295,130.567017,6.651401,0.582950,-420.923248,0.057514,0.000000
169.660004,27.697067,-420.923248,-0.001048,0.002280,0.057904,123.202705,6.276245,0.579044,-420.923248,0.056769,0.000000
170.110001,23.665764,-420.923248,-0.001056,0.002239,0.056872,105.270576,5.362739,0.568718,-420.923248,0.056022,0.000000
170.560013,20.794769,-421.012207,-0.001056,0.002217,0.056309,92.499756,4.712162,0.563086,-421.012207,0.055269,0.000000
171.010010,18.212738,-421.012207,-0.001052,0.002192,0.055667,81.014305,4.127065,0.556667,-421.012207,0.054522,0.000000
171.460007,14.007912,-420.923248,-0.001043,0.002153,0.054678,62.310303,3.174238,0.546781,-420.923248,0.053768,0.000000
171.910004,12.316223,-421.012207,-0.001043,0.002136,0.054245,54.785297,2.790896,0.542451,-421.012207,0.053022,0.000000
172.360001,8.725433,-421.012207,-0.001052,0.002101,0.053369,38.812668,1.977211,0.533685,-421.012207,0.052268,0.000000
172.810013,5.658943,-421.056671,-0.001056,0.002069,0.052554,25.172235,1.282335,0.525540,-421.056671,0.051522,0.000000
173.260010,1.960167,-421.145630,-0.001043,0.002032,0.051617,8.719258,0.444180,0.516169,-421.145630,0.050768,0.000000
173.710007,0.523933,-421.101166,-0.001039,0.002016,0.051210,2.330572,0.118725,0.512096,-421.101166,0.050021,0.000000
174.160004,-0.917900,-421.101166,-0.001048,0.001975,0.050160,-4.083024,-0.207999,0.501605,-421.101166,0.049267,0.000000
174.610016,-0.141502,-421.190125,-0.001043,0.001949,0.049500,-0.629434,-0.032065,0.495004,-421.190125,0.048521,0.000000
175.060013,-0.141869,-421.145630,-0.001048,0.001917,0.048686,-0.631063,-0.032148,0.486859,-421.145630,0.047767,0.000000
175.510010,-0.034256,-421.190125,-0.001048,0.001888,0.047958,-0.152378,-0.007763,0.479576,-421.190125,0.047021,0.000000
175.960007,-0.023087,-421.190125,-0.001035,0.001880,0.047749,-0.102694,-0.005231,0.477487,-421.190125,0.046267,0.000000
176.410004,-0.123253,-421.234619,-0.001035,0.001831,0.046500,-0.548256,-0.027929,0.464997,-421.234619,0.045520,0.000000
176.860016,-0.092346,-421.234619,-0.001039,0.001805,0.045858,-0.410776,-0.020926,0.458578,-421.234619,0.044766,0.000000
177.310013,-0.084900,-421.279083,-0.001026,0.001772,0.044999,-0.377654,-0.019239,0.449994,-421.279083,0.044020,0.000000
177.760010,-0.084526,-421.279083,-0.001026,0.001754,0.044541,-0.375991,-0.019154,0.445406,-421.279083,0.043266,0.000000
178.210007,-0.105751,-421.323578,-0.001026,0.001715,0.043561,-0.470404,-0.023964,0.435611,-421.323578,0.042520,0.000000
178.660004,-0.117668,-421.323578,-0.001030,0.001684,0.042780,-0.523414,-0.026664,0.427799,-421.323578,0.041766,0.000000
179.110016,-0.072609,-421.323578,-0.001035,0.001650,0.041921,-0.322981,-0.016453,0.419215,-421.323578,0.041019,0.000000
179.560013,-0.100166,-421.412537,-0.001035,0.001628,0.041340,-0.445562,-0.022698,0.413401,-421.412537,0.040265,0.000000
180.010010,-0.084900,-421.412537,-0.001022,0.001613,0.040977,-0.377654,-0.019239,0.409768,-421.412537,0.039519,0.000000
180.460007,-0.084526,-421.457001,-0.001022,0.001565,0.039763,-0.375991,-0.019154,0.397626,-421.457001,0.038765,0.000000
180.910004,-0.100166,-421.412537,-0.001052,0.001545,0.039233,-0.445562,-0.022698,0.392327,-421.412537,0.038019,0.000000
181.360016,-0.124001,-421.545959,-0.001069,0.001509,0.038323,-0.551582,-0.028099,0.383228,-421.545959,0.037265,0.000000
181.810013,-0.089737,-421.545959,-0.001043,0.001487,0.037776,-0.399170,-0.020335,0.377763,-421.545959,0.036518,0.000000
182.260010,-0.093460,-421.501495,-0.001052,0.001443,0.036657,-0.415731,-0.021178,0.366575,-421.501495,0.035764,0.000000
182.710007,-0.099052,-421.501495,-0.001082,0.001421,0.036094,-0.440607,-0.022446,0.360943,-421.501495,0.035018,0.000000
183.160004,-0.084152,-421.634949,-0.001074,0.001390,0.035296,-0.374328,-0.019069,0.352964,-421.634949,0.034264,0.000000
183.610016,-0.096817,-421.634949,-0.001082,0.001364,0.034654,-0.430664,-0.021939,0.346545,-421.634949,0.033518,0.000000
184.060013,-0.095695,-421.590454,-0.001087,0.001334,0.033873,-0.425675,-0.021685,0.338733,-421.590454,0.032764,0.000000
184.510010,-0.075966,-421.634949,-0.001130,0.001305,0.033154,-0.337913,-0.017214,0.331542,-421.634949,0.033015,0.000000
184.600006,-0.063675,-421.634949,-0.001125,0.001306,0.033171,-0.283240,-0.014429,0.331708,-421.634949,0.033015,0.000000