File: Data/sima compression 500bar/P2-21-500bar-1_11072024_163511.csv
Time (sec),S:Load (lbs),S:HL1 (DIM),S:LVDT (in),S:Position (in),Ch:Position (mm),Ch:Load (N),Ch:Stress (MPa),Ch:Strain (mm/mm),Ch:HL1 (DIM),Set Point (),Cycles ()
0.010000,0.002609,-259.991150,-0.008938,-0.005331,-0.135399,0.011607,0.000591,-1.353993,-259.991150,-0.135192,0.000000
0.480000,-0.046921,-259.991150,-0.008933,-0.005250,-0.133354,-0.208714,-0.010632,-1.333540,-259.991150,-0.132624,0.000000
0.950000,0.017502,-260.035645,-0.008731,-0.004956,-0.125878,0.077852,0.003966,-1.258780,-260.035645,-0.124785,0.000000
1.420000,0.062935,-260.035645,-0.008433,-0.004650,-0.118107,0.279948,0.014261,-1.181069,-260.035645,-0.116962,0.000000
1.890000,0.003349,-260.080109,-0.008114,-0.004341,-0.110251,0.014898,0.000759,-1.102510,-260.080109,-0.109141,0.000000
2.360000,0.020111,-260.124603,-0.007821,-0.004033,-0.102437,0.089459,0.004557,-1.024374,-260.124603,-0.101300,0.000000
2.830000,0.036491,-260.169098,-0.007511,-0.003722,-0.094536,0.162322,0.008269,-0.945361,-260.169098,-0.093478,0.000000
3.300000,0.091232,-260.302521,-0.007463,-0.000008,-0.000191,0.405822,0.020674,-0.001908,-260.302521,0.000035,0.000000
3.770000,0.123260,-260.258057,-0.007455,-0.000008,-0.000191,0.548290,0.027931,-0.001908,-260.258057,0.000590,0.000000
4.240000,0.169800,-260.302521,-0.007446,0.000016,0.000416,0.755307,0.038477,0.004163,-260.302521,0.001370,0.000000
4.710000,0.247627,-260.302521,-0.007442,0.000051,0.001284,1.101501,0.056113,0.012838,-260.302521,0.002159,0.000000
5.180000,0.369392,-260.435974,-0.007411,0.000078,0.001986,1.643139,0.083706,0.019863,-260.435974,0.002940,0.000000
5.650000,0.695595,-260.391479,-0.007399,0.000112,0.002845,3.094160,0.157624,0.028447,-260.391479,0.003721,0.000000
6.120000,1.088074,-260.435974,-0.007360,0.000141,0.003591,4.839993,0.246561,0.035911,-260.435974,0.004510,0.000000
6.590000,1.441086,-260.480438,-0.007351,0.000167,0.004241,6.410270,0.326555,0.042406,-260.480438,0.005290,0.000000
7.060000,2.026825,-260.524933,-0.007321,0.000203,0.005152,9.015768,0.459285,0.051520,-260.524933,0.006071,0.000000
7.530000,2.728004,-260.613892,-0.007291,0.000238,0.006045,12.134769,0.618175,0.060452,-260.613892,0.006860,0.000000
8.000000,3.107452,-260.613892,-0.007269,0.000258,0.006557,13.822639,0.704159,0.065570,-260.613892,0.007641,0.000000
8.470000,4.188820,-260.702850,-0.007261,0.000297,0.007553,18.632801,0.949200,0.075531,-260.702850,0.008421,0.000000
8.940001,4.898186,-260.658386,-0.007217,0.000327,0.008300,21.788218,1.109945,0.082995,-260.658386,0.009211,0.000000
9.410001,5.933754,-260.702850,-0.007213,0.000359,0.009123,26.394655,1.344608,0.091231,-260.702850,0.009991,0.000000
9.880000,6.646851,-260.791809,-0.007196,0.000385,0.009774,29.566668,1.506198,0.097741,-260.791809,0.010772,0.000000
10.350000,7.802322,-260.791809,-0.007179,0.000421,0.010702,34.706463,1.768032,0.107022,-260.791809,0.011561,0.000000
10.820001,8.855392,-260.836304,-0.007148,0.000450,0.011430,39.390755,2.006661,0.114304,-260.836304,0.012340,0.000000
11.290001,9.772171,-260.925262,-0.007123,0.000482,0.012237,43.468788,2.214406,0.122373,-260.925262,0.013121,0.000000
11.760000,11.068031,-260.925262,-0.007118,0.000510,0.012966,49.233063,2.508052,0.129655,-260.925262,0.013910,0.000000
12.230000,12.197807,-260.925262,-0.007092,0.000543,0.013789,54.258556,2.764063,0.137891,-260.925262,0.014691,0.000000
12.700001,13.561066,-261.014221,-0.007067,0.000573,0.014543,60.322632,3.072982,0.145431,-261.014221,0.015471,0.000000
13.170001,14.585083,-261.058716,-0.007054,0.000602,0.015299,64.877693,3.305027,0.152985,-261.058716,0.016261,0.000000
13.640000,16.250336,-261.058716,-0.007006,0.000637,0.016183,72.285103,3.682379,0.161827,-261.058716,0.017041,0.000000
14.110001,16.505783,-261.103180,-0.007015,0.000654,0.016608,73.421387,3.740264,0.166081,-261.103180,0.017822,0.000000
14.580001,18.408981,-261.192139,-0.006985,0.000696,0.017666,81.887238,4.171535,0.176664,-261.192139,0.018611,0.000000
15.050001,19.803139,-261.236633,-0.006946,0.000726,0.018429,88.088760,4.487455,0.184294,-261.236633,0.019391,0.000000
15.520000,21.552177,-261.236633,-0.006946,0.000762,0.019365,95.868874,4.883793,0.193650,-261.236633,0.020172,0.000000
15.990001,21.926781,-261.236633,-0.006916,0.000781,0.019834,97.535194,4.968679,0.198344,-261.236633,0.020961,0.000000
16.460001,23.928284,-261.236633,-0.006873,0.000824,0.020918,106.438324,5.422226,0.209184,-261.236633,0.021742,0.000000
16.930000,25.214828,-261.370056,-0.006855,0.000853,0.021663,112.161156,5.713762,0.216632,-261.370056,0.022522,0.000000
17.400002,26.690544,-261.414551,-0.006834,0.000885,0.022487,118.725471,6.048163,0.224868,-261.414551,0.023312,0.000000
17.870001,27.269585,-261.370056,-0.006795,0.000908,0.023052,121.301170,6.179376,0.230515,-261.370056,0.024092,0.000000
18.340000,28.905785,-261.459045,-0.006778,0.000943,0.023961,128.579346,6.550145,0.239614,-261.459045,0.024873,0.000000
18.810001,29.980827,-261.459045,-0.006739,0.000972,0.024699,133.361374,6.793753,0.246987,-261.459045,0.025662,0.000000
19.280001,31.654266,-261.503510,-0.006739,0.001009,0.025618,140.805206,7.172959,0.256177,-261.503510,0.026441,0.000000
19.750000,32.399757,-261.592468,-0.006704,0.001033,0.026234,144.121323,7.341890,0.262339,-261.592468,0.027222,0.000000
20.220001,33.739182,-261.636963,-0.006670,0.001067,0.027110,150.079376,7.645408,0.271104,-261.636963,0.028011,0.000000
20.690001,34.744583,-261.592468,-0.006648,0.001098,0.027899,154.551620,7.873235,0.278992,-261.592468,0.028792,0.000000
21.160002,36.046776,-261.636963,-0.006635,0.001131,0.028739,160.344070,8.168316,0.287395,-261.636963,0.029572,0.000000
21.630001,36.924080,-261.725922,-0.006605,0.001161,0.029477,164.246506,8.367116,0.294768,-261.725922,0.030362,0.000000
22.100000,37.926506,-261.770386,-0.006588,0.001191,0.030258,168.705521,8.594269,0.302580,-261.770386,0.031142,0.000000
22.570002,38.800468,-261.814880,-0.006541,0.001220,0.030986,172.593109,8.792312,0.309862,-261.814880,0.031923,0.000000
23.040001,39.620430,-261.859344,-0.006510,0.001249,0.031723,176.240479,8.978118,0.317235,-261.859344,0.032712,0.000000
23.510000,40.240807,-261.814880,-0.006485,0.001275,0.032382,179.000046,9.118697,0.323820,-261.814880,0.033492,0.000000
23.980001,41.113274,-261.859344,-0.006463,0.001313,0.033354,182.880981,9.316401,0.333540,-261.859344,0.034273,0.000000
24.450001,42.798630,-261.948334,-0.006433,0.001344,0.034126,190.377808,9.698308,0.341261,-261.948334,0.035062,0.000000
24.920002,43.110306,-261.992798,-0.006407,0.001368,0.034759,191.764221,9.768934,0.347590,-261.992798,0.035843,0.000000
25.390001,44.293335,-262.037292,-0.006359,0.001403,0.035626,197.026596,10.037013,0.356265,-262.037292,0.036623,0.000000
25.860001,45.650635,-262.037292,-0.006342,0.001438,0.036536,203.064163,10.344582,0.365363,-262.037292,0.037413,0.000000
26.330002,46.102318,-262.037292,-0.006316,0.001466,0.037239,205.073349,10.446934,0.372388,-262.037292,0.038193,0.000000
26.800001,46.538368,-262.126251,-0.006291,0.001493,0.037925,207.013000,10.545745,0.379246,-262.126251,0.038974,0.000000
27.270000,47.985405,-262.215210,-0.006239,0.001528,0.038809,213.449738,10.873649,0.388088,-262.215210,0.039763,0.000000
27.740002,47.695328,-262.259674,-0.006226,0.001546,0.039260,212.159409,10.807916,0.392600,-262.259674,0.040544,0.000000
28.210001,49.816734,-262.215210,-0.006204,0.001591,0.040421,221.595901,11.288633,0.404212,-262.215210,0.041323,0.000000
28.680002,49.714333,-262.259674,-0.006170,0.001613,0.040977,221.140396,11.265429,0.409768,-262.259674,0.042112,0.000000
29.150002,51.306221,-262.304169,-0.006140,0.001653,0.041982,228.221466,11.626156,0.419821,-262.304169,0.042893,0.000000
29.620001,50.948746,-262.393127,-0.006109,0.001670,0.042426,226.631332,11.545151,0.424256,-262.393127,0.043673,0.000000
30.090002,52.905563,-262.393127,-0.006062,0.001716,0.043587,235.335693,11.988572,0.435869,-262.393127,0.044463,0.000000
30.560001,53.080948,-262.437622,-0.006032,0.001741,0.044212,236.115845,12.028315,0.442121,-262.437622,0.045243,0.000000
31.030001,54.094925,-262.437622,-0.006002,0.001776,0.045113,240.626251,12.258085,0.451129,-262.437622,0.046024,0.000000
31.500002,53.974274,-262.482086,-0.006002,0.001797,0.045634,240.089554,12.230745,0.456337,-262.482086,0.046813,0.000000
31.970001,55.547173,-262.526581,-0.005946,0.001837,0.046666,247.086166,12.587169,0.466662,-262.526581,0.047594,0.000000
32.440002,55.786240,-262.571045,-0.005898,0.001865,0.047376,248.149582,12.641342,0.473763,-262.571045,0.048374,0.000000
32.910000,56.462097,-262.615540,-0.005894,0.001896,0.048148,251.155945,12.794495,0.481484,-262.615540,0.049163,0.000000
33.380001,56.676582,-262.660004,-0.005859,0.001923,0.048851,252.110031,12.843098,0.488509,-262.660004,0.049944,0.000000
33.850002,58.012283,-262.704498,-0.005816,0.001959,0.049753,258.051514,13.145771,0.497532,-262.704498,0.050724,0.000000
34.320004,58.113937,-262.748993,-0.005795,0.001985,0.050421,258.503693,13.168806,0.504209,-262.748993,0.051514,0.000000
34.790001,59.264938,-262.837952,-0.005756,0.002020,0.051296,263.623627,13.429626,0.512959,-262.837952,0.052294,0.000000
35.260002,59.970215,-262.837952,-0.005730,0.002051,0.052086,266.760834,13.589445,0.520862,-262.837952,0.053075,0.000000
35.730003,60.842308,-262.837952,-0.005683,0.002083,0.052919,270.640106,13.787064,0.529189,-262.837952,0.053864,0.000000
36.200001,61.301819,-262.837952,-0.005652,0.002113,0.053664,272.684113,13.891191,0.536638,-262.837952,0.054645,0.000000
36.670002,62.151947,-262.926910,-0.005639,0.002146,0.054506,276.465668,14.083833,0.545055,-262.926910,0.055424,0.000000
37.140003,62.859825,-262.971375,-0.005596,0.002177,0.055285,279.614471,14.244240,0.552852,-262.971375,0.056213,0.000000
37.610001,63.679413,-262.971375,-0.005570,0.002207,0.056066,283.260162,14.429961,0.560664,-262.971375,0.056994,0.000000
38.080002,63.981415,-263.015869,-0.005519,0.002237,0.056813,284.603546,14.498396,0.568128,-263.015869,0.057774,0.000000
38.550003,64.819244,-262.971375,-0.005514,0.002271,0.057679,288.330414,14.688251,0.576788,-262.971375,0.058564,0.000000
39.020000,65.575912,-263.015869,-0.005471,0.002301,0.058443,291.696228,14.859715,0.584433,-263.015869,0.059344,0.000000
39.490002,66.466995,-263.104828,-0.005454,0.002334,0.059284,295.659973,15.061637,0.592836,-263.104828,0.060125,0.000000
39.960003,66.617432,-263.060333,-0.005428,0.002359,0.059925,296.329132,15.095726,0.599255,-263.060333,0.060914,0.000000
40.430000,66.875488,-263.238281,-0.005385,0.002388,0.060654,297.477020,15.154202,0.606537,-263.238281,0.061695,0.000000
40.900002,68.031326,-263.238281,-0.005376,0.002419,0.061442,302.618439,15.416119,0.614425,-263.238281,0.062475,0.000000
41.370003,69.043076,-263.282745,-0.005346,0.002454,0.062319,307.118927,15.645385,0.623191,-263.282745,0.063264,0.000000
41.840000,69.575195,-263.371704,-0.005325,0.002482,0.063047,309.485931,15.765965,0.630473,-263.371704,0.064045,0.000000
42.310001,70.697891,-263.416199,-0.005282,0.002517,0.063924,314.479919,16.020370,0.639238,-263.416199,0.064825,0.000000
42.780003,71.300385,-263.327240,-0.005243,0.002545,0.064652,317.159943,16.156898,0.646521,-263.327240,0.065615,0.000000
43.250004,72.063004,-263.371704,-0.005230,0.002575,0.065415,320.552246,16.329710,0.654151,-263.371704,0.066395,0.000000
43.720001,72.987244,-263.460663,-0.005191,0.002609,0.066274,324.663483,16.539146,0.662735,-263.460663,0.067176,0.000000
44.190002,73.610962,-263.505157,-0.005152,0.002636,0.066950,327.437927,16.680481,0.669502,-263.505157,0.067965,0.000000
44.660004,74.380280,-263.594116,-0.005135,0.002666,0.067722,330.860016,16.854813,0.677224,-263.594116,0.068746,0.000000
45.130001,74.440613,-263.594116,-0.005109,0.002688,0.068286,331.128387,16.868484,0.682856,-263.594116,0.069525,0.000000
45.600002,76.001221,-263.549622,-0.005088,0.002726,0.069230,338.070312,17.222122,0.692303,-263.549622,0.070314,0.000000
46.070004,77.083710,-263.638611,-0.005053,0.002759,0.070072,342.885468,17.467419,0.700720,-263.638611,0.071095,0.000000
46.540001,78.367645,-263.683075,-0.005044,0.002793,0.070940,348.596710,17.758362,0.709395,-263.683075,0.071875,0.000000
47.010002,78.482346,-263.727570,-0.004988,0.002816,0.071521,349.106903,17.784353,0.715209,-263.727570,0.072665,0.000000
47.480003,79.629242,-263.772034,-0.004980,0.002849,0.072354,354.208557,18.044245,0.723536,-263.772034,0.073445,0.000000
47.950001,80.513626,-263.772034,-0.004954,0.002881,0.073177,358.142487,18.244648,0.731772,-263.772034,0.074226,0.000000
48.420002,81.858643,-263.816528,-0.004915,0.002913,0.074001,364.125427,18.549433,0.740008,-263.816528,0.075015,0.000000
48.890003,82.475662,-263.905487,-0.004898,0.002940,0.074677,366.870056,18.689253,0.746775,-263.905487,0.075796,0.000000
49.360001,83.516815,-263.905487,-0.004876,0.002972,0.075483,371.501343,18.925180,0.754829,-263.905487,0.076576,0.000000
49.830002,84.682343,-263.949951,-0.004846,0.003003,0.076273,376.685883,19.189293,0.762732,-263.949951,0.077365,0.000000
50.300003,86.318542,-263.949951,-0.004820,0.003039,0.077201,383.964050,19.560062,0.772013,-263.949951,0.078146,0.000000
50.770004,86.077621,-263.994446,-0.004794,0.003055,0.077590,382.892395,19.505468,0.775903,-263.994446,0.078927,0.000000
51.240002,88.609375,-264.038940,-0.004769,0.003102,0.078788,394.154175,20.079170,0.787879,-264.038940,0.079716,0.000000
51.710003,89.364182,-264.083405,-0.004751,0.003130,0.079499,397.511719,20.250212,0.794994,-264.083405,0.080496,0.000000
52.180004,90.169617,-264.127899,-0.004704,0.003160,0.080262,401.094482,20.432728,0.802625,-264.127899,0.081277,0.000000
52.650002,90.931870,-264.127899,-0.004700,0.003182,0.080826,404.485168,20.605455,0.808257,-264.127899,0.082066,0.000000
53.120003,93.152328,-264.261322,-0.004656,0.003224,0.081901,414.362244,21.108620,0.819006,-264.261322,0.082847,0.000000
53.590004,94.011765,-264.261322,-0.004656,0.003253,0.082621,418.185211,21.303371,0.826212,-264.261322,0.083626,0.000000
54.060001,95.192932,-264.305817,-0.004609,0.003283,0.083384,423.439301,21.571026,0.833843,-264.305817,0.084415,0.000000
54.530003,96.050507,-264.350281,-0.004605,0.003308,0.084034,427.253998,21.765356,0.840338,-264.350281,0.085196,0.000000
55.000004,97.923904,-264.394775,-0.004566,0.003347,0.085015,435.587280,22.189875,0.850148,-264.394775,0.085978,0.000000
55.470001,98.794144,-264.394775,-0.004557,0.003375,0.085734,439.458313,22.387074,0.857339,-264.394775,0.086766,0.000000
55.940002,99.947372,-264.439240,-0.004527,0.003404,0.086462,444.588104,22.648397,0.864621,-264.439240,0.087546,0.000000
56.410004,101.499802,-264.528229,-0.004514,0.003435,0.087260,451.493652,23.000183,0.872600,-264.528229,0.088327,0.000000
56.880001,101.378403,-264.572693,-0.004493,0.003452,0.087676,450.953644,22.972673,0.876763,-264.572693,0.089116,0.000000
57.350002,104.262802,-264.528229,-0.004454,0.003499,0.088865,463.784119,23.626289,0.888648,-264.528229,0.089897,0.000000
57.820004,105.103622,-264.572693,-0.004454,0.003525,0.089542,467.524261,23.816820,0.895415,-264.572693,0.090677,0.000000
58.290001,107.176620,-264.617187,-0.004424,0.003562,0.090477,476.745422,24.286570,0.904772,-264.617187,0.091467,0.000000
58.760002,107.357956,-264.706146,-0.004381,0.003583,0.091016,477.552032,24.327660,0.910161,-264.706146,0.092247,0.000000
59.230003,109.803711,-264.706146,-0.004376,0.003624,0.092056,488.431305,24.881876,0.920562,-264.706146,0.093028,0.000000
59.700005,111.259308,-264.706146,-0.004368,0.003653,0.092775,494.906128,25.211720,0.927753,-264.706146,0.093817,0.000000
60.170002,112.896637,-264.750610,-0.004320,0.003686,0.093617,502.189331,25.582743,0.936171,-264.750610,0.094597,0.000000
60.640003,113.365814,-264.839569,-0.004316,0.003707,0.094155,504.276337,25.689060,0.941546,-264.839569,0.095378,0.000000
61.110004,115.361740,-264.884064,-0.004286,0.003742,0.095040,513.154663,26.141342,0.950402,-264.884064,0.096167,0.000000
61.580002,117.094757,-264.928558,-0.004260,0.003777,0.095933,520.863464,26.534052,0.959335,-264.928558,0.096948,0.000000
62.050003,118.831879,-264.884064,-0.004243,0.003809,0.096757,528.590576,26.927689,0.967571,-264.884064,0.097727,0.000000
62.520004,119.985489,-264.973022,-0.004238,0.003835,0.097416,533.722107,27.189100,0.974156,-264.973022,0.098518,0.000000
62.990002,121.624298,-265.017517,-0.004204,0.003868,0.098248,541.011902,27.560461,0.982483,-265.017517,0.099297,0.000000
63.460003,123.063889,-265.150940,-0.004169,0.003897,0.098995,547.415527,27.886675,0.989947,-265.150940,0.100079,0.000000
63.930004,125.137634,-265.106476,-0.004182,0.003932,0.099879,556.640015,28.356592,0.998788,-265.106476,0.100867,0.000000
64.400002,126.466629,-265.017517,-0.004152,0.003958,0.100537,562.551636,28.657749,1.005374,-265.017517,0.101647,0.000000
64.870003,128.243210,-265.106476,-0.004135,0.003991,0.101379,570.454285,29.060326,1.013792,-265.106476,0.102428,0.000000
65.340004,130.014587,-265.150940,-0.004096,0.004024,0.102219,578.333740,29.461727,1.022194,-265.150940,0.103217,0.000000
65.810005,131.548019,-265.328888,-0.004087,0.004055,0.103001,585.154785,29.809208,1.030006,-265.328888,0.103998,0.000000
66.280006,132.279358,-265.239899,-0.004066,0.004072,0.103434,588.407959,29.974932,1.034336,-265.239899,0.104778,0.000000
66.750000,135.234879,-265.328888,-0.004057,0.004117,0.104562,601.554810,30.644661,1.045615,-265.328888,0.105568,0.000000
67.220001,136.577652,-265.373352,-0.004031,0.004143,0.105238,607.527710,30.948938,1.052382,-265.373352,0.106348,0.000000
67.690002,138.031769,-265.373352,-0.004014,0.004173,0.105992,613.995972,31.278446,1.059922,-265.373352,0.107129,0.000000
68.160004,140.063431,-265.506805,-0.003997,0.004206,0.106834,623.033264,31.738827,1.068340,-265.506805,0.107918,0.000000
68.630005,142.102539,-265.462311,-0.003980,0.004237,0.107623,632.103638,32.200897,1.076227,-265.462311,0.108698,0.000000
69.100006,143.816574,-265.462311,-0.003958,0.004267,0.108369,639.728088,32.589302,1.083691,-265.462311,0.109479,0.000000
69.570000,145.200317,-265.551270,-0.003958,0.004293,0.109037,645.883240,32.902863,1.090368,-265.551270,0.110268,0.000000
70.040001,147.366409,-265.640228,-0.003928,0.004325,0.109860,655.518555,33.393707,1.098604,-265.640228,0.111049,0.000000
70.510002,148.694656,-265.684723,-0.003923,0.004357,0.110667,661.426880,33.694691,1.106673,-265.684723,0.111829,0.000000
70.980003,151.210770,-265.684723,-0.003898,0.004388,0.111456,672.619080,34.264851,1.114561,-265.684723,0.112619,0.000000
71.450005,152.983276,-265.684723,-0.003880,0.004419,0.112245,680.503601,34.666504,1.122448,-265.684723,0.113398,0.000000
71.920006,155.370178,-265.684723,-0.003876,0.004452,0.113068,691.121094,35.207386,1.130684,-265.684723,0.114180,0.000000
72.390007,156.536072,-265.773682,-0.003846,0.004479,0.113771,696.307251,35.471584,1.137709,-265.773682,0.114968,0.000000
72.860001,159.444305,-265.773682,-0.003833,0.004513,0.114638,709.243713,36.130596,1.146384,-265.773682,0.115748,0.000000
73.330002,160.942352,-265.907135,-0.003833,0.004540,0.115306,715.907349,36.470055,1.153061,-265.907135,0.116529,0.000000
73.800003,163.427948,-265.862640,-0.003798,0.004577,0.116243,726.963806,37.033302,1.162432,-265.862640,0.117318,0.000000
74.270004,164.326111,-265.862640,-0.003786,0.004595,0.116703,730.959045,37.236828,1.167035,-265.862640,0.118099,0.000000
74.740005,167.664795,-265.907135,-0.003777,0.004639,0.117830,745.810242,37.993385,1.178298,-265.907135,0.118879,0.000000
75.210007,169.029541,-265.996094,-0.003764,0.004664,0.118455,751.880920,38.302643,1.184551,-265.996094,0.119669,0.000000
75.680000,171.195267,-266.040558,-0.003734,0.004697,0.119314,761.514587,38.793404,1.193135,-266.040558,0.120449,0.000000
76.150002,172.663147,-266.040558,-0.003734,0.004721,0.119921,768.044006,39.126030,1.199206,-266.040558,0.121230,0.000000
76.620003,175.415359,-266.085052,-0.003729,0.004757,0.120840,780.286499,39.749691,1.208396,-266.085052,0.122019,0.000000
77.090004,177.342392,-266.174011,-0.003725,0.004788,0.121619,788.858337,40.186359,1.216193,-266.174011,0.122800,0.000000
77.560005,179.444809,-266.218506,-0.003686,0.004821,0.122452,798.210388,40.662777,1.224519,-266.218506,0.123580,0.000000
78.030006,181.533813,-266.262970,-0.003682,0.004849,0.123154,807.502747,41.136150,1.231544,-266.262970,0.124369,0.000000
78.500000,183.863739,-266.262970,-0.003669,0.004881,0.123980,817.866760,41.664120,1.239795,-266.262970,0.125150,0.000000
78.970001,186.047714,-266.307465,-0.003639,0.004913,0.124794,827.581543,42.159016,1.247940,-266.307465,0.125930,0.000000
79.440002,188.315460,-266.307465,-0.003648,0.004946,0.125618,837.669006,42.672894,1.256176,-266.307465,0.126720,0.000000
79.910004,190.594757,-266.440887,-0.003639,0.004974,0.126346,847.807800,43.189388,1.263458,-266.440887,0.127499,0.000000
80.380005,192.823029,-266.440887,-0.003617,0.005005,0.127118,857.719666,43.694321,1.271180,-266.440887,0.128281,0.000000
80.850006,194.806274,-266.440887,-0.003600,0.005036,0.127916,866.541565,44.143734,1.279158,-266.440887,0.129069,0.000000
81.320007,197.364868,-266.440887,-0.003579,0.005070,0.128774,877.922791,44.723518,1.287742,-266.440887,0.129851,0.000000
81.790001,199.654572,-266.529846,-0.003591,0.005099,0.129502,888.107910,45.242371,1.295025,-266.529846,0.130630,0.000000
82.260002,202.263428,-266.618835,-0.003561,0.005134,0.130414,899.712646,45.833549,1.304139,-266.618835,0.131419,0.000000
82.730003,203.800201,-266.618835,-0.003553,0.005157,0.130986,906.548584,46.181786,1.309861,-266.618835,0.132200,0.000000
83.200005,205.959595,-266.574341,-0.003540,0.005190,0.131835,916.154053,46.671108,1.318355,-266.574341,0.132980,0.000000
83.670006,208.210205,-266.707794,-0.003531,0.005217,0.132503,926.165222,47.181107,1.325031,-266.707794,0.133770,0.000000
84.140007,210.872650,-266.707794,-0.003514,0.005252,0.133389,938.008423,47.784428,1.333888,-266.707794,0.134550,0.000000
84.610001,212.902100,-266.752258,-0.003501,0.005279,0.134082,947.035828,48.244305,1.340822,-266.752258,0.135331,0.000000
85.080002,215.640533,-266.841217,-0.003497,0.005314,0.134966,959.216980,48.864845,1.349663,-266.841217,0.136120,0.000000
85.550003,217.825226,-266.841217,-0.003488,0.005342,0.135695,968.934998,49.359901,1.356945,-266.841217,0.136901,0.000000
86.020004,220.121277,-266.841217,-0.003466,0.005373,0.136476,979.148315,49.880192,1.364757,-266.841217,0.137681,0.000000
86.490005,220.157013,-266.930176,-0.003458,0.005372,0.136450,979.307312,49.888290,1.364500,-266.930176,0.023946,0.000000
86.960007,219.760834,-267.019135,-0.003445,0.005385,0.136771,977.544983,49.798515,1.367710,-267.019135,982.000671,0.000000
87.430008,219.847229,-267.019135,-0.003419,0.005396,0.137048,977.929321,49.818092,1.370480,-267.019135,982.000671,0.000000
87.900002,219.691193,-267.019135,-0.003432,0.005402,0.137213,977.235229,49.782734,1.372130,-267.019135,982.000671,0.000000
88.370003,219.767517,-267.063629,-0.003419,0.005411,0.137446,977.574768,49.800030,1.374462,-267.063629,982.000671,0.000000
88.840004,219.833801,-267.108124,-0.003415,0.005421,0.137699,977.869568,49.815052,1.376990,-267.108124,982.000671,0.000000
89.310005,219.882965,-267.197083,-0.003406,0.005430,0.137916,978.088257,49.826191,1.379155,-267.197083,982.000671,0.000000
89.780006,219.448029,-267.197083,-0.003397,0.005433,0.138011,976.153564,49.727631,1.380109,-267.197083,982.000671,0.000000
90.250008,219.827484,-267.197083,-0.003380,0.005444,0.138271,977.841492,49.813618,1.382713,-267.197083,982.000671,0.000000
90.720001,219.999512,-267.241547,-0.003385,0.005452,0.138479,978.606689,49.852604,1.384787,-267.241547,982.000671,0.000000
91.190002,219.254028,-267.286041,-0.003367,0.005452,0.138479,975.290649,49.683674,1.384787,-267.286041,982.000671,0.000000
91.660004,219.966736,-267.286041,-0.003354,0.005449,0.138392,978.460937,49.845173,1.383924,-267.286041,982.000671,0.000000
92.130005,219.115509,-267.330505,-0.003354,0.005449,0.138401,974.674438,49.652283,1.384015,-267.330505,982.000671,0.000000
92.600006,220.185333,-267.419464,-0.003337,0.005457,0.138609,979.433289,49.894707,1.386089,-267.419464,982.000671,0.000000
93.070007,219.394775,-267.419464,-0.003346,0.005460,0.138688,975.916687,49.715565,1.386876,-267.419464,982.000671,0.000000
93.540001,219.418243,-267.419464,-0.003333,0.005485,0.139320,976.021118,49.720886,1.393205,-267.419464,982.000671,0.000000
94.010002,219.267059,-267.552917,-0.003337,0.005492,0.139493,975.348572,49.686626,1.394931,-267.552917,982.000671,0.000000
94.480003,220.421783,-267.552917,-0.003311,0.005478,0.139137,980.485046,49.948292,1.391373,-267.552917,982.000671,0.000000
94.950005,219.772736,-267.508453,-0.003311,0.005484,0.139286,977.597961,49.801216,1.392856,-267.508453,982.000671,0.000000
95.420006,220.145477,-267.641876,-0.003303,0.005516,0.140118,979.255981,49.885677,1.401183,-267.641876,982.000671,0.000000
95.890007,219.520630,-267.686371,-0.003311,0.005517,0.140126,976.476501,49.744087,1.401259,-267.686371,982.000671,0.000000
96.360008,219.866943,-267.730835,-0.003294,0.005549,0.140933,978.017029,49.822559,1.409328,-267.730835,982.000671,0.000000
96.830002,220.099304,-267.775330,-0.003272,0.005488,0.139407,979.050598,49.875217,1.394068,-267.775330,982.000671,0.000000
97.300003,219.621552,-267.775330,-0.003290,0.005525,0.140326,976.925476,49.766956,1.403257,-267.775330,982.000671,0.000000
97.770004,219.528839,-267.775330,-0.003264,0.005543,0.140786,976.513062,49.745945,1.407860,-267.775330,982.000671,0.000000
98.240005,219.509460,-267.819794,-0.003264,0.005550,0.140968,976.426819,49.741558,1.409677,-267.819794,982.000671,0.000000
98.710007,219.675934,-267.864288,-0.003260,0.005557,0.141142,977.167358,49.779278,1.411418,-267.864288,982.000671,0.000000
99.180008,219.790985,-267.864288,-0.003255,0.005562,0.141280,977.679138,49.805347,1.412795,-267.864288,982.000671,0.000000
99.650002,219.358673,-267.908783,-0.003255,0.005565,0.141340,975.756104,49.707386,1.413401,-267.908783,982.000671,0.000000
100.120003,219.750397,-267.997742,-0.003264,0.005570,0.141488,977.498596,49.796154,1.414885,-267.997742,982.000671,0.000000
100.590004,219.196686,-268.042206,-0.003234,0.005570,0.141488,975.035583,49.670677,1.414885,-268.042206,982.000671,0.000000
101.060005,220.390137,-268.086700,-0.003242,0.005551,0.141002,980.344299,49.941120,1.410025,-268.086700,982.000671,0.000000
101.530006,219.796204,-268.131165,-0.003225,0.005552,0.141012,977.702332,49.806530,1.410116,-268.131165,982.000671,0.000000
102.000008,219.666229,-268.131165,-0.003208,0.005591,0.142008,977.124207,49.777081,1.420077,-268.131165,982.000671,0.000000
102.470001,219.578003,-268.175659,-0.003216,0.005595,0.142103,976.731750,49.757088,1.421031,-268.175659,982.000671,0.000000
102.940002,219.480438,-268.264618,-0.003225,0.005598,0.142182,976.297729,49.734978,1.421818,-268.264618,982.000671,0.000000
103.410004,219.915741,-268.309082,-0.003199,0.005608,0.142433,978.234070,49.833622,1.424332,-268.309082,982.000671,0.000000
103.880005,219.580963,-268.309082,-0.003191,0.005609,0.142468,976.744934,49.757755,1.424680,-268.309082,982.000671,0.000000
104.350006,219.307648,-268.264618,-0.003186,0.005615,0.142615,975.529114,49.695824,1.426148,-268.264618,982.000671,0.000000
104.820007,219.477081,-268.353577,-0.003182,0.005617,0.142677,976.282837,49.734219,1.426769,-268.353577,982.000671,0.000000
105.290009,220.448975,-268.442535,-0.003178,0.005613,0.142572,980.606018,49.954453,1.425725,-268.442535,982.000671,0.000000
105.760002,219.997650,-268.442535,-0.003191,0.005613,0.142572,978.598450,49.852180,1.425725,-268.442535,982.000671,0.000000
106.230003,219.888550,-268.442535,-0.003182,0.005635,0.143119,978.113098,49.827457,1.431190,-268.442535,982.000671,0.000000
106.700005,219.585449,-268.531494,-0.003152,0.005635,0.143136,976.764832,49.758778,1.431356,-268.531494,982.000671,0.000000
107.170006,219.684845,-268.531494,-0.003160,0.005642,0.143317,977.206970,49.781296,1.433173,-268.531494,982.000671,0.000000
107.640007,219.564575,-268.575989,-0.003160,0.005645,0.143379,976.671997,49.754044,1.433794,-268.575989,982.000671,0.000000
108.110008,219.444672,-268.620453,-0.003156,0.005649,0.143475,976.138672,49.726871,1.434748,-268.620453,982.000671,0.000000
108.580002,219.822632,-268.664948,-0.003147,0.005656,0.143666,977.819885,49.812523,1.436655,-268.664948,982.000671,0.000000
109.050003,219.513947,-268.753906,-0.003147,0.005657,0.143691,976.446777,49.742573,1.436913,-268.753906,982.000671,0.000000
109.520004,219.528473,-268.753906,-0.003147,0.005662,0.143812,976.511414,49.745861,1.438124,-268.753906,982.000671,0.000000
109.990005,219.428680,-268.842865,-0.003143,0.005666,0.143917,976.067505,49.723248,1.439168,-268.842865,982.000671,0.000000
110.460007,219.388092,-268.887360,-0.003134,0.005669,0.144003,975.886963,49.714054,1.440031,-268.887360,982.000671,0.000000
110.930008,219.498291,-268.798401,-0.003117,0.005674,0.144115,976.377136,49.739025,1.441152,-268.798401,982.000671,0.000000
111.400002,219.479309,-268.887360,-0.003126,0.005678,0.144211,976.292725,49.734722,1.442106,-268.887360,982.000671,0.000000
111.870003,219.564575,-268.931824,-0.003143,0.005683,0.144359,976.671997,49.754044,1.443589,-268.931824,982.000671,0.000000
112.340004,219.362000,-268.931824,-0.003113,0.005685,0.144394,975.770935,49.708141,1.443937,-268.931824,982.000671,0.000000
112.810005,219.563843,-268.931824,-0.003109,0.005690,0.144524,976.668762,49.753880,1.445239,-268.931824,982.000671,0.000000
113.280006,219.960419,-268.976318,-0.003104,0.005698,0.144740,978.432800,49.843742,1.447404,-268.976318,982.000671,0.000000
113.750008,219.766022,-269.020782,-0.003104,0.005698,0.144740,977.568115,49.799690,1.447404,-269.020782,982.000671,0.000000
114.220009,219.678894,-269.109741,-0.003087,0.005703,0.144845,977.180542,49.779949,1.448449,-269.109741,982.000671,0.000000
114.690002,219.534058,-269.154236,-0.003100,0.005704,0.144887,976.536255,49.747128,1.448873,-269.154236,982.000671,0.000000
115.160004,219.952972,-269.198730,-0.003091,0.005712,0.145096,978.399658,49.842056,1.450962,-269.198730,982.000671,0.000000
115.630005,219.705719,-269.154236,-0.003078,0.005712,0.145096,977.299866,49.786030,1.450962,-269.154236,982.000671,0.000000
116.100006,219.556030,-269.198730,-0.003083,0.005716,0.145192,976.633972,49.752106,1.451916,-269.198730,982.000671,0.000000
116.570007,219.378387,-269.287689,-0.003078,0.005717,0.145199,975.843811,49.711853,1.451992,-269.287689,982.000671,0.000000
117.040009,219.437988,-269.376648,-0.003065,0.005721,0.145304,976.108948,49.725361,1.453036,-269.376648,982.000671,0.000000
117.510002,219.383972,-269.421112,-0.003061,0.005724,0.145382,975.868652,49.713120,1.453824,-269.421112,982.000671,0.000000
117.980003,219.440582,-269.332153,-0.003044,0.005735,0.145659,976.120483,49.725948,1.456594,-269.332153,982.000671,0.000000
118.450005,219.907532,-269.421112,-0.003053,0.005735,0.145676,978.197571,49.831760,1.456761,-269.421112,982.000671,0.000000
118.920006,219.637573,-269.465607,-0.003053,0.005736,0.145685,976.996704,49.770584,1.456851,-269.465607,982.000671,0.000000
119.390007,219.389557,-269.510071,-0.003048,0.005737,0.145729,975.893494,49.714386,1.457291,-269.510071,982.000671,0.000000
119.860008,219.438354,-269.554565,-0.003035,0.005741,0.145834,976.110535,49.725441,1.458335,-269.554565,982.000671,0.000000
120.330009,219.219757,-269.554565,-0.003044,0.005741,0.145834,975.138184,49.675907,1.458335,-269.554565,982.000671,0.000000
120.800003,219.999512,-269.599030,-0.003035,0.005752,0.146111,978.606689,49.852604,1.461106,-269.599030,982.000671,0.000000
121.270004,219.755981,-269.643524,-0.003044,0.005753,0.146120,977.523437,49.797417,1.461197,-269.643524,982.000671,0.000000
121.740005,219.475952,-269.732483,-0.003040,0.005753,0.146120,976.277771,49.733963,1.461197,-269.732483,982.000671,0.000000
122.210007,219.151611,-269.732483,-0.003048,0.005753,0.146127,974.835083,49.660461,1.461272,-269.732483,982.000671,0.000000
122.680008,220.322723,-269.732483,-0.003044,0.005754,0.146162,980.044434,49.925846,1.461620,-269.732483,982.000671,0.000000
123.150009,219.972717,-269.776978,-0.003027,0.005754,0.146162,978.487488,49.846531,1.461620,-269.776978,982.000671,0.000000
123.620003,219.613007,-269.821442,-0.003022,0.005754,0.146162,976.887451,49.765018,1.461620,-269.821442,982.000671,0.000000
124.090004,219.273010,-269.910400,-0.003014,0.005754,0.146162,975.375061,49.687973,1.461620,-269.910400,982.000671,0.000000
124.560005,220.656738,-269.865936,-0.002997,0.005768,0.146501,981.530212,50.001530,1.465012,-269.865936,982.000671,0.000000
125.030006,220.326447,-269.910400,-0.003005,0.005767,0.146492,980.060974,49.926685,1.464921,-269.910400,982.000671,0.000000
125.500008,219.993927,-269.954895,-0.002997,0.005767,0.146492,978.581848,49.851337,1.464921,-269.954895,982.000671,0.000000
125.970009,219.631989,-270.043854,-0.003009,0.005767,0.146492,976.971863,49.769318,1.464921,-270.043854,982.000671,0.000000
126.440002,219.313599,-270.043854,-0.002997,0.005767,0.146492,975.555603,49.697170,1.464921,-270.043854,982.000671,0.000000
126.910004,221.023529,-270.132812,-0.002992,0.005794,0.147160,983.161743,50.084644,1.471597,-270.132812,982.000671,0.000000
127.380005,220.571838,-270.088348,-0.002988,0.005777,0.146734,981.152527,49.982292,1.467343,-270.088348,982.000671,0.000000
127.850006,220.294067,-270.088348,-0.002975,0.005777,0.146734,979.916931,49.919350,1.467343,-270.088348,982.000671,0.000000
128.320007,219.929138,-270.221771,-0.002979,0.005777,0.146734,978.293640,49.836655,1.467343,-270.221771,982.000671,0.000000
128.790009,219.613373,-270.266266,-0.002971,0.005777,0.146734,976.889099,49.765102,1.467343,-270.266266,982.000671,0.000000
129.260010,219.305420,-270.266266,-0.002984,0.005777,0.146734,975.519226,49.695316,1.467343,-270.266266,982.000671,0.000000
129.730011,220.100067,-270.310730,-0.002962,0.005805,0.147437,979.054016,49.875389,1.474368,-270.310730,982.000671,0.000000
130.200012,219.790619,-270.310730,-0.002962,0.005805,0.147437,977.677490,49.805267,1.474368,-270.310730,982.000671,0.000000
130.670013,219.503510,-270.355225,-0.002971,0.005805,0.147437,976.400391,49.740204,1.474368,-270.355225,982.000671,0.000000
131.139999,219.197784,-270.399689,-0.002958,0.005805,0.147437,975.040466,49.670929,1.474368,-270.399689,982.000671,0.000000
131.610001,220.316772,-270.488678,-0.002958,0.005818,0.147783,980.017944,49.924492,1.477835,-270.488678,982.000671,0.000000
132.080002,219.985748,-270.533142,-0.002945,0.005818,0.147783,978.545471,49.849483,1.477835,-270.533142,982.000671,0.000000
132.550003,219.726562,-270.488678,-0.002936,0.005818,0.147783,977.392578,49.790749,1.477835,-270.488678,982.000671,0.000000
133.020004,219.470001,-270.577637,-0.002949,0.005819,0.147793,976.251343,49.732613,1.477926,-270.577637,982.000671,0.000000
133.490005,219.204498,-270.622101,-0.002945,0.005819,0.147793,975.070312,49.672447,1.477926,-270.622101,982.000671,0.000000
133.960007,220.367432,-270.711060,-0.002940,0.005813,0.147662,980.243286,49.935974,1.476624,-270.711060,982.000671,0.000000
134.430008,220.081421,-270.622101,-0.002915,0.005813,0.147662,978.971069,49.871162,1.476624,-270.622101,982.000671,0.000000
134.900009,219.796570,-270.666595,-0.002928,0.005813,0.147662,977.703979,49.806614,1.476624,-270.666595,982.000671,0.000000
135.370010,219.515442,-270.755554,-0.002940,0.005814,0.147671,976.453430,49.742912,1.476715,-270.755554,982.000671,0.000000
135.840012,220.074371,-270.844513,-0.002906,0.005839,0.148304,978.939697,49.869568,1.483043,-270.844513,982.000671,0.000000
136.310013,219.854675,-270.844513,-0.002923,0.005839,0.148304,977.962463,49.819782,1.483043,-270.844513,982.000671,0.000000
136.780014,219.636810,-270.844513,-0.002928,0.005839,0.148304,976.993347,49.770412,1.483043,-270.844513,982.000671,0.000000
137.250000,219.398132,-270.844513,-0.002915,0.005839,0.148304,975.931641,49.716328,1.483043,-270.844513,982.000671,0.000000
137.720001,219.857269,-270.977966,-0.002919,0.005853,0.148677,977.973999,49.820370,1.486767,-270.977966,982.000671,0.000000
138.190002,219.950745,-271.066925,-0.002910,0.005850,0.148600,978.389771,49.841549,1.485995,-271.066925,982.000671,0.000000
138.660004,219.764160,-271.066925,-0.002893,0.005850,0.148600,977.559814,49.799271,1.485995,-271.066925,982.000671,0.000000
139.130005,219.549683,-271.022430,-0.002889,0.005850,0.148600,976.605774,49.750671,1.485995,-271.022430,982.000671,0.000000
139.600006,219.366119,-271.066925,-0.002910,0.005852,0.148643,975.789246,49.709072,1.486434,-271.066925,982.000671,0.000000
140.070007,219.218262,-271.155884,-0.002906,0.005852,0.148651,975.131531,49.675568,1.486510,-271.155884,982.000671,0.000000
140.540009,219.908661,-271.244843,-0.002906,0.005861,0.148877,978.202576,49.832012,1.488766,-271.244843,982.000671,0.000000
141.010010,219.705353,-271.244843,-0.002893,0.005861,0.148877,977.298218,49.785942,1.488766,-271.244843,982.000671,0.000000
141.480011,219.500153,-271.244843,-0.002893,0.005861,0.148877,976.385437,49.739445,1.488766,-271.244843,982.000671,0.000000
141.950012,219.431641,-271.289307,-0.002893,0.005864,0.148937,976.080688,49.723923,1.489371,-271.289307,982.000671,0.000000
142.420013,219.362000,-271.289307,-0.002889,0.005865,0.148981,975.770935,49.708141,1.489810,-271.289307,982.000671,0.000000
142.889999,219.261108,-271.378296,-0.002897,0.005867,0.149016,975.322144,49.685280,1.490159,-271.378296,982.000671,0.000000
143.360001,220.011444,-271.467255,-0.002880,0.005877,0.149267,978.659790,49.855305,1.492672,-271.467255,982.000671,0.000000
143.830002,219.870667,-271.422760,-0.002871,0.005876,0.149258,978.033569,49.823406,1.492581,-271.422760,982.000671,0.000000
144.300003,219.683746,-271.422760,-0.002889,0.005876,0.149258,977.202087,49.781048,1.492581,-271.422760,982.000671,0.000000
144.770004,219.514679,-271.511719,-0.002880,0.005876,0.149258,976.450073,49.742737,1.492581,-271.511719,982.000671,0.000000
145.240005,220.101929,-271.645172,-0.002867,0.005886,0.149493,979.062256,49.875809,1.494928,-271.645172,982.000671,0.000000
145.710007,219.954468,-271.600677,-0.002871,0.005886,0.149493,978.406311,49.842396,1.494928,-271.600677,982.000671,0.000000
146.180008,219.793976,-271.600677,-0.002880,0.005886,0.149493,977.692444,49.806026,1.494928,-271.600677,982.000671,0.000000
146.650009,219.631989,-271.645172,-0.002859,0.005887,0.149528,976.971863,49.769318,1.495276,-271.645172,982.000671,0.000000
147.120010,219.397400,-271.689636,-0.002863,0.005873,0.149172,975.928406,49.716160,1.491718,-271.689636,0.149311,0.000000
147.590012,219.006775,-271.778625,-0.002876,0.005855,0.148721,974.190796,49.627647,1.487206,-271.778625,0.148530,0.000000
148.060013,218.588226,-271.734131,-0.002876,0.005837,0.148269,972.328979,49.532803,1.482695,-271.734131,0.147741,0.000000
148.530014,217.531067,-271.778625,-0.002837,0.005808,0.147532,967.626526,49.293243,1.475322,-271.778625,0.146960,0.000000
149.000000,215.811066,-271.689636,-0.002850,0.005771,0.146587,959.975586,48.903488,1.465875,-271.689636,0.146180,0.000000
149.470001,215.004883,-271.823090,-0.002824,0.005747,0.145980,956.389465,48.720802,1.459804,-271.823090,0.145390,0.000000
149.940002,214.537933,-271.956543,-0.002811,0.005719,0.145252,954.312378,48.614990,1.452522,-271.956543,0.144610,0.000000
150.410004,214.127960,-271.956543,-0.002815,0.005689,0.144489,952.488708,48.522087,1.444891,-271.956543,0.143829,0.000000
150.880005,213.493408,-272.001007,-0.002811,0.005655,0.143631,949.666138,48.378300,1.436307,-272.001007,0.143040,0.000000
151.350006,212.788879,-271.956543,-0.002815,0.005623,0.142833,946.532227,48.218651,1.428329,-271.956543,0.142261,0.000000
151.820007,212.049347,-272.089966,-0.002815,0.005592,0.142043,943.242615,48.051071,1.420426,-272.089966,0.141479,0.000000
152.290009,210.872650,-272.089966,-0.002802,0.005573,0.141566,938.008423,47.784428,1.415657,-272.089966,0.140691,0.000000
152.760010,208.847321,-272.134460,-0.002790,0.005541,0.140733,928.999268,47.325478,1.407330,-272.134460,0.139909,0.000000
153.230011,206.286530,-272.134460,-0.002777,0.005508,0.139893,917.608337,46.745193,1.398927,-272.134460,0.139130,0.000000
153.700012,203.961792,-272.134460,-0.002790,0.005482,0.139242,907.267334,46.218403,1.392417,-272.134460,0.138339,0.000000
154.170013,201.123962,-272.134460,-0.002807,0.005457,0.138609,894.644043,45.575340,1.386089,-272.134460,0.137560,0.000000
154.640015,197.010742,-272.267914,-0.002798,0.005414,0.137525,876.347534,44.643272,1.375249,-272.267914,0.136779,0.000000
155.110001,193.352539,-272.312378,-0.002811,0.005383,0.136736,860.075073,43.814312,1.367361,-272.312378,0.135990,0.000000
155.580002,190.718750,-272.312378,-0.002790,0.005361,0.136171,848.359375,43.217484,1.361714,-272.312378,0.135210,0.000000
156.050003,187.246750,-272.356873,-0.002794,0.005329,0.135348,832.915161,42.430721,1.353478,-272.356873,0.134429,0.000000
156.520004,184.248032,-272.401337,-0.002798,0.005303,0.134706,819.576172,41.751202,1.347059,-272.401337,0.133640,0.000000
156.990005,180.385040,-272.490295,-0.002781,0.005265,0.133726,802.392761,40.875832,1.337264,-272.490295,0.132859,0.000000
157.460007,176.902985,-272.490295,-0.002798,0.005237,0.133015,786.903748,40.086788,1.330148,-272.490295,0.132079,0.000000
157.930008,172.797211,-272.490295,-0.002798,0.005203,0.132156,768.640381,39.156410,1.321564,-272.490295,0.131289,0.000000
158.400009,169.455917,-272.579254,-0.002790,0.005174,0.131412,753.777588,38.399258,1.314116,-272.579254,0.130509,0.000000
158.870010,165.751175,-272.579254,-0.002785,0.005142,0.130596,737.298035,37.559753,1.305955,-272.579254,0.129728,0.000000
159.340012,161.883713,-272.668243,-0.002794,0.005113,0.129858,720.094727,36.683372,1.298582,-272.668243,0.128939,0.000000
159.810013,158.161102,-272.668243,-0.002785,0.005082,0.129086,703.535706,35.839817,1.290861,-272.668243,0.128160,0.000000
160.280014,154.422485,-272.668243,-0.002781,0.005052,0.128316,686.905518,34.992634,1.283155,-272.668243,0.127378,0.000000
160.750015,151.074493,-272.712708,-0.002798,0.005024,0.127613,672.012939,34.233971,1.276130,-272.712708,0.126590,0.000000
161.220001,147.138885,-272.801666,-0.002790,0.004986,0.126650,654.506470,33.342148,1.266502,-272.801666,0.125808,0.000000
161.690002,142.387405,-272.846161,-0.002777,0.004948,0.125671,633.370789,32.265450,1.256706,-272.846161,0.125029,0.000000
162.160004,140.356125,-272.890625,-0.002777,0.004932,0.125262,624.335205,31.805153,1.252619,-272.890625,0.124238,0.000000
162.630005,136.486801,-272.846161,-0.002781,0.004896,0.124369,607.123596,30.928350,1.243686,-272.846161,0.123459,0.000000
163.100006,132.885956,-272.890625,-0.002798,0.004865,0.123563,591.106262,30.112389,1.235632,-272.890625,0.122678,0.000000
163.570007,128.483017,-272.935120,-0.002777,0.004826,0.122591,571.520996,29.114668,1.225912,-272.935120,0.121889,0.000000
164.040009,126.681488,-273.068573,-0.002772,0.004813,0.122254,563.507385,28.706434,1.222536,-273.068573,0.121109,0.000000
164.510010,121.515564,-272.979584,-0.002798,0.004767,0.121091,540.528198,27.535820,1.210909,-272.979584,0.120328,0.000000
164.980011,118.449448,-272.979584,-0.002785,0.004740,0.120388,526.889465,26.841028,1.203884,-272.979584,0.119539,0.000000
165.450012,114.690720,-273.113037,-0.002802,0.004704,0.119486,510.169800,25.989288,1.194861,-273.113037,0.118758,0.000000
165.920013,111.529648,-273.157532,-0.002785,0.004679,0.118837,496.108643,25.272980,1.188366,-273.157532,0.117978,0.000000
166.390015,107.468185,-273.157532,-0.002777,0.004644,0.117951,478.042358,24.352638,1.179510,-273.157532,0.117188,0.000000
166.860001,104.440430,-273.201996,-0.002785,0.004618,0.117292,464.574219,23.666540,1.172924,-273.201996,0.116408,0.000000
167.330002,101.107315,-273.201996,-0.002790,0.004589,0.116573,449.747803,22.911245,1.165733,-273.201996,0.115627,0.000000
167.800003,97.836029,-273.290955,-0.002790,0.004562,0.115887,435.196381,22.169962,1.158874,-273.290955,0.114838,0.000000
168.270004,94.675323,-273.335449,-0.002781,0.004531,0.115090,421.136871,21.453735,1.150896,-273.335449,0.114057,0.000000
168.740005,90.196060,-273.335449,-0.002785,0.004491,0.114066,401.212128,20.438721,1.140661,-273.335449,0.113277,0.000000
169.210007,87.587585,-273.335449,-0.002777,0.004470,0.113538,389.609039,19.847631,1.135378,-273.335449,0.112489,0.000000
169.680008,84.228043,-273.335449,-0.002807,0.004437,0.112696,374.665039,19.086346,1.126960,-273.335449,0.111707,0.000000
170.150009,80.732590,-273.468872,-0.002790,0.004407,0.111942,359.116486,18.294266,1.119421,-273.468872,0.110928,0.000000
170.620010,76.155380,-273.513367,-0.002790,0.004365,0.110875,338.756042,17.257057,1.108747,-273.513367,0.110137,0.000000
171.090012,73.793045,-273.513367,-0.002781,0.004344,0.110346,328.247864,16.721743,1.103463,-273.513367,0.109358,0.000000
171.560013,70.888916,-273.513367,-0.002790,0.004315,0.109600,315.329651,16.063658,1.096000,-273.513367,0.108577,0.000000
172.030014,66.897827,-273.602325,-0.002772,0.004281,0.108732,297.576385,15.159264,1.087325,-273.602325,0.107788,0.000000
172.500015,63.664520,-273.646820,-0.002807,0.004250,0.107944,283.193939,14.426586,1.079437,-273.646820,0.107007,0.000000
172.970001,60.147835,-273.691284,-0.002781,0.004219,0.107155,267.550934,13.629694,1.071549,-273.691284,0.106227,0.000000
173.440002,56.731316,-273.646820,-0.002785,0.004187,0.106357,252.353500,12.855499,1.063571,-273.646820,0.105438,0.000000
173.910004,54.359306,-273.691284,-0.002781,0.004165,0.105785,241.802277,12.317995,1.057848,-273.691284,0.104657,0.000000
174.380005,50.693672,-273.780243,-0.002794,0.004130,0.104892,225.496719,11.487350,1.048916,-273.780243,0.103877,0.000000
174.850006,47.369873,-273.780243,-0.002794,0.004098,0.104085,210.711716,10.734167,1.040846,-273.780243,0.103087,0.000000
175.320007,43.706474,-273.824738,-0.002777,0.004060,0.103122,194.416107,9.904029,1.031217,-273.824738,0.102307,0.000000
175.790009,41.647629,-273.869202,-0.002772,0.004038,0.102559,185.257904,9.437488,1.025585,-273.869202,0.101526,0.000000
176.260010,38.351013,-273.913696,-0.002790,0.004003,0.101674,170.593826,8.690464,1.016744,-273.913696,0.100737,0.000000
176.730011,36.311905,-273.913696,-0.002794,0.003974,0.100937,161.523422,8.228395,1.009371,-273.913696,0.099956,0.000000
177.200012,33.347816,-274.047150,-0.002798,0.003939,0.100051,148.338501,7.556723,1.000514,-274.047150,0.099176,0.000000
177.670013,31.244659,-274.091614,-0.002798,0.003913,0.099402,138.983185,7.080141,0.994019,-274.091614,0.098388,0.000000
178.140015,28.705078,-274.047150,-0.002772,0.003885,0.098674,127.686562,6.504664,0.986737,-274.047150,0.097606,0.000000
178.610016,25.842278,-274.091614,-0.002772,0.003852,0.097832,114.952194,5.855944,0.978320,-274.091614,0.096827,0.000000
179.080002,23.567825,-274.091614,-0.002794,0.003821,0.097060,104.834923,5.340546,0.970598,-274.091614,0.096036,0.000000
179.550003,20.592567,-274.180573,-0.002794,0.003790,0.096262,91.600311,4.666343,0.962620,-274.180573,0.095257,0.000000
180.020004,18.014267,-274.225067,-0.002785,0.003758,0.095455,80.131462,4.082091,0.954551,-274.225067,0.094476,0.000000
180.490005,15.502243,-274.269531,-0.002790,0.003727,0.094657,68.957420,3.512858,0.946572,-274.269531,0.093687,0.000000
180.960007,13.194275,-274.225067,-0.002790,0.003699,0.093956,58.691067,2.989866,0.939562,-274.225067,0.092906,0.000000
181.430008,11.628075,-274.269531,-0.002777,0.003675,0.093357,51.724258,2.634959,0.933567,-274.269531,0.092126,0.000000
181.900009,8.507225,-274.358521,-0.002781,0.003635,0.092317,37.842026,1.927765,0.923166,-274.358521,0.091337,0.000000
182.370010,6.723557,-274.402985,-0.002790,0.003608,0.091631,29.907873,1.523580,0.916308,-274.402985,0.090556,0.000000
182.840012,3.255653,-274.402985,-0.002802,0.003564,0.090530,14.481870,0.737742,0.905301,-274.402985,0.089776,0.000000
183.310013,2.159760,-274.402985,-0.002790,0.003543,0.089993,9.607090,0.489408,0.899927,-274.402985,0.088986,0.000000
183.780014,0.896675,-274.491943,-0.002794,0.003519,0.089377,3.988610,0.203189,0.893765,-274.491943,0.088206,0.000000
184.250015,-0.682930,-274.536438,-0.002785,0.003482,0.088439,-3.037824,-0.154754,0.884394,-274.536438,0.087425,0.000000
184.720001,-0.291191,-274.536438,-0.002785,0.003456,0.087772,-1.295283,-0.065985,0.877717,-274.536438,0.086636,0.000000
185.190002,-0.135918,-274.580902,-0.002768,0.003424,0.086974,-0.604592,-0.030799,0.869739,-274.580902,0.085855,0.000000
185.660004,-0.193260,-274.625397,-0.002794,0.003396,0.086264,-0.859664,-0.043793,0.862638,-274.625397,0.085075,0.000000
186.130005,-0.219322,-274.625397,-0.002785,0.003359,0.085308,-0.975594,-0.049699,0.853085,-274.625397,0.084287,0.000000
186.600006,-0.218582,-274.758820,-0.002798,0.003331,0.084606,-0.972302,-0.049531,0.846060,-274.758820,0.083505,0.000000
187.070007,-0.232361,-274.758820,-0.002777,0.003295,0.083696,-1.033593,-0.052654,0.836961,-274.758820,0.082724,0.000000
187.540009,-0.287468,-274.714355,-0.002802,0.003268,0.083012,-1.278721,-0.065141,0.830118,-274.714355,0.081935,0.000000
188.010010,-0.275925,-274.758820,-0.002811,0.003240,0.082291,-1.227374,-0.062525,0.822912,-274.758820,0.081156,0.000000
188.480011,-0.315399,-274.847809,-0.002837,0.003207,0.081468,-1.402966,-0.071470,0.814676,-274.847809,0.080375,0.000000
188.950012,-0.288216,-274.936768,-0.002828,0.003170,0.080530,-1.282047,-0.065311,0.805305,-274.936768,0.079586,0.000000
189.420013,-0.283371,-274.981232,-0.002850,0.003147,0.079932,-1.260497,-0.064213,0.799324,-274.981232,0.078805,0.000000
189.890015,-0.277412,-274.936768,-0.002854,0.003112,0.079056,-1.233992,-0.062863,0.790559,-274.936768,0.078025,0.000000
190.360016,-0.273323,-274.981232,-0.002910,0.003083,0.078302,-1.215802,-0.061936,0.783019,-274.981232,0.077236,0.000000
190.800003,-0.186554,-275.025726,-0.002997,0.003052,0.077522,-0.829833,-0.042274,0.775222,-275.025726,0.077434,0.000000