File: Data/sima compression 500bar/P2-21-500bar-2re_11072024_164636.csv
Time (sec),S:Load (lbs),S:HL1 (DIM),S:LVDT (in),S:Position (in),Ch:Position (mm),Ch:Load (N),Ch:Stress (MPa),Ch:Strain (mm/mm),Ch:HL1 (DIM),Set Point (),Cycles ()
0.010000,-0.088997,-310.165680,-0.015401,-0.008109,-0.205965,-0.395878,-0.020167,-2.059649,-310.165680,-0.205757,0.000000
0.490000,-0.072235,-310.210144,-0.015388,-0.008014,-0.203546,-0.321318,-0.016369,-2.035456,-310.210144,-0.202878,0.000000
0.970000,-0.078941,-310.299103,-0.015164,-0.007715,-0.195949,-0.351149,-0.017888,-1.959486,-310.299103,-0.194883,0.000000
1.450000,-0.143738,-310.343597,-0.014823,-0.007398,-0.187909,-0.639378,-0.032571,-1.879094,-310.343597,-0.186886,0.000000
1.930000,-0.110962,-310.388062,-0.014508,-0.007100,-0.180340,-0.493583,-0.025144,-1.803396,-310.388062,-0.178891,0.000000
2.410000,-0.101654,-310.388062,-0.014155,-0.006774,-0.172057,-0.452180,-0.023035,-1.720568,-310.388062,-0.170896,0.000000
2.890000,-0.059578,-310.432556,-0.013844,-0.006464,-0.164183,-0.265016,-0.013501,-1.641827,-310.432556,-0.162899,0.000000
3.370000,-0.127724,-310.432556,-0.013521,-0.006139,-0.155918,-0.568143,-0.028943,-1.559180,-310.432556,-0.154904,0.000000
3.850000,-0.079315,-310.477051,-0.013206,-0.005829,-0.148051,-0.352812,-0.017973,-1.480515,-310.477051,-0.146907,0.000000
4.330000,-0.087135,-310.477051,-0.012853,-0.005510,-0.139944,-0.387597,-0.019745,-1.399442,-310.477051,-0.138912,0.000000
4.810000,-0.045052,-310.477051,-0.012564,-0.005198,-0.132017,-0.200399,-0.010209,-1.320171,-310.477051,-0.130915,0.000000
5.290000,-0.109848,-310.521515,-0.012193,-0.004882,-0.123995,-0.488628,-0.024892,-1.239947,-310.521515,-0.122920,0.000000
5.770000,-0.074844,-310.654968,-0.011878,-0.004564,-0.115913,-0.332924,-0.016960,-1.159132,-310.654968,-0.114925,0.000000
6.250000,-0.097931,-310.566010,-0.011563,-0.004246,-0.107839,-0.435618,-0.022191,-1.078392,-310.566010,-0.106928,0.000000
6.730000,-0.065910,-310.654968,-0.011232,-0.003936,-0.099982,-0.293184,-0.014935,-0.999818,-310.654968,-0.098933,0.000000
7.210001,-0.057343,-310.610474,-0.010912,-0.003617,-0.091864,-0.255072,-0.012994,-0.918639,-310.610474,-0.090936,0.000000
7.690001,-0.081177,-310.699432,-0.010585,-0.003304,-0.083920,-0.361092,-0.018395,-0.839202,-310.699432,-0.082941,0.000000
8.170000,-0.109100,-310.832886,-0.010257,-0.002988,-0.075890,-0.485303,-0.024722,-0.758902,-310.832886,-0.074927,0.000000
8.650001,-0.077827,-310.788391,-0.009938,-0.002674,-0.067921,-0.346194,-0.017636,-0.679207,-310.788391,-0.066932,0.000000
9.130000,-0.027924,-310.788391,-0.009632,-0.002361,-0.059968,-0.124210,-0.006328,-0.599679,-310.788391,-0.058935,0.000000
9.610001,-0.082291,-310.877380,-0.009278,-0.002046,-0.051980,-0.366047,-0.018647,-0.519802,-310.877380,-0.050940,0.000000
10.090000,-0.103889,-310.921844,-0.008968,-0.001730,-0.043941,-0.462123,-0.023542,-0.439411,-310.921844,-0.042945,0.000000
10.570001,-0.111336,-310.966339,-0.008658,-0.001420,-0.036067,-0.495246,-0.025229,-0.360670,-310.966339,-0.034948,0.000000
11.050000,-0.040962,-310.966339,-0.008343,-0.001111,-0.028219,-0.182209,-0.009282,-0.282187,-310.966339,-0.026953,0.000000
11.530001,-0.055481,-311.010803,-0.008006,-0.000787,-0.019989,-0.246792,-0.012572,-0.199888,-311.010803,-0.018956,0.000000
12.010000,-0.078941,-310.877380,-0.007670,-0.000481,-0.012210,-0.351149,-0.017888,-0.122101,-310.877380,-0.010961,0.000000
12.490001,-0.141129,-311.010803,-0.007330,-0.000159,-0.004041,-0.627771,-0.031980,-0.040408,-311.010803,-0.002966,0.000000
12.970000,-0.018616,-311.055298,-0.007045,0.000150,0.003808,-0.082807,-0.004218,0.038076,-311.055298,0.005031,0.000000
13.450001,-0.049896,-311.099762,-0.006700,0.000470,0.011925,-0.221950,-0.011307,0.119254,-311.099762,0.013026,0.000000
13.930000,-0.018242,-311.055298,-0.006381,0.000782,0.019869,-0.081144,-0.004134,0.198692,-311.055298,0.021023,0.000000
14.410001,0.181351,-311.099762,-0.006092,-0.000000,-0.000000,0.806688,0.041095,-0.000000,-311.099762,0.000156,0.000000
14.890000,0.156769,-311.233215,-0.006088,-0.000000,-0.000009,0.697342,0.035524,-0.000091,-311.233215,0.000173,0.000000
15.370001,0.126236,-311.277710,-0.006105,0.000008,0.000207,0.561526,0.028605,0.002074,-311.277710,0.000970,0.000000
15.850000,0.213371,-311.233215,-0.006079,0.000039,0.000998,0.949123,0.048351,0.009977,-311.233215,0.001777,0.000000
16.330000,0.468819,-311.277710,-0.006053,0.000069,0.001752,2.085410,0.106236,0.017516,-311.277710,0.002575,0.000000
16.810001,0.726501,-311.322174,-0.006015,0.000095,0.002410,3.231640,0.164628,0.024102,-311.322174,0.003373,0.000000
17.290001,1.076157,-311.366669,-0.005971,0.000135,0.003426,4.786983,0.243861,0.034261,-311.366669,0.004171,0.000000
17.770000,1.356552,-311.455627,-0.005971,0.000165,0.004197,6.034245,0.307399,0.041967,-311.455627,0.004978,0.000000
18.250000,1.764671,-311.411133,-0.005941,0.000194,0.004925,7.849650,0.399880,0.049249,-311.411133,0.005776,0.000000
18.730001,2.269981,-311.411133,-0.005911,0.000222,0.005636,10.097382,0.514385,0.056365,-311.411133,0.006574,0.000000
19.210001,2.941002,-311.455627,-0.005868,0.000260,0.006599,13.082230,0.666441,0.065993,-311.455627,0.007371,0.000000
19.690001,3.338318,-311.544586,-0.005864,0.000285,0.007241,14.849580,0.756474,0.072413,-311.544586,0.008178,0.000000
20.170000,4.207809,-311.544586,-0.005842,0.000323,0.008195,18.717272,0.953503,0.081951,-311.544586,0.008976,0.000000
20.650002,4.948456,-311.589050,-0.005825,0.000349,0.008854,22.011831,1.121336,0.088536,-311.589050,0.009774,0.000000
21.130001,5.718155,-311.589050,-0.005773,0.000379,0.009635,25.435623,1.295752,0.096348,-311.589050,0.010572,0.000000
21.610001,6.545937,-311.722504,-0.005764,0.000410,0.010424,29.117781,1.483330,0.104236,-311.722504,0.011377,0.000000
22.090000,7.845886,-311.722504,-0.005747,0.000450,0.011438,34.900246,1.777903,0.114380,-311.722504,0.012175,0.000000
22.570002,8.570152,-311.678009,-0.005721,0.000475,0.012063,38.121941,1.942024,0.120632,-311.678009,0.012973,0.000000
23.050001,9.588966,-311.766998,-0.005717,0.000504,0.012791,42.653854,2.172891,0.127914,-311.766998,0.013771,0.000000
23.530001,10.759331,-311.766998,-0.005674,0.000538,0.013676,47.859894,2.438099,0.136756,-311.766998,0.014578,0.000000
24.010000,12.132645,-311.811462,-0.005665,0.000573,0.014552,53.968700,2.749297,0.145522,-311.811462,0.015376,0.000000
24.490002,13.233749,-311.900421,-0.005622,0.000601,0.015271,58.866657,2.998810,0.152713,-311.900421,0.016174,0.000000
24.970001,14.697540,-311.855957,-0.005605,0.000635,0.016139,65.377922,3.330510,0.161388,-311.855957,0.016971,0.000000
25.450001,15.619911,-311.855957,-0.005579,0.000664,0.016867,69.480835,3.539522,0.168670,-311.855957,0.017778,0.000000
25.930000,17.295212,-311.944916,-0.005558,0.000699,0.017753,76.932945,3.919151,0.177527,-311.944916,0.018576,0.000000
26.410002,18.529999,-311.944916,-0.005523,0.000728,0.018488,82.425552,4.198958,0.184885,-311.944916,0.019374,0.000000
26.890001,20.057098,-312.078339,-0.005506,0.000761,0.019321,89.218430,4.545003,0.193211,-312.078339,0.020172,0.000000
27.370001,21.251297,-312.033875,-0.005493,0.000789,0.020033,94.530487,4.815613,0.200327,-312.033875,0.020977,0.000000
27.850000,22.848030,-312.122833,-0.005441,0.000823,0.020900,101.633110,5.177438,0.209002,-312.122833,0.021775,0.000000
28.330002,24.187454,-312.078339,-0.005433,0.000852,0.021637,107.591171,5.480955,0.216375,-312.078339,0.022573,0.000000
28.810001,25.582359,-312.167328,-0.005402,0.000885,0.022487,113.796021,5.797045,0.224868,-312.167328,0.023371,0.000000
29.290001,26.751984,-312.211792,-0.005389,0.000913,0.023189,118.998764,6.062086,0.231893,-312.211792,0.024178,0.000000
29.770002,28.397125,-312.167328,-0.005346,0.000948,0.024092,126.316719,6.434880,0.240916,-312.167328,0.024976,0.000000
30.250002,29.621857,-312.211792,-0.005316,0.000980,0.024899,131.764603,6.712409,0.248986,-312.211792,0.025774,0.000000
30.730001,30.837654,-312.211792,-0.005282,0.001011,0.025678,137.172729,6.987912,0.256782,-312.211792,0.026571,0.000000
31.210001,31.917534,-312.256287,-0.005269,0.001041,0.026432,141.976288,7.232616,0.264322,-312.256287,0.027378,0.000000
31.690002,33.011940,-312.389709,-0.005226,0.001071,0.027204,146.844437,7.480613,0.272043,-312.389709,0.028176,0.000000
32.170002,34.394188,-312.300751,-0.005208,0.001107,0.028123,152.992996,7.793834,0.281233,-312.300751,0.028974,0.000000
32.650002,35.274475,-312.389709,-0.005178,0.001136,0.028853,156.908707,7.993310,0.288530,-312.389709,0.029781,0.000000
33.130001,36.188644,-312.434204,-0.005139,0.001168,0.029658,160.975128,8.200464,0.296584,-312.434204,0.030579,0.000000
33.610001,37.120323,-312.434204,-0.005109,0.001201,0.030500,165.119446,8.411586,0.305002,-312.434204,0.031377,0.000000
34.090000,38.147324,-312.478668,-0.005083,0.001233,0.031307,169.687775,8.644307,0.313071,-312.478668,0.032175,0.000000
34.570004,39.149384,-312.478668,-0.005040,0.001266,0.032156,174.145157,8.871377,0.321565,-312.478668,0.032980,0.000000
35.050003,39.726189,-312.478668,-0.005027,0.001294,0.032868,176.710907,9.002083,0.328680,-312.478668,0.033778,0.000000
35.530003,40.232613,-312.567657,-0.004980,0.001323,0.033605,178.963593,9.116840,0.336053,-312.567657,0.034576,0.000000
36.010002,41.108429,-312.656616,-0.004945,0.001354,0.034394,182.859421,9.315303,0.343941,-312.656616,0.035374,0.000000
36.490002,42.120171,-312.656616,-0.004915,0.001390,0.035304,187.359879,9.544567,0.353040,-312.656616,0.036181,0.000000
36.970001,42.418068,-312.656616,-0.004889,0.001417,0.035981,188.684982,9.612071,0.359807,-312.656616,0.036978,0.000000
37.450001,43.359795,-312.701080,-0.004846,0.001451,0.036865,192.873993,9.825470,0.368649,-312.701080,0.037776,0.000000
37.930000,43.705727,-312.834534,-0.004812,0.001479,0.037576,194.412781,9.903859,0.375764,-312.834534,0.038574,0.000000
38.410004,44.613571,-312.834534,-0.004781,0.001514,0.038453,198.451080,10.109579,0.384530,-312.834534,0.039381,0.000000
38.890003,44.944984,-312.790039,-0.004756,0.001545,0.039251,199.925278,10.184679,0.392509,-312.790039,0.040179,0.000000
39.370003,45.368370,-312.790039,-0.004712,0.001574,0.039970,201.808594,10.280620,0.399700,-312.790039,0.040977,0.000000
39.850002,46.074020,-312.923492,-0.004700,0.001606,0.040794,204.947479,10.440522,0.407936,-312.923492,0.041775,0.000000
40.330002,45.795113,-312.923492,-0.004639,0.001625,0.041270,203.706833,10.377321,0.412705,-312.923492,0.042580,0.000000
40.810001,47.619362,-313.012451,-0.004622,0.001676,0.042580,211.821503,10.790702,0.425801,-313.012451,0.043378,0.000000
41.290001,47.435043,-312.967957,-0.004575,0.001700,0.043180,211.001617,10.748935,0.431796,-312.967957,0.044176,0.000000
41.770000,48.262451,-312.967957,-0.004536,0.001734,0.044038,214.682098,10.936427,0.440380,-312.967957,0.044974,0.000000
42.250004,47.990990,-313.012451,-0.004514,0.001753,0.044532,213.474579,10.874914,0.445316,-313.012451,0.045781,0.000000
42.730003,49.508041,-313.145905,-0.004458,0.001800,0.045720,220.222763,11.218682,0.457200,-313.145905,0.046578,0.000000
43.210003,49.592567,-313.101410,-0.004445,0.001827,0.046397,220.598755,11.237836,0.463968,-313.101410,0.047376,0.000000
43.690002,50.311615,-313.101410,-0.004411,0.001860,0.047237,223.797241,11.400775,0.472370,-313.101410,0.048174,0.000000
44.170002,50.301933,-313.101410,-0.004372,0.001885,0.047888,223.754181,11.398582,0.478880,-313.101410,0.048981,0.000000
44.650002,50.919327,-313.190369,-0.004329,0.001920,0.048772,226.500473,11.538485,0.487722,-313.190369,0.049779,0.000000
45.130001,51.783981,-313.234863,-0.004294,0.001953,0.049596,230.346649,11.734418,0.495957,-313.234863,0.050577,0.000000
45.610001,52.594635,-313.279327,-0.004255,0.001984,0.050403,233.952621,11.918115,0.504027,-313.279327,0.051375,0.000000
46.090004,52.536171,-313.323822,-0.004238,0.002008,0.050993,233.692566,11.904866,0.509931,-313.323822,0.052180,0.000000
46.570004,53.966454,-313.234863,-0.004195,0.002050,0.052068,240.054779,12.228972,0.520680,-313.234863,0.052978,0.000000
47.050003,54.042046,-313.412781,-0.004161,0.002076,0.052727,240.391022,12.246103,0.527266,-313.412781,0.053776,0.000000
47.530003,54.958450,-313.368286,-0.004139,0.002113,0.053673,244.467392,12.453763,0.536728,-313.368286,0.054574,0.000000
48.010002,54.672470,-313.457275,-0.004100,0.002133,0.054185,243.195297,12.388959,0.541846,-313.457275,0.055381,0.000000
48.490002,56.366020,-313.412781,-0.004057,0.002176,0.055259,250.728577,12.772722,0.552595,-313.412781,0.056178,0.000000
48.970001,56.534332,-313.501740,-0.004031,0.002202,0.055927,251.477264,12.810863,0.559271,-313.501740,0.056976,0.000000
49.450001,57.633949,-313.590698,-0.004005,0.002237,0.056820,256.368622,13.060040,0.568204,-313.590698,0.057774,0.000000
49.930004,57.957169,-313.590698,-0.003971,0.002266,0.057549,257.806366,13.133282,0.575486,-313.590698,0.058581,0.000000
50.410004,59.234406,-313.590698,-0.003941,0.002303,0.058502,263.487793,13.422708,0.585024,-313.590698,0.059379,0.000000
50.890003,60.072243,-313.590698,-0.003893,0.002332,0.059240,267.214691,13.612565,0.592397,-313.590698,0.060177,0.000000
51.370003,61.368843,-313.724152,-0.003876,0.002367,0.060133,272.982239,13.906379,0.601329,-313.724152,0.060975,0.000000
51.850002,61.380386,-313.679657,-0.003846,0.002390,0.060698,273.033600,13.908994,0.606976,-313.679657,0.061782,0.000000
52.330002,63.258270,-313.724152,-0.003824,0.002430,0.061729,281.386841,14.334529,0.617286,-313.724152,0.062579,0.000000
52.810001,64.010834,-313.679657,-0.003786,0.002458,0.062431,284.734406,14.505062,0.624311,-313.679657,0.063377,0.000000
53.290001,65.423981,-313.768616,-0.003777,0.002491,0.063282,291.020386,14.825286,0.632819,-313.768616,0.064175,0.000000
53.770004,65.723740,-313.768616,-0.003751,0.002512,0.063801,292.353790,14.893212,0.638012,-313.768616,0.064981,0.000000
54.250004,67.968033,-313.813110,-0.003729,0.002555,0.064885,302.336914,15.401776,0.648852,-313.813110,0.065778,0.000000
54.730003,69.086639,-313.857605,-0.003686,0.002586,0.065675,307.312714,15.655256,0.656755,-313.857605,0.066576,0.000000
55.210003,70.225723,-313.902069,-0.003652,0.002616,0.066446,312.379608,15.913377,0.664461,-313.902069,0.067374,0.000000
55.690002,70.796951,-313.902069,-0.003648,0.002639,0.067018,314.920563,16.042818,0.670184,-313.902069,0.068181,0.000000
56.170002,72.985382,-313.991028,-0.003609,0.002682,0.068121,324.655182,16.538725,0.681205,-313.991028,0.068979,0.000000
56.650002,73.732361,-314.035522,-0.003600,0.002712,0.068874,327.977936,16.707991,0.688745,-314.035522,0.069777,0.000000
57.130001,75.482513,-314.079987,-0.003557,0.002742,0.069656,335.763000,17.104582,0.696557,-314.079987,0.070575,0.000000
57.610004,76.252197,-313.991028,-0.003518,0.002770,0.070349,339.186707,17.278996,0.703491,-313.991028,0.071382,0.000000
58.090004,78.187042,-314.079987,-0.003518,0.002806,0.071277,347.793335,17.717438,0.712771,-314.079987,0.072179,0.000000
58.570004,79.170853,-314.168945,-0.003479,0.002837,0.072058,352.169556,17.940372,0.720583,-314.168945,0.072977,0.000000
59.050003,80.598907,-314.213440,-0.003475,0.002867,0.072829,358.521851,18.263973,0.728289,-314.213440,0.073783,0.000000
59.530003,81.669479,-314.168945,-0.003432,0.002892,0.073462,363.283997,18.506569,0.734618,-314.168945,0.074581,0.000000
60.010002,83.868332,-314.213440,-0.003415,0.002933,0.074494,373.064972,19.004835,0.744943,-314.213440,0.075378,0.000000
60.490002,85.127701,-314.213440,-0.003385,0.002963,0.075248,378.666931,19.290213,0.752483,-314.213440,0.076176,0.000000
60.970001,86.601547,-314.346893,-0.003350,0.002994,0.076055,385.222931,19.624191,0.760552,-314.346893,0.076983,0.000000
61.450005,87.460983,-314.391357,-0.003337,0.003019,0.076680,389.045898,19.818941,0.766805,-314.391357,0.077781,0.000000
61.930004,89.538452,-314.346893,-0.003307,0.003058,0.077669,398.286926,20.289703,0.776691,-314.346893,0.078579,0.000000
62.410004,90.322296,-314.302399,-0.003281,0.003083,0.078302,401.773651,20.467325,0.783019,-314.302399,0.079377,0.000000
62.890003,92.703995,-314.435852,-0.003260,0.003124,0.079342,412.367950,21.007027,0.793420,-314.435852,0.080184,0.000000
63.370003,93.399948,-314.480316,-0.003203,0.003146,0.079907,415.463715,21.164730,0.799067,-314.480316,0.080982,0.000000
63.850002,94.839539,-314.480316,-0.003221,0.003179,0.080738,421.867340,21.490946,0.807379,-314.480316,0.081779,0.000000
64.330002,96.325684,-314.480316,-0.003199,0.003210,0.081528,428.478027,21.827713,0.815282,-314.480316,0.082577,0.000000
64.810005,98.656738,-314.569275,-0.003165,0.003249,0.082517,438.847076,22.355936,0.825168,-314.569275,0.083384,0.000000
65.290001,99.546707,-314.569275,-0.003126,0.003272,0.083115,442.805878,22.557606,0.831148,-314.569275,0.084182,0.000000
65.770004,101.015717,-314.747223,-0.003139,0.003304,0.083922,449.340363,22.890490,0.839217,-314.747223,0.084980,0.000000
66.250000,102.758041,-314.613770,-0.003117,0.003336,0.084745,457.090607,23.285305,0.847453,-314.613770,0.085778,0.000000
66.730003,104.792313,-314.613770,-0.003096,0.003372,0.085639,466.139496,23.746279,0.856385,-314.613770,0.086583,0.000000
67.210007,106.134720,-314.658234,-0.003074,0.003400,0.086358,472.110809,24.050470,0.863577,-314.658234,0.087381,0.000000
67.690002,108.085571,-314.791687,-0.003048,0.003434,0.087234,480.788635,24.492540,0.872343,-314.791687,0.088179,0.000000
68.170006,109.449203,-314.836182,-0.003044,0.003464,0.087979,486.854370,24.801544,0.879791,-314.836182,0.088977,0.000000
68.650002,111.214996,-314.791687,-0.003001,0.003497,0.088812,494.709015,25.201679,0.888118,-314.791687,0.089784,0.000000
69.130005,112.703369,-314.791687,-0.002979,0.003525,0.089532,501.329620,25.538948,0.895324,-314.791687,0.090582,0.000000
69.610001,114.786041,-314.880646,-0.002971,0.003558,0.090373,510.593811,26.010889,0.903727,-314.880646,0.091379,0.000000
70.090004,116.217819,-314.925140,-0.002953,0.003590,0.091189,516.962708,26.335333,0.911887,-314.925140,0.092177,0.000000
70.570000,117.939667,-314.969604,-0.002936,0.003620,0.091952,524.621826,26.725512,0.919518,-314.969604,0.092984,0.000000
71.050003,119.506989,-314.969604,-0.002919,0.003651,0.092724,531.593628,27.080669,0.927239,-314.969604,0.093782,0.000000
71.530006,121.493225,-314.925140,-0.002902,0.003682,0.093531,540.428833,27.530758,0.935308,-314.925140,0.094580,0.000000
72.010002,123.072830,-315.058563,-0.002876,0.003712,0.094276,547.455261,27.888700,0.942757,-315.058563,0.095378,0.000000
72.490005,124.953674,-315.103058,-0.002871,0.003746,0.095152,555.821716,28.314907,0.951523,-315.103058,0.096183,0.000000
72.970001,127.135406,-315.058563,-0.002854,0.003779,0.095976,565.526550,28.809294,0.959759,-315.058563,0.096981,0.000000
73.450005,128.708679,-315.103058,-0.002846,0.003807,0.096687,572.524780,29.165802,0.966874,-315.103058,0.097779,0.000000
73.930000,130.764175,-315.147552,-0.002811,0.003839,0.097520,581.668091,29.631586,0.975201,-315.147552,0.098577,0.000000
74.410004,132.426071,-315.192017,-0.002794,0.003868,0.098248,589.060608,30.008177,0.982483,-315.192017,0.099384,0.000000
74.890007,134.965652,-315.192017,-0.002777,0.003906,0.099202,600.357178,30.583654,0.992021,-315.192017,0.100182,0.000000
75.370003,136.423874,-315.280975,-0.002772,0.003933,0.099895,606.843689,30.914091,0.998955,-315.280975,0.100979,0.000000
75.850006,138.641342,-315.236511,-0.002746,0.003965,0.100719,616.707520,31.416576,1.007191,-315.236511,0.101777,0.000000
76.330002,140.365799,-315.369934,-0.002721,0.003996,0.101500,624.378235,31.807344,1.015003,-315.369934,0.102584,0.000000
76.810005,142.958252,-315.369934,-0.002712,0.004031,0.102384,635.910034,32.394802,1.023844,-315.369934,0.103382,0.000000
77.290001,145.169785,-315.369934,-0.002708,0.004064,0.103234,645.747437,32.895943,1.032338,-315.369934,0.104180,0.000000
77.770004,146.883057,-315.414429,-0.002682,0.004091,0.103920,653.368469,33.284176,1.039196,-315.414429,0.104978,0.000000
78.250000,148.372925,-315.458893,-0.002665,0.004119,0.104631,659.995728,33.621784,1.046311,-315.458893,0.105783,0.000000
78.730003,150.725952,-315.458893,-0.002652,0.004152,0.105464,670.462524,34.154987,1.054638,-315.458893,0.106581,0.000000
79.210007,153.144501,-315.547852,-0.002643,0.004186,0.106322,681.220764,34.703041,1.063222,-315.547852,0.107379,0.000000
79.690002,155.023499,-315.503387,-0.002626,0.004216,0.107076,689.578979,35.128826,1.070762,-315.503387,0.108177,0.000000
80.170006,157.503494,-315.547852,-0.002608,0.004248,0.107909,700.610535,35.690804,1.079089,-315.547852,0.108984,0.000000
80.650002,159.269669,-315.636841,-0.002617,0.004276,0.108602,708.466858,36.091022,1.086023,-315.636841,0.109782,0.000000
81.130005,161.840515,-315.681305,-0.002583,0.004311,0.109495,719.902588,36.673584,1.094955,-315.681305,0.110579,0.000000
81.610001,163.983154,-315.725800,-0.002600,0.004342,0.110284,729.433472,37.159115,1.102843,-315.725800,0.111377,0.000000
82.090004,165.863998,-315.770264,-0.002561,0.004369,0.110970,737.799927,37.585320,1.109701,-315.770264,0.112184,0.000000
82.570007,168.706696,-315.725800,-0.002552,0.004405,0.111880,750.444885,38.229485,1.118800,-315.725800,0.112982,0.000000
83.050003,169.561661,-315.814758,-0.002531,0.004422,0.112314,754.247925,38.423222,1.123145,-315.814758,0.113780,0.000000
83.530006,173.899811,-315.859222,-0.002518,0.004473,0.113624,773.544983,39.406258,1.136241,-315.859222,0.114578,0.000000
84.010002,175.282791,-315.903717,-0.002522,0.004497,0.114222,779.696777,39.719646,1.142221,-315.903717,0.115385,0.000000
84.490005,178.320236,-315.903717,-0.002501,0.004532,0.115124,793.208008,40.407940,1.151244,-315.903717,0.116183,0.000000
84.970001,179.249313,-315.859222,-0.002488,0.004553,0.115644,797.340759,40.618477,1.156437,-315.859222,0.116981,0.000000
85.450005,183.054947,-315.948181,-0.002466,0.004598,0.116790,814.269043,41.480846,1.167897,-315.948181,0.117786,0.000000
85.930000,184.624496,-316.037170,-0.002466,0.004621,0.117362,821.250793,41.836506,1.173620,-316.037170,0.118584,0.000000
86.410004,187.620605,-316.081635,-0.002466,0.004657,0.118290,834.578125,42.515438,1.182901,-316.081635,0.119382,0.000000
86.890007,189.148453,-315.992676,-0.002440,0.004683,0.118958,841.374329,42.861652,1.189577,-315.992676,0.120179,0.000000
87.370003,191.330933,-316.126129,-0.002445,0.004711,0.119660,851.082520,43.356209,1.196602,-316.126129,0.120986,0.000000
87.850006,194.239899,-316.215088,-0.002419,0.004749,0.120622,864.022217,44.015388,1.206216,-316.215088,0.121784,0.000000
88.330002,196.967529,-316.215088,-0.002414,0.004781,0.121438,876.155334,44.633480,1.214376,-316.215088,0.122582,0.000000
88.810005,198.755676,-316.215088,-0.002406,0.004804,0.122019,884.109375,45.038677,1.220190,-316.215088,0.123380,0.000000
89.290001,202.351654,-316.170593,-0.002384,0.004847,0.123111,900.105103,45.853539,1.231105,-316.170593,0.124187,0.000000
89.770004,204.250763,-316.304047,-0.002389,0.004872,0.123752,908.552795,46.283886,1.237524,-316.304047,0.124985,0.000000
90.250008,207.096436,-316.304047,-0.002363,0.004908,0.124673,921.210937,46.928722,1.246729,-316.304047,0.125783,0.000000
90.730003,208.441071,-316.393005,-0.002350,0.004927,0.125141,927.192200,47.233425,1.251407,-316.393005,0.126581,0.000000
91.210007,212.269806,-316.348511,-0.002345,0.004973,0.126302,944.223267,48.101028,1.263019,-316.348511,0.127386,0.000000
91.690002,214.171509,-316.393005,-0.002337,0.004997,0.126918,952.682434,48.531956,1.269181,-316.393005,0.128184,0.000000
92.170006,217.185883,-316.481964,-0.002328,0.005034,0.127863,966.091064,49.215027,1.278628,-316.481964,0.128982,0.000000
92.650002,218.978851,-316.526459,-0.002307,0.005060,0.128514,974.066589,49.621315,1.285138,-316.526459,0.129780,0.000000
93.130005,220.356995,-316.526459,-0.002302,0.005066,0.128679,980.196838,49.933609,1.286789,-316.526459,0.022597,0.000000
93.610008,219.760437,-316.526459,-0.002272,0.005079,0.129000,977.543274,49.798424,1.289998,-316.526459,982.000671,0.000000
94.090004,219.561218,-316.526459,-0.002289,0.005086,0.129172,976.657104,49.753284,1.291724,-316.526459,982.000671,0.000000
94.570007,219.572021,-316.570923,-0.002289,0.005094,0.129381,976.705139,49.755730,1.293813,-316.570923,982.000671,0.000000
95.050003,219.816315,-316.659882,-0.002268,0.005104,0.129633,977.791809,49.811089,1.296327,-316.659882,982.000671,0.000000
95.530006,219.449524,-316.659882,-0.002285,0.005108,0.129754,976.160217,49.727974,1.297538,-316.659882,982.000671,0.000000
96.010002,220.022614,-316.659882,-0.002259,0.005122,0.130100,978.709473,49.857838,1.301005,-316.659882,982.000671,0.000000
96.490005,219.452484,-316.704376,-0.002251,0.005123,0.130119,976.173401,49.728642,1.301186,-316.704376,982.000671,0.000000
96.970001,219.776093,-316.748840,-0.002216,0.005133,0.130387,977.612915,49.801975,1.303866,-316.748840,982.000671,0.000000
97.450005,219.633484,-316.837830,-0.002238,0.005139,0.130535,976.978516,49.769661,1.305350,-316.837830,982.000671,0.000000
97.930008,220.019623,-316.882294,-0.002207,0.005149,0.130786,978.696167,49.857159,1.307863,-316.882294,982.000671,0.000000
98.410004,219.442810,-316.793335,-0.002216,0.005149,0.130795,976.130371,49.726452,1.307954,-316.793335,982.000671,0.000000
98.890007,219.923920,-316.926788,-0.002203,0.005159,0.131029,978.270447,49.835472,1.310285,-316.926788,982.000671,0.000000
99.370003,220.103790,-316.882294,-0.002186,0.005169,0.131298,979.070557,49.876232,1.312980,-316.882294,982.000671,0.000000
99.850006,219.585815,-316.926788,-0.002186,0.005170,0.131307,976.766479,49.758858,1.313071,-316.926788,982.000671,0.000000
100.330002,219.453979,-317.015747,-0.002186,0.005175,0.131445,976.180054,49.728985,1.314449,-317.015747,982.000671,0.000000
100.810005,219.360138,-317.015747,-0.002164,0.005180,0.131566,975.762634,49.707718,1.315660,-317.015747,982.000671,0.000000
101.290009,219.920197,-317.060211,-0.002151,0.005191,0.131861,978.253906,49.834625,1.318612,-317.060211,982.000671,0.000000
101.770004,219.428284,-317.104706,-0.002164,0.005192,0.131887,976.065735,49.723164,1.318869,-317.104706,982.000671,0.000000
102.250008,219.560486,-317.104706,-0.002156,0.005199,0.132061,976.653809,49.753117,1.320610,-317.104706,982.000671,0.000000
102.730003,219.590637,-317.104706,-0.002169,0.005205,0.132200,976.787964,49.759953,1.322003,-317.104706,982.000671,0.000000
103.210007,219.821899,-317.193665,-0.002147,0.005213,0.132399,977.816650,49.812355,1.323987,-317.193665,982.000671,0.000000
103.690002,219.541870,-317.193665,-0.002134,0.005216,0.132494,976.570984,49.748898,1.324940,-317.193665,982.000671,0.000000
104.170006,219.640533,-317.238129,-0.002126,0.005222,0.132642,977.009888,49.771255,1.326424,-317.238129,982.000671,0.000000
104.650002,219.869171,-317.282623,-0.002121,0.005229,0.132824,978.026917,49.823067,1.328241,-317.282623,982.000671,0.000000
105.130005,219.481903,-317.282623,-0.002108,0.005231,0.132859,976.304260,49.735310,1.328589,-317.282623,982.000671,0.000000
105.610008,219.532562,-317.327118,-0.002100,0.005236,0.132998,976.529602,49.746792,1.329982,-317.327118,982.000671,0.000000
106.090004,219.517670,-317.327118,-0.002095,0.005241,0.133119,976.463379,49.743412,1.331193,-317.327118,982.000671,0.000000
106.570007,219.533691,-317.460541,-0.002100,0.005246,0.133249,976.534607,49.747044,1.332495,-317.460541,982.000671,0.000000
107.050003,219.581726,-317.416077,-0.002095,0.005252,0.133405,976.748291,49.757931,1.334054,-317.416077,982.000671,0.000000
107.530006,219.471863,-317.460541,-0.002091,0.005255,0.133483,976.259583,49.733036,1.334826,-317.460541,982.000671,0.000000
108.010002,219.444305,-317.416077,-0.002074,0.005260,0.133596,976.137024,49.726791,1.335962,-317.416077,982.000671,0.000000
108.490005,219.681885,-317.549500,-0.002070,0.005266,0.133769,977.193848,49.780624,1.337688,-317.549500,982.000671,0.000000
108.970009,220.067657,-317.593994,-0.002065,0.005274,0.133952,978.909851,49.868042,1.339520,-317.593994,982.000671,0.000000
109.450005,219.712799,-317.593994,-0.002078,0.005274,0.133952,977.331360,49.787632,1.339520,-317.593994,982.000671,0.000000
109.930008,220.361847,-317.638458,-0.002035,0.005283,0.134194,980.218445,49.934708,1.341942,-317.638458,982.000671,0.000000
110.410004,219.912384,-317.638458,-0.002039,0.005283,0.134194,978.219116,49.832859,1.341942,-317.638458,982.000671,0.000000
110.890007,219.512085,-317.727448,-0.002035,0.005283,0.134194,976.438538,49.742149,1.341942,-317.727448,982.000671,0.000000
111.370003,220.431091,-317.682953,-0.002035,0.005305,0.134741,980.526489,49.950397,1.347407,-317.682953,982.000671,0.000000
111.850006,220.202820,-317.727448,-0.002022,0.005277,0.134047,979.511047,49.898674,1.340474,-317.727448,982.000671,0.000000
112.330002,219.764923,-317.727448,-0.002013,0.005277,0.134047,977.563171,49.799442,1.340474,-317.727448,982.000671,0.000000
112.810005,220.034149,-317.816406,-0.002026,0.005304,0.134715,978.760803,49.860451,1.347150,-317.816406,982.000671,0.000000
113.290009,219.728424,-317.860870,-0.002018,0.005304,0.134715,977.400818,49.791172,1.347150,-317.860870,982.000671,0.000000
113.770004,219.565338,-317.816406,-0.002018,0.005307,0.134792,976.675415,49.754215,1.347922,-317.816406,982.000671,0.000000
114.250008,219.257385,-317.860870,-0.002005,0.005307,0.134801,975.305542,49.684433,1.348013,-317.860870,982.000671,0.000000
114.730003,220.303375,-317.949829,-0.002001,0.005321,0.135157,979.958374,49.921459,1.351571,-317.949829,982.000671,0.000000
115.210007,219.968994,-317.994324,-0.001992,0.005321,0.135157,978.470947,49.845688,1.351571,-317.994324,982.000671,0.000000
115.690002,219.614105,-317.994324,-0.001992,0.005322,0.135166,976.892334,49.765266,1.351662,-317.994324,982.000671,0.000000
116.170006,219.874390,-318.038788,-0.001979,0.005329,0.135357,978.050110,49.824249,1.353569,-318.038788,982.000671,0.000000
116.650009,219.598846,-318.038788,-0.001970,0.005329,0.135364,976.824463,49.761806,1.353645,-318.038788,982.000671,0.000000
117.130005,219.539276,-318.038788,-0.001957,0.005333,0.135469,976.559448,49.748310,1.354690,-318.038788,982.000671,0.000000
117.610008,219.757477,-318.127777,-0.001975,0.005338,0.135590,977.530090,49.797756,1.355901,-318.127777,982.000671,0.000000
118.090004,219.470001,-318.127777,-0.001966,0.005339,0.135599,976.251343,49.732613,1.355992,-318.127777,982.000671,0.000000
118.570007,219.655823,-318.172241,-0.001949,0.005344,0.135738,977.077881,49.774723,1.357384,-318.172241,982.000671,0.000000
119.050003,220.160004,-318.261200,-0.001979,0.005352,0.135937,979.320618,49.888969,1.359368,-318.261200,982.000671,0.000000
119.530006,219.861359,-318.216736,-0.001953,0.005352,0.135937,977.992187,49.821293,1.359368,-318.216736,982.000671,0.000000
120.010002,219.586548,-318.305695,-0.001962,0.005353,0.135964,976.769775,49.759022,1.359640,-318.305695,982.000671,0.000000
120.490005,219.419373,-318.305695,-0.001944,0.005355,0.136025,976.026123,49.721142,1.360246,-318.305695,982.000671,0.000000
120.970009,219.872894,-318.305695,-0.001940,0.005364,0.136250,978.043457,49.823910,1.362502,-318.305695,982.000671,0.000000
121.450005,219.711670,-318.394653,-0.001927,0.005364,0.136250,977.326294,49.787376,1.362502,-318.394653,982.000671,0.000000
121.930008,219.456238,-318.394653,-0.001940,0.005365,0.136276,976.190125,49.729492,1.362759,-318.394653,982.000671,0.000000
122.410004,219.563843,-318.483612,-0.001927,0.005370,0.136397,976.668762,49.753880,1.363970,-318.483612,982.000671,0.000000
122.890007,219.511719,-318.394653,-0.001932,0.005373,0.136467,976.436890,49.742065,1.364667,-318.394653,982.000671,0.000000
123.370003,219.885193,-318.528076,-0.001932,0.005379,0.136623,978.098206,49.826698,1.366226,-318.528076,982.000671,0.000000
123.850006,219.673676,-318.483612,-0.001910,0.005379,0.136623,977.157288,49.778767,1.366226,-318.483612,982.000671,0.000000
124.330009,219.527344,-318.572571,-0.001893,0.005381,0.136683,976.506409,49.745609,1.366832,-318.572571,982.000671,0.000000
124.810005,219.474091,-318.617065,-0.001901,0.005384,0.136744,976.269531,49.733540,1.367437,-318.617065,982.000671,0.000000
125.290009,219.427917,-318.617065,-0.001901,0.005386,0.136797,976.064148,49.723076,1.367967,-318.617065,982.000671,0.000000
125.770004,219.418610,-318.617065,-0.001897,0.005389,0.136874,976.022705,49.720966,1.368739,-318.617065,982.000671,0.000000
126.250008,219.614868,-318.706024,-0.001888,0.005394,0.136995,976.895752,49.765442,1.369950,-318.706024,982.000671,0.000000
126.730003,219.513184,-318.794983,-0.001906,0.005396,0.137048,976.443420,49.742397,1.370480,-318.794983,982.000671,0.000000
127.210007,219.486755,-318.794983,-0.001897,0.005398,0.137099,976.325867,49.736408,1.370995,-318.794983,982.000671,0.000000
127.690002,219.860260,-318.839447,-0.001893,0.005405,0.137281,977.987305,49.821049,1.372812,-318.839447,982.000671,0.000000
128.170013,219.619690,-318.794983,-0.001906,0.005403,0.137246,976.917175,49.766533,1.372463,-318.794983,982.000671,0.000000
128.650009,219.362762,-318.839447,-0.001880,0.005403,0.137246,975.774292,49.708313,1.372463,-318.839447,982.000671,0.000000
129.130005,219.087952,-318.883942,-0.001884,0.005403,0.137246,974.551880,49.646042,1.372463,-318.883942,982.000671,0.000000
129.610001,220.240082,-318.883942,-0.001845,0.005360,0.136137,979.676819,49.907116,1.361366,-318.883942,982.000671,0.000000
130.090012,219.917206,-318.928406,-0.001832,0.005382,0.136692,978.240601,49.833950,1.366922,-318.928406,982.000671,0.000000
130.570007,219.690063,-318.928406,-0.001845,0.005390,0.136918,977.230225,49.782478,1.369178,-318.928406,982.000671,0.000000
131.050003,219.662140,-319.017395,-0.001841,0.005410,0.137420,977.106018,49.776154,1.374205,-319.017395,982.000671,0.000000
131.529999,219.687836,-319.017395,-0.001837,0.005419,0.137637,977.220276,49.781975,1.376369,-319.017395,982.000671,0.000000
132.010010,219.643890,-319.017395,-0.001837,0.005421,0.137698,977.024841,49.772018,1.376975,-319.017395,982.000671,0.000000
132.490005,219.667358,-319.106354,-0.001845,0.005429,0.137888,977.129211,49.777336,1.378883,-319.106354,982.000671,0.000000
132.970001,219.824860,-319.061859,-0.001837,0.005429,0.137888,977.829834,49.813023,1.378883,-319.061859,982.000671,0.000000
133.450012,219.613739,-319.150818,-0.001841,0.005429,0.137888,976.890686,49.765186,1.378883,-319.150818,982.000671,0.000000
133.930008,219.625275,-319.239777,-0.001845,0.005432,0.137967,976.942017,49.767799,1.379670,-319.239777,982.000671,0.000000
134.410004,219.540009,-319.284271,-0.001858,0.005433,0.138009,976.562744,49.748474,1.380094,-319.284271,982.000671,0.000000
134.889999,219.363495,-319.239777,-0.001828,0.005434,0.138018,975.777588,49.708477,1.380185,-319.239777,982.000671,0.000000
135.370010,219.255127,-319.284271,-0.001832,0.005436,0.138062,975.295532,49.683922,1.380624,-319.284271,982.000671,0.000000
135.850006,219.776093,-319.284271,-0.001832,0.005444,0.138279,977.612915,49.801975,1.382789,-319.284271,982.000671,0.000000
136.330002,219.622314,-319.373230,-0.001837,0.005444,0.138279,976.928833,49.767128,1.382789,-319.373230,982.000671,0.000000
136.810013,219.494568,-319.417725,-0.001841,0.005445,0.138314,976.360596,49.738178,1.383137,-319.417725,982.000671,0.000000
137.290009,219.705353,-319.373230,-0.001828,0.005450,0.138435,977.298218,49.785942,1.384348,-319.373230,982.000671,0.000000
137.770004,219.564209,-319.417725,-0.001815,0.005451,0.138453,976.670410,49.753960,1.384530,-319.417725,982.000671,0.000000
138.250000,219.663269,-319.462189,-0.001824,0.005454,0.138530,977.111023,49.776405,1.385302,-319.462189,982.000671,0.000000
138.730011,219.677795,-319.551147,-0.001811,0.005457,0.138609,977.175659,49.779701,1.386089,-319.551147,982.000671,0.000000
139.210007,219.716888,-319.551147,-0.001837,0.005459,0.138669,977.349548,49.788559,1.386695,-319.551147,982.000671,0.000000
139.690002,219.710175,-319.595642,-0.001811,0.005461,0.138712,977.319641,49.787037,1.387119,-319.595642,982.000671,0.000000
140.170013,219.632355,-319.595642,-0.001798,0.005462,0.138747,976.973511,49.769402,1.387467,-319.595642,982.000671,0.000000
140.650009,219.620819,-319.640106,-0.001807,0.005465,0.138807,976.922180,49.766788,1.388072,-319.640106,982.000671,0.000000
141.130005,219.609650,-319.684601,-0.001802,0.005467,0.138860,976.872498,49.764256,1.388602,-319.684601,982.000671,0.000000
141.610001,219.629761,-319.729065,-0.001781,0.005469,0.138921,976.961975,49.768814,1.389208,-319.729065,982.000671,0.000000
142.090012,219.621185,-319.729065,-0.001794,0.005471,0.138972,976.923828,49.766869,1.389723,-319.729065,982.000671,0.000000
142.570007,219.553040,-319.773560,-0.001781,0.005472,0.139000,976.620667,49.751431,1.389995,-319.773560,982.000671,0.000000
143.050003,219.959656,-319.818024,-0.001785,0.005479,0.139172,978.429443,49.843571,1.391721,-319.818024,982.000671,0.000000
143.530014,219.823395,-319.862518,-0.001768,0.005479,0.139163,977.823303,49.812695,1.391630,-319.862518,982.000671,0.000000
144.010010,219.691559,-319.818024,-0.001772,0.005479,0.139172,977.236877,49.782822,1.391721,-319.818024,982.000671,0.000000
144.490005,219.746674,-319.862518,-0.001794,0.005483,0.139258,977.481995,49.795307,1.392584,-319.862518,982.000671,0.000000
144.970001,219.599945,-319.951477,-0.001772,0.005483,0.139258,976.829346,49.762058,1.392584,-319.951477,982.000671,0.000000
145.450012,219.901581,-319.951477,-0.001772,0.005489,0.139414,978.171082,49.830410,1.394143,-319.951477,982.000671,0.000000
145.930008,219.802521,-320.040436,-0.001776,0.005489,0.139414,977.730469,49.807961,1.394143,-320.040436,982.000671,0.000000
146.410004,219.618591,-320.040436,-0.001763,0.005489,0.139414,976.912292,49.766281,1.394143,-320.040436,982.000671,0.000000
146.889999,219.481171,-319.995972,-0.001755,0.005490,0.139442,976.301025,49.735142,1.394416,-319.995972,982.000671,0.000000
147.370010,219.635345,-320.084930,-0.001768,0.005494,0.139537,976.986816,49.770081,1.395370,-320.084930,982.000671,0.000000
147.850006,219.535553,-320.084930,-0.001763,0.005495,0.139572,976.542908,49.747467,1.395718,-320.084930,982.000671,0.000000
148.330002,219.584320,-320.173889,-0.001755,0.005498,0.139640,976.759827,49.758518,1.396399,-320.173889,982.000671,0.000000
148.810013,219.498291,-320.173889,-0.001759,0.005498,0.139649,976.377136,49.739025,1.396490,-320.173889,982.000671,0.000000
149.290009,219.488251,-320.218353,-0.001759,0.005500,0.139700,976.332520,49.736748,1.397005,-320.218353,982.000671,0.000000
149.770004,220.136536,-320.173889,-0.001742,0.005507,0.139865,979.216187,49.883652,1.398655,-320.173889,982.000671,0.000000
150.250000,219.883698,-320.262848,-0.001733,0.005506,0.139858,978.091553,49.826355,1.398579,-320.262848,982.000671,0.000000
150.730011,219.735138,-320.307343,-0.001755,0.005506,0.139858,977.430725,49.792694,1.398579,-320.307343,982.000671,0.000000
151.210007,219.542236,-320.351807,-0.001733,0.005506,0.139858,976.572632,49.748981,1.398579,-320.351807,982.000671,0.000000
151.690002,219.318451,-320.351807,-0.001755,0.005507,0.139865,975.577209,49.698273,1.398655,-320.351807,982.000671,0.000000
152.170013,219.965637,-320.396301,-0.001720,0.005515,0.140074,978.455994,49.844929,1.400744,-320.396301,982.000671,0.000000
152.650009,219.817413,-320.351807,-0.001733,0.005515,0.140074,977.796692,49.811340,1.400744,-320.351807,982.000671,0.000000
153.130005,219.645020,-320.440765,-0.001725,0.005515,0.140074,977.029846,49.772274,1.400744,-320.440765,982.000671,0.000000
153.610001,219.499054,-320.529724,-0.001729,0.005503,0.139779,976.380554,49.739197,1.397792,-320.529724,0.140074,0.000000
154.090012,219.212311,-320.574219,-0.001720,0.005493,0.139528,975.105042,49.674217,1.395279,-320.574219,0.139319,0.000000
154.570007,218.853363,-320.440765,-0.001720,0.005468,0.138877,973.508362,49.592884,1.388769,-320.440765,0.138521,0.000000
155.050003,217.868805,-320.529724,-0.001716,0.005440,0.138174,969.128845,49.369774,1.381744,-320.529724,0.137723,0.000000
155.530014,216.229980,-320.574219,-0.001677,0.005410,0.137411,961.838989,48.998413,1.374114,-320.574219,0.136925,0.000000
156.010010,215.324005,-320.663177,-0.001686,0.005384,0.136744,957.809021,48.793118,1.367437,-320.663177,0.136120,0.000000
156.490005,214.740875,-320.707672,-0.001681,0.005351,0.135920,955.215149,48.660976,1.359201,-320.707672,0.135322,0.000000
156.970001,214.380402,-320.707672,-0.001677,0.005324,0.135227,953.611633,48.579292,1.352267,-320.707672,0.134524,0.000000
157.450012,213.727631,-320.707672,-0.001673,0.005282,0.134159,950.708008,48.431370,1.341594,-320.707672,0.133726,0.000000
157.930008,213.262177,-320.752136,-0.001673,0.005258,0.133552,948.637512,48.325901,1.335523,-320.752136,0.132919,0.000000
158.410004,212.493988,-320.796631,-0.001664,0.005237,0.133024,945.220459,48.151825,1.330239,-320.796631,0.132122,0.000000
158.890015,211.425262,-320.885590,-0.001660,0.005203,0.132156,940.466553,47.909649,1.321564,-320.885590,0.131324,0.000000
159.370010,208.801147,-320.841095,-0.001669,0.005160,0.131072,928.793884,47.315014,1.310724,-320.841095,0.130526,0.000000
159.850006,206.820496,-320.885590,-0.001660,0.005134,0.130405,919.983521,46.866196,1.304048,-320.885590,0.129719,0.000000
160.330002,203.800568,-320.885590,-0.001651,0.005101,0.129563,906.550171,46.181870,1.295630,-320.885590,0.128921,0.000000
160.810013,200.773560,-320.974548,-0.001656,0.005073,0.128861,893.085388,45.495937,1.288605,-320.974548,0.128123,0.000000
161.290009,196.855072,-321.019012,-0.001673,0.005039,0.127985,875.655090,44.607994,1.279855,-321.019012,0.127325,0.000000
161.770004,193.526825,-321.019012,-0.001660,0.005009,0.127222,860.850342,43.853806,1.272224,-321.019012,0.126520,0.000000
162.250015,190.119598,-320.974548,-0.001660,0.004978,0.126432,845.694214,43.081718,1.264321,-320.974548,0.125722,0.000000
162.730011,186.925766,-321.063507,-0.001651,0.004949,0.125695,831.487305,42.357983,1.256948,-321.063507,0.124924,0.000000
163.210007,183.455994,-321.152466,-0.001647,0.004912,0.124759,816.053040,41.571720,1.247592,-321.152466,0.124126,0.000000
163.690002,180.375732,-321.196960,-0.001669,0.004886,0.124108,802.351318,40.873726,1.241082,-321.196960,0.123319,0.000000
164.170013,177.224350,-321.196960,-0.001664,0.004857,0.123380,788.333252,40.159611,1.233800,-321.196960,0.122522,0.000000
164.650009,173.259689,-321.196960,-0.001651,0.004823,0.122496,770.697571,39.261204,1.224959,-321.196960,0.121724,0.000000
165.130005,169.155029,-321.196960,-0.001664,0.004786,0.121559,752.439148,38.331078,1.215587,-321.196960,0.120926,0.000000
165.610001,166.304901,-321.241425,-0.001656,0.004763,0.120986,739.761169,37.685226,1.209864,-321.241425,0.120119,0.000000
166.090012,162.582657,-321.330383,-0.001664,0.004729,0.120119,723.203796,36.841755,1.201189,-321.330383,0.119321,0.000000
166.570007,158.223297,-321.330383,-0.001664,0.004696,0.119286,703.812378,35.853909,1.192863,-321.330383,0.118523,0.000000
167.050003,154.911407,-321.374878,-0.001651,0.004661,0.118393,689.080383,35.103424,1.183930,-321.374878,0.117725,0.000000
167.530014,150.931870,-321.374878,-0.001669,0.004636,0.117751,671.378479,34.201649,1.177511,-321.374878,0.116918,0.000000
168.010010,147.768936,-321.419342,-0.001664,0.004609,0.117076,657.309082,33.484921,1.170759,-321.419342,0.116122,0.000000
168.490005,143.110184,-321.508301,-0.001656,0.004570,0.116078,636.585876,32.429230,1.160782,-321.508301,0.115324,0.000000
168.970001,140.032150,-321.508301,-0.001660,0.004544,0.115420,622.894104,31.731739,1.154196,-321.508301,0.114526,0.000000
169.450012,135.679489,-321.419342,-0.001664,0.004507,0.114473,603.532532,30.745413,1.144734,-321.419342,0.113719,0.000000
169.930008,132.608170,-321.508301,-0.001664,0.004480,0.113780,589.870605,30.049440,1.137800,-321.508301,0.112922,0.000000
170.410004,129.559174,-321.552795,-0.001651,0.004453,0.113112,576.307983,29.358528,1.131123,-321.552795,0.112124,0.000000
170.890015,125.555435,-321.641754,-0.001656,0.004420,0.112261,558.498474,28.451267,1.122615,-321.641754,0.111326,0.000000
171.370010,121.527100,-321.686249,-0.001673,0.004383,0.111326,540.579529,27.538433,1.113259,-321.686249,0.110519,0.000000
171.850006,118.204056,-321.686249,-0.001664,0.004354,0.110579,525.797913,26.785421,1.105795,-321.686249,0.109721,0.000000
172.330002,114.610291,-321.686249,-0.001664,0.004321,0.109756,509.812042,25.971064,1.097559,-321.686249,0.108923,0.000000
172.810013,110.619202,-321.686249,-0.001656,0.004286,0.108872,492.058777,25.066669,1.088717,-321.686249,0.108116,0.000000
173.290009,106.924149,-321.730713,-0.001664,0.004258,0.108144,475.622375,24.229359,1.081435,-321.730713,0.107318,0.000000
173.770004,103.751160,-321.819672,-0.001656,0.004227,0.107362,461.508209,23.510349,1.073623,-321.819672,0.106521,0.000000
174.250015,100.343948,-321.864166,-0.001673,0.004199,0.106643,446.352173,22.738264,1.066432,-321.864166,0.105723,0.000000
174.730011,96.898026,-321.819672,-0.001651,0.004170,0.105913,431.023956,21.957405,1.059135,-321.819672,0.104917,0.000000
175.210007,92.642181,-321.819672,-0.001647,0.004131,0.104917,412.093018,20.993017,1.049173,-321.819672,0.104119,0.000000
175.690002,89.048782,-321.864166,-0.001651,0.004099,0.104119,396.108765,20.178743,1.041194,-321.864166,0.103322,0.000000
176.170013,85.604340,-321.953125,-0.001660,0.004069,0.103356,380.787109,19.398220,1.033564,-321.953125,0.102524,0.000000
176.650009,81.762939,-321.997620,-0.001669,0.004036,0.102515,363.699707,18.527746,1.025146,-321.997620,0.101717,0.000000
177.130005,78.474518,-321.997620,-0.001669,0.004008,0.101796,349.072083,17.782579,1.017955,-321.997620,0.100919,0.000000
177.610016,75.745026,-321.997620,-0.001677,0.003985,0.101214,336.930695,17.164068,1.012141,-321.997620,0.100121,0.000000
178.090012,72.226852,-322.086578,-0.001664,0.003953,0.100398,321.281097,16.366838,1.003981,-322.086578,0.099323,0.000000
178.570007,68.363113,-322.131042,-0.001656,0.003917,0.099479,304.094330,15.491303,0.994792,-322.131042,0.098516,0.000000
179.050003,64.278931,-322.175537,-0.001664,0.003878,0.098509,285.926971,14.565814,0.985087,-322.175537,0.097718,0.000000
179.530014,62.151199,-322.131042,-0.001669,0.003859,0.098023,276.462341,14.083664,0.980227,-322.131042,0.096921,0.000000
180.010010,58.470673,-322.131042,-0.001664,0.003821,0.097051,260.090546,13.249643,0.970508,-322.131042,0.096123,0.000000
180.490005,55.079102,-322.220001,-0.001681,0.003791,0.096297,245.004074,12.481103,0.962968,-322.220001,0.095317,0.000000
180.970001,51.495758,-322.220001,-0.001669,0.003757,0.095420,229.064575,11.669106,0.954202,-322.220001,0.094519,0.000000
181.450012,48.734993,-322.308960,-0.001677,0.003729,0.094727,216.784073,11.043508,0.947268,-322.308960,0.093722,0.000000
181.930008,45.762344,-322.308960,-0.001690,0.003699,0.093946,203.561081,10.369896,0.939456,-322.308960,0.092924,0.000000
182.410004,42.854485,-322.308960,-0.001694,0.003663,0.093045,190.626266,9.710965,0.930448,-322.308960,0.092117,0.000000
182.890015,39.617828,-322.397919,-0.001699,0.003629,0.092186,176.228897,8.977529,0.921864,-322.397919,0.091319,0.000000
183.370010,36.897270,-322.442413,-0.001694,0.003600,0.091440,164.127258,8.361041,0.914400,-322.442413,0.090521,0.000000
183.850006,34.070221,-322.442413,-0.001707,0.003572,0.090728,151.551910,7.720423,0.907285,-322.442413,0.089723,0.000000
184.330002,30.801163,-322.486908,-0.001716,0.003536,0.089819,137.010422,6.979643,0.898186,-322.486908,0.088916,0.000000
184.810013,27.410713,-322.486908,-0.001725,0.003502,0.088942,121.928940,6.211356,0.889420,-322.486908,0.088118,0.000000
185.290009,24.956779,-322.531372,-0.001742,0.003473,0.088214,111.013298,5.655287,0.882138,-322.531372,0.087321,0.000000
185.770004,22.368790,-322.575867,-0.001750,0.003446,0.087520,99.501343,5.068841,0.875204,-322.575867,0.086523,0.000000
186.250015,19.490723,-322.620331,-0.001763,0.003411,0.086644,86.699066,4.416661,0.866438,-322.620331,0.085716,0.000000
186.730011,16.683029,-322.620331,-0.001772,0.003380,0.085864,74.209824,3.780428,0.858641,-322.620331,0.084918,0.000000
187.210007,14.176224,-322.620331,-0.001781,0.003349,0.085057,63.058994,3.212378,0.850572,-322.620331,0.084120,0.000000
187.690002,11.415825,-322.664825,-0.001807,0.003318,0.084268,50.780125,2.586863,0.842684,-322.664825,0.083322,0.000000
188.170013,9.159988,-322.709290,-0.001789,0.003287,0.083496,40.745663,2.075683,0.834963,-322.709290,0.082517,0.000000
188.650009,6.408905,-322.798248,-0.001807,0.003253,0.082629,28.508234,1.452279,0.826288,-322.798248,0.081719,0.000000
189.130005,4.674393,-322.753784,-0.001828,0.003228,0.081979,20.792738,1.059232,0.819793,-322.753784,0.080921,0.000000
189.610016,2.028313,-322.798248,-0.001850,0.003191,0.081051,9.022386,0.459622,0.810513,-322.798248,0.080123,0.000000
190.090012,0.350029,-322.798248,-0.001858,0.003161,0.080288,1.557007,0.079318,0.802882,-322.798248,0.079316,0.000000
190.570007,-0.713837,-322.887238,-0.001880,0.003130,0.079490,-3.175304,-0.161758,0.794904,-322.887238,0.078518,0.000000
191.050003,-0.252838,-322.887238,-0.001936,0.003101,0.078761,-1.124680,-0.057294,0.787606,-322.887238,0.077721,0.000000
191.530014,-0.116180,-322.931702,-0.001957,0.003075,0.078102,-0.516796,-0.026327,0.781021,-322.931702,0.076923,0.000000
192.010010,-0.144104,-322.976196,-0.002009,0.003038,0.077174,-0.641007,-0.032654,0.771740,-322.976196,0.076116,0.000000
192.490005,-0.071121,-322.931702,-0.002026,0.003009,0.076437,-0.316363,-0.016116,0.764367,-322.931702,0.075318,0.000000
192.970016,-0.073730,-323.020660,-0.002082,0.002976,0.075587,-0.327969,-0.016708,0.755874,-323.020660,0.074520,0.000000
193.450012,-0.088623,-323.065155,-0.002139,0.002944,0.074790,-0.394215,-0.020082,0.747895,-323.065155,0.073722,0.000000
193.930008,-0.103516,-323.109619,-0.002203,0.002909,0.073878,-0.460460,-0.023457,0.738781,-323.109619,0.072917,0.000000
194.410004,-0.048035,-323.109619,-0.002242,0.002891,0.073428,-0.213669,-0.010885,0.734285,-323.109619,0.072119,0.000000
194.890015,-0.063301,-323.109619,-0.002289,0.002850,0.072378,-0.281577,-0.014344,0.723778,-323.109619,0.071321,0.000000
195.000015,-0.066650,-323.198578,-0.002298,0.002850,0.072378,-0.296476,-0.015103,0.723778,-323.198578,0.072301,0.000000