File: Data/sima compression 500bar/P2-21-500bar-3re_11072024_165052.csv
Time (sec),S:Load (lbs),S:HL1 (DIM),S:LVDT (in),S:Position (in),Ch:Position (mm),Ch:Load (N),Ch:Stress (MPa),Ch:Strain (mm/mm),Ch:HL1 (DIM),Set Point (),Cycles ()
0.010000,-0.103516,-327.112915,-0.015151,-0.008947,-0.227265,-0.460460,-0.023457,-2.272648,-327.112915,-0.227101,0.000000
0.490000,-0.084152,-327.068420,-0.015151,-0.008857,-0.224967,-0.374328,-0.019069,-2.249666,-327.068420,-0.224326,0.000000
0.970000,-0.084526,-327.112915,-0.014948,-0.008555,-0.217301,-0.375991,-0.019154,-2.173014,-327.112915,-0.216329,0.000000
1.450000,-0.136284,-327.201874,-0.014599,-0.008239,-0.209262,-0.606221,-0.030882,-2.092623,-327.201874,-0.208334,0.000000
1.930000,-0.096069,-327.290833,-0.014275,-0.007925,-0.201291,-0.427338,-0.021770,-2.012913,-327.290833,-0.200338,0.000000
2.410000,-0.055855,-327.246368,-0.013965,-0.007612,-0.193340,-0.248455,-0.012657,-1.933400,-327.246368,-0.192342,0.000000
2.890000,-0.119530,-327.290833,-0.013642,-0.007299,-0.185396,-0.531695,-0.027086,-1.853963,-327.290833,-0.184347,0.000000
3.370000,-0.115433,-327.290833,-0.013301,-0.006982,-0.177339,-0.513470,-0.026157,-1.773390,-327.290833,-0.176350,0.000000
3.850000,-0.134796,-327.379791,-0.012999,-0.006671,-0.169456,-0.599603,-0.030545,-1.694558,-327.379791,-0.168355,0.000000
4.330000,-0.062927,-327.335327,-0.012667,-0.006367,-0.161712,-0.279914,-0.014260,-1.617119,-327.335327,-0.160358,0.000000
4.810000,-0.070007,-327.424286,-0.012322,-0.006042,-0.153456,-0.311408,-0.015864,-1.534563,-327.424286,-0.152363,0.000000
5.290000,-0.102028,-327.424286,-0.012016,-0.005731,-0.145564,-0.453843,-0.023120,-1.455640,-327.424286,-0.144366,0.000000
5.770000,-0.153786,-327.468750,-0.011693,-0.005416,-0.137576,-0.684073,-0.034848,-1.375764,-327.468750,-0.136371,0.000000
6.250000,-0.069260,-327.513245,-0.011365,-0.005108,-0.129737,-0.308082,-0.015694,-1.297371,-327.513245,-0.128376,0.000000
6.730000,-0.084526,-327.602203,-0.011037,-0.004785,-0.121542,-0.375991,-0.019154,-1.215421,-327.602203,-0.120379,0.000000
7.210001,-0.081917,-327.691162,-0.010727,-0.004474,-0.113633,-0.364384,-0.018563,-1.136331,-327.691162,-0.112384,0.000000
7.690001,-0.167191,-327.602203,-0.010395,-0.004150,-0.105411,-0.743701,-0.037886,-1.054108,-327.602203,-0.104387,0.000000
8.170000,-0.047661,-327.557709,-0.010050,-0.003843,-0.097606,-0.212006,-0.010800,-0.976064,-327.557709,-0.096392,0.000000
8.650001,-0.103142,-327.646698,-0.009718,-0.003521,-0.089437,-0.458798,-0.023372,-0.894371,-327.646698,-0.088379,0.000000
9.130000,-0.060692,-327.735657,-0.009378,-0.003206,-0.081433,-0.269971,-0.013753,-0.814328,-327.735657,-0.080384,0.000000
9.610001,-0.123253,-327.691162,-0.009089,-0.002891,-0.073419,-0.548256,-0.027929,-0.734194,-327.691162,-0.072387,0.000000
10.090000,-0.061440,-327.735657,-0.008761,-0.002575,-0.065406,-0.273297,-0.013922,-0.654060,-327.735657,-0.064392,0.000000
10.570001,-0.077080,-327.780121,-0.008433,-0.002262,-0.057453,-0.342868,-0.017467,-0.574532,-327.780121,-0.056396,0.000000
11.050000,-0.061813,-327.824615,-0.008088,-0.001944,-0.049388,-0.274960,-0.014007,-0.493883,-327.824615,-0.048400,0.000000
11.530001,-0.086014,-327.869080,-0.007756,-0.001630,-0.041402,-0.382608,-0.019491,-0.414022,-327.869080,-0.040405,0.000000
12.010000,-0.094955,-327.869080,-0.007450,-0.001314,-0.033363,-0.422383,-0.021517,-0.333631,-327.869080,-0.032408,0.000000
12.490001,-0.054733,-327.824615,-0.007140,-0.001005,-0.025531,-0.243466,-0.012403,-0.255314,-327.824615,-0.024413,0.000000
12.970000,-0.051384,-327.913574,-0.006795,-0.000685,-0.017397,-0.228567,-0.011644,-0.173969,-327.913574,-0.016417,0.000000
13.450001,-0.048409,-327.958038,-0.006463,-0.000375,-0.009530,-0.215332,-0.010970,-0.095304,-327.958038,-0.008421,0.000000
13.930000,-0.105377,-328.002533,-0.006131,-0.000060,-0.001535,-0.468741,-0.023879,-0.015352,-328.002533,-0.000425,0.000000
14.410001,-0.096069,-328.047028,-0.005859,0.000240,0.006097,-0.427338,-0.021770,0.060967,-328.047028,0.007571,0.000000
14.890000,-0.046173,-328.002533,-0.005514,0.000569,0.014448,-0.205388,-0.010463,0.144477,-328.002533,0.015567,0.000000
15.370001,0.099052,-328.047028,-0.005251,0.000018,0.000459,0.440607,0.022446,0.004587,-328.047028,0.000684,0.000000
15.850000,0.230125,-328.091492,-0.005247,0.000018,0.000459,1.023649,0.052147,0.004587,-328.091492,0.000805,0.000000
16.330000,0.168686,-328.180450,-0.005251,0.000026,0.000649,0.750352,0.038225,0.006495,-328.180450,0.001612,0.000000
16.810001,0.543297,-328.180450,-0.005226,0.000063,0.001612,2.416705,0.123113,0.016124,-328.180450,0.002410,0.000000
17.290001,0.809914,-328.180450,-0.005217,0.000082,0.002089,3.602676,0.183529,0.020893,-328.180450,0.003208,0.000000
17.770000,1.596359,-328.180450,-0.005174,0.000126,0.003208,7.100961,0.361740,0.032081,-328.180450,0.004015,0.000000
18.250000,2.244293,-328.313904,-0.005165,0.000152,0.003859,9.983115,0.508564,0.038591,-328.313904,0.004813,0.000000
18.730001,3.251930,-328.269409,-0.005152,0.000190,0.004839,14.465308,0.736898,0.048386,-328.269409,0.005611,0.000000
19.210001,3.796715,-328.358368,-0.005126,0.000210,0.005332,16.888630,0.860348,0.053322,-328.358368,0.006409,0.000000
19.690001,5.012878,-328.447357,-0.005101,0.000248,0.006287,22.298397,1.135935,0.062875,-328.447357,0.007214,0.000000
20.170000,6.134094,-328.358368,-0.005088,0.000281,0.007128,27.285814,1.390006,0.071277,-328.358368,0.008012,0.000000
20.650002,7.457878,-328.402863,-0.005049,0.000312,0.007935,33.174297,1.689979,0.079347,-328.402863,0.008810,0.000000
21.130001,8.385460,-328.536316,-0.005053,0.000337,0.008551,37.300388,1.900172,0.085508,-328.536316,0.009608,0.000000
21.610001,9.998573,-328.536316,-0.005019,0.000375,0.009521,44.475876,2.265709,0.095213,-328.536316,0.010415,0.000000
22.090000,11.385666,-328.580780,-0.005019,0.000408,0.010372,50.645973,2.580029,0.103721,-328.580780,0.011212,0.000000
22.570002,13.112350,-328.580780,-0.004975,0.000440,0.011170,58.326649,2.971301,0.111700,-328.580780,0.012010,0.000000
23.050001,14.200798,-328.536316,-0.004971,0.000463,0.011768,63.168304,3.217947,0.117680,-328.536316,0.012808,0.000000
23.530001,16.019096,-328.669739,-0.004932,0.000502,0.012757,71.256500,3.629979,0.127566,-328.669739,0.013615,0.000000
24.010000,17.361496,-328.714233,-0.004919,0.000530,0.013450,77.227791,3.934171,0.134500,-328.714233,0.014413,0.000000
24.490002,19.268784,-328.758698,-0.004907,0.000566,0.014369,85.711830,4.366369,0.143690,-328.758698,0.015211,0.000000
24.970001,20.432449,-328.669739,-0.004863,0.000590,0.014985,90.888077,4.630059,0.149852,-328.669739,0.016009,0.000000
25.450001,22.267876,-328.758698,-0.004850,0.000628,0.015939,99.052460,5.045973,0.159389,-328.758698,0.016816,0.000000
25.930000,23.615860,-328.803192,-0.004820,0.000657,0.016676,105.048592,5.351430,0.166762,-328.803192,0.017613,0.000000
26.410002,25.431923,-328.847656,-0.004803,0.000694,0.017621,113.126846,5.762956,0.176210,-328.847656,0.018411,0.000000
26.890001,26.489464,-328.936646,-0.004794,0.000718,0.018228,117.831017,6.002598,0.182281,-328.936646,0.019209,0.000000
27.370001,27.897026,-328.847656,-0.004769,0.000751,0.019079,124.092171,6.321557,0.190789,-328.847656,0.020015,0.000000
27.850000,29.190651,-328.847656,-0.004725,0.000782,0.019868,129.846497,6.614696,0.198677,-328.847656,0.020812,0.000000
28.330002,30.799675,-328.936646,-0.004712,0.000819,0.020805,137.003799,6.979306,0.208048,-328.936646,0.021610,0.000000
28.810001,31.814384,-328.936646,-0.004682,0.000844,0.021445,141.517456,7.209243,0.214452,-328.936646,0.022408,0.000000
29.290001,33.221954,-328.981110,-0.004665,0.000877,0.022278,147.778641,7.528202,0.222779,-328.981110,0.023215,0.000000
29.770002,34.028885,-329.070068,-0.004618,0.000906,0.023024,151.368042,7.711056,0.230243,-329.070068,0.024013,0.000000
30.250002,35.643120,-329.025604,-0.004600,0.000946,0.024022,158.548523,8.076846,0.240220,-329.025604,0.024811,0.000000
30.730001,36.383026,-329.070068,-0.004562,0.000972,0.024681,161.839783,8.244512,0.246805,-329.070068,0.025609,0.000000
31.210001,37.187347,-329.159027,-0.004549,0.001001,0.025418,165.417587,8.426773,0.254178,-329.159027,0.026416,0.000000
31.690002,38.034866,-329.159027,-0.004518,0.001032,0.026207,169.187531,8.618824,0.262066,-329.159027,0.027213,0.000000
32.170002,39.490105,-329.159027,-0.004484,0.001071,0.027204,175.660751,8.948586,0.272043,-329.159027,0.028011,0.000000
32.650002,39.740334,-329.203522,-0.004449,0.001094,0.027795,176.773834,9.005289,0.277948,-329.203522,0.028809,0.000000
33.130001,40.767342,-329.292480,-0.004411,0.001128,0.028644,181.342194,9.238011,0.286441,-329.292480,0.029615,0.000000
33.610001,41.613373,-329.292480,-0.004398,0.001159,0.029451,185.105530,9.429725,0.294510,-329.292480,0.030412,0.000000
34.090000,42.594574,-329.336975,-0.004381,0.001194,0.030317,189.470123,9.652068,0.303170,-329.336975,0.031210,0.000000
34.570004,42.899544,-329.381439,-0.004350,0.001223,0.031054,190.826706,9.721176,0.310543,-329.381439,0.032008,0.000000
35.050003,44.035652,-329.336975,-0.004281,0.001258,0.031957,195.880371,9.978621,0.319566,-329.336975,0.032815,0.000000
35.530003,44.311577,-329.381439,-0.004251,0.001286,0.032659,197.107742,10.041147,0.326591,-329.381439,0.033613,0.000000
36.010002,44.917061,-329.425934,-0.004247,0.001317,0.033440,199.801071,10.178351,0.334403,-329.425934,0.034411,0.000000
36.490002,45.454391,-329.470398,-0.004204,0.001347,0.034220,202.191238,10.300113,0.342200,-329.470398,0.035209,0.000000
36.970001,46.133224,-329.470398,-0.004186,0.001382,0.035104,205.210831,10.453938,0.351041,-329.470398,0.036016,0.000000
37.450001,46.638161,-329.470398,-0.004143,0.001411,0.035851,207.456894,10.568357,0.358505,-329.470398,0.036813,0.000000
37.930000,47.125229,-329.559357,-0.004109,0.001443,0.036657,209.623489,10.678730,0.366575,-329.559357,0.037611,0.000000
38.410004,47.756401,-329.559357,-0.004087,0.001475,0.037463,212.431076,10.821755,0.374629,-329.559357,0.038409,0.000000
38.890003,48.157814,-329.603851,-0.004053,0.001506,0.038244,214.216660,10.912717,0.382441,-329.603851,0.039216,0.000000
39.370003,48.740204,-329.603851,-0.004010,0.001536,0.039016,216.807251,11.044687,0.390162,-329.603851,0.040014,0.000000
39.850002,48.961395,-329.603851,-0.003975,0.001567,0.039796,217.791168,11.094810,0.397959,-329.603851,0.040812,0.000000
40.330002,49.802216,-329.648315,-0.003949,0.001605,0.040759,221.531326,11.285343,0.407588,-329.648315,0.041610,0.000000
40.810001,50.174210,-329.737305,-0.003923,0.001631,0.041426,223.186035,11.369638,0.414264,-329.737305,0.042415,0.000000
41.290001,50.889168,-329.692810,-0.003893,0.001664,0.042277,226.366318,11.531650,0.422773,-329.692810,0.043213,0.000000
41.770000,50.870918,-329.737305,-0.003859,0.001691,0.042953,226.285141,11.527514,0.429525,-329.737305,0.044011,0.000000
42.250004,51.960114,-329.737305,-0.003837,0.001730,0.043934,231.130127,11.774329,0.439335,-329.737305,0.044809,0.000000
42.730003,52.343651,-329.781769,-0.003777,0.001758,0.044653,232.836182,11.861241,0.446527,-329.781769,0.045616,0.000000
43.210003,52.943916,-329.870728,-0.003768,0.001791,0.045485,235.506302,11.997263,0.454854,-329.870728,0.046413,0.000000
43.690002,53.002007,-329.959686,-0.003725,0.001818,0.046188,235.764694,12.010427,0.461878,-329.959686,0.047211,0.000000
44.170002,53.692017,-329.915222,-0.003704,0.001852,0.047046,238.834015,12.166785,0.470462,-329.915222,0.048018,0.000000
44.650002,54.794235,-329.959686,-0.003660,0.001891,0.048035,243.736938,12.416551,0.480349,-329.959686,0.048816,0.000000
45.130001,54.867966,-330.004181,-0.003622,0.001917,0.048693,244.064896,12.433259,0.486934,-330.004181,0.049614,0.000000
45.610001,54.820305,-330.048645,-0.003604,0.001943,0.049354,243.852890,12.422459,0.493535,-330.048645,0.050412,0.000000
46.090004,55.571381,-330.048645,-0.003566,0.001976,0.050203,247.193848,12.592655,0.502028,-330.048645,0.051217,0.000000
46.570004,56.352615,-330.048645,-0.003523,0.002011,0.051070,250.668945,12.769685,0.510703,-330.048645,0.052015,0.000000
47.050003,56.722755,-330.048645,-0.003501,0.002044,0.051929,252.315414,12.853560,0.519288,-330.048645,0.052813,0.000000
47.530003,57.376640,-330.093140,-0.003471,0.002074,0.052683,255.224045,13.001733,0.526827,-330.093140,0.053611,0.000000
48.010002,57.816788,-330.182098,-0.003445,0.002104,0.053429,257.181915,13.101471,0.534291,-330.182098,0.054418,0.000000
48.490002,58.184319,-330.226593,-0.003410,0.002136,0.054245,258.816772,13.184755,0.542451,-330.226593,0.055216,0.000000
48.970001,59.212067,-330.137604,-0.003393,0.002172,0.055164,263.388428,13.417645,0.551641,-330.137604,0.056013,0.000000
49.450001,59.063118,-330.226593,-0.003346,0.002193,0.055711,262.725861,13.383894,0.557106,-330.226593,0.056811,0.000000
49.930004,60.344818,-330.271057,-0.003311,0.002232,0.056690,268.427155,13.674332,0.566902,-330.271057,0.057618,0.000000
50.410004,59.641785,-330.315552,-0.003285,0.002248,0.057097,265.299896,13.515021,0.570974,-330.315552,0.058416,0.000000
50.890003,61.912506,-330.404510,-0.003268,0.002299,0.058407,275.400574,14.029574,0.584070,-330.404510,0.059214,0.000000
51.370003,61.684990,-330.404510,-0.003242,0.002321,0.058963,274.388550,13.978019,0.589626,-330.404510,0.060012,0.000000
51.850002,62.860939,-330.360016,-0.003208,0.002359,0.059916,279.619415,14.244493,0.599164,-330.360016,0.060819,0.000000
52.330002,62.357864,-330.448975,-0.003173,0.002377,0.060368,277.381622,14.130493,0.603676,-330.448975,0.061617,0.000000
52.810001,64.379852,-330.537933,-0.003152,0.002425,0.061589,286.375885,14.588683,0.615893,-330.537933,0.062413,0.000000
53.290001,64.183975,-330.537933,-0.003117,0.002445,0.062110,285.504578,14.544297,0.621101,-330.537933,0.063211,0.000000
53.770004,65.442596,-330.537933,-0.003087,0.002484,0.063082,291.103210,14.829504,0.630821,-330.537933,0.064018,0.000000
54.250004,65.126831,-330.493469,-0.003061,0.002503,0.063585,289.698608,14.757951,0.635847,-330.493469,0.064816,0.000000
54.730003,66.880325,-330.582428,-0.003044,0.002547,0.064704,297.498535,15.155298,0.647035,-330.582428,0.065613,0.000000
55.210003,67.292923,-330.626923,-0.003005,0.002577,0.065448,299.333862,15.248795,0.654484,-330.626923,0.066411,0.000000
55.690002,68.202255,-330.715881,-0.002966,0.002607,0.066221,303.378784,15.454852,0.662205,-330.715881,0.067218,0.000000
56.170002,68.160172,-330.671387,-0.002949,0.002630,0.066793,303.191589,15.445315,0.667928,-330.671387,0.068016,0.000000
56.650002,70.006027,-330.671387,-0.002919,0.002674,0.067912,311.402374,15.863592,0.679116,-330.671387,0.068814,0.000000
57.130001,70.144547,-330.760345,-0.002880,0.002699,0.068563,312.018524,15.894981,0.685626,-330.760345,0.069612,0.000000
57.610004,71.534988,-330.760345,-0.002846,0.002738,0.069533,318.203522,16.210060,0.695331,-330.760345,0.070419,0.000000
58.090004,70.977539,-330.849304,-0.002850,0.002752,0.069907,315.723877,16.083740,0.699070,-330.849304,0.071217,0.000000
58.570004,73.068787,-330.849304,-0.002807,0.002799,0.071086,325.026184,16.557623,0.710864,-330.849304,0.072014,0.000000
59.050003,73.142883,-330.849304,-0.002781,0.002823,0.071701,325.355804,16.574413,0.717010,-330.849304,0.072812,0.000000
59.530003,74.448807,-330.849304,-0.002764,0.002860,0.072656,331.164825,16.870340,0.726564,-330.849304,0.073618,0.000000
60.010002,74.335968,-331.027252,-0.002725,0.002880,0.073150,330.662903,16.844770,0.731499,-331.027252,0.074416,0.000000
60.490002,76.549347,-330.982758,-0.002703,0.002928,0.074373,340.508514,17.346331,0.743732,-330.982758,0.075213,0.000000
60.970001,76.841660,-331.027252,-0.002669,0.002951,0.074953,341.808777,17.412569,0.749530,-331.027252,0.076011,0.000000
61.450005,78.385529,-331.027252,-0.002665,0.002990,0.075942,348.676239,17.762415,0.759416,-331.027252,0.076818,0.000000
61.930004,78.295776,-331.116211,-0.002621,0.003008,0.076411,348.277008,17.742075,0.764110,-331.116211,0.077616,0.000000
62.410004,80.079437,-331.160675,-0.002591,0.003050,0.077469,356.211121,18.146259,0.774692,-331.160675,0.078414,0.000000
62.890003,80.859192,-331.116211,-0.002561,0.003079,0.078197,359.679657,18.322954,0.781974,-331.116211,0.079212,0.000000
63.370003,82.206436,-331.205170,-0.002552,0.003114,0.079091,365.672485,18.628244,0.790907,-331.205170,0.080019,0.000000
63.850002,82.403793,-331.205170,-0.002522,0.003135,0.079628,366.550385,18.672968,0.796281,-331.205170,0.080817,0.000000
64.330002,84.438812,-331.205170,-0.002505,0.003178,0.080721,375.602600,19.134108,0.807212,-331.205170,0.081614,0.000000
64.810005,85.265472,-331.294128,-0.002462,0.003207,0.081449,379.279755,19.321432,0.814494,-331.294128,0.082412,0.000000
65.290001,86.579575,-331.294128,-0.002449,0.003241,0.082317,385.125183,19.619211,0.823169,-331.294128,0.083218,0.000000
65.770004,86.760544,-331.338593,-0.002436,0.003261,0.082829,385.930176,19.660221,0.828286,-331.338593,0.084016,0.000000
66.250000,88.874878,-331.338593,-0.002410,0.003304,0.083920,395.335205,20.139336,0.839202,-331.338593,0.084813,0.000000
66.730003,89.614044,-331.338593,-0.002363,0.003335,0.084701,398.623169,20.306833,0.847014,-331.338593,0.085611,0.000000
67.210007,91.012665,-331.472046,-0.002341,0.003367,0.085516,404.844543,20.623764,0.855159,-331.472046,0.086418,0.000000
67.690002,91.414841,-331.427551,-0.002320,0.003388,0.086055,406.633514,20.714899,0.860549,-331.427551,0.087216,0.000000
68.170006,93.486710,-331.516541,-0.002302,0.003429,0.087104,415.849640,21.184391,0.871041,-331.516541,0.088014,0.000000
68.650002,94.173004,-331.472046,-0.002281,0.003455,0.087754,418.902435,21.339907,0.877535,-331.472046,0.088812,0.000000
69.130005,96.288818,-331.516541,-0.002255,0.003495,0.088760,428.314056,21.819359,0.887603,-331.516541,0.089619,0.000000
69.610001,96.824295,-331.516541,-0.002238,0.003515,0.089280,430.695984,21.940699,0.892796,-331.516541,0.090417,0.000000
70.090004,98.509277,-331.605499,-0.002216,0.003553,0.090235,438.191162,22.322521,0.902349,-331.605499,0.091214,0.000000
70.570000,99.898590,-331.649963,-0.002190,0.003584,0.091024,444.371124,22.637344,0.910237,-331.649963,0.092012,0.000000
71.050003,102.290344,-331.605499,-0.002169,0.003619,0.091926,455.010162,23.179323,0.919260,-331.605499,0.092819,0.000000
71.530006,103.394424,-331.694458,-0.002164,0.003642,0.092498,459.921356,23.429510,0.924983,-331.694458,0.093617,0.000000
72.010002,105.528870,-331.649963,-0.002151,0.003679,0.093434,469.415863,23.913183,0.934339,-331.649963,0.094415,0.000000
72.490005,107.288696,-331.738922,-0.002134,0.003706,0.094120,477.243958,24.311968,0.941197,-331.738922,0.095220,0.000000
72.970001,110.204376,-331.827881,-0.002121,0.003745,0.095125,490.213562,24.972668,0.951250,-331.827881,0.096018,0.000000
73.450005,111.862549,-331.783417,-0.002104,0.003769,0.095725,497.589478,25.348415,0.957245,-331.783417,0.096816,0.000000
73.930000,113.733353,-331.916870,-0.002104,0.003797,0.096453,505.911224,25.772346,0.964527,-331.916870,0.097614,0.000000
74.410004,116.224518,-331.827881,-0.002087,0.003833,0.097354,516.992493,26.336851,0.973536,-331.827881,0.098421,0.000000
74.890007,119.310745,-331.872375,-0.002061,0.003869,0.098274,530.720703,27.036201,0.982740,-331.872375,0.099219,0.000000
75.370003,121.223999,-332.005829,-0.002070,0.003895,0.098933,539.231262,27.469749,0.989326,-332.005829,0.100017,0.000000
75.850006,123.638458,-331.961334,-0.002052,0.003926,0.099730,549.971313,28.016874,0.997305,-331.961334,0.100814,0.000000
76.330002,126.246185,-332.005829,-0.002039,0.003960,0.100572,561.571106,28.607796,1.005722,-332.005829,0.101621,0.000000
76.810005,128.953705,-332.005829,-0.002035,0.003992,0.101403,573.614746,29.221329,1.014034,-332.005829,0.102419,0.000000
77.290001,131.356995,-332.050293,-0.002039,0.004021,0.102141,584.305115,29.765921,1.021407,-332.050293,0.103217,0.000000
77.770004,134.329651,-332.139252,-0.002026,0.004057,0.103043,597.528137,30.439533,1.030430,-332.139252,0.104015,0.000000
78.250000,136.475998,-332.139252,-0.002005,0.004086,0.103780,607.075562,30.925903,1.037803,-332.139252,0.104820,0.000000
78.730003,139.081482,-332.139252,-0.001996,0.004112,0.104457,618.665344,31.516315,1.044570,-332.139252,0.105618,0.000000
79.210007,141.878754,-332.139252,-0.002013,0.004147,0.105332,631.108215,32.150185,1.053321,-332.139252,0.106416,0.000000
79.690002,145.109833,-332.228210,-0.001983,0.004181,0.106191,645.480774,32.882355,1.061905,-332.228210,0.107214,0.000000
80.170006,147.606583,-332.317200,-0.002005,0.004209,0.106911,656.586853,33.448128,1.069112,-332.317200,0.108021,0.000000
80.650002,150.605301,-332.228210,-0.001988,0.004243,0.107770,669.925842,34.127647,1.077696,-332.228210,0.108819,0.000000
81.130005,152.992203,-332.317200,-0.001983,0.004272,0.108516,680.543335,34.668526,1.085160,-332.317200,0.109617,0.000000
81.610001,156.235199,-332.406158,-0.001988,0.004305,0.109349,694.968872,35.403404,1.093486,-332.406158,0.110414,0.000000
82.090004,158.958359,-332.406158,-0.001992,0.004335,0.110112,707.082092,36.020477,1.101117,-332.406158,0.111221,0.000000
82.570007,161.642792,-332.450623,-0.001970,0.004365,0.110875,719.023071,36.628780,1.108747,-332.450623,0.112019,0.000000
83.050003,164.640015,-332.450623,-0.001979,0.004401,0.111776,732.355347,37.307961,1.117755,-332.450623,0.112817,0.000000
83.530006,166.245316,-332.495117,-0.001975,0.004425,0.112401,739.496094,37.671726,1.124008,-332.495117,0.113615,0.000000
84.010002,170.638931,-332.539581,-0.001970,0.004462,0.113336,759.039856,38.667336,1.133364,-332.539581,0.114422,0.000000
84.490005,173.004242,-332.584076,-0.001970,0.004487,0.113978,769.561279,39.203323,1.139783,-332.584076,0.115220,0.000000
84.970001,176.691849,-332.584076,-0.001979,0.004526,0.114967,785.964600,40.038948,1.149669,-332.584076,0.116018,0.000000
85.450005,179.182648,-332.584076,-0.001957,0.004556,0.115713,797.044250,40.603367,1.157133,-332.584076,0.116815,0.000000
85.930000,182.675873,-332.673035,-0.001966,0.004587,0.116511,812.582886,41.394943,1.165112,-332.673035,0.117621,0.000000
86.410004,185.015869,-332.628540,-0.001979,0.004613,0.117170,822.991699,41.925194,1.171697,-332.628540,0.118419,0.000000
86.890007,188.337799,-332.673035,-0.001970,0.004646,0.118012,837.768372,42.677956,1.180115,-332.673035,0.119217,0.000000
87.370003,191.143616,-332.761993,-0.001962,0.004683,0.118956,850.249268,43.313759,1.189562,-332.761993,0.120014,0.000000
87.850006,194.915375,-332.806488,-0.001966,0.004714,0.119728,867.026917,44.168453,1.197283,-332.806488,0.120821,0.000000
88.330002,197.139954,-332.806488,-0.001970,0.004738,0.120335,876.922302,44.672550,1.203354,-332.806488,0.121619,0.000000
88.810005,200.602264,-332.806488,-0.001962,0.004772,0.121203,892.323425,45.457123,1.212029,-332.806488,0.122417,0.000000
89.290001,203.790894,-332.806488,-0.001979,0.004806,0.122080,906.507141,46.179676,1.220795,-332.806488,0.123215,0.000000
89.770004,206.909119,-332.939911,-0.001953,0.004837,0.122859,920.377747,46.886276,1.228592,-332.939911,0.124022,0.000000
90.250008,210.174835,-332.850952,-0.001962,0.004871,0.123727,934.904358,47.626297,1.237267,-332.850952,0.124820,0.000000
90.730003,213.236847,-332.939911,-0.001966,0.004900,0.124455,948.524841,48.320160,1.244549,-332.939911,0.125618,0.000000
91.210007,215.975647,-332.984406,-0.001966,0.004931,0.125236,960.707642,48.940781,1.252361,-332.984406,0.126415,0.000000
91.690002,219.433868,-332.939911,-0.001944,0.004964,0.126076,976.090576,49.724426,1.260764,-332.939911,0.127221,0.000000
92.170006,220.615417,-333.073364,-0.001944,0.004965,0.126102,981.346375,49.992168,1.261021,-333.073364,0.022139,0.000000
92.650002,220.193878,-333.117828,-0.001949,0.004961,0.126016,979.471313,49.896648,1.260158,-333.117828,982.000671,0.000000
93.130005,219.805145,-333.117828,-0.001936,0.004961,0.126016,977.742126,49.808556,1.260158,-333.117828,982.000671,0.000000
93.610008,219.386963,-333.073364,-0.001944,0.004976,0.126381,975.881958,49.713799,1.263807,-333.073364,982.000671,0.000000
94.090004,220.032288,-333.162323,-0.001932,0.004978,0.126441,978.752502,49.860031,1.264412,-333.162323,982.000671,0.000000
94.570007,219.640533,-333.162323,-0.001919,0.004978,0.126441,977.009888,49.771255,1.264412,-333.162323,982.000671,0.000000
95.050003,219.293488,-333.162323,-0.001932,0.004978,0.126441,975.466125,49.692616,1.264412,-333.162323,982.000671,0.000000
95.530006,218.978851,-333.251282,-0.001944,0.004978,0.126441,974.066589,49.621315,1.264412,-333.251282,982.000671,0.000000
96.010002,220.569611,-333.295776,-0.001936,0.004950,0.125721,981.142639,49.981789,1.257206,-333.295776,982.000671,0.000000
96.490005,220.295563,-333.340240,-0.001906,0.004950,0.125721,979.923584,49.919689,1.257206,-333.340240,982.000671,0.000000
96.970001,219.906036,-333.295776,-0.001901,0.004964,0.126095,978.190918,49.831417,1.260945,-333.295776,982.000671,0.000000
97.450005,219.712402,-333.340240,-0.001893,0.004977,0.126423,977.329590,49.787540,1.264231,-333.340240,982.000671,0.000000
97.930008,219.568298,-333.429199,-0.001888,0.004989,0.126718,976.688599,49.754890,1.267183,-333.429199,982.000671,0.000000
98.410004,219.379150,-333.429199,-0.001906,0.004994,0.126839,975.847168,49.712029,1.268394,-333.429199,982.000671,0.000000
98.890007,219.887817,-333.473694,-0.001897,0.005003,0.127074,978.109863,49.827293,1.270741,-333.473694,982.000671,0.000000
99.370003,219.698639,-333.429199,-0.001884,0.005004,0.127091,977.268372,49.784424,1.270907,-333.429199,982.000671,0.000000
99.850006,219.591766,-333.473694,-0.001901,0.005006,0.127153,976.792969,49.760204,1.271528,-333.473694,982.000671,0.000000
100.330002,219.881836,-333.562653,-0.001884,0.005011,0.127281,978.083252,49.825935,1.272815,-333.562653,982.000671,0.000000
100.810005,219.800293,-333.562653,-0.001888,0.005011,0.127281,977.720520,49.807461,1.272815,-333.562653,982.000671,0.000000
101.290009,219.727295,-333.562653,-0.001884,0.005014,0.127344,977.395813,49.790920,1.273435,-333.562653,982.000671,0.000000
101.770004,219.844604,-333.607147,-0.001880,0.005017,0.127430,977.917664,49.817497,1.274298,-333.607147,982.000671,0.000000
102.250008,219.742950,-333.651611,-0.001876,0.005018,0.127456,977.465454,49.794464,1.274556,-333.651611,982.000671,0.000000
102.730003,219.647247,-333.651611,-0.001884,0.005019,0.127481,977.039734,49.772778,1.274813,-333.651611,982.000671,0.000000
103.210007,219.866211,-333.740570,-0.001871,0.005024,0.127602,978.013733,49.822395,1.276024,-333.740570,982.000671,0.000000
103.690002,219.753387,-333.696106,-0.001884,0.005024,0.127602,977.511902,49.796829,1.276024,-333.696106,982.000671,0.000000
104.170006,219.643158,-333.696106,-0.001867,0.005025,0.127646,977.021545,49.771851,1.276463,-333.696106,982.000671,0.000000
104.650002,219.563477,-333.740570,-0.001854,0.005027,0.127681,976.667114,49.753796,1.276812,-333.740570,982.000671,0.000000
105.130005,219.505737,-333.829529,-0.001863,0.005028,0.127716,976.410278,49.740711,1.277160,-333.829529,982.000671,0.000000
105.610008,219.442810,-333.829529,-0.001858,0.005029,0.127742,976.130371,49.726452,1.277417,-333.829529,982.000671,0.000000
106.090004,219.769379,-333.874023,-0.001867,0.005033,0.127837,977.583008,49.800453,1.278371,-333.874023,982.000671,0.000000
106.570007,219.546722,-333.874023,-0.001854,0.005033,0.127837,976.592590,49.750000,1.278371,-333.874023,982.000671,0.000000
107.050003,219.336304,-333.962982,-0.001837,0.005033,0.127837,975.656616,49.702320,1.278371,-333.962982,982.000671,0.000000
107.530006,219.833069,-334.007446,-0.001837,0.005040,0.128019,977.866333,49.814884,1.280188,-334.007446,982.000671,0.000000
108.010002,219.674805,-334.007446,-0.001832,0.005040,0.128019,977.162354,49.779022,1.280188,-334.007446,982.000671,0.000000
108.490005,219.514313,-334.051941,-0.001841,0.005040,0.128028,976.448425,49.742653,1.280279,-334.051941,982.000671,0.000000
108.970009,219.338928,-334.007446,-0.001854,0.005040,0.128028,975.668274,49.702911,1.280279,-334.007446,982.000671,0.000000
109.450005,219.252899,-334.051941,-0.001824,0.005042,0.128072,975.285583,49.683418,1.280718,-334.051941,982.000671,0.000000
109.930008,219.200775,-334.096436,-0.001824,0.005044,0.128107,975.053772,49.671604,1.281066,-334.096436,982.000671,0.000000
110.410004,219.104340,-334.185394,-0.001828,0.005044,0.128114,974.624756,49.649750,1.281142,-334.185394,982.000671,0.000000
110.890007,219.080872,-334.185394,-0.001811,0.005047,0.128184,974.520386,49.644436,1.281838,-334.185394,982.000671,0.000000
111.370003,219.010498,-334.185394,-0.001824,0.005047,0.128193,974.207336,49.628490,1.281929,-334.185394,982.000671,0.000000
111.850006,219.077881,-334.185394,-0.001819,0.005050,0.128263,974.507080,49.643757,1.282625,-334.185394,982.000671,0.000000
112.330002,220.699188,-334.318817,-0.001807,0.005048,0.128210,981.718994,50.011150,1.282095,-334.318817,982.000671,0.000000
112.810005,220.459778,-334.274353,-0.001807,0.005047,0.128202,980.654053,49.956898,1.282020,-334.274353,982.000671,0.000000
113.290009,220.312683,-334.363312,-0.001815,0.005047,0.128202,979.999756,49.923569,1.282020,-334.363312,982.000671,0.000000
113.770004,220.114563,-334.363312,-0.001807,0.005048,0.128210,979.118469,49.878674,1.282095,-334.363312,982.000671,0.000000
114.250008,219.942169,-334.363312,-0.001789,0.005048,0.128219,978.351624,49.839607,1.282186,-334.363312,982.000671,0.000000
114.730003,219.782806,-334.407776,-0.001785,0.005048,0.128228,977.642761,49.803493,1.282277,-334.407776,982.000671,0.000000
115.210007,219.579865,-334.452271,-0.001794,0.005048,0.128228,976.739990,49.757511,1.282277,-334.452271,982.000671,0.000000
115.690002,219.408569,-334.541229,-0.001785,0.005065,0.128653,975.978088,49.718693,1.286531,-334.541229,982.000671,0.000000
116.170006,220.121643,-334.585724,-0.001781,0.005071,0.128791,979.149963,49.880280,1.287909,-334.585724,982.000671,0.000000
116.650009,219.980530,-334.541229,-0.001789,0.005071,0.128791,978.522278,49.848301,1.287909,-334.541229,982.000671,0.000000
117.130005,219.835297,-334.585724,-0.001789,0.005071,0.128791,977.876221,49.815392,1.287909,-334.585724,982.000671,0.000000
117.610008,219.678894,-334.585724,-0.001785,0.005071,0.128791,977.180542,49.779949,1.287909,-334.585724,982.000671,0.000000
118.090004,219.524750,-334.674683,-0.001789,0.005071,0.128791,976.494873,49.745022,1.287909,-334.674683,982.000671,0.000000
118.570007,219.367218,-334.719147,-0.001781,0.005071,0.128791,975.794128,49.709324,1.287909,-334.719147,982.000671,0.000000
119.050003,219.225342,-334.719147,-0.001772,0.005071,0.128791,975.163025,49.677174,1.287909,-334.719147,982.000671,0.000000
119.530006,220.638123,-334.719147,-0.001772,0.005070,0.128782,981.447388,49.997311,1.287818,-334.719147,982.000671,0.000000
120.010002,220.419922,-334.763641,-0.001772,0.005070,0.128782,980.476807,49.947868,1.287818,-334.763641,982.000671,0.000000
120.490005,220.313049,-334.763641,-0.001776,0.005070,0.128782,980.001404,49.923649,1.287818,-334.763641,982.000671,0.000000
120.970009,220.138397,-334.852600,-0.001785,0.005070,0.128782,979.224487,49.884075,1.287818,-334.852600,982.000671,0.000000
121.450005,219.980896,-334.808105,-0.001768,0.005070,0.128782,978.523926,49.848381,1.287818,-334.808105,982.000671,0.000000
121.930008,219.788757,-334.852600,-0.001768,0.005072,0.128826,977.669250,49.804844,1.288257,-334.852600,982.000671,0.000000
122.410004,219.642029,-334.897095,-0.001776,0.005078,0.128973,977.016541,49.771595,1.289726,-334.897095,982.000671,0.000000
122.890007,219.524750,-334.897095,-0.001759,0.005083,0.129112,976.494873,49.745022,1.291119,-334.897095,982.000671,0.000000
123.370003,220.106018,-335.075012,-0.001759,0.005092,0.129347,979.080444,49.876736,1.293465,-335.075012,982.000671,0.000000
123.850006,220.028198,-335.030518,-0.001768,0.005092,0.129347,978.734314,49.859104,1.293465,-335.030518,982.000671,0.000000
124.330009,219.878113,-334.986053,-0.001759,0.005092,0.129347,978.066711,49.825092,1.293465,-334.986053,982.000671,0.000000
124.810005,219.754852,-335.030518,-0.001755,0.005093,0.129354,977.518433,49.797161,1.293541,-335.030518,982.000671,0.000000
125.290009,219.882599,-335.075012,-0.001763,0.005096,0.129449,978.086670,49.826111,1.294495,-335.075012,982.000671,0.000000
125.770004,219.825989,-335.163971,-0.001768,0.005096,0.129449,977.834839,49.813282,1.294495,-335.163971,982.000671,0.000000
126.250008,219.715759,-335.163971,-0.001768,0.005096,0.129449,977.344482,49.788300,1.294495,-335.163971,982.000671,0.000000
126.730003,219.597717,-335.208435,-0.001755,0.005098,0.129477,976.819458,49.761555,1.294767,-335.208435,982.000671,0.000000
127.210007,219.596985,-335.163971,-0.001738,0.005100,0.129528,976.816162,49.761391,1.295282,-335.163971,982.000671,0.000000
127.690002,219.593994,-335.252930,-0.001763,0.005101,0.129554,976.802856,49.760712,1.295539,-335.252930,982.000671,0.000000
128.170013,219.532562,-335.297424,-0.001750,0.005101,0.129563,976.529602,49.746792,1.295630,-335.297424,982.000671,0.000000
128.650009,219.556030,-335.341888,-0.001738,0.005103,0.129614,976.633972,49.752106,1.296145,-335.341888,982.000671,0.000000
129.130005,219.512085,-335.297424,-0.001746,0.005103,0.129624,976.438538,49.742149,1.296236,-335.297424,982.000671,0.000000
129.610001,219.505371,-335.386383,-0.001738,0.005105,0.129667,976.408630,49.740627,1.296675,-335.386383,982.000671,0.000000
130.090012,219.658417,-335.386383,-0.001733,0.005108,0.129745,977.089417,49.775311,1.297447,-335.386383,982.000671,0.000000
130.570007,219.620056,-335.475342,-0.001738,0.005109,0.129763,976.918823,49.766617,1.297629,-335.475342,982.000671,0.000000
131.050003,219.584686,-335.475342,-0.001750,0.005109,0.129770,976.761475,49.758598,1.297704,-335.475342,982.000671,0.000000
131.529999,219.562714,-335.519806,-0.001755,0.005110,0.129805,976.663757,49.753624,1.298052,-335.519806,982.000671,0.000000
132.010010,219.531067,-335.564301,-0.001738,0.005111,0.129823,976.522949,49.746449,1.298234,-335.564301,982.000671,0.000000
132.490005,219.544861,-335.475342,-0.001725,0.005113,0.129858,976.584290,49.749577,1.298582,-335.475342,982.000671,0.000000
132.970001,219.508728,-335.608765,-0.001725,0.005113,0.129875,976.423584,49.741386,1.298749,-335.608765,982.000671,0.000000
133.450012,219.684845,-335.608765,-0.001729,0.005117,0.129970,977.206970,49.781296,1.299703,-335.608765,982.000671,0.000000
133.930008,219.678162,-335.653259,-0.001738,0.005117,0.129970,977.177246,49.779785,1.299703,-335.653259,982.000671,0.000000
134.410004,219.608154,-335.697723,-0.001712,0.005117,0.129979,976.865845,49.763920,1.299793,-335.697723,982.000671,0.000000
134.889999,219.550446,-335.697723,-0.001720,0.005118,0.130005,976.609131,49.750843,1.300051,-335.697723,982.000671,0.000000
135.370010,219.508728,-335.742218,-0.001720,0.005119,0.130031,976.423584,49.741386,1.300308,-335.742218,982.000671,0.000000
135.850006,219.481171,-335.786713,-0.001716,0.005120,0.130049,976.301025,49.735142,1.300490,-335.786713,982.000671,0.000000
136.330002,219.615234,-335.831177,-0.001725,0.005123,0.130126,976.897339,49.765522,1.301262,-335.831177,982.000671,0.000000
136.810013,219.597717,-335.875671,-0.001720,0.005123,0.130126,976.819458,49.761555,1.301262,-335.875671,982.000671,0.000000
137.290009,219.523621,-335.831177,-0.001707,0.005123,0.130126,976.489807,49.744766,1.301262,-335.831177,982.000671,0.000000
137.770004,219.450256,-335.920135,-0.001720,0.005123,0.130135,976.163513,49.728138,1.301353,-335.920135,982.000671,0.000000
138.250000,220.179382,-335.920135,-0.001707,0.005135,0.130431,979.406799,49.893360,1.304305,-335.920135,982.000671,0.000000
138.730011,220.139160,-335.964630,-0.001716,0.005129,0.130275,979.227905,49.884247,1.302746,-335.964630,982.000671,0.000000
139.210007,220.049774,-335.964630,-0.001712,0.005129,0.130275,978.830261,49.863991,1.302746,-335.964630,982.000671,0.000000
139.690002,219.882599,-336.009094,-0.001699,0.005129,0.130275,978.086670,49.826111,1.302746,-336.009094,982.000671,0.000000
140.170013,219.790253,-336.098053,-0.001703,0.005129,0.130275,977.675842,49.805183,1.302746,-336.098053,982.000671,0.000000
140.650009,219.606659,-336.142548,-0.001703,0.005129,0.130275,976.859192,49.763580,1.302746,-336.142548,982.000671,0.000000
141.130005,219.519165,-336.142548,-0.001703,0.005129,0.130275,976.470032,49.743755,1.302746,-336.142548,982.000671,0.000000
141.610001,220.428864,-336.187042,-0.001707,0.005133,0.130387,980.516541,49.949894,1.303866,-336.187042,982.000671,0.000000
142.090012,220.288116,-336.187042,-0.001703,0.005133,0.130387,979.890503,49.917999,1.303866,-336.187042,982.000671,0.000000
142.570007,220.128723,-336.231506,-0.001694,0.005133,0.130387,979.181458,49.881882,1.303866,-336.231506,982.000671,0.000000
143.050003,220.031158,-336.276001,-0.001703,0.005133,0.130387,978.747498,49.859772,1.303866,-336.276001,982.000671,0.000000
143.530014,219.875153,-336.276001,-0.001703,0.005133,0.130387,978.053528,49.824421,1.303866,-336.276001,982.000671,0.000000
144.010010,219.793976,-336.276001,-0.001712,0.005134,0.130396,977.692444,49.806026,1.303957,-336.276001,982.000671,0.000000
144.490005,219.688965,-336.276001,-0.001699,0.005134,0.130412,977.225342,49.782234,1.304123,-336.276001,982.000671,0.000000
144.970001,220.123901,-336.364960,-0.001690,0.005143,0.130638,979.160034,49.880787,1.306379,-336.364960,982.000671,0.000000
145.450012,220.041229,-336.409424,-0.001694,0.005143,0.130638,978.792297,49.862057,1.306379,-336.409424,982.000671,0.000000
145.930008,219.921326,-336.453918,-0.001699,0.005143,0.130638,978.258911,49.834885,1.306379,-336.453918,982.000671,0.000000
146.410004,219.839020,-336.453918,-0.001707,0.005143,0.130638,977.892822,49.816231,1.306379,-336.453918,982.000671,0.000000
146.889999,219.741821,-336.409424,-0.001703,0.005143,0.130638,977.460449,49.794209,1.306379,-336.409424,982.000671,0.000000
147.370010,219.614471,-336.498383,-0.001681,0.005143,0.130638,976.893982,49.765350,1.306379,-336.498383,982.000671,0.000000
147.850006,219.535156,-336.542877,-0.001694,0.005143,0.130638,976.541138,49.747379,1.306379,-336.542877,982.000671,0.000000
148.330002,219.413391,-336.587372,-0.001686,0.005143,0.130638,975.999512,49.719784,1.306379,-336.587372,982.000671,0.000000
148.810013,219.311005,-336.631836,-0.001703,0.005143,0.130638,975.544067,49.696583,1.306379,-336.631836,982.000671,0.000000
149.290009,219.213440,-336.587372,-0.001703,0.005143,0.130638,975.110107,49.674473,1.306379,-336.587372,982.000671,0.000000
149.770004,220.828430,-336.631836,-0.001686,0.005136,0.130465,982.293945,50.040436,1.304653,-336.631836,982.000671,0.000000
150.250000,220.685059,-336.676331,-0.001681,0.005136,0.130465,981.656189,50.007950,1.304653,-336.676331,982.000671,0.000000
150.730011,220.581543,-336.720795,-0.001669,0.005136,0.130465,981.195679,49.984493,1.304653,-336.720795,982.000671,0.000000
151.210007,220.386047,-336.676331,-0.001686,0.005136,0.130465,980.326111,49.940193,1.304653,-336.676331,982.000671,0.000000
151.690002,220.335022,-336.676331,-0.001673,0.005136,0.130465,980.099121,49.928631,1.304653,-336.676331,982.000671,0.000000
152.170013,220.220703,-336.809753,-0.001677,0.005136,0.130465,979.590637,49.902725,1.304653,-336.809753,982.000671,0.000000
152.650009,220.117554,-336.809753,-0.001681,0.005136,0.130456,979.131775,49.879349,1.304562,-336.809753,0.130465,0.000000
153.130005,219.919464,-336.809753,-0.001673,0.005125,0.130170,978.250610,49.834461,1.301701,-336.809753,0.129710,0.000000
153.610001,219.127411,-336.854248,-0.001677,0.005094,0.129389,974.727417,49.654984,1.293889,-336.854248,0.128912,0.000000
154.090012,217.800293,-336.854248,-0.001660,0.005068,0.128739,968.824097,49.354252,1.287394,-336.854248,0.128114,0.000000
154.570007,216.734192,-336.898712,-0.001634,0.005034,0.127855,964.081848,49.112671,1.278553,-336.898712,0.127316,0.000000
155.050003,216.279510,-336.943207,-0.001634,0.005013,0.127334,962.059326,49.009640,1.273345,-336.943207,0.126511,0.000000
155.530014,215.990173,-337.032166,-0.001617,0.004977,0.126406,960.772278,48.944073,1.264064,-337.032166,0.125713,0.000000
156.010010,215.463654,-337.076660,-0.001625,0.004939,0.125462,958.430176,48.824764,1.254617,-337.076660,0.124915,0.000000
156.490005,215.020508,-336.987671,-0.001621,0.004909,0.124680,956.458984,48.724342,1.246805,-336.987671,0.124108,0.000000
156.970001,214.282104,-337.076660,-0.001604,0.004878,0.123908,953.174377,48.557018,1.239084,-337.076660,0.123310,0.000000
157.450012,213.104279,-337.121124,-0.001617,0.004851,0.123224,947.935181,48.290119,1.232241,-337.121124,0.122513,0.000000
157.930008,211.261047,-337.165619,-0.001625,0.004818,0.122366,939.736084,47.872440,1.223657,-337.165619,0.121715,0.000000
158.410004,209.226776,-337.165619,-0.001630,0.004792,0.121706,930.687195,47.411465,1.217056,-337.165619,0.120908,0.000000
158.890015,206.698730,-337.165619,-0.001621,0.004762,0.120943,919.441895,46.838600,1.209425,-337.165619,0.120110,0.000000
159.370010,203.640442,-337.210083,-0.001604,0.004728,0.120084,905.837952,46.145584,1.200841,-337.210083,0.119312,0.000000
159.850006,200.233246,-337.254578,-0.001613,0.004696,0.119286,890.681946,45.373501,1.192863,-337.254578,0.118514,0.000000
160.330002,196.968658,-337.299042,-0.001617,0.004668,0.118558,876.160339,44.633736,1.185580,-337.299042,0.117709,0.000000
160.810013,193.579681,-337.299042,-0.001608,0.004637,0.117777,861.085449,43.865784,1.177768,-337.299042,0.116911,0.000000
161.290009,190.189240,-337.343536,-0.001613,0.004608,0.117040,846.003967,43.097500,1.170395,-337.343536,0.116113,0.000000
161.770004,186.887405,-337.343536,-0.001600,0.004577,0.116251,831.316711,42.349289,1.162508,-337.343536,0.115315,0.000000
162.250015,183.292526,-337.432495,-0.001617,0.004542,0.115376,815.325867,41.534679,1.153757,-337.432495,0.114508,0.000000
162.730011,179.162918,-337.432495,-0.001613,0.004508,0.114508,796.956482,40.598900,1.145082,-337.432495,0.113710,0.000000
163.210007,177.410538,-337.476990,-0.001621,0.004488,0.113987,789.161499,40.201805,1.139874,-337.476990,0.112912,0.000000
163.690002,173.231018,-337.521454,-0.001613,0.004457,0.113199,770.570068,39.254711,1.131986,-337.521454,0.112115,0.000000
164.170013,168.369705,-337.521454,-0.001625,0.004415,0.112131,748.945862,38.153118,1.121313,-337.521454,0.111308,0.000000
164.650009,164.444901,-337.610413,-0.001617,0.004384,0.111343,731.487427,37.263748,1.113425,-337.610413,0.110510,0.000000
165.130005,161.711685,-337.654907,-0.001600,0.004359,0.110726,719.329529,36.644394,1.107263,-337.654907,0.109712,0.000000
165.610001,157.167984,-337.610413,-0.001604,0.004321,0.109756,699.118103,35.614777,1.097559,-337.610413,0.108914,0.000000
166.090012,153.271866,-337.654907,-0.001617,0.004289,0.108949,681.787292,34.731899,1.089490,-337.654907,0.108107,0.000000
166.570007,149.335876,-337.654907,-0.001630,0.004257,0.108134,664.279175,33.839993,1.081344,-337.654907,0.107309,0.000000
167.050003,146.601181,-337.699371,-0.001613,0.004234,0.107544,652.114624,33.220303,1.075440,-337.699371,0.106511,0.000000
167.530014,141.989716,-337.788330,-0.001608,0.004194,0.106530,631.601807,32.175331,1.065297,-337.788330,0.105714,0.000000
168.010010,138.441376,-337.743866,-0.001617,0.004163,0.105748,615.817993,31.371264,1.057485,-337.743866,0.104908,0.000000
168.490005,134.366882,-337.788330,-0.001617,0.004127,0.104829,597.693726,30.447971,1.048295,-337.788330,0.104110,0.000000
168.970001,132.017960,-337.832825,-0.001613,0.004107,0.104309,587.245239,29.915697,1.043087,-337.832825,0.103312,0.000000
169.450012,127.665298,-337.788330,-0.001604,0.004070,0.103373,567.883606,28.929369,1.033731,-337.788330,0.102515,0.000000
169.930008,124.120682,-337.921783,-0.001613,0.004038,0.102557,552.116394,28.126150,1.025570,-337.921783,0.101708,0.000000
170.410004,120.100174,-337.921783,-0.001625,0.004005,0.101717,534.232239,27.215088,1.017168,-337.921783,0.100910,0.000000
170.890015,117.124176,-337.966278,-0.001604,0.003976,0.100996,520.994385,26.540718,1.009961,-337.966278,0.100112,0.000000
171.370010,113.020996,-337.966278,-0.001604,0.003942,0.100121,502.742493,25.610924,1.001211,-337.966278,0.099314,0.000000
171.850006,109.977982,-337.966278,-0.001600,0.003914,0.099410,489.206482,24.921366,0.994095,-337.966278,0.098507,0.000000
172.330002,105.799957,-338.010742,-0.001630,0.003878,0.098500,470.621704,23.974613,0.984996,-338.010742,0.097709,0.000000
172.810013,103.243622,-338.055237,-0.001617,0.003856,0.097944,459.250580,23.395338,0.979440,-338.055237,0.096911,0.000000
173.290009,99.300201,-338.055237,-0.001625,0.003821,0.097060,441.709351,22.501747,0.970598,-338.055237,0.096114,0.000000
173.770004,95.472946,-338.055237,-0.001604,0.003787,0.096183,424.684875,21.634480,0.961833,-338.055237,0.095308,0.000000
174.250015,91.730972,-338.144196,-0.001608,0.003753,0.095325,408.039734,20.786535,0.953249,-338.144196,0.094510,0.000000
174.730011,88.925522,-338.188660,-0.001617,0.003730,0.094743,395.560486,20.150810,0.947435,-338.188660,0.093712,0.000000
175.210007,85.382034,-338.144196,-0.001613,0.003697,0.093911,379.798248,19.347845,0.939108,-338.144196,0.092915,0.000000
175.690002,81.611755,-338.144196,-0.001613,0.003663,0.093036,363.027222,18.493488,0.930357,-338.144196,0.092108,0.000000
176.170013,78.130447,-338.277618,-0.001591,0.003628,0.092143,347.541595,17.704613,0.921425,-338.277618,0.091310,0.000000
176.650009,74.913528,-338.322113,-0.001613,0.003601,0.091475,333.232025,16.975649,0.914749,-338.322113,0.090512,0.000000
177.130005,71.356613,-338.366608,-0.001604,0.003568,0.090633,317.410065,16.169640,0.906331,-338.366608,0.089714,0.000000
177.610016,67.529373,-338.366608,-0.001617,0.003535,0.089784,300.385651,15.302375,0.897838,-338.366608,0.088907,0.000000
178.090012,64.095734,-338.322113,-0.001600,0.003502,0.088942,285.112061,14.524301,0.889420,-338.322113,0.088109,0.000000
178.570007,61.022163,-338.322113,-0.001608,0.003473,0.088205,271.440125,13.827821,0.882047,-338.322113,0.087311,0.000000
179.050003,58.517220,-338.455566,-0.001621,0.003450,0.087632,260.297607,13.260192,0.876324,-338.455566,0.086514,0.000000
179.530014,54.484795,-338.455566,-0.001617,0.003409,0.086592,242.360474,12.346432,0.865923,-338.455566,0.085707,0.000000
180.010010,51.578804,-338.455566,-0.001613,0.003380,0.085846,229.433975,11.687924,0.858460,-338.455566,0.084909,0.000000
180.490005,48.615089,-338.455566,-0.001604,0.003351,0.085127,216.250717,11.016336,0.851268,-338.455566,0.084111,0.000000
180.970001,45.177719,-338.588989,-0.001608,0.003316,0.084234,200.960526,10.237417,0.842336,-338.588989,0.083313,0.000000
181.450012,41.742958,-338.588989,-0.001617,0.003284,0.083408,185.681946,9.459089,0.834085,-338.588989,0.082508,0.000000
181.930008,38.613167,-338.588989,-0.001613,0.003253,0.082620,171.759949,8.749868,0.826197,-338.588989,0.081710,0.000000
182.410004,35.936180,-338.588989,-0.001613,0.003222,0.081848,159.852112,8.143255,0.818476,-338.588989,0.080912,0.000000
182.890015,32.772133,-338.588989,-0.001613,0.003192,0.081068,145.777725,7.426271,0.810679,-338.588989,0.080105,0.000000
183.370010,29.548500,-338.677948,-0.001617,0.003159,0.080235,131.438293,6.695786,0.802352,-338.677948,0.079307,0.000000
183.850006,26.008728,-338.766937,-0.001621,0.003121,0.079263,115.692604,5.893662,0.792633,-338.766937,0.078509,0.000000
184.330002,24.151711,-338.766937,-0.001604,0.003101,0.078770,107.432175,5.472856,0.787697,-338.766937,0.077711,0.000000
184.810013,21.195816,-338.722443,-0.001613,0.003070,0.077981,94.283699,4.803041,0.779809,-338.722443,0.076905,0.000000
185.290009,18.034370,-338.766937,-0.001608,0.003036,0.077113,80.220886,4.086647,0.771134,-338.766937,0.076107,0.000000
185.770004,15.467239,-338.855896,-0.001604,0.003006,0.076350,68.801720,3.504926,0.763504,-338.855896,0.075309,0.000000
186.250015,12.707581,-338.900360,-0.001600,0.002976,0.075587,56.526142,2.879579,0.755874,-338.900360,0.074511,0.000000
186.730011,10.562721,-338.944855,-0.001634,0.002947,0.074858,46.985332,2.393547,0.748577,-338.944855,0.073706,0.000000
187.210007,6.915703,-338.944855,-0.001608,0.002909,0.073878,30.762583,1.567121,0.738781,-338.944855,0.072908,0.000000
187.690002,5.043411,-338.944855,-0.001613,0.002884,0.073262,22.434214,1.142853,0.732619,-338.944855,0.072110,0.000000
188.170013,2.286743,-339.033813,-0.001617,0.002848,0.072335,10.171942,0.518183,0.723354,-339.033813,0.071312,0.000000
188.650009,-0.237198,-339.078278,-0.001604,0.002811,0.071389,-1.055109,-0.053750,0.713892,-339.078278,0.070505,0.000000
189.130005,-0.485947,-339.033813,-0.001617,0.002784,0.070722,-2.161599,-0.110117,0.707215,-339.033813,0.069707,0.000000
189.610016,-0.071869,-339.033813,-0.001617,0.002758,0.070045,-0.319689,-0.016286,0.700448,-339.033813,0.068909,0.000000
190.090012,-0.081917,-339.078278,-0.001621,0.002722,0.069144,-0.364384,-0.018563,0.691440,-339.078278,0.068111,0.000000
190.570007,-0.100166,-339.122772,-0.001621,0.002695,0.068441,-0.445562,-0.022698,0.684415,-339.122772,0.067305,0.000000
191.050003,-0.116554,-339.167267,-0.001656,0.002658,0.067513,-0.518459,-0.026412,0.675134,-339.167267,0.066507,0.000000
191.530014,-0.115059,-339.167267,-0.001738,0.002616,0.066437,-0.511808,-0.026073,0.664370,-339.167267,0.065709,0.000000
192.010010,-0.110962,-339.167267,-0.001781,0.002595,0.065925,-0.493583,-0.025144,0.659253,-339.167267,0.064911,0.000000
192.490005,-0.113571,-339.211731,-0.001837,0.002563,0.065094,-0.505190,-0.025736,0.650941,-339.211731,0.064104,0.000000
192.970016,-0.094955,-339.300690,-0.001919,0.002529,0.064234,-0.422383,-0.021517,0.642342,-339.300690,0.063308,0.000000
193.450012,-0.103516,-339.345184,-0.001957,0.002504,0.063601,-0.460460,-0.023457,0.636014,-339.345184,0.062510,0.000000
193.930008,-0.093094,-339.434143,-0.002026,0.002468,0.062691,-0.414102,-0.021095,0.626915,-339.434143,0.061712,0.000000
194.410004,-0.085648,-339.345184,-0.002052,0.002443,0.062059,-0.380979,-0.019408,0.620587,-339.345184,0.060905,0.000000
194.890015,-0.094208,-339.300690,-0.002108,0.002403,0.061035,-0.419057,-0.021348,0.610352,-339.300690,0.060107,0.000000
195.370010,-0.104263,-339.434143,-0.002177,0.002377,0.060375,-0.463786,-0.023626,0.603751,-339.434143,0.059309,0.000000
195.850006,-0.096443,-339.523102,-0.002220,0.002346,0.059586,-0.429001,-0.021854,0.595864,-339.523102,0.058511,0.000000
196.330002,-0.102776,-339.478607,-0.002242,0.002315,0.058789,-0.457169,-0.023289,0.587885,-339.478607,0.057705,0.000000
196.800003,-0.064789,-339.567566,-0.002259,0.002294,0.058277,-0.288195,-0.014681,0.582768,-339.567566,0.058156,0.000000