File: Data/sima compression 500bar/P2-21-500bar-1re_11072024_164230.csv
Time (sec),S:Load (lbs),S:HL1 (DIM),S:LVDT (in),S:Position (in),Ch:Position (mm),Ch:Load (N),Ch:Stress (MPa),Ch:Strain (mm/mm),Ch:HL1 (DIM),Set Point (),Cycles ()
0.010000,-0.084900,-293.129456,-0.009365,-0.009457,-0.240195,-0.377654,-0.019239,-2.401955,-293.129456,-0.240186,0.000000
0.480000,-0.075592,-293.129456,-0.009360,-0.009379,-0.238218,-0.336250,-0.017129,-2.382183,-293.129456,-0.237637,0.000000
0.950000,-0.099052,-293.173950,-0.009153,-0.009086,-0.230794,-0.440607,-0.022446,-2.307938,-293.173950,-0.229798,0.000000
1.420000,-0.122879,-293.173950,-0.008839,-0.008784,-0.223120,-0.546593,-0.027845,-2.231196,-293.173950,-0.221975,0.000000
1.890000,-0.082664,-293.262909,-0.008532,-0.008477,-0.215315,-0.367710,-0.018732,-2.153151,-293.262909,-0.214136,0.000000
2.360000,-0.036491,-293.307404,-0.008213,-0.008171,-0.207535,-0.162322,-0.008269,-2.075349,-293.307404,-0.206313,0.000000
2.830000,-0.071121,-293.307404,-0.007869,-0.007854,-0.199496,-0.316363,-0.016116,-1.994958,-293.307404,-0.198490,0.000000
3.300000,-0.059952,-293.351868,-0.007562,-0.007547,-0.191691,-0.266679,-0.013585,-1.916913,-293.351868,-0.190651,0.000000
3.770000,-0.017876,-293.351868,-0.007252,-0.007240,-0.183887,-0.079515,-0.004051,-1.838868,-293.351868,-0.182829,0.000000
4.240000,0.007080,-293.396362,-0.007157,-0.000004,-0.000112,0.031494,0.001604,-0.001120,-293.396362,0.000123,0.000000
4.710000,0.119530,-293.485321,-0.007166,-0.000003,-0.000077,0.531695,0.027086,-0.000772,-293.485321,0.000565,0.000000
5.180000,0.155281,-293.485321,-0.007157,0.000014,0.000365,0.690725,0.035187,0.003649,-293.485321,0.001344,0.000000
5.650000,0.332527,-293.574280,-0.007136,0.000048,0.001223,1.479155,0.075352,0.012233,-293.574280,0.002135,0.000000
6.120000,0.562286,-293.529785,-0.007105,0.000078,0.001977,2.501175,0.127416,0.019772,-293.529785,0.002914,0.000000
6.590000,1.058655,-293.574280,-0.007088,0.000115,0.002923,4.709132,0.239895,0.029235,-293.574280,0.003696,0.000000
7.060000,1.477951,-293.663239,-0.007062,0.000139,0.003531,6.574255,0.334908,0.035306,-293.663239,0.004484,0.000000
7.530000,2.014534,-293.707733,-0.007036,0.000168,0.004275,8.961095,0.456500,0.042754,-293.707733,0.005264,0.000000
8.000000,2.655388,-293.663239,-0.007028,0.000202,0.005135,11.811755,0.601719,0.051353,-293.663239,0.006045,0.000000
8.470000,3.576263,-293.618744,-0.006993,0.000239,0.006062,15.908014,0.810393,0.060619,-293.618744,0.006834,0.000000
8.940001,4.119560,-293.707733,-0.006976,0.000262,0.006661,18.324718,0.933506,0.066614,-293.707733,0.007615,0.000000
9.410001,5.121986,-293.796692,-0.006954,0.000299,0.007589,22.783733,1.160659,0.075895,-293.796692,0.008395,0.000000
9.880000,5.756882,-293.841156,-0.006907,0.000325,0.008257,25.607889,1.304528,0.082571,-293.841156,0.009185,0.000000
10.350000,6.754837,-293.841156,-0.006890,0.000360,0.009132,30.047016,1.530668,0.091322,-293.841156,0.009965,0.000000
10.820001,7.586349,-293.796692,-0.006868,0.000387,0.009826,33.745770,1.719091,0.098256,-293.796692,0.010746,0.000000
11.290001,8.708679,-293.885651,-0.006855,0.000418,0.010623,38.738140,1.973415,0.106234,-293.885651,0.011535,0.000000
11.760000,9.595665,-293.974609,-0.006821,0.000450,0.011421,42.683651,2.174409,0.114213,-293.974609,0.012315,0.000000
12.230000,10.641289,-294.019073,-0.006804,0.000480,0.012193,47.334816,2.411350,0.121934,-294.019073,0.013096,0.000000
12.700001,11.514877,-294.063568,-0.006786,0.000507,0.012888,51.220734,2.609308,0.128883,-294.063568,0.013885,0.000000
13.170001,12.127052,-294.019073,-0.006756,0.000529,0.013426,53.943821,2.748029,0.134258,-294.019073,0.014666,0.000000
13.640000,13.931946,-294.063568,-0.006743,0.000573,0.014561,61.972389,3.157024,0.145612,-294.063568,0.015445,0.000000
14.110001,15.103432,-294.108063,-0.006726,0.000604,0.015333,67.183418,3.422487,0.153334,-294.108063,0.016236,0.000000
14.580001,16.274544,-294.197021,-0.006700,0.000634,0.016105,72.392784,3.687864,0.161055,-294.197021,0.017015,0.000000
15.050001,16.752663,-294.197021,-0.006679,0.000652,0.016564,74.519562,3.796208,0.165642,-294.197021,0.017797,0.000000
15.520000,18.892693,-294.197021,-0.006635,0.000698,0.017736,84.038895,4.281146,0.177360,-294.197021,0.018585,0.000000
15.990001,19.976669,-294.241486,-0.006648,0.000727,0.018473,88.860664,4.526778,0.184733,-294.241486,0.019367,0.000000
16.460001,21.484406,-294.241486,-0.006614,0.000762,0.019348,95.567406,4.868436,0.193484,-294.241486,0.020146,0.000000
16.930000,21.932365,-294.285980,-0.006562,0.000781,0.019843,97.560036,4.969945,0.198434,-294.285980,0.020935,0.000000
17.400002,24.149849,-294.374939,-0.006554,0.000825,0.020953,107.423897,5.472434,0.209532,-294.374939,0.021716,0.000000
17.870001,25.112801,-294.374939,-0.006523,0.000852,0.021630,111.707314,5.690642,0.216299,-294.374939,0.022496,0.000000
18.340000,26.528557,-294.419403,-0.006497,0.000884,0.022454,118.004913,6.011457,0.224535,-294.419403,0.023286,0.000000
18.810001,27.034615,-294.463898,-0.006472,0.000903,0.022947,120.255974,6.126132,0.229471,-294.463898,0.024066,0.000000
19.280001,29.068886,-294.552856,-0.006454,0.000947,0.024066,129.304855,6.587103,0.240659,-294.552856,0.024847,0.000000
19.750000,29.892204,-294.597351,-0.006428,0.000976,0.024794,132.967163,6.773670,0.247941,-294.597351,0.025636,0.000000
20.220001,31.261787,-294.508362,-0.006394,0.001006,0.025540,139.059372,7.084023,0.255405,-294.508362,0.026417,0.000000
20.690001,32.068718,-294.552856,-0.006368,0.001031,0.026191,142.648788,7.266875,0.261915,-294.552856,0.027197,0.000000
21.160002,33.562675,-294.597351,-0.006325,0.001070,0.027171,149.294235,7.605411,0.271710,-294.597351,0.027986,0.000000
21.630001,34.229225,-294.641815,-0.006321,0.001096,0.027848,152.259201,7.756454,0.278477,-294.641815,0.028767,0.000000
22.100000,35.506088,-294.730774,-0.006303,0.001132,0.028741,157.938965,8.045794,0.287410,-294.730774,0.029546,0.000000
22.570002,36.279137,-294.730774,-0.006260,0.001158,0.029409,161.377655,8.220970,0.294086,-294.730774,0.030337,0.000000
23.040001,37.264801,-294.775269,-0.006234,0.001190,0.030232,165.762115,8.444324,0.302322,-294.775269,0.031116,0.000000
23.510000,38.048645,-294.775269,-0.006213,0.001221,0.031004,169.248825,8.621946,0.310043,-294.775269,0.031898,0.000000
23.980001,38.680939,-294.819733,-0.006178,0.001253,0.031819,172.061401,8.765226,0.318189,-294.819733,0.032686,0.000000
24.450001,39.683365,-294.864227,-0.006148,0.001281,0.032547,176.520416,8.992379,0.325471,-294.864227,0.033468,0.000000
24.920002,40.446724,-294.908691,-0.006114,0.001317,0.033449,179.916016,9.165359,0.334494,-294.908691,0.034247,0.000000
25.390001,41.109924,-294.908691,-0.006066,0.001343,0.034100,182.866074,9.315642,0.341004,-294.908691,0.035036,0.000000
25.860001,41.461815,-294.953186,-0.006049,0.001371,0.034820,184.431366,9.395382,0.348195,-294.953186,0.035817,0.000000
26.330002,42.347313,-294.997681,-0.006019,0.001403,0.035636,188.370255,9.596038,0.356355,-294.997681,0.036597,0.000000
26.800001,42.123894,-294.997681,-0.006002,0.001420,0.036078,187.376434,9.545410,0.360776,-294.997681,0.037387,0.000000
27.270000,44.215134,-295.042145,-0.005950,0.001467,0.037274,196.678741,10.019293,0.372736,-295.042145,0.038167,0.000000
27.740002,44.346214,-295.086639,-0.005924,0.001495,0.037976,197.261810,10.048995,0.379761,-295.086639,0.038948,0.000000
28.210001,45.184792,-295.131104,-0.005885,0.001529,0.038827,200.991989,10.239020,0.388270,-295.131104,0.039737,0.000000
28.680002,44.638153,-295.175598,-0.005872,0.001542,0.039174,198.560425,10.115149,0.391737,-295.175598,0.040518,0.000000
29.150002,46.406921,-295.175598,-0.005842,0.001588,0.040335,206.428299,10.515959,0.403349,-295.175598,0.041298,0.000000
29.620001,46.794189,-295.264557,-0.005799,0.001618,0.041098,208.150955,10.603715,0.410979,-295.264557,0.042087,0.000000
30.090002,47.527763,-295.220062,-0.005769,0.001650,0.041914,211.414047,10.769945,0.419139,-295.220062,0.042868,0.000000
30.560001,47.439880,-295.220062,-0.005739,0.001672,0.042477,211.023132,10.750031,0.424771,-295.220062,0.043647,0.000000
31.030001,48.830688,-295.309021,-0.005700,0.001714,0.043526,217.209747,11.065192,0.435263,-295.309021,0.044438,0.000000
31.500002,48.918571,-295.398010,-0.005678,0.001740,0.044186,217.600677,11.085107,0.441864,-295.398010,0.045217,0.000000
31.970001,50.043510,-295.353516,-0.005639,0.001778,0.045157,222.604645,11.340022,0.451568,-295.353516,0.045999,0.000000
32.440002,49.422768,-295.398010,-0.005614,0.001793,0.045538,219.843445,11.199359,0.455383,-295.398010,0.046787,0.000000
32.910000,50.969597,-295.398010,-0.005596,0.001836,0.046622,226.724091,11.549876,0.466223,-295.398010,0.047569,0.000000
33.380001,51.096207,-295.442474,-0.005562,0.001862,0.047290,227.287277,11.578567,0.472900,-295.442474,0.048348,0.000000
33.850002,52.061020,-295.531433,-0.005519,0.001897,0.048192,231.578979,11.797195,0.481923,-295.531433,0.049137,0.000000
34.320004,52.276627,-295.531433,-0.005480,0.001920,0.048774,232.538055,11.846053,0.487737,-295.531433,0.049918,0.000000
34.790001,53.447365,-295.575928,-0.005458,0.001955,0.049667,237.745758,12.111345,0.496669,-295.575928,0.050699,0.000000
35.260002,54.026405,-295.620392,-0.005424,0.001986,0.050447,240.321457,12.242558,0.504466,-295.620392,0.051488,0.000000
35.730003,55.606010,-295.620392,-0.005398,0.002025,0.051428,247.347885,12.600502,0.514276,-295.620392,0.052268,0.000000
36.200001,55.960876,-295.620392,-0.005385,0.002048,0.052017,248.926407,12.680917,0.520166,-295.620392,0.053049,0.000000
36.670002,57.258972,-295.709351,-0.005346,0.002084,0.052928,254.700623,12.975069,0.529280,-295.709351,0.053838,0.000000
37.140003,57.545700,-295.753845,-0.005307,0.002111,0.053612,255.976059,13.040042,0.536123,-295.753845,0.054619,0.000000
37.610001,58.820328,-295.842804,-0.005299,0.002147,0.054524,261.645874,13.328877,0.545237,-295.842804,0.055399,0.000000
38.080002,59.484268,-295.842804,-0.005260,0.002174,0.055217,264.599243,13.479328,0.552171,-295.842804,0.056188,0.000000
38.550003,59.891647,-295.798309,-0.005217,0.002200,0.055885,266.411346,13.571641,0.558847,-295.798309,0.056969,0.000000
39.020000,61.043762,-295.887299,-0.005200,0.002235,0.056778,271.536224,13.832714,0.567780,-295.887299,0.057750,0.000000
39.490002,61.180054,-295.842804,-0.005182,0.002264,0.057506,272.142456,13.863598,0.575062,-295.842804,0.058539,0.000000
39.960003,62.814026,-295.887299,-0.005152,0.002298,0.058374,279.410736,14.233861,0.583737,-295.887299,0.059318,0.000000
40.430000,64.139297,-295.931763,-0.005105,0.002334,0.059293,285.305847,14.534172,0.592927,-295.931763,0.060100,0.000000
40.900002,64.270370,-295.976257,-0.005088,0.002359,0.059925,285.888885,14.563874,0.599255,-295.976257,0.060888,0.000000
41.370003,65.240402,-296.020721,-0.005053,0.002391,0.060742,290.203796,14.783687,0.607415,-296.020721,0.061670,0.000000
41.840000,65.629532,-296.065216,-0.005032,0.002415,0.061340,291.934723,14.871865,0.613395,-296.065216,0.062449,0.000000
42.310001,67.045288,-296.109680,-0.005023,0.002454,0.062319,298.232330,15.192679,0.623191,-296.109680,0.063238,0.000000
42.780003,67.486923,-296.198639,-0.004993,0.002479,0.062961,300.196838,15.292755,0.629610,-296.198639,0.064019,0.000000
43.250004,68.821884,-296.154175,-0.004958,0.002515,0.063872,306.135040,15.595262,0.638724,-296.154175,0.064800,0.000000
43.720001,69.280273,-296.198639,-0.004937,0.002542,0.064557,308.174042,15.699134,0.645567,-296.198639,0.065589,0.000000
44.190002,70.375793,-296.198639,-0.004907,0.002576,0.065424,313.047150,15.947383,0.654242,-296.198639,0.066369,0.000000
44.660004,71.311188,-296.287628,-0.004889,0.002605,0.066161,317.208008,16.159346,0.661615,-296.287628,0.067150,0.000000
45.130001,71.758408,-296.287628,-0.004859,0.002632,0.066855,319.197327,16.260687,0.668549,-296.287628,0.067939,0.000000
45.600002,73.008469,-296.376587,-0.004833,0.002665,0.067697,324.757874,16.543955,0.676966,-296.376587,0.068720,0.000000
46.070004,72.852814,-296.376587,-0.004812,0.002686,0.068225,324.065491,16.508684,0.682250,-296.376587,0.069500,0.000000
46.540001,75.432983,-296.465546,-0.004760,0.002732,0.069404,335.542664,17.093357,0.694044,-296.465546,0.070290,0.000000
47.010002,75.416962,-296.465546,-0.004743,0.002755,0.069969,335.471405,17.089727,0.699691,-296.465546,0.071070,0.000000
47.480003,76.912048,-296.510010,-0.004725,0.002791,0.070879,342.121887,17.428520,0.708790,-296.510010,0.071851,0.000000
47.950001,76.810760,-296.465546,-0.004691,0.002810,0.071365,341.671326,17.405567,0.713650,-296.465546,0.072640,0.000000
48.420002,78.265625,-296.510010,-0.004682,0.002847,0.072310,348.142883,17.735245,0.723097,-296.510010,0.073419,0.000000
48.890003,79.312729,-296.554504,-0.004661,0.002879,0.073133,352.800629,17.972521,0.731333,-296.554504,0.074201,0.000000
49.360001,80.765350,-296.643463,-0.004626,0.002914,0.074019,359.262207,18.301689,0.740189,-296.643463,0.074989,0.000000
49.830002,80.955643,-296.643463,-0.004587,0.002937,0.074599,360.108673,18.344810,0.745988,-296.643463,0.075771,0.000000
50.300003,82.370285,-296.687958,-0.004583,0.002972,0.075492,366.401337,18.665375,0.754920,-296.687958,0.076550,0.000000
50.770004,83.500427,-296.732422,-0.004553,0.003004,0.076299,371.428436,18.921469,0.762989,-296.732422,0.077341,0.000000
51.240002,84.665588,-296.732422,-0.004510,0.003036,0.077123,376.611359,19.185495,0.771225,-296.732422,0.078120,0.000000
51.710003,85.480331,-296.776917,-0.004480,0.003063,0.077808,380.235504,19.370121,0.778084,-296.776917,0.078901,0.000000
52.180004,87.122864,-296.776917,-0.004471,0.003100,0.078736,387.541840,19.742323,0.787364,-296.776917,0.079690,0.000000
52.650002,87.861664,-296.821381,-0.004454,0.003128,0.079456,390.828186,19.909739,0.794555,-296.821381,0.080470,0.000000
53.120003,88.868927,-296.865875,-0.004428,0.003160,0.080253,395.308716,20.137987,0.802534,-296.865875,0.081251,0.000000
53.590004,89.695221,-296.865875,-0.004398,0.003188,0.080974,398.984283,20.325228,0.809740,-296.865875,0.082040,0.000000
54.060001,91.436066,-296.954834,-0.004393,0.003221,0.081823,406.727936,20.719707,0.818234,-296.954834,0.082821,0.000000
54.530003,92.261978,-297.043793,-0.004359,0.003250,0.082543,410.401764,20.906862,0.825425,-297.043793,0.083601,0.000000
55.000004,93.462143,-296.910339,-0.004346,0.003282,0.083375,415.740387,21.178823,0.833752,-296.910339,0.084391,0.000000
55.470001,94.182312,-296.999298,-0.004329,0.003306,0.083966,418.943848,21.342018,0.839656,-296.999298,0.085171,0.000000
55.940002,95.781647,-297.088287,-0.004281,0.003340,0.084841,426.058044,21.704432,0.848407,-297.088287,0.085952,0.000000
56.410004,97.226822,-297.177246,-0.004264,0.003373,0.085673,432.486511,22.031914,0.856734,-297.177246,0.086741,0.000000
56.880001,98.456772,-297.177246,-0.004234,0.003406,0.086515,437.957581,22.310623,0.865151,-297.177246,0.087520,0.000000
57.350002,99.475586,-297.221710,-0.004221,0.003433,0.087209,442.489502,22.541489,0.872085,-297.221710,0.088302,0.000000
57.820004,99.369080,-297.221710,-0.004204,0.003450,0.087625,442.015747,22.517355,0.876249,-297.221710,0.089090,0.000000
58.290001,102.246033,-297.221710,-0.004178,0.003496,0.088797,454.813080,23.169281,0.887967,-297.221710,0.089872,0.000000
58.760002,103.297241,-297.310669,-0.004152,0.003526,0.089551,459.489075,23.407490,0.895506,-297.310669,0.090651,0.000000
59.230003,105.021332,-297.310669,-0.004122,0.003559,0.090400,467.158203,23.798176,0.903999,-297.310669,0.091442,0.000000
59.700005,105.362793,-297.310669,-0.004087,0.003581,0.090946,468.677124,23.875549,0.909465,-297.310669,0.092221,0.000000
60.170002,108.170853,-297.444122,-0.004096,0.003625,0.092082,481.167969,24.511866,0.920820,-297.444122,0.093002,0.000000
60.640003,109.024704,-297.444122,-0.004061,0.003650,0.092716,484.966095,24.705351,0.927163,-297.444122,0.093791,0.000000
61.110004,110.614731,-297.533081,-0.004066,0.003683,0.093549,492.038910,25.065657,0.935490,-297.533081,0.094571,0.000000
61.580002,110.806870,-297.488586,-0.004036,0.003701,0.093999,492.893585,25.109196,0.939986,-297.488586,0.095352,0.000000
62.050003,113.888626,-297.488586,-0.004005,0.003749,0.095222,506.601898,25.807531,0.952219,-297.488586,0.096141,0.000000
62.520004,114.875412,-297.488586,-0.003984,0.003775,0.095890,510.991364,26.031141,0.958896,-297.488586,0.096922,0.000000
62.990002,116.531357,-297.622040,-0.003984,0.003808,0.096731,518.357361,26.406384,0.967313,-297.622040,0.097702,0.000000
63.460003,117.467499,-297.622040,-0.003958,0.003834,0.097373,522.521545,26.618517,0.973732,-297.622040,0.098492,0.000000
63.930004,119.594498,-297.666534,-0.003928,0.003872,0.098336,531.982910,27.100500,0.983361,-297.666534,0.099272,0.000000
64.400002,120.579041,-297.666534,-0.003915,0.003899,0.099030,536.362366,27.323601,0.990295,-297.666534,0.100053,0.000000
64.870003,122.868759,-297.666534,-0.003898,0.003933,0.099888,546.547546,27.842459,0.998879,-297.666534,0.100842,0.000000
65.340004,123.767670,-297.844452,-0.003876,0.003955,0.100460,550.546082,28.046156,1.004602,-297.844452,0.101623,0.000000
65.810005,125.609055,-297.844452,-0.003854,0.003991,0.101363,558.737000,28.463419,1.013625,-297.844452,0.102403,0.000000
66.280006,127.331268,-297.799957,-0.003842,0.004023,0.102177,566.397766,28.853678,1.021770,-297.799957,0.103191,0.000000
66.750000,129.186813,-297.888916,-0.003824,0.004055,0.102993,574.651672,29.274149,1.029930,-297.888916,0.103973,0.000000
67.220001,130.018692,-297.933411,-0.003811,0.004079,0.103608,578.352051,29.462658,1.036077,-297.933411,0.104752,0.000000
67.690002,130.962646,-297.977905,-0.003803,0.004112,0.104449,582.550964,29.676561,1.044495,-297.977905,0.105543,0.000000
68.160004,134.014984,-298.022369,-0.003764,0.004143,0.105222,596.128418,30.368229,1.052216,-298.022369,0.106322,0.000000
68.630005,135.780411,-298.066864,-0.003742,0.004176,0.106062,603.981445,30.768282,1.060618,-298.066864,0.107103,0.000000
69.100006,137.020401,-298.066864,-0.003747,0.004203,0.106757,609.497192,31.049267,1.067567,-298.066864,0.107892,0.000000
69.570000,138.435791,-298.066864,-0.003734,0.004234,0.107555,615.793152,31.369999,1.075546,-298.066864,0.108673,0.000000
70.040001,141.125076,-298.155823,-0.003708,0.004265,0.108325,627.755676,31.979399,1.083252,-298.155823,0.109453,0.000000
70.510002,142.582169,-298.155823,-0.003704,0.004297,0.109150,634.237183,32.309582,1.091503,-298.155823,0.110242,0.000000
70.980003,144.364334,-298.200287,-0.003678,0.004322,0.109791,642.164612,32.713428,1.097907,-298.200287,0.111023,0.000000
71.450005,146.303650,-298.200287,-0.003652,0.004360,0.110737,650.791138,33.152882,1.107369,-298.200287,0.111803,0.000000
71.920006,148.111893,-298.289246,-0.003648,0.004385,0.111386,658.834595,33.562634,1.113864,-298.289246,0.112593,0.000000
72.390007,150.207977,-298.422699,-0.003639,0.004419,0.112246,668.158447,34.037613,1.122464,-298.422699,0.113373,0.000000
72.860001,152.401993,-298.378235,-0.003626,0.004450,0.113026,677.917908,34.534786,1.130260,-298.378235,0.114154,0.000000
73.330002,153.465118,-298.378235,-0.003609,0.004477,0.113712,682.646912,34.775696,1.137119,-298.378235,0.114943,0.000000
73.800003,156.427338,-298.422699,-0.003596,0.004511,0.114587,695.823547,35.446941,1.145869,-298.422699,0.115724,0.000000
74.270004,157.960770,-298.378235,-0.003600,0.004541,0.115350,702.644592,35.794422,1.153500,-298.378235,0.116504,0.000000
74.740005,160.632919,-298.556152,-0.003566,0.004575,0.116201,714.530884,36.399940,1.162008,-298.556152,0.117292,0.000000
75.210007,161.209351,-298.556152,-0.003553,0.004591,0.116617,717.095032,36.530560,1.166172,-298.556152,0.118074,0.000000
75.680000,164.669067,-298.556152,-0.003561,0.004635,0.117736,732.484619,37.314545,1.177360,-298.556152,0.118853,0.000000
76.150002,165.973480,-298.645111,-0.003531,0.004660,0.118360,738.286926,37.610130,1.183597,-298.645111,0.119644,0.000000
76.620003,168.552902,-298.556152,-0.003514,0.004698,0.119323,749.760742,38.194633,1.193226,-298.556152,0.120423,0.000000
77.090004,169.602249,-298.689575,-0.003527,0.004718,0.119842,754.428467,38.432423,1.198419,-298.689575,0.121204,0.000000
77.560005,172.220779,-298.689575,-0.003510,0.004752,0.120709,766.076294,39.025787,1.207094,-298.689575,0.121993,0.000000
78.030006,174.487411,-298.689575,-0.003466,0.004786,0.121577,776.158752,39.539413,1.215769,-298.689575,0.122774,0.000000
78.500000,177.145035,-298.734070,-0.003479,0.004824,0.122522,787.980469,40.141640,1.225216,-298.734070,0.123554,0.000000
78.970001,178.479980,-298.778534,-0.003466,0.004846,0.123086,793.918579,40.444145,1.230863,-298.778534,0.124343,0.000000
79.440002,181.175217,-298.823029,-0.003458,0.004882,0.123996,805.907593,41.054890,1.239962,-298.823029,0.125124,0.000000
79.910004,183.150650,-298.867523,-0.003441,0.004914,0.124812,814.694763,41.502529,1.248122,-298.867523,0.125904,0.000000
80.380005,185.742371,-298.956482,-0.003415,0.004947,0.125652,826.223328,42.089821,1.256525,-298.956482,0.126694,0.000000
80.850006,187.586731,-298.823029,-0.003432,0.004971,0.126260,834.427429,42.507759,1.262596,-298.823029,0.127474,0.000000
81.320007,189.975861,-298.956482,-0.003406,0.005005,0.127136,845.054810,43.049149,1.271361,-298.956482,0.128255,0.000000
81.790001,192.025024,-299.000946,-0.003393,0.005034,0.127855,854.169983,43.513493,1.278553,-299.000946,0.129044,0.000000
82.260002,194.375824,-299.045441,-0.003385,0.005069,0.128741,864.626831,44.046192,1.287409,-299.045441,0.129825,0.000000
82.730003,196.637970,-299.000946,-0.003354,0.005096,0.129434,874.689392,44.558804,1.294343,-299.000946,0.130605,0.000000
83.200005,199.452362,-299.089905,-0.003359,0.005133,0.130379,887.208435,45.196552,1.303790,-299.089905,0.131393,0.000000
83.670006,201.089325,-299.089905,-0.003359,0.005159,0.131047,894.489990,45.567493,1.310467,-299.089905,0.132175,0.000000
84.140007,203.162323,-299.178864,-0.003333,0.005191,0.131863,903.711121,46.037239,1.318627,-299.178864,0.132956,0.000000
84.610001,205.211853,-299.223358,-0.003341,0.005218,0.132547,912.827942,46.501671,1.325470,-299.223358,0.133745,0.000000
85.080002,207.945068,-299.178864,-0.003303,0.005250,0.133337,924.985840,47.121025,1.333373,-299.178864,0.134524,0.000000
85.550003,209.927582,-299.267853,-0.003320,0.005277,0.134040,933.804504,47.570267,1.340398,-299.267853,0.135305,0.000000
86.020004,212.787415,-299.267853,-0.003316,0.005312,0.134933,946.525696,48.218319,1.349330,-299.267853,0.136094,0.000000
86.490005,214.870087,-299.312317,-0.003307,0.005339,0.135617,955.789856,48.690258,1.356173,-299.312317,0.136875,0.000000
86.960007,217.282684,-299.356812,-0.003303,0.005373,0.136476,966.521667,49.236961,1.364757,-299.356812,0.137655,0.000000
87.430008,219.836029,-299.312317,-0.003277,0.005404,0.137257,977.879517,49.815556,1.372569,-299.312317,0.138444,0.000000
87.900002,220.262787,-299.356812,-0.003268,0.005402,0.137222,979.777832,49.912262,1.372221,-299.356812,0.024095,0.000000
88.370003,220.657135,-299.401276,-0.003268,0.005420,0.137664,981.531982,50.001621,1.376642,-299.401276,982.000671,0.000000
88.840004,219.432404,-299.534729,-0.003255,0.005411,0.137439,976.084106,49.724094,1.374386,-299.534729,982.000671,0.000000
89.310005,219.439850,-299.534729,-0.003255,0.005431,0.137950,976.117187,49.725780,1.379503,-299.534729,982.000671,0.000000
89.780006,219.602936,-299.534729,-0.003221,0.005441,0.138202,976.842651,49.762737,1.382017,-299.534729,982.000671,0.000000
90.250008,219.604431,-299.490234,-0.003255,0.005450,0.138418,976.849304,49.763073,1.384181,-299.490234,982.000671,0.000000
90.720001,219.546326,-299.579193,-0.003221,0.005457,0.138609,976.590820,49.749908,1.386089,-299.579193,982.000671,0.000000
91.190002,219.395142,-299.623688,-0.003225,0.005464,0.138783,975.918335,49.715652,1.387830,-299.623688,982.000671,0.000000
91.660004,219.099121,-299.712646,-0.003212,0.005469,0.138922,974.601562,49.648571,1.389223,-299.712646,982.000671,0.000000
92.130005,219.524750,-299.712646,-0.003203,0.005478,0.139130,976.494873,49.745022,1.391297,-299.712646,982.000671,0.000000
92.600006,219.173584,-299.712646,-0.003225,0.005486,0.139337,974.932800,49.665443,1.393371,-299.712646,982.000671,0.000000
93.070007,220.867889,-299.757141,-0.003208,0.005482,0.139242,982.469421,50.049381,1.392417,-299.757141,982.000671,0.000000
93.540001,220.026703,-299.801605,-0.003178,0.005482,0.139234,978.727661,49.858765,1.392342,-299.801605,982.000671,0.000000
94.010002,219.232422,-299.846100,-0.003182,0.005488,0.139407,975.194519,49.678776,1.394068,-299.846100,982.000671,0.000000
94.480003,220.314911,-299.890564,-0.003160,0.005481,0.139225,980.009644,49.924072,1.392251,-299.890564,982.000671,0.000000
94.950005,219.537781,-299.890564,-0.003156,0.005488,0.139399,976.552795,49.747974,1.393992,-299.890564,982.000671,0.000000
95.420006,219.889282,-299.979523,-0.003169,0.005521,0.140239,978.116394,49.827621,1.402394,-299.979523,982.000671,0.000000
95.890007,220.138031,-299.979523,-0.003160,0.005533,0.140526,979.222839,49.883987,1.405256,-299.979523,982.000671,0.000000
96.360008,219.414520,-300.024017,-0.003134,0.005533,0.140535,976.004517,49.720039,1.405347,-300.024017,982.000671,0.000000
96.830002,219.913483,-300.068481,-0.003139,0.005542,0.140769,978.223999,49.833107,1.407693,-300.068481,982.000671,0.000000
97.300003,220.084778,-300.024017,-0.003130,0.005555,0.141098,978.985962,49.871922,1.410979,-300.024017,982.000671,0.000000
97.770004,219.571655,-300.068481,-0.003113,0.005556,0.141116,976.703491,49.755650,1.411160,-300.068481,982.000671,0.000000
98.240005,219.923553,-300.112976,-0.003117,0.005567,0.141402,978.268799,49.835392,1.414022,-300.112976,982.000671,0.000000
98.710007,219.527710,-300.201935,-0.003134,0.005567,0.141411,976.507996,49.745689,1.414112,-300.201935,982.000671,0.000000
99.180008,219.559753,-300.157471,-0.003122,0.005574,0.141575,976.650574,49.752949,1.415748,-300.157471,982.000671,0.000000
99.650002,219.774597,-300.201935,-0.003096,0.005581,0.141749,977.606262,49.801636,1.417489,-300.201935,982.000671,0.000000
100.120003,219.521759,-300.290894,-0.003109,0.005585,0.141853,976.481567,49.744343,1.418533,-300.290894,982.000671,0.000000
100.590004,219.368713,-300.335388,-0.003087,0.005589,0.141956,975.800781,49.709660,1.419563,-300.335388,982.000671,0.000000
101.060005,219.489746,-300.379852,-0.003096,0.005594,0.142086,976.339172,49.737087,1.420865,-300.379852,982.000671,0.000000
101.530006,219.750397,-300.335388,-0.003083,0.005601,0.142277,977.498596,49.796154,1.422772,-300.335388,982.000671,0.000000
102.000008,219.576141,-300.335388,-0.003070,0.005606,0.142391,976.723450,49.756664,1.423908,-300.335388,982.000671,0.000000
102.470001,219.259979,-300.468811,-0.003061,0.005607,0.142407,975.317078,49.685020,1.424074,-300.468811,982.000671,0.000000
102.940002,219.312103,-300.424347,-0.003074,0.005613,0.142563,975.548950,49.696835,1.425634,-300.424347,982.000671,0.000000
103.410004,218.977722,-300.557800,-0.003061,0.005614,0.142598,974.061584,49.621059,1.425982,-300.557800,982.000671,0.000000
103.880005,220.409485,-300.513306,-0.003044,0.005614,0.142591,980.430359,49.945503,1.425906,-300.513306,982.000671,0.000000
104.350006,219.852417,-300.513306,-0.003044,0.005614,0.142607,977.952393,49.819267,1.426073,-300.513306,982.000671,0.000000
104.820007,219.283447,-300.602264,-0.003031,0.005615,0.142616,975.421509,49.690342,1.426164,-300.602264,982.000671,0.000000
105.290009,221.913147,-300.646759,-0.003022,0.005637,0.143189,987.118958,50.286240,1.431886,-300.646759,982.000671,0.000000
105.760002,219.576874,-300.735718,-0.002979,0.005633,0.143075,976.726746,49.756832,1.430751,-300.735718,982.000671,0.000000
106.230003,219.623047,-300.646759,-0.002971,0.005642,0.143319,976.932129,49.767292,1.433188,-300.646759,982.000671,0.000000
106.700005,219.367584,-300.691223,-0.002979,0.005647,0.143440,975.795776,49.709404,1.434399,-300.691223,982.000671,0.000000
107.170006,219.681519,-300.735718,-0.002984,0.005654,0.143613,977.192200,49.780544,1.436125,-300.735718,982.000671,0.000000
107.640007,220.040466,-300.780182,-0.002988,0.005664,0.143865,978.788879,49.861885,1.438654,-300.780182,982.000671,0.000000
108.110008,219.661041,-300.824677,-0.002992,0.005664,0.143865,977.101135,49.775906,1.438654,-300.824677,982.000671,0.000000
108.580002,219.244354,-300.869141,-0.002988,0.005664,0.143865,975.247620,49.681480,1.438654,-300.869141,982.000671,0.000000
109.050003,219.907898,-300.869141,-0.002984,0.005673,0.144091,978.199158,49.831841,1.440910,-300.869141,982.000671,0.000000
109.520004,219.455475,-300.869141,-0.002984,0.005674,0.144124,976.186707,49.729321,1.441243,-300.869141,982.000671,0.000000
109.990005,219.684845,-300.958130,-0.003001,0.005682,0.144324,977.206970,49.781296,1.443241,-300.958130,982.000671,0.000000
110.460007,219.567566,-301.002594,-0.002975,0.005686,0.144419,976.685303,49.754723,1.444195,-301.002594,982.000671,0.000000
110.930008,219.413757,-300.958130,-0.002971,0.005688,0.144463,976.001160,49.719868,1.444634,-300.958130,982.000671,0.000000
111.400002,219.880341,-301.002594,-0.002984,0.005696,0.144671,978.076599,49.825596,1.446708,-301.002594,982.000671,0.000000
111.870003,219.580231,-301.091553,-0.002966,0.005698,0.144731,976.741638,49.757591,1.447314,-301.091553,982.000671,0.000000
112.340004,219.581329,-301.091553,-0.002949,0.005701,0.144801,976.746521,49.757839,1.448010,-301.091553,982.000671,0.000000
112.810005,219.804016,-301.180511,-0.002962,0.005707,0.144957,977.737122,49.808304,1.449569,-301.180511,982.000671,0.000000
113.280006,219.529572,-301.136047,-0.002958,0.005707,0.144966,976.516296,49.746113,1.449660,-301.136047,982.000671,0.000000
113.750008,219.726196,-301.091553,-0.002958,0.005714,0.145131,977.390930,49.790668,1.451310,-301.091553,982.000671,0.000000
114.220009,219.445801,-301.269470,-0.002958,0.005714,0.145148,976.143677,49.727131,1.451477,-301.269470,982.000671,0.000000
114.690002,219.421234,-301.313965,-0.002949,0.005718,0.145235,976.034424,49.721561,1.452355,-301.313965,982.000671,0.000000
115.160004,219.439850,-301.313965,-0.002928,0.005726,0.145443,976.117187,49.725780,1.454429,-301.313965,982.000671,0.000000
115.630005,219.609650,-301.313965,-0.002928,0.005726,0.145452,976.872498,49.764256,1.454520,-301.313965,982.000671,0.000000
116.100006,219.700867,-301.358429,-0.002953,0.005731,0.145573,977.278259,49.784927,1.455731,-301.358429,982.000671,0.000000
116.570007,219.516541,-301.358429,-0.002923,0.005733,0.145617,976.458313,49.743160,1.456170,-301.358429,982.000671,0.000000
117.040009,219.415649,-301.447418,-0.002915,0.005736,0.145703,976.009583,49.720299,1.457033,-301.447418,982.000671,0.000000
117.510002,219.251404,-301.491882,-0.002919,0.005737,0.145729,975.278931,49.683079,1.457291,-301.491882,982.000671,0.000000
117.980003,220.407623,-301.447418,-0.002910,0.005741,0.145834,980.422058,49.945080,1.458335,-301.447418,982.000671,0.000000
118.450005,219.998016,-301.491882,-0.002915,0.005742,0.145843,978.600037,49.852261,1.458426,-301.491882,982.000671,0.000000
118.920006,219.605164,-301.580841,-0.002910,0.005742,0.145850,976.852539,49.763241,1.458502,-301.580841,982.000671,0.000000
119.390007,220.396851,-301.625336,-0.002897,0.005760,0.146310,980.374146,49.942642,1.463104,-301.625336,982.000671,0.000000
119.860008,220.102661,-301.625336,-0.002906,0.005760,0.146310,979.065552,49.875977,1.463104,-301.625336,982.000671,0.000000
120.330009,219.801025,-301.625336,-0.002884,0.005760,0.146310,977.723816,49.807625,1.463104,-301.625336,982.000671,0.000000
120.800003,219.467773,-301.669800,-0.002906,0.005761,0.146319,976.241394,49.732105,1.463195,-301.669800,982.000671,0.000000
121.270004,219.850555,-301.758759,-0.002880,0.005769,0.146527,977.944092,49.818848,1.465269,-301.758759,982.000671,0.000000
121.740005,219.575745,-301.803253,-0.002880,0.005769,0.146536,976.721680,49.756573,1.465360,-301.803253,982.000671,0.000000
122.210007,219.316956,-301.892212,-0.002889,0.005769,0.146545,975.570557,49.697933,1.465451,-301.892212,982.000671,0.000000
122.680008,220.147339,-301.803253,-0.002880,0.005780,0.146822,979.264282,49.886101,1.468221,-301.803253,982.000671,0.000000
123.150009,219.875885,-301.847748,-0.002871,0.005780,0.146822,978.056763,49.824589,1.468221,-301.847748,982.000671,0.000000
123.620003,219.571655,-301.981171,-0.002880,0.005780,0.146822,976.703491,49.755650,1.468221,-301.981171,982.000671,0.000000
124.090004,219.279358,-301.936707,-0.002871,0.005780,0.146822,975.403320,49.689411,1.468221,-301.936707,982.000671,0.000000
124.560005,220.881287,-301.981171,-0.002871,0.005790,0.147073,982.529053,50.052414,1.470734,-301.981171,982.000671,0.000000
125.030006,220.394226,-301.981171,-0.002854,0.005778,0.146762,980.362488,49.942043,1.467616,-301.981171,982.000671,0.000000
125.500008,220.116821,-301.981171,-0.002871,0.005778,0.146762,979.128540,49.879185,1.467616,-301.981171,982.000671,0.000000
125.970009,219.794708,-302.159088,-0.002846,0.005778,0.146762,977.695679,49.806194,1.467616,-302.159088,982.000671,0.000000
126.440002,219.438354,-302.070129,-0.002854,0.005778,0.146762,976.110535,49.725441,1.467616,-302.070129,982.000671,0.000000
126.910004,219.863983,-302.159088,-0.002846,0.005803,0.147403,978.003845,49.821888,1.474035,-302.159088,982.000671,0.000000
127.380005,219.601440,-302.114624,-0.002837,0.005804,0.147411,976.835999,49.762398,1.474111,-302.114624,982.000671,0.000000
127.850006,219.919067,-302.203583,-0.002854,0.005813,0.147646,978.248840,49.834373,1.476457,-302.203583,982.000671,0.000000
128.320007,219.849823,-302.203583,-0.002850,0.005812,0.147637,977.940857,49.818680,1.476366,-302.203583,982.000671,0.000000
128.790009,219.610016,-302.292542,-0.002837,0.005813,0.147646,976.874146,49.764339,1.476457,-302.292542,982.000671,0.000000
129.260010,219.859131,-302.248077,-0.002833,0.005820,0.147820,977.982239,49.820793,1.478198,-302.248077,982.000671,0.000000
129.730011,219.723572,-302.337036,-0.002824,0.005820,0.147820,977.379272,49.790073,1.478198,-302.337036,982.000671,0.000000
130.200012,219.589539,-302.381500,-0.002854,0.005826,0.147992,976.783081,49.759701,1.479924,-302.381500,982.000671,0.000000
130.670013,219.909393,-302.381500,-0.002837,0.005827,0.148011,978.205811,49.832184,1.480106,-302.381500,982.000671,0.000000
131.139999,219.719116,-302.381500,-0.002820,0.005827,0.148018,977.359436,49.789066,1.480182,-302.381500,982.000671,0.000000
131.610001,219.556763,-302.514954,-0.002811,0.005829,0.148053,976.637268,49.752274,1.480530,-302.514954,982.000671,0.000000
132.080002,219.515442,-302.425995,-0.002824,0.005832,0.148123,976.453430,49.742912,1.481226,-302.425995,982.000671,0.000000
132.550003,219.575745,-302.514954,-0.002815,0.005836,0.148227,976.721680,49.756573,1.482271,-302.514954,982.000671,0.000000
133.020004,219.483765,-302.603912,-0.002820,0.005837,0.148253,976.312561,49.735729,1.482528,-302.603912,982.000671,0.000000
133.490005,219.573517,-302.559418,-0.002811,0.005839,0.148313,976.711792,49.756069,1.483134,-302.559418,982.000671,0.000000
133.960007,219.614868,-302.559418,-0.002802,0.005843,0.148418,976.895752,49.765442,1.484178,-302.559418,982.000671,0.000000
134.430008,219.485260,-302.603912,-0.002807,0.005843,0.148418,976.319214,49.736073,1.484178,-302.603912,982.000671,0.000000
134.900009,219.660645,-302.692871,-0.002828,0.005848,0.148548,977.099365,49.775814,1.485480,-302.692871,982.000671,0.000000
135.370010,219.494202,-302.692871,-0.002802,0.005848,0.148548,976.358948,49.738098,1.485480,-302.692871,982.000671,0.000000
135.840012,219.510590,-302.737366,-0.002807,0.005851,0.148609,976.431885,49.741810,1.486086,-302.737366,982.000671,0.000000
136.310013,219.650604,-302.781830,-0.002794,0.005855,0.148713,977.054687,49.773537,1.487131,-302.781830,982.000671,0.000000
136.780014,219.612244,-302.781830,-0.002802,0.005858,0.148781,976.884033,49.764843,1.487812,-302.781830,982.000671,0.000000
137.250000,219.526215,-302.826324,-0.002790,0.005859,0.148808,976.501343,49.745354,1.488084,-302.826324,982.000671,0.000000
137.720001,219.446533,-302.915283,-0.002781,0.005861,0.148860,976.146912,49.727295,1.488599,-302.915283,982.000671,0.000000
138.190002,219.381744,-302.915283,-0.002785,0.005862,0.148886,975.858765,49.712616,1.488857,-302.915283,982.000671,0.000000
138.660004,219.472595,-302.915283,-0.002768,0.005866,0.149007,976.262878,49.733200,1.490068,-302.915283,982.000671,0.000000
139.130005,219.428680,-302.959747,-0.002785,0.005866,0.149007,976.067505,49.723248,1.490068,-302.959747,982.000671,0.000000
139.600006,219.300934,-303.048706,-0.002785,0.005868,0.149042,975.499268,49.694302,1.490416,-303.048706,982.000671,0.000000
140.070007,220.243805,-303.048706,-0.002764,0.005879,0.149320,979.693359,49.907959,1.493202,-303.048706,982.000671,0.000000
140.540009,220.115326,-303.093201,-0.002768,0.005879,0.149320,979.121887,49.878845,1.493202,-303.093201,982.000671,0.000000
141.010010,219.900085,-303.048706,-0.002755,0.005879,0.149328,978.164429,49.830070,1.493277,-303.048706,982.000671,0.000000
141.480011,219.702728,-303.182159,-0.002785,0.005879,0.149328,977.286560,49.785351,1.493277,-303.182159,982.000671,0.000000
141.950012,219.490112,-303.226654,-0.002768,0.005879,0.149328,976.340759,49.737171,1.493277,-303.226654,982.000671,0.000000
142.420013,220.430725,-303.137695,-0.002738,0.005892,0.149649,980.524841,49.950317,1.496487,-303.137695,982.000671,0.000000
142.889999,220.319763,-303.182159,-0.002738,0.005892,0.149649,980.031250,49.925171,1.496487,-303.182159,982.000671,0.000000
143.360001,220.129486,-303.271118,-0.002746,0.005892,0.149649,979.184875,49.882053,1.496487,-303.271118,982.000671,0.000000
143.830002,219.921326,-303.360077,-0.002759,0.005892,0.149658,978.258911,49.834885,1.496578,-303.360077,982.000671,0.000000
144.300003,219.719116,-303.360077,-0.002751,0.005892,0.149658,977.359436,49.789066,1.496578,-303.360077,982.000671,0.000000
144.770004,219.509857,-303.360077,-0.002742,0.005892,0.149658,976.428589,49.741646,1.496578,-303.360077,982.000671,0.000000
145.240005,219.282684,-303.360077,-0.002742,0.005892,0.149658,975.418091,49.690166,1.496578,-303.360077,982.000671,0.000000
145.710007,219.060760,-303.404572,-0.002742,0.005892,0.149658,974.430908,49.639877,1.496578,-303.404572,982.000671,0.000000
146.180008,220.748718,-303.493530,-0.002746,0.005867,0.149034,981.939331,50.022373,1.490340,-303.493530,982.000671,0.000000
146.650009,220.496246,-303.493530,-0.002729,0.005867,0.149034,980.816284,49.965164,1.490340,-303.493530,982.000671,0.000000
147.120010,220.284760,-303.538025,-0.002721,0.005867,0.149034,979.875549,49.917240,1.490340,-303.538025,982.000671,0.000000
147.590012,220.043823,-303.582489,-0.002716,0.005867,0.149034,978.803833,49.862644,1.490340,-303.582489,982.000671,0.000000
148.060013,219.818542,-303.626984,-0.002716,0.005868,0.149051,977.801697,49.811592,1.490507,-303.626984,5607.367676,0.000000
148.530014,219.471497,-303.671448,-0.002725,0.005867,0.149034,976.257996,49.732952,1.490340,-303.671448,0.148755,0.000000
149.000000,218.771057,-303.671448,-0.002699,0.005843,0.148409,973.142273,49.574230,1.484088,-303.671448,0.147967,0.000000
149.470001,217.329224,-303.626984,-0.002699,0.005817,0.147759,966.728699,49.247505,1.477593,-303.626984,0.147185,0.000000
149.940002,216.321594,-303.715942,-0.002669,0.005786,0.146961,962.246521,49.019176,1.469614,-303.715942,0.146406,0.000000
150.410004,215.524719,-303.715942,-0.002652,0.005754,0.146154,958.701843,48.838596,1.461545,-303.715942,0.145617,0.000000
150.880005,215.085693,-303.804901,-0.002639,0.005719,0.145270,956.748962,48.739113,1.452703,-303.804901,0.144836,0.000000
151.350006,214.547607,-303.849365,-0.002639,0.005701,0.144810,954.355408,48.617184,1.448101,-303.849365,0.144056,0.000000
151.820007,214.134644,-303.849365,-0.002665,0.005672,0.144064,952.518494,48.523605,1.440637,-303.849365,0.143266,0.000000
152.290009,212.714050,-303.804901,-0.002656,0.005631,0.143024,946.199341,48.201694,1.430236,-303.804901,0.142486,0.000000
152.760010,211.973785,-303.982819,-0.002652,0.005606,0.142400,942.906494,48.033947,1.423999,-303.982819,0.141705,0.000000
153.230011,210.387451,-304.027313,-0.002647,0.005583,0.141800,935.850098,47.674477,1.418003,-304.027313,0.140916,0.000000
153.700012,208.521118,-303.982819,-0.002643,0.005555,0.141090,927.548279,47.251560,1.410903,-303.982819,0.140135,0.000000
154.170013,206.206085,-303.982819,-0.002647,0.005525,0.140344,917.250488,46.726967,1.403439,-303.982819,0.139355,0.000000
154.640015,202.859955,-304.071777,-0.002639,0.005487,0.139372,902.366150,45.968723,1.393719,-304.071777,0.138567,0.000000
155.110001,199.936462,-304.116272,-0.002647,0.005460,0.138679,889.361816,45.306252,1.386786,-304.116272,0.137785,0.000000
155.580002,196.928436,-304.160736,-0.002647,0.005436,0.138081,875.981445,44.624622,1.380805,-304.160736,0.137006,0.000000
156.050003,192.874786,-304.160736,-0.002639,0.005396,0.137066,857.949890,43.706051,1.370662,-304.160736,0.136215,0.000000
156.520004,189.206543,-304.205231,-0.002643,0.005364,0.136250,841.632751,42.874813,1.362502,-304.205231,0.135436,0.000000
156.990005,186.549301,-304.205231,-0.002634,0.005336,0.135531,829.812744,42.272675,1.355310,-304.205231,0.134654,0.000000
157.460007,183.022186,-304.294189,-0.002639,0.005308,0.134829,814.123352,41.473419,1.348286,-304.294189,0.133866,0.000000
157.930008,179.843979,-304.338654,-0.002634,0.005277,0.134047,799.985962,40.753231,1.340474,-304.338654,0.133084,0.000000
158.400009,175.799652,-304.294189,-0.002639,0.005244,0.133198,781.995911,39.836769,1.331980,-304.294189,0.132305,0.000000
158.870010,171.684189,-304.338654,-0.002634,0.005210,0.132321,763.689392,38.904194,1.323214,-304.338654,0.131516,0.000000
159.340012,168.455353,-304.427643,-0.002630,0.005181,0.131593,749.326843,38.172527,1.315932,-304.427643,0.130735,0.000000
159.810013,164.124649,-304.472107,-0.002634,0.005148,0.130761,730.062927,37.191177,1.307606,-304.472107,0.129955,0.000000
160.280014,160.698456,-304.472107,-0.002630,0.005120,0.130041,714.822449,36.414791,1.300414,-304.472107,0.129165,0.000000
160.750015,156.970627,-304.472107,-0.002608,0.005090,0.129286,698.240234,35.570053,1.292860,-304.472107,0.128385,0.000000
161.220001,153.301270,-304.472107,-0.002617,0.005059,0.128497,681.918091,34.738564,1.284972,-304.472107,0.127604,0.000000
161.690002,150.024033,-304.561066,-0.002634,0.005033,0.127830,667.340210,33.995930,1.278295,-304.561066,0.126815,0.000000
162.160004,146.441055,-304.650024,-0.002634,0.004997,0.126936,651.402344,33.184017,1.269363,-304.650024,0.126034,0.000000
162.630005,143.199921,-304.650024,-0.002643,0.004973,0.126313,636.985046,32.449566,1.263125,-304.650024,0.125254,0.000000
163.100006,139.228577,-304.650024,-0.002634,0.004938,0.125436,619.319641,31.549646,1.254360,-304.650024,0.124466,0.000000
163.570007,136.334503,-304.650024,-0.002639,0.004908,0.124673,606.446167,30.893839,1.246729,-304.650024,0.123684,0.000000
164.040009,131.958755,-304.694519,-0.002643,0.004875,0.123815,586.981873,29.902281,1.238145,-304.694519,0.122905,0.000000
164.510010,128.690811,-304.738983,-0.002639,0.004844,0.123042,572.445312,29.161755,1.230424,-304.738983,0.122114,0.000000
164.980011,125.615005,-304.783478,-0.002621,0.004821,0.122461,558.763428,28.464767,1.224610,-304.783478,0.121335,0.000000
165.450012,122.141144,-304.827972,-0.002634,0.004790,0.121663,543.310913,27.677580,1.216632,-304.827972,0.120553,0.000000
165.920013,117.670441,-304.783478,-0.002630,0.004749,0.120614,523.424255,26.664503,1.206140,-304.783478,0.119765,0.000000
166.390015,114.505646,-304.827972,-0.002647,0.004721,0.119921,509.346558,25.947350,1.199206,-304.827972,0.118983,0.000000
166.860001,111.032898,-304.872437,-0.002643,0.004692,0.119167,493.898987,25.160414,1.191667,-304.872437,0.118204,0.000000
167.330002,108.293365,-304.916931,-0.002626,0.004669,0.118585,481.712952,24.539627,1.185853,-304.916931,0.117415,0.000000
167.800003,103.870697,-304.961395,-0.002639,0.004627,0.117536,462.039948,23.537436,1.175361,-304.961395,0.116634,0.000000
168.270004,100.374115,-305.005890,-0.002647,0.004598,0.116790,446.486359,22.745098,1.167897,-305.005890,0.115853,0.000000
168.740005,96.582626,-305.005890,-0.002634,0.004565,0.115940,429.620972,21.885937,1.159404,-305.005890,0.115064,0.000000
169.210007,94.022934,-305.094849,-0.002639,0.004541,0.115350,418.234894,21.305902,1.153500,-305.094849,0.114284,0.000000
169.680008,90.162170,-305.094849,-0.002634,0.004509,0.114535,401.061371,20.431040,1.145355,-305.094849,0.113503,0.000000
170.150009,86.189331,-305.094849,-0.002639,0.004471,0.113564,383.389282,19.530781,1.135635,-305.094849,0.112714,0.000000
170.620010,82.833511,-305.094849,-0.002647,0.004443,0.112844,368.461853,18.770342,1.128444,-305.094849,0.111933,0.000000
171.090012,79.937576,-305.139313,-0.002630,0.004416,0.112159,355.580109,18.114113,1.121585,-305.139313,0.111153,0.000000
171.560013,76.150543,-305.139313,-0.002634,0.004382,0.111291,338.734528,17.255960,1.112911,-305.139313,0.110365,0.000000
172.030014,72.836060,-305.228271,-0.002630,0.004350,0.110493,323.990967,16.504889,1.104932,-305.228271,0.109583,0.000000
172.500015,69.065414,-305.228271,-0.002630,0.004316,0.109635,307.218292,15.650447,1.096348,-305.228271,0.108802,0.000000
172.970001,66.576096,-305.272766,-0.002634,0.004292,0.109011,296.145264,15.086359,1.090110,-305.272766,0.108013,0.000000
173.440002,63.169632,-305.317261,-0.002621,0.004261,0.108222,280.992554,14.314444,1.082223,-305.317261,0.107234,0.000000
173.910004,59.495064,-305.406219,-0.002639,0.004227,0.107364,264.647247,13.481774,1.073638,-305.406219,0.106452,0.000000
174.380005,55.878212,-305.406219,-0.002626,0.004194,0.106522,248.558701,12.662184,1.065221,-305.406219,0.105664,0.000000
174.850006,53.196762,-305.406219,-0.002647,0.004168,0.105871,236.631012,12.054559,1.058711,-305.406219,0.104882,0.000000
175.320007,50.094894,-305.450684,-0.002647,0.004139,0.105126,222.833221,11.351665,1.051262,-305.450684,0.104103,0.000000
175.790009,46.867172,-305.450684,-0.002643,0.004106,0.104294,208.475601,10.620253,1.042935,-305.450684,0.103314,0.000000
176.260010,43.865105,-305.584137,-0.002634,0.004076,0.103531,195.121735,9.939975,1.035305,-305.584137,0.102533,0.000000
176.730011,41.624542,-305.584137,-0.002634,0.004055,0.103001,185.155212,9.432257,1.030006,-305.584137,0.101752,0.000000
177.200012,38.731209,-305.584137,-0.002643,0.004018,0.102065,172.285019,8.776617,1.020650,-305.584137,0.100963,0.000000
177.670013,35.684456,-305.628601,-0.002639,0.003980,0.101093,158.732391,8.086213,1.010930,-305.628601,0.100183,0.000000
178.140015,33.670662,-305.628601,-0.002621,0.003955,0.100469,149.774582,7.629881,1.004693,-305.628601,0.099402,0.000000
178.610016,31.595802,-305.762054,-0.002626,0.003932,0.099879,140.545151,7.159711,0.998788,-305.762054,0.098613,0.000000
179.080002,27.927193,-305.717590,-0.002626,0.003891,0.098821,124.226357,6.328393,0.988206,-305.717590,0.097832,0.000000
179.550003,25.352608,-305.762054,-0.002647,0.003861,0.098076,112.774033,5.744983,0.980757,-305.762054,0.097052,0.000000
180.020004,23.074432,-305.762054,-0.002630,0.003834,0.097373,102.640198,5.228741,0.973732,-305.762054,0.096262,0.000000
180.490005,20.416069,-305.851013,-0.002630,0.003801,0.096557,90.815208,4.626348,0.965572,-305.851013,0.095482,0.000000
180.960007,18.085014,-305.851013,-0.002626,0.003774,0.095855,80.446159,4.098123,0.958547,-305.851013,0.094701,0.000000
181.430008,15.590866,-305.851013,-0.002630,0.003738,0.094945,69.351639,3.532941,0.949448,-305.851013,0.093912,0.000000
181.900009,13.036392,-305.895508,-0.002643,0.003710,0.094242,57.988770,2.954089,0.942424,-305.895508,0.093133,0.000000
182.370010,10.602936,-305.895508,-0.002643,0.003680,0.093470,47.164215,2.402660,0.934703,-305.895508,0.092351,0.000000
182.840012,8.289383,-305.984467,-0.002621,0.003649,0.092672,36.873016,1.878401,0.926724,-305.984467,0.091563,0.000000
183.310013,6.242081,-306.028931,-0.002634,0.003619,0.091926,27.766161,1.414476,0.919260,-306.028931,0.090781,0.000000
183.780014,4.316917,-306.028931,-0.002643,0.003590,0.091189,19.202608,0.978227,0.911887,-306.028931,0.090002,0.000000
184.250015,1.881973,-306.073425,-0.002634,0.003554,0.090262,8.371435,0.426461,0.902622,-306.073425,0.089211,0.000000
184.720001,1.271278,-306.073425,-0.002630,0.003537,0.089828,5.654929,0.288076,0.898277,-306.073425,0.088432,0.000000
185.190002,-0.603989,-306.162384,-0.002639,0.003496,0.088804,-2.686676,-0.136866,0.888042,-306.162384,0.087651,0.000000
185.660004,-0.256561,-306.206879,-0.002630,0.003462,0.087929,-1.141242,-0.058138,0.879292,-306.206879,0.086862,0.000000
186.130005,-0.280022,-306.251343,-0.002652,0.003426,0.087027,-1.245599,-0.063454,0.870268,-306.251343,0.086082,0.000000
186.600006,-0.200706,-306.251343,-0.002673,0.003406,0.086524,-0.892787,-0.045481,0.865242,-306.251343,0.085301,0.000000
187.070007,-0.188049,-306.295837,-0.002673,0.003375,0.085717,-0.836485,-0.042613,0.857173,-306.295837,0.084512,0.000000
187.540009,-0.206291,-306.295837,-0.002777,0.003337,0.084754,-0.917629,-0.046746,0.847544,-306.295837,0.083731,0.000000
188.010010,-0.193260,-306.340302,-0.002824,0.003313,0.084138,-0.859664,-0.043793,0.841382,-306.340302,0.082951,0.000000
188.480011,-0.202942,-306.384796,-0.002915,0.003282,0.083359,-0.902731,-0.045987,0.833585,-306.384796,0.082161,0.000000
188.950012,-0.205551,-306.429260,-0.002988,0.003243,0.082361,-0.914337,-0.046579,0.823608,-306.429260,0.081381,0.000000
189.420013,-0.207039,-306.429260,-0.003061,0.003213,0.081607,-0.920955,-0.046916,0.816069,-306.429260,0.080600,0.000000
189.890015,-0.169052,-306.473755,-0.003104,0.003176,0.080661,-0.751981,-0.038308,0.806607,-306.473755,0.079811,0.000000
190.360016,-0.094582,-306.562714,-0.003139,0.003164,0.080375,-0.420720,-0.021432,0.803745,-306.562714,0.080262,0.000000
190.400009,-0.099052,-306.518219,-0.003143,0.003165,0.080384,-0.440607,-0.022446,0.803836,-306.518219,0.080262,0.000000