File: Data/compression 28/AutoNoHeating-17-28-reverse-1-34up_10222024_183601.csv
Time (sec),S:Load (lbs),S:HL1 (DIM),S:LVDT (in),S:Position (in),Ch:Position (mm),Ch:Load (N),Ch:Stress (MPa),Ch:Strain (mm/mm),Ch:HL1 (DIM),Set Point (),Cycles ()
0.110000,-0.150436,-1299.822388,-0.005661,-0.005723,-0.145364,-0.669175,-0.034089,-1.453642,-1299.822388,-0.145069,0.000000
0.550000,-0.058830,-1299.777832,-0.005674,-0.005607,-0.142415,-0.261690,-0.013331,-1.424150,-1299.777832,-0.141357,0.000000
0.990000,0.037239,-1299.866821,-0.005463,-0.005331,-0.135417,0.165648,0.008438,-1.354175,-1299.866821,-0.134020,0.000000
1.430000,-0.014893,-1299.822388,-0.005385,-0.000000,-0.000000,-0.066245,-0.003375,-0.000000,-1299.822388,0.000233,0.000000
1.870000,0.088623,-1299.822388,-0.005398,-0.000000,-0.000000,0.394215,0.020082,-0.000000,-1299.822388,0.000675,0.000000
2.310000,0.070755,-1299.866821,-0.005385,0.000013,0.000338,0.314734,0.016033,0.003376,-1299.866821,0.001413,0.000000
2.750000,0.162727,-1299.777832,-0.005394,0.000043,0.001084,0.723847,0.036875,0.010840,-1299.777832,0.002141,0.000000
3.190000,0.242416,-1299.866821,-0.005372,0.000070,0.001768,1.078322,0.054932,0.017683,-1299.866821,0.002878,0.000000
3.630000,0.319870,-1299.822388,-0.005333,0.000090,0.002280,1.422853,0.072484,0.022800,-1299.822388,0.003608,0.000000
4.070000,0.663193,-1299.866821,-0.005316,0.000122,0.003096,2.950029,0.150282,0.030960,-1299.866821,0.004344,0.000000
4.510000,1.094772,-1299.733398,-0.005282,0.000154,0.003901,4.869791,0.248079,0.039015,-1299.733398,0.005073,0.000000
4.950000,1.514809,-1299.822388,-0.005264,0.000181,0.004596,6.738205,0.343261,0.045964,-1299.822388,0.005809,0.000000
5.390000,1.852554,-1299.866821,-0.005243,0.000200,0.005090,8.240573,0.419795,0.050899,-1299.866821,0.006546,0.000000
5.830000,2.485214,-1299.777832,-0.005217,0.000233,0.005906,11.054785,0.563158,0.059060,-1299.777832,0.007276,0.000000
6.270000,3.480194,-1299.822388,-0.005182,0.000272,0.006911,15.480677,0.788623,0.069112,-1299.822388,0.008012,0.000000
6.710001,4.379471,-1299.822388,-0.005174,0.000306,0.007779,19.480860,0.992402,0.077787,-1299.822388,0.008742,0.000000
7.150001,4.611832,-1299.777832,-0.005148,0.000325,0.008247,20.514452,1.045056,0.082465,-1299.777832,0.009479,0.000000
7.590000,5.752785,-1299.822388,-0.005131,0.000359,0.009123,25.589664,1.303600,0.091231,-1299.822388,0.010207,0.000000
8.030001,6.303894,-1299.822388,-0.005105,0.000384,0.009765,28.041121,1.428483,0.097650,-1299.822388,0.010944,0.000000
8.470000,7.099281,-1299.777832,-0.005096,0.000414,0.010528,31.579180,1.608720,0.105281,-1299.777832,0.011680,0.000000
8.910001,7.696938,-1299.822388,-0.005044,0.000442,0.011238,34.237690,1.744151,0.112381,-1299.822388,0.012410,0.000000
9.350000,8.419716,-1299.777832,-0.005049,0.000470,0.011950,37.452766,1.907935,0.119497,-1299.777832,0.013147,0.000000
9.790001,9.227020,-1299.777832,-0.005001,0.000501,0.012722,41.043835,2.090873,0.127218,-1299.777832,0.013875,0.000000
10.230000,9.786324,-1299.822388,-0.004975,0.000530,0.013468,43.531742,2.217613,0.134682,-1299.822388,0.014613,0.000000
10.670000,10.358284,-1299.822388,-0.004954,0.000562,0.014274,46.075947,2.347221,0.142736,-1299.822388,0.015341,0.000000
11.110001,10.398872,-1299.866821,-0.004928,0.000580,0.014743,46.256496,2.356418,0.147429,-1299.866821,0.016078,0.000000
11.550000,11.569611,-1299.822388,-0.004919,0.000623,0.015818,51.464199,2.621711,0.158178,-1299.822388,0.016806,0.000000
11.990001,11.733833,-1299.911255,-0.004881,0.000648,0.016467,52.194698,2.658925,0.164673,-1299.911255,0.017544,0.000000
12.430000,12.255150,-1299.866821,-0.004842,0.000686,0.017414,54.513630,2.777057,0.174135,-1299.866821,0.018281,0.000000
12.870001,11.780006,-1299.777832,-0.004820,0.000705,0.017900,52.400085,2.669388,0.178995,-1299.777832,0.019009,0.000000
13.310000,12.402985,-1299.866821,-0.004803,0.000738,0.018740,55.171230,2.810556,0.187398,-1299.866821,0.019747,0.000000
13.750001,12.297974,-1299.866821,-0.004773,0.000757,0.019226,54.704121,2.786761,0.192258,-1299.866821,0.020475,0.000000
14.190001,12.916481,-1299.911255,-0.004743,0.000794,0.020170,57.455376,2.926917,0.201705,-1299.911255,0.021212,0.000000
14.630001,12.854668,-1299.822388,-0.004712,0.000819,0.020812,57.180416,2.912909,0.208124,-1299.822388,0.021940,0.000000
15.070001,12.787643,-1299.822388,-0.004708,0.000843,0.021403,56.882278,2.897722,0.214028,-1299.822388,0.022678,0.000000
15.510001,13.408386,-1299.866821,-0.004652,0.000881,0.022382,59.643482,3.038384,0.223824,-1299.866821,0.023415,0.000000
15.950001,13.214386,-1299.866821,-0.004648,0.000904,0.022973,58.780525,2.994423,0.229728,-1299.866821,0.024143,0.000000
16.390001,13.434456,-1299.955811,-0.004618,0.000934,0.023727,59.759445,3.044291,0.237267,-1299.955811,0.024880,0.000000
16.830000,13.521591,-1299.866821,-0.004570,0.000962,0.024438,60.147041,3.064036,0.244383,-1299.866821,0.025609,0.000000
17.270000,14.033600,-1299.911255,-0.004562,0.000997,0.025332,62.424568,3.180059,0.253315,-1299.911255,0.026346,0.000000
17.710001,13.503342,-1299.911255,-0.004527,0.001016,0.025816,60.065865,3.059901,0.258160,-1299.911255,0.027074,0.000000
18.150002,14.017220,-1299.822388,-0.004488,0.001052,0.026727,62.351707,3.176347,0.267274,-1299.822388,0.027811,0.000000
18.590000,13.782249,-1299.911255,-0.004471,0.001074,0.027283,61.306507,3.123102,0.272830,-1299.911255,0.028549,0.000000
19.030001,14.171753,-1299.911255,-0.004441,0.001107,0.028114,63.039104,3.211365,0.281142,-1299.911255,0.029277,0.000000
19.470001,14.473373,-1299.866821,-0.004411,0.001140,0.028947,64.380783,3.279713,0.289469,-1299.866821,0.030014,0.000000
19.910002,14.196701,-1299.955811,-0.004381,0.001163,0.029546,63.150082,3.217019,0.295464,-1299.955811,0.030742,0.000000
20.350000,14.038445,-1299.911255,-0.004337,0.001188,0.030179,62.446121,3.181157,0.301792,-1299.911255,0.031480,0.000000
20.790001,14.533325,-1300.000244,-0.004320,0.001224,0.031080,64.647461,3.293298,0.310800,-1300.000244,0.032208,0.000000
21.230001,14.937347,-1300.000244,-0.004281,0.001258,0.031948,66.444641,3.384851,0.319475,-1300.000244,0.032945,0.000000
21.670000,14.637962,-1300.000244,-0.004268,0.001281,0.032547,65.112907,3.317010,0.325471,-1300.000244,0.033683,0.000000
22.110001,14.990601,-1299.955811,-0.004225,0.001310,0.033283,66.681519,3.396919,0.332829,-1299.955811,0.034411,0.000000
22.550001,14.639824,-1299.955811,-0.004199,0.001332,0.033838,65.121193,3.317431,0.338385,-1299.955811,0.035148,0.000000
22.990002,15.018524,-1299.955811,-0.004182,0.001366,0.034697,66.805733,3.403246,0.346969,-1299.955811,0.035876,0.000000
23.430000,15.057625,-1300.000244,-0.004139,0.001396,0.035460,66.979660,3.412107,0.354599,-1300.000244,0.036614,0.000000
23.870001,15.119064,-1300.000244,-0.004130,0.001424,0.036162,67.252960,3.426029,0.361624,-1300.000244,0.037342,0.000000
24.310001,15.305252,-1300.000244,-0.004074,0.001456,0.036995,68.081161,3.468220,0.369951,-1300.000244,0.038079,0.000000
24.750002,15.084068,-1299.955811,-0.004057,0.001481,0.037620,67.097290,3.418099,0.376203,-1299.955811,0.038807,0.000000
25.190001,14.727707,-1299.955811,-0.004031,0.001496,0.038009,65.512115,3.337346,0.380094,-1299.955811,0.039545,0.000000
25.630001,15.669060,-1300.044800,-0.004001,0.001537,0.039051,69.699455,3.550660,0.390510,-1300.044800,0.040282,0.000000
26.070002,15.803864,-1299.955811,-0.003984,0.001568,0.039823,70.299095,3.581207,0.398232,-1299.955811,0.041010,0.000000
26.510002,15.683960,-1300.000244,-0.003936,0.001594,0.040498,69.765739,3.554036,0.404984,-1300.000244,0.041747,0.000000
26.950001,15.710770,-1299.955811,-0.003906,0.001621,0.041175,69.884995,3.560111,0.411751,-1299.955811,0.042476,0.000000
27.390001,15.945366,-1300.000244,-0.003885,0.001653,0.041999,70.928528,3.613272,0.419987,-1300.000244,0.043213,0.000000
27.830002,16.103996,-1300.000244,-0.003859,0.001687,0.042840,71.634155,3.649218,0.428405,-1300.000244,0.043941,0.000000
28.270000,16.147934,-1300.000244,-0.003833,0.001718,0.043638,71.829597,3.659174,0.436383,-1300.000244,0.044678,0.000000
28.710001,15.603523,-1300.044800,-0.003803,0.001732,0.043994,69.407936,3.535809,0.439941,-1300.044800,0.045416,0.000000
29.150002,16.427956,-1299.955811,-0.003755,0.001772,0.045018,73.075195,3.722628,0.450175,-1299.955811,0.046144,0.000000
29.590002,16.866615,-1299.955811,-0.003751,0.001805,0.045858,75.026451,3.822030,0.458578,-1299.955811,0.046881,0.000000
30.030001,16.976463,-1300.000244,-0.003691,0.001837,0.046656,75.515083,3.846922,0.466556,-1300.000244,0.047609,0.000000
30.470001,16.124100,-1299.911255,-0.003691,0.001853,0.047072,71.723579,3.653773,0.470720,-1299.911255,0.048347,0.000000
30.910002,17.094879,-1300.089233,-0.003660,0.001888,0.047958,76.041817,3.873755,0.479576,-1300.089233,0.049075,0.000000
31.350002,17.160042,-1300.000244,-0.003617,0.001918,0.048728,76.331680,3.888521,0.487283,-1300.000244,0.049812,0.000000
31.790001,17.469109,-1300.000244,-0.003600,0.001950,0.049526,77.706474,3.958557,0.495261,-1300.000244,0.050550,0.000000
32.230003,17.288513,-1300.000244,-0.003574,0.001976,0.050186,76.903145,3.917633,0.501862,-1300.000244,0.051278,0.000000
32.670002,17.511185,-1300.000244,-0.003544,0.002003,0.050880,77.893639,3.968091,0.508796,-1300.000244,0.052015,0.000000
33.110001,17.460915,-1300.089233,-0.003505,0.002031,0.051582,77.670029,3.956700,0.515821,-1300.089233,0.052745,0.000000
33.550003,18.082039,-1300.000244,-0.003484,0.002068,0.052536,80.432922,4.097449,0.525359,-1300.000244,0.053481,0.000000
33.990002,17.735725,-1300.044800,-0.003449,0.002093,0.053152,78.892448,4.018973,0.531520,-1300.044800,0.054210,0.000000
34.430000,18.146080,-1300.044800,-0.003423,0.002122,0.053906,80.717796,4.111960,0.539060,-1300.044800,0.054946,0.000000
34.870003,18.460365,-1300.044800,-0.003393,0.002154,0.054704,82.115807,4.183178,0.547038,-1300.044800,0.055683,0.000000
35.310001,18.287956,-1300.133667,-0.003380,0.002178,0.055311,81.348892,4.144110,0.553109,-1300.133667,0.056413,0.000000
35.750000,18.771667,-1300.044800,-0.003337,0.002209,0.056118,83.500549,4.253721,0.561179,-1300.044800,0.057149,0.000000
36.190002,18.477867,-1300.089233,-0.003316,0.002234,0.056751,82.193657,4.187144,0.567507,-1300.089233,0.057879,0.000000
36.630001,18.956367,-1300.000244,-0.003290,0.002262,0.057444,84.322136,4.295574,0.574441,-1300.000244,0.058616,0.000000
37.070004,19.261711,-1300.044800,-0.003251,0.002296,0.058312,85.680367,4.364766,0.583116,-1300.044800,0.059344,0.000000
37.510002,19.812447,-1300.133667,-0.003247,0.002326,0.059084,88.130165,4.489564,0.590837,-1300.133667,0.060081,0.000000
37.950001,19.237137,-1300.044800,-0.003199,0.002345,0.059561,85.571060,4.359198,0.595606,-1300.044800,0.060810,0.000000
38.390003,19.495186,-1300.089233,-0.003178,0.002374,0.060307,86.718918,4.417672,0.603070,-1300.089233,0.061547,0.000000
38.830002,19.941666,-1300.133667,-0.003130,0.002410,0.061226,88.704956,4.518846,0.612260,-1300.133667,0.062284,0.000000
39.270000,19.930489,-1300.089233,-0.003139,0.002435,0.061841,88.655243,4.516313,0.618406,-1300.089233,0.063012,0.000000
39.710003,19.844101,-1300.089233,-0.003096,0.002459,0.062448,88.270973,4.496737,0.624477,-1300.089233,0.063750,0.000000
40.150002,20.657364,-1300.133667,-0.003061,0.002495,0.063368,91.888542,4.681026,0.633682,-1300.133667,0.064478,0.000000
40.590000,20.619011,-1300.089233,-0.003035,0.002518,0.063948,91.717941,4.672335,0.639481,-1300.089233,0.065215,0.000000
41.030003,21.236404,-1300.044800,-0.003009,0.002553,0.064841,94.464241,4.812238,0.648413,-1300.044800,0.065943,0.000000
41.470001,21.564087,-1300.044800,-0.002975,0.002583,0.065604,95.921852,4.886492,0.656043,-1300.044800,0.066681,0.000000
41.910004,20.909088,-1300.089233,-0.002949,0.002601,0.066074,93.008270,4.738067,0.660737,-1300.089233,0.067418,0.000000
42.350002,21.650856,-1300.089233,-0.002949,0.002635,0.066941,96.307816,4.906154,0.669412,-1300.089233,0.068146,0.000000
42.790001,22.060463,-1300.089233,-0.002906,0.002668,0.067765,98.129837,4.998972,0.677648,-1300.089233,0.068884,0.000000
43.230003,21.746552,-1300.133667,-0.002876,0.002688,0.068284,96.733490,4.927839,0.682840,-1300.133667,0.069612,0.000000
43.670002,22.601517,-1300.044800,-0.002863,0.002722,0.069144,100.536568,5.121577,0.691440,-1300.044800,0.070349,0.000000
44.110001,22.820473,-1300.000244,-0.002841,0.002749,0.069828,101.510536,5.171193,0.698283,-1300.000244,0.071077,0.000000
44.550003,23.863121,-1300.133667,-0.002802,0.002787,0.070791,106.148460,5.407461,0.707912,-1300.133667,0.071815,0.000000
44.990002,23.881363,-1300.044800,-0.002785,0.002810,0.071380,106.229607,5.411594,0.713801,-1300.044800,0.072552,0.000000
45.430000,24.368057,-1300.133667,-0.002755,0.002843,0.072205,108.394531,5.521881,0.722052,-1300.133667,0.073280,0.000000
45.870003,24.497643,-1300.133667,-0.002729,0.002870,0.072890,108.970955,5.551245,0.728895,-1300.133667,0.074017,0.000000
46.310001,24.445877,-1300.089233,-0.002699,0.002892,0.073445,108.740692,5.539515,0.734451,-1300.089233,0.074746,0.000000
46.750004,25.033112,-1300.133667,-0.002690,0.002919,0.074155,111.352844,5.672585,0.741552,-1300.133667,0.075483,0.000000
47.190002,25.980057,-1300.044800,-0.002647,0.002953,0.075006,115.565063,5.887165,0.750060,-1300.044800,0.076211,0.000000
47.630001,26.181885,-1300.089233,-0.002643,0.002978,0.075648,116.462837,5.932900,0.756479,-1300.089233,0.076948,0.000000
48.070004,27.266602,-1300.089233,-0.002617,0.003015,0.076584,121.287903,6.178700,0.765836,-1300.089233,0.077686,0.000000
48.510002,27.248726,-1300.000244,-0.002596,0.003038,0.077156,121.208389,6.174650,0.771558,-1300.000244,0.078414,0.000000
48.950001,28.175194,-1300.089233,-0.002565,0.003070,0.077989,125.329521,6.384590,0.779885,-1300.089233,0.079151,0.000000
49.390003,29.385033,-1300.044800,-0.002539,0.003107,0.078917,130.711151,6.658743,0.789166,-1300.044800,0.079879,0.000000
49.830002,28.944511,-1300.044800,-0.002522,0.003130,0.079498,128.751617,6.558920,0.794979,-1300.044800,0.080617,0.000000
50.270004,29.868370,-1300.044800,-0.002475,0.003157,0.080200,132.861145,6.768269,0.802004,-1300.044800,0.081345,0.000000
50.710003,30.469376,-1300.044800,-0.002462,0.003188,0.080982,135.534546,6.904459,0.809816,-1300.044800,0.082082,0.000000
51.150002,31.154167,-1300.133667,-0.002436,0.003213,0.081622,138.580658,7.059635,0.816220,-1300.133667,0.082810,0.000000
51.590004,32.027756,-1300.044800,-0.002406,0.003246,0.082438,142.466568,7.257594,0.824380,-1300.044800,0.083548,0.000000
52.030003,32.331612,-1300.044800,-0.002384,0.003270,0.083062,143.818192,7.326447,0.830618,-1300.044800,0.084285,0.000000
52.470001,33.443146,-1300.044800,-0.002363,0.003302,0.083869,148.762543,7.578325,0.838687,-1300.044800,0.085013,0.000000
52.910004,34.097031,-1300.000244,-0.002333,0.003329,0.084555,151.671173,7.726498,0.845546,-1300.000244,0.085751,0.000000
53.350002,35.317665,-1300.089233,-0.002307,0.003359,0.085325,157.100815,8.003098,0.853252,-1300.089233,0.086479,0.000000
53.790001,35.717598,-1300.000244,-0.002281,0.003385,0.085976,158.879807,8.093723,0.859762,-1300.000244,0.087216,0.000000
54.230003,36.262375,-1300.044800,-0.002268,0.003411,0.086627,161.303101,8.217172,0.866272,-1300.044800,0.087944,0.000000
54.670002,38.642952,-1300.089233,-0.002242,0.003453,0.087702,171.892441,8.756618,0.877021,-1300.089233,0.088682,0.000000
55.110004,40.098183,-1300.000244,-0.002220,0.003484,0.088500,178.365631,9.086378,0.884999,-1300.000244,0.089419,0.000000
55.550003,39.241730,-1300.044800,-0.002203,0.003501,0.088925,174.555939,8.892303,0.889253,-1300.044800,0.090147,0.000000
55.990002,41.799553,-1300.133667,-0.002173,0.003540,0.089914,185.933701,9.471914,0.899140,-1300.133667,0.090884,0.000000
56.430004,41.934357,-1300.044800,-0.002160,0.003560,0.090417,186.533340,9.502461,0.904166,-1300.044800,0.091613,0.000000
56.870003,43.173233,-1300.089233,-0.002126,0.003589,0.091161,192.044128,9.783195,0.911615,-1300.089233,0.092350,0.000000
57.310001,44.340256,-1300.044800,-0.002108,0.003616,0.091856,197.235306,10.047646,0.918564,-1300.044800,0.093078,0.000000
57.750004,45.416405,-1300.089233,-0.002100,0.003646,0.092601,202.022263,10.291505,0.926012,-1300.089233,0.093815,0.000000
58.190002,47.262260,-1300.044800,-0.002074,0.003680,0.093478,210.233032,10.709782,0.934778,-1300.044800,0.094553,0.000000
58.630001,47.892685,-1299.911255,-0.002052,0.003704,0.094076,213.037308,10.852637,0.940758,-1299.911255,0.095281,0.000000
59.070004,49.319992,-1300.044800,-0.002061,0.003732,0.094787,219.386276,11.176070,0.947874,-1300.044800,0.096018,0.000000
59.510002,50.597595,-1300.000244,-0.002022,0.003763,0.095576,225.069351,11.465579,0.955762,-1300.000244,0.096746,0.000000
59.950005,52.472122,-1300.089233,-0.002005,0.003795,0.096383,233.407654,11.890352,0.963831,-1300.089233,0.097484,0.000000
60.390003,53.287247,-1300.133667,-0.001983,0.003822,0.097067,237.033508,12.075063,0.970674,-1300.133667,0.098212,0.000000
60.830002,55.368431,-1299.955811,-0.001970,0.003851,0.097805,246.291077,12.546666,0.978047,-1299.955811,0.098949,0.000000
61.270004,56.005188,-1300.089233,-0.001944,0.003872,0.098342,249.123520,12.690957,0.983422,-1300.089233,0.099687,0.000000
61.710003,58.089729,-1300.044800,-0.001927,0.003907,0.099235,258.396027,13.163321,0.992354,-1300.044800,0.100415,0.000000
62.150002,60.041710,-1300.044800,-0.001923,0.003937,0.099991,267.078857,13.605646,0.999909,-1300.044800,0.101152,0.000000
62.590004,61.146912,-1300.000244,-0.001897,0.003960,0.100580,271.995056,13.856089,1.005798,-1300.000244,0.101882,0.000000
63.030003,62.514259,-1300.044800,-0.001888,0.003990,0.101343,278.077301,14.165934,1.013428,-1300.044800,0.102618,0.000000
63.470001,64.761154,-1300.133667,-0.001876,0.004021,0.102133,288.071991,14.675088,1.021331,-1300.133667,0.103347,0.000000
63.910004,66.018280,-1300.044800,-0.001850,0.004036,0.102515,293.663971,14.959956,1.025146,-1300.044800,0.017997,0.000000
64.350006,65.386368,-1300.000244,-0.001850,0.004050,0.102878,290.853088,14.816763,1.028780,-1300.000244,294.500458,0.000000
64.790001,65.419144,-1300.044800,-0.001815,0.004063,0.103208,290.998871,14.824189,1.032080,-1300.044800,294.500458,0.000000
65.230003,64.760406,-1300.089233,-0.001824,0.004068,0.103338,288.068665,14.674918,1.033382,-1300.089233,294.500458,0.000000
65.670006,64.883301,-1300.044800,-0.001807,0.004079,0.103606,288.615326,14.702765,1.036062,-1300.044800,294.500458,0.000000
66.110001,64.645355,-1300.044800,-0.001798,0.004087,0.103806,287.556915,14.648848,1.038060,-1300.044800,294.500458,0.000000
66.550003,65.263489,-1300.000244,-0.001789,0.004101,0.104162,290.306488,14.788918,1.041618,-1300.000244,294.500458,0.000000
66.990005,65.023315,-1300.044800,-0.001763,0.004109,0.104362,289.238159,14.734494,1.043617,-1300.044800,294.500458,0.000000
67.430000,64.992767,-1300.000244,-0.001759,0.004119,0.104622,289.102264,14.727571,1.046221,-1300.000244,294.500458,0.000000
67.870003,64.952560,-1300.044800,-0.001768,0.004132,0.104960,288.923431,14.718461,1.049597,-1300.044800,294.500458,0.000000
68.310005,64.936539,-1300.000244,-0.001750,0.004131,0.104934,288.852142,14.714830,1.049339,-1300.000244,294.500458,0.000000
68.750000,64.821854,-1299.955811,-0.001759,0.004138,0.105099,288.342010,14.688843,1.050990,-1299.955811,294.500458,0.000000
69.190002,65.459351,-1300.044800,-0.001738,0.004151,0.105427,291.177734,14.833301,1.054275,-1300.044800,294.500458,0.000000
69.630005,64.822601,-1300.044800,-0.001733,0.004151,0.105427,288.345337,14.689012,1.054275,-1300.044800,294.500458,0.000000
70.070000,66.395874,-1300.044800,-0.001729,0.004132,0.104951,295.343597,15.045521,1.049506,-1300.044800,294.500458,0.000000
70.510002,65.655594,-1300.044800,-0.001707,0.004132,0.104960,292.050659,14.877770,1.049597,-1300.044800,294.500458,0.000000
70.950005,64.985321,-1300.044800,-0.001703,0.004147,0.105332,289.069153,14.725884,1.053321,-1300.044800,294.500458,0.000000
71.390007,64.788345,-1300.089233,-0.001707,0.004170,0.105923,288.192963,14.681249,1.059226,-1300.089233,294.500458,0.000000
71.830002,65.517075,-1300.000244,-0.001694,0.004184,0.106278,291.434509,14.846381,1.062783,-1300.000244,294.500458,0.000000
72.270004,64.970810,-1300.044800,-0.001716,0.004184,0.106278,289.004608,14.722596,1.062783,-1300.044800,294.500458,0.000000
72.710007,64.456558,-1300.000244,-0.001703,0.004184,0.106286,286.717102,14.606065,1.062859,-1300.000244,294.500458,0.000000
73.150002,65.936371,-1299.955811,-0.001686,0.004188,0.106365,293.299622,14.941396,1.063646,-1299.955811,294.500458,0.000000
73.590004,65.375580,-1300.133667,-0.001681,0.004188,0.106365,290.805115,14.814319,1.063646,-1300.133667,294.500458,0.000000
74.030006,65.078415,-1300.000244,-0.001681,0.004204,0.106781,289.483246,14.746980,1.067810,-1300.000244,294.500458,0.000000
74.470001,65.505905,-1300.044800,-0.001686,0.004215,0.107058,291.384827,14.843851,1.070580,-1300.044800,294.500458,0.000000
74.910004,65.184540,-1300.089233,-0.001669,0.004215,0.107067,289.955322,14.771028,1.070671,-1300.089233,294.500458,0.000000
75.350006,64.826324,-1299.955811,-0.001673,0.004217,0.107111,288.361908,14.689856,1.071110,-1299.955811,294.500458,0.000000
75.790001,65.613144,-1300.089233,-0.001664,0.004229,0.107405,291.861847,14.868151,1.074047,-1300.089233,294.500458,0.000000
76.230003,65.274292,-1300.044800,-0.001656,0.004229,0.107405,290.354553,14.791366,1.074047,-1300.044800,294.500458,0.000000
76.670006,64.881805,-1300.000244,-0.001677,0.004229,0.107405,288.608673,14.702427,1.074047,-1300.000244,294.500458,0.000000
77.110001,64.497147,-1300.089233,-0.001664,0.004229,0.107405,286.897644,14.615263,1.074047,-1300.089233,294.500458,0.000000
77.550003,66.754471,-1300.089233,-0.001647,0.004169,0.105897,296.938721,15.126780,1.058968,-1300.089233,294.500458,0.000000
77.990005,66.337784,-1300.133667,-0.001621,0.004169,0.105897,295.085205,15.032356,1.058968,-1300.133667,294.500458,0.000000
78.430000,65.945297,-1300.000244,-0.001621,0.004173,0.105992,293.339325,14.943419,1.059922,-1300.000244,294.500458,0.000000
78.870003,65.507019,-1300.089233,-0.001625,0.004197,0.106616,291.389771,14.844102,1.066159,-1300.089233,294.500458,0.000000
79.310005,65.161087,-1300.089233,-0.001625,0.004217,0.107102,289.850983,14.765714,1.071019,-1300.089233,294.500458,0.000000
79.750000,64.976013,-1300.044800,-0.001621,0.004248,0.107891,289.027740,14.723775,1.078907,-1300.044800,294.500458,0.000000
80.190002,65.114914,-1300.044800,-0.001621,0.004256,0.108100,289.645599,14.755250,1.080996,-1300.044800,294.500458,0.000000
80.630005,65.127579,-1300.000244,-0.001608,0.004259,0.108186,289.701935,14.758121,1.081859,-1300.000244,294.500458,0.000000
81.070007,65.211349,-1300.000244,-0.001617,0.004264,0.108298,290.074585,14.777102,1.082980,-1300.000244,294.500458,0.000000
81.510002,65.023315,-1300.089233,-0.001608,0.004266,0.108351,289.238159,14.734494,1.083509,-1300.089233,294.500458,0.000000
81.950005,65.146942,-1300.000244,-0.001617,0.004270,0.108446,289.788086,14.762508,1.084463,-1300.000244,294.500458,0.000000
82.390007,65.011398,-1300.089233,-0.001613,0.004271,0.108489,289.185150,14.731793,1.084887,-1300.089233,294.500458,0.000000
82.830002,65.009903,-1300.089233,-0.001625,0.004274,0.108567,289.178497,14.731455,1.085674,-1300.089233,294.500458,0.000000
83.270004,65.015488,-1300.089233,-0.001625,0.004278,0.108654,289.203339,14.732720,1.086537,-1300.089233,294.500458,0.000000
83.710007,64.888138,-1300.133667,-0.001617,0.004278,0.108663,288.636841,14.703862,1.086628,-1300.133667,294.500458,0.000000
84.150002,65.539413,-1299.955811,-0.001608,0.004288,0.108914,291.533875,14.851443,1.089141,-1299.955811,294.500458,0.000000
84.590004,65.388977,-1300.089233,-0.001608,0.004288,0.108914,290.864685,14.817353,1.089141,-1300.089233,294.500458,0.000000
85.030006,65.200180,-1300.044800,-0.001608,0.004288,0.108914,290.024872,14.774571,1.089141,-1300.044800,294.500458,0.000000
85.470001,64.983093,-1300.044800,-0.001617,0.004288,0.108923,289.059235,14.725379,1.089232,-1300.044800,294.500458,0.000000
85.910004,64.752228,-1300.178223,-0.001621,0.004288,0.108923,288.032288,14.673065,1.089232,-1300.178223,294.500458,0.000000
86.350006,64.519867,-1300.089233,-0.001595,0.004288,0.108923,286.998688,14.620411,1.089232,-1300.089233,294.500458,0.000000
86.790001,64.261063,-1300.089233,-0.001600,0.004288,0.108923,285.847473,14.561765,1.089232,-1300.089233,294.500458,0.000000
87.230003,64.042480,-1300.089233,-0.001604,0.004288,0.108923,284.875183,14.512234,1.089232,-1300.089233,294.500458,0.000000
87.670006,66.688934,-1300.133667,-0.001565,0.004120,0.104648,296.647186,15.111929,1.046478,-1300.133667,294.500458,0.000000
88.110001,66.410019,-1300.133667,-0.001569,0.004121,0.104664,295.406525,15.048725,1.046645,-1300.133667,294.500458,0.000000
88.550003,66.151596,-1300.133667,-0.001565,0.004121,0.104664,294.256989,14.990166,1.046645,-1300.133667,294.500458,0.000000
88.990005,65.895782,-1300.000244,-0.001561,0.004123,0.104734,293.119080,14.932199,1.047341,-1300.000244,294.500458,0.000000
89.430008,65.666016,-1300.133667,-0.001556,0.004140,0.105169,292.097015,14.880132,1.051686,-1300.133667,294.500458,0.000000
89.870003,65.456375,-1300.089233,-0.001569,0.004229,0.107423,291.164490,14.832626,1.074229,-1300.089233,294.500458,0.000000
90.310005,65.229599,-1300.178223,-0.001561,0.004275,0.108577,290.155762,14.781239,1.085765,-1300.178223,294.500458,0.000000
90.750008,65.026657,-1300.089233,-0.001548,0.004288,0.108923,289.253021,14.735251,1.089232,-1300.089233,294.500458,0.000000
91.190002,64.875473,-1300.133667,-0.001544,0.004301,0.109252,288.580505,14.700992,1.092517,-1300.133667,294.500458,0.000000
91.630005,65.094437,-1300.133667,-0.001544,0.004314,0.109573,289.554504,14.750610,1.095727,-1300.133667,294.500458,0.000000
92.070007,64.958893,-1300.089233,-0.001565,0.004315,0.109600,288.951599,14.719896,1.096000,-1300.089233,294.500458,0.000000
92.510002,64.960754,-1300.178223,-0.001561,0.004317,0.109661,288.959869,14.720317,1.096605,-1300.178223,294.500458,0.000000
92.950005,64.830048,-1300.133667,-0.001556,0.004320,0.109730,288.378448,14.690699,1.097302,-1300.133667,294.500458,0.000000
93.390007,65.225510,-1300.133667,-0.001556,0.004324,0.109833,290.137543,14.780312,1.098331,-1300.133667,294.500458,0.000000
93.830002,65.092575,-1300.089233,-0.001569,0.004324,0.109833,289.546234,14.750189,1.098331,-1300.089233,294.500458,0.000000
94.270004,65.131302,-1300.044800,-0.001561,0.004327,0.109912,289.718506,14.758964,1.099118,-1300.044800,294.500458,0.000000
94.710007,65.092941,-1300.133667,-0.001569,0.004328,0.109938,289.547852,14.750272,1.099376,-1300.133667,294.500458,0.000000
95.150002,65.009155,-1300.178223,-0.001552,0.004329,0.109963,289.175171,14.731285,1.099633,-1300.178223,294.500458,0.000000
95.590004,65.030014,-1300.089233,-0.001552,0.004333,0.110050,289.267944,14.736012,1.100496,-1300.089233,294.500458,0.000000
96.030006,64.995377,-1300.133667,-0.001556,0.004333,0.110050,289.113861,14.728163,1.100496,-1300.133667,294.500458,0.000000
96.470001,64.941757,-1300.044800,-0.001565,0.004335,0.110103,288.875366,14.716012,1.101026,-1300.044800,294.500458,0.000000
96.910004,64.916443,-1300.133667,-0.001556,0.004335,0.110103,288.762756,14.710277,1.101026,-1300.133667,294.500458,0.000000
97.350006,65.014374,-1300.089233,-0.001539,0.004338,0.110189,289.198364,14.732468,1.101889,-1300.089233,294.500458,0.000000
97.790001,64.914200,-1300.133667,-0.001552,0.004338,0.110189,288.752777,14.709768,1.101889,-1300.133667,294.500458,0.000000
98.230003,65.505157,-1300.222656,-0.001556,0.004348,0.110440,291.381500,14.843681,1.104402,-1300.222656,294.500458,0.000000
98.670006,65.559891,-1300.044800,-0.001556,0.004348,0.110433,291.624969,14.856084,1.104326,-1300.044800,294.500458,0.000000
99.110008,65.482437,-1300.133667,-0.001561,0.004348,0.110433,291.280426,14.838532,1.104326,-1300.133667,294.500458,0.000000
99.550003,65.342056,-1300.089233,-0.001556,0.004348,0.110433,290.655975,14.806722,1.104326,-1300.089233,294.500458,0.000000
99.990005,65.216568,-1300.000244,-0.001561,0.004348,0.110433,290.097778,14.778286,1.104326,-1300.000244,294.500458,0.000000
100.430008,65.093307,-1300.089233,-0.001556,0.004348,0.110440,289.549500,14.750354,1.104402,-1300.089233,294.500458,0.000000
100.870003,64.978256,-1300.089233,-0.001548,0.004348,0.110449,289.037720,14.724283,1.104493,-1300.089233,294.500458,0.000000
101.310005,64.856491,-1300.133667,-0.001556,0.004348,0.110449,288.496094,14.696691,1.104493,-1300.133667,294.500458,0.000000
101.750008,65.205032,-1300.089233,-0.001544,0.004355,0.110605,290.046478,14.775672,1.106052,-1300.089233,294.500458,0.000000
102.190002,65.118637,-1300.000244,-0.001544,0.004355,0.110605,289.662170,14.756094,1.106052,-1300.000244,294.500458,0.000000
102.630005,65.014374,-1300.133667,-0.001548,0.004355,0.110605,289.198364,14.732468,1.106052,-1300.133667,294.500458,0.000000
103.070007,65.405365,-1300.089233,-0.001539,0.004361,0.110779,290.937592,14.821068,1.107793,-1300.089233,294.500458,0.000000
103.510002,65.385620,-1300.044800,-0.001556,0.004361,0.110779,290.849762,14.816593,1.107793,-1300.044800,294.500458,0.000000
103.950005,65.298859,-1300.089233,-0.001539,0.004361,0.110779,290.463837,14.796933,1.107793,-1300.089233,294.500458,0.000000
104.390007,65.206894,-1300.044800,-0.001539,0.004361,0.110779,290.054749,14.776093,1.107793,-1300.044800,294.500458,0.000000
104.830002,65.101501,-1300.133667,-0.001544,0.004361,0.110779,289.585937,14.752212,1.107793,-1300.133667,294.500458,0.000000
105.270004,65.006180,-1300.044800,-0.001535,0.004361,0.110779,289.161926,14.730611,1.107793,-1300.044800,294.500458,0.000000
105.710007,64.901535,-1300.044800,-0.001539,0.004362,0.110787,288.696442,14.706899,1.107869,-1300.044800,294.500458,0.000000
106.150002,64.797272,-1300.133667,-0.001526,0.004365,0.110882,288.232666,14.683272,1.108823,-1300.133667,294.500458,0.000000
106.590004,64.941757,-1300.044800,-0.001526,0.004366,0.110891,288.875366,14.716012,1.108914,-1300.044800,294.500458,0.000000
107.030006,64.873993,-1300.133667,-0.001552,0.004366,0.110891,288.573944,14.700657,1.108914,-1300.133667,294.500458,0.000000
107.470009,64.799515,-1300.133667,-0.001526,0.004366,0.110891,288.242645,14.683780,1.108914,-1300.133667,294.500458,0.000000
107.910004,65.619476,-1300.222656,-0.001526,0.004376,0.111143,291.890015,14.869586,1.111427,-1300.222656,294.500458,0.000000
108.350006,65.578888,-1300.133667,-0.001535,0.004376,0.111143,291.709473,14.860388,1.111427,-1300.133667,294.500458,0.000000
108.790009,65.529358,-1300.133667,-0.001544,0.004376,0.111143,291.489136,14.849164,1.111427,-1300.133667,294.500458,0.000000
109.230003,65.421753,-1300.178223,-0.001531,0.004376,0.111143,291.010498,14.824781,1.111427,-1300.178223,294.500458,0.000000
109.670006,65.328278,-1300.044800,-0.001526,0.004376,0.111143,290.594696,14.803599,1.111427,-1300.044800,294.500458,0.000000
110.110008,65.231461,-1300.133667,-0.001531,0.004376,0.111143,290.164032,14.781660,1.111427,-1300.133667,294.500458,0.000000
110.550003,65.113419,-1300.178223,-0.001518,0.004376,0.111143,289.638947,14.754911,1.111427,-1300.178223,294.500458,0.000000
110.990005,65.032242,-1300.133667,-0.001531,0.004376,0.111143,289.277863,14.736517,1.111427,-1300.133667,294.500458,0.000000
111.430008,64.938782,-1300.133667,-0.001531,0.004376,0.111143,288.862122,14.715339,1.111427,-1300.133667,294.500458,0.000000
111.870003,64.800262,-1300.133667,-0.001531,0.004376,0.111143,288.245972,14.683949,1.111427,-1300.133667,294.500458,0.000000
112.310005,64.693756,-1300.178223,-0.001535,0.004376,0.111143,287.772186,14.659815,1.111427,-1300.178223,294.500458,0.000000
112.750008,64.593216,-1300.178223,-0.001526,0.004376,0.111143,287.324982,14.637032,1.111427,-1300.178223,294.500458,0.000000
113.190002,64.490067,-1300.133667,-0.001526,0.004376,0.111143,286.866150,14.613658,1.111427,-1300.133667,294.500458,0.000000
113.630005,66.398849,-1300.222656,-0.001513,0.004390,0.111508,295.356842,15.046194,1.115075,-1300.222656,294.500458,0.000000
114.070007,66.252136,-1300.133667,-0.001513,0.004386,0.111394,294.704224,15.012949,1.113940,-1300.133667,294.500458,0.000000
114.510002,66.121811,-1300.222656,-0.001509,0.004386,0.111394,294.124512,14.983417,1.113940,-1300.222656,294.500458,0.000000
114.950005,65.980301,-1300.133667,-0.001505,0.004386,0.111394,293.495026,14.951350,1.113940,-1300.133667,294.500458,0.000000
115.390007,65.886093,-1300.133667,-0.001509,0.004386,0.111394,293.075989,14.930002,1.113940,-1300.133667,294.500458,0.000000
115.830002,65.792252,-1300.267212,-0.001526,0.004386,0.111394,292.658539,14.908737,1.113940,-1300.267212,294.500458,0.000000
116.270004,65.613144,-1300.133667,-0.001505,0.004386,0.111394,291.861847,14.868151,1.113940,-1300.133667,294.500458,0.000000
116.710007,65.559525,-1300.178223,-0.001496,0.004386,0.111394,291.623322,14.856000,1.113940,-1300.178223,294.500458,0.000000
117.150009,65.424728,-1300.222656,-0.001513,0.004386,0.111394,291.023712,14.825455,1.113940,-1300.222656,294.500458,0.000000
117.590004,65.317856,-1300.133667,-0.001509,0.004386,0.111394,290.548340,14.801237,1.113940,-1300.133667,294.500458,0.000000
118.030006,65.239655,-1300.133667,-0.001500,0.004386,0.111394,290.200470,14.783518,1.113940,-1300.133667,294.500458,0.000000
118.470009,65.081024,-1300.133667,-0.001500,0.004387,0.111438,289.494843,14.747571,1.114379,-1300.133667,294.500458,0.000000
118.910004,65.039688,-1300.133667,-0.001513,0.004393,0.111577,289.310974,14.738203,1.115772,-1300.133667,294.500458,0.000000
119.350006,65.032242,-1300.133667,-0.001500,0.004393,0.111577,289.277863,14.736517,1.115772,-1300.133667,294.500458,0.000000
119.790009,64.944733,-1300.133667,-0.001500,0.004393,0.111577,288.888611,14.716687,1.115772,-1300.133667,294.500458,0.000000
120.230003,64.861328,-1300.267212,-0.001505,0.004393,0.111577,288.517609,14.697787,1.115772,-1300.267212,294.500458,0.000000
120.670006,65.368500,-1300.178223,-0.001492,0.004402,0.111819,290.773621,14.812714,1.118194,-1300.178223,294.500458,0.000000
121.110008,65.458237,-1300.178223,-0.001492,0.004402,0.111819,291.172791,14.833049,1.118194,-1300.178223,294.500458,0.000000
121.550003,65.375946,-1300.178223,-0.001496,0.004402,0.111819,290.806732,14.814402,1.118194,-1300.178223,294.500458,0.000000
121.990005,65.340576,-1300.178223,-0.001505,0.004402,0.111819,290.649414,14.806386,1.118194,-1300.178223,294.500458,0.000000
122.430008,65.275772,-1300.178223,-0.001500,0.004402,0.111819,290.361145,14.791701,1.118194,-1300.178223,294.500458,0.000000
122.870003,65.196457,-1300.133667,-0.001509,0.004402,0.111819,290.008331,14.773728,1.118194,-1300.133667,294.500458,0.000000
123.310005,65.102249,-1300.311646,-0.001500,0.004402,0.111819,289.589264,14.752380,1.118194,-1300.311646,294.500458,0.000000
123.750008,65.058685,-1300.133667,-0.001496,0.004402,0.111819,289.395477,14.742508,1.118194,-1300.133667,294.500458,0.000000
124.190002,65.007294,-1300.178223,-0.001500,0.004403,0.111845,289.166870,14.730864,1.118452,-1300.178223,294.500458,0.000000
124.630005,64.969681,-1300.133667,-0.001487,0.004394,0.111612,288.999573,14.722340,1.116120,-1300.133667,0.111698,0.000000
125.070007,64.902664,-1300.178223,-0.001505,0.004383,0.111317,288.701477,14.707154,1.113168,-1300.178223,0.110961,0.000000
125.510010,64.725784,-1300.222656,-0.001496,0.004357,0.110666,287.914673,14.667072,1.106658,-1300.222656,0.110233,0.000000
125.950005,64.602158,-1300.178223,-0.001496,0.004329,0.109963,287.364746,14.639058,1.099633,-1300.178223,0.109495,0.000000
126.390007,64.520233,-1300.222656,-0.001479,0.004301,0.109235,287.000336,14.620494,1.092351,-1300.222656,0.108767,0.000000
126.830009,64.438690,-1300.178223,-0.001483,0.004276,0.108611,286.637604,14.602016,1.086113,-1300.178223,0.108030,0.000000
127.270004,64.342606,-1300.178223,-0.001475,0.004246,0.107839,286.210205,14.580243,1.078392,-1300.178223,0.107293,0.000000
127.710007,64.248398,-1300.178223,-0.001475,0.004219,0.107162,285.791138,14.558895,1.071625,-1300.178223,0.106564,0.000000
128.150009,64.144135,-1300.178223,-0.001475,0.004192,0.106477,285.327362,14.535268,1.064767,-1300.178223,0.105827,0.000000
128.590012,63.942688,-1300.222656,-0.001470,0.004164,0.105774,284.431274,14.489620,1.057742,-1300.222656,0.105099,0.000000
129.029999,63.237778,-1300.133667,-0.001457,0.004136,0.105046,281.295685,14.329885,1.050460,-1300.133667,0.104362,0.000000
129.470001,62.072998,-1300.133667,-0.001457,0.004108,0.104353,276.114471,14.065943,1.043526,-1300.133667,0.103633,0.000000
129.910004,60.762993,-1300.178223,-0.001449,0.004085,0.103755,270.287292,13.769092,1.037546,-1300.178223,0.102896,0.000000
130.350006,58.768944,-1300.133667,-0.001431,0.004057,0.103052,261.417328,13.317233,1.030521,-1300.133667,0.102159,0.000000
130.790009,57.602295,-1300.178223,-0.001440,0.004045,0.102731,256.227814,13.052867,1.027311,-1300.178223,0.101431,0.000000
131.230011,54.071091,-1300.178223,-0.001427,0.004002,0.101647,240.520218,12.252684,1.016471,-1300.178223,0.100693,0.000000
131.670013,51.365433,-1300.178223,-0.001431,0.003972,0.100901,228.484863,11.639573,1.009008,-1300.178223,0.099965,0.000000
132.110001,49.044060,-1300.178223,-0.001423,0.003954,0.100424,218.158875,11.113543,1.004239,-1300.178223,0.099228,0.000000
132.550003,45.721008,-1300.133667,-0.001423,0.003924,0.099670,203.377197,10.360529,0.996699,-1300.133667,0.098500,0.000000
132.990005,41.807373,-1300.133667,-0.001431,0.003888,0.098759,185.968491,9.473686,0.987585,-1300.133667,0.097762,0.000000
133.430008,38.701416,-1300.267212,-0.001440,0.003859,0.098021,172.152496,8.769866,0.980212,-1300.267212,0.097025,0.000000
133.870010,35.494171,-1300.133667,-0.001444,0.003831,0.097311,157.885956,8.043095,0.973112,-1300.133667,0.096297,0.000000
134.310013,32.449280,-1300.178223,-0.001423,0.003806,0.096660,144.341599,7.353112,0.966602,-1300.178223,0.095560,0.000000
134.750000,29.474396,-1300.133667,-0.001427,0.003776,0.095923,131.108658,6.678994,0.959229,-1300.133667,0.094830,0.000000
135.190002,25.603958,-1300.178223,-0.001436,0.003743,0.095064,113.892097,5.801940,0.950644,-1300.178223,0.094094,0.000000
135.630005,22.703926,-1300.133667,-0.001427,0.003716,0.094397,100.992104,5.144783,0.943968,-1300.133667,0.093364,0.000000
136.070007,19.289268,-1300.178223,-0.001427,0.003686,0.093634,85.802948,4.371011,0.936338,-1300.178223,0.092628,0.000000
136.510010,16.773148,-1300.178223,-0.001427,0.003660,0.092957,74.610687,3.800850,0.929570,-1300.178223,0.091891,0.000000
136.950012,12.147163,-1300.133667,-0.001449,0.003621,0.091977,54.033283,2.752587,0.919775,-1300.133667,0.091161,0.000000
137.389999,9.690994,-1300.178223,-0.001427,0.003598,0.091387,43.107697,2.196011,0.913870,-1300.178223,0.090426,0.000000
137.830002,6.976028,-1300.178223,-0.001431,0.003573,0.090763,31.030924,1.580791,0.907633,-1300.178223,0.089696,0.000000
138.270004,3.941933,-1300.133667,-0.001436,0.003542,0.089975,17.534592,0.893255,0.899745,-1300.133667,0.088959,0.000000
138.710007,2.595436,-1300.267212,-0.001431,0.003528,0.089601,11.545076,0.588134,0.896006,-1300.267212,0.088230,0.000000
139.150009,-1.179302,-1300.133667,-0.001431,0.003489,0.088612,-5.245798,-0.267234,0.886120,-1300.133667,0.087493,0.000000
139.590012,-3.361404,-1300.267212,-0.001440,0.003457,0.087807,-14.952273,-0.761705,0.878065,-1300.267212,0.086765,0.000000
140.030014,-0.415565,-1300.133667,-0.001423,0.003431,0.087146,-1.848528,-0.094168,0.871464,-1300.133667,0.086028,0.000000
140.470001,-0.493019,-1300.178223,-0.001423,0.003400,0.086358,-2.193058,-0.111720,0.863577,-1300.178223,0.085290,0.000000
140.910004,-0.080429,-1300.222656,-0.001414,0.003374,0.085707,-0.357766,-0.018225,0.857067,-1300.222656,0.084562,0.000000
141.350006,-0.122139,-1300.178223,-0.001418,0.003338,0.084788,-0.543301,-0.027677,0.847877,-1300.178223,0.083825,0.000000
141.790009,-0.058090,-1300.222656,-0.001431,0.003316,0.084225,-0.258398,-0.013163,0.842245,-1300.222656,0.083097,0.000000
142.230011,-0.070007,-1300.178223,-0.001423,0.003286,0.083471,-0.311408,-0.015864,0.834706,-1300.178223,0.082359,0.000000
142.670013,-0.073730,-1300.222656,-0.001431,0.003259,0.082768,-0.327969,-0.016708,0.827681,-1300.222656,0.081631,0.000000
143.110001,-0.153046,-1300.267212,-0.001427,0.003226,0.081943,-0.680781,-0.034681,0.819430,-1300.267212,0.080894,0.000000
143.550003,-0.142616,-1300.178223,-0.001431,0.003198,0.081233,-0.634389,-0.032317,0.812329,-1300.178223,0.080157,0.000000
143.990005,-0.135544,-1300.178223,-0.001431,0.003168,0.080470,-0.602929,-0.030715,0.804699,-1300.178223,0.079428,0.000000
144.430008,-0.142242,-1300.267212,-0.001414,0.003137,0.079689,-0.632726,-0.032233,0.796887,-1300.267212,0.078691,0.000000
144.870010,-0.138519,-1300.222656,-0.001444,0.003114,0.079107,-0.616165,-0.031389,0.791073,-1300.222656,0.077963,0.000000
145.310013,-0.167564,-1300.267212,-0.001440,0.003078,0.078179,-0.745364,-0.037971,0.781793,-1300.267212,0.077225,0.000000
145.750000,-0.173523,-1300.222656,-0.001436,0.003050,0.077469,-0.771869,-0.039321,0.774692,-1300.222656,0.076497,0.000000
146.190002,-0.202194,-1300.178223,-0.001457,0.003027,0.076897,-0.899405,-0.045818,0.768970,-1300.178223,0.075760,0.000000
146.630005,-0.198105,-1300.222656,-0.001449,0.002991,0.075960,-0.881214,-0.044891,0.759598,-1300.222656,0.075023,0.000000
147.070007,-0.180969,-1300.178223,-0.001466,0.002961,0.075206,-0.804991,-0.041008,0.752059,-1300.178223,0.074294,0.000000
147.510010,-0.182831,-1300.311646,-0.001513,0.002930,0.074416,-0.813272,-0.041430,0.744156,-1300.311646,0.073557,0.000000
147.950012,-0.172035,-1300.133667,-0.001539,0.002903,0.073731,-0.765251,-0.038984,0.737313,-1300.133667,0.072829,0.000000
148.390015,-0.182465,-1300.311646,-0.001578,0.002874,0.073003,-0.811643,-0.041347,0.730031,-1300.311646,0.072092,0.000000
148.830002,-0.182465,-1300.222656,-0.001604,0.002847,0.072326,-0.811643,-0.041347,0.723263,-1300.222656,0.071363,0.000000
149.270004,-0.229012,-1300.267212,-0.001630,0.002819,0.071606,-1.018694,-0.051895,0.716057,-1300.267212,0.070626,0.000000
149.710007,-0.214111,-1300.267212,-0.001651,0.002787,0.070800,-0.952415,-0.048518,0.708002,-1300.267212,0.069889,0.000000
150.150009,-0.212624,-1300.178223,-0.001681,0.002763,0.070175,-0.945797,-0.048181,0.701750,-1300.178223,0.069161,0.000000
150.590012,-0.216347,-1300.222656,-0.001716,0.002728,0.069282,-0.962358,-0.049025,0.692817,-1300.222656,0.068423,0.000000
151.030014,-0.232361,-1300.178223,-0.001759,0.002701,0.068597,-1.033593,-0.052654,0.685974,-1300.178223,0.067695,0.000000
151.470001,-0.231239,-1300.178223,-0.001776,0.002677,0.067998,-1.028604,-0.052400,0.679979,-1300.178223,0.066958,0.000000
151.910004,-0.212624,-1300.178223,-0.001815,0.002648,0.067253,-0.945797,-0.048181,0.672530,-1300.178223,0.066230,0.000000
152.350006,-0.226028,-1300.178223,-0.001832,0.002617,0.066472,-1.005425,-0.051219,0.664718,-1300.178223,0.065492,0.000000
152.790009,-0.240555,-1300.178223,-0.001880,0.002587,0.065718,-1.070041,-0.054511,0.657179,-1300.178223,0.064764,0.000000
153.230011,-0.253960,-1300.178223,-0.001901,0.002562,0.065067,-1.129669,-0.057548,0.650669,-1300.178223,0.064027,0.000000
153.670013,-0.216721,-1300.178223,-0.001932,0.002526,0.064166,-0.964021,-0.049110,0.641661,-1300.178223,0.063290,0.000000
154.110001,-0.234222,-1300.267212,-0.001957,0.002505,0.063636,-1.041873,-0.053076,0.636362,-1300.267212,0.062561,0.000000
154.550003,-0.192886,-1300.222656,-0.001996,0.002470,0.062734,-0.858001,-0.043709,0.627339,-1300.222656,0.061824,0.000000
154.990005,-0.225281,-1300.267212,-0.002031,0.002444,0.062066,-1.002099,-0.051049,0.620662,-1300.267212,0.061096,0.000000
155.430008,-0.201828,-1300.222656,-0.002052,0.002413,0.061296,-0.897776,-0.045735,0.612956,-1300.222656,0.060358,0.000000
155.870010,-0.217461,-1300.222656,-0.002074,0.002396,0.060861,-0.967313,-0.049277,0.608611,-1300.222656,0.059630,0.000000
156.310013,-0.214111,-1300.311646,-0.002139,0.002352,0.059733,-0.952415,-0.048518,0.597332,-1300.311646,0.058893,0.000000
156.750000,-0.218208,-1300.178223,-0.002147,0.002329,0.059153,-0.970639,-0.049447,0.591534,-1300.178223,0.058156,0.000000
157.190002,-0.218208,-1300.222656,-0.002173,0.002302,0.058468,-0.970639,-0.049447,0.584675,-1300.222656,0.057427,0.000000
157.630005,-0.212624,-1300.222656,-0.002199,0.002273,0.057739,-0.945797,-0.048181,0.577393,-1300.222656,0.056690,0.000000
158.070007,-0.220444,-1300.178223,-0.002233,0.002241,0.056932,-0.980583,-0.049953,0.569324,-1300.178223,0.055962,0.000000
158.510010,-0.214111,-1300.222656,-0.002264,0.002213,0.056222,-0.952415,-0.048518,0.562223,-1300.222656,0.055225,0.000000
158.950012,-0.203316,-1300.089233,-0.002281,0.002183,0.055441,-0.904394,-0.046072,0.554411,-1300.089233,0.054496,0.000000
159.390015,-0.208153,-1300.222656,-0.002307,0.002168,0.055060,-0.925910,-0.047168,0.550596,-1300.222656,0.053759,0.000000
159.830002,-0.202568,-1300.178223,-0.002341,0.002127,0.054036,-0.901068,-0.045903,0.540362,-1300.178223,0.053022,0.000000
160.270004,-0.194374,-1300.178223,-0.002367,0.002112,0.053655,-0.864619,-0.044046,0.536547,-1300.178223,0.052294,0.000000
160.710007,-0.205177,-1300.222656,-0.002423,0.002068,0.052519,-0.912674,-0.046494,0.525192,-1300.222656,0.051556,0.000000
161.150009,-0.159744,-1300.133667,-0.002427,0.002043,0.051894,-0.710578,-0.036199,0.518939,-1300.133667,0.050828,0.000000
161.590012,-0.161980,-1300.178223,-0.002453,0.002017,0.051244,-0.720522,-0.036705,0.512444,-1300.178223,0.050091,0.000000
162.030014,-0.164963,-1300.178223,-0.002496,0.001981,0.050307,-0.733791,-0.037381,0.503073,-1300.178223,0.049363,0.000000
162.470001,-0.199219,-1300.089233,-0.002531,0.001952,0.049587,-0.886169,-0.045144,0.495867,-1300.089233,0.048625,0.000000
162.910004,-0.218956,-1300.178223,-0.002561,0.001926,0.048911,-0.973965,-0.049616,0.489114,-1300.178223,0.047888,0.000000
163.350006,-0.137779,-1300.178223,-0.002587,0.001906,0.048416,-0.612873,-0.031221,0.484164,-1300.178223,0.047160,0.000000
163.790009,-0.129585,-1300.178223,-0.002617,0.001874,0.047602,-0.576424,-0.029364,0.476019,-1300.178223,0.046422,0.000000
164.230011,-0.175385,-1300.178223,-0.002647,0.001843,0.046804,-0.780149,-0.039743,0.468040,-1300.178223,0.045693,0.000000
164.670013,-0.213737,-1300.089233,-0.002686,0.001809,0.045953,-0.950752,-0.048434,0.459532,-1300.089233,0.044957,0.000000
165.110001,-0.169800,-1300.133667,-0.002703,0.001784,0.045304,-0.755307,-0.038477,0.453037,-1300.133667,0.044227,0.000000
165.550003,-0.154533,-1300.089233,-0.002729,0.001756,0.044609,-0.687399,-0.035018,0.446088,-1300.089233,0.043491,0.000000
165.990005,-0.158257,-1300.178223,-0.002781,0.001730,0.043941,-0.703960,-0.035861,0.439411,-1300.178223,0.042762,0.000000
166.430008,-0.206291,-1300.222656,-0.002807,0.001695,0.043057,-0.917629,-0.046746,0.430570,-1300.222656,0.042024,0.000000
166.870010,-0.180603,-1300.133667,-0.002854,0.001662,0.042224,-0.803362,-0.040925,0.422243,-1300.133667,0.041289,0.000000
167.310013,-0.207787,-1300.133667,-0.002863,0.001639,0.041635,-0.924281,-0.047085,0.416354,-1300.133667,0.040559,0.000000
167.750015,-0.189537,-1300.133667,-0.002893,0.001604,0.040742,-0.843103,-0.042950,0.407421,-1300.133667,0.039823,0.000000
168.190002,-0.198471,-1300.089233,-0.002936,0.001581,0.040161,-0.882843,-0.044974,0.401608,-1300.089233,0.039093,0.000000
168.630005,-0.179482,-1300.133667,-0.002962,0.001547,0.039293,-0.798374,-0.040671,0.392933,-1300.133667,0.038356,0.000000
169.070007,-0.170174,-1300.133667,-0.002997,0.001525,0.038730,-0.756970,-0.038562,0.387301,-1300.133667,0.037628,0.000000
169.510010,-0.173897,-1300.222656,-0.003018,0.001499,0.038070,-0.773532,-0.039406,0.380700,-1300.222656,0.036891,0.000000
169.950012,-0.194008,-1300.133667,-0.003044,0.001464,0.037195,-0.862990,-0.043963,0.371949,-1300.133667,0.036153,0.000000
170.390015,-0.227890,-1300.089233,-0.003087,0.001431,0.036353,-1.013705,-0.051641,0.363532,-1300.089233,0.035425,0.000000
170.830002,-0.210014,-1300.133667,-0.003130,0.001403,0.035643,-0.934190,-0.047590,0.356431,-1300.133667,0.034688,0.000000
171.270004,-0.232361,-1300.089233,-0.003147,0.001380,0.035053,-1.033593,-0.052654,0.350527,-1300.089233,0.033960,0.000000
171.710007,-0.203316,-1300.089233,-0.003165,0.001347,0.034203,-0.904394,-0.046072,0.342033,-1300.089233,0.033222,0.000000
172.150009,-0.235710,-1300.089233,-0.003208,0.001318,0.033474,-1.048491,-0.053413,0.334736,-1300.089233,0.032494,0.000000
172.590012,-0.234962,-1300.089233,-0.003229,0.001289,0.032745,-1.045165,-0.053243,0.327454,-1300.089233,0.031757,0.000000
173.030014,-0.221558,-1300.133667,-0.003264,0.001258,0.031957,-0.985538,-0.050206,0.319566,-1300.133667,0.031019,0.000000
173.470001,-0.213737,-1300.133667,-0.003277,0.001233,0.031306,-0.950752,-0.048434,0.313056,-1300.133667,0.030291,0.000000
173.910004,-0.229752,-1300.133667,-0.003328,0.001205,0.030612,-1.021986,-0.052062,0.306122,-1300.133667,0.029554,0.000000
174.350006,-0.229752,-1300.089233,-0.003367,0.001172,0.029780,-1.021986,-0.052062,0.297796,-1300.089233,0.028826,0.000000
174.790009,-0.217834,-1300.133667,-0.003372,0.001148,0.029147,-0.968976,-0.049362,0.291467,-1300.133667,0.028088,0.000000
175.230011,-0.227890,-1300.133667,-0.003419,0.001130,0.028705,-1.013705,-0.051641,0.287046,-1300.133667,0.027360,0.000000
175.670013,-0.211136,-1300.044800,-0.003458,0.001091,0.027707,-0.939179,-0.047844,0.277069,-1300.044800,0.026623,0.000000
176.110016,-0.177620,-1300.178223,-0.003488,0.001067,0.027092,-0.790093,-0.040249,0.270923,-1300.178223,0.026962,0.000000
176.200012,-0.173149,-1300.133667,-0.003479,0.001067,0.027100,-0.770206,-0.039236,0.270998,-1300.133667,0.026962,0.000000