File: Data/compression 28/AutoNoHeating-17-28-reverse-1-3_10222024_182710.csv
Time (sec),S:Load (lbs),S:HL1 (DIM),S:LVDT (in),S:Position (in),Ch:Position (mm),Ch:Load (N),Ch:Stress (MPa),Ch:Strain (mm/mm),Ch:HL1 (DIM),Set Point (),Cycles ()
0.110000,-0.081177,-1298.888306,-0.011900,-0.006407,-0.162735,-0.361092,-0.018395,-1.627353,-1298.888306,-0.162545,0.000000
0.530000,-0.068886,-1298.888306,-0.011908,-0.006296,-0.159925,-0.306419,-0.015610,-1.599254,-1298.888306,-0.159214,0.000000
0.950000,-0.080429,-1298.799316,-0.011740,-0.006033,-0.153247,-0.357766,-0.018225,-1.532474,-1298.799316,-0.152224,0.000000
1.370000,-0.091232,-1298.843750,-0.011473,-0.005768,-0.146501,-0.405822,-0.020674,-1.465012,-1298.843750,-0.145217,0.000000
1.790000,-0.072983,-1298.888306,-0.011197,-0.005492,-0.139502,-0.324644,-0.016538,-1.395021,-1298.888306,-0.138227,0.000000
2.210000,-0.070374,-1298.932739,-0.010930,-0.005215,-0.132461,-0.313037,-0.015947,-1.324607,-1298.932739,-0.131219,0.000000
2.630000,-0.046547,-1298.843750,-0.010662,-0.004942,-0.125522,-0.207051,-0.010548,-1.255223,-1298.843750,-0.124231,0.000000
3.050000,-0.084526,-1298.888306,-0.010378,-0.004665,-0.118488,-0.375991,-0.019154,-1.184884,-1298.888306,-0.117241,0.000000
3.470000,-0.033516,-1298.754761,-0.010089,-0.004385,-0.111386,-0.149086,-0.007595,-1.113864,-1298.754761,-0.110233,0.000000
3.890000,-0.059952,-1298.888306,-0.009800,-0.004115,-0.104527,-0.266679,-0.013585,-1.045267,-1298.888306,-0.103243,0.000000
4.310000,-0.087135,-1298.888306,-0.009524,-0.003841,-0.097572,-0.387597,-0.019745,-0.975716,-1298.888306,-0.096236,0.000000
4.730000,-0.076332,-1298.888306,-0.009248,-0.003561,-0.090461,-0.339542,-0.017297,-0.904605,-1298.888306,-0.089246,0.000000
5.150000,-0.035744,-1298.888306,-0.008964,-0.003288,-0.083522,-0.158996,-0.008100,-0.835220,-1298.888306,-0.082240,0.000000
5.570000,-0.029419,-1298.799316,-0.008688,-0.003016,-0.076611,-0.130862,-0.006666,-0.766108,-1298.799316,-0.075250,0.000000
5.990000,-0.001488,-1298.888306,-0.008416,-0.002733,-0.069413,-0.006618,-0.000337,-0.694135,-1298.888306,-0.068260,0.000000
6.410000,-0.078194,-1298.932739,-0.008119,-0.002461,-0.062501,-0.347823,-0.017719,-0.625007,-1298.932739,-0.061252,0.000000
6.830000,-0.115059,-1298.888306,-0.007830,-0.002189,-0.055606,-0.511808,-0.026073,-0.556062,-1298.888306,-0.054262,0.000000
7.250000,-0.110222,-1298.799316,-0.007545,-0.001912,-0.048556,-0.490291,-0.024977,-0.485557,-1298.799316,-0.047255,0.000000
7.670001,0.001122,-1298.843750,-0.007269,-0.001633,-0.041479,0.004989,0.000254,-0.414794,-1298.843750,-0.040265,0.000000
8.090000,-0.004471,-1298.843750,-0.006972,-0.001361,-0.034559,-0.019887,-0.001013,-0.345591,-1298.843750,-0.033259,0.000000
8.510000,-0.034630,-1298.799316,-0.006691,-0.001085,-0.027569,-0.154041,-0.007847,-0.275692,-1298.799316,-0.026269,0.000000
8.930000,-0.074844,-1298.888306,-0.006416,-0.000808,-0.020519,-0.332924,-0.016960,-0.205187,-1298.888306,-0.019279,0.000000
9.350000,-0.122879,-1298.932739,-0.006148,-0.000536,-0.013607,-0.546593,-0.027845,-0.136075,-1298.932739,-0.012271,0.000000
9.770000,-0.023087,-1298.843750,-0.005885,-0.000256,-0.006504,-0.102694,-0.005231,-0.065040,-1298.843750,-0.005281,0.000000
10.190001,0.027931,-1298.888306,-0.005605,0.000019,0.000494,0.124244,0.006329,0.004936,-1298.888306,0.001726,0.000000
10.610001,0.038727,-1298.888306,-0.005312,0.000290,0.007362,0.172265,0.008776,0.073624,-1298.888306,0.008716,0.000000
11.030001,0.005959,-1298.932739,-0.005204,-0.000000,-0.000000,0.026505,0.001350,-0.000000,-1298.932739,0.000235,0.000000
11.450001,0.087135,-1298.888306,-0.005217,-0.000000,-0.000000,0.387597,0.019745,-0.000000,-1298.888306,0.000528,0.000000
11.870001,0.096817,-1298.843750,-0.005221,0.000000,0.000009,0.430664,0.021939,0.000091,-1298.843750,0.001231,0.000000
12.290001,0.191772,-1298.888306,-0.005217,0.000030,0.000754,0.853047,0.043456,0.007540,-1298.888306,0.001926,0.000000
12.710001,0.333649,-1298.888306,-0.005200,0.000062,0.001587,1.484143,0.075606,0.015866,-1298.888306,0.002628,0.000000
13.130001,0.475151,-1298.888306,-0.005165,0.000086,0.002194,2.113577,0.107671,0.021937,-1298.888306,0.003331,0.000000
13.550000,0.650536,-1298.888306,-0.005152,0.000113,0.002870,2.893727,0.147413,0.028705,-1298.888306,0.004033,0.000000
13.970000,1.044876,-1298.888306,-0.005101,0.000145,0.003686,4.647841,0.236772,0.036865,-1298.888306,0.004727,0.000000
14.390000,1.382248,-1298.888306,-0.005083,0.000170,0.004310,6.148546,0.313222,0.043102,-1298.888306,0.005429,0.000000
14.810000,1.970222,-1298.932739,-0.005079,0.000203,0.005169,8.763988,0.446459,0.051687,-1298.932739,0.006132,0.000000
15.230000,2.267006,-1298.888306,-0.005036,0.000225,0.005715,10.084146,0.513711,0.057152,-1298.888306,0.006834,0.000000
15.650001,2.888870,-1298.932739,-0.005023,0.000255,0.006469,12.850337,0.654627,0.064691,-1298.932739,0.007527,0.000000
16.070002,3.589668,-1298.843750,-0.004993,0.000282,0.007172,15.967642,0.813430,0.071716,-1298.843750,0.008230,0.000000
16.490002,4.291222,-1298.932739,-0.004988,0.000311,0.007909,19.088306,0.972405,0.079089,-1298.932739,0.008932,0.000000
16.910002,4.994263,-1298.888306,-0.004958,0.000341,0.008655,22.215590,1.131716,0.086553,-1298.888306,0.009626,0.000000
17.330000,5.424347,-1298.888306,-0.004924,0.000362,0.009184,24.128700,1.229174,0.091837,-1298.888306,0.010328,0.000000
17.750000,6.275223,-1298.977173,-0.004907,0.000392,0.009947,27.913586,1.421986,0.099467,-1298.977173,0.011031,0.000000
18.170000,7.026299,-1298.888306,-0.004894,0.000421,0.010693,31.254538,1.592182,0.106931,-1298.888306,0.011733,0.000000
18.590000,7.635124,-1298.843750,-0.004859,0.000448,0.011370,33.962730,1.730144,0.113698,-1298.843750,0.012428,0.000000
19.010000,8.179909,-1298.888306,-0.004850,0.000477,0.012124,36.386051,1.853594,0.121238,-1298.888306,0.013131,0.000000
19.430000,8.509827,-1298.932739,-0.004833,0.000496,0.012610,37.853600,1.928354,0.126098,-1298.932739,0.013833,0.000000
19.850000,9.407616,-1298.932739,-0.004794,0.000530,0.013450,41.847164,2.131796,0.134500,-1298.932739,0.014526,0.000000
20.270000,9.833984,-1298.888306,-0.004773,0.000557,0.014136,43.743748,2.228413,0.141358,-1298.888306,0.015229,0.000000
20.690001,10.558250,-1298.799316,-0.004738,0.000592,0.015046,46.965443,2.392534,0.150457,-1298.799316,0.015931,0.000000
21.110001,10.599586,-1298.888306,-0.004738,0.000615,0.015627,47.149315,2.401901,0.156271,-1298.888306,0.016634,0.000000
21.530001,11.097076,-1298.888306,-0.004712,0.000642,0.016295,49.362263,2.514633,0.162947,-1298.888306,0.017327,0.000000
21.950001,11.272461,-1298.932739,-0.004669,0.000665,0.016902,50.142410,2.554376,0.169018,-1298.932739,0.018030,0.000000
22.370001,11.704788,-1298.888306,-0.004639,0.000697,0.017700,52.065498,2.652343,0.176997,-1298.888306,0.018732,0.000000
22.790001,11.836975,-1298.888306,-0.004618,0.000720,0.018281,52.653496,2.682297,0.182810,-1298.888306,0.019435,0.000000
23.210001,12.091682,-1298.977173,-0.004605,0.000751,0.019070,53.786491,2.740014,0.190698,-1298.977173,0.020128,0.000000
23.630001,12.506126,-1298.932739,-0.004562,0.000782,0.019860,55.630028,2.833929,0.198601,-1298.932739,0.020831,0.000000
24.050001,12.484901,-1298.932739,-0.004540,0.000804,0.020414,55.535614,2.829119,0.204142,-1298.932739,0.021533,0.000000
24.470001,12.982391,-1298.888306,-0.004510,0.000837,0.021256,57.748562,2.941852,0.212560,-1298.888306,0.022226,0.000000
24.890001,12.780197,-1298.888306,-0.004484,0.000860,0.021854,56.849155,2.896034,0.218540,-1298.888306,0.022929,0.000000
25.310001,13.116447,-1298.932739,-0.004458,0.000891,0.022626,58.344872,2.972229,0.226261,-1298.932739,0.023631,0.000000
25.730001,13.057617,-1299.021729,-0.004441,0.000918,0.023329,58.083183,2.958898,0.233286,-1299.021729,0.024334,0.000000
26.150002,12.948135,-1298.932739,-0.004406,0.000938,0.023831,57.596184,2.934089,0.238312,-1298.932739,0.025029,0.000000
26.570002,13.335777,-1298.932739,-0.004359,0.000978,0.024829,59.320499,3.021930,0.248289,-1298.932739,0.025731,0.000000
26.990002,13.311943,-1298.932739,-0.004363,0.001001,0.025436,59.214481,3.016530,0.254360,-1298.932739,0.026434,0.000000
27.410002,13.405411,-1298.932739,-0.004316,0.001029,0.026148,59.630245,3.037709,0.261476,-1298.932739,0.027136,0.000000
27.830002,13.182732,-1298.977173,-0.004303,0.001049,0.026632,58.639717,2.987250,0.266320,-1298.977173,0.027830,0.000000
28.250002,14.029877,-1298.932739,-0.004260,0.001087,0.027604,62.408009,3.179216,0.276040,-1298.932739,0.028532,0.000000
28.670002,13.598671,-1298.888306,-0.004225,0.001106,0.028081,60.489910,3.081503,0.280809,-1298.888306,0.029235,0.000000
29.090002,13.680962,-1298.888306,-0.004212,0.001133,0.028783,60.855957,3.100150,0.287834,-1298.888306,0.029928,0.000000
29.510002,14.264847,-1298.977173,-0.004178,0.001169,0.029686,63.453209,3.232460,0.296857,-1298.977173,0.030630,0.000000
29.930002,13.902153,-1299.021729,-0.004156,0.001187,0.030144,61.839867,3.150273,0.301444,-1299.021729,0.031333,0.000000
30.350002,14.337830,-1298.932739,-0.004139,0.001221,0.031003,63.777851,3.248999,0.310028,-1298.932739,0.032035,0.000000
30.770002,14.306549,-1298.932739,-0.004083,0.001246,0.031637,63.638710,3.241910,0.316372,-1298.932739,0.032729,0.000000
31.190001,14.321815,-1298.977173,-0.004074,0.001275,0.032382,63.706615,3.245370,0.323820,-1298.977173,0.033431,0.000000
31.610001,14.388100,-1298.932739,-0.004036,0.001301,0.033050,64.001465,3.260390,0.330497,-1298.932739,0.034134,0.000000
32.030003,14.401505,-1299.066162,-0.004010,0.001328,0.033743,64.061089,3.263427,0.337431,-1299.066162,0.034829,0.000000
32.450001,14.448799,-1299.021729,-0.003988,0.001352,0.034334,64.271469,3.274145,0.343335,-1299.021729,0.035530,0.000000
32.870003,14.598488,-1298.977173,-0.003958,0.001379,0.035036,64.937317,3.308065,0.350360,-1298.977173,0.036232,0.000000
33.290001,14.849098,-1298.977173,-0.003941,0.001409,0.035782,66.052086,3.364854,0.357824,-1298.977173,0.036935,0.000000
33.710003,15.198753,-1298.977173,-0.003893,0.001438,0.036520,67.607430,3.444087,0.365197,-1298.977173,0.037629,0.000000
34.130001,15.064705,-1298.977173,-0.003898,0.001461,0.037118,67.011154,3.413711,0.371177,-1298.977173,0.038332,0.000000
34.550003,15.272858,-1299.021729,-0.003867,0.001494,0.037941,67.937065,3.460879,0.379413,-1299.021729,0.039034,0.000000
34.970001,15.210670,-1298.977173,-0.003816,0.001519,0.038583,67.660439,3.446787,0.385832,-1298.977173,0.039737,0.000000
35.390003,15.475060,-1298.932739,-0.003794,0.001548,0.039328,68.836502,3.506699,0.393281,-1298.932739,0.040430,0.000000
35.810001,15.434837,-1299.021729,-0.003773,0.001575,0.040005,68.657585,3.497584,0.400048,-1299.021729,0.041133,0.000000
36.230003,15.945366,-1299.021729,-0.003755,0.001607,0.040828,70.928528,3.613272,0.408284,-1299.021729,0.041835,0.000000
36.650002,15.504105,-1299.021729,-0.003721,0.001628,0.041358,68.965698,3.513280,0.413583,-1299.021729,0.042529,0.000000
37.070004,15.775185,-1298.977173,-0.003704,0.001659,0.042130,70.171524,3.574708,0.421304,-1298.977173,0.043231,0.000000
37.490002,15.814659,-1298.977173,-0.003665,0.001686,0.042815,70.347115,3.583653,0.428147,-1298.977173,0.043934,0.000000
37.910004,16.092079,-1299.066162,-0.003643,0.001715,0.043552,71.581146,3.646517,0.435520,-1299.066162,0.044636,0.000000
38.330002,16.219803,-1299.021729,-0.003609,0.001743,0.044280,72.149284,3.675460,0.442802,-1299.021729,0.045329,0.000000
38.750000,16.010902,-1298.977173,-0.003587,0.001767,0.044878,71.220055,3.628122,0.448783,-1298.977173,0.046032,0.000000
39.170002,16.402634,-1298.932739,-0.003566,0.001797,0.045650,72.962555,3.716890,0.456504,-1298.932739,0.046734,0.000000
39.590000,16.589935,-1298.932739,-0.003548,0.001825,0.046362,73.795715,3.759333,0.463619,-1298.932739,0.047429,0.000000
40.010002,16.867355,-1298.977173,-0.003497,0.001855,0.047116,75.029747,3.822197,0.471159,-1298.977173,0.048132,0.000000
40.430000,16.683777,-1298.932739,-0.003466,0.001881,0.047776,74.213142,3.780598,0.477760,-1298.932739,0.048834,0.000000
40.850002,16.699791,-1298.977173,-0.003454,0.001904,0.048356,74.284378,3.784227,0.483558,-1298.977173,0.049537,0.000000
41.270000,17.140678,-1298.888306,-0.003410,0.001935,0.049154,76.245544,3.884133,0.491537,-1298.888306,0.050230,0.000000
41.690002,17.784508,-1298.932739,-0.003389,0.001970,0.050030,79.109444,4.030027,0.500303,-1298.932739,0.050933,0.000000
42.110001,17.471718,-1298.977173,-0.003380,0.001996,0.050689,77.718086,3.959148,0.506888,-1298.977173,0.051635,0.000000
42.530003,17.414001,-1299.066162,-0.003333,0.002021,0.051340,77.461349,3.946069,0.513398,-1299.066162,0.052338,0.000000
42.950001,17.977028,-1299.066162,-0.003311,0.002054,0.052163,79.965813,4.073653,0.521634,-1299.066162,0.053031,0.000000
43.370003,17.589012,-1298.977173,-0.003290,0.002073,0.052649,78.239830,3.985727,0.526494,-1298.977173,0.053733,0.000000
43.790001,17.930107,-1298.932739,-0.003281,0.002103,0.053412,79.757103,4.063020,0.534124,-1298.932739,0.054436,0.000000
44.210003,18.145714,-1299.021729,-0.003242,0.002131,0.054124,80.716164,4.111877,0.541240,-1299.021729,0.055129,0.000000
44.630001,18.213486,-1299.110596,-0.003203,0.002158,0.054801,81.017632,4.127235,0.548007,-1299.110596,0.055832,0.000000
45.050003,18.752304,-1299.021729,-0.003186,0.002187,0.055555,83.414413,4.249333,0.555547,-1299.021729,0.056534,0.000000
45.470001,18.263756,-1299.021729,-0.003134,0.002209,0.056101,81.241241,4.138626,0.561012,-1299.021729,0.057237,0.000000
45.890003,18.795128,-1299.021729,-0.003130,0.002238,0.056855,83.604904,4.259037,0.568552,-1299.021729,0.057930,0.000000
46.310001,18.743370,-1299.021729,-0.003109,0.002264,0.057506,83.374672,4.247308,0.575062,-1299.021729,0.058633,0.000000
46.730003,19.539131,-1299.110596,-0.003070,0.002298,0.058365,86.914398,4.427630,0.583646,-1299.110596,0.059335,0.000000
47.150002,19.170105,-1299.066162,-0.003044,0.002319,0.058911,85.272888,4.344007,0.589111,-1299.066162,0.060030,0.000000
47.570004,20.179237,-1298.977173,-0.003027,0.002356,0.059830,89.761734,4.572680,0.598301,-1298.977173,0.060732,0.000000
47.990002,20.105133,-1299.021729,-0.002997,0.002381,0.060481,89.432098,4.555888,0.604811,-1299.021729,0.061435,0.000000
48.410004,19.868675,-1299.110596,-0.002945,0.002404,0.061061,88.380280,4.502306,0.610610,-1299.110596,0.062137,0.000000
48.830002,20.521820,-1299.066162,-0.002932,0.002437,0.061912,91.285614,4.650311,0.619118,-1299.066162,0.062831,0.000000
49.250004,20.417931,-1299.021729,-0.002915,0.002459,0.062466,90.823494,4.626769,0.624659,-1299.021729,0.063533,0.000000
49.670002,20.782104,-1299.110596,-0.002897,0.002489,0.063221,92.443420,4.709292,0.632214,-1299.110596,0.064236,0.000000
50.090004,20.664062,-1299.066162,-0.002871,0.002513,0.063836,91.918343,4.682544,0.638360,-1299.066162,0.064938,0.000000
50.510002,20.921379,-1299.110596,-0.002841,0.002538,0.064469,93.062943,4.740852,0.644689,-1299.110596,0.065632,0.000000
50.930004,21.508606,-1299.110596,-0.002815,0.002571,0.065302,95.675056,4.873919,0.653015,-1299.110596,0.066334,0.000000
51.350002,21.008881,-1299.066162,-0.002807,0.002588,0.065727,93.452171,4.760681,0.657270,-1299.066162,0.067037,0.000000
51.770004,22.225052,-1299.066162,-0.002772,0.002626,0.066690,98.861969,5.036269,0.666898,-1299.066162,0.067730,0.000000
52.190002,22.561302,-1299.110596,-0.002738,0.002654,0.067418,100.357681,5.112464,0.674181,-1299.110596,0.068432,0.000000
52.610001,23.010384,-1299.110596,-0.002725,0.002683,0.068155,102.355301,5.214228,0.681554,-1299.110596,0.069135,0.000000
53.030003,23.262856,-1299.066162,-0.002703,0.002711,0.068858,103.478348,5.271438,0.688578,-1299.066162,0.069837,0.000000
53.450001,23.000702,-1299.021729,-0.002677,0.002730,0.069344,102.312233,5.212034,0.693438,-1299.021729,0.070532,0.000000
53.870003,23.871681,-1299.110596,-0.002656,0.002764,0.070211,106.186539,5.409400,0.702113,-1299.110596,0.071233,0.000000
54.290001,23.505638,-1299.021729,-0.002634,0.002784,0.070705,104.558304,5.326454,0.707049,-1299.021729,0.071936,0.000000
54.710003,24.213524,-1299.110596,-0.002608,0.002812,0.071416,107.707130,5.486863,0.714164,-1299.110596,0.072631,0.000000
55.130001,25.041306,-1299.110596,-0.002587,0.002841,0.072170,111.389290,5.674441,0.721704,-1299.110596,0.073333,0.000000
55.550003,25.517570,-1299.066162,-0.002565,0.002871,0.072924,113.507820,5.782364,0.729243,-1299.066162,0.074036,0.000000
55.970001,25.815094,-1299.021729,-0.002548,0.002895,0.073541,114.831276,5.849784,0.735405,-1299.021729,0.074738,0.000000
56.390003,26.281303,-1299.021729,-0.002514,0.002924,0.074261,116.905075,5.955429,0.742612,-1299.021729,0.075431,0.000000
56.810001,26.904282,-1299.110596,-0.002492,0.002951,0.074964,119.676224,6.096598,0.749636,-1299.110596,0.076134,0.000000
57.230003,27.163086,-1299.110596,-0.002453,0.002978,0.075631,120.827438,6.155243,0.756313,-1299.110596,0.076836,0.000000
57.650002,28.342010,-1299.021729,-0.002436,0.003012,0.076499,126.071556,6.422391,0.764988,-1299.021729,0.077539,0.000000
58.070004,28.169235,-1299.021729,-0.002427,0.003034,0.077071,125.303017,6.383240,0.770711,-1299.021729,0.078232,0.000000
58.490002,29.150063,-1299.066162,-0.002402,0.003066,0.077869,129.665955,6.605499,0.778689,-1299.066162,0.078935,0.000000
58.910004,29.659470,-1299.199585,-0.002363,0.003093,0.078571,131.931915,6.720932,0.785714,-1299.199585,0.079637,0.000000
59.330002,30.151375,-1299.066162,-0.002345,0.003117,0.079169,134.120010,6.832399,0.791694,-1299.066162,0.080331,0.000000
59.750004,31.073738,-1299.021729,-0.002341,0.003149,0.079984,138.222885,7.041409,0.799839,-1299.021729,0.081033,0.000000
60.170002,31.445740,-1299.066162,-0.002307,0.003174,0.080609,139.877640,7.125706,0.806092,-1299.066162,0.081736,0.000000
60.590004,32.537910,-1299.066162,-0.002289,0.003202,0.081328,144.735855,7.373196,0.813283,-1299.066162,0.082438,0.000000
61.010002,32.991455,-1299.066162,-0.002259,0.003226,0.081944,146.753326,7.475971,0.819445,-1299.066162,0.083133,0.000000
61.430004,34.188637,-1299.066162,-0.002238,0.003258,0.082742,152.078659,7.747256,0.827423,-1299.066162,0.083835,0.000000
61.850002,34.638458,-1299.110596,-0.002233,0.003282,0.083375,154.079559,7.849187,0.833752,-1299.110596,0.084538,0.000000
62.270004,35.154938,-1299.110596,-0.002182,0.003307,0.083999,156.376968,7.966223,0.839989,-1299.110596,0.085231,0.000000
62.690002,36.260513,-1299.066162,-0.002182,0.003334,0.084676,161.294815,8.216749,0.846757,-1299.066162,0.085934,0.000000
63.110004,38.531990,-1299.110596,-0.002147,0.003376,0.085752,171.398849,8.731474,0.857521,-1299.110596,0.086636,0.000000
63.530003,38.768440,-1299.110596,-0.002117,0.003398,0.086315,172.450638,8.785054,0.863153,-1299.110596,0.087339,0.000000
63.950005,39.288277,-1299.110596,-0.002113,0.003420,0.086878,174.762985,8.902850,0.868785,-1299.110596,0.088032,0.000000
64.370003,41.069336,-1299.066162,-0.002078,0.003456,0.087781,182.685532,9.306445,0.877808,-1299.066162,0.088735,0.000000
64.790001,41.216423,-1299.155151,-0.002070,0.003474,0.088240,183.339813,9.339775,0.882395,-1299.155151,0.089437,0.000000
65.210007,43.197067,-1299.155151,-0.002044,0.003511,0.089177,192.150146,9.788596,0.891767,-1299.155151,0.090140,0.000000
65.630005,43.881119,-1299.155151,-0.002022,0.003536,0.089819,195.192963,9.943604,0.898186,-1299.155151,0.090833,0.000000
66.050003,45.159096,-1299.066162,-0.002005,0.003565,0.090556,200.877686,10.233197,0.905559,-1299.066162,0.091535,0.000000
66.470001,46.068802,-1299.110596,-0.001988,0.003587,0.091119,204.924271,10.439340,0.911191,-1299.110596,0.092238,0.000000
66.889999,46.605766,-1299.155151,-0.001975,0.003610,0.091691,207.312805,10.561018,0.916914,-1299.155151,0.092931,0.000000
67.310005,48.841118,-1299.155151,-0.001949,0.003647,0.092645,217.256149,11.067555,0.926451,-1299.155151,0.093634,0.000000
67.730003,49.438400,-1299.066162,-0.001932,0.003669,0.093201,219.912994,11.202902,0.932008,-1299.066162,0.094336,0.000000
68.150002,51.177010,-1299.066162,-0.001897,0.003699,0.093964,227.646713,11.596876,0.939638,-1299.066162,0.095039,0.000000
68.570000,51.907234,-1299.110596,-0.001906,0.003726,0.094631,230.894913,11.762347,0.946315,-1299.110596,0.095734,0.000000
68.990005,54.026779,-1299.155151,-0.001884,0.003755,0.095387,240.323120,12.242643,0.953869,-1299.155151,0.096436,0.000000
69.410004,55.381470,-1299.110596,-0.001867,0.003783,0.096097,246.349075,12.549621,0.960970,-1299.110596,0.097139,0.000000
69.830002,56.518318,-1299.155151,-0.001850,0.003812,0.096825,251.406036,12.807234,0.968252,-1299.155151,0.097832,0.000000
70.250000,58.505676,-1299.155151,-0.001824,0.003840,0.097537,260.246246,13.257576,0.975367,-1299.155151,0.098534,0.000000
70.670006,59.339417,-1299.066162,-0.001815,0.003859,0.098023,263.954895,13.446505,0.980227,-1299.066162,0.099237,0.000000
71.090004,61.244843,-1299.155151,-0.001794,0.003890,0.098802,272.430664,13.878280,0.988024,-1299.155151,0.099939,0.000000
71.510002,62.281532,-1299.110596,-0.001789,0.003914,0.099410,277.042084,14.113197,0.994095,-1299.110596,0.100633,0.000000
71.930000,64.774567,-1299.110596,-0.001772,0.003951,0.100356,288.131653,14.678127,1.003557,-1299.110596,0.101335,0.000000
72.350006,65.896515,-1299.155151,-0.001755,0.003970,0.100849,293.122345,14.932364,1.008493,-1299.155151,0.102038,0.000000
72.770004,65.350998,-1299.155151,-0.001733,0.003970,0.100833,290.695770,14.808748,1.008326,-1299.155151,0.017707,0.000000
73.190002,65.396057,-1299.155151,-0.001725,0.003987,0.101275,290.896179,14.818958,1.012747,-1299.155151,294.500458,0.000000
73.610001,66.032059,-1299.199585,-0.001716,0.004001,0.101630,293.725281,14.963078,1.016305,-1299.199585,294.500458,0.000000
74.030006,64.829300,-1299.110596,-0.001690,0.004002,0.101640,288.375122,14.690529,1.016396,-1299.110596,294.500458,0.000000
74.450005,65.136505,-1299.021729,-0.001699,0.004015,0.101986,289.741638,14.760143,1.019863,-1299.021729,294.500458,0.000000
74.870003,65.366257,-1299.199585,-0.001686,0.004029,0.102333,290.763641,14.812205,1.023330,-1299.199585,294.500458,0.000000
75.290001,65.177475,-1299.155151,-0.001673,0.004037,0.102533,289.923889,14.769426,1.025328,-1299.155151,294.500458,0.000000
75.710007,64.916809,-1299.155151,-0.001677,0.004043,0.102696,288.764374,14.710359,1.026963,-1299.155151,294.500458,0.000000
76.130005,64.936172,-1299.066162,-0.001664,0.004050,0.102880,288.850525,14.714746,1.028795,-1299.066162,294.500458,0.000000
76.550003,64.900803,-1299.110596,-0.001673,0.004058,0.103070,288.693176,14.706732,1.030703,-1299.110596,294.500458,0.000000
76.970001,65.008041,-1299.199585,-0.001651,0.004066,0.103269,289.170197,14.731032,1.032686,-1299.199585,294.500458,0.000000
77.390007,65.262375,-1299.199585,-0.001643,0.004076,0.103521,290.301544,14.788666,1.035214,-1299.199585,294.500458,0.000000
77.810005,65.323807,-1299.110596,-0.001638,0.004084,0.103738,290.574799,14.802586,1.037379,-1299.110596,294.500458,0.000000
78.230003,65.139862,-1299.110596,-0.001621,0.004088,0.103842,289.756592,14.760904,1.038424,-1299.110596,294.500458,0.000000
78.650002,65.226990,-1299.066162,-0.001638,0.004095,0.104024,290.144135,14.780647,1.040241,-1299.066162,294.500458,0.000000
79.070007,64.942123,-1299.199585,-0.001634,0.004099,0.104119,288.876984,14.716096,1.041194,-1299.199585,294.500458,0.000000
79.490005,65.210617,-1299.199585,-0.001625,0.004106,0.104292,290.071320,14.776937,1.042920,-1299.199585,294.500458,0.000000
79.910004,65.085861,-1299.155151,-0.001613,0.004111,0.104422,289.516357,14.748668,1.044222,-1299.155151,294.500458,0.000000
80.330002,64.874359,-1299.110596,-0.001600,0.004114,0.104492,288.575562,14.700740,1.044919,-1299.110596,294.500458,0.000000
80.750008,65.143585,-1299.155151,-0.001608,0.004122,0.104692,289.773132,14.761747,1.046917,-1299.155151,294.500458,0.000000
81.170006,65.020325,-1299.244141,-0.001595,0.004126,0.104804,289.224854,14.733816,1.048037,-1299.244141,294.500458,0.000000
81.590004,64.808075,-1299.155151,-0.001595,0.004132,0.104943,288.280701,14.685719,1.049430,-1299.155151,294.500458,0.000000
82.010002,65.537933,-1299.155151,-0.001582,0.004140,0.105150,291.527283,14.851108,1.051504,-1299.155151,294.500458,0.000000
82.430000,65.128693,-1299.155151,-0.001587,0.004140,0.105169,289.706879,14.758373,1.051686,-1299.155151,294.500458,0.000000
82.850006,65.007675,-1299.199585,-0.001582,0.004145,0.105281,289.168579,14.730949,1.052806,-1299.199585,294.500458,0.000000
83.270004,65.081024,-1299.244141,-0.001578,0.004150,0.105403,289.494843,14.747571,1.054033,-1299.244141,294.500458,0.000000
83.690002,65.431427,-1299.199585,-0.001565,0.004159,0.105646,291.053528,14.826973,1.056455,-1299.199585,294.500458,0.000000
84.110001,65.260880,-1299.110596,-0.001561,0.004159,0.105646,290.294891,14.788326,1.056455,-1299.110596,294.500458,0.000000
84.530006,65.408340,-1299.199585,-0.001556,0.004167,0.105845,290.950836,14.821742,1.058453,-1299.199585,294.500458,0.000000
84.950005,65.272797,-1299.155151,-0.001556,0.004167,0.105845,290.347900,14.791027,1.058453,-1299.155151,294.500458,0.000000
85.370003,65.048630,-1299.244141,-0.001556,0.004170,0.105906,289.350769,14.740230,1.059059,-1299.244141,294.500458,0.000000
85.790001,65.111938,-1299.244141,-0.001544,0.004176,0.106062,289.632355,14.754577,1.060618,-1299.244141,294.500458,0.000000
86.210007,64.985703,-1299.199585,-0.001561,0.004176,0.106062,289.070831,14.725970,1.060618,-1299.199585,294.500458,0.000000
86.630005,64.964844,-1299.199585,-0.001556,0.004180,0.106166,288.978058,14.721244,1.061663,-1299.199585,294.500458,0.000000
87.050003,64.918304,-1299.199585,-0.001556,0.004184,0.106262,288.771027,14.710697,1.062617,-1299.199585,294.500458,0.000000
87.470001,64.747009,-1299.244141,-0.001544,0.004184,0.106262,288.009094,14.671882,1.062617,-1299.244141,294.500458,0.000000
87.890007,65.278381,-1299.288574,-0.001526,0.004192,0.106478,290.372742,14.792293,1.064782,-1299.288574,294.500458,0.000000
88.310005,65.046021,-1299.155151,-0.001526,0.004193,0.106495,289.339142,14.739638,1.064948,-1299.155151,294.500458,0.000000
88.730003,64.946976,-1299.288574,-0.001531,0.004195,0.106564,288.898590,14.717196,1.065645,-1299.288574,294.500458,0.000000
89.150002,64.978622,-1299.244141,-0.001535,0.004199,0.106651,289.039337,14.724366,1.066508,-1299.244141,294.500458,0.000000
89.570007,64.939529,-1299.333008,-0.001548,0.004201,0.106704,288.865448,14.715508,1.067038,-1299.333008,294.500458,0.000000
89.990005,65.108582,-1299.244141,-0.001526,0.004206,0.106834,289.617432,14.753816,1.068340,-1299.244141,294.500458,0.000000
90.410004,64.934311,-1299.199585,-0.001518,0.004206,0.106842,288.842255,14.714326,1.068415,-1299.199585,294.500458,0.000000
90.830002,64.909363,-1299.199585,-0.001518,0.004209,0.106904,288.731262,14.708673,1.069036,-1299.199585,294.500458,0.000000
91.250008,65.344666,-1299.288574,-0.001518,0.004216,0.107094,290.667603,14.807313,1.070944,-1299.288574,294.500458,0.000000
91.670006,65.186401,-1299.288574,-0.001513,0.004216,0.107094,289.963593,14.771450,1.070944,-1299.288574,294.500458,0.000000
92.090004,65.054962,-1299.244141,-0.001505,0.004219,0.107155,289.378937,14.741665,1.071549,-1299.244141,294.500458,0.000000
92.510002,64.987183,-1299.199585,-0.001513,0.004220,0.107181,289.077423,14.726306,1.071807,-1299.199585,294.500458,0.000000
92.930008,65.007294,-1299.199585,-0.001509,0.004222,0.107250,289.166870,14.730864,1.072503,-1299.199585,294.500458,0.000000
93.350006,64.920532,-1299.244141,-0.001518,0.004224,0.107302,288.780945,14.711203,1.073018,-1299.244141,294.500458,0.000000
93.770004,65.395309,-1299.333008,-0.001509,0.004232,0.107502,290.892853,14.818789,1.075016,-1299.333008,294.500458,0.000000
94.190002,65.326797,-1299.244141,-0.001496,0.004232,0.107502,290.588104,14.803264,1.075016,-1299.244141,294.500458,0.000000
94.610008,65.145081,-1299.199585,-0.001505,0.004232,0.107502,289.779785,14.762086,1.075016,-1299.199585,294.500458,0.000000
95.030006,65.056824,-1299.199585,-0.001487,0.004234,0.107544,289.387207,14.742087,1.075440,-1299.199585,294.500458,0.000000
95.450005,65.114914,-1299.288574,-0.001496,0.004238,0.107639,289.645599,14.755250,1.076394,-1299.288574,294.500458,0.000000
95.870003,65.024048,-1299.288574,-0.001487,0.004238,0.107648,289.241425,14.734660,1.076485,-1299.288574,294.500458,0.000000
96.290001,64.944366,-1299.244141,-0.001487,0.004240,0.107692,288.886963,14.716604,1.076924,-1299.244141,294.500458,0.000000
96.710007,64.980850,-1299.244141,-0.001483,0.004243,0.107779,289.049255,14.724871,1.077787,-1299.244141,294.500458,0.000000
97.130005,64.897079,-1299.244141,-0.001487,0.004244,0.107788,288.676636,14.705889,1.077878,-1299.244141,294.500458,0.000000
97.550003,65.006546,-1299.244141,-0.001487,0.004247,0.107865,289.163544,14.730694,1.078650,-1299.244141,294.500458,0.000000
97.970001,64.955536,-1299.288574,-0.001470,0.004249,0.107918,288.936646,14.719135,1.079180,-1299.288574,294.500458,0.000000
98.390007,65.546112,-1299.288574,-0.001470,0.004258,0.108144,291.563660,14.852961,1.081435,-1299.288574,294.500458,0.000000
98.810005,65.552826,-1299.244141,-0.001479,0.004257,0.108134,291.593536,14.854483,1.081344,-1299.244141,294.500458,0.000000
99.230003,65.383759,-1299.244141,-0.001479,0.004257,0.108134,290.841492,14.816172,1.081344,-1299.244141,294.500458,0.000000
99.650002,65.235565,-1299.288574,-0.001470,0.004257,0.108134,290.182281,14.782591,1.081344,-1299.288574,294.500458,0.000000
100.070007,65.063522,-1299.244141,-0.001466,0.004258,0.108144,289.416992,14.743606,1.081435,-1299.244141,294.500458,0.000000
100.490005,64.915314,-1299.244141,-0.001466,0.004258,0.108160,288.757751,14.710021,1.081602,-1299.244141,294.500458,0.000000
100.910004,64.766739,-1299.199585,-0.001475,0.004261,0.108230,288.096832,14.676353,1.082298,-1299.199585,294.500458,0.000000
101.330002,65.502548,-1299.244141,-0.001483,0.004268,0.108411,291.369873,14.843089,1.084115,-1299.244141,294.500458,0.000000
101.750008,65.379669,-1299.288574,-0.001466,0.004268,0.108411,290.823303,14.815245,1.084115,-1299.288574,294.500458,0.000000
102.170006,65.254181,-1299.244141,-0.001466,0.004268,0.108411,290.265106,14.786808,1.084115,-1299.244141,294.500458,0.000000
102.590004,65.077667,-1299.244141,-0.001462,0.004268,0.108411,289.479919,14.746810,1.084115,-1299.244141,294.500458,0.000000
103.010002,64.955902,-1299.199585,-0.001470,0.004269,0.108430,288.938293,14.719218,1.084297,-1299.199585,294.500458,0.000000
103.430008,64.922760,-1299.244141,-0.001470,0.004271,0.108490,288.790863,14.711707,1.084902,-1299.244141,294.500458,0.000000
103.850006,65.371475,-1299.244141,-0.001444,0.004278,0.108655,290.786835,14.813388,1.086553,-1299.244141,294.500458,0.000000
104.270004,65.313385,-1299.199585,-0.001453,0.004278,0.108655,290.528442,14.800224,1.086553,-1299.199585,294.500458,0.000000
104.690002,65.193115,-1299.199585,-0.001466,0.004278,0.108655,289.993469,14.772971,1.086553,-1299.199585,294.500458,0.000000
105.110008,65.055328,-1299.155151,-0.001466,0.004278,0.108663,289.380554,14.741748,1.086628,-1299.155151,294.500458,0.000000
105.530006,65.066879,-1299.244141,-0.001449,0.004280,0.108716,289.431946,14.744366,1.087158,-1299.244141,294.500458,0.000000
105.950005,64.967087,-1299.244141,-0.001449,0.004280,0.108716,288.988037,14.721752,1.087158,-1299.244141,294.500458,0.000000
106.370003,65.066498,-1299.199585,-0.001444,0.004285,0.108837,289.430237,14.744279,1.088369,-1299.199585,294.500458,0.000000
106.790009,65.084747,-1299.199585,-0.001444,0.004285,0.108837,289.511414,14.748415,1.088369,-1299.199585,294.500458,0.000000
107.210007,64.979370,-1299.199585,-0.001440,0.004285,0.108837,289.042664,14.724536,1.088369,-1299.199585,294.500458,0.000000
107.630005,65.371109,-1299.244141,-0.001444,0.004292,0.109019,290.785217,14.813306,1.090186,-1299.244141,294.500458,0.000000
108.050003,65.361420,-1299.244141,-0.001440,0.004292,0.109019,290.742126,14.811110,1.090186,-1299.244141,294.500458,0.000000
108.470009,65.274292,-1299.244141,-0.001444,0.004292,0.109019,290.354553,14.791366,1.090186,-1299.244141,294.500458,0.000000
108.890007,65.167038,-1299.199585,-0.001444,0.004292,0.109019,289.877472,14.767062,1.090186,-1299.199585,294.500458,0.000000
109.310005,65.048996,-1299.199585,-0.001440,0.004293,0.109037,289.352386,14.740314,1.090368,-1299.199585,294.500458,0.000000
109.730003,64.963364,-1299.333008,-0.001444,0.004294,0.109063,288.971466,14.720909,1.090625,-1299.333008,294.500458,0.000000
110.150002,64.911224,-1299.244141,-0.001440,0.004296,0.109123,288.739532,14.709093,1.091231,-1299.244141,294.500458,0.000000
110.570007,65.100388,-1299.244141,-0.001423,0.004298,0.109167,289.580994,14.751959,1.091670,-1299.244141,294.500458,0.000000
110.990005,65.027405,-1299.244141,-0.001444,0.004298,0.109167,289.256348,14.735421,1.091670,-1299.244141,294.500458,0.000000
111.410004,64.941757,-1299.288574,-0.001431,0.004299,0.109202,288.875366,14.716012,1.092018,-1299.288574,294.500458,0.000000
111.830002,64.972672,-1299.333008,-0.001427,0.004301,0.109235,289.012878,14.723018,1.092351,-1299.333008,294.500458,0.000000
112.250008,64.887390,-1299.288574,-0.001440,0.004301,0.109235,288.633514,14.703692,1.092351,-1299.288574,294.500458,0.000000
112.670006,65.206146,-1299.288574,-0.001431,0.004306,0.109374,290.051422,14.775925,1.093744,-1299.288574,294.500458,0.000000
113.090004,65.187897,-1299.199585,-0.001436,0.004306,0.109374,289.970245,14.771788,1.093744,-1299.199585,294.500458,0.000000
113.510002,65.096664,-1299.288574,-0.001431,0.004306,0.109374,289.564423,14.751115,1.093744,-1299.288574,294.500458,0.000000
113.930008,64.999100,-1299.377563,-0.001427,0.004306,0.109374,289.130432,14.729006,1.093744,-1299.377563,294.500458,0.000000
114.350006,64.895584,-1299.333008,-0.001423,0.004306,0.109374,288.669983,14.705549,1.093744,-1299.333008,294.500458,0.000000
114.770004,65.041183,-1299.244141,-0.001431,0.004310,0.109470,289.317627,14.738543,1.094698,-1299.244141,294.500458,0.000000
115.190002,65.022568,-1299.288574,-0.001436,0.004311,0.109488,289.234833,14.734324,1.094879,-1299.288574,294.500458,0.000000
115.610008,64.949203,-1299.244141,-0.001423,0.004311,0.109488,288.908478,14.717700,1.094879,-1299.244141,294.500458,0.000000
116.030006,64.832657,-1299.377563,-0.001423,0.004311,0.109488,288.390076,14.691290,1.094879,-1299.377563,294.500458,0.000000
116.450005,65.273163,-1299.288574,-0.001418,0.004317,0.109661,290.349518,14.791110,1.096605,-1299.288574,294.500458,0.000000
116.870003,65.273544,-1299.288574,-0.001423,0.004317,0.109661,290.351227,14.791197,1.096605,-1299.288574,294.500458,0.000000
117.290009,65.206894,-1299.244141,-0.001414,0.004317,0.109661,290.054749,14.776093,1.096605,-1299.244141,294.500458,0.000000
117.710007,65.110443,-1299.333008,-0.001423,0.004317,0.109661,289.625702,14.754238,1.096605,-1299.333008,294.500458,0.000000
118.130005,65.076187,-1299.333008,-0.001410,0.004318,0.109686,289.473328,14.746475,1.096863,-1299.333008,294.500458,0.000000
118.550003,65.011398,-1299.288574,-0.001423,0.004319,0.109695,289.185150,14.731793,1.096953,-1299.288574,294.500458,0.000000
118.970009,64.997620,-1299.244141,-0.001418,0.004320,0.109739,289.123840,14.728671,1.097392,-1299.244141,294.500458,0.000000
119.390007,64.996124,-1299.333008,-0.001418,0.004321,0.109747,289.117187,14.728333,1.097468,-1299.333008,294.500458,0.000000
119.810005,64.911972,-1299.333008,-0.001431,0.004321,0.109756,288.742859,14.709263,1.097559,-1299.333008,294.500458,0.000000
120.230003,64.965225,-1299.377563,-0.001414,0.004323,0.109809,288.979767,14.721331,1.098089,-1299.377563,294.500458,0.000000
120.650009,64.916443,-1299.377563,-0.001406,0.004323,0.109809,288.762756,14.710277,1.098089,-1299.377563,294.500458,0.000000
121.070007,64.834518,-1299.333008,-0.001418,0.004323,0.109809,288.398346,14.691712,1.098089,-1299.333008,294.500458,0.000000
121.490005,65.175980,-1299.333008,-0.001406,0.004329,0.109956,289.917236,14.769088,1.099557,-1299.333008,294.500458,0.000000
121.910004,65.184921,-1299.333008,-0.001418,0.004329,0.109956,289.957001,14.771114,1.099557,-1299.333008,294.500458,0.000000
122.330009,65.117889,-1299.377563,-0.001418,0.004329,0.109956,289.658844,14.755924,1.099557,-1299.377563,294.500458,0.000000
122.750008,65.046402,-1299.377563,-0.001406,0.004329,0.109956,289.340851,14.739726,1.099557,-1299.377563,294.500458,0.000000
123.170006,64.999100,-1299.333008,-0.001423,0.004329,0.109956,289.130432,14.729006,1.099557,-1299.333008,294.500458,0.000000
123.590004,64.902664,-1299.333008,-0.001414,0.004329,0.109956,288.701477,14.707154,1.099557,-1299.333008,294.500458,0.000000
124.010002,64.970810,-1299.333008,-0.001406,0.004336,0.110137,289.004608,14.722596,1.101374,-1299.333008,294.500458,0.000000
124.430008,65.309662,-1299.421997,-0.001393,0.004336,0.110137,290.511871,14.799381,1.101374,-1299.421997,294.500458,0.000000
124.850006,65.279877,-1299.333008,-0.001410,0.004336,0.110137,290.379395,14.792631,1.101374,-1299.333008,294.500458,0.000000
125.270004,65.231842,-1299.333008,-0.001401,0.004336,0.110137,290.165710,14.781747,1.101374,-1299.333008,294.500458,0.000000
125.690002,65.156982,-1299.288574,-0.001423,0.004336,0.110137,289.832733,14.764783,1.101374,-1299.288574,294.500458,0.000000
126.110008,65.061661,-1299.333008,-0.001397,0.004336,0.110137,289.408722,14.743183,1.101374,-1299.333008,294.500458,0.000000
126.530006,64.995377,-1299.377563,-0.001410,0.004336,0.110137,289.113861,14.728163,1.101374,-1299.377563,294.500458,0.000000
126.950005,64.949203,-1299.377563,-0.001401,0.004336,0.110147,288.908478,14.717700,1.101465,-1299.377563,294.500458,0.000000
127.370003,64.933945,-1299.288574,-0.001401,0.004338,0.110190,288.840607,14.714242,1.101904,-1299.288574,294.500458,0.000000
127.790009,64.958511,-1299.421997,-0.001393,0.004339,0.110216,288.949890,14.719809,1.102161,-1299.421997,294.500458,0.000000
128.210007,64.928360,-1299.421997,-0.001397,0.004340,0.110224,288.815765,14.712976,1.102237,-1299.421997,294.500458,0.000000
128.630005,64.887024,-1299.421997,-0.001388,0.004340,0.110224,288.631897,14.703610,1.102237,-1299.421997,294.500458,0.000000
129.050003,64.913834,-1299.466553,-0.001384,0.004341,0.110268,288.751160,14.709685,1.102676,-1299.466553,294.500458,0.000000
129.470001,64.848663,-1299.421997,-0.001393,0.004341,0.110268,288.461273,14.694917,1.102676,-1299.421997,294.500458,0.000000
129.889999,65.230347,-1299.377563,-0.001388,0.004346,0.110398,290.159088,14.781407,1.103978,-1299.377563,294.500458,0.000000
130.310013,65.210983,-1299.421997,-0.001406,0.004346,0.110398,290.072937,14.777020,1.103978,-1299.421997,294.500458,0.000000
130.730011,65.161087,-1299.421997,-0.001401,0.004346,0.110398,289.850983,14.765714,1.103978,-1299.421997,294.500458,0.000000
131.150009,65.130554,-1299.466553,-0.001388,0.004347,0.110424,289.715179,14.758794,1.104236,-1299.466553,294.500458,0.000000
131.570007,65.083267,-1299.421997,-0.001401,0.004347,0.110424,289.504822,14.748078,1.104236,-1299.421997,294.500458,0.000000
131.990005,65.045654,-1299.421997,-0.001401,0.004348,0.110433,289.337524,14.739556,1.104326,-1299.421997,294.500458,0.000000
132.410004,65.031876,-1299.377563,-0.001388,0.004349,0.110458,289.276245,14.736434,1.104584,-1299.377563,294.500458,0.000000
132.830002,64.993515,-1299.421997,-0.001388,0.004349,0.110458,289.105591,14.727740,1.104584,-1299.421997,294.500458,0.000000
133.250000,64.912338,-1299.377563,-0.001397,0.004339,0.110216,288.744507,14.709346,1.102161,-1299.377563,0.110424,0.000000
133.670013,64.783127,-1299.377563,-0.001388,0.004330,0.109981,288.169739,14.680066,1.099815,-1299.377563,0.109721,0.000000
134.090012,64.680359,-1299.421997,-0.001388,0.004306,0.109383,287.712616,14.656779,1.093835,-1299.421997,0.109028,0.000000
134.510010,64.517258,-1299.466553,-0.001375,0.004284,0.108811,286.987091,14.619820,1.088112,-1299.466553,0.108325,0.000000
134.930008,64.460281,-1299.421997,-0.001362,0.004254,0.108048,286.733643,14.606909,1.080482,-1299.421997,0.107623,0.000000
135.350006,64.373520,-1299.421997,-0.001354,0.004227,0.107353,286.347717,14.587249,1.073532,-1299.421997,0.106920,0.000000
135.770004,64.239471,-1299.333008,-0.001367,0.004201,0.106695,285.751434,14.556872,1.066947,-1299.333008,0.106227,0.000000
136.190002,64.134460,-1299.333008,-0.001358,0.004176,0.106062,285.284332,14.533076,1.060618,-1299.333008,0.105524,0.000000
136.610001,64.000397,-1299.510986,-0.001362,0.004148,0.105359,284.687988,14.502697,1.053594,-1299.510986,0.104822,0.000000
137.030014,63.892044,-1299.421997,-0.001354,0.004121,0.104674,284.205994,14.478144,1.046735,-1299.421997,0.104129,0.000000
137.450012,63.753143,-1299.377563,-0.001362,0.004096,0.104050,283.588135,14.446669,1.040498,-1299.377563,0.103426,0.000000
137.870010,63.241135,-1299.333008,-0.001362,0.004079,0.103599,281.310608,14.330647,1.035986,-1299.333008,0.102724,0.000000
138.290009,62.207802,-1299.377563,-0.001358,0.004051,0.102905,276.714111,14.096490,1.029052,-1299.377563,0.102021,0.000000
138.710007,60.597290,-1299.510986,-0.001354,0.004021,0.102124,269.550201,13.731542,1.021240,-1299.510986,0.101326,0.000000
139.130005,58.689995,-1299.377563,-0.001328,0.003993,0.101414,261.066132,13.299343,1.014140,-1299.377563,0.100624,0.000000
139.550003,56.459488,-1299.421997,-0.001302,0.003966,0.100728,251.144348,12.793902,1.007282,-1299.421997,0.099921,0.000000
139.970001,54.907066,-1299.377563,-0.001328,0.003950,0.100321,244.238831,12.442120,1.003209,-1299.377563,0.099219,0.000000
140.389999,52.003304,-1299.421997,-0.001324,0.003918,0.099523,231.322250,11.784117,0.995231,-1299.421997,0.098525,0.000000
140.810013,49.433937,-1299.466553,-0.001306,0.003894,0.098916,219.893127,11.201890,0.989160,-1299.466553,0.097823,0.000000
141.230011,46.191689,-1299.421997,-0.001306,0.003865,0.098170,205.470886,10.467186,0.981696,-1299.421997,0.097120,0.000000
141.650009,43.765678,-1299.421997,-0.001324,0.003844,0.097641,194.679459,9.917445,0.976412,-1299.421997,0.096427,0.000000
142.070007,40.443001,-1299.421997,-0.001306,0.003814,0.096887,179.899460,9.164515,0.968873,-1299.421997,0.095725,0.000000
142.490005,37.167610,-1299.421997,-0.001324,0.003779,0.095976,165.329788,8.422301,0.959759,-1299.421997,0.095022,0.000000
142.910004,34.095917,-1299.466553,-0.001315,0.003756,0.095404,151.666214,7.726245,0.954036,-1299.466553,0.094320,0.000000
143.330002,30.703972,-1299.510986,-0.001315,0.003724,0.094597,136.578094,6.957620,0.945966,-1299.510986,0.093626,0.000000
143.750000,28.465271,-1299.421997,-0.001306,0.003707,0.094155,126.619850,6.450323,0.941546,-1299.421997,0.092924,0.000000
144.170013,25.058434,-1299.421997,-0.001319,0.003675,0.093348,111.465477,5.678322,0.933476,-1299.421997,0.092221,0.000000
144.590012,22.149834,-1299.421997,-0.001328,0.003650,0.092707,98.527382,5.019224,0.927072,-1299.421997,0.091526,0.000000
145.010010,18.940727,-1299.466553,-0.001311,0.003619,0.091935,84.252563,4.292030,0.919351,-1299.466553,0.090825,0.000000
145.430008,15.783752,-1299.466553,-0.001302,0.003591,0.091214,70.209641,3.576649,0.912145,-1299.466553,0.090123,0.000000
145.850006,13.345833,-1299.510986,-0.001302,0.003570,0.090677,59.365231,3.024209,0.906770,-1299.510986,0.089420,0.000000
146.270004,10.792473,-1299.466553,-0.001332,0.003548,0.090114,48.007317,2.445609,0.901138,-1299.466553,0.088726,0.000000
146.690002,6.776062,-1299.466553,-0.001311,0.003507,0.089081,30.141430,1.535478,0.890813,-1299.466553,0.088023,0.000000
147.110001,4.356384,-1299.510986,-0.001315,0.003482,0.088439,19.378164,0.987171,0.884394,-1299.510986,0.087321,0.000000
147.530014,1.528587,-1299.421997,-0.001315,0.003449,0.087599,6.799496,0.346383,0.875991,-1299.421997,0.086618,0.000000
147.950012,0.160118,-1299.466553,-0.001315,0.003438,0.087330,0.712241,0.036283,0.873296,-1299.466553,0.085925,0.000000
148.370010,-2.250992,-1299.466553,-0.001319,0.003403,0.086445,-10.012912,-0.510082,0.864455,-1299.466553,0.085222,0.000000
148.790009,-0.446846,-1299.421997,-0.001311,0.003370,0.085595,-1.987670,-0.101257,0.855946,-1299.421997,0.084520,0.000000
149.210007,-0.405510,-1299.510986,-0.001324,0.003347,0.085015,-1.803798,-0.091890,0.850148,-1299.510986,0.083826,0.000000
149.630005,-0.186554,-1299.421997,-0.001324,0.003320,0.084329,-0.829833,-0.042274,0.843290,-1299.421997,0.083124,0.000000
150.050003,-0.109100,-1299.421997,-0.001302,0.003291,0.083601,-0.485303,-0.024722,0.836008,-1299.421997,0.082421,0.000000
150.470001,-0.098305,-1299.466553,-0.001315,0.003259,0.082785,-0.437281,-0.022276,0.827847,-1299.466553,0.081719,0.000000
150.890015,-0.110970,-1299.466553,-0.001311,0.003232,0.082100,-0.493617,-0.025146,0.821004,-1299.466553,0.081026,0.000000
151.310013,-0.048409,-1299.555420,-0.001319,0.003207,0.081468,-0.215332,-0.010970,0.814676,-1299.555420,0.080323,0.000000
151.730011,-0.074471,-1299.510986,-0.001293,0.003176,0.080670,-0.331261,-0.016875,0.806697,-1299.510986,0.079621,0.000000
152.150009,-0.093468,-1299.466553,-0.001311,0.003151,0.080037,-0.415765,-0.021180,0.800369,-1299.466553,0.078926,0.000000
152.570007,-0.134056,-1299.466553,-0.001315,0.003121,0.079265,-0.596311,-0.030378,0.792648,-1299.466553,0.078223,0.000000
152.990005,-0.127724,-1299.466553,-0.001315,0.003095,0.078605,-0.568143,-0.028943,0.786047,-1299.466553,0.077521,0.000000
153.410004,-0.119530,-1299.466553,-0.001315,0.003069,0.077955,-0.531695,-0.027086,0.779552,-1299.466553,0.076818,0.000000
153.830002,-0.134796,-1299.466553,-0.001315,0.003036,0.077123,-0.599603,-0.030545,0.771225,-1299.466553,0.076125,0.000000
154.250000,-0.147827,-1299.466553,-0.001319,0.003011,0.076490,-0.657568,-0.033498,0.764897,-1299.466553,0.075422,0.000000
154.670013,-0.169060,-1299.421997,-0.001324,0.002979,0.075674,-0.752015,-0.038309,0.756737,-1299.421997,0.074720,0.000000
155.090012,-0.175385,-1299.466553,-0.001328,0.002951,0.074945,-0.780149,-0.039743,0.749455,-1299.466553,0.074017,0.000000
155.510010,-0.198105,-1299.510986,-0.001337,0.002926,0.074322,-0.881214,-0.044891,0.743217,-1299.510986,0.073324,0.000000
155.930008,-0.167564,-1299.466553,-0.001345,0.002896,0.073550,-0.745364,-0.037971,0.735496,-1299.466553,0.072622,0.000000
156.350006,-0.169426,-1299.466553,-0.001345,0.002868,0.072838,-0.753644,-0.038392,0.728380,-1299.466553,0.071919,0.000000
156.770004,-0.238693,-1299.466553,-0.001362,0.002844,0.072249,-1.061761,-0.054089,0.722491,-1299.466553,0.071226,0.000000
157.190002,-0.178368,-1299.466553,-0.001388,0.002822,0.071677,-0.793419,-0.040419,0.716768,-1299.466553,0.070523,0.000000
157.610001,-0.196609,-1299.466553,-0.001410,0.002788,0.070818,-0.874563,-0.044552,0.708184,-1299.466553,0.069821,0.000000
158.030014,-0.194374,-1299.555420,-0.001440,0.002761,0.070124,-0.864619,-0.044046,0.701235,-1299.555420,0.069118,0.000000
158.450012,-0.218956,-1299.466553,-0.001483,0.002730,0.069351,-0.973965,-0.049616,0.693514,-1299.466553,0.068425,0.000000
158.870010,-0.230499,-1299.377563,-0.001500,0.002708,0.068772,-1.025312,-0.052232,0.687715,-1299.377563,0.067722,0.000000
159.290009,-0.213737,-1299.555420,-0.001544,0.002681,0.068095,-0.950752,-0.048434,0.680948,-1299.555420,0.067020,0.000000
159.710007,-0.212997,-1299.466553,-0.001569,0.002650,0.067306,-0.947460,-0.048266,0.673060,-1299.466553,0.066325,0.000000
160.130005,-0.229752,-1299.466553,-0.001595,0.002623,0.066620,-1.021986,-0.052062,0.666202,-1299.466553,0.065623,0.000000
160.550003,-0.228264,-1299.466553,-0.001630,0.002593,0.065874,-1.015368,-0.051725,0.658738,-1299.466553,0.064920,0.000000
160.970001,-0.201828,-1299.466553,-0.001673,0.002566,0.065171,-0.897776,-0.045735,0.651713,-1299.466553,0.064218,0.000000
161.390015,-0.212624,-1299.510986,-0.001673,0.002547,0.064687,-0.945797,-0.048181,0.646869,-1299.510986,0.063524,0.000000
161.810013,-0.214485,-1299.510986,-0.001725,0.002512,0.063810,-0.954078,-0.048603,0.638103,-1299.510986,0.062822,0.000000
162.230011,-0.254326,-1299.510986,-0.001725,0.002485,0.063126,-1.131298,-0.057631,0.631260,-1299.510986,0.062119,0.000000
162.650009,-0.220444,-1299.466553,-0.001768,0.002460,0.062492,-0.980583,-0.049953,0.624916,-1299.466553,0.061417,0.000000
163.070007,-0.225281,-1299.466553,-0.001794,0.002434,0.061816,-1.002099,-0.051049,0.618164,-1299.466553,0.060723,0.000000
163.490005,-0.209648,-1299.555420,-0.001828,0.002404,0.061070,-0.932561,-0.047507,0.610700,-1299.555420,0.060021,0.000000
163.910004,-0.212624,-1299.555420,-0.001863,0.002377,0.060368,-0.945797,-0.048181,0.603676,-1299.555420,0.059318,0.000000
164.330002,-0.245018,-1299.510986,-0.001880,0.002350,0.059700,-1.089895,-0.055522,0.596999,-1299.510986,0.058625,0.000000
164.750015,-0.191772,-1299.466553,-0.001906,0.002320,0.058919,-0.853047,-0.043456,0.589187,-1299.466553,0.057923,0.000000
165.170013,-0.203690,-1299.466553,-0.001927,0.002305,0.058537,-0.906056,-0.046157,0.585372,-1299.466553,0.057220,0.000000
165.590012,-0.227890,-1299.555420,-0.001975,0.002275,0.057792,-1.013705,-0.051641,0.577923,-1299.555420,0.056518,0.000000
166.010010,-0.209274,-1299.555420,-0.002005,0.002239,0.056881,-0.930899,-0.047422,0.568809,-1299.555420,0.055823,0.000000
166.430008,-0.199593,-1299.510986,-0.002039,0.002213,0.056222,-0.887832,-0.045228,0.562223,-1299.510986,0.055120,0.000000
166.850006,-0.223053,-1299.466553,-0.002052,0.002183,0.055459,-0.992189,-0.050545,0.554593,-1299.466553,0.054419,0.000000
167.270004,-0.240555,-1299.377563,-0.002078,0.002156,0.054766,-1.070041,-0.054511,0.547659,-1299.377563,0.053724,0.000000
167.690002,-0.219696,-1299.510986,-0.002108,0.002133,0.054185,-0.977257,-0.049784,0.541846,-1299.510986,0.053022,0.000000
168.110001,-0.228264,-1299.466553,-0.002134,0.002099,0.053317,-1.015368,-0.051725,0.533171,-1299.466553,0.052319,0.000000
168.530014,-0.199593,-1299.421997,-0.002151,0.002076,0.052736,-0.887832,-0.045228,0.527357,-1299.421997,0.051617,0.000000
168.950012,-0.199966,-1299.421997,-0.002186,0.002041,0.051842,-0.889495,-0.045313,0.518425,-1299.421997,0.050923,0.000000
169.370010,-0.191399,-1299.421997,-0.002225,0.002033,0.051635,-0.851384,-0.043372,0.516351,-1299.421997,0.050221,0.000000
169.790009,-0.214111,-1299.466553,-0.002242,0.002010,0.051054,-0.952415,-0.048518,0.510537,-1299.466553,0.049519,0.000000
170.210007,-0.216721,-1299.466553,-0.002281,0.001963,0.049856,-0.964021,-0.049110,0.498562,-1299.466553,0.048816,0.000000
170.630005,-0.175385,-1299.466553,-0.002315,0.001935,0.049146,-0.780149,-0.039743,0.491461,-1299.466553,0.048123,0.000000
171.050003,-0.180229,-1299.377563,-0.002350,0.001909,0.048486,-0.801699,-0.040841,0.484860,-1299.377563,0.048391,0.000000
171.200012,-0.180969,-1299.421997,-0.002350,0.001909,0.048495,-0.804991,-0.041008,0.484951,-1299.421997,0.048391,0.000000