File: Data/compression 28/AutoNoHeating-17-28-reverse-1-2_10222024_182335.csv
Time (sec),S:Load (lbs),S:HL1 (DIM),S:LVDT (in),S:Position (in),Ch:Position (mm),Ch:Load (N),Ch:Stress (MPa),Ch:Strain (mm/mm),Ch:HL1 (DIM),Set Point (),Cycles ()
0.110000,-0.090485,-1297.865234,-0.012973,-0.007554,-0.191882,-0.402496,-0.020504,-1.918821,-1297.865234,-0.191673,0.000000
0.520000,-0.074844,-1297.865234,-0.012943,-0.007447,-0.189149,-0.332924,-0.016960,-1.891494,-1297.865234,-0.188344,0.000000
0.930000,-0.061066,-1297.865234,-0.012810,-0.007190,-0.182629,-0.271634,-0.013838,-1.826288,-1297.865234,-0.181527,0.000000
1.340000,-0.059578,-1297.909668,-0.012542,-0.006927,-0.175942,-0.265016,-0.013501,-1.759416,-1297.909668,-0.174694,0.000000
1.750000,-0.093468,-1297.865234,-0.012271,-0.006663,-0.169247,-0.415765,-0.021180,-1.692469,-1297.865234,-0.167860,0.000000
2.160000,-0.104637,-1297.954102,-0.012008,-0.006387,-0.162231,-0.465449,-0.023711,-1.622312,-1297.954102,-0.161026,0.000000
2.570000,-0.051758,-1297.865234,-0.011693,-0.006114,-0.155302,-0.230230,-0.011728,-1.553018,-1297.865234,-0.154192,0.000000
2.980000,-0.026436,-1297.998657,-0.011421,-0.005847,-0.148512,-0.117593,-0.005990,-1.485117,-1297.998657,-0.147376,0.000000
3.390000,-0.039101,-1297.954102,-0.011128,-0.005585,-0.141852,-0.173928,-0.008860,-1.418518,-1297.954102,-0.140542,0.000000
3.800000,-0.050644,-1297.865234,-0.010865,-0.005316,-0.135034,-0.225275,-0.011476,-1.350345,-1297.865234,-0.133708,0.000000
4.210000,-0.080429,-1297.954102,-0.010606,-0.005042,-0.128079,-0.357766,-0.018225,-1.280793,-1297.954102,-0.126874,0.000000
4.620000,-0.102776,-1297.954102,-0.010300,-0.004771,-0.121186,-0.457169,-0.023289,-1.211863,-1297.954102,-0.120040,0.000000
5.030000,-0.075966,-1297.954102,-0.010063,-0.004508,-0.114499,-0.337913,-0.017214,-1.144991,-1297.954102,-0.113224,0.000000
5.440000,-0.060692,-1297.954102,-0.009787,-0.004240,-0.107691,-0.269971,-0.013753,-1.076909,-1297.954102,-0.106390,0.000000
5.850000,-0.057343,-1297.954102,-0.009490,-0.003972,-0.100901,-0.255072,-0.012994,-1.009008,-1297.954102,-0.099556,0.000000
6.260000,-0.057716,-1297.954102,-0.009240,-0.003701,-0.093999,-0.256735,-0.013079,-0.939986,-1297.954102,-0.092724,0.000000
6.670001,-0.026436,-1297.909668,-0.008955,-0.003433,-0.087199,-0.117593,-0.005990,-0.871994,-1297.909668,-0.085890,0.000000
7.080000,-0.030159,-1297.954102,-0.008701,-0.003166,-0.080417,-0.134154,-0.006834,-0.804169,-1297.954102,-0.079056,0.000000
7.490000,0.005585,-1297.954102,-0.008412,-0.002889,-0.073385,0.024842,0.001266,-0.733846,-1297.954102,-0.072240,0.000000
7.900001,-0.042450,-1297.954102,-0.008123,-0.002624,-0.066646,-0.188827,-0.009619,-0.666459,-1297.954102,-0.065406,0.000000
8.310000,-0.076706,-1297.909668,-0.007847,-0.002353,-0.059760,-0.341205,-0.017382,-0.597605,-1297.909668,-0.058572,0.000000
8.720000,-0.118042,-1297.909668,-0.007558,-0.002087,-0.053022,-0.525077,-0.026749,-0.530218,-1297.909668,-0.051738,0.000000
9.130000,-0.048035,-1297.954102,-0.007317,-0.001822,-0.046283,-0.213669,-0.010885,-0.462832,-1297.954102,-0.044904,0.000000
9.540001,-0.035004,-1297.909668,-0.007032,-0.001548,-0.039328,-0.155704,-0.007932,-0.393281,-1297.909668,-0.038088,0.000000
9.950001,-0.018990,-1297.909668,-0.006756,-0.001277,-0.032434,-0.084470,-0.004303,-0.324335,-1297.909668,-0.031254,0.000000
10.360001,-0.015266,-1297.954102,-0.006489,-0.001010,-0.025653,-0.067908,-0.003459,-0.256525,-1297.954102,-0.024420,0.000000
10.770000,-0.050270,-1297.998657,-0.006204,-0.000743,-0.018861,-0.223612,-0.011391,-0.188609,-1297.998657,-0.017586,0.000000
11.180000,0.013405,-1297.998657,-0.005954,-0.000472,-0.011994,0.059628,0.003038,-0.119936,-1297.998657,-0.010754,0.000000
11.590000,0.088997,-1297.954102,-0.005687,-0.000201,-0.005108,0.395878,0.020167,-0.051081,-1297.954102,-0.003936,0.000000
12.000001,0.086021,-1297.954102,-0.005605,-0.000005,-0.000139,0.382642,0.019493,-0.001393,-1297.954102,0.000044,0.000000
12.410001,0.065536,-1297.998657,-0.005609,-0.000005,-0.000139,0.291521,0.014851,-0.001393,-1297.998657,0.000338,0.000000
12.820001,0.074478,-1297.909668,-0.005614,-0.000005,-0.000139,0.331295,0.016877,-0.001393,-1297.909668,0.001023,0.000000
13.230000,0.138527,-1297.998657,-0.005609,0.000025,0.000624,0.616198,0.031391,0.006238,-1297.998657,0.001708,0.000000
13.640000,0.141129,-1297.998657,-0.005588,0.000053,0.001353,0.627771,0.031980,0.013535,-1297.998657,0.002394,0.000000
14.050000,0.130707,-1297.998657,-0.005553,0.000078,0.001986,0.581413,0.029619,0.019863,-1297.998657,0.003078,0.000000
14.460001,0.161980,-1297.954102,-0.005540,0.000104,0.002645,0.720522,0.036705,0.026449,-1297.954102,0.003755,0.000000
14.870001,0.200706,-1297.954102,-0.005506,0.000134,0.003391,0.892787,0.045481,0.033913,-1297.954102,0.004440,0.000000
15.280001,0.249863,-1297.954102,-0.005484,0.000155,0.003945,1.111445,0.056620,0.039454,-1297.954102,0.005125,0.000000
15.690001,0.288216,-1297.865234,-0.005454,0.000185,0.004701,1.282047,0.065311,0.047008,-1297.865234,0.005811,0.000000
16.100000,0.298645,-1297.954102,-0.005450,0.000209,0.005299,1.328439,0.067674,0.052989,-1297.954102,0.006495,0.000000
16.510000,0.380569,-1297.954102,-0.005407,0.000242,0.006157,1.692858,0.086238,0.061573,-1297.954102,0.007172,0.000000
16.920000,0.443123,-1297.954102,-0.005372,0.000271,0.006885,1.971109,0.100413,0.068855,-1297.954102,0.007857,0.000000
17.330000,0.525421,-1297.998657,-0.005364,0.000292,0.007423,2.337190,0.119062,0.074229,-1297.998657,0.008542,0.000000
17.740002,0.614044,-1297.865234,-0.005342,0.000321,0.008151,2.731405,0.139144,0.081511,-1297.865234,0.009228,0.000000
18.150002,0.665428,-1298.043091,-0.005312,0.000342,0.008698,2.959972,0.150788,0.086977,-1298.043091,0.009912,0.000000
18.560001,0.870979,-1297.998657,-0.005290,0.000371,0.009418,3.874310,0.197367,0.094183,-1297.998657,0.010589,0.000000
18.970001,1.095894,-1297.998657,-0.005260,0.000401,0.010181,4.874779,0.248333,0.101814,-1297.998657,0.011274,0.000000
19.380001,1.197922,-1297.998657,-0.005226,0.000422,0.010728,5.328622,0.271453,0.107279,-1297.998657,0.011959,0.000000
19.790001,1.355064,-1297.865234,-0.005208,0.000446,0.011326,6.027627,0.307062,0.113259,-1297.865234,0.012645,0.000000
20.200001,1.738983,-1297.954102,-0.005187,0.000481,0.012210,7.735384,0.394059,0.122101,-1297.954102,0.013329,0.000000
20.610001,2.165344,-1297.909668,-0.005148,0.000510,0.012956,9.631932,0.490674,0.129565,-1297.909668,0.014015,0.000000
21.020000,2.452820,-1297.998657,-0.005122,0.000535,0.013598,10.910687,0.555817,0.135984,-1297.998657,0.014691,0.000000
21.430000,3.139473,-1297.998657,-0.005113,0.000568,0.014439,13.965074,0.711415,0.144386,-1297.998657,0.015376,0.000000
21.840000,3.368111,-1297.909668,-0.005075,0.000589,0.014950,14.982104,0.763225,0.149503,-1297.909668,0.016062,0.000000
22.250002,4.003006,-1297.998657,-0.005057,0.000617,0.015662,17.806259,0.907094,0.156619,-1297.998657,0.016746,0.000000
22.660002,4.569382,-1297.998657,-0.005036,0.000643,0.016330,20.325624,1.035437,0.163296,-1297.998657,0.017432,0.000000
23.070002,5.222527,-1297.998657,-0.005001,0.000671,0.017041,23.230959,1.183441,0.170411,-1297.998657,0.018107,0.000000
23.480001,5.929657,-1297.998657,-0.004997,0.000702,0.017821,26.376432,1.343680,0.178208,-1297.998657,0.018793,0.000000
23.890001,6.300545,-1297.865234,-0.004963,0.000725,0.018420,28.026222,1.427724,0.184203,-1297.865234,0.019479,0.000000
24.300001,7.035980,-1298.043091,-0.004932,0.000753,0.019130,31.297604,1.594376,0.191304,-1298.043091,0.020163,0.000000
24.710001,7.753540,-1298.043091,-0.004919,0.000781,0.019825,34.489468,1.756977,0.198253,-1298.043091,0.020849,0.000000
25.120001,8.257362,-1297.954102,-0.004894,0.000807,0.020493,36.730583,1.871145,0.204929,-1297.954102,0.021524,0.000000
25.530001,8.774216,-1297.954102,-0.004868,0.000837,0.021256,39.029659,1.988266,0.212560,-1297.954102,0.022210,0.000000
25.940001,9.051628,-1297.998657,-0.004846,0.000856,0.021750,40.263653,2.051128,0.217495,-1297.998657,0.022894,0.000000
26.350000,9.871597,-1298.043091,-0.004829,0.000888,0.022547,43.911057,2.236936,0.225474,-1298.043091,0.023580,0.000000
26.760002,10.326637,-1298.043091,-0.004799,0.000913,0.023180,45.935177,2.340050,0.231802,-1298.043091,0.024264,0.000000
27.170002,10.937698,-1298.043091,-0.004760,0.000947,0.024066,48.653313,2.478518,0.240659,-1298.043091,0.024941,0.000000
27.580002,10.807739,-1297.998657,-0.004747,0.000967,0.024552,48.075226,2.449069,0.245519,-1297.998657,0.025627,0.000000
27.990002,11.123512,-1297.998657,-0.004730,0.000992,0.025185,49.479855,2.520624,0.251847,-1297.998657,0.026311,0.000000
28.400002,11.671272,-1298.087646,-0.004691,0.001022,0.025964,51.916412,2.644748,0.259644,-1298.087646,0.026997,0.000000
28.810001,11.727127,-1297.954102,-0.004687,0.001043,0.026502,52.164867,2.657405,0.265018,-1297.954102,0.027681,0.000000
29.220001,12.186638,-1298.043091,-0.004635,0.001076,0.027335,54.208874,2.761532,0.273345,-1298.043091,0.028358,0.000000
29.630001,12.203018,-1297.998657,-0.004605,0.001100,0.027942,54.281734,2.765243,0.279416,-1297.998657,0.029044,0.000000
30.040001,12.309143,-1297.998657,-0.004605,0.001125,0.028567,54.753803,2.789292,0.285669,-1297.998657,0.029728,0.000000
30.450001,12.545601,-1298.043091,-0.004566,0.001152,0.029269,55.805618,2.842874,0.292693,-1298.043091,0.030414,0.000000
30.860001,12.464424,-1297.954102,-0.004549,0.001180,0.029972,55.444527,2.824479,0.299718,-1297.954102,0.031098,0.000000
31.270002,12.830841,-1298.087646,-0.004514,0.001208,0.030691,57.074432,2.907510,0.306910,-1298.087646,0.031775,0.000000
31.680002,12.777962,-1298.043091,-0.004493,0.001232,0.031298,56.839214,2.895527,0.312981,-1298.043091,0.032461,0.000000
32.090000,13.179008,-1297.998657,-0.004467,0.001267,0.032175,58.623158,2.986406,0.321746,-1297.998657,0.033145,0.000000
32.500000,13.245293,-1298.087646,-0.004441,0.001291,0.032789,58.918003,3.001426,0.327893,-1298.087646,0.033831,0.000000
32.910000,13.391258,-1297.998657,-0.004406,0.001318,0.033475,59.567291,3.034503,0.334751,-1297.998657,0.034515,0.000000
33.320000,13.182732,-1297.998657,-0.004368,0.001342,0.034099,58.639717,2.987250,0.340989,-1297.998657,0.035192,0.000000
33.730003,13.127991,-1298.043091,-0.004342,0.001365,0.034680,58.396217,2.974845,0.346802,-1298.043091,0.035878,0.000000
34.140003,13.867897,-1297.954102,-0.004316,0.001402,0.035617,61.687489,3.142510,0.356174,-1297.954102,0.036562,0.000000
34.550003,13.617661,-1298.043091,-0.004299,0.001423,0.036137,60.574379,3.085806,0.361367,-1298.043091,0.037248,0.000000
34.960003,13.793793,-1297.998657,-0.004277,0.001451,0.036857,61.357853,3.125718,0.368573,-1297.998657,0.037932,0.000000
35.370003,13.730492,-1298.043091,-0.004255,0.001478,0.037534,61.076279,3.111374,0.375340,-1298.043091,0.038609,0.000000
35.780003,13.845924,-1298.043091,-0.004238,0.001504,0.038193,61.589748,3.137531,0.381926,-1298.043091,0.039293,0.000000
36.190002,13.893593,-1298.043091,-0.004178,0.001530,0.038860,61.801788,3.148333,0.388603,-1298.043091,0.039979,0.000000
36.600002,13.998230,-1298.043091,-0.004161,0.001554,0.039484,62.267239,3.172044,0.394840,-1298.043091,0.040665,0.000000
37.010002,14.122223,-1297.954102,-0.004143,0.001584,0.040239,62.818787,3.200141,0.402395,-1297.954102,0.041349,0.000000
37.420002,14.254791,-1298.087646,-0.004113,0.001613,0.040968,63.408478,3.230182,0.409677,-1298.087646,0.042026,0.000000
37.830002,14.245483,-1297.998657,-0.004087,0.001639,0.041635,63.367073,3.228073,0.416354,-1297.998657,0.042710,0.000000
38.240002,14.709457,-1298.043091,-0.004031,0.001669,0.042398,65.430931,3.333211,0.423984,-1298.043091,0.043396,0.000000
38.650002,14.469276,-1298.132080,-0.004031,0.001691,0.042945,64.362556,3.278785,0.429449,-1298.132080,0.044080,0.000000
39.060001,14.480080,-1297.998657,-0.004005,0.001715,0.043569,64.410614,3.281233,0.435687,-1297.998657,0.044766,0.000000
39.470001,14.483803,-1298.043091,-0.003967,0.001742,0.044245,64.427170,3.282077,0.442454,-1298.043091,0.045443,0.000000
39.880001,14.803665,-1298.043091,-0.003958,0.001769,0.044931,65.849991,3.354558,0.449312,-1298.043091,0.046127,0.000000
40.290001,15.093002,-1298.043091,-0.003928,0.001798,0.045659,67.137024,3.420123,0.456595,-1298.043091,0.046813,0.000000
40.700001,14.942566,-1298.087646,-0.003906,0.001821,0.046248,66.467850,3.386034,0.462484,-1298.087646,0.047497,0.000000
41.110001,14.841652,-1298.043091,-0.003876,0.001843,0.046813,66.018967,3.363166,0.468131,-1298.043091,0.048183,0.000000
41.520000,15.257591,-1298.043091,-0.003863,0.001879,0.047732,67.869156,3.457420,0.477321,-1298.043091,0.048860,0.000000
41.930000,15.662735,-1297.998657,-0.003820,0.001909,0.048486,69.671326,3.549226,0.484860,-1297.998657,0.049544,0.000000
42.340000,15.559959,-1298.043091,-0.003786,0.001934,0.049128,69.214157,3.525937,0.491279,-1298.043091,0.050230,0.000000
42.750004,16.128944,-1298.043091,-0.003768,0.001967,0.049952,71.745125,3.654871,0.499515,-1298.043091,0.050914,0.000000
43.160004,15.558098,-1297.998657,-0.003734,0.001987,0.050481,69.205879,3.525515,0.504814,-1297.998657,0.051600,0.000000
43.570004,15.790459,-1298.087646,-0.003704,0.002015,0.051193,70.239471,3.578169,0.511930,-1298.087646,0.052277,0.000000
43.980003,15.839981,-1298.087646,-0.003686,0.002042,0.051861,70.459755,3.589391,0.518606,-1298.087646,0.052961,0.000000
44.390003,16.015366,-1298.087646,-0.003660,0.002069,0.052554,71.239906,3.629134,0.525540,-1298.087646,0.053647,0.000000
44.800003,16.380669,-1298.043091,-0.003626,0.002101,0.053378,72.864853,3.711912,0.533776,-1298.043091,0.054331,0.000000
45.210003,16.011269,-1297.998657,-0.003596,0.002123,0.053924,71.221680,3.628205,0.539242,-1297.998657,0.055017,0.000000
45.620003,16.346039,-1298.087646,-0.003587,0.002151,0.054627,72.710815,3.704065,0.546266,-1298.087646,0.055692,0.000000
46.030003,16.677818,-1297.998657,-0.003553,0.002179,0.055355,74.186638,3.779248,0.553548,-1297.998657,0.056378,0.000000
46.440002,16.726974,-1298.087646,-0.003523,0.002205,0.056013,74.405296,3.790386,0.560134,-1298.087646,0.057064,0.000000
46.850002,16.928795,-1298.087646,-0.003501,0.002236,0.056795,75.303040,3.836120,0.567946,-1298.087646,0.057748,0.000000
47.260002,16.586960,-1298.087646,-0.003466,0.002255,0.057281,73.782486,3.758659,0.572806,-1298.087646,0.058434,0.000000
47.670002,17.190948,-1298.087646,-0.003445,0.002287,0.058078,76.469154,3.895525,0.580785,-1298.087646,0.059109,0.000000
48.080002,17.236374,-1298.043091,-0.003423,0.002311,0.058702,76.671219,3.905818,0.587022,-1298.043091,0.059795,0.000000
48.490002,17.825096,-1298.087646,-0.003397,0.002347,0.059621,79.289986,4.039225,0.596212,-1298.087646,0.060480,0.000000
48.900002,17.136581,-1298.087646,-0.003402,0.002366,0.060091,76.227318,3.883205,0.600905,-1298.087646,0.061165,0.000000
49.310001,17.242706,-1297.998657,-0.003346,0.002390,0.060714,76.699387,3.907253,0.607143,-1297.998657,0.061851,0.000000
49.720001,17.813179,-1298.132080,-0.003328,0.002421,0.061503,79.236977,4.036524,0.615030,-1298.132080,0.062526,0.000000
50.130001,17.600189,-1298.087646,-0.003290,0.002442,0.062015,78.289551,3.988260,0.620147,-1298.087646,0.063212,0.000000
50.540001,18.245132,-1298.087646,-0.003277,0.002475,0.062857,81.158401,4.134406,0.628565,-1298.087646,0.063897,0.000000
50.950001,18.136772,-1298.043091,-0.003251,0.002498,0.063447,80.676392,4.109851,0.634470,-1298.043091,0.064582,0.000000
51.360001,18.263008,-1298.043091,-0.003238,0.002524,0.064106,81.237915,4.138457,0.641055,-1298.043091,0.065267,0.000000
51.770004,18.546753,-1298.132080,-0.003195,0.002552,0.064817,82.500076,4.202754,0.648171,-1298.132080,0.065943,0.000000
52.180004,18.889709,-1298.043091,-0.003178,0.002586,0.065683,84.025627,4.280469,0.656831,-1298.043091,0.066629,0.000000
52.590004,18.977966,-1298.087646,-0.003139,0.002607,0.066222,84.418213,4.300468,0.662220,-1298.087646,0.067314,0.000000
53.000004,18.872208,-1298.176514,-0.003122,0.002632,0.066846,83.947769,4.276504,0.668458,-1298.176514,0.067999,0.000000
53.410004,19.359276,-1298.087646,-0.003096,0.002660,0.067565,86.114357,4.386875,0.675649,-1298.087646,0.068684,0.000000
53.820004,19.825859,-1298.132080,-0.003070,0.002691,0.068346,88.189827,4.492604,0.683461,-1298.132080,0.069360,0.000000
54.230003,20.021355,-1298.087646,-0.003035,0.002719,0.069058,89.059433,4.536904,0.690577,-1298.087646,0.070046,0.000000
54.640003,19.811333,-1298.176514,-0.003001,0.002741,0.069612,88.125206,4.489312,0.696118,-1298.176514,0.070731,0.000000
55.050003,19.728668,-1298.087646,-0.003001,0.002764,0.070210,87.757500,4.470580,0.702098,-1298.087646,0.071416,0.000000
55.460003,20.900146,-1298.087646,-0.002958,0.002800,0.071130,92.968498,4.736041,0.711303,-1298.087646,0.072101,0.000000
55.870003,20.605232,-1298.176514,-0.002940,0.002822,0.071668,91.656654,4.669212,0.716677,-1298.176514,0.072777,0.000000
56.280003,21.013725,-1298.043091,-0.002923,0.002850,0.072379,93.473717,4.761778,0.723793,-1298.043091,0.073463,0.000000
56.690002,21.023407,-1298.087646,-0.002889,0.002878,0.073089,93.516785,4.763972,0.730893,-1298.087646,0.074148,0.000000
57.100002,21.141449,-1298.087646,-0.002880,0.002903,0.073731,94.041862,4.790721,0.737313,-1298.087646,0.074833,0.000000
57.510002,21.439720,-1298.087646,-0.002850,0.002926,0.074329,95.368637,4.858310,0.743293,-1298.087646,0.075518,0.000000
57.920002,21.621063,-1298.132080,-0.002820,0.002952,0.074980,96.175293,4.899403,0.749803,-1298.132080,0.076194,0.000000
58.330002,22.306976,-1298.087646,-0.002802,0.002984,0.075804,99.226387,5.054833,0.758039,-1298.087646,0.076879,0.000000
58.740002,22.463371,-1298.176514,-0.002777,0.003011,0.076490,99.922066,5.090272,0.764897,-1298.176514,0.077565,0.000000
59.150002,22.509544,-1298.176514,-0.002755,0.003036,0.077123,100.127457,5.100736,0.771225,-1298.176514,0.078250,0.000000
59.560001,23.785667,-1298.087646,-0.002729,0.003068,0.077920,105.803932,5.389909,0.779204,-1298.087646,0.078935,0.000000
59.970001,23.611023,-1298.176514,-0.002703,0.003089,0.078467,105.027077,5.350334,0.784669,-1298.176514,0.079611,0.000000
60.380001,24.265282,-1298.132080,-0.002686,0.003121,0.079272,107.937363,5.498591,0.792724,-1298.132080,0.080296,0.000000
60.790005,24.014671,-1298.176514,-0.002647,0.003140,0.079758,106.822594,5.441803,0.797583,-1298.176514,0.080982,0.000000
61.200005,24.648827,-1298.176514,-0.002630,0.003167,0.080453,109.643456,5.585504,0.804532,-1298.176514,0.081666,0.000000
61.610004,25.447937,-1298.087646,-0.002600,0.003196,0.081189,113.198074,5.766585,0.811890,-1298.087646,0.082352,0.000000
62.020004,25.593163,-1298.221069,-0.002591,0.003222,0.081849,113.844070,5.799494,0.818491,-1298.221069,0.083028,0.000000
62.430004,25.602470,-1298.087646,-0.002561,0.003242,0.082352,113.885475,5.801602,0.823517,-1298.087646,0.083713,0.000000
62.840004,26.395996,-1298.221069,-0.002535,0.003276,0.083210,117.415253,5.981418,0.832102,-1298.221069,0.084399,0.000000
63.250004,27.551842,-1298.132080,-0.002522,0.003307,0.084008,122.556709,6.243337,0.840080,-1298.132080,0.085083,0.000000
63.660004,27.925331,-1298.132080,-0.002492,0.003332,0.084641,124.218079,6.327971,0.846408,-1298.132080,0.085769,0.000000
64.070000,29.109100,-1298.176514,-0.002475,0.003365,0.085483,129.483749,6.596217,0.854826,-1298.176514,0.086445,0.000000
64.480003,28.880463,-1298.176514,-0.002462,0.003386,0.086003,128.466721,6.544406,0.860034,-1298.176514,0.087130,0.000000
64.889999,29.609940,-1298.176514,-0.002432,0.003414,0.086713,131.711594,6.709708,0.867135,-1298.176514,0.087816,0.000000
65.300003,30.118973,-1298.087646,-0.002414,0.003440,0.087374,133.975876,6.825057,0.873735,-1298.087646,0.088500,0.000000
65.710007,30.835419,-1298.132080,-0.002380,0.003468,0.088076,137.162796,6.987406,0.880760,-1298.132080,0.089186,0.000000
66.120003,31.921257,-1298.221069,-0.002380,0.003499,0.088874,141.992844,7.233460,0.888739,-1298.221069,0.089862,0.000000
66.530006,31.929077,-1298.043091,-0.002341,0.003521,0.089437,142.027634,7.235232,0.894371,-1298.043091,0.090547,0.000000
66.940002,32.872299,-1298.176514,-0.002315,0.003548,0.090121,146.223297,7.448969,0.901214,-1298.176514,0.091233,0.000000
67.350006,33.831528,-1298.087646,-0.002302,0.003577,0.090851,150.490158,7.666334,0.908511,-1298.087646,0.091917,0.000000
67.760002,34.436264,-1298.176514,-0.002255,0.003603,0.091526,153.180145,7.803369,0.915263,-1298.176514,0.092603,0.000000
68.170006,35.106163,-1298.265503,-0.002255,0.003630,0.092203,156.160019,7.955170,0.922031,-1298.265503,0.093279,0.000000
68.580002,35.593971,-1298.132080,-0.002225,0.003651,0.092724,158.329895,8.065709,0.927239,-1298.132080,0.093964,0.000000
68.990005,37.015312,-1298.221069,-0.002220,0.003684,0.093582,164.652328,8.387790,0.935823,-1298.221069,0.094650,0.000000
69.400002,38.010666,-1298.132080,-0.002195,0.003710,0.094224,169.079880,8.613339,0.942242,-1298.132080,0.095334,0.000000
69.810005,39.801407,-1298.087646,-0.002160,0.003746,0.095143,177.045502,9.019128,0.951432,-1298.087646,0.096020,0.000000
70.220001,39.764908,-1298.176514,-0.002147,0.003763,0.095585,176.883148,9.010858,0.955853,-1298.176514,0.096695,0.000000
70.630005,40.436668,-1298.132080,-0.002126,0.003787,0.096201,179.871277,9.163079,0.962014,-1298.132080,0.097381,0.000000
71.040001,41.937706,-1298.132080,-0.002121,0.003819,0.096990,186.548233,9.503221,0.969902,-1298.132080,0.098065,0.000000
71.450005,42.593079,-1298.132080,-0.002087,0.003840,0.097537,189.463470,9.651730,0.975367,-1298.132080,0.098751,0.000000
71.860001,44.152206,-1298.132080,-0.002070,0.003873,0.098379,196.398819,10.005033,0.983785,-1298.132080,0.099437,0.000000
72.270004,44.939400,-1298.265503,-0.002052,0.003896,0.098967,199.900436,10.183414,0.989674,-1298.265503,0.100112,0.000000
72.680000,45.541527,-1298.132080,-0.002026,0.003921,0.099593,202.578827,10.319858,0.995927,-1298.132080,0.100798,0.000000
73.090004,47.287209,-1298.176514,-0.002009,0.003950,0.100321,210.344009,10.715434,1.003209,-1298.176514,0.101482,0.000000
73.500000,48.644135,-1298.132080,-0.002001,0.003985,0.101214,216.379913,11.022919,1.012141,-1298.132080,0.102168,0.000000
73.910004,49.946320,-1298.176514,-0.001962,0.004007,0.101768,222.172333,11.317998,1.017683,-1298.176514,0.102852,0.000000
74.320007,50.778572,-1298.221069,-0.001944,0.004030,0.102368,225.874374,11.506589,1.023678,-1298.221069,0.103529,0.000000
74.730003,52.449409,-1298.221069,-0.001944,0.004059,0.103096,233.306625,11.885206,1.030960,-1298.221069,0.104215,0.000000
75.140007,53.897194,-1298.221069,-0.001919,0.004088,0.103833,239.746689,12.213279,1.038333,-1298.221069,0.104899,0.000000
75.550003,55.495789,-1298.087646,-0.001901,0.004115,0.104518,246.857590,12.575526,1.045176,-1298.087646,0.105585,0.000000
75.960007,56.518318,-1298.087646,-0.001871,0.004139,0.105125,251.406036,12.807234,1.051247,-1298.087646,0.106269,0.000000
76.370003,57.480904,-1298.176514,-0.001867,0.004162,0.105715,255.687836,13.025358,1.057151,-1298.176514,0.106946,0.000000
76.780006,59.894997,-1298.176514,-0.001832,0.004198,0.106625,266.426239,13.572400,1.066250,-1298.176514,0.107632,0.000000
77.190002,60.833000,-1298.265503,-0.001841,0.004219,0.107172,270.598694,13.784955,1.071716,-1298.265503,0.108316,0.000000
77.600006,62.627464,-1298.132080,-0.001828,0.004248,0.107900,278.580872,14.191586,1.078998,-1298.132080,0.109002,0.000000
78.010002,63.764313,-1298.221069,-0.001811,0.004272,0.108516,283.637817,14.449200,1.085160,-1298.221069,0.109686,0.000000
78.420006,65.219543,-1298.221069,-0.001798,0.004298,0.109158,290.111023,14.778960,1.091579,-1298.221069,0.110363,0.000000
78.830002,65.354340,-1298.176514,-0.001776,0.004301,0.109235,290.710632,14.809505,1.092351,-1298.176514,0.019174,0.000000
79.240005,65.464569,-1298.265503,-0.001759,0.004311,0.109488,291.200958,14.834484,1.094879,-1298.265503,294.500458,0.000000
79.650002,65.125717,-1298.176514,-0.001750,0.004327,0.109912,289.693665,14.757698,1.099118,-1298.176514,294.500458,0.000000
80.060005,65.491379,-1298.221069,-0.001733,0.004342,0.110286,291.320190,14.840559,1.102858,-1298.221069,294.500458,0.000000
80.470001,65.418762,-1298.176514,-0.001742,0.004353,0.110563,290.997192,14.824103,1.105628,-1298.176514,294.500458,0.000000
80.880005,65.049744,-1298.176514,-0.001725,0.004358,0.110701,289.355713,14.740482,1.107006,-1298.176514,294.500458,0.000000
81.290001,65.378555,-1298.265503,-0.001720,0.004370,0.110996,290.818329,14.814992,1.109958,-1298.265503,294.500458,0.000000
81.700005,64.605499,-1298.221069,-0.001716,0.004370,0.111005,287.379608,14.639815,1.110049,-1298.221069,294.500458,0.000000
82.110001,65.768051,-1298.221069,-0.001694,0.004376,0.111144,292.550903,14.903254,1.111442,-1298.221069,294.500458,0.000000
82.520004,64.955536,-1298.265503,-0.001690,0.004386,0.111396,288.936646,14.719135,1.113955,-1298.265503,294.500458,0.000000
82.930000,64.973038,-1298.221069,-0.001681,0.004399,0.111733,289.014496,14.723101,1.117331,-1298.221069,294.500458,0.000000
83.340004,65.303711,-1298.176514,-0.001677,0.004410,0.112019,290.485413,14.798033,1.120193,-1298.176514,294.500458,0.000000
83.750008,64.956650,-1298.132080,-0.001677,0.004412,0.112072,288.941620,14.719388,1.120723,-1298.132080,294.500458,0.000000
84.160004,64.859085,-1298.176514,-0.001660,0.004423,0.112349,288.507629,14.697279,1.123493,-1298.176514,294.500458,0.000000
84.570007,65.022934,-1298.265503,-0.001664,0.004425,0.112392,289.236450,14.734407,1.123917,-1298.265503,294.500458,0.000000
84.980003,65.949020,-1298.176514,-0.001656,0.004433,0.112601,293.355896,14.944262,1.126006,-1298.176514,294.500458,0.000000
85.390007,65.251572,-1298.132080,-0.001647,0.004433,0.112601,290.253479,14.786218,1.126006,-1298.132080,294.500458,0.000000
85.800003,64.563049,-1298.221069,-0.001656,0.004433,0.112601,287.190796,14.630196,1.126006,-1298.221069,294.500458,0.000000
86.210007,66.663605,-1298.221069,-0.001638,0.004319,0.109712,296.534515,15.106189,1.097120,-1298.221069,294.500458,0.000000
86.620003,66.013824,-1298.265503,-0.001621,0.004319,0.109712,293.644165,14.958947,1.097120,-1298.265503,294.500458,0.000000
87.030006,65.414673,-1298.221069,-0.001621,0.004394,0.111603,290.979004,14.823176,1.116029,-1298.221069,294.500458,0.000000
87.440002,65.304825,-1298.265503,-0.001613,0.004456,0.113173,290.490356,14.798285,1.131729,-1298.265503,294.500458,0.000000
87.850006,65.426208,-1298.221069,-0.001617,0.004465,0.113398,291.030304,14.825791,1.133985,-1298.221069,294.500458,0.000000
88.260002,65.108948,-1298.221069,-0.001621,0.004467,0.113459,289.619049,14.753899,1.134590,-1298.221069,294.500458,0.000000
88.670006,65.111191,-1298.265503,-0.001617,0.004472,0.113580,289.629028,14.754407,1.135802,-1298.265503,294.500458,0.000000
89.080002,65.082886,-1298.176514,-0.001608,0.004476,0.113701,289.503143,14.747993,1.137013,-1298.176514,294.500458,0.000000
89.490005,65.054581,-1298.265503,-0.001608,0.004481,0.113806,289.377228,14.741579,1.138057,-1298.265503,294.500458,0.000000
89.900002,65.253067,-1298.176514,-0.001613,0.004487,0.113962,290.260132,14.786556,1.139617,-1298.176514,294.500458,0.000000
90.310005,64.969681,-1298.176514,-0.001595,0.004488,0.113987,288.999573,14.722340,1.139874,-1298.176514,294.500458,0.000000
90.720001,65.933014,-1298.221069,-0.001608,0.004502,0.114343,293.284698,14.940635,1.143432,-1298.221069,294.500458,0.000000
91.130005,65.621704,-1298.132080,-0.001591,0.004502,0.114343,291.899933,14.870091,1.143432,-1298.132080,294.500458,0.000000
91.540001,65.288803,-1298.310059,-0.001595,0.004502,0.114343,290.419098,14.794654,1.143432,-1298.310059,294.500458,0.000000
91.950005,64.916809,-1298.221069,-0.001591,0.004502,0.114343,288.764374,14.710359,1.143432,-1298.221069,294.500458,0.000000
92.360001,64.551514,-1298.221069,-0.001578,0.004502,0.114343,287.139465,14.627582,1.143432,-1298.221069,294.500458,0.000000
92.770004,66.580200,-1298.265503,-0.001565,0.004473,0.113606,296.163513,15.087289,1.136059,-1298.265503,294.500458,0.000000
93.180008,66.175430,-1298.221069,-0.001565,0.004473,0.113606,294.363007,14.995566,1.136059,-1298.221069,294.500458,0.000000
93.590004,65.797470,-1298.310059,-0.001552,0.004473,0.113615,292.681763,14.909920,1.136150,-1298.310059,294.500458,0.000000
94.000008,65.433289,-1298.265503,-0.001552,0.004483,0.113866,291.061798,14.827395,1.138663,-1298.265503,294.500458,0.000000
94.410004,65.113052,-1298.265503,-0.001548,0.004505,0.114431,289.637329,14.754828,1.144310,-1298.265503,294.500458,0.000000
94.820007,65.496216,-1298.265503,-0.001552,0.004529,0.115029,291.341705,14.841655,1.150290,-1298.265503,294.500458,0.000000
95.230003,65.247849,-1298.265503,-0.001539,0.004529,0.115029,290.236938,14.785374,1.150290,-1298.265503,294.500458,0.000000
95.640007,64.979370,-1298.310059,-0.001544,0.004530,0.115055,289.042664,14.724536,1.150548,-1298.310059,294.500458,0.000000
96.050003,65.130554,-1298.265503,-0.001548,0.004535,0.115194,289.715179,14.758794,1.151940,-1298.265503,294.500458,0.000000
96.460007,64.882553,-1298.265503,-0.001561,0.004535,0.115194,288.612000,14.702597,1.151940,-1298.265503,294.500458,0.000000
96.870003,64.874359,-1298.310059,-0.001544,0.004539,0.115280,288.575562,14.700740,1.152803,-1298.310059,294.500458,0.000000
97.280006,64.967453,-1298.310059,-0.001535,0.004543,0.115392,288.989655,14.721835,1.153924,-1298.310059,294.500458,0.000000
97.690002,64.776428,-1298.354492,-0.001535,0.004543,0.115401,288.139954,14.678548,1.154014,-1298.354492,294.500458,0.000000
98.100006,65.301849,-1298.265503,-0.001548,0.004552,0.115610,290.477142,14.797610,1.156104,-1298.265503,294.500458,0.000000
98.510002,65.082520,-1298.265503,-0.001548,0.004552,0.115610,289.501495,14.747910,1.156104,-1298.265503,294.500458,0.000000
98.920006,64.984955,-1298.310059,-0.001548,0.004554,0.115671,289.067505,14.725801,1.156709,-1298.310059,294.500458,0.000000
99.330002,64.922760,-1298.265503,-0.001539,0.004556,0.115713,288.790863,14.711707,1.157133,-1298.265503,294.500458,0.000000
99.740005,65.097412,-1298.354492,-0.001539,0.004560,0.115827,289.567749,14.751285,1.158269,-1298.354492,294.500458,0.000000
100.150002,64.912720,-1298.310059,-0.001544,0.004560,0.115827,288.746185,14.709433,1.158269,-1298.310059,294.500458,0.000000
100.560005,65.147675,-1298.354492,-0.001531,0.004565,0.115957,289.791321,14.762674,1.159571,-1298.354492,294.500458,0.000000
100.970001,65.003204,-1298.310059,-0.001531,0.004566,0.115965,289.148682,14.729937,1.159646,-1298.310059,294.500458,0.000000
101.380005,64.965958,-1298.398926,-0.001522,0.004568,0.116027,288.983002,14.721497,1.160267,-1298.398926,294.500458,0.000000
101.790009,65.460480,-1298.310059,-0.001526,0.004575,0.116217,291.182770,14.833556,1.162175,-1298.310059,294.500458,0.000000
102.200005,65.334976,-1298.354492,-0.001526,0.004575,0.116217,290.624481,14.805117,1.162175,-1298.354492,294.500458,0.000000
102.610008,65.180450,-1298.354492,-0.001513,0.004575,0.116217,289.937134,14.770102,1.162175,-1298.354492,294.500458,0.000000
103.020004,65.141724,-1298.354492,-0.001522,0.004578,0.116286,289.764862,14.761325,1.162856,-1298.354492,294.500458,0.000000
103.430008,65.046021,-1298.354492,-0.001518,0.004579,0.116304,289.339142,14.739638,1.163038,-1298.354492,294.500458,0.000000
103.840004,65.061661,-1298.398926,-0.001522,0.004581,0.116364,289.408722,14.743183,1.163643,-1298.398926,294.500458,0.000000
104.250008,64.972672,-1298.354492,-0.001500,0.004583,0.116416,289.012878,14.723018,1.164158,-1298.354492,294.500458,0.000000
104.660004,64.920532,-1298.354492,-0.001518,0.004584,0.116425,288.780945,14.711203,1.164249,-1298.354492,294.500458,0.000000
105.070007,65.537933,-1298.487915,-0.001522,0.004593,0.116650,291.527283,14.851108,1.166505,-1298.487915,294.500458,0.000000
105.480003,65.380035,-1298.354492,-0.001509,0.004591,0.116616,290.824921,14.815328,1.166156,-1298.354492,294.500458,0.000000
105.890007,65.206512,-1298.398926,-0.001505,0.004591,0.116616,290.053040,14.776007,1.166156,-1298.398926,294.500458,0.000000
106.300003,65.019958,-1298.398926,-0.001509,0.004591,0.116616,289.223206,14.733733,1.166156,-1298.398926,294.500458,0.000000
106.710007,64.828934,-1298.398926,-0.001505,0.004591,0.116616,288.373505,14.690447,1.166156,-1298.398926,294.500458,0.000000
107.120003,65.369614,-1298.443481,-0.001496,0.004599,0.116815,290.778564,14.812966,1.168155,-1298.443481,294.500458,0.000000
107.530006,65.263855,-1298.443481,-0.001483,0.004599,0.116815,290.308136,14.789001,1.168155,-1298.443481,294.500458,0.000000
107.940002,65.103363,-1298.398926,-0.001500,0.004599,0.116815,289.594208,14.752633,1.168155,-1298.398926,294.500458,0.000000
108.350006,64.948837,-1298.443481,-0.001496,0.004599,0.116825,288.906860,14.717617,1.168246,-1298.443481,294.500458,0.000000
108.760002,65.012878,-1298.398926,-0.001492,0.004603,0.116920,289.191711,14.732129,1.169199,-1298.398926,294.500458,0.000000
109.170006,65.076935,-1298.443481,-0.001492,0.004605,0.116971,289.476654,14.746644,1.169714,-1298.443481,294.500458,0.000000
109.580002,64.960754,-1298.398926,-0.001492,0.004605,0.116971,288.959869,14.720317,1.169714,-1298.398926,294.500458,0.000000
109.990005,65.422485,-1298.487915,-0.001487,0.004613,0.117162,291.013763,14.824946,1.171622,-1298.487915,294.500458,0.000000
110.400002,65.332382,-1298.398926,-0.001492,0.004612,0.117146,290.612946,14.804529,1.171455,-1298.398926,294.500458,0.000000
110.810005,65.231842,-1298.398926,-0.001483,0.004612,0.117146,290.165710,14.781747,1.171455,-1298.398926,294.500458,0.000000
111.220009,65.072083,-1298.487915,-0.001492,0.004612,0.117153,289.455078,14.745544,1.171531,-1298.487915,294.500458,0.000000
111.630005,64.965958,-1298.398926,-0.001475,0.004612,0.117153,288.983002,14.721497,1.171531,-1298.398926,294.500458,0.000000
112.040009,65.042297,-1298.443481,-0.001487,0.004618,0.117309,289.322601,14.738795,1.173090,-1298.443481,294.500458,0.000000
112.450005,65.175613,-1298.398926,-0.001487,0.004618,0.117309,289.915619,14.769006,1.173090,-1298.398926,294.500458,0.000000
112.860008,65.063522,-1298.443481,-0.001475,0.004618,0.117309,289.416992,14.743606,1.173090,-1298.443481,294.500458,0.000000
113.270004,64.948090,-1298.443481,-0.001492,0.004618,0.117309,288.903534,14.717447,1.173090,-1298.443481,294.500458,0.000000
113.680008,65.441483,-1298.443481,-0.001475,0.004626,0.117500,291.098267,14.829251,1.174998,-1298.443481,294.500458,0.000000
114.090004,65.384140,-1298.532349,-0.001479,0.004626,0.117500,290.843170,14.816257,1.174998,-1298.532349,294.500458,0.000000
114.500008,65.284714,-1298.443481,-0.001479,0.004626,0.117500,290.400909,14.793728,1.174998,-1298.443481,294.500458,0.000000
114.910004,65.164062,-1298.487915,-0.001470,0.004626,0.117500,289.864227,14.766387,1.174998,-1298.487915,294.500458,0.000000
115.320007,65.019211,-1298.532349,-0.001487,0.004626,0.117500,289.219879,14.733563,1.174998,-1298.532349,294.500458,0.000000
115.730003,64.913452,-1298.443481,-0.001466,0.004626,0.117509,288.749451,14.709599,1.175089,-1298.443481,294.500458,0.000000
116.140007,65.115280,-1298.487915,-0.001470,0.004631,0.117630,289.647247,14.755334,1.176300,-1298.487915,294.500458,0.000000
116.550003,65.051605,-1298.487915,-0.001479,0.004631,0.117630,289.363983,14.740905,1.176300,-1298.487915,294.500458,0.000000
116.960007,65.040802,-1298.576904,-0.001470,0.004634,0.117700,289.315948,14.738456,1.176996,-1298.576904,294.500458,0.000000
117.370003,65.123474,-1298.532349,-0.001470,0.004635,0.117718,289.683685,14.757190,1.177178,-1298.532349,294.500458,0.000000
117.780006,65.021820,-1298.487915,-0.001449,0.004636,0.117744,289.231506,14.734156,1.177435,-1298.487915,294.500458,0.000000
118.190002,65.284714,-1298.532349,-0.001462,0.004639,0.117830,290.400909,14.793728,1.178298,-1298.532349,294.500458,0.000000
118.600006,65.205032,-1298.487915,-0.001466,0.004639,0.117830,290.046478,14.775672,1.178298,-1298.487915,294.500458,0.000000
119.010002,65.091080,-1298.532349,-0.001457,0.004639,0.117830,289.539581,14.749849,1.178298,-1298.532349,294.500458,0.000000
119.420006,65.015488,-1298.487915,-0.001462,0.004640,0.117856,289.203339,14.732720,1.178556,-1298.487915,294.500458,0.000000
119.830009,64.970810,-1298.487915,-0.001449,0.004640,0.117856,289.004608,14.722596,1.178556,-1298.487915,294.500458,0.000000
120.240005,65.426590,-1298.576904,-0.001466,0.004647,0.118039,291.032013,14.825877,1.180388,-1298.576904,294.500458,0.000000
120.650009,65.390472,-1298.532349,-0.001453,0.004647,0.118039,290.871338,14.817693,1.180388,-1298.532349,294.500458,0.000000
121.060005,65.309296,-1298.487915,-0.001453,0.004647,0.118039,290.510254,14.799298,1.180388,-1298.487915,294.500458,0.000000
121.470009,65.226257,-1298.576904,-0.001453,0.004647,0.118039,290.140869,14.780481,1.180388,-1298.576904,294.500458,0.000000
121.880005,65.205032,-1298.532349,-0.001444,0.004649,0.118081,290.046478,14.775672,1.180812,-1298.532349,294.500458,0.000000
122.290009,65.172623,-1298.532349,-0.001453,0.004650,0.118107,289.902313,14.768328,1.181069,-1298.532349,294.500458,0.000000
122.700005,65.110077,-1298.487915,-0.001453,0.004650,0.118116,289.624084,14.754154,1.181160,-1298.487915,294.500458,0.000000
123.110008,65.152893,-1298.576904,-0.001457,0.004652,0.118160,289.814545,14.763856,1.181599,-1298.576904,294.500458,0.000000
123.520004,65.078415,-1298.532349,-0.001453,0.004652,0.118160,289.483246,14.746980,1.181599,-1298.532349,294.500458,0.000000
123.930008,65.053101,-1298.532349,-0.001453,0.004654,0.118202,289.370636,14.741242,1.182023,-1298.532349,294.500458,0.000000
124.340004,65.028519,-1298.532349,-0.001453,0.004654,0.118211,289.261292,14.735673,1.182114,-1298.532349,294.500458,0.000000
124.750008,65.043045,-1298.576904,-0.001449,0.004655,0.118246,289.325928,14.738965,1.182462,-1298.576904,294.500458,0.000000
125.160004,65.000214,-1298.621338,-0.001453,0.004656,0.118255,289.135376,14.729259,1.182553,-1298.621338,294.500458,0.000000
125.570007,65.059799,-1298.532349,-0.001444,0.004658,0.118325,289.400452,14.742761,1.183249,-1298.532349,294.500458,0.000000
125.980003,65.073578,-1298.576904,-0.001457,0.004659,0.118351,289.461731,14.745884,1.183506,-1298.576904,294.500458,0.000000
126.390007,65.051987,-1298.532349,-0.001457,0.004659,0.118351,289.365692,14.740992,1.183506,-1298.532349,294.500458,0.000000
126.800003,64.987930,-1298.487915,-0.001440,0.004659,0.118351,289.080750,14.726475,1.183506,-1298.487915,294.500458,0.000000
127.210007,64.942871,-1298.621338,-0.001436,0.004660,0.118376,288.880310,14.716265,1.183764,-1298.621338,294.500458,0.000000
127.620003,65.006927,-1298.487915,-0.001449,0.004663,0.118428,289.165253,14.730780,1.184278,-1298.487915,294.500458,0.000000
128.029999,64.986816,-1298.665894,-0.001440,0.004665,0.118481,289.075806,14.726223,1.184808,-1298.665894,294.500458,0.000000
128.440002,65.096298,-1298.532349,-0.001431,0.004665,0.118488,289.562805,14.751032,1.184884,-1298.532349,294.500458,0.000000
128.850006,65.059052,-1298.576904,-0.001440,0.004665,0.118497,289.397125,14.742592,1.184975,-1298.576904,294.500458,0.000000
129.260010,64.992035,-1298.665894,-0.001440,0.004665,0.118497,289.098999,14.727406,1.184975,-1298.665894,294.500458,0.000000
129.670013,64.906754,-1298.576904,-0.001440,0.004665,0.118497,288.719666,14.708080,1.184975,-1298.576904,294.500458,0.000000
130.080002,65.155502,-1298.576904,-0.001431,0.004670,0.118628,289.826141,14.764448,1.186277,-1298.576904,294.500458,0.000000
130.490005,65.190506,-1298.621338,-0.001444,0.004670,0.118628,289.981842,14.772380,1.186277,-1298.621338,294.500458,0.000000
130.900009,65.133530,-1298.532349,-0.001431,0.004670,0.118628,289.728424,14.759469,1.186277,-1298.532349,294.500458,0.000000
131.310013,65.053848,-1298.576904,-0.001440,0.004670,0.118628,289.373962,14.741412,1.186277,-1298.576904,294.500458,0.000000
131.720001,64.989044,-1298.443481,-0.001423,0.004671,0.118637,289.085693,14.726727,1.186368,-1298.443481,294.500458,0.000000
132.130005,65.163315,-1298.621338,-0.001427,0.004675,0.118741,289.860901,14.766218,1.187412,-1298.621338,294.500458,0.000000
132.540009,65.190506,-1298.532349,-0.001427,0.004675,0.118741,289.981842,14.772380,1.187412,-1298.532349,294.500458,0.000000
132.950012,65.135025,-1298.532349,-0.001440,0.004675,0.118741,289.735077,14.759808,1.187412,-1298.532349,294.500458,0.000000
133.360001,65.064270,-1298.621338,-0.001436,0.004675,0.118749,289.420319,14.743774,1.187488,-1298.621338,294.500458,0.000000
133.770004,65.028519,-1298.532349,-0.001440,0.004676,0.118758,289.261292,14.735673,1.187579,-1298.532349,294.500458,0.000000
134.180008,64.980484,-1298.576904,-0.001418,0.004676,0.118758,289.047638,14.724789,1.187579,-1298.576904,294.500458,0.000000
134.590012,64.891113,-1298.576904,-0.001427,0.004676,0.118758,288.650085,14.704536,1.187579,-1298.576904,294.500458,0.000000
135.000000,65.159225,-1298.621338,-0.001436,0.004680,0.118879,289.842712,14.765291,1.188790,-1298.621338,294.500458,0.000000
135.410004,65.127197,-1298.621338,-0.001436,0.004680,0.118879,289.700256,14.758034,1.188790,-1298.621338,294.500458,0.000000
135.820007,65.072083,-1298.576904,-0.001431,0.004680,0.118879,289.455078,14.745544,1.188790,-1298.576904,294.500458,0.000000
136.230011,65.018463,-1298.621338,-0.001427,0.004680,0.118879,289.216583,14.733395,1.188790,-1298.621338,294.500458,0.000000
136.639999,64.952179,-1298.576904,-0.001436,0.004680,0.118879,288.921722,14.718374,1.188790,-1298.576904,294.500458,0.000000
137.050003,64.871002,-1298.532349,-0.001423,0.004680,0.118879,288.560638,14.699979,1.188790,-1298.532349,294.500458,0.000000
137.460007,64.807327,-1298.576904,-0.001418,0.004683,0.118940,288.277374,14.685551,1.189396,-1298.576904,294.500458,0.000000
137.870010,65.360306,-1298.576904,-0.001418,0.004688,0.119070,290.737152,14.810857,1.190698,-1298.576904,294.500458,0.000000
138.280014,65.350616,-1298.576904,-0.001423,0.004688,0.119070,290.694061,14.808661,1.190698,-1298.576904,294.500458,0.000000
138.690002,65.306686,-1298.621338,-0.001423,0.004688,0.119070,290.498657,14.798706,1.190698,-1298.621338,294.500458,0.000000
139.100006,65.243378,-1298.621338,-0.001436,0.004688,0.119070,290.217041,14.784361,1.190698,-1298.621338,294.500458,0.000000
139.510010,65.173004,-1298.665894,-0.001423,0.004678,0.118818,289.903992,14.768414,1.188184,-1298.665894,0.118818,0.000000
139.920013,64.977127,-1298.576904,-0.001423,0.004662,0.118402,289.032684,14.724028,1.184021,-1298.576904,0.118134,0.000000
140.330002,64.914200,-1298.710327,-0.001418,0.004642,0.117909,288.752777,14.709768,1.179086,-1298.710327,0.117448,0.000000
140.740005,64.789093,-1298.621338,-0.001393,0.004615,0.117214,288.196289,14.681417,1.172137,-1298.621338,0.116772,0.000000
141.150009,64.657272,-1298.665894,-0.001393,0.004591,0.116607,287.609924,14.651547,1.166066,-1298.665894,0.116087,0.000000
141.560013,64.608490,-1298.576904,-0.001401,0.004567,0.115999,287.392914,14.640493,1.159995,-1298.576904,0.115401,0.000000
141.970001,64.495285,-1298.576904,-0.001380,0.004538,0.115255,286.889343,14.614841,1.152546,-1298.576904,0.114717,0.000000
142.380005,64.423050,-1298.576904,-0.001371,0.004511,0.114587,286.568024,14.598472,1.145869,-1298.576904,0.114031,0.000000
142.790009,64.270737,-1298.576904,-0.001384,0.004484,0.113901,285.890503,14.563957,1.139011,-1298.576904,0.113355,0.000000
143.200012,64.164612,-1298.710327,-0.001380,0.004458,0.113233,285.418457,14.539909,1.132335,-1298.710327,0.112670,0.000000
143.610001,63.970612,-1298.576904,-0.001393,0.004439,0.112757,284.555481,14.495948,1.127566,-1298.576904,0.111984,0.000000
144.020004,63.234436,-1298.576904,-0.001380,0.004415,0.112133,281.280823,14.329128,1.121328,-1298.576904,0.111300,0.000000
144.430008,61.934479,-1298.665894,-0.001388,0.004384,0.111343,275.498322,14.034554,1.113425,-1298.665894,0.110614,0.000000
144.840012,60.480736,-1298.710327,-0.001362,0.004359,0.110728,269.031738,13.705131,1.107279,-1298.710327,0.109938,0.000000
145.250000,59.040398,-1298.665894,-0.001341,0.004341,0.110251,262.624817,13.378746,1.102510,-1298.665894,0.109253,0.000000
145.660004,56.996819,-1298.621338,-0.001358,0.004313,0.109539,253.534515,12.915664,1.095394,-1298.621338,0.108567,0.000000
146.070007,54.341431,-1298.621338,-0.001332,0.004284,0.108811,241.722763,12.313944,1.088112,-1298.621338,0.107883,0.000000
146.480011,51.982452,-1298.621338,-0.001332,0.004261,0.108230,231.229492,11.779391,1.082298,-1298.621338,0.107197,0.000000
146.889999,48.952087,-1298.576904,-0.001328,0.004232,0.107493,217.749756,11.092702,1.074925,-1298.576904,0.106521,0.000000
147.300003,46.440804,-1298.665894,-0.001324,0.004206,0.106842,206.579010,10.523637,1.068415,-1298.665894,0.105836,0.000000
147.710007,43.809250,-1298.621338,-0.001328,0.004188,0.106383,194.873276,9.927318,1.063828,-1298.621338,0.105150,0.000000
148.120010,40.691750,-1298.710327,-0.001350,0.004160,0.105655,181.005936,9.220882,1.056546,-1298.710327,0.104466,0.000000
148.530014,37.479660,-1298.621338,-0.001345,0.004130,0.104892,166.717850,8.493011,1.048916,-1298.621338,0.103780,0.000000
148.940002,34.699532,-1298.621338,-0.001332,0.004106,0.104292,154.351227,7.863026,1.042920,-1298.621338,0.103105,0.000000
149.350006,31.313171,-1298.576904,-0.001328,0.004076,0.103538,139.287949,7.095666,1.035381,-1298.576904,0.102419,0.000000
149.760010,29.956993,-1298.621338,-0.001345,0.004058,0.103078,133.255356,6.788352,1.030778,-1298.621338,0.101735,0.000000
150.170013,25.574173,-1298.665894,-0.001328,0.004025,0.102228,113.759605,5.795190,1.022285,-1298.665894,0.101049,0.000000
150.580002,22.760147,-1298.665894,-0.001350,0.003996,0.101509,101.242187,5.157523,1.015094,-1298.665894,0.100363,0.000000
150.990005,19.722336,-1298.621338,-0.001328,0.003971,0.100875,87.729332,4.469145,1.008750,-1298.621338,0.099688,0.000000
151.400009,16.585846,-1298.710327,-0.001341,0.003941,0.100112,73.777527,3.758406,1.001120,-1298.710327,0.099002,0.000000
151.810013,13.637772,-1298.576904,-0.001345,0.003917,0.099488,60.663837,3.090363,0.994882,-1298.576904,0.098318,0.000000
152.220001,10.870674,-1298.621338,-0.001328,0.003892,0.098855,48.355175,2.463330,0.988554,-1298.621338,0.097632,0.000000
152.630005,7.403137,-1298.710327,-0.001345,0.003859,0.098014,32.930798,1.677575,0.980136,-1298.710327,0.096948,0.000000
153.040009,5.466057,-1298.665894,-0.001319,0.003838,0.097485,24.314236,1.238626,0.974853,-1298.665894,0.096262,0.000000
153.450012,2.265884,-1298.710327,-0.001345,0.003806,0.096678,10.079157,0.513457,0.966783,-1298.710327,0.095585,0.000000
153.860001,0.481476,-1298.665894,-0.001345,0.003778,0.095959,2.141711,0.109104,0.959592,-1298.665894,0.094901,0.000000
154.270004,-0.781982,-1298.710327,-0.001345,0.003768,0.095715,-3.478431,-0.177200,0.957155,-1298.710327,0.094215,0.000000
154.680008,-4.507568,-1298.621338,-0.001332,0.003725,0.094606,-20.050665,-1.021430,0.946057,-1298.621338,0.093531,0.000000
155.090012,-0.395088,-1298.710327,-0.001306,0.003706,0.094129,-1.757440,-0.089528,0.941288,-1298.710327,0.092845,0.000000
155.500000,-0.313538,-1298.799316,-0.001311,0.003674,0.093331,-1.394685,-0.071049,0.933310,-1298.799316,0.092168,0.000000
155.910004,-0.071121,-1298.710327,-0.001319,0.003652,0.092759,-0.316363,-0.016116,0.927587,-1298.710327,0.091484,0.000000
156.320007,-0.237572,-1298.665894,-0.001306,0.003616,0.091856,-1.056772,-0.053835,0.918564,-1298.665894,0.090798,0.000000
156.730011,-0.101288,-1298.710327,-0.001319,0.003590,0.091198,-0.450551,-0.022952,0.911978,-1298.710327,0.090114,0.000000
157.140015,-0.045059,-1298.665894,-0.001311,0.003567,0.090591,-0.200433,-0.010211,0.905907,-1298.665894,0.089428,0.000000
157.550003,-0.052879,-1298.843750,-0.001319,0.003544,0.090026,-0.235219,-0.011983,0.900260,-1298.843750,0.088751,0.000000
157.960007,-0.072983,-1298.710327,-0.001302,0.003512,0.089211,-0.324644,-0.016538,0.892115,-1298.710327,0.088067,0.000000
158.370010,-0.122139,-1298.754761,-0.001328,0.003485,0.088526,-0.543301,-0.027677,0.885257,-1298.754761,0.087381,0.000000
158.780014,-0.099052,-1298.754761,-0.001332,0.003457,0.087816,-0.440607,-0.022446,0.878156,-1298.754761,0.086697,0.000000
159.190002,-0.095329,-1298.754761,-0.001311,0.003434,0.087218,-0.424046,-0.021602,0.872176,-1298.754761,0.086011,0.000000
159.600006,-0.124741,-1298.754761,-0.001328,0.003403,0.086427,-0.554874,-0.028267,0.864273,-1298.754761,0.085334,0.000000
160.010010,-0.115059,-1298.710327,-0.001319,0.003379,0.085820,-0.511808,-0.026073,0.858202,-1298.710327,0.084650,0.000000
160.420013,-0.166077,-1298.710327,-0.001328,0.003344,0.084927,-0.738746,-0.037634,0.849270,-1298.710327,0.083964,0.000000
160.830002,-0.183952,-1298.710327,-0.001328,0.003319,0.084303,-0.818261,-0.041684,0.843032,-1298.710327,0.083280,0.000000
161.240005,-0.186928,-1298.754761,-0.001332,0.003294,0.083678,-0.831496,-0.042358,0.836780,-1298.754761,0.082594,0.000000
161.650009,-0.178741,-1298.754761,-0.001345,0.003267,0.082994,-0.795082,-0.040503,0.829937,-1298.754761,0.081919,0.000000
162.060013,-0.191399,-1298.665894,-0.001350,0.003238,0.082247,-0.851384,-0.043372,0.822473,-1298.665894,0.081233,0.000000
162.470001,-0.182091,-1298.754761,-0.001358,0.003209,0.081502,-0.809980,-0.041262,0.815024,-1298.754761,0.080549,0.000000
162.880005,-0.187302,-1298.665894,-0.001380,0.003179,0.080747,-0.833159,-0.042443,0.807469,-1298.665894,0.079863,0.000000
163.290009,-0.164589,-1298.754761,-0.001388,0.003161,0.080279,-0.732128,-0.037296,0.802791,-1298.754761,0.079177,0.000000
163.700012,-0.184326,-1298.754761,-0.001436,0.003127,0.079430,-0.819924,-0.041769,0.794298,-1298.754761,0.078502,0.000000
164.110001,-0.229378,-1298.710327,-0.001449,0.003103,0.078814,-1.020323,-0.051978,0.788136,-1298.710327,0.077816,0.000000
164.520004,-0.232361,-1298.799316,-0.001470,0.003079,0.078216,-1.033593,-0.052654,0.782156,-1298.799316,0.077132,0.000000
164.930008,-0.220070,-1298.710327,-0.001509,0.003046,0.077365,-0.978920,-0.049869,0.773648,-1298.710327,0.076446,0.000000
165.340012,-0.210762,-1298.710327,-0.001539,0.003020,0.076706,-0.937516,-0.047759,0.767062,-1298.710327,0.075761,0.000000
165.750015,-0.231613,-1298.754761,-0.001565,0.002996,0.076090,-1.030267,-0.052484,0.760900,-1298.754761,0.075085,0.000000
166.160004,-0.249863,-1298.710327,-0.001604,0.002967,0.075371,-1.111445,-0.056620,0.753709,-1298.710327,0.074399,0.000000
166.570007,-0.232361,-1298.843750,-0.001630,0.002942,0.074729,-1.033593,-0.052654,0.747290,-1298.843750,0.073715,0.000000
166.980011,-0.217461,-1298.710327,-0.001656,0.002917,0.074087,-0.967313,-0.049277,0.740870,-1298.710327,0.073029,0.000000
167.100006,-0.169060,-1298.710327,-0.001664,0.002919,0.074148,-0.752015,-0.038309,0.741476,-1298.710327,0.074017,0.000000