File: Data/compression 28/AutoNoHeating-17-28-reverse-1-4_10222024_183045.csv
Time (sec),S:Load (lbs),S:HL1 (DIM),S:LVDT (in),S:Position (in),Ch:Position (mm),Ch:Load (N),Ch:Stress (MPa),Ch:Strain (mm/mm),Ch:HL1 (DIM),Set Point (),Cycles ()
0.110000,-0.074844,-1299.555420,-0.009033,-0.003912,-0.099375,-0.332924,-0.016960,-0.993747,-1299.555420,-0.099158,0.000000
0.510000,-0.117668,-1299.555420,-0.009020,-0.003819,-0.096990,-0.523414,-0.026664,-0.969902,-1299.555420,-0.096055,0.000000
0.910000,-0.109474,-1299.555420,-0.008852,-0.003568,-0.090616,-0.486965,-0.024807,-0.906164,-1299.555420,-0.089393,0.000000
1.310000,-0.078941,-1299.555420,-0.008606,-0.003313,-0.084138,-0.351149,-0.017888,-0.841382,-1299.555420,-0.082733,0.000000
1.710000,-0.065536,-1299.510986,-0.008338,-0.003048,-0.077418,-0.291521,-0.014851,-0.774178,-1299.510986,-0.076073,0.000000
2.110000,-0.088997,-1299.599976,-0.008084,-0.002792,-0.070912,-0.395878,-0.020167,-0.709123,-1299.599976,-0.069412,0.000000
2.510000,-0.064423,-1299.555420,-0.007817,-0.002525,-0.064131,-0.286566,-0.014598,-0.641313,-1299.555420,-0.062735,0.000000
2.910000,-0.083038,-1299.510986,-0.007532,-0.002257,-0.057315,-0.369373,-0.018817,-0.573154,-1299.510986,-0.056075,0.000000
3.310000,-0.009308,-1299.644409,-0.007248,-0.001993,-0.050628,-0.041403,-0.002109,-0.506283,-1299.644409,-0.049414,0.000000
3.710000,-0.002235,-1299.510986,-0.006980,-0.001732,-0.043994,-0.009944,-0.000507,-0.439941,-1299.510986,-0.042754,0.000000
4.110000,-0.037979,-1299.599976,-0.006709,-0.001474,-0.037439,-0.168940,-0.008606,-0.374387,-1299.599976,-0.036094,0.000000
4.510000,-0.049149,-1299.555420,-0.006454,-0.001211,-0.030770,-0.218624,-0.011137,-0.307697,-1299.555420,-0.029416,0.000000
4.910000,-0.082291,-1299.510986,-0.006200,-0.000946,-0.024031,-0.366047,-0.018647,-0.240311,-1299.510986,-0.022756,0.000000
5.310000,-0.010056,-1299.599976,-0.005946,-0.000680,-0.017267,-0.044729,-0.002279,-0.172667,-1299.599976,-0.016095,0.000000
5.710000,0.016754,-1299.555420,-0.005674,-0.000417,-0.010580,0.074526,0.003797,-0.105795,-1299.555420,-0.009435,0.000000
6.110000,0.000748,-1299.555420,-0.005420,-0.000157,-0.003989,0.003326,0.000169,-0.039893,-1299.555420,-0.002775,0.000000
6.510000,0.024208,-1299.644409,-0.005221,-0.000002,-0.000044,0.107683,0.005486,-0.000439,-1299.644409,0.000191,0.000000
6.910000,0.014153,-1299.599976,-0.005221,-0.000002,-0.000044,0.062954,0.003207,-0.000439,-1299.599976,0.000191,0.000000
7.310000,0.109848,-1299.599976,-0.005217,-0.000001,-0.000035,0.488628,0.024892,-0.000348,-1299.599976,0.000833,0.000000
7.710001,0.078575,-1299.555420,-0.005208,-0.000001,-0.000035,0.349520,0.017805,-0.000348,-1299.555420,0.001500,0.000000
8.110001,0.299019,-1299.510986,-0.005213,0.000041,0.001031,1.330102,0.067759,0.010310,-1299.510986,0.002159,0.000000
8.510000,0.471054,-1299.644409,-0.005182,0.000070,0.001777,2.095353,0.106742,0.017774,-1299.644409,0.002827,0.000000
8.910001,0.770439,-1299.599976,-0.005174,0.000099,0.002506,3.427084,0.174584,0.025056,-1299.599976,0.003494,0.000000
9.310000,1.033707,-1299.644409,-0.005148,0.000119,0.003017,4.598157,0.234241,0.030173,-1299.644409,0.004162,0.000000
9.710000,1.580719,-1299.555420,-0.005122,0.000150,0.003815,7.031389,0.358196,0.038152,-1299.555420,0.004830,0.000000
10.110001,1.962029,-1299.599976,-0.005113,0.000171,0.004353,8.727539,0.444602,0.043526,-1299.599976,0.005497,0.000000
10.510000,2.753693,-1299.555420,-0.005083,0.000207,0.005264,12.249037,0.623996,0.052640,-1299.555420,0.006165,0.000000
10.910001,3.034088,-1299.555420,-0.005049,0.000228,0.005801,13.496298,0.687534,0.058015,-1299.555420,0.006832,0.000000
11.310000,3.631004,-1299.644409,-0.005049,0.000252,0.006390,16.151514,0.822797,0.063904,-1299.644409,0.007502,0.000000
11.710001,4.473312,-1299.599976,-0.005014,0.000281,0.007128,19.898287,1.013667,0.071277,-1299.599976,0.008160,0.000000
12.110001,4.935799,-1299.599976,-0.004993,0.000302,0.007665,21.955528,1.118468,0.076652,-1299.599976,0.008828,0.000000
12.510000,6.067062,-1299.555420,-0.004971,0.000339,0.008602,26.987640,1.374816,0.086023,-1299.555420,0.009496,0.000000
12.910001,6.321396,-1299.644409,-0.004945,0.000358,0.009105,28.118973,1.432449,0.091049,-1299.644409,0.010163,0.000000
13.310000,7.201309,-1299.510986,-0.004928,0.000388,0.009851,32.033024,1.631840,0.098513,-1299.510986,0.010831,0.000000
13.710001,7.634010,-1299.599976,-0.004902,0.000410,0.010407,33.957775,1.729891,0.104069,-1299.599976,0.011499,0.000000
14.110001,8.105804,-1299.644409,-0.004889,0.000431,0.010944,36.056419,1.836802,0.109444,-1299.644409,0.012166,0.000000
14.510000,9.035988,-1299.599976,-0.004850,0.000468,0.011880,40.194080,2.047584,0.118800,-1299.599976,0.012834,0.000000
14.910001,9.254204,-1299.644409,-0.004833,0.000488,0.012392,41.164753,2.097033,0.123917,-1299.644409,0.013494,0.000000
15.310000,9.569603,-1299.599976,-0.004816,0.000510,0.012956,42.567719,2.168503,0.129565,-1299.599976,0.014162,0.000000
15.710001,10.343765,-1299.599976,-0.004781,0.000539,0.013685,46.011364,2.343931,0.136847,-1299.599976,0.014829,0.000000
16.110001,11.139526,-1299.599976,-0.004760,0.000574,0.014578,49.551086,2.524253,0.145779,-1299.599976,0.015497,0.000000
16.510000,11.217346,-1299.599976,-0.004730,0.000600,0.015236,49.897247,2.541887,0.152365,-1299.599976,0.016165,0.000000
16.910002,11.396835,-1299.555420,-0.004717,0.000622,0.015809,50.695656,2.582560,0.158087,-1299.555420,0.016832,0.000000
17.310001,11.975128,-1299.644409,-0.004704,0.000652,0.016555,53.268032,2.713603,0.165551,-1299.644409,0.017500,0.000000
17.710001,11.721916,-1299.644409,-0.004652,0.000667,0.016946,52.141689,2.656224,0.169457,-1299.644409,0.018167,0.000000
18.110001,12.553795,-1299.599976,-0.004652,0.000704,0.017890,55.842068,2.844731,0.178904,-1299.599976,0.018828,0.000000
18.510000,12.343033,-1299.644409,-0.004613,0.000727,0.018454,54.904552,2.796971,0.184536,-1299.644409,0.019495,0.000000
18.910002,12.426071,-1299.644409,-0.004583,0.000749,0.019026,55.273926,2.815788,0.190259,-1299.644409,0.020163,0.000000
19.310001,12.718384,-1299.599976,-0.004575,0.000780,0.019816,56.574196,2.882027,0.198162,-1299.599976,0.020831,0.000000
19.710001,12.881851,-1299.599976,-0.004531,0.000804,0.020414,57.301334,2.919069,0.204142,-1299.599976,0.021498,0.000000
20.110001,13.456429,-1299.555420,-0.004506,0.000835,0.021221,59.857185,3.049270,0.212211,-1299.555420,0.022166,0.000000
20.510000,13.014046,-1299.644409,-0.004480,0.000856,0.021733,57.889366,2.949025,0.217329,-1299.644409,0.022834,0.000000
20.910002,13.144379,-1299.599976,-0.004458,0.000882,0.022401,58.469116,2.978559,0.224005,-1299.599976,0.023501,0.000000
21.310001,13.487701,-1299.644409,-0.004432,0.000914,0.023206,59.996292,3.056357,0.232059,-1299.644409,0.024160,0.000000
21.710001,13.307106,-1299.644409,-0.004415,0.000934,0.023736,59.192963,3.015433,0.237358,-1299.644409,0.024829,0.000000
22.110001,13.768845,-1299.599976,-0.004368,0.000968,0.024576,61.246880,3.120065,0.245761,-1299.599976,0.025497,0.000000
22.510000,13.483978,-1299.599976,-0.004333,0.000989,0.025132,59.979733,3.055513,0.251317,-1299.599976,0.026164,0.000000
22.910002,13.551750,-1299.644409,-0.004324,0.001017,0.025834,60.281197,3.070870,0.258342,-1299.644409,0.026832,0.000000
23.310001,13.945351,-1299.644409,-0.004294,0.001044,0.026520,62.032017,3.160062,0.265200,-1299.644409,0.027500,0.000000
23.710001,13.782249,-1299.644409,-0.004273,0.001066,0.027065,61.306507,3.123102,0.270650,-1299.644409,0.028167,0.000000
24.110001,14.101746,-1299.644409,-0.004247,0.001095,0.027802,62.727695,3.195501,0.278023,-1299.644409,0.028835,0.000000
24.510000,13.993759,-1299.599976,-0.004204,0.001119,0.028419,62.247349,3.171031,0.284185,-1299.599976,0.029502,0.000000
24.910002,14.038445,-1299.555420,-0.004178,0.001142,0.029000,62.446121,3.181157,0.289999,-1299.555420,0.030161,0.000000
25.310001,14.363525,-1299.599976,-0.004156,0.001174,0.029823,63.892151,3.254822,0.298235,-1299.599976,0.030829,0.000000
25.710001,14.070465,-1299.644409,-0.004139,0.001193,0.030309,62.588554,3.188413,0.303094,-1299.644409,0.031498,0.000000
26.110001,14.578384,-1299.644409,-0.004092,0.001225,0.031115,64.847893,3.303509,0.311149,-1299.644409,0.032166,0.000000
26.510002,14.509125,-1299.599976,-0.004079,0.001249,0.031731,64.539810,3.287815,0.317310,-1299.599976,0.032833,0.000000
26.910002,14.459969,-1299.688965,-0.004049,0.001271,0.032287,64.321152,3.276676,0.322867,-1299.688965,0.033501,0.000000
27.310001,14.712067,-1299.644409,-0.004010,0.001302,0.033075,65.442543,3.333802,0.330754,-1299.644409,0.034169,0.000000
27.710001,14.364265,-1299.599976,-0.004001,0.001320,0.033536,63.895443,3.254989,0.335357,-1299.599976,0.034836,0.000000
28.110001,14.845001,-1299.644409,-0.003984,0.001352,0.034350,66.033867,3.363925,0.343502,-1299.644409,0.035495,0.000000
28.510002,14.935860,-1299.644409,-0.003945,0.001381,0.035087,66.438019,3.384514,0.350875,-1299.644409,0.036162,0.000000
28.910002,15.083321,-1299.644409,-0.003919,0.001406,0.035720,67.093964,3.417929,0.357203,-1299.644409,0.036830,0.000000
29.310001,15.038635,-1299.688965,-0.003893,0.001428,0.036276,66.895187,3.407803,0.362759,-1299.688965,0.037498,0.000000
29.710001,15.250145,-1299.644409,-0.003876,0.001455,0.036953,67.836029,3.455732,0.369527,-1299.644409,0.038165,0.000000
30.110001,15.648209,-1299.644409,-0.003854,0.001487,0.037767,69.606705,3.545935,0.377672,-1299.644409,0.038835,0.000000
30.510002,15.427391,-1299.599976,-0.003824,0.001511,0.038374,68.624466,3.495897,0.383743,-1299.599976,0.039502,0.000000
30.910002,15.300041,-1299.644409,-0.003811,0.001533,0.038937,68.057983,3.467039,0.389375,-1299.644409,0.040170,0.000000
31.310001,15.628471,-1299.644409,-0.003781,0.001564,0.039728,69.518913,3.541462,0.397278,-1299.644409,0.040828,0.000000
31.710001,15.470589,-1299.688965,-0.003751,0.001582,0.040177,68.816612,3.505685,0.401774,-1299.688965,0.041496,0.000000
32.110001,16.054466,-1299.599976,-0.003725,0.001620,0.041140,71.413834,3.637994,0.411403,-1299.599976,0.042164,0.000000
32.510002,15.869026,-1299.688965,-0.003691,0.001642,0.041705,70.588951,3.595973,0.417050,-1299.688965,0.042831,0.000000
32.910000,16.333000,-1299.644409,-0.003673,0.001675,0.042545,72.652817,3.701111,0.425452,-1299.644409,0.043499,0.000000
33.310001,16.185173,-1299.688965,-0.003656,0.001697,0.043101,71.995247,3.667613,0.431009,-1299.688965,0.044167,0.000000
33.710003,16.554192,-1299.644409,-0.003617,0.001726,0.043846,73.636719,3.751233,0.438457,-1299.644409,0.044834,0.000000
34.110001,16.363907,-1299.688965,-0.003596,0.001750,0.044462,72.790291,3.708114,0.444619,-1299.688965,0.045504,0.000000
34.510002,16.504669,-1299.733398,-0.003570,0.001776,0.045113,73.416435,3.740011,0.451129,-1299.733398,0.046162,0.000000
34.910000,16.614517,-1299.688965,-0.003553,0.001801,0.045737,73.905067,3.764903,0.457367,-1299.688965,0.046830,0.000000
35.310001,16.831238,-1299.644409,-0.003531,0.001827,0.046413,74.869087,3.814013,0.464134,-1299.644409,0.047497,0.000000
35.710003,17.304146,-1299.688965,-0.003492,0.001858,0.047202,76.972687,3.921175,0.472022,-1299.688965,0.048165,0.000000
36.110001,17.016678,-1299.688965,-0.003454,0.001880,0.047749,75.693962,3.856034,0.477487,-1299.688965,0.048833,0.000000
36.510002,16.704254,-1299.688965,-0.003441,0.001901,0.048279,74.304230,3.785238,0.482786,-1299.688965,0.049500,0.000000
36.910000,17.349579,-1299.733398,-0.003406,0.001934,0.049119,77.174782,3.931471,0.491189,-1299.733398,0.050168,0.000000
37.310001,18.032883,-1299.644409,-0.003393,0.001965,0.049900,80.214272,4.086309,0.499001,-1299.644409,0.050836,0.000000
37.710003,17.994530,-1299.644409,-0.003346,0.001993,0.050619,80.043663,4.077619,0.506192,-1299.644409,0.051496,0.000000
38.110001,17.498154,-1299.688965,-0.003341,0.002013,0.051140,77.835678,3.965138,0.511400,-1299.688965,0.052163,0.000000
38.510002,17.322021,-1299.777832,-0.003311,0.002033,0.051626,77.052200,3.925226,0.516260,-1299.777832,0.052831,0.000000
38.910004,17.884682,-1299.733398,-0.003277,0.002064,0.052424,79.555038,4.052727,0.524238,-1299.733398,0.053499,0.000000
39.310001,18.146454,-1299.688965,-0.003268,0.002091,0.053108,80.719460,4.112045,0.531081,-1299.688965,0.054166,0.000000
39.710003,18.384773,-1299.777832,-0.003238,0.002118,0.053785,81.779556,4.166049,0.537849,-1299.777832,0.054834,0.000000
40.110001,18.434669,-1299.733398,-0.003208,0.002143,0.054427,82.001503,4.177356,0.544268,-1299.733398,0.055502,0.000000
40.510002,18.875931,-1299.733398,-0.003208,0.002171,0.055146,83.964333,4.277347,0.551459,-1299.733398,0.056169,0.000000
40.910004,18.595909,-1299.733398,-0.003165,0.002191,0.055658,82.718735,4.213893,0.556576,-1299.733398,0.056837,0.000000
41.310001,18.551971,-1299.733398,-0.003139,0.002218,0.056343,82.523293,4.203937,0.563435,-1299.733398,0.057497,0.000000
41.710003,19.105316,-1299.733398,-0.003109,0.002250,0.057141,84.984688,4.329327,0.571413,-1299.733398,0.058165,0.000000
42.110001,19.296715,-1299.777832,-0.003083,0.002273,0.057730,85.836075,4.372698,0.577302,-1299.777832,0.058832,0.000000
42.510002,20.012039,-1299.733398,-0.003074,0.002307,0.058598,89.017998,4.534793,0.585977,-1299.733398,0.059500,0.000000
42.910004,19.622169,-1299.688965,-0.003044,0.002329,0.059153,87.283768,4.446447,0.591534,-1299.688965,0.060168,0.000000
43.310001,20.513252,-1299.733398,-0.003027,0.002358,0.059882,91.247505,4.648369,0.598816,-1299.733398,0.060835,0.000000
43.710003,20.173279,-1299.733398,-0.003001,0.002382,0.060498,89.735229,4.571330,0.604978,-1299.733398,0.061503,0.000000
44.110001,20.303986,-1299.777832,-0.002962,0.002406,0.061105,90.316635,4.600949,0.611049,-1299.777832,0.062171,0.000000
44.510002,20.013901,-1299.733398,-0.002936,0.002424,0.061582,89.026276,4.535215,0.615818,-1299.733398,0.062829,0.000000
44.910004,20.989517,-1299.777832,-0.002915,0.002460,0.062483,93.366035,4.756292,0.624826,-1299.777832,0.063498,0.000000
45.310001,21.529457,-1299.733398,-0.002884,0.002489,0.063212,95.767807,4.878645,0.632123,-1299.733398,0.064166,0.000000
45.710003,20.980583,-1299.777832,-0.002867,0.002510,0.063750,93.326294,4.754268,0.637497,-1299.777832,0.064834,0.000000
46.110001,21.140701,-1299.733398,-0.002850,0.002536,0.064408,94.038536,4.790551,0.644083,-1299.733398,0.065501,0.000000
46.510002,22.061951,-1299.688965,-0.002828,0.002569,0.065250,98.136459,4.999309,0.652501,-1299.688965,0.066169,0.000000
46.910004,21.676178,-1299.777832,-0.002790,0.002586,0.065683,96.420456,4.911892,0.656831,-1299.777832,0.066837,0.000000
47.310001,22.728127,-1299.688965,-0.002777,0.002619,0.066516,101.099754,5.150267,0.665157,-1299.688965,0.067504,0.000000
47.710003,22.529655,-1299.733398,-0.002742,0.002642,0.067097,100.216911,5.105293,0.670971,-1299.733398,0.068163,0.000000
48.110001,22.372513,-1299.777832,-0.002734,0.002661,0.067600,99.517906,5.069684,0.675997,-1299.777832,0.068831,0.000000
48.510002,23.587189,-1299.777832,-0.002708,0.002697,0.068510,104.921059,5.344934,0.685096,-1299.777832,0.069498,0.000000
48.910004,23.341797,-1299.777832,-0.002682,0.002717,0.069021,103.829498,5.289327,0.690213,-1299.777832,0.070167,0.000000
49.310001,24.075371,-1299.733398,-0.002656,0.002747,0.069777,107.092598,5.455557,0.697768,-1299.733398,0.070835,0.000000
49.710003,24.425774,-1299.777832,-0.002626,0.002774,0.070454,108.651268,5.534960,0.704535,-1299.777832,0.071503,0.000000
50.110001,24.248520,-1299.777832,-0.002626,0.002796,0.071017,107.862801,5.494793,0.710167,-1299.777832,0.072170,0.000000
50.510002,25.113914,-1299.777832,-0.002596,0.002824,0.071728,111.712273,5.690895,0.717283,-1299.777832,0.072838,0.000000
50.910004,25.045776,-1299.822388,-0.002578,0.002845,0.072275,111.409180,5.675454,0.722748,-1299.822388,0.073497,0.000000
51.310001,26.186722,-1299.777832,-0.002557,0.002880,0.073141,116.484360,5.933996,0.731408,-1299.777832,0.074164,0.000000
51.710003,26.195656,-1299.777832,-0.002527,0.002902,0.073706,116.524094,5.936020,0.737055,-1299.777832,0.074832,0.000000
52.110001,26.509193,-1299.777832,-0.002501,0.002925,0.074285,117.918785,6.007069,0.742854,-1299.777832,0.075500,0.000000
52.510002,27.175369,-1299.822388,-0.002488,0.002953,0.075006,120.882080,6.158027,0.750060,-1299.822388,0.076167,0.000000
52.910004,27.535828,-1299.777832,-0.002471,0.002977,0.075622,122.485481,6.239708,0.756222,-1299.777832,0.076836,0.000000
53.310001,29.094948,-1299.777832,-0.002453,0.003014,0.076550,129.420792,6.593009,0.765503,-1299.777832,0.077504,0.000000
53.710003,28.803757,-1299.777832,-0.002419,0.003033,0.077044,128.125504,6.527024,0.770438,-1299.777832,0.078172,0.000000
54.110004,29.411095,-1299.733398,-0.002402,0.003061,0.077737,130.827087,6.664649,0.777372,-1299.733398,0.078839,0.000000
54.510002,29.766342,-1299.733398,-0.002371,0.003084,0.078328,132.407303,6.745150,0.783276,-1299.733398,0.079498,0.000000
54.910004,30.768021,-1299.777832,-0.002363,0.003114,0.079091,136.862991,6.972133,0.790907,-1299.777832,0.080166,0.000000
55.310001,31.753693,-1299.777832,-0.002337,0.003144,0.079863,141.247482,7.195490,0.798628,-1299.777832,0.080833,0.000000
55.710003,31.403290,-1299.822388,-0.002307,0.003161,0.080296,139.688812,7.116087,0.802958,-1299.822388,0.081501,0.000000
56.110004,32.597862,-1299.733398,-0.002294,0.003191,0.081059,145.002533,7.386781,0.810588,-1299.733398,0.082169,0.000000
56.510002,33.357124,-1299.777832,-0.002276,0.003218,0.081745,148.379898,7.558832,0.817446,-1299.777832,0.082836,0.000000
56.910004,34.027771,-1299.822388,-0.002251,0.003243,0.082368,151.363083,7.710803,0.823684,-1299.822388,0.083505,0.000000
57.310001,34.601219,-1299.822388,-0.002233,0.003266,0.082959,153.913910,7.840748,0.829588,-1299.822388,0.084173,0.000000
57.710003,35.321022,-1299.777832,-0.002212,0.003293,0.083643,157.115753,8.003859,0.836432,-1299.777832,0.084832,0.000000
58.110004,36.276527,-1299.822388,-0.002177,0.003321,0.084364,161.366058,8.220379,0.843638,-1299.822388,0.085499,0.000000
58.510002,37.428276,-1299.822388,-0.002164,0.003350,0.085101,166.489288,8.481369,0.851011,-1299.822388,0.086167,0.000000
58.910004,39.442810,-1299.777832,-0.002147,0.003387,0.086028,175.450378,8.937869,0.860276,-1299.777832,0.086835,0.000000
59.310001,39.250290,-1299.777832,-0.002121,0.003402,0.086402,174.594009,8.894242,0.864016,-1299.777832,0.087502,0.000000
59.710003,39.969719,-1299.822388,-0.002091,0.003428,0.087069,177.794189,9.057268,0.870692,-1299.822388,0.088170,0.000000
60.110004,41.698639,-1299.822388,-0.002078,0.003459,0.087867,185.484802,9.449047,0.878671,-1299.822388,0.088838,0.000000
60.510002,41.811096,-1299.777832,-0.002074,0.003476,0.088291,185.985046,9.474530,0.882910,-1299.777832,0.089505,0.000000
60.910004,43.608543,-1299.866821,-0.002039,0.003513,0.089219,193.980484,9.881838,0.892191,-1299.866821,0.090165,0.000000
61.310001,44.152946,-1299.866821,-0.002018,0.003534,0.089766,196.402115,10.005200,0.897656,-1299.866821,0.090833,0.000000
61.710003,44.712624,-1299.822388,-0.002009,0.003553,0.090235,198.891678,10.132025,0.902349,-1299.822388,0.091501,0.000000
62.110004,46.791580,-1299.822388,-0.001988,0.003588,0.091128,208.139343,10.603124,0.911282,-1299.822388,0.092168,0.000000
62.510002,47.237312,-1299.822388,-0.001970,0.003607,0.091622,210.122055,10.704128,0.916217,-1299.822388,0.092836,0.000000
62.910004,48.851913,-1299.866821,-0.001957,0.003637,0.092385,217.304169,11.070002,0.923847,-1299.866821,0.093504,0.000000
63.310001,49.807053,-1299.822388,-0.001944,0.003663,0.093045,221.552841,11.286440,0.930448,-1299.822388,0.094171,0.000000
63.710003,51.666306,-1299.822388,-0.001927,0.003696,0.093868,229.823212,11.707752,0.938684,-1299.822388,0.094839,0.000000
64.110001,52.636337,-1299.777832,-0.001906,0.003717,0.094423,234.138123,11.927565,0.944225,-1299.777832,0.095499,0.000000
64.510002,53.176277,-1299.866821,-0.001888,0.003736,0.094899,236.539902,12.049916,0.948994,-1299.866821,0.096167,0.000000
64.910004,55.269753,-1299.866821,-0.001880,0.003769,0.095732,245.852142,12.524304,0.957321,-1299.866821,0.096834,0.000000
65.310005,56.342186,-1299.822388,-0.001854,0.003796,0.096418,250.622559,12.767322,0.964179,-1299.822388,0.097502,0.000000
65.710007,57.996643,-1299.777832,-0.001845,0.003822,0.097067,257.981964,13.142227,0.970674,-1299.777832,0.098170,0.000000
66.110001,59.188232,-1299.822388,-0.001828,0.003844,0.097649,263.282410,13.412245,0.976488,-1299.822388,0.098837,0.000000
66.510002,60.329178,-1299.777832,-0.001819,0.003867,0.098230,268.357574,13.670788,0.982301,-1299.777832,0.099505,0.000000
66.910004,62.429359,-1299.777832,-0.001811,0.003901,0.099079,277.699646,14.146695,0.990795,-1299.777832,0.100173,0.000000
67.310005,63.892792,-1299.822388,-0.001785,0.003926,0.099721,284.209320,14.478313,0.997214,-1299.822388,0.100840,0.000000
67.710007,65.588943,-1299.822388,-0.001781,0.003953,0.100416,291.754181,14.862667,1.004163,-1299.822388,0.101500,0.000000
68.110001,65.323441,-1299.777832,-0.001755,0.003953,0.100407,290.573181,14.802504,1.004072,-1299.777832,0.017631,0.000000
68.510002,66.351929,-1299.733398,-0.001725,0.003927,0.099747,295.148132,15.035563,0.997471,-1299.733398,294.500458,0.000000
68.910004,65.154388,-1299.822388,-0.001729,0.003966,0.100728,289.821198,14.764195,1.007282,-1299.822388,294.500458,0.000000
69.310005,64.965958,-1299.822388,-0.001712,0.003985,0.101222,288.983002,14.721497,1.012217,-1299.822388,294.500458,0.000000
69.710007,64.971924,-1299.733398,-0.001712,0.003996,0.101491,289.009552,14.722848,1.014912,-1299.733398,294.500458,0.000000
70.110001,65.081406,-1299.777832,-0.001707,0.004006,0.101743,289.496552,14.747658,1.017425,-1299.777832,294.500458,0.000000
70.510002,65.430679,-1299.822388,-0.001699,0.004018,0.102054,291.050201,14.826804,1.020544,-1299.822388,294.500458,0.000000
70.910004,64.605499,-1299.777832,-0.001707,0.004018,0.102054,287.379608,14.639815,1.020544,-1299.777832,294.500458,0.000000
71.310005,65.697678,-1299.733398,-0.001699,0.004028,0.102324,292.237854,14.887306,1.023239,-1299.733398,294.500458,0.000000
71.710007,64.793549,-1299.777832,-0.001677,0.004028,0.102324,288.216095,14.682427,1.023239,-1299.777832,294.500458,0.000000
72.110001,65.549469,-1299.733398,-0.001669,0.004042,0.102671,291.578613,14.853722,1.026706,-1299.733398,294.500458,0.000000
72.510002,65.410568,-1299.777832,-0.001669,0.004057,0.103052,290.960754,14.822247,1.030521,-1299.777832,294.500458,0.000000
72.910004,64.914200,-1299.777832,-0.001643,0.004058,0.103078,288.752777,14.709768,1.030778,-1299.777832,294.500458,0.000000
73.310005,65.237427,-1299.777832,-0.001660,0.004068,0.103329,290.190582,14.783012,1.033291,-1299.777832,294.500458,0.000000
73.710007,65.497345,-1299.822388,-0.001634,0.004078,0.103590,291.346741,14.841910,1.035895,-1299.822388,294.500458,0.000000
74.110001,65.149536,-1299.688965,-0.001651,0.004080,0.103641,289.799622,14.763096,1.036410,-1299.688965,294.500458,0.000000
74.510002,65.279495,-1299.777832,-0.001638,0.004088,0.103841,290.377686,14.792545,1.038409,-1299.777832,294.500458,0.000000
74.910004,65.319351,-1299.644409,-0.001625,0.004094,0.103980,290.554993,14.801576,1.039801,-1299.644409,294.500458,0.000000
75.310005,65.212845,-1299.777832,-0.001630,0.004097,0.104076,290.081207,14.777442,1.040755,-1299.777832,294.500458,0.000000
75.710007,65.060547,-1299.688965,-0.001608,0.004101,0.104171,289.403778,14.742930,1.041709,-1299.688965,294.500458,0.000000
76.110001,65.244125,-1299.777832,-0.001613,0.004108,0.104336,290.220367,14.784530,1.043359,-1299.777832,294.500458,0.000000
76.510002,64.993515,-1299.777832,-0.001634,0.004110,0.104396,289.105591,14.727740,1.043965,-1299.777832,294.500458,0.000000
76.910004,65.015854,-1299.688965,-0.001617,0.004116,0.104534,289.204956,14.732802,1.045343,-1299.688965,294.500458,0.000000
77.310005,65.647781,-1299.822388,-0.001608,0.004128,0.104848,292.015930,14.876000,1.048476,-1299.822388,294.500458,0.000000
77.710007,65.466431,-1299.688965,-0.001617,0.004128,0.104839,291.209229,14.834905,1.048386,-1299.688965,294.500458,0.000000
78.110001,65.066132,-1299.733398,-0.001604,0.004128,0.104855,289.428619,14.744196,1.048552,-1299.733398,294.500458,0.000000
78.510002,65.504410,-1299.688965,-0.001587,0.004137,0.105081,291.378174,14.843512,1.050808,-1299.688965,294.500458,0.000000
78.910004,65.141357,-1299.688965,-0.001578,0.004137,0.105081,289.763245,14.761243,1.050808,-1299.688965,294.500458,0.000000
79.310005,65.243378,-1299.733398,-0.001591,0.004143,0.105220,290.217041,14.784361,1.052201,-1299.733398,294.500458,0.000000
79.710007,65.117142,-1299.733398,-0.001578,0.004146,0.105299,289.655518,14.755754,1.052988,-1299.733398,294.500458,0.000000
80.110001,64.997986,-1299.733398,-0.001574,0.004149,0.105376,289.125488,14.728754,1.053760,-1299.733398,294.500458,0.000000
80.510002,65.004318,-1299.688965,-0.001578,0.004152,0.105462,289.153656,14.730189,1.054623,-1299.688965,294.500458,0.000000
80.910004,65.348022,-1299.777832,-0.001565,0.004160,0.105653,290.682526,14.808074,1.056531,-1299.777832,294.500458,0.000000
81.310005,65.127945,-1299.733398,-0.001574,0.004160,0.105653,289.703583,14.758204,1.056531,-1299.733398,294.500458,0.000000
81.710007,65.274292,-1299.733398,-0.001574,0.004165,0.105801,290.354553,14.791366,1.058014,-1299.733398,294.500458,0.000000
82.110001,65.107468,-1299.733398,-0.001565,0.004167,0.105853,289.612488,14.753563,1.058529,-1299.733398,294.500458,0.000000
82.510002,65.166306,-1299.733398,-0.001565,0.004171,0.105939,289.874207,14.766895,1.059392,-1299.733398,294.500458,0.000000
82.910004,65.021439,-1299.688965,-0.001556,0.004173,0.105992,289.229797,14.734068,1.059922,-1299.688965,294.500458,0.000000
83.310005,65.128311,-1299.733398,-0.001561,0.004177,0.106095,289.705200,14.758286,1.060951,-1299.733398,294.500458,0.000000
83.710007,65.023682,-1299.777832,-0.001548,0.004179,0.106157,289.239777,14.734576,1.061572,-1299.777832,294.500458,0.000000
84.110001,64.943253,-1299.777832,-0.001552,0.004181,0.106200,288.882019,14.716352,1.061996,-1299.777832,294.500458,0.000000
84.510002,64.892227,-1299.733398,-0.001556,0.004183,0.106260,288.655029,14.704788,1.062602,-1299.733398,294.500458,0.000000
84.910004,64.949951,-1299.777832,-0.001552,0.004187,0.106356,288.911804,14.717870,1.063555,-1299.777832,294.500458,0.000000
85.310005,65.095917,-1299.688965,-0.001544,0.004192,0.106469,289.561096,14.750946,1.064691,-1299.688965,294.500458,0.000000
85.710007,64.981598,-1299.822388,-0.001535,0.004192,0.106486,289.052582,14.725040,1.064857,-1299.822388,294.500458,0.000000
86.110001,64.844940,-1299.733398,-0.001539,0.004193,0.106504,288.444702,14.694074,1.065039,-1299.733398,294.500458,0.000000
86.510002,65.561020,-1299.733398,-0.001539,0.004202,0.106737,291.629974,14.856339,1.067371,-1299.733398,294.500458,0.000000
86.910004,65.319717,-1299.733398,-0.001526,0.004202,0.106737,290.556610,14.801660,1.067371,-1299.733398,294.500458,0.000000
87.310005,65.109329,-1299.822388,-0.001522,0.004202,0.106737,289.620758,14.753985,1.067371,-1299.822388,294.500458,0.000000
87.710007,64.877716,-1299.822388,-0.001526,0.004202,0.106737,288.590485,14.701500,1.067371,-1299.822388,294.500458,0.000000
88.110001,64.653915,-1299.733398,-0.001518,0.004202,0.106737,287.594971,14.650786,1.067371,-1299.733398,294.500458,0.000000
88.510002,64.397354,-1299.733398,-0.001522,0.004203,0.106746,286.453735,14.592649,1.067461,-1299.733398,294.500458,0.000000
88.910004,66.423050,-1299.822388,-0.001522,0.004173,0.106000,295.464478,15.051679,1.059998,-1299.822388,294.500458,0.000000
89.310005,66.183243,-1299.777832,-0.001496,0.004173,0.106000,294.397766,14.997336,1.059998,-1299.777832,294.500458,0.000000
89.710007,65.854446,-1299.777832,-0.001492,0.004173,0.106000,292.935211,14.922832,1.059998,-1299.777832,294.500458,0.000000
90.110001,65.654846,-1299.777832,-0.001479,0.004174,0.106009,292.047333,14.877601,1.060089,-1299.777832,294.500458,0.000000
90.510002,65.398285,-1299.733398,-0.001483,0.004178,0.106122,290.906097,14.819464,1.061224,-1299.733398,294.500458,0.000000
90.910004,65.152145,-1299.733398,-0.001492,0.004182,0.106234,289.811218,14.763687,1.062344,-1299.733398,294.500458,0.000000
91.310005,64.978256,-1299.733398,-0.001483,0.004194,0.106539,289.037720,14.724283,1.065387,-1299.733398,294.500458,0.000000
91.710007,65.227371,-1299.733398,-0.001483,0.004222,0.107232,290.145844,14.780734,1.072321,-1299.733398,294.500458,0.000000
92.110001,65.116028,-1299.733398,-0.001487,0.004224,0.107284,289.650543,14.755503,1.072836,-1299.733398,294.500458,0.000000
92.510002,65.009903,-1299.733398,-0.001487,0.004224,0.107302,289.178497,14.731455,1.073018,-1299.733398,294.500458,0.000000
92.910004,64.932449,-1299.777832,-0.001500,0.004227,0.107371,288.833954,14.713903,1.073714,-1299.777832,294.500458,0.000000
93.310005,64.837494,-1299.777832,-0.001483,0.004227,0.107371,288.411591,14.692387,1.073714,-1299.777832,294.500458,0.000000
93.710007,65.294769,-1299.733398,-0.001492,0.004235,0.107570,290.445648,14.796006,1.075697,-1299.733398,294.500458,0.000000
94.110008,65.174866,-1299.733398,-0.001483,0.004235,0.107570,289.912292,14.768836,1.075697,-1299.733398,294.500458,0.000000
94.510002,65.030014,-1299.733398,-0.001483,0.004235,0.107570,289.267944,14.736012,1.075697,-1299.733398,294.500458,0.000000
94.910004,64.929840,-1299.777832,-0.001475,0.004241,0.107718,288.822357,14.713312,1.077181,-1299.777832,294.500458,0.000000
95.310005,65.216934,-1299.733398,-0.001492,0.004242,0.107735,290.099426,14.778368,1.077348,-1299.733398,294.500458,0.000000
95.710007,65.072464,-1299.777832,-0.001483,0.004242,0.107735,289.456787,14.745631,1.077348,-1299.777832,294.500458,0.000000
96.110008,64.931335,-1299.777832,-0.001492,0.004242,0.107735,288.829010,14.713651,1.077348,-1299.777832,294.500458,0.000000
96.510002,64.798767,-1299.822388,-0.001483,0.004242,0.107744,288.239319,14.683610,1.077438,-1299.822388,294.500458,0.000000
96.910004,65.331253,-1299.733398,-0.001475,0.004250,0.107951,290.607941,14.804274,1.079513,-1299.733398,294.500458,0.000000
97.310005,65.254547,-1299.733398,-0.001470,0.004250,0.107951,290.266724,14.786892,1.079513,-1299.733398,294.500458,0.000000
97.710007,65.113800,-1299.777832,-0.001479,0.004250,0.107960,289.640656,14.754998,1.079603,-1299.777832,294.500458,0.000000
98.110008,64.966705,-1299.777832,-0.001475,0.004251,0.107969,288.986328,14.721666,1.079694,-1299.777832,294.500458,0.000000
98.510002,64.831161,-1299.733398,-0.001487,0.004251,0.107969,288.383423,14.690951,1.079694,-1299.733398,294.500458,0.000000
98.910004,65.839554,-1299.822388,-0.001483,0.004264,0.108298,292.868958,14.919456,1.082980,-1299.822388,294.500458,0.000000
99.310005,65.834702,-1299.822388,-0.001466,0.004264,0.108298,292.847382,14.918357,1.082980,-1299.822388,294.500458,0.000000
99.710007,65.750549,-1299.777832,-0.001496,0.004264,0.108298,292.473053,14.899287,1.082980,-1299.777832,294.500458,0.000000
100.110008,65.599365,-1299.777832,-0.001475,0.004264,0.108307,291.800537,14.865029,1.083070,-1299.777832,294.500458,0.000000
100.510002,65.473129,-1299.777832,-0.001479,0.004264,0.108307,291.239014,14.836423,1.083070,-1299.777832,294.500458,0.000000
100.910004,65.326797,-1299.733398,-0.001470,0.004264,0.108307,290.588104,14.803264,1.083070,-1299.733398,294.500458,0.000000
101.310005,65.191620,-1299.733398,-0.001466,0.004264,0.108307,289.986816,14.772633,1.083070,-1299.733398,294.500458,0.000000
101.710007,65.036713,-1299.822388,-0.001470,0.004264,0.108307,289.297760,14.737530,1.083070,-1299.822388,294.500458,0.000000
102.110008,65.346161,-1299.777832,-0.001466,0.004271,0.108472,290.674255,14.807652,1.084721,-1299.777832,294.500458,0.000000
102.510002,65.286942,-1299.733398,-0.001470,0.004271,0.108472,290.410828,14.794232,1.084721,-1299.733398,294.500458,0.000000
102.910004,65.207260,-1299.777832,-0.001457,0.004271,0.108472,290.056366,14.776176,1.084721,-1299.777832,294.500458,0.000000
103.310005,65.069855,-1299.777832,-0.001457,0.004271,0.108489,289.445160,14.745040,1.084887,-1299.777832,294.500458,0.000000
103.710007,65.065765,-1299.777832,-0.001462,0.004274,0.108558,289.426971,14.744113,1.085584,-1299.777832,294.500458,0.000000
104.110008,65.061661,-1299.777832,-0.001466,0.004274,0.108567,289.408722,14.743183,1.085674,-1299.777832,294.500458,0.000000
104.510002,65.108215,-1299.777832,-0.001457,0.004276,0.108611,289.615814,14.753733,1.086113,-1299.777832,294.500458,0.000000
104.910004,65.149170,-1299.822388,-0.001466,0.004278,0.108654,289.797974,14.763013,1.086537,-1299.822388,294.500458,0.000000
105.310005,65.253433,-1299.777832,-0.001466,0.004281,0.108742,290.261780,14.786639,1.087415,-1299.777832,294.500458,0.000000
105.710007,65.245239,-1299.733398,-0.001457,0.004281,0.108742,290.225311,14.784782,1.087415,-1299.733398,294.500458,0.000000
106.110008,65.185669,-1299.777832,-0.001470,0.004281,0.108749,289.960327,14.771283,1.087491,-1299.777832,294.500458,0.000000
106.510002,65.061661,-1299.733398,-0.001457,0.004282,0.108767,289.408722,14.743183,1.087673,-1299.733398,294.500458,0.000000
106.910004,65.046768,-1299.822388,-0.001453,0.004283,0.108784,289.342468,14.739808,1.087839,-1299.822388,294.500458,0.000000
107.310005,65.145081,-1299.822388,-0.001449,0.004286,0.108863,289.779785,14.762086,1.088627,-1299.822388,294.500458,0.000000
107.710007,65.112671,-1299.733398,-0.001444,0.004286,0.108863,289.635620,14.754742,1.088627,-1299.733398,294.500458,0.000000
108.110008,65.051987,-1299.777832,-0.001466,0.004287,0.108879,289.365692,14.740992,1.088793,-1299.777832,294.500458,0.000000
108.510002,65.035965,-1299.822388,-0.001440,0.004291,0.108984,289.294434,14.737360,1.089838,-1299.822388,294.500458,0.000000
108.910004,65.284714,-1299.777832,-0.001436,0.004291,0.109000,290.400909,14.793728,1.090004,-1299.777832,294.500458,0.000000
109.310005,65.235565,-1299.911255,-0.001444,0.004291,0.109000,290.182281,14.782591,1.090004,-1299.911255,294.500458,0.000000
109.710007,65.132416,-1299.866821,-0.001444,0.004292,0.109010,289.723450,14.759216,1.090095,-1299.866821,294.500458,0.000000
110.110008,65.117889,-1299.866821,-0.001453,0.004293,0.109044,289.658844,14.755924,1.090443,-1299.866821,294.500458,0.000000
110.510002,65.170029,-1299.866821,-0.001436,0.004295,0.109096,289.890778,14.767740,1.090958,-1299.866821,294.500458,0.000000
110.910004,65.117142,-1299.822388,-0.001444,0.004295,0.109105,289.655518,14.755754,1.091049,-1299.822388,294.500458,0.000000
111.310005,65.079910,-1299.777832,-0.001462,0.004296,0.109123,289.489899,14.747318,1.091231,-1299.777832,294.500458,0.000000
111.710007,65.064636,-1299.822388,-0.001449,0.004297,0.109149,289.421967,14.743857,1.091488,-1299.822388,294.500458,0.000000
112.110008,65.080276,-1299.822388,-0.001440,0.004299,0.109184,289.491516,14.747402,1.091836,-1299.822388,294.500458,0.000000
112.510002,65.100769,-1299.777832,-0.001440,0.004300,0.109218,289.582672,14.752046,1.092184,-1299.777832,294.500458,0.000000
112.910004,65.056442,-1299.777832,-0.001440,0.004300,0.109218,289.385498,14.742001,1.092184,-1299.777832,294.500458,0.000000
113.310005,65.015121,-1299.822388,-0.001444,0.004301,0.109235,289.201691,14.732637,1.092351,-1299.822388,294.500458,0.000000
113.710007,65.086609,-1299.822388,-0.001440,0.004303,0.109287,289.519684,14.748837,1.092866,-1299.822388,294.500458,0.000000
114.110008,65.035599,-1299.822388,-0.001427,0.004303,0.109287,289.292786,14.737277,1.092866,-1299.822388,294.500458,0.000000
114.510002,65.026291,-1299.866821,-0.001440,0.004305,0.109340,289.251373,14.735168,1.093396,-1299.866821,294.500458,0.000000
114.910004,65.009903,-1299.822388,-0.001436,0.004305,0.109340,289.178497,14.731455,1.093396,-1299.822388,294.500458,0.000000
115.310005,65.011765,-1299.777832,-0.001440,0.004306,0.109374,289.186768,14.731876,1.093744,-1299.777832,294.500458,0.000000
115.710007,65.031876,-1299.866821,-0.001431,0.004307,0.109391,289.276245,14.736434,1.093910,-1299.866821,294.500458,0.000000
116.110008,65.000214,-1299.777832,-0.001436,0.004307,0.109391,289.135376,14.729259,1.093910,-1299.777832,294.500458,0.000000
116.510002,64.955902,-1299.777832,-0.001444,0.004309,0.109452,288.938293,14.719218,1.094516,-1299.777832,294.500458,0.000000
116.910004,65.002823,-1299.822388,-0.001431,0.004309,0.109452,289.147003,14.729851,1.094516,-1299.822388,294.500458,0.000000
117.310005,64.979370,-1299.822388,-0.001449,0.004311,0.109495,289.042664,14.724536,1.094955,-1299.822388,294.500458,0.000000
117.710007,64.989426,-1299.866821,-0.001444,0.004311,0.109495,289.087402,14.726814,1.094955,-1299.866821,294.500458,0.000000
118.110008,64.956284,-1299.866821,-0.001431,0.004311,0.109495,288.939972,14.719304,1.094955,-1299.866821,294.500458,0.000000
118.510002,64.880310,-1299.866821,-0.001431,0.004311,0.109505,288.602020,14.702088,1.095046,-1299.866821,294.500458,0.000000
118.910004,64.948837,-1299.911255,-0.001431,0.004314,0.109565,288.906860,14.717617,1.095651,-1299.911255,294.500458,0.000000
119.310005,64.924637,-1299.866821,-0.001436,0.004314,0.109565,288.799194,14.712132,1.095651,-1299.866821,294.500458,0.000000
119.710007,65.098892,-1299.866821,-0.001418,0.004318,0.109677,289.574341,14.751619,1.096772,-1299.866821,294.500458,0.000000
120.110008,65.183426,-1299.866821,-0.001423,0.004318,0.109677,289.950348,14.770775,1.096772,-1299.866821,294.500458,0.000000
120.510002,65.116776,-1299.866821,-0.001418,0.004318,0.109677,289.653870,14.755672,1.096772,-1299.866821,294.500458,0.000000
120.910004,65.056076,-1299.866821,-0.001418,0.004318,0.109677,289.383881,14.741918,1.096772,-1299.866821,294.500458,0.000000
121.310005,65.000961,-1299.777832,-0.001423,0.004318,0.109677,289.138702,14.729428,1.096772,-1299.777832,294.500458,0.000000
121.710007,64.932083,-1299.777832,-0.001427,0.004318,0.109686,288.832336,14.713820,1.096863,-1299.777832,294.500458,0.000000
122.110008,64.855743,-1299.866821,-0.001423,0.004318,0.109686,288.492767,14.696522,1.096863,-1299.866821,294.500458,0.000000
122.510002,64.993515,-1299.777832,-0.001431,0.004321,0.109765,289.105591,14.727740,1.097650,-1299.777832,294.500458,0.000000
122.910004,64.980118,-1299.911255,-0.001427,0.004321,0.109765,289.045990,14.724706,1.097650,-1299.911255,294.500458,0.000000
123.310005,64.911224,-1299.866821,-0.001423,0.004321,0.109765,288.739532,14.709093,1.097650,-1299.866821,294.500458,0.000000
123.710007,65.058685,-1299.866821,-0.001418,0.004325,0.109860,289.395477,14.742508,1.098604,-1299.866821,294.500458,0.000000
124.110008,65.051987,-1299.822388,-0.001418,0.004325,0.109860,289.365692,14.740992,1.098604,-1299.822388,294.500458,0.000000
124.510002,65.016983,-1299.822388,-0.001427,0.004325,0.109860,289.209991,14.733059,1.098604,-1299.822388,294.500458,0.000000
124.910004,64.991287,-1299.822388,-0.001414,0.004326,0.109886,289.095673,14.727236,1.098861,-1299.822388,294.500458,0.000000
125.310005,64.968201,-1299.911255,-0.001410,0.004326,0.109886,288.992981,14.722005,1.098861,-1299.911255,294.500458,0.000000
125.710007,64.923889,-1299.866821,-0.001414,0.004327,0.109903,288.795868,14.711963,1.099028,-1299.866821,294.500458,0.000000
126.110008,64.954041,-1299.866821,-0.001410,0.004328,0.109928,288.929993,14.718796,1.099285,-1299.866821,294.500458,0.000000
126.510010,64.946976,-1299.822388,-0.001410,0.004328,0.109928,288.898590,14.717196,1.099285,-1299.822388,294.500458,0.000000
126.910004,64.859467,-1299.822388,-0.001410,0.004328,0.109928,288.509308,14.697365,1.099285,-1299.822388,294.500458,0.000000
127.310005,65.035217,-1299.866821,-0.001414,0.004331,0.110016,289.291107,14.737191,1.100163,-1299.866821,294.500458,0.000000
127.710007,65.022186,-1299.777832,-0.001418,0.004331,0.110016,289.233124,14.734238,1.100163,-1299.777832,294.500458,0.000000
128.110001,64.981232,-1299.911255,-0.001401,0.004332,0.110024,289.050964,14.724958,1.100239,-1299.911255,294.500458,0.000000
128.510010,65.148804,-1299.866821,-0.001401,0.004328,0.109928,289.796356,14.762930,1.099285,-1299.866821,0.110094,0.000000
128.910004,65.000595,-1299.866821,-0.001414,0.004318,0.109677,289.137085,14.729345,1.096772,-1299.866821,0.109470,0.000000
129.310013,64.897446,-1299.866821,-0.001410,0.004298,0.109175,288.678253,14.705972,1.091745,-1299.866821,0.108802,0.000000
129.710007,64.757065,-1299.822388,-0.001401,0.004275,0.108577,288.053802,14.674161,1.085765,-1299.822388,0.108142,0.000000
130.110001,64.658386,-1299.822388,-0.001384,0.004249,0.107935,287.614868,14.651799,1.079346,-1299.822388,0.107474,0.000000
130.510010,64.603271,-1299.822388,-0.001401,0.004229,0.107423,287.369690,14.639311,1.074229,-1299.822388,0.106807,0.000000
130.910004,64.522461,-1299.911255,-0.001380,0.004203,0.106755,287.010254,14.620998,1.067552,-1299.911255,0.106139,0.000000
131.310013,64.412994,-1299.866821,-0.001375,0.004175,0.106035,286.523315,14.596193,1.060346,-1299.866821,0.105471,0.000000
131.710007,64.273727,-1299.866821,-0.001375,0.004147,0.105341,285.903809,14.564635,1.053412,-1299.866821,0.104804,0.000000
132.110001,64.226807,-1299.866821,-0.001384,0.004123,0.104734,285.695099,14.554003,1.047341,-1299.866821,0.104136,0.000000
132.510010,64.094986,-1299.866821,-0.001380,0.004099,0.104110,285.108734,14.524132,1.041103,-1299.866821,0.103468,0.000000
132.910004,63.846619,-1299.866821,-0.001375,0.004081,0.103659,284.003937,14.467851,1.036592,-1299.866821,0.102810,0.000000
133.310013,62.944351,-1299.777832,-0.001371,0.004053,0.102948,279.990448,14.263393,1.029476,-1299.777832,0.102141,0.000000
133.710007,61.694672,-1299.822388,-0.001371,0.004025,0.102245,274.431610,13.980212,1.022452,-1299.822388,0.101473,0.000000
134.110001,60.119537,-1299.822388,-0.001354,0.003999,0.101587,267.425049,13.623281,1.015866,-1299.822388,0.100805,0.000000
134.510010,58.751442,-1299.866821,-0.001341,0.003983,0.101161,261.339478,13.313267,1.011612,-1299.866821,0.100138,0.000000
134.910004,56.876541,-1299.866821,-0.001337,0.003955,0.100450,252.999496,12.888409,1.004496,-1299.866821,0.099470,0.000000
135.310013,54.074440,-1299.866821,-0.001341,0.003926,0.099730,240.535126,12.253443,0.997305,-1299.866821,0.098802,0.000000
135.710007,51.986923,-1299.866821,-0.001328,0.003905,0.099175,231.249390,11.780405,0.991748,-1299.866821,0.098135,0.000000
136.110001,48.877609,-1299.822388,-0.001324,0.003875,0.098430,217.418457,11.075825,0.984300,-1299.822388,0.097476,0.000000
136.510010,46.611725,-1299.777832,-0.001324,0.003852,0.097840,207.339310,10.562368,0.978395,-1299.777832,0.096809,0.000000
136.910004,44.036026,-1299.822388,-0.001337,0.003834,0.097388,195.882034,9.978705,0.973884,-1299.822388,0.096141,0.000000
137.310013,40.748718,-1299.822388,-0.001341,0.003803,0.096591,181.259354,9.233791,0.965905,-1299.822388,0.095472,0.000000
137.710007,37.833786,-1299.866821,-0.001337,0.003778,0.095950,168.293091,8.573258,0.959501,-1299.866821,0.094804,0.000000
138.110001,34.838425,-1299.822388,-0.001332,0.003750,0.095255,154.969055,7.894500,0.952552,-1299.822388,0.094136,0.000000
138.510010,31.416321,-1299.822388,-0.001341,0.003720,0.094492,139.746780,7.119040,0.944922,-1299.822388,0.093469,0.000000
138.910004,29.647926,-1299.911255,-0.001315,0.003705,0.094111,131.880569,6.718316,0.941107,-1299.911255,0.092801,0.000000
139.310013,27.511253,-1299.866821,-0.001332,0.003687,0.093652,122.376167,6.234139,0.936519,-1299.866821,0.092133,0.000000
139.710007,23.492607,-1299.866821,-0.001337,0.003648,0.092663,104.500336,5.323501,0.926633,-1299.866821,0.091475,0.000000
140.110001,20.149445,-1299.822388,-0.001337,0.003618,0.091899,89.629204,4.565929,0.918988,-1299.822388,0.090807,0.000000
140.510010,17.277336,-1299.866821,-0.001337,0.003593,0.091266,76.853432,3.915100,0.912659,-1299.866821,0.090140,0.000000
140.910004,15.093750,-1299.777832,-0.001332,0.003571,0.090703,67.140350,3.420293,0.907027,-1299.777832,0.089472,0.000000
141.310013,11.783730,-1299.777832,-0.001328,0.003538,0.089870,52.416645,2.670231,0.898701,-1299.777832,0.088803,0.000000
141.710007,8.347847,-1299.866821,-0.001328,0.003511,0.089168,37.133080,1.891649,0.891676,-1299.866821,0.088135,0.000000
142.110001,5.837685,-1299.866821,-0.001341,0.003485,0.088517,25.967318,1.322838,0.885166,-1299.866821,0.087467,0.000000
142.510010,4.596191,-1299.866821,-0.001341,0.003469,0.088109,20.444880,1.041512,0.881093,-1299.866821,0.086800,0.000000
142.910004,2.216362,-1299.822388,-0.001337,0.003448,0.087590,9.858871,0.502235,0.875900,-1299.822388,0.086141,0.000000
143.310013,-1.056419,-1299.911255,-0.001328,0.003414,0.086704,-4.699188,-0.239388,0.867044,-1299.911255,0.085474,0.000000
143.710007,-4.384312,-1299.866821,-0.001332,0.003379,0.085829,-19.502392,-0.993499,0.858293,-1299.866821,0.084806,0.000000
144.110001,-0.405144,-1299.955811,-0.001332,0.003357,0.085257,-1.802169,-0.091807,0.852570,-1299.955811,0.084138,0.000000
144.510010,-0.353378,-1299.866821,-0.001324,0.003330,0.084580,-1.571905,-0.080077,0.845803,-1299.866821,0.083471,0.000000
144.910004,-0.199593,-1299.911255,-0.001319,0.003301,0.083852,-0.887832,-0.045228,0.838521,-1299.911255,0.082803,0.000000
145.310013,-0.155647,-1299.822388,-0.001315,0.003276,0.083201,-0.692354,-0.035270,0.832011,-1299.822388,0.082134,0.000000
145.710007,-0.110222,-1299.777832,-0.001324,0.003247,0.082473,-0.490291,-0.024977,0.824729,-1299.777832,0.081466,0.000000
146.110001,-0.068512,-1299.866821,-0.001319,0.003224,0.081882,-0.304756,-0.015525,0.818824,-1299.866821,0.080808,0.000000
146.510010,-0.059204,-1299.866821,-0.001328,0.003210,0.081536,-0.263353,-0.013416,0.815357,-1299.866821,0.080140,0.000000
146.910004,-0.066650,-1299.911255,-0.001328,0.003171,0.080547,-0.296476,-0.015103,0.805471,-1299.911255,0.079472,0.000000
147.310013,-0.086388,-1299.866821,-0.001324,0.003149,0.079975,-0.384271,-0.019576,0.799748,-1299.866821,0.078805,0.000000
147.710007,-0.145226,-1299.866821,-0.001328,0.003119,0.079212,-0.645995,-0.032909,0.792118,-1299.866821,0.078137,0.000000
148.110001,-0.128098,-1299.911255,-0.001319,0.003091,0.078518,-0.569806,-0.029027,0.785184,-1299.911255,0.077469,0.000000
148.510010,-0.097191,-1299.866821,-0.001345,0.003071,0.078016,-0.432327,-0.022024,0.780158,-1299.866821,0.076802,0.000000
148.910004,-0.128838,-1299.911255,-0.001337,0.003039,0.077183,-0.573098,-0.029195,0.771831,-1299.911255,0.076134,0.000000
149.310013,-0.138519,-1299.866821,-0.001337,0.003021,0.076723,-0.616165,-0.031389,0.767228,-1299.866821,0.075474,0.000000
149.710007,-0.174271,-1299.866821,-0.001337,0.002985,0.075813,-0.775194,-0.039490,0.758130,-1299.866821,0.074806,0.000000
150.110001,-0.165703,-1299.822388,-0.001350,0.002958,0.075136,-0.737083,-0.037549,0.751362,-1299.822388,0.074139,0.000000
150.510010,-0.172035,-1299.911255,-0.001341,0.002945,0.074797,-0.765251,-0.038984,0.747971,-1299.911255,0.073471,0.000000
150.910004,-0.189163,-1299.777832,-0.001354,0.002908,0.073861,-0.841440,-0.042865,0.738615,-1299.777832,0.072803,0.000000
151.310013,-0.203690,-1299.822388,-0.001354,0.002882,0.073194,-0.906056,-0.046157,0.731938,-1299.822388,0.072136,0.000000
151.710007,-0.187675,-1299.822388,-0.001371,0.002852,0.072447,-0.834822,-0.042528,0.724474,-1299.822388,0.071468,0.000000
152.110001,-0.174644,-1299.822388,-0.001375,0.002824,0.071736,-0.776857,-0.039575,0.717359,-1299.822388,0.070800,0.000000
152.510010,-0.192513,-1299.866821,-0.001414,0.002803,0.071208,-0.856338,-0.043624,0.712075,-1299.866821,0.070133,0.000000
152.910004,-0.191399,-1299.866821,-0.001457,0.002774,0.070470,-0.851384,-0.043372,0.704702,-1299.866821,0.069472,0.000000
153.310013,-0.229752,-1299.822388,-0.001470,0.002748,0.069793,-1.021986,-0.052062,0.697935,-1299.822388,0.068805,0.000000
153.710007,-0.227890,-1299.911255,-0.001509,0.002723,0.069170,-1.013705,-0.051641,0.691697,-1299.911255,0.068137,0.000000
154.110001,-0.201454,-1299.866821,-0.001548,0.002696,0.068467,-0.896113,-0.045650,0.684672,-1299.866821,0.067470,0.000000
154.510010,-0.199219,-1299.822388,-0.001556,0.002667,0.067739,-0.886169,-0.045144,0.677390,-1299.822388,0.066802,0.000000
154.910004,-0.221191,-1299.866821,-0.001591,0.002636,0.066967,-0.983909,-0.050123,0.669669,-1299.866821,0.066134,0.000000
155.310013,-0.237198,-1299.955811,-0.001608,0.002615,0.066420,-1.055109,-0.053750,0.664204,-1299.955811,0.065467,0.000000
155.710007,-0.238319,-1299.866821,-0.001630,0.002592,0.065848,-1.060098,-0.054004,0.658481,-1299.866821,0.064799,0.000000
156.110001,-0.225281,-1299.955811,-0.001664,0.002567,0.065190,-1.002099,-0.051049,0.651895,-1299.955811,0.064139,0.000000
156.510010,-0.215599,-1299.866821,-0.001681,0.002542,0.064573,-0.959033,-0.048855,0.645733,-1299.866821,0.063471,0.000000
156.910004,-0.187675,-1299.822388,-0.001720,0.002519,0.063975,-0.834822,-0.042528,0.639753,-1299.822388,0.062804,0.000000
157.310013,-0.241295,-1299.911255,-0.001755,0.002484,0.063090,-1.073333,-0.054678,0.630897,-1299.911255,0.062136,0.000000
157.710007,-0.234962,-1299.955811,-0.001776,0.002461,0.062517,-1.045165,-0.053243,0.625174,-1299.955811,0.061468,0.000000
158.110001,-0.207039,-1299.822388,-0.001798,0.002448,0.062171,-0.920955,-0.046916,0.621707,-1299.822388,0.060801,0.000000
158.510010,-0.207413,-1299.866821,-0.001824,0.002428,0.061668,-0.922618,-0.047000,0.616681,-1299.866821,0.060133,0.000000
158.910004,-0.205551,-1299.866821,-0.001850,0.002396,0.060870,-0.914337,-0.046579,0.608702,-1299.866821,0.059465,0.000000
159.310013,-0.240555,-1299.866821,-0.001893,0.002356,0.059830,-1.070041,-0.054511,0.598301,-1299.866821,0.058807,0.000000
159.710007,-0.207413,-1299.955811,-0.001927,0.002326,0.059084,-0.922618,-0.047000,0.590837,-1299.955811,0.058139,0.000000
160.110001,-0.205917,-1299.866821,-0.001932,0.002305,0.058537,-0.915966,-0.046662,0.585372,-1299.866821,0.057470,0.000000
160.510010,-0.210388,-1299.955811,-0.001953,0.002289,0.058130,-0.935853,-0.047675,0.581299,-1299.955811,0.056802,0.000000
160.910004,-0.220070,-1299.911255,-0.001996,0.002252,0.057193,-0.978920,-0.049869,0.571928,-1299.911255,0.056135,0.000000
161.310013,-0.180969,-1299.866821,-0.002022,0.002230,0.056639,-0.804991,-0.041008,0.566387,-1299.866821,0.056465,0.000000
161.400009,-0.181717,-1299.911255,-0.002026,0.002230,0.056646,-0.808317,-0.041178,0.566463,-1299.911255,0.056465,0.000000