File: Data/compression 28/AutoNoHeating-17-28-reverse-1-1_10222024_181954.csv
Time (sec),S:Load (lbs),S:HL1 (DIM),S:LVDT (in),S:Position (in),Ch:Position (mm),Ch:Load (N),Ch:Stress (MPa),Ch:Strain (mm/mm),Ch:HL1 (DIM),Set Point (),Cycles ()
0.110000,-0.044312,-1296.085937,-0.006071,-0.006252,-0.158788,-0.197107,-0.010041,-1.587885,-1296.085937,-0.158581,0.000000
0.500000,-0.052132,-1296.085937,-0.006075,-0.006164,-0.156569,-0.231893,-0.011813,-1.565690,-1296.085937,-0.155701,0.000000
0.890000,-0.083412,-1296.130493,-0.005946,-0.005925,-0.150490,-0.371036,-0.018901,-1.504905,-1296.130493,-0.149216,0.000000
1.280000,-0.011543,-1296.085937,-0.005708,-0.005669,-0.144003,-0.051347,-0.002616,-1.440031,-1296.085937,-0.142710,0.000000
1.670000,0.037239,-1296.085937,-0.005454,-0.005414,-0.137516,0.165648,0.008438,-1.375158,-1296.085937,-0.136206,0.000000
2.060000,0.039101,-1296.041504,-0.005368,-0.000000,-0.000008,0.173928,0.008860,-0.000076,-1296.041504,0.000209,0.000000
2.450000,0.026810,-1296.041504,-0.005372,-0.000000,-0.000000,0.119255,0.006075,-0.000000,-1296.041504,0.000469,0.000000
2.840000,0.053253,-1296.130493,-0.005359,0.000002,0.000044,0.236882,0.012067,0.000439,-1296.130493,0.001119,0.000000
3.230000,0.095329,-1296.085937,-0.005364,0.000030,0.000755,0.424046,0.021602,0.007555,-1296.085937,0.001770,0.000000
3.620000,0.082298,-1296.085937,-0.005355,0.000052,0.001328,0.366081,0.018649,0.013277,-1296.085937,0.002421,0.000000
4.010000,0.124001,-1296.130493,-0.005333,0.000074,0.001882,0.551582,0.028099,0.018818,-1296.130493,0.003070,0.000000
4.400000,0.195496,-1296.085937,-0.005312,0.000109,0.002775,0.869608,0.044300,0.027751,-1296.085937,0.003721,0.000000
4.790000,0.238693,-1296.130493,-0.005277,0.000128,0.003244,1.061761,0.054089,0.032444,-1296.130493,0.004371,0.000000
5.180000,0.318748,-1296.041504,-0.005264,0.000156,0.003954,1.417864,0.072229,0.039545,-1296.041504,0.005013,0.000000
5.570000,0.387268,-1296.041504,-0.005247,0.000180,0.004562,1.722654,0.087756,0.045616,-1296.041504,0.005664,0.000000
5.960001,0.505684,-1296.174927,-0.005200,0.000199,0.005057,2.249394,0.114590,0.050566,-1296.174927,0.006315,0.000000
6.350000,0.809166,-1296.085937,-0.005208,0.000232,0.005898,3.599350,0.183360,0.058984,-1296.085937,0.006964,0.000000
6.740000,1.056793,-1296.174927,-0.005161,0.000252,0.006401,4.700851,0.239473,0.064010,-1296.174927,0.007615,0.000000
7.130000,1.297348,-1296.130493,-0.005139,0.000276,0.006999,5.770892,0.293983,0.069990,-1296.130493,0.008265,0.000000
7.520000,1.719620,-1296.130493,-0.005139,0.000303,0.007685,7.649251,0.389671,0.076849,-1296.130493,0.008916,0.000000
7.910000,2.097946,-1296.085937,-0.005101,0.000328,0.008334,9.332130,0.475401,0.083343,-1296.085937,0.009567,0.000000
8.300000,2.730980,-1296.130493,-0.005101,0.000359,0.009106,12.148005,0.618849,0.091065,-1296.130493,0.010216,0.000000
8.690001,3.170380,-1296.219360,-0.005062,0.000382,0.009704,14.102553,0.718418,0.097045,-1296.219360,0.010867,0.000000
9.080001,3.434395,-1296.130493,-0.005036,0.000398,0.010112,15.276951,0.778245,0.101117,-1296.130493,0.011517,0.000000
9.470000,4.201851,-1296.174927,-0.005023,0.000434,0.011014,18.690765,0.952153,0.110140,-1296.174927,0.012168,0.000000
9.860001,4.574226,-1296.174927,-0.005001,0.000453,0.011509,20.347176,1.036535,0.115091,-1296.174927,0.012819,0.000000
10.250001,5.201675,-1296.174927,-0.004963,0.000477,0.012124,23.138208,1.178717,0.121238,-1296.174927,0.013468,0.000000
10.640000,6.133347,-1296.174927,-0.004971,0.000509,0.012940,27.282488,1.389836,0.129398,-1296.174927,0.014119,0.000000
11.030001,6.566788,-1296.219360,-0.004941,0.000534,0.013573,29.210531,1.488055,0.135726,-1296.219360,0.014770,0.000000
11.420000,7.171524,-1296.174927,-0.004919,0.000564,0.014327,31.900532,1.625091,0.143266,-1296.174927,0.015420,0.000000
11.810000,7.573311,-1296.174927,-0.004889,0.000583,0.014813,33.687771,1.716137,0.148126,-1296.174927,0.016071,0.000000
12.200001,8.202621,-1296.085937,-0.004863,0.000610,0.015498,36.487083,1.858741,0.154984,-1296.085937,0.016720,0.000000
12.590000,8.830444,-1296.219360,-0.004846,0.000639,0.016243,39.279778,2.001007,0.162433,-1296.219360,0.017371,0.000000
12.980000,9.078445,-1296.219360,-0.004825,0.000659,0.016747,40.382942,2.057205,0.167474,-1296.219360,0.018022,0.000000
13.370001,9.729347,-1296.219360,-0.004799,0.000692,0.017571,43.278297,2.204702,0.175710,-1296.219360,0.018672,0.000000
13.760000,9.822441,-1296.219360,-0.004781,0.000711,0.018055,43.692402,2.225797,0.180555,-1296.219360,0.019323,0.000000
14.150001,10.638313,-1296.174927,-0.004760,0.000742,0.018846,47.321583,2.410676,0.188457,-1296.174927,0.019965,0.000000
14.540001,10.874397,-1296.263916,-0.004730,0.000767,0.019488,48.371735,2.464174,0.194877,-1296.263916,0.020614,0.000000
14.930000,11.356987,-1296.174927,-0.004700,0.000801,0.020346,50.518402,2.573530,0.203461,-1296.174927,0.021265,0.000000
15.320001,11.212509,-1296.219360,-0.004674,0.000820,0.020823,49.875732,2.540791,0.208230,-1296.219360,0.021916,0.000000
15.710001,11.227402,-1296.219360,-0.004652,0.000840,0.021335,49.941978,2.544166,0.213347,-1296.219360,0.022566,0.000000
16.100000,11.906235,-1296.174927,-0.004639,0.000872,0.022158,52.961578,2.697991,0.221583,-1296.174927,0.023217,0.000000
16.490002,11.817986,-1296.263916,-0.004622,0.000890,0.022619,52.569027,2.677994,0.226185,-1296.263916,0.023866,0.000000
16.880001,12.134506,-1296.263916,-0.004596,0.000920,0.023363,53.976978,2.749718,0.233634,-1296.263916,0.024517,0.000000
17.270000,12.332230,-1296.174927,-0.004566,0.000947,0.024049,54.856499,2.794523,0.240492,-1296.174927,0.025168,0.000000
17.660002,12.273773,-1296.263916,-0.004553,0.000969,0.024612,54.596470,2.781277,0.246124,-1296.263916,0.025818,0.000000
18.050001,12.746307,-1296.174927,-0.004518,0.001001,0.025427,56.698406,2.888355,0.254269,-1296.174927,0.026469,0.000000
18.440001,12.623428,-1296.219360,-0.004488,0.001021,0.025931,56.151814,2.860510,0.259311,-1296.219360,0.027118,0.000000
18.830002,12.777588,-1296.263916,-0.004458,0.001050,0.026676,56.837551,2.895443,0.266759,-1296.263916,0.027769,0.000000
19.220001,12.795090,-1296.219360,-0.004437,0.001074,0.027275,56.915401,2.899409,0.272755,-1296.219360,0.028420,0.000000
19.610001,13.152565,-1296.219360,-0.004411,0.001103,0.028020,58.505531,2.980414,0.280203,-1296.219360,0.029070,0.000000
20.000000,13.057617,-1296.263916,-0.004368,0.001128,0.028653,58.083183,2.958898,0.286532,-1296.263916,0.029721,0.000000
20.390001,12.975319,-1296.308350,-0.004355,0.001148,0.029165,57.717102,2.940249,0.291649,-1296.308350,0.030372,0.000000
20.780001,13.224434,-1296.263916,-0.004329,0.001177,0.029902,58.825218,2.996700,0.299022,-1296.263916,0.031021,0.000000
21.170000,13.197998,-1296.219360,-0.004307,0.001202,0.030518,58.707626,2.990709,0.305184,-1296.219360,0.031672,0.000000
21.560001,13.354019,-1296.308350,-0.004281,0.001227,0.031160,59.401646,3.026064,0.311603,-1296.308350,0.032321,0.000000
21.950001,13.712242,-1296.263916,-0.004238,0.001257,0.031923,60.995098,3.107239,0.319233,-1296.263916,0.032972,0.000000
22.340000,13.553238,-1296.308350,-0.004230,0.001279,0.032477,60.287815,3.071208,0.324774,-1296.308350,0.033623,0.000000
22.730001,13.747620,-1296.263916,-0.004178,0.001305,0.033154,61.152466,3.115255,0.331542,-1296.263916,0.034273,0.000000
23.120001,13.693253,-1296.263916,-0.004182,0.001330,0.033779,60.910629,3.102935,0.337794,-1296.263916,0.034915,0.000000
23.510000,13.815018,-1296.352783,-0.004143,0.001354,0.034387,61.452267,3.130528,0.343865,-1296.352783,0.035566,0.000000
23.900002,14.084991,-1296.308350,-0.004122,0.001381,0.035089,62.653172,3.191705,0.350890,-1296.308350,0.036215,0.000000
24.290001,13.932686,-1296.308350,-0.004092,0.001402,0.035617,61.975681,3.157192,0.356174,-1296.308350,0.036866,0.000000
24.680000,14.299103,-1296.397339,-0.004074,0.001433,0.036389,63.605587,3.240223,0.363895,-1296.397339,0.037517,0.000000
25.070002,14.364265,-1296.263916,-0.004057,0.001459,0.037057,63.895443,3.254989,0.370571,-1296.263916,0.038167,0.000000
25.460001,14.308411,-1296.352783,-0.004040,0.001480,0.037595,63.646988,3.242332,0.375946,-1296.352783,0.038818,0.000000
25.850000,14.757492,-1296.352783,-0.004005,0.001512,0.038411,65.644600,3.344095,0.384106,-1296.352783,0.039467,0.000000
26.240002,14.272293,-1296.397339,-0.003975,0.001531,0.038878,63.486332,3.234148,0.388784,-1296.397339,0.040118,0.000000
26.630001,14.480820,-1296.397339,-0.003945,0.001557,0.039555,64.413902,3.281401,0.395552,-1296.397339,0.040769,0.000000
27.020000,14.739990,-1296.308350,-0.003932,0.001586,0.040274,65.566750,3.340130,0.402743,-1296.308350,0.041419,0.000000
27.410002,14.305061,-1296.397339,-0.003898,0.001602,0.040700,63.632092,3.241573,0.406997,-1296.397339,0.042070,0.000000
27.800001,15.099701,-1296.352783,-0.003880,0.001635,0.041540,67.166824,3.421641,0.415400,-1296.352783,0.042719,0.000000
28.190001,14.855057,-1296.352783,-0.003850,0.001659,0.042130,66.078590,3.366204,0.421304,-1296.352783,0.043370,0.000000
28.580002,14.480080,-1296.352783,-0.003811,0.001674,0.042529,64.410614,3.281233,0.425286,-1296.352783,0.044021,0.000000
28.970001,15.168221,-1296.352783,-0.003798,0.001709,0.043396,67.471611,3.437168,0.433961,-1296.352783,0.044671,0.000000
29.360001,15.301903,-1296.397339,-0.003781,0.001737,0.044117,68.066261,3.467461,0.441167,-1296.397339,0.045322,0.000000
29.750002,15.698853,-1296.352783,-0.003747,0.001765,0.044819,69.831985,3.557411,0.448192,-1296.352783,0.045973,0.000000
30.140001,15.516388,-1296.397339,-0.003721,0.001788,0.045417,69.020340,3.516064,0.454172,-1296.397339,0.046622,0.000000
30.530001,15.657890,-1296.397339,-0.003695,0.001815,0.046094,69.649773,3.548129,0.460940,-1296.397339,0.047273,0.000000
30.920002,15.582298,-1296.352783,-0.003669,0.001840,0.046736,69.313522,3.530999,0.467359,-1296.352783,0.047923,0.000000
31.310001,15.769600,-1296.397339,-0.003656,0.001867,0.047420,70.146683,3.573442,0.474202,-1296.397339,0.048574,0.000000
31.700001,15.999725,-1296.397339,-0.003613,0.001895,0.048123,71.170334,3.625590,0.481227,-1296.397339,0.049225,0.000000
32.090000,16.115540,-1296.352783,-0.003600,0.001920,0.048774,71.685501,3.651834,0.487737,-1296.352783,0.049867,0.000000
32.480003,15.772957,-1296.441772,-0.003570,0.001944,0.049381,70.161613,3.574203,0.493808,-1296.441772,0.050516,0.000000
32.870003,16.001961,-1296.308350,-0.003544,0.001967,0.049962,71.180275,3.626096,0.499621,-1296.308350,0.051167,0.000000
33.260002,15.768112,-1296.486328,-0.003540,0.001986,0.050439,70.140068,3.573105,0.504390,-1296.486328,0.051817,0.000000
33.650002,16.522171,-1296.397339,-0.003497,0.002021,0.051323,73.494286,3.743977,0.513232,-1296.397339,0.052468,0.000000
34.040001,16.528122,-1296.397339,-0.003462,0.002046,0.051965,73.520760,3.745326,0.519651,-1296.397339,0.053119,0.000000
34.430000,16.777245,-1296.441772,-0.003445,0.002073,0.052649,74.628914,3.801778,0.526494,-1296.441772,0.053768,0.000000
34.820004,16.652870,-1296.397339,-0.003410,0.002097,0.053257,74.075668,3.773594,0.532565,-1296.397339,0.054419,0.000000
35.210003,16.461845,-1296.441772,-0.003402,0.002117,0.053777,73.225945,3.730308,0.537773,-1296.441772,0.055069,0.000000
35.600002,17.250900,-1296.441772,-0.003359,0.002149,0.054575,76.735840,3.909110,0.545752,-1296.441772,0.055720,0.000000
35.990002,17.294838,-1296.352783,-0.003328,0.002178,0.055312,76.931282,3.919066,0.553125,-1296.352783,0.056371,0.000000
36.380001,17.568909,-1296.441772,-0.003316,0.002204,0.055989,78.150406,3.981172,0.559892,-1296.441772,0.057020,0.000000
36.770000,17.374527,-1296.397339,-0.003290,0.002226,0.056536,77.285759,3.937124,0.565357,-1296.397339,0.057671,0.000000
37.160004,17.376015,-1296.397339,-0.003272,0.002251,0.057169,77.292374,3.937461,0.571686,-1296.397339,0.058322,0.000000
37.550003,17.928619,-1296.441772,-0.003238,0.002277,0.057836,79.750481,4.062683,0.578362,-1296.441772,0.058972,0.000000
37.940002,17.625504,-1296.352783,-0.003221,0.002296,0.058322,78.402153,3.993996,0.583222,-1296.352783,0.059623,0.000000
38.330002,18.372482,-1296.486328,-0.003216,0.002327,0.059102,81.724884,4.163264,0.591019,-1296.486328,0.060272,0.000000
38.720001,18.440628,-1296.397339,-0.003173,0.002352,0.059735,82.028008,4.178706,0.597347,-1296.397339,0.060923,0.000000
39.110001,18.692352,-1296.397339,-0.003165,0.002378,0.060402,83.147736,4.235748,0.604024,-1296.397339,0.061574,0.000000
39.500000,18.995468,-1296.441772,-0.003130,0.002404,0.061070,84.496063,4.304435,0.610700,-1296.441772,0.062224,0.000000
39.890003,18.614525,-1296.352783,-0.003126,0.002424,0.061574,82.801544,4.218112,0.615742,-1296.352783,0.062875,0.000000
40.280003,19.011475,-1296.441772,-0.003091,0.002451,0.062258,84.567261,4.308062,0.622585,-1296.441772,0.063524,0.000000
40.670002,19.360390,-1296.397339,-0.003057,0.002481,0.063012,86.119316,4.387127,0.630124,-1296.397339,0.064175,0.000000
41.060001,20.013901,-1296.441772,-0.003053,0.002511,0.063777,89.026276,4.535215,0.637770,-1296.441772,0.064817,0.000000
41.450001,19.629990,-1296.441772,-0.003001,0.002530,0.064271,87.318558,4.448219,0.642705,-1296.441772,0.065468,0.000000
41.840000,19.767395,-1296.352783,-0.002984,0.002559,0.064991,87.929764,4.479356,0.649912,-1296.352783,0.066118,0.000000
42.230003,20.151306,-1296.486328,-0.002966,0.002581,0.065563,89.637489,4.566351,0.655635,-1296.486328,0.066769,0.000000
42.620003,20.647682,-1296.441772,-0.002945,0.002612,0.066334,91.845474,4.678832,0.663341,-1296.441772,0.067418,0.000000
43.010002,20.678589,-1296.486328,-0.002923,0.002634,0.066915,91.982956,4.685835,0.669154,-1296.486328,0.068069,0.000000
43.400002,20.941483,-1296.486328,-0.002893,0.002658,0.067523,93.152367,4.745408,0.675225,-1296.486328,0.068720,0.000000
43.790001,21.543983,-1296.530762,-0.002880,0.002688,0.068278,95.832428,4.881936,0.682780,-1296.530762,0.069370,0.000000
44.180000,21.416260,-1296.486328,-0.002850,0.002710,0.068832,95.264282,4.852994,0.688321,-1296.486328,0.070021,0.000000
44.570004,21.458710,-1296.397339,-0.002824,0.002732,0.069395,95.453110,4.862613,0.693953,-1296.397339,0.070670,0.000000
44.960003,21.979660,-1296.397339,-0.002815,0.002764,0.070193,97.770409,4.980662,0.701931,-1296.397339,0.071321,0.000000
45.350002,22.316284,-1296.441772,-0.002790,0.002785,0.070740,99.267792,5.056942,0.707397,-1296.441772,0.071972,0.000000
45.740002,22.610458,-1296.530762,-0.002764,0.002810,0.071373,100.576340,5.123603,0.713725,-1296.530762,0.072622,0.000000
46.130001,23.000702,-1296.486328,-0.002755,0.002839,0.072119,102.312233,5.212034,0.721189,-1296.486328,0.073273,0.000000
46.520000,23.115021,-1296.486328,-0.002721,0.002859,0.072614,102.820747,5.237938,0.726140,-1296.486328,0.073924,0.000000
46.910004,23.072571,-1296.486328,-0.002703,0.002879,0.073117,102.631920,5.228320,0.731166,-1296.486328,0.074573,0.000000
47.300003,24.705421,-1296.486328,-0.002686,0.002921,0.074201,109.895203,5.598329,0.742006,-1296.486328,0.075224,0.000000
47.690002,24.577698,-1296.441772,-0.002656,0.002942,0.074738,109.327057,5.569386,0.747380,-1296.441772,0.075874,0.000000
48.080002,24.571739,-1296.575195,-0.002643,0.002963,0.075250,109.300552,5.568036,0.752498,-1296.575195,0.076525,0.000000
48.470001,25.275902,-1296.575195,-0.002613,0.002990,0.075943,112.432823,5.727601,0.759432,-1296.575195,0.077176,0.000000
48.860001,25.281487,-1296.530762,-0.002591,0.003011,0.076473,112.457672,5.728867,0.764730,-1296.530762,0.077825,0.000000
49.250004,26.148369,-1296.486328,-0.002570,0.003040,0.077210,116.313751,5.925305,0.772103,-1296.486328,0.078476,0.000000
49.640003,27.075577,-1296.530762,-0.002539,0.003070,0.077990,120.438179,6.135414,0.779900,-1296.530762,0.079126,0.000000
50.030003,27.580887,-1296.530762,-0.002522,0.003095,0.078606,122.685913,6.249918,0.786062,-1296.530762,0.079777,0.000000
50.420002,27.426353,-1296.486328,-0.002496,0.003116,0.079144,121.998512,6.214900,0.791437,-1296.486328,0.080418,0.000000
50.810001,27.776756,-1296.486328,-0.002496,0.003138,0.079699,123.557182,6.294303,0.796993,-1296.486328,0.081069,0.000000
51.200001,28.729279,-1296.530762,-0.002483,0.003170,0.080523,127.794212,6.510148,0.805229,-1296.530762,0.081719,0.000000
51.590004,29.113945,-1296.530762,-0.002449,0.003191,0.081051,129.505295,6.597314,0.810513,-1296.530762,0.082370,0.000000
51.980003,30.490234,-1296.486328,-0.002427,0.003225,0.081910,135.627335,6.909185,0.819097,-1296.486328,0.083019,0.000000
52.370003,30.291382,-1296.575195,-0.002402,0.003246,0.082456,134.742798,6.864125,0.824562,-1296.575195,0.083670,0.000000
52.760002,31.160500,-1296.486328,-0.002393,0.003274,0.083159,138.608826,7.061070,0.831587,-1296.486328,0.084321,0.000000
53.150002,31.439034,-1296.619751,-0.002350,0.003295,0.083689,139.847809,7.124187,0.836886,-1296.619751,0.084971,0.000000
53.540001,32.434761,-1296.441772,-0.002324,0.003323,0.084417,144.277023,7.349822,0.844168,-1296.441772,0.085622,0.000000
53.930004,33.252861,-1296.575195,-0.002324,0.003350,0.085084,147.916107,7.535206,0.850844,-1296.575195,0.086273,0.000000
54.320004,33.440910,-1296.619751,-0.002294,0.003375,0.085734,148.752594,7.577818,0.857339,-1296.619751,0.086922,0.000000
54.710003,33.948082,-1296.486328,-0.002276,0.003400,0.086359,151.008606,7.692745,0.863592,-1296.486328,0.087573,0.000000
55.100002,35.730255,-1296.575195,-0.002264,0.003431,0.087139,158.936111,8.096591,0.871389,-1296.575195,0.088223,0.000000
55.490002,36.010651,-1296.619751,-0.002225,0.003453,0.087711,160.183380,8.160130,0.877112,-1296.619751,0.088874,0.000000
55.880001,36.616127,-1296.575195,-0.002216,0.003479,0.088362,162.876663,8.297333,0.883622,-1296.575195,0.089525,0.000000
56.270004,37.551155,-1296.619751,-0.002199,0.003503,0.088978,167.035873,8.509213,0.889783,-1296.619751,0.090174,0.000000
56.660004,37.047340,-1296.530762,-0.002173,0.003520,0.089411,164.794800,8.395047,0.894113,-1296.530762,0.090825,0.000000
57.050003,39.677032,-1296.575195,-0.002156,0.003556,0.090323,176.492249,8.990944,0.903227,-1296.575195,0.091475,0.000000
57.440002,41.204872,-1296.619751,-0.002121,0.003586,0.091093,183.288422,9.337157,0.910933,-1296.619751,0.092126,0.000000
57.830002,41.818176,-1296.619751,-0.002104,0.003612,0.091744,186.016541,9.476134,0.917443,-1296.619751,0.092777,0.000000
58.220001,41.838654,-1296.664185,-0.002095,0.003626,0.092109,186.107620,9.480774,0.921092,-1296.664185,0.093426,0.000000
58.610004,43.505394,-1296.619751,-0.002061,0.003659,0.092949,193.521652,9.858463,0.929495,-1296.619751,0.094077,0.000000
59.000004,44.424034,-1296.575195,-0.002052,0.003683,0.093540,197.607971,10.066630,0.935399,-1296.575195,0.094728,0.000000
59.390003,45.172134,-1296.664185,-0.002026,0.003709,0.094198,200.935684,10.236153,0.941985,-1296.664185,0.095369,0.000000
59.780003,46.624382,-1296.530762,-0.002009,0.003737,0.094919,207.395615,10.565236,0.949191,-1296.530762,0.096020,0.000000
60.170002,47.426849,-1296.664185,-0.001992,0.003758,0.095464,210.965164,10.747077,0.954641,-1296.664185,0.096671,0.000000
60.560001,48.786003,-1296.664185,-0.001975,0.003785,0.096150,217.010986,11.055066,0.961500,-1296.664185,0.097320,0.000000
60.950005,50.111656,-1296.619751,-0.001966,0.003812,0.096818,222.907776,11.355463,0.968176,-1296.619751,0.097971,0.000000
61.340004,51.679344,-1296.619751,-0.001936,0.003842,0.097599,229.881210,11.710708,0.975988,-1296.619751,0.098621,0.000000
61.730003,52.179810,-1296.619751,-0.001919,0.003861,0.098076,232.107391,11.824114,0.980757,-1296.619751,0.099272,0.000000
62.120003,53.095848,-1296.708740,-0.001910,0.003885,0.098674,236.182129,12.031691,0.986737,-1296.708740,0.099923,0.000000
62.510002,55.008720,-1296.575195,-0.001893,0.003917,0.099488,244.691010,12.465155,0.994882,-1296.575195,0.100572,0.000000
62.900002,55.971680,-1296.664185,-0.001888,0.003941,0.100095,248.974472,12.683364,1.000953,-1296.664185,0.101223,0.000000
63.290005,57.853279,-1296.664185,-0.001867,0.003968,0.100790,257.344238,13.109740,1.007902,-1296.664185,0.101874,0.000000
63.680004,59.010239,-1296.575195,-0.001854,0.003992,0.101397,262.490662,13.371911,1.013973,-1296.575195,0.102524,0.000000
64.070000,60.140015,-1296.664185,-0.001837,0.004015,0.101986,267.516144,13.627922,1.019863,-1296.664185,0.103175,0.000000
64.460007,61.540878,-1296.619751,-0.001824,0.004043,0.102698,273.747498,13.945362,1.026978,-1296.619751,0.103824,0.000000
64.850006,63.280609,-1296.619751,-0.001807,0.004068,0.103340,281.486206,14.339591,1.033397,-1296.619751,0.104475,0.000000
65.240005,64.958511,-1296.664185,-0.001794,0.004097,0.104059,288.949890,14.719809,1.040589,-1296.664185,0.105126,0.000000
65.630005,65.994827,-1296.664185,-0.001776,0.004119,0.104614,293.559662,14.954642,1.046145,-1296.664185,0.105776,0.000000
66.020004,65.225128,-1296.619751,-0.001750,0.004115,0.104519,290.135864,14.780226,1.045191,-1296.619751,0.018345,0.000000
66.410004,65.264236,-1296.664185,-0.001742,0.004131,0.104917,290.309814,14.789087,1.049173,-1296.664185,294.500458,0.000000
66.800003,66.598068,-1296.664185,-0.001742,0.004153,0.105480,296.243011,15.091338,1.054805,-1296.664185,294.500458,0.000000
67.190002,65.314133,-1296.708740,-0.001720,0.004125,0.104787,290.531769,14.800394,1.047871,-1296.708740,294.500458,0.000000
67.580002,65.310410,-1296.619751,-0.001699,0.004160,0.105655,290.515198,14.799551,1.056546,-1296.619751,294.500458,0.000000
67.970001,65.019211,-1296.753174,-0.001720,0.004167,0.105845,289.219879,14.733563,1.058453,-1296.753174,294.500458,0.000000
68.360001,65.178207,-1296.708740,-0.001707,0.004178,0.106122,289.927155,14.769593,1.061224,-1296.708740,294.500458,0.000000
68.750000,64.910477,-1296.619751,-0.001699,0.004184,0.106262,288.736206,14.708923,1.062617,-1296.619751,294.500458,0.000000
69.140007,65.120132,-1296.708740,-0.001699,0.004193,0.106504,289.668823,14.756433,1.065039,-1296.708740,294.500458,0.000000
69.530006,65.188644,-1296.708740,-0.001677,0.004203,0.106764,289.973572,14.771957,1.067643,-1296.708740,294.500458,0.000000
69.920006,65.345032,-1296.664185,-0.001690,0.004212,0.106990,290.669220,14.807396,1.069899,-1296.664185,294.500458,0.000000
70.310005,65.061661,-1296.708740,-0.001660,0.004217,0.107111,289.408722,14.743183,1.071110,-1296.708740,294.500458,0.000000
70.700005,65.474991,-1296.664185,-0.001647,0.004226,0.107346,291.247314,14.836845,1.073457,-1296.664185,294.500458,0.000000
71.090004,65.003204,-1296.708740,-0.001656,0.004231,0.107459,289.148682,14.729937,1.074592,-1296.708740,294.500458,0.000000
71.480003,65.411316,-1296.664185,-0.001638,0.004240,0.107701,290.964050,14.822415,1.077015,-1296.664185,294.500458,0.000000
71.870003,65.029633,-1296.797607,-0.001660,0.004241,0.107711,289.266266,14.735926,1.077105,-1296.797607,294.500458,0.000000
72.260002,65.713684,-1296.664185,-0.001630,0.004253,0.108031,292.309052,14.890933,1.080315,-1296.664185,294.500458,0.000000
72.650002,65.197571,-1296.708740,-0.001638,0.004253,0.108031,290.013275,14.773981,1.080315,-1296.708740,294.500458,0.000000
73.040001,65.368118,-1296.753174,-0.001621,0.004263,0.108274,290.771912,14.812628,1.082737,-1296.753174,294.500458,0.000000
73.430000,64.985703,-1296.708740,-0.001617,0.004263,0.108274,289.070831,14.725970,1.082737,-1296.708740,294.500458,0.000000
73.820000,65.112671,-1296.708740,-0.001621,0.004270,0.108464,289.635620,14.754742,1.084645,-1296.708740,294.500458,0.000000
74.210007,65.502930,-1296.797607,-0.001617,0.004280,0.108707,291.371582,14.843176,1.087067,-1296.797607,294.500458,0.000000
74.600006,65.101883,-1296.619751,-0.001604,0.004279,0.108690,289.587646,14.752297,1.086901,-1296.619751,294.500458,0.000000
74.990005,65.578140,-1296.797607,-0.001617,0.004289,0.108950,291.706146,14.860219,1.089505,-1296.797607,294.500458,0.000000
75.380005,65.226624,-1296.708740,-0.001600,0.004289,0.108950,290.142517,14.780564,1.089505,-1296.708740,294.500458,0.000000
75.770004,64.776428,-1296.708740,-0.001591,0.004289,0.108950,288.139954,14.678548,1.089505,-1296.708740,294.500458,0.000000
76.160004,64.334045,-1296.842163,-0.001604,0.004290,0.108960,286.172119,14.578302,1.089596,-1296.842163,294.500458,0.000000
76.550003,64.530289,-1296.708740,-0.001587,0.004328,0.109930,287.045074,14.622772,1.099300,-1296.708740,294.500458,0.000000
76.940002,65.227371,-1296.753174,-0.001513,0.004231,0.107476,290.145844,14.780734,1.074759,-1296.753174,294.500458,0.000000
77.330002,65.274658,-1296.708740,-0.001496,0.004296,0.109115,290.356171,14.791450,1.091155,-1296.708740,294.500458,0.000000
77.720001,65.308548,-1296.797607,-0.001513,0.004304,0.109323,290.506927,14.799129,1.093229,-1296.797607,294.500458,0.000000
78.110001,65.185287,-1296.797607,-0.001500,0.004309,0.109453,289.958649,14.771197,1.094531,-1296.797607,294.500458,0.000000
78.500000,65.454514,-1296.753174,-0.001513,0.004320,0.109723,291.156219,14.832205,1.097226,-1296.753174,294.500458,0.000000
78.890007,65.163315,-1296.842163,-0.001509,0.004320,0.109723,289.860901,14.766218,1.097226,-1296.842163,294.500458,0.000000
79.280006,64.851273,-1296.842163,-0.001505,0.004327,0.109904,288.472870,14.695509,1.099043,-1296.842163,294.500458,0.000000
79.670006,65.334976,-1296.753174,-0.001509,0.004330,0.109991,290.624481,14.805117,1.099906,-1296.753174,294.500458,0.000000
80.060005,65.031876,-1296.842163,-0.001509,0.004330,0.109991,289.276245,14.736434,1.099906,-1296.842163,294.500458,0.000000
80.450005,65.038574,-1296.753174,-0.001496,0.004336,0.110139,289.306030,14.737952,1.101389,-1296.753174,294.500458,0.000000
80.840004,65.196838,-1296.753174,-0.001500,0.004341,0.110268,290.010010,14.773814,1.102676,-1296.753174,294.500458,0.000000
81.230003,64.991653,-1296.797607,-0.001496,0.004341,0.110268,289.097321,14.727320,1.102676,-1296.797607,294.500458,0.000000
81.620003,65.315628,-1296.797607,-0.001518,0.004349,0.110458,290.538422,14.800733,1.104584,-1296.797607,294.500458,0.000000
82.010002,65.140976,-1296.842163,-0.001513,0.004349,0.110458,289.761536,14.761156,1.104584,-1296.842163,294.500458,0.000000
82.400002,64.992035,-1296.797607,-0.001496,0.004351,0.110520,289.098999,14.727406,1.105204,-1296.797607,294.500458,0.000000
82.790001,64.994629,-1296.886597,-0.001518,0.004354,0.110598,289.110535,14.727993,1.105977,-1296.886597,294.500458,0.000000
83.180000,65.096298,-1296.842163,-0.001505,0.004359,0.110711,289.562805,14.751032,1.107112,-1296.842163,294.500458,0.000000
83.570007,64.879578,-1296.753174,-0.001500,0.004359,0.110711,288.598785,14.701922,1.107112,-1296.753174,294.500458,0.000000
83.960007,64.877335,-1296.886597,-0.001513,0.004370,0.110997,288.588806,14.701414,1.109973,-1296.886597,294.500458,0.000000
84.350006,65.485046,-1296.842163,-0.001496,0.004370,0.110997,291.292023,14.839124,1.109973,-1296.842163,294.500458,0.000000
84.740005,65.257156,-1296.842163,-0.001505,0.004370,0.110997,290.278320,14.787483,1.109973,-1296.842163,294.500458,0.000000
85.130005,65.010269,-1296.842163,-0.001518,0.004370,0.110997,289.180115,14.731537,1.109973,-1296.842163,294.500458,0.000000
85.520004,64.752960,-1296.842163,-0.001500,0.004370,0.110997,288.035553,14.673230,1.109973,-1296.842163,294.500458,0.000000
85.910004,65.627289,-1296.931030,-0.001500,0.004382,0.111300,291.924774,14.871357,1.113001,-1296.931030,294.500458,0.000000
86.300003,65.438126,-1296.886597,-0.001492,0.004382,0.111300,291.083313,14.828491,1.113001,-1296.886597,294.500458,0.000000
86.690002,65.198318,-1296.842163,-0.001500,0.004382,0.111300,290.016602,14.774151,1.113001,-1296.842163,294.500458,0.000000
87.080002,64.955536,-1296.931030,-0.001492,0.004382,0.111300,288.936646,14.719135,1.113001,-1296.931030,294.500458,0.000000
87.470001,64.701950,-1296.886597,-0.001496,0.004382,0.111300,287.808655,14.661672,1.113001,-1296.886597,294.500458,0.000000
87.860001,64.459534,-1296.931030,-0.001496,0.004382,0.111309,286.730316,14.606739,1.113092,-1296.931030,294.500458,0.000000
88.250008,65.776611,-1296.886597,-0.001479,0.004403,0.111838,292.588989,14.905192,1.118376,-1296.886597,294.500458,0.000000
88.640007,65.763962,-1296.886597,-0.001487,0.004398,0.111716,292.532715,14.902327,1.117165,-1296.886597,294.500458,0.000000
89.030006,65.521545,-1296.931030,-0.001483,0.004398,0.111716,291.454376,14.847394,1.117165,-1296.931030,294.500458,0.000000
89.420006,65.294022,-1296.842163,-0.001479,0.004398,0.111716,290.442322,14.795836,1.117165,-1296.842163,294.500458,0.000000
89.810005,65.072464,-1296.931030,-0.001483,0.004398,0.111716,289.456787,14.745631,1.117165,-1296.931030,294.500458,0.000000
90.200005,64.857224,-1296.931030,-0.001475,0.004399,0.111726,288.499329,14.696856,1.117256,-1296.931030,294.500458,0.000000
90.590004,64.656891,-1296.886597,-0.001479,0.004399,0.111726,287.608215,14.651461,1.117256,-1296.886597,294.500458,0.000000
90.980003,64.441284,-1296.886597,-0.001466,0.004399,0.111726,286.649139,14.602604,1.117256,-1296.886597,294.500458,0.000000
91.370003,66.372787,-1296.886597,-0.001470,0.004407,0.111925,295.240906,15.040289,1.119254,-1296.886597,294.500458,0.000000
91.760002,66.103928,-1297.020020,-0.001487,0.004406,0.111907,294.044952,14.979364,1.119072,-1297.020020,294.500458,0.000000
92.150002,65.863007,-1296.886597,-0.001466,0.004406,0.111907,292.973297,14.924770,1.119072,-1296.886597,294.500458,0.000000
92.540001,65.603836,-1296.931030,-0.001475,0.004406,0.111907,291.820435,14.866042,1.119072,-1296.931030,294.500458,0.000000
92.930008,65.418396,-1296.931030,-0.001457,0.004406,0.111907,290.995544,14.824020,1.119072,-1296.931030,294.500458,0.000000
93.320007,65.211349,-1296.842163,-0.001457,0.004406,0.111907,290.074585,14.777102,1.119072,-1296.842163,294.500458,0.000000
93.710007,64.993515,-1296.931030,-0.001475,0.004406,0.111916,289.105591,14.727740,1.119163,-1296.931030,294.500458,0.000000
94.100006,64.765259,-1296.886597,-0.001453,0.004406,0.111916,288.090271,14.676017,1.119163,-1296.886597,294.500458,0.000000
94.490005,65.618729,-1296.931030,-0.001470,0.004426,0.112428,291.886688,14.869416,1.124280,-1296.931030,294.500458,0.000000
94.880005,65.519684,-1296.975586,-0.001449,0.004426,0.112428,291.446106,14.846972,1.124280,-1296.975586,294.500458,0.000000
95.270004,65.322327,-1296.886597,-0.001444,0.004426,0.112428,290.568207,14.802251,1.124280,-1296.886597,294.500458,0.000000
95.660004,65.164810,-1296.886597,-0.001462,0.004426,0.112428,289.867554,14.766557,1.124280,-1296.886597,294.500458,0.000000
96.050003,64.990540,-1296.931030,-0.001444,0.004426,0.112428,289.092346,14.727067,1.124280,-1296.931030,294.500458,0.000000
96.440002,64.803604,-1296.975586,-0.001449,0.004426,0.112428,288.260834,14.684707,1.124280,-1296.975586,294.500458,0.000000
96.830002,64.657272,-1296.975586,-0.001453,0.004427,0.112437,287.609924,14.651547,1.124371,-1296.975586,294.500458,0.000000
97.220001,64.474426,-1296.931030,-0.001440,0.004427,0.112437,286.796570,14.610113,1.124371,-1296.931030,294.500458,0.000000
97.610008,66.351181,-1297.020020,-0.001444,0.004419,0.112245,295.144806,15.035393,1.122448,-1297.020020,294.500458,0.000000
98.000008,66.146378,-1296.931030,-0.001440,0.004419,0.112245,294.233795,14.988984,1.122448,-1296.931030,294.500458,0.000000
98.390007,65.925201,-1296.975586,-0.001444,0.004419,0.112254,293.249939,14.938865,1.122539,-1296.975586,294.500458,0.000000
98.780006,65.797104,-1296.975586,-0.001449,0.004419,0.112254,292.680145,14.909837,1.122539,-1296.975586,294.500458,0.000000
99.170006,65.589691,-1296.975586,-0.001444,0.004419,0.112254,291.757507,14.862837,1.122539,-1296.975586,294.500458,0.000000
99.560005,65.400528,-1296.975586,-0.001436,0.004419,0.112254,290.916077,14.819972,1.122539,-1296.975586,294.500458,0.000000
99.950005,65.255295,-1296.975586,-0.001431,0.004419,0.112254,290.270050,14.787061,1.122539,-1296.975586,294.500458,0.000000
100.340004,65.055328,-1296.975586,-0.001449,0.004419,0.112254,289.380554,14.741748,1.122539,-1296.975586,294.500458,0.000000
100.730003,65.112305,-1297.020020,-0.001423,0.004443,0.112852,289.634003,14.754659,1.128519,-1297.020020,294.500458,0.000000
101.120003,65.133530,-1297.020020,-0.001440,0.004446,0.112940,289.728424,14.759469,1.129398,-1297.020020,294.500458,0.000000
101.510002,65.100021,-1297.020020,-0.001431,0.004448,0.112975,289.579346,14.751876,1.129746,-1297.020020,294.500458,0.000000
101.900002,65.117889,-1297.064575,-0.001427,0.004451,0.113052,289.658844,14.755924,1.130518,-1297.064575,294.500458,0.000000
102.290009,65.108948,-1297.020020,-0.001436,0.004451,0.113052,289.619049,14.753899,1.130518,-1297.020020,294.500458,0.000000
102.680008,65.018097,-1297.020020,-0.001423,0.004452,0.113070,289.214935,14.733311,1.130700,-1297.020020,294.500458,0.000000
103.070007,64.973785,-1297.020020,-0.001418,0.004453,0.113096,289.017822,14.723270,1.130957,-1297.020020,294.500458,0.000000
103.460007,64.982346,-1297.064575,-0.001436,0.004456,0.113182,289.055908,14.725209,1.131820,-1297.064575,294.500458,0.000000
103.850006,64.978989,-1297.064575,-0.001423,0.004456,0.113182,289.040985,14.724449,1.131820,-1297.064575,294.500458,0.000000
104.240005,64.863556,-1297.064575,-0.001423,0.004456,0.113191,288.527496,14.698292,1.131911,-1297.064575,294.500458,0.000000
104.630005,65.481323,-1297.153442,-0.001436,0.004465,0.113398,291.275482,14.838281,1.133985,-1297.153442,294.500458,0.000000
105.020004,65.393066,-1297.064575,-0.001410,0.004465,0.113398,290.882874,14.818280,1.133985,-1297.064575,294.500458,0.000000
105.410004,65.308167,-1297.109009,-0.001423,0.004465,0.113398,290.505219,14.799042,1.133985,-1297.109009,294.500458,0.000000
105.800003,65.205399,-1297.109009,-0.001418,0.004465,0.113398,290.048096,14.775755,1.133985,-1297.109009,294.500458,0.000000
106.190002,65.065384,-1297.109009,-0.001423,0.004465,0.113398,289.425293,14.744026,1.133985,-1297.109009,294.500458,0.000000
106.580002,65.045273,-1297.153442,-0.001427,0.004466,0.113433,289.335815,14.739470,1.134333,-1297.153442,294.500458,0.000000
106.970009,64.971542,-1297.064575,-0.001410,0.004466,0.113442,289.007843,14.722762,1.134424,-1297.064575,294.500458,0.000000
107.360008,64.857971,-1297.109009,-0.001431,0.004466,0.113442,288.502655,14.697026,1.134424,-1297.109009,294.500458,0.000000
107.750008,65.175232,-1297.153442,-0.001418,0.004472,0.113582,289.913910,14.768919,1.135817,-1297.153442,294.500458,0.000000
108.140007,65.094803,-1297.109009,-0.001410,0.004472,0.113582,289.556152,14.750693,1.135817,-1297.109009,294.500458,0.000000
108.530006,65.016983,-1297.109009,-0.001414,0.004472,0.113582,289.209991,14.733059,1.135817,-1297.109009,294.500458,0.000000
108.920006,64.930588,-1297.153442,-0.001427,0.004472,0.113582,288.825684,14.713481,1.135817,-1297.153442,294.500458,0.000000
109.310005,64.790207,-1297.153442,-0.001418,0.004472,0.113589,288.201233,14.681670,1.135892,-1297.153442,294.500458,0.000000
109.700005,65.321213,-1297.153442,-0.001406,0.004481,0.113807,290.563263,14.801998,1.138072,-1297.153442,294.500458,0.000000
110.090004,65.342056,-1297.109009,-0.001410,0.004481,0.113807,290.655975,14.806722,1.138072,-1297.109009,294.500458,0.000000
110.480003,65.295517,-1297.242432,-0.001418,0.004481,0.113807,290.448975,14.796175,1.138072,-1297.242432,294.500458,0.000000
110.870003,65.213211,-1297.197998,-0.001418,0.004481,0.113807,290.082855,14.777525,1.138072,-1297.197998,294.500458,0.000000
111.260002,65.110077,-1297.242432,-0.001418,0.004481,0.113807,289.624084,14.754154,1.138072,-1297.242432,294.500458,0.000000
111.650002,65.015488,-1297.153442,-0.001401,0.004481,0.113807,289.203339,14.732720,1.138072,-1297.153442,294.500458,0.000000
112.040009,64.926117,-1297.153442,-0.001423,0.004481,0.113807,288.805786,14.712468,1.138072,-1297.153442,294.500458,0.000000
112.430008,64.903778,-1297.197998,-0.001406,0.004483,0.113859,288.706421,14.707407,1.138587,-1297.197998,294.500458,0.000000
112.820007,64.844940,-1297.153442,-0.001406,0.004483,0.113859,288.444702,14.694074,1.138587,-1297.153442,294.500458,0.000000
113.210007,64.876221,-1297.197998,-0.001406,0.004485,0.113910,288.583832,14.701161,1.139102,-1297.197998,294.500458,0.000000
113.600006,64.819244,-1297.242432,-0.001397,0.004485,0.113910,288.330414,14.688251,1.139102,-1297.242432,294.500458,0.000000
113.990005,64.734726,-1297.242432,-0.001410,0.004485,0.113910,287.954437,14.669099,1.139102,-1297.242432,294.500458,0.000000
114.380005,65.682404,-1297.153442,-0.001393,0.004497,0.114224,292.169922,14.883845,1.142236,-1297.153442,294.500458,0.000000
114.770004,65.743851,-1297.197998,-0.001388,0.004497,0.114224,292.443268,14.897769,1.142236,-1297.197998,294.500458,0.000000
115.160004,65.684265,-1297.286987,-0.001414,0.004497,0.114224,292.178192,14.884267,1.142236,-1297.286987,294.500458,0.000000
115.550003,65.597137,-1297.242432,-0.001393,0.004497,0.114224,291.790649,14.864524,1.142236,-1297.242432,294.500458,0.000000
115.940002,65.541275,-1297.197998,-0.001406,0.004497,0.114224,291.542145,14.851865,1.142236,-1297.197998,294.500458,0.000000
116.330002,65.470520,-1297.286987,-0.001397,0.004497,0.114224,291.227417,14.835832,1.142236,-1297.286987,294.500458,0.000000
116.720009,65.357330,-1297.153442,-0.001393,0.004497,0.114224,290.723938,14.810183,1.142236,-1297.153442,294.500458,0.000000
117.110008,65.273544,-1297.286987,-0.001410,0.004497,0.114224,290.351227,14.791197,1.142236,-1297.286987,294.500458,0.000000
117.500008,65.187897,-1297.242432,-0.001401,0.004497,0.114224,289.970245,14.771788,1.142236,-1297.242432,294.500458,0.000000
117.890007,65.092941,-1297.197998,-0.001397,0.004497,0.114224,289.547852,14.750272,1.142236,-1297.197998,294.500458,0.000000
118.280006,65.000595,-1297.197998,-0.001388,0.004497,0.114224,289.137085,14.729345,1.142236,-1297.197998,294.500458,0.000000
118.670006,64.907867,-1297.153442,-0.001401,0.004497,0.114224,288.724609,14.708333,1.142236,-1297.153442,294.500458,0.000000
119.060005,64.792068,-1297.286987,-0.001393,0.004497,0.114224,288.209503,14.682093,1.142236,-1297.286987,294.500458,0.000000
119.450005,64.715729,-1297.197998,-0.001393,0.004497,0.114224,287.869934,14.664794,1.142236,-1297.197998,294.500458,0.000000
119.840004,64.610352,-1297.197998,-0.001388,0.004497,0.114224,287.401184,14.640915,1.142236,-1297.197998,294.500458,0.000000
120.230003,65.855560,-1297.242432,-0.001388,0.004511,0.114578,292.940155,14.923083,1.145779,-1297.242432,294.500458,0.000000
120.620003,65.811996,-1297.153442,-0.001393,0.004511,0.114578,292.746368,14.913212,1.145779,-1297.153442,294.500458,0.000000
121.010002,65.759109,-1297.242432,-0.001393,0.004511,0.114578,292.511139,14.901227,1.145779,-1297.242432,294.500458,0.000000
121.400009,65.682785,-1297.242432,-0.001375,0.004511,0.114578,292.171631,14.883932,1.145779,-1297.242432,294.500458,0.000000
121.790009,65.587448,-1297.197998,-0.001384,0.004511,0.114578,291.747528,14.862329,1.145779,-1297.197998,294.500458,0.000000
122.180008,65.533081,-1297.286987,-0.001393,0.004511,0.114578,291.505707,14.850009,1.145779,-1297.286987,294.500458,0.000000
122.570007,65.454895,-1297.153442,-0.001406,0.004511,0.114578,291.157928,14.832291,1.145779,-1297.153442,294.500458,0.000000
122.960007,65.351746,-1297.197998,-0.001380,0.004511,0.114578,290.699097,14.808917,1.145779,-1297.197998,294.500458,0.000000
123.350006,65.290665,-1297.242432,-0.001380,0.004511,0.114578,290.427368,14.795076,1.145779,-1297.242432,294.500458,0.000000
123.740005,65.216934,-1297.242432,-0.001375,0.004511,0.114578,290.099426,14.778368,1.145779,-1297.242432,294.500458,0.000000
124.130005,65.110809,-1297.197998,-0.001380,0.004511,0.114578,289.627350,14.754320,1.145779,-1297.197998,294.500458,0.000000
124.520004,65.022934,-1297.153442,-0.001375,0.004511,0.114578,289.236450,14.734407,1.145779,-1297.153442,294.500458,0.000000
124.910004,64.951447,-1297.286987,-0.001375,0.004511,0.114578,288.918457,14.718208,1.145779,-1297.286987,294.500458,0.000000
125.300003,64.857605,-1297.242432,-0.001384,0.004511,0.114578,288.501038,14.696943,1.145779,-1297.242432,294.500458,0.000000
125.690002,64.775681,-1297.286987,-0.001388,0.004511,0.114578,288.136627,14.678379,1.145779,-1297.286987,294.500458,0.000000
126.080009,64.698227,-1297.286987,-0.001384,0.004511,0.114578,287.792084,14.660829,1.145779,-1297.286987,294.500458,0.000000
126.470009,64.619278,-1297.286987,-0.001384,0.004511,0.114578,287.440918,14.642938,1.145779,-1297.286987,1681.640747,0.000000
126.860008,64.498260,-1297.331421,-0.001397,0.004502,0.114352,286.902588,14.615515,1.143523,-1297.331421,0.114154,0.000000
127.250008,64.375000,-1297.331421,-0.001384,0.004480,0.113798,286.354309,14.587584,1.137982,-1297.331421,0.113503,0.000000
127.640007,64.278564,-1297.286987,-0.001375,0.004459,0.113252,285.925323,14.565731,1.132516,-1297.286987,0.112852,0.000000
128.029999,64.138184,-1297.331421,-0.001375,0.004428,0.112480,285.300903,14.533920,1.124795,-1297.331421,0.112202,0.000000
128.420013,64.043594,-1297.331421,-0.001358,0.004413,0.112089,284.880127,14.512486,1.120889,-1297.331421,0.111551,0.000000
128.810013,63.924805,-1297.331421,-0.001350,0.004385,0.111386,284.351746,14.485568,1.113864,-1297.331421,0.110902,0.000000
129.200012,63.852203,-1297.331421,-0.001354,0.004359,0.110728,284.028778,14.469116,1.107279,-1297.331421,0.110251,0.000000
129.590012,63.755005,-1297.331421,-0.001362,0.004338,0.110181,283.596436,14.447090,1.101813,-1297.331421,0.109600,0.000000
129.980011,63.662292,-1297.286987,-0.001354,0.004303,0.109306,283.184021,14.426082,1.093063,-1297.286987,0.108950,0.000000
130.370010,63.555420,-1297.375854,-0.001345,0.004292,0.109020,282.708618,14.401864,1.090201,-1297.375854,0.108299,0.000000
130.760010,63.328644,-1297.375854,-0.001354,0.004265,0.108325,281.699890,14.350476,1.083252,-1297.375854,0.107650,0.000000
131.150009,62.433456,-1297.286987,-0.001350,0.004238,0.107641,277.717896,14.147624,1.076409,-1297.286987,0.106999,0.000000
131.540009,61.389694,-1297.331421,-0.001345,0.004214,0.107034,273.075012,13.911104,1.070338,-1297.331421,0.106357,0.000000
131.930008,60.271835,-1297.331421,-0.001315,0.004194,0.106522,268.102509,13.657793,1.065221,-1297.331421,0.105706,0.000000
132.320007,58.760750,-1297.331421,-0.001311,0.004175,0.106045,261.380859,13.315376,1.060452,-1297.331421,0.105057,0.000000
132.710007,57.690552,-1297.375854,-0.001302,0.004162,0.105724,256.620392,13.072865,1.057242,-1297.375854,0.104406,0.000000
133.100006,55.301407,-1297.375854,-0.001311,0.004132,0.104961,245.992950,12.531478,1.049612,-1297.375854,0.103756,0.000000
133.490005,52.607666,-1297.375854,-0.001315,0.004103,0.104215,234.010590,11.921067,1.042148,-1297.375854,0.103105,0.000000
133.880005,50.230064,-1297.420410,-0.001302,0.004077,0.103547,223.434479,11.382296,1.035472,-1297.420410,0.102454,0.000000
134.270004,46.571136,-1297.331421,-0.001293,0.004046,0.102767,207.158768,10.553170,1.027675,-1297.331421,0.101805,0.000000
134.660004,46.249031,-1297.509399,-0.001302,0.004046,0.102767,205.725967,10.480180,1.027675,-1297.509399,0.101154,0.000000
135.050003,42.215126,-1297.375854,-0.001311,0.004003,0.101665,187.782257,9.566085,1.016653,-1297.375854,0.100504,0.000000
135.440002,39.096878,-1297.464844,-0.001306,0.003977,0.101014,173.911606,8.859479,1.010143,-1297.464844,0.099853,0.000000
135.830002,36.875298,-1297.420410,-0.001298,0.003961,0.100607,164.029510,8.356062,1.006070,-1297.420410,0.099202,0.000000
136.220001,33.002998,-1297.286987,-0.001302,0.003926,0.099723,146.804672,7.478587,0.997229,-1297.286987,0.098553,0.000000
136.610001,29.977104,-1297.420410,-0.001293,0.003898,0.099004,133.344818,6.792909,0.990038,-1297.420410,0.097902,0.000000
137.000000,26.809326,-1297.420410,-0.001298,0.003869,0.098283,119.253838,6.075080,0.982831,-1297.420410,0.097251,0.000000
137.389999,25.044655,-1297.420410,-0.001311,0.003854,0.097902,111.404190,5.675200,0.979016,-1297.420410,0.096601,0.000000
137.780014,21.796082,-1297.420410,-0.001306,0.003827,0.097199,96.953812,4.939063,0.971991,-1297.420410,0.095950,0.000000
138.170013,18.548248,-1297.420410,-0.001298,0.003794,0.096376,82.506729,4.203093,0.963755,-1297.420410,0.095301,0.000000
138.560013,15.781891,-1297.464844,-0.001315,0.003770,0.095768,70.201355,3.576228,0.957684,-1297.464844,0.094650,0.000000
138.950012,12.745193,-1297.420410,-0.001293,0.003745,0.095117,56.693451,2.888102,0.951174,-1297.420410,0.093999,0.000000
139.340012,10.313232,-1297.464844,-0.001293,0.003720,0.094494,45.875549,2.337012,0.944937,-1297.464844,0.093349,0.000000
139.730011,8.192940,-1297.420410,-0.001298,0.003699,0.093947,36.444016,1.856547,0.939471,-1297.420410,0.092698,0.000000
140.120010,6.833778,-1297.464844,-0.001306,0.003679,0.093435,30.398165,1.548556,0.934354,-1297.464844,0.092049,0.000000
140.510010,3.462318,-1297.509399,-0.001293,0.003651,0.092733,15.401161,0.784573,0.927330,-1297.509399,0.091398,0.000000
140.900009,0.879547,-1297.375854,-0.001302,0.003622,0.092005,3.912421,0.199308,0.920047,-1297.375854,0.090756,0.000000
141.290009,-1.303303,-1297.509399,-0.001298,0.003594,0.091284,-5.797380,-0.295333,0.912841,-1297.509399,0.090105,0.000000
141.680008,-3.717022,-1297.598267,-0.001302,0.003568,0.090616,-16.534140,-0.842289,0.906164,-1297.598267,0.089455,0.000000
142.070007,-5.776985,-1297.464844,-0.001306,0.003540,0.089914,-25.697313,-1.309083,0.899140,-1297.464844,0.088804,0.000000
142.460007,-0.358597,-1297.509399,-0.001268,0.003516,0.089316,-1.595118,-0.081259,0.893160,-1297.509399,0.088155,0.000000
142.850006,-0.327690,-1297.420410,-0.001272,0.003489,0.088613,-1.457639,-0.074256,0.886135,-1297.420410,0.087504,0.000000
143.240005,-0.121391,-1297.464844,-0.001285,0.003459,0.087860,-0.539975,-0.027508,0.878595,-1297.464844,0.086853,0.000000
143.630005,-0.049149,-1297.509399,-0.001272,0.003437,0.087304,-0.218624,-0.011137,0.873039,-1297.509399,0.086203,0.000000
144.020004,-0.025696,-1297.375854,-0.001276,0.003419,0.086845,-0.114301,-0.005823,0.868452,-1297.375854,0.085552,0.000000
144.410004,-0.056602,-1297.509399,-0.001272,0.003386,0.086003,-0.251780,-0.012826,0.860034,-1297.509399,0.084901,0.000000
144.800003,-0.081177,-1297.464844,-0.001272,0.003363,0.085431,-0.361092,-0.018395,0.854311,-1297.464844,0.084252,0.000000
145.190002,-0.128838,-1297.509399,-0.001276,0.003334,0.084685,-0.573098,-0.029195,0.846848,-1297.509399,0.083601,0.000000
145.580002,-0.120277,-1297.509399,-0.001272,0.003308,0.084017,-0.535021,-0.027255,0.840171,-1297.509399,0.082951,0.000000
145.970001,-0.088997,-1297.464844,-0.001263,0.003287,0.083498,-0.395878,-0.020167,0.834978,-1297.464844,0.082300,0.000000
146.360001,-0.113945,-1297.464844,-0.001276,0.003267,0.082986,-0.506853,-0.025820,0.829861,-1297.464844,0.081649,0.000000
146.750000,-0.144478,-1297.375854,-0.001272,0.003231,0.082066,-0.642670,-0.032739,0.820656,-1297.375854,0.081000,0.000000
147.139999,-0.144104,-1297.509399,-0.001293,0.003200,0.081277,-0.641007,-0.032654,0.812768,-1297.509399,0.080349,0.000000
147.530014,-0.162727,-1297.464844,-0.001281,0.003173,0.080600,-0.723847,-0.036875,0.806001,-1297.464844,0.079699,0.000000
147.920013,-0.144478,-1297.420410,-0.001281,0.003148,0.079967,-0.642670,-0.032739,0.799673,-1297.420410,0.079048,0.000000
148.310013,-0.174271,-1297.509399,-0.001298,0.003123,0.079318,-0.775194,-0.039490,0.793178,-1297.509399,0.078397,0.000000
148.700012,-0.171288,-1297.464844,-0.001306,0.003106,0.078883,-0.761925,-0.038814,0.788833,-1297.464844,0.077748,0.000000
149.090012,-0.183205,-1297.509399,-0.001311,0.003069,0.077946,-0.814935,-0.041515,0.779461,-1297.509399,0.077097,0.000000
149.480011,-0.160492,-1297.509399,-0.001315,0.003046,0.077366,-0.713904,-0.036368,0.773663,-1297.509399,0.076446,0.000000
149.870010,-0.170174,-1297.420410,-0.001358,0.003020,0.076715,-0.756970,-0.038562,0.767153,-1297.420410,0.075805,0.000000
150.260010,-0.189537,-1297.464844,-0.001367,0.002990,0.075952,-0.843103,-0.042950,0.759522,-1297.464844,0.075154,0.000000
150.650009,-0.167564,-1297.420410,-0.001388,0.002977,0.075622,-0.745364,-0.037971,0.756222,-1297.420410,0.074503,0.000000
151.040009,-0.200706,-1297.553833,-0.001418,0.002943,0.074764,-0.892787,-0.045481,0.747638,-1297.553833,0.073854,0.000000
151.430008,-0.202568,-1297.509399,-0.001449,0.002921,0.074182,-0.901068,-0.045903,0.741824,-1297.509399,0.073203,0.000000
151.820007,-0.211136,-1297.553833,-0.001466,0.002896,0.073559,-0.939179,-0.047844,0.735587,-1297.553833,0.072553,0.000000
152.210007,-0.199593,-1297.464844,-0.001496,0.002869,0.072865,-0.887832,-0.045228,0.728653,-1297.464844,0.071902,0.000000
152.600006,-0.212250,-1297.509399,-0.001509,0.002846,0.072284,-0.944134,-0.048096,0.722839,-1297.509399,0.071251,0.000000
152.990005,-0.221931,-1297.553833,-0.001565,0.002815,0.071512,-0.987200,-0.050290,0.715118,-1297.553833,0.070602,0.000000
153.380005,-0.233101,-1297.553833,-0.001556,0.002795,0.071000,-1.036885,-0.052821,0.710001,-1297.553833,0.069951,0.000000
153.770004,-0.214859,-1297.553833,-0.001595,0.002778,0.070549,-0.955741,-0.048688,0.705489,-1297.553833,0.069300,0.000000
154.160004,-0.198471,-1297.553833,-0.001638,0.002739,0.069569,-0.882843,-0.044974,0.695694,-1297.553833,0.068650,0.000000
154.550003,-0.203690,-1297.553833,-0.001656,0.002714,0.068937,-0.906056,-0.046157,0.689366,-1297.553833,0.067999,0.000000
154.940002,-0.235336,-1297.553833,-0.001686,0.002690,0.068320,-1.046828,-0.053328,0.683204,-1297.553833,0.067350,0.000000
155.330002,-0.216721,-1297.598267,-0.001703,0.002671,0.067843,-0.964021,-0.049110,0.678435,-1297.598267,0.066699,0.000000
155.720001,-0.218582,-1297.553833,-0.001733,0.002643,0.067141,-0.972302,-0.049531,0.671410,-1297.553833,0.066048,0.000000
156.110001,-0.175758,-1297.464844,-0.001772,0.002614,0.066387,-0.781812,-0.039827,0.663871,-1297.464844,0.066292,0.000000
156.200012,-0.183205,-1297.509399,-0.001776,0.002614,0.066387,-0.814935,-0.041515,0.663871,-1297.509399,0.066292,0.000000