File: Data/Symmetrical membranes compression/Durapore PVDF 5um test 2-3.csv
Time (sec),S:Load (lbs),S:HL1 (DIM),S:LVDT (in),S:Position (in),Ch:Position (mm),Ch:Load (N),Ch:Stress (MPa),Ch:Strain (mm/mm),Ch:HL1 (DIM),Set Point (),Cycles ()
0.010000,-0.009308,-37.897770,0.000000,-0.000000,-0.000000,-0.041403,-0.002109,-0.000000,-37.897770,0.000199,0.000000
0.240000,-0.000374,-37.853291,0.000004,-0.000000,-0.000000,-0.001663,-0.000085,-0.000000,-37.853291,0.000199,0.000000
0.470000,0.010429,-37.808807,-0.000004,0.000057,0.001448,0.046392,0.002363,0.014483,-37.808807,0.002212,0.000000
0.700000,-0.024574,-37.808807,0.000034,0.000185,0.004692,-0.109312,-0.005569,0.046918,-37.808807,0.006045,0.000000
0.930000,-0.014153,-37.808807,0.000198,0.000337,0.008560,-0.062954,-0.003207,0.085595,-37.808807,0.009878,0.000000
1.160000,-0.007072,-37.853291,0.000358,0.000487,0.012358,-0.031460,-0.001603,0.123581,-37.853291,0.013711,0.000000
1.390000,0.009308,-37.897770,0.000504,0.000648,0.016460,0.041403,0.002109,0.164599,-37.897770,0.017544,0.000000
1.620000,0.049156,-37.808807,0.000664,0.000793,0.020146,0.218658,0.011139,0.201457,-37.808807,0.021377,0.000000
1.850000,0.154160,-37.897770,0.000854,0.000941,0.023892,0.685736,0.034933,0.238921,-37.897770,0.025210,0.000000
2.080000,0.310928,-37.897770,0.000987,0.001092,0.027743,1.383078,0.070457,0.277427,-37.897770,0.029043,0.000000
2.310000,0.564888,-37.853291,0.001151,0.001243,0.031567,2.512747,0.128005,0.315672,-37.853291,0.032877,0.000000
2.540000,0.667290,-37.853291,0.001242,0.000001,0.000017,2.968253,0.151210,0.000174,-37.853291,0.000286,0.000000
2.770000,0.628563,-37.853291,0.001255,0.000001,0.000017,2.795988,0.142434,0.000174,-37.853291,0.000286,0.000000
3.000000,0.622238,-37.897770,0.001250,0.000001,0.000017,2.767853,0.141001,0.000174,-37.897770,0.000382,0.000000
3.230000,0.542923,-37.942253,0.001255,0.000001,0.000017,2.415042,0.123028,0.000174,-37.942253,0.000763,0.000000
3.460000,0.534729,-37.897770,0.001259,0.000007,0.000173,2.378593,0.121171,0.001733,-37.897770,0.001145,0.000000
3.690000,0.607338,-37.808807,0.001263,0.000024,0.000598,2.701574,0.137625,0.005984,-37.808807,0.001535,0.000000
3.920000,0.671387,-37.897770,0.001272,0.000039,0.000980,2.986477,0.152138,0.009799,-37.897770,0.001916,0.000000
4.150000,0.687027,-37.942253,0.001298,0.000048,0.001231,3.056049,0.155683,0.012314,-37.942253,0.002298,0.000000
4.380000,0.745491,-38.075695,0.001285,0.000062,0.001578,3.316110,0.168931,0.015783,-38.075695,0.002680,0.000000
4.610000,0.818474,-37.942253,0.001315,0.000086,0.002185,3.640753,0.185469,0.021854,-37.942253,0.003061,0.000000
4.840000,0.832253,-37.942253,0.001341,0.000097,0.002463,3.702044,0.188591,0.024628,-37.942253,0.003452,0.000000
5.070000,0.847519,-37.942253,0.001350,0.000110,0.002801,3.769953,0.192051,0.028012,-37.942253,0.003833,0.000000
5.300000,0.897049,-37.986732,0.001362,0.000128,0.003243,3.990273,0.203274,0.032435,-37.986732,0.004215,0.000000
5.530000,0.888855,-37.986732,0.001362,0.000136,0.003460,3.953825,0.201417,0.034602,-37.986732,0.004596,0.000000
5.760000,0.957741,-37.942253,0.001401,0.000157,0.003981,4.260244,0.217027,0.039806,-37.942253,0.004978,0.000000
5.990000,0.979340,-37.897770,0.001423,0.000170,0.004319,4.356320,0.221922,0.043188,-37.897770,0.005368,0.000000
6.220000,1.030724,-38.031212,0.001436,0.000183,0.004657,4.584888,0.233565,0.046569,-38.031212,0.005750,0.000000
6.450000,1.095894,-38.075695,0.001436,0.000202,0.005134,4.874779,0.248333,0.051340,-38.075695,0.006131,0.000000
6.680000,1.037430,-38.031212,0.001440,0.000203,0.005151,4.614718,0.235085,0.051512,-38.031212,0.006513,0.000000
6.910000,1.139084,-38.031212,0.001479,0.000231,0.005862,5.066898,0.258120,0.058624,-38.031212,0.006894,0.000000
7.140000,1.175209,-38.031212,0.001487,0.000248,0.006305,5.227591,0.266306,0.063047,-38.031212,0.007285,0.000000
7.370000,1.168877,-38.031212,0.001513,0.000258,0.006565,5.199423,0.264871,0.065649,-38.031212,0.007666,0.000000
7.600000,1.247078,-38.031212,0.001513,0.000273,0.006946,5.547280,0.282592,0.069464,-38.031212,0.008048,0.000000
7.830000,1.286545,-38.031212,0.001535,0.000285,0.007233,5.722837,0.291535,0.072327,-38.031212,0.008429,0.000000
8.060000,1.310005,-37.986732,0.001548,0.000299,0.007606,5.827194,0.296851,0.076056,-37.986732,0.008811,0.000000
8.290000,1.411293,-37.986732,0.001552,0.000317,0.008057,6.277745,0.319804,0.080565,-37.986732,0.009201,0.000000
8.520000,1.426186,-38.031212,0.001582,0.000337,0.008560,6.343990,0.323178,0.085595,-38.031212,0.009583,0.000000
8.750000,1.478691,-38.120174,0.001608,0.000354,0.009002,6.577547,0.335076,0.090018,-38.120174,0.009964,0.000000
8.980000,1.478691,-38.075695,0.001600,0.000367,0.009331,6.577547,0.335076,0.093313,-38.075695,0.010346,0.000000
9.210000,1.520393,-38.075695,0.001621,0.000381,0.009687,6.763048,0.344526,0.096869,-38.075695,0.010736,0.000000
9.440001,1.560616,-38.075695,0.001660,0.000393,0.009990,6.941965,0.353641,0.099904,-38.075695,0.011118,0.000000
9.670000,1.647003,-38.120174,0.001664,0.000411,0.010433,7.326236,0.373216,0.104327,-38.120174,0.011499,0.000000
9.900001,1.698021,-38.120174,0.001690,0.000426,0.010823,7.553174,0.384777,0.108229,-38.120174,0.011881,0.000000
10.130000,1.723343,-38.075695,0.001681,0.000438,0.011126,7.665812,0.390515,0.111265,-38.075695,0.012262,0.000000
10.360001,1.794464,-38.164658,0.001716,0.000458,0.011621,7.982175,0.406631,0.116208,-38.164658,0.012653,0.000000
10.590000,1.854790,-38.120174,0.001707,0.000475,0.012072,8.250517,0.420301,0.120717,-38.120174,0.013034,0.000000
10.820001,1.859627,-38.120174,0.001746,0.000489,0.012410,8.272033,0.421397,0.124099,-38.120174,0.013416,0.000000
11.050000,1.865959,-38.075695,0.001742,0.000502,0.012748,8.300200,0.422832,0.127483,-38.075695,0.013798,0.000000
11.280001,1.912132,-38.164658,0.001768,0.000514,0.013043,8.505589,0.433295,0.130431,-38.164658,0.014179,0.000000
11.510000,2.015282,-38.164658,0.001785,0.000535,0.013598,8.964420,0.456669,0.135982,-38.164658,0.014569,0.000000
11.740001,2.066292,-38.120174,0.001798,0.000549,0.013954,9.191325,0.468228,0.139536,-38.120174,0.014951,0.000000
11.970000,2.019379,-38.120174,0.001815,0.000553,0.014040,8.982645,0.457598,0.140404,-38.120174,0.015333,0.000000
12.200001,1.961288,-38.209137,0.001802,0.000553,0.014049,8.724247,0.444434,0.140490,-38.209137,0.015714,0.000000
12.430000,2.293068,-38.164658,0.001841,0.000595,0.015116,10.200075,0.519617,0.151157,-38.164658,0.016096,0.000000
12.660001,2.248383,-38.164658,0.001863,0.000608,0.015437,10.001306,0.509491,0.154367,-38.164658,0.016486,0.000000
12.890000,2.241310,-38.120174,0.001893,0.000623,0.015827,9.969846,0.507888,0.158269,-38.120174,0.016868,0.000000
13.120001,2.327332,-38.164658,0.001901,0.000639,0.016243,10.352488,0.527381,0.162431,-38.164658,0.017249,0.000000
13.350000,2.393242,-38.253616,0.001910,0.000655,0.016633,10.645672,0.542316,0.166335,-38.253616,0.017631,0.000000
13.580001,2.477768,-38.209137,0.001927,0.000671,0.017041,11.021663,0.561470,0.170409,-38.209137,0.018012,0.000000
13.810000,2.459892,-38.164658,0.001932,0.000681,0.017310,10.942147,0.557420,0.173098,-38.164658,0.018403,0.000000
14.040001,2.572350,-38.164658,0.001957,0.000697,0.017691,11.442382,0.582903,0.176914,-38.164658,0.018784,0.000000
14.270000,2.720551,-38.253616,0.001983,0.000721,0.018316,12.101613,0.616486,0.183159,-38.253616,0.019166,0.000000
14.500001,2.709007,-38.253616,0.001983,0.000736,0.018689,12.050266,0.613870,0.186887,-38.253616,0.019547,0.000000
14.730000,2.662834,-38.253616,0.002013,0.000743,0.018862,11.844878,0.603407,0.188622,-38.253616,0.019929,0.000000
14.960001,2.739914,-38.253616,0.002009,0.000760,0.019304,12.187746,0.620873,0.193045,-38.253616,0.020319,0.000000
15.190001,2.797638,-38.253616,0.002022,0.000775,0.019686,12.444515,0.633954,0.196860,-38.253616,0.020701,0.000000
15.420001,2.932434,-38.253616,0.002061,0.000792,0.020120,13.044118,0.664499,0.201196,-38.253616,0.021082,0.000000
15.650001,2.932060,-38.298100,0.002057,0.000804,0.020423,13.042456,0.664414,0.204231,-38.298100,0.021464,0.000000
15.880001,2.956268,-38.253616,0.002078,0.000816,0.020718,13.150138,0.669900,0.207179,-38.253616,0.021845,0.000000
16.110001,3.067230,-38.298100,0.002095,0.000832,0.021134,13.643722,0.695044,0.211343,-38.298100,0.022236,0.000000
16.340000,3.223625,-38.253616,0.002117,0.000856,0.021741,14.339401,0.730484,0.217414,-38.253616,0.022617,0.000000
16.570002,3.160698,-38.298100,0.002130,0.000866,0.021984,14.059486,0.716224,0.219842,-38.298100,0.022999,0.000000
16.800001,3.203896,-38.298100,0.002134,0.000882,0.022401,14.251639,0.726013,0.224005,-38.298100,0.023380,0.000000
17.030001,3.241875,-38.298100,0.002143,0.000894,0.022695,14.420579,0.734619,0.226954,-38.298100,0.023762,0.000000
17.260000,3.339806,-38.298100,0.002169,0.000909,0.023094,14.856197,0.756811,0.230943,-38.298100,0.024152,0.000000
17.490002,3.442955,-38.298100,0.002195,0.000924,0.023467,15.315029,0.780185,0.234671,-38.298100,0.024534,0.000000
17.720001,3.488388,-38.298100,0.002195,0.000938,0.023814,15.517125,0.790480,0.238140,-38.298100,0.024915,0.000000
17.950001,3.593765,-38.342579,0.002212,0.000952,0.024178,15.985867,0.814359,0.241783,-38.342579,0.025297,0.000000
18.180000,3.654465,-38.298100,0.002229,0.000970,0.024638,16.255871,0.828114,0.246380,-38.298100,0.025687,0.000000
18.410002,3.722237,-38.253616,0.002238,0.000984,0.025002,16.557335,0.843471,0.250021,-38.253616,0.026069,0.000000
18.640001,3.741226,-38.431541,0.002259,0.000997,0.025314,16.641806,0.847774,0.253143,-38.431541,0.026450,0.000000
18.870001,3.793732,-38.387062,0.002272,0.001014,0.025748,16.875360,0.859672,0.257479,-38.387062,0.026832,0.000000
19.100000,3.854057,-38.431541,0.002276,0.001028,0.026121,17.143703,0.873342,0.261209,-38.431541,0.027214,0.000000
19.330002,3.967255,-38.342579,0.002315,0.001046,0.026580,17.647230,0.898993,0.265804,-38.342579,0.027604,0.000000
19.560001,4.026093,-38.342579,0.002341,0.001060,0.026936,17.908955,0.912326,0.269360,-38.342579,0.027985,0.000000
19.790001,4.109505,-38.342579,0.002345,0.001074,0.027283,18.279989,0.931227,0.272828,-38.342579,0.028367,0.000000
20.020000,4.182861,-38.387062,0.002350,0.001089,0.027656,18.606297,0.947850,0.276558,-38.387062,0.028749,0.000000
20.250002,4.303139,-38.431541,0.002376,0.001111,0.028211,19.141317,0.975105,0.282109,-38.431541,0.029130,0.000000
20.480001,4.330688,-38.342579,0.002384,0.001124,0.028558,19.263865,0.981348,0.285578,-38.342579,0.029520,0.000000
20.710001,4.319893,-38.298100,0.002406,0.001139,0.028922,19.215843,0.978902,0.289219,-38.298100,0.029902,0.000000
20.940001,4.359367,-38.476021,0.002419,0.001151,0.029243,19.391434,0.987847,0.292429,-38.476021,0.030284,0.000000
21.170000,4.469215,-38.431541,0.002436,0.001166,0.029616,19.880062,1.012739,0.296157,-38.431541,0.030665,0.000000
21.400002,4.597313,-38.431541,0.002440,0.001180,0.029980,20.449869,1.041766,0.299800,-38.431541,0.031047,0.000000
21.630001,4.633057,-38.342579,0.002453,0.001194,0.030318,20.608866,1.049866,0.303181,-38.342579,0.031437,0.000000
21.860001,4.766365,-38.431541,0.002496,0.001209,0.030708,21.201851,1.080074,0.307084,-38.431541,0.031818,0.000000
22.090000,4.852013,-38.431541,0.002488,0.001228,0.031194,21.582830,1.099482,0.311942,-38.431541,0.032200,0.000000
22.320002,4.913086,-38.476021,0.002535,0.001244,0.031602,21.854498,1.113321,0.316018,-38.476021,0.032582,0.000000
22.550001,4.884041,-38.431541,0.002531,0.001259,0.031983,21.725298,1.106739,0.319833,-38.431541,0.032963,0.000000
22.780001,4.938034,-38.387062,0.002509,0.001272,0.032304,21.965473,1.118975,0.323041,-38.387062,0.033353,0.000000
23.010000,5.055702,-38.387062,0.002548,0.001287,0.032694,22.488886,1.145639,0.326945,-38.387062,0.033735,0.000000
23.240002,5.164803,-38.520504,0.002565,0.001305,0.033137,22.974190,1.170361,0.331368,-38.520504,0.034117,0.000000
23.470001,5.302582,-38.520504,0.002578,0.001320,0.033527,23.587061,1.201582,0.335270,-38.520504,0.034498,0.000000
23.700001,5.222893,-38.476021,0.002608,0.001328,0.033744,23.232588,1.183524,0.337437,-38.476021,0.034880,0.000000
23.930000,5.433289,-38.564983,0.002630,0.001349,0.034255,24.168474,1.231201,0.342554,-38.564983,0.035270,0.000000
24.160002,5.482437,-38.520504,0.002647,0.001363,0.034620,24.387098,1.242338,0.346197,-38.520504,0.035652,0.000000
24.390001,5.500687,-38.520504,0.002652,0.001377,0.034967,24.468277,1.246473,0.349666,-38.520504,0.036033,0.000000
24.620001,5.614632,-38.520504,0.002677,0.001394,0.035400,24.975128,1.272294,0.354001,-38.520504,0.036415,0.000000
24.850000,5.644424,-38.520504,0.002690,0.001406,0.035712,25.107655,1.279045,0.357124,-38.520504,0.036796,0.000000
25.080002,5.840660,-38.431541,0.002699,0.001425,0.036198,25.980555,1.323513,0.361980,-38.431541,0.037187,0.000000
25.310001,5.867104,-38.431541,0.002708,0.001438,0.036527,26.098181,1.329505,0.365275,-38.431541,0.037568,0.000000
25.540001,5.891304,-38.520504,0.002729,0.001449,0.036805,26.205830,1.334989,0.368051,-38.520504,0.037950,0.000000
25.770000,6.021637,-38.520504,0.002738,0.001462,0.037143,26.785580,1.364522,0.371433,-38.520504,0.038331,0.000000
26.000002,6.221230,-38.564983,0.002759,0.001487,0.037759,27.673410,1.409751,0.377591,-38.564983,0.038713,0.000000
26.230001,6.212662,-38.520504,0.002772,0.001496,0.037993,27.635300,1.407809,0.379932,-38.520504,0.039103,0.000000
26.460001,6.250275,-38.520504,0.002777,0.001511,0.038392,27.802610,1.416332,0.383921,-38.520504,0.039485,0.000000
26.690001,6.382835,-38.564983,0.002824,0.001528,0.038800,28.392269,1.446371,0.387997,-38.564983,0.039866,0.000000
26.920002,6.338150,-38.653946,0.002820,0.001540,0.039112,28.193499,1.436245,0.391120,-38.653946,0.040248,0.000000
27.150002,6.602905,-38.564983,0.002828,0.001558,0.039571,29.371189,1.496240,0.395715,-38.564983,0.040638,0.000000
27.380001,6.598442,-38.609467,0.002863,0.001573,0.039953,29.351336,1.495228,0.399532,-38.609467,0.041020,0.000000
27.610001,6.701584,-38.609467,0.002859,0.001587,0.040309,29.810133,1.518601,0.403086,-38.609467,0.041401,0.000000
27.840002,6.838249,-38.564983,0.002876,0.001603,0.040716,30.418051,1.549569,0.407162,-38.564983,0.041783,0.000000
28.070002,6.840485,-38.609467,0.002889,0.001615,0.041020,30.427996,1.550076,0.410197,-38.609467,0.042164,0.000000
28.300001,6.984962,-38.564983,0.002915,0.001632,0.041462,31.070665,1.582815,0.414620,-38.564983,0.042555,0.000000
28.530001,7.089226,-38.609467,0.002910,0.001649,0.041878,31.534451,1.606442,0.418783,-38.609467,0.042936,0.000000
28.760002,7.057945,-38.564983,0.002953,0.001660,0.042164,31.395308,1.599353,0.421645,-38.564983,0.043318,0.000000
28.990002,7.275787,-38.698429,0.002958,0.001679,0.042659,32.364319,1.648717,0.426588,-38.698429,0.043699,0.000000
29.220001,7.308929,-38.653946,0.002953,0.001691,0.042954,32.511742,1.656227,0.429536,-38.653946,0.044081,0.000000
29.450001,7.249718,-38.609467,0.002984,0.001699,0.043144,32.248356,1.642810,0.431444,-38.609467,0.044471,0.000000
29.680002,7.578522,-38.653946,0.003009,0.001723,0.043760,33.710949,1.717318,0.437602,-38.653946,0.044853,0.000000
29.910002,7.714813,-38.653946,0.003035,0.001740,0.044194,34.317204,1.748202,0.441938,-38.653946,0.045234,0.000000
30.140001,7.866371,-38.653946,0.003040,0.001758,0.044662,34.991367,1.782545,0.446621,-38.653946,0.045616,0.000000
30.370001,7.844025,-38.653946,0.003048,0.001771,0.044992,34.891964,1.777481,0.449916,-38.653946,0.045998,0.000000
30.600002,7.877167,-38.698429,0.003053,0.001784,0.045304,35.039387,1.784992,0.453039,-38.698429,0.046388,0.000000
30.830002,7.986649,-38.653946,0.003087,0.001796,0.045616,35.526386,1.809800,0.456161,-38.653946,0.046770,0.000000
31.060001,8.181770,-38.698429,0.003091,0.001814,0.046067,36.394333,1.854016,0.460671,-38.698429,0.047151,0.000000
31.290001,8.210815,-38.698429,0.003117,0.001826,0.046388,36.523533,1.860597,0.463879,-38.698429,0.047533,0.000000
31.520002,8.398491,-38.742908,0.003134,0.001844,0.046839,37.358353,1.903125,0.468388,-38.742908,0.047914,0.000000
31.750002,8.220123,-38.653946,0.003130,0.001848,0.046934,36.564934,1.862707,0.469342,-38.653946,0.048305,0.000000
31.980001,8.814056,-38.742908,0.003160,0.001878,0.047689,39.206882,1.997294,0.476887,-38.742908,0.048686,0.000000
32.210003,8.781288,-38.698429,0.003173,0.001894,0.048096,39.061119,1.989868,0.480964,-38.698429,0.049068,0.000000
32.440002,8.722450,-38.787388,0.003165,0.001904,0.048357,38.799397,1.976535,0.483566,-38.787388,0.049449,0.000000
32.670002,8.701599,-38.787388,0.003186,0.001913,0.048599,38.706646,1.971811,0.485994,-38.787388,0.049831,0.000000
32.900002,9.170044,-38.698429,0.003225,0.001937,0.049198,40.790394,2.077962,0.491978,-38.698429,0.050221,0.000000
33.130001,9.241165,-38.742908,0.003229,0.001950,0.049536,41.106754,2.094078,0.495359,-38.742908,0.050603,0.000000
33.360001,9.159988,-38.787388,0.003242,0.001960,0.049796,40.745663,2.075683,0.497962,-38.787388,0.050984,0.000000
33.590000,8.955185,-38.787388,0.003247,0.001963,0.049865,39.834652,2.029274,0.498654,-38.787388,0.051366,0.000000
33.820004,9.856697,-38.787388,0.003281,0.001999,0.050767,43.844780,2.233560,0.507674,-38.787388,0.051747,0.000000
34.050003,9.714455,-38.742908,0.003290,0.002011,0.051080,43.212051,2.201327,0.510796,-38.742908,0.052138,0.000000
34.280003,9.709984,-38.742908,0.003307,0.002022,0.051366,43.192165,2.200314,0.513658,-38.742908,0.052519,0.000000
34.510002,9.901756,-38.831871,0.003311,0.002038,0.051773,44.045212,2.243770,0.517734,-38.831871,0.052901,0.000000
34.740002,10.299080,-38.876350,0.003328,0.002061,0.052354,45.812595,2.333805,0.523544,-38.876350,0.053282,0.000000
34.970001,10.270409,-38.742908,0.003354,0.002074,0.052684,45.685059,2.327308,0.526840,-38.742908,0.053664,0.000000
35.200001,10.200775,-38.787388,0.003359,0.002083,0.052901,45.375313,2.311529,0.529007,-38.787388,0.054054,0.000000
35.430000,10.416374,-38.787388,0.003393,0.002099,0.053326,46.334347,2.360384,0.533258,-38.787388,0.054436,0.000000
35.660000,10.873650,-38.831871,0.003406,0.002125,0.053985,48.368408,2.464004,0.539847,-38.831871,0.054817,0.000000
35.890003,10.798431,-38.876350,0.003415,0.002135,0.054236,48.033821,2.446960,0.542362,-38.876350,0.055199,0.000000
36.120003,10.768639,-38.831871,0.003436,0.002148,0.054557,47.901299,2.440208,0.545572,-38.831871,0.055589,0.000000
36.350002,11.069519,-38.831871,0.003428,0.002165,0.054982,49.239681,2.508389,0.549820,-38.831871,0.055971,0.000000
36.580002,11.158516,-38.920834,0.003454,0.002179,0.055338,49.635559,2.528556,0.553376,-38.920834,0.056352,0.000000
36.810001,11.366295,-38.876350,0.003458,0.002194,0.055719,50.559803,2.575639,0.557193,-38.876350,0.056734,0.000000
37.040001,11.394226,-38.876350,0.003492,0.002205,0.055997,50.684048,2.581969,0.559968,-38.876350,0.057115,0.000000
37.270000,11.509285,-38.831871,0.003479,0.002217,0.056318,51.195858,2.608041,0.563177,-38.831871,0.057506,0.000000
37.500000,11.877190,-38.876350,0.003488,0.002239,0.056873,52.832378,2.691410,0.568726,-38.876350,0.057887,0.000000
37.730003,12.178444,-38.876350,0.003531,0.002258,0.057358,54.172424,2.759675,0.573584,-38.876350,0.058269,0.000000
37.960003,11.939751,-38.876350,0.003544,0.002265,0.057532,53.110664,2.705586,0.575317,-38.876350,0.058651,0.000000
38.190002,12.183655,-38.876350,0.003566,0.002283,0.057983,54.195602,2.760855,0.579827,-38.876350,0.059032,0.000000
38.420002,12.282333,-38.920834,0.003566,0.002297,0.058356,54.634548,2.783216,0.583557,-38.920834,0.059422,0.000000
38.650002,12.631989,-38.965313,0.003609,0.002315,0.058798,56.189892,2.862450,0.587980,-38.965313,0.059804,0.000000
38.880001,12.598480,-38.876350,0.003617,0.002323,0.058997,56.040840,2.854856,0.589974,-38.876350,0.060186,0.000000
39.110001,12.929520,-38.965313,0.003604,0.002339,0.059414,57.513374,2.929871,0.594136,-38.965313,0.060567,0.000000
39.340000,13.245659,-38.920834,0.003596,0.002359,0.059917,58.919632,3.001509,0.599166,-38.920834,0.060949,0.000000
39.570004,13.324974,-38.876350,0.003643,0.002374,0.060307,59.272446,3.019482,0.603068,-38.876350,0.061339,0.000000
39.800003,13.591225,-38.876350,0.003660,0.002390,0.060714,60.456787,3.079816,0.607144,-38.876350,0.061720,0.000000
40.030003,13.644096,-39.009792,0.003678,0.002403,0.061027,60.691971,3.091796,0.610267,-39.009792,0.062102,0.000000
40.260002,13.883163,-38.965313,0.003691,0.002419,0.061452,61.755394,3.145970,0.614516,-38.965313,0.062484,0.000000
40.490002,13.840340,-39.009792,0.003686,0.002432,0.061781,61.564907,3.136266,0.617812,-39.009792,0.062865,0.000000
40.720001,14.329636,-38.965313,0.003708,0.002450,0.062232,63.741402,3.247142,0.622322,-38.965313,0.063255,0.000000
40.950001,14.286812,-38.965313,0.003721,0.002461,0.062501,63.550915,3.237438,0.625009,-38.965313,0.063637,0.000000
41.180000,14.656952,-39.009792,0.003729,0.002479,0.062961,65.197380,3.321313,0.629606,-39.009792,0.064019,0.000000
41.410004,14.944427,-39.009792,0.003747,0.002495,0.063385,66.476135,3.386456,0.633854,-39.009792,0.064400,0.000000
41.640003,15.285515,-39.009792,0.003777,0.002514,0.063863,67.993362,3.463747,0.638625,-39.009792,0.064782,0.000000
41.870003,15.276207,-38.965313,0.003798,0.002528,0.064218,67.951965,3.461638,0.642181,-38.965313,0.065172,0.000000
42.100002,15.332062,-38.965313,0.003807,0.002540,0.064504,68.200417,3.474295,0.645043,-38.965313,0.065554,0.000000
42.330002,15.433350,-39.009792,0.003824,0.002552,0.064825,68.650970,3.497247,0.648250,-39.009792,0.065935,0.000000
42.560001,15.877220,-39.054276,0.003837,0.002569,0.065259,70.625404,3.597830,0.652588,-39.054276,0.066317,0.000000
42.790001,15.979622,-39.009792,0.003850,0.002582,0.065580,71.080910,3.621034,0.655796,-39.009792,0.066698,0.000000
43.020000,16.187401,-39.009792,0.003837,0.002597,0.065953,72.005157,3.668117,0.659526,-39.009792,0.067089,0.000000
43.250004,16.577652,-39.009792,0.003876,0.002615,0.066421,73.741081,3.756550,0.664207,-39.009792,0.067470,0.000000
43.480003,17.287392,-39.009792,0.003902,0.002639,0.067028,76.898155,3.917379,0.670278,-39.009792,0.067852,0.000000
43.710003,16.896400,-39.054276,0.003893,0.002646,0.067219,75.158943,3.828779,0.672186,-39.054276,0.068233,0.000000
43.940002,17.201744,-39.098755,0.003928,0.002664,0.067670,76.517181,3.897971,0.676696,-39.098755,0.068624,0.000000
44.170002,17.256859,-39.009792,0.003932,0.002675,0.067956,76.762344,3.910460,0.679559,-39.009792,0.069005,0.000000
44.400002,17.686951,-39.009792,0.003954,0.002694,0.068433,78.675484,4.007920,0.684328,-39.009792,0.069387,0.000000
44.630001,17.909996,-39.098755,0.003954,0.002709,0.068806,79.667641,4.058463,0.688056,-39.098755,0.069768,0.000000
44.860001,18.074585,-39.098755,0.003984,0.002720,0.069092,80.399773,4.095759,0.690919,-39.098755,0.070150,0.000000
45.090004,18.508400,-39.143238,0.004014,0.002739,0.069569,82.329475,4.194063,0.695688,-39.143238,0.070540,0.000000
45.320004,18.747833,-39.054276,0.003992,0.002752,0.069898,83.394524,4.248320,0.698983,-39.054276,0.070922,0.000000
45.550003,19.033821,-39.098755,0.004040,0.002769,0.070323,84.666664,4.313126,0.703233,-39.098755,0.071303,0.000000
45.780003,19.221870,-39.143238,0.004036,0.002784,0.070714,85.503151,4.355738,0.707136,-39.143238,0.071685,0.000000
46.010002,19.528328,-39.187717,0.004044,0.002798,0.071078,86.866341,4.425182,0.710779,-39.187717,0.072066,0.000000
46.240002,19.679512,-39.187717,0.004053,0.002812,0.071433,87.538841,4.459441,0.714335,-39.187717,0.072457,0.000000
46.470001,19.858994,-39.187717,0.004070,0.002826,0.071772,88.337212,4.500113,0.717716,-39.187717,0.072838,0.000000
46.700001,20.289833,-39.187717,0.004074,0.002842,0.072188,90.253685,4.597742,0.721878,-39.187717,0.073220,0.000000
46.930004,19.951347,-39.098755,0.004092,0.002845,0.072275,88.748024,4.521040,0.722746,-39.098755,0.073601,0.000000
47.160004,20.386650,-39.232201,0.004113,0.002861,0.072665,90.684349,4.619681,0.726649,-39.232201,0.073983,0.000000
47.390003,21.323166,-39.187717,0.004139,0.002886,0.073315,94.850182,4.831898,0.733153,-39.187717,0.074373,0.000000
47.620003,21.191345,-39.187717,0.004118,0.002897,0.073576,94.263809,4.802028,0.735755,-39.187717,0.074755,0.000000
47.850002,21.859383,-39.098755,0.004156,0.002918,0.074122,97.235390,4.953407,0.741219,-39.098755,0.075136,0.000000
48.080002,22.013916,-39.143238,0.004152,0.002933,0.074495,97.922791,4.988425,0.744947,-39.143238,0.075518,0.000000
48.310001,22.188560,-39.143238,0.004182,0.002947,0.074842,98.699646,5.028000,0.748416,-39.143238,0.075900,0.000000
48.540001,22.702057,-39.232201,0.004186,0.002962,0.075232,100.983795,5.144360,0.752318,-39.232201,0.076290,0.000000
48.770000,22.805206,-39.232201,0.004208,0.002975,0.075570,101.442627,5.167734,0.755700,-39.232201,0.076671,0.000000
49.000004,23.143692,-39.187717,0.004195,0.002990,0.075952,102.948280,5.244435,0.759517,-39.187717,0.077053,0.000000
49.230003,23.602829,-39.143238,0.004247,0.003008,0.076394,104.990623,5.348478,0.763939,-39.143238,0.077435,0.000000
49.460003,23.907059,-39.232201,0.004260,0.003023,0.076775,106.343910,5.417417,0.767755,-39.232201,0.077816,0.000000
49.690002,24.061218,-39.276680,0.004268,0.003038,0.077157,107.029648,5.452350,0.771570,-39.276680,0.078206,0.000000
49.920002,24.357254,-39.232201,0.004247,0.003049,0.077443,108.346474,5.519433,0.774433,-39.232201,0.078588,0.000000
50.150002,24.409386,-39.232201,0.004290,0.003060,0.077729,108.578369,5.531246,0.777294,-39.232201,0.078970,0.000000
50.380001,25.114662,-39.187717,0.004286,0.003078,0.078172,111.715599,5.691064,0.781717,-39.187717,0.079351,0.000000
50.610001,25.469528,-39.232201,0.004316,0.003092,0.078545,113.294121,5.771478,0.785447,-39.232201,0.079733,0.000000
50.840004,25.842278,-39.276680,0.004316,0.003109,0.078978,114.952194,5.855944,0.789783,-39.276680,0.080123,0.000000
51.070004,26.485733,-39.276680,0.004333,0.003127,0.079429,117.814423,6.001753,0.794292,-39.276680,0.080505,0.000000
51.300003,26.822365,-39.276680,0.004346,0.003143,0.079837,119.311836,6.078035,0.798369,-39.276680,0.080886,0.000000
51.530003,27.335121,-39.321159,0.004385,0.003160,0.080270,121.592690,6.194227,0.802704,-39.321159,0.081268,0.000000
51.760002,27.414062,-39.321159,0.004398,0.003173,0.080600,121.943840,6.212115,0.805999,-39.321159,0.081649,0.000000
51.990002,27.590569,-39.276680,0.004393,0.003186,0.080912,122.728981,6.252112,0.809122,-39.276680,0.082039,0.000000
52.220001,28.006874,-39.276680,0.004398,0.003201,0.081294,124.580795,6.346448,0.812937,-39.276680,0.082421,0.000000
52.450001,28.148010,-39.276680,0.004432,0.003209,0.081519,125.208603,6.378430,0.815193,-39.276680,0.082803,0.000000
52.680004,28.792587,-39.276680,0.004424,0.003231,0.082066,128.075821,6.524493,0.820656,-39.276680,0.083184,0.000000
52.910004,29.396568,-39.410122,0.004441,0.003246,0.082456,130.762466,6.661357,0.824558,-39.410122,0.083574,0.000000
53.140003,29.965553,-39.321159,0.004454,0.003265,0.082933,133.293442,6.790291,0.829327,-39.321159,0.083956,0.000000
53.370003,30.199409,-39.365643,0.004475,0.003278,0.083262,134.333679,6.843284,0.832624,-39.365643,0.084338,0.000000
53.600002,30.650719,-39.321159,0.004506,0.003295,0.083687,136.341202,6.945552,0.836872,-39.321159,0.084719,0.000000
53.830002,30.728920,-39.321159,0.004484,0.003305,0.083956,136.689056,6.963273,0.839562,-39.321159,0.085101,0.000000
54.060001,31.220825,-39.410122,0.004510,0.003321,0.084355,138.877167,7.074740,0.843551,-39.410122,0.085491,0.000000
54.290001,31.947327,-39.410122,0.004527,0.003341,0.084849,142.108810,7.239367,0.848494,-39.410122,0.085873,0.000000
54.520004,32.427681,-39.365643,0.004540,0.003355,0.085222,144.245529,7.348217,0.852222,-39.365643,0.086254,0.000000
54.750004,32.199417,-39.321159,0.004540,0.003361,0.085361,143.230164,7.296492,0.853611,-39.321159,0.086636,0.000000
54.980003,31.791298,-39.365643,0.004549,0.003366,0.085509,141.414749,7.204011,0.855085,-39.365643,0.087017,0.000000
55.210003,34.023300,-39.365643,0.004553,0.003401,0.086393,151.343201,7.709790,0.863931,-39.365643,0.087408,0.000000
55.440002,34.113045,-39.454605,0.004583,0.003413,0.086679,151.742401,7.730126,0.866792,-39.454605,0.087789,0.000000
55.670002,34.430305,-39.365643,0.004583,0.003428,0.087069,153.153641,7.802019,0.870694,-39.365643,0.088171,0.000000
55.900002,34.795975,-39.365643,0.004609,0.003441,0.087399,154.780228,7.884881,0.873991,-39.365643,0.088552,0.000000
56.130001,35.846809,-39.365643,0.004635,0.003463,0.087954,159.454575,8.123003,0.879540,-39.365643,0.088934,0.000000
56.360004,36.121994,-39.410122,0.004631,0.003474,0.088240,160.678650,8.185361,0.882403,-39.410122,0.089324,0.000000
56.590004,36.075447,-39.410122,0.004635,0.003483,0.088474,160.471603,8.174813,0.884744,-39.410122,0.089706,0.000000
56.820004,36.814232,-39.454605,0.004648,0.003505,0.089029,163.757889,8.342224,0.890294,-39.454605,0.090087,0.000000
57.050003,38.203178,-39.365643,0.004656,0.003528,0.089602,169.936218,8.656963,0.896017,-39.365643,0.090469,0.000000
57.280003,38.165199,-39.321159,0.004678,0.003537,0.089845,169.767288,8.648358,0.898445,-39.321159,0.090851,0.000000
57.510002,38.440384,-39.454605,0.004691,0.003551,0.090191,170.991364,8.710716,0.901914,-39.454605,0.091241,0.000000
57.740002,38.979950,-39.454605,0.004678,0.003564,0.090521,173.391479,8.832983,0.905211,-39.454605,0.091622,0.000000
57.970001,39.397751,-39.410122,0.004708,0.003577,0.090868,175.249954,8.927658,0.908679,-39.410122,0.092004,0.000000
58.200005,40.199097,-39.410122,0.004734,0.003597,0.091371,178.814514,9.109245,0.913710,-39.410122,0.092386,0.000000
58.430004,40.369270,-39.454605,0.004717,0.003605,0.091570,179.571487,9.147807,0.915704,-39.454605,0.092767,0.000000
58.660004,40.763985,-39.454605,0.004756,0.003624,0.092039,181.327255,9.237251,0.920386,-39.454605,0.093157,0.000000
58.890003,42.476898,-39.454605,0.004743,0.003648,0.092672,188.946686,9.625402,0.926718,-39.454605,0.093539,0.000000
59.120003,42.809425,-39.499084,0.004773,0.003660,0.092967,190.425827,9.700754,0.929667,-39.499084,0.093920,0.000000
59.350002,42.907364,-39.454605,0.004786,0.003671,0.093253,190.861481,9.722948,0.932528,-39.454605,0.094302,0.000000
59.580002,43.343781,-39.499084,0.004799,0.003685,0.093591,192.802765,9.821841,0.935910,-39.499084,0.094684,0.000000
59.810001,44.005859,-39.543564,0.004794,0.003701,0.094007,195.747833,9.971869,0.940073,-39.543564,0.095074,0.000000
60.040005,44.679855,-39.499084,0.004829,0.003716,0.094398,198.745926,10.124599,0.943976,-39.499084,0.095456,0.000000
60.270004,44.956154,-39.543564,0.004816,0.003730,0.094753,199.974960,10.187210,0.947531,-39.543564,0.095837,0.000000
60.500004,45.292404,-39.499084,0.004829,0.003737,0.094926,201.470673,10.263406,0.949265,-39.499084,0.096219,0.000000
60.730003,46.486977,-39.543564,0.004855,0.003759,0.095473,206.784393,10.534100,0.954728,-39.543564,0.096600,0.000000
60.960003,47.173264,-39.543564,0.004855,0.003778,0.095967,209.837158,10.689614,0.959671,-39.543564,0.096991,0.000000
61.190002,47.819702,-39.588047,0.004863,0.003793,0.096340,212.712662,10.836100,0.963401,-39.588047,0.097372,0.000000
61.420002,48.116112,-39.588047,0.004872,0.003803,0.096592,214.031158,10.903267,0.965917,-39.588047,0.097754,0.000000
61.650002,48.840370,-39.588047,0.004885,0.003819,0.096991,217.252823,11.067387,0.969906,-39.588047,0.098135,0.000000
61.880001,49.437660,-39.499084,0.004894,0.003836,0.097433,219.909698,11.202734,0.974328,-39.499084,0.098526,0.000000
62.110004,50.347366,-39.588047,0.004907,0.003851,0.097806,223.956268,11.408876,0.978057,-39.588047,0.098907,0.000000
62.340004,50.496689,-39.588047,0.004907,0.003861,0.098057,224.620483,11.442714,0.980572,-39.588047,0.099289,0.000000
62.570004,51.435806,-39.588047,0.004932,0.003878,0.098491,228.797897,11.655520,0.984907,-39.588047,0.099670,0.000000
62.800003,52.358917,-39.543564,0.004932,0.003898,0.099011,232.904099,11.864700,0.990111,-39.543564,0.100052,0.000000
63.030003,53.225433,-39.543564,0.004945,0.003914,0.099410,236.758545,12.061056,0.994101,-39.543564,0.100442,0.000000
63.260002,53.680473,-39.543564,0.004967,0.003927,0.099757,238.782669,12.164169,0.997570,-39.543564,0.100824,0.000000
63.490002,54.075554,-39.588047,0.004971,0.003939,0.100043,240.540070,12.253695,1.000431,-39.588047,0.101205,0.000000
63.720001,54.692947,-39.632526,0.004950,0.003953,0.100399,243.286377,12.393600,1.003987,-39.632526,0.101587,0.000000
63.950005,55.549782,-39.588047,0.004988,0.003968,0.100780,247.097763,12.587761,1.007802,-39.588047,0.101968,0.000000
64.180000,56.249840,-39.588047,0.004988,0.003984,0.101205,250.211777,12.746396,1.012053,-39.588047,0.102359,0.000000
64.410004,56.907822,-39.632526,0.005019,0.003997,0.101518,253.138626,12.895496,1.015175,-39.632526,0.102740,0.000000
64.639999,58.059944,-39.632526,0.005014,0.004016,0.102012,258.263519,13.156571,1.020118,-39.632526,0.103122,0.000000
64.870003,59.609383,-39.721489,0.005027,0.004039,0.102601,265.155762,13.507679,1.026015,-39.721489,0.103503,0.000000
65.100006,59.596725,-39.588047,0.005044,0.004049,0.102853,265.099487,13.504811,1.028530,-39.588047,0.103885,0.000000
65.330002,60.499725,-39.588047,0.005049,0.004064,0.103235,269.116211,13.709435,1.032345,-39.588047,0.104275,0.000000
65.560005,61.068336,-39.632526,0.005070,0.004079,0.103608,271.645538,13.838284,1.036075,-39.632526,0.104657,0.000000
65.790001,61.421722,-39.765972,0.005066,0.004085,0.103763,273.217468,13.918361,1.037635,-39.765972,0.105038,0.000000
66.020004,62.893341,-39.765972,0.005083,0.004110,0.104388,279.763550,14.251835,1.043880,-39.765972,0.105420,0.000000
66.250000,63.375565,-39.721489,0.005062,0.004120,0.104648,281.908600,14.361108,1.046482,-39.721489,0.105801,0.000000
66.480003,64.553375,-39.588047,0.005096,0.004140,0.105160,287.147766,14.628004,1.051597,-39.588047,0.106192,0.000000
66.710007,65.193848,-39.677010,0.005105,0.004154,0.105507,289.996704,14.773137,1.055066,-39.677010,0.106573,0.000000
66.940002,66.145645,-39.721489,0.005122,0.004169,0.105888,294.230530,14.988817,1.058883,-39.721489,0.106955,0.000000
67.170006,66.981979,-39.721489,0.005105,0.004185,0.106304,297.950714,15.178333,1.063045,-39.721489,0.107337,0.000000
67.400002,67.156250,-39.677010,0.005135,0.004185,0.106304,298.725922,15.217823,1.063045,-39.677010,0.106539,0.000000
67.630005,66.507584,-39.677010,0.005135,0.004185,0.106304,295.840515,15.070834,1.063045,-39.677010,0.106539,0.000000
67.860001,66.105789,-39.677010,0.005139,0.004184,0.106270,294.053223,14.979786,1.062698,-39.677010,0.106304,0.000000
68.090004,65.669006,-39.765972,0.005152,0.004183,0.106252,292.110321,14.880810,1.062524,-39.765972,0.106304,0.000000
68.320000,65.298111,-39.765972,0.005144,0.004183,0.106244,290.460510,14.796764,1.062439,-39.765972,0.106304,0.000000
68.550003,64.977509,-39.765972,0.005157,0.004183,0.106244,289.034393,14.724113,1.062439,-39.765972,0.106304,0.000000
68.780006,64.687057,-39.632526,0.005165,0.004182,0.106235,287.742401,14.658298,1.062352,-39.632526,0.106304,0.000000
69.010002,64.432358,-39.721489,0.005170,0.004182,0.106235,286.609436,14.600581,1.062352,-39.721489,0.106304,0.000000
69.240005,64.204468,-39.765972,0.005157,0.004182,0.106235,285.595734,14.548941,1.062352,-39.765972,0.106304,0.000000
69.470001,63.989609,-39.765972,0.005152,0.004182,0.106235,284.639984,14.500253,1.062352,-39.765972,0.106304,0.000000
69.700005,63.826508,-39.765972,0.005148,0.004182,0.106235,283.914490,14.463294,1.062352,-39.765972,0.106304,0.000000
69.930000,63.633240,-39.765972,0.005157,0.004182,0.106235,283.054779,14.419498,1.062352,-39.765972,0.106304,0.000000
70.160004,63.461945,-39.765972,0.005174,0.004182,0.106235,282.292816,14.380682,1.062352,-39.765972,0.106304,0.000000
70.390007,63.295120,-39.854931,0.005187,0.004182,0.106226,281.550751,14.342879,1.062265,-39.854931,0.106304,0.000000
70.620003,63.169632,-39.721489,0.005165,0.004182,0.106226,280.992554,14.314444,1.062265,-39.721489,0.106304,0.000000
70.850006,63.037079,-39.810452,0.005170,0.004182,0.106226,280.402924,14.284407,1.062265,-39.810452,0.106304,0.000000
71.080002,62.914185,-39.765972,0.005170,0.004182,0.106226,279.856262,14.256558,1.062265,-39.765972,0.106304,0.000000
71.310005,62.784973,-39.765972,0.005182,0.004182,0.106226,279.281494,14.227279,1.062265,-39.765972,0.106304,0.000000
71.540001,62.673630,-39.854931,0.005165,0.004182,0.106226,278.786224,14.202047,1.062265,-39.854931,0.106304,0.000000
71.770004,62.563789,-39.854931,0.005187,0.004182,0.106226,278.297638,14.177157,1.062265,-39.854931,0.106304,0.000000
72.000000,62.479256,-39.899414,0.005182,0.004182,0.106226,277.921600,14.158001,1.062265,-39.899414,0.106304,0.000000
72.230003,62.366058,-39.810452,0.005165,0.004182,0.106226,277.418091,14.132351,1.062265,-39.810452,0.106304,0.000000
72.460007,62.267006,-39.854931,0.005200,0.004182,0.106226,276.977478,14.109905,1.062265,-39.854931,0.106304,0.000000
72.690002,62.188805,-39.854931,0.005187,0.004182,0.106226,276.629608,14.092185,1.062265,-39.854931,0.106304,0.000000
72.920006,62.105766,-39.943893,0.005187,0.004182,0.106226,276.260254,14.073368,1.062265,-39.943893,0.106304,0.000000
73.150002,62.019753,-39.810452,0.005178,0.004182,0.106226,275.877625,14.053876,1.062265,-39.810452,0.106304,0.000000
73.380005,61.941177,-39.943893,0.005178,0.004182,0.106226,275.528107,14.036072,1.062265,-39.943893,0.106304,0.000000
73.610001,61.864471,-39.899414,0.005165,0.004182,0.106226,275.186920,14.018689,1.062265,-39.899414,0.106304,0.000000
73.840004,61.788879,-39.899414,0.005200,0.004182,0.106226,274.850677,14.001560,1.062265,-39.899414,0.106304,0.000000
74.070007,61.704727,-39.899414,0.005191,0.004182,0.106226,274.476349,13.982491,1.062265,-39.899414,0.106304,0.000000
74.300003,61.650726,-39.899414,0.005170,0.004182,0.106226,274.236115,13.970254,1.062265,-39.899414,0.106304,0.000000
74.530006,61.586311,-39.854931,0.005195,0.004182,0.106226,273.949585,13.955658,1.062265,-39.854931,0.106304,0.000000
74.760002,61.508110,-39.899414,0.005187,0.004182,0.106226,273.601746,13.937937,1.062265,-39.899414,0.106304,0.000000
74.990005,61.451508,-39.943893,0.005178,0.004182,0.106226,273.349945,13.925111,1.062265,-39.943893,0.106304,0.000000
75.220001,61.401237,-39.899414,0.005195,0.004182,0.106226,273.126343,13.913719,1.062265,-39.899414,0.106304,0.000000
75.450005,61.341286,-39.988377,0.005191,0.004182,0.106226,272.859680,13.900134,1.062265,-39.988377,0.106304,0.000000
75.680000,61.278358,-39.943893,0.005174,0.004182,0.106226,272.579742,13.885875,1.062265,-39.943893,0.106304,0.000000
75.910004,61.235535,-39.899414,0.005187,0.004182,0.106226,272.389252,13.876170,1.062265,-39.899414,0.106304,0.000000
76.140007,61.182281,-39.943893,0.005174,0.004182,0.106226,272.152374,13.864103,1.062265,-39.943893,0.106304,0.000000
76.370003,61.124199,-39.943893,0.005204,0.004182,0.106226,271.894012,13.850941,1.062265,-39.943893,0.106304,0.000000
76.600006,61.059402,-39.943893,0.005187,0.004182,0.106226,271.605774,13.836259,1.062265,-39.943893,0.106304,0.000000
76.830002,61.012856,-40.032856,0.005191,0.004182,0.106226,271.398743,13.825710,1.062265,-40.032856,0.106304,0.000000
77.060005,60.970406,-39.899414,0.005191,0.004182,0.106226,271.209900,13.816091,1.062265,-39.899414,0.106304,0.000000
77.290001,60.926094,-39.988377,0.005204,0.004182,0.106226,271.012787,13.806050,1.062265,-39.988377,0.106304,0.000000
77.520004,60.875450,-39.988377,0.005182,0.004182,0.106226,270.787537,13.794574,1.062265,-39.988377,0.106304,0.000000
77.750000,60.820709,-40.032856,0.005200,0.004182,0.106226,270.544037,13.782169,1.062265,-40.032856,0.106304,0.000000
77.980003,60.787567,-40.032856,0.005208,0.004182,0.106226,270.396606,13.774660,1.062265,-40.032856,0.106304,0.000000
78.210007,60.755173,-40.032856,0.005200,0.004182,0.106226,270.252502,13.767319,1.062265,-40.032856,0.106304,0.000000
78.440002,60.711609,-39.988377,0.005195,0.004182,0.106226,270.058716,13.757447,1.062265,-39.988377,0.106304,0.000000
78.670006,60.645325,-40.032856,0.005195,0.004182,0.106218,269.763885,13.742427,1.062178,-40.032856,0.106304,0.000000
78.900002,60.615906,-40.077335,0.005182,0.004182,0.106218,269.633026,13.735761,1.062178,-40.077335,0.106304,0.000000
79.130005,60.597290,-40.032856,0.005204,0.004182,0.106218,269.550201,13.731542,1.062178,-40.032856,0.106304,0.000000
79.360001,60.545158,-39.988377,0.005191,0.004182,0.106218,269.318329,13.719729,1.062178,-39.988377,0.106304,0.000000
79.590004,60.501961,-40.032856,0.005204,0.004182,0.106218,269.126160,13.709941,1.062178,-40.032856,0.106304,0.000000
79.820007,60.471802,-40.032856,0.005178,0.004182,0.106218,268.992004,13.703107,1.062178,-40.032856,0.106304,0.000000
80.050003,60.441261,-40.077335,0.005191,0.004182,0.106218,268.856171,13.696185,1.062178,-40.077335,0.106304,0.000000
80.280006,60.403282,-40.077335,0.005187,0.004182,0.106218,268.687225,13.687580,1.062178,-40.077335,0.106304,0.000000
80.510002,60.360832,-40.077335,0.005191,0.004182,0.106218,268.498383,13.677960,1.062178,-40.077335,0.106304,0.000000
80.740005,60.320992,-40.077335,0.005204,0.004182,0.106218,268.321167,13.668932,1.062178,-40.077335,0.106304,0.000000
80.970001,60.300507,-40.121819,0.005221,0.004182,0.106218,268.230042,13.664289,1.062178,-40.121819,0.106304,0.000000
81.200005,60.275932,-40.166298,0.005195,0.004182,0.106218,268.120728,13.658721,1.062178,-40.166298,0.106304,0.000000
81.430000,60.238693,-40.077335,0.005200,0.004182,0.106218,267.955078,13.650283,1.062178,-40.077335,0.106304,0.000000
81.660004,60.199593,-40.077335,0.005191,0.004182,0.106218,267.781158,13.641422,1.062178,-40.077335,0.106304,0.000000
81.890007,60.170921,-40.121819,0.005195,0.004182,0.106218,267.653625,13.634926,1.062178,-40.121819,0.106304,0.000000
82.120003,60.130333,-40.077335,0.005195,0.004182,0.106218,267.473083,13.625729,1.062178,-40.077335,0.106304,0.000000
82.350006,60.104263,-40.166298,0.005208,0.004182,0.106218,267.357117,13.619822,1.062178,-40.166298,0.106304,0.000000
82.580002,60.069267,-40.121819,0.005195,0.004182,0.106218,267.201447,13.611890,1.062178,-40.121819,0.106304,0.000000
82.810005,60.041336,-40.166298,0.005200,0.004182,0.106218,267.077209,13.605560,1.062178,-40.166298,0.106304,0.000000
83.040001,60.024582,-40.121819,0.005195,0.004182,0.106218,267.002686,13.601765,1.062178,-40.121819,0.106304,0.000000
83.270004,59.998138,-40.166298,0.005204,0.004182,0.106218,266.885040,13.595773,1.062178,-40.166298,0.106304,0.000000
83.500008,59.962769,-40.166298,0.005191,0.004182,0.106218,266.727722,13.587758,1.062178,-40.166298,0.106304,0.000000
83.730003,59.920685,-40.210781,0.005208,0.004182,0.106218,266.540527,13.578221,1.062178,-40.210781,0.106304,0.000000
83.960007,59.911003,-40.166298,0.005187,0.004182,0.106218,266.497437,13.576027,1.062178,-40.166298,0.106304,0.000000
84.190002,59.894997,-40.166298,0.005208,0.004182,0.106218,266.426239,13.572400,1.062178,-40.166298,0.106304,0.000000
84.420006,59.852173,-40.210781,0.005204,0.004182,0.106218,266.235748,13.562696,1.062178,-40.210781,0.106304,0.000000
84.650002,59.813820,-40.166298,0.005213,0.004182,0.106218,266.065155,13.554006,1.062178,-40.166298,0.106304,0.000000
84.880005,59.794823,-40.255260,0.005208,0.004182,0.106218,265.980652,13.549701,1.062178,-40.255260,0.106304,0.000000
85.110001,59.792221,-40.255260,0.005195,0.004182,0.106218,265.969086,13.549111,1.062178,-40.255260,0.106304,0.000000
85.340004,59.750885,-40.210781,0.005195,0.004182,0.106218,265.785217,13.539744,1.062178,-40.210781,0.106304,0.000000
85.570007,59.727051,-40.121819,0.005213,0.004182,0.106218,265.679199,13.534344,1.062178,-40.121819,0.106304,0.000000
85.800003,59.684975,-40.255260,0.005200,0.004182,0.106218,265.492035,13.524808,1.062178,-40.255260,0.106304,0.000000
86.030006,59.670822,-40.255260,0.005182,0.004182,0.106218,265.429077,13.521602,1.062178,-40.255260,0.106304,0.000000
86.260002,59.658913,-40.255260,0.005174,0.004182,0.106218,265.376099,13.518903,1.062178,-40.255260,0.106304,0.000000
86.490005,59.636940,-40.255260,0.005200,0.004182,0.106218,265.278351,13.513925,1.062178,-40.255260,0.106304,0.000000
86.720001,59.599701,-40.299740,0.005195,0.004182,0.106218,265.112701,13.505485,1.062178,-40.299740,0.106304,0.000000
86.950005,59.575500,-40.255260,0.005200,0.004182,0.106218,265.005066,13.500002,1.062178,-40.255260,0.106304,0.000000
87.180008,59.553528,-40.299740,0.005200,0.004182,0.106218,264.907318,13.495022,1.062178,-40.299740,0.106304,0.000000
87.410004,59.537888,-40.255260,0.005200,0.004182,0.106218,264.837738,13.491478,1.062178,-40.255260,0.106304,0.000000
87.640007,59.526344,-40.210781,0.005200,0.004182,0.106218,264.786407,13.488862,1.062178,-40.210781,0.106304,0.000000
87.870003,59.495811,-40.299740,0.005208,0.004182,0.106218,264.650574,13.481944,1.062178,-40.299740,0.106304,0.000000
88.100006,59.452240,-40.299740,0.005204,0.004182,0.106218,264.456757,13.472070,1.062178,-40.299740,0.106304,0.000000
88.330002,59.443680,-40.299740,0.005195,0.004182,0.106218,264.418701,13.470131,1.062178,-40.299740,0.106304,0.000000
88.560005,59.439209,-40.299740,0.005191,0.004182,0.106218,264.398804,13.469118,1.062178,-40.299740,0.106304,0.000000
88.790001,59.422829,-40.299740,0.005200,0.004182,0.106218,264.325958,13.465405,1.062178,-40.299740,0.106304,0.000000
89.020004,59.390060,-40.299740,0.005200,0.004182,0.106218,264.180176,13.457980,1.062178,-40.299740,0.106304,0.000000
89.250008,59.377769,-40.344223,0.005200,0.004182,0.106218,264.125519,13.455195,1.062178,-40.344223,0.106304,0.000000
89.480003,59.333458,-40.344223,0.005217,0.004182,0.106218,263.928406,13.445153,1.062178,-40.344223,0.106304,0.000000
89.710007,59.325638,-40.299740,0.005182,0.004182,0.106218,263.893616,13.443381,1.062178,-40.299740,0.106304,0.000000
89.940002,59.314095,-40.388702,0.005182,0.004182,0.106218,263.842255,13.440765,1.062178,-40.388702,0.106304,0.000000
90.170006,59.292496,-40.299740,0.005208,0.004182,0.106218,263.746185,13.435872,1.062178,-40.299740,0.106304,0.000000
90.400002,59.274994,-40.388702,0.005191,0.004182,0.106218,263.668335,13.431905,1.062178,-40.388702,0.106304,0.000000
90.630005,59.261215,-40.388702,0.005200,0.004182,0.106218,263.607056,13.428783,1.062178,-40.388702,0.106304,0.000000
90.860001,59.239616,-40.388702,0.005200,0.004182,0.106218,263.510986,13.423889,1.062178,-40.388702,0.106304,0.000000
91.090004,59.203125,-40.388702,0.005208,0.004182,0.106218,263.348663,13.415620,1.062178,-40.388702,0.106304,0.000000
91.320007,59.195679,-40.388702,0.005204,0.004182,0.106218,263.315521,13.413933,1.062178,-40.388702,0.106304,0.000000
91.550003,59.180038,-40.388702,0.005195,0.004182,0.106218,263.245972,13.410389,1.062178,-40.388702,0.106304,0.000000
91.780006,59.162910,-40.433186,0.005204,0.004182,0.106218,263.169769,13.406507,1.062178,-40.433186,0.106304,0.000000
92.010002,59.146523,-40.388702,0.005195,0.004182,0.106218,263.096863,13.402794,1.062178,-40.388702,0.106304,0.000000
92.240005,59.128654,-40.344223,0.005200,0.004182,0.106218,263.017395,13.398745,1.062178,-40.344223,0.106304,0.000000
92.470001,59.110779,-40.344223,0.005213,0.004182,0.106218,262.937866,13.394693,1.062178,-40.344223,0.106304,0.000000
92.700005,59.085457,-40.433186,0.005195,0.004182,0.106218,262.825226,13.388956,1.062178,-40.433186,0.106304,0.000000
92.930008,59.067955,-40.477665,0.005208,0.004182,0.106218,262.747375,13.384990,1.062178,-40.477665,0.106304,0.000000
93.160004,59.057526,-40.433186,0.005200,0.004182,0.106218,262.700989,13.382627,1.062178,-40.433186,0.106304,0.000000
93.390007,59.044868,-40.433186,0.005208,0.004182,0.106218,262.644684,13.379759,1.062178,-40.433186,0.106304,0.000000
93.620003,59.035561,-40.477665,0.005191,0.004182,0.106218,262.603302,13.377649,1.062178,-40.477665,0.106304,0.000000
93.850006,59.001297,-40.388702,0.005204,0.004182,0.106218,262.450867,13.369885,1.062178,-40.388702,0.106304,0.000000
94.080002,58.990875,-40.477665,0.005200,0.004182,0.106218,262.404510,13.367524,1.062178,-40.477665,0.106304,0.000000
94.310005,58.964066,-40.477665,0.005217,0.004182,0.106218,262.285248,13.361448,1.062178,-40.477665,0.106304,0.000000
94.540001,58.949539,-40.433186,0.005195,0.004182,0.106218,262.220642,13.358157,1.062178,-40.433186,0.106304,0.000000
94.770004,58.937996,-40.477665,0.005204,0.004182,0.106218,262.169312,13.355540,1.062178,-40.477665,0.106304,0.000000
95.000008,58.927567,-40.477665,0.005200,0.004182,0.106218,262.122894,13.353177,1.062178,-40.477665,0.106304,0.000000
95.230003,58.914162,-40.566628,0.005200,0.004182,0.106218,262.063293,13.350140,1.062178,-40.566628,0.106304,0.000000
95.460007,58.897408,-40.522148,0.005204,0.004182,0.106218,261.988739,13.346343,1.062178,-40.522148,0.106304,0.000000
95.690002,58.882141,-40.477665,0.005204,0.004182,0.106218,261.920837,13.342884,1.062178,-40.477665,0.106304,0.000000
95.920006,58.867249,-40.477665,0.005204,0.004182,0.106218,261.854614,13.339509,1.062178,-40.477665,0.106304,0.000000
96.150002,58.846390,-40.477665,0.005200,0.004182,0.106218,261.761810,13.334783,1.062178,-40.477665,0.106304,0.000000
96.380005,58.829262,-40.522148,0.005200,0.004182,0.106218,261.685638,13.330901,1.062178,-40.522148,0.106304,0.000000
96.610008,58.814743,-40.522148,0.005226,0.004182,0.106218,261.621033,13.327612,1.062178,-40.522148,0.106304,0.000000
96.840004,58.802452,-40.522148,0.005208,0.004182,0.106218,261.566376,13.324826,1.062178,-40.522148,0.106304,0.000000
97.070007,58.793518,-40.477665,0.005208,0.004182,0.106218,261.526642,13.322802,1.062178,-40.477665,0.106304,0.000000
97.300003,58.785698,-40.566628,0.005226,0.004182,0.106218,261.491852,13.321030,1.062178,-40.566628,0.106304,0.000000
97.530006,58.774895,-40.611107,0.005204,0.004182,0.106218,261.443787,13.318582,1.062178,-40.611107,0.106304,0.000000
97.760002,58.757767,-40.566628,0.005208,0.004182,0.106218,261.367615,13.314700,1.062178,-40.566628,0.106304,0.000000
97.800003,58.751068,-40.566628,0.005213,0.004182,0.106218,261.337799,13.313182,1.062178,-40.566628,0.106304,0.000000