File: Data/Symmetrical membranes compression/Durapore PVDF 5um test 2-1.csv
Time (sec),S:Load (lbs),S:HL1 (DIM),S:LVDT (in),S:Position (in),Ch:Position (mm),Ch:Load (N),Ch:Stress (MPa),Ch:Strain (mm/mm),Ch:HL1 (DIM),Set Point (),Cycles ()
0.010000,0.002983,-28.512289,-0.000009,-0.000000,-0.000000,0.013269,0.000676,-0.000000,-28.512289,0.000208,0.000000
0.240000,-0.003723,-28.467808,-0.000022,-0.000000,-0.000000,-0.016561,-0.000844,-0.000000,-28.467808,0.000208,0.000000
0.470000,0.001495,-28.467808,-0.000030,0.000064,0.001630,0.006652,0.000339,0.016303,-28.467808,0.002255,0.000000
0.700000,-0.019363,-28.423328,0.000013,0.000193,0.004891,-0.086133,-0.004388,0.048910,-28.423328,0.006088,0.000000
0.930000,-0.070374,-28.467808,0.000172,0.000341,0.008672,-0.313037,-0.015947,0.086721,-28.467808,0.009921,0.000000
1.160000,-0.040588,-28.423328,0.000332,0.000490,0.012436,-0.180546,-0.009197,0.124358,-28.423328,0.013754,0.000000
1.390000,-0.013031,-28.512289,0.000483,0.000639,0.016243,-0.057965,-0.002953,0.162431,-28.512289,0.017587,0.000000
1.620000,0.007820,-28.467808,0.000642,0.000790,0.020076,0.034786,0.001772,0.200762,-28.467808,0.021420,0.000000
1.850000,0.016014,-28.512289,0.000819,0.000949,0.024109,0.071234,0.003629,0.241088,-28.512289,0.025254,0.000000
2.080000,-0.006325,-28.512289,0.000987,0.001098,0.027881,-0.028134,-0.001433,0.278812,-28.512289,0.029087,0.000000
2.310000,-0.030159,-28.556770,0.001147,0.001245,0.031619,-0.134154,-0.006834,0.316190,-28.556770,0.032902,0.000000
2.540000,-0.006325,-28.556770,0.001289,0.001397,0.035496,-0.028134,-0.001433,0.354955,-28.556770,0.036736,0.000000
2.770000,0.032028,-28.512289,0.001436,0.001546,0.039259,0.142469,0.007258,0.392592,-28.512289,0.040569,0.000000
3.000000,0.056976,-28.512289,0.001617,0.001703,0.043248,0.253443,0.012911,0.432485,-28.512289,0.044402,0.000000
3.230000,0.156769,-28.467808,0.001781,0.001852,0.047038,0.697342,0.035524,0.470383,-28.467808,0.048235,0.000000
3.460000,0.332901,-28.556770,0.001919,0.001999,0.050776,1.480818,0.075436,0.507759,-28.556770,0.052068,0.000000
3.690000,0.602875,-28.601252,0.002074,0.002153,0.054678,2.681721,0.136613,0.546785,-28.601252,0.055901,0.000000
3.920000,0.606224,-28.512289,0.002108,0.000001,0.000026,2.696619,0.137372,0.000259,-28.512289,0.000304,0.000000
4.150000,0.576065,-28.512289,0.002126,0.000001,0.000026,2.562465,0.130538,0.000259,-28.512289,0.000304,0.000000
4.380000,0.574944,-28.512289,0.002139,0.000001,0.000026,2.557477,0.130284,0.000259,-28.512289,0.000486,0.000000
4.610000,0.545532,-28.690214,0.002126,0.000001,0.000026,2.426649,0.123619,0.000259,-28.690214,0.000867,0.000000
4.840000,0.541435,-28.645733,0.002117,0.000001,0.000026,2.408424,0.122691,0.000259,-28.645733,0.001258,0.000000
5.070000,0.523186,-28.645733,0.002130,0.000001,0.000026,2.327246,0.118556,0.000259,-28.645733,0.001639,0.000000
5.300000,0.533615,-28.556770,0.002113,0.000001,0.000035,2.373639,0.120919,0.000346,-28.556770,0.002021,0.000000
5.530000,0.739906,-28.556770,0.002182,0.000059,0.001500,3.291268,0.167665,0.015003,-28.556770,0.002402,0.000000
5.760000,0.697456,-28.645733,0.002195,0.000073,0.001847,3.102441,0.158046,0.018472,-28.645733,0.002784,0.000000
5.990000,0.726501,-28.645733,0.002195,0.000086,0.002185,3.231640,0.164628,0.021854,-28.645733,0.003174,0.000000
6.220000,0.787575,-28.601252,0.002212,0.000103,0.002619,3.503308,0.178467,0.026190,-28.601252,0.003556,0.000000
6.450000,0.839333,-28.645733,0.002246,0.000118,0.003001,3.733538,0.190195,0.030007,-28.645733,0.003937,0.000000
6.680000,0.869865,-28.645733,0.002233,0.000132,0.003348,3.869355,0.197114,0.033476,-28.645733,0.004319,0.000000
6.910000,0.892578,-28.601252,0.002268,0.000145,0.003677,3.970386,0.202261,0.036770,-28.601252,0.004700,0.000000
7.140000,0.964821,-28.690214,0.002272,0.000165,0.004180,4.291738,0.218632,0.041800,-28.690214,0.005091,0.000000
7.370000,0.996841,-28.690214,0.002268,0.000176,0.004475,4.434172,0.225887,0.044749,-28.690214,0.005472,0.000000
7.600000,0.977852,-28.601252,0.002307,0.000189,0.004813,4.349702,0.221584,0.048131,-28.601252,0.005854,0.000000
7.830000,1.044884,-28.645733,0.002307,0.000208,0.005290,4.647875,0.236774,0.052901,-28.645733,0.006235,0.000000
8.060000,1.052330,-28.734694,0.002328,0.000219,0.005559,4.680998,0.238461,0.055589,-28.734694,0.006617,0.000000
8.290000,1.124565,-28.690214,0.002345,0.000237,0.006027,5.002316,0.254830,0.060273,-28.690214,0.007007,0.000000
8.520000,1.135368,-28.690214,0.002367,0.000249,0.006322,5.050371,0.257278,0.063221,-28.690214,0.007389,0.000000
8.750000,1.142067,-28.645733,0.002384,0.000258,0.006547,5.080168,0.258796,0.065475,-28.645733,0.007770,0.000000
8.980000,1.200531,-28.690214,0.002380,0.000271,0.006894,5.340229,0.272044,0.068944,-28.690214,0.008152,0.000000
9.210000,1.340919,-28.734694,0.002414,0.000302,0.007675,5.964708,0.303857,0.076750,-28.734694,0.008533,0.000000
9.440001,1.290649,-28.734694,0.002414,0.000308,0.007831,5.741096,0.292465,0.078309,-28.734694,0.008924,0.000000
9.670000,1.349480,-28.779175,0.002436,0.000328,0.008325,6.002785,0.305796,0.083253,-28.779175,0.009305,0.000000
9.900001,1.412415,-28.734694,0.002453,0.000344,0.008733,6.282734,0.320058,0.087329,-28.734694,0.009687,0.000000
10.130000,1.417999,-28.779175,0.002449,0.000356,0.009036,6.307576,0.321323,0.090364,-28.779175,0.010068,0.000000
10.360001,1.472366,-28.779175,0.002488,0.000368,0.009340,6.549413,0.333643,0.093400,-28.779175,0.010450,0.000000
10.590000,1.548325,-28.779175,0.002492,0.000386,0.009800,6.887292,0.350855,0.097997,-28.779175,0.010840,0.000000
10.820001,1.587425,-28.823656,0.002518,0.000400,0.010164,7.061220,0.359716,0.101640,-28.823656,0.011222,0.000000
11.050000,1.626152,-28.779175,0.002518,0.000417,0.010598,7.233486,0.368491,0.105975,-28.779175,0.011604,0.000000
11.280001,1.669350,-28.779175,0.002565,0.000433,0.011005,7.425638,0.378280,0.110051,-28.779175,0.011985,0.000000
11.510000,1.681641,-28.823656,0.002578,0.000444,0.011265,7.480311,0.381065,0.112652,-28.823656,0.012375,0.000000
11.740001,1.715897,-28.823656,0.002591,0.000460,0.011682,7.632689,0.388828,0.116815,-28.823656,0.012757,0.000000
11.970000,1.744942,-28.823656,0.002591,0.000475,0.012054,7.761889,0.395409,0.120543,-28.823656,0.013139,0.000000
12.200001,1.839149,-28.779175,0.002613,0.000490,0.012453,8.180945,0.416757,0.124533,-28.779175,0.013520,0.000000
12.430000,1.808243,-28.779175,0.002630,0.000494,0.012557,8.043466,0.409754,0.125573,-28.779175,0.013902,0.000000
12.660001,1.922562,-28.868137,0.002626,0.000515,0.013069,8.551981,0.435659,0.130691,-28.868137,0.014292,0.000000
12.890000,1.995178,-28.868137,0.002660,0.000538,0.013659,8.874996,0.452114,0.136587,-28.868137,0.014673,0.000000
13.120001,2.062202,-28.868137,0.002690,0.000555,0.014092,9.173135,0.467302,0.140925,-28.868137,0.015055,0.000000
13.350000,2.052895,-28.868137,0.002686,0.000569,0.014457,9.131731,0.465193,0.144566,-28.868137,0.015437,0.000000
13.580001,2.089760,-28.823656,0.002716,0.000582,0.014786,9.295716,0.473546,0.147863,-28.823656,0.015818,0.000000
13.810000,2.132210,-28.912619,0.002725,0.000594,0.015081,9.484543,0.483166,0.150811,-28.912619,0.016208,0.000000
14.040001,2.217857,-28.957100,0.002742,0.000610,0.015489,9.865522,0.502574,0.154885,-28.957100,0.016590,0.000000
14.270000,2.301262,-28.868137,0.002764,0.000631,0.016018,10.236525,0.521473,0.160177,-28.868137,0.016972,0.000000
14.500001,2.309830,-28.868137,0.002764,0.000638,0.016200,10.274635,0.523415,0.161997,-28.868137,0.017353,0.000000
14.730000,2.419678,-28.868137,0.002807,0.000658,0.016711,10.763264,0.548307,0.167114,-28.868137,0.017735,0.000000
14.960001,2.447235,-28.868137,0.002802,0.000674,0.017110,10.885845,0.554551,0.171104,-28.868137,0.018125,0.000000
15.190001,2.503464,-28.957100,0.002828,0.000689,0.017501,11.135962,0.567293,0.175006,-28.957100,0.018507,0.000000
15.420001,2.537346,-28.868137,0.002846,0.000706,0.017925,11.286678,0.574971,0.179255,-28.868137,0.018888,0.000000
15.650001,2.539215,-28.912619,0.002850,0.000716,0.018194,11.294992,0.575394,0.181944,-28.912619,0.019270,0.000000
15.880001,2.619270,-28.912619,0.002859,0.000732,0.018593,11.651096,0.593535,0.185933,-28.912619,0.019651,0.000000
16.110001,2.760025,-28.912619,0.002893,0.000749,0.019036,12.277205,0.625431,0.190356,-28.912619,0.020042,0.000000
16.340000,2.743645,-28.957100,0.002893,0.000759,0.019270,12.204341,0.621719,0.192697,-28.957100,0.020423,0.000000
16.570002,2.868385,-29.001579,0.002915,0.000778,0.019764,12.759215,0.649985,0.197640,-29.001579,0.020805,0.000000
16.800001,2.879929,-29.001579,0.002928,0.000795,0.020180,12.810562,0.652601,0.201803,-29.001579,0.021186,0.000000
17.030001,2.974144,-28.957100,0.002953,0.000811,0.020605,13.229653,0.673951,0.206053,-28.957100,0.021568,0.000000
17.260000,2.992386,-29.001579,0.002962,0.000824,0.020926,13.310797,0.678084,0.209261,-29.001579,0.021958,0.000000
17.490002,3.005424,-28.957100,0.002988,0.000840,0.021325,13.368795,0.681039,0.213250,-28.957100,0.022340,0.000000
17.720001,3.039680,-29.001579,0.002984,0.000852,0.021637,13.521174,0.688801,0.216373,-29.001579,0.022721,0.000000
17.950001,3.199059,-29.001579,0.003022,0.000871,0.022132,14.230124,0.724917,0.221316,-29.001579,0.023103,0.000000
18.180000,3.233688,-29.001579,0.003031,0.000885,0.022470,14.384164,0.732764,0.224698,-29.001579,0.023485,0.000000
18.410002,3.246719,-29.046061,0.003044,0.000894,0.022695,14.442129,0.735717,0.226954,-29.046061,0.023875,0.000000
18.640001,3.333107,-29.090542,0.003053,0.000913,0.023181,14.826401,0.755293,0.231810,-29.090542,0.024256,0.000000
18.870001,3.509987,-29.090542,0.003074,0.000936,0.023771,15.613201,0.795374,0.237707,-29.090542,0.024638,0.000000
19.100000,3.479080,-29.046061,0.003091,0.000947,0.024065,15.475721,0.788371,0.240655,-29.046061,0.025019,0.000000
19.330002,3.450783,-29.001579,0.003078,0.000959,0.024352,15.349849,0.781959,0.243516,-29.001579,0.025401,0.000000
19.560001,3.588554,-29.001579,0.003109,0.000975,0.024777,15.962687,0.813178,0.247767,-29.001579,0.025791,0.000000
19.790001,3.643669,-29.090542,0.003122,0.000990,0.025141,16.207850,0.825667,0.251408,-29.090542,0.026173,0.000000
20.020000,3.730057,-29.046061,0.003130,0.001005,0.025522,16.592121,0.845243,0.255225,-29.046061,0.026554,0.000000
20.250002,3.755005,-29.046061,0.003139,0.001015,0.025783,16.703096,0.850896,0.257825,-29.046061,0.026936,0.000000
20.480001,3.841400,-29.046061,0.003165,0.001030,0.026156,17.087400,0.870474,0.261555,-29.046061,0.027326,0.000000
20.710001,3.947525,-29.046061,0.003182,0.001048,0.026624,17.559469,0.894522,0.266239,-29.046061,0.027708,0.000000
20.940001,4.024231,-29.135023,0.003203,0.001068,0.027127,17.900673,0.911904,0.271267,-29.135023,0.028089,0.000000
21.170000,3.996674,-29.090542,0.003229,0.001075,0.027300,17.778091,0.905659,0.273003,-29.090542,0.028471,0.000000
21.400002,4.083443,-29.135023,0.003238,0.001094,0.027786,18.164061,0.925321,0.277859,-29.135023,0.028853,0.000000
21.630001,4.130356,-29.046061,0.003247,0.001108,0.028150,18.372740,0.935952,0.281502,-29.046061,0.029243,0.000000
21.860001,4.249893,-29.090542,0.003242,0.001124,0.028558,18.904469,0.963040,0.285578,-29.090542,0.029624,0.000000
22.090000,4.385437,-29.135023,0.003298,0.001140,0.028965,19.507399,0.993754,0.289652,-29.135023,0.030006,0.000000
22.320002,4.357880,-29.135023,0.003277,0.001150,0.029200,19.384817,0.987510,0.291995,-29.135023,0.030388,0.000000
22.550001,4.555237,-29.135023,0.003294,0.001171,0.029746,20.262705,1.032231,0.297459,-29.135023,0.030769,0.000000
22.780001,4.614441,-29.135023,0.003324,0.001185,0.030101,20.526058,1.045647,0.301015,-29.135023,0.031159,0.000000
23.010000,4.614441,-29.090542,0.003333,0.001199,0.030457,20.526058,1.045647,0.304569,-29.090542,0.031541,0.000000
23.240002,4.698975,-29.179504,0.003372,0.001213,0.030821,20.902082,1.064803,0.308212,-29.179504,0.031923,0.000000
23.470001,4.798767,-29.223986,0.003372,0.001230,0.031246,21.345982,1.087416,0.312462,-29.223986,0.032304,0.000000
23.700001,4.767860,-29.223986,0.003376,0.001242,0.031558,21.208502,1.080413,0.315583,-29.223986,0.032686,0.000000
23.930000,4.948463,-29.179504,0.003389,0.001261,0.032018,22.011866,1.121338,0.320179,-29.179504,0.033076,0.000000
24.160002,4.952187,-29.179504,0.003423,0.001271,0.032295,22.028425,1.122182,0.322954,-29.179504,0.033458,0.000000
24.390001,5.146935,-29.223986,0.003436,0.001292,0.032816,22.894709,1.166312,0.328158,-29.223986,0.033839,0.000000
24.620001,5.290298,-29.223986,0.003466,0.001310,0.033284,23.532423,1.198799,0.332842,-29.223986,0.034221,0.000000
24.850000,5.289551,-29.179504,0.003454,0.001325,0.033657,23.529097,1.198629,0.336570,-29.179504,0.034602,0.000000
25.080002,5.345039,-29.179504,0.003492,0.001339,0.034013,23.775923,1.211203,0.340126,-29.179504,0.034992,0.000000
25.310001,5.330513,-29.179504,0.003479,0.001353,0.034359,23.711306,1.207911,0.343595,-29.179504,0.035374,0.000000
25.540001,5.397919,-29.223986,0.003523,0.001365,0.034680,24.011141,1.223186,0.346804,-29.223986,0.035756,0.000000
25.770000,5.555428,-29.268465,0.003540,0.001380,0.035062,24.711777,1.258878,0.350619,-29.268465,0.036137,0.000000
26.000002,5.546867,-29.268465,0.003535,0.001394,0.035400,24.673698,1.256938,0.354001,-29.268465,0.036519,0.000000
26.230001,5.661552,-29.268465,0.003566,0.001408,0.035764,25.183844,1.282926,0.357644,-29.268465,0.036909,0.000000
26.460001,5.744225,-29.223986,0.003583,0.001421,0.036094,25.551586,1.301660,0.360939,-29.223986,0.037291,0.000000
26.690001,6.137444,-29.268465,0.003596,0.001449,0.036814,27.300713,1.390765,0.368138,-29.268465,0.037672,0.000000
26.920002,5.962059,-29.268465,0.003617,0.001458,0.037030,26.520563,1.351022,0.370305,-29.268465,0.038054,0.000000
27.150002,6.032066,-29.312946,0.003622,0.001475,0.037456,26.831972,1.366886,0.374555,-29.312946,0.038435,0.000000
27.380001,6.042122,-29.312946,0.003626,0.001488,0.037802,26.876701,1.369164,0.378024,-29.312946,0.038826,0.000000
27.610001,6.175430,-29.268465,0.003660,0.001503,0.038175,27.469687,1.399372,0.381752,-29.268465,0.039207,0.000000
27.840002,6.367943,-29.357428,0.003678,0.001521,0.038635,28.326025,1.442997,0.386349,-29.357428,0.039589,0.000000
28.070002,6.331078,-29.268465,0.003686,0.001531,0.038886,28.162039,1.434643,0.388864,-29.268465,0.039970,0.000000
28.300001,6.551521,-29.357428,0.003695,0.001549,0.039355,29.142622,1.484596,0.393548,-29.357428,0.040352,0.000000
28.530001,6.503860,-29.312946,0.003725,0.001564,0.039728,28.930616,1.473796,0.397276,-29.312946,0.040742,0.000000
28.760002,6.615944,-29.357428,0.003725,0.001575,0.039996,29.429188,1.499194,0.399965,-29.357428,0.041124,0.000000
28.990002,6.796547,-29.268465,0.003755,0.001594,0.040491,30.232552,1.540120,0.404908,-29.268465,0.041505,0.000000
29.220001,6.920174,-29.312946,0.003764,0.001609,0.040881,30.782471,1.568134,0.408810,-29.312946,0.041887,0.000000
29.450001,6.914589,-29.401909,0.003764,0.001623,0.041228,30.757627,1.566868,0.412279,-29.401909,0.042277,0.000000
29.680002,7.055717,-29.357428,0.003773,0.001641,0.041688,31.385399,1.598848,0.416876,-29.357428,0.042659,0.000000
29.910002,6.998001,-29.312946,0.003811,0.001648,0.041852,31.128664,1.585770,0.418522,-29.312946,0.043040,0.000000
30.140001,7.071358,-29.401909,0.003807,0.001661,0.042190,31.454969,1.602393,0.421904,-29.401909,0.043422,0.000000
30.370001,7.095558,-29.401909,0.003842,0.001670,0.042416,31.562618,1.607877,0.424160,-29.401909,0.043804,0.000000
30.600002,7.507408,-29.401909,0.003850,0.001698,0.043118,33.394619,1.701203,0.431185,-29.401909,0.044194,0.000000
30.830002,7.464958,-29.446390,0.003850,0.001711,0.043465,33.205791,1.691584,0.434654,-29.446390,0.044575,0.000000
31.060001,7.668266,-29.357428,0.003889,0.001728,0.043899,34.110153,1.737654,0.438989,-29.357428,0.044957,0.000000
31.290001,7.780724,-29.401909,0.003936,0.001744,0.044289,34.610386,1.763137,0.442891,-29.401909,0.045339,0.000000
31.520002,7.832115,-29.401909,0.003898,0.001758,0.044653,34.838989,1.774783,0.446534,-29.401909,0.045720,0.000000
31.750002,7.977341,-29.446390,0.003945,0.001776,0.045113,35.484985,1.807691,0.451131,-29.446390,0.046110,0.000000
31.980001,7.953880,-29.446390,0.003962,0.001785,0.045339,35.380627,1.802375,0.453385,-29.446390,0.046492,0.000000
32.210003,8.173950,-29.446390,0.003962,0.001805,0.045842,36.359547,1.852244,0.458415,-29.446390,0.046873,0.000000
32.440002,8.309120,-29.401909,0.003958,0.001820,0.046240,36.960812,1.882874,0.462404,-29.401909,0.047255,0.000000
32.670002,8.128891,-29.401909,0.004023,0.001830,0.046475,36.159115,1.842033,0.464745,-29.401909,0.047637,0.000000
32.900002,8.559731,-29.490871,0.003992,0.001851,0.047004,38.075584,1.939663,0.470037,-29.490871,0.048027,0.000000
33.130001,8.507973,-29.490871,0.004036,0.001862,0.047307,37.845352,1.927934,0.473072,-29.490871,0.048408,0.000000
33.360001,8.703468,-29.446390,0.004031,0.001878,0.047706,38.714962,1.972234,0.477061,-29.446390,0.048790,0.000000
33.590000,8.847198,-29.446390,0.004066,0.001893,0.048070,39.354305,2.004804,0.480702,-29.446390,0.049172,0.000000
33.820004,9.002106,-29.446390,0.004066,0.001907,0.048443,40.043365,2.039906,0.484432,-29.446390,0.049553,0.000000
34.050003,8.899330,-29.535351,0.004066,0.001920,0.048773,39.586197,2.016617,0.487727,-29.535351,0.049944,0.000000
34.280003,9.376717,-29.535351,0.004105,0.001941,0.049302,41.709717,2.124794,0.493019,-29.535351,0.050325,0.000000
34.510002,9.434433,-29.490871,0.004118,0.001958,0.049744,41.966454,2.137873,0.497441,-29.490871,0.050707,0.000000
34.740002,9.507790,-29.446390,0.004139,0.001972,0.050100,42.292759,2.154496,0.500995,-29.446390,0.051088,0.000000
34.970001,9.507790,-29.535351,0.004143,0.001986,0.050455,42.292759,2.154496,0.504551,-29.535351,0.051470,0.000000
35.200001,9.529015,-29.579832,0.004148,0.001997,0.050724,42.387173,2.159306,0.507240,-29.579832,0.051860,0.000000
35.430000,9.833984,-29.579832,0.004165,0.002015,0.051184,43.743748,2.228413,0.511837,-29.579832,0.052242,0.000000
35.660000,10.058899,-29.535351,0.004199,0.002033,0.051635,44.744217,2.279379,0.516347,-29.535351,0.052623,0.000000
35.890003,9.866013,-29.535351,0.004199,0.002038,0.051773,43.886215,2.235670,0.517734,-29.535351,0.053005,0.000000
36.120003,10.234657,-29.579832,0.004234,0.002060,0.052328,45.526028,2.319206,0.523284,-29.579832,0.053386,0.000000
36.350002,10.438347,-29.579832,0.004217,0.002077,0.052753,46.432087,2.365363,0.527533,-29.579832,0.053777,0.000000
36.580002,10.551178,-29.624313,0.004260,0.002093,0.053152,46.933983,2.390931,0.531522,-29.624313,0.054158,0.000000
36.810001,10.625282,-29.624313,0.004264,0.002107,0.053517,47.263615,2.407723,0.535165,-29.624313,0.054540,0.000000
37.040001,10.626770,-29.579832,0.004277,0.002120,0.053855,47.270233,2.408060,0.538547,-29.579832,0.054921,0.000000
37.270000,10.881844,-29.624313,0.004281,0.002136,0.054245,48.404858,2.465861,0.542449,-29.624313,0.055312,0.000000
37.500000,11.097076,-29.624313,0.004299,0.002153,0.054678,49.362263,2.514633,0.546785,-29.624313,0.055693,0.000000
37.730003,11.091118,-29.624313,0.004324,0.002165,0.054982,49.335754,2.513283,0.549820,-29.624313,0.056075,0.000000
37.960003,10.963768,-29.624313,0.004337,0.002169,0.055095,48.769276,2.484425,0.550948,-29.624313,0.056456,0.000000
38.190002,10.662148,-29.579832,0.004329,0.002169,0.055104,47.427601,2.416077,0.551035,-29.579832,0.056838,0.000000
38.420002,11.993004,-29.579832,0.004363,0.002213,0.056205,53.347546,2.717654,0.562049,-29.579832,0.057228,0.000000
38.650002,11.801605,-29.624313,0.004393,0.002226,0.056543,52.496162,2.674282,0.565431,-29.624313,0.057610,0.000000
38.880001,11.948692,-29.668795,0.004385,0.002242,0.056951,53.150436,2.707612,0.569507,-29.668795,0.057991,0.000000
39.110001,11.941620,-29.668795,0.004424,0.002252,0.057211,53.118977,2.706010,0.572108,-29.668795,0.058373,0.000000
39.340000,12.434639,-29.624313,0.004402,0.002275,0.057792,55.312038,2.817729,0.577919,-29.624313,0.058754,0.000000
39.570004,12.336334,-29.624313,0.004437,0.002285,0.058043,54.874756,2.795453,0.580434,-29.624313,0.059145,0.000000
39.800003,12.287178,-29.668795,0.004445,0.002294,0.058278,54.656097,2.784314,0.582775,-29.668795,0.059526,0.000000
40.030003,12.853928,-29.668795,0.004458,0.002318,0.058876,57.177124,2.912742,0.588759,-29.668795,0.059908,0.000000
40.260002,13.202843,-29.713276,0.004480,0.002339,0.059422,58.729179,2.991807,0.594223,-29.713276,0.060290,0.000000
40.490002,13.074371,-29.713276,0.004462,0.002349,0.059656,58.157707,2.962695,0.596564,-29.713276,0.060671,0.000000
40.720001,13.076607,-29.668795,0.004527,0.002362,0.059986,58.167652,2.963202,0.599860,-29.668795,0.061061,0.000000
40.950001,13.308594,-29.713276,0.004536,0.002376,0.060342,59.199581,3.015770,0.603416,-29.713276,0.061443,0.000000
41.180000,13.585266,-29.802237,0.004527,0.002393,0.060784,60.430283,3.078465,0.607839,-29.802237,0.061825,0.000000
41.410004,13.665329,-29.713276,0.004540,0.002404,0.061070,60.786419,3.096608,0.610700,-29.713276,0.062206,0.000000
41.640003,13.777039,-29.713276,0.004557,0.002417,0.061400,61.283329,3.121922,0.613995,-29.713276,0.062588,0.000000
41.870003,13.839226,-29.713276,0.004570,0.002426,0.061625,61.559952,3.136013,0.616251,-29.713276,0.062978,0.000000
42.100002,14.749680,-29.713276,0.004587,0.002457,0.062397,65.609848,3.342325,0.623968,-29.713276,0.063360,0.000000
42.330002,14.771645,-29.713276,0.004600,0.002471,0.062761,65.707558,3.347303,0.627611,-29.713276,0.063741,0.000000
42.560001,14.732178,-29.757757,0.004622,0.002485,0.063108,65.531998,3.338359,0.631080,-29.757757,0.064123,0.000000
42.790001,14.830482,-29.757757,0.004639,0.002495,0.063368,65.969284,3.360635,0.633682,-29.757757,0.064504,0.000000
43.020000,15.078110,-29.713276,0.004652,0.002513,0.063819,67.070786,3.416749,0.638192,-29.713276,0.064894,0.000000
43.250004,15.378242,-29.802237,0.004661,0.002529,0.064244,68.405838,3.484759,0.642440,-29.802237,0.065276,0.000000
43.480003,15.607994,-29.757757,0.004691,0.002543,0.064582,69.427826,3.536822,0.645822,-29.757757,0.065658,0.000000
43.710003,15.459793,-29.802237,0.004682,0.002554,0.064860,68.768593,3.503239,0.648599,-29.802237,0.066039,0.000000
43.940002,16.013512,-29.802237,0.004708,0.002571,0.065311,71.231659,3.628714,0.653108,-29.802237,0.066421,0.000000
44.170002,16.189270,-29.846718,0.004730,0.002587,0.065718,72.013466,3.668541,0.657183,-29.846718,0.066811,0.000000
44.400002,16.416786,-29.757757,0.004751,0.002604,0.066143,73.025513,3.720097,0.661433,-29.757757,0.067193,0.000000
44.630001,16.600739,-29.802237,0.004756,0.002617,0.066481,73.843773,3.761781,0.664815,-29.802237,0.067574,0.000000
44.860001,16.801079,-29.846718,0.004777,0.002633,0.066872,74.734932,3.807179,0.668717,-29.846718,0.067956,0.000000
45.090004,17.209572,-29.802237,0.004799,0.002652,0.067349,76.552002,3.899745,0.673488,-29.802237,0.068337,0.000000
45.320004,17.276222,-29.802237,0.004816,0.002662,0.067626,76.848473,3.914848,0.676262,-29.802237,0.068728,0.000000
45.550003,17.215157,-29.846718,0.004812,0.002672,0.067860,76.576843,3.901010,0.678603,-29.846718,0.069109,0.000000
45.780003,17.934204,-29.802237,0.004833,0.002695,0.068450,79.775322,4.063949,0.684500,-29.802237,0.069491,0.000000
46.010002,18.096558,-29.935680,0.004816,0.002710,0.068823,80.497505,4.100739,0.688230,-29.935680,0.069872,0.000000
46.240002,18.406372,-29.846718,0.004876,0.002726,0.069239,81.875633,4.170944,0.692394,-29.846718,0.070263,0.000000
46.470001,18.509148,-29.846718,0.004881,0.002742,0.069638,82.332802,4.194233,0.696383,-29.846718,0.070644,0.000000
46.700001,18.690498,-29.846718,0.004889,0.002755,0.069968,83.139488,4.235328,0.699678,-29.846718,0.071026,0.000000
46.930004,18.784706,-29.846718,0.004898,0.002767,0.070289,83.558548,4.256675,0.702885,-29.846718,0.071407,0.000000
47.160004,19.216286,-29.935680,0.004911,0.002782,0.070670,85.478310,4.354473,0.706702,-29.935680,0.071789,0.000000
47.390003,19.462791,-29.935680,0.004932,0.002798,0.071060,86.574821,4.410331,0.710605,-29.935680,0.072179,0.000000
47.620003,19.708931,-29.891199,0.004950,0.002812,0.071433,87.669701,4.466108,0.714333,-29.891199,0.072561,0.000000
47.850002,20.178871,-29.935680,0.004967,0.002830,0.071884,89.760101,4.572598,0.718842,-29.935680,0.072942,0.000000
48.080002,20.852859,-29.891199,0.004980,0.002851,0.072413,92.758148,4.725326,0.724134,-29.891199,0.073324,0.000000
48.310001,20.705772,-29.891199,0.004971,0.002863,0.072717,92.103874,4.691995,0.727169,-29.891199,0.073706,0.000000
48.540001,20.902390,-29.980162,0.004997,0.002878,0.073090,92.978470,4.736549,0.730897,-29.980162,0.074096,0.000000
48.770000,21.233429,-29.935680,0.005001,0.002894,0.073506,94.451012,4.811564,0.735061,-29.935680,0.074477,0.000000
49.000004,21.603195,-29.980162,0.005032,0.002909,0.073896,96.095810,4.895354,0.738963,-29.980162,0.074859,0.000000
49.230003,21.950989,-29.980162,0.005036,0.002926,0.074313,97.642876,4.974165,0.743126,-29.980162,0.075240,0.000000
49.460003,21.739105,-30.024641,0.005075,0.002931,0.074443,96.700371,4.926152,0.744426,-30.024641,0.075622,0.000000
49.690002,22.675621,-30.024641,0.005062,0.002955,0.075058,100.866203,5.138369,0.750584,-30.024641,0.076012,0.000000
49.920002,22.936661,-29.980162,0.005070,0.002970,0.075431,102.027359,5.197522,0.754313,-29.980162,0.076394,0.000000
50.150002,23.040924,-29.935680,0.005088,0.002982,0.075752,102.491150,5.221148,0.757522,-29.935680,0.076775,0.000000
50.380001,23.322060,-29.980162,0.005105,0.002998,0.076160,103.741699,5.284854,0.761597,-29.980162,0.077157,0.000000
50.610001,23.561501,-29.980162,0.005131,0.003011,0.076481,104.806786,5.339112,0.764806,-29.980162,0.077539,0.000000
50.840004,23.861259,-29.980162,0.005113,0.003029,0.076932,106.140182,5.407039,0.769316,-29.980162,0.077929,0.000000
51.070004,24.433220,-29.980162,0.005161,0.003045,0.077339,108.684387,5.536647,0.773392,-29.980162,0.078310,0.000000
51.300003,23.994194,-29.980162,0.005152,0.003046,0.077374,106.731506,5.437162,0.773739,-29.980162,0.078692,0.000000
51.530003,24.241821,-30.024641,0.005174,0.003063,0.077799,107.833008,5.493275,0.777987,-30.024641,0.079074,0.000000
51.760002,25.468048,-30.024641,0.005165,0.003089,0.078458,113.287537,5.771142,0.784578,-30.024641,0.079455,0.000000
51.990002,25.826637,-30.069122,0.005195,0.003103,0.078822,114.882622,5.852399,0.788221,-30.069122,0.079845,0.000000
52.220001,25.986389,-30.024641,0.005217,0.003116,0.079143,115.593231,5.888600,0.791429,-30.024641,0.080227,0.000000
52.450001,26.400467,-30.069122,0.005243,0.003134,0.079594,117.435143,5.982431,0.795939,-30.069122,0.080609,0.000000
52.680004,26.565804,-30.069122,0.005256,0.003144,0.079863,118.170593,6.019897,0.798628,-30.069122,0.080990,0.000000
52.910004,27.087868,-30.069122,0.005251,0.003163,0.080348,120.492851,6.138199,0.803484,-30.069122,0.081372,0.000000
53.140003,26.827950,-30.113604,0.005269,0.003174,0.080609,119.336678,6.079300,0.806086,-30.113604,0.081762,0.000000
53.370003,27.533226,-30.069122,0.005273,0.003187,0.080947,122.473907,6.239118,0.809468,-30.069122,0.082144,0.000000
53.600002,28.331215,-30.069122,0.005299,0.003210,0.081528,126.023537,6.419945,0.815278,-30.069122,0.082525,0.000000
53.830002,28.655556,-30.158085,0.005303,0.003223,0.081866,127.466278,6.493442,0.818661,-30.158085,0.082907,0.000000
54.060001,28.916588,-30.113604,0.005329,0.003237,0.082222,128.627411,6.552592,0.822217,-30.113604,0.083288,0.000000
54.290001,29.536957,-30.113604,0.005333,0.003254,0.082664,131.386948,6.693170,0.826640,-30.113604,0.083679,0.000000
54.520004,29.552231,-30.113604,0.005359,0.003265,0.082933,131.454895,6.696631,0.829327,-30.113604,0.084060,0.000000
54.750004,30.037804,-30.113604,0.005359,0.003280,0.083314,133.614822,6.806664,0.833144,-30.113604,0.084442,0.000000
54.980003,30.307396,-30.113604,0.005389,0.003291,0.083601,134.814026,6.867754,0.836006,-30.113604,0.084823,0.000000
55.210003,30.773979,-30.113604,0.005402,0.003306,0.083973,136.889496,6.973484,0.839734,-30.113604,0.085214,0.000000
55.440002,31.442764,-30.158085,0.005372,0.003325,0.084450,139.864395,7.125032,0.844505,-30.158085,0.085595,0.000000
55.670002,32.123833,-30.158085,0.005411,0.003345,0.084953,142.893951,7.279365,0.849535,-30.158085,0.085977,0.000000
55.900002,32.549080,-30.158085,0.005445,0.003361,0.085370,144.785538,7.375727,0.853696,-30.158085,0.086358,0.000000
56.130001,32.837669,-30.158085,0.005471,0.003374,0.085708,146.069244,7.441122,0.857078,-30.158085,0.086740,0.000000
56.360004,33.151207,-30.202566,0.005437,0.003388,0.086046,147.463928,7.512171,0.860462,-30.202566,0.087130,0.000000
56.590004,33.348938,-30.158085,0.005467,0.003402,0.086410,148.343491,7.556978,0.864103,-30.158085,0.087512,0.000000
56.820004,34.012131,-30.158085,0.005493,0.003417,0.086801,151.293518,7.707259,0.868005,-30.158085,0.087893,0.000000
57.050003,34.583725,-30.158085,0.005484,0.003432,0.087182,153.836090,7.836784,0.871822,-30.158085,0.088275,0.000000
57.280003,34.619843,-30.158085,0.005510,0.003445,0.087494,153.996750,7.844968,0.874945,-30.158085,0.088656,0.000000
57.510002,35.565666,-30.247047,0.005506,0.003464,0.087989,158.203979,8.059295,0.879888,-30.247047,0.089047,0.000000
57.740002,36.194611,-30.202566,0.005523,0.003482,0.088431,161.001663,8.201816,0.884310,-30.202566,0.089428,0.000000
57.970001,36.477982,-30.202566,0.005558,0.003496,0.088787,162.262161,8.266028,0.887866,-30.202566,0.089810,0.000000
58.200005,36.806046,-30.158085,0.005553,0.003508,0.089107,163.721466,8.340369,0.891074,-30.158085,0.090191,0.000000
58.430004,37.092766,-30.158085,0.005549,0.003520,0.089411,164.996857,8.405341,0.894110,-30.158085,0.090573,0.000000
58.660004,37.910873,-30.291527,0.005579,0.003541,0.089949,168.635986,8.590727,0.899486,-30.291527,0.090963,0.000000
58.890003,38.598640,-30.291527,0.005605,0.003556,0.090313,171.695328,8.746576,0.903129,-30.291527,0.091345,0.000000
59.120003,38.767700,-30.247047,0.005592,0.003567,0.090599,172.447342,8.784886,0.905990,-30.247047,0.091726,0.000000
59.350002,38.270958,-30.247047,0.005618,0.003568,0.090616,170.237717,8.672323,0.906164,-30.247047,0.092108,0.000000
59.580002,37.787987,-30.291527,0.005609,0.003570,0.090668,168.089355,8.562881,0.906685,-30.291527,0.092490,0.000000
59.810001,40.826546,-30.336008,0.005627,0.003614,0.091805,181.605545,9.251428,0.918045,-30.336008,0.092880,0.000000
60.040005,41.102852,-30.336008,0.005631,0.003629,0.092186,182.834610,9.314039,0.921860,-30.336008,0.093262,0.000000
60.270004,41.627518,-30.291527,0.005652,0.003645,0.092576,185.168442,9.432930,0.925763,-30.291527,0.093643,0.000000
60.500004,41.529587,-30.291527,0.005652,0.003655,0.092828,184.732834,9.410739,0.928278,-30.291527,0.094025,0.000000
60.730003,42.935295,-30.291527,0.005678,0.003676,0.093383,190.985733,9.729278,0.933828,-30.291527,0.094406,0.000000
60.960003,42.751343,-30.336008,0.005696,0.003681,0.093504,190.167465,9.687593,0.935043,-30.336008,0.094796,0.000000
61.190002,42.872360,-30.380489,0.005700,0.003700,0.093973,190.705780,9.715015,0.939725,-30.380489,0.095178,0.000000
61.420002,45.064148,-30.336008,0.005730,0.003725,0.094623,200.455338,10.211681,0.946229,-30.336008,0.095560,0.000000
61.650002,45.597015,-30.291527,0.005747,0.003741,0.095022,202.825653,10.332432,0.950219,-30.291527,0.095941,0.000000
61.880001,45.722130,-30.424971,0.005752,0.003752,0.095299,203.382187,10.360783,0.952995,-30.424971,0.096323,0.000000
62.110004,45.932892,-30.336008,0.005747,0.003765,0.095629,204.319702,10.408543,0.956290,-30.336008,0.096713,0.000000
62.340004,46.480278,-30.336008,0.005752,0.003779,0.095993,206.754608,10.532581,0.959933,-30.336008,0.097094,0.000000
62.570004,47.449936,-30.336008,0.005790,0.003798,0.096479,211.067856,10.752309,0.964789,-30.336008,0.097476,0.000000
62.800003,47.178848,-30.336008,0.005764,0.003799,0.096505,209.862000,10.690880,0.965048,-30.336008,0.097858,0.000000
63.030003,48.364487,-30.380489,0.005803,0.003821,0.097060,215.135986,10.959549,0.970598,-30.380489,0.098239,0.000000
63.260002,48.957298,-30.380489,0.005803,0.003836,0.097424,217.772934,11.093883,0.974241,-30.380489,0.098630,0.000000
63.490002,50.332474,-30.424971,0.005838,0.003861,0.098066,223.890030,11.405502,0.980659,-30.424971,0.099011,0.000000
63.720001,50.603188,-30.424971,0.005816,0.003872,0.098343,225.094223,11.466846,0.983433,-30.424971,0.099393,0.000000
63.950005,51.121902,-30.380489,0.005846,0.003886,0.098708,227.401581,11.584389,0.987076,-30.380489,0.099774,0.000000
64.180000,51.312187,-30.424971,0.005846,0.003898,0.099020,228.248001,11.627508,0.990199,-30.424971,0.100165,0.000000
64.410004,52.264709,-30.380489,0.005842,0.003914,0.099427,232.485046,11.843353,0.994275,-30.380489,0.100546,0.000000
64.639999,53.031425,-30.424971,0.005868,0.003931,0.099835,235.895569,12.017093,0.998349,-30.424971,0.100928,0.000000
64.870003,53.642120,-30.424971,0.005864,0.003945,0.100191,238.612076,12.155478,1.001905,-30.424971,0.101309,0.000000
65.100006,54.180939,-30.469452,0.005890,0.003959,0.100564,241.008850,12.277576,1.005635,-30.469452,0.101691,0.000000
65.330002,55.233635,-30.513933,0.005907,0.003979,0.101058,245.691483,12.516120,1.010578,-30.513933,0.102081,0.000000
65.560005,55.864067,-30.469452,0.005924,0.003993,0.101413,248.495789,12.658978,1.014134,-30.469452,0.102463,0.000000
65.790001,56.339211,-30.558413,0.005902,0.004005,0.101725,250.609329,12.766647,1.017255,-30.558413,0.102844,0.000000
66.020004,57.052307,-30.424971,0.005928,0.004021,0.102133,253.781342,12.928238,1.021331,-30.424971,0.103226,0.000000
66.250000,57.622406,-30.469452,0.005928,0.004033,0.102428,256.317261,13.057424,1.024280,-30.469452,0.103608,0.000000
66.480003,58.715324,-30.513933,0.005959,0.004052,0.102931,261.178802,13.305082,1.029310,-30.513933,0.103998,0.000000
66.710007,59.203499,-30.513933,0.005959,0.004064,0.103235,263.350311,13.415705,1.032345,-30.513933,0.104379,0.000000
66.940002,59.705833,-30.513933,0.005980,0.004079,0.103599,265.584808,13.529535,1.035988,-30.513933,0.104761,0.000000
67.170006,60.666550,-30.513933,0.005963,0.004093,0.103972,269.858276,13.747236,1.039716,-30.513933,0.105142,0.000000
67.400002,61.690575,-30.469452,0.005997,0.004113,0.104475,274.413391,13.979283,1.044746,-30.469452,0.105524,0.000000
67.630005,62.313927,-30.558413,0.006010,0.004127,0.104822,277.186188,14.120538,1.048215,-30.558413,0.105914,0.000000
67.860001,62.916420,-30.558413,0.005997,0.004142,0.105195,279.866211,14.257065,1.051945,-30.558413,0.106296,0.000000
68.090004,63.538658,-30.513933,0.006015,0.004153,0.105498,282.634064,14.398066,1.054979,-30.513933,0.106677,0.000000
68.320000,64.188454,-30.558413,0.006040,0.004169,0.105888,285.524506,14.545312,1.058883,-30.558413,0.107059,0.000000
68.550003,65.133156,-30.513933,0.006049,0.004184,0.106270,289.726746,14.759384,1.062698,-30.513933,0.107440,0.000000
68.780006,66.047707,-30.558413,0.006045,0.004200,0.106669,293.794861,14.966624,1.066687,-30.558413,0.107831,0.000000
69.010002,66.760429,-30.602894,0.006053,0.004216,0.107085,296.965210,15.128129,1.070851,-30.602894,0.108212,0.000000
69.240005,67.094444,-30.558413,0.006084,0.004213,0.107007,298.450989,15.203818,1.070069,-30.558413,0.107302,0.000000
69.470001,66.467369,-30.558413,0.006088,0.004213,0.107007,295.661621,15.061721,1.070069,-30.558413,0.107302,0.000000
69.700005,65.976585,-30.602894,0.006101,0.004209,0.106912,293.478516,14.950507,1.069116,-30.602894,0.107007,0.000000
69.930000,65.547615,-30.558413,0.006079,0.004208,0.106886,291.570343,14.853302,1.068856,-30.558413,0.107007,0.000000
70.160004,65.171135,-30.602894,0.006101,0.004208,0.106877,289.895691,14.767991,1.068769,-30.602894,0.107007,0.000000
70.390007,64.846809,-30.602894,0.006062,0.004207,0.106868,288.453003,14.694497,1.068682,-30.602894,0.107007,0.000000
70.620003,64.560081,-30.602894,0.006092,0.004207,0.106860,287.177582,14.629524,1.068595,-30.602894,0.107007,0.000000
70.850006,64.304634,-30.602894,0.006092,0.004207,0.106860,286.041290,14.571638,1.068595,-30.602894,0.107007,0.000000
71.080002,64.058128,-30.647375,0.006109,0.004207,0.106851,284.944794,14.515779,1.068508,-30.647375,0.107007,0.000000
71.310005,63.861137,-30.647375,0.006096,0.004207,0.106851,284.068512,14.471141,1.068508,-30.647375,0.107007,0.000000
71.540001,63.674583,-30.691856,0.006109,0.004207,0.106851,283.238678,14.428866,1.068508,-30.691856,0.107007,0.000000
71.770004,63.481316,-30.647375,0.006109,0.004206,0.106842,282.378998,14.385072,1.068421,-30.647375,0.107007,0.000000
72.000000,63.314873,-30.647375,0.006105,0.004206,0.106842,281.638611,14.347355,1.068421,-30.647375,0.107007,0.000000
72.230003,63.171867,-30.647375,0.006114,0.004206,0.106842,281.002502,14.314950,1.068421,-30.647375,0.107007,0.000000
72.460007,63.009514,-30.647375,0.006114,0.004206,0.106842,280.280304,14.278159,1.068421,-30.647375,0.107007,0.000000
72.690002,62.881798,-30.647375,0.006075,0.004206,0.106842,279.712219,14.249219,1.068421,-30.647375,0.107007,0.000000
72.920006,62.759285,-30.691856,0.006114,0.004206,0.106842,279.167236,14.221457,1.068421,-30.691856,0.107007,0.000000
73.150002,62.653908,-30.647375,0.006096,0.004206,0.106834,278.698486,14.197578,1.068336,-30.647375,0.107007,0.000000
73.380005,62.510170,-30.691856,0.006118,0.004206,0.106834,278.059113,14.165007,1.068336,-30.691856,0.107007,0.000000
73.610001,62.415962,-30.780819,0.006109,0.004206,0.106834,277.640076,14.143659,1.068336,-30.780819,0.107007,0.000000
73.840004,62.299034,-30.691856,0.006092,0.004206,0.106834,277.119934,14.117163,1.068336,-30.691856,0.107007,0.000000
74.070007,62.192162,-30.691856,0.006105,0.004206,0.106834,276.644562,14.092945,1.068336,-30.691856,0.107007,0.000000
74.300003,62.119919,-30.736338,0.006135,0.004206,0.106834,276.323212,14.076575,1.068336,-30.736338,0.107007,0.000000
74.530006,62.022736,-30.691856,0.006096,0.004206,0.106834,275.890900,14.054553,1.068336,-30.691856,0.107007,0.000000
74.760002,61.946770,-30.780819,0.006096,0.004206,0.106834,275.553009,14.037339,1.068336,-30.780819,0.107007,0.000000
74.990005,61.857399,-30.780819,0.006096,0.004206,0.106834,275.155457,14.017087,1.068336,-30.780819,0.107007,0.000000
75.220001,61.765427,-30.736338,0.006114,0.004206,0.106834,274.746338,13.996245,1.068336,-30.736338,0.107007,0.000000
75.450005,61.695419,-30.691856,0.006118,0.004206,0.106834,274.434937,13.980382,1.068336,-30.691856,0.107007,0.000000
75.680000,61.616844,-30.736338,0.006127,0.004206,0.106834,274.085419,13.962577,1.068336,-30.736338,0.107007,0.000000
75.910004,61.547211,-30.736338,0.006122,0.004206,0.106834,273.775665,13.946797,1.068336,-30.736338,0.107007,0.000000
76.140007,61.476837,-30.780819,0.006140,0.004206,0.106834,273.462616,13.930850,1.068336,-30.780819,0.107007,0.000000
76.370003,61.419487,-30.780819,0.006105,0.004206,0.106834,273.207520,13.917854,1.068336,-30.780819,0.107007,0.000000
76.600006,61.343155,-30.780819,0.006118,0.004206,0.106834,272.867981,13.900558,1.068336,-30.780819,0.107007,0.000000
76.830002,61.281342,-30.825298,0.006131,0.004206,0.106834,272.593018,13.886550,1.068336,-30.825298,0.107007,0.000000
77.060005,61.213570,-30.825298,0.006131,0.004206,0.106834,272.291565,13.871193,1.068336,-30.825298,0.107007,0.000000
77.290001,61.156219,-30.780819,0.006118,0.004206,0.106834,272.036438,13.858197,1.068336,-30.780819,0.107007,0.000000
77.520004,61.102600,-30.825298,0.006114,0.004206,0.106834,271.797943,13.846047,1.068336,-30.825298,0.107007,0.000000
77.750000,61.043022,-30.780819,0.006105,0.004206,0.106834,271.532928,13.832546,1.068336,-30.780819,0.107007,0.000000
77.980003,60.991631,-30.825298,0.006140,0.004206,0.106834,271.304321,13.820901,1.068336,-30.825298,0.107007,0.000000
78.210007,60.926094,-30.869780,0.006105,0.004206,0.106834,271.012787,13.806050,1.068336,-30.869780,0.107007,0.000000
78.440002,60.889977,-30.869780,0.006109,0.004206,0.106834,270.852142,13.797866,1.068336,-30.869780,0.107007,0.000000
78.670006,60.840080,-30.869780,0.006144,0.004206,0.106834,270.630188,13.786560,1.068336,-30.869780,0.107007,0.000000
78.900002,60.776405,-30.825298,0.006131,0.004206,0.106834,270.346954,13.772130,1.068336,-30.825298,0.107007,0.000000
79.130005,60.725761,-30.825298,0.006114,0.004206,0.106834,270.121674,13.760654,1.068336,-30.825298,0.107007,0.000000
79.360001,60.690384,-30.869780,0.006131,0.004206,0.106834,269.964325,13.752637,1.068336,-30.869780,0.107007,0.000000
79.590004,60.652779,-30.914261,0.006131,0.004206,0.106825,269.797028,13.744116,1.068249,-30.914261,0.107007,0.000000
79.820007,60.601013,-30.914261,0.006109,0.004206,0.106825,269.566772,13.732387,1.068249,-30.914261,0.107007,0.000000
80.050003,60.558189,-30.869780,0.006144,0.004206,0.106825,269.376282,13.722682,1.068249,-30.869780,0.107007,0.000000
80.280006,60.505318,-30.914261,0.006135,0.004206,0.106825,269.141083,13.710701,1.068249,-30.914261,0.107007,0.000000
80.510002,60.458023,-30.958742,0.006127,0.004206,0.106825,268.930725,13.699984,1.068249,-30.958742,0.107007,0.000000
80.740005,60.421532,-30.958742,0.006118,0.004206,0.106825,268.768402,13.691715,1.068249,-30.958742,0.107007,0.000000
80.970001,60.384666,-30.958742,0.006109,0.004206,0.106825,268.604401,13.683361,1.068249,-30.958742,0.107007,0.000000
81.200005,60.355247,-30.958742,0.006140,0.004206,0.106825,268.473541,13.676695,1.068249,-30.958742,0.107007,0.000000
81.430000,60.311310,-30.914261,0.006109,0.004206,0.106825,268.278107,13.666739,1.068249,-30.914261,0.107007,0.000000
81.660004,60.268860,-30.958742,0.006144,0.004206,0.106825,268.089264,13.657119,1.068249,-30.958742,0.107007,0.000000
81.890007,60.214493,-30.958742,0.006101,0.004206,0.106825,267.847443,13.644799,1.068249,-30.958742,0.107007,0.000000
82.120003,60.188423,-30.958742,0.006101,0.004206,0.106825,267.731476,13.638891,1.068249,-30.958742,0.107007,0.000000
82.350006,60.158638,-30.958742,0.006140,0.004206,0.106825,267.598999,13.632142,1.068249,-30.958742,0.107007,0.000000
82.580002,60.116928,-30.914261,0.006144,0.004206,0.106825,267.413452,13.622691,1.068249,-30.914261,0.107007,0.000000
82.810005,60.083420,-31.003223,0.006131,0.004206,0.106825,267.264404,13.615098,1.068249,-31.003223,0.107007,0.000000
83.040001,60.051018,-31.003223,0.006127,0.004206,0.106825,267.120270,13.607755,1.068249,-31.003223,0.107007,0.000000
83.270004,60.019745,-31.003223,0.006144,0.004206,0.106825,266.981171,13.600668,1.068249,-31.003223,0.107007,0.000000
83.500008,59.976173,-31.047705,0.006122,0.004206,0.106825,266.787354,13.590796,1.068249,-31.047705,0.107007,0.000000
83.730003,59.941917,-31.047705,0.006135,0.004206,0.106825,266.634979,13.583033,1.068249,-31.047705,0.107007,0.000000
83.960007,59.903191,-31.047705,0.006127,0.004206,0.106825,266.462708,13.574258,1.068249,-31.047705,0.107007,0.000000
84.190002,59.881592,-31.047705,0.006131,0.004206,0.106825,266.366638,13.569363,1.068249,-31.047705,0.107007,0.000000
84.420006,59.839890,-31.047705,0.006114,0.004206,0.106825,266.181122,13.559913,1.068249,-31.047705,0.107007,0.000000
84.650002,59.821266,-31.003223,0.006127,0.004206,0.106825,266.098267,13.555693,1.068249,-31.003223,0.107007,0.000000
84.880005,59.801163,-31.047705,0.006127,0.004206,0.106825,266.008850,13.551137,1.068249,-31.047705,0.107007,0.000000
85.110001,59.755356,-31.092184,0.006131,0.004206,0.106825,265.805084,13.540757,1.068249,-31.092184,0.107007,0.000000
85.340004,59.728546,-31.047705,0.006135,0.004206,0.106825,265.685852,13.534682,1.068249,-31.047705,0.107007,0.000000
85.570007,59.693169,-31.047705,0.006135,0.004206,0.106825,265.528473,13.526666,1.068249,-31.047705,0.107007,0.000000
85.800003,59.667480,-31.047705,0.006127,0.004206,0.106825,265.414215,13.520844,1.068249,-31.047705,0.107007,0.000000
86.030006,59.640297,-31.092184,0.006135,0.004206,0.106825,265.293304,13.514685,1.068249,-31.092184,0.107007,0.000000
86.260002,59.628006,-31.136665,0.006140,0.004206,0.106825,265.238617,13.511900,1.068249,-31.136665,0.107007,0.000000
86.490005,59.592628,-31.092184,0.006109,0.004206,0.106825,265.081238,13.503882,1.068249,-31.092184,0.107007,0.000000
86.720001,59.565079,-31.136665,0.006135,0.004206,0.106825,264.958710,13.497640,1.068249,-31.136665,0.107007,0.000000
86.950005,59.531937,-31.092184,0.006153,0.004206,0.106825,264.811279,13.490129,1.068249,-31.092184,0.107007,0.000000
87.180008,59.495071,-31.136665,0.006135,0.004206,0.106825,264.647308,13.481775,1.068249,-31.136665,0.107007,0.000000
87.410004,59.484642,-31.136665,0.006127,0.004206,0.106825,264.600891,13.479412,1.068249,-31.136665,0.107007,0.000000
87.640007,59.466026,-31.136665,0.006140,0.004206,0.106825,264.518097,13.475194,1.068249,-31.136665,0.107007,0.000000
87.870003,59.435120,-31.136665,0.006135,0.004206,0.106825,264.380615,13.468190,1.068249,-31.136665,0.107007,0.000000
88.100006,59.418358,-31.136665,0.006122,0.004206,0.106825,264.306061,13.464393,1.068249,-31.136665,0.107007,0.000000
88.330002,59.391922,-31.181147,0.006140,0.004206,0.106825,264.188477,13.458402,1.068249,-31.181147,0.107007,0.000000
88.560005,59.353943,-31.181147,0.006140,0.004206,0.106825,264.019531,13.449796,1.068249,-31.181147,0.107007,0.000000
88.790001,59.341278,-31.092184,0.006127,0.004206,0.106825,263.963196,13.446925,1.068249,-31.092184,0.107007,0.000000
89.020004,59.320801,-31.136665,0.006122,0.004206,0.106825,263.872101,13.442286,1.068249,-31.136665,0.107007,0.000000
89.250008,59.289520,-31.136665,0.006135,0.004206,0.106825,263.732971,13.435197,1.068249,-31.136665,0.107007,0.000000
89.480003,59.280952,-31.181147,0.006157,0.004206,0.106825,263.694855,13.433256,1.068249,-31.181147,0.107007,0.000000
89.710007,59.248932,-31.225628,0.006131,0.004206,0.106825,263.552399,13.426000,1.068249,-31.225628,0.107007,0.000000
89.940002,59.206482,-31.181147,0.006140,0.004206,0.106825,263.363586,13.416380,1.068249,-31.181147,0.107007,0.000000
90.170006,59.204994,-31.181147,0.006135,0.004206,0.106825,263.356964,13.416043,1.068249,-31.181147,0.107007,0.000000
90.400002,59.185257,-31.181147,0.006135,0.004206,0.106825,263.269165,13.411572,1.068249,-31.181147,0.107007,0.000000
90.630005,59.159561,-31.225628,0.006153,0.004206,0.106825,263.154877,13.405748,1.068249,-31.225628,0.107007,0.000000
90.860001,59.147644,-31.225628,0.006135,0.004206,0.106825,263.101868,13.403048,1.068249,-31.225628,0.107007,0.000000
91.090004,59.129028,-31.181147,0.006140,0.004206,0.106825,263.019043,13.398829,1.068249,-31.181147,0.107007,0.000000
91.320007,59.091415,-31.181147,0.006118,0.004206,0.106825,262.851746,13.390306,1.068249,-31.181147,0.107007,0.000000
91.550003,59.073914,-31.181147,0.006153,0.004206,0.106825,262.773895,13.386340,1.068249,-31.181147,0.107007,0.000000
91.780006,59.056786,-31.225628,0.006144,0.004206,0.106825,262.697693,13.382459,1.068249,-31.225628,0.107007,0.000000
92.010002,59.024391,-31.225628,0.006135,0.004206,0.106825,262.553619,13.375118,1.068249,-31.225628,0.107007,0.000000
92.240005,59.019547,-31.270109,0.006135,0.004206,0.106825,262.532043,13.374021,1.068249,-31.270109,0.107007,0.000000
92.470001,58.993111,-31.270109,0.006135,0.004206,0.106825,262.414459,13.368031,1.068249,-31.270109,0.107007,0.000000
92.700005,58.962578,-31.270109,0.006131,0.004206,0.106825,262.278656,13.361111,1.068249,-31.270109,0.107007,0.000000
92.930008,58.948051,-31.270109,0.006144,0.004206,0.106825,262.214020,13.357819,1.068249,-31.270109,0.107007,0.000000
93.160004,58.930183,-31.270109,0.006131,0.004206,0.106825,262.134552,13.353771,1.068249,-31.270109,0.107007,0.000000
93.390007,58.911560,-31.314590,0.006127,0.004206,0.106825,262.051697,13.349550,1.068249,-31.314590,0.107007,0.000000
93.620003,58.908211,-31.314590,0.006144,0.004206,0.106825,262.036804,13.348791,1.068249,-31.314590,0.107007,0.000000
93.850006,58.896294,-31.359070,0.006148,0.004206,0.106825,261.983795,13.346090,1.068249,-31.359070,0.107007,0.000000
94.080002,58.849747,-31.359070,0.006161,0.004206,0.106825,261.776733,13.335544,1.068249,-31.359070,0.107007,0.000000
94.310005,58.844910,-31.270109,0.006127,0.004206,0.106825,261.755219,13.334448,1.068249,-31.270109,0.107007,0.000000
94.540001,58.825912,-31.359070,0.006140,0.004206,0.106825,261.670715,13.330143,1.068249,-31.359070,0.107007,0.000000
94.770004,58.803574,-31.270109,0.006135,0.004206,0.106825,261.571350,13.325081,1.068249,-31.270109,0.107007,0.000000
95.000008,58.792778,-31.314590,0.006135,0.004206,0.106825,261.523346,13.322634,1.068249,-31.314590,0.107007,0.000000
95.230003,58.777504,-31.359070,0.006131,0.004206,0.106825,261.455383,13.319173,1.068249,-31.359070,0.107007,0.000000
95.460007,58.752556,-31.403551,0.006144,0.004206,0.106825,261.344421,13.313519,1.068249,-31.403551,0.107007,0.000000
95.690002,58.725006,-31.403551,0.006131,0.004206,0.106825,261.221863,13.307277,1.068249,-31.403551,0.107007,0.000000
95.920006,58.732826,-31.359070,0.006144,0.004206,0.106825,261.256653,13.309049,1.068249,-31.359070,0.107007,0.000000
96.150002,58.702286,-31.403551,0.006153,0.004206,0.106825,261.120819,13.302129,1.068249,-31.403551,0.107007,0.000000
96.380005,58.675850,-31.403551,0.006153,0.004206,0.106825,261.003204,13.296138,1.068249,-31.403551,0.107007,0.000000
96.610008,58.664680,-31.403551,0.006135,0.004206,0.106825,260.953522,13.293607,1.068249,-31.403551,0.107007,0.000000
96.840004,58.650902,-31.359070,0.006135,0.004206,0.106825,260.892242,13.290484,1.068249,-31.359070,0.107007,0.000000
97.070007,58.633026,-31.314590,0.006105,0.004206,0.106825,260.812714,13.286433,1.068249,-31.314590,0.107007,0.000000
97.300003,58.626328,-31.403551,0.006148,0.004206,0.106825,260.782928,13.284916,1.068249,-31.403551,0.107007,0.000000
97.530006,58.605469,-31.403551,0.006157,0.004206,0.106825,260.690155,13.280189,1.068249,-31.403551,0.107007,0.000000
97.760002,58.586853,-31.448032,0.006118,0.004206,0.106825,260.607330,13.275970,1.068249,-31.448032,0.107007,0.000000
97.990005,58.566002,-31.492514,0.006153,0.004206,0.106825,260.514587,13.271245,1.068249,-31.492514,0.107007,0.000000
98.220001,58.564140,-31.448032,0.006153,0.004206,0.106825,260.506317,13.270824,1.068249,-31.448032,0.107007,0.000000
98.450005,58.542168,-31.448032,0.006140,0.004206,0.106825,260.408569,13.265844,1.068249,-31.448032,0.107007,0.000000
98.680008,58.505302,-31.448032,0.006148,0.004206,0.106825,260.244568,13.257491,1.068249,-31.448032,0.107007,0.000000
98.910004,58.500465,-31.492514,0.006157,0.004206,0.106825,260.223053,13.256395,1.068249,-31.492514,0.107007,0.000000
99.140007,58.488922,-31.492514,0.006144,0.004206,0.106825,260.171722,13.253779,1.068249,-31.492514,0.107007,0.000000
99.370003,58.477379,-31.448032,0.006140,0.004206,0.106825,260.120361,13.251163,1.068249,-31.448032,0.107007,0.000000
99.600006,58.466576,-31.492514,0.006131,0.004206,0.106825,260.072327,13.248715,1.068249,-31.492514,0.107007,0.000000