File: Data/Symmetrical membranes compression/Durapore PVDF 5um test 2-2.csv
Time (sec),S:Load (lbs),S:HL1 (DIM),S:LVDT (in),S:Position (in),Ch:Position (mm),Ch:Load (N),Ch:Stress (MPa),Ch:Strain (mm/mm),Ch:HL1 (DIM),Set Point (),Cycles ()
0.010000,0.002975,-33.449677,0.000017,-0.000000,-0.000000,0.013236,0.000674,-0.000000,-33.449677,0.000225,0.000000
0.240000,-0.001122,-33.405193,0.000009,-0.000000,-0.000000,-0.004989,-0.000254,-0.000000,-33.405193,0.000225,0.000000
0.470000,-0.010429,-33.360714,0.000013,0.000059,0.001500,-0.046392,-0.002363,0.015003,-33.360714,0.002099,0.000000
0.700000,-0.007446,-33.316231,0.000047,0.000187,0.004744,-0.033123,-0.001687,0.047436,-33.316231,0.005932,0.000000
0.930000,-0.009315,-33.360714,0.000181,0.000339,0.008612,-0.041437,-0.002111,0.086116,-33.360714,0.009765,0.000000
1.160000,0.069260,-33.405193,0.000349,0.000487,0.012367,0.308082,0.015694,0.123666,-33.405193,0.013581,0.000000
1.390000,0.177246,-33.405193,0.000530,0.000631,0.016035,0.788430,0.040165,0.160349,-33.405193,0.017414,0.000000
1.620000,0.284859,-33.405193,0.000677,0.000790,0.020076,1.267115,0.064550,0.200762,-33.405193,0.021247,0.000000
1.850000,0.490784,-33.449677,0.000858,0.000943,0.023953,2.183115,0.111213,0.239527,-33.449677,0.025080,0.000000
2.080000,0.639359,-33.405193,0.000961,-0.000007,-0.000182,2.844009,0.144881,-0.001821,-33.405193,0.000035,0.000000
2.310000,0.589836,-33.360714,0.000936,-0.000007,-0.000182,2.623722,0.133659,-0.001821,-33.360714,0.000035,0.000000
2.540000,0.535469,-33.449677,0.000940,-0.000008,-0.000191,2.381885,0.121339,-0.001908,-33.449677,0.000043,0.000000
2.770000,0.563766,-33.405193,0.000923,-0.000007,-0.000182,2.507759,0.127751,-0.001821,-33.405193,0.000425,0.000000
3.000000,0.558556,-33.405193,0.000940,-0.000004,-0.000104,2.484579,0.126571,-0.001041,-33.405193,0.000807,0.000000
3.230000,0.600266,-33.449677,0.000936,0.000011,0.000277,2.670114,0.136022,0.002774,-33.449677,0.001188,0.000000
3.460000,0.638245,-33.405193,0.000940,0.000023,0.000581,2.839054,0.144628,0.005810,-33.405193,0.001578,0.000000
3.690000,0.672874,-33.494156,0.000961,0.000036,0.000919,2.993095,0.152476,0.009194,-33.494156,0.001960,0.000000
3.920000,0.730965,-33.494156,0.000987,0.000055,0.001396,3.251493,0.165639,0.013962,-33.494156,0.002342,0.000000
4.150000,0.764107,-33.494156,0.001005,0.000068,0.001734,3.398916,0.173149,0.017344,-33.494156,0.002723,0.000000
4.380000,0.798363,-33.449677,0.001013,0.000088,0.002237,3.551295,0.180912,0.022374,-33.449677,0.003105,0.000000
4.610000,0.821449,-33.449677,0.001026,0.000099,0.002524,3.653989,0.186143,0.025236,-33.449677,0.003495,0.000000
4.840000,0.839325,-33.538635,0.001035,0.000109,0.002758,3.733504,0.190194,0.027579,-33.538635,0.003876,0.000000
5.070000,0.947311,-33.583118,0.001082,0.000135,0.003417,4.213851,0.214664,0.034168,-33.583118,0.004258,0.000000
5.300000,0.966675,-33.538635,0.001061,0.000150,0.003807,4.299984,0.219052,0.038070,-33.538635,0.004640,0.000000
5.530000,0.943214,-33.538635,0.001074,0.000159,0.004033,4.195627,0.213735,0.040326,-33.538635,0.005021,0.000000
5.760000,0.993118,-33.538635,0.001087,0.000174,0.004432,4.417611,0.225044,0.044315,-33.538635,0.005411,0.000000
5.990000,1.035568,-33.538635,0.001130,0.000189,0.004804,4.606438,0.234663,0.048044,-33.538635,0.005793,0.000000
6.220000,1.065353,-33.538635,0.001151,0.000203,0.005160,4.738929,0.241413,0.051599,-33.538635,0.006175,0.000000
6.450000,1.156212,-33.583118,0.001168,0.000221,0.005620,5.143087,0.262001,0.056196,-33.583118,0.006556,0.000000
6.680000,1.144669,-33.494156,0.001173,0.000230,0.005845,5.091740,0.259386,0.058450,-33.494156,0.006938,0.000000
6.910000,1.215424,-33.538635,0.001199,0.000247,0.006261,5.406474,0.275419,0.062614,-33.538635,0.007328,0.000000
7.140000,1.254517,-33.538635,0.001203,0.000264,0.006695,5.580369,0.284278,0.066949,-33.538635,0.007710,0.000000
7.370000,1.304794,-33.583118,0.001203,0.000280,0.007111,5.804015,0.295671,0.071112,-33.583118,0.008091,0.000000
7.600000,1.302925,-33.627598,0.001233,0.000295,0.007501,5.795701,0.295247,0.075015,-33.627598,0.008473,0.000000
7.830000,1.341286,-33.538635,0.001233,0.000305,0.007744,5.966337,0.303940,0.077443,-33.538635,0.008854,0.000000
8.060000,1.342400,-33.538635,0.001281,0.000316,0.008031,5.971292,0.304192,0.080306,-33.538635,0.009245,0.000000
8.290000,1.485016,-33.538635,0.001272,0.000338,0.008594,6.605680,0.336509,0.085942,-33.538635,0.009626,0.000000
8.520000,1.506241,-33.583118,0.001285,0.000352,0.008950,6.700094,0.341319,0.089498,-33.583118,0.010008,0.000000
8.750000,1.466400,-33.672081,0.001306,0.000353,0.008958,6.522873,0.332291,0.089585,-33.672081,0.010389,0.000000
8.980000,1.669716,-33.583118,0.001324,0.000386,0.009800,7.427267,0.378363,0.097997,-33.583118,0.010771,0.000000
9.210000,1.652962,-33.583118,0.001315,0.000400,0.010155,7.352741,0.374566,0.101553,-33.583118,0.011161,0.000000
9.440001,1.715889,-33.627598,0.001362,0.000417,0.010598,7.632655,0.388826,0.105975,-33.627598,0.011543,0.000000
9.670000,1.690941,-33.672081,0.001367,0.000429,0.010892,7.521680,0.383173,0.108924,-33.672081,0.011924,0.000000
9.900001,1.746422,-33.672081,0.001380,0.000440,0.011178,7.768472,0.395745,0.111785,-33.672081,0.012306,0.000000
10.130000,1.884201,-33.716560,0.001384,0.000463,0.011768,8.381345,0.426966,0.117682,-33.716560,0.012696,0.000000
10.360001,1.902077,-33.672081,0.001414,0.000477,0.012107,8.460860,0.431017,0.121066,-33.672081,0.013078,0.000000
10.590000,1.877869,-33.627598,0.001436,0.000485,0.012323,8.353177,0.425531,0.123232,-33.627598,0.013459,0.000000
10.820001,1.998146,-33.716560,0.001440,0.000502,0.012757,8.888198,0.452786,0.127568,-33.716560,0.013841,0.000000
11.050000,1.902824,-33.716560,0.001444,0.000506,0.012852,8.464186,0.431186,0.128524,-33.716560,0.014222,0.000000
11.280001,2.098320,-33.672081,0.001496,0.000535,0.013589,9.333794,0.475486,0.135895,-33.672081,0.014613,0.000000
11.510000,2.121407,-33.672081,0.001492,0.000551,0.014006,9.436487,0.480718,0.140056,-33.672081,0.014994,0.000000
11.740001,2.137047,-33.627598,0.001496,0.000564,0.014318,9.506059,0.484262,0.143179,-33.627598,0.015376,0.000000
11.970000,2.252106,-33.761044,0.001526,0.000581,0.014769,10.017866,0.510334,0.147688,-33.761044,0.015757,0.000000
12.200001,2.321739,-33.716560,0.001535,0.000599,0.015211,10.327612,0.526114,0.152111,-33.716560,0.016139,0.000000
12.430000,2.347435,-33.672081,0.001535,0.000610,0.015497,10.441913,0.531936,0.154973,-33.672081,0.016529,0.000000
12.660001,2.276680,-33.716560,0.001574,0.000610,0.015497,10.127178,0.515903,0.154973,-33.716560,0.016911,0.000000
12.890000,2.216362,-33.716560,0.001565,0.000610,0.015497,9.858871,0.502235,0.154973,-33.716560,0.017292,0.000000
13.120001,2.177635,-33.716560,0.001565,0.000610,0.015497,9.686605,0.493459,0.154973,-33.716560,0.017674,0.000000
13.350000,2.419304,-33.850002,0.001608,0.000663,0.016841,10.761601,0.548222,0.168415,-33.850002,0.018056,0.000000
13.580001,2.592827,-33.805523,0.001638,0.000687,0.017457,11.533470,0.587543,0.174573,-33.805523,0.018446,0.000000
13.810000,2.646820,-33.716560,0.001638,0.000704,0.017882,11.773643,0.599778,0.178821,-33.716560,0.018827,0.000000
14.040001,2.783852,-33.805523,0.001677,0.000720,0.018298,12.383190,0.630830,0.182985,-33.805523,0.019209,0.000000
14.270000,2.763748,-33.805523,0.001686,0.000730,0.018550,12.293766,0.626274,0.185500,-33.805523,0.019591,0.000000
14.500001,2.748108,-33.850002,0.001677,0.000739,0.018775,12.224195,0.622730,0.187753,-33.850002,0.019972,0.000000
14.730000,2.949936,-33.761044,0.001725,0.000765,0.019426,13.121970,0.668465,0.194258,-33.761044,0.020363,0.000000
14.960001,3.037064,-33.761044,0.001720,0.000782,0.019860,13.509534,0.688208,0.198595,-33.761044,0.020744,0.000000
15.190001,3.049355,-33.805523,0.001755,0.000796,0.020206,13.564206,0.690994,0.202064,-33.805523,0.021126,0.000000
15.420001,3.013237,-33.850002,0.001755,0.000807,0.020501,13.403547,0.682809,0.205013,-33.850002,0.021507,0.000000
15.650001,3.180801,-33.805523,0.001781,0.000826,0.020978,14.148911,0.720780,0.209782,-33.805523,0.021889,0.000000
15.880001,3.277992,-33.805523,0.001781,0.000842,0.021394,14.581238,0.742804,0.213945,-33.805523,0.022279,0.000000
16.110001,3.239265,-33.850002,0.001807,0.000852,0.021646,14.408973,0.734028,0.216460,-33.850002,0.022661,0.000000
16.340000,3.257515,-33.761044,0.001819,0.000864,0.021950,14.490150,0.738163,0.219496,-33.761044,0.023042,0.000000
16.570002,3.345764,-33.850002,0.001828,0.000873,0.022184,14.882702,0.758161,0.221836,-33.850002,0.023424,0.000000
16.800001,3.605309,-33.850002,0.001824,0.000903,0.022929,16.037212,0.816975,0.229295,-33.850002,0.023805,0.000000
17.030001,3.553551,-33.850002,0.001871,0.000915,0.023250,15.806983,0.805246,0.232502,-33.850002,0.024196,0.000000
17.260000,3.542374,-33.894485,0.001871,0.000926,0.023519,15.757265,0.802713,0.235191,-33.894485,0.024577,0.000000
17.490002,3.608658,-33.805523,0.001876,0.000940,0.023875,16.052113,0.817734,0.238747,-33.805523,0.024959,0.000000
17.720001,3.772133,-33.805523,0.001910,0.000959,0.024360,16.779285,0.854778,0.243603,-33.805523,0.025340,0.000000
17.950001,3.791496,-33.938965,0.001927,0.000971,0.024655,16.865417,0.859165,0.246552,-33.938965,0.025731,0.000000
18.180000,3.874908,-33.938965,0.001957,0.000987,0.025080,17.236454,0.878067,0.250802,-33.938965,0.026112,0.000000
18.410002,3.861504,-33.894485,0.001944,0.000997,0.025332,17.176826,0.875029,0.253317,-33.894485,0.026494,0.000000
18.640001,4.050293,-33.850002,0.001975,0.001016,0.025809,18.016603,0.917809,0.258086,-33.850002,0.026875,0.000000
18.870001,4.100189,-33.894485,0.001975,0.001031,0.026199,18.238552,0.929116,0.261989,-33.894485,0.027257,0.000000
19.100000,4.118813,-33.938965,0.002009,0.001043,0.026494,18.321394,0.933336,0.264937,-33.938965,0.027647,0.000000
19.330002,4.165359,-33.938965,0.002018,0.001060,0.026936,18.528444,0.943884,0.269360,-33.938965,0.028029,0.000000
19.560001,4.273346,-33.894485,0.002031,0.001075,0.027309,19.008793,0.968354,0.273090,-33.894485,0.028410,0.000000
19.790001,4.433838,-33.894485,0.002039,0.001096,0.027829,19.722696,1.004722,0.278292,-33.894485,0.028792,0.000000
20.020000,4.409264,-33.983448,0.002082,0.001107,0.028124,19.613384,0.999153,0.281240,-33.983448,0.029173,0.000000
20.250002,4.372765,-33.938965,0.002057,0.001116,0.028350,19.451029,0.990883,0.283496,-33.938965,0.029564,0.000000
20.480001,4.595078,-34.027927,0.002082,0.001138,0.028896,20.439926,1.041260,0.288960,-34.027927,0.029945,0.000000
20.710001,4.812912,-33.938965,0.002117,0.001158,0.029425,21.408901,1.090621,0.294249,-33.938965,0.030327,0.000000
20.940001,4.751099,-33.983448,0.002117,0.001170,0.029711,21.133942,1.076614,0.297112,-33.983448,0.030709,0.000000
21.170000,4.747749,-33.938965,0.002160,0.001184,0.030075,21.119043,1.075855,0.300753,-33.938965,0.031090,0.000000
21.400002,4.827805,-33.983448,0.002169,0.001199,0.030466,21.475147,1.093996,0.304656,-33.983448,0.031480,0.000000
21.630001,4.839722,-34.027927,0.002177,0.001209,0.030717,21.528156,1.096697,0.307171,-34.027927,0.031862,0.000000
21.860001,5.049370,-34.027927,0.002195,0.001229,0.031220,22.460718,1.144204,0.312201,-34.027927,0.032244,0.000000
22.090000,5.046387,-33.983448,0.002182,0.001241,0.031532,22.447449,1.143528,0.315323,-33.983448,0.032625,0.000000
22.320002,5.139107,-33.983448,0.002225,0.001254,0.031862,22.859888,1.164538,0.318618,-33.983448,0.033007,0.000000
22.550001,5.269066,-34.027927,0.002233,0.001275,0.032382,23.437975,1.193987,0.323822,-34.027927,0.033397,0.000000
22.780001,5.476479,-34.072407,0.002268,0.001296,0.032911,24.360594,1.240988,0.329112,-34.072407,0.033778,0.000000
23.010000,5.395302,-34.072407,0.002268,0.001307,0.033197,23.999500,1.222593,0.331973,-34.072407,0.034160,0.000000
23.240002,5.457115,-34.027927,0.002302,0.001321,0.033553,24.274460,1.236600,0.335529,-34.027927,0.034542,0.000000
23.470001,5.523399,-34.027927,0.002307,0.001336,0.033935,24.569307,1.251620,0.339346,-34.027927,0.034923,0.000000
23.700001,5.710701,-34.116890,0.002320,0.001352,0.034342,25.402466,1.294063,0.343421,-34.116890,0.035313,0.000000
23.930000,5.778847,-34.116890,0.002341,0.001369,0.034776,25.705595,1.309505,0.347758,-34.116890,0.035695,0.000000
24.160002,5.656708,-34.072407,0.002337,0.001376,0.034940,25.162292,1.281828,0.349404,-34.072407,0.036077,0.000000
24.390001,5.912155,-34.072407,0.002358,0.001397,0.035478,26.298580,1.339713,0.354783,-34.072407,0.036458,0.000000
24.620001,5.987373,-34.072407,0.002389,0.001411,0.035842,26.633167,1.356758,0.358424,-34.072407,0.036840,0.000000
24.850000,6.052170,-34.027927,0.002419,0.001425,0.036198,26.921396,1.371441,0.361980,-34.027927,0.037230,0.000000
25.080002,6.116959,-34.161369,0.002427,0.001440,0.036579,27.209591,1.386123,0.365795,-34.161369,0.037612,0.000000
25.310001,6.198135,-34.072407,0.002423,0.001455,0.036961,27.570683,1.404518,0.369612,-34.072407,0.037993,0.000000
25.540001,6.251762,-34.072407,0.002432,0.001467,0.037265,27.809229,1.416670,0.372648,-34.072407,0.038375,0.000000
25.770000,6.475182,-34.072407,0.002462,0.001489,0.037811,28.803045,1.467297,0.378111,-34.072407,0.038756,0.000000
26.000002,6.422676,-34.161369,0.002462,0.001500,0.038089,28.569490,1.455399,0.380885,-34.161369,0.039147,0.000000
26.230001,6.519119,-34.161369,0.002492,0.001513,0.038435,28.998491,1.477254,0.384354,-34.161369,0.039528,0.000000
26.460001,6.790581,-34.161369,0.002518,0.001534,0.038973,30.206011,1.538768,0.389731,-34.161369,0.039910,0.000000
26.690001,6.774200,-34.161369,0.002544,0.001548,0.039329,30.133148,1.535056,0.393287,-34.161369,0.040291,0.000000
26.920002,6.817390,-34.161369,0.002548,0.001561,0.039650,30.325268,1.544843,0.396496,-34.161369,0.040682,0.000000
27.150002,6.881439,-34.161369,0.002535,0.001576,0.040031,30.610170,1.559356,0.400311,-34.161369,0.041063,0.000000
27.380001,6.973045,-34.250332,0.002578,0.001589,0.040369,31.017654,1.580115,0.403693,-34.250332,0.041445,0.000000
27.610001,7.169655,-34.161369,0.002574,0.001607,0.040820,31.892218,1.624667,0.408203,-34.161369,0.041826,0.000000
27.840002,7.312279,-34.161369,0.002596,0.001623,0.041228,32.526642,1.656986,0.412279,-34.161369,0.042208,0.000000
28.070002,7.209869,-34.205853,0.002600,0.001632,0.041445,32.071102,1.633780,0.414448,-34.205853,0.042598,0.000000
28.300001,7.470535,-34.161369,0.002626,0.001652,0.041956,33.230602,1.692847,0.419563,-34.161369,0.042980,0.000000
28.530001,7.445587,-34.205853,0.002643,0.001667,0.042338,33.119625,1.687194,0.423380,-34.205853,0.043361,0.000000
28.760002,7.555435,-34.205853,0.002660,0.001681,0.042702,33.608253,1.712086,0.427021,-34.205853,0.043743,0.000000
28.990002,7.644432,-34.205853,0.002665,0.001699,0.043144,34.004131,1.732253,0.431444,-34.205853,0.044124,0.000000
29.220001,7.652252,-34.161369,0.002682,0.001708,0.043379,34.038918,1.734025,0.433787,-34.161369,0.044515,0.000000
29.450001,7.873444,-34.250332,0.002712,0.001725,0.043804,35.022827,1.784148,0.438035,-34.250332,0.044896,0.000000
29.680002,8.047340,-34.250332,0.002725,0.001739,0.044177,35.796356,1.823553,0.441765,-34.250332,0.045278,0.000000
29.910002,8.033188,-34.250332,0.002699,0.001751,0.044480,35.733406,1.820346,0.444801,-34.250332,0.045659,0.000000
30.140001,8.251770,-34.250332,0.002729,0.001769,0.044922,36.705708,1.869878,0.449224,-34.250332,0.046041,0.000000
30.370001,8.354919,-34.250332,0.002781,0.001787,0.045399,37.164539,1.893252,0.453992,-34.250332,0.046431,0.000000
30.600002,8.452850,-34.205853,0.002785,0.001803,0.045798,37.600155,1.915443,0.457982,-34.205853,0.046813,0.000000
30.830002,8.523232,-34.294815,0.002802,0.001819,0.046197,37.913227,1.931392,0.461971,-34.294815,0.047194,0.000000
31.060001,8.547806,-34.294815,0.002785,0.001832,0.046544,38.022537,1.936960,0.465440,-34.294815,0.047576,0.000000
31.290001,8.567917,-34.250332,0.002811,0.001843,0.046813,38.112000,1.941518,0.468129,-34.250332,0.047958,0.000000
31.520002,8.874748,-34.294815,0.002841,0.001861,0.047281,39.476852,2.011047,0.472811,-34.294815,0.048348,0.000000
31.750002,9.014015,-34.250332,0.002850,0.001878,0.047689,40.096344,2.042605,0.476887,-34.250332,0.048729,0.000000
31.980001,8.983856,-34.339294,0.002871,0.001888,0.047958,39.962189,2.035771,0.479576,-34.339294,0.049111,0.000000
32.210003,9.092590,-34.339294,0.002889,0.001901,0.048287,40.445862,2.060410,0.482871,-34.339294,0.049493,0.000000
32.440002,9.377083,-34.250332,0.002884,0.001924,0.048868,41.711349,2.124877,0.488681,-34.250332,0.049874,0.000000
32.670002,9.464958,-34.339294,0.002910,0.001939,0.049250,42.102238,2.144790,0.492498,-34.339294,0.050264,0.000000
32.900002,9.480225,-34.339294,0.002932,0.001953,0.049605,42.170147,2.148250,0.496054,-34.339294,0.050646,0.000000
33.130001,9.574440,-34.339294,0.002953,0.001965,0.049917,42.589237,2.169599,0.499175,-34.339294,0.051028,0.000000
33.360001,9.841431,-34.383774,0.002945,0.001983,0.050377,43.776871,2.230100,0.503771,-34.383774,0.051409,0.000000
33.590000,10.063736,-34.383774,0.002984,0.002001,0.050828,44.765732,2.280475,0.508281,-34.383774,0.051791,0.000000
33.820004,9.957611,-34.428257,0.003005,0.002009,0.051028,44.293667,2.256427,0.510276,-34.428257,0.052181,0.000000
34.050003,9.616890,-34.383774,0.003005,0.002009,0.051019,42.778065,2.179219,0.510189,-34.383774,0.052563,0.000000
34.280003,9.374100,-34.428257,0.002988,0.002009,0.051028,41.698078,2.124201,0.510276,-34.428257,0.052944,0.000000
34.510002,9.187912,-34.383774,0.002992,0.002009,0.051028,40.869873,2.082011,0.510276,-34.383774,0.053326,0.000000
34.740002,11.362946,-34.383774,0.003053,0.002077,0.052745,50.544907,2.574880,0.527446,-34.383774,0.053707,0.000000
34.970001,10.861359,-34.383774,0.003061,0.002090,0.053091,48.313736,2.461219,0.530915,-34.383774,0.054098,0.000000
35.200001,10.854652,-34.383774,0.003065,0.002104,0.053447,48.283905,2.459699,0.534471,-34.383774,0.054479,0.000000
35.430000,11.080315,-34.428257,0.003104,0.002121,0.053881,49.287701,2.510835,0.538808,-34.428257,0.054861,0.000000
35.660000,10.779060,-34.472736,0.003096,0.002125,0.053967,47.947655,2.442570,0.539675,-34.472736,0.055242,0.000000
35.890003,10.475952,-34.428257,0.003113,0.002125,0.053976,46.599361,2.373885,0.539762,-34.428257,0.055632,0.000000
36.120003,11.917778,-34.383774,0.003160,0.002170,0.055129,53.012924,2.700607,0.551295,-34.383774,0.056014,0.000000
36.350002,11.813141,-34.472736,0.003169,0.002186,0.055537,52.547474,2.676896,0.555371,-34.472736,0.056396,0.000000
36.580002,11.716324,-34.472736,0.003169,0.002197,0.055806,52.116810,2.654957,0.558060,-34.472736,0.056777,0.000000
36.810001,11.793777,-34.472736,0.003178,0.002211,0.056170,52.461342,2.672508,0.561703,-34.472736,0.057159,0.000000
37.040001,12.034706,-34.428257,0.003199,0.002226,0.056552,53.533047,2.727103,0.565518,-34.428257,0.057549,0.000000
37.270000,12.336327,-34.428257,0.003247,0.002245,0.057011,54.874722,2.795452,0.570115,-34.428257,0.057931,0.000000
37.500000,12.347870,-34.517220,0.003247,0.002256,0.057298,54.926067,2.798067,0.572976,-34.517220,0.058312,0.000000
37.730003,12.401489,-34.561699,0.003234,0.002267,0.057584,55.164577,2.810218,0.575838,-34.561699,0.058694,0.000000
37.960003,12.582466,-34.517220,0.003251,0.002282,0.057957,55.969604,2.851228,0.579568,-34.517220,0.059075,0.000000
38.190002,13.073624,-34.517220,0.003272,0.002304,0.058520,58.154381,2.962525,0.585203,-34.517220,0.059466,0.000000
38.420002,13.037872,-34.517220,0.003311,0.002316,0.058824,57.995354,2.954424,0.588239,-34.517220,0.059847,0.000000
38.650002,13.120544,-34.472736,0.003298,0.002331,0.059214,58.363098,2.973158,0.592141,-34.472736,0.060229,0.000000
38.880001,13.196877,-34.472736,0.003307,0.002345,0.059570,58.702637,2.990455,0.595697,-34.472736,0.060610,0.000000
39.110001,13.488441,-34.561699,0.003328,0.002359,0.059925,59.999584,3.056525,0.599253,-34.561699,0.060992,0.000000
39.340000,13.535362,-34.517220,0.003333,0.002375,0.060324,60.208298,3.067157,0.603242,-34.517220,0.061382,0.000000
39.570004,13.825073,-34.517220,0.003346,0.002387,0.060636,61.496998,3.132807,0.606365,-34.517220,0.061764,0.000000
39.800003,14.017960,-34.517220,0.003385,0.002402,0.061018,62.355000,3.176515,0.610180,-34.517220,0.062145,0.000000
40.030003,14.188881,-34.561699,0.003380,0.002417,0.061400,63.115295,3.215246,0.613995,-34.561699,0.062527,0.000000
40.260002,14.611519,-34.561699,0.003397,0.002437,0.061911,64.995285,3.311017,0.619112,-34.561699,0.062909,0.000000
40.490002,14.626785,-34.561699,0.003415,0.002448,0.062171,65.063187,3.314477,0.621714,-34.561699,0.063299,0.000000
40.720001,14.862503,-34.606178,0.003441,0.002466,0.062640,66.111717,3.367891,0.626396,-34.606178,0.063680,0.000000
40.950001,14.948143,-34.606178,0.003471,0.002478,0.062935,66.492661,3.387298,0.629347,-34.606178,0.064062,0.000000
41.180000,15.470955,-34.606178,0.003458,0.002500,0.063507,68.818245,3.505768,0.635069,-34.606178,0.064444,0.000000
41.410004,15.314186,-34.606178,0.003462,0.002510,0.063758,68.120903,3.470244,0.637585,-34.606178,0.064825,0.000000
41.640003,15.313446,-34.650661,0.003488,0.002521,0.064036,68.117607,3.470077,0.640359,-34.650661,0.065215,0.000000
41.870003,15.878334,-34.606178,0.003497,0.002540,0.064504,70.630356,3.598082,0.645043,-34.606178,0.065597,0.000000
42.100002,16.304695,-34.561699,0.003540,0.002558,0.064981,72.526909,3.694697,0.649812,-34.561699,0.065978,0.000000
42.330002,16.347519,-34.695141,0.003535,0.002575,0.065415,72.717400,3.704401,0.654149,-34.695141,0.066360,0.000000
42.560001,16.522911,-34.650661,0.003566,0.002590,0.065779,73.497581,3.744145,0.657790,-34.650661,0.066742,0.000000
42.790001,16.545624,-34.606178,0.003561,0.002602,0.066091,73.598610,3.749292,0.660913,-34.606178,0.067132,0.000000
43.020000,16.669250,-34.650661,0.003561,0.002614,0.066404,74.148529,3.777306,0.664035,-34.650661,0.067513,0.000000
43.250004,17.198761,-34.606178,0.003587,0.002632,0.066846,76.503906,3.897295,0.668458,-34.606178,0.067895,0.000000
43.480003,17.275848,-34.650661,0.003600,0.002644,0.067167,76.846809,3.914763,0.671666,-34.650661,0.068277,0.000000
43.710003,17.673912,-34.695141,0.003643,0.002661,0.067583,78.617485,4.004966,0.675829,-34.695141,0.068658,0.000000
43.940002,17.345108,-34.650661,0.003635,0.002667,0.067748,77.154892,3.930458,0.677477,-34.650661,0.069049,0.000000
44.170002,18.436905,-34.650661,0.003648,0.002695,0.068459,82.011452,4.177862,0.684587,-34.650661,0.069430,0.000000
44.400002,18.375458,-34.650661,0.003648,0.002711,0.068849,81.738121,4.163939,0.688491,-34.650661,0.069812,0.000000
44.630001,18.507278,-34.650661,0.003695,0.002723,0.069170,82.324486,4.193809,0.691699,-34.650661,0.070193,0.000000
44.860001,18.783951,-34.739624,0.003678,0.002738,0.069543,83.555183,4.256504,0.695429,-34.739624,0.070584,0.000000
45.090004,19.168983,-34.695141,0.003717,0.002756,0.069994,85.267899,4.343753,0.699939,-34.695141,0.070965,0.000000
45.320004,19.570778,-34.650661,0.003717,0.002772,0.070401,87.055168,4.434802,0.704013,-34.650661,0.071347,0.000000
45.550003,19.339165,-34.695141,0.003734,0.002782,0.070662,86.024902,4.382317,0.706615,-34.695141,0.071728,0.000000
45.780003,20.028419,-34.650661,0.003773,0.002800,0.071130,89.090858,4.538505,0.711299,-34.650661,0.072110,0.000000
46.010002,20.225410,-34.739624,0.003760,0.002816,0.071529,89.967117,4.583144,0.715288,-34.739624,0.072500,0.000000
46.240002,20.267113,-34.739624,0.003777,0.002828,0.071832,90.152618,4.592593,0.718324,-34.739624,0.072882,0.000000
46.470001,20.727364,-34.695141,0.003786,0.002846,0.072283,92.199921,4.696888,0.722834,-34.695141,0.073263,0.000000
46.700001,20.843170,-34.739624,0.003794,0.002857,0.072569,92.715050,4.723130,0.725695,-34.739624,0.073645,0.000000
46.930004,21.381248,-34.784103,0.003811,0.002877,0.073064,95.108543,4.845060,0.730638,-34.784103,0.074026,0.000000
47.160004,21.607651,-34.784103,0.003842,0.002891,0.073428,96.115631,4.896364,0.734279,-34.784103,0.074417,0.000000
47.390003,21.539879,-34.784103,0.003846,0.002898,0.073619,95.814163,4.881006,0.736189,-34.784103,0.074798,0.000000
47.620003,22.038490,-34.784103,0.003837,0.002917,0.074087,98.032104,4.993993,0.740870,-34.784103,0.075180,0.000000
47.850002,22.706902,-34.828587,0.003872,0.002936,0.074581,101.005341,5.145458,0.745814,-34.828587,0.075561,0.000000
48.080002,22.710991,-34.784103,0.003893,0.002948,0.074876,101.023537,5.146384,0.748762,-34.784103,0.075943,0.000000
48.310001,22.986176,-34.784103,0.003915,0.002966,0.075327,102.247612,5.208742,0.753272,-34.784103,0.076333,0.000000
48.540001,23.342911,-34.828587,0.003936,0.002979,0.075666,103.834450,5.289579,0.756655,-34.828587,0.076715,0.000000
48.770000,23.328018,-34.784103,0.003928,0.002988,0.075891,103.768204,5.286204,0.758909,-34.784103,0.077096,0.000000
49.000004,24.025841,-34.828587,0.003941,0.003009,0.076429,106.872276,5.444334,0.764286,-34.828587,0.077478,0.000000
49.230003,24.270859,-34.828587,0.003971,0.003022,0.076750,107.962173,5.499856,0.767495,-34.828587,0.077859,0.000000
49.460003,24.493538,-34.873066,0.003984,0.003037,0.077148,108.952698,5.550315,0.771485,-34.873066,0.078250,0.000000
49.690002,24.940018,-34.828587,0.003988,0.003054,0.077582,110.938736,5.651489,0.775820,-34.828587,0.078631,0.000000
49.920002,25.248337,-34.828587,0.003997,0.003068,0.077929,112.310211,5.721355,0.779289,-34.828587,0.079013,0.000000
50.150002,25.577515,-34.784103,0.004018,0.003083,0.078310,113.774467,5.795948,0.783104,-34.784103,0.079395,0.000000
50.380001,26.050056,-34.873066,0.004031,0.003100,0.078744,115.876442,5.903027,0.787442,-34.873066,0.079776,0.000000
50.610001,26.018776,-34.917545,0.004040,0.003110,0.079004,115.737297,5.895939,0.790042,-34.917545,0.080166,0.000000
50.840004,26.420570,-34.917545,0.004018,0.003123,0.079334,117.524567,5.986987,0.793339,-34.917545,0.080548,0.000000
51.070004,26.988808,-34.828587,0.004092,0.003141,0.079793,120.052216,6.115751,0.797933,-34.828587,0.080930,0.000000
51.300003,27.023811,-34.873066,0.004074,0.003150,0.080010,120.207916,6.123683,0.800102,-34.873066,0.081311,0.000000
51.530003,27.716049,-34.828587,0.004079,0.003172,0.080574,123.287148,6.280547,0.805740,-34.828587,0.081693,0.000000
51.760002,28.288765,-34.917545,0.004100,0.003190,0.081034,125.834709,6.410326,0.810337,-34.917545,0.082083,0.000000
51.990002,28.737839,-34.917545,0.004113,0.003208,0.081484,127.832291,6.512087,0.814844,-34.917545,0.082465,0.000000
52.220001,29.002968,-34.962029,0.004130,0.003221,0.081823,129.011642,6.572166,0.818228,-34.962029,0.082846,0.000000
52.450001,29.145966,-34.917545,0.004135,0.003233,0.082118,129.647736,6.604570,0.821176,-34.917545,0.083228,0.000000
52.680004,29.493385,-34.917545,0.004148,0.003248,0.082490,131.193130,6.683297,0.824905,-34.917545,0.083609,0.000000
52.910004,30.043381,-34.917545,0.004174,0.003262,0.082855,133.639633,6.807928,0.828548,-34.917545,0.083999,0.000000
53.140003,30.421341,-34.962029,0.004195,0.003276,0.083219,135.320877,6.893575,0.832191,-34.962029,0.084381,0.000000
53.370003,30.895370,-34.917545,0.004191,0.003295,0.083687,137.429474,7.000991,0.836872,-34.917545,0.084763,0.000000
53.600002,30.764664,-34.962029,0.004199,0.003300,0.083809,136.848053,6.971373,0.838087,-34.962029,0.085144,0.000000
53.830002,32.010994,-34.917545,0.004217,0.003327,0.084511,142.392014,7.253795,0.845112,-34.917545,0.085534,0.000000
54.060001,32.340546,-35.006508,0.004230,0.003342,0.084893,143.857925,7.328472,0.848927,-35.006508,0.085916,0.000000
54.290001,32.464920,-35.006508,0.004238,0.003354,0.085196,144.411179,7.356656,0.851963,-35.006508,0.086298,0.000000
54.520004,32.632858,-34.962029,0.004255,0.003365,0.085465,145.158203,7.394711,0.854650,-34.962029,0.086679,0.000000
54.750004,33.618530,-34.962029,0.004264,0.003387,0.086037,149.542694,7.618068,0.860375,-34.962029,0.087061,0.000000
54.980003,34.104103,-35.050991,0.004299,0.003402,0.086419,151.702621,7.728100,0.864190,-35.050991,0.087451,0.000000
55.210003,33.929832,-35.006508,0.004294,0.003411,0.086636,150.927429,7.688610,0.866359,-35.006508,0.087833,0.000000
55.440002,33.790192,-35.050991,0.004307,0.003415,0.086731,150.306274,7.656967,0.867312,-35.050991,0.088214,0.000000
55.670002,35.816643,-35.006508,0.004316,0.003450,0.087642,159.320389,8.116167,0.876419,-35.006508,0.088596,0.000000
55.900002,35.879570,-35.006508,0.004359,0.003462,0.087937,159.600296,8.130426,0.879367,-35.006508,0.088977,0.000000
56.130001,36.062035,-35.006508,0.004337,0.003474,0.088240,160.411942,8.171774,0.882403,-35.006508,0.089368,0.000000
56.360004,36.609421,-35.050991,0.004363,0.003489,0.088613,162.846832,8.295814,0.886131,-35.050991,0.089749,0.000000
56.590004,37.069679,-35.050991,0.004368,0.003507,0.089073,164.894165,8.400110,0.890728,-35.050991,0.090131,0.000000
56.820004,37.828941,-35.006508,0.004372,0.003521,0.089437,168.271530,8.572161,0.894371,-35.006508,0.090512,0.000000
57.050003,37.879959,-35.006508,0.004398,0.003532,0.089714,168.498474,8.583722,0.897145,-35.006508,0.090894,0.000000
57.280003,38.474640,-35.050991,0.004428,0.003547,0.090096,171.143753,8.718478,0.900960,-35.050991,0.091284,0.000000
57.510002,38.254196,-35.095470,0.004424,0.003550,0.090174,170.163162,8.668525,0.901742,-35.095470,0.091666,0.000000
57.740002,40.540932,-35.095470,0.004432,0.003587,0.091111,180.335068,9.186707,0.911107,-35.095470,0.092047,0.000000
57.970001,40.445976,-35.095470,0.004445,0.003597,0.091362,179.912689,9.165190,0.913623,-35.095470,0.092429,0.000000
58.200005,40.925591,-35.095470,0.004454,0.003615,0.091822,182.046112,9.273871,0.918219,-35.095470,0.092811,0.000000
58.430004,41.360893,-35.050991,0.004449,0.003628,0.092143,183.982437,9.372512,0.921427,-35.050991,0.093201,0.000000
58.660004,42.068779,-35.139950,0.004484,0.003645,0.092576,187.131271,9.532922,0.925763,-35.139950,0.093582,0.000000
58.890003,42.353638,-35.095470,0.004488,0.003656,0.092854,188.398392,9.597472,0.928539,-35.095470,0.093964,0.000000
59.120003,42.733833,-35.139950,0.004475,0.003669,0.093183,190.089584,9.683625,0.931834,-35.139950,0.094346,0.000000
59.350002,42.310822,-35.095470,0.004501,0.003670,0.093209,188.207932,9.587770,0.932095,-35.095470,0.094727,0.000000
59.580002,44.657135,-35.139950,0.004544,0.003707,0.094146,198.644852,10.119452,0.941460,-35.139950,0.095117,0.000000
59.810001,44.971420,-35.095470,0.004540,0.003720,0.094493,200.042862,10.190670,0.944929,-35.095470,0.095499,0.000000
60.040005,45.296501,-35.095470,0.004553,0.003733,0.094822,201.488907,10.264334,0.948224,-35.095470,0.095880,0.000000
60.270004,45.576897,-35.139950,0.004562,0.003744,0.095100,202.736160,10.327872,0.951000,-35.139950,0.096262,0.000000
60.500004,46.203598,-35.095470,0.004575,0.003759,0.095482,205.523865,10.469886,0.954815,-35.095470,0.096644,0.000000
60.730003,46.229294,-35.139950,0.004596,0.003766,0.095664,205.638168,10.475707,0.956636,-35.139950,0.097034,0.000000
60.960003,47.453651,-35.139950,0.004605,0.003789,0.096245,211.084381,10.753151,0.962448,-35.139950,0.097415,0.000000
61.190002,48.028595,-35.139950,0.004592,0.003806,0.096678,213.641861,10.883435,0.966783,-35.139950,0.097797,0.000000
61.420002,48.720093,-35.184433,0.004613,0.003821,0.097043,216.717804,11.040132,0.970426,-35.184433,0.098179,0.000000
61.650002,49.514740,-35.139950,0.004622,0.003836,0.097424,220.252563,11.220201,0.974241,-35.139950,0.098569,0.000000
61.880001,49.766457,-35.139950,0.004648,0.003849,0.097754,221.372253,11.277241,0.977536,-35.139950,0.098950,0.000000
62.110004,50.613609,-35.228912,0.004648,0.003868,0.098239,225.140579,11.469208,0.982394,-35.228912,0.099332,0.000000
62.340004,51.111839,-35.228912,0.004665,0.003879,0.098517,227.356812,11.582108,0.985168,-35.228912,0.099714,0.000000
62.570004,52.371208,-35.228912,0.004669,0.003901,0.099081,232.958771,11.867485,0.990806,-35.228912,0.100095,0.000000
62.800003,52.608406,-35.184433,0.004678,0.003911,0.099341,234.013870,11.921235,0.993406,-35.184433,0.100485,0.000000
63.030003,53.140152,-35.139950,0.004704,0.003926,0.099714,236.379196,12.041731,0.997136,-35.139950,0.100867,0.000000
63.260002,53.772812,-35.184433,0.004708,0.003940,0.100078,239.193420,12.185094,1.000779,-35.184433,0.101249,0.000000
63.490002,54.833336,-35.273396,0.004712,0.003959,0.100546,243.910858,12.425411,1.005461,-35.273396,0.101630,0.000000
63.720001,55.539726,-35.228912,0.004730,0.003974,0.100928,247.053040,12.585483,1.009278,-35.228912,0.102012,0.000000
63.950005,56.116898,-35.273396,0.004743,0.003989,0.101327,249.620422,12.716270,1.013266,-35.273396,0.102402,0.000000
64.180000,56.611786,-35.228912,0.004743,0.004001,0.101630,251.821808,12.828414,1.016301,-35.228912,0.102784,0.000000
64.410004,57.372910,-35.228912,0.004760,0.004019,0.102081,255.207443,13.000887,1.020811,-35.228912,0.103165,0.000000
64.639999,58.163834,-35.273396,0.004769,0.004031,0.102393,258.725647,13.180113,1.023933,-35.273396,0.103547,0.000000
64.870003,58.759628,-35.362354,0.004786,0.004044,0.102723,261.375885,13.315123,1.027228,-35.362354,0.103928,0.000000
65.100006,59.778809,-35.228912,0.004777,0.004063,0.103209,265.909424,13.546072,1.032086,-35.228912,0.104319,0.000000
65.330002,60.657608,-35.273396,0.004794,0.004083,0.103703,269.818512,13.745211,1.037029,-35.273396,0.104700,0.000000
65.560005,61.574020,-35.273396,0.004807,0.004095,0.104006,273.894928,13.952872,1.040065,-35.273396,0.105082,0.000000
65.790001,62.388771,-35.317875,0.004842,0.004112,0.104449,277.519104,14.137498,1.044487,-35.317875,0.105463,0.000000
66.020004,62.906372,-35.317875,0.004838,0.004125,0.104778,279.821533,14.254788,1.047782,-35.317875,0.105845,0.000000
66.250000,63.549088,-35.317875,0.004833,0.004139,0.105142,282.680450,14.400430,1.051425,-35.317875,0.106235,0.000000
66.480003,64.536240,-35.317875,0.004885,0.004156,0.105559,287.071533,14.624121,1.055586,-35.317875,0.106617,0.000000
66.710007,65.405731,-35.273396,0.004859,0.004171,0.105940,290.939209,14.821150,1.059403,-35.273396,0.106998,0.000000
66.940002,65.879395,-35.362354,0.004872,0.004185,0.106304,293.046173,14.928484,1.063045,-35.362354,0.107380,0.000000
67.170006,66.910858,-35.406837,0.004889,0.004203,0.106755,297.634369,15.162217,1.067554,-35.406837,0.107761,0.000000
67.400002,66.808838,-35.317875,0.004889,0.004213,0.107007,297.180542,15.139099,1.070069,-35.317875,0.108152,0.000000
67.630005,67.194229,-35.317875,0.004907,0.004210,0.106946,298.894867,15.226430,1.069462,-35.317875,0.107172,0.000000
67.860001,66.631577,-35.362354,0.004911,0.004210,0.106938,296.392059,15.098930,1.069377,-35.362354,0.106946,0.000000
68.090004,66.144150,-35.406837,0.004919,0.004209,0.106920,294.223877,14.988479,1.069203,-35.406837,0.106946,0.000000
68.320000,65.724854,-35.406837,0.004919,0.004209,0.106912,292.358765,14.893464,1.069116,-35.406837,0.106946,0.000000
68.550003,65.370728,-35.406837,0.004919,0.004209,0.106903,290.783508,14.813218,1.069028,-35.406837,0.106946,0.000000
68.780006,65.059799,-35.362354,0.004911,0.004209,0.106903,289.400452,14.742761,1.069028,-35.362354,0.106946,0.000000
69.010002,64.784241,-35.362354,0.004941,0.004209,0.106903,288.174683,14.680319,1.069028,-35.362354,0.106946,0.000000
69.240005,64.518738,-35.362354,0.004958,0.004209,0.106903,286.993683,14.620155,1.069028,-35.362354,0.106946,0.000000
69.470001,64.295685,-35.406837,0.004932,0.004208,0.106894,286.001495,14.569611,1.068943,-35.406837,0.106946,0.000000
69.700005,64.091263,-35.406837,0.004928,0.004208,0.106894,285.092163,14.523288,1.068943,-35.406837,0.106946,0.000000
69.930000,63.914001,-35.406837,0.004950,0.004208,0.106894,284.303680,14.483119,1.068943,-35.406837,0.106946,0.000000
70.160004,63.731171,-35.362354,0.004937,0.004208,0.106894,283.490417,14.441689,1.068943,-35.362354,0.106946,0.000000
70.390007,63.559143,-35.495800,0.004941,0.004208,0.106894,282.725189,14.402708,1.068943,-35.495800,0.106946,0.000000
70.620003,63.427322,-35.451317,0.004937,0.004208,0.106894,282.138824,14.372836,1.068943,-35.451317,0.106946,0.000000
70.850006,63.276871,-35.406837,0.004941,0.004208,0.106894,281.469574,14.338743,1.068943,-35.406837,0.106946,0.000000
71.080002,63.142075,-35.451317,0.004932,0.004208,0.106894,280.869965,14.308198,1.068943,-35.451317,0.106946,0.000000
71.310005,63.019196,-35.451317,0.004945,0.004208,0.106894,280.323395,14.280354,1.068943,-35.451317,0.106946,0.000000
71.540001,62.887375,-35.451317,0.004941,0.004208,0.106894,279.737000,14.250484,1.068943,-35.451317,0.106946,0.000000
71.770004,62.778275,-35.495800,0.004932,0.004208,0.106894,279.251709,14.225760,1.068943,-35.495800,0.106946,0.000000
72.000000,62.684799,-35.451317,0.004924,0.004208,0.106894,278.835907,14.204578,1.068943,-35.451317,0.106946,0.000000
72.230003,62.575699,-35.451317,0.004937,0.004208,0.106886,278.350616,14.179855,1.068856,-35.451317,0.106946,0.000000
72.460007,62.471062,-35.451317,0.004937,0.004208,0.106886,277.885162,14.156145,1.068856,-35.451317,0.106946,0.000000
72.690002,62.371269,-35.495800,0.004941,0.004208,0.106886,277.441254,14.133532,1.068856,-35.495800,0.106946,0.000000
72.920006,62.293816,-35.540279,0.004932,0.004208,0.106886,277.096741,14.115980,1.068856,-35.540279,0.106946,0.000000
73.150002,62.205933,-35.584763,0.004958,0.004208,0.106886,276.705811,14.096066,1.068856,-35.584763,0.106946,0.000000
73.380005,62.116936,-35.584763,0.004950,0.004208,0.106886,276.309937,14.075899,1.068856,-35.584763,0.106946,0.000000
73.610001,62.035385,-35.495800,0.004937,0.004208,0.106886,275.947174,14.057419,1.068856,-35.495800,0.106946,0.000000
73.840004,61.960541,-35.540279,0.004954,0.004208,0.106886,275.614258,14.040460,1.068856,-35.540279,0.106946,0.000000
74.070007,61.883835,-35.495800,0.004941,0.004208,0.106886,275.273041,14.023078,1.068856,-35.495800,0.106946,0.000000
74.300003,61.816429,-35.629242,0.004945,0.004208,0.106886,274.973206,14.007803,1.068856,-35.629242,0.106946,0.000000
74.530006,61.746429,-35.540279,0.004932,0.004208,0.106886,274.661835,13.991940,1.068856,-35.540279,0.106946,0.000000
74.760002,61.687218,-35.540279,0.004954,0.004208,0.106886,274.398437,13.978523,1.068856,-35.540279,0.106946,0.000000
74.990005,61.612373,-35.629242,0.004945,0.004208,0.106886,274.065521,13.961563,1.068856,-35.629242,0.106946,0.000000
75.220001,61.558380,-35.584763,0.004954,0.004208,0.106886,273.825348,13.949328,1.068856,-35.584763,0.106946,0.000000
75.450005,61.490982,-35.584763,0.004954,0.004208,0.106886,273.525543,13.934056,1.068856,-35.584763,0.106946,0.000000
75.680000,61.431030,-35.584763,0.004963,0.004208,0.106886,273.258881,13.920470,1.068856,-35.584763,0.106946,0.000000
75.910004,61.381874,-35.584763,0.004937,0.004208,0.106886,273.040222,13.909331,1.068856,-35.584763,0.106946,0.000000
76.140007,61.311867,-35.584763,0.004980,0.004208,0.106886,272.728790,13.893467,1.068856,-35.584763,0.106946,0.000000
76.370003,61.264580,-35.629242,0.004967,0.004208,0.106886,272.518463,13.882751,1.068856,-35.629242,0.106946,0.000000
76.600006,61.218033,-35.629242,0.004941,0.004208,0.106886,272.311401,13.872205,1.068856,-35.629242,0.106946,0.000000
76.830002,61.161804,-35.629242,0.004950,0.004208,0.106886,272.061279,13.859463,1.068856,-35.629242,0.106946,0.000000
77.060005,61.095520,-35.584763,0.004941,0.004208,0.106886,271.766449,13.844443,1.068856,-35.584763,0.106946,0.000000
77.290001,61.054558,-35.629242,0.004967,0.004208,0.106886,271.584229,13.835160,1.068856,-35.629242,0.106946,0.000000
77.520004,61.013222,-35.673721,0.004954,0.004208,0.106886,271.400360,13.825794,1.068856,-35.673721,0.106946,0.000000
77.750000,60.962585,-35.673721,0.004954,0.004208,0.106886,271.175110,13.814320,1.068856,-35.673721,0.106946,0.000000
77.980003,60.920135,-35.718204,0.004958,0.004208,0.106886,270.986298,13.804700,1.068856,-35.718204,0.106946,0.000000
78.210007,60.862785,-35.629242,0.004958,0.004208,0.106886,270.731201,13.791704,1.068856,-35.629242,0.106946,0.000000
78.440002,60.822197,-35.629242,0.004954,0.004208,0.106886,270.550659,13.782507,1.068856,-35.629242,0.106946,0.000000
78.670006,60.784958,-35.673721,0.004971,0.004208,0.106886,270.385010,13.774068,1.068856,-35.673721,0.106946,0.000000
78.900002,60.763367,-35.718204,0.004950,0.004208,0.106886,270.288940,13.769176,1.068856,-35.718204,0.106946,0.000000
79.130005,60.709366,-35.718204,0.004958,0.004208,0.106886,270.048737,13.756939,1.068856,-35.718204,0.106946,0.000000
79.360001,60.661331,-35.673721,0.004954,0.004208,0.106886,269.835083,13.746054,1.068856,-35.673721,0.106946,0.000000
79.590004,60.617020,-35.718204,0.004967,0.004208,0.106886,269.637970,13.736013,1.068856,-35.718204,0.106946,0.000000
79.820007,60.589836,-35.762684,0.004958,0.004208,0.106886,269.517059,13.729854,1.068856,-35.762684,0.106946,0.000000
80.050003,60.548874,-35.762684,0.004958,0.004208,0.106886,269.334839,13.720571,1.068856,-35.762684,0.106946,0.000000
80.280006,60.507919,-35.718204,0.004958,0.004208,0.106886,269.152679,13.711290,1.068856,-35.718204,0.106946,0.000000
80.510002,60.468819,-35.673721,0.004963,0.004208,0.106886,268.978729,13.702430,1.068856,-35.673721,0.106946,0.000000
80.740005,60.435303,-35.673721,0.004967,0.004208,0.106877,268.829651,13.694836,1.068769,-35.673721,0.106946,0.000000
80.970001,60.395462,-35.762684,0.004958,0.004208,0.106877,268.652435,13.685807,1.068769,-35.762684,0.106946,0.000000
81.200005,60.370140,-35.762684,0.004954,0.004208,0.106877,268.539795,13.680069,1.068769,-35.762684,0.106946,0.000000
81.430000,60.320984,-35.718204,0.004954,0.004208,0.106877,268.321136,13.668930,1.068769,-35.718204,0.106946,0.000000
81.660004,60.294174,-35.673721,0.004967,0.004208,0.106877,268.201874,13.662855,1.068769,-35.673721,0.106946,0.000000
81.890007,60.265129,-35.762684,0.004971,0.004208,0.106877,268.072693,13.656274,1.068769,-35.762684,0.106946,0.000000
82.120003,60.237946,-35.718204,0.004950,0.004208,0.106877,267.951752,13.650113,1.068769,-35.718204,0.106946,0.000000
82.350006,60.202568,-35.807167,0.004945,0.004208,0.106877,267.794403,13.642097,1.068769,-35.807167,0.106946,0.000000
82.580002,60.170174,-35.762684,0.004954,0.004208,0.106877,267.650299,13.634756,1.068769,-35.762684,0.106946,0.000000
82.810005,60.140755,-35.762684,0.004950,0.004208,0.106877,267.519440,13.628090,1.068769,-35.762684,0.106946,0.000000
83.040001,60.112831,-35.762684,0.004963,0.004208,0.106877,267.395233,13.621762,1.068769,-35.762684,0.106946,0.000000
83.270004,60.079689,-35.807167,0.004975,0.004208,0.106877,267.247803,13.614252,1.068769,-35.807167,0.106946,0.000000
83.500008,60.036491,-35.851646,0.004958,0.004208,0.106877,267.055664,13.604464,1.068769,-35.851646,0.106946,0.000000
83.730003,60.015640,-35.807167,0.004963,0.004208,0.106877,266.962891,13.599739,1.068769,-35.807167,0.106946,0.000000
83.960007,59.985481,-35.807167,0.004932,0.004208,0.106877,266.828735,13.592904,1.068769,-35.807167,0.106946,0.000000
84.190002,59.957924,-35.807167,0.004950,0.004208,0.106877,266.706177,13.586659,1.068769,-35.807167,0.106946,0.000000
84.420006,59.929993,-35.851646,0.004963,0.004208,0.106877,266.581909,13.580330,1.068769,-35.851646,0.106946,0.000000
84.650002,59.901321,-35.851646,0.004954,0.004208,0.106877,266.454376,13.573833,1.068769,-35.851646,0.106946,0.000000
84.880005,59.873024,-35.896126,0.004984,0.004208,0.106877,266.328522,13.567422,1.068769,-35.896126,0.106946,0.000000
85.110001,59.864830,-35.851646,0.004958,0.004208,0.106877,266.292053,13.565564,1.068769,-35.851646,0.106946,0.000000
85.340004,59.832436,-35.851646,0.004963,0.004208,0.106877,266.147980,13.558224,1.068769,-35.851646,0.106946,0.000000
85.570007,59.787750,-35.851646,0.004980,0.004208,0.106877,265.949188,13.548098,1.068769,-35.851646,0.106946,0.000000
85.800003,59.781044,-35.940609,0.004932,0.004208,0.106877,265.919373,13.546578,1.068769,-35.940609,0.106946,0.000000
86.030006,59.755348,-35.896126,0.004963,0.004208,0.106877,265.805054,13.540755,1.068769,-35.896126,0.106946,0.000000
86.260002,59.724442,-35.851646,0.004988,0.004208,0.106877,265.667572,13.533751,1.068769,-35.851646,0.106946,0.000000
86.490005,59.691307,-35.896126,0.004975,0.004208,0.106877,265.520203,13.526243,1.068769,-35.896126,0.106946,0.000000
86.720001,59.683487,-35.940609,0.004967,0.004208,0.106877,265.485413,13.524471,1.068769,-35.940609,0.106946,0.000000
86.950005,59.657417,-35.940609,0.004958,0.004208,0.106877,265.369446,13.518564,1.068769,-35.940609,0.106946,0.000000
87.180008,59.626137,-35.940609,0.004932,0.004208,0.106877,265.230316,13.511476,1.068769,-35.940609,0.106946,0.000000
87.410004,59.606773,-35.940609,0.004971,0.004208,0.106877,265.144165,13.507089,1.068769,-35.940609,0.106946,0.000000
87.640007,59.586670,-35.940609,0.004963,0.004208,0.106877,265.054749,13.502533,1.068769,-35.940609,0.106946,0.000000
87.870003,59.566933,-35.851646,0.004980,0.004208,0.106877,264.966949,13.498059,1.068769,-35.851646,0.106946,0.000000
88.100006,59.525223,-35.940609,0.004958,0.004208,0.106877,264.781403,13.488608,1.068769,-35.940609,0.106946,0.000000
88.330002,59.515541,-35.985088,0.004958,0.004208,0.106877,264.738342,13.486414,1.068769,-35.985088,0.106946,0.000000
88.560005,59.494316,-35.896126,0.004971,0.004208,0.106877,264.643921,13.481606,1.068769,-35.896126,0.106946,0.000000
88.790001,59.473839,-35.985088,0.004984,0.004208,0.106877,264.552856,13.476964,1.068769,-35.985088,0.106946,0.000000
89.020004,59.447029,-35.940609,0.004958,0.004208,0.106877,264.433594,13.470890,1.068769,-35.940609,0.106946,0.000000
89.250008,59.423195,-36.029572,0.004967,0.004208,0.106877,264.327576,13.465488,1.068769,-36.029572,0.106946,0.000000
89.480003,59.409042,-35.985088,0.004988,0.004208,0.106877,264.264618,13.462282,1.068769,-35.985088,0.106946,0.000000
89.710007,59.381859,-35.940609,0.004954,0.004208,0.106877,264.143707,13.456121,1.068769,-35.940609,0.106946,0.000000
89.940002,59.356911,-35.940609,0.004971,0.004208,0.106877,264.032715,13.450468,1.068769,-35.940609,0.106946,0.000000
90.170006,59.334946,-35.940609,0.004971,0.004208,0.106877,263.935028,13.445491,1.068769,-35.940609,0.106946,0.000000
90.400002,59.330475,-36.074051,0.004963,0.004208,0.106877,263.915131,13.444478,1.068769,-36.074051,0.106946,0.000000
90.630005,59.300682,-36.029572,0.004958,0.004208,0.106877,263.782623,13.437726,1.068769,-36.029572,0.106946,0.000000
90.860001,59.281319,-36.029572,0.004975,0.004208,0.106877,263.696472,13.433339,1.068769,-36.029572,0.106946,0.000000
91.090004,59.272011,-35.985088,0.004984,0.004208,0.106877,263.655060,13.431230,1.068769,-35.985088,0.106946,0.000000
91.320007,59.249298,-36.029572,0.004967,0.004208,0.106877,263.554047,13.426084,1.068769,-36.029572,0.106946,0.000000
91.550003,59.231422,-36.029572,0.004945,0.004208,0.106877,263.474518,13.422032,1.068769,-36.029572,0.106946,0.000000
91.780006,59.210197,-36.074051,0.004975,0.004208,0.106877,263.380127,13.417223,1.068769,-36.074051,0.106946,0.000000
92.010002,59.183388,-36.029572,0.004967,0.004208,0.106877,263.260864,13.411147,1.068769,-36.029572,0.106946,0.000000
92.240005,59.171844,-36.074051,0.004984,0.004208,0.106877,263.209503,13.408532,1.068769,-36.074051,0.106946,0.000000
92.470001,59.148010,-36.118534,0.004997,0.004208,0.106877,263.103485,13.403131,1.068769,-36.118534,0.106946,0.000000
92.700005,59.140190,-36.118534,0.004975,0.004208,0.106877,263.068695,13.401359,1.068769,-36.118534,0.106946,0.000000
92.930008,59.108543,-36.074051,0.004958,0.004208,0.106877,262.927917,13.394187,1.068769,-36.074051,0.106946,0.000000
93.160004,59.099602,-36.118534,0.004971,0.004208,0.106877,262.888153,13.392161,1.068769,-36.118534,0.106946,0.000000
93.390007,59.077637,-36.074051,0.004954,0.004208,0.106877,262.790466,13.387184,1.068769,-36.074051,0.106946,0.000000
93.620003,59.064598,-36.163013,0.004980,0.004208,0.106877,262.732452,13.384229,1.068769,-36.163013,0.106946,0.000000
93.850006,59.043373,-36.163013,0.004971,0.004208,0.106877,262.638031,13.379419,1.068769,-36.163013,0.106946,0.000000
94.080002,59.022896,-36.074051,0.004958,0.004208,0.106877,262.546967,13.374780,1.068769,-36.074051,0.106946,0.000000
94.310005,59.006508,-36.163013,0.004980,0.004208,0.106877,262.474060,13.371065,1.068769,-36.163013,0.106946,0.000000
94.540001,58.993103,-36.029572,0.004971,0.004208,0.106877,262.414429,13.368028,1.068769,-36.029572,0.106946,0.000000
94.770004,58.976349,-36.163013,0.004967,0.004208,0.106877,262.339905,13.364232,1.068769,-36.163013,0.106946,0.000000
95.000008,58.955498,-36.163013,0.004954,0.004208,0.106877,262.247162,13.359507,1.068769,-36.163013,0.106946,0.000000
95.230003,58.942833,-36.163013,0.004971,0.004208,0.106877,262.190826,13.356637,1.068769,-36.163013,0.106946,0.000000
95.460007,58.926453,-36.163013,0.004967,0.004208,0.106877,262.117950,13.352925,1.068769,-36.163013,0.106946,0.000000
95.690002,58.902245,-36.118534,0.004988,0.004208,0.106877,262.010284,13.347440,1.068769,-36.118534,0.106946,0.000000
95.920006,58.894424,-36.163013,0.004984,0.004208,0.106877,261.975494,13.345668,1.068769,-36.163013,0.106946,0.000000
96.150002,58.886604,-36.207493,0.004980,0.004208,0.106877,261.940704,13.343896,1.068769,-36.207493,0.106946,0.000000
96.380005,58.865753,-36.163013,0.004975,0.004208,0.106877,261.847961,13.339170,1.068769,-36.163013,0.106946,0.000000
96.610008,58.844528,-36.118534,0.004963,0.004208,0.106877,261.753540,13.334360,1.068769,-36.118534,0.106946,0.000000
96.840004,58.828888,-36.251976,0.004980,0.004208,0.106877,261.683960,13.330816,1.068769,-36.251976,0.106946,0.000000
97.070007,58.811760,-36.251976,0.004988,0.004208,0.106877,261.607788,13.326935,1.068769,-36.251976,0.106946,0.000000
97.300003,58.801704,-36.207493,0.004980,0.004208,0.106877,261.563049,13.324656,1.068769,-36.207493,0.106946,0.000000
97.530006,58.773033,-36.207493,0.004963,0.004208,0.106877,261.435516,13.318160,1.068769,-36.207493,0.106946,0.000000
97.760002,58.778244,-36.207493,0.004967,0.004208,0.106877,261.458679,13.319341,1.068769,-36.207493,0.106946,0.000000
97.900002,58.759628,-36.340939,0.004971,0.004208,0.106877,261.375885,13.315123,1.068769,-36.340939,0.106946,0.000000