File: Data/Symmetrical membranes compression/Durapore PVDF 5um test 1_10272023_145107.csv
Time (sec),S:Load (lbs),S:HL1 (DIM),S:LVDT (in),S:Position (in),Ch:Position (mm),Ch:Load (N),Ch:Stress (MPa),Ch:Strain (mm/mm),Ch:HL1 (DIM),Set Point (),Cycles ()
0.010000,0.002983,-1213.573730,0.000004,-0.000000,-0.000000,0.013269,0.000676,-0.000000,-1213.573730,0.000217,0.000000
0.260000,0.014526,-1213.529297,-0.000034,-0.000000,-0.000000,0.064617,0.003292,-0.000000,-1213.529297,0.000217,0.000000
0.510000,-0.024200,-1213.484863,-0.000039,0.000075,0.001899,-0.107649,-0.005484,0.018992,-1213.484863,0.002576,0.000000
0.760000,-0.021965,-1213.529297,0.000086,0.000220,0.005576,-0.097705,-0.004977,0.055763,-1213.529297,0.006756,0.000000
1.010000,-0.036118,-1213.529297,0.000246,0.000384,0.009756,-0.160659,-0.008184,0.097563,-1213.529297,0.010918,0.000000
1.260000,-0.062180,-1213.529297,0.000431,0.000545,0.013841,-0.276589,-0.014090,0.138409,-1213.529297,0.015081,0.000000
1.510000,-0.049896,-1213.573730,0.000535,0.000708,0.017986,-0.221950,-0.011307,0.179863,-1213.573730,0.019244,0.000000
1.760000,0.007820,-1213.484863,0.000720,0.000870,0.022106,0.034786,0.001772,0.221056,-1213.484863,0.023406,0.000000
2.010000,-0.005211,-1213.440308,0.000884,0.001045,0.026537,-0.023179,-0.001181,0.265371,-1213.440308,0.027569,0.000000
2.260000,-0.038353,-1213.484863,0.001108,0.001202,0.030535,-0.170603,-0.008691,0.305350,-1213.484863,0.031732,0.000000
2.510000,-0.009682,-1213.573730,0.001237,0.001365,0.034663,-0.043066,-0.002194,0.346630,-1213.573730,0.035912,0.000000
2.760000,-0.021965,-1213.529297,0.001410,0.001529,0.038834,-0.097705,-0.004977,0.388344,-1213.529297,0.040074,0.000000
3.010000,-0.039841,-1213.529297,0.001630,0.001694,0.043032,-0.177220,-0.009028,0.430317,-1213.529297,0.044237,0.000000
3.260000,0.017136,-1213.529297,0.001742,0.001864,0.047351,0.076223,0.003883,0.473505,-1213.529297,0.048400,0.000000
3.510000,0.099052,-1213.573730,0.001962,0.002023,0.051374,0.440607,0.022446,0.513744,-1213.573730,0.052563,0.000000
3.760000,0.274811,-1213.529297,0.002164,0.002187,0.055537,1.222420,0.062273,0.555371,-1213.529297,0.056725,0.000000
4.010000,0.484459,-1213.573730,0.002276,0.002348,0.059630,2.154981,0.109780,0.596304,-1213.573730,0.060888,0.000000
4.260000,0.628571,-1213.573730,0.002419,-0.000000,-0.000000,2.796021,0.142436,-0.000000,-1213.573730,0.000156,0.000000
4.510000,0.571594,-1213.573730,0.002367,-0.000000,-0.000009,2.542578,0.129525,-0.000087,-1213.573730,0.000156,0.000000
4.760000,0.531380,-1213.529297,0.002419,-0.000001,-0.000017,2.363695,0.120412,-0.000173,-1213.529297,0.000304,0.000000
5.010000,0.556702,-1213.573730,0.002432,-0.000000,-0.000009,2.476333,0.126150,-0.000087,-1213.573730,0.000720,0.000000
5.260000,0.552979,-1213.573730,0.002419,-0.000000,-0.000000,2.459771,0.125307,-0.000000,-1213.573730,0.001136,0.000000
5.510000,0.542923,-1213.573730,0.002371,0.000001,0.000017,2.415042,0.123028,0.000174,-1213.573730,0.001552,0.000000
5.760000,0.643089,-1213.573730,0.002402,0.000040,0.001015,2.860604,0.145726,0.010147,-1213.573730,0.001969,0.000000
6.010000,0.688896,-1213.662720,0.002419,0.000055,0.001388,3.064363,0.156106,0.013876,-1213.662720,0.002385,0.000000
6.260000,0.751823,-1213.573730,0.002475,0.000073,0.001856,3.344278,0.170366,0.018559,-1213.573730,0.002810,0.000000
6.510000,0.767464,-1213.573730,0.002462,0.000084,0.002125,3.413849,0.173910,0.021247,-1213.573730,0.003226,0.000000
6.760000,0.850876,-1213.573730,0.002475,0.000105,0.002662,3.784885,0.192811,0.026624,-1213.573730,0.003642,0.000000
7.010000,0.881035,-1213.529297,0.002471,0.000126,0.003191,3.919039,0.199645,0.031914,-1213.529297,0.004059,0.000000
7.260000,0.906731,-1213.573730,0.002544,0.000139,0.003538,4.033340,0.205468,0.035383,-1213.573730,0.004475,0.000000
7.510000,0.921249,-1213.573730,0.002552,0.000157,0.003989,4.097922,0.208758,0.039893,-1213.573730,0.004891,0.000000
7.760000,0.928703,-1213.573730,0.002501,0.000169,0.004301,4.131079,0.210447,0.043014,-1213.573730,0.005307,0.000000
8.010000,1.026260,-1213.573730,0.002574,0.000188,0.004770,4.565034,0.232554,0.047698,-1213.573730,0.005724,0.000000
8.260000,1.023659,-1213.618286,0.002608,0.000204,0.005186,4.553462,0.231964,0.051860,-1213.618286,0.006140,0.000000
8.510000,1.050468,-1213.618286,0.002557,0.000212,0.005377,4.672717,0.238040,0.053768,-1213.618286,0.006556,0.000000
8.760000,1.105949,-1213.618286,0.002634,0.000231,0.005862,4.919508,0.250612,0.058625,-1213.618286,0.006973,0.000000
9.010000,1.168137,-1213.573730,0.002634,0.000254,0.006461,5.196131,0.264704,0.064609,-1213.573730,0.007389,0.000000
9.260000,1.214684,-1213.618286,0.002617,0.000270,0.006851,5.403182,0.275251,0.068511,-1213.618286,0.007805,0.000000
9.510000,1.222878,-1213.618286,0.002669,0.000286,0.007276,5.439631,0.277108,0.072760,-1213.618286,0.008221,0.000000
9.760000,1.291763,-1213.618286,0.002703,0.000307,0.007788,5.746050,0.292718,0.077877,-1213.618286,0.008638,0.000000
10.010000,1.301819,-1213.618286,0.002729,0.000318,0.008065,5.790780,0.294996,0.080652,-1213.618286,0.009054,0.000000
10.260000,1.338684,-1213.573730,0.002742,0.000333,0.008447,5.954764,0.303350,0.084468,-1213.573730,0.009470,0.000000
10.510000,1.401237,-1213.573730,0.002725,0.000349,0.008863,6.233016,0.317525,0.088631,-1213.573730,0.009886,0.000000
10.760000,1.455978,-1213.662720,0.002764,0.000370,0.009392,6.476515,0.329929,0.093921,-1213.662720,0.010303,0.000000
11.010000,1.454117,-1213.618286,0.002755,0.000382,0.009696,6.468235,0.329508,0.096956,-1213.618286,0.010719,0.000000
11.260000,1.488373,-1213.618286,0.002772,0.000399,0.010147,6.620613,0.337270,0.101465,-1213.618286,0.011144,0.000000
11.510000,1.514442,-1213.573730,0.002802,0.000415,0.010537,6.736577,0.343178,0.105368,-1213.573730,0.011560,0.000000
11.760000,1.611259,-1213.618286,0.002820,0.000433,0.011005,7.167240,0.365117,0.110051,-1213.618286,0.011976,0.000000
12.010000,1.614983,-1213.573730,0.002846,0.000449,0.011395,7.183801,0.365960,0.113954,-1213.573730,0.012393,0.000000
12.260000,1.652222,-1213.662720,0.002850,0.000460,0.011682,7.349449,0.374399,0.116816,-1213.662720,0.012809,0.000000
12.510000,1.733772,-1213.573730,0.002854,0.000478,0.012141,7.712204,0.392878,0.121412,-1213.573730,0.013225,0.000000
12.760000,1.764305,-1213.618286,0.002897,0.000497,0.012635,7.848021,0.399797,0.126355,-1213.618286,0.013641,0.000000
13.010000,1.815323,-1213.573730,0.002889,0.000514,0.013060,8.074960,0.411358,0.130604,-1213.573730,0.014058,0.000000
13.260000,1.853676,-1213.662720,0.002889,0.000532,0.013520,8.245562,0.420049,0.135201,-1213.662720,0.014474,0.000000
13.510000,1.849953,-1213.618286,0.002923,0.000545,0.013841,8.229001,0.419205,0.138409,-1213.618286,0.014890,0.000000
13.760000,1.918839,-1213.618286,0.002940,0.000561,0.014257,8.535420,0.434815,0.142572,-1213.618286,0.015307,0.000000
14.010000,1.940811,-1213.573730,0.002992,0.000570,0.014465,8.633160,0.439794,0.144653,-1213.573730,0.015723,0.000000
14.260000,2.039116,-1213.618286,0.002997,0.000591,0.015012,9.070440,0.462070,0.150117,-1213.618286,0.016139,0.000000
14.510000,2.122528,-1213.618286,0.002962,0.000612,0.015541,9.441477,0.480972,0.155407,-1213.618286,0.016555,0.000000
14.760000,2.176147,-1213.662720,0.002992,0.000629,0.015983,9.679987,0.493122,0.159830,-1213.662720,0.016972,0.000000
15.010001,2.189552,-1213.662720,0.003005,0.000643,0.016339,9.739615,0.496160,0.163385,-1213.662720,0.017388,0.000000
15.260001,2.221947,-1213.662720,0.003083,0.000661,0.016781,9.883713,0.503500,0.167809,-1213.662720,0.017804,0.000000
15.510001,2.258072,-1213.662720,0.003074,0.000674,0.017128,10.044406,0.511686,0.171277,-1213.662720,0.018220,0.000000
15.760001,2.398453,-1213.662720,0.003113,0.000697,0.017709,10.668851,0.543497,0.177088,-1213.662720,0.018637,0.000000
16.010000,2.437553,-1213.618286,0.003104,0.000713,0.018108,10.842779,0.552357,0.181077,-1213.618286,0.019053,0.000000
16.260000,2.470322,-1213.618286,0.003126,0.000728,0.018481,10.988540,0.559783,0.184806,-1213.618286,0.019469,0.000000
16.510000,2.471809,-1213.662720,0.003156,0.000740,0.018793,10.995157,0.560120,0.187928,-1213.662720,0.019894,0.000000
16.760000,2.580544,-1213.618286,0.003126,0.000757,0.019235,11.478831,0.584760,0.192351,-1213.618286,0.020310,0.000000
17.010000,2.657257,-1213.618286,0.003212,0.000777,0.019747,11.820070,0.602143,0.197467,-1213.618286,0.020727,0.000000
17.260000,2.676620,-1213.662720,0.003152,0.000795,0.020189,11.906202,0.606531,0.201891,-1213.662720,0.021143,0.000000
17.510000,2.759659,-1213.618286,0.003234,0.000811,0.020597,12.275576,0.625348,0.205966,-1213.618286,0.021559,0.000000
17.760000,2.892967,-1213.662720,0.003251,0.000833,0.021160,12.868561,0.655556,0.211603,-1213.662720,0.021976,0.000000
18.010000,2.866898,-1213.662720,0.003216,0.000845,0.021464,12.752598,0.649648,0.214639,-1213.662720,0.022392,0.000000
18.260000,2.907486,-1213.707275,0.003234,0.000860,0.021837,12.933144,0.658846,0.218368,-1213.707275,0.022808,0.000000
18.510000,3.054573,-1213.573730,0.003272,0.000883,0.022435,13.587420,0.692176,0.224352,-1213.573730,0.023224,0.000000
18.760000,3.071701,-1213.707275,0.003285,0.000898,0.022808,13.663609,0.696057,0.228081,-1213.707275,0.023641,0.000000
19.010000,3.048248,-1213.662720,0.003307,0.000909,0.023077,13.559285,0.690743,0.230769,-1213.662720,0.024057,0.000000
19.260000,3.166290,-1213.618286,0.003307,0.000928,0.023571,14.084363,0.717492,0.235712,-1213.618286,0.024473,0.000000
19.510000,3.223633,-1213.662720,0.003294,0.000943,0.023961,14.339435,0.730486,0.239615,-1213.662720,0.024889,0.000000
19.760000,3.260124,-1213.662720,0.003397,0.000957,0.024308,14.501757,0.738755,0.243083,-1213.662720,0.025306,0.000000
20.010000,3.318588,-1213.618286,0.003393,0.000971,0.024664,14.761818,0.752003,0.246639,-1213.618286,0.025722,0.000000
20.260000,3.464928,-1213.618286,0.003376,0.000991,0.025176,15.412768,0.785164,0.251756,-1213.618286,0.026138,0.000000
20.510000,3.309647,-1213.618286,0.003397,0.000992,0.025202,14.722043,0.749977,0.252016,-1213.618286,0.026554,0.000000
20.760000,3.581108,-1213.618286,0.003454,0.001025,0.026043,15.929564,0.811491,0.260428,-1213.618286,0.026971,0.000000
21.010000,3.556160,-1213.618286,0.003428,0.001040,0.026416,15.818589,0.805837,0.264157,-1213.618286,0.027387,0.000000
21.260000,3.562119,-1213.662720,0.003462,0.001053,0.026754,15.845095,0.807188,0.267540,-1213.662720,0.027803,0.000000
21.510000,3.697662,-1213.618286,0.003454,0.001069,0.027162,16.448023,0.837902,0.271615,-1213.618286,0.028228,0.000000
21.760000,3.699524,-1213.618286,0.003510,0.001081,0.027465,16.456305,0.838324,0.274650,-1213.618286,0.028644,0.000000
22.010000,3.868584,-1213.618286,0.003531,0.001101,0.027968,17.208319,0.876634,0.279681,-1213.618286,0.029061,0.000000
22.260000,3.943428,-1213.662720,0.003535,0.001119,0.028410,17.541245,0.893594,0.284103,-1213.662720,0.029477,0.000000
22.510000,3.989975,-1213.707275,0.003488,0.001137,0.028887,17.748295,0.904141,0.288873,-1213.707275,0.029893,0.000000
22.760000,4.067055,-1213.662720,0.003518,0.001152,0.029269,18.091164,0.921608,0.292689,-1213.662720,0.030310,0.000000
23.010000,4.083443,-1213.662720,0.003570,0.001168,0.029676,18.164061,0.925321,0.296765,-1213.662720,0.030726,0.000000
23.260000,4.141159,-1213.662720,0.003617,0.001183,0.030058,18.420795,0.938400,0.300581,-1213.662720,0.031142,0.000000
23.510000,4.304626,-1213.662720,0.003583,0.001203,0.030552,19.147934,0.975442,0.305524,-1213.662720,0.031558,0.000000
23.760000,4.322128,-1213.573730,0.003635,0.001217,0.030908,19.225786,0.979408,0.309079,-1213.573730,0.031975,0.000000
24.010000,4.434586,-1213.618286,0.003626,0.001235,0.031359,19.726023,1.004892,0.313589,-1213.618286,0.032391,0.000000
24.260000,4.560074,-1213.662720,0.003622,0.001253,0.031827,20.284222,1.033327,0.318272,-1213.662720,0.032807,0.000000
24.510000,4.567894,-1213.662720,0.003678,0.001267,0.032183,20.319008,1.035100,0.321828,-1213.662720,0.033223,0.000000
24.760000,4.628967,-1213.662720,0.003669,0.001284,0.032625,20.590675,1.048939,0.326250,-1213.662720,0.033640,0.000000
25.010002,4.700836,-1213.662720,0.003725,0.001303,0.033085,20.910364,1.065225,0.330847,-1213.662720,0.034056,0.000000
25.260002,4.714615,-1213.662720,0.003721,0.001317,0.033440,20.971655,1.068347,0.334403,-1213.662720,0.034472,0.000000
25.510002,4.809563,-1213.662720,0.003721,0.001332,0.033822,21.394003,1.089862,0.338218,-1213.662720,0.034888,0.000000
25.760002,4.869522,-1213.618286,0.003781,0.001347,0.034212,21.660717,1.103449,0.342121,-1213.618286,0.035305,0.000000
26.010002,4.935425,-1213.618286,0.003751,0.001362,0.034585,21.953865,1.118383,0.345850,-1213.618286,0.035721,0.000000
26.260002,5.152145,-1213.662720,0.003824,0.001384,0.035157,22.917887,1.167493,0.351574,-1213.662720,0.036137,0.000000
26.510002,5.270561,-1213.707275,0.003816,0.001405,0.035678,23.444628,1.194326,0.356777,-1213.707275,0.036562,0.000000
26.760002,5.258644,-1213.707275,0.003811,0.001421,0.036103,23.391617,1.191626,0.361026,-1213.707275,0.036979,0.000000
27.010002,5.272797,-1213.707275,0.003885,0.001435,0.036458,23.454571,1.194833,0.364582,-1213.707275,0.037395,0.000000
27.260002,5.345413,-1213.662720,0.003850,0.001450,0.036831,23.777586,1.211288,0.368311,-1213.662720,0.037811,0.000000
27.510002,5.462334,-1213.662720,0.003893,0.001466,0.037239,24.297674,1.237782,0.372387,-1213.662720,0.038227,0.000000
27.760002,5.517822,-1213.707275,0.003876,0.001482,0.037646,24.544498,1.250356,0.376463,-1213.707275,0.038644,0.000000
28.010002,5.687622,-1213.751709,0.003898,0.001500,0.038089,25.299807,1.288833,0.380886,-1213.751709,0.039060,0.000000
28.260002,5.771774,-1213.707275,0.003915,0.001518,0.038566,25.674135,1.307903,0.385655,-1213.707275,0.039476,0.000000
28.510002,5.785553,-1213.662720,0.003932,0.001531,0.038895,25.735424,1.311025,0.388951,-1213.662720,0.039892,0.000000
28.760002,5.861519,-1213.662720,0.003958,0.001549,0.039337,26.073338,1.328239,0.393374,-1213.662720,0.040309,0.000000
29.010002,5.916260,-1213.707275,0.003992,0.001564,0.039736,26.316837,1.340644,0.397363,-1213.707275,0.040725,0.000000
29.260002,6.105049,-1213.707275,0.004010,0.001583,0.040196,27.156614,1.383424,0.401959,-1213.707275,0.041141,0.000000
29.510002,6.080101,-1213.796143,0.004040,0.001596,0.040543,27.045641,1.377771,0.405428,-1213.796143,0.041557,0.000000
29.760002,6.104309,-1213.751709,0.003988,0.001606,0.040803,27.153322,1.383256,0.408030,-1213.751709,0.041974,0.000000
30.010002,6.246178,-1213.751709,0.004018,0.001622,0.041211,27.784386,1.415404,0.412106,-1213.751709,0.042390,0.000000
30.260002,6.511307,-1213.751709,0.004053,0.001646,0.041800,28.963739,1.475483,0.418003,-1213.751709,0.042806,0.000000
30.510002,6.488968,-1213.707275,0.004135,0.001662,0.042208,28.864370,1.470421,0.422079,-1213.707275,0.043223,0.000000
30.760002,6.606262,-1213.707275,0.004139,0.001680,0.042668,29.386122,1.497000,0.426675,-1213.707275,0.043639,0.000000
31.010002,6.730263,-1213.662720,0.004139,0.001699,0.043162,29.937704,1.525099,0.431619,-1213.662720,0.044055,0.000000
31.260002,6.769363,-1213.707275,0.004113,0.001714,0.043543,30.111631,1.533960,0.435434,-1213.707275,0.044471,0.000000
31.510002,6.900063,-1213.662720,0.004169,0.001731,0.043968,30.693010,1.563577,0.439684,-1213.662720,0.044888,0.000000
31.760002,6.833786,-1213.707275,0.004195,0.001743,0.044263,30.398199,1.548558,0.442632,-1213.707275,0.045313,0.000000
32.010002,7.125725,-1213.707275,0.004169,0.001763,0.044792,31.696808,1.614712,0.447922,-1213.707275,0.045729,0.000000
32.260002,7.145088,-1213.751709,0.004191,0.001778,0.045174,31.782940,1.619100,0.451738,-1213.751709,0.046145,0.000000
32.510002,7.160355,-1213.751709,0.004230,0.001790,0.045477,31.850847,1.622560,0.454774,-1213.751709,0.046561,0.000000
32.760002,7.341324,-1213.707275,0.004243,0.001809,0.045954,32.655838,1.663568,0.459543,-1213.707275,0.046978,0.000000
33.010002,7.475380,-1213.707275,0.004212,0.001827,0.046397,33.252151,1.693945,0.463966,-1213.707275,0.047394,0.000000
33.260002,7.593422,-1213.796143,0.004238,0.001844,0.046830,33.777229,1.720694,0.468302,-1213.796143,0.047810,0.000000
33.510002,7.533844,-1213.751709,0.004264,0.001855,0.047125,33.512211,1.707193,0.471251,-1213.751709,0.048226,0.000000
33.760002,7.688377,-1213.796143,0.004268,0.001871,0.047533,34.199612,1.742211,0.475327,-1213.796143,0.048643,0.000000
34.010002,7.968773,-1213.751709,0.004290,0.001892,0.048044,35.446873,1.805750,0.480443,-1213.751709,0.049059,0.000000
34.260002,8.033195,-1213.796143,0.004359,0.001910,0.048504,35.733437,1.820348,0.485040,-1213.796143,0.049475,0.000000
34.510002,8.097618,-1213.707275,0.004320,0.001925,0.048903,36.020004,1.834946,0.489029,-1213.707275,0.049891,0.000000
34.760002,8.155708,-1213.796143,0.004342,0.001940,0.049284,36.278404,1.848110,0.492844,-1213.796143,0.050308,0.000000
35.010002,8.113625,-1213.751709,0.004389,0.001951,0.049545,36.091206,1.838574,0.495446,-1213.751709,0.050724,0.000000
35.260002,8.380989,-1213.751709,0.004424,0.001973,0.050108,37.280502,1.899159,0.501083,-1213.751709,0.051140,0.000000
35.510002,8.443550,-1213.707275,0.004419,0.001988,0.050507,37.558788,1.913336,0.505072,-1213.707275,0.051557,0.000000
35.760002,8.620796,-1213.885132,0.004402,0.002004,0.050898,38.347218,1.953500,0.508975,-1213.885132,0.051973,0.000000
36.010002,8.709793,-1213.796143,0.004445,0.002020,0.051305,38.743095,1.973667,0.513051,-1213.796143,0.052389,0.000000
36.260002,8.829697,-1213.751709,0.004402,0.002035,0.051678,39.276451,2.000838,0.516780,-1213.751709,0.052805,0.000000
36.510002,8.974182,-1213.751709,0.004471,0.002056,0.052216,39.919155,2.033579,0.522157,-1213.751709,0.053222,0.000000
36.760002,9.070625,-1213.796143,0.004458,0.002070,0.052580,40.348156,2.055433,0.525799,-1213.796143,0.053647,0.000000
37.010002,9.180099,-1213.751709,0.004506,0.002083,0.052901,40.835121,2.080240,0.529008,-1213.751709,0.054063,0.000000
37.260002,9.612427,-1213.707275,0.004544,0.002108,0.053551,42.758209,2.178207,0.535512,-1213.707275,0.054479,0.000000
37.510002,9.518585,-1213.796143,0.004501,0.002122,0.053907,42.340782,2.156942,0.539068,-1213.796143,0.054895,0.000000
37.760002,9.523804,-1213.796143,0.004549,0.002133,0.054184,42.363995,2.158125,0.541843,-1213.796143,0.055312,0.000000
38.010002,9.840317,-1213.751709,0.004562,0.002154,0.054722,43.771915,2.229848,0.547220,-1213.751709,0.055728,0.000000
38.260002,9.974747,-1213.796143,0.004596,0.002171,0.055138,44.369888,2.260310,0.551382,-1213.796143,0.056144,0.000000
38.510002,10.080124,-1213.796143,0.004609,0.002187,0.055554,44.838631,2.284189,0.555545,-1213.796143,0.056560,0.000000
38.760002,10.293121,-1213.707275,0.004661,0.002205,0.056014,45.786091,2.332454,0.560141,-1213.707275,0.056977,0.000000
39.010002,10.515427,-1213.751709,0.004626,0.002223,0.056474,46.774952,2.382830,0.564738,-1213.751709,0.057393,0.000000
39.260002,10.703476,-1213.796143,0.004618,0.002243,0.056968,47.611439,2.425442,0.569681,-1213.796143,0.057809,0.000000
39.510002,10.691933,-1213.796143,0.004622,0.002255,0.057280,47.560093,2.422827,0.572803,-1213.796143,0.058226,0.000000
39.760002,10.724701,-1213.751709,0.004712,0.002272,0.057705,47.705853,2.430252,0.577052,-1213.751709,0.058642,0.000000
40.010002,11.035637,-1213.751709,0.004721,0.002291,0.058182,49.088966,2.500711,0.581822,-1213.751709,0.059058,0.000000
40.260002,10.983505,-1213.840698,0.004743,0.002301,0.058451,48.857071,2.488898,0.584510,-1213.840698,0.059474,0.000000
40.510002,11.124260,-1213.796143,0.004700,0.002318,0.058885,49.483181,2.520793,0.588846,-1213.796143,0.059891,0.000000
40.760002,11.432587,-1213.796143,0.004747,0.002336,0.059327,50.854687,2.590661,0.593270,-1213.796143,0.060307,0.000000
41.010002,11.590843,-1213.751709,0.004760,0.002352,0.059735,51.558647,2.626523,0.597345,-1213.751709,0.060723,0.000000
41.260002,11.737556,-1213.751709,0.004764,0.002367,0.060125,52.211258,2.659768,0.601248,-1213.751709,0.061139,0.000000
41.510002,11.874214,-1213.796143,0.004812,0.002382,0.060498,52.819141,2.690735,0.604977,-1213.796143,0.061556,0.000000
41.760002,12.076042,-1213.796143,0.004829,0.002399,0.060923,53.716919,2.736470,0.609226,-1213.796143,0.061981,0.000000
42.010002,12.493843,-1213.796143,0.004846,0.002422,0.061521,55.575390,2.831145,0.615210,-1213.796143,0.062397,0.000000
42.260002,12.435753,-1213.840698,0.004842,0.002434,0.061825,55.316990,2.817982,0.618246,-1213.840698,0.062813,0.000000
42.510002,12.555656,-1213.796143,0.004816,0.002449,0.062206,55.850349,2.845152,0.622061,-1213.796143,0.063229,0.000000
42.760002,12.474854,-1213.796143,0.004894,0.002457,0.062406,55.490921,2.826842,0.624056,-1213.796143,0.063646,0.000000
43.010002,12.955215,-1213.707275,0.004855,0.002479,0.062969,57.627678,2.935694,0.629693,-1213.707275,0.064062,0.000000
43.260002,13.227043,-1213.796143,0.004919,0.002495,0.063386,58.836826,2.997291,0.633855,-1213.796143,0.064478,0.000000
43.510002,13.467598,-1213.796143,0.004885,0.002512,0.063793,59.906868,3.051801,0.637931,-1213.796143,0.064895,0.000000
43.760002,13.527550,-1213.751709,0.004894,0.002529,0.064235,60.173546,3.065387,0.642354,-1213.751709,0.065311,0.000000
44.010002,13.806084,-1213.751709,0.004932,0.002546,0.064660,61.412529,3.128503,0.646604,-1213.751709,0.065727,0.000000
44.260002,13.987801,-1213.796143,0.004971,0.002562,0.065085,62.220844,3.169681,0.650853,-1213.796143,0.066143,0.000000
44.510002,14.099144,-1213.751709,0.004967,0.002578,0.065493,62.716125,3.194911,0.654929,-1213.751709,0.066560,0.000000
44.760002,14.013870,-1213.796143,0.004997,0.002589,0.065770,62.336807,3.175588,0.657704,-1213.796143,0.066976,0.000000
45.010002,14.661049,-1213.751709,0.004997,0.002612,0.066343,65.215599,3.322241,0.663428,-1213.751709,0.067392,0.000000
45.260002,14.620461,-1213.751709,0.005032,0.002624,0.066655,65.035057,3.313044,0.666550,-1213.751709,0.067808,0.000000
45.510002,14.858040,-1213.796143,0.005006,0.002640,0.067054,66.091866,3.366880,0.670539,-1213.796143,0.068225,0.000000
45.760002,15.463142,-1213.796143,0.005019,0.002663,0.067652,68.783493,3.503998,0.676523,-1213.796143,0.068641,0.000000
46.010002,15.562935,-1213.840698,0.005118,0.002681,0.068086,69.227394,3.526612,0.680859,-1213.840698,0.069057,0.000000
46.260002,15.734230,-1213.796143,0.005053,0.002697,0.068493,69.989349,3.565428,0.684935,-1213.796143,0.069473,0.000000
46.510002,15.856743,-1213.751709,0.005135,0.002711,0.068858,70.534317,3.593189,0.688577,-1213.751709,0.069890,0.000000
46.760002,16.022820,-1213.840698,0.005105,0.002727,0.069265,71.273064,3.630823,0.692653,-1213.840698,0.070306,0.000000
47.010002,16.238419,-1213.751709,0.005161,0.002739,0.069578,72.232094,3.679678,0.695775,-1213.751709,0.070731,0.000000
47.260002,16.444344,-1213.796143,0.005165,0.002754,0.069959,73.148094,3.726341,0.699591,-1213.796143,0.071147,0.000000
47.510002,16.830864,-1213.796143,0.005191,0.002771,0.070375,74.867424,3.813928,0.703754,-1213.796143,0.071563,0.000000
47.760002,17.626999,-1213.751709,0.005165,0.002799,0.071087,78.408806,3.994335,0.710865,-1213.751709,0.071980,0.000000
48.010002,17.611359,-1213.796143,0.005226,0.002814,0.071468,78.339233,3.990791,0.714681,-1213.796143,0.072396,0.000000
48.260002,17.781906,-1213.796143,0.005230,0.002830,0.071876,79.097870,4.029438,0.718757,-1213.796143,0.072812,0.000000
48.510002,17.797173,-1213.796143,0.005264,0.002843,0.072223,79.165779,4.032897,0.722226,-1213.796143,0.073229,0.000000
48.760002,18.115181,-1213.796143,0.005277,0.002861,0.072665,80.580353,4.104959,0.726649,-1213.796143,0.073645,0.000000
49.010002,18.403397,-1213.840698,0.005247,0.002877,0.073072,81.862396,4.170269,0.730725,-1213.840698,0.074061,0.000000
49.260002,18.220558,-1213.796143,0.005290,0.002882,0.073203,81.049088,4.128838,0.732026,-1213.796143,0.074477,0.000000
49.510002,19.322411,-1213.885132,0.005325,0.002912,0.073974,85.950378,4.378521,0.739744,-1213.885132,0.074894,0.000000
49.760002,19.500031,-1213.840698,0.005351,0.002929,0.074399,86.740471,4.418770,0.743993,-1213.840698,0.075310,0.000000
50.010002,19.720848,-1213.840698,0.005307,0.002946,0.074824,87.722710,4.468808,0.748242,-1213.840698,0.075726,0.000000
50.260002,19.918579,-1213.840698,0.005368,0.002961,0.075215,88.602264,4.513615,0.752145,-1213.840698,0.076142,0.000000
50.510002,20.143120,-1213.796143,0.005364,0.002978,0.075648,89.601074,4.564497,0.756481,-1213.796143,0.076559,0.000000
50.760002,20.266373,-1213.840698,0.005398,0.002987,0.075874,90.149330,4.592426,0.758736,-1213.840698,0.076975,0.000000
51.010002,20.660721,-1213.796143,0.005385,0.003005,0.076325,91.903473,4.681786,0.763245,-1213.796143,0.077391,0.000000
51.260002,21.038300,-1213.885132,0.005385,0.003021,0.076741,93.583031,4.767347,0.767408,-1213.885132,0.077808,0.000000
51.510002,21.808372,-1213.796143,0.005424,0.003044,0.077322,97.008484,4.941848,0.773219,-1213.796143,0.078224,0.000000
51.760002,21.942421,-1213.885132,0.005441,0.003059,0.077686,97.604767,4.972224,0.776861,-1213.885132,0.078640,0.000000
52.010002,22.178139,-1213.840698,0.005424,0.003075,0.078102,98.653290,5.025638,0.781024,-1213.840698,0.079065,0.000000
52.260002,22.600037,-1213.796143,0.005484,0.003094,0.078579,100.529984,5.121241,0.785793,-1213.796143,0.079481,0.000000
52.510002,22.808189,-1213.929687,0.005463,0.003109,0.078978,101.455894,5.168410,0.789783,-1213.929687,0.079898,0.000000
52.760002,23.223755,-1213.840698,0.005514,0.003127,0.079421,103.304420,5.262578,0.794205,-1213.840698,0.080314,0.000000
53.010002,23.135880,-1213.929687,0.005484,0.003136,0.079646,102.913528,5.242665,0.796460,-1213.929687,0.080730,0.000000
53.260002,23.646027,-1213.840698,0.005519,0.003155,0.080132,105.182777,5.358266,0.801317,-1213.840698,0.081146,0.000000
53.510002,24.075371,-1213.796143,0.005566,0.003171,0.080548,107.092598,5.455557,0.805480,-1213.796143,0.081563,0.000000
53.760002,24.381462,-1213.840698,0.005579,0.003186,0.080921,108.454163,5.524919,0.809209,-1213.840698,0.081979,0.000000
54.010002,24.973907,-1213.885132,0.005579,0.003205,0.081407,111.089485,5.659168,0.814065,-1213.885132,0.082395,0.000000
54.260002,25.275528,-1213.840698,0.005566,0.003221,0.081814,112.431160,5.727516,0.818141,-1213.840698,0.082811,0.000000
54.510002,25.565979,-1213.796143,0.005583,0.003238,0.082248,113.723152,5.793334,0.822477,-1213.796143,0.083228,0.000000
54.760002,25.387985,-1213.840698,0.005579,0.003242,0.082343,112.931396,5.752999,0.823431,-1213.840698,0.083644,0.000000
55.010002,25.813232,-1213.796143,0.005592,0.003258,0.082742,114.822990,5.849362,0.827420,-1213.796143,0.084060,0.000000
55.260002,26.584419,-1213.796143,0.005627,0.003281,0.083340,118.253403,6.024116,0.833404,-1213.796143,0.084476,0.000000
55.510002,27.263626,-1213.840698,0.005618,0.003300,0.083809,121.274666,6.178026,0.838087,-1213.840698,0.084893,0.000000
55.760002,27.633392,-1213.885132,0.005644,0.003318,0.084277,122.919472,6.261817,0.842770,-1213.885132,0.085309,0.000000
56.010002,28.150986,-1213.840698,0.005691,0.003336,0.084728,125.221840,6.379105,0.847279,-1213.840698,0.085725,0.000000
56.260002,28.291000,-1213.840698,0.005717,0.003347,0.085014,125.844658,6.410832,0.850141,-1213.840698,0.086142,0.000000
56.510002,29.046173,-1213.840698,0.005696,0.003367,0.085526,129.203827,6.581957,0.855258,-1213.840698,0.086558,0.000000
56.760002,29.354866,-1213.796143,0.005696,0.003384,0.085942,130.576965,6.651907,0.859421,-1213.796143,0.086974,0.000000
57.010002,29.583504,-1213.885132,0.005734,0.003399,0.086332,131.593994,6.703718,0.863323,-1213.885132,0.087399,0.000000
57.260002,30.195312,-1213.796143,0.005717,0.003415,0.086740,134.315460,6.842355,0.867400,-1213.796143,0.087815,0.000000
57.510002,30.759460,-1213.840698,0.005752,0.003433,0.087200,136.824921,6.970193,0.871996,-1213.840698,0.088232,0.000000
57.760002,31.100922,-1213.840698,0.005764,0.003450,0.087633,138.343811,7.047570,0.876332,-1213.840698,0.088648,0.000000
58.010002,31.460632,-1213.796143,0.005764,0.003464,0.087989,139.943878,7.129081,0.879887,-1213.796143,0.089064,0.000000
58.260002,31.692253,-1213.796143,0.005799,0.003479,0.088362,140.974182,7.181567,0.883616,-1213.796143,0.089480,0.000000
58.510002,32.895012,-1213.885132,0.005829,0.003501,0.088934,146.324326,7.454116,0.889340,-1213.885132,0.089897,0.000000
58.760002,33.223450,-1213.840698,0.005821,0.003516,0.089307,147.785278,7.528541,0.893069,-1213.840698,0.090313,0.000000
59.010002,33.430115,-1213.796143,0.005877,0.003530,0.089671,148.704575,7.575372,0.896712,-1213.796143,0.090729,0.000000
59.260002,33.746628,-1213.885132,0.005821,0.003544,0.090027,150.112503,7.647095,0.900267,-1213.885132,0.091145,0.000000
59.510002,34.539040,-1213.885132,0.005864,0.003562,0.090478,153.637314,7.826658,0.904777,-1213.885132,0.091562,0.000000
59.760002,34.980301,-1213.840698,0.005864,0.003581,0.090963,155.600143,7.926650,0.909633,-1213.840698,0.091978,0.000000
60.010002,35.623756,-1213.840698,0.005924,0.003597,0.091362,158.462387,8.072459,0.913623,-1213.840698,0.092394,0.000000
60.260002,35.947350,-1213.840698,0.005868,0.003611,0.091709,159.901794,8.145786,0.917091,-1213.840698,0.092810,0.000000
60.510002,37.139687,-1213.840698,0.005915,0.003636,0.092342,165.205582,8.415974,0.923422,-1213.840698,0.093227,0.000000
60.760002,37.252892,-1213.840698,0.005963,0.003651,0.092732,165.709137,8.441627,0.927325,-1213.840698,0.093643,0.000000
61.010002,37.705696,-1213.840698,0.005924,0.003664,0.093053,167.723312,8.544233,0.930533,-1213.840698,0.094059,0.000000
61.260002,38.759880,-1213.840698,0.005971,0.003684,0.093582,172.412552,8.783114,0.935823,-1213.840698,0.094476,0.000000
61.510002,39.096130,-1213.885132,0.005937,0.003698,0.093929,173.908279,8.859309,0.939292,-1213.885132,0.094892,0.000000
61.760002,39.294235,-1213.974121,0.005954,0.003712,0.094276,174.789490,8.904202,0.942761,-1213.974121,0.095308,0.000000
62.010002,40.292564,-1213.885132,0.006015,0.003732,0.094796,179.230270,9.130425,0.947965,-1213.885132,0.095724,0.000000
62.260002,40.687653,-1213.840698,0.006049,0.003747,0.095169,180.987717,9.219954,0.951694,-1213.840698,0.096149,0.000000
62.510002,41.207855,-1213.885132,0.006049,0.003763,0.095568,183.301697,9.337833,0.955683,-1213.885132,0.096566,0.000000
62.760002,41.780937,-1213.885132,0.006066,0.003777,0.095941,185.850891,9.467695,0.959412,-1213.885132,0.096982,0.000000
63.010002,42.297417,-1213.885132,0.006028,0.003790,0.096271,188.148300,9.584732,0.962707,-1213.885132,0.097398,0.000000
63.260002,43.589180,-1213.840698,0.006045,0.003816,0.096930,193.894363,9.877450,0.969298,-1213.840698,0.097814,0.000000
63.510002,43.627533,-1213.885132,0.006023,0.003824,0.097129,194.064957,9.886141,0.971293,-1213.885132,0.098231,0.000000
63.760002,44.497398,-1213.840698,0.006053,0.003844,0.097632,197.934311,10.083255,0.976323,-1213.840698,0.098647,0.000000
64.010002,44.602402,-1213.885132,0.006092,0.003855,0.097918,198.401398,10.107048,0.979185,-1213.885132,0.099063,0.000000
64.260002,45.153885,-1213.885132,0.006127,0.003867,0.098222,200.854507,10.232017,0.982220,-1213.885132,0.099479,0.000000
64.510002,45.504662,-1213.929687,0.006140,0.003878,0.098500,202.414841,10.311503,0.984995,-1213.929687,0.099896,0.000000
64.760002,46.972557,-1213.885132,0.006135,0.003907,0.099228,208.944366,10.644134,0.992280,-1213.885132,0.100312,0.000000
65.010002,47.748581,-1213.929687,0.006122,0.003921,0.099601,212.396301,10.819983,0.996009,-1213.929687,0.100728,0.000000
65.260002,48.598709,-1213.929687,0.006170,0.003940,0.100087,216.177856,11.012626,1.000865,-1213.929687,0.101145,0.000000
65.510002,48.918205,-1213.840698,0.006174,0.003950,0.100338,217.599045,11.085024,1.003380,-1213.840698,0.101561,0.000000
65.760002,49.848389,-1213.929687,0.006196,0.003971,0.100867,221.736710,11.295807,1.008670,-1213.929687,0.101977,0.000000
66.010002,50.339172,-1213.929687,0.006196,0.003984,0.101188,223.919815,11.407020,1.011879,-1213.929687,0.102393,0.000000
66.260002,51.257446,-1213.885132,0.006170,0.004002,0.101656,228.004501,11.615104,1.016562,-1213.885132,0.102810,0.000000
66.510002,51.962715,-1213.974121,0.006222,0.004019,0.102072,231.141708,11.774920,1.020725,-1213.974121,0.103226,0.000000
66.760002,52.704483,-1213.974121,0.006226,0.004036,0.102506,234.441254,11.943007,1.025061,-1213.974121,0.103642,0.000000
67.010002,53.657387,-1213.885132,0.006170,0.004053,0.102957,238.679977,12.158937,1.029570,-1213.885132,0.104058,0.000000
67.260002,54.622574,-1213.974121,0.006252,0.004073,0.103460,242.973343,12.377652,1.034601,-1213.974121,0.104483,0.000000
67.510002,54.994949,-1213.929687,0.006222,0.004086,0.103772,244.629745,12.462034,1.037723,-1213.929687,0.104900,0.000000
67.760002,55.857735,-1213.974121,0.006260,0.004104,0.104232,248.467621,12.657544,1.042319,-1213.974121,0.105316,0.000000
68.010002,56.398048,-1213.929687,0.006273,0.004115,0.104518,250.871048,12.779981,1.045181,-1213.929687,0.105732,0.000000
68.260002,57.279823,-1213.885132,0.006312,0.004132,0.104943,254.793381,12.979793,1.049430,-1213.885132,0.106148,0.000000
68.510002,58.017120,-1213.840698,0.006321,0.004148,0.105351,258.073029,13.146868,1.053506,-1213.840698,0.106565,0.000000
68.760002,58.557434,-1213.929687,0.006308,0.004165,0.105802,260.476471,13.269304,1.058015,-1213.929687,0.106981,0.000000
69.010002,60.052879,-1213.974121,0.006291,0.004184,0.106270,267.128540,13.608177,1.062699,-1213.974121,0.107397,0.000000
69.260002,61.162552,-1213.929687,0.006338,0.004204,0.106790,272.064606,13.859632,1.067902,-1213.929687,0.107814,0.000000
69.510002,62.027946,-1213.974121,0.006338,0.004222,0.107232,275.914093,14.055734,1.072325,-1213.974121,0.108230,0.000000
69.760002,62.624863,-1213.885132,0.006355,0.004235,0.107579,278.569305,14.190996,1.075794,-1213.885132,0.108646,0.000000
70.010002,63.507751,-1213.929687,0.006364,0.004254,0.108048,282.496582,14.391062,1.080477,-1213.929687,0.109062,0.000000
70.260002,64.321396,-1213.885132,0.006377,0.004269,0.108429,286.115845,14.575437,1.084292,-1213.885132,0.109479,0.000000
70.510002,64.804733,-1213.929687,0.006334,0.004280,0.108715,288.265839,14.684962,1.087154,-1213.929687,0.109895,0.000000
70.760002,66.003387,-1213.929687,0.006407,0.004301,0.109236,293.597717,14.956581,1.092358,-1213.929687,0.110311,0.000000
71.010002,67.272064,-1213.929687,0.006411,0.004320,0.109721,299.241089,15.244068,1.097214,-1213.929687,0.110727,0.000000
71.260002,67.217331,-1213.929687,0.006403,0.004319,0.109695,298.997620,15.231665,1.096954,-1213.929687,0.109912,0.000000
71.510002,66.566055,-1213.929687,0.006441,0.004318,0.109687,296.100616,15.084084,1.096867,-1213.929687,0.109695,0.000000
71.760002,66.020157,-1213.974121,0.006433,0.004317,0.109652,293.672333,14.960382,1.096521,-1213.974121,0.109695,0.000000
72.010002,65.595276,-1213.885132,0.006437,0.004317,0.109643,291.782349,14.864102,1.096433,-1213.885132,0.109695,0.000000
72.260002,65.221420,-1213.929687,0.006446,0.004316,0.109635,290.119354,14.779385,1.096347,-1213.929687,0.109695,0.000000
72.510002,64.906387,-1213.840698,0.006454,0.004316,0.109635,288.718018,14.707997,1.096347,-1213.840698,0.109695,0.000000
72.760002,64.616302,-1213.974121,0.006398,0.004316,0.109626,287.427673,14.642263,1.096260,-1213.974121,0.109695,0.000000
73.010002,64.341125,-1213.885132,0.006454,0.004316,0.109626,286.203613,14.579907,1.096260,-1213.885132,0.109695,0.000000
73.260002,64.119934,-1213.929687,0.006411,0.004316,0.109626,285.219727,14.529785,1.096260,-1213.929687,0.109695,0.000000
73.510002,63.893539,-1213.885132,0.006407,0.004316,0.109626,284.212646,14.478482,1.096260,-1213.885132,0.109695,0.000000
73.760002,63.718140,-1213.929687,0.006407,0.004316,0.109626,283.432434,14.438737,1.096260,-1213.929687,0.109695,0.000000
74.010002,63.540527,-1213.885132,0.006467,0.004316,0.109626,282.642395,14.398489,1.096260,-1213.885132,0.109695,0.000000
74.260002,63.377045,-1213.840698,0.006472,0.004316,0.109617,281.915161,14.361444,1.096174,-1213.840698,0.109695,0.000000
74.510002,63.220657,-1213.885132,0.006446,0.004316,0.109617,281.219543,14.326005,1.096174,-1213.885132,0.109695,0.000000
74.760002,63.065002,-1213.929687,0.006459,0.004316,0.109617,280.527130,14.290734,1.096174,-1213.929687,0.109695,0.000000
75.010002,62.942123,-1213.929687,0.006424,0.004316,0.109617,279.980560,14.262890,1.096174,-1213.929687,0.109695,0.000000
75.260002,62.817375,-1213.974121,0.006416,0.004316,0.109617,279.425629,14.234620,1.096174,-1213.974121,0.109695,0.000000
75.510002,62.691887,-1213.885132,0.006437,0.004316,0.109617,278.867432,14.206184,1.096174,-1213.885132,0.109695,0.000000
75.760002,62.575333,-1213.885132,0.006450,0.004316,0.109617,278.348969,14.179773,1.096174,-1213.885132,0.109695,0.000000
76.010002,62.468460,-1213.929687,0.006437,0.004316,0.109617,277.873596,14.155556,1.096174,-1213.929687,0.109695,0.000000
76.260002,62.348557,-1213.974121,0.006428,0.004316,0.109617,277.340240,14.128385,1.096174,-1213.974121,0.109695,0.000000
76.510002,62.263283,-1213.974121,0.006424,0.004316,0.109617,276.960907,14.109061,1.096174,-1213.974121,0.109695,0.000000
76.760002,62.171684,-1213.885132,0.006454,0.004316,0.109617,276.553467,14.088305,1.096174,-1213.885132,0.109695,0.000000
77.010002,62.099068,-1213.885132,0.006437,0.004316,0.109617,276.230438,14.071850,1.096174,-1213.885132,0.109695,0.000000
77.260002,61.994431,-1213.929687,0.006463,0.004316,0.109617,275.765015,14.048139,1.096174,-1213.929687,0.109695,0.000000
77.510002,61.920334,-1213.885132,0.006420,0.004316,0.109617,275.435394,14.031348,1.096174,-1213.885132,0.109695,0.000000
77.760002,61.828354,-1213.885132,0.006476,0.004316,0.109617,275.026245,14.010505,1.096174,-1213.885132,0.109695,0.000000
78.010002,61.755745,-1213.929687,0.006472,0.004315,0.109609,274.703278,13.994052,1.096087,-1213.929687,0.109695,0.000000
78.260002,61.687225,-1213.929687,0.006428,0.004315,0.109609,274.398468,13.978525,1.096087,-1213.929687,0.109695,0.000000
78.510002,61.622803,-1213.929687,0.006450,0.004315,0.109609,274.111908,13.963926,1.096087,-1213.929687,0.109695,0.000000
78.760002,61.549072,-1213.929687,0.006467,0.004315,0.109609,273.783936,13.947220,1.096087,-1213.929687,0.109695,0.000000
79.010002,61.477577,-1213.885132,0.006467,0.004315,0.109609,273.465912,13.931018,1.096087,-1213.885132,0.109695,0.000000
79.260002,61.409065,-1213.885132,0.006472,0.004315,0.109609,273.161163,13.915493,1.096087,-1213.885132,0.109695,0.000000
79.510002,61.345390,-1213.929687,0.006416,0.004315,0.109609,272.877930,13.901064,1.096087,-1213.929687,0.109695,0.000000
79.760002,61.286926,-1213.929687,0.006485,0.004315,0.109609,272.617859,13.887815,1.096087,-1213.929687,0.109695,0.000000
80.010002,61.230698,-1213.885132,0.006472,0.004315,0.109609,272.367737,13.875074,1.096087,-1213.885132,0.109695,0.000000
80.260002,61.185638,-1213.885132,0.006493,0.004315,0.109609,272.167328,13.864863,1.096087,-1213.885132,0.109695,0.000000
80.510002,61.112656,-1213.885132,0.006424,0.004315,0.109609,271.842682,13.848326,1.096087,-1213.885132,0.109695,0.000000
80.760002,61.062012,-1213.929687,0.006424,0.004315,0.109609,271.617401,13.836849,1.096087,-1213.929687,0.109695,0.000000
81.010002,60.999825,-1213.929687,0.006450,0.004315,0.109609,271.340759,13.822758,1.096087,-1213.929687,0.109695,0.000000
81.260002,60.951042,-1213.929687,0.006454,0.004315,0.109609,271.123779,13.811704,1.096087,-1213.929687,0.109695,0.000000
81.510002,60.892952,-1213.929687,0.006437,0.004315,0.109609,270.865387,13.798541,1.096087,-1213.929687,0.109695,0.000000
81.760002,60.866142,-1213.885132,0.006480,0.004315,0.109609,270.746124,13.792465,1.096087,-1213.885132,0.109695,0.000000
82.010002,60.807312,-1213.885132,0.006441,0.004315,0.109609,270.484436,13.779134,1.096087,-1213.885132,0.109695,0.000000
82.260002,60.753685,-1213.929687,0.006450,0.004315,0.109609,270.245880,13.766982,1.096087,-1213.929687,0.109695,0.000000
82.510002,60.709000,-1213.885132,0.006476,0.004315,0.109609,270.047119,13.756856,1.096087,-1213.885132,0.109695,0.000000
82.760002,60.667671,-1213.885132,0.006485,0.004315,0.109609,269.863281,13.747491,1.096087,-1213.885132,0.109695,0.000000
83.010002,60.617027,-1213.929687,0.006510,0.004315,0.109609,269.638000,13.736014,1.096087,-1213.929687,0.109695,0.000000
83.260002,60.596550,-1213.885132,0.006428,0.004315,0.109609,269.546906,13.731375,1.096087,-1213.885132,0.109695,0.000000
83.510002,60.558563,-1213.974121,0.006510,0.004315,0.109609,269.377930,13.722767,1.096087,-1213.974121,0.109695,0.000000
83.760002,60.497498,-1213.885132,0.006437,0.004315,0.109609,269.106323,13.708929,1.096087,-1213.885132,0.109695,0.000000
84.010002,60.452065,-1213.885132,0.006450,0.004315,0.109609,268.904205,13.698633,1.096087,-1213.885132,0.109695,0.000000
84.260002,60.418556,-1213.929687,0.006454,0.004315,0.109609,268.755157,13.691040,1.096087,-1213.929687,0.109695,0.000000
84.510002,60.375359,-1213.929687,0.006454,0.004315,0.109609,268.563019,13.681252,1.096087,-1213.929687,0.109695,0.000000
84.760002,60.342590,-1213.885132,0.006459,0.004315,0.109609,268.417236,13.673827,1.096087,-1213.885132,0.109695,0.000000
85.010002,60.310196,-1213.885132,0.006476,0.004315,0.109609,268.273163,13.666486,1.096087,-1213.885132,0.109695,0.000000
85.260002,60.271469,-1213.840698,0.006493,0.004315,0.109609,268.100891,13.657710,1.096087,-1213.840698,0.109695,0.000000
85.510002,60.234604,-1213.929687,0.006467,0.004315,0.109609,267.936890,13.649357,1.096087,-1213.929687,0.109695,0.000000
85.760002,60.182098,-1213.840698,0.006467,0.004315,0.109609,267.703339,13.637459,1.096087,-1213.840698,0.109695,0.000000
86.010002,60.162735,-1213.929687,0.006441,0.004315,0.109609,267.617218,13.633071,1.096087,-1213.929687,0.109695,0.000000
86.260002,60.120651,-1213.929687,0.006450,0.004315,0.109609,267.430023,13.623534,1.096087,-1213.929687,0.109695,0.000000
86.510002,60.102036,-1213.974121,0.006485,0.004315,0.109609,267.347198,13.619316,1.096087,-1213.974121,0.109695,0.000000
86.760002,60.070015,-1213.929687,0.006480,0.004315,0.109609,267.204773,13.612060,1.096087,-1213.929687,0.109695,0.000000
87.010002,60.046928,-1213.974121,0.006480,0.004315,0.109609,267.102081,13.606829,1.096087,-1213.974121,0.109695,0.000000
87.260002,60.005966,-1213.929687,0.006467,0.004315,0.109609,266.919861,13.597547,1.096087,-1213.929687,0.109695,0.000000
87.510002,59.971703,-1213.929687,0.006441,0.004315,0.109609,266.767456,13.589783,1.096087,-1213.929687,0.109695,0.000000
87.760002,59.941170,-1213.885132,0.006437,0.004315,0.109609,266.631653,13.582863,1.096087,-1213.885132,0.109695,0.000000
88.010002,59.898720,-1214.018555,0.006515,0.004315,0.109609,266.442810,13.573244,1.096087,-1214.018555,0.109695,0.000000
88.260002,59.889412,-1213.974121,0.006454,0.004315,0.109609,266.401398,13.571135,1.096087,-1213.974121,0.109695,0.000000
88.510002,59.849197,-1213.885132,0.006450,0.004315,0.109609,266.222534,13.562022,1.096087,-1213.885132,0.109695,0.000000
88.760002,59.828339,-1213.929687,0.006441,0.004315,0.109609,266.129730,13.557296,1.096087,-1213.929687,0.109695,0.000000
89.010002,59.789246,-1213.885132,0.006510,0.004315,0.109609,265.955841,13.548436,1.096087,-1213.885132,0.109695,0.000000
89.260002,59.771744,-1213.929687,0.006454,0.004315,0.109609,265.877991,13.544471,1.096087,-1213.929687,0.109695,0.000000
89.510002,59.733391,-1213.885132,0.006497,0.004315,0.109609,265.707397,13.535779,1.096087,-1213.885132,0.109695,0.000000
89.760002,59.699127,-1213.885132,0.006459,0.004315,0.109609,265.554993,13.528016,1.096087,-1213.885132,0.109695,0.000000
90.010002,59.689072,-1213.974121,0.006420,0.004315,0.109609,265.510254,13.525737,1.096087,-1213.974121,0.109695,0.000000
90.260002,59.661888,-1214.018555,0.006485,0.004315,0.109609,265.389343,13.519577,1.096087,-1214.018555,0.109695,0.000000
90.510002,59.640297,-1213.929687,0.006463,0.004315,0.109609,265.293304,13.514685,1.096087,-1213.929687,0.109695,0.000000
90.760002,59.601196,-1213.974121,0.006437,0.004315,0.109609,265.119354,13.505824,1.096087,-1213.974121,0.109695,0.000000
91.010002,59.585556,-1213.929687,0.006476,0.004315,0.109609,265.049805,13.502280,1.096087,-1213.929687,0.109695,0.000000
91.260002,59.543480,-1214.018555,0.006467,0.004315,0.109609,264.862640,13.492745,1.096087,-1214.018555,0.109695,0.000000
91.510002,59.534164,-1213.974121,0.006497,0.004315,0.109609,264.821198,13.490634,1.096087,-1213.974121,0.109695,0.000000
91.760002,59.499535,-1214.018555,0.006459,0.004315,0.109609,264.667145,13.482787,1.096087,-1214.018555,0.109695,0.000000
92.010002,59.483894,-1213.974121,0.006485,0.004315,0.109609,264.597565,13.479243,1.096087,-1213.974121,0.109695,0.000000
92.260002,59.467888,-1214.018555,0.006433,0.004315,0.109609,264.526367,13.475616,1.096087,-1214.018555,0.109695,0.000000
92.510002,59.441078,-1213.929687,0.006497,0.004315,0.109609,264.407135,13.469541,1.096087,-1213.929687,0.109695,0.000000
92.760002,59.405701,-1213.974121,0.006463,0.004315,0.109609,264.249756,13.461524,1.096087,-1213.974121,0.109695,0.000000
93.010002,59.389687,-1214.018555,0.006459,0.004315,0.109609,264.178528,13.457896,1.096087,-1214.018555,0.109695,0.000000
93.260002,59.369583,-1213.974121,0.006480,0.004315,0.109609,264.089081,13.453341,1.096087,-1213.974121,0.109695,0.000000
93.510002,59.349846,-1213.974121,0.006519,0.004315,0.109609,264.001312,13.448867,1.096087,-1213.974121,0.109695,0.000000
93.760002,59.334206,-1214.018555,0.006476,0.004315,0.109609,263.931732,13.445323,1.096087,-1214.018555,0.109695,0.000000
94.010002,59.295105,-1213.929687,0.006502,0.004315,0.109609,263.757812,13.436462,1.096087,-1213.929687,0.109695,0.000000
94.260002,59.278351,-1214.018555,0.006437,0.004315,0.109609,263.683289,13.432666,1.096087,-1214.018555,0.109695,0.000000
94.510002,59.254143,-1214.018555,0.006450,0.004315,0.109609,263.575592,13.427181,1.096087,-1214.018555,0.109695,0.000000
94.760002,59.245583,-1213.974121,0.006489,0.004315,0.109609,263.537506,13.425241,1.096087,-1213.974121,0.109695,0.000000
95.010002,59.218765,-1213.974121,0.006459,0.004315,0.109609,263.418213,13.419164,1.096087,-1213.974121,0.109695,0.000000
95.260002,59.198288,-1213.929687,0.006416,0.004315,0.109609,263.327148,13.414524,1.096087,-1213.929687,0.109695,0.000000
95.510002,59.174828,-1214.018555,0.006497,0.004315,0.109609,263.222778,13.409207,1.096087,-1214.018555,0.109695,0.000000
95.760002,59.154724,-1213.974121,0.006454,0.004315,0.109609,263.133362,13.404652,1.096087,-1213.974121,0.109695,0.000000
96.010002,59.135727,-1214.018555,0.006454,0.004315,0.109609,263.048859,13.400347,1.096087,-1214.018555,0.109695,0.000000
96.260002,59.124931,-1213.929687,0.006454,0.004315,0.109609,263.000824,13.397902,1.096087,-1213.929687,0.109695,0.000000
96.510002,59.108917,-1213.974121,0.006441,0.004315,0.109609,262.929596,13.394273,1.096087,-1213.974121,0.109695,0.000000
96.760002,59.075409,-1214.018555,0.006454,0.004315,0.109609,262.780548,13.386680,1.096087,-1214.018555,0.109695,0.000000
97.010002,59.070190,-1213.974121,0.006441,0.004315,0.109609,262.757324,13.385496,1.096087,-1213.974121,0.109695,0.000000
97.260002,59.035561,-1213.974121,0.006411,0.004315,0.109609,262.603302,13.377649,1.096087,-1213.974121,0.109695,0.000000
97.510002,59.028488,-1214.063110,0.006454,0.004315,0.109609,262.571838,13.376046,1.096087,-1214.063110,0.109695,0.000000
97.760002,59.015823,-1213.974121,0.006493,0.004315,0.109609,262.515503,13.373177,1.096087,-1213.974121,0.109695,0.000000
98.010002,58.991623,-1213.974121,0.006441,0.004315,0.109609,262.407837,13.367693,1.096087,-1213.974121,0.109695,0.000000
98.260002,58.987526,-1213.974121,0.006485,0.004315,0.109609,262.389618,13.366765,1.096087,-1213.974121,0.109695,0.000000
98.510002,58.957367,-1213.974121,0.006450,0.004315,0.109609,262.255463,13.359931,1.096087,-1213.974121,0.109695,0.000000
98.760002,58.934647,-1214.018555,0.006433,0.004315,0.109609,262.154388,13.354781,1.096087,-1214.018555,0.109695,0.000000
99.010002,58.921989,-1213.929687,0.006437,0.004315,0.109609,262.098114,13.351913,1.096087,-1213.929687,0.109695,0.000000
99.260002,58.910446,-1213.974121,0.006485,0.004315,0.109609,262.046753,13.349298,1.096087,-1213.974121,0.109695,0.000000
99.510002,58.899277,-1213.974121,0.006480,0.004315,0.109609,261.997070,13.346766,1.096087,-1213.974121,0.109695,0.000000
99.760002,58.880653,-1213.929687,0.006472,0.004315,0.109609,261.914215,13.342546,1.096087,-1213.929687,0.109695,0.000000
100.010002,58.848259,-1214.018555,0.006450,0.004315,0.109609,261.770142,13.335206,1.096087,-1214.018555,0.109695,0.000000
100.260002,58.847885,-1213.929687,0.006476,0.004315,0.109609,261.768463,13.335121,1.096087,-1213.929687,0.109695,0.000000
100.510002,58.819588,-1213.929687,0.006485,0.004315,0.109609,261.642609,13.328709,1.096087,-1213.929687,0.109695,0.000000
100.760002,58.813629,-1213.974121,0.006463,0.004315,0.109609,261.616089,13.327359,1.096087,-1213.974121,0.109695,0.000000
101.010002,58.789047,-1213.885132,0.006480,0.004315,0.109609,261.506744,13.321789,1.096087,-1213.885132,0.109695,0.000000
101.260002,58.771553,-1213.974121,0.006489,0.004315,0.109609,261.428925,13.317824,1.096087,-1213.974121,0.109695,0.000000
101.500008,58.765594,-1213.974121,0.006472,0.004315,0.109609,261.402405,13.316474,1.096087,-1213.974121,0.109695,0.000000