File: Data/Symmetrical membranes compression/Durapore PVDF 5um test 3_10272023_145600.csv
Time (sec),S:Load (lbs),S:HL1 (DIM),S:LVDT (in),S:Position (in),Ch:Position (mm),Ch:Load (N),Ch:Stress (MPa),Ch:Strain (mm/mm),Ch:HL1 (DIM),Set Point (),Cycles ()
0.110000,0.001495,-1214.730347,-0.000052,-0.001291,-0.032790,0.006652,0.000339,-0.327898,-1214.730347,-0.032582,0.000000
0.350000,-0.008560,-1214.730347,-0.000013,-0.001291,-0.032790,-0.038078,-0.001940,-0.327898,-1214.730347,-0.032582,0.000000
0.590000,-0.009682,-1214.685791,-0.000039,-0.001177,-0.029885,-0.043066,-0.002194,-0.298846,-1214.685791,-0.029113,0.000000
0.830000,-0.011543,-1214.730347,0.000039,-0.001031,-0.026182,-0.051347,-0.002616,-0.261815,-1214.730347,-0.025124,0.000000
1.070000,0.003357,-1214.730347,0.000211,-0.000876,-0.022244,0.014932,0.000761,-0.222443,-1214.730347,-0.021117,0.000000
1.310000,0.032402,-1214.774780,0.000397,-0.000721,-0.018307,0.144131,0.007342,-0.183071,-1214.774780,-0.017110,0.000000
1.550000,0.034630,-1214.730347,0.000543,-0.000558,-0.014162,0.154041,0.007847,-0.141618,-1214.730347,-0.013121,0.000000
1.790000,0.053627,-1214.685791,0.000711,-0.000407,-0.010337,0.238545,0.012152,-0.103374,-1214.685791,-0.009115,0.000000
2.030000,0.154541,-1214.730347,0.000858,-0.000251,-0.006383,0.687433,0.035019,-0.063828,-1214.730347,-0.005125,0.000000
2.270000,0.387268,-1214.730347,0.001030,-0.000094,-0.002394,1.722654,0.087756,-0.023936,-1214.730347,-0.001119,0.000000
2.510000,0.641602,-1214.774780,0.001224,0.000011,0.000269,2.853986,0.145389,0.002689,-1214.774780,0.001509,0.000000
2.750000,0.601753,-1214.730347,0.001224,0.000019,0.000486,2.676732,0.136359,0.004856,-1214.730347,0.000668,0.000000
2.990000,0.585747,-1214.730347,0.001255,0.000019,0.000477,2.605532,0.132732,0.004770,-1214.730347,0.000668,0.000000
3.230000,0.557442,-1214.774780,0.001216,0.000019,0.000477,2.479625,0.126318,0.004770,-1214.774780,0.000980,0.000000
3.470000,0.569733,-1214.685791,0.001242,0.000019,0.000486,2.534297,0.129103,0.004856,-1214.685791,0.001379,0.000000
3.710000,0.544785,-1214.730347,0.001220,0.000019,0.000486,2.423323,0.123450,0.004856,-1214.730347,0.001778,0.000000
3.950000,0.654259,-1214.774780,0.001246,0.000051,0.001284,2.910288,0.148257,0.012835,-1214.774780,0.002177,0.000000
4.190000,0.659103,-1214.774780,0.001293,0.000064,0.001630,2.931838,0.149355,0.016304,-1214.774780,0.002576,0.000000
4.430000,0.732086,-1214.774780,0.001246,0.000083,0.002116,3.256482,0.165893,0.021160,-1214.774780,0.002975,0.000000
4.670000,0.775658,-1214.730347,0.001332,0.000096,0.002446,3.450298,0.175767,0.024456,-1214.730347,0.003382,0.000000
4.910000,0.780869,-1214.819214,0.001350,0.000107,0.002723,3.473477,0.176947,0.027231,-1214.819214,0.003781,0.000000
5.150000,0.875824,-1214.596802,0.001380,0.000129,0.003287,3.895860,0.198465,0.032868,-1214.596802,0.004180,0.000000
5.390000,0.885132,-1214.730347,0.001375,0.000145,0.003686,3.937263,0.200574,0.036857,-1214.730347,0.004579,0.000000
5.630000,0.901146,-1214.774780,0.001414,0.000162,0.004111,4.008497,0.204203,0.041107,-1214.774780,0.004978,0.000000
5.870000,0.918648,-1214.774780,0.001380,0.000178,0.004510,4.086349,0.208169,0.045096,-1214.774780,0.005377,0.000000
6.110000,0.955513,-1214.774780,0.001367,0.000191,0.004839,4.250334,0.216522,0.048391,-1214.774780,0.005776,0.000000
6.350000,1.005035,-1214.730347,0.001449,0.000208,0.005290,4.470621,0.227744,0.052901,-1214.730347,0.006175,0.000000
6.590000,0.994606,-1214.730347,0.001462,0.000215,0.005455,4.424229,0.225381,0.054549,-1214.730347,0.006582,0.000000
6.830000,1.053444,-1214.730347,0.001427,0.000226,0.005741,4.685953,0.238714,0.057411,-1214.730347,0.006981,0.000000
7.070000,1.109299,-1214.685791,0.001496,0.000250,0.006357,4.934407,0.251371,0.063568,-1214.685791,0.007380,0.000000
7.310000,1.165154,-1214.685791,0.001500,0.000268,0.006816,5.182862,0.264028,0.068164,-1214.685791,0.007779,0.000000
7.550000,1.170738,-1214.774780,0.001475,0.000284,0.007215,5.207704,0.265293,0.072153,-1214.774780,0.008178,0.000000
7.790000,1.240005,-1214.730347,0.001535,0.000302,0.007666,5.515820,0.280989,0.076663,-1214.730347,0.008577,0.000000
8.030001,1.280594,-1214.774780,0.001539,0.000318,0.008074,5.696366,0.290187,0.080739,-1214.774780,0.008976,0.000000
8.270000,1.333099,-1214.730347,0.001539,0.000333,0.008455,5.929922,0.302085,0.084555,-1214.730347,0.009375,0.000000
8.510000,1.371452,-1214.774780,0.001561,0.000350,0.008889,6.100524,0.310776,0.088891,-1214.774780,0.009782,0.000000
8.750000,1.359161,-1214.730347,0.001608,0.000357,0.009063,6.045852,0.307990,0.090625,-1214.730347,0.010181,0.000000
8.990001,1.422836,-1214.685791,0.001608,0.000379,0.009626,6.329092,0.322419,0.096262,-1214.685791,0.010580,0.000000
9.230000,1.457100,-1214.774780,0.001591,0.000391,0.009930,6.481504,0.330184,0.099298,-1214.774780,0.010979,0.000000
9.470000,1.507736,-1214.730347,0.001625,0.000409,0.010398,6.706746,0.341658,0.103981,-1214.730347,0.011378,0.000000
9.710000,1.559502,-1214.774780,0.001669,0.000426,0.010832,6.937010,0.353388,0.108317,-1214.774780,0.011777,0.000000
9.950001,1.587051,-1214.730347,0.001621,0.000441,0.011213,7.059557,0.359631,0.112132,-1214.730347,0.012176,0.000000
10.190001,1.597481,-1214.685791,0.001699,0.000452,0.011482,7.105949,0.361994,0.114821,-1214.685791,0.012575,0.000000
10.430000,1.630249,-1214.730347,0.001677,0.000466,0.011838,7.251710,0.369420,0.118376,-1214.730347,0.012982,0.000000
10.670000,1.680519,-1214.730347,0.001694,0.000479,0.012176,7.475322,0.380811,0.121759,-1214.730347,0.013381,0.000000
10.910001,1.758347,-1214.774780,0.001694,0.000500,0.012688,7.821516,0.398447,0.126875,-1214.774780,0.013780,0.000000
11.150001,1.827980,-1214.730347,0.001707,0.000519,0.013182,8.131261,0.414226,0.131818,-1214.730347,0.014179,0.000000
11.390000,1.846596,-1214.685791,0.001789,0.000535,0.013581,8.214068,0.418445,0.135808,-1214.685791,0.014578,0.000000
11.630000,1.893517,-1214.685791,0.001807,0.000552,0.014023,8.422782,0.429077,0.140230,-1214.685791,0.014977,0.000000
11.870001,1.918091,-1214.685791,0.001815,0.000566,0.014370,8.532094,0.434646,0.143700,-1214.685791,0.015376,0.000000
12.110001,2.062202,-1214.685791,0.001815,0.000588,0.014934,9.173135,0.467302,0.149336,-1214.685791,0.015775,0.000000
12.350000,2.038368,-1214.774780,0.001819,0.000600,0.015237,9.067115,0.461901,0.152372,-1214.774780,0.016182,0.000000
12.590000,2.074120,-1214.641357,0.001815,0.000613,0.015558,9.226145,0.470002,0.155580,-1214.641357,0.016581,0.000000
12.830001,2.130348,-1214.774780,0.001850,0.000628,0.015948,9.476262,0.482744,0.159483,-1214.774780,0.016980,0.000000
13.070001,2.239075,-1214.685791,0.001858,0.000647,0.016434,9.959902,0.507382,0.164340,-1214.685791,0.017379,0.000000
13.310000,2.236473,-1214.730347,0.001910,0.000660,0.016772,9.948329,0.506792,0.167721,-1214.730347,0.017778,0.000000
13.550000,2.250252,-1214.641357,0.001893,0.000677,0.017197,10.009620,0.509914,0.171971,-1214.641357,0.018177,0.000000
13.790001,2.294563,-1214.730347,0.001936,0.000690,0.017535,10.206727,0.519955,0.175353,-1214.730347,0.018576,0.000000
14.030001,2.453568,-1214.774780,0.001906,0.000713,0.018108,10.914013,0.555986,0.181077,-1214.774780,0.018975,0.000000
14.270000,2.477768,-1214.730347,0.001962,0.000728,0.018498,11.021663,0.561470,0.184980,-1214.730347,0.019382,0.000000
14.510000,2.473671,-1214.774780,0.001962,0.000740,0.018793,11.003438,0.560542,0.187928,-1214.774780,0.019781,0.000000
14.750001,2.524315,-1214.685791,0.001953,0.000756,0.019209,11.228713,0.572018,0.192091,-1214.685791,0.020180,0.000000
14.990001,2.628204,-1214.641357,0.002026,0.000774,0.019660,11.690837,0.595560,0.196600,-1214.641357,0.020579,0.000000
15.230000,2.639748,-1214.819214,0.002018,0.000788,0.020016,11.742184,0.598175,0.200156,-1214.819214,0.020978,0.000000
15.470000,2.677734,-1214.685791,0.002052,0.000804,0.020414,11.911158,0.606783,0.204145,-1214.685791,0.021377,0.000000
15.710001,2.765244,-1214.730347,0.002070,0.000819,0.020813,12.300418,0.626613,0.208134,-1214.730347,0.021776,0.000000
15.950001,2.856842,-1214.685791,0.002052,0.000840,0.021342,12.707868,0.647370,0.213425,-1214.685791,0.022175,0.000000
16.190001,2.907486,-1214.685791,0.002048,0.000856,0.021741,12.933144,0.658846,0.217414,-1214.685791,0.022583,0.000000
16.430000,2.918289,-1214.819214,0.002095,0.000868,0.022036,12.981198,0.661294,0.220362,-1214.819214,0.022982,0.000000
16.670000,2.976746,-1214.774780,0.002078,0.000883,0.022435,13.241226,0.674540,0.224352,-1214.774780,0.023380,0.000000
16.910002,3.079895,-1214.774780,0.002113,0.000902,0.022903,13.700057,0.697914,0.229034,-1214.774780,0.023779,0.000000
17.150002,3.130539,-1214.685791,0.002182,0.000918,0.023320,13.925333,0.709390,0.233197,-1214.685791,0.024178,0.000000
17.390001,3.104469,-1214.730347,0.002156,0.000929,0.023606,13.809369,0.703483,0.236059,-1214.730347,0.024577,0.000000
17.630001,3.266083,-1214.730347,0.002169,0.000952,0.024170,14.528262,0.740105,0.241696,-1214.730347,0.024976,0.000000
17.870001,3.298851,-1214.685791,0.002242,0.000965,0.024499,14.674022,0.747530,0.244992,-1214.685791,0.025384,0.000000
18.110001,3.329758,-1214.730347,0.002225,0.000979,0.024855,14.811502,0.754534,0.248547,-1214.730347,0.025783,0.000000
18.350000,3.345024,-1214.685791,0.002199,0.000992,0.025184,14.879411,0.757993,0.251843,-1214.685791,0.026182,0.000000
18.590000,3.467911,-1214.730347,0.002281,0.001011,0.025670,15.426038,0.785840,0.256699,-1214.730347,0.026580,0.000000
18.830002,3.572914,-1214.774780,0.002302,0.001029,0.026130,15.893116,0.809634,0.261295,-1214.774780,0.026979,0.000000
19.070002,3.617599,-1214.641357,0.002324,0.001044,0.026511,16.091887,0.819760,0.265111,-1214.641357,0.027378,0.000000
19.310001,3.582970,-1214.685791,0.002259,0.001057,0.026841,15.937845,0.811913,0.268407,-1214.685791,0.027777,0.000000
19.550001,3.654465,-1214.730347,0.002294,0.001071,0.027214,16.255871,0.828114,0.272136,-1214.730347,0.028176,0.000000
19.790001,3.743835,-1214.730347,0.002333,0.001087,0.027612,16.653412,0.848365,0.276125,-1214.730347,0.028584,0.000000
20.030001,3.773994,-1214.730347,0.002337,0.001096,0.027847,16.787565,0.855199,0.278467,-1214.730347,0.028983,0.000000
20.270000,3.881989,-1214.596802,0.002350,0.001114,0.028306,17.267948,0.879671,0.283063,-1214.596802,0.029382,0.000000
20.510000,3.976196,-1214.774780,0.002328,0.001130,0.028697,17.687004,0.901019,0.286965,-1214.774780,0.029781,0.000000
20.750002,4.091629,-1214.685791,0.002410,0.001149,0.029182,18.200476,0.927176,0.291822,-1214.685791,0.030179,0.000000
20.990002,4.128868,-1214.774780,0.002440,0.001165,0.029598,18.366123,0.935615,0.295984,-1214.774780,0.030578,0.000000
21.230001,4.097961,-1214.819214,0.002449,0.001177,0.029893,18.228643,0.928611,0.298933,-1214.819214,0.030977,0.000000
21.470001,4.177650,-1214.730347,0.002466,0.001195,0.030353,18.583117,0.946669,0.303529,-1214.730347,0.031376,0.000000
21.710001,4.218613,-1214.730347,0.002449,0.001208,0.030674,18.765326,0.955951,0.306738,-1214.730347,0.031784,0.000000
21.950001,4.397720,-1214.730347,0.002445,0.001230,0.031246,19.562037,0.996538,0.312462,-1214.730347,0.032183,0.000000
22.190001,4.360481,-1214.730347,0.002488,0.001239,0.031463,19.396389,0.988099,0.314630,-1214.730347,0.032582,0.000000
22.430000,4.503845,-1214.774780,0.002458,0.001256,0.031897,20.034103,1.020586,0.318966,-1214.774780,0.032981,0.000000
22.670002,4.706421,-1214.730347,0.002492,0.001281,0.032547,20.935205,1.066490,0.325470,-1214.730347,0.033380,0.000000
22.910002,4.637527,-1214.774780,0.002505,0.001293,0.032851,20.628752,1.050879,0.328505,-1214.774780,0.033778,0.000000
23.150002,4.618164,-1214.685791,0.002535,0.001304,0.033119,20.542620,1.046491,0.331193,-1214.685791,0.034177,0.000000
23.390001,4.700836,-1214.730347,0.002522,0.001322,0.033570,20.910364,1.065225,0.335703,-1214.730347,0.034576,0.000000
23.630001,4.750359,-1214.774780,0.002604,0.001335,0.033917,21.130650,1.076447,0.339172,-1214.774780,0.034984,0.000000
23.870001,4.850899,-1214.730347,0.002587,0.001349,0.034273,21.577875,1.099229,0.342728,-1214.730347,0.035383,0.000000
24.110001,4.961868,-1214.774780,0.002604,0.001368,0.034741,22.071493,1.124375,0.347411,-1214.774780,0.035782,0.000000
24.350000,4.922768,-1214.774780,0.002665,0.001378,0.035001,21.897564,1.115515,0.350012,-1214.774780,0.036181,0.000000
24.590002,5.242264,-1214.774780,0.002647,0.001402,0.035608,23.318754,1.187914,0.356083,-1214.774780,0.036580,0.000000
24.830002,5.308914,-1214.685791,0.002708,0.001422,0.036120,23.615231,1.203017,0.361200,-1214.685791,0.036979,0.000000
25.070002,5.244865,-1214.730347,0.002721,0.001436,0.036476,23.330326,1.188503,0.364756,-1214.730347,0.037377,0.000000
25.310001,5.284714,-1214.774780,0.002673,0.001450,0.036840,23.507582,1.197533,0.368398,-1214.774780,0.037776,0.000000
25.550001,5.332748,-1214.685791,0.002673,0.001464,0.037195,23.721251,1.208418,0.371953,-1214.685791,0.038184,0.000000
25.790001,5.530853,-1214.730347,0.002699,0.001484,0.037681,24.602465,1.253309,0.376810,-1214.730347,0.038583,0.000000
26.030001,5.518562,-1214.774780,0.002712,0.001495,0.037984,24.547791,1.250524,0.379845,-1214.774780,0.038982,0.000000
26.270000,5.591179,-1214.819214,0.002759,0.001511,0.038383,24.870806,1.266979,0.383834,-1214.819214,0.039381,0.000000
26.510002,5.765816,-1214.819214,0.002798,0.001532,0.038912,25.647629,1.306553,0.389125,-1214.819214,0.039780,0.000000
26.750002,5.800446,-1214.774780,0.002846,0.001544,0.039225,25.801670,1.314400,0.392246,-1214.774780,0.040179,0.000000
26.990002,5.848854,-1214.730347,0.002772,0.001561,0.039641,26.017002,1.325369,0.396409,-1214.730347,0.040578,0.000000
27.230001,5.966530,-1214.863770,0.002807,0.001577,0.040057,26.540451,1.352035,0.400572,-1214.863770,0.040976,0.000000
27.470001,5.982910,-1214.730347,0.002850,0.001590,0.040387,26.613314,1.355747,0.403867,-1214.730347,0.041384,0.000000
27.710001,6.178780,-1214.774780,0.002841,0.001608,0.040846,27.484585,1.400131,0.408464,-1214.774780,0.041783,0.000000
27.950001,6.221977,-1214.730347,0.002859,0.001622,0.041193,27.676737,1.409920,0.411932,-1214.730347,0.042182,0.000000
28.190001,5.982536,-1214.685791,0.002910,0.001628,0.041341,26.611650,1.355662,0.413407,-1214.685791,0.042581,0.000000
28.430002,6.440186,-1214.819214,0.002928,0.001654,0.042000,28.647377,1.459367,0.419997,-1214.819214,0.042980,0.000000
28.670002,6.599564,-1214.730347,0.002902,0.001674,0.042520,29.356325,1.495482,0.425201,-1214.730347,0.043379,0.000000
28.910002,6.572380,-1214.819214,0.002958,0.001686,0.042832,29.235407,1.489323,0.428323,-1214.819214,0.043778,0.000000
29.150002,6.675522,-1214.730347,0.002932,0.001704,0.043283,29.694204,1.512695,0.432833,-1214.730347,0.044176,0.000000
29.390001,6.778671,-1214.774780,0.003001,0.001721,0.043708,30.153036,1.536069,0.437082,-1214.774780,0.044584,0.000000
29.630001,6.827080,-1214.730347,0.002975,0.001735,0.044064,30.368368,1.547038,0.440637,-1214.730347,0.044983,0.000000
29.870001,6.918312,-1214.774780,0.002979,0.001749,0.044419,30.774189,1.567712,0.444193,-1214.774780,0.045382,0.000000
30.110001,6.836388,-1214.774780,0.003009,0.001760,0.044697,30.409771,1.549147,0.446968,-1214.774780,0.045781,0.000000
30.350002,7.217697,-1214.730347,0.003061,0.001782,0.045269,32.105919,1.635554,0.452692,-1214.730347,0.046180,0.000000
30.590002,7.212860,-1214.774780,0.003074,0.001796,0.045607,32.084404,1.634457,0.456074,-1214.774780,0.046579,0.000000
30.830002,7.217323,-1214.774780,0.003074,0.001809,0.045954,32.104256,1.635469,0.459543,-1214.774780,0.046978,0.000000
31.070002,7.388618,-1214.774780,0.003065,0.001827,0.046414,32.866215,1.674285,0.464139,-1214.774780,0.047385,0.000000
31.310001,7.409096,-1214.730347,0.003104,0.001841,0.046752,32.957302,1.678925,0.467522,-1214.730347,0.047784,0.000000
31.550001,7.623581,-1214.819214,0.003122,0.001860,0.047238,33.911381,1.727528,0.472378,-1214.819214,0.048183,0.000000
31.790001,7.454529,-1214.774780,0.003109,0.001865,0.047377,33.159401,1.689220,0.473766,-1214.774780,0.048582,0.000000
32.030003,7.496231,-1214.774780,0.003160,0.001880,0.047758,33.344902,1.698670,0.477581,-1214.774780,0.048981,0.000000
32.270000,7.856316,-1214.774780,0.003169,0.001903,0.048339,34.946636,1.780267,0.483392,-1214.774780,0.049380,0.000000
32.510002,8.019417,-1214.774780,0.003208,0.001921,0.048781,35.672146,1.817226,0.487815,-1214.774780,0.049779,0.000000
32.750000,8.149750,-1214.730347,0.003186,0.001938,0.049224,36.251896,1.846760,0.492237,-1214.730347,0.050178,0.000000
32.990002,8.219383,-1214.730347,0.003225,0.001954,0.049640,36.561642,1.862539,0.496400,-1214.730347,0.050585,0.000000
33.230003,8.185867,-1214.774780,0.003247,0.001967,0.049952,36.412556,1.854944,0.499522,-1214.774780,0.050984,0.000000
33.470001,8.554146,-1214.730347,0.003212,0.001986,0.050447,38.050739,1.938397,0.504465,-1214.730347,0.051383,0.000000
33.710003,8.605156,-1214.819214,0.003264,0.002002,0.050854,38.277645,1.949956,0.508541,-1214.819214,0.051782,0.000000
33.950001,8.572762,-1214.730347,0.003277,0.002014,0.051158,38.133549,1.942616,0.511577,-1214.730347,0.052181,0.000000
34.190002,8.698250,-1214.730347,0.003290,0.002028,0.051505,38.691746,1.971052,0.515046,-1214.730347,0.052580,0.000000
34.430000,9.011047,-1214.774780,0.003298,0.002049,0.052034,40.083141,2.041933,0.520336,-1214.774780,0.052979,0.000000
34.670002,8.964127,-1214.730347,0.003303,0.002063,0.052389,39.874428,2.031300,0.523891,-1214.730347,0.053378,0.000000
34.910000,9.044930,-1214.774780,0.003341,0.002076,0.052736,40.233856,2.049610,0.527360,-1214.774780,0.053785,0.000000
35.150002,9.098923,-1214.774780,0.003359,0.002090,0.053092,40.474030,2.061846,0.530916,-1214.774780,0.054184,0.000000
35.390003,9.574440,-1214.774780,0.003363,0.002113,0.053681,42.589237,2.169599,0.536813,-1214.774780,0.054583,0.000000
35.630001,9.560295,-1214.819214,0.003393,0.002128,0.054063,42.526318,2.166394,0.540629,-1214.819214,0.054982,0.000000
35.870003,9.543907,-1214.774780,0.003397,0.002141,0.054375,42.453419,2.162680,0.543751,-1214.774780,0.055381,0.000000
36.110001,9.674988,-1214.819214,0.003385,0.002157,0.054791,43.036495,2.192384,0.547913,-1214.819214,0.055780,0.000000
36.350002,9.961342,-1214.730347,0.003406,0.002176,0.055260,44.310261,2.257272,0.552597,-1214.730347,0.056179,0.000000
36.590000,9.952026,-1214.819214,0.003436,0.002189,0.055598,44.268826,2.255162,0.555978,-1214.819214,0.056578,0.000000
36.830002,10.041771,-1214.774780,0.003488,0.002203,0.055953,44.668030,2.275498,0.559534,-1214.774780,0.056985,0.000000
37.070004,10.212692,-1214.774780,0.003449,0.002219,0.056352,45.428326,2.314229,0.563524,-1214.774780,0.057384,0.000000
37.310001,10.677780,-1214.863770,0.003462,0.002242,0.056951,47.497139,2.419620,0.569507,-1214.863770,0.057783,0.000000
37.550003,10.669594,-1214.819214,0.003523,0.002257,0.057324,47.460724,2.417764,0.573237,-1214.819214,0.058182,0.000000
37.790001,10.808487,-1214.819214,0.003531,0.002273,0.057723,48.078552,2.449238,0.577226,-1214.819214,0.058581,0.000000
38.030003,10.739594,-1214.730347,0.003557,0.002283,0.058000,47.772099,2.433627,0.580001,-1214.730347,0.058980,0.000000
38.270000,11.117554,-1214.774780,0.003557,0.002304,0.058529,49.453350,2.519274,0.585291,-1214.774780,0.059379,0.000000
38.510002,11.136543,-1214.774780,0.003557,0.002318,0.058867,49.537819,2.523577,0.588673,-1214.774780,0.059778,0.000000
38.750000,11.123138,-1214.819214,0.003609,0.002330,0.059188,49.478191,2.520539,0.591882,-1214.819214,0.060185,0.000000
38.990002,11.586372,-1214.819214,0.003609,0.002351,0.059717,51.538757,2.625510,0.597172,-1214.819214,0.060584,0.000000
39.230003,11.665688,-1214.819214,0.003617,0.002366,0.060099,51.891571,2.643482,0.600987,-1214.819214,0.060983,0.000000
39.470001,11.721169,-1214.819214,0.003617,0.002379,0.060428,52.138363,2.656055,0.604283,-1214.819214,0.061382,0.000000
39.710003,11.673882,-1214.819214,0.003660,0.002390,0.060714,51.928017,2.645339,0.607145,-1214.819214,0.061781,0.000000
39.950001,12.170998,-1214.774780,0.003695,0.002410,0.061209,54.139301,2.757987,0.612088,-1214.774780,0.062180,0.000000
40.190002,12.432030,-1214.819214,0.003639,0.002429,0.061703,55.300430,2.817138,0.617031,-1214.819214,0.062579,0.000000
40.430000,12.463310,-1214.863770,0.003712,0.002443,0.062041,55.439571,2.824226,0.620413,-1214.863770,0.062978,0.000000
40.670002,12.537415,-1214.774780,0.003678,0.002459,0.062466,55.769207,2.841019,0.624663,-1214.774780,0.063386,0.000000
40.910004,12.569809,-1214.908203,0.003704,0.002470,0.062735,55.913303,2.848359,0.627351,-1214.908203,0.063784,0.000000
41.150002,12.903450,-1214.819214,0.003721,0.002488,0.063186,57.397411,2.923964,0.631861,-1214.819214,0.064183,0.000000
41.390003,12.913506,-1214.774780,0.003717,0.002498,0.063438,57.442142,2.926242,0.634376,-1214.774780,0.064582,0.000000
41.630001,13.127991,-1214.908203,0.003781,0.002513,0.063828,58.396217,2.974845,0.638279,-1214.908203,0.064981,0.000000
41.870003,13.391258,-1214.774780,0.003794,0.002528,0.064218,59.567291,3.034503,0.642181,-1214.774780,0.065380,0.000000
42.110001,13.738312,-1214.819214,0.003777,0.002548,0.064721,61.111061,3.113146,0.647211,-1214.819214,0.065779,0.000000
42.350002,13.951683,-1214.819214,0.003794,0.002569,0.065250,62.060184,3.161496,0.652501,-1214.819214,0.066178,0.000000
42.590000,13.955032,-1214.819214,0.003807,0.002582,0.065571,62.075085,3.162256,0.655709,-1214.819214,0.066586,0.000000
42.830002,14.179947,-1214.819214,0.003816,0.002598,0.065996,63.075554,3.213222,0.659959,-1214.819214,0.066985,0.000000
43.070004,14.157234,-1214.819214,0.003829,0.002610,0.066282,62.974522,3.208075,0.662821,-1214.819214,0.067383,0.000000
43.310001,14.740738,-1214.863770,0.003829,0.002630,0.066811,65.570076,3.340299,0.668111,-1214.863770,0.067782,0.000000
43.550003,14.537796,-1214.819214,0.003859,0.002637,0.066985,64.667343,3.294312,0.669846,-1214.819214,0.068181,0.000000
43.790001,14.978310,-1214.863770,0.003902,0.002656,0.067461,66.626846,3.394133,0.674615,-1214.863770,0.068580,0.000000
44.030003,15.723427,-1214.819214,0.003863,0.002682,0.068121,69.941292,3.562979,0.681206,-1214.819214,0.068979,0.000000
44.270000,15.648209,-1214.863770,0.003923,0.002694,0.068424,69.606705,3.545935,0.684241,-1214.863770,0.069387,0.000000
44.510002,15.535751,-1214.863770,0.003958,0.002706,0.068745,69.106476,3.520452,0.687450,-1214.863770,0.069786,0.000000
44.750004,15.873497,-1214.730347,0.003967,0.002723,0.069170,70.608841,3.596986,0.691700,-1214.730347,0.070185,0.000000
44.990002,15.905518,-1214.819214,0.003962,0.002734,0.069456,70.751274,3.604242,0.694561,-1214.819214,0.070584,0.000000
45.230003,16.307312,-1214.774780,0.004010,0.002753,0.069916,72.538544,3.695290,0.699158,-1214.774780,0.070982,0.000000
45.470001,16.501320,-1214.730347,0.003997,0.002767,0.070271,73.401535,3.739253,0.702713,-1214.730347,0.071381,0.000000
45.710003,16.701279,-1214.863770,0.004005,0.002781,0.070627,74.291000,3.784564,0.706269,-1214.863770,0.071780,0.000000
45.950001,17.254250,-1214.730347,0.004014,0.002804,0.071225,76.750732,3.909869,0.712253,-1214.730347,0.072179,0.000000
46.190002,17.556618,-1214.819214,0.004005,0.002821,0.071650,78.095734,3.978386,0.716502,-1214.819214,0.072587,0.000000
46.430000,17.676895,-1214.774780,0.004083,0.002839,0.072110,78.630760,4.005641,0.721098,-1214.774780,0.072986,0.000000
46.670002,17.800522,-1214.819214,0.004087,0.002853,0.072465,79.180679,4.033656,0.724654,-1214.819214,0.073385,0.000000
46.910004,18.015755,-1214.863770,0.004100,0.002870,0.072890,80.138077,4.082428,0.728904,-1214.863770,0.073784,0.000000
47.150002,18.308067,-1214.774780,0.004135,0.002883,0.073237,81.438354,4.148667,0.732372,-1214.774780,0.074183,0.000000
47.390003,18.478241,-1214.863770,0.004096,0.002897,0.073584,82.195320,4.187229,0.735841,-1214.863770,0.074581,0.000000
47.630001,18.810028,-1214.819214,0.004161,0.002915,0.074035,83.671181,4.262413,0.740351,-1214.819214,0.074980,0.000000
47.870003,19.332092,-1214.774780,0.004130,0.002934,0.074529,85.993439,4.380715,0.745294,-1214.774780,0.075379,0.000000
48.110001,19.508972,-1214.863770,0.004174,0.002948,0.074876,86.780243,4.420796,0.748763,-1214.863770,0.075787,0.000000
48.350002,19.763672,-1214.819214,0.004161,0.002965,0.075310,87.913200,4.478512,0.753099,-1214.819214,0.076186,0.000000
48.590004,19.958046,-1214.863770,0.004221,0.002980,0.075683,88.777824,4.522558,0.756828,-1214.863770,0.076585,0.000000
48.830002,20.117798,-1214.819214,0.004247,0.002993,0.076012,89.488434,4.558758,0.760123,-1214.819214,0.076984,0.000000
49.070004,20.506180,-1214.819214,0.004225,0.003009,0.076437,91.216042,4.646767,0.764373,-1214.819214,0.077383,0.000000
49.310001,20.613426,-1214.908203,0.004225,0.003020,0.076706,91.693100,4.671069,0.767061,-1214.908203,0.077781,0.000000
49.550003,20.920631,-1214.819214,0.004212,0.003038,0.077157,93.059616,4.740683,0.771571,-1214.819214,0.078180,0.000000
49.790001,21.743576,-1214.863770,0.004303,0.003062,0.077773,96.720261,4.927165,0.777728,-1214.863770,0.078579,0.000000
50.030003,21.935349,-1214.863770,0.004264,0.003073,0.078050,97.573303,4.970621,0.780504,-1214.863770,0.078987,0.000000
50.270004,22.054131,-1214.819214,0.004333,0.003089,0.078458,98.101669,4.997538,0.784579,-1214.819214,0.079386,0.000000
50.510002,22.543434,-1214.863770,0.004286,0.003107,0.078926,100.278206,5.108415,0.789262,-1214.863770,0.079785,0.000000
50.750004,22.861435,-1214.863770,0.004324,0.003123,0.079316,101.692741,5.180475,0.793165,-1214.863770,0.080184,0.000000
50.990002,22.928467,-1214.863770,0.004307,0.003136,0.079646,101.990913,5.195665,0.796460,-1214.863770,0.080583,0.000000
51.230003,23.201416,-1214.908203,0.004368,0.003149,0.079976,103.205055,5.257516,0.799756,-1214.908203,0.080982,0.000000
51.470001,23.292648,-1214.819214,0.004376,0.003161,0.080288,103.610878,5.278189,0.802878,-1214.819214,0.081380,0.000000
51.710003,24.164368,-1214.819214,0.004398,0.003183,0.080843,107.488472,5.475724,0.808428,-1214.819214,0.081779,0.000000
51.950001,24.360985,-1214.908203,0.004402,0.003197,0.081207,108.363075,5.520278,0.812070,-1214.908203,0.082187,0.000000
52.190002,24.556107,-1214.908203,0.004411,0.003210,0.081545,109.231018,5.564494,0.815452,-1214.908203,0.082586,0.000000
52.430004,24.989174,-1214.819214,0.004393,0.003226,0.081944,111.157394,5.662628,0.819442,-1214.819214,0.082985,0.000000
52.670002,25.298241,-1214.863770,0.004393,0.003244,0.082404,112.532196,5.732664,0.824038,-1214.863770,0.083384,0.000000
52.910004,25.856804,-1214.908203,0.004458,0.003260,0.082811,115.016808,5.859235,0.828114,-1214.908203,0.083783,0.000000
53.150002,25.960320,-1214.908203,0.004411,0.003272,0.083115,115.477272,5.882692,0.831149,-1214.908203,0.084182,0.000000
53.390003,26.314072,-1214.908203,0.004467,0.003287,0.083496,117.050835,5.962854,0.834965,-1214.908203,0.084581,0.000000
53.630001,26.969078,-1214.908203,0.004454,0.003306,0.083965,119.964447,6.111280,0.839648,-1214.908203,0.084979,0.000000
53.870003,27.430817,-1214.908203,0.004475,0.003322,0.084390,122.018364,6.215912,0.843898,-1214.908203,0.085387,0.000000
54.110004,27.790161,-1214.952637,0.004506,0.003339,0.084806,123.616814,6.297340,0.848060,-1214.952637,0.085786,0.000000
54.350002,28.264938,-1214.863770,0.004493,0.003354,0.085196,125.728722,6.404927,0.851963,-1214.863770,0.086185,0.000000
54.590004,28.315948,-1214.908203,0.004536,0.003366,0.085508,125.955627,6.416486,0.855085,-1214.908203,0.086584,0.000000
54.830002,29.122879,-1214.908203,0.004583,0.003386,0.085994,129.545029,6.599339,0.859941,-1214.908203,0.086983,0.000000
55.070004,29.474770,-1214.908203,0.004579,0.003401,0.086393,131.110321,6.679079,0.863931,-1214.908203,0.087382,0.000000
55.310001,29.584251,-1214.908203,0.004575,0.003413,0.086688,131.597321,6.703887,0.866879,-1214.908203,0.087781,0.000000
55.550003,30.005775,-1214.863770,0.004613,0.003429,0.087095,133.472351,6.799406,0.870955,-1214.863770,0.088180,0.000000
55.790001,30.745682,-1214.863770,0.004592,0.003449,0.087599,136.763626,6.967071,0.875985,-1214.863770,0.088587,0.000000
56.030003,31.032410,-1214.863770,0.004596,0.003463,0.087963,138.039047,7.032045,0.879627,-1214.863770,0.088986,0.000000
56.270004,31.420792,-1214.952637,0.004600,0.003477,0.088318,139.766663,7.120053,0.883183,-1214.952637,0.089385,0.000000
56.510002,31.687782,-1214.952637,0.004678,0.003490,0.088639,140.954300,7.180554,0.886392,-1214.952637,0.089784,0.000000
56.750004,32.783676,-1214.908203,0.004652,0.003514,0.089264,145.829071,7.428887,0.892636,-1214.908203,0.090183,0.000000
56.990002,33.098701,-1214.908203,0.004682,0.003528,0.089610,147.230377,7.500273,0.896105,-1214.908203,0.090582,0.000000
57.230003,33.262177,-1214.952637,0.004708,0.003540,0.089923,147.957550,7.537317,0.899227,-1214.952637,0.090981,0.000000
57.470001,33.644226,-1214.863770,0.004682,0.003555,0.090304,149.656998,7.623890,0.903042,-1214.863770,0.091388,0.000000
57.710003,34.391205,-1214.952637,0.004708,0.003574,0.090790,152.979721,7.793159,0.907899,-1214.952637,0.091787,0.000000
57.950005,34.833214,-1214.863770,0.004760,0.003589,0.091163,154.945877,7.893319,0.911628,-1214.863770,0.092186,0.000000
58.190002,35.276711,-1214.908203,0.004708,0.003604,0.091536,156.918640,7.993817,0.915357,-1214.908203,0.092585,0.000000
58.430004,35.743660,-1214.863770,0.004760,0.003619,0.091935,158.995743,8.099629,0.919346,-1214.863770,0.092984,0.000000
58.670002,36.798965,-1214.863770,0.004760,0.003642,0.092507,163.689972,8.338765,0.925070,-1214.863770,0.093383,0.000000
58.910004,37.290123,-1214.863770,0.004803,0.003657,0.092897,165.874756,8.450063,0.928972,-1214.863770,0.093782,0.000000
59.150002,37.734367,-1214.908203,0.004786,0.003672,0.093270,167.850845,8.550730,0.932701,-1214.908203,0.094181,0.000000
59.390003,37.908264,-1214.908203,0.004777,0.003687,0.093652,168.624374,8.590136,0.936517,-1214.908203,0.094588,0.000000
59.630001,38.800468,-1214.908203,0.004803,0.003704,0.094094,172.593109,8.792312,0.940940,-1214.908203,0.094987,0.000000
59.870003,39.150497,-1214.908203,0.004833,0.003717,0.094424,174.150116,8.871630,0.944236,-1214.908203,0.095386,0.000000
60.110004,39.402222,-1214.908203,0.004850,0.003731,0.094770,175.269836,8.928671,0.947705,-1214.908203,0.095785,0.000000
60.350002,40.387520,-1214.863770,0.004855,0.003750,0.095247,179.652664,9.151943,0.952474,-1214.863770,0.096184,0.000000
60.590004,40.966934,-1214.997192,0.004876,0.003766,0.095646,182.230026,9.283239,0.956463,-1214.997192,0.096583,0.000000
60.830002,41.187752,-1214.952637,0.004911,0.003779,0.095976,183.212265,9.333278,0.959759,-1214.952637,0.096982,0.000000
61.070004,41.635338,-1214.908203,0.004919,0.003792,0.096314,185.203232,9.434702,0.963141,-1214.908203,0.097381,0.000000
61.310001,42.590477,-1214.952637,0.004937,0.003812,0.096817,189.451904,9.651140,0.968171,-1214.952637,0.097788,0.000000
61.550003,43.443207,-1214.908203,0.004894,0.003830,0.097277,193.245041,9.844372,0.972767,-1214.908203,0.098187,0.000000
61.790005,43.096901,-1214.908203,0.004941,0.003833,0.097346,191.704590,9.765897,0.973461,-1214.908203,0.098586,0.000000
62.030003,44.465370,-1214.908203,0.004980,0.003858,0.098005,197.791840,10.075996,0.980052,-1214.908203,0.098985,0.000000
62.270004,44.694756,-1214.863770,0.004928,0.003869,0.098265,198.812195,10.127976,0.982654,-1214.863770,0.099384,0.000000
62.510002,45.583237,-1214.908203,0.004967,0.003888,0.098760,202.764359,10.329309,0.987597,-1214.908203,0.099783,0.000000
62.750004,46.008858,-1214.908203,0.004928,0.003900,0.099063,204.657623,10.425756,0.990632,-1214.908203,0.100182,0.000000
62.990002,46.476929,-1214.908203,0.005001,0.003915,0.099445,206.739700,10.531822,0.994448,-1214.908203,0.100581,0.000000
63.230003,47.230980,-1214.908203,0.004975,0.003934,0.099930,210.093887,10.702693,0.999305,-1214.908203,0.100988,0.000000
63.470001,48.099724,-1214.863770,0.005006,0.003950,0.100338,213.958252,10.899553,1.003380,-1214.863770,0.101387,0.000000
63.710003,49.030655,-1214.997192,0.005023,0.003967,0.100763,218.099243,11.110505,1.007630,-1214.997192,0.101786,0.000000
63.950005,49.389252,-1214.908203,0.005040,0.003980,0.101101,219.694366,11.191764,1.011012,-1214.908203,0.102185,0.000000
64.190002,50.137352,-1214.908203,0.005014,0.003997,0.101526,223.022079,11.361286,1.015261,-1214.908203,0.102584,0.000000
64.430000,50.482162,-1214.997192,0.005010,0.004011,0.101873,224.555878,11.439422,1.018730,-1214.997192,0.102983,0.000000
64.670006,51.799988,-1214.908203,0.005057,0.004030,0.102359,230.417847,11.738045,1.023587,-1214.908203,0.103382,0.000000
64.910004,51.816002,-1214.952637,0.005040,0.004037,0.102532,230.489090,11.741673,1.025321,-1214.952637,0.103781,0.000000
65.150002,52.718262,-1214.863770,0.005118,0.004056,0.103018,234.502533,11.946129,1.030177,-1214.863770,0.104189,0.000000
65.389999,54.121361,-1214.952637,0.005079,0.004080,0.103642,240.743835,12.264075,1.036422,-1214.952637,0.104587,0.000000
65.630005,54.705612,-1214.997192,0.005101,0.004093,0.103963,243.342712,12.396469,1.039630,-1214.997192,0.104986,0.000000
65.870003,54.958084,-1214.908203,0.005126,0.004104,0.104249,244.465775,12.453680,1.042492,-1214.908203,0.105385,0.000000
66.110001,55.749748,-1214.997192,0.005126,0.004122,0.104692,247.987259,12.633074,1.046915,-1214.997192,0.105784,0.000000
66.350006,56.350380,-1214.908203,0.005131,0.004133,0.104978,250.659012,12.769178,1.049777,-1214.908203,0.106183,0.000000
66.590004,57.415367,-1214.952637,0.005113,0.004151,0.105437,255.396301,13.010508,1.054373,-1214.952637,0.106582,0.000000
66.830002,58.091972,-1214.952637,0.005148,0.004165,0.105793,258.406006,13.163829,1.057929,-1214.952637,0.106981,0.000000
67.070000,58.736176,-1214.863770,0.005144,0.004181,0.106192,261.271545,13.309808,1.061918,-1214.863770,0.107389,0.000000
67.310005,59.583321,-1214.952637,0.005208,0.004194,0.106530,265.039856,13.501774,1.065300,-1214.952637,0.107788,0.000000
67.550003,61.298843,-1214.908203,0.005182,0.004219,0.107172,272.670868,13.890516,1.071718,-1214.908203,0.108186,0.000000
67.790001,62.108009,-1214.997192,0.005200,0.004237,0.107631,276.270233,14.073876,1.076314,-1214.997192,0.108585,0.000000
68.030006,62.690765,-1214.952637,0.005234,0.004251,0.107978,278.862457,14.205931,1.079783,-1214.952637,0.108984,0.000000
68.270004,63.450043,-1214.908203,0.005217,0.004268,0.108412,282.239899,14.377986,1.084119,-1214.908203,0.109383,0.000000
68.510002,64.336288,-1214.952637,0.005208,0.004283,0.108776,286.182098,14.578811,1.087761,-1214.952637,0.109782,0.000000
68.750000,65.073959,-1214.908203,0.005256,0.004295,0.109106,289.463440,14.745970,1.091057,-1214.908203,0.110181,0.000000
68.990005,66.032440,-1214.952637,0.005290,0.004315,0.109591,293.726959,14.963164,1.095914,-1214.952637,0.110589,0.000000
69.230003,67.190521,-1214.997192,0.005256,0.004331,0.109999,298.878357,15.225590,1.099989,-1214.997192,0.110988,0.000000
69.470001,66.968582,-1214.952637,0.005295,0.004329,0.109956,297.891144,15.175297,1.099555,-1214.952637,0.110146,0.000000
69.710007,66.356781,-1214.952637,0.005316,0.004329,0.109947,295.169708,15.036661,1.099469,-1214.952637,0.109947,0.000000
69.950005,65.840668,-1214.908203,0.005325,0.004328,0.109938,292.873932,14.919708,1.099382,-1214.908203,0.109947,0.000000
70.190002,65.413925,-1214.952637,0.005269,0.004328,0.109930,290.975677,14.823008,1.099295,-1214.952637,0.109947,0.000000
70.430000,65.050873,-1214.952637,0.005277,0.004328,0.109930,289.360748,14.740739,1.099295,-1214.952637,0.109947,0.000000
70.670006,64.720200,-1214.908203,0.005286,0.004328,0.109930,287.889832,14.665807,1.099295,-1214.908203,0.109947,0.000000
70.910004,64.453583,-1214.997192,0.005290,0.004328,0.109930,286.703857,14.605391,1.099295,-1214.997192,0.109947,0.000000
71.150002,64.205200,-1214.952637,0.005303,0.004328,0.109921,285.598999,14.549107,1.099209,-1214.952637,0.109947,0.000000
71.390007,63.972107,-1214.908203,0.005303,0.004328,0.109921,284.562134,14.496286,1.099209,-1214.908203,0.109947,0.000000
71.630005,63.765808,-1214.908203,0.005269,0.004328,0.109921,283.644470,14.449539,1.099209,-1214.908203,0.109947,0.000000
71.870003,63.565094,-1214.952637,0.005307,0.004328,0.109921,282.751648,14.404057,1.099209,-1214.952637,0.109947,0.000000
72.110001,63.396790,-1215.041626,0.005282,0.004328,0.109921,282.002991,14.365917,1.099209,-1215.041626,0.109947,0.000000
72.350006,63.233688,-1214.952637,0.005351,0.004328,0.109921,281.277496,14.328959,1.099209,-1214.952637,0.109947,0.000000
72.590004,63.077667,-1214.908203,0.005307,0.004328,0.109921,280.583466,14.293604,1.099209,-1214.908203,0.109947,0.000000
72.830002,62.938766,-1214.997192,0.005333,0.004328,0.109921,279.965607,14.262128,1.099209,-1214.997192,0.109947,0.000000
73.070000,62.808441,-1214.908203,0.005346,0.004328,0.109921,279.385895,14.232596,1.099209,-1214.908203,0.109947,0.000000
73.310005,62.665817,-1214.997192,0.005290,0.004328,0.109921,278.751465,14.200277,1.099209,-1214.997192,0.109947,0.000000
73.550003,62.564537,-1214.952637,0.005320,0.004328,0.109921,278.300964,14.177326,1.099209,-1214.952637,0.109947,0.000000
73.790001,62.453568,-1214.952637,0.005320,0.004328,0.109921,277.807343,14.152181,1.099209,-1214.952637,0.109947,0.000000
74.030006,62.347443,-1215.041626,0.005342,0.004328,0.109921,277.335266,14.128132,1.099209,-1215.041626,0.109947,0.000000
74.270004,62.254349,-1214.952637,0.005338,0.004328,0.109921,276.921173,14.107037,1.099209,-1214.952637,0.109947,0.000000
74.510002,62.147102,-1215.041626,0.005333,0.004328,0.109921,276.444122,14.082735,1.099209,-1215.041626,0.109947,0.000000
74.750000,62.060341,-1214.908203,0.005346,0.004328,0.109921,276.058197,14.063075,1.099209,-1214.908203,0.109947,0.000000
74.990005,61.984749,-1214.997192,0.005351,0.004328,0.109921,275.721924,14.045944,1.099209,-1214.997192,0.109947,0.000000
75.230003,61.881607,-1214.908203,0.005320,0.004328,0.109921,275.263123,14.022573,1.099209,-1214.908203,0.109947,0.000000
75.470001,61.798195,-1214.952637,0.005359,0.004328,0.109921,274.892090,14.003671,1.099209,-1214.952637,0.109947,0.000000
75.710007,61.724838,-1215.041626,0.005303,0.004328,0.109921,274.565796,13.987048,1.099209,-1215.041626,0.109947,0.000000
75.950005,61.645515,-1215.041626,0.005264,0.004328,0.109921,274.212952,13.969073,1.099209,-1215.041626,0.109947,0.000000
76.190002,61.571793,-1214.952637,0.005299,0.004328,0.109921,273.885010,13.952368,1.099209,-1214.952637,0.109947,0.000000
76.430000,61.496941,-1214.997192,0.005286,0.004328,0.109921,273.552063,13.935406,1.099209,-1214.997192,0.109947,0.000000
76.670006,61.436615,-1214.952637,0.005338,0.004328,0.109921,273.283722,13.921736,1.099209,-1214.952637,0.109947,0.000000
76.910004,61.369965,-1215.041626,0.005320,0.004328,0.109921,272.987244,13.906632,1.099209,-1215.041626,0.109947,0.000000
77.150002,61.312248,-1214.997192,0.005286,0.004328,0.109921,272.730499,13.893555,1.099209,-1214.997192,0.109947,0.000000
77.390007,61.257133,-1215.086182,0.005303,0.004328,0.109921,272.485352,13.881065,1.099209,-1215.086182,0.109947,0.000000
77.630005,61.191223,-1215.041626,0.005342,0.004328,0.109921,272.192169,13.866129,1.099209,-1215.041626,0.109947,0.000000
77.870003,61.131645,-1215.041626,0.005325,0.004328,0.109921,271.927124,13.852629,1.099209,-1215.041626,0.109947,0.000000
78.110001,61.068718,-1215.041626,0.005333,0.004328,0.109921,271.647217,13.838369,1.099209,-1215.041626,0.109947,0.000000
78.350006,61.006531,-1215.041626,0.005307,0.004328,0.109921,271.370605,13.824278,1.099209,-1215.041626,0.109947,0.000000
78.590004,60.973763,-1214.952637,0.005338,0.004328,0.109921,271.224854,13.816852,1.099209,-1214.952637,0.109947,0.000000
78.830002,60.916786,-1214.997192,0.005320,0.004328,0.109921,270.971405,13.803942,1.099209,-1214.997192,0.109947,0.000000
79.070007,60.852364,-1215.041626,0.005351,0.004328,0.109921,270.684845,13.789342,1.099209,-1215.041626,0.109947,0.000000
79.310005,60.813263,-1215.086182,0.005346,0.004328,0.109921,270.510895,13.780482,1.099209,-1215.086182,0.109947,0.000000
79.550003,60.777519,-1215.041626,0.005355,0.004328,0.109921,270.351898,13.772383,1.099209,-1215.041626,0.109947,0.000000
79.790001,60.717567,-1214.997192,0.005295,0.004328,0.109921,270.085236,13.758797,1.099209,-1214.997192,0.109947,0.000000
80.030006,60.666550,-1215.086182,0.005295,0.004328,0.109921,269.858276,13.747236,1.099209,-1215.086182,0.109947,0.000000
80.270004,60.618889,-1214.952637,0.005290,0.004328,0.109921,269.646271,13.736437,1.099209,-1214.952637,0.109947,0.000000
80.510002,60.580536,-1214.997192,0.005329,0.004328,0.109921,269.475677,13.727745,1.099209,-1214.997192,0.109947,0.000000
80.750008,60.533989,-1215.086182,0.005325,0.004328,0.109921,269.268646,13.717198,1.099209,-1215.086182,0.109947,0.000000
80.990005,60.497864,-1214.997192,0.005325,0.004328,0.109921,269.107941,13.709012,1.099209,-1214.997192,0.109947,0.000000
81.230003,60.453552,-1215.041626,0.005346,0.004328,0.109921,268.910828,13.698971,1.099209,-1215.041626,0.109947,0.000000
81.470001,60.414085,-1214.952637,0.005355,0.004327,0.109912,268.735260,13.690027,1.099122,-1214.952637,0.109947,0.000000
81.710007,60.373871,-1215.086182,0.005351,0.004327,0.109912,268.556396,13.680915,1.099122,-1215.086182,0.109947,0.000000
81.950005,60.328438,-1215.086182,0.005320,0.004327,0.109912,268.354309,13.670619,1.099122,-1215.086182,0.109947,0.000000
82.190002,60.295670,-1214.997192,0.005303,0.004327,0.109912,268.208527,13.663194,1.099122,-1214.997192,0.109947,0.000000
82.430000,60.253593,-1215.086182,0.005364,0.004327,0.109912,268.021362,13.653659,1.099122,-1215.086182,0.109947,0.000000
82.670006,60.224174,-1214.997192,0.005333,0.004327,0.109912,267.890503,13.646993,1.099122,-1214.997192,0.109947,0.000000
82.910004,60.196991,-1214.997192,0.005381,0.004327,0.109912,267.769592,13.640833,1.099122,-1214.997192,0.109947,0.000000
83.150002,60.150070,-1215.086182,0.005342,0.004327,0.109912,267.560883,13.630200,1.099122,-1215.086182,0.109947,0.000000
83.390007,60.120651,-1215.041626,0.005312,0.004327,0.109912,267.430023,13.623534,1.099122,-1215.041626,0.109947,0.000000
83.630005,60.081558,-1215.086182,0.005295,0.004327,0.109912,267.256104,13.614676,1.099122,-1215.086182,0.109947,0.000000
83.870003,60.053627,-1214.997192,0.005316,0.004327,0.109912,267.131866,13.608346,1.099122,-1214.997192,0.109947,0.000000
84.110001,60.012291,-1215.041626,0.005307,0.004327,0.109912,266.947998,13.598980,1.099122,-1215.041626,0.109947,0.000000
84.350006,59.988464,-1215.041626,0.005325,0.004327,0.109912,266.842010,13.593580,1.099122,-1215.041626,0.109947,0.000000
84.590004,59.957558,-1214.952637,0.005316,0.004327,0.109912,266.704529,13.586576,1.099122,-1214.952637,0.109947,0.000000
84.830002,59.918831,-1215.041626,0.005307,0.004327,0.109912,266.532257,13.577801,1.099122,-1215.041626,0.109947,0.000000
85.070007,59.899094,-1214.952637,0.005346,0.004327,0.109912,266.444489,13.573329,1.099122,-1214.952637,0.109947,0.000000
85.310005,59.841377,-1215.041626,0.005290,0.004327,0.109912,266.187744,13.560250,1.099122,-1215.041626,0.109947,0.000000
85.550003,59.824615,-1215.041626,0.005359,0.004327,0.109912,266.113190,13.556452,1.099122,-1215.041626,0.109947,0.000000
85.790001,59.789612,-1214.908203,0.005376,0.004327,0.109912,265.957489,13.548519,1.099122,-1214.908203,0.109947,0.000000
86.030006,59.766525,-1214.997192,0.005355,0.004327,0.109912,265.854797,13.543288,1.099122,-1214.997192,0.109947,0.000000
86.270004,59.735992,-1214.952637,0.005325,0.004327,0.109912,265.718964,13.536369,1.099122,-1214.952637,0.109947,0.000000
86.510002,59.711418,-1214.997192,0.005364,0.004327,0.109912,265.609650,13.530801,1.099122,-1214.997192,0.109947,0.000000
86.750008,59.673805,-1215.041626,0.005351,0.004327,0.109912,265.442352,13.522277,1.099122,-1215.041626,0.109947,0.000000
86.990005,59.652206,-1214.908203,0.005342,0.004327,0.109912,265.346252,13.517383,1.099122,-1214.908203,0.109947,0.000000
87.230003,59.623909,-1214.997192,0.005312,0.004327,0.109912,265.220398,13.510971,1.099122,-1214.997192,0.109947,0.000000
87.470001,59.595612,-1214.997192,0.005359,0.004327,0.109912,265.094513,13.504559,1.099122,-1214.997192,0.109947,0.000000
87.710007,59.560982,-1214.997192,0.005325,0.004327,0.109912,264.940491,13.496712,1.099122,-1214.997192,0.109947,0.000000
87.950005,59.549805,-1215.041626,0.005320,0.004327,0.109912,264.890747,13.494179,1.099122,-1215.041626,0.109947,0.000000
88.190002,59.517410,-1214.997192,0.005355,0.004327,0.109912,264.746674,13.486837,1.099122,-1214.997192,0.109947,0.000000
88.430008,59.492836,-1215.041626,0.005359,0.004327,0.109912,264.637360,13.481269,1.099122,-1215.041626,0.109947,0.000000
88.670006,59.461929,-1214.997192,0.005359,0.004327,0.109912,264.499878,13.474266,1.099122,-1214.997192,0.109947,0.000000
88.910004,59.454109,-1214.997192,0.005342,0.004327,0.109912,264.465088,13.472494,1.099122,-1214.997192,0.109947,0.000000
89.150002,59.422081,-1214.952637,0.005359,0.004327,0.109912,264.322632,13.465236,1.099122,-1214.952637,0.109947,0.000000
89.390007,59.403091,-1214.952637,0.005320,0.004327,0.109912,264.238159,13.460933,1.099122,-1214.952637,0.109947,0.000000
89.630005,59.372932,-1215.041626,0.005325,0.004327,0.109912,264.104004,13.454100,1.099122,-1215.041626,0.109947,0.000000
89.870003,59.347237,-1214.952637,0.005346,0.004327,0.109912,263.989685,13.448277,1.099122,-1214.952637,0.109947,0.000000
90.110001,59.330109,-1215.041626,0.005333,0.004327,0.109912,263.913513,13.444394,1.099122,-1215.041626,0.109947,0.000000
90.350006,59.306274,-1215.041626,0.005368,0.004327,0.109912,263.807495,13.438993,1.099122,-1215.041626,0.109947,0.000000
90.590004,59.285797,-1215.041626,0.005307,0.004327,0.109912,263.716400,13.434354,1.099122,-1215.041626,0.109947,0.000000
90.830002,59.276489,-1215.041626,0.005342,0.004327,0.109912,263.674988,13.432244,1.099122,-1215.041626,0.109947,0.000000
91.070007,59.237762,-1214.997192,0.005329,0.004327,0.109912,263.502716,13.423469,1.099122,-1214.997192,0.109947,0.000000
91.310005,59.215042,-1214.997192,0.005312,0.004327,0.109912,263.401672,13.418321,1.099122,-1214.997192,0.109947,0.000000
91.550003,59.200897,-1215.086182,0.005338,0.004327,0.109912,263.338745,13.415114,1.099122,-1215.086182,0.109947,0.000000
91.790001,59.179298,-1214.952637,0.005338,0.004327,0.109912,263.242676,13.410220,1.099122,-1214.952637,0.109947,0.000000
92.030006,59.161423,-1215.041626,0.005329,0.004327,0.109912,263.163147,13.406170,1.099122,-1215.041626,0.109947,0.000000
92.270004,59.138336,-1215.041626,0.005338,0.004327,0.109912,263.060455,13.400939,1.099122,-1215.041626,0.109947,0.000000
92.510002,59.104820,-1215.041626,0.005351,0.004327,0.109912,262.911377,13.393344,1.099122,-1215.041626,0.109947,0.000000
92.750008,59.089180,-1215.086182,0.005381,0.004327,0.109912,262.841797,13.389799,1.099122,-1215.086182,0.109947,0.000000
92.990005,59.076897,-1214.997192,0.005338,0.004327,0.109912,262.787170,13.387016,1.099122,-1214.997192,0.109947,0.000000
93.230003,59.052315,-1215.041626,0.005303,0.004327,0.109912,262.677826,13.381446,1.099122,-1215.041626,0.109947,0.000000
93.470001,59.041893,-1215.041626,0.005320,0.004327,0.109912,262.631470,13.379085,1.099122,-1215.041626,0.109947,0.000000
93.710007,59.024017,-1214.997192,0.005312,0.004327,0.109912,262.551941,13.375033,1.099122,-1214.997192,0.109947,0.000000
93.950005,58.996834,-1214.997192,0.005329,0.004327,0.109912,262.431030,13.368874,1.099122,-1214.997192,0.109947,0.000000
94.190002,58.977470,-1214.997192,0.005381,0.004327,0.109912,262.344879,13.364487,1.099122,-1214.997192,0.109947,0.000000
94.430008,58.958107,-1215.041626,0.005316,0.004327,0.109912,262.258759,13.360098,1.099122,-1215.041626,0.109947,0.000000
94.670006,58.931671,-1215.041626,0.005368,0.004327,0.109912,262.141174,13.354108,1.099122,-1215.041626,0.109947,0.000000
94.910004,58.919380,-1214.997192,0.005325,0.004327,0.109912,262.086487,13.351322,1.099122,-1214.997192,0.109947,0.000000
95.150002,58.898529,-1215.086182,0.005338,0.004327,0.109912,261.993744,13.346597,1.099122,-1215.086182,0.109947,0.000000
95.390007,58.880653,-1214.952637,0.005342,0.004327,0.109912,261.914215,13.342546,1.099122,-1214.952637,0.109947,0.000000
95.630005,58.861290,-1215.041626,0.005333,0.004327,0.109912,261.828094,13.338159,1.099122,-1215.041626,0.109947,0.000000
95.870003,58.844536,-1214.997192,0.005316,0.004327,0.109912,261.753571,13.334362,1.099122,-1214.997192,0.109947,0.000000
96.110008,58.835228,-1214.997192,0.005355,0.004327,0.109912,261.712158,13.332253,1.099122,-1214.997192,0.109947,0.000000
96.350006,58.813995,-1215.086182,0.005325,0.004327,0.109912,261.617706,13.327442,1.099122,-1215.086182,0.109947,0.000000
96.590004,58.794632,-1214.997192,0.005381,0.004327,0.109912,261.531586,13.323054,1.099122,-1214.997192,0.109947,0.000000
96.830002,58.776764,-1215.041626,0.005320,0.004327,0.109912,261.452118,13.319005,1.099122,-1215.041626,0.109947,0.000000
97.070007,58.771545,-1215.041626,0.005351,0.004327,0.109912,261.428894,13.317822,1.099122,-1215.041626,0.109947,0.000000
97.310005,58.753304,-1215.086182,0.005338,0.004327,0.109912,261.347748,13.313689,1.099122,-1215.086182,0.109947,0.000000
97.550003,58.723511,-1215.041626,0.005359,0.004327,0.109912,261.215210,13.306938,1.099122,-1215.041626,0.109947,0.000000
97.790001,58.720909,-1214.952637,0.005359,0.004327,0.109912,261.203644,13.306348,1.099122,-1214.952637,0.109947,0.000000
98.030006,58.692978,-1214.997192,0.005355,0.004327,0.109912,261.079407,13.300018,1.099122,-1214.997192,0.109947,0.000000
98.270004,58.673241,-1215.041626,0.005376,0.004327,0.109912,260.991608,13.295547,1.099122,-1215.041626,0.109947,0.000000
98.510002,58.665047,-1214.997192,0.005316,0.004327,0.109912,260.955170,13.293689,1.099122,-1214.997192,0.109947,0.000000
98.750008,58.650528,-1214.997192,0.005333,0.004327,0.109912,260.890564,13.290400,1.099122,-1214.997192,0.109947,0.000000
98.990005,58.638237,-1214.952637,0.005389,0.004327,0.109912,260.835907,13.287615,1.099122,-1214.952637,0.109947,0.000000
99.230003,58.617760,-1215.041626,0.005364,0.004327,0.109912,260.744812,13.282974,1.099122,-1215.041626,0.109947,0.000000
99.470001,58.602119,-1215.041626,0.005351,0.004327,0.109912,260.675232,13.279429,1.099122,-1215.041626,0.109947,0.000000
99.700005,58.596161,-1215.041626,0.005329,0.004327,0.109912,260.648743,13.278080,1.099122,-1215.041626,0.109947,0.000000