File: Data/Symmetrical membranes compression/Durapore PVDF 5um test 2_10272023_145343.csv
Time (sec),S:Load (lbs),S:HL1 (DIM),S:LVDT (in),S:Position (in),Ch:Position (mm),Ch:Load (N),Ch:Stress (MPa),Ch:Strain (mm/mm),Ch:HL1 (DIM),Set Point (),Cycles ()
0.110000,0.008568,-1214.107544,0.000034,-0.000000,-0.000000,0.038112,0.001941,-0.000000,-1214.107544,0.000252,0.000000
0.350000,0.007454,-1214.018555,-0.000039,-0.000000,-0.000000,0.033157,0.001689,-0.000000,-1214.018555,0.000252,0.000000
0.590000,0.007454,-1214.196533,0.000017,0.000109,0.002775,0.033157,0.001689,0.027751,-1214.196533,0.003703,0.000000
0.830000,0.014900,-1214.107544,0.000082,0.000254,0.006452,0.066279,0.003376,0.064522,-1214.107544,0.007692,0.000000
1.070000,-0.000366,-1214.107544,0.000233,0.000413,0.010502,-0.001629,-0.000083,0.105021,-1214.107544,0.011699,0.000000
1.310000,0.000374,-1214.107544,0.000448,0.000574,0.014578,0.001663,0.000085,0.145781,-1214.107544,0.015688,0.000000
1.550000,0.059212,-1214.107544,0.000629,0.000734,0.018645,0.263387,0.013418,0.186454,-1214.107544,0.019695,0.000000
1.790000,0.154541,-1214.107544,0.000733,0.000889,0.022574,0.687433,0.035019,0.225739,-1214.107544,0.023684,0.000000
2.030000,0.328064,-1214.063110,0.000910,0.001039,0.026381,1.459301,0.074340,0.263810,-1214.063110,0.027691,0.000000
2.270000,0.613670,-1214.063110,0.001151,0.001200,0.030492,2.729742,0.139060,0.304917,-1214.063110,0.031680,0.000000
2.510000,0.576805,-1214.063110,0.001143,-0.000000,-0.000000,2.565757,0.130706,-0.000000,-1214.063110,0.000225,0.000000
2.750000,0.542549,-1214.107544,0.001186,-0.000000,-0.000000,2.413379,0.122943,-0.000000,-1214.107544,0.000225,0.000000
2.990000,0.559677,-1214.107544,0.001155,-0.000000,-0.000000,2.489568,0.126825,-0.000000,-1214.107544,0.000408,0.000000
3.230000,0.533981,-1214.152100,0.001194,-0.000000,-0.000000,2.375268,0.121002,-0.000000,-1214.152100,0.000807,0.000000
3.470000,0.557076,-1214.107544,0.001138,-0.000000,-0.000000,2.477996,0.126235,-0.000000,-1214.107544,0.001205,0.000000
3.710000,0.631546,-1214.152100,0.001181,0.000024,0.000616,2.809257,0.143110,0.006157,-1214.152100,0.001604,0.000000
3.950000,0.695595,-1214.107544,0.001186,0.000037,0.000945,3.094160,0.157624,0.009453,-1214.107544,0.002003,0.000000
4.190000,0.749962,-1214.107544,0.001242,0.000057,0.001448,3.335997,0.169944,0.014482,-1214.107544,0.002402,0.000000
4.430000,0.796883,-1214.107544,0.001233,0.000076,0.001925,3.544711,0.180576,0.019252,-1214.107544,0.002801,0.000000
4.670000,0.787941,-1214.107544,0.001289,0.000091,0.002316,3.504936,0.178550,0.023155,-1214.107544,0.003209,0.000000
4.910000,0.809540,-1214.196533,0.001268,0.000106,0.002680,3.601013,0.183444,0.026797,-1214.196533,0.003608,0.000000
5.150000,0.851990,-1214.063110,0.001281,0.000119,0.003018,3.789840,0.193064,0.030179,-1214.063110,0.004007,0.000000
5.390000,0.921997,-1214.107544,0.001315,0.000138,0.003504,4.101248,0.208928,0.035036,-1214.107544,0.004406,0.000000
5.630000,0.949181,-1214.107544,0.001302,0.000150,0.003816,4.222166,0.215087,0.038158,-1214.107544,0.004804,0.000000
5.870000,0.979713,-1214.107544,0.001367,0.000166,0.004215,4.357983,0.222006,0.042147,-1214.107544,0.005203,0.000000
6.110000,1.040039,-1214.196533,0.001306,0.000183,0.004640,4.626325,0.235676,0.046397,-1214.196533,0.005602,0.000000
6.350000,1.070946,-1214.107544,0.001324,0.000202,0.005134,4.763804,0.242680,0.051340,-1214.107544,0.006001,0.000000
6.590000,1.059776,-1214.107544,0.001380,0.000215,0.005472,4.714120,0.240149,0.054722,-1214.107544,0.006409,0.000000
6.830000,1.098877,-1214.107544,0.001384,0.000231,0.005862,4.888049,0.249009,0.058624,-1214.107544,0.006808,0.000000
7.070000,1.118607,-1214.107544,0.001380,0.000244,0.006201,4.975811,0.253480,0.062007,-1214.107544,0.007207,0.000000
7.310000,1.187126,-1214.152100,0.001440,0.000262,0.006660,5.280601,0.269007,0.066603,-1214.152100,0.007606,0.000000
7.550000,1.237396,-1214.107544,0.001427,0.000277,0.007033,5.504213,0.280398,0.070332,-1214.107544,0.008004,0.000000
7.790000,1.250427,-1214.152100,0.001414,0.000290,0.007354,5.562178,0.283351,0.073541,-1214.152100,0.008403,0.000000
8.030001,1.267189,-1214.063110,0.001462,0.000296,0.007519,5.636738,0.287149,0.075188,-1214.063110,0.008802,0.000000
8.270000,1.379272,-1214.107544,0.001462,0.000326,0.008291,6.135310,0.312548,0.082907,-1214.107544,0.009201,0.000000
8.510000,1.401611,-1214.196533,0.001526,0.000341,0.008672,6.234679,0.317610,0.086722,-1214.196533,0.009609,0.000000
8.750000,1.443321,-1214.152100,0.001526,0.000357,0.009080,6.420214,0.327061,0.090799,-1214.152100,0.010008,0.000000
8.990001,1.483910,-1214.152100,0.001500,0.000374,0.009505,6.600760,0.336259,0.095048,-1214.152100,0.010407,0.000000
9.230000,1.522636,-1214.107544,0.001565,0.000389,0.009886,6.773025,0.345034,0.098864,-1214.107544,0.010806,0.000000
9.470000,1.583328,-1214.107544,0.001582,0.000404,0.010259,7.042996,0.358787,0.102593,-1214.107544,0.011205,0.000000
9.710000,1.586311,-1214.152100,0.001574,0.000416,0.010563,7.056265,0.359463,0.105628,-1214.152100,0.011603,0.000000
9.950001,1.677544,-1214.063110,0.001600,0.000434,0.011031,7.462087,0.380137,0.110311,-1214.063110,0.012002,0.000000
10.190001,1.680519,-1214.152100,0.001587,0.000451,0.011456,7.475322,0.380811,0.114560,-1214.152100,0.012401,0.000000
10.430000,1.726318,-1214.196533,0.001647,0.000465,0.011820,7.679048,0.391189,0.118203,-1214.196533,0.012809,0.000000
10.670000,1.775101,-1214.152100,0.001643,0.000482,0.012254,7.896042,0.402244,0.122539,-1214.152100,0.013208,0.000000
10.910001,1.801910,-1214.196533,0.001630,0.000497,0.012635,8.015298,0.408319,0.126355,-1214.196533,0.013607,0.000000
11.150001,1.876389,-1214.107544,0.001712,0.000514,0.013060,8.346593,0.425196,0.130604,-1214.107544,0.014006,0.000000
11.390000,1.895004,-1214.107544,0.001690,0.000527,0.013381,8.429400,0.429414,0.133813,-1214.107544,0.014405,0.000000
11.630000,1.953842,-1214.107544,0.001738,0.000540,0.013711,8.691124,0.442747,0.137108,-1214.107544,0.014804,0.000000
11.870001,2.001503,-1214.152100,0.001763,0.000560,0.014222,8.903130,0.453547,0.142225,-1214.152100,0.015202,0.000000
12.110001,2.047676,-1214.152100,0.001746,0.000576,0.014621,9.108519,0.464010,0.146214,-1214.152100,0.015601,0.000000
12.350000,2.096458,-1214.152100,0.001729,0.000593,0.015055,9.325513,0.475064,0.150550,-1214.152100,0.016009,0.000000
12.590000,2.141518,-1214.196533,0.001776,0.000609,0.015463,9.525947,0.485275,0.154626,-1214.196533,0.016408,0.000000
12.830001,2.147102,-1214.240967,0.001811,0.000619,0.015731,9.550788,0.486540,0.157315,-1214.240967,0.016807,0.000000
13.070001,2.313927,-1214.152100,0.001807,0.000643,0.016321,10.292860,0.524343,0.163212,-1214.152100,0.017206,0.000000
13.310000,2.352654,-1214.196533,0.001785,0.000657,0.016694,10.465125,0.533119,0.166941,-1214.196533,0.017605,0.000000
13.550000,2.367920,-1214.196533,0.001798,0.000670,0.017006,10.533034,0.536578,0.170063,-1214.196533,0.018004,0.000000
13.790001,2.391754,-1214.107544,0.001871,0.000683,0.017353,10.639053,0.541979,0.173532,-1214.107544,0.018403,0.000000
14.030001,2.506439,-1214.152100,0.001884,0.000703,0.017856,11.149199,0.567967,0.178562,-1214.152100,0.018810,0.000000
14.270000,2.483727,-1214.152100,0.001863,0.000715,0.018168,11.048167,0.562820,0.181684,-1214.152100,0.019209,0.000000
14.510000,2.529526,-1214.196533,0.001906,0.000733,0.018619,11.251892,0.573199,0.186193,-1214.196533,0.019608,0.000000
14.750001,2.587616,-1214.152100,0.001923,0.000748,0.019010,11.510291,0.586362,0.190096,-1214.152100,0.020007,0.000000
14.990001,2.748482,-1214.196533,0.001957,0.000768,0.019513,12.225858,0.622815,0.195126,-1214.196533,0.020406,0.000000
15.230000,2.765244,-1214.152100,0.001996,0.000784,0.019911,12.300418,0.626613,0.199115,-1214.152100,0.020805,0.000000
15.470000,2.786469,-1214.196533,0.002001,0.000797,0.020232,12.394831,0.631423,0.202324,-1214.196533,0.021204,0.000000
15.710001,2.809555,-1214.240967,0.001957,0.000810,0.020571,12.497525,0.636654,0.205706,-1214.240967,0.021603,0.000000
15.950001,2.933556,-1214.152100,0.002005,0.000830,0.021082,13.049107,0.664753,0.210822,-1214.152100,0.022010,0.000000
16.190001,2.938019,-1214.196533,0.001988,0.000843,0.021403,13.068960,0.665765,0.214031,-1214.196533,0.022409,0.000000
16.430000,2.998718,-1214.152100,0.001996,0.000861,0.021871,13.338965,0.679519,0.218714,-1214.152100,0.022808,0.000000
16.670000,3.081383,-1214.152100,0.002026,0.000879,0.022331,13.706675,0.698251,0.223311,-1214.152100,0.023207,0.000000
16.910002,3.194214,-1214.196533,0.002052,0.000898,0.022808,14.208573,0.723819,0.228080,-1214.196533,0.023606,0.000000
17.150002,3.209854,-1214.152100,0.002057,0.000912,0.023155,14.278144,0.727363,0.231549,-1214.152100,0.024005,0.000000
17.390001,3.283958,-1214.107544,0.002052,0.000928,0.023563,14.607777,0.744156,0.235625,-1214.107544,0.024404,0.000000
17.630001,3.262360,-1214.152100,0.002113,0.000939,0.023840,14.511701,0.739261,0.238400,-1214.152100,0.024803,0.000000
17.870001,3.403488,-1214.196533,0.002130,0.000959,0.024352,15.139471,0.771241,0.243517,-1214.196533,0.025210,0.000000
18.110001,3.423592,-1214.285522,0.002130,0.000973,0.024707,15.228896,0.775797,0.247073,-1214.285522,0.025609,0.000000
18.350000,3.424713,-1214.152100,0.002147,0.000986,0.025045,15.233885,0.776051,0.250455,-1214.152100,0.026008,0.000000
18.590000,3.553925,-1214.240967,0.002164,0.001006,0.025548,15.808646,0.805331,0.255485,-1214.240967,0.026407,0.000000
18.830002,3.625420,-1214.240967,0.002225,0.001022,0.025956,16.126673,0.821532,0.259561,-1214.240967,0.026806,0.000000
19.070002,3.644783,-1214.196533,0.002195,0.001036,0.026312,16.212805,0.825920,0.263116,-1214.196533,0.027205,0.000000
19.310001,3.663406,-1214.240967,0.002208,0.001047,0.026598,16.295645,0.830140,0.265978,-1214.240967,0.027604,0.000000
19.550001,3.791130,-1214.152100,0.002242,0.001064,0.027023,16.863789,0.859082,0.270227,-1214.152100,0.028003,0.000000
19.790001,3.919594,-1214.240967,0.002268,0.001084,0.027543,17.435225,0.888193,0.275431,-1214.240967,0.028410,0.000000
20.030001,3.904701,-1214.285522,0.002298,0.001098,0.027881,17.368979,0.884818,0.278813,-1214.285522,0.028809,0.000000
20.270000,3.915871,-1214.152100,0.002281,0.001112,0.028254,17.418663,0.887349,0.282542,-1214.152100,0.029208,0.000000
20.510000,3.963905,-1214.240967,0.002337,0.001125,0.028566,17.632332,0.898234,0.285664,-1214.240967,0.029607,0.000000
20.750002,4.081947,-1214.240967,0.002302,0.001141,0.028991,18.157408,0.924982,0.289914,-1214.240967,0.030006,0.000000
20.990002,4.125519,-1214.285522,0.002324,0.001153,0.029278,18.351225,0.934856,0.292775,-1214.285522,0.030405,0.000000
21.230001,4.179138,-1214.285522,0.002371,0.001168,0.029676,18.589735,0.947006,0.296765,-1214.285522,0.030804,0.000000
21.470001,4.315056,-1214.240967,0.002333,0.001187,0.030145,19.194326,0.977806,0.301447,-1214.240967,0.031203,0.000000
21.710001,4.412613,-1214.240967,0.002358,0.001204,0.030587,19.628283,0.999912,0.305871,-1214.240967,0.031610,0.000000
21.950001,4.440918,-1214.240967,0.002367,0.001219,0.030969,19.754190,1.006326,0.309686,-1214.240967,0.032009,0.000000
22.190001,4.438683,-1214.196533,0.002419,0.001234,0.031342,19.744246,1.005820,0.313415,-1214.196533,0.032408,0.000000
22.430000,4.536247,-1214.329956,0.002427,0.001251,0.031766,20.178236,1.027928,0.317665,-1214.329956,0.032807,0.000000
22.670002,4.582420,-1214.152100,0.002453,0.001267,0.032183,20.383623,1.038391,0.321827,-1214.152100,0.033206,0.000000
22.910002,4.792435,-1214.329956,0.002483,0.001286,0.032660,21.317814,1.085981,0.326597,-1214.329956,0.033605,0.000000
23.150002,4.679977,-1214.196533,0.002445,0.001294,0.032868,20.817579,1.060498,0.328678,-1214.196533,0.034004,0.000000
23.390001,4.863930,-1214.196533,0.002475,0.001313,0.033353,21.635839,1.102182,0.333535,-1214.196533,0.034403,0.000000
23.630001,5.051979,-1214.285522,0.002531,0.001336,0.033935,22.472324,1.144795,0.339345,-1214.285522,0.034810,0.000000
23.870001,5.041183,-1214.196533,0.002539,0.001349,0.034273,22.424305,1.142349,0.342727,-1214.196533,0.035209,0.000000
24.110001,5.003571,-1214.285522,0.002522,0.001362,0.034602,22.256994,1.133825,0.346023,-1214.285522,0.035608,0.000000
24.350000,5.104858,-1214.196533,0.002552,0.001378,0.035001,22.707544,1.156778,0.350012,-1214.196533,0.036007,0.000000
24.590002,5.109322,-1214.285522,0.002604,0.001391,0.035322,22.727398,1.157789,0.353221,-1214.285522,0.036406,0.000000
24.830002,5.185661,-1214.285522,0.002604,0.001403,0.035634,23.066973,1.175088,0.356343,-1214.285522,0.036805,0.000000
25.070002,5.323814,-1214.240967,0.002600,0.001422,0.036111,23.681509,1.206394,0.361113,-1214.240967,0.037204,0.000000
25.310001,5.427330,-1214.240967,0.002656,0.001436,0.036476,24.141970,1.229851,0.364755,-1214.240967,0.037603,0.000000
25.550001,5.631020,-1214.240967,0.002621,0.001461,0.037100,25.048027,1.276007,0.370999,-1214.240967,0.038011,0.000000
25.790001,5.654480,-1214.240967,0.002660,0.001477,0.037516,25.152384,1.281323,0.375162,-1214.240967,0.038409,0.000000
26.030001,5.660439,-1214.285522,0.002626,0.001493,0.037915,25.178888,1.282674,0.379151,-1214.285522,0.038808,0.000000
26.270000,5.699539,-1214.240967,0.002656,0.001507,0.038271,25.352816,1.291534,0.382707,-1214.240967,0.039207,0.000000
26.510002,5.765076,-1214.329956,0.002703,0.001521,0.038626,25.644337,1.306385,0.386262,-1214.329956,0.039606,0.000000
26.750002,5.934875,-1214.285522,0.002725,0.001537,0.039051,26.399645,1.344862,0.390512,-1214.285522,0.040005,0.000000
26.990002,5.978439,-1214.240967,0.002712,0.001553,0.039450,26.593426,1.354734,0.394501,-1214.240967,0.040404,0.000000
27.230001,5.862633,-1214.329956,0.002742,0.001563,0.039702,26.078293,1.328492,0.397016,-1214.329956,0.040812,0.000000
27.470001,6.281555,-1214.329956,0.002790,0.001586,0.040283,27.941753,1.423421,0.402826,-1214.329956,0.041211,0.000000
27.710001,6.293839,-1214.329956,0.002807,0.001602,0.040690,27.996391,1.426204,0.406902,-1214.329956,0.041609,0.000000
27.950001,6.289749,-1214.329956,0.002802,0.001616,0.041046,27.978201,1.425277,0.410458,-1214.329956,0.042008,0.000000
28.190001,6.389168,-1214.285522,0.002824,0.001632,0.041453,28.420437,1.447806,0.414534,-1214.285522,0.042407,0.000000
28.430002,6.416351,-1214.329956,0.002828,0.001645,0.041774,28.541357,1.453966,0.417743,-1214.329956,0.042806,0.000000
28.670002,6.617432,-1214.329956,0.002867,0.001663,0.042234,29.435806,1.499531,0.422339,-1214.329956,0.043205,0.000000
28.910002,6.559715,-1214.329956,0.002880,0.001672,0.042477,29.179071,1.486453,0.424767,-1214.329956,0.043604,0.000000
29.150002,6.795425,-1214.418945,0.002871,0.001693,0.043014,30.227562,1.539865,0.430144,-1214.418945,0.044012,0.000000
29.390001,6.642014,-1214.374390,0.002871,0.001704,0.043283,29.545153,1.505102,0.432832,-1214.374390,0.044411,0.000000
29.630001,7.087738,-1214.374390,0.002928,0.001728,0.043882,31.527834,1.606104,0.438816,-1214.374390,0.044810,0.000000
29.870001,7.066513,-1214.285522,0.002919,0.001742,0.044237,31.433420,1.601295,0.442372,-1214.285522,0.045208,0.000000
30.110001,7.155510,-1214.374390,0.002906,0.001759,0.044671,31.829298,1.621462,0.446708,-1214.374390,0.045607,0.000000
30.350002,7.310043,-1214.329956,0.002966,0.001777,0.045130,32.516697,1.656479,0.451304,-1214.329956,0.046006,0.000000
30.590002,7.360313,-1214.285522,0.002979,0.001791,0.045495,32.740311,1.667871,0.454947,-1214.285522,0.046405,0.000000
30.830002,7.361061,-1214.374390,0.003018,0.001803,0.045807,32.743633,1.668040,0.458069,-1214.374390,0.046804,0.000000
31.070002,7.463837,-1214.285522,0.003014,0.001818,0.046180,33.200802,1.691329,0.461798,-1214.285522,0.047212,0.000000
31.310001,7.668640,-1214.374390,0.003018,0.001836,0.046639,34.111816,1.737739,0.466394,-1214.374390,0.047611,0.000000
31.550001,7.812752,-1214.329956,0.003009,0.001854,0.047090,34.752857,1.770395,0.470903,-1214.329956,0.048010,0.000000
31.790001,7.750938,-1214.374390,0.003048,0.001865,0.047368,34.477898,1.756388,0.473679,-1214.374390,0.048409,0.000000
32.030003,7.870842,-1214.418945,0.003053,0.001882,0.047793,35.011253,1.783558,0.477928,-1214.418945,0.048807,0.000000
32.270000,8.001915,-1214.329956,0.003113,0.001899,0.048226,35.594296,1.813260,0.482264,-1214.329956,0.049206,0.000000
32.510002,8.194801,-1214.374390,0.003117,0.001916,0.048660,36.452297,1.856969,0.486600,-1214.374390,0.049605,0.000000
32.750000,8.178421,-1214.374390,0.003134,0.001928,0.048981,36.379433,1.853257,0.489809,-1214.374390,0.050004,0.000000
32.990002,8.170975,-1214.374390,0.003126,0.001941,0.049302,36.346310,1.851569,0.493018,-1214.374390,0.050412,0.000000
33.230003,8.594360,-1214.418945,0.003104,0.001963,0.049848,38.229626,1.947510,0.498481,-1214.418945,0.050811,0.000000
33.470001,8.688942,-1214.329956,0.003152,0.001978,0.050247,38.650345,1.968942,0.502470,-1214.329956,0.051210,0.000000
33.710003,8.785385,-1214.418945,0.003199,0.001994,0.050655,39.079346,1.990797,0.506547,-1214.418945,0.051609,0.000000
33.950001,8.846085,-1214.329956,0.003203,0.002009,0.051036,39.349350,2.004551,0.510362,-1214.329956,0.052008,0.000000
34.190002,8.766769,-1214.374390,0.003238,0.002021,0.051331,38.996536,1.986578,0.513311,-1214.374390,0.052406,0.000000
34.430000,9.169304,-1214.463379,0.003234,0.002041,0.051834,40.787102,2.077794,0.518341,-1214.463379,0.052805,0.000000
34.670002,9.285110,-1214.285522,0.003208,0.002057,0.052242,41.302235,2.104036,0.522417,-1214.285522,0.053204,0.000000
34.910000,9.285110,-1214.418945,0.003260,0.002071,0.052615,41.302235,2.104036,0.526146,-1214.418945,0.053612,0.000000
35.150002,9.343575,-1214.418945,0.003255,0.002083,0.052918,41.562294,2.117284,0.529181,-1214.418945,0.054011,0.000000
35.390003,9.656738,-1214.329956,0.003268,0.002105,0.053456,42.955318,2.188248,0.534558,-1214.329956,0.054410,0.000000
35.630001,9.729721,-1214.418945,0.003320,0.002121,0.053872,43.279961,2.204786,0.538721,-1214.418945,0.054809,0.000000
35.870003,9.724884,-1214.285522,0.003285,0.002134,0.054202,43.258446,2.203690,0.542016,-1214.285522,0.055208,0.000000
36.110001,9.776642,-1214.374390,0.003354,0.002147,0.054522,43.488674,2.215419,0.545225,-1214.374390,0.055606,0.000000
36.350002,10.226097,-1214.374390,0.003307,0.002168,0.055069,45.487953,2.317267,0.550689,-1214.374390,0.056005,0.000000
36.590000,10.282700,-1214.374390,0.003320,0.002183,0.055459,45.739731,2.330093,0.554591,-1214.374390,0.056404,0.000000
36.830002,10.297218,-1214.374390,0.003350,0.002197,0.055797,45.804314,2.333383,0.557973,-1214.374390,0.056812,0.000000
37.070004,10.323654,-1214.374390,0.003402,0.002211,0.056162,45.921906,2.339373,0.561615,-1214.374390,0.057211,0.000000
37.310001,10.812210,-1214.374390,0.003367,0.002233,0.056717,48.095112,2.450082,0.567166,-1214.374390,0.057610,0.000000
37.550003,10.675919,-1214.374390,0.003397,0.002244,0.057003,47.488857,2.419198,0.570027,-1214.374390,0.058009,0.000000
37.790001,10.904930,-1214.374390,0.003410,0.002261,0.057428,48.507553,2.471092,0.574277,-1214.374390,0.058408,0.000000
38.030003,11.167084,-1214.374390,0.003458,0.002281,0.057931,49.673668,2.530497,0.579307,-1214.374390,0.058807,0.000000
38.270000,11.453064,-1214.329956,0.003445,0.002298,0.058382,50.945774,2.595301,0.583816,-1214.329956,0.059206,0.000000
38.510002,11.495140,-1214.374390,0.003501,0.002314,0.058772,51.132938,2.604836,0.587719,-1214.374390,0.059604,0.000000
38.750000,11.572968,-1214.374390,0.003497,0.002327,0.059101,51.479130,2.622472,0.591014,-1214.374390,0.060012,0.000000
38.990002,11.481361,-1214.285522,0.003492,0.002338,0.059388,51.071648,2.601714,0.593876,-1214.285522,0.060411,0.000000
39.230003,11.906609,-1214.374390,0.003544,0.002359,0.059908,52.963242,2.698076,0.599079,-1214.374390,0.060810,0.000000
39.470001,11.943474,-1214.374390,0.003544,0.002371,0.060229,53.127224,2.706430,0.602288,-1214.374390,0.061209,0.000000
39.710003,12.048859,-1214.374390,0.003518,0.002388,0.060645,53.596001,2.730310,0.606451,-1214.374390,0.061608,0.000000
39.950001,12.373566,-1214.463379,0.003600,0.002406,0.061113,55.040367,2.803890,0.611134,-1214.463379,0.062007,0.000000
40.190002,12.571671,-1214.374390,0.003613,0.002421,0.061486,55.921585,2.848781,0.614863,-1214.374390,0.062406,0.000000
40.430000,12.513954,-1214.463379,0.003600,0.002433,0.061798,55.664848,2.835703,0.617985,-1214.463379,0.062813,0.000000
40.670002,12.670723,-1214.329956,0.003626,0.002448,0.062171,56.362190,2.871227,0.621714,-1214.329956,0.063212,0.000000
40.910004,12.961174,-1214.329956,0.003596,0.002464,0.062579,57.654182,2.937044,0.625790,-1214.329956,0.063611,0.000000
41.150002,13.419937,-1214.374390,0.003656,0.002486,0.063134,59.694862,3.041001,0.631340,-1214.374390,0.064010,0.000000
41.390003,13.343597,-1214.374390,0.003665,0.002496,0.063403,59.355286,3.023702,0.634029,-1214.374390,0.064409,0.000000
41.630001,13.582664,-1214.418945,0.003699,0.002514,0.063854,60.418709,3.077876,0.638538,-1214.418945,0.064808,0.000000
41.870003,13.499252,-1214.418945,0.003729,0.002524,0.064105,60.047672,3.058975,0.641053,-1214.418945,0.065207,0.000000
42.110001,13.864548,-1214.329956,0.003708,0.002542,0.064556,61.672588,3.141751,0.645563,-1214.329956,0.065606,0.000000
42.350002,14.123344,-1214.374390,0.003764,0.002558,0.064973,62.823772,3.200396,0.649725,-1214.374390,0.066013,0.000000
42.590000,14.137871,-1214.418945,0.003712,0.002569,0.065259,62.888390,3.203687,0.652587,-1214.418945,0.066412,0.000000
42.830002,14.481941,-1214.418945,0.003686,0.002588,0.065736,64.418892,3.281655,0.657357,-1214.418945,0.066811,0.000000
43.070004,14.871811,-1214.418945,0.003820,0.002607,0.066230,66.153122,3.370000,0.662300,-1214.418945,0.067210,0.000000
43.310001,14.842400,-1214.374390,0.003755,0.002619,0.066534,66.022293,3.363336,0.665335,-1214.374390,0.067609,0.000000
43.550003,15.065445,-1214.463379,0.003824,0.002635,0.066932,67.014442,3.413879,0.669325,-1214.463379,0.068008,0.000000
43.790001,15.354034,-1214.374390,0.003837,0.002653,0.067375,68.298157,3.479274,0.673748,-1214.374390,0.068407,0.000000
44.030003,15.578201,-1214.463379,0.003790,0.002670,0.067817,69.295303,3.530071,0.678170,-1214.463379,0.068806,0.000000
44.270000,15.877220,-1214.418945,0.003837,0.002685,0.068207,70.625404,3.597830,0.682073,-1214.418945,0.069213,0.000000
44.510002,15.742790,-1214.374390,0.003837,0.002695,0.068459,70.027428,3.567367,0.684588,-1214.374390,0.069612,0.000000
44.750004,16.111443,-1214.418945,0.003880,0.002711,0.068866,71.667274,3.650905,0.688664,-1214.418945,0.070011,0.000000
44.990002,16.759743,-1214.418945,0.003911,0.002736,0.069499,74.551056,3.797812,0.694995,-1214.418945,0.070410,0.000000
45.230003,16.728462,-1214.374390,0.003954,0.002749,0.069820,74.411919,3.790724,0.698203,-1214.374390,0.070809,0.000000
45.470001,16.784317,-1214.374390,0.003923,0.002763,0.070185,74.660370,3.803381,0.701846,-1214.374390,0.071208,0.000000
45.710003,17.029343,-1214.374390,0.003919,0.002778,0.070557,75.750298,3.858904,0.705575,-1214.374390,0.071607,0.000000
45.950001,17.149246,-1214.374390,0.003949,0.002792,0.070922,76.283653,3.886075,0.709217,-1214.374390,0.072006,0.000000
46.190002,17.472839,-1214.418945,0.003958,0.002809,0.071338,77.723068,3.959402,0.713380,-1214.418945,0.072413,0.000000
46.430000,17.713387,-1214.463379,0.004014,0.002821,0.071650,78.793076,4.013911,0.716502,-1214.463379,0.072812,0.000000
46.670002,17.969955,-1214.418945,0.004023,0.002838,0.072075,79.934357,4.072050,0.720751,-1214.418945,0.073211,0.000000
46.910004,18.556442,-1214.374390,0.004027,0.002857,0.072569,82.543175,4.204950,0.725694,-1214.374390,0.073610,0.000000
47.150002,18.948547,-1214.418945,0.004031,0.002879,0.073116,84.287346,4.293802,0.731158,-1214.418945,0.074009,0.000000
47.390003,19.088562,-1214.329956,0.004031,0.002894,0.073515,84.910164,4.325530,0.735147,-1214.329956,0.074408,0.000000
47.630001,19.187614,-1214.418945,0.004014,0.002908,0.073853,85.350769,4.347976,0.738530,-1214.418945,0.074807,0.000000
47.870003,19.519394,-1214.463379,0.004053,0.002925,0.074287,86.826599,4.423158,0.742866,-1214.463379,0.075206,0.000000
48.110001,19.701111,-1214.374390,0.004109,0.002939,0.074659,87.634918,4.464335,0.746595,-1214.374390,0.075613,0.000000
48.350002,19.898094,-1214.418945,0.004139,0.002952,0.074972,88.511147,4.508972,0.749717,-1214.418945,0.076012,0.000000
48.590004,20.425751,-1214.374390,0.004118,0.002971,0.075466,90.858276,4.628541,0.754660,-1214.374390,0.076411,0.000000
48.830002,20.883392,-1214.374390,0.004092,0.002990,0.075943,92.893967,4.732244,0.759430,-1214.374390,0.076810,0.000000
49.070004,20.991753,-1214.463379,0.004122,0.003002,0.076246,93.375977,4.756799,0.762465,-1214.463379,0.077209,0.000000
49.310001,21.340294,-1214.418945,0.004186,0.003021,0.076723,94.926369,4.835780,0.767235,-1214.418945,0.077608,0.000000
49.550003,21.527969,-1214.463379,0.004161,0.003034,0.077053,95.761192,4.878308,0.770530,-1214.463379,0.078007,0.000000
49.790001,21.656441,-1214.374390,0.004186,0.003048,0.077426,96.332657,4.907420,0.774259,-1214.374390,0.078406,0.000000
50.030003,22.129356,-1214.507935,0.004186,0.003064,0.077834,98.436295,5.014584,0.778335,-1214.507935,0.078813,0.000000
50.270004,22.181488,-1214.418945,0.004230,0.003074,0.078076,98.668190,5.026397,0.780763,-1214.418945,0.079212,0.000000
50.510002,22.800743,-1214.418945,0.004234,0.003093,0.078562,101.422768,5.166722,0.785620,-1214.418945,0.079611,0.000000
50.750004,23.617355,-1214.463379,0.004217,0.003117,0.079178,105.055244,5.351769,0.791777,-1214.463379,0.080010,0.000000
50.990002,23.523888,-1214.418945,0.004255,0.003126,0.079412,104.639481,5.330589,0.794119,-1214.418945,0.080409,0.000000
51.230003,23.902588,-1214.507935,0.004299,0.003146,0.079906,106.324020,5.416404,0.799062,-1214.507935,0.080808,0.000000
51.470001,24.273476,-1214.418945,0.004264,0.003162,0.080322,107.973816,5.500448,0.803224,-1214.418945,0.081207,0.000000
51.710003,24.562065,-1214.374390,0.004268,0.003177,0.080695,109.257523,5.565844,0.806953,-1214.374390,0.081606,0.000000
51.950001,24.788094,-1214.507935,0.004281,0.003192,0.081077,110.262947,5.617063,0.810769,-1214.507935,0.082014,0.000000
52.190002,24.998108,-1214.418945,0.004368,0.003205,0.081398,111.197136,5.664652,0.813978,-1214.418945,0.082412,0.000000
52.430004,25.322823,-1214.507935,0.004346,0.003221,0.081805,112.641541,5.738234,0.818054,-1214.507935,0.082811,0.000000
52.670002,25.967026,-1214.463379,0.004329,0.003238,0.082248,115.507103,5.884212,0.822477,-1214.463379,0.083210,0.000000
52.910004,26.444405,-1214.418945,0.004363,0.003255,0.082673,117.630585,5.992388,0.826726,-1214.418945,0.083609,0.000000
53.150002,26.547554,-1214.463379,0.004393,0.003268,0.083019,118.089417,6.015762,0.830195,-1214.463379,0.084008,0.000000
53.390003,26.874123,-1214.418945,0.004359,0.003282,0.083375,119.542068,6.089763,0.833751,-1214.418945,0.084407,0.000000
53.630001,27.456512,-1214.507935,0.004393,0.003300,0.083826,122.132668,6.221735,0.838261,-1214.507935,0.084815,0.000000
53.870003,27.834846,-1214.463379,0.004437,0.003315,0.084190,123.815582,6.307466,0.841903,-1214.463379,0.085214,0.000000
54.110004,28.074280,-1214.463379,0.004411,0.003329,0.084555,124.880630,6.361723,0.845545,-1214.463379,0.085613,0.000000
54.350002,28.412392,-1214.418945,0.004424,0.003342,0.084893,126.384628,6.438340,0.848927,-1214.418945,0.086011,0.000000
54.590004,29.110962,-1214.507935,0.004449,0.003362,0.085396,129.492020,6.596638,0.853957,-1214.507935,0.086410,0.000000
54.830002,29.570847,-1214.507935,0.004462,0.003379,0.085821,131.537689,6.700850,0.858206,-1214.507935,0.086809,0.000000
55.070004,29.996468,-1214.552368,0.004471,0.003393,0.086194,133.430954,6.797297,0.861936,-1214.552368,0.087208,0.000000
55.310001,30.352081,-1214.418945,0.004475,0.003409,0.086592,135.012802,6.877880,0.865925,-1214.418945,0.087607,0.000000
55.550003,30.469383,-1214.463379,0.004493,0.003420,0.086870,135.534592,6.904461,0.868700,-1214.463379,0.088015,0.000000
55.790001,31.269234,-1214.507935,0.004501,0.003440,0.087382,139.092499,7.085710,0.873817,-1214.507935,0.088414,0.000000
56.030003,31.671028,-1214.552368,0.004523,0.003455,0.087763,140.879776,7.176758,0.877632,-1214.552368,0.088813,0.000000
56.270004,32.039673,-1214.507935,0.004544,0.003472,0.088188,142.519577,7.260294,0.881882,-1214.507935,0.089211,0.000000
56.510002,32.486893,-1214.552368,0.004527,0.003487,0.088570,144.508911,7.361635,0.885698,-1214.552368,0.089610,0.000000
56.750004,33.166100,-1214.552368,0.004566,0.003504,0.089003,147.530182,7.515545,0.890034,-1214.552368,0.090009,0.000000
56.990002,33.649071,-1214.507935,0.004587,0.003521,0.089428,149.678543,7.624989,0.894283,-1214.507935,0.090408,0.000000
57.230003,33.873611,-1214.418945,0.004575,0.003535,0.089784,150.677353,7.675870,0.897839,-1214.418945,0.090807,0.000000
57.470001,34.110435,-1214.552368,0.004592,0.003546,0.090070,151.730789,7.729535,0.900700,-1214.552368,0.091215,0.000000
57.710003,35.246544,-1214.507935,0.004609,0.003571,0.090694,156.784454,7.986981,0.906945,-1214.507935,0.091614,0.000000
57.950005,35.576843,-1214.463379,0.004626,0.003584,0.091041,158.253708,8.061828,0.910413,-1214.463379,0.092013,0.000000
58.190002,35.736961,-1214.552368,0.004618,0.003597,0.091362,158.965942,8.098111,0.913622,-1214.552368,0.092412,0.000000
58.430004,36.225883,-1214.507935,0.004669,0.003614,0.091787,161.140778,8.208902,0.917872,-1214.507935,0.092810,0.000000
58.670002,37.210808,-1214.552368,0.004644,0.003631,0.092238,165.521942,8.432090,0.922381,-1214.552368,0.093209,0.000000
58.910004,37.351936,-1214.507935,0.004700,0.003645,0.092585,166.149704,8.464070,0.925850,-1214.507935,0.093608,0.000000
59.150002,38.008430,-1214.552368,0.004656,0.003662,0.093019,169.069946,8.612833,0.930186,-1214.552368,0.094007,0.000000
59.390003,38.746101,-1214.507935,0.004738,0.003680,0.093461,172.351273,8.779992,0.934609,-1214.507935,0.094415,0.000000
59.630001,39.567184,-1214.507935,0.004730,0.003698,0.093938,176.003632,8.966053,0.939379,-1214.507935,0.094814,0.000000
59.870003,40.066162,-1214.552368,0.004712,0.003713,0.094319,178.223190,9.079123,0.943194,-1214.552368,0.095213,0.000000
60.110004,40.416191,-1214.507935,0.004777,0.003727,0.094666,179.780197,9.158440,0.946664,-1214.507935,0.095612,0.000000
60.350002,40.838089,-1214.507935,0.004725,0.003744,0.095100,181.656891,9.254044,0.951000,-1214.507935,0.096011,0.000000
60.590004,41.538521,-1214.507935,0.004738,0.003759,0.095482,184.772568,9.412764,0.954815,-1214.507935,0.096409,0.000000
60.830002,41.875145,-1214.507935,0.004760,0.003771,0.095785,186.269943,9.489043,0.957851,-1214.507935,0.096808,0.000000
61.070004,42.434082,-1214.552368,0.004769,0.003789,0.096236,188.756226,9.615700,0.962360,-1214.552368,0.097207,0.000000
61.310001,43.328148,-1214.552368,0.004790,0.003806,0.096670,192.733231,9.818298,0.966696,-1214.552368,0.097615,0.000000
61.550003,44.005119,-1214.552368,0.004777,0.003823,0.097112,195.744553,9.971703,0.971119,-1214.552368,0.098014,0.000000
61.790005,44.258331,-1214.552368,0.004850,0.003835,0.097415,196.870895,10.029081,0.974154,-1214.552368,0.098413,0.000000
62.030003,44.760292,-1214.507935,0.004786,0.003850,0.097788,199.103729,10.142827,0.977883,-1214.507935,0.098812,0.000000
62.270004,45.310287,-1214.552368,0.004850,0.003862,0.098101,201.550232,10.267457,0.981005,-1214.552368,0.099211,0.000000
62.510002,46.564438,-1214.507935,0.004838,0.003885,0.098690,207.128967,10.551653,0.986903,-1214.507935,0.099610,0.000000
62.750004,46.822487,-1214.552368,0.004850,0.003896,0.098950,208.276825,10.610126,0.989504,-1214.552368,0.100008,0.000000
62.990002,47.648781,-1214.552368,0.004894,0.003915,0.099453,211.952362,10.797368,0.994535,-1214.552368,0.100407,0.000000
63.230003,47.696449,-1214.552368,0.004915,0.003922,0.099618,212.164398,10.808169,0.996182,-1214.552368,0.100815,0.000000
63.470001,48.471352,-1214.596802,0.004919,0.003939,0.100061,215.611343,10.983766,1.000605,-1214.596802,0.101214,0.000000
63.710003,49.537086,-1214.463379,0.004924,0.003960,0.100572,220.351959,11.225265,1.005722,-1214.463379,0.101613,0.000000
63.950005,49.796631,-1214.596802,0.004911,0.003970,0.100832,221.506470,11.284078,1.008323,-1214.596802,0.102012,0.000000
64.190002,50.861610,-1214.463379,0.004919,0.003992,0.101387,226.243744,11.525406,1.013874,-1214.463379,0.102411,0.000000
64.430000,51.650673,-1214.507935,0.004958,0.004006,0.101760,229.753662,11.704209,1.017603,-1214.507935,0.102810,0.000000
64.670006,52.158958,-1214.552368,0.004915,0.004019,0.102081,232.014633,11.819388,1.020811,-1214.552368,0.103209,0.000000
64.910004,52.722359,-1214.552368,0.004980,0.004034,0.102463,234.520767,11.947058,1.024627,-1214.552368,0.103607,0.000000
65.150002,53.608978,-1214.552368,0.004984,0.004052,0.102922,238.464645,12.147968,1.029224,-1214.552368,0.104015,0.000000
65.389999,54.508629,-1214.552368,0.005001,0.004070,0.103391,242.466492,12.351832,1.033906,-1214.552368,0.104414,0.000000
65.630005,55.299179,-1214.552368,0.004980,0.004086,0.103772,245.983032,12.530973,1.037722,-1214.552368,0.104813,0.000000
65.870003,55.537491,-1214.552368,0.004997,0.004098,0.104084,247.043091,12.584975,1.040844,-1214.552368,0.105212,0.000000
66.110001,56.645676,-1214.463379,0.005032,0.004117,0.104561,251.972549,12.836094,1.045614,-1214.463379,0.105611,0.000000
66.350006,57.869659,-1214.596802,0.005010,0.004136,0.105056,257.417114,13.113453,1.050557,-1214.596802,0.106010,0.000000
66.590004,58.294914,-1214.552368,0.005023,0.004150,0.105403,259.308716,13.209816,1.054026,-1214.552368,0.106409,0.000000
66.830002,58.742134,-1214.552368,0.005019,0.004161,0.105697,261.298065,13.311158,1.056975,-1214.552368,0.106816,0.000000
67.070000,59.541245,-1214.552368,0.005023,0.004176,0.106070,264.852692,13.492238,1.060704,-1214.552368,0.107215,0.000000
67.310005,60.278542,-1214.507935,0.005083,0.004192,0.106487,268.132355,13.659313,1.064866,-1214.507935,0.107614,0.000000
67.550003,61.215057,-1214.596802,0.005096,0.004209,0.106903,272.298187,13.871530,1.069029,-1214.596802,0.108013,0.000000
67.790001,61.801170,-1214.507935,0.005057,0.004220,0.107180,274.905334,14.004346,1.071804,-1214.507935,0.108412,0.000000
68.030006,62.477028,-1214.596802,0.005040,0.004233,0.107510,277.911713,14.157497,1.075100,-1214.596802,0.108811,0.000000
68.270004,64.118073,-1214.552368,0.005070,0.004261,0.108221,285.211426,14.529363,1.082211,-1214.552368,0.109210,0.000000
68.510002,65.215820,-1214.507935,0.005152,0.004277,0.108646,290.094452,14.778116,1.086460,-1214.507935,0.109609,0.000000
68.750000,65.977707,-1214.596802,0.005122,0.004293,0.109045,293.483490,14.950762,1.090450,-1214.596802,0.110016,0.000000
68.990005,66.625259,-1214.507935,0.005157,0.004306,0.109383,296.363953,15.097500,1.093832,-1214.507935,0.110415,0.000000
69.230003,67.541290,-1214.552368,0.005096,0.004318,0.109687,300.438660,15.305075,1.096867,-1214.552368,0.110788,0.000000
69.470001,66.857620,-1214.641357,0.005152,0.004313,0.109548,297.397552,15.150153,1.095480,-1214.641357,0.109808,0.000000
69.710007,66.236130,-1214.596802,0.005161,0.004312,0.109513,294.633026,15.009321,1.095132,-1214.596802,0.109548,0.000000
69.950005,65.741989,-1214.596802,0.005170,0.004311,0.109487,292.434967,14.897348,1.094872,-1214.596802,0.109548,0.000000
70.190002,65.361801,-1214.463379,0.005170,0.004310,0.109479,290.743805,14.811195,1.094786,-1214.463379,0.109548,0.000000
70.430000,65.011017,-1214.552368,0.005148,0.004310,0.109479,289.183441,14.731707,1.094786,-1214.552368,0.109548,0.000000
70.670006,64.699722,-1214.685791,0.005148,0.004310,0.109470,287.798737,14.661167,1.094699,-1214.685791,0.109548,0.000000
70.910004,64.431244,-1214.596802,0.005139,0.004310,0.109470,286.604492,14.600328,1.094699,-1214.596802,0.109548,0.000000
71.150002,64.173553,-1214.552368,0.005135,0.004310,0.109470,285.458221,14.541936,1.094699,-1214.552368,0.109548,0.000000
71.390007,63.966141,-1214.507935,0.005161,0.004309,0.109461,284.535614,14.494935,1.094612,-1214.507935,0.109548,0.000000
71.630005,63.755386,-1214.507935,0.005157,0.004309,0.109461,283.598114,14.447177,1.094612,-1214.507935,0.109548,0.000000
71.870003,63.577011,-1214.596802,0.005178,0.004309,0.109461,282.804657,14.406757,1.094612,-1214.596802,0.109548,0.000000
72.110001,63.414658,-1214.552368,0.005213,0.004309,0.109461,282.082489,14.369967,1.094612,-1214.552368,0.109548,0.000000
72.350006,63.223633,-1214.596802,0.005191,0.004309,0.109461,281.232758,14.326680,1.094612,-1214.596802,0.109548,0.000000
72.590004,63.094421,-1214.552368,0.005178,0.004309,0.109453,280.657990,14.297400,1.094525,-1214.552368,0.109548,0.000000
72.830002,62.945473,-1214.596802,0.005217,0.004309,0.109453,279.995453,14.263647,1.094525,-1214.596802,0.109548,0.000000
73.070000,62.814766,-1214.596802,0.005226,0.004309,0.109453,279.414032,14.234030,1.094525,-1214.596802,0.109548,0.000000
73.310005,62.675133,-1214.596802,0.005174,0.004309,0.109453,278.792908,14.202388,1.094525,-1214.596802,0.109548,0.000000
73.550003,62.563042,-1214.596802,0.005165,0.004309,0.109453,278.294312,14.176988,1.094525,-1214.596802,0.109548,0.000000
73.790001,62.458405,-1214.552368,0.005217,0.004309,0.109453,277.828857,14.153276,1.094525,-1214.552368,0.109548,0.000000
74.030006,62.337013,-1214.596802,0.005204,0.004309,0.109453,277.288879,14.125770,1.094525,-1214.596802,0.109548,0.000000
74.270004,62.246529,-1214.596802,0.005221,0.004309,0.109444,276.886383,14.105265,1.094439,-1214.596802,0.109548,0.000000
74.510002,62.137421,-1214.507935,0.005187,0.004309,0.109444,276.401062,14.080541,1.094439,-1214.507935,0.109548,0.000000
74.750000,62.053642,-1214.596802,0.005157,0.004309,0.109444,276.028381,14.061557,1.094439,-1214.596802,0.109548,0.000000
74.990005,61.964272,-1214.596802,0.005187,0.004309,0.109444,275.630859,14.041305,1.094439,-1214.596802,0.109548,0.000000
75.230003,61.870430,-1214.596802,0.005234,0.004309,0.109444,275.213409,14.020041,1.094439,-1214.596802,0.109548,0.000000
75.470001,61.797447,-1214.641357,0.005221,0.004309,0.109444,274.888763,14.003502,1.094439,-1214.641357,0.109548,0.000000
75.710007,61.714035,-1214.596802,0.005161,0.004309,0.109444,274.517731,13.984600,1.094439,-1214.596802,0.109548,0.000000
75.950005,61.642540,-1214.596802,0.005165,0.004309,0.109444,274.199707,13.968399,1.094439,-1214.596802,0.109548,0.000000
76.190002,61.564339,-1214.596802,0.005204,0.004309,0.109444,273.851868,13.950679,1.094439,-1214.596802,0.109548,0.000000
76.430000,61.502159,-1214.552368,0.005234,0.004309,0.109444,273.575256,13.936588,1.094439,-1214.552368,0.109548,0.000000
76.670006,61.433266,-1214.596802,0.005178,0.004309,0.109444,273.268799,13.920977,1.094439,-1214.596802,0.109548,0.000000
76.910004,61.360283,-1214.552368,0.005187,0.004309,0.109444,272.944183,13.904439,1.094439,-1214.552368,0.109548,0.000000
77.150002,61.316711,-1214.596802,0.005208,0.004309,0.109444,272.750366,13.894566,1.094439,-1214.596802,0.109548,0.000000
77.390007,61.232185,-1214.552368,0.005165,0.004309,0.109444,272.374359,13.875411,1.094439,-1214.552368,0.109548,0.000000
77.630005,61.178192,-1214.596802,0.005213,0.004309,0.109444,272.134186,13.863176,1.094439,-1214.596802,0.109548,0.000000
77.870003,61.117126,-1214.641357,0.005217,0.004309,0.109444,271.862549,13.849339,1.094439,-1214.641357,0.109548,0.000000
78.110001,61.055679,-1214.507935,0.005230,0.004309,0.109444,271.589233,13.835414,1.094439,-1214.507935,0.109548,0.000000
78.350006,61.000946,-1214.641357,0.005191,0.004309,0.109444,271.345764,13.823012,1.094439,-1214.641357,0.109548,0.000000
78.590004,60.947693,-1214.596802,0.005230,0.004309,0.109444,271.108887,13.810945,1.094439,-1214.596802,0.109548,0.000000
78.830002,60.899284,-1214.552368,0.005217,0.004309,0.109444,270.893555,13.799975,1.094439,-1214.552368,0.109548,0.000000
79.070007,60.838585,-1214.596802,0.005182,0.004309,0.109444,270.623535,13.786221,1.094439,-1214.596802,0.109548,0.000000
79.310005,60.796883,-1214.552368,0.005152,0.004309,0.109444,270.438049,13.776771,1.094439,-1214.552368,0.109548,0.000000
79.550003,60.744377,-1214.641357,0.005195,0.004309,0.109444,270.204498,13.764873,1.094439,-1214.641357,0.109548,0.000000
79.790001,60.672882,-1214.552368,0.005208,0.004309,0.109444,269.886444,13.748672,1.094439,-1214.552368,0.109548,0.000000
80.030006,60.633041,-1214.596802,0.005234,0.004309,0.109444,269.709229,13.739643,1.094439,-1214.596802,0.109548,0.000000
80.270004,60.582771,-1214.641357,0.005226,0.004309,0.109444,269.485626,13.728251,1.094439,-1214.641357,0.109548,0.000000
80.510002,60.551865,-1214.552368,0.005165,0.004309,0.109444,269.348145,13.721249,1.094439,-1214.552368,0.109548,0.000000
80.750008,60.503082,-1214.596802,0.005157,0.004309,0.109444,269.131165,13.710195,1.094439,-1214.596802,0.109548,0.000000
80.990005,60.458771,-1214.596802,0.005217,0.004308,0.109435,268.934052,13.700153,1.094352,-1214.596802,0.109548,0.000000
81.230003,60.430840,-1214.552368,0.005213,0.004308,0.109435,268.809814,13.693824,1.094352,-1214.552368,0.109548,0.000000
81.470001,60.379456,-1214.596802,0.005226,0.004308,0.109435,268.581238,13.682179,1.094352,-1214.596802,0.109548,0.000000
81.710007,60.346313,-1214.596802,0.005195,0.004308,0.109435,268.433807,13.674670,1.094352,-1214.596802,0.109548,0.000000
81.950005,60.310562,-1214.596802,0.005191,0.004308,0.109435,268.274780,13.666569,1.094352,-1214.596802,0.109548,0.000000
82.190002,60.271461,-1214.641357,0.005221,0.004308,0.109435,268.100861,13.657708,1.094352,-1214.641357,0.109548,0.000000
82.430000,60.236092,-1214.596802,0.005204,0.004308,0.109435,267.943512,13.649693,1.094352,-1214.596802,0.109548,0.000000
82.670006,60.185822,-1214.596802,0.005200,0.004308,0.109435,267.719910,13.638302,1.094352,-1214.596802,0.109548,0.000000
82.910004,60.172043,-1214.596802,0.005187,0.004308,0.109435,267.658600,13.635180,1.094352,-1214.596802,0.109548,0.000000
83.150002,60.113205,-1214.596802,0.005217,0.004308,0.109435,267.396881,13.621846,1.094352,-1214.596802,0.109548,0.000000
83.390007,60.089005,-1214.641357,0.005178,0.004308,0.109435,267.289246,13.616364,1.094352,-1214.641357,0.109548,0.000000
83.630005,60.047668,-1214.596802,0.005230,0.004308,0.109435,267.105377,13.606996,1.094352,-1214.596802,0.109548,0.000000
83.870003,60.014900,-1214.641357,0.005217,0.004308,0.109435,266.959595,13.599571,1.094352,-1214.641357,0.109548,0.000000
84.110001,59.982880,-1214.596802,0.005234,0.004308,0.109435,266.817169,13.592316,1.094352,-1214.596802,0.109548,0.000000
84.350006,59.950478,-1214.641357,0.005234,0.004308,0.109435,266.673035,13.584972,1.094352,-1214.641357,0.109548,0.000000
84.590004,59.912125,-1214.596802,0.005191,0.004308,0.109435,266.502441,13.576281,1.094352,-1214.596802,0.109548,0.000000
84.830002,59.896858,-1214.596802,0.005221,0.004308,0.109435,266.434540,13.572823,1.094352,-1214.596802,0.109548,0.000000
85.070007,59.847336,-1214.641357,0.005191,0.004308,0.109435,266.214233,13.561601,1.094352,-1214.641357,0.109548,0.000000
85.310005,59.816429,-1214.552368,0.005221,0.004308,0.109435,266.076752,13.554596,1.094352,-1214.552368,0.109548,0.000000
85.550003,59.772484,-1214.685791,0.005170,0.004308,0.109435,265.881287,13.544639,1.094352,-1214.685791,0.109548,0.000000
85.790001,59.759827,-1214.596802,0.005221,0.004308,0.109435,265.824982,13.541770,1.094352,-1214.596802,0.109548,0.000000
86.030006,59.721100,-1214.641357,0.005204,0.004308,0.109435,265.652710,13.532994,1.094352,-1214.641357,0.109548,0.000000
86.270004,59.690193,-1214.730347,0.005256,0.004308,0.109435,265.515228,13.525991,1.094352,-1214.730347,0.109548,0.000000
86.510002,59.665985,-1214.596802,0.005221,0.004308,0.109435,265.407562,13.520505,1.094352,-1214.596802,0.109548,0.000000
86.750008,59.638435,-1214.641357,0.005238,0.004308,0.109435,265.285004,13.514263,1.094352,-1214.641357,0.109548,0.000000
86.990005,59.605659,-1214.641357,0.005200,0.004308,0.109435,265.139221,13.506836,1.094352,-1214.641357,0.109548,0.000000
87.230003,59.574753,-1214.596802,0.005174,0.004308,0.109435,265.001740,13.499832,1.094352,-1214.596802,0.109548,0.000000
87.470001,59.560234,-1214.641357,0.005213,0.004308,0.109435,264.937164,13.496542,1.094352,-1214.641357,0.109548,0.000000
87.710007,59.520020,-1214.641357,0.005221,0.004308,0.109435,264.758270,13.487430,1.094352,-1214.641357,0.109548,0.000000
87.950005,59.502518,-1214.641357,0.005174,0.004308,0.109435,264.680420,13.483463,1.094352,-1214.641357,0.109548,0.000000
88.190002,59.468254,-1214.641357,0.005208,0.004308,0.109435,264.528015,13.475698,1.094352,-1214.641357,0.109548,0.000000
88.430008,59.445168,-1214.596802,0.005182,0.004308,0.109435,264.425323,13.470468,1.094352,-1214.596802,0.109548,0.000000
88.670006,59.410912,-1214.641357,0.005230,0.004308,0.109435,264.272919,13.462705,1.094352,-1214.641357,0.109548,0.000000
88.910004,59.405327,-1214.596802,0.005226,0.004308,0.109435,264.248077,13.461439,1.094352,-1214.596802,0.109548,0.000000
89.150002,59.370697,-1214.730347,0.005243,0.004308,0.109435,264.094055,13.453592,1.094352,-1214.730347,0.109548,0.000000
89.390007,59.343887,-1214.641357,0.005187,0.004308,0.109435,263.974792,13.447517,1.094352,-1214.641357,0.109548,0.000000
89.630005,59.334946,-1214.641357,0.005243,0.004308,0.109435,263.935028,13.445491,1.094352,-1214.641357,0.109548,0.000000
89.870003,59.296219,-1214.730347,0.005191,0.004308,0.109435,263.762756,13.436715,1.094352,-1214.730347,0.109548,0.000000
90.110001,59.279839,-1214.641357,0.005187,0.004308,0.109435,263.689880,13.433003,1.094352,-1214.641357,0.109548,0.000000
90.350006,59.247810,-1214.641357,0.005200,0.004308,0.109435,263.547424,13.425746,1.094352,-1214.641357,0.109548,0.000000
90.590004,59.247810,-1214.596802,0.005200,0.004308,0.109435,263.547424,13.425746,1.094352,-1214.596802,0.109548,0.000000
90.830002,59.217651,-1214.596802,0.005204,0.004308,0.109435,263.413269,13.418911,1.094352,-1214.596802,0.109548,0.000000
91.070007,59.178177,-1214.685791,0.005191,0.004308,0.109435,263.237671,13.409966,1.094352,-1214.685791,0.109548,0.000000
91.310005,59.168869,-1214.596802,0.005182,0.004308,0.109435,263.196289,13.407858,1.094352,-1214.596802,0.109548,0.000000
91.550003,59.142059,-1214.685791,0.005204,0.004308,0.109435,263.077026,13.401782,1.094352,-1214.685791,0.109548,0.000000
91.790001,59.120834,-1214.685791,0.005213,0.004308,0.109435,262.982605,13.396973,1.094352,-1214.685791,0.109548,0.000000
92.030006,59.104080,-1214.641357,0.005178,0.004308,0.109435,262.908081,13.393176,1.094352,-1214.641357,0.109548,0.000000
92.270004,59.072426,-1214.685791,0.005243,0.004308,0.109435,262.767273,13.386003,1.094352,-1214.685791,0.109548,0.000000
92.510002,59.056412,-1214.596802,0.005195,0.004308,0.109435,262.696045,13.382375,1.094352,-1214.596802,0.109548,0.000000
92.750008,59.033699,-1214.641357,0.005234,0.004308,0.109435,262.595001,13.377228,1.094352,-1214.641357,0.109548,0.000000
92.990005,59.018059,-1214.685791,0.005247,0.004308,0.109435,262.525452,13.373684,1.094352,-1214.685791,0.109548,0.000000
93.230003,58.989014,-1214.596802,0.005217,0.004308,0.109435,262.396240,13.367102,1.094352,-1214.596802,0.109548,0.000000
93.470001,58.989761,-1214.685791,0.005234,0.004308,0.109435,262.399567,13.367271,1.094352,-1214.685791,0.109548,0.000000
93.710007,58.954758,-1214.596802,0.005170,0.004308,0.109435,262.243866,13.359339,1.094352,-1214.596802,0.109548,0.000000
93.950005,58.940605,-1214.641357,0.005238,0.004308,0.109435,262.180908,13.356133,1.094352,-1214.641357,0.109548,0.000000
94.190002,58.922356,-1214.596802,0.005200,0.004308,0.109435,262.099731,13.351997,1.094352,-1214.596802,0.109548,0.000000
94.430008,58.904114,-1214.641357,0.005200,0.004308,0.109435,262.018585,13.347862,1.094352,-1214.641357,0.109548,0.000000
94.670006,58.876183,-1214.685791,0.005251,0.004308,0.109435,261.894348,13.341534,1.094352,-1214.685791,0.109548,0.000000
94.910004,58.878418,-1214.596802,0.005247,0.004308,0.109435,261.904297,13.342040,1.094352,-1214.596802,0.109548,0.000000
95.150002,58.859055,-1214.596802,0.005247,0.004308,0.109435,261.818146,13.337652,1.094352,-1214.596802,0.109548,0.000000
95.390007,58.816231,-1214.596802,0.005247,0.004308,0.109435,261.627655,13.327949,1.094352,-1214.596802,0.109548,0.000000
95.630005,58.800591,-1214.596802,0.005182,0.004308,0.109435,261.558075,13.324404,1.094352,-1214.596802,0.109548,0.000000
95.870003,58.796127,-1214.685791,0.005226,0.004308,0.109435,261.538239,13.323393,1.094352,-1214.685791,0.109548,0.000000
96.110008,58.762611,-1214.685791,0.005200,0.004308,0.109435,261.389160,13.315798,1.094352,-1214.685791,0.109548,0.000000
96.350006,58.742500,-1214.552368,0.005174,0.004308,0.109435,261.299683,13.311240,1.094352,-1214.552368,0.109548,0.000000
96.590004,58.741013,-1214.641357,0.005204,0.004308,0.109435,261.293060,13.310904,1.094352,-1214.641357,0.109548,0.000000
96.830002,58.725746,-1214.641357,0.005208,0.004308,0.109435,261.225159,13.307445,1.094352,-1214.641357,0.109548,0.000000
97.070007,58.687767,-1214.596802,0.005178,0.004308,0.109435,261.056213,13.298839,1.094352,-1214.596802,0.109548,0.000000
97.310005,58.676964,-1214.552368,0.005208,0.004308,0.109435,261.008179,13.296390,1.094352,-1214.552368,0.109548,0.000000
97.550003,58.673988,-1214.641357,0.005191,0.004308,0.109435,260.994934,13.295715,1.094352,-1214.641357,0.109548,0.000000
97.790001,58.651642,-1214.596802,0.005256,0.004308,0.109435,260.895538,13.290652,1.094352,-1214.596802,0.109548,0.000000
98.030006,58.627441,-1214.596802,0.005182,0.004308,0.109435,260.787872,13.285168,1.094352,-1214.596802,0.109548,0.000000
98.270004,58.624092,-1214.685791,0.005213,0.004308,0.109435,260.772980,13.284410,1.094352,-1214.685791,0.109548,0.000000
98.510002,58.605095,-1214.596802,0.005230,0.004308,0.109435,260.688477,13.280105,1.094352,-1214.596802,0.109548,0.000000
98.750008,58.584991,-1214.552368,0.005217,0.004308,0.109435,260.599060,13.275549,1.094352,-1214.552368,0.109548,0.000000
98.990005,58.573074,-1214.685791,0.005234,0.004308,0.109435,260.546051,13.272849,1.094352,-1214.685791,0.109548,0.000000
99.230003,58.567116,-1214.641357,0.005247,0.004308,0.109435,260.519531,13.271498,1.094352,-1214.641357,0.109548,0.000000
99.470001,58.522804,-1214.596802,0.005187,0.004308,0.109435,260.322449,13.261457,1.094352,-1214.596802,0.109548,0.000000
99.700005,58.514236,-1214.596802,0.005251,0.004308,0.109435,260.284332,13.259515,1.094352,-1214.596802,0.109548,0.000000