File: Data/Symmetrical membranes compression/Millioire Express PES 045um test 2_10302023_172437.csv
Time (sec),S:Load (lbs),S:HL1 (DIM),S:LVDT (in),S:Position (in),Ch:Position (mm),Ch:Load (N),Ch:Stress (MPa),Ch:Strain (mm/mm),Ch:HL1 (DIM),Set Point (),Cycles ()
0.110000,0.007820,-114.627411,-0.000009,-0.000000,-0.000000,0.034786,0.001772,-0.000000,-114.627411,0.000269,0.000000
0.340000,-0.001488,-114.627411,-0.000026,-0.000000,-0.000000,-0.006618,-0.000337,-0.000000,-114.627411,0.000269,0.000000
0.570000,-0.017868,-114.627411,-0.000026,0.000117,0.002966,-0.079481,-0.004049,0.029659,-114.627411,0.004085,0.000000
0.800000,-0.014893,-114.627411,0.000103,0.000259,0.006574,-0.066245,-0.003375,0.065736,-114.627411,0.007918,0.000000
1.030000,-0.011543,-114.538452,0.000263,0.000414,0.010511,-0.051347,-0.002616,0.105107,-114.538452,0.011751,0.000000
1.260000,-0.010796,-114.671890,0.000435,0.000565,0.014353,-0.048021,-0.002446,0.143526,-114.671890,0.015567,0.000000
1.490000,0.033142,-114.627411,0.000595,0.000713,0.018099,0.147423,0.007510,0.180990,-114.627411,0.019400,0.000000
1.720000,0.175766,-114.627411,0.000746,0.000869,0.022071,0.781846,0.039829,0.220709,-114.627411,0.023233,0.000000
1.950000,0.360085,-114.627411,0.000901,0.001011,0.025679,1.601736,0.081596,0.256785,-114.627411,0.027066,0.000000
2.180000,0.696709,-114.671890,0.001074,0.001163,0.029546,3.099115,0.157876,0.295464,-114.671890,0.030795,0.000000
2.410000,0.666550,-114.716370,0.001078,-0.000003,-0.000069,2.964961,0.151042,-0.000694,-114.716370,0.000147,0.000000
2.640000,0.659477,-114.671890,0.001074,-0.000003,-0.000069,2.933501,0.149440,-0.000694,-114.671890,0.000147,0.000000
2.870000,0.643463,-114.627411,0.001078,-0.000003,-0.000069,2.862267,0.145811,-0.000694,-114.627411,0.000434,0.000000
3.100000,0.658356,-114.716370,0.001074,-0.000003,-0.000069,2.928513,0.149186,-0.000694,-114.716370,0.000815,0.000000
3.330000,0.643837,-114.671890,0.001069,-0.000002,-0.000052,2.863930,0.145896,-0.000520,-114.671890,0.001205,0.000000
3.560000,0.655006,-114.671890,0.001095,0.000020,0.000520,2.913614,0.148427,0.005203,-114.671890,0.001587,0.000000
3.790000,0.744377,-114.716370,0.001108,0.000038,0.000954,3.311155,0.168678,0.009540,-114.716370,0.001969,0.000000
4.020000,0.785706,-114.716370,0.001095,0.000051,0.001301,3.494993,0.178043,0.013009,-114.716370,0.002350,0.000000
4.250000,0.875076,-114.716370,0.001147,0.000068,0.001735,3.892534,0.198295,0.017345,-114.716370,0.002732,0.000000
4.480000,0.908218,-114.716370,0.001151,0.000082,0.002073,4.039957,0.205805,0.020727,-114.716370,0.003122,0.000000
4.710000,0.980835,-114.760857,0.001173,0.000094,0.002394,4.362972,0.222260,0.023936,-114.760857,0.003504,0.000000
4.940000,1.016953,-114.716370,0.001164,0.000110,0.002784,4.523631,0.230445,0.027838,-114.716370,0.003885,0.000000
5.170000,1.086960,-114.805336,0.001194,0.000130,0.003304,4.835039,0.246309,0.033041,-114.805336,0.004267,0.000000
5.400000,1.152122,-114.716370,0.001212,0.000145,0.003677,5.124897,0.261075,0.036770,-114.716370,0.004648,0.000000
5.630000,1.169624,-114.716370,0.001246,0.000157,0.003989,5.202749,0.265041,0.039893,-114.716370,0.005039,0.000000
5.860000,1.217659,-114.805336,0.001242,0.000172,0.004380,5.416418,0.275925,0.043795,-114.805336,0.005420,0.000000
6.090000,1.261230,-114.760857,0.001242,0.000182,0.004631,5.610233,0.285799,0.046310,-114.760857,0.005802,0.000000
6.320000,1.340919,-114.760857,0.001281,0.000199,0.005056,5.964708,0.303857,0.050560,-114.760857,0.006183,0.000000
6.550000,1.412041,-114.760857,0.001302,0.000217,0.005507,6.281071,0.319973,0.055069,-114.760857,0.006565,0.000000
6.780000,1.487633,-114.760857,0.001289,0.000228,0.005802,6.617321,0.337102,0.058018,-114.760857,0.006955,0.000000
7.010000,1.548325,-114.849815,0.001315,0.000245,0.006227,6.887292,0.350855,0.062267,-114.849815,0.007337,0.000000
7.240000,1.649239,-114.849815,0.001350,0.000268,0.006808,7.336180,0.373723,0.068078,-114.849815,0.007718,0.000000
7.470000,1.649239,-114.805336,0.001371,0.000281,0.007129,7.336180,0.373723,0.071287,-114.805336,0.008100,0.000000
7.700000,1.695786,-114.760857,0.001375,0.000296,0.007510,7.543231,0.384270,0.075102,-114.760857,0.008481,0.000000
7.930000,1.772865,-114.805336,0.001397,0.000309,0.007848,7.886099,0.401737,0.078485,-114.805336,0.008872,0.000000
8.160001,1.900589,-114.894295,0.001423,0.000329,0.008369,8.454242,0.430680,0.083688,-114.894295,0.009253,0.000000
8.390000,1.923309,-114.849815,0.001440,0.000340,0.008638,8.555307,0.435828,0.086376,-114.849815,0.009635,0.000000
8.620001,1.981766,-114.894295,0.001431,0.000352,0.008950,8.815334,0.449075,0.089498,-114.894295,0.010017,0.000000
8.850000,2.064438,-114.805336,0.001449,0.000372,0.009453,9.183078,0.467808,0.094528,-114.805336,0.010407,0.000000
9.080001,2.161255,-114.894295,0.001453,0.000388,0.009843,9.613742,0.489747,0.098431,-114.894295,0.010788,0.000000
9.310000,2.199234,-114.849815,0.001479,0.000401,0.010190,9.782681,0.498354,0.101900,-114.849815,0.011170,0.000000
9.540001,2.262535,-114.938774,0.001513,0.000417,0.010598,10.064259,0.512698,0.105975,-114.938774,0.011551,0.000000
9.770000,2.288979,-114.894295,0.001513,0.000430,0.010927,10.181885,0.518690,0.109271,-114.894295,0.011933,0.000000
10.000000,2.366432,-114.849815,0.001539,0.000447,0.011352,10.526416,0.536241,0.113520,-114.849815,0.012323,0.000000
10.230000,2.485214,-114.938774,0.001522,0.000462,0.011734,11.054785,0.563158,0.117336,-114.938774,0.012705,0.000000
10.460000,2.481491,-114.938774,0.001565,0.000473,0.012002,11.038223,0.562314,0.120025,-114.938774,0.013086,0.000000
10.690001,2.517616,-114.938774,0.001561,0.000479,0.012159,11.198916,0.570500,0.121585,-114.938774,0.013468,0.000000
10.920000,2.706406,-114.849815,0.001591,0.000507,0.012870,12.038693,0.613280,0.128697,-114.849815,0.013850,0.000000
11.150001,2.738800,-114.938774,0.001600,0.000521,0.013225,12.182791,0.620621,0.132252,-114.938774,0.014240,0.000000
11.380000,2.797264,-114.983261,0.001638,0.000534,0.013563,12.442852,0.633869,0.135635,-114.983261,0.014621,0.000000
11.610001,2.912331,-114.938774,0.001651,0.000553,0.014049,12.954694,0.659944,0.140491,-114.938774,0.015003,0.000000
11.840000,2.939880,-114.983261,0.001669,0.000565,0.014361,13.077241,0.666186,0.143613,-114.983261,0.015385,0.000000
12.070001,3.040054,-114.894295,0.001669,0.000582,0.014786,13.522837,0.688886,0.147863,-114.894295,0.015766,0.000000
12.300000,3.119736,-114.938774,0.001681,0.000596,0.015142,13.877277,0.706942,0.151418,-114.938774,0.016156,0.000000
12.530001,3.130913,-114.983261,0.001720,0.000604,0.015341,13.926995,0.709475,0.153412,-114.983261,0.016538,0.000000
12.760000,3.299225,-115.027740,0.001738,0.000626,0.015905,14.675685,0.747615,0.159050,-115.027740,0.016920,0.000000
12.990001,3.348007,-115.027740,0.001733,0.000641,0.016269,14.892680,0.758669,0.162692,-115.027740,0.017301,0.000000
13.220000,3.402740,-115.072220,0.001755,0.000653,0.016590,15.136146,0.771072,0.165900,-115.072220,0.017683,0.000000
13.450001,3.518547,-115.027740,0.001776,0.000672,0.017067,15.651279,0.797314,0.170670,-115.027740,0.018073,0.000000
13.680000,3.519669,-115.027740,0.001785,0.000680,0.017275,15.656268,0.797568,0.172752,-115.027740,0.018455,0.000000
13.910001,3.656326,-115.027740,0.001802,0.000698,0.017717,16.264153,0.828535,0.177175,-115.027740,0.018836,0.000000
14.140000,3.758362,-115.027740,0.001819,0.000714,0.018125,16.718029,0.851657,0.181250,-115.027740,0.019218,0.000000
14.370001,3.785172,-115.027740,0.001837,0.000723,0.018368,16.837284,0.857732,0.183679,-115.027740,0.019599,0.000000
14.600000,3.928902,-115.116699,0.001837,0.000743,0.018862,17.476627,0.890302,0.188622,-115.116699,0.019990,0.000000
14.830001,4.010826,-115.027740,0.001876,0.000759,0.019287,17.841045,0.908866,0.192872,-115.027740,0.020371,0.000000
15.060000,4.081581,-115.116699,0.001884,0.000776,0.019712,18.155779,0.924899,0.197121,-115.116699,0.020753,0.000000
15.290001,4.166847,-115.072220,0.001888,0.000791,0.020102,18.535063,0.944221,0.201023,-115.072220,0.021134,0.000000
15.520000,4.256966,-115.027740,0.001914,0.000807,0.020493,18.935928,0.964642,0.204926,-115.027740,0.021516,0.000000
15.750001,4.347450,-115.116699,0.001932,0.000822,0.020874,19.338425,0.985146,0.208742,-115.116699,0.021906,0.000000
15.980000,4.447990,-115.116699,0.001953,0.000836,0.021247,19.785650,1.007929,0.212471,-115.116699,0.022288,0.000000
16.210001,4.541458,-115.161179,0.001970,0.000853,0.021655,20.201414,1.029109,0.216546,-115.161179,0.022669,0.000000
16.440001,4.593590,-115.116699,0.001962,0.000865,0.021976,20.433308,1.040922,0.219756,-115.116699,0.023051,0.000000
16.670000,4.740677,-115.072220,0.001983,0.000882,0.022400,21.087584,1.074253,0.224004,-115.072220,0.023432,0.000000
16.900002,4.822227,-115.116699,0.002001,0.000899,0.022834,21.450338,1.092732,0.228341,-115.116699,0.023823,0.000000
17.130001,4.907501,-115.161179,0.002031,0.000914,0.023207,21.829657,1.112056,0.232070,-115.161179,0.024204,0.000000
17.360001,4.933937,-115.161179,0.002035,0.000926,0.023511,21.947248,1.118046,0.235105,-115.161179,0.024586,0.000000
17.590000,5.026657,-115.161179,0.002026,0.000938,0.023831,22.359688,1.139057,0.238314,-115.161179,0.024967,0.000000
17.820002,5.215454,-115.072220,0.002087,0.000958,0.024326,23.199499,1.181839,0.243257,-115.072220,0.025358,0.000000
18.050001,5.349503,-115.116699,0.002108,0.000975,0.024777,23.795776,1.212215,0.247767,-115.116699,0.025739,0.000000
18.280001,5.327911,-115.161179,0.002108,0.000985,0.025011,23.699734,1.207322,0.250109,-115.161179,0.026121,0.000000
18.510000,5.461586,-115.205666,0.002130,0.001003,0.025470,24.294348,1.237613,0.254705,-115.205666,0.026502,0.000000
18.740002,5.585220,-115.250145,0.002130,0.001021,0.025939,24.844301,1.265629,0.259387,-115.250145,0.026884,0.000000
18.970001,5.664162,-115.116699,0.002147,0.001036,0.026303,25.195450,1.283517,0.263030,-115.116699,0.027274,0.000000
19.200001,5.710709,-115.205666,0.002169,0.001050,0.026659,25.402500,1.294065,0.266585,-115.205666,0.027656,0.000000
19.430000,5.802307,-115.205666,0.002207,0.001064,0.027023,25.809952,1.314822,0.270228,-115.205666,0.028037,0.000000
19.660002,5.841034,-115.294624,0.002207,0.001073,0.027266,25.982216,1.323597,0.272656,-115.294624,0.028419,0.000000
19.890001,6.088295,-115.250145,0.002207,0.001097,0.027855,27.082088,1.379627,0.278553,-115.250145,0.028801,0.000000
20.120001,6.106537,-115.205666,0.002233,0.001107,0.028124,27.163233,1.383761,0.281241,-115.205666,0.029191,0.000000
20.350000,6.211548,-115.250145,0.002264,0.001123,0.028514,27.630344,1.407557,0.285145,-115.250145,0.029572,0.000000
20.580002,6.275970,-115.294624,0.002238,0.001137,0.028870,27.916910,1.422155,0.288699,-115.294624,0.029954,0.000000
20.810001,6.436836,-115.383591,0.002298,0.001154,0.029312,28.632477,1.458608,0.293123,-115.383591,0.030336,0.000000
21.040001,6.554878,-115.250145,0.002294,0.001170,0.029720,29.157555,1.485357,0.297198,-115.250145,0.030717,0.000000
21.270000,6.544449,-115.294624,0.002324,0.001183,0.030058,29.111162,1.482993,0.300581,-115.294624,0.031107,0.000000
21.500002,6.597328,-115.250145,0.002311,0.001194,0.030318,29.346382,1.494976,0.303182,-115.250145,0.031489,0.000000
21.730001,6.751488,-115.294624,0.002337,0.001210,0.030734,30.032118,1.529909,0.307345,-115.294624,0.031871,0.000000
21.960001,6.881821,-115.250145,0.002341,0.001227,0.031168,30.611868,1.559443,0.311681,-115.250145,0.032252,0.000000
22.190001,6.812927,-115.294624,0.002367,0.001231,0.031272,30.305414,1.543831,0.312722,-115.294624,0.032634,0.000000
22.420002,7.067261,-115.250145,0.002363,0.001253,0.031836,31.436747,1.601464,0.318359,-115.250145,0.033024,0.000000
22.650002,7.282494,-115.339104,0.002402,0.001276,0.032408,32.394150,1.650237,0.324083,-115.339104,0.033406,0.000000
22.880001,7.311905,-115.383591,0.002432,0.001290,0.032772,32.524979,1.656901,0.327725,-115.383591,0.033787,0.000000
23.110001,7.331268,-115.339104,0.002432,0.001306,0.033180,32.611111,1.661289,0.331801,-115.339104,0.034169,0.000000
23.340002,7.397179,-115.339104,0.002453,0.001318,0.033475,32.904293,1.676225,0.334749,-115.339104,0.034550,0.000000
23.570002,7.534584,-115.294624,0.002466,0.001333,0.033857,33.515503,1.707361,0.338565,-115.294624,0.034941,0.000000
23.800001,7.625443,-115.294624,0.002488,0.001346,0.034195,33.919662,1.727950,0.341947,-115.294624,0.035322,0.000000
24.030001,7.734550,-115.383591,0.002479,0.001363,0.034628,34.404999,1.752674,0.346284,-115.383591,0.035704,0.000000
24.260000,7.852592,-115.383591,0.002479,0.001375,0.034932,34.930077,1.779423,0.349319,-115.383591,0.036085,0.000000
24.490002,7.999680,-115.383591,0.002518,0.001395,0.035426,35.584351,1.812753,0.354262,-115.383591,0.036467,0.000000
24.720001,8.096123,-115.294624,0.002535,0.001410,0.035816,36.013351,1.834608,0.358165,-115.294624,0.036857,0.000000
24.950001,8.141930,-115.428070,0.002557,0.001420,0.036059,36.217113,1.844988,0.360593,-115.428070,0.037239,0.000000
25.180000,8.271141,-115.383591,0.002587,0.001440,0.036580,36.791874,1.874267,0.365796,-115.383591,0.037620,0.000000
25.410002,8.347473,-115.383591,0.002570,0.001453,0.036909,37.131416,1.891564,0.369092,-115.383591,0.038002,0.000000
25.640001,8.502380,-115.383591,0.002630,0.001472,0.037386,37.820477,1.926667,0.373862,-115.383591,0.038392,0.000000
25.870001,8.541107,-115.383591,0.002634,0.001484,0.037698,37.992741,1.935443,0.376983,-115.383591,0.038774,0.000000
26.100000,8.671066,-115.428070,0.002647,0.001498,0.038037,38.570827,1.964892,0.380366,-115.428070,0.039155,0.000000
26.330002,8.783524,-115.428070,0.002652,0.001512,0.038409,39.071064,1.990375,0.384095,-115.428070,0.039537,0.000000
26.560001,9.021843,-115.428070,0.002669,0.001532,0.038921,40.131161,2.044379,0.389211,-115.428070,0.039918,0.000000
26.790001,9.029289,-115.428070,0.002686,0.001544,0.039207,40.164284,2.046066,0.392073,-115.428070,0.040309,0.000000
27.020000,9.122009,-115.383591,0.002699,0.001561,0.039650,40.576725,2.067077,0.396496,-115.383591,0.040690,0.000000
27.250002,9.177864,-115.428070,0.002725,0.001576,0.040023,40.825180,2.079734,0.400225,-115.428070,0.041072,0.000000
27.480001,9.197601,-115.517029,0.002738,0.001587,0.040309,40.912975,2.084206,0.403087,-115.517029,0.041453,0.000000
27.710001,9.357353,-115.517029,0.002742,0.001602,0.040682,41.623585,2.120407,0.406816,-115.517029,0.041835,0.000000
27.940001,9.545769,-115.428070,0.002759,0.001618,0.041098,42.461700,2.163102,0.410979,-115.428070,0.042225,0.000000
28.170002,9.659348,-115.428070,0.002777,0.001633,0.041488,42.966923,2.188839,0.414881,-115.428070,0.042607,0.000000
28.400002,9.849625,-115.517029,0.002790,0.001653,0.041991,43.813320,2.231957,0.419911,-115.517029,0.042988,0.000000
28.630001,9.975487,-115.517029,0.002798,0.001671,0.042433,44.373180,2.260478,0.424334,-115.517029,0.043370,0.000000
28.860001,10.053688,-115.517029,0.002824,0.001686,0.042824,44.721039,2.278198,0.428236,-115.517029,0.043752,0.000000
29.090002,10.100235,-115.517029,0.002850,0.001699,0.043162,44.928089,2.288746,0.431619,-115.517029,0.044142,0.000000
29.320002,10.183647,-115.561508,0.002854,0.001713,0.043517,45.299126,2.307647,0.435174,-115.561508,0.044523,0.000000
29.550001,10.392548,-115.517029,0.002880,0.001730,0.043951,46.228359,2.354985,0.439511,-115.517029,0.044905,0.000000
29.780001,10.500534,-115.561508,0.002906,0.001745,0.044324,46.708710,2.379455,0.443240,-115.561508,0.045287,0.000000
30.010002,10.434998,-115.561508,0.002884,0.001753,0.044515,46.417187,2.364604,0.445147,-115.561508,0.045668,0.000000
30.240002,10.863968,-115.517029,0.002932,0.001777,0.045130,48.325344,2.461810,0.451304,-115.517029,0.046058,0.000000
30.470001,10.581711,-115.561508,0.002923,0.001777,0.045139,47.069801,2.397850,0.451391,-115.561508,0.046440,0.000000
30.700001,11.038239,-115.561508,0.002953,0.001805,0.045859,49.100536,2.501301,0.458589,-115.561508,0.046822,0.000000
30.930002,11.136543,-115.561508,0.002962,0.001822,0.046267,49.537819,2.523577,0.462666,-115.561508,0.047203,0.000000
31.160002,11.141388,-115.561508,0.002988,0.001833,0.046553,49.559368,2.524675,0.465527,-115.561508,0.047585,0.000000
31.390001,11.309700,-115.605995,0.003009,0.001852,0.047030,50.308060,2.562815,0.470297,-115.605995,0.047975,0.000000
31.620001,11.475777,-115.561508,0.003027,0.001865,0.047377,51.046803,2.600448,0.473766,-115.561508,0.048357,0.000000
31.850002,11.399071,-115.605995,0.003031,0.001874,0.047602,50.705601,2.583066,0.476021,-115.605995,0.048738,0.000000
32.080002,11.327202,-115.650475,0.003031,0.001887,0.047923,50.385910,2.566781,0.479229,-115.650475,0.049120,0.000000
32.310001,11.931564,-115.650475,0.003074,0.001910,0.048504,53.074249,2.703731,0.485040,-115.650475,0.049501,0.000000
32.540001,11.946083,-115.650475,0.003078,0.001922,0.048807,53.138832,2.707021,0.488075,-115.650475,0.049892,0.000000
32.770000,12.107323,-115.605995,0.003117,0.001940,0.049276,53.856060,2.743559,0.492758,-115.605995,0.050273,0.000000
33.000000,12.302071,-115.650475,0.003109,0.001958,0.049735,54.722343,2.787689,0.497354,-115.650475,0.050655,0.000000
33.230003,12.418625,-115.694954,0.003122,0.001972,0.050091,55.240803,2.814101,0.500910,-115.694954,0.051036,0.000000
33.460003,12.499428,-115.650475,0.003156,0.001988,0.050490,55.600231,2.832411,0.504899,-115.650475,0.051418,0.000000
33.690002,12.497192,-115.605995,0.003156,0.001998,0.050741,55.590286,2.831904,0.507414,-115.605995,0.051808,0.000000
33.920002,12.630501,-115.650475,0.003178,0.002012,0.051097,56.183273,2.862112,0.510969,-115.650475,0.052190,0.000000
34.150002,12.920952,-115.650475,0.003182,0.002030,0.051565,57.475266,2.927930,0.515653,-115.650475,0.052571,0.000000
34.380001,12.932495,-115.694954,0.003178,0.002043,0.051895,57.526611,2.930545,0.518948,-115.694954,0.052953,0.000000
34.610001,13.038628,-115.694954,0.003199,0.002055,0.052198,57.998711,2.954595,0.521983,-115.694954,0.053343,0.000000
34.840000,13.297798,-115.694954,0.003229,0.002073,0.052658,59.151562,3.013324,0.526580,-115.694954,0.053725,0.000000
35.070004,13.248642,-115.739433,0.003255,0.002084,0.052935,58.932903,3.002185,0.529354,-115.739433,0.054106,0.000000
35.300003,13.578194,-115.783913,0.003238,0.002103,0.053412,60.398823,3.076863,0.534124,-115.783913,0.054488,0.000000
35.530003,13.675751,-115.694954,0.003277,0.002115,0.053733,60.832779,3.098969,0.537333,-115.694954,0.054869,0.000000
35.760002,13.579681,-115.694954,0.003277,0.002123,0.053915,60.405441,3.077200,0.539155,-115.694954,0.055260,0.000000
35.990002,14.124832,-115.694954,0.003298,0.002150,0.054609,62.830391,3.200733,0.546092,-115.694954,0.055641,0.000000
36.220001,14.229843,-115.739433,0.003337,0.002164,0.054974,63.297504,3.224529,0.549735,-115.739433,0.056023,0.000000
36.450001,14.351982,-115.694954,0.003350,0.002181,0.055390,63.840805,3.252206,0.553898,-115.694954,0.056404,0.000000
36.680000,14.442467,-115.783913,0.003346,0.002196,0.055771,64.243301,3.272710,0.557713,-115.783913,0.056786,0.000000
36.910000,14.608177,-115.694954,0.003385,0.002210,0.056127,64.980415,3.310260,0.561269,-115.694954,0.057176,0.000000
37.140003,14.852081,-115.739433,0.003393,0.002227,0.056569,66.065353,3.365530,0.565691,-115.739433,0.057558,0.000000
37.370003,14.997307,-115.739433,0.003410,0.002243,0.056968,66.711349,3.398438,0.569681,-115.739433,0.057939,0.000000
37.600002,14.975334,-115.783913,0.003410,0.002252,0.057211,66.613617,3.393459,0.572110,-115.783913,0.058321,0.000000
37.830002,15.164871,-115.828400,0.003402,0.002268,0.057618,67.456718,3.436409,0.576185,-115.828400,0.058703,0.000000
38.060001,15.478783,-115.783913,0.003454,0.002289,0.058130,68.853065,3.507542,0.581302,-115.783913,0.059093,0.000000
38.290001,15.508942,-115.783913,0.003479,0.002300,0.058416,68.987221,3.514376,0.584164,-115.783913,0.059474,0.000000
38.520000,15.694016,-115.783913,0.003462,0.002316,0.058815,69.810471,3.556315,0.588153,-115.783913,0.059856,0.000000
38.750000,15.776306,-115.828400,0.003510,0.002329,0.059145,70.176514,3.574962,0.591448,-115.828400,0.060238,0.000000
38.980003,15.846687,-115.872879,0.003492,0.002339,0.059422,70.489586,3.590911,0.594224,-115.872879,0.060619,0.000000
39.210003,16.394073,-115.828400,0.003514,0.002363,0.060021,72.924484,3.714950,0.600208,-115.828400,0.061009,0.000000
39.440002,16.497963,-115.783913,0.003531,0.002377,0.060368,73.386604,3.738492,0.603677,-115.783913,0.061391,0.000000
39.670002,16.362419,-115.828400,0.003566,0.002386,0.060602,72.783676,3.707777,0.606018,-115.828400,0.061773,0.000000
39.900002,16.725853,-115.828400,0.003561,0.002407,0.061131,74.400307,3.790132,0.611308,-115.828400,0.062154,0.000000
40.130001,17.137329,-115.961838,0.003591,0.002425,0.061590,76.230644,3.883374,0.615904,-115.961838,0.062536,0.000000
40.360001,17.149986,-115.872879,0.003587,0.002437,0.061911,76.286949,3.886242,0.619112,-115.872879,0.062926,0.000000
40.590000,17.288139,-115.917358,0.003622,0.002453,0.062310,76.901482,3.917548,0.623102,-115.917358,0.063307,0.000000
40.820004,17.287025,-115.872879,0.003622,0.002464,0.062596,76.896530,3.917296,0.625964,-115.872879,0.063689,0.000000
41.050003,17.322021,-115.917358,0.003652,0.002476,0.062891,77.052200,3.925226,0.628912,-115.917358,0.064071,0.000000
41.280003,17.959526,-116.050804,0.003652,0.002498,0.063446,79.887962,4.069687,0.634463,-116.050804,0.064452,0.000000
41.510002,17.930107,-115.917358,0.003669,0.002508,0.063706,79.757103,4.063020,0.637064,-115.917358,0.064843,0.000000
41.740002,18.190773,-115.872879,0.003691,0.002523,0.064088,80.916603,4.122088,0.640880,-115.872879,0.065224,0.000000
41.970001,18.274551,-115.872879,0.003708,0.002540,0.064522,81.289261,4.141072,0.645217,-115.872879,0.065606,0.000000
42.200001,18.908707,-115.961838,0.003747,0.002560,0.065033,84.110130,4.284774,0.650333,-115.961838,0.065987,0.000000
42.430000,18.853592,-115.961838,0.003734,0.002572,0.065319,83.864967,4.272285,0.653194,-115.961838,0.066369,0.000000
42.660004,18.984665,-115.961838,0.003751,0.002585,0.065666,84.448006,4.301986,0.656663,-115.961838,0.066759,0.000000
42.890003,19.043129,-115.961838,0.003777,0.002600,0.066039,84.708069,4.315235,0.660392,-115.961838,0.067141,0.000000
43.120003,19.482529,-115.917358,0.003777,0.002616,0.066447,86.662613,4.414804,0.664469,-115.917358,0.067522,0.000000
43.350002,19.600571,-115.961838,0.003794,0.002629,0.066768,87.187691,4.441553,0.667677,-115.961838,0.067904,0.000000
43.580002,19.593872,-115.961838,0.003824,0.002640,0.067063,87.157898,4.440035,0.670626,-115.961838,0.068294,0.000000
43.810001,20.172165,-115.961838,0.003824,0.002663,0.067635,89.730270,4.571078,0.676349,-115.961838,0.068676,0.000000
44.040001,20.427238,-115.961838,0.003850,0.002678,0.068017,90.864891,4.628878,0.680165,-115.961838,0.069057,0.000000
44.270000,20.588104,-116.006317,0.003867,0.002695,0.068450,91.580460,4.665331,0.684502,-116.006317,0.069439,0.000000
44.500004,20.745621,-116.050804,0.003867,0.002709,0.068814,92.281128,4.701025,0.688144,-116.050804,0.069820,0.000000
44.730003,20.862541,-116.050804,0.003889,0.002722,0.069135,92.801216,4.727519,0.691353,-116.050804,0.070211,0.000000
44.960003,21.063995,-116.006317,0.003889,0.002736,0.069491,93.697334,4.773170,0.694909,-116.006317,0.070592,0.000000
45.190002,21.431900,-116.006317,0.003923,0.002753,0.069924,95.333855,4.856538,0.699244,-116.006317,0.070974,0.000000
45.420002,21.573776,-116.006317,0.003932,0.002764,0.070202,95.964951,4.888687,0.702019,-116.006317,0.071355,0.000000
45.650002,21.752144,-116.139763,0.003954,0.002781,0.070644,96.758369,4.929106,0.706442,-116.139763,0.071737,0.000000
45.880001,22.353897,-116.095284,0.003958,0.002799,0.071095,99.435097,5.065465,0.710952,-116.095284,0.072127,0.000000
46.110001,22.506195,-116.050804,0.003962,0.002813,0.071459,100.112556,5.099977,0.714594,-116.050804,0.072509,0.000000
46.340004,22.698708,-116.050804,0.004005,0.002827,0.071806,100.968895,5.143600,0.718064,-116.050804,0.072890,0.000000
46.570004,22.997353,-116.095284,0.003997,0.002845,0.072257,102.297333,5.211275,0.722572,-116.095284,0.073272,0.000000
46.800003,23.268066,-116.139763,0.004027,0.002861,0.072674,103.501526,5.272619,0.726736,-116.139763,0.073653,0.000000
47.030003,23.519791,-116.139763,0.004031,0.002874,0.072994,104.621254,5.329661,0.729944,-116.139763,0.074044,0.000000
47.260002,23.654961,-116.050804,0.004036,0.002888,0.073350,105.222519,5.360291,0.733499,-116.050804,0.074425,0.000000
47.490002,23.880249,-116.095284,0.004070,0.002902,0.073706,106.224655,5.411342,0.737055,-116.095284,0.074807,0.000000
47.720001,23.929031,-116.006317,0.004079,0.002910,0.073914,106.441650,5.422396,0.739137,-116.006317,0.075189,0.000000
47.950001,24.795166,-116.095284,0.004053,0.002936,0.074573,110.294411,5.618665,0.745727,-116.095284,0.075570,0.000000
48.180004,24.945236,-116.184242,0.004100,0.002950,0.074928,110.961952,5.652671,0.749283,-116.184242,0.075960,0.000000
48.410004,25.150414,-116.139763,0.004096,0.002964,0.075275,111.874626,5.699165,0.752752,-116.139763,0.076342,0.000000
48.640003,25.390221,-116.050804,0.004126,0.002976,0.075596,112.941345,5.753506,0.755961,-116.050804,0.076724,0.000000
48.870003,25.813980,-116.095284,0.004139,0.002994,0.076056,114.826317,5.849532,0.760558,-116.095284,0.077105,0.000000
49.100002,26.010590,-116.228722,0.004161,0.003008,0.076394,115.700882,5.894084,0.763939,-116.228722,0.077487,0.000000
49.330002,26.243698,-116.184242,0.004174,0.003022,0.076750,116.737801,5.946907,0.767495,-116.184242,0.077877,0.000000
49.560001,26.744537,-116.184242,0.004161,0.003040,0.077218,118.965645,6.060399,0.772178,-116.184242,0.078258,0.000000
49.790001,27.449440,-116.184242,0.004199,0.003061,0.077747,122.101204,6.220132,0.777469,-116.184242,0.078640,0.000000
50.020004,27.529869,-116.184242,0.004225,0.003075,0.078094,122.458977,6.238357,0.780937,-116.184242,0.079022,0.000000
50.250004,27.685150,-116.273209,0.004204,0.003088,0.078441,123.149696,6.273545,0.784406,-116.273209,0.079403,0.000000
50.480003,27.812500,-116.273209,0.004247,0.003101,0.078770,123.716179,6.302403,0.787701,-116.273209,0.079793,0.000000
50.710003,28.576241,-116.184242,0.004251,0.003122,0.079299,127.113464,6.475469,0.792991,-116.184242,0.080175,0.000000
50.940002,28.613846,-116.228722,0.004277,0.003134,0.079594,127.280746,6.483990,0.795940,-116.228722,0.080557,0.000000
51.170002,28.831314,-116.228722,0.004281,0.003144,0.079863,128.248093,6.533269,0.798629,-116.228722,0.080938,0.000000
51.400002,29.191399,-116.228722,0.004299,0.003160,0.080253,129.849823,6.614865,0.802531,-116.228722,0.081320,0.000000
51.630001,29.828529,-116.317688,0.004281,0.003180,0.080773,132.683929,6.759242,0.807734,-116.317688,0.081710,0.000000
51.860001,30.148766,-116.273209,0.004346,0.003194,0.081120,134.108414,6.831808,0.811203,-116.273209,0.082092,0.000000
52.090004,30.355064,-116.273209,0.004337,0.003209,0.081502,135.026077,6.878556,0.815019,-116.273209,0.082473,0.000000
52.320004,30.772118,-116.317688,0.004350,0.003223,0.081875,136.881210,6.973062,0.818748,-116.317688,0.082855,0.000000
52.550003,30.931870,-116.228722,0.004368,0.003236,0.082204,137.591827,7.009262,0.822043,-116.228722,0.083245,0.000000
52.780003,31.539948,-116.273209,0.004368,0.003255,0.082673,140.296692,7.147054,0.826727,-116.273209,0.083627,0.000000
53.010002,31.786087,-116.317688,0.004393,0.003266,0.082968,141.391571,7.202830,0.829675,-116.317688,0.084008,0.000000
53.240002,31.682938,-116.317688,0.004393,0.003273,0.083124,140.932739,7.179456,0.831236,-116.317688,0.084390,0.000000
53.470001,32.016960,-116.273209,0.004419,0.003285,0.083444,142.418549,7.255147,0.834444,-116.273209,0.084771,0.000000
53.700001,33.174667,-116.317688,0.004445,0.003311,0.084104,147.568283,7.517487,0.841036,-116.317688,0.085162,0.000000
53.930004,33.339630,-116.317688,0.004437,0.003325,0.084459,148.302078,7.554868,0.844592,-116.317688,0.085543,0.000000
54.160004,33.921272,-116.273209,0.004458,0.003342,0.084875,150.889359,7.686670,0.848754,-116.273209,0.085925,0.000000
54.390003,34.425461,-116.317688,0.004484,0.003359,0.085318,153.132095,7.800921,0.853177,-116.317688,0.086306,0.000000
54.620003,34.809006,-116.317688,0.004501,0.003375,0.085717,154.838196,7.887834,0.857166,-116.317688,0.086688,0.000000
54.850002,35.271126,-116.362167,0.004506,0.003389,0.086072,156.893799,7.992551,0.860722,-116.362167,0.087078,0.000000
55.080002,35.210800,-116.406647,0.004514,0.003398,0.086306,156.625458,7.978881,0.863063,-116.406647,0.087460,0.000000
55.310001,35.737335,-116.362167,0.004527,0.003415,0.086740,158.967606,8.098196,0.867400,-116.362167,0.087841,0.000000
55.540001,36.515594,-116.362167,0.004531,0.003433,0.087200,162.429474,8.274551,0.871995,-116.362167,0.088223,0.000000
55.770004,36.698425,-116.406647,0.004544,0.003445,0.087494,163.242752,8.315982,0.874945,-116.406647,0.088604,0.000000
56.000004,37.065216,-116.406647,0.004553,0.003462,0.087928,164.874313,8.399098,0.879280,-116.406647,0.088995,0.000000
56.230003,37.645744,-116.362167,0.004575,0.003475,0.088258,167.456635,8.530647,0.882576,-116.362167,0.089376,0.000000
56.460003,37.691544,-116.406647,0.004605,0.003486,0.088535,167.660355,8.541026,0.885351,-116.406647,0.089758,0.000000
56.690002,38.496613,-116.406647,0.004605,0.003502,0.088943,171.241486,8.723457,0.889427,-116.406647,0.090139,0.000000
56.920002,39.170235,-116.362167,0.004613,0.003520,0.089411,174.237900,8.876101,0.894110,-116.362167,0.090521,0.000000
57.150002,39.387703,-116.451126,0.004618,0.003533,0.089749,175.205246,8.925382,0.897492,-116.451126,0.090911,0.000000
57.380001,40.496994,-116.495613,0.004639,0.003554,0.090270,180.139633,9.176750,0.902696,-116.495613,0.091293,0.000000
57.610004,40.802719,-116.406647,0.004648,0.003567,0.090608,181.499557,9.246028,0.906077,-116.406647,0.091675,0.000000
57.840004,41.298340,-116.362167,0.004665,0.003582,0.090981,183.704193,9.358337,0.909806,-116.362167,0.092056,0.000000
58.070004,41.800674,-116.495613,0.004678,0.003598,0.091397,185.938690,9.472169,0.913970,-116.495613,0.092438,0.000000
58.300003,42.109367,-116.495613,0.004678,0.003610,0.091683,187.311829,9.542119,0.916831,-116.495613,0.092828,0.000000
58.530003,43.008652,-116.495613,0.004704,0.003631,0.092229,191.312042,9.745900,0.922295,-116.495613,0.093209,0.000000
58.760002,43.357933,-116.495613,0.004695,0.003643,0.092524,192.865723,9.825048,0.925243,-116.495613,0.093591,0.000000
58.990002,43.551941,-116.451126,0.004721,0.003655,0.092845,193.728714,9.869011,0.928452,-116.451126,0.093973,0.000000
59.220001,44.269127,-116.584572,0.004781,0.003671,0.093253,196.918915,10.031528,0.932528,-116.584572,0.094354,0.000000
59.450005,45.175110,-116.540092,0.004760,0.003691,0.093747,200.948929,10.236826,0.937471,-116.540092,0.094744,0.000000
59.680004,45.529984,-116.540092,0.004734,0.003703,0.094051,202.527481,10.317242,0.940507,-116.540092,0.095126,0.000000
59.910004,46.009972,-116.495613,0.004773,0.003718,0.094441,204.662582,10.426008,0.944409,-116.495613,0.095508,0.000000
60.140003,46.396126,-116.540092,0.004777,0.003731,0.094779,206.380280,10.513513,0.947792,-116.540092,0.095889,0.000000
60.370003,46.545074,-116.540092,0.004794,0.003743,0.095083,207.042831,10.547265,0.950826,-116.540092,0.096271,0.000000
60.600002,47.856194,-116.540092,0.004807,0.003765,0.095620,212.874985,10.844369,0.956204,-116.540092,0.096661,0.000000
60.830002,48.415497,-116.584572,0.004807,0.003779,0.095985,215.362885,10.971108,0.959846,-116.584572,0.097043,0.000000
61.060001,48.499283,-116.495613,0.004842,0.003789,0.096236,215.735580,10.990094,0.962361,-116.495613,0.097424,0.000000
61.290005,49.543045,-116.540092,0.004846,0.003806,0.096678,220.378464,11.226614,0.966783,-116.540092,0.097806,0.000000
61.520004,50.539139,-116.540092,0.004859,0.003826,0.097181,224.809311,11.452332,0.971813,-116.540092,0.098196,0.000000
61.750004,50.825119,-116.629051,0.004863,0.003840,0.097528,226.081421,11.517137,0.975282,-116.629051,0.098578,0.000000
61.980003,51.525177,-116.584572,0.004885,0.003854,0.097901,229.195435,11.675772,0.979011,-116.584572,0.098959,0.000000
62.210003,51.755676,-116.629051,0.004885,0.003865,0.098161,230.220749,11.728004,0.981613,-116.629051,0.099341,0.000000
62.440002,52.435257,-116.540092,0.004915,0.003883,0.098638,233.243668,11.881999,0.986382,-116.540092,0.099722,0.000000
62.670002,53.488327,-116.584572,0.004924,0.003899,0.099046,237.927963,12.120628,0.990459,-116.584572,0.100113,0.000000
62.900002,53.606743,-116.673538,0.004924,0.003908,0.099254,238.454697,12.147462,0.992540,-116.673538,0.100494,0.000000
63.130005,54.332870,-116.584572,0.004932,0.003922,0.099618,241.684677,12.312004,0.996182,-116.584572,0.100876,0.000000
63.360004,54.541397,-116.540092,0.004950,0.003938,0.100034,242.612244,12.359257,1.000345,-116.540092,0.101257,0.000000
63.590004,56.377563,-116.584572,0.004971,0.003959,0.100564,250.779922,12.775338,1.005635,-116.584572,0.101639,0.000000
63.820004,56.722382,-116.629051,0.004950,0.003970,0.100841,252.313751,12.853475,1.008410,-116.629051,0.102029,0.000000
64.050003,57.331215,-116.673538,0.004971,0.003984,0.101197,255.021988,12.991439,1.011966,-116.673538,0.102411,0.000000
64.280006,57.594482,-116.673538,0.005001,0.003994,0.101457,256.193054,13.051097,1.014568,-116.673538,0.102792,0.000000
64.510002,58.743622,-116.673538,0.005014,0.004014,0.101960,261.304687,13.311495,1.019598,-116.673538,0.103174,0.000000
64.740005,59.509590,-116.584572,0.004993,0.004027,0.102289,264.711884,13.485065,1.022893,-116.584572,0.103555,0.000000
64.970001,59.162910,-116.673538,0.005014,0.004028,0.102315,263.169769,13.406507,1.023154,-116.673538,0.103946,0.000000
65.200005,60.595428,-116.718018,0.005036,0.004050,0.102879,269.541931,13.731121,1.028790,-116.718018,0.104327,0.000000
65.430000,62.675873,-116.806976,0.005032,0.004082,0.103677,278.796204,14.202557,1.036769,-116.806976,0.104709,0.000000
65.660004,63.414291,-116.673538,0.005036,0.004095,0.104006,282.080841,14.369884,1.040065,-116.673538,0.105090,0.000000
65.889999,64.035782,-116.629051,0.005088,0.004109,0.104362,284.845398,14.510715,1.043620,-116.629051,0.105472,0.000000
66.120003,64.586884,-116.762497,0.005066,0.004121,0.104665,287.296814,14.635596,1.046655,-116.762497,0.105862,0.000000
66.350006,65.619110,-116.762497,0.005062,0.004139,0.105142,291.888367,14.869503,1.051425,-116.762497,0.106244,0.000000
66.580002,66.399963,-116.762497,0.005101,0.004156,0.105559,295.361786,15.046447,1.055587,-116.762497,0.106625,0.000000
66.810005,66.751862,-116.718018,0.005109,0.004163,0.105741,296.927124,15.126188,1.057409,-116.718018,0.107007,0.000000
67.040001,67.731949,-116.762497,0.005122,0.004171,0.105940,301.286743,15.348279,1.059403,-116.762497,0.106192,0.000000
67.270004,67.049759,-116.718018,0.005131,0.004170,0.105923,298.252228,15.193693,1.059229,-116.718018,0.106192,0.000000
67.500000,66.468857,-116.806976,0.005118,0.004166,0.105828,295.668243,15.062058,1.058276,-116.806976,0.105923,0.000000
67.730003,66.017166,-116.762497,0.005131,0.004165,0.105802,293.659027,14.959704,1.058015,-116.762497,0.105923,0.000000
67.960007,65.619110,-116.762497,0.005144,0.004165,0.105793,291.888367,14.869503,1.057929,-116.762497,0.105923,0.000000
68.190002,65.283218,-116.718018,0.005139,0.004165,0.105784,290.394257,14.793388,1.057842,-116.718018,0.105923,0.000000
68.420006,64.996124,-116.806976,0.005157,0.004165,0.105784,289.117187,14.728333,1.057842,-116.806976,0.105923,0.000000
68.650002,64.744034,-116.806976,0.005139,0.004164,0.105776,287.995850,14.671207,1.057755,-116.806976,0.105923,0.000000
68.880005,64.509811,-116.851456,0.005152,0.004164,0.105776,286.953979,14.618133,1.057755,-116.851456,0.105923,0.000000
69.110001,64.306870,-116.762497,0.005144,0.004164,0.105776,286.051239,14.572145,1.057755,-116.762497,0.105923,0.000000
69.340004,64.099457,-116.806976,0.005148,0.004164,0.105767,285.128632,14.525145,1.057669,-116.806976,0.105923,0.000000
69.570000,63.941940,-116.806976,0.005144,0.004164,0.105767,284.427948,14.489450,1.057669,-116.806976,0.105923,0.000000
69.800003,63.776978,-116.940422,0.005126,0.004164,0.105767,283.694153,14.452070,1.057669,-116.940422,0.105923,0.000000
70.030006,63.624313,-116.895943,0.005139,0.004164,0.105767,283.015076,14.417476,1.057669,-116.895943,0.105923,0.000000
70.260002,63.502548,-116.806976,0.005144,0.004164,0.105758,282.473450,14.389883,1.057582,-116.806976,0.105923,0.000000
70.490005,63.373322,-116.851456,0.005157,0.004164,0.105758,281.898621,14.360600,1.057582,-116.851456,0.105923,0.000000
70.720001,63.247833,-116.895943,0.005148,0.004164,0.105758,281.340424,14.332164,1.057582,-116.895943,0.105923,0.000000
70.950005,63.130539,-116.940422,0.005148,0.004164,0.105758,280.818665,14.305584,1.057582,-116.940422,0.105923,0.000000
71.180000,63.019943,-116.895943,0.005148,0.004164,0.105758,280.326721,14.280523,1.057582,-116.895943,0.105923,0.000000
71.410004,62.908600,-116.851456,0.005139,0.004164,0.105758,279.831421,14.255293,1.057582,-116.851456,0.105923,0.000000
71.640007,62.824448,-116.851456,0.005157,0.004164,0.105758,279.457092,14.236223,1.057582,-116.851456,0.105923,0.000000
71.870003,62.744019,-116.895943,0.005139,0.004163,0.105749,279.099335,14.217998,1.057495,-116.895943,0.105923,0.000000
72.100006,62.638268,-116.940422,0.005178,0.004163,0.105749,278.628937,14.194035,1.057495,-116.940422,0.105923,0.000000
72.330002,62.559319,-116.940422,0.005170,0.004163,0.105749,278.277740,14.176145,1.057495,-116.940422,0.105923,0.000000
72.560005,62.474792,-116.940422,0.005135,0.004163,0.105749,277.901764,14.156991,1.057495,-116.940422,0.105923,0.000000
72.790001,62.396965,-116.984901,0.005178,0.004163,0.105749,277.555573,14.139354,1.057495,-116.984901,0.105923,0.000000
73.020004,62.326591,-116.940422,0.005157,0.004163,0.105749,277.242523,14.123408,1.057495,-116.940422,0.105923,0.000000
73.250000,62.245781,-116.984901,0.005157,0.004163,0.105749,276.883057,14.105096,1.057495,-116.984901,0.105923,0.000000
73.480003,62.180992,-116.940422,0.005157,0.004163,0.105749,276.594879,14.090414,1.057495,-116.940422,0.105923,0.000000
73.710007,62.141518,-116.940422,0.005157,0.004163,0.105749,276.419281,14.081470,1.057495,-116.940422,0.105923,0.000000
73.940002,62.058105,-116.940422,0.005152,0.004163,0.105749,276.048248,14.062568,1.057495,-116.940422,0.105923,0.000000
74.170006,61.997780,-116.984901,0.005161,0.004163,0.105749,275.779907,14.048898,1.057495,-116.984901,0.105923,0.000000
74.400002,61.932243,-117.073860,0.005161,0.004163,0.105749,275.488373,14.034047,1.057495,-117.073860,0.105923,0.000000
74.630005,61.878998,-116.984901,0.005161,0.004163,0.105749,275.251526,14.021981,1.057495,-116.984901,0.105923,0.000000
74.860001,61.836922,-116.984901,0.005157,0.004163,0.105749,275.064362,14.012447,1.057495,-116.984901,0.105923,0.000000
75.090004,61.783295,-117.029381,0.005161,0.004163,0.105749,274.825806,14.000295,1.057495,-117.029381,0.105923,0.000000
75.320007,61.728188,-117.073860,0.005170,0.004163,0.105741,274.580688,13.987807,1.057409,-117.073860,0.105923,0.000000
75.550003,61.681267,-116.984901,0.005161,0.004163,0.105741,274.371979,13.977175,1.057409,-116.984901,0.105923,0.000000
75.780006,61.622063,-117.029381,0.005157,0.004163,0.105741,274.108612,13.963759,1.057409,-117.029381,0.105923,0.000000
76.010002,61.577377,-116.984901,0.005157,0.004163,0.105741,273.909851,13.953633,1.057409,-116.984901,0.105923,0.000000
76.240005,61.537155,-116.984901,0.005170,0.004163,0.105741,273.730927,13.944519,1.057409,-116.984901,0.105923,0.000000
76.470001,61.488380,-117.073860,0.005178,0.004163,0.105741,273.513977,13.933467,1.057409,-117.073860,0.105923,0.000000
76.700005,61.435875,-117.118347,0.005174,0.004163,0.105741,273.280426,13.921569,1.057409,-117.118347,0.105923,0.000000
76.930000,61.403107,-117.073860,0.005174,0.004163,0.105741,273.134674,13.914144,1.057409,-117.073860,0.105923,0.000000
77.160004,61.361397,-117.073860,0.005161,0.004163,0.105741,272.949127,13.904691,1.057409,-117.073860,0.105923,0.000000
77.390007,61.310753,-117.073860,0.005148,0.004163,0.105741,272.723846,13.893215,1.057409,-117.073860,0.105923,0.000000
77.620003,61.281708,-117.073860,0.005178,0.004163,0.105741,272.594666,13.886634,1.057409,-117.073860,0.105923,0.000000
77.850006,61.241867,-117.162827,0.005174,0.004163,0.105741,272.417419,13.877605,1.057409,-117.162827,0.105923,0.000000
78.080002,61.209099,-117.073860,0.005157,0.004163,0.105741,272.271667,13.870180,1.057409,-117.073860,0.105923,0.000000
78.310005,61.172234,-117.073860,0.005165,0.004163,0.105741,272.107697,13.861826,1.057409,-117.073860,0.105923,0.000000
78.540001,61.125687,-117.073860,0.005178,0.004163,0.105741,271.900635,13.851279,1.057409,-117.073860,0.105923,0.000000
78.770004,61.089569,-117.118347,0.005165,0.004163,0.105741,271.739990,13.843095,1.057409,-117.118347,0.105923,0.000000
79.000000,61.059036,-117.207306,0.005182,0.004163,0.105741,271.604156,13.836175,1.057409,-117.207306,0.105923,0.000000
79.230003,61.020309,-117.118347,0.005161,0.004163,0.105741,271.431885,13.827400,1.057409,-117.118347,0.105923,0.000000
79.460007,60.994614,-117.118347,0.005174,0.004163,0.105741,271.317596,13.821577,1.057409,-117.118347,0.105923,0.000000
79.690002,60.964447,-117.118347,0.005178,0.004163,0.105741,271.183411,13.814741,1.057409,-117.118347,0.105923,0.000000
79.920006,60.932053,-117.162827,0.005178,0.004163,0.105741,271.039307,13.807400,1.057409,-117.162827,0.105923,0.000000
80.150002,60.894814,-117.207306,0.005178,0.004163,0.105741,270.873657,13.798962,1.057409,-117.207306,0.105923,0.000000
80.380005,60.865028,-117.162827,0.005161,0.004163,0.105741,270.741180,13.792212,1.057409,-117.162827,0.105923,0.000000
80.610001,60.837845,-117.162827,0.005152,0.004163,0.105741,270.620239,13.786052,1.057409,-117.162827,0.105923,0.000000
80.840004,60.798370,-117.162827,0.005165,0.004163,0.105741,270.444672,13.777107,1.057409,-117.162827,0.105923,0.000000
81.070007,60.772308,-117.207306,0.005182,0.004163,0.105741,270.328735,13.771202,1.057409,-117.207306,0.105923,0.000000
81.300003,60.757042,-117.207306,0.005161,0.004163,0.105741,270.260834,13.767743,1.057409,-117.207306,0.105923,0.000000
81.530006,60.714584,-117.251785,0.005161,0.004163,0.105741,270.071960,13.758121,1.057409,-117.251785,0.105923,0.000000
81.760002,60.687035,-117.296265,0.005165,0.004163,0.105741,269.949402,13.751879,1.057409,-117.296265,0.105923,0.000000
81.990005,60.668411,-117.207306,0.005165,0.004163,0.105732,269.866577,13.747659,1.057322,-117.207306,0.105923,0.000000
82.220001,60.630806,-117.251785,0.005170,0.004163,0.105732,269.699280,13.739137,1.057322,-117.251785,0.105923,0.000000
82.450005,60.605110,-117.251785,0.005178,0.004163,0.105732,269.584991,13.733314,1.057322,-117.251785,0.105923,0.000000
82.680000,60.577927,-117.251785,0.005170,0.004163,0.105732,269.464081,13.727155,1.057322,-117.251785,0.105923,0.000000
82.910004,60.562286,-117.251785,0.005178,0.004163,0.105732,269.394501,13.723610,1.057322,-117.251785,0.105923,0.000000
83.140007,60.528404,-117.251785,0.005170,0.004163,0.105732,269.243774,13.715933,1.057322,-117.251785,0.105923,0.000000
83.370003,60.500099,-117.296265,0.005174,0.004163,0.105732,269.117889,13.709518,1.057322,-117.296265,0.105923,0.000000
83.600006,60.482971,-117.340752,0.005187,0.004163,0.105732,269.041687,13.705638,1.057322,-117.340752,0.105923,0.000000
83.830002,60.467705,-117.296265,0.005174,0.004163,0.105732,268.973785,13.702178,1.057322,-117.296265,0.105923,0.000000
84.060005,60.447594,-117.207306,0.005174,0.004163,0.105732,268.884338,13.697620,1.057322,-117.207306,0.105923,0.000000
84.290001,60.408127,-117.296265,0.005191,0.004163,0.105732,268.708771,13.688677,1.057322,-117.296265,0.105923,0.000000
84.520004,60.386154,-117.296265,0.005174,0.004163,0.105732,268.611023,13.683698,1.057322,-117.296265,0.105923,0.000000
84.750008,60.335144,-117.340752,0.005165,0.004163,0.105732,268.384125,13.672139,1.057322,-117.340752,0.105923,0.000000
84.980003,60.339607,-117.340752,0.005174,0.004163,0.105732,268.403992,13.673150,1.057322,-117.340752,0.105923,0.000000
85.210007,60.331413,-117.251785,0.005170,0.004163,0.105732,268.367523,13.671294,1.057322,-117.251785,0.105923,0.000000
85.440002,60.297905,-117.385231,0.005195,0.004163,0.105732,268.218475,13.663701,1.057322,-117.385231,0.105923,0.000000
85.670006,60.275192,-117.340752,0.005161,0.004163,0.105732,268.117432,13.658554,1.057322,-117.340752,0.105923,0.000000
85.900002,60.255829,-117.340752,0.005174,0.004163,0.105732,268.031311,13.654165,1.057322,-117.340752,0.105923,0.000000
86.130005,60.230507,-117.251785,0.005152,0.004163,0.105732,267.918671,13.648428,1.057322,-117.251785,0.105923,0.000000
86.360001,60.212257,-117.385231,0.005187,0.004163,0.105732,267.837494,13.644293,1.057322,-117.385231,0.105923,0.000000
86.590004,60.190659,-117.340752,0.005178,0.004163,0.105732,267.741425,13.639398,1.057322,-117.340752,0.105923,0.000000
86.820007,60.170921,-117.429710,0.005170,0.004163,0.105732,267.653625,13.634926,1.057322,-117.429710,0.105923,0.000000
87.050003,60.157890,-117.385231,0.005187,0.004163,0.105732,267.595673,13.631972,1.057322,-117.385231,0.105923,0.000000
87.280006,60.128105,-117.340752,0.005174,0.004163,0.105732,267.463165,13.625223,1.057322,-117.340752,0.105923,0.000000
87.510002,60.112091,-117.340752,0.005174,0.004163,0.105732,267.391937,13.621595,1.057322,-117.340752,0.105923,0.000000
87.740005,60.094963,-117.429710,0.005191,0.004163,0.105732,267.315735,13.617713,1.057322,-117.429710,0.105923,0.000000
87.970001,60.074478,-117.429710,0.005178,0.004163,0.105732,267.224640,13.613071,1.057322,-117.429710,0.105923,0.000000
88.200005,60.059586,-117.340752,0.005170,0.004163,0.105732,267.158386,13.609696,1.057322,-117.340752,0.105923,0.000000
88.430008,60.052139,-117.429710,0.005178,0.004163,0.105732,267.125244,13.608009,1.057322,-117.429710,0.105923,0.000000
88.660004,60.028679,-117.429710,0.005174,0.004163,0.105732,267.020905,13.602693,1.057322,-117.429710,0.105923,0.000000
88.890007,60.001869,-117.429710,0.005187,0.004163,0.105732,266.901642,13.596618,1.057322,-117.429710,0.105923,0.000000
89.120003,59.994423,-117.518669,0.005178,0.004163,0.105732,266.868530,13.594931,1.057322,-117.518669,0.105923,0.000000
89.350006,59.965744,-117.474190,0.005170,0.004163,0.105732,266.740936,13.588431,1.057322,-117.474190,0.105923,0.000000
89.580002,59.943779,-117.385231,0.005165,0.004163,0.105732,266.643250,13.583455,1.057322,-117.385231,0.105923,0.000000
89.810005,59.937073,-117.474190,0.005182,0.004163,0.105732,266.613403,13.581935,1.057322,-117.474190,0.105923,0.000000
90.040001,59.920319,-117.474190,0.005170,0.004163,0.105732,266.538879,13.578138,1.057322,-117.474190,0.105923,0.000000
90.270004,59.906166,-117.518669,0.005182,0.004163,0.105732,266.475922,13.574931,1.057322,-117.518669,0.105923,0.000000
90.500008,59.878242,-117.474190,0.005174,0.004163,0.105732,266.351715,13.568604,1.057322,-117.474190,0.105923,0.000000
90.730003,59.877495,-117.563156,0.005182,0.004163,0.105732,266.348389,13.568435,1.057322,-117.563156,0.105923,0.000000
90.960007,59.852173,-117.563156,0.005182,0.004163,0.105732,266.235748,13.562696,1.057322,-117.563156,0.105923,0.000000
91.190002,59.840630,-117.474190,0.005165,0.004163,0.105732,266.184418,13.560081,1.057322,-117.474190,0.105923,0.000000
91.420006,59.833183,-117.563156,0.005182,0.004163,0.105732,266.151306,13.558393,1.057322,-117.563156,0.105923,0.000000
91.650002,59.800789,-117.563156,0.005178,0.004163,0.105732,266.007202,13.551052,1.057322,-117.563156,0.105923,0.000000
91.880005,59.776581,-117.518669,0.005187,0.004163,0.105732,265.899506,13.545567,1.057322,-117.518669,0.105923,0.000000
92.110001,59.788872,-117.563156,0.005161,0.004163,0.105732,265.954193,13.548352,1.057322,-117.563156,0.105923,0.000000
92.340004,59.760941,-117.563156,0.005195,0.004163,0.105732,265.829926,13.542023,1.057322,-117.563156,0.105923,0.000000
92.570007,59.740837,-117.563156,0.005191,0.004163,0.105732,265.740509,13.537467,1.057322,-117.563156,0.105923,0.000000
92.800003,59.719978,-117.563156,0.005170,0.004163,0.105732,265.647736,13.532740,1.057322,-117.563156,0.105923,0.000000
93.030006,59.711418,-117.518669,0.005157,0.004163,0.105732,265.609650,13.530801,1.057322,-117.518669,0.105923,0.000000
93.260002,59.698753,-117.652115,0.005170,0.004163,0.105732,265.553314,13.527931,1.057322,-117.652115,0.105923,0.000000
93.490005,59.684235,-117.696594,0.005174,0.004163,0.105732,265.488739,13.524641,1.057322,-117.696594,0.105923,0.000000
93.720001,59.683487,-117.652115,0.005187,0.004163,0.105732,265.485413,13.524471,1.057322,-117.652115,0.105923,0.000000
93.950005,59.654068,-117.607635,0.005178,0.004163,0.105732,265.354553,13.517805,1.057322,-117.607635,0.105923,0.000000
94.180008,59.628380,-117.563156,0.005174,0.004163,0.105732,265.240295,13.511984,1.057322,-117.563156,0.105923,0.000000
94.410004,59.636566,-117.518669,0.005157,0.004163,0.105732,265.276703,13.513839,1.057322,-117.518669,0.105923,0.000000
94.640007,59.622795,-117.607635,0.005178,0.004163,0.105732,265.215424,13.510718,1.057322,-117.607635,0.105923,0.000000
94.870003,59.592628,-117.696594,0.005174,0.004163,0.105732,265.081238,13.503882,1.057322,-117.696594,0.105923,0.000000
95.100006,59.581085,-117.652115,0.005191,0.004163,0.105732,265.029907,13.501267,1.057322,-117.652115,0.105923,0.000000
95.330002,59.585556,-117.696594,0.005174,0.004163,0.105732,265.049805,13.502280,1.057322,-117.696594,0.105923,0.000000
95.560005,59.572891,-117.652115,0.005195,0.004163,0.105732,264.993469,13.499411,1.057322,-117.652115,0.105923,0.000000
95.790001,59.544594,-117.696594,0.005174,0.004163,0.105732,264.867584,13.492997,1.057322,-117.696594,0.105923,0.000000
96.020004,59.533424,-117.696594,0.005200,0.004163,0.105732,264.817902,13.490466,1.057322,-117.696594,0.105923,0.000000
96.250008,59.511452,-117.696594,0.005165,0.004163,0.105732,264.720154,13.485488,1.057322,-117.696594,0.105923,0.000000
96.480003,59.502518,-117.652115,0.005200,0.004163,0.105732,264.680420,13.483463,1.057322,-117.652115,0.105923,0.000000
96.710007,59.522995,-117.696594,0.005200,0.004163,0.105732,264.771515,13.488103,1.057322,-117.696594,0.105923,0.000000
96.940002,59.494324,-117.696594,0.005195,0.004163,0.105732,264.643982,13.481606,1.057322,-117.696594,0.105923,0.000000
97.170006,59.466393,-117.741081,0.005191,0.004163,0.105732,264.519714,13.475277,1.057322,-117.741081,0.105923,0.000000
97.400002,59.456711,-117.785561,0.005182,0.004163,0.105732,264.476654,13.473083,1.057322,-117.785561,0.105923,0.000000
97.500008,59.464165,-117.696594,0.005157,0.004163,0.105732,264.509827,13.474772,1.057322,-117.696594,0.105923,0.000000