File: Data/Symmetrical membranes compression/Millioire Express PES 045um test 3_10302023_172724.csv
Time (sec),S:Load (lbs),S:HL1 (DIM),S:LVDT (in),S:Position (in),Ch:Position (mm),Ch:Load (N),Ch:Stress (MPa),Ch:Strain (mm/mm),Ch:HL1 (DIM),Set Point (),Cycles ()
0.110000,0.009682,-119.920647,0.000017,-0.000000,-0.000000,0.043066,0.002194,-0.000000,-119.920647,0.000260,0.000000
0.350000,0.007072,-119.787201,0.000009,-0.000000,-0.000000,0.031460,0.001603,-0.000000,-119.787201,0.000347,0.000000
0.590000,-0.071121,-119.876160,0.000026,0.000127,0.003217,-0.316363,-0.016116,0.032173,-119.876160,0.004336,0.000000
0.830000,-0.031654,-119.920647,0.000138,0.000281,0.007129,-0.140806,-0.007173,0.071286,-119.920647,0.008343,0.000000
1.070000,-0.010056,-119.876160,0.000315,0.000433,0.010996,-0.044729,-0.002279,0.109963,-119.876160,0.012332,0.000000
1.310000,-0.029045,-119.876160,0.000474,0.000593,0.015072,-0.129199,-0.006582,0.150724,-119.876160,0.016339,0.000000
1.550000,-0.038353,-119.876160,0.000647,0.000755,0.019174,-0.170603,-0.008691,0.191744,-119.876160,0.020328,0.000000
1.790000,-0.016388,-119.920647,0.000798,0.000912,0.023164,-0.072897,-0.003714,0.231636,-119.920647,0.024334,0.000000
2.030000,-0.002609,-119.920647,0.000961,0.001063,0.026988,-0.011607,-0.000591,0.269880,-119.920647,0.028324,0.000000
2.270000,-0.028305,-119.965126,0.001138,0.001222,0.031047,-0.125907,-0.006414,0.310466,-119.965126,0.032330,0.000000
2.510000,-0.006706,-120.009605,0.001319,0.001380,0.035053,-0.029831,-0.001520,0.350532,-120.009605,0.036319,0.000000
2.750000,0.095695,-119.831680,0.001466,0.001536,0.039008,0.425675,0.021685,0.390078,-119.831680,0.040326,0.000000
2.990000,0.280396,-119.965126,0.001656,0.001693,0.043006,1.247262,0.063539,0.430057,-119.965126,0.044315,0.000000
3.230000,0.590950,-119.965126,0.001815,0.001851,0.047021,2.628677,0.133911,0.470210,-119.965126,0.048322,0.000000
3.470000,0.645691,-119.920647,0.001850,-0.000000,-0.000009,2.872177,0.146316,-0.000086,-119.920647,0.000243,0.000000
3.710000,0.633774,-119.965126,0.001828,-0.000000,-0.000009,2.819167,0.143615,-0.000086,-119.965126,0.000243,0.000000
3.950000,0.638245,-119.965126,0.001858,-0.000000,-0.000009,2.839054,0.144628,-0.000086,-119.965126,0.000529,0.000000
4.190000,0.647552,-120.054085,0.001845,-0.000000,-0.000000,2.880457,0.146737,-0.000000,-120.054085,0.000928,0.000000
4.430000,0.614784,-119.965126,0.001867,-0.000000,-0.000000,2.734697,0.139312,-0.000000,-119.965126,0.001327,0.000000
4.670000,0.628189,-119.965126,0.001841,-0.000000,-0.000000,2.794325,0.142350,-0.000000,-119.965126,0.001726,0.000000
4.910000,0.792778,-119.965126,0.001897,0.000048,0.001232,3.526453,0.179646,0.012315,-119.965126,0.002125,0.000000
5.150000,0.815125,-120.009605,0.001923,0.000062,0.001578,3.625855,0.184710,0.015784,-120.009605,0.002532,0.000000
5.390000,0.861298,-120.009605,0.001932,0.000075,0.001917,3.831243,0.195173,0.019166,-120.009605,0.002931,0.000000
5.630000,0.931305,-120.009605,0.001932,0.000089,0.002263,4.142651,0.211037,0.022635,-120.009605,0.003330,0.000000
5.870000,0.977104,-119.965126,0.001944,0.000102,0.002593,4.346376,0.221415,0.025930,-119.965126,0.003729,0.000000
6.110000,1.025887,-120.009605,0.001992,0.000121,0.003079,4.563371,0.232469,0.030787,-120.009605,0.004128,0.000000
6.350000,1.107063,-120.054085,0.001953,0.000140,0.003556,4.924463,0.250864,0.035556,-120.054085,0.004527,0.000000
6.590000,1.107437,-120.098564,0.002005,0.000155,0.003937,4.926126,0.250949,0.039372,-120.098564,0.004926,0.000000
6.830000,1.168129,-120.054085,0.002005,0.000169,0.004293,5.196097,0.264702,0.042928,-120.054085,0.005325,0.000000
7.070000,1.254890,-120.009605,0.002035,0.000186,0.004718,5.582031,0.284362,0.047178,-120.009605,0.005732,0.000000
7.310000,1.301071,-120.054085,0.002039,0.000199,0.005065,5.787454,0.294827,0.050647,-120.054085,0.006131,0.000000
7.550000,1.394157,-120.054085,0.002061,0.000212,0.005377,6.201522,0.315921,0.053768,-120.054085,0.006530,0.000000
7.790000,1.445175,-120.143051,0.002078,0.000230,0.005854,6.428460,0.327481,0.058538,-120.143051,0.006929,0.000000
8.030001,1.562477,-120.009605,0.002108,0.000255,0.006478,6.950245,0.354062,0.064782,-120.009605,0.007328,0.000000
8.270000,1.589287,-120.098564,0.002117,0.000268,0.006799,7.069501,0.360138,0.067991,-120.098564,0.007727,0.000000
8.510000,1.609390,-120.098564,0.002139,0.000283,0.007198,7.158926,0.364693,0.071980,-120.098564,0.008126,0.000000
8.750000,1.688705,-120.054085,0.002164,0.000296,0.007528,7.511737,0.382666,0.075276,-120.054085,0.008525,0.000000
8.990001,1.797440,-120.143051,0.002151,0.000317,0.008048,7.995410,0.407306,0.080479,-120.143051,0.008932,0.000000
9.230000,1.821648,-120.143051,0.002173,0.000327,0.008317,8.103093,0.412791,0.083167,-120.143051,0.009331,0.000000
9.470000,1.889046,-120.143051,0.002203,0.000340,0.008638,8.402895,0.428064,0.086376,-120.143051,0.009730,0.000000
9.710000,1.988098,-120.143051,0.002195,0.000361,0.009158,8.843502,0.450509,0.091579,-120.143051,0.010129,0.000000
9.950001,2.046188,-120.187531,0.002233,0.000375,0.009531,9.101900,0.463673,0.095308,-120.187531,0.010528,0.000000
10.190001,2.122894,-120.232010,0.002251,0.000393,0.009973,9.443106,0.481055,0.099731,-120.232010,0.010927,0.000000
10.430000,2.160133,-120.143051,0.002255,0.000409,0.010389,9.608753,0.489493,0.103894,-120.143051,0.011326,0.000000
10.670000,2.194389,-120.143051,0.002281,0.000421,0.010693,9.761131,0.497256,0.106929,-120.143051,0.011725,0.000000
10.910001,2.274078,-120.187531,0.002298,0.000435,0.011048,10.115605,0.515314,0.110485,-120.187531,0.012133,0.000000
11.150001,2.354507,-120.143051,0.002307,0.000455,0.011560,10.473372,0.533539,0.115602,-120.143051,0.012531,0.000000
11.390000,2.389511,-120.187531,0.002302,0.000465,0.011812,10.629076,0.541471,0.118116,-120.187531,0.012930,0.000000
11.630000,2.432709,-120.143051,0.002345,0.000477,0.012107,10.821229,0.551260,0.121066,-120.143051,0.013329,0.000000
11.870001,2.494896,-120.232010,0.002337,0.000488,0.012401,11.097852,0.565351,0.124014,-120.232010,0.013728,0.000000
12.110001,2.625595,-120.232010,0.002376,0.000514,0.013052,11.679231,0.594968,0.130518,-120.232010,0.014127,0.000000
12.350000,2.704170,-120.187531,0.002380,0.000531,0.013477,12.028749,0.612774,0.134767,-120.187531,0.014526,0.000000
12.590000,2.799866,-120.187531,0.002393,0.000549,0.013954,12.454425,0.634459,0.139537,-120.187531,0.014925,0.000000
12.830001,2.898544,-120.276489,0.002427,0.000566,0.014379,12.893369,0.656820,0.143786,-120.276489,0.015333,0.000000
13.070001,2.955521,-120.276489,0.002453,0.000580,0.014743,13.146812,0.669731,0.147429,-120.276489,0.015732,0.000000
13.310000,2.976372,-120.276489,0.002462,0.000589,0.014960,13.239563,0.674455,0.149597,-120.276489,0.016130,0.000000
13.550000,3.059784,-120.232010,0.002471,0.000610,0.015489,13.610599,0.693357,0.154887,-120.232010,0.016529,0.000000
13.790001,3.205009,-120.276489,0.002492,0.000628,0.015948,14.256594,0.726265,0.159483,-120.276489,0.016928,0.000000
14.030001,3.232193,-120.232010,0.002488,0.000639,0.016235,14.377513,0.732425,0.162345,-120.232010,0.017327,0.000000
14.270000,3.365501,-120.276489,0.002514,0.000660,0.016763,14.970498,0.762634,0.167635,-120.276489,0.017726,0.000000
14.510000,3.353958,-120.320976,0.002552,0.000669,0.016980,14.919151,0.760018,0.169804,-120.320976,0.018125,0.000000
14.750001,3.499557,-120.320976,0.002561,0.000688,0.017466,15.566810,0.793011,0.174660,-120.320976,0.018533,0.000000
14.990001,3.580734,-120.320976,0.002570,0.000703,0.017856,15.927901,0.811406,0.178562,-120.320976,0.018932,0.000000
15.230000,3.611267,-120.320976,0.002578,0.000712,0.018090,16.063719,0.818325,0.180904,-120.320976,0.019330,0.000000
15.470000,3.752022,-120.320976,0.002600,0.000730,0.018550,16.689827,0.850220,0.185500,-120.320976,0.019729,0.000000
15.710001,3.861130,-120.276489,0.002617,0.000753,0.019114,17.175163,0.874945,0.191137,-120.276489,0.020128,0.000000
15.950001,3.957947,-120.276489,0.002643,0.000769,0.019521,17.605827,0.896884,0.195213,-120.276489,0.020527,0.000000
16.190001,4.014549,-120.409935,0.002652,0.000784,0.019903,17.857607,0.909710,0.199029,-120.409935,0.020926,0.000000
16.430000,4.113228,-120.365456,0.002686,0.000799,0.020284,18.296551,0.932071,0.202845,-120.365456,0.021325,0.000000
16.670000,4.253983,-120.365456,0.002690,0.000818,0.020779,18.922659,0.963966,0.207788,-120.365456,0.021733,0.000000
16.910002,4.329948,-120.409935,0.002708,0.000832,0.021143,19.260572,0.981180,0.211430,-120.409935,0.022132,0.000000
17.150002,4.347816,-120.365456,0.002712,0.000842,0.021377,19.340054,0.985229,0.213772,-120.365456,0.022531,0.000000
17.390001,4.480011,-120.365456,0.002729,0.000861,0.021871,19.928083,1.015185,0.218715,-120.365456,0.022929,0.000000
17.630001,4.571991,-120.409935,0.002742,0.000878,0.022296,20.337231,1.036028,0.222964,-120.409935,0.023328,0.000000
17.870001,4.659866,-120.365456,0.002777,0.000893,0.022678,20.728121,1.055941,0.226780,-120.365456,0.023727,0.000000
18.110001,4.755569,-120.454414,0.002777,0.000910,0.023103,21.153830,1.077627,0.231029,-120.454414,0.024126,0.000000
18.350000,4.797272,-120.365456,0.002794,0.000921,0.023398,21.339331,1.087077,0.233977,-120.365456,0.024534,0.000000
18.590000,4.886642,-120.454414,0.002807,0.000938,0.023823,21.736872,1.107329,0.238227,-120.454414,0.024933,0.000000
18.830002,5.075432,-120.454414,0.002828,0.000957,0.024308,22.576649,1.150109,0.243084,-120.454414,0.025332,0.000000
19.070002,5.139481,-120.365456,0.002863,0.000970,0.024647,22.861551,1.164623,0.246466,-120.365456,0.025731,0.000000
19.310001,5.243378,-120.454414,0.002871,0.000986,0.025046,23.323709,1.188166,0.250455,-120.454414,0.026130,0.000000
19.550001,5.361046,-120.409935,0.002893,0.001003,0.025470,23.847122,1.214830,0.254705,-120.409935,0.026529,0.000000
19.790001,5.503288,-120.498894,0.002915,0.001020,0.025913,24.479849,1.247063,0.259127,-120.498894,0.026927,0.000000
20.030001,5.493240,-120.454414,0.002897,0.001033,0.026234,24.435154,1.244786,0.262336,-120.454414,0.027326,0.000000
20.270000,5.615372,-120.454414,0.002936,0.001050,0.026667,24.978420,1.272462,0.266672,-120.454414,0.027734,0.000000
20.510000,5.646286,-120.498894,0.002923,0.001061,0.026953,25.115934,1.279467,0.269534,-120.498894,0.028133,0.000000
20.750002,5.869705,-120.498894,0.002953,0.001082,0.027491,26.109753,1.330094,0.274911,-120.498894,0.028532,0.000000
20.990002,5.915878,-120.543381,0.002975,0.001095,0.027812,26.315142,1.340557,0.278120,-120.543381,0.028931,0.000000
21.230001,5.829117,-120.498894,0.002997,0.001105,0.028072,25.929207,1.320897,0.280721,-120.498894,0.029330,0.000000
21.470001,6.162766,-120.454414,0.002992,0.001130,0.028697,27.413349,1.396503,0.286965,-120.454414,0.029729,0.000000
21.710001,6.248039,-120.587860,0.003022,0.001145,0.029087,27.792667,1.415826,0.290868,-120.587860,0.030127,0.000000
21.950001,6.281548,-120.498894,0.003035,0.001161,0.029477,27.941719,1.423419,0.294770,-120.498894,0.030526,0.000000
22.190001,6.359001,-120.498894,0.003044,0.001174,0.029815,28.286249,1.440970,0.298152,-120.498894,0.030934,0.000000
22.430000,6.404434,-120.543381,0.003091,0.001186,0.030119,28.488346,1.451265,0.301188,-120.543381,0.031333,0.000000
22.670002,6.642754,-120.543381,0.003091,0.001205,0.030604,29.548443,1.505270,0.306045,-120.543381,0.031732,0.000000
22.910002,6.681847,-120.587860,0.003083,0.001218,0.030925,29.722338,1.514128,0.309253,-120.587860,0.032131,0.000000
23.150002,6.788719,-120.543381,0.003122,0.001232,0.031281,30.197731,1.538346,0.312808,-120.543381,0.032530,0.000000
23.390001,6.784622,-120.632339,0.003130,0.001241,0.031515,30.179506,1.537417,0.315150,-120.632339,0.032929,0.000000
23.630001,7.194611,-120.543381,0.003191,0.001275,0.032382,32.003227,1.630322,0.323822,-120.543381,0.033328,0.000000
23.870001,7.165565,-120.587860,0.003169,0.001290,0.032764,31.874027,1.623740,0.327638,-120.587860,0.033726,0.000000
24.110001,7.128700,-120.587860,0.003191,0.001301,0.033050,31.710043,1.615387,0.330500,-120.587860,0.034134,0.000000
24.350000,7.198700,-120.543381,0.003208,0.001313,0.033345,32.021416,1.631249,0.333448,-120.543381,0.034533,0.000000
24.590002,7.453033,-120.632339,0.003234,0.001335,0.033900,33.152748,1.688882,0.338999,-120.632339,0.034932,0.000000
24.830002,7.520058,-120.632339,0.003242,0.001347,0.034221,33.450886,1.704069,0.342207,-120.632339,0.035331,0.000000
25.070002,7.507774,-120.587860,0.003238,0.001360,0.034542,33.396248,1.701286,0.345416,-120.587860,0.035730,0.000000
25.310001,7.736038,-120.632339,0.003277,0.001375,0.034932,34.411617,1.753011,0.349319,-120.632339,0.036129,0.000000
25.550001,7.920364,-120.632339,0.003290,0.001398,0.035522,35.231541,1.794780,0.355216,-120.632339,0.036528,0.000000
25.790001,7.924828,-120.632339,0.003303,0.001411,0.035842,35.251392,1.795792,0.358425,-120.632339,0.036926,0.000000
26.030001,8.067818,-120.676819,0.003328,0.001429,0.036302,35.887444,1.828194,0.363022,-120.676819,0.037334,0.000000
26.270000,8.136711,-120.676819,0.003354,0.001442,0.036632,36.193897,1.843805,0.366316,-120.676819,0.037733,0.000000
26.510002,8.320663,-120.721298,0.003341,0.001462,0.037135,37.012161,1.885489,0.371346,-120.721298,0.038132,0.000000
26.750002,8.324387,-120.632339,0.003385,0.001474,0.037447,37.028721,1.886333,0.374468,-120.632339,0.038531,0.000000
26.990002,8.455086,-120.721298,0.003367,0.001488,0.037802,37.610100,1.915950,0.378024,-120.721298,0.038930,0.000000
27.230001,8.540359,-120.676819,0.003428,0.001502,0.038141,37.989418,1.935273,0.381407,-120.676819,0.039329,0.000000
27.470001,8.729523,-120.632339,0.003449,0.001524,0.038704,38.830856,1.978138,0.387043,-120.632339,0.039728,0.000000
27.710001,8.834908,-120.676819,0.003454,0.001538,0.039060,39.299633,2.002019,0.390599,-120.676819,0.040127,0.000000
27.950001,8.919067,-120.721298,0.003466,0.001554,0.039467,39.673992,2.021090,0.394675,-120.721298,0.040534,0.000000
28.190001,8.986839,-120.721298,0.003479,0.001568,0.039823,39.975456,2.036447,0.398231,-120.721298,0.040933,0.000000
28.430002,9.164833,-120.721298,0.003484,0.001586,0.040274,40.767212,2.076781,0.402740,-120.721298,0.041332,0.000000
28.670002,9.235954,-120.721298,0.003518,0.001599,0.040612,41.083576,2.092897,0.406122,-120.721298,0.041731,0.000000
28.910002,9.343567,-120.810265,0.003514,0.001613,0.040968,41.562260,2.117283,0.409678,-120.810265,0.042130,0.000000
29.150002,9.553963,-120.676819,0.003544,0.001630,0.041401,42.498150,2.164959,0.414014,-120.676819,0.042529,0.000000
29.390001,9.842918,-120.765785,0.003544,0.001654,0.042008,43.783489,2.230437,0.420085,-120.765785,0.042928,0.000000
29.630001,9.798607,-120.765785,0.003548,0.001669,0.042381,43.586380,2.220396,0.423814,-120.765785,0.043327,0.000000
29.870001,9.849998,-120.765785,0.003587,0.001682,0.042728,43.814983,2.232042,0.427282,-120.765785,0.043734,0.000000
30.110001,9.896545,-120.810265,0.003609,0.001696,0.043066,44.022034,2.242589,0.430664,-120.810265,0.044133,0.000000
30.350002,10.198532,-120.765785,0.003635,0.001716,0.043595,45.365337,2.311021,0.435955,-120.765785,0.044532,0.000000
30.590002,10.211945,-120.810265,0.003639,0.001731,0.043960,45.424999,2.314059,0.439598,-120.810265,0.044931,0.000000
30.830002,10.232422,-120.721298,0.003669,0.001740,0.044194,45.516087,2.318700,0.441939,-120.721298,0.045330,0.000000
31.070002,10.632721,-120.721298,0.003660,0.001764,0.044818,47.296703,2.409409,0.448183,-120.721298,0.045729,0.000000
31.310001,10.712784,-120.854744,0.003695,0.001780,0.045200,47.652843,2.427552,0.451999,-120.854744,0.046128,0.000000
31.550001,10.728424,-120.854744,0.003721,0.001793,0.045547,47.722412,2.431096,0.455468,-120.854744,0.046535,0.000000
31.790001,10.892639,-120.810265,0.003712,0.001811,0.045998,48.452877,2.468307,0.459977,-120.810265,0.046934,0.000000
32.030003,10.873650,-120.854744,0.003742,0.001823,0.046310,48.368408,2.464004,0.463099,-120.854744,0.047333,0.000000
32.270000,11.180855,-120.899223,0.003755,0.001843,0.046822,49.734924,2.533618,0.468215,-120.899223,0.047732,0.000000
32.510002,11.206917,-120.899223,0.003760,0.001855,0.047125,49.850857,2.539524,0.471251,-120.899223,0.048131,0.000000
32.750000,11.210648,-120.854744,0.003773,0.001865,0.047359,49.867451,2.540369,0.473593,-120.854744,0.048530,0.000000
32.990002,11.489922,-120.899223,0.003798,0.001885,0.047888,51.109722,2.603653,0.478883,-120.899223,0.048929,0.000000
33.230003,11.602753,-120.943703,0.003798,0.001899,0.048235,51.611622,2.629221,0.482352,-120.943703,0.049328,0.000000
33.470001,11.743134,-120.854744,0.003833,0.001917,0.048703,52.236069,2.661032,0.487035,-120.854744,0.049735,0.000000
33.710003,11.900276,-120.899223,0.003859,0.001934,0.049128,52.935074,2.696641,0.491284,-120.899223,0.050134,0.000000
33.950001,12.041405,-120.899223,0.003846,0.001949,0.049510,53.562843,2.728621,0.495099,-120.899223,0.050533,0.000000
34.190002,12.170624,-120.854744,0.003872,0.001967,0.049952,54.137638,2.757903,0.499523,-120.854744,0.050932,0.000000
34.430000,12.223122,-120.943703,0.003911,0.001980,0.050299,54.371162,2.769799,0.502992,-120.943703,0.051331,0.000000
34.670002,12.232803,-120.899223,0.003902,0.001990,0.050542,54.414227,2.771993,0.505420,-120.899223,0.051730,0.000000
34.910000,12.671837,-120.943703,0.003923,0.002014,0.051158,56.367146,2.871479,0.511577,-120.943703,0.052129,0.000000
35.150002,12.732529,-120.899223,0.003962,0.002026,0.051470,56.637115,2.885232,0.514699,-120.899223,0.052528,0.000000
35.390003,12.809608,-120.899223,0.003967,0.002041,0.051834,56.979984,2.902699,0.518341,-120.899223,0.052936,0.000000
35.630001,13.104904,-120.943703,0.003971,0.002060,0.052328,58.293526,2.969614,0.523284,-120.943703,0.053334,0.000000
35.870003,12.966011,-120.943703,0.003992,0.002069,0.052563,57.675697,2.938140,0.525626,-120.943703,0.053733,0.000000
36.110001,13.294815,-120.988190,0.004010,0.002090,0.053074,59.138290,3.012648,0.530743,-120.988190,0.054132,0.000000
36.350002,13.409134,-120.943703,0.004027,0.002103,0.053404,59.646805,3.038553,0.534038,-120.943703,0.054531,0.000000
36.590000,13.471687,-120.988190,0.004040,0.002117,0.053768,59.925056,3.052728,0.537680,-120.988190,0.054930,0.000000
36.830002,13.761398,-120.988190,0.004049,0.002137,0.054271,61.213757,3.118377,0.542710,-120.988190,0.055329,0.000000
37.070004,13.937531,-120.943703,0.004053,0.002153,0.054696,61.997231,3.158290,0.546960,-120.943703,0.055728,0.000000
37.310001,14.119621,-121.032669,0.004105,0.002169,0.055086,62.807213,3.199552,0.550862,-121.032669,0.056136,0.000000
37.550003,14.204521,-120.988190,0.004113,0.002184,0.055485,63.184864,3.218791,0.554851,-120.988190,0.056535,0.000000
37.790001,14.311760,-120.988190,0.004105,0.002198,0.055823,63.661888,3.243091,0.558233,-120.988190,0.056933,0.000000
38.030003,14.690094,-121.121628,0.004139,0.002220,0.056378,65.344803,3.328823,0.563784,-121.121628,0.057332,0.000000
38.270000,14.716530,-121.032669,0.004161,0.002232,0.056682,65.462395,3.334813,0.566819,-121.032669,0.057731,0.000000
38.510002,14.628654,-121.077148,0.004139,0.002243,0.056977,65.071503,3.314901,0.569768,-121.077148,0.058130,0.000000
38.750000,14.996925,-121.032669,0.004161,0.002263,0.057480,66.709656,3.398352,0.574798,-121.032669,0.058529,0.000000
38.990002,15.241577,-121.077148,0.004186,0.002280,0.057905,67.797920,3.453791,0.579047,-121.077148,0.058928,0.000000
39.230003,15.301529,-121.121628,0.004199,0.002293,0.058234,68.064598,3.467376,0.582342,-121.121628,0.059336,0.000000
39.470001,15.476540,-121.077148,0.004238,0.002309,0.058651,68.843086,3.507034,0.586505,-121.077148,0.059735,0.000000
39.710003,15.545059,-121.121628,0.004234,0.002322,0.058980,69.147881,3.522561,0.589800,-121.121628,0.060133,0.000000
39.950001,15.961746,-121.077148,0.004268,0.002344,0.059526,71.001396,3.616983,0.595265,-121.077148,0.060532,0.000000
40.190002,15.993767,-121.077148,0.004268,0.002353,0.059761,71.143829,3.624239,0.597606,-121.077148,0.060931,0.000000
40.430000,16.249962,-121.121628,0.004307,0.002372,0.060238,72.283440,3.682294,0.602376,-121.121628,0.061330,0.000000
40.670002,16.354225,-121.166107,0.004294,0.002384,0.060550,72.747231,3.705920,0.605497,-121.166107,0.061729,0.000000
40.910004,16.597755,-121.121628,0.004346,0.002402,0.061009,73.830505,3.761105,0.610094,-121.121628,0.062128,0.000000
41.150002,16.898636,-121.121628,0.004346,0.002419,0.061452,75.168884,3.829286,0.614516,-121.121628,0.062536,0.000000
41.390003,16.941086,-121.166107,0.004363,0.002434,0.061816,75.357712,3.838905,0.618159,-121.166107,0.062935,0.000000
41.630001,17.058754,-121.166107,0.004376,0.002449,0.062206,75.881126,3.865569,0.622062,-121.166107,0.063333,0.000000
41.870003,17.060989,-121.166107,0.004381,0.002460,0.062475,75.891068,3.866076,0.624750,-121.166107,0.063732,0.000000
42.110001,17.700722,-121.166107,0.004385,0.002484,0.063091,78.736740,4.011041,0.630907,-121.166107,0.064131,0.000000
42.350002,17.650452,-121.166107,0.004424,0.002494,0.063351,78.513130,3.999650,0.633509,-121.166107,0.064530,0.000000
42.590000,17.846321,-121.121628,0.004437,0.002511,0.063776,79.384399,4.044034,0.637759,-121.121628,0.064929,0.000000
42.830002,18.240288,-121.166107,0.004467,0.002530,0.064253,81.136856,4.133308,0.642528,-121.166107,0.065328,0.000000
43.070004,18.541542,-121.166107,0.004449,0.002549,0.064756,82.476898,4.201573,0.647558,-121.166107,0.065736,0.000000
43.310001,18.542282,-121.166107,0.004488,0.002562,0.065068,82.480186,4.201741,0.650680,-121.166107,0.066135,0.000000
43.550003,18.610054,-121.255074,0.004488,0.002575,0.065415,82.781654,4.217098,0.654149,-121.255074,0.066534,0.000000
43.790001,18.767944,-121.166107,0.004514,0.002589,0.065762,83.483986,4.252877,0.657618,-121.166107,0.066933,0.000000
44.030003,19.264313,-121.255074,0.004527,0.002609,0.066265,85.691940,4.365355,0.662648,-121.255074,0.067331,0.000000
44.270000,19.198036,-121.210594,0.004523,0.002617,0.066464,85.397133,4.350337,0.664642,-121.210594,0.067730,0.000000
44.510002,19.345123,-121.255074,0.004557,0.002631,0.066828,86.051407,4.383667,0.668285,-121.255074,0.068129,0.000000
44.750004,20.200836,-121.255074,0.004557,0.002662,0.067626,89.857811,4.577575,0.676263,-121.255074,0.068537,0.000000
44.990002,20.248871,-121.210594,0.004592,0.002674,0.067921,90.071480,4.588460,0.679212,-121.210594,0.068936,0.000000
45.230003,20.321106,-121.299553,0.004592,0.002690,0.068337,90.392792,4.604828,0.683374,-121.299553,0.069335,0.000000
45.470001,20.288712,-121.255074,0.004618,0.002700,0.068580,90.248695,4.597488,0.685802,-121.255074,0.069734,0.000000
45.710003,20.833862,-121.299553,0.004644,0.002720,0.069083,92.673645,4.721021,0.690832,-121.299553,0.070133,0.000000
45.950001,21.083725,-121.255074,0.004635,0.002735,0.069465,93.785095,4.777640,0.694648,-121.255074,0.070532,0.000000
46.190002,21.311249,-121.210594,0.004678,0.002750,0.069846,94.797173,4.829198,0.698464,-121.210594,0.070930,0.000000
46.430000,21.241241,-121.344032,0.004678,0.002763,0.070176,94.485764,4.813334,0.701759,-121.344032,0.071329,0.000000
46.670002,21.733521,-121.299553,0.004687,0.002782,0.070662,96.675529,4.924886,0.706616,-121.299553,0.071737,0.000000
46.910004,22.190422,-121.299553,0.004695,0.002799,0.071095,98.707924,5.028421,0.710952,-121.299553,0.072136,0.000000
47.150002,22.350540,-121.388512,0.004687,0.002814,0.071468,99.420166,5.064705,0.714681,-121.388512,0.072535,0.000000
47.390003,22.693123,-121.255074,0.004734,0.002832,0.071936,100.944054,5.142335,0.719364,-121.255074,0.072934,0.000000
47.630001,22.755676,-121.344032,0.004751,0.002846,0.072301,101.222305,5.156510,0.723007,-121.344032,0.073333,0.000000
47.870003,23.183533,-121.344032,0.004777,0.002862,0.072691,103.125504,5.253464,0.726909,-121.344032,0.073732,0.000000
48.110001,23.150398,-121.344032,0.004777,0.002872,0.072951,102.978111,5.245955,0.729511,-121.344032,0.074130,0.000000
48.350002,23.644531,-121.388512,0.004794,0.002890,0.073402,105.176125,5.357927,0.734020,-121.388512,0.074529,0.000000
48.590004,23.913383,-121.255074,0.004803,0.002907,0.073836,106.372040,5.418850,0.738356,-121.255074,0.074937,0.000000
48.830002,24.419067,-121.388512,0.004833,0.002926,0.074321,108.621437,5.533440,0.743213,-121.388512,0.075336,0.000000
49.070004,24.521469,-121.344032,0.004859,0.002940,0.074677,109.076942,5.556644,0.746768,-121.344032,0.075735,0.000000
49.310001,24.760162,-121.344032,0.004872,0.002956,0.075076,110.138702,5.610733,0.750758,-121.344032,0.076134,0.000000
49.550003,25.023804,-121.388512,0.004885,0.002967,0.075371,111.311440,5.670475,0.753706,-121.388512,0.076533,0.000000
49.790001,25.477722,-121.344032,0.004898,0.002985,0.075813,113.330566,5.773335,0.758130,-121.344032,0.076932,0.000000
50.030003,25.802803,-121.388512,0.004894,0.003002,0.076247,114.776604,5.846999,0.762465,-121.388512,0.077331,0.000000
50.270004,25.987503,-121.388512,0.004924,0.003015,0.076585,115.598190,5.888853,0.765847,-121.388512,0.077729,0.000000
50.510002,26.347588,-121.388512,0.004919,0.003030,0.076966,117.199921,5.970449,0.769663,-121.388512,0.078137,0.000000
50.750004,27.116531,-121.432999,0.004928,0.003053,0.077547,120.620354,6.144694,0.775474,-121.432999,0.078536,0.000000
50.990002,27.245377,-121.388512,0.004971,0.003069,0.077955,121.193489,6.173891,0.779549,-121.388512,0.078935,0.000000
51.230003,27.391716,-121.477478,0.004954,0.003083,0.078311,121.844437,6.207051,0.783105,-121.477478,0.079334,0.000000
51.470001,27.612160,-121.477478,0.004993,0.003098,0.078701,122.825020,6.257005,0.787007,-121.477478,0.079733,0.000000
51.710003,28.254501,-121.432999,0.005001,0.003115,0.079126,125.682297,6.402561,0.791257,-121.432999,0.080132,0.000000
51.950001,28.524849,-121.521957,0.005019,0.003131,0.079516,126.884865,6.463823,0.795160,-121.521957,0.080531,0.000000
52.190002,28.550911,-121.432999,0.005036,0.003143,0.079837,127.000793,6.469729,0.798369,-121.432999,0.080930,0.000000
52.430004,29.459503,-121.477478,0.005053,0.003164,0.080366,131.042419,6.675619,0.803658,-121.477478,0.081337,0.000000
52.670002,29.797241,-121.477478,0.005083,0.003181,0.080799,132.544754,6.752151,0.807995,-121.477478,0.081736,0.000000
52.910004,29.924591,-121.477478,0.005070,0.003194,0.081129,133.111237,6.781009,0.811290,-121.477478,0.082135,0.000000
53.150002,30.369209,-121.566437,0.005096,0.003211,0.081554,135.088989,6.881761,0.815540,-121.566437,0.082534,0.000000
53.390003,30.539757,-121.477478,0.005118,0.003224,0.081892,135.847626,6.920408,0.818922,-121.477478,0.082933,0.000000
53.630001,31.271835,-121.432999,0.005113,0.003244,0.082404,139.104065,7.086299,0.824038,-121.432999,0.083332,0.000000
53.870003,31.335510,-121.521957,0.005131,0.003254,0.082664,139.387314,7.100728,0.826640,-121.521957,0.083731,0.000000
54.110004,31.337006,-121.521957,0.005144,0.003263,0.082881,139.393967,7.101067,0.828808,-121.521957,0.084130,0.000000
54.350002,32.223991,-121.566437,0.005157,0.003285,0.083427,143.339478,7.302061,0.834271,-121.566437,0.084537,0.000000
54.590004,32.611259,-121.566437,0.005165,0.003298,0.083757,145.062134,7.389817,0.837567,-121.566437,0.084936,0.000000
54.830002,33.253235,-121.477478,0.005187,0.003318,0.084268,147.917770,7.535291,0.842683,-121.477478,0.085335,0.000000
55.070004,33.698219,-121.566437,0.005204,0.003336,0.084745,149.897171,7.636126,0.847453,-121.566437,0.085734,0.000000
55.310001,34.019943,-121.477478,0.005217,0.003350,0.085092,151.328262,7.709029,0.850922,-121.477478,0.086133,0.000000
55.550003,34.502914,-121.566437,0.005230,0.003368,0.085543,153.476624,7.818472,0.855432,-121.566437,0.086532,0.000000
55.790001,34.788895,-121.566437,0.005247,0.003381,0.085873,154.748734,7.883276,0.858727,-121.566437,0.086931,0.000000
56.030003,34.925186,-121.610924,0.005277,0.003394,0.086220,155.354980,7.914160,0.862196,-121.610924,0.087330,0.000000
56.270004,35.930962,-121.610924,0.005264,0.003415,0.086749,159.828903,8.142072,0.867487,-121.610924,0.087737,0.000000
56.510002,36.107841,-121.566437,0.005295,0.003426,0.087009,160.615707,8.182154,0.870088,-121.566437,0.088136,0.000000
56.750004,36.459732,-121.610924,0.005290,0.003439,0.087356,162.180984,8.261893,0.873557,-121.610924,0.088535,0.000000
56.990002,37.236504,-121.566437,0.005320,0.003459,0.087859,165.636246,8.437912,0.878587,-121.566437,0.088934,0.000000
57.230003,37.229797,-121.610924,0.005316,0.003469,0.088110,165.606415,8.436393,0.881102,-121.610924,0.089333,0.000000
57.470001,37.685951,-121.699883,0.005325,0.003483,0.088466,167.635483,8.539759,0.884658,-121.699883,0.089732,0.000000
57.710003,38.456017,-121.610924,0.005333,0.003501,0.088934,171.060898,8.714257,0.889341,-121.610924,0.090131,0.000000
57.950005,39.020912,-121.655403,0.005355,0.003519,0.089394,173.573685,8.842265,0.893936,-121.655403,0.090538,0.000000
58.190002,39.721344,-121.655403,0.005381,0.003536,0.089810,176.689362,9.000985,0.898100,-121.655403,0.090937,0.000000
58.430004,40.312668,-121.610924,0.005376,0.003552,0.090226,179.319702,9.134981,0.902262,-121.610924,0.091336,0.000000
58.670002,40.792282,-121.744362,0.005402,0.003569,0.090642,181.453140,9.243663,0.906425,-121.744362,0.091735,0.000000
58.910004,41.303925,-121.655403,0.005415,0.003585,0.091059,183.729034,9.359603,0.910587,-121.655403,0.092134,0.000000
59.150002,41.635338,-121.699883,0.005433,0.003597,0.091371,185.203232,9.434702,0.913710,-121.699883,0.092533,0.000000
59.390003,42.654518,-121.699883,0.005454,0.003619,0.091926,189.736771,9.665652,0.919259,-121.699883,0.092932,0.000000
59.630001,42.847038,-121.655403,0.005463,0.003630,0.092212,190.593140,9.709278,0.922122,-121.655403,0.093331,0.000000
59.870003,43.129669,-121.744362,0.005454,0.003643,0.092542,191.850357,9.773323,0.925417,-121.744362,0.093739,0.000000
60.110004,43.938835,-121.699883,0.005471,0.003664,0.093062,195.449707,9.956682,0.930620,-121.699883,0.094137,0.000000
60.350002,44.709641,-121.699883,0.005506,0.003680,0.093461,198.878418,10.131350,0.934610,-121.699883,0.094536,0.000000
60.590004,45.195213,-121.744362,0.005502,0.003696,0.093869,201.038345,10.241382,0.938685,-121.744362,0.094935,0.000000
60.830002,45.637596,-121.699883,0.005527,0.003709,0.094207,203.006165,10.341627,0.942068,-121.699883,0.095334,0.000000
61.070004,46.042366,-121.744362,0.005540,0.003722,0.094545,204.806671,10.433350,0.945450,-121.744362,0.095733,0.000000
61.310001,47.156876,-121.699883,0.005553,0.003745,0.095126,209.764252,10.685901,0.951261,-121.699883,0.096132,0.000000
61.550003,47.764961,-121.788841,0.005558,0.003759,0.095490,212.469162,10.823694,0.954903,-121.788841,0.096531,0.000000
61.790005,47.844276,-121.744362,0.005570,0.003769,0.095724,212.821976,10.841668,0.957244,-121.744362,0.096939,0.000000
62.030003,48.481033,-121.744362,0.005575,0.003784,0.096115,215.654404,10.985959,0.961147,-121.744362,0.097337,0.000000
62.270004,49.308815,-121.833328,0.005553,0.003800,0.096531,219.336563,11.173537,0.965309,-121.833328,0.097736,0.000000
62.510002,50.316452,-121.744362,0.005609,0.003823,0.097103,223.818756,11.401871,0.971033,-121.744362,0.098135,0.000000
62.750004,50.739098,-121.744362,0.005596,0.003836,0.097442,225.698776,11.497644,0.974416,-121.744362,0.098534,0.000000
62.990002,51.238823,-121.833328,0.005631,0.003848,0.097736,227.921661,11.610883,0.977364,-121.833328,0.098933,0.000000
63.230003,51.445488,-121.788841,0.005631,0.003861,0.098057,228.840958,11.657714,0.980573,-121.788841,0.099332,0.000000
63.470001,52.896248,-121.788841,0.005657,0.003883,0.098638,235.294266,11.986462,0.986383,-121.788841,0.099731,0.000000
63.710003,53.150208,-121.877808,0.005665,0.003893,0.098872,236.423935,12.044009,0.988724,-121.877808,0.100139,0.000000
63.950005,52.622185,-121.788841,0.005665,0.003896,0.098950,234.075165,11.924357,0.989505,-121.788841,0.100538,0.000000
64.190002,54.862747,-121.833328,0.005678,0.003927,0.099757,244.041687,12.432076,0.997571,-121.833328,0.100936,0.000000
64.430000,55.699471,-121.877808,0.005691,0.003947,0.100251,247.763626,12.621680,1.002514,-121.877808,0.101335,0.000000
64.670006,56.285583,-121.877808,0.005687,0.003959,0.100564,250.370773,12.754495,1.005635,-121.877808,0.101734,0.000000
64.910004,56.779724,-121.788841,0.005730,0.003971,0.100867,252.568832,12.866469,1.008671,-121.788841,0.102133,0.000000
65.150002,57.204231,-121.833328,0.005730,0.003987,0.101257,254.457123,12.962664,1.012573,-121.833328,0.102532,0.000000
65.389999,58.302727,-121.922287,0.005730,0.004005,0.101726,259.343475,13.211587,1.017256,-121.922287,0.102931,0.000000
65.630005,58.889961,-121.877808,0.005743,0.004015,0.101977,261.955627,13.344656,1.019771,-121.877808,0.103339,0.000000
65.870003,59.512566,-121.966766,0.005752,0.004028,0.102315,264.725128,13.485741,1.023154,-121.966766,0.103738,0.000000
66.110001,61.519653,-121.877808,0.005777,0.004060,0.103122,273.653076,13.940553,1.031218,-121.877808,0.104136,0.000000
66.350006,62.306107,-121.922287,0.005773,0.004073,0.103460,277.151398,14.118765,1.034601,-121.922287,0.104535,0.000000
66.590004,62.946960,-121.877808,0.005808,0.004089,0.103859,280.002075,14.263986,1.038590,-121.877808,0.104934,0.000000
66.830002,63.319702,-121.877808,0.005812,0.004102,0.104197,281.660095,14.348450,1.041972,-121.877808,0.105333,0.000000
67.070000,64.446503,-121.966766,0.005808,0.004118,0.104605,286.672363,14.603786,1.046048,-121.966766,0.105732,0.000000
67.310005,65.237793,-121.922287,0.005833,0.004133,0.104978,290.192200,14.783095,1.049778,-121.922287,0.106131,0.000000
67.550003,66.141907,-121.966766,0.005829,0.004148,0.105368,294.213898,14.987970,1.053680,-121.966766,0.106539,0.000000
67.790001,66.667328,-121.966766,0.005842,0.004160,0.105654,296.551086,15.107032,1.056541,-121.966766,0.106938,0.000000
68.030006,67.147690,-121.966766,0.005842,0.004162,0.105706,298.687836,15.215884,1.057062,-121.966766,0.105975,0.000000
68.270004,66.477417,-121.966766,0.005872,0.004162,0.105706,295.706329,15.063998,1.057062,-121.966766,0.105975,0.000000
68.510002,65.916992,-121.966766,0.005868,0.004160,0.105654,293.213440,14.937003,1.056541,-121.966766,0.105706,0.000000
68.750000,65.484680,-121.966766,0.005864,0.004159,0.105637,291.290405,14.839041,1.056368,-121.966766,0.105706,0.000000
68.990005,65.100754,-121.966766,0.005881,0.004159,0.105628,289.582611,14.752042,1.056281,-121.966766,0.105706,0.000000
69.230003,64.798767,-121.966766,0.005868,0.004158,0.105619,288.239319,14.683610,1.056195,-121.966766,0.105706,0.000000
69.470001,64.507202,-122.055733,0.005890,0.004158,0.105611,286.942352,14.617541,1.056108,-122.055733,0.105706,0.000000
69.710007,64.262543,-122.011246,0.005902,0.004158,0.105602,285.854065,14.562100,1.056021,-122.011246,0.105706,0.000000
69.950005,64.042099,-122.011246,0.005902,0.004157,0.105593,284.873474,14.512148,1.055935,-122.011246,0.105706,0.000000
70.190002,63.844376,-122.100212,0.005864,0.004157,0.105593,283.993958,14.467342,1.055935,-122.100212,0.105706,0.000000
70.430000,63.668243,-122.011246,0.005890,0.004157,0.105585,283.210480,14.427430,1.055848,-122.011246,0.105706,0.000000
70.670006,63.496582,-122.011246,0.005872,0.004157,0.105585,282.446899,14.388531,1.055848,-122.011246,0.105706,0.000000
70.910004,63.343536,-122.055733,0.005885,0.004157,0.105585,281.766113,14.353850,1.055848,-122.055733,0.105706,0.000000
71.150002,63.183792,-122.055733,0.005915,0.004157,0.105576,281.055542,14.317653,1.055761,-122.055733,0.105706,0.000000
71.390007,63.047867,-122.055733,0.005890,0.004157,0.105576,280.450928,14.286851,1.055761,-122.055733,0.105706,0.000000
71.630005,62.916794,-122.100212,0.005907,0.004157,0.105576,279.867889,14.257150,1.055761,-122.100212,0.105706,0.000000
71.870003,62.809555,-122.100212,0.005907,0.004157,0.105576,279.390869,14.232848,1.055761,-122.100212,0.105706,0.000000
72.110001,62.693001,-122.100212,0.005890,0.004156,0.105567,278.872406,14.206437,1.055674,-122.100212,0.105706,0.000000
72.350006,62.583893,-122.055733,0.005890,0.004156,0.105567,278.387054,14.181713,1.055674,-122.055733,0.105706,0.000000
72.590004,62.481865,-122.144691,0.005907,0.004156,0.105567,277.933228,14.158593,1.055674,-122.144691,0.105706,0.000000
72.830002,62.401062,-122.100212,0.005907,0.004156,0.105567,277.573792,14.140283,1.055674,-122.100212,0.105706,0.000000
73.070000,62.283020,-122.144691,0.005885,0.004156,0.105567,277.048706,14.113534,1.055674,-122.144691,0.105706,0.000000
73.310005,62.206680,-122.100212,0.005894,0.004156,0.105567,276.709137,14.096235,1.055674,-122.100212,0.105706,0.000000
73.550003,62.132950,-122.100212,0.005890,0.004156,0.105567,276.381165,14.079528,1.055674,-122.100212,0.105706,0.000000
73.790001,62.042465,-122.189171,0.005902,0.004156,0.105567,275.978668,14.059024,1.055674,-122.189171,0.105706,0.000000
74.030006,61.979530,-122.144691,0.005894,0.004156,0.105567,275.698730,14.044763,1.055674,-122.144691,0.105706,0.000000
74.270004,61.887558,-122.144691,0.005907,0.004156,0.105567,275.289612,14.023921,1.055674,-122.144691,0.105706,0.000000
74.510002,61.849205,-122.189171,0.005898,0.004156,0.105567,275.119019,14.015230,1.055674,-122.189171,0.105706,0.000000
74.750000,61.773987,-122.189171,0.005902,0.004156,0.105559,274.784424,13.998186,1.055587,-122.189171,0.105706,0.000000
74.990005,61.697273,-122.189171,0.005902,0.004156,0.105559,274.443176,13.980802,1.055587,-122.189171,0.105706,0.000000
75.230003,61.644402,-122.189171,0.005894,0.004156,0.105559,274.208008,13.968821,1.055587,-122.189171,0.105706,0.000000
75.470001,61.568062,-122.144691,0.005907,0.004156,0.105559,273.868408,13.951522,1.055587,-122.144691,0.105706,0.000000
75.710007,61.523003,-122.233650,0.005890,0.004156,0.105559,273.667969,13.941312,1.055587,-122.233650,0.105706,0.000000
75.950005,61.455231,-122.189171,0.005898,0.004156,0.105559,273.366516,13.925955,1.055587,-122.189171,0.105706,0.000000
76.190002,61.396027,-122.233650,0.005881,0.004156,0.105559,273.103180,13.912539,1.055587,-122.233650,0.105706,0.000000
76.430000,61.343895,-122.233650,0.005915,0.004156,0.105559,272.871277,13.900725,1.055587,-122.233650,0.105706,0.000000
76.670006,61.296974,-122.189171,0.005898,0.004156,0.105559,272.662567,13.890093,1.055587,-122.189171,0.105706,0.000000
76.910004,61.248940,-122.278137,0.005915,0.004156,0.105559,272.448883,13.879208,1.055587,-122.278137,0.105706,0.000000
77.150002,61.203506,-122.189171,0.005920,0.004156,0.105559,272.246796,13.868913,1.055587,-122.189171,0.105706,0.000000
77.390007,61.160316,-122.233650,0.005890,0.004156,0.105559,272.054687,13.859126,1.055587,-122.233650,0.105706,0.000000
77.630005,61.108925,-122.278137,0.005920,0.004156,0.105559,271.826080,13.847481,1.055587,-122.278137,0.105706,0.000000
77.870003,61.076904,-122.278137,0.005911,0.004156,0.105559,271.683624,13.840224,1.055587,-122.278137,0.105706,0.000000
78.110001,61.015457,-122.367096,0.005894,0.004156,0.105559,271.410309,13.826301,1.055587,-122.367096,0.105706,0.000000
78.350006,60.978966,-122.322617,0.005911,0.004156,0.105559,271.247986,13.818031,1.055587,-122.322617,0.105706,0.000000
78.590004,60.931679,-122.322617,0.005890,0.004156,0.105559,271.037659,13.807316,1.055587,-122.322617,0.105706,0.000000
78.830002,60.895554,-122.367096,0.005902,0.004156,0.105559,270.876953,13.799129,1.055587,-122.367096,0.105706,0.000000
79.070007,60.852364,-122.278137,0.005885,0.004156,0.105559,270.684845,13.789342,1.055587,-122.278137,0.105706,0.000000
79.310005,60.814011,-122.322617,0.005894,0.004156,0.105559,270.514221,13.780651,1.055587,-122.322617,0.105706,0.000000
79.550003,60.783844,-122.322617,0.005907,0.004156,0.105559,270.380035,13.773815,1.055587,-122.322617,0.105706,0.000000
79.790001,60.736557,-122.367096,0.005902,0.004156,0.105559,270.169708,13.763101,1.055587,-122.367096,0.105706,0.000000
80.030006,60.711235,-122.367096,0.005898,0.004156,0.105559,270.057068,13.757362,1.055587,-122.367096,0.105706,0.000000
80.270004,60.682556,-122.322617,0.005915,0.004156,0.105559,269.929504,13.750864,1.055587,-122.322617,0.105706,0.000000
80.510002,60.636757,-122.322617,0.005907,0.004156,0.105559,269.725769,13.740485,1.055587,-122.322617,0.105706,0.000000
80.750008,60.599892,-122.322617,0.005902,0.004156,0.105559,269.561768,13.732132,1.055587,-122.322617,0.105706,0.000000
80.990005,60.566383,-122.411575,0.005907,0.004156,0.105559,269.412720,13.724539,1.055587,-122.411575,0.105706,0.000000
81.230003,60.540688,-122.367096,0.005902,0.004156,0.105559,269.298431,13.718716,1.055587,-122.367096,0.105706,0.000000
81.470001,60.507172,-122.411575,0.005920,0.004156,0.105559,269.149353,13.711121,1.055587,-122.411575,0.105706,0.000000
81.710007,60.471428,-122.411575,0.005890,0.004156,0.105559,268.990356,13.703021,1.055587,-122.411575,0.105706,0.000000
81.950005,60.451317,-122.411575,0.005911,0.004156,0.105559,268.900879,13.698463,1.055587,-122.411575,0.105706,0.000000
82.190002,60.404770,-122.367096,0.005907,0.004156,0.105559,268.693848,13.687917,1.055587,-122.367096,0.105706,0.000000
82.430000,60.387268,-122.411575,0.005881,0.004156,0.105559,268.615997,13.683950,1.055587,-122.411575,0.105706,0.000000
82.670006,60.349655,-122.367096,0.005907,0.004156,0.105559,268.448669,13.675427,1.055587,-122.367096,0.105706,0.000000
82.910004,60.316521,-122.367096,0.005911,0.004156,0.105559,268.301270,13.667918,1.055587,-122.367096,0.105706,0.000000
83.150002,60.299019,-122.367096,0.005907,0.004156,0.105559,268.223419,13.663953,1.055587,-122.367096,0.105706,0.000000
83.390007,60.263268,-122.456055,0.005902,0.004156,0.105559,268.064392,13.655851,1.055587,-122.456055,0.105706,0.000000
83.630005,60.247253,-122.367096,0.005890,0.004156,0.105559,267.993164,13.652223,1.055587,-122.367096,0.105706,0.000000
83.870003,60.217842,-122.456055,0.005907,0.004156,0.105559,267.862335,13.645558,1.055587,-122.456055,0.105706,0.000000
84.110001,60.193634,-122.500542,0.005915,0.004156,0.105559,267.754669,13.640073,1.055587,-122.500542,0.105706,0.000000
84.350006,60.169800,-122.500542,0.005915,0.004156,0.105559,267.648651,13.634672,1.055587,-122.500542,0.105706,0.000000
84.590004,60.155281,-122.456055,0.005915,0.004156,0.105559,267.584045,13.631382,1.055587,-122.456055,0.105706,0.000000
84.830002,60.122139,-122.500542,0.005928,0.004156,0.105559,267.436646,13.623871,1.055587,-122.500542,0.105706,0.000000
85.070007,60.098305,-122.545021,0.005924,0.004156,0.105559,267.330597,13.618470,1.055587,-122.545021,0.105706,0.000000
85.310005,60.071121,-122.545021,0.005907,0.004156,0.105559,267.209686,13.612310,1.055587,-122.545021,0.105706,0.000000
85.550003,60.049530,-122.589500,0.005907,0.004156,0.105559,267.113647,13.607418,1.055587,-122.589500,0.105706,0.000000
85.790001,60.028671,-122.500542,0.005911,0.004156,0.105559,267.020874,13.602691,1.055587,-122.500542,0.105706,0.000000
86.030006,60.011169,-122.589500,0.005920,0.004156,0.105559,266.943024,13.598725,1.055587,-122.589500,0.105706,0.000000
86.270004,59.978035,-122.500542,0.005902,0.004156,0.105559,266.795624,13.591217,1.055587,-122.500542,0.105706,0.000000
86.510002,59.960159,-122.589500,0.005907,0.004156,0.105559,266.716095,13.587166,1.055587,-122.589500,0.105706,0.000000
86.750008,59.932228,-122.589500,0.005915,0.004156,0.105559,266.591858,13.580836,1.055587,-122.589500,0.105706,0.000000
86.990005,59.918449,-122.633980,0.005924,0.004156,0.105559,266.530579,13.577715,1.055587,-122.633980,0.105706,0.000000
87.230003,59.884567,-122.589500,0.005915,0.004156,0.105559,266.379852,13.570037,1.055587,-122.589500,0.105706,0.000000
87.470001,59.865204,-122.500542,0.005911,0.004156,0.105559,266.293732,13.565649,1.055587,-122.500542,0.105706,0.000000
87.710007,59.848816,-122.589500,0.005898,0.004156,0.105559,266.220825,13.561935,1.055587,-122.589500,0.105706,0.000000
87.950005,59.824989,-122.633980,0.005920,0.004156,0.105559,266.114838,13.556537,1.055587,-122.633980,0.105706,0.000000
88.190002,59.803017,-122.545021,0.005898,0.004156,0.105559,266.017090,13.551557,1.055587,-122.545021,0.105706,0.000000
88.430008,59.782906,-122.633980,0.005907,0.004156,0.105559,265.927643,13.547000,1.055587,-122.633980,0.105706,0.000000
88.670006,59.772110,-122.545021,0.005915,0.004156,0.105550,265.879639,13.544554,1.055501,-122.545021,0.105706,0.000000
88.910004,59.747162,-122.589500,0.005907,0.004156,0.105550,265.768646,13.538900,1.055501,-122.589500,0.105706,0.000000
89.150002,59.727051,-122.633980,0.005907,0.004156,0.105550,265.679199,13.534344,1.055501,-122.633980,0.105706,0.000000
89.390007,59.712898,-122.633980,0.005946,0.004156,0.105550,265.616241,13.531136,1.055501,-122.633980,0.105706,0.000000
89.630005,59.700989,-122.678467,0.005915,0.004156,0.105550,265.563263,13.528438,1.055501,-122.678467,0.105706,0.000000
89.870003,59.680130,-122.633980,0.005920,0.004156,0.105550,265.470490,13.523711,1.055501,-122.633980,0.105706,0.000000
90.110001,59.657043,-122.633980,0.005898,0.004156,0.105550,265.367798,13.518478,1.055501,-122.633980,0.105706,0.000000
90.350006,59.637680,-122.722946,0.005924,0.004156,0.105550,265.281647,13.514091,1.055501,-122.722946,0.105706,0.000000
90.590004,59.628372,-122.633980,0.005920,0.004156,0.105550,265.240234,13.511982,1.055501,-122.633980,0.105706,0.000000
90.830002,59.600075,-122.722946,0.005928,0.004156,0.105550,265.114380,13.505570,1.055501,-122.722946,0.105706,0.000000
91.070007,59.588905,-122.678467,0.005898,0.004156,0.105550,265.064697,13.503039,1.055501,-122.678467,0.105706,0.000000
91.310005,59.573265,-122.767426,0.005928,0.004156,0.105550,264.995117,13.499495,1.055501,-122.767426,0.105706,0.000000
91.550003,59.562836,-122.678467,0.005915,0.004156,0.105550,264.948730,13.497132,1.055501,-122.678467,0.105706,0.000000
91.790001,59.530067,-122.722946,0.005907,0.004156,0.105550,264.802979,13.489706,1.055501,-122.722946,0.105706,0.000000
92.030006,59.521500,-122.767426,0.005907,0.004156,0.105550,264.764862,13.487764,1.055501,-122.767426,0.105706,0.000000
92.270004,59.504372,-122.722946,0.005933,0.004156,0.105550,264.688660,13.483884,1.055501,-122.722946,0.105706,0.000000
92.510002,59.482407,-122.678467,0.005911,0.004156,0.105550,264.590973,13.478906,1.055501,-122.678467,0.105706,0.000000
92.750008,59.468254,-122.767426,0.005937,0.004156,0.105550,264.528015,13.475698,1.055501,-122.767426,0.105706,0.000000
92.990005,59.465271,-122.722946,0.005924,0.004156,0.105550,264.514740,13.475023,1.055501,-122.722946,0.105706,0.000000
93.230003,59.433250,-122.767426,0.005920,0.004156,0.105550,264.372314,13.467767,1.055501,-122.767426,0.105706,0.000000
93.470001,59.424316,-122.678467,0.005928,0.004156,0.105550,264.332550,13.465742,1.055501,-122.678467,0.105706,0.000000
93.710007,59.417984,-122.767426,0.005907,0.004156,0.105550,264.304382,13.464308,1.055501,-122.767426,0.105706,0.000000
93.950005,59.397133,-122.811905,0.005933,0.004156,0.105550,264.211639,13.459582,1.055501,-122.811905,0.105706,0.000000
94.190002,59.375908,-122.767426,0.005924,0.004156,0.105550,264.117218,13.454773,1.055501,-122.767426,0.105706,0.000000
94.430008,59.365105,-122.811905,0.005907,0.004156,0.105550,264.069183,13.452326,1.055501,-122.811905,0.105706,0.000000
94.670006,59.352448,-122.811905,0.005911,0.004156,0.105550,264.012878,13.449456,1.055501,-122.811905,0.105706,0.000000
94.910004,59.328987,-122.811905,0.005885,0.004156,0.105550,263.908508,13.444140,1.055501,-122.811905,0.105706,0.000000
95.150002,59.315208,-122.811905,0.005885,0.004156,0.105550,263.847229,13.441018,1.055501,-122.811905,0.105706,0.000000
95.390007,59.314095,-122.767426,0.005937,0.004156,0.105550,263.842255,13.440765,1.055501,-122.767426,0.105706,0.000000
95.630005,59.295097,-122.856384,0.005920,0.004156,0.105550,263.757751,13.436460,1.055501,-122.856384,0.105706,0.000000
95.870003,59.294731,-122.811905,0.005902,0.004156,0.105550,263.756134,13.436378,1.055501,-122.811905,0.105706,0.000000
96.110008,59.263824,-122.900871,0.005902,0.004156,0.105550,263.618652,13.429374,1.055501,-122.900871,0.105706,0.000000
96.350006,59.260094,-122.811905,0.005933,0.004156,0.105550,263.602051,13.428529,1.055501,-122.811905,0.105706,0.000000
96.590004,59.237007,-122.856384,0.005915,0.004156,0.105550,263.499359,13.423298,1.055501,-122.856384,0.105706,0.000000
96.830002,59.222488,-122.900871,0.005907,0.004156,0.105550,263.434784,13.420008,1.055501,-122.900871,0.105706,0.000000
97.070007,59.210945,-122.856384,0.005928,0.004156,0.105550,263.383453,13.417392,1.055501,-122.856384,0.105706,0.000000
97.310005,59.192696,-122.856384,0.005924,0.004156,0.105550,263.302246,13.413257,1.055501,-122.856384,0.105706,0.000000
97.550003,59.193443,-122.900871,0.005928,0.004156,0.105550,263.305573,13.413426,1.055501,-122.900871,0.105706,0.000000
97.790001,59.168495,-122.900871,0.005911,0.004156,0.105550,263.194611,13.407773,1.055501,-122.900871,0.105706,0.000000
98.030006,59.168869,-122.900871,0.005915,0.004156,0.105550,263.196289,13.407858,1.055501,-122.900871,0.105706,0.000000
98.270004,59.139450,-122.900871,0.005915,0.004156,0.105550,263.065399,13.401191,1.055501,-122.900871,0.105706,0.000000
98.400002,59.135727,-122.945351,0.005924,0.004156,0.105550,263.048859,13.400347,1.055501,-122.945351,0.105706,0.000000