File: Data/Symmetrical membranes compression/Millioire Express PES 045um test 1_10302023_172215.csv
Time (sec),S:Load (lbs),S:HL1 (DIM),S:LVDT (in),S:Position (in),Ch:Position (mm),Ch:Load (N),Ch:Stress (MPa),Ch:Strain (mm/mm),Ch:HL1 (DIM),Set Point (),Cycles ()
0.110000,-0.001862,-110.001389,-0.000013,-0.000000,-0.000000,-0.008281,-0.000422,-0.000000,-110.001389,0.000278,0.000000
0.350000,0.010056,-109.912430,-0.000017,-0.000000,-0.000000,0.044729,0.002279,-0.000000,-109.912430,0.000364,0.000000
0.590000,0.001862,-109.956909,0.000013,0.000127,0.003235,0.008281,0.000422,0.032348,-109.956909,0.004353,0.000000
0.830000,0.003349,-110.001389,0.000155,0.000289,0.007328,0.014898,0.000759,0.073281,-110.001389,0.008360,0.000000
1.070000,-0.002975,-110.001389,0.000293,0.000440,0.011187,-0.013236,-0.000674,0.111872,-110.001389,0.012349,0.000000
1.310000,0.014893,-110.045876,0.000427,0.000599,0.015211,0.066245,0.003375,0.152112,-110.045876,0.016356,0.000000
1.550000,0.034256,-110.001389,0.000621,0.000749,0.019018,0.152378,0.007763,0.190183,-110.001389,0.020345,0.000000
1.790000,0.063675,-110.134834,0.000806,0.000910,0.023112,0.283240,0.014429,0.231116,-110.134834,0.024352,0.000000
2.030000,0.120277,-110.045876,0.000949,0.001069,0.027153,0.535021,0.027255,0.271528,-110.045876,0.028341,0.000000
2.270000,0.334023,-110.090355,0.001117,0.001224,0.031081,1.485806,0.075691,0.310814,-110.090355,0.032348,0.000000
2.510000,0.666176,-110.045876,0.001289,0.001380,0.035045,2.963298,0.150958,0.350446,-110.045876,0.036337,0.000000
2.750000,0.678467,-110.090355,0.001293,-0.000000,-0.000000,3.017971,0.153743,-0.000000,-110.090355,0.000269,0.000000
2.990000,0.653145,-110.045876,0.001298,-0.000000,-0.000000,2.905333,0.148005,-0.000000,-110.045876,0.000269,0.000000
3.230000,0.605850,-110.045876,0.001272,-0.000000,-0.000000,2.694956,0.137288,-0.000000,-110.045876,0.000494,0.000000
3.470000,0.628563,-110.090355,0.001298,-0.000000,-0.000000,2.795988,0.142434,-0.000000,-110.090355,0.000902,0.000000
3.710000,0.603615,-110.134834,0.001289,0.000000,0.000009,2.685013,0.136781,0.000087,-110.134834,0.001301,0.000000
3.950000,0.679955,-110.090355,0.001319,0.000025,0.000642,3.024589,0.154080,0.006417,-110.090355,0.001700,0.000000
4.190000,0.726875,-110.134834,0.001311,0.000040,0.001023,3.233303,0.164712,0.010233,-110.134834,0.002099,0.000000
4.430000,0.766342,-110.134834,0.001345,0.000058,0.001474,3.408860,0.173656,0.014743,-110.134834,0.002498,0.000000
4.670000,0.825920,-110.134834,0.001328,0.000076,0.001934,3.673876,0.187156,0.019339,-110.134834,0.002897,0.000000
4.910000,0.878426,-110.134834,0.001375,0.000091,0.002316,3.907432,0.199054,0.023155,-110.134834,0.003295,0.000000
5.150000,0.937637,-110.090355,0.001375,0.000106,0.002680,4.170819,0.212472,0.026797,-110.090355,0.003694,0.000000
5.390000,0.983810,-110.134834,0.001401,0.000119,0.003027,4.376207,0.222935,0.030266,-110.134834,0.004102,0.000000
5.630000,1.050461,-110.134834,0.001423,0.000135,0.003417,4.672683,0.238038,0.034169,-110.134834,0.004501,0.000000
5.870000,1.103340,-110.179314,0.001444,0.000154,0.003903,4.907902,0.250020,0.039025,-110.179314,0.004900,0.000000
6.110000,1.174095,-110.268280,0.001453,0.000172,0.004371,5.222636,0.266054,0.043708,-110.268280,0.005299,0.000000
6.350000,1.198296,-110.134834,0.001457,0.000185,0.004709,5.330285,0.271538,0.047091,-110.134834,0.005698,0.000000
6.590000,1.245590,-110.223793,0.001513,0.000201,0.005099,5.540662,0.282255,0.050993,-110.223793,0.006097,0.000000
6.830000,1.271278,-110.179314,0.001496,0.000212,0.005377,5.654929,0.288076,0.053768,-110.179314,0.006496,0.000000
7.070000,1.363258,-110.179314,0.001522,0.000229,0.005810,6.064076,0.308919,0.058104,-110.179314,0.006894,0.000000
7.310000,1.452995,-110.223793,0.001535,0.000247,0.006261,6.463246,0.329253,0.062614,-110.223793,0.007302,0.000000
7.550000,1.522263,-110.223793,0.001552,0.000258,0.006556,6.771362,0.344950,0.065562,-110.223793,0.007701,0.000000
7.790000,1.601944,-110.223793,0.001582,0.000279,0.007094,7.125803,0.363006,0.070939,-110.223793,0.008100,0.000000
8.030001,1.684990,-110.223793,0.001608,0.000298,0.007571,7.495210,0.381824,0.075709,-110.223793,0.008499,0.000000
8.270000,1.701744,-110.223793,0.001604,0.000313,0.007961,7.569736,0.385621,0.079611,-110.223793,0.008898,0.000000
8.510000,1.748665,-110.223793,0.001634,0.000327,0.008308,7.778450,0.396253,0.083080,-110.223793,0.009297,0.000000
8.750000,1.804893,-110.179314,0.001638,0.000343,0.008707,8.028567,0.408995,0.087070,-110.179314,0.009696,0.000000
8.990001,1.933731,-110.223793,0.001673,0.000361,0.009158,8.601665,0.438190,0.091579,-110.223793,0.010095,0.000000
9.230000,1.979164,-110.268280,0.001664,0.000375,0.009531,8.803761,0.448485,0.095308,-110.268280,0.010502,0.000000
9.470000,2.023102,-110.268280,0.001669,0.000385,0.009791,8.999207,0.458441,0.097910,-110.268280,0.010901,0.000000
9.710000,2.128113,-110.312759,0.001699,0.000408,0.010372,9.466318,0.482237,0.103720,-110.312759,0.011300,0.000000
9.950001,2.207794,-110.312759,0.001729,0.000422,0.010728,9.820759,0.500293,0.107276,-110.312759,0.011699,0.000000
10.190001,2.210030,-110.357239,0.001750,0.000437,0.011101,9.830703,0.500800,0.111005,-110.357239,0.012098,0.000000
10.430000,2.304985,-110.268280,0.001750,0.000454,0.011543,10.253085,0.522317,0.115428,-110.268280,0.012497,0.000000
10.670000,2.370895,-110.223793,0.001785,0.000468,0.011890,10.546269,0.537253,0.118897,-110.223793,0.012896,0.000000
10.910001,2.499367,-110.312759,0.001789,0.000488,0.012393,11.117739,0.566365,0.123927,-110.312759,0.013295,0.000000
11.150001,2.513885,-110.312759,0.001824,0.000499,0.012670,11.182322,0.569655,0.126701,-110.312759,0.013702,0.000000
11.390000,2.524689,-110.446205,0.001798,0.000509,0.012930,11.230376,0.572103,0.129303,-110.446205,0.014101,0.000000
11.630000,2.593575,-110.357239,0.001845,0.000517,0.013130,11.536796,0.587712,0.131298,-110.357239,0.014500,0.000000
11.870001,2.758537,-110.401718,0.001871,0.000546,0.013867,12.270587,0.625093,0.138669,-110.401718,0.014899,0.000000
12.110001,2.828171,-110.357239,0.001880,0.000562,0.014283,12.580332,0.640873,0.142832,-110.357239,0.015298,0.000000
12.350000,2.917542,-110.312759,0.001901,0.000580,0.014734,12.977873,0.661124,0.147341,-110.312759,0.015697,0.000000
12.590000,2.973396,-110.401718,0.001901,0.000593,0.015055,13.226327,0.673781,0.150551,-110.401718,0.016096,0.000000
12.830001,3.076912,-110.446205,0.001927,0.000612,0.015549,13.686788,0.697238,0.155494,-110.446205,0.016495,0.000000
13.070001,3.124580,-110.401718,0.001927,0.000625,0.015888,13.898828,0.708040,0.158876,-110.401718,0.016902,0.000000
13.310000,3.141335,-110.446205,0.001940,0.000633,0.016087,13.973354,0.711837,0.160870,-110.446205,0.017301,0.000000
13.550000,3.302948,-110.401718,0.001988,0.000655,0.016642,14.692246,0.748459,0.166421,-110.401718,0.017700,0.000000
13.790001,3.363640,-110.446205,0.001983,0.000673,0.017084,14.962217,0.762212,0.170844,-110.446205,0.018099,0.000000
14.030001,3.436996,-110.446205,0.002005,0.000684,0.017379,15.288524,0.778835,0.173792,-110.446205,0.018498,0.000000
14.270000,3.526741,-110.446205,0.002001,0.000704,0.017874,15.687728,0.799171,0.178735,-110.446205,0.018897,0.000000
14.510000,3.565468,-110.490685,0.002039,0.000713,0.018116,15.859993,0.807947,0.181163,-110.490685,0.019296,0.000000
14.750001,3.709946,-110.401718,0.002052,0.000734,0.018637,16.502663,0.840686,0.186366,-110.401718,0.019703,0.000000
14.990001,3.785164,-110.490685,0.002065,0.000748,0.018992,16.837250,0.857730,0.189922,-110.490685,0.020102,0.000000
15.230000,3.855919,-110.446205,0.002091,0.000761,0.019339,17.151983,0.873764,0.193391,-110.446205,0.020501,0.000000
15.470000,4.001518,-110.446205,0.002108,0.000783,0.019894,17.799643,0.906757,0.198942,-110.446205,0.020900,0.000000
15.710001,4.069290,-110.579643,0.002104,0.000799,0.020284,18.101107,0.922114,0.202844,-110.579643,0.021299,0.000000
15.950001,4.151955,-110.490685,0.002134,0.000814,0.020675,18.468817,0.940846,0.206747,-110.490685,0.021698,0.000000
16.190001,4.243927,-110.535164,0.002151,0.000831,0.021100,18.877930,0.961688,0.210996,-110.535164,0.022097,0.000000
16.430000,4.294197,-110.490685,0.002182,0.000842,0.021386,19.101543,0.973079,0.213858,-110.490685,0.022496,0.000000
16.670000,4.478149,-110.490685,0.002195,0.000863,0.021923,19.919804,1.014763,0.219234,-110.490685,0.022903,0.000000
16.910002,4.519112,-110.535164,0.002203,0.000875,0.022227,20.102013,1.024045,0.222270,-110.535164,0.023302,0.000000
17.150002,4.591354,-110.535164,0.002220,0.000888,0.022548,20.423365,1.040416,0.225479,-110.535164,0.023701,0.000000
17.390001,4.726524,-110.535164,0.002229,0.000908,0.023060,21.024630,1.071046,0.230596,-110.535164,0.024100,0.000000
17.630001,4.844940,-110.579643,0.002272,0.000925,0.023485,21.551371,1.097879,0.234845,-110.579643,0.024499,0.000000
17.870001,4.895210,-110.535164,0.002276,0.000935,0.023745,21.774982,1.109271,0.237446,-110.535164,0.024898,0.000000
18.110001,4.969315,-110.579643,0.002285,0.000954,0.024222,22.104616,1.126063,0.242216,-110.579643,0.025297,0.000000
18.350000,5.046394,-110.579643,0.002307,0.000967,0.024560,22.447483,1.143529,0.245598,-110.579643,0.025696,0.000000
18.590000,5.230347,-110.579643,0.002320,0.000989,0.025115,23.265743,1.185213,0.251149,-110.579643,0.026103,0.000000
18.830002,5.361046,-110.624123,0.002345,0.001007,0.025566,23.847122,1.214830,0.255658,-110.624123,0.026502,0.000000
19.070002,5.368126,-110.535164,0.002333,0.001015,0.025783,23.878616,1.216435,0.257826,-110.535164,0.026901,0.000000
19.310001,5.441483,-110.624123,0.002337,0.001029,0.026138,24.204924,1.233058,0.261382,-110.624123,0.027300,0.000000
19.550001,5.564362,-110.624123,0.002371,0.001045,0.026546,24.751516,1.260902,0.265457,-110.624123,0.027699,0.000000
19.790001,5.722992,-110.624123,0.002402,0.001066,0.027066,25.457140,1.296849,0.270661,-110.624123,0.028098,0.000000
20.030001,5.752785,-110.668610,0.002423,0.001083,0.027500,25.589664,1.303600,0.274997,-110.668610,0.028497,0.000000
20.270000,5.816460,-110.624123,0.002453,0.001095,0.027812,25.872904,1.318029,0.278120,-110.624123,0.028896,0.000000
20.510000,5.929657,-110.713089,0.002449,0.001110,0.028193,26.376432,1.343680,0.281935,-110.713089,0.029304,0.000000
20.750002,6.119568,-110.624123,0.002471,0.001131,0.028723,27.221197,1.386714,0.287225,-110.624123,0.029702,0.000000
20.990002,6.103188,-110.624123,0.002488,0.001137,0.028887,27.148335,1.383002,0.288873,-110.624123,0.030101,0.000000
21.230001,6.259209,-110.668610,0.002492,0.001159,0.029434,27.842350,1.418357,0.294336,-110.668610,0.030500,0.000000
21.470001,6.403687,-110.668610,0.002514,0.001175,0.029841,28.485020,1.451096,0.298412,-110.668610,0.030899,0.000000
21.710001,6.535141,-110.757568,0.002527,0.001193,0.030301,29.069759,1.480884,0.303008,-110.757568,0.031298,0.000000
21.950001,6.515404,-110.668610,0.002565,0.001206,0.030639,28.981964,1.476412,0.306391,-110.668610,0.031697,0.000000
22.190001,6.608864,-110.757568,0.002570,0.001220,0.030977,29.397694,1.497590,0.309773,-110.757568,0.032096,0.000000
22.430000,6.764145,-110.757568,0.002583,0.001237,0.031420,30.088419,1.532777,0.314195,-110.757568,0.032504,0.000000
22.670002,6.902298,-110.668610,0.002608,0.001252,0.031810,30.702955,1.564083,0.318099,-110.668610,0.032903,0.000000
22.910002,6.859100,-110.713089,0.002617,0.001260,0.032009,30.510801,1.554294,0.320093,-110.713089,0.033301,0.000000
23.150002,6.943634,-110.713089,0.002634,0.001273,0.032330,30.886827,1.573450,0.323302,-110.713089,0.033700,0.000000
23.390001,7.354355,-110.713089,0.002660,0.001306,0.033163,32.713806,1.666521,0.331627,-110.713089,0.034099,0.000000
23.630001,7.331268,-110.846527,0.002673,0.001320,0.033518,32.611111,1.661289,0.335183,-110.846527,0.034498,0.000000
23.870001,7.382286,-110.757568,0.002677,0.001336,0.033926,32.838047,1.672850,0.339259,-110.757568,0.034897,0.000000
24.110001,7.395691,-110.802048,0.002695,0.001348,0.034229,32.897675,1.675887,0.342294,-110.802048,0.035296,0.000000
24.350000,7.539429,-110.846527,0.002733,0.001362,0.034594,33.537052,1.708459,0.345937,-110.846527,0.035704,0.000000
24.590002,7.731567,-110.802048,0.002716,0.001380,0.035053,34.391731,1.751998,0.350532,-110.802048,0.036103,0.000000
24.830002,7.805672,-110.802048,0.002746,0.001393,0.035392,34.721363,1.768790,0.353915,-110.802048,0.036502,0.000000
25.070002,7.858177,-110.757568,0.002768,0.001405,0.035678,34.954918,1.780688,0.356777,-110.757568,0.036900,0.000000
25.310001,8.055908,-110.846527,0.002772,0.001428,0.036276,35.834469,1.825495,0.362760,-110.846527,0.037299,0.000000
25.550001,8.170227,-110.802048,0.002802,0.001443,0.036658,36.342983,1.851400,0.366577,-110.802048,0.037698,0.000000
25.790001,8.248795,-110.757568,0.002807,0.001460,0.037083,36.692471,1.869204,0.370826,-110.757568,0.038097,0.000000
26.030001,8.370186,-110.846527,0.002833,0.001477,0.037516,37.232445,1.896711,0.375162,-110.846527,0.038496,0.000000
26.270000,8.488228,-110.757568,0.002850,0.001493,0.037924,37.757523,1.923460,0.379238,-110.757568,0.038904,0.000000
26.510002,8.535149,-110.846527,0.002863,0.001507,0.038271,37.966236,1.934092,0.382707,-110.846527,0.039303,0.000000
26.750002,8.626755,-110.891014,0.002902,0.001521,0.038635,38.373722,1.954851,0.386349,-110.891014,0.039702,0.000000
26.990002,8.756340,-110.891014,0.002897,0.001533,0.038938,38.950146,1.984215,0.389384,-110.891014,0.040100,0.000000
27.230001,8.805496,-110.891014,0.002902,0.001546,0.039268,39.168804,1.995354,0.392680,-110.891014,0.040499,0.000000
27.470001,9.148445,-110.802048,0.002936,0.001572,0.039918,40.694317,2.073067,0.399184,-110.802048,0.040898,0.000000
27.710001,9.120148,-110.935493,0.002958,0.001586,0.040283,40.568443,2.066655,0.402826,-110.935493,0.041297,0.000000
27.950001,9.189407,-110.891014,0.002949,0.001600,0.040647,40.876526,2.082350,0.406468,-110.891014,0.041705,0.000000
28.190001,9.216217,-110.846527,0.002997,0.001611,0.040907,40.995781,2.088425,0.409070,-110.846527,0.042104,0.000000
28.430002,9.389374,-110.979973,0.002984,0.001628,0.041341,41.766022,2.127663,0.413406,-110.979973,0.042503,0.000000
28.670002,9.562523,-110.891014,0.003001,0.001646,0.041818,42.536224,2.166899,0.418176,-110.891014,0.042902,0.000000
28.910002,9.688759,-110.935493,0.003009,0.001661,0.042191,43.097752,2.195504,0.421905,-110.935493,0.043301,0.000000
29.150002,9.979210,-110.935493,0.003040,0.001685,0.042798,44.389744,2.261321,0.427976,-110.935493,0.043700,0.000000
29.390001,10.013840,-110.979973,0.003074,0.001702,0.043223,44.543785,2.269169,0.432226,-110.979973,0.044098,0.000000
29.630001,10.089058,-110.979973,0.003074,0.001716,0.043578,44.878372,2.286213,0.435780,-110.979973,0.044497,0.000000
29.870001,10.109543,-110.979973,0.003109,0.001728,0.043899,44.969494,2.290855,0.438990,-110.979973,0.044905,0.000000
30.110001,10.341156,-110.979973,0.003134,0.001749,0.044437,45.999760,2.343339,0.444367,-110.979973,0.045304,0.000000
30.350002,10.436111,-110.979973,0.003122,0.001763,0.044792,46.422142,2.364857,0.447922,-110.979973,0.045703,0.000000
30.590002,10.462921,-110.979973,0.003130,0.001774,0.045052,46.541397,2.370932,0.450524,-110.979973,0.046102,0.000000
30.830002,10.645386,-111.024452,0.003169,0.001791,0.045495,47.353043,2.412279,0.454946,-111.024452,0.046501,0.000000
31.070002,10.916473,-110.979973,0.003173,0.001810,0.045980,48.558899,2.473708,0.459803,-110.979973,0.046900,0.000000
31.310001,10.973076,-110.979973,0.003199,0.001825,0.046362,48.810680,2.486534,0.463618,-110.979973,0.047299,0.000000
31.550001,11.083664,-110.935493,0.003221,0.001842,0.046795,49.302601,2.511594,0.467955,-110.935493,0.047697,0.000000
31.790001,11.174530,-110.935493,0.003242,0.001856,0.047142,49.706791,2.532185,0.471424,-110.935493,0.048105,0.000000
32.030003,11.216980,-111.024452,0.003238,0.001869,0.047472,49.895618,2.541804,0.474719,-111.024452,0.048504,0.000000
32.270000,11.484337,-110.979973,0.003294,0.001888,0.047958,51.084881,2.602388,0.479576,-110.979973,0.048903,0.000000
32.510002,11.470932,-111.068932,0.003285,0.001900,0.048261,51.025253,2.599350,0.482611,-111.068932,0.049302,0.000000
32.750000,11.349915,-111.024452,0.003298,0.001903,0.048339,50.486942,2.571927,0.483392,-111.024452,0.049701,0.000000
32.990002,11.917412,-111.068932,0.003337,0.001934,0.049128,53.011295,2.700524,0.491283,-111.068932,0.050100,0.000000
33.230003,12.056679,-111.113419,0.003333,0.001949,0.049501,53.630787,2.732082,0.495012,-111.113419,0.050499,0.000000
33.470001,12.074921,-111.024452,0.003341,0.001963,0.049857,53.711929,2.736216,0.498568,-111.024452,0.050897,0.000000
33.710003,12.338562,-111.113419,0.003354,0.001983,0.050368,54.884666,2.795958,0.503684,-111.113419,0.051305,0.000000
33.950001,12.365372,-111.068932,0.003376,0.001998,0.050750,55.003922,2.802033,0.507500,-111.068932,0.051704,0.000000
34.190002,12.526611,-111.068932,0.003372,0.002013,0.051140,55.721149,2.838571,0.511403,-111.068932,0.052103,0.000000
34.430000,12.566452,-111.113419,0.003402,0.002025,0.051444,55.898369,2.847599,0.514438,-111.113419,0.052502,0.000000
34.670002,12.598480,-111.113419,0.003410,0.002039,0.051782,56.040840,2.854856,0.517821,-111.113419,0.052901,0.000000
34.910000,12.965263,-111.113419,0.003436,0.002058,0.052285,57.672371,2.937971,0.522850,-111.113419,0.053300,0.000000
35.150002,13.094109,-111.068932,0.003454,0.002073,0.052649,58.245502,2.967167,0.526493,-111.068932,0.053699,0.000000
35.390003,13.112350,-111.157898,0.003479,0.002086,0.052996,58.326649,2.971301,0.529962,-111.157898,0.054098,0.000000
35.630001,13.336891,-111.157898,0.003492,0.002105,0.053464,59.325455,3.022183,0.534645,-111.157898,0.054505,0.000000
35.870003,13.296677,-111.113419,0.003479,0.002114,0.053690,59.146572,3.013070,0.536900,-111.113419,0.054904,0.000000
36.110001,13.605743,-111.202377,0.003505,0.002136,0.054254,60.521370,3.083106,0.542536,-111.202377,0.055303,0.000000
36.350002,13.782249,-111.157898,0.003548,0.002151,0.054627,61.306507,3.123102,0.546265,-111.157898,0.055702,0.000000
36.590000,13.540581,-111.157898,0.003548,0.002151,0.054635,60.231510,3.068340,0.546352,-111.157898,0.056101,0.000000
36.830002,14.331131,-111.202377,0.003574,0.002185,0.055494,63.748055,3.247481,0.554938,-111.202377,0.056500,0.000000
37.070004,14.339317,-111.157898,0.003596,0.002198,0.055832,63.784470,3.249336,0.558320,-111.157898,0.056899,0.000000
37.310001,14.448051,-111.246857,0.003591,0.002216,0.056283,64.268143,3.273975,0.562829,-111.246857,0.057298,0.000000
37.550003,14.646156,-111.202377,0.003622,0.002233,0.056708,65.149361,3.318866,0.567079,-111.202377,0.057705,0.000000
37.790001,14.642059,-111.246857,0.003613,0.002247,0.057081,65.131134,3.317938,0.570808,-111.246857,0.058104,0.000000
38.030003,14.916496,-111.246857,0.003639,0.002262,0.057445,66.351891,3.380126,0.574451,-111.246857,0.058503,0.000000
38.270000,15.042358,-111.246857,0.003669,0.002280,0.057905,66.911751,3.408647,0.579046,-111.246857,0.058902,0.000000
38.510002,15.101196,-111.291336,0.003678,0.002292,0.058208,67.173477,3.421980,0.582082,-111.291336,0.059301,0.000000
38.750000,15.447876,-111.246857,0.003712,0.002310,0.058668,68.715584,3.500539,0.586679,-111.246857,0.059700,0.000000
38.990002,15.557350,-111.246857,0.003712,0.002326,0.059084,69.202553,3.525346,0.590841,-111.246857,0.060099,0.000000
39.230003,15.698105,-111.246857,0.003721,0.002342,0.059474,69.828659,3.557241,0.594743,-111.246857,0.060498,0.000000
39.470001,15.806465,-111.291336,0.003725,0.002354,0.059804,70.310669,3.581796,0.598039,-111.291336,0.060905,0.000000
39.710003,15.918922,-111.291336,0.003768,0.002367,0.060116,70.810905,3.607279,0.601161,-111.291336,0.061304,0.000000
39.950001,16.538551,-111.291336,0.003790,0.002392,0.060749,73.567154,3.747689,0.607492,-111.291336,0.061703,0.000000
40.190002,16.573181,-111.291336,0.003786,0.002406,0.061105,73.721191,3.755537,0.611048,-111.291336,0.062102,0.000000
40.430000,16.346039,-111.291336,0.003798,0.002416,0.061356,72.710815,3.704065,0.613562,-111.291336,0.062501,0.000000
40.670002,16.810387,-111.335823,0.003807,0.002436,0.061877,74.776337,3.809288,0.618766,-111.335823,0.062900,0.000000
40.910004,17.196159,-111.335823,0.003842,0.002456,0.062371,76.492340,3.896705,0.623709,-111.335823,0.063299,0.000000
41.150002,17.235260,-111.380302,0.003859,0.002470,0.062735,76.666267,3.905566,0.627351,-111.380302,0.063698,0.000000
41.390003,17.335426,-111.380302,0.003876,0.002485,0.063108,77.111824,3.928264,0.631080,-111.380302,0.064105,0.000000
41.630001,17.352554,-111.424782,0.003872,0.002494,0.063342,77.188019,3.932145,0.633422,-111.424782,0.064504,0.000000
41.870003,17.596458,-111.335823,0.003898,0.002513,0.063828,78.272957,3.987414,0.638278,-111.335823,0.064903,0.000000
42.110001,18.097672,-111.380302,0.003923,0.002532,0.064305,80.502464,4.100991,0.643048,-111.380302,0.065302,0.000000
42.350002,17.862709,-111.424782,0.003954,0.002536,0.064409,79.457298,4.047748,0.644089,-111.424782,0.065701,0.000000
42.590000,18.155022,-111.380302,0.003954,0.002553,0.064834,80.757568,4.113986,0.648338,-111.380302,0.066100,0.000000
42.830002,18.691978,-111.424782,0.003958,0.002575,0.065415,83.146072,4.235663,0.654148,-111.424782,0.066499,0.000000
43.070004,18.983551,-111.335823,0.003992,0.002595,0.065909,84.443054,4.301734,0.659091,-111.335823,0.066906,0.000000
43.310001,19.000679,-111.424782,0.003992,0.002607,0.066230,84.519241,4.305615,0.662300,-111.424782,0.067305,0.000000
43.550003,19.069565,-111.424782,0.003992,0.002620,0.066560,84.825661,4.321225,0.665596,-111.424782,0.067704,0.000000
43.790001,19.323151,-111.380302,0.004010,0.002637,0.066985,85.953667,4.378689,0.669845,-111.380302,0.068103,0.000000
44.030003,19.707443,-111.513741,0.004057,0.002654,0.067418,87.663086,4.465770,0.674182,-111.513741,0.068502,0.000000
44.270000,19.831070,-111.424782,0.004079,0.002669,0.067791,88.213005,4.493784,0.677911,-111.424782,0.068901,0.000000
44.510002,19.589401,-111.469261,0.004053,0.002671,0.067852,87.138008,4.439022,0.678517,-111.469261,0.069300,0.000000
44.750004,20.689018,-111.469261,0.004092,0.002707,0.068754,92.029350,4.688199,0.687537,-111.469261,0.069699,0.000000
44.990002,20.800354,-111.469261,0.004100,0.002723,0.069153,92.524597,4.713428,0.691526,-111.469261,0.070107,0.000000
45.230003,20.803703,-111.513741,0.004113,0.002737,0.069508,92.539497,4.714187,0.695082,-111.513741,0.070505,0.000000
45.470001,20.889725,-111.469261,0.004139,0.002751,0.069881,92.922134,4.733679,0.698811,-111.469261,0.070904,0.000000
45.710003,21.373810,-111.558228,0.004139,0.002767,0.070280,95.075455,4.843374,0.702800,-111.558228,0.071303,0.000000
45.950001,21.602074,-111.469261,0.004169,0.002783,0.070679,96.090820,4.895100,0.706789,-111.469261,0.071702,0.000000
46.190002,21.648621,-111.513741,0.004191,0.002792,0.070922,96.297874,4.905648,0.709217,-111.513741,0.072101,0.000000
46.430000,22.007210,-111.469261,0.004191,0.002813,0.071459,97.892960,4.986905,0.714594,-111.469261,0.072500,0.000000
46.670002,22.421661,-111.513741,0.004217,0.002829,0.071867,99.736534,5.080821,0.718670,-111.513741,0.072899,0.000000
46.910004,22.645462,-111.513741,0.004212,0.002845,0.072266,100.732048,5.131535,0.722659,-111.513741,0.073307,0.000000
47.150002,22.936653,-111.558228,0.004238,0.002862,0.072682,102.027328,5.197520,0.726822,-111.558228,0.073706,0.000000
47.390003,23.211464,-111.513741,0.004277,0.002877,0.073072,103.249748,5.259793,0.730724,-111.513741,0.074104,0.000000
47.630001,23.506760,-111.602707,0.004268,0.002894,0.073515,104.563286,5.326708,0.735147,-111.602707,0.074503,0.000000
47.870003,23.631500,-111.558228,0.004307,0.002907,0.073836,105.118164,5.354975,0.738356,-111.558228,0.074902,0.000000
48.110001,23.901474,-111.558228,0.004299,0.002922,0.074209,106.319069,5.416152,0.742085,-111.558228,0.075301,0.000000
48.350002,24.081329,-111.558228,0.004320,0.002938,0.074616,107.119102,5.456907,0.746161,-111.558228,0.075700,0.000000
48.590004,24.117073,-111.513741,0.004329,0.002944,0.074790,107.278099,5.465007,0.747895,-111.513741,0.076099,0.000000
48.830002,25.063644,-111.647186,0.004337,0.002971,0.075475,111.488655,5.679503,0.754747,-111.647186,0.076507,0.000000
49.070004,25.198448,-111.647186,0.004363,0.002987,0.075865,112.088295,5.710050,0.758649,-111.647186,0.076906,0.000000
49.310001,25.343300,-111.647186,0.004376,0.003001,0.076220,112.732628,5.742874,0.762205,-111.647186,0.077304,0.000000
49.550003,25.473259,-111.647186,0.004381,0.003014,0.076567,113.310715,5.772323,0.765674,-111.647186,0.077703,0.000000
49.790001,25.996811,-111.647186,0.004415,0.003033,0.077027,115.639587,5.890962,0.770270,-111.647186,0.078102,0.000000
50.030003,26.336792,-111.691666,0.004419,0.003047,0.077391,117.151901,5.968003,0.773913,-111.691666,0.078501,0.000000
50.270004,26.649208,-111.602707,0.004428,0.003064,0.077825,118.541595,6.038797,0.778248,-111.602707,0.078900,0.000000
50.510002,27.452415,-111.647186,0.004449,0.003088,0.078432,122.114441,6.220807,0.784319,-111.647186,0.079299,0.000000
50.750004,27.617378,-111.647186,0.004475,0.003101,0.078753,122.848236,6.258187,0.787528,-111.647186,0.079707,0.000000
50.990002,27.776009,-111.647186,0.004471,0.003116,0.079152,123.553856,6.294134,0.791517,-111.647186,0.080106,0.000000
51.230003,27.859421,-111.691666,0.004510,0.003129,0.079473,123.924896,6.313035,0.794726,-111.691666,0.080505,0.000000
51.470001,28.580704,-111.647186,0.004531,0.003150,0.080019,127.133316,6.476480,0.800189,-111.647186,0.080903,0.000000
51.710003,28.785881,-111.691666,0.004531,0.003163,0.080348,128.045990,6.522974,0.803485,-111.691666,0.081302,0.000000
51.950001,28.909882,-111.647186,0.004544,0.003174,0.080609,128.597580,6.551073,0.806086,-111.647186,0.081701,0.000000
52.190002,29.395454,-111.736153,0.004536,0.003192,0.081068,130.757507,6.661106,0.810683,-111.736153,0.082100,0.000000
52.430004,30.133125,-111.736153,0.004592,0.003211,0.081563,134.038834,6.828264,0.815626,-111.736153,0.082499,0.000000
52.670002,30.336815,-111.647186,0.004592,0.003226,0.081953,134.944885,6.874420,0.819528,-111.647186,0.082907,0.000000
52.910004,30.658913,-111.736153,0.004605,0.003243,0.082360,136.377655,6.947409,0.823605,-111.736153,0.083306,0.000000
53.150002,30.878616,-111.736153,0.004631,0.003255,0.082681,137.354950,6.997195,0.826813,-111.736153,0.083705,0.000000
53.390003,31.319130,-111.647186,0.004618,0.003274,0.083150,139.314453,7.097016,0.831496,-111.647186,0.084104,0.000000
53.630001,31.789810,-111.825111,0.004648,0.003288,0.083514,141.408142,7.203674,0.835138,-111.825111,0.084503,0.000000
53.870003,31.824440,-111.736153,0.004661,0.003299,0.083783,141.562180,7.211522,0.837827,-111.736153,0.084901,0.000000
54.110004,31.551491,-111.825111,0.004648,0.003302,0.083861,140.348038,7.149670,0.838607,-111.825111,0.085300,0.000000
54.350002,33.139290,-111.780632,0.004682,0.003334,0.084685,147.410919,7.509470,0.846846,-111.780632,0.085699,0.000000
54.590004,33.496391,-111.780632,0.004704,0.003349,0.085066,148.999390,7.590391,0.850662,-111.780632,0.086107,0.000000
54.830002,33.753700,-111.869591,0.004695,0.003363,0.085430,150.143951,7.648698,0.854304,-111.869591,0.086506,0.000000
55.070004,34.539406,-111.780632,0.004712,0.003385,0.085968,153.638947,7.826741,0.859681,-111.780632,0.086905,0.000000
55.310001,34.785545,-111.825111,0.004717,0.003399,0.086332,154.733841,7.882517,0.863323,-111.825111,0.087304,0.000000
55.550003,35.319160,-111.825111,0.004751,0.003416,0.086775,157.107468,8.003436,0.867746,-111.825111,0.087703,0.000000
55.790001,35.329582,-111.780632,0.004764,0.003426,0.087017,157.153824,8.005797,0.870174,-111.780632,0.088101,0.000000
56.030003,35.800262,-111.780632,0.004790,0.003441,0.087399,159.247528,8.112455,0.873990,-111.780632,0.088500,0.000000
56.270004,36.493996,-111.825111,0.004790,0.003460,0.087893,162.333405,8.269657,0.878933,-111.825111,0.088908,0.000000
56.510002,36.480217,-111.869591,0.004790,0.003467,0.088058,162.272110,8.266536,0.880581,-111.869591,0.089307,0.000000
56.750004,37.186974,-111.914070,0.004833,0.003488,0.088587,165.415924,8.426689,0.885871,-111.914070,0.089706,0.000000
56.990002,37.816284,-111.825111,0.004846,0.003504,0.088995,168.215240,8.569292,0.889947,-111.825111,0.090105,0.000000
57.230003,37.906403,-111.958557,0.004855,0.003518,0.089350,168.616104,8.589713,0.893503,-111.958557,0.090504,0.000000
57.470001,38.765839,-111.869591,0.004868,0.003535,0.089784,172.439056,8.784464,0.897839,-111.869591,0.090903,0.000000
57.710003,39.280457,-111.914070,0.004872,0.003549,0.090148,174.728195,8.901078,0.901482,-111.914070,0.091302,0.000000
57.950005,39.836777,-111.914070,0.004876,0.003566,0.090573,177.202835,9.027143,0.905730,-111.914070,0.091700,0.000000
58.190002,40.612801,-111.869591,0.004885,0.003585,0.091050,180.654755,9.202991,0.910500,-111.869591,0.092108,0.000000
58.430004,40.890968,-111.914070,0.004919,0.003598,0.091388,181.892105,9.266026,0.913883,-111.914070,0.092507,0.000000
58.670002,41.512085,-111.869591,0.004928,0.003615,0.091813,184.654984,9.406774,0.918132,-111.869591,0.092906,0.000000
58.910004,42.134689,-111.958557,0.004924,0.003632,0.092255,187.424454,9.547857,0.922555,-111.958557,0.093305,0.000000
59.150002,42.518234,-111.914070,0.004967,0.003648,0.092654,189.130554,9.634769,0.926544,-111.914070,0.093704,0.000000
59.390003,43.044395,-111.914070,0.004967,0.003662,0.093027,191.471039,9.754000,0.930273,-111.914070,0.094103,0.000000
59.630001,43.725464,-111.914070,0.004975,0.003679,0.093444,194.500580,9.908332,0.934436,-111.914070,0.094502,0.000000
59.870003,43.960434,-111.914070,0.004993,0.003693,0.093790,195.545776,9.961576,0.937905,-111.914070,0.094900,0.000000
60.110004,44.755447,-112.003036,0.004997,0.003710,0.094233,199.082169,10.141729,0.942327,-112.003036,0.095308,0.000000
60.350002,45.363533,-112.003036,0.005010,0.003725,0.094623,201.787079,10.279524,0.946230,-112.003036,0.095707,0.000000
60.590004,45.922089,-112.003036,0.005001,0.003740,0.095005,204.271652,10.406094,0.950046,-112.003036,0.096106,0.000000
60.830002,46.335793,-112.047516,0.005053,0.003755,0.095377,206.111893,10.499841,0.953775,-112.047516,0.096505,0.000000
61.070004,46.584167,-111.958557,0.005049,0.003765,0.095629,207.216721,10.556123,0.956290,-111.958557,0.096904,0.000000
61.310001,48.081482,-112.047516,0.005049,0.003790,0.096271,213.877121,10.895419,0.962707,-112.047516,0.097303,0.000000
61.550003,48.659401,-112.003036,0.005079,0.003808,0.096713,216.447830,11.026379,0.967131,-112.003036,0.097702,0.000000
61.790005,48.555138,-112.047516,0.005092,0.003813,0.096860,215.984039,11.002751,0.968605,-112.047516,0.098101,0.000000
62.030003,49.616028,-112.091995,0.005113,0.003835,0.097398,220.703110,11.243153,0.973981,-112.091995,0.098508,0.000000
62.270004,50.640053,-112.047516,0.005122,0.003854,0.097901,225.258209,11.475200,0.979011,-112.047516,0.098907,0.000000
62.510002,51.086151,-112.047516,0.005126,0.003869,0.098283,227.242554,11.576288,0.982827,-112.047516,0.099306,0.000000
62.750004,51.635773,-112.047516,0.005131,0.003883,0.098630,229.687393,11.700833,0.986295,-112.047516,0.099705,0.000000
62.990002,51.825684,-112.047516,0.005139,0.003893,0.098872,230.532150,11.743868,0.988724,-112.047516,0.100104,0.000000
63.230003,52.491112,-112.091995,0.005152,0.003913,0.099393,233.492126,11.894656,0.993928,-112.091995,0.100503,0.000000
63.470001,53.749359,-112.003036,0.005191,0.003930,0.099826,239.089096,12.179779,0.998263,-112.003036,0.100902,0.000000
63.710003,53.616798,-112.091995,0.005178,0.003937,0.100000,238.499435,12.149740,0.999998,-112.091995,0.101301,0.000000
63.950005,54.439369,-112.091995,0.005213,0.003951,0.100347,242.158401,12.336137,1.003466,-112.091995,0.101708,0.000000
64.190002,53.898682,-112.091995,0.005195,0.003952,0.100373,239.753311,12.213615,1.003727,-112.091995,0.102107,0.000000
64.430000,56.654236,-112.136475,0.005213,0.003992,0.101387,252.010620,12.838034,1.013874,-112.136475,0.102506,0.000000
64.670006,57.133484,-112.091995,0.005238,0.004005,0.101726,254.142426,12.946632,1.017256,-112.091995,0.102905,0.000000
64.910004,57.735977,-112.136475,0.005247,0.004018,0.102055,256.822449,13.083159,1.020552,-112.136475,0.103304,0.000000
65.150002,58.252090,-112.225441,0.005251,0.004031,0.102393,259.118225,13.200112,1.023933,-112.225441,0.103703,0.000000
65.389999,59.458199,-112.136475,0.005273,0.004051,0.102888,264.483276,13.473420,1.028876,-112.136475,0.104102,0.000000
65.630005,59.917336,-112.180962,0.005282,0.004066,0.103269,266.525635,13.577462,1.032693,-112.180962,0.104501,0.000000
65.870003,60.829651,-112.136475,0.005299,0.004079,0.103616,270.583801,13.784196,1.036161,-112.136475,0.104908,0.000000
66.110001,62.510170,-112.180962,0.005299,0.004105,0.104267,278.059113,14.165007,1.042666,-112.180962,0.105307,0.000000
66.350006,63.367371,-112.180962,0.005303,0.004121,0.104665,281.872131,14.359251,1.046655,-112.180962,0.105706,0.000000
66.590004,63.852570,-112.180962,0.005329,0.004135,0.105038,284.030426,14.469199,1.050384,-112.180962,0.106105,0.000000
66.830002,64.624496,-112.269920,0.005329,0.004149,0.105394,287.464111,14.644120,1.053939,-112.269920,0.106504,0.000000
67.070000,65.578140,-112.225441,0.005338,0.004165,0.105802,291.706146,14.860219,1.058015,-112.225441,0.106903,0.000000
67.310005,66.264801,-112.180962,0.005364,0.004181,0.106200,294.760559,15.015819,1.062005,-112.180962,0.107302,0.000000
67.550003,66.797287,-112.225441,0.005359,0.004191,0.106443,297.129181,15.136481,1.064433,-112.225441,0.107701,0.000000
67.790001,67.751678,-112.269920,0.005407,0.004200,0.106686,301.374512,15.352750,1.066861,-112.269920,0.108065,0.000000
68.030006,67.043427,-112.314400,0.005376,0.004198,0.106634,298.224060,15.192258,1.066341,-112.314400,0.106912,0.000000
68.270004,66.462158,-112.269920,0.005407,0.004195,0.106565,295.638458,15.060540,1.065647,-112.269920,0.106634,0.000000
68.510002,66.007111,-112.225441,0.005376,0.004194,0.106530,293.614288,14.957425,1.065300,-112.225441,0.106634,0.000000
68.750000,65.627670,-112.269920,0.005398,0.004193,0.106513,291.926453,14.871443,1.065126,-112.269920,0.106634,0.000000
68.990005,65.297745,-112.269920,0.005398,0.004193,0.106513,290.458862,14.796680,1.065126,-112.269920,0.106634,0.000000
69.230003,65.002457,-112.314400,0.005407,0.004193,0.106504,289.145355,14.729767,1.065040,-112.314400,0.106634,0.000000
69.470001,64.739563,-112.269920,0.005411,0.004193,0.106495,287.975952,14.670195,1.064953,-112.269920,0.106634,0.000000
69.710007,64.522461,-112.269920,0.005385,0.004193,0.106495,287.010254,14.620998,1.064953,-112.269920,0.106634,0.000000
69.950005,64.307236,-112.314400,0.005407,0.004193,0.106495,286.052856,14.572228,1.064953,-112.314400,0.106634,0.000000
70.190002,64.129608,-112.225441,0.005415,0.004192,0.106487,285.262756,14.531977,1.064866,-112.225441,0.106634,0.000000
70.430000,63.952744,-112.358879,0.005402,0.004192,0.106487,284.476013,14.491899,1.064866,-112.358879,0.106634,0.000000
70.670006,63.791122,-112.269920,0.005415,0.004192,0.106487,283.757080,14.455275,1.064866,-112.269920,0.106634,0.000000
70.910004,63.642548,-112.314400,0.005420,0.004192,0.106487,283.096191,14.421608,1.064866,-112.314400,0.106634,0.000000
71.150002,63.499191,-112.358879,0.005437,0.004192,0.106487,282.458496,14.389122,1.064866,-112.358879,0.106634,0.000000
71.390007,63.365875,-112.314400,0.005398,0.004192,0.106487,281.865479,14.358912,1.064866,-112.314400,0.106634,0.000000
71.630005,63.250076,-112.358879,0.005420,0.004192,0.106478,281.350403,14.332672,1.064780,-112.358879,0.106634,0.000000
71.870003,63.142822,-112.403366,0.005428,0.004192,0.106478,280.873291,14.308368,1.064780,-112.403366,0.106634,0.000000
72.110001,63.038193,-112.314400,0.005411,0.004192,0.106478,280.407898,14.284658,1.064780,-112.314400,0.106634,0.000000
72.350006,62.936157,-112.447845,0.005433,0.004192,0.106478,279.954010,14.261537,1.064780,-112.447845,0.106634,0.000000
72.590004,62.839340,-112.358879,0.005407,0.004192,0.106478,279.523346,14.239598,1.064780,-112.358879,0.106634,0.000000
72.830002,62.751839,-112.403366,0.005411,0.004192,0.106478,279.134125,14.219769,1.064780,-112.403366,0.106634,0.000000
73.070000,62.660980,-112.358879,0.005402,0.004192,0.106478,278.729950,14.199181,1.064780,-112.358879,0.106634,0.000000
73.310005,62.570862,-112.403366,0.005407,0.004192,0.106478,278.329102,14.178760,1.064780,-112.403366,0.106634,0.000000
73.550003,62.501602,-112.447845,0.005420,0.004192,0.106469,278.021027,14.163065,1.064693,-112.447845,0.106634,0.000000
73.790001,62.414093,-112.358879,0.005411,0.004192,0.106469,277.631744,14.143235,1.064693,-112.358879,0.106634,0.000000
74.030006,62.348557,-112.447845,0.005428,0.004192,0.106469,277.340240,14.128385,1.064693,-112.447845,0.106634,0.000000
74.270004,62.281158,-112.492325,0.005420,0.004192,0.106469,277.040436,14.113112,1.064693,-112.492325,0.106634,0.000000
74.510002,62.205940,-112.447845,0.005428,0.004192,0.106469,276.705841,14.096067,1.064693,-112.447845,0.106634,0.000000
74.750000,62.145988,-112.536804,0.005424,0.004192,0.106469,276.439148,14.082482,1.064693,-112.536804,0.106634,0.000000
74.990005,62.090874,-112.403366,0.005420,0.004192,0.106469,276.194000,14.069993,1.064693,-112.403366,0.106634,0.000000
75.230003,62.028687,-112.492325,0.005424,0.004192,0.106469,275.917389,14.055901,1.064693,-112.492325,0.106634,0.000000
75.470001,61.965385,-112.492325,0.005433,0.004192,0.106469,275.635803,14.041557,1.064693,-112.492325,0.106634,0.000000
75.710007,61.924423,-112.447845,0.005433,0.004192,0.106469,275.453583,14.032275,1.064693,-112.447845,0.106634,0.000000
75.950005,61.852180,-112.536804,0.005424,0.004192,0.106469,275.132233,14.015904,1.064693,-112.536804,0.106634,0.000000
76.190002,61.810852,-112.536804,0.005415,0.004192,0.106469,274.948395,14.006539,1.064693,-112.536804,0.106634,0.000000
76.430000,61.747551,-112.536804,0.005428,0.004192,0.106469,274.666840,13.992195,1.064693,-112.536804,0.106634,0.000000
76.670006,61.703606,-112.536804,0.005433,0.004192,0.106469,274.471344,13.982237,1.064693,-112.536804,0.106634,0.000000
76.910004,61.644775,-112.536804,0.005428,0.004192,0.106469,274.209656,13.968906,1.064693,-112.536804,0.106634,0.000000
77.150002,61.597481,-112.581284,0.005420,0.004192,0.106469,273.999268,13.958189,1.064693,-112.581284,0.106634,0.000000
77.390007,61.554283,-112.492325,0.005437,0.004192,0.106469,273.807129,13.948400,1.064693,-112.492325,0.106634,0.000000
77.630005,61.516678,-112.536804,0.005433,0.004192,0.106469,273.639862,13.939878,1.064693,-112.536804,0.106634,0.000000
77.870003,61.483162,-112.625771,0.005437,0.004191,0.106461,273.490753,13.932283,1.064607,-112.625771,0.106634,0.000000
78.110001,61.429169,-112.492325,0.005411,0.004191,0.106461,273.250580,13.920049,1.064607,-112.492325,0.106634,0.000000
78.350006,61.392677,-112.625771,0.005420,0.004191,0.106461,273.088257,13.911779,1.064607,-112.625771,0.106634,0.000000
78.590004,61.343147,-112.536804,0.005433,0.004191,0.106461,272.867950,13.900556,1.064607,-112.536804,0.106634,0.000000
78.830002,61.303680,-112.581284,0.005433,0.004191,0.106461,272.692383,13.891612,1.064607,-112.581284,0.106634,0.000000
79.070007,61.270912,-112.625771,0.005437,0.004191,0.106461,272.546631,13.884187,1.064607,-112.625771,0.106634,0.000000
79.310005,61.231812,-112.625771,0.005420,0.004191,0.106461,272.372711,13.875327,1.064607,-112.625771,0.106634,0.000000
79.550003,61.178192,-112.625771,0.005437,0.004191,0.106461,272.134186,13.863176,1.064607,-112.625771,0.106634,0.000000
79.790001,61.149147,-112.625771,0.005445,0.004191,0.106461,272.005005,13.856595,1.064607,-112.625771,0.106634,0.000000
80.030006,61.128296,-112.581284,0.005433,0.004191,0.106461,271.912231,13.851870,1.064607,-112.581284,0.106634,0.000000
80.270004,61.073181,-112.625771,0.005433,0.004191,0.106461,271.667084,13.839380,1.064607,-112.625771,0.106634,0.000000
80.510002,61.043762,-112.581284,0.005428,0.004191,0.106461,271.536224,13.832714,1.064607,-112.581284,0.106634,0.000000
80.750008,60.996841,-112.670250,0.005433,0.004191,0.106461,271.327515,13.822082,1.064607,-112.670250,0.106634,0.000000
80.990005,60.983437,-112.625771,0.005454,0.004191,0.106461,271.267883,13.819044,1.064607,-112.625771,0.106634,0.000000
81.230003,60.932800,-112.714729,0.005441,0.004191,0.106461,271.042633,13.807570,1.064607,-112.714729,0.106634,0.000000
81.470001,60.913437,-112.625771,0.005441,0.004191,0.106461,270.956512,13.803183,1.064607,-112.625771,0.106634,0.000000
81.710007,60.870239,-112.670250,0.005415,0.004191,0.106461,270.764343,13.793393,1.064607,-112.670250,0.106634,0.000000
81.950005,60.852364,-112.759209,0.005437,0.004191,0.106461,270.684845,13.789342,1.064607,-112.759209,0.106634,0.000000
82.190002,60.821831,-112.625771,0.005445,0.004191,0.106461,270.549011,13.782424,1.064607,-112.625771,0.106634,0.000000
82.430000,60.790176,-112.714729,0.005437,0.004191,0.106461,270.408203,13.775250,1.064607,-112.714729,0.106634,0.000000
82.670006,60.770073,-112.759209,0.005433,0.004191,0.106461,270.318787,13.770695,1.064607,-112.759209,0.106634,0.000000
82.910004,60.744003,-112.714729,0.005445,0.004191,0.106461,270.202820,13.764788,1.064607,-112.714729,0.106634,0.000000
83.150002,60.706390,-112.759209,0.005437,0.004191,0.106461,270.035522,13.756265,1.064607,-112.759209,0.106634,0.000000
83.390007,60.691124,-112.759209,0.005441,0.004191,0.106461,269.967590,13.752806,1.064607,-112.759209,0.106634,0.000000
83.630005,60.654259,-112.714729,0.005441,0.004191,0.106461,269.803619,13.744452,1.064607,-112.714729,0.106634,0.000000
83.870003,60.636757,-112.759209,0.005420,0.004191,0.106461,269.725769,13.740485,1.064607,-112.759209,0.106634,0.000000
84.110001,60.592445,-112.670250,0.005450,0.004191,0.106461,269.528656,13.730444,1.064607,-112.670250,0.106634,0.000000
84.350006,60.587608,-112.759209,0.005433,0.004191,0.106461,269.507141,13.729348,1.064607,-112.759209,0.106634,0.000000
84.590004,60.550743,-112.714729,0.005450,0.004191,0.106461,269.343170,13.720995,1.064607,-112.714729,0.106634,0.000000
84.830002,60.516487,-112.759209,0.005428,0.004191,0.106461,269.190765,13.713231,1.064607,-112.759209,0.106634,0.000000
85.070007,60.503448,-112.848175,0.005450,0.004191,0.106461,269.132782,13.710278,1.064607,-112.848175,0.106634,0.000000
85.310005,60.474037,-112.759209,0.005437,0.004191,0.106461,269.001953,13.703613,1.064607,-112.759209,0.106634,0.000000
85.550003,60.452812,-112.803696,0.005428,0.004191,0.106461,268.907532,13.698803,1.064607,-112.803696,0.106634,0.000000
85.790001,60.424507,-112.759209,0.005441,0.004191,0.106461,268.781647,13.692389,1.064607,-112.759209,0.106634,0.000000
86.030006,60.422646,-112.803696,0.005428,0.004191,0.106461,268.773346,13.691967,1.064607,-112.803696,0.106634,0.000000
86.270004,60.398445,-112.848175,0.005437,0.004191,0.106461,268.665710,13.686483,1.064607,-112.848175,0.106634,0.000000
86.510002,60.370888,-112.848175,0.005445,0.004191,0.106461,268.543121,13.680239,1.064607,-112.848175,0.106634,0.000000
86.750008,60.351151,-112.892654,0.005445,0.004191,0.106461,268.455322,13.675766,1.064607,-112.892654,0.106634,0.000000
86.990005,60.329926,-112.848175,0.005450,0.004191,0.106461,268.360901,13.670957,1.064607,-112.848175,0.106634,0.000000
87.230003,60.311676,-112.892654,0.005428,0.004191,0.106461,268.279724,13.666821,1.064607,-112.892654,0.106634,0.000000
87.470001,60.263641,-112.892654,0.005445,0.004191,0.106461,268.066071,13.655936,1.064607,-112.892654,0.106634,0.000000
87.710007,60.264763,-112.848175,0.005441,0.004191,0.106461,268.071045,13.656190,1.064607,-112.848175,0.106634,0.000000
87.950005,60.231995,-112.848175,0.005445,0.004191,0.106461,267.925293,13.648765,1.064607,-112.848175,0.106634,0.000000
88.190002,60.214859,-112.892654,0.005445,0.004191,0.106461,267.849060,13.644882,1.064607,-112.892654,0.106634,0.000000
88.430008,60.201454,-112.848175,0.005441,0.004191,0.106461,267.789429,13.641845,1.064607,-112.848175,0.106634,0.000000
88.670006,60.174644,-112.937134,0.005445,0.004191,0.106461,267.670197,13.635769,1.064607,-112.937134,0.106634,0.000000
88.910004,60.160126,-112.892654,0.005445,0.004191,0.106461,267.605591,13.632479,1.064607,-112.892654,0.106634,0.000000
89.150002,60.139641,-112.981613,0.005437,0.004191,0.106461,267.514496,13.627837,1.064607,-112.981613,0.106634,0.000000
89.390007,60.136665,-112.937134,0.005450,0.004191,0.106461,267.501251,13.627163,1.064607,-112.937134,0.106634,0.000000
89.630005,60.107620,-112.892654,0.005445,0.004191,0.106461,267.372040,13.620582,1.064607,-112.892654,0.106634,0.000000
89.870003,60.091232,-112.937134,0.005437,0.004191,0.106461,267.299164,13.616868,1.064607,-112.937134,0.106634,0.000000
90.110001,60.072243,-112.892654,0.005437,0.004191,0.106461,267.214691,13.612565,1.064607,-112.892654,0.106634,0.000000
90.350006,60.048042,-112.981613,0.005437,0.004191,0.106461,267.107025,13.607080,1.064607,-112.981613,0.106634,0.000000
90.590004,60.039474,-112.937134,0.005450,0.004191,0.106461,267.068909,13.605140,1.064607,-112.937134,0.106634,0.000000
90.830002,60.019363,-112.937134,0.005441,0.004191,0.106461,266.979462,13.600582,1.064607,-112.937134,0.106634,0.000000
91.070007,60.002609,-113.070580,0.005454,0.004191,0.106461,266.904938,13.596786,1.064607,-113.070580,0.106634,0.000000
91.310005,59.993301,-112.981613,0.005437,0.004191,0.106461,266.863525,13.594677,1.064607,-112.981613,0.106634,0.000000
91.550003,59.963142,-113.026100,0.005441,0.004191,0.106461,266.729370,13.587842,1.064607,-113.026100,0.106634,0.000000
91.790001,59.955688,-112.981613,0.005437,0.004191,0.106461,266.696228,13.586153,1.064607,-112.981613,0.106634,0.000000
92.030006,59.941910,-112.937134,0.005445,0.004191,0.106461,266.634918,13.583031,1.064607,-112.937134,0.106634,0.000000
92.270004,59.918083,-113.070580,0.005437,0.004191,0.106461,266.528931,13.577632,1.064607,-113.070580,0.106634,0.000000
92.510002,59.902443,-113.026100,0.005445,0.004191,0.106461,266.459381,13.574088,1.064607,-113.026100,0.106634,0.000000
92.750008,59.864456,-112.981613,0.005437,0.004191,0.106461,266.290405,13.565479,1.064607,-112.981613,0.106634,0.000000
92.990005,59.871536,-113.070580,0.005433,0.004191,0.106461,266.321899,13.567083,1.064607,-113.070580,0.106634,0.000000
93.230003,59.856644,-113.026100,0.005445,0.004191,0.106461,266.255646,13.563709,1.064607,-113.026100,0.106634,0.000000
93.470001,59.828712,-113.070580,0.005433,0.004191,0.106461,266.131409,13.557380,1.064607,-113.070580,0.106634,0.000000
93.710007,59.817543,-113.070580,0.005458,0.004191,0.106461,266.081726,13.554849,1.064607,-113.070580,0.106634,0.000000
93.950005,59.807114,-113.070580,0.005463,0.004191,0.106461,266.035339,13.552485,1.064607,-113.070580,0.106634,0.000000
94.190002,59.797432,-113.070580,0.005454,0.004191,0.106461,265.992249,13.550291,1.064607,-113.070580,0.106634,0.000000
94.430008,59.768387,-113.070580,0.005454,0.004191,0.106461,265.863068,13.543711,1.064607,-113.070580,0.106634,0.000000
94.670006,59.764664,-113.115059,0.005458,0.004191,0.106461,265.846497,13.542866,1.064607,-113.115059,0.106634,0.000000
94.910004,59.753120,-113.115059,0.005437,0.004191,0.106461,265.795166,13.540251,1.064607,-113.115059,0.106634,0.000000
95.150002,59.719978,-113.070580,0.005445,0.004191,0.106461,265.647736,13.532740,1.064607,-113.070580,0.106634,0.000000
95.390007,59.724823,-113.159538,0.005450,0.004191,0.106461,265.669281,13.533838,1.064607,-113.159538,0.106634,0.000000
95.630005,59.700241,-113.115059,0.005450,0.004191,0.106461,265.559937,13.528268,1.064607,-113.115059,0.106634,0.000000
95.870003,59.703964,-113.159538,0.005445,0.004191,0.106461,265.576508,13.529112,1.064607,-113.159538,0.106634,0.000000
96.110008,59.680878,-113.159538,0.005467,0.004191,0.106461,265.473816,13.523881,1.064607,-113.159538,0.106634,0.000000
96.350006,59.661888,-113.159538,0.005450,0.004191,0.106461,265.389343,13.519577,1.064607,-113.159538,0.106634,0.000000
96.590004,59.653328,-113.159538,0.005450,0.004191,0.106461,265.351257,13.517637,1.064607,-113.159538,0.106634,0.000000
96.830002,59.642151,-113.159538,0.005437,0.004191,0.106461,265.301544,13.515104,1.064607,-113.159538,0.106634,0.000000
97.070007,59.633217,-113.248505,0.005454,0.004191,0.106461,265.261810,13.513080,1.064607,-113.248505,0.106634,0.000000
97.310005,59.610878,-113.159538,0.005437,0.004191,0.106461,265.162415,13.508018,1.064607,-113.159538,0.106634,0.000000
97.550003,59.612366,-113.159538,0.005437,0.004191,0.106461,265.169037,13.508355,1.064607,-113.159538,0.106634,0.000000
97.790001,59.583321,-113.204018,0.005463,0.004191,0.106461,265.039856,13.501774,1.064607,-113.204018,0.106634,0.000000
98.030006,59.578476,-113.159538,0.005441,0.004191,0.106461,265.018311,13.500676,1.064607,-113.159538,0.106634,0.000000
98.270004,59.561348,-113.248505,0.005445,0.004191,0.106461,264.942108,13.496794,1.064607,-113.248505,0.106634,0.000000
98.300003,59.553902,-113.204018,0.005454,0.004191,0.106461,264.908997,13.495108,1.064607,-113.204018,0.106634,0.000000