File: Data/Symmetrical membranes compression/Sartorius Cellulose Nitrate 045um test 3_10302023_171835.csv
Time (sec),S:Load (lbs),S:HL1 (DIM),S:LVDT (in),S:Position (in),Ch:Position (mm),Ch:Load (N),Ch:Stress (MPa),Ch:Strain (mm/mm),Ch:HL1 (DIM),Set Point (),Cycles ()
0.110000,0.004471,-102.617554,0.000017,-0.000000,-0.000000,0.019887,0.001013,-0.000000,-102.617554,0.000295,0.000000
0.350000,-0.004837,-102.706512,-0.000004,-0.000000,-0.000000,-0.021516,-0.001096,-0.000000,-102.706512,0.000416,0.000000
0.590000,0.035004,-102.617554,0.000026,0.000126,0.003209,0.155704,0.007932,0.032087,-102.617554,0.004406,0.000000
0.830000,0.014900,-102.662033,0.000172,0.000280,0.007111,0.066279,0.003376,0.071112,-102.662033,0.008412,0.000000
1.070000,-0.021965,-102.617554,0.000315,0.000437,0.011109,-0.097705,-0.004977,0.111091,-102.617554,0.012401,0.000000
1.310000,-0.013405,-102.662033,0.000466,0.000595,0.015116,-0.059628,-0.003038,0.151157,-102.662033,0.016408,0.000000
1.550000,0.036865,-102.706512,0.000629,0.000746,0.018940,0.163985,0.008354,0.189403,-102.706512,0.020397,0.000000
1.790000,0.044319,-102.662033,0.000806,0.000904,0.022955,0.197141,0.010043,0.229555,-102.662033,0.024404,0.000000
2.030000,0.026070,-102.662033,0.000979,0.001070,0.027179,0.115964,0.005907,0.271789,-102.662033,0.028393,0.000000
2.270000,0.031281,-102.750999,0.001138,0.001222,0.031047,0.139143,0.007088,0.310467,-102.750999,0.032400,0.000000
2.510000,0.035004,-102.662033,0.001315,0.001379,0.035027,0.155704,0.007932,0.350273,-102.662033,0.036389,0.000000
2.750000,0.037239,-102.706512,0.001470,0.001539,0.039086,0.165648,0.008438,0.390859,-102.706512,0.040395,0.000000
2.990000,0.023834,-102.750999,0.001647,0.001701,0.043197,0.106020,0.005401,0.431965,-102.750999,0.044385,0.000000
3.230000,-0.017502,-102.706512,0.001802,0.001852,0.047047,-0.077852,-0.003966,0.470470,-102.706512,0.048391,0.000000
3.470000,0.032768,-102.750999,0.001957,0.002013,0.051123,0.145760,0.007425,0.511230,-102.750999,0.052380,0.000000
3.710000,0.050270,-102.750999,0.002130,0.002166,0.055017,0.223612,0.011391,0.550169,-102.750999,0.056387,0.000000
3.950000,0.037987,-102.750999,0.002302,0.002332,0.059223,0.168974,0.008608,0.592228,-102.750999,0.060394,0.000000
4.190000,0.029045,-102.795479,0.002471,0.002487,0.063169,0.129199,0.006582,0.631688,-102.795479,0.064383,0.000000
4.430000,0.048409,-102.795479,0.002634,0.002646,0.067201,0.215332,0.010970,0.672014,-102.795479,0.068389,0.000000
4.670000,0.049530,-102.839958,0.002790,0.002796,0.071026,0.220321,0.011224,0.710258,-102.839958,0.072379,0.000000
4.910000,0.025322,-102.795479,0.002940,0.002959,0.075154,0.112638,0.005738,0.751538,-102.795479,0.076385,0.000000
5.150000,-0.001114,-102.750999,0.003134,0.003118,0.079204,-0.004955,-0.000252,0.792038,-102.750999,0.080375,0.000000
5.390000,0.023087,-102.839958,0.003290,0.003268,0.083019,0.102694,0.005231,0.830195,-102.839958,0.084381,0.000000
5.630000,0.059212,-102.750999,0.003462,0.003429,0.087087,0.263387,0.013418,0.870868,-102.750999,0.088370,0.000000
5.870000,0.041710,-102.884438,0.003630,0.003586,0.091093,0.185535,0.009452,0.910934,-102.884438,0.092377,0.000000
6.110000,0.023834,-102.839958,0.003794,0.003748,0.095195,0.106020,0.005401,0.951954,-102.839958,0.096366,0.000000
6.350000,0.035378,-102.839958,0.003941,0.003904,0.099150,0.157367,0.008017,0.991500,-102.839958,0.100373,0.000000
6.590000,0.058838,-102.839958,0.004139,0.004059,0.103096,0.261724,0.013333,1.030958,-102.839958,0.104362,0.000000
6.830000,0.036499,-102.795479,0.004281,0.004216,0.107076,0.162356,0.008271,1.070764,-102.795479,0.108369,0.000000
7.070000,0.026443,-102.839958,0.004437,0.004374,0.111092,0.117626,0.005992,1.110916,-102.839958,0.112358,0.000000
7.310000,0.027931,-102.884438,0.004613,0.004528,0.115020,0.124244,0.006329,1.150202,-102.884438,0.116364,0.000000
7.550000,0.099052,-102.839958,0.004769,0.004686,0.119027,0.440607,0.022446,1.190267,-102.839958,0.120354,0.000000
7.790000,0.227524,-102.928925,0.004928,0.004846,0.123094,1.012076,0.051558,1.230941,-102.928925,0.124360,0.000000
8.030001,0.468445,-102.839958,0.005101,0.005005,0.127118,2.083747,0.106151,1.271180,-102.839958,0.128349,0.000000
8.270000,0.602127,-102.928925,0.005204,-0.000005,-0.000139,2.678395,0.136444,-0.001387,-102.928925,0.000095,0.000000
8.510000,0.580902,-102.884438,0.005230,-0.000005,-0.000139,2.583982,0.131634,-0.001387,-102.884438,0.000095,0.000000
8.750000,0.597664,-102.884438,0.005204,-0.000005,-0.000139,2.658542,0.135433,-0.001387,-102.884438,0.000165,0.000000
8.990001,0.664314,-102.928925,0.005213,-0.000005,-0.000130,2.955018,0.150536,-0.001301,-102.928925,0.000572,0.000000
9.230000,0.641975,-102.928925,0.005226,-0.000000,-0.000009,2.855649,0.145474,-0.000086,-102.928925,0.000971,0.000000
9.470000,0.704163,-102.973404,0.005221,0.000019,0.000494,3.132272,0.159566,0.004943,-102.973404,0.001370,0.000000
9.710000,0.757034,-102.928925,0.005243,0.000034,0.000859,3.367457,0.171546,0.008586,-102.928925,0.001769,0.000000
9.950001,0.751076,-102.928925,0.005243,0.000047,0.001197,3.340952,0.170196,0.011968,-102.928925,0.002168,0.000000
10.190001,0.827789,-102.973404,0.005260,0.000063,0.001596,3.682191,0.187580,0.015957,-102.973404,0.002567,0.000000
10.430000,0.904121,-103.017883,0.005290,0.000079,0.001995,4.021733,0.204877,0.019946,-103.017883,0.002966,0.000000
10.670000,0.946571,-103.062363,0.005299,0.000094,0.002376,4.210560,0.214496,0.023763,-103.062363,0.003365,0.000000
10.910001,0.988281,-102.973404,0.005316,0.000102,0.002584,4.396094,0.223948,0.025843,-102.973404,0.003772,0.000000
11.150001,1.085098,-102.973404,0.005312,0.000124,0.003139,4.826758,0.245887,0.031394,-102.973404,0.004171,0.000000
11.390000,1.174469,-103.017883,0.005338,0.000142,0.003608,5.224299,0.266138,0.036077,-103.017883,0.004570,0.000000
11.630000,1.216171,-103.062363,0.005385,0.000155,0.003946,5.409800,0.275588,0.039459,-103.062363,0.004969,0.000000
11.870001,1.272774,-103.017883,0.005372,0.000173,0.004397,5.661581,0.288415,0.043968,-103.017883,0.005368,0.000000
12.110001,1.326019,-103.106842,0.005389,0.000185,0.004709,5.898428,0.300480,0.047091,-103.106842,0.005767,0.000000
12.350000,1.425819,-103.062363,0.005402,0.000202,0.005125,6.342361,0.323095,0.051253,-103.062363,0.006166,0.000000
12.590000,1.509232,-103.017883,0.005441,0.000219,0.005559,6.713398,0.341997,0.055590,-103.017883,0.006565,0.000000
12.830001,1.560989,-103.062363,0.005433,0.000226,0.005741,6.943627,0.353725,0.057410,-103.062363,0.006973,0.000000
13.070001,1.659668,-103.106842,0.005471,0.000242,0.006157,7.382572,0.376086,0.061574,-103.106842,0.007371,0.000000
13.310000,1.707329,-103.106842,0.005467,0.000254,0.006461,7.594578,0.386886,0.064608,-103.106842,0.007770,0.000000
13.550000,1.854416,-103.106842,0.005467,0.000277,0.007042,8.248854,0.420217,0.070419,-103.106842,0.008169,0.000000
13.790001,1.924049,-103.106842,0.005506,0.000295,0.007502,8.558599,0.435996,0.075016,-103.106842,0.008568,0.000000
14.030001,2.017143,-103.062363,0.005527,0.000313,0.007952,8.972701,0.457091,0.079524,-103.062363,0.008967,0.000000
14.270000,2.139656,-103.106842,0.005532,0.000330,0.008386,9.517666,0.484853,0.083861,-103.106842,0.009366,0.000000
14.510000,2.241684,-103.151329,0.005536,0.000346,0.008785,9.971508,0.507973,0.087850,-103.151329,0.009765,0.000000
14.750001,2.278175,-103.106842,0.005553,0.000356,0.009037,10.133830,0.516242,0.090365,-103.106842,0.010173,0.000000
14.990001,2.369408,-103.151329,0.005575,0.000372,0.009461,10.539652,0.536915,0.094615,-103.151329,0.010571,0.000000
15.230000,2.478889,-103.151329,0.005596,0.000390,0.009912,11.026651,0.561724,0.099125,-103.151329,0.010970,0.000000
15.470000,2.554108,-103.151329,0.005622,0.000406,0.010303,11.361238,0.578769,0.103027,-103.151329,0.011369,0.000000
15.710001,2.659119,-103.151329,0.005631,0.000426,0.010814,11.828350,0.602565,0.108143,-103.151329,0.011768,0.000000
15.950001,2.678848,-103.151329,0.005631,0.000432,0.010979,11.916112,0.607036,0.109791,-103.151329,0.012167,0.000000
16.190001,2.796150,-103.240288,0.005665,0.000451,0.011447,12.437898,0.633617,0.114474,-103.240288,0.012566,0.000000
16.430000,2.898178,-103.106842,0.005678,0.000467,0.011864,12.891740,0.656737,0.118637,-103.106842,0.012965,0.000000
16.670000,2.950310,-103.195808,0.005683,0.000477,0.012124,13.123633,0.668550,0.121239,-103.195808,0.013373,0.000000
16.910002,3.087341,-103.195808,0.005713,0.000497,0.012635,13.733180,0.699602,0.126355,-103.195808,0.013772,0.000000
17.150002,3.174477,-103.195808,0.005721,0.000514,0.013052,14.120777,0.719347,0.130517,-103.195808,0.014170,0.000000
17.390001,3.289169,-103.240288,0.005747,0.000534,0.013572,14.630956,0.745336,0.135721,-103.240288,0.014569,0.000000
17.630001,3.327522,-103.240288,0.005752,0.000549,0.013954,14.801558,0.754027,0.139537,-103.240288,0.014968,0.000000
17.870001,3.403488,-103.240288,0.005764,0.000564,0.014335,15.139471,0.771241,0.143353,-103.240288,0.015367,0.000000
18.110001,3.498444,-103.240288,0.005812,0.000580,0.014726,15.561854,0.792759,0.147255,-103.240288,0.015766,0.000000
18.350000,3.613136,-103.284767,0.005803,0.000595,0.015124,16.072033,0.818748,0.151244,-103.284767,0.016174,0.000000
18.590000,3.666382,-103.284767,0.005808,0.000608,0.015445,16.308882,0.830814,0.154453,-103.284767,0.016573,0.000000
18.830002,3.778839,-103.240288,0.005846,0.000628,0.015940,16.809116,0.856297,0.159396,-103.240288,0.016972,0.000000
19.070002,3.867088,-103.284767,0.005855,0.000644,0.016347,17.201668,0.876295,0.163472,-103.284767,0.017371,0.000000
19.310001,3.974709,-103.329247,0.005885,0.000658,0.016711,17.680387,0.900682,0.167114,-103.329247,0.017770,0.000000
19.550001,4.039871,-103.284767,0.005877,0.000672,0.017067,17.970245,0.915448,0.170670,-103.284767,0.018168,0.000000
19.790001,4.102058,-103.329247,0.005898,0.000686,0.017431,18.246866,0.929540,0.174312,-103.329247,0.018567,0.000000
20.030001,4.164619,-103.329247,0.005928,0.000702,0.017822,18.525152,0.943716,0.178216,-103.329247,0.018966,0.000000
20.270000,4.372025,-103.329247,0.005915,0.000718,0.018246,19.447737,0.990715,0.182464,-103.329247,0.019374,0.000000
20.510000,4.400703,-103.373734,0.005941,0.000738,0.018749,19.575306,0.997214,0.187494,-103.373734,0.019773,0.000000
20.750002,4.596565,-103.329247,0.005963,0.000751,0.019070,20.446543,1.041597,0.190703,-103.329247,0.020172,0.000000
20.990002,4.691895,-103.373734,0.005963,0.000769,0.019539,20.870588,1.063198,0.195386,-103.373734,0.020571,0.000000
21.230001,4.850899,-103.284767,0.005997,0.000787,0.019990,21.577875,1.099229,0.199895,-103.284767,0.020970,0.000000
21.470001,4.884415,-103.373734,0.006006,0.000801,0.020336,21.726961,1.106824,0.203364,-103.373734,0.021368,0.000000
21.710001,5.029640,-103.373734,0.006040,0.000817,0.020744,22.372957,1.139733,0.207441,-103.373734,0.021767,0.000000
21.950001,5.091080,-103.373734,0.006036,0.000828,0.021022,22.646254,1.153655,0.210216,-103.373734,0.022166,0.000000
22.190001,5.312271,-103.462692,0.006049,0.000851,0.021611,23.630161,1.203778,0.216113,-103.462692,0.022574,0.000000
22.430000,5.376686,-103.418213,0.006071,0.000861,0.021871,23.916695,1.218374,0.218715,-103.418213,0.022973,0.000000
22.670002,5.301094,-103.373734,0.006084,0.000867,0.022010,23.580444,1.201245,0.220102,-103.373734,0.023372,0.000000
22.910002,5.577026,-103.462692,0.006096,0.000892,0.022661,24.807852,1.263772,0.226606,-103.462692,0.023771,0.000000
23.150002,5.775131,-103.373734,0.006105,0.000912,0.023164,25.689066,1.308663,0.231637,-103.373734,0.024170,0.000000
23.390001,5.857048,-103.462692,0.006127,0.000925,0.023502,26.053452,1.327226,0.235018,-103.462692,0.024569,0.000000
23.630001,5.959824,-103.373734,0.006148,0.000941,0.023892,26.510620,1.350515,0.238921,-103.373734,0.024967,0.000000
23.870001,6.022385,-103.462692,0.006165,0.000953,0.024213,26.788904,1.364692,0.242129,-103.462692,0.025366,0.000000
24.110001,6.207825,-103.462692,0.006170,0.000971,0.024673,27.613783,1.406713,0.246726,-103.462692,0.025774,0.000000
24.350000,6.310226,-103.418213,0.006204,0.000985,0.025011,28.069288,1.429918,0.250108,-103.418213,0.026173,0.000000
24.590002,6.416725,-103.462692,0.006200,0.000998,0.025349,28.543018,1.454051,0.253491,-103.462692,0.026572,0.000000
24.830002,6.430130,-103.507172,0.006204,0.001008,0.025592,28.602646,1.457088,0.255919,-103.507172,0.026971,0.000000
25.070002,6.801384,-103.507172,0.006243,0.001041,0.026442,30.254066,1.541216,0.264417,-103.507172,0.027370,0.000000
25.310001,6.819260,-103.551651,0.006256,0.001052,0.026711,30.333582,1.545266,0.267106,-103.551651,0.027769,0.000000
25.550001,6.892990,-103.462692,0.006256,0.001066,0.027083,30.661551,1.561974,0.270835,-103.462692,0.028167,0.000000
25.790001,7.005074,-103.507172,0.006291,0.001084,0.027543,31.160124,1.587372,0.275432,-103.507172,0.028566,0.000000
26.030001,7.145828,-103.551651,0.006291,0.001098,0.027899,31.786232,1.619268,0.278987,-103.551651,0.028974,0.000000
26.270000,7.286591,-103.507172,0.006312,0.001114,0.028298,32.412373,1.651165,0.282976,-103.507172,0.029373,0.000000
26.510002,7.388992,-103.596138,0.006342,0.001128,0.028644,32.867878,1.674370,0.286445,-103.596138,0.029772,0.000000
26.750002,7.485062,-103.507172,0.006338,0.001142,0.029017,33.295216,1.696139,0.290174,-103.507172,0.030171,0.000000
26.990002,7.623215,-103.596138,0.006355,0.001163,0.029529,33.909752,1.727445,0.295291,-103.596138,0.030570,0.000000
27.230001,7.718170,-103.551651,0.006381,0.001175,0.029833,34.332134,1.748962,0.298325,-103.551651,0.030969,0.000000
27.470001,7.823174,-103.551651,0.006381,0.001192,0.030275,34.799213,1.772756,0.302749,-103.551651,0.031368,0.000000
27.710001,7.922974,-103.596138,0.006411,0.001207,0.030656,35.243145,1.795372,0.306564,-103.596138,0.031767,0.000000
27.950001,8.093521,-103.551651,0.006428,0.001226,0.031133,36.001781,1.834018,0.311334,-103.551651,0.032174,0.000000
28.190001,8.154587,-103.640617,0.006446,0.001237,0.031411,36.273415,1.847856,0.314109,-103.640617,0.032573,0.000000
28.430002,8.325882,-103.640617,0.006459,0.001254,0.031845,37.035374,1.886672,0.318446,-103.640617,0.032972,0.000000
28.670002,8.422325,-103.640617,0.006463,0.001270,0.032261,37.464375,1.908526,0.322608,-103.640617,0.033371,0.000000
28.910002,8.592125,-103.685097,0.006502,0.001288,0.032720,38.219681,1.947003,0.327204,-103.685097,0.033770,0.000000
29.150002,8.713890,-103.551651,0.006497,0.001306,0.033163,38.761318,1.974596,0.331628,-103.551651,0.034169,0.000000
29.390001,8.796928,-103.640617,0.006519,0.001319,0.033510,39.130692,1.993412,0.335097,-103.640617,0.034568,0.000000
29.630001,8.839005,-103.640617,0.006519,0.001332,0.033831,39.317856,2.002947,0.338305,-103.640617,0.034967,0.000000
29.870001,9.045303,-103.640617,0.006545,0.001350,0.034281,40.235519,2.049695,0.342815,-103.640617,0.035374,0.000000
30.110001,9.126106,-103.729576,0.006575,0.001363,0.034628,40.594948,2.068005,0.346284,-103.729576,0.035773,0.000000
30.350002,9.253090,-103.596138,0.006558,0.001377,0.034984,41.159798,2.096780,0.349839,-103.596138,0.036172,0.000000
30.590002,9.443741,-103.685097,0.006588,0.001397,0.035487,42.007858,2.139982,0.354869,-103.685097,0.036571,0.000000
30.830002,9.709984,-103.685097,0.006622,0.001419,0.036042,43.192165,2.200314,0.360419,-103.685097,0.036970,0.000000
31.070002,9.713715,-103.685097,0.006653,0.001433,0.036406,43.208759,2.201159,0.364061,-103.685097,0.037369,0.000000
31.310001,9.784462,-103.774055,0.006644,0.001449,0.036805,43.523460,2.217191,0.368051,-103.774055,0.037768,0.000000
31.550001,9.848885,-103.640617,0.006653,0.001462,0.037126,43.810028,2.231789,0.371259,-103.640617,0.038175,0.000000
31.790001,10.074913,-103.729576,0.006687,0.001483,0.037664,44.815453,2.283008,0.376637,-103.729576,0.038574,0.000000
32.030003,10.123322,-103.685097,0.006700,0.001495,0.037967,45.030785,2.293977,0.379671,-103.685097,0.038973,0.000000
32.270000,10.178802,-103.685097,0.006700,0.001506,0.038245,45.277576,2.306550,0.382447,-103.685097,0.039372,0.000000
32.510002,10.437607,-103.818542,0.006726,0.001528,0.038800,46.428795,2.365196,0.387997,-103.818542,0.039771,0.000000
32.750000,10.539261,-103.774055,0.006743,0.001544,0.039216,46.880974,2.388231,0.392160,-103.774055,0.040170,0.000000
32.990002,10.703102,-103.818542,0.006756,0.001560,0.039615,47.609776,2.425358,0.396149,-103.818542,0.040569,0.000000
33.230003,10.816307,-103.818542,0.006773,0.001576,0.040031,48.113338,2.451010,0.400311,-103.818542,0.040968,0.000000
33.470001,10.844978,-103.774055,0.006778,0.001587,0.040309,48.240871,2.457507,0.403087,-103.774055,0.041375,0.000000
33.710003,11.071754,-103.818542,0.006812,0.001607,0.040820,49.249622,2.508895,0.408204,-103.818542,0.041774,0.000000
33.950001,11.153679,-103.774055,0.006821,0.001619,0.041133,49.614040,2.527460,0.411325,-103.774055,0.042173,0.000000
34.190002,11.188675,-103.863022,0.006825,0.001631,0.041436,49.769711,2.535390,0.414361,-103.863022,0.042572,0.000000
34.430000,11.356247,-103.863022,0.006851,0.001648,0.041861,50.515110,2.573362,0.418610,-103.863022,0.042971,0.000000
34.670002,11.498863,-103.774055,0.006868,0.001665,0.042303,51.149498,2.605680,0.423033,-103.774055,0.043370,0.000000
34.910000,11.404282,-103.818542,0.006864,0.001666,0.042321,50.728779,2.584247,0.423206,-103.818542,0.043769,0.000000
35.150002,11.959114,-103.774055,0.006890,0.001697,0.043110,53.196796,2.709974,0.431099,-103.774055,0.044168,0.000000
35.390003,12.105835,-103.818542,0.006929,0.001715,0.043552,53.849442,2.743222,0.435521,-103.818542,0.044575,0.000000
35.630001,12.199669,-103.863022,0.006929,0.001730,0.043942,54.266838,2.764485,0.439423,-103.863022,0.044974,0.000000
35.870003,12.314362,-103.818542,0.006933,0.001747,0.044367,54.777016,2.790474,0.443673,-103.818542,0.045373,0.000000
36.110001,12.263344,-103.951981,0.006967,0.001755,0.044575,54.550079,2.778913,0.445755,-103.951981,0.045772,0.000000
36.350002,12.634972,-103.863022,0.006985,0.001777,0.045148,56.203159,2.863125,0.451478,-103.863022,0.046171,0.000000
36.590000,12.710937,-103.951981,0.006972,0.001792,0.045529,56.541073,2.880340,0.455294,-103.951981,0.046570,0.000000
36.830002,12.841637,-103.907501,0.007023,0.001807,0.045894,57.122452,2.909956,0.458936,-103.907501,0.046969,0.000000
37.070004,13.118683,-103.951981,0.007019,0.001827,0.046397,58.354816,2.972736,0.463966,-103.951981,0.047368,0.000000
37.310001,12.989098,-103.951981,0.007036,0.001835,0.046605,57.778393,2.943372,0.466047,-103.951981,0.047775,0.000000
37.550003,13.239334,-103.907501,0.007045,0.001851,0.047004,58.891499,3.000076,0.470037,-103.907501,0.048174,0.000000
37.790001,13.434082,-103.951981,0.007075,0.001868,0.047446,59.757782,3.044206,0.474459,-103.951981,0.048573,0.000000
38.030003,13.433716,-104.040947,0.007084,0.001879,0.047715,59.756153,3.044123,0.477148,-104.040947,0.048972,0.000000
38.270000,13.802361,-103.951981,0.007084,0.001901,0.048296,61.395966,3.127660,0.482958,-103.951981,0.049371,0.000000
38.510002,13.955032,-103.951981,0.007114,0.001917,0.048695,62.075085,3.162256,0.486948,-103.951981,0.049770,0.000000
38.750000,14.201920,-103.951981,0.007123,0.001935,0.049137,63.173294,3.218201,0.491370,-103.951981,0.050169,0.000000
38.990002,14.276390,-103.951981,0.007148,0.001950,0.049527,63.504555,3.235076,0.495272,-103.951981,0.050568,0.000000
39.230003,14.445450,-104.040947,0.007187,0.001965,0.049900,64.256569,3.273386,0.499002,-104.040947,0.050976,0.000000
39.470001,14.645782,-103.996460,0.007183,0.001982,0.050334,65.147697,3.318782,0.503338,-103.996460,0.051374,0.000000
39.710003,14.816704,-103.996460,0.007183,0.001997,0.050733,65.907990,3.357513,0.507327,-103.996460,0.051773,0.000000
39.950001,14.885590,-104.040947,0.007209,0.002011,0.051080,66.214409,3.373123,0.510796,-104.040947,0.052172,0.000000
40.190002,15.140671,-103.996460,0.007217,0.002029,0.051539,67.349068,3.430925,0.515393,-103.996460,0.052571,0.000000
40.430000,15.363350,-103.996460,0.007226,0.002045,0.051947,68.339592,3.481385,0.519468,-103.996460,0.052970,0.000000
40.670002,15.470215,-104.040947,0.007243,0.002059,0.052294,68.814949,3.505601,0.522937,-104.040947,0.053369,0.000000
40.910004,15.614326,-104.040947,0.007269,0.002075,0.052710,69.455994,3.538257,0.527100,-104.040947,0.053768,0.000000
41.150002,15.740562,-104.040947,0.007265,0.002090,0.053074,70.017517,3.566863,0.530743,-104.040947,0.054176,0.000000
41.390003,16.006805,-104.085426,0.007295,0.002105,0.053464,71.201828,3.627194,0.534645,-104.085426,0.054574,0.000000
41.630001,16.208633,-104.085426,0.007304,0.002123,0.053924,72.099602,3.672929,0.539242,-104.085426,0.054973,0.000000
41.870003,16.384018,-104.085426,0.007330,0.002136,0.054254,72.879753,3.712672,0.542536,-104.085426,0.055372,0.000000
42.110001,16.541908,-104.085426,0.007321,0.002151,0.054635,73.582085,3.748450,0.546352,-104.085426,0.055771,0.000000
42.350002,16.815971,-104.085426,0.007364,0.002169,0.055104,74.801178,3.810554,0.551035,-104.085426,0.056170,0.000000
42.590000,17.079987,-104.174385,0.007355,0.002186,0.055528,75.975578,3.870380,0.555285,-104.174385,0.056569,0.000000
42.830002,17.244202,-104.129906,0.007377,0.002204,0.055979,76.706039,3.907592,0.559794,-104.129906,0.056968,0.000000
43.070004,17.338409,-104.085426,0.007399,0.002217,0.056300,77.125099,3.928940,0.563003,-104.085426,0.057376,0.000000
43.310001,17.349205,-104.129906,0.007412,0.002226,0.056552,77.173119,3.931386,0.565518,-104.129906,0.057775,0.000000
43.550003,17.975540,-104.174385,0.007442,0.002250,0.057159,79.959198,4.073316,0.571589,-104.174385,0.058174,0.000000
43.790001,17.944633,-104.129906,0.007442,0.002261,0.057428,79.821716,4.066312,0.574277,-104.129906,0.058572,0.000000
44.030003,18.180344,-104.174385,0.007442,0.002278,0.057853,80.870209,4.119724,0.578527,-104.174385,0.058971,0.000000
44.270000,18.388870,-104.129906,0.007450,0.002296,0.058321,81.797783,4.166978,0.583210,-104.129906,0.059370,0.000000
44.510002,18.848381,-104.218872,0.007472,0.002314,0.058763,83.841789,4.271104,0.587632,-104.218872,0.059769,0.000000
44.750004,18.886360,-104.174385,0.007511,0.002326,0.059093,84.010727,4.279710,0.590928,-104.174385,0.060177,0.000000
44.990002,19.045364,-104.174385,0.007528,0.002343,0.059500,84.718010,4.315741,0.595003,-104.174385,0.060576,0.000000
45.230003,19.185005,-104.263351,0.007532,0.002356,0.059830,85.339165,4.347384,0.598299,-104.263351,0.060975,0.000000
45.470001,19.549927,-104.129906,0.007549,0.002370,0.060194,86.962418,4.430077,0.601941,-104.129906,0.061374,0.000000
45.710003,19.700371,-104.218872,0.007558,0.002386,0.060593,87.631622,4.464168,0.605930,-104.218872,0.061773,0.000000
45.950001,19.985229,-104.263351,0.007588,0.002403,0.061044,88.898743,4.528718,0.610440,-104.263351,0.062171,0.000000
46.190002,19.972198,-104.218872,0.007588,0.002419,0.061434,88.840775,4.525765,0.614343,-104.218872,0.062570,0.000000
46.430000,20.858444,-104.263351,0.007631,0.002441,0.061989,92.782997,4.726591,0.619893,-104.263351,0.062969,0.000000
46.670002,20.879669,-104.263351,0.007614,0.002455,0.062354,92.877411,4.731401,0.623536,-104.263351,0.063377,0.000000
46.910004,20.912071,-104.307831,0.007614,0.002467,0.062657,93.021538,4.738743,0.626570,-104.307831,0.063776,0.000000
47.150002,21.333595,-104.263351,0.007653,0.002486,0.063143,94.896568,4.834262,0.631427,-104.263351,0.064175,0.000000
47.390003,21.488876,-104.352310,0.007649,0.002498,0.063438,95.587296,4.869449,0.634376,-104.352310,0.064574,0.000000
47.630001,21.913376,-104.352310,0.007666,0.002516,0.063906,97.475563,4.965642,0.639059,-104.352310,0.064973,0.000000
47.870003,22.016151,-104.263351,0.007692,0.002528,0.064218,97.932732,4.988931,0.642181,-104.263351,0.065371,0.000000
48.110001,22.305115,-104.352310,0.007718,0.002547,0.064704,99.218109,5.054411,0.647037,-104.352310,0.065770,0.000000
48.350002,22.730736,-104.307831,0.007735,0.002563,0.065111,101.111366,5.150858,0.651114,-104.307831,0.066169,0.000000
48.590004,22.906120,-104.352310,0.007713,0.002578,0.065493,101.891510,5.190601,0.654929,-104.352310,0.066577,0.000000
48.830002,23.161568,-104.352310,0.007765,0.002593,0.065857,103.027802,5.248486,0.658572,-104.352310,0.066976,0.000000
49.070004,23.383133,-104.307831,0.007761,0.002607,0.066213,104.013367,5.298694,0.662127,-104.307831,0.067375,0.000000
49.310001,23.802048,-104.396790,0.007774,0.002626,0.066698,105.876793,5.393621,0.666984,-104.396790,0.067774,0.000000
49.550003,24.065689,-104.352310,0.007795,0.002639,0.067037,107.049530,5.453363,0.670365,-104.352310,0.068173,0.000000
49.790001,24.426521,-104.352310,0.007787,0.002656,0.067461,108.654594,5.535129,0.674615,-104.352310,0.068572,0.000000
50.030003,24.669304,-104.396790,0.007817,0.002669,0.067791,109.734543,5.590144,0.677911,-104.396790,0.068970,0.000000
50.270004,25.266594,-104.352310,0.007834,0.002691,0.068363,112.391426,5.725492,0.683634,-104.352310,0.069369,0.000000
50.510002,25.427826,-104.441277,0.007856,0.002705,0.068719,113.108620,5.762028,0.687190,-104.441277,0.069777,0.000000
50.750004,25.614388,-104.441277,0.007869,0.002718,0.069049,113.938484,5.804303,0.690485,-104.441277,0.070176,0.000000
50.990002,25.821426,-104.441277,0.007881,0.002732,0.069387,114.859444,5.851219,0.693868,-104.441277,0.070575,0.000000
51.230003,26.358017,-104.485756,0.007886,0.002751,0.069864,117.246315,5.972812,0.698638,-104.485756,0.070974,0.000000
51.470001,26.616066,-104.396790,0.007899,0.002765,0.070228,118.394173,6.031287,0.702280,-104.396790,0.071373,0.000000
51.710003,26.937424,-104.485756,0.007899,0.002780,0.070601,119.823647,6.104107,0.706009,-104.485756,0.071772,0.000000
51.950001,27.380920,-104.396790,0.007938,0.002798,0.071060,121.796417,6.204605,0.710605,-104.396790,0.072171,0.000000
52.190002,28.097740,-104.485756,0.007950,0.002819,0.071607,124.984993,6.367039,0.716068,-104.485756,0.072569,0.000000
52.430004,28.257118,-104.530235,0.007963,0.002834,0.071988,125.693939,6.403154,0.719884,-104.530235,0.072977,0.000000
52.670002,28.515915,-104.485756,0.007985,0.002848,0.072344,126.845123,6.461799,0.723440,-104.485756,0.073376,0.000000
52.910004,28.711411,-104.530235,0.007972,0.002862,0.072682,127.714729,6.506099,0.726822,-104.530235,0.073775,0.000000
53.150002,29.417427,-104.485756,0.007998,0.002882,0.073194,130.855255,6.666084,0.731939,-104.485756,0.074174,0.000000
53.390003,29.491158,-104.485756,0.008006,0.002894,0.073515,131.183228,6.682792,0.735148,-104.485756,0.074573,0.000000
53.630001,29.306458,-104.530235,0.008019,0.002899,0.073627,130.361633,6.640938,0.736275,-104.530235,0.074972,0.000000
53.870003,30.474220,-104.530235,0.008045,0.002926,0.074321,135.556107,6.905557,0.743212,-104.530235,0.075371,0.000000
54.110004,30.979530,-104.574715,0.008058,0.002945,0.074807,137.803833,7.020061,0.748069,-104.574715,0.075770,0.000000
54.350002,31.209656,-104.530235,0.008067,0.002959,0.075171,138.827484,7.072209,0.751711,-104.530235,0.076177,0.000000
54.590004,31.662086,-104.530235,0.008084,0.002977,0.075613,140.839996,7.174732,0.756134,-104.530235,0.076576,0.000000
54.830002,31.697464,-104.574715,0.008101,0.002989,0.075908,140.997360,7.182748,0.759082,-104.574715,0.076975,0.000000
55.070004,32.377792,-104.485756,0.008119,0.003006,0.076359,144.023621,7.336913,0.763592,-104.485756,0.077374,0.000000
55.310001,32.582222,-104.574715,0.008127,0.003020,0.076706,144.932968,7.383237,0.767061,-104.574715,0.077773,0.000000
55.550003,32.746063,-104.530235,0.008136,0.003030,0.076966,145.661758,7.420364,0.769663,-104.530235,0.078172,0.000000
55.790001,33.315796,-104.574715,0.008136,0.003048,0.077417,148.196060,7.549468,0.774173,-104.574715,0.078571,0.000000
56.030003,33.897812,-104.574715,0.008153,0.003064,0.077834,150.785004,7.681354,0.778335,-104.574715,0.078970,0.000000
56.270004,34.116020,-104.574715,0.008170,0.003077,0.078146,151.755630,7.730801,0.781457,-104.574715,0.079377,0.000000
56.510002,34.934128,-104.619194,0.008170,0.003097,0.078657,155.394760,7.916186,0.786574,-104.619194,0.079776,0.000000
56.750004,35.401077,-104.574715,0.008201,0.003113,0.079074,157.471863,8.021998,0.790736,-104.574715,0.080175,0.000000
56.990002,36.004326,-104.574715,0.008213,0.003132,0.079542,160.155243,8.158697,0.795419,-104.574715,0.080574,0.000000
57.230003,36.412071,-104.619194,0.008226,0.003146,0.079915,161.968979,8.251093,0.799148,-104.619194,0.080973,0.000000
57.470001,36.385262,-104.574715,0.008226,0.003157,0.080192,161.849731,8.245018,0.801924,-104.574715,0.081372,0.000000
57.710003,37.344864,-104.708160,0.008257,0.003178,0.080730,166.118256,8.462466,0.807301,-104.708160,0.081771,0.000000
57.950005,37.711281,-104.663681,0.008282,0.003192,0.081068,167.748154,8.545499,0.810683,-104.663681,0.082178,0.000000
58.190002,38.098549,-104.663681,0.008278,0.003206,0.081432,169.470810,8.633254,0.814325,-104.663681,0.082577,0.000000
58.430004,38.966545,-104.708160,0.008291,0.003225,0.081927,173.331848,8.829946,0.819268,-104.708160,0.082976,0.000000
58.670002,38.864143,-104.663681,0.008300,0.003234,0.082152,172.876343,8.806741,0.821523,-104.663681,0.083375,0.000000
58.910004,39.429405,-104.708160,0.008300,0.003249,0.082525,175.390747,8.934831,0.825252,-104.708160,0.083774,0.000000
59.150002,40.145851,-104.752640,0.008321,0.003268,0.083002,178.577667,9.097180,0.830022,-104.752640,0.084173,0.000000
59.390003,40.480614,-104.663681,0.008330,0.003282,0.083375,180.066757,9.173038,0.833751,-104.663681,0.084572,0.000000
59.630001,41.278610,-104.708160,0.008356,0.003300,0.083809,183.616425,9.353867,0.838087,-104.708160,0.084971,0.000000
59.870003,41.969734,-104.708160,0.008356,0.003317,0.084260,186.690704,9.510478,0.842597,-104.708160,0.085378,0.000000
60.110004,42.622871,-104.797119,0.008377,0.003333,0.084667,189.596008,9.658481,0.846672,-104.797119,0.085777,0.000000
60.350002,43.160950,-104.663681,0.008403,0.003350,0.085101,191.989487,9.780411,0.851009,-104.663681,0.086176,0.000000
60.590004,43.617477,-104.752640,0.008399,0.003363,0.085430,194.020233,9.883862,0.854305,-104.752640,0.086575,0.000000
60.830002,44.324242,-104.797119,0.008412,0.003385,0.085968,197.164078,10.044017,0.859681,-104.797119,0.086974,0.000000
61.070004,44.809074,-104.752640,0.008412,0.003398,0.086298,199.320724,10.153881,0.862977,-104.752640,0.087373,0.000000
61.310001,45.208626,-104.886086,0.008429,0.003409,0.086601,201.098007,10.244421,0.866011,-104.886086,0.087772,0.000000
61.550003,45.814850,-104.797119,0.008464,0.003427,0.087052,203.794632,10.381794,0.870521,-104.797119,0.088171,0.000000
61.790005,46.635185,-104.752640,0.008455,0.003444,0.087486,207.443665,10.567684,0.874858,-104.752640,0.088578,0.000000
62.030003,47.114426,-104.841599,0.008476,0.003460,0.087876,209.575439,10.676281,0.878760,-104.841599,0.088977,0.000000
62.270004,47.692352,-104.752640,0.008489,0.003475,0.088258,212.146179,10.807241,0.882576,-104.752640,0.089376,0.000000
62.510002,48.161537,-104.841599,0.008502,0.003489,0.088622,214.233215,10.913560,0.886218,-104.841599,0.089775,0.000000
62.750004,48.821014,-104.797119,0.008507,0.003505,0.089021,217.166718,11.063000,0.890207,-104.797119,0.090174,0.000000
62.990002,49.721779,-104.841599,0.008524,0.003526,0.089558,221.173523,11.267116,0.895585,-104.841599,0.090573,0.000000
63.230003,50.250175,-104.841599,0.008532,0.003537,0.089836,223.523941,11.386852,0.898359,-104.841599,0.090972,0.000000
63.470001,50.660904,-104.797119,0.008563,0.003549,0.090157,225.350952,11.479925,0.901568,-104.797119,0.091371,0.000000
63.710003,51.510284,-104.930565,0.008545,0.003569,0.090642,229.129196,11.672398,0.906425,-104.930565,0.091778,0.000000
63.950005,52.375305,-104.886086,0.008576,0.003585,0.091050,232.976990,11.868414,0.910501,-104.886086,0.092177,0.000000
64.190002,53.038872,-104.886086,0.008580,0.003604,0.091536,235.928680,12.018781,0.915357,-104.886086,0.092576,0.000000
64.430000,53.505455,-104.886086,0.008580,0.003616,0.091839,238.004150,12.124510,0.918392,-104.886086,0.092975,0.000000
64.670006,53.680099,-104.841599,0.008606,0.003626,0.092091,238.781006,12.164084,0.920907,-104.841599,0.093374,0.000000
64.910004,55.076500,-104.886086,0.008606,0.003648,0.092663,244.992508,12.480513,0.926631,-104.886086,0.093773,0.000000
65.150002,55.369179,-104.841599,0.008636,0.003659,0.092941,246.294403,12.546835,0.929406,-104.841599,0.094172,0.000000
65.389999,55.985085,-104.886086,0.008632,0.003674,0.093322,249.034088,12.686401,0.933222,-104.886086,0.094571,0.000000
65.630005,56.887718,-104.930565,0.008636,0.003695,0.093842,253.049210,12.890942,0.938425,-104.930565,0.094979,0.000000
65.870003,57.841736,-104.975044,0.008675,0.003711,0.094250,257.292877,13.107125,0.942501,-104.975044,0.095377,0.000000
66.110001,58.369011,-104.975044,0.008662,0.003721,0.094519,259.638336,13.226607,0.945190,-104.975044,0.095776,0.000000
66.350006,59.149132,-104.930565,0.008679,0.003738,0.094935,263.108490,13.403384,0.949352,-104.930565,0.096175,0.000000
66.590004,59.579224,-104.930565,0.008701,0.003750,0.095239,265.021637,13.500845,0.952387,-104.930565,0.096574,0.000000
66.830002,60.666550,-105.019524,0.008675,0.003769,0.095724,269.858276,13.747236,0.957244,-105.019524,0.096973,0.000000
67.070000,61.292511,-104.975044,0.008709,0.003782,0.096063,272.642700,13.889081,0.960626,-104.975044,0.097372,0.000000
67.310005,62.122154,-105.019524,0.008718,0.003800,0.096531,276.333130,14.077082,0.965309,-105.019524,0.097771,0.000000
67.550003,63.915871,-105.019524,0.008735,0.003824,0.097138,284.311981,14.483543,0.971380,-105.019524,0.098179,0.000000
67.790001,64.812920,-104.975044,0.008748,0.003839,0.097511,288.302277,14.686818,0.975109,-104.975044,0.098578,0.000000
68.030006,65.323814,-105.019524,0.008752,0.003852,0.097840,290.574829,14.802588,0.978404,-105.019524,0.098977,0.000000
68.270004,65.802315,-105.019524,0.008765,0.003865,0.098179,292.703308,14.911017,0.981787,-105.019524,0.099375,0.000000
68.510002,67.041191,-105.064003,0.008778,0.003884,0.098656,298.214111,15.191751,0.986557,-105.064003,0.099774,0.000000
68.750000,67.082161,-105.064003,0.008795,0.003884,0.098656,298.396362,15.201035,0.986557,-105.064003,0.098881,0.000000
68.990005,66.386192,-105.064003,0.008791,0.003884,0.098656,295.300537,15.043326,0.986557,-105.064003,0.098881,0.000000
69.230003,65.927803,-105.064003,0.008795,0.003879,0.098534,293.261505,14.939454,0.985343,-105.064003,0.098656,0.000000
69.470001,65.440742,-105.019524,0.008804,0.003878,0.098491,291.094971,14.829084,0.984908,-105.019524,0.098656,0.000000
69.710007,65.009529,-105.064003,0.008795,0.003877,0.098482,289.176819,14.731370,0.984822,-105.064003,0.098656,0.000000
69.950005,64.639015,-105.064003,0.008821,0.003877,0.098474,287.528687,14.647410,0.984735,-105.064003,0.098656,0.000000
70.190002,64.315056,-105.064003,0.008808,0.003877,0.098465,286.087646,14.574000,0.984648,-105.064003,0.098656,0.000000
70.430000,64.000771,-105.152969,0.008795,0.003876,0.098456,284.689636,14.502782,0.984562,-105.152969,0.098656,0.000000
70.670006,63.737877,-105.108490,0.008795,0.003876,0.098456,283.520233,14.443210,0.984562,-105.108490,0.098656,0.000000
70.910004,63.479088,-105.108490,0.008808,0.003876,0.098456,282.369080,14.384566,0.984562,-105.108490,0.098656,0.000000
71.150002,63.254921,-105.064003,0.008834,0.003876,0.098447,281.371948,14.333770,0.984475,-105.064003,0.098656,0.000000
71.390007,63.032234,-105.064003,0.008813,0.003876,0.098447,280.381378,14.283309,0.984475,-105.064003,0.098656,0.000000
71.630005,62.843071,-105.108490,0.008826,0.003876,0.098447,279.539948,14.240443,0.984475,-105.108490,0.098656,0.000000
71.870003,62.657997,-105.152969,0.008821,0.003876,0.098447,278.716705,14.198505,0.984475,-105.152969,0.098656,0.000000
72.110001,62.480377,-105.197449,0.008817,0.003876,0.098447,277.926605,14.158256,0.984475,-105.197449,0.098656,0.000000
72.350006,62.315414,-105.152969,0.008813,0.003876,0.098447,277.192810,14.120875,0.984475,-105.152969,0.098656,0.000000
72.590004,62.160141,-105.152969,0.008821,0.003876,0.098447,276.502106,14.085689,0.984475,-105.152969,0.098656,0.000000
72.830002,62.029808,-105.197449,0.008843,0.003876,0.098447,275.922363,14.056155,0.984475,-105.197449,0.098656,0.000000
73.070000,61.893150,-105.152969,0.008826,0.003876,0.098447,275.314484,14.025188,0.984475,-105.152969,0.098656,0.000000
73.310005,61.760208,-105.197449,0.008821,0.003876,0.098447,274.723114,13.995063,0.984475,-105.197449,0.098656,0.000000
73.550003,61.647385,-105.197449,0.008826,0.003876,0.098447,274.221252,13.969497,0.984475,-105.197449,0.098656,0.000000
73.790001,61.532318,-105.241928,0.008826,0.003876,0.098447,273.709412,13.943423,0.984475,-105.241928,0.098656,0.000000
74.030006,61.428055,-105.197449,0.008852,0.003876,0.098447,273.245636,13.919796,0.984475,-105.197449,0.098656,0.000000
74.270004,61.320808,-105.241928,0.008821,0.003876,0.098447,272.768585,13.895494,0.984475,-105.241928,0.098656,0.000000
74.510002,61.214684,-105.241928,0.008834,0.003876,0.098447,272.296509,13.871446,0.984475,-105.241928,0.098656,0.000000
74.750000,61.120102,-105.241928,0.008830,0.003876,0.098447,271.875793,13.850014,0.984475,-105.241928,0.098656,0.000000
74.990005,61.019936,-105.197449,0.008821,0.003876,0.098447,271.430237,13.827315,0.984475,-105.197449,0.098656,0.000000
75.230003,60.931679,-105.286407,0.008821,0.003876,0.098447,271.037659,13.807316,0.984475,-105.286407,0.098656,0.000000
75.470001,60.792046,-105.286407,0.008830,0.003876,0.098439,270.416534,13.775675,0.984388,-105.286407,0.098656,0.000000
75.710007,60.703789,-105.286407,0.008826,0.003876,0.098439,270.023926,13.755675,0.984388,-105.286407,0.098656,0.000000
75.950005,60.620003,-105.330894,0.008830,0.003876,0.098439,269.651245,13.736690,0.984388,-105.330894,0.098656,0.000000
76.190002,60.548141,-105.241928,0.008834,0.003876,0.098439,269.331573,13.720406,0.984388,-105.241928,0.098656,0.000000
76.430000,60.469193,-105.330894,0.008830,0.003876,0.098439,268.980408,13.702515,0.984388,-105.330894,0.098656,0.000000
76.670006,60.394348,-105.286407,0.008834,0.003876,0.098439,268.647491,13.685555,0.984388,-105.286407,0.098656,0.000000
76.910004,60.326202,-105.286407,0.008821,0.003876,0.098439,268.344360,13.670113,0.984388,-105.286407,0.098656,0.000000
77.150002,60.263649,-105.286407,0.008834,0.003876,0.098439,268.066101,13.655937,0.984388,-105.286407,0.098656,0.000000
77.390007,60.194016,-105.286407,0.008843,0.003876,0.098439,267.756348,13.640159,0.984388,-105.286407,0.098656,0.000000
77.630005,60.126244,-105.419853,0.008830,0.003876,0.098439,267.454895,13.624802,0.984388,-105.419853,0.098656,0.000000
77.870003,60.044693,-105.330894,0.008839,0.003876,0.098439,267.092133,13.606322,0.984388,-105.330894,0.098656,0.000000
78.110001,60.000748,-105.330894,0.008826,0.003876,0.098439,266.896667,13.596363,0.984388,-105.330894,0.098656,0.000000
78.350006,59.920692,-105.330894,0.008843,0.003876,0.098439,266.540558,13.578223,0.984388,-105.330894,0.098656,0.000000
78.590004,59.867439,-105.375374,0.008852,0.003876,0.098439,266.303680,13.566155,0.984388,-105.375374,0.098656,0.000000
78.830002,59.821266,-105.419853,0.008830,0.003876,0.098439,266.098267,13.555693,0.984388,-105.419853,0.098656,0.000000
79.070007,59.767273,-105.375374,0.008852,0.003876,0.098439,265.858093,13.543458,0.984388,-105.375374,0.098656,0.000000
79.310005,59.712906,-105.419853,0.008843,0.003876,0.098439,265.616272,13.531137,0.984388,-105.419853,0.098656,0.000000
79.550003,59.664871,-105.375374,0.008813,0.003876,0.098439,265.402588,13.520252,0.984388,-105.375374,0.098656,0.000000
79.790001,59.614601,-105.330894,0.008826,0.003876,0.098439,265.178986,13.508862,0.984388,-105.330894,0.098656,0.000000
80.030006,59.550179,-105.419853,0.008843,0.003876,0.098439,264.892426,13.494263,0.984388,-105.419853,0.098656,0.000000
80.270004,59.502144,-105.508820,0.008843,0.003876,0.098439,264.678741,13.483379,0.984388,-105.508820,0.098656,0.000000
80.510002,59.452988,-105.419853,0.008860,0.003876,0.098439,264.460083,13.472239,0.984388,-105.419853,0.098656,0.000000
80.750008,59.409050,-105.464333,0.008843,0.003876,0.098439,264.264648,13.462283,0.984388,-105.464333,0.098656,0.000000
80.990005,59.366974,-105.508820,0.008852,0.003876,0.098439,264.077484,13.452748,0.984388,-105.508820,0.098656,0.000000
81.230003,59.315956,-105.508820,0.008834,0.003876,0.098439,263.850555,13.441188,0.984388,-105.508820,0.098656,0.000000
81.470001,59.300316,-105.508820,0.008869,0.003876,0.098439,263.780975,13.437644,0.984388,-105.508820,0.098656,0.000000
81.710007,59.235153,-105.464333,0.008860,0.003876,0.098439,263.491119,13.422877,0.984388,-105.464333,0.098656,0.000000
81.950005,59.186371,-105.508820,0.008847,0.003876,0.098439,263.274139,13.411824,0.984388,-105.508820,0.098656,0.000000
82.190002,59.150993,-105.419853,0.008843,0.003876,0.098439,263.116760,13.403807,0.984388,-105.419853,0.098656,0.000000
82.430000,59.100357,-105.553299,0.008843,0.003876,0.098439,262.891510,13.392332,0.984388,-105.553299,0.098656,0.000000
82.670006,59.063858,-105.508820,0.008852,0.003876,0.098439,262.729156,13.384061,0.984388,-105.508820,0.098656,0.000000
82.910004,59.022530,-105.508820,0.008860,0.003876,0.098439,262.545319,13.374697,0.984388,-105.508820,0.098656,0.000000
83.150002,59.001305,-105.597778,0.008856,0.003876,0.098439,262.450897,13.369887,0.984388,-105.597778,0.098656,0.000000
83.390007,58.948051,-105.553299,0.008843,0.003876,0.098439,262.214020,13.357819,0.984388,-105.553299,0.098656,0.000000
83.630005,58.917519,-105.553299,0.008864,0.003876,0.098439,262.078217,13.350901,0.984388,-105.553299,0.098656,0.000000
83.870003,58.874321,-105.597778,0.008843,0.003876,0.098439,261.886047,13.341112,0.984388,-105.597778,0.098656,0.000000
84.110001,58.838951,-105.553299,0.008856,0.003876,0.098439,261.728729,13.333097,0.984388,-105.553299,0.098656,0.000000
84.350006,58.807297,-105.686737,0.008847,0.003876,0.098439,261.587921,13.325924,0.984388,-105.686737,0.098656,0.000000
84.590004,58.763725,-105.508820,0.008847,0.003876,0.098439,261.394104,13.316051,0.984388,-105.508820,0.098656,0.000000
84.830002,58.738037,-105.642258,0.008852,0.003876,0.098439,261.279846,13.310229,0.984388,-105.642258,0.098656,0.000000
85.070007,58.704521,-105.597778,0.008864,0.003876,0.098439,261.130737,13.302635,0.984388,-105.597778,0.098656,0.000000
85.310005,58.664680,-105.597778,0.008847,0.003876,0.098439,260.953522,13.293607,0.984388,-105.597778,0.098656,0.000000
85.550003,58.641594,-105.686737,0.008843,0.003876,0.098439,260.850830,13.288376,0.984388,-105.686737,0.098656,0.000000
85.790001,58.607704,-105.597778,0.008839,0.003876,0.098439,260.700073,13.280695,0.984388,-105.597778,0.098656,0.000000
86.030006,58.565628,-105.597778,0.008869,0.003876,0.098439,260.512939,13.271161,0.984388,-105.597778,0.098656,0.000000
86.270004,58.545517,-105.642258,0.008856,0.003876,0.098439,260.423462,13.266603,0.984388,-105.642258,0.098656,0.000000
86.510002,58.516846,-105.642258,0.008864,0.003876,0.098439,260.295929,13.260107,0.984388,-105.642258,0.098656,0.000000
86.750008,58.470299,-105.686737,0.008869,0.003876,0.098439,260.088867,13.249559,0.984388,-105.686737,0.098656,0.000000
86.990005,58.447586,-105.642258,0.008860,0.003876,0.098439,259.987854,13.244412,0.984388,-105.642258,0.098656,0.000000
87.230003,58.416679,-105.597778,0.008839,0.003876,0.098439,259.850372,13.237409,0.984388,-105.597778,0.098656,0.000000
87.470001,58.380554,-105.686737,0.008869,0.003876,0.098439,259.689667,13.229222,0.984388,-105.686737,0.098656,0.000000
87.710007,58.367149,-105.686737,0.008852,0.003876,0.098439,259.630035,13.226185,0.984388,-105.686737,0.098656,0.000000
87.950005,58.343697,-105.642258,0.008852,0.003876,0.098439,259.525726,13.220870,0.984388,-105.642258,0.098656,0.000000
88.190002,58.316513,-105.731224,0.008864,0.003876,0.098439,259.404816,13.214710,0.984388,-105.731224,0.098656,0.000000
88.430008,58.274803,-105.686737,0.008852,0.003876,0.098439,259.219269,13.205259,0.984388,-105.686737,0.098656,0.000000
88.670006,58.266983,-105.686737,0.008852,0.003876,0.098439,259.184479,13.203486,0.984388,-105.686737,0.098656,0.000000
88.910004,58.235703,-105.686737,0.008839,0.003876,0.098439,259.045349,13.196399,0.984388,-105.686737,0.098656,0.000000
89.150002,58.203308,-105.775703,0.008843,0.003876,0.098439,258.901245,13.189057,0.984388,-105.775703,0.098656,0.000000
89.390007,58.188042,-105.731224,0.008843,0.003876,0.098439,258.833344,13.185598,0.984388,-105.731224,0.098656,0.000000
89.630005,58.151176,-105.775703,0.008852,0.003876,0.098439,258.669342,13.177245,0.984388,-105.775703,0.098656,0.000000
89.870003,58.142609,-105.775703,0.008864,0.003876,0.098439,258.631226,13.175303,0.984388,-105.775703,0.098656,0.000000
90.110001,58.108353,-105.686737,0.008869,0.003876,0.098439,258.478851,13.167541,0.984388,-105.686737,0.098656,0.000000
90.350006,58.074471,-105.775703,0.008852,0.003876,0.098439,258.328156,13.159863,0.984388,-105.775703,0.098656,0.000000
90.590004,58.044678,-105.731224,0.008860,0.003876,0.098439,258.195618,13.153111,0.984388,-105.731224,0.098656,0.000000
90.830002,58.023453,-105.820183,0.008847,0.003876,0.098439,258.101196,13.148302,0.984388,-105.820183,0.098656,0.000000
91.070007,57.998505,-105.731224,0.008839,0.003876,0.098439,257.990234,13.142649,0.984388,-105.731224,0.098656,0.000000
91.310005,57.982864,-105.775703,0.008860,0.003876,0.098439,257.920654,13.139105,0.984388,-105.775703,0.098656,0.000000
91.550003,57.948975,-105.775703,0.008852,0.003876,0.098439,257.769928,13.131425,0.984388,-105.775703,0.098656,0.000000
91.790001,57.945251,-105.864662,0.008839,0.003876,0.098439,257.753357,13.130582,0.984388,-105.864662,0.098656,0.000000
92.030006,57.913605,-105.775703,0.008843,0.003876,0.098439,257.612579,13.123411,0.984388,-105.775703,0.098656,0.000000
92.270004,57.906158,-105.864662,0.008847,0.003876,0.098439,257.579468,13.121723,0.984388,-105.864662,0.098656,0.000000
92.510002,57.870781,-105.820183,0.008856,0.003876,0.098439,257.422089,13.113707,0.984388,-105.820183,0.098656,0.000000
92.750008,57.874878,-105.820183,0.008847,0.003876,0.098439,257.440308,13.114635,0.984388,-105.820183,0.098656,0.000000
92.990005,57.837639,-105.864662,0.008847,0.003876,0.098439,257.274658,13.106196,0.984388,-105.864662,0.098656,0.000000
93.230003,57.819763,-105.909142,0.008843,0.003876,0.098439,257.195160,13.102145,0.984388,-105.909142,0.098656,0.000000
93.470001,57.800026,-105.909142,0.008852,0.003876,0.098439,257.107361,13.097673,0.984388,-105.909142,0.098656,0.000000
93.710007,57.766144,-105.864662,0.008847,0.003876,0.098439,256.956635,13.089995,0.984388,-105.864662,0.098656,0.000000
93.950005,57.759438,-105.864662,0.008852,0.003876,0.098439,256.926819,13.088475,0.984388,-105.864662,0.098656,0.000000
94.190002,57.726303,-105.909142,0.008856,0.003876,0.098439,256.779419,13.080967,0.984388,-105.909142,0.098656,0.000000
94.430008,57.708054,-105.820183,0.008856,0.003876,0.098439,256.698242,13.076832,0.984388,-105.820183,0.098656,0.000000
94.670006,57.696510,-105.953629,0.008847,0.003876,0.098439,256.646881,13.074216,0.984388,-105.953629,0.098656,0.000000
94.910004,57.666344,-105.953629,0.008882,0.003876,0.098439,256.512695,13.067381,0.984388,-105.953629,0.098656,0.000000
95.150002,57.651077,-105.909142,0.008847,0.003876,0.098439,256.444794,13.063921,0.984388,-105.909142,0.098656,0.000000
95.390007,57.632462,-105.909142,0.008852,0.003876,0.098439,256.362000,13.059702,0.984388,-105.909142,0.098656,0.000000
95.630005,57.607140,-105.864662,0.008869,0.003876,0.098439,256.249359,13.053965,0.984388,-105.864662,0.098656,0.000000
95.870003,57.595222,-105.909142,0.008847,0.003876,0.098439,256.196350,13.051264,0.984388,-105.909142,0.098656,0.000000
96.110008,57.574371,-105.953629,0.008860,0.003876,0.098439,256.103607,13.046539,0.984388,-105.953629,0.098656,0.000000
96.350006,57.562828,-105.953629,0.008847,0.003876,0.098439,256.052246,13.043922,0.984388,-105.953629,0.098656,0.000000
96.590004,57.547188,-106.042587,0.008869,0.003876,0.098439,255.982681,13.040379,0.984388,-106.042587,0.098656,0.000000
96.830002,57.511810,-105.953629,0.008856,0.003876,0.098439,255.825302,13.032363,0.984388,-105.953629,0.098656,0.000000
97.070007,57.514420,-105.998108,0.008860,0.003876,0.098439,255.836914,13.032953,0.984388,-105.998108,0.098656,0.000000
97.310005,57.493942,-106.042587,0.008864,0.003876,0.098439,255.745834,13.028314,0.984388,-106.042587,0.098656,0.000000
97.550003,57.471596,-105.953629,0.008839,0.003876,0.098439,255.646423,13.023250,0.984388,-105.953629,0.098656,0.000000
97.790001,57.467873,-106.087067,0.008860,0.003876,0.098439,255.629868,13.022407,0.984388,-106.087067,0.098656,0.000000
98.030006,57.413506,-106.042587,0.008873,0.003876,0.098439,255.388031,13.010087,0.984388,-106.042587,0.098656,0.000000
98.270004,57.419838,-106.042587,0.008860,0.003876,0.098439,255.416199,13.011521,0.984388,-106.042587,0.098656,0.000000
98.510002,57.393028,-106.042587,0.008856,0.003876,0.098439,255.296936,13.005445,0.984388,-106.042587,0.098656,0.000000
98.750008,57.384460,-106.042587,0.008860,0.003876,0.098439,255.258835,13.003505,0.984388,-106.042587,0.098656,0.000000
98.990005,57.365845,-106.042587,0.008856,0.003876,0.098439,255.176025,12.999286,0.984388,-106.042587,0.098656,0.000000
99.200005,57.349457,-106.042587,0.008864,0.003876,0.098439,255.103119,12.995572,0.984388,-106.042587,0.098656,0.000000