File: Data/Symmetrical membranes compression/Sartorius Cellulose Nitrate 5um test 1_10302023_165819.csv
Time (sec),S:Load (lbs),S:HL1 (DIM),S:LVDT (in),S:Position (in),Ch:Position (mm),Ch:Load (N),Ch:Stress (MPa),Ch:Strain (mm/mm),Ch:HL1 (DIM),Set Point (),Cycles ()
0.010000,-0.009308,-56.090481,0.000030,-0.000000,-0.000000,-0.041403,-0.002109,-0.000000,-56.090481,-0.000000,0.000000
0.260000,-0.004837,-56.090481,0.000034,-0.000000,-0.000000,-0.021516,-0.001096,-0.000000,-56.090481,-0.000000,0.000000
0.510000,-0.031654,-56.090481,0.000026,0.000075,0.001908,-0.140806,-0.007173,0.019079,-56.090481,0.002740,0.000000
0.760000,-0.055481,-56.134960,0.000069,0.000222,0.005637,-0.246792,-0.012572,0.056370,-56.134960,0.006920,0.000000
1.010000,-0.009308,-56.134960,0.000233,0.000381,0.009670,-0.041403,-0.002109,0.096696,-56.134960,0.011083,0.000000
1.260000,-0.000000,-56.134960,0.000414,0.000547,0.013902,-0.000000,-0.000000,0.139016,-56.134960,0.015246,0.000000
1.510000,-0.035004,-56.090481,0.000586,0.000712,0.018090,-0.155704,-0.007932,0.180904,-56.090481,0.019409,0.000000
1.760000,-0.003723,-56.223923,0.000737,0.000874,0.022201,-0.016561,-0.000844,0.222010,-56.223923,0.023571,0.000000
2.010000,0.027931,-56.134960,0.000923,0.001037,0.026329,0.124244,0.006329,0.263290,-56.134960,0.027734,0.000000
2.260000,0.085274,-56.223923,0.001091,0.001202,0.030535,0.379317,0.019323,0.305350,-56.223923,0.031897,0.000000
2.510000,0.139267,-56.223923,0.001242,0.001361,0.034568,0.619490,0.031558,0.345676,-56.223923,0.036059,0.000000
2.760000,0.303116,-56.179440,0.001418,0.001533,0.038930,1.348327,0.068687,0.389298,-56.179440,0.040239,0.000000
3.010000,0.526535,-56.223923,0.001587,0.001696,0.043075,2.342145,0.119315,0.430751,-56.223923,0.044402,0.000000
3.260000,0.687775,-56.223923,0.001694,-0.000000,-0.000000,3.059375,0.155852,-0.000000,-56.223923,0.000260,0.000000
3.510000,0.654633,-56.223923,0.001656,-0.000000,-0.000000,2.911951,0.148342,-0.000000,-56.223923,0.000260,0.000000
3.760000,0.654633,-56.268402,0.001690,-0.000000,-0.000000,2.911951,0.148342,-0.000000,-56.268402,0.000373,0.000000
4.010000,0.604362,-56.268402,0.001703,-0.000000,-0.000000,2.688339,0.136950,-0.000000,-56.268402,0.000789,0.000000
4.260000,0.629684,-56.268402,0.001686,-0.000000,-0.000000,2.800976,0.142689,-0.000000,-56.268402,0.001205,0.000000
4.510000,0.608833,-56.312885,0.001681,0.000000,0.000009,2.708226,0.137964,0.000086,-56.312885,0.001622,0.000000
4.760000,0.679955,-56.312885,0.001686,0.000036,0.000902,3.024589,0.154080,0.009018,-56.312885,0.002038,0.000000
5.010000,0.705276,-56.357365,0.001720,0.000054,0.001379,3.137227,0.159818,0.013788,-56.357365,0.002454,0.000000
5.260000,0.728737,-56.357365,0.001729,0.000067,0.001691,3.241584,0.165134,0.016911,-56.357365,0.002870,0.000000
5.510000,0.747726,-56.357365,0.001750,0.000087,0.002211,3.326053,0.169437,0.022114,-56.357365,0.003287,0.000000
5.760000,0.779747,-56.357365,0.001759,0.000102,0.002602,3.468488,0.176693,0.026016,-56.357365,0.003703,0.000000
6.010000,0.843056,-56.401848,0.001781,0.000118,0.002992,3.750099,0.191039,0.029919,-56.401848,0.004119,0.000000
6.260000,0.881409,-56.357365,0.001815,0.000134,0.003399,3.920702,0.199730,0.033995,-56.357365,0.004536,0.000000
6.510000,0.932053,-56.401848,0.001811,0.000150,0.003798,4.145977,0.211206,0.037984,-56.401848,0.004952,0.000000
6.760000,0.922371,-56.401848,0.001845,0.000164,0.004163,4.102911,0.209012,0.041626,-56.401848,0.005368,0.000000
7.010000,0.953278,-56.446327,0.001841,0.000178,0.004527,4.240390,0.216016,0.045269,-56.446327,0.005784,0.000000
7.260000,0.981949,-56.446327,0.001880,0.000197,0.005013,4.367927,0.222513,0.050125,-56.446327,0.006201,0.000000
7.510000,1.006523,-56.401848,0.001880,0.000216,0.005481,4.477239,0.228081,0.054808,-56.401848,0.006626,0.000000
7.760000,1.042274,-56.446327,0.001888,0.000230,0.005854,4.636269,0.236183,0.058537,-56.446327,0.007042,0.000000
8.010000,1.085838,-56.490807,0.001932,0.000250,0.006348,4.830050,0.246054,0.063480,-56.490807,0.007458,0.000000
8.260000,1.116371,-56.446327,0.001953,0.000263,0.006669,4.965867,0.252973,0.066689,-56.446327,0.007874,0.000000
8.510000,1.168503,-56.490807,0.001957,0.000280,0.007111,5.197760,0.264787,0.071112,-56.490807,0.008291,0.000000
8.760000,1.183029,-56.535290,0.001966,0.000296,0.007519,5.262377,0.268078,0.075188,-56.535290,0.008707,0.000000
9.010000,1.209839,-56.490807,0.001988,0.000317,0.008039,5.381632,0.274153,0.080391,-56.490807,0.009123,0.000000
9.260000,1.231812,-56.490807,0.002009,0.000330,0.008386,5.479372,0.279132,0.083860,-56.490807,0.009539,0.000000
9.510000,1.257133,-56.535290,0.002035,0.000347,0.008802,5.592009,0.284871,0.088023,-56.535290,0.009956,0.000000
9.760000,1.272774,-56.579769,0.002009,0.000357,0.009071,5.661581,0.288415,0.090712,-56.579769,0.010372,0.000000
10.010000,1.343521,-56.579769,0.002044,0.000377,0.009574,5.976280,0.304446,0.095742,-56.579769,0.010788,0.000000
10.260000,1.374054,-56.624252,0.002078,0.000392,0.009947,6.112097,0.311365,0.099471,-56.624252,0.011205,0.000000
10.510000,1.430283,-56.535290,0.002087,0.000410,0.010415,6.362215,0.324107,0.104154,-56.535290,0.011621,0.000000
10.760000,1.474220,-56.579769,0.002104,0.000426,0.010814,6.557659,0.334063,0.108143,-56.579769,0.012037,0.000000
11.010000,1.497681,-56.668732,0.002126,0.000442,0.011222,6.662016,0.339379,0.112218,-56.668732,0.012453,0.000000
11.260000,1.527100,-56.579769,0.002143,0.000459,0.011655,6.792878,0.346046,0.116555,-56.579769,0.012870,0.000000
11.510000,1.538269,-56.624252,0.002147,0.000476,0.012080,6.842563,0.348577,0.120804,-56.624252,0.013286,0.000000
11.760000,1.594124,-56.668732,0.002151,0.000488,0.012401,7.091017,0.361234,0.124013,-56.668732,0.013702,0.000000
12.010000,1.670837,-56.624252,0.002216,0.000515,0.013069,7.432256,0.378617,0.130691,-56.624252,0.014118,0.000000
12.260000,1.693924,-56.668732,0.002207,0.000527,0.013390,7.534950,0.383849,0.133899,-56.668732,0.014535,0.000000
12.510000,1.699883,-56.668732,0.002212,0.000533,0.013529,7.561455,0.385199,0.135287,-56.668732,0.014960,0.000000
12.760000,1.800797,-56.713211,0.002233,0.000566,0.014370,8.010343,0.408066,0.143699,-56.713211,0.015376,0.000000
13.010000,1.829842,-56.713211,0.002259,0.000581,0.014751,8.139542,0.414648,0.147514,-56.713211,0.015792,0.000000
13.260000,1.856277,-56.713211,0.002276,0.000599,0.015202,8.257134,0.420639,0.152024,-56.713211,0.016208,0.000000
13.510000,1.883461,-56.713211,0.002294,0.000612,0.015541,8.378053,0.426798,0.155407,-56.713211,0.016625,0.000000
13.760000,1.924423,-56.757694,0.002307,0.000629,0.015983,8.560262,0.436081,0.159829,-56.757694,0.017041,0.000000
14.010000,1.973206,-56.757694,0.002315,0.000644,0.016356,8.777257,0.447135,0.163559,-56.757694,0.017457,0.000000
14.260000,1.989212,-56.668732,0.002337,0.000657,0.016694,8.848457,0.450762,0.166940,-56.668732,0.017874,0.000000
14.510000,2.033157,-56.713211,0.002350,0.000670,0.017006,9.043936,0.460720,0.170063,-56.713211,0.018290,0.000000
14.760000,2.119919,-56.802174,0.002380,0.000696,0.017683,9.429870,0.480380,0.176827,-56.802174,0.018706,0.000000
15.010001,2.134811,-56.757694,0.002393,0.000709,0.018004,9.496116,0.483755,0.180036,-56.757694,0.019122,0.000000
15.260001,2.175774,-56.846657,0.002397,0.000728,0.018481,9.678325,0.493037,0.184805,-56.846657,0.019539,0.000000
15.510001,2.172050,-56.846657,0.002402,0.000736,0.018697,9.661763,0.492194,0.186974,-56.846657,0.019955,0.000000
15.760001,2.266632,-56.846657,0.002449,0.000757,0.019226,10.082483,0.513626,0.192263,-56.846657,0.020371,0.000000
16.010000,2.302750,-56.846657,0.002462,0.000775,0.019677,10.243142,0.521811,0.196773,-56.846657,0.020787,0.000000
16.260000,2.345573,-56.802174,0.002483,0.000790,0.020068,10.433632,0.531515,0.200676,-56.802174,0.021204,0.000000
16.510000,2.389145,-56.846657,0.002492,0.000804,0.020432,10.627447,0.541388,0.204318,-56.846657,0.021620,0.000000
16.760000,2.416695,-56.935616,0.002509,0.000824,0.020917,10.749994,0.547631,0.209174,-56.935616,0.022036,0.000000
17.010000,2.454308,-56.846657,0.002522,0.000841,0.021360,10.917305,0.556154,0.213598,-56.846657,0.022452,0.000000
17.260000,2.450211,-56.891136,0.002544,0.000852,0.021646,10.899081,0.555226,0.216459,-56.891136,0.022869,0.000000
17.510000,2.475906,-56.935616,0.002557,0.000863,0.021932,11.013382,0.561048,0.219321,-56.935616,0.023285,0.000000
17.760000,2.527664,-56.891136,0.002574,0.000885,0.022478,11.243612,0.572777,0.224785,-56.891136,0.023710,0.000000
18.010000,2.631554,-56.980099,0.002596,0.000905,0.022990,11.705735,0.596319,0.229901,-56.980099,0.024126,0.000000
18.260000,2.656876,-56.935616,0.002621,0.000917,0.023302,11.818373,0.602057,0.233023,-56.935616,0.024542,0.000000
18.510000,2.675125,-56.980099,0.002634,0.000935,0.023745,11.899550,0.606192,0.237446,-56.980099,0.024959,0.000000
18.760000,2.752205,-57.024578,0.002660,0.000956,0.024291,12.242419,0.623659,0.242910,-57.024578,0.025375,0.000000
19.010000,2.760399,-57.024578,0.002647,0.000971,0.024672,12.278868,0.625515,0.246725,-57.024578,0.025791,0.000000
19.260000,2.804337,-57.024578,0.002682,0.000986,0.025037,12.474312,0.635472,0.250368,-57.024578,0.026208,0.000000
19.510000,2.814392,-57.024578,0.002677,0.001000,0.025392,12.519041,0.637750,0.253923,-57.024578,0.026624,0.000000
19.760000,2.879929,-57.024578,0.002703,0.001014,0.025757,12.810562,0.652601,0.257566,-57.024578,0.027040,0.000000
20.010000,2.955894,-57.069061,0.002725,0.001033,0.026242,13.148476,0.669815,0.262422,-57.069061,0.027456,0.000000
20.260000,3.000206,-57.113541,0.002751,0.001053,0.026754,13.345583,0.679856,0.267539,-57.113541,0.027873,0.000000
20.510000,3.016220,-57.113541,0.002759,0.001065,0.027057,13.416817,0.683485,0.270574,-57.113541,0.028289,0.000000
20.760000,3.071701,-57.113541,0.002772,0.001085,0.027569,13.663609,0.696057,0.275691,-57.113541,0.028705,0.000000
21.010000,3.088455,-57.113541,0.002772,0.001101,0.027959,13.738135,0.699854,0.279593,-57.113541,0.029121,0.000000
21.260000,3.088089,-57.113541,0.002802,0.001111,0.028228,13.736506,0.699771,0.282281,-57.113541,0.029538,0.000000
21.510000,3.208359,-57.202503,0.002846,0.001134,0.028792,14.271493,0.727024,0.287919,-57.202503,0.029954,0.000000
21.760000,3.281723,-57.113541,0.002846,0.001156,0.029356,14.597833,0.743649,0.293555,-57.113541,0.030370,0.000000
22.010000,3.235916,-57.113541,0.002863,0.001160,0.029460,14.394073,0.733269,0.294596,-57.113541,0.030786,0.000000
22.260000,3.180809,-57.113541,0.002859,0.001160,0.029468,14.148945,0.720782,0.294682,-57.113541,0.031203,0.000000
22.510000,3.334221,-57.158024,0.002884,0.001197,0.030405,14.831355,0.755545,0.304049,-57.158024,0.031619,0.000000
22.760000,3.426575,-57.202503,0.002897,0.001217,0.030899,15.242166,0.776473,0.308992,-57.202503,0.032044,0.000000
23.010000,3.418007,-57.291466,0.002936,0.001232,0.031298,15.204054,0.774531,0.312981,-57.291466,0.032460,0.000000
23.260000,3.432159,-57.202503,0.002940,0.001244,0.031602,15.267008,0.777738,0.316017,-57.202503,0.032876,0.000000
23.510000,3.547592,-57.246983,0.002945,0.001266,0.032157,15.780478,0.803896,0.321567,-57.246983,0.033293,0.000000
23.760000,3.601585,-57.291466,0.002971,0.001281,0.032547,16.020653,0.816131,0.325470,-57.291466,0.033709,0.000000
24.010000,3.646645,-57.202503,0.002988,0.001298,0.032963,16.221085,0.826342,0.329632,-57.202503,0.034125,0.000000
24.260000,3.691704,-57.246983,0.003005,0.001318,0.033484,16.421518,0.836552,0.334835,-57.246983,0.034542,0.000000
24.510000,3.756493,-57.335945,0.003035,0.001335,0.033917,16.709713,0.851233,0.339172,-57.335945,0.034958,0.000000
24.760000,3.751282,-57.291466,0.003027,0.001345,0.034160,16.686535,0.850053,0.341600,-57.291466,0.035374,0.000000
25.010002,3.754631,-57.335945,0.003061,0.001362,0.034594,16.701433,0.850812,0.345936,-57.335945,0.035790,0.000000
25.260002,3.759476,-57.335945,0.003053,0.001374,0.034888,16.722982,0.851909,0.348884,-57.335945,0.036207,0.000000
25.510002,3.859268,-57.335945,0.003087,0.001389,0.035270,17.166882,0.874523,0.352700,-57.335945,0.036623,0.000000
25.760002,4.011940,-57.335945,0.003091,0.001414,0.035903,17.846001,0.909119,0.359031,-57.335945,0.037039,0.000000
26.010002,3.969490,-57.335945,0.003104,0.001418,0.036025,17.657173,0.899499,0.360245,-57.335945,0.037455,0.000000
26.260002,4.087532,-57.335945,0.003143,0.001443,0.036649,18.182251,0.926248,0.366489,-57.335945,0.037872,0.000000
26.510002,4.143021,-57.380428,0.003182,0.001463,0.037161,18.429075,0.938822,0.371606,-57.380428,0.038288,0.000000
26.760002,4.157166,-57.380428,0.003165,0.001481,0.037629,18.491997,0.942027,0.376289,-57.380428,0.038704,0.000000
27.010002,4.188446,-57.424908,0.003169,0.001497,0.038028,18.631138,0.949115,0.380278,-57.424908,0.039120,0.000000
27.260002,4.188072,-57.424908,0.003208,0.001508,0.038297,18.629475,0.949031,0.382966,-57.424908,0.039537,0.000000
27.510002,4.300903,-57.469387,0.003229,0.001529,0.038834,19.131374,0.974599,0.388343,-57.469387,0.039953,0.000000
27.760002,4.373886,-57.513870,0.003238,0.001544,0.039216,19.456017,0.991137,0.392159,-57.513870,0.040378,0.000000
28.010002,4.436073,-57.380428,0.003260,0.001561,0.039641,19.732639,1.005229,0.396408,-57.380428,0.040794,0.000000
28.260002,4.484108,-57.424908,0.003281,0.001576,0.040040,19.946308,1.016113,0.400397,-57.424908,0.041211,0.000000
28.510002,4.532890,-57.513870,0.003272,0.001593,0.040465,20.163303,1.027168,0.404647,-57.513870,0.041627,0.000000
28.760002,4.576828,-57.513870,0.003281,0.001609,0.040881,20.358747,1.037124,0.408809,-57.513870,0.042043,0.000000
29.010002,4.632317,-57.513870,0.003333,0.001625,0.041263,20.605574,1.049698,0.412625,-57.513870,0.042459,0.000000
29.260002,4.693382,-57.558350,0.003337,0.001644,0.041748,20.877207,1.063536,0.417482,-57.558350,0.042876,0.000000
29.510002,4.752594,-57.602833,0.003376,0.001659,0.042138,21.140594,1.076953,0.421385,-57.602833,0.043292,0.000000
29.760002,4.840843,-57.558350,0.003350,0.001675,0.042537,21.533146,1.096951,0.425374,-57.558350,0.043708,0.000000
30.010002,4.887016,-57.602833,0.003402,0.001691,0.042954,21.738535,1.107414,0.429536,-57.602833,0.044124,0.000000
30.260002,4.946228,-57.513870,0.003393,0.001707,0.043370,22.001921,1.120831,0.433699,-57.513870,0.044541,0.000000
30.510002,5.005058,-57.558350,0.003441,0.001727,0.043873,22.263611,1.134162,0.438729,-57.558350,0.044957,0.000000
30.760002,5.054214,-57.602833,0.003454,0.001741,0.044220,22.482269,1.145301,0.442198,-57.602833,0.045373,0.000000
31.010002,5.022560,-57.647312,0.003449,0.001753,0.044523,22.341463,1.138128,0.445233,-57.647312,0.045789,0.000000
31.260002,5.199066,-57.602833,0.003497,0.001773,0.045035,23.126602,1.178125,0.450350,-57.602833,0.046206,0.000000
31.510002,5.238907,-57.602833,0.003518,0.001788,0.045417,23.303822,1.187153,0.454166,-57.602833,0.046622,0.000000
31.760002,5.334610,-57.691795,0.003514,0.001805,0.045850,23.729530,1.208840,0.458502,-57.691795,0.047038,0.000000
32.010002,5.355461,-57.647312,0.003548,0.001819,0.046206,23.822281,1.213565,0.462057,-57.647312,0.047455,0.000000
32.260002,5.483185,-57.647312,0.003544,0.001839,0.046717,24.390425,1.242507,0.467174,-57.647312,0.047871,0.000000
32.510002,5.495102,-57.691795,0.003557,0.001856,0.047142,24.443434,1.245208,0.471424,-57.691795,0.048287,0.000000
32.760002,5.535690,-57.691795,0.003570,0.001872,0.047541,24.623980,1.254405,0.475413,-57.691795,0.048703,0.000000
33.010002,5.620590,-57.736275,0.003574,0.001887,0.047923,25.001635,1.273644,0.479228,-57.736275,0.049128,0.000000
33.260002,5.739006,-57.736275,0.003626,0.001909,0.048495,25.528374,1.300477,0.484952,-57.736275,0.049545,0.000000
33.510002,5.741982,-57.691795,0.003635,0.001920,0.048764,25.541609,1.301152,0.487640,-57.691795,0.049961,0.000000
33.760002,5.739754,-57.736275,0.003635,0.001929,0.049007,25.531700,1.300647,0.490069,-57.736275,0.050377,0.000000
34.010002,5.985146,-57.736275,0.003682,0.001961,0.049813,26.623257,1.356253,0.498134,-57.736275,0.050793,0.000000
34.260002,6.025360,-57.736275,0.003682,0.001977,0.050221,26.802141,1.365366,0.502210,-57.736275,0.051210,0.000000
34.510002,6.083076,-57.736275,0.003699,0.001994,0.050646,27.058876,1.378445,0.506460,-57.736275,0.051626,0.000000
34.760002,6.090523,-57.825237,0.003725,0.002007,0.050967,27.091999,1.380132,0.509668,-57.825237,0.052042,0.000000
35.010002,6.194046,-57.825237,0.003734,0.002024,0.051400,27.552492,1.403591,0.514004,-57.825237,0.052458,0.000000
35.260002,6.281555,-57.780754,0.003729,0.002040,0.051808,27.941753,1.423421,0.518080,-57.780754,0.052875,0.000000
35.510002,6.209312,-57.825237,0.003760,0.002044,0.051929,27.620401,1.407050,0.519294,-57.825237,0.053291,0.000000
35.760002,6.286766,-57.869717,0.003742,0.002059,0.052294,27.964931,1.424602,0.522937,-57.869717,0.053707,0.000000
36.010002,6.598068,-57.914200,0.003803,0.002092,0.053135,29.349674,1.495144,0.531349,-57.914200,0.054124,0.000000
36.260002,6.626740,-57.869717,0.003811,0.002106,0.053499,29.477209,1.501641,0.534991,-57.869717,0.054540,0.000000
36.510002,6.689301,-57.869717,0.003842,0.002123,0.053915,29.755495,1.515817,0.539154,-57.869717,0.054956,0.000000
36.760002,6.693024,-57.869717,0.003833,0.002133,0.054167,29.772057,1.516661,0.541669,-57.869717,0.055372,0.000000
37.010002,6.885170,-57.869717,0.003880,0.002155,0.054748,30.626766,1.560202,0.547479,-57.869717,0.055789,0.000000
37.260002,6.696373,-57.958679,0.003876,0.002155,0.054748,29.786955,1.517420,0.547479,-57.958679,0.056205,0.000000
37.510002,7.030762,-57.958679,0.003902,0.002183,0.055459,31.274389,1.593193,0.554590,-57.958679,0.056621,0.000000
37.760002,7.082527,-57.914200,0.003915,0.002201,0.055910,31.504654,1.604924,0.559100,-57.914200,0.057037,0.000000
38.010002,7.146942,-57.914200,0.003928,0.002213,0.056222,31.791187,1.619520,0.562222,-57.914200,0.057462,0.000000
38.260002,7.280258,-57.914200,0.003941,0.002235,0.056777,32.384205,1.649730,0.567772,-57.914200,0.057879,0.000000
38.510002,7.323074,-57.914200,0.003954,0.002248,0.057107,32.574661,1.659432,0.571068,-57.914200,0.058295,0.000000
38.760002,7.289940,-57.958679,0.003980,0.002259,0.057376,32.427273,1.651924,0.573756,-57.958679,0.058711,0.000000
39.010002,7.580391,-58.003159,0.003992,0.002282,0.057965,33.719261,1.717741,0.579653,-58.003159,0.059127,0.000000
39.260002,7.684654,-58.003159,0.004023,0.002302,0.058460,34.183048,1.741368,0.584597,-58.003159,0.059544,0.000000
39.510002,7.764709,-58.047642,0.004036,0.002315,0.058789,34.539154,1.759508,0.587892,-58.047642,0.059960,0.000000
39.760002,7.854828,-58.092121,0.004036,0.002332,0.059240,34.940018,1.779929,0.592401,-58.092121,0.060376,0.000000
40.010002,7.976219,-58.003159,0.004066,0.002348,0.059630,35.479996,1.807437,0.596304,-58.003159,0.060793,0.000000
40.260002,8.056648,-58.003159,0.004096,0.002366,0.060107,35.837761,1.825662,0.601074,-58.003159,0.061209,0.000000
40.510002,8.101707,-58.092121,0.004109,0.002381,0.060489,36.038193,1.835873,0.604890,-58.092121,0.061625,0.000000
40.760002,8.063728,-58.092121,0.004105,0.002392,0.060749,35.869255,1.827267,0.607491,-58.092121,0.062041,0.000000
41.010002,8.309120,-58.092121,0.004130,0.002410,0.061226,36.960812,1.882874,0.612261,-58.092121,0.062458,0.000000
41.260002,8.537010,-58.092121,0.004143,0.002430,0.061729,37.974518,1.934514,0.617291,-58.092121,0.062874,0.000000
41.510002,8.613724,-58.092121,0.004186,0.002447,0.062154,38.315758,1.951898,0.621540,-58.092121,0.063290,0.000000
41.760002,8.694153,-58.092121,0.004186,0.002464,0.062579,38.673523,1.970123,0.625790,-58.092121,0.063706,0.000000
42.010002,8.844963,-58.136604,0.004204,0.002479,0.062961,39.344360,2.004297,0.629606,-58.136604,0.064123,0.000000
42.260002,8.951462,-58.181084,0.004225,0.002496,0.063403,39.818092,2.028430,0.634029,-58.181084,0.064539,0.000000
42.510002,8.996895,-58.092121,0.004217,0.002509,0.063741,40.020187,2.038725,0.637410,-58.092121,0.064955,0.000000
42.760002,9.153290,-58.092121,0.004255,0.002528,0.064209,40.715866,2.074165,0.642093,-58.092121,0.065371,0.000000
43.010002,9.234467,-58.181084,0.004243,0.002540,0.064522,41.076958,2.092560,0.645216,-58.181084,0.065796,0.000000
43.260002,9.403526,-58.225563,0.004281,0.002557,0.064955,41.828976,2.130869,0.649551,-58.225563,0.066213,0.000000
43.510002,9.243774,-58.181084,0.004277,0.002573,0.065345,41.118362,2.094669,0.653455,-58.181084,0.066629,0.000000
43.760002,9.627319,-58.225563,0.004329,0.002589,0.065770,42.824455,2.181582,0.657704,-58.225563,0.067045,0.000000
44.010002,9.930801,-58.225563,0.004307,0.002614,0.066386,44.174412,2.250352,0.663861,-58.225563,0.067461,0.000000
44.260002,9.912926,-58.181084,0.004337,0.002627,0.066716,44.094894,2.246301,0.667156,-58.181084,0.067878,0.000000
44.510002,9.870102,-58.225563,0.004363,0.002636,0.066958,43.904408,2.236597,0.669585,-58.225563,0.068294,0.000000
44.760002,10.165024,-58.270046,0.004368,0.002655,0.067444,45.216286,2.303427,0.674441,-58.270046,0.068710,0.000000
45.010002,10.292747,-58.270046,0.004368,0.002671,0.067843,45.784428,2.332370,0.678430,-58.270046,0.069127,0.000000
45.260002,10.268173,-58.225563,0.004398,0.002681,0.068103,45.675117,2.326801,0.681032,-58.225563,0.069543,0.000000
45.510002,10.688210,-58.270046,0.004419,0.002711,0.068849,47.543530,2.421983,0.688490,-58.270046,0.069959,0.000000
45.760002,10.902321,-58.270046,0.004441,0.002729,0.069317,48.495945,2.470501,0.693173,-58.270046,0.070375,0.000000
46.010002,10.841629,-58.270046,0.004462,0.002738,0.069543,48.225975,2.456748,0.695428,-58.270046,0.070792,0.000000
46.260002,11.069519,-58.359009,0.004493,0.002758,0.070063,49.239681,2.508389,0.700631,-58.359009,0.071208,0.000000
46.510002,11.084412,-58.314526,0.004488,0.002770,0.070358,49.305927,2.511764,0.703580,-58.314526,0.071624,0.000000
46.760002,11.352150,-58.314526,0.004506,0.002787,0.070792,50.496883,2.572434,0.707916,-58.314526,0.072040,0.000000
47.010002,11.577065,-58.447971,0.004518,0.002808,0.071321,51.497356,2.623400,0.713206,-58.447971,0.072457,0.000000
47.260002,11.725639,-58.447971,0.004531,0.002822,0.071685,52.158249,2.657068,0.716849,-58.447971,0.072873,0.000000
47.510002,11.513756,-58.403488,0.004531,0.002835,0.071997,51.215744,2.609054,0.719970,-58.403488,0.073289,0.000000
47.760002,12.255524,-58.359009,0.004562,0.002861,0.072673,54.515293,2.777141,0.726735,-58.359009,0.073705,0.000000
48.010002,12.311005,-58.403488,0.004579,0.002878,0.073098,54.762085,2.789714,0.730984,-58.403488,0.074122,0.000000
48.260002,12.398888,-58.403488,0.004583,0.002892,0.073445,55.153008,2.809628,0.734453,-58.403488,0.074547,0.000000
48.510002,12.540390,-58.447971,0.004605,0.002906,0.073818,55.782440,2.841693,0.738182,-58.447971,0.074963,0.000000
48.760002,12.718758,-58.403488,0.004635,0.002920,0.074174,56.575859,2.882112,0.741738,-58.403488,0.075379,0.000000
49.010002,12.937714,-58.447971,0.004648,0.002938,0.074625,57.549824,2.931728,0.746247,-58.447971,0.075795,0.000000
49.260002,13.124268,-58.447971,0.004652,0.002955,0.075067,58.379658,2.974001,0.750670,-58.447971,0.076212,0.000000
49.510002,13.251617,-58.536930,0.004643,0.002970,0.075449,58.946136,3.002860,0.754486,-58.536930,0.076628,0.000000
49.760002,13.380836,-58.536930,0.004691,0.002982,0.075735,59.520935,3.032141,0.757348,-58.536930,0.077044,0.000000
50.010002,13.740173,-58.492451,0.004704,0.003003,0.076272,61.119343,3.113568,0.762724,-58.492451,0.077461,0.000000
50.260002,13.982216,-58.492451,0.004738,0.003022,0.076758,62.196003,3.168415,0.767581,-58.492451,0.077877,0.000000
50.510002,14.092438,-58.492451,0.004738,0.003036,0.077122,62.686295,3.193392,0.771223,-58.492451,0.078293,0.000000
50.760002,14.353470,-58.536930,0.004738,0.003051,0.077495,63.847424,3.252543,0.774953,-58.536930,0.078709,0.000000
51.010002,14.710579,-58.581413,0.004786,0.003071,0.078007,65.435921,3.333465,0.780069,-58.581413,0.079126,0.000000
51.260002,14.754143,-58.581413,0.004773,0.003084,0.078336,65.629707,3.343336,0.783364,-58.581413,0.079542,0.000000
51.510002,15.109016,-58.536930,0.004803,0.003104,0.078848,67.208260,3.423752,0.788482,-58.536930,0.079958,0.000000
51.760002,15.369675,-58.536930,0.004820,0.003120,0.079256,68.367729,3.482818,0.792557,-58.536930,0.080374,0.000000
52.010002,15.284775,-58.581413,0.004842,0.003134,0.079603,67.990074,3.463580,0.796026,-58.581413,0.080791,0.000000
52.260002,15.612831,-58.581413,0.004846,0.003149,0.079993,69.449341,3.537918,0.799929,-58.581413,0.081207,0.000000
52.510002,15.723053,-58.625893,0.004863,0.003163,0.080348,69.939636,3.562895,0.803484,-58.625893,0.081623,0.000000
52.760002,16.245865,-58.581413,0.004859,0.003184,0.080877,72.265213,3.681365,0.808774,-58.581413,0.082039,0.000000
53.010002,16.556801,-58.625893,0.004881,0.003201,0.081311,73.648331,3.751825,0.813111,-58.625893,0.082456,0.000000
53.260002,16.545258,-58.581413,0.004902,0.003210,0.081528,73.596985,3.749209,0.815279,-58.581413,0.082881,0.000000
53.510002,16.718781,-58.670376,0.004928,0.003226,0.081935,74.368851,3.788530,0.819354,-58.670376,0.083297,0.000000
53.760002,17.475815,-58.670376,0.004954,0.003251,0.082586,77.736305,3.960076,0.825858,-58.670376,0.083713,0.000000
54.010002,17.587898,-58.759335,0.004954,0.003267,0.082976,78.234879,3.985475,0.829762,-58.759335,0.084130,0.000000
54.260002,17.705566,-58.714855,0.004967,0.003281,0.083349,78.758293,4.012139,0.833491,-58.714855,0.084546,0.000000
54.510002,18.333755,-58.714855,0.004984,0.003303,0.083895,81.552620,4.154489,0.838954,-58.714855,0.084962,0.000000
54.760002,18.520317,-58.714855,0.004980,0.003318,0.084277,82.382484,4.196764,0.842769,-58.714855,0.085378,0.000000
55.010002,18.502441,-58.759335,0.005006,0.003328,0.084528,82.302971,4.192713,0.845284,-58.759335,0.085795,0.000000
55.260002,19.332092,-58.759335,0.005040,0.003354,0.085196,85.993439,4.380715,0.851962,-58.759335,0.086211,0.000000
55.510002,19.467262,-58.759335,0.005049,0.003370,0.085604,86.594704,4.411345,0.856038,-58.759335,0.086627,0.000000
55.760002,19.680260,-58.759335,0.005053,0.003387,0.086037,87.542168,4.459611,0.860374,-58.759335,0.087043,0.000000
56.010002,19.828087,-58.803818,0.005075,0.003400,0.086367,88.199738,4.493109,0.863670,-58.803818,0.087460,0.000000
56.260002,20.252968,-58.759335,0.005101,0.003419,0.086835,90.089699,4.589388,0.868352,-58.759335,0.087876,0.000000
56.510002,20.483841,-58.803818,0.005088,0.003434,0.087217,91.116676,4.641705,0.872168,-58.803818,0.088292,0.000000
56.760002,20.560173,-58.848297,0.005122,0.003443,0.087451,91.456215,4.659002,0.874510,-58.848297,0.088708,0.000000
57.010002,20.836105,-58.803818,0.005118,0.003459,0.087859,92.683624,4.721529,0.878586,-58.803818,0.089125,0.000000
57.260002,21.882095,-58.848297,0.005139,0.003485,0.088526,97.336418,4.958553,0.885263,-58.848297,0.089541,0.000000
57.510002,21.961411,-58.848297,0.005165,0.003499,0.088865,97.689232,4.976527,0.888646,-58.848297,0.089957,0.000000
57.760002,22.265640,-58.892780,0.005174,0.003516,0.089316,99.042511,5.045466,0.893156,-58.892780,0.090374,0.000000
58.010002,22.630562,-58.848297,0.005195,0.003531,0.089688,100.665764,5.128159,0.896885,-58.848297,0.090790,0.000000
58.260002,22.936279,-58.892780,0.005204,0.003548,0.090122,102.025665,5.197435,0.901220,-58.892780,0.091215,0.000000
58.510002,22.897186,-58.892780,0.005208,0.003554,0.090269,101.851768,5.188576,0.902695,-58.892780,0.091631,0.000000
58.760002,23.611397,-58.892780,0.005243,0.003580,0.090920,105.028740,5.350419,0.909199,-58.892780,0.092047,0.000000
59.010002,24.186340,-58.937260,0.005247,0.003596,0.091336,107.586212,5.480703,0.913361,-58.937260,0.092464,0.000000
59.260002,24.359116,-58.892780,0.005264,0.003610,0.091683,108.354759,5.519855,0.916830,-58.892780,0.092880,0.000000
59.510002,24.962730,-58.937260,0.005269,0.003628,0.092151,111.039772,5.656635,0.921514,-58.937260,0.093296,0.000000
59.760002,25.458359,-58.981743,0.005282,0.003646,0.092602,113.244438,5.768947,0.926023,-58.981743,0.093712,0.000000
60.010002,25.331009,-58.937260,0.005312,0.003654,0.092810,112.677956,5.740088,0.928105,-58.937260,0.094129,0.000000
60.260002,25.848984,-58.937260,0.005307,0.003670,0.093218,114.982025,5.857463,0.932181,-58.937260,0.094545,0.000000
60.510002,26.757942,-59.026222,0.005329,0.003696,0.093869,119.025269,6.063436,0.938685,-59.026222,0.094961,0.000000
60.760002,27.106110,-59.026222,0.005364,0.003710,0.094224,120.573997,6.142332,0.942240,-59.026222,0.095377,0.000000
61.010002,27.477737,-59.026222,0.005346,0.003726,0.094649,122.227081,6.226544,0.946490,-59.026222,0.095794,0.000000
61.260002,27.893677,-58.981743,0.005368,0.003743,0.095065,124.077271,6.320797,0.950652,-58.981743,0.096210,0.000000
61.510002,28.387070,-59.070702,0.005411,0.003756,0.095412,126.271996,6.432602,0.954121,-59.070702,0.096626,0.000000
61.760002,28.947495,-59.115185,0.005398,0.003775,0.095880,128.764893,6.559596,0.958805,-59.115185,0.097043,0.000000
62.010002,28.931480,-59.070702,0.005394,0.003785,0.096149,128.693649,6.555967,0.961493,-59.070702,0.097459,0.000000
62.260002,29.751816,-59.070702,0.005415,0.003807,0.096687,132.342682,6.741858,0.966869,-59.070702,0.097875,0.000000
62.510002,30.333832,-59.115185,0.005433,0.003824,0.097121,134.931625,6.873744,0.971206,-59.115185,0.098291,0.000000
62.760002,30.902451,-59.115185,0.005454,0.003840,0.097546,137.460968,7.002595,0.975455,-59.115185,0.098708,0.000000
63.010002,31.318016,-59.115185,0.005463,0.003855,0.097910,139.309494,7.096764,0.979097,-59.115185,0.099124,0.000000
63.260002,31.907104,-59.159664,0.005454,0.003875,0.098413,141.929886,7.230253,0.984128,-59.159664,0.099540,0.000000
63.510002,32.306290,-59.115185,0.005497,0.003887,0.098725,143.705551,7.320710,0.987249,-59.115185,0.099965,0.000000
63.760002,32.750534,-59.204147,0.005506,0.003904,0.099159,145.681656,7.421377,0.991586,-59.204147,0.100381,0.000000
64.010002,33.363831,-59.248627,0.005523,0.003922,0.099610,148.409729,7.560352,0.996095,-59.248627,0.100798,0.000000
64.260002,33.698593,-59.159664,0.005527,0.003936,0.099965,149.898834,7.636210,0.999650,-59.159664,0.101214,0.000000
64.510002,34.802673,-59.204147,0.005553,0.003954,0.100433,154.810028,7.886398,1.004333,-59.204147,0.101630,0.000000
64.760002,34.605316,-59.204147,0.005558,0.003960,0.100589,153.932129,7.841677,1.005895,-59.204147,0.102046,0.000000
65.010002,35.392883,-59.248627,0.005570,0.003987,0.101275,157.435410,8.020143,1.012746,-59.248627,0.102463,0.000000
65.260002,36.886101,-59.248627,0.005583,0.004008,0.101795,164.077576,8.358510,1.017949,-59.248627,0.102879,0.000000
65.510002,37.268158,-59.248627,0.005592,0.004023,0.102176,165.777039,8.445086,1.021765,-59.248627,0.103295,0.000000
65.760002,37.587646,-59.248627,0.005601,0.004035,0.102480,167.198196,8.517483,1.024800,-59.248627,0.103712,0.000000
66.010002,37.877357,-59.293106,0.005614,0.004046,0.102758,168.486908,8.583132,1.027575,-59.293106,0.104128,0.000000
66.260002,38.840309,-59.337589,0.005622,0.004066,0.103287,172.770325,8.801340,1.032866,-59.337589,0.104544,0.000000
66.510002,39.404457,-59.293106,0.005627,0.004080,0.103625,175.279785,8.929178,1.036247,-59.293106,0.104960,0.000000
66.760002,40.594933,-59.337589,0.005661,0.004105,0.104266,180.575272,9.198943,1.042665,-59.337589,0.105377,0.000000
67.010002,40.864899,-59.337589,0.005652,0.004115,0.104509,181.776154,9.260118,1.045094,-59.337589,0.105793,0.000000
67.260002,41.936584,-59.337589,0.005661,0.004136,0.105064,186.543243,9.502966,1.050643,-59.337589,0.106209,0.000000
67.510002,41.940681,-59.337589,0.005691,0.004149,0.105394,186.561462,9.503894,1.053939,-59.337589,0.106625,0.000000
67.760002,43.000458,-59.382069,0.005708,0.004167,0.105836,191.275589,9.744043,1.058362,-59.382069,0.107042,0.000000
68.010002,43.409317,-59.382069,0.005708,0.004178,0.106131,193.094284,9.836692,1.061310,-59.382069,0.107458,0.000000
68.260002,44.186836,-59.382069,0.005713,0.004195,0.106547,196.552872,10.012879,1.065473,-59.382069,0.107874,0.000000
68.510002,44.425896,-59.426552,0.005721,0.004210,0.106929,197.616257,10.067052,1.069289,-59.426552,0.108299,0.000000
68.760002,45.638718,-59.471031,0.005747,0.004225,0.107310,203.011154,10.341882,1.073105,-59.471031,0.108715,0.000000
69.010002,47.407860,-59.426552,0.005760,0.004255,0.108074,210.880692,10.742775,1.080736,-59.426552,0.109132,0.000000
69.260002,47.964554,-59.426552,0.005760,0.004267,0.108394,213.356995,10.868923,1.083945,-59.426552,0.109548,0.000000
69.510002,48.496674,-59.471031,0.005790,0.004284,0.108802,215.723984,10.989504,1.088021,-59.471031,0.109964,0.000000
69.760002,49.174393,-59.426552,0.005799,0.004300,0.109227,218.738617,11.143077,1.092270,-59.426552,0.110380,0.000000
70.010002,49.718803,-59.471031,0.005808,0.004312,0.109522,221.160278,11.266441,1.095219,-59.471031,0.110797,0.000000
70.260002,50.329117,-59.515514,0.005812,0.004328,0.109938,223.875092,11.404741,1.099381,-59.515514,0.111213,0.000000
70.510002,51.442886,-59.515514,0.005816,0.004347,0.110406,228.829391,11.657125,1.104064,-59.515514,0.111629,0.000000
70.760002,52.103104,-59.515514,0.005816,0.004359,0.110727,231.766174,11.806732,1.107273,-59.515514,0.112045,0.000000
71.010002,52.768532,-59.471031,0.005842,0.004374,0.111100,234.726151,11.957520,1.111002,-59.471031,0.112462,0.000000
71.260002,53.929962,-59.559994,0.005851,0.004396,0.111664,239.892456,12.220704,1.116640,-59.559994,0.112878,0.000000
71.510002,54.886955,-59.559994,0.005872,0.004414,0.112115,244.149368,12.437562,1.121149,-59.559994,0.113294,0.000000
71.760002,55.445145,-59.604473,0.005890,0.004424,0.112375,246.632324,12.564049,1.123750,-59.604473,0.113711,0.000000
72.010002,56.403633,-59.559994,0.005898,0.004443,0.112861,250.895889,12.781246,1.128607,-59.559994,0.114127,0.000000
72.260002,57.332329,-59.604473,0.005885,0.004459,0.113260,255.026932,12.991692,1.132597,-59.604473,0.114543,0.000000
72.510002,58.335495,-59.693436,0.005924,0.004476,0.113693,259.489227,13.219012,1.136932,-59.693436,0.114959,0.000000
72.760002,59.114502,-59.604473,0.005920,0.004491,0.114084,262.954437,13.395538,1.140836,-59.604473,0.115376,0.000000
73.010002,59.983246,-59.604473,0.005933,0.004507,0.114474,266.818817,13.592398,1.144738,-59.604473,0.115792,0.000000
73.260002,61.250801,-59.648956,0.005950,0.004525,0.114942,272.457184,13.879630,1.149420,-59.648956,0.116208,0.000000
73.510002,61.836174,-59.604473,0.005950,0.004541,0.115350,275.061035,14.012278,1.153497,-59.604473,0.116633,0.000000
73.760002,62.561554,-59.693436,0.005959,0.004553,0.115645,278.287689,14.176651,1.156445,-59.693436,0.117049,0.000000
74.010002,64.054398,-59.648956,0.005963,0.004575,0.116199,284.928192,14.514935,1.161995,-59.648956,0.117466,0.000000
74.260002,64.889633,-59.693436,0.005967,0.004590,0.116581,288.643494,14.704201,1.165811,-59.693436,0.117882,0.000000
74.510002,65.889450,-59.693436,0.005993,0.004607,0.117006,293.090912,14.930763,1.170061,-59.693436,0.118298,0.000000
74.760002,66.696747,-59.648956,0.005980,0.004620,0.117353,296.681946,15.113698,1.173529,-59.648956,0.118714,0.000000
75.010002,67.447449,-59.693436,0.005997,0.004624,0.117457,300.021240,15.283811,1.174570,-59.693436,0.117700,0.000000
75.260002,66.845703,-59.782398,0.006015,0.004624,0.117457,297.344543,15.147452,1.174570,-59.782398,0.117700,0.000000
75.510002,66.395508,-59.737919,0.006027,0.004623,0.117422,295.341980,15.045437,1.174223,-59.737919,0.117457,0.000000
75.760002,65.990738,-59.782398,0.006023,0.004622,0.117405,293.541473,14.953715,1.174050,-59.782398,0.117457,0.000000
76.010002,65.615753,-59.826878,0.006027,0.004622,0.117405,291.873444,14.868742,1.174050,-59.826878,0.117457,0.000000
76.260002,65.303329,-59.782398,0.006032,0.004622,0.117396,290.483704,14.797946,1.173963,-59.782398,0.117457,0.000000
76.510002,65.031128,-59.826878,0.006036,0.004622,0.117396,289.272919,14.736264,1.173963,-59.826878,0.117457,0.000000
76.760002,64.785355,-59.782398,0.006040,0.004622,0.117396,288.179657,14.680572,1.173963,-59.782398,0.117457,0.000000
77.010002,64.553741,-59.782398,0.006040,0.004622,0.117388,287.149384,14.628087,1.173877,-59.782398,0.117457,0.000000
77.260002,64.353043,-59.826878,0.006045,0.004622,0.117388,286.256622,14.582607,1.173877,-59.826878,0.117457,0.000000
77.510002,64.147858,-59.915840,0.006045,0.004622,0.117388,285.343933,14.536113,1.173877,-59.915840,0.117457,0.000000
77.760002,63.993332,-59.826878,0.006032,0.004622,0.117388,284.656555,14.501096,1.173877,-59.826878,0.117457,0.000000
78.010002,63.827255,-59.871361,0.006032,0.004622,0.117388,283.917816,14.463463,1.173877,-59.871361,0.117457,0.000000
78.260002,63.689468,-59.871361,0.006045,0.004622,0.117388,283.304901,14.432240,1.173877,-59.871361,0.117457,0.000000
78.510002,63.544250,-59.826878,0.006036,0.004622,0.117388,282.658936,14.399333,1.173877,-59.826878,0.117457,0.000000
78.760002,63.420990,-59.871361,0.006040,0.004622,0.117388,282.110657,14.371402,1.173877,-59.871361,0.117457,0.000000
79.010002,63.298111,-59.915840,0.006053,0.004622,0.117388,281.564056,14.343556,1.173877,-59.915840,0.117457,0.000000
79.260002,63.170013,-59.871361,0.006049,0.004621,0.117379,280.994263,14.314529,1.173790,-59.871361,0.117457,0.000000
79.510002,63.058670,-59.915840,0.006032,0.004621,0.117379,280.498962,14.289299,1.173790,-59.915840,0.117457,0.000000
79.760002,62.960358,-59.960323,0.006045,0.004621,0.117379,280.061646,14.267021,1.173790,-59.960323,0.117457,0.000000
80.010002,62.862801,-60.004803,0.006045,0.004621,0.117379,279.627716,14.244914,1.173790,-60.004803,0.117457,0.000000
80.260002,62.765244,-59.960323,0.006045,0.004621,0.117379,279.193756,14.222808,1.173790,-59.960323,0.117457,0.000000
80.510002,62.684807,-59.960323,0.006045,0.004621,0.117379,278.835937,14.204580,1.173790,-59.960323,0.117457,0.000000
80.760002,62.573097,-60.004803,0.006049,0.004621,0.117379,278.339050,14.179267,1.173790,-60.004803,0.117457,0.000000
81.010002,62.496017,-60.004803,0.006058,0.004621,0.117379,277.996155,14.161799,1.173790,-60.004803,0.117457,0.000000
81.260002,62.419304,-60.049282,0.006066,0.004621,0.117379,277.654938,14.144416,1.173790,-60.049282,0.117457,0.000000
81.510002,62.355629,-60.049282,0.006058,0.004621,0.117379,277.371704,14.129987,1.173790,-60.049282,0.117457,0.000000
81.760002,62.283020,-59.960323,0.006049,0.004621,0.117379,277.048706,14.113534,1.173790,-59.960323,0.117457,0.000000
82.010002,62.210037,-60.049282,0.006049,0.004621,0.117379,276.724060,14.096996,1.173790,-60.049282,0.117457,0.000000
82.260002,62.133698,-60.049282,0.006062,0.004621,0.117379,276.384491,14.079698,1.173790,-60.049282,0.117457,0.000000
82.510002,62.069275,-60.049282,0.006053,0.004621,0.117379,276.097931,14.065099,1.173790,-60.049282,0.117457,0.000000
82.760002,62.011185,-60.093765,0.006075,0.004621,0.117379,275.839539,14.051935,1.173790,-60.093765,0.117457,0.000000
83.010002,61.954956,-60.093765,0.006071,0.004621,0.117379,275.589417,14.039194,1.173790,-60.093765,0.117457,0.000000
83.260002,61.886818,-60.093765,0.006062,0.004621,0.117379,275.286316,14.023753,1.173790,-60.093765,0.117457,0.000000
83.510002,61.831329,-60.138245,0.006045,0.004621,0.117379,275.039490,14.011180,1.173790,-60.138245,0.117457,0.000000
83.760002,61.782921,-60.093765,0.006053,0.004621,0.117379,274.824158,14.000210,1.173790,-60.093765,0.117457,0.000000
84.010002,61.729675,-60.093765,0.006062,0.004621,0.117379,274.587311,13.988144,1.173790,-60.093765,0.117457,0.000000
84.260002,61.684616,-60.138245,0.006075,0.004621,0.117379,274.386871,13.977934,1.173790,-60.138245,0.117457,0.000000
84.510002,61.634346,-60.093765,0.006040,0.004621,0.117379,274.163269,13.966542,1.173790,-60.093765,0.117457,0.000000
84.760002,61.573647,-60.138245,0.006066,0.004621,0.117379,273.893250,13.952787,1.173790,-60.138245,0.117457,0.000000
85.010002,61.529335,-60.182728,0.006058,0.004621,0.117379,273.696136,13.942747,1.173790,-60.182728,0.117457,0.000000
85.260002,61.474968,-60.182728,0.006045,0.004621,0.117379,273.454315,13.930428,1.173790,-60.182728,0.117457,0.000000
85.510002,61.438850,-60.227207,0.006062,0.004621,0.117379,273.293671,13.922242,1.173790,-60.227207,0.117457,0.000000
85.760002,61.415390,-60.227207,0.006066,0.004621,0.117379,273.189301,13.916926,1.173790,-60.227207,0.117457,0.000000
86.010002,61.351341,-60.182728,0.006066,0.004621,0.117379,272.904388,13.902413,1.173790,-60.182728,0.117457,0.000000
86.260002,61.299583,-60.227207,0.006036,0.004621,0.117379,272.674164,13.890684,1.173790,-60.227207,0.117457,0.000000
86.510002,61.269791,-60.227207,0.006049,0.004621,0.117379,272.541626,13.883933,1.173790,-60.227207,0.117457,0.000000
86.760002,61.230324,-60.271690,0.006053,0.004621,0.117379,272.366089,13.874990,1.173790,-60.271690,0.117457,0.000000
87.010002,61.194946,-60.271690,0.006066,0.004621,0.117379,272.208710,13.866973,1.173790,-60.271690,0.117457,0.000000
87.260002,61.143562,-60.271690,0.006066,0.004621,0.117379,271.980164,13.855330,1.173790,-60.271690,0.117457,0.000000
87.510002,61.113022,-60.271690,0.006062,0.004621,0.117379,271.844299,13.848409,1.173790,-60.271690,0.117457,0.000000
87.760002,61.072807,-60.271690,0.006062,0.004621,0.117370,271.665405,13.839296,1.173703,-60.271690,0.117457,0.000000
88.010002,61.040787,-60.316170,0.006049,0.004621,0.117370,271.522980,13.832040,1.173703,-60.316170,0.117457,0.000000
88.260002,61.016579,-60.271690,0.006053,0.004621,0.117370,271.415283,13.826555,1.173703,-60.271690,0.117457,0.000000
88.510002,60.962212,-60.360649,0.006079,0.004621,0.117370,271.173462,13.814235,1.173703,-60.360649,0.117457,0.000000
88.760002,60.936523,-60.360649,0.006066,0.004621,0.117370,271.059204,13.808414,1.173703,-60.360649,0.117457,0.000000
89.010002,60.910828,-60.316170,0.006071,0.004621,0.117370,270.944885,13.802590,1.173703,-60.316170,0.117457,0.000000
89.260002,60.884758,-60.360649,0.006088,0.004621,0.117370,270.828918,13.796683,1.173703,-60.360649,0.117457,0.000000
89.510002,60.833000,-60.405132,0.006053,0.004621,0.117370,270.598694,13.784955,1.173703,-60.405132,0.117457,0.000000
89.760002,60.813637,-60.360649,0.006058,0.004621,0.117370,270.512573,13.780567,1.173703,-60.360649,0.117457,0.000000
90.010002,60.779007,-60.316170,0.006062,0.004621,0.117370,270.358521,13.772719,1.173703,-60.316170,0.117457,0.000000
90.260002,60.749962,-60.360649,0.006066,0.004621,0.117370,270.229340,13.766138,1.173703,-60.360649,0.117457,0.000000
90.510002,60.706024,-60.316170,0.006049,0.004621,0.117370,270.033875,13.756182,1.173703,-60.316170,0.117457,0.000000
90.760002,60.682564,-60.405132,0.006066,0.004621,0.117370,269.929535,13.750865,1.173703,-60.405132,0.117457,0.000000
91.010002,60.662827,-60.494095,0.006040,0.004621,0.117370,269.841736,13.746393,1.173703,-60.494095,0.117457,0.000000
91.260002,60.630432,-60.449612,0.006066,0.004621,0.117370,269.697632,13.739053,1.173703,-60.449612,0.117457,0.000000
91.510002,60.591705,-60.449612,0.006066,0.004621,0.117370,269.525360,13.730276,1.173703,-60.449612,0.117457,0.000000
91.760002,60.575691,-60.449612,0.006071,0.004621,0.117370,269.454132,13.726647,1.173703,-60.449612,0.117457,0.000000
92.010002,60.554466,-60.494095,0.006058,0.004621,0.117370,269.359711,13.721838,1.173703,-60.494095,0.117457,0.000000
92.260002,60.523933,-60.494095,0.006079,0.004621,0.117370,269.223907,13.714919,1.173703,-60.494095,0.117457,0.000000
92.510002,60.498985,-60.494095,0.006066,0.004621,0.117370,269.112915,13.709266,1.173703,-60.494095,0.117457,0.000000
92.760002,60.471802,-60.494095,0.006053,0.004621,0.117370,268.992004,13.703107,1.173703,-60.494095,0.117457,0.000000
93.010002,60.442009,-60.538574,0.006058,0.004621,0.117370,268.859497,13.696355,1.173703,-60.538574,0.117457,0.000000
93.260002,60.418922,-60.583054,0.006079,0.004621,0.117370,268.756775,13.691124,1.173703,-60.583054,0.117457,0.000000
93.510002,60.386902,-60.494095,0.006062,0.004621,0.117370,268.614349,13.683867,1.173703,-60.494095,0.117457,0.000000
93.760002,60.372749,-60.583054,0.006066,0.004621,0.117370,268.551392,13.680661,1.173703,-60.583054,0.117457,0.000000
94.010002,60.351898,-60.538574,0.006075,0.004621,0.117370,268.458649,13.675936,1.173703,-60.538574,0.117457,0.000000
94.260002,60.319496,-60.627537,0.006075,0.004621,0.117370,268.314514,13.668593,1.173703,-60.627537,0.117457,0.000000
94.510002,60.301994,-60.583054,0.006066,0.004621,0.117370,268.236664,13.664628,1.173703,-60.583054,0.117457,0.000000
94.760002,60.289711,-60.627537,0.006053,0.004621,0.117370,268.182037,13.661844,1.173703,-60.627537,0.117457,0.000000
95.010002,60.249496,-60.627537,0.006066,0.004621,0.117370,268.003143,13.652731,1.173703,-60.627537,0.117457,0.000000
95.260002,60.231621,-60.627537,0.006071,0.004621,0.117370,267.923645,13.648681,1.173703,-60.627537,0.117457,0.000000
95.510002,60.212257,-60.672016,0.006062,0.004621,0.117370,267.837494,13.644293,1.173703,-60.672016,0.117457,0.000000
95.760002,60.189171,-60.672016,0.006071,0.004621,0.117370,267.734802,13.639061,1.173703,-60.672016,0.117457,0.000000
96.010002,60.161613,-60.627537,0.006066,0.004621,0.117370,267.612213,13.632817,1.173703,-60.627537,0.117457,0.000000
96.260002,60.151558,-60.672016,0.006066,0.004621,0.117370,267.567505,13.630538,1.173703,-60.672016,0.117457,0.000000
96.510002,60.134804,-60.672016,0.006058,0.004621,0.117370,267.492981,13.626741,1.173703,-60.672016,0.117457,0.000000
96.760002,60.102776,-60.716499,0.006066,0.004621,0.117370,267.350494,13.619483,1.173703,-60.716499,0.117457,0.000000
97.010002,60.091980,-60.672016,0.006058,0.004621,0.117370,267.302490,13.617038,1.173703,-60.672016,0.117457,0.000000
97.260002,60.075592,-60.672016,0.006066,0.004621,0.117370,267.229584,13.613324,1.173703,-60.672016,0.117457,0.000000
97.510002,60.049156,-60.760979,0.006075,0.004621,0.117370,267.112000,13.607333,1.173703,-60.760979,0.117457,0.000000
97.760002,60.033142,-60.760979,0.006062,0.004621,0.117370,267.040741,13.603704,1.173703,-60.760979,0.117457,0.000000
98.010002,60.020111,-60.760979,0.006049,0.004621,0.117370,266.982788,13.600752,1.173703,-60.760979,0.117457,0.000000
98.260002,59.994415,-60.760979,0.006062,0.004621,0.117370,266.868500,13.594929,1.173703,-60.760979,0.117457,0.000000
98.510002,59.965004,-60.805462,0.006075,0.004621,0.117370,266.737671,13.588264,1.173703,-60.805462,0.117457,0.000000
98.760002,59.954575,-60.805462,0.006079,0.004621,0.117370,266.691254,13.585900,1.173703,-60.805462,0.117457,0.000000
99.010002,59.943405,-60.760979,0.006071,0.004621,0.117370,266.641571,13.583369,1.173703,-60.760979,0.117457,0.000000
99.260002,59.916222,-60.805462,0.006088,0.004621,0.117370,266.520660,13.577209,1.173703,-60.805462,0.117457,0.000000
99.510002,59.904305,-60.805462,0.006071,0.004621,0.117370,266.467651,13.574510,1.173703,-60.805462,0.117457,0.000000
99.760002,59.894249,-60.805462,0.006049,0.004621,0.117370,266.422913,13.572231,1.173703,-60.805462,0.117457,0.000000
100.010002,59.864090,-60.805462,0.006058,0.004621,0.117370,266.288757,13.565397,1.173703,-60.805462,0.117457,0.000000
100.260002,59.835045,-60.849941,0.006053,0.004621,0.117370,266.159576,13.558815,1.173703,-60.849941,0.117457,0.000000
100.510002,59.836906,-60.894421,0.006058,0.004621,0.117370,266.167847,13.559237,1.173703,-60.894421,0.117457,0.000000
100.760002,59.827599,-60.938904,0.006075,0.004621,0.117370,266.126465,13.557127,1.173703,-60.938904,0.117457,0.000000
101.010002,59.798920,-60.894421,0.006062,0.004621,0.117370,265.998871,13.550630,1.173703,-60.894421,0.117457,0.000000
101.260002,59.789612,-60.894421,0.006079,0.004621,0.117370,265.957489,13.548519,1.173703,-60.894421,0.117457,0.000000
101.510002,59.757217,-60.894421,0.006066,0.004621,0.117370,265.813385,13.541180,1.173703,-60.894421,0.117457,0.000000
101.760002,59.760941,-60.938904,0.006062,0.004621,0.117370,265.829926,13.542023,1.173703,-60.938904,0.117457,0.000000
102.010002,59.735992,-60.894421,0.006079,0.004621,0.117370,265.718964,13.536369,1.173703,-60.894421,0.117457,0.000000
102.260002,59.721466,-60.983383,0.006066,0.004621,0.117370,265.654358,13.533078,1.173703,-60.983383,0.117457,0.000000
102.510002,59.712158,-60.938904,0.006071,0.004621,0.117370,265.612946,13.530968,1.173703,-60.938904,0.117457,0.000000
102.760002,59.688698,-61.027866,0.006066,0.004621,0.117370,265.508575,13.525653,1.173703,-61.027866,0.117457,0.000000
103.010002,59.669334,-60.983383,0.006049,0.004621,0.117370,265.422455,13.521264,1.173703,-60.983383,0.117457,0.000000
103.260002,59.650345,-60.983383,0.006027,0.004621,0.117370,265.337982,13.516961,1.173703,-60.983383,0.117457,0.000000
103.510002,59.642151,-60.938904,0.006075,0.004621,0.117370,265.301544,13.515104,1.173703,-60.938904,0.117457,0.000000
103.760002,59.632103,-61.072346,0.006053,0.004621,0.117370,265.256836,13.512828,1.173703,-61.072346,0.117457,0.000000
104.010002,59.611618,-61.072346,0.006066,0.004621,0.117370,265.165710,13.508185,1.173703,-61.072346,0.117457,0.000000
104.260002,59.589279,-60.983383,0.006079,0.004621,0.117370,265.066345,13.503123,1.173703,-60.983383,0.117457,0.000000
104.510002,59.586670,-61.072346,0.006066,0.004621,0.117370,265.054749,13.502533,1.173703,-61.072346,0.117457,0.000000
104.760002,59.574753,-61.072346,0.006062,0.004621,0.117370,265.001740,13.499832,1.173703,-61.072346,0.117457,0.000000
105.010002,59.562096,-61.072346,0.006066,0.004621,0.117370,264.945435,13.496964,1.173703,-61.072346,0.117457,0.000000
105.260002,59.546455,-61.072346,0.006071,0.004621,0.117370,264.875854,13.493420,1.173703,-61.072346,0.117457,0.000000
105.400002,59.525230,-61.116825,0.006045,0.004621,0.117370,264.781464,13.488610,1.173703,-61.116825,0.117457,0.000000