File: Data/Symmetrical membranes compression/Sartorius Cellulose Nitrate 045um test 1_10302023_171307.csv
Time (sec),S:Load (lbs),S:HL1 (DIM),S:LVDT (in),S:Position (in),Ch:Position (mm),Ch:Load (N),Ch:Stress (MPa),Ch:Strain (mm/mm),Ch:HL1 (DIM),Set Point (),Cycles ()
0.110000,-0.010048,-91.497314,-0.000022,-0.000000,-0.000000,-0.044695,-0.002277,-0.000000,-91.497314,0.000286,0.000000
0.310000,-0.011169,-91.452835,-0.000004,-0.000000,-0.000000,-0.049684,-0.002531,-0.000000,-91.452835,0.000286,0.000000
0.510000,-0.008560,-91.497314,-0.000013,0.000085,0.002168,-0.038078,-0.001940,0.021680,-91.497314,0.002992,0.000000
0.710000,0.002609,-91.497314,0.000039,0.000201,0.005099,0.011607,0.000591,0.050992,-91.497314,0.006322,0.000000
0.910000,0.017136,-91.497314,0.000190,0.000335,0.008507,0.076223,0.003883,0.085074,-91.497314,0.009670,0.000000
1.110000,0.024948,-91.497314,0.000332,0.000467,0.011855,0.110975,0.005653,0.118550,-91.497314,0.013000,0.000000
1.310000,0.029793,-91.541794,0.000474,0.000598,0.015185,0.132525,0.006751,0.151851,-91.541794,0.016330,0.000000
1.510000,0.025322,-91.497314,0.000591,0.000723,0.018376,0.112638,0.005738,0.183764,-91.497314,0.019660,0.000000
1.710000,0.018623,-91.497314,0.000737,0.000854,0.021689,0.082841,0.004220,0.216892,-91.497314,0.022990,0.000000
1.910000,0.009315,-91.541794,0.000875,0.000986,0.025037,0.041437,0.002111,0.250368,-91.541794,0.026320,0.000000
2.110000,0.029793,-91.541794,0.000992,0.001117,0.028367,0.132525,0.006751,0.283669,-91.541794,0.029650,0.000000
2.310000,0.072617,-91.586281,0.001134,0.001251,0.031775,0.323015,0.016455,0.317751,-91.586281,0.032981,0.000000
2.510000,0.151184,-91.541794,0.001268,0.001380,0.035062,0.672500,0.034259,0.350618,-91.541794,0.036311,0.000000
2.710000,0.307953,-91.541794,0.001397,0.001511,0.038383,1.369843,0.069783,0.383834,-91.541794,0.039658,0.000000
2.910000,0.525795,-91.541794,0.001539,0.001641,0.041687,2.338853,0.119147,0.416875,-91.541794,0.042988,0.000000
3.110000,0.664314,-91.586281,0.001587,-0.000010,-0.000252,2.955018,0.150536,-0.002515,-91.586281,-0.000078,0.000000
3.310000,0.652023,-91.541794,0.001630,-0.000010,-0.000260,2.900345,0.147751,-0.002601,-91.541794,-0.000078,0.000000
3.510000,0.641228,-91.586281,0.001613,-0.000010,-0.000260,2.852323,0.145304,-0.002601,-91.586281,-0.000078,0.000000
3.710000,0.638252,-91.630760,0.001587,-0.000010,-0.000260,2.839088,0.144630,-0.002601,-91.630760,0.000208,0.000000
3.910000,0.635643,-91.541794,0.001587,-0.000010,-0.000260,2.827481,0.144039,-0.002601,-91.541794,0.000546,0.000000
4.110000,0.639366,-91.541794,0.001613,-0.000010,-0.000260,2.844043,0.144882,-0.002601,-91.541794,0.000876,0.000000
4.310000,0.646072,-91.630760,0.001625,-0.000010,-0.000252,2.873873,0.146402,-0.002515,-91.630760,0.001214,0.000000
4.510000,0.717194,-91.630760,0.001634,0.000026,0.000668,3.190237,0.162518,0.006678,-91.630760,0.001544,0.000000
4.710000,0.722778,-91.630760,0.001630,0.000036,0.000919,3.215079,0.163784,0.009193,-91.630760,0.001882,0.000000
4.910000,0.809914,-91.675240,0.001681,0.000053,0.001353,3.602676,0.183529,0.013529,-91.675240,0.002211,0.000000
5.110000,0.855339,-91.630760,0.001681,0.000064,0.001622,3.804738,0.193823,0.016217,-91.630760,0.002550,0.000000
5.310000,0.892952,-91.719719,0.001690,0.000074,0.001882,3.972049,0.202346,0.018819,-91.719719,0.002879,0.000000
5.510000,0.930191,-91.630760,0.001703,0.000081,0.002047,4.137696,0.210784,0.020467,-91.630760,0.003209,0.000000
5.710000,1.001686,-91.675240,0.001703,0.000101,0.002558,4.455722,0.226985,0.025583,-91.675240,0.003547,0.000000
5.910000,1.076904,-91.675240,0.001733,0.000117,0.002975,4.790309,0.244030,0.029746,-91.675240,0.003876,0.000000
6.110000,1.142441,-91.630760,0.001763,0.000129,0.003287,5.081831,0.258881,0.032868,-91.630760,0.004215,0.000000
6.310000,1.161057,-91.675240,0.001755,0.000144,0.003651,5.164638,0.263099,0.036510,-91.675240,0.004544,0.000000
6.510000,1.231438,-91.719719,0.001763,0.000157,0.003989,5.477708,0.279048,0.039893,-91.719719,0.004883,0.000000
6.710001,1.278732,-91.719719,0.001759,0.000167,0.004232,5.688086,0.289765,0.042321,-91.719719,0.005212,0.000000
6.910000,1.365868,-91.675240,0.001781,0.000183,0.004648,6.075683,0.309510,0.046483,-91.675240,0.005550,0.000000
7.110000,1.429543,-91.719719,0.001794,0.000194,0.004917,6.358923,0.323939,0.049171,-91.719719,0.005880,0.000000
7.310000,1.464912,-91.719719,0.001811,0.000203,0.005169,6.516256,0.331954,0.051687,-91.719719,0.006209,0.000000
7.510000,1.536781,-91.764198,0.001798,0.000217,0.005524,6.835945,0.348240,0.055242,-91.764198,0.006548,0.000000
7.710001,1.612747,-91.719719,0.001828,0.000231,0.005871,7.173858,0.365454,0.058711,-91.719719,0.006877,0.000000
7.910000,1.702866,-91.675240,0.001850,0.000245,0.006227,7.574725,0.385875,0.062267,-91.675240,0.007215,0.000000
8.110001,1.779198,-91.719719,0.001854,0.000259,0.006582,7.914267,0.403172,0.065823,-91.719719,0.007545,0.000000
8.310000,1.827232,-91.719719,0.001863,0.000272,0.006903,8.127935,0.414057,0.069032,-91.719719,0.007883,0.000000
8.510000,1.912880,-91.764198,0.001884,0.000285,0.007241,8.508915,0.433465,0.072414,-91.764198,0.008213,0.000000
8.710000,1.959053,-91.719719,0.001914,0.000294,0.007458,8.714303,0.443928,0.074581,-91.719719,0.008542,0.000000
8.910001,2.090874,-91.764198,0.001927,0.000314,0.007978,9.300671,0.473799,0.079785,-91.764198,0.008880,0.000000
9.110001,2.168701,-91.808685,0.001927,0.000326,0.008291,9.646865,0.491435,0.082907,-91.808685,0.009210,0.000000
9.310000,2.176895,-91.764198,0.001944,0.000333,0.008455,9.683313,0.493291,0.084555,-91.764198,0.009548,0.000000
9.510000,2.274826,-91.764198,0.001970,0.000346,0.008785,10.118932,0.515483,0.087850,-91.764198,0.009878,0.000000
9.710000,2.389145,-91.853165,0.001962,0.000363,0.009227,10.627447,0.541388,0.092273,-91.853165,0.010216,0.000000
9.910001,2.433083,-91.853165,0.001975,0.000372,0.009453,10.822892,0.551344,0.094528,-91.853165,0.010545,0.000000
10.110001,2.500114,-91.764198,0.001983,0.000387,0.009826,11.121064,0.566534,0.098257,-91.764198,0.010884,0.000000
10.310000,2.607727,-91.808685,0.002018,0.000404,0.010259,11.599750,0.590919,0.102593,-91.808685,0.011213,0.000000
10.510000,2.612938,-91.808685,0.002039,0.000412,0.010459,11.622929,0.592100,0.104588,-91.808685,0.011543,0.000000
10.710000,2.687790,-91.808685,0.002039,0.000425,0.010806,11.955887,0.609062,0.108057,-91.808685,0.011881,0.000000
10.910001,2.806572,-91.853165,0.002031,0.000439,0.011144,12.484256,0.635978,0.111439,-91.853165,0.012211,0.000000
11.110001,2.909721,-91.853165,0.002057,0.000454,0.011543,12.943087,0.659352,0.115428,-91.853165,0.012549,0.000000
11.310000,2.867645,-91.808685,0.002078,0.000455,0.011560,12.755923,0.649818,0.115601,-91.808685,0.012878,0.000000
11.510000,3.031113,-91.808685,0.002070,0.000476,0.012098,13.483063,0.686860,0.120978,-91.808685,0.013217,0.000000
11.710001,3.140594,-91.808685,0.002100,0.000495,0.012575,13.970062,0.711669,0.125748,-91.808685,0.013546,0.000000
11.910001,3.190865,-91.853165,0.002117,0.000507,0.012870,14.193674,0.723060,0.128697,-91.853165,0.013876,0.000000
12.110001,3.260498,-91.853165,0.002134,0.000522,0.013260,14.503420,0.738839,0.132599,-91.853165,0.014214,0.000000
12.310000,3.311882,-91.853165,0.002126,0.000533,0.013529,14.731987,0.750483,0.135287,-91.853165,0.014543,0.000000
12.510000,3.354332,-91.897644,0.002143,0.000544,0.013806,14.920814,0.760103,0.138063,-91.897644,0.014882,0.000000
12.710001,3.494347,-91.853165,0.002151,0.000560,0.014222,15.543630,0.791830,0.142225,-91.853165,0.015211,0.000000
12.910001,3.514824,-91.897644,0.002173,0.000566,0.014370,15.634718,0.796470,0.143699,-91.897644,0.015549,0.000000
13.110001,3.635849,-91.942123,0.002173,0.000585,0.014864,16.173063,0.823895,0.148642,-91.942123,0.015879,0.000000
13.310000,3.707718,-91.986610,0.002207,0.000596,0.015150,16.492752,0.840181,0.151505,-91.986610,0.016217,0.000000
13.510000,3.787407,-91.897644,0.002229,0.000613,0.015558,16.847227,0.858239,0.155581,-91.897644,0.016547,0.000000
13.710001,3.895020,-91.986610,0.002251,0.000627,0.015931,17.325912,0.882624,0.159310,-91.986610,0.016876,0.000000
13.910001,3.953857,-91.942123,0.002246,0.000641,0.016269,17.587637,0.895957,0.162692,-91.942123,0.017214,0.000000
14.110001,4.016785,-91.942123,0.002238,0.000654,0.016607,17.867550,0.910216,0.166074,-91.942123,0.017544,0.000000
14.310000,4.048439,-91.942123,0.002276,0.000664,0.016859,18.008356,0.917389,0.168589,-91.942123,0.017882,0.000000
14.510000,4.104294,-91.942123,0.002281,0.000672,0.017076,18.256811,0.930046,0.170757,-91.942123,0.018212,0.000000
14.710001,4.288986,-91.986610,0.002294,0.000691,0.017561,19.078363,0.971898,0.175613,-91.986610,0.018550,0.000000
14.910001,4.367935,-91.986610,0.002302,0.000707,0.017960,19.429546,0.989788,0.179603,-91.986610,0.018880,0.000000
15.110001,4.443153,-91.942123,0.002311,0.000714,0.018142,19.764133,1.006833,0.181424,-91.942123,0.019218,0.000000
15.310000,4.408524,-92.031090,0.002307,0.000718,0.018229,19.610092,0.998986,0.182291,-92.031090,0.019547,0.000000
15.510001,4.398468,-91.986610,0.002307,0.000735,0.018680,19.565363,0.996707,0.186801,-91.986610,0.019877,0.000000
15.710001,4.652428,-92.031090,0.002354,0.000747,0.018984,20.695032,1.054255,0.189836,-92.031090,0.020215,0.000000
15.910001,4.865051,-91.986610,0.002380,0.000772,0.019608,21.640829,1.102436,0.196080,-91.986610,0.020545,0.000000
16.110001,4.920532,-92.031090,0.002410,0.000785,0.019946,21.887621,1.115009,0.199462,-92.031090,0.020883,0.000000
16.310001,4.973785,-92.075569,0.002397,0.000795,0.020198,22.124502,1.127076,0.201977,-92.075569,0.021212,0.000000
16.510000,4.988678,-91.986610,0.002410,0.000805,0.020441,22.190748,1.130450,0.204405,-91.986610,0.021551,0.000000
16.710001,5.315620,-92.120049,0.002445,0.000828,0.021022,23.645061,1.204537,0.210216,-92.120049,0.021880,0.000000
16.910002,5.337219,-92.120049,0.002436,0.000837,0.021264,23.741137,1.209431,0.212644,-92.120049,0.022210,0.000000
17.110001,5.359558,-92.075569,0.002440,0.000843,0.021412,23.840506,1.214493,0.214118,-92.075569,0.022548,0.000000
17.310001,5.441856,-92.120049,0.002445,0.000856,0.021741,24.206587,1.233142,0.217414,-92.120049,0.022877,0.000000
17.510000,5.482071,-92.075569,0.002479,0.000866,0.021984,24.385469,1.242255,0.219842,-92.075569,0.023216,0.000000
17.710001,5.704750,-92.075569,0.002466,0.000886,0.022505,25.375996,1.292715,0.225045,-92.075569,0.023545,0.000000
17.910002,5.858170,-92.075569,0.002501,0.000902,0.022903,26.058439,1.327480,0.229034,-92.075569,0.023883,0.000000
18.110001,5.924820,-92.031090,0.002505,0.000916,0.023268,26.354916,1.342583,0.232676,-92.031090,0.024213,0.000000
18.310001,5.967270,-92.075569,0.002522,0.000927,0.023554,26.543743,1.352203,0.235539,-92.075569,0.024551,0.000000
18.510000,6.037651,-92.075569,0.002544,0.000937,0.023805,26.856813,1.368151,0.238054,-92.075569,0.024881,0.000000
18.710001,6.173569,-92.120049,0.002561,0.000951,0.024144,27.461405,1.398951,0.241436,-92.120049,0.025210,0.000000
18.910002,6.239105,-92.164528,0.002570,0.000960,0.024378,27.752926,1.413801,0.243778,-92.164528,0.025549,0.000000
19.110001,6.418213,-92.164528,0.002574,0.000975,0.024777,28.549637,1.454388,0.247767,-92.164528,0.025878,0.000000
19.310001,6.336662,-92.164528,0.002574,0.000975,0.024777,28.186882,1.435908,0.247767,-92.164528,0.026216,0.000000
19.510000,6.728027,-92.164528,0.002596,0.001008,0.025609,29.927761,1.524593,0.256092,-92.164528,0.026546,0.000000
19.710001,6.785744,-92.164528,0.002617,0.001020,0.025904,30.184496,1.537672,0.259040,-92.164528,0.026884,0.000000
19.910002,6.830803,-92.164528,0.002613,0.001035,0.026277,30.384930,1.547882,0.262769,-92.164528,0.027214,0.000000
20.110001,6.870277,-92.164528,0.002643,0.001044,0.026511,30.560520,1.556827,0.265111,-92.164528,0.027552,0.000000
20.310001,6.981987,-92.209015,0.002665,0.001057,0.026849,31.057428,1.582141,0.268493,-92.209015,0.027881,0.000000
20.510000,7.052734,-92.209015,0.002656,0.001071,0.027196,31.372129,1.598172,0.271962,-92.209015,0.028211,0.000000
20.710001,7.138756,-92.164528,0.002665,0.001076,0.027335,31.754772,1.617665,0.273350,-92.164528,0.028549,0.000000
20.910002,7.312279,-92.209015,0.002690,0.001094,0.027795,32.526642,1.656986,0.277946,-92.209015,0.028879,0.000000
21.110001,7.425110,-92.209015,0.002712,0.001107,0.028116,33.028538,1.682554,0.281155,-92.209015,0.029217,0.000000
21.310001,7.433304,-92.164528,0.002699,0.001119,0.028428,33.064987,1.684411,0.284277,-92.164528,0.029546,0.000000
21.510000,7.641083,-92.209015,0.002742,0.001134,0.028792,33.989235,1.731494,0.287919,-92.209015,0.029885,0.000000
21.710001,7.727852,-92.209015,0.002742,0.001146,0.029113,34.375202,1.751156,0.291128,-92.209015,0.030214,0.000000
21.910002,7.826897,-92.253494,0.002755,0.001160,0.029460,34.815777,1.773600,0.294596,-92.253494,0.030544,0.000000
22.110001,7.924088,-92.209015,0.002751,0.001175,0.029841,35.248100,1.795624,0.298412,-92.209015,0.030882,0.000000
22.310001,8.006012,-92.209015,0.002785,0.001185,0.030110,35.612518,1.814188,0.301101,-92.209015,0.031211,0.000000
22.510000,8.114746,-92.253494,0.002820,0.001199,0.030457,36.096195,1.838828,0.304570,-92.253494,0.031550,0.000000
22.710001,8.208954,-92.253494,0.002802,0.001211,0.030752,36.515251,1.860175,0.307518,-92.253494,0.031879,0.000000
22.910002,8.332954,-92.297974,0.002802,0.001224,0.031099,37.066833,1.888274,0.310988,-92.297974,0.032217,0.000000
23.110001,8.415619,-92.253494,0.002841,0.001234,0.031350,37.434544,1.907007,0.313502,-92.253494,0.032547,0.000000
23.310001,8.637924,-92.297974,0.002841,0.001256,0.031905,38.423405,1.957382,0.319052,-92.297974,0.032885,0.000000
23.510000,8.728043,-92.297974,0.002846,0.001270,0.032252,38.824272,1.977803,0.322521,-92.297974,0.033215,0.000000
23.710001,8.801773,-92.342453,0.002876,0.001283,0.032590,39.152241,1.994510,0.325904,-92.342453,0.033544,0.000000
23.910002,8.849434,-92.297974,0.002880,0.001295,0.032903,39.364246,2.005310,0.329026,-92.297974,0.033883,0.000000
24.110001,8.905289,-92.342453,0.002889,0.001307,0.033197,39.612701,2.017967,0.331974,-92.342453,0.034212,0.000000
24.310001,8.967850,-92.297974,0.002910,0.001317,0.033458,39.890987,2.032144,0.334576,-92.297974,0.034550,0.000000
24.510000,9.068764,-92.297974,0.002923,0.001330,0.033787,40.339874,2.055011,0.337871,-92.297974,0.034880,0.000000
24.710001,9.163345,-92.386932,0.002932,0.001341,0.034065,40.760597,2.076444,0.340646,-92.386932,0.035218,0.000000
24.910002,9.288834,-92.342453,0.002936,0.001353,0.034377,41.318794,2.104880,0.343769,-92.342453,0.035548,0.000000
25.110001,9.540558,-92.386932,0.002971,0.001373,0.034871,42.438522,2.161921,0.348712,-92.386932,0.035877,0.000000
25.310001,9.625458,-92.342453,0.002958,0.001387,0.035227,42.816174,2.181160,0.352268,-92.342453,0.036215,0.000000
25.510002,9.767334,-92.386932,0.002984,0.001400,0.035556,43.447273,2.213310,0.355563,-92.386932,0.036545,0.000000
25.710001,9.834732,-92.386932,0.003009,0.001416,0.035955,43.747074,2.228582,0.359552,-92.386932,0.036883,0.000000
25.910002,9.885750,-92.342453,0.003005,0.001426,0.036233,43.974010,2.240143,0.362327,-92.342453,0.037213,0.000000
26.110001,9.973251,-92.431419,0.003022,0.001439,0.036554,44.363239,2.259971,0.365536,-92.431419,0.037551,0.000000
26.310001,10.180664,-92.431419,0.003048,0.001455,0.036961,45.285854,2.306972,0.369612,-92.431419,0.037880,0.000000
26.510002,10.192207,-92.386932,0.003048,0.001466,0.037239,45.337204,2.309587,0.372387,-92.386932,0.038219,0.000000
26.710001,10.265938,-92.342453,0.003070,0.001477,0.037516,45.665173,2.326295,0.375162,-92.342453,0.038548,0.000000
26.910002,10.116249,-92.342453,0.003078,0.001479,0.037568,44.999325,2.292375,0.375682,-92.342453,0.038878,0.000000
27.110001,10.624535,-92.431419,0.003091,0.001505,0.038227,47.260292,2.407554,0.382273,-92.431419,0.039216,0.000000
27.310001,10.767899,-92.431419,0.003117,0.001522,0.038661,47.898006,2.440041,0.386609,-92.431419,0.039546,0.000000
27.510002,10.828224,-92.431419,0.003113,0.001536,0.039008,48.166348,2.453711,0.390078,-92.431419,0.039884,0.000000
27.710001,10.935463,-92.431419,0.003122,0.001549,0.039337,48.643368,2.478011,0.393374,-92.431419,0.040213,0.000000
27.910002,10.973816,-92.431419,0.003156,0.001559,0.039589,48.813972,2.486702,0.395889,-92.431419,0.040551,0.000000
28.110001,11.057602,-92.431419,0.003147,0.001571,0.039910,49.186668,2.505688,0.399097,-92.431419,0.040881,0.000000
28.310001,11.239319,-92.431419,0.003178,0.001587,0.040300,49.994987,2.546866,0.403000,-92.431419,0.041219,0.000000
28.510002,11.300766,-92.431419,0.003182,0.001599,0.040603,50.268318,2.560790,0.406035,-92.431419,0.041549,0.000000
28.710001,11.228897,-92.520378,0.003199,0.001602,0.040690,49.948627,2.544504,0.406903,-92.520378,0.041878,0.000000
28.910002,11.491043,-92.520378,0.003199,0.001621,0.041185,51.114712,2.603908,0.411846,-92.520378,0.042217,0.000000
29.110001,11.752449,-92.520378,0.003221,0.001639,0.041618,52.277504,2.663143,0.416181,-92.520378,0.042546,0.000000
29.310001,11.748352,-92.520378,0.003229,0.001650,0.041913,52.259281,2.662215,0.419131,-92.520378,0.042884,0.000000
29.510002,11.966568,-92.475899,0.003255,0.001663,0.042251,53.229954,2.711663,0.422513,-92.475899,0.043214,0.000000
29.710001,12.091309,-92.564857,0.003272,0.001679,0.042650,53.784828,2.739930,0.426502,-92.564857,0.043552,0.000000
29.910002,12.166901,-92.520378,0.003272,0.001691,0.042945,54.121078,2.757059,0.429450,-92.520378,0.043882,0.000000
30.110001,12.261856,-92.609337,0.003277,0.001704,0.043292,54.543461,2.778576,0.432919,-92.609337,0.044211,0.000000
30.310001,12.440224,-92.564857,0.003290,0.001718,0.043648,55.336880,2.818995,0.436475,-92.564857,0.044549,0.000000
30.510002,12.468147,-92.520378,0.003320,0.001729,0.043908,55.461090,2.825322,0.439076,-92.520378,0.044879,0.000000
30.710001,12.420486,-92.564857,0.003303,0.001736,0.044107,55.249084,2.814523,0.441071,-92.564857,0.045217,0.000000
30.910002,12.547836,-92.564857,0.003337,0.001747,0.044367,55.815563,2.843380,0.443673,-92.564857,0.045547,0.000000
31.110001,12.880737,-92.609337,0.003350,0.001767,0.044870,57.296383,2.918817,0.448703,-92.609337,0.045885,0.000000
31.310001,12.963036,-92.564857,0.003359,0.001779,0.045182,57.662460,2.937466,0.451825,-92.564857,0.046215,0.000000
31.510002,13.102676,-92.564857,0.003372,0.001795,0.045581,58.283615,2.969109,0.455814,-92.564857,0.046553,0.000000
31.710001,13.229279,-92.564857,0.003385,0.001805,0.045850,58.846771,2.997797,0.458502,-92.564857,0.046882,0.000000
31.910002,13.219223,-92.653824,0.003376,0.001815,0.046102,58.802040,2.995519,0.461017,-92.653824,0.047212,0.000000
32.110001,13.417702,-92.609337,0.003406,0.001828,0.046431,59.684917,3.040495,0.464313,-92.609337,0.047550,0.000000
32.310001,13.640381,-92.653824,0.003419,0.001844,0.046830,60.675446,3.090955,0.468302,-92.653824,0.047880,0.000000
32.510002,13.712990,-92.609337,0.003432,0.001854,0.047082,60.998425,3.107408,0.470817,-92.609337,0.048218,0.000000
32.710003,13.868271,-92.653824,0.003445,0.001868,0.047455,61.689148,3.142595,0.474546,-92.653824,0.048547,0.000000
32.910000,14.131165,-92.698303,0.003462,0.001886,0.047897,62.858559,3.202168,0.478969,-92.698303,0.048886,0.000000
33.110001,14.186279,-92.742783,0.003475,0.001897,0.048192,63.103722,3.214657,0.481917,-92.742783,0.049215,0.000000
33.310001,14.450661,-92.609337,0.003505,0.001913,0.048591,64.279747,3.274567,0.485907,-92.609337,0.049553,0.000000
33.510002,14.464066,-92.742783,0.003505,0.001925,0.048886,64.339378,3.277604,0.488855,-92.742783,0.049883,0.000000
33.710003,14.608543,-92.698303,0.003514,0.001938,0.049215,64.982048,3.310343,0.492151,-92.698303,0.050212,0.000000
33.910000,14.621208,-92.698303,0.003535,0.001946,0.049423,65.038383,3.313213,0.494233,-92.698303,0.050551,0.000000
34.110001,14.798088,-92.698303,0.003548,0.001960,0.049796,65.825180,3.353295,0.497962,-92.698303,0.050880,0.000000
34.310001,14.886711,-92.742783,0.003548,0.001974,0.050134,66.219398,3.373377,0.501343,-92.742783,0.051218,0.000000
34.510002,15.075500,-92.742783,0.003557,0.001985,0.050412,67.059174,3.416157,0.504119,-92.742783,0.051548,0.000000
34.710003,15.335045,-92.698303,0.003574,0.002003,0.050880,68.213684,3.474971,0.508802,-92.698303,0.051886,0.000000
34.910000,15.465378,-92.698303,0.003579,0.002016,0.051201,68.793434,3.504505,0.512010,-92.698303,0.052216,0.000000
35.110001,15.687683,-92.787262,0.003613,0.002029,0.051548,69.782303,3.554880,0.515479,-92.787262,0.052545,0.000000
35.310001,15.786736,-92.742783,0.003617,0.002043,0.051895,70.222908,3.577325,0.518948,-92.742783,0.052883,0.000000
35.510002,15.886528,-92.698303,0.003639,0.002055,0.052207,70.666809,3.599939,0.522070,-92.698303,0.053213,0.000000
35.710003,15.978134,-92.787262,0.003626,0.002067,0.052510,71.074287,3.620697,0.525105,-92.787262,0.053551,0.000000
35.910000,16.049629,-92.787262,0.003639,0.002079,0.052814,71.392319,3.636898,0.528140,-92.787262,0.053881,0.000000
36.110001,16.474136,-92.787262,0.003682,0.002094,0.053187,73.280617,3.733093,0.531870,-92.787262,0.054219,0.000000
36.310001,16.187408,-92.787262,0.003682,0.002104,0.053447,72.005188,3.668119,0.534472,-92.787262,0.054548,0.000000
36.510002,16.658829,-92.787262,0.003678,0.002116,0.053751,74.102173,3.774945,0.537507,-92.787262,0.054887,0.000000
36.710003,16.925446,-92.831741,0.003721,0.002134,0.054202,75.288139,3.835361,0.542016,-92.831741,0.055216,0.000000
36.910000,17.099350,-92.876228,0.003712,0.002146,0.054497,76.061707,3.874768,0.544965,-92.876228,0.055546,0.000000
37.110001,17.422569,-92.787262,0.003734,0.002164,0.054956,77.499458,3.948011,0.549561,-92.787262,0.055884,0.000000
37.310001,17.499275,-92.787262,0.003751,0.002175,0.055251,77.840660,3.965392,0.552509,-92.787262,0.056214,0.000000
37.510002,17.565926,-92.831741,0.003764,0.002188,0.055563,78.137138,3.980495,0.555632,-92.831741,0.056552,0.000000
37.710003,17.576355,-92.876228,0.003764,0.002197,0.055797,78.183533,3.982859,0.557973,-92.876228,0.056881,0.000000
37.910004,17.622154,-92.876228,0.003786,0.002208,0.056084,78.387260,3.993237,0.560835,-92.876228,0.057220,0.000000
38.110001,18.281998,-92.831741,0.003798,0.002229,0.056612,81.322388,4.142760,0.566125,-92.831741,0.057549,0.000000
38.310001,18.237320,-92.876228,0.003794,0.002238,0.056847,81.123650,4.132636,0.568467,-92.876228,0.057879,0.000000
38.510002,18.344559,-92.920708,0.003807,0.002250,0.057142,81.600670,4.156937,0.571415,-92.920708,0.058217,0.000000
38.710003,18.478615,-92.831741,0.003820,0.002260,0.057393,82.196983,4.187314,0.573930,-92.831741,0.058546,0.000000
38.910004,18.674484,-92.876228,0.003824,0.002275,0.057783,83.068253,4.231699,0.577832,-92.876228,0.058885,0.000000
39.110001,19.173462,-92.920708,0.003824,0.002293,0.058234,85.287819,4.344769,0.582342,-92.920708,0.059214,0.000000
39.310001,19.198036,-92.876228,0.003854,0.002304,0.058529,85.397133,4.350337,0.585290,-92.876228,0.059552,0.000000
39.510002,19.422203,-92.876228,0.003859,0.002317,0.058850,86.394272,4.401134,0.588499,-92.876228,0.059882,0.000000
39.710003,19.451622,-92.876228,0.003876,0.002327,0.059101,86.525139,4.407801,0.591014,-92.876228,0.060220,0.000000
39.910004,19.671692,-92.965187,0.003902,0.002342,0.059492,87.504059,4.457669,0.594917,-92.965187,0.060550,0.000000
40.110001,20.019493,-92.920708,0.003911,0.002356,0.059847,89.051155,4.536482,0.598472,-92.920708,0.060879,0.000000
40.310001,19.780052,-93.009666,0.003915,0.002359,0.059917,87.986069,4.482224,0.599167,-93.009666,0.061217,0.000000
40.510002,20.398941,-92.920708,0.003932,0.002379,0.060437,90.739021,4.622466,0.604370,-92.920708,0.061547,0.000000
40.710003,20.609703,-92.920708,0.003949,0.002395,0.060836,91.676537,4.670225,0.608359,-92.920708,0.061885,0.000000
40.910004,21.113152,-92.920708,0.003949,0.002414,0.061313,93.915985,4.784308,0.613128,-92.920708,0.062215,0.000000
41.110001,21.168633,-92.965187,0.003980,0.002425,0.061590,94.162781,4.796881,0.615904,-92.965187,0.062553,0.000000
41.310001,21.290771,-92.965187,0.003984,0.002438,0.061920,94.706085,4.824558,0.619199,-92.965187,0.062883,0.000000
41.510002,21.340294,-92.965187,0.003984,0.002448,0.062189,94.926369,4.835780,0.621888,-92.965187,0.063221,0.000000
41.710003,21.427803,-92.965187,0.004010,0.002458,0.062440,95.315628,4.855610,0.624403,-92.965187,0.063550,0.000000
41.910004,21.817680,-93.054146,0.004018,0.002474,0.062848,97.049889,4.943957,0.628479,-93.054146,0.063880,0.000000
42.110001,21.846352,-93.009666,0.004027,0.002481,0.063030,97.177429,4.950454,0.630300,-93.009666,0.064218,0.000000
42.310001,22.139778,-93.009666,0.004040,0.002497,0.063412,98.482651,5.016945,0.634116,-93.009666,0.064548,0.000000
42.510002,22.341232,-93.009666,0.004044,0.002511,0.063784,99.378761,5.062596,0.637845,-93.009666,0.064886,0.000000
42.710003,22.462624,-93.054146,0.004066,0.002519,0.063975,99.918739,5.090103,0.639752,-93.054146,0.065215,0.000000
42.910004,22.922508,-93.054146,0.004070,0.002539,0.064487,101.964409,5.194314,0.644869,-93.054146,0.065554,0.000000
43.110001,23.196571,-93.054146,0.004096,0.002550,0.064764,103.183502,5.256418,0.647645,-93.054146,0.065883,0.000000
43.310001,23.450905,-93.054146,0.004105,0.002565,0.065155,104.314835,5.314051,0.651547,-93.054146,0.066213,0.000000
43.510002,23.824768,-93.054146,0.004083,0.002579,0.065510,105.977859,5.398770,0.655103,-93.054146,0.066551,0.000000
43.710003,24.074631,-93.098633,0.004126,0.002595,0.065901,107.089310,5.455389,0.659005,-93.098633,0.066881,0.000000
43.910004,24.166229,-93.098633,0.004126,0.002605,0.066161,107.496758,5.476146,0.661606,-93.098633,0.067219,0.000000
44.110001,23.892166,-93.054146,0.004139,0.002605,0.066161,106.277664,5.414042,0.661606,-93.054146,0.067548,0.000000
44.310001,24.637283,-93.098633,0.004148,0.002626,0.066690,109.592110,5.582888,0.666897,-93.098633,0.067886,0.000000
44.510002,24.977257,-93.098633,0.004169,0.002643,0.067123,111.104385,5.659927,0.671233,-93.098633,0.068216,0.000000
44.710003,25.589066,-93.098633,0.004169,0.002661,0.067583,113.825851,5.798565,0.675829,-93.098633,0.068554,0.000000
44.910004,25.673965,-93.098633,0.004178,0.002673,0.067904,114.203499,5.817804,0.679038,-93.098633,0.068884,0.000000
45.110001,25.840790,-93.143112,0.004212,0.002685,0.068190,114.945572,5.855607,0.681900,-93.143112,0.069213,0.000000
45.310001,26.009850,-93.143112,0.004208,0.002697,0.068494,115.697586,5.893917,0.684935,-93.143112,0.069552,0.000000
45.510002,26.239227,-93.143112,0.004230,0.002709,0.068814,116.717911,5.945894,0.688144,-93.143112,0.069881,0.000000
45.710003,26.552025,-93.143112,0.004247,0.002725,0.069205,118.109306,6.016775,0.692046,-93.143112,0.070219,0.000000
45.910004,26.537125,-93.143112,0.004243,0.002728,0.069300,118.043022,6.013398,0.693000,-93.143112,0.070549,0.000000
46.110001,26.829437,-93.187592,0.004251,0.002741,0.069630,119.343300,6.079638,0.696296,-93.187592,0.070887,0.000000
46.310001,27.490028,-93.143112,0.004251,0.002762,0.070167,122.281754,6.229330,0.701672,-93.143112,0.071217,0.000000
46.510002,27.808777,-93.187592,0.004286,0.002775,0.070497,123.699615,6.301559,0.704968,-93.187592,0.071546,0.000000
46.710003,28.474205,-93.187592,0.004299,0.002795,0.070991,126.659592,6.452347,0.709911,-93.187592,0.071884,0.000000
46.910004,28.681244,-93.143112,0.004303,0.002807,0.071303,127.580544,6.499263,0.713033,-93.143112,0.072214,0.000000
47.110001,28.807854,-93.187592,0.004303,0.002818,0.071589,128.143738,6.527953,0.715895,-93.187592,0.072552,0.000000
47.310001,28.935951,-93.187592,0.004324,0.002829,0.071858,128.713547,6.556981,0.718583,-93.187592,0.072882,0.000000
47.510002,29.201454,-93.143112,0.004329,0.002843,0.072205,129.894562,6.617144,0.722052,-93.143112,0.073220,0.000000
47.710003,29.745117,-93.187592,0.004342,0.002858,0.072604,132.312897,6.740340,0.726041,-93.187592,0.073549,0.000000
47.910004,29.943962,-93.232071,0.004363,0.002870,0.072899,133.197403,6.785399,0.728990,-93.232071,0.073888,0.000000
48.110001,29.917526,-93.232071,0.004363,0.002877,0.073072,133.079803,6.779408,0.730724,-93.232071,0.074217,0.000000
48.310001,30.565826,-93.232071,0.004406,0.002896,0.073558,135.963593,6.926315,0.735581,-93.232071,0.074547,0.000000
48.510002,31.147469,-93.232071,0.004393,0.002911,0.073948,138.550858,7.058117,0.739483,-93.232071,0.074885,0.000000
48.710003,31.378342,-93.276558,0.004406,0.002924,0.074261,139.577835,7.110434,0.742606,-93.276558,0.075214,0.000000
48.910004,31.644218,-93.232071,0.004424,0.002937,0.074607,140.760513,7.170682,0.746075,-93.232071,0.075553,0.000000
49.110001,31.965202,-93.232071,0.004437,0.002951,0.074954,142.188324,7.243418,0.749544,-93.232071,0.075882,0.000000
49.310001,32.034836,-93.276558,0.004458,0.002960,0.075180,142.498062,7.259198,0.751798,-93.276558,0.076220,0.000000
49.510002,32.543121,-93.321037,0.004454,0.002976,0.075596,144.759033,7.374377,0.755961,-93.321037,0.076550,0.000000
49.710003,32.900230,-93.321037,0.004449,0.002989,0.075908,146.347534,7.455299,0.759082,-93.321037,0.076888,0.000000
49.910004,33.102051,-93.276558,0.004467,0.003000,0.076203,147.245270,7.501032,0.762032,-93.276558,0.077218,0.000000
50.110001,33.033905,-93.321037,0.004484,0.003008,0.076411,146.942154,7.485590,0.764113,-93.321037,0.077547,0.000000
50.310001,33.729874,-93.321037,0.004488,0.003024,0.076819,150.037964,7.643299,0.768189,-93.321037,0.077886,0.000000
50.510002,34.368492,-93.276558,0.004506,0.003041,0.077235,152.878693,7.788012,0.772351,-93.276558,0.078215,0.000000
50.710003,34.828743,-93.276558,0.004523,0.003054,0.077582,154.925980,7.892306,0.775820,-93.276558,0.078553,0.000000
50.910004,35.042862,-93.365517,0.004527,0.003066,0.077877,155.878433,7.940826,0.778769,-93.365517,0.078883,0.000000
51.110001,35.567162,-93.365517,0.004557,0.003081,0.078258,158.210632,8.059634,0.782585,-93.365517,0.079221,0.000000
51.310001,35.688553,-93.321037,0.004557,0.003091,0.078501,158.750610,8.087142,0.785013,-93.321037,0.079551,0.000000
51.510002,36.220299,-93.321037,0.004575,0.003105,0.078874,161.115936,8.207637,0.788742,-93.321037,0.079880,0.000000
51.710003,36.801575,-93.409996,0.004579,0.003121,0.079264,163.701584,8.339356,0.792644,-93.409996,0.080218,0.000000
51.910004,36.841415,-93.365517,0.004587,0.003128,0.079455,163.878799,8.348384,0.794553,-93.365517,0.080548,0.000000
52.110001,37.156815,-93.365517,0.004587,0.003141,0.079793,165.281769,8.419854,0.797934,-93.365517,0.080886,0.000000
52.310001,37.773468,-93.409996,0.004592,0.003158,0.080201,168.024780,8.559590,0.802011,-93.409996,0.081216,0.000000
52.510002,38.186050,-93.409996,0.004609,0.003169,0.080496,169.860031,8.653083,0.804959,-93.409996,0.081554,0.000000
52.710003,38.626945,-93.409996,0.004609,0.003182,0.080834,171.821228,8.752992,0.808341,-93.409996,0.081883,0.000000
52.910004,39.328491,-93.409996,0.004652,0.003200,0.081285,174.941864,8.911963,0.812851,-93.409996,0.082222,0.000000
53.110004,39.335571,-93.409996,0.004639,0.003206,0.081441,174.973358,8.913568,0.814412,-93.409996,0.082551,0.000000
53.310001,39.404457,-93.454475,0.004648,0.003215,0.081649,175.279785,8.929178,0.816494,-93.454475,0.082881,0.000000
53.510002,40.157394,-93.454475,0.004656,0.003233,0.082126,178.629013,9.099795,0.821263,-93.454475,0.083219,0.000000
53.710003,40.740898,-93.454475,0.004678,0.003247,0.082482,181.224564,9.232019,0.824818,-93.454475,0.083549,0.000000
53.910004,40.758400,-93.365517,0.004656,0.003253,0.082621,181.302414,9.235986,0.826207,-93.365517,0.083887,0.000000
54.110004,41.451759,-93.454475,0.004687,0.003269,0.083037,184.386627,9.393103,0.830369,-93.454475,0.084216,0.000000
54.310001,42.221085,-93.454475,0.004712,0.003288,0.083505,187.808762,9.567434,0.835052,-93.454475,0.084555,0.000000
54.510002,42.738304,-93.498962,0.004700,0.003302,0.083869,190.109467,9.684638,0.838694,-93.498962,0.084884,0.000000
54.710003,43.100998,-93.498962,0.004743,0.003312,0.084130,191.722809,9.766826,0.841296,-93.498962,0.085222,0.000000
54.910004,43.564606,-93.498962,0.004721,0.003327,0.084511,193.785049,9.871881,0.845111,-93.498962,0.085552,0.000000
55.110004,44.015175,-93.498962,0.004756,0.003340,0.084832,195.789276,9.973982,0.848321,-93.498962,0.085881,0.000000
55.310001,44.395737,-93.498962,0.004734,0.003352,0.085144,197.482101,10.060217,0.851442,-93.498962,0.086220,0.000000
55.510002,45.086861,-93.498962,0.004777,0.003368,0.085543,200.556366,10.216829,0.855432,-93.498962,0.086549,0.000000
55.710003,45.446571,-93.587921,0.004773,0.003378,0.085795,202.156448,10.298341,0.857947,-93.587921,0.086887,0.000000
55.910004,45.400398,-93.498962,0.004773,0.003383,0.085933,201.951065,10.287878,0.859334,-93.498962,0.087217,0.000000
56.110004,46.340263,-93.543442,0.004781,0.003403,0.086436,206.131790,10.500854,0.864364,-93.543442,0.087555,0.000000
56.310001,47.226883,-93.543442,0.004777,0.003421,0.086905,210.075668,10.701764,0.869047,-93.543442,0.087885,0.000000
56.510002,47.518456,-93.543442,0.004807,0.003433,0.087200,211.372650,10.767836,0.871995,-93.543442,0.088214,0.000000
56.710003,48.128395,-93.543442,0.004816,0.003447,0.087564,214.085800,10.906051,0.875638,-93.543442,0.088552,0.000000
56.910004,48.455711,-93.543442,0.004846,0.003458,0.087833,215.541763,10.980221,0.878327,-93.543442,0.088882,0.000000
57.110004,48.758453,-93.543442,0.004838,0.003467,0.088058,216.888428,11.048823,0.880581,-93.543442,0.089220,0.000000
57.310001,49.483833,-93.632401,0.004850,0.003485,0.088509,220.115082,11.213197,0.885091,-93.632401,0.089550,0.000000
57.510002,50.105324,-93.587921,0.004859,0.003498,0.088839,222.879608,11.354029,0.888386,-93.587921,0.089888,0.000000
57.710003,50.750648,-93.587921,0.004881,0.003511,0.089185,225.750153,11.500261,0.891855,-93.587921,0.090218,0.000000
57.910004,50.691437,-93.587921,0.004872,0.003517,0.089342,225.486771,11.486843,0.893416,-93.587921,0.090556,0.000000
58.110004,51.563164,-93.632401,0.004898,0.003537,0.089827,229.364410,11.684380,0.898273,-93.632401,0.090885,0.000000
58.310001,52.197685,-93.543442,0.004907,0.003548,0.090131,232.186905,11.828165,0.901307,-93.543442,0.091215,0.000000
58.510002,53.071640,-93.587921,0.004919,0.003565,0.090547,236.074448,12.026206,0.905471,-93.587921,0.091553,0.000000
58.710003,53.624245,-93.543442,0.004937,0.003578,0.090885,238.532547,12.151428,0.908853,-93.543442,0.091883,0.000000
58.910004,54.194717,-93.587921,0.004924,0.003591,0.091215,241.070145,12.280698,0.912148,-93.587921,0.092221,0.000000
59.110004,54.217430,-93.632401,0.004941,0.003597,0.091362,241.171173,12.285846,0.913623,-93.632401,0.092550,0.000000
59.310001,54.973351,-93.632401,0.004945,0.003616,0.091857,244.533676,12.457140,0.918566,-93.632401,0.092889,0.000000
59.510002,55.991417,-93.632401,0.004967,0.003630,0.092212,249.062256,12.687837,0.922122,-93.632401,0.093218,0.000000
59.710003,56.154884,-93.632401,0.004971,0.003637,0.092386,249.789398,12.724878,0.923856,-93.632401,0.093548,0.000000
59.910004,56.806168,-93.632401,0.004971,0.003651,0.092741,252.686447,12.872461,0.927411,-93.632401,0.093886,0.000000
60.110004,56.977829,-93.587921,0.004984,0.003658,0.092915,253.450043,12.911361,0.929146,-93.587921,0.094215,0.000000
60.310001,57.815292,-93.632401,0.004984,0.003675,0.093348,257.175262,13.101132,0.933482,-93.632401,0.094554,0.000000
60.510002,58.893684,-93.676880,0.004993,0.003691,0.093756,261.972198,13.345500,0.937558,-93.676880,0.094883,0.000000
60.710003,59.396019,-93.721367,0.005014,0.003704,0.094085,264.206696,13.459331,0.940853,-93.721367,0.095221,0.000000
60.910004,60.055115,-93.632401,0.005023,0.003719,0.094467,267.138489,13.608684,0.944669,-93.632401,0.095551,0.000000
61.110004,60.499359,-93.676880,0.005053,0.003730,0.094744,269.114594,13.709351,0.947444,-93.676880,0.095889,0.000000
61.310001,61.117126,-93.632401,0.005036,0.003743,0.095083,271.862549,13.849339,0.950826,-93.632401,0.096219,0.000000
61.510002,62.020874,-93.676880,0.005044,0.003755,0.095386,275.882629,14.054132,0.953862,-93.676880,0.096548,0.000000
61.710003,62.263657,-93.676880,0.005053,0.003766,0.095655,276.962585,14.109147,0.956550,-93.676880,0.096886,0.000000
61.910004,62.674385,-93.721367,0.005066,0.003772,0.095820,278.789581,14.202218,0.958198,-93.721367,0.097216,0.000000
62.110004,63.749420,-93.676880,0.005062,0.003797,0.096436,283.571594,14.445825,0.964355,-93.676880,0.097554,0.000000
62.310001,65.283966,-93.676880,0.005083,0.003814,0.096869,290.397583,14.793558,0.968691,-93.676880,0.097884,0.000000
62.510002,65.721130,-93.721367,0.005101,0.003824,0.097121,292.342194,14.892621,0.971206,-93.721367,0.098222,0.000000
62.710003,66.375763,-93.721367,0.005109,0.003839,0.097520,295.254150,15.040963,0.975195,-93.721367,0.098552,0.000000
62.910004,66.792084,-93.810326,0.005113,0.003849,0.097762,297.106018,15.135303,0.977624,-93.810326,0.098890,0.000000
63.110004,67.453781,-93.721367,0.005126,0.003852,0.097840,300.049408,15.285245,0.978404,-93.721367,0.098083,0.000000
63.310001,66.922775,-93.765846,0.005122,0.003852,0.097832,297.687378,15.164918,0.978318,-93.765846,0.098083,0.000000
63.510002,66.395508,-93.721367,0.005148,0.003849,0.097771,295.341980,15.045437,0.977710,-93.721367,0.097832,0.000000
63.710003,65.940094,-93.765846,0.005144,0.003848,0.097736,293.316193,14.942239,0.977364,-93.765846,0.097832,0.000000
63.910004,65.552444,-93.765846,0.005144,0.003848,0.097728,291.591827,14.854396,0.977277,-93.765846,0.097832,0.000000
64.110001,65.197952,-93.810326,0.005139,0.003847,0.097719,290.014984,14.774067,0.977190,-93.810326,0.097832,0.000000
64.310005,64.880692,-93.810326,0.005148,0.003847,0.097710,288.603729,14.702175,0.977104,-93.810326,0.097832,0.000000
64.510002,64.598434,-93.765846,0.005131,0.003847,0.097710,287.348175,14.638215,0.977104,-93.765846,0.097832,0.000000
64.710007,64.329956,-93.854805,0.005139,0.003847,0.097702,286.153931,14.577376,0.977017,-93.854805,0.097832,0.000000
64.910004,64.096848,-93.810326,0.005144,0.003847,0.097702,285.117004,14.524553,0.977017,-93.810326,0.097832,0.000000
65.110001,63.879761,-93.810326,0.005174,0.003847,0.097702,284.151367,14.475361,0.977017,-93.810326,0.097832,0.000000
65.310005,63.667130,-93.810326,0.005139,0.003847,0.097702,283.205536,14.427178,0.977017,-93.810326,0.097832,0.000000
65.510002,63.465683,-93.765846,0.005152,0.003846,0.097693,282.309448,14.381530,0.976930,-93.765846,0.097832,0.000000
65.710007,63.295135,-93.854805,0.005157,0.003846,0.097693,281.550812,14.342883,0.976930,-93.854805,0.097832,0.000000
65.910004,63.128311,-93.810326,0.005144,0.003846,0.097693,280.808746,14.305079,0.976930,-93.810326,0.097832,0.000000
66.110001,62.966324,-93.810326,0.005165,0.003846,0.097693,280.088196,14.268373,0.976930,-93.810326,0.097832,0.000000
66.310005,62.825569,-93.810326,0.005157,0.003846,0.097693,279.462097,14.236478,0.976930,-93.810326,0.097832,0.000000
66.510002,62.676994,-93.810326,0.005165,0.003846,0.097693,278.801208,14.202810,0.976930,-93.810326,0.097832,0.000000
66.710007,62.552246,-93.810326,0.005165,0.003846,0.097693,278.246277,14.174541,0.976930,-93.810326,0.097832,0.000000
66.910004,62.417076,-93.854805,0.005161,0.003846,0.097693,277.645020,14.143911,0.976930,-93.854805,0.097832,0.000000
67.110001,62.291954,-93.810326,0.005165,0.003846,0.097693,277.088440,14.115559,0.976930,-93.810326,0.097832,0.000000
67.310005,62.176521,-93.943771,0.005161,0.003846,0.097693,276.574982,14.089401,0.976930,-93.943771,0.097832,0.000000
67.510002,62.078964,-93.899284,0.005157,0.003846,0.097684,276.141022,14.067294,0.976844,-93.899284,0.097832,0.000000
67.710007,61.966873,-93.899284,0.005148,0.003846,0.097684,275.642426,14.041894,0.976844,-93.899284,0.097832,0.000000
67.910004,61.865219,-93.943771,0.005152,0.003846,0.097684,275.190247,14.018859,0.976844,-93.943771,0.097832,0.000000
68.110001,61.754250,-93.943771,0.005170,0.003846,0.097684,274.696625,13.993712,0.976844,-93.943771,0.097832,0.000000
68.310005,61.659668,-93.943771,0.005170,0.003846,0.097684,274.275909,13.972281,0.976844,-93.943771,0.097832,0.000000
68.510002,61.581100,-93.943771,0.005157,0.003846,0.097684,273.926422,13.954476,0.976844,-93.943771,0.097832,0.000000
68.710007,61.489120,-93.943771,0.005157,0.003846,0.097684,273.517273,13.933634,0.976844,-93.943771,0.097832,0.000000
68.910004,61.396774,-93.899284,0.005182,0.003846,0.097684,273.106506,13.912708,0.976844,-93.899284,0.097832,0.000000
69.110001,61.316711,-93.899284,0.005182,0.003846,0.097684,272.750366,13.894566,0.976844,-93.899284,0.097832,0.000000
69.310005,61.242241,-93.943771,0.005174,0.003846,0.097684,272.419098,13.877689,0.976844,-93.943771,0.097832,0.000000
69.510002,61.175583,-93.943771,0.005161,0.003846,0.097684,272.122589,13.862585,0.976844,-93.943771,0.097832,0.000000
69.710007,61.101486,-93.988251,0.005174,0.003846,0.097684,271.792999,13.845795,0.976844,-93.988251,0.097832,0.000000
69.910004,61.010254,-93.943771,0.005182,0.003846,0.097684,271.387177,13.825121,0.976844,-93.943771,0.097832,0.000000
70.110001,60.948441,-93.943771,0.005165,0.003846,0.097684,271.112213,13.811114,0.976844,-93.943771,0.097832,0.000000
70.310005,60.862793,-93.988251,0.005161,0.003846,0.097684,270.731232,13.791706,0.976844,-93.988251,0.097832,0.000000
70.510002,60.812149,-93.988251,0.005174,0.003846,0.097684,270.505951,13.780231,0.976844,-93.988251,0.097832,0.000000
70.710007,60.757408,-94.032730,0.005157,0.003846,0.097684,270.262451,13.767825,0.976844,-94.032730,0.097832,0.000000
70.910004,60.688148,-93.943771,0.005165,0.003846,0.097684,269.954376,13.752131,0.976844,-93.943771,0.097832,0.000000
71.110001,60.615540,-93.988251,0.005174,0.003846,0.097684,269.631378,13.735678,0.976844,-93.988251,0.097832,0.000000
71.310005,60.557816,-94.032730,0.005170,0.003846,0.097684,269.374603,13.722597,0.976844,-94.032730,0.097832,0.000000
71.510002,60.497498,-94.032730,0.005174,0.003846,0.097684,269.106323,13.708929,0.976844,-94.032730,0.097832,0.000000
71.710007,60.464729,-94.032730,0.005174,0.003846,0.097684,268.960541,13.701503,0.976844,-94.032730,0.097832,0.000000
71.910004,60.396584,-94.032730,0.005170,0.003846,0.097684,268.657410,13.686062,0.976844,-94.032730,0.097832,0.000000
72.110001,60.349663,-94.121689,0.005157,0.003846,0.097684,268.448700,13.675429,0.976844,-94.121689,0.097832,0.000000
72.310005,60.295670,-94.077209,0.005174,0.003846,0.097684,268.208527,13.663194,0.976844,-94.077209,0.097832,0.000000
72.510002,60.231247,-94.121689,0.005182,0.003846,0.097684,267.921967,13.648596,0.976844,-94.121689,0.097832,0.000000
72.710007,60.186562,-94.032730,0.005195,0.003846,0.097684,267.723206,13.638470,0.976844,-94.032730,0.097832,0.000000
72.910004,60.134430,-94.077209,0.005170,0.003846,0.097684,267.491302,13.626657,0.976844,-94.077209,0.097832,0.000000
73.110001,60.099426,-94.121689,0.005170,0.003846,0.097684,267.335602,13.618725,0.976844,-94.121689,0.097832,0.000000
73.310005,60.054375,-94.166176,0.005200,0.003846,0.097684,267.135193,13.608516,0.976844,-94.166176,0.097832,0.000000
73.510002,59.997772,-94.121689,0.005174,0.003846,0.097684,266.883423,13.595690,0.976844,-94.121689,0.097832,0.000000
73.710007,59.973564,-94.077209,0.005170,0.003846,0.097684,266.775726,13.590203,0.976844,-94.077209,0.097832,0.000000
73.910004,59.920319,-94.121689,0.005178,0.003846,0.097684,266.538879,13.578138,0.976844,-94.121689,0.097832,0.000000
74.110001,59.867439,-94.166176,0.005182,0.003846,0.097684,266.303680,13.566155,0.976844,-94.166176,0.097832,0.000000
74.310005,59.820892,-94.166176,0.005187,0.003846,0.097684,266.096619,13.555608,0.976844,-94.166176,0.097832,0.000000
74.510002,59.780304,-94.121689,0.005182,0.003846,0.097684,265.916077,13.546411,0.976844,-94.121689,0.097832,0.000000
74.710007,59.743065,-94.121689,0.005161,0.003846,0.097684,265.750427,13.537972,0.976844,-94.121689,0.097832,0.000000
74.910004,59.708435,-94.210655,0.005178,0.003846,0.097684,265.596375,13.530125,0.976844,-94.210655,0.097832,0.000000
75.110001,59.661888,-94.210655,0.005170,0.003846,0.097684,265.389343,13.519577,0.976844,-94.210655,0.097832,0.000000
75.310005,59.629868,-94.166176,0.005182,0.003846,0.097684,265.246887,13.512321,0.976844,-94.166176,0.097832,0.000000
75.510002,59.584068,-94.255135,0.005182,0.003846,0.097684,265.043182,13.501944,0.976844,-94.255135,0.097832,0.000000
75.710007,59.564331,-94.210655,0.005195,0.003846,0.097684,264.955383,13.497471,0.976844,-94.210655,0.097832,0.000000
75.910004,59.515549,-94.166176,0.005182,0.003846,0.097684,264.738373,13.486417,0.976844,-94.166176,0.097832,0.000000
76.110001,59.470116,-94.210655,0.005191,0.003845,0.097676,264.536285,13.476121,0.976757,-94.210655,0.097832,0.000000
76.310005,59.433258,-94.166176,0.005182,0.003845,0.097676,264.372345,13.467769,0.976757,-94.166176,0.097832,0.000000
76.510002,59.390434,-94.210655,0.005187,0.003845,0.097676,264.181854,13.458065,0.976757,-94.210655,0.097832,0.000000
76.710007,59.377769,-94.210655,0.005174,0.003845,0.097676,264.125519,13.455195,0.976757,-94.210655,0.097832,0.000000
76.910004,59.351334,-94.166176,0.005182,0.003845,0.097676,264.007904,13.449204,0.976757,-94.166176,0.097832,0.000000
77.110001,59.302925,-94.255135,0.005187,0.003845,0.097676,263.792572,13.438234,0.976757,-94.255135,0.097832,0.000000
77.310005,59.275368,-94.210655,0.005182,0.003845,0.097676,263.670013,13.431991,0.976757,-94.210655,0.097832,0.000000
77.510002,59.237015,-94.210655,0.005187,0.003845,0.097676,263.499390,13.423300,0.976757,-94.210655,0.097832,0.000000
77.710007,59.207970,-94.299614,0.005191,0.003845,0.097676,263.370209,13.416718,0.976757,-94.299614,0.097832,0.000000
77.910004,59.180786,-94.255135,0.005187,0.003845,0.097676,263.249298,13.410559,0.976757,-94.255135,0.097832,0.000000
78.110001,59.142433,-94.255135,0.005170,0.003845,0.097676,263.078674,13.401867,0.976757,-94.255135,0.097832,0.000000
78.310005,59.114128,-94.299614,0.005195,0.003845,0.097676,262.952789,13.395452,0.976757,-94.299614,0.097832,0.000000
78.510002,59.085083,-94.344101,0.005182,0.003845,0.097676,262.823578,13.388871,0.976757,-94.344101,0.097832,0.000000
78.710007,59.067215,-94.255135,0.005191,0.003845,0.097676,262.744080,13.384822,0.976757,-94.255135,0.097832,0.000000
78.910004,59.035561,-94.344101,0.005187,0.003845,0.097676,262.603302,13.377649,0.976757,-94.344101,0.097832,0.000000
79.110001,59.002792,-94.299614,0.005178,0.003845,0.097676,262.457520,13.370224,0.976757,-94.299614,0.097832,0.000000
79.310005,58.977097,-94.299614,0.005191,0.003845,0.097676,262.343231,13.364401,0.976757,-94.299614,0.097832,0.000000
79.510002,58.944702,-94.299614,0.005191,0.003845,0.097676,262.199127,13.357060,0.976757,-94.299614,0.097832,0.000000
79.710007,58.920868,-94.344101,0.005200,0.003845,0.097676,262.093109,13.351660,0.976757,-94.344101,0.097832,0.000000
79.910004,58.886986,-94.344101,0.005195,0.003845,0.097676,261.942383,13.343982,0.976757,-94.344101,0.097832,0.000000
80.110001,58.856453,-94.344101,0.005182,0.003845,0.097676,261.806580,13.337063,0.976757,-94.344101,0.097832,0.000000
80.310005,58.817352,-94.299614,0.005195,0.003845,0.097676,261.632660,13.328202,0.976757,-94.299614,0.097832,0.000000
80.510002,58.809532,-94.388580,0.005187,0.003845,0.097676,261.597870,13.326430,0.976757,-94.388580,0.097832,0.000000
80.710007,58.794266,-94.388580,0.005191,0.003845,0.097676,261.529968,13.322971,0.976757,-94.388580,0.097832,0.000000
80.910004,58.774529,-94.344101,0.005170,0.003845,0.097676,261.442169,13.318499,0.976757,-94.344101,0.097832,0.000000
81.110001,58.729095,-94.388580,0.005204,0.003845,0.097676,261.240051,13.308203,0.976757,-94.388580,0.097832,0.000000
81.310005,58.699684,-94.388580,0.005200,0.003845,0.097676,261.109222,13.301538,0.976757,-94.388580,0.097832,0.000000
81.510002,58.685532,-94.388580,0.005178,0.003845,0.097676,261.046295,13.298332,0.976757,-94.388580,0.097832,0.000000
81.710007,58.659462,-94.388580,0.005200,0.003845,0.097676,260.930328,13.292423,0.976757,-94.388580,0.097832,0.000000
81.910004,58.640472,-94.388580,0.005200,0.003845,0.097676,260.845856,13.288121,0.976757,-94.388580,0.097832,0.000000
82.110001,58.610313,-94.477539,0.005187,0.003845,0.097676,260.711700,13.281287,0.976757,-94.477539,0.097832,0.000000
82.310005,58.582008,-94.477539,0.005191,0.003845,0.097676,260.585785,13.274873,0.976757,-94.477539,0.097832,0.000000
82.510002,58.563766,-94.388580,0.005195,0.003845,0.097676,260.504639,13.270739,0.976757,-94.388580,0.097832,0.000000
82.710007,58.552963,-94.477539,0.005195,0.003845,0.097676,260.456573,13.268291,0.976757,-94.477539,0.097832,0.000000
82.910004,58.520195,-94.433060,0.005200,0.003845,0.097676,260.310822,13.260866,0.976757,-94.433060,0.097832,0.000000
83.110001,58.500092,-94.433060,0.005195,0.003845,0.097676,260.221405,13.256310,0.976757,-94.433060,0.097832,0.000000
83.310005,58.485191,-94.522018,0.005191,0.003845,0.097676,260.155121,13.252934,0.976757,-94.522018,0.097832,0.000000
83.510002,58.464340,-94.477539,0.005195,0.003845,0.097676,260.062378,13.248209,0.976757,-94.477539,0.097832,0.000000
83.710007,58.439766,-94.477539,0.005208,0.003845,0.097676,259.953064,13.242640,0.976757,-94.477539,0.097832,0.000000
83.910004,58.411461,-94.477539,0.005200,0.003845,0.097676,259.827148,13.236226,0.976757,-94.477539,0.097832,0.000000
84.110001,58.376831,-94.522018,0.005200,0.003845,0.097676,259.673126,13.228379,0.976757,-94.522018,0.097832,0.000000
84.310005,58.377205,-94.522018,0.005182,0.003845,0.097676,259.674774,13.228463,0.976757,-94.522018,0.097832,0.000000
84.510002,58.358215,-94.477539,0.005182,0.003845,0.097676,259.590302,13.224160,0.976757,-94.477539,0.097832,0.000000
84.710007,58.331779,-94.477539,0.005187,0.003845,0.097676,259.472717,13.218170,0.976757,-94.477539,0.097676,0.000000
84.900002,58.307945,-94.566505,0.005195,0.003845,0.097676,259.366699,13.212770,0.976757,-94.566505,0.097676,0.000000