File: Data/Symmetrical membranes compression/Sartorius Cellulose Nitrate 045um test 2_10302023_171617.csv
Time (sec),S:Load (lbs),S:HL1 (DIM),S:LVDT (in),S:Position (in),Ch:Position (mm),Ch:Load (N),Ch:Stress (MPa),Ch:Strain (mm/mm),Ch:HL1 (DIM),Set Point (),Cycles ()
0.110000,0.002975,-97.769127,0.000009,-0.000000,-0.000000,0.013236,0.000674,-0.000000,-97.769127,0.000252,0.000000
0.330000,0.007446,-97.813614,0.000017,-0.000000,-0.000000,0.033123,0.001687,-0.000000,-97.813614,0.000252,0.000000
0.550000,-0.007446,-97.858093,0.000000,0.000102,0.002584,-0.033123,-0.001687,0.025843,-97.858093,0.003738,0.000000
0.770000,-0.014153,-97.902573,0.000103,0.000238,0.006036,-0.062954,-0.003207,0.060360,-97.902573,0.007397,0.000000
0.990000,-0.044685,-97.902573,0.000254,0.000390,0.009895,-0.198770,-0.010126,0.098950,-97.902573,0.011075,0.000000
1.210000,-0.046173,-97.858093,0.000401,0.000525,0.013338,-0.205388,-0.010463,0.133380,-97.858093,0.014734,0.000000
1.430000,0.002975,-97.858093,0.000543,0.000673,0.017084,0.013236,0.000674,0.170844,-97.858093,0.018394,0.000000
1.650000,0.007446,-97.947052,0.000694,0.000812,0.020631,0.033123,0.001687,0.206314,-97.947052,0.022071,0.000000
1.870000,0.024948,-97.947052,0.000849,0.000955,0.024256,0.110975,0.005653,0.242564,-97.947052,0.025731,0.000000
2.090000,0.031281,-97.902573,0.001018,0.001107,0.028107,0.139143,0.007088,0.281068,-97.902573,0.029390,0.000000
2.310000,0.018990,-97.902573,0.001168,0.001250,0.031741,0.084470,0.004303,0.317405,-97.902573,0.033067,0.000000
2.530000,0.005959,-97.947052,0.001306,0.001392,0.035348,0.026505,0.001350,0.353482,-97.947052,0.036727,0.000000
2.750000,-0.005211,-97.991531,0.001475,0.001538,0.039077,-0.023179,-0.001181,0.390772,-97.991531,0.040387,0.000000
2.970000,-0.013779,-97.902573,0.001608,0.001682,0.042711,-0.061291,-0.003122,0.427109,-97.902573,0.044064,0.000000
3.190000,0.039101,-97.858093,0.001785,0.001831,0.046501,0.173928,0.008860,0.465007,-97.858093,0.047723,0.000000
3.410000,0.080803,-97.947052,0.001936,0.001968,0.049978,0.359429,0.018310,0.499782,-97.947052,0.051383,0.000000
3.630000,0.195122,-97.991531,0.002061,0.002115,0.053716,0.867945,0.044215,0.537160,-97.991531,0.055060,0.000000
3.850000,0.363060,-97.947052,0.002212,0.002261,0.057436,1.614972,0.082271,0.574363,-97.947052,0.058720,0.000000
4.070000,0.683678,-97.991531,0.002376,0.002405,0.061096,3.041150,0.154924,0.610961,-97.991531,0.062223,0.000000
4.290000,0.573082,-97.947052,0.002397,-0.000000,-0.000000,2.549196,0.129862,-0.000000,-97.947052,0.000234,0.000000
4.510000,0.549622,-97.991531,0.002384,-0.000000,-0.000000,2.444839,0.124546,-0.000000,-97.991531,0.000234,0.000000
4.730000,0.636757,-97.947052,0.002389,-0.000000,-0.000000,2.832436,0.144291,-0.000000,-97.947052,0.000460,0.000000
4.950000,0.617767,-98.080498,0.002384,-0.000000,-0.000000,2.747966,0.139988,-0.000000,-98.080498,0.000824,0.000000
5.170000,0.627075,-98.080498,0.002397,-0.000000,-0.000000,2.789370,0.142097,-0.000000,-98.080498,0.001188,0.000000
5.390000,0.617393,-98.036018,0.002358,0.000000,0.000009,2.746303,0.139903,0.000086,-98.036018,0.001561,0.000000
5.610000,0.711227,-98.080498,0.002423,0.000036,0.000902,3.163697,0.161166,0.009018,-98.080498,0.001925,0.000000
5.830000,0.770813,-98.036018,0.002427,0.000053,0.001344,3.428747,0.174669,0.013442,-98.036018,0.002289,0.000000
6.050000,0.808418,-98.080498,0.002419,0.000066,0.001674,3.596024,0.183190,0.016737,-98.080498,0.002654,0.000000
6.270000,0.851242,-98.036018,0.002453,0.000074,0.001882,3.786514,0.192894,0.018818,-98.036018,0.003027,0.000000
6.490000,0.920502,-98.080498,0.002471,0.000093,0.002367,4.094596,0.208589,0.023675,-98.080498,0.003391,0.000000
6.710001,1.009499,-98.080498,0.002492,0.000110,0.002784,4.490474,0.228756,0.027838,-98.080498,0.003755,0.000000
6.930000,1.043015,-98.080498,0.002514,0.000123,0.003113,4.639560,0.236350,0.031133,-98.080498,0.004128,0.000000
7.150001,1.063126,-98.124977,0.002505,0.000136,0.003452,4.729019,0.240908,0.034515,-98.124977,0.004492,0.000000
7.370000,1.140205,-98.080498,0.002539,0.000153,0.003876,5.071887,0.258374,0.038765,-98.080498,0.004856,0.000000
7.590000,1.190102,-98.036018,0.002527,0.000162,0.004119,5.293837,0.269681,0.041193,-98.036018,0.005221,0.000000
7.810000,1.265694,-98.036018,0.002561,0.000178,0.004510,5.630086,0.286810,0.045095,-98.036018,0.005594,0.000000
8.030001,1.347244,-98.080498,0.002557,0.000194,0.004917,5.992842,0.305290,0.049171,-98.080498,0.005958,0.000000
8.250000,1.396767,-98.124977,0.002587,0.000203,0.005160,6.213129,0.316512,0.051599,-98.124977,0.006322,0.000000
8.470000,1.483162,-98.169456,0.002583,0.000220,0.005585,6.597434,0.336089,0.055849,-98.169456,0.006695,0.000000
8.690001,1.574760,-98.169456,0.002608,0.000239,0.006062,7.004884,0.356846,0.060619,-98.169456,0.007059,0.000000
8.910001,1.654076,-98.124977,0.002617,0.000250,0.006339,7.357696,0.374819,0.063394,-98.124977,0.007423,0.000000
9.130000,1.715149,-98.124977,0.002626,0.000263,0.006686,7.629364,0.388658,0.066863,-98.124977,0.007788,0.000000
9.350000,1.821274,-98.213943,0.002656,0.000281,0.007137,8.101431,0.412707,0.071373,-98.213943,0.008161,0.000000
9.570001,1.883835,-98.213943,0.002665,0.000294,0.007458,8.379716,0.426883,0.074581,-98.213943,0.008525,0.000000
9.790001,2.010063,-98.213943,0.002690,0.000311,0.007909,8.941208,0.455487,0.079091,-98.213943,0.008889,0.000000
10.010000,2.070389,-98.169456,0.002703,0.000323,0.008213,9.209549,0.469157,0.082126,-98.169456,0.009262,0.000000
10.230000,2.108376,-98.213943,0.002695,0.000331,0.008412,9.378523,0.477765,0.084120,-98.213943,0.009626,0.000000
10.450001,2.248756,-98.213943,0.002738,0.000353,0.008976,10.002968,0.509575,0.089758,-98.213943,0.009990,0.000000
10.670000,2.312057,-98.258423,0.002733,0.000367,0.009323,10.284545,0.523920,0.093227,-98.258423,0.010355,0.000000
10.890000,2.401428,-98.213943,0.002755,0.000379,0.009626,10.682086,0.544171,0.096262,-98.213943,0.010728,0.000000
11.110001,2.485588,-98.213943,0.002777,0.000398,0.010112,11.056448,0.563242,0.101118,-98.213943,0.011092,0.000000
11.330001,2.517609,-98.302902,0.002790,0.000405,0.010285,11.198882,0.570498,0.102853,-98.302902,0.011456,0.000000
11.550000,2.567879,-98.258423,0.002794,0.000417,0.010580,11.422495,0.581890,0.105801,-98.258423,0.011829,0.000000
11.770000,2.714226,-98.258423,0.002807,0.000437,0.011109,12.073480,0.615052,0.111091,-98.258423,0.012193,0.000000
11.990001,2.814018,-98.258423,0.002837,0.000450,0.011421,12.517379,0.637666,0.114213,-98.258423,0.012557,0.000000
12.210001,2.902267,-98.213943,0.002859,0.000465,0.011812,12.909930,0.657663,0.118116,-98.213943,0.012922,0.000000
12.430000,3.015099,-98.258423,0.002867,0.000484,0.012289,13.411828,0.683231,0.122885,-98.258423,0.013295,0.000000
12.650001,3.068718,-98.347382,0.002871,0.000496,0.012609,13.650339,0.695381,0.126095,-98.347382,0.013659,0.000000
12.870001,3.147667,-98.258423,0.002889,0.000511,0.012974,14.001522,0.713272,0.129737,-98.258423,0.014023,0.000000
13.090000,3.227348,-98.258423,0.002902,0.000526,0.013373,14.355963,0.731328,0.133726,-98.258423,0.014396,0.000000
13.310000,3.285072,-98.347382,0.002928,0.000539,0.013685,14.612732,0.744408,0.136848,-98.347382,0.014760,0.000000
13.530001,3.398270,-98.391861,0.002923,0.000556,0.014118,15.116259,0.770059,0.141184,-98.391861,0.015124,0.000000
13.750001,3.480934,-98.347382,0.002945,0.000571,0.014500,15.483969,0.788791,0.145000,-98.347382,0.015489,0.000000
13.970000,3.545357,-98.391861,0.002936,0.000580,0.014743,15.770535,0.803389,0.147428,-98.391861,0.015862,0.000000
14.190001,3.627281,-98.347382,0.002962,0.000595,0.015107,16.134953,0.821954,0.151070,-98.347382,0.016226,0.000000
14.410001,3.714043,-98.347382,0.002966,0.000612,0.015541,16.520887,0.841614,0.155407,-98.347382,0.016590,0.000000
14.630001,3.822403,-98.391861,0.002992,0.000628,0.015957,17.002897,0.866169,0.159569,-98.391861,0.016954,0.000000
14.850000,3.885704,-98.391861,0.003001,0.000642,0.016295,17.284475,0.880513,0.162951,-98.391861,0.017327,0.000000
15.070001,3.941193,-98.391861,0.003031,0.000656,0.016659,17.531300,0.893087,0.166594,-98.391861,0.017691,0.000000
15.290001,4.017151,-98.391861,0.003035,0.000665,0.016902,17.869179,0.910299,0.169022,-98.391861,0.018056,0.000000
15.510001,4.172806,-98.391861,0.003057,0.000684,0.017379,18.561567,0.945571,0.173792,-98.391861,0.018429,0.000000
15.730000,4.325478,-98.436348,0.003065,0.000702,0.017839,19.240685,0.980167,0.178388,-98.436348,0.018793,0.000000
15.950001,4.331810,-98.436348,0.003091,0.000711,0.018056,19.268854,0.981602,0.180557,-98.436348,0.019157,0.000000
16.170000,4.332550,-98.525307,0.003074,0.000722,0.018342,19.272144,0.981770,0.183418,-98.525307,0.019521,0.000000
16.390001,4.547409,-98.347382,0.003130,0.000743,0.018871,20.227886,1.030458,0.188708,-98.347382,0.019894,0.000000
16.610001,4.687050,-98.480827,0.003126,0.000759,0.019270,20.849039,1.062101,0.192698,-98.480827,0.020258,0.000000
16.830000,4.739182,-98.436348,0.003152,0.000772,0.019617,21.080933,1.073914,0.196166,-98.436348,0.020623,0.000000
17.050001,4.850151,-98.436348,0.003160,0.000789,0.020050,21.574549,1.099060,0.200502,-98.436348,0.020995,0.000000
17.270000,4.882545,-98.436348,0.003160,0.000796,0.020206,21.718647,1.106401,0.202063,-98.436348,0.021360,0.000000
17.490002,5.120491,-98.480827,0.003191,0.000817,0.020761,22.777082,1.160320,0.207614,-98.480827,0.021724,0.000000
17.710001,5.200928,-98.436348,0.003199,0.000829,0.021056,23.134882,1.178547,0.210562,-98.436348,0.022088,0.000000
17.930000,5.210983,-98.480827,0.003199,0.000835,0.021221,23.179611,1.180826,0.212210,-98.480827,0.022461,0.000000
18.150002,5.394928,-98.480827,0.003208,0.000857,0.021767,23.997839,1.222508,0.217673,-98.480827,0.022825,0.000000
18.370001,5.439613,-98.525307,0.003242,0.000868,0.022054,24.196609,1.232634,0.220535,-98.525307,0.023190,0.000000
18.590000,5.649261,-98.525307,0.003281,0.000887,0.022522,25.129169,1.280141,0.225218,-98.525307,0.023562,0.000000
18.810001,5.702881,-98.480827,0.003285,0.000900,0.022851,25.367682,1.292291,0.228514,-98.480827,0.023927,0.000000
19.030001,5.818321,-98.436348,0.003285,0.000914,0.023216,25.881186,1.318450,0.232156,-98.436348,0.024291,0.000000
19.250000,5.863373,-98.569786,0.003298,0.000925,0.023484,26.081585,1.328659,0.234844,-98.569786,0.024655,0.000000
19.470001,6.092384,-98.525307,0.003290,0.000944,0.023987,27.100279,1.380554,0.239874,-98.525307,0.025028,0.000000
19.690001,6.155319,-98.569786,0.003333,0.000954,0.024230,27.380228,1.394815,0.242302,-98.569786,0.025392,0.000000
19.910002,6.258461,-98.525307,0.003328,0.000966,0.024542,27.839025,1.418187,0.245425,-98.525307,0.025757,0.000000
20.130001,6.363472,-98.569786,0.003350,0.000981,0.024907,28.306137,1.441983,0.249067,-98.569786,0.026129,0.000000
20.350000,6.310593,-98.569786,0.003372,0.000995,0.025280,28.070917,1.430001,0.252796,-98.569786,0.026494,0.000000
20.570002,6.693764,-98.525307,0.003389,0.001018,0.025852,29.775349,1.516829,0.258520,-98.525307,0.026858,0.000000
20.790001,6.762657,-98.569786,0.003406,0.001032,0.026208,30.081802,1.532440,0.262076,-98.569786,0.027222,0.000000
21.010000,6.817398,-98.614265,0.003415,0.001045,0.026546,30.325302,1.544845,0.265457,-98.614265,0.027595,0.000000
21.230001,6.964485,-98.614265,0.003436,0.001060,0.026927,30.979578,1.578175,0.269274,-98.614265,0.027959,0.000000
21.450001,7.082153,-98.614265,0.003441,0.001072,0.027222,31.502991,1.604839,0.272222,-98.614265,0.028324,0.000000
21.670000,7.197586,-98.614265,0.003479,0.001087,0.027604,32.016460,1.630996,0.276038,-98.614265,0.028697,0.000000
21.890001,7.294029,-98.614265,0.003462,0.001099,0.027916,32.445461,1.652851,0.279160,-98.614265,0.029061,0.000000
22.110001,7.237801,-98.614265,0.003466,0.001103,0.028011,32.195347,1.640109,0.280113,-98.614265,0.029425,0.000000
22.330002,7.556923,-98.658752,0.003488,0.001130,0.028705,33.614872,1.712423,0.287051,-98.658752,0.029789,0.000000
22.550001,7.655235,-98.703232,0.003518,0.001145,0.029095,34.052189,1.734701,0.290954,-98.703232,0.030162,0.000000
22.770000,7.718536,-98.703232,0.003510,0.001156,0.029356,34.333763,1.749045,0.293555,-98.703232,0.030526,0.000000
22.990002,7.872322,-98.658752,0.003553,0.001176,0.029876,35.017838,1.783894,0.298759,-98.658752,0.030891,0.000000
23.210001,8.041756,-98.658752,0.003553,0.001193,0.030301,35.771515,1.822288,0.303008,-98.658752,0.031263,0.000000
23.430000,8.033562,-98.658752,0.003574,0.001200,0.030483,35.735065,1.820431,0.304830,-98.658752,0.031628,0.000000
23.650002,8.016060,-98.703232,0.003566,0.001212,0.030795,35.657215,1.816465,0.307951,-98.703232,0.031992,0.000000
23.870001,8.278214,-98.703232,0.003587,0.001229,0.031211,36.823334,1.875870,0.312114,-98.703232,0.032356,0.000000
24.090002,8.419342,-98.703232,0.003626,0.001246,0.031645,37.451103,1.907850,0.316450,-98.703232,0.032729,0.000000
24.310001,8.569405,-98.747711,0.003609,0.001263,0.032087,38.118614,1.941855,0.320873,-98.747711,0.033093,0.000000
24.530001,8.642021,-98.703232,0.003643,0.001276,0.032408,38.441631,1.958310,0.324082,-98.703232,0.033458,0.000000
24.750002,8.715378,-98.747711,0.003635,0.001290,0.032772,38.767937,1.974933,0.327725,-98.747711,0.033830,0.000000
24.970001,8.814056,-98.747711,0.003648,0.001304,0.033111,39.206882,1.997294,0.331106,-98.747711,0.034195,0.000000
25.190001,8.902679,-98.703232,0.003669,0.001316,0.033432,39.601097,2.017376,0.334315,-98.703232,0.034559,0.000000
25.410002,9.090355,-98.747711,0.003691,0.001332,0.033822,40.435917,2.059904,0.338217,-98.747711,0.034923,0.000000
25.630001,9.119774,-98.792191,0.003699,0.001343,0.034108,40.566780,2.066570,0.341080,-98.792191,0.035296,0.000000
25.850000,9.327560,-98.792191,0.003717,0.001360,0.034542,41.491062,2.113656,0.345416,-98.792191,0.035660,0.000000
26.070002,9.479485,-98.792191,0.003751,0.001377,0.034975,42.166855,2.148082,0.349752,-98.792191,0.036025,0.000000
26.290001,9.686523,-98.792191,0.003760,0.001395,0.035435,43.087807,2.194998,0.354348,-98.792191,0.036397,0.000000
26.510002,9.685410,-98.792191,0.003751,0.001409,0.035790,43.082855,2.194745,0.357903,-98.792191,0.036762,0.000000
26.730001,9.773285,-98.792191,0.003777,0.001422,0.036111,43.473743,2.214658,0.361112,-98.792191,0.037126,0.000000
26.950001,9.830261,-98.792191,0.003816,0.001435,0.036449,43.727184,2.227569,0.364495,-98.792191,0.037490,0.000000
27.170002,10.065224,-98.881157,0.003829,0.001454,0.036926,44.772350,2.280812,0.369265,-98.881157,0.037863,0.000000
27.390001,10.121452,-98.836670,0.003833,0.001466,0.037239,45.022469,2.293554,0.372386,-98.836670,0.038227,0.000000
27.610001,10.113266,-98.836670,0.003850,0.001473,0.037421,44.986053,2.291699,0.374208,-98.836670,0.038592,0.000000
27.830002,10.354935,-98.836670,0.003833,0.001493,0.037932,46.061050,2.346462,0.379324,-98.836670,0.038956,0.000000
28.050001,10.582077,-98.881157,0.003872,0.001510,0.038366,47.071430,2.397933,0.383661,-98.881157,0.039329,0.000000
28.270000,10.647987,-98.881157,0.003902,0.001524,0.038713,47.364613,2.412868,0.387129,-98.881157,0.039693,0.000000
28.490002,10.726189,-98.881157,0.003898,0.001539,0.039103,47.712471,2.430589,0.391032,-98.881157,0.040057,0.000000
28.710001,10.867691,-98.836670,0.003919,0.001553,0.039441,48.341904,2.462654,0.394414,-98.836670,0.040430,0.000000
28.930002,10.846466,-98.881157,0.003915,0.001563,0.039710,48.247490,2.457844,0.397103,-98.881157,0.040794,0.000000
29.150002,11.117554,-98.881157,0.003932,0.001581,0.040161,49.453350,2.519274,0.401612,-98.881157,0.041158,0.000000
29.370001,11.208786,-98.925636,0.003945,0.001595,0.040525,49.859169,2.539947,0.405254,-98.925636,0.041523,0.000000
29.590002,11.135796,-98.881157,0.003967,0.001604,0.040751,49.534492,2.523407,0.407509,-98.881157,0.041896,0.000000
29.810001,11.287354,-98.925636,0.003971,0.001614,0.040985,50.208656,2.557751,0.409850,-98.925636,0.042260,0.000000
30.030001,11.687653,-98.925636,0.003997,0.001638,0.041609,51.989277,2.648460,0.416094,-98.925636,0.042624,0.000000
30.250002,11.724144,-98.925636,0.004023,0.001649,0.041878,52.151596,2.656729,0.418783,-98.925636,0.042997,0.000000
30.470001,11.851128,-98.970116,0.004031,0.001667,0.042329,52.716450,2.685504,0.423292,-98.970116,0.043361,0.000000
30.690001,12.003799,-98.925636,0.004053,0.001682,0.042728,53.395565,2.720100,0.427282,-98.925636,0.043725,0.000000
30.910002,12.122215,-98.925636,0.004036,0.001698,0.043136,53.922306,2.746933,0.431358,-98.925636,0.044090,0.000000
31.130001,12.255150,-98.970116,0.004057,0.001712,0.043474,54.513630,2.777057,0.434740,-98.970116,0.044463,0.000000
31.350002,12.342659,-98.970116,0.004074,0.001722,0.043734,54.902889,2.796887,0.437342,-98.970116,0.044827,0.000000
31.570002,12.409683,-98.925636,0.004096,0.001736,0.044098,55.201027,2.812074,0.440984,-98.925636,0.045191,0.000000
31.790001,12.692314,-98.925636,0.004109,0.001754,0.044549,56.458233,2.876119,0.445493,-98.925636,0.045564,0.000000
32.010002,12.791740,-99.014595,0.004130,0.001766,0.044862,56.900505,2.898650,0.448616,-99.014595,0.045928,0.000000
32.230003,12.896744,-98.970116,0.004143,0.001779,0.045191,57.367580,2.922444,0.451911,-98.970116,0.046292,0.000000
32.450001,13.138420,-99.014595,0.004135,0.001798,0.045668,58.442612,2.977209,0.456681,-99.014595,0.046657,0.000000
32.670002,13.008461,-99.014595,0.004169,0.001803,0.045807,57.864525,2.947759,0.458068,-99.014595,0.047030,0.000000
32.890003,13.230392,-98.970116,0.004182,0.001821,0.046249,58.851727,2.998050,0.462491,-98.970116,0.047394,0.000000
33.110001,13.462006,-99.014595,0.004174,0.001835,0.046613,59.881992,3.050534,0.466133,-99.014595,0.047758,0.000000
33.330002,13.566643,-99.014595,0.004199,0.001849,0.046960,60.347443,3.074245,0.469602,-99.014595,0.048131,0.000000
33.550003,13.791931,-99.059074,0.004217,0.001866,0.047385,61.349575,3.125296,0.473852,-99.059074,0.048495,0.000000
33.770000,14.028015,-99.014595,0.004238,0.001883,0.047819,62.399727,3.178794,0.478188,-99.014595,0.048859,0.000000
33.990002,14.111801,-99.059074,0.004238,0.001897,0.048174,62.772427,3.197780,0.481743,-99.059074,0.049224,0.000000
34.210003,14.209732,-99.014595,0.004268,0.001909,0.048487,63.208046,3.219971,0.484866,-99.014595,0.049597,0.000000
34.430000,14.408211,-99.014595,0.004255,0.001926,0.048920,64.090919,3.264947,0.489201,-99.014595,0.049961,0.000000
34.650002,14.498695,-99.103561,0.004290,0.001938,0.049232,64.493416,3.285451,0.492324,-99.103561,0.050325,0.000000
34.870003,14.696793,-99.059074,0.004307,0.001955,0.049649,65.374596,3.330341,0.496486,-99.059074,0.050698,0.000000
35.090000,14.892662,-99.059074,0.004329,0.001970,0.050039,66.245872,3.374726,0.500389,-99.059074,0.051062,0.000000
35.310001,14.909424,-99.103561,0.004324,0.001980,0.050290,66.320427,3.378524,0.502904,-99.103561,0.051426,0.000000
35.530003,15.042732,-99.059074,0.004350,0.001994,0.050655,66.913414,3.408732,0.506547,-99.059074,0.051791,0.000000
35.750000,15.402069,-99.148041,0.004359,0.002015,0.051184,68.511826,3.490159,0.511836,-99.148041,0.052164,0.000000
35.970001,15.479149,-99.103561,0.004368,0.002028,0.051504,68.854691,3.507625,0.515045,-99.103561,0.052528,0.000000
36.190002,15.621025,-99.148041,0.004389,0.002040,0.051817,69.485786,3.539775,0.518167,-99.148041,0.052892,0.000000
36.410000,15.747627,-99.103561,0.004398,0.002055,0.052198,70.048943,3.568463,0.521982,-99.103561,0.053265,0.000000
36.630001,15.795296,-99.103561,0.004393,0.002066,0.052467,70.260986,3.579265,0.524672,-99.103561,0.053629,0.000000
36.850002,16.152031,-99.192520,0.004424,0.002084,0.052944,71.847824,3.660102,0.529441,-99.192520,0.053993,0.000000
37.070004,16.490517,-99.237000,0.004441,0.002102,0.053386,73.353485,3.736804,0.533864,-99.237000,0.054358,0.000000
37.290001,16.457748,-99.148041,0.004449,0.002112,0.053638,73.207718,3.729379,0.536379,-99.148041,0.054731,0.000000
37.510002,16.514343,-99.148041,0.004467,0.002125,0.053985,73.459465,3.742204,0.539848,-99.148041,0.055095,0.000000
37.730003,16.910919,-99.192520,0.004471,0.002141,0.054392,75.223526,3.832069,0.543923,-99.192520,0.055459,0.000000
37.950001,17.144402,-99.148041,0.004493,0.002158,0.054809,76.262108,3.884977,0.548086,-99.148041,0.055832,0.000000
38.170002,17.261696,-99.237000,0.004514,0.002172,0.055173,76.783859,3.911556,0.551729,-99.237000,0.056196,0.000000
38.390003,17.495178,-99.192520,0.004540,0.002188,0.055572,77.822441,3.964464,0.555718,-99.192520,0.056560,0.000000
38.610001,17.375267,-99.237000,0.004523,0.002194,0.055728,77.289047,3.937292,0.557279,-99.237000,0.056925,0.000000
38.830002,17.941650,-99.281487,0.004549,0.002217,0.056309,79.808449,4.065636,0.563089,-99.281487,0.057298,0.000000
39.050003,18.043678,-99.237000,0.004549,0.002230,0.056630,80.262291,4.088756,0.566298,-99.237000,0.057662,0.000000
39.270000,17.961014,-99.237000,0.004596,0.002238,0.056838,79.894577,4.070024,0.568380,-99.237000,0.058026,0.000000
39.490002,18.245132,-99.237000,0.004587,0.002255,0.057280,81.158401,4.134406,0.572802,-99.237000,0.058399,0.000000
39.710003,18.459991,-99.237000,0.004600,0.002270,0.057653,82.114143,4.183094,0.576531,-99.237000,0.058763,0.000000
39.930000,18.955620,-99.281487,0.004600,0.002289,0.058130,84.318810,4.295405,0.581301,-99.281487,0.059127,0.000000
40.150002,19.018921,-99.281487,0.004622,0.002300,0.058416,84.600388,4.309749,0.584163,-99.281487,0.059492,0.000000
40.370003,19.204735,-99.325966,0.004635,0.002316,0.058815,85.426926,4.351855,0.588152,-99.325966,0.059865,0.000000
40.590000,19.186493,-99.281487,0.004648,0.002322,0.058989,85.345779,4.347722,0.589886,-99.281487,0.060229,0.000000
40.810001,19.707443,-99.281487,0.004665,0.002343,0.059518,87.663086,4.465770,0.595177,-99.281487,0.060593,0.000000
41.030003,19.780052,-99.237000,0.004669,0.002354,0.059804,87.986069,4.482224,0.598039,-99.237000,0.060957,0.000000
41.250004,19.873894,-99.325966,0.004695,0.002368,0.060159,88.403496,4.503489,0.601594,-99.325966,0.061330,0.000000
41.470001,20.067520,-99.325966,0.004712,0.002379,0.060428,89.264786,4.547365,0.604282,-99.325966,0.061694,0.000000
41.690002,19.711533,-99.281487,0.004708,0.002379,0.060428,87.681274,4.466697,0.604282,-99.281487,0.062059,0.000000
41.910004,21.150009,-99.325966,0.004734,0.002420,0.061469,94.079941,4.792661,0.614690,-99.325966,0.062432,0.000000
42.130001,21.221878,-99.370445,0.004738,0.002433,0.061798,94.399628,4.808946,0.617984,-99.370445,0.062796,0.000000
42.350002,21.222252,-99.325966,0.004760,0.002444,0.062076,94.401291,4.809031,0.620760,-99.325966,0.063160,0.000000
42.570004,21.477699,-99.370445,0.004790,0.002459,0.062458,95.537575,4.866916,0.624576,-99.370445,0.063524,0.000000
42.790001,21.626648,-99.370445,0.004786,0.002470,0.062744,96.200134,4.900669,0.627437,-99.370445,0.063897,0.000000
43.010002,21.978165,-99.370445,0.004807,0.002488,0.063203,97.763756,4.980323,0.632034,-99.370445,0.064261,0.000000
43.230003,22.104774,-99.370445,0.004812,0.002500,0.063507,98.326950,5.009014,0.635069,-99.370445,0.064626,0.000000
43.450001,22.367294,-99.414925,0.004825,0.002514,0.063845,99.494698,5.068501,0.638451,-99.414925,0.064999,0.000000
43.670002,22.678596,-99.370445,0.004842,0.002529,0.064244,100.879433,5.139043,0.642440,-99.370445,0.065363,0.000000
43.890003,22.955269,-99.414925,0.004863,0.002545,0.064652,102.110138,5.201738,0.646517,-99.414925,0.065727,0.000000
44.110001,23.141830,-99.370445,0.004881,0.002559,0.064999,102.940002,5.244014,0.649986,-99.370445,0.066091,0.000000
44.330002,23.595383,-99.459404,0.004889,0.002575,0.065406,104.957504,5.346790,0.654061,-99.459404,0.066464,0.000000
44.550003,23.959564,-99.414925,0.004898,0.002592,0.065831,106.577461,5.429315,0.658311,-99.414925,0.066828,0.000000
44.770000,23.929398,-99.414925,0.004911,0.002600,0.066048,106.443275,5.422479,0.660478,-99.414925,0.067193,0.000000
44.990002,23.522392,-99.459404,0.004881,0.002605,0.066178,104.632828,5.330250,0.661779,-99.459404,0.067565,0.000000
45.210003,24.511787,-99.414925,0.004928,0.002629,0.066768,109.033875,5.554451,0.667677,-99.414925,0.067930,0.000000
45.430000,24.911346,-99.459404,0.004941,0.002646,0.067210,110.811203,5.644992,0.672100,-99.459404,0.068294,0.000000
45.650002,25.376434,-99.503891,0.004937,0.002664,0.067670,112.880020,5.750382,0.676696,-99.503891,0.068658,0.000000
45.870003,25.418518,-99.503891,0.004954,0.002674,0.067912,113.067215,5.759919,0.679124,-99.503891,0.069031,0.000000
46.090004,25.650505,-99.503891,0.004988,0.002688,0.068277,114.099144,5.812488,0.682767,-99.503891,0.069395,0.000000
46.310001,25.940956,-99.503891,0.005001,0.002702,0.068624,115.391136,5.878305,0.686236,-99.503891,0.069760,0.000000
46.530003,26.255608,-99.503891,0.005001,0.002718,0.069049,116.790779,5.949606,0.690485,-99.503891,0.070132,0.000000
46.750004,26.649208,-99.503891,0.005023,0.002731,0.069369,118.541595,6.038797,0.693694,-99.503891,0.070497,0.000000
46.970001,26.723312,-99.503891,0.005027,0.002743,0.069682,118.871231,6.055589,0.696815,-99.503891,0.070861,0.000000
47.190002,27.231598,-99.503891,0.005036,0.002760,0.070115,121.132195,6.170768,0.701152,-99.503891,0.071225,0.000000
47.410004,27.513855,-99.459404,0.005066,0.002772,0.070401,122.387741,6.234729,0.704013,-99.459404,0.071598,0.000000
47.630001,28.266792,-99.548370,0.005088,0.002798,0.071060,125.736969,6.405346,0.710605,-99.548370,0.071962,0.000000
47.850002,28.515541,-99.592850,0.005083,0.002809,0.071338,126.843460,6.461714,0.713380,-99.592850,0.072327,0.000000
48.070004,28.694649,-99.503891,0.005113,0.002821,0.071642,127.640175,6.502300,0.716415,-99.503891,0.072700,0.000000
48.290001,28.865944,-99.548370,0.005122,0.002834,0.071971,128.402130,6.541116,0.719710,-99.548370,0.073064,0.000000
48.510002,29.316887,-99.548370,0.005118,0.002850,0.072396,130.408020,6.643301,0.723960,-99.548370,0.073428,0.000000
48.730003,29.647179,-99.592850,0.005152,0.002865,0.072760,131.877243,6.718147,0.727603,-99.592850,0.073792,0.000000
48.950001,29.626694,-99.592850,0.005135,0.002872,0.072951,131.786118,6.713505,0.729510,-99.592850,0.074165,0.000000
49.170002,30.331596,-99.592850,0.005157,0.002892,0.073454,134.921677,6.873238,0.734540,-99.592850,0.074529,0.000000
49.390003,30.831696,-99.637329,0.005157,0.002910,0.073905,137.146225,6.986562,0.739049,-99.637329,0.074894,0.000000
49.610001,31.130707,-99.548370,0.005200,0.002922,0.074226,138.476303,7.054319,0.742259,-99.548370,0.075267,0.000000
49.830002,31.473289,-99.637329,0.005191,0.002939,0.074642,140.000183,7.131949,0.746421,-99.637329,0.075631,0.000000
50.050003,31.731346,-99.637329,0.005217,0.002952,0.074980,141.148071,7.190426,0.749803,-99.637329,0.075995,0.000000
50.270004,31.862793,-99.592850,0.005230,0.002963,0.075258,141.732788,7.220212,0.752578,-99.592850,0.076359,0.000000
50.490002,32.542000,-99.592850,0.005256,0.002982,0.075735,144.754044,7.374123,0.757348,-99.592850,0.076732,0.000000
50.710003,32.867828,-99.637329,0.005251,0.002994,0.076056,146.203400,7.447957,0.760557,-99.637329,0.077096,0.000000
50.930004,32.903572,-99.681808,0.005256,0.003004,0.076298,146.362396,7.456056,0.762985,-99.681808,0.077461,0.000000
51.150002,33.353027,-99.681808,0.005290,0.003017,0.076619,148.361679,7.557904,0.766193,-99.681808,0.077833,0.000000
51.370003,34.164803,-99.637329,0.005273,0.003037,0.077140,151.972626,7.741855,0.771397,-99.637329,0.078198,0.000000
51.590004,34.449295,-99.726295,0.005290,0.003050,0.077478,153.238113,7.806322,0.774779,-99.726295,0.078562,0.000000
51.810001,34.815338,-99.637329,0.005299,0.003065,0.077859,154.866364,7.889268,0.778595,-99.637329,0.078926,0.000000
52.030003,35.345596,-99.726295,0.005329,0.003081,0.078267,157.225067,8.009426,0.782671,-99.726295,0.079299,0.000000
52.250004,35.410385,-99.726295,0.005333,0.003090,0.078493,157.513260,8.024108,0.784926,-99.726295,0.079663,0.000000
52.470001,36.302589,-99.770775,0.005342,0.003111,0.079013,161.481979,8.226285,0.790129,-99.770775,0.080028,0.000000
52.690002,36.490639,-99.637329,0.005364,0.003122,0.079299,162.318466,8.268897,0.792991,-99.637329,0.080400,0.000000
52.910004,36.755020,-99.681808,0.005364,0.003136,0.079655,163.494492,8.328806,0.796546,-99.681808,0.080765,0.000000
53.130001,37.588020,-99.681808,0.005364,0.003154,0.080114,167.199860,8.517568,0.801143,-99.681808,0.081129,0.000000
53.350002,37.868042,-99.726295,0.005394,0.003165,0.080383,168.445465,8.581020,0.803831,-99.726295,0.081493,0.000000
53.570004,38.258667,-99.770775,0.005398,0.003178,0.080713,170.183044,8.669538,0.807127,-99.770775,0.081866,0.000000
53.790001,39.051071,-99.770775,0.005415,0.003197,0.081216,173.707840,8.849099,0.812156,-99.770775,0.082230,0.000000
54.010002,38.871964,-99.815254,0.005411,0.003202,0.081337,172.911133,8.808513,0.813371,-99.815254,0.082595,0.000000
54.230003,39.471855,-99.815254,0.005415,0.003219,0.081771,175.579575,8.944450,0.817707,-99.815254,0.082959,0.000000
54.450001,40.145477,-99.815254,0.005433,0.003236,0.082196,178.576004,9.097095,0.821956,-99.815254,0.083332,0.000000
54.670002,40.555458,-99.770775,0.005445,0.003247,0.082473,180.399689,9.189998,0.824731,-99.770775,0.083696,0.000000
54.890003,40.048660,-99.770775,0.005463,0.003247,0.082482,178.145340,9.075156,0.824818,-99.770775,0.084060,0.000000
55.110004,42.055748,-99.770775,0.005493,0.003282,0.083366,187.073303,9.529969,0.833664,-99.770775,0.084433,0.000000
55.330002,42.392372,-99.815254,0.005489,0.003294,0.083679,188.570694,9.606249,0.836785,-99.815254,0.084797,0.000000
55.550003,42.783363,-99.859734,0.005506,0.003308,0.084017,190.309906,9.694848,0.840168,-99.859734,0.085162,0.000000
55.770004,43.445442,-99.815254,0.005514,0.003326,0.084468,193.254974,9.844878,0.844678,-99.815254,0.085526,0.000000
55.990002,43.780945,-99.815254,0.005527,0.003337,0.084763,194.747375,9.920904,0.847626,-99.815254,0.085899,0.000000
56.210003,44.394241,-99.815254,0.005536,0.003353,0.085179,197.475449,10.059878,0.851789,-99.815254,0.086263,0.000000
56.430004,44.917053,-99.815254,0.005540,0.003369,0.085569,199.801025,10.178349,0.855691,-99.815254,0.086627,0.000000
56.650002,45.198570,-99.859734,0.005545,0.003378,0.085812,201.053284,10.242143,0.858120,-99.859734,0.087000,0.000000
56.870003,45.788033,-99.859734,0.005579,0.003395,0.086237,203.675339,10.375717,0.862369,-99.859734,0.087364,0.000000
57.090004,46.731628,-99.815254,0.005592,0.003415,0.086749,207.872665,10.589539,0.867486,-99.815254,0.087729,0.000000
57.310001,47.267097,-99.859734,0.005592,0.003428,0.087078,210.254547,10.710877,0.870781,-99.859734,0.088093,0.000000
57.530003,47.583618,-99.948700,0.005596,0.003440,0.087364,211.662506,10.782602,0.873643,-99.948700,0.088466,0.000000
57.750004,48.122437,-99.948700,0.005605,0.003455,0.087746,214.059296,10.904700,0.877459,-99.948700,0.088830,0.000000
57.970001,48.340645,-99.904213,0.005639,0.003464,0.087997,215.029922,10.954147,0.879974,-99.904213,0.089194,0.000000
58.190002,49.333023,-99.904213,0.005644,0.003487,0.088561,219.444244,11.179023,0.885611,-99.904213,0.089567,0.000000
58.410004,50.097504,-99.904213,0.005639,0.003501,0.088925,222.844833,11.352257,0.889253,-99.904213,0.089931,0.000000
58.630001,50.340286,-99.859734,0.005639,0.003510,0.089159,223.924774,11.407272,0.891594,-99.859734,0.090295,0.000000
58.850002,50.875389,-99.993179,0.005652,0.003523,0.089489,226.305038,11.528528,0.894890,-99.993179,0.090660,0.000000
59.070004,51.677475,-100.037659,0.005700,0.003540,0.089914,229.872894,11.710283,0.899140,-100.037659,0.091033,0.000000
59.290001,51.347557,-99.948700,0.005687,0.003543,0.089983,228.405334,11.635523,0.899833,-99.948700,0.091397,0.000000
59.510002,53.062706,-99.993179,0.005704,0.003572,0.090729,236.034698,12.024181,0.907291,-99.993179,0.091761,0.000000
59.730003,53.814522,-99.993179,0.005713,0.003586,0.091093,239.378952,12.194545,0.910933,-99.993179,0.092134,0.000000
59.950005,53.760155,-99.993179,0.005717,0.003593,0.091258,239.137115,12.182225,0.912582,-99.993179,0.092498,0.000000
60.170002,54.982285,-99.993179,0.005747,0.003616,0.091839,244.573410,12.459164,0.918392,-99.993179,0.092862,0.000000
60.390003,55.529297,-99.993179,0.005743,0.003628,0.092151,247.006653,12.583118,0.921514,-99.993179,0.093227,0.000000
60.610004,55.655907,-99.993179,0.005743,0.003634,0.092316,247.569839,12.611809,0.923161,-99.993179,0.093600,0.000000
60.830002,56.432304,-100.037659,0.005760,0.003654,0.092802,251.023422,12.787743,0.928018,-100.037659,0.093964,0.000000
61.050003,56.564865,-100.037659,0.005777,0.003657,0.092897,251.613083,12.817781,0.928972,-100.037659,0.094328,0.000000
61.270004,58.263260,-100.082138,0.005790,0.003685,0.093608,259.167938,13.202643,0.936083,-100.082138,0.094701,0.000000
61.490002,58.753296,-100.037659,0.005782,0.003697,0.093895,261.347717,13.313687,0.938945,-100.037659,0.095065,0.000000
61.710003,59.492088,-100.037659,0.005782,0.003711,0.094250,264.634033,13.481100,0.942500,-100.037659,0.095430,0.000000
61.930004,59.809723,-100.082138,0.005803,0.003721,0.094502,266.046936,13.553077,0.945015,-100.082138,0.095794,0.000000
62.150002,60.678833,-100.126617,0.005799,0.003739,0.094979,269.912933,13.750020,0.949785,-100.126617,0.096167,0.000000
62.370003,61.600456,-100.082138,0.005825,0.003752,0.095308,274.012512,13.958862,0.953081,-100.082138,0.096531,0.000000
62.590004,62.067039,-100.082138,0.005833,0.003763,0.095586,276.087982,14.064592,0.955856,-100.082138,0.096895,0.000000
62.810001,62.827423,-100.082138,0.005851,0.003778,0.095950,279.470337,14.236897,0.959498,-100.082138,0.097268,0.000000
63.030003,63.701378,-100.126617,0.005842,0.003801,0.096540,283.357880,14.434938,0.965395,-100.126617,0.097632,0.000000
63.250004,65.131294,-100.171104,0.005829,0.003817,0.096947,289.718475,14.758963,0.969472,-100.171104,0.097997,0.000000
63.470001,65.775505,-100.126617,0.005868,0.003831,0.097303,292.584045,14.904942,0.973026,-100.126617,0.098361,0.000000
63.690002,66.355659,-100.126617,0.005864,0.003842,0.097598,295.164703,15.036407,0.975976,-100.126617,0.098734,0.000000
63.910004,67.217323,-100.126617,0.005890,0.003857,0.097970,298.997589,15.231664,0.979705,-100.126617,0.099098,0.000000
64.130005,67.273552,-100.171104,0.005902,0.003856,0.097944,299.247711,15.244405,0.979445,-100.171104,0.098187,0.000000
64.350006,66.666954,-100.126617,0.005920,0.003856,0.097944,296.549408,15.106948,0.979445,-100.126617,0.098187,0.000000
64.570000,66.207817,-100.171104,0.005902,0.003851,0.097823,294.507080,15.002906,0.978231,-100.171104,0.097944,0.000000
64.790001,65.730446,-100.260063,0.005924,0.003850,0.097788,292.383636,14.894732,0.977883,-100.260063,0.097944,0.000000
65.010002,65.326790,-100.171104,0.005950,0.003850,0.097780,290.588074,14.803262,0.977796,-100.171104,0.097944,0.000000
65.230003,64.952187,-100.171104,0.005898,0.003849,0.097771,288.921753,14.718376,0.977710,-100.171104,0.097944,0.000000
65.450005,64.638649,-100.171104,0.005911,0.003849,0.097762,287.527069,14.647327,0.977623,-100.171104,0.097944,0.000000
65.670006,64.349678,-100.215584,0.005928,0.003849,0.097762,286.241669,14.581845,0.977623,-100.215584,0.097944,0.000000
65.889999,64.093864,-100.215584,0.005933,0.003849,0.097754,285.103760,14.523878,0.977536,-100.215584,0.097944,0.000000
66.110001,63.851082,-100.171104,0.005937,0.003849,0.097754,284.023804,14.468863,0.977536,-100.171104,0.097944,0.000000
66.330002,63.625053,-100.171104,0.005924,0.003849,0.097754,283.018372,14.417643,0.977536,-100.171104,0.097944,0.000000
66.550003,63.414650,-100.215584,0.005946,0.003848,0.097745,282.082458,14.369965,0.977450,-100.215584,0.097944,0.000000
66.770004,63.215431,-100.260063,0.005937,0.003848,0.097745,281.196289,14.324821,0.977450,-100.260063,0.097944,0.000000
66.990005,63.044518,-100.260063,0.005928,0.003848,0.097745,280.436035,14.286092,0.977450,-100.260063,0.097944,0.000000
67.210007,62.864662,-100.260063,0.005928,0.003848,0.097745,279.635986,14.245337,0.977450,-100.260063,0.097944,0.000000
67.430000,62.720558,-100.260063,0.005946,0.003848,0.097745,278.994965,14.212682,0.977450,-100.260063,0.097944,0.000000
67.650002,62.576820,-100.260063,0.005950,0.003848,0.097745,278.355591,14.180110,0.977450,-100.260063,0.097944,0.000000
67.870003,62.430107,-100.260063,0.005946,0.003848,0.097745,277.702972,14.146865,0.977450,-100.260063,0.097944,0.000000
68.090004,62.302010,-100.349022,0.005941,0.003848,0.097745,277.133179,14.117838,0.977450,-100.349022,0.097944,0.000000
68.310005,62.161621,-100.304543,0.005950,0.003848,0.097745,276.508698,14.086025,0.977450,-100.304543,0.097944,0.000000
68.530006,62.052895,-100.260063,0.005954,0.003848,0.097745,276.025055,14.061387,0.977450,-100.260063,0.097944,0.000000
68.750000,61.918839,-100.349022,0.005954,0.003848,0.097745,275.428741,14.031010,0.977450,-100.349022,0.097944,0.000000
68.970001,61.824997,-100.349022,0.005954,0.003848,0.097745,275.011322,14.009745,0.977450,-100.349022,0.097944,0.000000
69.190002,61.717384,-100.304543,0.005946,0.003848,0.097745,274.532623,13.985359,0.977450,-100.304543,0.097944,0.000000
69.410004,61.634720,-100.349022,0.005950,0.003848,0.097745,274.164917,13.966627,0.977450,-100.349022,0.097944,0.000000
69.630005,61.522263,-100.304543,0.005937,0.003848,0.097745,273.664703,13.941144,0.977450,-100.304543,0.097944,0.000000
69.850006,61.412781,-100.349022,0.005954,0.003848,0.097736,273.177704,13.916335,0.977363,-100.349022,0.097944,0.000000
70.070000,61.313362,-100.349022,0.005941,0.003848,0.097736,272.735443,13.893806,0.977363,-100.349022,0.097944,0.000000
70.290001,61.212822,-100.349022,0.005959,0.003848,0.097736,272.288239,13.871023,0.977363,-100.349022,0.097944,0.000000
70.510002,61.151375,-100.393509,0.005959,0.003848,0.097736,272.014893,13.857100,0.977363,-100.393509,0.097944,0.000000
70.730003,61.076157,-100.304543,0.005967,0.003848,0.097736,271.680328,13.840055,0.977363,-100.304543,0.097944,0.000000
70.950005,60.997215,-100.349022,0.005967,0.003848,0.097736,271.329163,13.822166,0.977363,-100.349022,0.097944,0.000000
71.170006,60.918648,-100.437988,0.005950,0.003848,0.097736,270.979675,13.804362,0.977363,-100.437988,0.097944,0.000000
71.390007,60.838585,-100.393509,0.005950,0.003848,0.097736,270.623535,13.786221,0.977363,-100.393509,0.097944,0.000000
71.610001,60.777519,-100.393509,0.005954,0.003848,0.097736,270.351898,13.772383,0.977363,-100.393509,0.097944,0.000000
71.830002,60.694107,-100.349022,0.005946,0.003848,0.097736,269.980865,13.753482,0.977363,-100.349022,0.097944,0.000000
72.050003,60.655006,-100.437988,0.005954,0.003848,0.097736,269.806946,13.744621,0.977363,-100.437988,0.097944,0.000000
72.270004,60.567497,-100.482468,0.005954,0.003848,0.097736,269.417694,13.724792,0.977363,-100.482468,0.097944,0.000000
72.490005,60.520576,-100.482468,0.005963,0.003848,0.097736,269.208984,13.714159,0.977363,-100.482468,0.097944,0.000000
72.710007,60.450943,-100.393509,0.005954,0.003848,0.097736,268.899231,13.698380,0.977363,-100.393509,0.097944,0.000000
72.930000,60.383171,-100.437988,0.005959,0.003848,0.097736,268.597748,13.683022,0.977363,-100.437988,0.097944,0.000000
73.150002,60.343330,-100.393509,0.005950,0.003848,0.097736,268.420532,13.673994,0.977363,-100.393509,0.097944,0.000000
73.370003,60.257683,-100.482468,0.005950,0.003848,0.097736,268.039551,13.654586,0.977363,-100.482468,0.097944,0.000000
73.590004,60.223053,-100.482468,0.005976,0.003848,0.097736,267.885529,13.646739,0.977363,-100.482468,0.097944,0.000000
73.810005,60.167198,-100.437988,0.005963,0.003848,0.097736,267.637054,13.634083,0.977363,-100.437988,0.097944,0.000000
74.030006,60.126610,-100.437988,0.005959,0.003848,0.097736,267.456512,13.624885,0.977363,-100.437988,0.097944,0.000000
74.250000,60.069260,-100.482468,0.005950,0.003848,0.097736,267.201416,13.611889,0.977363,-100.482468,0.097944,0.000000
74.470001,60.009308,-100.526947,0.005963,0.003848,0.097736,266.934723,13.598304,0.977363,-100.526947,0.097944,0.000000
74.690002,59.962395,-100.526947,0.005959,0.003848,0.097736,266.726044,13.587672,0.977363,-100.526947,0.097944,0.000000
74.910004,59.901321,-100.526947,0.005959,0.003848,0.097736,266.454376,13.573833,0.977363,-100.526947,0.097944,0.000000
75.130005,59.869675,-100.526947,0.005963,0.003848,0.097736,266.313599,13.566663,0.977363,-100.526947,0.097944,0.000000
75.350006,59.822380,-100.526947,0.005950,0.003848,0.097736,266.103241,13.555945,0.977363,-100.526947,0.097944,0.000000
75.570007,59.785141,-100.571434,0.005976,0.003848,0.097736,265.937592,13.547506,0.977363,-100.571434,0.097944,0.000000
75.790001,59.725189,-100.571434,0.005963,0.003848,0.097736,265.670898,13.533921,0.977363,-100.571434,0.097944,0.000000
76.010002,59.681252,-100.526947,0.005959,0.003848,0.097736,265.475464,13.523965,0.977363,-100.526947,0.097944,0.000000
76.230003,59.644386,-100.526947,0.005959,0.003848,0.097736,265.311493,13.515611,0.977363,-100.526947,0.097944,0.000000
76.450005,59.590767,-100.660393,0.005946,0.003848,0.097736,265.072968,13.503460,0.977363,-100.660393,0.097944,0.000000
76.670006,59.572517,-100.615913,0.005954,0.003848,0.097736,264.991791,13.499325,0.977363,-100.615913,0.097944,0.000000
76.890007,59.521133,-100.571434,0.005967,0.003848,0.097736,264.763214,13.487681,0.977363,-100.571434,0.097944,0.000000
77.110001,59.420219,-100.526947,0.005963,0.003848,0.097728,264.314331,13.464814,0.977276,-100.526947,0.097944,0.000000
77.330002,59.379631,-100.615913,0.005963,0.003848,0.097728,264.133789,13.455617,0.977276,-100.615913,0.097944,0.000000
77.550003,59.329361,-100.615913,0.005967,0.003848,0.097728,263.910187,13.444225,0.977276,-100.615913,0.097944,0.000000
77.770004,59.306274,-100.615913,0.005954,0.003848,0.097728,263.807495,13.438993,0.977276,-100.615913,0.097944,0.000000
77.990005,59.270897,-100.615913,0.005980,0.003848,0.097728,263.650116,13.430978,0.977276,-100.615913,0.097944,0.000000
78.210007,59.248924,-100.660393,0.005963,0.003848,0.097728,263.552368,13.425998,0.977276,-100.660393,0.097944,0.000000
78.430000,59.199028,-100.660393,0.005959,0.003848,0.097728,263.330414,13.414692,0.977276,-100.660393,0.097944,0.000000
78.650002,59.150246,-100.615913,0.005963,0.003848,0.097728,263.113434,13.403637,0.977276,-100.615913,0.097944,0.000000
78.870003,59.119339,-100.660393,0.005959,0.003848,0.097728,262.975952,13.396634,0.977276,-100.660393,0.097944,0.000000
79.090004,59.093277,-100.704872,0.005937,0.003848,0.097728,262.860016,13.390728,0.977276,-100.704872,0.097944,0.000000
79.310005,59.067207,-100.615913,0.005989,0.003848,0.097728,262.744049,13.384820,0.977276,-100.615913,0.097944,0.000000
79.530006,59.027367,-100.660393,0.005959,0.003848,0.097728,262.566833,13.375793,0.977276,-100.660393,0.097944,0.000000
79.750000,59.007629,-100.704872,0.005976,0.003848,0.097728,262.479034,13.371320,0.977276,-100.704872,0.097944,0.000000
79.970001,58.956612,-100.704872,0.005967,0.003848,0.097728,262.252106,13.359759,0.977276,-100.704872,0.097944,0.000000
80.190002,58.950287,-100.660393,0.005967,0.003848,0.097728,262.223969,13.358326,0.977276,-100.660393,0.097944,0.000000
80.410004,58.895172,-100.704872,0.005963,0.003848,0.097728,261.978821,13.345837,0.977276,-100.704872,0.097944,0.000000
80.630005,58.867615,-100.704872,0.005971,0.003848,0.097728,261.856232,13.339592,0.977276,-100.704872,0.097944,0.000000
80.850006,58.839691,-100.704872,0.005963,0.003848,0.097728,261.732025,13.333264,0.977276,-100.704872,0.097944,0.000000
81.070007,58.812134,-100.704872,0.005967,0.003848,0.097728,261.609436,13.327020,0.977276,-100.704872,0.097944,0.000000
81.290001,58.787186,-100.793839,0.005976,0.003848,0.097728,261.498474,13.321366,0.977276,-100.793839,0.097944,0.000000
81.510002,58.741753,-100.793839,0.005980,0.003848,0.097728,261.296356,13.311071,0.977276,-100.793839,0.097944,0.000000
81.730003,58.744362,-100.749352,0.005976,0.003848,0.097728,261.307983,13.311663,0.977276,-100.749352,0.097944,0.000000
81.950005,58.692978,-100.704872,0.005971,0.003848,0.097728,261.079407,13.300018,0.977276,-100.704872,0.097944,0.000000
82.170006,58.672119,-100.749352,0.005954,0.003848,0.097728,260.986633,13.295293,0.977276,-100.749352,0.097944,0.000000
82.390007,58.631905,-100.793839,0.005963,0.003848,0.097728,260.807739,13.286180,0.977276,-100.793839,0.097944,0.000000
82.610001,58.611427,-100.793839,0.005980,0.003848,0.097728,260.716644,13.281540,0.977276,-100.793839,0.097944,0.000000
82.830002,58.596527,-100.793839,0.005976,0.003848,0.097728,260.650360,13.278162,0.977276,-100.793839,0.097944,0.000000
83.050003,58.567856,-100.793839,0.005980,0.003848,0.097728,260.522827,13.271666,0.977276,-100.793839,0.097944,0.000000
83.270004,58.545143,-100.838318,0.005971,0.003848,0.097728,260.421814,13.266520,0.977276,-100.838318,0.097944,0.000000
83.490005,58.516472,-100.838318,0.005967,0.003848,0.097728,260.294281,13.260022,0.977276,-100.838318,0.097944,0.000000
83.710007,58.488167,-100.882797,0.005989,0.003848,0.097728,260.168365,13.253608,0.977276,-100.882797,0.097944,0.000000
83.930000,58.467316,-100.793839,0.005976,0.003848,0.097728,260.075623,13.248882,0.977276,-100.793839,0.097944,0.000000
84.150002,58.452797,-100.793839,0.005971,0.003848,0.097728,260.011017,13.245593,0.977276,-100.793839,0.097944,0.000000
84.370003,58.417419,-100.838318,0.005959,0.003848,0.097728,259.853668,13.237576,0.977276,-100.838318,0.097944,0.000000
84.590004,58.404015,-100.882797,0.005980,0.003848,0.097728,259.794037,13.234539,0.977276,-100.882797,0.097944,0.000000
84.810005,58.377205,-100.838318,0.005971,0.003848,0.097728,259.674774,13.228463,0.977276,-100.838318,0.097944,0.000000
85.030006,58.350021,-100.793839,0.005980,0.003848,0.097728,259.553864,13.222303,0.977276,-100.793839,0.097944,0.000000
85.250008,58.323952,-100.838318,0.005989,0.003848,0.097728,259.437897,13.216396,0.977276,-100.838318,0.097944,0.000000
85.470001,58.295654,-100.882797,0.005954,0.003848,0.097728,259.312012,13.209985,0.977276,-100.882797,0.097944,0.000000
85.690002,58.277405,-100.927277,0.005967,0.003848,0.097728,259.230835,13.205849,0.977276,-100.927277,0.097944,0.000000
85.910004,58.259163,-100.927277,0.005959,0.003848,0.097728,259.149689,13.201715,0.977276,-100.927277,0.097944,0.000000
86.130005,58.249847,-100.882797,0.005976,0.003848,0.097728,259.108276,13.199604,0.977276,-100.882797,0.097944,0.000000
86.350006,58.208519,-100.838318,0.005980,0.003848,0.097728,258.924438,13.190239,0.977276,-100.838318,0.097944,0.000000
86.570007,58.198463,-100.838318,0.005976,0.003848,0.097728,258.879700,13.187961,0.977276,-100.838318,0.097944,0.000000
86.790001,58.170906,-100.971756,0.005980,0.003848,0.097728,258.757111,13.181716,0.977276,-100.971756,0.097944,0.000000
87.010002,58.137764,-100.927277,0.005984,0.003848,0.097728,258.609680,13.174206,0.977276,-100.927277,0.097944,0.000000
87.230003,58.125107,-100.927277,0.005976,0.003848,0.097728,258.553375,13.171337,0.977276,-100.927277,0.097944,0.000000
87.450005,58.093079,-100.882797,0.005997,0.003848,0.097728,258.410919,13.164080,0.977276,-100.882797,0.097944,0.000000
87.670006,58.092339,-100.927277,0.005950,0.003848,0.097728,258.407623,13.163913,0.977276,-100.927277,0.097944,0.000000
87.890007,58.073715,-100.971756,0.005980,0.003848,0.097728,258.324799,13.159692,0.977276,-100.971756,0.097944,0.000000
88.110001,58.051003,-100.971756,0.005971,0.003848,0.097728,258.223755,13.154545,0.977276,-100.971756,0.097944,0.000000
88.330002,58.024567,-100.927277,0.005989,0.003848,0.097728,258.106171,13.148555,0.977276,-100.927277,0.097944,0.000000
88.550003,58.008553,-100.971756,0.005976,0.003848,0.097728,258.034943,13.144926,0.977276,-100.971756,0.097944,0.000000
88.770004,57.999619,-100.971756,0.005984,0.003848,0.097728,257.995178,13.142901,0.977276,-100.971756,0.097944,0.000000
88.990005,57.984718,-100.971756,0.005971,0.003848,0.097728,257.928894,13.139525,0.977276,-100.971756,0.097944,0.000000
89.210007,57.951950,-101.060722,0.005976,0.003848,0.097728,257.783142,13.132100,0.977276,-101.060722,0.097944,0.000000
89.430008,57.932961,-101.060722,0.005963,0.003848,0.097728,257.698669,13.127796,0.977276,-101.060722,0.097944,0.000000
89.650002,57.931473,-100.971756,0.005989,0.003848,0.097728,257.692047,13.127460,0.977276,-100.971756,0.097944,0.000000
89.870003,57.903542,-101.016243,0.005976,0.003848,0.097728,257.567810,13.121130,0.977276,-101.016243,0.097944,0.000000
90.090004,57.885674,-101.060722,0.005980,0.003848,0.097728,257.488342,13.117082,0.977276,-101.060722,0.097944,0.000000
90.310005,57.847687,-101.016243,0.005980,0.003848,0.097728,257.319366,13.108473,0.977276,-101.016243,0.097944,0.000000
90.530006,57.852158,-101.060722,0.005989,0.003848,0.097728,257.339264,13.109487,0.977276,-101.060722,0.097944,0.000000
90.750008,57.824974,-101.105202,0.005971,0.003848,0.097728,257.218323,13.103327,0.977276,-101.105202,0.097944,0.000000
90.970001,57.832794,-101.016243,0.005980,0.003848,0.097728,257.253113,13.105099,0.977276,-101.016243,0.097944,0.000000
91.190002,57.791832,-101.060722,0.005967,0.003848,0.097728,257.070923,13.095816,0.977276,-101.060722,0.097944,0.000000
91.410004,57.778427,-101.105202,0.005954,0.003848,0.097728,257.011292,13.092778,0.977276,-101.105202,0.097944,0.000000
91.630005,57.749008,-101.105202,0.005971,0.003848,0.097728,256.880432,13.086112,0.977276,-101.105202,0.097944,0.000000
91.850006,57.738213,-101.105202,0.005980,0.003848,0.097728,256.832397,13.083667,0.977276,-101.105202,0.097944,0.000000
92.070007,57.730019,-101.060722,0.005984,0.003848,0.097728,256.795959,13.081809,0.977276,-101.060722,0.097944,0.000000
92.290001,57.704323,-101.105202,0.005980,0.003848,0.097728,256.681641,13.075986,0.977276,-101.105202,0.097944,0.000000
92.510002,57.686821,-101.149681,0.005967,0.003848,0.097728,256.603790,13.072021,0.977276,-101.149681,0.097944,0.000000
92.730003,57.668205,-101.194160,0.005967,0.003848,0.097728,256.520996,13.067801,0.977276,-101.194160,0.097944,0.000000
92.950005,57.653313,-101.105202,0.005997,0.003848,0.097728,256.454742,13.064427,0.977276,-101.105202,0.097944,0.000000
93.170006,57.650330,-101.105202,0.005976,0.003848,0.097728,256.441467,13.063751,0.977276,-101.105202,0.097944,0.000000
93.390007,57.627991,-101.060722,0.005976,0.003848,0.097728,256.342102,13.058689,0.977276,-101.060722,0.097944,0.000000
93.610008,57.594101,-101.105202,0.005984,0.003848,0.097728,256.191345,13.051009,0.977276,-101.105202,0.097944,0.000000
93.830002,57.591866,-101.149681,0.005980,0.003848,0.097728,256.181427,13.050503,0.977276,-101.149681,0.097944,0.000000
94.050003,57.560959,-101.194160,0.005997,0.003848,0.097728,256.043945,13.043500,0.977276,-101.194160,0.097944,0.000000
94.270004,57.560593,-101.149681,0.005976,0.003848,0.097728,256.042297,13.043416,0.977276,-101.149681,0.097944,0.000000
94.490005,57.537132,-101.149681,0.005984,0.003848,0.097728,255.937943,13.038101,0.977276,-101.149681,0.097944,0.000000
94.500008,57.550163,-101.149681,0.005980,0.003848,0.097728,255.995911,13.041053,0.977276,-101.149681,0.097944,0.000000