File: Data/Symmetrical membranes compression/Sartorius Cellulose Nitrate 5um test 2_10302023_170238.csv
Time (sec),S:Load (lbs),S:HL1 (DIM),S:LVDT (in),S:Position (in),Ch:Position (mm),Ch:Load (N),Ch:Stress (MPa),Ch:Strain (mm/mm),Ch:HL1 (DIM),Set Point (),Cycles ()
0.110000,-0.005592,-67.655525,0.000000,-0.000000,-0.000000,-0.024876,-0.001267,-0.000000,-67.655525,0.000243,0.000000
0.360000,0.063675,-67.655525,-0.000004,0.000001,0.000017,0.283240,0.014429,0.000173,-67.655525,0.000555,0.000000
0.610000,0.045799,-67.655525,-0.000009,0.000138,0.003504,0.203725,0.010378,0.035036,-67.655525,0.004718,0.000000
0.860000,0.049149,-67.655525,0.000121,0.000295,0.007493,0.218624,0.011137,0.074929,-67.655525,0.008880,0.000000
1.110000,0.082291,-67.700005,0.000319,0.000462,0.011742,0.366047,0.018647,0.117423,-67.700005,0.013060,0.000000
1.360000,0.092346,-67.744492,0.000466,0.000624,0.015853,0.410776,0.020926,0.158528,-67.744492,0.017223,0.000000
1.610000,0.115059,-67.700005,0.000647,0.000793,0.020154,0.511808,0.026073,0.201543,-67.700005,0.021386,0.000000
1.860000,0.147087,-67.700005,0.000828,0.000950,0.024126,0.654276,0.033330,0.241262,-67.700005,0.025548,0.000000
2.110000,0.268852,-67.700005,0.001009,0.001116,0.028358,1.195915,0.060923,0.283582,-67.700005,0.029711,0.000000
2.360000,0.409981,-67.700005,0.001147,0.001276,0.032400,1.823686,0.092903,0.323996,-67.700005,0.033874,0.000000
2.610000,0.617760,-67.700005,0.001319,0.001442,0.036614,2.747932,0.139986,0.366142,-67.700005,0.038036,0.000000
2.860000,0.694847,-67.788971,0.001384,-0.000000,-0.000000,3.090834,0.157455,-0.000000,-67.788971,0.000252,0.000000
3.110000,0.680321,-67.788971,0.001388,-0.000000,-0.000000,3.026218,0.154163,-0.000000,-67.788971,0.000252,0.000000
3.360000,0.622978,-67.788971,0.001388,-0.000000,-0.000000,2.771146,0.141169,-0.000000,-67.788971,0.000512,0.000000
3.610000,0.637497,-67.788971,0.001354,0.000000,0.000009,2.835728,0.144459,0.000087,-67.788971,0.000928,0.000000
3.860000,0.611061,-67.833450,0.001380,0.000000,0.000009,2.718136,0.138468,0.000087,-67.833450,0.001344,0.000000
4.110000,0.608078,-67.788971,0.001362,0.000013,0.000330,2.704866,0.137792,0.003296,-67.788971,0.001760,0.000000
4.360000,0.702667,-67.788971,0.001397,0.000035,0.000893,3.125620,0.159227,0.008932,-67.788971,0.002177,0.000000
4.610000,0.735435,-67.833450,0.001418,0.000059,0.001492,3.271380,0.166652,0.014916,-67.833450,0.002602,0.000000
4.860000,0.762245,-67.788971,0.001427,0.000074,0.001873,3.390636,0.172727,0.018732,-67.788971,0.003018,0.000000
5.110000,0.790916,-67.788971,0.001440,0.000092,0.002342,3.518172,0.179224,0.023415,-67.788971,0.003434,0.000000
5.360000,0.786819,-67.922409,0.001466,0.000108,0.002749,3.499948,0.178296,0.027492,-67.922409,0.003850,0.000000
5.610000,0.817726,-67.833450,0.001483,0.000126,0.003191,3.637428,0.185299,0.031914,-67.833450,0.004267,0.000000
5.860000,0.890343,-67.833450,0.001505,0.000141,0.003573,3.960442,0.201755,0.035729,-67.833450,0.004683,0.000000
6.110000,0.936516,-67.877930,0.001526,0.000155,0.003946,4.165830,0.212218,0.039458,-67.877930,0.005099,0.000000
6.360000,0.973007,-67.877930,0.001556,0.000171,0.004353,4.328152,0.220487,0.043535,-67.877930,0.005516,0.000000
6.610000,0.987900,-67.922409,0.001544,0.000189,0.004804,4.394398,0.223861,0.048045,-67.922409,0.005932,0.000000
6.860000,1.004288,-67.966896,0.001565,0.000204,0.005186,4.467295,0.227575,0.051861,-67.966896,0.006348,0.000000
7.110000,1.025513,-67.877930,0.001582,0.000216,0.005481,4.561708,0.232385,0.054809,-67.877930,0.006764,0.000000
7.360000,1.038918,-67.877930,0.001591,0.000240,0.006105,4.621336,0.235422,0.061053,-67.877930,0.007181,0.000000
7.610000,1.066841,-67.966896,0.001630,0.000255,0.006487,4.745546,0.241750,0.064868,-67.966896,0.007597,0.000000
7.860001,1.124191,-67.922409,0.001660,0.000274,0.006964,5.000653,0.254745,0.069638,-67.922409,0.008013,0.000000
8.110001,1.155472,-67.966896,0.001656,0.000287,0.007285,5.139795,0.261834,0.072847,-67.966896,0.008429,0.000000
8.360001,1.204620,-67.966896,0.001669,0.000303,0.007684,5.358419,0.272971,0.076836,-67.966896,0.008846,0.000000
8.610001,1.215050,-68.011375,0.001686,0.000321,0.008161,5.404811,0.275334,0.081606,-68.011375,0.009262,0.000000
8.860001,1.256378,-68.011375,0.001716,0.000337,0.008568,5.588649,0.284699,0.085682,-68.011375,0.009678,0.000000
9.110001,1.275002,-68.011375,0.001694,0.000350,0.008898,5.671490,0.288919,0.088977,-68.011375,0.010095,0.000000
9.360001,1.302185,-67.966896,0.001742,0.000368,0.009357,5.792408,0.295079,0.093574,-67.966896,0.010511,0.000000
9.610001,1.356178,-68.011375,0.001763,0.000391,0.009938,6.032582,0.307314,0.099384,-68.011375,0.010927,0.000000
9.860001,1.395279,-68.011375,0.001768,0.000402,0.010207,6.206511,0.316175,0.102073,-68.011375,0.011352,0.000000
10.110001,1.412407,-68.055855,0.001798,0.000414,0.010528,6.282700,0.320056,0.105282,-68.055855,0.011768,0.000000
10.360001,1.470871,-68.055855,0.001815,0.000435,0.011040,6.542761,0.333304,0.110398,-68.055855,0.012185,0.000000
10.610001,1.476082,-68.055855,0.001815,0.000444,0.011265,6.565940,0.334485,0.112653,-68.055855,0.012601,0.000000
10.860001,1.542732,-68.055855,0.001858,0.000471,0.011968,6.862416,0.349588,0.119677,-68.055855,0.013017,0.000000
11.110001,1.551300,-68.055855,0.001880,0.000488,0.012401,6.900527,0.351530,0.124013,-68.055855,0.013433,0.000000
11.360001,1.588913,-68.055855,0.001893,0.000504,0.012792,7.067838,0.360053,0.127916,-68.055855,0.013850,0.000000
11.610001,1.677910,-68.055855,0.001927,0.000524,0.013312,7.463716,0.380220,0.133119,-68.055855,0.014266,0.000000
11.860001,1.677162,-68.100334,0.001927,0.000534,0.013572,7.460390,0.380050,0.135721,-68.100334,0.014682,0.000000
12.110001,1.725945,-68.100334,0.001940,0.000551,0.013997,7.677385,0.391105,0.139970,-68.100334,0.015098,0.000000
12.360001,1.768768,-68.189301,0.001953,0.000569,0.014448,7.867875,0.400809,0.144480,-68.189301,0.015515,0.000000
12.610001,1.839142,-68.189301,0.001975,0.000589,0.014951,8.180911,0.416755,0.149510,-68.189301,0.015931,0.000000
12.860001,1.834305,-68.189301,0.001979,0.000602,0.015289,8.159395,0.415659,0.152892,-68.189301,0.016347,0.000000
13.110001,1.855156,-68.189301,0.002005,0.000620,0.015740,8.252146,0.420384,0.157401,-68.189301,0.016763,0.000000
13.360001,1.901703,-68.189301,0.002022,0.000635,0.016122,8.459197,0.430932,0.161218,-68.189301,0.017180,0.000000
13.610001,1.965752,-68.144814,0.002048,0.000650,0.016503,8.744100,0.445446,0.165033,-68.144814,0.017596,0.000000
13.860001,1.968727,-68.189301,0.002052,0.000662,0.016816,8.757336,0.446120,0.168155,-68.189301,0.018012,0.000000
14.110001,2.025703,-68.144814,0.002065,0.000680,0.017267,9.010778,0.459031,0.172665,-68.144814,0.018429,0.000000
14.360001,2.091988,-68.189301,0.002087,0.000700,0.017770,9.305626,0.474051,0.177695,-68.189301,0.018845,0.000000
14.610001,2.141884,-68.189301,0.002117,0.000718,0.018238,9.527575,0.485358,0.182378,-68.189301,0.019261,0.000000
14.860001,2.158264,-68.278259,0.002117,0.000733,0.018619,9.600438,0.489070,0.186193,-68.278259,0.019686,0.000000
15.110001,2.205933,-68.233780,0.002147,0.000749,0.019036,9.812478,0.499871,0.190357,-68.233780,0.020102,0.000000
15.360001,2.223808,-68.233780,0.002156,0.000767,0.019478,9.891994,0.503922,0.194779,-68.233780,0.020519,0.000000
15.610001,2.272583,-68.278259,0.002186,0.000777,0.019738,10.108954,0.514975,0.197380,-68.278259,0.020935,0.000000
15.860001,2.315781,-68.233780,0.002195,0.000797,0.020241,10.301106,0.524763,0.202411,-68.233780,0.021351,0.000000
16.110001,2.346687,-68.233780,0.002203,0.000811,0.020588,10.438586,0.531767,0.205879,-68.233780,0.021767,0.000000
16.360001,2.397705,-68.278259,0.002251,0.000831,0.021117,10.665524,0.543328,0.211170,-68.278259,0.022184,0.000000
16.610001,2.440895,-68.278259,0.002246,0.000848,0.021542,10.857643,0.553115,0.215419,-68.278259,0.022600,0.000000
16.860001,2.492287,-68.322739,0.002268,0.000868,0.022045,11.086245,0.564760,0.220449,-68.322739,0.023016,0.000000
17.110001,2.457283,-68.322739,0.002294,0.000875,0.022227,10.930541,0.556828,0.222270,-68.322739,0.023432,0.000000
17.360001,2.546280,-68.367218,0.002294,0.000892,0.022669,11.326419,0.576995,0.226692,-68.367218,0.023849,0.000000
17.610001,2.552612,-68.322739,0.002307,0.000904,0.022955,11.354587,0.578430,0.229555,-68.322739,0.024265,0.000000
17.860001,2.636024,-68.322739,0.002324,0.000927,0.023554,11.725622,0.597332,0.235539,-68.322739,0.024681,0.000000
18.110001,2.640862,-68.367218,0.002350,0.000940,0.023866,11.747139,0.598428,0.238660,-68.367218,0.025098,0.000000
18.360001,2.713844,-68.367218,0.002376,0.000960,0.024378,12.071782,0.614966,0.243778,-68.367218,0.025514,0.000000
18.610001,2.744751,-68.367218,0.002371,0.000979,0.024855,12.209262,0.621969,0.248547,-68.367218,0.025930,0.000000
18.860001,2.771935,-68.411705,0.002406,0.000995,0.025280,12.330180,0.628129,0.252796,-68.411705,0.026346,0.000000
19.110001,2.794655,-68.367218,0.002436,0.001006,0.025549,12.431246,0.633278,0.255485,-68.367218,0.026763,0.000000
19.360001,2.841568,-68.411705,0.002440,0.001021,0.025939,12.639926,0.643909,0.259387,-68.411705,0.027179,0.000000
19.610001,2.916420,-68.411705,0.002449,0.001043,0.026485,12.972884,0.660870,0.264851,-68.411705,0.027595,0.000000
19.860001,2.971901,-68.411705,0.002471,0.001059,0.026893,13.219676,0.673442,0.268927,-68.411705,0.028020,0.000000
20.110001,2.981956,-68.456184,0.002488,0.001076,0.027335,13.264405,0.675721,0.273350,-68.456184,0.028436,0.000000
20.360001,2.997223,-68.456184,0.002514,0.001085,0.027569,13.332314,0.679180,0.275691,-68.456184,0.028853,0.000000
20.610001,3.087708,-68.500664,0.002527,0.001107,0.028115,13.734809,0.699685,0.281154,-68.500664,0.029269,0.000000
20.860001,3.113403,-68.500664,0.002535,0.001123,0.028523,13.849110,0.705507,0.285231,-68.500664,0.029685,0.000000
21.110001,3.096649,-68.411705,0.002565,0.001135,0.028827,13.774584,0.701711,0.288266,-68.411705,0.030101,0.000000
21.360001,3.211708,-68.500664,0.002570,0.001154,0.029321,14.286391,0.727783,0.293209,-68.500664,0.030518,0.000000
21.610001,3.275383,-68.545143,0.002600,0.001176,0.029876,14.569632,0.742212,0.298760,-68.545143,0.030934,0.000000
21.860001,3.240753,-68.545143,0.002591,0.001180,0.029971,14.415590,0.734365,0.299714,-68.545143,0.031350,0.000000
22.110001,3.341293,-68.500664,0.002634,0.001207,0.030648,14.862815,0.757148,0.306478,-68.500664,0.031767,0.000000
22.360001,3.308899,-68.500664,0.002617,0.001210,0.030734,14.718718,0.749807,0.307345,-68.500664,0.032183,0.000000
22.610001,3.454498,-68.545143,0.002639,0.001239,0.031472,15.366376,0.782800,0.314716,-68.545143,0.032599,0.000000
22.860001,3.401245,-68.545143,0.002673,0.001248,0.031706,15.129494,0.770733,0.317058,-68.545143,0.033015,0.000000
23.110001,3.428055,-68.545143,0.002682,0.001261,0.032035,15.248750,0.776808,0.320354,-68.545143,0.033432,0.000000
23.360001,3.428802,-68.545143,0.002716,0.001271,0.032295,15.252075,0.776978,0.322955,-68.545143,0.033848,0.000000
23.610001,3.626160,-68.589630,0.002733,0.001303,0.033102,16.129963,0.821700,0.331020,-68.589630,0.034264,0.000000
23.860001,3.656693,-68.589630,0.002746,0.001320,0.033518,16.265781,0.828618,0.335183,-68.589630,0.034680,0.000000
24.110001,3.677917,-68.589630,0.002764,0.001338,0.033995,16.360193,0.833428,0.339953,-68.589630,0.035097,0.000000
24.360001,3.738617,-68.634109,0.002755,0.001354,0.034385,16.630199,0.847183,0.343855,-68.634109,0.035513,0.000000
24.610001,3.734894,-68.589630,0.002794,0.001366,0.034689,16.613638,0.846339,0.346890,-68.589630,0.035929,0.000000
24.860001,3.740852,-68.678589,0.002815,0.001380,0.035053,16.640142,0.847689,0.350532,-68.678589,0.036345,0.000000
25.110001,3.791122,-68.678589,0.002824,0.001397,0.035496,16.863754,0.859081,0.354956,-68.678589,0.036770,0.000000
25.360001,3.893150,-68.634109,0.002850,0.001414,0.035921,17.317598,0.882200,0.359205,-68.634109,0.037187,0.000000
25.610001,4.013428,-68.678589,0.002863,0.001435,0.036458,17.852617,0.909456,0.364582,-68.678589,0.037603,0.000000
25.860001,3.954964,-68.678589,0.002871,0.001438,0.036536,17.592558,0.896208,0.365363,-68.678589,0.038019,0.000000
26.110001,4.134819,-68.678589,0.002897,0.001475,0.037456,18.392593,0.936963,0.374555,-68.678589,0.038435,0.000000
26.360001,4.104660,-68.723068,0.002923,0.001484,0.037698,18.258440,0.930129,0.376983,-68.723068,0.038852,0.000000
26.610001,4.118805,-68.723068,0.002932,0.001506,0.038245,18.321360,0.933335,0.382447,-68.723068,0.039268,0.000000
26.860001,4.206314,-68.723068,0.002953,0.001522,0.038661,18.710619,0.953164,0.386609,-68.723068,0.039684,0.000000
27.110001,4.241692,-68.767548,0.002949,0.001536,0.039008,18.867987,0.961181,0.390078,-68.767548,0.040100,0.000000
27.360001,4.302391,-68.678589,0.002979,0.001552,0.039433,19.137991,0.974936,0.394327,-68.678589,0.040517,0.000000
27.610001,4.379845,-68.767548,0.002992,0.001567,0.039814,19.482523,0.992487,0.398144,-68.767548,0.040933,0.000000
27.860001,4.421921,-68.767548,0.003009,0.001586,0.040283,19.669685,1.002022,0.402826,-68.767548,0.041349,0.000000
28.110001,4.476288,-68.723068,0.003044,0.001601,0.040664,19.911522,1.014341,0.406642,-68.723068,0.041766,0.000000
28.360001,4.500862,-68.767548,0.003053,0.001613,0.040968,20.020834,1.019910,0.409678,-68.767548,0.042182,0.000000
28.610001,4.552994,-68.812035,0.003074,0.001632,0.041462,20.252728,1.031723,0.414621,-68.812035,0.042598,0.000000
28.860001,4.618904,-68.767548,0.003100,0.001648,0.041852,20.545912,1.046659,0.418523,-68.767548,0.043014,0.000000
29.110001,4.682953,-68.812035,0.003091,0.001668,0.042364,20.830814,1.061172,0.423640,-68.812035,0.043431,0.000000
29.360001,4.723541,-68.812035,0.003104,0.001680,0.042676,21.011360,1.070370,0.426762,-68.812035,0.043847,0.000000
29.610001,4.783867,-68.812035,0.003126,0.001694,0.043032,21.279703,1.084040,0.430318,-68.812035,0.044263,0.000000
29.860001,4.862434,-68.812035,0.003165,0.001715,0.043561,21.629189,1.101843,0.435607,-68.812035,0.044679,0.000000
30.110001,4.958511,-68.856514,0.003191,0.001735,0.044072,22.056561,1.123615,0.440725,-68.856514,0.045104,0.000000
30.360001,4.948456,-68.856514,0.003169,0.001748,0.044411,22.011831,1.121336,0.444106,-68.856514,0.045521,0.000000
30.610001,5.019577,-68.856514,0.003208,0.001765,0.044836,22.328194,1.137452,0.448356,-68.856514,0.045937,0.000000
30.860001,5.017342,-68.945473,0.003242,0.001776,0.045122,22.318251,1.136946,0.451218,-68.945473,0.046353,0.000000
31.110001,5.175972,-68.856514,0.003242,0.001799,0.045703,23.023872,1.172892,0.457028,-68.856514,0.046769,0.000000
31.360001,5.158844,-68.900993,0.003251,0.001808,0.045928,22.947683,1.169011,0.459283,-68.900993,0.047186,0.000000
31.610001,5.266090,-68.900993,0.003264,0.001825,0.046362,23.424740,1.193313,0.463619,-68.900993,0.047602,0.000000
31.860001,5.331253,-68.900993,0.003281,0.001841,0.046769,23.714598,1.208079,0.467695,-68.900993,0.048018,0.000000
32.110001,5.498817,-68.945473,0.003307,0.001867,0.047429,24.459961,1.246050,0.474286,-68.945473,0.048435,0.000000
32.360001,5.461960,-68.945473,0.003337,0.001883,0.047828,24.296011,1.237698,0.478275,-68.945473,0.048851,0.000000
32.610001,5.500679,-68.989952,0.003359,0.001897,0.048174,24.468243,1.246472,0.481744,-68.989952,0.049267,0.000000
32.860001,5.664528,-68.945473,0.003359,0.001918,0.048729,25.197079,1.283600,0.487294,-68.945473,0.049683,0.000000
33.110001,5.685379,-68.989952,0.003380,0.001933,0.049094,25.289829,1.288325,0.490937,-68.989952,0.050100,0.000000
33.360001,5.667130,-68.989952,0.003393,0.001941,0.049293,25.208651,1.284190,0.492931,-68.989952,0.050516,0.000000
33.610001,5.879761,-68.989952,0.003406,0.001966,0.049944,26.154482,1.332373,0.499436,-68.989952,0.050932,0.000000
33.860001,5.927048,-69.078918,0.003419,0.001984,0.050394,26.364824,1.343088,0.503945,-69.078918,0.051348,0.000000
34.110001,5.994080,-69.034439,0.003454,0.002000,0.050793,26.662998,1.358278,0.507934,-69.034439,0.051765,0.000000
34.360001,6.058495,-68.989952,0.003462,0.002017,0.051244,26.949530,1.372874,0.512444,-68.989952,0.052181,0.000000
34.610001,6.077858,-69.034439,0.003501,0.002031,0.051600,27.035662,1.377262,0.515999,-69.034439,0.052597,0.000000
34.860001,6.173935,-69.078918,0.003484,0.002048,0.052008,27.463034,1.399034,0.520076,-69.078918,0.053014,0.000000
35.110001,6.179893,-69.078918,0.003505,0.002058,0.052285,27.489540,1.400384,0.522850,-69.078918,0.053438,0.000000
35.360001,6.264420,-69.078918,0.003527,0.002076,0.052727,27.865530,1.419538,0.527274,-69.078918,0.053855,0.000000
35.610001,6.353790,-69.078918,0.003553,0.002092,0.053144,28.263071,1.439790,0.531436,-69.078918,0.054271,0.000000
35.860001,6.464386,-69.078918,0.003566,0.002107,0.053508,28.755026,1.464851,0.535078,-69.078918,0.054687,0.000000
36.110001,6.629341,-69.078918,0.003583,0.002129,0.054072,29.488783,1.502230,0.540716,-69.078918,0.055104,0.000000
36.360001,6.645355,-69.123398,0.003587,0.002145,0.054488,29.560017,1.505859,0.544878,-69.123398,0.055520,0.000000
36.610001,6.705681,-69.167877,0.003622,0.002162,0.054904,29.828358,1.519529,0.549041,-69.167877,0.055936,0.000000
36.860001,6.798775,-69.167877,0.003639,0.002176,0.055260,30.242460,1.540624,0.552597,-69.167877,0.056352,0.000000
37.110001,6.898567,-69.167877,0.003639,0.002194,0.055719,30.686359,1.563238,0.557192,-69.167877,0.056769,0.000000
37.360001,6.957031,-69.123398,0.003665,0.002207,0.056049,30.946421,1.576486,0.560488,-69.123398,0.057185,0.000000
37.610001,7.060555,-69.123398,0.003686,0.002225,0.056526,31.406916,1.599945,0.565258,-69.123398,0.057601,0.000000
37.860001,7.174126,-69.167877,0.003699,0.002242,0.056951,31.912106,1.625680,0.569507,-69.167877,0.058017,0.000000
38.110001,7.279137,-69.212357,0.003729,0.002260,0.057410,32.379215,1.649476,0.574103,-69.212357,0.058434,0.000000
38.360001,7.248230,-69.167877,0.003729,0.002273,0.057731,32.241737,1.642472,0.577312,-69.167877,0.058850,0.000000
38.610001,7.352867,-69.212357,0.003755,0.002289,0.058139,32.707188,1.666183,0.581388,-69.212357,0.059266,0.000000
38.860001,7.466064,-69.123398,0.003781,0.002302,0.058477,33.210712,1.691834,0.584770,-69.123398,0.059682,0.000000
39.110001,7.626183,-69.212357,0.003777,0.002322,0.058980,33.922955,1.728118,0.589800,-69.212357,0.060099,0.000000
39.360001,7.674591,-69.256844,0.003773,0.002335,0.059318,34.138287,1.739087,0.593183,-69.256844,0.060515,0.000000
39.610001,7.793381,-69.212357,0.003816,0.002353,0.059778,34.666687,1.766005,0.597779,-69.212357,0.060931,0.000000
39.860001,7.919983,-69.301323,0.003820,0.002373,0.060272,35.229843,1.794694,0.602722,-69.301323,0.061348,0.000000
40.110001,8.001534,-69.212357,0.003850,0.002389,0.060680,35.592598,1.813173,0.606798,-69.212357,0.061764,0.000000
40.360001,8.074890,-69.256844,0.003859,0.002404,0.061070,35.918903,1.829796,0.610700,-69.256844,0.062189,0.000000
40.610001,8.130379,-69.256844,0.003898,0.002417,0.061391,36.165730,1.842370,0.613909,-69.256844,0.062605,0.000000
40.860001,8.271881,-69.256844,0.003911,0.002434,0.061816,36.795166,1.874435,0.618159,-69.256844,0.063021,0.000000
41.110001,8.369438,-69.256844,0.003919,0.002452,0.062284,37.229122,1.896542,0.622841,-69.256844,0.063438,0.000000
41.360001,8.512062,-69.345802,0.003949,0.002468,0.062683,37.863544,1.928861,0.626831,-69.345802,0.063854,0.000000
41.610001,8.420082,-69.301323,0.003928,0.002475,0.062857,37.454395,1.908018,0.628565,-69.301323,0.064270,0.000000
41.860001,8.814423,-69.301323,0.003967,0.002502,0.063559,39.208511,1.997377,0.635590,-69.301323,0.064686,0.000000
42.110001,8.857620,-69.345802,0.003997,0.002518,0.063967,39.400661,2.007165,0.639666,-69.345802,0.065103,0.000000
42.360001,8.888153,-69.345802,0.003984,0.002532,0.064305,39.536480,2.014084,0.643048,-69.345802,0.065519,0.000000
42.610001,9.159988,-69.345802,0.004027,0.002552,0.064825,40.745663,2.075683,0.648251,-69.345802,0.065935,0.000000
42.860001,9.106735,-69.256844,0.004027,0.002560,0.065025,40.508781,2.063616,0.650246,-69.256844,0.066351,0.000000
43.110001,9.502945,-69.434761,0.004040,0.002585,0.065658,42.271210,2.153398,0.656577,-69.434761,0.066768,0.000000
43.360001,9.567360,-69.434761,0.004053,0.002601,0.066065,42.557743,2.167995,0.660652,-69.434761,0.067184,0.000000
43.610001,9.306702,-69.390282,0.004074,0.002602,0.066100,41.398277,2.108929,0.661000,-69.390282,0.067600,0.000000
43.860001,9.834351,-69.390282,0.004105,0.002635,0.066932,43.745377,2.228496,0.669325,-69.390282,0.068017,0.000000
44.110001,9.781479,-69.434761,0.004117,0.002647,0.067227,43.510193,2.216515,0.672273,-69.434761,0.068433,0.000000
44.360001,9.844032,-69.479248,0.004109,0.002660,0.067557,43.788441,2.230690,0.675569,-69.479248,0.068849,0.000000
44.610001,9.874199,-69.479248,0.004126,0.002669,0.067791,43.922630,2.237525,0.677911,-69.479248,0.069265,0.000000
44.860001,10.407433,-69.434761,0.004148,0.002699,0.068563,46.294571,2.358358,0.685629,-69.434761,0.069682,0.000000
45.110001,10.503876,-69.479248,0.004178,0.002715,0.068953,46.723572,2.380212,0.689531,-69.479248,0.070098,0.000000
45.360001,10.471855,-69.479248,0.004199,0.002726,0.069239,46.581139,2.372956,0.692394,-69.479248,0.070523,0.000000
45.610001,10.861732,-69.479248,0.004208,0.002752,0.069907,48.315399,2.461304,0.699071,-69.479248,0.070939,0.000000
45.860001,10.811829,-69.479248,0.004217,0.002764,0.070202,48.093414,2.449995,0.702019,-69.479248,0.071355,0.000000
46.110001,10.632721,-69.479248,0.004234,0.002769,0.070323,47.296703,2.409409,0.703233,-69.479248,0.071772,0.000000
46.360001,10.942162,-69.479248,0.004247,0.002790,0.070861,48.673164,2.479529,0.708610,-69.479248,0.072188,0.000000
46.610001,11.207664,-69.568207,0.004255,0.002808,0.071312,49.854183,2.539693,0.713120,-69.568207,0.072604,0.000000
46.860001,11.450821,-69.568207,0.004286,0.002830,0.071884,50.935795,2.594793,0.718843,-69.568207,0.073020,0.000000
47.110001,11.437416,-69.568207,0.004299,0.002837,0.072058,50.876167,2.591755,0.720578,-69.568207,0.073437,0.000000
47.360001,12.147156,-69.612686,0.004342,0.002871,0.072925,54.033249,2.752585,0.729250,-69.612686,0.073853,0.000000
47.610001,12.025024,-69.568207,0.004342,0.002883,0.073220,53.489979,2.724910,0.732198,-69.568207,0.074269,0.000000
47.860001,12.175835,-69.568207,0.004363,0.002900,0.073662,54.160816,2.759084,0.736622,-69.568207,0.074686,0.000000
48.110001,12.195938,-69.612686,0.004372,0.002914,0.074018,54.250240,2.763639,0.740177,-69.612686,0.075102,0.000000
48.360001,12.356430,-69.568207,0.004389,0.002928,0.074365,54.964146,2.800007,0.743646,-69.568207,0.075518,0.000000
48.610001,12.620071,-69.612686,0.004406,0.002944,0.074790,56.136883,2.859749,0.747895,-69.612686,0.075934,0.000000
48.860001,12.727684,-69.657173,0.004424,0.002960,0.075188,56.615566,2.884134,0.751885,-69.657173,0.076351,0.000000
49.110001,13.129852,-69.612686,0.004432,0.002981,0.075709,58.404499,2.975267,0.757088,-69.612686,0.076767,0.000000
49.360001,13.254967,-69.612686,0.004454,0.002995,0.076082,58.961037,3.003618,0.760817,-69.612686,0.077183,0.000000
49.610001,13.336891,-69.701653,0.004449,0.003011,0.076481,59.325455,3.022183,0.764806,-69.701653,0.077599,0.000000
49.860001,13.597549,-69.701653,0.004471,0.003028,0.076914,60.484921,3.081249,0.769143,-69.701653,0.078016,0.000000
50.110001,13.794533,-69.746132,0.004488,0.003043,0.077287,61.361145,3.125886,0.772872,-69.746132,0.078432,0.000000
50.360001,14.072701,-69.657173,0.004501,0.003061,0.077738,62.598499,3.188920,0.777381,-69.657173,0.078857,0.000000
50.610001,14.300964,-69.701653,0.004536,0.003078,0.078172,63.613865,3.240645,0.781717,-69.701653,0.079273,0.000000
50.860001,14.464806,-69.701653,0.004544,0.003092,0.078545,64.342667,3.277772,0.785446,-69.701653,0.079689,0.000000
51.110001,14.730309,-69.790611,0.004570,0.003110,0.079004,65.523682,3.337935,0.790043,-69.790611,0.080106,0.000000
51.360001,14.901596,-69.746132,0.004583,0.003127,0.079429,66.285606,3.376750,0.794292,-69.746132,0.080522,0.000000
51.610001,15.093369,-69.701653,0.004579,0.003142,0.079802,67.138657,3.420206,0.798021,-69.701653,0.080938,0.000000
51.860001,15.338394,-69.746132,0.004609,0.003158,0.080218,68.228584,3.475730,0.802184,-69.746132,0.081354,0.000000
52.110001,15.432228,-69.746132,0.004644,0.003172,0.080574,68.645981,3.496993,0.805740,-69.746132,0.081771,0.000000
52.360001,16.012016,-69.835091,0.004648,0.003196,0.081172,71.225006,3.628375,0.811724,-69.835091,0.082187,0.000000
52.610001,16.049995,-69.790611,0.004656,0.003207,0.081450,71.393944,3.636981,0.814499,-69.790611,0.082603,0.000000
52.860001,16.289803,-69.835091,0.004652,0.003222,0.081849,72.460663,3.691322,0.818487,-69.835091,0.083019,0.000000
53.110004,16.651375,-69.790611,0.004669,0.003240,0.082291,74.069016,3.773255,0.822911,-69.790611,0.083436,0.000000
53.360004,17.153336,-69.835091,0.004691,0.003261,0.082829,76.301849,3.887001,0.828287,-69.835091,0.083852,0.000000
53.610004,17.148865,-69.835091,0.004704,0.003276,0.083210,76.281960,3.885988,0.832103,-69.835091,0.084268,0.000000
53.860004,17.361115,-69.835091,0.004747,0.003291,0.083601,77.226097,3.934085,0.836006,-69.835091,0.084685,0.000000
54.110004,17.614334,-69.879578,0.004721,0.003305,0.083956,78.352470,3.991465,0.839562,-69.879578,0.085101,0.000000
54.360004,18.101395,-69.879578,0.004764,0.003328,0.084529,80.519028,4.101835,0.845285,-69.879578,0.085517,0.000000
54.610004,18.142731,-69.835091,0.004777,0.003338,0.084797,80.702896,4.111202,0.847974,-69.835091,0.085933,0.000000
54.860004,18.167679,-69.835091,0.004777,0.003348,0.085040,80.813873,4.116855,0.850402,-69.835091,0.086350,0.000000
55.110004,19.120949,-69.879578,0.004812,0.003377,0.085769,85.054230,4.332869,0.857687,-69.879578,0.086766,0.000000
55.360004,19.270271,-69.879578,0.004807,0.003394,0.086202,85.718445,4.366706,0.862022,-69.879578,0.087182,0.000000
55.610004,19.536514,-69.879578,0.004833,0.003411,0.086645,86.902756,4.427038,0.866446,-69.879578,0.087607,0.000000
55.860004,19.633705,-69.879578,0.004850,0.003425,0.086991,87.335083,4.449061,0.869915,-69.879578,0.088023,0.000000
56.110004,20.063423,-69.968536,0.004863,0.003442,0.087434,89.246567,4.546437,0.874337,-69.968536,0.088440,0.000000
56.360004,20.263390,-69.968536,0.004876,0.003456,0.087781,90.136055,4.591750,0.877806,-69.968536,0.088856,0.000000
56.610004,20.321106,-69.968536,0.004889,0.003466,0.088032,90.392792,4.604828,0.880321,-69.968536,0.089272,0.000000
56.860004,20.638741,-69.924057,0.004911,0.003480,0.088388,91.805702,4.676805,0.883876,-69.924057,0.089688,0.000000
57.110004,21.563713,-69.968536,0.004928,0.003505,0.089029,95.920189,4.886407,0.890294,-69.968536,0.090105,0.000000
57.360004,21.053932,-70.013016,0.004911,0.003515,0.089272,93.652565,4.770889,0.892722,-70.013016,0.090521,0.000000
57.610004,22.216484,-70.013016,0.004950,0.003538,0.089862,98.823860,5.034328,0.898619,-70.013016,0.090937,0.000000
57.860004,22.405647,-70.013016,0.004980,0.003552,0.090218,99.665298,5.077192,0.902175,-70.013016,0.091354,0.000000
58.110004,23.072563,-70.057495,0.004984,0.003574,0.090781,102.631889,5.228317,0.907812,-70.057495,0.091770,0.000000
58.360004,22.721794,-70.013016,0.004997,0.003588,0.091128,101.071587,5.148832,0.911281,-70.013016,0.092186,0.000000
58.610004,23.558884,-70.013016,0.005019,0.003601,0.091475,104.795151,5.338519,0.914750,-70.013016,0.092602,0.000000
58.860004,23.877640,-70.013016,0.005023,0.003617,0.091865,106.213043,5.410751,0.918653,-70.013016,0.093019,0.000000
59.110004,24.311821,-70.057495,0.005036,0.003637,0.092377,108.144379,5.509138,0.923769,-70.057495,0.093435,0.000000
59.360004,24.726646,-70.057495,0.005036,0.003654,0.092802,109.989616,5.603138,0.928018,-70.057495,0.093851,0.000000
59.610004,25.048744,-70.013016,0.005075,0.003667,0.093131,111.422379,5.676126,0.931314,-70.013016,0.094267,0.000000
59.860004,25.107582,-70.101982,0.005075,0.003677,0.093400,111.684105,5.689459,0.934002,-70.101982,0.094684,0.000000
60.110004,26.072403,-70.101982,0.005105,0.003701,0.093999,115.975838,5.908091,0.939986,-70.101982,0.095100,0.000000
60.360004,26.462646,-70.146461,0.005101,0.003717,0.094415,117.711731,5.996521,0.944149,-70.146461,0.095516,0.000000
60.610004,26.783257,-70.146461,0.005118,0.003732,0.094796,119.137878,6.069172,0.947965,-70.146461,0.095941,0.000000
60.860004,27.320961,-70.190941,0.005122,0.003749,0.095221,121.529701,6.191018,0.952214,-70.190941,0.096357,0.000000
61.110004,27.798721,-70.101982,0.005152,0.003766,0.095664,123.654892,6.299280,0.956637,-70.101982,0.096774,0.000000
61.360004,28.311844,-70.190941,0.005165,0.003783,0.096089,125.937370,6.415555,0.960886,-70.190941,0.097190,0.000000
61.610004,28.698746,-70.146461,0.005174,0.003797,0.096453,127.658394,6.503229,0.964528,-70.146461,0.097606,0.000000
61.860004,28.683105,-70.190941,0.005148,0.003808,0.096713,127.588829,6.499684,0.967131,-70.190941,0.098023,0.000000
62.110004,29.673988,-70.146461,0.005195,0.003831,0.097311,131.996490,6.724222,0.973114,-70.146461,0.098439,0.000000
62.360004,30.178551,-70.190941,0.005200,0.003847,0.097710,134.240891,6.838558,0.977104,-70.190941,0.098855,0.000000
62.610004,30.604546,-70.190941,0.005221,0.003861,0.098075,136.135818,6.935089,0.980746,-70.190941,0.099271,0.000000
62.860004,30.838020,-70.235420,0.005230,0.003873,0.098378,137.174362,6.987995,0.983781,-70.235420,0.099688,0.000000
63.110004,31.856087,-70.279900,0.005247,0.003897,0.098985,141.702957,7.218692,0.989851,-70.279900,0.100104,0.000000
63.360004,31.983810,-70.190941,0.005282,0.003911,0.099349,142.271088,7.247635,0.993494,-70.190941,0.100520,0.000000
63.610004,32.317833,-70.190941,0.005290,0.003925,0.099705,143.756897,7.323326,0.997049,-70.190941,0.100936,0.000000
63.860004,32.845108,-70.235420,0.005277,0.003943,0.100156,146.102341,7.442808,1.001559,-70.235420,0.101353,0.000000
64.110001,33.559692,-70.324387,0.005282,0.003959,0.100546,149.280960,7.604735,1.005462,-70.324387,0.101769,0.000000
64.360001,34.615372,-70.279900,0.005312,0.003977,0.101023,153.976868,7.843956,1.010231,-70.279900,0.102185,0.000000
64.610001,34.005051,-70.279900,0.005303,0.003977,0.101023,151.262024,7.705655,1.010231,-70.279900,0.102601,0.000000
64.860001,35.188446,-70.324387,0.005325,0.004001,0.101621,156.526031,7.973816,1.016215,-70.324387,0.103018,0.000000
65.110001,36.711823,-70.324387,0.005355,0.004031,0.102385,163.302338,8.319018,1.023847,-70.324387,0.103434,0.000000
65.360001,37.113243,-70.324387,0.005368,0.004045,0.102749,165.087952,8.409981,1.027489,-70.324387,0.103850,0.000000
65.610001,36.567719,-70.368866,0.005389,0.004046,0.102766,162.661331,8.286364,1.027662,-70.368866,0.104275,0.000000
65.860001,37.516891,-70.368866,0.005385,0.004066,0.103287,166.883469,8.501450,1.032866,-70.368866,0.104692,0.000000
66.110001,38.989258,-70.368866,0.005407,0.004093,0.103963,173.432877,8.835092,1.039630,-70.368866,0.105108,0.000000
66.360001,39.297211,-70.413345,0.005424,0.004107,0.104327,174.802719,8.904875,1.043272,-70.413345,0.105524,0.000000
66.610001,40.014397,-70.368866,0.005437,0.004122,0.104692,177.992920,9.067392,1.046915,-70.368866,0.105940,0.000000
66.860001,41.302437,-70.413345,0.005433,0.004147,0.105333,183.722412,9.359266,1.053332,-70.413345,0.106357,0.000000
67.110001,41.458458,-70.368866,0.005467,0.004156,0.105567,184.416428,9.394621,1.055674,-70.368866,0.106773,0.000000
67.360001,41.942169,-70.413345,0.005458,0.004174,0.106010,186.568085,9.504230,1.060097,-70.413345,0.107189,0.000000
67.610001,42.647446,-70.502304,0.005476,0.004188,0.106383,189.705307,9.664049,1.063826,-70.502304,0.107605,0.000000
67.860001,43.234299,-70.502304,0.005493,0.004205,0.106799,192.315765,9.797032,1.067989,-70.502304,0.108022,0.000000
68.110001,43.691948,-70.457825,0.005501,0.004218,0.107137,194.351486,9.900737,1.071370,-70.457825,0.108438,0.000000
68.360001,44.919289,-70.457825,0.005510,0.004235,0.107579,199.810974,10.178856,1.075794,-70.457825,0.108854,0.000000
68.610001,45.833458,-70.546791,0.005514,0.004258,0.108152,203.877411,10.386010,1.081518,-70.546791,0.109270,0.000000
68.860001,47.292046,-70.457825,0.005553,0.004279,0.108698,210.365524,10.716530,1.086981,-70.457825,0.109687,0.000000
69.110001,47.493500,-70.502304,0.005549,0.004292,0.109028,211.261642,10.762181,1.090276,-70.502304,0.110103,0.000000
69.360001,48.064720,-70.502304,0.005545,0.004307,0.109409,213.802551,10.891621,1.094092,-70.502304,0.110519,0.000000
69.610001,48.988571,-70.502304,0.005588,0.004323,0.109817,217.912048,11.100968,1.098168,-70.502304,0.110936,0.000000
69.860001,49.497978,-70.546791,0.005588,0.004337,0.110155,220.178009,11.216402,1.101550,-70.546791,0.111352,0.000000
70.110001,50.198410,-70.502304,0.005609,0.004352,0.110537,223.293686,11.375122,1.105366,-70.502304,0.111768,0.000000
70.360001,50.931244,-70.546791,0.005614,0.004368,0.110944,226.553482,11.541185,1.109442,-70.546791,0.112184,0.000000
70.610001,51.972397,-70.546791,0.005635,0.004386,0.111413,231.184769,11.777113,1.114125,-70.546791,0.112601,0.000000
70.860001,52.803154,-70.457825,0.005609,0.004404,0.111855,234.880157,11.965366,1.118548,-70.457825,0.113026,0.000000
71.110001,53.410500,-70.591270,0.005648,0.004420,0.112262,237.581772,12.102992,1.122623,-70.591270,0.113442,0.000000
71.360001,54.592407,-70.591270,0.005657,0.004437,0.112696,242.839157,12.370816,1.126960,-70.591270,0.113858,0.000000
71.610001,55.169586,-70.635750,0.005657,0.004451,0.113060,245.406570,12.501607,1.130602,-70.635750,0.114274,0.000000
71.860001,56.385376,-70.591270,0.005652,0.004471,0.113555,250.814682,12.777108,1.135545,-70.591270,0.114691,0.000000
72.110001,56.999420,-70.635750,0.005687,0.004484,0.113901,253.546082,12.916253,1.139014,-70.635750,0.115107,0.000000
72.360001,57.598938,-70.635750,0.005696,0.004494,0.114153,256.212860,13.052107,1.141529,-70.635750,0.115523,0.000000
72.610001,59.062737,-70.680229,0.005696,0.004520,0.114812,262.724182,13.383807,1.148120,-70.680229,0.115939,0.000000
72.860001,59.961273,-70.635750,0.005717,0.004534,0.115168,266.721069,13.587419,1.151675,-70.635750,0.116356,0.000000
73.110001,60.717186,-70.680229,0.005717,0.004551,0.115592,270.083527,13.758711,1.155925,-70.680229,0.116772,0.000000
73.360001,61.661156,-70.680229,0.005726,0.004566,0.115983,274.282532,13.972617,1.159828,-70.680229,0.117188,0.000000
73.610001,62.732841,-70.680229,0.005747,0.004586,0.116494,279.049622,14.215465,1.164944,-70.680229,0.117604,0.000000
73.860001,63.700630,-70.724709,0.005747,0.004597,0.116772,283.354553,14.434770,1.167720,-70.724709,0.118021,0.000000
74.110001,64.329201,-70.680229,0.005760,0.004611,0.117128,286.150574,14.577205,1.171275,-70.680229,0.118437,0.000000
74.360001,65.488396,-70.724709,0.005782,0.004631,0.117622,291.306946,14.839883,1.176219,-70.724709,0.118853,0.000000
74.610001,66.144890,-70.724709,0.005777,0.004638,0.117813,294.227173,14.988647,1.178126,-70.724709,0.119270,0.000000
74.860001,67.316002,-70.769196,0.005786,0.004650,0.118116,299.436523,15.254025,1.181162,-70.769196,0.118359,0.000000
75.110001,66.696373,-70.769196,0.005808,0.004650,0.118107,296.680298,15.113614,1.181075,-70.769196,0.118116,0.000000
75.360001,66.225700,-70.813675,0.005812,0.004648,0.118064,294.586639,15.006958,1.180641,-70.813675,0.118116,0.000000
75.610001,65.807152,-70.769196,0.005803,0.004648,0.118055,292.724823,14.912114,1.180554,-70.769196,0.118116,0.000000
75.860001,65.445198,-70.769196,0.005825,0.004648,0.118055,291.114777,14.830093,1.180554,-70.769196,0.118116,0.000000
76.110001,65.136497,-70.769196,0.005808,0.004648,0.118047,289.741608,14.760141,1.180468,-70.769196,0.118116,0.000000
76.360001,64.844566,-70.769196,0.005821,0.004648,0.118047,288.443024,14.693989,1.180468,-70.769196,0.118116,0.000000
76.610001,64.593208,-70.769196,0.005803,0.004648,0.118047,287.324951,14.637031,1.180468,-70.769196,0.118116,0.000000
76.860001,64.388405,-70.813675,0.005812,0.004648,0.118047,286.413940,14.590621,1.180468,-70.813675,0.118116,0.000000
77.110001,64.164619,-70.769196,0.005808,0.004647,0.118038,285.418488,14.539911,1.180381,-70.769196,0.118116,0.000000
77.360001,63.980293,-70.813675,0.005821,0.004647,0.118038,284.598572,14.498142,1.180381,-70.813675,0.118116,0.000000
77.610001,63.792992,-70.813675,0.005799,0.004647,0.118038,283.765411,14.455699,1.180381,-70.813675,0.118116,0.000000
77.860001,63.643669,-70.902634,0.005795,0.004647,0.118038,283.101166,14.421862,1.180381,-70.902634,0.118116,0.000000
78.110001,63.502541,-70.858154,0.005833,0.004647,0.118038,282.473419,14.389881,1.180381,-70.858154,0.118116,0.000000
78.360001,63.353218,-70.858154,0.005808,0.004647,0.118038,281.809174,14.356044,1.180381,-70.858154,0.118116,0.000000
78.610001,63.211708,-70.902634,0.005821,0.004647,0.118038,281.179718,14.323977,1.180381,-70.902634,0.118116,0.000000
78.860001,63.098137,-70.902634,0.005829,0.004647,0.118038,280.674530,14.298242,1.180381,-70.902634,0.118116,0.000000
79.110001,62.998711,-70.902634,0.005816,0.004647,0.118038,280.232269,14.275712,1.180381,-70.902634,0.118116,0.000000
79.360001,62.879929,-70.902634,0.005812,0.004647,0.118038,279.703888,14.248796,1.180381,-70.902634,0.118116,0.000000
79.610001,62.768219,-70.947121,0.005825,0.004647,0.118029,279.206970,14.223482,1.180294,-70.947121,0.118116,0.000000
79.860001,62.675865,-70.902634,0.005803,0.004647,0.118029,278.796173,14.202554,1.180294,-70.902634,0.118116,0.000000
80.110001,62.576073,-70.947121,0.005812,0.004647,0.118029,278.352264,14.179941,1.180294,-70.947121,0.118116,0.000000
80.360001,62.504204,-70.947121,0.005821,0.004647,0.118029,278.032593,14.163655,1.180294,-70.947121,0.118116,0.000000
80.610001,62.404037,-70.991600,0.005842,0.004647,0.118029,277.587036,14.140958,1.180294,-70.991600,0.118116,0.000000
80.860001,62.308334,-71.036079,0.005846,0.004647,0.118029,277.161316,14.119270,1.180294,-71.036079,0.118116,0.000000
81.110001,62.247269,-70.991600,0.005825,0.004647,0.118029,276.889679,14.105433,1.180294,-70.991600,0.118116,0.000000
81.360001,62.179871,-70.991600,0.005833,0.004647,0.118029,276.589874,14.090160,1.180294,-70.991600,0.118116,0.000000
81.610001,62.098320,-70.991600,0.005812,0.004647,0.118029,276.227112,14.071680,1.180294,-70.991600,0.118116,0.000000
81.860001,62.024216,-70.991600,0.005846,0.004647,0.118029,275.897491,14.054888,1.180294,-70.991600,0.118116,0.000000
82.110001,61.960541,-71.036079,0.005842,0.004647,0.118029,275.614258,14.040460,1.180294,-71.036079,0.118116,0.000000
82.360001,61.896492,-71.080559,0.005829,0.004647,0.118029,275.329346,14.025946,1.180294,-71.080559,0.118116,0.000000
82.610001,61.831696,-71.125038,0.005833,0.004647,0.118029,275.041107,14.011263,1.180294,-71.125038,0.118116,0.000000
82.860001,61.778450,-71.080559,0.005816,0.004647,0.118029,274.804260,13.999197,1.180294,-71.080559,0.118116,0.000000
83.110001,61.711792,-71.080559,0.005846,0.004647,0.118029,274.507751,13.984092,1.180294,-71.080559,0.118116,0.000000
83.360001,61.643280,-71.125038,0.005833,0.004647,0.118029,274.203003,13.968567,1.180294,-71.125038,0.118116,0.000000
83.610001,61.603806,-71.125038,0.005829,0.004647,0.118029,274.027405,13.959621,1.180294,-71.125038,0.118116,0.000000
83.860001,61.548325,-71.080559,0.005833,0.004647,0.118029,273.780609,13.947050,1.180294,-71.080559,0.118116,0.000000
84.110001,61.502525,-71.125038,0.005833,0.004647,0.118029,273.576904,13.936671,1.180294,-71.125038,0.118116,0.000000
84.360001,61.431030,-71.169525,0.005829,0.004647,0.118029,273.258881,13.920470,1.180294,-71.169525,0.118116,0.000000
84.610001,61.401237,-71.169525,0.005851,0.004647,0.118029,273.126343,13.913719,1.180294,-71.169525,0.118116,0.000000
84.860001,61.340912,-71.125038,0.005833,0.004646,0.118021,272.858002,13.900049,1.180208,-71.125038,0.118116,0.000000
85.110001,61.316711,-71.169525,0.005829,0.004646,0.118021,272.750366,13.894566,1.180208,-71.169525,0.118116,0.000000
85.360001,61.256386,-71.169525,0.005838,0.004646,0.118021,272.482025,13.880896,1.180208,-71.169525,0.118116,0.000000
85.610001,61.203133,-71.169525,0.005838,0.004646,0.118021,272.245117,13.868829,1.180208,-71.169525,0.118116,0.000000
85.860001,61.178932,-71.169525,0.005851,0.004646,0.118021,272.137482,13.863344,1.180208,-71.169525,0.118116,0.000000
86.110001,61.123817,-71.258484,0.005838,0.004646,0.118021,271.892334,13.850855,1.180208,-71.258484,0.118116,0.000000
86.360001,61.083229,-71.258484,0.005838,0.004646,0.118021,271.711761,13.841658,1.180208,-71.258484,0.118116,0.000000
86.610001,61.047112,-71.214005,0.005825,0.004646,0.118021,271.551117,13.833473,1.180208,-71.214005,0.118116,0.000000
86.860001,61.003914,-71.169525,0.005846,0.004646,0.118021,271.358948,13.823685,1.180208,-71.169525,0.118116,0.000000
87.110001,60.965561,-71.258484,0.005833,0.004646,0.118021,271.188354,13.814994,1.180208,-71.258484,0.118116,0.000000
87.360001,60.937263,-71.302963,0.005829,0.004646,0.118021,271.062500,13.808581,1.180208,-71.302963,0.118116,0.000000
87.610001,60.908958,-71.302963,0.005868,0.004646,0.118021,270.936584,13.802168,1.180208,-71.302963,0.118116,0.000000
87.860001,60.857201,-71.302963,0.005838,0.004646,0.118021,270.706360,13.790439,1.180208,-71.302963,0.118116,0.000000
88.110001,60.830391,-71.258484,0.005833,0.004646,0.118021,270.587097,13.784364,1.180208,-71.258484,0.118116,0.000000
88.360001,60.789055,-71.258484,0.005855,0.004646,0.118021,270.403229,13.774997,1.180208,-71.258484,0.118116,0.000000
88.610001,60.758148,-71.347443,0.005829,0.004646,0.118021,270.265747,13.767994,1.180208,-71.347443,0.118116,0.000000
88.860001,60.736549,-71.347443,0.005851,0.004646,0.118021,270.169678,13.763099,1.180208,-71.347443,0.118116,0.000000
89.110001,60.701920,-71.347443,0.005838,0.004646,0.118021,270.015625,13.755251,1.180208,-71.347443,0.118116,0.000000
89.360001,60.667664,-71.347443,0.005825,0.004646,0.118021,269.863251,13.747489,1.180208,-71.347443,0.118116,0.000000
89.610001,60.625954,-71.347443,0.005825,0.004646,0.118021,269.677704,13.738038,1.180208,-71.347443,0.118116,0.000000
89.860001,60.593559,-71.436409,0.005829,0.004646,0.118021,269.533600,13.730697,1.180208,-71.436409,0.118116,0.000000
90.110001,60.565636,-71.391930,0.005842,0.004646,0.118021,269.409393,13.724369,1.180208,-71.391930,0.118116,0.000000
90.360001,60.550735,-71.436409,0.005846,0.004646,0.118021,269.343109,13.720993,1.180208,-71.436409,0.118116,0.000000
90.610001,60.513870,-71.436409,0.005829,0.004646,0.118021,269.179138,13.712639,1.180208,-71.436409,0.118116,0.000000
90.860001,60.480736,-71.436409,0.005829,0.004646,0.118021,269.031738,13.705131,1.180208,-71.436409,0.118116,0.000000
91.110001,60.455414,-71.391930,0.005829,0.004646,0.118021,268.919098,13.699392,1.180208,-71.391930,0.118116,0.000000
91.360001,60.425247,-71.436409,0.005833,0.004646,0.118021,268.784912,13.692556,1.180208,-71.436409,0.118116,0.000000
91.610001,60.398437,-71.436409,0.005829,0.004646,0.118021,268.665680,13.686481,1.180208,-71.436409,0.118116,0.000000
91.860001,60.375725,-71.525368,0.005838,0.004646,0.118021,268.564636,13.681334,1.180208,-71.525368,0.118116,0.000000
92.110001,60.345558,-71.480888,0.005842,0.004646,0.118021,268.430450,13.674499,1.180208,-71.480888,0.118116,0.000000
92.360001,60.323219,-71.480888,0.005846,0.004646,0.118021,268.331085,13.669436,1.180208,-71.480888,0.118116,0.000000
92.610001,60.291565,-71.436409,0.005833,0.004646,0.118021,268.190277,13.662264,1.180208,-71.436409,0.118116,0.000000
92.860001,60.281509,-71.480888,0.005851,0.004646,0.118021,268.145538,13.659985,1.180208,-71.480888,0.118116,0.000000
93.110001,60.255447,-71.525368,0.005838,0.004646,0.118021,268.029602,13.654079,1.180208,-71.525368,0.118116,0.000000
93.360008,60.231239,-71.569847,0.005859,0.004646,0.118021,267.921936,13.648595,1.180208,-71.569847,0.118116,0.000000
93.610008,60.196609,-71.614334,0.005821,0.004646,0.118021,267.767883,13.640747,1.180208,-71.614334,0.118116,0.000000
93.860008,60.178368,-71.614334,0.005842,0.004646,0.118021,267.686737,13.636613,1.180208,-71.614334,0.118116,0.000000
94.110008,60.159378,-71.569847,0.005838,0.004646,0.118021,267.602264,13.632310,1.180208,-71.569847,0.118116,0.000000
94.360008,60.131821,-71.614334,0.005851,0.004646,0.118021,267.479706,13.626065,1.180208,-71.614334,0.118116,0.000000
94.610008,60.114319,-71.614334,0.005842,0.004646,0.118021,267.401855,13.622099,1.180208,-71.614334,0.118116,0.000000
94.860008,60.089745,-71.569847,0.005846,0.004646,0.118021,267.292542,13.616531,1.180208,-71.569847,0.118116,0.000000
95.110008,60.055855,-71.614334,0.005833,0.004646,0.118021,267.141785,13.608850,1.180208,-71.614334,0.118116,0.000000
95.360008,60.042824,-71.658813,0.005855,0.004646,0.118021,267.083832,13.605899,1.180208,-71.658813,0.118116,0.000000
95.610008,60.027184,-71.614334,0.005851,0.004646,0.118021,267.014252,13.602354,1.180208,-71.614334,0.118116,0.000000
95.860008,60.006332,-71.614334,0.005851,0.004646,0.118021,266.921509,13.597629,1.180208,-71.614334,0.118116,0.000000
96.110008,59.991432,-71.703293,0.005846,0.004646,0.118021,266.855225,13.594253,1.180208,-71.703293,0.118116,0.000000
96.360008,59.966858,-71.703293,0.005846,0.004646,0.118021,266.745911,13.588684,1.180208,-71.703293,0.118116,0.000000
96.610008,59.942284,-71.658813,0.005838,0.004646,0.118021,266.636597,13.583116,1.180208,-71.658813,0.118116,0.000000
96.860008,59.932228,-71.703293,0.005842,0.004646,0.118021,266.591858,13.580836,1.180208,-71.703293,0.118116,0.000000
97.110008,59.908394,-71.747772,0.005825,0.004646,0.118021,266.485840,13.575436,1.180208,-71.747772,0.118116,0.000000
97.360008,59.896111,-71.703293,0.005855,0.004646,0.118021,266.431213,13.572653,1.180208,-71.703293,0.118116,0.000000
97.610008,59.871529,-71.703293,0.005851,0.004646,0.118021,266.321869,13.567082,1.180208,-71.703293,0.118116,0.000000
97.860008,59.854774,-71.703293,0.005855,0.004646,0.118021,266.247345,13.563285,1.180208,-71.703293,0.118116,0.000000
98.110008,59.831688,-71.658813,0.005851,0.004646,0.118021,266.144653,13.558054,1.180208,-71.658813,0.118116,0.000000
98.360008,59.801155,-71.703293,0.005877,0.004646,0.118021,266.008820,13.551136,1.180208,-71.703293,0.118116,0.000000
98.610008,59.797058,-71.703293,0.005838,0.004646,0.118021,265.990601,13.550207,1.180208,-71.703293,0.118116,0.000000
98.860008,59.764290,-71.792252,0.005855,0.004646,0.118021,265.844849,13.542782,1.180208,-71.792252,0.118116,0.000000
99.110008,59.765404,-71.836739,0.005838,0.004646,0.118021,265.849792,13.543035,1.180208,-71.836739,0.118116,0.000000
99.360008,59.734497,-71.792252,0.005842,0.004646,0.118021,265.712311,13.536030,1.180208,-71.792252,0.118116,0.000000
99.610008,59.714760,-71.747772,0.005851,0.004646,0.118021,265.624512,13.531558,1.180208,-71.747772,0.118116,0.000000
99.860008,59.703217,-71.792252,0.005833,0.004646,0.118021,265.573181,13.528943,1.180208,-71.792252,0.118116,0.000000
100.110008,59.679390,-71.836739,0.005821,0.004646,0.118021,265.467194,13.523542,1.180208,-71.836739,0.118116,0.000000
100.360008,59.671570,-71.792252,0.005855,0.004646,0.118021,265.432404,13.521770,1.180208,-71.792252,0.118116,0.000000
100.610008,59.652946,-71.881218,0.005842,0.004646,0.118021,265.349548,13.517551,1.180208,-71.881218,0.118116,0.000000
100.860008,59.631721,-71.881218,0.005855,0.004646,0.118021,265.255157,13.512741,1.180208,-71.881218,0.118116,0.000000
101.110008,59.620178,-71.836739,0.005833,0.004646,0.118021,265.203796,13.510126,1.180208,-71.836739,0.118116,0.000000
101.360008,59.603424,-71.836739,0.005842,0.004646,0.118021,265.129272,13.506330,1.180208,-71.836739,0.118116,0.000000
101.610008,59.594856,-71.836739,0.005833,0.004646,0.118021,265.091156,13.504388,1.180208,-71.836739,0.118116,0.000000
101.860008,59.574753,-71.881218,0.005829,0.004646,0.118021,265.001740,13.499832,1.180208,-71.881218,0.118116,0.000000
102.110008,59.552032,-71.881218,0.005821,0.004646,0.118021,264.900665,13.494683,1.180208,-71.881218,0.118116,0.000000
102.360008,59.544586,-71.925697,0.005851,0.004646,0.118021,264.867554,13.492996,1.180208,-71.925697,0.118116,0.000000
102.610008,59.518890,-71.925697,0.005838,0.004646,0.118021,264.753235,13.487173,1.180208,-71.925697,0.118116,0.000000
102.860008,59.522987,-71.925697,0.005855,0.004646,0.118021,264.771484,13.488102,1.180208,-71.925697,0.118116,0.000000
103.110008,59.501762,-71.925697,0.005838,0.004646,0.118021,264.677063,13.483292,1.180208,-71.925697,0.118116,0.000000
103.360008,59.482773,-71.881218,0.005855,0.004646,0.118021,264.592590,13.478989,1.180208,-71.881218,0.118116,0.000000
103.610008,59.455215,-71.970177,0.005864,0.004646,0.118021,264.470001,13.472745,1.180208,-71.970177,0.118116,0.000000
103.860008,59.450378,-71.970177,0.005846,0.004646,0.118021,264.448486,13.471648,1.180208,-71.970177,0.118116,0.000000
104.110008,59.440323,-71.970177,0.005846,0.004646,0.118021,264.403748,13.469370,1.180208,-71.970177,0.118116,0.000000
104.360008,59.427292,-71.970177,0.005846,0.004646,0.118021,264.345795,13.466417,1.180208,-71.970177,0.118116,0.000000
104.610008,59.411278,-71.970177,0.005838,0.004646,0.118021,264.274567,13.462789,1.180208,-71.970177,0.118116,0.000000
104.860008,59.387817,-72.014656,0.005859,0.004646,0.118021,264.170197,13.457472,1.180208,-72.014656,0.118116,0.000000
105.110008,59.370689,-72.014656,0.005846,0.004646,0.118021,264.094025,13.453591,1.180208,-72.014656,0.118116,0.000000
105.200005,59.372551,-72.014656,0.005877,0.004646,0.118021,264.102295,13.454012,1.180208,-72.014656,0.118116,0.000000