File: Data/Symmetrical membranes compression/Sartorius Cellulose Nitrate 5um test 3_10302023_170908.csv
Time (sec),S:Load (lbs),S:HL1 (DIM),S:LVDT (in),S:Position (in),Ch:Position (mm),Ch:Load (N),Ch:Stress (MPa),Ch:Strain (mm/mm),Ch:HL1 (DIM),Set Point (),Cycles ()
0.110000,0.004845,-82.690086,-0.000013,-0.000000,-0.000000,0.021550,0.001098,-0.000000,-82.690086,0.000225,0.000000
0.360000,0.082298,-82.645607,-0.000017,0.000001,0.000035,0.366081,0.018649,0.000347,-82.645607,0.000538,0.000000
0.610000,0.103897,-82.645607,-0.000030,0.000141,0.003573,0.462157,0.023543,0.035730,-82.645607,0.004700,0.000000
0.860000,0.132195,-82.734566,0.000125,0.000295,0.007484,0.588031,0.029956,0.074842,-82.734566,0.008863,0.000000
1.110000,0.151932,-82.645607,0.000332,0.000463,0.011751,0.675826,0.034428,0.117510,-82.645607,0.013026,0.000000
1.360000,0.138153,-82.645607,0.000474,0.000628,0.015948,0.614536,0.031306,0.159483,-82.645607,0.017206,0.000000
1.610000,0.195496,-82.690086,0.000664,0.000795,0.020180,0.869608,0.044300,0.201804,-82.690086,0.021368,0.000000
1.860000,0.238319,-82.645607,0.000811,0.000950,0.024118,1.060098,0.054004,0.241176,-82.645607,0.025531,0.000000
2.110000,0.336998,-82.690086,0.001009,0.001116,0.028358,1.499042,0.076365,0.283583,-82.690086,0.029694,0.000000
2.360000,0.509033,-82.734566,0.001155,0.001277,0.032426,2.264293,0.115349,0.324256,-82.734566,0.033857,0.000000
2.610000,0.625587,-82.690086,0.001276,-0.000006,-0.000147,2.782752,0.141760,-0.001474,-82.690086,0.000095,0.000000
2.860000,0.611435,-82.779053,0.001263,-0.000006,-0.000147,2.719798,0.138553,-0.001474,-82.779053,0.000095,0.000000
3.110000,0.643837,-82.779053,0.001289,-0.000006,-0.000147,2.863930,0.145896,-0.001474,-82.779053,0.000147,0.000000
3.360000,0.653145,-82.734566,0.001263,-0.000006,-0.000147,2.905333,0.148005,-0.001474,-82.734566,0.000564,0.000000
3.610000,0.636757,-82.823532,0.001250,-0.000006,-0.000147,2.832436,0.144291,-0.001474,-82.823532,0.000980,0.000000
3.860000,0.631546,-82.734566,0.001263,-0.000005,-0.000139,2.809257,0.143110,-0.001388,-82.734566,0.001396,0.000000
4.110000,0.639740,-82.734566,0.001268,-0.000005,-0.000139,2.845706,0.144967,-0.001388,-82.734566,0.001812,0.000000
4.360000,0.726501,-82.868011,0.001311,0.000043,0.001101,3.231640,0.164628,0.011013,-82.868011,0.002229,0.000000
4.610000,0.742516,-82.823532,0.001319,0.000057,0.001440,3.302874,0.168256,0.014396,-82.823532,0.002645,0.000000
4.860000,0.789803,-82.823532,0.001332,0.000075,0.001899,3.513217,0.178972,0.018992,-82.823532,0.003061,0.000000
5.110000,0.790924,-82.779053,0.001384,0.000098,0.002498,3.518206,0.179226,0.024976,-82.779053,0.003478,0.000000
5.360000,0.827042,-82.779053,0.001371,0.000110,0.002801,3.678865,0.187410,0.028011,-82.779053,0.003894,0.000000
5.610000,0.825928,-82.868011,0.001406,0.000132,0.003347,3.673910,0.187158,0.033475,-82.868011,0.004310,0.000000
5.860000,0.833748,-82.868011,0.001406,0.000144,0.003668,3.708696,0.188930,0.036683,-82.868011,0.004726,0.000000
6.110000,0.869118,-82.823532,0.001427,0.000163,0.004137,3.866029,0.196945,0.041366,-82.823532,0.005143,0.000000
6.360000,0.954391,-82.868011,0.001444,0.000178,0.004510,4.245345,0.216268,0.045095,-82.868011,0.005559,0.000000
6.610000,0.989021,-82.912491,0.001444,0.000191,0.004848,4.399386,0.224115,0.048478,-82.912491,0.005975,0.000000
6.860000,1.011742,-82.956970,0.001496,0.000207,0.005247,4.500452,0.229264,0.052467,-82.956970,0.006391,0.000000
7.110000,1.032219,-82.912491,0.001505,0.000228,0.005784,4.591539,0.233904,0.057844,-82.912491,0.006808,0.000000
7.360000,1.067596,-82.956970,0.001518,0.000241,0.006123,4.748906,0.241921,0.061226,-82.956970,0.007233,0.000000
7.610000,1.082115,-82.956970,0.001526,0.000258,0.006565,4.813488,0.245211,0.065649,-82.956970,0.007649,0.000000
7.860001,1.108925,-82.912491,0.001531,0.000277,0.007024,4.932744,0.251286,0.070245,-82.912491,0.008065,0.000000
8.110001,1.133507,-82.956970,0.001565,0.000291,0.007389,5.042090,0.256856,0.073888,-82.956970,0.008481,0.000000
8.360001,1.184151,-82.956970,0.001595,0.000308,0.007822,5.267365,0.268332,0.078223,-82.956970,0.008898,0.000000
8.610001,1.210587,-82.912491,0.001591,0.000318,0.008083,5.384958,0.274323,0.080825,-82.912491,0.009314,0.000000
8.860001,1.258621,-82.956970,0.001608,0.000341,0.008664,5.598627,0.285208,0.086635,-82.956970,0.009730,0.000000
9.110001,1.303307,-82.956970,0.001660,0.000361,0.009175,5.797397,0.295334,0.091752,-82.956970,0.010147,0.000000
9.360001,1.319321,-83.001457,0.001638,0.000375,0.009513,5.868631,0.298962,0.095134,-83.001457,0.010563,0.000000
9.610001,1.328255,-82.912491,0.001669,0.000390,0.009904,5.908372,0.300987,0.099037,-82.912491,0.010979,0.000000
9.860001,1.372940,-83.090416,0.001681,0.000406,0.010311,6.107142,0.311113,0.103113,-83.090416,0.011395,0.000000
10.110001,1.400124,-83.001457,0.001729,0.000424,0.010780,6.228061,0.317273,0.107796,-83.001457,0.011812,0.000000
10.360001,1.455978,-83.045937,0.001694,0.000434,0.011022,6.476515,0.329929,0.110224,-83.045937,0.012228,0.000000
10.610001,1.480186,-83.090416,0.001742,0.000449,0.011404,6.584198,0.335415,0.114040,-83.090416,0.012644,0.000000
10.860001,1.557266,-83.134895,0.001772,0.000472,0.011994,6.927066,0.352882,0.119937,-83.134895,0.013060,0.000000
11.110001,1.613495,-83.090416,0.001781,0.000495,0.012566,7.177184,0.365623,0.125660,-83.090416,0.013477,0.000000
11.360001,1.628014,-83.090416,0.001785,0.000509,0.012922,7.241766,0.368913,0.129216,-83.090416,0.013893,0.000000
11.610001,1.625412,-83.045937,0.001798,0.000523,0.013286,7.230194,0.368324,0.132858,-83.045937,0.014309,0.000000
11.860001,1.671211,-83.134895,0.001824,0.000537,0.013650,7.433919,0.378702,0.136501,-83.134895,0.014726,0.000000
12.110001,1.750900,-83.090416,0.001841,0.000559,0.014196,7.788393,0.396760,0.141965,-83.090416,0.015142,0.000000
12.360001,1.769516,-83.134895,0.001863,0.000572,0.014535,7.871200,0.400978,0.145347,-83.134895,0.015567,0.000000
12.610001,1.763184,-83.090416,0.001867,0.000580,0.014726,7.843032,0.399543,0.147255,-83.090416,0.015983,0.000000
12.860001,1.890541,-83.179375,0.001893,0.000609,0.015463,8.409547,0.428403,0.154626,-83.179375,0.016399,0.000000
13.110001,1.918465,-83.134895,0.001914,0.000624,0.015853,8.533757,0.434730,0.158528,-83.134895,0.016815,0.000000
13.360001,1.913994,-83.134895,0.001910,0.000637,0.016174,8.513870,0.433717,0.161737,-83.134895,0.017232,0.000000
13.610001,1.946022,-83.134895,0.001949,0.000655,0.016642,8.656339,0.440975,0.166420,-83.134895,0.017648,0.000000
13.860001,1.978416,-83.179375,0.001962,0.000669,0.016980,8.800436,0.448316,0.169803,-83.179375,0.018064,0.000000
14.110001,2.060341,-83.179375,0.001979,0.000689,0.017501,9.164854,0.466880,0.175006,-83.179375,0.018481,0.000000
14.360001,2.073746,-83.223862,0.002001,0.000701,0.017795,9.224482,0.469918,0.177954,-83.223862,0.018897,0.000000
14.610001,2.119545,-83.223862,0.002009,0.000715,0.018160,9.428207,0.480296,0.181596,-83.223862,0.019313,0.000000
14.860001,2.130714,-83.223862,0.002018,0.000722,0.018333,9.477891,0.482827,0.183331,-83.223862,0.019729,0.000000
15.110001,2.229027,-83.179375,0.002061,0.000752,0.019096,9.915206,0.505105,0.190963,-83.179375,0.020146,0.000000
15.360001,2.234985,-83.223862,0.002052,0.000767,0.019469,9.941711,0.506455,0.194692,-83.223862,0.020562,0.000000
15.610001,2.295303,-83.268341,0.002100,0.000788,0.020007,10.210019,0.520123,0.200069,-83.268341,0.020978,0.000000
15.860001,2.359726,-83.223862,0.002113,0.000804,0.020414,10.496585,0.534722,0.204145,-83.223862,0.021394,0.000000
16.110001,2.384674,-83.223862,0.002126,0.000821,0.020865,10.607560,0.540375,0.208655,-83.223862,0.021811,0.000000
16.360001,2.404037,-83.268341,0.002151,0.000831,0.021108,10.693693,0.544763,0.211083,-83.268341,0.022227,0.000000
16.610001,2.434570,-83.268341,0.002151,0.000843,0.021412,10.829510,0.551682,0.214118,-83.268341,0.022643,0.000000
16.860001,2.497505,-83.268341,0.002182,0.000866,0.021993,11.109458,0.565943,0.219928,-83.268341,0.023059,0.000000
17.110001,2.540703,-83.312820,0.002186,0.000882,0.022400,11.301611,0.575732,0.224004,-83.312820,0.023476,0.000000
17.360001,2.581291,-83.312820,0.002199,0.000903,0.022938,11.482157,0.584929,0.229381,-83.312820,0.023892,0.000000
17.610001,2.575706,-83.312820,0.002225,0.000912,0.023164,11.457314,0.583663,0.231636,-83.312820,0.024317,0.000000
17.860001,2.616661,-83.312820,0.002246,0.000926,0.023519,11.639490,0.592944,0.235191,-83.312820,0.024733,0.000000
18.110001,2.686295,-83.357300,0.002264,0.000945,0.024013,11.949235,0.608723,0.240135,-83.357300,0.025149,0.000000
18.360001,2.733215,-83.312820,0.002259,0.000958,0.024343,12.157949,0.619355,0.243430,-83.312820,0.025566,0.000000
18.610001,2.748108,-83.357300,0.002276,0.000972,0.024690,12.224195,0.622730,0.246899,-83.357300,0.025982,0.000000
18.860001,2.816254,-83.312820,0.002311,0.000995,0.025262,12.527322,0.638172,0.252623,-83.312820,0.026398,0.000000
19.110001,2.808060,-83.357300,0.002328,0.001008,0.025600,12.490873,0.636315,0.256005,-83.357300,0.026815,0.000000
19.360001,2.895569,-83.357300,0.002345,0.001032,0.026225,12.880134,0.656145,0.262249,-83.357300,0.027231,0.000000
19.610001,2.916794,-83.401787,0.002358,0.001042,0.026476,12.974547,0.660955,0.264764,-83.401787,0.027647,0.000000
19.860001,2.997604,-83.401787,0.002380,0.001065,0.027040,13.334010,0.679267,0.270400,-83.401787,0.028063,0.000000
20.110001,3.026276,-83.401787,0.002402,0.001078,0.027378,13.461546,0.685764,0.273783,-83.401787,0.028480,0.000000
20.360001,3.047874,-83.401787,0.002406,0.001092,0.027743,13.557623,0.690658,0.277425,-83.401787,0.028896,0.000000
20.610001,3.108940,-83.446266,0.002432,0.001111,0.028211,13.829256,0.704496,0.282108,-83.446266,0.029312,0.000000
20.860001,3.067978,-83.401787,0.002440,0.001122,0.028497,13.647047,0.695214,0.284970,-83.401787,0.029728,0.000000
21.110001,3.184158,-83.357300,0.002462,0.001139,0.028931,14.163843,0.721541,0.289306,-83.357300,0.030145,0.000000
21.360001,3.210968,-83.446266,0.002475,0.001158,0.029416,14.283099,0.727616,0.294163,-83.446266,0.030561,0.000000
21.610001,3.218048,-83.490746,0.002496,0.001173,0.029789,14.314593,0.729220,0.297892,-83.490746,0.030977,0.000000
21.860001,3.304810,-83.490746,0.002509,0.001189,0.030197,14.700527,0.748881,0.301967,-83.490746,0.031394,0.000000
22.110001,3.381142,-83.490746,0.002548,0.001211,0.030761,15.040070,0.766178,0.307605,-83.490746,0.031810,0.000000
22.360001,3.339813,-83.490746,0.002527,0.001215,0.030873,14.856232,0.756812,0.308732,-83.490746,0.032226,0.000000
22.610001,3.458969,-83.535225,0.002561,0.001242,0.031541,15.386263,0.783814,0.315409,-83.535225,0.032651,0.000000
22.860001,3.511848,-83.535225,0.002570,0.001259,0.031975,15.621482,0.795796,0.319746,-83.535225,0.033067,0.000000
23.110001,3.503654,-83.490746,0.002596,0.001276,0.032400,15.585033,0.793939,0.323996,-83.490746,0.033484,0.000000
23.360001,3.532700,-83.490746,0.002613,0.001292,0.032825,15.714232,0.800521,0.328245,-83.490746,0.033900,0.000000
23.610001,3.568077,-83.490746,0.002634,0.001304,0.033119,15.871599,0.808538,0.331193,-83.490746,0.034316,0.000000
23.860001,3.705109,-83.490746,0.002652,0.001326,0.033692,16.481146,0.839590,0.336917,-83.490746,0.034732,0.000000
24.110001,3.680908,-83.490746,0.002656,0.001335,0.033917,16.373497,0.834106,0.339172,-83.490746,0.035149,0.000000
24.360001,3.759102,-83.579704,0.002673,0.001355,0.034412,16.721321,0.851825,0.344115,-83.579704,0.035565,0.000000
24.610001,3.823524,-83.579704,0.002712,0.001378,0.035001,17.007887,0.866423,0.350012,-83.579704,0.035981,0.000000
24.860001,3.879379,-83.579704,0.002716,0.001394,0.035417,17.256340,0.879080,0.354174,-83.579704,0.036397,0.000000
25.110001,3.835442,-83.624191,0.002721,0.001404,0.035652,17.060896,0.869123,0.356516,-83.624191,0.036814,0.000000
25.360001,3.893898,-83.579704,0.002746,0.001423,0.036137,17.320923,0.882370,0.361372,-83.579704,0.037230,0.000000
25.610001,3.963531,-83.579704,0.002772,0.001437,0.036510,17.630669,0.898149,0.365101,-83.579704,0.037646,0.000000
25.860001,3.980293,-83.668671,0.002790,0.001450,0.036831,17.705229,0.901947,0.368311,-83.668671,0.038063,0.000000
26.110001,4.096100,-83.668671,0.002790,0.001468,0.037291,18.220362,0.928190,0.372907,-83.668671,0.038479,0.000000
26.360001,4.070404,-83.668671,0.002802,0.001474,0.037438,18.106062,0.922367,0.374381,-83.668671,0.038895,0.000000
26.610001,4.249519,-83.624191,0.002828,0.001509,0.038331,18.902805,0.962955,0.383313,-83.624191,0.039311,0.000000
26.860001,4.232018,-83.668671,0.002850,0.001521,0.038635,18.824955,0.958989,0.386349,-83.668671,0.039728,0.000000
27.110001,4.282661,-83.713150,0.002854,0.001542,0.039155,19.050230,0.970465,0.391552,-83.713150,0.040144,0.000000
27.360001,4.333672,-83.668671,0.002910,0.001560,0.039615,19.277134,0.982024,0.396149,-83.668671,0.040560,0.000000
27.610001,4.363838,-83.668671,0.002893,0.001571,0.039892,19.411322,0.988860,0.398923,-83.668671,0.040985,0.000000
27.860001,4.455070,-83.713150,0.002910,0.001589,0.040352,19.817142,1.009533,0.403520,-83.713150,0.041401,0.000000
28.110001,4.439796,-83.757629,0.002910,0.001594,0.040491,19.749201,1.006072,0.404907,-83.757629,0.041818,0.000000
28.360001,4.593590,-83.757629,0.002958,0.001624,0.041245,20.433308,1.040922,0.412452,-83.757629,0.042234,0.000000
28.610001,4.628967,-83.713150,0.002975,0.001639,0.041627,20.590675,1.048939,0.416268,-83.713150,0.042650,0.000000
28.860001,4.646835,-83.757629,0.002971,0.001650,0.041922,20.670156,1.052988,0.419217,-83.757629,0.043066,0.000000
29.110001,4.701576,-83.757629,0.003018,0.001669,0.042390,20.913656,1.065392,0.423900,-83.757629,0.043483,0.000000
29.360001,4.741791,-83.802109,0.003027,0.001683,0.042754,21.092539,1.074505,0.427542,-83.802109,0.043899,0.000000
29.610001,4.782753,-83.802109,0.003048,0.001697,0.043101,21.274748,1.083787,0.431011,-83.802109,0.044315,0.000000
29.860001,4.892235,-83.802109,0.003057,0.001716,0.043587,21.761747,1.108596,0.435868,-83.802109,0.044731,0.000000
30.110001,4.936920,-83.802109,0.003074,0.001731,0.043968,21.960518,1.118722,0.439683,-83.802109,0.045148,0.000000
30.360001,5.035599,-83.802109,0.003083,0.001754,0.044549,22.399462,1.141083,0.445493,-83.802109,0.045564,0.000000
30.610001,5.101135,-83.846596,0.003104,0.001771,0.044974,22.690983,1.155934,0.449743,-83.846596,0.045980,0.000000
30.860001,5.086609,-83.802109,0.003122,0.001784,0.045312,22.626366,1.152642,0.453125,-83.802109,0.046397,0.000000
31.110001,5.150284,-83.846596,0.003122,0.001799,0.045685,22.909607,1.167071,0.456854,-83.846596,0.046813,0.000000
31.360001,5.172256,-83.846596,0.003139,0.001811,0.046006,23.007345,1.172050,0.460063,-83.846596,0.047229,0.000000
31.610001,5.317856,-83.891075,0.003173,0.001833,0.046553,23.655005,1.205043,0.465527,-83.891075,0.047645,0.000000
31.860001,5.304451,-83.891075,0.003199,0.001843,0.046813,23.595377,1.202006,0.468128,-83.891075,0.048062,0.000000
32.110001,5.418770,-83.891075,0.003186,0.001862,0.047307,24.103891,1.227911,0.473071,-83.891075,0.048478,0.000000
32.360001,5.553566,-83.891075,0.003199,0.001883,0.047836,24.703495,1.258456,0.478362,-83.891075,0.048894,0.000000
32.610001,5.637352,-83.891075,0.003260,0.001902,0.048313,25.076195,1.277442,0.483131,-83.891075,0.049310,0.000000
32.860001,5.628784,-83.935555,0.003268,0.001918,0.048721,25.038082,1.275501,0.487207,-83.935555,0.049735,0.000000
33.110001,5.647400,-83.891075,0.003272,0.001931,0.049050,25.120890,1.279719,0.490503,-83.891075,0.050152,0.000000
33.360001,5.822044,-83.935555,0.003320,0.001952,0.049588,25.897747,1.319294,0.495879,-83.935555,0.050568,0.000000
33.610001,5.838806,-83.935555,0.003303,0.001967,0.049961,25.972307,1.323092,0.499608,-83.935555,0.050984,0.000000
33.860001,5.842896,-83.935555,0.003328,0.001979,0.050273,25.990498,1.324019,0.502731,-83.935555,0.051400,0.000000
34.110001,6.056267,-83.935555,0.003354,0.002003,0.050871,26.939621,1.372370,0.508714,-83.935555,0.051817,0.000000
34.360001,6.111755,-83.891075,0.003389,0.002019,0.051288,27.186445,1.384944,0.512877,-83.891075,0.052233,0.000000
34.610001,6.153458,-83.935555,0.003393,0.002035,0.051678,27.371946,1.394393,0.516779,-83.935555,0.052649,0.000000
34.860001,6.211174,-83.980034,0.003372,0.002052,0.052112,27.628681,1.407472,0.521116,-83.980034,0.053066,0.000000
35.110001,6.210060,-84.024513,0.003428,0.002064,0.052432,27.623728,1.407220,0.524324,-84.024513,0.053482,0.000000
35.360001,6.300545,-83.980034,0.003436,0.002083,0.052901,28.026222,1.427724,0.529007,-83.980034,0.053898,0.000000
35.610001,6.411514,-84.024513,0.003449,0.002098,0.053300,28.519840,1.452870,0.532996,-84.024513,0.054314,0.000000
35.860001,6.291237,-84.024513,0.003454,0.002101,0.053378,27.984819,1.425615,0.533777,-84.024513,0.054731,0.000000
36.110001,6.409653,-84.024513,0.003471,0.002116,0.053751,28.511559,1.452448,0.537506,-84.024513,0.055147,0.000000
36.360001,6.780907,-84.024513,0.003484,0.002149,0.054574,30.162979,1.536575,0.545745,-84.024513,0.055563,0.000000
36.610001,6.751862,-84.113480,0.003514,0.002162,0.054921,30.033781,1.529994,0.549214,-84.113480,0.055979,0.000000
36.860001,6.878098,-84.069000,0.003544,0.002182,0.055424,30.595306,1.558599,0.554244,-84.069000,0.056396,0.000000
37.110001,6.911232,-84.069000,0.003557,0.002198,0.055832,30.742695,1.566108,0.558319,-84.069000,0.056812,0.000000
37.360001,6.992783,-84.069000,0.003574,0.002213,0.056214,31.105450,1.584587,0.562135,-84.069000,0.057228,0.000000
37.610001,7.040451,-84.113480,0.003570,0.002227,0.056578,31.317490,1.595389,0.565777,-84.113480,0.057644,0.000000
37.860001,7.105614,-84.113480,0.003591,0.002240,0.056907,31.607347,1.610155,0.569073,-84.113480,0.058069,0.000000
38.110001,7.285095,-84.069000,0.003622,0.002263,0.057471,32.405724,1.650826,0.574710,-84.069000,0.058486,0.000000
38.360001,7.342445,-84.157959,0.003622,0.002279,0.057879,32.660828,1.663822,0.578786,-84.157959,0.058902,0.000000
38.610001,7.460487,-84.113480,0.003648,0.002298,0.058364,33.185905,1.690571,0.583643,-84.113480,0.059318,0.000000
38.860001,7.408356,-84.157959,0.003660,0.002306,0.058564,32.954014,1.678757,0.585637,-84.157959,0.059734,0.000000
39.110001,7.544266,-84.157959,0.003673,0.002322,0.058989,33.558571,1.709555,0.589886,-84.157959,0.060151,0.000000
39.360001,7.627678,-84.202438,0.003695,0.002336,0.059344,33.929607,1.728456,0.593442,-84.202438,0.060567,0.000000
39.610001,7.832855,-84.157959,0.003695,0.002357,0.059856,34.842281,1.774950,0.598559,-84.157959,0.060983,0.000000
39.860001,7.880524,-84.246918,0.003738,0.002370,0.060203,35.054321,1.785752,0.602028,-84.246918,0.061400,0.000000
40.110001,8.011597,-84.202438,0.003760,0.002390,0.060714,35.637363,1.815454,0.607144,-84.202438,0.061816,0.000000
40.360001,8.064842,-84.246918,0.003768,0.002403,0.061027,35.874210,1.827519,0.610266,-84.246918,0.062232,0.000000
40.610001,8.219009,-84.202438,0.003781,0.002423,0.061547,36.559978,1.862454,0.615470,-84.202438,0.062648,0.000000
40.860001,8.314339,-84.202438,0.003794,0.002440,0.061981,36.984024,1.884056,0.619806,-84.202438,0.063065,0.000000
41.110001,8.423813,-84.202438,0.003816,0.002459,0.062466,37.470989,1.908863,0.624663,-84.202438,0.063481,0.000000
41.360001,8.510201,-84.246918,0.003824,0.002472,0.062787,37.855263,1.928439,0.627872,-84.246918,0.063897,0.000000
41.610001,8.569786,-84.291405,0.003837,0.002487,0.063160,38.120312,1.941941,0.631601,-84.291405,0.064313,0.000000
41.860001,8.692665,-84.291405,0.003863,0.002503,0.063568,38.666904,1.969786,0.635676,-84.291405,0.064730,0.000000
42.110001,8.622284,-84.291405,0.003867,0.002510,0.063750,38.353836,1.953837,0.637497,-84.291405,0.065146,0.000000
42.360001,9.015137,-84.291405,0.003889,0.002537,0.064444,40.101330,2.042859,0.644435,-84.291405,0.065562,0.000000
42.610001,9.081795,-84.291405,0.003915,0.002553,0.064851,40.397842,2.057964,0.648511,-84.291405,0.065978,0.000000
42.860001,9.139885,-84.335884,0.003941,0.002566,0.065172,40.656239,2.071128,0.651720,-84.335884,0.066403,0.000000
43.110001,9.338356,-84.335884,0.003941,0.002587,0.065710,41.539082,2.116102,0.657097,-84.335884,0.066820,0.000000
43.360001,9.441879,-84.291405,0.003958,0.002606,0.066195,41.999577,2.139560,0.661954,-84.291405,0.067236,0.000000
43.610001,9.507416,-84.380363,0.003967,0.002617,0.066464,42.291096,2.154411,0.664642,-84.380363,0.067652,0.000000
43.860001,9.272079,-84.380363,0.003971,0.002617,0.066464,41.244270,2.101083,0.664642,-84.380363,0.068068,0.000000
44.110001,10.004158,-84.380363,0.004010,0.002656,0.067461,44.500717,2.266975,0.674615,-84.380363,0.068485,0.000000
44.360001,10.004158,-84.380363,0.004023,0.002671,0.067834,44.500717,2.266975,0.678344,-84.380363,0.068901,0.000000
44.610001,10.029480,-84.380363,0.004031,0.002686,0.068233,44.613354,2.272713,0.682333,-84.380363,0.069317,0.000000
44.860001,9.984428,-84.380363,0.004057,0.002695,0.068441,44.412956,2.262504,0.684414,-84.380363,0.069734,0.000000
45.110001,10.299828,-84.380363,0.004061,0.002716,0.068996,45.815922,2.333974,0.689965,-84.380363,0.070150,0.000000
45.360001,10.529579,-84.335884,0.004105,0.002734,0.069439,46.837906,2.386037,0.694387,-84.335884,0.070566,0.000000
45.610001,10.678528,-84.424843,0.004100,0.002750,0.069838,47.500465,2.419789,0.698377,-84.424843,0.070982,0.000000
45.860001,10.651344,-84.424843,0.004105,0.002761,0.070124,47.379547,2.413629,0.701239,-84.424843,0.071399,0.000000
46.110001,11.107872,-84.469330,0.004152,0.002789,0.070844,49.410282,2.517080,0.708437,-84.469330,0.071815,0.000000
46.360001,11.050156,-84.424843,0.004156,0.002801,0.071156,49.153545,2.504001,0.711558,-84.424843,0.072231,0.000000
46.610001,11.197617,-84.469330,0.004165,0.002818,0.071589,49.809486,2.537416,0.715895,-84.469330,0.072647,0.000000
46.860001,11.273582,-84.469330,0.004182,0.002833,0.071962,50.147400,2.554630,0.719624,-84.469330,0.073064,0.000000
47.110001,11.357361,-84.469330,0.004186,0.002842,0.072188,50.520065,2.573615,0.721879,-84.469330,0.073480,0.000000
47.360001,11.503334,-84.469330,0.004212,0.002859,0.072630,51.169384,2.606693,0.726301,-84.469330,0.073896,0.000000
47.610001,11.964699,-84.424843,0.004217,0.002882,0.073194,53.221638,2.711240,0.731938,-84.424843,0.074313,0.000000
47.860001,12.349365,-84.469330,0.004255,0.002907,0.073827,54.932720,2.798406,0.738269,-84.469330,0.074729,0.000000
48.110001,12.264465,-84.513809,0.004264,0.002919,0.074139,54.555065,2.779167,0.741391,-84.513809,0.075154,0.000000
48.360001,12.403358,-84.558289,0.004286,0.002936,0.074564,55.172894,2.810641,0.745640,-84.558289,0.075570,0.000000
48.610001,12.419373,-84.513809,0.004307,0.002949,0.074894,55.244129,2.814270,0.748936,-84.513809,0.075986,0.000000
48.860001,12.584702,-84.558289,0.004320,0.002962,0.075232,55.979549,2.851734,0.752318,-84.558289,0.076403,0.000000
49.110001,12.897865,-84.558289,0.004320,0.002982,0.075752,57.372570,2.922698,0.757521,-84.558289,0.076819,0.000000
49.360001,13.006973,-84.558289,0.004329,0.002996,0.076099,57.857906,2.947422,0.760990,-84.558289,0.077235,0.000000
49.610001,13.406532,-84.558289,0.004363,0.003016,0.076602,59.635235,3.037964,0.766020,-84.558289,0.077651,0.000000
49.860001,13.493294,-84.558289,0.004363,0.003030,0.076966,60.021168,3.057624,0.769662,-84.558289,0.078068,0.000000
50.110001,13.495895,-84.602768,0.004376,0.003042,0.077270,60.032742,3.058214,0.772698,-84.602768,0.078484,0.000000
50.360001,13.901413,-84.602768,0.004411,0.003063,0.077808,61.836575,3.150105,0.778075,-84.602768,0.078900,0.000000
50.610001,14.063766,-84.691734,0.004398,0.003078,0.078172,62.558758,3.186895,0.781717,-84.691734,0.079316,0.000000
50.860001,14.335594,-84.558289,0.004445,0.003095,0.078623,63.767906,3.248492,0.786227,-84.558289,0.079733,0.000000
51.110001,14.575035,-84.602768,0.004462,0.003113,0.079074,64.832993,3.302750,0.790736,-84.602768,0.080149,0.000000
51.360001,14.735527,-84.602768,0.004480,0.003127,0.079429,65.546898,3.339118,0.794291,-84.602768,0.080565,0.000000
51.610001,15.025604,-84.602768,0.004467,0.003145,0.079889,66.837227,3.404851,0.798888,-84.602768,0.080982,0.000000
51.860001,15.180511,-84.602768,0.004488,0.003161,0.080296,67.526291,3.439953,0.802964,-84.602768,0.081398,0.000000
52.110001,15.366699,-84.647247,0.004501,0.003177,0.080704,68.354492,3.482144,0.807040,-84.647247,0.081814,0.000000
52.360001,15.606133,-84.647247,0.004531,0.003193,0.081103,69.419548,3.536400,0.811029,-84.647247,0.082230,0.000000
52.610001,15.726410,-84.691734,0.004527,0.003207,0.081459,69.954567,3.563655,0.814585,-84.691734,0.082647,0.000000
52.860001,16.252945,-84.691734,0.004583,0.003229,0.082013,72.296707,3.682970,0.820135,-84.691734,0.083063,0.000000
53.110004,16.369499,-84.647247,0.004575,0.003241,0.082326,72.815170,3.709382,0.823257,-84.647247,0.083488,0.000000
53.360004,16.264488,-84.602768,0.004587,0.003256,0.082690,72.348061,3.685586,0.826899,-84.602768,0.083904,0.000000
53.610004,16.970879,-84.691734,0.004600,0.003276,0.083219,75.490242,3.845656,0.832190,-84.691734,0.084320,0.000000
53.860004,17.394264,-84.691734,0.004644,0.003296,0.083722,77.373550,3.941597,0.837220,-84.691734,0.084737,0.000000
54.110004,17.459427,-84.691734,0.004626,0.003312,0.084121,77.663406,3.956363,0.841209,-84.691734,0.085153,0.000000
54.360004,17.674660,-84.780693,0.004665,0.003327,0.084502,78.620811,4.005135,0.845024,-84.780693,0.085569,0.000000
54.610004,17.891380,-84.691734,0.004652,0.003341,0.084849,79.584831,4.054245,0.848493,-84.691734,0.085985,0.000000
54.860004,18.370255,-84.736214,0.004687,0.003363,0.085413,81.714973,4.162759,0.854131,-84.736214,0.086402,0.000000
55.110004,18.432816,-84.780693,0.004704,0.003373,0.085682,81.993256,4.176936,0.856819,-84.780693,0.086818,0.000000
55.360004,18.903862,-84.780693,0.004695,0.003394,0.086211,84.088577,4.283676,0.862109,-84.780693,0.087234,0.000000
55.610004,19.313843,-84.780693,0.004730,0.003412,0.086662,85.912262,4.376579,0.866618,-84.780693,0.087651,0.000000
55.860004,19.490349,-84.780693,0.004747,0.003429,0.087087,86.697403,4.416576,0.870867,-84.780693,0.088067,0.000000
56.110004,19.813568,-84.780693,0.004751,0.003446,0.087529,88.135155,4.489819,0.875291,-84.780693,0.088483,0.000000
56.360004,19.918205,-84.780693,0.004799,0.003459,0.087859,88.600601,4.513530,0.878586,-84.780693,0.088899,0.000000
56.610004,20.288719,-84.825172,0.004803,0.003474,0.088231,90.248734,4.597489,0.882315,-84.825172,0.089316,0.000000
56.860004,20.703537,-84.780693,0.004794,0.003493,0.088717,92.093933,4.691488,0.887172,-84.780693,0.089732,0.000000
57.110004,20.632416,-84.780693,0.004816,0.003500,0.088908,91.777573,4.675373,0.889079,-84.780693,0.090148,0.000000
57.360004,21.036438,-84.869652,0.004825,0.003518,0.089359,93.574753,4.766925,0.893589,-84.869652,0.090564,0.000000
57.610004,21.899231,-84.869652,0.004846,0.003542,0.089957,97.412643,4.962437,0.899573,-84.869652,0.090981,0.000000
57.860004,22.039612,-84.869652,0.004868,0.003555,0.090287,98.037086,4.994247,0.902869,-84.869652,0.091397,0.000000
58.110004,22.410492,-84.869652,0.004876,0.003573,0.090746,99.686844,5.078290,0.907465,-84.869652,0.091822,0.000000
58.360004,22.775421,-84.914139,0.004881,0.003588,0.091145,101.310135,5.160985,0.911454,-84.914139,0.092238,0.000000
58.610004,23.317223,-84.869652,0.004932,0.003609,0.091666,103.720184,5.283758,0.916657,-84.869652,0.092654,0.000000
58.860004,23.558517,-84.869652,0.004919,0.003623,0.092013,104.793518,5.338437,0.920126,-84.869652,0.093071,0.000000
59.110004,23.776726,-84.914139,0.004950,0.003637,0.092368,105.764160,5.387883,0.923682,-84.914139,0.093487,0.000000
59.360004,24.253738,-84.914139,0.004937,0.003656,0.092854,107.886017,5.495975,0.928538,-84.914139,0.093903,0.000000
59.610004,24.662979,-84.869652,0.004954,0.003673,0.093287,109.706413,5.588711,0.932874,-84.869652,0.094319,0.000000
59.860004,25.073334,-84.958618,0.004984,0.003688,0.093678,111.531761,5.681698,0.936777,-84.958618,0.094736,0.000000
60.110004,25.520180,-85.003098,0.005006,0.003704,0.094077,113.519432,5.782956,0.940766,-85.003098,0.095152,0.000000
60.360004,25.529861,-84.914139,0.004997,0.003715,0.094363,113.562492,5.785149,0.943628,-84.914139,0.095568,0.000000
60.610004,26.190445,-84.914139,0.005014,0.003734,0.094848,116.500916,5.934840,0.948484,-84.914139,0.095985,0.000000
60.860004,26.762039,-84.958618,0.005027,0.003750,0.095239,119.043495,6.064365,0.952387,-84.958618,0.096401,0.000000
61.110004,27.125099,-85.003098,0.005062,0.003766,0.095664,120.658470,6.146636,0.956636,-85.003098,0.096817,0.000000
61.360004,27.709724,-85.003098,0.005062,0.003784,0.096106,123.259010,6.279113,0.961060,-85.003098,0.097233,0.000000
61.610004,28.148010,-85.003098,0.005075,0.003799,0.096487,125.208603,6.378430,0.964875,-85.003098,0.097650,0.000000
61.860004,28.673798,-85.003098,0.005079,0.003817,0.096956,127.547424,6.497575,0.969558,-85.003098,0.098066,0.000000
62.110004,29.262520,-85.047577,0.005122,0.003837,0.097450,130.166183,6.630982,0.974502,-85.047577,0.098482,0.000000
62.360004,29.564140,-85.047577,0.005109,0.003849,0.097771,131.507858,6.699330,0.977710,-85.047577,0.098898,0.000000
62.610004,30.253029,-85.092056,0.005144,0.003870,0.098291,134.572189,6.855434,0.982914,-85.092056,0.099315,0.000000
62.860004,30.465652,-85.092056,0.005139,0.003881,0.098577,135.517990,6.903615,0.985775,-85.092056,0.099731,0.000000
63.110004,30.893143,-85.092056,0.005165,0.003896,0.098959,137.419556,7.000486,0.989591,-85.092056,0.100147,0.000000
63.360004,31.389137,-85.092056,0.005165,0.003915,0.099445,139.625854,7.112880,0.994447,-85.092056,0.100572,0.000000
63.610004,31.939133,-85.092056,0.005161,0.003927,0.099748,142.072357,7.237511,0.997483,-85.092056,0.100988,0.000000
63.860004,32.544235,-85.092056,0.005208,0.003949,0.100303,144.763992,7.374629,1.003033,-85.092056,0.101405,0.000000
64.110001,33.099075,-85.092056,0.005204,0.003963,0.100659,147.232040,7.500358,1.006589,-85.092056,0.101821,0.000000
64.360001,33.609596,-85.136543,0.005238,0.003979,0.101075,149.502945,7.616044,1.010751,-85.136543,0.102237,0.000000
64.610001,34.142838,-85.136543,0.005230,0.003994,0.101439,151.874924,7.736877,1.014393,-85.136543,0.102653,0.000000
64.860001,34.753899,-85.047577,0.005251,0.004009,0.101830,154.593063,7.875346,1.018296,-85.047577,0.103070,0.000000
65.110001,34.579254,-85.136543,0.005251,0.004015,0.101986,153.816208,7.835771,1.019857,-85.136543,0.103486,0.000000
65.360001,36.163696,-85.136543,0.005273,0.004046,0.102766,160.864151,8.194811,1.027662,-85.136543,0.103902,0.000000
65.610001,37.024254,-85.181023,0.005277,0.004065,0.103261,164.692108,8.389815,1.032605,-85.181023,0.104319,0.000000
65.860001,37.538872,-85.181023,0.005299,0.004081,0.103659,166.981247,8.506430,1.036595,-85.181023,0.104735,0.000000
66.110001,37.759315,-85.136543,0.005286,0.004092,0.103946,167.961823,8.556383,1.039456,-85.136543,0.105151,0.000000
66.360001,37.900818,-85.136543,0.005329,0.004103,0.104206,168.591263,8.588448,1.042058,-85.136543,0.105567,0.000000
66.610001,39.315460,-85.225502,0.005329,0.004128,0.104848,174.883896,8.909011,1.048476,-85.225502,0.105984,0.000000
66.860001,39.738106,-85.225502,0.005346,0.004144,0.105264,176.763916,9.004784,1.052638,-85.225502,0.106400,0.000000
67.110001,40.385658,-85.136543,0.005372,0.004159,0.105628,179.644379,9.151521,1.056281,-85.136543,0.106816,0.000000
67.360001,41.743332,-85.225502,0.005376,0.004182,0.106226,185.683609,9.459174,1.062265,-85.225502,0.107232,0.000000
67.610001,41.938080,-85.181023,0.005398,0.004192,0.106478,186.549896,9.503304,1.064780,-85.181023,0.107649,0.000000
67.860001,42.510040,-85.181023,0.005402,0.004210,0.106938,189.094101,9.632913,1.069376,-85.181023,0.108065,0.000000
68.110001,43.148659,-85.358948,0.005415,0.004223,0.107276,191.934814,9.777625,1.072757,-85.358948,0.108481,0.000000
68.360001,43.880745,-85.314461,0.005411,0.004240,0.107683,195.191299,9.943519,1.076834,-85.314461,0.108906,0.000000
68.610001,44.339508,-85.269981,0.005441,0.004253,0.108022,197.231979,10.047476,1.080216,-85.269981,0.109322,0.000000
68.860001,45.292786,-85.269981,0.005454,0.004270,0.108464,201.472366,10.263492,1.084639,-85.269981,0.109739,0.000000
69.110001,44.843330,-85.269981,0.005463,0.004270,0.108464,199.473099,10.161644,1.084639,-85.269981,0.110155,0.000000
69.360001,47.899765,-85.314461,0.005476,0.004315,0.109591,213.068802,10.854241,1.095913,-85.314461,0.110571,0.000000
69.610001,48.188721,-85.269981,0.005501,0.004328,0.109938,214.354141,10.919721,1.099381,-85.269981,0.110987,0.000000
69.860001,48.580833,-85.358948,0.005489,0.004341,0.110268,216.098343,11.008574,1.102677,-85.358948,0.111404,0.000000
70.110001,49.514740,-85.314461,0.005497,0.004358,0.110701,220.252563,11.220201,1.107014,-85.314461,0.111820,0.000000
70.360001,50.047607,-85.403427,0.005519,0.004372,0.111048,222.622879,11.340950,1.110482,-85.403427,0.112236,0.000000
70.610001,50.736122,-85.358948,0.005519,0.004387,0.111421,225.685547,11.496969,1.114212,-85.358948,0.112653,0.000000
70.860001,51.449585,-85.358948,0.005536,0.004403,0.111829,228.859177,11.658643,1.118287,-85.358948,0.113069,0.000000
71.110001,52.537659,-85.403427,0.005553,0.004422,0.112323,233.699173,11.905204,1.123230,-85.403427,0.113485,0.000000
71.360001,53.242187,-85.358948,0.005575,0.004437,0.112705,236.833084,12.064853,1.127046,-85.358948,0.113901,0.000000
71.610001,54.163437,-85.447906,0.005553,0.004455,0.113147,240.931000,12.273611,1.131469,-85.447906,0.114318,0.000000
71.860001,54.986382,-85.403427,0.005575,0.004472,0.113581,244.591644,12.460092,1.135805,-85.403427,0.114734,0.000000
72.110001,55.548668,-85.447906,0.005614,0.004486,0.113953,247.092819,12.587508,1.139534,-85.447906,0.115150,0.000000
72.360001,56.707115,-85.403427,0.005601,0.004504,0.114413,252.245850,12.850017,1.144130,-85.403427,0.115566,0.000000
72.610001,57.150986,-85.536865,0.005614,0.004513,0.114639,254.220276,12.950599,1.146385,-85.536865,0.115983,0.000000
72.860001,58.227509,-85.358948,0.005618,0.004537,0.115228,259.008881,13.194542,1.152283,-85.358948,0.116399,0.000000
73.110001,59.556511,-85.403427,0.005639,0.004554,0.115679,264.920593,13.495698,1.156792,-85.403427,0.116815,0.000000
73.360001,60.448715,-85.447906,0.005635,0.004571,0.116104,268.889313,13.697874,1.161041,-85.447906,0.117240,0.000000
73.610001,61.060524,-85.492386,0.005652,0.004584,0.116434,271.610779,13.836513,1.164337,-85.492386,0.117656,0.000000
73.860001,61.979164,-85.492386,0.005678,0.004600,0.116833,275.697083,14.044679,1.168326,-85.492386,0.118073,0.000000
74.110001,62.769341,-85.536865,0.005661,0.004617,0.117284,279.211975,14.223736,1.172836,-85.536865,0.118489,0.000000
74.360001,64.040611,-85.492386,0.005708,0.004631,0.117622,284.866852,14.511809,1.176218,-85.492386,0.118905,0.000000
74.610001,64.457298,-85.492386,0.005704,0.004640,0.117856,286.720367,14.606233,1.178560,-85.492386,0.119322,0.000000
74.860001,66.437950,-85.536865,0.005713,0.004668,0.118567,295.530762,15.055055,1.185670,-85.536865,0.119738,0.000000
75.110001,67.472038,-85.536865,0.005717,0.004674,0.118732,300.130615,15.289383,1.187319,-85.536865,0.118975,0.000000
75.360001,66.804375,-85.536865,0.005739,0.004674,0.118732,297.160706,15.138087,1.187319,-85.536865,0.118975,0.000000
75.610001,66.277092,-85.536865,0.005717,0.004673,0.118697,294.815216,15.018603,1.186971,-85.536865,0.118732,0.000000
75.860001,65.831352,-85.581352,0.005726,0.004672,0.118680,292.832489,14.917598,1.186798,-85.581352,0.118732,0.000000
76.110001,65.444832,-85.581352,0.005708,0.004672,0.118680,291.113159,14.830010,1.186798,-85.581352,0.118732,0.000000
76.360001,65.101875,-85.625832,0.005747,0.004672,0.118671,289.587616,14.752295,1.186711,-85.625832,0.118732,0.000000
76.610001,64.812920,-85.581352,0.005747,0.004672,0.118671,288.302277,14.686818,1.186711,-85.581352,0.118732,0.000000
76.860001,64.545555,-85.625832,0.005734,0.004672,0.118671,287.112976,14.626232,1.186711,-85.625832,0.118732,0.000000
77.110001,64.321022,-85.625832,0.005752,0.004672,0.118663,286.114197,14.575352,1.186625,-85.625832,0.118732,0.000000
77.360001,64.097969,-85.536865,0.005747,0.004672,0.118663,285.122009,14.524807,1.186625,-85.536865,0.118732,0.000000
77.610001,63.902473,-85.714790,0.005747,0.004672,0.118663,284.252411,14.480507,1.186625,-85.714790,0.118732,0.000000
77.860001,63.732292,-85.670311,0.005734,0.004672,0.118663,283.495392,14.441944,1.186625,-85.670311,0.118732,0.000000
78.110001,63.564720,-85.714790,0.005743,0.004672,0.118663,282.750000,14.403972,1.186625,-85.714790,0.118732,0.000000
78.360001,63.410561,-85.670311,0.005747,0.004672,0.118663,282.064270,14.369038,1.186625,-85.670311,0.118732,0.000000
78.610001,63.270927,-85.670311,0.005734,0.004672,0.118663,281.443146,14.337397,1.186625,-85.670311,0.118732,0.000000
78.860001,63.133888,-85.670311,0.005752,0.004671,0.118654,280.833557,14.306343,1.186538,-85.670311,0.118732,0.000000
79.110001,62.994621,-85.670311,0.005739,0.004671,0.118654,280.214081,14.274785,1.186538,-85.670311,0.118732,0.000000
79.360001,62.896690,-85.714790,0.005721,0.004671,0.118654,279.778442,14.252594,1.186538,-85.714790,0.118732,0.000000
79.610001,62.772690,-85.714790,0.005743,0.004671,0.118654,279.226868,14.224495,1.186538,-85.714790,0.118732,0.000000
79.860001,62.663582,-85.714790,0.005760,0.004671,0.118654,278.741547,14.199771,1.186538,-85.714790,0.118732,0.000000
80.110001,62.560066,-85.759277,0.005769,0.004671,0.118654,278.281067,14.176313,1.186538,-85.759277,0.118732,0.000000
80.360001,62.474045,-85.759277,0.005743,0.004671,0.118654,277.898437,14.156821,1.186538,-85.759277,0.118732,0.000000
80.610001,62.379837,-85.714790,0.005743,0.004671,0.118654,277.479370,14.135473,1.186538,-85.714790,0.118732,0.000000
80.860001,62.293076,-85.714790,0.005756,0.004671,0.118654,277.093445,14.115813,1.186538,-85.714790,0.118732,0.000000
81.110001,62.203331,-85.759277,0.005752,0.004671,0.118654,276.694244,14.095476,1.186538,-85.759277,0.118732,0.000000
81.360001,62.122528,-85.714790,0.005752,0.004671,0.118654,276.334808,14.077167,1.186538,-85.714790,0.118732,0.000000
81.610001,62.059967,-85.803757,0.005760,0.004671,0.118654,276.056519,14.062989,1.186538,-85.803757,0.118732,0.000000
81.860001,61.967995,-85.892715,0.005760,0.004671,0.118654,275.647400,14.042148,1.186538,-85.892715,0.118732,0.000000
82.110001,61.903198,-85.848236,0.005756,0.004671,0.118654,275.359192,14.027466,1.186538,-85.848236,0.118732,0.000000
82.360001,61.841759,-85.803757,0.005747,0.004671,0.118654,275.085876,14.013543,1.186538,-85.803757,0.118732,0.000000
82.610001,61.776596,-85.848236,0.005764,0.004671,0.118654,274.796021,13.998776,1.186538,-85.848236,0.118732,0.000000
82.860001,61.704727,-85.848236,0.005760,0.004671,0.118654,274.476349,13.982491,1.186538,-85.848236,0.118732,0.000000
83.110001,61.633972,-85.848236,0.005760,0.004671,0.118654,274.161591,13.966457,1.186538,-85.848236,0.118732,0.000000
83.360001,61.581100,-85.848236,0.005752,0.004671,0.118654,273.926422,13.954476,1.186538,-85.848236,0.118732,0.000000
83.610001,61.522263,-85.803757,0.005747,0.004671,0.118654,273.664703,13.941144,1.186538,-85.803757,0.118732,0.000000
83.860001,61.471619,-85.848236,0.005760,0.004671,0.118654,273.439423,13.929668,1.186538,-85.848236,0.118732,0.000000
84.110001,61.407204,-85.892715,0.005752,0.004671,0.118654,273.152893,13.915071,1.186538,-85.892715,0.118732,0.000000
84.360001,61.362892,-85.937195,0.005760,0.004671,0.118654,272.955780,13.905030,1.186538,-85.937195,0.118732,0.000000
84.610001,61.314484,-85.848236,0.005769,0.004671,0.118654,272.740448,13.894061,1.186538,-85.848236,0.118732,0.000000
84.860001,61.272774,-85.937195,0.005760,0.004671,0.118654,272.554901,13.884609,1.186538,-85.937195,0.118732,0.000000
85.110001,61.231071,-85.981682,0.005756,0.004671,0.118654,272.369415,13.875159,1.186538,-85.981682,0.118732,0.000000
85.360001,61.167763,-85.937195,0.005747,0.004671,0.118654,272.087799,13.860813,1.186538,-85.937195,0.118732,0.000000
85.610001,61.111534,-85.981682,0.005777,0.004671,0.118654,271.837677,13.848071,1.186538,-85.981682,0.118732,0.000000
85.860001,61.081375,-86.026161,0.005756,0.004671,0.118654,271.703522,13.841237,1.186538,-86.026161,0.118732,0.000000
86.110001,61.029243,-85.981682,0.005782,0.004671,0.118654,271.471619,13.829424,1.186538,-85.981682,0.118732,0.000000
86.360001,60.994987,-85.937195,0.005769,0.004671,0.118645,271.319244,13.821661,1.186451,-85.937195,0.118732,0.000000
86.610001,60.948441,-85.981682,0.005764,0.004671,0.118645,271.112213,13.811114,1.186451,-85.981682,0.118732,0.000000
86.860001,60.907104,-85.981682,0.005760,0.004671,0.118645,270.928345,13.801747,1.186451,-85.981682,0.118732,0.000000
87.110001,60.894814,-85.981682,0.005764,0.004671,0.118645,270.873657,13.798962,1.186451,-85.981682,0.118732,0.000000
87.360001,60.831512,-86.070641,0.005756,0.004671,0.118645,270.592072,13.784617,1.186451,-86.070641,0.118732,0.000000
87.610001,60.794647,-85.981682,0.005747,0.004671,0.118645,270.428101,13.776264,1.186451,-85.981682,0.118732,0.000000
87.860001,60.760391,-86.070641,0.005752,0.004671,0.118645,270.275726,13.768502,1.186451,-86.070641,0.118732,0.000000
88.110001,60.725388,-86.026161,0.005773,0.004671,0.118645,270.120026,13.760570,1.186451,-86.026161,0.118732,0.000000
88.360001,60.692245,-86.026161,0.005764,0.004671,0.118645,269.972595,13.753059,1.186451,-86.026161,0.118732,0.000000
88.610001,60.655380,-86.070641,0.005777,0.004671,0.118645,269.808594,13.744705,1.186451,-86.070641,0.118732,0.000000
88.860001,60.620377,-86.026161,0.005777,0.004671,0.118645,269.652893,13.736773,1.186451,-86.026161,0.118732,0.000000
89.110001,60.589844,-86.115120,0.005760,0.004671,0.118645,269.517090,13.729856,1.186451,-86.115120,0.118732,0.000000
89.360001,60.561172,-86.026161,0.005756,0.004671,0.118645,269.389557,13.723357,1.186451,-86.026161,0.118732,0.000000
89.610001,60.520210,-86.070641,0.005769,0.004671,0.118645,269.207336,13.714076,1.186451,-86.070641,0.118732,0.000000
89.860001,60.490044,-86.115120,0.005756,0.004671,0.118645,269.073151,13.707240,1.186451,-86.115120,0.118732,0.000000
90.110001,60.458771,-86.115120,0.005760,0.004671,0.118645,268.934052,13.700153,1.186451,-86.115120,0.118732,0.000000
90.360001,60.425629,-86.115120,0.005773,0.004671,0.118645,268.786621,13.692643,1.186451,-86.115120,0.118732,0.000000
90.610001,60.394722,-86.115120,0.005764,0.004671,0.118645,268.649139,13.685639,1.186451,-86.115120,0.118732,0.000000
90.860001,60.380569,-86.159599,0.005782,0.004671,0.118645,268.586182,13.682432,1.186451,-86.159599,0.118732,0.000000
91.110001,60.342590,-86.159599,0.005786,0.004671,0.118645,268.417236,13.673827,1.186451,-86.159599,0.118732,0.000000
91.360001,60.321365,-86.204086,0.005760,0.004671,0.118645,268.322845,13.669017,1.186451,-86.204086,0.118732,0.000000
91.610001,60.275558,-86.159599,0.005786,0.004671,0.118645,268.119080,13.658637,1.186451,-86.159599,0.118732,0.000000
91.860001,60.256569,-86.204086,0.005777,0.004671,0.118645,268.034607,13.654334,1.186451,-86.204086,0.118732,0.000000
92.110001,60.227898,-86.204086,0.005782,0.004671,0.118645,267.907074,13.647837,1.186451,-86.204086,0.118732,0.000000
92.360001,60.215233,-86.248566,0.005756,0.004671,0.118645,267.850739,13.644966,1.186451,-86.248566,0.118732,0.000000
92.610001,60.182838,-86.159599,0.005769,0.004671,0.118645,267.706635,13.637626,1.186451,-86.159599,0.118732,0.000000
92.860001,60.166458,-86.248566,0.005760,0.004671,0.118645,267.633759,13.633914,1.186451,-86.248566,0.118732,0.000000
93.110001,60.129219,-86.204086,0.005773,0.004671,0.118645,267.468140,13.625476,1.186451,-86.204086,0.118732,0.000000
93.360008,60.111717,-86.204086,0.005769,0.004671,0.118645,267.390259,13.621510,1.186451,-86.204086,0.118732,0.000000
93.610008,60.073364,-86.204086,0.005752,0.004671,0.118645,267.219666,13.612819,1.186451,-86.204086,0.118732,0.000000
93.860008,60.058098,-86.204086,0.005777,0.004671,0.118645,267.151764,13.609359,1.186451,-86.204086,0.118732,0.000000
94.110008,60.020859,-86.248566,0.005764,0.004671,0.118645,266.986115,13.600921,1.186451,-86.248566,0.118732,0.000000
94.360008,60.011551,-86.293045,0.005777,0.004671,0.118645,266.944702,13.598812,1.186451,-86.293045,0.118732,0.000000
94.610008,59.983994,-86.293045,0.005764,0.004671,0.118645,266.822144,13.592566,1.186451,-86.293045,0.118732,0.000000
94.860008,59.969101,-86.293045,0.005777,0.004671,0.118645,266.755890,13.589192,1.186451,-86.293045,0.118732,0.000000
95.110008,59.938194,-86.293045,0.005773,0.004671,0.118645,266.618408,13.582190,1.186451,-86.293045,0.118732,0.000000
95.360008,59.927391,-86.337524,0.005756,0.004671,0.118645,266.570343,13.579741,1.186451,-86.337524,0.118732,0.000000
95.610008,59.889038,-86.337524,0.005764,0.004671,0.118645,266.399750,13.571050,1.186451,-86.337524,0.118732,0.000000
95.860008,59.883080,-86.293045,0.005777,0.004671,0.118645,266.373230,13.569700,1.186451,-86.293045,0.118732,0.000000
96.110008,59.850311,-86.293045,0.005764,0.004671,0.118645,266.227478,13.562274,1.186451,-86.293045,0.118732,0.000000
96.360008,59.836533,-86.337524,0.005769,0.004671,0.118645,266.166199,13.559152,1.186451,-86.337524,0.118732,0.000000
96.610008,59.817917,-86.337524,0.005769,0.004671,0.118645,266.083374,13.554935,1.186451,-86.337524,0.118732,0.000000
96.860008,59.787010,-86.382004,0.005782,0.004671,0.118645,265.945892,13.547930,1.186451,-86.382004,0.118732,0.000000
97.110008,59.788872,-86.382004,0.005777,0.004671,0.118645,265.954193,13.548352,1.186451,-86.382004,0.118732,0.000000
97.360008,59.776581,-86.382004,0.005786,0.004671,0.118645,265.899506,13.545567,1.186451,-86.382004,0.118732,0.000000
97.610008,59.736366,-86.382004,0.005795,0.004671,0.118645,265.720642,13.536454,1.186451,-86.382004,0.118732,0.000000
97.860008,59.712532,-86.382004,0.005821,0.004671,0.118645,265.614594,13.531054,1.186451,-86.382004,0.118732,0.000000
98.110008,59.696518,-86.382004,0.005782,0.004671,0.118645,265.543365,13.527425,1.186451,-86.382004,0.118732,0.000000
98.360008,59.687584,-86.426491,0.005795,0.004671,0.118645,265.503632,13.525400,1.186451,-86.426491,0.118732,0.000000
98.610008,59.656677,-86.382004,0.005790,0.004671,0.118645,265.366150,13.518396,1.186451,-86.382004,0.118732,0.000000
98.860008,59.642899,-86.426491,0.005764,0.004671,0.118645,265.304871,13.515274,1.186451,-86.426491,0.118732,0.000000
99.110008,59.620186,-86.470970,0.005782,0.004671,0.118645,265.203827,13.510128,1.186451,-86.470970,0.118732,0.000000
99.360008,59.614601,-86.470970,0.005816,0.004671,0.118645,265.178986,13.508862,1.186451,-86.470970,0.118732,0.000000
99.610008,59.589653,-86.470970,0.005782,0.004671,0.118645,265.068024,13.503208,1.186451,-86.470970,0.118732,0.000000
99.860008,59.572891,-86.426491,0.005786,0.004671,0.118645,264.993469,13.499411,1.186451,-86.426491,0.118732,0.000000
100.110008,59.552040,-86.515450,0.005795,0.004671,0.118645,264.900696,13.494685,1.186451,-86.515450,0.118732,0.000000
100.360008,59.545341,-86.515450,0.005782,0.004671,0.118645,264.870911,13.493167,1.186451,-86.515450,0.118732,0.000000
100.610008,59.518524,-86.515450,0.005803,0.004671,0.118645,264.751617,13.487090,1.186451,-86.515450,0.118732,0.000000
100.860008,59.501770,-86.515450,0.005795,0.004671,0.118645,264.677094,13.483294,1.186451,-86.515450,0.118732,0.000000
101.110008,59.488739,-86.515450,0.005790,0.004671,0.118645,264.619141,13.480341,1.186451,-86.515450,0.118732,0.000000
101.360008,59.469749,-86.515450,0.005803,0.004671,0.118645,264.534668,13.476038,1.186451,-86.515450,0.118732,0.000000
101.610008,59.457832,-86.515450,0.005782,0.004671,0.118645,264.481659,13.473337,1.186451,-86.515450,0.118732,0.000000
101.860008,59.437347,-86.515450,0.005799,0.004671,0.118645,264.390533,13.468696,1.186451,-86.515450,0.118732,0.000000
102.110008,59.430649,-86.559929,0.005799,0.004671,0.118645,264.360718,13.467177,1.186451,-86.559929,0.118732,0.000000
102.360008,59.407562,-86.559929,0.005795,0.004671,0.118645,264.258026,13.461946,1.186451,-86.559929,0.118732,0.000000
102.610008,59.396019,-86.604408,0.005795,0.004671,0.118645,264.206696,13.459331,1.186451,-86.604408,0.118732,0.000000
102.860008,59.374420,-86.604408,0.005795,0.004671,0.118645,264.110626,13.454436,1.186451,-86.604408,0.118732,0.000000
103.110008,59.371071,-86.604408,0.005795,0.004671,0.118645,264.095703,13.453677,1.186451,-86.604408,0.118732,0.000000
103.360008,59.341278,-86.559929,0.005799,0.004671,0.118645,263.963196,13.446925,1.186451,-86.559929,0.118732,0.000000
103.610008,59.333458,-86.559929,0.005795,0.004671,0.118645,263.928406,13.445153,1.186451,-86.559929,0.118732,0.000000
103.860008,59.318565,-86.648895,0.005782,0.004671,0.118645,263.862152,13.441779,1.186451,-86.648895,0.118732,0.000000
104.110008,59.295479,-86.648895,0.005808,0.004671,0.118645,263.759460,13.436548,1.186451,-86.648895,0.118732,0.000000
104.360008,59.293243,-86.604408,0.005799,0.004671,0.118645,263.749512,13.436041,1.186451,-86.604408,0.118732,0.000000
104.610008,59.271645,-86.648895,0.005790,0.004671,0.118645,263.653442,13.431147,1.186451,-86.648895,0.118732,0.000000
104.860008,59.254517,-86.648895,0.005799,0.004671,0.118645,263.577240,13.427265,1.186451,-86.648895,0.118732,0.000000
105.110008,59.233292,-86.693375,0.005786,0.004671,0.118645,263.482849,13.422456,1.186451,-86.693375,0.118732,0.000000
105.360008,59.226959,-86.648895,0.005799,0.004671,0.118645,263.454681,13.421021,1.186451,-86.648895,0.118732,0.000000
105.600006,59.210579,-86.782333,0.005760,0.004671,0.118645,263.381805,13.417309,1.186451,-86.782333,0.118732,0.000000