File: Data/Symmetrical membranes compression/Sterlitech PVDF 02um test 3_10272023_144603.csv
Time (sec),S:Load (lbs),S:HL1 (DIM),S:LVDT (in),S:Position (in),Ch:Position (mm),Ch:Load (N),Ch:Stress (MPa),Ch:Strain (mm/mm),Ch:HL1 (DIM),Set Point (),Cycles ()
0.110000,-0.011177,-1212.550781,0.009274,-0.001269,-0.032243,-0.049718,-0.002533,-0.322435,-1212.550781,-0.032018,0.000000
0.320000,-0.004097,-1212.550781,0.009265,-0.001269,-0.032243,-0.018224,-0.000928,-0.322435,-1212.550781,-0.032018,0.000000
0.530000,-0.012665,-1212.550781,0.009322,-0.001195,-0.030344,-0.056336,-0.002870,-0.303443,-1212.550781,-0.029624,0.000000
0.740000,-0.017876,-1212.639648,0.009369,-0.001074,-0.027292,-0.079515,-0.004051,-0.272916,-1212.639648,-0.026138,0.000000
0.950000,-0.018250,-1212.595215,0.009546,-0.000932,-0.023684,-0.081178,-0.004135,-0.236839,-1212.595215,-0.022635,0.000000
1.160000,-0.021225,-1212.595215,0.009619,-0.000797,-0.020250,-0.094413,-0.004810,-0.202498,-1212.595215,-0.019131,0.000000
1.370000,-0.009315,-1212.550781,0.009783,-0.000658,-0.016703,-0.041437,-0.002111,-0.167028,-1212.550781,-0.015627,0.000000
1.580000,0.006325,-1212.506226,0.009955,-0.000522,-0.013269,0.028134,0.001433,-0.132686,-1212.506226,-0.012141,0.000000
1.790000,0.051384,-1212.595215,0.010085,-0.000385,-0.009782,0.228567,0.011644,-0.097823,-1212.595215,-0.008638,0.000000
2.000000,0.223793,-1212.595215,0.010201,-0.000244,-0.006192,0.995481,0.050712,-0.061920,-1212.595215,-0.005134,0.000000
2.210000,0.618507,-1212.639648,0.010365,0.000009,0.000225,2.751258,0.140156,0.002255,-1212.639648,0.001388,0.000000
2.420000,0.644203,-1212.550781,0.010365,0.000010,0.000260,2.865559,0.145979,0.002602,-1212.550781,0.000460,0.000000
2.630000,0.630424,-1212.550781,0.010382,0.000010,0.000260,2.804268,0.142856,0.002602,-1212.550781,0.000460,0.000000
2.840000,0.647926,-1212.639648,0.010408,0.000010,0.000252,2.882120,0.146822,0.002515,-1212.639648,0.000616,0.000000
3.050000,0.628563,-1212.550781,0.010395,0.000010,0.000260,2.795988,0.142434,0.002602,-1212.550781,0.000963,0.000000
3.260000,0.593933,-1212.639648,0.010361,0.000010,0.000260,2.641946,0.134587,0.002602,-1212.639648,0.001310,0.000000
3.470000,0.587601,-1212.639648,0.010378,0.000010,0.000260,2.613779,0.133152,0.002602,-1212.639648,0.001665,0.000000
3.680000,0.597656,-1212.550781,0.010378,0.000011,0.000269,2.658508,0.135431,0.002689,-1212.550781,0.002012,0.000000
3.890000,0.765594,-1212.595215,0.010451,0.000054,0.001379,3.405534,0.173486,0.013789,-1212.595215,0.002359,0.000000
4.100000,0.876564,-1212.595215,0.010481,0.000071,0.001813,3.899152,0.198632,0.018125,-1212.595215,0.002714,0.000000
4.310000,0.897415,-1212.595215,0.010442,0.000082,0.002090,3.991902,0.203357,0.020900,-1212.595215,0.003061,0.000000
4.520000,0.910820,-1212.595215,0.010425,0.000086,0.002177,4.051530,0.206395,0.021767,-1212.595215,0.003417,0.000000
4.730000,1.040031,-1212.595215,0.010490,0.000103,0.002628,4.626291,0.235675,0.026277,-1212.595215,0.003764,0.000000
4.940000,1.117859,-1212.595215,0.010468,0.000126,0.003200,4.972485,0.253310,0.032001,-1212.595215,0.004111,0.000000
5.150000,1.194939,-1212.595215,0.010516,0.000140,0.003547,5.315352,0.270777,0.035470,-1212.595215,0.004466,0.000000
5.360000,1.254517,-1212.684204,0.010550,0.000151,0.003842,5.580369,0.284278,0.038418,-1212.684204,0.004813,0.000000
5.570000,1.308884,-1212.595215,0.010511,0.000166,0.004215,5.822206,0.296597,0.042147,-1212.595215,0.005160,0.000000
5.780000,1.335701,-1212.595215,0.010563,0.000179,0.004536,5.941495,0.302674,0.045356,-1212.595215,0.005516,0.000000
5.990000,1.425438,-1212.684204,0.010572,0.000193,0.004891,6.340664,0.323009,0.048912,-1212.684204,0.005862,0.000000
6.200000,1.507362,-1212.595215,0.010555,0.000205,0.005212,6.705083,0.341573,0.052120,-1212.595215,0.006209,0.000000
6.410000,1.564705,-1212.639648,0.010619,0.000214,0.005446,6.960155,0.354567,0.054462,-1212.639648,0.006565,0.000000
6.620000,1.681259,-1212.639648,0.010559,0.000230,0.005854,7.478614,0.380979,0.058538,-1212.639648,0.006912,0.000000
6.830000,1.743820,-1212.595215,0.010619,0.000244,0.006192,7.756900,0.395155,0.061920,-1212.595215,0.007259,0.000000
7.040000,1.898727,-1212.639648,0.010615,0.000266,0.006756,8.445961,0.430258,0.067557,-1212.639648,0.007614,0.000000
7.250000,1.944527,-1212.550781,0.010684,0.000277,0.007033,8.649687,0.440636,0.070332,-1212.550781,0.007961,0.000000
7.460001,1.986603,-1212.639648,0.010632,0.000290,0.007354,8.836850,0.450171,0.073541,-1212.639648,0.008317,0.000000
7.670001,2.075226,-1212.639648,0.010697,0.000303,0.007692,9.231066,0.470253,0.076923,-1212.639648,0.008664,0.000000
7.880001,2.201836,-1212.684204,0.010706,0.000319,0.008100,9.794254,0.498943,0.080999,-1212.684204,0.009011,0.000000
8.090000,2.307220,-1212.639648,0.010706,0.000331,0.008403,10.263029,0.522824,0.084035,-1212.639648,0.009366,0.000000
8.300000,2.365311,-1212.684204,0.010727,0.000341,0.008664,10.521427,0.535987,0.086636,-1212.684204,0.009713,0.000000
8.510000,2.462868,-1212.639648,0.010740,0.000356,0.009037,10.955383,0.558094,0.090365,-1212.639648,0.010060,0.000000
8.720000,2.672890,-1212.639648,0.010714,0.000374,0.009487,11.889607,0.605685,0.094875,-1212.639648,0.010415,0.000000
8.930000,2.763374,-1212.639648,0.010774,0.000388,0.009852,12.292103,0.626190,0.098517,-1212.639648,0.010762,0.000000
9.140000,2.822212,-1212.639648,0.010753,0.000399,0.010147,12.553827,0.639522,0.101465,-1212.639648,0.011109,0.000000
9.350000,2.942482,-1212.595215,0.010757,0.000415,0.010537,13.088814,0.666776,0.105368,-1212.595215,0.011465,0.000000
9.560000,3.071701,-1212.728638,0.010783,0.000427,0.010858,13.663609,0.696057,0.108577,-1212.728638,0.011812,0.000000
9.770000,3.138351,-1212.684204,0.010826,0.000439,0.011161,13.960084,0.711161,0.111612,-1212.684204,0.012167,0.000000
9.980000,3.352470,-1212.639648,0.010831,0.000454,0.011543,14.912533,0.759681,0.115428,-1212.639648,0.012514,0.000000
10.190001,3.321556,-1212.684204,0.010809,0.000458,0.011630,14.775020,0.752675,0.116295,-1212.684204,0.012861,0.000000
10.400001,3.537910,-1212.639648,0.010869,0.000475,0.012054,15.737411,0.801702,0.120545,-1212.639648,0.013217,0.000000
10.610001,3.722229,-1212.639648,0.010861,0.000490,0.012445,16.557302,0.843469,0.124447,-1212.639648,0.013563,0.000000
10.820001,3.995552,-1212.684204,0.010856,0.000512,0.013000,17.773104,0.905405,0.129997,-1212.684204,0.013910,0.000000
11.030001,4.053642,-1212.595215,0.010921,0.000521,0.013225,18.031502,0.918568,0.132252,-1212.595215,0.014266,0.000000
11.240001,4.237595,-1212.639648,0.010874,0.000538,0.013676,18.849762,0.960253,0.136762,-1212.639648,0.014613,0.000000
11.450001,4.415215,-1212.595215,0.010900,0.000553,0.014049,19.639854,1.000502,0.140491,-1212.595215,0.014960,0.000000
11.660001,4.618164,-1212.728638,0.010934,0.000568,0.014422,20.542620,1.046491,0.144220,-1212.728638,0.015315,0.000000
11.870001,4.778282,-1212.639648,0.010912,0.000580,0.014743,21.254860,1.082774,0.147429,-1212.639648,0.015662,0.000000
12.080001,4.977127,-1212.639648,0.010960,0.000595,0.015107,22.139366,1.127833,0.151071,-1212.639648,0.016018,0.000000
12.290001,5.020325,-1212.684204,0.010986,0.000603,0.015307,22.331520,1.137622,0.153065,-1212.684204,0.016365,0.000000
12.500001,5.225502,-1212.595215,0.010973,0.000619,0.015714,23.244194,1.184116,0.157141,-1212.595215,0.016711,0.000000
12.710001,5.488770,-1212.728638,0.011003,0.000634,0.016104,24.415266,1.243773,0.161044,-1212.728638,0.017067,0.000000
12.920001,5.603455,-1212.639648,0.010981,0.000645,0.016382,24.925411,1.269761,0.163819,-1212.639648,0.017414,0.000000
13.130001,5.711075,-1212.639648,0.011050,0.000657,0.016694,25.404129,1.294148,0.166941,-1212.639648,0.017761,0.000000
13.340001,5.988861,-1212.684204,0.011020,0.000673,0.017102,26.639784,1.357095,0.171017,-1212.684204,0.018116,0.000000
13.550000,6.163132,-1212.639648,0.011025,0.000688,0.017466,27.414980,1.396586,0.174660,-1212.639648,0.018463,0.000000
13.760000,6.412994,-1212.639648,0.011033,0.000704,0.017891,28.526424,1.453205,0.178909,-1212.639648,0.018810,0.000000
13.970000,6.431244,-1212.550781,0.011055,0.000708,0.017978,28.607601,1.457341,0.179776,-1212.550781,0.019166,0.000000
14.180000,6.671051,-1212.728638,0.011063,0.000723,0.018368,29.674316,1.511682,0.183679,-1212.728638,0.019513,0.000000
14.390000,6.938042,-1212.684204,0.011059,0.000739,0.018767,30.861950,1.572183,0.187668,-1212.684204,0.019868,0.000000
14.600000,7.269455,-1212.684204,0.011098,0.000758,0.019252,32.336151,1.647282,0.192524,-1212.684204,0.020215,0.000000
14.810000,7.380051,-1212.728638,0.011115,0.000769,0.019539,32.828106,1.672343,0.195386,-1212.728638,0.020562,0.000000
15.020000,7.632889,-1212.639648,0.011098,0.000785,0.019929,33.952785,1.729637,0.199288,-1212.639648,0.020918,0.000000
15.230000,7.801949,-1212.639648,0.011171,0.000798,0.020276,34.704800,1.767947,0.202758,-1212.639648,0.021264,0.000000
15.440001,7.944939,-1212.639648,0.011115,0.000810,0.020571,35.340851,1.800349,0.205706,-1212.639648,0.021611,0.000000
15.650001,8.029839,-1212.684204,0.011132,0.000820,0.020822,35.718506,1.819587,0.208221,-1212.684204,0.021967,0.000000
15.860001,8.403702,-1212.684204,0.011197,0.000836,0.021247,37.381531,1.904306,0.212470,-1212.684204,0.022314,0.000000
16.070002,8.618927,-1212.684204,0.011223,0.000850,0.021585,38.338902,1.953077,0.215853,-1212.684204,0.022661,0.000000
16.280001,8.826714,-1212.684204,0.011188,0.000865,0.021967,39.263184,2.000162,0.219669,-1212.684204,0.023016,0.000000
16.490002,9.043808,-1212.595215,0.011257,0.000878,0.022305,40.228867,2.049356,0.223050,-1212.595215,0.023363,0.000000
16.700001,9.289200,-1212.639648,0.011193,0.000892,0.022661,41.320423,2.104963,0.226606,-1212.639648,0.023710,0.000000
16.910002,9.483208,-1212.684204,0.011244,0.000906,0.023008,42.183414,2.148926,0.230075,-1212.684204,0.024066,0.000000
17.120001,9.721527,-1212.639648,0.011283,0.000921,0.023398,43.243511,2.202929,0.233977,-1212.639648,0.024412,0.000000
17.330000,9.812386,-1212.639648,0.011244,0.000932,0.023675,43.647671,2.223518,0.236753,-1212.639648,0.024768,0.000000
17.540001,10.099854,-1212.595215,0.011270,0.000949,0.024109,44.926392,2.288660,0.241089,-1212.595215,0.025115,0.000000
17.750000,10.521751,-1212.639648,0.011283,0.000967,0.024551,46.803089,2.384263,0.245512,-1212.639648,0.025462,0.000000
17.960001,10.634956,-1212.595215,0.011344,0.000980,0.024881,47.306648,2.409915,0.248807,-1212.595215,0.025817,0.000000
18.170000,10.821510,-1212.595215,0.011331,0.000993,0.025210,48.136482,2.452189,0.252103,-1212.595215,0.026164,0.000000
18.380001,10.914978,-1212.639648,0.011305,0.001003,0.025488,48.552246,2.473369,0.254878,-1212.639648,0.026511,0.000000
18.590000,11.327942,-1212.595215,0.011335,0.001021,0.025930,50.389202,2.566948,0.259301,-1212.595215,0.026867,0.000000
18.800001,11.436676,-1212.595215,0.011387,0.001031,0.026190,50.872875,2.591588,0.261902,-1212.595215,0.027214,0.000000
19.010000,11.587486,-1212.684204,0.011357,0.001044,0.026520,51.543713,2.625762,0.265198,-1212.684204,0.027560,0.000000
19.220001,11.774040,-1212.639648,0.011378,0.001057,0.026858,52.373547,2.668036,0.268580,-1212.639648,0.027916,0.000000
19.430000,12.074173,-1212.639648,0.011408,0.001073,0.027248,53.708603,2.736047,0.272483,-1212.639648,0.028263,0.000000
19.640001,12.592888,-1212.595215,0.011378,0.001092,0.027743,56.015965,2.853589,0.277426,-1212.595215,0.028618,0.000000
19.850000,12.667366,-1212.639648,0.011430,0.001103,0.028011,56.347260,2.870466,0.280114,-1212.639648,0.028965,0.000000
20.060001,12.915367,-1212.639648,0.011404,0.001117,0.028376,57.450420,2.926664,0.283756,-1212.639648,0.029312,0.000000
20.270000,13.036011,-1212.595215,0.011438,0.001129,0.028688,57.987072,2.954002,0.286878,-1212.595215,0.029668,0.000000
20.480001,13.306725,-1212.728638,0.011490,0.001142,0.029017,59.191269,3.015347,0.290174,-1212.728638,0.030015,0.000000
20.690001,13.482857,-1212.639648,0.011456,0.001157,0.029390,59.974743,3.055259,0.293903,-1212.639648,0.030362,0.000000
20.900002,13.642235,-1212.639648,0.011507,0.001166,0.029607,60.683693,3.091374,0.296071,-1212.639648,0.030717,0.000000
21.110001,13.931198,-1212.639648,0.011482,0.001183,0.030049,61.969063,3.156855,0.300494,-1212.639648,0.031064,0.000000
21.320002,14.384377,-1212.639648,0.011477,0.001200,0.030474,63.984901,3.259546,0.304743,-1212.639648,0.031411,0.000000
21.530001,14.665886,-1212.639648,0.011503,0.001214,0.030830,65.237122,3.323337,0.308299,-1212.639648,0.031766,0.000000
21.740002,14.862869,-1212.684204,0.011551,0.001226,0.031133,66.113342,3.367974,0.311334,-1212.684204,0.032113,0.000000
21.950001,15.104538,-1212.684204,0.011568,0.001239,0.031472,67.188339,3.422737,0.314716,-1212.684204,0.032469,0.000000
22.160002,15.392014,-1212.639648,0.011546,0.001255,0.031888,68.467094,3.487880,0.318879,-1212.639648,0.032816,0.000000
22.370001,15.638527,-1212.639648,0.011546,0.001270,0.032252,69.563644,3.543741,0.322521,-1212.639648,0.033163,0.000000
22.580002,15.936050,-1212.684204,0.011546,0.001284,0.032608,70.887093,3.611161,0.326077,-1212.684204,0.033518,0.000000
22.790001,15.888756,-1212.684204,0.011598,0.001295,0.032885,70.676712,3.600444,0.328852,-1212.684204,0.033865,0.000000
23.000002,16.315498,-1212.684204,0.011620,0.001309,0.033258,72.574959,3.697145,0.332581,-1212.684204,0.034212,0.000000
23.210001,16.421623,-1212.728638,0.011594,0.001318,0.033475,73.047028,3.721193,0.334749,-1212.728638,0.034568,0.000000
23.420002,16.634247,-1212.684204,0.011576,0.001332,0.033839,73.992828,3.769374,0.338392,-1212.684204,0.034915,0.000000
23.630001,17.010719,-1212.639648,0.011663,0.001346,0.034195,75.667458,3.854684,0.341947,-1212.639648,0.035261,0.000000
23.840002,16.849106,-1212.639648,0.011658,0.001351,0.034307,74.948563,3.818062,0.343075,-1212.639648,0.035617,0.000000
24.050001,17.649338,-1212.728638,0.011645,0.001373,0.034871,78.508179,3.999397,0.348712,-1212.728638,0.035964,0.000000
24.260000,17.847809,-1212.728638,0.011658,0.001387,0.035218,79.391022,4.044371,0.352181,-1212.728638,0.036311,0.000000
24.470001,18.292419,-1212.639648,0.011667,0.001404,0.035669,81.368744,4.145122,0.356690,-1212.639648,0.036666,0.000000
24.680000,18.378067,-1212.728638,0.011706,0.001416,0.035964,81.749725,4.164529,0.359639,-1212.728638,0.037013,0.000000
24.890001,18.565002,-1212.595215,0.011719,0.001429,0.036302,82.581253,4.206890,0.363021,-1212.595215,0.037369,0.000000
25.100000,18.807411,-1212.684204,0.011753,0.001444,0.036666,83.659546,4.261820,0.366663,-1212.684204,0.037716,0.000000
25.310001,18.914284,-1212.773071,0.011732,0.001453,0.036909,84.134933,4.286038,0.369092,-1212.773071,0.038063,0.000000
25.520000,19.295593,-1212.639648,0.011762,0.001468,0.037291,85.831085,4.372444,0.372907,-1212.639648,0.038418,0.000000
25.730001,19.532799,-1212.728638,0.011753,0.001483,0.037664,86.886230,4.426196,0.376636,-1212.728638,0.038765,0.000000
25.940001,19.719727,-1212.728638,0.011775,0.001496,0.037993,87.717728,4.468554,0.379932,-1212.728638,0.039112,0.000000
26.150002,20.118164,-1212.728638,0.011758,0.001511,0.038392,89.490067,4.558841,0.383921,-1212.728638,0.039467,0.000000
26.360001,20.544159,-1212.728638,0.011779,0.001529,0.038834,91.384979,4.655373,0.388344,-1212.728638,0.039814,0.000000
26.570002,20.601501,-1212.684204,0.011809,0.001538,0.039077,91.640053,4.668367,0.390772,-1212.684204,0.040161,0.000000
26.780001,20.826042,-1212.773071,0.011835,0.001555,0.039493,92.638863,4.719248,0.394935,-1212.773071,0.040517,0.000000
26.990002,21.074043,-1212.639648,0.011826,0.001569,0.039849,93.742027,4.775446,0.398490,-1212.639648,0.040864,0.000000
27.200001,21.252411,-1212.684204,0.011891,0.001580,0.040127,94.535446,4.815865,0.401266,-1212.684204,0.041219,0.000000
27.410002,21.597229,-1212.773071,0.011883,0.001595,0.040525,96.069275,4.894002,0.405255,-1212.773071,0.041566,0.000000
27.620001,21.735748,-1212.728638,0.011848,0.001606,0.040803,96.685440,4.925391,0.408030,-1212.728638,0.041913,0.000000
27.830002,21.792351,-1212.728638,0.011857,0.001618,0.041098,96.937218,4.938218,0.410979,-1212.728638,0.042269,0.000000
28.040001,22.257820,-1212.684204,0.011887,0.001635,0.041523,99.007729,5.043694,0.415228,-1212.684204,0.042616,0.000000
28.250002,22.585503,-1212.728638,0.011887,0.001650,0.041904,100.465332,5.117948,0.419044,-1212.728638,0.042962,0.000000
28.460001,23.046875,-1212.728638,0.011964,0.001667,0.042347,102.517624,5.222497,0.423466,-1212.728638,0.043318,0.000000
28.670002,23.212578,-1212.684204,0.011934,0.001684,0.042780,103.254700,5.260046,0.427802,-1212.684204,0.043665,0.000000
28.880001,23.303062,-1212.773071,0.011952,0.001695,0.043040,103.657196,5.280550,0.430405,-1212.773071,0.044012,0.000000
29.090002,23.400253,-1212.639648,0.012008,0.001707,0.043361,104.089523,5.302573,0.433613,-1212.639648,0.044367,0.000000
29.300001,23.839279,-1212.684204,0.011999,0.001723,0.043760,106.042412,5.402058,0.437602,-1212.684204,0.044714,0.000000
29.510002,23.957695,-1212.773071,0.012021,0.001735,0.044072,106.569153,5.428891,0.440725,-1212.773071,0.045070,0.000000
29.720001,23.957695,-1212.684204,0.012033,0.001746,0.044341,106.569153,5.428891,0.443413,-1212.684204,0.045417,0.000000
29.930002,24.587379,-1212.773071,0.012008,0.001766,0.044844,109.370125,5.571580,0.448442,-1212.773071,0.045764,0.000000
30.140001,24.551628,-1212.684204,0.012016,0.001777,0.045148,109.211098,5.563478,0.451478,-1212.684204,0.046119,0.000000
30.350002,25.066246,-1212.817627,0.012016,0.001794,0.045573,111.500229,5.680093,0.455727,-1212.817627,0.046466,0.000000
30.560001,25.253555,-1212.684204,0.012081,0.001809,0.045937,112.333427,5.722538,0.459370,-1212.684204,0.046813,0.000000
30.770002,25.401382,-1212.728638,0.012085,0.001820,0.046232,112.990990,5.756035,0.462318,-1212.728638,0.047168,0.000000
30.980001,25.502670,-1212.773071,0.012089,0.001832,0.046544,113.441544,5.778988,0.465440,-1212.773071,0.047515,0.000000
31.190001,25.821419,-1212.684204,0.012085,0.001845,0.046874,114.859406,5.851217,0.468736,-1212.684204,0.047862,0.000000
31.400002,25.776733,-1212.817627,0.012089,0.001857,0.047168,114.660637,5.841091,0.471684,-1212.817627,0.048218,0.000000
31.610001,26.174431,-1212.773071,0.012089,0.001870,0.047507,116.429680,5.931211,0.475066,-1212.773071,0.048565,0.000000
31.820002,26.451103,-1212.684204,0.012124,0.001886,0.047906,117.660385,5.993906,0.479056,-1212.684204,0.048912,0.000000
32.030003,26.290985,-1212.817627,0.012163,0.001888,0.047966,116.948143,5.957623,0.479663,-1212.817627,0.049267,0.000000
32.240002,27.374214,-1212.728638,0.012176,0.001917,0.048695,121.766586,6.203085,0.486948,-1212.728638,0.049614,0.000000
32.450001,27.464325,-1212.862061,0.012176,0.001931,0.049042,122.167419,6.223505,0.490416,-1212.862061,0.049970,0.000000
32.660000,27.663918,-1212.773071,0.012202,0.001944,0.049380,123.055252,6.268734,0.493799,-1212.773071,0.050316,0.000000
32.870003,27.933891,-1212.684204,0.012223,0.001959,0.049761,124.256157,6.329910,0.497614,-1212.684204,0.050663,0.000000
33.080002,28.113747,-1212.773071,0.012223,0.001972,0.050100,125.056190,6.370666,0.500997,-1212.773071,0.051019,0.000000
33.290001,28.216148,-1212.728638,0.012215,0.001986,0.050438,125.511696,6.393870,0.504379,-1212.728638,0.051366,0.000000
33.500000,28.365097,-1212.773071,0.012245,0.001997,0.050715,126.174255,6.427623,0.507154,-1212.773071,0.051713,0.000000
33.710003,28.515533,-1212.773071,0.012275,0.002009,0.051036,126.843430,6.461712,0.510362,-1212.773071,0.052068,0.000000
33.920002,29.084152,-1212.817627,0.012227,0.002026,0.051470,129.372772,6.590563,0.514699,-1212.817627,0.052415,0.000000
34.130001,29.068512,-1212.773071,0.012240,0.002037,0.051747,129.303192,6.587019,0.517474,-1212.773071,0.052762,0.000000
34.340000,29.354118,-1212.773071,0.012322,0.002050,0.052077,130.573639,6.651738,0.520769,-1212.773071,0.053118,0.000000
34.550003,29.676590,-1212.773071,0.012275,0.002065,0.052441,132.008072,6.724812,0.524411,-1212.773071,0.053464,0.000000
34.760002,29.815857,-1212.773071,0.012305,0.002077,0.052762,132.627548,6.756370,0.527620,-1212.773071,0.053820,0.000000
34.970001,30.358406,-1212.773071,0.012352,0.002095,0.053204,135.040939,6.879313,0.532043,-1212.773071,0.054167,0.000000
35.180000,30.545708,-1212.773071,0.012335,0.002106,0.053499,135.874100,6.921756,0.534992,-1212.773071,0.054514,0.000000
35.390003,30.360268,-1212.728638,0.012327,0.002116,0.053742,135.049210,6.879735,0.537420,-1212.728638,0.054869,0.000000
35.600002,30.435486,-1212.817627,0.012357,0.002123,0.053915,135.383804,6.896780,0.539155,-1212.817627,0.055216,0.000000
35.810001,31.154915,-1212.773071,0.012348,0.002145,0.054470,138.583984,7.059805,0.544705,-1212.773071,0.055563,0.000000
36.020000,31.690384,-1212.773071,0.012365,0.002161,0.054895,140.965866,7.181144,0.548954,-1212.773071,0.055919,0.000000
36.230003,31.879921,-1212.817627,0.012361,0.002175,0.055251,141.808975,7.224093,0.552509,-1212.817627,0.056266,0.000000
36.440002,32.098129,-1212.684204,0.012413,0.002189,0.055589,142.779617,7.273540,0.555892,-1212.684204,0.056613,0.000000
36.650002,32.343155,-1212.773071,0.012404,0.002202,0.055919,143.869537,7.329064,0.559187,-1212.773071,0.056968,0.000000
36.860001,32.322670,-1212.817627,0.012421,0.002209,0.056118,143.778412,7.324421,0.561182,-1212.817627,0.057315,0.000000
37.070004,33.158646,-1212.817627,0.012417,0.002232,0.056682,147.497025,7.513857,0.566819,-1212.817627,0.057671,0.000000
37.280003,33.188812,-1212.773071,0.012447,0.002243,0.056977,147.631210,7.520692,0.569768,-1212.773071,0.058017,0.000000
37.490002,33.401810,-1212.728638,0.012443,0.002254,0.057246,148.578674,7.568958,0.572456,-1212.728638,0.058364,0.000000
37.700001,33.648315,-1212.862061,0.012443,0.002268,0.057610,149.675186,7.624817,0.576098,-1212.862061,0.058720,0.000000
37.910004,33.995743,-1212.817627,0.012482,0.002283,0.057983,151.220612,7.703546,0.579827,-1212.817627,0.059067,0.000000
38.120003,34.344658,-1212.817627,0.012486,0.002297,0.058347,152.772675,7.782611,0.583469,-1212.817627,0.059414,0.000000
38.330002,34.695061,-1212.862061,0.012508,0.002312,0.058737,154.331345,7.862013,0.587372,-1212.862061,0.059769,0.000000
38.540001,34.815331,-1212.817627,0.012521,0.002324,0.059032,154.866318,7.889266,0.590321,-1212.817627,0.060116,0.000000
38.750000,35.000778,-1212.906616,0.012512,0.002335,0.059318,155.691238,7.931290,0.593182,-1212.906616,0.060463,0.000000
38.960003,35.849037,-1212.862061,0.012590,0.002358,0.059882,159.464478,8.123508,0.598820,-1212.862061,0.060819,0.000000
39.170002,36.097786,-1212.817627,0.012590,0.002372,0.060246,160.570969,8.179875,0.602462,-1212.817627,0.061165,0.000000
39.380001,36.154015,-1212.817627,0.012559,0.002381,0.060489,160.821091,8.192617,0.604890,-1212.817627,0.061521,0.000000
39.590000,36.390099,-1212.817627,0.012551,0.002395,0.060827,161.871246,8.246115,0.608272,-1212.817627,0.061868,0.000000
39.800003,36.755020,-1212.817627,0.012628,0.002411,0.061243,163.494492,8.328806,0.612435,-1212.817627,0.062215,0.000000
40.010002,37.224586,-1212.862061,0.012585,0.002426,0.061608,165.583237,8.435211,0.616077,-1212.862061,0.062570,0.000000
40.220001,37.155319,-1212.817627,0.012628,0.002434,0.061825,165.275116,8.419516,0.618246,-1212.817627,0.062917,0.000000
40.430000,37.449127,-1212.906616,0.012637,0.002447,0.062163,166.582031,8.486094,0.621627,-1212.906616,0.063264,0.000000
40.640003,37.216393,-1212.773071,0.012654,0.002451,0.062258,165.546783,8.433355,0.622582,-1212.773071,0.063620,0.000000
40.850002,38.226265,-1212.862061,0.012663,0.002474,0.062848,170.038925,8.662195,0.628478,-1212.862061,0.063967,0.000000
41.060001,39.132248,-1212.862061,0.012633,0.002496,0.063394,174.068939,8.867494,0.633942,-1212.862061,0.064313,0.000000
41.270000,39.206352,-1212.862061,0.012646,0.002507,0.063672,174.398560,8.884286,0.636717,-1212.862061,0.064669,0.000000
41.480003,39.539619,-1212.862061,0.012680,0.002520,0.064019,175.881012,8.959805,0.640186,-1212.862061,0.065016,0.000000
41.690002,39.885559,-1212.817627,0.012710,0.002536,0.064409,177.419830,9.038197,0.644089,-1212.817627,0.065363,0.000000
41.900002,40.049774,-1212.906616,0.012736,0.002547,0.064695,178.150299,9.075408,0.646951,-1212.906616,0.065718,0.000000
42.110001,40.551727,-1212.862061,0.012728,0.002562,0.065085,180.383087,9.189153,0.650853,-1212.862061,0.066065,0.000000
42.320004,40.520821,-1212.817627,0.012758,0.002572,0.065319,180.245605,9.182149,0.653195,-1212.817627,0.066421,0.000000
42.530003,41.275993,-1212.906616,0.012732,0.002591,0.065805,183.604782,9.353274,0.658051,-1212.906616,0.066768,0.000000
42.740002,41.538147,-1212.817627,0.012758,0.002603,0.066126,184.770905,9.412679,0.661260,-1212.817627,0.067115,0.000000
42.950001,41.996910,-1212.817627,0.012766,0.002617,0.066482,186.811584,9.516636,0.664815,-1212.817627,0.067470,0.000000
43.160004,41.997650,-1212.817627,0.012749,0.002626,0.066698,186.814880,9.516804,0.666984,-1212.817627,0.067817,0.000000
43.370003,42.527908,-1212.906616,0.012805,0.002642,0.067115,189.173584,9.636962,0.671146,-1212.906616,0.068164,0.000000
43.580002,43.111794,-1212.862061,0.012766,0.002660,0.067557,191.770828,9.769273,0.675569,-1212.862061,0.068520,0.000000
43.790001,43.628273,-1212.817627,0.012801,0.002675,0.067947,194.068253,9.886308,0.679471,-1212.817627,0.068866,0.000000
44.000004,43.902336,-1212.906616,0.012853,0.002686,0.068225,195.287338,9.948411,0.682247,-1212.906616,0.069213,0.000000
44.210003,43.980537,-1212.817627,0.012883,0.002699,0.068554,195.635208,9.966132,0.685542,-1212.817627,0.069569,0.000000
44.420002,44.357002,-1212.906616,0.012840,0.002712,0.068884,197.309799,10.051440,0.688838,-1212.906616,0.069916,0.000000
44.630001,44.526436,-1212.906616,0.012857,0.002724,0.069179,198.063477,10.089835,0.691786,-1212.906616,0.070271,0.000000
44.840004,44.795288,-1212.817627,0.012866,0.002732,0.069395,199.259399,10.150758,0.693954,-1212.817627,0.070618,0.000000
45.050003,45.346771,-1212.906616,0.012866,0.002750,0.069838,201.712509,10.275725,0.698377,-1212.906616,0.070965,0.000000
45.260002,45.842400,-1212.862061,0.012870,0.002762,0.070167,203.917175,10.388036,0.701673,-1212.862061,0.071321,0.000000
45.470001,46.508202,-1212.906616,0.012939,0.002779,0.070584,206.878815,10.538909,0.705835,-1212.906616,0.071668,0.000000
45.680000,46.942757,-1212.906616,0.012909,0.002792,0.070922,208.811813,10.637382,0.709217,-1212.906616,0.072014,0.000000
45.890003,47.419395,-1212.817627,0.012965,0.002806,0.071277,210.932007,10.745389,0.712773,-1212.817627,0.072370,0.000000
46.100002,47.636490,-1212.951050,0.012956,0.002820,0.071624,211.897690,10.794583,0.716242,-1212.951050,0.072717,0.000000
46.310001,48.144775,-1212.906616,0.012930,0.002834,0.071971,214.158661,10.909761,0.719711,-1212.906616,0.073064,0.000000
46.520000,48.473953,-1212.906616,0.012969,0.002845,0.072275,215.622910,10.984354,0.722746,-1212.906616,0.073419,0.000000
46.730003,49.168060,-1212.862061,0.013012,0.002864,0.072734,218.710449,11.141642,0.727342,-1212.862061,0.073766,0.000000
46.940002,49.665550,-1212.862061,0.013016,0.002875,0.073029,220.923401,11.254375,0.730291,-1212.862061,0.074122,0.000000
47.150002,49.674484,-1212.951050,0.013025,0.002883,0.073237,220.963135,11.256399,0.732372,-1212.951050,0.074469,0.000000
47.360001,50.413643,-1212.862061,0.013047,0.002901,0.073697,224.251083,11.423895,0.736969,-1212.862061,0.074816,0.000000
47.570004,50.926025,-1212.817627,0.013038,0.002917,0.074096,226.530273,11.540002,0.740958,-1212.817627,0.075171,0.000000
47.780003,50.620308,-1212.862061,0.013042,0.002917,0.074104,225.170380,11.470726,0.741045,-1212.862061,0.075518,0.000000
47.990002,52.040169,-1212.773071,0.013029,0.002945,0.074816,231.486237,11.792471,0.748156,-1212.773071,0.075865,0.000000
48.200001,52.412163,-1212.951050,0.013016,0.002958,0.075128,233.140945,11.876766,0.751278,-1212.951050,0.076220,0.000000
48.410004,52.863853,-1212.862061,0.013060,0.002972,0.075492,235.150162,11.979120,0.754920,-1212.862061,0.076567,0.000000
48.620003,53.141647,-1212.862061,0.013103,0.002983,0.075778,236.385849,12.042069,0.757782,-1212.862061,0.076914,0.000000
48.830002,53.745628,-1212.906616,0.013094,0.002997,0.076125,239.072495,12.178934,0.761251,-1212.906616,0.077270,0.000000
49.040001,54.209610,-1212.862061,0.013111,0.003012,0.076498,241.136383,12.284074,0.764980,-1212.862061,0.077617,0.000000
49.250004,54.691833,-1212.862061,0.013085,0.003025,0.076845,243.281433,12.393347,0.768449,-1212.862061,0.077964,0.000000
49.460003,55.381088,-1212.862061,0.013103,0.003040,0.077226,246.347382,12.549534,0.772265,-1212.862061,0.078319,0.000000
49.670002,56.345535,-1212.862061,0.013124,0.003060,0.077712,250.637451,12.768081,0.777121,-1212.862061,0.078666,0.000000
49.880001,56.672852,-1212.862061,0.013137,0.003072,0.078024,252.093430,12.842252,0.780243,-1212.862061,0.079022,0.000000
50.090004,57.244820,-1212.906616,0.013210,0.003086,0.078380,254.637680,12.971861,0.783799,-1212.906616,0.079369,0.000000
50.300003,57.522232,-1212.906616,0.013167,0.003097,0.078666,255.871674,13.034724,0.786661,-1212.906616,0.079715,0.000000
50.510002,57.935196,-1212.862061,0.013137,0.003111,0.079030,257.708618,13.128304,0.790303,-1212.862061,0.080071,0.000000
50.720001,58.650894,-1212.906616,0.013215,0.003126,0.079395,260.892212,13.290483,0.793945,-1212.906616,0.080418,0.000000
50.930004,58.991615,-1212.862061,0.013176,0.003138,0.079707,262.407806,13.367691,0.797067,-1212.862061,0.080765,0.000000
51.140003,59.084335,-1212.906616,0.013180,0.003144,0.079845,262.820251,13.388702,0.798455,-1212.906616,0.081120,0.000000
51.350002,60.449455,-1212.995483,0.013210,0.003170,0.080513,268.892609,13.698043,0.805132,-1212.995483,0.081467,0.000000
51.560001,61.091049,-1212.862061,0.013262,0.003184,0.080869,271.746552,13.843430,0.808688,-1212.862061,0.081814,0.000000
51.770004,61.382622,-1212.906616,0.013215,0.003194,0.081120,273.043549,13.909500,0.811203,-1212.906616,0.082170,0.000000
51.980003,62.015282,-1212.906616,0.013288,0.003209,0.081519,275.857758,14.052863,0.815193,-1212.906616,0.082517,0.000000
52.190002,62.450584,-1212.906616,0.013279,0.003223,0.081857,277.794067,14.151505,0.818574,-1212.906616,0.082872,0.000000
52.400002,62.773804,-1212.951050,0.013228,0.003232,0.082100,279.231812,14.224748,0.821003,-1212.951050,0.083219,0.000000
52.610001,63.379654,-1212.906616,0.013279,0.003249,0.082534,281.926788,14.362035,0.825339,-1212.906616,0.083566,0.000000
52.820004,64.008957,-1212.951050,0.013245,0.003262,0.082855,284.726074,14.504637,0.828548,-1212.951050,0.083921,0.000000
53.030003,64.344467,-1212.862061,0.013310,0.003271,0.083080,286.218475,14.580665,0.830802,-1212.862061,0.084268,0.000000
53.240002,65.072083,-1212.995483,0.013318,0.003286,0.083453,289.455078,14.745544,0.834531,-1212.995483,0.084615,0.000000
53.450001,65.661545,-1212.951050,0.013344,0.003298,0.083757,292.077148,14.879119,0.837567,-1212.951050,0.084971,0.000000
53.660004,67.013260,-1212.951050,0.013310,0.003319,0.084303,298.089874,15.185422,0.843030,-1212.951050,0.085318,0.000000
53.870003,67.211365,-1212.951050,0.013379,0.003320,0.084320,298.971069,15.230312,0.843204,-1212.951050,0.084555,0.000000
54.080002,66.535507,-1212.906616,0.013370,0.003320,0.084320,295.964722,15.077162,0.843204,-1212.906616,0.084555,0.000000
54.290001,66.063339,-1212.906616,0.013396,0.003319,0.084303,293.864410,14.970167,0.843030,-1212.906616,0.084320,0.000000
54.500004,65.574051,-1212.906616,0.013387,0.003319,0.084294,291.687958,14.859292,0.842943,-1212.906616,0.084320,0.000000
54.710003,65.141724,-1212.951050,0.013383,0.003318,0.084286,289.764862,14.761325,0.842857,-1212.951050,0.084320,0.000000
54.920002,64.779770,-1212.995483,0.013383,0.003318,0.084277,288.154816,14.679305,0.842770,-1212.995483,0.084320,0.000000
55.130001,64.446121,-1212.951050,0.013400,0.003318,0.084277,286.670654,14.603700,0.842770,-1212.951050,0.084320,0.000000
55.340004,64.137802,-1212.995483,0.013348,0.003318,0.084268,285.299194,14.533834,0.842683,-1212.995483,0.084320,0.000000
55.550003,63.865601,-1212.995483,0.013387,0.003318,0.084268,284.088379,14.472152,0.842683,-1212.995483,0.084320,0.000000
55.760002,63.606049,-1212.995483,0.013331,0.003318,0.084268,282.933838,14.413336,0.842683,-1212.995483,0.084320,0.000000
55.970001,63.368851,-1212.995483,0.013374,0.003318,0.084268,281.878723,14.359587,0.842683,-1212.995483,0.084320,0.000000
56.180004,63.160690,-1212.995483,0.013392,0.003318,0.084268,280.952789,14.312417,0.842683,-1212.995483,0.084320,0.000000
56.390003,62.946953,-1212.995483,0.013396,0.003318,0.084268,280.002045,14.263984,0.842683,-1212.995483,0.084320,0.000000
56.600002,62.759277,-1212.906616,0.013379,0.003318,0.084268,279.167206,14.221456,0.842683,-1212.906616,0.084320,0.000000
56.810001,62.591713,-1212.951050,0.013374,0.003317,0.084260,278.421844,14.183485,0.842597,-1212.951050,0.084320,0.000000
57.020004,62.423401,-1212.995483,0.013392,0.003317,0.084260,277.673157,14.145345,0.842597,-1212.995483,0.084320,0.000000
57.230003,62.269241,-1212.951050,0.013370,0.003317,0.084260,276.987427,14.110413,0.842597,-1212.951050,0.084320,0.000000
57.440002,62.117683,-1212.995483,0.013400,0.003317,0.084260,276.313263,14.076069,0.842597,-1212.995483,0.084320,0.000000
57.650002,61.970596,-1213.040039,0.013379,0.003317,0.084260,275.658966,14.042738,0.842597,-1213.040039,0.084320,0.000000
57.860004,61.832069,-1212.906616,0.013357,0.003317,0.084260,275.042786,14.011347,0.842597,-1212.906616,0.084320,0.000000
58.070004,61.722969,-1212.995483,0.013340,0.003317,0.084260,274.557465,13.986625,0.842597,-1212.995483,0.084320,0.000000
58.280003,61.594124,-1212.951050,0.013413,0.003317,0.084260,273.984344,13.957428,0.842597,-1212.951050,0.084320,0.000000
58.490002,61.477577,-1212.906616,0.013383,0.003317,0.084260,273.465912,13.931018,0.842597,-1212.906616,0.084320,0.000000
58.700005,61.380386,-1212.951050,0.013348,0.003317,0.084260,273.033600,13.908994,0.842597,-1212.951050,0.084320,0.000000
58.910004,61.262344,-1212.951050,0.013383,0.003317,0.084260,272.508514,13.882245,0.842597,-1212.951050,0.084320,0.000000
59.120003,61.152122,-1212.995483,0.013370,0.003317,0.084260,272.018219,13.857269,0.842597,-1212.995483,0.084320,0.000000
59.330002,61.066849,-1212.951050,0.013383,0.003317,0.084260,271.638916,13.837945,0.842597,-1212.951050,0.084320,0.000000
59.540005,60.964447,-1212.995483,0.013409,0.003317,0.084260,271.183411,13.814741,0.842597,-1212.995483,0.084320,0.000000
59.750004,60.865021,-1212.995483,0.013396,0.003317,0.084260,270.741119,13.792212,0.842597,-1212.995483,0.084320,0.000000
59.960003,60.784958,-1212.951050,0.013392,0.003317,0.084260,270.385010,13.774068,0.842597,-1212.951050,0.084320,0.000000
60.170002,60.691872,-1212.995483,0.013357,0.003317,0.084260,269.970917,13.752975,0.842597,-1212.995483,0.084320,0.000000
60.380001,60.603989,-1213.040039,0.013353,0.003317,0.084260,269.580017,13.733060,0.842597,-1213.040039,0.084320,0.000000
60.590004,60.536591,-1212.951050,0.013413,0.003317,0.084260,269.280212,13.717787,0.842597,-1212.951050,0.084320,0.000000
60.800003,60.458763,-1212.995483,0.013392,0.003317,0.084260,268.934021,13.700151,0.842597,-1212.995483,0.084320,0.000000
61.010002,60.391739,-1212.951050,0.013413,0.003317,0.084260,268.635864,13.684963,0.842597,-1212.951050,0.084320,0.000000
61.220001,60.312424,-1212.995483,0.013422,0.003317,0.084260,268.283051,13.666990,0.842597,-1212.995483,0.084320,0.000000
61.430004,60.245392,-1212.995483,0.013374,0.003317,0.084260,267.984894,13.651801,0.842597,-1212.995483,0.084320,0.000000
61.640003,60.169800,-1212.995483,0.013396,0.003317,0.084260,267.648651,13.634672,0.842597,-1212.995483,0.084320,0.000000
61.850002,60.098679,-1213.040039,0.013405,0.003317,0.084260,267.332275,13.618556,0.842597,-1213.040039,0.084320,0.000000
62.060001,60.031654,-1212.951050,0.013383,0.003317,0.084260,267.034149,13.603368,0.842597,-1212.951050,0.084320,0.000000
62.270004,59.954567,-1213.040039,0.013396,0.003317,0.084260,266.691223,13.585898,0.842597,-1213.040039,0.084320,0.000000
62.480003,59.905792,-1213.040039,0.013409,0.003317,0.084260,266.474274,13.574846,0.842597,-1213.040039,0.084320,0.000000
62.690002,59.835037,-1212.995483,0.013422,0.003317,0.084260,266.159546,13.558813,0.842597,-1212.995483,0.084320,0.000000
62.900002,59.784393,-1212.995483,0.013400,0.003317,0.084260,265.934265,13.547338,0.842597,-1212.995483,0.084320,0.000000
63.110004,59.730400,-1212.995483,0.013409,0.003317,0.084260,265.694092,13.535103,0.842597,-1212.995483,0.084320,0.000000
63.320004,59.680130,-1213.084473,0.013379,0.003317,0.084260,265.470490,13.523711,0.842597,-1213.084473,0.084320,0.000000
63.530003,59.600075,-1213.040039,0.013374,0.003317,0.084260,265.114380,13.505570,0.842597,-1213.040039,0.084320,0.000000
63.740002,59.560226,-1213.040039,0.013396,0.003317,0.084260,264.937134,13.496540,0.842597,-1213.040039,0.084320,0.000000
63.950005,59.511078,-1213.040039,0.013426,0.003317,0.084251,264.718506,13.485403,0.842510,-1213.040039,0.084320,0.000000
64.160004,59.435112,-1212.951050,0.013396,0.003317,0.084251,264.380585,13.468189,0.842510,-1212.951050,0.084320,0.000000
64.370003,59.395638,-1212.995483,0.013422,0.003317,0.084251,264.204987,13.459244,0.842510,-1212.995483,0.084320,0.000000
64.580002,59.359146,-1213.040039,0.013405,0.003317,0.084251,264.042664,13.450974,0.842510,-1213.040039,0.084320,0.000000
64.790001,59.295471,-1213.084473,0.013413,0.003317,0.084251,263.759430,13.436546,0.842510,-1213.084473,0.084320,0.000000
65.000000,59.241852,-1213.040039,0.013396,0.003317,0.084251,263.520905,13.424396,0.842510,-1213.040039,0.084320,0.000000
65.210007,59.198654,-1212.951050,0.013383,0.003317,0.084251,263.328766,13.414606,0.842510,-1212.951050,0.084320,0.000000
65.420006,59.152107,-1213.040039,0.013392,0.003317,0.084251,263.121704,13.404059,0.842510,-1213.040039,0.084320,0.000000
65.630005,59.103699,-1212.951050,0.013392,0.003317,0.084251,262.906372,13.393089,0.842510,-1212.951050,0.084320,0.000000
65.840004,59.070183,-1213.040039,0.013392,0.003317,0.084251,262.757294,13.385494,0.842510,-1213.040039,0.084320,0.000000
66.050003,59.014702,-1212.995483,0.013422,0.003317,0.084251,262.510498,13.372923,0.842510,-1212.995483,0.084320,0.000000
66.260002,58.976723,-1212.995483,0.013430,0.003317,0.084251,262.341553,13.364317,0.842510,-1212.995483,0.084320,0.000000
66.470001,58.939110,-1213.084473,0.013405,0.003317,0.084251,262.174255,13.355793,0.842510,-1213.084473,0.084320,0.000000
66.680000,58.882507,-1212.995483,0.013383,0.003317,0.084251,261.922485,13.342967,0.842510,-1212.995483,0.084320,0.000000
66.889999,58.848999,-1213.084473,0.013387,0.003317,0.084251,261.773407,13.335374,0.842510,-1213.084473,0.084320,0.000000
67.100006,58.817345,-1213.084473,0.013392,0.003317,0.084251,261.632629,13.328200,0.842510,-1213.084473,0.084320,0.000000
67.310005,58.771545,-1213.040039,0.013387,0.003317,0.084251,261.428894,13.317822,0.842510,-1213.040039,0.084320,0.000000
67.520004,58.732445,-1213.040039,0.013417,0.003317,0.084251,261.254974,13.308962,0.842510,-1213.040039,0.084320,0.000000
67.730003,58.704514,-1212.995483,0.013387,0.003317,0.084251,261.130707,13.302633,0.842510,-1212.995483,0.084320,0.000000
67.940002,58.644196,-1212.995483,0.013435,0.003317,0.084251,260.862396,13.288964,0.842510,-1212.995483,0.084320,0.000000
68.150002,58.618500,-1213.040039,0.013426,0.003317,0.084251,260.748108,13.283142,0.842510,-1213.040039,0.084320,0.000000
68.360001,58.581261,-1212.951050,0.013392,0.003317,0.084251,260.582458,13.274704,0.842510,-1212.951050,0.084320,0.000000
68.570000,58.552963,-1213.084473,0.013413,0.003317,0.084251,260.456573,13.268291,0.842510,-1213.084473,0.084320,0.000000
68.780006,58.507530,-1212.995483,0.013374,0.003317,0.084251,260.254486,13.257996,0.842510,-1212.995483,0.084320,0.000000
68.990005,58.498970,-1213.084473,0.013426,0.003317,0.084251,260.216400,13.256057,0.842510,-1213.084473,0.084320,0.000000
69.200005,58.441246,-1213.040039,0.013417,0.003317,0.084251,259.959656,13.242975,0.842510,-1213.040039,0.084320,0.000000
69.410004,58.404015,-1213.084473,0.013422,0.003317,0.084251,259.794037,13.234539,0.842510,-1213.084473,0.084320,0.000000
69.620003,58.380180,-1213.084473,0.013443,0.003317,0.084251,259.688019,13.229138,0.842510,-1213.084473,0.084320,0.000000
69.830002,58.335495,-1212.995483,0.013417,0.003317,0.084251,259.489227,13.219012,0.842510,-1212.995483,0.084320,0.000000
70.040001,58.308685,-1213.040039,0.013370,0.003317,0.084251,259.369995,13.212936,0.842510,-1213.040039,0.084320,0.000000
70.250000,58.274429,-1213.040039,0.013400,0.003317,0.084251,259.217621,13.205174,0.842510,-1213.040039,0.084320,0.000000
70.460007,58.253571,-1212.951050,0.013417,0.003317,0.084251,259.124817,13.200448,0.842510,-1212.951050,0.084320,0.000000
70.670006,58.205536,-1213.040039,0.013405,0.003317,0.084251,258.911163,13.189563,0.842510,-1213.040039,0.084320,0.000000
70.880005,58.188408,-1213.040039,0.013392,0.003317,0.084251,258.834961,13.185681,0.842510,-1213.040039,0.084320,0.000000
71.090004,58.162338,-1213.129028,0.013400,0.003317,0.084251,258.718994,13.179774,0.842510,-1213.129028,0.084320,0.000000
71.300003,58.136276,-1213.129028,0.013361,0.003317,0.084251,258.603058,13.173869,0.842510,-1213.129028,0.084320,0.000000
71.510002,58.119522,-1213.084473,0.013400,0.003317,0.084251,258.528534,13.170072,0.842510,-1213.084473,0.084320,0.000000
71.720001,58.073715,-1213.040039,0.013435,0.003317,0.084251,258.324799,13.159692,0.842510,-1213.040039,0.084320,0.000000
71.930000,58.037971,-1212.995483,0.013396,0.003317,0.084251,258.165802,13.151592,0.842510,-1212.995483,0.084320,0.000000
72.140007,58.021957,-1213.040039,0.013392,0.003317,0.084251,258.094543,13.147964,0.842510,-1213.040039,0.084320,0.000000
72.350006,57.997009,-1213.040039,0.013383,0.003317,0.084251,257.983582,13.142310,0.842510,-1213.040039,0.084320,0.000000
72.560005,57.954933,-1213.040039,0.013383,0.003317,0.084251,257.796417,13.132775,0.842510,-1213.040039,0.084320,0.000000
72.770004,57.937798,-1213.084473,0.013417,0.003317,0.084251,257.720184,13.128893,0.842510,-1213.084473,0.084320,0.000000
72.980003,57.915833,-1213.084473,0.013443,0.003317,0.084251,257.622498,13.123916,0.842510,-1213.084473,0.084320,0.000000
73.190002,57.863701,-1213.040039,0.013396,0.003317,0.084251,257.390594,13.112102,0.842510,-1213.040039,0.084320,0.000000
73.400002,57.854393,-1213.084473,0.013396,0.003317,0.084251,257.349182,13.109993,0.842510,-1213.084473,0.084320,0.000000
73.610001,57.827950,-1213.040039,0.013448,0.003317,0.084251,257.231567,13.104000,0.842510,-1213.040039,0.084320,0.000000
73.820000,57.791458,-1213.040039,0.013430,0.003317,0.084251,257.069244,13.095732,0.842510,-1213.040039,0.084320,0.000000
74.030006,57.763901,-1212.995483,0.013392,0.003317,0.084251,256.946655,13.089487,0.842510,-1212.995483,0.084320,0.000000
74.240005,57.754219,-1213.129028,0.013443,0.003317,0.084251,256.903595,13.087294,0.842510,-1213.129028,0.084320,0.000000
74.450005,57.716988,-1213.129028,0.013392,0.003317,0.084251,256.737976,13.078856,0.842510,-1213.129028,0.084320,0.000000
74.660004,57.690544,-1212.995483,0.013379,0.003317,0.084251,256.620361,13.072865,0.842510,-1212.995483,0.084320,0.000000
74.870003,57.670807,-1213.084473,0.013396,0.003317,0.084251,256.532562,13.068391,0.842510,-1213.084473,0.084320,0.000000
75.080002,57.652565,-1213.084473,0.013422,0.003317,0.084251,256.451416,13.064258,0.842510,-1213.084473,0.084320,0.000000
75.290001,57.626869,-1213.040039,0.013435,0.003317,0.084251,256.337128,13.058434,0.842510,-1213.040039,0.084320,0.000000
75.500000,57.600060,-1213.173462,0.013392,0.003317,0.084251,256.217865,13.052361,0.842510,-1213.173462,0.084320,0.000000
75.710007,57.584793,-1213.040039,0.013422,0.003317,0.084251,256.149963,13.048901,0.842510,-1213.040039,0.084320,0.000000
75.920006,57.559097,-1213.129028,0.013405,0.003317,0.084251,256.035645,13.043077,0.842510,-1213.129028,0.084320,0.000000
76.130005,57.524467,-1213.040039,0.013443,0.003317,0.084251,255.881607,13.035231,0.842510,-1213.040039,0.084320,0.000000
76.340004,57.522606,-1213.040039,0.013405,0.003317,0.084251,255.873337,13.034809,0.842510,-1213.040039,0.084320,0.000000
76.550003,57.488350,-1213.040039,0.013422,0.003317,0.084251,255.720947,13.027046,0.842510,-1213.040039,0.084320,0.000000
76.760002,57.468987,-1212.995483,0.013366,0.003317,0.084251,255.634827,13.022658,0.842510,-1212.995483,0.084320,0.000000
76.970001,57.456696,-1213.129028,0.013417,0.003317,0.084251,255.580139,13.019874,0.842510,-1213.129028,0.084320,0.000000
77.180000,57.430260,-1213.129028,0.013422,0.003317,0.084251,255.462555,13.013883,0.842510,-1213.129028,0.084320,0.000000
77.390007,57.407539,-1213.084473,0.013435,0.003317,0.084251,255.361496,13.008734,0.842510,-1213.084473,0.084320,0.000000
77.600006,57.393021,-1213.040039,0.013392,0.003317,0.084251,255.296906,13.005445,0.842510,-1213.040039,0.084320,0.000000
77.810005,57.362862,-1213.084473,0.013430,0.003317,0.084251,255.162750,12.998610,0.842510,-1213.084473,0.084320,0.000000
78.020004,57.331955,-1213.173462,0.013409,0.003317,0.084251,255.025269,12.991607,0.842510,-1213.173462,0.084320,0.000000
78.230003,57.325623,-1212.995483,0.013417,0.003317,0.084251,254.997101,12.990171,0.842510,-1212.995483,0.084320,0.000000
78.440002,57.307747,-1213.084473,0.013456,0.003317,0.084251,254.917587,12.986121,0.842510,-1213.084473,0.084320,0.000000
78.650002,57.286148,-1213.084473,0.013379,0.003317,0.084251,254.821518,12.981227,0.842510,-1213.084473,0.084320,0.000000
78.860001,57.267532,-1213.040039,0.013448,0.003317,0.084251,254.738708,12.977009,0.842510,-1213.040039,0.084320,0.000000
79.070007,57.262314,-1213.129028,0.013430,0.003317,0.084251,254.715500,12.975826,0.842510,-1213.129028,0.084320,0.000000
79.280006,57.224335,-1213.084473,0.013417,0.003317,0.084251,254.546555,12.967219,0.842510,-1213.084473,0.084320,0.000000
79.490005,57.213539,-1213.084473,0.013430,0.003317,0.084251,254.498535,12.964774,0.842510,-1213.084473,0.084320,0.000000
79.700005,57.190079,-1213.173462,0.013374,0.003317,0.084251,254.394180,12.959457,0.842510,-1213.173462,0.084320,0.000000
79.910004,57.165871,-1213.084473,0.013430,0.003317,0.084251,254.286499,12.953972,0.842510,-1213.084473,0.084320,0.000000
80.120003,57.145393,-1213.173462,0.013405,0.003317,0.084251,254.195404,12.949331,0.842510,-1213.173462,0.084320,0.000000
80.330002,57.135338,-1213.129028,0.013426,0.003317,0.084251,254.150681,12.947053,0.842510,-1213.129028,0.084320,0.000000
80.540001,57.116348,-1213.129028,0.013422,0.003317,0.084251,254.066208,12.942750,0.842510,-1213.129028,0.084320,0.000000
80.750008,57.084320,-1213.129028,0.013400,0.003317,0.084251,253.923737,12.935492,0.842510,-1213.129028,0.084320,0.000000
80.960007,57.071663,-1213.084473,0.013452,0.003317,0.084251,253.867432,12.932624,0.842510,-1213.084473,0.084320,0.000000
81.170006,57.053787,-1213.084473,0.013448,0.003317,0.084251,253.787918,12.928573,0.842510,-1213.084473,0.084320,0.000000
81.380005,57.023628,-1213.129028,0.013392,0.003317,0.084251,253.653763,12.921739,0.842510,-1213.129028,0.084320,0.000000
81.590004,57.011337,-1213.173462,0.013413,0.003317,0.084251,253.599091,12.918953,0.842510,-1213.173462,0.084320,0.000000
81.800003,57.006866,-1213.084473,0.013383,0.003317,0.084251,253.579208,12.917941,0.842510,-1213.084473,0.084320,0.000000
82.010002,56.976334,-1212.995483,0.013409,0.003317,0.084251,253.443390,12.911021,0.842510,-1212.995483,0.084320,0.000000
82.220001,56.959579,-1213.129028,0.013405,0.003317,0.084251,253.368866,12.907225,0.842510,-1213.129028,0.084320,0.000000
82.430000,56.951385,-1213.040039,0.013387,0.003317,0.084251,253.332413,12.905368,0.842510,-1213.040039,0.084320,0.000000
82.640007,56.929413,-1213.084473,0.013435,0.003317,0.084251,253.234680,12.900390,0.842510,-1213.084473,0.084320,0.000000
82.850006,56.898880,-1213.129028,0.013374,0.003317,0.084251,253.098862,12.893470,0.842510,-1213.129028,0.084320,0.000000
83.060005,56.887711,-1213.084473,0.013392,0.003317,0.084251,253.049179,12.890939,0.842510,-1213.084473,0.084320,0.000000
83.270004,56.875793,-1213.173462,0.013422,0.003317,0.084251,252.996170,12.888239,0.842510,-1213.173462,0.084320,0.000000
83.480003,56.852333,-1213.129028,0.013392,0.003317,0.084251,252.891815,12.882923,0.842510,-1213.129028,0.084320,0.000000
83.690002,56.847122,-1213.129028,0.013387,0.003317,0.084251,252.868622,12.881742,0.842510,-1213.129028,0.084320,0.000000
83.900002,56.851219,-1213.129028,0.013396,0.003317,0.084251,252.886856,12.882670,0.842510,-1213.129028,0.084320,0.000000
84.110001,56.822922,-1213.129028,0.013435,0.003317,0.084251,252.760986,12.876258,0.842510,-1213.129028,0.084320,0.000000
84.300003,56.811745,-1213.129028,0.013435,0.003317,0.084251,252.711258,12.873726,0.842510,-1213.129028,0.084320,0.000000