File: Data/Symmetrical membranes compression/Sterlitech PVDF 045um test 3_10272023_143826.csv
Time (sec),S:Load (lbs),S:HL1 (DIM),S:LVDT (in),S:Position (in),Ch:Position (mm),Ch:Load (N),Ch:Stress (MPa),Ch:Strain (mm/mm),Ch:HL1 (DIM),Set Point (),Cycles ()
0.110000,0.008186,-1210.148804,0.009563,-0.001239,-0.031480,0.036415,0.001855,-0.314802,-1210.148804,-0.031281,0.000000
0.300000,0.005585,-1210.193237,0.009628,-0.001239,-0.031480,0.024842,0.001266,-0.314802,-1210.193237,-0.031281,0.000000
0.490000,-0.003723,-1210.193237,0.009585,-0.001184,-0.030075,-0.016561,-0.000844,-0.300753,-1210.193237,-0.029529,0.000000
0.680000,-0.002609,-1210.193237,0.009653,-0.001084,-0.027534,-0.011607,-0.000591,-0.275344,-1210.193237,-0.026372,0.000000
0.870000,-0.016388,-1210.193237,0.009735,-0.000964,-0.024473,-0.072897,-0.003714,-0.244731,-1210.193237,-0.023198,0.000000
1.060000,-0.037987,-1210.193237,0.009860,-0.000836,-0.021238,-0.168974,-0.008608,-0.212383,-1210.193237,-0.020042,0.000000
1.250000,-0.051392,-1210.104248,0.009994,-0.000712,-0.018073,-0.228601,-0.011646,-0.180730,-1210.104248,-0.016868,0.000000
1.440000,-0.021225,-1210.104248,0.010154,-0.000585,-0.014847,-0.094413,-0.004810,-0.148469,-1210.104248,-0.013711,0.000000
1.630000,-0.020111,-1210.148804,0.010231,-0.000460,-0.011682,-0.089459,-0.004557,-0.116815,-1210.148804,-0.010537,0.000000
1.820000,0.026436,-1210.104248,0.010430,-0.000338,-0.008577,0.117593,0.005990,-0.085769,-1210.104248,-0.007380,0.000000
2.010000,0.149323,-1210.148804,0.010555,-0.000212,-0.005377,0.664220,0.033837,-0.053768,-1210.148804,-0.004206,0.000000
2.200000,0.421524,-1210.193237,0.010632,-0.000084,-0.002142,1.875033,0.095519,-0.021420,-1210.193237,-0.001049,0.000000
2.390000,0.649788,-1210.148804,0.010718,-0.000008,-0.000191,2.890401,0.147244,-0.001908,-1210.148804,0.000026,0.000000
2.580000,0.624466,-1210.193237,0.010693,-0.000008,-0.000191,2.777763,0.141506,-0.001908,-1210.193237,0.000026,0.000000
2.770000,0.608826,-1210.193237,0.010749,-0.000008,-0.000191,2.708192,0.137962,-0.001908,-1210.193237,0.000026,0.000000
2.960000,0.595421,-1210.193237,0.010706,-0.000008,-0.000191,2.648564,0.134924,-0.001908,-1210.193237,0.000225,0.000000
3.150000,0.597656,-1210.237671,0.010697,-0.000008,-0.000191,2.658508,0.135431,-0.001908,-1210.237671,0.000546,0.000000
3.340000,0.564514,-1210.148804,0.010762,-0.000007,-0.000182,2.511084,0.127921,-0.001821,-1210.148804,0.000859,0.000000
3.530000,0.566750,-1210.237671,0.010744,-0.000007,-0.000173,2.521028,0.128427,-0.001734,-1210.237671,0.001179,0.000000
3.720000,0.743622,-1210.148804,0.010766,0.000022,0.000564,3.307795,0.168507,0.005637,-1210.148804,0.001492,0.000000
3.910000,0.784584,-1210.237671,0.010727,0.000038,0.000954,3.490004,0.177789,0.009539,-1210.237671,0.001812,0.000000
4.100000,0.843048,-1210.193237,0.010779,0.000049,0.001249,3.750065,0.191037,0.012488,-1210.193237,0.002125,0.000000
4.290000,0.871346,-1210.148804,0.010813,0.000062,0.001587,3.875938,0.197450,0.015870,-1210.148804,0.002446,0.000000
4.480000,0.930557,-1210.193237,0.010779,0.000074,0.001891,4.139326,0.210867,0.018906,-1210.193237,0.002758,0.000000
4.670000,0.970024,-1210.148804,0.010779,0.000084,0.002125,4.314883,0.219811,0.021247,-1210.148804,0.003079,0.000000
4.860000,1.042267,-1210.237671,0.010796,0.000097,0.002454,4.636234,0.236181,0.024543,-1210.237671,0.003391,0.000000
5.050000,1.110786,-1210.193237,0.010826,0.000109,0.002758,4.941025,0.251708,0.027578,-1210.193237,0.003712,0.000000
5.240000,1.174088,-1210.104248,0.010835,0.000120,0.003044,5.222602,0.266052,0.030440,-1210.104248,0.004024,0.000000
5.430000,1.177437,-1210.282227,0.010878,0.000123,0.003131,5.237501,0.266811,0.031307,-1210.282227,0.004345,0.000000
5.620000,1.293617,-1210.193237,0.010848,0.000143,0.003642,5.754297,0.293138,0.036423,-1210.193237,0.004657,0.000000
5.810000,1.401604,-1210.148804,0.010895,0.000159,0.004033,6.234644,0.317608,0.040326,-1210.148804,0.004978,0.000000
6.000000,1.443687,-1210.237671,0.010917,0.000171,0.004345,6.421843,0.327144,0.043448,-1210.237671,0.005290,0.000000
6.190000,1.536781,-1210.193237,0.010874,0.000185,0.004700,6.835945,0.348240,0.047004,-1210.193237,0.005611,0.000000
6.380000,1.602318,-1210.193237,0.010908,0.000197,0.005013,7.127466,0.363090,0.050126,-1210.193237,0.005923,0.000000
6.570000,1.701736,-1210.193237,0.010925,0.000211,0.005368,7.569702,0.385619,0.053681,-1210.193237,0.006244,0.000000
6.760000,1.765045,-1210.237671,0.010951,0.000222,0.005646,7.851313,0.399965,0.056456,-1210.237671,0.006556,0.000000
6.950000,1.900589,-1210.282227,0.010938,0.000237,0.006019,8.454242,0.430680,0.060186,-1210.282227,0.006877,0.000000
7.140000,1.937454,-1210.148804,0.010960,0.000243,0.006183,8.618227,0.439033,0.061833,-1210.148804,0.007189,0.000000
7.330000,2.004852,-1210.237671,0.010951,0.000255,0.006487,8.918029,0.454306,0.064868,-1210.237671,0.007510,0.000000
7.520000,2.154915,-1210.148804,0.010990,0.000272,0.006903,9.585540,0.488311,0.069031,-1210.148804,0.007831,0.000000
7.710001,2.249130,-1210.193237,0.010994,0.000283,0.007181,10.004631,0.509660,0.071806,-1210.193237,0.008143,0.000000
7.900001,2.341476,-1210.193237,0.010990,0.000296,0.007519,10.415407,0.530586,0.075188,-1210.193237,0.008464,0.000000
8.090000,2.447227,-1210.237671,0.011012,0.000307,0.007805,10.885812,0.554550,0.078050,-1210.237671,0.008776,0.000000
8.280001,2.563034,-1210.282227,0.011059,0.000321,0.008152,11.400945,0.580792,0.081519,-1210.282227,0.009097,0.000000
8.470000,2.615913,-1210.193237,0.011029,0.000331,0.008412,11.636164,0.592774,0.084121,-1210.193237,0.009409,0.000000
8.660001,2.818481,-1210.237671,0.011055,0.000344,0.008733,12.537231,0.638677,0.087330,-1210.237671,0.009730,0.000000
8.850000,2.955887,-1210.193237,0.011098,0.000356,0.009054,13.148441,0.669814,0.090538,-1210.193237,0.010042,0.000000
9.040000,3.018822,-1210.237671,0.011063,0.000367,0.009314,13.428390,0.684075,0.093140,-1210.237671,0.010363,0.000000
9.230000,3.094040,-1210.193237,0.011081,0.000372,0.009461,13.762977,0.701119,0.094614,-1210.193237,0.010676,0.000000
9.420000,3.341667,-1210.237671,0.011128,0.000390,0.009912,14.864478,0.757233,0.099124,-1210.237671,0.010996,0.000000
9.610001,3.577377,-1210.104248,0.011145,0.000407,0.010346,15.912969,0.810645,0.103460,-1210.104248,0.011309,0.000000
9.800000,3.660416,-1210.237671,0.011163,0.000418,0.010606,16.282343,0.829462,0.106062,-1210.237671,0.011630,0.000000
9.990001,3.841019,-1210.237671,0.011137,0.000431,0.010953,17.085705,0.870387,0.109531,-1210.237671,0.011942,0.000000
10.180000,4.031677,-1210.237671,0.011158,0.000445,0.011300,17.933796,0.913591,0.112999,-1210.237671,0.012263,0.000000
10.370001,4.173172,-1210.237671,0.011167,0.000456,0.011595,18.563196,0.945654,0.115948,-1210.237671,0.012575,0.000000
10.560000,4.242439,-1210.237671,0.011219,0.000463,0.011751,18.871313,0.961351,0.117509,-1210.237671,0.012896,0.000000
10.750001,4.577942,-1210.282227,0.011193,0.000481,0.012219,20.363703,1.037376,0.122192,-1210.282227,0.013208,0.000000
10.940001,4.790199,-1210.148804,0.011180,0.000493,0.012514,21.307871,1.085475,0.125140,-1210.148804,0.013529,0.000000
11.130000,4.989418,-1210.193237,0.011236,0.000506,0.012844,22.194040,1.130618,0.128436,-1210.193237,0.013841,0.000000
11.320001,5.170761,-1210.193237,0.011232,0.000517,0.013121,23.000694,1.171711,0.131211,-1210.193237,0.014162,0.000000
11.510000,5.369240,-1210.193237,0.011206,0.000529,0.013433,23.883572,1.216687,0.134333,-1210.193237,0.014474,0.000000
11.700001,5.558029,-1210.237671,0.011262,0.000541,0.013746,24.723349,1.259467,0.137455,-1210.237671,0.014795,0.000000
11.890000,5.776237,-1210.193237,0.011262,0.000553,0.014058,25.693987,1.308914,0.140577,-1210.193237,0.015107,0.000000
12.080001,6.017166,-1210.237671,0.011292,0.000569,0.014457,26.765692,1.363509,0.144566,-1210.237671,0.015428,0.000000
12.270000,6.185104,-1210.193237,0.011300,0.000579,0.014708,27.512718,1.401565,0.147081,-1210.193237,0.015740,0.000000
12.460001,6.445389,-1210.237671,0.011309,0.000592,0.015038,28.670521,1.460546,0.150377,-1210.237671,0.016061,0.000000
12.650001,6.823349,-1210.282227,0.011318,0.000609,0.015471,30.351772,1.546193,0.154713,-1210.282227,0.016373,0.000000
12.840000,7.051613,-1210.193237,0.011296,0.000621,0.015783,31.367140,1.597918,0.157835,-1210.193237,0.016694,0.000000
13.030001,7.186783,-1210.193237,0.011344,0.000631,0.016026,31.968407,1.628548,0.160263,-1210.193237,0.017015,0.000000
13.220000,7.390099,-1210.237671,0.011335,0.000644,0.016347,32.872799,1.674620,0.163472,-1210.237671,0.017327,0.000000
13.410001,7.534210,-1210.193237,0.011344,0.000651,0.016547,33.513840,1.707276,0.165467,-1210.193237,0.017648,0.000000
13.600000,7.890572,-1210.326660,0.011382,0.000668,0.016963,35.099014,1.788029,0.169630,-1210.326660,0.017960,0.000000
13.790001,8.043991,-1210.237671,0.011417,0.000679,0.017258,35.781460,1.822794,0.172578,-1210.237671,0.018281,0.000000
13.980000,8.235390,-1210.237671,0.011395,0.000689,0.017501,36.632843,1.866166,0.175006,-1210.237671,0.018593,0.000000
14.170001,8.318428,-1210.237671,0.011348,0.000700,0.017778,37.002216,1.884983,0.177781,-1210.237671,0.018914,0.000000
14.360001,8.764526,-1210.193237,0.011426,0.000715,0.018151,38.986561,1.986070,0.181510,-1210.193237,0.019226,0.000000
14.550001,9.253082,-1210.282227,0.011421,0.000735,0.018680,41.159767,2.096778,0.186800,-1210.282227,0.019547,0.000000
14.740001,9.464218,-1210.237671,0.011395,0.000747,0.018975,42.098946,2.144622,0.189749,-1210.237671,0.019859,0.000000
14.930000,9.635506,-1210.326660,0.011400,0.000758,0.019261,42.860870,2.183437,0.192611,-1210.326660,0.020180,0.000000
15.120001,9.847763,-1210.237671,0.011495,0.000770,0.019556,43.805038,2.231535,0.195559,-1210.237671,0.020493,0.000000
15.310000,9.995590,-1210.237671,0.011464,0.000780,0.019816,44.462605,2.265033,0.198161,-1210.237671,0.020813,0.000000
15.500001,10.333336,-1210.282227,0.011456,0.000797,0.020241,45.964973,2.341568,0.202411,-1210.282227,0.021126,0.000000
15.690001,10.579842,-1210.237671,0.011529,0.000808,0.020536,47.061485,2.397426,0.205359,-1210.237671,0.021446,0.000000
15.880001,10.724327,-1210.326660,0.011482,0.000819,0.020805,47.704189,2.430167,0.208048,-1210.326660,0.021759,0.000000
16.070002,10.926895,-1210.237671,0.011533,0.000831,0.021117,48.605259,2.476070,0.211169,-1210.237671,0.022080,0.000000
16.260000,11.316399,-1210.237671,0.011507,0.000848,0.021533,50.337856,2.564333,0.215332,-1210.237671,0.022392,0.000000
16.450001,11.442635,-1210.237671,0.011563,0.000859,0.021819,50.899380,2.592938,0.218194,-1210.237671,0.022713,0.000000
16.640001,11.669037,-1210.193237,0.011542,0.000870,0.022097,51.906467,2.644242,0.220969,-1210.193237,0.023025,0.000000
16.830000,11.736809,-1210.193237,0.011538,0.000880,0.022357,52.207932,2.659599,0.223571,-1210.193237,0.023346,0.000000
17.020000,12.200035,-1210.237671,0.011585,0.000895,0.022739,54.268467,2.764568,0.227387,-1210.237671,0.023658,0.000000
17.210001,12.398140,-1210.237671,0.011568,0.000907,0.023042,55.149681,2.809459,0.230422,-1210.237671,0.023979,0.000000
17.400002,12.634964,-1210.237671,0.011559,0.000921,0.023389,56.203125,2.863124,0.233891,-1210.237671,0.024291,0.000000
17.590000,12.911270,-1210.237671,0.011628,0.000934,0.023736,57.432198,2.925736,0.237360,-1210.237671,0.024612,0.000000
17.780001,13.005478,-1210.326660,0.011598,0.000944,0.023987,57.851254,2.947083,0.239875,-1210.326660,0.024924,0.000000
17.970001,13.299278,-1210.237671,0.011611,0.000958,0.024326,59.158146,3.013659,0.243257,-1210.237671,0.025245,0.000000
18.160002,13.378967,-1210.326660,0.011602,0.000966,0.024534,59.512619,3.031717,0.245338,-1210.326660,0.025566,0.000000
18.350000,13.563667,-1210.371216,0.011650,0.000979,0.024863,60.334206,3.073571,0.248634,-1210.371216,0.025878,0.000000
18.540001,13.923378,-1210.237671,0.011689,0.000992,0.025193,61.934280,3.155083,0.251929,-1210.237671,0.026199,0.000000
18.730001,14.196701,-1210.237671,0.011650,0.001003,0.025488,63.150082,3.217019,0.254878,-1210.237671,0.026511,0.000000
18.920000,14.241753,-1210.193237,0.011667,0.001013,0.025722,63.350479,3.227227,0.257219,-1210.193237,0.026832,0.000000
19.110001,14.637589,-1210.282227,0.011693,0.001028,0.026121,65.111244,3.316925,0.261208,-1210.282227,0.027144,0.000000
19.300001,14.751160,-1210.237671,0.011680,0.001039,0.026398,65.616432,3.342661,0.263984,-1210.237671,0.027465,0.000000
19.490002,15.082947,-1210.237671,0.011706,0.001053,0.026745,67.092300,3.417845,0.267453,-1210.237671,0.027777,0.000000
19.680000,15.363716,-1210.282227,0.011749,0.001066,0.027083,68.341225,3.481468,0.270835,-1210.282227,0.028098,0.000000
19.870001,15.596817,-1210.237671,0.011740,0.001079,0.027404,69.378105,3.534289,0.274043,-1210.237671,0.028410,0.000000
20.060001,15.846306,-1210.282227,0.011766,0.001093,0.027751,70.487892,3.590824,0.277512,-1210.282227,0.028731,0.000000
20.250002,15.914078,-1210.282227,0.011732,0.001099,0.027925,70.789352,3.606182,0.279247,-1210.282227,0.029043,0.000000
20.440001,16.374702,-1210.193237,0.011758,0.001115,0.028324,72.838318,3.710561,0.283236,-1210.193237,0.029364,0.000000
20.630001,16.674095,-1210.282227,0.011801,0.001129,0.028688,74.170082,3.778404,0.286878,-1210.282227,0.029676,0.000000
20.820002,16.706116,-1210.282227,0.011809,0.001135,0.028835,74.312515,3.785660,0.288353,-1210.282227,0.029997,0.000000
21.010000,17.064339,-1210.193237,0.011826,0.001148,0.029156,75.905968,3.866835,0.291561,-1210.193237,0.030310,0.000000
21.200001,17.416977,-1210.282227,0.011779,0.001167,0.029642,77.474586,3.946743,0.296418,-1210.282227,0.030630,0.000000
21.390001,17.898079,-1210.282227,0.011818,0.001180,0.029963,79.614632,4.055763,0.299626,-1210.282227,0.030943,0.000000
21.580002,18.131554,-1210.282227,0.011878,0.001194,0.030318,80.653175,4.108669,0.303182,-1210.282227,0.031263,0.000000
21.770000,18.385139,-1210.326660,0.011814,0.001206,0.030622,81.781181,4.166132,0.306217,-1210.326660,0.031576,0.000000
21.960001,18.625694,-1210.193237,0.011822,0.001218,0.030934,82.851227,4.220643,0.309339,-1210.193237,0.031897,0.000000
22.150002,18.808159,-1210.326660,0.011900,0.001227,0.031177,83.662872,4.261990,0.311767,-1210.326660,0.032209,0.000000
22.340000,19.086693,-1210.326660,0.011878,0.001242,0.031550,84.901848,4.325107,0.315497,-1210.326660,0.032530,0.000000
22.530001,19.430023,-1210.237671,0.011917,0.001252,0.031801,86.429062,4.402906,0.318012,-1210.237671,0.032842,0.000000
22.720001,19.633705,-1210.326660,0.011895,0.001261,0.032035,87.335083,4.449061,0.320353,-1210.326660,0.033163,0.000000
22.910002,19.899956,-1210.326660,0.011904,0.001276,0.032408,88.519424,4.509395,0.324082,-1210.326660,0.033475,0.000000
23.100000,20.442871,-1210.326660,0.011883,0.001291,0.032781,90.934433,4.632421,0.327811,-1210.326660,0.033796,0.000000
23.290001,20.896049,-1210.282227,0.011947,0.001308,0.033223,92.950272,4.735113,0.332234,-1210.282227,0.034108,0.000000
23.480001,21.124687,-1210.237671,0.011943,0.001319,0.033492,93.967300,4.786922,0.334923,-1210.237671,0.034429,0.000000
23.670002,21.453865,-1210.326660,0.011982,0.001334,0.033874,95.431557,4.861516,0.338738,-1210.326660,0.034750,0.000000
23.860001,21.625526,-1210.326660,0.012008,0.001344,0.034134,96.195145,4.900414,0.341340,-1210.326660,0.035062,0.000000
24.050001,21.857887,-1210.326660,0.011973,0.001355,0.034429,97.228737,4.953068,0.344289,-1210.326660,0.035383,0.000000
24.240002,22.050034,-1210.282227,0.011990,0.001368,0.034741,98.083450,4.996609,0.347411,-1210.282227,0.035695,0.000000
24.430000,22.421288,-1210.282227,0.012012,0.001379,0.035036,99.734871,5.080736,0.350359,-1210.282227,0.036016,0.000000
24.620001,22.822334,-1210.326660,0.011995,0.001392,0.035348,101.518814,5.171615,0.353481,-1210.326660,0.036328,0.000000
24.810001,22.892342,-1210.371216,0.012033,0.001401,0.035582,101.830223,5.187479,0.355823,-1210.371216,0.036649,0.000000
25.000002,23.695175,-1210.371216,0.012042,0.001421,0.036085,105.401405,5.369403,0.360852,-1210.371216,0.036961,0.000000
25.190001,23.988602,-1210.282227,0.012046,0.001434,0.036415,106.706627,5.435895,0.364148,-1210.282227,0.037282,0.000000
25.380001,24.131592,-1210.282227,0.012038,0.001444,0.036684,107.342682,5.468297,0.366836,-1210.282227,0.037594,0.000000
25.570002,24.436195,-1210.282227,0.012094,0.001459,0.037048,108.697624,5.537321,0.370479,-1210.282227,0.037915,0.000000
25.760002,24.691643,-1210.326660,0.012068,0.001470,0.037325,109.833916,5.595206,0.373254,-1210.326660,0.038227,0.000000
25.950001,24.856979,-1210.326660,0.012081,0.001480,0.037594,110.569366,5.632672,0.375942,-1210.326660,0.038548,0.000000
26.140001,25.282974,-1210.415649,0.012072,0.001494,0.037941,112.464287,5.729204,0.379411,-1210.415649,0.038860,0.000000
26.330002,25.536186,-1210.326660,0.012141,0.001505,0.038219,113.590630,5.786582,0.382186,-1210.326660,0.039181,0.000000
26.520000,25.769661,-1210.282227,0.012098,0.001516,0.038496,114.629173,5.839489,0.384962,-1210.282227,0.039493,0.000000
26.710001,25.744713,-1210.282227,0.012111,0.001521,0.038635,114.518204,5.833835,0.386349,-1210.282227,0.039814,0.000000
26.900002,26.186348,-1210.415649,0.012141,0.001534,0.038964,116.482697,5.933911,0.389645,-1210.415649,0.040127,0.000000
27.090002,27.048019,-1210.371216,0.012137,0.001557,0.039545,120.315598,6.129169,0.395455,-1210.371216,0.040447,0.000000
27.280001,27.288193,-1210.326660,0.012137,0.001569,0.039840,121.383942,6.183593,0.398403,-1210.326660,0.040760,0.000000
27.470001,27.487419,-1210.371216,0.012197,0.001581,0.040161,122.270149,6.228738,0.401612,-1210.371216,0.041080,0.000000
27.660002,27.783821,-1210.326660,0.012236,0.001594,0.040499,123.588608,6.295904,0.404994,-1210.326660,0.041393,0.000000
27.850000,28.103317,-1210.415649,0.012206,0.001607,0.040820,125.009796,6.368303,0.408203,-1210.415649,0.041714,0.000000
28.040001,28.361000,-1210.326660,0.012227,0.001619,0.041124,126.156029,6.426694,0.411238,-1210.326660,0.042026,0.000000
28.230001,28.563576,-1210.415649,0.012232,0.001631,0.041427,127.057129,6.472599,0.414274,-1210.415649,0.042347,0.000000
28.420002,28.881950,-1210.326660,0.012262,0.001642,0.041705,128.473328,6.544744,0.417049,-1210.326660,0.042659,0.000000
28.610001,28.833916,-1210.371216,0.012266,0.001648,0.041861,128.259659,6.533859,0.418610,-1210.371216,0.042980,0.000000
28.800001,29.252090,-1210.371216,0.012215,0.001662,0.042208,130.119797,6.628618,0.422079,-1210.371216,0.043292,0.000000
28.990002,29.818466,-1210.371216,0.012258,0.001679,0.042650,132.639160,6.756961,0.426501,-1210.371216,0.043613,0.000000
29.180002,30.034813,-1210.415649,0.012296,0.001690,0.042936,133.601517,6.805986,0.429363,-1210.415649,0.043934,0.000000
29.370001,30.276855,-1210.371216,0.012288,0.001702,0.043231,134.678177,6.860834,0.432312,-1210.371216,0.044246,0.000000
29.560001,30.730034,-1210.326660,0.012305,0.001718,0.043630,136.694016,6.963525,0.436301,-1210.326660,0.044567,0.000000
29.750002,30.800789,-1210.415649,0.012305,0.001726,0.043838,137.008759,6.979558,0.438383,-1210.415649,0.044879,0.000000
29.940001,31.210396,-1210.326660,0.012335,0.001741,0.044211,138.830780,7.072377,0.442112,-1210.326660,0.045200,0.000000
30.130001,31.517227,-1210.415649,0.012352,0.001751,0.044480,140.195633,7.141906,0.444800,-1210.415649,0.045512,0.000000
30.320002,31.518349,-1210.415649,0.012361,0.001758,0.044645,140.200623,7.142160,0.446448,-1210.415649,0.045833,0.000000
30.510002,31.827789,-1210.371216,0.012374,0.001770,0.044948,141.577072,7.212280,0.449483,-1210.371216,0.046145,0.000000
30.700001,32.311501,-1210.415649,0.012374,0.001784,0.045321,143.728729,7.321891,0.453212,-1210.415649,0.046466,0.000000
30.890001,32.385979,-1210.371216,0.012387,0.001796,0.045616,144.060028,7.338768,0.456161,-1210.371216,0.046778,0.000000
31.080002,33.062950,-1210.371216,0.012404,0.001812,0.046024,147.071350,7.492171,0.460237,-1210.371216,0.047099,0.000000
31.270002,33.318024,-1210.460083,0.012365,0.001824,0.046336,148.205978,7.549972,0.463359,-1210.460083,0.047411,0.000000
31.460001,33.762260,-1210.415649,0.012417,0.001839,0.046717,150.182037,7.650638,0.467174,-1210.415649,0.047732,0.000000
31.650002,34.009148,-1210.326660,0.012404,0.001850,0.046995,151.280243,7.706583,0.469950,-1210.326660,0.048044,0.000000
31.840002,34.035957,-1210.415649,0.012400,0.001857,0.047177,151.399506,7.712658,0.471771,-1210.415649,0.048365,0.000000
32.030003,34.550201,-1210.371216,0.012460,0.001875,0.047628,153.686966,7.829187,0.476280,-1210.371216,0.048677,0.000000
32.220001,34.954231,-1210.415649,0.012465,0.001889,0.047975,155.484192,7.920742,0.479749,-1210.415649,0.048998,0.000000
32.410000,35.138924,-1210.326660,0.012486,0.001900,0.048261,156.305740,7.962594,0.482611,-1210.326660,0.049310,0.000000
32.600002,35.411499,-1210.460083,0.012490,0.001912,0.048556,157.518219,8.024361,0.485559,-1210.460083,0.049631,0.000000
32.790001,35.690033,-1210.460083,0.012460,0.001922,0.048816,158.757202,8.087478,0.488162,-1210.460083,0.049944,0.000000
32.980003,36.123848,-1210.415649,0.012473,0.001937,0.049206,160.686905,8.185781,0.492064,-1210.415649,0.050264,0.000000
33.170002,36.304825,-1210.415649,0.012482,0.001948,0.049475,161.491928,8.226791,0.494752,-1210.415649,0.050577,0.000000
33.360001,36.725975,-1210.371216,0.012512,0.001961,0.049805,163.365295,8.322226,0.498048,-1210.371216,0.050897,0.000000
33.550003,36.974724,-1210.415649,0.012486,0.001973,0.050126,164.471786,8.378592,0.501256,-1210.415649,0.051210,0.000000
33.740002,37.264053,-1210.371216,0.012499,0.001985,0.050420,165.758789,8.444156,0.504205,-1210.371216,0.051531,0.000000
33.930000,37.481148,-1210.371216,0.012551,0.001995,0.050663,166.724472,8.493350,0.506633,-1210.371216,0.051843,0.000000
34.120003,38.403511,-1210.460083,0.012499,0.002017,0.051236,170.827347,8.702360,0.512357,-1210.460083,0.052164,0.000000
34.310001,38.696571,-1210.326660,0.012572,0.002029,0.051531,172.130951,8.768768,0.515305,-1210.326660,0.052476,0.000000
34.500000,38.813126,-1210.415649,0.012559,0.002039,0.051791,172.649399,8.795179,0.517907,-1210.415649,0.052797,0.000000
34.690002,38.895416,-1210.415649,0.012616,0.002049,0.052042,173.015457,8.813828,0.520422,-1210.415649,0.053118,0.000000
34.880001,39.295349,-1210.460083,0.012585,0.002063,0.052406,174.794449,8.904454,0.524065,-1210.460083,0.053430,0.000000
35.070004,39.691551,-1210.460083,0.012603,0.002075,0.052693,176.556839,8.994234,0.526926,-1210.460083,0.053751,0.000000
35.260002,39.757088,-1210.371216,0.012598,0.002084,0.052927,176.848358,9.009086,0.529268,-1210.371216,0.054063,0.000000
35.450001,39.964500,-1210.460083,0.012624,0.002096,0.053248,177.770981,9.056085,0.532477,-1210.460083,0.054384,0.000000
35.640003,40.435181,-1210.415649,0.012616,0.002112,0.053655,179.864670,9.162743,0.536552,-1210.415649,0.054696,0.000000
35.830002,40.965813,-1210.415649,0.012624,0.002121,0.053881,182.225037,9.282986,0.538807,-1210.415649,0.055017,0.000000
36.020000,41.803650,-1210.460083,0.012689,0.002142,0.054410,185.951920,9.472842,0.544098,-1210.460083,0.055329,0.000000
36.210003,42.115692,-1210.460083,0.012659,0.002154,0.054713,187.339951,9.543552,0.547133,-1210.460083,0.055650,0.000000
36.400002,42.426254,-1210.415649,0.012680,0.002167,0.055034,188.721405,9.613926,0.550341,-1210.415649,0.055962,0.000000
36.590000,42.604622,-1210.460083,0.012697,0.002178,0.055312,189.514816,9.654346,0.553117,-1210.460083,0.056283,0.000000
36.780003,42.696594,-1210.415649,0.012697,0.002187,0.055554,189.923935,9.675186,0.555545,-1210.415649,0.056595,0.000000
36.970001,43.512840,-1210.460083,0.012684,0.002205,0.056005,193.554779,9.860151,0.560054,-1210.460083,0.056916,0.000000
37.160004,43.538902,-1210.415649,0.012741,0.002215,0.056257,193.670715,9.866056,0.562569,-1210.415649,0.057228,0.000000
37.350002,43.688225,-1210.371216,0.012771,0.002225,0.056517,194.334930,9.899894,0.565171,-1210.371216,0.057549,0.000000
37.540001,44.546539,-1210.504639,0.012775,0.002242,0.056951,198.152908,10.094391,0.569507,-1210.504639,0.057861,0.000000
37.730003,44.526062,-1210.460083,0.012784,0.002248,0.057107,198.061813,10.089749,0.571068,-1210.460083,0.058182,0.000000
37.920002,44.973282,-1210.504639,0.012792,0.002262,0.057445,200.051147,10.191091,0.574450,-1210.504639,0.058494,0.000000
38.110001,45.264481,-1210.415649,0.012741,0.002275,0.057783,201.346466,10.257078,0.577832,-1210.415649,0.058815,0.000000
38.300003,45.884102,-1210.415649,0.012758,0.002290,0.058156,204.102676,10.397486,0.581561,-1210.415649,0.059127,0.000000
38.490002,46.322762,-1210.371216,0.012797,0.002303,0.058486,206.053940,10.496888,0.584857,-1210.371216,0.059448,0.000000
38.680000,46.606506,-1210.371216,0.012810,0.002315,0.058798,207.316101,10.561185,0.587979,-1210.371216,0.059761,0.000000
38.870003,47.062294,-1210.415649,0.012848,0.002329,0.059153,209.343536,10.664469,0.591535,-1210.415649,0.060081,0.000000
39.060001,47.171768,-1210.460083,0.012844,0.002337,0.059353,209.830505,10.689275,0.593529,-1210.460083,0.060394,0.000000
39.250000,47.724373,-1210.371216,0.012827,0.002353,0.059769,212.288620,10.814497,0.597692,-1210.371216,0.060714,0.000000
39.440002,48.014816,-1210.504639,0.012827,0.002363,0.060021,213.580566,10.880313,0.600207,-1210.504639,0.061027,0.000000
39.630001,48.191322,-1210.415649,0.012818,0.002373,0.060281,214.365707,10.920310,0.602808,-1210.415649,0.061348,0.000000
39.820004,48.860481,-1210.460083,0.012853,0.002388,0.060662,217.342270,11.071943,0.606624,-1210.460083,0.061660,0.000000
40.010002,49.321472,-1210.460083,0.012878,0.002401,0.060992,219.392868,11.176406,0.609920,-1210.460083,0.061981,0.000000
40.200001,49.363556,-1210.415649,0.012887,0.002409,0.061191,219.580063,11.185942,0.611914,-1210.415649,0.062301,0.000000
40.390003,50.024513,-1210.460083,0.012878,0.002425,0.061590,222.520142,11.335717,0.615904,-1210.460083,0.062614,0.000000
40.580002,50.722710,-1210.460083,0.012926,0.002440,0.061981,225.625885,11.493930,0.619806,-1210.460083,0.062935,0.000000
40.770000,50.837776,-1210.593506,0.012943,0.002449,0.062197,226.137726,11.520004,0.621974,-1210.593506,0.063247,0.000000
40.960003,51.282761,-1210.460083,0.012887,0.002462,0.062536,228.117111,11.620840,0.625356,-1210.460083,0.063568,0.000000
41.150002,51.697586,-1210.415649,0.012939,0.002475,0.062857,229.962341,11.714841,0.628565,-1210.415649,0.063880,0.000000
41.340000,52.141449,-1210.460083,0.012904,0.002486,0.063143,231.936752,11.815421,0.631427,-1210.460083,0.064201,0.000000
41.530003,52.299339,-1210.415649,0.012913,0.002496,0.063394,232.639084,11.851199,0.633942,-1210.415649,0.064513,0.000000
41.720001,52.894020,-1210.504639,0.012952,0.002512,0.063793,235.284348,11.985956,0.637931,-1210.504639,0.064834,0.000000
41.910004,53.465233,-1210.504639,0.012939,0.002524,0.064105,237.825241,12.115395,0.641053,-1210.504639,0.065146,0.000000
42.100002,53.731110,-1210.415649,0.012947,0.002532,0.064322,239.007919,12.175644,0.643221,-1210.415649,0.065467,0.000000
42.290001,54.120613,-1210.549072,0.012973,0.002546,0.064678,240.740509,12.263906,0.646777,-1210.549072,0.065779,0.000000
42.480003,53.886765,-1210.415649,0.013021,0.002546,0.064678,239.700302,12.210915,0.646777,-1210.415649,0.066100,0.000000
42.670002,55.233635,-1210.504639,0.013029,0.002574,0.065389,245.691483,12.516120,0.653888,-1210.504639,0.066412,0.000000
42.860001,55.798523,-1210.504639,0.013029,0.002585,0.065658,248.204224,12.644126,0.656577,-1210.504639,0.066733,0.000000
43.050003,56.150787,-1210.460083,0.012991,0.002597,0.065970,249.771179,12.723950,0.659699,-1210.460083,0.067045,0.000000
43.240002,56.604332,-1210.593506,0.013004,0.002611,0.066317,251.788651,12.826725,0.663168,-1210.593506,0.067366,0.000000
43.430000,56.948776,-1210.460083,0.013073,0.002621,0.066586,253.320816,12.904778,0.665856,-1210.460083,0.067678,0.000000
43.620003,57.166992,-1210.460083,0.013042,0.002632,0.066863,254.291489,12.954226,0.668631,-1210.460083,0.067999,0.000000
43.810001,57.928116,-1210.460083,0.013055,0.002647,0.067227,257.677124,13.126699,0.672274,-1210.460083,0.068311,0.000000
44.000004,58.399918,-1210.460083,0.013051,0.002660,0.067557,259.775818,13.233610,0.675569,-1210.460083,0.068632,0.000000
44.190002,58.150055,-1210.504639,0.013085,0.002664,0.067661,258.664368,13.176991,0.676610,-1210.504639,0.068944,0.000000
44.380001,59.316322,-1210.460083,0.013133,0.002685,0.068190,263.852173,13.441271,0.681899,-1210.460083,0.069265,0.000000
44.570004,59.810837,-1210.460083,0.013055,0.002696,0.068485,266.051880,13.553329,0.684848,-1210.460083,0.069578,0.000000
44.760002,60.774536,-1210.460083,0.013098,0.002714,0.068927,270.338654,13.771707,0.689271,-1210.460083,0.069898,0.000000
44.950001,61.127541,-1210.460083,0.013137,0.002727,0.069257,271.908875,13.851699,0.692566,-1210.460083,0.070211,0.000000
45.140003,61.536034,-1210.549072,0.013124,0.002738,0.069534,273.725952,13.944264,0.695342,-1210.549072,0.070531,0.000000
45.330002,61.876015,-1210.460083,0.013176,0.002748,0.069794,275.238251,14.021306,0.697943,-1210.460083,0.070844,0.000000
45.520000,62.259560,-1210.460083,0.013120,0.002759,0.070072,276.944366,14.108218,0.700718,-1210.460083,0.071165,0.000000
45.710003,62.565277,-1210.504639,0.013129,0.002774,0.070453,278.304260,14.177494,0.704534,-1210.504639,0.071485,0.000000
45.900002,63.270172,-1210.415649,0.013189,0.002782,0.070662,281.439789,14.337226,0.706615,-1210.415649,0.071798,0.000000
46.090004,63.573654,-1210.549072,0.013198,0.002791,0.070896,282.789734,14.405996,0.708957,-1210.549072,0.072118,0.000000
46.280003,64.614441,-1210.504639,0.013198,0.002812,0.071433,287.419403,14.641842,0.714334,-1210.504639,0.072431,0.000000
46.470001,65.206146,-1210.504639,0.013189,0.002825,0.071763,290.051422,14.775925,0.717629,-1210.504639,0.072752,0.000000
46.660004,65.963547,-1210.593506,0.013228,0.002839,0.072101,293.420502,14.947554,0.721012,-1210.593506,0.073064,0.000000
46.850002,66.391022,-1210.460083,0.013189,0.002851,0.072405,295.322021,15.044420,0.724047,-1210.460083,0.073385,0.000000
47.040001,66.860214,-1210.504639,0.013189,0.002863,0.072708,297.409088,15.150742,0.727082,-1210.504639,0.073697,0.000000
47.230003,67.324936,-1210.504639,0.013245,0.002873,0.072977,299.476257,15.256049,0.729770,-1210.504639,0.074018,0.000000
47.420002,67.261261,-1210.504639,0.013245,0.002869,0.072864,299.193024,15.241620,0.728643,-1210.504639,0.073124,0.000000
47.610001,66.719467,-1210.593506,0.013258,0.002869,0.072864,296.783020,15.118848,0.728643,-1210.593506,0.073124,0.000000
47.800003,66.203354,-1210.504639,0.013254,0.002867,0.072821,294.487213,15.001894,0.728210,-1210.504639,0.072864,0.000000
47.990002,65.805664,-1210.549072,0.013275,0.002866,0.072804,292.718201,14.911777,0.728036,-1210.549072,0.072864,0.000000
48.180004,65.443344,-1210.460083,0.013219,0.002866,0.072795,291.106537,14.829674,0.727949,-1210.460083,0.072864,0.000000
48.370003,65.132782,-1210.504639,0.013267,0.002866,0.072786,289.725098,14.759299,0.727863,-1210.504639,0.072864,0.000000
48.560001,64.856110,-1210.593506,0.013236,0.002866,0.072786,288.494385,14.696605,0.727863,-1210.593506,0.072864,0.000000
48.750004,64.615555,-1210.460083,0.013297,0.002865,0.072778,287.424347,14.642094,0.727776,-1210.460083,0.072864,0.000000
48.940002,64.379852,-1210.549072,0.013232,0.002865,0.072778,286.375885,14.588683,0.727776,-1210.549072,0.072864,0.000000
49.130001,64.172440,-1210.460083,0.013254,0.002865,0.072778,285.453278,14.541683,0.727776,-1210.460083,0.072864,0.000000
49.320004,64.004120,-1210.549072,0.013292,0.002865,0.072778,284.704559,14.503541,0.727776,-1210.549072,0.072864,0.000000
49.510002,63.796341,-1210.549072,0.013236,0.002865,0.072778,283.780304,14.456458,0.727776,-1210.549072,0.072864,0.000000
49.700001,63.635849,-1210.460083,0.013284,0.002865,0.072778,283.066406,14.420090,0.727776,-1210.460083,0.072864,0.000000
49.890003,63.507370,-1210.549072,0.013279,0.002865,0.072778,282.494904,14.390976,0.727776,-1210.549072,0.072864,0.000000
50.080002,63.353958,-1210.549072,0.013297,0.002865,0.072769,281.812469,14.356212,0.727689,-1210.549072,0.072864,0.000000
50.270004,63.206879,-1210.504639,0.013262,0.002865,0.072769,281.158234,14.322884,0.727689,-1210.504639,0.072864,0.000000
50.460003,63.090698,-1210.549072,0.013267,0.002865,0.072769,280.641449,14.296556,0.727689,-1210.549072,0.072864,0.000000
50.650002,62.971535,-1210.504639,0.013305,0.002865,0.072769,280.111389,14.269554,0.727689,-1210.504639,0.072864,0.000000
50.840004,62.837105,-1210.504639,0.013262,0.002865,0.072769,279.513397,14.239092,0.727689,-1210.504639,0.072864,0.000000
51.030003,62.735451,-1210.504639,0.013288,0.002865,0.072769,279.061218,14.216057,0.727689,-1210.504639,0.072864,0.000000
51.220001,62.637886,-1210.549072,0.013258,0.002865,0.072769,278.627228,14.193948,0.727689,-1210.549072,0.072864,0.000000
51.410004,62.521706,-1210.593506,0.013297,0.002865,0.072769,278.110443,14.167621,0.727689,-1210.593506,0.072864,0.000000
51.600002,62.442017,-1210.549072,0.013292,0.002865,0.072769,277.755951,14.149563,0.727689,-1210.549072,0.072864,0.000000
51.790001,62.341103,-1210.549072,0.013279,0.002865,0.072769,277.307068,14.126696,0.727689,-1210.549072,0.072864,0.000000
51.980003,62.265144,-1210.504639,0.013279,0.002865,0.072769,276.969208,14.109484,0.727689,-1210.504639,0.072864,0.000000
52.170002,62.181732,-1210.504639,0.013271,0.002865,0.072769,276.598145,14.090582,0.727689,-1210.504639,0.072864,0.000000
52.360001,62.103157,-1210.549072,0.013267,0.002865,0.072769,276.248627,14.072777,0.727689,-1210.549072,0.072864,0.000000
52.550003,62.018631,-1210.549072,0.013284,0.002865,0.072769,275.872650,14.053622,0.727689,-1210.549072,0.072864,0.000000
52.740002,61.962029,-1210.593506,0.013245,0.002865,0.072760,275.620880,14.040796,0.727603,-1210.593506,0.072864,0.000000
52.930004,61.884949,-1210.549072,0.013323,0.002865,0.072760,275.278015,14.023330,0.727603,-1210.549072,0.072864,0.000000
53.120003,61.810844,-1210.549072,0.013271,0.002865,0.072760,274.948364,14.006538,0.727603,-1210.549072,0.072864,0.000000
53.310001,61.743073,-1210.593506,0.013271,0.002865,0.072760,274.646912,13.991180,0.727603,-1210.593506,0.072864,0.000000
53.500004,61.665993,-1210.549072,0.013271,0.002865,0.072760,274.304047,13.973714,0.727603,-1210.549072,0.072864,0.000000
53.690002,61.607903,-1210.593506,0.013249,0.002865,0.072760,274.045624,13.960550,0.727603,-1210.593506,0.072864,0.000000
53.880001,61.553169,-1210.504639,0.013305,0.002865,0.072760,273.802185,13.948148,0.727603,-1210.504639,0.072864,0.000000
54.070004,61.494705,-1210.504639,0.013301,0.002865,0.072760,273.542114,13.934899,0.727603,-1210.504639,0.072864,0.000000
54.260002,61.432144,-1210.549072,0.013305,0.002865,0.072760,273.263824,13.920722,0.727603,-1210.549072,0.072864,0.000000
54.450001,61.381126,-1210.549072,0.013249,0.002865,0.072760,273.036896,13.909162,0.727603,-1210.549072,0.072864,0.000000
54.640003,61.314476,-1210.549072,0.013318,0.002865,0.072760,272.740417,13.894059,0.727603,-1210.549072,0.072864,0.000000
54.830002,61.267555,-1210.593506,0.013262,0.002865,0.072760,272.531708,13.883427,0.727603,-1210.593506,0.072864,0.000000
55.020004,61.218399,-1210.593506,0.013288,0.002865,0.072760,272.313049,13.872288,0.727603,-1210.593506,0.072864,0.000000
55.210003,61.162178,-1210.638062,0.013245,0.002865,0.072760,272.062958,13.859548,0.727603,-1210.638062,0.072864,0.000000
55.400002,61.117859,-1210.593506,0.013297,0.002865,0.072760,271.865814,13.849505,0.727603,-1210.593506,0.072864,0.000000
55.590004,61.063866,-1210.593506,0.013258,0.002865,0.072760,271.625641,13.837270,0.727603,-1210.593506,0.072864,0.000000
55.780003,61.028122,-1210.593506,0.013297,0.002865,0.072760,271.466644,13.829170,0.727603,-1210.593506,0.072864,0.000000
55.970001,60.983810,-1210.549072,0.013310,0.002865,0.072760,271.269531,13.819129,0.727603,-1210.549072,0.072864,0.000000
56.160004,60.931679,-1210.638062,0.013279,0.002865,0.072760,271.037659,13.807316,0.727603,-1210.638062,0.072864,0.000000
56.350002,60.891090,-1210.593506,0.013288,0.002865,0.072760,270.857086,13.798119,0.727603,-1210.593506,0.072864,0.000000
56.540001,60.848640,-1210.593506,0.013245,0.002865,0.072760,270.668274,13.788499,0.727603,-1210.593506,0.072864,0.000000
56.730003,60.796501,-1210.593506,0.013267,0.002865,0.072760,270.436340,13.776685,0.727603,-1210.593506,0.072864,0.000000
56.920002,60.757408,-1210.504639,0.013271,0.002865,0.072760,270.262451,13.767825,0.727603,-1210.504639,0.072864,0.000000
57.110004,60.726501,-1210.638062,0.013258,0.002865,0.072760,270.124969,13.760821,0.727603,-1210.638062,0.072864,0.000000
57.300003,60.685165,-1210.638062,0.013262,0.002865,0.072760,269.941101,13.751455,0.727603,-1210.638062,0.072864,0.000000
57.490002,60.641228,-1210.593506,0.013284,0.002865,0.072760,269.745667,13.741498,0.727603,-1210.593506,0.072864,0.000000
57.680004,60.608086,-1210.593506,0.013305,0.002865,0.072760,269.598236,13.733989,0.727603,-1210.593506,0.072864,0.000000
57.870003,60.570099,-1210.593506,0.013288,0.002865,0.072760,269.429260,13.725381,0.727603,-1210.593506,0.072864,0.000000
58.060001,60.534355,-1210.682495,0.013314,0.002865,0.072760,269.270264,13.717280,0.727603,-1210.682495,0.072864,0.000000
58.250004,60.489296,-1210.638062,0.013318,0.002865,0.072760,269.069824,13.707070,0.727603,-1210.638062,0.072864,0.000000
58.440002,60.454666,-1210.593506,0.013301,0.002865,0.072760,268.915771,13.699223,0.727603,-1210.593506,0.072864,0.000000
58.630001,60.429718,-1210.593506,0.013271,0.002865,0.072760,268.804810,13.693569,0.727603,-1210.593506,0.072864,0.000000
58.820004,60.392105,-1210.504639,0.013310,0.002865,0.072760,268.637512,13.685047,0.727603,-1210.504639,0.072864,0.000000
59.010002,60.365669,-1210.638062,0.013314,0.002865,0.072760,268.519897,13.679056,0.727603,-1210.638062,0.072864,0.000000
59.200005,60.326942,-1210.549072,0.013275,0.002865,0.072760,268.347656,13.670280,0.727603,-1210.549072,0.072864,0.000000
59.390003,60.284866,-1210.549072,0.013323,0.002865,0.072760,268.160492,13.660746,0.727603,-1210.549072,0.072864,0.000000
59.580002,60.259544,-1210.593506,0.013305,0.002865,0.072760,268.047852,13.655008,0.727603,-1210.593506,0.072864,0.000000
59.770004,60.229752,-1210.504639,0.013292,0.002865,0.072760,267.915314,13.648256,0.727603,-1210.504639,0.072864,0.000000
59.960003,60.200333,-1210.682495,0.013305,0.002865,0.072760,267.784454,13.641590,0.727603,-1210.682495,0.072864,0.000000
60.150002,60.169060,-1210.593506,0.013292,0.002865,0.072760,267.645355,13.634503,0.727603,-1210.593506,0.072864,0.000000
60.340004,60.146713,-1210.593506,0.013314,0.002865,0.072760,267.545929,13.629439,0.727603,-1210.593506,0.072864,0.000000
60.530003,60.105751,-1210.682495,0.013249,0.002865,0.072760,267.363739,13.620158,0.727603,-1210.682495,0.072864,0.000000
60.720001,60.084160,-1210.549072,0.013262,0.002865,0.072760,267.267700,13.615266,0.727603,-1210.549072,0.072864,0.000000
60.910004,60.051384,-1210.593506,0.013279,0.002865,0.072760,267.121887,13.607838,0.727603,-1210.593506,0.072864,0.000000
61.100002,60.016754,-1210.638062,0.013318,0.002865,0.072760,266.967865,13.599991,0.727603,-1210.638062,0.072864,0.000000
61.290005,59.987709,-1210.593506,0.013310,0.002865,0.072760,266.838654,13.593410,0.727603,-1210.593506,0.072864,0.000000
61.480003,59.968719,-1210.638062,0.013249,0.002865,0.072760,266.754181,13.589107,0.727603,-1210.638062,0.072864,0.000000
61.670002,59.947495,-1210.549072,0.013323,0.002865,0.072760,266.659760,13.584296,0.727603,-1210.549072,0.072864,0.000000
61.860004,59.922920,-1210.638062,0.013262,0.002865,0.072760,266.550476,13.578728,0.727603,-1210.638062,0.072864,0.000000
62.050003,59.898346,-1210.593506,0.013279,0.002864,0.072752,266.441162,13.573159,0.727515,-1210.593506,0.072864,0.000000
62.240002,59.874512,-1210.549072,0.013314,0.002864,0.072752,266.335144,13.567759,0.727515,-1210.549072,0.072864,0.000000
62.430004,59.851051,-1210.638062,0.013318,0.002864,0.072752,266.230774,13.562442,0.727515,-1210.638062,0.072864,0.000000
62.620003,59.830940,-1210.549072,0.013318,0.002864,0.072752,266.141327,13.557884,0.727515,-1210.549072,0.072864,0.000000
62.810001,59.810089,-1210.593506,0.013314,0.002864,0.072752,266.048553,13.553161,0.727515,-1210.593506,0.072864,0.000000
63.000004,59.768387,-1210.638062,0.013336,0.002864,0.072752,265.863068,13.543711,0.727515,-1210.638062,0.072864,0.000000
63.190002,59.751999,-1210.593506,0.013305,0.002864,0.072752,265.790161,13.539996,0.727515,-1210.593506,0.072864,0.000000
63.380005,59.723328,-1210.593506,0.013323,0.002864,0.072752,265.662628,13.533499,0.727515,-1210.593506,0.072864,0.000000
63.570004,59.716255,-1210.549072,0.013267,0.002864,0.072752,265.631165,13.531897,0.727515,-1210.549072,0.072864,0.000000
63.760002,59.685715,-1210.638062,0.013275,0.002864,0.072752,265.495331,13.524977,0.727515,-1210.638062,0.072864,0.000000
63.950005,59.654068,-1210.682495,0.013344,0.002864,0.072752,265.354553,13.517805,0.727515,-1210.682495,0.072864,0.000000
64.139999,59.638054,-1210.549072,0.013301,0.002864,0.072752,265.283325,13.514176,0.727515,-1210.549072,0.072864,0.000000
64.330002,59.616829,-1210.682495,0.013297,0.002864,0.072752,265.188904,13.509367,0.727515,-1210.682495,0.072864,0.000000
64.520004,59.587036,-1210.638062,0.013323,0.002864,0.072752,265.056366,13.502615,0.727515,-1210.638062,0.072864,0.000000
64.710007,59.575493,-1210.638062,0.013267,0.002864,0.072752,265.005035,13.500000,0.727515,-1210.638062,0.072864,0.000000
64.900002,59.543846,-1210.638062,0.013310,0.002864,0.072752,264.864258,13.492828,0.727515,-1210.638062,0.072864,0.000000
65.090004,59.527084,-1210.682495,0.013297,0.002864,0.072752,264.789703,13.489031,0.727515,-1210.682495,0.072864,0.000000
65.280006,59.502510,-1210.593506,0.013279,0.002864,0.072752,264.680389,13.483461,0.727515,-1210.593506,0.072864,0.000000
65.470001,59.491714,-1210.638062,0.013297,0.002864,0.072752,264.632355,13.481015,0.727515,-1210.638062,0.072864,0.000000
65.660004,59.460060,-1210.593506,0.013292,0.002864,0.072752,264.491547,13.473842,0.727515,-1210.593506,0.072864,0.000000
65.850006,59.446281,-1210.638062,0.013336,0.002864,0.072752,264.430267,13.470720,0.727515,-1210.638062,0.072864,0.000000
66.040001,59.413139,-1210.593506,0.013297,0.002864,0.072752,264.282837,13.463209,0.727515,-1210.593506,0.072864,0.000000
66.230003,59.405693,-1210.682495,0.013318,0.002864,0.072752,264.249725,13.461523,0.727515,-1210.682495,0.072864,0.000000
66.420006,59.394150,-1210.593506,0.013323,0.002864,0.072752,264.198364,13.458906,0.727515,-1210.593506,0.072864,0.000000
66.610001,59.370689,-1210.638062,0.013292,0.002864,0.072752,264.094025,13.453591,0.727515,-1210.638062,0.072864,0.000000
66.800003,59.349838,-1210.638062,0.013336,0.002864,0.072752,264.001251,13.448866,0.727515,-1210.638062,0.072864,0.000000
66.990005,59.345741,-1210.638062,0.013318,0.002864,0.072752,263.983032,13.447937,0.727515,-1210.638062,0.072864,0.000000
67.180000,59.314835,-1210.682495,0.013271,0.002864,0.072752,263.845551,13.440934,0.727515,-1210.682495,0.072864,0.000000
67.370003,59.301056,-1210.638062,0.013297,0.002864,0.072752,263.784271,13.437812,0.727515,-1210.638062,0.072864,0.000000
67.560005,59.273872,-1210.638062,0.013275,0.002864,0.072752,263.663361,13.431651,0.727515,-1210.638062,0.072864,0.000000
67.750000,59.258232,-1210.727051,0.013314,0.002864,0.072752,263.593781,13.428107,0.727515,-1210.727051,0.072864,0.000000
67.940002,59.240356,-1210.638062,0.013292,0.002864,0.072752,263.514252,13.424057,0.727515,-1210.638062,0.072864,0.000000
68.130005,59.238495,-1210.682495,0.013267,0.002864,0.072752,263.505981,13.423635,0.727515,-1210.682495,0.072864,0.000000
68.320000,59.198280,-1210.593506,0.013275,0.002864,0.072752,263.327087,13.414522,0.727515,-1210.593506,0.072864,0.000000
68.510002,59.178543,-1210.682495,0.013271,0.002864,0.072752,263.239319,13.410050,0.727515,-1210.682495,0.072864,0.000000
68.700005,59.171844,-1210.727051,0.013297,0.002864,0.072752,263.209503,13.408532,0.727515,-1210.727051,0.072864,0.000000
68.890007,59.153595,-1210.638062,0.013275,0.002864,0.072752,263.128326,13.404396,0.727515,-1210.638062,0.072864,0.000000
69.080002,59.140190,-1210.727051,0.013292,0.002864,0.072752,263.068695,13.401359,0.727515,-1210.727051,0.072864,0.000000
69.270004,59.118965,-1210.638062,0.013288,0.002864,0.072752,262.974304,13.396548,0.727515,-1210.638062,0.072864,0.000000
69.460007,59.106308,-1210.638062,0.013258,0.002864,0.072752,262.917999,13.393681,0.727515,-1210.638062,0.072864,0.000000
69.650002,59.090294,-1210.682495,0.013305,0.002864,0.072752,262.846741,13.390052,0.727515,-1210.682495,0.072864,0.000000
69.840004,59.078003,-1210.638062,0.013310,0.002864,0.072752,262.792084,13.387267,0.727515,-1210.638062,0.072864,0.000000
70.030006,59.063484,-1210.682495,0.013305,0.002864,0.072752,262.727509,13.383977,0.727515,-1210.682495,0.072864,0.000000
70.220001,59.032951,-1210.682495,0.013267,0.002864,0.072752,262.591675,13.377058,0.727515,-1210.682495,0.072864,0.000000
70.410004,59.031830,-1210.682495,0.013336,0.002864,0.072752,262.586700,13.376804,0.727515,-1210.682495,0.072864,0.000000
70.600006,59.017685,-1210.682495,0.013314,0.002864,0.072752,262.523773,13.373598,0.727515,-1210.682495,0.072864,0.000000
70.790001,58.991989,-1210.638062,0.013284,0.002864,0.072752,262.409485,13.367775,0.727515,-1210.638062,0.072864,0.000000
70.980003,58.977837,-1210.727051,0.013314,0.002864,0.072752,262.346527,13.364569,0.727515,-1210.727051,0.072864,0.000000
71.170006,58.957359,-1210.727051,0.013348,0.002864,0.072752,262.255432,13.359929,0.727515,-1210.727051,0.072864,0.000000
71.360001,58.943954,-1210.682495,0.013310,0.002864,0.072752,262.195801,13.356892,0.727515,-1210.682495,0.072864,0.000000
71.550003,58.932037,-1210.638062,0.013310,0.002864,0.072752,262.142792,13.354191,0.727515,-1210.638062,0.072864,0.000000
71.740005,58.908203,-1210.593506,0.013310,0.002864,0.072752,262.036774,13.348790,0.727515,-1210.593506,0.072864,0.000000
71.930000,58.900757,-1210.682495,0.013331,0.002864,0.072752,262.003662,13.347102,0.727515,-1210.682495,0.072864,0.000000
72.120003,58.888092,-1210.682495,0.013288,0.002864,0.072752,261.947327,13.344233,0.727515,-1210.682495,0.072864,0.000000
72.310005,58.869102,-1210.727051,0.013288,0.002864,0.072752,261.862854,13.339930,0.727515,-1210.727051,0.072864,0.000000
72.500000,58.853096,-1210.682495,0.013344,0.002864,0.072752,261.791656,13.336303,0.727515,-1210.682495,0.072864,0.000000
72.690002,58.857559,-1210.682495,0.013292,0.002864,0.072752,261.811493,13.337314,0.727515,-1210.682495,0.072864,0.000000
72.880005,58.847504,-1210.727051,0.013344,0.002864,0.072752,261.766785,13.335035,0.727515,-1210.727051,0.072864,0.000000
73.070000,58.818092,-1210.638062,0.013292,0.002864,0.072752,261.635956,13.328370,0.727515,-1210.638062,0.072864,0.000000
73.260002,58.802078,-1210.593506,0.013297,0.002864,0.072752,261.564697,13.324741,0.727515,-1210.593506,0.072864,0.000000
73.450005,58.789047,-1210.727051,0.013271,0.002864,0.072752,261.506744,13.321789,0.727515,-1210.727051,0.072864,0.000000
73.640007,58.769684,-1210.638062,0.013323,0.002864,0.072752,261.420624,13.317401,0.727515,-1210.638062,0.072864,0.000000
73.830002,58.720154,-1210.638062,0.013284,0.002864,0.072752,261.200287,13.306176,0.727515,-1210.638062,0.072864,0.000000
74.020004,58.675102,-1210.638062,0.013284,0.002864,0.072752,260.999878,13.295968,0.727515,-1210.638062,0.072864,0.000000
74.210007,58.668770,-1210.682495,0.013275,0.002864,0.072752,260.971710,13.294534,0.727515,-1210.682495,0.072864,0.000000
74.400002,58.643822,-1210.727051,0.013228,0.002864,0.072752,260.860748,13.288880,0.727515,-1210.727051,0.072864,0.000000
74.590004,58.609192,-1210.638062,0.013275,0.002864,0.072752,260.706696,13.281033,0.727515,-1210.638062,0.072864,0.000000
74.780006,58.605835,-1210.682495,0.013228,0.002864,0.072752,260.691772,13.280272,0.727515,-1210.682495,0.072864,0.000000
74.970001,58.590195,-1210.727051,0.013254,0.002864,0.072752,260.622192,13.276728,0.727515,-1210.727051,0.072864,0.000000
75.160004,58.599510,-1210.638062,0.013292,0.002864,0.072752,260.663635,13.278839,0.727515,-1210.638062,0.072864,0.000000
75.350006,58.683289,-1210.682495,0.013292,0.002864,0.072752,261.036316,13.297824,0.727515,-1210.682495,0.072864,0.000000
75.540001,58.667282,-1210.593506,0.013340,0.002864,0.072752,260.965118,13.294196,0.727515,-1210.593506,0.072864,0.000000
75.730003,58.657967,-1210.727051,0.013267,0.002864,0.072752,260.923676,13.292085,0.727515,-1210.727051,0.072864,0.000000
75.920006,58.648659,-1210.727051,0.013271,0.002864,0.072752,260.882263,13.289976,0.727515,-1210.727051,0.072864,0.000000
76.110001,58.641960,-1210.638062,0.013331,0.002864,0.072752,260.852478,13.288458,0.727515,-1210.638062,0.072864,0.000000
76.300003,58.617378,-1210.682495,0.013271,0.002864,0.072752,260.743134,13.282887,0.727515,-1210.682495,0.072864,0.000000
76.490005,58.617378,-1210.682495,0.013292,0.002864,0.072752,260.743134,13.282887,0.727515,-1210.682495,0.072864,0.000000
76.680000,58.586845,-1210.638062,0.013310,0.002864,0.072752,260.607300,13.275970,0.727515,-1210.638062,0.072864,0.000000
76.870003,58.583122,-1210.727051,0.013288,0.002864,0.072752,260.590729,13.275126,0.727515,-1210.727051,0.072864,0.000000
77.060005,58.568230,-1210.638062,0.013301,0.002864,0.072752,260.524506,13.271750,0.727515,-1210.638062,0.072864,0.000000
77.250000,58.544022,-1210.638062,0.013292,0.002864,0.072752,260.416809,13.266265,0.727515,-1210.638062,0.072864,0.000000
77.440002,58.549980,-1210.727051,0.013323,0.002864,0.072752,260.443329,13.267615,0.727515,-1210.727051,0.072864,0.000000
77.630005,58.527641,-1210.682495,0.013305,0.002864,0.072752,260.343964,13.262553,0.727515,-1210.682495,0.072864,0.000000
77.700005,58.533226,-1210.682495,0.013275,0.002864,0.072752,260.368805,13.263819,0.727515,-1210.682495,0.072864,0.000000