File: Data/Symmetrical membranes compression/Sterlitech PVDF 02um test 2_10272023_144332.csv
Time (sec),S:Load (lbs),S:HL1 (DIM),S:LVDT (in),S:Position (in),Ch:Position (mm),Ch:Load (N),Ch:Stress (MPa),Ch:Strain (mm/mm),Ch:HL1 (DIM),Set Point (),Cycles ()
0.110000,-0.001862,-1211.883545,0.005118,-0.005191,-0.131862,-0.008281,-0.000422,-1.318617,-1211.883545,-0.131732,0.000000
0.330000,-0.013779,-1211.838989,0.005144,-0.005191,-0.131862,-0.061291,-0.003122,-1.318617,-1211.838989,-0.131732,0.000000
0.550000,-0.017502,-1211.883545,0.005118,-0.005104,-0.129650,-0.077852,-0.003966,-1.296502,-1211.883545,-0.128627,0.000000
0.770000,-0.008942,-1211.883545,0.005234,-0.004969,-0.126216,-0.039774,-0.002026,-1.262160,-1211.883545,-0.124950,0.000000
0.990000,-0.026070,-1211.838989,0.005450,-0.004823,-0.122496,-0.115964,-0.005907,-1.224956,-1211.838989,-0.121290,0.000000
1.210000,-0.033142,-1211.883545,0.005566,-0.004673,-0.118697,-0.147423,-0.007510,-1.186972,-1211.883545,-0.117630,0.000000
1.430000,-0.048782,-1211.838989,0.005726,-0.004532,-0.115116,-0.216995,-0.011054,-1.151155,-1211.838989,-0.113953,0.000000
1.650000,-0.064796,-1211.838989,0.005829,-0.004387,-0.111438,-0.288229,-0.014683,-1.114385,-1211.838989,-0.110294,0.000000
1.870000,-0.044312,-1211.883545,0.005997,-0.004249,-0.107926,-0.197107,-0.010041,-1.079262,-1211.883545,-0.106634,0.000000
2.090000,-0.028679,-1211.883545,0.006178,-0.004105,-0.104275,-0.127570,-0.006499,-1.042752,-1211.883545,-0.102957,0.000000
2.310000,-0.004845,-1211.794556,0.006325,-0.003958,-0.100529,-0.021550,-0.001098,-1.005288,-1211.794556,-0.099297,0.000000
2.530000,-0.017876,-1211.883545,0.006485,-0.003817,-0.096964,-0.079515,-0.004051,-0.969645,-1211.883545,-0.095638,0.000000
2.750000,-0.011543,-1211.883545,0.006584,-0.003666,-0.093123,-0.051347,-0.002616,-0.931227,-1211.883545,-0.091961,0.000000
2.970000,-0.024208,-1211.883545,0.006765,-0.003523,-0.089472,-0.107683,-0.005486,-0.894717,-1211.883545,-0.088301,0.000000
3.190000,-0.049530,-1211.883545,0.006967,-0.003380,-0.085864,-0.220321,-0.011224,-0.858640,-1211.883545,-0.084641,0.000000
3.410000,-0.063675,-1211.927979,0.007084,-0.003236,-0.082196,-0.283240,-0.014429,-0.821956,-1211.927979,-0.080964,0.000000
3.630000,-0.030540,-1211.883545,0.007235,-0.003085,-0.078354,-0.135851,-0.006921,-0.783538,-1211.883545,-0.077304,0.000000
3.850000,-0.024208,-1211.883545,0.007381,-0.002951,-0.074946,-0.107683,-0.005486,-0.749456,-1211.883545,-0.073645,0.000000
4.070000,0.003723,-1211.883545,0.007532,-0.002806,-0.071260,0.016561,0.000844,-0.712599,-1211.883545,-0.069985,0.000000
4.290000,-0.007446,-1211.794556,0.007662,-0.002661,-0.067592,-0.033123,-0.001687,-0.675916,-1211.794556,-0.066308,0.000000
4.510000,-0.002983,-1211.883545,0.007834,-0.002507,-0.063672,-0.013269,-0.000676,-0.636717,-1211.883545,-0.062648,0.000000
4.730000,-0.017876,-1211.883545,0.007950,-0.002364,-0.060038,-0.079515,-0.004051,-0.600380,-1211.883545,-0.058989,0.000000
4.950000,-0.040962,-1211.883545,0.008162,-0.002223,-0.056465,-0.182209,-0.009282,-0.564650,-1211.883545,-0.055312,0.000000
5.170000,-0.034264,-1211.927979,0.008308,-0.002087,-0.053022,-0.152412,-0.007764,-0.530222,-1211.927979,-0.051652,0.000000
5.390000,-0.022346,-1211.838989,0.008438,-0.001931,-0.049042,-0.099402,-0.005064,-0.490416,-1211.838989,-0.047992,0.000000
5.610000,-0.010803,-1211.794556,0.008597,-0.001787,-0.045382,-0.048055,-0.002448,-0.453819,-1211.794556,-0.044315,0.000000
5.830000,-0.028679,-1211.883545,0.008787,-0.001644,-0.041766,-0.127570,-0.006499,-0.417656,-1211.883545,-0.040656,0.000000
6.050000,-0.004845,-1211.927979,0.008899,-0.001504,-0.038210,-0.021550,-0.001098,-0.382099,-1211.927979,-0.036996,0.000000
6.270000,-0.008194,-1211.927979,0.009084,-0.001357,-0.034472,-0.036449,-0.001857,-0.344722,-1211.927979,-0.033319,0.000000
6.490000,-0.036491,-1211.883545,0.009244,-0.001209,-0.030717,-0.162322,-0.008269,-0.307171,-1211.883545,-0.029659,0.000000
6.710001,-0.017128,-1211.838989,0.009369,-0.001069,-0.027144,-0.076189,-0.003881,-0.271441,-1211.838989,-0.025999,0.000000
6.930000,-0.008942,-1211.883545,0.009528,-0.000920,-0.023372,-0.039774,-0.002026,-0.233717,-1211.883545,-0.022322,0.000000
7.150001,-0.020859,-1211.927979,0.009632,-0.000784,-0.019920,-0.092784,-0.004727,-0.199202,-1211.927979,-0.018663,0.000000
7.370000,0.011917,-1211.927979,0.009774,-0.000638,-0.016217,0.053010,0.002700,-0.162171,-1211.927979,-0.015003,0.000000
7.590000,-0.010056,-1211.838989,0.009942,-0.000491,-0.012479,-0.044729,-0.002279,-0.124794,-1211.838989,-0.011326,0.000000
7.810000,0.013405,-1211.927979,0.010098,-0.000348,-0.008828,0.059628,0.003038,-0.088284,-1211.927979,-0.007666,0.000000
8.030001,0.099045,-1211.883545,0.010261,-0.000203,-0.005151,0.440573,0.022444,-0.051513,-1211.883545,-0.004007,0.000000
8.250000,0.421150,-1211.972534,0.010382,-0.000062,-0.001587,1.873370,0.095434,-0.015870,-1211.972534,-0.000347,0.000000
8.470000,0.688141,-1211.972534,0.010503,-0.000000,-0.000009,3.061003,0.155935,-0.000087,-1211.972534,0.000147,0.000000
8.690001,0.637497,-1211.838989,0.010464,-0.000001,-0.000026,2.835728,0.144459,-0.000260,-1211.838989,0.000147,0.000000
8.910001,0.624466,-1211.838989,0.010503,-0.000001,-0.000026,2.777763,0.141506,-0.000260,-1211.838989,0.000147,0.000000
9.130000,0.615158,-1211.883545,0.010511,-0.000001,-0.000026,2.736360,0.139397,-0.000260,-1211.883545,0.000520,0.000000
9.350000,0.629311,-1211.838989,0.010499,-0.000001,-0.000017,2.799313,0.142604,-0.000174,-1211.838989,0.000885,0.000000
9.570001,0.659843,-1211.883545,0.010529,0.000016,0.000408,2.935130,0.149523,0.004076,-1211.883545,0.001249,0.000000
9.790001,0.731712,-1211.838989,0.010537,0.000028,0.000711,3.254819,0.165808,0.007111,-1211.838989,0.001613,0.000000
10.010000,0.739532,-1211.927979,0.010494,0.000040,0.001023,3.289605,0.167580,0.010233,-1211.927979,0.001986,0.000000
10.230000,0.814751,-1211.927979,0.010524,0.000055,0.001388,3.624192,0.184625,0.013875,-1211.927979,0.002350,0.000000
10.450001,0.837837,-1211.972534,0.010555,0.000066,0.001674,3.726886,0.189857,0.016737,-1211.972534,0.002714,0.000000
10.670000,0.926834,-1211.883545,0.010563,0.000077,0.001960,4.122764,0.210024,0.019599,-1211.883545,0.003087,0.000000
10.890000,0.990135,-1211.838989,0.010637,0.000094,0.002394,4.404341,0.224368,0.023935,-1211.838989,0.003452,0.000000
11.110001,1.067963,-1211.838989,0.010572,0.000109,0.002775,4.750535,0.242004,0.027751,-1211.838989,0.003816,0.000000
11.330001,1.144295,-1211.883545,0.010602,0.000125,0.003174,5.090077,0.259301,0.031740,-1211.883545,0.004180,0.000000
11.550000,1.259361,-1211.972534,0.010658,0.000148,0.003764,5.601919,0.285375,0.037637,-1211.972534,0.004553,0.000000
11.770000,1.298836,-1211.883545,0.010628,0.000159,0.004041,5.777510,0.294320,0.040413,-1211.883545,0.004917,0.000000
11.990001,1.323036,-1211.883545,0.010641,0.000173,0.004405,5.885159,0.299804,0.044055,-1211.883545,0.005281,0.000000
12.210001,1.356552,-1211.838989,0.010645,0.000184,0.004666,6.034245,0.307399,0.046656,-1211.838989,0.005654,0.000000
12.430000,1.480179,-1211.927979,0.010684,0.000202,0.005134,6.584164,0.335413,0.051340,-1211.927979,0.006019,0.000000
12.650001,1.555023,-1211.927979,0.010710,0.000216,0.005481,6.917089,0.352373,0.054809,-1211.927979,0.006383,0.000000
12.870001,1.618698,-1211.883545,0.010727,0.000226,0.005741,7.200329,0.366802,0.057410,-1211.883545,0.006747,0.000000
13.090000,1.727432,-1211.883545,0.010749,0.000243,0.006183,7.684002,0.391442,0.061833,-1211.883545,0.007120,0.000000
13.310000,1.849945,-1211.927979,0.010740,0.000259,0.006591,8.228967,0.419204,0.065909,-1211.927979,0.007484,0.000000
13.530001,1.887924,-1211.972534,0.010800,0.000271,0.006877,8.397906,0.427810,0.068771,-1211.972534,0.007848,0.000000
13.750001,1.998520,-1211.972534,0.010800,0.000288,0.007311,8.889860,0.452871,0.073107,-1211.972534,0.008221,0.000000
13.970000,2.075226,-1211.927979,0.010770,0.000302,0.007675,9.231066,0.470253,0.076749,-1211.927979,0.008586,0.000000
14.190001,2.141510,-1211.883545,0.010843,0.000314,0.007970,9.525912,0.485273,0.079698,-1211.883545,0.008950,0.000000
14.410001,2.268120,-1211.883545,0.010805,0.000328,0.008334,10.089101,0.513963,0.083340,-1211.883545,0.009314,0.000000
14.630001,2.369774,-1211.972534,0.010800,0.000342,0.008690,10.541281,0.536998,0.086896,-1211.972534,0.009687,0.000000
14.850000,2.447975,-1212.016968,0.010835,0.000354,0.009002,10.889137,0.554719,0.090018,-1212.016968,0.010051,0.000000
15.070001,2.614426,-1211.927979,0.010831,0.000370,0.009401,11.629546,0.592437,0.094007,-1211.927979,0.010415,0.000000
15.290001,2.787575,-1211.883545,0.010925,0.000392,0.009947,12.399752,0.631673,0.099471,-1211.883545,0.010780,0.000000
15.510001,2.905617,-1211.927979,0.010843,0.000403,0.010242,12.924829,0.658422,0.102419,-1211.927979,0.011153,0.000000
15.730000,2.976372,-1212.016968,0.010891,0.000417,0.010580,13.239563,0.674455,0.105802,-1212.016968,0.011517,0.000000
15.950001,3.125694,-1211.927979,0.010930,0.000433,0.010988,13.903783,0.708292,0.109877,-1211.927979,0.011881,0.000000
16.170000,3.306664,-1211.972534,0.010968,0.000449,0.011404,14.708774,0.749301,0.114040,-1211.972534,0.012254,0.000000
16.390001,3.428802,-1211.927979,0.010934,0.000462,0.011734,15.252075,0.776978,0.117336,-1211.927979,0.012618,0.000000
16.610001,3.577011,-1211.927979,0.010951,0.000476,0.012089,15.911340,0.810562,0.120891,-1211.927979,0.012982,0.000000
16.830000,3.601959,-1212.016968,0.010960,0.000484,0.012289,16.022314,0.816216,0.122886,-1212.016968,0.013347,0.000000
17.050001,3.775856,-1211.972534,0.010981,0.000501,0.012722,16.795847,0.855621,0.127222,-1211.972534,0.013719,0.000000
17.270000,4.013054,-1211.927979,0.011007,0.000517,0.013121,17.850956,0.909371,0.131211,-1211.927979,0.014084,0.000000
17.490002,4.157539,-1211.927979,0.010968,0.000531,0.013477,18.493658,0.942112,0.134767,-1211.927979,0.014448,0.000000
17.710001,4.321381,-1211.972534,0.010994,0.000547,0.013884,19.222462,0.979239,0.138843,-1211.972534,0.014821,0.000000
17.930000,4.410004,-1212.016968,0.011081,0.000558,0.014162,19.616676,0.999321,0.141618,-1212.016968,0.015185,0.000000
18.150002,4.657631,-1211.927979,0.011025,0.000575,0.014604,20.718178,1.055434,0.146041,-1211.927979,0.015549,0.000000
18.370001,4.866531,-1211.972534,0.011089,0.000589,0.014968,21.647413,1.102772,0.149683,-1211.972534,0.015914,0.000000
18.590000,4.922020,-1211.927979,0.011072,0.000599,0.015211,21.894238,1.115346,0.152111,-1211.927979,0.016286,0.000000
18.810001,4.993515,-1211.972534,0.011115,0.000610,0.015506,22.212265,1.131547,0.155060,-1211.972534,0.016651,0.000000
19.030001,5.283218,-1211.972534,0.011085,0.000625,0.015888,23.500929,1.197194,0.158876,-1211.972534,0.017015,0.000000
19.250000,5.590050,-1211.972534,0.011141,0.000647,0.016425,24.865784,1.266723,0.164253,-1211.972534,0.017388,0.000000
19.470001,5.710701,-1211.972534,0.011137,0.000659,0.016746,25.402466,1.294063,0.167461,-1211.972534,0.017752,0.000000
19.690001,5.905823,-1211.927979,0.011132,0.000674,0.017128,26.270412,1.338279,0.171277,-1211.927979,0.018116,0.000000
19.910002,6.106537,-1212.016968,0.011124,0.000689,0.017509,27.163233,1.383761,0.175093,-1212.016968,0.018481,0.000000
20.130001,6.184731,-1212.016968,0.011167,0.000695,0.017665,27.511055,1.401480,0.176654,-1212.016968,0.018853,0.000000
20.350000,6.541840,-1212.016968,0.011163,0.000716,0.018186,29.099556,1.482402,0.181857,-1212.016968,0.019218,0.000000
20.570002,6.741798,-1211.972534,0.011206,0.000731,0.018567,29.989017,1.527713,0.185673,-1211.972534,0.019582,0.000000
20.790001,6.905273,-1212.016968,0.011266,0.000745,0.018932,30.716190,1.564757,0.189315,-1212.016968,0.019955,0.000000
21.010000,7.105980,-1212.061401,0.011232,0.000758,0.019261,31.608978,1.610238,0.192610,-1212.061401,0.020319,0.000000
21.230001,7.394196,-1212.016968,0.011244,0.000774,0.019660,32.891026,1.675549,0.196600,-1212.016968,0.020683,0.000000
21.450001,7.542030,-1212.061401,0.011305,0.000787,0.019990,33.548626,1.709049,0.199895,-1212.061401,0.021048,0.000000
21.670000,7.790771,-1211.972534,0.011266,0.000803,0.020397,34.655083,1.765414,0.203971,-1211.972534,0.021420,0.000000
21.890001,7.915894,-1211.972534,0.011313,0.000816,0.020735,35.211655,1.793767,0.207354,-1211.972534,0.021785,0.000000
22.110001,8.151230,-1212.016968,0.011279,0.000830,0.021082,36.258480,1.847095,0.210822,-1212.016968,0.022149,0.000000
22.330002,8.592865,-1212.016968,0.011344,0.000851,0.021620,38.222973,1.947171,0.216199,-1212.016968,0.022522,0.000000
22.550001,8.753731,-1212.061401,0.011352,0.000863,0.021932,38.938538,1.983624,0.219321,-1212.061401,0.022886,0.000000
22.770000,8.936195,-1211.972534,0.011326,0.000877,0.022270,39.750183,2.024971,0.222703,-1211.972534,0.023250,0.000000
22.990002,9.083282,-1211.927979,0.011331,0.000890,0.022600,40.404457,2.058301,0.225999,-1211.927979,0.023615,0.000000
23.210001,9.278404,-1212.016968,0.011378,0.000903,0.022938,41.272404,2.102517,0.229381,-1212.016968,0.023987,0.000000
23.430000,9.519699,-1212.016968,0.011361,0.000916,0.023276,42.345737,2.157195,0.232763,-1212.016968,0.024352,0.000000
23.650002,9.736420,-1212.016968,0.011378,0.000932,0.023667,43.309757,2.206304,0.236666,-1212.016968,0.024716,0.000000
23.870001,9.959473,-1211.972534,0.011426,0.000947,0.024048,44.301949,2.256849,0.240481,-1211.972534,0.025089,0.000000
24.090002,10.152733,-1211.972534,0.011378,0.000958,0.024334,45.161610,2.300642,0.243343,-1211.972534,0.025453,0.000000
24.310001,10.697517,-1212.016968,0.011417,0.000982,0.024933,47.584934,2.424092,0.249327,-1212.016968,0.025817,0.000000
24.530001,10.805504,-1212.105957,0.011460,0.000996,0.025288,48.065281,2.448562,0.252883,-1212.105957,0.026182,0.000000
24.750002,10.969345,-1212.061401,0.011447,0.001009,0.025626,48.794083,2.485689,0.256265,-1212.061401,0.026554,0.000000
24.970001,11.071007,-1211.972534,0.011447,0.001018,0.025861,49.246296,2.508726,0.258607,-1211.972534,0.026919,0.000000
25.190001,11.281769,-1211.972534,0.011499,0.001031,0.026182,50.183815,2.556485,0.261815,-1211.972534,0.027283,0.000000
25.410002,11.556206,-1212.061401,0.011495,0.001046,0.026580,51.404572,2.618674,0.265805,-1212.061401,0.027656,0.000000
25.630001,11.658981,-1212.061401,0.011469,0.001060,0.026927,51.861740,2.641963,0.269274,-1212.061401,0.028020,0.000000
25.850000,12.251793,-1212.061401,0.011533,0.001081,0.027448,54.498695,2.776296,0.274477,-1212.061401,0.028384,0.000000
26.070002,12.442078,-1211.972534,0.011538,0.001094,0.027786,55.345127,2.819415,0.277859,-1211.972534,0.028749,0.000000
26.290001,12.609650,-1212.016968,0.011538,0.001107,0.028115,56.090523,2.857387,0.281154,-1212.016968,0.029121,0.000000
26.510002,12.961914,-1212.061401,0.011611,0.001123,0.028523,57.657475,2.937212,0.285230,-1212.061401,0.029486,0.000000
26.730001,13.165970,-1212.016968,0.011594,0.001137,0.028887,58.565159,2.983451,0.288873,-1212.016968,0.029850,0.000000
26.950001,13.375244,-1212.016968,0.011607,0.001154,0.029312,59.496056,3.030874,0.293122,-1212.016968,0.030223,0.000000
27.170002,13.753204,-1212.016968,0.011585,0.001168,0.029676,61.177307,3.116521,0.296765,-1212.016968,0.030587,0.000000
27.390001,13.821716,-1212.061401,0.011628,0.001180,0.029963,61.482063,3.132046,0.299626,-1212.061401,0.030951,0.000000
27.610001,14.039932,-1212.016968,0.011589,0.001193,0.030310,62.452736,3.181494,0.303095,-1212.016968,0.031316,0.000000
27.830002,14.181801,-1212.105957,0.011641,0.001202,0.030535,63.083801,3.213642,0.305350,-1212.105957,0.031688,0.000000
28.050001,14.616364,-1212.016968,0.011701,0.001221,0.031012,65.016830,3.312115,0.310120,-1212.016968,0.032053,0.000000
28.270000,14.724350,-1212.016968,0.011706,0.001232,0.031298,65.497177,3.336585,0.312981,-1212.016968,0.032417,0.000000
28.490002,15.040497,-1212.061401,0.011658,0.001246,0.031636,66.903473,3.408225,0.316364,-1212.061401,0.032781,0.000000
28.710001,15.421806,-1212.061401,0.011701,0.001263,0.032079,68.599617,3.494631,0.320786,-1212.061401,0.033154,0.000000
28.930002,15.627724,-1212.105957,0.011732,0.001275,0.032374,69.515587,3.541293,0.323735,-1212.105957,0.033518,0.000000
29.150002,15.991158,-1212.016968,0.011732,0.001294,0.032868,71.132225,3.623648,0.328678,-1212.016968,0.033882,0.000000
29.370001,16.129684,-1211.972534,0.011740,0.001307,0.033197,71.748421,3.655039,0.331974,-1211.972534,0.034255,0.000000
29.590002,16.420876,-1212.061401,0.011732,0.001321,0.033553,73.043701,3.721024,0.335530,-1212.061401,0.034620,0.000000
29.810001,16.651749,-1212.105957,0.011779,0.001334,0.033874,74.070679,3.773340,0.338738,-1212.105957,0.034984,0.000000
30.030001,17.030449,-1212.061401,0.011753,0.001349,0.034264,75.755219,3.859155,0.342641,-1212.061401,0.035348,0.000000
30.250002,17.196899,-1212.016968,0.011822,0.001363,0.034611,76.495628,3.896873,0.346110,-1212.016968,0.035721,0.000000
30.470001,17.454208,-1212.016968,0.011831,0.001378,0.034993,77.640198,3.955180,0.349925,-1212.016968,0.036085,0.000000
30.690001,17.845200,-1212.061401,0.011788,0.001393,0.035383,79.379410,4.043780,0.353828,-1212.061401,0.036449,0.000000
30.910002,17.883186,-1212.150391,0.011839,0.001402,0.035608,79.548386,4.052388,0.356083,-1212.150391,0.036822,0.000000
31.130001,18.502441,-1212.016968,0.011848,0.001424,0.036172,82.302971,4.192713,0.361720,-1212.016968,0.037187,0.000000
31.350002,18.625694,-1212.061401,0.011857,0.001437,0.036502,82.851227,4.220643,0.365015,-1212.061401,0.037551,0.000000
31.570002,18.924339,-1212.061401,0.011891,0.001451,0.036866,84.179665,4.288317,0.368657,-1212.061401,0.037915,0.000000
31.790001,19.080734,-1212.105957,0.011878,0.001464,0.037178,84.875343,4.323756,0.371779,-1212.105957,0.038288,0.000000
32.010002,19.403580,-1212.061401,0.011904,0.001479,0.037560,86.311432,4.396914,0.375595,-1212.061401,0.038652,0.000000
32.230003,19.599075,-1212.061401,0.011887,0.001493,0.037915,87.181038,4.441214,0.379151,-1212.061401,0.039016,0.000000
32.450001,19.620674,-1212.061401,0.011934,0.001498,0.038054,87.277115,4.446108,0.380539,-1212.061401,0.039389,0.000000
32.670002,20.445480,-1212.016968,0.011930,0.001523,0.038696,90.946037,4.633012,0.386956,-1212.016968,0.039754,0.000000
32.890003,21.024895,-1212.105957,0.011973,0.001548,0.039320,93.523399,4.764309,0.393200,-1212.105957,0.040118,0.000000
33.110001,21.083351,-1212.061401,0.011995,0.001558,0.039580,93.783432,4.777555,0.395802,-1212.061401,0.040482,0.000000
33.330002,21.240868,-1212.150391,0.011947,0.001574,0.039979,94.484100,4.813250,0.399791,-1212.150391,0.040855,0.000000
33.550003,21.239380,-1212.016968,0.011969,0.001583,0.040196,94.477478,4.812912,0.401959,-1212.016968,0.041219,0.000000
33.770000,21.727188,-1212.105957,0.011995,0.001603,0.040716,96.647362,4.923451,0.407162,-1212.105957,0.041583,0.000000
33.990002,21.934227,-1212.105957,0.012016,0.001615,0.041028,97.568314,4.970367,0.410285,-1212.105957,0.041956,0.000000
34.210003,22.046684,-1212.150391,0.012012,0.001626,0.041297,98.068550,4.995850,0.412973,-1212.150391,0.042321,0.000000
34.430000,22.500229,-1212.061401,0.012042,0.001643,0.041740,100.086014,5.098625,0.417395,-1212.061401,0.042685,0.000000
34.650002,22.831642,-1212.061401,0.012077,0.001659,0.042138,101.560219,5.173724,0.421385,-1212.061401,0.043049,0.000000
34.870003,23.081505,-1212.061401,0.012081,0.001674,0.042529,102.671661,5.230343,0.425287,-1212.061401,0.043422,0.000000
35.090000,23.299713,-1212.105957,0.012042,0.001690,0.042919,103.642303,5.279790,0.429190,-1212.105957,0.043786,0.000000
35.310001,23.449783,-1212.105957,0.012072,0.001702,0.043231,104.309845,5.313797,0.432312,-1212.105957,0.044150,0.000000
35.530003,23.583092,-1212.061401,0.012150,0.001715,0.043552,104.902832,5.344005,0.435521,-1212.061401,0.044523,0.000000
35.750000,23.872421,-1212.105957,0.012102,0.001729,0.043916,106.189835,5.409568,0.439163,-1212.105957,0.044888,0.000000
35.970001,24.127869,-1212.061401,0.012111,0.001743,0.044272,107.326118,5.467453,0.442719,-1212.061401,0.045252,0.000000
36.190002,24.235489,-1212.150391,0.012098,0.001753,0.044523,107.804840,5.491840,0.445234,-1212.150391,0.045616,0.000000
36.410000,24.641747,-1212.150391,0.012189,0.001770,0.044948,109.611961,5.583899,0.449483,-1212.150391,0.045989,0.000000
36.630001,24.758301,-1212.061401,0.012146,0.001779,0.045191,110.130424,5.610312,0.451911,-1212.061401,0.046353,0.000000
36.850002,25.417397,-1212.105957,0.012180,0.001802,0.045763,113.062225,5.759665,0.457635,-1212.105957,0.046717,0.000000
37.070004,25.576027,-1212.061401,0.012158,0.001817,0.046154,113.767853,5.795610,0.461537,-1212.061401,0.047090,0.000000
37.290001,25.839294,-1212.150391,0.012197,0.001833,0.046561,114.938919,5.855268,0.465614,-1212.150391,0.047455,0.000000
37.510002,26.168098,-1212.061401,0.012227,0.001848,0.046943,116.401512,5.929776,0.469429,-1212.061401,0.047819,0.000000
37.730003,26.337532,-1212.061401,0.012266,0.001861,0.047264,117.155197,5.968170,0.472638,-1212.061401,0.048183,0.000000
37.950001,26.575104,-1212.105957,0.012219,0.001875,0.047619,118.211967,6.022005,0.476193,-1212.105957,0.048556,0.000000
38.170002,26.467857,-1212.105957,0.012279,0.001883,0.047819,117.734909,5.997702,0.478188,-1212.105957,0.048920,0.000000
38.390003,26.771713,-1212.150391,0.012240,0.001900,0.048261,119.086525,6.066557,0.482611,-1212.150391,0.049284,0.000000
38.610001,27.271065,-1212.105957,0.012292,0.001914,0.048625,121.307755,6.179712,0.486253,-1212.105957,0.049657,0.000000
38.830002,27.472519,-1212.061401,0.012288,0.001929,0.049007,122.203865,6.225362,0.490069,-1212.061401,0.050022,0.000000
39.050003,27.892555,-1212.105957,0.012292,0.001945,0.049406,124.072281,6.320543,0.494058,-1212.105957,0.050386,0.000000
39.270000,27.914902,-1212.061401,0.012301,0.001957,0.049709,124.171684,6.325607,0.497093,-1212.061401,0.050750,0.000000
39.490002,28.311852,-1212.150391,0.012327,0.001974,0.050134,125.937408,6.415557,0.501343,-1212.150391,0.051123,0.000000
39.710003,28.638794,-1212.150391,0.012357,0.001987,0.050481,127.391716,6.489644,0.504812,-1212.150391,0.051487,0.000000
39.930000,28.648842,-1212.105957,0.012378,0.001997,0.050733,127.436417,6.491920,0.507327,-1212.105957,0.051851,0.000000
40.150002,28.799286,-1212.061401,0.012357,0.002011,0.051080,128.105621,6.526011,0.510796,-1212.061401,0.052224,0.000000
40.370003,29.110214,-1212.105957,0.012404,0.002024,0.051409,129.488693,6.596469,0.514091,-1212.105957,0.052589,0.000000
40.590000,29.870598,-1212.194824,0.012439,0.002045,0.051955,132.871048,6.768774,0.519555,-1212.194824,0.052953,0.000000
40.810001,29.908211,-1212.150391,0.012478,0.002057,0.052250,133.038361,6.777297,0.522503,-1212.150391,0.053317,0.000000
41.030003,30.265686,-1212.061401,0.012456,0.002073,0.052667,134.628494,6.858303,0.526666,-1212.061401,0.053690,0.000000
41.250004,30.632103,-1212.061401,0.012443,0.002089,0.053057,136.258392,6.941334,0.530568,-1212.061401,0.054054,0.000000
41.470001,30.447403,-1212.150391,0.012456,0.002094,0.053196,135.436813,6.899480,0.531956,-1212.150391,0.054418,0.000000
41.690002,31.134056,-1212.105957,0.012486,0.002117,0.053768,138.491196,7.055078,0.537680,-1212.105957,0.054783,0.000000
41.910004,31.375732,-1212.150391,0.012490,0.002131,0.054124,139.566223,7.109843,0.541235,-1212.150391,0.055156,0.000000
42.130001,31.523560,-1212.016968,0.012503,0.002144,0.054462,140.223801,7.143341,0.544618,-1212.016968,0.055520,0.000000
42.350002,31.849388,-1212.150391,0.012499,0.002159,0.054835,141.673157,7.217175,0.548347,-1212.150391,0.055884,0.000000
42.570004,32.254898,-1212.105957,0.012538,0.002174,0.055208,143.476959,7.309064,0.552076,-1212.105957,0.056257,0.000000
42.790001,32.390816,-1212.150391,0.012525,0.002184,0.055476,144.081543,7.339864,0.554764,-1212.150391,0.056621,0.000000
43.010002,32.834686,-1212.061401,0.012525,0.002202,0.055927,146.055984,7.440446,0.559274,-1212.061401,0.056985,0.000000
43.230003,32.971344,-1212.105957,0.012538,0.002216,0.056292,146.663864,7.471413,0.562916,-1212.105957,0.057350,0.000000
43.450001,33.277809,-1212.150391,0.012594,0.002229,0.056612,148.027084,7.540859,0.566125,-1212.150391,0.057723,0.000000
43.670002,34.142456,-1212.150391,0.012590,0.002251,0.057185,151.873230,7.736791,0.571848,-1212.150391,0.058087,0.000000
43.890003,34.212837,-1212.150391,0.012641,0.002262,0.057462,152.186295,7.752739,0.574624,-1212.150391,0.058451,0.000000
44.110001,34.373703,-1212.194824,0.012646,0.002275,0.057792,152.901871,7.789193,0.577919,-1212.194824,0.058824,0.000000
44.330002,34.553925,-1212.105957,0.012641,0.002288,0.058121,153.703537,7.830031,0.581215,-1212.105957,0.059188,0.000000
44.550003,34.926674,-1212.105957,0.012637,0.002304,0.058529,155.361603,7.914497,0.585290,-1212.105957,0.059552,0.000000
44.770000,35.176910,-1212.194824,0.012663,0.002315,0.058807,156.474716,7.971202,0.588066,-1212.194824,0.059917,0.000000
44.990002,35.426765,-1212.150391,0.012663,0.002329,0.059145,157.586121,8.027820,0.591448,-1212.150391,0.060289,0.000000
45.210003,35.182121,-1212.150391,0.012715,0.002333,0.059257,156.497894,7.972383,0.592575,-1212.150391,0.060654,0.000000
45.430000,36.028526,-1212.105957,0.012659,0.002355,0.059821,160.262894,8.164181,0.598212,-1212.105957,0.061018,0.000000
45.650002,37.038399,-1212.150391,0.012697,0.002380,0.060463,164.755020,8.393022,0.604629,-1212.150391,0.061391,0.000000
45.870003,37.284538,-1212.194824,0.012736,0.002394,0.060819,165.849915,8.448797,0.608185,-1212.194824,0.061755,0.000000
46.090004,37.531792,-1212.150391,0.012719,0.002408,0.061174,166.949753,8.504826,0.611741,-1212.150391,0.062119,0.000000
46.310001,37.556366,-1212.150391,0.012784,0.002417,0.061382,167.059067,8.510394,0.613822,-1212.150391,0.062484,0.000000
46.530003,37.817772,-1212.239380,0.012753,0.002429,0.061703,168.221848,8.569630,0.617031,-1212.239380,0.062857,0.000000
46.750004,38.238922,-1212.194824,0.012771,0.002446,0.062137,170.095215,8.665063,0.621367,-1212.194824,0.063221,0.000000
46.970001,38.283241,-1212.194824,0.012758,0.002456,0.062380,170.292358,8.675107,0.623795,-1212.194824,0.063585,0.000000
47.190002,39.406685,-1212.194824,0.012797,0.002479,0.062969,175.289688,8.929683,0.629692,-1212.194824,0.063958,0.000000
47.410004,39.667717,-1212.105957,0.012818,0.002493,0.063325,176.450821,8.988833,0.633248,-1212.105957,0.064322,0.000000
47.630001,39.939552,-1212.150391,0.012853,0.002506,0.063654,177.660004,9.050432,0.636544,-1212.150391,0.064686,0.000000
47.850002,40.403152,-1212.150391,0.012874,0.002522,0.064062,179.722198,9.155485,0.640620,-1212.150391,0.065051,0.000000
48.070004,40.707756,-1212.150391,0.012835,0.002536,0.064409,181.077148,9.224509,0.644088,-1212.150391,0.065423,0.000000
48.290001,40.957619,-1212.239380,0.012835,0.002553,0.064834,182.188583,9.281129,0.648338,-1212.239380,0.065788,0.000000
48.510002,41.624161,-1212.150391,0.012887,0.002567,0.065198,185.153519,9.432169,0.651980,-1212.150391,0.066152,0.000000
48.730003,41.696777,-1212.150391,0.012913,0.002578,0.065476,185.476532,9.448625,0.654755,-1212.150391,0.066525,0.000000
48.950001,42.076965,-1212.150391,0.012883,0.002592,0.065831,187.167694,9.534776,0.658311,-1212.150391,0.066889,0.000000
49.170002,42.096329,-1212.239380,0.012904,0.002601,0.066074,187.253830,9.539165,0.660739,-1212.239380,0.067253,0.000000
49.390003,42.909966,-1212.239380,0.012935,0.002621,0.066568,190.873062,9.723537,0.665682,-1212.239380,0.067618,0.000000
49.610001,42.658615,-1212.150391,0.012913,0.002624,0.066638,189.754990,9.666580,0.666376,-1212.150391,0.067990,0.000000
49.830002,43.679291,-1212.150391,0.012930,0.002649,0.067279,194.295197,9.897869,0.672793,-1212.150391,0.068355,0.000000
50.050003,44.104912,-1212.194824,0.012956,0.002661,0.067592,196.188446,9.994316,0.675916,-1212.194824,0.068719,0.000000
50.270004,44.472816,-1212.239380,0.012952,0.002674,0.067921,197.824966,10.077684,0.679211,-1212.239380,0.069092,0.000000
50.490002,45.127075,-1212.194824,0.013008,0.002693,0.068398,200.735260,10.225941,0.683981,-1212.194824,0.069456,0.000000
50.710003,45.416031,-1212.194824,0.013034,0.002706,0.068745,202.020599,10.291420,0.687450,-1212.194824,0.069820,0.000000
50.930004,45.828247,-1212.150391,0.012973,0.002719,0.069075,203.854218,10.384829,0.690745,-1212.150391,0.070185,0.000000
51.150002,46.182747,-1212.239380,0.012978,0.002732,0.069395,205.431122,10.465160,0.693954,-1212.239380,0.070557,0.000000
51.370003,46.834770,-1212.239380,0.013016,0.002747,0.069786,208.331467,10.612910,0.697857,-1212.239380,0.070922,0.000000
51.590004,47.131180,-1212.239380,0.013021,0.002761,0.070124,209.649963,10.680078,0.701238,-1212.239380,0.071286,0.000000
51.810001,47.612656,-1212.239380,0.013064,0.002778,0.070549,211.791672,10.789183,0.705488,-1212.239380,0.071659,0.000000
52.030003,48.120201,-1212.150391,0.013038,0.002791,0.070887,214.049347,10.904194,0.708870,-1212.150391,0.072023,0.000000
52.250004,48.791962,-1212.328369,0.013094,0.002808,0.071312,217.037491,11.056417,0.713120,-1212.328369,0.072387,0.000000
52.470001,49.218697,-1212.194824,0.013103,0.002821,0.071650,218.935699,11.153116,0.716502,-1212.194824,0.072752,0.000000
52.690002,49.496117,-1212.194824,0.013120,0.002835,0.071997,220.169724,11.215981,0.719971,-1212.194824,0.073124,0.000000
52.910004,49.996956,-1212.239380,0.013081,0.002849,0.072370,222.397568,11.329473,0.723700,-1212.239380,0.073489,0.000000
53.130001,50.336189,-1212.194824,0.013090,0.002862,0.072691,223.906555,11.406343,0.726908,-1212.194824,0.073853,0.000000
53.350002,51.015770,-1212.239380,0.013137,0.002877,0.073081,226.929474,11.560339,0.730811,-1212.239380,0.074226,0.000000
53.570004,51.175514,-1212.328369,0.013111,0.002889,0.073393,227.640060,11.596538,0.733933,-1212.328369,0.074590,0.000000
53.790001,51.390007,-1212.194824,0.013163,0.002897,0.073575,228.594162,11.645142,0.735754,-1212.194824,0.074954,0.000000
54.010002,52.678787,-1212.194824,0.013146,0.002922,0.074208,234.326950,11.937183,0.742085,-1212.194824,0.075319,0.000000
54.230003,53.907616,-1212.239380,0.013210,0.002946,0.074824,239.793045,12.215640,0.748242,-1212.239380,0.075691,0.000000
54.450001,54.088585,-1212.239380,0.013180,0.002955,0.075058,240.598038,12.256649,0.750583,-1212.239380,0.076056,0.000000
54.670002,54.531708,-1212.239380,0.013206,0.002970,0.075449,242.569153,12.357061,0.754486,-1212.239380,0.076420,0.000000
54.890003,54.736145,-1212.194824,0.013215,0.002981,0.075709,243.478531,12.403387,0.757088,-1212.194824,0.076784,0.000000
55.110004,55.399712,-1212.194824,0.013180,0.002999,0.076177,246.430222,12.553754,0.761771,-1212.194824,0.077157,0.000000
55.330002,55.820488,-1212.194824,0.013206,0.003012,0.076507,248.301926,12.649104,0.765066,-1212.194824,0.077521,0.000000
55.550003,56.287071,-1212.283813,0.013245,0.003024,0.076819,250.377396,12.754833,0.768188,-1212.283813,0.077886,0.000000
55.770004,56.831108,-1212.283813,0.013254,0.003040,0.077226,252.797394,12.878113,0.772264,-1212.283813,0.078258,0.000000
55.990002,57.781776,-1212.194824,0.013228,0.003056,0.077634,257.026184,13.093537,0.776340,-1212.194824,0.078623,0.000000
56.210003,58.317619,-1212.194824,0.013245,0.003072,0.078024,259.409729,13.214961,0.780243,-1212.194824,0.078987,0.000000
56.430004,58.948051,-1212.283813,0.013262,0.003087,0.078397,262.214020,13.357819,0.783972,-1212.283813,0.079351,0.000000
56.650002,59.441071,-1212.283813,0.013279,0.003099,0.078727,264.407074,13.469539,0.787267,-1212.283813,0.079724,0.000000
56.870003,59.741203,-1212.239380,0.013336,0.003111,0.079030,265.742157,13.537550,0.790303,-1212.239380,0.080088,0.000000
57.090004,60.456528,-1212.239380,0.013305,0.003126,0.079395,268.924072,13.699645,0.793945,-1212.239380,0.080453,0.000000
57.310001,61.036316,-1212.194824,0.013344,0.003140,0.079767,271.503082,13.831027,0.797674,-1212.194824,0.080825,0.000000
57.530003,61.114136,-1212.239380,0.013305,0.003146,0.079915,271.849243,13.848660,0.799148,-1212.239380,0.081190,0.000000
57.750004,62.224182,-1212.239380,0.013323,0.003167,0.080444,276.786987,14.100201,0.804438,-1212.239380,0.081554,0.000000
57.970001,63.337570,-1212.283813,0.013366,0.003188,0.080973,281.739594,14.352498,0.809729,-1212.283813,0.081918,0.000000
58.190002,64.086044,-1212.239380,0.013405,0.003200,0.081285,285.068970,14.522105,0.812851,-1212.239380,0.082291,0.000000
58.410004,64.520981,-1212.239380,0.013366,0.003214,0.081632,287.003662,14.620664,0.816320,-1212.239380,0.082655,0.000000
58.630001,65.206879,-1212.239380,0.013357,0.003229,0.082005,290.054687,14.776090,0.820049,-1212.239380,0.083019,0.000000
58.850002,66.067810,-1212.239380,0.013426,0.003245,0.082430,293.884308,14.971180,0.824298,-1212.239380,0.083392,0.000000
59.070004,66.783142,-1212.239380,0.013430,0.003259,0.082777,297.066254,15.133276,0.827767,-1212.239380,0.083757,0.000000
59.290001,67.397919,-1212.194824,0.013392,0.003273,0.083132,299.800903,15.272587,0.831322,-1212.194824,0.084121,0.000000
59.510002,67.313400,-1212.239380,0.013426,0.003272,0.083106,299.424957,15.253434,0.831062,-1212.239380,0.083288,0.000000
59.730003,66.659134,-1212.239380,0.013473,0.003271,0.083080,296.514648,15.105176,0.830802,-1212.239380,0.083288,0.000000
59.950005,66.097595,-1212.328369,0.013456,0.003271,0.083080,294.016785,14.977929,0.830802,-1212.328369,0.083080,0.000000
60.170002,65.626923,-1212.239380,0.013422,0.003271,0.083072,291.923126,14.871273,0.830715,-1212.239380,0.083080,0.000000
60.390003,65.225128,-1212.150391,0.013469,0.003270,0.083063,290.135864,14.780226,0.830629,-1212.150391,0.083080,0.000000
60.610004,64.843079,-1212.194824,0.013452,0.003270,0.083063,288.436432,14.693652,0.830629,-1212.194824,0.083080,0.000000
60.830002,64.527679,-1212.283813,0.013422,0.003270,0.083054,287.033447,14.622181,0.830542,-1212.283813,0.083080,0.000000
61.050003,64.224564,-1212.283813,0.013439,0.003270,0.083054,285.685120,14.553494,0.830542,-1212.283813,0.083080,0.000000
61.270004,63.960556,-1212.239380,0.013435,0.003270,0.083054,284.510773,14.493670,0.830542,-1212.239380,0.083080,0.000000
61.490002,63.711807,-1212.239380,0.013491,0.003270,0.083054,283.404266,14.437303,0.830542,-1212.239380,0.083080,0.000000
61.710003,63.493973,-1212.283813,0.013473,0.003270,0.083046,282.435303,14.387940,0.830455,-1212.283813,0.083080,0.000000
61.930004,63.269058,-1212.283813,0.013430,0.003270,0.083046,281.434814,14.336973,0.830455,-1212.283813,0.083080,0.000000
62.150002,63.064255,-1212.283813,0.013473,0.003270,0.083046,280.523804,14.290565,0.830455,-1212.283813,0.083080,0.000000
62.370003,62.889984,-1212.239380,0.013443,0.003270,0.083046,279.748627,14.251074,0.830455,-1212.239380,0.083080,0.000000
62.590004,62.727997,-1212.239380,0.013499,0.003270,0.083046,279.028076,14.214368,0.830455,-1212.239380,0.083080,0.000000
62.810001,62.561546,-1212.283813,0.013499,0.003270,0.083046,278.287659,14.176649,0.830455,-1212.283813,0.083080,0.000000
63.030003,62.403290,-1212.328369,0.013491,0.003270,0.083046,277.583710,14.140788,0.830455,-1212.328369,0.083080,0.000000
63.250004,62.256950,-1212.283813,0.013465,0.003270,0.083046,276.932739,14.107627,0.830455,-1212.283813,0.083080,0.000000
63.470001,62.107254,-1212.283813,0.013495,0.003270,0.083046,276.266876,14.073705,0.830455,-1212.283813,0.083080,0.000000
63.690002,61.982880,-1212.239380,0.013478,0.003270,0.083046,275.713623,14.045522,0.830455,-1212.239380,0.083080,0.000000
63.910004,61.851807,-1212.283813,0.013456,0.003269,0.083037,275.130585,14.015820,0.830369,-1212.283813,0.083080,0.000000
64.130005,61.745682,-1212.283813,0.013452,0.003269,0.083037,274.658508,13.991772,0.830369,-1212.283813,0.083080,0.000000
64.350006,61.618706,-1212.372803,0.013469,0.003269,0.083037,274.093689,13.962998,0.830369,-1212.372803,0.083080,0.000000
64.570000,61.515556,-1212.283813,0.013499,0.003269,0.083037,273.634857,13.939625,0.830369,-1212.283813,0.083080,0.000000
64.790001,61.417992,-1212.239380,0.013486,0.003269,0.083037,273.200867,13.917516,0.830369,-1212.239380,0.083080,0.000000
65.010002,61.323036,-1212.239380,0.013491,0.003269,0.083037,272.778503,13.895998,0.830369,-1212.239380,0.083080,0.000000
65.230003,61.219147,-1212.239380,0.013486,0.003269,0.083037,272.316376,13.872458,0.830369,-1212.239380,0.083080,0.000000
65.450005,61.132385,-1212.283813,0.013461,0.003269,0.083037,271.930420,13.852797,0.830369,-1212.283813,0.083080,0.000000
65.670006,61.035568,-1212.283813,0.013469,0.003269,0.083037,271.499756,13.830857,0.830369,-1212.283813,0.083080,0.000000
65.889999,60.944710,-1212.283813,0.013461,0.003269,0.083037,271.095612,13.810269,0.830369,-1212.283813,0.083080,0.000000
66.110001,60.864647,-1212.239380,0.013495,0.003269,0.083037,270.739471,13.792126,0.830369,-1212.239380,0.083080,0.000000
66.330002,60.779007,-1212.283813,0.013456,0.003269,0.083037,270.358521,13.772719,0.830369,-1212.283813,0.083080,0.000000
66.550003,60.716820,-1212.239380,0.013452,0.003269,0.083037,270.081909,13.758628,0.830369,-1212.239380,0.083080,0.000000
66.770004,60.625587,-1212.194824,0.013482,0.003269,0.083037,269.676086,13.737955,0.830369,-1212.194824,0.083080,0.000000
66.990005,60.554466,-1212.239380,0.013504,0.003269,0.083037,269.359711,13.721838,0.830369,-1212.239380,0.083080,0.000000
67.210007,60.474777,-1212.328369,0.013465,0.003269,0.083037,269.005249,13.703780,0.830369,-1212.328369,0.083080,0.000000
67.430000,60.414078,-1212.283813,0.013461,0.003269,0.083037,268.735229,13.690025,0.830369,-1212.283813,0.083080,0.000000
67.650002,60.341095,-1212.283813,0.013486,0.003269,0.083037,268.410583,13.673488,0.830369,-1212.283813,0.083080,0.000000
67.870003,60.292686,-1212.239380,0.013478,0.003269,0.083037,268.195251,13.662518,0.830369,-1212.239380,0.083080,0.000000
68.090004,60.212624,-1212.239380,0.013469,0.003269,0.083037,267.839142,13.644376,0.830369,-1212.239380,0.083080,0.000000
68.310005,60.151924,-1212.283813,0.013452,0.003269,0.083037,267.569122,13.630621,0.830369,-1212.283813,0.083080,0.000000
68.530006,60.100914,-1212.283813,0.013517,0.003269,0.083037,267.342224,13.619062,0.830369,-1212.283813,0.083080,0.000000
68.750000,60.024948,-1212.283813,0.013508,0.003269,0.083037,267.004303,13.601848,0.830369,-1212.283813,0.083080,0.000000
68.970001,59.969841,-1212.239380,0.013508,0.003269,0.083037,266.759186,13.589360,0.830369,-1212.239380,0.083080,0.000000
69.190002,59.893875,-1212.239380,0.013486,0.003269,0.083037,266.421265,13.572145,0.830369,-1212.239380,0.083080,0.000000
69.410004,59.856636,-1212.283813,0.013525,0.003269,0.083037,266.255615,13.563707,0.830369,-1212.283813,0.083080,0.000000
69.630005,59.805618,-1212.283813,0.013504,0.003269,0.083037,266.028687,13.552147,0.830369,-1212.283813,0.083080,0.000000
69.850006,59.752747,-1212.283813,0.013478,0.003269,0.083037,265.793488,13.540166,0.830369,-1212.283813,0.083080,0.000000
70.070000,59.702103,-1212.239380,0.013504,0.003269,0.083037,265.568207,13.528690,0.830369,-1212.239380,0.083080,0.000000
70.290001,59.645500,-1212.239380,0.013491,0.003269,0.083037,265.316437,13.515863,0.830369,-1212.239380,0.083080,0.000000
70.510002,59.595230,-1212.328369,0.013452,0.003269,0.083037,265.092834,13.504472,0.830369,-1212.328369,0.083080,0.000000
70.730003,59.547943,-1212.283813,0.013517,0.003269,0.083037,264.882477,13.493756,0.830369,-1212.283813,0.083080,0.000000
70.950005,59.498039,-1212.239380,0.013482,0.003269,0.083028,264.660492,13.482449,0.830281,-1212.239380,0.083080,0.000000
71.170006,59.441811,-1212.239380,0.013439,0.003269,0.083028,264.410370,13.469707,0.830281,-1212.239380,0.083080,0.000000
71.390007,59.410538,-1212.239380,0.013508,0.003269,0.083028,264.271271,13.462620,0.830281,-1212.239380,0.083080,0.000000
71.610001,59.351326,-1212.239380,0.013478,0.003269,0.083028,264.007874,13.449203,0.830281,-1212.239380,0.083080,0.000000
71.830002,59.313347,-1212.328369,0.013499,0.003269,0.083028,263.838959,13.440597,0.830281,-1212.328369,0.083080,0.000000
72.050003,59.270523,-1212.283813,0.013473,0.003269,0.083028,263.648468,13.430892,0.830281,-1212.283813,0.083080,0.000000
72.270004,59.242592,-1212.194824,0.013508,0.003269,0.083028,263.524200,13.424563,0.830281,-1212.194824,0.083080,0.000000
72.490005,59.183388,-1212.239380,0.013491,0.003269,0.083028,263.260864,13.411147,0.830281,-1212.239380,0.083080,0.000000
72.710007,59.145409,-1212.283813,0.013486,0.003269,0.083028,263.091919,13.402541,0.830281,-1212.283813,0.083080,0.000000
72.930000,59.115242,-1212.283813,0.013456,0.003269,0.083028,262.957733,13.395705,0.830281,-1212.283813,0.083080,0.000000
73.150002,59.069069,-1212.283813,0.013512,0.003269,0.083028,262.752350,13.385242,0.830281,-1212.283813,0.083080,0.000000
73.370003,59.041138,-1212.194824,0.013491,0.003269,0.083028,262.628082,13.378913,0.830281,-1212.194824,0.083080,0.000000
73.590004,58.989754,-1212.239380,0.013469,0.003269,0.083028,262.399536,13.367269,0.830281,-1212.239380,0.083080,0.000000
73.810005,58.961082,-1212.283813,0.013461,0.003269,0.083028,262.272003,13.360772,0.830281,-1212.283813,0.083080,0.000000
74.030006,58.918259,-1212.239380,0.013478,0.003269,0.083028,262.081512,13.351068,0.830281,-1212.239380,0.083080,0.000000
74.250000,58.888840,-1212.239380,0.013508,0.003269,0.083028,261.950653,13.344402,0.830281,-1212.239380,0.083080,0.000000
74.470001,58.845642,-1212.239380,0.013512,0.003269,0.083028,261.758484,13.334613,0.830281,-1212.239380,0.083080,0.000000
74.690002,58.813995,-1212.239380,0.013504,0.003269,0.083028,261.617706,13.327442,0.830281,-1212.239380,0.083080,0.000000
74.910004,58.779732,-1212.328369,0.013504,0.003269,0.083028,261.465302,13.319678,0.830281,-1212.328369,0.083080,0.000000
75.130005,58.743240,-1212.328369,0.013482,0.003269,0.083028,261.302979,13.311408,0.830281,-1212.328369,0.083080,0.000000
75.350006,58.719040,-1212.328369,0.013508,0.003269,0.083028,261.195343,13.305925,0.830281,-1212.328369,0.083080,0.000000
75.570007,58.661324,-1212.239380,0.013478,0.003269,0.083028,260.938599,13.292846,0.830281,-1212.239380,0.083080,0.000000
75.790001,58.642326,-1212.283813,0.013482,0.003269,0.083028,260.854095,13.288541,0.830281,-1212.283813,0.083080,0.000000
76.010002,58.607330,-1212.283813,0.013491,0.003269,0.083028,260.698425,13.280611,0.830281,-1212.283813,0.083080,0.000000
76.230003,58.579773,-1212.372803,0.013499,0.003269,0.083028,260.575836,13.274366,0.830281,-1212.372803,0.083080,0.000000
76.450005,58.555191,-1212.283813,0.013473,0.003269,0.083028,260.466492,13.268796,0.830281,-1212.283813,0.083080,0.000000
76.670006,58.535461,-1212.239380,0.013525,0.003269,0.083028,260.378723,13.264325,0.830281,-1212.239380,0.083080,0.000000
76.890007,58.500084,-1212.283813,0.013525,0.003269,0.083028,260.221375,13.256309,0.830281,-1212.283813,0.083080,0.000000
77.110001,58.445343,-1212.283813,0.013482,0.003269,0.083028,259.977875,13.243904,0.830281,-1212.283813,0.083080,0.000000
77.330002,58.428215,-1212.239380,0.013478,0.003269,0.083028,259.901672,13.240023,0.830281,-1212.239380,0.083080,0.000000
77.550003,58.399918,-1212.283813,0.013465,0.003269,0.083028,259.775818,13.233610,0.830281,-1212.283813,0.083080,0.000000
77.770004,58.383904,-1212.283813,0.013521,0.003269,0.083028,259.704559,13.229981,0.830281,-1212.283813,0.083080,0.000000
77.990005,58.352249,-1212.239380,0.013465,0.003269,0.083028,259.563782,13.222809,0.830281,-1212.239380,0.083080,0.000000
78.210007,58.307198,-1212.328369,0.013473,0.003269,0.083028,259.363373,13.212600,0.830281,-1212.328369,0.083080,0.000000
78.430000,58.281502,-1212.328369,0.013512,0.003269,0.083028,259.249054,13.206777,0.830281,-1212.328369,0.083080,0.000000
78.650002,58.259903,-1212.239380,0.013491,0.003269,0.083028,259.152985,13.201883,0.830281,-1212.239380,0.083080,0.000000
78.870003,58.229370,-1212.239380,0.013486,0.003269,0.083028,259.017181,13.194964,0.830281,-1212.239380,0.083080,0.000000
79.090004,58.207397,-1212.239380,0.013525,0.003269,0.083028,258.919434,13.189984,0.830281,-1212.239380,0.083080,0.000000
79.310005,58.184685,-1212.328369,0.013538,0.003269,0.083028,258.818390,13.184838,0.830281,-1212.328369,0.083080,0.000000
79.530006,58.156754,-1212.283813,0.013499,0.003269,0.083028,258.694153,13.178509,0.830281,-1212.283813,0.083080,0.000000
79.750000,58.135529,-1212.283813,0.013504,0.003269,0.083028,258.599731,13.173699,0.830281,-1212.283813,0.083080,0.000000
79.970001,58.104996,-1212.283813,0.013525,0.003269,0.083028,258.463928,13.166780,0.830281,-1212.283813,0.083080,0.000000
80.190002,58.079674,-1212.283813,0.013530,0.003269,0.083028,258.351288,13.161042,0.830281,-1212.283813,0.083080,0.000000
80.410004,58.056587,-1212.372803,0.013517,0.003269,0.083028,258.248596,13.155810,0.830281,-1212.372803,0.083080,0.000000
80.630005,58.025307,-1212.239380,0.013525,0.003269,0.083028,258.109467,13.148723,0.830281,-1212.239380,0.083080,0.000000
80.850006,58.011528,-1212.239380,0.013512,0.003269,0.083028,258.048157,13.145600,0.830281,-1212.239380,0.083080,0.000000
81.070007,57.976524,-1212.283813,0.013469,0.003269,0.083028,257.892456,13.137669,0.830281,-1212.283813,0.083080,0.000000
81.290001,57.967964,-1212.283813,0.013499,0.003269,0.083028,257.854370,13.135729,0.830281,-1212.283813,0.083080,0.000000
81.510002,57.929237,-1212.283813,0.013512,0.003269,0.083028,257.682129,13.126953,0.830281,-1212.283813,0.083080,0.000000
81.730003,57.906525,-1212.283813,0.013508,0.003269,0.083028,257.581085,13.121806,0.830281,-1212.283813,0.083080,0.000000
81.950005,57.869659,-1212.283813,0.013491,0.003269,0.083028,257.417114,13.113453,0.830281,-1212.283813,0.083080,0.000000
82.170006,57.853271,-1212.239380,0.013525,0.003269,0.083028,257.344208,13.109738,0.830281,-1212.239380,0.083080,0.000000
82.390007,57.848434,-1212.283813,0.013564,0.003269,0.083028,257.322693,13.108643,0.830281,-1212.283813,0.083080,0.000000
82.610001,57.817528,-1212.328369,0.013482,0.003269,0.083028,257.185211,13.101639,0.830281,-1212.328369,0.083080,0.000000
82.830002,57.802628,-1212.328369,0.013534,0.003269,0.083028,257.118927,13.098263,0.830281,-1212.328369,0.083080,0.000000
83.050003,57.756081,-1212.239380,0.013482,0.003269,0.083028,256.911865,13.087714,0.830281,-1212.239380,0.083080,0.000000
83.270004,57.746399,-1212.239380,0.013517,0.003269,0.083028,256.868805,13.085522,0.830281,-1212.239380,0.083080,0.000000
83.490005,57.714752,-1212.239380,0.013482,0.003269,0.083028,256.728027,13.078350,0.830281,-1212.239380,0.083080,0.000000
83.710007,57.702087,-1212.283813,0.013491,0.003269,0.083028,256.671692,13.075480,0.830281,-1212.283813,0.083080,0.000000
83.930000,57.692406,-1212.328369,0.013478,0.003269,0.083028,256.628632,13.073286,0.830281,-1212.328369,0.083080,0.000000
84.150002,57.657036,-1212.239380,0.013560,0.003269,0.083028,256.471313,13.065270,0.830281,-1212.239380,0.083080,0.000000
84.370003,57.647354,-1212.328369,0.013542,0.003269,0.083028,256.428253,13.063078,0.830281,-1212.328369,0.083080,0.000000
84.590004,57.620171,-1212.283813,0.013547,0.003269,0.083028,256.307312,13.056917,0.830281,-1212.283813,0.083080,0.000000
84.810005,57.602669,-1212.283813,0.013499,0.003269,0.083028,256.229462,13.052952,0.830281,-1212.283813,0.083080,0.000000
85.030006,57.580696,-1212.283813,0.013482,0.003269,0.083028,256.131714,13.047972,0.830281,-1212.283813,0.083080,0.000000
85.250008,57.569527,-1212.328369,0.013521,0.003269,0.083028,256.082031,13.045441,0.830281,-1212.328369,0.083080,0.000000
85.470001,57.546066,-1212.283813,0.013478,0.003269,0.083028,255.977692,13.040125,0.830281,-1212.283813,0.083080,0.000000
85.690002,57.530426,-1212.283813,0.013486,0.003269,0.083028,255.908112,13.036581,0.830281,-1212.283813,0.083080,0.000000
85.910004,57.512550,-1212.328369,0.013512,0.003269,0.083028,255.828598,13.032531,0.830281,-1212.328369,0.083080,0.000000
86.130005,57.481644,-1212.283813,0.013508,0.003269,0.083028,255.691116,13.025527,0.830281,-1212.283813,0.083080,0.000000
86.350006,57.471222,-1212.194824,0.013486,0.003269,0.083028,255.644760,13.023165,0.830281,-1212.194824,0.083080,0.000000
86.570007,57.445152,-1212.283813,0.013512,0.003269,0.083028,255.528793,13.017258,0.830281,-1212.283813,0.083080,0.000000
86.790001,57.429512,-1212.283813,0.013521,0.003269,0.083028,255.459229,13.013714,0.830281,-1212.283813,0.083080,0.000000
87.010002,57.409401,-1212.372803,0.013486,0.003269,0.083028,255.369766,13.009156,0.830281,-1212.372803,0.083080,0.000000
87.230003,57.396744,-1212.283813,0.013517,0.003269,0.083028,255.313461,13.006289,0.830281,-1212.283813,0.083080,0.000000
87.450005,57.377754,-1212.328369,0.013512,0.003269,0.083028,255.229004,13.001986,0.830281,-1212.328369,0.083080,0.000000
87.670006,57.350945,-1212.283813,0.013521,0.003269,0.083028,255.109741,12.995910,0.830281,-1212.283813,0.083080,0.000000
87.890007,57.338280,-1212.239380,0.013482,0.003269,0.083028,255.053406,12.993039,0.830281,-1212.239380,0.083080,0.000000
88.110001,57.316315,-1212.328369,0.013508,0.003269,0.083028,254.955704,12.988063,0.830281,-1212.328369,0.083080,0.000000
88.330002,57.304398,-1212.283813,0.013568,0.003269,0.083028,254.902695,12.985362,0.830281,-1212.283813,0.083080,0.000000
88.550003,57.296951,-1212.239380,0.013525,0.003269,0.083028,254.869568,12.983675,0.830281,-1212.239380,0.083080,0.000000
88.770004,57.267532,-1212.328369,0.013473,0.003269,0.083028,254.738708,12.977009,0.830281,-1212.328369,0.083080,0.000000
88.990005,57.255241,-1212.283813,0.013534,0.003269,0.083028,254.684036,12.974223,0.830281,-1212.283813,0.083080,0.000000
89.210007,57.235878,-1212.372803,0.013521,0.003269,0.083028,254.597900,12.969835,0.830281,-1212.372803,0.083080,0.000000
89.430008,57.229546,-1212.283813,0.013534,0.003269,0.083028,254.569733,12.968401,0.830281,-1212.283813,0.083080,0.000000
89.650002,57.193802,-1212.283813,0.013517,0.003269,0.083028,254.410736,12.960300,0.830281,-1212.283813,0.083080,0.000000
89.870003,57.194176,-1212.239380,0.013495,0.003269,0.083028,254.412399,12.960385,0.830281,-1212.239380,0.083080,0.000000
89.900002,57.178162,-1212.283813,0.013495,0.003269,0.083028,254.341171,12.956757,0.830281,-1212.283813,0.083080,0.000000