File: Data/Symmetrical membranes compression/Sterlitech PVDF 02um test 1_10272023_144136.csv
Time (sec),S:Load (lbs),S:HL1 (DIM),S:LVDT (in),S:Position (in),Ch:Position (mm),Ch:Load (N),Ch:Stress (MPa),Ch:Strain (mm/mm),Ch:HL1 (DIM),Set Point (),Cycles ()
0.110000,-0.004097,-1211.260742,0.009485,-0.001355,-0.034412,-0.018224,-0.000928,-0.344115,-1211.260742,-0.034221,0.000000
0.310000,0.003349,-1211.260742,0.009481,-0.001355,-0.034412,0.014898,0.000759,-0.344115,-1211.260742,-0.034221,0.000000
0.510000,0.001862,-1211.260742,0.009416,-0.001290,-0.032755,0.008281,0.000422,-0.327551,-1211.260742,-0.032105,0.000000
0.710000,-0.015640,-1211.260742,0.009511,-0.001175,-0.029841,-0.069571,-0.003544,-0.298412,-1211.260742,-0.028775,0.000000
0.910000,-0.029419,-1211.260742,0.009628,-0.001050,-0.026676,-0.130862,-0.006666,-0.266758,-1211.260742,-0.025444,0.000000
1.110000,-0.026810,-1211.260742,0.009731,-0.000923,-0.023441,-0.119255,-0.006075,-0.234411,-1211.260742,-0.022114,0.000000
1.310000,-0.016388,-1211.260742,0.009852,-0.000784,-0.019903,-0.072897,-0.003714,-0.199028,-1211.260742,-0.018784,0.000000
1.510000,-0.005585,-1211.216309,0.010011,-0.000650,-0.016512,-0.024842,-0.001266,-0.165120,-1211.216309,-0.015437,0.000000
1.710000,0.047661,-1211.349731,0.010141,-0.000520,-0.013208,0.212006,0.010800,-0.132079,-1211.349731,-0.012106,0.000000
1.910000,0.214111,-1211.260742,0.010348,-0.000395,-0.010042,0.952415,0.048518,-0.100425,-1211.260742,-0.008776,0.000000
2.110000,0.562653,-1211.305298,0.010438,-0.000263,-0.006686,2.502804,0.127499,-0.066863,-1211.305298,-0.005446,0.000000
2.310000,0.689629,-1211.216309,0.010524,-0.000001,-0.000017,3.067621,0.156272,-0.000173,-1211.216309,0.000156,0.000000
2.510000,0.670265,-1211.349731,0.010481,-0.000001,-0.000035,2.981488,0.151884,-0.000347,-1211.349731,0.000156,0.000000
2.710000,0.655373,-1211.305298,0.010481,-0.000002,-0.000043,2.915243,0.148510,-0.000433,-1211.305298,0.000156,0.000000
2.910000,0.631912,-1211.349731,0.010477,-0.000002,-0.000043,2.810886,0.143193,-0.000433,-1211.349731,0.000477,0.000000
3.110000,0.642342,-1211.394165,0.010473,-0.000001,-0.000035,2.857278,0.145557,-0.000347,-1211.394165,0.000815,0.000000
3.310000,0.658356,-1211.305298,0.010494,0.000010,0.000243,2.928513,0.149186,0.002428,-1211.305298,0.001145,0.000000
3.510000,0.740273,-1211.305298,0.010503,0.000023,0.000581,3.292897,0.167748,0.005810,-1211.305298,0.001483,0.000000
3.710000,0.822571,-1211.260742,0.010516,0.000036,0.000902,3.658978,0.186397,0.009019,-1211.260742,0.001812,0.000000
3.910000,0.862785,-1211.260742,0.010529,0.000048,0.001231,3.837861,0.195510,0.012315,-1211.260742,0.002151,0.000000
4.110000,0.907471,-1211.305298,0.010520,0.000059,0.001509,4.036631,0.205636,0.015090,-1211.305298,0.002480,0.000000
4.310000,0.966301,-1211.305298,0.010568,0.000069,0.001743,4.298321,0.218967,0.017431,-1211.305298,0.002810,0.000000
4.510000,1.068336,-1211.260742,0.010542,0.000083,0.002116,4.752198,0.242089,0.021160,-1211.260742,0.003148,0.000000
4.710000,1.160683,-1211.305298,0.010537,0.000096,0.002437,5.162974,0.263014,0.024369,-1211.305298,0.003478,0.000000
4.910000,1.213188,-1211.349731,0.010611,0.000102,0.002593,5.396531,0.274912,0.025930,-1211.349731,0.003816,0.000000
5.110000,1.382614,-1211.260742,0.010606,0.000121,0.003070,6.150175,0.313305,0.030700,-1211.260742,0.004145,0.000000
5.310000,1.495445,-1211.305298,0.010632,0.000137,0.003478,6.652073,0.338873,0.034776,-1211.305298,0.004484,0.000000
5.510000,1.682373,-1211.349731,0.010628,0.000155,0.003946,7.483569,0.381231,0.039459,-1211.349731,0.004813,0.000000
5.710000,1.738235,-1211.349731,0.010589,0.000165,0.004180,7.732058,0.393890,0.041800,-1211.349731,0.005143,0.000000
5.910000,1.828720,-1211.305298,0.010619,0.000179,0.004544,8.134553,0.414394,0.045443,-1211.305298,0.005481,0.000000
6.110000,1.944527,-1211.305298,0.010684,0.000190,0.004822,8.649687,0.440636,0.048218,-1211.305298,0.005810,0.000000
6.310000,2.111725,-1211.349731,0.010667,0.000205,0.005195,9.393421,0.478524,0.051947,-1211.349731,0.006149,0.000000
6.510000,2.263275,-1211.349731,0.010697,0.000217,0.005507,10.067551,0.512865,0.055069,-1211.349731,0.006478,0.000000
6.710001,2.369774,-1211.305298,0.010701,0.000229,0.005819,10.541281,0.536998,0.058191,-1211.305298,0.006816,0.000000
6.910000,2.453934,-1211.349731,0.010727,0.000234,0.005940,10.915643,0.556069,0.059405,-1211.349731,0.007146,0.000000
7.110000,2.757416,-1211.260742,0.010727,0.000259,0.006574,12.265598,0.624839,0.065736,-1211.260742,0.007484,0.000000
7.310000,2.951797,-1211.260742,0.010740,0.000272,0.006920,13.130251,0.668887,0.069205,-1211.260742,0.007814,0.000000
7.510000,3.067604,-1211.349731,0.010718,0.000283,0.007189,13.645385,0.695129,0.071893,-1211.349731,0.008143,0.000000
7.710001,3.204636,-1211.394165,0.010744,0.000296,0.007519,14.254931,0.726181,0.075188,-1211.394165,0.008481,0.000000
7.910000,3.397522,-1211.305298,0.010753,0.000309,0.007857,15.112932,0.769890,0.078571,-1211.305298,0.008811,0.000000
8.110001,3.532692,-1211.394165,0.010744,0.000321,0.008143,15.714199,0.800519,0.081432,-1211.394165,0.009149,0.000000
8.310000,3.792984,-1211.349731,0.010835,0.000335,0.008499,16.872036,0.859502,0.084988,-1211.349731,0.009479,0.000000
8.510000,3.954964,-1211.349731,0.010843,0.000347,0.008820,17.592558,0.896208,0.088197,-1211.349731,0.009817,0.000000
8.710000,4.100189,-1211.394165,0.010852,0.000357,0.009063,18.238552,0.929116,0.090625,-1211.394165,0.010147,0.000000
8.910001,4.174294,-1211.349731,0.010787,0.000366,0.009288,18.568186,0.945908,0.092880,-1211.349731,0.010476,0.000000
9.110001,4.371651,-1211.438721,0.010835,0.000375,0.009513,19.446074,0.990630,0.095135,-1211.438721,0.010814,0.000000
9.310000,4.807701,-1211.394165,0.010874,0.000399,0.010147,21.385723,1.089441,0.101465,-1211.394165,0.011144,0.000000
9.510000,5.006172,-1211.394165,0.010839,0.000413,0.010493,22.268566,1.134415,0.104934,-1211.394165,0.011482,0.000000
9.710000,5.246727,-1211.394165,0.010874,0.000428,0.010884,23.338608,1.188925,0.108837,-1211.394165,0.011812,0.000000
9.910001,5.425461,-1211.394165,0.010908,0.000442,0.011222,24.133656,1.229427,0.112219,-1211.394165,0.012150,0.000000
10.110001,5.677933,-1211.394165,0.010874,0.000457,0.011603,25.256706,1.286638,0.116035,-1211.394165,0.012479,0.000000
10.310000,5.876038,-1211.349731,0.010917,0.000468,0.011881,26.137920,1.331529,0.118810,-1211.349731,0.012818,0.000000
10.510000,6.074135,-1211.349731,0.010904,0.000479,0.012167,27.019100,1.376419,0.121672,-1211.349731,0.013147,0.000000
10.710000,6.157173,-1211.305298,0.010977,0.000489,0.012410,27.388474,1.395235,0.124100,-1211.305298,0.013477,0.000000
10.910001,6.435707,-1211.349731,0.010930,0.000502,0.012757,28.627455,1.458352,0.127569,-1211.349731,0.013815,0.000000
11.110001,6.653175,-1211.394165,0.010956,0.000516,0.013104,29.594803,1.507631,0.131038,-1211.394165,0.014144,0.000000
11.310000,6.925377,-1211.394165,0.011016,0.000531,0.013494,30.805614,1.569313,0.134940,-1211.394165,0.014483,0.000000
11.510000,7.041931,-1211.394165,0.010999,0.000543,0.013780,31.324074,1.595724,0.137802,-1211.394165,0.014812,0.000000
11.710001,7.320839,-1211.394165,0.011050,0.000558,0.014179,32.564716,1.658926,0.141792,-1211.394165,0.015150,0.000000
11.910001,7.400902,-1211.394165,0.010986,0.000567,0.014405,32.920856,1.677068,0.144046,-1211.394165,0.015480,0.000000
12.110001,7.738266,-1211.394165,0.011020,0.000583,0.014812,34.421528,1.753516,0.148122,-1211.394165,0.015818,0.000000
12.310000,7.918129,-1211.394165,0.011016,0.000595,0.015124,35.221596,1.794274,0.151244,-1211.394165,0.016148,0.000000
12.510000,7.937119,-1211.438721,0.011020,0.000605,0.015367,35.306068,1.798577,0.153672,-1211.438721,0.016477,0.000000
12.710001,8.026115,-1211.349731,0.011089,0.000610,0.015506,35.701946,1.818744,0.155060,-1211.349731,0.016816,0.000000
12.910001,8.396255,-1211.438721,0.011072,0.000629,0.015983,37.348412,1.902619,0.159830,-1211.438721,0.017145,0.000000
13.110001,8.787987,-1211.394165,0.011115,0.000649,0.016477,39.090916,1.991386,0.164773,-1211.394165,0.017483,0.000000
13.310000,8.866562,-1211.394165,0.011094,0.000661,0.016798,39.440437,2.009192,0.167982,-1211.394165,0.017813,0.000000
13.510000,9.105247,-1211.394165,0.011094,0.000675,0.017145,40.502163,2.063279,0.171451,-1211.394165,0.018151,0.000000
13.710001,9.263138,-1211.483154,0.011094,0.000689,0.017492,41.204494,2.099057,0.174919,-1211.483154,0.018481,0.000000
13.910001,9.370750,-1211.438721,0.011124,0.000698,0.017726,41.683178,2.123442,0.177261,-1211.438721,0.018810,0.000000
14.110001,9.304840,-1211.483154,0.011184,0.000706,0.017926,41.389996,2.108507,0.179255,-1211.483154,0.019148,0.000000
14.310000,9.873451,-1211.394165,0.011137,0.000729,0.018524,43.919304,2.237356,0.185239,-1211.394165,0.019478,0.000000
14.510000,10.005646,-1211.483154,0.011132,0.000741,0.018810,44.507336,2.267312,0.188101,-1211.483154,0.019816,0.000000
14.710001,10.156456,-1211.438721,0.011193,0.000753,0.019114,45.178173,2.301486,0.191137,-1211.438721,0.020146,0.000000
14.910001,10.258858,-1211.438721,0.011175,0.000762,0.019365,45.633678,2.324690,0.193652,-1211.438721,0.020484,0.000000
15.110001,10.438339,-1211.483154,0.011180,0.000777,0.019738,46.432053,2.365361,0.197381,-1211.483154,0.020813,0.000000
15.310000,10.714272,-1211.438721,0.011188,0.000791,0.020085,47.659462,2.427889,0.200850,-1211.438721,0.021152,0.000000
15.510001,10.838272,-1211.438721,0.011184,0.000802,0.020380,48.211040,2.455987,0.203798,-1211.438721,0.021481,0.000000
15.710001,11.016640,-1211.483154,0.011244,0.000816,0.020727,49.004459,2.496406,0.207267,-1211.483154,0.021811,0.000000
15.910001,11.275810,-1211.483154,0.011279,0.000831,0.021108,50.157310,2.555135,0.211083,-1211.483154,0.022149,0.000000
16.110001,11.669777,-1211.438721,0.011300,0.000849,0.021568,51.909760,2.644409,0.215679,-1211.438721,0.022478,0.000000
16.310001,11.834740,-1211.438721,0.011296,0.000861,0.021871,52.643551,2.681790,0.218714,-1211.438721,0.022817,0.000000
16.510000,11.873093,-1211.483154,0.011331,0.000871,0.022132,52.814156,2.690481,0.221316,-1211.483154,0.023146,0.000000
16.710001,12.054070,-1211.394165,0.011283,0.000884,0.022452,53.619179,2.731491,0.224525,-1211.394165,0.023484,0.000000
16.910002,12.226105,-1211.394165,0.011292,0.000896,0.022756,54.384430,2.770475,0.227560,-1211.394165,0.023814,0.000000
17.110001,12.535172,-1211.483154,0.011309,0.000912,0.023172,55.759228,2.840510,0.231723,-1211.483154,0.024152,0.000000
17.310001,12.644646,-1211.438721,0.011331,0.000923,0.023432,56.246193,2.865318,0.234324,-1211.438721,0.024482,0.000000
17.510000,12.739235,-1211.527710,0.011369,0.000931,0.023658,56.666946,2.886752,0.236579,-1211.527710,0.024811,0.000000
17.710001,13.079582,-1211.483154,0.011382,0.000952,0.024170,58.180889,2.963876,0.241696,-1211.483154,0.025150,0.000000
17.910002,13.380081,-1211.483154,0.011421,0.000964,0.024473,59.517574,3.031970,0.244731,-1211.483154,0.025479,0.000000
18.110001,13.645958,-1211.438721,0.011374,0.000978,0.024846,60.700253,3.092218,0.248460,-1211.438721,0.025817,0.000000
18.310001,13.874969,-1211.438721,0.011417,0.000993,0.025228,61.718948,3.144113,0.252276,-1211.438721,0.026147,0.000000
18.510000,14.093552,-1211.438721,0.011395,0.001006,0.025557,62.691250,3.193644,0.255572,-1211.438721,0.026485,0.000000
18.710001,14.214569,-1211.438721,0.011413,0.001016,0.025817,63.229561,3.221067,0.258173,-1211.438721,0.026815,0.000000
18.910002,14.273407,-1211.438721,0.011438,0.001028,0.026112,63.491283,3.234400,0.261122,-1211.438721,0.027144,0.000000
19.110001,14.770897,-1211.438721,0.011469,0.001046,0.026572,65.704231,3.347133,0.265718,-1211.438721,0.027482,0.000000
19.310001,14.832336,-1211.394165,0.011430,0.001058,0.026884,65.977524,3.361056,0.268840,-1211.394165,0.027812,0.000000
19.510000,14.945168,-1211.483154,0.011503,0.001068,0.027127,66.479424,3.386623,0.271268,-1211.483154,0.028150,0.000000
19.710001,15.443031,-1211.483154,0.011503,0.001086,0.027586,68.694031,3.499441,0.275864,-1211.483154,0.028480,0.000000
19.910002,15.593094,-1211.483154,0.011469,0.001099,0.027916,69.361549,3.533446,0.279160,-1211.483154,0.028818,0.000000
20.110001,15.723053,-1211.438721,0.011512,0.001108,0.028150,69.939636,3.562895,0.281502,-1211.438721,0.029147,0.000000
20.310001,16.004562,-1211.483154,0.011486,0.001124,0.028549,71.191849,3.626686,0.285491,-1211.483154,0.029486,0.000000
20.510000,16.312515,-1211.572144,0.011516,0.001138,0.028905,72.561691,3.696469,0.289046,-1211.572144,0.029815,0.000000
20.710001,16.360184,-1211.438721,0.011559,0.001150,0.029200,72.773735,3.707271,0.291995,-1211.438721,0.030145,0.000000
20.910002,16.671860,-1211.483154,0.011533,0.001163,0.029538,74.160133,3.777897,0.295377,-1211.483154,0.030483,0.000000
21.110001,16.846870,-1211.483154,0.011563,0.001175,0.029850,74.938622,3.817555,0.298499,-1211.483154,0.030813,0.000000
21.310001,16.903473,-1211.438721,0.011611,0.001187,0.030162,75.190399,3.830382,0.301621,-1211.438721,0.031151,0.000000
21.510000,17.188339,-1211.438721,0.011563,0.001202,0.030526,76.457550,3.894933,0.305264,-1211.438721,0.031480,0.000000
21.710001,17.326485,-1211.483154,0.011585,0.001211,0.030761,77.072052,3.926238,0.307605,-1211.483154,0.031819,0.000000
21.910002,17.406548,-1211.527710,0.011615,0.001221,0.031012,77.428192,3.944380,0.310120,-1211.527710,0.032148,0.000000
22.110001,17.620659,-1211.483154,0.011611,0.001231,0.031272,78.380608,3.992898,0.312722,-1211.483154,0.032478,0.000000
22.310001,17.935318,-1211.483154,0.011645,0.001247,0.031662,79.780281,4.064201,0.316624,-1211.483154,0.032816,0.000000
22.510000,18.330032,-1211.438721,0.011650,0.001264,0.032113,81.536057,4.153645,0.321134,-1211.438721,0.033145,0.000000
22.710001,18.544144,-1211.438721,0.011637,0.001280,0.032512,82.488472,4.202163,0.325123,-1211.438721,0.033484,0.000000
22.910002,18.675224,-1211.483154,0.011689,0.001289,0.032746,83.071548,4.231866,0.327464,-1211.483154,0.033813,0.000000
23.110001,18.915031,-1211.527710,0.011689,0.001303,0.033093,84.138260,4.286207,0.330933,-1211.527710,0.034151,0.000000
23.310001,19.101959,-1211.527710,0.011723,0.001318,0.033484,84.969757,4.328566,0.334836,-1211.527710,0.034481,0.000000
23.510000,19.269531,-1211.527710,0.011732,0.001332,0.033822,85.715157,4.366538,0.338218,-1211.527710,0.034819,0.000000
23.710001,19.379005,-1211.483154,0.011736,0.001340,0.034030,86.202118,4.391345,0.340299,-1211.483154,0.035149,0.000000
23.910002,19.710045,-1211.527710,0.011706,0.001355,0.034420,87.674660,4.466360,0.344202,-1211.527710,0.035478,0.000000
24.110001,19.938309,-1211.483154,0.011736,0.001368,0.034758,88.690025,4.518085,0.347584,-1211.483154,0.035816,0.000000
24.310001,19.954323,-1211.483154,0.011719,0.001379,0.035027,88.761261,4.521714,0.350273,-1211.483154,0.036146,0.000000
24.510000,20.294670,-1211.483154,0.011775,0.001394,0.035409,90.275200,4.598838,0.354088,-1211.483154,0.036484,0.000000
24.710001,20.607460,-1211.527710,0.011740,0.001407,0.035747,91.666557,4.669717,0.357471,-1211.527710,0.036814,0.000000
24.910002,21.028244,-1211.572144,0.011809,0.001425,0.036207,93.538300,4.765068,0.362067,-1211.572144,0.037152,0.000000
25.110001,21.069206,-1211.483154,0.011826,0.001436,0.036467,93.720512,4.774350,0.364668,-1211.483154,0.037481,0.000000
25.310001,21.352951,-1211.483154,0.011839,0.001452,0.036874,94.982674,4.838648,0.368744,-1211.483154,0.037820,0.000000
25.510002,21.478439,-1211.483154,0.011852,0.001462,0.037126,95.540871,4.867084,0.371259,-1211.483154,0.038149,0.000000
25.710001,21.457962,-1211.527710,0.011831,0.001471,0.037351,95.449783,4.862443,0.373514,-1211.527710,0.038479,0.000000
25.910002,21.875015,-1211.527710,0.011874,0.001486,0.037733,97.304924,4.956950,0.377330,-1211.527710,0.038817,0.000000
26.110001,22.180367,-1211.527710,0.011865,0.001500,0.038106,98.663200,5.026143,0.381059,-1211.527710,0.039147,0.000000
26.310001,21.901825,-1211.527710,0.011895,0.001506,0.038245,97.424187,4.963024,0.382447,-1211.527710,0.039485,0.000000
26.510002,22.676735,-1211.527710,0.011900,0.001526,0.038765,100.871155,5.138622,0.387650,-1211.527710,0.039814,0.000000
26.710001,23.012619,-1211.572144,0.011874,0.001543,0.039190,102.365242,5.214734,0.391899,-1211.572144,0.040153,0.000000
26.910002,23.315353,-1211.438721,0.011917,0.001556,0.039520,103.711868,5.283335,0.395195,-1211.438721,0.040482,0.000000
27.110001,23.487762,-1211.527710,0.011921,0.001572,0.039936,104.478783,5.322403,0.399358,-1211.527710,0.040812,0.000000
27.310001,23.579742,-1211.527710,0.011926,0.001583,0.040196,104.887932,5.343246,0.401959,-1211.527710,0.041150,0.000000
27.510002,23.762199,-1211.527710,0.011926,0.001594,0.040499,105.699539,5.384591,0.404995,-1211.527710,0.041479,0.000000
27.710001,24.008339,-1211.483154,0.011973,0.001610,0.040890,106.794426,5.440367,0.408897,-1211.483154,0.041818,0.000000
27.910002,24.274216,-1211.483154,0.011964,0.001622,0.041211,107.977104,5.500616,0.412106,-1211.483154,0.042147,0.000000
28.110001,24.325600,-1211.527710,0.012003,0.001631,0.041419,108.205673,5.512259,0.414187,-1211.527710,0.042485,0.000000
28.310001,24.684944,-1211.572144,0.011986,0.001648,0.041861,109.804115,5.593688,0.418610,-1211.572144,0.042815,0.000000
28.510002,25.025291,-1211.483154,0.012042,0.001660,0.042173,111.318054,5.670812,0.421732,-1211.483154,0.043153,0.000000
28.710001,25.368240,-1211.483154,0.012003,0.001676,0.042581,112.843567,5.748525,0.425808,-1211.483154,0.043483,0.000000
28.910002,25.500061,-1211.527710,0.012029,0.001689,0.042910,113.429939,5.778397,0.429103,-1211.527710,0.043812,0.000000
29.110001,25.716782,-1211.438721,0.012042,0.001702,0.043240,114.393959,5.827506,0.432399,-1211.438721,0.044150,0.000000
29.310001,25.857544,-1211.527710,0.012046,0.001714,0.043526,115.020103,5.859403,0.435261,-1211.527710,0.044480,0.000000
29.510002,26.045959,-1211.527710,0.012085,0.001727,0.043864,115.858215,5.902099,0.438643,-1211.527710,0.044818,0.000000
29.710001,26.330086,-1211.483154,0.012064,0.001740,0.044194,117.122070,5.966483,0.441939,-1211.483154,0.045148,0.000000
29.910002,26.473816,-1211.527710,0.012085,0.001750,0.044463,117.761414,5.999052,0.444627,-1211.527710,0.045486,0.000000
30.110001,26.299545,-1211.483154,0.012102,0.001754,0.044549,116.986221,5.959562,0.445494,-1211.483154,0.045816,0.000000
30.310001,26.909866,-1211.572144,0.012098,0.001773,0.045035,119.701065,6.097863,0.450350,-1211.572144,0.046154,0.000000
30.510002,27.369743,-1211.527710,0.012098,0.001794,0.045564,121.746696,6.202072,0.455640,-1211.527710,0.046483,0.000000
30.710001,27.864998,-1211.527710,0.012133,0.001807,0.045902,123.949699,6.314299,0.459023,-1211.527710,0.046813,0.000000
30.910002,27.937988,-1211.483154,0.012133,0.001819,0.046206,124.274376,6.330839,0.462058,-1211.483154,0.047151,0.000000
31.110001,28.153587,-1211.572144,0.012154,0.001833,0.046570,125.233414,6.379694,0.465700,-1211.572144,0.047481,0.000000
31.310001,28.364349,-1211.572144,0.012189,0.001846,0.046891,126.170929,6.427454,0.468909,-1211.572144,0.047819,0.000000
31.510002,28.572510,-1211.572144,0.012184,0.001858,0.047203,127.096870,6.474624,0.472031,-1211.572144,0.048148,0.000000
31.710001,28.877853,-1211.572144,0.012232,0.001874,0.047602,128.455109,6.543815,0.476020,-1211.572144,0.048487,0.000000
31.910002,28.852158,-1211.483154,0.012227,0.001882,0.047801,128.340805,6.537992,0.478015,-1211.483154,0.048816,0.000000
32.110001,28.841736,-1211.572144,0.012271,0.001892,0.048044,128.294449,6.535631,0.480443,-1211.572144,0.049146,0.000000
32.310001,29.318375,-1211.572144,0.012240,0.001908,0.048469,130.414642,6.643639,0.484693,-1211.572144,0.049484,0.000000
32.510002,29.715317,-1211.572144,0.012284,0.001922,0.048816,132.180328,6.733587,0.488162,-1211.572144,0.049813,0.000000
32.710003,30.016197,-1211.527710,0.012275,0.001936,0.049163,133.518707,6.801768,0.491630,-1211.527710,0.050152,0.000000
32.910000,30.130142,-1211.527710,0.012305,0.001948,0.049484,134.025574,6.827588,0.494839,-1211.527710,0.050481,0.000000
33.110001,30.416496,-1211.527710,0.012266,0.001960,0.049779,135.299332,6.892477,0.497788,-1211.527710,0.050819,0.000000
33.310001,30.520386,-1211.616577,0.012279,0.001972,0.050091,135.761459,6.916018,0.500910,-1211.616577,0.051149,0.000000
33.510002,30.811211,-1211.527710,0.012335,0.001986,0.050438,137.055115,6.981920,0.504378,-1211.527710,0.051487,0.000000
33.710003,31.049156,-1211.527710,0.012301,0.001997,0.050715,138.113541,7.035839,0.507154,-1211.527710,0.051817,0.000000
33.910000,31.275932,-1211.572144,0.012335,0.002009,0.051019,139.122299,7.087227,0.510189,-1211.572144,0.052146,0.000000
34.110001,31.326950,-1211.572144,0.012361,0.002017,0.051227,139.349228,7.098788,0.512270,-1211.572144,0.052485,0.000000
34.310001,31.535103,-1211.572144,0.012374,0.002030,0.051565,140.275146,7.145956,0.515653,-1211.572144,0.052814,0.000000
34.510002,32.351715,-1211.572144,0.012374,0.002050,0.052068,143.907623,7.331003,0.520682,-1211.572144,0.053152,0.000000
34.710003,32.514442,-1211.616577,0.012378,0.002061,0.052346,144.631470,7.367878,0.523458,-1211.616577,0.053482,0.000000
34.910000,32.849953,-1211.572144,0.012374,0.002078,0.052779,146.123886,7.443906,0.527794,-1211.572144,0.053820,0.000000
35.110001,33.050285,-1211.572144,0.012434,0.002089,0.053057,147.015015,7.489302,0.530569,-1211.572144,0.054150,0.000000
35.310001,33.143753,-1211.572144,0.012439,0.002099,0.053317,147.430771,7.510482,0.533171,-1211.572144,0.054479,0.000000
35.510002,33.647949,-1211.572144,0.012434,0.002119,0.053811,149.673553,7.624734,0.538114,-1211.572144,0.054817,0.000000
35.710003,34.014732,-1211.572144,0.012417,0.002130,0.054106,151.305084,7.707849,0.541062,-1211.572144,0.055147,0.000000
35.910000,34.241508,-1211.572144,0.012499,0.002143,0.054436,152.313843,7.759236,0.544358,-1211.572144,0.055485,0.000000
36.110001,34.430298,-1211.527710,0.012490,0.002156,0.054765,153.153610,7.802017,0.547653,-1211.527710,0.055815,0.000000
36.310001,34.606056,-1211.527710,0.012512,0.002167,0.055043,153.935425,7.841844,0.550428,-1211.527710,0.056153,0.000000
36.510002,34.853317,-1211.527710,0.012482,0.002180,0.055381,155.035294,7.897875,0.553811,-1211.527710,0.056482,0.000000
36.710003,35.225685,-1211.572144,0.012473,0.002196,0.055789,156.691666,7.982254,0.557886,-1211.572144,0.056821,0.000000
36.910000,35.502357,-1211.572144,0.012534,0.002208,0.056075,157.922379,8.044949,0.560748,-1211.572144,0.057150,0.000000
37.110001,35.685570,-1211.616577,0.012503,0.002221,0.056404,158.737335,8.086466,0.564044,-1211.616577,0.057480,0.000000
37.310001,36.056076,-1211.527710,0.012547,0.002234,0.056743,160.385437,8.170424,0.567426,-1211.527710,0.057818,0.000000
37.510002,36.763214,-1211.616577,0.012521,0.002253,0.057228,163.530945,8.330664,0.572282,-1211.616577,0.058147,0.000000
37.710003,37.006744,-1211.572144,0.012616,0.002266,0.057566,164.614227,8.385849,0.575665,-1211.572144,0.058486,0.000000
37.910004,37.082710,-1211.661133,0.012590,0.002277,0.057835,164.952133,8.403062,0.578353,-1211.661133,0.058815,0.000000
38.110001,37.123299,-1211.616577,0.012594,0.002287,0.058087,165.132675,8.412259,0.580868,-1211.616577,0.059153,0.000000
38.310001,37.364967,-1211.572144,0.012598,0.002302,0.058468,166.207672,8.467022,0.584683,-1211.572144,0.059483,0.000000
38.510002,37.894852,-1211.572144,0.012624,0.002314,0.058772,168.564713,8.587096,0.587719,-1211.572144,0.059821,0.000000
38.710003,38.167801,-1211.572144,0.012594,0.002326,0.059084,169.778854,8.648948,0.590841,-1211.572144,0.060151,0.000000
38.910004,38.244514,-1211.616577,0.012628,0.002338,0.059379,170.120102,8.666330,0.593789,-1211.616577,0.060480,0.000000
39.110001,38.887230,-1211.616577,0.012646,0.002355,0.059813,172.979034,8.811972,0.598126,-1211.616577,0.060819,0.000000
39.310001,39.083466,-1211.572144,0.012672,0.002368,0.060142,173.851944,8.856440,0.601421,-1211.572144,0.061148,0.000000
39.510002,39.840126,-1211.616577,0.012684,0.002384,0.060558,177.217728,9.027901,0.605584,-1211.616577,0.061486,0.000000
39.710003,39.977905,-1211.572144,0.012693,0.002395,0.060827,177.830597,9.059123,0.608272,-1211.572144,0.061816,0.000000
39.910004,40.269104,-1211.572144,0.012723,0.002408,0.061157,179.125916,9.125109,0.611568,-1211.572144,0.062154,0.000000
40.110001,40.374481,-1211.616577,0.012728,0.002417,0.061400,179.594666,9.148988,0.613996,-1211.616577,0.062484,0.000000
40.310001,40.960220,-1211.661133,0.012710,0.002436,0.061868,182.200165,9.281718,0.618679,-1211.661133,0.062813,0.000000
40.510002,41.341904,-1211.616577,0.012753,0.002448,0.062180,183.897980,9.368209,0.621801,-1211.616577,0.063151,0.000000
40.710003,41.491974,-1211.616577,0.012758,0.002459,0.062449,184.565521,9.402216,0.624489,-1211.616577,0.063481,0.000000
40.910004,41.754868,-1211.661133,0.012766,0.002474,0.062839,185.734924,9.461788,0.628392,-1211.661133,0.063819,0.000000
41.110001,42.368538,-1211.616577,0.012736,0.002487,0.063169,188.464676,9.600848,0.631687,-1211.616577,0.064149,0.000000
41.310001,42.730110,-1211.616577,0.012766,0.002501,0.063516,190.073029,9.682781,0.635156,-1211.616577,0.064487,0.000000
41.510002,42.930817,-1211.661133,0.012766,0.002512,0.063793,190.965805,9.728262,0.637931,-1211.661133,0.064816,0.000000
41.710003,43.414528,-1211.616577,0.012766,0.002528,0.064201,193.117462,9.837873,0.642007,-1211.616577,0.065155,0.000000
41.910004,43.813713,-1211.616577,0.012779,0.002542,0.064556,194.893127,9.928329,0.645563,-1211.616577,0.065484,0.000000
42.110001,44.063950,-1211.572144,0.012814,0.002554,0.064860,196.006241,9.985034,0.648598,-1211.572144,0.065814,0.000000
42.310001,44.528671,-1211.572144,0.012853,0.002569,0.065241,198.073425,10.090342,0.652414,-1211.572144,0.066152,0.000000
42.510002,44.622505,-1211.661133,0.012848,0.002577,0.065450,198.490814,10.111604,0.654495,-1211.661133,0.066482,0.000000
42.710003,45.163933,-1211.616577,0.012874,0.002593,0.065874,200.899200,10.234293,0.658745,-1211.616577,0.066820,0.000000
42.910004,45.388107,-1211.572144,0.012827,0.002605,0.066161,201.896378,10.285092,0.661607,-1211.572144,0.067149,0.000000
43.110001,45.563866,-1211.661133,0.012853,0.002614,0.066395,202.678192,10.324920,0.663948,-1211.661133,0.067488,0.000000
43.310001,46.113113,-1211.661133,0.012904,0.002629,0.066776,205.121368,10.449381,0.667764,-1211.661133,0.067817,0.000000
43.510002,46.377495,-1211.616577,0.012878,0.002642,0.067115,206.297394,10.509290,0.671146,-1211.616577,0.068155,0.000000
43.710003,46.698112,-1211.661133,0.012917,0.002652,0.067357,207.723572,10.581944,0.673574,-1211.661133,0.068485,0.000000
43.910004,47.379929,-1211.661133,0.012883,0.002667,0.067730,210.756454,10.736445,0.677303,-1211.661133,0.068814,0.000000
44.110001,47.864754,-1211.661133,0.012878,0.002681,0.068095,212.913055,10.846308,0.680946,-1211.661133,0.069153,0.000000
44.310001,48.298569,-1211.705566,0.012930,0.002695,0.068441,214.842758,10.944612,0.684415,-1211.705566,0.069482,0.000000
44.510002,48.634445,-1211.616577,0.012935,0.002705,0.068719,216.336823,11.020722,0.687190,-1211.616577,0.069820,0.000000
44.710003,49.025436,-1211.616577,0.012943,0.002720,0.069092,218.076035,11.109323,0.690919,-1211.616577,0.070150,0.000000
44.910004,49.395950,-1211.661133,0.012917,0.002731,0.069369,219.724167,11.193282,0.693694,-1211.661133,0.070488,0.000000
45.110001,49.455528,-1211.705566,0.012991,0.002740,0.069595,219.989182,11.206782,0.695948,-1211.705566,0.070818,0.000000
45.310001,50.038292,-1211.616577,0.012922,0.002757,0.070029,222.581436,11.338840,0.700285,-1211.616577,0.071147,0.000000
45.510002,50.540619,-1211.616577,0.013012,0.002767,0.070280,224.815903,11.452668,0.702800,-1211.616577,0.071485,0.000000
45.710003,50.905174,-1211.616577,0.012978,0.002780,0.070618,226.437531,11.535277,0.706182,-1211.616577,0.071815,0.000000
45.910004,51.625717,-1211.661133,0.013008,0.002797,0.071034,229.642654,11.698555,0.710345,-1211.661133,0.072153,0.000000
46.110001,52.172729,-1211.661133,0.013047,0.002813,0.071459,232.075897,11.822510,0.714594,-1211.661133,0.072483,0.000000
46.310001,52.768898,-1211.705566,0.013012,0.002826,0.071789,234.727783,11.957603,0.717890,-1211.705566,0.072821,0.000000
46.510002,52.955833,-1211.661133,0.013016,0.002837,0.072049,235.559311,11.999964,0.720491,-1211.661133,0.073150,0.000000
46.710003,53.486458,-1211.661133,0.013025,0.002851,0.072405,237.919647,12.120205,0.724047,-1211.661133,0.073489,0.000000
46.910004,53.769463,-1211.661133,0.013055,0.002863,0.072708,239.178513,12.184335,0.727082,-1211.661133,0.073818,0.000000
47.110001,54.034218,-1211.616577,0.013077,0.002873,0.072986,240.356201,12.244329,0.729857,-1211.616577,0.074148,0.000000
47.310001,54.738747,-1211.661133,0.013077,0.002888,0.073367,243.490112,12.403977,0.733673,-1211.661133,0.074486,0.000000
47.510002,55.126015,-1211.705566,0.013051,0.002899,0.073627,245.212753,12.491734,0.736275,-1211.705566,0.074816,0.000000
47.710003,55.371780,-1211.661133,0.013124,0.002913,0.074000,246.305984,12.547424,0.740004,-1211.661133,0.075154,0.000000
47.910004,56.096420,-1211.661133,0.013120,0.002928,0.074365,249.529343,12.711631,0.743646,-1211.661133,0.075483,0.000000
48.110001,57.072037,-1211.661133,0.013137,0.002948,0.074868,253.869095,12.932709,0.748676,-1211.661133,0.075822,0.000000
48.310001,57.396744,-1211.661133,0.013124,0.002957,0.075110,255.313461,13.006289,0.751104,-1211.661133,0.076151,0.000000
48.510002,58.075203,-1211.661133,0.013073,0.002972,0.075483,258.331390,13.160028,0.754833,-1211.661133,0.076481,0.000000
48.710003,58.385391,-1211.661133,0.013107,0.002984,0.075804,259.711182,13.230319,0.758042,-1211.661133,0.076819,0.000000
48.910004,58.705635,-1211.661133,0.013189,0.002996,0.076090,261.135712,13.302887,0.760904,-1211.661133,0.077148,0.000000
49.110001,59.410538,-1211.661133,0.013193,0.003009,0.076420,264.271271,13.462620,0.764200,-1211.661133,0.077487,0.000000
49.310001,59.886795,-1211.705566,0.013202,0.003022,0.076749,266.389771,13.570541,0.767495,-1211.705566,0.077816,0.000000
49.510002,60.051758,-1211.661133,0.013154,0.003029,0.076940,267.123566,13.607924,0.769403,-1211.661133,0.078154,0.000000
49.710003,61.027374,-1211.705566,0.013193,0.003051,0.077487,271.463318,13.829000,0.774866,-1211.705566,0.078484,0.000000
49.910004,61.573647,-1211.705566,0.013167,0.003064,0.077825,273.893250,13.952787,0.778249,-1211.705566,0.078822,0.000000
50.110001,62.462128,-1211.750122,0.013219,0.003078,0.078180,277.845428,14.154120,0.781804,-1211.750122,0.079152,0.000000
50.310001,62.926476,-1211.705566,0.013245,0.003091,0.078510,279.910950,14.259343,0.785099,-1211.705566,0.079481,0.000000
50.510002,63.434387,-1211.705566,0.013254,0.003104,0.078831,282.170258,14.374438,0.788308,-1211.705566,0.079819,0.000000
50.710003,63.704361,-1211.705566,0.013206,0.003113,0.079074,283.371155,14.435615,0.790736,-1211.705566,0.080149,0.000000
50.910004,64.539215,-1211.661133,0.013228,0.003130,0.079507,287.084778,14.624795,0.795073,-1211.661133,0.080487,0.000000
51.110001,65.043411,-1211.705566,0.013254,0.003142,0.079802,289.327545,14.739048,0.798021,-1211.705566,0.080817,0.000000
51.310001,65.476105,-1211.750122,0.013254,0.003153,0.080080,291.252258,14.837097,0.800796,-1211.750122,0.081155,0.000000
51.510002,65.560638,-1211.705566,0.013271,0.003160,0.080253,291.628296,14.856253,0.802531,-1211.705566,0.081485,0.000000
51.710003,66.454697,-1211.705566,0.013310,0.003177,0.080704,295.605255,15.058849,0.807040,-1211.705566,0.081823,0.000000
51.910004,67.586349,-1211.750122,0.013288,0.003188,0.080964,300.639099,15.315286,0.809642,-1211.750122,0.081138,0.000000
52.110001,66.918686,-1211.750122,0.013258,0.003187,0.080947,297.669189,15.163991,0.809468,-1211.750122,0.081138,0.000000
52.310001,66.353043,-1211.794556,0.013314,0.003187,0.080938,295.153076,15.035815,0.809382,-1211.794556,0.080947,0.000000
52.510002,65.849976,-1211.750122,0.013310,0.003187,0.080938,292.915314,14.921818,0.809382,-1211.750122,0.080947,0.000000
52.710003,65.423599,-1211.705566,0.013271,0.003186,0.080930,291.018707,14.825199,0.809295,-1211.705566,0.080947,0.000000
52.910004,65.042664,-1211.705566,0.013331,0.003186,0.080930,289.324219,14.738878,0.809295,-1211.705566,0.080947,0.000000
53.110004,64.733978,-1211.750122,0.013331,0.003186,0.080930,287.951111,14.668929,0.809295,-1211.750122,0.080947,0.000000
53.310001,64.439804,-1211.750122,0.013331,0.003186,0.080930,286.642578,14.602269,0.809295,-1211.750122,0.080947,0.000000
53.510002,64.153442,-1211.705566,0.013301,0.003186,0.080930,285.368774,14.537378,0.809295,-1211.705566,0.080947,0.000000
53.710003,63.898361,-1211.750122,0.013331,0.003186,0.080921,284.234100,14.479576,0.809208,-1211.750122,0.080947,0.000000
53.910004,63.652603,-1211.750122,0.013344,0.003186,0.080921,283.140930,14.423886,0.809208,-1211.750122,0.080947,0.000000
54.110004,63.424332,-1211.705566,0.013323,0.003186,0.080921,282.125519,14.372159,0.809208,-1211.705566,0.080947,0.000000
54.310001,63.244476,-1211.750122,0.013340,0.003186,0.080921,281.325470,14.331404,0.809208,-1211.750122,0.080947,0.000000
54.510002,63.061646,-1211.705566,0.013318,0.003186,0.080921,280.512207,14.289973,0.809208,-1211.705566,0.080947,0.000000
54.710003,62.887749,-1211.705566,0.013357,0.003186,0.080921,279.738678,14.250567,0.809208,-1211.705566,0.080947,0.000000
54.910004,62.713852,-1211.705566,0.013348,0.003186,0.080921,278.965149,14.211162,0.809208,-1211.705566,0.080947,0.000000
55.110004,62.555222,-1211.750122,0.013340,0.003186,0.080921,278.259521,14.175216,0.809208,-1211.750122,0.080947,0.000000
55.310001,62.404411,-1211.794556,0.013327,0.003186,0.080921,277.588684,14.141042,0.809208,-1211.794556,0.080947,0.000000
55.510002,62.264023,-1211.705566,0.013383,0.003186,0.080921,276.964203,14.109229,0.809208,-1211.705566,0.080947,0.000000
55.710003,62.148590,-1211.750122,0.013357,0.003186,0.080921,276.450745,14.083072,0.809208,-1211.750122,0.080947,0.000000
55.910004,62.013420,-1211.750122,0.013357,0.003186,0.080921,275.849457,14.052442,0.809208,-1211.750122,0.080947,0.000000
56.110004,61.877502,-1211.750122,0.013344,0.003186,0.080921,275.244873,14.021643,0.809208,-1211.750122,0.080947,0.000000
56.310001,61.773979,-1211.794556,0.013331,0.003186,0.080921,274.784393,13.998184,0.809208,-1211.794556,0.080947,0.000000
56.510002,61.659294,-1211.705566,0.013340,0.003186,0.080921,274.274231,13.972197,0.809208,-1211.705566,0.080947,0.000000
56.710003,61.556892,-1211.794556,0.013318,0.003186,0.080921,273.818726,13.948992,0.809208,-1211.794556,0.080947,0.000000
56.910004,61.447411,-1211.794556,0.013331,0.003186,0.080921,273.331726,13.924182,0.809208,-1211.794556,0.080947,0.000000
57.110004,61.356552,-1211.794556,0.013310,0.003186,0.080921,272.927582,13.903593,0.809208,-1211.794556,0.080947,0.000000
57.310001,61.254898,-1211.794556,0.013310,0.003186,0.080921,272.475403,13.880559,0.809208,-1211.794556,0.080947,0.000000
57.510002,61.159195,-1211.750122,0.013379,0.003186,0.080921,272.049683,13.858871,0.809208,-1211.750122,0.080947,0.000000
57.710003,61.083977,-1211.794556,0.013318,0.003186,0.080921,271.715088,13.841827,0.809208,-1211.794556,0.080947,0.000000
57.910004,60.991631,-1211.794556,0.013379,0.003186,0.080921,271.304321,13.820901,0.809208,-1211.794556,0.080947,0.000000
58.110004,60.903000,-1211.705566,0.013331,0.003186,0.080921,270.910065,13.800817,0.809208,-1211.705566,0.080947,0.000000
58.310001,60.815125,-1211.794556,0.013323,0.003186,0.080921,270.519196,13.780904,0.809208,-1211.794556,0.080947,0.000000
58.510002,60.750328,-1211.750122,0.013361,0.003186,0.080921,270.230957,13.766222,0.809208,-1211.750122,0.080947,0.000000
58.710003,60.667664,-1211.750122,0.013366,0.003186,0.080921,269.863251,13.747489,0.809208,-1211.750122,0.080947,0.000000
58.910004,60.590584,-1211.794556,0.013379,0.003186,0.080921,269.520386,13.730022,0.809208,-1211.794556,0.080947,0.000000
59.110004,60.517967,-1211.750122,0.013344,0.003186,0.080921,269.197357,13.713568,0.809208,-1211.750122,0.080947,0.000000
59.310001,60.450195,-1211.794556,0.013353,0.003186,0.080921,268.895905,13.698210,0.809208,-1211.794556,0.080947,0.000000
59.510002,60.389877,-1211.838989,0.013370,0.003186,0.080921,268.627594,13.684542,0.809208,-1211.838989,0.080947,0.000000
59.710003,60.322472,-1211.750122,0.013348,0.003186,0.080921,268.327759,13.669268,0.809208,-1211.750122,0.080947,0.000000
59.910004,60.249863,-1211.750122,0.013305,0.003186,0.080921,268.004761,13.652814,0.809208,-1211.750122,0.080947,0.000000
60.110004,60.189537,-1211.838989,0.013387,0.003186,0.080921,267.736420,13.639144,0.809208,-1211.838989,0.080947,0.000000
60.310001,60.119530,-1211.838989,0.013396,0.003186,0.080921,267.425018,13.623281,0.809208,-1211.838989,0.080947,0.000000
60.510002,60.072243,-1211.750122,0.013379,0.003186,0.080921,267.214691,13.612565,0.809208,-1211.750122,0.080947,0.000000
60.710003,60.011543,-1211.794556,0.013353,0.003186,0.080921,266.944672,13.598810,0.809208,-1211.794556,0.080947,0.000000
60.910004,59.962021,-1211.838989,0.013353,0.003186,0.080921,266.724396,13.587588,0.809208,-1211.838989,0.080947,0.000000
61.110004,59.885307,-1211.794556,0.013340,0.003186,0.080921,266.383148,13.570205,0.809208,-1211.794556,0.080947,0.000000
61.310001,59.840256,-1211.794556,0.013379,0.003186,0.080921,266.182739,13.559997,0.809208,-1211.794556,0.080947,0.000000
61.510002,59.796310,-1211.750122,0.013383,0.003186,0.080921,265.987274,13.550037,0.809208,-1211.750122,0.080947,0.000000
61.710003,59.745667,-1211.794556,0.013323,0.003186,0.080921,265.761993,13.538561,0.809208,-1211.794556,0.080947,0.000000
61.910004,59.693169,-1211.794556,0.013314,0.003186,0.080921,265.528473,13.526666,0.809208,-1211.794556,0.080947,0.000000
62.110004,59.625397,-1211.794556,0.013379,0.003186,0.080921,265.227020,13.511308,0.809208,-1211.794556,0.080947,0.000000
62.310001,59.577728,-1211.838989,0.013344,0.003186,0.080921,265.014984,13.500506,0.809208,-1211.838989,0.080947,0.000000
62.510002,59.527458,-1211.750122,0.013323,0.003186,0.080921,264.791351,13.489115,0.809208,-1211.750122,0.080947,0.000000
62.710003,59.503258,-1211.838989,0.013366,0.003186,0.080921,264.683716,13.483631,0.809208,-1211.838989,0.080947,0.000000
62.910004,59.464531,-1211.838989,0.013379,0.003186,0.080921,264.511444,13.474855,0.809208,-1211.838989,0.080947,0.000000
63.110004,59.400856,-1211.838989,0.013340,0.003186,0.080921,264.228210,13.460426,0.809208,-1211.838989,0.080947,0.000000
63.310001,59.355423,-1211.794556,0.013396,0.003186,0.080921,264.026123,13.450131,0.809208,-1211.794556,0.080947,0.000000
63.510002,59.302917,-1211.794556,0.013374,0.003186,0.080921,263.792542,13.438233,0.809208,-1211.794556,0.080947,0.000000
63.710003,59.253769,-1211.750122,0.013336,0.003186,0.080921,263.573914,13.427095,0.809208,-1211.750122,0.080947,0.000000
63.910004,59.221367,-1211.750122,0.013327,0.003186,0.080921,263.429810,13.419754,0.809208,-1211.750122,0.080947,0.000000
64.110001,59.197906,-1211.794556,0.013387,0.003186,0.080921,263.325439,13.414437,0.809208,-1211.794556,0.080947,0.000000
64.310005,59.160675,-1211.750122,0.013366,0.003186,0.080921,263.159821,13.406001,0.809208,-1211.750122,0.080947,0.000000
64.510002,59.124924,-1211.794556,0.013387,0.003186,0.080921,263.000793,13.397900,0.809208,-1211.794556,0.080947,0.000000
64.710007,59.074280,-1211.794556,0.013370,0.003186,0.080921,262.775513,13.386423,0.809208,-1211.794556,0.080947,0.000000
64.910004,59.020287,-1211.750122,0.013340,0.003186,0.080921,262.535339,13.374188,0.809208,-1211.750122,0.080947,0.000000
65.110001,58.970764,-1211.794556,0.013374,0.003186,0.080921,262.315063,13.362967,0.809208,-1211.794556,0.080947,0.000000
65.310005,58.940598,-1211.750122,0.013370,0.003186,0.080921,262.180878,13.356131,0.809208,-1211.750122,0.080947,0.000000
65.510002,58.919373,-1211.883545,0.013336,0.003186,0.080921,262.086456,13.351321,0.809208,-1211.883545,0.080947,0.000000
65.710007,58.888092,-1211.838989,0.013353,0.003186,0.080921,261.947327,13.344233,0.809208,-1211.838989,0.080947,0.000000
65.910004,58.854210,-1211.838989,0.013331,0.003186,0.080921,261.796600,13.336555,0.809208,-1211.838989,0.080947,0.000000
66.110001,58.812134,-1211.794556,0.013336,0.003186,0.080921,261.609436,13.327020,0.809208,-1211.794556,0.080947,0.000000
66.310005,58.761490,-1211.794556,0.013379,0.003186,0.080921,261.384155,13.315543,0.809208,-1211.794556,0.080947,0.000000
66.510002,58.729836,-1211.838989,0.013353,0.003186,0.080921,261.243347,13.308371,0.809208,-1211.838989,0.080947,0.000000
66.710007,58.706009,-1211.794556,0.013387,0.003186,0.080921,261.137360,13.302972,0.809208,-1211.794556,0.080947,0.000000
66.910004,58.672867,-1211.794556,0.013344,0.003186,0.080921,260.989960,13.295462,0.809208,-1211.794556,0.080947,0.000000
67.110001,58.628555,-1211.794556,0.013396,0.003186,0.080921,260.792847,13.285420,0.809208,-1211.794556,0.080947,0.000000
67.310005,58.602112,-1211.883545,0.013383,0.003186,0.080921,260.675201,13.279428,0.809208,-1211.883545,0.080947,0.000000
67.510002,58.571579,-1211.883545,0.013361,0.003186,0.080921,260.539398,13.272510,0.809208,-1211.883545,0.080947,0.000000
67.710007,58.541420,-1211.838989,0.013336,0.003186,0.080921,260.405243,13.265675,0.809208,-1211.838989,0.080947,0.000000
67.910004,58.525032,-1211.838989,0.013383,0.003186,0.080921,260.332336,13.261962,0.809208,-1211.838989,0.080947,0.000000
68.110001,58.484818,-1211.794556,0.013379,0.003186,0.080921,260.153473,13.252849,0.809208,-1211.794556,0.080947,0.000000
68.310005,58.441246,-1211.838989,0.013361,0.003186,0.080921,259.959656,13.242975,0.809208,-1211.838989,0.080947,0.000000
68.510002,58.410339,-1211.838989,0.013396,0.003186,0.080921,259.822174,13.235972,0.809208,-1211.838989,0.080947,0.000000
68.710007,58.379807,-1211.838989,0.013383,0.003186,0.080921,259.686340,13.229053,0.809208,-1211.838989,0.080947,0.000000
68.910004,58.365654,-1211.838989,0.013340,0.003186,0.080921,259.623383,13.225846,0.809208,-1211.838989,0.080947,0.000000
69.110001,58.342567,-1211.883545,0.013366,0.003186,0.080921,259.520691,13.220614,0.809208,-1211.883545,0.080947,0.000000
69.310005,58.301239,-1211.883545,0.013370,0.003186,0.080921,259.336853,13.211250,0.809208,-1211.883545,0.080947,0.000000
69.510002,58.276657,-1211.838989,0.013396,0.003186,0.080921,259.227509,13.205680,0.809208,-1211.838989,0.080947,0.000000
69.710007,58.242775,-1211.838989,0.013387,0.003186,0.080921,259.076813,13.198002,0.809208,-1211.838989,0.080947,0.000000
69.910004,58.208145,-1211.838989,0.013392,0.003186,0.080921,258.922760,13.190154,0.809208,-1211.838989,0.080947,0.000000
70.110001,58.187660,-1211.883545,0.013383,0.003186,0.080921,258.831635,13.185513,0.809208,-1211.883545,0.080947,0.000000
70.310005,58.155266,-1211.883545,0.013396,0.003186,0.080921,258.687531,13.178172,0.809208,-1211.883545,0.080947,0.000000
70.510002,58.145210,-1211.838989,0.013383,0.003186,0.080921,258.642822,13.175893,0.809208,-1211.838989,0.080947,0.000000
70.710007,58.111328,-1211.883545,0.013370,0.003186,0.080921,258.492096,13.168216,0.809208,-1211.883545,0.080947,0.000000
70.910004,58.082657,-1211.838989,0.013357,0.003186,0.080921,258.364563,13.161718,0.809208,-1211.838989,0.080947,0.000000
71.110001,58.055099,-1211.883545,0.013331,0.003186,0.080921,258.241974,13.155474,0.809208,-1211.883545,0.080947,0.000000
71.310005,58.021584,-1211.838989,0.013383,0.003186,0.080921,258.092896,13.147879,0.809208,-1211.838989,0.080947,0.000000
71.510002,58.008553,-1211.838989,0.013331,0.003186,0.080921,258.034943,13.144926,0.809208,-1211.838989,0.080947,0.000000
71.710007,57.981369,-1211.838989,0.013400,0.003186,0.080921,257.914001,13.138766,0.809208,-1211.838989,0.080947,0.000000
71.910004,57.967590,-1211.883545,0.013318,0.003186,0.080921,257.852722,13.135644,0.809208,-1211.883545,0.080947,0.000000
72.110001,57.939667,-1211.838989,0.013353,0.003186,0.080921,257.728516,13.129316,0.809208,-1211.838989,0.080947,0.000000
72.310005,57.910248,-1211.838989,0.013336,0.003186,0.080921,257.597656,13.122650,0.809208,-1211.838989,0.080947,0.000000
72.510002,57.885300,-1211.883545,0.013370,0.003186,0.080921,257.486664,13.116996,0.809208,-1211.883545,0.080947,0.000000
72.710007,57.867798,-1211.883545,0.013370,0.003186,0.080921,257.408813,13.113030,0.809208,-1211.883545,0.080947,0.000000
72.910004,57.835770,-1211.883545,0.013409,0.003186,0.080921,257.266357,13.105772,0.809208,-1211.883545,0.080947,0.000000
73.110001,57.815292,-1211.883545,0.013383,0.003186,0.080921,257.175262,13.101132,0.809208,-1211.883545,0.080947,0.000000
73.310005,57.794067,-1211.883545,0.013353,0.003186,0.080921,257.080841,13.096323,0.809208,-1211.883545,0.080947,0.000000
73.510002,57.772469,-1211.883545,0.013336,0.003186,0.080921,256.984772,13.091429,0.809208,-1211.883545,0.080947,0.000000
73.710007,57.751984,-1211.838989,0.013331,0.003186,0.080921,256.893646,13.086787,0.809208,-1211.838989,0.080947,0.000000
73.910004,57.725922,-1211.927979,0.013336,0.003186,0.080921,256.777710,13.080881,0.809208,-1211.927979,0.080947,0.000000
74.110001,57.711029,-1211.883545,0.013387,0.003186,0.080921,256.711487,13.077506,0.809208,-1211.883545,0.080947,0.000000
74.310005,57.678627,-1211.883545,0.013392,0.003186,0.080921,256.567352,13.070164,0.809208,-1211.883545,0.080947,0.000000
74.510002,57.661125,-1211.838989,0.013387,0.003186,0.080921,256.489502,13.066197,0.809208,-1211.838989,0.080947,0.000000
74.710007,57.633202,-1211.883545,0.013392,0.003186,0.080921,256.365295,13.059870,0.809208,-1211.883545,0.080947,0.000000
74.910004,57.619797,-1211.838989,0.013379,0.003186,0.080921,256.305664,13.056832,0.809208,-1211.838989,0.080947,0.000000
75.110001,57.607132,-1211.838989,0.013400,0.003186,0.080921,256.249329,13.053963,0.809208,-1211.838989,0.080947,0.000000
75.310005,57.584419,-1211.838989,0.013396,0.003186,0.080921,256.148285,13.048817,0.809208,-1211.838989,0.080947,0.000000
75.510002,57.557610,-1211.838989,0.013383,0.003186,0.080921,256.029022,13.042741,0.809208,-1211.838989,0.080947,0.000000
75.710007,57.535263,-1211.883545,0.013387,0.003186,0.080921,255.929626,13.037677,0.809208,-1211.883545,0.080947,0.000000
75.910004,57.522980,-1211.794556,0.013405,0.003186,0.080921,255.875000,13.034894,0.809208,-1211.794556,0.080947,0.000000
76.110001,57.502129,-1211.883545,0.013379,0.003186,0.080921,255.782242,13.030169,0.809208,-1211.883545,0.080947,0.000000
76.310005,57.490952,-1211.927979,0.013400,0.003186,0.080921,255.732529,13.027636,0.809208,-1211.927979,0.080947,0.000000
76.510002,57.469360,-1211.838989,0.013344,0.003186,0.080921,255.636490,13.022743,0.809208,-1211.838989,0.080947,0.000000
76.710007,57.436218,-1211.838989,0.013357,0.003186,0.080921,255.489059,13.015233,0.809208,-1211.838989,0.080947,0.000000
76.910004,57.417221,-1211.838989,0.013405,0.003186,0.080921,255.404556,13.010928,0.809208,-1211.838989,0.080947,0.000000
77.110001,57.391907,-1211.838989,0.013370,0.003186,0.080921,255.291946,13.005192,0.809208,-1211.838989,0.080947,0.000000
77.310005,57.388176,-1211.883545,0.013387,0.003186,0.080921,255.275360,13.004347,0.809208,-1211.883545,0.080947,0.000000
77.510002,57.379242,-1211.883545,0.013327,0.003186,0.080921,255.235611,13.002322,0.809208,-1211.883545,0.080947,0.000000
77.710007,57.346100,-1211.838989,0.013392,0.003186,0.080921,255.088196,12.994811,0.809208,-1211.838989,0.080947,0.000000
77.910004,57.326736,-1211.883545,0.013392,0.003186,0.080921,255.002060,12.990424,0.809208,-1211.883545,0.080947,0.000000
78.110001,57.314079,-1211.794556,0.013383,0.003186,0.080921,254.945755,12.987556,0.809208,-1211.794556,0.080947,0.000000
78.310005,57.287270,-1211.838989,0.013400,0.003186,0.080921,254.826508,12.981481,0.809208,-1211.838989,0.080947,0.000000
78.510002,57.281311,-1211.883545,0.013366,0.003186,0.080921,254.800003,12.980131,0.809208,-1211.883545,0.080947,0.000000
78.710007,57.263062,-1211.838989,0.013383,0.003186,0.080921,254.718826,12.975996,0.809208,-1211.838989,0.080947,0.000000
78.910004,57.255615,-1211.838989,0.013353,0.003186,0.080921,254.685699,12.974308,0.809208,-1211.838989,0.080947,0.000000
79.110001,57.239227,-1211.883545,0.013361,0.003186,0.080921,254.612793,12.970594,0.809208,-1211.883545,0.080947,0.000000
79.310005,57.204971,-1211.838989,0.013405,0.003186,0.080921,254.460419,12.962831,0.809208,-1211.838989,0.080947,0.000000
79.510002,57.181511,-1211.838989,0.013387,0.003186,0.080921,254.356064,12.957516,0.809208,-1211.838989,0.080947,0.000000
79.710007,57.162148,-1211.838989,0.013331,0.003186,0.080921,254.269928,12.953128,0.809208,-1211.838989,0.080947,0.000000
79.910004,57.150604,-1211.838989,0.013387,0.003186,0.080921,254.218582,12.950512,0.809208,-1211.838989,0.080947,0.000000
80.110001,57.146881,-1211.883545,0.013361,0.003186,0.080921,254.202026,12.949668,0.809208,-1211.883545,0.080947,0.000000
80.310005,57.143532,-1211.883545,0.013413,0.003186,0.080921,254.187119,12.948909,0.809208,-1211.883545,0.080947,0.000000
80.510002,57.115227,-1211.794556,0.013383,0.003186,0.080921,254.061218,12.942495,0.809208,-1211.794556,0.080947,0.000000
80.710007,57.097359,-1211.927979,0.013366,0.003186,0.080921,253.981735,12.938446,0.809208,-1211.927979,0.080947,0.000000
80.910004,57.069801,-1211.838989,0.013413,0.003186,0.080921,253.859161,12.932202,0.809208,-1211.838989,0.080947,0.000000
81.110001,57.049324,-1211.838989,0.013396,0.003186,0.080921,253.768066,12.927562,0.809208,-1211.838989,0.080947,0.000000
81.310005,57.041504,-1211.883545,0.013392,0.003186,0.080921,253.733276,12.925789,0.809208,-1211.883545,0.080947,0.000000
81.510002,57.021767,-1211.838989,0.013387,0.003186,0.080921,253.645493,12.921317,0.809208,-1211.838989,0.080947,0.000000
81.710007,57.013573,-1211.838989,0.013400,0.003186,0.080921,253.609039,12.919459,0.809208,-1211.838989,0.080947,0.000000
81.910004,57.009476,-1211.883545,0.013353,0.003186,0.080921,253.590820,12.918532,0.809208,-1211.883545,0.080947,0.000000
82.110001,56.984154,-1211.927979,0.013392,0.003186,0.080921,253.478180,12.912793,0.809208,-1211.927979,0.080947,0.000000
82.310005,56.964050,-1211.883545,0.013374,0.003186,0.080921,253.388748,12.908237,0.809208,-1211.883545,0.080947,0.000000
82.400002,56.966652,-1211.838989,0.013383,0.003186,0.080921,253.400330,12.908828,0.809208,-1211.838989,0.080947,0.000000