File: Data/Symmetrical membranes compression/Sterlitech PVDF 045um test 2_10272023_143615.csv
Time (sec),S:Load (lbs),S:HL1 (DIM),S:LVDT (in),S:Position (in),Ch:Position (mm),Ch:Load (N),Ch:Stress (MPa),Ch:Strain (mm/mm),Ch:HL1 (DIM),Set Point (),Cycles ()
0.010000,0.004463,-1209.214600,0.008912,-0.001838,-0.046674,0.019853,0.001011,-0.466740,-1209.214600,-0.046466,0.000000
0.200000,0.007072,-1209.214600,0.008981,-0.001838,-0.046674,0.031460,0.001603,-0.466740,-1209.214600,-0.046466,0.000000
0.390000,-0.026443,-1209.303589,0.008985,-0.001837,-0.046657,-0.117626,-0.005992,-0.466567,-1209.303589,-0.046240,0.000000
0.580000,0.020851,-1209.214600,0.008916,-0.001736,-0.044098,0.092750,0.004725,-0.440984,-1209.214600,-0.043084,0.000000
0.770000,-0.006706,-1209.303589,0.008985,-0.001622,-0.041202,-0.029831,-0.001520,-0.412019,-1209.303589,-0.039910,0.000000
0.960000,0.016380,-1209.259155,0.009097,-0.001499,-0.038063,0.072863,0.003712,-0.380625,-1209.259155,-0.036753,0.000000
1.150000,0.014519,-1209.214600,0.009257,-0.001367,-0.034724,0.064583,0.003290,-0.347237,-1209.214600,-0.033579,0.000000
1.340000,0.002235,-1209.259155,0.009451,-0.001248,-0.031688,0.009944,0.000507,-0.316884,-1209.259155,-0.030422,0.000000
1.530000,0.000740,-1209.214600,0.009589,-0.001123,-0.028523,0.003292,0.000168,-0.285230,-1209.214600,-0.027248,0.000000
1.720000,0.005585,-1209.259155,0.009653,-0.001004,-0.025505,0.024842,0.001266,-0.255051,-1209.259155,-0.024092,0.000000
1.910000,0.024574,-1209.303589,0.009766,-0.000878,-0.022296,0.109312,0.005569,-0.222963,-1209.303589,-0.020917,0.000000
2.100000,0.009682,-1209.214600,0.009912,-0.000749,-0.019036,0.043066,0.002194,-0.190356,-1209.214600,-0.017761,0.000000
2.290000,0.005211,-1209.303589,0.010093,-0.000621,-0.015783,0.023179,0.001181,-0.157835,-1209.303589,-0.014587,0.000000
2.480000,0.013405,-1209.214600,0.010154,-0.000503,-0.012783,0.059628,0.003038,-0.127829,-1209.214600,-0.011430,0.000000
2.670000,0.053993,-1209.303589,0.010270,-0.000379,-0.009635,0.240174,0.012235,-0.096349,-1209.303589,-0.008256,0.000000
2.860000,0.084152,-1209.259155,0.010447,-0.000254,-0.006461,0.374328,0.019069,-0.064608,-1209.259155,-0.005099,0.000000
3.050000,0.212997,-1209.259155,0.010568,-0.000131,-0.003330,0.947460,0.048266,-0.033301,-1209.259155,-0.001925,0.000000
3.240000,0.577545,-1209.303589,0.010718,-0.000001,-0.000017,2.569049,0.130874,-0.000173,-1209.303589,0.001231,0.000000
3.430000,0.664680,-1209.214600,0.010792,-0.000005,-0.000139,2.956646,0.150619,-0.001387,-1209.214600,0.000061,0.000000
3.620000,0.642342,-1209.259155,0.010792,-0.000006,-0.000147,2.857278,0.145557,-0.001474,-1209.259155,0.000061,0.000000
3.810000,0.635635,-1209.303589,0.010796,-0.000006,-0.000147,2.827447,0.144037,-0.001474,-1209.303589,0.000061,0.000000
4.000000,0.615898,-1209.259155,0.010753,-0.000006,-0.000147,2.739652,0.139565,-0.001474,-1209.259155,0.000356,0.000000
4.190000,0.637871,-1209.303589,0.010736,-0.000006,-0.000147,2.837391,0.144544,-0.001474,-1209.303589,0.000676,0.000000
4.380000,0.628563,-1209.259155,0.010766,-0.000005,-0.000130,2.795988,0.142434,-0.001301,-1209.259155,0.000989,0.000000
4.570000,0.708992,-1209.214600,0.010774,0.000014,0.000364,3.153754,0.160660,0.003642,-1209.214600,0.001310,0.000000
4.760000,0.761124,-1209.214600,0.010753,0.000029,0.000746,3.385647,0.172473,0.007458,-1209.214600,0.001622,0.000000
4.950000,0.799110,-1209.303589,0.010805,0.000041,0.001049,3.554621,0.181081,0.010494,-1209.303589,0.001943,0.000000
5.140000,0.840073,-1209.259155,0.010792,0.000051,0.001292,3.736830,0.190363,0.012922,-1209.259155,0.002255,0.000000
5.330000,0.943588,-1209.259155,0.010813,0.000064,0.001630,4.197290,0.213820,0.016304,-1209.259155,0.002576,0.000000
5.520000,0.987160,-1209.303589,0.010861,0.000076,0.001934,4.391106,0.223694,0.019339,-1209.303589,0.002888,0.000000
5.710000,1.010986,-1209.303589,0.010796,0.000082,0.002073,4.497092,0.229093,0.020727,-1209.303589,0.003209,0.000000
5.900000,1.086205,-1209.259155,0.010856,0.000092,0.002342,4.831679,0.246137,0.023415,-1209.259155,0.003521,0.000000
6.090000,1.161797,-1209.259155,0.010869,0.000106,0.002688,5.167929,0.263267,0.026884,-1209.259155,0.003842,0.000000
6.280000,1.254517,-1209.214600,0.010908,0.000126,0.003209,5.580369,0.284278,0.032087,-1209.214600,0.004154,0.000000
6.470000,1.339424,-1209.259155,0.010900,0.000139,0.003521,5.958056,0.303518,0.035209,-1209.259155,0.004475,0.000000
6.660000,1.382988,-1209.348145,0.010878,0.000150,0.003816,6.151838,0.313390,0.038158,-1209.348145,0.004787,0.000000
6.850000,1.436607,-1209.259155,0.010887,0.000163,0.004145,6.390349,0.325540,0.041454,-1209.259155,0.005108,0.000000
7.040000,1.516670,-1209.303589,0.010938,0.000177,0.004501,6.746486,0.343682,0.045009,-1209.303589,0.005429,0.000000
7.230000,1.594124,-1209.303589,0.010925,0.000189,0.004796,7.091017,0.361234,0.047958,-1209.303589,0.005741,0.000000
7.420001,1.696152,-1209.259155,0.010960,0.000202,0.005143,7.544860,0.384353,0.051427,-1209.259155,0.006062,0.000000
7.610000,1.756104,-1209.303589,0.010921,0.000212,0.005394,7.811539,0.397939,0.053942,-1209.303589,0.006374,0.000000
7.800000,1.791855,-1209.259155,0.010973,0.000220,0.005576,7.970569,0.406040,0.055763,-1209.259155,0.006695,0.000000
7.990000,1.902077,-1209.259155,0.011003,0.000234,0.005941,8.460860,0.431017,0.059405,-1209.259155,0.007007,0.000000
8.180000,2.037621,-1209.303589,0.011046,0.000251,0.006374,9.063788,0.461731,0.063741,-1209.303589,0.007328,0.000000
8.370001,2.071877,-1209.259155,0.011012,0.000262,0.006660,9.216167,0.469494,0.066603,-1209.259155,0.007640,0.000000
8.560000,2.156410,-1209.303589,0.011007,0.000272,0.006912,9.592192,0.488650,0.069118,-1209.303589,0.007961,0.000000
8.750000,2.261787,-1209.259155,0.011037,0.000287,0.007285,10.060933,0.512528,0.072847,-1209.259155,0.008273,0.000000
8.940001,2.307220,-1209.348145,0.011042,0.000297,0.007554,10.263029,0.522824,0.075536,-1209.348145,0.008594,0.000000
9.130000,2.444626,-1209.214600,0.011072,0.000311,0.007892,10.874239,0.553960,0.078918,-1209.214600,0.008906,0.000000
9.320001,2.607353,-1209.348145,0.011033,0.000325,0.008256,11.598086,0.590835,0.082560,-1209.348145,0.009227,0.000000
9.510000,2.640488,-1209.348145,0.011119,0.000331,0.008395,11.745476,0.598343,0.083948,-1209.348145,0.009539,0.000000
9.700001,2.732841,-1209.303589,0.011141,0.000340,0.008646,12.156286,0.619271,0.086463,-1209.303589,0.009860,0.000000
9.890000,2.926476,-1209.348145,0.011141,0.000355,0.009011,13.017613,0.663149,0.090105,-1209.348145,0.010173,0.000000
10.080001,3.078026,-1209.303589,0.011163,0.000370,0.009409,13.691743,0.697491,0.094094,-1209.303589,0.010493,0.000000
10.270000,3.184151,-1209.259155,0.011145,0.000384,0.009756,14.163810,0.721539,0.097563,-1209.259155,0.010806,0.000000
10.460000,3.331612,-1209.348145,0.011163,0.000395,0.010034,14.819749,0.754954,0.100338,-1209.348145,0.011127,0.000000
10.650001,3.493965,-1209.259155,0.011154,0.000409,0.010389,15.541933,0.791744,0.103894,-1209.259155,0.011439,0.000000
10.840000,3.622810,-1209.348145,0.011158,0.000420,0.010667,16.115065,0.820941,0.106669,-1209.348145,0.011760,0.000000
11.030001,3.722603,-1209.259155,0.011201,0.000428,0.010875,16.558964,0.843554,0.108750,-1209.259155,0.012072,0.000000
11.220000,3.998535,-1209.259155,0.011180,0.000447,0.011352,17.786373,0.906081,0.113520,-1209.259155,0.012393,0.000000
11.410001,4.207062,-1209.348145,0.011236,0.000461,0.011699,18.713945,0.953334,0.116989,-1209.348145,0.012705,0.000000
11.600000,4.302765,-1209.303589,0.011223,0.000469,0.011924,19.139654,0.975020,0.119244,-1209.303589,0.013026,0.000000
11.790001,4.489693,-1209.303589,0.011197,0.000483,0.012263,19.971151,1.017379,0.122626,-1209.303589,0.013338,0.000000
11.980000,4.705666,-1209.303589,0.011257,0.000495,0.012575,20.931847,1.066319,0.125748,-1209.303589,0.013659,0.000000
12.170001,4.953667,-1209.348145,0.011266,0.000510,0.012965,22.035009,1.122517,0.129651,-1209.348145,0.013971,0.000000
12.360001,5.055328,-1209.348145,0.011240,0.000518,0.013156,22.487225,1.145554,0.131558,-1209.348145,0.014292,0.000000
12.550000,5.322319,-1209.348145,0.011257,0.000534,0.013563,23.674858,1.206055,0.135635,-1209.348145,0.014613,0.000000
12.740001,5.478714,-1209.303589,0.011318,0.000545,0.013832,24.370537,1.241494,0.138323,-1209.303589,0.014925,0.000000
12.930000,5.704742,-1209.348145,0.011339,0.000555,0.014092,25.375961,1.292713,0.140924,-1209.348145,0.015246,0.000000
13.120001,5.931892,-1209.348145,0.011270,0.000570,0.014474,26.386375,1.344186,0.144740,-1209.348145,0.015558,0.000000
13.310000,6.300911,-1209.348145,0.011305,0.000585,0.014864,28.027851,1.427807,0.148643,-1209.348145,0.015879,0.000000
13.500001,6.568275,-1209.259155,0.011331,0.000599,0.015211,29.217148,1.488392,0.152112,-1209.259155,0.016191,0.000000
13.690001,6.659134,-1209.392578,0.011352,0.000608,0.015445,29.621307,1.508981,0.154453,-1209.392578,0.016512,0.000000
13.880001,6.794678,-1209.392578,0.011369,0.000616,0.015636,30.224236,1.539696,0.156361,-1209.392578,0.016824,0.000000
14.070001,7.132790,-1209.259155,0.011357,0.000633,0.016087,31.728233,1.616313,0.160871,-1209.259155,0.017145,0.000000
14.260000,7.332756,-1209.392578,0.011374,0.000645,0.016382,32.617729,1.661626,0.163819,-1209.392578,0.017457,0.000000
14.450001,7.503304,-1209.303589,0.011369,0.000653,0.016581,33.376362,1.700273,0.165814,-1209.303589,0.017778,0.000000
14.640000,7.697678,-1209.303589,0.011378,0.000665,0.016894,34.240978,1.744319,0.168936,-1209.303589,0.018090,0.000000
14.830001,7.980309,-1209.303589,0.011404,0.000680,0.017275,35.498184,1.808364,0.172752,-1209.303589,0.018411,0.000000
15.020000,8.291618,-1209.303589,0.011408,0.000693,0.017596,36.882961,1.878908,0.175960,-1209.303589,0.018723,0.000000
15.210001,8.693405,-1209.303589,0.011421,0.000709,0.018012,38.670197,1.969954,0.180123,-1209.303589,0.019044,0.000000
15.400001,8.894485,-1209.303589,0.011417,0.000723,0.018377,39.564648,2.015519,0.183765,-1209.303589,0.019357,0.000000
15.590001,9.189034,-1209.348145,0.011421,0.000736,0.018689,40.874863,2.082265,0.186887,-1209.348145,0.019677,0.000000
15.780001,9.313034,-1209.348145,0.011503,0.000747,0.018975,41.426445,2.110364,0.189749,-1209.348145,0.019990,0.000000
15.970001,9.454536,-1209.348145,0.011486,0.000758,0.019261,42.055878,2.142429,0.192611,-1209.348145,0.020310,0.000000
16.160000,9.853348,-1209.437012,0.011525,0.000774,0.019660,43.829880,2.232800,0.196600,-1209.437012,0.020623,0.000000
16.350000,9.981071,-1209.303589,0.011469,0.000781,0.019842,44.398022,2.261743,0.198422,-1209.303589,0.020944,0.000000
16.540001,10.202629,-1209.348145,0.011477,0.000796,0.020224,45.383560,2.311949,0.202237,-1209.348145,0.021256,0.000000
16.730001,10.631607,-1209.392578,0.011525,0.000813,0.020640,47.291752,2.409157,0.206400,-1209.392578,0.021577,0.000000
16.920000,10.692299,-1209.303589,0.011503,0.000820,0.020839,47.561722,2.422910,0.208394,-1209.303589,0.021889,0.000000
17.110001,10.920937,-1209.437012,0.011555,0.000832,0.021143,48.578751,2.474720,0.211430,-1209.437012,0.022210,0.000000
17.300001,11.085152,-1209.348145,0.011538,0.000842,0.021394,49.309216,2.511931,0.213945,-1209.348145,0.022522,0.000000
17.490002,11.307091,-1209.392578,0.011538,0.000854,0.021698,50.296452,2.562223,0.216980,-1209.392578,0.022843,0.000000
17.680000,11.667542,-1209.348145,0.011581,0.000869,0.022071,51.899818,2.643903,0.220709,-1209.348145,0.023155,0.000000
17.870001,11.906235,-1209.303589,0.011568,0.000882,0.022400,52.961578,2.697991,0.224005,-1209.303589,0.023476,0.000000
18.060001,12.262970,-1209.481567,0.011632,0.000896,0.022765,54.548416,2.778829,0.227647,-1209.481567,0.023797,0.000000
18.250000,12.367973,-1209.303589,0.011576,0.000906,0.023025,55.015491,2.802623,0.230249,-1209.303589,0.024109,0.000000
18.440001,12.633102,-1209.392578,0.011654,0.000923,0.023432,56.194847,2.862702,0.234325,-1209.392578,0.024430,0.000000
18.630001,12.775352,-1209.392578,0.011624,0.000933,0.023701,56.827606,2.894936,0.237013,-1209.392578,0.024742,0.000000
18.820002,12.929512,-1209.348145,0.011641,0.000943,0.023961,57.513344,2.929869,0.239615,-1209.348145,0.025063,0.000000
19.010000,13.314178,-1209.437012,0.011645,0.000958,0.024334,59.224422,3.017036,0.243344,-1209.437012,0.025375,0.000000
19.200001,13.315666,-1209.348145,0.011663,0.000966,0.024542,59.231041,3.017373,0.245425,-1209.348145,0.025696,0.000000
19.390001,13.676125,-1209.392578,0.011654,0.000978,0.024837,60.834442,3.099054,0.248374,-1209.392578,0.026008,0.000000
19.580002,13.992264,-1209.392578,0.011745,0.000993,0.025210,62.240700,3.170692,0.252103,-1209.392578,0.026329,0.000000
19.770000,14.270058,-1209.348145,0.011740,0.001008,0.025592,63.476387,3.233641,0.255919,-1209.348145,0.026641,0.000000
19.960001,14.527740,-1209.392578,0.011745,0.001019,0.025878,64.622620,3.292033,0.258780,-1209.392578,0.026962,0.000000
20.150002,14.722862,-1209.437012,0.011732,0.001030,0.026173,65.490562,3.336248,0.261729,-1209.437012,0.027274,0.000000
20.340000,15.001770,-1209.348145,0.011775,0.001044,0.026528,66.731209,3.399450,0.265285,-1209.348145,0.027595,0.000000
20.530001,15.257217,-1209.392578,0.011779,0.001056,0.026832,67.867493,3.457335,0.268320,-1209.392578,0.027907,0.000000
20.720001,15.428505,-1209.303589,0.011753,0.001067,0.027092,68.629417,3.496149,0.270921,-1209.303589,0.028228,0.000000
20.910002,15.823219,-1209.392578,0.011770,0.001083,0.027508,70.385193,3.585593,0.275084,-1209.392578,0.028540,0.000000
21.100000,16.087975,-1209.303589,0.011792,0.001094,0.027777,71.562881,3.645587,0.277772,-1209.303589,0.028861,0.000000
21.290001,16.198196,-1209.392578,0.011801,0.001103,0.028020,72.053177,3.670564,0.280201,-1209.392578,0.029173,0.000000
21.480001,16.556419,-1209.437012,0.011852,0.001117,0.028376,73.646629,3.751738,0.283756,-1209.437012,0.029494,0.000000
21.670000,16.927307,-1209.348145,0.011814,0.001133,0.028775,75.296425,3.835783,0.287746,-1209.348145,0.029807,0.000000
21.860001,17.165993,-1209.437012,0.011874,0.001144,0.029069,76.358147,3.889869,0.290694,-1209.437012,0.030127,0.000000
22.050001,17.547676,-1209.392578,0.011848,0.001158,0.029416,78.055962,3.976360,0.294163,-1209.392578,0.030440,0.000000
22.240002,17.727905,-1209.348145,0.011826,0.001171,0.029746,78.857658,4.017201,0.297459,-1209.348145,0.030761,0.000000
22.430000,17.982239,-1209.392578,0.011835,0.001183,0.030041,79.988991,4.074833,0.300407,-1209.392578,0.031073,0.000000
22.620001,18.188904,-1209.392578,0.011887,0.001193,0.030301,80.908287,4.121665,0.303009,-1209.392578,0.031394,0.000000
22.810001,18.458130,-1209.437012,0.011908,0.001206,0.030622,82.105865,4.182672,0.306217,-1209.437012,0.031706,0.000000
23.000002,18.833481,-1209.392578,0.011895,0.001219,0.030960,83.775505,4.267728,0.309600,-1209.392578,0.032027,0.000000
23.190001,18.871086,-1209.392578,0.011947,0.001226,0.031142,83.942787,4.276249,0.311421,-1209.392578,0.032348,0.000000
23.380001,19.178665,-1209.437012,0.011878,0.001238,0.031446,85.310966,4.345948,0.314456,-1209.437012,0.032660,0.000000
23.570002,19.803513,-1209.392578,0.011960,0.001256,0.031905,88.090424,4.487540,0.319052,-1209.392578,0.032981,0.000000
23.760000,20.203812,-1209.392578,0.011921,0.001272,0.032304,89.871040,4.578249,0.323042,-1209.392578,0.033293,0.000000
23.950001,20.573952,-1209.392578,0.011999,0.001285,0.032651,91.517509,4.662124,0.326511,-1209.392578,0.033614,0.000000
24.140001,20.815994,-1209.392578,0.011952,0.001299,0.032989,92.594170,4.716971,0.329893,-1209.392578,0.033926,0.000000
24.330002,21.079254,-1209.437012,0.011960,0.001311,0.033310,93.765205,4.776627,0.333102,-1209.437012,0.034247,0.000000
24.520000,21.142189,-1209.348145,0.012025,0.001321,0.033562,94.045151,4.790888,0.335617,-1209.348145,0.034559,0.000000
24.710001,21.554405,-1209.392578,0.012021,0.001333,0.033865,95.878784,4.884298,0.338652,-1209.392578,0.034880,0.000000
24.900002,21.864967,-1209.348145,0.012003,0.001347,0.034221,97.260231,4.954672,0.342207,-1209.348145,0.035192,0.000000
25.090002,22.233986,-1209.437012,0.012029,0.001360,0.034550,98.901711,5.038293,0.345503,-1209.437012,0.035513,0.000000
25.280001,22.167702,-1209.437012,0.012008,0.001364,0.034646,98.606865,5.023273,0.346457,-1209.437012,0.035825,0.000000
25.470001,22.967934,-1209.392578,0.012025,0.001388,0.035261,102.166473,5.204608,0.352614,-1209.392578,0.036146,0.000000
25.660002,23.315353,-1209.392578,0.012029,0.001402,0.035608,103.711868,5.283335,0.356083,-1209.392578,0.036458,0.000000
25.850000,23.467285,-1209.392578,0.012094,0.001411,0.035851,104.387695,5.317763,0.358511,-1209.392578,0.036779,0.000000
26.040001,23.774490,-1209.392578,0.012081,0.001425,0.036198,105.754211,5.387376,0.361980,-1209.392578,0.037091,0.000000
26.230001,24.043716,-1209.437012,0.012120,0.001437,0.036493,106.951790,5.448384,0.364929,-1209.437012,0.037412,0.000000
26.420002,24.244797,-1209.481567,0.012115,0.001447,0.036762,107.846245,5.493949,0.367617,-1209.481567,0.037724,0.000000
26.610001,24.695740,-1209.437012,0.012124,0.001462,0.037143,109.852135,5.596135,0.371433,-1209.437012,0.038045,0.000000
26.800001,24.787712,-1209.437012,0.012158,0.001469,0.037308,110.261253,5.616976,0.373081,-1209.437012,0.038357,0.000000
26.990002,25.028641,-1209.348145,0.012146,0.001480,0.037594,111.332954,5.671571,0.375943,-1209.348145,0.038678,0.000000
27.180002,25.194344,-1209.481567,0.012107,0.001489,0.037828,112.070038,5.709120,0.378284,-1209.481567,0.038990,0.000000
27.370001,25.660553,-1209.437012,0.012124,0.001506,0.038245,114.143837,5.814764,0.382447,-1209.437012,0.039311,0.000000
27.560001,26.225075,-1209.481567,0.012197,0.001522,0.038661,116.654961,5.942687,0.386610,-1209.481567,0.039624,0.000000
27.750002,26.668938,-1209.437012,0.012133,0.001537,0.039034,118.629356,6.043268,0.390339,-1209.437012,0.039944,0.000000
27.940001,26.812675,-1209.392578,0.012210,0.001548,0.039329,119.268738,6.075840,0.393287,-1209.392578,0.040257,0.000000
28.130001,27.123611,-1209.526001,0.012215,0.001561,0.039641,120.651848,6.146298,0.396409,-1209.526001,0.040578,0.000000
28.320002,27.448318,-1209.437012,0.012189,0.001574,0.039988,122.096222,6.219878,0.399878,-1209.437012,0.040890,0.000000
28.510002,27.718285,-1209.437012,0.012219,0.001586,0.040274,123.297089,6.281053,0.402740,-1209.437012,0.041211,0.000000
28.700001,27.886223,-1209.526001,0.012249,0.001598,0.040586,124.044113,6.319108,0.405862,-1209.526001,0.041531,0.000000
28.890001,28.151726,-1209.437012,0.012275,0.001609,0.040881,125.225128,6.379272,0.408810,-1209.437012,0.041844,0.000000
29.080002,28.223595,-1209.437012,0.012245,0.001617,0.041072,125.544823,6.395558,0.410718,-1209.437012,0.042165,0.000000
29.270000,28.518517,-1209.392578,0.012253,0.001631,0.041419,126.856697,6.462388,0.414187,-1209.392578,0.042477,0.000000
29.460001,29.192879,-1209.481567,0.012288,0.001647,0.041844,129.856415,6.615201,0.418437,-1209.481567,0.042798,0.000000
29.650002,29.368271,-1209.437012,0.012279,0.001658,0.042112,130.636597,6.654945,0.421125,-1209.437012,0.043110,0.000000
29.840002,29.602119,-1209.526001,0.012340,0.001668,0.042364,131.676804,6.707936,0.423640,-1209.526001,0.043431,0.000000
30.030001,29.975983,-1209.481567,0.012253,0.001683,0.042754,133.339828,6.792655,0.427543,-1209.481567,0.043743,0.000000
30.220001,30.098862,-1209.437012,0.012309,0.001693,0.043006,133.886429,6.820500,0.430057,-1209.437012,0.044064,0.000000
30.410002,30.563583,-1209.481567,0.012335,0.001708,0.043387,135.953613,6.925807,0.433873,-1209.481567,0.044376,0.000000
30.600002,30.918083,-1209.437012,0.012370,0.001720,0.043682,137.530502,7.006138,0.436822,-1209.437012,0.044697,0.000000
30.790001,31.008194,-1209.437012,0.012331,0.001730,0.043934,137.931335,7.026557,0.439337,-1209.437012,0.045009,0.000000
30.980001,31.007454,-1209.570557,0.012340,0.001736,0.044090,137.928040,7.026390,0.440898,-1209.570557,0.045330,0.000000
31.170002,31.514999,-1209.392578,0.012413,0.001753,0.044515,140.185715,7.141401,0.445147,-1209.392578,0.045642,0.000000
31.360001,31.789436,-1209.526001,0.012383,0.001764,0.044801,141.406479,7.203589,0.448009,-1209.526001,0.045963,0.000000
31.550001,32.442947,-1209.481567,0.012378,0.001779,0.045191,144.313431,7.351677,0.451912,-1209.481567,0.046275,0.000000
31.740002,32.744568,-1209.437012,0.012409,0.001791,0.045495,145.655106,7.420025,0.454947,-1209.437012,0.046596,0.000000
31.930002,32.908417,-1209.481567,0.012439,0.001803,0.045807,146.383942,7.457154,0.458069,-1209.481567,0.046908,0.000000
32.120003,33.240196,-1209.481567,0.012404,0.001817,0.046145,147.859772,7.532336,0.461451,-1209.481567,0.047229,0.000000
32.310001,33.435692,-1209.481567,0.012452,0.001826,0.046379,148.729385,7.576636,0.463793,-1209.481567,0.047541,0.000000
32.500000,33.266266,-1209.526001,0.012460,0.001833,0.046570,147.975739,7.538243,0.465701,-1209.526001,0.047862,0.000000
32.690002,34.382263,-1209.437012,0.012486,0.001856,0.047134,152.939941,7.791132,0.471337,-1209.437012,0.048174,0.000000
32.880001,34.321564,-1209.526001,0.012473,0.001865,0.047359,152.669937,7.777378,0.473592,-1209.526001,0.048495,0.000000
33.070000,34.544617,-1209.526001,0.012499,0.001875,0.047628,153.662125,7.827922,0.476281,-1209.526001,0.048807,0.000000
33.260002,35.092003,-1209.481567,0.012499,0.001891,0.048036,156.097031,7.951962,0.480357,-1209.481567,0.049128,0.000000
33.450001,35.450974,-1209.526001,0.012486,0.001905,0.048383,157.693802,8.033305,0.483825,-1209.526001,0.049441,0.000000
33.640003,35.563431,-1209.481567,0.012512,0.001912,0.048573,158.194046,8.058788,0.485734,-1209.481567,0.049761,0.000000
33.830002,35.830048,-1209.570557,0.012538,0.001926,0.048929,159.380005,8.119205,0.489289,-1209.570557,0.050074,0.000000
34.020000,36.222900,-1209.526001,0.012538,0.001938,0.049224,161.127502,8.208226,0.492237,-1209.526001,0.050395,0.000000
34.210003,36.446693,-1209.481567,0.012512,0.001952,0.049571,162.122986,8.258939,0.495706,-1209.481567,0.050715,0.000000
34.400002,36.464943,-1209.526001,0.012525,0.001958,0.049735,162.204163,8.263074,0.497354,-1209.526001,0.051028,0.000000
34.590000,37.641266,-1209.481567,0.012611,0.001983,0.050360,167.436707,8.529633,0.503598,-1209.481567,0.051348,0.000000
34.780003,37.918686,-1209.481567,0.012547,0.001996,0.050698,168.670746,8.592497,0.506981,-1209.481567,0.051661,0.000000
34.970001,37.946243,-1209.526001,0.012620,0.002004,0.050898,168.793320,8.598742,0.508975,-1209.526001,0.051982,0.000000
35.160000,38.143227,-1209.437012,0.012581,0.002013,0.051140,169.669540,8.643378,0.511403,-1209.437012,0.052294,0.000000
35.350002,38.495117,-1209.481567,0.012624,0.002028,0.051513,171.234833,8.723118,0.515132,-1209.481567,0.052615,0.000000
35.540001,38.918877,-1209.526001,0.012590,0.002040,0.051825,173.119812,8.819143,0.518254,-1209.526001,0.052927,0.000000
35.730003,39.144905,-1209.481567,0.012659,0.002051,0.052094,174.125229,8.870362,0.520943,-1209.481567,0.053248,0.000000
35.920002,39.349342,-1209.570557,0.012633,0.002063,0.052406,175.034622,8.916689,0.524065,-1209.570557,0.053560,0.000000
36.110001,39.452484,-1209.570557,0.012659,0.002074,0.052675,175.493408,8.940061,0.526753,-1209.570557,0.053881,0.000000
36.300003,39.854279,-1209.526001,0.012646,0.002083,0.052901,177.280685,9.031109,0.529008,-1209.526001,0.054193,0.000000
36.490002,40.742760,-1209.526001,0.012680,0.002105,0.053464,181.232849,9.232441,0.534645,-1209.526001,0.054514,0.000000
36.680000,41.308022,-1209.481567,0.012715,0.002119,0.053811,183.747253,9.360532,0.538114,-1209.481567,0.054826,0.000000
36.870003,41.629379,-1209.570557,0.012680,0.002133,0.054176,185.176727,9.433352,0.541756,-1209.570557,0.055147,0.000000
37.060001,41.741089,-1209.526001,0.012672,0.002143,0.054436,185.673630,9.458667,0.544358,-1209.526001,0.055459,0.000000
37.250000,41.750023,-1209.526001,0.012710,0.002151,0.054644,185.713379,9.460690,0.546439,-1209.526001,0.055780,0.000000
37.440002,42.587494,-1209.526001,0.012753,0.002169,0.055104,189.438629,9.650464,0.551035,-1209.526001,0.056092,0.000000
37.630001,42.833626,-1209.570557,0.012684,0.002180,0.055372,190.533478,9.706239,0.553724,-1209.570557,0.056413,0.000000
37.820004,43.009758,-1209.526001,0.012715,0.002192,0.055685,191.316956,9.746151,0.556846,-1209.526001,0.056725,0.000000
38.010002,43.627151,-1209.526001,0.012779,0.002207,0.056049,194.063263,9.886054,0.560488,-1209.526001,0.057046,0.000000
38.200001,43.785416,-1209.570557,0.012788,0.002218,0.056326,194.767258,9.921917,0.563263,-1209.570557,0.057358,0.000000
38.390003,44.168213,-1209.570557,0.012805,0.002230,0.056639,196.470016,10.008660,0.566385,-1209.570557,0.057679,0.000000
38.580002,44.348816,-1209.526001,0.012810,0.002239,0.056881,197.273392,10.049585,0.568813,-1209.526001,0.057991,0.000000
38.770000,44.537605,-1209.570557,0.012805,0.002251,0.057176,198.113159,10.092366,0.571762,-1209.570557,0.058312,0.000000
38.960003,44.939766,-1209.526001,0.012810,0.002263,0.057471,199.902069,10.183496,0.574711,-1209.526001,0.058624,0.000000
39.150002,45.584717,-1209.659424,0.012818,0.002279,0.057879,202.770950,10.329645,0.578787,-1209.659424,0.058945,0.000000
39.340000,46.343239,-1209.570557,0.012848,0.002295,0.058286,206.145020,10.501528,0.582862,-1209.570557,0.059258,0.000000
39.530003,46.537247,-1209.570557,0.012801,0.002304,0.058520,207.008011,10.545491,0.585204,-1209.570557,0.059578,0.000000
39.720001,46.870522,-1209.570557,0.012861,0.002318,0.058876,208.490494,10.621012,0.588760,-1209.570557,0.059899,0.000000
39.910004,47.159851,-1209.570557,0.012840,0.002328,0.059136,209.777496,10.686575,0.591361,-1209.570557,0.060211,0.000000
40.100002,47.297630,-1209.570557,0.012827,0.002339,0.059405,210.390366,10.717796,0.594050,-1209.570557,0.060532,0.000000
40.290001,47.988754,-1209.570557,0.012904,0.002354,0.059804,213.464645,10.874408,0.598039,-1209.570557,0.060845,0.000000
40.480003,48.050568,-1209.570557,0.012866,0.002360,0.059943,213.739594,10.888414,0.599427,-1209.570557,0.061165,0.000000
40.670002,48.633331,-1209.526001,0.012878,0.002376,0.060342,216.331863,11.020470,0.603416,-1209.526001,0.061478,0.000000
40.860001,49.098053,-1209.570557,0.012909,0.002389,0.060680,218.399048,11.125778,0.606798,-1209.570557,0.061799,0.000000
41.050003,49.570221,-1209.526001,0.012913,0.002402,0.061009,220.499359,11.232773,0.610093,-1209.526001,0.062111,0.000000
41.240002,50.093773,-1209.526001,0.012939,0.002416,0.061374,222.828232,11.351411,0.613736,-1209.526001,0.062432,0.000000
41.430000,50.381989,-1209.570557,0.012969,0.002427,0.061651,224.110275,11.416722,0.616511,-1209.570557,0.062744,0.000000
41.620003,50.730904,-1209.659424,0.012939,0.002441,0.062007,225.662323,11.495787,0.620067,-1209.659424,0.063065,0.000000
41.810001,51.213501,-1209.526001,0.012930,0.002453,0.062301,227.809036,11.605145,0.623015,-1209.526001,0.063377,0.000000
42.000004,51.462616,-1209.570557,0.012926,0.002462,0.062536,228.917145,11.661596,0.625357,-1209.570557,0.063698,0.000000
42.190002,51.639496,-1209.614990,0.013004,0.002475,0.062865,229.703949,11.701677,0.628652,-1209.614990,0.064010,0.000000
42.380001,52.460945,-1209.570557,0.012947,0.002491,0.063264,233.357941,11.887820,0.632641,-1209.570557,0.064331,0.000000
42.570004,52.812469,-1209.614990,0.013016,0.002500,0.063498,234.921600,11.967477,0.634983,-1209.614990,0.064643,0.000000
42.760002,53.177017,-1209.570557,0.013047,0.002513,0.063828,236.543182,12.050085,0.638279,-1209.570557,0.064964,0.000000
42.950001,53.691635,-1209.614990,0.013008,0.002526,0.064157,238.832321,12.166698,0.641574,-1209.614990,0.065276,0.000000
43.140003,54.054329,-1209.570557,0.013021,0.002535,0.064383,240.445663,12.248885,0.643829,-1209.570557,0.065597,0.000000
43.330002,54.899239,-1209.570557,0.012999,0.002554,0.064877,244.204010,12.440346,0.648772,-1209.570557,0.065909,0.000000
43.520000,55.175171,-1209.614990,0.013073,0.002563,0.065111,245.431412,12.502872,0.651113,-1209.614990,0.066230,0.000000
43.710003,55.517754,-1209.659424,0.013038,0.002576,0.065424,246.955307,12.580503,0.654235,-1209.659424,0.066542,0.000000
43.900002,55.864433,-1209.659424,0.013064,0.002587,0.065701,248.497406,12.659061,0.657010,-1209.659424,0.066863,0.000000
44.090004,56.211113,-1209.614990,0.013090,0.002598,0.065979,250.039520,12.737620,0.659786,-1209.614990,0.067175,0.000000
44.280003,56.899628,-1209.659424,0.013064,0.002613,0.066377,253.102188,12.893640,0.663775,-1209.659424,0.067496,0.000000
44.470001,57.220238,-1209.703979,0.013120,0.002622,0.066603,254.528336,12.966290,0.666029,-1209.703979,0.067808,0.000000
44.660004,57.416855,-1209.614990,0.013137,0.002631,0.066820,255.402924,13.010845,0.668198,-1209.614990,0.068129,0.000000
44.850002,58.205910,-1209.703979,0.013068,0.002647,0.067245,258.912811,13.189648,0.672447,-1209.703979,0.068441,0.000000
45.040001,59.062363,-1209.614990,0.013120,0.002666,0.067704,262.722504,13.383722,0.677043,-1209.614990,0.068762,0.000000
45.230003,59.828705,-1209.659424,0.013124,0.002681,0.068086,266.131378,13.557378,0.680859,-1209.659424,0.069083,0.000000
45.420002,60.162354,-1209.659424,0.013107,0.002691,0.068363,267.615509,13.632984,0.683634,-1209.659424,0.069395,0.000000
45.610001,60.674736,-1209.570557,0.013142,0.002706,0.068728,269.894714,13.749091,0.687276,-1209.570557,0.069716,0.000000
45.800003,60.975243,-1209.570557,0.013129,0.002716,0.068979,271.231415,13.817187,0.689791,-1209.570557,0.070029,0.000000
45.990002,61.245583,-1209.614990,0.013146,0.002728,0.069283,272.433960,13.878447,0.692827,-1209.614990,0.070349,0.000000
46.180000,62.124382,-1209.659424,0.013159,0.002742,0.069656,276.343048,14.077586,0.696556,-1209.659424,0.070662,0.000000
46.370003,62.459518,-1209.659424,0.013198,0.002752,0.069898,277.833801,14.153529,0.698984,-1209.659424,0.070982,0.000000
46.560001,62.639000,-1209.614990,0.013193,0.002759,0.070081,278.632202,14.194201,0.700805,-1209.614990,0.071295,0.000000
46.750004,63.694687,-1209.659424,0.013172,0.002781,0.070627,283.328125,14.433422,0.706269,-1209.659424,0.071616,0.000000
46.940002,64.344849,-1209.570557,0.013189,0.002793,0.070930,286.220184,14.580751,0.709304,-1209.570557,0.071928,0.000000
47.130001,64.793182,-1209.659424,0.013210,0.002806,0.071260,288.214478,14.682344,0.712600,-1209.659424,0.072249,0.000000
47.320004,65.278748,-1209.659424,0.013254,0.002818,0.071581,290.374359,14.792376,0.715808,-1209.659424,0.072561,0.000000
47.510002,65.860031,-1209.526001,0.013249,0.002830,0.071884,292.960052,14.924097,0.718844,-1209.526001,0.072882,0.000000
47.700001,66.310226,-1209.614990,0.013241,0.002842,0.072188,294.962616,15.026112,0.721879,-1209.614990,0.073194,0.000000
47.890003,66.621155,-1209.526001,0.013279,0.002854,0.072491,296.345703,15.096569,0.724914,-1209.526001,0.073515,0.000000
48.080002,67.108215,-1209.703979,0.013254,0.002865,0.072778,298.512238,15.206940,0.727776,-1209.703979,0.073827,0.000000
48.270000,66.987564,-1209.659424,0.013262,0.002859,0.072613,297.975555,15.179599,0.726128,-1209.659424,0.072864,0.000000
48.460003,66.467743,-1209.614990,0.013254,0.002859,0.072613,295.663300,15.061806,0.726128,-1209.614990,0.072864,0.000000
48.650002,66.048813,-1209.703979,0.013241,0.002856,0.072543,293.799805,14.966875,0.725435,-1209.703979,0.072613,0.000000
48.840004,65.667130,-1209.659424,0.013288,0.002855,0.072526,292.101990,14.880384,0.725261,-1209.659424,0.072613,0.000000
49.030003,65.311890,-1209.659424,0.013323,0.002855,0.072517,290.521790,14.799886,0.725175,-1209.659424,0.072613,0.000000
49.220001,65.020691,-1209.659424,0.013327,0.002855,0.072509,289.226471,14.733899,0.725087,-1209.659424,0.072613,0.000000
49.410004,64.754074,-1209.614990,0.013301,0.002854,0.072500,288.040497,14.673483,0.725001,-1209.614990,0.072613,0.000000
49.600002,64.495285,-1209.703979,0.013314,0.002854,0.072491,286.889343,14.614841,0.724914,-1209.703979,0.072613,0.000000
49.790001,64.277435,-1209.614990,0.013284,0.002854,0.072491,285.920319,14.565475,0.724914,-1209.614990,0.072613,0.000000
49.980003,64.072632,-1209.614990,0.013305,0.002854,0.072483,285.009308,14.519066,0.724827,-1209.614990,0.072613,0.000000
50.170002,63.886444,-1209.703979,0.013305,0.002854,0.072483,284.181091,14.476875,0.724827,-1209.703979,0.072613,0.000000
50.360001,63.715164,-1209.659424,0.013336,0.002854,0.072483,283.419220,14.438063,0.724827,-1209.659424,0.072613,0.000000
50.550003,63.575150,-1209.703979,0.013284,0.002854,0.072483,282.796387,14.406335,0.724827,-1209.703979,0.072613,0.000000
50.740002,63.407211,-1209.614990,0.013323,0.002854,0.072483,282.049377,14.368279,0.724827,-1209.614990,0.072613,0.000000
50.930004,63.260864,-1209.659424,0.013279,0.002853,0.072474,281.398376,14.335116,0.724741,-1209.659424,0.072613,0.000000
51.120003,63.144318,-1209.614990,0.013344,0.002853,0.072474,280.879944,14.308706,0.724741,-1209.614990,0.072613,0.000000
51.310001,62.995735,-1209.659424,0.013271,0.002853,0.072474,280.219025,14.275038,0.724741,-1209.659424,0.072613,0.000000
51.500004,62.864662,-1209.614990,0.013323,0.002853,0.072474,279.635986,14.245337,0.724741,-1209.614990,0.072613,0.000000
51.690002,62.775665,-1209.703979,0.013353,0.002853,0.072474,279.240112,14.225169,0.724741,-1209.703979,0.072613,0.000000
51.880001,62.660233,-1209.659424,0.013340,0.002853,0.072474,278.726624,14.199012,0.724741,-1209.659424,0.072613,0.000000
52.070004,62.551125,-1209.614990,0.013318,0.002853,0.072474,278.241302,14.174287,0.724741,-1209.614990,0.072613,0.000000
52.260002,62.474045,-1209.570557,0.013275,0.002853,0.072474,277.898437,14.156821,0.724741,-1209.570557,0.072613,0.000000
52.450001,62.382065,-1209.659424,0.013292,0.002853,0.072474,277.489288,14.135978,0.724741,-1209.659424,0.072613,0.000000
52.640003,62.285995,-1209.703979,0.013310,0.002853,0.072474,277.061951,14.114208,0.724741,-1209.703979,0.072613,0.000000
52.830002,62.199974,-1209.614990,0.013297,0.002853,0.072474,276.679291,14.094716,0.724741,-1209.614990,0.072613,0.000000
53.020004,62.112839,-1209.659424,0.013310,0.002853,0.072474,276.291718,14.074970,0.724741,-1209.659424,0.072613,0.000000
53.210003,62.027939,-1209.614990,0.013348,0.002853,0.072474,275.914062,14.055732,0.724741,-1209.614990,0.072613,0.000000
53.400002,61.954956,-1209.659424,0.013297,0.002853,0.072474,275.589417,14.039194,0.724741,-1209.659424,0.072613,0.000000
53.590004,61.883461,-1209.659424,0.013340,0.002853,0.072474,275.271393,14.022992,0.724741,-1209.659424,0.072613,0.000000
53.780003,61.799675,-1209.570557,0.013340,0.002853,0.072474,274.898682,14.004007,0.724741,-1209.570557,0.072613,0.000000
53.970001,61.731529,-1209.703979,0.013275,0.002853,0.072474,274.595551,13.988564,0.724741,-1209.703979,0.072613,0.000000
54.160004,61.691315,-1209.614990,0.013353,0.002853,0.072474,274.416687,13.979451,0.724741,-1209.614990,0.072613,0.000000
54.350002,61.603065,-1209.659424,0.013314,0.002853,0.072474,274.024109,13.959455,0.724741,-1209.659424,0.072613,0.000000
54.540001,61.550186,-1209.703979,0.013305,0.002853,0.072474,273.788910,13.947471,0.724741,-1209.703979,0.072613,0.000000
54.730003,61.487999,-1209.614990,0.013323,0.002853,0.072465,273.512268,13.933379,0.724654,-1209.614990,0.072613,0.000000
54.920002,61.428795,-1209.614990,0.013314,0.002853,0.072465,273.248932,13.919964,0.724654,-1209.614990,0.072613,0.000000
55.110004,61.365120,-1209.614990,0.013284,0.002853,0.072465,272.965698,13.905535,0.724654,-1209.614990,0.072613,0.000000
55.300003,61.306656,-1209.659424,0.013275,0.002853,0.072465,272.705627,13.892287,0.724654,-1209.659424,0.072613,0.000000
55.490002,61.265320,-1209.570557,0.013318,0.002853,0.072465,272.521759,13.882920,0.724654,-1209.570557,0.072613,0.000000
55.680004,61.190475,-1209.703979,0.013301,0.002853,0.072465,272.188843,13.865959,0.724654,-1209.703979,0.072613,0.000000
55.870003,61.151001,-1209.614990,0.013318,0.002853,0.072465,272.013245,13.857015,0.724654,-1209.614990,0.072613,0.000000
56.060001,61.121956,-1209.703979,0.013318,0.002853,0.072465,271.884033,13.850432,0.724654,-1209.703979,0.072613,0.000000
56.250004,61.051949,-1209.703979,0.013301,0.002853,0.072465,271.572632,13.834569,0.724654,-1209.703979,0.072613,0.000000
56.440002,61.004662,-1209.703979,0.013297,0.002853,0.072465,271.362274,13.823853,0.724654,-1209.703979,0.072613,0.000000
56.630001,60.964447,-1209.614990,0.013305,0.002853,0.072465,271.183411,13.814741,0.724654,-1209.614990,0.072613,0.000000
56.820004,60.908218,-1209.659424,0.013348,0.002853,0.072465,270.933289,13.801999,0.724654,-1209.659424,0.072613,0.000000
57.010002,60.857201,-1209.659424,0.013327,0.002853,0.072465,270.706360,13.790439,0.724654,-1209.659424,0.072613,0.000000
57.200005,60.830391,-1209.703979,0.013361,0.002853,0.072465,270.587097,13.784364,0.724654,-1209.703979,0.072613,0.000000
57.390003,60.781609,-1209.703979,0.013301,0.002853,0.072465,270.370087,13.773309,0.724654,-1209.703979,0.072613,0.000000
57.580002,60.726128,-1209.703979,0.013310,0.002853,0.072465,270.123322,13.760737,0.724654,-1209.703979,0.072613,0.000000
57.770004,60.702667,-1209.659424,0.013348,0.002853,0.072465,270.018951,13.755421,0.724654,-1209.659424,0.072613,0.000000
57.960003,60.656868,-1209.703979,0.013353,0.002853,0.072465,269.815216,13.745043,0.724654,-1209.703979,0.072613,0.000000
58.150002,60.615532,-1209.703979,0.013331,0.002853,0.072465,269.631348,13.735676,0.724654,-1209.703979,0.072613,0.000000
58.340004,60.580154,-1209.703979,0.013318,0.002853,0.072465,269.473999,13.727659,0.724654,-1209.703979,0.072613,0.000000
58.530003,60.562653,-1209.703979,0.013348,0.002853,0.072465,269.396118,13.723694,0.724654,-1209.703979,0.072613,0.000000
58.720001,60.507919,-1209.748413,0.013353,0.002853,0.072465,269.152679,13.711290,0.724654,-1209.748413,0.072613,0.000000
58.910004,60.471794,-1209.659424,0.013348,0.002853,0.072465,268.991974,13.703105,0.724654,-1209.659424,0.072613,0.000000
59.100002,60.447220,-1209.748413,0.013344,0.002853,0.072465,268.882660,13.697536,0.724654,-1209.748413,0.072613,0.000000
59.290001,60.408867,-1209.659424,0.013331,0.002853,0.072465,268.712067,13.688846,0.724654,-1209.659424,0.072613,0.000000
59.480003,60.361572,-1209.748413,0.013323,0.002853,0.072465,268.501678,13.678128,0.724654,-1209.748413,0.072613,0.000000
59.670002,60.324333,-1209.703979,0.013327,0.002853,0.072465,268.336029,13.669689,0.724654,-1209.703979,0.072613,0.000000
59.860004,60.302368,-1209.703979,0.013357,0.002853,0.072465,268.238342,13.664712,0.724654,-1209.703979,0.072613,0.000000
60.050003,60.251724,-1209.703979,0.013310,0.002853,0.072465,268.013062,13.653236,0.724654,-1209.703979,0.072613,0.000000
60.240002,60.240181,-1209.659424,0.013344,0.002853,0.072465,267.961700,13.650620,0.724654,-1209.659424,0.072613,0.000000
60.430004,60.208900,-1209.748413,0.013344,0.002853,0.072465,267.822571,13.643532,0.724654,-1209.748413,0.072613,0.000000
60.620003,60.184700,-1209.748413,0.013340,0.002853,0.072465,267.714905,13.638048,0.724654,-1209.748413,0.072613,0.000000
60.810001,60.137032,-1209.703979,0.013310,0.002853,0.072465,267.502869,13.627247,0.724654,-1209.703979,0.072613,0.000000
61.000004,60.122887,-1209.748413,0.013301,0.002853,0.072465,267.439972,13.624041,0.724654,-1209.748413,0.072613,0.000000
61.190002,60.091972,-1209.659424,0.013353,0.002853,0.072465,267.302429,13.617036,0.724654,-1209.659424,0.072613,0.000000
61.380001,60.060699,-1209.748413,0.013314,0.002853,0.072465,267.163330,13.609949,0.724654,-1209.748413,0.072613,0.000000
61.570004,60.023460,-1209.703979,0.013318,0.002853,0.072465,266.997681,13.601511,0.724654,-1209.703979,0.072613,0.000000
61.760002,59.999252,-1209.659424,0.013292,0.002853,0.072465,266.890015,13.596025,0.724654,-1209.659424,0.072613,0.000000
61.950005,59.960899,-1209.703979,0.013327,0.002853,0.072465,266.719391,13.587334,0.724654,-1209.703979,0.072613,0.000000
62.140003,59.934090,-1209.703979,0.013318,0.002853,0.072465,266.600159,13.581259,0.724654,-1209.703979,0.072613,0.000000
62.330002,59.913612,-1209.659424,0.013310,0.002853,0.072465,266.509064,13.576619,0.724654,-1209.659424,0.072613,0.000000
62.520004,59.877113,-1209.703979,0.013344,0.002853,0.072465,266.346710,13.568348,0.724654,-1209.703979,0.072613,0.000000
62.710003,59.852539,-1209.703979,0.013310,0.002853,0.072465,266.237396,13.562778,0.724654,-1209.703979,0.072613,0.000000
62.900002,59.837646,-1209.748413,0.013344,0.002853,0.072465,266.171143,13.559404,0.724654,-1209.748413,0.072613,0.000000
63.090004,59.818657,-1209.748413,0.013331,0.002853,0.072465,266.086670,13.555101,0.724654,-1209.748413,0.072613,0.000000
63.280003,59.787376,-1209.659424,0.013297,0.002853,0.072465,265.947540,13.548013,0.724654,-1209.659424,0.072613,0.000000
63.470001,59.766151,-1209.748413,0.013327,0.002853,0.072465,265.853119,13.543204,0.724654,-1209.748413,0.072613,0.000000
63.660004,59.748650,-1209.748413,0.013353,0.002853,0.072465,265.775269,13.539238,0.724654,-1209.748413,0.072613,0.000000
63.850002,59.708801,-1209.748413,0.013310,0.002853,0.072465,265.598022,13.530208,0.724654,-1209.748413,0.072613,0.000000
64.040001,59.697632,-1209.748413,0.013379,0.002853,0.072465,265.548340,13.527678,0.724654,-1209.748413,0.072613,0.000000
64.230003,59.665985,-1209.748413,0.013305,0.002853,0.072465,265.407562,13.520505,0.724654,-1209.748413,0.072613,0.000000
64.420006,59.643639,-1209.703979,0.013279,0.002853,0.072465,265.308167,13.515441,0.724654,-1209.703979,0.072613,0.000000
64.610001,59.620178,-1209.659424,0.013310,0.002853,0.072465,265.203796,13.510126,0.724654,-1209.659424,0.072613,0.000000
64.800003,59.592255,-1209.792847,0.013305,0.002853,0.072465,265.079590,13.503798,0.724654,-1209.792847,0.072613,0.000000
64.990005,59.575867,-1209.703979,0.013323,0.002853,0.072465,265.006683,13.500084,0.724654,-1209.703979,0.072613,0.000000
65.180000,59.533791,-1209.748413,0.013318,0.002853,0.072465,264.819519,13.490550,0.724654,-1209.748413,0.072613,0.000000
65.370003,59.532303,-1209.792847,0.013361,0.002853,0.072465,264.812897,13.490212,0.724654,-1209.792847,0.072613,0.000000
65.560005,59.511078,-1209.748413,0.013314,0.002853,0.072465,264.718506,13.485403,0.724654,-1209.748413,0.072613,0.000000
65.750000,59.483521,-1209.792847,0.013301,0.002853,0.072465,264.595917,13.479158,0.724654,-1209.792847,0.072613,0.000000
65.940002,59.467880,-1209.792847,0.013327,0.002853,0.072457,264.526337,13.475615,0.724568,-1209.792847,0.072613,0.000000
66.130005,59.467506,-1209.792847,0.013318,0.002853,0.072457,264.524689,13.475530,0.724568,-1209.792847,0.072613,0.000000
66.320000,59.436226,-1209.748413,0.013327,0.002853,0.072457,264.385529,13.468441,0.724568,-1209.748413,0.072613,0.000000
66.510002,59.398247,-1209.659424,0.013327,0.002853,0.072457,264.216583,13.459835,0.724568,-1209.659424,0.072613,0.000000
66.700005,59.397873,-1209.837402,0.013348,0.002853,0.072457,264.214935,13.459750,0.724568,-1209.837402,0.072613,0.000000
66.889999,59.362495,-1209.703979,0.013331,0.002853,0.072457,264.057556,13.451734,0.724568,-1209.703979,0.072613,0.000000
67.080002,59.334198,-1209.837402,0.013323,0.002853,0.072457,263.931702,13.445321,0.724568,-1209.837402,0.072613,0.000000
67.270004,59.321167,-1209.659424,0.013297,0.002853,0.072457,263.873718,13.442369,0.724568,-1209.659424,0.072613,0.000000
67.460007,59.308876,-1209.748413,0.013344,0.002853,0.072457,263.819061,13.439584,0.724568,-1209.748413,0.072613,0.000000
67.650002,59.280952,-1209.837402,0.013353,0.002853,0.072457,263.694855,13.433256,0.724568,-1209.837402,0.072613,0.000000
67.840004,59.263451,-1209.748413,0.013340,0.002853,0.072457,263.617004,13.429290,0.724568,-1209.748413,0.072613,0.000000
68.030006,59.238869,-1209.748413,0.013357,0.002853,0.072457,263.507660,13.423719,0.724568,-1209.748413,0.072613,0.000000
68.220001,59.238129,-1209.748413,0.013331,0.002853,0.072457,263.504364,13.423553,0.724568,-1209.748413,0.072613,0.000000
68.410004,59.220993,-1209.748413,0.013370,0.002853,0.072457,263.428131,13.419668,0.724568,-1209.748413,0.072613,0.000000
68.600006,59.199402,-1209.837402,0.013310,0.002853,0.072457,263.332092,13.414776,0.724568,-1209.837402,0.072613,0.000000
68.790001,59.198280,-1209.748413,0.013370,0.002853,0.072457,263.327087,13.414522,0.724568,-1209.748413,0.072613,0.000000
68.980003,59.163651,-1209.792847,0.013305,0.002853,0.072457,263.173065,13.406674,0.724568,-1209.792847,0.072613,0.000000
69.170006,59.150620,-1209.792847,0.013357,0.002853,0.072457,263.115082,13.403722,0.724568,-1209.792847,0.072613,0.000000
69.360001,59.141312,-1209.792847,0.013331,0.002853,0.072457,263.073700,13.401612,0.724568,-1209.792847,0.072613,0.000000
69.550003,59.106308,-1209.837402,0.013348,0.002853,0.072457,262.917999,13.393681,0.724568,-1209.837402,0.072613,0.000000
69.740005,59.081726,-1209.748413,0.013327,0.002853,0.072457,262.808655,13.388110,0.724568,-1209.748413,0.072613,0.000000
69.930000,59.077263,-1209.837402,0.013310,0.002853,0.072457,262.788788,13.387098,0.724568,-1209.837402,0.072613,0.000000
70.120003,59.063110,-1209.792847,0.013361,0.002853,0.072457,262.725830,13.383892,0.724568,-1209.792847,0.072613,0.000000
70.310005,59.045609,-1209.748413,0.013366,0.002853,0.072457,262.647980,13.379926,0.724568,-1209.748413,0.072613,0.000000
70.500000,59.026619,-1209.792847,0.013314,0.002853,0.072457,262.563507,13.375623,0.724568,-1209.792847,0.072613,0.000000
70.690002,59.009865,-1209.792847,0.013327,0.002853,0.072457,262.488983,13.371826,0.724568,-1209.792847,0.072613,0.000000
70.880005,58.990128,-1209.837402,0.013310,0.002853,0.072457,262.401184,13.367354,0.724568,-1209.837402,0.072613,0.000000
71.070000,58.976723,-1209.792847,0.013340,0.002853,0.072457,262.341553,13.364317,0.724568,-1209.792847,0.072613,0.000000
71.260002,58.951401,-1209.748413,0.013357,0.002853,0.072457,262.228912,13.358578,0.724568,-1209.748413,0.072613,0.000000
71.450005,58.962196,-1209.792847,0.013357,0.002853,0.072457,262.276947,13.361025,0.724568,-1209.792847,0.072613,0.000000
71.640007,58.929428,-1209.748413,0.013318,0.002853,0.072457,262.131195,13.353600,0.724568,-1209.748413,0.072613,0.000000
71.830002,58.913414,-1209.792847,0.013327,0.002853,0.072457,262.059967,13.349971,0.724568,-1209.792847,0.072613,0.000000
72.020004,58.910439,-1209.748413,0.013357,0.002853,0.072457,262.046722,13.349297,0.724568,-1209.748413,0.072613,0.000000
72.210007,58.897408,-1209.837402,0.013323,0.002853,0.072457,261.988739,13.346343,0.724568,-1209.837402,0.072613,0.000000
72.400002,58.867989,-1209.792847,0.013344,0.002853,0.072457,261.857880,13.339677,0.724568,-1209.792847,0.072613,0.000000
72.590004,58.864639,-1209.748413,0.013353,0.002853,0.072457,261.842987,13.338918,0.724568,-1209.748413,0.072613,0.000000
72.780006,58.846390,-1209.837402,0.013361,0.002853,0.072457,261.761810,13.334783,0.724568,-1209.837402,0.072613,0.000000
72.970001,58.827400,-1209.792847,0.013318,0.002853,0.072457,261.677338,13.330480,0.724568,-1209.792847,0.072613,0.000000
73.160004,58.812874,-1209.748413,0.013361,0.002853,0.072457,261.612732,13.327188,0.724568,-1209.748413,0.072613,0.000000
73.350006,58.801331,-1209.792847,0.013336,0.002853,0.072457,261.561371,13.324573,0.724568,-1209.792847,0.072613,0.000000
73.540001,58.785324,-1209.748413,0.013383,0.002853,0.072457,261.490173,13.320946,0.724568,-1209.748413,0.072613,0.000000
73.730003,58.752182,-1209.792847,0.013318,0.002853,0.072457,261.342743,13.313435,0.724568,-1209.792847,0.072613,0.000000
73.920006,58.761116,-1209.748413,0.013327,0.002853,0.072457,261.382507,13.315459,0.724568,-1209.748413,0.072613,0.000000
74.110001,58.743240,-1209.748413,0.013310,0.002853,0.072457,261.302979,13.311408,0.724568,-1209.748413,0.072613,0.000000
74.300003,58.733559,-1209.837402,0.013314,0.002853,0.072457,261.259918,13.309215,0.724568,-1209.837402,0.072613,0.000000
74.490005,58.719780,-1209.748413,0.013301,0.002853,0.072457,261.198639,13.306092,0.724568,-1209.748413,0.072613,0.000000
74.680000,58.708611,-1209.748413,0.013331,0.002853,0.072457,261.148956,13.303561,0.724568,-1209.748413,0.072613,0.000000
74.870003,58.698929,-1209.748413,0.013370,0.002853,0.072457,261.105865,13.301368,0.724568,-1209.748413,0.072613,0.000000
75.060005,58.684410,-1209.748413,0.013331,0.002853,0.072457,261.041290,13.298078,0.724568,-1209.748413,0.072613,0.000000
75.250000,58.669510,-1209.837402,0.013336,0.002853,0.072457,260.975006,13.294701,0.724568,-1209.837402,0.072613,0.000000
75.440002,58.659462,-1209.792847,0.013374,0.002853,0.072457,260.930328,13.292423,0.724568,-1209.792847,0.072613,0.000000
75.630005,58.646057,-1209.837402,0.013357,0.002853,0.072457,260.870697,13.289387,0.724568,-1209.837402,0.072613,0.000000
75.820007,58.626694,-1209.703979,0.013310,0.002853,0.072457,260.784546,13.284998,0.724568,-1209.703979,0.072613,0.000000
76.010002,58.618126,-1209.748413,0.013327,0.002853,0.072457,260.746460,13.283057,0.724568,-1209.748413,0.072613,0.000000
76.200005,58.592804,-1209.792847,0.013370,0.002853,0.072457,260.633820,13.277319,0.724568,-1209.792847,0.072613,0.000000
76.390007,58.578285,-1209.792847,0.013379,0.002853,0.072457,260.569214,13.274029,0.724568,-1209.792847,0.072613,0.000000
76.580002,58.566742,-1209.748413,0.013357,0.002853,0.072457,260.517883,13.271414,0.724568,-1209.748413,0.072613,0.000000
76.770004,58.554825,-1209.792847,0.013327,0.002853,0.072457,260.464874,13.268713,0.724568,-1209.792847,0.072613,0.000000
76.960007,58.548866,-1209.881836,0.013314,0.002853,0.072457,260.438354,13.267363,0.724568,-1209.881836,0.072613,0.000000
77.150002,58.533966,-1209.792847,0.013327,0.002853,0.072457,260.372070,13.263987,0.724568,-1209.792847,0.072613,0.000000
77.340004,58.526154,-1209.748413,0.013331,0.002853,0.072457,260.337341,13.262217,0.724568,-1209.748413,0.072613,0.000000
77.530006,58.518700,-1209.837402,0.013314,0.002853,0.072457,260.304169,13.260527,0.724568,-1209.837402,0.072613,0.000000
77.720001,58.492264,-1209.792847,0.013361,0.002853,0.072457,260.186584,13.254537,0.724568,-1209.792847,0.072613,0.000000
77.910004,58.485191,-1209.748413,0.013344,0.002853,0.072457,260.155121,13.252934,0.724568,-1209.748413,0.072613,0.000000
78.100006,58.488167,-1209.792847,0.013323,0.002853,0.072457,260.168365,13.253608,0.724568,-1209.792847,0.072613,0.000000
78.290001,58.463219,-1209.748413,0.013370,0.002853,0.072457,260.057373,13.247955,0.724568,-1209.748413,0.072613,0.000000
78.480003,58.458008,-1209.792847,0.013392,0.002853,0.072457,260.034210,13.246774,0.724568,-1209.792847,0.072613,0.000000
78.600006,58.459496,-1209.748413,0.013353,0.002853,0.072457,260.040833,13.247111,0.724568,-1209.748413,0.072613,0.000000