File: Data/Symmetrical membranes compression/Sterlitech PVDF 045um test 1_10272023_143339.csv
Time (sec),S:Load (lbs),S:HL1 (DIM),S:LVDT (in),S:Position (in),Ch:Position (mm),Ch:Load (N),Ch:Stress (MPa),Ch:Strain (mm/mm),Ch:HL1 (DIM),Set Point (),Cycles ()
0.110000,-0.002609,-1207.835693,0.000095,-0.000000,-0.000000,-0.011607,-0.000591,-0.000000,-1207.835693,0.000208,0.000000
0.330000,-0.005959,-1207.702271,0.000103,-0.000000,-0.000000,-0.026505,-0.001350,-0.000000,-1207.702271,0.000208,0.000000
0.550000,-0.012291,-1207.746826,0.000026,0.000085,0.002159,-0.054673,-0.002785,0.021594,-1207.746826,0.002914,0.000000
0.770000,-0.026810,-1207.746826,0.000095,0.000207,0.005255,-0.119255,-0.006075,0.052554,-1207.746826,0.006574,0.000000
0.990000,-0.039474,-1207.791260,0.000267,0.000358,0.009089,-0.175591,-0.008945,0.090885,-1207.791260,0.010233,0.000000
1.210000,-0.040962,-1207.746826,0.000423,0.000502,0.012748,-0.182209,-0.009282,0.127482,-1207.746826,0.013910,0.000000
1.430000,-0.018623,-1207.746826,0.000573,0.000649,0.016486,-0.082841,-0.004220,0.164860,-1207.746826,0.017570,0.000000
1.650000,-0.005959,-1207.791260,0.000686,0.000793,0.020137,-0.026505,-0.001350,0.201370,-1207.791260,0.021230,0.000000
1.870000,-0.006706,-1207.791260,0.000862,0.000930,0.023623,-0.029831,-0.001520,0.236232,-1207.791260,0.024907,0.000000
2.090000,-0.026810,-1207.791260,0.001018,0.001074,0.027292,-0.119255,-0.006075,0.272916,-1207.791260,0.028566,0.000000
2.310000,-0.021599,-1207.791260,0.001190,0.001222,0.031038,-0.096076,-0.004894,0.310380,-1207.791260,0.032226,0.000000
2.530000,-0.043198,-1207.791260,0.001293,0.001366,0.034689,-0.192153,-0.009789,0.346890,-1207.791260,0.035903,0.000000
2.750000,-0.046547,-1207.791260,0.001427,0.001510,0.038366,-0.207051,-0.010548,0.383661,-1207.791260,0.039563,0.000000
2.970000,-0.033142,-1207.791260,0.001578,0.001649,0.041896,-0.147423,-0.007510,0.418957,-1207.791260,0.043223,0.000000
3.190000,-0.004471,-1207.835693,0.001794,0.001799,0.045685,-0.019887,-0.001013,0.456855,-1207.835693,0.046900,0.000000
3.410000,0.021225,-1207.791260,0.001897,0.001944,0.049389,0.094413,0.004810,0.493885,-1207.791260,0.050559,0.000000
3.630000,-0.005585,-1207.835693,0.002095,0.002087,0.053022,-0.024842,-0.001266,0.530222,-1207.835693,0.054219,0.000000
3.850000,-0.005219,-1207.746826,0.002195,0.002238,0.056847,-0.023213,-0.001183,0.568466,-1207.746826,0.057896,0.000000
4.070000,-0.020111,-1207.835693,0.002367,0.002378,0.060411,-0.089459,-0.004557,0.604109,-1207.835693,0.061556,0.000000
4.290000,-0.041710,-1207.835693,0.002522,0.002520,0.064001,-0.185535,-0.009452,0.640013,-1207.835693,0.065215,0.000000
4.510000,-0.055855,-1207.791260,0.002690,0.002664,0.067661,-0.248455,-0.012657,0.676610,-1207.791260,0.068892,0.000000
4.730000,-0.023460,-1207.746826,0.002828,0.002813,0.071442,-0.104357,-0.005316,0.714420,-1207.746826,0.072552,0.000000
4.950000,0.000366,-1207.791260,0.002966,0.002954,0.075024,0.001629,0.000083,0.750237,-1207.791260,0.076212,0.000000
5.170000,0.017128,-1207.835693,0.003126,0.003097,0.078657,0.076189,0.003881,0.786574,-1207.835693,0.079871,0.000000
5.390000,0.012657,-1207.835693,0.003281,0.003241,0.082317,0.056302,0.002868,0.823171,-1207.835693,0.083549,0.000000
5.610000,0.004837,-1207.835693,0.003475,0.003392,0.086150,0.021516,0.001096,0.861502,-1207.835693,0.087208,0.000000
5.830000,-0.014153,-1207.791260,0.003587,0.003536,0.089810,-0.062954,-0.003207,0.898099,-1207.791260,0.090868,0.000000
6.050000,-0.033890,-1207.791260,0.003751,0.003675,0.093348,-0.150749,-0.007680,0.933482,-1207.791260,0.094545,0.000000
6.270000,-0.030540,-1207.835693,0.003842,0.003814,0.096869,-0.135851,-0.006921,0.968691,-1207.835693,0.098205,0.000000
6.490000,0.006325,-1207.835693,0.004014,0.003970,0.100841,0.028134,0.001433,1.008410,-1207.835693,0.101864,0.000000
6.710001,0.008560,-1207.791260,0.004152,0.004112,0.104440,0.038078,0.001940,1.044400,-1207.791260,0.105541,0.000000
6.930000,-0.004097,-1207.835693,0.004337,0.004252,0.108013,-0.018224,-0.000928,1.080130,-1207.835693,0.109201,0.000000
7.150001,0.003349,-1207.835693,0.004480,0.004396,0.111664,0.014898,0.000759,1.116640,-1207.835693,0.112861,0.000000
7.370000,0.002975,-1207.835693,0.004618,0.004543,0.115393,0.013236,0.000674,1.153931,-1207.835693,0.116538,0.000000
7.590000,-0.034630,-1207.791260,0.004773,0.004689,0.119105,-0.154041,-0.007847,1.191048,-1207.791260,0.120197,0.000000
7.810000,-0.001862,-1207.835693,0.005001,0.004833,0.122747,-0.008281,-0.000422,1.227471,-1207.835693,0.123857,0.000000
8.030001,-0.001122,-1207.835693,0.005083,0.004980,0.126485,-0.004989,-0.000254,1.264849,-1207.835693,0.127534,0.000000
8.250000,0.005211,-1207.835693,0.005243,0.005115,0.129919,0.023179,0.001181,1.299191,-1207.835693,0.131194,0.000000
8.470000,0.002235,-1207.835693,0.005372,0.005260,0.133596,0.009944,0.000507,1.335961,-1207.835693,0.134854,0.000000
8.690001,-0.013779,-1207.924683,0.005527,0.005407,0.137343,-0.061291,-0.003122,1.373425,-1207.924683,0.138513,0.000000
8.910001,-0.010056,-1207.880249,0.005661,0.005553,0.141054,-0.044729,-0.002279,1.410543,-1207.880249,0.142190,0.000000
9.130000,-0.037987,-1207.835693,0.005872,0.005697,0.144697,-0.168974,-0.008608,1.446966,-1207.835693,0.145850,0.000000
9.350000,-0.022720,-1207.924683,0.005963,0.005836,0.148244,-0.101065,-0.005149,1.482436,-1207.924683,0.149510,0.000000
9.570001,-0.013779,-1207.924683,0.006114,0.005981,0.151912,-0.061291,-0.003122,1.519119,-1207.924683,0.153187,0.000000
9.790001,0.013405,-1207.924683,0.006308,0.006132,0.155745,0.059628,0.003038,1.557451,-1207.924683,0.156846,0.000000
10.010000,0.008934,-1207.880249,0.006424,0.006267,0.159188,0.039741,0.002024,1.591879,-1207.880249,0.160506,0.000000
10.230000,0.011543,-1207.880249,0.006601,0.006419,0.163047,0.051347,0.002616,1.630471,-1207.880249,0.164183,0.000000
10.450001,0.006699,-1207.924683,0.006730,0.006563,0.166707,0.029797,0.001518,1.667068,-1207.924683,0.167843,0.000000
10.670000,-0.008568,-1207.969238,0.006885,0.006704,0.170288,-0.038112,-0.001941,1.702884,-1207.969238,0.171503,0.000000
10.890000,-0.065910,-1207.880249,0.007015,0.006845,0.173870,-0.293184,-0.014935,1.738701,-1207.880249,0.175180,0.000000
11.110001,-0.017502,-1207.880249,0.007192,0.006998,0.177747,-0.077852,-0.003966,1.777466,-1207.880249,0.178839,0.000000
11.330001,0.005211,-1207.835693,0.007377,0.007137,0.181268,0.023179,0.001181,1.812675,-1207.835693,0.182499,0.000000
11.550000,0.015640,-1207.924683,0.007524,0.007280,0.184901,0.069571,0.003544,1.849012,-1207.924683,0.186176,0.000000
11.770000,0.025322,-1207.969238,0.007700,0.007421,0.188500,0.112638,0.005738,1.885002,-1207.969238,0.189836,0.000000
11.990001,0.024200,-1207.835693,0.007851,0.007578,0.192472,0.107649,0.005484,1.924721,-1207.835693,0.193495,0.000000
12.210001,0.008186,-1207.924683,0.007959,0.007721,0.196114,0.036415,0.001855,1.961144,-1207.924683,0.197172,0.000000
12.430000,-0.006332,-1207.969238,0.008097,0.007862,0.199687,-0.028168,-0.001435,1.996874,-1207.969238,0.200832,0.000000
12.650001,-0.018623,-1207.880249,0.008265,0.007998,0.203148,-0.082841,-0.004220,2.031476,-1207.880249,0.204492,0.000000
12.870001,-0.008194,-1207.969238,0.008438,0.008150,0.206998,-0.036449,-0.001857,2.069981,-1207.969238,0.208152,0.000000
13.090000,0.007072,-1207.924683,0.008589,0.008295,0.210701,0.031460,0.001603,2.107012,-1207.924683,0.211829,0.000000
13.310000,0.012283,-1207.835693,0.008705,0.008434,0.214222,0.054639,0.002783,2.142221,-1207.835693,0.215488,0.000000
13.530001,0.015640,-1207.924683,0.008890,0.008581,0.217968,0.069571,0.003544,2.179685,-1207.924683,0.219148,0.000000
13.750001,0.015266,-1207.924683,0.009067,0.008728,0.221689,0.067908,0.003459,2.216889,-1207.924683,0.222825,0.000000
13.970000,-0.010056,-1208.013672,0.009188,0.008875,0.225418,-0.044729,-0.002279,2.254180,-1208.013672,0.226485,0.000000
14.190001,-0.001862,-1207.880249,0.009352,0.009018,0.229052,-0.008281,-0.000422,2.290517,-1207.880249,0.230144,0.000000
14.410001,0.005959,-1207.969238,0.009533,0.009165,0.232789,0.026505,0.001350,2.327894,-1207.969238,0.233821,0.000000
14.630001,0.012657,-1207.835693,0.009619,0.009301,0.236250,0.056302,0.002868,2.362496,-1207.835693,0.237481,0.000000
14.850000,0.018990,-1208.013672,0.009826,0.009443,0.239857,0.084470,0.004303,2.398573,-1208.013672,0.241141,0.000000
15.070001,0.002602,-1207.969238,0.009912,0.009589,0.243569,0.011573,0.000590,2.435690,-1207.969238,0.244818,0.000000
15.290001,0.005585,-1207.924683,0.010111,0.009738,0.247350,0.024842,0.001266,2.473501,-1207.924683,0.248478,0.000000
15.510001,0.016380,-1207.969238,0.010223,0.009882,0.250992,0.072863,0.003712,2.509925,-1207.969238,0.252137,0.000000
15.730000,0.033142,-1207.969238,0.010395,0.010022,0.254548,0.147423,0.007510,2.545481,-1207.969238,0.255814,0.000000
15.950001,0.176132,-1207.969238,0.010520,0.010166,0.258216,0.783475,0.039912,2.582165,-1207.969238,0.259474,0.000000
16.170000,0.580902,-1207.969238,0.010731,0.010316,0.262024,2.583982,0.131634,2.620236,-1207.969238,0.263134,0.000000
16.390001,0.609947,-1207.969238,0.010736,-0.000009,-0.000234,2.713181,0.138216,-0.002341,-1207.969238,-0.000009,0.000000
16.610001,0.585739,-1207.924683,0.010731,-0.000009,-0.000234,2.605498,0.132730,-0.002341,-1207.924683,-0.000009,0.000000
16.830000,0.630424,-1207.969238,0.010723,-0.000009,-0.000234,2.804268,0.142856,-0.002341,-1207.969238,0.000147,0.000000
17.050001,0.593185,-1207.969238,0.010779,-0.000009,-0.000234,2.638621,0.134418,-0.002341,-1207.969238,0.000512,0.000000
17.270000,0.579407,-1207.969238,0.010787,-0.000009,-0.000234,2.577330,0.131295,-0.002341,-1207.969238,0.000876,0.000000
17.490002,0.647926,-1207.969238,0.010762,0.000016,0.000408,2.882120,0.146822,0.004076,-1207.969238,0.001240,0.000000
17.710001,0.757774,-1208.013672,0.010757,0.000031,0.000781,3.370749,0.171714,0.007805,-1208.013672,0.001613,0.000000
17.930000,0.824059,-1208.013672,0.010783,0.000041,0.001049,3.665596,0.186734,0.010494,-1208.013672,0.001977,0.000000
18.150002,0.842674,-1208.013672,0.010800,0.000058,0.001474,3.748402,0.190953,0.014743,-1208.013672,0.002342,0.000000
18.370001,0.926086,-1207.924683,0.010861,0.000072,0.001821,4.119438,0.209854,0.018212,-1207.924683,0.002714,0.000000
18.590000,0.997208,-1207.969238,0.010856,0.000085,0.002151,4.435801,0.225970,0.021507,-1207.969238,0.003079,0.000000
18.810001,1.090675,-1207.969238,0.010856,0.000099,0.002506,4.851566,0.247151,0.025063,-1207.969238,0.003443,0.000000
19.030001,1.117485,-1207.969238,0.010831,0.000112,0.002836,4.970822,0.253226,0.028358,-1207.969238,0.003807,0.000000
19.250000,1.176697,-1208.013672,0.010895,0.000121,0.003061,5.234209,0.266643,0.030613,-1208.013672,0.004180,0.000000
19.470001,1.290642,-1208.013672,0.010856,0.000139,0.003530,5.741061,0.292464,0.035296,-1208.013672,0.004544,0.000000
19.690001,1.406822,-1207.924683,0.010930,0.000156,0.003963,6.257858,0.318790,0.039633,-1207.924683,0.004909,0.000000
19.910002,1.462303,-1207.969238,0.010904,0.000170,0.004310,6.504649,0.331363,0.043101,-1207.969238,0.005281,0.000000
20.130001,1.539757,-1207.969238,0.010960,0.000187,0.004752,6.849180,0.348914,0.047524,-1207.969238,0.005646,0.000000
20.350000,1.642159,-1208.013672,0.010977,0.000202,0.005134,7.304686,0.372118,0.051340,-1208.013672,0.006010,0.000000
20.570002,1.736000,-1208.058105,0.010925,0.000215,0.005472,7.722114,0.393383,0.054722,-1208.058105,0.006374,0.000000
20.790001,1.839142,-1207.924683,0.010947,0.000231,0.005862,8.180911,0.416755,0.058625,-1207.924683,0.006747,0.000000
21.010000,1.918457,-1207.924683,0.011003,0.000242,0.006149,8.533723,0.434729,0.061487,-1207.924683,0.007111,0.000000
21.230001,1.985863,-1208.013672,0.010999,0.000253,0.006435,8.833559,0.450003,0.064348,-1208.013672,0.007475,0.000000
21.450001,2.162361,-1207.969238,0.011029,0.000273,0.006938,9.618663,0.489998,0.069378,-1207.969238,0.007848,0.000000
21.670000,2.229393,-1207.969238,0.011025,0.000285,0.007241,9.916836,0.505188,0.072414,-1207.969238,0.008213,0.000000
21.890001,2.337379,-1207.969238,0.011068,0.000296,0.007519,10.397183,0.529658,0.075189,-1207.969238,0.008577,0.000000
22.110001,2.459892,-1208.013672,0.011106,0.000314,0.007979,10.942147,0.557420,0.079785,-1208.013672,0.008941,0.000000
22.330002,2.583145,-1208.058105,0.011050,0.000327,0.008317,11.490403,0.585349,0.083167,-1208.058105,0.009314,0.000000
22.550001,2.759277,-1207.969238,0.011063,0.000342,0.008690,12.273879,0.625261,0.086896,-1207.969238,0.009678,0.000000
22.770000,2.875832,-1208.013672,0.011102,0.000354,0.008984,12.792337,0.651673,0.089845,-1208.013672,0.010043,0.000000
22.990002,2.970039,-1208.013672,0.011128,0.000367,0.009323,13.211395,0.673021,0.093227,-1208.013672,0.010415,0.000000
23.210001,2.999084,-1208.013672,0.011106,0.000374,0.009496,13.340594,0.679602,0.094962,-1208.013672,0.010780,0.000000
23.430000,3.420609,-1208.013672,0.011128,0.000399,0.010138,15.215627,0.775121,0.101379,-1208.013672,0.011144,0.000000
23.650002,3.645523,-1208.102661,0.011106,0.000418,0.010624,16.216097,0.826087,0.106235,-1208.102661,0.011508,0.000000
23.870001,3.695053,-1208.013672,0.011188,0.000427,0.010849,16.436417,0.837311,0.108490,-1208.013672,0.011881,0.000000
24.090002,3.943420,-1207.969238,0.011219,0.000443,0.011257,17.541210,0.893592,0.112566,-1207.969238,0.012245,0.000000
24.310001,4.097588,-1208.013672,0.011193,0.000455,0.011569,18.226980,0.928527,0.115688,-1208.013672,0.012609,0.000000
24.530001,4.240578,-1208.013672,0.011167,0.000469,0.011916,18.863031,0.960929,0.119157,-1208.013672,0.012982,0.000000
24.750002,4.562675,-1208.058105,0.011262,0.000484,0.012289,20.295794,1.033917,0.122886,-1208.058105,0.013347,0.000000
24.970001,4.732483,-1208.013672,0.011257,0.000495,0.012583,21.051136,1.072396,0.125835,-1208.013672,0.013711,0.000000
25.190001,5.054581,-1208.058105,0.011253,0.000513,0.013026,22.483898,1.145384,0.130258,-1208.058105,0.014075,0.000000
25.410002,5.257149,-1207.969238,0.011240,0.000526,0.013373,23.384966,1.191287,0.133726,-1207.969238,0.014448,0.000000
25.630001,5.552444,-1208.147095,0.011292,0.000544,0.013806,24.698507,1.258202,0.138063,-1208.147095,0.014812,0.000000
25.850000,5.637718,-1208.013672,0.011270,0.000554,0.014084,25.077824,1.277525,0.140838,-1208.013672,0.015176,0.000000
26.070002,5.962799,-1208.058105,0.011326,0.000570,0.014483,26.523855,1.351190,0.144827,-1208.058105,0.015549,0.000000
26.290001,6.199257,-1208.013672,0.011300,0.000583,0.014812,27.575672,1.404772,0.148122,-1208.013672,0.015914,0.000000
26.510002,6.562691,-1208.013672,0.011300,0.000602,0.015289,29.192307,1.487127,0.152892,-1208.013672,0.016278,0.000000
26.730001,6.891121,-1208.058105,0.011288,0.000619,0.015723,30.653236,1.561550,0.157228,-1208.058105,0.016642,0.000000
26.950001,7.076561,-1208.058105,0.011339,0.000629,0.015983,31.478115,1.603572,0.159830,-1208.058105,0.017015,0.000000
27.170002,7.316002,-1208.058105,0.011387,0.000642,0.016313,32.543201,1.657830,0.163125,-1208.058105,0.017379,0.000000
27.390001,7.593788,-1208.058105,0.011335,0.000658,0.016703,33.778858,1.720777,0.167028,-1208.058105,0.017743,0.000000
27.610001,7.900627,-1208.013672,0.011387,0.000673,0.017084,35.143745,1.790308,0.170844,-1208.013672,0.018108,0.000000
27.830002,8.072289,-1208.058105,0.011369,0.000684,0.017371,35.907333,1.829207,0.173705,-1208.058105,0.018481,0.000000
28.050001,8.343750,-1208.147095,0.011438,0.000699,0.017743,37.114853,1.890721,0.177434,-1208.147095,0.018845,0.000000
28.270000,8.667336,-1208.013672,0.011438,0.000714,0.018142,38.554234,1.964046,0.181424,-1208.013672,0.019209,0.000000
28.490002,9.162598,-1208.013672,0.011426,0.000734,0.018645,40.757271,2.076274,0.186454,-1208.013672,0.019582,0.000000
28.710001,9.435547,-1208.102661,0.011473,0.000748,0.018992,41.971409,2.138125,0.189923,-1208.102661,0.019946,0.000000
28.930002,9.729347,-1208.102661,0.011495,0.000763,0.019382,43.278297,2.204702,0.193825,-1208.102661,0.020310,0.000000
29.150002,9.883507,-1208.147095,0.011495,0.000776,0.019703,43.964035,2.239635,0.197034,-1208.147095,0.020675,0.000000
29.370001,10.242477,-1208.102661,0.011507,0.000792,0.020120,45.560814,2.320979,0.201197,-1208.102661,0.021048,0.000000
29.590002,10.461060,-1208.013672,0.011538,0.000804,0.020423,46.533115,2.370510,0.204232,-1208.013672,0.021412,0.000000
29.810001,10.650970,-1208.102661,0.011499,0.000816,0.020735,47.377884,2.413544,0.207354,-1208.102661,0.021776,0.000000
30.030001,11.014030,-1208.102661,0.011555,0.000836,0.021230,48.992855,2.495815,0.212297,-1208.102661,0.022149,0.000000
30.250002,11.297409,-1208.058105,0.011576,0.000849,0.021559,50.253384,2.560030,0.215592,-1208.058105,0.022513,0.000000
30.470001,11.521576,-1208.058105,0.011538,0.000861,0.021871,51.250530,2.610826,0.218714,-1208.058105,0.022877,0.000000
30.690001,11.669777,-1208.102661,0.011529,0.000871,0.022114,51.909760,2.644409,0.221143,-1208.102661,0.023242,0.000000
30.910002,11.966934,-1208.102661,0.011572,0.000884,0.022461,53.231583,2.711746,0.224612,-1208.102661,0.023615,0.000000
31.130001,12.252167,-1208.191650,0.011620,0.000899,0.022843,54.500359,2.776381,0.228427,-1208.191650,0.023979,0.000000
31.350002,12.783173,-1208.102661,0.011620,0.000922,0.023406,56.862392,2.896708,0.234065,-1208.102661,0.024343,0.000000
31.570002,12.915367,-1208.058105,0.011650,0.000933,0.023701,57.450420,2.926664,0.237013,-1208.058105,0.024716,0.000000
31.790001,13.140274,-1208.147095,0.011650,0.000948,0.024092,58.450859,2.977629,0.240916,-1208.147095,0.025080,0.000000
32.010002,13.301888,-1208.147095,0.011650,0.000961,0.024421,59.169750,3.014251,0.244211,-1208.147095,0.025444,0.000000
32.230003,13.537598,-1208.102661,0.011680,0.000974,0.024742,60.218243,3.067663,0.247420,-1208.102661,0.025809,0.000000
32.450001,13.901779,-1208.058105,0.011684,0.000989,0.025132,61.838203,3.150188,0.251322,-1208.058105,0.026182,0.000000
32.670002,14.198563,-1208.102661,0.011654,0.001004,0.025505,63.158360,3.217440,0.255051,-1208.102661,0.026546,0.000000
32.890003,14.444695,-1208.058105,0.011663,0.001018,0.025869,64.253212,3.273214,0.258694,-1208.058105,0.026910,0.000000
33.110001,14.710945,-1208.147095,0.011732,0.001031,0.026190,65.437553,3.333548,0.261902,-1208.147095,0.027283,0.000000
33.330002,14.953362,-1208.147095,0.011727,0.001047,0.026589,66.515877,3.388480,0.265892,-1208.147095,0.027647,0.000000
33.550003,15.235245,-1208.191650,0.011736,0.001059,0.026901,67.769753,3.452356,0.269014,-1208.191650,0.028011,0.000000
33.770000,15.485107,-1208.147095,0.011736,0.001074,0.027283,68.881195,3.508976,0.272829,-1208.147095,0.028376,0.000000
33.990002,15.763641,-1208.102661,0.011736,0.001091,0.027708,70.120178,3.572092,0.277079,-1208.102661,0.028749,0.000000
34.210003,15.843330,-1208.147095,0.011762,0.001098,0.027899,70.474655,3.590150,0.278987,-1208.147095,0.029113,0.000000
34.430000,16.519188,-1208.191650,0.011809,0.001122,0.028488,73.481018,3.743302,0.284884,-1208.191650,0.029477,0.000000
34.650002,16.666275,-1208.191650,0.011814,0.001132,0.028749,74.135292,3.776632,0.287485,-1208.191650,0.029850,0.000000
34.870003,16.999542,-1208.191650,0.011809,0.001148,0.029156,75.617737,3.852151,0.291561,-1208.191650,0.030214,0.000000
35.090000,17.358513,-1208.102661,0.011822,0.001163,0.029529,77.214523,3.933495,0.295290,-1208.102661,0.030578,0.000000
35.310001,17.792328,-1208.236084,0.011826,0.001181,0.030006,79.144226,4.031799,0.300060,-1208.236084,0.030943,0.000000
35.530003,18.039207,-1208.147095,0.011861,0.001192,0.030284,80.242401,4.087743,0.302836,-1208.147095,0.031316,0.000000
35.750000,18.334869,-1208.280518,0.011887,0.001209,0.030700,81.557571,4.154740,0.306998,-1208.280518,0.031680,0.000000
35.970001,18.556061,-1208.147095,0.011852,0.001221,0.031003,82.541481,4.204864,0.310034,-1208.147095,0.032044,0.000000
36.190002,18.791031,-1208.147095,0.011921,0.001233,0.031307,83.586678,4.258109,0.313069,-1208.147095,0.032417,0.000000
36.410000,19.091904,-1208.191650,0.011878,0.001246,0.031636,84.925026,4.326287,0.316364,-1208.191650,0.032781,0.000000
36.630001,19.484390,-1208.191650,0.011921,0.001260,0.031992,86.670898,4.415226,0.319920,-1208.191650,0.033145,0.000000
36.850002,19.972191,-1208.147095,0.011917,0.001277,0.032426,88.840744,4.525763,0.324256,-1208.147095,0.033510,0.000000
37.070004,20.565384,-1208.102661,0.011947,0.001298,0.032972,91.479393,4.660182,0.329719,-1208.102661,0.033883,0.000000
37.290001,20.972389,-1208.147095,0.011999,0.001312,0.033336,93.289848,4.752411,0.333362,-1208.147095,0.034247,0.000000
37.510002,21.122452,-1208.147095,0.011960,0.001327,0.033700,93.957359,4.786416,0.337004,-1208.147095,0.034611,0.000000
37.730003,21.402473,-1208.191650,0.011956,0.001340,0.034030,95.202957,4.849870,0.340299,-1208.191650,0.034984,0.000000
37.950001,21.616219,-1208.147095,0.011982,0.001352,0.034351,96.153740,4.898305,0.343508,-1208.147095,0.035348,0.000000
38.170002,22.127113,-1208.147095,0.012038,0.001371,0.034828,98.426315,5.014075,0.348278,-1208.147095,0.035712,0.000000
38.390003,22.465973,-1208.147095,0.012008,0.001384,0.035149,99.933640,5.090862,0.351487,-1208.147095,0.036077,0.000000
38.610001,22.552734,-1208.147095,0.012051,0.001394,0.035400,100.319572,5.110523,0.354002,-1208.147095,0.036450,0.000000
38.830002,23.253166,-1208.191650,0.012021,0.001415,0.035947,103.435249,5.269243,0.359465,-1208.191650,0.036814,0.000000
39.050003,23.697411,-1208.191650,0.012098,0.001431,0.036337,105.411346,5.369910,0.363368,-1208.191650,0.037178,0.000000
39.270000,23.846359,-1208.191650,0.012068,0.001441,0.036606,106.073906,5.403662,0.366056,-1208.191650,0.037551,0.000000
39.490002,24.254105,-1208.191650,0.012077,0.001458,0.037022,107.887642,5.496059,0.370219,-1208.191650,0.037915,0.000000
39.710003,24.531898,-1208.147095,0.012085,0.001471,0.037360,109.123337,5.559008,0.373601,-1208.147095,0.038279,0.000000
39.930000,24.856979,-1208.191650,0.012150,0.001484,0.037681,110.569366,5.632672,0.376810,-1208.191650,0.038644,0.000000
40.150002,25.164185,-1208.147095,0.012107,0.001499,0.038063,111.935883,5.702286,0.380626,-1208.147095,0.039016,0.000000
40.370003,25.357445,-1208.147095,0.012171,0.001510,0.038357,112.795547,5.746079,0.383574,-1208.147095,0.039381,0.000000
40.590000,25.516823,-1208.236084,0.012154,0.001519,0.038574,113.504494,5.782195,0.385742,-1208.236084,0.039745,0.000000
40.810001,26.201988,-1208.191650,0.012128,0.001539,0.039086,116.552261,5.937456,0.390859,-1208.191650,0.040109,0.000000
41.030003,26.735222,-1208.236084,0.012202,0.001557,0.039546,118.924210,6.058288,0.395455,-1208.236084,0.040482,0.000000
41.250004,27.033119,-1208.236084,0.012171,0.001570,0.039875,120.249321,6.125793,0.398751,-1208.236084,0.040846,0.000000
41.470001,27.439011,-1208.191650,0.012223,0.001588,0.040326,122.054817,6.217769,0.403260,-1208.191650,0.041211,0.000000
41.690002,27.797600,-1208.236084,0.012232,0.001602,0.040690,123.649902,6.299026,0.406903,-1208.236084,0.041584,0.000000
41.910004,28.069809,-1208.280518,0.012249,0.001615,0.041028,124.860748,6.360710,0.410285,-1208.280518,0.041948,0.000000
42.130001,28.446274,-1208.191650,0.012275,0.001629,0.041384,126.535347,6.446018,0.413840,-1208.191650,0.042312,0.000000
42.350002,28.570648,-1208.236084,0.012210,0.001641,0.041670,127.088593,6.474201,0.416702,-1208.236084,0.042676,0.000000
42.570004,28.677147,-1208.147095,0.012258,0.001652,0.041956,127.562317,6.498334,0.419564,-1208.147095,0.043049,0.000000
42.790001,29.500458,-1208.191650,0.012266,0.001672,0.042459,131.224594,6.684899,0.424594,-1208.191650,0.043413,0.000000
43.010002,29.569351,-1208.280518,0.012275,0.001683,0.042737,131.531036,6.700511,0.427369,-1208.280518,0.043778,0.000000
43.230003,29.914169,-1208.236084,0.012279,0.001694,0.043023,133.064865,6.778648,0.430231,-1208.236084,0.044150,0.000000
43.450001,30.479431,-1208.191650,0.012301,0.001715,0.043561,135.579285,6.906738,0.435608,-1208.191650,0.044515,0.000000
43.670002,30.759079,-1208.191650,0.012344,0.001729,0.043908,136.823212,6.970107,0.439077,-1208.191650,0.044879,0.000000
43.890003,31.163849,-1208.191650,0.012348,0.001743,0.044272,138.623718,7.061829,0.442719,-1208.191650,0.045243,0.000000
44.110001,31.319504,-1208.280518,0.012348,0.001753,0.044523,139.316116,7.097101,0.445234,-1208.280518,0.045616,0.000000
44.330002,31.457649,-1208.236084,0.012361,0.001766,0.044844,139.930618,7.128406,0.448442,-1208.236084,0.045980,0.000000
44.550003,31.754807,-1208.280518,0.012340,0.001780,0.045208,141.252441,7.195742,0.452085,-1208.280518,0.046345,0.000000
44.770000,32.493965,-1208.236084,0.012378,0.001797,0.045651,144.540375,7.363237,0.456508,-1208.236084,0.046717,0.000000
44.990002,33.191414,-1208.236084,0.012409,0.001817,0.046154,147.642776,7.521282,0.461538,-1208.236084,0.047082,0.000000
45.210003,33.075233,-1208.236084,0.012426,0.001823,0.046293,147.125992,7.494955,0.462925,-1208.236084,0.047446,0.000000
45.430000,33.615547,-1208.236084,0.012434,0.001842,0.046787,149.529419,7.617392,0.467868,-1208.236084,0.047810,0.000000
45.650002,33.840836,-1208.191650,0.012439,0.001854,0.047090,150.531555,7.668443,0.470904,-1208.191650,0.048183,0.000000
45.870003,34.097397,-1208.236084,0.012413,0.001869,0.047481,151.672791,7.726581,0.474806,-1208.236084,0.048547,0.000000
46.090004,34.698410,-1208.191650,0.012439,0.001884,0.047862,154.346237,7.862772,0.478622,-1208.191650,0.048912,0.000000
46.310001,34.816452,-1208.325073,0.012426,0.001895,0.048140,154.871307,7.889521,0.481397,-1208.325073,0.049284,0.000000
46.530003,35.361229,-1208.369507,0.012452,0.001912,0.048556,157.294601,8.012969,0.485560,-1208.369507,0.049649,0.000000
46.750004,35.696365,-1208.280518,0.012525,0.001926,0.048920,158.785370,8.088912,0.489202,-1208.280518,0.050013,0.000000
46.970001,36.199814,-1208.280518,0.012503,0.001943,0.049345,161.024811,8.202995,0.493451,-1208.280518,0.050377,0.000000
47.190002,36.207260,-1208.236084,0.012529,0.001955,0.049657,161.057938,8.204682,0.496573,-1208.236084,0.050750,0.000000
47.410004,36.706985,-1208.325073,0.012503,0.001969,0.050004,163.280823,8.317922,0.500042,-1208.325073,0.051114,0.000000
47.630001,37.043236,-1208.280518,0.012551,0.001982,0.050334,164.776535,8.394117,0.503338,-1208.280518,0.051479,0.000000
47.850002,37.637169,-1208.191650,0.012547,0.002002,0.050845,167.418488,8.528705,0.508455,-1208.191650,0.051851,0.000000
48.070004,38.249352,-1208.280518,0.012585,0.002019,0.051270,170.141617,8.667427,0.512704,-1208.280518,0.052216,0.000000
48.290001,38.359947,-1208.325073,0.012564,0.002029,0.051548,170.633560,8.692489,0.515479,-1208.325073,0.052580,0.000000
48.510002,38.586723,-1208.325073,0.012577,0.002041,0.051843,171.642319,8.743876,0.518427,-1208.325073,0.052944,0.000000
48.730003,38.935631,-1208.413940,0.012641,0.002057,0.052242,173.194336,8.822940,0.522417,-1208.413940,0.053317,0.000000
48.950001,39.350082,-1208.280518,0.012624,0.002070,0.052589,175.037903,8.916856,0.525886,-1208.280518,0.053681,0.000000
49.170002,39.604416,-1208.280518,0.012641,0.002083,0.052901,176.169235,8.974489,0.529008,-1208.280518,0.054046,0.000000
49.390003,40.047913,-1208.325073,0.012646,0.002097,0.053265,178.142014,9.074986,0.532650,-1208.325073,0.054418,0.000000
49.610001,40.361450,-1208.325073,0.012697,0.002111,0.053621,179.536697,9.146036,0.536206,-1208.325073,0.054783,0.000000
49.830002,40.494011,-1208.325073,0.012650,0.002120,0.053855,180.126358,9.176075,0.538548,-1208.325073,0.055147,0.000000
50.050003,41.768272,-1208.325073,0.012650,0.002146,0.054514,185.794556,9.464826,0.545138,-1208.325073,0.055511,0.000000
50.270004,42.141014,-1208.325073,0.012654,0.002162,0.054913,187.452591,9.549290,0.549128,-1208.325073,0.055884,0.000000
50.490002,42.277679,-1208.280518,0.012715,0.002174,0.055208,188.060516,9.580259,0.552076,-1208.280518,0.056248,0.000000
50.710003,42.772186,-1208.413940,0.012710,0.002190,0.055615,190.260193,9.692316,0.556152,-1208.413940,0.056613,0.000000
50.930004,43.155357,-1208.325073,0.012762,0.002203,0.055945,191.964615,9.779143,0.559448,-1208.325073,0.056985,0.000000
51.150002,43.378036,-1208.369507,0.012719,0.002216,0.056274,192.955139,9.829604,0.562743,-1208.369507,0.057350,0.000000
51.370003,44.062828,-1208.325073,0.012762,0.002235,0.056769,196.001251,9.984779,0.567686,-1208.325073,0.057714,0.000000
51.590004,44.385681,-1208.325073,0.012741,0.002247,0.057081,197.437378,10.057939,0.570808,-1208.325073,0.058078,0.000000
51.810001,44.738686,-1208.325073,0.012758,0.002260,0.057402,199.007614,10.137932,0.574017,-1208.325073,0.058451,0.000000
52.030003,44.854492,-1208.413940,0.012805,0.002269,0.057636,199.522751,10.164173,0.576359,-1208.413940,0.058815,0.000000
52.250004,45.268570,-1208.325073,0.012818,0.002284,0.058017,201.364655,10.258004,0.580174,-1208.325073,0.059179,0.000000
52.470001,45.746330,-1208.280518,0.012857,0.002297,0.058347,203.489838,10.366267,0.583469,-1208.280518,0.059552,0.000000
52.690002,46.729759,-1208.369507,0.012775,0.002319,0.058911,207.864349,10.589115,0.589107,-1208.369507,0.059917,0.000000
52.910004,47.035477,-1208.413940,0.012801,0.002332,0.059223,209.224243,10.658391,0.592229,-1208.413940,0.060281,0.000000
53.130001,47.400406,-1208.413940,0.012857,0.002347,0.059613,210.847534,10.741086,0.596131,-1208.413940,0.060645,0.000000
53.350002,47.640213,-1208.325073,0.012883,0.002360,0.059934,211.914246,10.795426,0.599340,-1208.325073,0.061018,0.000000
53.570004,47.947418,-1208.369507,0.012878,0.002373,0.060264,213.280762,10.865041,0.602635,-1208.369507,0.061382,0.000000
53.790001,48.698868,-1208.369507,0.012891,0.002388,0.060654,216.623383,11.035321,0.606538,-1208.369507,0.061746,0.000000
54.010002,49.254822,-1208.369507,0.012870,0.002403,0.061035,219.096390,11.161302,0.610354,-1208.369507,0.062111,0.000000
54.230003,49.683418,-1208.413940,0.012930,0.002417,0.061391,221.002884,11.258424,0.613909,-1208.413940,0.062484,0.000000
54.450001,50.104202,-1208.369507,0.012896,0.002431,0.061755,222.874619,11.353775,0.617552,-1208.369507,0.062848,0.000000
54.670002,50.659035,-1208.369507,0.012956,0.002447,0.062154,225.342636,11.479501,0.621541,-1208.369507,0.063212,0.000000
54.890003,50.944275,-1208.413940,0.012935,0.002460,0.062484,226.611450,11.544137,0.624837,-1208.413940,0.063585,0.000000
55.110004,51.387024,-1208.413940,0.012991,0.002472,0.062787,228.580902,11.644465,0.627872,-1208.413940,0.063949,0.000000
55.330002,51.976860,-1208.369507,0.012956,0.002489,0.063221,231.204620,11.778125,0.632208,-1208.369507,0.064313,0.000000
55.550003,52.033463,-1208.369507,0.012973,0.002497,0.063420,231.456406,11.790952,0.634202,-1208.369507,0.064678,0.000000
55.770004,53.221329,-1208.369507,0.013008,0.002520,0.064010,236.740295,12.060125,0.640100,-1208.369507,0.065051,0.000000
55.990002,53.503960,-1208.413940,0.013008,0.002531,0.064279,237.997498,12.124171,0.642788,-1208.413940,0.065415,0.000000
56.210003,54.004807,-1208.458496,0.013012,0.002546,0.064678,240.225372,12.237663,0.646777,-1208.458496,0.065779,0.000000
56.430004,54.527985,-1208.458496,0.013042,0.002561,0.065042,242.552597,12.356217,0.650420,-1208.458496,0.066152,0.000000
56.650002,55.408646,-1208.413940,0.013055,0.002580,0.065536,246.469971,12.555779,0.655363,-1208.413940,0.066516,0.000000
56.870003,55.802986,-1208.369507,0.013060,0.002590,0.065796,248.224075,12.645138,0.657964,-1208.369507,0.066880,0.000000
57.090004,56.138496,-1208.458496,0.013042,0.002605,0.066178,249.716507,12.721166,0.661780,-1208.458496,0.067245,0.000000
57.310001,56.560768,-1208.458496,0.013073,0.002618,0.066508,251.594864,12.816853,0.665076,-1208.458496,0.067618,0.000000
57.530003,57.008362,-1208.458496,0.013038,0.002631,0.066828,253.585861,12.918280,0.668284,-1208.458496,0.067982,0.000000
57.750004,57.552399,-1208.413940,0.013116,0.002646,0.067210,256.005859,13.041560,0.672100,-1208.413940,0.068346,0.000000
57.970001,58.134415,-1208.369507,0.013107,0.002657,0.067488,258.594788,13.173447,0.674875,-1208.369507,0.068719,0.000000
58.190002,58.954750,-1208.369507,0.013133,0.002676,0.067965,262.243835,13.359337,0.679645,-1208.369507,0.069083,0.000000
58.410004,59.843231,-1208.502930,0.013107,0.002696,0.068476,266.195984,13.560670,0.684762,-1208.502930,0.069447,0.000000
58.630001,60.649048,-1208.413940,0.013159,0.002711,0.068858,269.780426,13.743270,0.688577,-1208.413940,0.069812,0.000000
58.850002,60.968910,-1208.369507,0.013111,0.002725,0.069213,271.203247,13.815752,0.692133,-1208.369507,0.070185,0.000000
59.070004,61.456352,-1208.369507,0.013142,0.002738,0.069552,273.371521,13.926208,0.695515,-1208.369507,0.070549,0.000000
59.290001,61.698387,-1208.413940,0.013133,0.002751,0.069872,274.448120,13.981054,0.698724,-1208.413940,0.070913,0.000000
59.510002,62.392120,-1208.502930,0.013180,0.002768,0.070297,277.534027,14.138257,0.702973,-1208.502930,0.071286,0.000000
59.730003,63.088089,-1208.458496,0.013146,0.002780,0.070618,280.629822,14.295965,0.706182,-1208.458496,0.071650,0.000000
59.950005,63.361038,-1208.413940,0.013193,0.002790,0.070870,281.843964,14.357816,0.708697,-1208.413940,0.072014,0.000000
60.170002,64.372025,-1208.458496,0.013185,0.002809,0.071355,286.341064,14.586909,0.713553,-1208.458496,0.072379,0.000000
60.390003,65.046768,-1208.502930,0.013185,0.002827,0.071815,289.342468,14.739808,0.718150,-1208.502930,0.072752,0.000000
60.610004,65.601974,-1208.547485,0.013198,0.002838,0.072093,291.812164,14.865620,0.720925,-1208.547485,0.073116,0.000000
60.830002,66.184738,-1208.458496,0.013258,0.002855,0.072517,294.404419,14.997676,0.725175,-1208.458496,0.073480,0.000000
61.050003,66.743668,-1208.458496,0.013236,0.002868,0.072847,296.890656,15.124331,0.728470,-1208.458496,0.073853,0.000000
61.270004,67.245621,-1208.458496,0.013254,0.002882,0.073203,299.123474,15.238075,0.732025,-1208.458496,0.074217,0.000000
61.490002,67.047516,-1208.547485,0.013245,0.002878,0.073090,298.242249,15.193185,0.730898,-1208.547485,0.073341,0.000000
61.710003,66.477051,-1208.547485,0.013228,0.002877,0.073064,295.704681,15.063915,0.730638,-1208.547485,0.073090,0.000000
61.930004,65.975464,-1208.591919,0.013292,0.002874,0.073012,293.473511,14.950253,0.730118,-1208.591919,0.073090,0.000000
62.150002,65.558777,-1208.547485,0.013297,0.002874,0.073003,291.619995,14.855831,0.730031,-1208.547485,0.073090,0.000000
62.370003,65.201294,-1208.458496,0.013284,0.002874,0.072994,290.029846,14.774824,0.729944,-1208.458496,0.073090,0.000000
62.590004,64.878082,-1208.502930,0.013267,0.002873,0.072986,288.592133,14.701584,0.729857,-1208.502930,0.073090,0.000000
62.810001,64.590240,-1208.547485,0.013288,0.002873,0.072977,287.311737,14.636357,0.729771,-1208.547485,0.073090,0.000000
63.030003,64.332550,-1208.591919,0.013275,0.002873,0.072977,286.165466,14.577964,0.729771,-1208.591919,0.073090,0.000000
63.250004,64.104294,-1208.458496,0.013262,0.002873,0.072968,285.150146,14.526240,0.729684,-1208.458496,0.073090,0.000000
63.470001,63.882355,-1208.502930,0.013258,0.002873,0.072968,284.162903,14.475948,0.729684,-1208.502930,0.073090,0.000000
63.690002,63.696167,-1208.547485,0.013292,0.002873,0.072968,283.334717,14.433758,0.729684,-1208.547485,0.073090,0.000000
63.910004,63.520035,-1208.591919,0.013297,0.002873,0.072968,282.551239,14.393846,0.729684,-1208.591919,0.073090,0.000000
64.130005,63.351730,-1208.547485,0.013254,0.002873,0.072968,281.802582,14.355707,0.729684,-1208.547485,0.073090,0.000000
64.350006,63.202408,-1208.502930,0.013348,0.002872,0.072960,281.138336,14.321870,0.729597,-1208.502930,0.073090,0.000000
64.570000,63.056808,-1208.591919,0.013288,0.002872,0.072960,280.490692,14.288877,0.729597,-1208.591919,0.073090,0.000000
64.790001,62.924240,-1208.547485,0.013297,0.002872,0.072960,279.901001,14.258837,0.729597,-1208.547485,0.073090,0.000000
65.010002,62.788322,-1208.591919,0.013288,0.002872,0.072960,279.296417,14.228038,0.729597,-1208.591919,0.073090,0.000000
65.230003,62.667679,-1208.547485,0.013318,0.002872,0.072960,278.759766,14.200699,0.729597,-1208.547485,0.073090,0.000000
65.450005,62.552238,-1208.591919,0.013314,0.002872,0.072960,278.246246,14.174540,0.729597,-1208.591919,0.073090,0.000000
65.670006,62.448723,-1208.547485,0.013292,0.002872,0.072960,277.785797,14.151083,0.729597,-1208.547485,0.073090,0.000000
65.889999,62.339615,-1208.591919,0.013262,0.002872,0.072960,277.300446,14.126358,0.729597,-1208.591919,0.073090,0.000000
66.110001,62.231255,-1208.636353,0.013254,0.002872,0.072960,276.818451,14.101804,0.729597,-1208.636353,0.073090,0.000000
66.330002,62.143745,-1208.591919,0.013314,0.002872,0.072960,276.429199,14.081974,0.729597,-1208.591919,0.073090,0.000000
66.550003,62.067787,-1208.547485,0.013336,0.002872,0.072960,276.091309,14.064761,0.729597,-1208.547485,0.073090,0.000000
66.770004,61.972084,-1208.591919,0.013292,0.002872,0.072960,275.665588,14.043075,0.729597,-1208.591919,0.073090,0.000000
66.990005,61.890160,-1208.547485,0.013301,0.002872,0.072960,275.301178,14.024510,0.729597,-1208.547485,0.073090,0.000000
67.210007,61.812706,-1208.636353,0.013310,0.002872,0.072960,274.956635,14.006959,0.729597,-1208.636353,0.073090,0.000000
67.430000,61.736374,-1208.591919,0.013310,0.002872,0.072960,274.617096,13.989662,0.729597,-1208.591919,0.073090,0.000000
67.650002,61.654823,-1208.636353,0.013297,0.002872,0.072960,274.254364,13.971183,0.729597,-1208.636353,0.073090,0.000000
67.870003,61.581093,-1208.547485,0.013331,0.002872,0.072951,273.926392,13.954475,0.729511,-1208.547485,0.073090,0.000000
68.090004,61.499916,-1208.547485,0.013292,0.002872,0.072951,273.565277,13.936080,0.729511,-1208.547485,0.073090,0.000000
68.310005,61.447784,-1208.591919,0.013262,0.002872,0.072951,273.333405,13.924267,0.729511,-1208.591919,0.073090,0.000000
68.530006,61.377403,-1208.591919,0.013327,0.002872,0.072951,273.020325,13.908319,0.729511,-1208.591919,0.073090,0.000000
68.750000,61.318199,-1208.636353,0.013331,0.002872,0.072951,272.756958,13.894902,0.729511,-1208.636353,0.073090,0.000000
68.970001,61.252663,-1208.547485,0.013301,0.002872,0.072951,272.465454,13.880052,0.729511,-1208.547485,0.073090,0.000000
69.190002,61.203133,-1208.591919,0.013275,0.002872,0.072951,272.245117,13.868829,0.729511,-1208.591919,0.073090,0.000000
69.410004,61.137970,-1208.680908,0.013288,0.002872,0.072951,271.955261,13.854062,0.729511,-1208.680908,0.073090,0.000000
69.630005,61.078018,-1208.636353,0.013318,0.002872,0.072951,271.688599,13.840477,0.729511,-1208.636353,0.073090,0.000000
69.850006,61.021416,-1208.591919,0.013279,0.002872,0.072951,271.436829,13.827651,0.729511,-1208.591919,0.073090,0.000000
70.070000,60.968910,-1208.591919,0.013340,0.002872,0.072951,271.203247,13.815752,0.729511,-1208.591919,0.073090,0.000000
70.290001,60.934654,-1208.636353,0.013305,0.002872,0.072951,271.050873,13.807990,0.729511,-1208.636353,0.073090,0.000000
70.510002,60.863159,-1208.680908,0.013310,0.002872,0.072951,270.732849,13.791789,0.729511,-1208.680908,0.073090,0.000000
70.730003,60.824432,-1208.547485,0.013297,0.002872,0.072951,270.560577,13.783014,0.729511,-1208.547485,0.073090,0.000000
70.950005,60.780495,-1208.636353,0.013297,0.002872,0.072951,270.365143,13.773057,0.729511,-1208.636353,0.073090,0.000000
71.170006,60.734688,-1208.591919,0.013336,0.002872,0.072951,270.161377,13.762677,0.729511,-1208.591919,0.073090,0.000000
71.390007,60.685539,-1208.591919,0.013284,0.002872,0.072951,269.942749,13.751540,0.729511,-1208.591919,0.073090,0.000000
71.610001,60.651276,-1208.636353,0.013331,0.002872,0.072951,269.790344,13.743775,0.729511,-1208.636353,0.073090,0.000000
71.830002,60.594681,-1208.636353,0.013348,0.002872,0.072951,269.538605,13.730951,0.729511,-1208.636353,0.073090,0.000000
72.050003,60.563400,-1208.591919,0.013284,0.002872,0.072951,269.399445,13.723863,0.729511,-1208.591919,0.073090,0.000000
72.270004,60.516853,-1208.591919,0.013340,0.002872,0.072951,269.192413,13.713315,0.729511,-1208.591919,0.073090,0.000000
72.490005,60.463234,-1208.680908,0.013336,0.002872,0.072951,268.953888,13.701164,0.729511,-1208.680908,0.073090,0.000000
72.710007,60.436424,-1208.680908,0.013344,0.002872,0.072951,268.834656,13.695089,0.729511,-1208.680908,0.073090,0.000000
72.930000,60.395088,-1208.636353,0.013292,0.002872,0.072951,268.650757,13.685722,0.729511,-1208.636353,0.073090,0.000000
73.150002,60.342957,-1208.591919,0.013305,0.002872,0.072951,268.418884,13.673909,0.729511,-1208.591919,0.073090,0.000000
73.370003,60.327690,-1208.680908,0.013288,0.002872,0.072951,268.350983,13.670449,0.729511,-1208.680908,0.073090,0.000000
73.590004,60.291939,-1208.636353,0.013310,0.002872,0.072951,268.191925,13.662349,0.729511,-1208.636353,0.073090,0.000000
73.810005,60.239807,-1208.680908,0.013318,0.002872,0.072951,267.960052,13.650536,0.729511,-1208.680908,0.073090,0.000000
74.030006,60.212997,-1208.636353,0.013353,0.002872,0.072951,267.840790,13.644460,0.729511,-1208.636353,0.073090,0.000000
74.250000,60.169060,-1208.591919,0.013279,0.002872,0.072951,267.645355,13.634503,0.729511,-1208.591919,0.073090,0.000000
74.470001,60.136292,-1208.591919,0.013323,0.002872,0.072951,267.499573,13.627078,0.729511,-1208.591919,0.073090,0.000000
74.690002,60.106125,-1208.636353,0.013314,0.002872,0.072951,267.365387,13.620242,0.729511,-1208.636353,0.073090,0.000000
74.910004,60.076340,-1208.680908,0.013327,0.002872,0.072951,267.232910,13.613494,0.729511,-1208.680908,0.073090,0.000000
75.130005,60.035004,-1208.636353,0.013292,0.002872,0.072951,267.049042,13.604126,0.729511,-1208.636353,0.073090,0.000000
75.350006,60.011917,-1208.636353,0.013340,0.002872,0.072951,266.946350,13.598894,0.729511,-1208.636353,0.073090,0.000000
75.570007,59.983612,-1208.636353,0.013292,0.002872,0.072951,266.820435,13.592481,0.729511,-1208.636353,0.073090,0.000000
75.790001,59.949356,-1208.680908,0.013327,0.002872,0.072951,266.668060,13.584719,0.729511,-1208.680908,0.073090,0.000000
76.010002,59.917709,-1208.680908,0.013310,0.002872,0.072951,266.527283,13.577546,0.729511,-1208.680908,0.073090,0.000000
76.230003,59.876747,-1208.591919,0.013318,0.002872,0.072951,266.345062,13.568265,0.729511,-1208.591919,0.073090,0.000000
76.450005,59.853661,-1208.591919,0.013288,0.002872,0.072951,266.242371,13.563033,0.729511,-1208.591919,0.073090,0.000000
76.670006,59.825729,-1208.725342,0.013305,0.002872,0.072951,266.118134,13.556705,0.729511,-1208.725342,0.073090,0.000000
76.890007,59.798172,-1208.725342,0.013297,0.002872,0.072951,265.995544,13.550460,0.729511,-1208.725342,0.073090,0.000000
77.110001,59.778069,-1208.680908,0.013336,0.002872,0.072951,265.906128,13.545904,0.729511,-1208.680908,0.073090,0.000000
77.330002,59.746788,-1208.636353,0.013310,0.002872,0.072951,265.766998,13.538815,0.729511,-1208.636353,0.073090,0.000000
77.550003,59.721840,-1208.591919,0.013323,0.002872,0.072951,265.656006,13.533162,0.729511,-1208.591919,0.073090,0.000000
77.770004,59.708801,-1208.725342,0.013340,0.002872,0.072951,265.598022,13.530208,0.729511,-1208.725342,0.073090,0.000000
77.990005,59.666725,-1208.680908,0.013297,0.002872,0.072951,265.410858,13.520673,0.729511,-1208.680908,0.073090,0.000000
78.210007,59.641777,-1208.769897,0.013297,0.002872,0.072951,265.299866,13.515020,0.729511,-1208.769897,0.073090,0.000000
78.430000,59.617577,-1208.680908,0.013284,0.002872,0.072951,265.192230,13.509536,0.729511,-1208.680908,0.073090,0.000000
78.650002,59.587036,-1208.680908,0.013340,0.002872,0.072951,265.056366,13.502615,0.729511,-1208.680908,0.073090,0.000000
78.870003,59.566933,-1208.636353,0.013288,0.002872,0.072951,264.966949,13.498059,0.729511,-1208.636353,0.073090,0.000000
79.090004,59.541985,-1208.636353,0.013336,0.002872,0.072951,264.855988,13.492407,0.729511,-1208.636353,0.073090,0.000000
79.310005,59.512192,-1208.680908,0.013310,0.002872,0.072951,264.723450,13.485655,0.729511,-1208.680908,0.073090,0.000000
79.530006,59.490219,-1208.725342,0.013331,0.002872,0.072951,264.625702,13.480677,0.729511,-1208.725342,0.073090,0.000000
79.750000,59.452614,-1208.680908,0.013297,0.002872,0.072951,264.458435,13.472155,0.729511,-1208.680908,0.073090,0.000000
79.970001,59.438835,-1208.636353,0.013284,0.002872,0.072951,264.397156,13.469032,0.729511,-1208.636353,0.073090,0.000000
80.190002,59.425430,-1208.725342,0.013336,0.002872,0.072951,264.337524,13.465995,0.729511,-1208.725342,0.073090,0.000000
80.410004,59.400108,-1208.725342,0.013310,0.002872,0.072951,264.224884,13.460258,0.729511,-1208.725342,0.073090,0.000000
80.630005,59.369202,-1208.636353,0.013331,0.002872,0.072951,264.087402,13.453253,0.729511,-1208.636353,0.073090,0.000000
80.850006,59.347229,-1208.680908,0.013370,0.002872,0.072951,263.989655,13.448275,0.729511,-1208.680908,0.073090,0.000000
81.070007,59.334198,-1208.680908,0.013344,0.002872,0.072951,263.931702,13.445321,0.729511,-1208.680908,0.073090,0.000000
81.290001,59.307014,-1208.680908,0.013353,0.002872,0.072951,263.810791,13.439161,0.729511,-1208.680908,0.073090,0.000000
81.510002,59.285416,-1208.725342,0.013348,0.002872,0.072951,263.714691,13.434268,0.729511,-1208.725342,0.073090,0.000000
81.730003,59.262329,-1208.769897,0.013323,0.002872,0.072951,263.612000,13.429035,0.729511,-1208.769897,0.073090,0.000000
81.950005,59.240356,-1208.680908,0.013292,0.002872,0.072951,263.514252,13.424057,0.729511,-1208.680908,0.073090,0.000000
82.170006,59.220627,-1208.680908,0.013310,0.002872,0.072942,263.426514,13.419586,0.729424,-1208.680908,0.073090,0.000000
82.390007,59.197166,-1208.725342,0.013331,0.002872,0.072942,263.322144,13.414269,0.729424,-1208.725342,0.073090,0.000000
82.610001,59.188225,-1208.680908,0.013353,0.002872,0.072942,263.282379,13.412243,0.729424,-1208.680908,0.073090,0.000000
82.830002,59.161415,-1208.725342,0.013310,0.002872,0.072942,263.163116,13.406168,0.729424,-1208.725342,0.073090,0.000000
83.050003,59.146896,-1208.636353,0.013331,0.002872,0.072942,263.098541,13.402878,0.729424,-1208.636353,0.073090,0.000000
83.270004,59.128273,-1208.725342,0.013305,0.002872,0.072942,263.015686,13.398659,0.729424,-1208.725342,0.073090,0.000000
83.490005,59.099228,-1208.725342,0.013310,0.002872,0.072942,262.886505,13.392076,0.729424,-1208.725342,0.073090,0.000000
83.710007,59.082474,-1208.769897,0.013344,0.002872,0.072942,262.811981,13.388280,0.729424,-1208.769897,0.073090,0.000000
83.930000,59.071678,-1208.725342,0.013340,0.002872,0.072942,262.763947,13.385833,0.729424,-1208.725342,0.073090,0.000000
84.150002,59.051193,-1208.680908,0.013370,0.002872,0.072942,262.672821,13.381191,0.729424,-1208.680908,0.073090,0.000000
84.370003,59.045235,-1208.725342,0.013318,0.002872,0.072942,262.646332,13.379842,0.729424,-1208.725342,0.073090,0.000000
84.590004,59.002045,-1208.725342,0.013331,0.002872,0.072942,262.454193,13.370054,0.729424,-1208.725342,0.073090,0.000000
84.810005,58.994225,-1208.769897,0.013323,0.002872,0.072942,262.419403,13.368282,0.729424,-1208.769897,0.073090,0.000000
85.030006,58.975601,-1208.725342,0.013344,0.002872,0.072942,262.336578,13.364062,0.729424,-1208.725342,0.073090,0.000000
85.250008,58.957359,-1208.680908,0.013331,0.002872,0.072942,262.255432,13.359929,0.729424,-1208.680908,0.073090,0.000000
85.470001,58.949913,-1208.680908,0.013310,0.002872,0.072942,262.222321,13.358241,0.729424,-1208.680908,0.073090,0.000000
85.690002,58.934639,-1208.680908,0.013284,0.002872,0.072942,262.154358,13.354779,0.729424,-1208.680908,0.073090,0.000000
85.910004,58.916023,-1208.680908,0.013370,0.002872,0.072942,262.071564,13.350562,0.729424,-1208.680908,0.073090,0.000000
86.130005,58.892937,-1208.725342,0.013331,0.002872,0.072942,261.968872,13.345330,0.729424,-1208.725342,0.073090,0.000000
86.350006,58.872826,-1208.680908,0.013288,0.002872,0.072942,261.879395,13.340773,0.729424,-1208.680908,0.073090,0.000000
86.570007,58.860168,-1208.725342,0.013301,0.002872,0.072942,261.823120,13.337905,0.729424,-1208.725342,0.073090,0.000000
86.790001,58.839317,-1208.725342,0.013318,0.002872,0.072942,261.730347,13.333180,0.729424,-1208.725342,0.073090,0.000000
87.010002,58.832985,-1208.725342,0.013366,0.002872,0.072942,261.702179,13.331745,0.729424,-1208.725342,0.073090,0.000000
87.230003,58.818832,-1208.769897,0.013361,0.002872,0.072942,261.639221,13.328538,0.729424,-1208.769897,0.073090,0.000000
87.450005,58.801331,-1208.680908,0.013336,0.002872,0.072942,261.561371,13.324573,0.729424,-1208.680908,0.073090,0.000000
87.670006,58.784576,-1208.680908,0.013361,0.002872,0.072942,261.486847,13.320776,0.729424,-1208.680908,0.073090,0.000000
87.890007,58.756645,-1208.725342,0.013327,0.002872,0.072942,261.362610,13.314446,0.729424,-1208.725342,0.073090,0.000000
88.110001,58.755157,-1208.814331,0.013331,0.002872,0.072942,261.355988,13.314109,0.729424,-1208.814331,0.073090,0.000000
88.330002,58.732445,-1208.769897,0.013348,0.002872,0.072942,261.254974,13.308962,0.729424,-1208.769897,0.073090,0.000000
88.550003,58.727600,-1208.725342,0.013327,0.002872,0.072942,261.233398,13.307864,0.729424,-1208.725342,0.073090,0.000000
88.770004,58.701164,-1208.814331,0.013340,0.002872,0.072942,261.115814,13.301874,0.729424,-1208.814331,0.073090,0.000000
88.990005,58.692604,-1208.769897,0.013297,0.002872,0.072942,261.077728,13.299934,0.729424,-1208.769897,0.073090,0.000000
89.210007,58.665787,-1208.814331,0.013288,0.002872,0.072942,260.958466,13.293858,0.729424,-1208.814331,0.073090,0.000000
89.430008,58.650146,-1208.725342,0.013383,0.002872,0.072942,260.888885,13.290313,0.729424,-1208.725342,0.073090,0.000000
89.650002,58.647919,-1208.725342,0.013340,0.002872,0.072942,260.878967,13.289808,0.729424,-1208.725342,0.073090,0.000000
89.870003,58.633018,-1208.725342,0.013344,0.002872,0.072942,260.812683,13.286432,0.729424,-1208.725342,0.073090,0.000000
90.090004,58.617012,-1208.769897,0.013284,0.002872,0.072942,260.741486,13.282805,0.729424,-1208.769897,0.073090,0.000000
90.310005,58.602486,-1208.769897,0.013353,0.002872,0.072942,260.676880,13.279513,0.729424,-1208.769897,0.073090,0.000000
90.530006,58.589081,-1208.725342,0.013323,0.002872,0.072942,260.617249,13.276476,0.729424,-1208.725342,0.073090,0.000000
90.750008,58.561897,-1208.769897,0.013297,0.002872,0.072942,260.496338,13.270316,0.729424,-1208.769897,0.073090,0.000000
90.970001,58.556686,-1208.814331,0.013327,0.002872,0.072942,260.473145,13.269135,0.729424,-1208.814331,0.073090,0.000000
91.190002,58.545883,-1208.769897,0.013314,0.002872,0.072942,260.425110,13.266686,0.729424,-1208.769897,0.073090,0.000000
91.410004,58.523544,-1208.858765,0.013292,0.002872,0.072942,260.325714,13.261625,0.729424,-1208.858765,0.073090,0.000000
91.630005,58.524658,-1208.769897,0.013314,0.002872,0.072942,260.330688,13.261878,0.729424,-1208.769897,0.073090,0.000000
91.700005,58.512001,-1208.725342,0.013327,0.002872,0.072942,260.274384,13.259008,0.729424,-1208.725342,0.073090,0.000000