File: Data/compression 5/AutoNoheating-10-5-4-240223_02232024_193947.csv
Time (sec),S:Load (lbs),S:HL1 (DIM),S:LVDT (in),S:Position (in),Ch:Position (mm),Ch:Load (N),Ch:Stress (MPa),Ch:Strain (mm/mm),Ch:HL1 (DIM),Set Point (),Cycles ()
0.110000,-0.002983,-399.661346,0.000013,-0.000000,-0.000000,-0.013269,-0.000676,-0.000000,-399.661346,0.000208,0.000000
0.390000,-0.006706,-399.616852,0.000000,-0.000000,-0.000000,-0.029831,-0.001520,-0.000000,-399.616852,0.000260,0.000000
0.670000,-0.036125,-399.661346,0.000026,0.000153,0.003894,-0.160693,-0.008186,0.038939,-399.661346,0.004926,0.000000
0.950000,-0.069633,-399.616852,0.000194,0.000337,0.008551,-0.309745,-0.015779,0.085508,-399.616852,0.009591,0.000000
1.230000,0.024574,-399.705841,0.000379,0.000515,0.013086,0.109312,0.005569,0.130863,-399.705841,0.014257,0.000000
1.510000,-0.035378,-399.661346,0.000565,0.000704,0.017891,-0.157367,-0.008017,0.178908,-399.661346,0.018906,0.000000
1.790000,-0.006706,-399.661346,0.000772,0.000888,0.022548,-0.029831,-0.001520,0.225478,-399.661346,0.023571,0.000000
2.070000,-0.000748,-399.661346,0.000957,0.001075,0.027300,-0.003326,-0.000169,0.273001,-399.661346,0.028237,0.000000
2.350000,-0.009682,-399.661346,0.001155,0.001259,0.031974,-0.043066,-0.002194,0.319744,-399.661346,0.032902,0.000000
2.630000,-0.010429,-399.705841,0.001306,0.001439,0.036545,-0.046392,-0.002363,0.365447,-399.705841,0.037568,0.000000
2.910000,-0.046181,-399.750305,0.001509,0.001622,0.041210,-0.205422,-0.010465,0.412103,-399.750305,0.042234,0.000000
3.190000,0.006325,-399.705841,0.001673,0.001804,0.045815,0.028134,0.001433,0.458154,-399.705841,0.046899,0.000000
3.470000,-0.026443,-399.750305,0.001884,0.001989,0.050516,-0.117626,-0.005992,0.505159,-399.750305,0.051565,0.000000
3.750000,0.019363,-399.705841,0.002057,0.002171,0.055138,0.086133,0.004388,0.551380,-399.705841,0.056231,0.000000
4.030000,0.008186,-399.750305,0.002255,0.002358,0.059891,0.036415,0.001855,0.598907,-399.750305,0.060897,0.000000
4.310000,0.001114,-399.794800,0.002427,0.002535,0.064383,0.004955,0.000252,0.643830,-399.794800,0.065562,0.000000
4.590000,-0.005219,-399.750305,0.002621,0.002729,0.069309,-0.023213,-0.001183,0.693086,-399.750305,0.070228,0.000000
4.870000,-0.012665,-399.794800,0.002794,0.002904,0.073766,-0.056336,-0.002870,0.737661,-399.794800,0.074894,0.000000
5.150000,-0.015274,-399.705841,0.003005,0.003097,0.078657,-0.067942,-0.003461,0.786573,-399.705841,0.079559,0.000000
5.430000,-0.012291,-399.705841,0.003173,0.003274,0.083158,-0.054673,-0.002785,0.831583,-399.705841,0.084225,0.000000
5.710000,0.027924,-399.839264,0.003341,0.003451,0.087659,0.124210,0.006328,0.876589,-399.839264,0.088891,0.000000
5.990000,-0.004845,-399.750305,0.003548,0.003642,0.092516,-0.021550,-0.001098,0.925157,-399.750305,0.093556,0.000000
6.270000,0.035744,-399.705841,0.003725,0.003822,0.097077,0.158996,0.008100,0.970773,-399.705841,0.098222,0.000000
6.550000,-0.002983,-399.750305,0.003915,0.004010,0.101847,-0.013269,-0.000676,1.018470,-399.750305,0.102887,0.000000
6.830000,0.071121,-399.794800,0.004092,0.004189,0.106409,0.316363,0.016116,1.064085,-399.794800,0.107536,0.000000
7.110000,0.196609,-399.839264,0.004273,0.004381,0.111282,0.874563,0.044552,1.112823,-399.839264,0.112202,0.000000
7.390000,0.463600,-399.883759,0.004458,0.004562,0.115870,2.062196,0.105053,1.158700,-399.883759,0.116867,0.000000
7.670001,0.569351,-399.794800,0.004575,-0.000001,-0.000017,2.532601,0.129017,-0.000174,-399.794800,0.000199,0.000000
7.950000,0.513123,-399.750305,0.004575,-0.000001,-0.000017,2.282483,0.116275,-0.000174,-399.750305,0.000199,0.000000
8.230000,0.554832,-399.839264,0.004592,-0.000000,-0.000009,2.468018,0.125727,-0.000087,-399.839264,0.000399,0.000000
8.510000,0.514984,-399.883759,0.004579,-0.000000,-0.000009,2.290764,0.116697,-0.000087,-399.883759,0.000867,0.000000
8.790000,0.497116,-399.883759,0.004583,-0.000000,-0.000009,2.211283,0.112648,-0.000087,-399.883759,0.001336,0.000000
9.070001,0.687767,-399.839264,0.004605,0.000036,0.000911,3.059340,0.155850,0.009106,-399.839264,0.001804,0.000000
9.350000,0.736176,-399.839264,0.004613,0.000051,0.001283,3.274672,0.166820,0.012835,-399.839264,0.002272,0.000000
9.630000,0.805435,-399.839264,0.004631,0.000077,0.001951,3.582755,0.182514,0.019515,-399.839264,0.002732,0.000000
9.910001,0.855339,-399.883759,0.004648,0.000092,0.002342,3.804738,0.193823,0.023417,-399.883759,0.003200,0.000000
10.190001,0.863525,-399.839264,0.004661,0.000112,0.002845,3.841153,0.195678,0.028447,-399.839264,0.003668,0.000000
10.470000,0.903748,-399.794800,0.004682,0.000130,0.003304,4.020070,0.204792,0.033042,-399.794800,0.004137,0.000000
10.750001,1.005775,-399.839264,0.004717,0.000151,0.003825,4.473913,0.227912,0.038246,-399.839264,0.004605,0.000000
11.030001,1.078018,-399.928223,0.004730,0.000167,0.004232,4.795264,0.244282,0.042323,-399.928223,0.005065,0.000000
11.310000,1.066101,-399.839264,0.004730,0.000177,0.004501,4.742254,0.241582,0.045010,-399.839264,0.005533,0.000000
11.590000,1.211327,-399.883759,0.004769,0.000206,0.005221,5.388250,0.274491,0.052209,-399.883759,0.006001,0.000000
11.870001,1.255638,-399.883759,0.004773,0.000221,0.005620,5.585357,0.284532,0.056198,-399.883759,0.006470,0.000000
12.150001,1.289894,-399.883759,0.004786,0.000241,0.006114,5.737736,0.292294,0.061141,-399.883759,0.006938,0.000000
12.430000,1.366234,-399.883759,0.004794,0.000259,0.006591,6.077312,0.309593,0.065910,-399.883759,0.007398,0.000000
12.710001,1.442566,-399.928223,0.004829,0.000277,0.007042,6.416854,0.326890,0.070418,-399.928223,0.007866,0.000000
12.990001,1.506615,-399.883759,0.004846,0.000293,0.007432,6.701757,0.341404,0.074324,-399.883759,0.008334,0.000000
13.270000,1.625778,-399.883759,0.004855,0.000313,0.007952,7.231822,0.368407,0.079524,-399.883759,0.008803,0.000000
13.550000,1.706581,-399.928223,0.004885,0.000332,0.008438,7.591252,0.386717,0.084380,-399.928223,0.009271,0.000000
13.830001,1.752007,-399.928223,0.004885,0.000350,0.008889,7.793314,0.397010,0.088892,-399.928223,0.009739,0.000000
14.110001,1.795952,-399.883759,0.004911,0.000367,0.009331,7.988793,0.406969,0.093313,-399.883759,0.010199,0.000000
14.390000,1.892769,-400.017181,0.004937,0.000388,0.009852,8.419456,0.428908,0.098517,-400.017181,0.010667,0.000000
14.670001,1.981018,-399.928223,0.004950,0.000405,0.010277,8.812009,0.448905,0.102767,-399.928223,0.011135,0.000000
14.950001,2.063309,-399.972717,0.004954,0.000424,0.010762,9.178056,0.467552,0.107623,-399.972717,0.011604,0.000000
15.230000,2.119911,-399.928223,0.004980,0.000440,0.011170,9.429836,0.480379,0.111700,-399.928223,0.012072,0.000000
15.510001,2.242050,-399.972717,0.004997,0.000461,0.011708,9.973137,0.508056,0.117078,-399.972717,0.012531,0.000000
15.790001,2.295303,-400.061676,0.005019,0.000477,0.012115,10.210019,0.520123,0.121151,-400.061676,0.013000,0.000000
16.070002,2.368660,-400.061676,0.005032,0.000497,0.012635,10.536325,0.536746,0.126355,-400.061676,0.013468,0.000000
16.350000,2.477020,-399.928223,0.005049,0.000515,0.013069,11.018336,0.561301,0.130692,-399.928223,0.013936,0.000000
16.630001,2.576439,-399.972717,0.005070,0.000536,0.013624,11.460572,0.583829,0.136241,-399.972717,0.014405,0.000000
16.910002,2.593575,-400.017181,0.005101,0.000550,0.013962,11.536796,0.587712,0.139625,-400.017181,0.014873,0.000000
17.190001,2.700066,-399.972717,0.005105,0.000570,0.014474,12.010491,0.611844,0.144742,-399.972717,0.015333,0.000000
17.470001,2.830025,-400.061676,0.005109,0.000592,0.015046,12.588578,0.641293,0.150465,-400.061676,0.015801,0.000000
17.750000,2.842690,-399.972717,0.005139,0.000608,0.015437,12.644915,0.644163,0.154367,-399.972717,0.016269,0.000000
18.030001,2.919395,-400.061676,0.005152,0.000625,0.015879,12.986119,0.661544,0.158791,-400.061676,0.016738,0.000000
18.310001,3.022545,-400.017181,0.005182,0.000645,0.016382,13.444951,0.684918,0.163822,-400.017181,0.017206,0.000000
18.590000,3.084732,-400.061676,0.005200,0.000660,0.016755,13.721574,0.699010,0.167550,-400.061676,0.017666,0.000000
18.870001,3.110420,-400.061676,0.005200,0.000674,0.017110,13.835840,0.704831,0.171104,-400.061676,0.018134,0.000000
19.150002,3.331612,-400.061676,0.005213,0.000701,0.017813,14.819749,0.754954,0.178129,-400.061676,0.018602,0.000000
19.430000,3.415398,-400.017181,0.005251,0.000721,0.018316,15.192448,0.773940,0.183159,-400.017181,0.019071,0.000000
19.710001,3.407204,-400.106140,0.005269,0.000738,0.018750,15.155999,0.772083,0.187496,-400.106140,0.019539,0.000000
19.990002,3.482048,-400.106140,0.005277,0.000754,0.019157,15.488923,0.789043,0.191572,-400.106140,0.019998,0.000000
20.270000,3.556526,-400.106140,0.005290,0.000772,0.019599,15.820219,0.805920,0.195993,-400.106140,0.020466,0.000000
20.550001,3.651855,-400.106140,0.005286,0.000789,0.020042,16.244265,0.827522,0.200418,-400.106140,0.020935,0.000000
20.830002,3.729309,-400.106140,0.005312,0.000804,0.020423,16.588795,0.845074,0.204233,-400.106140,0.021403,0.000000
21.110001,3.734894,-400.061676,0.005329,0.000820,0.020822,16.613638,0.846339,0.208222,-400.061676,0.021871,0.000000
21.390001,4.032417,-400.106140,0.005351,0.000849,0.021568,17.937088,0.913759,0.215678,-400.106140,0.022340,0.000000
21.670000,3.992943,-400.150635,0.005359,0.000867,0.022010,17.761497,0.904814,0.220103,-400.150635,0.022799,0.000000
21.950001,4.051781,-400.150635,0.005381,0.000880,0.022349,18.023220,0.918147,0.223487,-400.150635,0.023268,0.000000
22.230001,4.133331,-400.106140,0.005394,0.000898,0.022808,18.385977,0.936626,0.228082,-400.106140,0.023736,0.000000
22.510000,4.289726,-400.106140,0.005424,0.000918,0.023329,19.081656,0.972066,0.233286,-400.106140,0.024204,0.000000
22.790001,4.309837,-400.195129,0.005428,0.000933,0.023701,19.171114,0.976623,0.237014,-400.195129,0.024673,0.000000
23.070002,4.309837,-400.195129,0.005445,0.000952,0.024170,19.171114,0.976623,0.241696,-400.195129,0.025132,0.000000
23.350000,4.589859,-400.195129,0.005458,0.000978,0.024846,20.416712,1.040077,0.248459,-400.195129,0.025601,0.000000
23.630001,4.513893,-400.150635,0.005467,0.000989,0.025124,20.078800,1.022863,0.251238,-400.150635,0.026069,0.000000
23.910002,4.580925,-400.150635,0.005484,0.001009,0.025635,20.376972,1.038052,0.256355,-400.150635,0.026537,0.000000
24.190001,4.678856,-400.150635,0.005519,0.001025,0.026043,20.812590,1.060244,0.260427,-400.150635,0.027006,0.000000
24.470001,4.833763,-400.195129,0.005536,0.001046,0.026572,21.501652,1.095346,0.265719,-400.195129,0.027474,0.000000
24.750002,4.916801,-400.284088,0.005545,0.001064,0.027031,21.871025,1.114163,0.270313,-400.284088,0.027933,0.000000
25.030001,5.042664,-400.239594,0.005549,0.001087,0.027613,22.430887,1.142684,0.276127,-400.239594,0.028402,0.000000
25.310001,5.116020,-400.150635,0.005575,0.001108,0.028133,22.757195,1.159307,0.281327,-400.150635,0.028870,0.000000
25.590002,5.034103,-400.195129,0.005583,0.001123,0.028515,22.392811,1.140744,0.285146,-400.195129,0.029338,0.000000
25.870001,5.076180,-400.284088,0.005596,0.001138,0.028905,22.579973,1.150279,0.289049,-400.284088,0.029807,0.000000
26.150002,5.219543,-400.284088,0.005605,0.001158,0.029408,23.217690,1.182765,0.294079,-400.284088,0.030266,0.000000
26.430000,5.343170,-400.150635,0.005631,0.001177,0.029893,23.767609,1.210780,0.298935,-400.150635,0.030734,0.000000
26.710001,5.393814,-400.195129,0.005639,0.001192,0.030284,23.992884,1.222256,0.302837,-400.195129,0.031203,0.000000
26.990002,5.613884,-400.239594,0.005670,0.001219,0.030951,24.971804,1.272124,0.309514,-400.239594,0.031671,0.000000
27.270000,5.637344,-400.239594,0.005670,0.001237,0.031428,25.076160,1.277440,0.314283,-400.239594,0.032139,0.000000
27.550001,5.560631,-400.284088,0.005674,0.001252,0.031801,24.734921,1.260057,0.318014,-400.284088,0.032599,0.000000
27.830002,5.566223,-400.284088,0.005691,0.001267,0.032174,24.759798,1.261324,0.321743,-400.284088,0.033067,0.000000
28.110001,5.724480,-400.195129,0.005708,0.001287,0.032686,25.463757,1.297186,0.326860,-400.195129,0.033536,0.000000
28.390001,5.915131,-400.284088,0.005739,0.001308,0.033223,26.311815,1.340388,0.332234,-400.284088,0.034004,0.000000
28.670002,5.883484,-400.284088,0.005752,0.001321,0.033544,26.171043,1.333217,0.335444,-400.284088,0.034472,0.000000
28.950001,5.925560,-400.284088,0.005734,0.001338,0.033995,26.358208,1.342751,0.339952,-400.284088,0.034941,0.000000
29.230001,6.043228,-400.328552,0.005756,0.001359,0.034516,26.881622,1.369415,0.345156,-400.328552,0.035400,0.000000
29.510002,6.026100,-400.239594,0.005799,0.001375,0.034932,26.805431,1.365534,0.349319,-400.239594,0.035869,0.000000
29.790001,6.102806,-400.284088,0.005786,0.001392,0.035366,27.146637,1.382916,0.353657,-400.284088,0.036337,0.000000
30.070002,6.317665,-400.284088,0.005821,0.001416,0.035973,28.102379,1.431603,0.359728,-400.284088,0.036805,0.000000
30.350002,6.275215,-400.373047,0.005812,0.001430,0.036328,27.913551,1.421984,0.363282,-400.373047,0.037274,0.000000
30.630001,6.248405,-400.284088,0.005829,0.001445,0.036701,27.794296,1.415909,0.367010,-400.284088,0.037733,0.000000
30.910002,6.440926,-400.284088,0.005842,0.001467,0.037274,28.650667,1.459535,0.372736,-400.284088,0.038201,0.000000
31.190001,6.576469,-400.328552,0.005851,0.001489,0.037811,29.253597,1.490249,0.378111,-400.328552,0.038670,0.000000
31.470001,6.580933,-400.284088,0.005881,0.001506,0.038262,29.273451,1.491261,0.382623,-400.284088,0.039138,0.000000
31.750002,6.589500,-400.373047,0.005877,0.001524,0.038722,29.311562,1.493202,0.387217,-400.373047,0.039606,0.000000
32.030003,6.718712,-400.417511,0.005902,0.001544,0.039216,29.886322,1.522482,0.392161,-400.417511,0.040074,0.000000
32.310001,6.791695,-400.373047,0.005920,0.001564,0.039719,30.210966,1.539020,0.397191,-400.373047,0.040534,0.000000
32.590000,6.674400,-400.328552,0.005920,0.001575,0.040014,29.689215,1.512441,0.400139,-400.328552,0.041003,0.000000
32.870003,6.916817,-400.373047,0.005946,0.001599,0.040604,30.767538,1.567373,0.406036,-400.373047,0.041471,0.000000
33.150002,7.027779,-400.417511,0.005950,0.001619,0.041133,31.261120,1.592517,0.411327,-400.417511,0.041939,0.000000
33.430000,6.992409,-400.462006,0.005976,0.001638,0.041601,31.103788,1.584502,0.416009,-400.462006,0.042407,0.000000
33.710003,7.024055,-400.373047,0.005971,0.001655,0.042035,31.244558,1.591674,0.420347,-400.373047,0.042867,0.000000
33.990002,7.164818,-400.328552,0.005993,0.001675,0.042538,31.870701,1.623571,0.425377,-400.328552,0.043336,0.000000
34.270000,7.163322,-400.417511,0.006002,0.001690,0.042928,31.864050,1.623232,0.429279,-400.417511,0.043804,0.000000
34.550003,7.345787,-400.462006,0.006006,0.001711,0.043457,32.675694,1.664579,0.434566,-400.462006,0.044272,0.000000
34.830002,7.433296,-400.373047,0.006023,0.001730,0.043942,33.064953,1.684409,0.439423,-400.373047,0.044740,0.000000
35.110001,7.359940,-400.417511,0.006049,0.001746,0.044350,32.738647,1.667786,0.443499,-400.417511,0.045200,0.000000
35.390003,7.426590,-400.417511,0.006058,0.001765,0.044818,33.035122,1.682889,0.448185,-400.417511,0.045668,0.000000
35.670002,7.443352,-400.328552,0.006075,0.001782,0.045252,33.109684,1.686688,0.452518,-400.328552,0.046136,0.000000
35.950001,7.547241,-400.506470,0.006079,0.001801,0.045755,33.571804,1.710229,0.457548,-400.506470,0.046605,0.000000
36.230003,7.614265,-400.506470,0.006075,0.001819,0.046206,33.869946,1.725417,0.462060,-400.506470,0.047073,0.000000
36.510002,7.571815,-400.417511,0.006101,0.001833,0.046570,33.681118,1.715798,0.465701,-400.417511,0.047541,0.000000
36.790001,7.864128,-400.417511,0.006127,0.001858,0.047203,34.981388,1.782037,0.472033,-400.417511,0.048001,0.000000
37.070004,7.816093,-400.417511,0.006135,0.001875,0.047619,34.767719,1.771152,0.476193,-400.417511,0.048469,0.000000
37.350002,7.819077,-400.506470,0.006153,0.001892,0.048053,34.780991,1.771828,0.480530,-400.506470,0.048938,0.000000
37.630001,7.978447,-400.506470,0.006144,0.001912,0.048573,35.489906,1.807942,0.485734,-400.506470,0.049406,0.000000
37.910004,8.074150,-400.506470,0.006165,0.001934,0.049111,35.915615,1.829629,0.491113,-400.506470,0.049874,0.000000
38.190002,8.011215,-400.462006,0.006174,0.001947,0.049449,35.635666,1.815367,0.494493,-400.462006,0.050334,0.000000
38.470001,8.035797,-400.506470,0.006187,0.001966,0.049926,35.745010,1.820938,0.499262,-400.506470,0.050802,0.000000
38.750000,8.236877,-400.506470,0.006200,0.001987,0.050473,36.639462,1.866503,0.504727,-400.506470,0.051271,0.000000
39.030003,8.216393,-400.550964,0.006217,0.002003,0.050880,36.548340,1.861861,0.508803,-400.550964,0.051739,0.000000
39.310001,8.226074,-400.506470,0.006226,0.002022,0.051349,36.591404,1.864055,0.513485,-400.506470,0.052207,0.000000
39.590000,8.316566,-400.506470,0.006239,0.002040,0.051817,36.993935,1.884561,0.518167,-400.506470,0.052676,0.000000
39.870003,8.354546,-400.550964,0.006234,0.002057,0.052242,37.162876,1.893167,0.522418,-400.550964,0.053135,0.000000
40.150002,8.262566,-400.506470,0.006273,0.002070,0.052571,36.753727,1.872324,0.525714,-400.506470,0.053603,0.000000
40.430000,8.619301,-400.595459,0.006256,0.002095,0.053204,38.340565,1.953161,0.532043,-400.595459,0.054072,0.000000
40.710003,8.677765,-400.550964,0.006273,0.002115,0.053716,38.600628,1.966410,0.537160,-400.550964,0.054540,0.000000
40.990002,8.634941,-400.550964,0.006286,0.002132,0.054158,38.410137,1.956706,0.541584,-400.550964,0.055008,0.000000
41.270000,8.640152,-400.550964,0.006312,0.002150,0.054601,38.433315,1.957886,0.546005,-400.550964,0.055468,0.000000
41.550003,8.661011,-400.595459,0.006325,0.002166,0.055026,38.526100,1.962613,0.550256,-400.595459,0.055936,0.000000
41.830002,8.804001,-400.639923,0.006325,0.002186,0.055520,39.162151,1.995015,0.555199,-400.639923,0.056404,0.000000
42.110001,8.821503,-400.595459,0.006342,0.002202,0.055928,39.240005,1.998981,0.559275,-400.595459,0.056873,0.000000
42.390003,8.717606,-400.550964,0.006338,0.002216,0.056283,38.777847,1.975438,0.562829,-400.550964,0.057341,0.000000
42.670002,9.168182,-400.595459,0.006372,0.002245,0.057029,40.782112,2.077540,0.570289,-400.595459,0.057809,0.000000
42.950001,9.024818,-400.684418,0.006377,0.002261,0.057437,40.144398,2.045053,0.574365,-400.684418,0.058269,0.000000
43.230003,9.008430,-400.684418,0.006381,0.002278,0.057862,40.071499,2.041339,0.578616,-400.684418,0.058737,0.000000
43.510002,9.069504,-400.639923,0.006403,0.002294,0.058261,40.343166,2.055179,0.582605,-400.639923,0.059206,0.000000
43.790001,9.209511,-400.595459,0.006407,0.002313,0.058755,40.965950,2.086905,0.587548,-400.595459,0.059674,0.000000
44.070004,9.156265,-400.595459,0.006433,0.002329,0.059145,40.729103,2.074839,0.591450,-400.595459,0.060142,0.000000
44.350002,9.369629,-400.639923,0.006416,0.002351,0.059717,41.678192,2.123188,0.597173,-400.639923,0.060602,0.000000
44.630001,9.622101,-400.595459,0.006437,0.002374,0.060298,42.801243,2.180399,0.602983,-400.595459,0.061070,0.000000
44.910004,9.389740,-400.639923,0.006450,0.002388,0.060645,41.767651,2.127745,0.606454,-400.639923,0.061539,0.000000
45.190002,9.305214,-400.728882,0.006450,0.002403,0.061036,41.391659,2.108592,0.610356,-400.728882,0.062007,0.000000
45.470001,9.476128,-400.639923,0.006472,0.002423,0.061539,42.151920,2.147321,0.615386,-400.639923,0.062475,0.000000
45.750004,9.734184,-400.639923,0.006472,0.002442,0.062024,43.299812,2.205798,0.620242,-400.639923,0.062935,0.000000
46.030003,9.664925,-400.728882,0.006493,0.002458,0.062432,42.991734,2.190103,0.624318,-400.728882,0.063403,0.000000
46.310001,9.955750,-400.684418,0.006506,0.002482,0.063030,44.285385,2.256005,0.630302,-400.684418,0.063871,0.000000
46.590004,10.042885,-400.728882,0.006515,0.002504,0.063594,44.672981,2.275750,0.635938,-400.728882,0.064339,0.000000
46.870003,9.827278,-400.684418,0.006532,0.002520,0.064001,43.713917,2.226893,0.640014,-400.684418,0.064808,0.000000
47.150002,9.831375,-400.684418,0.006532,0.002534,0.064374,43.732140,2.227821,0.643743,-400.684418,0.065276,0.000000
47.430004,9.806427,-400.684418,0.006558,0.002550,0.064782,43.621166,2.222168,0.647819,-400.684418,0.065736,0.000000
47.710003,10.158691,-400.773376,0.006562,0.002575,0.065398,45.188118,2.301992,0.653977,-400.773376,0.066204,0.000000
47.990002,10.152733,-400.728882,0.006575,0.002590,0.065797,45.161610,2.300642,0.657966,-400.728882,0.066672,0.000000
48.270000,10.279335,-400.639923,0.006592,0.002610,0.066291,45.724766,2.329330,0.662909,-400.639923,0.067141,0.000000
48.550003,10.461426,-400.773376,0.006601,0.002633,0.066872,46.534744,2.370593,0.668719,-400.773376,0.067609,0.000000
48.830002,10.178429,-400.728882,0.006601,0.002647,0.067227,45.275913,2.306465,0.672273,-400.728882,0.068069,0.000000
49.110001,10.164276,-400.817841,0.006610,0.002661,0.067583,45.212959,2.303258,0.675831,-400.817841,0.068537,0.000000
49.390003,10.192200,-400.773376,0.006622,0.002677,0.067999,45.337170,2.309586,0.679994,-400.773376,0.069005,0.000000
49.670002,10.602928,-400.773376,0.006640,0.002701,0.068615,47.164181,2.402658,0.686148,-400.773376,0.069474,0.000000
49.950001,10.594368,-400.684418,0.006648,0.002718,0.069049,47.126102,2.400718,0.690486,-400.684418,0.069942,0.000000
50.230003,10.601067,-400.773376,0.006674,0.002734,0.069439,47.155899,2.402236,0.694388,-400.773376,0.070410,0.000000
50.510002,10.666977,-400.817841,0.006674,0.002752,0.069890,47.449081,2.417171,0.698900,-400.817841,0.070870,0.000000
50.790001,10.795448,-400.728882,0.006687,0.002771,0.070376,48.020554,2.446284,0.703756,-400.728882,0.071338,0.000000
51.070004,10.950729,-400.773376,0.006700,0.002789,0.070852,48.711277,2.481471,0.708525,-400.773376,0.071806,0.000000
51.350002,11.181595,-400.773376,0.006713,0.002813,0.071451,49.738216,2.533786,0.714509,-400.773376,0.072275,0.000000
51.630001,11.091858,-400.817841,0.006717,0.002829,0.071850,49.339046,2.513451,0.718498,-400.817841,0.072743,0.000000
51.910004,10.950729,-400.773376,0.006713,0.002842,0.072196,48.711277,2.481471,0.721965,-400.773376,0.073203,0.000000
52.190002,11.145851,-400.773376,0.006722,0.002863,0.072708,49.579224,2.525686,0.727082,-400.773376,0.073671,0.000000
52.470001,11.412842,-400.773376,0.006752,0.002884,0.073263,50.766857,2.586187,0.732635,-400.773376,0.074139,0.000000
52.750004,11.416191,-400.817841,0.006748,0.002904,0.073766,50.781754,2.586946,0.737665,-400.817841,0.074607,0.000000
53.030003,11.380814,-400.817841,0.006786,0.002920,0.074174,50.624386,2.578929,0.741741,-400.817841,0.075076,0.000000
53.310001,11.536095,-400.906799,0.006778,0.002941,0.074694,51.315113,2.614116,0.746941,-400.906799,0.075536,0.000000
53.590004,11.651901,-400.862335,0.006799,0.002961,0.075215,51.830246,2.640358,0.752146,-400.862335,0.076004,0.000000
53.870003,11.273201,-400.862335,0.006812,0.002970,0.075440,50.145702,2.554544,0.754402,-400.862335,0.076472,0.000000
54.150002,11.457153,-400.773376,0.006821,0.002989,0.075917,50.963963,2.596228,0.759170,-400.773376,0.076940,0.000000
54.430004,11.966560,-400.862335,0.006825,0.003016,0.076602,53.229919,2.711662,0.766021,-400.862335,0.077409,0.000000
54.710003,11.821335,-400.862335,0.006851,0.003033,0.077027,52.583923,2.678753,0.770272,-400.862335,0.077877,0.000000
54.990002,11.837715,-400.951294,0.006860,0.003050,0.077478,52.656788,2.682465,0.774779,-400.951294,0.078337,0.000000
55.270004,12.034698,-400.817841,0.006877,0.003071,0.077998,53.533012,2.727102,0.779984,-400.817841,0.078805,0.000000
55.550003,12.057419,-400.906799,0.006881,0.003088,0.078423,53.634079,2.732250,0.784234,-400.906799,0.079273,0.000000
55.830002,11.998581,-400.862335,0.006885,0.003104,0.078840,53.372353,2.718917,0.788397,-400.862335,0.079742,0.000000
56.110004,12.171738,-400.906799,0.006903,0.003123,0.079325,54.142593,2.758155,0.793253,-400.906799,0.080210,0.000000
56.390003,12.233925,-400.906799,0.006916,0.003142,0.079811,54.419216,2.772247,0.798109,-400.906799,0.080669,0.000000
56.670002,12.347496,-400.862335,0.006933,0.003162,0.080323,54.924404,2.797983,0.803227,-400.862335,0.081138,0.000000
56.950005,12.352333,-400.906799,0.006942,0.003178,0.080722,54.945923,2.799079,0.807216,-400.906799,0.081606,0.000000
57.230003,12.462555,-400.906799,0.006942,0.003196,0.081190,55.436214,2.824055,0.811898,-400.906799,0.082074,0.000000
57.510002,12.548950,-400.906799,0.006959,0.003216,0.081675,55.820518,2.843633,0.816754,-400.906799,0.082543,0.000000
57.790001,12.442451,-401.040253,0.006976,0.003229,0.082014,55.346786,2.819500,0.820138,-401.040253,0.083011,0.000000
58.070004,12.936584,-400.906799,0.006993,0.003254,0.082664,57.544804,2.931472,0.826640,-400.906799,0.083471,0.000000
58.350002,12.868820,-400.995789,0.007006,0.003270,0.083054,57.243370,2.916116,0.830542,-400.995789,0.083939,0.000000
58.630001,12.977180,-400.995789,0.006998,0.003288,0.083523,57.725380,2.940671,0.835228,-400.995789,0.084407,0.000000
58.910004,13.069901,-400.951294,0.007028,0.003307,0.084008,58.137821,2.961682,0.840084,-400.951294,0.084876,0.000000
59.190002,13.145493,-401.040253,0.007019,0.003326,0.084485,58.474072,2.978811,0.844853,-401.040253,0.085344,0.000000
59.470001,13.249008,-400.951294,0.007049,0.003344,0.084936,58.934532,3.002268,0.849361,-400.951294,0.085804,0.000000
59.750004,13.133202,-400.951294,0.007067,0.003359,0.085309,58.419399,2.976026,0.853093,-400.951294,0.086272,0.000000
60.030003,13.619888,-400.951294,0.007071,0.003383,0.085916,60.584290,3.086311,0.859160,-400.951294,0.086740,0.000000
60.310001,13.567390,-401.040253,0.007084,0.003400,0.086350,60.350765,3.074414,0.863497,-401.040253,0.087208,0.000000
60.590004,13.612442,-401.040253,0.007105,0.003418,0.086818,60.551167,3.084623,0.868179,-401.040253,0.087677,0.000000
60.870003,13.548767,-401.084747,0.007097,0.003433,0.087208,60.267925,3.070194,0.872081,-401.084747,0.088136,0.000000
61.150002,13.701813,-400.951294,0.007110,0.003452,0.087685,60.948708,3.104875,0.876854,-400.951294,0.088604,0.000000
61.430004,13.769211,-401.040253,0.007127,0.003467,0.088050,61.248508,3.120148,0.880495,-401.040253,0.089073,0.000000
61.710003,14.036201,-401.084747,0.007140,0.003485,0.088518,62.436142,3.180649,0.885177,-401.084747,0.089541,0.000000
61.990002,14.528107,-400.995789,0.007157,0.003510,0.089160,64.624245,3.292116,0.891596,-400.995789,0.090009,0.000000
62.270004,14.661049,-401.040253,0.007174,0.003530,0.089663,65.215599,3.322241,0.896626,-401.040253,0.090478,0.000000
62.550003,14.480446,-400.995789,0.007179,0.003546,0.090079,64.412239,3.281316,0.900790,-400.995789,0.090937,0.000000
62.830002,14.477097,-401.040253,0.007192,0.003563,0.090495,64.397339,3.280557,0.904949,-401.040253,0.091406,0.000000
63.110004,14.660301,-401.084747,0.007205,0.003580,0.090920,65.212280,3.322072,0.909200,-401.084747,0.091874,0.000000
63.390003,14.793983,-401.129211,0.007226,0.003597,0.091371,65.806923,3.352365,0.913711,-401.129211,0.092342,0.000000
63.670002,14.838669,-401.084747,0.007235,0.003613,0.091770,66.005699,3.362490,0.917701,-401.084747,0.092811,0.000000
63.950005,15.586021,-401.040253,0.007239,0.003642,0.092498,69.330086,3.531843,0.924983,-401.040253,0.093270,0.000000
64.230003,15.354774,-401.040253,0.007252,0.003655,0.092837,68.301445,3.479442,0.928367,-401.040253,0.093739,0.000000
64.510002,15.422920,-401.084747,0.007269,0.003673,0.093296,68.604576,3.494884,0.932961,-401.084747,0.094207,0.000000
64.790001,15.355148,-401.129211,0.007291,0.003687,0.093652,68.303108,3.479526,0.936519,-401.129211,0.094675,0.000000
65.070000,15.958015,-401.129211,0.007278,0.003710,0.094224,70.984795,3.616138,0.942242,-401.129211,0.095144,0.000000
65.350006,15.784492,-401.084747,0.007299,0.003723,0.094571,70.212929,3.576817,0.945709,-401.084747,0.095612,0.000000
65.630005,16.019463,-401.173706,0.007317,0.003739,0.094979,71.258125,3.630062,0.949785,-401.173706,0.096071,0.000000
65.910004,16.997307,-401.084747,0.007317,0.003771,0.095776,75.607796,3.851645,0.957764,-401.084747,0.096540,0.000000
66.190002,16.753403,-401.129211,0.007343,0.003783,0.096089,74.522858,3.796375,0.960886,-401.129211,0.097008,0.000000
66.470001,16.716171,-401.218170,0.007347,0.003800,0.096514,74.357246,3.787939,0.965137,-401.218170,0.097476,0.000000
66.750000,16.872192,-401.173706,0.007351,0.003817,0.096947,75.051262,3.823293,0.969474,-401.173706,0.097945,0.000000
67.030006,17.148117,-401.084747,0.007360,0.003837,0.097467,76.278633,3.885819,0.974675,-401.084747,0.098404,0.000000
67.310005,17.328346,-401.173706,0.007403,0.003853,0.097858,77.080338,3.926659,0.978577,-401.173706,0.098872,0.000000
67.590004,18.060059,-401.218170,0.007403,0.003877,0.098474,80.335152,4.092468,0.984735,-401.218170,0.099341,0.000000
67.870003,18.463715,-401.173706,0.007416,0.003899,0.099029,82.130707,4.183938,0.990287,-401.173706,0.099809,0.000000
68.150002,18.324074,-401.173706,0.007416,0.003914,0.099419,81.509552,4.152294,0.994190,-401.173706,0.100277,0.000000
68.430000,18.257790,-401.173706,0.007437,0.003928,0.099774,81.214706,4.137274,0.997744,-401.173706,0.100737,0.000000
68.710007,18.501320,-401.218170,0.007450,0.003945,0.100199,82.297981,4.192459,1.001994,-401.218170,0.101205,0.000000
68.990005,19.344749,-401.218170,0.007455,0.003969,0.100824,86.049744,4.383583,1.008239,-401.218170,0.101674,0.000000
69.270004,19.111641,-401.218170,0.007468,0.003982,0.101145,85.012825,4.330760,1.011445,-401.218170,0.102142,0.000000
69.550003,19.866066,-401.218170,0.007489,0.004005,0.101717,88.368675,4.501715,1.017172,-401.218170,0.102610,0.000000
69.830002,20.560913,-401.173706,0.007493,0.004028,0.102324,91.459511,4.659169,1.023239,-401.173706,0.103079,0.000000
70.110001,20.268974,-401.218170,0.007519,0.004040,0.102619,90.160904,4.593015,1.026191,-401.218170,0.103538,0.000000
70.390007,20.607086,-401.262665,0.007519,0.004058,0.103079,91.664894,4.669632,1.030786,-401.262665,0.104007,0.000000
70.670006,20.775032,-401.262665,0.007524,0.004075,0.103495,92.411957,4.707690,1.034949,-401.262665,0.104475,0.000000
70.950005,21.608772,-401.262665,0.007532,0.004097,0.104076,96.120621,4.896618,1.040759,-401.262665,0.104943,0.000000
71.230003,21.950233,-401.262665,0.007537,0.004116,0.104535,97.639511,4.973994,1.045354,-401.262665,0.105411,0.000000
71.510002,22.073860,-401.173706,0.007554,0.004131,0.104926,98.189430,5.002008,1.049256,-401.173706,0.105871,0.000000
71.790001,22.460762,-401.307129,0.007580,0.004148,0.105359,99.910461,5.089681,1.053594,-401.307129,0.106339,0.000000
72.070000,22.818977,-401.307129,0.007588,0.004166,0.105819,101.503883,5.170854,1.058189,-401.307129,0.106807,0.000000
72.350006,23.310143,-401.307129,0.007593,0.004185,0.106304,103.688690,5.282154,1.063045,-401.307129,0.107276,0.000000
72.630005,24.106270,-401.262665,0.007601,0.004208,0.106886,107.230042,5.462559,1.068858,-401.262665,0.107744,0.000000
72.910004,24.502106,-401.307129,0.007618,0.004225,0.107310,108.990807,5.552256,1.073105,-401.307129,0.108212,0.000000
73.190002,24.512527,-401.262665,0.007636,0.004238,0.107640,109.037170,5.554618,1.076401,-401.262665,0.108672,0.000000
73.470001,25.198441,-401.351624,0.007636,0.004258,0.108143,112.088264,5.710048,1.081432,-401.351624,0.109140,0.000000
73.750000,25.812859,-401.307129,0.007657,0.004279,0.108681,114.821327,5.849277,1.086810,-401.307129,0.109609,0.000000
74.030006,26.603027,-401.307129,0.007662,0.004300,0.109218,118.336174,6.028332,1.092184,-401.307129,0.110077,0.000000
74.310005,27.044662,-401.307129,0.007679,0.004318,0.109687,120.300667,6.128408,1.096866,-401.307129,0.110545,0.000000
74.590004,27.641953,-401.307129,0.007696,0.004338,0.110173,122.957542,6.263756,1.101726,-401.307129,0.111005,0.000000
74.870003,28.256363,-401.351624,0.007700,0.004357,0.110667,125.690582,6.402984,1.106669,-401.351624,0.111473,0.000000
75.150002,28.318176,-401.351624,0.007692,0.004368,0.110944,125.965538,6.416991,1.109444,-401.351624,0.111942,0.000000
75.430000,28.862587,-401.307129,0.007726,0.004387,0.111430,128.387192,6.540356,1.114300,-401.307129,0.112410,0.000000
75.710007,30.066841,-401.351624,0.007731,0.004412,0.112054,133.743988,6.813244,1.120545,-401.351624,0.112878,0.000000
75.990005,30.527092,-401.307129,0.007752,0.004428,0.112462,135.791290,6.917538,1.124621,-401.307129,0.113347,0.000000
76.270004,30.950851,-401.396088,0.007756,0.004444,0.112887,137.676270,7.013563,1.128868,-401.396088,0.113806,0.000000
76.550003,31.773048,-401.351624,0.007774,0.004467,0.113459,141.333572,7.199876,1.134594,-401.351624,0.114274,0.000000
76.830002,32.336075,-401.307129,0.007769,0.004481,0.113824,143.838043,7.327459,1.138235,-401.307129,0.114743,0.000000
77.110001,32.733025,-401.396088,0.007778,0.004498,0.114249,145.603760,7.417409,1.142486,-401.396088,0.115211,0.000000
77.390007,33.844933,-401.396088,0.007791,0.004518,0.114760,150.549774,7.669371,1.147599,-401.396088,0.115679,0.000000
77.670006,34.617233,-401.396088,0.007800,0.004537,0.115246,153.985138,7.844377,1.152459,-401.396088,0.116139,0.000000
77.950005,35.274467,-401.396088,0.007821,0.004557,0.115740,156.908661,7.993309,1.157402,-401.396088,0.116607,0.000000
78.230003,35.969315,-401.440582,0.007817,0.004575,0.116200,159.999496,8.150764,1.161997,-401.440582,0.117076,0.000000
78.510002,36.747200,-401.351624,0.007830,0.004592,0.116642,163.459717,8.327034,1.166421,-401.351624,0.117544,0.000000
78.790001,37.449493,-401.440582,0.007847,0.004609,0.117076,166.583664,8.486176,1.170755,-401.440582,0.118012,0.000000
79.070007,37.931717,-401.440582,0.007860,0.004624,0.117448,168.728699,8.595450,1.174483,-401.440582,0.118472,0.000000
79.350006,39.257362,-401.485077,0.007864,0.004648,0.118047,174.625473,8.895845,1.180467,-401.485077,0.118940,0.000000
79.630005,40.161110,-401.396088,0.007869,0.004667,0.118533,178.645538,9.100637,1.185327,-401.396088,0.119409,0.000000
79.910004,40.938255,-401.396088,0.007881,0.004685,0.118992,182.102448,9.276741,1.189922,-401.396088,0.119877,0.000000
80.190002,41.715393,-401.485077,0.007899,0.004701,0.119417,185.559341,9.452844,1.194172,-401.485077,0.120345,0.000000
80.470001,42.815758,-401.485077,0.007890,0.004722,0.119929,190.454010,9.702189,1.199286,-401.485077,0.120813,0.000000
80.750008,43.658432,-401.485077,0.007912,0.004740,0.120406,194.202408,9.893142,1.204058,-401.485077,0.121273,0.000000
81.030006,44.072884,-401.529541,0.007929,0.004752,0.120709,196.045975,9.987058,1.207094,-401.529541,0.121741,0.000000
81.310005,45.412308,-401.485077,0.007925,0.004776,0.121308,202.004028,10.290576,1.213078,-401.485077,0.122210,0.000000
81.590004,46.399094,-401.485077,0.007933,0.004794,0.121767,206.393478,10.514185,1.217673,-401.485077,0.122678,0.000000
81.870003,47.403008,-401.529541,0.007946,0.004814,0.122270,210.859116,10.741674,1.222703,-401.529541,0.123146,0.000000
82.150002,48.126160,-401.529541,0.007959,0.004829,0.122652,214.075851,10.905543,1.226518,-401.529541,0.123606,0.000000
82.430000,49.188164,-401.618500,0.007955,0.004847,0.123120,218.799881,11.146197,1.231200,-401.618500,0.124074,0.000000
82.710007,50.118347,-401.529541,0.007963,0.004864,0.123536,222.937546,11.356979,1.235363,-401.529541,0.124542,0.000000
82.990005,50.870918,-401.574036,0.007989,0.004880,0.123944,226.285141,11.527514,1.239440,-401.574036,0.125011,0.000000
83.270004,52.641548,-401.574036,0.007985,0.004904,0.124551,234.161301,11.928745,1.245511,-401.574036,0.125479,0.000000
83.550003,53.994003,-401.618500,0.007998,0.004925,0.125089,240.177322,12.235216,1.250889,-401.618500,0.125947,0.000000
83.830002,54.893654,-401.574036,0.007994,0.004941,0.125497,244.179169,12.439080,1.254965,-401.574036,0.126407,0.000000
84.110001,55.678986,-401.529541,0.008011,0.004957,0.125912,247.672501,12.617039,1.259125,-401.529541,0.126875,0.000000
84.390007,56.832230,-401.574036,0.008019,0.004975,0.126364,252.802383,12.878367,1.263636,-401.574036,0.127344,0.000000
84.670006,58.072227,-401.618500,0.008028,0.004993,0.126832,258.318176,13.159355,1.268318,-401.618500,0.127812,0.000000
84.950005,59.045609,-401.618500,0.008028,0.005008,0.127213,262.647980,13.379926,1.272133,-401.618500,0.128280,0.000000
85.230003,60.551857,-401.618500,0.008032,0.005032,0.127820,269.348114,13.721247,1.278204,-401.618500,0.128740,0.000000
85.510002,61.983627,-401.574036,0.008050,0.005051,0.128289,275.716949,14.045691,1.282886,-401.574036,0.129208,0.000000
85.790001,62.870621,-401.574036,0.008041,0.005066,0.128688,279.662476,14.246686,1.286876,-401.574036,0.129676,0.000000
86.070007,63.918098,-401.618500,0.008054,0.005083,0.129104,284.321899,14.484048,1.291039,-401.618500,0.130145,0.000000
86.350006,65.031502,-401.618500,0.008071,0.005102,0.129589,289.274567,14.736349,1.295895,-401.618500,0.130613,0.000000
86.630005,66.201866,-401.662994,0.008063,0.005116,0.129954,294.480621,15.001557,1.299540,-401.662994,0.131072,0.000000
86.910004,67.277275,-401.618500,0.008080,0.005134,0.130413,299.264252,15.245248,1.304135,-401.618500,0.131541,0.000000
87.190002,66.933952,-401.662994,0.008084,0.005128,0.130240,297.737091,15.167451,1.302401,-401.662994,0.130457,0.000000
87.470001,66.376884,-401.618500,0.008101,0.005125,0.130171,295.259125,15.041217,1.301709,-401.618500,0.130240,0.000000
87.750008,65.871574,-401.618500,0.008093,0.005123,0.130136,293.011383,14.926712,1.301360,-401.618500,0.130240,0.000000
88.030006,65.433281,-401.618500,0.008101,0.005123,0.130119,291.061768,14.827394,1.301186,-401.618500,0.130240,0.000000
88.310005,65.063515,-401.618500,0.008110,0.005122,0.130110,289.416962,14.743604,1.301099,-401.618500,0.130240,0.000000
88.590004,64.731361,-401.707458,0.008119,0.005122,0.130110,287.939484,14.668336,1.301099,-401.707458,0.130240,0.000000
88.870003,64.412605,-401.662994,0.008110,0.005122,0.130101,286.521576,14.596105,1.301012,-401.662994,0.130240,0.000000
89.150002,64.134071,-401.662994,0.008110,0.005122,0.130101,285.282593,14.532988,1.301012,-401.662994,0.130240,0.000000
89.430008,63.876396,-401.707458,0.008097,0.005122,0.130101,284.136414,14.474598,1.301012,-401.707458,0.130240,0.000000
89.710007,63.659676,-401.662994,0.008101,0.005122,0.130093,283.172394,14.425488,1.300925,-401.662994,0.130240,0.000000
89.990005,63.432152,-401.618500,0.008110,0.005122,0.130093,282.160309,14.373932,1.300925,-401.618500,0.130240,0.000000
90.270004,63.230324,-401.662994,0.008136,0.005122,0.130093,281.262543,14.328197,1.300925,-401.662994,0.130240,0.000000
90.550003,63.043030,-401.662994,0.008106,0.005122,0.130093,280.429413,14.285754,1.300925,-401.662994,0.130240,0.000000
90.830002,62.861679,-401.751953,0.008114,0.005122,0.130093,279.622711,14.244660,1.300925,-401.751953,0.130240,0.000000
91.110001,62.701187,-401.707458,0.008127,0.005122,0.130093,278.908813,14.208292,1.300925,-401.707458,0.130240,0.000000
91.390007,62.555962,-401.751953,0.008114,0.005122,0.130093,278.262817,14.175384,1.300925,-401.751953,0.130240,0.000000
91.670006,62.412598,-401.751953,0.008114,0.005122,0.130093,277.625092,14.142897,1.300925,-401.751953,0.130240,0.000000
91.950005,62.279663,-401.751953,0.008127,0.005122,0.130093,277.033783,14.112774,1.300925,-401.751953,0.130240,0.000000
92.230003,62.147102,-401.796417,0.008127,0.005122,0.130093,276.444122,14.082735,1.300925,-401.796417,0.130240,0.000000
92.510002,62.015648,-401.751953,0.008110,0.005122,0.130093,275.859375,14.052947,1.300925,-401.751953,0.130240,0.000000
92.790001,61.906174,-401.707458,0.008127,0.005122,0.130093,275.372406,14.028139,1.300925,-401.707458,0.130240,0.000000
93.070007,61.806007,-401.796417,0.008140,0.005122,0.130093,274.926849,14.005442,1.300925,-401.796417,0.130240,0.000000
93.350006,61.694664,-401.796417,0.008127,0.005122,0.130093,274.431580,13.980210,1.300925,-401.796417,0.130240,0.000000
93.630005,61.589287,-401.796417,0.008123,0.005122,0.130093,273.962830,13.956331,1.300925,-401.796417,0.130240,0.000000
93.910004,61.501404,-401.796417,0.008132,0.005122,0.130093,273.571899,13.936418,1.300925,-401.796417,0.130240,0.000000
94.190002,61.406075,-401.751953,0.008127,0.005122,0.130093,273.147858,13.914815,1.300925,-401.751953,0.130240,0.000000
94.470001,61.301437,-401.796417,0.008140,0.005122,0.130093,272.682404,13.891104,1.300925,-401.796417,0.130240,0.000000
94.750008,61.224358,-401.840912,0.008144,0.005122,0.130093,272.339539,13.873637,1.300925,-401.840912,0.130240,0.000000
95.030006,61.134621,-401.840912,0.008127,0.005122,0.130093,271.940369,13.853303,1.300925,-401.840912,0.130240,0.000000
95.310005,61.057533,-401.796417,0.008119,0.005122,0.130093,271.597473,13.835835,1.300925,-401.796417,0.130240,0.000000
95.590004,60.975616,-401.840912,0.008144,0.005122,0.130093,271.233093,13.817272,1.300925,-401.840912,0.130240,0.000000
95.870003,60.908958,-401.840912,0.008136,0.005122,0.130093,270.936584,13.802168,1.300925,-401.840912,0.130240,0.000000
96.150002,60.835602,-401.840912,0.008140,0.005122,0.130093,270.610260,13.785544,1.300925,-401.840912,0.130240,0.000000
96.430008,60.766342,-401.885406,0.008136,0.005122,0.130093,270.302185,13.769850,1.300925,-401.885406,0.130240,0.000000
96.710007,60.692986,-401.840912,0.008132,0.005121,0.130084,269.975891,13.753227,1.300838,-401.840912,0.130240,0.000000
96.990005,60.615158,-401.840912,0.008132,0.005121,0.130084,269.629700,13.735591,1.300838,-401.840912,0.130240,0.000000
97.270004,60.555580,-401.929871,0.008157,0.005121,0.130084,269.364685,13.722091,1.300838,-401.929871,0.130240,0.000000
97.550003,60.498230,-401.885406,0.008140,0.005121,0.130084,269.109558,13.709095,1.300838,-401.885406,0.130240,0.000000
97.830002,60.437164,-401.885406,0.008127,0.005121,0.130084,268.837921,13.695257,1.300838,-401.885406,0.130240,0.000000
98.110008,60.383171,-401.885406,0.008140,0.005121,0.130084,268.597748,13.683022,1.300838,-401.885406,0.130240,0.000000
98.390007,60.329918,-401.840912,0.008136,0.005121,0.130084,268.360870,13.670955,1.300838,-401.840912,0.130240,0.000000
98.670006,60.268852,-401.885406,0.008140,0.005121,0.130084,268.089233,13.657117,1.300838,-401.885406,0.130240,0.000000
98.950005,60.203316,-401.974365,0.008149,0.005121,0.130084,267.797729,13.642266,1.300838,-401.974365,0.130240,0.000000
99.230003,60.158257,-401.885406,0.008140,0.005121,0.130084,267.597290,13.632056,1.300838,-401.885406,0.130240,0.000000
99.510002,60.095329,-401.885406,0.008132,0.005121,0.130084,267.317383,13.617797,1.300838,-401.885406,0.130240,0.000000
99.790009,60.059952,-401.885406,0.008136,0.005121,0.130084,267.160004,13.609779,1.300838,-401.885406,0.130240,0.000000
100.070007,60.005585,-401.929871,0.008149,0.005121,0.130084,266.918182,13.597460,1.300838,-401.929871,0.130240,0.000000
100.350006,59.973190,-401.929871,0.008153,0.005121,0.130084,266.774078,13.590119,1.300838,-401.929871,0.130240,0.000000
100.630005,59.905418,-401.974365,0.008127,0.005121,0.130084,266.472595,13.574762,1.300838,-401.974365,0.130240,0.000000
100.910004,59.856262,-401.929871,0.008132,0.005121,0.130084,266.253937,13.563623,1.300838,-401.929871,0.130240,0.000000
101.190002,59.817909,-401.974365,0.008140,0.005121,0.130084,266.083344,13.554933,1.300838,-401.974365,0.130240,0.000000
101.470001,59.794075,-401.929871,0.008144,0.005121,0.130084,265.977325,13.549531,1.300838,-401.929871,0.130240,0.000000
101.750008,59.734497,-401.974365,0.008153,0.005121,0.130084,265.712311,13.536030,1.300838,-401.974365,0.130240,0.000000
102.030006,59.699493,-402.018829,0.008144,0.005121,0.130084,265.556610,13.528098,1.300838,-402.018829,0.130240,0.000000
102.310005,59.646248,-401.974365,0.008136,0.005121,0.130084,265.319763,13.516033,1.300838,-401.974365,0.130240,0.000000
102.590004,59.614967,-402.018829,0.008144,0.005121,0.130084,265.180634,13.508945,1.300838,-402.018829,0.130240,0.000000
102.870003,59.568420,-401.974365,0.008153,0.005121,0.130084,264.973572,13.498398,1.300838,-401.974365,0.130240,0.000000
103.150002,59.528206,-402.018829,0.008149,0.005121,0.130084,264.794678,13.489285,1.300838,-402.018829,0.130240,0.000000
103.430008,59.487984,-402.018829,0.008144,0.005121,0.130084,264.615753,13.480170,1.300838,-402.018829,0.130240,0.000000
103.710007,59.450378,-402.063324,0.008144,0.005121,0.130084,264.448486,13.471648,1.300838,-402.063324,0.130240,0.000000
103.990005,59.401596,-402.018829,0.008140,0.005121,0.130084,264.231506,13.460594,1.300838,-402.018829,0.130240,0.000000
104.270004,59.366592,-402.018829,0.008153,0.005121,0.130084,264.075806,13.452662,1.300838,-402.018829,0.130240,0.000000
104.550003,59.339409,-402.018829,0.008153,0.005121,0.130084,263.954865,13.446503,1.300838,-402.018829,0.130240,0.000000
104.830002,59.299942,-402.107788,0.008157,0.005121,0.130084,263.779327,13.437559,1.300838,-402.107788,0.130240,0.000000
105.110008,59.267174,-402.063324,0.008144,0.005121,0.130084,263.633545,13.430133,1.300838,-402.063324,0.130240,0.000000
105.390007,59.229561,-402.063324,0.008144,0.005121,0.130084,263.466248,13.421611,1.300838,-402.063324,0.130240,0.000000
105.670006,59.191948,-402.107788,0.008144,0.005121,0.130084,263.298920,13.413087,1.300838,-402.107788,0.130240,0.000000
105.950005,59.155083,-402.063324,0.008162,0.005121,0.130084,263.134949,13.404734,1.300838,-402.063324,0.130240,0.000000
106.230003,59.114128,-402.063324,0.008140,0.005121,0.130084,262.952789,13.395452,1.300838,-402.063324,0.130240,0.000000
106.510002,59.099976,-402.152283,0.008140,0.005121,0.130084,262.889832,13.392246,1.300838,-402.152283,0.130240,0.000000
106.790009,59.060501,-402.063324,0.008149,0.005121,0.130084,262.714233,13.383301,1.300838,-402.063324,0.130240,0.000000
107.070007,59.032204,-402.107788,0.008153,0.005121,0.130084,262.588348,13.376888,1.300838,-402.107788,0.130240,0.000000
107.350006,59.005768,-402.107788,0.008149,0.005121,0.130084,262.470764,13.370898,1.300838,-402.107788,0.130240,0.000000
107.630005,58.976723,-402.152283,0.008140,0.005121,0.130084,262.341553,13.364317,1.300838,-402.152283,0.130240,0.000000
107.910004,58.932777,-402.152283,0.008149,0.005121,0.130084,262.146088,13.354359,1.300838,-402.152283,0.130240,0.000000
108.190002,58.923096,-402.152283,0.008140,0.005121,0.130084,262.103027,13.352164,1.300838,-402.152283,0.130240,0.000000
108.470009,58.891449,-402.107788,0.008153,0.005121,0.130084,261.962250,13.344993,1.300838,-402.107788,0.130240,0.000000
108.750008,58.856445,-402.196747,0.008144,0.005121,0.130084,261.806549,13.337061,1.300838,-402.196747,0.130240,0.000000
109.030006,58.823303,-402.152283,0.008149,0.005121,0.130084,261.659119,13.329551,1.300838,-402.152283,0.130240,0.000000
109.310005,58.801704,-402.196747,0.008132,0.005121,0.130084,261.563049,13.324656,1.300838,-402.196747,0.130240,0.000000
109.590004,58.770798,-402.107788,0.008153,0.005121,0.130084,261.425568,13.317654,1.300838,-402.107788,0.130240,0.000000
109.870003,58.748459,-402.107788,0.008157,0.005121,0.130084,261.326202,13.312592,1.300838,-402.107788,0.130240,0.000000
110.150002,58.721642,-402.196747,0.008157,0.005121,0.130084,261.206909,13.306515,1.300838,-402.196747,0.130240,0.000000
110.430008,58.680687,-402.196747,0.008153,0.005121,0.130084,261.024719,13.297234,1.300838,-402.196747,0.130240,0.000000
110.710007,58.650894,-402.196747,0.008166,0.005121,0.130084,260.892212,13.290483,1.300838,-402.196747,0.130240,0.000000
110.990005,58.628181,-402.196747,0.008153,0.005121,0.130084,260.791168,13.285336,1.300838,-402.196747,0.130240,0.000000
111.270004,58.607323,-402.152283,0.008153,0.005121,0.130084,260.698395,13.280609,1.300838,-402.152283,0.130240,0.000000
111.550003,58.582748,-402.196747,0.008153,0.005121,0.130084,260.589081,13.275041,1.300838,-402.196747,0.130240,0.000000
111.830002,58.556313,-402.241241,0.008140,0.005121,0.130084,260.471497,13.269051,1.300838,-402.241241,0.130240,0.000000
112.110008,58.535461,-402.285736,0.008149,0.005121,0.130084,260.378723,13.264325,1.300838,-402.285736,0.130240,0.000000
112.390007,58.506416,-402.196747,0.008153,0.005121,0.130084,260.249542,13.257743,1.300838,-402.196747,0.130240,0.000000
112.670006,58.478111,-402.196747,0.008157,0.005121,0.130084,260.123627,13.251329,1.300838,-402.196747,0.130240,0.000000
112.950005,58.459869,-402.241241,0.008153,0.005121,0.130084,260.042480,13.247196,1.300838,-402.241241,0.130240,0.000000
113.230003,58.425240,-402.285736,0.008153,0.005121,0.130084,259.888458,13.239348,1.300838,-402.285736,0.130240,0.000000
113.510002,58.399170,-402.285736,0.008144,0.005121,0.130084,259.772491,13.233441,1.300838,-402.285736,0.130240,0.000000
113.790009,58.376831,-402.241241,0.008162,0.005121,0.130084,259.673126,13.228379,1.300838,-402.241241,0.130240,0.000000
114.070007,58.368263,-402.241241,0.008166,0.005121,0.130084,259.635010,13.226438,1.300838,-402.241241,0.130240,0.000000
114.350006,58.345177,-402.285736,0.008166,0.005121,0.130084,259.532318,13.221207,1.300838,-402.285736,0.130240,0.000000
114.630005,58.328049,-402.330200,0.008157,0.005121,0.130084,259.456116,13.217325,1.300838,-402.330200,0.130240,0.000000
114.910004,58.297516,-402.330200,0.008153,0.005121,0.130084,259.320312,13.210405,1.300838,-402.330200,0.130240,0.000000
115.190002,58.278893,-402.285736,0.008153,0.005121,0.130084,259.237457,13.206186,1.300838,-402.285736,0.130240,0.000000
115.470009,58.257294,-402.285736,0.008162,0.005121,0.130084,259.141388,13.201292,1.300838,-402.285736,0.130240,0.000000
115.750008,58.250221,-402.330200,0.008162,0.005121,0.130084,259.109924,13.199689,1.300838,-402.330200,0.130240,0.000000
116.030006,58.220062,-402.330200,0.008153,0.005121,0.130084,258.975769,13.192854,1.300838,-402.330200,0.130240,0.000000
116.310005,58.191017,-402.285736,0.008153,0.005121,0.130084,258.846558,13.186274,1.300838,-402.285736,0.130240,0.000000
116.590004,58.176491,-402.330200,0.008149,0.005121,0.130084,258.781952,13.182981,1.300838,-402.330200,0.130240,0.000000
116.870003,58.145958,-402.285736,0.008136,0.005121,0.130084,258.646149,13.176062,1.300838,-402.285736,0.130240,0.000000
117.150009,58.134789,-402.330200,0.008157,0.005121,0.130084,258.596466,13.173531,1.300838,-402.330200,0.130240,0.000000
117.400009,58.121750,-402.374695,0.008162,0.005121,0.130084,258.538452,13.170577,1.300838,-402.374695,0.130240,0.000000