File: Data/compression 5/AutoNoheating-17-5-4-240223_02232024_195303.csv
Time (sec),S:Load (lbs),S:HL1 (DIM),S:LVDT (in),S:Position (in),Ch:Position (mm),Ch:Load (N),Ch:Stress (MPa),Ch:Strain (mm/mm),Ch:HL1 (DIM),Set Point (),Cycles ()
0.110000,-0.001862,-417.498199,0.000017,-0.000000,-0.000000,-0.008281,-0.000422,-0.000000,-417.498199,0.000165,0.000000
0.350000,-0.005585,-417.453735,-0.000017,-0.000000,-0.000000,-0.024842,-0.001266,-0.000000,-417.453735,0.000165,0.000000
0.590000,0.011543,-417.542694,-0.000004,0.000104,0.002636,0.051347,0.002616,0.026364,-417.542694,0.003547,0.000000
0.830000,-0.010803,-417.542694,0.000129,0.000256,0.006513,-0.048055,-0.002448,0.065129,-417.542694,0.007554,0.000000
1.070000,-0.023087,-417.587158,0.000285,0.000413,0.010485,-0.102694,-0.005231,0.104847,-417.587158,0.011560,0.000000
1.310000,-0.052132,-417.498199,0.000440,0.000570,0.014474,-0.231893,-0.011813,0.144740,-417.498199,0.015549,0.000000
1.550000,-0.029045,-417.587158,0.000617,0.000728,0.018498,-0.129199,-0.006582,0.184979,-417.587158,0.019556,0.000000
1.790000,0.007820,-417.631653,0.000759,0.000883,0.022435,0.034786,0.001772,0.224352,-417.631653,0.023545,0.000000
2.030000,-0.008942,-417.631653,0.000936,0.001042,0.026459,-0.039774,-0.002026,0.264591,-417.631653,0.027552,0.000000
2.270000,-0.034630,-417.587158,0.001069,0.001199,0.030466,-0.154041,-0.007847,0.304656,-417.587158,0.031541,0.000000
2.510000,-0.004845,-417.631653,0.001263,0.001360,0.034550,-0.021550,-0.001098,0.345502,-417.631653,0.035548,0.000000
2.750000,0.009308,-417.542694,0.001410,0.001512,0.038401,0.041403,0.002109,0.384008,-417.542694,0.039537,0.000000
2.990000,-0.011917,-417.631653,0.001578,0.001675,0.042555,-0.053010,-0.002700,0.425547,-417.631653,0.043543,0.000000
3.230000,-0.051392,-417.498199,0.001729,0.001825,0.046353,-0.228601,-0.011646,0.463532,-417.498199,0.047533,0.000000
3.470000,-0.026443,-417.631653,0.001888,0.001987,0.050464,-0.117626,-0.005992,0.504638,-417.631653,0.051539,0.000000
3.710000,0.002602,-417.676117,0.002061,0.002142,0.054418,0.011573,0.000590,0.544185,-417.676117,0.055528,0.000000
3.950000,0.011917,-417.631653,0.002207,0.002300,0.058416,0.053010,0.002700,0.584163,-417.631653,0.059535,0.000000
4.190000,-0.021225,-417.587158,0.002371,0.002457,0.062414,-0.094413,-0.004810,0.624142,-417.587158,0.063524,0.000000
4.430000,0.010422,-417.587158,0.002535,0.002619,0.066516,0.046358,0.002362,0.665161,-417.587158,0.067531,0.000000
4.670000,0.003349,-417.631653,0.002686,0.002773,0.070445,0.014898,0.000759,0.704447,-417.631653,0.071520,0.000000
4.910000,0.003723,-417.631653,0.002850,0.002935,0.074538,0.016561,0.000844,0.745380,-417.631653,0.075527,0.000000
5.150000,-0.028671,-417.676117,0.003009,0.003089,0.078458,-0.127536,-0.006497,0.784578,-417.676117,0.079516,0.000000
5.390000,-0.013031,-417.631653,0.003152,0.003247,0.082482,-0.057965,-0.002953,0.824818,-417.631653,0.083522,0.000000
5.630000,-0.005585,-417.631653,0.003298,0.003402,0.086402,-0.024842,-0.001266,0.864016,-417.631653,0.087529,0.000000
5.870000,-0.026443,-417.765106,0.003488,0.003564,0.090521,-0.117626,-0.005992,0.905211,-417.765106,0.091518,0.000000
6.110000,0.004463,-417.676117,0.003630,0.003716,0.094380,0.019853,0.001011,0.943801,-417.676117,0.095525,0.000000
6.350000,-0.012665,-417.720612,0.003820,0.003875,0.098421,-0.056336,-0.002870,0.984215,-417.720612,0.099514,0.000000
6.590000,0.012283,-417.631653,0.003988,0.004036,0.102515,0.054639,0.002783,1.025146,-417.631653,0.103521,0.000000
6.830000,0.019737,-417.676117,0.004130,0.004188,0.106365,0.087796,0.004473,1.063652,-417.676117,0.107510,0.000000
7.070000,0.004463,-417.676117,0.004294,0.004351,0.110528,0.019853,0.001011,1.105278,-417.676117,0.111516,0.000000
7.310000,-0.010429,-417.720612,0.004454,0.004504,0.114404,-0.046392,-0.002363,1.144043,-417.720612,0.115506,0.000000
7.550000,-0.014526,-417.720612,0.004587,0.004661,0.118394,-0.064617,-0.003292,1.183936,-417.720612,0.119512,0.000000
7.790000,-0.002983,-417.765106,0.004769,0.004822,0.122470,-0.013269,-0.000676,1.224695,-417.765106,0.123502,0.000000
8.030001,-0.001862,-417.676117,0.004924,0.004984,0.126589,-0.008281,-0.000422,1.265888,-417.676117,0.127508,0.000000
8.270000,-0.003349,-417.720612,0.005075,0.005133,0.130379,-0.014898,-0.000759,1.303787,-417.720612,0.131497,0.000000
8.510000,-0.007446,-417.720612,0.005260,0.005297,0.134533,-0.033123,-0.001687,1.345326,-417.720612,0.135504,0.000000
8.750000,0.027924,-417.720612,0.005376,0.005452,0.138479,0.124210,0.006328,1.384787,-417.720612,0.139493,0.000000
8.990001,0.016380,-417.720612,0.005562,0.005610,0.142485,0.072863,0.003712,1.424850,-417.720612,0.143500,0.000000
9.230000,-0.021973,-417.765106,0.005730,0.005766,0.146448,-0.097739,-0.004979,1.464482,-417.765106,0.147489,0.000000
9.470000,-0.005959,-417.765106,0.005872,0.005923,0.150446,-0.026505,-0.001350,1.504462,-417.765106,0.151496,0.000000
9.710000,0.014519,-417.765106,0.006023,0.006077,0.154357,0.064583,0.003290,1.543575,-417.765106,0.155485,0.000000
9.950001,-0.011917,-417.809570,0.006204,0.006242,0.158546,-0.053010,-0.002700,1.585462,-417.809570,0.159491,0.000000
10.190001,-0.035004,-417.765106,0.006359,0.006397,0.162492,-0.155704,-0.007932,1.624920,-417.765106,0.163481,0.000000
10.430000,-0.002609,-417.809570,0.006497,0.006552,0.166429,-0.011607,-0.000591,1.664294,-417.809570,0.167487,0.000000
10.670000,0.026810,-417.854065,0.006679,0.006710,0.170436,0.119255,0.006075,1.704357,-417.854065,0.171494,0.000000
10.910001,0.035744,-417.765106,0.006825,0.006865,0.174382,0.158996,0.008100,1.743818,-417.765106,0.175483,0.000000
11.150001,0.006332,-417.765106,0.006985,0.007025,0.178423,0.028168,0.001435,1.784230,-417.765106,0.179490,0.000000
11.390000,-0.012291,-417.809570,0.007157,0.007179,0.182352,-0.054673,-0.002785,1.823517,-417.809570,0.183479,0.000000
11.630000,-0.000000,-417.809570,0.007317,0.007340,0.186436,-0.000000,-0.000000,1.864360,-417.809570,0.187486,0.000000
11.870001,-0.006332,-417.854065,0.007468,0.007491,0.190278,-0.028168,-0.001435,1.902780,-417.854065,0.191475,0.000000
12.110001,-0.015266,-417.765106,0.007653,0.007657,0.194493,-0.067908,-0.003459,1.944925,-417.765106,0.195481,0.000000
12.350000,-0.041336,-417.809570,0.007804,0.007810,0.198369,-0.183872,-0.009367,1.983690,-417.809570,0.199470,0.000000
12.590000,-0.020485,-417.765106,0.007963,0.007972,0.202480,-0.091121,-0.004642,2.024798,-417.765106,0.203477,0.000000
12.830001,0.039467,-417.809570,0.008101,0.008119,0.206235,0.175557,0.008943,2.062348,-417.809570,0.207466,0.000000
13.070001,0.033882,-417.898529,0.008287,0.008285,0.210441,0.150715,0.007678,2.104409,-417.898529,0.211473,0.000000
13.310000,0.004463,-417.809570,0.008438,0.008440,0.214370,0.019853,0.001011,2.143696,-417.809570,0.215462,0.000000
13.550000,0.007072,-417.854065,0.008597,0.008599,0.218402,0.031460,0.001603,2.184021,-417.854065,0.219469,0.000000
13.790001,0.026810,-417.854065,0.008748,0.008754,0.222348,0.119255,0.006075,2.223478,-417.854065,0.223458,0.000000
14.030001,-0.000748,-417.898529,0.008908,0.008913,0.226398,-0.003326,-0.000169,2.263980,-417.898529,0.227465,0.000000
14.270000,-0.049896,-417.854065,0.009080,0.009070,0.230379,-0.221950,-0.011307,2.303786,-417.854065,0.231454,0.000000
14.510000,0.001114,-417.809570,0.009248,0.009229,0.234411,0.004955,0.000252,2.344110,-417.809570,0.235461,0.000000
14.750001,0.037605,-417.854065,0.009382,0.009381,0.238270,0.167277,0.008521,2.382701,-417.854065,0.239449,0.000000
14.990001,0.040962,-417.854065,0.009550,0.009540,0.242320,0.182209,0.009282,2.423203,-417.854065,0.243456,0.000000
15.230000,0.001488,-417.898529,0.009710,0.009699,0.246344,0.006618,0.000337,2.463440,-417.898529,0.247463,0.000000
15.470000,0.020477,-417.898529,0.009873,0.009859,0.250420,0.091088,0.004640,2.504200,-417.898529,0.251452,0.000000
15.710001,0.010422,-417.898529,0.010024,0.010010,0.254262,0.046358,0.002362,2.542620,-417.898529,0.255458,0.000000
15.950001,0.010056,-417.943024,0.010192,0.010175,0.258433,0.044729,0.002279,2.584334,-417.943024,0.259448,0.000000
16.190001,-0.029045,-417.943024,0.010348,0.010334,0.262475,-0.129199,-0.006582,2.624745,-417.943024,0.263454,0.000000
16.430000,-0.051018,-417.854065,0.010486,0.010489,0.266412,-0.226938,-0.011561,2.664116,-417.854065,0.267444,0.000000
16.670000,0.028671,-417.987488,0.010654,0.010647,0.270427,0.127536,0.006497,2.704270,-417.987488,0.271450,0.000000
16.910002,0.029785,-417.898529,0.010826,0.010798,0.274260,0.132491,0.006749,2.742599,-417.898529,0.275440,0.000000
17.150002,0.033142,-417.943024,0.010977,0.010961,0.278414,0.147423,0.007510,2.784142,-417.943024,0.279446,0.000000
17.390001,0.005585,-417.898529,0.011137,0.011116,0.282334,0.024842,0.001266,2.823339,-417.898529,0.283435,0.000000
17.630001,0.022713,-417.943024,0.011305,0.011276,0.286419,0.101031,0.005147,2.864185,-417.943024,0.287442,0.000000
17.870001,0.030159,-417.943024,0.011456,0.011427,0.290234,0.134154,0.006834,2.902344,-417.943024,0.291431,0.000000
18.110001,0.014893,-417.943024,0.011620,0.011592,0.294432,0.066245,0.003375,2.944319,-417.943024,0.295438,0.000000
18.350000,-0.032028,-417.987488,0.011766,0.011746,0.298343,-0.142469,-0.007258,2.983428,-417.987488,0.299427,0.000000
18.590000,0.013031,-417.898529,0.011939,0.011906,0.302419,0.057965,0.002953,3.024188,-417.898529,0.303434,0.000000
18.830002,0.090858,-417.943024,0.012098,0.012059,0.306287,0.404159,0.020589,3.062866,-417.943024,0.307423,0.000000
19.070002,0.473656,-418.076447,0.012236,0.012218,0.310328,2.106926,0.107332,3.103281,-418.076447,0.311429,0.000000
19.310001,0.698944,-418.031982,0.012275,-0.000002,-0.000043,3.109059,0.158383,-0.000431,-418.031982,0.000165,0.000000
19.550001,0.668404,-418.031982,0.012262,-0.000002,-0.000043,2.973208,0.151462,-0.000431,-418.031982,0.000165,0.000000
19.790001,0.621857,-417.987488,0.012284,-0.000002,-0.000043,2.766157,0.140915,-0.000431,-417.987488,0.000451,0.000000
20.030001,0.640106,-418.031982,0.012266,-0.000002,-0.000043,2.847335,0.145050,-0.000431,-418.031982,0.000850,0.000000
20.270000,0.794640,-418.031982,0.012284,0.000015,0.000382,3.534734,0.180068,0.003815,-418.031982,0.001249,0.000000
20.510000,1.017319,-417.943024,0.012301,0.000033,0.000850,4.525259,0.230528,0.008501,-417.943024,0.001657,0.000000
20.750002,1.251915,-418.031982,0.012305,0.000051,0.001283,5.568796,0.283688,0.012835,-418.031982,0.002056,0.000000
20.990002,1.377029,-417.987488,0.012335,0.000060,0.001518,6.125333,0.312039,0.015177,-417.987488,0.002455,0.000000
21.230001,1.627266,-417.987488,0.012327,0.000076,0.001925,7.238441,0.368744,0.019254,-417.987488,0.002853,0.000000
21.470001,1.826111,-417.987488,0.012361,0.000090,0.002298,8.122947,0.413803,0.022982,-417.987488,0.003252,0.000000
21.710001,2.182472,-418.031982,0.012365,0.000113,0.002862,9.708121,0.494555,0.028618,-418.031982,0.003651,0.000000
21.950001,2.353767,-418.076447,0.012370,0.000127,0.003226,10.470080,0.533371,0.032262,-418.076447,0.004050,0.000000
22.190001,2.623360,-418.076447,0.012404,0.000142,0.003616,11.669287,0.594462,0.036165,-418.076447,0.004457,0.000000
22.430000,2.846039,-418.031982,0.012409,0.000158,0.004024,12.659813,0.644922,0.040241,-418.031982,0.004856,0.000000
22.670002,3.170753,-418.120941,0.012421,0.000175,0.004449,14.104216,0.718503,0.044488,-418.120941,0.005255,0.000000
22.910002,3.401619,-417.987488,0.012439,0.000188,0.004787,15.131157,0.770818,0.047871,-417.987488,0.005654,0.000000
23.150002,3.653343,-418.076447,0.012452,0.000203,0.005151,16.250883,0.827859,0.051512,-418.076447,0.006053,0.000000
23.390001,3.940819,-418.031982,0.012469,0.000218,0.005533,17.529638,0.893002,0.055331,-418.031982,0.006452,0.000000
23.630001,4.235733,-418.031982,0.012473,0.000234,0.005949,18.841482,0.959831,0.059491,-418.031982,0.006851,0.000000
23.870001,4.424904,-418.076447,0.012486,0.000251,0.006365,19.682955,1.002698,0.063654,-418.076447,0.007250,0.000000
24.110001,4.732483,-418.076447,0.012495,0.000267,0.006773,21.051136,1.072396,0.067731,-418.076447,0.007658,0.000000
24.350000,4.956650,-418.076447,0.012516,0.000282,0.007172,22.048279,1.123193,0.071720,-418.076447,0.008057,0.000000
24.590002,5.307793,-418.076447,0.012555,0.000299,0.007606,23.610241,1.202763,0.076057,-418.076447,0.008455,0.000000
24.830002,5.505524,-418.076447,0.012542,0.000313,0.007952,24.489792,1.247569,0.079524,-418.076447,0.008854,0.000000
25.070002,5.581863,-418.120941,0.012555,0.000323,0.008213,24.829369,1.264868,0.082128,-418.120941,0.009253,0.000000
25.310001,6.103180,-418.076447,0.012568,0.000348,0.008828,27.148300,1.383000,0.088283,-418.076447,0.009652,0.000000
25.550001,6.276337,-418.120941,0.012581,0.000363,0.009210,27.918539,1.422238,0.092102,-418.120941,0.010051,0.000000
25.790001,6.373528,-418.076447,0.012607,0.000376,0.009539,28.350866,1.444262,0.095394,-418.076447,0.010450,0.000000
26.030001,6.646103,-418.120941,0.012607,0.000393,0.009973,29.563343,1.506028,0.099732,-418.120941,0.010858,0.000000
26.270000,6.861702,-418.165436,0.012633,0.000409,0.010381,30.522375,1.554884,0.103808,-418.165436,0.011257,0.000000
26.510002,7.101143,-418.076447,0.012654,0.000425,0.010797,31.587461,1.609142,0.107972,-418.076447,0.011656,0.000000
26.750002,7.246742,-418.165436,0.012659,0.000440,0.011179,32.235119,1.642135,0.111787,-418.165436,0.012055,0.000000
26.990002,7.329033,-418.165436,0.012676,0.000452,0.011491,32.601166,1.660783,0.114909,-418.165436,0.012453,0.000000
27.230001,7.651505,-418.165436,0.012693,0.000472,0.011994,34.035591,1.733856,0.119940,-418.165436,0.012852,0.000000
27.470001,7.771042,-418.120941,0.012719,0.000489,0.012419,34.567322,1.760943,0.124186,-418.120941,0.013251,0.000000
27.710001,7.909187,-418.120941,0.012728,0.000505,0.012826,35.181824,1.792247,0.128263,-418.120941,0.013650,0.000000
27.950001,8.005630,-418.165436,0.012753,0.000518,0.013156,35.610825,1.814102,0.131559,-418.165436,0.014058,0.000000
28.190001,8.073402,-418.165436,0.012766,0.000532,0.013511,35.912289,1.829459,0.135113,-418.165436,0.014457,0.000000
28.430002,8.350822,-418.165436,0.012762,0.000550,0.013971,37.146313,1.892323,0.139712,-418.165436,0.014856,0.000000
28.670002,8.236877,-418.209900,0.012779,0.000561,0.014240,36.639462,1.866503,0.142399,-418.209900,0.015255,0.000000
28.910002,8.473709,-418.165436,0.012797,0.000576,0.014639,37.692940,1.920170,0.146388,-418.165436,0.015654,0.000000
29.150002,8.861343,-418.209900,0.012805,0.000599,0.015220,39.417225,2.008009,0.152198,-418.209900,0.016052,0.000000
29.390001,8.905289,-418.209900,0.012831,0.000615,0.015627,39.612701,2.017967,0.156275,-418.209900,0.016451,0.000000
29.630001,8.837517,-418.165436,0.012840,0.000627,0.015922,39.311237,2.002610,0.159223,-418.165436,0.016850,0.000000
29.870001,9.006195,-418.254395,0.012861,0.000644,0.016356,40.061558,2.040833,0.163560,-418.254395,0.017258,0.000000
30.110001,9.028542,-418.209900,0.012879,0.000656,0.016668,40.160957,2.045897,0.166683,-418.209900,0.017657,0.000000
30.350002,9.324203,-418.209900,0.012891,0.000676,0.017180,41.476128,2.112895,0.171796,-418.209900,0.018056,0.000000
30.590002,9.450066,-418.254395,0.012900,0.000692,0.017570,42.035992,2.141416,0.175702,-418.254395,0.018455,0.000000
30.830002,9.456024,-418.165436,0.012909,0.000705,0.017917,42.062496,2.142766,0.179169,-418.165436,0.018854,0.000000
31.070002,9.669769,-418.298859,0.012926,0.000725,0.018420,43.013283,2.191201,0.184199,-418.298859,0.019253,0.000000
31.310001,9.827278,-418.209900,0.012956,0.000743,0.018871,43.713917,2.226893,0.188707,-418.209900,0.019652,0.000000
31.550001,9.746101,-418.254395,0.012956,0.000756,0.019200,43.352825,2.208498,0.192004,-418.254395,0.020050,0.000000
31.790001,9.705513,-418.209900,0.012986,0.000767,0.019478,43.172279,2.199301,0.194778,-418.209900,0.020458,0.000000
32.030003,10.013840,-418.209900,0.012995,0.000786,0.019972,44.543785,2.269169,0.199721,-418.209900,0.020857,0.000000
32.270000,10.135979,-418.298859,0.012995,0.000801,0.020354,45.087086,2.296846,0.203540,-418.298859,0.021256,0.000000
32.510002,10.186623,-418.209900,0.013029,0.000815,0.020701,45.312359,2.308322,0.207007,-418.209900,0.021655,0.000000
32.750000,10.229073,-418.298859,0.013038,0.000830,0.021091,45.501186,2.317941,0.210909,-418.298859,0.022053,0.000000
32.990002,10.459938,-418.298859,0.013042,0.000848,0.021542,46.528130,2.370256,0.215421,-418.298859,0.022452,0.000000
33.230003,10.699005,-418.298859,0.013073,0.000868,0.022036,47.591553,2.424429,0.220364,-418.298859,0.022851,0.000000
33.470001,10.679268,-418.343353,0.013094,0.000882,0.022409,47.503757,2.419957,0.224092,-418.343353,0.023250,0.000000
33.710003,10.638680,-418.209900,0.013111,0.000895,0.022721,47.323212,2.410759,0.227215,-418.209900,0.023658,0.000000
33.950001,10.721718,-418.254395,0.013120,0.000911,0.023129,47.692581,2.429576,0.231291,-418.254395,0.024057,0.000000
34.190002,10.818535,-418.343353,0.013129,0.000924,0.023458,48.123245,2.451515,0.234584,-418.343353,0.024456,0.000000
34.430000,11.000252,-418.254395,0.013142,0.000942,0.023927,48.931564,2.492693,0.239270,-418.254395,0.024855,0.000000
34.670002,11.246765,-418.343353,0.013150,0.000959,0.024369,50.028111,2.548553,0.243690,-418.343353,0.025254,0.000000
34.910000,11.342461,-418.298859,0.013189,0.000977,0.024820,50.453785,2.570238,0.248202,-418.298859,0.025653,0.000000
35.150002,11.478378,-418.298859,0.013185,0.000995,0.025280,51.058376,2.601038,0.252797,-418.298859,0.026051,0.000000
35.390003,11.539818,-418.343353,0.013206,0.001011,0.025670,51.331673,2.614960,0.256699,-418.343353,0.026459,0.000000
35.630001,11.428108,-418.298859,0.013223,0.001023,0.025991,50.834763,2.589646,0.259909,-418.298859,0.026858,0.000000
35.870003,11.669777,-418.432312,0.013254,0.001041,0.026442,51.909760,2.644409,0.264417,-418.432312,0.027257,0.000000
36.110001,11.779633,-418.343353,0.013262,0.001056,0.026832,52.398422,2.669303,0.268319,-418.343353,0.027656,0.000000
36.350002,11.884262,-418.387817,0.013271,0.001072,0.027231,52.863838,2.693012,0.272308,-418.387817,0.028055,0.000000
36.590000,11.958740,-418.343353,0.013297,0.001087,0.027604,53.195133,2.709889,0.276040,-418.343353,0.028454,0.000000
36.830002,12.063004,-418.298859,0.013292,0.001102,0.027994,53.658920,2.733516,0.279942,-418.298859,0.028853,0.000000
37.070004,12.430534,-418.343353,0.013314,0.001123,0.028532,55.293777,2.816799,0.285317,-418.343353,0.029252,0.000000
37.310001,12.364250,-418.343353,0.013344,0.001138,0.028896,54.998932,2.801779,0.288962,-418.343353,0.029659,0.000000
37.550003,12.248817,-418.387817,0.013348,0.001150,0.029217,54.485462,2.775622,0.292167,-418.387817,0.030058,0.000000
37.790001,12.478943,-418.387817,0.013379,0.001166,0.029616,55.509109,2.827769,0.296157,-418.387817,0.030457,0.000000
38.030003,12.697899,-418.343353,0.013383,0.001183,0.030041,56.483074,2.877385,0.300407,-418.343353,0.030856,0.000000
38.270000,12.871796,-418.432312,0.013400,0.001199,0.030466,57.256607,2.916790,0.304658,-418.432312,0.031255,0.000000
38.510002,12.823387,-418.387817,0.013413,0.001211,0.030761,57.041275,2.905821,0.307606,-418.387817,0.031654,0.000000
38.750000,12.855042,-418.387817,0.013422,0.001225,0.031107,57.182079,2.912994,0.311073,-418.387817,0.032053,0.000000
38.990002,13.129852,-418.476776,0.013443,0.001242,0.031558,58.404499,2.975267,0.315585,-418.476776,0.032452,0.000000
39.230003,13.132462,-418.387817,0.013456,0.001254,0.031845,58.416107,2.975858,0.318446,-418.387817,0.032859,0.000000
39.470001,13.396095,-418.432312,0.013465,0.001272,0.032321,59.588806,3.035599,0.323215,-418.432312,0.033258,0.000000
39.710003,13.493660,-418.387817,0.013504,0.001288,0.032720,60.022797,3.057707,0.327204,-418.387817,0.033657,0.000000
39.950001,13.804214,-418.432312,0.013495,0.001308,0.033223,61.404213,3.128080,0.332234,-418.432312,0.034056,0.000000
40.190002,13.914436,-418.476776,0.013508,0.001324,0.033640,61.894505,3.153056,0.336398,-418.476776,0.034455,0.000000
40.430000,13.696976,-418.387817,0.013517,0.001333,0.033857,60.927193,3.103779,0.338566,-418.387817,0.034854,0.000000
40.670002,13.790443,-418.521271,0.013542,0.001348,0.034229,61.342957,3.124959,0.342295,-418.521271,0.035253,0.000000
40.910004,14.229843,-418.432312,0.013555,0.001368,0.034759,63.297504,3.224529,0.347586,-418.432312,0.035652,0.000000
41.150002,14.202660,-418.521271,0.013568,0.001382,0.035097,63.176586,3.218369,0.350966,-418.521271,0.036059,0.000000
41.390003,14.283089,-418.476776,0.013594,0.001398,0.035504,63.534351,3.236594,0.355042,-418.476776,0.036458,0.000000
41.630001,14.566093,-418.387817,0.013611,0.001415,0.035929,64.793221,3.300724,0.359293,-418.387817,0.036857,0.000000
41.870003,14.948891,-418.521271,0.013637,0.001435,0.036458,66.495987,3.387467,0.364584,-418.521271,0.037256,0.000000
42.110001,15.002510,-418.476776,0.013642,0.001451,0.036849,66.734497,3.399617,0.368486,-418.476776,0.037655,0.000000
42.350002,14.845001,-418.476776,0.013646,0.001462,0.037126,66.033867,3.363925,0.371260,-418.476776,0.038054,0.000000
42.590000,14.852448,-418.565735,0.013668,0.001475,0.037473,66.066986,3.365613,0.374727,-418.565735,0.038453,0.000000
42.830002,15.195030,-418.521271,0.013689,0.001493,0.037933,67.590874,3.443243,0.379326,-418.521271,0.038852,0.000000
43.070004,15.523087,-418.565735,0.013693,0.001511,0.038383,69.050140,3.517582,0.383834,-418.565735,0.039259,0.000000
43.310001,15.583412,-418.565735,0.013711,0.001527,0.038782,69.318481,3.531252,0.387823,-418.565735,0.039658,0.000000
43.550003,15.656395,-418.565735,0.013724,0.001542,0.039164,69.643120,3.547790,0.391638,-418.565735,0.040057,0.000000
43.790001,15.845192,-418.521271,0.013732,0.001559,0.039589,70.482933,3.590572,0.395889,-418.521271,0.040456,0.000000
44.030003,15.997864,-418.476776,0.013762,0.001574,0.039988,71.162048,3.625168,0.399878,-418.476776,0.040855,0.000000
44.270000,16.114792,-418.565735,0.013775,0.001589,0.040361,71.682175,3.651664,0.403606,-418.565735,0.041254,0.000000
44.510002,16.290924,-418.565735,0.013784,0.001605,0.040768,72.465652,3.691576,0.407682,-418.565735,0.041653,0.000000
44.750004,16.295761,-418.610229,0.013793,0.001618,0.041089,72.487167,3.692672,0.410892,-418.610229,0.042052,0.000000
44.990002,16.587700,-418.610229,0.013814,0.001636,0.041557,73.785774,3.758826,0.415574,-418.610229,0.042459,0.000000
45.230003,16.745964,-418.565735,0.013831,0.001653,0.041974,74.489769,3.794690,0.419737,-418.565735,0.042858,0.000000
45.470001,16.889320,-418.610229,0.013831,0.001669,0.042390,75.127449,3.827175,0.423901,-418.610229,0.043257,0.000000
45.710003,17.063591,-418.610229,0.013862,0.001683,0.042745,75.902641,3.866665,0.427455,-418.610229,0.043656,0.000000
45.950001,17.425171,-418.565735,0.013879,0.001701,0.043214,77.511032,3.948600,0.432140,-418.565735,0.044055,0.000000
46.190002,17.329094,-418.565735,0.013892,0.001714,0.043535,77.083656,3.926829,0.435346,-418.565735,0.044454,0.000000
46.430000,17.216270,-418.565735,0.013896,0.001725,0.043812,76.581795,3.901263,0.438124,-418.565735,0.044853,0.000000
46.670002,18.067513,-418.610229,0.013909,0.001750,0.044445,80.368309,4.094157,0.444453,-418.610229,0.045252,0.000000
46.910004,18.099533,-418.565735,0.013931,0.001763,0.044792,80.510742,4.101413,0.447923,-418.565735,0.045659,0.000000
47.150002,18.181458,-418.610229,0.013952,0.001779,0.045183,80.875160,4.119977,0.451826,-418.610229,0.046058,0.000000
47.390003,18.307320,-418.654724,0.013969,0.001792,0.045529,81.435028,4.148498,0.455293,-418.654724,0.046457,0.000000
47.630001,18.511009,-418.565735,0.013982,0.001807,0.045902,82.341080,4.194654,0.459024,-418.565735,0.046856,0.000000
47.870003,18.766457,-418.654724,0.013995,0.001826,0.046379,83.477371,4.252540,0.463793,-418.654724,0.047255,0.000000
48.110001,18.926949,-418.610229,0.014008,0.001841,0.046752,84.191269,4.288908,0.467522,-418.610229,0.047654,0.000000
48.350002,18.910187,-418.654724,0.014012,0.001852,0.047047,84.116714,4.285110,0.470470,-418.654724,0.048053,0.000000
48.590004,19.368576,-418.654724,0.014030,0.001872,0.047550,86.155731,4.388982,0.475500,-418.654724,0.048461,0.000000
48.830002,19.770370,-418.610229,0.014051,0.001889,0.047984,87.943001,4.480030,0.479838,-418.610229,0.048860,0.000000
49.070004,20.035126,-418.654724,0.014060,0.001907,0.048435,89.120689,4.540024,0.484345,-418.654724,0.049259,0.000000
49.310001,19.927139,-418.699188,0.014094,0.001919,0.048738,88.640343,4.515554,0.487381,-418.699188,0.049657,0.000000
49.550003,19.944641,-418.699188,0.014086,0.001930,0.049033,88.718193,4.519520,0.490329,-418.699188,0.050056,0.000000
49.790001,20.467079,-418.699188,0.014099,0.001951,0.049553,91.042114,4.637906,0.495534,-418.699188,0.050455,0.000000
50.030003,20.359833,-418.654724,0.014112,0.001961,0.049805,90.565056,4.613604,0.498047,-418.654724,0.050854,0.000000
50.270004,20.712471,-418.654724,0.014116,0.001979,0.050256,92.133675,4.693513,0.502558,-418.654724,0.051253,0.000000
50.510002,21.389816,-418.699188,0.014150,0.002000,0.050794,95.146652,4.847002,0.507937,-418.699188,0.051661,0.000000
50.750004,21.599464,-418.699188,0.014163,0.002014,0.051166,96.079216,4.894508,0.511665,-418.699188,0.052060,0.000000
50.990002,21.742081,-418.743683,0.014185,0.002032,0.051617,96.713608,4.926826,0.516173,-418.743683,0.052459,0.000000
51.230003,21.862358,-418.654724,0.014189,0.002044,0.051912,97.248627,4.954081,0.519121,-418.654724,0.052858,0.000000
51.470001,21.951729,-418.699188,0.014181,0.002058,0.052285,97.646164,4.974333,0.522853,-418.699188,0.053257,0.000000
51.710003,22.600769,-418.743683,0.014219,0.002078,0.052771,100.533241,5.121408,0.527709,-418.743683,0.053655,0.000000
51.950001,22.824196,-418.654724,0.014228,0.002093,0.053161,101.527092,5.172037,0.531611,-418.654724,0.054054,0.000000
52.190002,23.005173,-418.743683,0.014237,0.002108,0.053534,102.332123,5.213047,0.535339,-418.743683,0.054453,0.000000
52.430004,23.542130,-418.699188,0.014258,0.002127,0.054020,104.720619,5.334723,0.540195,-418.699188,0.054861,0.000000
52.670002,23.933121,-418.743683,0.014262,0.002144,0.054453,106.459839,5.423323,0.544533,-418.743683,0.055260,0.000000
52.910004,24.063080,-418.788147,0.014275,0.002160,0.054861,107.037926,5.452772,0.548609,-418.788147,0.055659,0.000000
53.150002,23.946526,-418.743683,0.014293,0.002170,0.055112,106.519463,5.426360,0.551122,-418.743683,0.056058,0.000000
53.390003,24.414223,-418.788147,0.014310,0.002186,0.055529,108.599884,5.532342,0.555286,-418.788147,0.056457,0.000000
53.630001,24.677864,-418.788147,0.014319,0.002201,0.055901,109.772621,5.592084,0.559014,-418.788147,0.056856,0.000000
53.870003,24.907623,-418.788147,0.014336,0.002215,0.056248,110.794640,5.644148,0.562485,-418.788147,0.057254,0.000000
54.110004,25.109444,-418.788147,0.014353,0.002228,0.056604,111.692383,5.689881,0.566039,-418.788147,0.057653,0.000000
54.350002,25.827751,-418.788147,0.014362,0.002246,0.057055,114.887573,5.852652,0.570550,-418.788147,0.058061,0.000000
54.590004,26.635056,-418.788147,0.014375,0.002268,0.057619,118.478645,6.035590,0.576186,-418.788147,0.058460,0.000000
54.830002,26.893852,-418.743683,0.014383,0.002284,0.058018,119.629829,6.094234,0.580175,-418.743683,0.058859,0.000000
55.070004,26.877846,-418.832642,0.014392,0.002295,0.058304,119.558632,6.090607,0.583037,-418.832642,0.059257,0.000000
55.310001,27.262505,-418.788147,0.014418,0.002312,0.058720,121.269676,6.177772,0.587200,-418.788147,0.059656,0.000000
55.550003,27.367882,-418.743683,0.014426,0.002323,0.059015,121.738419,6.201651,0.590148,-418.743683,0.060055,0.000000
55.790001,27.934265,-418.832642,0.014444,0.002342,0.059492,124.257820,6.329995,0.594917,-418.832642,0.060454,0.000000
56.030003,28.471222,-418.788147,0.014457,0.002358,0.059899,126.646317,6.451671,0.598994,-418.788147,0.060853,0.000000
56.270004,28.905785,-418.832642,0.014465,0.002376,0.060350,128.579346,6.550145,0.603501,-418.832642,0.061261,0.000000
56.510002,29.756279,-418.877106,0.014482,0.002396,0.060871,132.362534,6.742869,0.608706,-418.877106,0.061660,0.000000
56.750004,29.857567,-418.832642,0.014487,0.002409,0.061200,132.813095,6.765821,0.612002,-418.832642,0.062059,0.000000
56.990002,30.022530,-418.832642,0.014504,0.002422,0.061530,133.546875,6.803203,0.615299,-418.832642,0.062458,0.000000
57.230003,30.590027,-418.832642,0.014508,0.002440,0.061972,136.071228,6.931799,0.619720,-418.832642,0.062857,0.000000
57.470001,30.842865,-418.877106,0.014530,0.002454,0.062328,137.195923,6.989093,0.623278,-418.877106,0.063255,0.000000
57.710003,31.473663,-418.877106,0.014551,0.002471,0.062770,140.001846,7.132034,0.627698,-418.877106,0.063654,0.000000
57.950005,31.880295,-418.877106,0.014551,0.002486,0.063134,141.810638,7.224178,0.631339,-418.877106,0.064053,0.000000
58.190002,32.211334,-418.877106,0.014564,0.002501,0.063525,143.283173,7.299192,0.635245,-418.877106,0.064461,0.000000
58.430004,33.373878,-418.832642,0.014573,0.002524,0.064106,148.454422,7.562629,0.641055,-418.832642,0.064860,0.000000
58.670002,33.501602,-418.832642,0.014594,0.002536,0.064426,149.022568,7.591571,0.644261,-418.832642,0.065259,0.000000
58.910004,33.729126,-418.877106,0.014599,0.002550,0.064773,150.034653,7.643129,0.647732,-418.877106,0.065658,0.000000
59.150002,34.064629,-418.877106,0.014616,0.002564,0.065137,151.527039,7.719155,0.651373,-418.877106,0.066057,0.000000
59.390003,34.924438,-418.877106,0.014629,0.002582,0.065588,155.351654,7.913991,0.655884,-418.877106,0.066456,0.000000
59.630001,35.487839,-418.877106,0.014638,0.002600,0.066031,157.857788,8.041659,0.660305,-418.877106,0.066854,0.000000
59.870003,35.711266,-418.966064,0.014651,0.002612,0.066334,158.851639,8.092288,0.663341,-418.966064,0.067253,0.000000
60.110004,36.053474,-418.877106,0.014672,0.002626,0.066690,160.373871,8.169834,0.666898,-418.877106,0.067661,0.000000
60.350002,36.647781,-418.877106,0.014668,0.002642,0.067097,163.017471,8.304506,0.670975,-418.877106,0.068060,0.000000
60.590004,36.912537,-418.921600,0.014689,0.002654,0.067418,164.195160,8.364501,0.674181,-418.921600,0.068459,0.000000
60.830002,37.782028,-418.877106,0.014711,0.002674,0.067912,168.062851,8.561530,0.679124,-418.877106,0.068858,0.000000
61.070004,38.164452,-418.921600,0.014724,0.002686,0.068233,169.763962,8.648189,0.682333,-418.921600,0.069257,0.000000
61.310001,39.309128,-418.966064,0.014720,0.002708,0.068780,174.855728,8.907576,0.687799,-418.966064,0.069656,0.000000
61.550003,39.928383,-418.921600,0.014745,0.002724,0.069179,177.610321,9.047901,0.691788,-418.921600,0.070055,0.000000
61.790005,39.898216,-418.966064,0.014745,0.002733,0.069430,177.476135,9.041065,0.694301,-418.966064,0.070462,0.000000
62.030003,40.419540,-418.966064,0.014758,0.002750,0.069838,179.795090,9.159199,0.698377,-418.966064,0.070861,0.000000
62.270004,41.454361,-418.921600,0.014771,0.002768,0.070297,184.398209,9.393692,0.702972,-418.921600,0.071260,0.000000
62.510002,42.009941,-419.010559,0.014784,0.002784,0.070714,186.869553,9.519588,0.707136,-419.010559,0.071659,0.000000
62.750004,42.796394,-418.966064,0.014793,0.002800,0.071121,190.367874,9.697802,0.711212,-418.966064,0.072058,0.000000
62.990002,43.411926,-419.055054,0.014810,0.002815,0.071511,193.105896,9.837283,0.715114,-419.055054,0.072457,0.000000
63.230003,44.490318,-418.921600,0.014797,0.002836,0.072023,197.902817,10.081651,0.720231,-418.921600,0.072856,0.000000
63.470001,44.963974,-419.055054,0.014814,0.002850,0.072379,200.009750,10.188982,0.723785,-419.055054,0.073255,0.000000
63.710003,45.234314,-419.010559,0.014832,0.002861,0.072674,201.212280,10.250242,0.726738,-419.010559,0.073662,0.000000
63.950005,45.654724,-418.966064,0.014840,0.002876,0.073055,203.082352,10.345509,0.730553,-418.966064,0.074061,0.000000
64.190002,46.567406,-419.010559,0.014845,0.002892,0.073463,207.142166,10.552324,0.734629,-419.010559,0.074460,0.000000
64.430000,47.700165,-419.055054,0.014862,0.002910,0.073914,212.180923,10.809012,0.739137,-419.055054,0.074859,0.000000
64.670006,48.344368,-419.055054,0.014857,0.002927,0.074339,215.046494,10.954990,0.743387,-419.055054,0.075258,0.000000
64.910004,49.019852,-419.010559,0.014888,0.002943,0.074746,218.051193,11.108057,0.747464,-419.010559,0.075657,0.000000
65.150002,49.860298,-418.966064,0.014883,0.002958,0.075145,221.789688,11.298505,0.751453,-418.966064,0.076056,0.000000
65.389999,50.574883,-419.055054,0.014896,0.002975,0.075553,224.968307,11.460432,0.755529,-419.055054,0.076455,0.000000
65.630005,51.207542,-419.010559,0.014909,0.002989,0.075917,227.782532,11.603795,0.759170,-419.010559,0.076862,0.000000
65.870003,52.175339,-419.010559,0.014905,0.003006,0.076342,232.087494,11.823101,0.763421,-419.010559,0.077261,0.000000
66.110001,52.818054,-419.055054,0.014935,0.003023,0.076784,234.946442,11.968742,0.767842,-419.055054,0.077660,0.000000
66.350006,53.513275,-419.055054,0.014948,0.003036,0.077105,238.038940,12.126282,0.771051,-419.055054,0.078059,0.000000
66.590004,54.374573,-419.055054,0.014957,0.003052,0.077521,241.870178,12.321455,0.775215,-419.055054,0.078458,0.000000
66.830002,55.260071,-419.055054,0.014961,0.003069,0.077947,245.809067,12.522111,0.779465,-419.055054,0.078857,0.000000
67.070000,56.011520,-419.055054,0.014961,0.003082,0.078276,249.151688,12.692392,0.782758,-419.055054,0.079256,0.000000
67.310005,56.983040,-419.055054,0.014991,0.003100,0.078753,253.473221,12.912541,0.787527,-419.055054,0.079655,0.000000
67.550003,57.752357,-419.099518,0.014987,0.003115,0.079108,256.895325,13.086871,0.791085,-419.099518,0.080062,0.000000
67.790001,57.967216,-419.099518,0.014987,0.003125,0.079368,257.851044,13.135559,0.793685,-419.099518,0.080461,0.000000
68.030006,59.823868,-419.055054,0.014995,0.003150,0.080002,266.109863,13.556282,0.800017,-419.055054,0.080860,0.000000
68.270004,60.514244,-419.144012,0.015008,0.003163,0.080331,269.180817,13.712724,0.803314,-419.144012,0.081259,0.000000
68.510002,61.442947,-419.188477,0.015034,0.003178,0.080730,273.311890,13.923171,0.807303,-419.188477,0.081658,0.000000
68.750000,62.119545,-419.055054,0.015021,0.003191,0.081051,276.321533,14.076489,0.810509,-419.055054,0.082057,0.000000
68.990005,63.291771,-419.144012,0.015039,0.003211,0.081554,281.535858,14.342120,0.815539,-419.144012,0.082456,0.000000
69.230003,64.461388,-419.099518,0.015039,0.003228,0.081988,286.738586,14.607160,0.819876,-419.099518,0.082855,0.000000
69.470001,65.035973,-419.099518,0.015052,0.003239,0.082282,289.294464,14.737362,0.822825,-419.099518,0.083262,0.000000
69.710007,65.528236,-419.188477,0.015069,0.003251,0.082569,291.484161,14.848910,0.825686,-419.188477,0.083661,0.000000
69.950005,66.931343,-419.099518,0.015069,0.003273,0.083132,297.725494,15.166859,0.831322,-419.099518,0.084060,0.000000
70.190002,67.091835,-419.188477,0.015073,0.003272,0.083115,298.439392,15.203227,0.831152,-419.188477,0.083297,0.000000
70.430000,66.356773,-419.144012,0.015086,0.003272,0.083106,295.169678,15.036660,0.831065,-419.144012,0.083106,0.000000
70.670006,65.701775,-419.188477,0.015090,0.003272,0.083098,292.256104,14.888235,0.830977,-419.188477,0.083106,0.000000
70.910004,65.108208,-419.188477,0.015095,0.003272,0.083098,289.615784,14.753730,0.830977,-419.188477,0.083106,0.000000
71.150002,64.568642,-419.144012,0.015108,0.003271,0.083089,287.215668,14.631463,0.830890,-419.144012,0.083106,0.000000
71.390007,64.070778,-419.232971,0.015099,0.003271,0.083089,285.001068,14.518645,0.830890,-419.232971,0.083106,0.000000
71.630005,63.626534,-419.144012,0.015108,0.003271,0.083089,283.024963,14.417979,0.830890,-419.144012,0.083106,0.000000
71.870003,63.206505,-419.188477,0.015108,0.003271,0.083089,281.156586,14.322799,0.830890,-419.188477,0.083106,0.000000
72.110001,62.811783,-419.232971,0.015120,0.003271,0.083089,279.400757,14.233353,0.830890,-419.232971,0.083106,0.000000
72.350006,62.452820,-419.188477,0.015120,0.003271,0.083089,277.804016,14.152011,0.830890,-419.188477,0.083106,0.000000
72.590004,62.121407,-419.277435,0.015095,0.003271,0.083089,276.329803,14.076912,0.830890,-419.277435,0.083106,0.000000
72.830002,61.824257,-419.188477,0.015125,0.003271,0.083089,275.008026,14.009577,0.830890,-419.188477,0.083106,0.000000
73.070000,61.534172,-419.321930,0.015125,0.003271,0.083089,273.717682,13.943843,0.830890,-419.321930,0.083106,0.000000
73.310005,61.256760,-419.277435,0.015120,0.003271,0.083089,272.483673,13.880980,0.830890,-419.277435,0.083106,0.000000
73.550003,61.011734,-419.188477,0.015112,0.003271,0.083089,271.393738,13.825457,0.830890,-419.188477,0.083106,0.000000
73.790001,60.755547,-419.277435,0.015133,0.003271,0.083089,270.254181,13.767404,0.830890,-419.277435,0.083106,0.000000
74.030006,60.528770,-419.232971,0.015125,0.003271,0.083089,269.245422,13.716015,0.830890,-419.232971,0.083106,0.000000
74.270004,60.310188,-419.277435,0.015138,0.003271,0.083089,268.273102,13.666484,0.830890,-419.277435,0.083106,0.000000
74.510002,60.111710,-419.277435,0.015138,0.003271,0.083089,267.390228,13.621508,0.830890,-419.277435,0.083106,0.000000
74.750000,59.917709,-419.277435,0.015125,0.003271,0.083089,266.527283,13.577546,0.830890,-419.277435,0.083106,0.000000
74.990005,59.738594,-419.277435,0.015133,0.003271,0.083089,265.730530,13.536959,0.830890,-419.277435,0.083106,0.000000
75.230003,59.562462,-419.277435,0.015133,0.003271,0.083089,264.947052,13.497046,0.830890,-419.277435,0.083106,0.000000
75.470001,59.388939,-419.277435,0.015120,0.003271,0.083089,264.175201,13.457726,0.830890,-419.277435,0.083106,0.000000
75.710007,59.226585,-419.321930,0.015142,0.003271,0.083089,263.453003,13.420936,0.830890,-419.321930,0.083106,0.000000
75.950005,59.069817,-419.232971,0.015133,0.003271,0.083089,262.755676,13.385412,0.830890,-419.232971,0.083106,0.000000
76.190002,58.918259,-419.366394,0.015146,0.003271,0.083089,262.081512,13.351068,0.830890,-419.366394,0.083106,0.000000
76.430000,58.781967,-419.277435,0.015129,0.003271,0.083089,261.475250,13.320185,0.830890,-419.277435,0.083106,0.000000
76.670006,58.651642,-419.321930,0.015142,0.003271,0.083089,260.895538,13.290652,0.830890,-419.321930,0.083106,0.000000
76.910004,58.505295,-419.321930,0.015142,0.003271,0.083089,260.244537,13.257489,0.830890,-419.321930,0.083106,0.000000
77.150002,58.382042,-419.321930,0.015146,0.003271,0.083089,259.696289,13.229560,0.830890,-419.321930,0.083106,0.000000
77.390007,58.271820,-419.410889,0.015151,0.003271,0.083089,259.205994,13.204583,0.830890,-419.410889,0.083106,0.000000
77.630005,58.157501,-419.321930,0.015159,0.003271,0.083089,258.697479,13.178679,0.830890,-419.321930,0.083106,0.000000
77.870003,58.036484,-419.366394,0.015138,0.003271,0.083089,258.159180,13.151256,0.830890,-419.366394,0.083106,0.000000
78.110001,57.937057,-419.366394,0.015146,0.003271,0.083089,257.716888,13.128724,0.830890,-419.366394,0.083106,0.000000
78.350006,57.822365,-419.321930,0.015151,0.003271,0.083089,257.206726,13.102735,0.830890,-419.321930,0.083106,0.000000
78.590004,57.722198,-419.366394,0.015159,0.003271,0.083089,256.761169,13.080037,0.830890,-419.366394,0.083106,0.000000
78.830002,57.633949,-419.321930,0.015155,0.003271,0.083089,256.368622,13.060040,0.830890,-419.321930,0.083106,0.000000
79.070007,57.534523,-419.366394,0.015155,0.003271,0.083089,255.926346,13.037509,0.830890,-419.366394,0.083106,0.000000
79.310005,57.436958,-419.366394,0.015151,0.003271,0.083089,255.492355,13.015401,0.830890,-419.366394,0.083106,0.000000
79.550003,57.353920,-419.321930,0.015151,0.003271,0.083089,255.122971,12.996584,0.830890,-419.321930,0.083106,0.000000
79.790001,57.257103,-419.366394,0.015151,0.003271,0.083089,254.692322,12.974645,0.830890,-419.366394,0.083106,0.000000
80.030006,57.181885,-419.366394,0.015164,0.003271,0.083089,254.357727,12.957600,0.830890,-419.366394,0.083106,0.000000
80.270004,57.096985,-419.410889,0.015142,0.003271,0.083089,253.980072,12.938362,0.830890,-419.410889,0.083106,0.000000
80.510002,57.009102,-419.410889,0.015172,0.003271,0.083089,253.589157,12.918447,0.830890,-419.410889,0.083106,0.000000
80.750008,56.942078,-419.366394,0.015159,0.003271,0.083089,253.291016,12.903259,0.830890,-419.366394,0.083106,0.000000
80.990005,56.848244,-419.366394,0.015159,0.003271,0.083089,252.873611,12.881996,0.830890,-419.366394,0.083106,0.000000
81.230003,56.784935,-419.410889,0.015151,0.003271,0.083089,252.592010,12.867650,0.830890,-419.410889,0.083106,0.000000
81.470001,56.698174,-419.410889,0.015168,0.003271,0.083089,252.206070,12.847990,0.830890,-419.410889,0.083106,0.000000
81.710007,56.637474,-419.410889,0.015172,0.003271,0.083089,251.936066,12.834235,0.830890,-419.410889,0.083106,0.000000
81.950005,56.564117,-419.410889,0.015159,0.003271,0.083089,251.609756,12.817612,0.830890,-419.410889,0.083106,0.000000
82.190002,56.490387,-419.410889,0.015168,0.003271,0.083089,251.281784,12.800905,0.830890,-419.410889,0.083106,0.000000
82.430000,56.432297,-419.455383,0.015155,0.003271,0.083089,251.023392,12.787741,0.830890,-419.455383,0.083106,0.000000
82.670006,56.368996,-419.455383,0.015155,0.003271,0.083089,250.741821,12.773397,0.830890,-419.455383,0.083106,0.000000
82.910004,56.298988,-419.455383,0.015159,0.003271,0.083089,250.430405,12.757533,0.830890,-419.455383,0.083106,0.000000
83.150002,56.258774,-419.499847,0.015159,0.003271,0.083089,250.251526,12.748421,0.830890,-419.499847,0.083106,0.000000
83.390007,56.179832,-419.455383,0.015168,0.003271,0.083089,249.900375,12.730532,0.830890,-419.455383,0.083106,0.000000
83.630005,56.126953,-419.455383,0.015151,0.003271,0.083089,249.665161,12.718549,0.830890,-419.455383,0.083106,0.000000
83.870003,56.069237,-419.544342,0.015164,0.003271,0.083089,249.408417,12.705471,0.830890,-419.544342,0.083106,0.000000
84.110001,55.998116,-419.499847,0.015164,0.003271,0.083089,249.092056,12.689355,0.830890,-419.499847,0.083106,0.000000
84.350006,55.952309,-419.455383,0.015155,0.003271,0.083089,248.888306,12.678974,0.830890,-419.455383,0.083106,0.000000
84.590004,55.891991,-419.499847,0.015164,0.003271,0.083089,248.619995,12.665306,0.830890,-419.499847,0.083106,0.000000
84.830002,55.830177,-419.455383,0.015155,0.003271,0.083089,248.345032,12.651299,0.830890,-419.455383,0.083106,0.000000
85.070007,55.782509,-419.544342,0.015168,0.003271,0.083089,248.132996,12.640497,0.830890,-419.544342,0.083106,0.000000
85.310005,55.738945,-419.544342,0.015146,0.003271,0.083089,247.939209,12.630626,0.830890,-419.544342,0.083106,0.000000
85.550003,55.686066,-419.499847,0.015164,0.003271,0.083089,247.703995,12.618643,0.830890,-419.499847,0.083106,0.000000
85.790001,55.632072,-419.544342,0.015159,0.003271,0.083089,247.463821,12.606408,0.830890,-419.544342,0.083106,0.000000
86.030006,55.586639,-419.499847,0.015164,0.003271,0.083089,247.261719,12.596112,0.830890,-419.499847,0.083106,0.000000
86.270004,55.538605,-419.499847,0.015159,0.003271,0.083089,247.048050,12.585228,0.830890,-419.499847,0.083106,0.000000
86.510002,55.493919,-419.544342,0.015181,0.003271,0.083089,246.849289,12.575102,0.830890,-419.544342,0.083106,0.000000
86.750008,55.444771,-419.499847,0.015168,0.003271,0.083089,246.630661,12.563965,0.830890,-419.499847,0.083106,0.000000
86.990005,55.402321,-419.588806,0.015164,0.003271,0.083089,246.441833,12.554345,0.830890,-419.588806,0.083106,0.000000
87.230003,55.358749,-419.588806,0.015177,0.003271,0.083089,246.248016,12.544473,0.830890,-419.588806,0.083106,0.000000
87.470001,55.313324,-419.544342,0.015172,0.003271,0.083089,246.045959,12.534178,0.830890,-419.544342,0.083106,0.000000
87.710007,55.279434,-419.544342,0.015172,0.003271,0.083089,245.895203,12.526499,0.830890,-419.544342,0.083106,0.000000
87.950005,55.219482,-419.544342,0.015164,0.003271,0.083089,245.628525,12.512914,0.830890,-419.544342,0.083106,0.000000
88.190002,55.193047,-419.588806,0.015164,0.003271,0.083089,245.510925,12.506923,0.830890,-419.588806,0.083106,0.000000
88.430008,55.141655,-419.544342,0.015168,0.003271,0.083089,245.282333,12.495277,0.830890,-419.544342,0.083106,0.000000
88.670006,55.105537,-419.588806,0.015168,0.003271,0.083089,245.121674,12.487093,0.830890,-419.588806,0.083106,0.000000
88.910004,55.046700,-419.633301,0.015172,0.003271,0.083089,244.859955,12.473761,0.830890,-419.633301,0.083106,0.000000
89.150002,55.030319,-419.588806,0.015168,0.003271,0.083089,244.787079,12.470048,0.830890,-419.588806,0.083106,0.000000
89.390007,54.977440,-419.588806,0.015181,0.003271,0.083089,244.551865,12.458066,0.830890,-419.588806,0.083106,0.000000
89.630005,54.936111,-419.588806,0.015155,0.003271,0.083089,244.368027,12.448700,0.830890,-419.588806,0.083106,0.000000
89.870003,54.909294,-419.633301,0.015164,0.003271,0.083089,244.248734,12.442623,0.830890,-419.633301,0.083106,0.000000
90.110001,54.853065,-419.633301,0.015155,0.003271,0.083089,243.998627,12.429882,0.830890,-419.633301,0.083106,0.000000
90.350006,54.829979,-419.544342,0.015164,0.003271,0.083089,243.895920,12.424651,0.830890,-419.544342,0.083106,0.000000
90.590004,54.792747,-419.633301,0.015168,0.003271,0.083089,243.730316,12.416214,0.830890,-419.633301,0.083106,0.000000
90.830002,54.744705,-419.544342,0.015177,0.003271,0.083089,243.516617,12.405328,0.830890,-419.544342,0.083106,0.000000
91.070007,54.714920,-419.633301,0.015164,0.003271,0.083089,243.384125,12.398578,0.830890,-419.633301,0.083106,0.000000
91.310005,54.673210,-419.633301,0.015168,0.003271,0.083089,243.198578,12.389126,0.830890,-419.633301,0.083106,0.000000
91.550003,54.639328,-419.633301,0.015164,0.003271,0.083089,243.047867,12.381449,0.830890,-419.633301,0.083106,0.000000
91.790001,54.593529,-419.677765,0.015177,0.003271,0.083089,242.844147,12.371070,0.830890,-419.677765,0.083106,0.000000
92.030006,54.552933,-419.633301,0.015164,0.003271,0.083089,242.663559,12.361871,0.830890,-419.633301,0.083106,0.000000
92.270004,54.518677,-419.722260,0.015159,0.003271,0.083089,242.511185,12.354109,0.830890,-419.722260,0.083106,0.000000
92.510002,54.475479,-419.722260,0.015164,0.003271,0.083089,242.319031,12.344319,0.830890,-419.722260,0.083106,0.000000
92.750008,54.453514,-419.633301,0.015164,0.003271,0.083089,242.221329,12.339343,0.830890,-419.633301,0.083106,0.000000
92.990005,54.409203,-419.766724,0.015172,0.003271,0.083089,242.024216,12.329301,0.830890,-419.766724,0.083106,0.000000
93.230003,54.379410,-419.677765,0.015177,0.003271,0.083089,241.891693,12.322551,0.830890,-419.677765,0.083106,0.000000
93.470001,54.336212,-419.722260,0.015181,0.003271,0.083089,241.699539,12.312761,0.830890,-419.722260,0.083106,0.000000
93.710007,54.312759,-419.677765,0.015172,0.003271,0.083089,241.595215,12.307447,0.830890,-419.677765,0.083106,0.000000
93.950005,54.268074,-419.722260,0.015164,0.003271,0.083089,241.396454,12.297321,0.830890,-419.722260,0.083106,0.000000
94.190002,54.249825,-419.722260,0.015168,0.003271,0.083089,241.315277,12.293185,0.830890,-419.722260,0.083106,0.000000
94.430008,54.206627,-419.722260,0.015177,0.003271,0.083089,241.123123,12.283397,0.830890,-419.722260,0.083106,0.000000
94.670006,54.192856,-419.722260,0.015181,0.003271,0.083089,241.061859,12.280277,0.830890,-419.722260,0.083106,0.000000
94.910004,54.139229,-419.766724,0.015177,0.003271,0.083089,240.823318,12.268125,0.830890,-419.766724,0.083106,0.000000
95.150002,54.144447,-419.722260,0.015185,0.003271,0.083089,240.846527,12.269307,0.830890,-419.722260,0.083106,0.000000
95.390007,54.096405,-419.722260,0.015172,0.003271,0.083089,240.632828,12.258421,0.830890,-419.722260,0.083106,0.000000
95.630005,54.063637,-419.722260,0.015194,0.003271,0.083089,240.487061,12.250996,0.830890,-419.722260,0.083106,0.000000
95.870003,54.031990,-419.811218,0.015185,0.003271,0.083089,240.346298,12.243824,0.830890,-419.811218,0.083106,0.000000
96.110008,54.008530,-419.766724,0.015202,0.003271,0.083089,240.241943,12.238508,0.830890,-419.766724,0.083106,0.000000
96.350006,53.978363,-419.722260,0.015185,0.003271,0.083089,240.107758,12.231672,0.830890,-419.722260,0.083106,0.000000
96.590004,53.957138,-419.811218,0.015181,0.003271,0.083089,240.013336,12.226862,0.830890,-419.811218,0.083106,0.000000
96.830002,53.909851,-419.766724,0.015177,0.003271,0.083089,239.802994,12.216147,0.830890,-419.766724,0.083106,0.000000
97.070007,53.893837,-419.811218,0.015181,0.003271,0.083089,239.731766,12.212519,0.830890,-419.811218,0.083106,0.000000
97.310005,53.864044,-419.811218,0.015189,0.003271,0.083089,239.599228,12.205767,0.830890,-419.811218,0.083106,0.000000
97.550003,53.842079,-419.811218,0.015181,0.003271,0.083089,239.501526,12.200790,0.830890,-419.811218,0.083106,0.000000
97.790001,53.805954,-419.811218,0.015185,0.003271,0.083089,239.340836,12.192603,0.830890,-419.811218,0.083106,0.000000
98.030006,53.796646,-419.766724,0.015177,0.003271,0.083089,239.299438,12.190495,0.830890,-419.766724,0.083106,0.000000
98.270004,53.762016,-419.855682,0.015177,0.003271,0.083089,239.145386,12.182647,0.830890,-419.855682,0.083106,0.000000
98.510002,53.730736,-419.766724,0.015185,0.003271,0.083089,239.006256,12.175558,0.830890,-419.766724,0.083106,0.000000
98.750008,53.709511,-419.811218,0.015185,0.003271,0.083089,238.911835,12.170750,0.830890,-419.811218,0.083106,0.000000
98.990005,53.683449,-419.855682,0.015181,0.003271,0.083089,238.795914,12.164843,0.830890,-419.855682,0.083106,0.000000
99.230003,53.643974,-419.811218,0.015194,0.003271,0.083089,238.620316,12.155898,0.830890,-419.811218,0.083106,0.000000
99.470001,53.624611,-419.811218,0.015189,0.003271,0.083089,238.534180,12.151510,0.830890,-419.811218,0.083106,0.000000
99.710007,53.598175,-419.855682,0.015185,0.003271,0.083089,238.416595,12.145519,0.830890,-419.855682,0.083106,0.000000
99.950005,53.568382,-419.855682,0.015181,0.003271,0.083089,238.284058,12.138769,0.830890,-419.855682,0.083106,0.000000
100.190002,53.550140,-419.900177,0.015177,0.003271,0.083089,238.202927,12.134636,0.830890,-419.900177,0.083106,0.000000
100.430008,53.505081,-419.811218,0.015189,0.003271,0.083089,238.002487,12.124425,0.830890,-419.811218,0.083106,0.000000
100.500008,53.520348,-419.811218,0.015177,0.003271,0.083089,238.070389,12.127884,0.830890,-419.811218,0.083106,0.000000