File: Data/compression 5/AutoNoheating-10-5-2-240223_02232024_193342.csv
Time (sec),S:Load (lbs),S:HL1 (DIM),S:LVDT (in),S:Position (in),Ch:Position (mm),Ch:Load (N),Ch:Stress (MPa),Ch:Strain (mm/mm),Ch:HL1 (DIM),Set Point (),Cycles ()
0.110000,-0.000374,-391.298920,0.000009,-0.000000,-0.000000,-0.001663,-0.000085,-0.000000,-391.298920,0.000208,0.000000
0.420000,-0.018990,-391.343414,0.000000,0.000010,0.000252,-0.084470,-0.004303,0.002515,-391.343414,0.000832,0.000000
0.730000,0.032394,-391.298920,0.000034,0.000199,0.005056,0.144098,0.007341,0.050559,-391.298920,0.006001,0.000000
1.040000,0.027557,-391.343414,0.000246,0.000400,0.010172,0.122581,0.006245,0.101725,-391.343414,0.011152,0.000000
1.350000,-0.004097,-391.387878,0.000418,0.000602,0.015298,-0.018224,-0.000928,0.152978,-391.387878,0.016321,0.000000
1.660000,0.040962,-391.343414,0.000629,0.000802,0.020362,0.182209,0.009282,0.203624,-391.343414,0.021490,0.000000
1.970000,0.008194,-391.387878,0.000815,0.001011,0.025678,0.036449,0.001857,0.256784,-391.387878,0.026659,0.000000
2.280000,0.015266,-391.432373,0.001056,0.001218,0.030934,0.067908,0.003459,0.309339,-391.432373,0.031810,0.000000
2.590000,0.016388,-391.432373,0.001242,0.001411,0.035834,0.072897,0.003714,0.358337,-391.432373,0.036979,0.000000
2.900000,0.008194,-391.387878,0.001444,0.001616,0.041055,0.036449,0.001857,0.410546,-391.387878,0.042147,0.000000
3.210000,0.052132,-391.387878,0.001660,0.001815,0.046110,0.231893,0.011813,0.461104,-391.387878,0.047316,0.000000
3.520000,0.016014,-391.432373,0.001871,0.002024,0.051418,0.071234,0.003629,0.514176,-391.432373,0.052467,0.000000
3.830000,0.030159,-391.387878,0.002078,0.002232,0.056699,0.134154,0.006834,0.566990,-391.387878,0.057636,0.000000
4.140000,0.032394,-391.432373,0.002259,0.002428,0.061668,0.144098,0.007341,0.616682,-391.432373,0.062804,0.000000
4.450000,-0.040588,-391.476837,0.002488,0.002631,0.066828,-0.180546,-0.009197,0.668282,-391.476837,0.067973,0.000000
4.760000,0.033516,-391.432373,0.002690,0.002834,0.071980,0.149086,0.007595,0.719798,-391.432373,0.073124,0.000000
5.070000,0.010796,-391.432373,0.002880,0.003041,0.077235,0.048021,0.002446,0.772351,-391.432373,0.078293,0.000000
5.380000,0.053253,-391.476837,0.003104,0.003247,0.082473,0.236882,0.012067,0.824731,-391.476837,0.083462,0.000000
5.690000,0.039101,-391.432373,0.003298,0.003447,0.087546,0.173928,0.008860,0.875463,-391.432373,0.088630,0.000000
6.000000,0.020851,-391.476837,0.003488,0.003652,0.092758,0.092750,0.004725,0.927585,-391.476837,0.093799,0.000000
6.310000,0.060326,-391.476837,0.003678,0.003847,0.097719,0.268342,0.013670,0.977190,-391.476837,0.098950,0.000000
6.620000,0.001488,-391.432373,0.003867,0.004049,0.102853,0.006618,0.000337,1.028528,-391.432373,0.104119,0.000000
6.930000,0.035004,-391.476837,0.004109,0.004269,0.108438,0.155704,0.007932,1.084378,-391.476837,0.109288,0.000000
7.240000,0.041336,-391.476837,0.004307,0.004465,0.113416,0.183872,0.009367,1.134157,-391.476837,0.114457,0.000000
7.550000,0.021973,-391.432373,0.004514,0.004668,0.118576,0.097739,0.004979,1.185756,-391.432373,0.119608,0.000000
7.860001,0.056976,-391.476837,0.004712,0.004866,0.123597,0.253443,0.012911,1.235971,-391.476837,0.124776,0.000000
8.170000,0.039474,-391.610291,0.004907,0.005074,0.128879,0.175591,0.008945,1.288785,-391.610291,0.129945,0.000000
8.480000,0.040215,-391.521332,0.005109,0.005283,0.134177,0.178883,0.009113,1.341770,-391.521332,0.135114,0.000000
8.790000,0.038727,-391.521332,0.005307,0.005475,0.139077,0.172265,0.008776,1.390769,-391.521332,0.140265,0.000000
9.100000,-0.007820,-391.521332,0.005523,0.005686,0.144419,-0.034786,-0.001772,1.444189,-391.521332,0.145434,0.000000
9.410001,0.080803,-391.476837,0.005726,0.005882,0.149397,0.359429,0.018310,1.493968,-391.476837,0.150602,0.000000
9.720000,0.052505,-391.521332,0.005946,0.006091,0.154704,0.233556,0.011898,1.547044,-391.521332,0.155771,0.000000
10.030001,0.089371,-391.565826,0.006153,0.006295,0.159899,0.397541,0.020252,1.598991,-391.565826,0.160922,0.000000
10.340000,0.133308,-391.565826,0.006372,0.006495,0.164981,0.592985,0.030208,1.649811,-391.565826,0.166091,0.000000
10.650001,0.248001,-391.565826,0.006566,0.006701,0.170193,1.103164,0.056198,1.701929,-391.565826,0.171259,0.000000
10.960001,0.685913,-391.521332,0.006760,0.006885,0.174885,3.051094,0.155430,1.748847,-391.521332,0.176168,0.000000
11.270000,0.565636,-391.610291,0.006756,-0.000001,-0.000026,2.516073,0.128175,-0.000257,-391.610291,0.000191,0.000000
11.580001,0.544411,-391.610291,0.006765,-0.000001,-0.000017,2.421660,0.123365,-0.000170,-391.610291,0.000347,0.000000
11.890000,0.508286,-391.610291,0.006769,-0.000001,-0.000017,2.260967,0.115179,-0.000170,-391.610291,0.000867,0.000000
12.200001,0.549622,-391.610291,0.006760,0.000012,0.000295,2.444839,0.124546,0.002948,-391.610291,0.001379,0.000000
12.510000,0.692986,-391.565826,0.006778,0.000046,0.001162,3.082554,0.157033,0.011623,-391.565826,0.001899,0.000000
12.820001,0.687401,-391.610291,0.006795,0.000062,0.001570,3.057712,0.155767,0.015700,-391.610291,0.002420,0.000000
13.130001,0.760010,-391.565826,0.006808,0.000080,0.002029,3.380692,0.172221,0.020295,-391.565826,0.002931,0.000000
13.440001,0.849380,-391.610291,0.006842,0.000101,0.002559,3.778233,0.192472,0.025586,-391.610291,0.003452,0.000000
13.750001,0.905609,-391.654785,0.006847,0.000118,0.003009,4.028351,0.205214,0.030094,-391.654785,0.003964,0.000000
14.060000,0.954391,-391.654785,0.006873,0.000135,0.003434,4.245345,0.216268,0.034344,-391.654785,0.004484,0.000000
14.370001,1.074295,-391.654785,0.006898,0.000169,0.004302,4.778703,0.243439,0.043015,-391.654785,0.004995,0.000000
14.680000,1.073181,-391.654785,0.006907,0.000185,0.004692,4.773748,0.243186,0.046918,-391.654785,0.005516,0.000000
14.990001,1.106689,-391.654785,0.006929,0.000204,0.005186,4.922801,0.250779,0.051861,-391.654785,0.006036,0.000000
15.300001,1.209839,-391.654785,0.006942,0.000222,0.005629,5.381632,0.274153,0.056285,-391.654785,0.006548,0.000000
15.610001,1.312241,-391.699249,0.006963,0.000247,0.006270,5.837138,0.297358,0.062701,-391.699249,0.007068,0.000000
15.920001,1.385971,-391.654785,0.006993,0.000263,0.006678,6.165107,0.314066,0.066777,-391.654785,0.007580,0.000000
16.230001,1.453369,-391.699249,0.006993,0.000285,0.007242,6.464909,0.329338,0.072416,-391.699249,0.008100,0.000000
16.540001,1.492470,-391.699249,0.007028,0.000302,0.007666,6.638837,0.338198,0.076663,-391.699249,0.008620,0.000000
16.850000,1.573273,-391.699249,0.007036,0.000323,0.008204,6.998267,0.356509,0.082041,-391.699249,0.009132,0.000000
17.160002,1.617584,-391.654785,0.007067,0.000343,0.008725,7.195374,0.366550,0.087246,-391.654785,0.009652,0.000000
17.470001,1.710678,-391.743744,0.007101,0.000368,0.009340,7.609476,0.387645,0.093400,-391.743744,0.010164,0.000000
17.780001,1.763557,-391.788208,0.007097,0.000383,0.009739,7.844695,0.399628,0.097389,-391.788208,0.010684,0.000000
18.090000,1.893517,-391.699249,0.007148,0.000407,0.010329,8.422782,0.429077,0.103290,-391.699249,0.011196,0.000000
18.400002,1.939690,-391.699249,0.007153,0.000429,0.010893,8.628170,0.439540,0.108925,-391.699249,0.011717,0.000000
18.710001,1.985115,-391.743744,0.007174,0.000449,0.011396,8.830233,0.449834,0.113956,-391.743744,0.012237,0.000000
19.020000,2.021614,-391.788208,0.007196,0.000465,0.011803,8.992589,0.458104,0.118032,-391.788208,0.012748,0.000000
19.330002,2.132576,-391.743744,0.007226,0.000489,0.012419,9.486172,0.483249,0.124190,-391.743744,0.013269,0.000000
19.640001,2.199234,-391.788208,0.007248,0.000507,0.012878,9.782681,0.498354,0.128785,-391.788208,0.013780,0.000000
19.950001,2.264397,-391.743744,0.007256,0.000528,0.013399,10.072539,0.513120,0.133989,-391.743744,0.014301,0.000000
20.260000,2.396965,-391.743744,0.007278,0.000551,0.013997,10.662233,0.543160,0.139973,-391.743744,0.014812,0.000000
20.570002,2.427498,-391.788208,0.007312,0.000572,0.014535,10.798050,0.550079,0.145348,-391.788208,0.015333,0.000000
20.880001,2.455795,-391.832703,0.007312,0.000589,0.014960,10.923923,0.556491,0.149598,-391.832703,0.015853,0.000000
21.190001,2.570114,-391.699249,0.007343,0.000613,0.015576,11.432439,0.582396,0.155756,-391.699249,0.016365,0.000000
21.500002,2.638260,-391.832703,0.007381,0.000632,0.016044,11.735566,0.597838,0.160438,-391.832703,0.016885,0.000000
21.810001,2.693741,-391.788208,0.007373,0.000650,0.016512,11.982358,0.610410,0.165120,-391.788208,0.017397,0.000000
22.120001,2.817741,-391.832703,0.007420,0.000673,0.017093,12.533939,0.638509,0.170933,-391.832703,0.017917,0.000000
22.430000,2.859451,-391.877167,0.007416,0.000691,0.017562,12.719475,0.647961,0.175615,-391.877167,0.018437,0.000000
22.740002,2.900406,-391.788208,0.007450,0.000713,0.018108,12.901649,0.657241,0.181077,-391.788208,0.018949,0.000000
23.050001,2.997223,-391.832703,0.007463,0.000731,0.018576,13.332314,0.679180,0.185763,-391.832703,0.019469,0.000000
23.360001,3.068352,-391.788208,0.007485,0.000753,0.019122,13.648710,0.695298,0.191224,-391.788208,0.019981,0.000000
23.670002,3.075798,-391.832703,0.007524,0.000767,0.019469,13.681833,0.696986,0.194695,-391.832703,0.020501,0.000000
23.980001,3.263100,-391.877167,0.007541,0.000791,0.020102,14.514993,0.739429,0.201023,-391.877167,0.021013,0.000000
24.290001,3.301079,-391.832703,0.007567,0.000812,0.020631,14.683932,0.748035,0.206315,-391.832703,0.021533,0.000000
24.600000,3.363266,-391.921661,0.007575,0.000833,0.021152,14.960554,0.762127,0.211519,-391.921661,0.022054,0.000000
24.910002,3.491364,-391.832703,0.007606,0.000855,0.021715,15.530360,0.791154,0.217155,-391.832703,0.022566,0.000000
25.220001,3.527115,-391.921661,0.007636,0.000877,0.022270,15.689390,0.799256,0.222703,-391.921661,0.023086,0.000000
25.530001,3.595253,-391.921661,0.007644,0.000895,0.022739,15.992484,0.814696,0.227389,-391.921661,0.023597,0.000000
25.840002,3.690208,-391.832703,0.007675,0.000916,0.023259,16.414867,0.836213,0.232593,-391.832703,0.024118,0.000000
26.150002,3.771385,-391.921661,0.007687,0.000938,0.023814,16.775959,0.854608,0.238142,-391.921661,0.024638,0.000000
26.460001,3.796707,-391.877167,0.007713,0.000957,0.024300,16.888597,0.860346,0.242998,-391.877167,0.025150,0.000000
26.770000,3.821655,-391.966125,0.007713,0.000974,0.024751,16.999571,0.865999,0.247509,-391.966125,0.025670,0.000000
27.080002,3.957199,-391.966125,0.007739,0.000995,0.025280,17.602501,0.896714,0.252797,-391.966125,0.026182,0.000000
27.390001,3.950500,-391.877167,0.007778,0.001010,0.025661,17.572704,0.895196,0.256612,-391.877167,0.026702,0.000000
27.700001,4.055511,-392.010620,0.007769,0.001029,0.026147,18.039816,0.918992,0.261468,-392.010620,0.027214,0.000000
28.010002,4.275955,-391.966125,0.007812,0.001061,0.026962,19.020399,0.968945,0.269621,-391.966125,0.027734,0.000000
28.320002,4.248398,-391.966125,0.007825,0.001080,0.027422,18.897818,0.962701,0.274219,-391.966125,0.028254,0.000000
28.630001,4.293457,-392.010620,0.007847,0.001097,0.027864,19.098251,0.972911,0.278640,-392.010620,0.028766,0.000000
28.940001,4.377983,-391.966125,0.007856,0.001117,0.028376,19.474241,0.992065,0.283757,-391.966125,0.029286,0.000000
29.250002,4.518738,-392.010620,0.007894,0.001137,0.028887,20.100349,1.023961,0.288875,-392.010620,0.029798,0.000000
29.560001,4.571243,-392.010620,0.007903,0.001154,0.029304,20.333906,1.035859,0.293038,-392.010620,0.030319,0.000000
29.870001,4.823715,-392.055115,0.007950,0.001184,0.030067,21.456957,1.093070,0.300668,-392.055115,0.030830,0.000000
30.180002,4.778656,-392.055115,0.007981,0.001203,0.030561,21.256523,1.082859,0.305611,-392.055115,0.031350,0.000000
30.490002,4.709396,-392.010620,0.007968,0.001218,0.030943,20.948441,1.067165,0.309427,-392.010620,0.031871,0.000000
30.800001,4.840469,-392.055115,0.007989,0.001237,0.031420,21.531483,1.096866,0.314195,-392.055115,0.032382,0.000000
31.110001,4.938034,-392.055115,0.008006,0.001257,0.031923,21.965473,1.118975,0.319226,-392.055115,0.032903,0.000000
31.420002,4.906006,-392.010620,0.008032,0.001270,0.032252,21.823004,1.111717,0.322522,-392.010620,0.033414,0.000000
31.730001,5.206512,-392.055115,0.008050,0.001301,0.033041,23.159723,1.179813,0.330414,-392.055115,0.033935,0.000000
32.040001,5.296257,-392.055115,0.008093,0.001326,0.033675,23.558928,1.200149,0.336746,-392.055115,0.034455,0.000000
32.350002,5.207260,-392.010620,0.008097,0.001341,0.034056,23.163050,1.179982,0.340561,-392.010620,0.034967,0.000000
32.660000,5.146561,-392.055115,0.008119,0.001356,0.034455,22.893045,1.166227,0.344550,-392.055115,0.035487,0.000000
32.970001,5.376686,-392.099579,0.008149,0.001378,0.035001,23.916695,1.218374,0.350012,-392.099579,0.035999,0.000000
33.280003,5.465683,-392.099579,0.008162,0.001396,0.035470,24.312572,1.238541,0.354698,-392.099579,0.036519,0.000000
33.590000,5.762466,-392.010620,0.008179,0.001425,0.036198,25.632730,1.305794,0.361980,-392.010620,0.037031,0.000000
33.900002,5.807152,-392.188538,0.008218,0.001449,0.036805,25.831501,1.315919,0.368051,-392.188538,0.037551,0.000000
34.210003,5.712936,-392.144073,0.008222,0.001465,0.037213,25.412411,1.294570,0.372127,-392.144073,0.038072,0.000000
34.520000,5.812363,-392.144073,0.008261,0.001486,0.037733,25.854681,1.317100,0.377331,-392.144073,0.038583,0.000000
34.830002,5.943436,-392.099579,0.008265,0.001505,0.038236,26.437723,1.346802,0.382361,-392.099579,0.039103,0.000000
35.140003,5.905083,-392.099579,0.008287,0.001519,0.038592,26.267120,1.338111,0.385915,-392.099579,0.039615,0.000000
35.450001,6.106163,-392.188538,0.008291,0.001545,0.039242,27.161570,1.383676,0.392422,-392.188538,0.040135,0.000000
35.760002,6.356773,-392.099579,0.008343,0.001573,0.039945,28.276340,1.440465,0.399446,-392.099579,0.040656,0.000000
36.070004,6.150475,-392.144073,0.008347,0.001588,0.040326,27.358677,1.393717,0.403262,-392.144073,0.041167,0.000000
36.380001,6.191811,-392.144073,0.008373,0.001603,0.040725,27.542549,1.403084,0.407251,-392.144073,0.041688,0.000000
36.690002,6.385445,-392.188538,0.008399,0.001627,0.041315,28.403877,1.446962,0.413148,-392.188538,0.042199,0.000000
37.000000,6.526199,-392.233032,0.008420,0.001648,0.041853,29.029985,1.478858,0.418526,-392.233032,0.042720,0.000000
37.310001,6.529182,-392.144073,0.008433,0.001663,0.042243,29.043255,1.479534,0.422428,-392.144073,0.043231,0.000000
37.620003,6.742546,-392.144073,0.008451,0.001689,0.042902,29.992342,1.527883,0.429018,-392.144073,0.043751,0.000000
37.930000,6.723183,-392.188538,0.008476,0.001706,0.043336,29.906210,1.523495,0.433355,-392.188538,0.044272,0.000000
38.240002,6.806221,-392.188538,0.008494,0.001728,0.043882,30.275583,1.542312,0.438817,-392.188538,0.044784,0.000000
38.550003,6.990921,-392.188538,0.008511,0.001752,0.044506,31.097170,1.584165,0.445062,-392.188538,0.045304,0.000000
38.860001,6.964485,-392.188538,0.008524,0.001770,0.044948,30.979578,1.578175,0.449483,-392.188538,0.045816,0.000000
39.170002,6.994270,-392.188538,0.008558,0.001786,0.045373,31.112068,1.584924,0.453733,-392.188538,0.046336,0.000000
39.480003,7.199448,-392.188538,0.008571,0.001811,0.045998,32.024742,1.631418,0.459978,-392.188538,0.046856,0.000000
39.790001,7.313393,-392.188538,0.008601,0.001832,0.046536,32.531593,1.657238,0.465357,-392.188538,0.047368,0.000000
40.100002,7.289566,-392.233032,0.008610,0.001852,0.047030,32.425610,1.651839,0.470300,-392.233032,0.047888,0.000000
40.410004,7.367760,-392.188538,0.008632,0.001869,0.047472,32.773434,1.669558,0.474720,-392.188538,0.048400,0.000000
40.720001,7.524155,-392.277496,0.008670,0.001893,0.048079,33.469112,1.704998,0.480791,-392.277496,0.048921,0.000000
41.030003,7.567726,-392.233032,0.008666,0.001910,0.048522,33.662926,1.714871,0.485216,-392.233032,0.049432,0.000000
41.340000,7.701408,-392.188538,0.008683,0.001931,0.049050,34.257576,1.745164,0.490503,-392.188538,0.049952,0.000000
41.650002,7.842537,-392.321991,0.008709,0.001955,0.049657,34.885345,1.777144,0.496574,-392.321991,0.050473,0.000000
41.960003,7.765457,-392.233032,0.008744,0.001974,0.050152,34.542480,1.759678,0.501518,-392.233032,0.050984,0.000000
42.270000,7.810883,-392.321991,0.008761,0.001994,0.050655,34.744541,1.769971,0.506548,-392.321991,0.051505,0.000000
42.580002,8.004143,-392.233032,0.008770,0.002015,0.051193,35.604206,1.813765,0.511926,-392.233032,0.052016,0.000000
42.890003,8.004143,-392.321991,0.008804,0.002034,0.051652,35.604206,1.813765,0.516521,-392.321991,0.052537,0.000000
43.200001,8.205971,-392.321991,0.008804,0.002057,0.052242,36.501980,1.859500,0.522418,-392.321991,0.053048,0.000000
43.510002,8.286774,-392.321991,0.008839,0.002079,0.052797,36.861412,1.877810,0.527970,-392.321991,0.053569,0.000000
43.820004,8.263321,-392.366455,0.008869,0.002098,0.053300,36.757088,1.872495,0.532996,-392.366455,0.054089,0.000000
44.130001,8.251778,-392.366455,0.008869,0.002116,0.053751,36.705742,1.869879,0.537508,-392.366455,0.054601,0.000000
44.440002,8.222733,-392.277496,0.008903,0.002133,0.054176,36.576542,1.863298,0.541759,-392.277496,0.055121,0.000000
44.750004,8.497169,-392.366455,0.008921,0.002155,0.054739,37.797298,1.925486,0.547394,-392.366455,0.055633,0.000000
45.060001,8.437218,-392.321991,0.008938,0.002173,0.055182,37.530621,1.911901,0.551819,-392.321991,0.056153,0.000000
45.370003,8.671814,-392.366455,0.008959,0.002196,0.055789,38.574154,1.965061,0.557886,-392.366455,0.056674,0.000000
45.680000,8.714630,-392.366455,0.008972,0.002218,0.056335,38.764610,1.974763,0.563351,-392.366455,0.057185,0.000000
45.990002,8.828949,-392.321991,0.009011,0.002237,0.056829,39.273125,2.000668,0.568294,-392.321991,0.057705,0.000000
46.300003,8.945129,-392.366455,0.009015,0.002260,0.057410,39.789925,2.026995,0.574104,-392.366455,0.058217,0.000000
46.610001,8.949974,-392.366455,0.009050,0.002280,0.057905,39.811474,2.028093,0.579047,-392.366455,0.058737,0.000000
46.920002,8.863213,-392.499908,0.009084,0.002294,0.058278,39.425537,2.008433,0.582775,-392.499908,0.059249,0.000000
47.230003,9.222176,-392.410950,0.009089,0.002322,0.058971,41.022285,2.089775,0.589713,-392.410950,0.059769,0.000000
47.540001,9.080299,-392.410950,0.009119,0.002338,0.059379,40.391190,2.057625,0.593789,-392.410950,0.060290,0.000000
47.850002,9.177490,-392.410950,0.009127,0.002360,0.059943,40.823517,2.079649,0.599429,-392.410950,0.060801,0.000000
48.160004,9.149193,-392.366455,0.009140,0.002379,0.060428,40.697643,2.073237,0.604285,-392.366455,0.061322,0.000000
48.470001,9.331284,-392.455444,0.009166,0.002399,0.060932,41.507622,2.114499,0.609315,-392.455444,0.061833,0.000000
48.780003,9.301865,-392.455444,0.009184,0.002415,0.061330,41.376759,2.107833,0.613304,-392.455444,0.062353,0.000000
49.090004,9.755417,-392.410950,0.009205,0.002444,0.062076,43.394260,2.210609,0.620761,-392.410950,0.062874,0.000000
49.400002,9.685410,-392.544403,0.009218,0.002463,0.062562,43.082855,2.194745,0.625617,-392.544403,0.063386,0.000000
49.710003,9.634392,-392.455444,0.009265,0.002483,0.063056,42.855915,2.183184,0.630560,-392.455444,0.063906,0.000000
50.020004,9.677589,-392.499908,0.009274,0.002501,0.063533,43.048069,2.192973,0.635332,-392.499908,0.064418,0.000000
50.330002,9.855583,-392.455444,0.009291,0.002522,0.064071,43.839825,2.233307,0.640707,-392.455444,0.064938,0.000000
50.640003,9.764725,-392.455444,0.009309,0.002537,0.064444,43.435665,2.212718,0.644435,-392.455444,0.065450,0.000000
50.950001,9.814995,-392.455444,0.009334,0.002555,0.064903,43.659279,2.224110,0.649034,-392.455444,0.065970,0.000000
51.260002,10.298332,-392.499908,0.009360,0.002588,0.065736,45.809269,2.333635,0.657357,-392.499908,0.066490,0.000000
51.570004,10.075279,-392.455444,0.009403,0.002606,0.066196,44.817081,2.283091,0.661955,-392.455444,0.067002,0.000000
51.880001,10.121460,-392.499908,0.009416,0.002624,0.066638,45.022503,2.293555,0.666376,-392.499908,0.067522,0.000000
52.190002,10.179543,-392.544403,0.009434,0.002642,0.067106,45.280869,2.306717,0.671062,-392.544403,0.068034,0.000000
52.500004,10.175453,-392.499908,0.009438,0.002659,0.067531,45.262676,2.305791,0.675309,-392.499908,0.068554,0.000000
52.810001,10.303543,-392.499908,0.009455,0.002678,0.068034,45.832447,2.334816,0.680339,-392.499908,0.069066,0.000000
53.120003,10.798431,-392.588867,0.009490,0.002709,0.068797,48.033821,2.446960,0.687973,-392.588867,0.069586,0.000000
53.430004,10.630859,-392.544403,0.009516,0.002727,0.069257,47.288425,2.408987,0.692568,-392.544403,0.070107,0.000000
53.740002,10.433128,-392.588867,0.009533,0.002742,0.069638,46.408875,2.364181,0.696383,-392.588867,0.070618,0.000000
54.050003,10.509468,-392.588867,0.009546,0.002761,0.070141,46.748447,2.381480,0.701413,-392.588867,0.071139,0.000000
54.360004,10.885567,-392.544403,0.009580,0.002783,0.070688,48.421417,2.466705,0.706878,-392.544403,0.071650,0.000000
54.670002,10.811836,-392.588867,0.009580,0.002802,0.071173,48.093449,2.449997,0.711734,-392.588867,0.072171,0.000000
54.980003,11.304108,-392.588867,0.009623,0.002832,0.071936,50.283184,2.561548,0.719365,-392.588867,0.072691,0.000000
55.290001,11.139153,-392.588867,0.009636,0.002851,0.072413,49.549423,2.524168,0.724134,-392.588867,0.073203,0.000000
55.600002,10.885567,-392.544403,0.009649,0.002867,0.072821,48.421417,2.466705,0.728210,-392.544403,0.073723,0.000000
55.910004,11.005844,-392.588867,0.009671,0.002886,0.073307,48.956440,2.493960,0.733066,-392.588867,0.074235,0.000000
56.220001,11.300018,-392.633362,0.009684,0.002910,0.073922,50.264992,2.560621,0.739224,-392.633362,0.074755,0.000000
56.530003,11.007332,-392.588867,0.009710,0.002922,0.074217,48.963058,2.494297,0.742172,-392.588867,0.075267,0.000000
56.840004,11.528282,-392.633362,0.009731,0.002951,0.074955,51.280361,2.612346,0.749545,-392.633362,0.075787,0.000000
57.150002,11.712234,-392.588867,0.009744,0.002976,0.075587,52.098621,2.654030,0.755874,-392.588867,0.076307,0.000000
57.460003,11.470932,-392.677826,0.009791,0.002992,0.076004,51.025253,2.599350,0.760037,-392.677826,0.076819,0.000000
57.770004,11.326454,-392.722321,0.009791,0.003009,0.076429,50.382584,2.566611,0.764288,-392.722321,0.077339,0.000000
58.080002,11.815376,-392.677826,0.009822,0.003034,0.077070,52.557419,2.677402,0.770703,-392.677826,0.077851,0.000000
58.390003,11.627327,-392.722321,0.009826,0.003049,0.077443,51.720932,2.634790,0.774435,-392.722321,0.078371,0.000000
58.700005,11.716324,-392.677826,0.009856,0.003069,0.077955,52.116810,2.654957,0.779552,-392.677826,0.078892,0.000000
59.010002,11.921875,-392.633362,0.009869,0.003090,0.078493,53.031147,2.701535,0.784927,-392.633362,0.079403,0.000000
59.320004,11.930069,-392.722321,0.009873,0.003107,0.078926,53.067596,2.703392,0.789264,-392.722321,0.079924,0.000000
59.630001,12.136360,-392.588867,0.009899,0.003130,0.079507,53.985226,2.750139,0.795074,-392.588867,0.080435,0.000000
59.940002,12.462563,-392.633362,0.009938,0.003156,0.080175,55.436249,2.824057,0.801751,-392.633362,0.080955,0.000000
60.250004,12.254036,-392.677826,0.009955,0.003172,0.080574,54.508675,2.776804,0.805740,-392.677826,0.081467,0.000000
60.560001,12.061142,-392.633362,0.009968,0.003187,0.080947,53.650639,2.733094,0.809472,-392.633362,0.081988,0.000000
60.870003,12.525124,-392.766785,0.009981,0.003215,0.081658,55.714531,2.838233,0.816580,-392.766785,0.082508,0.000000
61.180004,12.512459,-392.677826,0.010011,0.003234,0.082144,55.658195,2.835364,0.821436,-392.677826,0.083020,0.000000
61.490002,12.592896,-392.766785,0.010037,0.003255,0.082681,56.015995,2.853591,0.826814,-392.766785,0.083540,0.000000
61.800003,12.505013,-392.766785,0.010050,0.003273,0.083141,55.625072,2.833676,0.831409,-392.766785,0.084052,0.000000
62.110004,12.772003,-392.722321,0.010063,0.003296,0.083714,56.812706,2.894177,0.837135,-392.722321,0.084572,0.000000
62.420002,12.671089,-392.811279,0.010093,0.003311,0.084095,56.363819,2.871310,0.840951,-392.811279,0.085084,0.000000
62.730003,12.910156,-392.722321,0.010098,0.003334,0.084693,57.427242,2.925483,0.846935,-392.722321,0.085604,0.000000
63.040005,13.203957,-392.811279,0.010119,0.003360,0.085335,58.734131,2.992059,0.853350,-392.811279,0.086124,0.000000
63.350002,13.089638,-392.766785,0.010128,0.003379,0.085821,58.225616,2.966154,0.858210,-392.766785,0.086636,0.000000
63.660004,13.171928,-392.722321,0.010175,0.003397,0.086289,58.591663,2.984802,0.862892,-392.722321,0.087156,0.000000
63.970001,13.283272,-392.811279,0.010184,0.003418,0.086827,59.086945,3.010032,0.868266,-392.811279,0.087668,0.000000
64.280006,13.269867,-392.766785,0.010210,0.003435,0.087260,59.027317,3.006995,0.872604,-392.766785,0.088188,0.000000
64.590004,13.640747,-392.900238,0.010218,0.003461,0.087902,60.677074,3.091038,0.879023,-392.900238,0.088708,0.000000
64.900002,13.707405,-392.855774,0.010257,0.003483,0.088457,60.973583,3.106143,0.884572,-392.855774,0.089220,0.000000
65.210007,13.580795,-392.811279,0.010270,0.003501,0.088917,60.410393,3.077452,0.889166,-392.811279,0.089741,0.000000
65.520004,13.604630,-392.855774,0.010266,0.003519,0.089385,60.516415,3.082853,0.893852,-392.855774,0.090252,0.000000
65.830002,13.762138,-392.855774,0.010309,0.003539,0.089888,61.217049,3.118545,0.898882,-392.855774,0.090773,0.000000
66.139999,13.916679,-392.900238,0.010309,0.003559,0.090400,61.904480,3.153565,0.903996,-392.900238,0.091284,0.000000
66.450005,13.680595,-392.811279,0.010322,0.003572,0.090729,60.854328,3.100067,0.907292,-392.811279,0.091805,0.000000
66.760002,14.249947,-392.811279,0.010356,0.003601,0.091458,63.386929,3.229084,0.914578,-392.811279,0.092325,0.000000
67.070000,14.251442,-392.900238,0.010365,0.003620,0.091952,63.393581,3.229423,0.919521,-392.900238,0.092837,0.000000
67.380005,14.206009,-392.855774,0.010386,0.003639,0.092420,63.191483,3.219128,0.924203,-392.855774,0.093357,0.000000
67.690002,14.557159,-392.944733,0.010408,0.003664,0.093062,64.753479,3.298699,0.930622,-392.944733,0.093869,0.000000
68.000000,14.483803,-392.900238,0.010438,0.003684,0.093574,64.427170,3.282077,0.935740,-392.900238,0.094389,0.000000
68.310005,14.361664,-392.855774,0.010451,0.003698,0.093938,63.883873,3.254400,0.939381,-392.855774,0.094909,0.000000
68.620003,14.935860,-392.900238,0.010451,0.003726,0.094649,66.438019,3.384514,0.946492,-392.900238,0.095421,0.000000
68.930000,14.727333,-392.811279,0.010490,0.003744,0.095109,65.510452,3.337261,0.951087,-392.811279,0.095941,0.000000
69.240005,14.761963,-392.900238,0.010511,0.003762,0.095560,65.664490,3.345109,0.955599,-392.900238,0.096453,0.000000
69.550003,14.830849,-392.944733,0.010511,0.003781,0.096028,65.970909,3.360718,0.960281,-392.944733,0.096973,0.000000
69.860001,15.015923,-392.900238,0.010537,0.003802,0.096566,66.794159,3.402657,0.965655,-392.900238,0.097485,0.000000
70.170006,14.953735,-392.989197,0.010555,0.003818,0.096982,66.517540,3.388565,0.969819,-392.989197,0.098005,0.000000
70.480003,15.672783,-392.944733,0.010568,0.003846,0.097684,69.716019,3.551503,0.976844,-392.944733,0.098526,0.000000
70.790001,15.670921,-392.944733,0.010602,0.003868,0.098240,69.707741,3.551081,0.982396,-392.944733,0.099037,0.000000
71.100006,15.533142,-392.944733,0.010615,0.003885,0.098690,69.094864,3.519860,0.986904,-392.944733,0.099557,0.000000
71.410004,15.543945,-392.944733,0.010637,0.003904,0.099167,69.142921,3.522308,0.991673,-392.944733,0.100069,0.000000
71.720001,15.691032,-392.989197,0.010649,0.003922,0.099627,69.797195,3.555639,0.996271,-392.989197,0.100590,0.000000
72.030006,15.521599,-392.944733,0.010671,0.003937,0.100000,69.043518,3.517245,1.000000,-392.944733,0.101110,0.000000
72.340004,15.868652,-393.033691,0.010688,0.003963,0.100659,70.587288,3.595888,1.006589,-393.033691,0.101622,0.000000
72.650002,16.489029,-392.944733,0.010710,0.003989,0.101327,73.346863,3.736467,1.013269,-392.944733,0.102142,0.000000
72.960007,16.276031,-393.078156,0.010723,0.004007,0.101786,72.399406,3.688201,1.017864,-393.078156,0.102654,0.000000
73.270004,16.077927,-392.989197,0.010744,0.004023,0.102185,71.518188,3.643310,1.021854,-392.989197,0.103174,0.000000
73.580002,16.401146,-393.033691,0.010757,0.004047,0.102792,72.955940,3.716553,1.027925,-393.033691,0.103686,0.000000
73.890007,16.205650,-393.033691,0.010779,0.004059,0.103096,72.086334,3.672253,1.030960,-393.033691,0.104206,0.000000
74.200005,16.570946,-393.033691,0.010792,0.004080,0.103633,73.711250,3.755030,1.036335,-393.033691,0.104726,0.000000
74.510002,17.512306,-393.033691,0.010818,0.004114,0.104484,77.898628,3.968345,1.044835,-393.033691,0.105238,0.000000
74.820007,17.047958,-393.033691,0.010831,0.004130,0.104900,75.833107,3.863122,1.048999,-393.033691,0.105758,0.000000
75.130005,16.968269,-393.033691,0.010843,0.004147,0.105342,75.478630,3.845065,1.053420,-393.033691,0.106270,0.000000
75.440002,16.929543,-393.122650,0.010861,0.004163,0.105732,75.306366,3.836289,1.057322,-393.122650,0.106790,0.000000
75.750000,17.315689,-393.033691,0.010878,0.004185,0.106296,77.024033,3.923791,1.062961,-393.033691,0.107302,0.000000
76.060005,17.452728,-393.122650,0.010882,0.004204,0.106782,77.633614,3.954845,1.067817,-393.122650,0.107822,0.000000
76.370003,18.357590,-393.078156,0.010921,0.004235,0.107580,81.658638,4.159889,1.075796,-393.078156,0.108343,0.000000
76.680000,18.017990,-393.078156,0.010956,0.004253,0.108022,80.148026,4.082935,1.080217,-393.078156,0.108854,0.000000
76.990005,17.787857,-393.122650,0.010973,0.004269,0.108429,79.124336,4.030786,1.084293,-393.122650,0.109375,0.000000
77.300003,17.755836,-393.078156,0.010986,0.004285,0.108837,78.981903,4.023530,1.088369,-393.078156,0.109886,0.000000
77.610001,18.448448,-393.122650,0.010990,0.004311,0.109505,82.062798,4.180478,1.095046,-393.122650,0.110407,0.000000
77.920006,18.092834,-393.078156,0.011016,0.004326,0.109869,80.480949,4.099895,1.098691,-393.078156,0.110927,0.000000
78.230003,19.166756,-393.078156,0.011029,0.004357,0.110667,85.257988,4.343249,1.106669,-393.078156,0.111439,0.000000
78.540001,19.185371,-393.167114,0.011046,0.004377,0.111170,85.340797,4.347467,1.111699,-393.167114,0.111959,0.000000
78.850006,18.968651,-393.078156,0.011076,0.004395,0.111638,84.376770,4.298358,1.116381,-393.078156,0.112471,0.000000
79.160004,19.168617,-393.167114,0.011089,0.004414,0.112106,85.266266,4.343671,1.121063,-393.167114,0.112991,0.000000
79.470001,19.505615,-393.167114,0.011115,0.004434,0.112635,86.765312,4.420036,1.126354,-393.167114,0.113503,0.000000
79.780006,19.371185,-393.167114,0.011137,0.004451,0.113043,86.167336,4.389573,1.130431,-393.167114,0.114023,0.000000
80.090004,19.905167,-393.211609,0.011154,0.004473,0.113624,88.542603,4.510575,1.136241,-393.211609,0.114543,0.000000
80.400002,20.103645,-393.167114,0.011171,0.004494,0.114144,89.425484,4.555551,1.141445,-393.167114,0.115055,0.000000
80.710007,20.365051,-393.211609,0.011184,0.004514,0.114656,90.588272,4.614787,1.146562,-393.211609,0.115575,0.000000
81.020004,20.410110,-393.167114,0.011197,0.004530,0.115064,90.788704,4.624997,1.150638,-393.167114,0.116087,0.000000
81.330002,21.350349,-393.211609,0.011227,0.004560,0.115827,94.971100,4.838058,1.158269,-393.211609,0.116607,0.000000
81.640007,21.274384,-393.211609,0.011240,0.004577,0.116252,94.633186,4.820844,1.162519,-393.211609,0.117128,0.000000
81.950005,21.249435,-393.167114,0.011257,0.004596,0.116729,94.522209,4.815191,1.167288,-393.167114,0.117639,0.000000
82.260002,21.701492,-393.256104,0.011279,0.004614,0.117197,96.533058,4.917629,1.171970,-393.256104,0.118159,0.000000
82.570007,22.289101,-393.256104,0.011305,0.004640,0.117848,99.146873,5.050783,1.178476,-393.256104,0.118671,0.000000
82.880005,22.528534,-393.256104,0.011331,0.004659,0.118342,100.211922,5.105039,1.183419,-393.256104,0.119192,0.000000
83.190002,22.944473,-393.211609,0.011326,0.004680,0.118871,102.062111,5.199292,1.188707,-393.211609,0.119703,0.000000
83.500008,23.113533,-393.211609,0.011361,0.004696,0.119270,102.814133,5.237602,1.192696,-393.211609,0.120224,0.000000
83.810005,23.126938,-393.256104,0.011369,0.004710,0.119625,102.873756,5.240639,1.196254,-393.256104,0.120744,0.000000
84.120003,24.147614,-393.211609,0.011391,0.004739,0.120380,107.413948,5.471927,1.203797,-393.211609,0.121256,0.000000
84.430000,24.715103,-393.256104,0.011404,0.004762,0.120952,109.938271,5.600523,1.209520,-393.256104,0.121776,0.000000
84.740005,24.824211,-393.300568,0.011421,0.004779,0.121386,110.423607,5.625247,1.213857,-393.300568,0.122288,0.000000
85.050003,25.084129,-393.256104,0.011451,0.004796,0.121811,111.579781,5.684145,1.218108,-393.256104,0.122808,0.000000
85.360001,25.684761,-393.300568,0.011469,0.004820,0.122418,114.251526,5.820250,1.224179,-393.300568,0.123320,0.000000
85.670006,25.959572,-393.256104,0.011486,0.004834,0.122782,115.473946,5.882523,1.227820,-393.256104,0.123840,0.000000
85.980003,27.138878,-393.300568,0.011516,0.004864,0.123536,120.719757,6.149757,1.235363,-393.300568,0.124360,0.000000
86.290001,27.793510,-393.256104,0.011520,0.004886,0.124100,123.631706,6.298100,1.241003,-393.256104,0.124872,0.000000
86.600006,28.062363,-393.300568,0.011542,0.004903,0.124525,124.827621,6.359022,1.245249,-393.300568,0.125392,0.000000
86.910004,28.341644,-393.345062,0.011551,0.004919,0.124941,126.069931,6.422308,1.249413,-393.345062,0.125904,0.000000
87.220001,28.970947,-393.300568,0.011589,0.004937,0.125409,128.869217,6.564910,1.254095,-393.300568,0.126424,0.000000
87.530006,29.778999,-393.434021,0.011576,0.004960,0.125982,132.463608,6.748018,1.259821,-393.434021,0.126945,0.000000
87.840004,30.624283,-393.345062,0.011607,0.004982,0.126546,136.223618,6.939562,1.265457,-393.345062,0.127456,0.000000
88.150002,31.454674,-393.345062,0.011620,0.005005,0.127118,139.917374,7.127731,1.271180,-393.345062,0.127977,0.000000
88.460007,32.231071,-393.389526,0.011641,0.005025,0.127630,143.370972,7.303665,1.276297,-393.389526,0.128488,0.000000
88.770004,32.750160,-393.345062,0.011654,0.005045,0.128133,145.679993,7.421293,1.281327,-393.345062,0.129009,0.000000
89.080002,33.803230,-393.434021,0.011671,0.005067,0.128705,150.364273,7.659921,1.287050,-393.434021,0.129520,0.000000
89.390007,34.456367,-393.345062,0.011680,0.005085,0.129156,153.269577,7.807925,1.291561,-393.345062,0.130041,0.000000
89.700005,35.018280,-393.345062,0.011697,0.005106,0.129685,155.769089,7.935256,1.296853,-393.345062,0.130561,0.000000
90.010002,36.372597,-393.434021,0.011723,0.005130,0.130309,161.793396,8.242148,1.303094,-393.434021,0.131073,0.000000
90.320007,36.948288,-393.300568,0.011727,0.005148,0.130761,164.354187,8.372602,1.307606,-393.300568,0.131593,0.000000
90.630005,37.538498,-393.434021,0.011740,0.005164,0.131168,166.979584,8.506346,1.311682,-393.434021,0.132105,0.000000
90.940002,38.588959,-393.389526,0.011749,0.005186,0.131732,171.652267,8.744383,1.317318,-393.389526,0.132625,0.000000
91.250008,39.537766,-393.389526,0.011775,0.005204,0.132183,175.872772,8.959385,1.321825,-393.389526,0.133145,0.000000
91.560005,40.120155,-393.434021,0.011783,0.005221,0.132608,178.463364,9.091357,1.326076,-393.434021,0.133657,0.000000
91.870003,42.036758,-393.434021,0.011796,0.005249,0.133336,186.988846,9.525666,1.333362,-393.434021,0.134177,0.000000
92.180008,42.978485,-393.478485,0.011801,0.005268,0.133796,191.177856,9.739064,1.337957,-393.478485,0.134689,0.000000
92.490005,43.801430,-393.434021,0.011826,0.005287,0.134290,194.838486,9.925546,1.342900,-393.434021,0.135209,0.000000
92.800003,44.532768,-393.434021,0.011839,0.005303,0.134689,198.091644,10.091269,1.346889,-393.434021,0.135721,0.000000
93.110001,45.773514,-393.434021,0.011844,0.005325,0.135261,203.610764,10.372427,1.352612,-393.434021,0.136241,0.000000
93.420006,46.106789,-393.434021,0.011865,0.005338,0.135573,205.093246,10.447948,1.355734,-393.434021,0.136762,0.000000
93.730003,48.284790,-393.478485,0.011861,0.005369,0.136371,214.781479,10.941490,1.363713,-393.478485,0.137273,0.000000
94.040001,49.704651,-393.478485,0.011883,0.005390,0.136900,221.097336,11.263235,1.369004,-393.478485,0.137794,0.000000
94.350006,50.611374,-393.522980,0.011904,0.005408,0.137360,225.130630,11.468701,1.373599,-393.522980,0.138305,0.000000
94.660004,51.463364,-393.434021,0.011904,0.005426,0.137828,228.920471,11.661764,1.378285,-393.434021,0.138826,0.000000
94.970001,52.910774,-393.478485,0.011930,0.005446,0.138340,235.358871,11.989753,1.383398,-393.478485,0.139346,0.000000
95.280006,53.338257,-393.522980,0.011926,0.005458,0.138626,237.260422,12.086621,1.386263,-393.522980,0.139858,0.000000
95.590004,55.051918,-393.478485,0.011934,0.005486,0.139346,244.883163,12.474942,1.393458,-393.478485,0.140378,0.000000
95.900002,57.466011,-393.567444,0.011943,0.005514,0.140057,255.621582,13.021984,1.400570,-393.567444,0.140890,0.000000
96.210007,58.378319,-393.522980,0.011956,0.005531,0.140499,259.679718,13.228716,1.404995,-393.522980,0.141410,0.000000
96.520004,59.256378,-393.522980,0.011973,0.005546,0.140864,263.585541,13.427688,1.408636,-393.522980,0.141921,0.000000
96.830002,60.306839,-393.567444,0.011977,0.005564,0.141315,268.258209,13.665725,1.413147,-393.567444,0.142442,0.000000
97.140007,61.983627,-393.567444,0.011986,0.005587,0.141921,275.716949,14.045691,1.419214,-393.567444,0.142962,0.000000
97.450005,63.422844,-393.611938,0.012003,0.005608,0.142442,282.118896,14.371821,1.424419,-393.611938,0.143474,0.000000
97.760002,65.935616,-393.567444,0.012016,0.005637,0.143188,293.296265,14.941224,1.431879,-393.567444,0.143994,0.000000
98.070007,66.976036,-393.611938,0.012038,0.005652,0.143561,297.924286,15.176987,1.435607,-393.611938,0.144506,0.000000
98.380005,67.193123,-393.611938,0.012042,0.005653,0.143578,298.889923,15.226179,1.435781,-393.611938,0.143786,0.000000
98.690002,66.537743,-393.567444,0.012038,0.005652,0.143561,295.974670,15.077668,1.435607,-393.567444,0.143578,0.000000
99.000008,65.988121,-393.611938,0.012042,0.005652,0.143552,293.529816,14.953122,1.435520,-393.611938,0.143578,0.000000
99.310005,65.540154,-393.567444,0.012059,0.005651,0.143543,291.537170,14.851611,1.435433,-393.567444,0.143578,0.000000
99.620003,65.130180,-393.611938,0.012059,0.005651,0.143535,289.713501,14.758710,1.435346,-393.611938,0.143578,0.000000
99.930008,64.794670,-393.656403,0.012064,0.005651,0.143535,288.221100,14.682682,1.435346,-393.656403,0.143578,0.000000
100.240005,64.471077,-393.611938,0.012072,0.005651,0.143535,286.781677,14.609354,1.435346,-393.611938,0.143578,0.000000
100.550003,64.217873,-393.656403,0.012072,0.005651,0.143526,285.655365,14.551978,1.435259,-393.656403,0.143578,0.000000
100.860008,63.972847,-393.611938,0.012064,0.005651,0.143526,284.565430,14.496454,1.435259,-393.611938,0.143578,0.000000
101.170006,63.741966,-393.656403,0.012064,0.005651,0.143526,283.538422,14.444136,1.435259,-393.656403,0.143578,0.000000
101.480003,63.519295,-393.656403,0.012077,0.005651,0.143526,282.547943,14.393678,1.435259,-393.656403,0.143578,0.000000
101.790009,63.353218,-393.656403,0.012068,0.005651,0.143526,281.809174,14.356044,1.435259,-393.656403,0.143578,0.000000
102.100006,63.183418,-393.700897,0.012068,0.005651,0.143526,281.053894,14.317567,1.435259,-393.700897,0.143578,0.000000
102.410004,62.991646,-393.700897,0.012077,0.005651,0.143526,280.200836,14.274112,1.435259,-393.700897,0.143578,0.000000
102.720001,62.879929,-393.700897,0.012068,0.005651,0.143526,279.703888,14.248796,1.435259,-393.700897,0.143578,0.000000
103.030006,62.713478,-393.700897,0.012072,0.005651,0.143526,278.963470,14.211078,1.435259,-393.700897,0.143578,0.000000
103.340004,62.596184,-393.656403,0.012072,0.005651,0.143526,278.441742,14.184499,1.435259,-393.656403,0.143578,0.000000
103.650002,62.463989,-393.745392,0.012068,0.005651,0.143526,277.853699,14.154542,1.435259,-393.745392,0.143578,0.000000
103.960007,62.371269,-393.700897,0.012077,0.005651,0.143526,277.441254,14.133532,1.435259,-393.700897,0.143578,0.000000
104.270004,62.236847,-393.700897,0.012094,0.005651,0.143526,276.843323,14.103071,1.435259,-393.700897,0.143578,0.000000
104.580002,62.137047,-393.656403,0.012072,0.005651,0.143526,276.399384,14.080456,1.435259,-393.656403,0.143578,0.000000
104.890007,62.032036,-393.789856,0.012081,0.005651,0.143526,275.932281,14.056660,1.435259,-393.789856,0.143578,0.000000
105.200005,61.932243,-393.789856,0.012072,0.005651,0.143526,275.488373,14.034047,1.435259,-393.789856,0.143578,0.000000
105.510002,61.856277,-393.789856,0.012089,0.005651,0.143526,275.150452,14.016833,1.435259,-393.789856,0.143578,0.000000
105.820007,61.748291,-393.789856,0.012072,0.005651,0.143526,274.670105,13.992363,1.435259,-393.789856,0.143578,0.000000
106.130005,61.689453,-393.700897,0.012077,0.005651,0.143526,274.408386,13.979030,1.435259,-393.700897,0.143578,0.000000
106.440002,61.584824,-393.789856,0.012085,0.005651,0.143526,273.942963,13.955320,1.435259,-393.789856,0.143578,0.000000
106.750008,61.521515,-393.834351,0.012077,0.005651,0.143526,273.661377,13.940974,1.435259,-393.834351,0.143578,0.000000
107.060005,61.437737,-393.745392,0.012094,0.005651,0.143526,273.288696,13.921989,1.435259,-393.745392,0.143578,0.000000
107.370003,61.374054,-393.834351,0.012077,0.005651,0.143526,273.005432,13.907559,1.435259,-393.834351,0.143578,0.000000
107.680008,61.300697,-393.834351,0.012081,0.005651,0.143526,272.679108,13.890936,1.435259,-393.834351,0.143578,0.000000
107.990005,61.230324,-393.834351,0.012081,0.005651,0.143526,272.366089,13.874990,1.435259,-393.834351,0.143578,0.000000
108.300003,61.159195,-393.834351,0.012081,0.005651,0.143526,272.049683,13.858871,1.435259,-393.834351,0.143578,0.000000
108.610008,61.107063,-393.834351,0.012089,0.005651,0.143526,271.817780,13.847058,1.435259,-393.834351,0.143578,0.000000
108.920006,61.027382,-393.834351,0.012089,0.005651,0.143526,271.463348,13.829002,1.435259,-393.834351,0.143578,0.000000
109.230003,60.973015,-393.789856,0.012081,0.005651,0.143526,271.221527,13.816683,1.435259,-393.789856,0.143578,0.000000
109.540009,60.923859,-393.878815,0.012077,0.005651,0.143526,271.002869,13.805544,1.435259,-393.878815,0.143578,0.000000
109.850006,60.851990,-393.878815,0.012081,0.005651,0.143526,270.683167,13.789258,1.435259,-393.878815,0.143578,0.000000
110.160004,60.810661,-393.878815,0.012085,0.005651,0.143526,270.499329,13.779893,1.435259,-393.878815,0.143578,0.000000
110.470009,60.746239,-393.878815,0.012077,0.005650,0.143517,270.212769,13.765294,1.435172,-393.878815,0.143578,0.000000
110.780006,60.700066,-393.878815,0.012085,0.005650,0.143517,270.007385,13.754831,1.435172,-393.878815,0.143578,0.000000
111.090004,60.634529,-393.878815,0.012102,0.005650,0.143517,269.715851,13.739981,1.435172,-393.878815,0.143578,0.000000
111.400002,60.601753,-393.923309,0.012072,0.005650,0.143517,269.570068,13.732553,1.435172,-393.923309,0.143578,0.000000
111.710007,60.560799,-393.878815,0.012098,0.005650,0.143517,269.387878,13.723273,1.435172,-393.878815,0.143578,0.000000
112.020004,60.506805,-393.967773,0.012081,0.005650,0.143517,269.147705,13.711039,1.435172,-393.967773,0.143578,0.000000
112.330002,60.465096,-393.834351,0.012085,0.005650,0.143517,268.962189,13.701587,1.435172,-393.834351,0.143578,0.000000
112.640007,60.416313,-393.878815,0.012098,0.005650,0.143517,268.745178,13.690532,1.435172,-393.878815,0.143578,0.000000
112.950005,60.348167,-393.878815,0.012081,0.005650,0.143517,268.442047,13.675091,1.435172,-393.878815,0.143578,0.000000
113.260002,60.333275,-393.923309,0.012102,0.005650,0.143517,268.375824,13.671715,1.435172,-393.923309,0.143578,0.000000
113.570007,60.301254,-394.012268,0.012081,0.005650,0.143517,268.233368,13.664459,1.435172,-394.012268,0.143578,0.000000
113.880005,60.243164,-393.923309,0.012098,0.005650,0.143517,267.974976,13.651296,1.435172,-393.923309,0.143578,0.000000
114.190002,60.218582,-394.012268,0.012102,0.005650,0.143517,267.865631,13.645725,1.435172,-394.012268,0.143578,0.000000
114.500008,60.170174,-393.923309,0.012094,0.005650,0.143517,267.650299,13.634756,1.435172,-393.923309,0.143578,0.000000
114.810005,60.147087,-393.923309,0.012098,0.005650,0.143517,267.547607,13.629525,1.435172,-393.923309,0.143578,0.000000
115.120003,60.103523,-394.012268,0.012094,0.005650,0.143517,267.353821,13.619653,1.435172,-394.012268,0.143578,0.000000
115.430008,60.080811,-394.012268,0.012094,0.005650,0.143517,267.252808,13.614507,1.435172,-394.012268,0.143578,0.000000
115.740005,60.029045,-393.967773,0.012094,0.005650,0.143517,267.022522,13.602777,1.435172,-393.967773,0.143578,0.000000
116.050003,60.015266,-394.012268,0.012094,0.005650,0.143517,266.961243,13.599653,1.435172,-394.012268,0.143578,0.000000
116.360008,59.976540,-394.012268,0.012107,0.005650,0.143517,266.788971,13.590878,1.435172,-394.012268,0.143578,0.000000
116.670006,59.947128,-393.967773,0.012085,0.005650,0.143517,266.658142,13.584214,1.435172,-393.967773,0.143578,0.000000
116.980003,59.915100,-394.056732,0.012098,0.005650,0.143517,266.515686,13.576956,1.435172,-394.056732,0.143578,0.000000
117.290009,59.887543,-394.056732,0.012089,0.005650,0.143517,266.393097,13.570711,1.435172,-394.056732,0.143578,0.000000
117.600006,59.851425,-393.967773,0.012089,0.005650,0.143517,266.232422,13.562527,1.435172,-393.967773,0.143578,0.000000
117.910004,59.827225,-394.012268,0.012098,0.005650,0.143517,266.124786,13.557043,1.435172,-394.012268,0.143578,0.000000
118.220009,59.811211,-394.101227,0.012089,0.005650,0.143517,266.053558,13.553414,1.435172,-394.101227,0.143578,0.000000
118.530006,59.763550,-394.056732,0.012077,0.005650,0.143517,265.841553,13.542614,1.435172,-394.056732,0.143578,0.000000
118.840004,59.745300,-394.101227,0.012098,0.005650,0.143517,265.760376,13.538479,1.435172,-394.101227,0.143578,0.000000
119.150009,59.710297,-394.056732,0.012077,0.005650,0.143517,265.604675,13.530547,1.435172,-394.056732,0.143578,0.000000
119.460007,59.690933,-394.056732,0.012094,0.005650,0.143517,265.518524,13.526159,1.435172,-394.056732,0.143578,0.000000
119.770004,59.666359,-394.101227,0.012077,0.005650,0.143517,265.409210,13.520591,1.435172,-394.101227,0.143578,0.000000
120.080009,59.628372,-394.056732,0.012098,0.005650,0.143517,265.240234,13.511982,1.435172,-394.056732,0.143578,0.000000
120.390007,59.603424,-394.101227,0.012102,0.005650,0.143517,265.129272,13.506330,1.435172,-394.101227,0.143578,0.000000
120.700005,59.573639,-394.101227,0.012085,0.005650,0.143517,264.996796,13.499579,1.435172,-394.101227,0.143578,0.000000
121.010002,59.554642,-394.101227,0.012102,0.005650,0.143517,264.912262,13.495275,1.435172,-394.101227,0.143578,0.000000
121.320007,59.532677,-394.056732,0.012085,0.005650,0.143517,264.814575,13.490297,1.435172,-394.056732,0.143578,0.000000
121.630005,59.502144,-394.101227,0.012089,0.005650,0.143517,264.678741,13.483379,1.435172,-394.101227,0.143578,0.000000
121.940002,59.481285,-394.101227,0.012098,0.005650,0.143517,264.585968,13.478652,1.435172,-394.101227,0.143578,0.000000
122.250008,59.449638,-394.145721,0.012107,0.005650,0.143517,264.445190,13.471480,1.435172,-394.145721,0.143578,0.000000
122.560005,59.435860,-394.101227,0.012107,0.005650,0.143517,264.383911,13.468359,1.435172,-394.101227,0.143578,0.000000
122.870003,59.419106,-394.145721,0.012081,0.005650,0.143517,264.309387,13.464562,1.435172,-394.145721,0.143578,0.000000
123.180008,59.391548,-394.101227,0.012094,0.005650,0.143517,264.186798,13.458317,1.435172,-394.101227,0.143578,0.000000
123.490005,59.358780,-394.145721,0.012098,0.005650,0.143517,264.041046,13.450891,1.435172,-394.145721,0.143578,0.000000
123.800003,59.353195,-394.145721,0.012107,0.005650,0.143517,264.016205,13.449626,1.435172,-394.145721,0.143578,0.000000
124.110008,59.315582,-394.145721,0.012089,0.005650,0.143517,263.848877,13.441104,1.435172,-394.145721,0.143578,0.000000
124.420006,59.295845,-394.190186,0.012089,0.005650,0.143517,263.761078,13.436630,1.435172,-394.190186,0.143578,0.000000
124.730003,59.283928,-394.145721,0.012102,0.005650,0.143517,263.708069,13.433929,1.435172,-394.145721,0.143578,0.000000
125.040009,59.252281,-394.190186,0.012098,0.005650,0.143517,263.567322,13.426759,1.435172,-394.190186,0.143578,0.000000
125.350006,59.239990,-394.234680,0.012085,0.005650,0.143517,263.512634,13.423973,1.435172,-394.234680,0.143578,0.000000
125.660004,59.219139,-394.190186,0.012094,0.005650,0.143517,263.419891,13.419249,1.435172,-394.190186,0.143578,0.000000
125.970009,59.203499,-394.234680,0.012102,0.005650,0.143517,263.350311,13.415705,1.435172,-394.234680,0.143578,0.000000
126.280006,59.185249,-394.145721,0.012102,0.005650,0.143517,263.269135,13.411569,1.435172,-394.145721,0.143578,0.000000
126.590004,59.158066,-394.234680,0.012089,0.005650,0.143517,263.148224,13.405409,1.435172,-394.234680,0.143578,0.000000
126.900009,59.140198,-394.190186,0.012102,0.005650,0.143517,263.068726,13.401360,1.435172,-394.190186,0.143578,0.000000
127.210007,59.134605,-394.279144,0.012098,0.005650,0.143517,263.043854,13.400093,1.435172,-394.279144,0.143578,0.000000
127.520004,59.104820,-394.234680,0.012085,0.005650,0.143517,262.911377,13.393344,1.435172,-394.234680,0.143578,0.000000
127.830009,59.080986,-394.234680,0.012085,0.005650,0.143517,262.805359,13.387943,1.435172,-394.234680,0.143578,0.000000
128.139999,59.081360,-394.279144,0.012102,0.005650,0.143517,262.807007,13.388027,1.435172,-394.279144,0.143578,0.000000
128.450012,59.050079,-394.279144,0.012098,0.005650,0.143517,262.667877,13.380939,1.435172,-394.279144,0.143578,0.000000
128.700012,59.044495,-394.234680,0.012081,0.005650,0.143517,262.643036,13.379674,1.435172,-394.234680,0.143578,0.000000