File: Data/compression 5/AutoNoheating-10-5-3-240223_02232024_193652.csv
Time (sec),S:Load (lbs),S:HL1 (DIM),S:LVDT (in),S:Position (in),Ch:Position (mm),Ch:Load (N),Ch:Stress (MPa),Ch:Strain (mm/mm),Ch:HL1 (DIM),Set Point (),Cycles ()
0.110000,-0.025688,-395.658051,-0.000009,-0.000000,-0.000000,-0.114267,-0.005821,-0.000000,-395.658051,0.000130,0.000000
0.390000,-0.013031,-395.613586,-0.000009,-0.000000,-0.000000,-0.057965,-0.002953,-0.000000,-395.613586,0.000130,0.000000
0.670000,0.024956,-395.613586,0.000013,0.000138,0.003503,0.111009,0.005655,0.035033,-395.613586,0.004327,0.000000
0.950000,0.146347,-395.702545,0.000147,0.000316,0.008030,0.650984,0.033163,0.080304,-395.702545,0.008993,0.000000
1.230000,0.508293,-395.747009,0.000319,0.000492,0.012497,2.261001,0.115181,0.124966,-395.747009,0.013659,0.000000
1.510000,0.563034,-395.658051,0.000414,-0.000000,-0.000000,2.504501,0.127585,-0.000000,-395.658051,0.000234,0.000000
1.790000,0.513130,-395.658051,0.000401,-0.000000,-0.000000,2.282517,0.116277,-0.000000,-395.658051,0.000234,0.000000
2.070000,0.525421,-395.747009,0.000435,-0.000000,-0.000000,2.337190,0.119062,-0.000000,-395.747009,0.000520,0.000000
2.350000,0.510529,-395.747009,0.000427,0.000001,0.000017,2.270944,0.115687,0.000174,-395.747009,0.000989,0.000000
2.630000,0.653893,-395.747009,0.000427,0.000024,0.000607,2.908659,0.148174,0.006071,-395.747009,0.001457,0.000000
2.910000,0.704903,-395.702545,0.000435,0.000036,0.000902,3.135564,0.159733,0.009019,-395.702545,0.001925,0.000000
3.190000,0.792786,-395.702545,0.000457,0.000055,0.001396,3.526487,0.179648,0.013962,-395.702545,0.002394,0.000000
3.470000,0.923119,-395.702545,0.000483,0.000084,0.002134,4.106236,0.209182,0.021335,-395.702545,0.002853,0.000000
3.750000,0.934288,-395.747009,0.000509,0.000100,0.002532,4.155921,0.211713,0.025325,-395.747009,0.003322,0.000000
4.030000,0.961472,-395.791504,0.000504,0.000115,0.002923,4.276839,0.217873,0.029227,-395.791504,0.003790,0.000000
4.310000,1.007271,-395.835999,0.000513,0.000130,0.003304,4.480564,0.228251,0.033042,-395.835999,0.004258,0.000000
4.590000,1.154358,-395.702545,0.000530,0.000154,0.003903,5.134840,0.261581,0.039026,-395.702545,0.004726,0.000000
4.870000,1.170372,-395.702545,0.000569,0.000166,0.004224,5.206075,0.265210,0.042236,-395.702545,0.005186,0.000000
5.150000,1.259743,-395.747009,0.000578,0.000191,0.004848,5.603616,0.285462,0.048477,-395.747009,0.005654,0.000000
5.430000,1.358047,-395.835999,0.000591,0.000213,0.005420,6.040897,0.307738,0.054200,-395.835999,0.006122,0.000000
5.710000,1.364006,-395.791504,0.000612,0.000230,0.005845,6.067402,0.309088,0.058450,-395.791504,0.006591,0.000000
5.990000,1.403473,-395.791504,0.000617,0.000243,0.006183,6.242959,0.318031,0.061834,-395.791504,0.007059,0.000000
6.270000,1.491730,-395.835999,0.000664,0.000262,0.006660,6.635545,0.338031,0.066603,-395.835999,0.007527,0.000000
6.550000,1.666740,-395.835999,0.000668,0.000285,0.007241,7.414032,0.377689,0.072413,-395.835999,0.007987,0.000000
6.830000,1.688713,-395.791504,0.000694,0.000299,0.007588,7.511771,0.382668,0.075883,-395.791504,0.008455,0.000000
7.110000,1.787766,-395.835999,0.000686,0.000320,0.008117,7.952378,0.405113,0.081171,-395.835999,0.008924,0.000000
7.390000,1.922188,-395.835999,0.000733,0.000342,0.008690,8.550319,0.435574,0.086897,-395.835999,0.009392,0.000000
7.670001,1.920700,-395.791504,0.000733,0.000356,0.009045,8.543700,0.435237,0.090451,-395.791504,0.009860,0.000000
7.950000,1.970596,-395.791504,0.000750,0.000371,0.009427,8.765650,0.446544,0.094267,-395.791504,0.010320,0.000000
8.230000,2.115448,-395.880463,0.000763,0.000392,0.009956,9.409983,0.479367,0.099558,-395.880463,0.010788,0.000000
8.510000,2.257324,-395.835999,0.000785,0.000412,0.010468,10.041080,0.511517,0.104675,-395.835999,0.011257,0.000000
8.790000,2.264030,-395.880463,0.000806,0.000424,0.010771,10.070910,0.513037,0.107711,-395.880463,0.011725,0.000000
9.070001,2.415215,-395.835999,0.000811,0.000445,0.011291,10.743411,0.547295,0.112911,-395.835999,0.012193,0.000000
9.350000,2.545540,-395.835999,0.000828,0.000466,0.011838,11.323127,0.576828,0.118376,-395.835999,0.012653,0.000000
9.630000,2.595810,-395.880463,0.000845,0.000481,0.012210,11.546740,0.588219,0.122104,-395.880463,0.013121,0.000000
9.910001,2.691139,-395.924957,0.000875,0.000500,0.012687,11.970785,0.609821,0.126873,-395.924957,0.013589,0.000000
10.190001,2.853867,-395.880463,0.000892,0.000523,0.013286,12.694633,0.646695,0.132857,-395.880463,0.014058,0.000000
10.470000,2.919777,-395.835999,0.000901,0.000539,0.013685,12.987817,0.661631,0.136847,-395.835999,0.014526,0.000000
10.750001,3.021431,-395.835999,0.000927,0.000556,0.014110,13.439996,0.684666,0.141097,-395.835999,0.014994,0.000000
11.030001,3.136124,-395.880463,0.000944,0.000575,0.014595,13.950174,0.710656,0.145953,-395.880463,0.015454,0.000000
11.310000,3.241135,-395.969421,0.000961,0.000593,0.015064,14.417287,0.734452,0.150639,-395.969421,0.015922,0.000000
11.590000,3.349121,-395.880463,0.000987,0.000614,0.015601,14.897635,0.758922,0.156013,-395.880463,0.016390,0.000000
11.870001,3.423599,-395.880463,0.000992,0.000629,0.015974,15.228930,0.775799,0.159741,-395.880463,0.016859,0.000000
12.150001,3.480194,-395.880463,0.001026,0.000645,0.016390,15.480677,0.788623,0.163905,-395.880463,0.017327,0.000000
12.430000,3.668617,-395.924957,0.001026,0.000665,0.016894,16.318825,0.831321,0.168935,-395.924957,0.017787,0.000000
12.710001,3.806023,-395.969421,0.001039,0.000683,0.017336,16.930035,0.862457,0.173360,-395.969421,0.018255,0.000000
12.990001,3.814957,-395.924957,0.001074,0.000699,0.017752,16.969774,0.864482,0.177519,-395.924957,0.018723,0.000000
13.270000,4.097588,-395.969421,0.001095,0.000725,0.018411,18.226980,0.928527,0.184112,-395.969421,0.019192,0.000000
13.550000,4.131477,-395.924957,0.001108,0.000743,0.018879,18.377729,0.936206,0.188794,-395.924957,0.019660,0.000000
13.830001,4.157539,-395.924957,0.001138,0.000759,0.019278,18.493658,0.942112,0.192784,-395.924957,0.020128,0.000000
14.110001,4.322502,-395.969421,0.001130,0.000778,0.019773,19.227449,0.979493,0.197727,-395.969421,0.020588,0.000000
14.390000,4.420807,-396.013916,0.001155,0.000796,0.020224,19.664732,1.001769,0.202238,-396.013916,0.021056,0.000000
14.670001,4.490440,-395.924957,0.001181,0.000809,0.020553,19.974476,1.017548,0.205531,-395.924957,0.021525,0.000000
14.950001,4.679237,-395.924957,0.001190,0.000831,0.021100,20.814287,1.060330,0.210997,-395.924957,0.021993,0.000000
15.230000,4.861328,-396.013916,0.001207,0.000853,0.021663,21.624268,1.101593,0.216632,-396.013916,0.022461,0.000000
15.510001,4.891487,-396.013916,0.001220,0.000870,0.022106,21.758421,1.108427,0.221057,-396.013916,0.022921,0.000000
15.790001,4.931702,-396.013916,0.001242,0.000885,0.022478,21.937305,1.117540,0.224785,-396.013916,0.023389,0.000000
16.070002,5.137253,-395.969421,0.001268,0.000908,0.023051,22.851643,1.164118,0.230508,-395.969421,0.023857,0.000000
16.350000,5.212105,-396.013916,0.001285,0.000925,0.023493,23.184601,1.181080,0.234932,-396.013916,0.024326,0.000000
16.630001,5.202789,-396.013916,0.001302,0.000936,0.023779,23.143162,1.178969,0.237794,-396.013916,0.024794,0.000000
16.910002,5.545006,-396.102875,0.001298,0.000962,0.024447,24.665419,1.256516,0.244470,-396.102875,0.025254,0.000000
17.190001,5.608681,-396.058380,0.001337,0.000982,0.024933,24.948658,1.270945,0.249326,-396.058380,0.025722,0.000000
17.470001,5.689484,-396.013916,0.001345,0.000999,0.025366,25.308086,1.289255,0.253664,-396.013916,0.026190,0.000000
17.750000,5.772896,-396.013916,0.001367,0.001016,0.025800,25.679123,1.308157,0.258001,-396.013916,0.026659,0.000000
18.030001,5.948654,-396.013916,0.001401,0.001036,0.026320,26.460936,1.347984,0.263202,-396.013916,0.027127,0.000000
18.310001,5.980675,-396.058380,0.001388,0.001052,0.026728,26.603371,1.355240,0.267278,-396.058380,0.027595,0.000000
18.590000,6.060738,-396.102875,0.001423,0.001068,0.027127,26.959507,1.373383,0.271267,-396.102875,0.028055,0.000000
18.870001,6.401085,-396.102875,0.001440,0.001093,0.027760,28.473448,1.450507,0.277599,-396.102875,0.028523,0.000000
19.150002,6.408531,-396.102875,0.001457,0.001111,0.028211,28.506571,1.452194,0.282107,-396.102875,0.028991,0.000000
19.430000,6.445770,-396.102875,0.001466,0.001128,0.028644,28.672218,1.460632,0.286445,-396.102875,0.029460,0.000000
19.710001,6.553017,-396.147339,0.001492,0.001145,0.029095,29.149275,1.484935,0.290952,-396.147339,0.029928,0.000000
19.990002,6.688560,-396.058380,0.001492,0.001163,0.029546,29.752203,1.515649,0.295464,-396.058380,0.030387,0.000000
20.270000,6.743668,-396.058380,0.001513,0.001179,0.029954,29.997332,1.528137,0.299540,-396.058380,0.030856,0.000000
20.550001,6.853516,-396.102875,0.001531,0.001195,0.030362,30.485960,1.553029,0.303617,-396.102875,0.031324,0.000000
20.830002,7.176735,-396.191833,0.001561,0.001220,0.030977,31.923712,1.626271,0.309775,-396.191833,0.031792,0.000000
21.110001,7.269829,-396.147339,0.001565,0.001240,0.031506,32.337814,1.647367,0.315062,-396.147339,0.032261,0.000000
21.390001,7.250465,-396.147339,0.001578,0.001256,0.031905,32.251682,1.642979,0.319052,-396.147339,0.032729,0.000000
21.670000,7.336113,-396.147339,0.001591,0.001273,0.032330,32.632660,1.662387,0.323302,-396.147339,0.033189,0.000000
21.950001,7.393089,-396.147339,0.001608,0.001288,0.032712,32.886105,1.675298,0.327117,-396.147339,0.033657,0.000000
22.230001,7.518951,-396.191833,0.001638,0.001305,0.033154,33.445965,1.703819,0.331542,-396.191833,0.034125,0.000000
22.510000,7.743858,-396.191833,0.001651,0.001325,0.033648,34.446404,1.754783,0.336485,-396.191833,0.034594,0.000000
22.790001,8.006012,-396.102875,0.001656,0.001349,0.034256,35.612518,1.814188,0.342556,-396.102875,0.035062,0.000000
23.070002,8.017555,-396.147339,0.001690,0.001367,0.034715,35.663868,1.816804,0.347151,-396.147339,0.035522,0.000000
23.350000,7.971756,-396.147339,0.001699,0.001382,0.035105,35.460140,1.806426,0.351053,-396.147339,0.035990,0.000000
23.630001,8.000427,-396.191833,0.001716,0.001397,0.035478,35.587677,1.812923,0.354781,-396.191833,0.036458,0.000000
23.910002,8.344124,-396.236298,0.001725,0.001421,0.036094,37.116516,1.890805,0.360939,-396.236298,0.036927,0.000000
24.190001,8.273003,-396.236298,0.001733,0.001432,0.036380,36.800152,1.874689,0.363800,-396.236298,0.037395,0.000000
24.470001,8.493446,-396.147339,0.001768,0.001452,0.036883,37.780735,1.924642,0.368830,-396.147339,0.037854,0.000000
24.750002,8.789108,-396.147339,0.001763,0.001477,0.037508,39.095905,1.991640,0.375076,-396.147339,0.038323,0.000000
25.030001,8.846085,-396.147339,0.001781,0.001496,0.037993,39.349350,2.004551,0.379932,-396.147339,0.038791,0.000000
25.310001,8.805496,-396.280792,0.001815,0.001512,0.038401,39.168804,1.995354,0.384008,-396.280792,0.039259,0.000000
25.590002,8.751503,-396.191833,0.001819,0.001524,0.038713,38.928631,1.983119,0.387130,-396.191833,0.039728,0.000000
25.870001,9.054985,-396.236298,0.001832,0.001547,0.039303,40.278584,2.051889,0.393027,-396.236298,0.040196,0.000000
26.150002,9.238190,-396.191833,0.001858,0.001564,0.039728,41.093521,2.093404,0.397278,-396.191833,0.040655,0.000000
26.430000,9.308197,-396.280792,0.001867,0.001582,0.040187,41.404930,2.109268,0.401873,-396.280792,0.041124,0.000000
26.710001,9.667534,-396.280792,0.001897,0.001609,0.040864,43.003338,2.190695,0.408636,-396.280792,0.041592,0.000000
26.990002,9.681313,-396.280792,0.001893,0.001627,0.041332,43.064629,2.193817,0.413318,-396.280792,0.042060,0.000000
27.270000,9.506676,-396.280792,0.001919,0.001640,0.041653,42.287807,2.154244,0.416528,-396.280792,0.042529,0.000000
27.550001,9.691368,-396.280792,0.001936,0.001658,0.042104,43.109360,2.196095,0.421039,-396.280792,0.042988,0.000000
27.830002,9.997459,-396.280792,0.001949,0.001681,0.042685,44.470921,2.265457,0.426849,-396.280792,0.043457,0.000000
28.110001,9.934158,-396.325287,0.001962,0.001693,0.043006,44.189342,2.251112,0.430059,-396.325287,0.043925,0.000000
28.390001,10.031349,-396.280792,0.001979,0.001713,0.043500,44.621670,2.273136,0.435002,-396.280792,0.044393,0.000000
28.670002,10.442818,-396.236298,0.001983,0.001738,0.044142,46.451973,2.366376,0.441417,-396.236298,0.044862,0.000000
28.950001,10.411537,-396.236298,0.002005,0.001754,0.044549,46.312832,2.359288,0.445493,-396.236298,0.045330,0.000000
29.230001,10.409302,-396.280792,0.002026,0.001769,0.044931,46.302887,2.358782,0.449309,-396.280792,0.045790,0.000000
29.510002,10.606285,-396.280792,0.002048,0.001789,0.045451,47.179111,2.403419,0.454513,-396.280792,0.046258,0.000000
29.790001,10.812958,-396.325287,0.002061,0.001810,0.045963,48.098438,2.450251,0.459630,-396.325287,0.046726,0.000000
30.070002,10.764175,-396.325287,0.002078,0.001821,0.046258,47.881443,2.439197,0.462579,-396.325287,0.047194,0.000000
30.350002,10.845352,-396.280792,0.002087,0.001838,0.046692,48.242535,2.457592,0.466916,-396.280792,0.047663,0.000000
30.630001,11.162613,-396.325287,0.002108,0.001861,0.047281,49.653782,2.529484,0.472813,-396.325287,0.048122,0.000000
30.910002,11.137291,-396.325287,0.002117,0.001876,0.047654,49.541145,2.523746,0.476541,-396.325287,0.048590,0.000000
31.190001,11.178627,-396.325287,0.002121,0.001894,0.048114,49.725018,2.533113,0.481136,-396.325287,0.049059,0.000000
31.470001,11.396088,-396.325287,0.002147,0.001915,0.048634,50.692329,2.582390,0.486340,-396.325287,0.049527,0.000000
31.750002,11.693985,-396.280792,0.002169,0.001937,0.049189,52.017445,2.649895,0.491889,-396.280792,0.049995,0.000000
32.030003,11.667175,-396.369751,0.002182,0.001951,0.049553,51.898190,2.643820,0.495534,-396.369751,0.050464,0.000000
32.310001,11.631432,-396.414246,0.002199,0.001967,0.049952,51.739193,2.635720,0.499523,-396.414246,0.050923,0.000000
32.590000,12.017578,-396.369751,0.002199,0.001989,0.050533,53.456856,2.723222,0.505333,-396.369751,0.051392,0.000000
32.870003,12.017578,-396.325287,0.002225,0.002006,0.050958,53.456856,2.723222,0.509583,-396.325287,0.051860,0.000000
33.150002,12.146797,-396.325287,0.002233,0.002027,0.051478,54.031651,2.752503,0.514784,-396.325287,0.052328,0.000000
33.430000,12.192223,-396.414246,0.002255,0.002041,0.051843,54.233715,2.762797,0.518428,-396.414246,0.052797,0.000000
33.710003,12.466286,-396.458710,0.002276,0.002063,0.052398,55.452808,2.824901,0.523977,-396.458710,0.053257,0.000000
33.990002,12.528847,-396.458710,0.002285,0.002080,0.052840,55.731094,2.839077,0.528402,-396.458710,0.053725,0.000000
34.270000,12.401497,-396.369751,0.002294,0.002095,0.053204,55.164612,2.810219,0.532043,-396.369751,0.054193,0.000000
34.550003,12.930267,-396.369751,0.002311,0.002119,0.053829,57.516701,2.930041,0.538288,-396.369751,0.054661,0.000000
34.830002,12.976814,-396.369751,0.002333,0.002140,0.054358,57.723751,2.940588,0.543575,-396.369751,0.055130,0.000000
35.110001,12.890793,-396.458710,0.002350,0.002153,0.054696,57.341110,2.921095,0.546959,-396.458710,0.055589,0.000000
35.390003,13.104904,-396.503204,0.002367,0.002175,0.055242,58.293526,2.969614,0.552424,-396.503204,0.056057,0.000000
35.670002,13.168213,-396.414246,0.002367,0.002193,0.055702,58.575138,2.983960,0.557019,-396.414246,0.056526,0.000000
35.950001,13.214012,-396.458710,0.002393,0.002208,0.056075,58.778862,2.994338,0.560747,-396.458710,0.056994,0.000000
36.230003,13.481750,-396.503204,0.002406,0.002228,0.056595,59.969822,3.055008,0.565952,-396.503204,0.057462,0.000000
36.510002,13.646339,-396.458710,0.002423,0.002250,0.057150,60.701950,3.092305,0.571500,-396.458710,0.057931,0.000000
36.790001,13.780762,-396.503204,0.002436,0.002268,0.057610,61.299889,3.122765,0.576099,-396.503204,0.058390,0.000000
37.070004,13.710754,-396.369751,0.002445,0.002283,0.057991,60.988483,3.106901,0.579914,-396.369751,0.058859,0.000000
37.350002,13.837738,-396.414246,0.002449,0.002301,0.058442,61.553333,3.135676,0.584422,-396.414246,0.059327,0.000000
37.630001,13.951309,-396.503204,0.002479,0.002320,0.058928,62.058521,3.161412,0.589282,-396.503204,0.059795,0.000000
37.910004,13.943489,-396.547668,0.002483,0.002334,0.059292,62.023739,3.159640,0.592923,-396.547668,0.060263,0.000000
38.190002,14.311394,-396.503204,0.002483,0.002357,0.059856,63.660259,3.243008,0.598558,-396.503204,0.060723,0.000000
38.470001,14.513596,-396.547668,0.002518,0.002377,0.060368,64.559700,3.288828,0.603676,-396.547668,0.061192,0.000000
38.750000,14.424599,-396.503204,0.002522,0.002393,0.060793,64.163818,3.268661,0.607926,-396.503204,0.061660,0.000000
39.030003,14.523277,-396.458710,0.002539,0.002411,0.061235,64.602760,3.291022,0.612347,-396.458710,0.062128,0.000000
39.310001,14.818565,-396.547668,0.002557,0.002434,0.061816,65.916267,3.357935,0.618157,-396.547668,0.062596,0.000000
39.590000,14.747070,-396.547668,0.002574,0.002449,0.062206,65.598244,3.341734,0.622063,-396.547668,0.063065,0.000000
39.870003,14.761597,-396.547668,0.002591,0.002465,0.062622,65.662865,3.345026,0.626222,-396.547668,0.063524,0.000000
40.150002,14.952995,-396.503204,0.002613,0.002486,0.063151,66.514244,3.388397,0.631514,-396.503204,0.063993,0.000000
40.430000,15.332069,-396.547668,0.002621,0.002506,0.063663,68.200447,3.474297,0.636631,-396.547668,0.064461,0.000000
40.710003,15.265785,-396.547668,0.002630,0.002524,0.064105,67.905602,3.459276,0.641051,-396.547668,0.064929,0.000000
40.990002,15.358131,-396.636627,0.002656,0.002542,0.064565,68.316383,3.480202,0.645650,-396.636627,0.065397,0.000000
41.270000,15.442665,-396.636627,0.002652,0.002560,0.065024,68.692406,3.499358,0.650245,-396.636627,0.065857,0.000000
41.550003,15.335419,-396.547668,0.002673,0.002574,0.065389,68.215347,3.475055,0.653890,-396.547668,0.066325,0.000000
41.830002,15.450485,-396.592163,0.002677,0.002590,0.065779,68.727188,3.501130,0.657792,-396.592163,0.066794,0.000000
42.110001,15.893234,-396.636627,0.002703,0.002613,0.066360,70.696640,3.601458,0.663602,-396.636627,0.067262,0.000000
42.390003,16.147934,-396.636627,0.002708,0.002635,0.066924,71.829597,3.659174,0.669238,-396.636627,0.067730,0.000000
42.670002,16.121124,-396.636627,0.002729,0.002652,0.067349,71.710342,3.653099,0.673488,-396.636627,0.068190,0.000000
42.950001,16.027290,-396.636627,0.002751,0.002667,0.067730,71.292946,3.631836,0.677303,-396.636627,0.068658,0.000000
43.230003,16.042923,-396.592163,0.002755,0.002683,0.068147,71.362488,3.635378,0.681467,-396.592163,0.069127,0.000000
43.510002,16.132294,-396.592163,0.002768,0.002700,0.068589,71.760025,3.655630,0.685887,-396.592163,0.069595,0.000000
43.790001,16.433914,-396.636627,0.002777,0.002721,0.069109,73.101700,3.723978,0.691092,-396.636627,0.070063,0.000000
44.070004,16.799591,-396.681122,0.002802,0.002744,0.069690,74.728310,3.806842,0.696901,-396.681122,0.070532,0.000000
44.350002,16.896034,-396.681122,0.002815,0.002763,0.070176,75.157310,3.828696,0.701757,-396.681122,0.070991,0.000000
44.630001,16.734047,-396.592163,0.002833,0.002778,0.070566,74.436760,3.791989,0.705660,-396.592163,0.071460,0.000000
44.910004,16.696442,-396.681122,0.002841,0.002795,0.070982,74.269485,3.783468,0.709823,-396.681122,0.071928,0.000000
45.190002,16.825653,-396.725616,0.002854,0.002815,0.071494,74.844246,3.812747,0.714940,-396.725616,0.072396,0.000000
45.470001,16.920609,-396.681122,0.002854,0.002829,0.071867,75.266624,3.834265,0.718668,-396.681122,0.072864,0.000000
45.750004,17.147011,-396.681122,0.002876,0.002848,0.072344,76.273712,3.885568,0.723441,-396.681122,0.073324,0.000000
46.030003,17.502625,-396.592163,0.002897,0.002871,0.072925,77.855560,3.966151,0.729251,-396.592163,0.073792,0.000000
46.310001,17.672432,-396.725616,0.002923,0.002891,0.073437,78.610901,4.004630,0.734368,-396.725616,0.074260,0.000000
46.590004,17.508583,-396.681122,0.002923,0.002907,0.073844,77.882065,3.967502,0.738444,-396.681122,0.074729,0.000000
46.870003,17.341019,-396.636627,0.002923,0.002921,0.074182,77.136703,3.929531,0.741824,-396.636627,0.075197,0.000000
47.150002,17.412888,-396.725616,0.002940,0.002936,0.074581,77.456390,3.945817,0.745814,-396.725616,0.075665,0.000000
47.430004,17.912979,-396.725616,0.002949,0.002961,0.075206,79.680908,4.059139,0.752059,-396.725616,0.076125,0.000000
47.710003,18.073845,-396.725616,0.002988,0.002979,0.075665,80.396477,4.095592,0.756653,-396.725616,0.076593,0.000000
47.990002,18.546013,-396.814575,0.002984,0.003005,0.076325,82.496788,4.202586,0.763247,-396.814575,0.077062,0.000000
48.270000,18.469307,-396.725616,0.003014,0.003023,0.076784,82.155579,4.185205,0.767842,-396.725616,0.077530,0.000000
48.550003,18.142365,-396.681122,0.003018,0.003036,0.077123,80.701271,4.111119,0.771225,-396.681122,0.077998,0.000000
48.830002,18.350891,-396.681122,0.003031,0.003055,0.077599,81.628838,4.158371,0.775994,-396.681122,0.078458,0.000000
49.110001,18.672623,-396.725616,0.003048,0.003077,0.078146,83.059975,4.231277,0.781456,-396.725616,0.078926,0.000000
49.390003,18.538193,-396.770081,0.003065,0.003091,0.078519,82.461998,4.200815,0.785188,-396.770081,0.079395,0.000000
49.670002,18.526276,-396.725616,0.003061,0.003107,0.078918,82.408989,4.198114,0.789177,-396.725616,0.079863,0.000000
49.950001,19.171974,-396.725616,0.003070,0.003134,0.079603,85.281204,4.344431,0.796028,-396.725616,0.080331,0.000000
50.230003,19.119469,-396.725616,0.003083,0.003151,0.080045,85.047646,4.332533,0.800449,-396.725616,0.080791,0.000000
50.510002,18.930672,-396.770081,0.003096,0.003167,0.080444,84.207832,4.289752,0.804438,-396.770081,0.081259,0.000000
50.790001,19.052811,-396.814575,0.003104,0.003184,0.080886,84.751137,4.317429,0.808862,-396.814575,0.081727,0.000000
51.070004,19.196922,-396.814575,0.003117,0.003201,0.081294,85.392174,4.350085,0.812939,-396.814575,0.082196,0.000000
51.350002,19.431885,-396.814575,0.003139,0.003219,0.081771,86.437340,4.403328,0.817708,-396.814575,0.082664,0.000000
51.630001,19.415131,-396.814575,0.003156,0.003235,0.082178,86.362816,4.399532,0.821784,-396.814575,0.083132,0.000000
51.910004,19.748779,-396.859039,0.003169,0.003257,0.082716,87.846954,4.475138,0.827159,-396.859039,0.083592,0.000000
52.190002,19.567429,-396.814575,0.003178,0.003270,0.083054,87.040268,4.434043,0.830542,-396.814575,0.084060,0.000000
52.470001,19.945015,-396.814575,0.003186,0.003291,0.083583,88.719856,4.519605,0.835833,-396.814575,0.084528,0.000000
52.750004,19.870918,-396.859039,0.003195,0.003308,0.084025,88.390259,4.502814,0.840254,-396.859039,0.084997,0.000000
53.030003,20.533737,-396.814575,0.003216,0.003333,0.084659,91.338623,4.653011,0.846586,-396.814575,0.085465,0.000000
53.310001,20.433571,-396.814575,0.003225,0.003349,0.085058,90.893066,4.630313,0.850576,-396.814575,0.085925,0.000000
53.590004,20.242172,-396.814575,0.003242,0.003363,0.085413,90.041679,4.586942,0.854130,-396.814575,0.086393,0.000000
53.870003,20.720673,-396.903534,0.003260,0.003386,0.086003,92.170158,4.695372,0.860027,-396.903534,0.086861,0.000000
54.150002,20.681198,-396.903534,0.003260,0.003402,0.086402,91.994560,4.686427,0.864016,-396.903534,0.087330,0.000000
54.430004,20.705772,-396.859039,0.003272,0.003421,0.086887,92.103874,4.691995,0.868872,-396.859039,0.087798,0.000000
54.710003,20.931435,-396.859039,0.003281,0.003439,0.087347,93.107674,4.743131,0.873470,-396.859039,0.088266,0.000000
54.990002,21.012611,-396.859039,0.003316,0.003459,0.087850,93.468765,4.761526,0.878501,-396.859039,0.088726,0.000000
55.270004,21.223373,-396.859039,0.003311,0.003476,0.088301,94.406281,4.809285,0.883008,-396.859039,0.089194,0.000000
55.550003,20.694977,-396.903534,0.003341,0.003488,0.088604,92.055855,4.689549,0.886044,-396.903534,0.089662,0.000000
55.830002,21.500420,-396.947998,0.003333,0.003513,0.089229,95.638641,4.872065,0.892289,-396.947998,0.090131,0.000000
56.110004,21.681015,-396.859039,0.003354,0.003534,0.089758,96.441971,4.912988,0.897580,-396.859039,0.090599,0.000000
56.390003,21.698517,-396.992493,0.003367,0.003550,0.090165,96.519821,4.916955,0.901653,-396.992493,0.091059,0.000000
56.670002,21.796082,-396.903534,0.003372,0.003568,0.090625,96.953812,4.939063,0.906251,-396.903534,0.091527,0.000000
56.950005,21.963646,-396.947998,0.003402,0.003588,0.091137,97.699173,4.977033,0.911369,-396.947998,0.091995,0.000000
57.230003,21.911888,-396.903534,0.003410,0.003605,0.091570,97.468948,4.965305,0.915702,-396.903534,0.092463,0.000000
57.510002,22.322990,-396.992493,0.003428,0.003626,0.092091,99.297623,5.058462,0.920907,-396.992493,0.092932,0.000000
57.790001,22.369904,-396.992493,0.003436,0.003644,0.092559,99.506302,5.069093,0.925588,-396.992493,0.093392,0.000000
58.070004,22.596306,-396.992493,0.003449,0.003665,0.093079,100.513390,5.120396,0.930793,-396.992493,0.093860,0.000000
58.350002,22.559448,-396.992493,0.003462,0.003681,0.093487,100.349434,5.112044,0.934869,-396.992493,0.094328,0.000000
58.630001,22.662964,-396.992493,0.003475,0.003699,0.093946,100.809898,5.135501,0.939464,-396.992493,0.094796,0.000000
58.910004,22.589607,-396.947998,0.003484,0.003713,0.094320,100.483589,5.118878,0.943196,-396.947998,0.095265,0.000000
59.190002,22.612320,-396.992493,0.003488,0.003732,0.094788,100.584625,5.124025,0.947878,-396.992493,0.095733,0.000000
59.470001,22.811913,-396.992493,0.003510,0.003751,0.095273,101.472458,5.169253,0.952734,-396.992493,0.096193,0.000000
59.750004,23.390205,-396.992493,0.003527,0.003772,0.095803,104.044830,5.300296,0.958025,-396.992493,0.096661,0.000000
60.030003,23.498566,-396.992493,0.003523,0.003789,0.096253,104.526840,5.324851,0.962533,-396.992493,0.097129,0.000000
60.310001,23.578629,-396.947998,0.003557,0.003808,0.096730,104.882980,5.342993,0.967302,-396.947998,0.097598,0.000000
60.590004,23.836685,-396.992493,0.003561,0.003829,0.097259,106.030869,5.401470,0.972593,-396.992493,0.098066,0.000000
60.870003,23.943550,-397.036957,0.003574,0.003846,0.097684,106.506233,5.425686,0.976844,-397.036957,0.098525,0.000000
61.150002,23.889183,-397.036957,0.003587,0.003862,0.098083,106.264397,5.413366,0.980833,-397.036957,0.098994,0.000000
61.430004,23.536552,-397.036957,0.003591,0.003879,0.098525,104.695816,5.333459,0.985254,-397.036957,0.099462,0.000000
61.710003,24.726654,-396.992493,0.003604,0.003904,0.099159,109.989647,5.603140,0.991586,-396.992493,0.099930,0.000000
61.990002,24.600418,-397.081451,0.003617,0.003921,0.099601,109.428123,5.574534,0.996010,-397.081451,0.100399,0.000000
62.270004,24.456306,-397.081451,0.003643,0.003936,0.099965,108.787086,5.541878,0.999651,-397.081451,0.100867,0.000000
62.550003,24.600044,-397.081451,0.003660,0.003954,0.100442,109.426460,5.574450,1.004420,-397.081451,0.101327,0.000000
62.830002,24.672287,-397.036957,0.003639,0.003969,0.100806,109.747810,5.590820,1.008061,-397.036957,0.101795,0.000000
63.110004,24.572861,-397.036957,0.003660,0.003983,0.101162,109.305542,5.568290,1.011619,-397.036957,0.102263,0.000000
63.390003,25.342926,-397.036957,0.003686,0.004009,0.101821,112.730965,5.742789,1.018209,-397.036957,0.102732,0.000000
63.670002,25.727219,-397.125946,0.003708,0.004030,0.102359,114.440384,5.829871,1.023587,-397.125946,0.103200,0.000000
63.950005,25.873558,-397.170410,0.003695,0.004048,0.102827,115.091331,5.863032,1.028269,-397.170410,0.103660,0.000000
64.230003,25.782326,-397.125946,0.003721,0.004064,0.103226,114.685516,5.842358,1.032258,-397.125946,0.104128,0.000000
64.510002,25.666519,-397.125946,0.003717,0.004079,0.103599,114.170380,5.816116,1.035986,-397.125946,0.104596,0.000000
64.790001,25.766319,-397.081451,0.003738,0.004096,0.104041,114.614311,5.838731,1.040411,-397.081451,0.105065,0.000000
65.070000,26.029213,-397.125946,0.003747,0.004115,0.104509,115.783722,5.898304,1.045093,-397.125946,0.105533,0.000000
65.350006,26.695389,-397.125946,0.003768,0.004137,0.105082,118.747017,6.049262,1.050816,-397.125946,0.106001,0.000000
65.630005,27.221924,-397.125946,0.003781,0.004159,0.105646,121.089165,6.168576,1.056455,-397.125946,0.106461,0.000000
65.910004,27.133667,-397.125946,0.003786,0.004176,0.106071,120.696579,6.148577,1.060705,-397.125946,0.106929,0.000000
66.190002,26.925140,-397.170410,0.003794,0.004192,0.106487,119.769005,6.101324,1.064865,-397.170410,0.107397,0.000000
66.470001,26.877472,-397.214905,0.003816,0.004207,0.106860,119.556969,6.090522,1.068597,-397.214905,0.107865,0.000000
66.750000,27.000732,-397.214905,0.003807,0.004223,0.107267,120.105255,6.118453,1.072670,-397.214905,0.108334,0.000000
67.030006,27.129570,-397.259369,0.003803,0.004240,0.107701,120.678352,6.147648,1.077007,-397.259369,0.108793,0.000000
67.310005,27.952141,-397.170410,0.003842,0.004264,0.108317,124.337334,6.334045,1.083165,-397.170410,0.109262,0.000000
67.590004,28.718109,-397.170410,0.003859,0.004288,0.108915,127.744530,6.507617,1.089149,-397.170410,0.109730,0.000000
67.870003,28.385208,-397.170410,0.003867,0.004304,0.109314,126.263710,6.432180,1.093138,-397.170410,0.110198,0.000000
68.150002,28.417984,-397.303864,0.003885,0.004318,0.109678,126.409508,6.439608,1.096779,-397.303864,0.110667,0.000000
68.430000,28.376648,-397.170410,0.003889,0.004333,0.110068,126.225632,6.430240,1.100682,-397.170410,0.111126,0.000000
68.710007,28.779182,-397.214905,0.003889,0.004353,0.110554,128.016190,6.521456,1.105538,-397.214905,0.111595,0.000000
68.990005,29.378326,-397.214905,0.003911,0.004375,0.111118,130.681320,6.657224,1.111177,-397.214905,0.112063,0.000000
69.270004,29.867256,-397.170410,0.003945,0.004399,0.111734,132.856186,6.768017,1.117335,-397.170410,0.112531,0.000000
69.550003,30.188614,-397.214905,0.003936,0.004418,0.112210,134.285660,6.840838,1.122104,-397.214905,0.113000,0.000000
69.830002,29.994606,-397.259369,0.003954,0.004432,0.112575,133.422668,6.796875,1.125745,-397.259369,0.113468,0.000000
70.110001,30.019554,-397.214905,0.003962,0.004450,0.113034,133.533646,6.802528,1.130344,-397.214905,0.113928,0.000000
70.390007,29.912682,-397.214905,0.003988,0.004464,0.113381,133.058258,6.778310,1.133811,-397.214905,0.114396,0.000000
70.670006,30.881966,-397.214905,0.003984,0.004487,0.113979,137.369843,6.997953,1.139795,-397.214905,0.114864,0.000000
70.950005,30.868561,-397.214905,0.003992,0.004502,0.114352,137.310211,6.994916,1.143523,-397.214905,0.115332,0.000000
71.230003,31.679588,-397.303864,0.004014,0.004528,0.115020,140.917847,7.178698,1.150203,-397.303864,0.115801,0.000000
71.510002,31.961853,-397.303864,0.004040,0.004547,0.115488,142.173416,7.242659,1.154885,-397.303864,0.116260,0.000000
71.790001,31.851257,-397.259369,0.004036,0.004561,0.115861,141.681473,7.217598,1.158613,-397.259369,0.116728,0.000000
72.070000,31.518356,-397.259369,0.004040,0.004574,0.116182,140.200653,7.142162,1.161823,-397.259369,0.117197,0.000000
72.350006,32.118988,-397.348328,0.004053,0.004597,0.116763,142.872391,7.278267,1.167633,-397.348328,0.117665,0.000000
72.630005,32.961670,-397.303864,0.004079,0.004617,0.117284,146.620834,7.469221,1.172837,-397.303864,0.118133,0.000000
72.910004,32.864853,-397.303864,0.004074,0.004631,0.117630,146.190170,7.447282,1.176304,-397.303864,0.118602,0.000000
73.190002,33.391014,-397.259369,0.004092,0.004652,0.118168,148.530655,7.566512,1.181682,-397.259369,0.119061,0.000000
73.470001,33.525810,-397.303864,0.004118,0.004667,0.118541,149.130249,7.597057,1.185410,-397.303864,0.119530,0.000000
73.750000,34.123474,-397.303864,0.004113,0.004689,0.119096,151.788788,7.732490,1.190963,-397.303864,0.119998,0.000000
74.030006,34.091820,-397.392822,0.004122,0.004701,0.119417,151.647995,7.725317,1.194168,-397.392822,0.120466,0.000000
74.310005,35.023499,-397.303864,0.004148,0.004727,0.120067,155.792297,7.936439,1.200675,-397.303864,0.120935,0.000000
74.590004,35.104301,-397.392822,0.004152,0.004743,0.120475,156.151733,7.954748,1.204751,-397.392822,0.121394,0.000000
74.870003,35.031319,-397.392822,0.004165,0.004755,0.120787,155.827087,7.938210,1.207874,-397.392822,0.121863,0.000000
75.150002,36.038582,-397.259369,0.004169,0.004779,0.121394,160.307617,8.166459,1.213941,-397.259369,0.122331,0.000000
75.430000,36.663795,-397.437286,0.004178,0.004800,0.121914,163.088715,8.308134,1.219145,-397.437286,0.122799,0.000000
75.710007,36.881638,-397.392822,0.004195,0.004816,0.122331,164.057724,8.357498,1.223308,-397.392822,0.123268,0.000000
75.990005,37.250656,-397.392822,0.004199,0.004837,0.122860,165.699188,8.441119,1.228600,-397.392822,0.123727,0.000000
76.270004,37.637550,-397.348328,0.004230,0.004853,0.123276,167.420181,8.528790,1.232763,-397.348328,0.124195,0.000000
76.550003,38.404266,-397.392822,0.004225,0.004873,0.123779,170.830704,8.702531,1.237789,-397.392822,0.124664,0.000000
76.830002,38.008064,-397.481781,0.004234,0.004880,0.123961,169.068314,8.612751,1.239614,-397.481781,0.125132,0.000000
77.110001,39.170235,-397.437286,0.004260,0.004908,0.124655,174.237900,8.876101,1.246551,-397.437286,0.125600,0.000000
77.390007,40.087013,-397.392822,0.004264,0.004928,0.125175,178.315933,9.083847,1.251752,-397.392822,0.126068,0.000000
77.670006,40.497002,-397.437286,0.004268,0.004947,0.125661,180.139664,9.176751,1.256612,-397.437286,0.126528,0.000000
77.950005,41.114395,-397.392822,0.004277,0.004966,0.126138,182.885971,9.316655,1.261381,-397.392822,0.126996,0.000000
78.230003,41.652473,-397.481781,0.004290,0.004983,0.126580,185.279449,9.438585,1.265801,-397.481781,0.127465,0.000000
78.510002,42.095963,-397.526245,0.004299,0.005001,0.127023,187.252197,9.539081,1.270226,-397.526245,0.127933,0.000000
78.790001,42.641861,-397.437286,0.004320,0.005022,0.127569,189.680466,9.662784,1.275687,-397.437286,0.128401,0.000000
79.070007,43.632378,-397.481781,0.004312,0.005039,0.128002,194.086502,9.887239,1.280025,-397.481781,0.128861,0.000000
79.350006,44.324989,-397.481781,0.004346,0.005061,0.128540,197.167404,10.044186,1.285403,-397.481781,0.129329,0.000000
79.630005,44.752846,-397.481781,0.004359,0.005074,0.128887,199.070602,10.141139,1.288870,-397.481781,0.129798,0.000000
79.910004,45.212349,-397.526245,0.004363,0.005093,0.129364,201.114578,10.245264,1.293639,-397.526245,0.130266,0.000000
80.190002,46.015182,-397.481781,0.004381,0.005112,0.129832,204.685760,10.427190,1.298325,-397.481781,0.130734,0.000000
80.470001,46.659019,-397.526245,0.004381,0.005126,0.130205,207.549683,10.573085,1.302053,-397.526245,0.131203,0.000000
80.750008,46.922661,-397.481781,0.004385,0.005142,0.130613,208.722412,10.632827,1.306129,-397.481781,0.131662,0.000000
81.030006,48.571892,-397.481781,0.004393,0.005167,0.131254,216.058563,11.006548,1.312545,-397.481781,0.132131,0.000000
81.310005,49.160988,-397.481781,0.004406,0.005185,0.131706,218.679001,11.140039,1.317056,-397.481781,0.132599,0.000000
81.590004,50.132133,-397.526245,0.004419,0.005203,0.132165,222.998871,11.360104,1.321651,-397.526245,0.133067,0.000000
81.870003,51.213875,-397.570740,0.004415,0.005224,0.132694,227.810699,11.605229,1.326943,-397.570740,0.133535,0.000000
82.150002,52.066612,-397.526245,0.004437,0.005243,0.133180,231.603851,11.798463,1.331799,-397.526245,0.133995,0.000000
82.430000,52.678795,-397.481781,0.004454,0.005258,0.133561,234.326981,11.937185,1.335614,-397.481781,0.134463,0.000000
82.710007,52.796463,-397.481781,0.004458,0.005267,0.133778,234.850403,11.963850,1.337783,-397.481781,0.134932,0.000000
82.990005,54.998299,-397.570740,0.004454,0.005301,0.134654,244.644653,12.462792,1.346541,-397.570740,0.135400,0.000000
83.270004,55.563560,-397.570740,0.004462,0.005316,0.135018,247.159058,12.590883,1.350182,-397.570740,0.135868,0.000000
83.550003,56.388367,-397.481781,0.004480,0.005331,0.135409,250.827988,12.777786,1.354088,-397.481781,0.136328,0.000000
83.830002,57.113747,-397.570740,0.004484,0.005348,0.135842,254.054626,12.942161,1.358422,-397.570740,0.136796,0.000000
84.110001,58.299377,-397.615234,0.004493,0.005367,0.136310,259.328583,13.210828,1.363103,-397.615234,0.137265,0.000000
84.390007,58.676598,-397.570740,0.004506,0.005378,0.136597,261.006531,13.296308,1.365969,-397.570740,0.137733,0.000000
84.670006,59.829834,-397.570740,0.004501,0.005398,0.137117,266.136383,13.557634,1.371169,-397.570740,0.138201,0.000000
84.950005,61.544609,-397.615234,0.004527,0.005422,0.137724,273.764099,13.946208,1.377240,-397.615234,0.138669,0.000000
85.230003,62.919403,-397.570740,0.004531,0.005442,0.138218,279.879486,14.257740,1.382183,-397.570740,0.139129,0.000000
85.510002,63.737877,-397.659698,0.004527,0.005458,0.138626,283.520233,14.443210,1.386259,-397.659698,0.139597,0.000000
85.790001,64.546303,-397.615234,0.004536,0.005474,0.139034,287.116302,14.626401,1.390336,-397.615234,0.140066,0.000000
86.070007,65.503670,-397.704193,0.004540,0.005491,0.139467,291.374878,14.843344,1.394673,-397.704193,0.140534,0.000000
86.350006,66.466255,-397.570740,0.004549,0.005506,0.139840,295.656677,15.061468,1.398401,-397.570740,0.141002,0.000000
86.630005,66.974541,-397.570740,0.004579,0.005510,0.139944,297.917633,15.176648,1.399442,-397.570740,0.140179,0.000000
86.910004,66.307625,-397.615234,0.004579,0.005508,0.139909,294.951050,15.025522,1.399094,-397.615234,0.139944,0.000000
87.190002,65.670128,-397.659698,0.004583,0.005506,0.139840,292.115326,14.881064,1.398401,-397.659698,0.139944,0.000000
87.470001,65.131676,-397.659698,0.004583,0.005505,0.139823,289.720154,14.759048,1.398227,-397.659698,0.139944,0.000000
87.750008,64.642006,-397.615234,0.004592,0.005504,0.139814,287.541992,14.648088,1.398140,-397.615234,0.139944,0.000000
88.030006,64.213768,-397.615234,0.004575,0.005504,0.139805,285.637115,14.551047,1.398053,-397.615234,0.139944,0.000000
88.310005,63.822777,-397.748657,0.004579,0.005504,0.139805,283.897888,14.462447,1.398053,-397.748657,0.139944,0.000000
88.590004,63.476097,-397.748657,0.004592,0.005504,0.139805,282.355774,14.383889,1.398053,-397.748657,0.139944,0.000000
88.870003,63.161446,-397.704193,0.004587,0.005504,0.139797,280.956146,14.312589,1.397966,-397.704193,0.139944,0.000000
89.150002,62.881050,-397.704193,0.004596,0.005504,0.139797,279.708893,14.249049,1.397966,-397.704193,0.139944,0.000000
89.430008,62.616669,-397.748657,0.004596,0.005504,0.139797,278.532867,14.189140,1.397966,-397.748657,0.139944,0.000000
89.710007,62.372017,-397.615234,0.004609,0.005504,0.139797,277.444580,14.133701,1.397966,-397.615234,0.139944,0.000000
89.990005,62.143753,-397.748657,0.004609,0.005504,0.139797,276.429230,14.081976,1.397966,-397.748657,0.139944,0.000000
90.270004,61.932991,-397.748657,0.004596,0.005504,0.139797,275.491699,14.034216,1.397966,-397.748657,0.139944,0.000000
90.550003,61.739357,-397.748657,0.004609,0.005504,0.139797,274.630371,13.990338,1.397966,-397.748657,0.139944,0.000000
90.830002,61.558014,-397.659698,0.004596,0.005504,0.139797,273.823730,13.949245,1.397966,-397.659698,0.139944,0.000000
91.110001,61.390816,-397.704193,0.004622,0.005504,0.139797,273.079987,13.911358,1.397966,-397.704193,0.139944,0.000000
91.390007,61.227715,-397.704193,0.004605,0.005504,0.139797,272.354462,13.874399,1.397966,-397.704193,0.139944,0.000000
91.670006,61.075043,-397.793152,0.004609,0.005504,0.139797,271.675354,13.839803,1.397966,-397.793152,0.139944,0.000000
91.950005,60.921257,-397.748657,0.004605,0.005504,0.139797,270.991272,13.804955,1.397966,-397.748657,0.139944,0.000000
92.230003,60.775658,-397.793152,0.004609,0.005504,0.139797,270.343628,13.771961,1.397966,-397.793152,0.139944,0.000000
92.510002,60.647934,-397.748657,0.004605,0.005503,0.139788,269.775482,13.743018,1.397883,-397.748657,0.139944,0.000000
92.790001,60.523186,-397.793152,0.004609,0.005503,0.139788,269.220581,13.714749,1.397883,-397.793152,0.139944,0.000000
93.070007,60.407753,-397.837616,0.004609,0.005503,0.139788,268.707092,13.688593,1.397883,-397.837616,0.139944,0.000000
93.350006,60.298653,-397.882111,0.004613,0.005503,0.139788,268.221802,13.663871,1.397883,-397.882111,0.139944,0.000000
93.630005,60.184700,-397.748657,0.004618,0.005503,0.139788,267.714905,13.638048,1.397883,-397.748657,0.139944,0.000000
93.910004,60.074112,-397.704193,0.004618,0.005503,0.139788,267.222992,13.612988,1.397883,-397.704193,0.139944,0.000000
94.190002,59.971703,-397.793152,0.004618,0.005503,0.139788,266.767456,13.589783,1.397883,-397.793152,0.139944,0.000000
94.470001,59.875633,-397.837616,0.004609,0.005503,0.139788,266.340118,13.568012,1.397883,-397.837616,0.139944,0.000000
94.750008,59.782539,-397.837616,0.004600,0.005503,0.139788,265.926025,13.546917,1.397883,-397.837616,0.139944,0.000000
95.030006,59.700989,-397.748657,0.004609,0.005503,0.139788,265.563263,13.528438,1.397883,-397.748657,0.139944,0.000000
95.310005,59.604919,-397.837616,0.004613,0.005503,0.139788,265.135925,13.506668,1.397883,-397.837616,0.139944,0.000000
95.590004,59.511078,-397.793152,0.004618,0.005503,0.139788,264.718506,13.485403,1.397883,-397.793152,0.139944,0.000000
95.870003,59.423576,-397.882111,0.004622,0.005503,0.139788,264.329254,13.465575,1.397883,-397.882111,0.139944,0.000000
96.150002,59.346863,-397.837616,0.004618,0.005503,0.139788,263.988037,13.448191,1.397883,-397.837616,0.139944,0.000000
96.430008,59.270157,-397.837616,0.004622,0.005503,0.139788,263.646820,13.430809,1.397883,-397.837616,0.139944,0.000000
96.710007,59.192703,-397.793152,0.004618,0.005503,0.139788,263.302307,13.413259,1.397883,-397.793152,0.139944,0.000000
96.990005,59.120087,-397.926575,0.004618,0.005503,0.139788,262.979279,13.396804,1.397883,-397.926575,0.139944,0.000000
97.270004,59.040771,-397.882111,0.004626,0.005503,0.139788,262.626465,13.378830,1.397883,-397.882111,0.139944,0.000000
97.550003,58.975983,-397.882111,0.004618,0.005503,0.139788,262.338287,13.364148,1.397883,-397.882111,0.139944,0.000000
97.830002,58.894432,-397.882111,0.004609,0.005503,0.139788,261.975525,13.345670,1.397883,-397.882111,0.139944,0.000000
98.110008,58.822937,-397.882111,0.004618,0.005503,0.139788,261.657501,13.329468,1.397883,-397.882111,0.139944,0.000000
98.390007,58.775276,-397.837616,0.004622,0.005503,0.139788,261.445496,13.318668,1.397883,-397.837616,0.139944,0.000000
98.670006,58.713463,-397.926575,0.004622,0.005503,0.139788,261.170532,13.304661,1.397883,-397.926575,0.139944,0.000000
98.950005,58.649780,-397.926575,0.004613,0.005503,0.139788,260.887238,13.290231,1.397883,-397.926575,0.139944,0.000000
99.230003,58.589828,-397.926575,0.004635,0.005503,0.139788,260.620575,13.276646,1.397883,-397.926575,0.139944,0.000000
99.510002,58.541420,-397.926575,0.004613,0.005503,0.139788,260.405243,13.265675,1.397883,-397.926575,0.139944,0.000000
99.790009,58.475143,-397.926575,0.004618,0.005503,0.139788,260.110443,13.250656,1.397883,-397.926575,0.139944,0.000000
100.070007,58.418915,-397.971069,0.004622,0.005503,0.139788,259.860321,13.237915,1.397883,-397.971069,0.139944,0.000000
100.350006,58.360451,-397.971069,0.004618,0.005503,0.139788,259.600250,13.224667,1.397883,-397.971069,0.139944,0.000000
100.630005,58.322098,-397.926575,0.004626,0.005503,0.139788,259.429657,13.215976,1.397883,-397.926575,0.139944,0.000000
100.910004,58.279648,-397.926575,0.004635,0.005503,0.139788,259.240814,13.206356,1.397883,-397.926575,0.139944,0.000000
101.190002,58.231613,-397.926575,0.004631,0.005503,0.139788,259.027161,13.195473,1.397883,-397.926575,0.139944,0.000000
101.470001,58.176498,-398.015564,0.004626,0.005503,0.139788,258.781982,13.182983,1.397883,-398.015564,0.139944,0.000000
101.750008,58.115799,-398.060028,0.004622,0.005503,0.139788,258.511993,13.169229,1.397883,-398.060028,0.139944,0.000000
102.030006,58.074471,-398.015564,0.004631,0.005503,0.139788,258.328156,13.159863,1.397883,-398.015564,0.139944,0.000000
102.310005,58.031647,-397.971069,0.004626,0.005503,0.139788,258.137665,13.150160,1.397883,-397.971069,0.139944,0.000000
102.590004,57.989197,-398.015564,0.004631,0.005503,0.139788,257.948822,13.140540,1.397883,-398.015564,0.139944,0.000000
102.870003,57.937431,-397.971069,0.004626,0.005503,0.139788,257.718567,13.128810,1.397883,-397.971069,0.139944,0.000000
103.150002,57.899826,-398.060028,0.004635,0.005503,0.139788,257.551300,13.120288,1.397883,-398.060028,0.139944,0.000000
103.430008,57.845459,-398.060028,0.004631,0.005503,0.139788,257.309448,13.107968,1.397883,-398.060028,0.139944,0.000000
103.710007,57.811943,-398.015564,0.004631,0.005503,0.139788,257.160370,13.100373,1.397883,-398.015564,0.139944,0.000000
103.990005,57.761673,-398.015564,0.004626,0.005503,0.139788,256.936768,13.088982,1.397883,-398.015564,0.139944,0.000000
104.270004,57.723320,-398.015564,0.004631,0.005503,0.139788,256.766144,13.080291,1.397883,-398.015564,0.139944,0.000000
104.550003,57.683853,-398.104523,0.004631,0.005503,0.139788,256.590607,13.071348,1.397883,-398.104523,0.139944,0.000000
104.830002,57.640656,-398.104523,0.004644,0.005503,0.139788,256.398437,13.061560,1.397883,-398.104523,0.139944,0.000000
105.110008,57.592247,-398.015564,0.004622,0.005503,0.139788,256.183105,13.050591,1.397883,-398.015564,0.139944,0.000000
105.390007,57.549049,-398.015564,0.004639,0.005503,0.139788,255.990952,13.040801,1.397883,-398.015564,0.139944,0.000000
105.670006,57.521492,-398.015564,0.004635,0.005503,0.139788,255.868378,13.034556,1.397883,-398.015564,0.139944,0.000000
105.950005,57.481277,-398.104523,0.004631,0.005503,0.139788,255.689499,13.025444,1.397883,-398.104523,0.139944,0.000000
106.230003,57.445534,-398.148987,0.004635,0.005503,0.139788,255.530502,13.017344,1.397883,-398.148987,0.139944,0.000000
106.510002,57.399727,-398.104523,0.004622,0.005503,0.139788,255.326736,13.006964,1.397883,-398.104523,0.139944,0.000000
106.790009,57.367332,-398.060028,0.004639,0.005503,0.139788,255.182632,12.999623,1.397883,-398.060028,0.139944,0.000000
107.070007,57.330467,-398.060028,0.004635,0.005503,0.139788,255.018661,12.991270,1.397883,-398.060028,0.139944,0.000000
107.350006,57.296585,-398.104523,0.004644,0.005503,0.139788,254.867935,12.983591,1.397883,-398.104523,0.139944,0.000000
107.630005,57.260834,-398.193481,0.004644,0.005503,0.139788,254.708908,12.975491,1.397883,-398.193481,0.139944,0.000000
107.910004,57.238495,-398.193481,0.004622,0.005503,0.139788,254.609543,12.970428,1.397883,-398.193481,0.139944,0.000000
108.190002,57.183380,-398.104523,0.004631,0.005503,0.139788,254.364380,12.957939,1.397883,-398.104523,0.139944,0.000000
108.470009,57.155083,-398.148987,0.004648,0.005503,0.139788,254.238510,12.951528,1.397883,-398.148987,0.139944,0.000000
108.750008,57.139069,-398.104523,0.004652,0.005503,0.139788,254.167267,12.947898,1.397883,-398.104523,0.139944,0.000000
109.030006,57.084328,-398.237946,0.004631,0.005503,0.139788,253.923767,12.935494,1.397883,-398.237946,0.139944,0.000000
109.310005,57.059380,-398.237946,0.004639,0.005503,0.139788,253.812790,12.929840,1.397883,-398.237946,0.139944,0.000000
109.590004,57.030708,-398.148987,0.004639,0.005503,0.139788,253.685257,12.923344,1.397883,-398.148987,0.139944,0.000000
109.870003,56.996452,-398.148987,0.004635,0.005503,0.139788,253.532883,12.915581,1.397883,-398.148987,0.139944,0.000000
110.150002,56.968521,-398.148987,0.004639,0.005503,0.139788,253.408646,12.909251,1.397883,-398.148987,0.139944,0.000000
110.430008,56.934639,-398.193481,0.004648,0.005503,0.139788,253.257919,12.901573,1.397883,-398.193481,0.139944,0.000000
110.710007,56.918251,-398.193481,0.004626,0.005503,0.139788,253.185028,12.897861,1.397883,-398.193481,0.139944,0.000000
110.990005,56.893677,-398.193481,0.004626,0.005503,0.139788,253.075714,12.892292,1.397883,-398.193481,0.139944,0.000000
111.270004,56.862770,-398.237946,0.004644,0.005503,0.139788,252.938232,12.885287,1.397883,-398.237946,0.139944,0.000000
111.550003,56.829628,-398.237946,0.004639,0.005503,0.139788,252.790817,12.877778,1.397883,-398.237946,0.139944,0.000000
111.830002,56.807655,-398.193481,0.004635,0.005503,0.139788,252.693069,12.872799,1.397883,-398.193481,0.139944,0.000000
112.110008,56.781593,-398.282440,0.004648,0.005503,0.139788,252.577148,12.866893,1.397883,-398.282440,0.139944,0.000000
112.390007,56.760735,-398.237946,0.004631,0.005503,0.139788,252.484360,12.862165,1.397883,-398.237946,0.139944,0.000000
112.670006,56.727966,-398.237946,0.004644,0.005503,0.139788,252.338593,12.854741,1.397883,-398.237946,0.139944,0.000000
112.950005,56.702278,-398.193481,0.004656,0.005503,0.139788,252.224335,12.848920,1.397883,-398.193481,0.139944,0.000000
113.230003,56.676582,-398.237946,0.004644,0.005503,0.139788,252.110031,12.843098,1.397883,-398.237946,0.139944,0.000000
113.510002,56.665787,-398.326904,0.004644,0.005503,0.139788,252.062012,12.840651,1.397883,-398.326904,0.139944,0.000000
113.790009,56.628548,-398.237946,0.004618,0.005503,0.139788,251.896362,12.832212,1.397883,-398.237946,0.139944,0.000000
114.070007,56.600616,-398.237946,0.004644,0.005503,0.139788,251.772110,12.825883,1.397883,-398.237946,0.139944,0.000000
114.350006,56.584976,-398.193481,0.004652,0.005503,0.139788,251.702545,12.822339,1.397883,-398.193481,0.139944,0.000000
114.630005,56.560776,-398.237946,0.004635,0.005503,0.139788,251.594894,12.816855,1.397883,-398.237946,0.139944,0.000000
114.910004,56.525024,-398.282440,0.004644,0.005503,0.139788,251.435867,12.808754,1.397883,-398.282440,0.139944,0.000000
115.190002,56.509018,-398.282440,0.004639,0.005503,0.139788,251.364670,12.805126,1.397883,-398.282440,0.139944,0.000000
115.470009,56.496727,-398.326904,0.004661,0.005503,0.139788,251.309998,12.802341,1.397883,-398.326904,0.139944,0.000000
115.750008,56.472519,-398.282440,0.004639,0.005503,0.139788,251.202316,12.796856,1.397883,-398.282440,0.139944,0.000000
116.030006,56.451668,-398.282440,0.004644,0.005503,0.139788,251.109558,12.792130,1.397883,-398.282440,0.139944,0.000000
116.310005,56.427467,-398.282440,0.004639,0.005503,0.139788,251.001907,12.786647,1.397883,-398.282440,0.139944,0.000000
116.590004,56.397301,-398.326904,0.004661,0.005503,0.139788,250.867722,12.779811,1.397883,-398.326904,0.139944,0.000000
116.870003,56.382782,-398.371399,0.004644,0.005503,0.139788,250.803146,12.776521,1.397883,-398.371399,0.139944,0.000000
117.000008,56.373100,-398.282440,0.004639,0.005503,0.139788,250.760071,12.774326,1.397883,-398.282440,0.139944,0.000000