File: Data/compression 5/AutoNoheating-17-5-3-240223_02232024_195016.csv
Time (sec),S:Load (lbs),S:HL1 (DIM),S:LVDT (in),S:Position (in),Ch:Position (mm),Ch:Load (N),Ch:Stress (MPa),Ch:Strain (mm/mm),Ch:HL1 (DIM),Set Point (),Cycles ()
0.110000,0.008194,-413.806274,0.000013,-0.000000,-0.000000,0.036449,0.001857,-0.000000,-413.806274,0.000199,0.000000
0.310000,0.012283,-413.850769,0.000009,-0.000000,-0.000000,0.054639,0.002783,-0.000000,-413.850769,0.000199,0.000000
0.510000,-0.000374,-413.806274,0.000004,0.000074,0.001882,-0.001663,-0.000085,0.018818,-413.806274,0.002385,0.000000
0.710000,-0.010056,-413.850769,0.000056,0.000190,0.004822,-0.044729,-0.002279,0.048216,-413.850769,0.005715,0.000000
0.910000,-0.007820,-413.850769,0.000194,0.000322,0.008186,-0.034786,-0.001772,0.081863,-413.850769,0.009045,0.000000
1.110000,0.018616,-413.850769,0.000315,0.000454,0.011525,0.082807,0.004218,0.115254,-413.850769,0.012375,0.000000
1.310000,0.147461,-413.806274,0.000448,0.000576,0.014621,0.655939,0.033415,0.146214,-413.806274,0.015705,0.000000
1.510000,0.772675,-413.806274,0.000569,-0.000002,-0.000044,3.437028,0.175091,-0.000435,-413.806274,0.000061,0.000000
1.710000,0.688515,-413.806274,0.000560,-0.000002,-0.000061,3.062666,0.156020,-0.000609,-413.806274,0.000061,0.000000
1.910000,0.668777,-413.850769,0.000565,-0.000002,-0.000061,2.974871,0.151547,-0.000609,-413.850769,0.000061,0.000000
2.110000,0.616646,-413.850769,0.000569,-0.000002,-0.000061,2.742978,0.139734,-0.000609,-413.850769,0.000234,0.000000
2.310000,0.678085,-413.895264,0.000556,-0.000002,-0.000061,3.016274,0.153656,-0.000609,-413.895264,0.000572,0.000000
2.510000,0.659843,-413.895264,0.000569,-0.000002,-0.000052,2.935130,0.149523,-0.000522,-413.895264,0.000902,0.000000
2.710000,0.826294,-413.806274,0.000560,0.000016,0.000408,3.675539,0.187241,0.004076,-413.806274,0.001231,0.000000
2.910000,0.927574,-413.850769,0.000582,0.000029,0.000728,4.126056,0.210191,0.007282,-413.850769,0.001570,0.000000
3.110000,1.089188,-413.895264,0.000599,0.000041,0.001040,4.844948,0.246813,0.010405,-413.895264,0.001899,0.000000
3.310000,1.231064,-413.850769,0.000608,0.000055,0.001405,5.476046,0.278963,0.014050,-413.850769,0.002237,0.000000
3.510000,1.513695,-413.895264,0.000642,0.000073,0.001864,6.733251,0.343008,0.018644,-413.895264,0.002567,0.000000
3.710000,1.663383,-413.939728,0.000638,0.000085,0.002168,7.399099,0.376928,0.021680,-413.939728,0.002905,0.000000
3.910000,1.807869,-413.850769,0.000638,0.000094,0.002394,8.041802,0.409669,0.023936,-413.850769,0.003235,0.000000
4.110000,1.887184,-413.806274,0.000647,0.000101,0.002576,8.394614,0.427642,0.025756,-413.806274,0.003564,0.000000
4.310000,2.233864,-413.895264,0.000673,0.000124,0.003157,9.936723,0.506201,0.031566,-413.895264,0.003902,0.000000
4.510000,2.438293,-413.895264,0.000677,0.000138,0.003512,10.846071,0.552525,0.035120,-413.895264,0.004232,0.000000
4.710000,2.566765,-413.895264,0.000694,0.000148,0.003755,11.417541,0.581637,0.037550,-413.895264,0.004570,0.000000
4.910000,2.746986,-413.939728,0.000711,0.000162,0.004110,12.219206,0.622476,0.041104,-413.939728,0.004900,0.000000
5.110000,2.940254,-413.939728,0.000711,0.000171,0.004353,13.078904,0.666271,0.043534,-413.939728,0.005238,0.000000
5.310000,3.236290,-413.895264,0.000716,0.000189,0.004813,14.395737,0.733354,0.048129,-413.895264,0.005568,0.000000
5.510000,3.474602,-413.895264,0.000742,0.000202,0.005134,15.455800,0.787356,0.051338,-413.895264,0.005906,0.000000
5.710000,3.673828,-413.895264,0.000737,0.000215,0.005463,16.342003,0.832501,0.054635,-413.895264,0.006235,0.000000
5.910000,3.772133,-413.939728,0.000759,0.000222,0.005628,16.779285,0.854778,0.056281,-413.939728,0.006565,0.000000
6.110000,4.033165,-413.939728,0.000759,0.000240,0.006088,17.940414,0.913928,0.060876,-413.939728,0.006903,0.000000
6.310000,4.421547,-413.895264,0.000780,0.000256,0.006504,19.668022,1.001937,0.065040,-413.895264,0.007233,0.000000
6.510000,4.513153,-413.939728,0.000798,0.000266,0.006747,20.075508,1.022695,0.067470,-413.939728,0.007571,0.000000
6.710001,4.650558,-413.939728,0.000819,0.000277,0.007042,20.686718,1.053832,0.070418,-413.939728,0.007900,0.000000
6.910000,4.916061,-413.895264,0.000802,0.000290,0.007371,21.867733,1.113995,0.073715,-413.895264,0.008239,0.000000
7.110000,5.138741,-413.939728,0.000823,0.000304,0.007709,22.858259,1.164455,0.077095,-413.939728,0.008568,0.000000
7.310000,5.371468,-413.939728,0.000849,0.000319,0.008100,23.893480,1.217192,0.080997,-413.939728,0.008906,0.000000
7.510000,5.639206,-413.984222,0.000862,0.000334,0.008481,25.084440,1.277862,0.084812,-413.984222,0.009236,0.000000
7.710001,5.798958,-413.939728,0.000867,0.000346,0.008776,25.795053,1.314063,0.087760,-413.939728,0.009566,0.000000
7.910000,5.768417,-414.028687,0.000875,0.000351,0.008924,25.659203,1.307142,0.089236,-414.028687,0.009904,0.000000
8.110001,6.143028,-413.984222,0.000871,0.000370,0.009409,27.325554,1.392030,0.094092,-413.984222,0.010233,0.000000
8.310000,6.381714,-413.939728,0.000897,0.000383,0.009739,28.387281,1.446117,0.097389,-413.939728,0.010571,0.000000
8.510000,6.492683,-413.984222,0.000901,0.000396,0.010068,28.880898,1.471263,0.100682,-413.984222,0.010901,0.000000
8.710000,6.593971,-413.939728,0.000923,0.000409,0.010389,29.331450,1.494215,0.103892,-413.939728,0.011239,0.000000
8.910001,6.835640,-413.939728,0.000927,0.000422,0.010719,30.406445,1.548978,0.107188,-413.939728,0.011569,0.000000
9.110001,7.043427,-413.939728,0.000957,0.000437,0.011109,31.330727,1.596063,0.111090,-413.939728,0.011898,0.000000
9.310000,7.182693,-414.028687,0.000961,0.000451,0.011456,31.950216,1.627622,0.114561,-414.028687,0.012237,0.000000
9.510000,7.344673,-413.984222,0.000979,0.000465,0.011803,32.670738,1.664327,0.118028,-413.984222,0.012566,0.000000
9.710000,7.329781,-413.984222,0.000987,0.000474,0.012028,32.604492,1.660952,0.120284,-413.984222,0.012904,0.000000
9.910001,7.459732,-413.984222,0.000992,0.000484,0.012288,33.182545,1.690400,0.122884,-413.984222,0.013234,0.000000
10.110001,7.680923,-413.984222,0.001022,0.000501,0.012713,34.166454,1.740522,0.127135,-413.984222,0.013572,0.000000
10.310000,7.866737,-413.984222,0.001013,0.000515,0.013078,34.992996,1.782628,0.130776,-413.984222,0.013902,0.000000
10.510000,7.901367,-414.028687,0.001035,0.000526,0.013372,35.147038,1.790475,0.133724,-414.028687,0.014240,0.000000
10.710000,8.008614,-414.028687,0.001061,0.000541,0.013737,35.624092,1.814778,0.137369,-414.028687,0.014569,0.000000
10.910001,8.073402,-414.028687,0.001061,0.000552,0.014032,35.912289,1.829459,0.140317,-414.028687,0.014899,0.000000
11.110001,8.054787,-413.984222,0.001065,0.000563,0.014292,35.829479,1.825241,0.142918,-413.984222,0.015237,0.000000
11.310000,8.423439,-414.028687,0.001091,0.000580,0.014726,37.469330,1.908779,0.147255,-414.028687,0.015567,0.000000
11.510000,8.418968,-414.028687,0.001095,0.000591,0.015003,37.449440,1.907765,0.150029,-414.028687,0.015905,0.000000
11.710001,8.555626,-414.028687,0.001104,0.000602,0.015280,38.057323,1.938733,0.152804,-414.028687,0.016234,0.000000
11.910001,8.766762,-413.984222,0.001108,0.000619,0.015714,38.996506,1.986577,0.157141,-413.984222,0.016573,0.000000
12.110001,9.057213,-414.073181,0.001125,0.000637,0.016191,40.288494,2.052394,0.161910,-414.073181,0.016902,0.000000
12.310000,8.960396,-414.028687,0.001143,0.000648,0.016460,39.857830,2.030455,0.164598,-414.028687,0.017231,0.000000
12.510000,8.945129,-414.028687,0.001164,0.000658,0.016720,39.789925,2.026995,0.167202,-414.028687,0.017570,0.000000
12.710001,9.025558,-414.073181,0.001181,0.000672,0.017058,40.147690,2.045221,0.170581,-414.073181,0.017900,0.000000
12.910001,9.136528,-414.117645,0.001190,0.000685,0.017388,40.641308,2.070367,0.173878,-414.117645,0.018238,0.000000
13.110001,9.310425,-414.073181,0.001212,0.000700,0.017787,41.414837,2.109772,0.177867,-414.073181,0.018567,0.000000
13.310000,9.326065,-414.073181,0.001203,0.000711,0.018064,41.484409,2.113317,0.180642,-414.073181,0.018906,0.000000
13.510000,9.372238,-414.073181,0.001229,0.000721,0.018324,41.689796,2.123780,0.183242,-414.073181,0.019235,0.000000
13.710001,9.499962,-414.073181,0.001233,0.000736,0.018697,42.257942,2.152722,0.186974,-414.073181,0.019573,0.000000
13.910001,9.733444,-414.073181,0.001255,0.000754,0.019148,43.296524,2.205630,0.191482,-414.073181,0.019903,0.000000
14.110001,9.809036,-414.073181,0.001272,0.000768,0.019504,43.632771,2.222759,0.195039,-414.073181,0.020232,0.000000
14.310000,9.845528,-414.073181,0.001268,0.000780,0.019825,43.795094,2.231029,0.198245,-414.073181,0.020571,0.000000
14.510000,9.794510,-414.028687,0.001293,0.000791,0.020094,43.568157,2.219468,0.200936,-414.028687,0.020900,0.000000
14.710001,9.738281,-414.073181,0.001298,0.000800,0.020310,43.318039,2.206726,0.203101,-414.073181,0.021238,0.000000
14.910001,9.995590,-414.117645,0.001302,0.000816,0.020718,44.462605,2.265033,0.207178,-414.117645,0.021568,0.000000
15.110001,10.232422,-414.162140,0.001332,0.000832,0.021134,45.516087,2.318700,0.211341,-414.162140,0.021906,0.000000
15.310000,10.149384,-414.073181,0.001332,0.000841,0.021368,45.146713,2.299883,0.213684,-414.073181,0.022235,0.000000
15.510001,10.162041,-414.117645,0.001341,0.000852,0.021628,45.203014,2.302752,0.216284,-414.117645,0.022574,0.000000
15.710001,10.306152,-414.117645,0.001345,0.000866,0.021993,45.844055,2.335407,0.219929,-414.117645,0.022903,0.000000
15.910001,10.458450,-414.117645,0.001375,0.000881,0.022383,46.521511,2.369919,0.223831,-414.117645,0.023233,0.000000
16.110001,10.716507,-414.162140,0.001401,0.000900,0.022851,47.669403,2.428395,0.228513,-414.162140,0.023571,0.000000
16.310001,10.666611,-414.117645,0.001406,0.000912,0.023155,47.447453,2.417089,0.231549,-414.117645,0.023900,0.000000
16.510000,10.614105,-414.117645,0.001410,0.000921,0.023397,47.213898,2.405190,0.233975,-414.117645,0.024239,0.000000
16.710001,10.617455,-414.162140,0.001427,0.000932,0.023675,47.228798,2.405950,0.236753,-414.162140,0.024569,0.000000
16.910002,10.789490,-414.162140,0.001440,0.000947,0.024057,47.994049,2.444933,0.240568,-414.162140,0.024907,0.000000
17.110001,11.016640,-414.073181,0.001453,0.000961,0.024412,49.004459,2.496406,0.244122,-414.073181,0.025236,0.000000
17.310001,10.983498,-414.206604,0.001462,0.000971,0.024655,48.857037,2.488896,0.246552,-414.206604,0.025566,0.000000
17.510000,11.146965,-414.162140,0.001470,0.000986,0.025054,49.584175,2.525938,0.250541,-414.162140,0.025904,0.000000
17.710001,11.143990,-414.162140,0.001492,0.001000,0.025392,49.570942,2.525264,0.253921,-414.162140,0.026233,0.000000
17.910002,11.461998,-414.162140,0.001496,0.001016,0.025817,50.985512,2.597326,0.258171,-414.162140,0.026572,0.000000
18.110001,11.556953,-414.162140,0.001522,0.001031,0.026190,51.407898,2.618843,0.261900,-414.162140,0.026901,0.000000
18.310001,11.474655,-414.117645,0.001526,0.001042,0.026459,51.041817,2.600194,0.264591,-414.117645,0.027240,0.000000
18.510000,11.374115,-414.162140,0.001531,0.001052,0.026710,50.594589,2.577411,0.267104,-414.162140,0.027569,0.000000
18.710001,11.673126,-414.206604,0.001548,0.001069,0.027153,51.924660,2.645168,0.271528,-414.206604,0.027907,0.000000
18.910002,11.873466,-414.206604,0.001569,0.001084,0.027526,52.815815,2.690566,0.275256,-414.206604,0.028237,0.000000
19.110001,11.909958,-414.162140,0.001569,0.001097,0.027855,52.978138,2.698835,0.278553,-414.162140,0.028566,0.000000
19.310001,11.792290,-414.206604,0.001587,0.001105,0.028055,52.454723,2.672171,0.280548,-414.206604,0.028904,0.000000
19.510000,11.864899,-414.251099,0.001600,0.001116,0.028350,52.777706,2.688624,0.283496,-414.251099,0.029234,0.000000
19.710001,12.225731,-414.162140,0.001613,0.001135,0.028827,54.382767,2.770390,0.288265,-414.162140,0.029572,0.000000
19.910002,12.370956,-414.251099,0.001638,0.001150,0.029199,55.028763,2.803299,0.291993,-414.251099,0.029902,0.000000
20.110001,12.376915,-414.251099,0.001630,0.001162,0.029520,55.055267,2.804649,0.295203,-414.251099,0.030240,0.000000
20.310001,12.369469,-414.162140,0.001643,0.001175,0.029850,55.022144,2.802962,0.298500,-414.162140,0.030569,0.000000
20.510000,12.267067,-414.206604,0.001660,0.001183,0.030049,54.566639,2.779757,0.300494,-414.206604,0.030908,0.000000
20.710001,12.563103,-414.251099,0.001681,0.001200,0.030474,55.883472,2.846840,0.304741,-414.251099,0.031237,0.000000
20.910002,12.661407,-414.206604,0.001681,0.001213,0.030804,56.320755,2.869116,0.308037,-414.206604,0.031567,0.000000
21.110001,12.855782,-414.251099,0.001712,0.001227,0.031168,57.185371,2.913162,0.311679,-414.251099,0.031905,0.000000
21.310001,12.712051,-414.251099,0.001707,0.001233,0.031324,56.546028,2.880592,0.313242,-414.251099,0.032235,0.000000
21.510000,12.794716,-414.251099,0.001716,0.001245,0.031628,56.913738,2.899324,0.316277,-414.251099,0.032573,0.000000
21.710001,12.962654,-414.251099,0.001746,0.001260,0.031992,57.660767,2.937379,0.319918,-414.251099,0.032902,0.000000
21.910002,13.223686,-414.206604,0.001755,0.001276,0.032408,58.821896,2.996530,0.324082,-414.206604,0.033240,0.000000
22.110001,13.040108,-414.206604,0.001755,0.001284,0.032608,58.005295,2.954931,0.326076,-414.206604,0.033570,0.000000
22.310001,13.120544,-414.251099,0.001776,0.001294,0.032876,58.363098,2.973158,0.328764,-414.251099,0.033900,0.000000
22.510000,13.370407,-414.295593,0.001781,0.001310,0.033267,59.474541,3.029778,0.332666,-414.295593,0.034238,0.000000
22.710001,13.542809,-414.251099,0.001798,0.001324,0.033622,60.241421,3.068844,0.336224,-414.251099,0.034567,0.000000
22.910002,13.811295,-414.295593,0.001802,0.001342,0.034099,61.435707,3.129684,0.340993,-414.295593,0.034906,0.000000
23.110001,13.899918,-414.295593,0.001824,0.001355,0.034429,61.829922,3.149766,0.344289,-414.295593,0.035235,0.000000
23.310001,13.810547,-414.251099,0.001845,0.001365,0.034680,61.432381,3.129515,0.346802,-414.251099,0.035573,0.000000
23.510000,13.881302,-414.295593,0.001841,0.001377,0.034966,61.747116,3.145548,0.349664,-414.295593,0.035903,0.000000
23.710001,14.109932,-414.295593,0.001863,0.001393,0.035374,62.764111,3.197356,0.353740,-414.295593,0.036241,0.000000
23.910002,14.081261,-414.295593,0.001880,0.001403,0.035643,62.636578,3.190859,0.356427,-414.295593,0.036571,0.000000
24.110001,14.219414,-414.251099,0.001897,0.001415,0.035946,63.251110,3.222165,0.359463,-414.251099,0.036900,0.000000
24.310001,14.397781,-414.295593,0.001897,0.001431,0.036354,64.044533,3.262584,0.363539,-414.295593,0.037238,0.000000
24.510000,14.471138,-414.295593,0.001897,0.001442,0.036631,64.370834,3.279207,0.366313,-414.295593,0.037568,0.000000
24.710001,14.578751,-414.295593,0.001932,0.001457,0.037013,64.849518,3.303592,0.370132,-414.295593,0.037906,0.000000
24.910002,15.004745,-414.295593,0.001932,0.001475,0.037455,66.744438,3.400124,0.374553,-414.295593,0.038236,0.000000
25.110001,15.034912,-414.340057,0.001957,0.001488,0.037802,66.878632,3.406960,0.378024,-414.340057,0.038574,0.000000
25.310001,14.864731,-414.340057,0.001953,0.001496,0.037993,66.121628,3.368396,0.379932,-414.340057,0.038904,0.000000
25.510002,15.046822,-414.340057,0.001979,0.001511,0.038375,66.931602,3.409658,0.383747,-414.340057,0.039233,0.000000
25.710001,15.182365,-414.340057,0.001979,0.001523,0.038687,67.534531,3.440373,0.386869,-414.340057,0.039571,0.000000
25.910002,15.435211,-414.384552,0.002009,0.001539,0.039095,68.659248,3.497669,0.390946,-414.384552,0.039901,0.000000
26.110001,15.553253,-414.429016,0.002001,0.001554,0.039467,69.184326,3.524418,0.394674,-414.429016,0.040239,0.000000
26.310001,15.593842,-414.340057,0.002026,0.001564,0.039719,69.364868,3.533615,0.397187,-414.340057,0.040569,0.000000
26.510002,15.609848,-414.295593,0.002048,0.001576,0.040022,69.436073,3.537242,0.400222,-414.295593,0.040907,0.000000
26.710001,15.871628,-414.340057,0.002035,0.001592,0.040430,70.600525,3.596562,0.404299,-414.340057,0.041236,0.000000
26.910002,16.087975,-414.340057,0.002070,0.001606,0.040794,71.562881,3.645587,0.407944,-414.340057,0.041575,0.000000
27.110001,16.039940,-414.384552,0.002070,0.001617,0.041072,71.349213,3.634702,0.410718,-414.384552,0.041904,0.000000
27.310001,15.822105,-414.384552,0.002091,0.001623,0.041236,70.380241,3.585340,0.412364,-414.384552,0.042234,0.000000
27.510002,16.490883,-414.384552,0.002100,0.001645,0.041783,73.355110,3.736887,0.417830,-414.384552,0.042572,0.000000
27.710001,16.591057,-414.384552,0.002121,0.001657,0.042095,73.800705,3.759587,0.420948,-414.384552,0.042901,0.000000
27.910002,16.648026,-414.429016,0.002126,0.001670,0.042416,74.054115,3.772496,0.424158,-414.429016,0.043240,0.000000
28.110001,16.713936,-414.429016,0.002130,0.001682,0.042719,74.347298,3.787432,0.427194,-414.429016,0.043569,0.000000
28.310001,16.867355,-414.429016,0.002151,0.001695,0.043058,75.029747,3.822197,0.430577,-414.429016,0.043907,0.000000
28.510002,16.830490,-414.384552,0.002151,0.001705,0.043318,74.865761,3.813843,0.433177,-414.384552,0.044237,0.000000
28.710001,17.257225,-414.429016,0.002173,0.001724,0.043778,76.763969,3.910543,0.437776,-414.429016,0.044575,0.000000
28.910002,17.470596,-414.473511,0.002186,0.001738,0.044150,77.713097,3.958894,0.441504,-414.473511,0.044905,0.000000
29.110001,17.364471,-414.429016,0.002195,0.001747,0.044367,77.241028,3.934845,0.443673,-414.429016,0.045234,0.000000
29.310001,17.129128,-414.429016,0.002212,0.001755,0.044567,76.194168,3.881516,0.445668,-414.429016,0.045572,0.000000
29.510002,17.838501,-414.429016,0.002212,0.001774,0.045070,79.349617,4.042262,0.450698,-414.429016,0.045902,0.000000
29.710001,17.997505,-414.429016,0.002251,0.001787,0.045399,80.056900,4.078293,0.453991,-414.429016,0.046240,0.000000
29.910002,18.111450,-414.429016,0.002233,0.001799,0.045703,80.563751,4.104113,0.457026,-414.429016,0.046570,0.000000
30.110001,18.156876,-414.429016,0.002233,0.001813,0.046050,80.765816,4.114407,0.460497,-414.429016,0.046908,0.000000
30.310001,18.217575,-414.429016,0.002268,0.001823,0.046301,81.035820,4.128161,0.463010,-414.429016,0.047238,0.000000
30.510002,18.643570,-414.429016,0.002281,0.001841,0.046752,82.930740,4.224693,0.467522,-414.429016,0.047567,0.000000
30.710001,18.781723,-414.429016,0.002294,0.001854,0.047090,83.545273,4.255999,0.470901,-414.429016,0.047905,0.000000
30.910002,18.877045,-414.473511,0.002294,0.001865,0.047368,83.969292,4.277600,0.473676,-414.473511,0.048235,0.000000
31.110001,18.977219,-414.517975,0.002320,0.001877,0.047671,84.414886,4.300299,0.476711,-414.517975,0.048573,0.000000
31.310001,18.718414,-414.473511,0.002324,0.001883,0.047827,83.263664,4.241653,0.478274,-414.473511,0.048903,0.000000
31.510002,19.445290,-414.429016,0.002345,0.001906,0.048400,86.496971,4.406365,0.483997,-414.429016,0.049241,0.000000
31.710001,19.799042,-414.429016,0.002354,0.001922,0.048807,88.070534,4.486527,0.488074,-414.429016,0.049570,0.000000
31.910002,19.834793,-414.473511,0.002354,0.001932,0.049076,88.229568,4.494628,0.490761,-414.473511,0.049909,0.000000
32.110001,19.967354,-414.473511,0.002367,0.001944,0.049371,88.819229,4.524667,0.493709,-414.473511,0.050238,0.000000
32.310001,19.921181,-414.517975,0.002393,0.001954,0.049623,88.613838,4.514204,0.496226,-414.517975,0.050568,0.000000
32.510002,20.236206,-414.517975,0.002406,0.001969,0.050022,90.015137,4.585590,0.500216,-414.517975,0.050906,0.000000
32.710003,20.549004,-414.517975,0.002410,0.001982,0.050334,91.406532,4.656471,0.503338,-414.517975,0.051236,0.000000
32.910000,20.556816,-414.473511,0.002427,0.001992,0.050603,91.441284,4.658241,0.506025,-414.473511,0.051574,0.000000
33.110001,20.667412,-414.517975,0.002432,0.002004,0.050906,91.933243,4.683302,0.509061,-414.517975,0.051903,0.000000
33.310001,21.268799,-414.517975,0.002440,0.002024,0.051400,94.608345,4.819579,0.514004,-414.517975,0.052241,0.000000
33.510002,21.686600,-414.606934,0.002471,0.002039,0.051791,96.466812,4.914254,0.517906,-414.606934,0.052571,0.000000
33.710003,21.741707,-414.473511,0.002466,0.002051,0.052103,96.711945,4.926741,0.521029,-414.473511,0.052909,0.000000
33.910000,21.834061,-414.473511,0.002483,0.002064,0.052433,97.122749,4.947669,0.524325,-414.473511,0.053239,0.000000
34.110001,21.872040,-414.517975,0.002488,0.002073,0.052658,97.291695,4.956275,0.526577,-414.517975,0.053568,0.000000
34.310001,22.021362,-414.606934,0.002492,0.002085,0.052961,97.955910,4.990112,0.529613,-414.606934,0.053907,0.000000
34.510002,22.579178,-414.517975,0.002514,0.002103,0.053412,100.437202,5.116515,0.534124,-414.517975,0.054236,0.000000
34.710003,22.683815,-414.562469,0.002501,0.002114,0.053707,100.902649,5.140226,0.537073,-414.562469,0.054574,0.000000
34.910000,22.706154,-414.562469,0.002514,0.002125,0.053967,101.002014,5.145288,0.539673,-414.562469,0.054904,0.000000
35.110001,23.053947,-414.606934,0.002548,0.002140,0.054349,102.549080,5.224099,0.543488,-414.606934,0.055242,0.000000
35.310001,23.619957,-414.562469,0.002570,0.002156,0.054765,105.066818,5.352359,0.547652,-414.562469,0.055572,0.000000
35.510002,23.877640,-414.562469,0.002578,0.002170,0.055121,106.213043,5.410751,0.551206,-414.562469,0.055901,0.000000
35.710003,24.153564,-414.606934,0.002596,0.002184,0.055476,107.440422,5.473276,0.554763,-414.606934,0.056239,0.000000
35.910000,23.918228,-414.606934,0.002591,0.002191,0.055650,106.393593,5.419948,0.556497,-414.606934,0.056569,0.000000
36.110001,24.067177,-414.562469,0.002587,0.002202,0.055936,107.056152,5.453700,0.559358,-414.562469,0.056907,0.000000
36.310001,24.609352,-414.606934,0.002613,0.002221,0.056404,109.467865,5.576559,0.564044,-414.606934,0.057237,0.000000
36.510002,24.870384,-414.606934,0.002613,0.002232,0.056682,110.628998,5.635710,0.566818,-414.606934,0.057575,0.000000
36.710003,24.910225,-414.606934,0.002639,0.002242,0.056942,110.806213,5.644738,0.569419,-414.606934,0.057905,0.000000
36.910000,25.114662,-414.606934,0.002643,0.002255,0.057272,111.715599,5.691064,0.572715,-414.606934,0.058243,0.000000
37.110001,25.490379,-414.651428,0.002639,0.002267,0.057575,113.386871,5.776203,0.575751,-414.651428,0.058572,0.000000
37.310001,26.165863,-414.651428,0.002665,0.002284,0.058017,116.391571,5.929269,0.580171,-414.651428,0.058902,0.000000
37.510002,26.764641,-414.606934,0.002669,0.002301,0.058451,119.055069,6.064954,0.584509,-414.606934,0.059240,0.000000
37.710003,26.883430,-414.606934,0.002690,0.002314,0.058763,119.583473,6.091873,0.587631,-414.606934,0.059570,0.000000
37.910004,26.855125,-414.651428,0.002695,0.002323,0.059006,119.457565,6.085458,0.590058,-414.651428,0.059908,0.000000
38.110001,26.987694,-414.695892,0.002703,0.002335,0.059309,120.047256,6.115499,0.593093,-414.695892,0.060237,0.000000
38.310001,27.716049,-414.695892,0.002721,0.002351,0.059717,123.287148,6.280547,0.597169,-414.695892,0.060576,0.000000
38.510002,27.897026,-414.740387,0.002729,0.002362,0.059986,124.092171,6.321557,0.599860,-414.740387,0.060905,0.000000
38.710003,27.821808,-414.695892,0.002742,0.002372,0.060246,123.757584,6.304512,0.602461,-414.695892,0.061235,0.000000
38.910004,28.472343,-414.606934,0.002755,0.002388,0.060645,126.651306,6.451925,0.606450,-414.606934,0.061573,0.000000
39.110001,29.275177,-414.651428,0.002755,0.002407,0.061131,130.222488,6.633850,0.611306,-414.651428,0.061902,0.000000
39.310001,29.663185,-414.695892,0.002777,0.002421,0.061486,131.948441,6.721774,0.614860,-414.695892,0.062241,0.000000
39.510002,29.870224,-414.651428,0.002785,0.002432,0.061781,132.869385,6.768690,0.617812,-414.651428,0.062570,0.000000
39.710003,29.974121,-414.651428,0.002807,0.002445,0.062102,133.331543,6.792233,0.621018,-414.651428,0.062908,0.000000
39.910004,29.990875,-414.695892,0.002802,0.002452,0.062293,133.406082,6.796029,0.622926,-414.695892,0.063238,0.000000
40.110001,30.684235,-414.651428,0.002820,0.002470,0.062735,136.490295,6.953147,0.627350,-414.651428,0.063576,0.000000
40.310001,31.254333,-414.651428,0.002833,0.002485,0.063117,139.026215,7.082334,0.631165,-414.651428,0.063906,0.000000
40.510002,31.585373,-414.695892,0.002846,0.002498,0.063455,140.498749,7.157348,0.634549,-414.695892,0.064235,0.000000
40.710003,31.472549,-414.695892,0.002846,0.002505,0.063637,139.996887,7.131782,0.636370,-414.695892,0.064573,0.000000
40.910004,31.851997,-414.651428,0.002863,0.002518,0.063967,141.684753,7.217766,0.639666,-414.651428,0.064903,0.000000
41.110001,32.741592,-414.695892,0.002850,0.002537,0.064435,145.641876,7.419351,0.644348,-414.695892,0.065241,0.000000
41.310001,33.319138,-414.740387,0.002876,0.002552,0.064825,148.210922,7.550224,0.648250,-414.740387,0.065571,0.000000
41.510002,33.615547,-414.695892,0.002893,0.002564,0.065137,149.529419,7.617392,0.651373,-414.695892,0.065909,0.000000
41.710003,33.803223,-414.651428,0.002915,0.002574,0.065389,150.364243,7.659920,0.653886,-414.651428,0.066239,0.000000
41.910004,33.866158,-414.695892,0.002915,0.002584,0.065623,150.644196,7.674181,0.656229,-414.695892,0.066577,0.000000
42.110001,34.587440,-414.740387,0.002923,0.002601,0.066065,153.852615,7.837626,0.660650,-414.740387,0.066906,0.000000
42.310001,35.100571,-414.784882,0.002932,0.002615,0.066412,156.135132,7.953903,0.664120,-414.784882,0.067236,0.000000
42.510002,35.651680,-414.740387,0.002932,0.002629,0.066776,158.586594,8.078786,0.667761,-414.740387,0.067574,0.000000
42.710003,35.381714,-414.740387,0.002936,0.002633,0.066880,157.385727,8.017612,0.668802,-414.740387,0.067904,0.000000
42.910004,35.984207,-414.784882,0.002949,0.002649,0.067279,160.065750,8.154138,0.672792,-414.784882,0.068242,0.000000
43.110001,36.575165,-414.784882,0.002958,0.002664,0.067661,162.694458,8.288051,0.676607,-414.784882,0.068571,0.000000
43.310001,37.034676,-414.740387,0.002984,0.002675,0.067938,164.738464,8.392177,0.679385,-414.740387,0.068910,0.000000
43.510002,37.478912,-414.784882,0.002997,0.002690,0.068337,166.714523,8.492843,0.683374,-414.784882,0.069239,0.000000
43.710003,38.007309,-414.784882,0.003001,0.002702,0.068641,169.064957,8.612579,0.686410,-414.784882,0.069569,0.000000
43.910004,38.437027,-414.740387,0.003001,0.002714,0.068936,170.976440,8.709955,0.689358,-414.740387,0.069907,0.000000
44.110001,39.064102,-414.784882,0.003014,0.002730,0.069335,173.765808,8.852053,0.693347,-414.784882,0.070237,0.000000
44.310001,39.970459,-414.740387,0.003014,0.002746,0.069759,177.797485,9.057436,0.697594,-414.740387,0.070575,0.000000
44.510002,40.276924,-414.829346,0.003018,0.002757,0.070020,179.160706,9.126882,0.700198,-414.829346,0.070904,0.000000
44.710003,40.453423,-414.829346,0.003022,0.002766,0.070262,179.945816,9.166876,0.702624,-414.829346,0.071242,0.000000
44.910004,40.971024,-414.829346,0.003053,0.002781,0.070644,182.248215,9.284166,0.706439,-414.829346,0.071572,0.000000
45.110001,41.506493,-414.784882,0.003061,0.002792,0.070922,184.630096,9.405506,0.709217,-414.784882,0.071910,0.000000
45.310001,41.915359,-414.829346,0.003065,0.002807,0.071303,186.448837,9.498157,0.713033,-414.829346,0.072240,0.000000
45.510002,42.520096,-414.829346,0.003078,0.002820,0.071616,189.138840,9.635192,0.716155,-414.829346,0.072569,0.000000
45.710003,43.254410,-414.784882,0.003083,0.002833,0.071962,192.405228,9.801590,0.719622,-414.784882,0.072908,0.000000
45.910004,43.675934,-414.829346,0.003087,0.002845,0.072266,194.280258,9.897108,0.722658,-414.829346,0.073237,0.000000
46.110001,44.632935,-414.829346,0.003096,0.002863,0.072708,198.537216,10.113968,0.727082,-414.829346,0.073575,0.000000
46.310001,45.057442,-414.784882,0.003109,0.002873,0.072986,200.425507,10.210162,0.729856,-414.784882,0.073905,0.000000
46.510002,45.866600,-414.873840,0.003122,0.002890,0.073411,204.024826,10.393520,0.734107,-414.873840,0.074243,0.000000
46.710003,45.916504,-414.873840,0.003130,0.002898,0.073601,204.246811,10.404828,0.736014,-414.873840,0.074573,0.000000
46.910004,46.460541,-414.829346,0.003130,0.002910,0.073922,206.666809,10.528109,0.739220,-414.829346,0.074911,0.000000
47.110001,46.950951,-414.873840,0.003143,0.002924,0.074269,208.848267,10.639237,0.742691,-414.873840,0.075240,0.000000
47.310001,48.028595,-414.829346,0.003156,0.002940,0.074685,213.641861,10.883435,0.746854,-414.829346,0.075570,0.000000
47.510002,48.610992,-414.829346,0.003156,0.002953,0.075015,216.232498,11.015408,0.750147,-414.829346,0.075908,0.000000
47.710003,48.930481,-414.873840,0.003178,0.002964,0.075293,217.653656,11.087806,0.752925,-414.873840,0.076238,0.000000
47.910004,49.608574,-414.829346,0.003165,0.002980,0.075700,220.669952,11.241464,0.757002,-414.829346,0.076576,0.000000
48.110001,50.628128,-414.918304,0.003182,0.002996,0.076099,225.205154,11.472498,0.760991,-414.918304,0.076905,0.000000
48.310001,51.208656,-414.873840,0.003191,0.003007,0.076385,227.787476,11.604048,0.763852,-414.873840,0.077244,0.000000
48.510002,51.560181,-414.873840,0.003199,0.003017,0.076637,229.351135,11.683703,0.766366,-414.873840,0.077573,0.000000
48.710003,51.716202,-414.873840,0.003221,0.003026,0.076862,230.045151,11.719059,0.768621,-414.873840,0.077903,0.000000
48.910004,53.116325,-414.918304,0.003208,0.003045,0.077348,236.273209,12.036332,0.773477,-414.918304,0.078241,0.000000
49.110001,53.757545,-414.873840,0.003225,0.003059,0.077703,239.125504,12.181634,0.777031,-414.873840,0.078571,0.000000
49.310001,54.271797,-414.873840,0.003238,0.003071,0.077998,241.413010,12.298165,0.779980,-414.873840,0.078909,0.000000
49.510002,55.019150,-414.873840,0.003229,0.003084,0.078345,244.737396,12.467517,0.783451,-414.873840,0.079238,0.000000
49.710003,55.623878,-414.918304,0.003251,0.003097,0.078666,247.427368,12.604551,0.786660,-414.918304,0.079577,0.000000
49.910004,56.396927,-414.918304,0.003247,0.003111,0.079013,250.866058,12.779727,0.790127,-414.918304,0.079906,0.000000
50.110001,57.209068,-414.962799,0.003260,0.003125,0.079386,254.478653,12.963759,0.793859,-414.962799,0.080244,0.000000
50.310001,58.079300,-414.918304,0.003264,0.003138,0.079715,258.349640,13.160957,0.797152,-414.918304,0.080574,0.000000
50.510002,58.337357,-414.918304,0.003277,0.003146,0.079915,259.497528,13.219434,0.799147,-414.918304,0.080903,0.000000
50.710003,58.523918,-414.918304,0.003285,0.003155,0.080149,260.327393,13.261709,0.801489,-414.918304,0.081242,0.000000
50.910004,60.261032,-414.962799,0.003285,0.003179,0.080739,268.054443,13.655345,0.807386,-414.962799,0.081571,0.000000
51.110001,60.780869,-414.918304,0.003303,0.003190,0.081016,270.366821,13.773142,0.810161,-414.918304,0.081909,0.000000
51.310001,61.411293,-414.962799,0.003320,0.003202,0.081320,273.171082,13.915998,0.813196,-414.962799,0.082239,0.000000
51.510002,62.287109,-414.918304,0.003324,0.003215,0.081667,277.066895,14.114460,0.816667,-414.918304,0.082577,0.000000
51.710003,62.690765,-414.962799,0.003311,0.003223,0.081875,278.862457,14.205931,0.818748,-414.962799,0.082907,0.000000
51.910004,63.981400,-414.962799,0.003316,0.003245,0.082412,284.603485,14.498392,0.824123,-414.962799,0.083236,0.000000
52.110001,64.835632,-414.962799,0.003324,0.003258,0.082742,288.403290,14.691964,0.827420,-414.962799,0.083574,0.000000
52.310001,65.508133,-414.962799,0.003328,0.003268,0.083002,291.394714,14.844355,0.830020,-414.962799,0.083904,0.000000
52.510002,65.864502,-414.918304,0.003337,0.003275,0.083193,292.979950,14.925110,0.831927,-414.918304,0.084242,0.000000
52.710003,65.965042,-415.051758,0.003350,0.003281,0.083340,293.427155,14.947892,0.833404,-415.051758,0.084572,0.000000
52.910004,67.491760,-414.962799,0.003363,0.003296,0.083731,300.218353,15.293852,0.837306,-414.962799,0.083904,0.000000
53.110004,66.834518,-415.007263,0.003359,0.003296,0.083713,297.294800,15.144918,0.837132,-415.007263,0.083904,0.000000
53.310001,66.258835,-415.007263,0.003372,0.003296,0.083713,294.734009,15.014467,0.837132,-415.007263,0.083713,0.000000
53.510002,65.727463,-414.962799,0.003372,0.003295,0.083704,292.370361,14.894056,0.837045,-414.962799,0.083713,0.000000
53.710003,65.241516,-414.962799,0.003380,0.003295,0.083704,290.208771,14.783938,0.837045,-414.962799,0.083713,0.000000
53.910004,64.785355,-414.962799,0.003393,0.003295,0.083696,288.179657,14.680572,0.836958,-414.962799,0.083713,0.000000
54.110004,64.384689,-415.007263,0.003380,0.003295,0.083696,286.397400,14.589780,0.836958,-415.007263,0.083713,0.000000
54.310001,63.987000,-415.007263,0.003385,0.003295,0.083696,284.628387,14.499661,0.836958,-415.007263,0.083713,0.000000
54.510002,63.631744,-415.007263,0.003393,0.003295,0.083696,283.048126,14.419159,0.836958,-415.007263,0.083713,0.000000
54.710003,63.276138,-415.007263,0.003372,0.003295,0.083696,281.466309,14.338578,0.836958,-415.007263,0.083713,0.000000
54.910004,62.947327,-415.007263,0.003397,0.003295,0.083696,280.003693,14.264068,0.836958,-415.007263,0.083713,0.000000
55.110004,62.662834,-415.051758,0.003389,0.003295,0.083696,278.738220,14.199601,0.836958,-415.051758,0.083713,0.000000
55.310001,62.389145,-415.051758,0.003393,0.003295,0.083696,277.520782,14.137582,0.836958,-415.051758,0.083713,0.000000
55.510002,62.124016,-415.007263,0.003389,0.003295,0.083696,276.341431,14.077503,0.836958,-415.007263,0.083713,0.000000
55.710003,61.874153,-415.096222,0.003402,0.003295,0.083696,275.229980,14.020884,0.836958,-415.096222,0.083713,0.000000
55.910004,61.645142,-415.051758,0.003397,0.003295,0.083696,274.211273,13.968988,0.836958,-415.051758,0.083713,0.000000
56.110004,61.416878,-415.096222,0.003402,0.003295,0.083696,273.195923,13.917264,0.836958,-415.096222,0.083713,0.000000
56.310001,61.212448,-415.051758,0.003393,0.003295,0.083696,272.286560,13.870939,0.836958,-415.051758,0.083713,0.000000
56.510002,61.015831,-415.051758,0.003415,0.003295,0.083696,271.411957,13.826385,0.836958,-415.051758,0.083713,0.000000
56.710003,60.815498,-415.051758,0.003415,0.003295,0.083696,270.520844,13.780990,0.836958,-415.051758,0.083713,0.000000
56.910004,60.616280,-415.051758,0.003419,0.003295,0.083696,269.634674,13.735845,0.836958,-415.051758,0.083713,0.000000
57.110004,60.440147,-415.051758,0.003419,0.003295,0.083696,268.851196,13.695932,0.836958,-415.051758,0.083713,0.000000
57.310001,60.288963,-415.096222,0.003415,0.003295,0.083696,268.178711,13.661674,0.836958,-415.096222,0.083713,0.000000
57.510002,60.120277,-415.096222,0.003428,0.003295,0.083696,267.428345,13.623450,0.836958,-415.096222,0.083713,0.000000
57.710003,59.969841,-415.096222,0.003415,0.003295,0.083696,266.759186,13.589360,0.836958,-415.096222,0.083713,0.000000
57.910004,59.814560,-415.096222,0.003428,0.003295,0.083696,266.068451,13.554173,0.836958,-415.096222,0.083713,0.000000
58.110004,59.672310,-415.096222,0.003423,0.003295,0.083696,265.435699,13.521938,0.836958,-415.096222,0.083713,0.000000
58.310001,59.535652,-415.140717,0.003410,0.003295,0.083696,264.827820,13.490972,0.836958,-415.140717,0.083713,0.000000
58.510002,59.402718,-415.185211,0.003415,0.003295,0.083696,264.236481,13.460848,0.836958,-415.185211,0.083713,0.000000
58.710003,59.272011,-415.140717,0.003428,0.003295,0.083696,263.655060,13.431230,0.836958,-415.140717,0.083713,0.000000
58.910004,59.130882,-415.140717,0.003419,0.003295,0.083696,263.027313,13.399249,0.836958,-415.140717,0.083713,0.000000
59.110004,59.034065,-415.096222,0.003419,0.003295,0.083696,262.596649,13.377311,0.836958,-415.096222,0.083713,0.000000
59.310001,58.910065,-415.185211,0.003423,0.003295,0.083696,262.045044,13.349212,0.836958,-415.185211,0.083713,0.000000
59.510002,58.797607,-415.140717,0.003415,0.003295,0.083696,261.544830,13.323728,0.836958,-415.140717,0.083713,0.000000
59.710003,58.688507,-415.185211,0.003423,0.003295,0.083696,261.059509,13.299006,0.836958,-415.185211,0.083713,0.000000
59.910004,58.589828,-415.140717,0.003428,0.003295,0.083696,260.620575,13.276646,0.836958,-415.140717,0.083713,0.000000
60.110004,58.468430,-415.140717,0.003419,0.003295,0.083696,260.080566,13.249135,0.836958,-415.140717,0.083713,0.000000
60.310001,58.365654,-415.140717,0.003415,0.003295,0.083696,259.623383,13.225846,0.836958,-415.140717,0.083713,0.000000
60.510002,58.275169,-415.140717,0.003428,0.003295,0.083696,259.220886,13.205341,0.836958,-415.140717,0.083713,0.000000
60.710003,58.181335,-415.140717,0.003428,0.003295,0.083696,258.803497,13.184079,0.836958,-415.140717,0.083713,0.000000
60.910004,58.083771,-415.185211,0.003432,0.003295,0.083696,258.369507,13.161970,0.836958,-415.185211,0.083713,0.000000
61.110004,57.993286,-415.229675,0.003432,0.003295,0.083696,257.967010,13.141467,0.836958,-415.229675,0.083713,0.000000
61.310001,57.915459,-415.185211,0.003428,0.003295,0.083696,257.620819,13.123830,0.836958,-415.185211,0.083713,0.000000
61.510002,57.833534,-415.185211,0.003419,0.003295,0.083696,257.256409,13.105266,0.836958,-415.185211,0.083713,0.000000
61.710003,57.759811,-415.274170,0.003441,0.003295,0.083696,256.928467,13.088561,0.836958,-415.274170,0.083713,0.000000
61.910004,57.670067,-415.185211,0.003419,0.003295,0.083696,256.529266,13.068224,0.836958,-415.185211,0.083713,0.000000
62.110004,57.571388,-415.185211,0.003432,0.003295,0.083696,256.090332,13.045863,0.836958,-415.185211,0.083713,0.000000
62.310001,57.486862,-415.185211,0.003419,0.003295,0.083696,255.714340,13.026710,0.836958,-415.185211,0.083713,0.000000
62.510002,57.431374,-415.229675,0.003423,0.003295,0.083696,255.467514,13.014135,0.836958,-415.229675,0.083713,0.000000
62.710003,57.351318,-415.229675,0.003445,0.003295,0.083696,255.111404,12.995995,0.836958,-415.229675,0.083713,0.000000
62.910004,57.279449,-415.229675,0.003441,0.003295,0.083696,254.791718,12.979709,0.836958,-415.229675,0.083713,0.000000
63.110004,57.217636,-415.229675,0.003432,0.003295,0.083696,254.516754,12.965701,0.836958,-415.229675,0.083713,0.000000
63.310001,57.156563,-415.229675,0.003432,0.003295,0.083696,254.245087,12.951862,0.836958,-415.229675,0.083713,0.000000
63.510002,57.082458,-415.229675,0.003432,0.003295,0.083696,253.915451,12.935070,0.836958,-415.229675,0.083713,0.000000
63.710003,57.024002,-415.229675,0.003445,0.003295,0.083696,253.655426,12.921824,0.836958,-415.229675,0.083713,0.000000
63.910004,56.950645,-415.185211,0.003449,0.003295,0.083696,253.329117,12.905200,0.836958,-415.185211,0.083713,0.000000
64.110001,56.876915,-415.229675,0.003436,0.003295,0.083696,253.001160,12.888494,0.836958,-415.229675,0.083713,0.000000
64.310005,56.804298,-415.185211,0.003441,0.003295,0.083696,252.678146,12.872038,0.836958,-415.185211,0.083713,0.000000
64.510002,56.749557,-415.274170,0.003454,0.003295,0.083696,252.434647,12.859633,0.836958,-415.274170,0.083713,0.000000
64.710007,56.695198,-415.229675,0.003445,0.003295,0.083696,252.192841,12.847316,0.836958,-415.229675,0.083713,0.000000
64.910004,56.625191,-415.274170,0.003445,0.003295,0.083696,251.881424,12.831451,0.836958,-415.274170,0.083713,0.000000
65.110001,56.585716,-415.185211,0.003441,0.003295,0.083696,251.705841,12.822507,0.836958,-415.185211,0.083713,0.000000
65.310005,56.532097,-415.229675,0.003445,0.003295,0.083696,251.467331,12.810356,0.836958,-415.229675,0.083713,0.000000
65.510002,56.471024,-415.274170,0.003436,0.003295,0.083696,251.195663,12.796517,0.836958,-415.274170,0.083713,0.000000
65.710007,56.413307,-415.274170,0.003428,0.003295,0.083696,250.938919,12.783438,0.836958,-415.274170,0.083713,0.000000
65.910004,56.357826,-415.318634,0.003454,0.003295,0.083696,250.692139,12.770866,0.836958,-415.318634,0.083713,0.000000
66.110001,56.293030,-415.318634,0.003436,0.003295,0.083696,250.403900,12.756183,0.836958,-415.318634,0.083713,0.000000
66.310005,56.246483,-415.274170,0.003445,0.003295,0.083696,250.196854,12.745635,0.836958,-415.274170,0.083713,0.000000
66.510002,56.196213,-415.318634,0.003441,0.003295,0.083696,249.973236,12.734244,0.836958,-415.318634,0.083713,0.000000
66.710007,56.167168,-415.318634,0.003441,0.003295,0.083696,249.844040,12.727662,0.836958,-415.318634,0.083713,0.000000
66.910004,56.107964,-415.318634,0.003445,0.003295,0.083696,249.580688,12.714246,0.836958,-415.318634,0.083713,0.000000
67.110001,56.052483,-415.274170,0.003449,0.003295,0.083696,249.333893,12.701674,0.836958,-415.274170,0.083713,0.000000
67.310005,56.002953,-415.318634,0.003436,0.003295,0.083696,249.113571,12.690451,0.836958,-415.318634,0.083713,0.000000
67.510002,55.960129,-415.363129,0.003441,0.003295,0.083696,248.923080,12.680747,0.836958,-415.363129,0.083713,0.000000
67.710007,55.906509,-415.318634,0.003441,0.003295,0.083696,248.684570,12.668596,0.836958,-415.318634,0.083713,0.000000
67.910004,55.872993,-415.318634,0.003441,0.003295,0.083696,248.535492,12.661001,0.836958,-415.318634,0.083713,0.000000
68.110001,55.811180,-415.318634,0.003441,0.003295,0.083696,248.260529,12.646994,0.836958,-415.318634,0.083713,0.000000
68.310005,55.762032,-415.318634,0.003441,0.003295,0.083696,248.041901,12.635858,0.836958,-415.318634,0.083713,0.000000
68.510002,55.737823,-415.318634,0.003449,0.003295,0.083696,247.934219,12.630371,0.836958,-415.318634,0.083713,0.000000
68.710007,55.691650,-415.363129,0.003436,0.003295,0.083696,247.728836,12.619908,0.836958,-415.363129,0.083713,0.000000
68.910004,55.658508,-415.363129,0.003445,0.003295,0.083696,247.581406,12.612398,0.836958,-415.363129,0.083713,0.000000
69.110001,55.608986,-415.363129,0.003436,0.003295,0.083696,247.361130,12.601176,0.836958,-415.363129,0.083713,0.000000
69.310005,55.556480,-415.363129,0.003454,0.003295,0.083696,247.127563,12.589279,0.836958,-415.363129,0.083713,0.000000
69.510002,55.516266,-415.318634,0.003441,0.003295,0.083696,246.948685,12.580166,0.836958,-415.318634,0.083713,0.000000
69.710007,55.490944,-415.363129,0.003454,0.003295,0.083696,246.836044,12.574428,0.836958,-415.363129,0.083713,0.000000
69.910004,55.441048,-415.363129,0.003458,0.003295,0.083696,246.614090,12.563121,0.836958,-415.363129,0.083713,0.000000
70.110001,55.398224,-415.318634,0.003454,0.003295,0.083696,246.423615,12.553417,0.836958,-415.318634,0.083713,0.000000
70.310005,55.364708,-415.407593,0.003445,0.003295,0.083696,246.274521,12.545822,0.836958,-415.407593,0.083713,0.000000
70.510002,55.336037,-415.318634,0.003441,0.003295,0.083696,246.146988,12.539325,0.836958,-415.318634,0.083713,0.000000
70.710007,55.311829,-415.452087,0.003449,0.003295,0.083696,246.039307,12.533840,0.836958,-415.452087,0.083713,0.000000
70.910004,55.269379,-415.452087,0.003432,0.003295,0.083696,245.850479,12.524220,0.836958,-415.452087,0.083713,0.000000
71.110001,55.221344,-415.407593,0.003449,0.003295,0.083696,245.636810,12.513335,0.836958,-415.407593,0.083713,0.000000
71.310005,55.172935,-415.452087,0.003454,0.003295,0.083696,245.421478,12.502366,0.836958,-415.452087,0.083713,0.000000
71.510002,55.147614,-415.407593,0.003441,0.003295,0.083696,245.308838,12.496628,0.836958,-415.407593,0.083713,0.000000
71.710007,55.110748,-415.407593,0.003445,0.003295,0.083696,245.144852,12.488275,0.836958,-415.407593,0.083713,0.000000
71.910004,55.083939,-415.452087,0.003454,0.003295,0.083696,245.025589,12.482199,0.836958,-415.452087,0.083713,0.000000
72.110001,55.049683,-415.407593,0.003449,0.003295,0.083696,244.873215,12.474436,0.836958,-415.407593,0.083713,0.000000
72.310005,55.020638,-415.407593,0.003441,0.003295,0.083696,244.744019,12.467855,0.836958,-415.407593,0.083713,0.000000
72.510002,54.988983,-415.496552,0.003445,0.003295,0.083696,244.603210,12.460681,0.836958,-415.496552,0.083713,0.000000
72.710007,54.958450,-415.496552,0.003441,0.003295,0.083696,244.467392,12.453763,0.836958,-415.496552,0.083713,0.000000
72.910004,54.934990,-415.496552,0.003454,0.003295,0.083696,244.363037,12.448446,0.836958,-415.496552,0.083713,0.000000
73.110001,54.881371,-415.496552,0.003441,0.003295,0.083696,244.124527,12.436296,0.836958,-415.496552,0.083713,0.000000
73.310005,54.849716,-415.452087,0.003449,0.003295,0.083696,243.983719,12.429123,0.836958,-415.452087,0.083713,0.000000
73.510002,54.818062,-415.452087,0.003436,0.003295,0.083696,243.842911,12.421950,0.836958,-415.452087,0.083713,0.000000
73.710007,54.796097,-415.496552,0.003458,0.003295,0.083696,243.745209,12.416973,0.836958,-415.496552,0.083713,0.000000
73.910004,54.765930,-415.452087,0.003454,0.003295,0.083696,243.611023,12.410137,0.836958,-415.452087,0.083713,0.000000
74.110001,54.735023,-415.541046,0.003449,0.003295,0.083696,243.473541,12.403133,0.836958,-415.541046,0.083713,0.000000
74.310005,54.698906,-415.496552,0.003449,0.003295,0.083696,243.312881,12.394949,0.836958,-415.496552,0.083713,0.000000
74.510002,54.678795,-415.452087,0.003445,0.003295,0.083696,243.223434,12.390391,0.836958,-415.452087,0.083713,0.000000
74.710007,54.657570,-415.496552,0.003441,0.003295,0.083696,243.129013,12.385582,0.836958,-415.496552,0.083713,0.000000
74.910004,54.614006,-415.452087,0.003445,0.003295,0.083696,242.935226,12.375711,0.836958,-415.452087,0.083713,0.000000
75.110001,54.593895,-415.496552,0.003441,0.003295,0.083696,242.845779,12.371154,0.836958,-415.496552,0.083713,0.000000
75.310005,54.569321,-415.496552,0.003458,0.003295,0.083696,242.736465,12.365585,0.836958,-415.496552,0.083713,0.000000
75.510002,54.538414,-415.541046,0.003449,0.003295,0.083696,242.598984,12.358581,0.836958,-415.541046,0.083713,0.000000
75.710007,54.523521,-415.541046,0.003458,0.003295,0.083696,242.532730,12.355206,0.836958,-415.541046,0.083713,0.000000
75.910004,54.487396,-415.496552,0.003445,0.003295,0.083696,242.372040,12.347020,0.836958,-415.496552,0.083713,0.000000
76.110001,54.474365,-415.496552,0.003441,0.003295,0.083696,242.314072,12.344068,0.836958,-415.496552,0.083713,0.000000
76.310005,54.428940,-415.541046,0.003462,0.003295,0.083696,242.112015,12.333775,0.836958,-415.541046,0.083713,0.000000
76.510002,54.413300,-415.585541,0.003458,0.003295,0.083696,242.042450,12.330230,0.836958,-415.585541,0.083713,0.000000
76.710007,54.389465,-415.541046,0.003458,0.003295,0.083696,241.936432,12.324829,0.836958,-415.541046,0.083713,0.000000
76.910004,54.356323,-415.585541,0.003454,0.003295,0.083696,241.789001,12.317319,0.836958,-415.585541,0.083713,0.000000
77.110001,54.328026,-415.541046,0.003454,0.003295,0.083696,241.663132,12.310906,0.836958,-415.541046,0.083713,0.000000
77.310005,54.306801,-415.541046,0.003458,0.003295,0.083696,241.568710,12.306097,0.836958,-415.541046,0.083713,0.000000
77.510002,54.284454,-415.541046,0.003441,0.003295,0.083696,241.469315,12.301033,0.836958,-415.541046,0.083713,0.000000
77.710007,54.272537,-415.541046,0.003445,0.003295,0.083696,241.416306,12.298333,0.836958,-415.541046,0.083713,0.000000
77.910004,54.259506,-415.541046,0.003454,0.003295,0.083696,241.358337,12.295380,0.836958,-415.541046,0.083713,0.000000
78.110001,54.223389,-415.541046,0.003449,0.003295,0.083696,241.197678,12.287195,0.836958,-415.541046,0.083713,0.000000
78.310005,54.202904,-415.585541,0.003458,0.003295,0.083696,241.106552,12.282554,0.836958,-415.585541,0.083713,0.000000
78.510002,54.170883,-415.585541,0.003436,0.003295,0.083696,240.964127,12.275297,0.836958,-415.585541,0.083713,0.000000
78.710007,54.148911,-415.541046,0.003441,0.003295,0.083696,240.866379,12.270319,0.836958,-415.541046,0.083713,0.000000
78.910004,54.129547,-415.541046,0.003441,0.003295,0.083696,240.780258,12.265930,0.836958,-415.541046,0.083713,0.000000
79.110001,54.101990,-415.630005,0.003454,0.003295,0.083696,240.657669,12.259686,0.836958,-415.630005,0.083713,0.000000
79.310005,54.082260,-415.630005,0.003449,0.003295,0.083696,240.569901,12.255215,0.836958,-415.630005,0.083713,0.000000
79.510002,54.058052,-415.630005,0.003449,0.003295,0.083696,240.462219,12.249730,0.836958,-415.630005,0.083713,0.000000
79.710007,54.056938,-415.585541,0.003454,0.003295,0.083696,240.457275,12.249477,0.836958,-415.585541,0.083713,0.000000
79.910004,54.021935,-415.674500,0.003449,0.003295,0.083696,240.301559,12.241546,0.836958,-415.674500,0.083713,0.000000
80.110001,53.993263,-415.674500,0.003454,0.003295,0.083696,240.174026,12.235048,0.836958,-415.674500,0.083713,0.000000
80.310005,53.978363,-415.630005,0.003454,0.003295,0.083696,240.107758,12.231672,0.836958,-415.630005,0.083713,0.000000
80.510002,53.955276,-415.585541,0.003445,0.003295,0.083696,240.005051,12.226440,0.836958,-415.585541,0.083713,0.000000
80.710007,53.932938,-415.763458,0.003441,0.003295,0.083696,239.905685,12.221378,0.836958,-415.763458,0.083713,0.000000
80.910004,53.918785,-415.674500,0.003458,0.003295,0.083696,239.842728,12.218171,0.836958,-415.674500,0.083713,0.000000
81.110001,53.890488,-415.630005,0.003449,0.003295,0.083696,239.716858,12.211760,0.836958,-415.630005,0.083713,0.000000
81.310005,53.861069,-415.674500,0.003458,0.003295,0.083696,239.585999,12.205092,0.836958,-415.674500,0.083713,0.000000
81.510002,53.857346,-415.718964,0.003462,0.003295,0.083696,239.569443,12.204248,0.836958,-415.718964,0.083713,0.000000
81.710007,53.842079,-415.674500,0.003449,0.003295,0.083696,239.501526,12.200790,0.836958,-415.674500,0.083713,0.000000
81.910004,53.821968,-415.674500,0.003436,0.003295,0.083696,239.412064,12.196233,0.836958,-415.674500,0.083713,0.000000
82.110001,53.791809,-415.674500,0.003436,0.003295,0.083696,239.277924,12.189399,0.836958,-415.674500,0.083713,0.000000
82.310005,53.760529,-415.674500,0.003445,0.003295,0.083696,239.138779,12.182310,0.836958,-415.674500,0.083713,0.000000
82.510002,53.745636,-415.718964,0.003462,0.003295,0.083696,239.072525,12.178935,0.836958,-415.718964,0.083713,0.000000
82.710007,53.726639,-415.674500,0.003462,0.003295,0.083696,238.988022,12.174630,0.836958,-415.674500,0.083713,0.000000
82.910004,53.709137,-415.718964,0.003454,0.003295,0.083696,238.910172,12.170664,0.836958,-415.718964,0.083713,0.000000
83.110001,53.692757,-415.674500,0.003458,0.003295,0.083696,238.837311,12.166953,0.836958,-415.674500,0.083713,0.000000
83.300003,53.677490,-415.674500,0.003466,0.003295,0.083696,238.769409,12.163493,0.836958,-415.674500,0.083713,0.000000