File: Data/compression 5/AutoNoheating-17-5-2-240223_02232024_194752.csv
Time (sec),S:Load (lbs),S:HL1 (DIM),S:LVDT (in),S:Position (in),Ch:Position (mm),Ch:Load (N),Ch:Stress (MPa),Ch:Strain (mm/mm),Ch:HL1 (DIM),Set Point (),Cycles ()
0.110000,-0.006332,-410.559174,0.000000,-0.000000,-0.000000,-0.028168,-0.001435,-0.000000,-410.559174,0.000208,0.000000
0.340000,-0.003349,-410.514709,-0.000004,-0.000000,-0.000000,-0.014898,-0.000759,-0.000000,-410.514709,0.000208,0.000000
0.570000,-0.005585,-410.514709,-0.000009,0.000104,0.002645,-0.024842,-0.001266,0.026449,-410.514709,0.003347,0.000000
0.800000,-0.053993,-410.514709,0.000108,0.000243,0.006166,-0.240174,-0.012235,0.061660,-410.514709,0.007181,0.000000
1.030000,-0.067772,-410.559174,0.000259,0.000396,0.010051,-0.301465,-0.015357,0.100510,-410.559174,0.011014,0.000000
1.260000,0.001114,-410.603668,0.000410,0.000548,0.013910,0.004955,0.000252,0.139102,-410.603668,0.014847,0.000000
1.490000,0.025696,-410.603668,0.000556,0.000694,0.017631,0.114301,0.005823,0.176306,-410.603668,0.018680,0.000000
1.720000,0.023834,-410.514709,0.000707,0.000844,0.021438,0.106020,0.005401,0.214376,-410.514709,0.022513,0.000000
1.950000,-0.001488,-410.559174,0.000849,0.000996,0.025297,-0.006618,-0.000337,0.252969,-410.559174,0.026346,0.000000
2.180000,0.002235,-410.648132,0.001013,0.001144,0.029061,0.009944,0.000507,0.290606,-410.648132,0.030179,0.000000
2.410000,-0.001122,-410.603668,0.001168,0.001296,0.032920,-0.004989,-0.000254,0.329199,-410.603668,0.034013,0.000000
2.640000,0.004837,-410.603668,0.001319,0.001448,0.036779,0.021516,0.001096,0.367790,-410.603668,0.037846,0.000000
2.870000,-0.016754,-410.603668,0.001444,0.001600,0.040638,-0.074526,-0.003797,0.406380,-410.603668,0.041679,0.000000
3.100000,-0.012665,-410.514709,0.001647,0.001757,0.044636,-0.056336,-0.002870,0.446360,-410.514709,0.045495,0.000000
3.330000,-0.054741,-410.648132,0.001768,0.001902,0.048313,-0.243500,-0.012404,0.483130,-410.648132,0.049328,0.000000
3.560000,0.002235,-410.603668,0.001910,0.002049,0.052051,0.009944,0.000507,0.520506,-410.603668,0.053161,0.000000
3.790000,0.014893,-410.603668,0.002065,0.002205,0.056005,0.066245,0.003375,0.560055,-410.603668,0.056994,0.000000
4.020000,0.035744,-410.603668,0.002203,0.002349,0.059665,0.158996,0.008100,0.596651,-410.603668,0.060827,0.000000
4.250000,0.012291,-410.648132,0.002389,0.002505,0.063637,0.054673,0.002785,0.636370,-410.648132,0.064660,0.000000
4.480000,-0.017502,-410.603668,0.002557,0.002656,0.067461,-0.077852,-0.003966,0.674612,-410.603668,0.068493,0.000000
4.710000,-0.019363,-410.692627,0.002690,0.002804,0.071234,-0.086133,-0.004388,0.712340,-410.692627,0.072327,0.000000
4.940000,-0.013779,-410.648132,0.002841,0.002959,0.075154,-0.061291,-0.003122,0.751536,-410.648132,0.076160,0.000000
5.170000,0.000740,-410.603668,0.002997,0.003107,0.078909,0.003292,0.000168,0.789086,-410.603668,0.079993,0.000000
5.400000,-0.021973,-410.648132,0.003165,0.003262,0.082855,-0.097739,-0.004979,0.828548,-410.648132,0.083826,0.000000
5.630000,0.010796,-410.692627,0.003298,0.003408,0.086575,0.048021,0.002446,0.865749,-410.692627,0.087659,0.000000
5.860000,-0.023834,-410.737091,0.003458,0.003560,0.090417,-0.106020,-0.005401,0.904170,-410.737091,0.091475,0.000000
6.090000,0.003349,-410.603668,0.003613,0.003713,0.094302,0.014898,0.000759,0.943022,-410.603668,0.095308,0.000000
6.320000,0.004097,-410.603668,0.003760,0.003862,0.098100,0.018224,0.000928,0.981003,-410.603668,0.099141,0.000000
6.550000,0.013405,-410.692627,0.003898,0.004005,0.101734,0.059628,0.003038,1.017342,-410.692627,0.102974,0.000000
6.780000,-0.012291,-410.692627,0.004074,0.004166,0.105828,-0.054673,-0.002785,1.058276,-410.692627,0.106807,0.000000
7.010000,-0.036118,-410.692627,0.004230,0.004314,0.109565,-0.160659,-0.008184,1.095651,-410.692627,0.110640,0.000000
7.240000,-0.034630,-410.648132,0.004363,0.004462,0.113329,-0.154041,-0.007847,1.133288,-410.648132,0.114474,0.000000
7.470000,-0.000748,-410.648132,0.004540,0.004619,0.117318,-0.003326,-0.000169,1.173181,-410.648132,0.118307,0.000000
7.700000,0.033882,-410.692627,0.004691,0.004763,0.120986,0.150715,0.007678,1.209864,-410.692627,0.122140,0.000000
7.930000,0.010796,-410.781586,0.004829,0.004917,0.124889,0.048021,0.002446,1.248890,-410.781586,0.125973,0.000000
8.160001,-0.013779,-410.737091,0.004980,0.005072,0.128818,-0.061291,-0.003122,1.288178,-410.737091,0.129806,0.000000
8.390000,-0.000000,-410.692627,0.005135,0.005219,0.132573,-0.000000,-0.000000,1.325728,-410.692627,0.133639,0.000000
8.620001,0.020103,-410.692627,0.005312,0.005374,0.136501,0.089425,0.004556,1.365011,-410.692627,0.137473,0.000000
8.850000,0.023834,-410.648132,0.005445,0.005514,0.140048,0.106020,0.005401,1.400483,-410.648132,0.141288,0.000000
9.080001,0.006332,-410.781586,0.005583,0.005671,0.144038,0.028168,0.001435,1.440376,-410.781586,0.145122,0.000000
9.310000,-0.008194,-410.781586,0.005747,0.005827,0.148001,-0.036449,-0.001857,1.480008,-410.781586,0.148955,0.000000
9.540001,-0.056976,-410.692627,0.005898,0.005972,0.151678,-0.253443,-0.012911,1.516778,-410.692627,0.152788,0.000000
9.770000,0.000374,-410.737091,0.006058,0.006124,0.155554,0.001663,0.000085,1.555543,-410.737091,0.156621,0.000000
10.000000,0.038727,-410.692627,0.006222,0.006276,0.159413,0.172265,0.008776,1.594133,-410.692627,0.160454,0.000000
10.230000,0.044685,-410.781586,0.006342,0.006419,0.163039,0.198770,0.010126,1.630385,-410.781586,0.164287,0.000000
10.460000,0.035378,-410.737091,0.006510,0.006579,0.167106,0.157367,0.008017,1.671058,-410.737091,0.168120,0.000000
10.690001,0.013405,-410.781586,0.006661,0.006728,0.170896,0.059628,0.003038,1.708956,-410.781586,0.171953,0.000000
10.920000,0.009682,-410.781586,0.006817,0.006874,0.174598,0.043066,0.002194,1.745983,-410.781586,0.175786,0.000000
11.150001,0.025322,-410.781586,0.006963,0.007024,0.178414,0.112638,0.005738,1.784143,-410.781586,0.179620,0.000000
11.380000,0.023834,-410.826050,0.007110,0.007176,0.182265,0.106020,0.005401,1.822646,-410.826050,0.183453,0.000000
11.610001,0.009308,-410.826050,0.007256,0.007337,0.186349,0.041403,0.002109,1.863493,-410.826050,0.187286,0.000000
11.840000,-0.017876,-410.737091,0.007416,0.007486,0.190139,-0.079515,-0.004051,1.901391,-410.737091,0.191102,0.000000
12.070001,0.019363,-410.737091,0.007562,0.007630,0.193799,0.086133,0.004388,1.937987,-410.737091,0.194935,0.000000
12.300000,0.033516,-410.737091,0.007726,0.007786,0.197762,0.149086,0.007595,1.977619,-410.737091,0.198768,0.000000
12.530001,0.057343,-410.870544,0.007860,0.007932,0.201474,0.255072,0.012994,2.014737,-410.870544,0.202601,0.000000
12.760000,0.041702,-410.870544,0.008006,0.008081,0.205255,0.185501,0.009450,2.052549,-410.870544,0.206434,0.000000
12.990001,0.032021,-410.826050,0.008170,0.008237,0.209209,0.142435,0.007256,2.092093,-410.826050,0.210268,0.000000
13.220000,0.003723,-410.737091,0.008326,0.008386,0.213017,0.016561,0.000844,2.130165,-410.737091,0.214101,0.000000
13.450001,0.036865,-410.781586,0.008481,0.008534,0.216772,0.163985,0.008354,2.167715,-410.781586,0.217934,0.000000
13.680000,0.051758,-410.781586,0.008636,0.008687,0.220648,0.230230,0.011728,2.206480,-410.781586,0.221767,0.000000
13.910001,0.129211,-410.781586,0.008774,0.008836,0.224447,0.574761,0.029280,2.244465,-410.781586,0.225600,0.000000
14.140000,0.682182,-410.826050,0.008890,-0.000005,-0.000121,3.034498,0.154585,-0.001215,-410.826050,0.000069,0.000000
14.370001,0.625954,-410.781586,0.008899,-0.000006,-0.000147,2.784381,0.141843,-0.001472,-410.781586,0.000069,0.000000
14.600000,0.579407,-410.826050,0.008886,-0.000006,-0.000147,2.577330,0.131295,-0.001472,-410.826050,0.000087,0.000000
14.830001,0.602867,-410.870544,0.008903,-0.000005,-0.000139,2.681687,0.136612,-0.001385,-410.870544,0.000468,0.000000
15.060000,0.604729,-410.870544,0.008903,-0.000005,-0.000130,2.689968,0.137033,-0.001302,-410.870544,0.000850,0.000000
15.290001,0.792778,-410.915039,0.008890,0.000014,0.000364,3.526453,0.179646,0.003645,-410.915039,0.001232,0.000000
15.520000,0.946571,-410.826050,0.008912,0.000031,0.000780,4.210560,0.214496,0.007804,-410.826050,0.001622,0.000000
15.750001,1.075035,-410.870544,0.008921,0.000043,0.001084,4.781995,0.243606,0.010840,-410.870544,0.002003,0.000000
15.980000,1.286545,-410.915039,0.008951,0.000059,0.001509,5.722837,0.291535,0.015090,-410.915039,0.002385,0.000000
16.210001,1.454857,-410.915039,0.008955,0.000072,0.001821,6.471527,0.329675,0.018213,-410.915039,0.002766,0.000000
16.440001,1.761696,-410.915039,0.008981,0.000094,0.002385,7.836414,0.399206,0.023849,-410.915039,0.003157,0.000000
16.670000,1.974693,-410.915039,0.008981,0.000109,0.002758,8.783875,0.447472,0.027577,-410.915039,0.003538,0.000000
16.900002,2.145981,-410.915039,0.009020,0.000119,0.003027,9.545799,0.486286,0.030268,-410.915039,0.003920,0.000000
17.130001,2.337753,-410.959503,0.009002,0.000134,0.003408,10.398846,0.529742,0.034083,-410.959503,0.004302,0.000000
17.360001,2.637512,-410.915039,0.009033,0.000150,0.003816,11.732241,0.597669,0.038159,-410.915039,0.004683,0.000000
17.590000,2.897057,-410.915039,0.009050,0.000166,0.004215,12.886751,0.656482,0.042149,-410.915039,0.005073,0.000000
17.820002,3.075798,-410.915039,0.009063,0.000179,0.004536,13.681833,0.696986,0.045358,-410.915039,0.005455,0.000000
18.050001,3.383003,-411.003998,0.009071,0.000196,0.004969,15.048350,0.766599,0.049692,-411.003998,0.005837,0.000000
18.280001,3.604935,-410.915039,0.009071,0.000209,0.005316,16.035551,0.816890,0.053163,-410.915039,0.006218,0.000000
18.510000,3.893898,-410.915039,0.009084,0.000226,0.005741,17.320923,0.882370,0.057409,-410.915039,0.006600,0.000000
18.740002,4.199989,-410.959503,0.009119,0.000243,0.006166,18.682486,0.951731,0.061660,-410.959503,0.006990,0.000000
18.970001,4.323242,-410.959503,0.009119,0.000252,0.006392,19.230742,0.979661,0.063916,-410.959503,0.007371,0.000000
19.200001,4.673271,-411.003998,0.009127,0.000270,0.006851,20.787748,1.058978,0.068510,-411.003998,0.007753,0.000000
19.430000,5.006172,-410.959503,0.009140,0.000287,0.007293,22.268566,1.134415,0.072935,-410.959503,0.008134,0.000000
19.660002,5.231834,-410.959503,0.009171,0.000304,0.007719,23.272362,1.185551,0.077185,-410.959503,0.008516,0.000000
19.890001,5.355835,-410.959503,0.009184,0.000318,0.008065,23.823944,1.213650,0.080652,-410.959503,0.008907,0.000000
20.120001,5.587822,-411.003998,0.009179,0.000332,0.008429,24.855873,1.266219,0.084293,-411.003998,0.009288,0.000000
20.350000,5.824646,-411.003998,0.009196,0.000347,0.008820,25.909319,1.319884,0.088199,-411.003998,0.009670,0.000000
20.580002,6.036156,-411.048462,0.009201,0.000359,0.009106,26.850161,1.367812,0.091061,-411.048462,0.010051,0.000000
20.810001,6.291229,-410.959503,0.009240,0.000376,0.009539,27.984785,1.425613,0.095394,-410.959503,0.010433,0.000000
21.040001,6.433853,-410.915039,0.009227,0.000391,0.009930,28.619207,1.457932,0.099297,-410.915039,0.010823,0.000000
21.270000,6.792076,-411.003998,0.009261,0.000410,0.010424,30.212664,1.539106,0.104240,-411.003998,0.011205,0.000000
21.500002,6.895218,-411.048462,0.009265,0.000421,0.010702,30.671461,1.562479,0.107018,-411.048462,0.011586,0.000000
21.730001,7.085129,-411.003998,0.009283,0.000438,0.011126,31.516228,1.605513,0.111265,-411.003998,0.011968,0.000000
21.960001,7.288071,-411.003998,0.009296,0.000454,0.011543,32.418957,1.651500,0.115428,-411.003998,0.012349,0.000000
22.190001,7.443352,-411.003998,0.009313,0.000468,0.011899,33.109684,1.686688,0.118986,-411.003998,0.012740,0.000000
22.420002,7.543144,-411.048462,0.009334,0.000483,0.012263,33.553581,1.709301,0.122627,-411.048462,0.013121,0.000000
22.650002,7.731567,-411.048462,0.009339,0.000498,0.012653,34.391731,1.751998,0.126529,-411.048462,0.013503,0.000000
22.880001,7.645920,-411.048462,0.009347,0.000504,0.012809,34.010750,1.732590,0.128088,-411.048462,0.013885,0.000000
23.110001,8.163147,-411.003998,0.009365,0.000530,0.013451,36.311493,1.849796,0.134508,-411.003998,0.014266,0.000000
23.340002,8.264809,-411.092957,0.009378,0.000546,0.013858,36.763706,1.872832,0.138584,-411.092957,0.014656,0.000000
23.570002,8.341141,-411.048462,0.009386,0.000559,0.014188,37.103249,1.890129,0.141881,-411.048462,0.015038,0.000000
23.800001,8.381729,-411.137421,0.009399,0.000572,0.014526,37.283794,1.899327,0.145260,-411.137421,0.015419,0.000000
24.030001,8.380989,-411.048462,0.009429,0.000586,0.014873,37.280502,1.899159,0.148731,-411.048462,0.015801,0.000000
24.260000,8.734741,-411.092957,0.009438,0.000605,0.015359,38.854069,1.979321,0.153587,-411.092957,0.016191,0.000000
24.490002,8.765648,-411.003998,0.009438,0.000620,0.015740,38.991550,1.986324,0.157402,-411.003998,0.016573,0.000000
24.720001,8.817406,-411.048462,0.009464,0.000633,0.016070,39.221779,1.998053,0.160699,-411.048462,0.016954,0.000000
24.950001,8.716866,-411.092957,0.009490,0.000640,0.016261,38.774555,1.975270,0.162607,-411.092957,0.017336,0.000000
25.180000,9.174515,-411.092957,0.009481,0.000663,0.016842,40.810280,2.078975,0.168416,-411.092957,0.017717,0.000000
25.410002,9.174141,-411.048462,0.009485,0.000676,0.017163,40.808617,2.078890,0.171626,-411.048462,0.018108,0.000000
25.640001,9.319740,-411.092957,0.009516,0.000694,0.017631,41.456276,2.111883,0.176308,-411.092957,0.018489,0.000000
25.870001,9.307449,-411.092957,0.009524,0.000707,0.017952,41.401604,2.109098,0.179518,-411.092957,0.018871,0.000000
26.100000,9.431824,-411.181915,0.009550,0.000723,0.018368,41.954845,2.137282,0.183681,-411.181915,0.019253,0.000000
26.330002,9.594177,-411.137421,0.009563,0.000738,0.018741,42.677032,2.174072,0.187409,-411.137421,0.019634,0.000000
26.560001,9.498848,-411.048462,0.009572,0.000748,0.019001,42.252987,2.152470,0.190009,-411.048462,0.020024,0.000000
26.790001,9.668274,-411.092957,0.009593,0.000764,0.019400,43.006630,2.190862,0.193999,-411.092957,0.020406,0.000000
27.020000,9.931915,-411.137421,0.009597,0.000784,0.019912,44.179367,2.250604,0.199116,-411.137421,0.020787,0.000000
27.250002,10.027618,-411.181915,0.009623,0.000799,0.020302,44.605076,2.272291,0.203018,-411.181915,0.021169,0.000000
27.480001,10.030968,-411.137421,0.009641,0.000815,0.020692,44.619972,2.273050,0.206920,-411.137421,0.021551,0.000000
27.710001,10.076027,-411.092957,0.009649,0.000829,0.021048,44.820408,2.283260,0.210478,-411.092957,0.021941,0.000000
27.940001,10.140816,-411.092957,0.009666,0.000841,0.021368,45.108601,2.297942,0.213684,-411.092957,0.022323,0.000000
28.170002,10.222366,-411.181915,0.009675,0.000856,0.021742,45.471355,2.316421,0.217416,-411.181915,0.022704,0.000000
28.400002,10.215294,-411.181915,0.009684,0.000869,0.022071,45.439896,2.314819,0.220709,-411.181915,0.023086,0.000000
28.630001,10.541115,-411.137421,0.009688,0.000888,0.022556,46.889221,2.388651,0.225565,-411.137421,0.023467,0.000000
28.860001,10.567932,-411.092957,0.009714,0.000903,0.022930,47.008511,2.394728,0.229297,-411.092957,0.023857,0.000000
29.090002,10.905296,-411.137421,0.009735,0.000924,0.023476,48.509182,2.471175,0.234758,-411.137421,0.024239,0.000000
29.320002,10.718742,-411.137421,0.009744,0.000933,0.023701,47.679348,2.428902,0.237014,-411.137421,0.024621,0.000000
29.550001,10.764168,-411.137421,0.009757,0.000948,0.024092,47.881409,2.439195,0.240916,-411.137421,0.025002,0.000000
29.780001,10.751137,-411.181915,0.009774,0.000961,0.024421,47.823444,2.436242,0.244213,-411.181915,0.025384,0.000000
30.010002,10.924294,-411.137421,0.009787,0.000976,0.024785,48.593685,2.475480,0.247854,-411.137421,0.025774,0.000000
30.240002,11.095955,-411.226379,0.009804,0.000993,0.025210,49.357273,2.514379,0.252104,-411.226379,0.026156,0.000000
30.470001,11.056480,-411.226379,0.009813,0.001006,0.025540,49.181683,2.505434,0.255397,-411.226379,0.026537,0.000000
30.700001,11.139153,-411.270874,0.009822,0.001017,0.025826,49.549423,2.524168,0.258262,-411.270874,0.026919,0.000000
30.930002,11.550247,-411.181915,0.009839,0.001040,0.026407,51.378067,2.617323,0.264072,-411.181915,0.027300,0.000000
31.160002,11.744629,-411.181915,0.009865,0.001059,0.026902,52.242718,2.661371,0.269015,-411.181915,0.027691,0.000000
31.390001,11.604614,-411.226379,0.009899,0.001072,0.027222,51.619904,2.629643,0.272221,-411.226379,0.028072,0.000000
31.620001,11.628822,-411.226379,0.009891,0.001085,0.027560,51.727585,2.635129,0.275605,-411.226379,0.028454,0.000000
31.850002,11.692863,-411.181915,0.009899,0.001097,0.027864,52.012455,2.649641,0.278640,-411.181915,0.028835,0.000000
32.080002,11.696220,-411.226379,0.009912,0.001110,0.028202,52.027386,2.650401,0.282024,-411.226379,0.029217,0.000000
32.310001,11.952042,-411.226379,0.009934,0.001127,0.028636,53.165337,2.708371,0.286358,-411.226379,0.029607,0.000000
32.540001,12.197807,-411.315369,0.009947,0.001146,0.029113,54.258556,2.764063,0.291127,-411.315369,0.029989,0.000000
32.770000,12.282333,-411.315369,0.009973,0.001161,0.029486,54.634548,2.783216,0.294858,-411.315369,0.030370,0.000000
33.000000,12.532570,-411.270874,0.009977,0.001181,0.029989,55.747654,2.839921,0.299889,-411.270874,0.030752,0.000000
33.230003,12.477829,-411.315369,0.009998,0.001195,0.030362,55.504154,2.827517,0.303617,-411.315369,0.031142,0.000000
33.460003,12.374306,-411.270874,0.010011,0.001206,0.030630,55.043659,2.804058,0.306304,-411.270874,0.031524,0.000000
33.690002,12.663643,-411.315369,0.010033,0.001224,0.031099,56.330696,2.869622,0.310990,-411.315369,0.031905,0.000000
33.920002,12.636086,-411.315369,0.010042,0.001237,0.031428,56.208115,2.863378,0.314283,-411.315369,0.032287,0.000000
34.150002,12.911270,-411.270874,0.010063,0.001255,0.031879,57.432198,2.925736,0.318794,-411.270874,0.032669,0.000000
34.380001,12.845360,-411.226379,0.010072,0.001267,0.032174,57.139015,2.910800,0.321743,-411.226379,0.033059,0.000000
34.610001,12.879990,-411.270874,0.010085,0.001282,0.032564,57.293056,2.918648,0.325645,-411.270874,0.033440,0.000000
34.840000,13.268745,-411.315369,0.010106,0.001301,0.033041,59.022327,3.006741,0.330414,-411.315369,0.033822,0.000000
35.070004,13.428123,-411.315369,0.010106,0.001317,0.033449,59.731277,3.042856,0.334490,-411.315369,0.034203,0.000000
35.300003,13.359230,-411.315369,0.010132,0.001331,0.033796,59.424824,3.027245,0.337957,-411.315369,0.034585,0.000000
35.530003,13.302635,-411.270874,0.010141,0.001340,0.034047,59.173077,3.014420,0.340474,-411.270874,0.034975,0.000000
35.760002,13.556961,-411.270874,0.010162,0.001357,0.034472,60.304375,3.072051,0.344724,-411.270874,0.035357,0.000000
35.990002,13.733467,-411.359833,0.010167,0.001374,0.034897,61.089512,3.112048,0.348971,-411.359833,0.035738,0.000000
36.220001,13.849274,-411.359833,0.010175,0.001388,0.035244,61.604645,3.138290,0.352442,-411.359833,0.036120,0.000000
36.450001,13.835129,-411.359833,0.010188,0.001400,0.035556,61.541725,3.135085,0.355564,-411.359833,0.036502,0.000000
36.680000,13.912582,-411.270874,0.010218,0.001416,0.035955,61.886257,3.152636,0.359554,-411.270874,0.036892,0.000000
36.910000,14.206757,-411.359833,0.010214,0.001432,0.036380,63.194809,3.219297,0.363800,-411.359833,0.037273,0.000000
37.140003,14.218666,-411.359833,0.010244,0.001446,0.036718,63.247784,3.221996,0.367184,-411.359833,0.037655,0.000000
37.370003,14.398521,-411.404327,0.010244,0.001460,0.037091,64.047821,3.262752,0.370912,-411.404327,0.038037,0.000000
37.600002,14.344528,-411.315369,0.010257,0.001474,0.037447,63.807648,3.250517,0.374470,-411.315369,0.038418,0.000000
37.830002,14.839043,-411.270874,0.010274,0.001494,0.037959,66.007355,3.362575,0.379587,-411.270874,0.038808,0.000000
38.060001,14.932137,-411.359833,0.010287,0.001509,0.038340,66.421463,3.383671,0.383402,-411.359833,0.039190,0.000000
38.290001,14.787285,-411.448792,0.010309,0.001520,0.038618,65.777130,3.350847,0.386177,-411.448792,0.039571,0.000000
38.520000,14.920593,-411.404327,0.010317,0.001536,0.039017,66.370117,3.381055,0.390166,-411.404327,0.039953,0.000000
38.750000,15.092628,-411.404327,0.010339,0.001549,0.039338,67.135361,3.420039,0.393375,-411.404327,0.040335,0.000000
38.980003,15.257217,-411.359833,0.010352,0.001565,0.039745,67.867493,3.457335,0.397452,-411.359833,0.040725,0.000000
39.210003,15.502609,-411.359833,0.010369,0.001584,0.040239,68.959053,3.512941,0.402395,-411.359833,0.041107,0.000000
39.440002,15.609482,-411.493286,0.010378,0.001598,0.040586,69.434441,3.537159,0.405862,-411.493286,0.041488,0.000000
39.670002,15.803116,-411.493286,0.010378,0.001616,0.041046,70.295769,3.581037,0.410461,-411.493286,0.041870,0.000000
39.900002,16.061539,-411.404327,0.010408,0.001633,0.041471,71.445290,3.639597,0.414707,-411.404327,0.042251,0.000000
40.130001,16.054466,-411.404327,0.010421,0.001645,0.041792,71.413834,3.637994,0.417917,-411.404327,0.042641,0.000000
40.360001,15.810936,-411.404327,0.010438,0.001654,0.042000,70.330559,3.582809,0.419998,-411.404327,0.043023,0.000000
40.590000,16.187027,-411.493286,0.010455,0.001672,0.042459,72.003494,3.668033,0.424593,-411.493286,0.043405,0.000000
40.820004,16.581741,-411.448792,0.010468,0.001691,0.042954,73.759270,3.757476,0.429536,-411.448792,0.043786,0.000000
41.050003,16.778358,-411.448792,0.010477,0.001709,0.043396,74.633865,3.802030,0.433961,-411.448792,0.044168,0.000000
41.280003,16.676331,-411.448792,0.010490,0.001718,0.043647,74.180023,3.778910,0.436474,-411.448792,0.044558,0.000000
41.510002,16.681168,-411.493286,0.010503,0.001733,0.044021,74.201538,3.780007,0.440206,-411.493286,0.044940,0.000000
41.740002,17.199509,-411.493286,0.010529,0.001753,0.044515,76.507233,3.897465,0.445149,-411.493286,0.045321,0.000000
41.970001,17.114609,-411.537750,0.010529,0.001765,0.044818,76.129585,3.878226,0.448185,-411.537750,0.045703,0.000000
42.200001,17.135460,-411.448792,0.010555,0.001775,0.045087,76.222336,3.882951,0.450872,-411.448792,0.046093,0.000000
42.430000,17.604652,-411.448792,0.010559,0.001796,0.045616,78.309402,3.989271,0.456163,-411.448792,0.046475,0.000000
42.660004,17.896965,-411.448792,0.010576,0.001813,0.046041,79.609680,4.055511,0.460410,-411.448792,0.046856,0.000000
42.890003,17.845573,-411.537750,0.010593,0.001825,0.046362,79.381073,4.043865,0.463619,-411.537750,0.047238,0.000000
43.120003,18.062294,-411.582245,0.010598,0.001842,0.046787,80.345093,4.092974,0.467870,-411.582245,0.047619,0.000000
43.350002,18.191139,-411.493286,0.010615,0.001857,0.047160,80.918228,4.122171,0.471598,-411.493286,0.048009,0.000000
43.580002,18.147202,-411.448792,0.010637,0.001867,0.047429,80.722786,4.112215,0.474285,-411.448792,0.048391,0.000000
43.810001,18.534836,-411.537750,0.010641,0.001885,0.047888,82.447067,4.200054,0.478884,-411.537750,0.048773,0.000000
44.040001,18.702034,-411.537750,0.010649,0.001901,0.048279,83.190804,4.237941,0.482786,-411.537750,0.049154,0.000000
44.270000,18.376953,-411.537750,0.010658,0.001908,0.048461,81.744774,4.164277,0.484607,-411.537750,0.049536,0.000000
44.500004,19.247185,-411.493286,0.010680,0.001931,0.049059,85.615753,4.361475,0.490591,-411.493286,0.049926,0.000000
44.730003,19.474709,-411.537750,0.010701,0.001948,0.049484,86.627831,4.413032,0.494841,-411.537750,0.050308,0.000000
44.960003,19.450500,-411.537750,0.010710,0.001962,0.049831,86.520149,4.407547,0.498308,-411.537750,0.050690,0.000000
45.190002,19.665733,-411.626709,0.010705,0.001975,0.050169,87.477554,4.456319,0.501692,-411.626709,0.051071,0.000000
45.420002,19.911125,-411.626709,0.010744,0.001992,0.050594,88.569107,4.511926,0.505942,-411.626709,0.051453,0.000000
45.650002,20.160614,-411.537750,0.010762,0.002007,0.050984,89.678886,4.568460,0.509844,-411.537750,0.051843,0.000000
45.880001,20.431702,-411.582245,0.010783,0.002023,0.051392,90.884750,4.629889,0.513917,-411.582245,0.052224,0.000000
46.110001,20.249245,-411.537750,0.010779,0.002032,0.051609,90.073135,4.588545,0.516086,-411.537750,0.052606,0.000000
46.340004,20.731094,-411.626709,0.010774,0.002050,0.052077,92.216515,4.697733,0.520771,-411.626709,0.052987,0.000000
46.570004,20.991753,-411.582245,0.010800,0.002065,0.052450,93.375977,4.756799,0.524499,-411.582245,0.053369,0.000000
46.800003,21.110542,-411.537750,0.010809,0.002079,0.052814,93.904381,4.783717,0.528140,-411.537750,0.053760,0.000000
47.030003,21.502274,-411.582245,0.010839,0.002097,0.053257,95.646889,4.872485,0.532565,-411.582245,0.054141,0.000000
47.260002,21.501526,-411.626709,0.010843,0.002108,0.053551,95.643562,4.872315,0.535513,-411.626709,0.054523,0.000000
47.490002,21.964760,-411.671204,0.010839,0.002125,0.053985,97.704132,4.977285,0.539847,-411.671204,0.054904,0.000000
47.720001,22.051155,-411.626709,0.010865,0.002139,0.054323,98.088440,4.996863,0.543231,-411.626709,0.055286,0.000000
47.950001,22.325592,-411.582245,0.010869,0.002154,0.054713,99.309196,5.059052,0.547133,-411.582245,0.055676,0.000000
48.180004,22.646950,-411.671204,0.010904,0.002169,0.055104,100.738663,5.131872,0.551035,-411.671204,0.056058,0.000000
48.410004,23.269554,-411.671204,0.010895,0.002190,0.055624,103.508148,5.272956,0.556240,-411.671204,0.056439,0.000000
48.640003,23.195824,-411.715698,0.010912,0.002202,0.055928,103.180176,5.256249,0.559275,-411.715698,0.056821,0.000000
48.870003,23.677673,-411.671204,0.010930,0.002218,0.056335,105.323555,5.365438,0.563351,-411.671204,0.057202,0.000000
49.100002,23.616608,-411.626709,0.010943,0.002231,0.056673,105.051918,5.351600,0.566731,-411.626709,0.057592,0.000000
49.330002,23.860512,-411.671204,0.010960,0.002244,0.056985,106.136856,5.406869,0.569854,-411.671204,0.057974,0.000000
49.560001,24.103668,-411.671204,0.010973,0.002258,0.057350,107.218468,5.461969,0.573499,-411.671204,0.058356,0.000000
49.790001,24.056007,-411.715698,0.010973,0.002271,0.057679,107.006462,5.451169,0.576792,-411.715698,0.058737,0.000000
50.020004,24.894585,-411.626709,0.010999,0.002289,0.058139,110.736641,5.641193,0.581390,-411.626709,0.059119,0.000000
50.250004,25.141846,-411.671204,0.011003,0.002305,0.058547,111.836517,5.697224,0.585467,-411.671204,0.059509,0.000000
50.480003,26.058624,-411.671204,0.011037,0.002326,0.059093,115.914551,5.904969,0.590928,-411.671204,0.059891,0.000000
50.710003,25.995323,-411.715698,0.011042,0.002340,0.059440,115.632973,5.890625,0.594399,-411.715698,0.060272,0.000000
50.940002,26.042984,-411.715698,0.011050,0.002351,0.059717,115.844978,5.901424,0.597173,-411.715698,0.060654,0.000000
51.170002,26.056389,-411.626709,0.011059,0.002363,0.060021,115.904610,5.904462,0.600209,-411.626709,0.061044,0.000000
51.400002,26.619041,-411.715698,0.011068,0.002381,0.060472,118.407410,6.031961,0.604716,-411.715698,0.061426,0.000000
51.630001,26.990303,-411.671204,0.011094,0.002395,0.060844,120.058861,6.116090,0.608445,-411.671204,0.061807,0.000000
51.860001,26.949715,-411.715698,0.011098,0.002405,0.061087,119.878319,6.106893,0.610874,-411.715698,0.062189,0.000000
52.090004,27.151909,-411.715698,0.011102,0.002417,0.061400,120.777725,6.152711,0.613997,-411.715698,0.062570,0.000000
52.320004,28.685715,-411.715698,0.011119,0.002445,0.062111,127.600433,6.500276,0.621109,-411.715698,0.062961,0.000000
52.550003,28.970207,-411.715698,0.011137,0.002458,0.062440,128.865921,6.564743,0.624402,-411.715698,0.063342,0.000000
52.780003,29.121384,-411.760162,0.011150,0.002474,0.062830,129.538391,6.599000,0.628304,-411.760162,0.063724,0.000000
53.010002,29.252090,-411.760162,0.011150,0.002485,0.063126,130.119797,6.628618,0.631256,-411.760162,0.064106,0.000000
53.240002,29.418167,-411.760162,0.011163,0.002500,0.063490,130.858536,6.666252,0.634897,-411.760162,0.064487,0.000000
53.470001,29.994598,-411.715698,0.011175,0.002517,0.063923,133.422638,6.796873,0.639231,-411.715698,0.064877,0.000000
53.700001,30.248558,-411.715698,0.011167,0.002529,0.064244,134.552307,6.854421,0.642440,-411.715698,0.065259,0.000000
53.930004,30.847336,-411.760162,0.011193,0.002545,0.064652,137.215805,6.990106,0.646517,-411.760162,0.065640,0.000000
54.160004,31.825180,-411.804657,0.011210,0.002568,0.065233,141.565475,7.211689,0.652327,-411.804657,0.066022,0.000000
54.390003,32.231445,-411.804657,0.011223,0.002583,0.065614,143.372635,7.303750,0.656142,-411.804657,0.066404,0.000000
54.620003,32.220642,-411.760162,0.011240,0.002594,0.065892,143.324570,7.301302,0.658920,-411.760162,0.066794,0.000000
54.850002,32.490242,-411.804657,0.011249,0.002607,0.066230,144.523819,7.362394,0.662300,-411.804657,0.067175,0.000000
55.080002,33.029060,-411.760162,0.011266,0.002623,0.066620,146.920593,7.484492,0.666202,-411.760162,0.067557,0.000000
55.310001,33.825943,-411.849121,0.011270,0.002642,0.067097,150.465317,7.665069,0.670975,-411.849121,0.067938,0.000000
55.540001,34.141716,-411.804657,0.011283,0.002655,0.067444,151.869934,7.736624,0.674442,-411.804657,0.068320,0.000000
55.770004,34.309280,-411.849121,0.011296,0.002668,0.067756,152.615295,7.774594,0.677564,-411.849121,0.068710,0.000000
56.000004,35.022003,-411.804657,0.011313,0.002686,0.068216,155.785645,7.936100,0.682159,-411.804657,0.069092,0.000000
56.230003,35.841217,-411.760162,0.011322,0.002704,0.068684,159.429703,8.121736,0.686845,-411.760162,0.069474,0.000000
56.460003,36.175613,-411.849121,0.011331,0.002717,0.069014,160.917160,8.197511,0.690138,-411.849121,0.069855,0.000000
56.690002,36.436272,-411.849121,0.011344,0.002730,0.069343,162.076630,8.256577,0.693434,-411.849121,0.070237,0.000000
56.920002,36.451538,-411.804657,0.011365,0.002740,0.069595,162.144547,8.260036,0.695948,-411.804657,0.070627,0.000000
57.150002,37.135216,-411.804657,0.011365,0.002756,0.070011,165.185684,8.414960,0.700111,-411.804657,0.071008,0.000000
57.380001,37.922035,-411.893616,0.011374,0.002776,0.070523,168.685638,8.593256,0.705228,-411.893616,0.071390,0.000000
57.610004,38.322708,-411.893616,0.011387,0.002787,0.070783,170.467926,8.684050,0.707832,-411.893616,0.071772,0.000000
57.840004,38.752426,-411.893616,0.011400,0.002802,0.071165,172.379395,8.781425,0.711647,-411.893616,0.072153,0.000000
58.070004,38.951279,-411.849121,0.011413,0.002813,0.071451,173.263947,8.826486,0.714509,-411.849121,0.072544,0.000000
58.300003,40.016632,-411.804657,0.011413,0.002832,0.071945,178.002869,9.067899,0.719452,-411.804657,0.072925,0.000000
58.530003,40.532738,-411.893616,0.011434,0.002847,0.072318,180.298630,9.184850,0.723180,-411.893616,0.073307,0.000000
58.760002,41.062630,-411.893616,0.011456,0.002863,0.072708,182.655701,9.304925,0.727082,-411.893616,0.073688,0.000000
58.990002,41.718750,-411.893616,0.011434,0.002878,0.073107,185.574265,9.453604,0.731071,-411.893616,0.074070,0.000000
59.220001,42.760643,-411.849121,0.011447,0.002898,0.073619,190.208847,9.689700,0.736189,-411.849121,0.074460,0.000000
59.450005,43.088333,-411.849121,0.011482,0.002908,0.073862,191.666473,9.763956,0.738618,-411.849121,0.074842,0.000000
59.680004,43.341545,-411.893616,0.011477,0.002920,0.074174,192.792816,9.821335,0.741737,-411.893616,0.075223,0.000000
59.910004,44.060600,-411.893616,0.011490,0.002938,0.074625,195.991333,9.984275,0.746249,-411.893616,0.075605,0.000000
60.140003,44.906258,-411.893616,0.011499,0.002953,0.075015,199.753006,10.175903,0.750151,-411.893616,0.075995,0.000000
60.370003,45.590302,-411.938080,0.011516,0.002968,0.075397,202.795792,10.330911,0.753966,-411.938080,0.076377,0.000000
60.600002,46.295952,-411.893616,0.011520,0.002984,0.075804,205.934677,10.490813,0.758043,-411.893616,0.076758,0.000000
60.830002,46.932709,-411.849121,0.011538,0.002999,0.076186,208.767120,10.635104,0.761858,-411.849121,0.077140,0.000000
61.060001,47.867737,-411.938080,0.011533,0.003018,0.076654,212.926331,10.846984,0.766540,-411.938080,0.077521,0.000000
61.290005,48.529442,-411.938080,0.011551,0.003034,0.077070,215.869736,10.996929,0.770703,-411.938080,0.077912,0.000000
61.520004,48.959534,-411.938080,0.011546,0.003046,0.077356,217.782883,11.094389,0.773564,-411.938080,0.078293,0.000000
61.750004,48.971077,-411.849121,0.011563,0.003053,0.077539,217.834229,11.097005,0.775389,-411.849121,0.078675,0.000000
61.980003,50.148888,-411.893616,0.011589,0.003074,0.078085,223.073395,11.363900,0.780850,-411.893616,0.079056,0.000000
62.210003,51.438416,-411.938080,0.011598,0.003094,0.078579,228.809494,11.656112,0.785793,-411.938080,0.079438,0.000000
62.440002,52.082993,-411.938080,0.011589,0.003108,0.078935,231.676727,11.802175,0.789351,-411.938080,0.079828,0.000000
62.670002,52.375305,-411.893616,0.011611,0.003120,0.079256,232.976990,11.868414,0.792557,-411.893616,0.080210,0.000000
62.900002,53.307724,-411.938080,0.011602,0.003135,0.079637,237.124603,12.079703,0.796372,-411.938080,0.080591,0.000000
63.130005,54.193222,-411.938080,0.011620,0.003152,0.080071,241.063492,12.280359,0.800710,-411.938080,0.080973,0.000000
63.360004,54.848228,-411.938080,0.011628,0.003167,0.080435,243.977112,12.428786,0.804351,-411.938080,0.081354,0.000000
63.590004,55.073517,-411.982574,0.011637,0.003177,0.080695,244.979233,12.479837,0.806955,-411.982574,0.081745,0.000000
63.820004,56.704880,-411.893616,0.011632,0.003198,0.081225,252.235901,12.849509,0.812246,-411.893616,0.082126,0.000000
64.050003,57.417595,-411.938080,0.011663,0.003214,0.081624,255.406219,13.011013,0.816235,-411.938080,0.082508,0.000000
64.280006,58.010788,-411.982574,0.011680,0.003228,0.081988,258.044861,13.145432,0.819876,-411.982574,0.082890,0.000000
64.510002,58.921242,-411.982574,0.011663,0.003242,0.082334,262.094788,13.351745,0.823343,-411.982574,0.083271,0.000000
64.740005,59.652580,-412.027039,0.011680,0.003255,0.082681,265.347931,13.517467,0.826814,-412.027039,0.083661,0.000000
64.970001,60.094582,-411.938080,0.011693,0.003266,0.082959,267.314056,13.617627,0.829588,-411.938080,0.084043,0.000000
65.200005,61.296974,-411.982574,0.011706,0.003287,0.083488,272.662567,13.890093,0.834880,-411.982574,0.084424,0.000000
65.430000,62.157898,-411.982574,0.011710,0.003300,0.083809,276.492126,14.085180,0.838089,-411.982574,0.084806,0.000000
65.660004,62.310944,-412.071533,0.011727,0.003310,0.084069,277.172913,14.119862,0.840690,-412.071533,0.085188,0.000000
65.889999,64.216743,-412.071533,0.011714,0.003335,0.084702,285.650330,14.551723,0.847022,-412.071533,0.085578,0.000000
66.120003,65.045647,-412.027039,0.011727,0.003347,0.085006,289.337494,14.739554,0.850057,-412.027039,0.085960,0.000000
66.350006,65.931892,-412.115997,0.011749,0.003363,0.085413,293.279694,14.940381,0.854130,-412.115997,0.086341,0.000000
66.580002,66.592110,-412.027039,0.011753,0.003375,0.085725,296.216492,15.089988,0.857252,-412.027039,0.086723,0.000000
66.810005,67.320839,-412.071533,0.011762,0.003382,0.085890,299.458038,15.255120,0.858902,-412.071533,0.086124,0.000000
67.040001,66.569389,-412.027039,0.011770,0.003382,0.085890,296.115448,15.084839,0.858902,-412.027039,0.086124,0.000000
67.270004,65.975090,-411.982574,0.011775,0.003379,0.085821,293.471863,14.950169,0.858206,-411.982574,0.085890,0.000000
67.500000,65.350243,-412.027039,0.011783,0.003378,0.085795,290.692383,14.808577,0.857949,-412.027039,0.085890,0.000000
67.730003,64.796532,-412.071533,0.011779,0.003377,0.085777,288.229370,14.683104,0.857775,-412.071533,0.085890,0.000000
67.960007,64.274086,-412.115997,0.011788,0.003377,0.085769,285.905426,14.564716,0.857687,-412.115997,0.085890,0.000000
68.190002,63.787025,-412.160492,0.011796,0.003377,0.085769,283.738861,14.454346,0.857687,-412.160492,0.085890,0.000000
68.420006,63.343529,-412.115997,0.011783,0.003376,0.085760,281.766083,14.353849,0.857600,-412.115997,0.085890,0.000000
68.650002,62.928711,-412.115997,0.011805,0.003376,0.085760,279.920898,14.259851,0.857600,-412.115997,0.085890,0.000000
68.880005,62.551125,-412.115997,0.011805,0.003376,0.085760,278.241302,14.174287,0.857600,-412.115997,0.085890,0.000000
69.110001,62.202209,-412.115997,0.011792,0.003376,0.085751,276.689240,14.095222,0.857513,-412.115997,0.085890,0.000000
69.340004,61.865211,-412.160492,0.011805,0.003376,0.085751,275.190216,14.018857,0.857513,-412.160492,0.085890,0.000000
69.570000,61.551674,-412.115997,0.011805,0.003376,0.085751,273.795532,13.947809,0.857513,-412.115997,0.085890,0.000000
69.800003,61.252663,-412.071533,0.011809,0.003376,0.085751,272.465454,13.880052,0.857513,-412.071533,0.085890,0.000000
70.030006,60.977104,-412.115997,0.011805,0.003376,0.085751,271.239716,13.817609,0.857513,-412.115997,0.085890,0.000000
70.260002,60.709740,-412.160492,0.011805,0.003376,0.085751,270.050415,13.757023,0.857513,-412.160492,0.085890,0.000000
70.490005,60.485199,-412.160492,0.011814,0.003376,0.085751,269.051605,13.706142,0.857513,-412.160492,0.085890,0.000000
70.720001,60.244278,-412.115997,0.011809,0.003376,0.085751,267.979919,13.651548,0.857513,-412.115997,0.085890,0.000000
70.950005,60.012665,-412.115997,0.011805,0.003376,0.085751,266.949677,13.599064,0.857513,-412.115997,0.085890,0.000000
71.180000,59.814186,-412.115997,0.011818,0.003376,0.085751,266.066803,13.554088,0.857513,-412.115997,0.085890,0.000000
71.410004,59.601189,-412.160492,0.011822,0.003376,0.085751,265.119324,13.505823,0.857513,-412.160492,0.085890,0.000000
71.640007,59.400856,-412.160492,0.011809,0.003376,0.085751,264.228210,13.460426,0.857513,-412.160492,0.085890,0.000000
71.870003,59.228821,-412.249451,0.011818,0.003376,0.085751,263.462952,13.421442,0.857513,-412.249451,0.085890,0.000000
72.100006,59.051193,-412.160492,0.011818,0.003376,0.085751,262.672821,13.381191,0.857513,-412.160492,0.085890,0.000000
72.330002,58.872459,-412.160492,0.011809,0.003376,0.085751,261.877777,13.340690,0.857513,-412.160492,0.085890,0.000000
72.560005,58.709358,-412.160492,0.011835,0.003376,0.085751,261.152283,13.303731,0.857513,-412.160492,0.085890,0.000000
72.790001,58.552963,-412.204987,0.011814,0.003376,0.085751,260.456573,13.268291,0.857513,-412.204987,0.085890,0.000000
73.020004,58.404755,-412.204987,0.011826,0.003376,0.085751,259.797333,13.234707,0.857513,-412.204987,0.085890,0.000000
73.250000,58.260651,-412.160492,0.011831,0.003376,0.085743,259.156311,13.202052,0.857426,-412.160492,0.085890,0.000000
73.480003,58.119148,-412.204987,0.011835,0.003376,0.085743,258.526886,13.169988,0.857426,-412.204987,0.085890,0.000000
73.710007,57.994400,-412.249451,0.011831,0.003376,0.085743,257.971985,13.141720,0.857426,-412.249451,0.085890,0.000000
73.940002,57.867050,-412.249451,0.011831,0.003376,0.085743,257.405487,13.112861,0.857426,-412.249451,0.085890,0.000000
74.170006,57.738213,-412.249451,0.011826,0.003376,0.085743,256.832397,13.083667,0.857426,-412.249451,0.085890,0.000000
74.400002,57.611229,-412.160492,0.011831,0.003376,0.085743,256.267548,13.054891,0.857426,-412.160492,0.085890,0.000000
74.630005,57.496170,-412.249451,0.011839,0.003376,0.085743,255.755737,13.028818,0.857426,-412.249451,0.085890,0.000000
74.860001,57.383339,-412.249451,0.011826,0.003376,0.085743,255.253845,13.003251,0.857426,-412.249451,0.085890,0.000000
75.090004,57.279076,-412.249451,0.011826,0.003376,0.085743,254.790054,12.979624,0.857426,-412.249451,0.085890,0.000000
75.320007,57.155823,-412.293945,0.011826,0.003376,0.085743,254.241791,12.951694,0.857426,-412.293945,0.085890,0.000000
75.550003,57.057144,-412.249451,0.011844,0.003376,0.085743,253.802856,12.929334,0.857426,-412.249451,0.085890,0.000000
75.780006,56.957344,-412.293945,0.011848,0.003376,0.085743,253.358917,12.906718,0.857426,-412.293945,0.085890,0.000000
76.010002,56.857552,-412.249451,0.011839,0.003376,0.085743,252.915024,12.884106,0.857426,-412.249451,0.085890,0.000000
76.240005,56.759247,-412.293945,0.011835,0.003376,0.085743,252.477737,12.861829,0.857426,-412.293945,0.085890,0.000000
76.470001,56.658333,-412.249451,0.011852,0.003376,0.085743,252.028854,12.838962,0.857426,-412.249451,0.085890,0.000000
76.700005,56.576408,-412.293945,0.011844,0.003376,0.085743,251.664429,12.820397,0.857426,-412.293945,0.085890,0.000000
76.930000,56.490395,-412.249451,0.011839,0.003376,0.085743,251.281830,12.800906,0.857426,-412.249451,0.085890,0.000000
77.160004,56.392830,-412.293945,0.011844,0.003376,0.085743,250.847839,12.778798,0.857426,-412.293945,0.085890,0.000000
77.390007,56.321709,-412.293945,0.011835,0.003376,0.085743,250.531479,12.762682,0.857426,-412.293945,0.085890,0.000000
77.620003,56.237175,-412.338409,0.011839,0.003376,0.085743,250.155441,12.743526,0.857426,-412.338409,0.085890,0.000000
77.850006,56.140358,-412.338409,0.011857,0.003376,0.085743,249.724777,12.721587,0.857426,-412.338409,0.085890,0.000000
78.080002,56.073334,-412.338409,0.011844,0.003376,0.085743,249.426651,12.706399,0.857426,-412.338409,0.085890,0.000000
78.310005,55.996994,-412.293945,0.011852,0.003376,0.085743,249.087067,12.689100,0.857426,-412.293945,0.085890,0.000000
78.540001,55.924385,-412.382904,0.011839,0.003376,0.085743,248.764084,12.672647,0.857426,-412.382904,0.085890,0.000000
78.770004,55.842834,-412.382904,0.011844,0.003376,0.085743,248.401337,12.654167,0.857426,-412.382904,0.085890,0.000000
79.000000,55.780647,-412.338409,0.011852,0.003376,0.085743,248.124710,12.640076,0.857426,-412.338409,0.085890,0.000000
79.230003,55.696869,-412.338409,0.011852,0.003376,0.085743,247.752045,12.621091,0.857426,-412.338409,0.085890,0.000000
79.460007,55.632820,-412.338409,0.011852,0.003376,0.085743,247.467148,12.606578,0.857426,-412.338409,0.085890,0.000000
79.690002,55.556107,-412.382904,0.011848,0.003376,0.085743,247.125900,12.589193,0.857426,-412.382904,0.085890,0.000000
79.920006,55.500999,-412.338409,0.011839,0.003376,0.085743,246.880783,12.576706,0.857426,-412.338409,0.085890,0.000000
80.150002,55.425407,-412.338409,0.011857,0.003376,0.085743,246.544525,12.559577,0.857426,-412.338409,0.085890,0.000000
80.380005,55.381096,-412.382904,0.011865,0.003376,0.085743,246.347412,12.549535,0.857426,-412.382904,0.085890,0.000000
80.610001,55.308479,-412.427368,0.011844,0.003376,0.085743,246.024399,12.533081,0.857426,-412.427368,0.085890,0.000000
80.840004,55.240707,-412.427368,0.011844,0.003376,0.085743,245.722946,12.517723,0.857426,-412.427368,0.085890,0.000000
81.070007,55.188950,-412.427368,0.011857,0.003376,0.085743,245.492706,12.505995,0.857426,-412.427368,0.085890,0.000000
81.300003,55.139793,-412.427368,0.011848,0.003376,0.085743,245.274048,12.494856,0.857426,-412.427368,0.085890,0.000000
81.530006,55.071655,-412.427368,0.011839,0.003376,0.085743,244.970963,12.479416,0.857426,-412.427368,0.085890,0.000000
81.760002,55.024734,-412.427368,0.011852,0.003376,0.085743,244.762238,12.468782,0.857426,-412.427368,0.085890,0.000000
81.990005,54.963295,-412.427368,0.011852,0.003376,0.085743,244.488953,12.454861,0.857426,-412.427368,0.085890,0.000000
82.220001,54.901848,-412.471863,0.011839,0.003376,0.085743,244.215622,12.440937,0.857426,-412.471863,0.085890,0.000000
82.450005,54.848602,-412.382904,0.011865,0.003376,0.085743,243.978775,12.428870,0.857426,-412.382904,0.085890,0.000000
82.680000,54.807266,-412.427368,0.011861,0.003376,0.085743,243.794891,12.419504,0.857426,-412.427368,0.085890,0.000000
82.910004,54.749550,-412.427368,0.011861,0.003376,0.085743,243.538162,12.406425,0.857426,-412.427368,0.085890,0.000000
83.140007,54.692207,-412.471863,0.011839,0.003376,0.085743,243.283081,12.393431,0.857426,-412.471863,0.085890,0.000000
83.370003,54.655342,-412.471863,0.011861,0.003376,0.085743,243.119110,12.385077,0.857426,-412.471863,0.085890,0.000000
83.600006,54.605812,-412.427368,0.011861,0.003376,0.085743,242.898788,12.373854,0.857426,-412.427368,0.085890,0.000000
83.830002,54.555542,-412.427368,0.011857,0.003376,0.085743,242.675171,12.362463,0.857426,-412.427368,0.085890,0.000000
84.060005,54.504898,-412.427368,0.011874,0.003376,0.085743,242.449890,12.350986,0.857426,-412.427368,0.085890,0.000000
84.290001,54.472130,-412.471863,0.011865,0.003376,0.085743,242.304138,12.343561,0.857426,-412.471863,0.085890,0.000000
84.520004,54.424095,-412.471863,0.011852,0.003376,0.085743,242.090469,12.332677,0.857426,-412.471863,0.085890,0.000000
84.750008,54.380531,-412.471863,0.011865,0.003376,0.085743,241.896683,12.322804,0.857426,-412.471863,0.085890,0.000000
84.980003,54.347015,-412.471863,0.011852,0.003376,0.085743,241.747604,12.315209,0.857426,-412.471863,0.085890,0.000000
85.210007,54.281479,-412.516327,0.011852,0.003376,0.085743,241.456070,12.300359,0.857426,-412.516327,0.085890,0.000000
85.440002,54.240517,-412.471863,0.011848,0.003376,0.085743,241.273865,12.291077,0.857426,-412.471863,0.085890,0.000000
85.670006,54.209610,-412.471863,0.011857,0.003376,0.085743,241.136383,12.284074,0.857426,-412.471863,0.085890,0.000000
85.900002,54.169395,-412.427368,0.011865,0.003376,0.085743,240.957504,12.274961,0.857426,-412.427368,0.085890,0.000000
86.130005,54.126945,-412.471863,0.011857,0.003376,0.085743,240.768677,12.265341,0.857426,-412.471863,0.085890,0.000000
86.360001,54.086723,-412.516327,0.011870,0.003376,0.085743,240.589767,12.256227,0.857426,-412.516327,0.085890,0.000000
86.590004,54.036087,-412.560822,0.011865,0.003376,0.085743,240.364517,12.244752,0.857426,-412.560822,0.085890,0.000000
86.820007,54.001823,-412.516327,0.011861,0.003376,0.085743,240.212112,12.236988,0.857426,-412.516327,0.085890,0.000000
87.050003,53.967567,-412.516327,0.011861,0.003376,0.085743,240.059723,12.229225,0.857426,-412.516327,0.085890,0.000000
87.280006,53.932564,-412.471863,0.011852,0.003376,0.085743,239.904022,12.221293,0.857426,-412.471863,0.085890,0.000000
87.510002,53.895699,-412.427368,0.011870,0.003376,0.085743,239.740036,12.212939,0.857426,-412.427368,0.085890,0.000000
87.740005,53.849525,-412.516327,0.011857,0.003376,0.085743,239.534653,12.202477,0.857426,-412.516327,0.085890,0.000000
87.970001,53.817505,-412.605316,0.011857,0.003376,0.085743,239.392212,12.195221,0.857426,-412.605316,0.085890,0.000000
88.200005,53.785851,-412.560822,0.011852,0.003376,0.085743,239.251419,12.188048,0.857426,-412.560822,0.085890,0.000000
88.430008,53.744141,-412.560822,0.011861,0.003376,0.085743,239.065872,12.178596,0.857426,-412.560822,0.085890,0.000000
88.660004,53.713982,-412.516327,0.011870,0.003376,0.085743,238.931717,12.171762,0.857426,-412.516327,0.085890,0.000000
88.890007,53.668182,-412.516327,0.011861,0.003376,0.085743,238.727997,12.161385,0.857426,-412.516327,0.085890,0.000000
89.120003,53.640625,-412.605316,0.011874,0.003376,0.085743,238.605423,12.155139,0.857426,-412.605316,0.085890,0.000000
89.350006,53.594826,-412.605316,0.011861,0.003376,0.085743,238.401688,12.144762,0.857426,-412.605316,0.085890,0.000000
89.580002,53.560936,-412.560822,0.011865,0.003376,0.085743,238.250946,12.137081,0.857426,-412.560822,0.085890,0.000000
89.810005,53.524818,-412.516327,0.011865,0.003376,0.085743,238.090286,12.128897,0.857426,-412.516327,0.085890,0.000000
90.040001,53.498375,-412.560822,0.011865,0.003376,0.085743,237.972656,12.122906,0.857426,-412.560822,0.085890,0.000000
90.270004,53.474548,-412.649780,0.011870,0.003376,0.085743,237.866669,12.117505,0.857426,-412.649780,0.085890,0.000000
90.500008,53.430603,-412.605316,0.011861,0.003376,0.085743,237.671188,12.107548,0.857426,-412.605316,0.085890,0.000000
90.730003,53.406029,-412.560822,0.011857,0.003376,0.085743,237.561874,12.101978,0.857426,-412.560822,0.085890,0.000000
90.960007,53.384056,-412.605316,0.011865,0.003376,0.085743,237.464142,12.097000,0.857426,-412.605316,0.085890,0.000000
91.190002,53.355759,-412.605316,0.011878,0.003376,0.085743,237.338272,12.090588,0.857426,-412.605316,0.085890,0.000000
91.420006,53.317780,-412.649780,0.011878,0.003376,0.085743,237.169327,12.081982,0.857426,-412.649780,0.085890,0.000000
91.650002,53.284264,-412.694275,0.011870,0.003376,0.085743,237.020248,12.074387,0.857426,-412.694275,0.085890,0.000000
91.880005,53.262665,-412.649780,0.011861,0.003376,0.085743,236.924164,12.069492,0.857426,-412.649780,0.085890,0.000000
92.110001,53.235481,-412.605316,0.011861,0.003376,0.085743,236.803253,12.063333,0.857426,-412.605316,0.085890,0.000000
92.340004,53.198242,-412.649780,0.011874,0.003376,0.085743,236.637604,12.054893,0.857426,-412.649780,0.085890,0.000000
92.570007,53.168457,-412.649780,0.011861,0.003376,0.085743,236.505112,12.048144,0.857426,-412.649780,0.085890,0.000000
92.800003,53.149094,-412.694275,0.011857,0.003376,0.085743,236.418976,12.043757,0.857426,-412.694275,0.085890,0.000000
93.030006,53.113342,-412.649780,0.011865,0.003376,0.085743,236.259949,12.035655,0.857426,-412.649780,0.085890,0.000000
93.260002,53.095474,-412.694275,0.011870,0.003376,0.085743,236.180466,12.031607,0.857426,-412.694275,0.085890,0.000000
93.490005,53.076851,-412.605316,0.011852,0.003376,0.085743,236.097626,12.027386,0.857426,-412.605316,0.085890,0.000000
93.720001,53.038124,-412.649780,0.011870,0.003376,0.085743,235.925354,12.018611,0.857426,-412.649780,0.085890,0.000000
93.950005,53.012436,-412.738739,0.011861,0.003376,0.085743,235.811096,12.012790,0.857426,-412.738739,0.085890,0.000000
94.180008,52.992699,-412.649780,0.011857,0.003376,0.085743,235.723297,12.008318,0.857426,-412.649780,0.085890,0.000000
94.410004,52.968117,-412.738739,0.011883,0.003376,0.085743,235.613953,12.002748,0.857426,-412.738739,0.085890,0.000000
94.640007,52.934608,-412.694275,0.011865,0.003376,0.085743,235.464905,11.995153,0.857426,-412.694275,0.085890,0.000000
94.870003,52.916359,-412.738739,0.011874,0.003376,0.085743,235.383728,11.991018,0.857426,-412.738739,0.085890,0.000000
95.100006,52.889549,-412.649780,0.011861,0.003376,0.085743,235.264465,11.984943,0.857426,-412.649780,0.085890,0.000000
95.330002,52.865715,-412.694275,0.011857,0.003376,0.085743,235.158447,11.979543,0.857426,-412.694275,0.085890,0.000000
95.560005,52.840767,-412.738739,0.011857,0.003376,0.085743,235.047470,11.973888,0.857426,-412.738739,0.085890,0.000000
95.790001,52.816193,-412.694275,0.011878,0.003376,0.085743,234.938156,11.968320,0.857426,-412.694275,0.085890,0.000000
96.020004,52.784538,-412.694275,0.011870,0.003376,0.085743,234.797348,11.961147,0.857426,-412.694275,0.085890,0.000000
96.250008,52.767036,-412.738739,0.011861,0.003376,0.085743,234.719498,11.957182,0.857426,-412.738739,0.085890,0.000000
96.480003,52.745071,-412.694275,0.011865,0.003376,0.085743,234.621796,11.952204,0.857426,-412.694275,0.085890,0.000000
96.710007,52.724586,-412.694275,0.011874,0.003376,0.085743,234.530670,11.947562,0.857426,-412.694275,0.085890,0.000000
96.940002,52.695915,-412.738739,0.011865,0.003376,0.085743,234.403137,11.941065,0.857426,-412.738739,0.085890,0.000000
97.170006,52.677666,-412.827698,0.011878,0.003376,0.085743,234.321960,11.936930,0.857426,-412.827698,0.085890,0.000000
97.300003,52.653091,-412.827698,0.011865,0.003376,0.085743,234.212646,11.931361,0.857426,-412.827698,0.085890,0.000000