File: Data/compression 5/AutoNoheating-10-5-1-240223_02232024_193040.csv
Time (sec),S:Load (lbs),S:HL1 (DIM),S:LVDT (in),S:Position (in),Ch:Position (mm),Ch:Load (N),Ch:Stress (MPa),Ch:Strain (mm/mm),Ch:HL1 (DIM),Set Point (),Cycles ()
0.110000,-0.001488,-386.895325,0.000004,-0.000000,-0.000000,-0.006618,-0.000337,-0.000000,-386.895325,0.000165,0.000000
0.400000,0.006699,-386.850830,0.000004,-0.000000,-0.000000,0.029797,0.001518,-0.000000,-386.850830,0.000234,0.000000
0.690000,-0.000748,-386.984283,0.000034,0.000165,0.004180,-0.003326,-0.000169,0.041800,-386.984283,0.005056,0.000000
0.980000,-0.005959,-386.939789,0.000190,0.000349,0.008863,-0.026505,-0.001350,0.088631,-386.939789,0.009895,0.000000
1.270000,0.000748,-386.984283,0.000362,0.000544,0.013815,0.003326,0.000169,0.138151,-386.984283,0.014717,0.000000
1.560000,0.009682,-386.984283,0.000552,0.000728,0.018498,0.043066,0.002194,0.184979,-386.984283,0.019556,0.000000
1.850000,0.010056,-386.939789,0.000737,0.000922,0.023407,0.044729,0.002279,0.234065,-386.939789,0.024378,0.000000
2.140000,0.000374,-386.984283,0.000923,0.001112,0.028237,0.001663,0.000085,0.282370,-386.984283,0.029217,0.000000
2.430000,0.024200,-386.939789,0.001104,0.001303,0.033085,0.107649,0.005484,0.330847,-386.939789,0.034056,0.000000
2.720000,-0.005959,-387.073242,0.001306,0.001488,0.037794,-0.026505,-0.001350,0.377937,-387.073242,0.038878,0.000000
3.010000,0.007820,-386.984283,0.001492,0.001682,0.042720,0.034786,0.001772,0.427195,-386.984283,0.043717,0.000000
3.300000,0.009308,-386.984283,0.001664,0.001865,0.047359,0.041403,0.002109,0.473593,-386.984283,0.048539,0.000000
3.590000,0.006332,-386.984283,0.001876,0.002065,0.052459,0.028168,0.001435,0.524586,-386.984283,0.053378,0.000000
3.880000,0.022339,-386.984283,0.002091,0.002253,0.057228,0.099368,0.005062,0.572284,-386.984283,0.058200,0.000000
4.170000,0.061066,-387.028748,0.002268,0.002440,0.061972,0.271634,0.013838,0.619720,-387.028748,0.063039,0.000000
4.460000,0.030159,-387.028748,0.002479,0.002631,0.066829,0.134154,0.006834,0.668286,-387.028748,0.067861,0.000000
4.750000,0.038727,-387.028748,0.002656,0.002824,0.071720,0.172265,0.008776,0.717196,-387.028748,0.072700,0.000000
5.040000,0.035744,-387.028748,0.002850,0.003008,0.076403,0.158996,0.008100,0.764026,-387.028748,0.077539,0.000000
5.330000,0.009308,-387.073242,0.003040,0.003205,0.081406,0.041403,0.002109,0.814065,-387.073242,0.082360,0.000000
5.620000,0.009682,-387.117706,0.003221,0.003391,0.086142,0.043066,0.002194,0.861417,-387.117706,0.087200,0.000000
5.910000,0.034630,-387.028748,0.003402,0.003583,0.090998,0.154041,0.007847,0.909981,-387.028748,0.092021,0.000000
6.200000,0.018990,-387.028748,0.003600,0.003773,0.095828,0.084470,0.004303,0.958284,-387.028748,0.096861,0.000000
6.490000,0.053993,-387.073242,0.003794,0.003964,0.100694,0.240174,0.012235,1.006935,-387.073242,0.101682,0.000000
6.780000,0.028671,-387.117706,0.004005,0.004153,0.105498,0.127536,0.006497,1.054981,-387.117706,0.106522,0.000000
7.070000,0.027924,-387.028748,0.004169,0.004344,0.110328,0.124210,0.006328,1.103284,-387.028748,0.111343,0.000000
7.360000,0.029419,-387.117706,0.004372,0.004528,0.115011,0.130862,0.006666,1.150114,-387.117706,0.116182,0.000000
7.650001,0.035004,-387.073242,0.004557,0.004726,0.120033,0.155704,0.007932,1.200328,-387.073242,0.121021,0.000000
7.940001,0.020851,-387.162201,0.004730,0.004910,0.124716,0.092750,0.004725,1.247159,-387.162201,0.125843,0.000000
8.230000,0.061066,-387.117706,0.004928,0.005104,0.129642,0.271634,0.013838,1.296415,-387.117706,0.130682,0.000000
8.520000,0.038353,-387.162201,0.005113,0.005293,0.134446,0.170603,0.008691,1.344461,-387.162201,0.135504,0.000000
8.810000,0.066650,-387.162201,0.005303,0.005480,0.139190,0.296476,0.015103,1.391897,-387.162201,0.140343,0.000000
9.100000,0.023460,-387.117706,0.005506,0.005672,0.144064,0.104357,0.005316,1.440635,-387.117706,0.145165,0.000000
9.390000,0.036865,-387.162201,0.005683,0.005859,0.148825,0.163985,0.008354,1.488245,-387.162201,0.150004,0.000000
9.680000,0.004837,-387.073242,0.005877,0.006046,0.153560,0.021516,0.001096,1.535598,-387.073242,0.154826,0.000000
9.970000,0.015640,-387.162201,0.006088,0.006245,0.158633,0.069571,0.003544,1.586331,-387.162201,0.159665,0.000000
10.260000,0.040588,-387.206665,0.006291,0.006434,0.163420,0.180546,0.009197,1.634202,-387.206665,0.164487,0.000000
10.550000,0.067772,-387.162201,0.006463,0.006621,0.168173,0.301465,0.015357,1.681725,-387.162201,0.169326,0.000000
10.840000,0.043198,-387.206665,0.006670,0.006814,0.173072,0.192153,0.009789,1.730725,-387.206665,0.174165,0.000000
11.130000,0.059204,-387.251160,0.006851,0.007002,0.177851,0.263353,0.013416,1.778509,-387.251160,0.178987,0.000000
11.420000,0.034256,-387.206665,0.007045,0.007192,0.182681,0.152378,0.007763,1.826812,-387.206665,0.183826,0.000000
11.710001,0.037979,-387.295654,0.007252,0.007382,0.187503,0.168940,0.008606,1.875028,-387.295654,0.188648,0.000000
12.000001,-0.000748,-387.162201,0.007437,0.007572,0.192325,-0.003326,-0.000169,1.923247,-387.162201,0.193487,0.000000
12.290001,0.060326,-387.251160,0.007636,0.007764,0.197199,0.268342,0.013670,1.971985,-387.251160,0.198309,0.000000
12.580001,0.020103,-387.206665,0.007847,0.007955,0.202046,0.089425,0.004556,2.020462,-387.206665,0.203148,0.000000
12.870001,0.072609,-387.206665,0.008006,0.008144,0.206851,0.322981,0.016453,2.068507,-387.206665,0.207970,0.000000
13.160001,0.039841,-387.295654,0.008218,0.008337,0.211751,0.177220,0.009028,2.117507,-387.295654,0.212809,0.000000
13.450001,0.043198,-387.251160,0.008395,0.008523,0.216494,0.192153,0.009789,2.164943,-387.251160,0.217648,0.000000
13.740001,0.016754,-387.295654,0.008576,0.008712,0.221290,0.074526,0.003797,2.212901,-387.295654,0.222469,0.000000
14.030001,0.035744,-387.251160,0.008774,0.008902,0.226103,0.158996,0.008100,2.261030,-387.251160,0.227308,0.000000
14.320001,0.015266,-387.295654,0.008946,0.009095,0.231003,0.067908,0.003459,2.310029,-387.295654,0.232130,0.000000
14.610001,0.076332,-387.384613,0.009158,0.009283,0.235781,0.339542,0.017297,2.357814,-387.384613,0.236969,0.000000
14.900001,0.115807,-387.295654,0.009326,0.009476,0.240690,0.515133,0.026242,2.406900,-387.295654,0.241791,0.000000
15.190001,0.415192,-387.384613,0.009541,0.009662,0.245416,1.846865,0.094084,2.454162,-387.384613,0.246630,0.000000
15.480000,0.579041,-387.340118,0.009641,-0.000000,-0.000009,2.575701,0.131212,-0.000087,-387.340118,0.000199,0.000000
15.770000,0.541801,-387.251160,0.009641,-0.000000,-0.000009,2.410053,0.122774,-0.000087,-387.251160,0.000199,0.000000
16.060001,0.520203,-387.340118,0.009649,-0.000000,-0.000009,2.313977,0.117880,-0.000087,-387.340118,0.000520,0.000000
16.350000,0.510895,-387.340118,0.009653,-0.000000,-0.000009,2.272573,0.115770,-0.000087,-387.340118,0.001006,0.000000
16.640001,0.638992,-387.384613,0.009653,0.000024,0.000607,2.842380,0.144798,0.006071,-387.384613,0.001483,0.000000
16.930000,0.674362,-387.384613,0.009666,0.000033,0.000832,2.999713,0.152813,0.008323,-387.384613,0.001969,0.000000
17.220001,0.806931,-387.295654,0.009675,0.000067,0.001691,3.589406,0.182853,0.016911,-387.295654,0.002454,0.000000
17.510000,0.803955,-387.429077,0.009701,0.000084,0.002133,3.576171,0.182179,0.021332,-387.429077,0.002940,0.000000
17.800001,0.872841,-387.429077,0.009718,0.000100,0.002532,3.882590,0.197789,0.025321,-387.429077,0.003417,0.000000
18.090000,0.945824,-387.473572,0.009740,0.000121,0.003070,4.207234,0.214327,0.030699,-387.473572,0.003902,0.000000
18.380001,0.997955,-387.429077,0.009761,0.000135,0.003417,4.439127,0.226140,0.034166,-387.429077,0.004388,0.000000
18.670000,1.046364,-387.384613,0.009761,0.000152,0.003859,4.654459,0.237109,0.038591,-387.384613,0.004865,0.000000
18.960001,1.177811,-387.429077,0.009787,0.000178,0.004518,5.239163,0.266896,0.045180,-387.429077,0.005351,0.000000
19.250000,1.219894,-387.384613,0.009813,0.000200,0.005082,5.426362,0.276432,0.050820,-387.384613,0.005836,0.000000
19.540001,1.239258,-387.429077,0.009835,0.000215,0.005463,5.512494,0.280820,0.054635,-387.429077,0.006322,0.000000
19.830002,1.315590,-387.384613,0.009856,0.000231,0.005880,5.852036,0.298117,0.058798,-387.384613,0.006799,0.000000
20.120001,1.388947,-387.429077,0.009860,0.000249,0.006322,6.178343,0.314740,0.063219,-387.429077,0.007284,0.000000
20.410002,1.433632,-387.473572,0.009878,0.000268,0.006816,6.377113,0.324866,0.068162,-387.473572,0.007770,0.000000
20.700001,1.530075,-387.429077,0.009908,0.000285,0.007233,6.806114,0.346720,0.072326,-387.429077,0.008256,0.000000
20.990002,1.662643,-387.473572,0.009921,0.000310,0.007883,7.395807,0.376760,0.078828,-387.473572,0.008733,0.000000
21.280001,1.670464,-387.473572,0.009942,0.000330,0.008386,7.430593,0.378532,0.083858,-387.473572,0.009218,0.000000
21.570002,1.676048,-387.473572,0.009964,0.000346,0.008785,7.455435,0.379798,0.087847,-387.473572,0.009704,0.000000
21.860001,1.689827,-387.562531,0.009985,0.000362,0.009184,7.516726,0.382920,0.091837,-387.562531,0.010190,0.000000
22.150002,1.834679,-387.473572,0.009998,0.000380,0.009652,8.161058,0.415744,0.096522,-387.473572,0.010667,0.000000
22.440001,1.871918,-387.562531,0.010020,0.000397,0.010077,8.326706,0.424183,0.100769,-387.562531,0.011153,0.000000
22.730001,1.961655,-387.518036,0.010046,0.000415,0.010545,8.725876,0.444517,0.105455,-387.518036,0.011638,0.000000
23.020000,2.142258,-387.429077,0.010067,0.000447,0.011360,9.529238,0.485443,0.113604,-387.429077,0.012124,0.000000
23.310001,2.108742,-387.606995,0.010080,0.000460,0.011673,9.380152,0.477848,0.116726,-387.606995,0.012601,0.000000
23.600000,2.119171,-387.473572,0.010106,0.000477,0.012115,9.426544,0.480211,0.121151,-387.473572,0.013086,0.000000
23.890001,2.160133,-387.606995,0.010111,0.000493,0.012531,9.608753,0.489493,0.125314,-387.606995,0.013572,0.000000
24.180000,2.370522,-387.562531,0.010154,0.000517,0.013121,10.544606,0.537168,0.131211,-387.562531,0.014057,0.000000
24.470001,2.316154,-387.518036,0.010162,0.000527,0.013381,10.302770,0.524848,0.133811,-387.518036,0.014535,0.000000
24.760000,2.488190,-387.606995,0.010184,0.000554,0.014066,11.068021,0.563832,0.140662,-387.606995,0.015020,0.000000
25.050001,2.575699,-387.562531,0.010205,0.000579,0.014708,11.457281,0.583662,0.147081,-387.562531,0.015506,0.000000
25.340002,2.528778,-387.562531,0.010227,0.000596,0.015133,11.248567,0.573029,0.151328,-387.562531,0.015983,0.000000
25.630001,2.576073,-387.606995,0.010248,0.000612,0.015549,11.458943,0.583746,0.155491,-387.606995,0.016468,0.000000
25.920002,2.649055,-387.562531,0.010266,0.000629,0.015983,11.783587,0.600285,0.159829,-387.562531,0.016954,0.000000
26.210001,2.738800,-387.606995,0.010283,0.000648,0.016460,12.182791,0.620621,0.164598,-387.606995,0.017440,0.000000
26.500002,2.766357,-387.606995,0.010309,0.000663,0.016833,12.305372,0.626866,0.168326,-387.606995,0.017917,0.000000
26.790001,2.991264,-387.606995,0.010326,0.000695,0.017648,13.305808,0.677830,0.176478,-387.606995,0.018403,0.000000
27.080002,2.932060,-387.606995,0.010361,0.000711,0.018055,13.042456,0.664414,0.180555,-387.606995,0.018888,0.000000
27.370001,2.964081,-387.562531,0.010378,0.000730,0.018550,13.184890,0.671670,0.185498,-387.562531,0.019374,0.000000
27.660002,2.952171,-387.695984,0.010391,0.000744,0.018888,13.131914,0.668972,0.188881,-387.695984,0.019851,0.000000
27.950001,3.064621,-387.651489,0.010412,0.000760,0.019313,13.632115,0.694453,0.193128,-387.651489,0.020336,0.000000
28.240002,3.135376,-387.606995,0.010434,0.000781,0.019833,13.946849,0.710486,0.198332,-387.606995,0.020822,0.000000
28.530001,3.167030,-387.695984,0.010451,0.000794,0.020172,14.087654,0.717659,0.201716,-387.695984,0.021307,0.000000
28.820002,3.290657,-387.651489,0.010477,0.000820,0.020831,14.637573,0.745674,0.208305,-387.651489,0.021785,0.000000
29.110001,3.352470,-387.740448,0.010490,0.000842,0.021386,14.912533,0.759681,0.213858,-387.740448,0.022270,0.000000
29.400002,3.377045,-387.740448,0.010520,0.000862,0.021897,15.021845,0.765249,0.218971,-387.740448,0.022756,0.000000
29.690001,3.419121,-387.695984,0.010542,0.000878,0.022305,15.209009,0.774784,0.223048,-387.695984,0.023242,0.000000
29.980001,3.471252,-387.784943,0.010572,0.000899,0.022843,15.440902,0.786597,0.228426,-387.784943,0.023718,0.000000
30.270002,3.495461,-387.695984,0.010589,0.000915,0.023250,15.548585,0.792083,0.232502,-387.695984,0.024204,0.000000
30.560001,3.578499,-387.740448,0.010606,0.000933,0.023710,15.917958,0.810899,0.237097,-387.740448,0.024690,0.000000
30.850002,3.696915,-387.695984,0.010624,0.000959,0.024352,16.444698,0.837733,0.243516,-387.695984,0.025167,0.000000
31.140001,3.708084,-387.695984,0.010658,0.000978,0.024837,16.494381,0.840264,0.248372,-387.695984,0.025653,0.000000
31.430002,3.744202,-387.784943,0.010680,0.000995,0.025271,16.655041,0.848448,0.252710,-387.784943,0.026138,0.000000
31.720001,3.801552,-387.740448,0.010701,0.001014,0.025757,16.910147,0.861444,0.257566,-387.740448,0.026624,0.000000
32.010002,3.816071,-387.740448,0.010718,0.001033,0.026242,16.974730,0.864734,0.262422,-387.740448,0.027101,0.000000
32.300003,3.806015,-387.829407,0.010731,0.001044,0.026528,16.930000,0.862455,0.265283,-387.829407,0.027586,0.000000
32.590000,3.997047,-387.784943,0.010766,0.001071,0.027205,17.779755,0.905744,0.272047,-387.784943,0.028072,0.000000
32.880001,4.037636,-387.784943,0.010787,0.001093,0.027751,17.960300,0.914941,0.277512,-387.784943,0.028558,0.000000
33.170002,4.000023,-387.740448,0.010809,0.001111,0.028228,17.792990,0.906418,0.282281,-387.740448,0.029035,0.000000
33.460003,4.007469,-387.784943,0.010813,0.001127,0.028618,17.826113,0.908105,0.286183,-387.784943,0.029520,0.000000
33.750000,4.142639,-387.829407,0.010852,0.001147,0.029139,18.427380,0.938735,0.291388,-387.829407,0.030006,0.000000
34.040001,4.166473,-387.784943,0.010865,0.001165,0.029590,18.533400,0.944136,0.295896,-387.784943,0.030491,0.000000
34.330002,4.258820,-387.873901,0.010891,0.001185,0.030093,18.944176,0.965062,0.300926,-387.873901,0.030968,0.000000
34.620003,4.356010,-387.784943,0.010921,0.001206,0.030639,19.376503,0.987086,0.306391,-387.784943,0.031454,0.000000
34.910000,4.337395,-387.784943,0.010938,0.001225,0.031107,19.293695,0.982868,0.311073,-387.784943,0.031940,0.000000
35.200001,4.364204,-387.873901,0.010964,0.001243,0.031575,19.412951,0.988943,0.315755,-387.873901,0.032426,0.000000
35.490002,4.418945,-387.873901,0.010994,0.001261,0.032035,19.656450,1.001347,0.320354,-387.873901,0.032902,0.000000
35.780003,4.497513,-387.873901,0.011012,0.001281,0.032538,20.005936,1.019151,0.325384,-387.873901,0.033388,0.000000
36.070004,4.487457,-387.873901,0.011029,0.001296,0.032911,19.961206,1.016872,0.329112,-387.873901,0.033874,0.000000
36.360001,4.494164,-387.829407,0.011055,0.001316,0.033414,19.991037,1.018392,0.334142,-387.829407,0.034351,0.000000
36.650002,4.697105,-387.873901,0.011068,0.001337,0.033960,20.893768,1.064379,0.339603,-387.873901,0.034836,0.000000
36.940002,4.684448,-387.873901,0.011111,0.001356,0.034455,20.837467,1.061511,0.344547,-387.873901,0.035322,0.000000
37.230003,4.666573,-387.918365,0.011124,0.001372,0.034845,20.757952,1.057461,0.348449,-387.918365,0.035808,0.000000
37.520000,4.844193,-387.873901,0.011150,0.001397,0.035487,21.548044,1.097710,0.354868,-387.873901,0.036285,0.000000
37.810001,4.810310,-387.918365,0.011175,0.001414,0.035903,21.397329,1.090032,0.359031,-387.918365,0.036770,0.000000
38.100002,4.817009,-387.962860,0.011184,0.001429,0.036285,21.427126,1.091550,0.362847,-387.962860,0.037256,0.000000
38.390003,5.029259,-387.918365,0.011214,0.001452,0.036892,22.371260,1.139646,0.368917,-387.918365,0.037741,0.000000
38.680000,5.001335,-387.962860,0.011236,0.001472,0.037386,22.247049,1.133319,0.373861,-387.962860,0.038218,0.000000
38.970001,5.009529,-387.962860,0.011257,0.001490,0.037846,22.283499,1.135176,0.378455,-387.962860,0.038704,0.000000
39.260002,4.968567,-387.918365,0.011279,0.001506,0.038244,22.101290,1.125893,0.382445,-387.918365,0.039190,0.000000
39.550003,5.065010,-387.962860,0.011288,0.001525,0.038739,22.530291,1.147748,0.387388,-387.962860,0.039676,0.000000
39.840000,5.068733,-387.918365,0.011331,0.001541,0.039146,22.546852,1.148591,0.391464,-387.918365,0.040152,0.000000
40.130001,5.194595,-387.962860,0.011335,0.001559,0.039589,23.106714,1.177112,0.395889,-387.962860,0.040638,0.000000
40.420002,5.383385,-388.007324,0.011382,0.001586,0.040291,23.946491,1.219893,0.402913,-388.007324,0.041124,0.000000
40.710003,5.337585,-387.962860,0.011400,0.001605,0.040768,23.742765,1.209514,0.407682,-387.962860,0.041609,0.000000
41.000004,5.324181,-388.051819,0.011408,0.001622,0.041202,23.683138,1.206477,0.412016,-388.051819,0.042087,0.000000
41.290001,5.352112,-387.962860,0.011438,0.001639,0.041618,23.807383,1.212806,0.416179,-387.962860,0.042572,0.000000
41.580002,5.439987,-388.007324,0.011464,0.001658,0.042112,24.198271,1.232719,0.421123,-388.007324,0.043058,0.000000
41.870003,5.373703,-388.007324,0.011477,0.001671,0.042451,23.903425,1.217699,0.424506,-388.007324,0.043535,0.000000
42.160004,5.426582,-388.007324,0.011499,0.001689,0.042910,24.138643,1.229681,0.429101,-388.007324,0.044020,0.000000
42.450001,5.765442,-388.051819,0.011529,0.001721,0.043708,25.645966,1.306468,0.437080,-388.051819,0.044506,0.000000
42.740002,5.655220,-388.007324,0.011546,0.001739,0.044159,25.155676,1.281491,0.441591,-388.007324,0.044991,0.000000
43.030003,5.626549,-388.051819,0.011576,0.001754,0.044558,25.028139,1.274994,0.445581,-388.051819,0.045468,0.000000
43.320004,5.699905,-388.051819,0.011594,0.001773,0.045026,25.354446,1.291617,0.450262,-388.051819,0.045954,0.000000
43.610001,5.780708,-388.007324,0.011620,0.001790,0.045468,25.713875,1.309927,0.454683,-388.007324,0.046440,0.000000
43.900002,5.659317,-388.096283,0.011607,0.001804,0.045824,25.173899,1.282420,0.458241,-388.096283,0.046926,0.000000
44.190002,6.036530,-388.096283,0.011650,0.001833,0.046561,26.851824,1.367897,0.465614,-388.096283,0.047402,0.000000
44.480003,5.950508,-388.051819,0.011667,0.001851,0.047021,26.469183,1.348404,0.470209,-388.051819,0.047888,0.000000
44.770000,5.862633,-388.051819,0.011697,0.001868,0.047437,26.078293,1.328492,0.474372,-388.051819,0.048374,0.000000
45.060001,5.830238,-388.096283,0.011723,0.001882,0.047793,25.934195,1.321151,0.477926,-388.096283,0.048859,0.000000
45.350002,5.959450,-388.096283,0.011732,0.001903,0.048330,26.508957,1.350431,0.483305,-388.096283,0.049336,0.000000
45.640003,6.066322,-388.096283,0.011740,0.001922,0.048807,26.984350,1.374648,0.488074,-388.096283,0.049822,0.000000
45.930000,6.135208,-388.140778,0.011758,0.001940,0.049267,27.290770,1.390258,0.492668,-388.140778,0.050308,0.000000
46.220001,6.454330,-388.140778,0.011809,0.001970,0.050039,28.710297,1.462572,0.500390,-388.140778,0.050793,0.000000
46.510002,6.267403,-388.140778,0.011839,0.001986,0.050455,27.878799,1.420214,0.504549,-388.140778,0.051270,0.000000
46.800003,6.144516,-388.140778,0.011839,0.002003,0.050871,27.332172,1.392367,0.508713,-388.140778,0.051756,0.000000
47.090004,6.112869,-388.140778,0.011878,0.002017,0.051227,27.191401,1.385196,0.512270,-388.140778,0.052241,0.000000
47.380001,6.393631,-388.140778,0.011887,0.002040,0.051825,28.440290,1.448817,0.518254,-388.140778,0.052719,0.000000
47.670002,6.316925,-388.229736,0.011908,0.002055,0.052207,28.099087,1.431436,0.522070,-388.229736,0.053204,0.000000
47.960003,6.412628,-388.140778,0.011926,0.002078,0.052779,28.524796,1.453122,0.527792,-388.140778,0.053690,0.000000
48.250004,6.644989,-388.229736,0.011943,0.002104,0.053447,29.558388,1.505776,0.534469,-388.229736,0.054175,0.000000
48.540001,6.376877,-388.229736,0.011990,0.002117,0.053777,28.365765,1.445021,0.537765,-388.229736,0.054652,0.000000
48.830002,6.403313,-388.140778,0.011999,0.002134,0.054193,28.483356,1.451011,0.541929,-388.140778,0.055138,0.000000
49.120003,6.361610,-388.229736,0.012016,0.002149,0.054574,28.297857,1.441561,0.545744,-388.229736,0.055624,0.000000
49.410004,6.640518,-388.140778,0.012025,0.002171,0.055155,29.538500,1.504763,0.551554,-388.140778,0.056110,0.000000
49.700001,6.647964,-388.229736,0.012051,0.002189,0.055598,29.571623,1.506450,0.555978,-388.229736,0.056586,0.000000
49.990002,6.935432,-388.274231,0.012059,0.002214,0.056248,30.850344,1.571591,0.562481,-388.274231,0.057072,0.000000
50.280003,6.762657,-388.185272,0.012077,0.002228,0.056604,30.081802,1.532440,0.566039,-388.185272,0.057558,0.000000
50.570004,6.913467,-388.229736,0.012128,0.002252,0.057194,30.752640,1.566614,0.571935,-388.229736,0.058043,0.000000
50.860001,6.818512,-388.229736,0.012150,0.002268,0.057618,30.330256,1.545097,0.576182,-388.229736,0.058520,0.000000
51.150002,7.054596,-388.274231,0.012158,0.002292,0.058225,31.380409,1.598594,0.582253,-388.274231,0.059006,0.000000
51.440002,6.911606,-388.274231,0.012176,0.002306,0.058572,30.744358,1.566192,0.585724,-388.274231,0.059492,0.000000
51.730003,6.828568,-388.274231,0.012206,0.002319,0.058910,30.374985,1.547376,0.589104,-388.274231,0.059977,0.000000
52.020004,7.189018,-388.318695,0.012210,0.002347,0.059613,31.978350,1.629055,0.596129,-388.318695,0.060454,0.000000
52.310001,7.128700,-388.318695,0.012253,0.002365,0.060073,31.710043,1.615387,0.600727,-388.318695,0.060940,0.000000
52.600002,7.165192,-388.274231,0.012262,0.002384,0.060558,31.872364,1.623656,0.605583,-388.274231,0.061425,0.000000
52.890003,7.149551,-388.318695,0.012296,0.002401,0.060983,31.802794,1.620111,0.609834,-388.318695,0.061902,0.000000
53.180004,7.270569,-388.318695,0.012301,0.002423,0.061547,32.341106,1.647534,0.615469,-388.318695,0.062388,0.000000
53.470001,7.260887,-388.363190,0.012322,0.002441,0.061989,32.298038,1.645341,0.619890,-388.363190,0.062874,0.000000
53.760002,7.175987,-388.274231,0.012344,0.002457,0.062397,31.920385,1.626102,0.623966,-388.274231,0.063360,0.000000
54.050003,7.510376,-388.274231,0.012370,0.002480,0.062995,33.407822,1.701875,0.629950,-388.274231,0.063836,0.000000
54.340004,7.539421,-388.363190,0.012404,0.002501,0.063524,33.537022,1.708457,0.635242,-388.363190,0.064322,0.000000
54.630001,7.445213,-388.318695,0.012409,0.002517,0.063941,33.117962,1.687109,0.639405,-388.318695,0.064808,0.000000
54.920002,7.491386,-388.363190,0.012426,0.002535,0.064391,33.323353,1.697572,0.643913,-388.363190,0.065293,0.000000
55.210003,7.603104,-388.363190,0.012460,0.002558,0.064964,33.820293,1.722888,0.649636,-388.363190,0.065770,0.000000
55.500004,7.454147,-388.318695,0.012478,0.002569,0.065259,33.157703,1.689134,0.652588,-388.318695,0.066256,0.000000
55.790001,7.723747,-388.452148,0.012490,0.002593,0.065865,34.356945,1.750226,0.658655,-388.452148,0.066742,0.000000
56.080002,7.749443,-388.274231,0.012534,0.002613,0.066377,34.471245,1.756049,0.663772,-388.274231,0.067227,0.000000
56.370003,7.772156,-388.407654,0.012538,0.002634,0.066898,34.572277,1.761196,0.668976,-388.407654,0.067704,0.000000
56.660004,7.769554,-388.407654,0.012577,0.002651,0.067331,34.560703,1.760606,0.673314,-388.407654,0.068190,0.000000
56.950005,7.849609,-388.318695,0.012581,0.002669,0.067782,34.916805,1.778747,0.677822,-388.318695,0.068675,0.000000
57.240002,7.807533,-388.407654,0.012603,0.002687,0.068242,34.729641,1.769212,0.682420,-388.407654,0.069161,0.000000
57.530003,7.736412,-388.363190,0.012624,0.002702,0.068624,34.413280,1.753096,0.686236,-388.363190,0.069638,0.000000
57.820004,8.081596,-388.452148,0.012633,0.002724,0.069196,35.948734,1.831316,0.691958,-388.452148,0.070124,0.000000
58.110004,8.061859,-388.363190,0.012663,0.002744,0.069690,35.860939,1.826843,0.696901,-388.363190,0.070609,0.000000
58.400002,8.099098,-388.363190,0.012667,0.002765,0.070219,36.026588,1.835282,0.702193,-388.363190,0.071086,0.000000
58.690002,8.177299,-388.452148,0.012706,0.002783,0.070696,36.374443,1.853003,0.706962,-388.452148,0.071572,0.000000
58.980003,8.243584,-388.407654,0.012732,0.002804,0.071217,36.669292,1.868023,0.712166,-388.407654,0.072058,0.000000
59.270004,8.116974,-388.452148,0.012749,0.002818,0.071581,36.106102,1.839333,0.715807,-388.452148,0.072543,0.000000
59.560001,7.964302,-388.452148,0.012753,0.002830,0.071884,35.426987,1.804737,0.718842,-388.452148,0.073020,0.000000
59.850002,8.510574,-388.452148,0.012779,0.002863,0.072725,37.856926,1.928524,0.727252,-388.452148,0.073506,0.000000
60.140003,8.375031,-388.496613,0.012801,0.002880,0.073150,37.253998,1.897809,0.731503,-388.496613,0.073992,0.000000
60.430004,8.295341,-388.407654,0.012822,0.002896,0.073549,36.899521,1.879751,0.735492,-388.407654,0.074477,0.000000
60.720001,8.373909,-388.496613,0.012844,0.002915,0.074035,37.249008,1.897555,0.740348,-388.496613,0.074954,0.000000
61.010002,8.371307,-388.585602,0.012874,0.002930,0.074416,37.237434,1.896965,0.744163,-388.585602,0.075440,0.000000
61.300003,8.487488,-388.496613,0.012891,0.002950,0.074919,37.754230,1.923292,0.749193,-388.496613,0.075925,0.000000
61.590004,8.751122,-388.585602,0.012913,0.002971,0.075475,38.926933,1.983033,0.754746,-388.585602,0.076411,0.000000
61.880001,8.791344,-388.541107,0.012939,0.002994,0.076047,39.105850,1.992147,0.760469,-388.541107,0.076888,0.000000
62.170002,8.688568,-388.541107,0.012956,0.003013,0.076532,38.648682,1.968858,0.765325,-388.541107,0.077374,0.000000
62.460003,8.616699,-388.496613,0.012978,0.003028,0.076923,38.328991,1.952572,0.769227,-388.496613,0.077859,0.000000
62.750004,8.713142,-388.496613,0.012995,0.003046,0.077365,38.757992,1.974426,0.773651,-388.496613,0.078345,0.000000
63.040005,8.836769,-388.541107,0.013016,0.003065,0.077859,39.307911,2.002440,0.778595,-388.541107,0.078822,0.000000
63.330002,8.855019,-388.585602,0.013047,0.003082,0.078276,39.389091,2.006576,0.782758,-388.585602,0.079308,0.000000
63.620003,9.196480,-388.541107,0.013055,0.003107,0.078917,40.907986,2.083952,0.789173,-388.541107,0.079793,0.000000
63.910004,9.048279,-388.585602,0.013090,0.003127,0.079429,40.248753,2.050369,0.794290,-388.585602,0.080270,0.000000
64.200005,8.913109,-388.541107,0.013098,0.003144,0.079863,39.647488,2.019739,0.798628,-388.541107,0.080756,0.000000
64.490005,8.946991,-388.585602,0.013116,0.003163,0.080348,39.798203,2.027417,0.803484,-388.585602,0.081242,0.000000
64.780006,9.075462,-388.496613,0.013159,0.003180,0.080765,40.369671,2.056529,0.807647,-388.496613,0.081727,0.000000
65.070000,8.901566,-388.585602,0.013154,0.003194,0.081129,39.596142,2.017124,0.811288,-388.585602,0.082204,0.000000
65.360001,9.055351,-388.585602,0.013185,0.003212,0.081597,40.280212,2.051972,0.815970,-388.585602,0.082690,0.000000
65.650002,9.664925,-388.630066,0.013236,0.003245,0.082412,42.991734,2.190103,0.824123,-388.630066,0.083175,0.000000
65.940002,9.250847,-388.674561,0.013249,0.003257,0.082733,41.149822,2.096272,0.827333,-388.674561,0.083661,0.000000
66.230003,9.125732,-388.585602,0.013271,0.003274,0.083150,40.593285,2.067920,0.831496,-388.585602,0.084138,0.000000
66.520004,9.269096,-388.630066,0.013279,0.003292,0.083618,41.230999,2.100407,0.836178,-388.630066,0.084624,0.000000
66.810005,9.637001,-388.719025,0.013310,0.003314,0.084164,42.867523,2.183776,0.841640,-388.719025,0.085109,0.000000
67.100006,9.265739,-388.630066,0.013336,0.003324,0.084433,41.216068,2.099647,0.844331,-388.630066,0.085595,0.000000
67.389999,9.701790,-388.674561,0.013353,0.003349,0.085075,43.155716,2.198457,0.850746,-388.674561,0.086072,0.000000
67.680000,9.968040,-388.585602,0.013413,0.003377,0.085777,44.340057,2.258790,0.857771,-388.585602,0.086558,0.000000
67.970001,9.694344,-388.630066,0.013417,0.003393,0.086185,43.122593,2.196770,0.861847,-388.630066,0.087043,0.000000
68.260002,9.588959,-388.674561,0.013426,0.003408,0.086566,42.653820,2.172889,0.865662,-388.674561,0.087529,0.000000
68.550003,9.641464,-388.630066,0.013439,0.003426,0.087017,42.887375,2.184787,0.870174,-388.630066,0.088006,0.000000
68.840004,9.927452,-388.674561,0.013465,0.003445,0.087512,44.159512,2.249593,0.875117,-388.674561,0.088492,0.000000
69.130005,9.836594,-388.674561,0.013491,0.003460,0.087885,43.755352,2.229004,0.878845,-388.674561,0.088977,0.000000
69.420006,10.611870,-388.630066,0.013512,0.003492,0.088708,47.203953,2.404684,0.887085,-388.630066,0.089454,0.000000
69.710007,10.194443,-388.719025,0.013555,0.003509,0.089116,45.347145,2.310094,0.891161,-388.719025,0.089940,0.000000
70.000000,10.243965,-388.674561,0.013581,0.003527,0.089593,45.567432,2.321316,0.895930,-388.674561,0.090425,0.000000
70.290001,10.115494,-388.763519,0.013577,0.003543,0.089983,44.995964,2.292204,0.899832,-388.763519,0.090911,0.000000
70.580002,10.260719,-388.674561,0.013603,0.003557,0.090356,45.641960,2.325112,0.903560,-388.674561,0.091388,0.000000
70.870003,10.529205,-388.674561,0.013616,0.003578,0.090894,46.836243,2.385952,0.908939,-388.674561,0.091874,0.000000
71.160004,10.410789,-388.763519,0.013646,0.003591,0.091215,46.309505,2.359118,0.912148,-388.763519,0.092359,0.000000
71.450005,10.836411,-388.719025,0.013668,0.003617,0.091874,48.202763,2.455566,0.918738,-388.719025,0.092845,0.000000
71.740005,10.988335,-388.719025,0.013685,0.003639,0.092429,48.878555,2.489992,0.924286,-388.719025,0.093322,0.000000
72.030006,11.126114,-388.763519,0.013724,0.003659,0.092949,49.491425,2.521213,0.929491,-388.763519,0.093807,0.000000
72.320000,11.211014,-388.763519,0.013745,0.003675,0.093357,49.869080,2.540452,0.933567,-388.763519,0.094293,0.000000
72.610001,11.349915,-388.807983,0.013754,0.003697,0.093895,50.486942,2.571927,0.938945,-388.807983,0.094779,0.000000
72.900002,11.388641,-388.763519,0.013793,0.003712,0.094293,50.659206,2.580703,0.942935,-388.763519,0.095256,0.000000
73.190002,11.603500,-388.763519,0.013805,0.003730,0.094744,51.614948,2.629391,0.947442,-388.763519,0.095742,0.000000
73.480003,11.927086,-388.807983,0.013810,0.003755,0.095386,53.054329,2.702716,0.953862,-388.807983,0.096227,0.000000
73.770004,12.234299,-388.807983,0.013853,0.003775,0.095880,54.420879,2.772332,0.958805,-388.807983,0.096713,0.000000
74.060005,12.294250,-388.852478,0.013866,0.003792,0.096305,54.687557,2.785917,0.963051,-388.852478,0.097190,0.000000
74.350006,12.605553,-388.807983,0.013892,0.003812,0.096817,56.072300,2.856459,0.968169,-388.807983,0.097676,0.000000
74.640007,12.692314,-388.807983,0.013909,0.003829,0.097259,56.458233,2.876119,0.972593,-388.807983,0.098161,0.000000
74.930000,12.702744,-388.852478,0.013926,0.003841,0.097572,56.504623,2.878483,0.975716,-388.852478,0.098638,0.000000
75.220001,13.177513,-388.807983,0.013926,0.003863,0.098126,58.616505,2.986067,0.981264,-388.807983,0.099124,0.000000
75.510002,13.762512,-388.896942,0.013965,0.003888,0.098751,61.218712,3.118630,0.987509,-388.896942,0.099609,0.000000
75.800003,13.790070,-388.852478,0.013991,0.003907,0.099245,61.341293,3.124874,0.992452,-388.852478,0.100095,0.000000
76.090004,13.950935,-388.807983,0.013999,0.003923,0.099635,62.056858,3.161327,0.996355,-388.807983,0.100572,0.000000
76.380005,14.517685,-388.852478,0.014017,0.003944,0.100182,64.577888,3.289754,1.001816,-388.852478,0.101058,0.000000
76.670006,14.735519,-388.852478,0.014038,0.003962,0.100624,65.546867,3.339116,1.006241,-388.852478,0.101543,0.000000
76.960007,15.221840,-388.852478,0.014051,0.003983,0.101162,67.710129,3.449318,1.011619,-388.852478,0.102029,0.000000
77.250000,15.760292,-388.896942,0.014068,0.004003,0.101673,70.105278,3.571333,1.016733,-388.896942,0.102506,0.000000
77.540001,15.982597,-388.896942,0.014086,0.004022,0.102151,71.094147,3.621708,1.021505,-388.896942,0.102992,0.000000
77.830002,16.347153,-388.941437,0.014107,0.004040,0.102619,72.715767,3.704318,1.026187,-388.941437,0.103477,0.000000
78.120003,16.695320,-388.852478,0.014137,0.004058,0.103078,74.264496,3.783214,1.030782,-388.852478,0.103963,0.000000
78.410004,16.934380,-388.896942,0.014133,0.004077,0.103564,75.327881,3.837385,1.035638,-388.896942,0.104440,0.000000
78.700005,17.349205,-388.941437,0.014159,0.004093,0.103954,77.173119,3.931386,1.039540,-388.941437,0.104926,0.000000
78.990005,18.025063,-388.896942,0.014176,0.004113,0.104474,80.179482,4.084538,1.044745,-388.896942,0.105411,0.000000
79.280006,18.676712,-389.030396,0.014189,0.004134,0.105004,83.078163,4.232203,1.050036,-389.030396,0.105897,0.000000
79.570007,19.122444,-388.852478,0.014215,0.004154,0.105524,85.060883,4.333208,1.055240,-388.852478,0.106374,0.000000
79.860001,19.385338,-388.985931,0.014228,0.004168,0.105879,86.230286,4.392780,1.058794,-388.985931,0.106859,0.000000
80.150002,20.363556,-389.030396,0.014224,0.004194,0.106530,90.581619,4.614448,1.065300,-389.030396,0.107345,0.000000
80.440002,20.662575,-388.985931,0.014250,0.004210,0.106946,91.911720,4.682206,1.069460,-388.985931,0.107822,0.000000
80.730003,20.886002,-389.119354,0.014271,0.004223,0.107267,92.905579,4.732836,1.072670,-389.119354,0.108308,0.000000
81.020004,21.813576,-388.985931,0.014284,0.004247,0.107883,97.031631,4.943027,1.078828,-388.985931,0.108793,0.000000
81.310005,22.581039,-388.985931,0.014301,0.004266,0.108351,100.445480,5.116937,1.083509,-388.985931,0.109279,0.000000
81.600006,23.193214,-389.030396,0.014327,0.004286,0.108871,103.168571,5.255657,1.088714,-389.030396,0.109756,0.000000
81.890007,23.473244,-388.985931,0.014336,0.004301,0.109244,104.414200,5.319113,1.092442,-388.985931,0.110241,0.000000
82.180000,24.363213,-388.985931,0.014340,0.004322,0.109782,108.372986,5.520783,1.097820,-388.985931,0.110727,0.000000
82.470001,24.925865,-389.030396,0.014353,0.004337,0.110164,110.875786,5.648282,1.101635,-389.030396,0.111213,0.000000
82.760002,25.722374,-389.030396,0.014362,0.004355,0.110623,114.418831,5.828773,1.106230,-389.030396,0.111690,0.000000
83.050003,27.159355,-388.985931,0.014375,0.004382,0.111300,120.810844,6.154398,1.112998,-388.985931,0.112176,0.000000
83.340004,27.855324,-388.985931,0.014396,0.004402,0.111803,123.906670,6.312107,1.118028,-388.985931,0.112661,0.000000
83.630005,28.442177,-389.074890,0.014405,0.004419,0.112245,126.517120,6.445089,1.122448,-389.074890,0.113147,0.000000
83.920006,28.981003,-388.941437,0.014413,0.004435,0.112652,128.913940,6.567189,1.126525,-388.941437,0.113624,0.000000
84.210007,29.920128,-389.074890,0.014439,0.004453,0.113095,133.091370,6.779998,1.130949,-389.074890,0.114109,0.000000
84.500008,30.463417,-388.985931,0.014444,0.004467,0.113459,135.508041,6.903109,1.134590,-388.985931,0.114595,0.000000
84.790001,31.258804,-389.030396,0.014452,0.004484,0.113901,139.046112,7.083346,1.139011,-389.030396,0.115081,0.000000
85.080002,33.455055,-389.119354,0.014474,0.004517,0.114734,148.815521,7.581024,1.147338,-389.119354,0.115558,0.000000
85.370003,33.952919,-389.030396,0.014478,0.004534,0.115159,151.030121,7.693841,1.151588,-389.030396,0.116043,0.000000
85.660004,34.693939,-389.119354,0.014500,0.004549,0.115549,154.326355,7.861759,1.155491,-389.119354,0.116529,0.000000
85.950005,35.618912,-389.119354,0.014504,0.004568,0.116035,158.440826,8.071361,1.160347,-389.119354,0.117006,0.000000
86.240005,36.827263,-389.030396,0.014517,0.004588,0.116529,163.815842,8.345178,1.165290,-389.030396,0.117491,0.000000
86.530006,37.137825,-389.163849,0.014517,0.004601,0.116867,165.197296,8.415551,1.168673,-389.163849,0.117977,0.000000
86.820007,38.825417,-389.119354,0.014521,0.004624,0.117448,172.704071,8.797965,1.174483,-389.119354,0.118463,0.000000
87.110001,40.554710,-389.119354,0.014547,0.004648,0.118055,180.396362,9.189829,1.180554,-389.119354,0.118940,0.000000
87.400002,41.201897,-389.163849,0.014547,0.004664,0.118463,183.275192,9.336484,1.184631,-389.163849,0.119426,0.000000
87.690002,41.988716,-389.208313,0.014569,0.004679,0.118836,186.775131,9.514779,1.188359,-389.208313,0.119911,0.000000
87.980003,42.938271,-389.163849,0.014556,0.004697,0.119295,190.998962,9.729951,1.192953,-389.163849,0.120397,0.000000
88.270004,44.569633,-389.163849,0.014569,0.004719,0.119851,198.255630,10.099623,1.198506,-389.163849,0.120874,0.000000
88.560005,45.357201,-389.119354,0.014586,0.004735,0.120258,201.758911,10.278089,1.202582,-389.119354,0.121359,0.000000
88.850006,47.490150,-389.208313,0.014599,0.004764,0.120995,211.246735,10.761422,1.209951,-389.208313,0.121845,0.000000
89.140007,48.952827,-389.119354,0.014590,0.004782,0.121463,217.753052,11.092870,1.214633,-389.119354,0.122331,0.000000
89.430008,49.733322,-389.208313,0.014603,0.004796,0.121819,221.224869,11.269732,1.218191,-389.208313,0.122808,0.000000
89.720001,50.861984,-389.208313,0.014620,0.004813,0.122244,226.245407,11.525491,1.222442,-389.208313,0.123293,0.000000
90.010002,52.082619,-389.163849,0.014625,0.004831,0.122712,231.675064,11.802090,1.227123,-389.163849,0.123779,0.000000
90.300003,53.547157,-389.208313,0.014620,0.004849,0.123172,238.189651,12.133959,1.231718,-389.208313,0.124265,0.000000
90.590004,54.240891,-389.208313,0.014638,0.004863,0.123510,241.275528,12.291162,1.235102,-389.208313,0.124741,0.000000
90.880005,57.341637,-389.208313,0.014651,0.004898,0.124403,255.068344,12.993801,1.244034,-389.208313,0.125227,0.000000
91.170006,58.241661,-389.208313,0.014659,0.004911,0.124733,259.071838,13.197749,1.247331,-389.208313,0.125713,0.000000
91.460007,59.721092,-389.252808,0.014651,0.004930,0.125219,265.652679,13.532992,1.252187,-389.252808,0.126199,0.000000
91.750008,60.746605,-389.208313,0.014663,0.004945,0.125600,270.214386,13.765377,1.256002,-389.208313,0.126676,0.000000
92.040001,62.620758,-389.208313,0.014685,0.004968,0.126190,278.551056,14.190066,1.261899,-389.208313,0.127161,0.000000
92.330002,63.667122,-389.208313,0.014681,0.004983,0.126563,283.205505,14.427176,1.265627,-389.208313,0.127647,0.000000
92.620003,65.444084,-389.252808,0.014676,0.005005,0.127118,291.109833,14.829841,1.271180,-389.252808,0.128124,0.000000
92.910004,66.936928,-389.208313,0.014689,0.005022,0.127551,297.750336,15.168124,1.275513,-389.208313,0.128610,0.000000
93.200005,67.169655,-389.252808,0.014689,0.005020,0.127499,298.785553,15.220861,1.274995,-389.252808,0.127708,0.000000
93.490005,66.645363,-389.297272,0.014715,0.005019,0.127482,296.453369,15.102056,1.274821,-389.297272,0.127491,0.000000
93.780006,66.213402,-389.297272,0.014711,0.005018,0.127465,294.531921,15.004171,1.274647,-389.297272,0.127491,0.000000
94.070007,65.855553,-389.341766,0.014715,0.005018,0.127456,292.940125,14.923081,1.274560,-389.341766,0.127491,0.000000
94.360008,65.549461,-389.252808,0.014724,0.005018,0.127447,291.578552,14.853720,1.274473,-389.252808,0.127491,0.000000
94.650002,65.280251,-389.252808,0.014715,0.005018,0.127447,290.381042,14.792717,1.274473,-389.252808,0.127491,0.000000
94.940002,65.024422,-389.341766,0.014720,0.005018,0.127447,289.243073,14.734745,1.274473,-389.341766,0.127491,0.000000
95.230003,64.816643,-389.297272,0.014715,0.005017,0.127439,288.318817,14.687661,1.274385,-389.297272,0.127491,0.000000
95.520004,64.618538,-389.386230,0.014724,0.005017,0.127439,287.437622,14.642771,1.274385,-389.386230,0.127491,0.000000
95.810005,64.440544,-389.297272,0.014724,0.005017,0.127439,286.645844,14.602436,1.274385,-389.297272,0.127491,0.000000
96.100006,64.278938,-389.297272,0.014720,0.005017,0.127439,285.927002,14.565815,1.274385,-389.297272,0.127491,0.000000
96.390007,64.140038,-389.297272,0.014732,0.005017,0.127439,285.309143,14.534341,1.274385,-389.297272,0.127491,0.000000
96.680008,63.998543,-389.297272,0.014720,0.005017,0.127439,284.679749,14.502277,1.274385,-389.297272,0.127491,0.000000
96.970001,63.848473,-389.386230,0.014724,0.005017,0.127439,284.012177,14.468270,1.274385,-389.386230,0.127491,0.000000
97.260002,63.741966,-389.341766,0.014732,0.005017,0.127439,283.538422,14.444136,1.274385,-389.341766,0.127491,0.000000
97.550003,63.624306,-389.386230,0.014732,0.005017,0.127439,283.015045,14.417474,1.274385,-389.386230,0.127491,0.000000
97.840004,63.532692,-389.386230,0.014728,0.005017,0.127439,282.607513,14.396713,1.274385,-389.386230,0.127491,0.000000
98.130005,63.442589,-389.386230,0.014715,0.005017,0.127439,282.206726,14.376296,1.274385,-389.386230,0.127491,0.000000
98.420006,63.326027,-389.386230,0.014728,0.005017,0.127439,281.688232,14.349883,1.274385,-389.386230,0.127491,0.000000
98.710007,63.245979,-389.386230,0.014737,0.005017,0.127430,281.332153,14.331744,1.274298,-389.386230,0.127491,0.000000
99.000008,63.171867,-389.386230,0.014724,0.005017,0.127430,281.002502,14.314950,1.274298,-389.386230,0.127491,0.000000
99.290001,63.091438,-389.475220,0.014724,0.005017,0.127430,280.644745,14.296724,1.274298,-389.475220,0.127491,0.000000
99.580002,63.014732,-389.430725,0.014741,0.005017,0.127430,280.303528,14.279343,1.274298,-389.430725,0.127491,0.000000
99.870003,62.935043,-389.475220,0.014724,0.005017,0.127430,279.949066,14.261285,1.274298,-389.475220,0.127491,0.000000
100.160004,62.870995,-389.430725,0.014732,0.005017,0.127430,279.664154,14.246771,1.274298,-389.430725,0.127491,0.000000
100.450005,62.806198,-389.386230,0.014728,0.005017,0.127430,279.375916,14.232087,1.274298,-389.386230,0.127491,0.000000
100.740005,62.733589,-389.475220,0.014724,0.005017,0.127430,279.052948,14.215634,1.274298,-389.475220,0.127491,0.000000
101.030006,62.681831,-389.430725,0.014732,0.005017,0.127430,278.822723,14.203906,1.274298,-389.430725,0.127491,0.000000
101.320007,62.607727,-389.430725,0.014728,0.005017,0.127430,278.493073,14.187114,1.274298,-389.430725,0.127491,0.000000
101.610008,62.544792,-389.519684,0.014741,0.005017,0.127430,278.213135,14.172853,1.274298,-389.519684,0.127491,0.000000
101.900002,62.484474,-389.430725,0.014732,0.005017,0.127430,277.944824,14.159184,1.274298,-389.430725,0.127491,0.000000
102.190002,62.433830,-389.475220,0.014732,0.005017,0.127430,277.719543,14.147708,1.274298,-389.475220,0.127491,0.000000
102.480003,62.393982,-389.519684,0.014732,0.005017,0.127430,277.542297,14.138679,1.274298,-389.519684,0.127491,0.000000
102.770004,62.342598,-389.475220,0.014728,0.005017,0.127430,277.313721,14.127035,1.274298,-389.475220,0.127491,0.000000
103.060005,62.284508,-389.475220,0.014724,0.005017,0.127430,277.055328,14.113871,1.274298,-389.475220,0.127491,0.000000
103.350006,62.240196,-389.475220,0.014737,0.005017,0.127430,276.858215,14.103830,1.274298,-389.475220,0.127491,0.000000
103.640007,62.189552,-389.519684,0.014745,0.005017,0.127430,276.632935,14.092355,1.274298,-389.519684,0.127491,0.000000
103.930008,62.154922,-389.519684,0.014728,0.005017,0.127430,276.478912,14.084507,1.274298,-389.519684,0.127491,0.000000
104.220001,62.098694,-389.519684,0.014741,0.005017,0.127430,276.228790,14.071765,1.274298,-389.519684,0.127491,0.000000
104.510002,62.057732,-389.564178,0.014737,0.005017,0.127430,276.046570,14.062483,1.274298,-389.564178,0.127491,0.000000
104.800003,62.022728,-389.564178,0.014737,0.005017,0.127430,275.890869,14.054551,1.274298,-389.564178,0.127491,0.000000
105.090004,61.981392,-389.564178,0.014741,0.005017,0.127430,275.707001,14.045184,1.274298,-389.564178,0.127491,0.000000
105.380005,61.953094,-389.608643,0.014741,0.005017,0.127430,275.581116,14.038772,1.274298,-389.608643,0.127491,0.000000
105.670006,61.917351,-389.608643,0.014741,0.005017,0.127430,275.422119,14.030672,1.274298,-389.608643,0.127491,0.000000
105.960007,61.869682,-389.608643,0.014732,0.005017,0.127430,275.210083,14.019871,1.274298,-389.608643,0.127491,0.000000
106.250008,61.843620,-389.564178,0.014741,0.005017,0.127430,275.094177,14.013965,1.274298,-389.564178,0.127491,0.000000
106.540009,61.803772,-389.564178,0.014741,0.005017,0.127430,274.916901,14.004934,1.274298,-389.564178,0.127491,0.000000
106.830002,61.767281,-389.608643,0.014745,0.005017,0.127430,274.754578,13.996666,1.274298,-389.608643,0.127491,0.000000
107.120003,61.735260,-389.564178,0.014728,0.005017,0.127430,274.612152,13.989409,1.274298,-389.564178,0.127491,0.000000
107.410004,61.700256,-389.697601,0.014732,0.005017,0.127430,274.456451,13.981478,1.274298,-389.697601,0.127491,0.000000
107.700005,61.660042,-389.608643,0.014741,0.005017,0.127430,274.277557,13.972364,1.274298,-389.608643,0.127491,0.000000
107.990005,61.635834,-389.608643,0.014732,0.005017,0.127430,274.169891,13.966880,1.274298,-389.608643,0.127491,0.000000
108.280006,61.608650,-389.653137,0.014750,0.005017,0.127430,274.048950,13.960720,1.274298,-389.653137,0.127491,0.000000
108.570007,61.581093,-389.608643,0.014741,0.005017,0.127430,273.926392,13.954475,1.274298,-389.608643,0.127491,0.000000
108.860008,61.556519,-389.653137,0.014732,0.005017,0.127430,273.817078,13.948906,1.274298,-389.653137,0.127491,0.000000
109.150002,61.516304,-389.653137,0.014741,0.005017,0.127430,273.638184,13.939794,1.274298,-389.653137,0.127491,0.000000
109.440002,61.491722,-389.697601,0.014741,0.005017,0.127430,273.528839,13.934223,1.274298,-389.697601,0.127491,0.000000
109.730003,61.464172,-389.697601,0.014728,0.005017,0.127430,273.406281,13.927980,1.274298,-389.697601,0.127491,0.000000
110.020004,61.434006,-389.608643,0.014737,0.005017,0.127430,273.272095,13.921144,1.274298,-389.608643,0.127491,0.000000
110.310005,61.417625,-389.697601,0.014737,0.005017,0.127430,273.199249,13.917434,1.274298,-389.697601,0.127491,0.000000
110.600006,61.399376,-389.653137,0.014737,0.005017,0.127430,273.118073,13.913298,1.274298,-389.653137,0.127491,0.000000
110.890007,61.354691,-389.697601,0.014737,0.005017,0.127430,272.919281,13.903172,1.274298,-389.697601,0.127491,0.000000
111.180008,61.336823,-389.697601,0.014741,0.005017,0.127430,272.839813,13.899123,1.274298,-389.697601,0.127491,0.000000
111.470009,61.307404,-389.697601,0.014737,0.005017,0.127430,272.708954,13.892456,1.274298,-389.697601,0.127491,0.000000
111.760002,61.294739,-389.786560,0.014750,0.005017,0.127430,272.652618,13.889586,1.274298,-389.786560,0.127491,0.000000
112.050003,61.261971,-389.742096,0.014745,0.005017,0.127430,272.506866,13.882161,1.274298,-389.742096,0.127491,0.000000
112.340004,61.245956,-389.697601,0.014750,0.005017,0.127430,272.435608,13.878532,1.274298,-389.697601,0.127491,0.000000
112.630005,61.232552,-389.742096,0.014745,0.005017,0.127430,272.376007,13.875495,1.274298,-389.742096,0.127491,0.000000
112.920006,61.200157,-389.697601,0.014741,0.005017,0.127430,272.231903,13.868154,1.274298,-389.697601,0.127491,0.000000
113.210007,61.174461,-389.786560,0.014732,0.005017,0.127430,272.117584,13.862331,1.274298,-389.786560,0.127491,0.000000
113.500008,61.151749,-389.697601,0.014741,0.005017,0.127430,272.016571,13.857184,1.274298,-389.697601,0.127491,0.000000
113.790009,61.128662,-389.742096,0.014741,0.005017,0.127430,271.913879,13.851953,1.274298,-389.742096,0.127491,0.000000
114.080002,61.117493,-389.786560,0.014745,0.005017,0.127430,271.864197,13.849422,1.274298,-389.786560,0.127491,0.000000
114.370003,61.106323,-389.786560,0.014745,0.005017,0.127430,271.814514,13.846890,1.274298,-389.786560,0.127491,0.000000
114.660004,61.082115,-389.786560,0.014741,0.005017,0.127430,271.706818,13.841405,1.274298,-389.786560,0.127491,0.000000
114.950005,61.054558,-389.786560,0.014732,0.005017,0.127430,271.584229,13.835160,1.274298,-389.786560,0.127491,0.000000
115.240005,61.028496,-389.742096,0.014741,0.005017,0.127430,271.468292,13.829255,1.274298,-389.742096,0.127491,0.000000
115.530006,61.013969,-389.786560,0.014737,0.005017,0.127430,271.403687,13.825963,1.274298,-389.786560,0.127491,0.000000
115.820007,60.994606,-389.742096,0.014745,0.005017,0.127430,271.317566,13.821575,1.274298,-389.742096,0.127491,0.000000
116.110008,60.967056,-389.831055,0.014745,0.005017,0.127430,271.195007,13.815333,1.274298,-389.831055,0.127491,0.000000
116.400009,60.946945,-389.831055,0.014750,0.005017,0.127430,271.105560,13.810776,1.274298,-389.831055,0.127491,0.000000
116.690002,60.930191,-389.831055,0.014745,0.005017,0.127430,271.031036,13.806979,1.274298,-389.831055,0.127491,0.000000
116.980003,60.901512,-389.875549,0.014741,0.005017,0.127430,270.903442,13.800480,1.274298,-389.875549,0.127491,0.000000
117.270004,60.883270,-389.831055,0.014741,0.005017,0.127430,270.822327,13.796347,1.274298,-389.831055,0.127491,0.000000
117.560005,60.861671,-389.831055,0.014750,0.005017,0.127430,270.726227,13.791452,1.274298,-389.831055,0.127491,0.000000
117.850006,60.866508,-389.831055,0.014763,0.005017,0.127430,270.747742,13.792548,1.274298,-389.831055,0.127491,0.000000
118.140007,60.845284,-389.875549,0.014745,0.005017,0.127430,270.653351,13.787738,1.274298,-389.875549,0.127491,0.000000
118.430008,60.811775,-389.831055,0.014732,0.005017,0.127430,270.504272,13.780145,1.274298,-389.831055,0.127491,0.000000
118.720009,60.792412,-389.831055,0.014754,0.005017,0.127430,270.418152,13.775758,1.274298,-389.831055,0.127491,0.000000
119.010002,60.782356,-389.875549,0.014741,0.005017,0.127430,270.373413,13.773479,1.274298,-389.875549,0.127491,0.000000
119.300003,60.769325,-389.920013,0.014750,0.005017,0.127430,270.315460,13.770527,1.274298,-389.920013,0.127491,0.000000
119.590004,60.757408,-389.875549,0.014737,0.005017,0.127430,270.262451,13.767825,1.274298,-389.875549,0.127491,0.000000
119.880005,60.738785,-389.920013,0.014754,0.005017,0.127430,270.179596,13.763605,1.274298,-389.920013,0.127491,0.000000
120.170006,60.722031,-389.964508,0.014754,0.005017,0.127430,270.105072,13.759809,1.274298,-389.964508,0.127491,0.000000
120.460007,60.704155,-389.964508,0.014750,0.005017,0.127430,270.025574,13.755757,1.274298,-389.964508,0.127491,0.000000
120.750008,60.690010,-389.920013,0.014741,0.005017,0.127430,269.962646,13.752553,1.274298,-389.920013,0.127491,0.000000
121.040009,60.669151,-389.875549,0.014741,0.005017,0.127430,269.869873,13.747826,1.274298,-389.875549,0.127491,0.000000
121.330009,60.653885,-389.964508,0.014732,0.005017,0.127430,269.801941,13.744367,1.274298,-389.964508,0.127491,0.000000
121.620003,60.643837,-389.964508,0.014754,0.005017,0.127430,269.757263,13.742090,1.274298,-389.964508,0.127491,0.000000
121.910004,60.637505,-389.964508,0.014745,0.005017,0.127430,269.729095,13.740655,1.274298,-389.964508,0.127491,0.000000
122.200005,60.618515,-389.964508,0.014750,0.005017,0.127430,269.644623,13.736352,1.274298,-389.964508,0.127491,0.000000
122.490005,60.598030,-389.964508,0.014741,0.005017,0.127430,269.553497,13.731709,1.274298,-389.964508,0.127491,0.000000
122.780006,60.574944,-389.920013,0.014741,0.005017,0.127430,269.450806,13.726478,1.274298,-389.920013,0.127491,0.000000
123.070007,60.567497,-389.920013,0.014754,0.005017,0.127430,269.417694,13.724792,1.274298,-389.920013,0.127491,0.000000
123.360008,60.552605,-389.920013,0.014754,0.005017,0.127430,269.351440,13.721416,1.274298,-389.920013,0.127491,0.000000
123.500008,60.552971,-390.008972,0.014732,0.005017,0.127430,269.353058,13.721499,1.274298,-390.008972,0.127491,0.000000