File: Data/compression 5/AutoNoheating-17-5-1-240223_02232024_194527.csv
Time (sec),S:Load (lbs),S:HL1 (DIM),S:LVDT (in),S:Position (in),Ch:Position (mm),Ch:Load (N),Ch:Stress (MPa),Ch:Strain (mm/mm),Ch:HL1 (DIM),Set Point (),Cycles ()
0.110000,-0.006706,-407.178619,0.000004,-0.000000,-0.000000,-0.029831,-0.001520,-0.000000,-407.178619,0.000208,0.000000
0.340000,-0.008194,-407.178619,-0.000004,-0.000000,-0.000000,-0.036449,-0.001857,-0.000000,-407.178619,0.000208,0.000000
0.570000,-0.015266,-407.267578,-0.000009,0.000100,0.002532,-0.067908,-0.003459,0.025323,-407.267578,0.003296,0.000000
0.800000,-0.023460,-407.267578,0.000091,0.000247,0.006270,-0.104357,-0.005316,0.062701,-407.267578,0.007129,0.000000
1.030000,-0.002983,-407.267578,0.000241,0.000388,0.009860,-0.013269,-0.000676,0.098604,-407.267578,0.010962,0.000000
1.260000,0.004837,-407.223114,0.000397,0.000543,0.013780,0.021516,0.001096,0.137802,-407.223114,0.014795,0.000000
1.490000,0.000748,-407.223114,0.000548,0.000692,0.017570,0.003326,0.000169,0.175701,-407.223114,0.018611,0.000000
1.720000,0.030159,-407.267578,0.000668,0.000834,0.021186,0.134154,0.006834,0.211863,-407.267578,0.022444,0.000000
1.950000,0.018616,-407.267578,0.000841,0.000993,0.025219,0.082807,0.004218,0.252189,-407.267578,0.026277,0.000000
2.180000,-0.019737,-407.356537,0.000992,0.001145,0.029078,-0.087796,-0.004473,0.290780,-407.356537,0.030110,0.000000
2.410000,-0.030159,-407.223114,0.001155,0.001293,0.032833,-0.134154,-0.006834,0.328332,-407.223114,0.033943,0.000000
2.640000,-0.004845,-407.312073,0.001293,0.001449,0.036796,-0.021550,-0.001098,0.367964,-407.312073,0.037776,0.000000
2.870000,0.019737,-407.267578,0.001457,0.001594,0.040500,0.087796,0.004473,0.404995,-407.267578,0.041610,0.000000
3.100000,0.019363,-407.267578,0.001608,0.001748,0.044393,0.086133,0.004388,0.443934,-407.267578,0.045443,0.000000
3.330000,0.004837,-407.356537,0.001768,0.001899,0.048235,0.021516,0.001096,0.482351,-407.356537,0.049276,0.000000
3.560000,-0.010796,-407.312073,0.001901,0.002049,0.052034,-0.048021,-0.002446,0.520336,-407.312073,0.053109,0.000000
3.790000,0.011917,-407.312073,0.002065,0.002198,0.055841,0.053010,0.002700,0.558408,-407.312073,0.056942,0.000000
4.020000,0.023834,-407.312073,0.002229,0.002350,0.059691,0.106020,0.005401,0.596912,-407.312073,0.060775,0.000000
4.250000,0.021225,-407.312073,0.002363,0.002497,0.063420,0.094413,0.004810,0.634201,-407.312073,0.064608,0.000000
4.480000,0.008934,-407.356537,0.002522,0.002659,0.067531,0.039741,0.002024,0.675309,-407.356537,0.068424,0.000000
4.710000,-0.044685,-407.312073,0.002656,0.002798,0.071078,-0.198770,-0.010126,0.710777,-407.312073,0.072257,0.000000
4.940000,-0.022346,-407.267578,0.002833,0.002953,0.075015,-0.099402,-0.005064,0.750151,-407.267578,0.076090,0.000000
5.170000,0.029419,-407.401031,0.002984,0.003105,0.078865,0.130862,0.006666,0.788655,-407.401031,0.079923,0.000000
5.400000,0.032768,-407.356537,0.003126,0.003252,0.082612,0.145760,0.007425,0.826118,-407.356537,0.083757,0.000000
5.630000,0.045425,-407.356537,0.003272,0.003408,0.086567,0.202062,0.010294,0.865666,-407.356537,0.087590,0.000000
5.860000,0.002975,-407.312073,0.003441,0.003558,0.090373,0.013236,0.000674,0.903735,-407.312073,0.091423,0.000000
6.090000,0.018616,-407.356537,0.003587,0.003707,0.094146,0.082807,0.004218,0.941459,-407.356537,0.095256,0.000000
6.320000,0.019363,-407.356537,0.003751,0.003858,0.097988,0.086133,0.004388,0.979879,-407.356537,0.099089,0.000000
6.550000,0.040215,-407.445526,0.003893,0.004005,0.101734,0.178883,0.009113,1.017342,-407.445526,0.102922,0.000000
6.780000,-0.002609,-407.356537,0.004023,0.004157,0.105585,-0.011607,-0.000591,1.055846,-407.356537,0.106756,0.000000
7.010000,-0.019363,-407.356537,0.004204,0.004316,0.109626,-0.086133,-0.004388,1.096261,-407.356537,0.110589,0.000000
7.240000,-0.033890,-407.356537,0.004346,0.004461,0.113312,-0.150749,-0.007680,1.133118,-407.356537,0.114405,0.000000
7.470000,0.017128,-407.401031,0.004493,0.004616,0.117249,0.076189,0.003881,1.172489,-407.401031,0.118237,0.000000
7.700000,0.052132,-407.401031,0.004639,0.004766,0.121065,0.231893,0.011813,1.210648,-407.401031,0.122071,0.000000
7.930000,0.058838,-407.445526,0.004781,0.004916,0.124872,0.261724,0.013333,1.248716,-407.445526,0.125904,0.000000
8.160001,0.028671,-407.401031,0.004950,0.005068,0.128731,0.127536,0.006497,1.287311,-407.401031,0.129737,0.000000
8.390000,0.006699,-407.401031,0.005113,0.005218,0.132538,0.029797,0.001518,1.325379,-407.401031,0.133570,0.000000
8.620001,0.018250,-407.401031,0.005260,0.005364,0.136241,0.081178,0.004135,1.362411,-407.401031,0.137403,0.000000
8.850000,0.014893,-407.445526,0.005385,0.005517,0.140135,0.066245,0.003375,1.401350,-407.445526,0.141236,0.000000
9.080001,0.027557,-407.445526,0.005553,0.005668,0.143960,0.122581,0.006245,1.439596,-407.445526,0.145069,0.000000
9.310000,0.017502,-407.401031,0.005713,0.005825,0.147966,0.077852,0.003966,1.479659,-407.401031,0.148903,0.000000
9.540001,0.017128,-407.401031,0.005868,0.005969,0.151617,0.076189,0.003881,1.516172,-407.401031,0.152736,0.000000
9.770000,0.018616,-407.489990,0.006032,0.006121,0.155485,0.082807,0.004218,1.554850,-407.489990,0.156569,0.000000
10.000000,0.036865,-407.489990,0.006183,0.006274,0.159361,0.163985,0.008354,1.593615,-407.489990,0.160402,0.000000
10.230000,0.042824,-407.489990,0.006321,0.006420,0.163073,0.190490,0.009704,1.630730,-407.489990,0.164218,0.000000
10.460000,0.045799,-407.489990,0.006459,0.006570,0.166880,0.203725,0.010378,1.668802,-407.489990,0.168051,0.000000
10.690001,0.032021,-407.445526,0.006631,0.006728,0.170896,0.142435,0.007256,1.708956,-407.445526,0.171884,0.000000
10.920000,0.001114,-407.534485,0.006765,0.006874,0.174598,0.004955,0.000252,1.745983,-407.534485,0.175717,0.000000
11.150001,0.024948,-407.489990,0.006920,0.007023,0.178388,0.110975,0.005653,1.783882,-407.489990,0.179550,0.000000
11.380000,0.023834,-407.489990,0.007058,0.007178,0.182317,0.106020,0.005401,1.823169,-407.489990,0.183383,0.000000
11.610001,0.058464,-407.445526,0.007226,0.007324,0.186020,0.260061,0.013248,1.860200,-407.445526,0.187217,0.000000
11.840000,0.056229,-407.489990,0.007377,0.007480,0.190001,0.250117,0.012742,1.900006,-407.489990,0.191050,0.000000
12.070001,0.032394,-407.489990,0.007537,0.007633,0.193868,0.144098,0.007341,1.938684,-407.489990,0.194883,0.000000
12.300000,0.036865,-407.534485,0.007683,0.007780,0.197623,0.163985,0.008354,1.976234,-407.534485,0.198716,0.000000
12.530001,0.051758,-407.489990,0.007825,0.007934,0.201535,0.230230,0.011728,2.015347,-407.489990,0.202549,0.000000
12.760000,0.069633,-407.445526,0.007972,0.008074,0.205090,0.309745,0.015779,2.050902,-407.445526,0.206382,0.000000
12.990001,0.077454,-407.534485,0.008140,0.008234,0.209131,0.344531,0.017551,2.091313,-407.534485,0.210198,0.000000
13.220000,0.079315,-407.489990,0.008295,0.008386,0.213017,0.352812,0.017973,2.130165,-407.489990,0.214031,0.000000
13.450001,0.233101,-407.534485,0.008438,0.008536,0.216824,1.036885,0.052821,2.168238,-407.534485,0.217864,0.000000
13.680000,0.715324,-407.578949,0.008524,-0.000002,-0.000044,3.181922,0.162095,-0.000435,-407.578949,0.000087,0.000000
13.910001,0.671387,-407.489990,0.008532,-0.000002,-0.000052,2.986477,0.152138,-0.000519,-407.489990,0.000087,0.000000
14.140000,0.670273,-407.489990,0.008541,-0.000002,-0.000052,2.981523,0.151886,-0.000519,-407.489990,0.000148,0.000000
14.370001,0.651649,-407.578949,0.008532,-0.000002,-0.000052,2.898682,0.147666,-0.000519,-407.578949,0.000529,0.000000
14.600000,0.648674,-407.623444,0.008532,-0.000002,-0.000052,2.885446,0.146992,-0.000519,-407.623444,0.000911,0.000000
14.830001,0.622604,-407.534485,0.008528,-0.000002,-0.000052,2.769483,0.141084,-0.000519,-407.534485,0.001301,0.000000
15.060000,0.987534,-407.623444,0.008554,0.000037,0.000928,4.392769,0.223778,0.009281,-407.623444,0.001682,0.000000
15.290001,1.104828,-407.489990,0.008554,0.000048,0.001223,4.914520,0.250358,0.012229,-407.489990,0.002064,0.000000
15.520000,1.310753,-407.578949,0.008576,0.000065,0.001648,5.830520,0.297021,0.016476,-407.578949,0.002445,0.000000
15.750001,1.485764,-407.578949,0.008597,0.000077,0.001951,6.609006,0.336679,0.019511,-407.578949,0.002827,0.000000
15.980000,1.670090,-407.578949,0.008589,0.000090,0.002289,7.428930,0.378448,0.022895,-407.578949,0.003218,0.000000
16.210001,1.886810,-407.578949,0.008623,0.000108,0.002740,8.392951,0.427557,0.027403,-407.578949,0.003599,0.000000
16.440001,2.104652,-407.578949,0.008640,0.000124,0.003139,9.361961,0.476921,0.031392,-407.578949,0.003981,0.000000
16.670000,2.301262,-407.623444,0.008649,0.000137,0.003486,10.236525,0.521473,0.034863,-407.623444,0.004362,0.000000
16.900002,2.479256,-407.623444,0.008658,0.000150,0.003807,11.028280,0.561807,0.038072,-407.623444,0.004744,0.000000
17.130001,2.631180,-407.623444,0.008666,0.000165,0.004189,11.704072,0.596234,0.041887,-407.623444,0.005134,0.000000
17.360001,3.021805,-407.578949,0.008688,0.000184,0.004674,13.441659,0.684751,0.046743,-407.578949,0.005516,0.000000
17.590000,3.244110,-407.578949,0.008705,0.000200,0.005082,14.430523,0.735126,0.050820,-407.578949,0.005897,0.000000
17.820002,3.422104,-407.623444,0.008705,0.000212,0.005377,15.222279,0.775460,0.053768,-407.623444,0.006279,0.000000
18.050001,3.663025,-407.667908,0.008722,0.000227,0.005758,16.293949,0.830053,0.057583,-407.667908,0.006660,0.000000
18.280001,4.010826,-407.667908,0.008739,0.000244,0.006201,17.841045,0.908866,0.062008,-407.667908,0.007051,0.000000
18.510000,4.200363,-407.578949,0.008757,0.000257,0.006539,18.684149,0.951816,0.065388,-407.578949,0.007432,0.000000
18.740002,4.450966,-407.623444,0.008757,0.000275,0.006973,19.798885,1.008603,0.069725,-407.623444,0.007814,0.000000
18.970001,4.706787,-407.667908,0.008787,0.000290,0.007354,20.936834,1.066573,0.073541,-407.667908,0.008195,0.000000
19.200001,4.849403,-407.667908,0.008774,0.000301,0.007649,21.571224,1.098890,0.076489,-407.667908,0.008577,0.000000
19.430000,5.279869,-407.667908,0.008787,0.000321,0.008152,23.486031,1.196435,0.081519,-407.667908,0.008967,0.000000
19.660002,5.483185,-407.623444,0.008817,0.000335,0.008507,24.390425,1.242507,0.085073,-407.623444,0.009349,0.000000
19.890001,5.479088,-407.667908,0.008821,0.000341,0.008664,24.372200,1.241579,0.086636,-407.667908,0.009730,0.000000
20.120001,5.895027,-407.712402,0.008839,0.000362,0.009193,26.222391,1.335832,0.091928,-407.712402,0.010112,0.000000
20.350000,6.230911,-407.756866,0.008852,0.000382,0.009713,27.716478,1.411945,0.097128,-407.756866,0.010494,0.000000
20.580002,6.354164,-407.667908,0.008869,0.000398,0.010112,28.264734,1.439874,0.101117,-407.667908,0.010884,0.000000
20.810001,6.480026,-407.667908,0.008877,0.000409,0.010390,28.824596,1.468395,0.103895,-407.667908,0.011265,0.000000
21.040001,6.674034,-407.667908,0.008899,0.000425,0.010805,29.687586,1.512358,0.108055,-407.667908,0.011647,0.000000
21.270000,6.963364,-407.712402,0.008903,0.000443,0.011248,30.974588,1.577921,0.112480,-407.712402,0.012028,0.000000
21.500002,7.028160,-407.712402,0.008921,0.000454,0.011525,31.262817,1.592604,0.115254,-407.712402,0.012410,0.000000
21.730001,7.158485,-407.667908,0.008938,0.000465,0.011820,31.842533,1.622136,0.118202,-407.667908,0.012800,0.000000
21.960001,7.505539,-407.667908,0.008938,0.000487,0.012358,33.386303,1.700779,0.123581,-407.667908,0.013182,0.000000
22.190001,7.626556,-407.712402,0.008972,0.000501,0.012713,33.924618,1.728202,0.127135,-407.712402,0.013564,0.000000
22.420002,7.744232,-407.756866,0.008981,0.000516,0.013112,34.448067,1.754868,0.131124,-407.756866,0.013945,0.000000
22.650002,7.839928,-407.712402,0.008985,0.000531,0.013494,34.873741,1.776553,0.134939,-407.712402,0.014335,0.000000
22.880001,7.911049,-407.712402,0.009011,0.000546,0.013876,35.190102,1.792669,0.138758,-407.712402,0.014717,0.000000
23.110001,8.051064,-407.712402,0.009011,0.000558,0.014171,35.812920,1.824397,0.141706,-407.712402,0.015098,0.000000
23.340002,8.281937,-407.667908,0.009041,0.000576,0.014639,36.839893,1.876714,0.146388,-407.667908,0.015480,0.000000
23.570002,8.300179,-407.801361,0.009033,0.000589,0.014960,36.921040,1.880847,0.149598,-407.801361,0.015862,0.000000
23.800001,8.267410,-407.756866,0.009041,0.000598,0.015194,36.775276,1.873422,0.151937,-407.756866,0.016252,0.000000
24.030001,8.709045,-407.756866,0.009076,0.000620,0.015740,38.739769,1.973498,0.157402,-407.756866,0.016633,0.000000
24.260000,8.791710,-407.712402,0.009106,0.000636,0.016157,39.107479,1.992230,0.161566,-407.712402,0.017015,0.000000
24.490002,8.800278,-407.756866,0.009110,0.000649,0.016495,39.145592,1.994172,0.164946,-407.756866,0.017397,0.000000
24.720001,8.856880,-407.845825,0.009115,0.000664,0.016876,39.397369,2.006998,0.168761,-407.845825,0.017778,0.000000
24.950001,9.040833,-407.845825,0.009119,0.000681,0.017310,40.215633,2.048682,0.173098,-407.845825,0.018168,0.000000
25.180000,9.136528,-407.801361,0.009140,0.000695,0.017665,40.641308,2.070367,0.176652,-407.801361,0.018550,0.000000
25.410002,9.197227,-407.756866,0.009145,0.000711,0.018064,40.911312,2.084122,0.180642,-407.756866,0.018932,0.000000
25.640001,9.196114,-407.756866,0.009184,0.000722,0.018351,40.906357,2.083869,0.183507,-407.756866,0.019313,0.000000
25.870001,9.221428,-407.801361,0.009171,0.000739,0.018767,41.018959,2.089606,0.187666,-407.801361,0.019695,0.000000
26.100000,9.531616,-407.845825,0.009192,0.000756,0.019209,42.398746,2.159895,0.192091,-407.845825,0.020085,0.000000
26.330002,9.578911,-407.712402,0.009201,0.000770,0.019547,42.609123,2.170612,0.195471,-407.712402,0.020466,0.000000
26.560001,9.693596,-407.801361,0.009222,0.000788,0.020007,43.119267,2.196600,0.200070,-407.801361,0.020848,0.000000
26.790001,9.660828,-407.845825,0.009227,0.000799,0.020293,42.973507,2.189175,0.202931,-407.845825,0.021230,0.000000
27.020000,9.875320,-407.890320,0.009253,0.000818,0.020770,43.927620,2.237780,0.207700,-407.890320,0.021611,0.000000
27.250002,9.898033,-407.934814,0.009253,0.000830,0.021074,44.028652,2.242926,0.210735,-407.934814,0.022002,0.000000
27.480001,9.880531,-407.845825,0.009270,0.000842,0.021394,43.950798,2.238960,0.213945,-407.845825,0.022383,0.000000
27.710001,10.016075,-407.801361,0.009287,0.000856,0.021750,44.553726,2.269675,0.217499,-407.801361,0.022765,0.000000
27.940001,10.461060,-407.845825,0.009321,0.000881,0.022374,46.533115,2.370510,0.223744,-407.845825,0.023146,0.000000
28.170002,10.349716,-407.890320,0.009326,0.000893,0.022687,46.037838,2.345279,0.226867,-407.890320,0.023528,0.000000
28.400002,10.388077,-407.890320,0.009330,0.000909,0.023077,46.208473,2.353972,0.230769,-407.890320,0.023918,0.000000
28.630001,10.343018,-407.801361,0.009339,0.000920,0.023363,46.008041,2.343761,0.233630,-407.801361,0.024300,0.000000
28.860001,10.462173,-407.845825,0.009365,0.000934,0.023727,46.538071,2.370762,0.237271,-407.845825,0.024681,0.000000
29.090002,10.594368,-407.890320,0.009373,0.000950,0.024118,47.126102,2.400718,0.241177,-407.890320,0.025063,0.000000
29.320002,10.553406,-407.890320,0.009390,0.000963,0.024464,46.943893,2.391436,0.244644,-407.890320,0.025444,0.000000
29.550001,10.843117,-407.890320,0.009408,0.000979,0.024872,48.232594,2.457085,0.248721,-407.890320,0.025835,0.000000
29.780001,11.023338,-407.890320,0.009421,0.000998,0.025349,49.034256,2.497924,0.253490,-407.890320,0.026216,0.000000
30.010002,11.242668,-407.845825,0.009442,0.001017,0.025835,50.009884,2.547625,0.258346,-407.845825,0.026598,0.000000
30.240002,11.044937,-407.934814,0.009459,0.001028,0.026121,49.130333,2.502819,0.261207,-407.934814,0.026979,0.000000
30.470001,11.095207,-407.934814,0.009451,0.001042,0.026476,49.353947,2.514210,0.264765,-407.934814,0.027361,0.000000
30.700001,11.178993,-407.845825,0.009477,0.001055,0.026806,49.726646,2.533196,0.268061,-407.845825,0.027751,0.000000
30.930002,11.236710,-407.934814,0.009468,0.001069,0.027162,49.983379,2.546275,0.271615,-407.934814,0.028133,0.000000
31.160002,11.459763,-407.845825,0.009507,0.001086,0.027595,50.975571,2.596819,0.275953,-407.845825,0.028514,0.000000
31.390001,11.388268,-407.979279,0.009516,0.001097,0.027855,50.657543,2.580618,0.278553,-407.979279,0.028896,0.000000
31.620001,11.414330,-407.979279,0.009533,0.001110,0.028202,50.773472,2.586524,0.282020,-407.979279,0.029286,0.000000
31.850002,11.889107,-407.845825,0.009554,0.001134,0.028800,52.885387,2.694110,0.288004,-407.845825,0.029668,0.000000
32.080002,11.981453,-407.934814,0.009563,0.001149,0.029191,53.296165,2.715036,0.291910,-407.934814,0.030049,0.000000
32.310001,11.971405,-407.934814,0.009585,0.001164,0.029564,53.251469,2.712759,0.295638,-407.934814,0.030431,0.000000
32.540001,11.863785,-407.979279,0.009572,0.001174,0.029815,52.772751,2.688372,0.298151,-407.979279,0.030812,0.000000
32.770000,11.939003,-407.979279,0.009602,0.001188,0.030171,53.107338,2.705417,0.301709,-407.979279,0.031203,0.000000
33.000000,12.372818,-407.979279,0.009615,0.001209,0.030700,55.037045,2.803721,0.306997,-407.979279,0.031584,0.000000
33.230003,12.300209,-407.979279,0.009632,0.001220,0.030995,54.714062,2.787267,0.309945,-407.979279,0.031966,0.000000
33.460003,12.456604,-407.979279,0.009662,0.001236,0.031385,55.409740,2.822707,0.313847,-407.979279,0.032348,0.000000
33.690002,12.427559,-408.068237,0.009645,0.001249,0.031723,55.280544,2.816125,0.317231,-408.068237,0.032729,0.000000
33.920002,12.882973,-407.979279,0.009684,0.001273,0.032330,57.306324,2.919323,0.323302,-407.979279,0.033119,0.000000
34.150002,12.808495,-407.979279,0.009679,0.001288,0.032703,56.975029,2.902446,0.327030,-407.979279,0.033501,0.000000
34.380001,12.748543,-408.023773,0.009705,0.001298,0.032980,56.708351,2.888861,0.329804,-408.023773,0.033882,0.000000
34.610001,12.885201,-407.979279,0.009727,0.001314,0.033388,57.316235,2.919828,0.333881,-407.979279,0.034264,0.000000
34.840000,12.962654,-408.068237,0.009731,0.001330,0.033778,57.660767,2.937379,0.337783,-408.068237,0.034646,0.000000
35.070004,13.211777,-408.068237,0.009740,0.001346,0.034186,58.768917,2.993831,0.341859,-408.068237,0.035036,0.000000
35.300003,13.202835,-408.023773,0.009748,0.001360,0.034533,58.729145,2.991805,0.345330,-408.023773,0.035418,0.000000
35.530003,13.295929,-407.979279,0.009770,0.001375,0.034932,59.143246,3.012901,0.349319,-407.979279,0.035799,0.000000
35.760002,13.760651,-407.979279,0.009791,0.001396,0.035452,61.210430,3.118208,0.354524,-407.979279,0.036181,0.000000
35.990002,13.705170,-408.068237,0.009809,0.001409,0.035790,60.963638,3.105636,0.357903,-408.068237,0.036562,0.000000
36.220001,13.635536,-408.068237,0.009822,0.001421,0.036094,60.653893,3.089857,0.360939,-408.068237,0.036953,0.000000
36.450001,13.555099,-408.023773,0.009839,0.001432,0.036363,60.296093,3.071629,0.363626,-408.023773,0.037334,0.000000
36.680000,13.772942,-407.979279,0.009848,0.001448,0.036770,61.265102,3.120993,0.367703,-407.979279,0.037716,0.000000
36.910000,14.095787,-408.068237,0.009869,0.001467,0.037265,62.701191,3.194151,0.372646,-408.068237,0.038097,0.000000
37.140003,14.027641,-408.112732,0.009869,0.001477,0.037508,62.398064,3.178709,0.375076,-408.112732,0.038479,0.000000
37.370003,14.085732,-408.068237,0.009882,0.001490,0.037846,62.656464,3.191873,0.378459,-408.068237,0.038869,0.000000
37.600002,14.545616,-408.023773,0.009886,0.001512,0.038401,64.702133,3.296084,0.384008,-408.023773,0.039250,0.000000
37.830002,14.565346,-408.023773,0.009934,0.001525,0.038730,64.789894,3.300555,0.387305,-408.023773,0.039632,0.000000
38.060001,14.633865,-408.068237,0.009947,0.001540,0.039112,65.094681,3.316081,0.391120,-408.068237,0.040014,0.000000
38.290001,14.704247,-408.157196,0.009929,0.001553,0.039459,65.407753,3.332030,0.394587,-408.157196,0.040395,0.000000
38.520000,14.869576,-408.157196,0.009951,0.001569,0.039849,66.143173,3.369494,0.398489,-408.157196,0.040786,0.000000
38.750000,15.198753,-408.068237,0.009973,0.001589,0.040369,67.607430,3.444087,0.403693,-408.068237,0.041167,0.000000
38.980003,15.174179,-408.112732,0.009990,0.001601,0.040673,67.498123,3.438518,0.406729,-408.112732,0.041549,0.000000
39.210003,15.211784,-408.112732,0.010007,0.001614,0.040994,67.665398,3.447040,0.409938,-408.112732,0.041930,0.000000
39.440002,15.399094,-408.157196,0.010024,0.001631,0.041419,68.498589,3.489485,0.414189,-408.157196,0.042312,0.000000
39.670002,15.541336,-408.157196,0.010024,0.001645,0.041774,69.131317,3.521717,0.417743,-408.157196,0.042702,0.000000
39.900002,15.688423,-408.112732,0.010029,0.001661,0.042182,69.785591,3.555048,0.421819,-408.112732,0.043084,0.000000
40.130001,15.802368,-408.157196,0.010063,0.001675,0.042546,70.292442,3.580868,0.425460,-408.157196,0.043465,0.000000
40.360001,15.990044,-408.201691,0.010059,0.001692,0.042988,71.127266,3.623396,0.429885,-408.201691,0.043847,0.000000
40.590000,16.267464,-408.112732,0.010089,0.001709,0.043414,72.361290,3.686260,0.434135,-408.112732,0.044237,0.000000
40.820004,16.420135,-408.157196,0.010093,0.001726,0.043829,73.040413,3.720856,0.438295,-408.157196,0.044619,0.000000
41.050003,16.374336,-408.157196,0.010111,0.001737,0.044124,72.836685,3.710478,0.441243,-408.157196,0.045001,0.000000
41.280003,16.137878,-408.157196,0.010123,0.001747,0.044376,71.784866,3.656895,0.443760,-408.157196,0.045382,0.000000
41.510002,16.550468,-408.201691,0.010136,0.001765,0.044827,73.620163,3.750390,0.448268,-408.201691,0.045764,0.000000
41.740002,17.087799,-408.201691,0.010154,0.001786,0.045356,76.010330,3.872151,0.453559,-408.201691,0.046154,0.000000
41.970001,17.038277,-408.157196,0.010162,0.001799,0.045686,75.790039,3.860929,0.456856,-408.157196,0.046535,0.000000
42.200001,17.093010,-408.157196,0.010179,0.001814,0.046076,76.033508,3.873332,0.460758,-408.157196,0.046917,0.000000
42.430000,17.183128,-408.157196,0.010192,0.001826,0.046371,76.434372,3.893752,0.463706,-408.157196,0.047298,0.000000
42.660004,17.464272,-408.290649,0.010201,0.001843,0.046804,77.684959,3.957461,0.468040,-408.290649,0.047680,0.000000
42.890003,17.555496,-408.290649,0.010223,0.001858,0.047195,78.090744,3.978132,0.471946,-408.290649,0.048070,0.000000
43.120003,17.390167,-408.246155,0.010236,0.001866,0.047385,77.355324,3.940668,0.473854,-408.246155,0.048452,0.000000
43.350002,18.166565,-408.290649,0.010244,0.001889,0.047984,80.808914,4.116602,0.479838,-408.290649,0.048833,0.000000
43.580002,18.331520,-408.201691,0.010279,0.001906,0.048400,81.542671,4.153982,0.483997,-408.201691,0.049215,0.000000
43.810001,18.347160,-408.246155,0.010287,0.001921,0.048782,81.612244,4.157526,0.487816,-408.246155,0.049597,0.000000
44.040001,18.404510,-408.290649,0.010283,0.001934,0.049120,81.867348,4.170522,0.491196,-408.290649,0.049987,0.000000
44.270000,18.556435,-408.246155,0.010296,0.001948,0.049467,82.543144,4.204948,0.494667,-408.246155,0.050369,0.000000
44.500004,18.507652,-408.246155,0.010322,0.001963,0.049866,82.326149,4.193894,0.498656,-408.246155,0.050750,0.000000
44.730003,18.798103,-408.290649,0.010352,0.001976,0.050186,83.618141,4.259711,0.501862,-408.290649,0.051132,0.000000
44.960003,19.004402,-408.290649,0.010356,0.001991,0.050559,84.535805,4.306459,0.505594,-408.290649,0.051513,0.000000
45.190002,18.905724,-408.290649,0.010356,0.002000,0.050793,84.096855,4.284098,0.507933,-408.290649,0.051903,0.000000
45.420002,19.685097,-408.290649,0.010356,0.002024,0.051418,87.563683,4.460707,0.514178,-408.290649,0.052285,0.000000
45.650002,19.848198,-408.290649,0.010386,0.002038,0.051756,88.289192,4.497666,0.517562,-408.290649,0.052667,0.000000
45.880001,19.982994,-408.335144,0.010395,0.002053,0.052155,88.888794,4.528212,0.521551,-408.335144,0.053048,0.000000
46.110001,20.091354,-408.290649,0.010412,0.002066,0.052476,89.370811,4.552766,0.524757,-408.290649,0.053430,0.000000
46.340004,20.472290,-408.246155,0.010421,0.002086,0.052987,91.065292,4.639088,0.529874,-408.246155,0.053820,0.000000
46.570004,20.749336,-408.290649,0.010447,0.002100,0.053352,92.297661,4.701867,0.533519,-408.290649,0.054202,0.000000
46.800003,20.857697,-408.290649,0.010455,0.002113,0.053681,92.779671,4.726422,0.536812,-408.290649,0.054583,0.000000
47.030003,20.666298,-408.335144,0.010477,0.002124,0.053950,91.928284,4.683050,0.539503,-408.335144,0.054965,0.000000
47.260002,21.250549,-408.379608,0.010481,0.002143,0.054427,94.527161,4.815444,0.544272,-408.379608,0.055347,0.000000
47.490002,21.702614,-408.335144,0.010499,0.002162,0.054913,96.538048,4.917882,0.549128,-408.335144,0.055737,0.000000
47.720001,21.857147,-408.246155,0.010499,0.002176,0.055259,97.225449,4.952900,0.552595,-408.246155,0.056118,0.000000
47.950001,21.971840,-408.335144,0.010533,0.002189,0.055607,97.735626,4.978890,0.556065,-408.335144,0.056500,0.000000
48.180004,21.895500,-408.379608,0.010537,0.002200,0.055893,97.396049,4.961591,0.558927,-408.379608,0.056881,0.000000
48.410004,22.387405,-408.379608,0.010533,0.002217,0.056300,99.584152,5.073059,0.563003,-408.379608,0.057272,0.000000
48.640003,22.500977,-408.379608,0.010559,0.002232,0.056691,100.089340,5.098794,0.566905,-408.379608,0.057653,0.000000
48.870003,22.757172,-408.379608,0.010568,0.002244,0.057003,101.228958,5.156849,0.570028,-408.379608,0.058035,0.000000
49.100002,23.299713,-408.290649,0.010589,0.002265,0.057523,103.642303,5.279790,0.575232,-408.290649,0.058416,0.000000
49.330002,23.869446,-408.335144,0.010615,0.002282,0.057957,106.176598,5.408894,0.579566,-408.335144,0.058798,0.000000
49.560001,23.792740,-408.424103,0.010602,0.002292,0.058226,105.835396,5.391512,0.582257,-408.424103,0.059188,0.000000
49.790001,24.185966,-408.379608,0.010628,0.002311,0.058694,107.584549,5.480618,0.586939,-408.379608,0.059570,0.000000
50.020004,24.194527,-408.335144,0.010632,0.002322,0.058989,107.622627,5.482558,0.589887,-408.335144,0.059951,0.000000
50.250004,24.280922,-408.379608,0.010667,0.002334,0.059275,108.006935,5.502136,0.592749,-408.379608,0.060333,0.000000
50.480003,24.670418,-408.379608,0.010662,0.002349,0.059674,109.739502,5.590396,0.596738,-408.379608,0.060715,0.000000
50.710003,24.895706,-408.379608,0.010680,0.002363,0.060021,110.741631,5.641448,0.600209,-408.379608,0.061105,0.000000
50.940002,25.373085,-408.335144,0.010684,0.002379,0.060437,112.865120,5.749623,0.604368,-408.335144,0.061486,0.000000
51.170002,25.967766,-408.424103,0.010697,0.002400,0.060957,115.510391,5.884380,0.609572,-408.424103,0.061868,0.000000
51.400002,26.681602,-408.424103,0.010723,0.002419,0.061434,118.685692,6.046137,0.614341,-408.424103,0.062249,0.000000
51.630001,26.829437,-408.468567,0.010723,0.002433,0.061807,119.343300,6.079638,0.618073,-408.468567,0.062631,0.000000
51.860001,26.870399,-408.424103,0.010740,0.002446,0.062128,119.525505,6.088919,0.621279,-408.424103,0.063021,0.000000
52.090004,26.746399,-408.424103,0.010766,0.002456,0.062371,118.973923,6.060821,0.623709,-408.424103,0.063403,0.000000
52.320004,27.298256,-408.424103,0.010757,0.002472,0.062796,121.428703,6.185873,0.627959,-408.424103,0.063785,0.000000
52.550003,27.569336,-408.424103,0.010783,0.002485,0.063125,122.634529,6.247301,0.631252,-408.424103,0.064166,0.000000
52.780003,27.589821,-408.468567,0.010792,0.002496,0.063394,122.725655,6.251943,0.633943,-408.468567,0.064548,0.000000
53.010002,27.959587,-408.468567,0.010783,0.002511,0.063767,124.370453,6.335733,0.637672,-408.468567,0.064938,0.000000
53.240002,29.291191,-408.468567,0.010809,0.002537,0.064444,130.293732,6.637479,0.644435,-408.468567,0.065319,0.000000
53.470001,29.459503,-408.424103,0.010831,0.002549,0.064756,131.042419,6.675619,0.647558,-408.424103,0.065701,0.000000
53.700001,29.665421,-408.513062,0.010852,0.002563,0.065111,131.958374,6.722281,0.651112,-408.513062,0.066083,0.000000
53.930004,29.856079,-408.557526,0.010856,0.002576,0.065441,132.806473,6.765484,0.654408,-408.557526,0.066464,0.000000
54.160004,30.254890,-408.468567,0.010856,0.002593,0.065857,134.580475,6.855856,0.658572,-408.468567,0.066854,0.000000
54.390003,31.010063,-408.424103,0.010882,0.002609,0.066274,137.939651,7.026981,0.662735,-408.424103,0.067236,0.000000
54.620003,30.998886,-408.468567,0.010895,0.002621,0.066568,137.889938,7.024448,0.665684,-408.468567,0.067618,0.000000
54.850002,31.565269,-408.513062,0.010917,0.002639,0.067019,140.409332,7.152792,0.670191,-408.513062,0.067999,0.000000
55.080002,32.453751,-408.557526,0.010917,0.002659,0.067548,144.361496,7.354125,0.675483,-408.557526,0.068381,0.000000
55.310001,33.048431,-408.557526,0.010925,0.002675,0.067947,147.006760,7.488882,0.679472,-408.557526,0.068771,0.000000
55.540001,33.253235,-408.513062,0.010943,0.002690,0.068329,147.917770,7.535291,0.683287,-408.513062,0.069153,0.000000
55.770004,33.364571,-408.468567,0.010943,0.002702,0.068632,148.413025,7.560520,0.686323,-408.468567,0.069534,0.000000
56.000004,33.732101,-408.557526,0.010973,0.002714,0.068927,150.047882,7.643804,0.689271,-408.557526,0.069916,0.000000
56.230003,34.393806,-408.602020,0.010977,0.002732,0.069387,152.991287,7.793748,0.693866,-408.602020,0.070297,0.000000
56.460003,34.975456,-408.557526,0.010990,0.002746,0.069751,155.578598,7.925552,0.697511,-408.557526,0.070687,0.000000
56.690002,35.277451,-408.468567,0.010999,0.002759,0.070089,156.921936,7.993985,0.700891,-408.468567,0.071069,0.000000
56.920002,35.942505,-408.513062,0.010999,0.002777,0.070540,159.880249,8.144688,0.705402,-408.513062,0.071451,0.000000
57.150002,36.948654,-408.513062,0.011025,0.002798,0.071069,164.355820,8.372684,0.710690,-408.513062,0.071832,0.000000
57.380001,37.070053,-408.646484,0.011033,0.002808,0.071329,164.895828,8.400194,0.713294,-408.646484,0.072223,0.000000
57.610004,37.453590,-408.602020,0.011029,0.002824,0.071720,166.601898,8.487104,0.717196,-408.602020,0.072604,0.000000
57.840004,37.411514,-408.557526,0.011055,0.002837,0.072049,166.414734,8.477571,0.720493,-408.557526,0.072986,0.000000
58.070004,37.942520,-408.557526,0.011068,0.002849,0.072353,168.776764,8.597898,0.723528,-408.557526,0.073367,0.000000
58.300003,38.997078,-408.557526,0.011068,0.002867,0.072821,173.467667,8.836864,0.728210,-408.557526,0.073749,0.000000
58.530003,39.089424,-408.602020,0.011094,0.002877,0.073064,173.878448,8.857790,0.730636,-408.602020,0.074139,0.000000
58.760002,39.712776,-408.602020,0.011085,0.002892,0.073463,176.651245,8.999043,0.734625,-408.602020,0.074521,0.000000
58.990002,40.723022,-408.513062,0.011119,0.002913,0.073983,181.145050,9.227968,0.739830,-408.513062,0.074902,0.000000
59.220001,41.109177,-408.557526,0.011128,0.002926,0.074330,182.862747,9.315473,0.743300,-408.557526,0.075284,0.000000
59.450005,41.614113,-408.646484,0.011119,0.002941,0.074703,185.108826,9.429893,0.747029,-408.646484,0.075665,0.000000
59.680004,42.103409,-408.646484,0.011132,0.002957,0.075110,187.285309,9.540769,0.751105,-408.646484,0.076056,0.000000
59.910004,43.051842,-408.602020,0.011145,0.002972,0.075492,191.504150,9.755687,0.754920,-408.602020,0.076437,0.000000
60.140003,44.022987,-408.602020,0.011158,0.002991,0.075978,195.824020,9.975752,0.759776,-408.602020,0.076819,0.000000
60.370003,44.380096,-408.646484,0.011175,0.003004,0.076299,197.412521,10.056674,0.762986,-408.646484,0.077201,0.000000
60.600002,44.626976,-408.646484,0.011171,0.003014,0.076567,198.510696,10.112617,0.765673,-408.646484,0.077582,0.000000
60.830002,45.400764,-408.735474,0.011180,0.003032,0.077001,201.952682,10.287960,0.770010,-408.735474,0.077972,0.000000
61.060001,45.981667,-408.646484,0.011206,0.003047,0.077383,204.536667,10.419595,0.773826,-408.646484,0.078354,0.000000
61.290005,46.749130,-408.646484,0.011197,0.003063,0.077808,207.950516,10.593504,0.778076,-408.646484,0.078735,0.000000
61.520004,47.426849,-408.602020,0.011223,0.003078,0.078189,210.965164,10.747077,0.781891,-408.602020,0.079117,0.000000
61.750004,48.205475,-408.690979,0.011223,0.003094,0.078588,214.428665,10.923516,0.785880,-408.690979,0.079499,0.000000
61.980003,48.869789,-408.690979,0.011236,0.003109,0.078961,217.383682,11.074053,0.789609,-408.690979,0.079889,0.000000
62.210003,49.963074,-408.602020,0.011232,0.003127,0.079429,222.246857,11.321795,0.794290,-408.602020,0.080270,0.000000
62.440002,50.196182,-408.646484,0.011266,0.003137,0.079672,223.283768,11.374618,0.796720,-408.646484,0.080652,0.000000
62.670002,50.416626,-408.646484,0.011262,0.003150,0.080002,224.264359,11.424571,0.800017,-408.646484,0.081033,0.000000
62.900002,51.437294,-408.690979,0.011257,0.003166,0.080409,228.804504,11.655857,0.804093,-408.690979,0.081415,0.000000
63.130005,52.852310,-408.690979,0.011270,0.003187,0.080947,235.098816,11.976505,0.809468,-408.690979,0.081806,0.000000
63.360004,53.238838,-408.690979,0.011275,0.003200,0.081285,236.818176,12.064094,0.812852,-408.690979,0.082187,0.000000
63.590004,53.928467,-408.690979,0.011296,0.003213,0.081606,239.885803,12.220365,0.816061,-408.690979,0.082569,0.000000
63.820004,54.707848,-408.646484,0.011322,0.003231,0.082057,243.352661,12.396976,0.820569,-408.646484,0.082950,0.000000
64.050003,55.434715,-408.735474,0.011326,0.003243,0.082369,246.585922,12.561686,0.823692,-408.735474,0.083332,0.000000
64.280006,56.135147,-408.690979,0.011326,0.003259,0.082768,249.701599,12.720407,0.827681,-408.690979,0.083722,0.000000
64.510002,56.508263,-408.690979,0.011331,0.003270,0.083054,251.361313,12.804955,0.830542,-408.690979,0.084103,0.000000
64.740005,57.950462,-408.735474,0.011348,0.003289,0.083531,257.776520,13.131763,0.835311,-408.735474,0.084485,0.000000
64.970001,58.882515,-408.690979,0.011348,0.003305,0.083956,261.922516,13.342969,0.839562,-408.690979,0.084867,0.000000
65.200005,59.728546,-408.735474,0.011361,0.003322,0.084372,265.685852,13.534682,0.843725,-408.735474,0.085248,0.000000
65.430000,60.497490,-408.779938,0.011357,0.003337,0.084754,269.106262,13.708927,0.847540,-408.779938,0.085639,0.000000
65.660004,61.038551,-408.735474,0.011378,0.003348,0.085031,271.513031,13.831533,0.850314,-408.735474,0.086020,0.000000
65.889999,62.094597,-408.690979,0.011391,0.003365,0.085465,276.210571,14.070837,0.854652,-408.690979,0.086402,0.000000
66.120003,62.908234,-408.779938,0.011408,0.003380,0.085855,279.829803,14.255209,0.858554,-408.779938,0.086783,0.000000
66.350006,63.483551,-408.779938,0.011408,0.003390,0.086107,282.388947,14.385578,0.861067,-408.779938,0.087174,0.000000
66.580002,63.757980,-408.735474,0.011404,0.003401,0.086385,283.609650,14.447765,0.863846,-408.735474,0.087555,0.000000
66.810005,65.831360,-408.735474,0.011430,0.003426,0.087017,292.832520,14.917599,0.870174,-408.735474,0.087937,0.000000
67.040001,66.380600,-408.779938,0.011434,0.003439,0.087347,295.275665,15.042059,0.873470,-408.779938,0.088318,0.000000
67.270004,67.451553,-408.779938,0.011438,0.003456,0.087780,300.039490,15.284740,0.877804,-408.779938,0.088700,0.000000
67.500000,66.739944,-408.735474,0.011434,0.003446,0.087538,296.874115,15.123487,0.875378,-408.735474,0.087780,0.000000
67.730003,66.119568,-408.779938,0.011438,0.003446,0.087529,294.114532,14.982908,0.875291,-408.779938,0.087538,0.000000
67.960007,65.480209,-408.824432,0.011447,0.003445,0.087512,291.270508,14.838028,0.875117,-408.824432,0.087538,0.000000
68.190002,64.899673,-408.779938,0.011456,0.003445,0.087503,288.688171,14.706476,0.875030,-408.779938,0.087538,0.000000
68.420006,64.360489,-408.824432,0.011456,0.003445,0.087494,286.289764,14.584295,0.874943,-408.824432,0.087538,0.000000
68.650002,63.885330,-408.824432,0.011469,0.003445,0.087494,284.176147,14.476623,0.874943,-408.824432,0.087538,0.000000
68.880005,63.424713,-408.824432,0.011464,0.003445,0.087494,282.127228,14.372246,0.874943,-408.824432,0.087538,0.000000
69.110001,63.017334,-408.779938,0.011469,0.003444,0.087486,280.315094,14.279932,0.874856,-408.779938,0.087538,0.000000
69.340004,62.627464,-408.779938,0.011486,0.003444,0.087486,278.580872,14.191586,0.874856,-408.779938,0.087538,0.000000
69.570000,62.241310,-408.868896,0.011469,0.003444,0.087486,276.863190,14.104083,0.874856,-408.868896,0.087538,0.000000
69.800003,61.918465,-408.913391,0.011473,0.003444,0.087486,275.427094,14.030925,0.874856,-408.913391,0.087538,0.000000
70.030006,61.593384,-408.824432,0.011469,0.003444,0.087486,273.981049,13.957260,0.874856,-408.824432,0.087538,0.000000
70.260002,61.281334,-408.868896,0.011490,0.003444,0.087486,272.592987,13.886549,0.874856,-408.868896,0.087538,0.000000
70.490005,61.015465,-408.913391,0.011495,0.003444,0.087486,271.410339,13.826303,0.874856,-408.913391,0.087538,0.000000
70.720001,60.742516,-408.913391,0.011482,0.003444,0.087486,270.196198,13.764451,0.874856,-408.913391,0.087538,0.000000
70.950005,60.484085,-408.868896,0.011486,0.003444,0.087486,269.046661,13.705890,0.874856,-408.868896,0.087538,0.000000
71.180000,60.246140,-408.824432,0.011486,0.003444,0.087486,267.988220,13.651971,0.874856,-408.824432,0.087538,0.000000
71.410004,60.021599,-408.868896,0.011495,0.003444,0.087486,266.989410,13.601089,0.874856,-408.868896,0.087538,0.000000
71.640007,59.788864,-408.913391,0.011516,0.003444,0.087486,265.954163,13.548350,0.874856,-408.913391,0.087538,0.000000
71.870003,59.598953,-408.957855,0.011486,0.003444,0.087486,265.109375,13.505316,0.874856,-408.957855,0.087538,0.000000
72.100006,59.405693,-408.957855,0.011503,0.003444,0.087486,264.249725,13.461523,0.874856,-408.957855,0.087538,0.000000
72.330002,59.203873,-408.868896,0.011482,0.003444,0.087486,263.351990,13.415790,0.874856,-408.868896,0.087538,0.000000
72.560005,59.025505,-408.868896,0.011507,0.003444,0.087477,262.558563,13.375370,0.874772,-408.868896,0.087538,0.000000
72.790001,58.852722,-408.868896,0.011512,0.003444,0.087477,261.789978,13.336218,0.874772,-408.868896,0.087538,0.000000
73.020004,58.672867,-409.002350,0.011486,0.003444,0.087477,260.989960,13.295462,0.874772,-409.002350,0.087538,0.000000
73.250000,58.521683,-408.913391,0.011499,0.003444,0.087477,260.317444,13.261203,0.874772,-408.913391,0.087538,0.000000
73.480003,58.363052,-408.913391,0.011499,0.003444,0.087477,259.611816,13.225257,0.874772,-408.913391,0.087538,0.000000
73.710007,58.221550,-408.913391,0.011516,0.003444,0.087477,258.982391,13.193192,0.874772,-408.913391,0.087538,0.000000
73.940002,58.091965,-408.913391,0.011516,0.003444,0.087477,258.405975,13.163827,0.874772,-408.913391,0.087538,0.000000
74.170006,57.933334,-409.002350,0.011495,0.003444,0.087477,257.700348,13.127881,0.874772,-409.002350,0.087538,0.000000
74.400002,57.797043,-408.913391,0.011512,0.003444,0.087477,257.094086,13.096997,0.874772,-408.913391,0.087538,0.000000
74.630005,57.687943,-408.957855,0.011512,0.003444,0.087477,256.608795,13.072275,0.874772,-408.957855,0.087538,0.000000
74.860001,57.561707,-408.913391,0.011512,0.003444,0.087477,256.047272,13.043669,0.874772,-408.913391,0.087538,0.000000
75.090004,57.419830,-408.957855,0.011525,0.003444,0.087477,255.416168,13.011519,0.874772,-408.957855,0.087538,0.000000
75.320007,57.320038,-409.046814,0.011516,0.003444,0.087477,254.972260,12.988906,0.874772,-409.046814,0.087538,0.000000
75.550003,57.211678,-408.957855,0.011520,0.003444,0.087477,254.490250,12.964352,0.874772,-408.957855,0.087538,0.000000
75.780006,57.104431,-408.957855,0.011516,0.003444,0.087477,254.013199,12.940049,0.874772,-408.957855,0.087538,0.000000
76.010002,56.993835,-408.957855,0.011503,0.003444,0.087477,253.521240,12.914988,0.874772,-408.957855,0.087538,0.000000
76.240005,56.889946,-409.046814,0.011525,0.003444,0.087477,253.059113,12.891445,0.874772,-409.046814,0.087538,0.000000
76.470001,56.803932,-409.046814,0.011512,0.003444,0.087477,252.676514,12.871955,0.874772,-409.046814,0.087538,0.000000
76.700005,56.701157,-408.957855,0.011525,0.003444,0.087477,252.219345,12.848665,0.874772,-408.957855,0.087538,0.000000
76.930000,56.600243,-409.002350,0.011516,0.003444,0.087477,251.770447,12.825799,0.874772,-409.002350,0.087538,0.000000
77.160004,56.507149,-409.002350,0.011507,0.003444,0.087477,251.356354,12.804703,0.874772,-409.002350,0.087538,0.000000
77.390007,56.425224,-409.091309,0.011520,0.003444,0.087477,250.991928,12.786139,0.874772,-409.091309,0.087538,0.000000
77.620003,56.331764,-409.046814,0.011516,0.003444,0.087477,250.576202,12.764960,0.874772,-409.046814,0.087538,0.000000
77.850006,56.249466,-409.091309,0.011503,0.003444,0.087477,250.210114,12.746311,0.874772,-409.091309,0.087538,0.000000
78.080002,56.172760,-409.002350,0.011512,0.003444,0.087477,249.868912,12.728930,0.874772,-409.002350,0.087538,0.000000
78.310005,56.079292,-409.002350,0.011533,0.003444,0.087477,249.453156,12.707749,0.874772,-409.002350,0.087538,0.000000
78.540001,56.014496,-409.002350,0.011516,0.003444,0.087477,249.164917,12.693066,0.874772,-409.002350,0.087538,0.000000
78.770004,55.948593,-409.046814,0.011507,0.003444,0.087477,248.871765,12.678133,0.874772,-409.046814,0.087538,0.000000
79.000000,55.860710,-409.046814,0.011512,0.003444,0.087477,248.480850,12.658217,0.874772,-409.046814,0.087538,0.000000
79.230003,55.776924,-409.002350,0.011516,0.003444,0.087477,248.108154,12.639232,0.874772,-409.002350,0.087538,0.000000
79.460007,55.716972,-409.046814,0.011533,0.003444,0.087477,247.841476,12.625646,0.874772,-409.046814,0.087538,0.000000
79.690002,55.641754,-409.046814,0.011529,0.003444,0.087477,247.506882,12.608602,0.874772,-409.046814,0.087538,0.000000
79.920006,55.575844,-409.135773,0.011520,0.003444,0.087477,247.213699,12.593666,0.874772,-409.135773,0.087538,0.000000
80.150002,55.511421,-409.046814,0.011516,0.003444,0.087477,246.927139,12.579067,0.874772,-409.046814,0.087538,0.000000
80.380005,55.445885,-409.046814,0.011533,0.003444,0.087477,246.635620,12.564217,0.874772,-409.046814,0.087538,0.000000
80.610001,55.364708,-409.091309,0.011525,0.003444,0.087477,246.274521,12.545822,0.874772,-409.091309,0.087538,0.000000
80.840004,55.314812,-409.046814,0.011533,0.003444,0.087477,246.052567,12.534515,0.874772,-409.046814,0.087538,0.000000
81.070007,55.242203,-409.091309,0.011533,0.003444,0.087477,245.729584,12.518063,0.874772,-409.091309,0.087538,0.000000
81.300003,55.188576,-409.091309,0.011507,0.003444,0.087477,245.491043,12.505910,0.874772,-409.091309,0.087538,0.000000
81.530006,55.116707,-409.091309,0.011525,0.003444,0.087477,245.171356,12.489624,0.874772,-409.091309,0.087538,0.000000
81.760002,55.053780,-409.091309,0.011525,0.003444,0.087477,244.891449,12.475365,0.874772,-409.091309,0.087538,0.000000
81.990005,55.006111,-409.180267,0.011516,0.003444,0.087477,244.679398,12.464563,0.874772,-409.180267,0.087538,0.000000
82.220001,54.946907,-409.135773,0.011529,0.003444,0.087477,244.416046,12.451147,0.874772,-409.135773,0.087538,0.000000
82.450005,54.915253,-409.091309,0.011516,0.003444,0.087477,244.275238,12.443974,0.874772,-409.091309,0.087538,0.000000
82.680000,54.843391,-409.091309,0.011533,0.003444,0.087477,243.955582,12.427691,0.874772,-409.091309,0.087538,0.000000
82.910004,54.784180,-409.135773,0.011538,0.003444,0.087477,243.692200,12.414272,0.874772,-409.135773,0.087538,0.000000
83.140007,54.727951,-409.224762,0.011529,0.003444,0.087477,243.442078,12.401531,0.874772,-409.224762,0.087538,0.000000
83.370003,54.684013,-409.135773,0.011512,0.003444,0.087477,243.246643,12.391575,0.874772,-409.135773,0.087538,0.000000
83.600006,54.649384,-409.135773,0.011538,0.003444,0.087477,243.092606,12.383727,0.874772,-409.135773,0.087538,0.000000
83.830002,54.586449,-409.135773,0.011529,0.003444,0.087477,242.812653,12.369466,0.874772,-409.135773,0.087538,0.000000
84.060005,54.527245,-409.180267,0.011546,0.003444,0.087477,242.549301,12.356050,0.874772,-409.180267,0.087538,0.000000
84.290001,54.485168,-409.224762,0.011525,0.003444,0.087477,242.362137,12.346516,0.874772,-409.224762,0.087538,0.000000
84.520004,54.447929,-409.135773,0.011520,0.003444,0.087477,242.196487,12.338078,0.874772,-409.135773,0.087538,0.000000
84.750008,54.401382,-409.224762,0.011533,0.003444,0.087477,241.989441,12.327529,0.874772,-409.224762,0.087538,0.000000
84.980003,54.344780,-409.135773,0.011538,0.003444,0.087477,241.737656,12.314703,0.874772,-409.135773,0.087538,0.000000
85.210007,54.310150,-409.224762,0.011525,0.003444,0.087477,241.583618,12.306856,0.874772,-409.224762,0.087538,0.000000
85.440002,54.266586,-409.224762,0.011529,0.003444,0.087477,241.389832,12.296984,0.874772,-409.224762,0.087538,0.000000
85.670006,54.216316,-409.269226,0.011525,0.003444,0.087477,241.166214,12.285593,0.874772,-409.269226,0.087538,0.000000
85.900002,54.172745,-409.180267,0.011529,0.003444,0.087477,240.972397,12.275720,0.874772,-409.180267,0.087538,0.000000
86.130005,54.141464,-409.224762,0.011533,0.003444,0.087477,240.833267,12.268631,0.874772,-409.224762,0.087538,0.000000
86.360001,54.088219,-409.180267,0.011546,0.003444,0.087477,240.596420,12.256566,0.874772,-409.180267,0.087538,0.000000
86.590004,54.046509,-409.269226,0.011529,0.003444,0.087477,240.410873,12.247114,0.874772,-409.269226,0.087538,0.000000
86.820007,54.012253,-409.269226,0.011533,0.003444,0.087477,240.258499,12.239351,0.874772,-409.269226,0.087538,0.000000
87.050003,53.970177,-409.224762,0.011525,0.003444,0.087477,240.071335,12.229817,0.874772,-409.224762,0.087538,0.000000
87.280006,53.922882,-409.180267,0.011542,0.003444,0.087477,239.860962,12.219099,0.874772,-409.180267,0.087538,0.000000
87.510002,53.885643,-409.224762,0.011538,0.003444,0.087477,239.695312,12.210661,0.874772,-409.224762,0.087538,0.000000
87.740005,53.835747,-409.313721,0.011533,0.003444,0.087477,239.473358,12.199355,0.874772,-409.313721,0.087538,0.000000
87.970001,53.819733,-409.269226,0.011546,0.003444,0.087477,239.402130,12.195726,0.874772,-409.269226,0.087538,0.000000
88.200005,53.758293,-409.224762,0.011533,0.003444,0.087477,239.128830,12.181804,0.874772,-409.224762,0.087538,0.000000
88.430008,53.727760,-409.224762,0.011542,0.003444,0.087477,238.993011,12.174885,0.874772,-409.224762,0.087538,0.000000
88.660004,53.688286,-409.224762,0.011559,0.003444,0.087477,238.817429,12.165939,0.874772,-409.224762,0.087538,0.000000
88.890007,53.650681,-409.269226,0.011525,0.003444,0.087477,238.650146,12.157418,0.874772,-409.269226,0.087538,0.000000
89.120003,53.616425,-409.358185,0.011525,0.003444,0.087477,238.497772,12.149655,0.874772,-409.358185,0.087538,0.000000
89.350006,53.605621,-409.313721,0.011533,0.003444,0.087477,238.449707,12.147207,0.874772,-409.313721,0.087538,0.000000
89.580002,53.549767,-409.269226,0.011538,0.003444,0.087477,238.201263,12.134550,0.874772,-409.269226,0.087538,0.000000
89.810005,53.507317,-409.269226,0.011538,0.003444,0.087477,238.012436,12.124931,0.874772,-409.269226,0.087538,0.000000
90.040001,53.487206,-409.313721,0.011542,0.003444,0.087477,237.922974,12.120375,0.874772,-409.313721,0.087538,0.000000
90.270004,53.463005,-409.269226,0.011529,0.003444,0.087477,237.815323,12.114890,0.874772,-409.269226,0.087538,0.000000
90.500008,53.418694,-409.269226,0.011542,0.003444,0.087477,237.618210,12.104849,0.874772,-409.269226,0.087538,0.000000
90.730003,53.382568,-409.269226,0.011529,0.003444,0.087477,237.457520,12.096663,0.874772,-409.269226,0.087538,0.000000
90.960007,53.350922,-409.313721,0.011538,0.003444,0.087477,237.316757,12.089491,0.874772,-409.313721,0.087538,0.000000
91.190002,53.326714,-409.313721,0.011520,0.003444,0.087477,237.209076,12.084006,0.874772,-409.313721,0.087538,0.000000
91.420006,53.304375,-409.358185,0.011538,0.003444,0.087477,237.109695,12.078944,0.874772,-409.358185,0.087538,0.000000
91.650002,53.252983,-409.269226,0.011546,0.003444,0.087477,236.881104,12.067298,0.874772,-409.269226,0.087538,0.000000
91.880005,53.226547,-409.313721,0.011533,0.003444,0.087477,236.763504,12.061308,0.874772,-409.313721,0.087538,0.000000
92.110001,53.217239,-409.358185,0.011555,0.003444,0.087477,236.722107,12.059198,0.874772,-409.358185,0.087538,0.000000
92.340004,53.164734,-409.358185,0.011525,0.003444,0.087477,236.488541,12.047301,0.874772,-409.358185,0.087538,0.000000
92.570007,53.124519,-409.313721,0.011555,0.003444,0.087477,236.309662,12.038188,0.874772,-409.313721,0.087538,0.000000
92.800003,53.112228,-409.313721,0.011546,0.003444,0.087477,236.254990,12.035403,0.874772,-409.313721,0.087538,0.000000
93.030006,53.084297,-409.358185,0.011551,0.003444,0.087477,236.130753,12.029074,0.874772,-409.358185,0.087538,0.000000
93.260002,53.048180,-409.358185,0.011546,0.003444,0.087477,235.970093,12.020889,0.874772,-409.358185,0.087538,0.000000
93.490005,53.021370,-409.402679,0.011546,0.003444,0.087477,235.850830,12.014814,0.874772,-409.402679,0.087538,0.000000
93.720001,52.990837,-409.402679,0.011538,0.003444,0.087477,235.715012,12.007895,0.874772,-409.402679,0.087538,0.000000
93.950005,52.961418,-409.402679,0.011542,0.003444,0.087477,235.584152,12.001229,0.874772,-409.402679,0.087538,0.000000
94.180008,52.947266,-409.358185,0.011538,0.003444,0.087477,235.521194,11.998022,0.874772,-409.358185,0.087538,0.000000
94.410004,52.913383,-409.402679,0.011546,0.003444,0.087477,235.370483,11.990344,0.874772,-409.402679,0.087538,0.000000
94.640007,52.882103,-409.447144,0.011538,0.003444,0.087477,235.231339,11.983255,0.874772,-409.447144,0.087538,0.000000
94.870003,52.858643,-409.402679,0.011546,0.003444,0.087477,235.126984,11.977940,0.874772,-409.402679,0.087538,0.000000
95.100006,52.816566,-409.402679,0.011546,0.003444,0.087477,234.939819,11.968405,0.874772,-409.402679,0.087538,0.000000
95.330002,52.798691,-409.447144,0.011546,0.003444,0.087477,234.860306,11.964355,0.874772,-409.447144,0.087538,0.000000
95.560005,52.777466,-409.402679,0.011542,0.003444,0.087477,234.765900,11.959545,0.874772,-409.402679,0.087538,0.000000
95.790001,52.755867,-409.447144,0.011546,0.003444,0.087477,234.669815,11.954651,0.874772,-409.447144,0.087538,0.000000
96.020004,52.747673,-409.447144,0.011533,0.003444,0.087477,234.633362,11.952793,0.874772,-409.447144,0.087538,0.000000
96.250008,52.712669,-409.358185,0.011546,0.003444,0.087477,234.477661,11.944861,0.874772,-409.358185,0.087538,0.000000
96.480003,52.678040,-409.447144,0.011551,0.003444,0.087477,234.323624,11.937014,0.874772,-409.447144,0.087538,0.000000
96.710007,52.646019,-409.447144,0.011551,0.003444,0.087477,234.181183,11.929758,0.874772,-409.447144,0.087538,0.000000
96.940002,52.638573,-409.447144,0.011542,0.003444,0.087477,234.148071,11.928071,0.874772,-409.447144,0.087538,0.000000
97.170006,52.602448,-409.447144,0.011546,0.003444,0.087477,233.987366,11.919885,0.874772,-409.447144,0.087538,0.000000
97.400002,52.579735,-409.447144,0.011533,0.003444,0.087477,233.886337,11.914739,0.874772,-409.447144,0.087538,0.000000
97.630005,52.558136,-409.402679,0.011546,0.003444,0.087477,233.790268,11.909844,0.874772,-409.402679,0.087538,0.000000
97.800003,52.543617,-409.402679,0.011546,0.003444,0.087477,233.725677,11.906554,0.874772,-409.402679,0.087538,0.000000