File: Data/compression 30/AutoNoHeating-17-30-reverse-1-3_10242024_162919.csv
Time (sec),S:Load (lbs),S:HL1 (DIM),S:LVDT (in),S:Position (in),Ch:Position (mm),Ch:Load (N),Ch:Stress (MPa),Ch:Strain (mm/mm),Ch:HL1 (DIM),Set Point (),Cycles ()
0.010000,-0.039467,-181.927094,-0.009136,-0.004607,-0.117024,-0.175557,-0.008943,-1.170244,-181.927094,-0.116834,0.000000
0.360000,-0.037231,-181.971573,-0.009149,-0.004604,-0.116937,-0.165614,-0.008437,-1.169366,-181.971573,-0.116417,0.000000
0.710000,-0.093460,-181.971573,-0.009132,-0.004404,-0.111856,-0.415731,-0.021178,-1.118558,-181.971573,-0.110589,0.000000
1.060000,-0.022713,-182.016052,-0.008877,-0.004169,-0.105897,-0.101031,-0.005147,-1.058968,-182.016052,-0.104745,0.000000
1.410000,-0.040955,-182.016052,-0.008627,-0.003937,-0.100000,-0.182175,-0.009280,-1.000000,-182.016052,-0.098916,0.000000
1.760000,0.006706,-182.060532,-0.008416,-0.003710,-0.094242,0.029831,0.001520,-0.942424,-182.060532,-0.093089,0.000000
2.110000,-0.005211,-182.149490,-0.008179,-0.003489,-0.088632,-0.023179,-0.001181,-0.886316,-182.149490,-0.087260,0.000000
2.460000,-0.030533,-182.149490,-0.007942,-0.003255,-0.082682,-0.135817,-0.006919,-0.826818,-182.149490,-0.081433,0.000000
2.810000,-0.103516,-182.193970,-0.007718,-0.003028,-0.076923,-0.460460,-0.023457,-0.769227,-182.193970,-0.075587,0.000000
3.160000,-0.026810,-182.193970,-0.007468,-0.002791,-0.070888,-0.119255,-0.006075,-0.708881,-182.193970,-0.069760,0.000000
3.510000,0.022346,-182.193970,-0.007226,-0.002556,-0.064922,0.099402,0.005064,-0.649215,-182.193970,-0.063933,0.000000
3.860000,0.010429,-182.282944,-0.007002,-0.002340,-0.059440,0.046392,0.002363,-0.594395,-182.282944,-0.058104,0.000000
4.210000,-0.018242,-182.327423,-0.006773,-0.002111,-0.053612,-0.081144,-0.004134,-0.536123,-182.327423,-0.052277,0.000000
4.560000,-0.052505,-182.371902,-0.006523,-0.001881,-0.047767,-0.233556,-0.011898,-0.477669,-182.371902,-0.046450,0.000000
4.910000,-0.092346,-182.416382,-0.006295,-0.001649,-0.041896,-0.410776,-0.020926,-0.418958,-182.416382,-0.040604,0.000000
5.260000,0.017876,-182.416382,-0.006062,-0.001410,-0.035808,0.079515,0.004051,-0.358081,-182.416382,-0.034776,0.000000
5.610000,0.040962,-182.505341,-0.005833,-0.001192,-0.030275,0.182209,0.009282,-0.302746,-182.505341,-0.028948,0.000000
5.960001,0.034630,-182.549820,-0.005592,-0.000958,-0.024326,0.154041,0.007847,-0.243263,-182.549820,-0.023121,0.000000
6.310000,-0.020477,-182.549820,-0.005376,-0.000734,-0.018637,-0.091088,-0.004640,-0.186368,-182.549820,-0.017292,0.000000
6.660000,-0.049149,-182.549820,-0.005126,-0.000502,-0.012757,-0.218624,-0.011137,-0.127566,-182.549820,-0.011449,0.000000
7.010000,-0.016006,-182.683273,-0.004889,-0.000263,-0.006687,-0.071200,-0.003627,-0.066872,-182.683273,-0.005620,0.000000
7.360000,0.030167,-182.638779,-0.004661,-0.000043,-0.001084,0.134188,0.006836,-0.010840,-182.638779,0.000207,0.000000
7.710001,0.132195,-182.683273,-0.004557,-0.000002,-0.000051,0.588031,0.029956,-0.000515,-182.683273,0.000130,0.000000
8.060000,0.055855,-182.727753,-0.004566,-0.000002,-0.000051,0.248455,0.012657,-0.000515,-182.727753,0.000182,0.000000
8.410001,0.113205,-182.772232,-0.004570,-0.000002,-0.000051,0.503561,0.025653,-0.000515,-182.772232,0.000763,0.000000
8.760000,0.218216,-182.816711,-0.004562,0.000018,0.000468,0.970673,0.049448,0.004678,-182.816711,0.001353,0.000000
9.110001,0.346306,-182.816711,-0.004566,0.000032,0.000815,1.540445,0.078474,0.008145,-182.816711,0.001933,0.000000
9.460000,0.668785,-182.816711,-0.004540,0.000063,0.001605,2.974905,0.151549,0.016048,-182.816711,0.002515,0.000000
9.810000,0.903008,-182.905670,-0.004510,0.000082,0.002091,4.016778,0.204624,0.020908,-182.905670,0.003105,0.000000
10.160001,1.283195,-182.950150,-0.004493,0.000107,0.002705,5.707939,0.290776,0.027054,-182.950150,0.003686,0.000000
10.510000,1.759834,-182.950150,-0.004467,0.000134,0.003391,7.828134,0.398784,0.033913,-182.950150,0.004266,0.000000
10.860001,2.057358,-182.950150,-0.004445,0.000150,0.003799,9.151585,0.466204,0.037985,-182.950150,0.004848,0.000000
11.210001,2.497505,-183.039108,-0.004437,0.000172,0.004362,11.109458,0.565943,0.043617,-183.039108,0.005438,0.000000
11.560000,3.234802,-183.128082,-0.004419,0.000204,0.005178,14.389119,0.733017,0.051777,-183.128082,0.006018,0.000000
11.910001,3.609779,-183.128082,-0.004393,0.000223,0.005671,16.057100,0.817988,0.056713,-183.128082,0.006599,0.000000
12.260000,4.167969,-183.128082,-0.004368,0.000248,0.006297,18.540051,0.944475,0.062966,-183.128082,0.007181,0.000000
12.610001,4.782379,-183.172562,-0.004359,0.000272,0.006904,21.273085,1.083703,0.069036,-183.172562,0.007771,0.000000
12.960001,5.137627,-183.172562,-0.004346,0.000290,0.007362,22.853304,1.164203,0.073624,-183.172562,0.008351,0.000000
13.310000,5.975090,-183.261520,-0.004316,0.000320,0.008118,26.578527,1.353975,0.081178,-183.261520,0.008932,0.000000
13.660001,6.293839,-183.306000,-0.004307,0.000338,0.008577,27.996391,1.426204,0.085766,-183.306000,0.009514,0.000000
14.010000,6.888519,-183.306000,-0.004281,0.000360,0.009149,30.641665,1.560961,0.091488,-183.306000,0.010103,0.000000
14.360001,7.650764,-183.350479,-0.004260,0.000387,0.009826,34.032299,1.733688,0.098256,-183.350479,0.010684,0.000000
14.710001,7.855942,-183.394958,-0.004251,0.000405,0.010286,34.944973,1.780182,0.102858,-183.394958,0.011265,0.000000
15.060000,8.445038,-183.483917,-0.004234,0.000423,0.010745,37.565403,1.913673,0.107446,-183.483917,0.011854,0.000000
15.410001,9.183083,-183.439438,-0.004186,0.000451,0.011456,40.848392,2.080916,0.114561,-183.439438,0.012436,0.000000
15.760001,9.515984,-183.483917,-0.004199,0.000471,0.011951,42.329208,2.156353,0.119512,-183.483917,0.013017,0.000000
16.110001,9.885376,-183.528397,-0.004161,0.000487,0.012366,43.972347,2.240058,0.123660,-183.528397,0.013598,0.000000
16.460001,10.882957,-183.617371,-0.004139,0.000522,0.013252,48.409813,2.466113,0.132517,-183.617371,0.014187,0.000000
16.810001,10.952965,-183.617371,-0.004130,0.000536,0.013624,48.721222,2.481977,0.136241,-183.617371,0.014769,0.000000
17.160002,11.492905,-183.661850,-0.004109,0.000558,0.014171,51.122993,2.604329,0.141706,-183.661850,0.015350,0.000000
17.510000,12.212334,-183.661850,-0.004096,0.000585,0.014864,54.323174,2.767354,0.148640,-183.661850,0.015931,0.000000
17.860001,12.750778,-183.706329,-0.004074,0.000612,0.015550,56.718292,2.889368,0.155499,-183.706329,0.016520,0.000000
18.210001,12.962288,-183.750809,-0.004070,0.000629,0.015974,57.659138,2.937296,0.159738,-183.750809,0.017102,0.000000
18.560001,13.389397,-183.750809,-0.004049,0.000647,0.016443,59.559010,3.034081,0.164431,-183.750809,0.017683,0.000000
18.910002,14.127441,-183.839767,-0.004023,0.000675,0.017136,62.841999,3.201324,0.171365,-183.839767,0.018272,0.000000
19.260000,14.878891,-183.839767,-0.003992,0.000705,0.017909,66.184616,3.371605,0.179086,-183.839767,0.018853,0.000000
19.610001,14.930649,-183.928726,-0.003980,0.000723,0.018367,66.414841,3.383333,0.183673,-183.928726,0.019435,0.000000
19.960001,15.209557,-183.973221,-0.003967,0.000743,0.018871,67.655487,3.446535,0.188715,-183.973221,0.020016,0.000000
20.310001,15.500008,-183.973221,-0.003958,0.000765,0.019435,68.947479,3.512352,0.194347,-183.973221,0.020605,0.000000
20.660002,16.272308,-183.973221,-0.003923,0.000790,0.020058,72.382843,3.687358,0.200584,-183.973221,0.021186,0.000000
21.010000,16.843895,-184.017700,-0.003902,0.000819,0.020796,74.925385,3.816881,0.207957,-184.017700,0.021768,0.000000
21.360001,17.322769,-184.062180,-0.003867,0.000844,0.021447,77.055527,3.925396,0.214467,-184.062180,0.022349,0.000000
21.710001,17.148125,-184.106659,-0.003867,0.000859,0.021819,76.278671,3.885821,0.218192,-184.106659,0.022938,0.000000
22.060001,17.761055,-184.195618,-0.003850,0.000885,0.022470,79.005119,4.024713,0.224702,-184.195618,0.023519,0.000000
22.410002,18.124115,-184.195618,-0.003824,0.000906,0.023017,80.620087,4.106983,0.230167,-184.195618,0.024101,0.000000
22.760000,18.427971,-184.195618,-0.003790,0.000929,0.023597,81.971710,4.175838,0.235965,-184.195618,0.024682,0.000000
23.110001,19.086700,-184.240097,-0.003777,0.000960,0.024394,84.901886,4.325108,0.243944,-184.240097,0.025271,0.000000
23.460001,19.112389,-184.284576,-0.003760,0.000982,0.024933,85.016151,4.330929,0.249334,-184.284576,0.025852,0.000000
23.810001,18.983925,-184.373535,-0.003734,0.001000,0.025410,84.444717,4.301819,0.254103,-184.373535,0.026434,0.000000
24.160002,18.803322,-184.284576,-0.003712,0.001009,0.025627,83.641350,4.260894,0.256268,-184.284576,0.027023,0.000000
24.510000,19.703346,-184.373535,-0.003691,0.001039,0.026390,87.644859,4.464842,0.263898,-184.373535,0.027604,0.000000
24.860001,20.194130,-184.418030,-0.003678,0.001068,0.027136,89.827980,4.576055,0.271362,-184.418030,0.028185,0.000000
25.210001,20.788437,-184.418030,-0.003652,0.001098,0.027881,92.471588,4.710727,0.278811,-184.418030,0.028765,0.000000
25.560001,20.203812,-184.551468,-0.003639,0.001109,0.028176,89.871040,4.578249,0.281763,-184.551468,0.029356,0.000000
25.910002,20.414948,-184.551468,-0.003630,0.001136,0.028862,90.810219,4.626093,0.288621,-184.551468,0.029937,0.000000
26.260002,20.934410,-184.551468,-0.003579,0.001157,0.029381,93.120911,4.743805,0.293814,-184.551468,0.030518,0.000000
26.610001,21.150017,-184.595947,-0.003574,0.001178,0.029928,94.079971,4.792662,0.299279,-184.595947,0.031098,0.000000
26.960001,22.301018,-184.684906,-0.003531,0.001217,0.030907,99.199883,5.053483,0.309075,-184.684906,0.031689,0.000000
27.310001,21.759956,-184.684906,-0.003510,0.001234,0.031333,96.793121,4.930877,0.313329,-184.684906,0.032270,0.000000
27.660002,21.586433,-184.729385,-0.003497,0.001256,0.031905,96.021248,4.891556,0.319052,-184.729385,0.032850,0.000000
28.010002,22.211273,-184.773865,-0.003475,0.001283,0.032591,98.800674,5.033146,0.325910,-184.773865,0.033440,0.000000
28.360001,21.746925,-184.818344,-0.003454,0.001296,0.032920,96.735153,4.927924,0.329195,-184.818344,0.034022,0.000000
28.710001,21.972954,-184.862839,-0.003428,0.001319,0.033492,97.740578,4.979143,0.334918,-184.862839,0.034603,0.000000
29.060001,22.760895,-184.907318,-0.003402,0.001350,0.034299,101.245514,5.157692,0.342987,-184.907318,0.035183,0.000000
29.410002,22.594444,-184.862839,-0.003397,0.001370,0.034794,100.505104,5.119974,0.347938,-184.862839,0.035773,0.000000
29.760002,22.617905,-184.907318,-0.003363,0.001390,0.035313,100.609467,5.125290,0.353131,-184.907318,0.036355,0.000000
30.110001,23.080391,-184.996277,-0.003341,0.001419,0.036041,102.666710,5.230092,0.360413,-184.996277,0.036935,0.000000
30.460001,22.661476,-184.996277,-0.003320,0.001434,0.036423,100.803284,5.135164,0.364228,-184.996277,0.037516,0.000000
30.810001,23.185402,-184.996277,-0.003285,0.001462,0.037125,103.133820,5.253887,0.371253,-184.996277,0.038106,0.000000
31.160002,23.106461,-185.129715,-0.003268,0.001482,0.037646,102.782669,5.235999,0.376461,-185.129715,0.038688,0.000000
31.510002,23.325043,-185.129715,-0.003251,0.001506,0.038244,103.754974,5.285530,0.382441,-185.129715,0.039268,0.000000
31.860001,23.638580,-185.129715,-0.003221,0.001531,0.038895,105.149658,5.356579,0.388951,-185.129715,0.039849,0.000000
32.210003,23.190239,-185.218674,-0.003199,0.001550,0.039363,103.155334,5.254983,0.393629,-185.218674,0.040439,0.000000
32.560001,23.622566,-185.307648,-0.003182,0.001574,0.039988,105.078423,5.352950,0.399882,-185.307648,0.041019,0.000000
32.910000,24.291351,-185.307648,-0.003143,0.001604,0.040751,108.053329,5.504499,0.407512,-185.307648,0.041601,0.000000
33.260002,23.963661,-185.307648,-0.003126,0.001625,0.041263,106.595688,5.430243,0.412629,-185.307648,0.042191,0.000000
33.610001,24.128990,-185.263168,-0.003096,0.001647,0.041826,107.331108,5.467707,0.418261,-185.263168,0.042772,0.000000
33.960003,24.442528,-185.352127,-0.003087,0.001671,0.042433,108.725792,5.538756,0.424332,-185.352127,0.043352,0.000000
34.310001,24.174423,-185.396606,-0.003065,0.001690,0.042928,107.533203,5.478003,0.429283,-185.396606,0.043934,0.000000
34.660000,25.191002,-185.441086,-0.003048,0.001723,0.043752,112.055176,5.708363,0.437519,-185.441086,0.044524,0.000000
35.010002,24.944489,-185.441086,-0.003022,0.001742,0.044238,110.958626,5.652502,0.442379,-185.441086,0.045104,0.000000
35.360001,24.720695,-185.485565,-0.002997,0.001759,0.044680,109.963142,5.601790,0.446799,-185.485565,0.045685,0.000000
35.710003,25.322075,-185.574524,-0.002971,0.001786,0.045364,112.638214,5.738064,0.453642,-185.574524,0.046267,0.000000
36.060001,25.037209,-185.619003,-0.002945,0.001802,0.045781,111.371063,5.673512,0.457806,-185.619003,0.046857,0.000000
36.410000,25.148178,-185.574524,-0.002932,0.001823,0.046310,111.864685,5.698659,0.463105,-185.574524,0.047437,0.000000
36.760002,25.870209,-185.663483,-0.002902,0.001851,0.047004,115.076439,5.862273,0.470039,-185.663483,0.048018,0.000000
37.110001,25.676201,-185.663483,-0.002884,0.001868,0.047437,114.213448,5.818310,0.474368,-185.663483,0.048609,0.000000
37.460003,25.996445,-185.707977,-0.002863,0.001893,0.048079,115.637962,5.890879,0.480788,-185.707977,0.049188,0.000000
37.810001,26.625008,-185.663483,-0.002833,0.001919,0.048746,118.433952,6.033313,0.487464,-185.663483,0.049770,0.000000
38.160004,26.133476,-185.796936,-0.002811,0.001935,0.049154,116.247505,5.921930,0.491537,-185.796936,0.050351,0.000000
38.510002,26.304390,-185.885895,-0.002811,0.001957,0.049709,117.007767,5.960660,0.497093,-185.885895,0.050942,0.000000
38.860001,26.868538,-185.841415,-0.002781,0.001986,0.050438,119.517227,6.088498,0.504375,-185.841415,0.051522,0.000000
39.210003,27.268837,-185.930374,-0.002751,0.002011,0.051070,121.297844,6.179207,0.510703,-185.930374,0.052103,0.000000
39.560001,27.011902,-185.930374,-0.002746,0.002029,0.051547,120.154938,6.120984,0.515472,-185.930374,0.052684,0.000000
39.910004,27.643448,-186.019333,-0.002712,0.002054,0.052182,122.964195,6.264095,0.521816,-186.019333,0.053273,0.000000
40.260002,27.707123,-186.019333,-0.002703,0.002074,0.052675,123.247437,6.278524,0.526751,-186.019333,0.053855,0.000000
40.610001,28.480911,-186.063812,-0.002686,0.002105,0.053473,126.689423,6.453866,0.534730,-186.063812,0.054436,0.000000
40.960003,28.352440,-186.108292,-0.002656,0.002126,0.053994,126.117950,6.424755,0.539938,-186.108292,0.055017,0.000000
41.310001,28.163277,-186.108292,-0.002634,0.002145,0.054487,125.276512,6.381890,0.544873,-186.108292,0.055606,0.000000
41.660004,28.067947,-186.108292,-0.002608,0.002163,0.054948,124.852463,6.360288,0.549476,-186.108292,0.056188,0.000000
42.010002,28.926270,-186.197266,-0.002600,0.002194,0.055736,128.670471,6.554786,0.557364,-186.197266,0.056769,0.000000
42.360001,29.377213,-186.241745,-0.002578,0.002221,0.056404,130.676361,6.656971,0.564040,-186.241745,0.057358,0.000000
42.710003,29.611435,-186.241745,-0.002544,0.002244,0.057004,131.718246,6.710047,0.570035,-186.241745,0.057939,0.000000
43.060001,28.859612,-186.286224,-0.002535,0.002260,0.057393,128.373962,6.539681,0.573926,-186.286224,0.058521,0.000000
43.410004,29.360825,-186.241745,-0.002496,0.002284,0.058009,130.603470,6.653258,0.580088,-186.241745,0.059102,0.000000
43.760002,29.675850,-186.286224,-0.002488,0.002308,0.058616,132.004776,6.724644,0.586159,-186.286224,0.059691,0.000000
44.110001,29.711975,-186.375183,-0.002462,0.002328,0.059128,132.165466,6.732830,0.591276,-186.375183,0.060272,0.000000
44.460003,30.823135,-186.419662,-0.002445,0.002362,0.059995,137.108154,6.984622,0.599951,-186.419662,0.060854,0.000000
44.810001,30.627640,-186.419662,-0.002423,0.002382,0.060498,136.238541,6.940322,0.604978,-186.419662,0.061435,0.000000
45.160004,30.522629,-186.508621,-0.002406,0.002401,0.060984,135.771439,6.916526,0.609837,-186.508621,0.062024,0.000000
45.510002,30.571037,-186.464142,-0.002389,0.002421,0.061503,135.986771,6.927496,0.615030,-186.464142,0.062605,0.000000
45.860001,30.868935,-186.553116,-0.002367,0.002443,0.062059,137.311874,6.995001,0.620587,-186.553116,0.063187,0.000000
46.210003,31.460632,-186.642075,-0.002371,0.002467,0.062657,139.943878,7.129081,0.626567,-186.642075,0.063768,0.000000
46.560001,32.431038,-186.642075,-0.002337,0.002498,0.063438,144.260468,7.348978,0.634379,-186.642075,0.064357,0.000000
46.910004,31.883652,-186.642075,-0.002324,0.002513,0.063828,141.825562,7.224939,0.638285,-186.642075,0.064938,0.000000
47.260002,32.187134,-186.642075,-0.002302,0.002534,0.064373,143.175522,7.293709,0.643735,-186.642075,0.065520,0.000000
47.610001,32.530830,-186.686554,-0.002281,0.002558,0.064981,144.704361,7.371592,0.649806,-186.686554,0.066108,0.000000
47.960003,32.949753,-186.731033,-0.002255,0.002579,0.065510,146.567825,7.466521,0.655105,-186.731033,0.066690,0.000000
48.310001,34.889442,-186.775513,-0.002242,0.002618,0.066490,155.195984,7.906061,0.664900,-186.775513,0.067271,0.000000
48.660004,34.283966,-186.819992,-0.002220,0.002633,0.066872,152.502701,7.768858,0.668715,-186.819992,0.067851,0.000000
49.010002,34.134270,-186.864471,-0.002199,0.002655,0.067427,151.836823,7.734936,0.674271,-186.864471,0.068441,0.000000
49.360001,35.170952,-186.908951,-0.002177,0.002682,0.068130,156.448212,7.969851,0.681296,-186.908951,0.069023,0.000000
49.710003,34.645538,-186.908951,-0.002169,0.002695,0.068441,154.111053,7.850791,0.684415,-186.908951,0.069604,0.000000
50.060001,35.033173,-186.997925,-0.002151,0.002717,0.069023,155.835327,7.938631,0.690229,-186.997925,0.070184,0.000000
50.410004,36.319725,-186.997925,-0.002130,0.002749,0.069821,161.558212,8.230167,0.698207,-186.997925,0.070775,0.000000
50.760002,36.281372,-187.042404,-0.002117,0.002769,0.070323,161.387604,8.221477,0.703233,-187.042404,0.071356,0.000000
51.110001,36.620972,-187.086884,-0.002100,0.002792,0.070905,162.898224,8.298430,0.709047,-187.086884,0.071936,0.000000
51.460003,37.490463,-187.175842,-0.002091,0.002817,0.071547,166.765915,8.495461,0.715466,-187.175842,0.072526,0.000000
51.810001,37.274857,-187.131363,-0.002074,0.002834,0.071980,165.806839,8.446603,0.719796,-187.131363,0.073108,0.000000
52.160004,38.335747,-187.131363,-0.002048,0.002862,0.072691,170.525925,8.687004,0.726912,-187.131363,0.073689,0.000000
52.510002,38.714447,-187.086884,-0.002039,0.002884,0.073254,172.210464,8.772820,0.732544,-187.086884,0.074269,0.000000
52.860001,39.203003,-187.220322,-0.002018,0.002906,0.073818,174.383667,8.883527,0.738176,-187.220322,0.074859,0.000000
53.210003,40.053131,-187.309280,-0.002013,0.002931,0.074443,178.165222,9.076169,0.744428,-187.309280,0.075441,0.000000
53.560001,40.197983,-187.309280,-0.001992,0.002948,0.074885,178.809555,9.108993,0.748849,-187.309280,0.076020,0.000000
53.910004,40.995605,-187.264801,-0.001975,0.002975,0.075571,182.357559,9.289737,0.755707,-187.264801,0.076602,0.000000
54.260002,42.495522,-187.353760,-0.001966,0.003004,0.076307,189.029526,9.629622,0.763065,-187.353760,0.077192,0.000000
54.610004,42.654900,-187.398254,-0.001932,0.003024,0.076818,189.738464,9.665738,0.768182,-187.398254,0.077774,0.000000
54.960003,43.394424,-187.487213,-0.001936,0.003047,0.077400,193.028046,9.833317,0.773996,-187.487213,0.078353,0.000000
55.310001,44.299294,-187.442734,-0.001923,0.003069,0.077964,197.053101,10.038363,0.779643,-187.442734,0.078935,0.000000
55.660004,44.676880,-187.487213,-0.001897,0.003090,0.078484,198.732681,10.123926,0.784836,-187.487213,0.079525,0.000000
56.010002,46.286270,-187.620651,-0.001871,0.003121,0.079281,205.891617,10.488619,0.792814,-187.620651,0.080105,0.000000
56.360004,46.774452,-187.576172,-0.001876,0.003141,0.079777,208.063156,10.599242,0.797765,-187.576172,0.080686,0.000000
56.710003,47.236191,-187.576172,-0.001850,0.003160,0.080262,210.117065,10.703875,0.802625,-187.576172,0.081277,0.000000
57.060001,48.531303,-187.620651,-0.001841,0.003184,0.080886,215.878021,10.997350,0.808862,-187.620651,0.081858,0.000000
57.410004,48.812447,-187.709610,-0.001819,0.003201,0.081312,217.128601,11.061059,0.813117,-187.709610,0.082438,0.000000
57.760002,49.405266,-187.709610,-0.001807,0.003221,0.081805,219.765594,11.195393,0.818052,-187.709610,0.083019,0.000000
58.110004,50.938324,-187.754089,-0.001785,0.003249,0.082533,226.584976,11.542789,0.825334,-187.754089,0.083610,0.000000
58.460003,51.425011,-187.798569,-0.001785,0.003267,0.082975,228.749878,11.653074,0.829755,-187.798569,0.084190,0.000000
58.810001,52.606178,-187.798569,-0.001772,0.003291,0.083601,234.003967,11.920731,0.836008,-187.798569,0.084771,0.000000
59.160004,54.177963,-187.843063,-0.001755,0.003320,0.084320,240.995621,12.276902,0.843199,-187.843063,0.085352,0.000000
59.510002,54.676193,-187.843063,-0.001750,0.003340,0.084832,243.211853,12.389803,0.848316,-187.843063,0.085943,0.000000
59.860004,55.458176,-187.887543,-0.001725,0.003356,0.085240,246.690292,12.567002,0.852404,-187.887543,0.086523,0.000000
60.210003,57.205353,-187.976501,-0.001716,0.003389,0.086072,254.462112,12.962918,0.860715,-187.976501,0.087104,0.000000
60.560001,58.465828,-188.020981,-0.001690,0.003409,0.086592,260.069000,13.248546,0.865923,-188.020981,0.087695,0.000000
60.910004,59.012848,-187.976501,-0.001694,0.003426,0.087018,262.502258,13.372502,0.870178,-187.976501,0.088274,0.000000
61.260002,59.561722,-188.065460,-0.001673,0.003441,0.087390,264.943756,13.496880,0.873902,-188.065460,0.088856,0.000000
61.610004,61.746429,-188.109940,-0.001664,0.003473,0.088206,274.661835,13.991940,0.882062,-188.109940,0.089437,0.000000
61.960003,63.765068,-188.154419,-0.001656,0.003505,0.089021,283.641174,14.449371,0.890207,-188.154419,0.090028,0.000000
62.310001,64.834892,-188.154419,-0.001634,0.003524,0.089498,288.399994,14.691796,0.894976,-188.154419,0.090607,0.000000
62.660004,65.838799,-188.154419,-0.001643,0.003544,0.090009,292.865601,14.919285,0.900093,-188.154419,0.091189,0.000000
63.010002,66.579079,-188.243378,-0.001604,0.003552,0.090226,296.158539,15.087035,0.902258,-188.243378,0.090486,0.000000
63.360004,65.475365,-188.243378,-0.001604,0.003551,0.090191,291.248962,14.836929,0.901910,-188.243378,294.500488,0.000000
63.710003,64.424156,-188.287872,-0.001600,0.003553,0.090235,286.572968,14.598722,0.902349,-188.287872,294.500488,0.000000
64.060005,65.593040,-188.332352,-0.001587,0.003564,0.090530,291.772430,14.863595,0.905301,-188.332352,294.500488,0.000000
64.410004,64.760414,-188.332352,-0.001578,0.003566,0.090573,288.068695,14.674920,0.905725,-188.332352,294.500488,0.000000
64.760002,65.814598,-188.421310,-0.001565,0.003580,0.090937,292.757965,14.913801,0.909374,-188.421310,294.500488,0.000000
65.110001,65.065010,-188.465790,-0.001574,0.003580,0.090937,289.423615,14.743942,0.909374,-188.465790,294.500488,0.000000
65.460007,66.416359,-188.465790,-0.001569,0.003591,0.091207,295.434723,15.050162,0.912069,-188.465790,294.500488,0.000000
65.810005,65.805672,-188.510269,-0.001552,0.003587,0.091119,292.718262,14.911778,0.911191,-188.510269,294.500488,0.000000
66.160004,65.177467,-188.510269,-0.001544,0.003588,0.091128,289.923859,14.769425,0.911282,-188.510269,294.500488,0.000000
66.510002,65.552086,-188.554749,-0.001548,0.003614,0.091787,291.590240,14.854316,0.917867,-188.554749,294.500488,0.000000
66.860001,65.181190,-188.554749,-0.001544,0.003614,0.091787,289.940430,14.770268,0.917867,-188.554749,294.500488,0.000000
67.210007,64.789467,-188.643707,-0.001539,0.003614,0.091805,288.197937,14.681503,0.918049,-188.643707,294.500488,0.000000
67.560005,66.060371,-188.688202,-0.001535,0.003617,0.091865,293.851196,14.969494,0.918655,-188.688202,294.500488,0.000000
67.910004,65.604576,-188.732681,-0.001513,0.003617,0.091875,291.823730,14.866209,0.918745,-188.732681,294.500488,0.000000
68.260002,65.239281,-188.732681,-0.001531,0.003617,0.091882,290.198822,14.783432,0.918821,-188.732681,294.500488,0.000000
68.610001,64.833031,-188.777161,-0.001522,0.003625,0.092065,288.391724,14.691375,0.920653,-188.777161,294.500488,0.000000
68.960007,66.097237,-188.821640,-0.001513,0.003633,0.092282,294.015198,14.977848,0.922818,-188.821640,294.500488,0.000000
69.310005,65.736031,-188.866119,-0.001526,0.003633,0.092282,292.408478,14.895997,0.922818,-188.866119,294.500488,0.000000
69.660004,65.386375,-188.866119,-0.001522,0.003633,0.092282,290.853119,14.816764,0.922818,-188.866119,294.500488,0.000000
70.010002,65.076561,-188.866119,-0.001505,0.003633,0.092291,289.475006,14.746559,0.922909,-188.866119,294.500488,0.000000
70.360001,64.795052,-188.910599,-0.001526,0.003633,0.092291,288.222778,14.682769,0.922909,-188.910599,294.500488,0.000000
70.710007,64.529549,-189.044037,-0.001518,0.003644,0.092550,287.041779,14.622604,0.925498,-189.044037,294.500488,0.000000
71.060005,66.206703,-189.088516,-0.001496,0.003632,0.092264,294.502136,15.002653,0.922636,-189.088516,294.500488,0.000000
71.410004,65.869713,-189.044037,-0.001500,0.003632,0.092264,293.003113,14.926290,0.922636,-189.044037,294.500488,0.000000
71.760002,65.668266,-189.044037,-0.001496,0.003632,0.092264,292.107025,14.880642,0.922636,-189.044037,294.500488,0.000000
72.110001,65.419136,-189.133011,-0.001509,0.003633,0.092282,290.998840,14.824188,0.922818,-189.133011,294.500488,0.000000
72.460007,65.232948,-189.177490,-0.001496,0.003649,0.092680,290.170654,14.781998,0.926800,-189.177490,294.500488,0.000000
72.810005,65.076927,-189.177490,-0.001505,0.003656,0.092863,289.476624,14.746643,0.928632,-189.177490,294.500488,0.000000
73.160004,65.323814,-189.221970,-0.001496,0.003663,0.093045,290.574829,14.802588,0.930448,-189.221970,294.500488,0.000000
73.510002,65.229607,-189.355408,-0.001492,0.003663,0.093045,290.155792,14.781240,0.930448,-189.355408,294.500488,0.000000
73.860001,65.041924,-189.355408,-0.001505,0.003663,0.093045,289.320923,14.738711,0.930448,-189.355408,294.500488,0.000000
74.210007,64.990547,-189.310928,-0.001500,0.003665,0.093080,289.092407,14.727069,0.930797,-189.310928,294.500488,0.000000
74.560005,64.844566,-189.355408,-0.001492,0.003665,0.093080,288.443024,14.693989,0.930797,-189.355408,294.500488,0.000000
74.910004,64.716469,-189.444366,-0.001496,0.003665,0.093089,287.873230,14.664962,0.930887,-189.444366,294.500488,0.000000
75.260002,65.896523,-189.488846,-0.001479,0.003669,0.093192,293.122375,14.932365,0.931917,-189.488846,294.500488,0.000000
75.610001,65.762474,-189.488846,-0.001479,0.003669,0.093192,292.526093,14.901990,0.931917,-189.488846,294.500488,0.000000
75.960007,65.564735,-189.533325,-0.001487,0.003669,0.093192,291.646515,14.857182,0.931917,-189.533325,294.500488,0.000000
76.310005,65.378548,-189.577820,-0.001487,0.003669,0.093192,290.818298,14.814991,0.931917,-189.577820,294.500488,0.000000
76.660004,65.245613,-189.622299,-0.001466,0.003669,0.093201,290.226990,14.784867,0.932008,-189.622299,294.500488,0.000000
77.010002,65.086235,-189.622299,-0.001487,0.003669,0.093201,289.518036,14.748752,0.932008,-189.622299,294.500488,0.000000
77.360001,64.967827,-189.755737,-0.001487,0.003669,0.093201,288.991333,14.721920,0.932008,-189.755737,294.500488,0.000000
77.710007,64.798027,-189.755737,-0.001483,0.003669,0.093201,288.236023,14.683442,0.932008,-189.755737,294.500488,0.000000
78.060005,64.683708,-189.755737,-0.001492,0.003670,0.093210,287.727509,14.657538,0.932099,-189.755737,294.500488,0.000000
78.410004,66.334068,-189.755737,-0.001475,0.003677,0.093392,295.068665,15.031515,0.933915,-189.755737,294.500488,0.000000
78.760002,66.186607,-189.844696,-0.001483,0.003677,0.093392,294.412720,14.998099,0.933915,-189.844696,294.500488,0.000000
79.110001,66.043983,-189.889175,-0.001483,0.003677,0.093392,293.778320,14.965780,0.933915,-189.889175,294.500488,0.000000
79.460007,65.834709,-189.844696,-0.001475,0.003677,0.093392,292.847412,14.918358,0.933915,-189.844696,294.500488,0.000000
79.810005,65.784431,-189.889175,-0.001470,0.003677,0.093401,292.623779,14.906965,0.934006,-189.889175,294.500488,0.000000
80.160004,65.613899,-189.933655,-0.001483,0.003677,0.093401,291.865204,14.868322,0.934006,-189.933655,294.500488,0.000000
80.510002,65.551338,-189.978149,-0.001457,0.003677,0.093401,291.586914,14.854146,0.934006,-189.978149,294.500488,0.000000
80.860001,65.429939,-190.022629,-0.001479,0.003677,0.093401,291.046906,14.826636,0.934006,-190.022629,294.500488,0.000000
81.210007,65.305946,-190.022629,-0.001483,0.003677,0.093401,290.495361,14.798539,0.934006,-190.022629,294.500488,0.000000
81.560005,65.218803,-190.067108,-0.001470,0.003677,0.093401,290.107727,14.778792,0.934006,-190.067108,294.500488,0.000000
81.910004,65.082512,-190.067108,-0.001479,0.003677,0.093401,289.501465,14.747909,0.934006,-190.067108,294.500488,0.000000
82.260002,64.993523,-190.156067,-0.001470,0.003677,0.093401,289.105621,14.727742,0.934006,-190.156067,294.500488,0.000000
82.610001,65.625069,-190.200546,-0.001487,0.003700,0.093990,291.914886,14.870853,0.939895,-190.200546,294.500488,0.000000
82.960007,65.659325,-190.156067,-0.001475,0.003700,0.093982,292.067261,14.878615,0.939820,-190.156067,294.500488,0.000000
83.310005,65.614632,-190.200546,-0.001470,0.003700,0.093982,291.868469,14.868487,0.939820,-190.200546,294.500488,0.000000
83.660004,65.569572,-190.245026,-0.001466,0.003700,0.093982,291.668030,14.858277,0.939820,-190.245026,294.500488,0.000000
84.010002,65.497337,-190.289505,-0.001470,0.003700,0.093982,291.346710,14.841908,0.939820,-190.289505,294.500488,0.000000
84.360001,65.420998,-190.378464,-0.001470,0.003700,0.093982,291.007141,14.824610,0.939820,-190.378464,294.500488,0.000000
84.710007,65.368126,-190.378464,-0.001466,0.003700,0.093990,290.771942,14.812629,0.939895,-190.378464,294.500488,0.000000
85.060005,65.294395,-190.422958,-0.001466,0.003700,0.093990,290.443970,14.795921,0.939895,-190.422958,294.500488,0.000000
85.410004,65.234444,-190.467438,-0.001466,0.003700,0.093990,290.177307,14.782336,0.939895,-190.467438,294.500488,0.000000
85.760002,65.165550,-190.511917,-0.001462,0.003700,0.093990,289.870850,14.766726,0.939895,-190.511917,294.500488,0.000000
86.110001,65.107841,-190.511917,-0.001470,0.003701,0.093999,289.614136,14.753648,0.939986,-190.511917,294.500488,0.000000
86.460007,65.040062,-190.467438,-0.001466,0.003701,0.093999,289.312653,14.738289,0.939986,-190.467438,294.500488,0.000000
86.810005,65.498451,-190.556396,-0.001462,0.003708,0.094180,291.351654,14.842161,0.941803,-190.556396,294.500488,0.000000
87.160004,65.474251,-190.600876,-0.001470,0.003708,0.094180,291.244019,14.836677,0.941803,-190.600876,294.500488,0.000000
87.510002,65.427711,-190.689835,-0.001466,0.003708,0.094180,291.036987,14.826132,0.941803,-190.689835,294.500488,0.000000
87.860001,65.387123,-190.689835,-0.001466,0.003708,0.094180,290.856445,14.816934,0.941803,-190.689835,294.500488,0.000000
88.210007,65.323448,-190.689835,-0.001475,0.003708,0.094180,290.573212,14.802505,0.941803,-190.689835,294.500488,0.000000
88.560005,65.281731,-190.734314,-0.001466,0.003708,0.094180,290.387634,14.793052,0.941803,-190.734314,294.500488,0.000000
88.910004,65.237801,-190.823273,-0.001462,0.003708,0.094180,290.192230,14.783097,0.941803,-190.823273,294.500488,0.000000
89.260002,65.174492,-190.823273,-0.001470,0.003708,0.094180,289.910614,14.768751,0.941803,-190.823273,294.500488,0.000000
89.610001,65.112679,-190.823273,-0.001470,0.003710,0.094224,289.635651,14.754745,0.942242,-190.823273,294.500488,0.000000
89.960007,65.231468,-190.912247,-0.001457,0.003711,0.094250,290.164062,14.781662,0.942499,-190.912247,294.500488,0.000000
90.310005,65.191994,-190.912247,-0.001466,0.003711,0.094250,289.988464,14.772717,0.942499,-190.912247,294.500488,0.000000
90.660004,65.162209,-190.867767,-0.001470,0.003711,0.094250,289.855988,14.765968,0.942499,-190.867767,294.500488,0.000000
91.010002,65.110817,-190.956726,-0.001462,0.003711,0.094250,289.627380,14.754322,0.942499,-190.956726,294.500488,0.000000
91.360001,65.055336,-190.912247,-0.001457,0.003711,0.094250,289.380585,14.741750,0.942499,-190.912247,294.500488,0.000000
91.710007,65.029640,-191.045685,-0.001457,0.003712,0.094276,289.266296,14.735928,0.942757,-191.045685,294.500488,0.000000
92.060005,65.086235,-190.956726,-0.001470,0.003713,0.094310,289.518036,14.748752,0.943105,-190.956726,294.500488,0.000000
92.410004,65.065010,-191.134644,-0.001483,0.003713,0.094310,289.423615,14.743942,0.943105,-191.134644,294.500488,0.000000
92.760002,65.036720,-191.179123,-0.001457,0.003713,0.094310,289.297791,14.737532,0.943105,-191.179123,294.500488,0.000000
93.110001,65.007668,-191.179123,-0.001462,0.003713,0.094310,289.168549,14.730948,0.943105,-191.179123,294.500488,0.000000
93.460007,64.997246,-191.179123,-0.001457,0.003713,0.094310,289.122192,14.728586,0.943105,-191.179123,294.500488,0.000000
93.810005,64.949577,-191.223602,-0.001462,0.003716,0.094398,288.910156,14.717784,0.943983,-191.223602,294.500488,0.000000
94.160004,65.347649,-191.223602,-0.001462,0.003719,0.094466,290.680847,14.807989,0.944664,-191.223602,294.500488,0.000000
94.510002,65.368126,-191.268097,-0.001457,0.003719,0.094466,290.771942,14.812629,0.944664,-191.268097,294.500488,0.000000
94.860008,65.339821,-191.312576,-0.001457,0.003719,0.094466,290.646027,14.806215,0.944664,-191.312576,294.500488,0.000000
95.210007,65.319344,-191.312576,-0.001466,0.003719,0.094466,290.554962,14.801575,0.944664,-191.312576,294.500488,0.000000
95.560005,65.295891,-191.401535,-0.001440,0.003719,0.094466,290.450623,14.796261,0.944664,-191.401535,294.500488,0.000000
95.910004,65.264977,-191.401535,-0.001470,0.003719,0.094466,290.313110,14.789255,0.944664,-191.401535,294.500488,0.000000
96.260002,65.225136,-191.401535,-0.001457,0.003719,0.094466,290.135895,14.780228,0.944664,-191.401535,294.500488,0.000000
96.610008,65.181572,-191.446014,-0.001457,0.003719,0.094466,289.942108,14.770355,0.944664,-191.446014,294.500488,0.000000
96.960007,65.154381,-191.534973,-0.001462,0.003719,0.094466,289.821167,14.764194,0.944664,-191.534973,294.500488,0.000000
97.310005,65.085503,-191.579453,-0.001457,0.003719,0.094466,289.514771,14.748586,0.944664,-191.579453,294.500488,0.000000
97.660004,65.061287,-191.623932,-0.001444,0.003719,0.094466,289.407043,14.743098,0.944664,-191.623932,294.500488,0.000000
98.010002,65.031868,-191.668411,-0.001449,0.003719,0.094466,289.276184,14.736432,0.944664,-191.668411,294.500488,0.000000
98.360008,65.152901,-191.668411,-0.001449,0.003725,0.094615,289.814575,14.763858,0.946148,-191.668411,294.500488,0.000000
98.710007,65.381157,-191.623932,-0.001462,0.003725,0.094615,290.829926,14.815581,0.946148,-191.623932,294.500488,0.000000
99.060005,65.393074,-191.712906,-0.001453,0.003725,0.094615,290.882935,14.818282,0.946148,-191.712906,294.500488,0.000000
99.410004,65.374825,-191.757385,-0.001449,0.003725,0.094615,290.801758,14.814147,0.946148,-191.757385,294.500488,0.000000
99.760002,65.350258,-191.757385,-0.001457,0.003725,0.094615,290.692474,14.808580,0.946148,-191.757385,294.500488,0.000000
100.110008,65.331627,-191.846344,-0.001449,0.003725,0.094615,290.609589,14.804358,0.946148,-191.846344,294.500488,0.000000
100.460007,65.304451,-191.890823,-0.001436,0.003725,0.094615,290.488708,14.798200,0.946148,-191.890823,294.500488,0.000000
100.810005,65.281364,-191.890823,-0.001457,0.003725,0.094615,290.386017,14.792969,0.946148,-191.890823,294.500488,0.000000
101.160004,65.254921,-191.890823,-0.001444,0.003725,0.094622,290.268372,14.786977,0.946224,-191.890823,294.500488,0.000000
101.510002,65.234810,-191.979782,-0.001453,0.003725,0.094622,290.178925,14.782419,0.946224,-191.979782,294.500488,0.000000
101.860008,65.208748,-192.024261,-0.001444,0.003725,0.094622,290.062988,14.776513,0.946224,-192.024261,294.500488,0.000000
102.210007,65.163689,-192.024261,-0.001449,0.003725,0.094622,289.862549,14.766303,0.946224,-192.024261,294.500488,0.000000
102.560005,65.131676,-192.024261,-0.001436,0.003725,0.094622,289.720154,14.759048,0.946224,-192.024261,294.500488,0.000000
102.910004,65.083641,-192.113220,-0.001440,0.003726,0.094641,289.506500,14.748164,0.946405,-192.113220,294.500488,0.000000
103.260002,65.062782,-192.068741,-0.001444,0.003726,0.094641,289.413696,14.743437,0.946405,-192.068741,294.500488,0.000000
103.610008,65.047890,-192.202194,-0.001453,0.003726,0.094650,289.347473,14.740063,0.946496,-192.202194,294.500488,0.000000
103.960007,65.068001,-192.246674,-0.001453,0.003728,0.094692,289.436920,14.744620,0.946920,-192.246674,294.500488,0.000000
104.310005,65.119011,-192.246674,-0.001444,0.003728,0.094692,289.663818,14.756179,0.946920,-192.246674,294.500488,0.000000
104.660004,65.110069,-192.246674,-0.001449,0.003728,0.094692,289.624054,14.754152,0.946920,-192.246674,294.500488,0.000000
105.010002,65.090706,-192.246674,-0.001457,0.003728,0.094692,289.537933,14.749764,0.946920,-192.246674,294.500488,0.000000
105.360008,65.075813,-192.380112,-0.001440,0.003728,0.094692,289.471680,14.746390,0.946920,-192.380112,294.500488,0.000000
105.710007,65.034859,-192.335632,-0.001440,0.003728,0.094701,289.289490,14.737109,0.947011,-192.335632,294.500488,0.000000
106.060005,65.002464,-192.380112,-0.001449,0.003729,0.094710,289.145416,14.729769,0.947102,-192.380112,294.500488,0.000000
106.410004,65.497337,-192.469070,-0.001444,0.003735,0.094875,291.346710,14.841908,0.948752,-192.469070,294.500488,0.000000
106.760002,65.537926,-192.469070,-0.001453,0.003735,0.094875,291.527252,14.851107,0.948752,-192.469070,294.500488,0.000000
107.110008,65.553947,-192.469070,-0.001440,0.003735,0.094875,291.598511,14.854736,0.948752,-192.469070,294.500488,0.000000
107.460007,65.535316,-192.469070,-0.001444,0.003735,0.094875,291.515656,14.850515,0.948752,-192.469070,294.500488,0.000000
107.810005,65.537178,-192.513550,-0.001449,0.003735,0.094875,291.523926,14.850937,0.948752,-192.513550,294.500488,0.000000
108.160004,65.512978,-192.647003,-0.001444,0.003735,0.094875,291.416290,14.845453,0.948752,-192.647003,294.500488,0.000000
108.510002,65.485420,-192.647003,-0.001449,0.003735,0.094875,291.293701,14.839208,0.948752,-192.647003,294.500488,0.000000
108.860008,65.479836,-192.691483,-0.001453,0.003735,0.094875,291.268860,14.837942,0.948752,-192.691483,294.500488,0.000000
109.210007,65.445946,-192.691483,-0.001436,0.003735,0.094875,291.118103,14.830263,0.948752,-192.691483,294.500488,0.000000
109.560005,65.406487,-192.691483,-0.001436,0.003735,0.094875,290.942596,14.821321,0.948752,-192.691483,294.500488,0.000000
109.910004,65.391212,-192.735962,-0.001444,0.003735,0.094875,290.874634,14.817861,0.948752,-192.735962,294.500488,0.000000
110.260002,65.371483,-192.824921,-0.001431,0.003735,0.094875,290.786865,14.813390,0.948752,-192.824921,294.500488,0.000000
110.610008,65.325676,-192.824921,-0.001431,0.003735,0.094875,290.583130,14.803010,0.948752,-192.824921,294.500488,0.000000
110.960007,65.305946,-192.824921,-0.001444,0.003735,0.094875,290.495361,14.798539,0.948752,-192.824921,294.500488,0.000000
111.310005,65.299614,-192.913879,-0.001427,0.003735,0.094875,290.467194,14.797104,0.948752,-192.913879,294.500488,0.000000
111.660004,65.267586,-192.958359,-0.001440,0.003735,0.094875,290.324707,14.789846,0.948752,-192.958359,294.500488,0.000000
112.010002,65.249718,-192.913879,-0.001427,0.003735,0.094875,290.245239,14.785798,0.948752,-192.913879,294.500488,0.000000
112.360008,65.235939,-193.002853,-0.001440,0.003735,0.094875,290.183960,14.782675,0.948752,-193.002853,294.500488,0.000000
112.710007,65.202797,-193.002853,-0.001436,0.003735,0.094875,290.036530,14.775166,0.948752,-193.002853,294.500488,0.000000
113.060005,65.208000,-193.091812,-0.001440,0.003736,0.094901,290.059662,14.776343,0.949009,-193.091812,294.500488,0.000000
113.410004,65.212105,-193.091812,-0.001427,0.003736,0.094901,290.077942,14.777274,0.949009,-193.091812,294.500488,0.000000
113.760002,65.197960,-193.136292,-0.001440,0.003736,0.094901,290.015015,14.774069,0.949009,-193.136292,294.500488,0.000000
114.110008,65.165550,-193.180771,-0.001431,0.003736,0.094901,289.870850,14.766726,0.949009,-193.180771,294.500488,0.000000
114.460007,65.180077,-193.225250,-0.001436,0.003738,0.094943,289.935455,14.770016,0.949433,-193.225250,294.500488,0.000000
114.810005,65.189018,-193.225250,-0.001431,0.003738,0.094943,289.975250,14.772042,0.949433,-193.225250,294.500488,0.000000
115.160004,65.175987,-193.225250,-0.001440,0.003738,0.094943,289.917267,14.769090,0.949433,-193.225250,294.500488,0.000000
115.510002,65.171516,-193.269730,-0.001436,0.003738,0.094943,289.897369,14.768077,0.949433,-193.269730,294.500488,0.000000
115.860008,65.158485,-193.314209,-0.001440,0.003738,0.094943,289.839417,14.765123,0.949433,-193.314209,294.500488,0.000000
116.210007,65.135765,-193.314209,-0.001423,0.003738,0.094943,289.738342,14.759975,0.949433,-193.314209,294.500488,0.000000
116.560005,65.116768,-193.358688,-0.001440,0.003738,0.094943,289.653839,14.755671,0.949433,-193.358688,294.500488,0.000000
116.910004,65.087364,-193.447662,-0.001436,0.003738,0.094943,289.523041,14.749007,0.949433,-193.447662,294.500488,0.000000
117.260002,65.095924,-193.403168,-0.001440,0.003741,0.095031,289.561127,14.750948,0.950311,-193.403168,294.500488,0.000000
117.610008,65.261635,-193.447662,-0.001440,0.003741,0.095031,290.298248,14.788498,0.950311,-193.447662,294.500488,0.000000
117.960007,65.259026,-193.492142,-0.001440,0.003741,0.095031,290.286652,14.787907,0.950311,-193.492142,294.500488,0.000000
118.310005,65.257530,-193.492142,-0.001440,0.003741,0.095031,290.279999,14.787567,0.950311,-193.492142,294.500488,0.000000
118.660004,65.251945,-193.536621,-0.001431,0.003741,0.095031,290.255157,14.786302,0.950311,-193.536621,294.500488,0.000000
119.010002,65.243004,-193.625580,-0.001427,0.003741,0.095031,290.215363,14.784276,0.950311,-193.625580,294.500488,0.000000
119.360008,65.229607,-193.714539,-0.001436,0.003741,0.095031,290.155792,14.781240,0.950311,-193.714539,294.500488,0.000000
119.710007,65.214714,-193.670059,-0.001440,0.003741,0.095031,290.089539,14.777865,0.950311,-193.670059,294.500488,0.000000
120.060005,65.193855,-193.714539,-0.001436,0.003741,0.095031,289.996765,14.773139,0.950311,-193.714539,294.500488,0.000000
120.410004,65.170403,-193.714539,-0.001436,0.003741,0.095031,289.892426,14.767824,0.950311,-193.714539,294.500488,0.000000
120.760002,65.156242,-193.803497,-0.001436,0.003741,0.095031,289.829437,14.764615,0.950311,-193.803497,294.500488,0.000000
121.110008,65.130180,-193.847992,-0.001436,0.003741,0.095031,289.713501,14.758710,0.950311,-193.847992,294.500488,0.000000
121.460007,65.385262,-193.847992,-0.001436,0.003746,0.095152,290.848175,14.816512,0.951523,-193.847992,294.500488,0.000000
121.810005,65.449669,-193.847992,-0.001431,0.003746,0.095152,291.134674,14.831106,0.951523,-193.847992,294.500488,0.000000
122.160004,65.447441,-193.936951,-0.001436,0.003746,0.095152,291.124756,14.830602,0.951523,-193.936951,294.500488,0.000000
122.510002,65.462334,-193.892471,-0.001418,0.003746,0.095152,291.191010,14.833977,0.951523,-193.892471,294.500488,0.000000
122.860008,65.452278,-194.025909,-0.001431,0.003746,0.095152,291.146271,14.831698,0.951523,-194.025909,294.500488,0.000000
123.210007,65.439995,-193.981430,-0.001427,0.003746,0.095152,291.091644,14.828915,0.951523,-193.981430,294.500488,0.000000
123.560005,65.415047,-194.025909,-0.001427,0.003746,0.095152,290.980652,14.823262,0.951523,-194.025909,1681.640991,0.000000
123.910004,65.407600,-194.114868,-0.001418,0.003740,0.095004,290.947540,14.821574,0.950039,-194.114868,0.094831,0.000000
124.260002,65.289177,-194.114868,-0.001436,0.003720,0.094485,290.420776,14.794740,0.944846,-194.114868,0.094241,0.000000
124.610008,65.252693,-194.114868,-0.001423,0.003702,0.094024,290.258484,14.786471,0.940244,-194.114868,0.093661,0.000000
124.960007,65.190132,-194.114868,-0.001423,0.003683,0.093557,289.980194,14.772295,0.935565,-194.114868,0.093080,0.000000
125.310005,65.140984,-194.203827,-0.001414,0.003659,0.092940,289.761566,14.761158,0.929404,-194.203827,0.092489,0.000000
125.660004,65.110817,-194.248306,-0.001423,0.003637,0.092377,289.627380,14.754322,0.923772,-194.248306,0.091909,0.000000
126.010010,65.139870,-194.248306,-0.001410,0.003620,0.091943,289.756622,14.760905,0.919427,-194.248306,0.091328,0.000000
126.360008,65.054588,-194.337280,-0.001414,0.003591,0.091224,289.377258,14.741581,0.912235,-194.337280,0.090747,0.000000
126.710007,65.015114,-194.337280,-0.001418,0.003571,0.090712,289.201660,14.732635,0.907118,-194.337280,0.090156,0.000000
127.060005,64.973412,-194.381760,-0.001406,0.003556,0.090314,289.016174,14.723186,0.903136,-194.381760,0.089576,0.000000
127.410004,64.917931,-194.470718,-0.001401,0.003527,0.089576,288.769379,14.710613,0.895764,-194.470718,0.088995,0.000000
127.760010,64.869148,-194.426239,-0.001401,0.003509,0.089125,288.552368,14.699559,0.891252,-194.426239,0.088414,0.000000
128.110001,64.571251,-194.470718,-0.001401,0.003488,0.088588,287.227264,14.632055,0.885877,-194.470718,0.087825,0.000000
128.460007,63.664528,-194.559677,-0.001393,0.003458,0.087832,283.193970,14.426589,0.878323,-194.559677,0.087243,0.000000
128.810013,62.964088,-194.515198,-0.001388,0.003444,0.087476,280.078247,14.267866,0.874765,-194.515198,0.086662,0.000000
129.160004,61.758347,-194.559677,-0.001401,0.003420,0.086869,274.714844,13.994641,0.868694,-194.559677,0.086081,0.000000
129.510010,60.245773,-194.604156,-0.001388,0.003399,0.086332,267.986572,13.651888,0.863319,-194.604156,0.085492,0.000000
129.860001,58.830009,-194.648636,-0.001388,0.003378,0.085804,261.688965,13.331070,0.858036,-194.648636,0.084910,0.000000
130.210007,56.900002,-194.648636,-0.001397,0.003357,0.085266,253.103851,12.893724,0.852661,-194.648636,0.084329,0.000000
130.560013,54.550331,-194.737610,-0.001371,0.003331,0.084598,242.651993,12.361281,0.845985,-194.737610,0.083740,0.000000
130.910004,52.586815,-194.782089,-0.001388,0.003314,0.084164,233.917831,11.916343,0.841640,-194.782089,0.083159,0.000000
131.260010,50.047607,-194.737610,-0.001371,0.003290,0.083557,222.622879,11.340950,0.835569,-194.737610,0.082577,0.000000
131.610001,47.562767,-194.826569,-0.001380,0.003266,0.082950,211.569748,10.777877,0.829498,-194.826569,0.081996,0.000000
131.960007,45.071968,-194.915527,-0.001388,0.003243,0.082377,200.490128,10.213453,0.823775,-194.915527,0.081407,0.000000
132.310013,42.817993,-194.915527,-0.001384,0.003224,0.081901,190.463943,9.702696,0.819006,-194.915527,0.080826,0.000000
132.660004,39.631607,-194.915527,-0.001388,0.003195,0.081156,176.290192,8.980651,0.811557,-194.915527,0.080244,0.000000
133.010010,37.582436,-195.004486,-0.001384,0.003177,0.080705,167.175018,8.516302,0.807046,-195.004486,0.079663,0.000000
133.360001,35.539978,-194.960007,-0.001380,0.003159,0.080228,158.089722,8.053473,0.802277,-194.960007,0.079074,0.000000
133.710007,33.080086,-195.004486,-0.001380,0.003138,0.079698,147.147568,7.496055,0.796978,-195.004486,0.078493,0.000000
134.060013,30.001305,-195.048965,-0.001393,0.003108,0.078944,133.452469,6.798393,0.789438,-195.048965,0.077911,0.000000
134.410004,27.730583,-195.004486,-0.001380,0.003085,0.078372,123.351791,6.283840,0.783715,-195.004486,0.077322,0.000000
134.760010,25.031250,-195.137939,-0.001393,0.003062,0.077781,111.344559,5.672162,0.777811,-195.137939,0.076741,0.000000
135.110001,23.029007,-195.137939,-0.001384,0.003043,0.077297,102.438141,5.218448,0.772966,-195.137939,0.076160,0.000000
135.460007,20.476021,-195.137939,-0.001384,0.003019,0.076690,91.081886,4.639933,0.766895,-195.137939,0.075578,0.000000
135.810013,17.667213,-195.226898,-0.001388,0.002993,0.076013,78.587692,4.003448,0.760128,-195.226898,0.074989,0.000000
136.160004,15.329460,-195.182419,-0.001401,0.002973,0.075509,68.188843,3.473705,0.755087,-195.182419,0.074408,0.000000
136.510010,12.586937,-195.271378,-0.001397,0.002947,0.074859,55.989491,2.852241,0.748592,-195.271378,0.073827,0.000000
136.860001,10.749275,-195.271378,-0.001406,0.002929,0.074408,47.815163,2.435820,0.744080,-195.271378,0.073245,0.000000
137.210007,7.650024,-195.360336,-0.001406,0.002901,0.073696,34.029007,1.733520,0.736964,-195.360336,0.072656,0.000000
137.560013,5.461960,-195.360336,-0.001401,0.002881,0.073168,24.296011,1.237698,0.731681,-195.360336,0.072075,0.000000
137.910004,2.706779,-195.404816,-0.001427,0.002855,0.072510,12.040357,0.613365,0.725095,-195.404816,0.071494,0.000000
138.260010,0.163475,-195.360336,-0.001418,0.002828,0.071840,0.727173,0.037044,0.718403,-195.360336,0.070914,0.000000
138.610001,-1.422832,-195.449295,-0.001431,0.002814,0.071468,-6.329075,-0.322418,0.714679,-195.449295,0.070323,0.000000
138.960007,-2.751083,-195.493774,-0.001436,0.002797,0.071042,-12.237430,-0.623404,0.710425,-195.493774,0.069742,0.000000
139.310013,-0.311676,-195.538254,-0.001470,0.002774,0.070463,-1.386404,-0.070627,0.704626,-195.538254,0.069161,0.000000
139.660004,-0.051758,-195.538254,-0.001470,0.002735,0.069474,-0.230230,-0.011728,0.694740,-195.538254,0.068572,0.000000
140.010010,-0.049149,-195.582748,-0.001479,0.002716,0.068979,-0.218624,-0.011137,0.689790,-195.582748,0.067990,0.000000
140.360001,-0.008186,-195.627228,-0.001487,0.002691,0.068346,-0.036415,-0.001855,0.683461,-195.627228,0.067409,0.000000
140.710007,-0.062187,-195.671707,-0.001496,0.002673,0.067886,-0.276622,-0.014092,0.678859,-195.671707,0.066829,0.000000
141.060013,-0.081917,-195.627228,-0.001479,0.002650,0.067314,-0.364384,-0.018563,0.673136,-195.627228,0.066239,0.000000
141.410004,-0.051758,-195.671707,-0.001496,0.002629,0.066776,-0.230230,-0.011728,0.667761,-195.671707,0.065657,0.000000
141.760010,-0.101280,-195.716187,-0.001496,0.002602,0.066083,-0.450517,-0.022950,0.660828,-195.716187,0.065076,0.000000
142.000000,-0.040588,-195.760666,-0.001500,0.002596,0.065927,-0.180546,-0.009197,0.659268,-195.760666,0.065771,0.000000