File: Data/compression 30/AutoNoHeating-17-30-reverse-1-1_10242024_162253.csv
Time (sec),S:Load (lbs),S:HL1 (DIM),S:LVDT (in),S:Position (in),Ch:Position (mm),Ch:Load (N),Ch:Stress (MPa),Ch:Strain (mm/mm),Ch:HL1 (DIM),Set Point (),Cycles ()
0.110000,-0.032768,-135.355530,-0.007614,-0.007600,-0.193036,-0.145760,-0.007425,-1.930357,-135.355530,-0.192862,0.000000
0.470000,-0.037231,-135.355530,-0.007618,-0.007590,-0.192784,-0.165614,-0.008437,-1.927844,-135.355530,-0.192150,0.000000
0.830000,-0.007820,-135.400009,-0.007606,-0.007383,-0.187520,-0.034786,-0.001772,-1.875203,-135.400009,-0.186150,0.000000
1.190000,-0.006699,-135.488983,-0.007364,-0.007138,-0.181293,-0.029797,-0.001518,-1.812934,-135.488983,-0.180149,0.000000
1.550000,-0.004097,-135.533463,-0.007118,-0.006902,-0.175309,-0.018224,-0.000928,-1.753088,-135.533463,-0.174148,0.000000
1.910000,0.005219,-135.577942,-0.006903,-0.006676,-0.169560,0.023213,0.001183,-1.695603,-135.577942,-0.168163,0.000000
2.270000,-0.037979,-135.577942,-0.006648,-0.006435,-0.163445,-0.168940,-0.008606,-1.634454,-135.577942,-0.162162,0.000000
2.630000,-0.014893,-135.711380,-0.006403,-0.006193,-0.157314,-0.066245,-0.003375,-1.573139,-135.711380,-0.156160,0.000000
2.990000,-0.035370,-135.711380,-0.006170,-0.005960,-0.151373,-0.157333,-0.008015,-1.513731,-135.711380,-0.150160,0.000000
3.350000,0.019737,-135.800339,-0.005920,-0.005728,-0.145494,0.087796,0.004473,-1.454944,-135.800339,-0.144176,0.000000
3.710000,0.027557,-135.844818,-0.005678,-0.005485,-0.139319,0.122581,0.006245,-1.393190,-135.844818,-0.138174,0.000000
4.070000,0.010429,-135.844818,-0.005454,-0.005261,-0.133639,0.046392,0.002363,-1.336386,-135.844818,-0.132173,0.000000
4.430000,-0.022713,-135.978271,-0.005217,-0.005024,-0.127621,-0.101031,-0.005147,-1.276206,-135.978271,-0.126172,0.000000
4.790000,-0.048775,-135.933792,-0.004975,-0.004780,-0.121412,-0.216961,-0.011053,-1.214119,-135.933792,-0.120170,0.000000
5.150000,0.011177,-136.067230,-0.004721,-0.004539,-0.115288,0.049718,0.002533,-1.152879,-136.067230,-0.114187,0.000000
5.510000,0.133682,-136.111710,-0.004592,-0.000000,-0.000000,0.594648,0.030293,-0.000000,-136.111710,0.000147,0.000000
5.870000,0.118416,-136.156189,-0.004587,-0.000000,-0.000009,0.526740,0.026833,-0.000091,-136.156189,0.000147,0.000000
6.230000,0.128471,-136.200668,-0.004583,-0.000000,-0.000009,0.571469,0.029112,-0.000091,-136.200668,0.000728,0.000000
6.590000,0.187675,-136.289627,-0.004579,0.000016,0.000416,0.834822,0.042528,0.004163,-136.289627,0.001326,0.000000
6.950000,0.315399,-136.289627,-0.004566,0.000038,0.000972,1.402966,0.071470,0.009720,-136.289627,0.001926,0.000000
7.310000,0.497864,-136.334122,-0.004566,0.000060,0.001526,2.214609,0.112818,0.015261,-136.334122,0.002524,0.000000
7.670001,0.752937,-136.378601,-0.004536,0.000080,0.002038,3.349232,0.170618,0.020378,-136.378601,0.003131,0.000000
8.030001,1.101852,-136.512039,-0.004523,0.000102,0.002593,4.901284,0.249683,0.025934,-136.512039,0.003729,0.000000
8.390000,1.617218,-136.512039,-0.004497,0.000132,0.003356,7.193745,0.366467,0.033564,-136.512039,0.004327,0.000000
8.750000,2.036133,-136.556519,-0.004471,0.000157,0.003980,9.057171,0.461394,0.039802,-136.556519,0.004926,0.000000
9.110001,2.400314,-136.600998,-0.004467,0.000176,0.004466,10.677132,0.543919,0.044662,-136.600998,0.005524,0.000000
9.470000,3.008400,-136.645477,-0.004437,0.000203,0.005152,13.382031,0.681713,0.051520,-136.645477,0.006122,0.000000
9.830001,3.313744,-136.734436,-0.004428,0.000216,0.005499,14.740268,0.750905,0.054987,-136.734436,0.006730,0.000000
10.190001,4.284149,-136.823410,-0.004402,0.000255,0.006469,19.056847,0.970802,0.064691,-136.823410,0.007328,0.000000
10.550000,4.536987,-136.778931,-0.004376,0.000274,0.006972,20.181528,1.028096,0.069718,-136.778931,0.007927,0.000000
10.910001,5.155128,-136.912369,-0.004359,0.000298,0.007571,22.931156,1.168169,0.075713,-136.912369,0.008525,0.000000
11.270000,5.759117,-136.956848,-0.004342,0.000325,0.008256,25.617832,1.305035,0.082556,-136.956848,0.009123,0.000000
11.630000,6.039886,-137.045807,-0.004312,0.000339,0.008602,26.866756,1.368658,0.086023,-137.045807,0.009730,0.000000
11.990001,6.694511,-137.045807,-0.004299,0.000363,0.009218,29.778673,1.516998,0.092185,-137.045807,0.010328,0.000000
12.350000,7.430321,-137.090286,-0.004281,0.000393,0.009982,33.051716,1.683735,0.099815,-137.090286,0.010928,0.000000
12.710001,7.943825,-137.179260,-0.004264,0.000418,0.010607,35.335896,1.800096,0.106068,-137.179260,0.011526,0.000000
13.070001,8.439453,-137.134766,-0.004243,0.000441,0.011205,37.540562,1.912408,0.112048,-137.134766,0.012124,0.000000
13.430000,8.943275,-137.312698,-0.004221,0.000461,0.011717,39.781677,2.026575,0.117165,-137.312698,0.012731,0.000000
13.790001,9.411346,-137.312698,-0.004208,0.000484,0.012298,41.863758,2.132642,0.122979,-137.312698,0.013329,0.000000
14.150001,9.692482,-137.357178,-0.004178,0.000499,0.012670,43.114315,2.196348,0.126703,-137.357178,0.013927,0.000000
14.510000,10.303925,-137.401657,-0.004169,0.000527,0.013389,45.834145,2.334903,0.133894,-137.401657,0.014526,0.000000
14.870001,10.779068,-137.446136,-0.004143,0.000549,0.013945,47.947689,2.442572,0.139451,-137.446136,0.015124,0.000000
15.230000,11.823944,-137.579575,-0.004113,0.000581,0.014760,52.595531,2.679344,0.147596,-137.579575,0.015732,0.000000
15.590001,11.809052,-137.535095,-0.004105,0.000598,0.015194,52.529285,2.675969,0.151941,-137.535095,0.016330,0.000000
15.950001,12.482300,-137.624069,-0.004087,0.000621,0.015766,55.524044,2.828530,0.157664,-137.624069,0.016928,0.000000
16.310001,12.909782,-137.579575,-0.004066,0.000642,0.016295,57.425579,2.925399,0.162947,-137.579575,0.017527,0.000000
16.670000,13.610962,-137.713028,-0.004040,0.000670,0.017023,60.544582,3.084288,0.170229,-137.713028,0.018125,0.000000
17.030001,13.371155,-137.757507,-0.004027,0.000678,0.017232,59.477867,3.029947,0.172319,-137.757507,0.018732,0.000000
17.390001,14.695679,-137.757507,-0.004001,0.000717,0.018202,65.369644,3.330088,0.182023,-137.757507,0.019330,0.000000
17.750000,14.785797,-137.846466,-0.003984,0.000736,0.018697,65.770508,3.350509,0.186974,-137.846466,0.019928,0.000000
18.110001,15.447876,-137.890945,-0.003971,0.000763,0.019374,68.715584,3.500539,0.193741,-137.890945,0.020528,0.000000
18.470001,15.475060,-137.890945,-0.003954,0.000783,0.019893,68.836502,3.506699,0.198934,-137.890945,0.021126,0.000000
18.830002,15.854134,-138.068878,-0.003936,0.000805,0.020449,70.522705,3.592598,0.204490,-138.068878,0.021724,0.000000
19.190001,16.747086,-138.024384,-0.003906,0.000832,0.021135,74.494759,3.794944,0.211349,-138.024384,0.022331,0.000000
19.550001,17.443047,-138.113358,-0.003863,0.000860,0.021854,77.590546,3.952651,0.218540,-138.113358,0.022929,0.000000
19.910002,17.312340,-138.157837,-0.003863,0.000877,0.022279,77.009132,3.923032,0.222794,-138.157837,0.023528,0.000000
20.270000,17.853401,-138.246796,-0.003824,0.000907,0.023042,79.415894,4.045639,0.230424,-138.246796,0.024126,0.000000
20.630001,17.831429,-138.291275,-0.003803,0.000926,0.023510,79.318153,4.040659,0.235103,-138.291275,0.024724,0.000000
20.990002,18.131935,-138.291275,-0.003790,0.000947,0.024048,80.654877,4.108755,0.240477,-138.291275,0.025332,0.000000
21.350000,18.680443,-138.380234,-0.003764,0.000975,0.024759,83.094757,4.233049,0.247593,-138.380234,0.025930,0.000000
21.710001,19.477318,-138.469208,-0.003742,0.001006,0.025548,86.639435,4.413623,0.255480,-138.469208,0.026529,0.000000
22.070002,19.718987,-138.513687,-0.003712,0.001031,0.026190,87.714432,4.468387,0.261900,-138.513687,0.027127,0.000000
22.430000,19.451622,-138.513687,-0.003708,0.001046,0.026581,86.525139,4.407801,0.265806,-138.513687,0.027725,0.000000
22.790001,19.681007,-138.602646,-0.003691,0.001066,0.027083,87.545494,4.459780,0.270832,-138.602646,0.028332,0.000000
23.150002,20.386650,-138.647125,-0.003652,0.001096,0.027839,90.684349,4.619681,0.278387,-138.647125,0.028930,0.000000
23.510000,20.570229,-138.691605,-0.003635,0.001121,0.028462,91.500946,4.661281,0.284624,-138.691605,0.029530,0.000000
23.870001,21.246834,-138.691605,-0.003604,0.001150,0.029209,94.510635,4.814601,0.292088,-138.691605,0.030128,0.000000
24.230001,20.889351,-138.825043,-0.003579,0.001167,0.029642,92.920471,4.733594,0.296418,-138.825043,0.030726,0.000000
24.590002,20.815994,-138.869522,-0.003553,0.001185,0.030110,92.594170,4.716971,0.301096,-138.869522,0.031333,0.000000
24.950001,21.577126,-138.869522,-0.003535,0.001214,0.030838,95.979851,4.889446,0.308378,-138.869522,0.031931,0.000000
25.310001,21.693306,-138.958496,-0.003501,0.001237,0.031412,96.496643,4.915773,0.314116,-138.958496,0.032529,0.000000
25.670002,22.402306,-138.958496,-0.003484,0.001267,0.032182,99.650429,5.076435,0.321822,-138.958496,0.033128,0.000000
26.030001,22.207550,-139.047455,-0.003436,0.001292,0.032807,98.784119,5.032303,0.328075,-139.047455,0.033726,0.000000
26.390001,22.009453,-139.047455,-0.003436,0.001311,0.033301,97.902939,4.987413,0.333010,-139.047455,0.034324,0.000000
26.750002,22.519974,-139.136414,-0.003397,0.001339,0.034003,100.173843,5.103099,0.340035,-139.136414,0.034932,0.000000
27.110001,22.180740,-139.225372,-0.003367,0.001354,0.034394,98.664864,5.026227,0.343941,-139.225372,0.035530,0.000000
27.470001,22.371765,-139.225372,-0.003354,0.001377,0.034975,99.514580,5.069514,0.349755,-139.225372,0.036129,0.000000
27.830002,23.184654,-139.269852,-0.003324,0.001408,0.035755,103.130493,5.253718,0.357551,-139.269852,0.036727,0.000000
28.190001,23.077042,-139.358826,-0.003303,0.001428,0.036267,102.651810,5.229332,0.362669,-139.358826,0.037325,0.000000
28.550001,23.209602,-139.358826,-0.003268,0.001450,0.036822,103.241470,5.259371,0.368225,-139.358826,0.037932,0.000000
28.910002,23.663528,-139.492264,-0.003238,0.001477,0.037525,105.260635,5.362232,0.375250,-139.492264,0.038530,0.000000
29.270000,23.516815,-139.492264,-0.003229,0.001498,0.038037,104.608017,5.328986,0.380367,-139.492264,0.039130,0.000000
29.630001,24.141281,-139.536743,-0.003199,0.001523,0.038686,107.385780,5.470492,0.386862,-139.536743,0.039728,0.000000
29.990002,24.455940,-139.536743,-0.003169,0.001549,0.039346,108.785454,5.541795,0.393463,-139.536743,0.040326,0.000000
30.350002,24.658882,-139.625702,-0.003139,0.001573,0.039944,109.688187,5.587783,0.399443,-139.625702,0.040933,0.000000
30.710001,24.841713,-139.670181,-0.003109,0.001597,0.040560,110.501457,5.629213,0.405604,-139.670181,0.041531,0.000000
31.070002,24.871132,-139.759155,-0.003087,0.001615,0.041019,110.632317,5.635879,0.410192,-139.759155,0.042130,0.000000
31.430002,24.605629,-139.803635,-0.003074,0.001635,0.041523,109.451302,5.575716,0.415233,-139.803635,0.042728,0.000000
31.790001,25.941330,-139.848114,-0.003040,0.001669,0.042398,115.392799,5.878390,0.423984,-139.848114,0.043326,0.000000
32.150002,25.759613,-139.892593,-0.003009,0.001690,0.042936,114.584480,5.837212,0.429358,-139.892593,0.043934,0.000000
32.510002,26.006126,-139.981552,-0.002988,0.001712,0.043473,115.681030,5.893073,0.434733,-139.981552,0.044532,0.000000
32.870003,26.341255,-139.937073,-0.002958,0.001737,0.044108,117.171753,5.969014,0.441077,-139.937073,0.045131,0.000000
33.230003,26.467491,-140.070511,-0.002940,0.001760,0.044706,117.733284,5.997619,0.447057,-140.070511,0.045729,0.000000
33.590000,26.845451,-140.114990,-0.002915,0.001783,0.045287,119.414528,6.083266,0.452870,-140.114990,0.046327,0.000000
33.950001,27.101273,-140.114990,-0.002871,0.001810,0.045980,120.552483,6.141236,0.459804,-140.114990,0.046925,0.000000
34.310001,27.317619,-140.248444,-0.002876,0.001834,0.046588,121.514839,6.190261,0.465875,-140.248444,0.047532,0.000000
34.670002,27.516838,-140.248444,-0.002837,0.001855,0.047125,122.401009,6.235404,0.471250,-140.248444,0.048130,0.000000
35.030003,27.663925,-140.337402,-0.002815,0.001877,0.047672,123.055283,6.268735,0.476715,-140.337402,0.048730,0.000000
35.390003,27.772659,-140.381882,-0.002798,0.001898,0.048218,123.538956,6.293375,0.482180,-140.381882,0.049328,0.000000
35.750000,27.902245,-140.381882,-0.002768,0.001919,0.048746,124.115379,6.322739,0.487464,-140.381882,0.049926,0.000000
36.110001,28.278709,-140.515320,-0.002764,0.001943,0.049354,125.789986,6.408047,0.493535,-140.515320,0.050533,0.000000
36.470001,28.615334,-140.559799,-0.002729,0.001965,0.049900,127.287361,6.484327,0.499001,-140.559799,0.051131,0.000000
36.830002,29.018242,-140.515320,-0.002695,0.001990,0.050559,129.079590,6.575628,0.505586,-140.515320,0.051730,0.000000
37.190002,29.265503,-140.648773,-0.002682,0.002017,0.051244,130.179459,6.631658,0.512444,-140.648773,0.052328,0.000000
37.550003,29.472542,-140.648773,-0.002652,0.002039,0.051791,131.100418,6.678574,0.517910,-140.648773,0.052926,0.000000
37.910004,30.106316,-140.737732,-0.002608,0.002064,0.052433,133.919586,6.822189,0.524329,-140.737732,0.053534,0.000000
38.270000,29.095322,-140.782211,-0.002608,0.002073,0.052649,129.422455,6.593094,0.526494,-140.782211,0.054132,0.000000
38.630001,29.975983,-140.782211,-0.002578,0.002101,0.053378,133.339828,6.792655,0.533776,-140.782211,0.054731,0.000000
38.990002,30.751266,-140.960129,-0.002548,0.002132,0.054150,136.788467,6.968337,0.541497,-140.960129,0.055329,0.000000
39.350002,30.546463,-140.871170,-0.002518,0.002152,0.054652,135.877457,6.921927,0.546524,-140.871170,0.055927,0.000000
39.710003,31.271095,-141.093582,-0.002492,0.002183,0.055450,139.100784,7.086132,0.554502,-141.093582,0.056534,0.000000
40.070004,30.648117,-141.049103,-0.002470,0.002195,0.055762,136.329636,6.944963,0.557621,-141.049103,0.057132,0.000000
40.430000,31.217850,-141.049103,-0.002449,0.002223,0.056457,138.863937,7.074066,0.564570,-141.049103,0.057732,0.000000
40.790001,32.625420,-141.138062,-0.002427,0.002257,0.057332,145.125122,7.393026,0.573321,-141.138062,0.058330,0.000000
41.150002,32.088455,-141.182541,-0.002384,0.002277,0.057844,142.736572,7.271348,0.578438,-141.182541,0.058928,0.000000
41.510002,33.032417,-141.227020,-0.002354,0.002305,0.058555,146.935532,7.485253,0.585554,-141.227020,0.059526,0.000000
41.870003,32.617226,-141.271500,-0.002363,0.002323,0.058997,145.088669,7.391169,0.589974,-141.271500,0.060133,0.000000
42.230003,32.090317,-141.315979,-0.002315,0.002337,0.059353,142.744858,7.271770,0.593532,-141.315979,0.060732,0.000000
42.590000,33.408516,-141.449417,-0.002311,0.002371,0.060212,148.608505,7.570478,0.602116,-141.449417,0.061330,0.000000
42.950001,33.733597,-141.449417,-0.002276,0.002397,0.060896,150.054535,7.644142,0.608959,-141.449417,0.061928,0.000000
43.310001,34.649635,-141.493912,-0.002246,0.002425,0.061591,154.129272,7.851719,0.615908,-141.493912,0.062526,0.000000
43.670002,34.286942,-141.582870,-0.002238,0.002439,0.061947,152.515930,7.769532,0.619466,-141.582870,0.063134,0.000000
44.030003,34.924446,-141.582870,-0.002216,0.002465,0.062605,155.351700,7.913992,0.626052,-141.582870,0.063733,0.000000
44.390003,35.197395,-141.627350,-0.002190,0.002488,0.063187,156.565826,7.975844,0.631866,-141.627350,0.064331,0.000000
44.750004,36.050873,-141.760788,-0.002182,0.002511,0.063785,160.362289,8.169245,0.637846,-141.760788,0.064929,0.000000
45.110001,36.911049,-141.805267,-0.002147,0.002541,0.064548,164.188553,8.364162,0.645476,-141.805267,0.065527,0.000000
45.470001,37.157188,-141.805267,-0.002134,0.002562,0.065068,165.283432,8.419939,0.650684,-141.805267,0.066134,0.000000
45.830002,37.195541,-141.760788,-0.002117,0.002582,0.065571,165.454025,8.428631,0.655710,-141.760788,0.066732,0.000000
46.190002,37.493813,-141.894241,-0.002100,0.002602,0.066099,166.780807,8.496220,0.660994,-141.894241,0.067332,0.000000
46.550003,38.424370,-141.938721,-0.002078,0.002628,0.066741,170.920135,8.707087,0.667413,-141.938721,0.067930,0.000000
46.910004,39.395889,-141.938721,-0.002052,0.002654,0.067401,175.241669,8.927236,0.674014,-141.938721,0.068528,0.000000
47.270000,40.794525,-142.027679,-0.002044,0.002687,0.068242,181.463104,9.244171,0.682417,-142.027679,0.069135,0.000000
47.630001,40.644829,-142.027679,-0.002013,0.002705,0.068719,180.797226,9.210250,0.687186,-142.027679,0.069733,0.000000
47.990002,41.084976,-142.116638,-0.001996,0.002727,0.069265,182.755096,9.309989,0.692651,-142.116638,0.070332,0.000000
48.350002,41.803650,-142.161118,-0.001979,0.002750,0.069837,185.951920,9.472842,0.698374,-142.161118,0.070930,0.000000
48.710003,42.128365,-142.161118,-0.001975,0.002772,0.070402,187.396332,9.546424,0.704021,-142.161118,0.071528,0.000000
49.070004,43.703499,-142.250076,-0.001949,0.002801,0.071156,194.402878,9.903354,0.711560,-142.250076,0.072126,0.000000
49.430004,43.719505,-142.294556,-0.001940,0.002822,0.071677,194.474075,9.906982,0.716768,-142.294556,0.072734,0.000000
49.790001,44.381584,-142.428009,-0.001923,0.002845,0.072266,197.419144,10.057011,0.722658,-142.428009,0.073333,0.000000
50.150002,45.600365,-142.428009,-0.001906,0.002872,0.072952,202.840546,10.333191,0.729516,-142.428009,0.073931,0.000000
50.510002,45.660316,-142.472488,-0.001884,0.002890,0.073410,203.107239,10.346776,0.734103,-142.472488,0.074529,0.000000
50.870003,46.058380,-142.561447,-0.001880,0.002908,0.073871,204.877914,10.436977,0.738706,-142.561447,0.075127,0.000000
51.230003,47.494621,-142.472488,-0.001858,0.002940,0.074685,211.266632,10.762435,0.746851,-142.472488,0.075734,0.000000
51.590004,48.199150,-142.650406,-0.001837,0.002963,0.075250,214.400528,10.922084,0.752498,-142.650406,0.076334,0.000000
51.950001,49.145721,-142.650406,-0.001828,0.002988,0.075883,218.611084,11.136580,0.758826,-142.650406,0.076932,0.000000
52.310001,49.504318,-142.650406,-0.001819,0.003006,0.076359,220.206207,11.217839,0.763595,-142.650406,0.077530,0.000000
52.670002,50.070694,-142.872818,-0.001819,0.003027,0.076888,222.725571,11.346182,0.768879,-142.872818,0.078128,0.000000
53.030003,51.628326,-142.739365,-0.001794,0.003058,0.077677,229.654266,11.699146,0.776766,-142.739365,0.078735,0.000000
53.390003,52.317589,-142.917297,-0.001776,0.003083,0.078319,232.720261,11.855335,0.783186,-142.917297,0.079334,0.000000
53.750004,53.248894,-142.872818,-0.001759,0.003109,0.078979,236.862915,12.066372,0.789786,-142.872818,0.079932,0.000000
54.110004,54.002205,-142.961777,-0.001746,0.003132,0.079551,240.213806,12.237075,0.795509,-142.961777,0.080530,0.000000
54.470001,54.593903,-143.006256,-0.001720,0.003149,0.079993,242.845810,12.371156,0.799930,-143.006256,0.081128,0.000000
54.830002,56.172760,-143.006256,-0.001716,0.003180,0.080773,249.868912,12.728930,0.807727,-143.006256,0.081736,0.000000
55.190002,56.936867,-143.050735,-0.001699,0.003203,0.081346,253.267838,12.902079,0.813465,-143.050735,0.082335,0.000000
55.550003,57.283920,-143.184189,-0.001690,0.003220,0.081796,254.811600,12.980721,0.817961,-143.184189,0.082933,0.000000
55.910004,58.639359,-143.139694,-0.001694,0.003248,0.082508,260.840881,13.287868,0.825077,-143.139694,0.083531,0.000000
56.270004,59.264198,-143.228668,-0.001673,0.003271,0.083071,263.620331,13.429460,0.830709,-143.228668,0.084129,0.000000
56.630001,60.322479,-143.317627,-0.001669,0.003295,0.083687,268.327789,13.669270,0.836871,-143.317627,0.084729,0.000000
56.990002,60.929443,-143.317627,-0.001656,0.003315,0.084199,271.027710,13.806809,0.841988,-143.317627,0.085334,0.000000
57.350002,61.477951,-143.406586,-0.001643,0.003337,0.084754,273.467590,13.931103,0.847544,-143.406586,0.085934,0.000000
57.710003,62.844185,-143.451065,-0.001638,0.003362,0.085404,279.544891,14.240696,0.854039,-143.451065,0.086532,0.000000
58.070004,64.091637,-143.495544,-0.001617,0.003385,0.085985,285.093842,14.523373,0.859852,-143.495544,0.087130,0.000000
58.430004,64.657265,-143.584503,-0.001600,0.003405,0.086497,287.609863,14.651546,0.864970,-143.584503,0.087728,0.000000
58.790001,65.624687,-143.584503,-0.001591,0.003431,0.087148,291.913177,14.870767,0.871480,-143.584503,0.088335,0.000000
59.150002,66.866188,-143.673477,-0.001582,0.003447,0.087564,297.435669,15.152095,0.875643,-143.673477,0.087790,0.000000
59.510002,65.281364,-143.717957,-0.001582,0.003446,0.087537,290.386017,14.792969,0.875371,-143.717957,294.500488,0.000000
59.870003,65.304085,-143.762436,-0.001561,0.003463,0.087962,290.487091,14.798118,0.879625,-143.762436,294.500488,0.000000
60.230003,65.391960,-143.851395,-0.001552,0.003477,0.088309,290.877960,14.818030,0.883092,-143.851395,294.500488,0.000000
60.590004,64.606621,-143.851395,-0.001561,0.003480,0.088397,287.384613,14.640070,0.883970,-143.851395,294.500488,0.000000
60.950005,65.028893,-143.984833,-0.001531,0.003493,0.088726,289.262970,14.735758,0.887255,-143.984833,294.500488,0.000000
61.310001,64.087532,-143.895874,-0.001544,0.003493,0.088726,285.075592,14.522443,0.887255,-143.895874,294.500488,0.000000
61.670002,64.357506,-144.029312,-0.001483,0.003494,0.088744,286.276489,14.583619,0.887437,-144.029312,294.500488,0.000000
62.030003,65.931160,-144.073807,-0.001483,0.003425,0.086983,293.276459,14.940214,0.869829,-144.073807,294.500488,0.000000
62.390003,64.986824,-144.118286,-0.001479,0.003484,0.088483,289.075836,14.726225,0.884833,-144.118286,294.500488,0.000000
62.750004,65.083641,-144.207245,-0.001470,0.003530,0.089654,289.506500,14.748164,0.896536,-144.207245,294.500488,0.000000
63.110004,64.855003,-144.207245,-0.001475,0.003536,0.089802,288.489471,14.696354,0.898019,-144.207245,294.500488,0.000000
63.470001,65.277641,-144.251724,-0.001475,0.003547,0.090088,290.369446,14.792125,0.900881,-144.251724,294.500488,0.000000
63.830002,65.586342,-144.296204,-0.001475,0.003558,0.090382,291.742615,14.862078,0.903818,-144.296204,294.500488,0.000000
64.190002,65.084373,-144.340683,-0.001479,0.003558,0.090382,289.509766,14.748329,0.903818,-144.340683,294.500488,0.000000
64.550003,64.487831,-144.385162,-0.001475,0.003559,0.090391,286.856201,14.613152,0.903909,-144.385162,294.500488,0.000000
64.910004,67.074333,-144.429642,-0.001483,0.003440,0.087381,298.361542,15.199262,0.873811,-144.429642,294.500488,0.000000
65.270004,66.182503,-144.518616,-0.001466,0.003391,0.086125,294.394470,14.997169,0.861245,-144.518616,294.500488,0.000000
65.630005,65.565117,-144.563095,-0.001470,0.003422,0.086930,291.648193,14.857267,0.869300,-144.563095,294.500488,0.000000
65.990005,65.102623,-144.563095,-0.001466,0.003572,0.090721,289.590942,14.752465,0.907209,-144.563095,294.500488,0.000000
66.350006,65.037086,-144.652054,-0.001457,0.003587,0.091102,289.299408,14.737615,0.911024,-144.652054,294.500488,0.000000
66.710007,65.356590,-144.696533,-0.001470,0.003597,0.091370,290.720642,14.810016,0.913704,-144.696533,294.500488,0.000000
67.070000,65.011391,-144.696533,-0.001453,0.003597,0.091370,289.185120,14.731791,0.913704,-144.696533,294.500488,0.000000
67.430000,64.965965,-144.829971,-0.001466,0.003602,0.091493,288.983032,14.721498,0.914930,-144.829971,294.500488,0.000000
67.790001,64.623009,-144.829971,-0.001470,0.003602,0.091493,287.457489,14.643784,0.914930,-144.829971,294.500488,0.000000
68.150002,65.946053,-144.829971,-0.001444,0.003611,0.091717,293.342682,14.943589,0.917171,-144.829971,294.500488,0.000000
68.510002,65.478722,-144.963425,-0.001457,0.003611,0.091717,291.263885,14.837690,0.917171,-144.963425,294.500488,0.000000
68.870003,65.040062,-144.963425,-0.001449,0.003611,0.091717,289.312653,14.738289,0.917171,-144.963425,294.500488,0.000000
69.230003,64.668434,-145.052383,-0.001457,0.003611,0.091726,287.659576,14.654077,0.917262,-145.052383,294.500488,0.000000
69.590004,66.185860,-145.052383,-0.001444,0.003627,0.092133,294.409393,14.997931,0.921334,-145.052383,294.500488,0.000000
69.950005,65.780708,-145.096863,-0.001449,0.003627,0.092126,292.607208,14.906121,0.921259,-145.096863,294.500488,0.000000
70.310005,65.439995,-145.185822,-0.001449,0.003627,0.092133,291.091644,14.828915,0.921334,-145.185822,294.500488,0.000000
70.670006,65.091454,-145.230301,-0.001436,0.003627,0.092133,289.541260,14.749934,0.921334,-145.230301,294.500488,0.000000
71.030006,64.765999,-145.274780,-0.001444,0.003627,0.092133,288.093536,14.676186,0.921334,-145.274780,294.500488,0.000000
71.390007,65.944939,-145.319260,-0.001444,0.003660,0.092959,293.337738,14.943336,0.929585,-145.319260,294.500488,0.000000
71.750000,66.200752,-145.363754,-0.001418,0.003618,0.091891,294.475647,15.001305,0.918912,-145.363754,294.500488,0.000000
72.110001,65.861885,-145.452713,-0.001427,0.003618,0.091891,292.968292,14.924516,0.918912,-145.452713,294.500488,0.000000
72.470001,65.595268,-145.452713,-0.001427,0.003618,0.091891,291.782318,14.864100,0.918912,-145.452713,294.500488,0.000000
72.830002,65.296257,-145.497192,-0.001423,0.003618,0.091891,290.452271,14.796344,0.918912,-145.497192,294.500488,0.000000
73.190002,65.030388,-145.541672,-0.001418,0.003619,0.091926,289.269623,14.736096,0.919260,-145.541672,294.500488,0.000000
73.550003,65.592293,-145.586151,-0.001406,0.003657,0.092880,291.769104,14.863425,0.928798,-145.586151,294.500488,0.000000
73.910004,65.428444,-145.719589,-0.001423,0.003657,0.092880,291.040253,14.826298,0.928798,-145.719589,294.500488,0.000000
74.270004,65.253059,-145.675110,-0.001423,0.003657,0.092889,290.260101,14.786554,0.928889,-145.675110,294.500488,0.000000
74.630005,65.062782,-145.764084,-0.001423,0.003657,0.092889,289.413696,14.743437,0.928889,-145.764084,294.500488,0.000000
74.990005,64.939903,-145.897522,-0.001414,0.003659,0.092949,288.867126,14.715592,0.929495,-145.897522,294.500488,0.000000
75.350006,64.875099,-145.808563,-0.001423,0.003660,0.092975,288.578857,14.700908,0.929752,-145.808563,294.500488,0.000000
75.710007,65.379295,-145.853043,-0.001423,0.003669,0.093184,290.821625,14.815161,0.931841,-145.853043,294.500488,0.000000
76.070007,65.267586,-145.986481,-0.001427,0.003669,0.093184,290.324707,14.789846,0.931841,-145.986481,294.500488,0.000000
76.430000,65.116035,-145.897522,-0.001423,0.003669,0.093184,289.650604,14.755505,0.931841,-145.897522,294.500488,0.000000
76.790001,64.972664,-146.119919,-0.001410,0.003669,0.093201,289.012848,14.723016,0.932008,-146.119919,294.500488,0.000000
77.150002,65.848488,-146.075439,-0.001410,0.003681,0.093487,292.908691,14.921480,0.934869,-146.075439,294.500488,0.000000
77.510002,65.762093,-146.164398,-0.001414,0.003681,0.093487,292.524384,14.901904,0.934869,-146.164398,294.500488,0.000000
77.870003,65.603462,-146.208893,-0.001397,0.003681,0.093487,291.818787,14.865956,0.934869,-146.208893,294.500488,0.000000
78.230003,65.496590,-146.208893,-0.001414,0.003681,0.093487,291.343384,14.841740,0.934869,-146.208893,294.500488,0.000000
78.590004,65.323067,-146.342331,-0.001406,0.003681,0.093487,290.571503,14.802419,0.934869,-146.342331,294.500488,0.000000
78.950005,65.181938,-146.342331,-0.001406,0.003681,0.093496,289.943756,14.770438,0.934960,-146.342331,294.500488,0.000000
79.310005,65.037086,-146.475769,-0.001397,0.003681,0.093496,289.299408,14.737615,0.934960,-146.475769,294.500488,0.000000
79.670006,64.934685,-146.475769,-0.001406,0.003682,0.093522,288.843903,14.714410,0.935217,-146.475769,294.500488,0.000000
80.030006,64.812553,-146.475769,-0.001410,0.003682,0.093522,288.300629,14.686734,0.935217,-146.475769,294.500488,0.000000
80.390007,64.702690,-146.564728,-0.001406,0.003682,0.093522,287.811951,14.661839,0.935217,-146.564728,294.500488,0.000000
80.750008,64.560448,-146.609207,-0.001406,0.003682,0.093522,287.179199,14.629606,0.935217,-146.609207,294.500488,0.000000
81.110001,66.402580,-146.609207,-0.001384,0.003671,0.093236,295.373444,15.047040,0.932356,-146.609207,294.500488,0.000000
81.470001,66.262199,-146.742661,-0.001388,0.003671,0.093236,294.748993,15.015229,0.932356,-146.742661,294.500488,0.000000
81.830002,66.117714,-146.653702,-0.001384,0.003671,0.093236,294.106293,14.982488,0.932356,-146.653702,294.500488,0.000000
82.190002,65.918114,-146.787140,-0.001380,0.003671,0.093245,293.218414,14.937258,0.932447,-146.787140,294.500488,0.000000
82.550003,65.848488,-146.831619,-0.001380,0.003671,0.093245,292.908691,14.921480,0.932447,-146.831619,294.500488,0.000000
82.910004,65.670128,-146.876099,-0.001375,0.003671,0.093252,292.115326,14.881064,0.932522,-146.876099,294.500488,0.000000
83.270004,65.550224,-146.965057,-0.001384,0.003672,0.093261,291.581970,14.853893,0.932613,-146.965057,294.500488,0.000000
83.630005,65.415413,-146.965057,-0.001397,0.003672,0.093261,290.982300,14.823344,0.932613,-146.965057,294.500488,0.000000
83.990005,65.303337,-147.009537,-0.001380,0.003673,0.093305,290.483765,14.797948,0.933052,-147.009537,294.500488,0.000000
84.350006,65.204277,-147.142990,-0.001384,0.003674,0.093313,290.043121,14.775500,0.933128,-147.142990,294.500488,0.000000
84.710007,65.392708,-147.054031,-0.001380,0.003700,0.093982,290.881287,14.818199,0.939820,-147.054031,294.500488,0.000000
85.070007,65.325676,-147.187469,-0.001375,0.003700,0.093982,290.583130,14.803010,0.939820,-147.187469,294.500488,0.000000
85.430000,65.305199,-147.276428,-0.001393,0.003701,0.094008,290.492035,14.798369,0.940077,-147.276428,294.500488,0.000000
85.790001,65.266090,-147.276428,-0.001388,0.003702,0.094043,290.318085,14.789508,0.940425,-147.276428,294.500488,0.000000
86.150002,65.194221,-147.320908,-0.001388,0.003702,0.094043,289.998383,14.773222,0.940425,-147.320908,294.500488,0.000000
86.510002,65.177849,-147.231949,-0.001384,0.003704,0.094085,289.925537,14.769512,0.940849,-147.231949,294.500488,0.000000
86.870003,65.123100,-147.409866,-0.001393,0.003704,0.094085,289.682007,14.757106,0.940849,-147.409866,294.500488,0.000000
87.230003,65.302956,-147.409866,-0.001384,0.003711,0.094259,290.482056,14.797861,0.942590,-147.409866,294.500488,0.000000
87.590004,65.416908,-147.498840,-0.001384,0.003711,0.094259,290.988953,14.823683,0.942590,-147.498840,294.500488,0.000000
87.950005,65.352852,-147.543320,-0.001401,0.003711,0.094259,290.704010,14.809168,0.942590,-147.543320,294.500488,0.000000
88.310005,65.304451,-147.543320,-0.001375,0.003711,0.094259,290.488708,14.798200,0.942590,-147.543320,294.500488,0.000000
88.670006,65.248222,-147.632278,-0.001388,0.003711,0.094259,290.238586,14.785459,0.942590,-147.632278,294.500488,0.000000
89.030006,65.175606,-147.632278,-0.001397,0.003711,0.094259,289.915588,14.769003,0.942590,-147.632278,294.500488,0.000000
89.390007,65.113792,-147.721237,-0.001371,0.003713,0.094320,289.640625,14.754995,0.943196,-147.721237,294.500488,0.000000
89.750008,65.146187,-147.810196,-0.001380,0.003713,0.094320,289.784698,14.762337,0.943196,-147.810196,294.500488,0.000000
90.110001,65.095924,-147.810196,-0.001384,0.003714,0.094329,289.561127,14.750948,0.943287,-147.810196,294.500488,0.000000
90.470001,65.049004,-147.899155,-0.001388,0.003714,0.094329,289.352417,14.740315,0.943287,-147.899155,294.500488,0.000000
90.830002,65.485802,-147.899155,-0.001401,0.003720,0.094492,291.295380,14.839295,0.944922,-147.899155,294.500488,0.000000
91.190002,65.453407,-147.899155,-0.001380,0.003720,0.094485,291.151306,14.831954,0.944846,-147.899155,294.500488,0.000000
91.550003,65.393822,-147.988129,-0.001380,0.003720,0.094485,290.886261,14.818452,0.944846,-147.988129,294.500488,0.000000
91.910004,65.335732,-147.988129,-0.001375,0.003720,0.094492,290.627838,14.805288,0.944922,-147.988129,294.500488,0.000000
92.270004,65.277641,-148.121567,-0.001375,0.003720,0.094492,290.369446,14.792125,0.944922,-148.121567,294.500488,0.000000
92.630005,65.217690,-148.166046,-0.001388,0.003720,0.094492,290.102783,14.778540,0.944922,-148.166046,294.500488,0.000000
92.990005,65.161095,-148.077087,-0.001375,0.003721,0.094501,289.851013,14.765716,0.945013,-148.077087,294.500488,0.000000
93.350006,65.119011,-148.255005,-0.001375,0.003721,0.094510,289.663818,14.756179,0.945103,-148.255005,294.500488,0.000000
93.710007,65.042671,-148.255005,-0.001380,0.003721,0.094510,289.324249,14.738880,0.945103,-148.255005,294.500488,0.000000
94.070007,65.012886,-148.343979,-0.001375,0.003721,0.094510,289.191772,14.732131,0.945103,-148.343979,294.500488,0.000000
94.430008,64.976387,-148.388458,-0.001367,0.003722,0.094545,289.029419,14.723860,0.945452,-148.388458,294.500488,0.000000
94.790001,64.965965,-148.388458,-0.001375,0.003722,0.094545,288.983032,14.721498,0.945452,-148.388458,294.500488,0.000000
95.150002,64.903786,-148.477417,-0.001380,0.003722,0.094545,288.706451,14.707409,0.945452,-148.477417,294.500488,0.000000
95.510002,64.847923,-148.521896,-0.001371,0.003722,0.094545,288.457977,14.694750,0.945452,-148.521896,294.500488,0.000000
95.870003,64.782005,-148.610855,-0.001362,0.003722,0.094545,288.164764,14.679812,0.945452,-148.610855,294.500488,0.000000
96.230003,65.834343,-148.610855,-0.001384,0.003732,0.094787,292.845795,14.918276,0.947874,-148.610855,294.500488,0.000000
96.590004,65.784431,-148.655334,-0.001371,0.003732,0.094787,292.623779,14.906965,0.947874,-148.655334,294.500488,0.000000
96.950005,65.758369,-148.788788,-0.001371,0.003732,0.094787,292.507843,14.901059,0.947874,-148.788788,294.500488,0.000000
97.310005,65.627296,-148.744293,-0.001367,0.003732,0.094787,291.924805,14.871358,0.947874,-148.744293,294.500488,0.000000
97.670006,65.594536,-148.788788,-0.001380,0.003732,0.094787,291.779053,14.863934,0.947874,-148.788788,294.500488,0.000000
98.030006,65.541649,-148.877747,-0.001367,0.003732,0.094787,291.543823,14.851950,0.947874,-148.877747,294.500488,0.000000
98.390007,65.501442,-148.833267,-0.001375,0.003732,0.094796,291.364960,14.842839,0.947965,-148.833267,294.500488,0.000000
98.750008,65.406853,-148.966705,-0.001358,0.003732,0.094796,290.944214,14.821404,0.947965,-148.966705,294.500488,0.000000
99.110008,65.350990,-148.966705,-0.001362,0.003732,0.094796,290.695709,14.808746,0.947965,-148.966705,294.500488,0.000000
99.470001,65.297371,-149.011185,-0.001371,0.003732,0.094796,290.457214,14.796596,0.947965,-149.011185,294.500488,0.000000
99.830002,65.250084,-149.144623,-0.001371,0.003732,0.094796,290.246857,14.785880,0.947965,-149.144623,294.500488,0.000000
100.190002,65.216576,-149.100143,-0.001375,0.003732,0.094796,290.097809,14.778287,0.947965,-149.100143,294.500488,0.000000
100.550003,65.132042,-149.189117,-0.001362,0.003732,0.094796,289.721802,14.759132,0.947965,-149.189117,294.500488,0.000000
100.910004,65.082146,-149.233597,-0.001388,0.003733,0.094806,289.499847,14.747825,0.948056,-149.233597,294.500488,0.000000
101.270004,65.047508,-149.278076,-0.001354,0.003733,0.094813,289.345764,14.739976,0.948131,-149.278076,294.500488,0.000000
101.630005,65.282112,-149.411514,-0.001371,0.003738,0.094943,290.389343,14.793138,0.949433,-149.411514,294.500488,0.000000
101.990005,65.302223,-149.322556,-0.001362,0.003738,0.094943,290.478790,14.797695,0.949433,-149.322556,294.500488,0.000000
102.350006,65.298119,-149.455994,-0.001371,0.003738,0.094943,290.460541,14.796765,0.949433,-149.455994,294.500488,0.000000
102.710007,65.281364,-149.500473,-0.001367,0.003738,0.094943,290.386017,14.792969,0.949433,-149.500473,294.500488,0.000000
103.070007,65.248589,-149.455994,-0.001362,0.003738,0.094943,290.240204,14.785542,0.949433,-149.455994,294.500488,0.000000
103.430008,65.194603,-149.589432,-0.001371,0.003738,0.094943,290.000092,14.773308,0.949433,-149.589432,294.500488,0.000000
103.790009,65.146935,-149.589432,-0.001358,0.003738,0.094952,289.788025,14.762506,0.949524,-149.589432,294.500488,0.000000
104.150002,65.116768,-149.633926,-0.001362,0.003738,0.094952,289.653839,14.755671,0.949524,-149.633926,294.500488,0.000000
104.510002,65.090706,-149.678406,-0.001367,0.003739,0.094962,289.537933,14.749764,0.949615,-149.678406,294.500488,0.000000
104.870003,65.070976,-149.722885,-0.001380,0.003740,0.094987,289.450165,14.745294,0.949872,-149.722885,294.500488,0.000000
105.230003,65.281731,-149.811844,-0.001375,0.003743,0.095066,290.387634,14.793052,0.950660,-149.811844,294.500488,0.000000
105.590004,65.266472,-149.856323,-0.001367,0.003743,0.095066,290.319763,14.789594,0.950660,-149.856323,294.500488,0.000000
105.950005,65.287697,-149.900803,-0.001362,0.003743,0.095066,290.414185,14.794403,0.950660,-149.900803,294.500488,0.000000
106.310005,65.247856,-149.945282,-0.001362,0.003743,0.095066,290.236969,14.785376,0.950660,-149.945282,294.500488,0.000000
106.670006,65.224770,-149.945282,-0.001358,0.003743,0.095066,290.134277,14.780144,0.950660,-149.945282,294.500488,0.000000
107.030006,65.192360,-150.078735,-0.001358,0.003743,0.095066,289.990112,14.772799,0.950660,-150.078735,294.500488,0.000000
107.390007,65.143959,-150.034241,-0.001354,0.003743,0.095074,289.774811,14.761832,0.950735,-150.034241,294.500488,0.000000
107.750008,65.125343,-150.167694,-0.001354,0.003743,0.095083,289.691986,14.757614,0.950826,-150.167694,294.500488,0.000000
108.110008,65.085121,-150.167694,-0.001350,0.003743,0.095083,289.513092,14.748499,0.950826,-150.167694,294.500488,0.000000
108.470009,65.076927,-150.167694,-0.001371,0.003743,0.095083,289.476624,14.746643,0.950826,-150.167694,294.500488,0.000000
108.830002,65.026283,-150.256653,-0.001354,0.003743,0.095083,289.251343,14.735167,0.950826,-150.256653,294.500488,0.000000
109.190002,65.018089,-150.301132,-0.001371,0.003743,0.095083,289.214905,14.733310,0.950826,-150.301132,294.500488,0.000000
109.550003,64.977135,-150.345612,-0.001358,0.003743,0.095083,289.032745,14.724030,0.950826,-150.345612,294.500488,0.000000
109.910004,64.952553,-150.390091,-0.001362,0.003744,0.095092,288.923370,14.718459,0.950917,-150.390091,294.500488,0.000000
110.270004,64.913094,-150.390091,-0.001350,0.003744,0.095092,288.747864,14.709517,0.950917,-150.390091,294.500488,0.000000
110.630005,64.877342,-150.568024,-0.001362,0.003744,0.095092,288.588837,14.701416,0.950917,-150.568024,294.500488,0.000000
110.990005,64.840096,-150.568024,-0.001380,0.003744,0.095092,288.423157,14.692976,0.950917,-150.568024,294.500488,0.000000
111.350006,64.799141,-150.479065,-0.001358,0.003744,0.095092,288.240967,14.683695,0.950917,-150.479065,294.500488,0.000000
111.710007,65.794121,-150.656982,-0.001362,0.003756,0.095394,292.666870,14.909161,0.953945,-150.656982,294.500488,0.000000
112.070007,65.838799,-150.656982,-0.001362,0.003756,0.095394,292.865601,14.919285,0.953945,-150.656982,294.500488,0.000000
112.430008,65.868599,-150.745941,-0.001367,0.003756,0.095394,292.998169,14.926038,0.953945,-150.745941,294.500488,0.000000
112.790009,65.855186,-150.745941,-0.001358,0.003756,0.095394,292.938507,14.922998,0.953945,-150.745941,294.500488,0.000000
113.150009,65.849602,-150.790421,-0.001358,0.003756,0.095394,292.913666,14.921733,0.953945,-150.790421,294.500488,0.000000
113.510002,65.787788,-150.834900,-0.001362,0.003756,0.095394,292.638702,14.907725,0.953945,-150.834900,294.500488,0.000000
113.870003,65.758369,-150.879379,-0.001367,0.003756,0.095394,292.507843,14.901059,0.953945,-150.879379,294.500488,0.000000
114.230003,65.791512,-150.968353,-0.001367,0.003756,0.095394,292.655273,14.908570,0.953945,-150.968353,294.500488,0.000000
114.590004,65.751671,-151.012833,-0.001362,0.003756,0.095394,292.478027,14.899541,0.953945,-151.012833,294.500488,0.000000
114.950005,65.674583,-151.012833,-0.001350,0.003756,0.095394,292.135132,14.882073,0.953945,-151.012833,294.500488,0.000000
115.310005,65.608681,-151.101791,-0.001367,0.003756,0.095394,291.841980,14.867140,0.953945,-151.101791,294.500488,0.000000
115.670006,65.593040,-151.101791,-0.001350,0.003756,0.095394,291.772430,14.863595,0.953945,-151.101791,294.500488,0.000000
116.030006,65.573677,-151.146271,-0.001362,0.003756,0.095394,291.686279,14.859208,0.953945,-151.146271,294.500488,0.000000
116.390007,65.550957,-151.324188,-0.001362,0.003756,0.095394,291.585205,14.854059,0.953945,-151.324188,294.500488,0.000000
116.750008,65.530113,-151.279709,-0.001350,0.003756,0.095394,291.492493,14.849336,0.953945,-151.279709,294.500488,0.000000
117.110008,65.500694,-151.368683,-0.001354,0.003756,0.095394,291.361633,14.842669,0.953945,-151.368683,294.500488,0.000000
117.470009,65.463829,-151.368683,-0.001358,0.003756,0.095394,291.197662,14.834315,0.953945,-151.368683,294.500488,0.000000
117.830002,65.416908,-151.413162,-0.001354,0.003756,0.095394,290.988953,14.823683,0.953945,-151.413162,294.500488,0.000000
118.190002,65.364403,-151.457642,-0.001367,0.003756,0.095394,290.755371,14.811786,0.953945,-151.457642,294.500488,0.000000
118.550003,65.334236,-151.457642,-0.001358,0.003756,0.095394,290.621185,14.804950,0.953945,-151.457642,294.500488,0.000000
118.910004,65.308540,-151.546600,-0.001345,0.003756,0.095394,290.506897,14.799127,0.953945,-151.546600,294.500488,0.000000
119.270004,65.284340,-151.591080,-0.001354,0.003756,0.095394,290.399261,14.793643,0.953945,-151.591080,294.500488,0.000000
119.630005,65.256035,-151.635559,-0.001337,0.003756,0.095394,290.273346,14.787229,0.953945,-151.635559,1681.640991,0.000000
119.990005,65.237801,-151.724518,-0.001354,0.003751,0.095264,290.192230,14.783097,0.952643,-151.724518,0.095204,0.000000
120.350006,65.172264,-151.724518,-0.001341,0.003735,0.094857,289.900696,14.768247,0.948570,-151.724518,0.094606,0.000000
120.710007,65.090340,-151.813492,-0.001328,0.003716,0.094380,289.536285,14.749682,0.943801,-151.813492,0.094008,0.000000
121.070007,65.034477,-151.857971,-0.001341,0.003700,0.093973,289.287811,14.737023,0.939729,-151.857971,0.093408,0.000000
121.430008,64.986076,-151.857971,-0.001332,0.003676,0.093366,289.072510,14.726055,0.933658,-151.857971,0.092801,0.000000
121.790009,64.942497,-151.946930,-0.001337,0.003652,0.092759,288.878662,14.716180,0.927587,-151.946930,0.092203,0.000000
122.150009,64.917549,-151.946930,-0.001341,0.003631,0.092238,288.767670,14.710527,0.922379,-151.946930,0.091605,0.000000
122.510002,64.811806,-151.991409,-0.001341,0.003603,0.091519,288.297302,14.686565,0.915188,-151.991409,0.091007,0.000000
122.870003,64.790199,-152.080368,-0.001341,0.003589,0.091172,288.201202,14.681668,0.911721,-152.080368,0.090408,0.000000
123.230003,64.761909,-152.124847,-0.001324,0.003562,0.090486,288.075348,14.675258,0.904862,-152.124847,0.089802,0.000000
123.590004,64.661369,-152.124847,-0.001337,0.003531,0.089688,287.628143,14.652476,0.896884,-152.124847,0.089202,0.000000
123.950005,64.484489,-152.169327,-0.001337,0.003511,0.089168,286.841339,14.612393,0.891676,-152.169327,0.088604,0.000000
124.310005,64.073753,-152.169327,-0.001319,0.003491,0.088683,285.014282,14.519320,0.886831,-152.169327,0.088006,0.000000
124.670006,63.245979,-152.258301,-0.001319,0.003466,0.088049,281.332153,14.331744,0.880488,-152.258301,0.087408,0.000000
125.030006,62.313187,-152.347260,-0.001302,0.003449,0.087607,277.182892,14.120370,0.876067,-152.347260,0.086801,0.000000
125.390007,60.787575,-152.436218,-0.001298,0.003424,0.086974,270.396637,13.774662,0.869739,-152.436218,0.086202,0.000000
125.750008,59.548317,-152.436218,-0.001302,0.003407,0.086548,264.884155,13.493842,0.865484,-152.436218,0.085604,0.000000
126.110008,57.559845,-152.480698,-0.001298,0.003381,0.085890,256.038971,13.043247,0.858899,-152.480698,0.085006,0.000000
126.470009,56.265106,-152.525177,-0.001315,0.003364,0.085448,250.279694,12.749855,0.854478,-152.525177,0.084408,0.000000
126.830009,53.344963,-152.569656,-0.001306,0.003335,0.084701,237.290253,12.088141,0.847014,-152.569656,0.083808,0.000000
127.190002,51.265640,-152.614136,-0.001302,0.003316,0.084225,228.040955,11.616960,0.842245,-152.614136,0.083201,0.000000
127.550003,48.510452,-152.658630,-0.001293,0.003290,0.083557,215.785263,10.992625,0.835569,-152.658630,0.082603,0.000000
127.910004,45.906082,-152.747589,-0.001289,0.003264,0.082915,204.200455,10.402467,0.829149,-152.747589,0.082005,0.000000
128.270004,43.273033,-152.747589,-0.001289,0.003244,0.082396,192.488068,9.805809,0.823956,-152.747589,0.081407,0.000000
128.630005,40.453804,-152.792068,-0.001289,0.003218,0.081736,179.947510,9.166964,0.817356,-152.792068,0.080808,0.000000
128.990005,37.952576,-152.836548,-0.001298,0.003196,0.081172,168.821487,8.600176,0.811724,-152.836548,0.080200,0.000000
129.350006,35.377251,-152.881027,-0.001302,0.003172,0.080574,157.365875,8.016600,0.805744,-152.881027,0.079602,0.000000
129.710007,33.269623,-152.969986,-0.001298,0.003154,0.080105,147.990677,7.539004,0.801050,-152.969986,0.079004,0.000000
130.070007,30.079506,-153.014465,-0.001306,0.003122,0.079307,133.800323,6.816113,0.793072,-153.014465,0.078406,0.000000
130.430008,28.282806,-153.058960,-0.001302,0.003106,0.078900,125.808205,6.408976,0.788999,-153.058960,0.077807,0.000000
130.790009,26.007988,-153.103439,-0.001293,0.003084,0.078328,115.689308,5.893494,0.783276,-153.103439,0.077200,0.000000
131.150009,23.716408,-153.147919,-0.001302,0.003064,0.077834,105.495850,5.374215,0.778341,-153.147919,0.076602,0.000000
131.510010,20.649170,-153.147919,-0.001293,0.003037,0.077139,91.852097,4.679169,0.771392,-153.147919,0.076004,0.000000
131.870010,17.686577,-153.192398,-0.001298,0.003009,0.076420,78.673820,4.007835,0.764201,-153.192398,0.075406,0.000000
132.230011,15.877594,-153.236877,-0.001302,0.002992,0.075995,70.627068,3.597914,0.759946,-153.236877,0.074806,0.000000
132.590012,13.012932,-153.325836,-0.001306,0.002966,0.075327,57.884411,2.948772,0.753270,-153.325836,0.074199,0.000000
132.950012,10.195930,-153.281357,-0.001311,0.002939,0.074643,45.353764,2.310431,0.746427,-153.281357,0.073601,0.000000
133.310013,7.427719,-153.414795,-0.001298,0.002913,0.073992,33.040146,1.683145,0.739917,-153.414795,0.073003,0.000000
133.670013,5.154007,-153.414795,-0.001315,0.002888,0.073359,22.926168,1.167915,0.733588,-153.414795,0.072405,0.000000
134.029999,3.231079,-153.459274,-0.001315,0.002871,0.072924,14.372558,0.732173,0.729243,-153.459274,0.071806,0.000000
134.389999,0.946571,-153.548248,-0.001311,0.002849,0.072361,4.210560,0.214496,0.723611,-153.548248,0.071208,0.000000
134.750000,-0.974495,-153.592728,-0.001315,0.002826,0.071780,-4.334770,-0.220824,0.717798,-153.592728,0.070600,0.000000
135.110001,-4.443146,-153.592728,-0.001315,0.002793,0.070940,-19.764099,-1.006831,0.709395,-153.592728,0.070002,0.000000
135.470001,-0.243904,-153.681686,-0.001393,0.002774,0.070463,-1.084940,-0.055269,0.704626,-153.681686,0.069404,0.000000
135.830002,-0.027924,-153.681686,-0.001397,0.002751,0.069881,-0.124210,-0.006328,0.698813,-153.681686,0.068806,0.000000
136.190002,-0.070747,-153.815125,-0.001384,0.002727,0.069274,-0.314700,-0.016032,0.692742,-153.815125,0.068207,0.000000
136.550003,-0.046913,-153.815125,-0.001401,0.002709,0.068797,-0.208680,-0.010631,0.687973,-153.815125,0.067600,0.000000
136.910004,-0.045799,-153.815125,-0.001393,0.002686,0.068216,-0.203725,-0.010378,0.682159,-153.815125,0.067002,0.000000
137.270004,-0.091599,-153.948578,-0.001401,0.002657,0.067479,-0.407451,-0.020757,0.674786,-153.948578,0.066404,0.000000
137.630005,-0.076332,-153.993057,-0.001406,0.002632,0.066862,-0.339542,-0.017297,0.668624,-153.993057,0.065806,0.000000
137.990005,-0.040955,-153.948578,-0.001406,0.002614,0.066386,-0.182175,-0.009280,0.663855,-153.948578,0.065206,0.000000
138.350006,-0.051010,-154.037537,-0.001410,0.002588,0.065727,-0.226904,-0.011559,0.657270,-154.037537,0.064599,0.000000
138.710007,-0.098679,-154.037537,-0.001427,0.002559,0.064990,-0.438944,-0.022361,0.649897,-154.037537,0.064001,0.000000
139.070007,-0.124367,-154.126495,-0.001423,0.002534,0.064357,-0.553211,-0.028182,0.643568,-154.126495,0.063403,0.000000
139.430008,-0.079315,-154.126495,-0.001436,0.002517,0.063931,-0.352812,-0.017973,0.639314,-154.126495,0.062805,0.000000
139.790009,-0.093094,-154.170975,-0.001427,0.002496,0.063394,-0.414102,-0.021095,0.633940,-154.170975,0.062206,0.000000
140.150009,-0.090111,-154.259933,-0.001436,0.002467,0.062657,-0.400833,-0.020419,0.626567,-154.259933,0.061598,0.000000
140.510010,-0.099419,-154.215454,-0.001431,0.002444,0.062084,-0.442236,-0.022529,0.620844,-154.215454,0.061000,0.000000
140.870010,-0.135544,-154.348907,-0.001444,0.002416,0.061365,-0.602929,-0.030715,0.613653,-154.348907,0.060402,0.000000
141.230011,-0.099792,-154.393387,-0.001470,0.002392,0.060758,-0.443899,-0.022613,0.607582,-154.393387,0.059804,0.000000
141.590012,-0.123253,-154.393387,-0.001470,0.002369,0.060168,-0.548256,-0.027929,0.601677,-154.393387,0.059205,0.000000
141.950012,-0.109100,-154.571304,-0.001487,0.002356,0.059847,-0.485303,-0.024722,0.598468,-154.571304,0.058607,0.000000
142.310013,-0.100914,-154.482346,-0.001492,0.002328,0.059137,-0.448888,-0.022867,0.591367,-154.482346,0.058000,0.000000
142.670013,-0.127350,-154.615784,-0.001518,0.002298,0.058374,-0.566480,-0.028858,0.583737,-154.615784,0.057402,0.000000
143.030014,-0.149689,-154.660263,-0.001548,0.002276,0.057818,-0.665849,-0.033920,0.578181,-154.660263,0.056804,0.000000
143.389999,-0.120644,-154.615784,-0.001548,0.002246,0.057055,-0.536650,-0.027338,0.570550,-154.615784,0.056204,0.000000
143.750000,-0.137405,-154.749222,-0.001587,0.002232,0.056690,-0.611210,-0.031137,0.566902,-154.749222,0.055606,0.000000
144.110001,-0.141502,-154.793716,-0.001595,0.002203,0.055953,-0.629434,-0.032065,0.559529,-154.793716,0.054999,0.000000
144.470001,-0.141502,-154.838196,-0.001608,0.002185,0.055511,-0.629434,-0.032065,0.555108,-154.838196,0.054401,0.000000
144.830002,-0.134422,-154.838196,-0.001634,0.002159,0.054843,-0.597940,-0.030461,0.548431,-154.838196,0.053803,0.000000
145.190002,-0.133308,-154.927155,-0.001656,0.002129,0.054080,-0.592985,-0.030208,0.540801,-154.927155,0.053204,0.000000
145.550003,-0.129585,-154.971634,-0.001694,0.002111,0.053620,-0.576424,-0.029364,0.536198,-154.971634,0.052605,0.000000
145.910004,-0.119904,-154.927155,-0.001703,0.002084,0.052926,-0.533358,-0.027171,0.529265,-154.927155,0.051998,0.000000
146.270004,-0.118042,-155.105072,-0.001729,0.002065,0.052440,-0.525077,-0.026749,0.524405,-155.105072,0.051400,0.000000
146.400009,-0.109848,-155.060593,-0.001733,0.002057,0.052259,-0.488628,-0.024892,0.522588,-155.060593,0.052173,0.000000