File: Data/compression 30/AutoNoHeating-17-30-reverse-1-4_10242024_163228.csv
Time (sec),S:Load (lbs),S:HL1 (DIM),S:LVDT (in),S:Position (in),Ch:Position (mm),Ch:Load (N),Ch:Stress (MPa),Ch:Strain (mm/mm),Ch:HL1 (DIM),Set Point (),Cycles ()
0.010000,-0.029411,-200.208755,-0.007920,-0.003452,-0.087685,-0.130828,-0.006665,-0.876854,-200.208755,-0.087364,0.000000
0.380000,-0.052872,-200.164276,-0.007894,-0.003446,-0.087529,-0.235185,-0.011981,-0.875295,-200.164276,-0.086706,0.000000
0.750000,-0.056595,-200.164276,-0.007838,-0.003212,-0.081589,-0.251746,-0.012825,-0.815887,-200.164276,-0.080547,0.000000
1.120000,-0.048409,-200.208755,-0.007606,-0.002972,-0.075492,-0.215332,-0.010970,-0.754920,-200.208755,-0.074390,0.000000
1.490000,-0.009682,-200.297729,-0.007368,-0.002739,-0.069560,-0.043066,-0.002194,-0.695603,-200.297729,-0.068216,0.000000
1.860000,0.017876,-200.342209,-0.007101,-0.002491,-0.063264,0.079515,0.004051,-0.632638,-200.342209,-0.062059,0.000000
2.230000,0.006706,-200.342209,-0.006855,-0.002249,-0.057125,0.029831,0.001520,-0.571247,-200.342209,-0.055883,0.000000
2.600000,-0.024574,-200.342209,-0.006635,-0.002017,-0.051235,-0.109312,-0.005569,-0.512354,-200.342209,-0.049726,0.000000
2.970000,-0.057343,-200.386688,-0.006381,-0.001769,-0.044939,-0.255072,-0.012994,-0.449388,-200.386688,-0.043569,0.000000
3.340000,-0.065163,-200.475647,-0.006127,-0.001517,-0.038539,-0.289858,-0.014766,-0.385393,-200.475647,-0.037395,0.000000
3.710000,-0.013031,-200.431168,-0.005881,-0.001274,-0.032365,-0.057965,-0.002953,-0.323654,-200.431168,-0.031237,0.000000
4.080000,-0.007820,-200.475647,-0.005648,-0.001032,-0.026208,-0.034786,-0.001772,-0.262081,-200.475647,-0.025062,0.000000
4.450000,-0.017128,-200.431168,-0.005389,-0.000794,-0.020180,-0.076189,-0.003881,-0.201795,-200.431168,-0.018905,0.000000
4.820000,-0.010048,-200.564606,-0.005139,-0.000547,-0.013901,-0.044695,-0.002277,-0.139012,-200.564606,-0.012748,0.000000
5.190000,-0.024574,-200.609085,-0.004902,-0.000305,-0.007736,-0.109312,-0.005569,-0.077363,-200.609085,-0.006574,0.000000
5.560000,0.118790,-200.653564,-0.004661,-0.000009,-0.000216,0.528403,0.026918,-0.002165,-200.653564,-0.000000,0.000000
5.930000,0.115814,-200.698044,-0.004674,-0.000009,-0.000216,0.515167,0.026244,-0.002165,-200.698044,-0.000000,0.000000
6.300000,0.128098,-200.653564,-0.004665,-0.000009,-0.000216,0.569806,0.029027,-0.002165,-200.653564,0.000460,0.000000
6.670001,0.122887,-200.787018,-0.004669,0.000001,0.000026,0.546627,0.027847,0.000257,-200.787018,0.001075,0.000000
7.040000,0.243164,-200.787018,-0.004665,0.000018,0.000460,1.081648,0.055102,0.004602,-200.787018,0.001691,0.000000
7.410000,0.538826,-200.787018,-0.004618,0.000056,0.001422,2.396818,0.122100,0.014216,-200.787018,0.002307,0.000000
7.780000,0.768578,-200.787018,-0.004622,0.000078,0.001994,3.418804,0.174162,0.019939,-200.787018,0.002922,0.000000
8.150001,1.219894,-200.875977,-0.004592,0.000106,0.002696,5.426362,0.276432,0.026964,-200.875977,0.003538,0.000000
8.520000,1.622803,-200.920456,-0.004592,0.000126,0.003191,7.218587,0.367732,0.031914,-200.920456,0.004154,0.000000
8.890000,1.922562,-200.920456,-0.004579,0.000142,0.003608,8.551981,0.435659,0.036078,-200.920456,0.004769,0.000000
9.260000,2.602882,-200.920456,-0.004536,0.000175,0.004440,11.578199,0.589822,0.044404,-200.920456,0.005394,0.000000
9.630000,3.137611,-201.009415,-0.004527,0.000201,0.005117,13.956793,0.710993,0.051172,-201.009415,0.006010,0.000000
10.000000,3.688354,-200.964935,-0.004501,0.000224,0.005697,16.406620,0.835793,0.056970,-200.964935,0.006625,0.000000
10.370001,4.238716,-201.098373,-0.004484,0.000247,0.006278,18.854752,0.960507,0.062784,-201.098373,0.007241,0.000000
10.740001,4.648697,-201.187347,-0.004471,0.000264,0.006704,20.678436,1.053410,0.067038,-201.187347,0.007857,0.000000
11.110001,5.602348,-201.142868,-0.004441,0.000300,0.007623,24.920490,1.269510,0.076228,-201.142868,0.008472,0.000000
11.480000,6.010094,-201.098373,-0.004415,0.000324,0.008221,26.734232,1.361907,0.082208,-201.098373,0.009088,0.000000
11.850000,6.563812,-201.187347,-0.004406,0.000347,0.008811,29.197294,1.487381,0.088112,-201.187347,0.009704,0.000000
12.220000,7.316002,-201.276306,-0.004376,0.000374,0.009488,32.543201,1.657830,0.094880,-201.276306,0.010321,0.000000
12.590000,7.465324,-201.276306,-0.004368,0.000385,0.009791,33.207420,1.691667,0.097908,-201.276306,0.010944,0.000000
12.960001,8.579094,-201.276306,-0.004346,0.000421,0.010693,38.161716,1.944050,0.106931,-201.276306,0.011561,0.000000
13.330001,8.964867,-201.320786,-0.004329,0.000443,0.011240,39.877720,2.031468,0.112396,-201.320786,0.012175,0.000000
13.700001,9.475021,-201.365265,-0.004286,0.000467,0.011854,42.146999,2.147071,0.118543,-201.365265,0.012791,0.000000
14.070001,10.059647,-201.454224,-0.004286,0.000490,0.012436,44.747543,2.279548,0.124357,-201.454224,0.013408,0.000000
14.440001,10.366104,-201.454224,-0.004264,0.000508,0.012905,46.110733,2.348993,0.129050,-201.454224,0.014022,0.000000
14.810000,11.272835,-201.454224,-0.004247,0.000539,0.013694,50.144073,2.554461,0.136937,-201.454224,0.014638,0.000000
15.180000,11.618027,-201.454224,-0.004225,0.000560,0.014222,51.679565,2.632683,0.142221,-201.454224,0.015255,0.000000
15.550001,12.138603,-201.587677,-0.004199,0.000585,0.014847,53.995205,2.750647,0.148474,-201.587677,0.015871,0.000000
15.920001,12.720245,-201.587677,-0.004182,0.000611,0.015532,56.582478,2.882449,0.155317,-201.587677,0.016495,0.000000
16.290001,13.202843,-201.587677,-0.004148,0.000637,0.016174,58.729179,2.991807,0.161736,-201.587677,0.017111,0.000000
16.660000,13.457542,-201.587677,-0.004148,0.000655,0.016625,59.862137,3.049523,0.166248,-201.587677,0.017725,0.000000
17.030001,13.924500,-201.632156,-0.004143,0.000676,0.017162,61.939266,3.155337,0.171622,-201.632156,0.018342,0.000000
17.400002,14.621582,-201.676636,-0.004117,0.000707,0.017951,65.040047,3.313298,0.179510,-201.676636,0.018958,0.000000
17.770000,14.715790,-201.765594,-0.004092,0.000723,0.018360,65.459099,3.334646,0.183598,-201.765594,0.019572,0.000000
18.140001,15.462395,-201.721115,-0.004061,0.000748,0.019000,68.780167,3.503829,0.190002,-201.721115,0.020189,0.000000
18.510000,16.034363,-201.765594,-0.004057,0.000776,0.019712,71.324409,3.633439,0.197117,-201.765594,0.020805,0.000000
18.880001,16.295395,-201.765594,-0.004044,0.000796,0.020223,72.485535,3.692589,0.202235,-201.765594,0.021421,0.000000
19.250000,16.686760,-201.899033,-0.004005,0.000822,0.020874,74.226418,3.781274,0.208745,-201.899033,0.022045,0.000000
19.620001,17.032692,-201.899033,-0.003992,0.000848,0.021551,75.765198,3.859663,0.215512,-201.899033,0.022661,0.000000
19.990002,17.342506,-201.899033,-0.003967,0.000869,0.022070,77.143318,3.929868,0.220705,-201.899033,0.023276,0.000000
20.360001,17.812065,-201.943512,-0.003962,0.000896,0.022756,79.232025,4.036272,0.227563,-201.943512,0.023892,0.000000
20.730001,18.332268,-201.943512,-0.003941,0.000927,0.023554,81.545998,4.154151,0.235542,-201.943512,0.024508,0.000000
21.100000,18.451805,-201.987991,-0.003911,0.000947,0.024048,82.077728,4.181239,0.240477,-201.987991,0.025124,0.000000
21.470001,18.349403,-202.032486,-0.003889,0.000965,0.024517,81.622223,4.158034,0.245170,-202.032486,0.025739,0.000000
21.840000,19.079254,-202.032486,-0.003854,0.000998,0.025348,84.868759,4.323421,0.253482,-202.032486,0.026355,0.000000
22.210001,19.254639,-202.076965,-0.003850,0.001019,0.025878,85.648911,4.363163,0.258781,-202.076965,0.026971,0.000000
22.580002,19.679886,-202.165924,-0.003829,0.001048,0.026615,87.540504,4.459526,0.266154,-202.165924,0.027595,0.000000
22.950001,20.204185,-202.165924,-0.003816,0.001076,0.027327,89.872704,4.578334,0.273269,-202.165924,0.028211,0.000000
23.320002,19.873146,-202.210403,-0.003764,0.001095,0.027811,88.400169,4.503319,0.278114,-202.210403,0.028826,0.000000
23.690001,19.905174,-202.210403,-0.003764,0.001113,0.028263,88.542641,4.510577,0.282626,-202.210403,0.029442,0.000000
24.060001,20.253342,-202.299362,-0.003742,0.001136,0.028844,90.091362,4.589473,0.288439,-202.299362,0.030058,0.000000
24.430000,20.744873,-202.343842,-0.003738,0.001165,0.029581,92.277802,4.700855,0.295812,-202.343842,0.030674,0.000000
24.800001,21.597977,-202.388321,-0.003691,0.001197,0.030414,96.072601,4.894172,0.304139,-202.388321,0.031289,0.000000
25.170002,21.012611,-202.388321,-0.003673,0.001213,0.030821,93.468765,4.761526,0.308212,-202.388321,0.031905,0.000000
25.540001,21.106819,-202.432816,-0.003660,0.001239,0.031480,93.887817,4.782874,0.314797,-202.432816,0.032521,0.000000
25.910002,21.478447,-202.432816,-0.003626,0.001261,0.032026,95.540901,4.867086,0.320263,-202.432816,0.033145,0.000000
26.280001,21.776718,-202.521774,-0.003617,0.001285,0.032652,96.867683,4.934675,0.326515,-202.521774,0.033761,0.000000
26.650002,22.744141,-202.566254,-0.003591,0.001323,0.033605,101.170990,5.153896,0.336053,-202.566254,0.034377,0.000000
27.020000,22.215744,-202.566254,-0.003553,0.001342,0.034091,98.820564,5.034159,0.340913,-202.566254,0.034992,0.000000
27.390001,22.069771,-202.566254,-0.003544,0.001366,0.034706,98.171242,5.001081,0.347060,-202.566254,0.035608,0.000000
27.760002,22.549759,-202.655212,-0.003527,0.001391,0.035322,100.306335,5.109848,0.353222,-202.655212,0.036224,0.000000
28.130001,22.042221,-202.655212,-0.003501,0.001405,0.035678,98.048698,4.994839,0.356779,-202.655212,0.036839,0.000000
28.500002,22.123024,-202.788651,-0.003492,0.001423,0.036155,98.408127,5.013149,0.361548,-202.788651,0.037455,0.000000
28.870001,23.435265,-202.699692,-0.003449,0.001464,0.037178,104.245262,5.310507,0.371783,-202.699692,0.038072,0.000000
29.240002,23.235672,-202.788651,-0.003436,0.001486,0.037732,103.357430,5.265278,0.377324,-202.788651,0.038695,0.000000
29.610001,23.432655,-202.833130,-0.003423,0.001513,0.038435,104.233658,5.309916,0.384349,-202.833130,0.039311,0.000000
29.980001,23.091934,-202.833130,-0.003406,0.001529,0.038844,102.718056,5.232707,0.388436,-202.833130,0.039928,0.000000
30.350002,23.236046,-202.833130,-0.003376,0.001552,0.039416,103.359093,5.265363,0.394159,-202.833130,0.040542,0.000000
30.720001,23.880997,-202.922104,-0.003359,0.001583,0.040205,106.227982,5.411511,0.402047,-202.922104,0.041158,0.000000
31.090002,23.997543,-202.922104,-0.003346,0.001608,0.040856,106.746407,5.437921,0.408557,-202.922104,0.041775,0.000000
31.460001,23.885460,-203.011063,-0.003320,0.001635,0.041523,106.247833,5.412523,0.415233,-203.011063,0.042389,0.000000
31.830002,23.554794,-203.100021,-0.003298,0.001648,0.041861,104.776955,5.337593,0.418609,-203.100021,0.043005,0.000000
32.200001,23.449043,-203.055542,-0.003272,0.001667,0.042338,104.306557,5.313629,0.423378,-203.055542,0.043631,0.000000
32.570000,24.596321,-203.055542,-0.003251,0.001707,0.043352,109.409897,5.573606,0.433522,-203.055542,0.044245,0.000000
32.940002,24.542702,-203.100021,-0.003229,0.001731,0.043977,109.171387,5.561456,0.439775,-203.100021,0.044862,0.000000
33.310001,24.362846,-203.188980,-0.003212,0.001753,0.044515,108.371353,5.520700,0.445149,-203.188980,0.045478,0.000000
33.680000,24.778038,-203.188980,-0.003186,0.001781,0.045243,110.218216,5.614784,0.452431,-203.188980,0.046092,0.000000
34.050003,24.577332,-203.144501,-0.003152,0.001802,0.045771,109.325432,5.569303,0.457715,-203.144501,0.046709,0.000000
34.420002,25.067001,-203.188980,-0.003147,0.001828,0.046432,111.503593,5.680264,0.464316,-203.188980,0.047325,0.000000
34.790001,25.018967,-203.277939,-0.003134,0.001853,0.047064,111.289925,5.669379,0.470644,-203.277939,0.047939,0.000000
35.160000,24.769844,-203.366913,-0.003104,0.001872,0.047550,110.181770,5.612927,0.475504,-203.366913,0.048556,0.000000
35.530003,25.457619,-203.411392,-0.003091,0.001901,0.048288,113.241142,5.768779,0.482877,-203.411392,0.049181,0.000000
35.900002,24.365448,-203.366913,-0.003057,0.001907,0.048435,108.382927,5.521289,0.484345,-203.366913,0.049796,0.000000
36.270000,26.001282,-203.366913,-0.003040,0.001949,0.049502,115.659477,5.891974,0.495019,-203.366913,0.050412,0.000000
36.640003,25.590927,-203.411392,-0.003009,0.001965,0.049917,113.834129,5.798987,0.499167,-203.411392,0.051028,0.000000
37.010002,25.895905,-203.544830,-0.002992,0.001992,0.050603,115.190735,5.868096,0.506025,-203.544830,0.051643,0.000000
37.380001,26.608994,-203.544830,-0.002953,0.002023,0.051375,118.362717,6.029684,0.513747,-203.544830,0.052259,0.000000
37.750000,26.161400,-203.544830,-0.002940,0.002040,0.051808,116.371719,5.928258,0.518076,-203.544830,0.052875,0.000000
38.120003,26.229546,-203.589310,-0.002928,0.002061,0.052354,116.674843,5.943700,0.523542,-203.589310,0.053490,0.000000
38.490002,26.615326,-203.633789,-0.002910,0.002086,0.052979,118.390884,6.031119,0.529794,-203.633789,0.054106,0.000000
38.860001,26.915085,-203.722763,-0.002893,0.002111,0.053620,119.724274,6.099045,0.536198,-203.722763,0.054731,0.000000
39.230003,26.595963,-203.678268,-0.002880,0.002132,0.054150,118.304749,6.026731,0.541497,-203.678268,0.055346,0.000000
39.600002,26.489464,-203.722763,-0.002846,0.002147,0.054522,117.831017,6.002598,0.545222,-203.722763,0.055962,0.000000
39.970001,27.443108,-203.678268,-0.002815,0.002178,0.055329,122.073036,6.218697,0.553291,-203.678268,0.056578,0.000000
40.340000,27.332886,-203.811722,-0.002807,0.002199,0.055867,121.582748,6.193720,0.558666,-203.811722,0.057193,0.000000
40.710003,28.158066,-203.856201,-0.002777,0.002233,0.056725,125.253334,6.380709,0.567250,-203.856201,0.057809,0.000000
41.080002,27.674355,-203.856201,-0.002764,0.002250,0.057159,123.101677,6.271099,0.571595,-203.856201,0.058425,0.000000
41.450001,27.549980,-203.900681,-0.002734,0.002277,0.057827,122.548431,6.242915,0.578271,-203.900681,0.059041,0.000000
41.820004,28.752373,-203.900681,-0.002716,0.002305,0.058555,127.896942,6.515381,0.585554,-203.900681,0.059656,0.000000
42.190002,29.055107,-203.989639,-0.002686,0.002332,0.059240,129.243576,6.583982,0.592397,-203.989639,0.060281,0.000000
42.560001,28.697258,-204.034119,-0.002673,0.002356,0.059830,127.651779,6.502892,0.598301,-204.034119,0.060896,0.000000
42.930000,28.566925,-204.034119,-0.002634,0.002378,0.060411,127.072029,6.473358,0.604115,-204.034119,0.061512,0.000000
43.300003,29.247627,-204.034119,-0.002630,0.002406,0.061122,130.099945,6.627607,0.611215,-204.034119,0.062128,0.000000
43.670002,28.896477,-204.078598,-0.002613,0.002425,0.061598,128.537949,6.548035,0.615984,-204.078598,0.062743,0.000000
44.040001,29.548500,-204.123077,-0.002578,0.002452,0.062275,131.438293,6.695786,0.622751,-204.123077,0.063359,0.000000
44.410004,30.045990,-204.167572,-0.002565,0.002483,0.063056,133.651245,6.808519,0.630563,-204.167572,0.063975,0.000000
44.780003,29.730591,-204.212051,-0.002539,0.002504,0.063603,132.248276,6.737048,0.636029,-204.212051,0.064592,0.000000
45.150002,29.599518,-204.256531,-0.002509,0.002523,0.064087,131.665237,6.707347,0.640874,-204.256531,0.065206,0.000000
45.520000,29.778259,-204.256531,-0.002518,0.002544,0.064608,132.460312,6.747850,0.646082,-204.256531,0.065831,0.000000
45.890003,30.611252,-204.301010,-0.002492,0.002573,0.065345,136.165649,6.936609,0.653455,-204.301010,0.066446,0.000000
46.260002,31.364563,-204.345490,-0.002449,0.002603,0.066108,139.516541,7.107312,0.661085,-204.345490,0.067062,0.000000
46.630001,30.921066,-204.345490,-0.002436,0.002622,0.066611,137.543777,7.006814,0.666111,-204.345490,0.067678,0.000000
47.000004,31.188057,-204.345490,-0.002414,0.002645,0.067183,138.731400,7.067315,0.671834,-204.345490,0.068295,0.000000
47.370003,31.586494,-204.389969,-0.002397,0.002669,0.067783,140.503738,7.157602,0.677829,-204.389969,0.068909,0.000000
47.740002,31.891098,-204.478928,-0.002384,0.002691,0.068346,141.858688,7.226626,0.683461,-204.478928,0.069525,0.000000
48.110001,33.469215,-204.523407,-0.002354,0.002729,0.069309,148.878510,7.584233,0.693090,-204.523407,0.070142,0.000000
48.480003,33.076729,-204.523407,-0.002324,0.002748,0.069803,147.132645,7.495294,0.698025,-204.523407,0.070756,0.000000
48.850002,33.374626,-204.567886,-0.002311,0.002772,0.070401,148.457748,7.562799,0.704006,-204.567886,0.071382,0.000000
49.220001,33.728012,-204.567886,-0.002302,0.002795,0.070991,150.029694,7.642877,0.709910,-204.567886,0.071996,0.000000
49.590004,33.653908,-204.701340,-0.002281,0.002812,0.071433,149.700058,7.626084,0.714331,-204.701340,0.072612,0.000000
49.960003,34.794861,-204.656860,-0.002255,0.002842,0.072196,154.775269,7.884628,0.721961,-204.656860,0.073229,0.000000
50.330002,35.841599,-204.701340,-0.002242,0.002869,0.072873,159.431396,8.121822,0.728729,-204.701340,0.073845,0.000000
50.700001,36.101883,-204.701340,-0.002225,0.002893,0.073480,160.589203,8.180803,0.734800,-204.701340,0.074459,0.000000
51.070004,36.814606,-204.790298,-0.002212,0.002917,0.074104,163.759552,8.342309,0.741037,-204.790298,0.075076,0.000000
51.440002,36.592674,-204.834778,-0.002199,0.002935,0.074538,162.772339,8.292019,0.745382,-204.834778,0.075692,0.000000
51.810001,37.987579,-204.879257,-0.002190,0.002966,0.075327,168.977188,8.608109,0.753270,-204.879257,0.076307,0.000000
52.180004,38.814247,-204.879257,-0.002147,0.002992,0.075995,172.654388,8.795434,0.759946,-204.879257,0.076932,0.000000
52.550003,39.238380,-204.923737,-0.002143,0.003015,0.076585,174.541031,8.891544,0.765851,-204.923737,0.077548,0.000000
52.920002,39.886681,-204.968216,-0.002130,0.003038,0.077165,177.424820,9.038451,0.771649,-204.968216,0.078163,0.000000
53.290001,39.388069,-204.968216,-0.002113,0.003052,0.077521,175.206879,8.925464,0.775207,-204.968216,0.078779,0.000000
53.660004,41.725456,-205.012711,-0.002082,0.003090,0.078474,185.604095,9.455124,0.784745,-205.012711,0.079395,0.000000
54.030003,42.855980,-205.057190,-0.002074,0.003115,0.079126,190.632919,9.711304,0.791255,-205.057190,0.080010,0.000000
54.400002,43.117386,-205.057190,-0.002057,0.003137,0.079681,191.795715,9.770539,0.796811,-205.057190,0.080626,0.000000
54.770004,43.869202,-205.101669,-0.002031,0.003162,0.080305,195.139954,9.940904,0.803049,-205.101669,0.081242,0.000000
55.140003,44.799385,-205.146149,-0.002013,0.003182,0.080835,199.277618,10.151686,0.808348,-205.146149,0.081866,0.000000
55.510002,45.786545,-205.190628,-0.002005,0.003210,0.081536,203.668716,10.375379,0.815357,-205.190628,0.082482,0.000000
55.880001,46.332817,-205.190628,-0.001988,0.003226,0.081952,206.098663,10.499166,0.819521,-205.190628,0.083098,0.000000
56.250004,47.817467,-205.235107,-0.001988,0.003259,0.082777,212.702713,10.835592,0.827772,-205.235107,0.083713,0.000000
56.620003,48.912987,-205.279587,-0.001979,0.003287,0.083480,217.575836,11.083841,0.834796,-205.279587,0.084329,0.000000
56.990002,49.693855,-205.279587,-0.001944,0.003305,0.083938,221.049301,11.260788,0.839384,-205.279587,0.084945,0.000000
57.360004,50.161926,-205.368546,-0.001936,0.003324,0.084441,223.131393,11.366855,0.844410,-205.368546,0.085560,0.000000
57.730003,51.932182,-205.368546,-0.001927,0.003353,0.085171,231.005890,11.768002,0.851707,-205.368546,0.086176,0.000000
58.100002,52.857903,-205.368546,-0.001910,0.003377,0.085785,235.123688,11.977773,0.857854,-205.368546,0.086792,0.000000
58.470001,53.426888,-205.457520,-0.001897,0.003395,0.086246,237.654663,12.106706,0.862456,-205.457520,0.087416,0.000000
58.840004,55.084686,-205.501999,-0.001884,0.003428,0.087069,245.028915,12.482368,0.870692,-205.501999,0.088032,0.000000
59.210003,56.017479,-205.501999,-0.001854,0.003446,0.087520,249.178192,12.693742,0.875204,-205.501999,0.088648,0.000000
59.580002,57.183754,-205.546478,-0.001850,0.003469,0.088118,254.366043,12.958024,0.881184,-205.546478,0.089263,0.000000
59.950005,58.399178,-205.546478,-0.001828,0.003497,0.088812,259.772522,13.233443,0.888118,-205.546478,0.089879,0.000000
60.320004,59.377396,-205.635437,-0.001819,0.003516,0.089298,264.123840,13.455111,0.892978,-205.635437,0.090495,0.000000
60.690002,60.970032,-205.635437,-0.001798,0.003544,0.090026,271.208252,13.816007,0.900260,-205.635437,0.091110,0.000000
61.060001,61.357674,-205.679916,-0.001789,0.003563,0.090512,272.932556,13.903848,0.905120,-205.679916,0.091726,0.000000
61.430004,63.907677,-205.679916,-0.001794,0.003594,0.091275,284.275543,14.481687,0.912750,-205.679916,0.092342,0.000000
61.800003,65.531227,-205.679916,-0.001772,0.003618,0.091900,291.497467,14.849588,0.919003,-205.679916,0.092966,0.000000
62.170002,65.807533,-205.768875,-0.001755,0.003622,0.091996,292.726532,14.912200,0.919957,-205.768875,0.092238,0.000000
62.540005,64.673286,-205.768875,-0.001738,0.003622,0.091996,287.681152,14.655176,0.919957,-205.768875,294.500488,0.000000
62.910004,65.764336,-205.813354,-0.001720,0.003630,0.092194,292.534363,14.902411,0.921940,-205.813354,294.500488,0.000000
63.280003,65.119377,-205.813354,-0.001716,0.003648,0.092663,289.665466,14.756262,0.926633,-205.813354,294.500488,0.000000
63.650002,65.532722,-205.857849,-0.001716,0.003660,0.092959,291.504120,14.849927,0.929585,-205.857849,294.500488,0.000000
64.020004,64.882545,-205.946808,-0.001716,0.003660,0.092966,288.611969,14.702596,0.929661,-205.946808,294.500488,0.000000
64.389999,65.059425,-205.946808,-0.001707,0.003669,0.093192,289.398773,14.742677,0.931917,-205.946808,294.500488,0.000000
64.760002,64.601418,-205.946808,-0.001703,0.003670,0.093210,287.361450,14.638890,0.932099,-205.946808,294.500488,0.000000
65.130005,65.556175,-205.946808,-0.001703,0.003677,0.093408,291.608429,14.855242,0.934082,-205.946808,294.500488,0.000000
65.500000,64.962608,-206.035767,-0.001703,0.003677,0.093408,288.968109,14.720737,0.934082,-206.035767,294.500488,0.000000
65.870003,65.248222,-206.080246,-0.001690,0.003690,0.093729,290.238586,14.785459,0.937291,-206.080246,294.500488,0.000000
66.240005,64.787224,-206.124725,-0.001690,0.003690,0.093729,288.187958,14.680995,0.937291,-206.124725,294.500488,0.000000
66.610001,65.868599,-206.124725,-0.001669,0.003696,0.093868,292.998169,14.926038,0.938684,-206.124725,294.500488,0.000000
66.980003,65.454887,-206.124725,-0.001664,0.003696,0.093868,291.157867,14.832290,0.938684,-206.124725,294.500488,0.000000
67.350006,65.011772,-206.169205,-0.001686,0.003703,0.094068,289.186798,14.731878,0.940683,-206.169205,294.500488,0.000000
67.720001,65.028145,-206.258163,-0.001677,0.003709,0.094198,289.259644,14.735588,0.941985,-206.258163,294.500488,0.000000
68.090004,65.169273,-206.302658,-0.001673,0.003714,0.094336,289.887421,14.767569,0.943362,-206.302658,294.500488,0.000000
68.460007,64.999474,-206.213684,-0.001673,0.003714,0.094336,289.132111,14.729092,0.943362,-206.213684,294.500488,0.000000
68.830002,65.671242,-206.302658,-0.001664,0.003724,0.094597,292.120270,14.881316,0.945966,-206.302658,294.500488,0.000000
69.200005,65.463448,-206.347137,-0.001664,0.003724,0.094588,291.195953,14.834229,0.945876,-206.347137,294.500488,0.000000
69.570000,65.230354,-206.436096,-0.001669,0.003724,0.094588,290.159119,14.781409,0.945876,-206.436096,294.500488,0.000000
69.940002,65.388603,-206.347137,-0.001656,0.003729,0.094727,290.863037,14.817269,0.947268,-206.347137,294.500488,0.000000
70.310005,65.247475,-206.480576,-0.001651,0.003730,0.094745,290.235260,14.785289,0.947450,-206.480576,294.500488,0.000000
70.680000,65.096291,-206.480576,-0.001638,0.003731,0.094771,289.562775,14.751030,0.947707,-206.480576,294.500488,0.000000
71.050003,64.928352,-206.525055,-0.001660,0.003731,0.094771,288.815735,14.712975,0.947707,-206.525055,294.500488,0.000000
71.420006,65.808266,-206.569534,-0.001647,0.003741,0.095031,292.729797,14.912367,0.950311,-206.569534,294.500488,0.000000
71.790001,65.590431,-206.614014,-0.001643,0.003741,0.095031,291.760803,14.863005,0.950311,-206.614014,294.500488,0.000000
72.160004,65.425850,-206.614014,-0.001647,0.003741,0.095031,291.028717,14.825709,0.950311,-206.614014,294.500488,0.000000
72.530006,65.255302,-206.658493,-0.001643,0.003742,0.095039,290.270081,14.787063,0.950387,-206.658493,294.500488,0.000000
72.900002,65.066505,-206.658493,-0.001643,0.003742,0.095039,289.430267,14.744281,0.950387,-206.658493,294.500488,0.000000
73.270004,64.892982,-206.836426,-0.001638,0.003742,0.095039,288.658417,14.704960,0.950387,-206.836426,294.500488,0.000000
73.640007,64.725410,-206.791946,-0.001630,0.003742,0.095039,287.912994,14.666987,0.950387,-206.791946,294.500488,0.000000
74.010002,65.898384,-206.791946,-0.001643,0.003750,0.095248,293.130646,14.932788,0.952476,-206.791946,294.500488,0.000000
74.380005,65.754646,-206.791946,-0.001625,0.003750,0.095248,292.491272,14.900216,0.952476,-206.791946,294.500488,0.000000
74.750000,65.558403,-206.925385,-0.001643,0.003750,0.095248,291.618347,14.855746,0.952476,-206.925385,294.500488,0.000000
75.120003,65.367760,-206.880905,-0.001638,0.003750,0.095248,290.770325,14.812547,0.952476,-206.880905,294.500488,0.000000
75.490005,65.218437,-206.969864,-0.001630,0.003750,0.095248,290.106110,14.778709,0.952476,-206.969864,294.500488,0.000000
75.860001,65.058311,-206.880905,-0.001617,0.003750,0.095248,289.393829,14.742424,0.952476,-206.880905,294.500488,0.000000
76.230003,64.904518,-206.969864,-0.001643,0.003750,0.095248,288.709717,14.707574,0.952476,-206.969864,294.500488,0.000000
76.600006,64.771217,-207.014343,-0.001630,0.003750,0.095257,288.116760,14.677368,0.952567,-207.014343,294.500488,0.000000
76.970001,65.901360,-207.058823,-0.001634,0.003765,0.095620,293.143890,14.933461,0.956201,-207.058823,294.500488,0.000000
77.340004,65.769173,-207.103302,-0.001608,0.003765,0.095620,292.555878,14.903507,0.956201,-207.103302,294.500488,0.000000
77.710007,65.600487,-207.103302,-0.001625,0.003765,0.095620,291.805542,14.865283,0.956201,-207.103302,294.500488,0.000000
78.080002,65.497719,-207.147797,-0.001630,0.003765,0.095620,291.348419,14.841995,0.956201,-207.147797,294.500488,0.000000
78.450005,65.364403,-207.236755,-0.001613,0.003765,0.095620,290.755371,14.811786,0.956201,-207.236755,294.500488,0.000000
78.820007,65.257164,-207.192276,-0.001625,0.003765,0.095620,290.278351,14.787484,0.956201,-207.192276,294.500488,0.000000
79.190002,65.146935,-207.192276,-0.001608,0.003765,0.095629,289.788025,14.762506,0.956292,-207.192276,294.500488,0.000000
79.560005,65.058311,-207.281235,-0.001630,0.003766,0.095655,289.393829,14.742424,0.956549,-207.281235,294.500488,0.000000
79.930000,65.011391,-207.325714,-0.001630,0.003766,0.095664,289.185120,14.731791,0.956640,-207.325714,294.500488,0.000000
80.300003,64.934319,-207.325714,-0.001613,0.003766,0.095664,288.842285,14.714327,0.956640,-207.325714,294.500488,0.000000
80.670006,65.095924,-207.459152,-0.001617,0.003771,0.095794,289.561127,14.750948,0.957942,-207.459152,294.500488,0.000000
81.040001,65.137993,-207.459152,-0.001621,0.003771,0.095794,289.748260,14.760480,0.957942,-207.459152,294.500488,0.000000
81.410004,65.069115,-207.459152,-0.001625,0.003771,0.095794,289.441864,14.744872,0.957942,-207.459152,294.500488,0.000000
81.780006,65.019585,-207.503632,-0.001617,0.003771,0.095794,289.221558,14.733649,0.957942,-207.503632,294.500488,0.000000
82.150002,64.956657,-207.592606,-0.001617,0.003771,0.095794,288.941650,14.719389,0.957942,-207.592606,294.500488,0.000000
82.520004,64.867287,-207.637085,-0.001613,0.003771,0.095794,288.544098,14.699137,0.957942,-207.637085,294.500488,0.000000
82.890007,64.792442,-207.637085,-0.001600,0.003771,0.095794,288.211182,14.682177,0.957942,-207.637085,294.500488,0.000000
83.260002,65.776253,-207.592606,-0.001625,0.003783,0.096080,292.587372,14.905111,0.960803,-207.592606,294.500488,0.000000
83.630005,65.762840,-207.637085,-0.001613,0.003783,0.096080,292.527710,14.902072,0.960803,-207.637085,294.500488,0.000000
84.000008,65.654106,-207.726044,-0.001617,0.003783,0.096080,292.044037,14.877433,0.960803,-207.726044,294.500488,0.000000
84.370003,65.584099,-207.681564,-0.001604,0.003783,0.096080,291.732635,14.861569,0.960803,-207.681564,294.500488,0.000000
84.740005,65.548347,-207.726044,-0.001600,0.003783,0.096080,291.573608,14.853468,0.960803,-207.726044,294.500488,0.000000
85.110001,65.486534,-207.770523,-0.001600,0.003783,0.096080,291.298645,14.839460,0.960803,-207.770523,294.500488,0.000000
85.480003,65.376686,-207.815002,-0.001600,0.003783,0.096080,290.810028,14.814569,0.960803,-207.815002,294.500488,0.000000
85.850006,65.324928,-207.859482,-0.001600,0.003783,0.096080,290.579803,14.802840,0.960803,-207.859482,294.500488,0.000000
86.220001,65.267586,-207.903961,-0.001621,0.003783,0.096080,290.324707,14.789846,0.960803,-207.903961,294.500488,0.000000
86.590004,65.203545,-207.948441,-0.001587,0.003783,0.096080,290.039856,14.775334,0.960803,-207.948441,294.500488,0.000000
86.960007,65.128685,-207.992920,-0.001617,0.003783,0.096080,289.706848,14.758371,0.960803,-207.992920,294.500488,0.000000
87.330002,65.059807,-207.992920,-0.001608,0.003783,0.096080,289.400482,14.742763,0.960803,-207.992920,294.500488,0.000000
87.700005,65.003944,-208.037415,-0.001604,0.003783,0.096080,289.151978,14.730104,0.960803,-208.037415,294.500488,0.000000
88.070007,64.936913,-208.081894,-0.001595,0.003783,0.096080,288.853821,14.714914,0.960803,-208.081894,294.500488,0.000000
88.440002,64.860588,-208.037415,-0.001591,0.003783,0.096080,288.514313,14.697619,0.960803,-208.037415,294.500488,0.000000
88.810005,64.792809,-208.126373,-0.001591,0.003783,0.096080,288.212799,14.682261,0.960803,-208.126373,294.500488,0.000000
89.180008,64.744026,-208.126373,-0.001608,0.003783,0.096080,287.995819,14.671206,0.960803,-208.126373,294.500488,0.000000
89.550003,64.696739,-208.170853,-0.001595,0.003783,0.096080,287.785461,14.660490,0.960803,-208.170853,294.500488,0.000000
89.920006,64.623009,-208.170853,-0.001600,0.003783,0.096080,287.457489,14.643784,0.960803,-208.170853,294.500488,0.000000
90.290001,64.544060,-208.215332,-0.001587,0.003783,0.096080,287.106323,14.625893,0.960803,-208.215332,294.500488,0.000000
90.660004,64.487465,-208.259811,-0.001595,0.003783,0.096088,286.854584,14.613069,0.960879,-208.259811,294.500488,0.000000
91.030006,64.441658,-208.304291,-0.001604,0.003783,0.096088,286.650818,14.602688,0.960879,-208.304291,294.500488,0.000000
91.400002,64.404060,-208.348770,-0.001608,0.003783,0.096088,286.483582,14.594169,0.960879,-208.348770,294.500488,0.000000
91.770004,64.334053,-208.348770,-0.001604,0.003783,0.096088,286.172150,14.578304,0.960879,-208.348770,294.500488,0.000000
92.140007,64.258080,-208.393250,-0.001600,0.003783,0.096088,285.834229,14.561090,0.960879,-208.393250,294.500488,0.000000
92.510002,67.103752,-208.437744,-0.001561,0.003635,0.092333,298.492401,15.205928,0.923333,-208.437744,294.500488,0.000000
92.880005,66.764519,-208.482224,-0.001591,0.003595,0.091319,296.983398,15.129056,0.913189,-208.482224,294.500488,0.000000
93.250008,66.669197,-208.482224,-0.001587,0.003595,0.091319,296.559387,15.107456,0.913189,-208.482224,294.500488,0.000000
93.620003,66.662865,-208.615662,-0.001574,0.003595,0.091319,296.531219,15.106021,0.913189,-208.615662,294.500488,0.000000
93.990005,66.553764,-208.615662,-0.001574,0.003596,0.091328,296.045929,15.081299,0.913280,-208.615662,294.500488,0.000000
94.360008,66.457695,-208.615662,-0.001569,0.003596,0.091345,295.618591,15.059529,0.913447,-208.615662,294.500488,0.000000
94.730003,66.407417,-208.615662,-0.001565,0.003596,0.091345,295.394958,15.048136,0.913447,-208.615662,294.500488,0.000000
95.100006,66.358635,-208.704620,-0.001574,0.003596,0.091345,295.177948,15.037081,0.913447,-208.704620,294.500488,0.000000
95.470001,66.287148,-208.704620,-0.001556,0.003596,0.091345,294.859955,15.020883,0.913447,-208.704620,294.500488,0.000000
95.840004,66.237984,-208.704620,-0.001574,0.003596,0.091345,294.641266,15.009742,0.913447,-208.704620,294.500488,0.000000
96.210007,66.171700,-208.660141,-0.001569,0.003596,0.091345,294.346405,14.994721,0.913447,-208.660141,294.500488,0.000000
96.580002,66.135582,-208.749100,-0.001582,0.003596,0.091345,294.185760,14.986537,0.913447,-208.749100,294.500488,0.000000
96.950005,66.061119,-208.838058,-0.001574,0.003596,0.091345,293.854523,14.969664,0.913447,-208.838058,294.500488,0.000000
97.320007,66.024254,-208.882553,-0.001569,0.003596,0.091345,293.690552,14.961309,0.913447,-208.882553,294.500488,0.000000
97.690002,65.919609,-208.838058,-0.001556,0.003597,0.091354,293.225067,14.937597,0.913537,-208.838058,294.500488,0.000000
98.060005,65.912910,-208.882553,-0.001565,0.003597,0.091370,293.195282,14.936079,0.913704,-208.882553,294.500488,0.000000
98.430008,65.835075,-208.927032,-0.001574,0.003597,0.091370,292.849030,14.918441,0.913704,-208.927032,294.500488,0.000000
98.800003,65.830238,-209.015991,-0.001561,0.003598,0.091379,292.827515,14.917345,0.913795,-209.015991,294.500488,0.000000
99.170006,65.781090,-209.060471,-0.001569,0.003599,0.091414,292.608887,14.906208,0.914143,-209.060471,294.500488,0.000000
99.540001,65.728951,-209.060471,-0.001569,0.003605,0.091561,292.376984,14.894393,0.915612,-209.060471,294.500488,0.000000
99.910004,65.676826,-209.060471,-0.001565,0.003608,0.091649,292.145111,14.882582,0.916490,-209.060471,294.500488,0.000000
100.280006,65.596397,-209.104950,-0.001569,0.003638,0.092412,291.787354,14.864356,0.924120,-209.104950,294.500488,0.000000
100.650002,65.568459,-209.149429,-0.001569,0.003646,0.092610,291.663055,14.858025,0.926103,-209.149429,294.500488,0.000000
101.020004,65.532341,-209.193909,-0.001582,0.003646,0.092610,291.502411,14.849841,0.926103,-209.193909,294.500488,0.000000
101.390007,65.502556,-209.193909,-0.001569,0.003647,0.092645,291.369934,14.843092,0.926451,-209.193909,294.500488,0.000000
101.760002,65.449303,-209.193909,-0.001565,0.003647,0.092645,291.133026,14.831024,0.926451,-209.193909,294.500488,0.000000
102.130005,65.381905,-209.282867,-0.001569,0.003664,0.093061,290.833252,14.815751,0.930615,-209.282867,294.500488,0.000000
102.500008,65.361794,-209.327362,-0.001578,0.003758,0.095447,290.743774,14.811193,0.954475,-209.327362,294.500488,0.000000
102.870003,65.338341,-209.416321,-0.001561,0.003761,0.095525,290.639465,14.805880,0.955247,-209.416321,294.500488,0.000000
103.240005,65.289558,-209.371841,-0.001561,0.003761,0.095525,290.422455,14.794826,0.955247,-209.371841,294.500488,0.000000
103.610008,65.272057,-209.416321,-0.001565,0.003761,0.095534,290.344604,14.790859,0.955338,-209.416321,294.500488,0.000000
103.980003,65.226997,-209.416321,-0.001582,0.003762,0.095560,290.144165,14.780648,0.955595,-209.416321,294.500488,0.000000
104.350006,65.189766,-209.460800,-0.001578,0.003762,0.095560,289.978577,14.772212,0.955595,-209.460800,294.500488,0.000000
104.720001,65.142464,-209.549759,-0.001569,0.003763,0.095569,289.768158,14.761494,0.955686,-209.549759,294.500488,0.000000
105.090004,65.119011,-209.460800,-0.001582,0.003768,0.095699,289.663818,14.756179,0.956988,-209.460800,294.500488,0.000000
105.460007,65.079903,-209.505280,-0.001569,0.003768,0.095699,289.489868,14.747316,0.956988,-209.505280,294.500488,0.000000
105.830002,65.038948,-209.594238,-0.001556,0.003768,0.095715,289.307678,14.738036,0.957155,-209.594238,294.500488,0.000000
106.200005,65.210243,-209.683197,-0.001574,0.003796,0.096409,290.069641,14.776852,0.964088,-209.683197,294.500488,0.000000
106.570007,65.211723,-209.727692,-0.001561,0.003796,0.096409,290.076233,14.777188,0.964088,-209.727692,294.500488,0.000000
106.940002,65.202049,-209.683197,-0.001565,0.003797,0.096453,290.033203,14.774996,0.964527,-209.683197,294.500488,0.000000
107.310005,65.196083,-209.683197,-0.001574,0.003797,0.096453,290.006653,14.773643,0.964527,-209.683197,294.500488,0.000000
107.680008,65.158852,-209.683197,-0.001561,0.003799,0.096497,289.841034,14.765207,0.964967,-209.683197,294.500488,0.000000
108.050003,65.343178,-209.861130,-0.001582,0.003802,0.096574,290.660980,14.806976,0.965739,-209.861130,294.500488,0.000000
108.420006,65.355461,-209.816650,-0.001574,0.003802,0.096574,290.715607,14.809759,0.965739,-209.816650,294.500488,0.000000
108.790009,65.332375,-209.905609,-0.001561,0.003802,0.096574,290.612915,14.804527,0.965739,-209.905609,294.500488,0.000000
109.160004,65.331627,-209.816650,-0.001561,0.003802,0.096574,290.609589,14.804358,0.965739,-209.816650,294.500488,0.000000
109.530006,65.298119,-209.861130,-0.001578,0.003802,0.096574,290.460541,14.796765,0.965739,-209.861130,294.500488,0.000000
109.900002,65.264977,-209.905609,-0.001569,0.003802,0.096583,290.313110,14.789255,0.965829,-209.905609,294.500488,0.000000
110.270004,65.266472,-210.039047,-0.001574,0.003802,0.096583,290.319763,14.789594,0.965829,-210.039047,294.500488,0.000000
110.640007,65.238914,-210.039047,-0.001565,0.003802,0.096583,290.197174,14.783349,0.965829,-210.039047,294.500488,0.000000
111.010002,65.215080,-210.039047,-0.001574,0.003802,0.096583,290.091156,14.777948,0.965829,-210.039047,294.500488,0.000000
111.380005,65.188271,-210.039047,-0.001569,0.003802,0.096583,289.971924,14.771873,0.965829,-210.039047,294.500488,0.000000
111.750008,65.155128,-210.128006,-0.001556,0.003802,0.096583,289.824493,14.764363,0.965829,-210.128006,294.500488,0.000000
112.120003,65.131294,-210.172501,-0.001574,0.003802,0.096583,289.718475,14.758963,0.965829,-210.172501,294.500488,0.000000
112.490005,65.098534,-210.172501,-0.001556,0.003802,0.096583,289.572754,14.751538,0.965829,-210.172501,294.500488,0.000000
112.860008,65.347267,-210.172501,-0.001561,0.003808,0.096730,290.679169,14.807902,0.967298,-210.172501,294.500488,0.000000
113.230003,65.393456,-210.216980,-0.001574,0.003808,0.096730,290.884613,14.818368,0.967298,-210.216980,294.500488,0.000000
113.600006,65.400154,-210.305939,-0.001569,0.003808,0.096730,290.914429,14.819886,0.967298,-210.305939,294.500488,0.000000
113.970009,65.386742,-210.350418,-0.001569,0.003808,0.096730,290.854767,14.816847,0.967298,-210.350418,294.500488,0.000000
114.340004,65.368126,-210.305939,-0.001569,0.003808,0.096730,290.771942,14.812629,0.967298,-210.305939,294.500488,0.000000
114.710007,65.352119,-210.350418,-0.001565,0.003808,0.096730,290.700745,14.809002,0.967298,-210.350418,294.500488,0.000000
115.080002,65.330513,-210.350418,-0.001565,0.003808,0.096730,290.604645,14.804106,0.967298,-210.350418,294.500488,0.000000
115.450005,65.311150,-210.483856,-0.001565,0.003808,0.096730,290.518494,14.799718,0.967298,-210.483856,294.500488,0.000000
115.820007,65.297005,-210.528336,-0.001574,0.003808,0.096730,290.455597,14.796514,0.967298,-210.528336,294.500488,0.000000
116.190002,65.276894,-210.483856,-0.001569,0.003808,0.096730,290.366119,14.791956,0.967298,-210.483856,294.500488,0.000000
116.560005,65.266090,-210.483856,-0.001561,0.003809,0.096739,290.318085,14.789508,0.967389,-210.483856,294.500488,0.000000
116.930008,65.255302,-210.572815,-0.001574,0.003809,0.096739,290.270081,14.787063,0.967389,-210.572815,294.500488,0.000000
117.300003,65.234077,-210.572815,-0.001578,0.003809,0.096739,290.175659,14.782253,0.967389,-210.572815,294.500488,0.000000
117.670006,65.221413,-210.617310,-0.001582,0.003809,0.096739,290.119324,14.779383,0.967389,-210.617310,294.500488,0.000000
118.040009,65.188637,-210.706268,-0.001561,0.003809,0.096739,289.973541,14.771956,0.967389,-210.706268,294.500488,0.000000
118.410004,65.192741,-210.661789,-0.001565,0.003809,0.096756,289.991791,14.772886,0.967555,-210.661789,294.500488,0.000000
118.780006,65.216942,-210.706268,-0.001565,0.003810,0.096783,290.099457,14.778370,0.967828,-210.706268,294.500488,0.000000
119.150009,65.210243,-210.750748,-0.001565,0.003810,0.096783,290.069641,14.776852,0.967828,-210.750748,294.500488,0.000000
119.520004,65.210991,-210.795227,-0.001574,0.003810,0.096783,290.072968,14.777021,0.967828,-210.795227,294.500488,0.000000
119.890007,65.209129,-210.839706,-0.001561,0.003810,0.096783,290.064697,14.776600,0.967828,-210.839706,294.500488,0.000000
120.260002,65.182320,-210.839706,-0.001561,0.003811,0.096790,289.945435,14.770525,0.967904,-210.839706,294.500488,0.000000
120.630005,65.183052,-210.884186,-0.001578,0.003811,0.096790,289.948700,14.770691,0.967904,-210.884186,294.500488,0.000000
121.000008,65.139870,-210.928665,-0.001565,0.003811,0.096799,289.756622,14.760905,0.967994,-210.928665,294.500488,0.000000
121.370003,65.144325,-210.973145,-0.001574,0.003811,0.096809,289.776428,14.761915,0.968085,-210.973145,294.500488,0.000000
121.740005,65.148430,-211.017639,-0.001569,0.003811,0.096809,289.794678,14.762845,0.968085,-211.017639,294.500488,0.000000
122.110008,65.163322,-210.973145,-0.001569,0.003812,0.096825,289.860931,14.766220,0.968252,-210.973145,294.500488,0.000000
122.480003,65.150291,-211.017639,-0.001578,0.003812,0.096834,289.802979,14.763268,0.968343,-211.017639,294.500488,0.000000
122.850006,65.196465,-211.106598,-0.001561,0.003806,0.096669,290.008362,14.773730,0.966692,-211.106598,0.096774,0.000000
123.220009,65.062782,-211.151077,-0.001556,0.003795,0.096383,289.413696,14.743437,0.963831,-211.151077,0.096158,0.000000
123.590004,65.101509,-211.151077,-0.001548,0.003778,0.095967,289.585968,14.752213,0.959668,-211.151077,0.095543,0.000000
123.960007,65.011024,-211.106598,-0.001552,0.003758,0.095455,289.183472,14.731709,0.954551,-211.106598,0.094927,0.000000
124.330009,64.970802,-211.195557,-0.001561,0.003733,0.094822,289.004578,14.722594,0.948222,-211.195557,0.094310,0.000000
124.700005,64.944374,-211.240036,-0.001561,0.003711,0.094267,288.886993,14.716606,0.942666,-211.240036,0.093694,0.000000
125.070007,64.892601,-211.284515,-0.001565,0.003685,0.093608,288.656708,14.704874,0.936080,-211.284515,0.093080,0.000000
125.440002,64.877708,-211.240036,-0.001544,0.003665,0.093096,288.590454,14.701499,0.930963,-211.240036,0.092454,0.000000
125.810005,64.853508,-211.328995,-0.001552,0.003639,0.092438,288.482819,14.696015,0.924377,-211.328995,0.091840,0.000000
126.180008,64.780144,-211.373474,-0.001561,0.003616,0.091856,288.156464,14.679390,0.918564,-211.373474,0.091224,0.000000
126.550003,64.772331,-211.373474,-0.001565,0.003594,0.091293,288.121704,14.677621,0.912932,-211.373474,0.090607,0.000000
126.920006,64.391396,-211.417953,-0.001561,0.003563,0.090512,286.427246,14.591298,0.905120,-211.417953,0.089991,0.000000
127.290009,64.005241,-211.462448,-0.001539,0.003547,0.090105,284.709534,14.503796,0.901047,-211.462448,0.089377,0.000000
127.660004,62.983452,-211.462448,-0.001535,0.003522,0.089454,280.164398,14.272254,0.894537,-211.462448,0.088760,0.000000
128.029999,61.987732,-211.551407,-0.001531,0.003504,0.088995,275.735199,14.046620,0.889950,-211.551407,0.088144,0.000000
128.400009,60.453552,-211.551407,-0.001535,0.003478,0.088353,268.910828,13.698971,0.883531,-211.551407,0.087529,0.000000
128.770004,58.937256,-211.640366,-0.001522,0.003459,0.087850,262.166016,13.355373,0.878504,-211.640366,0.086904,0.000000
129.139999,56.886223,-211.595886,-0.001513,0.003431,0.087148,253.042557,12.890602,0.871480,-211.595886,0.086290,0.000000
129.510010,55.358009,-211.595886,-0.001531,0.003417,0.086783,246.244720,12.544304,0.867831,-211.595886,0.085673,0.000000
129.880005,52.479202,-211.684845,-0.001522,0.003385,0.085976,233.439148,11.891957,0.859762,-211.684845,0.085057,0.000000
130.250000,50.246826,-211.729324,-0.001526,0.003367,0.085517,223.509048,11.386093,0.855174,-211.729324,0.084441,0.000000
130.620010,47.542282,-211.773804,-0.001518,0.003341,0.084857,211.478638,10.773235,0.848573,-211.773804,0.083826,0.000000
130.990005,44.471703,-211.729324,-0.001518,0.003309,0.084052,197.820007,10.077432,0.840519,-211.729324,0.083210,0.000000
131.360001,41.943291,-211.818283,-0.001522,0.003291,0.083583,186.573074,9.504486,0.835826,-211.818283,0.082594,0.000000
131.730011,39.567184,-211.818283,-0.001518,0.003266,0.082959,176.003632,8.966053,0.829588,-211.818283,0.081979,0.000000
132.100006,36.542778,-211.862762,-0.001518,0.003242,0.082343,162.550400,8.280712,0.823427,-211.862762,0.081354,0.000000
132.470001,33.776794,-211.907257,-0.001535,0.003217,0.081701,150.246689,7.653931,0.817007,-211.907257,0.080739,0.000000
132.840012,31.792793,-211.951736,-0.001526,0.003200,0.081268,141.421402,7.204350,0.812678,-211.951736,0.080123,0.000000
133.210007,29.038727,-211.907257,-0.001518,0.003174,0.080626,129.170715,6.580270,0.806258,-211.907257,0.079507,0.000000
133.580002,26.616440,-211.996216,-0.001518,0.003152,0.080054,118.395836,6.031371,0.800536,-211.996216,0.078891,0.000000
133.950012,23.836678,-212.040695,-0.001535,0.003125,0.079368,106.030838,5.401468,0.793677,-212.040695,0.078276,0.000000
134.320007,21.335083,-212.085175,-0.001522,0.003102,0.078779,94.903191,4.834599,0.787788,-212.085175,0.077660,0.000000
134.690002,18.554581,-212.040695,-0.001522,0.003077,0.078146,82.534897,4.204528,0.781460,-212.040695,0.077044,0.000000
135.060013,15.647469,-212.085175,-0.001518,0.003050,0.077478,69.603416,3.545767,0.774783,-212.085175,0.076429,0.000000
135.430008,13.780388,-212.129654,-0.001518,0.003030,0.076967,61.298225,3.122680,0.769666,-212.129654,0.075804,0.000000
135.800003,10.599586,-212.174133,-0.001531,0.003006,0.076341,47.149315,2.401901,0.763413,-212.174133,0.075188,0.000000
136.170013,7.212112,-212.263092,-0.001531,0.002973,0.075518,32.081078,1.634288,0.755177,-212.263092,0.074573,0.000000
136.540009,4.973785,-212.263092,-0.001544,0.002952,0.074971,22.124502,1.127076,0.749712,-212.263092,0.073957,0.000000
136.910004,2.386162,-212.263092,-0.001544,0.002926,0.074329,10.614178,0.540712,0.743293,-212.263092,0.073341,0.000000
137.280014,1.477577,-212.307587,-0.001556,0.002919,0.074131,6.572592,0.334824,0.741310,-212.307587,0.072726,0.000000
137.650009,-1.626892,-212.307587,-0.001569,0.002887,0.073333,-7.236777,-0.368659,0.733331,-212.307587,0.072110,0.000000
138.020004,-3.790375,-212.441025,-0.001569,0.002861,0.072673,-16.860430,-0.858911,0.726730,-212.441025,0.071494,0.000000
138.389999,-0.140381,-212.396545,-0.001604,0.002828,0.071824,-0.624445,-0.031811,0.718237,-212.396545,0.070879,0.000000
138.760010,0.004471,-212.441025,-0.001604,0.002811,0.071407,0.019887,0.001013,0.714073,-212.441025,0.070254,0.000000
139.130005,-0.016380,-212.485504,-0.001621,0.002785,0.070740,-0.072863,-0.003712,0.707397,-212.485504,0.069638,0.000000
139.500000,-0.129211,-212.485504,-0.001630,0.002757,0.070037,-0.574761,-0.029280,0.700372,-212.485504,0.069023,0.000000
139.870010,-0.024200,-212.529984,-0.001625,0.002739,0.069560,-0.107649,-0.005484,0.695603,-212.529984,0.068407,0.000000
140.240005,-0.075592,-212.574463,-0.001630,0.002709,0.068814,-0.336250,-0.017129,0.688139,-212.574463,0.067790,0.000000
140.610001,-0.029045,-212.574463,-0.001634,0.002689,0.068311,-0.129199,-0.006582,0.683113,-212.574463,0.067176,0.000000
140.980011,-0.024948,-212.618942,-0.001643,0.002664,0.067669,-0.110975,-0.005653,0.676694,-212.618942,0.066560,0.000000
141.350006,-0.042824,-212.663422,-0.001647,0.002639,0.067018,-0.190490,-0.009704,0.670184,-212.663422,0.065943,0.000000
141.720001,-0.077454,-212.707901,-0.001638,0.002604,0.066152,-0.344531,-0.017551,0.661524,-212.707901,0.065327,0.000000
142.090012,-0.105377,-212.663422,-0.001651,0.002583,0.065615,-0.468741,-0.023879,0.656149,-212.663422,0.064704,0.000000
142.460007,-0.063675,-212.707901,-0.001651,0.002564,0.065129,-0.283240,-0.014429,0.651290,-212.707901,0.064087,0.000000
142.830002,-0.059952,-212.752396,-0.001651,0.002539,0.064478,-0.266679,-0.013585,0.644780,-212.752396,0.063473,0.000000
143.200012,-0.056595,-212.796875,-0.001656,0.002515,0.063889,-0.251746,-0.012825,0.638890,-212.796875,0.062857,0.000000
143.570007,-0.106499,-212.885834,-0.001651,0.002490,0.063255,-0.473730,-0.024133,0.632547,-212.885834,0.062240,0.000000
143.940002,-0.119156,-212.885834,-0.001656,0.002464,0.062587,-0.530032,-0.027001,0.625870,-212.885834,0.061626,0.000000
144.310013,-0.116180,-212.930313,-0.001647,0.002440,0.061980,-0.516796,-0.026327,0.619799,-212.930313,0.061009,0.000000
144.680008,-0.106125,-212.930313,-0.001660,0.002419,0.061452,-0.472067,-0.024048,0.614516,-212.930313,0.060393,0.000000
145.050003,-0.106125,-212.974792,-0.001664,0.002391,0.060732,-0.472067,-0.024048,0.607324,-212.974792,0.059777,0.000000
145.420013,-0.117294,-213.019272,-0.001669,0.002368,0.060151,-0.521751,-0.026579,0.601511,-213.019272,0.059153,0.000000
145.790009,-0.120644,-213.063751,-0.001677,0.002342,0.059483,-0.536650,-0.027338,0.594834,-213.063751,0.058537,0.000000
146.160004,-0.140381,-213.063751,-0.001686,0.002320,0.058928,-0.624445,-0.031811,0.589278,-213.063751,0.057923,0.000000
146.530014,-0.133682,-213.108231,-0.001699,0.002291,0.058181,-0.594648,-0.030293,0.581814,-213.108231,0.057306,0.000000
146.900009,-0.150810,-213.108231,-0.001703,0.002274,0.057765,-0.670837,-0.034174,0.577651,-213.108231,0.056690,0.000000
147.270004,-0.171288,-213.108231,-0.001720,0.002248,0.057090,-0.761925,-0.038814,0.570898,-213.108231,0.056074,0.000000
147.639999,-0.149315,-213.241684,-0.001733,0.002227,0.056578,-0.664186,-0.033835,0.565781,-213.241684,0.055459,0.000000
148.010010,-0.124367,-213.197205,-0.001746,0.002197,0.055815,-0.553211,-0.028182,0.558151,-213.197205,0.054843,0.000000
148.380005,-0.147827,-213.241684,-0.001763,0.002169,0.055104,-0.657568,-0.033498,0.551035,-213.241684,0.054219,0.000000
148.750000,-0.149689,-213.241684,-0.001789,0.002154,0.054722,-0.665849,-0.033920,0.547220,-213.241684,0.053603,0.000000
149.120010,-0.137032,-213.330643,-0.001798,0.002123,0.053933,-0.609547,-0.031052,0.539332,-213.330643,0.052987,0.000000
149.490005,-0.133308,-213.330643,-0.001832,0.002107,0.053517,-0.592985,-0.030208,0.535169,-213.330643,0.052372,0.000000
149.860001,-0.176498,-213.375122,-0.001850,0.002076,0.052727,-0.785104,-0.039995,0.527266,-213.375122,0.051756,0.000000
150.230011,-0.183952,-213.375122,-0.001867,0.002055,0.052207,-0.818261,-0.041684,0.522073,-213.375122,0.051140,0.000000
150.600006,-0.194374,-213.464081,-0.001901,0.002028,0.051512,-0.864619,-0.044046,0.515124,-213.464081,0.050524,0.000000
150.970001,-0.170174,-213.419601,-0.001919,0.002013,0.051123,-0.756970,-0.038562,0.511233,-213.419601,0.049909,0.000000
151.340012,-0.154533,-213.597534,-0.001953,0.001979,0.050272,-0.687399,-0.035018,0.502725,-213.597534,0.049293,0.000000
151.710007,-0.173149,-213.553040,-0.001966,0.001954,0.049623,-0.770206,-0.039236,0.496230,-213.553040,0.048669,0.000000
152.080002,-0.187675,-213.508560,-0.001983,0.001930,0.049016,-0.834822,-0.042528,0.490159,-213.508560,0.048053,0.000000
152.450012,-0.164955,-213.553040,-0.002009,0.001904,0.048365,-0.733757,-0.037379,0.483649,-213.553040,0.047437,0.000000
152.600006,-0.129211,-213.642014,-0.002018,0.001903,0.048330,-0.574761,-0.029280,0.483301,-213.642014,0.048218,0.000000