File: Data/compression 30/AutoNoHeating-17-30-reverse-1-2_10242024_162600.csv
Time (sec),S:Load (lbs),S:HL1 (DIM),S:LVDT (in),S:Position (in),Ch:Position (mm),Ch:Load (N),Ch:Stress (MPa),Ch:Strain (mm/mm),Ch:HL1 (DIM),Set Point (),Cycles ()
0.010000,-0.000366,-159.820053,-0.012210,-0.007560,-0.192030,-0.001629,-0.000083,-1.920304,-159.820053,-0.191761,0.000000
0.390000,-0.042450,-159.909012,-0.012215,-0.007545,-0.191649,-0.188827,-0.009619,-1.916489,-159.909012,-0.190912,0.000000
0.770000,-0.110962,-159.953506,-0.012150,-0.007319,-0.185899,-0.493583,-0.025144,-1.858989,-159.953506,-0.184580,0.000000
1.150000,-0.094208,-159.997986,-0.011874,-0.007063,-0.179412,-0.419057,-0.021348,-1.794116,-159.997986,-0.178249,0.000000
1.530000,-0.052872,-160.042465,-0.011620,-0.006815,-0.173107,-0.235185,-0.011981,-1.731075,-160.042465,-0.171919,0.000000
1.910000,-0.039093,-160.086945,-0.011339,-0.006565,-0.166741,-0.173894,-0.008859,-1.667413,-160.086945,-0.165588,0.000000
2.290000,-0.062553,-160.131424,-0.011106,-0.006321,-0.160549,-0.278251,-0.014175,-1.605492,-160.131424,-0.159258,0.000000
2.670000,-0.089363,-160.175903,-0.010843,-0.006074,-0.154271,-0.397507,-0.020250,-1.542708,-160.175903,-0.152926,0.000000
3.050000,-0.106865,-160.175903,-0.010602,-0.005819,-0.147809,-0.475359,-0.024216,-1.478092,-160.175903,-0.146597,0.000000
3.430000,-0.037605,-160.264862,-0.010343,-0.005566,-0.141375,-0.167277,-0.008521,-1.413749,-160.264862,-0.140265,0.000000
3.810000,-0.022713,-160.353836,-0.010067,-0.005314,-0.134975,-0.101031,-0.005147,-1.349754,-160.353836,-0.133934,0.000000
4.190000,0.001495,-160.398315,-0.009839,-0.005073,-0.128861,0.006652,0.000339,-1.288605,-160.398315,-0.127604,0.000000
4.570000,-0.029785,-160.442795,-0.009593,-0.004824,-0.122540,-0.132491,-0.006749,-1.225398,-160.442795,-0.121273,0.000000
4.950000,-0.050270,-160.487274,-0.009343,-0.004573,-0.116148,-0.223612,-0.011391,-1.161478,-160.487274,-0.114943,0.000000
5.330000,-0.046547,-160.442795,-0.009076,-0.004321,-0.109765,-0.207051,-0.010548,-1.097650,-160.442795,-0.108611,0.000000
5.710000,-0.000366,-160.576233,-0.008826,-0.004079,-0.103599,-0.001629,-0.000083,-1.035986,-160.576233,-0.102280,0.000000
6.090000,0.017136,-160.665192,-0.008563,-0.003825,-0.097146,0.076223,0.003883,-0.971461,-160.665192,-0.095950,0.000000
6.470000,-0.000740,-160.665192,-0.008321,-0.003580,-0.090928,-0.003292,-0.000168,-0.909283,-160.665192,-0.089619,0.000000
6.850000,0.005585,-160.709671,-0.008054,-0.003330,-0.084589,0.024842,0.001266,-0.845894,-160.709671,-0.083289,0.000000
7.230000,-0.015266,-160.620712,-0.007804,-0.003081,-0.078267,-0.067908,-0.003459,-0.782671,-160.620712,-0.076958,0.000000
7.610000,0.019363,-160.709671,-0.007558,-0.002833,-0.071963,0.086133,0.004388,-0.719630,-160.709671,-0.070626,0.000000
7.990000,0.005219,-160.843124,-0.007278,-0.002582,-0.065588,0.023213,0.001183,-0.655877,-160.843124,-0.064296,0.000000
8.370001,-0.004837,-160.887604,-0.006998,-0.002328,-0.059119,-0.021516,-0.001096,-0.591185,-160.887604,-0.057965,0.000000
8.750000,-0.023827,-160.887604,-0.006769,-0.002087,-0.053022,-0.105986,-0.005399,-0.530218,-160.887604,-0.051635,0.000000
9.130000,-0.055107,-160.887604,-0.006497,-0.001834,-0.046578,-0.245129,-0.012487,-0.465784,-160.887604,-0.045304,0.000000
9.510000,-0.078568,-160.976562,-0.006226,-0.001584,-0.040221,-0.349486,-0.017804,-0.402213,-160.976562,-0.038974,0.000000
9.890000,-0.009682,-161.065521,-0.005971,-0.001330,-0.033778,-0.043066,-0.002194,-0.337779,-161.065521,-0.032642,0.000000
10.270000,-0.010796,-161.110001,-0.005726,-0.001080,-0.027430,-0.048021,-0.002446,-0.274299,-161.110001,-0.026311,0.000000
10.650001,0.005585,-161.110001,-0.005489,-0.000840,-0.021326,0.024842,0.001266,-0.213256,-161.110001,-0.019981,0.000000
11.030001,-0.034630,-161.198959,-0.005226,-0.000593,-0.015064,-0.154041,-0.007847,-0.150639,-161.198959,-0.013650,0.000000
11.410001,-0.077454,-161.243454,-0.004963,-0.000344,-0.008725,-0.344531,-0.017551,-0.087249,-161.243454,-0.007320,0.000000
11.790001,-0.032394,-161.287933,-0.004695,-0.000085,-0.002151,-0.144098,-0.007341,-0.021513,-161.287933,-0.000989,0.000000
12.170001,0.041336,-161.332413,-0.004583,-0.000002,-0.000053,0.183872,0.009367,-0.000530,-161.332413,0.000173,0.000000
12.550000,0.157890,-161.332413,-0.004570,-0.000002,-0.000053,0.702331,0.035778,-0.000530,-161.332413,0.000277,0.000000
12.930000,0.116928,-161.376892,-0.004570,-0.000002,-0.000044,0.520122,0.026496,-0.000439,-161.376892,0.000910,0.000000
13.310000,0.183586,-161.421371,-0.004562,0.000020,0.000519,0.816632,0.041601,0.005193,-161.421371,0.001543,0.000000
13.690001,0.412964,-161.554810,-0.004557,0.000049,0.001249,1.836955,0.093579,0.012490,-161.554810,0.002176,0.000000
14.070001,0.595802,-161.599289,-0.004557,0.000067,0.001699,2.650261,0.135011,0.016987,-161.599289,0.002817,0.000000
14.450001,0.890343,-161.510330,-0.004506,0.000096,0.002445,3.960442,0.201755,0.024450,-161.510330,0.003452,0.000000
14.830001,1.263092,-161.643784,-0.004497,0.000123,0.003122,5.618514,0.286221,0.031218,-161.643784,0.004085,0.000000
15.210001,1.677910,-161.688263,-0.004471,0.000147,0.003746,7.463716,0.380220,0.037455,-161.688263,0.004717,0.000000
15.590001,2.130348,-161.777222,-0.004441,0.000173,0.004387,9.476262,0.482744,0.043875,-161.777222,0.005350,0.000000
15.970001,2.532135,-161.777222,-0.004437,0.000192,0.004873,11.263499,0.573790,0.048734,-161.777222,0.005983,0.000000
16.350000,3.159958,-161.777222,-0.004411,0.000224,0.005680,14.056194,0.716057,0.056804,-161.777222,0.006616,0.000000
16.730001,3.625046,-161.821701,-0.004376,0.000249,0.006330,16.125010,0.821447,0.063299,-161.821701,0.007249,0.000000
17.110001,4.156799,-161.910660,-0.004359,0.000274,0.006955,18.490366,0.941944,0.069551,-161.910660,0.007883,0.000000
17.490002,4.854622,-161.955139,-0.004342,0.000300,0.007623,21.594437,1.100073,0.076228,-161.955139,0.008516,0.000000
17.870001,5.291046,-162.044098,-0.004333,0.000322,0.008177,23.535749,1.198968,0.081769,-162.044098,0.009149,0.000000
18.250000,6.003395,-161.999619,-0.004316,0.000350,0.008898,26.704435,1.360389,0.088975,-161.999619,0.009782,0.000000
18.630001,6.474068,-161.999619,-0.004286,0.000372,0.009461,28.798092,1.467045,0.094607,-161.999619,0.010415,0.000000
19.010000,6.985710,-162.088593,-0.004255,0.000396,0.010059,31.073990,1.582985,0.100587,-162.088593,0.011047,0.000000
19.390001,7.764343,-162.177551,-0.004255,0.000423,0.010754,34.537525,1.759425,0.107536,-162.177551,0.011682,0.000000
19.770000,8.215286,-162.222031,-0.004225,0.000445,0.011308,36.543419,1.861610,0.113078,-162.222031,0.012315,0.000000
20.150002,8.777565,-162.266510,-0.004208,0.000467,0.011863,39.044559,1.989025,0.118634,-162.266510,0.012947,0.000000
20.530001,9.348412,-162.266510,-0.004174,0.000492,0.012505,41.583813,2.118380,0.125053,-162.266510,0.013580,0.000000
20.910002,9.977722,-162.399948,-0.004165,0.000516,0.013112,44.383125,2.260984,0.131124,-162.399948,0.014213,0.000000
21.290001,10.843864,-162.399948,-0.004152,0.000548,0.013918,48.235920,2.457255,0.139178,-162.399948,0.014846,0.000000
21.670000,10.968605,-162.399948,-0.004135,0.000566,0.014378,48.790791,2.485521,0.143781,-162.399948,0.015480,0.000000
22.050001,11.480247,-162.488907,-0.004100,0.000588,0.014941,51.066692,2.601461,0.149413,-162.488907,0.016113,0.000000
22.430000,12.187012,-162.488907,-0.004087,0.000615,0.015618,54.210537,2.761616,0.156180,-162.488907,0.016746,0.000000
22.810001,12.735512,-162.488907,-0.004070,0.000644,0.016346,56.650387,2.885908,0.163462,-162.488907,0.017379,0.000000
23.190001,12.448044,-162.666840,-0.004049,0.000650,0.016511,55.371666,2.820767,0.165112,-162.666840,0.018012,0.000000
23.570002,13.346207,-162.711319,-0.004023,0.000688,0.017465,59.366894,3.024294,0.174650,-162.711319,0.018644,0.000000
23.950001,14.084618,-162.666840,-0.004001,0.000714,0.018133,62.651508,3.191620,0.181327,-162.666840,0.019277,0.000000
24.330002,14.937355,-162.711319,-0.003971,0.000743,0.018870,66.444672,3.384853,0.188700,-162.711319,0.019912,0.000000
24.710001,15.076248,-162.800278,-0.003958,0.000762,0.019347,67.062500,3.416327,0.193469,-162.800278,0.020553,0.000000
25.090002,15.049065,-162.844757,-0.003936,0.000777,0.019737,66.941582,3.410167,0.197375,-162.844757,0.021186,0.000000
25.470001,15.773697,-162.933731,-0.003911,0.000803,0.020396,70.164909,3.574371,0.203960,-162.933731,0.021819,0.000000
25.850000,16.547493,-162.933731,-0.003898,0.000839,0.021298,73.606926,3.749715,0.212984,-162.933731,0.022452,0.000000
26.230001,17.104935,-162.978210,-0.003872,0.000867,0.022019,76.086548,3.876034,0.220190,-162.978210,0.023085,0.000000
26.610001,17.132858,-162.978210,-0.003846,0.000888,0.022556,76.210762,3.882361,0.225565,-162.978210,0.023718,0.000000
26.990002,17.648224,-163.067169,-0.003816,0.000913,0.023180,78.503220,3.999145,0.231802,-163.067169,0.024350,0.000000
27.370001,18.160980,-163.111649,-0.003803,0.000942,0.023927,80.784073,4.115337,0.239266,-163.111649,0.024985,0.000000
27.750002,18.298386,-163.156128,-0.003764,0.000965,0.024516,81.395287,4.146473,0.245155,-163.156128,0.025618,0.000000
28.130001,19.060257,-163.111649,-0.003747,0.000997,0.025313,84.784256,4.319116,0.253134,-163.111649,0.026251,0.000000
28.510002,18.702782,-163.245087,-0.003721,0.001012,0.025695,83.194130,4.238111,0.256949,-163.245087,0.026883,0.000000
28.890001,19.192078,-163.245087,-0.003695,0.001038,0.026372,85.370628,4.348987,0.263716,-163.245087,0.027516,0.000000
29.270000,19.562218,-163.378540,-0.003682,0.001063,0.027004,87.017090,4.432862,0.270045,-163.378540,0.028149,0.000000
29.650002,19.917458,-163.378540,-0.003656,0.001089,0.027655,88.597275,4.513361,0.276555,-163.378540,0.028783,0.000000
30.030001,20.741150,-163.467499,-0.003639,0.001122,0.028505,92.261246,4.700012,0.285048,-163.467499,0.029416,0.000000
30.410002,20.286110,-163.467499,-0.003600,0.001143,0.029026,90.237122,4.596898,0.290256,-163.467499,0.030049,0.000000
30.790001,20.503578,-163.556458,-0.003566,0.001166,0.029624,91.204468,4.646177,0.296236,-163.556458,0.030682,0.000000
31.170002,20.585495,-163.556458,-0.003557,0.001186,0.030126,91.568855,4.664740,0.301262,-163.556458,0.031315,0.000000
31.550001,20.912437,-163.689896,-0.003527,0.001213,0.030803,93.023170,4.738826,0.308030,-163.689896,0.031948,0.000000
31.930002,21.920456,-163.645416,-0.003497,0.001251,0.031775,97.507057,4.967247,0.317750,-163.645416,0.032582,0.000000
32.310001,21.279968,-163.734375,-0.003458,0.001271,0.032278,94.658028,4.822110,0.322776,-163.734375,0.033215,0.000000
32.690002,21.471741,-163.778854,-0.003432,0.001295,0.032894,95.511070,4.865566,0.328938,-163.778854,0.033848,0.000000
33.070000,21.488876,-163.823349,-0.003419,0.001316,0.033431,95.587296,4.869449,0.334312,-163.823349,0.034480,0.000000
33.450001,21.394661,-163.823349,-0.003415,0.001336,0.033943,95.168205,4.848100,0.339429,-163.823349,0.035113,0.000000
33.830002,22.223564,-163.867828,-0.003367,0.001367,0.034732,98.855354,5.035932,0.347317,-163.867828,0.035746,0.000000
34.210003,22.342354,-163.867828,-0.003341,0.001393,0.035383,99.383751,5.062850,0.353827,-163.867828,0.036379,0.000000
34.590000,22.350174,-163.956787,-0.003311,0.001416,0.035955,99.418541,5.064622,0.359550,-163.956787,0.037013,0.000000
34.970001,22.780258,-164.001266,-0.003294,0.001445,0.036692,101.331650,5.162080,0.366923,-164.001266,0.037646,0.000000
35.350002,22.514389,-164.045746,-0.003264,0.001464,0.037186,100.149002,5.101833,0.371858,-164.045746,0.038279,0.000000
35.730003,23.194336,-164.045746,-0.003255,0.001492,0.037906,103.173561,5.255911,0.379065,-164.045746,0.038921,0.000000
36.110001,23.361160,-164.134705,-0.003212,0.001518,0.038556,103.915634,5.293715,0.385560,-164.134705,0.039554,0.000000
36.490002,23.402870,-164.223679,-0.003182,0.001544,0.039216,104.101166,5.303166,0.392161,-164.223679,0.040186,0.000000
36.870003,23.775612,-164.312637,-0.003147,0.001569,0.039849,105.759201,5.387630,0.398489,-164.312637,0.040819,0.000000
37.250000,23.645279,-164.312637,-0.003134,0.001589,0.040361,105.179451,5.358097,0.403606,-164.312637,0.041452,0.000000
37.630001,24.412743,-164.357117,-0.003109,0.001620,0.041140,108.593300,5.532006,0.411403,-164.357117,0.042087,0.000000
38.010002,24.486847,-164.357117,-0.003083,0.001644,0.041766,108.922935,5.548799,0.417656,-164.357117,0.042719,0.000000
38.390003,24.644730,-164.401596,-0.003061,0.001669,0.042380,109.625229,5.584575,0.423802,-164.401596,0.043352,0.000000
38.770000,24.948212,-164.579514,-0.003040,0.001697,0.043101,110.975189,5.653346,0.431009,-164.579514,0.043985,0.000000
39.150002,24.503975,-164.579514,-0.003009,0.001715,0.043552,108.999123,5.552680,0.435520,-164.579514,0.044618,0.000000
39.530003,25.516083,-164.579514,-0.002979,0.001744,0.044297,113.501205,5.782027,0.442969,-164.579514,0.045251,0.000000
39.910004,25.604706,-164.535034,-0.002945,0.001771,0.044983,113.895416,5.802109,0.449827,-164.535034,0.045885,0.000000
40.290001,25.576035,-164.623993,-0.002919,0.001791,0.045494,113.767883,5.795612,0.454944,-164.623993,0.046518,0.000000
40.670002,26.186722,-164.712967,-0.002910,0.001820,0.046223,116.484360,5.933996,0.462227,-164.712967,0.047151,0.000000
41.050003,25.678062,-164.801926,-0.002889,0.001837,0.046656,114.221725,5.818732,0.466556,-164.801926,0.047784,0.000000
41.430000,26.451111,-164.757446,-0.002867,0.001866,0.047385,117.660416,5.993907,0.473854,-164.757446,0.048416,0.000000
41.810001,26.545692,-164.757446,-0.002833,0.001889,0.047992,118.081139,6.015340,0.479925,-164.757446,0.049049,0.000000
42.190002,26.827576,-164.846405,-0.002811,0.001913,0.048590,119.335014,6.079216,0.485905,-164.846405,0.049684,0.000000
42.570004,27.793510,-164.979843,-0.002785,0.001945,0.049397,123.631706,6.298100,0.493974,-164.979843,0.050316,0.000000
42.950001,27.336235,-164.979843,-0.002764,0.001964,0.049882,121.597649,6.194479,0.498819,-164.979843,0.050949,0.000000
43.330002,27.512367,-165.024323,-0.002751,0.001987,0.050463,122.381119,6.234391,0.504632,-165.024323,0.051582,0.000000
43.710003,27.824791,-164.979843,-0.002712,0.002011,0.051079,123.770851,6.305188,0.510794,-164.979843,0.052215,0.000000
44.090004,28.032944,-165.113297,-0.002682,0.002040,0.051817,124.696762,6.352356,0.518167,-165.113297,0.052848,0.000000
44.470001,27.189148,-165.157776,-0.002665,0.002049,0.052033,120.943367,6.161149,0.520332,-165.157776,0.053482,0.000000
44.850002,27.706375,-165.157776,-0.002660,0.002074,0.052684,123.244110,6.278355,0.526842,-165.157776,0.054115,0.000000
45.230003,28.599701,-165.246735,-0.002621,0.002107,0.053508,127.217827,6.480785,0.535078,-165.246735,0.054748,0.000000
45.610001,28.413887,-165.202255,-0.002604,0.002125,0.053976,126.391281,6.438679,0.539756,-165.202255,0.055381,0.000000
45.990002,29.418541,-165.291214,-0.002561,0.002159,0.054834,130.860199,6.666337,0.548340,-165.291214,0.056013,0.000000
46.370003,28.833923,-165.380173,-0.002544,0.002175,0.055234,128.259689,6.533861,0.552337,-165.380173,0.056646,0.000000
46.750004,29.496368,-165.424652,-0.002522,0.002202,0.055927,131.206406,6.683972,0.559271,-165.424652,0.057288,0.000000
47.130001,30.179298,-165.469131,-0.002492,0.002234,0.056742,134.244217,6.838727,0.567416,-165.469131,0.057921,0.000000
47.510002,31.056610,-165.469131,-0.002462,0.002267,0.057592,138.146698,7.037529,0.575925,-165.469131,0.058555,0.000000
47.890003,30.749031,-165.469131,-0.002440,0.002286,0.058077,136.778519,6.967830,0.580769,-165.469131,0.059188,0.000000
48.270000,31.125496,-165.558105,-0.002423,0.002311,0.058702,138.453125,7.053138,0.587022,-165.558105,0.059821,0.000000
48.650002,31.624107,-165.647064,-0.002410,0.002337,0.059370,140.671051,7.166125,0.593699,-165.647064,0.060454,0.000000
49.030003,31.590591,-165.647064,-0.002384,0.002358,0.059891,140.521973,7.158530,0.598907,-165.647064,0.061087,0.000000
49.410004,32.838783,-165.691544,-0.002358,0.002393,0.060784,146.074203,7.441374,0.607839,-165.691544,0.061720,0.000000
49.790001,32.455986,-165.736023,-0.002320,0.002410,0.061217,144.371429,7.354631,0.612169,-165.736023,0.062352,0.000000
50.170002,32.927040,-165.780502,-0.002320,0.002437,0.061894,146.466797,7.461374,0.618936,-165.780502,0.062987,0.000000
50.550003,33.321754,-165.913940,-0.002294,0.002459,0.062466,148.222565,7.550817,0.624659,-165.913940,0.063620,0.000000
50.930004,33.783493,-165.913940,-0.002285,0.002484,0.063099,150.276489,7.655449,0.630987,-165.913940,0.064252,0.000000
51.310001,34.596756,-165.913940,-0.002264,0.002514,0.063853,153.894058,7.839737,0.638527,-165.913940,0.064885,0.000000
51.690002,34.905823,-165.913940,-0.002225,0.002537,0.064443,155.268860,7.909772,0.644431,-165.913940,0.065518,0.000000
52.070004,34.904709,-166.002914,-0.002207,0.002558,0.064981,155.263901,7.909520,0.649806,-166.002914,0.066151,0.000000
52.450001,35.818512,-166.047394,-0.002199,0.002585,0.065648,159.328705,8.116590,0.656482,-166.047394,0.066785,0.000000
52.830002,36.291420,-166.091873,-0.002182,0.002609,0.066264,161.432297,8.223754,0.662644,-166.091873,0.067418,0.000000
53.210003,37.389923,-166.091873,-0.002151,0.002638,0.067002,166.318680,8.472678,0.670017,-166.091873,0.068051,0.000000
53.590004,37.853149,-166.136353,-0.002143,0.002666,0.067712,168.379211,8.577646,0.677118,-166.136353,0.068684,0.000000
53.970001,37.755592,-166.225311,-0.002121,0.002685,0.068190,167.945267,8.555539,0.681902,-166.225311,0.069317,0.000000
54.350002,38.661949,-166.314270,-0.002091,0.002714,0.068926,171.976944,8.760923,0.689260,-166.314270,0.069949,0.000000
54.730003,38.475761,-166.314270,-0.002104,0.002732,0.069395,171.148727,8.718732,0.693953,-166.314270,0.070584,0.000000
55.110004,38.624336,-166.314270,-0.002082,0.002750,0.069854,171.809631,8.752399,0.698540,-166.314270,0.071217,0.000000
55.490002,40.632172,-166.403244,-0.002061,0.002788,0.070817,180.740921,9.207382,0.708169,-166.403244,0.071849,0.000000
55.870003,41.097260,-166.403244,-0.002044,0.002813,0.071459,182.809738,9.312772,0.714588,-166.403244,0.072482,0.000000
56.250004,41.920204,-166.536682,-0.002022,0.002841,0.072161,186.470383,9.499254,0.721613,-166.536682,0.073115,0.000000
56.630001,41.687469,-166.581161,-0.002018,0.002859,0.072629,185.435120,9.446516,0.726291,-166.581161,0.073748,0.000000
57.010002,42.784111,-166.581161,-0.001983,0.002888,0.073366,190.313232,9.695018,0.733664,-166.581161,0.074381,0.000000
57.390003,43.410812,-166.714600,-0.001975,0.002914,0.074026,193.100937,9.837031,0.740265,-166.714600,0.075015,0.000000
57.770004,43.877769,-166.625641,-0.001966,0.002937,0.074606,195.178070,9.942844,0.746063,-166.625641,0.075657,0.000000
58.150002,44.559578,-166.759079,-0.001953,0.002963,0.075248,198.210907,10.097344,0.752483,-166.759079,0.076290,0.000000
58.530003,44.686188,-166.759079,-0.001932,0.002983,0.075769,198.774094,10.126035,0.757691,-166.759079,0.076923,0.000000
58.910004,46.227440,-166.848053,-0.001927,0.003016,0.076611,205.629929,10.475287,0.766108,-166.848053,0.077556,0.000000
59.290001,46.814293,-166.848053,-0.001897,0.003041,0.077235,208.240372,10.608271,0.772346,-166.848053,0.078188,0.000000
59.670002,47.270454,-166.892532,-0.001880,0.003065,0.077842,210.269485,10.711637,0.778417,-166.892532,0.078821,0.000000
60.050003,48.041260,-166.981491,-0.001880,0.003091,0.078518,213.698196,10.886305,0.785184,-166.981491,0.079454,0.000000
60.430004,48.393898,-166.981491,-0.001863,0.003108,0.078944,215.266815,10.966214,0.789438,-166.981491,0.080088,0.000000
60.810001,49.721039,-167.025970,-0.001858,0.003141,0.079793,221.170227,11.266948,0.797932,-167.025970,0.080721,0.000000
61.190002,50.399124,-167.025970,-0.001824,0.003163,0.080340,224.186508,11.420605,0.803397,-167.025970,0.081354,0.000000
61.570004,51.170685,-167.070450,-0.001807,0.003189,0.080998,227.618576,11.595443,0.809983,-167.070450,0.081987,0.000000
61.950005,52.214066,-167.114929,-0.001789,0.003218,0.081726,232.259766,11.831876,0.817265,-167.114929,0.082620,0.000000
62.330002,52.393555,-167.203888,-0.001789,0.003234,0.082143,233.058167,11.872549,0.821428,-167.203888,0.083253,0.000000
62.710003,53.389275,-167.248383,-0.001789,0.003262,0.082845,237.487350,12.098183,0.828453,-167.248383,0.083887,0.000000
63.090004,54.207748,-167.248383,-0.001763,0.003283,0.083392,241.128113,12.283651,0.833918,-167.248383,0.084520,0.000000
63.470001,55.048943,-167.292862,-0.001768,0.003307,0.083999,244.869919,12.474269,0.839989,-167.292862,0.085153,0.000000
63.850002,56.380547,-167.337341,-0.001742,0.003339,0.084806,250.793198,12.776014,0.848059,-167.337341,0.085785,0.000000
64.230003,57.419464,-167.470779,-0.001703,0.003359,0.085325,255.414536,13.011436,0.853252,-167.470779,0.086418,0.000000
64.610001,57.805244,-167.470779,-0.001699,0.003381,0.085872,257.130554,13.098855,0.858717,-167.470779,0.087051,0.000000
64.990005,59.475708,-167.426300,-0.001699,0.003411,0.086627,264.561157,13.477388,0.866272,-167.426300,0.087685,0.000000
65.370003,60.358597,-167.470779,-0.001690,0.003432,0.087165,268.488434,13.677454,0.871646,-167.470779,0.088318,0.000000
65.750000,60.666550,-167.559738,-0.001673,0.003447,0.087555,269.858276,13.747236,0.875552,-167.559738,0.088951,0.000000
66.130005,61.937462,-167.648712,-0.001664,0.003471,0.088162,275.511597,14.035230,0.881623,-167.648712,0.089584,0.000000
66.510002,63.925179,-167.693192,-0.001647,0.003502,0.088960,284.353394,14.485652,0.889602,-167.693192,0.090217,0.000000
66.889999,65.171135,-167.648712,-0.001643,0.003528,0.089610,289.895691,14.767991,0.896097,-167.648712,0.090850,0.000000
67.270004,65.551704,-167.693192,-0.001608,0.003536,0.089819,291.588531,14.854228,0.898186,-167.693192,0.015766,0.000000
67.650002,65.481331,-167.782150,-0.001617,0.003552,0.090226,291.275513,14.838282,0.902258,-167.782150,294.500488,0.000000
68.030006,64.870644,-167.871109,-0.001608,0.003558,0.090373,288.559021,14.699898,0.903727,-167.871109,294.500488,0.000000
68.410004,64.995384,-167.871109,-0.001591,0.003569,0.090659,289.113922,14.728165,0.906588,-167.871109,294.500488,0.000000
68.790001,64.515388,-167.915588,-0.001582,0.003573,0.090747,286.978790,14.619396,0.907466,-167.915588,294.500488,0.000000
69.170006,66.191444,-168.004547,-0.001556,0.003550,0.090182,294.434235,14.999196,0.901819,-168.004547,294.500488,0.000000
69.550003,65.256783,-167.960068,-0.001565,0.003554,0.090261,290.276672,14.787398,0.902607,-167.960068,294.500488,0.000000
69.930000,65.612404,-168.049026,-0.001565,0.003603,0.091526,291.858551,14.867983,0.915263,-168.049026,294.500488,0.000000
70.310005,65.229607,-168.138000,-0.001569,0.003602,0.091492,290.155792,14.781240,0.914915,-168.138000,294.500488,0.000000
70.690002,64.605873,-168.182480,-0.001561,0.003602,0.091492,287.381287,14.639900,0.914915,-168.182480,294.500488,0.000000
71.070000,66.580940,-168.182480,-0.001531,0.003563,0.090503,296.166809,15.087457,0.905029,-168.182480,294.500488,0.000000
71.450005,65.842903,-168.182480,-0.001531,0.003563,0.090512,292.883850,14.920215,0.905120,-168.182480,294.500488,0.000000
71.830002,65.275032,-168.271439,-0.001535,0.003583,0.090998,290.357849,14.791533,0.909980,-168.271439,294.500488,0.000000
72.210007,64.817757,-168.360397,-0.001544,0.003604,0.091544,288.323792,14.687914,0.915445,-168.360397,294.500488,0.000000
72.590004,65.350990,-168.360397,-0.001526,0.003632,0.092247,290.695709,14.808746,0.922470,-168.360397,294.500488,0.000000
72.970001,64.978249,-168.404877,-0.001526,0.003632,0.092255,289.037689,14.724281,0.922545,-168.404877,294.500488,0.000000
73.350006,65.707726,-168.404877,-0.001518,0.003648,0.092663,292.282562,14.889584,0.926633,-168.404877,294.500488,0.000000
73.730003,65.606438,-168.538330,-0.001513,0.003648,0.092663,291.832001,14.866632,0.926633,-168.538330,294.500488,0.000000
74.110001,65.284340,-168.538330,-0.001505,0.003648,0.092663,290.399261,14.793643,0.926633,-168.538330,294.500488,0.000000
74.490005,64.976021,-168.582809,-0.001526,0.003648,0.092671,289.027771,14.723777,0.926709,-168.582809,294.500488,0.000000
74.870003,64.680733,-168.582809,-0.001522,0.003648,0.092671,287.714264,14.656863,0.926709,-168.582809,294.500488,0.000000
75.250000,64.356758,-168.627289,-0.001505,0.003649,0.092680,286.273163,14.583450,0.926800,-168.627289,294.500488,0.000000
75.630005,66.563820,-168.760727,-0.001479,0.003580,0.090928,296.090668,15.083577,0.909283,-168.760727,294.500488,0.000000
76.010002,66.178780,-168.760727,-0.001487,0.003580,0.090937,294.377899,14.996325,0.909374,-168.760727,294.500488,0.000000
76.390007,65.802681,-168.805206,-0.001496,0.003581,0.090945,292.704956,14.911101,0.909450,-168.805206,294.500488,0.000000
76.770004,65.561012,-168.805206,-0.001492,0.003581,0.090954,291.629944,14.856339,0.909541,-168.805206,294.500488,0.000000
77.150002,65.303703,-168.805206,-0.001483,0.003636,0.092342,290.485382,14.798031,0.923424,-168.805206,294.500488,0.000000
77.530006,65.187904,-168.983139,-0.001496,0.003665,0.093087,289.970276,14.771790,0.930872,-168.983139,294.500488,0.000000
77.910004,65.360680,-169.027618,-0.001483,0.003674,0.093322,290.738831,14.810942,0.933219,-169.027618,294.500488,0.000000
78.290001,65.288445,-169.027618,-0.001492,0.003674,0.093322,290.417511,14.794573,0.933219,-169.027618,294.500488,0.000000
78.670006,65.096672,-169.027618,-0.001487,0.003674,0.093322,289.564453,14.751117,0.933219,-169.027618,294.500488,0.000000
79.050003,65.021080,-169.027618,-0.001487,0.003677,0.093408,289.228210,14.733988,0.934082,-169.027618,294.500488,0.000000
79.430000,65.151772,-169.116577,-0.001487,0.003681,0.093487,289.809540,14.763602,0.934869,-169.116577,294.500488,0.000000
79.810005,65.163689,-169.116577,-0.001483,0.003684,0.093564,289.862549,14.766303,0.935641,-169.116577,294.500488,0.000000
80.190002,65.079170,-169.250015,-0.001487,0.003684,0.093564,289.486603,14.747151,0.935641,-169.250015,294.500488,0.000000
80.570007,65.032616,-169.294495,-0.001483,0.003686,0.093634,289.279510,14.736601,0.936338,-169.294495,294.500488,0.000000
80.950005,64.982719,-169.294495,-0.001479,0.003686,0.093634,289.057587,14.725295,0.936338,-169.294495,294.500488,0.000000
81.330002,65.304451,-169.294495,-0.001475,0.003693,0.093790,290.488708,14.798200,0.937897,-169.294495,294.500488,0.000000
81.710007,65.229973,-169.338974,-0.001462,0.003693,0.093790,290.157410,14.781323,0.937897,-169.338974,294.500488,0.000000
82.090004,65.093681,-169.427948,-0.001479,0.003693,0.093790,289.551147,14.750440,0.937897,-169.427948,294.500488,0.000000
82.470001,65.015114,-169.516907,-0.001475,0.003693,0.093808,289.201660,14.732635,0.938079,-169.516907,294.500488,0.000000
82.850006,64.890007,-169.472427,-0.001462,0.003693,0.093808,288.645172,14.704286,0.938079,-169.472427,294.500488,0.000000
83.230003,65.527504,-169.561386,-0.001466,0.003701,0.093999,291.480896,14.848745,0.939986,-169.561386,294.500488,0.000000
83.610001,65.390846,-169.650345,-0.001470,0.003701,0.093999,290.873016,14.817778,0.939986,-169.650345,294.500488,0.000000
83.990005,65.288811,-169.650345,-0.001479,0.003701,0.093999,290.419128,14.794656,0.939986,-169.650345,294.500488,0.000000
84.370003,65.162209,-169.650345,-0.001483,0.003701,0.094006,289.855988,14.765968,0.940062,-169.650345,294.500488,0.000000
84.750008,65.030388,-169.739304,-0.001453,0.003701,0.094006,289.269623,14.736096,0.940062,-169.739304,294.500488,0.000000
85.130005,64.935432,-169.739304,-0.001453,0.003701,0.094006,288.847229,14.714580,0.940062,-169.739304,294.500488,0.000000
85.510002,64.790199,-169.828278,-0.001466,0.003701,0.094006,288.201202,14.681668,0.940062,-169.828278,294.500488,0.000000
85.890007,64.712013,-169.828278,-0.001462,0.003702,0.094024,287.853424,14.663952,0.940244,-169.828278,294.500488,0.000000
86.270004,64.614067,-169.872757,-0.001462,0.003702,0.094024,287.417725,14.641757,0.940244,-169.872757,294.500488,0.000000
86.650002,64.491936,-169.872757,-0.001466,0.003702,0.094024,286.874451,14.614081,0.940244,-169.872757,294.500488,0.000000
87.030006,64.411873,-170.006195,-0.001462,0.003702,0.094024,286.518311,14.595940,0.940244,-170.006195,294.500488,0.000000
87.410004,67.178596,-170.050674,-0.001466,0.003727,0.094674,298.825317,15.222887,0.946738,-170.050674,294.500488,0.000000
87.790001,66.715736,-170.050674,-0.001449,0.003575,0.090807,296.766418,15.118002,0.908072,-170.050674,294.500488,0.000000
88.170006,66.593239,-170.095154,-0.001427,0.003575,0.090807,296.221527,15.090243,0.908072,-170.095154,294.500488,0.000000
88.550003,66.424171,-170.095154,-0.001436,0.003575,0.090815,295.469482,15.051932,0.908148,-170.095154,294.500488,0.000000
88.930008,66.349693,-170.228607,-0.001436,0.003575,0.090815,295.138184,15.035056,0.908148,-170.228607,294.500488,0.000000
89.310005,66.230919,-170.184113,-0.001436,0.003575,0.090815,294.609833,15.008141,0.908148,-170.184113,294.500488,0.000000
89.690002,66.107658,-170.273087,-0.001431,0.003575,0.090815,294.061554,14.980209,0.908148,-170.273087,294.500488,0.000000
90.070007,66.007866,-170.228607,-0.001440,0.003575,0.090815,293.617645,14.957596,0.908148,-170.228607,294.500488,0.000000
90.450005,65.886101,-170.317566,-0.001431,0.003576,0.090824,293.076019,14.930004,0.908239,-170.317566,294.500488,0.000000
90.830002,65.848854,-170.451004,-0.001449,0.003576,0.090833,292.910339,14.921564,0.908329,-170.451004,294.500488,0.000000
91.210007,65.728951,-170.495483,-0.001444,0.003578,0.090884,292.376984,14.894393,0.908844,-170.495483,294.500488,0.000000
91.590004,65.596016,-170.495483,-0.001427,0.003601,0.091466,291.785645,14.864270,0.914658,-170.495483,294.500488,0.000000
91.970001,65.540169,-170.539963,-0.001436,0.003645,0.092594,291.537231,14.851615,0.925937,-170.539963,294.500488,0.000000
92.350006,65.448555,-170.539963,-0.001436,0.003676,0.093373,291.129700,14.830854,0.933734,-170.539963,294.500488,0.000000
92.730003,65.332756,-170.628922,-0.001444,0.003684,0.093573,290.614624,14.804614,0.935732,-170.628922,294.500488,0.000000
93.110001,65.270195,-170.673416,-0.001444,0.003686,0.093617,290.336334,14.790438,0.936171,-170.673416,294.500488,0.000000
93.490005,65.220299,-170.673416,-0.001440,0.003692,0.093773,290.114380,14.779131,0.937730,-170.673416,294.500488,0.000000
93.870003,65.100014,-170.717896,-0.001440,0.003692,0.093773,289.579315,14.751874,0.937730,-170.717896,294.500488,0.000000
94.250008,65.137260,-170.762375,-0.001427,0.003712,0.094276,289.744995,14.760314,0.942757,-170.762375,294.500488,0.000000
94.630005,65.054222,-170.851334,-0.001444,0.003712,0.094276,289.375641,14.741497,0.942757,-170.851334,294.500488,0.000000
95.010002,64.987556,-170.895813,-0.001436,0.003712,0.094276,289.079102,14.726391,0.942757,-170.895813,294.500488,0.000000
95.390007,64.899315,-170.940292,-0.001453,0.003712,0.094276,288.686584,14.706395,0.942757,-170.940292,294.500488,0.000000
95.770004,65.480583,-170.984772,-0.001444,0.003727,0.094674,291.272186,14.838112,0.946738,-170.984772,294.500488,0.000000
96.150002,65.405739,-171.073730,-0.001436,0.003727,0.094674,290.939270,14.821152,0.946738,-171.073730,294.500488,0.000000
96.530006,65.359184,-171.073730,-0.001444,0.003727,0.094674,290.732178,14.810603,0.946738,-171.073730,294.500488,0.000000
96.910004,65.302956,-171.162704,-0.001436,0.003727,0.094674,290.482056,14.797861,0.946738,-171.162704,294.500488,0.000000
97.290001,65.257530,-171.118225,-0.001444,0.003727,0.094674,290.279999,14.787567,0.946738,-171.118225,294.500488,0.000000
97.670006,65.220299,-171.162704,-0.001444,0.003727,0.094674,290.114380,14.779131,0.946738,-171.162704,294.500488,0.000000
98.050003,65.138374,-171.207184,-0.001427,0.003727,0.094674,289.749969,14.760567,0.946738,-171.207184,294.500488,0.000000
98.430008,65.065392,-171.251663,-0.001444,0.003727,0.094674,289.425323,14.744028,0.946738,-171.251663,294.500488,0.000000
98.810005,65.020332,-171.296143,-0.001431,0.003727,0.094674,289.224884,14.733818,0.946738,-171.296143,294.500488,0.000000
99.190002,64.974525,-171.385101,-0.001444,0.003727,0.094674,289.021118,14.723438,0.946738,-171.385101,294.500488,0.000000
99.570007,64.923515,-171.340622,-0.001440,0.003727,0.094674,288.794220,14.711879,0.946738,-171.340622,294.500488,0.000000
99.950005,64.842339,-171.340622,-0.001444,0.003727,0.094674,288.433136,14.693484,0.946738,-171.340622,294.500488,0.000000
100.330002,64.789833,-171.518555,-0.001444,0.003727,0.094674,288.199585,14.681586,0.946738,-171.518555,294.500488,0.000000
100.710007,64.775688,-171.474060,-0.001431,0.003728,0.094683,288.136658,14.678381,0.946829,-171.474060,294.500488,0.000000
101.090004,64.732857,-171.518555,-0.001431,0.003728,0.094683,287.946136,14.668674,0.946829,-171.518555,294.500488,0.000000
101.470001,64.687431,-171.563034,-0.001440,0.003728,0.094683,287.744080,14.658381,0.946829,-171.563034,294.500488,0.000000
101.850006,64.638283,-171.651993,-0.001440,0.003728,0.094683,287.525452,14.647244,0.946829,-171.651993,294.500488,0.000000
102.230003,64.581673,-171.696472,-0.001431,0.003728,0.094683,287.273621,14.634417,0.946829,-171.696472,294.500488,0.000000
102.610008,64.523964,-171.740952,-0.001431,0.003728,0.094683,287.016937,14.621340,0.946829,-171.740952,294.500488,0.000000
102.990005,64.481880,-171.740952,-0.001440,0.003728,0.094683,286.829742,14.611803,0.946829,-171.740952,294.500488,0.000000
103.370003,64.426018,-171.785431,-0.001440,0.003728,0.094683,286.581238,14.599144,0.946829,-171.785431,294.500488,0.000000
103.750008,64.386177,-171.874390,-0.001440,0.003728,0.094683,286.404022,14.590117,0.946829,-171.874390,294.500488,0.000000
104.130005,64.330330,-171.918869,-0.001427,0.003728,0.094683,286.155609,14.577461,0.946829,-171.918869,294.500488,0.000000
104.510002,64.268517,-171.918869,-0.001431,0.003728,0.094683,285.880646,14.563454,0.946829,-171.918869,294.500488,0.000000
104.890007,64.235741,-171.963364,-0.001436,0.003728,0.094683,285.734833,14.556027,0.946829,-171.963364,294.500488,0.000000
105.270004,64.182121,-172.007843,-0.001440,0.003728,0.094683,285.496338,14.543877,0.946829,-172.007843,294.500488,0.000000
105.650002,66.735847,-172.052322,-0.001410,0.003564,0.090538,296.855865,15.122559,0.905377,-172.052322,294.500488,0.000000
106.030006,66.664360,-172.141281,-0.001406,0.003564,0.090538,296.537872,15.106360,0.905377,-172.141281,294.500488,0.000000
106.410004,66.583549,-172.141281,-0.001418,0.003564,0.090538,296.178406,15.088048,0.905377,-172.141281,294.500488,0.000000
106.790009,66.572014,-172.185760,-0.001410,0.003564,0.090538,296.127106,15.085434,0.905377,-172.185760,294.500488,0.000000
107.170006,66.482643,-172.230240,-0.001406,0.003565,0.090547,295.729553,15.065183,0.905468,-172.230240,294.500488,0.000000
107.550003,66.405190,-172.274719,-0.001410,0.003565,0.090556,295.385040,15.047631,0.905559,-172.274719,294.500488,0.000000
107.930008,66.366463,-172.363678,-0.001401,0.003565,0.090556,295.212769,15.038856,0.905559,-172.363678,294.500488,0.000000
108.310005,66.326988,-172.319199,-0.001418,0.003565,0.090556,295.037170,15.029910,0.905559,-172.319199,294.500488,0.000000
108.690002,66.268150,-172.408173,-0.001410,0.003565,0.090556,294.775452,15.016578,0.905559,-172.408173,294.500488,0.000000
109.070007,66.209694,-172.363678,-0.001406,0.003565,0.090556,294.515442,15.003331,0.905559,-172.363678,294.500488,0.000000
109.450005,66.159416,-172.497131,-0.001397,0.003565,0.090556,294.291779,14.991938,0.905559,-172.497131,294.500488,0.000000
109.830002,66.110268,-172.541611,-0.001414,0.003565,0.090556,294.073151,14.980801,0.905559,-172.541611,294.500488,0.000000
110.210007,66.064095,-172.586090,-0.001414,0.003565,0.090556,293.867767,14.970338,0.905559,-172.586090,294.500488,0.000000
110.590004,66.022758,-172.630569,-0.001423,0.003565,0.090556,293.683899,14.960971,0.905559,-172.630569,294.500488,0.000000
110.970009,65.906944,-172.675049,-0.001406,0.003566,0.090573,293.168732,14.934727,0.905725,-172.675049,294.500488,0.000000
111.350006,65.963173,-172.675049,-0.001410,0.003567,0.090598,293.418854,14.947468,0.905983,-172.675049,294.500488,0.000000
111.730003,65.890572,-172.719528,-0.001418,0.003569,0.090642,293.095886,14.931017,0.906422,-172.719528,294.500488,0.000000
112.110008,65.845131,-172.764008,-0.001418,0.003569,0.090651,292.893768,14.920719,0.906513,-172.764008,294.500488,0.000000
112.490005,65.814598,-172.764008,-0.001388,0.003569,0.090651,292.757965,14.913801,0.906513,-172.764008,294.500488,0.000000
112.870003,65.753532,-172.764008,-0.001414,0.003569,0.090651,292.486328,14.899963,0.906513,-172.764008,294.500488,0.000000
113.250008,65.714058,-172.986420,-0.001410,0.003569,0.090651,292.310730,14.891019,0.906513,-172.986420,294.500488,0.000000
113.630005,65.642937,-172.941940,-0.001406,0.003574,0.090772,291.994354,14.874902,0.907724,-172.941940,294.500488,0.000000
114.010002,65.601982,-172.941940,-0.001418,0.003584,0.091024,291.812195,14.865622,0.910237,-172.941940,294.500488,0.000000
114.390007,65.569206,-172.986420,-0.001397,0.003584,0.091033,291.666382,14.858194,0.910328,-172.986420,294.500488,0.000000
114.770004,65.544624,-173.030899,-0.001410,0.003591,0.091205,291.557037,14.852624,0.912054,-173.030899,294.500488,0.000000
115.150009,65.509254,-173.119858,-0.001401,0.003669,0.093192,291.399719,14.844608,0.931917,-173.119858,294.500488,0.000000
115.530006,65.439629,-173.119858,-0.001414,0.003692,0.093773,291.089996,14.828833,0.937730,-173.119858,294.500488,0.000000
115.910004,65.417274,-173.119858,-0.001410,0.003699,0.093955,290.990570,14.823767,0.939547,-173.119858,294.500488,0.000000
116.290009,65.356209,-173.164337,-0.001401,0.003699,0.093964,290.718933,14.809928,0.939638,-173.164337,294.500488,0.000000
116.670006,65.350990,-173.208817,-0.001406,0.003709,0.094215,290.695709,14.808746,0.942151,-173.208817,294.500488,0.000000
117.050003,65.307426,-173.297791,-0.001410,0.003710,0.094224,290.501953,14.798875,0.942242,-173.297791,294.500488,0.000000
117.430008,65.288063,-173.386749,-0.001406,0.003710,0.094224,290.415802,14.794487,0.942242,-173.386749,294.500488,0.000000
117.810005,65.265358,-173.342270,-0.001406,0.003710,0.094224,290.314819,14.789341,0.942242,-173.342270,294.500488,0.000000
118.190002,65.218803,-173.386749,-0.001406,0.003710,0.094224,290.107727,14.778792,0.942242,-173.386749,294.500488,0.000000
118.570007,65.186043,-173.386749,-0.001406,0.003710,0.094224,289.962006,14.771369,0.942242,-173.386749,294.500488,0.000000
118.950005,65.257164,-173.520187,-0.001414,0.003728,0.094692,290.278351,14.787484,0.946920,-173.520187,294.500488,0.000000
119.330009,65.221779,-173.520187,-0.001414,0.003728,0.094692,290.120972,14.779467,0.946920,-173.520187,294.500488,0.000000
119.710007,65.167046,-173.520187,-0.001423,0.003728,0.094701,289.877502,14.767064,0.947011,-173.520187,294.500488,0.000000
120.090004,65.130180,-173.520187,-0.001410,0.003728,0.094701,289.713501,14.758710,0.947011,-173.520187,294.500488,0.000000
120.470009,65.081398,-173.609146,-0.001410,0.003728,0.094701,289.496521,14.747656,0.947011,-173.609146,294.500488,0.000000
120.850006,65.075813,-173.742599,-0.001397,0.003729,0.094709,289.471680,14.746390,0.947087,-173.742599,294.500488,0.000000
121.230003,65.038582,-173.831558,-0.001406,0.003729,0.094709,289.306061,14.737954,0.947087,-173.831558,294.500488,0.000000
121.610008,65.011772,-173.787079,-0.001423,0.003729,0.094709,289.186798,14.731878,0.947087,-173.787079,294.500488,0.000000
121.990005,64.993889,-173.742599,-0.001410,0.003729,0.094709,289.107269,14.727826,0.947087,-173.742599,294.500488,0.000000
122.370003,65.097404,-173.876038,-0.001393,0.003746,0.095152,289.567719,14.751283,0.951523,-173.876038,294.500488,0.000000
122.750008,65.136879,-173.920517,-0.001414,0.003749,0.095229,289.743317,14.760228,0.952295,-173.920517,294.500488,0.000000
123.130005,65.121986,-174.009476,-0.001427,0.003750,0.095248,289.677063,14.756853,0.952476,-174.009476,294.500488,0.000000
123.510002,65.122734,-173.964996,-0.001401,0.003751,0.095273,289.680389,14.757022,0.952734,-173.964996,294.500488,0.000000
123.890007,65.116035,-173.964996,-0.001406,0.003751,0.095273,289.650604,14.755505,0.952734,-173.964996,294.500488,0.000000
124.270004,65.068733,-174.053955,-0.001410,0.003751,0.095273,289.440186,14.744785,0.952734,-174.053955,294.500488,0.000000
124.650009,65.190880,-174.142929,-0.001414,0.003756,0.095394,289.983521,14.772465,0.953945,-174.142929,294.500488,0.000000
125.030006,65.240028,-174.098450,-0.001406,0.003756,0.095394,290.202148,14.783602,0.953945,-174.098450,294.500488,0.000000
125.410004,65.244499,-174.142929,-0.001406,0.003756,0.095394,290.222015,14.784615,0.953945,-174.142929,294.500488,0.000000
125.790009,65.242638,-174.231888,-0.001414,0.003756,0.095394,290.213745,14.784193,0.953945,-174.231888,294.500488,0.000000
126.170006,65.221413,-174.231888,-0.001401,0.003756,0.095394,290.119324,14.779383,0.953945,-174.231888,294.500488,0.000000
126.550003,65.201302,-174.276367,-0.001423,0.003756,0.095394,290.029877,14.774826,0.953945,-174.276367,294.500488,0.000000
126.930008,65.172630,-174.320847,-0.001397,0.003756,0.095394,289.902344,14.768330,0.953945,-174.320847,294.500488,0.000000
127.310005,65.156624,-174.365326,-0.001401,0.003756,0.095394,289.831146,14.764703,0.953945,-174.365326,294.500488,0.000000
127.690002,65.133904,-174.454285,-0.001410,0.003756,0.095394,289.730072,14.759553,0.953945,-174.454285,1681.640991,0.000000
128.070007,65.114174,-174.454285,-0.001406,0.003746,0.095143,289.642303,14.755083,0.951432,-174.454285,0.094943,0.000000
128.450012,65.034477,-174.543259,-0.001414,0.003725,0.094613,289.287811,14.737023,0.946133,-174.543259,0.094310,0.000000
128.830002,64.925377,-174.587738,-0.001418,0.003706,0.094129,288.802490,14.712301,0.941288,-174.587738,0.093678,0.000000
129.210007,64.888512,-174.587738,-0.001401,0.003682,0.093529,288.638519,14.703947,0.935293,-174.587738,0.093045,0.000000
129.590012,64.862450,-174.587738,-0.001393,0.003658,0.092922,288.522583,14.698041,0.929222,-174.587738,0.092410,0.000000
129.970001,64.825584,-174.632217,-0.001393,0.003636,0.092350,288.358612,14.689688,0.923499,-174.632217,0.091778,0.000000
130.350006,64.770470,-174.632217,-0.001406,0.003606,0.091605,288.113434,14.677198,0.916051,-174.632217,0.091145,0.000000
130.730011,64.767494,-174.765656,-0.001414,0.003588,0.091136,288.100189,14.676524,0.911357,-174.765656,0.090512,0.000000
131.110001,64.674019,-174.810135,-0.001393,0.003568,0.090633,287.684418,14.655342,0.906331,-174.810135,0.089879,0.000000
131.490005,64.654289,-174.810135,-0.001393,0.003548,0.090121,287.596649,14.650872,0.901214,-174.810135,0.089246,0.000000
131.870010,64.479271,-174.810135,-0.001393,0.003516,0.089314,286.818115,14.611212,0.893144,-174.810135,0.088612,0.000000
132.250000,63.698784,-174.943573,-0.001384,0.003489,0.088621,283.346344,14.434351,0.886210,-174.943573,0.087979,0.000000
132.630005,63.034096,-174.943573,-0.001375,0.003471,0.088170,280.389648,14.283730,0.881699,-174.943573,0.087346,0.000000
133.010010,61.631744,-174.943573,-0.001380,0.003443,0.087460,274.151703,13.965953,0.874598,-174.943573,0.086713,0.000000
133.389999,60.097191,-175.032547,-0.001358,0.003422,0.086921,267.325653,13.618217,0.869209,-175.032547,0.086081,0.000000
133.770004,58.425987,-175.032547,-0.001362,0.003398,0.086314,259.891785,13.239518,0.863138,-175.032547,0.085439,0.000000
134.150009,56.953255,-175.165985,-0.001354,0.003381,0.085881,253.340729,12.905792,0.858808,-175.165985,0.084806,0.000000
134.529999,54.049492,-175.165985,-0.001375,0.003348,0.085039,240.424149,12.247789,0.850390,-175.165985,0.084173,0.000000
134.910004,52.350731,-175.210464,-0.001358,0.003330,0.084571,232.867676,11.862845,0.845712,-175.210464,0.083539,0.000000
135.290009,49.219078,-175.165985,-0.001362,0.003302,0.083869,218.937393,11.153203,0.838687,-175.165985,0.082906,0.000000
135.670013,46.599434,-175.254944,-0.001362,0.003274,0.083166,207.284637,10.559583,0.831663,-175.254944,0.082273,0.000000
136.050003,43.967506,-175.254944,-0.001358,0.003255,0.082680,195.577240,9.963179,0.826803,-175.254944,0.081640,0.000000
136.430008,40.565887,-175.343903,-0.001367,0.003226,0.081935,180.446075,9.192362,0.819354,-175.343903,0.081007,0.000000
136.810013,38.074715,-175.343903,-0.001375,0.003202,0.081336,169.364792,8.627853,0.813359,-175.343903,0.080375,0.000000
137.190002,35.987198,-175.388397,-0.001375,0.003184,0.080886,160.079056,8.154816,0.808862,-175.388397,0.079742,0.000000
137.570007,33.992020,-175.432877,-0.001362,0.003168,0.080470,151.204056,7.702702,0.804699,-175.432877,0.079107,0.000000
137.950012,30.276489,-175.521835,-0.001371,0.003132,0.079558,134.676544,6.860751,0.795585,-175.521835,0.078474,0.000000
138.330002,27.071480,-175.521835,-0.001371,0.003102,0.078779,120.419960,6.134485,0.787788,-175.521835,0.077842,0.000000
138.710007,24.799263,-175.655273,-0.001371,0.003081,0.078249,110.312630,5.619593,0.782489,-175.655273,0.077209,0.000000
139.090012,22.571732,-175.610794,-0.001371,0.003063,0.077790,100.404076,5.114828,0.777902,-175.610794,0.076576,0.000000
139.470001,19.968102,-175.655273,-0.001367,0.003039,0.077183,88.822548,4.524837,0.771831,-175.655273,0.075943,0.000000
139.850006,16.502060,-175.699753,-0.001371,0.003006,0.076359,73.404831,3.739420,0.763595,-175.699753,0.075309,0.000000
140.230011,13.509300,-175.744232,-0.001367,0.002978,0.075648,60.092369,3.061251,0.756479,-175.744232,0.074676,0.000000
140.610001,11.135429,-175.744232,-0.001371,0.002956,0.075076,49.532864,2.523324,0.750757,-175.744232,0.074043,0.000000
140.990005,8.979767,-175.788712,-0.001375,0.002938,0.074615,39.943996,2.034844,0.746154,-175.788712,0.073410,0.000000
141.370010,6.119942,-175.788712,-0.001371,0.002908,0.073852,27.222860,1.386799,0.738524,-175.788712,0.072777,0.000000
141.750000,3.012123,-175.922165,-0.001371,0.002879,0.073115,13.398593,0.682557,0.731151,-175.922165,0.072145,0.000000
142.130005,0.275932,-175.966644,-0.001375,0.002851,0.072422,1.227408,0.062527,0.724217,-175.966644,0.071510,0.000000
142.510010,-1.558750,-175.966644,-0.001397,0.002832,0.071927,-6.933667,-0.353218,0.719266,-175.966644,0.070877,0.000000
142.889999,-3.414654,-175.922165,-0.001393,0.002813,0.071459,-15.189138,-0.773772,0.714588,-175.922165,0.070245,0.000000
143.270004,-0.283371,-176.055603,-0.001436,0.002784,0.070722,-1.260497,-0.064213,0.707215,-176.055603,0.069612,0.000000
143.650009,-0.074844,-176.100082,-0.001444,0.002753,0.069933,-0.332924,-0.016960,0.699327,-176.100082,0.068979,0.000000
144.030014,-0.066650,-176.144562,-0.001453,0.002732,0.069395,-0.296476,-0.015103,0.693953,-176.144562,0.068346,0.000000
144.410004,-0.053246,-176.144562,-0.001466,0.002704,0.068684,-0.236848,-0.012066,0.686837,-176.144562,0.067712,0.000000
144.790009,-0.040215,-176.100082,-0.001457,0.002689,0.068302,-0.178883,-0.009113,0.683022,-176.100082,0.067071,0.000000
145.170013,-0.075592,-176.189041,-0.001449,0.002659,0.067530,-0.336250,-0.017129,0.675301,-176.189041,0.066437,0.000000
145.550003,-0.102028,-176.233521,-0.001462,0.002630,0.066793,-0.453843,-0.023120,0.667928,-176.233521,0.065804,0.000000
145.930008,-0.082291,-176.366974,-0.001462,0.002605,0.066160,-0.366047,-0.018647,0.661600,-176.366974,0.065171,0.000000
146.310013,-0.076332,-176.366974,-0.001470,0.002581,0.065553,-0.339542,-0.017297,0.655529,-176.366974,0.064539,0.000000
146.690002,-0.092346,-176.322495,-0.001479,0.002556,0.064929,-0.410776,-0.020926,0.649291,-176.322495,0.063906,0.000000
147.070007,-0.087135,-176.455933,-0.001470,0.002527,0.064174,-0.387597,-0.019745,0.641737,-176.455933,0.063273,0.000000
147.450012,-0.122139,-176.500412,-0.001483,0.002501,0.063532,-0.543301,-0.027677,0.635317,-176.500412,0.062638,0.000000
147.830002,-0.090485,-176.544891,-0.001479,0.002479,0.062969,-0.402496,-0.020504,0.629685,-176.544891,0.062006,0.000000
148.210007,-0.090485,-176.500412,-0.001492,0.002455,0.062352,-0.402496,-0.020504,0.623524,-176.500412,0.061373,0.000000
148.590012,-0.080055,-176.589371,-0.001496,0.002432,0.061773,-0.356103,-0.018141,0.617725,-176.589371,0.060740,0.000000
148.970001,-0.114319,-176.633850,-0.001496,0.002406,0.061112,-0.508516,-0.025905,0.611124,-176.633850,0.060107,0.000000
149.350006,-0.131447,-176.722824,-0.001509,0.002378,0.060402,-0.584705,-0.029786,0.604024,-176.722824,0.059474,0.000000
149.730011,-0.118782,-176.767303,-0.001518,0.002354,0.059786,-0.528369,-0.026916,0.597862,-176.767303,0.058841,0.000000
150.110001,-0.109100,-176.722824,-0.001522,0.002328,0.059128,-0.485303,-0.024722,0.591276,-176.722824,0.058207,0.000000
150.490005,-0.119156,-176.722824,-0.001539,0.002307,0.058589,-0.530032,-0.027001,0.585887,-176.722824,0.057574,0.000000
150.870010,-0.128464,-176.856262,-0.001544,0.002282,0.057956,-0.571435,-0.029110,0.579558,-176.856262,0.056941,0.000000
151.250000,-0.124741,-176.856262,-0.001565,0.002254,0.057246,-0.554874,-0.028267,0.572458,-176.856262,0.056309,0.000000
151.630005,-0.163841,-176.945221,-0.001595,0.002232,0.056699,-0.728802,-0.037127,0.566992,-176.945221,0.055676,0.000000
152.010010,-0.137032,-176.945221,-0.001617,0.002205,0.056013,-0.609547,-0.031052,0.560134,-176.945221,0.055043,0.000000
152.390015,-0.148949,-176.989700,-0.001625,0.002181,0.055406,-0.662557,-0.033752,0.554063,-176.989700,0.054409,0.000000
152.770004,-0.135170,-177.034180,-0.001638,0.002162,0.054913,-0.601266,-0.030630,0.549128,-177.034180,0.053776,0.000000
153.150009,-0.135544,-177.123154,-0.001669,0.002130,0.054097,-0.602929,-0.030715,0.540967,-177.123154,0.053143,0.000000
153.530014,-0.132187,-177.167633,-0.001712,0.002111,0.053611,-0.587997,-0.029954,0.536108,-177.167633,0.052510,0.000000
153.910004,-0.150063,-177.123154,-0.001707,0.002081,0.052866,-0.667512,-0.034005,0.528659,-177.123154,0.051877,0.000000
154.290009,-0.135544,-177.167633,-0.001755,0.002049,0.052050,-0.602929,-0.030715,0.520499,-177.167633,0.051244,0.000000
154.670013,-0.134422,-177.212112,-0.001763,0.002032,0.051617,-0.597940,-0.030461,0.516169,-177.212112,0.050610,0.000000
155.050003,-0.151550,-177.301071,-0.001785,0.002003,0.050889,-0.674129,-0.034342,0.508887,-177.301071,0.049977,0.000000
155.300003,-0.106865,-177.301071,-0.001815,0.001993,0.050610,-0.475359,-0.024216,0.506101,-177.301071,0.050454,0.000000