File: Data/compression 25/AutoNoHeating-17-25-reverse-1-2_09232024_184206.csv
Time (sec),S:Load (lbs),S:HL1 (DIM),S:LVDT (in),S:Position (in),Ch:Position (mm),Ch:Load (N),Ch:Stress (MPa),Ch:Strain (mm/mm),Ch:HL1 (DIM),Set Point (),Cycles ()
0.110000,-0.117668,-30.469452,-0.007726,-0.003776,-0.095915,-0.523414,-0.026664,-0.959153,-30.469452,-0.095586,0.000000
0.470000,-0.134430,-30.513933,-0.007735,-0.003729,-0.094710,-0.597974,-0.030462,-0.947098,-30.513933,-0.094094,0.000000
0.830000,-0.174271,-30.513933,-0.007627,-0.003519,-0.089385,-0.775194,-0.039490,-0.893852,-30.513933,-0.088110,0.000000
1.190000,-0.219704,-30.469452,-0.007394,-0.003272,-0.083106,-0.977291,-0.049786,-0.831065,-30.469452,-0.082109,0.000000
1.550000,-0.188423,-30.513933,-0.007144,-0.003036,-0.077114,-0.838148,-0.042697,-0.771138,-30.513933,-0.076108,0.000000
1.910000,-0.139267,-30.469452,-0.006903,-0.002815,-0.071494,-0.619490,-0.031558,-0.714940,-30.469452,-0.070106,0.000000
2.270000,-0.130333,-30.602894,-0.006666,-0.002576,-0.065423,-0.579750,-0.029534,-0.654234,-30.602894,-0.064123,0.000000
2.630000,-0.148209,-30.558413,-0.006420,-0.002340,-0.059440,-0.659265,-0.033585,-0.594399,-30.558413,-0.058122,0.000000
2.990000,-0.187675,-30.602894,-0.006170,-0.002103,-0.053412,-0.834822,-0.042528,-0.534124,-30.602894,-0.052120,0.000000
3.350000,-0.217468,-30.558413,-0.005920,-0.001858,-0.047186,-0.967347,-0.049279,-0.471859,-30.558413,-0.046119,0.000000
3.710000,-0.209648,-30.602894,-0.005687,-0.001620,-0.041158,-0.932561,-0.047507,-0.411585,-30.602894,-0.040118,0.000000
4.070000,-0.138901,-30.602894,-0.005458,-0.001400,-0.035565,-0.617861,-0.031475,-0.355651,-30.602894,-0.034134,0.000000
4.430000,-0.116180,-30.602894,-0.005230,-0.001162,-0.029520,-0.516796,-0.026327,-0.295203,-30.602894,-0.028133,0.000000
4.790000,-0.150810,-30.691856,-0.004971,-0.000922,-0.023415,-0.670837,-0.034174,-0.234153,-30.691856,-0.022132,0.000000
5.150000,-0.163101,-30.647375,-0.004704,-0.000686,-0.017423,-0.725510,-0.036959,-0.174226,-30.647375,-0.016130,0.000000
5.510000,-0.188049,-30.647375,-0.004441,-0.000439,-0.011161,-0.836485,-0.042613,-0.111613,-30.647375,-0.010129,0.000000
5.870000,-0.068520,-30.691856,-0.004238,-0.000207,-0.005264,-0.304790,-0.015527,-0.052640,-30.691856,-0.004146,0.000000
6.230000,0.012657,-30.647375,-0.004169,-0.000000,-0.000000,0.056302,0.002868,-0.000000,-30.647375,0.000217,0.000000
6.590000,0.074471,-30.691856,-0.004169,-0.000000,-0.000000,0.331261,0.016875,-0.000000,-30.691856,0.000399,0.000000
6.950000,0.080429,-30.691856,-0.004174,-0.000000,-0.000000,0.357766,0.018225,-0.000000,-30.691856,0.000997,0.000000
7.310000,0.078194,-30.736338,-0.004174,0.000000,0.000009,0.347823,0.017719,0.000087,-30.736338,0.001604,0.000000
7.670001,0.388008,-30.780819,-0.004139,0.000051,0.001292,1.725946,0.087924,0.012922,-30.780819,0.002203,0.000000
8.030001,0.500465,-30.691856,-0.004118,0.000070,0.001769,2.226181,0.113407,0.017691,-30.691856,0.002801,0.000000
8.390000,0.741394,-30.736338,-0.004100,0.000098,0.002480,3.297885,0.168002,0.024802,-30.736338,0.003400,0.000000
8.750000,0.963699,-30.736338,-0.004092,0.000121,0.003079,4.286749,0.218377,0.030786,-30.736338,0.003998,0.000000
9.110001,1.146904,-30.736338,-0.004053,0.000138,0.003495,5.101684,0.259892,0.034950,-30.736338,0.004605,0.000000
9.470000,1.469383,-30.780819,-0.004049,0.000159,0.004041,6.536143,0.332967,0.040411,-30.780819,0.005203,0.000000
9.830001,1.946014,-30.780819,-0.004023,0.000189,0.004796,8.656304,0.440973,0.047958,-30.780819,0.005802,0.000000
10.190001,2.255829,-30.780819,-0.004010,0.000211,0.005359,10.034428,0.511178,0.053594,-30.780819,0.006400,0.000000
10.550000,2.692619,-30.780819,-0.003980,0.000231,0.005880,11.977369,0.610156,0.058798,-30.780819,0.006999,0.000000
10.910001,3.233307,-30.825298,-0.003954,0.000258,0.006556,14.382467,0.732678,0.065562,-30.825298,0.007605,0.000000
11.270000,3.687233,-30.825298,-0.003945,0.000277,0.007033,16.401632,0.835539,0.070331,-30.825298,0.008204,0.000000
11.630000,4.390640,-30.825298,-0.003911,0.000305,0.007753,19.530542,0.994933,0.077530,-30.825298,0.008802,0.000000
11.990001,4.804718,-30.914261,-0.003911,0.000327,0.008299,21.372454,1.088765,0.082991,-30.914261,0.009401,0.000000
12.350000,5.251564,-30.825298,-0.003889,0.000349,0.008863,23.360123,1.190021,0.088631,-30.825298,0.009999,0.000000
12.710001,5.992218,-30.914261,-0.003859,0.000375,0.009531,26.654716,1.357856,0.095307,-30.914261,0.010606,0.000000
13.070001,6.455078,-30.869780,-0.003842,0.000395,0.010042,28.713621,1.462742,0.100425,-30.869780,0.011204,0.000000
13.430000,6.995758,-30.869780,-0.003829,0.000419,0.010650,31.118687,1.585261,0.106496,-30.869780,0.011803,0.000000
13.790001,7.678688,-31.003223,-0.003807,0.000444,0.011282,34.156509,1.740016,0.112824,-31.003223,0.012401,0.000000
14.150001,7.902115,-31.003223,-0.003790,0.000458,0.011621,35.150364,1.790645,0.116208,-31.003223,0.013000,0.000000
14.510000,8.551903,-31.003223,-0.003777,0.000481,0.012210,38.040764,1.937889,0.122104,-31.003223,0.013607,0.000000
14.870001,9.534592,-30.958742,-0.003747,0.000515,0.013086,42.411983,2.160569,0.130863,-30.958742,0.014205,0.000000
15.230000,9.886116,-30.958742,-0.003708,0.000535,0.013598,43.975639,2.240226,0.135980,-30.958742,0.014803,0.000000
15.590001,10.665863,-31.003223,-0.003704,0.000563,0.014300,47.444130,2.416919,0.143005,-31.003223,0.015402,0.000000
15.950001,11.028549,-30.958742,-0.003678,0.000582,0.014795,49.057438,2.499105,0.147948,-30.958742,0.016000,0.000000
16.310001,11.676857,-31.003223,-0.003665,0.000610,0.015506,51.941254,2.646013,0.155060,-31.003223,0.016599,0.000000
16.670000,12.441704,-31.003223,-0.003643,0.000638,0.016200,55.343464,2.819330,0.161997,-31.003223,0.017206,0.000000
17.030001,12.801788,-31.003223,-0.003604,0.000661,0.016789,56.945198,2.900927,0.167894,-31.003223,0.017804,0.000000
17.390001,13.471313,-31.092184,-0.003596,0.000687,0.017457,59.923393,3.052643,0.174571,-31.092184,0.018403,0.000000
17.750000,13.764000,-31.092184,-0.003587,0.000708,0.017995,61.225330,3.118967,0.179949,-31.092184,0.019001,0.000000
18.110001,14.151268,-31.136665,-0.003561,0.000734,0.018637,62.947983,3.206723,0.186368,-31.136665,0.019599,0.000000
18.470001,14.982773,-31.092184,-0.003531,0.000759,0.019287,66.646706,3.395145,0.192871,-31.092184,0.020206,0.000000
18.830002,14.881119,-31.136665,-0.003505,0.000774,0.019669,66.194519,3.372110,0.196686,-31.136665,0.020805,0.000000
19.190001,15.334297,-31.092184,-0.003505,0.000796,0.020215,68.210358,3.474802,0.202151,-31.092184,0.021403,0.000000
19.550001,16.063774,-31.092184,-0.003471,0.000820,0.020822,71.455238,3.640103,0.208222,-31.092184,0.022002,0.000000
19.910002,16.779099,-31.136665,-0.003458,0.000849,0.021559,74.637161,3.802198,0.215591,-31.136665,0.022600,0.000000
20.270000,17.207703,-31.136665,-0.003445,0.000873,0.022166,76.543686,3.899321,0.221662,-31.136665,0.023207,0.000000
20.630001,17.542465,-31.181147,-0.003393,0.000896,0.022747,78.032784,3.975179,0.227472,-31.181147,0.023805,0.000000
20.990002,17.949837,-31.181147,-0.003397,0.000917,0.023294,79.844864,4.067491,0.232938,-31.181147,0.024404,0.000000
21.350000,18.585854,-31.181147,-0.003363,0.000944,0.023979,82.674004,4.211615,0.239788,-31.181147,0.025002,0.000000
21.710001,19.070679,-31.225628,-0.003354,0.000969,0.024620,84.830612,4.321477,0.246204,-31.225628,0.025600,0.000000
22.070002,19.373795,-31.136665,-0.003328,0.000994,0.025236,86.178940,4.390164,0.252362,-31.136665,0.026207,0.000000
22.430000,19.828461,-31.270109,-0.003303,0.001016,0.025800,88.201401,4.493193,0.257997,-31.270109,0.026806,0.000000
22.790001,20.331909,-31.225628,-0.003285,0.001041,0.026433,90.440849,4.607276,0.264329,-31.225628,0.027404,0.000000
23.150002,20.874825,-31.270109,-0.003247,0.001068,0.027127,92.855858,4.730303,0.271267,-31.270109,0.028003,0.000000
23.510000,20.874825,-31.225628,-0.003238,0.001089,0.027673,92.855858,4.730303,0.276733,-31.225628,0.028601,0.000000
23.870001,21.136978,-31.225628,-0.003212,0.001111,0.028211,94.021973,4.789708,0.282107,-31.225628,0.029199,0.000000
24.230001,21.843742,-31.314590,-0.003182,0.001137,0.028887,97.165817,4.949863,0.288871,-31.314590,0.029806,0.000000
24.590002,21.864220,-31.270109,-0.003182,0.001155,0.029347,97.256905,4.954503,0.293469,-31.270109,0.030405,0.000000
24.950001,22.249252,-31.314590,-0.003169,0.001180,0.029963,98.969620,5.041753,0.299627,-31.314590,0.031003,0.000000
25.310001,23.066238,-31.359070,-0.003130,0.001207,0.030648,102.603752,5.226884,0.306478,-31.359070,0.031602,0.000000
25.670002,23.275513,-31.314590,-0.003117,0.001229,0.031220,103.534653,5.274307,0.312201,-31.314590,0.032200,0.000000
26.030001,23.645279,-31.359070,-0.003087,0.001254,0.031845,105.179451,5.358097,0.318446,-31.359070,0.032807,0.000000
26.390001,23.566330,-31.359070,-0.003083,0.001270,0.032261,104.828270,5.340207,0.322609,-31.359070,0.033405,0.000000
26.750002,23.712677,-31.403551,-0.003057,0.001291,0.032781,105.479256,5.373369,0.327810,-31.403551,0.034004,0.000000
27.110001,25.227486,-31.448032,-0.003031,0.001330,0.033778,112.217461,5.716630,0.337783,-31.448032,0.034602,0.000000
27.470001,25.137749,-31.403551,-0.003027,0.001350,0.034290,111.818291,5.696295,0.342900,-31.403551,0.035201,0.000000
27.830002,25.173492,-31.403551,-0.002992,0.001372,0.034854,111.977287,5.704395,0.348536,-31.403551,0.035808,0.000000
28.190001,25.464691,-31.448032,-0.002988,0.001395,0.035426,113.272606,5.770381,0.354262,-31.448032,0.036406,0.000000
28.550001,25.390587,-31.448032,-0.002949,0.001409,0.035799,112.942970,5.753589,0.357991,-31.448032,0.037005,0.000000
28.910002,26.562813,-31.536995,-0.002949,0.001443,0.036649,118.157295,6.019219,0.366488,-31.536995,0.037603,0.000000
29.270000,26.911354,-31.448032,-0.002919,0.001466,0.037238,119.707680,6.098200,0.372384,-31.448032,0.038201,0.000000
29.630001,26.684212,-31.536995,-0.002906,0.001487,0.037776,118.697304,6.046729,0.377763,-31.536995,0.038808,0.000000
29.990002,27.732063,-31.492514,-0.002889,0.001516,0.038496,123.358376,6.284175,0.384962,-31.492514,0.039407,0.000000
30.350002,27.514969,-31.536995,-0.002859,0.001533,0.038930,122.392693,6.234981,0.389295,-31.536995,0.040005,0.000000
30.710001,27.640457,-31.536995,-0.002863,0.001552,0.039424,122.950897,6.263417,0.394242,-31.536995,0.040604,0.000000
31.070002,28.055656,-31.581474,-0.002833,0.001578,0.040092,124.797791,6.357502,0.400919,-31.581474,0.041202,0.000000
31.430002,28.672676,-31.625956,-0.002807,0.001602,0.040682,127.542435,6.497322,0.406816,-31.625956,0.041800,0.000000
31.790001,29.107979,-31.536995,-0.002802,0.001623,0.041228,129.478760,6.595963,0.412277,-31.536995,0.042407,0.000000
32.150002,29.816605,-31.581474,-0.002764,0.001651,0.041939,132.630875,6.756539,0.419389,-31.581474,0.043006,0.000000
32.510002,29.793518,-31.625956,-0.002742,0.001673,0.042485,132.528183,6.751307,0.424854,-31.625956,0.043604,0.000000
32.870003,29.930923,-31.536995,-0.002729,0.001693,0.043014,133.139404,6.782444,0.430142,-31.536995,0.044202,0.000000
33.230003,30.696152,-31.625956,-0.002712,0.001718,0.043630,136.543304,6.955847,0.436300,-31.625956,0.044801,0.000000
33.590000,31.258430,-31.536995,-0.002695,0.001743,0.044263,139.044449,7.083261,0.442632,-31.536995,0.045408,0.000000
33.950001,31.105385,-31.670437,-0.002673,0.001766,0.044853,138.363663,7.048581,0.448529,-31.670437,0.046006,0.000000
34.310001,32.324165,-31.625956,-0.002656,0.001792,0.045512,143.785065,7.324760,0.455118,-31.625956,0.046605,0.000000
34.670002,32.264206,-31.625956,-0.002639,0.001811,0.045997,143.518356,7.311173,0.459974,-31.625956,0.047203,0.000000
35.030003,32.501411,-31.714918,-0.002613,0.001838,0.046683,144.573502,7.364925,0.466829,-31.714918,0.047801,0.000000
35.390003,32.769890,-31.670437,-0.002613,0.001858,0.047203,145.767746,7.425763,0.472029,-31.670437,0.048408,0.000000
35.750000,33.373878,-31.714918,-0.002587,0.001879,0.047715,148.454422,7.562629,0.477147,-31.714918,0.049007,0.000000
36.110001,34.581482,-31.714918,-0.002565,0.001911,0.048547,153.826111,7.836276,0.485473,-31.714918,0.049605,0.000000
36.470001,34.486900,-31.670437,-0.002548,0.001930,0.049016,153.405396,7.814843,0.490155,-31.670437,0.050204,0.000000
36.830002,35.345963,-31.803881,-0.002548,0.001958,0.049727,157.226700,8.009510,0.497267,-31.803881,0.050802,0.000000
37.190002,35.300537,-31.714918,-0.002509,0.001977,0.050221,157.024628,7.999216,0.502210,-31.714918,0.051409,0.000000
37.550003,35.536247,-31.803881,-0.002509,0.001993,0.050629,158.073120,8.052629,0.506287,-31.803881,0.052007,0.000000
37.910004,36.934502,-31.759399,-0.002501,0.002027,0.051487,164.292862,8.369477,0.514871,-31.759399,0.052606,0.000000
38.270000,37.295334,-31.714918,-0.002470,0.002049,0.052034,165.897934,8.451243,0.520336,-31.714918,0.053204,0.000000
38.630001,38.545387,-31.848360,-0.002458,0.002081,0.052866,171.458450,8.734509,0.528659,-31.848360,0.053803,0.000000
38.990002,38.502937,-31.803881,-0.002432,0.002101,0.053360,171.269623,8.724890,0.533602,-31.803881,0.054401,0.000000
39.350002,38.804184,-31.848360,-0.002414,0.002122,0.053889,172.609634,8.793154,0.538893,-31.848360,0.055008,0.000000
39.710003,39.799911,-31.848360,-0.002393,0.002150,0.054609,177.038849,9.018789,0.546092,-31.848360,0.055607,0.000000
40.070004,40.004341,-31.848360,-0.002367,0.002169,0.055104,177.948196,9.065114,0.551035,-31.848360,0.056205,0.000000
40.430000,39.984978,-31.848360,-0.002367,0.002190,0.055624,177.862061,9.060725,0.556240,-31.848360,0.056803,0.000000
40.790001,40.816864,-31.848360,-0.002358,0.002215,0.056265,181.562485,9.249233,0.562655,-31.848360,0.057402,0.000000
41.150002,41.662521,-31.892841,-0.002341,0.002239,0.056881,185.324158,9.440863,0.568813,-31.892841,0.058009,0.000000
41.510002,42.337257,-31.803881,-0.002320,0.002261,0.057428,188.325531,9.593760,0.574278,-31.803881,0.058607,0.000000
41.870003,42.863045,-31.892841,-0.002307,0.002282,0.057974,190.664352,9.712905,0.579740,-31.892841,0.059206,0.000000
42.230003,43.064125,-31.892841,-0.002294,0.002303,0.058494,191.558792,9.758471,0.584944,-31.892841,0.059804,0.000000
42.590000,44.326843,-31.892841,-0.002294,0.002335,0.059301,197.175644,10.044606,0.593010,-31.892841,0.060402,0.000000
42.950001,45.541893,-31.981804,-0.002264,0.002362,0.060003,202.580460,10.319941,0.600035,-31.981804,0.061009,0.000000
43.310001,45.963417,-31.937323,-0.002255,0.002383,0.060532,204.455490,10.415460,0.605322,-31.937323,0.061607,0.000000
43.670002,45.447685,-31.981804,-0.002225,0.002396,0.060853,202.161407,10.298593,0.608532,-31.981804,0.062206,0.000000
44.030003,47.269699,-31.981804,-0.002220,0.002429,0.061695,210.266129,10.711468,0.616945,-31.981804,0.062804,0.000000
44.390003,48.265427,-31.981804,-0.002220,0.002459,0.062449,214.695343,10.937102,0.624489,-31.981804,0.063403,0.000000
44.750004,49.202690,-32.070766,-0.002199,0.002481,0.063030,218.864502,11.149488,0.630299,-32.070766,0.064010,0.000000
45.110001,49.794762,-31.981804,-0.002177,0.002506,0.063646,221.498169,11.283654,0.636457,-31.981804,0.064608,0.000000
45.470001,50.759209,-32.026283,-0.002156,0.002531,0.064288,225.788239,11.502201,0.642876,-32.026283,0.065207,0.000000
45.830002,50.542854,-31.981804,-0.002151,0.002546,0.064660,224.825851,11.453175,0.646604,-31.981804,0.065805,0.000000
46.190002,51.187057,-32.070766,-0.002134,0.002568,0.065233,227.691406,11.599153,0.652327,-32.070766,0.066403,0.000000
46.550003,52.040169,-32.070766,-0.002130,0.002593,0.065866,231.486237,11.792471,0.658659,-32.070766,0.067002,0.000000
46.910004,53.121162,-32.026283,-0.002130,0.002621,0.066585,236.294739,12.037428,0.665854,-32.026283,0.067609,0.000000
47.270000,54.071083,-32.070766,-0.002108,0.002643,0.067141,240.520187,12.252682,0.671406,-32.070766,0.068207,0.000000
47.630001,54.729813,-32.115246,-0.002100,0.002666,0.067722,243.450363,12.401953,0.677216,-32.115246,0.068806,0.000000
47.990002,54.471390,-32.115246,-0.002087,0.002681,0.068086,242.300842,12.343393,0.680857,-32.115246,0.069404,0.000000
48.350002,57.022141,-32.159729,-0.002061,0.002718,0.069040,253.647156,12.921402,0.690399,-32.159729,0.070002,0.000000
48.710003,57.919556,-32.159729,-0.002087,0.002743,0.069664,257.639038,13.124759,0.696640,-32.159729,0.070609,0.000000
49.070004,58.341454,-32.204208,-0.002052,0.002765,0.070228,259.515747,13.220362,0.702280,-32.204208,0.071208,0.000000
49.430004,58.822556,-32.159729,-0.002052,0.002786,0.070757,261.655792,13.329382,0.707567,-32.159729,0.071806,0.000000
49.790001,59.298820,-32.115246,-0.002039,0.002805,0.071243,263.774323,13.437305,0.712427,-32.115246,0.072405,0.000000
50.150002,59.851425,-32.204208,-0.002031,0.002831,0.071919,266.232422,13.562527,0.719191,-32.204208,0.073003,0.000000
50.510002,61.095146,-32.159729,-0.002031,0.002857,0.072578,271.764771,13.844357,0.725780,-32.159729,0.073610,0.000000
50.870003,61.543854,-32.204208,-0.002026,0.002874,0.072994,273.760742,13.946036,0.729944,-32.204208,0.074209,0.000000
51.230003,63.190117,-32.204208,-0.002001,0.002907,0.073836,281.083679,14.319085,0.738357,-32.204208,0.074807,0.000000
51.590004,63.827248,-32.204208,-0.001983,0.002929,0.074391,283.917786,14.463461,0.743906,-32.204208,0.075405,0.000000
51.950001,63.840279,-32.248688,-0.001988,0.002947,0.074850,283.975739,14.466414,0.748501,-32.248688,0.076004,0.000000
52.310001,64.108009,-32.159729,-0.001983,0.002964,0.075284,285.166656,14.527082,0.752838,-32.159729,0.076611,0.000000
52.670002,65.712944,-32.337650,-0.001970,0.002996,0.076099,292.305786,14.890766,0.760991,-32.337650,0.077209,0.000000
53.030003,66.096107,-32.337650,-0.001966,0.003018,0.076663,294.010162,14.977592,0.766627,-32.337650,0.077808,0.000000
53.390003,64.547783,-32.204208,-0.001970,0.003009,0.076420,287.122864,14.626737,0.764201,-32.204208,0.013430,0.000000
53.750004,65.308540,-32.293171,-0.001932,0.002898,0.073619,290.506897,14.799127,0.736189,-32.293171,294.500488,0.000000
54.110004,65.198692,-32.293171,-0.001940,0.003048,0.077426,290.018280,14.774235,0.774257,-32.293171,294.500488,0.000000
54.470001,64.919792,-32.382133,-0.001923,0.003062,0.077781,288.777649,14.711036,0.777815,-32.382133,294.500488,0.000000
54.830002,64.895210,-32.293171,-0.001923,0.003076,0.078137,288.668304,14.705465,0.781369,-32.293171,294.500488,0.000000
55.190002,65.446327,-32.337650,-0.001944,0.003095,0.078614,291.119812,14.830349,0.786138,-32.337650,294.500488,0.000000
55.550003,66.528801,-32.426613,-0.001936,0.003083,0.078319,295.934875,15.075642,0.783189,-32.426613,294.500488,0.000000
55.910004,64.989052,-32.382133,-0.001914,0.003111,0.079030,289.085754,14.726729,0.790301,-32.382133,294.500488,0.000000
56.270004,65.539787,-32.382133,-0.001919,0.003135,0.079629,291.535522,14.851528,0.796285,-32.382133,294.500488,0.000000
56.630001,64.200737,-32.337650,-0.001940,0.003136,0.079646,285.579132,14.548095,0.796459,-32.337650,294.500488,0.000000
56.990002,65.976585,-32.426613,-0.001923,0.003000,0.076194,293.478516,14.950507,0.761945,-32.426613,294.500488,0.000000
57.350002,65.278374,-32.471096,-0.001910,0.003169,0.080487,290.372711,14.792291,0.804873,-32.471096,294.500488,0.000000
57.710003,65.046761,-32.471096,-0.001919,0.003180,0.080765,289.342438,14.739807,0.807647,-32.471096,294.500488,0.000000
58.070004,65.007668,-32.471096,-0.001893,0.003191,0.081042,289.168549,14.730948,0.810422,-32.471096,294.500488,0.000000
58.430004,64.942131,-32.426613,-0.001914,0.003202,0.081337,288.877014,14.716098,0.813370,-32.426613,294.500488,0.000000
58.790001,64.806953,-32.471096,-0.001906,0.003215,0.081667,288.275726,14.685465,0.816667,-32.471096,294.500488,0.000000
59.150002,65.048622,-32.471096,-0.001910,0.003224,0.081892,289.350708,14.740228,0.818923,-32.471096,294.500488,0.000000
59.510002,65.323433,-32.515575,-0.001910,0.003236,0.082195,290.573151,14.802502,0.821954,-32.515575,294.500488,0.000000
59.870003,65.582603,-32.560055,-0.001897,0.003249,0.082525,291.725983,14.861231,0.825251,-32.560055,294.500488,0.000000
60.230003,64.685188,-32.471096,-0.001884,0.003249,0.082534,287.734100,14.657873,0.825338,-32.471096,294.500488,0.000000
60.590004,65.273170,-32.515575,-0.001897,0.003264,0.082915,290.349548,14.791112,0.829153,-32.515575,294.500488,0.000000
60.950005,64.338890,-32.560055,-0.001888,0.003264,0.082915,286.193665,14.579401,0.829153,-32.560055,294.500488,0.000000
61.310001,66.420448,-32.604538,-0.001897,0.003173,0.080600,295.452911,15.051089,0.806001,-32.604538,294.500488,0.000000
61.670002,65.398659,-32.604538,-0.001893,0.003236,0.082204,290.907776,14.819548,0.822041,-32.604538,294.500488,0.000000
62.030003,65.285088,-32.560055,-0.001884,0.003297,0.083748,290.402588,14.793813,0.837480,-32.560055,294.500488,0.000000
62.390003,65.026283,-32.649017,-0.001884,0.003304,0.083930,289.251343,14.735167,0.839300,-32.649017,294.500488,0.000000
62.750004,64.916435,-32.560055,-0.001880,0.003313,0.084138,288.762726,14.710275,0.841382,-32.560055,294.500488,0.000000
63.110004,64.961494,-32.649017,-0.001876,0.003321,0.084355,288.963165,14.720485,0.843551,-32.649017,294.500488,0.000000
63.470001,65.036705,-32.649017,-0.001871,0.003330,0.084581,289.297699,14.737528,0.845807,-32.649017,294.500488,0.000000
63.830002,65.005806,-32.604538,-0.001880,0.003337,0.084754,289.160278,14.730526,0.847540,-32.604538,294.500488,0.000000
64.190002,64.947334,-32.693501,-0.001884,0.003343,0.084910,288.900177,14.717276,0.849100,-32.693501,294.500488,0.000000
64.550003,65.212471,-32.649017,-0.001871,0.003354,0.085196,290.079559,14.777357,0.851961,-32.649017,294.500488,0.000000
64.910004,65.100761,-32.693501,-0.001867,0.003360,0.085344,289.582642,14.752044,0.853437,-32.693501,294.500488,0.000000
65.270004,65.304070,-32.649017,-0.001876,0.003368,0.085552,290.487000,14.798114,0.855519,-32.649017,294.500488,0.000000
65.630005,64.775673,-32.693501,-0.001858,0.003368,0.085552,288.136597,14.678377,0.855519,-32.693501,294.500488,0.000000
65.990005,66.151222,-32.737980,-0.001863,0.003379,0.085838,294.255341,14.990082,0.858380,-32.737980,294.500488,0.000000
66.350006,65.389351,-32.693501,-0.001854,0.003379,0.085829,290.866364,14.817439,0.858293,-32.693501,294.500488,0.000000
66.710007,64.710136,-32.782459,-0.001863,0.003380,0.085847,287.845062,14.663527,0.858467,-32.782459,294.500488,0.000000
67.070000,65.463448,-32.737980,-0.001854,0.003398,0.086306,291.195953,14.834229,0.863062,-32.737980,294.500488,0.000000
67.430000,64.853127,-32.737980,-0.001837,0.003398,0.086315,288.481110,14.695929,0.863149,-32.737980,294.500488,0.000000
67.790001,64.261436,-32.826942,-0.001845,0.003398,0.086315,285.849152,14.561850,0.863149,-32.826942,294.500488,0.000000
68.150002,66.415230,-32.782459,-0.001841,0.003248,0.082499,295.429687,15.049907,0.824990,-32.782459,294.500488,0.000000
68.510002,65.823540,-32.826942,-0.001841,0.003252,0.082594,292.797729,14.915827,0.825944,-32.826942,294.500488,0.000000
68.870003,65.251945,-32.826942,-0.001837,0.003392,0.086159,290.255157,14.786302,0.861590,-32.826942,294.500488,0.000000
69.230003,65.107826,-32.826942,-0.001828,0.003424,0.086974,289.614075,14.753644,0.869739,-32.826942,294.500488,0.000000
69.590004,64.684822,-32.915905,-0.001837,0.003426,0.087017,287.732452,14.657790,0.870174,-32.915905,294.500488,0.000000
69.950005,65.674583,-32.826942,-0.001824,0.003434,0.087217,292.135132,14.882073,0.872168,-32.826942,294.500488,0.000000
70.310005,65.104485,-32.915905,-0.001837,0.003434,0.087217,289.599213,14.752887,0.872168,-32.915905,294.500488,0.000000
70.670006,64.564919,-32.915905,-0.001811,0.003434,0.087217,287.199097,14.630620,0.872168,-32.915905,294.500488,0.000000
71.030006,66.863945,-32.871422,-0.001824,0.003304,0.083921,297.425690,15.151587,0.839213,-32.871422,294.500488,0.000000
71.390007,66.216759,-32.960384,-0.001824,0.003303,0.083904,294.546844,15.004931,0.839039,-32.960384,294.500488,0.000000
71.750000,65.727837,-32.915905,-0.001832,0.003316,0.084225,292.372009,14.894140,0.842249,-32.915905,294.500488,0.000000
72.110001,65.292900,-32.915905,-0.001819,0.003435,0.087243,290.437317,14.795583,0.872430,-32.915905,294.500488,0.000000
72.470001,65.074318,-32.915905,-0.001819,0.003460,0.087893,289.465027,14.746051,0.878932,-32.915905,294.500488,0.000000
72.830002,65.865990,-32.915905,-0.001802,0.003474,0.088232,292.986542,14.925447,0.882316,-32.915905,294.500488,0.000000
73.190002,65.398277,-32.960384,-0.001811,0.003474,0.088240,290.906067,14.819462,0.882403,-32.960384,294.500488,0.000000
73.550003,64.957390,-33.004868,-0.001819,0.003474,0.088240,288.944916,14.719555,0.882403,-33.004868,294.500488,0.000000
73.910004,66.434227,-32.960384,-0.001802,0.003461,0.087911,295.514191,15.054212,0.879106,-32.960384,294.500488,0.000000
74.270004,65.974724,-32.915905,-0.001807,0.003461,0.087911,293.470215,14.950087,0.879106,-32.915905,294.500488,0.000000
74.630005,65.535683,-33.049347,-0.001798,0.003462,0.087928,291.517273,14.850598,0.879280,-33.049347,294.500488,0.000000
74.990005,65.244499,-33.049347,-0.001815,0.003485,0.088518,290.222015,14.784615,0.885177,-33.049347,294.500488,0.000000
75.350006,65.195335,-33.004868,-0.001807,0.003497,0.088813,290.003326,14.773474,0.888126,-33.004868,294.500488,0.000000
75.710007,65.442970,-33.138309,-0.001802,0.003505,0.089038,291.104858,14.829589,0.890381,-33.138309,294.500488,0.000000
76.070007,65.254173,-33.049347,-0.001794,0.003505,0.089038,290.265045,14.786807,0.890381,-33.049347,294.500488,0.000000
76.430000,65.250084,-33.093826,-0.001811,0.003511,0.089185,290.246857,14.785880,0.891854,-33.093826,294.500488,0.000000
76.790001,65.124596,-33.049347,-0.001815,0.003513,0.089229,289.688660,14.757444,0.892289,-33.049347,294.500488,0.000000
77.150002,64.932442,-33.093826,-0.001807,0.003513,0.089238,288.833923,14.713902,0.892376,-33.093826,294.500488,0.000000
77.510002,65.479836,-33.138309,-0.001802,0.003522,0.089463,291.268860,14.837942,0.894628,-33.138309,294.500488,0.000000
77.870003,65.232201,-33.138309,-0.001802,0.003523,0.089472,290.167328,14.781828,0.894715,-33.138309,294.500488,0.000000
78.230003,65.209862,-33.182789,-0.001807,0.003527,0.089584,290.067963,14.776766,0.895843,-33.182789,294.500488,0.000000
78.590004,65.334602,-33.138309,-0.001824,0.003532,0.089706,290.622833,14.805033,0.897058,-33.138309,294.500488,0.000000
78.950005,65.194603,-33.182789,-0.001811,0.003532,0.089714,290.000092,14.773308,0.897145,-33.182789,294.500488,0.000000
79.310005,65.035225,-33.138309,-0.001807,0.003533,0.089749,289.291138,14.737193,0.897493,-33.138309,294.500488,0.000000
79.670006,65.579628,-33.182789,-0.001798,0.003542,0.089957,291.712769,14.860556,0.899571,-33.182789,294.500488,0.000000
80.030006,65.357323,-33.227272,-0.001807,0.003542,0.089957,290.723877,14.810181,0.899571,-33.227272,294.500488,0.000000
80.390007,65.130180,-33.182789,-0.001802,0.003542,0.089957,289.713501,14.758710,0.899571,-33.182789,294.500488,0.000000
80.750008,64.881065,-33.227272,-0.001789,0.003542,0.089957,288.605408,14.702259,0.899571,-33.227272,294.500488,0.000000
81.110001,66.056633,-33.227272,-0.001789,0.003546,0.090070,293.834564,14.968647,0.900699,-33.227272,294.500488,0.000000
81.470001,65.772148,-33.227272,-0.001794,0.003546,0.090061,292.569122,14.904181,0.900612,-33.227272,294.500488,0.000000
81.830002,65.453392,-33.316231,-0.001798,0.003546,0.090061,291.151215,14.831951,0.900612,-33.316231,294.500488,0.000000
82.190002,65.160332,-33.227272,-0.001789,0.003546,0.090070,289.847626,14.765542,0.900699,-33.227272,294.500488,0.000000
82.550003,64.899681,-33.271751,-0.001794,0.003561,0.090443,288.688202,14.706478,0.904431,-33.271751,294.500488,0.000000
82.910004,65.762459,-33.271751,-0.001798,0.003556,0.090330,292.526031,14.901986,0.903303,-33.271751,294.500488,0.000000
83.270004,65.471642,-33.316231,-0.001794,0.003556,0.090330,291.232422,14.836086,0.903303,-33.316231,294.500488,0.000000
83.630005,65.203911,-33.405193,-0.001794,0.003556,0.090330,290.041473,14.775417,0.903303,-33.405193,294.500488,0.000000
83.990005,64.950325,-33.316231,-0.001794,0.003556,0.090330,288.913483,14.717954,0.903303,-33.316231,294.500488,0.000000
84.350006,64.688911,-33.360714,-0.001789,0.003556,0.090330,287.750641,14.658716,0.903303,-33.360714,294.500488,0.000000
84.710007,66.589882,-33.316231,-0.001789,0.003555,0.090304,296.206573,15.089482,0.903042,-33.316231,294.500488,0.000000
85.070007,66.178398,-33.360714,-0.001776,0.003549,0.090148,294.376221,14.996240,0.901483,-33.360714,294.500488,0.000000
85.430000,65.896141,-33.316231,-0.001781,0.003549,0.090148,293.120667,14.932280,0.901483,-33.316231,294.500488,0.000000
85.790001,65.734901,-33.360714,-0.001794,0.003549,0.090148,292.403442,14.895741,0.901483,-33.360714,294.500488,0.000000
86.150002,65.462700,-33.449677,-0.001776,0.003549,0.090157,291.192627,14.834060,0.901566,-33.449677,294.500488,0.000000
86.510002,65.278755,-33.405193,-0.001781,0.003568,0.090616,290.374420,14.792377,0.906164,-33.405193,294.500488,0.000000
86.870003,65.107460,-33.405193,-0.001776,0.003575,0.090798,289.612457,14.753561,0.907985,-33.405193,294.500488,0.000000
87.230003,65.212837,-33.405193,-0.001781,0.003582,0.090972,290.081177,14.777440,0.909718,-33.405193,294.500488,0.000000
87.590004,65.050865,-33.449677,-0.001776,0.003582,0.090981,289.360687,14.740736,0.909805,-33.449677,294.500488,0.000000
87.950005,64.980476,-33.494156,-0.001785,0.003584,0.091041,289.047607,14.724787,0.910415,-33.494156,294.500488,0.000000
88.310005,65.084373,-33.449677,-0.001785,0.003589,0.091163,289.509766,14.748329,0.911626,-33.449677,294.500488,0.000000
88.670006,65.061653,-33.494156,-0.001776,0.003589,0.091163,289.408691,14.743181,0.911626,-33.494156,294.500488,0.000000
89.030006,64.911217,-33.449677,-0.001794,0.003589,0.091163,288.739502,14.709092,0.911626,-33.449677,294.500488,0.000000
89.390007,64.768974,-33.494156,-0.001772,0.003589,0.091163,288.106781,14.676860,0.911626,-33.494156,294.500488,0.000000
89.750008,65.397545,-33.538635,-0.001781,0.003599,0.091406,290.902802,14.819296,0.914056,-33.538635,294.500488,0.000000
90.110001,65.297371,-33.538635,-0.001763,0.003599,0.091406,290.457214,14.796596,0.914056,-33.538635,294.500488,0.000000
90.470001,65.159966,-33.583118,-0.001781,0.003599,0.091406,289.846008,14.765460,0.914056,-33.583118,294.500488,0.000000
90.830002,65.002083,-33.538635,-0.001776,0.003599,0.091414,289.143707,14.729683,0.914143,-33.538635,294.500488,0.000000
91.190002,64.905632,-33.538635,-0.001755,0.003600,0.091440,288.714661,14.707827,0.914404,-33.538635,294.500488,0.000000
91.550003,65.362541,-33.627598,-0.001776,0.003607,0.091622,290.747101,14.811363,0.916225,-33.627598,294.500488,0.000000
91.910004,65.306313,-33.538635,-0.001768,0.003607,0.091622,290.496979,14.798622,0.916225,-33.538635,294.500488,0.000000
92.270004,65.182304,-33.627598,-0.001781,0.003607,0.091622,289.945374,14.770521,0.916225,-33.627598,294.500488,0.000000
92.630005,65.037834,-33.538635,-0.001768,0.003608,0.091631,289.302734,14.737784,0.916312,-33.538635,294.500488,0.000000
92.990005,64.899681,-33.627598,-0.001772,0.003608,0.091631,288.688202,14.706478,0.916312,-33.627598,294.500488,0.000000
93.350006,64.758919,-33.627598,-0.001759,0.003608,0.091631,288.062073,14.674582,0.916312,-33.627598,294.500488,0.000000
93.710007,64.631569,-33.672081,-0.001763,0.003608,0.091640,287.495575,14.645722,0.916399,-33.672081,294.500488,0.000000
94.070007,66.008980,-33.672081,-0.001776,0.003619,0.091935,293.622620,14.957849,0.919347,-33.672081,294.500488,0.000000
94.430008,65.865990,-33.672081,-0.001772,0.003619,0.091935,292.986542,14.925447,0.919347,-33.672081,294.500488,0.000000
94.790001,65.662666,-33.716560,-0.001763,0.003619,0.091935,292.082123,14.879373,0.919347,-33.716560,294.500488,0.000000
95.150002,65.536812,-33.672081,-0.001755,0.003619,0.091935,291.522308,14.850854,0.919347,-33.672081,294.500488,0.000000
95.510002,65.349510,-33.716560,-0.001759,0.003619,0.091935,290.689148,14.808411,0.919347,-33.716560,294.500488,0.000000
95.870003,65.221031,-33.761044,-0.001772,0.003619,0.091935,290.117645,14.779297,0.919347,-33.761044,294.500488,0.000000
96.230003,65.044151,-33.716560,-0.001772,0.003619,0.091935,289.330841,14.739215,0.919347,-33.716560,294.500488,0.000000
96.590004,64.916069,-33.716560,-0.001772,0.003619,0.091935,288.761108,14.710192,0.919347,-33.716560,294.500488,0.000000
96.950005,64.771950,-33.761044,-0.001768,0.003619,0.091935,288.120026,14.677533,0.919347,-33.761044,294.500488,0.000000
97.310005,65.788155,-33.716560,-0.001759,0.003633,0.092281,292.640320,14.907809,0.922814,-33.716560,294.500488,0.000000
97.670006,65.694695,-33.761044,-0.001759,0.003633,0.092281,292.224609,14.886631,0.922814,-33.761044,294.500488,0.000000
98.030006,65.603462,-33.761044,-0.001772,0.003633,0.092281,291.818787,14.865956,0.922814,-33.761044,294.500488,0.000000
98.390007,65.504417,-33.805523,-0.001781,0.003633,0.092281,291.378204,14.843513,0.922814,-33.805523,294.500488,0.000000
98.750008,65.357323,-33.805523,-0.001759,0.003633,0.092281,290.723877,14.810181,0.922814,-33.805523,294.500488,0.000000
99.110008,65.265343,-33.894485,-0.001750,0.003633,0.092281,290.314758,14.789338,0.922814,-33.894485,294.500488,0.000000
99.470001,65.130547,-33.850002,-0.001763,0.003633,0.092281,289.715149,14.758793,0.922814,-33.850002,294.500488,0.000000
99.830002,65.022560,-33.850002,-0.001755,0.003633,0.092281,289.234802,14.734323,0.922814,-33.850002,294.500488,0.000000
100.190002,64.915688,-33.938965,-0.001772,0.003633,0.092281,288.759399,14.710105,0.922814,-33.938965,294.500488,0.000000
100.550003,64.771950,-33.805523,-0.001768,0.003633,0.092281,288.120026,14.677533,0.922814,-33.805523,294.500488,0.000000
100.910004,65.456001,-33.850002,-0.001763,0.003643,0.092541,291.162842,14.832541,0.925414,-33.850002,294.500488,0.000000
101.270004,65.384499,-33.894485,-0.001768,0.003642,0.092516,290.844788,14.816339,0.925157,-33.894485,294.500488,0.000000
101.630005,65.291039,-33.850002,-0.001759,0.003643,0.092524,290.429047,14.795160,0.925244,-33.850002,294.500488,0.000000
101.990005,65.234444,-33.894485,-0.001776,0.003643,0.092533,290.177307,14.782336,0.925331,-33.894485,294.500488,0.000000
102.350006,65.117149,-33.850002,-0.001768,0.003643,0.092533,289.655548,14.755756,0.925331,-33.850002,294.500488,0.000000
102.710007,65.140968,-33.938965,-0.001763,0.003645,0.092585,289.761505,14.761155,0.925850,-33.938965,294.500488,0.000000
103.070007,65.088463,-33.983448,-0.001768,0.003645,0.092594,289.527954,14.749257,0.925937,-33.983448,294.500488,0.000000
103.430008,65.018089,-33.938965,-0.001763,0.003645,0.092594,289.214905,14.733310,0.925937,-33.938965,294.500488,0.000000
103.790009,64.954781,-33.983448,-0.001759,0.003646,0.092602,288.933289,14.718964,0.926024,-33.983448,294.500488,0.000000
104.150002,65.293648,-33.983448,-0.001750,0.003652,0.092750,290.440643,14.795753,0.927496,-33.983448,294.500488,0.000000
104.510002,65.292900,-34.027927,-0.001781,0.003652,0.092750,290.437317,14.795583,0.927496,-34.027927,294.500488,0.000000
104.870003,65.223640,-33.983448,-0.001768,0.003652,0.092750,290.129242,14.779888,0.927496,-33.983448,294.500488,0.000000
105.230003,65.121986,-34.072407,-0.001768,0.003652,0.092750,289.677063,14.756853,0.927496,-34.072407,294.500488,0.000000
105.590004,65.083626,-34.027927,-0.001772,0.003652,0.092758,289.506439,14.748160,0.927583,-34.027927,294.500488,0.000000
105.950005,64.999107,-34.027927,-0.001759,0.003652,0.092758,289.130463,14.729008,0.927583,-34.027927,294.500488,0.000000
106.310005,65.221413,-34.116890,-0.001759,0.003656,0.092871,290.119324,14.779383,0.928711,-34.116890,294.500488,0.000000
106.670006,65.195335,-34.027927,-0.001755,0.003656,0.092871,290.003326,14.773474,0.928711,-34.027927,294.500488,0.000000
107.030006,65.109688,-34.072407,-0.001763,0.003656,0.092871,289.622345,14.754066,0.928711,-34.072407,294.500488,0.000000
107.390007,65.048256,-34.116890,-0.001763,0.003656,0.092871,289.349091,14.740146,0.928711,-34.116890,294.500488,0.000000
107.750008,64.986061,-34.027927,-0.001746,0.003656,0.092871,289.072449,14.726052,0.928711,-34.027927,294.500488,0.000000
108.110008,65.180824,-34.161369,-0.001755,0.003660,0.092975,289.938782,14.770185,0.929752,-34.161369,294.500488,0.000000
108.470009,65.156609,-34.072407,-0.001763,0.003660,0.092975,289.831085,14.764699,0.929752,-34.072407,294.500488,0.000000
108.830002,65.103737,-34.161369,-0.001763,0.003660,0.092975,289.595886,14.752718,0.929752,-34.161369,294.500488,0.000000
109.190002,65.216560,-34.205853,-0.001759,0.003665,0.093088,290.097748,14.778284,0.930880,-34.205853,294.500488,0.000000
109.550003,65.327156,-34.072407,-0.001746,0.003665,0.093088,290.589691,14.803345,0.930880,-34.072407,294.500488,0.000000
109.910004,65.292900,-34.161369,-0.001759,0.003665,0.093088,290.437317,14.795583,0.930880,-34.161369,294.500488,0.000000
110.270004,65.243370,-34.161369,-0.001742,0.003665,0.093088,290.217010,14.784359,0.930880,-34.161369,294.500488,0.000000
110.630005,65.158104,-34.250332,-0.001746,0.003665,0.093088,289.837708,14.765038,0.930880,-34.250332,294.500488,0.000000
110.990005,65.136131,-34.205853,-0.001746,0.003666,0.093123,289.739990,14.760058,0.931228,-34.205853,294.500488,0.000000
111.350006,65.105232,-34.205853,-0.001746,0.003667,0.093149,289.602539,14.753057,0.931485,-34.205853,294.500488,0.000000
111.710007,65.131660,-34.205853,-0.001755,0.003668,0.093166,289.720093,14.759045,0.931659,-34.205853,294.500488,0.000000
112.070007,65.112679,-34.250332,-0.001755,0.003668,0.093175,289.635651,14.754745,0.931747,-34.250332,294.500488,0.000000
112.430008,65.095924,-34.294815,-0.001750,0.003669,0.093201,289.561127,14.750948,0.932008,-34.294815,294.500488,0.000000
112.790009,65.038948,-34.250332,-0.001755,0.003669,0.093201,289.307678,14.738036,0.932008,-34.250332,294.500488,0.000000
113.150009,65.017342,-34.294815,-0.001755,0.003672,0.093261,289.211578,14.733141,0.932613,-34.294815,294.500488,0.000000
113.510002,65.369240,-34.383774,-0.001776,0.003674,0.093331,290.776886,14.812881,0.933310,-34.383774,1681.640991,0.000000
113.870003,65.310036,-34.339294,-0.001742,0.003665,0.093088,290.513550,14.799465,0.930880,-34.339294,0.093279,0.000000
114.230003,65.187889,-34.339294,-0.001746,0.003657,0.092889,289.970215,14.771787,0.928885,-34.339294,0.092680,0.000000
114.590004,65.117882,-34.294815,-0.001746,0.003642,0.092498,289.658813,14.755923,0.924983,-34.294815,0.092082,0.000000
114.950005,64.966331,-34.339294,-0.001746,0.003618,0.091909,288.984680,14.721581,0.919086,-34.339294,0.091484,0.000000
115.310005,64.787224,-34.339294,-0.001755,0.003596,0.091336,288.187958,14.680995,0.913363,-34.339294,0.090885,0.000000
115.670006,64.754082,-34.383774,-0.001742,0.003580,0.090920,288.040527,14.673485,0.909200,-34.383774,0.090278,0.000000
116.030006,64.614067,-34.383774,-0.001742,0.003553,0.090235,287.417725,14.641757,0.902349,-34.383774,0.089680,0.000000
116.390007,64.536613,-34.383774,-0.001738,0.003526,0.089558,287.073181,14.624206,0.895582,-34.383774,0.089081,0.000000
116.750008,64.494530,-34.383774,-0.001738,0.003508,0.089099,286.885986,14.614669,0.890987,-34.383774,0.088483,0.000000
117.110008,64.309090,-34.428257,-0.001755,0.003479,0.088379,286.061127,14.572648,0.883788,-34.428257,0.087885,0.000000
117.470009,64.272606,-34.428257,-0.001746,0.003461,0.087902,285.898834,14.564381,0.879019,-34.428257,0.087286,0.000000
117.830002,64.029808,-34.428257,-0.001742,0.003446,0.087538,284.818817,14.509362,0.875378,-34.428257,0.086679,0.000000
118.190002,63.237038,-34.517220,-0.001742,0.003421,0.086896,281.292389,14.329718,0.868959,-34.517220,0.086081,0.000000
118.550003,62.225670,-34.428257,-0.001750,0.003397,0.086280,276.793610,14.100538,0.862801,-34.428257,0.085482,0.000000
118.910004,61.315216,-34.428257,-0.001738,0.003378,0.085803,272.743713,13.894226,0.858032,-34.428257,0.084884,0.000000
119.270004,59.514053,-34.472736,-0.001729,0.003348,0.085040,264.731720,13.486077,0.850402,-34.472736,0.084285,0.000000
119.630005,58.237564,-34.561699,-0.001712,0.003330,0.084589,259.053619,13.196820,0.845890,-34.561699,0.083679,0.000000
119.990005,57.168854,-34.517220,-0.001707,0.003315,0.084199,254.299759,12.954648,0.841988,-34.517220,0.083080,0.000000
120.350006,55.526688,-34.561699,-0.001690,0.003297,0.083739,246.995041,12.582527,0.837393,-34.561699,0.082482,0.000000
120.710007,52.742088,-34.517220,-0.001699,0.003262,0.082846,234.608521,11.951528,0.828461,-34.517220,0.081884,0.000000
121.070007,50.694412,-34.561699,-0.001690,0.003242,0.082334,225.500015,11.487518,0.823343,-34.561699,0.081285,0.000000
121.430008,48.260590,-34.561699,-0.001694,0.003216,0.081693,214.673828,10.936007,0.816928,-34.561699,0.080678,0.000000
121.790009,45.934006,-34.517220,-0.001686,0.003195,0.081164,204.324661,10.408794,0.811637,-34.517220,0.080080,0.000000
122.150009,43.651733,-34.606178,-0.001686,0.003173,0.080583,194.172607,9.891624,0.805827,-34.606178,0.079481,0.000000
122.510002,41.377281,-34.561699,-0.001690,0.003152,0.080071,184.055344,9.376226,0.800710,-34.561699,0.078883,0.000000
122.870003,38.553955,-34.650661,-0.001686,0.003127,0.079429,171.496552,8.736451,0.794290,-34.650661,0.078284,0.000000
123.230003,35.631943,-34.606178,-0.001703,0.003099,0.078710,158.498795,8.074313,0.787095,-34.606178,0.077677,0.000000
123.590004,33.636406,-34.650661,-0.001681,0.003080,0.078241,149.622208,7.622118,0.782410,-34.650661,0.077079,0.000000
123.950005,30.399368,-34.695141,-0.001681,0.003051,0.077487,135.223145,6.888596,0.774866,-34.695141,0.076481,0.000000
124.310005,28.142044,-34.650661,-0.001690,0.003031,0.076984,125.182068,6.377078,0.769836,-34.650661,0.075882,0.000000
124.670006,25.958458,-34.650661,-0.001681,0.003010,0.076463,115.468987,5.882271,0.764632,-34.650661,0.075284,0.000000
125.030006,22.763870,-34.695141,-0.001690,0.002979,0.075674,101.258751,5.158367,0.756741,-34.695141,0.074685,0.000000
125.390007,20.511391,-34.650661,-0.001677,0.002959,0.075162,91.239220,4.647947,0.751623,-34.650661,0.074078,0.000000
125.750008,17.641518,-34.739624,-0.001673,0.002931,0.074442,78.473389,3.997625,0.744425,-34.739624,0.073480,0.000000
126.110008,15.586761,-34.650661,-0.001681,0.002911,0.073939,69.333374,3.532011,0.739394,-34.650661,0.072882,0.000000
126.470009,13.106766,-34.784103,-0.001677,0.002889,0.073376,58.301807,2.970036,0.733759,-34.784103,0.072283,0.000000
126.830009,11.520828,-34.695141,-0.001694,0.002874,0.073003,51.247204,2.610657,0.730031,-34.695141,0.071685,0.000000
127.190002,7.788170,-34.739624,-0.001686,0.002838,0.072084,34.643509,1.764825,0.720837,-34.739624,0.071078,0.000000
127.550003,6.084190,-34.784103,-0.001694,0.002822,0.071667,27.063831,1.378697,0.716674,-34.784103,0.070479,0.000000
127.910004,3.254532,-34.695141,-0.001677,0.002788,0.070818,14.476881,0.737487,0.708177,-34.695141,0.069881,0.000000
128.270004,1.798927,-34.784103,-0.001677,0.002772,0.070410,8.002028,0.407643,0.704100,-34.784103,0.069283,0.000000
128.630005,-0.588348,-34.828587,-0.001681,0.002750,0.069838,-2.617104,-0.133322,0.698377,-34.828587,0.068684,0.000000
128.990005,-3.004303,-34.828587,-0.001673,0.002722,0.069127,-13.363807,-0.680785,0.691266,-34.828587,0.068077,0.000000
129.350006,-0.265129,-34.828587,-0.001690,0.002701,0.068615,-1.179353,-0.060079,0.686148,-34.828587,0.067479,0.000000
129.710007,-0.034630,-34.828587,-0.001694,0.002678,0.068016,-0.154041,-0.007847,0.680165,-34.828587,0.066880,0.000000
130.070007,0.029419,-34.873066,-0.001673,0.002654,0.067409,0.130862,0.006666,0.674094,-34.873066,0.066282,0.000000
130.430008,-0.021973,-34.873066,-0.001604,0.002628,0.066759,-0.097739,-0.004979,0.667591,-34.873066,0.065683,0.000000
130.790009,-0.087509,-34.873066,-0.001539,0.002604,0.066152,-0.389260,-0.019830,0.661520,-34.873066,0.065077,0.000000
131.150009,-0.115440,-34.873066,-0.001509,0.002580,0.065528,-0.513504,-0.026159,0.655275,-34.873066,0.064478,0.000000
131.510010,-0.094582,-34.917545,-0.001462,0.002556,0.064929,-0.420720,-0.021432,0.649291,-34.917545,0.063880,0.000000
131.870010,-0.104263,-35.006508,-0.001449,0.002538,0.064470,-0.463786,-0.023626,0.644696,-35.006508,0.063282,0.000000
132.230011,-0.119904,-34.873066,-0.001444,0.002513,0.063828,-0.533358,-0.027171,0.638277,-34.873066,0.062683,0.000000
132.590012,-0.167572,-34.962029,-0.001444,0.002487,0.063169,-0.745398,-0.037972,0.631688,-34.962029,0.062076,0.000000
132.950012,-0.172409,-34.917545,-0.001453,0.002457,0.062405,-0.766914,-0.039068,0.624053,-34.917545,0.061478,0.000000
133.310013,-0.166824,-34.917545,-0.001457,0.002436,0.061868,-0.742072,-0.037803,0.618679,-34.917545,0.060879,0.000000
133.670013,-0.173897,-34.962029,-0.001453,0.002411,0.061235,-0.773532,-0.039406,0.612347,-34.962029,0.060281,0.000000
134.029999,-0.193260,-34.917545,-0.001470,0.002380,0.060463,-0.859664,-0.043793,0.604629,-34.917545,0.059682,0.000000
134.389999,-0.182091,-35.006508,-0.001470,0.002363,0.060020,-0.809980,-0.041262,0.600205,-35.006508,0.059084,0.000000
134.750000,-0.173897,-35.006508,-0.001496,0.002337,0.059362,-0.773532,-0.039406,0.593615,-35.006508,0.058477,0.000000
135.110001,-0.218216,-35.006508,-0.001492,0.002317,0.058841,-0.970673,-0.049448,0.588411,-35.006508,0.057879,0.000000
135.470001,-0.192894,-35.095470,-0.001513,0.002292,0.058217,-0.858035,-0.043710,0.582170,-35.095470,0.057280,0.000000
135.830002,-0.215981,-35.006508,-0.001526,0.002271,0.057688,-0.960729,-0.048942,0.576879,-35.006508,0.056682,0.000000
136.190002,-0.212997,-35.050991,-0.001522,0.002250,0.057159,-0.947460,-0.048266,0.571587,-35.050991,0.056083,0.000000
136.550003,-0.199219,-35.095470,-0.001539,0.002223,0.056465,-0.886169,-0.045144,0.564650,-35.095470,0.055476,0.000000
136.910004,-0.187309,-35.050991,-0.001561,0.002198,0.055832,-0.833193,-0.042445,0.558321,-35.050991,0.054878,0.000000
137.270004,-0.212997,-35.050991,-0.001578,0.002177,0.055294,-0.947460,-0.048266,0.552943,-35.050991,0.054280,0.000000
137.630005,-0.177628,-35.050991,-0.001582,0.002159,0.054843,-0.790127,-0.040251,0.548431,-35.050991,0.053681,0.000000
137.990005,-0.189537,-35.095470,-0.001617,0.002127,0.054020,-0.843103,-0.042950,0.540195,-35.095470,0.053083,0.000000
138.350006,-0.205177,-35.139950,-0.001613,0.002107,0.053508,-0.912674,-0.046494,0.535078,-35.139950,0.052476,0.000000
138.710007,-0.221191,-35.095470,-0.001656,0.002079,0.052805,-0.983909,-0.050123,0.528053,-35.095470,0.051877,0.000000
139.070007,-0.246887,-35.139950,-0.001647,0.002059,0.052294,-1.098209,-0.055945,0.522936,-35.139950,0.051279,0.000000
139.430008,-0.220078,-35.184433,-0.001681,0.002031,0.051591,-0.978954,-0.049870,0.515911,-35.184433,0.050680,0.000000
139.790009,-0.209274,-35.184433,-0.001707,0.002007,0.050975,-0.930899,-0.047422,0.509753,-35.184433,0.050082,0.000000
140.150009,-0.222679,-35.184433,-0.001716,0.001991,0.050568,-0.990526,-0.050460,0.505677,-35.184433,0.049475,0.000000
140.510010,-0.233482,-35.184433,-0.001733,0.001962,0.049831,-1.038581,-0.052908,0.498308,-35.184433,0.048877,0.000000
140.870010,-0.246887,-35.228912,-0.001781,0.001941,0.049293,-1.098209,-0.055945,0.492930,-35.228912,0.048278,0.000000
141.230011,-0.229385,-35.228912,-0.001785,0.001914,0.048625,-1.020357,-0.051979,0.486253,-35.228912,0.047680,0.000000
141.590012,-0.226776,-35.228912,-0.001807,0.001898,0.048218,-1.008751,-0.051388,0.482177,-35.228912,0.047082,0.000000
141.950012,-0.229385,-35.228912,-0.001854,0.001867,0.047429,-1.020357,-0.051979,0.474285,-35.228912,0.046483,0.000000
142.310013,-0.242043,-35.228912,-0.001858,0.001844,0.046848,-1.076659,-0.054848,0.468475,-35.228912,0.045876,0.000000
142.670013,-0.258804,-35.273396,-0.001876,0.001823,0.046310,-1.151219,-0.058646,0.463097,-35.273396,0.045278,0.000000
143.030014,-0.235718,-35.228912,-0.001906,0.001801,0.045737,-1.048525,-0.053414,0.457374,-35.228912,0.044680,0.000000
143.389999,-0.242043,-35.273396,-0.001936,0.001778,0.045165,-1.076659,-0.054848,0.451652,-35.273396,0.044081,0.000000
143.750000,-0.239441,-35.273396,-0.001940,0.001754,0.044541,-1.065086,-0.054258,0.445406,-35.273396,0.043483,0.000000
144.110001,-0.246513,-35.362354,-0.001970,0.001727,0.043856,-1.096546,-0.055861,0.438556,-35.362354,0.042876,0.000000
144.470001,-0.240929,-35.362354,-0.002022,0.001703,0.043248,-1.071704,-0.054595,0.432485,-35.362354,0.042277,0.000000
144.830002,-0.220818,-35.273396,-0.002035,0.001684,0.042763,-0.982246,-0.050038,0.427629,-35.273396,0.041679,0.000000
145.190002,-0.235718,-35.362354,-0.002048,0.001657,0.042087,-1.048525,-0.053414,0.420865,-35.362354,0.041080,0.000000
145.550003,-0.232735,-35.317875,-0.002070,0.001635,0.041523,-1.035256,-0.052738,0.415226,-35.317875,0.040482,0.000000
145.910004,-0.231247,-35.406837,-0.002091,0.001613,0.040968,-1.028638,-0.052401,0.409677,-35.406837,0.039875,0.000000
146.270004,-0.214485,-35.406837,-0.002113,0.001584,0.040222,-0.954078,-0.048603,0.402217,-35.406837,0.039277,0.000000
146.630005,-0.224915,-35.317875,-0.002121,0.001562,0.039676,-1.000470,-0.050966,0.396755,-35.317875,0.038678,0.000000
146.990005,-0.234970,-35.451317,-0.002177,0.001538,0.039060,-1.045199,-0.053245,0.390597,-35.451317,0.038080,0.000000
147.350006,-0.246513,-35.406837,-0.002195,0.001514,0.038444,-1.096546,-0.055861,0.384439,-35.406837,0.037481,0.000000
147.710007,-0.242416,-35.406837,-0.002207,0.001495,0.037984,-1.078322,-0.054932,0.379844,-35.406837,0.036874,0.000000
148.070007,-0.253960,-35.451317,-0.002242,0.001478,0.037542,-1.129669,-0.057548,0.375420,-35.451317,0.036276,0.000000
148.430008,-0.221565,-35.451317,-0.002276,0.001441,0.036606,-0.985571,-0.050207,0.366056,-35.451317,0.035678,0.000000
148.790009,-0.235718,-35.451317,-0.002302,0.001423,0.036154,-1.048525,-0.053414,0.361545,-35.451317,0.035079,0.000000
149.150009,-0.221191,-35.495800,-0.002302,0.001396,0.035461,-0.983909,-0.050123,0.354607,-35.495800,0.034481,0.000000
149.510010,-0.218956,-35.451317,-0.002341,0.001370,0.034802,-0.973965,-0.049616,0.348017,-35.451317,0.034724,0.000000
149.600006,-0.215981,-35.540279,-0.002337,0.001370,0.034810,-0.960729,-0.048942,0.348104,-35.540279,0.034724,0.000000