File: Data/compression 25/AutoNoHeating-17-25-reverse-1-1_09232024_183849.csv
Time (sec),S:Load (lbs),S:HL1 (DIM),S:LVDT (in),S:Position (in),Ch:Position (mm),Ch:Load (N),Ch:Stress (MPa),Ch:Strain (mm/mm),Ch:HL1 (DIM),Set Point (),Cycles ()
0.110000,-0.086021,-22.863209,-0.005131,-0.005364,-0.136250,-0.382642,-0.019493,-1.362498,-22.863209,-0.136042,0.000000
0.480000,-0.071129,-22.907690,-0.005135,-0.005316,-0.135018,-0.316397,-0.016118,-1.350182,-22.907690,-0.134428,0.000000
0.850000,-0.076340,-22.952171,-0.005023,-0.005101,-0.129572,-0.339576,-0.017299,-1.295721,-22.952171,-0.128271,0.000000
1.220000,-0.090492,-22.996653,-0.004769,-0.004859,-0.123415,-0.402530,-0.020506,-1.234148,-22.996653,-0.122114,0.000000
1.590000,-0.075966,-22.996653,-0.004527,-0.004608,-0.117032,-0.337913,-0.017214,-1.170320,-22.996653,-0.115939,0.000000
1.960000,-0.094582,-22.952171,-0.004286,-0.004364,-0.110840,-0.420720,-0.021432,-1.108399,-22.952171,-0.109782,0.000000
2.330000,0.129211,-23.041132,-0.004070,-0.000001,-0.000017,0.574761,0.029280,-0.000174,-23.041132,0.000139,0.000000
2.700000,0.100166,-22.996653,-0.004079,-0.000001,-0.000026,0.445562,0.022698,-0.000261,-22.996653,0.000139,0.000000
3.070000,0.129585,-23.085613,-0.004079,-0.000001,-0.000026,0.576424,0.029364,-0.000261,-23.085613,0.000616,0.000000
3.440000,0.112823,-23.041132,-0.004070,0.000000,0.000009,0.501864,0.025566,0.000087,-23.041132,0.001231,0.000000
3.810000,0.221558,-22.996653,-0.004066,0.000029,0.000746,0.985538,0.050206,0.007456,-22.996653,0.001847,0.000000
4.180000,0.398437,-22.996653,-0.004057,0.000057,0.001457,1.772339,0.090287,0.014568,-22.996653,0.002472,0.000000
4.550000,0.569725,-23.041132,-0.004018,0.000077,0.001960,2.534264,0.129102,0.019598,-23.041132,0.003087,0.000000
4.920000,0.770805,-23.085613,-0.004005,0.000097,0.002454,3.428714,0.174667,0.024541,-23.085613,0.003703,0.000000
5.290000,1.164032,-23.041132,-0.003988,0.000131,0.003339,5.177873,0.263773,0.033387,-23.041132,0.004319,0.000000
5.660000,1.393417,-23.085613,-0.003962,0.000153,0.003876,6.198230,0.315753,0.038765,-23.085613,0.004934,0.000000
6.030000,1.819412,-23.085613,-0.003958,0.000176,0.004475,8.093150,0.412285,0.044749,-23.085613,0.005550,0.000000
6.400000,2.269981,-23.219057,-0.003932,0.000201,0.005116,10.097382,0.514385,0.051164,-23.219057,0.006166,0.000000
6.770000,2.657990,-23.174576,-0.003919,0.000220,0.005576,11.823328,0.602309,0.055763,-23.174576,0.006782,0.000000
7.140000,3.247459,-23.219057,-0.003898,0.000247,0.006261,14.445421,0.735885,0.062614,-23.219057,0.007397,0.000000
7.510000,3.701752,-23.174576,-0.003872,0.000268,0.006808,16.466213,0.838829,0.068075,-23.174576,0.008022,0.000000
7.880001,4.361969,-23.219057,-0.003859,0.000298,0.007580,19.403008,0.988436,0.075796,-23.219057,0.008638,0.000000
8.250000,4.929466,-23.219057,-0.003842,0.000324,0.008230,21.927361,1.117033,0.082299,-23.219057,0.009253,0.000000
8.620001,5.400887,-23.219057,-0.003829,0.000342,0.008698,24.024343,1.223858,0.086981,-23.219057,0.009869,0.000000
8.990001,6.108398,-23.263536,-0.003807,0.000368,0.009349,27.171513,1.384183,0.093487,-23.263536,0.010485,0.000000
9.360001,6.632324,-23.219057,-0.003786,0.000391,0.009921,29.502052,1.502906,0.099210,-23.219057,0.011100,0.000000
9.730000,7.201309,-23.219057,-0.003768,0.000415,0.010545,32.033024,1.631840,0.105455,-23.219057,0.011716,0.000000
10.100000,7.752792,-23.263536,-0.003751,0.000438,0.011135,34.486141,1.756808,0.111352,-23.263536,0.012332,0.000000
10.470000,8.399231,-23.263536,-0.003712,0.000467,0.011863,37.361645,1.903293,0.118634,-23.263536,0.012948,0.000000
10.840000,9.044556,-23.352499,-0.003704,0.000495,0.012583,40.232193,2.049526,0.125833,-23.352499,0.013572,0.000000
11.210001,9.658226,-23.352499,-0.003682,0.000520,0.013199,42.961933,2.188585,0.131991,-23.352499,0.014188,0.000000
11.580001,9.836220,-23.308018,-0.003665,0.000536,0.013624,43.753693,2.228919,0.136241,-23.308018,0.014803,0.000000
11.950001,10.928009,-23.352499,-0.003643,0.000571,0.014509,48.610210,2.476322,0.145086,-23.352499,0.015419,0.000000
12.320001,11.110474,-23.352499,-0.003635,0.000591,0.015003,49.421856,2.517669,0.150029,-23.352499,0.016035,0.000000
12.690001,11.380074,-23.352499,-0.003613,0.000610,0.015489,50.621094,2.578761,0.154885,-23.352499,0.016651,0.000000
13.060000,12.221260,-23.485943,-0.003591,0.000634,0.016113,54.362881,2.769377,0.161131,-23.485943,0.017266,0.000000
13.430000,12.459953,-23.396980,-0.003557,0.000653,0.016581,55.424641,2.823466,0.165812,-23.396980,0.017882,0.000000
13.800000,13.259064,-23.441462,-0.003557,0.000685,0.017388,58.979259,3.004547,0.173878,-23.441462,0.018498,0.000000
14.170001,13.592712,-23.441462,-0.003523,0.000707,0.017969,60.463406,3.080153,0.179688,-23.441462,0.019122,0.000000
14.540001,14.264473,-23.441462,-0.003518,0.000731,0.018576,63.451546,3.232376,0.185759,-23.441462,0.019738,0.000000
14.910001,15.020012,-23.441462,-0.003497,0.000762,0.019356,66.812347,3.403583,0.193563,-23.441462,0.020354,0.000000
15.280001,15.036400,-23.530422,-0.003488,0.000783,0.019877,66.885246,3.407297,0.198768,-23.530422,0.020969,0.000000
15.650001,15.490318,-23.441462,-0.003445,0.000805,0.020458,68.904381,3.510156,0.204577,-23.441462,0.021585,0.000000
16.020000,16.484924,-23.485943,-0.003436,0.000839,0.021308,73.328606,3.735537,0.213078,-23.485943,0.022201,0.000000
16.390001,16.285332,-23.530422,-0.003432,0.000856,0.021741,72.440773,3.690309,0.217412,-23.530422,0.022816,0.000000
16.760000,17.112000,-23.619385,-0.003402,0.000884,0.022452,76.117973,3.877635,0.224524,-23.619385,0.023432,0.000000
17.130001,17.683594,-23.530422,-0.003372,0.000909,0.023086,78.660553,4.007160,0.230856,-23.530422,0.024048,0.000000
17.500000,17.734238,-23.574903,-0.003372,0.000928,0.023571,78.885826,4.018636,0.235712,-23.574903,0.024673,0.000000
17.870001,18.513237,-23.530422,-0.003363,0.000957,0.024299,82.350990,4.195159,0.242994,-23.530422,0.025288,0.000000
18.240002,18.579521,-23.619385,-0.003328,0.000975,0.024768,82.645836,4.210180,0.247680,-23.619385,0.025904,0.000000
18.610001,19.227448,-23.574903,-0.003328,0.001004,0.025505,85.527962,4.357002,0.255049,-23.574903,0.026520,0.000000
18.980001,19.649345,-23.663866,-0.003298,0.001028,0.026112,87.404655,4.452606,0.261120,-23.663866,0.027135,0.000000
19.350000,19.958786,-23.619385,-0.003277,0.001052,0.026719,88.781113,4.522726,0.267191,-23.619385,0.027751,0.000000
19.720001,20.331535,-23.619385,-0.003260,0.001075,0.027317,90.439186,4.607192,0.273175,-23.619385,0.028367,0.000000
20.090000,20.495377,-23.619385,-0.003247,0.001095,0.027812,91.167992,4.644319,0.278118,-23.619385,0.028982,0.000000
20.460001,20.849129,-23.663866,-0.003216,0.001117,0.028367,92.741554,4.724480,0.283670,-23.663866,0.029607,0.000000
20.830002,21.989708,-23.663866,-0.003208,0.001155,0.029330,97.815109,4.982939,0.293295,-23.663866,0.030223,0.000000
21.200001,22.026199,-23.752829,-0.003186,0.001178,0.029928,97.977425,4.991208,0.299279,-23.752829,0.030839,0.000000
21.570002,22.400436,-23.708347,-0.003173,0.001204,0.030587,99.642120,5.076012,0.305869,-23.708347,0.031454,0.000000
21.940001,22.136795,-23.619385,-0.003169,0.001218,0.030934,98.469383,5.016270,0.309339,-23.619385,0.032070,0.000000
22.310001,22.544540,-23.708347,-0.003152,0.001240,0.031506,100.283127,5.108666,0.315062,-23.708347,0.032686,0.000000
22.680000,23.370468,-23.797308,-0.003126,0.001269,0.032235,103.957031,5.295824,0.322348,-23.797308,0.033301,0.000000
23.050001,23.483292,-23.752829,-0.003117,0.001293,0.032833,104.458900,5.321390,0.328332,-23.752829,0.033917,0.000000
23.420002,24.068665,-23.797308,-0.003113,0.001320,0.033527,107.062767,5.454038,0.335270,-23.797308,0.034533,0.000000
23.790001,24.471573,-23.752829,-0.003083,0.001345,0.034160,108.854996,5.545338,0.341598,-23.752829,0.035157,0.000000
24.160002,24.333794,-23.797308,-0.003074,0.001361,0.034567,108.242119,5.514117,0.345674,-23.797308,0.035773,0.000000
24.530001,25.275154,-23.841789,-0.003070,0.001393,0.035391,112.429504,5.727432,0.353914,-23.841789,0.036389,0.000000
24.900002,25.372711,-23.797308,-0.003048,0.001414,0.035912,112.863457,5.749538,0.359118,-23.797308,0.037005,0.000000
25.270000,25.487030,-23.841789,-0.003035,0.001435,0.036441,113.371971,5.775444,0.364406,-23.841789,0.037620,0.000000
25.640001,26.363594,-23.797308,-0.003022,0.001465,0.037204,117.271126,5.974076,0.372040,-23.797308,0.038236,0.000000
26.010002,26.070908,-23.886271,-0.003001,0.001482,0.037637,115.969193,5.907752,0.376374,-23.886271,0.038852,0.000000
26.380001,27.054344,-23.841789,-0.002992,0.001515,0.038470,120.343735,6.130602,0.384701,-23.841789,0.039467,0.000000
26.750002,27.123238,-23.930752,-0.002979,0.001536,0.039008,120.650185,6.146214,0.390079,-23.930752,0.040083,0.000000
27.120001,27.215584,-23.930752,-0.002962,0.001558,0.039580,121.060966,6.167140,0.395802,-23.930752,0.040707,0.000000
27.490002,27.846756,-23.930752,-0.002966,0.001585,0.040257,123.868561,6.310165,0.402565,-23.930752,0.041323,0.000000
27.860001,27.939476,-23.930752,-0.002949,0.001604,0.040751,124.280998,6.331176,0.407508,-23.930752,0.041939,0.000000
28.230001,28.164391,-24.019714,-0.002936,0.001627,0.041332,125.281464,6.382142,0.413318,-24.019714,0.042555,0.000000
28.600002,28.530800,-23.930752,-0.002928,0.001653,0.041974,126.911339,6.465171,0.419737,-23.930752,0.043171,0.000000
28.970001,28.787743,-24.019714,-0.002902,0.001671,0.042433,128.054276,6.523396,0.424332,-24.019714,0.043786,0.000000
29.340002,29.457268,-23.975233,-0.002897,0.001700,0.043188,131.032471,6.675113,0.431879,-23.975233,0.044402,0.000000
29.710001,29.970024,-23.975233,-0.002867,0.001727,0.043873,133.313324,6.791305,0.438730,-23.975233,0.045018,0.000000
30.080002,30.077263,-24.108675,-0.002880,0.001748,0.044410,133.790344,6.815605,0.444104,-24.108675,0.045633,0.000000
30.450001,30.479057,-24.108675,-0.002876,0.001770,0.044966,135.577621,6.906653,0.449657,-24.108675,0.046258,0.000000
30.820002,31.034637,-24.019714,-0.002837,0.001799,0.045703,138.048965,7.032549,0.457026,-24.019714,0.046873,0.000000
31.190001,30.936333,-24.064194,-0.002841,0.001814,0.046076,137.611679,7.010273,0.460758,-24.064194,0.047489,0.000000
31.560001,32.626152,-24.064194,-0.002837,0.001853,0.047064,145.128372,7.393192,0.470644,-24.064194,0.048105,0.000000
31.930002,32.539024,-24.108675,-0.002824,0.001873,0.047567,144.740814,7.373448,0.475674,-24.108675,0.048721,0.000000
32.300003,33.515755,-24.064194,-0.002820,0.001904,0.048365,149.085526,7.594779,0.483649,-24.064194,0.049336,0.000000
32.670002,33.688904,-24.108675,-0.002802,0.001926,0.048929,149.855728,7.634015,0.489289,-24.108675,0.049952,0.000000
33.040001,33.684814,-24.153156,-0.002777,0.001950,0.049527,149.837540,7.633088,0.495272,-24.153156,0.050568,0.000000
33.410000,34.465302,-24.064194,-0.002772,0.001977,0.050221,153.309311,7.809949,0.502210,-24.064194,0.051184,0.000000
33.780003,34.036331,-24.108675,-0.002764,0.001994,0.050646,151.401169,7.712743,0.506461,-24.108675,0.051808,0.000000
34.150002,34.165169,-24.153156,-0.002772,0.002014,0.051149,151.974258,7.741938,0.511491,-24.153156,0.052424,0.000000
34.520000,34.684258,-24.197638,-0.002751,0.002043,0.051895,154.283279,7.859565,0.518947,-24.197638,0.053039,0.000000
34.890003,35.482994,-24.197638,-0.002746,0.002061,0.052354,157.836243,8.040562,0.523542,-24.197638,0.053655,0.000000
35.260002,36.275406,-24.153156,-0.002729,0.002090,0.053074,161.361069,8.220125,0.530741,-24.153156,0.054271,0.000000
35.630001,36.445206,-24.153156,-0.002738,0.002109,0.053568,162.116379,8.258602,0.535684,-24.153156,0.054887,0.000000
36.000000,37.325127,-24.108675,-0.002716,0.002136,0.054262,166.030457,8.457994,0.542621,-24.108675,0.055502,0.000000
36.370003,38.724503,-24.286600,-0.002708,0.002171,0.055147,172.255188,8.775097,0.551467,-24.286600,0.056118,0.000000
36.740002,38.718544,-24.286600,-0.002686,0.002189,0.055607,172.228683,8.773747,0.556065,-24.286600,0.056734,0.000000
37.110001,39.273750,-24.242119,-0.002695,0.002219,0.056352,174.698364,8.899559,0.563522,-24.242119,0.057358,0.000000
37.480003,40.079933,-24.242119,-0.002677,0.002244,0.056994,178.284454,9.082243,0.569941,-24.242119,0.057974,0.000000
37.850002,39.817413,-24.286600,-0.002682,0.002262,0.057445,177.116699,9.022755,0.574449,-24.286600,0.058590,0.000000
38.220001,40.685783,-24.375561,-0.002677,0.002290,0.058165,180.979401,9.219530,0.581648,-24.375561,0.059206,0.000000
38.590000,41.344139,-24.375561,-0.002673,0.002317,0.058841,183.907913,9.368715,0.588411,-24.375561,0.059821,0.000000
38.960003,41.513573,-24.375561,-0.002647,0.002337,0.059362,184.661591,9.407110,0.593615,-24.375561,0.060437,0.000000
39.330002,42.012177,-24.375561,-0.002652,0.002360,0.059951,186.879501,9.520096,0.599512,-24.375561,0.061053,0.000000
39.700001,41.860619,-24.331079,-0.002643,0.002379,0.060428,186.205338,9.485752,0.604281,-24.331079,0.061668,0.000000
40.070004,42.941994,-24.375561,-0.002634,0.002409,0.061183,191.015533,9.730794,0.611828,-24.375561,0.062284,0.000000
40.440002,43.445435,-24.420042,-0.002634,0.002431,0.061755,193.254944,9.844876,0.617551,-24.420042,0.062908,0.000000
40.810001,44.052406,-24.464523,-0.002621,0.002457,0.062405,195.954895,9.982418,0.624053,-24.464523,0.063524,0.000000
41.180000,44.361099,-24.464523,-0.002596,0.002480,0.062986,197.328018,10.052369,0.629863,-24.464523,0.064140,0.000000
41.550003,44.241570,-24.420042,-0.002591,0.002499,0.063481,196.796326,10.025283,0.634810,-24.420042,0.064756,0.000000
41.920002,45.815590,-24.464523,-0.002574,0.002537,0.064435,203.797928,10.381961,0.644348,-24.464523,0.065372,0.000000
42.290001,46.923393,-24.464523,-0.002570,0.002562,0.065076,208.725677,10.632993,0.650764,-24.464523,0.065987,0.000000
42.660004,46.692154,-24.553486,-0.002548,0.002584,0.065632,207.697067,10.580593,0.656316,-24.553486,0.066603,0.000000
43.030003,47.206398,-24.464523,-0.002548,0.002608,0.066247,209.984543,10.697123,0.662474,-24.464523,0.067219,0.000000
43.400002,47.023567,-24.509005,-0.002539,0.002624,0.066655,209.171280,10.655692,0.666550,-24.509005,0.067843,0.000000
43.770000,46.814667,-24.509005,-0.002544,0.002646,0.067201,208.242035,10.608356,0.672012,-24.509005,0.068459,0.000000
44.140003,47.903854,-24.509005,-0.002548,0.002676,0.067964,213.086990,10.855168,0.679642,-24.509005,0.069074,0.000000
44.510002,48.230423,-24.553486,-0.002527,0.002700,0.068571,214.539642,10.929171,0.685713,-24.553486,0.069690,0.000000
44.880001,49.157631,-24.597965,-0.002488,0.002727,0.069265,218.664062,11.139278,0.692651,-24.597965,0.070306,0.000000
45.250004,49.403397,-24.597965,-0.002492,0.002748,0.069794,219.757278,11.194970,0.697942,-24.597965,0.070922,0.000000
45.620003,49.495743,-24.553486,-0.002483,0.002769,0.070341,220.168060,11.215896,0.703408,-24.553486,0.071538,0.000000
45.990002,50.329491,-24.553486,-0.002475,0.002798,0.071078,223.876755,11.404825,0.710777,-24.553486,0.072153,0.000000
46.360001,50.354805,-24.597965,-0.002466,0.002817,0.071546,223.989365,11.410563,0.715459,-24.597965,0.072769,0.000000
46.730003,50.986725,-24.642447,-0.002462,0.002844,0.072248,226.800278,11.553757,0.722483,-24.642447,0.073393,0.000000
47.100002,51.334518,-24.597965,-0.002453,0.002867,0.072821,228.347336,11.632568,0.728210,-24.597965,0.074009,0.000000
47.470001,51.783226,-24.597965,-0.002414,0.002891,0.073419,230.343292,11.734247,0.734194,-24.597965,0.074625,0.000000
47.840004,53.271233,-24.642447,-0.002406,0.002924,0.074269,236.962280,12.071433,0.742691,-24.642447,0.075240,0.000000
48.210003,53.192657,-24.686928,-0.002402,0.002942,0.074737,236.612762,12.053629,0.747373,-24.686928,0.075856,0.000000
48.580002,53.630196,-24.731409,-0.002389,0.002965,0.075301,238.559021,12.152776,0.753012,-24.731409,0.076472,0.000000
48.950001,54.519424,-24.731409,-0.002371,0.002993,0.076012,242.514511,12.354278,0.760124,-24.731409,0.077088,0.000000
49.320004,54.642303,-24.686928,-0.002354,0.003012,0.076498,243.061111,12.382123,0.764980,-24.686928,0.077704,0.000000
49.690002,54.886955,-24.731409,-0.002367,0.003034,0.077062,244.149368,12.437562,0.770616,-24.731409,0.078319,0.000000
50.060001,55.228416,-24.731409,-0.002328,0.003053,0.077556,245.668259,12.514938,0.775559,-24.731409,0.078943,0.000000
50.430004,56.564491,-24.775890,-0.002320,0.003085,0.078362,251.611420,12.817698,0.783625,-24.775890,0.079559,0.000000
50.800003,57.897957,-24.820372,-0.002320,0.003114,0.079108,257.542969,13.119864,0.791081,-24.820372,0.080175,0.000000
51.170002,57.718849,-24.731409,-0.002302,0.003127,0.079429,256.746277,13.079278,0.794290,-24.731409,0.080790,0.000000
51.540001,58.720901,-24.731409,-0.002285,0.003156,0.080175,261.203613,13.306346,0.801751,-24.731409,0.081406,0.000000
51.910004,59.536026,-24.775890,-0.002285,0.003179,0.080747,264.829468,13.491056,0.807473,-24.775890,0.082022,0.000000
52.280003,59.878235,-24.909332,-0.002272,0.003199,0.081250,266.351685,13.568602,0.812503,-24.909332,0.082638,0.000000
52.650002,60.917152,-24.864851,-0.002259,0.003226,0.081944,270.973022,13.804024,0.819441,-24.864851,0.083254,0.000000
53.020004,62.451698,-24.820372,-0.002242,0.003257,0.082716,277.799042,14.151757,0.827159,-24.820372,0.083869,0.000000
53.390003,63.211708,-24.820372,-0.002238,0.003280,0.083323,281.179718,14.323977,0.833229,-24.820372,0.084494,0.000000
53.760002,64.495659,-24.864851,-0.002225,0.003311,0.084112,286.891022,14.614925,0.841121,-24.864851,0.085109,0.000000
54.130001,64.763390,-24.909332,-0.002216,0.003326,0.084476,288.081940,14.675594,0.844762,-24.909332,0.085725,0.000000
54.500004,65.895409,-24.998295,-0.002199,0.003353,0.085162,293.117432,14.932113,0.851617,-24.998295,0.086341,0.000000
54.870003,65.375572,-24.909332,-0.002173,0.003357,0.085257,290.805084,14.814316,0.852570,-24.909332,0.014973,0.000000
55.240002,65.032982,-24.909332,-0.002164,0.003372,0.085639,289.281158,14.736685,0.856385,-24.909332,294.500488,0.000000
55.610004,65.763588,-24.909332,-0.002156,0.003352,0.085144,292.531036,14.902242,0.851442,-24.909332,294.500488,0.000000
55.980003,65.147682,-24.953814,-0.002151,0.003397,0.086271,289.791351,14.762676,0.862714,-24.953814,294.500488,0.000000
56.350002,64.927605,-25.042776,-0.002139,0.003408,0.086558,288.812408,14.712806,0.865575,-25.042776,294.500488,0.000000
56.720001,65.448555,-24.998295,-0.002100,0.003421,0.086887,291.129700,14.830854,0.868872,-24.998295,294.500488,0.000000
57.090004,65.065758,-24.998295,-0.002121,0.003427,0.087052,289.426941,14.744112,0.870522,-24.998295,294.500488,0.000000
57.460003,65.074318,-24.998295,-0.002104,0.003436,0.087277,289.465027,14.746051,0.872774,-24.998295,294.500488,0.000000
57.830002,65.135765,-25.042776,-0.002108,0.003446,0.087520,289.738342,14.759975,0.875204,-25.042776,294.500488,0.000000
58.200005,65.243752,-25.087255,-0.002091,0.003457,0.087798,290.218689,14.784445,0.877978,-25.087255,294.500488,0.000000
58.570004,65.250450,-25.087255,-0.002082,0.003464,0.087980,290.248505,14.785963,0.879799,-25.087255,294.500488,0.000000
58.940002,64.993889,-25.087255,-0.002087,0.003469,0.088110,289.107269,14.727826,0.881101,-25.087255,294.500488,0.000000
59.310001,65.015862,-25.131737,-0.002087,0.003476,0.088301,289.204987,14.732804,0.883008,-25.131737,294.500488,0.000000
59.680004,65.253426,-25.087255,-0.002078,0.003485,0.088526,290.261719,14.786638,0.885264,-25.087255,294.500488,0.000000
60.050003,64.895576,-25.087255,-0.002070,0.003488,0.088604,288.669952,14.705547,0.886044,-25.087255,294.500488,0.000000
60.420002,64.933556,-25.176218,-0.002070,0.003496,0.088804,288.838867,14.714154,0.888039,-25.176218,294.500488,0.000000
60.790005,64.850899,-25.131737,-0.002052,0.003504,0.088995,288.471191,14.695423,0.889946,-25.131737,294.500488,0.000000
61.160004,64.992393,-25.131737,-0.002048,0.003504,0.088995,289.100616,14.727487,0.889946,-25.131737,294.500488,0.000000
61.530003,64.839729,-25.131737,-0.002039,0.003521,0.089437,288.421509,14.692893,0.894371,-25.131737,294.500488,0.000000
61.900002,65.761345,-25.176218,-0.002044,0.003512,0.089203,292.521057,14.901734,0.892028,-25.176218,294.500488,0.000000
62.270004,65.217308,-25.220699,-0.002057,0.003512,0.089203,290.101074,14.778454,0.892028,-25.220699,294.500488,0.000000
62.640003,64.714607,-25.220699,-0.002026,0.003512,0.089203,287.864960,14.664539,0.892028,-25.220699,294.500488,0.000000
63.010002,66.248787,-25.220699,-0.002026,0.003496,0.088804,294.689331,15.012190,0.888039,-25.220699,294.500488,0.000000
63.380005,65.774376,-25.220699,-0.002013,0.003497,0.088813,292.579041,14.904686,0.888126,-25.220699,294.500488,0.000000
63.750004,65.308922,-25.220699,-0.002013,0.003497,0.088830,290.508606,14.799213,0.888300,-25.220699,294.500488,0.000000
64.120003,65.118629,-25.309662,-0.002013,0.003533,0.089740,289.662140,14.756093,0.897402,-25.309662,294.500488,0.000000
64.490005,65.085869,-25.309662,-0.002022,0.003539,0.089888,289.516418,14.748669,0.898879,-25.309662,294.500488,0.000000
64.860001,65.057930,-25.265181,-0.001996,0.003546,0.090079,289.392120,14.742338,0.900786,-25.265181,294.500488,0.000000
65.230003,65.218422,-25.265181,-0.002001,0.003547,0.090105,290.106018,14.778706,0.901047,-25.265181,294.500488,0.000000
65.600006,65.154381,-25.309662,-0.002005,0.003551,0.090191,289.821167,14.764194,0.901914,-25.309662,294.500488,0.000000
65.970001,65.173378,-25.309662,-0.002005,0.003556,0.090313,289.905670,14.768499,0.903129,-25.309662,294.500488,0.000000
66.340004,65.043037,-25.354141,-0.001996,0.003556,0.090313,289.325867,14.738962,0.903129,-25.354141,294.500488,0.000000
66.710007,65.322685,-25.309662,-0.002009,0.003562,0.090478,290.569824,14.802332,0.904775,-25.309662,294.500488,0.000000
67.080002,65.136513,-25.398623,-0.002001,0.003562,0.090478,289.741669,14.760145,0.904775,-25.398623,294.500488,0.000000
67.450005,65.104851,-25.398623,-0.002005,0.003565,0.090556,289.600830,14.752970,0.905555,-25.398623,294.500488,0.000000
67.820000,64.941750,-25.398623,-0.001979,0.003567,0.090590,288.875336,14.716010,0.905903,-25.398623,294.500488,0.000000
68.190002,65.400139,-25.443104,-0.001992,0.003572,0.090738,290.914337,14.819883,0.907376,-25.443104,294.500488,0.000000
68.560005,65.207634,-25.443104,-0.001975,0.003573,0.090746,290.058044,14.776261,0.907463,-25.443104,294.500488,0.000000
68.930000,64.991646,-25.354141,-0.001979,0.003573,0.090746,289.097290,14.727318,0.907463,-25.354141,294.500488,0.000000
69.300003,64.770470,-25.398623,-0.001992,0.003573,0.090746,288.113434,14.677198,0.907463,-25.398623,294.500488,0.000000
69.670006,65.775124,-25.532066,-0.001992,0.003585,0.091067,292.582367,14.904856,0.910672,-25.532066,294.500488,0.000000
70.040001,65.605324,-25.532066,-0.001979,0.003585,0.091067,291.827057,14.866379,0.910672,-25.532066,294.500488,0.000000
70.410004,65.456001,-25.487585,-0.001970,0.003585,0.091067,291.162842,14.832541,0.910672,-25.487585,294.500488,0.000000
70.780006,65.283226,-25.487585,-0.001975,0.003585,0.091067,290.394287,14.793390,0.910672,-25.487585,294.500488,0.000000
71.150002,65.073204,-25.532066,-0.001970,0.003585,0.091067,289.460083,14.745798,0.910672,-25.532066,294.500488,0.000000
71.520004,64.889244,-25.487585,-0.001962,0.003585,0.091067,288.641785,14.704113,0.910672,-25.487585,294.500488,0.000000
71.890007,64.719078,-25.532066,-0.001975,0.003585,0.091067,287.884827,14.665552,0.910672,-25.532066,294.500488,0.000000
72.260002,64.530663,-25.576548,-0.001970,0.003586,0.091076,287.046722,14.622857,0.910759,-25.576548,294.500488,0.000000
72.630005,64.377235,-25.576548,-0.001970,0.003586,0.091076,286.364258,14.588090,0.910759,-25.576548,294.500488,0.000000
73.000000,66.558220,-25.532066,-0.001979,0.003468,0.088075,296.065735,15.082308,0.880753,-25.532066,294.500488,0.000000
73.370003,66.323997,-25.621027,-0.001966,0.003468,0.088084,295.023865,15.029233,0.880840,-25.621027,294.500488,0.000000
73.740005,66.123665,-25.621027,-0.001966,0.003468,0.088084,294.132751,14.983836,0.880840,-25.621027,294.500488,0.000000
74.110001,65.920357,-25.665508,-0.001953,0.003469,0.088101,293.228394,14.937766,0.881014,-25.665508,294.500488,0.000000
74.480003,65.773628,-25.665508,-0.001944,0.003469,0.088101,292.575714,14.904517,0.881014,-25.665508,294.500488,0.000000
74.850006,65.570686,-25.621027,-0.001957,0.003480,0.088396,291.672974,14.858530,0.883962,-25.621027,294.500488,0.000000
75.220001,65.432167,-25.621027,-0.001953,0.003501,0.088917,291.056824,14.827141,0.889166,-25.621027,294.500488,0.000000
75.590004,65.301094,-25.709990,-0.001953,0.003571,0.090712,290.473785,14.797440,0.907118,-25.709990,294.500488,0.000000
75.960007,65.207634,-25.709990,-0.001944,0.003587,0.091111,290.058044,14.776261,0.911107,-25.709990,294.500488,0.000000
76.330002,65.053474,-25.709990,-0.001949,0.003588,0.091145,289.372314,14.741328,0.911452,-25.709990,294.500488,0.000000
76.700005,65.079536,-25.754471,-0.001927,0.003600,0.091449,289.488251,14.747233,0.914487,-25.754471,294.500488,0.000000
77.070007,64.991280,-25.709990,-0.001936,0.003603,0.091510,289.095642,14.727234,0.915097,-25.709990,294.500488,0.000000
77.440002,65.216194,-25.754471,-0.001936,0.003608,0.091639,290.096130,14.778201,0.916395,-25.754471,294.500488,0.000000
77.810005,65.108574,-25.798952,-0.001936,0.003608,0.091639,289.617401,14.753814,0.916395,-25.798952,294.500488,0.000000
78.180000,65.267952,-25.798952,-0.001949,0.003612,0.091752,290.326355,14.789929,0.917523,-25.798952,294.500488,0.000000
78.550003,65.251564,-25.798952,-0.001940,0.003612,0.091752,290.253448,14.786216,0.917523,-25.798952,294.500488,0.000000
78.920006,65.156990,-25.843433,-0.001953,0.003612,0.091752,289.832764,14.764785,0.917523,-25.843433,294.500488,0.000000
79.290001,65.487648,-25.798952,-0.001927,0.003619,0.091934,291.303619,14.839713,0.919343,-25.798952,294.500488,0.000000
79.660004,65.528984,-25.887913,-0.001923,0.003619,0.091934,291.487488,14.849080,0.919343,-25.887913,294.500488,0.000000
80.030006,65.463081,-25.843433,-0.001932,0.003619,0.091934,291.194336,14.834146,0.919343,-25.843433,294.500488,0.000000
80.400002,65.365883,-25.887913,-0.001949,0.003619,0.091934,290.761963,14.812121,0.919343,-25.887913,294.500488,0.000000
80.770004,65.291039,-25.798952,-0.001932,0.003619,0.091934,290.429047,14.795160,0.919343,-25.798952,294.500488,0.000000
81.140007,65.246361,-25.843433,-0.001949,0.003622,0.091987,290.230316,14.785036,0.919866,-25.843433,294.500488,0.000000
81.510002,65.354347,-25.932394,-0.001940,0.003623,0.092030,290.710663,14.809507,0.920297,-25.932394,294.500488,0.000000
81.880005,65.323067,-25.932394,-0.001923,0.003624,0.092038,290.571503,14.802419,0.920384,-25.932394,294.500488,0.000000
82.250008,65.338707,-25.976875,-0.001936,0.003626,0.092091,290.641083,14.805963,0.920907,-25.976875,294.500488,0.000000
82.620003,65.302956,-25.932394,-0.001923,0.003626,0.092099,290.482056,14.797861,0.920994,-25.932394,294.500488,0.000000
82.990005,65.331261,-25.976875,-0.001949,0.003627,0.092125,290.607971,14.804276,0.921255,-25.976875,294.500488,0.000000
83.360001,65.295876,-25.976875,-0.001949,0.003627,0.092134,290.450562,14.796256,0.921338,-25.976875,294.500488,0.000000
83.730003,65.330147,-26.021357,-0.001949,0.003630,0.092203,290.602997,14.804023,0.922035,-26.021357,294.500488,0.000000
84.100006,65.347267,-25.976875,-0.001936,0.003630,0.092203,290.679169,14.807902,0.922035,-25.976875,294.500488,0.000000
84.470001,65.310783,-25.976875,-0.001940,0.003630,0.092203,290.516876,14.799635,0.922035,-25.976875,294.500488,0.000000
84.840004,65.295876,-25.976875,-0.001940,0.003631,0.092229,290.450562,14.796256,0.922292,-25.976875,294.500488,0.000000
85.210007,65.275780,-26.065838,-0.001932,0.003632,0.092255,290.361176,14.791703,0.922553,-26.065838,294.500488,0.000000
85.580002,65.263115,-26.021357,-0.001932,0.003632,0.092255,290.304840,14.788833,0.922553,-26.021357,294.500488,0.000000
85.950005,65.201668,-26.110319,-0.001940,0.003632,0.092264,290.031494,14.774909,0.922640,-26.110319,294.500488,0.000000
86.320007,65.341316,-26.065838,-0.001932,0.003636,0.092351,290.652679,14.806554,0.923507,-26.065838,294.500488,0.000000
86.690002,65.328285,-25.976875,-0.001940,0.003636,0.092351,290.594727,14.803600,0.923507,-25.976875,294.500488,0.000000
87.060005,65.286201,-26.110319,-0.001944,0.003636,0.092351,290.407532,14.794065,0.923507,-26.110319,294.500488,0.000000
87.430008,65.235924,-26.199280,-0.001940,0.003636,0.092351,290.183868,14.782672,0.923507,-26.199280,294.500488,0.000000
87.800003,65.175972,-26.243761,-0.001927,0.003636,0.092351,289.917206,14.769087,0.923507,-26.243761,294.500488,0.000000
88.170006,65.499565,-26.065838,-0.001919,0.003641,0.092490,291.356628,14.842414,0.924896,-26.065838,294.500488,0.000000
88.540001,65.500679,-26.065838,-0.001923,0.003641,0.092490,291.361572,14.842667,0.924896,-26.065838,294.500488,0.000000
88.910004,65.458611,-26.199280,-0.001940,0.003641,0.092490,291.174438,14.833133,0.924896,-26.199280,294.500488,0.000000
89.280006,65.397545,-26.199280,-0.001936,0.003641,0.092490,290.902802,14.819296,0.924896,-26.199280,294.500488,0.000000
89.650002,65.345039,-26.199280,-0.001927,0.003641,0.092490,290.669250,14.807397,0.924896,-26.199280,294.500488,0.000000
90.020004,65.305183,-26.243761,-0.001927,0.003641,0.092490,290.491974,14.798367,0.924896,-26.243761,294.500488,0.000000
90.390007,65.272423,-26.199280,-0.001932,0.003642,0.092498,290.346252,14.790943,0.924983,-26.199280,294.500488,0.000000
90.760002,65.204643,-26.199280,-0.001932,0.003642,0.092516,290.044739,14.775583,0.925157,-26.199280,294.500488,0.000000
91.130005,65.166298,-26.288242,-0.001919,0.003642,0.092516,289.874176,14.766894,0.925157,-26.288242,294.500488,0.000000
91.500008,65.118629,-26.332724,-0.001927,0.003643,0.092533,289.662140,14.756093,0.925327,-26.332724,294.500488,0.000000
91.870003,65.165550,-26.288242,-0.001932,0.003644,0.092559,289.870850,14.766726,0.925588,-26.288242,294.500488,0.000000
92.240005,65.146553,-26.243761,-0.001932,0.003644,0.092568,289.786346,14.762421,0.925676,-26.243761,294.500488,0.000000
92.610001,65.108955,-26.288242,-0.001932,0.003645,0.092576,289.619110,14.753900,0.925763,-26.288242,294.500488,0.000000
92.980003,65.120491,-26.332724,-0.001927,0.003646,0.092602,289.670410,14.756514,0.926024,-26.332724,294.500488,0.000000
93.350006,65.114540,-26.421684,-0.001923,0.003646,0.092611,289.643951,14.755165,0.926111,-26.421684,294.500488,0.000000
93.720001,65.101509,-26.332724,-0.001927,0.003646,0.092620,289.585968,14.752213,0.926198,-26.332724,294.500488,0.000000
94.090004,65.054207,-26.332724,-0.001932,0.003646,0.092620,289.375549,14.741493,0.926198,-26.332724,294.500488,0.000000
94.460007,65.061653,-26.377205,-0.001927,0.003647,0.092646,289.408691,14.743181,0.926455,-26.377205,294.500488,0.000000
94.830002,65.031120,-26.377205,-0.001923,0.003648,0.092654,289.272858,14.736262,0.926542,-26.377205,294.500488,0.000000
95.200005,65.035225,-26.466166,-0.001923,0.003648,0.092663,289.291138,14.737193,0.926629,-26.466166,294.500488,0.000000
95.570007,65.018837,-26.421684,-0.001914,0.003648,0.092663,289.218231,14.733479,0.926629,-26.421684,294.500488,0.000000
95.940002,65.007286,-26.421684,-0.001923,0.003649,0.092680,289.166840,14.730862,0.926803,-26.421684,294.500488,0.000000
96.310005,65.375572,-26.466166,-0.001927,0.003654,0.092802,290.805084,14.814316,0.928018,-26.466166,294.500488,0.000000
96.680008,65.385994,-26.466166,-0.001919,0.003654,0.092802,290.851440,14.816678,0.928018,-26.466166,294.500488,0.000000
97.050003,65.359932,-26.466166,-0.001914,0.003654,0.092802,290.735504,14.810773,0.928018,-26.466166,294.500488,0.000000
97.420006,65.329399,-26.555128,-0.001914,0.003654,0.092802,290.599670,14.803853,0.928018,-26.555128,294.500488,0.000000
97.790001,65.291039,-26.421684,-0.001923,0.003654,0.092802,290.429047,14.795160,0.928018,-26.421684,294.500488,0.000000
98.160004,65.264977,-26.466166,-0.001927,0.003654,0.092802,290.313110,14.789255,0.928018,-26.466166,294.500488,0.000000
98.530006,65.228859,-26.510647,-0.001914,0.003654,0.092802,290.152466,14.781071,0.928018,-26.510647,294.500488,0.000000
98.900002,65.191994,-26.599609,-0.001923,0.003654,0.092802,289.988464,14.772717,0.928018,-26.599609,294.500488,0.000000
99.270004,65.156242,-26.555128,-0.001914,0.003654,0.092811,289.829437,14.764615,0.928105,-26.555128,294.500488,0.000000
99.640007,65.108208,-26.510647,-0.001927,0.003655,0.092836,289.615784,14.753730,0.928363,-26.510647,294.500488,0.000000
100.010002,65.186409,-26.555128,-0.001901,0.003657,0.092880,289.963623,14.771451,0.928798,-26.555128,294.500488,0.000000
100.380005,65.219551,-26.555128,-0.001923,0.003657,0.092880,290.111053,14.778962,0.928798,-26.555128,294.500488,0.000000
100.750008,65.174858,-26.688570,-0.001919,0.003657,0.092889,289.912262,14.768834,0.928885,-26.688570,294.500488,0.000000
101.120003,65.165184,-26.688570,-0.001910,0.003657,0.092897,289.869202,14.766642,0.928972,-26.688570,294.500488,0.000000
101.490005,65.141716,-26.599609,-0.001906,0.003657,0.092897,289.764832,14.761324,0.928972,-26.599609,294.500488,0.000000
101.860008,65.112679,-26.599609,-0.001910,0.003657,0.092897,289.635651,14.754745,0.928972,-26.599609,294.500488,0.000000
102.230003,65.121239,-26.644089,-0.001927,0.003659,0.092932,289.673737,14.756683,0.929317,-26.644089,294.500488,0.000000
102.600006,65.113045,-26.688570,-0.001932,0.003659,0.092932,289.637299,14.754827,0.929317,-26.688570,294.500488,0.000000
102.970001,65.117882,-26.688570,-0.001923,0.003659,0.092940,289.658813,14.755923,0.929404,-26.688570,294.500488,0.000000
103.340004,65.103371,-26.733051,-0.001919,0.003659,0.092940,289.594269,14.752634,0.929404,-26.733051,294.500488,0.000000
103.710007,65.078789,-26.688570,-0.001910,0.003659,0.092949,289.484924,14.747064,0.929491,-26.688570,294.500488,0.000000
104.080002,65.074699,-26.688570,-0.001919,0.003659,0.092949,289.466705,14.746138,0.929491,-26.688570,294.500488,0.000000
104.450005,65.044151,-26.733051,-0.001927,0.003659,0.092949,289.330841,14.739215,0.929491,-26.733051,294.500488,0.000000
104.820007,65.020699,-26.777533,-0.001923,0.003660,0.092958,289.226501,14.733901,0.929578,-26.777533,294.500488,0.000000
105.190002,65.028145,-26.777533,-0.001914,0.003661,0.092984,289.259644,14.735588,0.929839,-26.777533,294.500488,0.000000
105.560005,65.041924,-26.733051,-0.001914,0.003661,0.092993,289.320923,14.738711,0.929926,-26.733051,294.500488,0.000000
105.930008,65.043419,-26.733051,-0.001914,0.003662,0.093010,289.327576,14.739050,0.930100,-26.733051,294.500488,0.000000
106.300003,65.039314,-26.777533,-0.001914,0.003662,0.093019,289.309326,14.738119,0.930187,-26.777533,294.500488,0.000000
106.670006,65.030754,-26.777533,-0.001910,0.003662,0.093019,289.271240,14.736180,0.930187,-26.777533,294.500488,0.000000
107.040009,65.037086,-26.866495,-0.001914,0.003662,0.093019,289.299408,14.737615,0.930187,-26.866495,294.500488,0.000000
107.410004,65.210609,-26.866495,-0.001897,0.003667,0.093149,290.071289,14.776936,0.931485,-26.866495,294.500488,0.000000
107.780006,65.321571,-26.822014,-0.001914,0.003667,0.093149,290.564850,14.802079,0.931485,-26.822014,294.500488,0.000000
108.150002,65.358437,-26.910975,-0.001914,0.003667,0.093149,290.728851,14.810433,0.931485,-26.910975,294.500488,0.000000
108.520004,65.341316,-26.866495,-0.001901,0.003667,0.093149,290.652679,14.806554,0.931485,-26.866495,294.500488,0.000000
108.890007,65.324547,-26.910975,-0.001910,0.003667,0.093149,290.578094,14.802753,0.931485,-26.910975,294.500488,0.000000
109.260002,65.297371,-26.910975,-0.001906,0.003667,0.093149,290.457214,14.796596,0.931485,-26.910975,294.500488,0.000000
109.630005,65.288063,-26.822014,-0.001910,0.003667,0.093149,290.415802,14.794487,0.931485,-26.822014,294.500488,0.000000
110.000008,65.271675,-26.910975,-0.001914,0.003667,0.093149,290.342926,14.790773,0.931485,-26.910975,294.500488,0.000000
110.370003,65.237785,-26.955456,-0.001914,0.003667,0.093149,290.192169,14.783093,0.931485,-26.955456,294.500488,0.000000
110.740005,65.205772,-26.999937,-0.001901,0.003667,0.093149,290.049774,14.775839,0.931485,-26.999937,294.500488,0.000000
111.110008,65.173378,-26.955456,-0.001906,0.003667,0.093149,289.905670,14.768499,0.931485,-26.955456,294.500488,0.000000
111.480003,65.147682,-26.955456,-0.001906,0.003667,0.093149,289.791351,14.762676,0.931485,-26.955456,294.500488,0.000000
111.850006,65.104485,-26.999937,-0.001906,0.003667,0.093149,289.599213,14.752887,0.931485,-26.999937,294.500488,0.000000
112.220009,65.082146,-26.999937,-0.001919,0.003668,0.093157,289.499847,14.747825,0.931572,-26.999937,294.500488,0.000000
112.590004,65.076180,-27.044418,-0.001910,0.003668,0.093166,289.473297,14.746473,0.931659,-27.044418,294.500488,0.000000
112.960007,65.041557,-27.044418,-0.001906,0.003668,0.093166,289.319305,14.738627,0.931659,-27.044418,294.500488,0.000000
113.330002,65.011391,-27.044418,-0.001919,0.003668,0.093175,289.185120,14.731791,0.931747,-27.044418,294.500488,0.000000
113.700005,65.285088,-27.044418,-0.001919,0.003673,0.093305,290.402588,14.793813,0.933049,-27.044418,294.500488,0.000000
114.070007,65.366264,-27.088900,-0.001901,0.003673,0.093305,290.763672,14.812207,0.933049,-27.088900,294.500488,0.000000
114.440002,65.370354,-27.133381,-0.001901,0.003673,0.093305,290.781860,14.813134,0.933049,-27.133381,294.500488,0.000000
114.810005,65.374825,-27.133381,-0.001906,0.003673,0.093305,290.801758,14.814147,0.933049,-27.133381,294.500488,0.000000
115.180008,65.361046,-27.088900,-0.001906,0.003673,0.093305,290.740448,14.811025,0.933049,-27.088900,1681.640991,0.000000
115.550003,65.355461,-27.088900,-0.001897,0.003665,0.093097,290.715607,14.809759,0.930967,-27.088900,0.092984,0.000000
115.920006,65.233696,-27.133381,-0.001914,0.003645,0.092594,290.173981,14.782166,0.925937,-27.133381,0.092368,0.000000
116.290009,65.202049,-27.133381,-0.001910,0.003625,0.092073,290.033203,14.774996,0.920732,-27.133381,0.091752,0.000000
116.660004,65.107094,-27.177860,-0.001901,0.003600,0.091440,289.610809,14.753479,0.914400,-27.177860,0.091136,0.000000
117.030006,65.102989,-27.177860,-0.001914,0.003577,0.090859,289.592560,14.752548,0.908591,-27.177860,0.090521,0.000000
117.400009,65.083260,-27.177860,-0.001897,0.003556,0.090313,289.504791,14.748077,0.903129,-27.177860,0.089905,0.000000
117.770004,64.990532,-27.177860,-0.001897,0.003538,0.089853,289.092316,14.727065,0.898530,-27.177860,0.089289,0.000000
118.140007,64.990913,-27.222342,-0.001906,0.003507,0.089073,289.094025,14.727151,0.890726,-27.222342,0.088674,0.000000
118.510002,64.884407,-27.266823,-0.001897,0.003482,0.088448,288.620270,14.703016,0.884481,-27.266823,0.088050,0.000000
118.880005,64.810310,-27.222342,-0.001906,0.003463,0.087954,288.290649,14.686226,0.879538,-27.222342,0.087434,0.000000
119.250008,64.631203,-27.266823,-0.001893,0.003436,0.087277,287.493958,14.645640,0.872774,-27.266823,0.086818,0.000000
119.620003,64.089760,-27.222342,-0.001906,0.003417,0.086783,285.085480,14.522947,0.867831,-27.222342,0.086202,0.000000
119.990005,63.438484,-27.311304,-0.001906,0.003402,0.086402,282.188477,14.375366,0.864016,-27.311304,0.085586,0.000000
120.360008,62.135559,-27.311304,-0.001876,0.003374,0.085699,276.392761,14.080119,0.856991,-27.311304,0.084971,0.000000
120.730003,60.644951,-27.311304,-0.001850,0.003347,0.085023,269.762207,13.742343,0.850227,-27.311304,0.084355,0.000000
121.100006,59.838020,-27.266823,-0.001824,0.003336,0.084728,266.172821,13.559489,0.847279,-27.266823,0.083739,0.000000
121.470009,57.543083,-27.311304,-0.001815,0.003305,0.083947,255.964417,13.039450,0.839475,-27.311304,0.083123,0.000000
121.840004,55.822723,-27.311304,-0.001824,0.003283,0.083392,248.311874,12.649611,0.833922,-27.311304,0.082499,0.000000
122.210007,53.576576,-27.400267,-0.001811,0.003256,0.082707,238.320511,12.140625,0.827071,-27.400267,0.081883,0.000000
122.580009,50.968109,-27.355785,-0.001802,0.003228,0.081987,226.717468,11.549539,0.819873,-27.355785,0.081268,0.000000
122.950005,49.253700,-27.400267,-0.001815,0.003213,0.081606,219.091400,11.161048,0.816057,-27.400267,0.080652,0.000000
123.320007,46.176048,-27.400267,-0.001815,0.003183,0.080860,205.401321,10.463642,0.808601,-27.400267,0.080036,0.000000
123.690002,43.891914,-27.400267,-0.001828,0.003164,0.080357,195.240982,9.946050,0.803571,-27.400267,0.079420,0.000000
124.060005,41.214180,-27.444746,-0.001811,0.003137,0.079689,183.329834,9.339267,0.796894,-27.444746,0.078805,0.000000
124.430008,38.843285,-27.444746,-0.001815,0.003118,0.079195,172.783554,8.802014,0.791951,-27.444746,0.078189,0.000000
124.800003,35.905640,-27.444746,-0.001828,0.003090,0.078484,159.716263,8.136334,0.784840,-27.444746,0.077573,0.000000
125.170006,33.637894,-27.489227,-0.001815,0.003067,0.077894,149.628830,7.622456,0.778943,-27.489227,0.076949,0.000000
125.540009,30.849197,-27.489227,-0.001807,0.003044,0.077313,137.224091,6.990528,0.773129,-27.489227,0.076333,0.000000
125.910004,28.412392,-27.489227,-0.001798,0.003018,0.076645,126.384628,6.438340,0.766453,-27.489227,0.075717,0.000000
126.280006,25.531342,-27.489227,-0.001811,0.002996,0.076090,113.569077,5.785485,0.760904,-27.489227,0.075102,0.000000
126.650009,22.513634,-27.533709,-0.001802,0.002968,0.075379,100.145645,5.101663,0.753792,-27.533709,0.074486,0.000000
127.020004,20.492401,-27.489227,-0.001815,0.002948,0.074885,91.154755,4.643644,0.748849,-27.489227,0.073870,0.000000
127.390007,17.852280,-27.444746,-0.001807,0.002923,0.074252,79.410904,4.045384,0.742517,-27.444746,0.073254,0.000000
127.760010,15.415474,-27.578190,-0.001794,0.002903,0.073731,68.571449,3.493196,0.737313,-27.578190,0.072639,0.000000
128.130005,12.214561,-27.667152,-0.001807,0.002871,0.072916,54.333084,2.767859,0.729164,-27.667152,0.072023,0.000000
128.500000,9.257919,-27.622671,-0.001815,0.002845,0.072274,41.181282,2.097875,0.722745,-27.622671,0.071399,0.000000
128.870010,6.722809,-27.533709,-0.001798,0.002822,0.071685,29.904547,1.523410,0.716848,-27.533709,0.070783,0.000000
129.240005,4.550392,-27.622671,-0.001819,0.002800,0.071112,20.241156,1.031134,0.711125,-27.622671,0.070167,0.000000
129.610001,2.364189,-27.578190,-0.001802,0.002778,0.070566,10.516438,0.535733,0.705660,-27.578190,0.069551,0.000000
129.980011,-0.389130,-27.711632,-0.001802,0.002751,0.069863,-1.730935,-0.088178,0.698635,-27.711632,0.068936,0.000000
130.350006,-2.158646,-27.622671,-0.001802,0.002731,0.069360,-9.602136,-0.489156,0.693605,-27.622671,0.068320,0.000000
130.720001,-0.322479,-27.711632,-0.001798,0.002706,0.068745,-1.434459,-0.073075,0.687450,-27.711632,0.067704,0.000000
131.090012,-0.168686,-27.667152,-0.001811,0.002680,0.068068,-0.750352,-0.038225,0.680683,-27.667152,0.067088,0.000000
131.460007,-0.030907,-27.711632,-0.001802,0.002656,0.067461,-0.137480,-0.007004,0.674612,-27.711632,0.066464,0.000000
131.830002,0.004097,-27.756113,-0.001733,0.002639,0.067028,0.018224,0.000928,0.670278,-27.756113,0.065848,0.000000
132.200012,-0.037613,-27.711632,-0.001690,0.002608,0.066239,-0.167311,-0.008523,0.662387,-27.711632,0.065233,0.000000
132.570007,-0.065536,-27.756113,-0.001634,0.002585,0.065658,-0.291521,-0.014851,0.656577,-27.756113,0.064617,0.000000
132.940002,-0.083038,-27.756113,-0.001591,0.002560,0.065016,-0.369373,-0.018817,0.650158,-27.756113,0.064001,0.000000
133.310013,-0.097191,-27.800594,-0.001569,0.002530,0.064261,-0.432327,-0.022024,0.642615,-27.800594,0.063385,0.000000
133.680008,-0.071869,-27.756113,-0.001544,0.002513,0.063836,-0.319689,-0.016286,0.638364,-27.756113,0.062770,0.000000
134.050003,-0.099052,-27.845076,-0.001509,0.002481,0.063030,-0.440607,-0.022446,0.630299,-27.845076,0.062154,0.000000
134.420013,-0.089371,-27.756113,-0.001483,0.002465,0.062614,-0.397541,-0.020252,0.626135,-27.756113,0.061538,0.000000
134.790009,-0.122887,-27.756113,-0.001479,0.002439,0.061955,-0.546627,-0.027847,0.619546,-27.756113,0.060914,0.000000
135.160004,-0.129219,-27.845076,-0.001475,0.002410,0.061226,-0.574795,-0.029281,0.612260,-27.845076,0.060298,0.000000
135.530014,-0.113205,-27.845076,-0.001444,0.002390,0.060706,-0.503561,-0.025653,0.607056,-27.845076,0.059682,0.000000
135.900009,-0.106873,-27.934038,-0.001462,0.002363,0.060029,-0.475393,-0.024218,0.600292,-27.934038,0.059067,0.000000
136.270004,-0.114319,-27.845076,-0.001462,0.002334,0.059275,-0.508516,-0.025905,0.592749,-27.845076,0.058451,0.000000
136.639999,-0.108734,-27.845076,-0.001470,0.002312,0.058720,-0.483674,-0.024640,0.587196,-27.845076,0.057835,0.000000
137.010010,-0.135544,-27.934038,-0.001479,0.002289,0.058130,-0.602929,-0.030715,0.581299,-27.934038,0.057219,0.000000
137.380005,-0.129585,-27.889557,-0.001483,0.002266,0.057566,-0.576424,-0.029364,0.575664,-27.889557,0.056604,0.000000
137.750000,-0.133682,-27.934038,-0.001496,0.002235,0.056769,-0.594648,-0.030293,0.567685,-27.934038,0.055988,0.000000
138.120010,-0.152306,-27.978518,-0.001505,0.002210,0.056144,-0.677489,-0.034513,0.561440,-27.978518,0.055364,0.000000
138.490005,-0.163849,-27.978518,-0.001505,0.002184,0.055485,-0.728836,-0.037129,0.554850,-27.978518,0.054748,0.000000
138.860001,-0.131447,-27.978518,-0.001513,0.002165,0.054999,-0.584705,-0.029786,0.549994,-27.978518,0.054132,0.000000
139.230011,-0.142250,-27.934038,-0.001522,0.002144,0.054453,-0.632760,-0.032234,0.544529,-27.934038,0.053517,0.000000
139.600006,-0.149696,-28.067480,-0.001544,0.002117,0.053759,-0.665883,-0.033922,0.537591,-28.067480,0.052901,0.000000
139.970001,-0.191399,-28.022999,-0.001569,0.002086,0.052996,-0.851384,-0.043372,0.529961,-28.022999,0.052285,0.000000
140.340012,-0.161987,-28.022999,-0.001574,0.002068,0.052537,-0.720556,-0.036707,0.525366,-28.022999,0.051669,0.000000
140.710007,-0.158630,-28.022999,-0.001591,0.002049,0.052042,-0.705623,-0.035946,0.520423,-28.022999,0.051053,0.000000
141.080002,-0.139267,-27.978518,-0.001600,0.002020,0.051314,-0.619490,-0.031558,0.513137,-27.978518,0.050438,0.000000
141.450012,-0.170174,-28.067480,-0.001625,0.002000,0.050802,-0.756970,-0.038562,0.508020,-28.067480,0.049813,0.000000
141.820007,-0.168312,-28.111961,-0.001621,0.001976,0.050186,-0.748689,-0.038140,0.501862,-28.111961,0.049198,0.000000
142.190002,-0.145226,-28.067480,-0.001651,0.001946,0.049432,-0.645995,-0.032909,0.494319,-28.067480,0.048582,0.000000
142.560013,-0.169807,-28.111961,-0.001660,0.001927,0.048946,-0.755341,-0.038479,0.489463,-28.111961,0.047966,0.000000
142.930008,-0.182465,-28.111961,-0.001699,0.001897,0.048192,-0.811643,-0.041347,0.481916,-28.111961,0.047351,0.000000
143.300003,-0.205177,-28.111961,-0.001703,0.001882,0.047801,-0.912674,-0.046494,0.478013,-28.111961,0.046735,0.000000
143.670013,-0.188049,-28.156443,-0.001712,0.001851,0.047012,-0.836485,-0.042613,0.470122,-28.156443,0.046119,0.000000
144.040009,-0.195496,-28.111961,-0.001742,0.001824,0.046318,-0.869608,-0.044300,0.463184,-28.111961,0.045503,0.000000
144.410004,-0.197357,-28.156443,-0.001763,0.001804,0.045824,-0.877889,-0.044722,0.458241,-28.156443,0.044887,0.000000
144.780014,-0.192146,-28.111961,-0.001776,0.001778,0.045174,-0.854709,-0.043541,0.451739,-28.111961,0.044263,0.000000
145.150009,-0.213371,-28.200924,-0.001807,0.001759,0.044688,-0.949123,-0.048351,0.446879,-28.200924,0.043647,0.000000
145.520004,-0.185440,-28.200924,-0.001828,0.001731,0.043968,-0.824879,-0.042021,0.439684,-28.200924,0.043032,0.000000
145.889999,-0.192520,-28.245403,-0.001845,0.001703,0.043266,-0.856372,-0.043626,0.432659,-28.245403,0.042416,0.000000
146.260010,-0.192520,-28.200924,-0.001867,0.001681,0.042694,-0.856372,-0.043626,0.426936,-28.200924,0.041800,0.000000
146.630005,-0.192520,-28.245403,-0.001888,0.001656,0.042069,-0.856372,-0.043626,0.420691,-28.245403,0.041185,0.000000
147.000000,-0.221565,-28.200924,-0.001910,0.001634,0.041514,-0.985571,-0.050207,0.415139,-28.200924,0.040569,0.000000
147.370010,-0.189911,-28.245403,-0.001932,0.001620,0.041141,-0.844766,-0.043034,0.411411,-28.245403,0.039953,0.000000
147.740005,-0.198479,-28.289885,-0.001953,0.001590,0.040395,-0.882877,-0.044976,0.403954,-28.289885,0.039337,0.000000
148.110001,-0.177628,-28.245403,-0.001975,0.001559,0.039589,-0.790127,-0.040251,0.395889,-28.245403,0.038713,0.000000
148.480011,-0.204803,-28.334366,-0.002001,0.001538,0.039077,-0.911011,-0.046409,0.390771,-28.334366,0.038097,0.000000
148.850006,-0.204803,-28.289885,-0.002018,0.001513,0.038435,-0.911011,-0.046409,0.384352,-28.289885,0.037481,0.000000
149.220001,-0.196991,-28.334366,-0.002074,0.001484,0.037690,-0.876260,-0.044639,0.376896,-28.334366,0.036866,0.000000
149.590012,-0.196243,-28.334366,-0.002065,0.001463,0.037169,-0.872934,-0.044469,0.371692,-28.334366,0.036250,0.000000
149.960007,-0.190285,-28.334366,-0.002091,0.001435,0.036441,-0.846429,-0.043119,0.364406,-28.334366,0.035634,0.000000
150.330002,-0.179489,-28.334366,-0.002100,0.001415,0.035929,-0.798408,-0.040673,0.359293,-28.334366,0.035019,0.000000
150.700012,-0.182465,-28.334366,-0.002134,0.001390,0.035305,-0.811643,-0.041347,0.353047,-28.334366,0.034403,0.000000
151.070007,-0.197357,-28.378847,-0.002169,0.001365,0.034680,-0.877889,-0.044722,0.346802,-28.378847,0.033787,0.000000
151.440002,-0.201080,-28.423328,-0.002186,0.001342,0.034091,-0.894450,-0.045565,0.340905,-28.423328,0.033162,0.000000
151.810013,-0.210396,-28.423328,-0.002195,0.001322,0.033570,-0.935887,-0.047676,0.335701,-28.423328,0.032547,0.000000
152.180008,-0.210762,-28.378847,-0.002220,0.001296,0.032929,-0.937516,-0.047759,0.329286,-28.378847,0.031931,0.000000
152.550003,-0.187309,-28.334366,-0.002251,0.001268,0.032217,-0.833193,-0.042445,0.322174,-28.334366,0.031315,0.000000
152.920013,-0.192520,-28.467808,-0.002281,0.001248,0.031688,-0.856372,-0.043626,0.316883,-28.467808,0.030700,0.000000
153.290009,-0.161613,-28.467808,-0.002307,0.001219,0.030960,-0.718893,-0.036622,0.309597,-28.467808,0.030084,0.000000
153.660004,-0.189911,-28.423328,-0.002320,0.001193,0.030309,-0.844766,-0.043034,0.303094,-28.423328,0.029468,0.000000
154.030014,-0.183578,-28.467808,-0.002333,0.001181,0.029997,-0.816598,-0.041599,0.299972,-28.467808,0.028853,0.000000
154.400009,-0.176132,-28.467808,-0.002371,0.001152,0.029260,-0.783475,-0.039912,0.292603,-28.467808,0.029095,0.000000