File: Data/compression 25/AutoNoHeating-17-25-reverse-1-5_09232024_185351.csv
Time (sec),S:Load (lbs),S:HL1 (DIM),S:LVDT (in),S:Position (in),Ch:Position (mm),Ch:Load (N),Ch:Stress (MPa),Ch:Strain (mm/mm),Ch:HL1 (DIM),Set Point (),Cycles ()
0.010000,0.033142,-51.197575,-0.008019,-0.007925,-0.201292,0.147423,0.007510,-2.012918,-51.197575,-0.201075,0.000000
0.360000,0.034256,-51.197575,-0.008019,-0.007924,-0.201274,0.152378,0.007763,-2.012744,-51.197575,-0.200832,0.000000
0.710000,0.055855,-51.242054,-0.008032,-0.007729,-0.196314,0.248455,0.012657,-1.963139,-51.242054,-0.195004,0.000000
1.060000,0.033142,-51.331017,-0.007795,-0.007502,-0.190555,0.147423,0.007510,-1.905555,-51.331017,-0.189159,0.000000
1.410000,-0.003349,-51.331017,-0.007545,-0.007270,-0.184658,-0.014898,-0.000759,-1.846584,-51.331017,-0.183331,0.000000
1.760000,0.055855,-51.331017,-0.007321,-0.007044,-0.178909,0.248455,0.012657,-1.789087,-51.331017,-0.177504,0.000000
2.110000,0.081924,-51.331017,-0.007075,-0.006814,-0.173064,0.364418,0.018564,-1.730636,-51.331017,-0.171676,0.000000
2.460000,0.073730,-51.331017,-0.006842,-0.006578,-0.167080,0.327969,0.016708,-1.670797,-51.331017,-0.165848,0.000000
2.810000,0.050644,-51.331017,-0.006605,-0.006358,-0.161486,0.225275,0.011476,-1.614861,-51.331017,-0.160020,0.000000
3.160000,0.013405,-51.331017,-0.006364,-0.006121,-0.155485,0.059628,0.003038,-1.554849,-51.331017,-0.154175,0.000000
3.510000,0.022339,-51.375500,-0.006118,-0.005888,-0.149544,0.099368,0.005062,-1.495444,-51.375500,-0.148348,0.000000
3.860000,0.067772,-51.375500,-0.005894,-0.005664,-0.143873,0.301465,0.015357,-1.438727,-51.375500,-0.142520,0.000000
4.210000,0.087135,-51.331017,-0.005644,-0.005431,-0.137950,0.387597,0.019745,-1.379496,-51.331017,-0.136692,0.000000
4.560000,0.070381,-51.375500,-0.005407,-0.005203,-0.132148,0.313071,0.015949,-1.321478,-51.375500,-0.130864,0.000000
4.910000,0.052879,-51.419979,-0.005182,-0.004979,-0.126468,0.235219,0.011983,-1.264675,-51.419979,-0.125019,0.000000
5.260000,0.019737,-51.419979,-0.004937,-0.004742,-0.120458,0.087796,0.004473,-1.204576,-51.419979,-0.119191,0.000000
5.610000,0.114693,-51.419979,-0.004743,0.000013,0.000321,0.510179,0.025990,0.003209,-51.419979,0.000538,0.000000
5.960001,0.093468,-51.464462,-0.004730,0.000013,0.000321,0.415765,0.021180,0.003209,-51.464462,0.000538,0.000000
6.310000,0.132195,-51.419979,-0.004738,0.000013,0.000321,0.588031,0.029956,0.003209,-51.419979,0.000945,0.000000
6.660000,0.122513,-51.508942,-0.004730,0.000023,0.000581,0.544964,0.027762,0.005810,-51.508942,0.001535,0.000000
7.010000,0.143738,-51.464462,-0.004721,0.000041,0.001049,0.639378,0.032571,0.010493,-51.464462,0.002116,0.000000
7.360000,0.226028,-51.419979,-0.004712,0.000066,0.001674,1.005425,0.051219,0.016737,-51.419979,0.002697,0.000000
7.710001,0.361572,-51.464462,-0.004678,0.000092,0.002333,1.608354,0.081933,0.023328,-51.464462,0.003287,0.000000
8.060000,0.484085,-51.508942,-0.004656,0.000108,0.002740,2.153318,0.109695,0.027404,-51.508942,0.003868,0.000000
8.410001,0.647552,-51.553421,-0.004661,0.000125,0.003165,2.880457,0.146737,0.031654,-51.553421,0.004449,0.000000
8.760000,1.148766,-51.553421,-0.004613,0.000158,0.004015,5.109964,0.260314,0.040153,-51.553421,0.005030,0.000000
9.110001,1.400116,-51.553421,-0.004609,0.000175,0.004458,6.228027,0.317271,0.044575,-51.553421,0.005620,0.000000
9.460000,1.764671,-51.553421,-0.004579,0.000201,0.005108,7.849650,0.399880,0.051080,-51.553421,0.006201,0.000000
9.810000,2.234978,-51.508942,-0.004583,0.000228,0.005784,9.941677,0.506453,0.057844,-51.508942,0.006782,0.000000
10.160001,2.581284,-51.508942,-0.004544,0.000245,0.006218,11.482122,0.584927,0.062180,-51.508942,0.007363,0.000000
10.510000,3.112663,-51.642384,-0.004527,0.000271,0.006886,13.845818,0.705340,0.068858,-51.642384,0.007952,0.000000
10.860001,3.642921,-51.553421,-0.004506,0.000293,0.007441,16.204523,0.825498,0.074408,-51.553421,0.008533,0.000000
11.210001,4.052528,-51.553421,-0.004501,0.000314,0.007987,18.026546,0.918316,0.079871,-51.553421,0.009115,0.000000
11.560000,4.618904,-51.597904,-0.004488,0.000334,0.008473,20.545912,1.046659,0.084728,-51.597904,0.009704,0.000000
11.910001,5.159218,-51.597904,-0.004449,0.000357,0.009071,22.949347,1.169095,0.090712,-51.597904,0.010285,0.000000
12.260000,5.800819,-51.642384,-0.004441,0.000381,0.009670,25.803333,1.314484,0.096696,-51.642384,0.010866,0.000000
12.610001,6.667702,-51.597904,-0.004419,0.000411,0.010450,29.659418,1.510923,0.104501,-51.597904,0.011447,0.000000
12.960001,7.025551,-51.597904,-0.004381,0.000432,0.010970,31.251211,1.592013,0.109704,-51.597904,0.012037,0.000000
13.310000,7.423241,-51.686867,-0.004359,0.000448,0.011378,33.020222,1.682130,0.113780,-51.686867,0.012618,0.000000
13.660001,8.254753,-51.686867,-0.004359,0.000480,0.012185,36.718975,1.870554,0.121845,-51.686867,0.013199,0.000000
14.010000,8.712769,-51.731346,-0.004333,0.000501,0.012722,38.756329,1.974342,0.127222,-51.731346,0.013780,0.000000
14.360001,9.129456,-51.731346,-0.004324,0.000517,0.013138,40.609848,2.068764,0.131385,-51.731346,0.014370,0.000000
14.710001,9.954636,-51.731346,-0.004294,0.000547,0.013884,44.280430,2.255753,0.138843,-51.731346,0.014951,0.000000
15.060000,10.287903,-51.686867,-0.004268,0.000566,0.014379,45.762878,2.331272,0.143786,-51.686867,0.015532,0.000000
15.410001,10.904556,-51.731346,-0.004251,0.000589,0.014951,48.505890,2.471008,0.149510,-51.731346,0.016113,0.000000
15.760001,11.412102,-51.686867,-0.004230,0.000613,0.015558,50.763565,2.586019,0.155580,-51.686867,0.016703,0.000000
16.110001,11.934166,-51.731346,-0.004212,0.000634,0.016113,53.085823,2.704321,0.161131,-51.731346,0.017284,0.000000
16.460001,12.420853,-51.775826,-0.004191,0.000658,0.016711,55.250713,2.814605,0.167114,-51.775826,0.017865,0.000000
16.810001,13.018517,-51.731346,-0.004182,0.000682,0.017327,57.909252,2.950038,0.173272,-51.731346,0.018455,0.000000
17.160002,13.455681,-51.820309,-0.004152,0.000704,0.017874,59.853859,3.049101,0.178735,-51.820309,0.019036,0.000000
17.510000,13.904762,-51.775826,-0.004143,0.000727,0.018463,61.851471,3.150864,0.184632,-51.775826,0.019617,0.000000
17.860001,14.086479,-51.775826,-0.004118,0.000744,0.018897,62.659790,3.192042,0.188968,-51.775826,0.020198,0.000000
18.210001,14.983521,-51.731346,-0.004083,0.000775,0.019677,66.650024,3.395314,0.196773,-51.731346,0.020787,0.000000
18.560001,15.491814,-51.820309,-0.004070,0.000799,0.020284,68.911026,3.510495,0.202844,-51.820309,0.021368,0.000000
18.910002,15.393875,-51.820309,-0.004044,0.000811,0.020588,68.475380,3.488302,0.205879,-51.820309,0.021949,0.000000
19.260000,16.467796,-51.820309,-0.004027,0.000846,0.021499,73.252419,3.731656,0.214985,-51.820309,0.022531,0.000000
19.610001,16.651375,-51.864788,-0.004010,0.000866,0.022002,74.069016,3.773255,0.220015,-51.864788,0.023120,0.000000
19.960001,16.735909,-51.775826,-0.003975,0.000881,0.022374,74.445038,3.792411,0.223744,-51.775826,0.023701,0.000000
20.310001,17.747643,-51.820309,-0.003967,0.000912,0.023155,78.945457,4.021673,0.231549,-51.820309,0.024282,0.000000
20.660002,18.076073,-51.820309,-0.003915,0.000936,0.023771,80.406387,4.096097,0.237707,-51.820309,0.024872,0.000000
21.010000,18.184807,-51.820309,-0.003915,0.000952,0.024187,80.890060,4.120736,0.241869,-51.820309,0.025453,0.000000
21.360001,18.969025,-51.820309,-0.003885,0.000982,0.024933,84.378433,4.298442,0.249327,-51.820309,0.026034,0.000000
21.710001,18.912796,-51.820309,-0.003867,0.000998,0.025358,84.128319,4.285701,0.253577,-51.820309,0.026615,0.000000
22.060001,19.389809,-51.909271,-0.003837,0.001024,0.026008,86.250175,4.393794,0.260081,-51.909271,0.027205,0.000000
22.410002,20.247749,-51.909271,-0.003820,0.001052,0.026728,90.066490,4.588206,0.267279,-51.909271,0.027786,0.000000
22.760000,20.433563,-51.953751,-0.003777,0.001072,0.027240,90.893028,4.630312,0.272396,-51.953751,0.028367,0.000000
23.110001,20.685287,-51.953751,-0.003773,0.001096,0.027847,92.012756,4.687353,0.278466,-51.953751,0.028948,0.000000
23.460001,20.766838,-51.953751,-0.003747,0.001115,0.028324,92.375511,4.705833,0.283236,-51.953751,0.029538,0.000000
23.810001,20.883018,-51.953751,-0.003725,0.001136,0.028853,92.892303,4.732160,0.288526,-51.953751,0.030119,0.000000
24.160002,21.969604,-51.998230,-0.003699,0.001166,0.029616,97.725685,4.978384,0.296158,-51.998230,0.030700,0.000000
24.510000,22.238457,-51.998230,-0.003686,0.001191,0.030249,98.921593,5.039307,0.302488,-51.998230,0.031281,0.000000
24.860001,22.149834,-51.998230,-0.003652,0.001206,0.030639,98.527382,5.019224,0.306391,-51.998230,0.031871,0.000000
25.210001,22.344208,-51.953751,-0.003630,0.001230,0.031246,99.391998,5.063270,0.312461,-51.953751,0.032452,0.000000
25.560001,22.920639,-52.042713,-0.003600,0.001257,0.031931,101.956093,5.193891,0.319312,-52.042713,0.033033,0.000000
25.910002,23.084488,-51.998230,-0.003583,0.001275,0.032374,102.684929,5.231020,0.323735,-51.998230,0.033622,0.000000
26.260002,23.894394,-52.087193,-0.003544,0.001306,0.033171,106.287575,5.414547,0.331714,-52.087193,0.034203,0.000000
26.610001,24.108513,-52.087193,-0.003527,0.001328,0.033726,107.240021,5.463067,0.337264,-52.087193,0.034784,0.000000
26.960001,23.896629,-52.087193,-0.003497,0.001344,0.034134,106.297516,5.415054,0.341340,-52.087193,0.035365,0.000000
27.310001,24.277191,-52.087193,-0.003484,0.001369,0.034767,107.990341,5.501290,0.347671,-52.087193,0.035955,0.000000
27.660002,24.106651,-51.998230,-0.003462,0.001382,0.035105,107.231743,5.462645,0.351053,-51.998230,0.036536,0.000000
28.010002,25.403252,-52.042713,-0.003436,0.001419,0.036042,112.999306,5.756459,0.360419,-52.042713,0.037117,0.000000
28.360001,25.571564,-52.087193,-0.003419,0.001444,0.036684,113.747993,5.794599,0.366836,-52.087193,0.037698,0.000000
28.710001,25.766312,-52.042713,-0.003380,0.001464,0.037195,114.614281,5.838730,0.371953,-52.042713,0.038288,0.000000
29.060001,26.247047,-52.176155,-0.003346,0.001491,0.037880,116.752701,5.947666,0.378804,-52.176155,0.038869,0.000000
29.410002,25.997559,-52.087193,-0.003311,0.001510,0.038357,115.642914,5.891131,0.383574,-52.087193,0.039450,0.000000
29.760002,26.763153,-52.131676,-0.003294,0.001536,0.039008,119.048454,6.064618,0.390078,-52.131676,0.040040,0.000000
30.110001,27.079300,-52.087193,-0.003272,0.001559,0.039606,120.454742,6.136257,0.396062,-52.087193,0.040621,0.000000
30.460001,26.983971,-52.131676,-0.003242,0.001580,0.040144,120.030693,6.114655,0.401439,-52.131676,0.041202,0.000000
30.810001,27.235321,-52.176155,-0.003216,0.001597,0.040569,121.148758,6.171612,0.405688,-52.176155,0.041783,0.000000
31.160002,28.012833,-52.220638,-0.003203,0.001628,0.041349,124.607300,6.347798,0.413493,-52.220638,0.042373,0.000000
31.510002,27.882133,-52.176155,-0.003173,0.001647,0.041835,124.025925,6.318182,0.418350,-52.176155,0.042954,0.000000
31.860001,28.392654,-52.176155,-0.003156,0.001672,0.042477,126.296837,6.433867,0.424767,-52.176155,0.043535,0.000000
32.210003,28.513306,-52.220638,-0.003113,0.001692,0.042980,126.833519,6.461207,0.429797,-52.220638,0.044116,0.000000
32.560001,28.943764,-52.176155,-0.003100,0.001716,0.043587,128.748291,6.558751,0.435868,-52.176155,0.044705,0.000000
32.910000,28.919189,-52.265118,-0.003078,0.001735,0.044081,128.638977,6.553182,0.440811,-52.265118,0.045287,0.000000
33.260002,29.226021,-52.265118,-0.003061,0.001756,0.044593,130.003830,6.622711,0.445927,-52.265118,0.045868,0.000000
33.610001,29.742874,-52.220638,-0.003040,0.001780,0.045208,132.302917,6.739831,0.452085,-52.220638,0.046449,0.000000
33.960003,30.937820,-52.265118,-0.003005,0.001813,0.046041,137.618301,7.010610,0.460410,-52.265118,0.047038,0.000000
34.310001,30.769882,-52.309597,-0.002988,0.001831,0.046518,136.871277,6.972555,0.465180,-52.309597,0.047619,0.000000
34.660000,30.477570,-52.265118,-0.002958,0.001847,0.046926,135.570999,6.906316,0.469256,-52.265118,0.048200,0.000000
35.010002,31.468079,-52.220638,-0.002923,0.001879,0.047715,139.977005,7.130768,0.477148,-52.220638,0.048790,0.000000
35.360001,31.447601,-52.309597,-0.002910,0.001897,0.048192,139.885910,7.126129,0.481917,-52.309597,0.049371,0.000000
35.710003,32.097389,-52.265118,-0.002884,0.001926,0.048912,142.776321,7.273372,0.489115,-52.265118,0.049952,0.000000
36.060001,32.379272,-52.309597,-0.002854,0.001945,0.049406,144.030197,7.337248,0.494058,-52.309597,0.050533,0.000000
36.410000,32.444809,-52.354080,-0.002833,0.001966,0.049935,144.321716,7.352099,0.499349,-52.354080,0.051123,0.000000
36.760002,32.760582,-52.309597,-0.002798,0.001990,0.050542,145.726349,7.423654,0.505419,-52.309597,0.051704,0.000000
37.110001,33.095345,-52.354080,-0.002781,0.002012,0.051106,147.215439,7.499512,0.511056,-52.354080,0.052285,0.000000
37.460003,33.399574,-52.354080,-0.002772,0.002033,0.051635,148.568726,7.568452,0.516346,-52.354080,0.052866,0.000000
37.810001,33.955528,-52.398560,-0.002742,0.002062,0.052363,151.041733,7.694433,0.523631,-52.398560,0.053456,0.000000
38.160004,34.343536,-52.354080,-0.002721,0.002082,0.052875,152.767685,7.782357,0.528747,-52.354080,0.054037,0.000000
38.510002,34.745331,-52.398560,-0.002686,0.002106,0.053499,154.554947,7.873405,0.534991,-52.398560,0.054618,0.000000
38.860001,35.048439,-52.398560,-0.002656,0.002128,0.054063,155.903244,7.942090,0.540628,-52.398560,0.055199,0.000000
39.210003,34.826508,-52.443043,-0.002639,0.002143,0.054427,154.916046,7.891799,0.544271,-52.443043,0.055789,0.000000
39.560001,35.849411,-52.398560,-0.002600,0.002174,0.055216,159.466141,8.123592,0.552163,-52.398560,0.056370,0.000000
39.910004,36.645172,-52.398560,-0.002587,0.002199,0.055858,163.005859,8.303915,0.558580,-52.398560,0.056951,0.000000
40.260002,35.895584,-52.443043,-0.002574,0.002209,0.056118,159.671539,8.134055,0.561182,-52.443043,0.057540,0.000000
40.610001,37.556000,-52.398560,-0.002535,0.002246,0.057055,167.057434,8.510311,0.570548,-52.398560,0.058121,0.000000
40.960003,37.519501,-52.487522,-0.002518,0.002265,0.057523,166.895081,8.502041,0.575231,-52.487522,0.058703,0.000000
41.310001,37.191071,-52.487522,-0.002483,0.002279,0.057896,165.434143,8.427617,0.578960,-52.487522,0.059284,0.000000
41.660004,38.598640,-52.487522,-0.002458,0.002313,0.058746,171.695328,8.746576,0.587459,-52.487522,0.059873,0.000000
42.010002,39.025009,-52.487522,-0.002423,0.002336,0.059336,173.591904,8.843193,0.593356,-52.487522,0.060454,0.000000
42.360001,38.966919,-52.487522,-0.002410,0.002352,0.059743,173.333511,8.830029,0.597432,-52.487522,0.061035,0.000000
42.710003,40.081055,-52.532001,-0.002371,0.002384,0.060558,178.289429,9.082497,0.605584,-52.532001,0.061616,0.000000
43.060001,39.683731,-52.532001,-0.002358,0.002400,0.060949,176.522049,8.992462,0.609486,-52.532001,0.062206,0.000000
43.410004,40.395340,-52.532001,-0.002341,0.002422,0.061521,179.687439,9.153715,0.615210,-52.532001,0.062787,0.000000
43.760002,41.429039,-52.532001,-0.002307,0.002451,0.062267,184.285568,9.387955,0.622668,-52.532001,0.063368,0.000000
44.110001,41.756729,-52.532001,-0.002281,0.002471,0.062770,185.743210,9.462210,0.627698,-52.532001,0.063958,0.000000
44.460003,42.433334,-52.532001,-0.002251,0.002500,0.063507,188.752899,9.615531,0.635069,-52.532001,0.064539,0.000000
44.810001,42.497009,-52.576485,-0.002216,0.002519,0.063975,189.036133,9.629959,0.639752,-52.576485,0.065120,0.000000
45.160004,42.622498,-52.620964,-0.002216,0.002539,0.064496,189.594345,9.658396,0.644956,-52.620964,0.065701,0.000000
45.510002,43.846855,-52.576485,-0.002195,0.002565,0.065146,195.040558,9.935840,0.651460,-52.576485,0.066291,0.000000
45.860001,44.332802,-52.620964,-0.002164,0.002588,0.065736,197.202148,10.045956,0.657357,-52.620964,0.066872,0.000000
46.210003,44.838112,-52.620964,-0.002151,0.002612,0.066334,199.449890,10.160461,0.663341,-52.620964,0.067453,0.000000
46.560001,45.260010,-52.576485,-0.002126,0.002635,0.066924,201.326584,10.256065,0.669238,-52.576485,0.068034,0.000000
46.910004,45.854691,-52.620964,-0.002091,0.002658,0.067505,203.971848,10.390821,0.675048,-52.620964,0.068624,0.000000
47.260002,45.718399,-52.620964,-0.002065,0.002673,0.067904,203.365601,10.359938,0.679038,-52.620964,0.069205,0.000000
47.610001,46.781898,-52.620964,-0.002031,0.002700,0.068580,208.096283,10.600929,0.685802,-52.620964,0.069786,0.000000
47.960003,47.486427,-52.620964,-0.002026,0.002726,0.069248,211.230179,10.760578,0.692480,-52.620964,0.070367,0.000000
48.310001,47.691231,-52.665447,-0.002005,0.002748,0.069803,212.141190,10.806988,0.698030,-52.665447,0.070956,0.000000
48.660004,48.322403,-52.665447,-0.001975,0.002770,0.070367,214.948776,10.950013,0.703667,-52.665447,0.071537,0.000000
49.010002,48.273247,-52.665447,-0.001944,0.002790,0.070870,214.730133,10.938874,0.708697,-52.665447,0.072118,0.000000
49.360001,49.673370,-52.665447,-0.001927,0.002817,0.071563,220.958191,11.256146,0.715635,-52.665447,0.072708,0.000000
49.710003,50.287407,-52.709927,-0.001893,0.002844,0.072249,223.689560,11.395289,0.722486,-52.709927,0.073289,0.000000
50.060001,50.718620,-52.709927,-0.001867,0.002866,0.072795,225.607697,11.493003,0.727949,-52.709927,0.073870,0.000000
50.410004,51.409744,-52.709927,-0.001845,0.002891,0.073428,228.681961,11.649615,0.734280,-52.709927,0.074451,0.000000
50.760002,50.841499,-52.709927,-0.001815,0.002908,0.073862,226.154282,11.520848,0.738616,-52.709927,0.075041,0.000000
51.110001,52.256142,-52.709927,-0.001807,0.002935,0.074538,232.446930,11.841411,0.745380,-52.709927,0.075622,0.000000
51.460003,52.812096,-52.798889,-0.001785,0.002958,0.075145,234.919937,11.967392,0.751451,-52.798889,0.076203,0.000000
51.810001,52.733528,-52.754410,-0.001742,0.002980,0.075683,234.570450,11.949589,0.756828,-52.754410,0.076784,0.000000
52.160004,53.101059,-52.754410,-0.001725,0.002996,0.076108,236.205307,12.032872,0.761077,-52.754410,0.077374,0.000000
52.510002,54.392075,-52.798889,-0.001699,0.003027,0.076897,241.948029,12.325420,0.768969,-52.798889,0.077955,0.000000
52.860001,54.323555,-52.798889,-0.001669,0.003048,0.077409,241.643234,12.309894,0.774086,-52.798889,0.078536,0.000000
53.210003,55.005745,-52.798889,-0.001660,0.003071,0.078007,244.677780,12.464479,0.780069,-52.798889,0.079126,0.000000
53.560001,55.323006,-52.754410,-0.001634,0.003092,0.078527,246.089020,12.536372,0.785273,-52.754410,0.079707,0.000000
53.910004,55.749001,-52.843369,-0.001608,0.003115,0.079117,247.983932,12.632904,0.791170,-52.843369,0.080288,0.000000
54.260002,55.895714,-52.843369,-0.001574,0.003133,0.079585,248.636551,12.666150,0.795853,-52.843369,0.080869,0.000000
54.610004,56.341812,-52.887852,-0.001561,0.003157,0.080192,250.620895,12.767238,0.801924,-52.887852,0.081459,0.000000
54.960003,56.828880,-52.887852,-0.001526,0.003178,0.080721,252.787491,12.877608,0.807214,-52.887852,0.082040,0.000000
55.310001,58.319855,-52.887852,-0.001522,0.003211,0.081563,259.419678,13.215467,0.815626,-52.887852,0.082621,0.000000
55.660004,58.594299,-52.887852,-0.001487,0.003230,0.082040,260.640472,13.277658,0.820395,-52.887852,0.083202,0.000000
56.010002,58.349274,-52.887852,-0.001475,0.003246,0.082438,259.550537,13.222134,0.824385,-52.887852,0.083791,0.000000
56.360004,59.690186,-52.932331,-0.001444,0.003277,0.083245,265.515198,13.525990,0.832450,-52.932331,0.084372,0.000000
56.710003,60.004845,-52.887852,-0.001436,0.003299,0.083783,266.914886,13.597292,0.837827,-52.887852,0.084953,0.000000
57.060001,60.312050,-52.932331,-0.001384,0.003323,0.084398,268.281403,13.666905,0.843984,-52.932331,0.085534,0.000000
57.410004,61.258621,-52.976814,-0.001380,0.003344,0.084927,272.491943,13.881402,0.849274,-52.976814,0.086124,0.000000
57.760002,61.463425,-53.021294,-0.001354,0.003364,0.085456,273.402954,13.927811,0.854564,-53.021294,0.086705,0.000000
58.110004,62.061455,-52.976814,-0.001332,0.003386,0.086011,276.063141,14.063327,0.860114,-52.976814,0.087286,0.000000
58.460003,62.719063,-53.021294,-0.001315,0.003409,0.086592,278.988312,14.212343,0.865925,-53.021294,0.087876,0.000000
58.810001,63.312256,-52.976814,-0.001285,0.003433,0.087208,281.626984,14.346763,0.872082,-52.976814,0.088457,0.000000
59.160004,64.425278,-52.976814,-0.001259,0.003462,0.087945,286.577942,14.598977,0.879454,-52.976814,0.089038,0.000000
59.510002,64.925751,-53.021294,-0.001250,0.003479,0.088370,288.804169,14.712385,0.883703,-53.021294,0.089619,0.000000
59.860004,65.505524,-52.932331,-0.001233,0.003503,0.088986,291.383118,14.843763,0.889860,-52.932331,0.090209,0.000000
60.210003,65.329025,-53.065773,-0.001199,0.003508,0.089099,290.598022,14.803769,0.890988,-53.065773,0.015643,0.000000
60.560001,65.829498,-52.976814,-0.001181,0.003510,0.089151,292.824219,14.917178,0.891508,-52.976814,294.500458,0.000000
60.910004,64.874725,-52.976814,-0.001168,0.003537,0.089827,288.577179,14.700823,0.898272,-52.976814,294.500458,0.000000
61.260002,65.165558,-53.065773,-0.001164,0.003553,0.090252,289.870880,14.766726,0.902522,-53.065773,294.500458,0.000000
61.610004,65.518555,-53.065773,-0.001134,0.003568,0.090634,291.441101,14.846717,0.906337,-53.065773,294.500458,0.000000
61.960003,65.855927,-53.065773,-0.001143,0.003576,0.090833,292.941803,14.923166,0.908332,-53.065773,294.500458,0.000000
62.310001,64.587265,-53.065773,-0.001130,0.003585,0.091059,287.298492,14.635684,0.910587,-53.065773,294.500458,0.000000
62.660004,65.399399,-53.110256,-0.001108,0.003588,0.091137,290.911041,14.819715,0.911367,-53.110256,294.500458,0.000000
63.010002,64.981979,-53.065773,-0.001091,0.003605,0.091579,289.054291,14.725127,0.915790,-53.065773,294.500458,0.000000
63.360004,65.761353,-53.065773,-0.001082,0.003624,0.092039,292.521118,14.901735,0.920387,-53.065773,294.500458,0.000000
63.710003,64.967453,-53.154736,-0.001082,0.003624,0.092056,288.989655,14.721835,0.920560,-53.154736,294.500458,0.000000
64.060005,64.916809,-53.110256,-0.001069,0.003632,0.092264,288.764374,14.710359,0.922641,-53.110256,294.500458,0.000000
64.410004,65.091080,-53.154736,-0.001065,0.003642,0.092516,289.539581,14.749849,0.925156,-53.154736,294.500458,0.000000
64.760002,65.054962,-53.199219,-0.001074,0.003650,0.092706,289.378937,14.741665,0.927064,-53.199219,294.500458,0.000000
65.110001,65.185287,-53.154736,-0.001056,0.003658,0.092906,289.958649,14.771197,0.929059,-53.154736,294.500458,0.000000
65.460007,64.926117,-53.199219,-0.001039,0.003663,0.093036,288.805786,14.712468,0.930360,-53.199219,294.500458,0.000000
65.810005,65.184921,-53.199219,-0.001052,0.003671,0.093244,289.957001,14.771114,0.932441,-53.199219,294.500458,0.000000
66.160004,64.652054,-53.243698,-0.001035,0.003671,0.093253,287.586700,14.650364,0.932528,-53.243698,294.500458,0.000000
66.510002,65.051605,-53.243698,-0.001022,0.003681,0.093504,289.363983,14.740905,0.935043,-53.243698,294.500458,0.000000
66.860001,65.081772,-53.243698,-0.001026,0.003694,0.093834,289.498169,14.747741,0.938338,-53.243698,294.500458,0.000000
67.210007,65.250458,-53.288177,-0.001013,0.003693,0.093799,290.248535,14.785965,0.937991,-53.288177,294.500458,0.000000
67.560005,64.775299,-53.199219,-0.001009,0.003693,0.093808,288.134918,14.678292,0.938078,-53.199219,294.500458,0.000000
67.910004,66.295334,-53.243698,-0.001009,0.003683,0.093548,294.896362,15.022738,0.935476,-53.243698,294.500458,0.000000
68.260002,65.749054,-53.243698,-0.000987,0.003683,0.093548,292.466400,14.898949,0.935476,-53.243698,294.500458,0.000000
68.610001,65.230713,-53.243698,-0.000992,0.003683,0.093556,290.160706,14.781491,0.935563,-53.243698,294.500458,0.000000
68.960007,65.378174,-53.243698,-0.000996,0.003714,0.094345,290.816650,14.814906,0.943455,-53.243698,294.500458,0.000000
69.310005,65.095917,-53.288177,-0.000987,0.003715,0.094363,289.561096,14.750946,0.943628,-53.288177,294.500458,0.000000
69.660004,64.946976,-53.332661,-0.000974,0.003718,0.094432,288.898590,14.717196,0.944322,-53.332661,294.500458,0.000000
70.010002,65.566971,-53.377140,-0.000974,0.003729,0.094710,291.656464,14.857688,0.947097,-53.377140,294.500458,0.000000
70.360001,65.272797,-53.288177,-0.000983,0.003729,0.094710,290.347900,14.791027,0.947097,-53.288177,294.500458,0.000000
70.710007,64.991287,-53.288177,-0.000974,0.003730,0.094744,289.095673,14.727236,0.947444,-53.288177,294.500458,0.000000
71.060005,65.446320,-53.332661,-0.000970,0.003739,0.094961,291.119781,14.830348,0.949612,-53.332661,294.500458,0.000000
71.410004,65.200928,-53.377140,-0.000970,0.003739,0.094961,290.028198,14.774741,0.949612,-53.377140,294.500458,0.000000
71.760002,64.930206,-53.332661,-0.000966,0.003739,0.094970,288.823975,14.713395,0.949699,-53.332661,294.500458,0.000000
72.110001,64.939896,-53.377140,-0.000974,0.003743,0.095074,288.867096,14.715591,0.950740,-53.377140,294.500458,0.000000
72.460007,65.076553,-53.421623,-0.000957,0.003748,0.095187,289.474976,14.746557,0.951867,-53.421623,294.500458,0.000000
72.810005,64.905640,-53.377140,-0.000961,0.003748,0.095187,288.714691,14.707828,0.951867,-53.377140,294.500458,0.000000
73.160004,64.840103,-53.421623,-0.000961,0.003750,0.095256,288.423187,14.692978,0.952561,-53.421623,294.500458,0.000000
73.510002,65.670120,-53.421623,-0.000961,0.003762,0.095551,292.115295,14.881063,0.955509,-53.421623,294.500458,0.000000
73.860001,65.565857,-53.421623,-0.000944,0.003762,0.095551,291.651489,14.857435,0.955509,-53.421623,294.500458,0.000000
74.210007,65.353226,-53.466103,-0.000953,0.003762,0.095551,290.705658,14.809253,0.955509,-53.466103,294.500458,0.000000
74.560005,65.138000,-53.466103,-0.000949,0.003762,0.095560,289.748291,14.760482,0.955596,-53.466103,294.500458,0.000000
74.910004,64.981232,-53.466103,-0.000936,0.003763,0.095586,289.050964,14.724958,0.955856,-53.466103,294.500458,0.000000
75.260002,65.722244,-53.466103,-0.000927,0.003773,0.095846,292.347137,14.892874,0.958458,-53.466103,294.500458,0.000000
75.610001,65.586700,-53.466103,-0.000940,0.003773,0.095846,291.744202,14.862159,0.958458,-53.466103,294.500458,0.000000
75.960007,65.395309,-53.510586,-0.000931,0.003773,0.095846,290.892853,14.818789,0.958458,-53.510586,294.500458,0.000000
76.310005,65.243011,-53.466103,-0.000936,0.003773,0.095846,290.215424,14.784278,0.958458,-53.466103,294.500458,0.000000
76.660004,65.039322,-53.510586,-0.000940,0.003773,0.095846,289.309357,14.738121,0.958458,-53.510586,294.500458,0.000000
77.010002,64.836746,-53.466103,-0.000923,0.003774,0.095854,288.408264,14.692217,0.958544,-53.466103,294.500458,0.000000
77.360001,65.645920,-53.555065,-0.000936,0.003784,0.096123,292.007629,14.875578,0.961233,-53.555065,294.500458,0.000000
77.710007,65.546112,-53.510586,-0.000936,0.003784,0.096123,291.563660,14.852961,0.961233,-53.510586,294.500458,0.000000
78.060005,65.363647,-53.555065,-0.000940,0.003784,0.096123,290.752014,14.811614,0.961233,-53.555065,294.500458,0.000000
78.410004,65.237045,-53.555065,-0.000927,0.003784,0.096123,290.188873,14.782926,0.961233,-53.555065,294.500458,0.000000
78.760002,65.049377,-53.555065,-0.000927,0.003785,0.096132,289.354095,14.740399,0.961320,-53.555065,294.500458,0.000000
79.110001,64.960373,-53.599545,-0.000940,0.003786,0.096167,288.958160,14.720231,0.961667,-53.599545,294.500458,0.000000
79.460007,64.882172,-53.644028,-0.000931,0.003787,0.096201,288.610321,14.702510,0.962013,-53.644028,294.500458,0.000000
79.810005,65.032608,-53.555065,-0.000923,0.003791,0.096297,289.279480,14.736600,0.962967,-53.555065,294.500458,0.000000
80.160004,65.003204,-53.555065,-0.000910,0.003791,0.096297,289.148682,14.729937,0.962967,-53.555065,294.500458,0.000000
80.510002,64.905640,-53.599545,-0.000914,0.003791,0.096297,288.714691,14.707828,0.962967,-53.599545,294.500458,0.000000
80.860001,64.820358,-53.599545,-0.000914,0.003793,0.096331,288.335358,14.688503,0.963314,-53.599545,294.500458,0.000000
81.210007,64.815521,-53.599545,-0.000923,0.003795,0.096392,288.313843,14.687407,0.963921,-53.599545,294.500458,0.000000
81.560005,65.116394,-53.599545,-0.000918,0.003800,0.096531,289.652191,14.755586,0.965309,-53.599545,294.500458,0.000000
81.910004,65.218430,-53.688507,-0.000914,0.003800,0.096531,290.106049,14.778708,0.965309,-53.688507,294.500458,0.000000
82.260002,65.094437,-53.688507,-0.000910,0.003800,0.096531,289.554504,14.750610,0.965309,-53.688507,294.500458,0.000000
82.610001,65.014740,-53.644028,-0.000914,0.003800,0.096531,289.200012,14.732551,0.965309,-53.644028,294.500458,0.000000
82.960007,64.908615,-53.688507,-0.000914,0.003800,0.096531,288.727936,14.708503,0.965309,-53.688507,294.500458,0.000000
83.310005,64.984207,-53.688507,-0.000905,0.003804,0.096618,289.064178,14.725632,0.966176,-53.688507,294.500458,0.000000
83.660004,64.960754,-53.732990,-0.000905,0.003804,0.096618,288.959869,14.720317,0.966176,-53.732990,294.500458,0.000000
84.010002,64.854996,-53.688507,-0.000910,0.003804,0.096618,288.489441,14.696352,0.966176,-53.688507,294.500458,0.000000
84.360001,65.051971,-53.688507,-0.000905,0.003808,0.096713,289.365631,14.740987,0.967130,-53.688507,294.500458,0.000000
84.710007,64.988297,-53.777470,-0.000910,0.003808,0.096713,289.082367,14.726559,0.967130,-53.777470,294.500458,0.000000
85.060005,64.925751,-53.732990,-0.000905,0.003808,0.096713,288.804169,14.712385,0.967130,-53.732990,294.500458,0.000000
85.410004,64.922028,-53.732990,-0.000905,0.003809,0.096756,288.787598,14.711542,0.967564,-53.732990,294.500458,0.000000
85.760002,64.850891,-53.688507,-0.000892,0.003809,0.096756,288.471161,14.695421,0.967564,-53.688507,294.500458,0.000000
86.110001,64.776428,-53.732990,-0.000897,0.003809,0.096756,288.139954,14.678548,0.967564,-53.732990,294.500458,0.000000
86.460007,65.202042,-53.777470,-0.000905,0.003815,0.096904,290.033173,14.774994,0.969038,-53.777470,294.500458,0.000000
86.810005,65.140976,-53.732990,-0.000892,0.003815,0.096904,289.761536,14.761156,0.969038,-53.732990,294.500458,0.000000
87.160004,65.079529,-53.732990,-0.000901,0.003815,0.096904,289.488190,14.747232,0.969038,-53.732990,294.500458,0.000000
87.510002,64.995377,-53.732990,-0.000897,0.003815,0.096904,289.113861,14.728163,0.969038,-53.732990,294.500458,0.000000
87.860001,64.928345,-53.777470,-0.000888,0.003815,0.096904,288.815704,14.712973,0.969038,-53.777470,294.500458,0.000000
88.210007,64.813660,-53.777470,-0.000901,0.003815,0.096912,288.305542,14.686985,0.969125,-53.777470,294.500458,0.000000
88.560005,65.218063,-53.777470,-0.000905,0.003821,0.097051,290.104431,14.778625,0.970512,-53.777470,294.500458,0.000000
88.910004,65.182312,-53.777470,-0.000910,0.003821,0.097051,289.945404,14.770522,0.970512,-53.777470,294.500458,0.000000
89.260002,65.117523,-53.821949,-0.000901,0.003821,0.097051,289.657196,14.755842,0.970512,-53.821949,294.500458,0.000000
89.610001,65.028519,-53.777470,-0.000892,0.003821,0.097051,289.261292,14.735673,0.970512,-53.777470,294.500458,0.000000
89.960007,64.971542,-53.866432,-0.000888,0.003821,0.097051,289.007843,14.722762,0.970512,-53.866432,294.500458,0.000000
90.310005,64.928726,-53.910912,-0.000888,0.003821,0.097060,288.817413,14.713059,0.970599,-53.910912,294.500458,0.000000
90.660004,64.868393,-53.910912,-0.000880,0.003822,0.097069,288.549011,14.699388,0.970686,-53.910912,294.500458,0.000000
91.010002,65.240402,-53.866432,-0.000897,0.003827,0.097216,290.203796,14.783687,0.972160,-53.866432,294.500458,0.000000
91.360001,65.229980,-53.866432,-0.000888,0.003827,0.097216,290.157440,14.781325,0.972160,-53.866432,294.500458,0.000000
91.710007,65.194229,-53.866432,-0.000875,0.003827,0.097216,289.998413,14.773223,0.972160,-53.866432,294.500458,0.000000
92.060005,65.124588,-53.910912,-0.000892,0.003827,0.097216,289.688629,14.757442,0.972160,-53.910912,294.500458,0.000000
92.410004,65.068359,-53.955395,-0.000892,0.003827,0.097216,289.438507,14.744701,0.972160,-53.955395,294.500458,0.000000
92.760002,65.007294,-53.955395,-0.000892,0.003827,0.097216,289.166870,14.730864,0.972160,-53.955395,294.500458,0.000000
93.110001,65.233322,-53.955395,-0.000875,0.003831,0.097320,290.172302,14.782083,0.973201,-53.955395,294.500458,0.000000
93.460007,65.205017,-53.955395,-0.000888,0.003831,0.097320,290.046417,14.775668,0.973201,-53.955395,294.500458,0.000000
93.810005,65.155121,-53.955395,-0.000880,0.003831,0.097320,289.824463,14.764361,0.973201,-53.955395,294.500458,0.000000
94.160004,65.102615,-53.955395,-0.000884,0.003831,0.097320,289.590881,14.752463,0.973201,-53.955395,294.500458,0.000000
94.510002,65.039688,-53.955395,-0.000880,0.003832,0.097329,289.310974,14.738203,0.973287,-53.955395,294.500458,0.000000
94.860008,65.062408,-53.999874,-0.000871,0.003833,0.097355,289.412048,14.743353,0.973548,-53.999874,294.500458,0.000000
95.210007,65.016602,-53.999874,-0.000888,0.003834,0.097372,289.208282,14.732972,0.973721,-53.999874,294.500458,0.000000
95.560005,65.016602,-53.955395,-0.000875,0.003834,0.097372,289.208282,14.732972,0.973721,-53.955395,294.500458,0.000000
95.910004,65.081024,-53.999874,-0.000884,0.003836,0.097424,289.494843,14.747571,0.974241,-53.999874,294.500458,0.000000
96.260002,65.065384,-54.044357,-0.000875,0.003836,0.097424,289.425293,14.744026,0.974241,-54.044357,294.500458,0.000000
96.610008,65.019577,-54.044357,-0.000892,0.003836,0.097424,289.221527,14.733647,0.974241,-54.044357,294.500458,0.000000
96.960007,65.124969,-54.044357,-0.000884,0.003839,0.097511,289.690338,14.757528,0.975109,-54.044357,294.500458,0.000000
97.310005,65.218430,-53.999874,-0.000880,0.003839,0.097511,290.106049,14.778708,0.975109,-53.999874,294.500458,0.000000
97.660004,65.193481,-54.044357,-0.000884,0.003839,0.097511,289.995087,14.773054,0.975109,-54.044357,294.500458,0.000000
98.010002,65.165176,-54.088837,-0.000871,0.003839,0.097511,289.869171,14.766640,0.975109,-54.088837,294.500458,0.000000
98.360008,65.110062,-54.088837,-0.000867,0.003839,0.097511,289.624023,14.754150,0.975109,-54.088837,294.500458,0.000000
98.710007,65.078049,-54.044357,-0.000875,0.003839,0.097520,289.481628,14.746897,0.975195,-54.044357,294.500458,0.000000
99.060005,65.116394,-54.088837,-0.000871,0.003841,0.097563,289.652191,14.755586,0.975629,-54.088837,294.500458,0.000000
99.410004,65.100388,-54.133316,-0.000875,0.003841,0.097563,289.580994,14.751959,0.975629,-54.133316,294.500458,0.000000
99.760002,65.062775,-54.088837,-0.000867,0.003841,0.097563,289.413666,14.743436,0.975629,-54.088837,294.500458,0.000000
100.110008,65.133530,-54.177799,-0.000880,0.003843,0.097615,289.728424,14.759469,0.976149,-54.177799,294.500458,0.000000
100.460007,65.128311,-54.177799,-0.000871,0.003843,0.097615,289.705200,14.758286,0.976149,-54.177799,294.500458,0.000000
100.810005,65.082138,-54.133316,-0.000871,0.003843,0.097615,289.499817,14.747823,0.976149,-54.133316,294.500458,0.000000
101.160004,65.059052,-54.133316,-0.000854,0.003843,0.097615,289.397125,14.742592,0.976149,-54.133316,294.500458,0.000000
101.510002,65.174484,-54.133316,-0.000875,0.003847,0.097702,289.910583,14.768749,0.977016,-54.133316,294.500458,0.000000
101.860008,65.230347,-54.177799,-0.000854,0.003847,0.097702,290.159088,14.781407,0.977016,-54.177799,294.500458,0.000000
102.210007,65.200928,-54.177799,-0.000871,0.003847,0.097702,290.028198,14.774741,0.977016,-54.177799,294.500458,0.000000
102.560005,65.185287,-54.177799,-0.000867,0.003847,0.097702,289.958649,14.771197,0.977016,-54.177799,294.500458,0.000000
102.910004,65.130173,-54.177799,-0.000858,0.003847,0.097702,289.713470,14.758708,0.977016,-54.177799,294.500458,0.000000
103.260002,65.106339,-54.133316,-0.000880,0.003847,0.097702,289.607452,14.753307,0.977016,-54.133316,294.500458,0.000000
103.610008,65.113419,-54.266762,-0.000862,0.003848,0.097745,289.638947,14.754911,0.977450,-54.266762,294.500458,0.000000
103.960007,65.120865,-54.222279,-0.000871,0.003848,0.097745,289.672089,14.756599,0.977450,-54.222279,294.500458,0.000000
104.310005,65.092194,-54.222279,-0.000880,0.003848,0.097745,289.544525,14.750102,0.977450,-54.222279,294.500458,0.000000
104.660004,65.069107,-54.266762,-0.000862,0.003848,0.097745,289.441833,14.744871,0.977450,-54.266762,294.500458,0.000000
105.010002,65.036346,-54.222279,-0.000871,0.003848,0.097745,289.296112,14.737447,0.977450,-54.222279,294.500458,0.000000
105.360008,64.995758,-54.266762,-0.000862,0.003848,0.097745,289.115570,14.728249,0.977450,-54.266762,294.500458,0.000000
105.710007,64.954041,-54.222279,-0.000858,0.003848,0.097745,288.929993,14.718796,0.977450,-54.222279,294.500458,0.000000
106.060005,64.922760,-54.266762,-0.000858,0.003848,0.097745,288.790863,14.711707,0.977450,-54.266762,294.500458,0.000000
106.410004,64.882172,-54.311241,-0.000862,0.003849,0.097754,288.610321,14.702510,0.977537,-54.311241,294.500458,0.000000
106.760002,65.059052,-54.266762,-0.000871,0.003852,0.097840,289.397125,14.742592,0.978404,-54.266762,294.500458,0.000000
107.110008,65.075806,-54.400204,-0.000867,0.003852,0.097840,289.471649,14.746388,0.978404,-54.400204,294.500458,0.000000
107.460007,65.051605,-54.311241,-0.000854,0.003852,0.097840,289.363983,14.740905,0.978404,-54.311241,294.500458,0.000000
107.810005,65.034103,-54.355721,-0.000858,0.003852,0.097840,289.286133,14.736938,0.978404,-54.355721,294.500458,0.000000
108.160004,64.999847,-54.311241,-0.000867,0.003852,0.097840,289.133759,14.729176,0.978404,-54.311241,294.500458,0.000000
108.510002,64.978622,-54.400204,-0.000862,0.003852,0.097840,289.039337,14.724366,0.978404,-54.400204,294.500458,0.000000
108.860008,64.940262,-54.355721,-0.000845,0.003852,0.097840,288.868713,14.715673,0.978404,-54.355721,294.500458,0.000000
109.210007,64.897812,-54.400204,-0.000867,0.003852,0.097840,288.679871,14.706054,0.978404,-54.400204,294.500458,0.000000
109.560005,64.863937,-54.444683,-0.000871,0.003852,0.097840,288.529205,14.698379,0.978404,-54.444683,294.500458,0.000000
109.910004,65.604202,-54.355721,-0.000862,0.003862,0.098083,291.822052,14.866125,0.980832,-54.355721,294.500458,0.000000
110.260002,65.654846,-54.400204,-0.000871,0.003862,0.098083,292.047333,14.877601,0.980832,-54.400204,294.500458,0.000000
110.610008,65.642197,-54.400204,-0.000867,0.003862,0.098083,291.991089,14.874735,0.980832,-54.400204,294.500458,0.000000
110.960007,65.615753,-54.444683,-0.000867,0.003862,0.098083,291.873444,14.868742,0.980832,-54.444683,294.500458,0.000000
111.310005,65.593781,-54.444683,-0.000867,0.003862,0.098083,291.775696,14.863764,0.980832,-54.444683,294.500458,0.000000
111.660004,65.587082,-54.489166,-0.000862,0.003862,0.098083,291.745911,14.862246,0.980832,-54.489166,294.500458,0.000000
112.010002,65.555054,-54.444683,-0.000862,0.003862,0.098083,291.603455,14.854987,0.980832,-54.444683,294.500458,0.000000
112.360008,65.536057,-54.444683,-0.000845,0.003862,0.098083,291.518951,14.850682,0.980832,-54.444683,294.500458,0.000000
112.710007,65.504791,-54.444683,-0.000854,0.003862,0.098083,291.379852,14.843598,0.980832,-54.444683,294.500458,0.000000
113.060005,65.473129,-54.489166,-0.000854,0.003862,0.098083,291.239014,14.836423,0.980832,-54.489166,294.500458,0.000000
113.410004,65.416153,-54.489166,-0.000849,0.003862,0.098083,290.985596,14.823512,0.980832,-54.489166,294.500458,0.000000
113.760002,65.384506,-54.489166,-0.000845,0.003862,0.098083,290.844818,14.816340,0.980832,-54.489166,294.500458,0.000000
114.110008,65.353973,-54.533646,-0.000858,0.003862,0.098083,290.708984,14.809422,0.980832,-54.533646,294.500458,0.000000
114.460007,65.318970,-54.489166,-0.000858,0.003862,0.098083,290.553284,14.801490,0.980832,-54.489166,294.500458,0.000000
114.810005,65.282852,-54.533646,-0.000858,0.003862,0.098083,290.392639,14.793305,0.980832,-54.533646,294.500458,0.000000
115.160004,65.264236,-54.533646,-0.000854,0.003862,0.098083,290.309814,14.789087,0.980832,-54.533646,294.500458,0.000000
115.510002,65.232208,-54.578129,-0.000862,0.003862,0.098092,290.167358,14.781830,0.980919,-54.578129,294.500458,0.000000
115.860008,65.189377,-54.578129,-0.000849,0.003862,0.098092,289.976837,14.772124,0.980919,-54.578129,294.500458,0.000000
116.210007,65.189011,-54.578129,-0.000854,0.003863,0.098109,289.975189,14.772040,0.981092,-54.578129,294.500458,0.000000
116.560005,65.160706,-54.578129,-0.000854,0.003863,0.098109,289.849304,14.765627,0.981092,-54.578129,294.500458,0.000000
116.910004,65.141342,-54.578129,-0.000854,0.003863,0.098109,289.763153,14.761239,0.981092,-54.578129,294.500458,0.000000
117.260002,65.100388,-54.578129,-0.000845,0.003863,0.098109,289.580994,14.751959,0.981092,-54.578129,294.500458,0.000000
117.610008,65.079529,-54.622608,-0.000858,0.003863,0.098118,289.488190,14.747232,0.981179,-54.622608,294.500458,0.000000
117.960007,65.047882,-54.622608,-0.000854,0.003863,0.098118,289.347443,14.740061,0.981179,-54.622608,294.500458,0.000000
118.310005,65.020706,-54.667088,-0.000849,0.003863,0.098118,289.226532,14.733903,0.981179,-54.667088,294.500458,0.000000
118.660004,65.010651,-54.667088,-0.000849,0.003863,0.098118,289.181824,14.731625,0.981179,-54.667088,294.500458,0.000000
119.010002,64.977875,-54.667088,-0.000841,0.003863,0.098118,289.036011,14.724196,0.981179,-54.667088,294.500458,0.000000
119.360008,64.960007,-54.667088,-0.000841,0.003863,0.098118,288.956543,14.720148,0.981179,-54.667088,294.500458,0.000000
119.710007,64.923889,-54.667088,-0.000854,0.003863,0.098118,288.795868,14.711963,0.981179,-54.667088,294.500458,0.000000
120.060005,65.212479,-54.667088,-0.000845,0.003870,0.098309,290.079590,14.777359,0.983087,-54.667088,294.500458,0.000000
120.410004,65.437759,-54.711571,-0.000854,0.003870,0.098309,291.081696,14.828408,0.983087,-54.711571,294.500458,0.000000
120.760002,65.441483,-54.711571,-0.000836,0.003865,0.098161,291.098267,14.829251,0.981613,-54.711571,0.098300,0.000000
121.110008,65.358444,-54.756050,-0.000862,0.003855,0.097927,290.728882,14.810435,0.979271,-54.756050,0.097719,0.000000
121.460007,65.241150,-54.711571,-0.000828,0.003835,0.097398,290.207123,14.783856,0.973981,-54.711571,0.097138,0.000000
121.810005,65.154007,-54.711571,-0.000854,0.003817,0.096956,289.819489,14.764109,0.969558,-54.711571,0.096548,0.000000
122.160004,65.105972,-54.800533,-0.000824,0.003794,0.096366,289.605835,14.753223,0.963661,-54.800533,0.095967,0.000000
122.510002,65.032990,-54.756050,-0.000819,0.003775,0.095880,289.281189,14.736687,0.958805,-54.756050,0.095386,0.000000
122.860008,65.057190,-54.800533,-0.000832,0.003749,0.095213,289.388824,14.742170,0.952127,-54.800533,0.094805,0.000000
123.210007,64.932816,-54.800533,-0.000832,0.003727,0.094675,288.835602,14.713986,0.946750,-54.800533,0.094215,0.000000
123.560005,64.917175,-54.800533,-0.000815,0.003707,0.094155,288.766022,14.710442,0.941547,-54.800533,0.093634,0.000000
123.910004,64.859467,-54.756050,-0.000828,0.003682,0.093513,288.509308,14.697365,0.935129,-54.756050,0.093053,0.000000
124.260002,64.754822,-54.756050,-0.000815,0.003659,0.092941,288.043823,14.673653,0.929406,-54.756050,0.092472,0.000000
124.610008,64.639023,-54.845013,-0.000819,0.003640,0.092446,287.528748,14.647412,0.924463,-54.845013,0.091883,0.000000
124.960007,63.943802,-54.800533,-0.000819,0.003616,0.091839,284.436249,14.489873,0.918392,-54.800533,0.091302,0.000000
125.310005,63.293259,-54.889492,-0.000811,0.003597,0.091354,281.542480,14.342458,0.913535,-54.889492,0.090720,0.000000
125.660004,62.319511,-54.845013,-0.000793,0.003575,0.090816,277.211029,14.121803,0.908159,-54.845013,0.090131,0.000000
126.010010,61.280960,-54.889492,-0.000785,0.003556,0.090322,272.591339,13.886464,0.903216,-54.889492,0.089550,0.000000
126.360008,59.893875,-54.889492,-0.000772,0.003535,0.089784,266.421265,13.572145,0.897839,-54.889492,0.088969,0.000000
126.710007,58.410713,-54.889492,-0.000772,0.003513,0.089220,259.823822,13.236056,0.892202,-54.889492,0.088388,0.000000
127.060005,56.789780,-54.889492,-0.000780,0.003491,0.088682,252.613556,12.868748,0.886825,-54.889492,0.087798,0.000000
127.410004,55.180756,-54.889492,-0.000780,0.003471,0.088171,245.456253,12.504138,0.881708,-54.889492,0.087217,0.000000
127.760010,53.276443,-54.933975,-0.000767,0.003451,0.087668,236.985458,12.072615,0.876678,-54.933975,0.086636,0.000000
128.110001,51.859940,-54.889492,-0.000759,0.003432,0.087174,230.684540,11.751630,0.871735,-54.889492,0.086055,0.000000
128.460007,48.920433,-54.889492,-0.000763,0.003404,0.086454,217.608948,11.085528,0.864537,-54.889492,0.085465,0.000000
128.810013,46.104919,-54.978455,-0.000767,0.003378,0.085803,205.084930,10.447524,0.858033,-54.978455,0.084884,0.000000
129.160004,43.694183,-54.933975,-0.000767,0.003357,0.085274,194.361435,9.901243,0.852743,-54.933975,0.084303,0.000000
129.510010,41.636452,-54.933975,-0.000776,0.003338,0.084789,185.208191,9.434955,0.847887,-54.933975,0.083713,0.000000
129.860001,39.333328,-54.889492,-0.000780,0.003316,0.084225,174.963379,8.913059,0.842250,-54.889492,0.083132,0.000000
130.210007,36.712944,-55.022938,-0.000763,0.003292,0.083618,163.307327,8.319272,0.836179,-55.022938,0.082551,0.000000
130.560013,34.698410,-55.022938,-0.000776,0.003273,0.083132,154.346237,7.862772,0.831322,-55.022938,0.081970,0.000000
130.910004,31.692245,-55.022938,-0.000763,0.003244,0.082404,140.974152,7.181565,0.824038,-55.022938,0.081380,0.000000
131.260010,29.489662,-55.067417,-0.000785,0.003223,0.081857,131.176575,6.682453,0.818574,-55.067417,0.080799,0.000000
131.610001,26.910240,-55.022938,-0.000767,0.003200,0.081285,119.702728,6.097948,0.812851,-55.022938,0.080218,0.000000
131.960007,24.608978,-54.978455,-0.000767,0.003176,0.080661,109.466202,5.576474,0.806607,-54.978455,0.079637,0.000000
132.310013,22.154297,-55.067417,-0.000759,0.003156,0.080158,98.547234,5.020236,0.801577,-55.067417,0.079048,0.000000
132.660004,19.750259,-55.067417,-0.000776,0.003133,0.079568,87.853539,4.475472,0.795680,-55.067417,0.078467,0.000000
133.010010,16.818199,-55.022938,-0.000763,0.003105,0.078865,74.811089,3.811058,0.788655,-55.022938,0.077886,0.000000
133.360001,14.585457,-55.022938,-0.000776,0.003085,0.078354,64.879349,3.305112,0.783538,-55.022938,0.077304,0.000000
133.710007,11.990021,-55.111897,-0.000772,0.003062,0.077773,53.334274,2.716978,0.777728,-55.111897,0.076715,0.000000
134.060013,9.145470,-55.067417,-0.000759,0.003034,0.077062,40.681080,2.072393,0.770617,-55.067417,0.076134,0.000000
134.410004,6.857613,-55.067417,-0.000776,0.003016,0.076602,30.504185,1.553957,0.766020,-55.067417,0.075553,0.000000
134.760010,4.271484,-55.067417,-0.000767,0.002988,0.075891,19.000511,0.967932,0.758909,-55.067417,0.074963,0.000000
135.110001,2.232368,-55.156380,-0.000767,0.002969,0.075405,9.930071,0.505862,0.754053,-55.156380,0.074382,0.000000
135.460007,0.800598,-55.067417,-0.000772,0.002954,0.075024,3.561238,0.181418,0.750237,-55.067417,0.073801,0.000000
135.810013,-1.365864,-55.111897,-0.000776,0.002925,0.074304,-6.075665,-0.309509,0.743039,-55.111897,0.073220,0.000000
136.160004,-0.365669,-55.156380,-0.000776,0.002901,0.073679,-1.626578,-0.082862,0.736795,-55.156380,0.072630,0.000000
136.510010,-0.160866,-55.111897,-0.000772,0.002880,0.073142,-0.715567,-0.036453,0.731418,-55.111897,0.072049,0.000000
136.860001,0.002609,-55.156380,-0.000793,0.002848,0.072327,0.011607,0.000591,0.723266,-55.156380,0.071468,0.000000
137.210007,0.076332,-55.200859,-0.000824,0.002830,0.071876,0.339542,0.017297,0.718757,-55.200859,0.070887,0.000000
137.560013,0.029419,-55.200859,-0.000849,0.002809,0.071355,0.130862,0.006666,0.713553,-55.200859,0.070297,0.000000
137.910004,0.105011,-55.200859,-0.000905,0.002787,0.070792,0.467112,0.023796,0.707916,-55.200859,0.069716,0.000000
138.260010,0.063301,-55.200859,-0.000931,0.002763,0.070185,0.281577,0.014344,0.701846,-55.200859,0.069135,0.000000
138.610001,0.078568,-55.200859,-0.000974,0.002734,0.069447,0.349486,0.017804,0.694474,-55.200859,0.068554,0.000000
138.960007,0.071121,-55.200859,-0.001013,0.002714,0.068927,0.316363,0.016116,0.689271,-55.200859,0.067964,0.000000
139.310013,0.116920,-55.200859,-0.001065,0.002694,0.068415,0.520088,0.026495,0.684154,-55.200859,0.067383,0.000000
139.660004,0.117668,-55.245342,-0.001091,0.002674,0.067930,0.523414,0.026664,0.679298,-55.245342,0.066802,0.000000
140.010010,0.101288,-55.245342,-0.001151,0.002647,0.067245,0.450551,0.022952,0.672447,-55.245342,0.066213,0.000000
140.360001,0.078568,-55.245342,-0.001173,0.002627,0.066733,0.349486,0.017804,0.667330,-55.245342,0.065632,0.000000
140.710007,0.054741,-55.200859,-0.001229,0.002595,0.065900,0.243500,0.012404,0.659005,-55.200859,0.065051,0.000000
141.060013,0.070007,-55.245342,-0.001268,0.002575,0.065397,0.311408,0.015864,0.653975,-55.245342,0.064470,0.000000
141.410004,0.058830,-55.245342,-0.001302,0.002551,0.064790,0.261690,0.013331,0.647904,-55.245342,0.063880,0.000000
141.760010,0.049149,-55.289822,-0.001354,0.002530,0.064270,0.218624,0.011137,0.642701,-55.289822,0.063299,0.000000
142.110001,0.032768,-55.334305,-0.001388,0.002508,0.063698,0.145760,0.007425,0.636977,-55.334305,0.062718,0.000000
142.460007,0.044312,-55.378784,-0.001444,0.002480,0.062987,0.197107,0.010041,0.629866,-55.378784,0.062137,0.000000
142.810013,0.039101,-55.334305,-0.001475,0.002459,0.062458,0.173928,0.008860,0.624576,-55.334305,0.061547,0.000000
143.160004,0.010056,-55.378784,-0.001513,0.002434,0.061816,0.044729,0.002279,0.618158,-55.378784,0.060966,0.000000
143.510010,0.015640,-55.289822,-0.001548,0.002414,0.061304,0.069571,0.003544,0.613042,-55.289822,0.060385,0.000000
143.860001,0.006699,-55.334305,-0.001587,0.002392,0.060758,0.029797,0.001518,0.607578,-55.334305,0.059795,0.000000
144.210007,-0.004845,-55.378784,-0.001621,0.002372,0.060237,-0.021550,-0.001098,0.602375,-55.378784,0.059214,0.000000
144.560013,0.011169,-55.334305,-0.001656,0.002341,0.059466,0.049684,0.002531,0.594657,-55.334305,0.058633,0.000000
144.910004,0.013405,-55.378784,-0.001690,0.002322,0.058971,0.059628,0.003038,0.589713,-55.378784,0.058052,0.000000
145.260010,-0.000374,-55.378784,-0.001725,0.002296,0.058312,-0.001663,-0.000085,0.583122,-55.378784,0.057462,0.000000
145.610001,0.017876,-55.423264,-0.001772,0.002274,0.057749,0.079515,0.004051,0.577486,-55.423264,0.056881,0.000000
145.960007,0.002975,-55.423264,-0.001776,0.002254,0.057254,0.013236,0.000674,0.572542,-55.423264,0.056300,0.000000
146.310013,-0.008934,-55.378784,-0.001819,0.002228,0.056595,-0.039741,-0.002024,0.565951,-55.378784,0.055719,0.000000
146.660004,-0.008934,-55.423264,-0.001854,0.002205,0.056005,-0.039741,-0.002024,0.560054,-55.423264,0.055130,0.000000
147.010010,-0.018250,-55.467747,-0.001871,0.002184,0.055468,-0.081178,-0.004135,0.554678,-55.467747,0.054548,0.000000
147.360001,-0.024208,-55.378784,-0.001893,0.002164,0.054973,-0.107683,-0.005486,0.549734,-55.378784,0.053967,0.000000
147.600006,0.010429,-55.467747,-0.001919,0.002148,0.054566,0.046392,0.002363,0.545658,-55.467747,0.054462,0.000000