File: Data/compression 25/AutoNoHeating-17-25-reverse-1-3_09232024_184520.csv
Time (sec),S:Load (lbs),S:HL1 (DIM),S:LVDT (in),S:Position (in),Ch:Position (mm),Ch:Load (N),Ch:Stress (MPa),Ch:Strain (mm/mm),Ch:HL1 (DIM),Set Point (),Cycles ()
0.110000,-0.201828,-37.363998,-0.009132,-0.004966,-0.126129,-0.897776,-0.045735,-1.261294,-37.363998,-0.125904,0.000000
0.470000,-0.215607,-37.452961,-0.009140,-0.004922,-0.125011,-0.959066,-0.048857,-1.250105,-37.452961,-0.124499,0.000000
0.830000,-0.218582,-37.408482,-0.009046,-0.004714,-0.119738,-0.972302,-0.049531,-1.197378,-37.408482,-0.118498,0.000000
1.190000,-0.269600,-37.408482,-0.008800,-0.004476,-0.113693,-1.199240,-0.061092,-1.136933,-37.408482,-0.112497,0.000000
1.550000,-0.262527,-37.452961,-0.008554,-0.004235,-0.107579,-1.167781,-0.059490,-1.075792,-37.452961,-0.106513,0.000000
1.910000,-0.189537,-37.408482,-0.008317,-0.004004,-0.101700,-0.843103,-0.042950,-1.016997,-37.408482,-0.100512,0.000000
2.270000,-0.158630,-37.541924,-0.008088,-0.003773,-0.095837,-0.705623,-0.035946,-0.958373,-37.541924,-0.094510,0.000000
2.630000,-0.185074,-37.452961,-0.007834,-0.003535,-0.089792,-0.823250,-0.041938,-0.897925,-37.452961,-0.088509,0.000000
2.990000,-0.218582,-37.497440,-0.007580,-0.003297,-0.083748,-0.972302,-0.049531,-0.837480,-37.497440,-0.082525,0.000000
3.350000,-0.225288,-37.497440,-0.007347,-0.003055,-0.077599,-1.002133,-0.051051,-0.775994,-37.497440,-0.076524,0.000000
3.710000,-0.235344,-37.452961,-0.007088,-0.002823,-0.071693,-1.046862,-0.053330,-0.716935,-37.452961,-0.070523,0.000000
4.070000,-0.194382,-37.497440,-0.006860,-0.002587,-0.065710,-0.864653,-0.044048,-0.657096,-37.497440,-0.064521,0.000000
4.430000,-0.156029,-37.497440,-0.006605,-0.002354,-0.059787,-0.694051,-0.035357,-0.597866,-37.497440,-0.058521,0.000000
4.790000,-0.192894,-37.541924,-0.006372,-0.002122,-0.053898,-0.858035,-0.043710,-0.538980,-37.541924,-0.052537,0.000000
5.150000,-0.183578,-37.497440,-0.006118,-0.001886,-0.047897,-0.816598,-0.041599,-0.478971,-37.497440,-0.046535,0.000000
5.510000,-0.200714,-37.541924,-0.005877,-0.001644,-0.041766,-0.892821,-0.045482,-0.417656,-37.541924,-0.040534,0.000000
5.870000,-0.235718,-37.541924,-0.005622,-0.001403,-0.035643,-1.048525,-0.053414,-0.356431,-37.541924,-0.034533,0.000000
6.230000,-0.204803,-37.630886,-0.005398,-0.001173,-0.029789,-0.911011,-0.046409,-0.297894,-37.630886,-0.028532,0.000000
6.590000,-0.151184,-37.630886,-0.005157,-0.000942,-0.023918,-0.672500,-0.034259,-0.239183,-37.630886,-0.022548,0.000000
6.950000,-0.180977,-37.630886,-0.004915,-0.000706,-0.017934,-0.805025,-0.041010,-0.179343,-37.630886,-0.016547,0.000000
7.310000,-0.179115,-37.586403,-0.004644,-0.000470,-0.011950,-0.796745,-0.040588,-0.119504,-37.586403,-0.010545,0.000000
7.670001,-0.114693,-37.675365,-0.004415,-0.000230,-0.005845,-0.510179,-0.025990,-0.058450,-37.675365,-0.004544,0.000000
8.030001,0.099052,-37.586403,-0.004324,-0.000004,-0.000112,0.440607,0.022446,-0.001124,-37.586403,0.000113,0.000000
8.390000,0.216721,-37.675365,-0.004333,-0.000004,-0.000112,0.964021,0.049110,-0.001124,-37.675365,0.000234,0.000000
8.750000,0.144104,-37.675365,-0.004324,-0.000004,-0.000112,0.641007,0.032654,-0.001124,-37.675365,0.000833,0.000000
9.110001,0.110596,-37.675365,-0.004324,-0.000004,-0.000104,0.491954,0.025061,-0.001041,-37.675365,0.001431,0.000000
9.470000,0.450943,-37.719845,-0.004320,0.000030,0.000772,2.005895,0.102185,0.007721,-37.719845,0.002029,0.000000
9.830001,0.918266,-37.630886,-0.004286,0.000060,0.001518,4.084652,0.208082,0.015177,-37.630886,0.002628,0.000000
10.190001,1.454483,-37.764328,-0.004277,0.000092,0.002324,6.469864,0.329591,0.023243,-37.764328,0.003235,0.000000
10.550000,1.871918,-37.764328,-0.004230,0.000114,0.002905,8.326706,0.424183,0.029053,-37.764328,0.003833,0.000000
10.910001,2.375359,-37.719845,-0.004208,0.000140,0.003547,10.566123,0.538264,0.035472,-37.719845,0.004432,0.000000
11.270000,2.864662,-37.764328,-0.004217,0.000160,0.004076,12.742654,0.649142,0.040760,-37.764328,0.005030,0.000000
11.630000,3.216553,-37.764328,-0.004191,0.000177,0.004484,14.307941,0.728881,0.044836,-37.764328,0.005629,0.000000
11.990001,4.171310,-37.764328,-0.004165,0.000212,0.005386,18.554916,0.945232,0.053855,-37.764328,0.006227,0.000000
12.350000,4.394737,-37.764328,-0.004156,0.000228,0.005784,19.548767,0.995862,0.057845,-37.764328,0.006834,0.000000
12.710001,5.074692,-37.808807,-0.004122,0.000255,0.006470,22.573357,1.149942,0.064695,-37.808807,0.007432,0.000000
13.070001,5.772888,-37.764328,-0.004109,0.000280,0.007120,25.679089,1.308155,0.071201,-37.764328,0.008031,0.000000
13.430000,6.080841,-37.808807,-0.004087,0.000297,0.007536,27.048931,1.377938,0.075365,-37.808807,0.008629,0.000000
13.790001,6.612961,-37.853291,-0.004074,0.000315,0.007996,29.415918,1.498518,0.079960,-37.853291,0.009228,0.000000
14.150001,7.684273,-37.808807,-0.004053,0.000350,0.008880,34.181351,1.741281,0.088805,-37.808807,0.009835,0.000000
14.510000,7.830246,-37.897770,-0.004027,0.000369,0.009375,34.830673,1.774359,0.093748,-37.897770,0.010433,0.000000
14.870001,8.343376,-37.942253,-0.004027,0.000390,0.009913,37.113190,1.890636,0.099126,-37.942253,0.011031,0.000000
15.230000,9.139877,-37.853291,-0.003975,0.000416,0.010572,40.656204,2.071126,0.105716,-37.853291,0.011629,0.000000
15.590001,9.372238,-37.942253,-0.003971,0.000433,0.010988,41.689796,2.123780,0.109879,-37.942253,0.012228,0.000000
15.950001,10.730652,-37.897770,-0.003949,0.000470,0.011950,47.732323,2.431600,0.119504,-37.897770,0.012835,0.000000
16.310001,10.752251,-37.942253,-0.003919,0.000489,0.012410,47.828400,2.436495,0.124103,-37.942253,0.013433,0.000000
16.670000,11.214737,-37.942253,-0.003919,0.000510,0.012965,49.885643,2.541296,0.129652,-37.942253,0.014032,0.000000
17.030001,11.750580,-37.897770,-0.003889,0.000534,0.013555,52.269188,2.662719,0.135548,-37.897770,0.014630,0.000000
17.390001,12.329994,-37.986732,-0.003876,0.000556,0.014127,54.846554,2.794017,0.141271,-37.986732,0.015229,0.000000
17.750000,12.732529,-37.942253,-0.003863,0.000576,0.014630,56.637115,2.885232,0.146301,-37.942253,0.015836,0.000000
18.110001,13.475037,-37.942253,-0.003829,0.000606,0.015385,59.939957,3.053487,0.153848,-37.942253,0.016434,0.000000
18.470001,13.551750,-37.942253,-0.003811,0.000619,0.015732,60.281197,3.070870,0.157315,-37.942253,0.017032,0.000000
18.830002,14.144569,-37.986732,-0.003786,0.000642,0.016304,62.918186,3.205205,0.163038,-37.986732,0.017631,0.000000
19.190001,15.022995,-38.031212,-0.003773,0.000674,0.017110,66.825623,3.404259,0.171104,-38.031212,0.018229,0.000000
19.550001,15.377121,-38.031212,-0.003747,0.000697,0.017700,68.400848,3.484505,0.177001,-38.031212,0.018828,0.000000
19.910002,15.518250,-38.031212,-0.003734,0.000713,0.018116,69.028618,3.516486,0.181164,-38.031212,0.019435,0.000000
20.270000,16.128197,-38.031212,-0.003708,0.000740,0.018784,71.741798,3.654702,0.187844,-38.031212,0.020033,0.000000
20.630001,16.395927,-38.031212,-0.003682,0.000756,0.019200,72.932724,3.715370,0.192004,-38.031212,0.020631,0.000000
20.990002,17.209190,-38.120174,-0.003665,0.000784,0.019912,76.550301,3.899658,0.199116,-38.120174,0.021230,0.000000
21.350000,18.054848,-38.075695,-0.003656,0.000817,0.020744,80.311974,4.091287,0.207443,-38.075695,0.021828,0.000000
21.710001,18.093948,-38.075695,-0.003604,0.000835,0.021221,80.485901,4.100147,0.212211,-38.075695,0.022435,0.000000
22.070002,18.738152,-38.075695,-0.003609,0.000865,0.021967,83.351463,4.246126,0.219672,-38.075695,0.023034,0.000000
22.430000,18.990623,-38.075695,-0.003566,0.000884,0.022444,84.474510,4.303337,0.224440,-38.075695,0.023632,0.000000
22.790001,18.872208,-38.164658,-0.003553,0.000898,0.022817,83.947769,4.276504,0.228169,-38.164658,0.024231,0.000000
23.150002,19.789360,-38.120174,-0.003531,0.000927,0.023554,88.027473,4.484333,0.235542,-38.120174,0.024829,0.000000
23.510000,20.354622,-38.209137,-0.003505,0.000954,0.024231,90.541878,4.612423,0.242305,-38.209137,0.025436,0.000000
23.870001,20.359459,-38.120174,-0.003492,0.000973,0.024707,90.563393,4.613520,0.247074,-38.120174,0.026034,0.000000
24.230001,20.958237,-38.164658,-0.003458,0.000998,0.025358,93.226891,4.749205,0.253577,-38.164658,0.026633,0.000000
24.590002,21.325768,-38.209137,-0.003454,0.001023,0.025991,94.861755,4.832488,0.259909,-38.209137,0.027231,0.000000
24.950001,21.484772,-38.253616,-0.003428,0.001043,0.026503,95.569038,4.868519,0.265026,-38.253616,0.027830,0.000000
25.310001,22.194138,-38.209137,-0.003389,0.001074,0.027283,98.724457,5.029263,0.272830,-38.209137,0.028436,0.000000
25.670002,22.712486,-38.253616,-0.003389,0.001100,0.027934,101.030182,5.146723,0.279337,-38.253616,0.029035,0.000000
26.030001,23.138107,-38.209137,-0.003367,0.001126,0.028593,102.923439,5.243170,0.285926,-38.209137,0.029633,0.000000
26.390001,23.170502,-38.298100,-0.003346,0.001144,0.029070,103.067535,5.250511,0.290695,-38.298100,0.030231,0.000000
26.750002,23.748421,-38.209137,-0.003316,0.001169,0.029694,105.638252,5.381469,0.296940,-38.209137,0.030830,0.000000
27.110001,24.121170,-38.209137,-0.003285,0.001196,0.030388,107.296326,5.465935,0.303878,-38.209137,0.031428,0.000000
27.470001,24.119308,-38.253616,-0.003272,0.001217,0.030917,107.288040,5.465513,0.309169,-38.253616,0.032035,0.000000
27.830002,24.810059,-38.253616,-0.003234,0.001245,0.031628,110.360649,5.622040,0.316277,-38.253616,0.032634,0.000000
28.190001,25.064384,-38.298100,-0.003216,0.001271,0.032278,111.491951,5.679670,0.322783,-38.298100,0.033232,0.000000
28.550001,25.567467,-38.298100,-0.003186,0.001297,0.032937,113.729774,5.793671,0.329373,-38.298100,0.033831,0.000000
28.910002,25.286697,-38.342579,-0.003178,0.001313,0.033362,112.480850,5.730047,0.333623,-38.342579,0.034429,0.000000
29.270000,25.735779,-38.342579,-0.003143,0.001335,0.033908,114.478462,5.831811,0.339085,-38.342579,0.035036,0.000000
29.630001,25.918983,-38.342579,-0.003130,0.001358,0.034490,115.293396,5.873326,0.344899,-38.342579,0.035634,0.000000
29.990002,26.564308,-38.431541,-0.003134,0.001386,0.035209,118.163948,6.019558,0.352094,-38.431541,0.036233,0.000000
30.350002,26.782516,-38.342579,-0.003091,0.001407,0.035738,119.134583,6.069005,0.357385,-38.342579,0.036831,0.000000
30.710001,26.690910,-38.387062,-0.003074,0.001421,0.036103,118.727097,6.048247,0.361026,-38.387062,0.037430,0.000000
31.070002,27.589073,-38.342579,-0.003053,0.001451,0.036866,122.722328,6.251773,0.368660,-38.342579,0.038037,0.000000
31.430002,28.441437,-38.431541,-0.003014,0.001483,0.037664,126.513832,6.444921,0.376639,-38.431541,0.038635,0.000000
31.790001,28.725929,-38.476021,-0.003009,0.001507,0.038288,127.779312,6.509389,0.382880,-38.476021,0.039233,0.000000
32.150002,28.685707,-38.387062,-0.002975,0.001529,0.038843,127.600395,6.500274,0.388432,-38.387062,0.039832,0.000000
32.510002,29.159744,-38.476021,-0.002962,0.001556,0.039511,129.709015,6.607693,0.395109,-38.476021,0.040430,0.000000
32.870003,28.798912,-38.431541,-0.002940,0.001571,0.039901,128.103958,6.525927,0.399011,-38.431541,0.041037,0.000000
33.230003,29.637123,-38.520504,-0.002906,0.001600,0.040630,131.832504,6.715868,0.406297,-38.520504,0.041636,0.000000
33.590000,30.216904,-38.520504,-0.002897,0.001625,0.041271,134.411499,6.847249,0.412713,-38.520504,0.042234,0.000000
33.950001,30.428787,-38.476021,-0.002876,0.001647,0.041826,135.354004,6.895262,0.418265,-38.476021,0.042833,0.000000
34.310001,31.120651,-38.520504,-0.002854,0.001674,0.042520,138.431564,7.052041,0.425203,-38.520504,0.043431,0.000000
34.670002,31.126610,-38.520504,-0.002833,0.001692,0.042980,138.458069,7.053391,0.429798,-38.520504,0.044038,0.000000
35.030003,31.347054,-38.564983,-0.002811,0.001713,0.043518,139.438660,7.103344,0.435176,-38.564983,0.044636,0.000000
35.390003,31.751823,-38.476021,-0.002807,0.001741,0.044229,141.239166,7.195066,0.442288,-38.476021,0.045235,0.000000
35.750000,32.394539,-38.520504,-0.002772,0.001761,0.044732,144.098099,7.340707,0.447318,-38.520504,0.045833,0.000000
36.110001,32.696533,-38.609467,-0.002746,0.001784,0.045313,145.441437,7.409140,0.453128,-38.609467,0.046432,0.000000
36.470001,33.910095,-38.564983,-0.002729,0.001815,0.046093,150.839630,7.684137,0.460932,-38.564983,0.047030,0.000000
36.830002,32.607910,-38.564983,-0.002716,0.001818,0.046189,145.047226,7.389058,0.461886,-38.564983,0.047637,0.000000
37.190002,34.490997,-38.609467,-0.002695,0.001862,0.047290,153.423615,7.815772,0.472900,-38.609467,0.048235,0.000000
37.550003,34.723358,-38.609467,-0.002677,0.001881,0.047767,154.457214,7.868425,0.477669,-38.609467,0.048833,0.000000
37.910004,35.132591,-38.653946,-0.002656,0.001904,0.048374,156.277573,7.961159,0.483740,-38.653946,0.049432,0.000000
38.270000,35.385811,-38.609467,-0.002621,0.001928,0.048964,157.403946,8.018539,0.489637,-38.609467,0.050030,0.000000
38.630001,36.031128,-38.653946,-0.002608,0.001953,0.049606,160.274460,8.164770,0.496056,-38.653946,0.050637,0.000000
38.990002,36.142838,-38.609467,-0.002600,0.001971,0.050065,160.771378,8.190084,0.500651,-38.609467,0.051236,0.000000
39.350002,36.937859,-38.653946,-0.002565,0.001995,0.050672,164.307800,8.370238,0.506722,-38.653946,0.051834,0.000000
39.710003,37.027596,-38.653946,-0.002548,0.002014,0.051158,164.706970,8.390573,0.511578,-38.653946,0.052433,0.000000
40.070004,36.823914,-38.698429,-0.002522,0.002035,0.051678,163.800949,8.344419,0.516782,-38.698429,0.053031,0.000000
40.430000,38.849243,-38.698429,-0.002496,0.002068,0.052537,172.810059,8.803365,0.525366,-38.698429,0.053638,0.000000
40.790001,38.957230,-38.698429,-0.002492,0.002088,0.053031,173.290405,8.827835,0.530309,-38.698429,0.054236,0.000000
41.150002,39.280083,-38.698429,-0.002488,0.002110,0.053603,174.726532,8.900994,0.536032,-38.698429,0.054835,0.000000
41.510002,39.863960,-38.742908,-0.002449,0.002131,0.054115,177.323746,9.033303,0.541149,-38.742908,0.055433,0.000000
41.870003,40.105255,-38.698429,-0.002440,0.002151,0.054627,178.397079,9.087980,0.546266,-38.698429,0.056032,0.000000
42.230003,41.036186,-38.787388,-0.002419,0.002176,0.055277,182.538071,9.298933,0.552773,-38.787388,0.056639,0.000000
42.590000,42.284752,-38.653946,-0.002393,0.002209,0.056110,188.091965,9.581861,0.561096,-38.653946,0.057237,0.000000
42.950001,42.432961,-38.787388,-0.002376,0.002228,0.056586,188.751236,9.615446,0.565865,-38.787388,0.057835,0.000000
43.310001,43.223129,-38.742908,-0.002367,0.002251,0.057177,192.266083,9.794501,0.571765,-38.742908,0.058434,0.000000
43.670002,44.170074,-38.742908,-0.002350,0.002281,0.057931,196.478302,10.009083,0.579308,-38.742908,0.059032,0.000000
44.030003,44.125015,-38.831871,-0.002328,0.002295,0.058295,196.277878,9.998871,0.582950,-38.831871,0.059631,0.000000
44.390003,44.943863,-38.831871,-0.002307,0.002320,0.058928,199.920288,10.184424,0.589282,-38.831871,0.060238,0.000000
44.750004,46.205093,-38.831871,-0.002276,0.002350,0.059691,205.530518,10.470223,0.596912,-38.831871,0.060836,0.000000
45.110001,46.326859,-38.831871,-0.002285,0.002366,0.060108,206.072159,10.497816,0.601075,-38.831871,0.061435,0.000000
45.470001,46.832169,-38.831871,-0.002246,0.002390,0.060706,208.319885,10.612321,0.607059,-38.831871,0.062033,0.000000
45.830002,47.810387,-38.876350,-0.002238,0.002416,0.061374,212.671219,10.833989,0.613736,-38.876350,0.062631,0.000000
46.190002,48.774086,-38.831871,-0.002216,0.002441,0.062007,216.957977,11.052366,0.620068,-38.831871,0.063238,0.000000
46.550003,49.300621,-38.920834,-0.002186,0.002462,0.062545,219.300110,11.171680,0.625446,-38.920834,0.063837,0.000000
46.910004,50.098244,-38.920834,-0.002186,0.002491,0.063273,222.848114,11.352424,0.632728,-38.920834,0.064435,0.000000
47.270000,51.248878,-38.876350,-0.002156,0.002516,0.063897,227.966400,11.613161,0.638974,-38.876350,0.065034,0.000000
47.630001,51.383301,-39.009792,-0.002139,0.002532,0.064322,228.564331,11.643622,0.643224,-39.009792,0.065632,0.000000
47.990002,52.940559,-38.965313,-0.002126,0.002567,0.065190,235.491364,11.996502,0.651895,-38.965313,0.066239,0.000000
48.350002,53.767227,-38.965313,-0.002095,0.002590,0.065797,239.168564,12.183828,0.657966,-38.965313,0.066837,0.000000
48.710003,54.254669,-38.876350,-0.002087,0.002612,0.066343,241.336823,12.294284,0.663428,-38.876350,0.067435,0.000000
49.070004,55.101067,-39.009792,-0.002070,0.002634,0.066907,245.101791,12.486080,0.669067,-39.009792,0.068034,0.000000
49.430004,56.216324,-39.009792,-0.002061,0.002661,0.067600,250.062698,12.738801,0.676005,-39.009792,0.068632,0.000000
49.790001,57.263062,-38.965313,-0.002039,0.002690,0.068320,254.718826,12.975996,0.683200,-38.965313,0.069239,0.000000
50.150002,57.483879,-39.098755,-0.002018,0.002705,0.068711,255.701065,13.026033,0.687106,-39.098755,0.069838,0.000000
50.510002,57.509201,-39.009792,-0.002001,0.002724,0.069187,255.813705,13.031772,0.691875,-39.009792,0.070436,0.000000
50.870003,59.349091,-39.009792,-0.001988,0.002753,0.069933,263.997925,13.448696,0.699331,-39.009792,0.071035,0.000000
51.230003,59.798920,-39.098755,-0.001983,0.002773,0.070427,265.998871,13.550630,0.704274,-39.098755,0.071633,0.000000
51.590004,60.817360,-39.009792,-0.001953,0.002799,0.071104,270.529114,13.781410,0.711042,-39.009792,0.072231,0.000000
51.950001,61.543854,-39.143238,-0.001944,0.002821,0.071650,273.760742,13.946036,0.716503,-39.143238,0.072838,0.000000
52.310001,62.224182,-39.098755,-0.001927,0.002842,0.072179,276.786987,14.100201,0.721795,-39.098755,0.073437,0.000000
52.670002,64.222328,-39.098755,-0.001906,0.002875,0.073020,285.675171,14.552988,0.730205,-39.098755,0.074035,0.000000
53.030003,65.472389,-39.143238,-0.001893,0.002902,0.073706,291.235718,14.836256,0.737055,-39.143238,0.074634,0.000000
53.390003,65.959084,-39.098755,-0.001871,0.002922,0.074217,293.400665,14.946542,0.742172,-39.098755,0.075232,0.000000
53.750004,65.349510,-39.098755,-0.001854,0.002922,0.074226,290.689148,14.808411,0.742260,-39.098755,0.013043,0.000000
54.110004,65.716667,-39.143238,-0.001811,0.002737,0.069517,292.322327,14.891609,0.695168,-39.143238,294.500488,0.000000
54.470001,65.449303,-39.143238,-0.001802,0.002942,0.074738,291.133026,14.831024,0.747377,-39.143238,294.500488,0.000000
54.830002,67.209877,-39.143238,-0.001811,0.002861,0.072665,298.964478,15.229976,0.726651,-39.143238,294.500488,0.000000
55.190002,65.441109,-39.098755,-0.001798,0.002840,0.072145,291.096588,14.829167,0.721446,-39.098755,294.500488,0.000000
55.550003,64.920906,-39.232201,-0.001802,0.002991,0.075961,288.782623,14.711287,0.759606,-39.232201,294.500488,0.000000
55.910004,64.788704,-39.143238,-0.001807,0.002997,0.076117,288.194550,14.681330,0.761165,-39.143238,294.500488,0.000000
56.270004,65.410194,-39.232201,-0.001772,0.002982,0.075752,290.959076,14.822162,0.757524,-39.232201,294.500488,0.000000
56.630001,65.175240,-39.232201,-0.001776,0.003023,0.076793,289.913940,14.768920,0.767929,-39.232201,294.500488,0.000000
56.990002,65.299599,-39.276680,-0.001781,0.003037,0.077149,290.467133,14.797101,0.771487,-39.276680,294.500488,0.000000
57.350002,65.143959,-39.276680,-0.001776,0.003046,0.077374,289.774811,14.761832,0.773739,-39.276680,294.500488,0.000000
57.710003,65.214699,-39.187717,-0.001759,0.003058,0.077677,290.089478,14.777862,0.776774,-39.187717,294.500488,0.000000
58.070004,65.295143,-39.232201,-0.001750,0.003069,0.077947,290.447296,14.796091,0.779465,-39.232201,294.500488,0.000000
58.430004,65.286568,-39.232201,-0.001750,0.003079,0.078198,290.409149,14.794147,0.781978,-39.232201,294.500488,0.000000
58.790001,65.124214,-39.276680,-0.001742,0.003090,0.078484,289.686981,14.757359,0.784840,-39.276680,294.500488,0.000000
59.150002,65.058311,-39.321159,-0.001750,0.003096,0.078632,289.393829,14.742424,0.786316,-39.321159,294.500488,0.000000
59.510002,65.266838,-39.321159,-0.001720,0.003106,0.078892,290.321381,14.789678,0.788916,-39.321159,294.500488,0.000000
59.870003,65.038567,-39.321159,-0.001725,0.003113,0.079065,289.306000,14.737949,0.790649,-39.321159,294.500488,0.000000
60.230003,64.860954,-39.321159,-0.001738,0.003121,0.079282,288.515930,14.697701,0.792818,-39.321159,294.500488,0.000000
60.590004,66.232399,-39.365643,-0.001716,0.003140,0.079767,294.616425,15.008476,0.797674,-39.365643,294.500488,0.000000
60.950005,65.259010,-39.410122,-0.001716,0.003136,0.079663,290.286591,14.787904,0.796633,-39.410122,294.500488,0.000000
61.310001,65.563988,-39.321159,-0.001707,0.003146,0.079915,291.643188,14.857012,0.799150,-39.321159,294.500488,0.000000
61.670002,64.635292,-39.410122,-0.001703,0.003152,0.080054,287.512146,14.646567,0.800539,-39.410122,294.500488,0.000000
62.030003,65.655586,-39.410122,-0.001677,0.003143,0.079820,292.050629,14.877769,0.798196,-39.410122,294.500488,0.000000
62.390003,65.790764,-39.410122,-0.001686,0.003175,0.080635,292.651947,14.908401,0.806349,-39.410122,294.500488,0.000000
62.750004,64.999107,-39.410122,-0.001677,0.003175,0.080652,289.130463,14.729008,0.806523,-39.410122,294.500488,0.000000
63.110004,65.579994,-39.454605,-0.001669,0.003180,0.080765,291.714386,14.860639,0.807647,-39.454605,294.500488,0.000000
63.470001,65.507393,-39.454605,-0.001669,0.003196,0.081172,291.391449,14.844188,0.811724,-39.454605,294.500488,0.000000
63.830002,64.753700,-39.454605,-0.001669,0.003196,0.081190,288.038849,14.673398,0.811898,-39.454605,294.500488,0.000000
64.190002,65.944176,-39.454605,-0.001651,0.003183,0.080843,293.334351,14.943164,0.808431,-39.454605,294.500488,0.000000
64.550003,65.130913,-39.499084,-0.001656,0.003183,0.080860,289.716766,14.758876,0.808601,-39.499084,294.500488,0.000000
64.910004,65.131294,-39.499084,-0.001647,0.003219,0.081753,289.718475,14.758963,0.817534,-39.499084,294.500488,0.000000
65.270004,64.418205,-39.499084,-0.001651,0.003219,0.081753,286.546478,14.597374,0.817534,-39.499084,294.500488,0.000000
65.630005,66.298683,-39.454605,-0.001643,0.003181,0.080800,294.911285,15.023497,0.807996,-39.454605,294.500488,0.000000
65.990005,65.526756,-39.499084,-0.001630,0.003210,0.081528,291.477570,14.848576,0.815282,-39.499084,294.500488,0.000000
66.350006,64.815147,-39.543564,-0.001643,0.003216,0.081675,288.312164,14.687323,0.816754,-39.543564,294.500488,0.000000
66.710007,66.034294,-39.499084,-0.001613,0.003248,0.082491,293.735199,14.963585,0.824907,-39.499084,294.500488,0.000000
67.070000,65.315239,-39.588047,-0.001625,0.003248,0.082499,290.536682,14.800645,0.824994,-39.588047,294.500488,0.000000
67.430000,65.456367,-39.499084,-0.001613,0.003267,0.082994,291.164459,14.832624,0.829937,-39.499084,294.500488,0.000000
67.790001,64.783867,-39.543564,-0.001625,0.003267,0.082994,288.173035,14.680234,0.829937,-39.543564,294.500488,0.000000
68.150002,66.970070,-39.588047,-0.001630,0.003197,0.081216,297.897736,15.175635,0.812159,-39.588047,294.500488,0.000000
68.510002,66.148979,-39.543564,-0.001600,0.003168,0.080470,294.245361,14.989573,0.804699,-39.543564,294.500488,0.000000
68.870003,65.467918,-39.588047,-0.001587,0.003241,0.082317,291.215851,14.835242,0.823173,-39.588047,294.500488,0.000000
69.230003,65.067986,-39.632526,-0.001600,0.003293,0.083636,289.436859,14.744617,0.836356,-39.632526,294.500488,0.000000
69.590004,65.203163,-39.632526,-0.001587,0.003302,0.083869,290.038147,14.775248,0.838695,-39.632526,294.500488,0.000000
69.950005,65.110817,-39.632526,-0.001604,0.003307,0.083991,289.627380,14.754322,0.839910,-39.632526,294.500488,0.000000
70.310005,65.170387,-39.543564,-0.001578,0.003314,0.084182,289.892365,14.767821,0.841817,-39.543564,294.500488,0.000000
70.670006,65.338707,-39.677010,-0.001591,0.003321,0.084364,290.641083,14.805963,0.843638,-39.677010,294.500488,0.000000
71.030006,65.591179,-39.632526,-0.001574,0.003329,0.084555,291.764130,14.863173,0.845546,-39.632526,294.500488,0.000000
71.390007,65.084007,-39.677010,-0.001587,0.003329,0.084555,289.508118,14.748247,0.845546,-39.677010,294.500488,0.000000
71.750000,64.545555,-39.677010,-0.001595,0.003329,0.084555,287.112976,14.626232,0.845546,-39.677010,294.500488,0.000000
72.110001,66.788719,-39.721489,-0.001574,0.003212,0.081580,297.091064,15.134540,0.815800,-39.721489,294.500488,0.000000
72.470001,66.084190,-39.721489,-0.001578,0.003211,0.081563,293.957153,14.974892,0.815626,-39.721489,294.500488,0.000000
72.830002,65.498451,-39.677010,-0.001561,0.003266,0.082968,291.351654,14.842161,0.829675,-39.677010,294.500488,0.000000
73.190002,65.185661,-39.765972,-0.001548,0.003349,0.085075,289.960297,14.771281,0.850750,-39.765972,294.500488,0.000000
73.550003,64.941383,-39.677010,-0.001565,0.003359,0.085327,288.873688,14.715928,0.853267,-39.677010,294.500488,0.000000
73.910004,65.132408,-39.765972,-0.001552,0.003363,0.085413,289.723419,14.759214,0.854133,-39.765972,294.500488,0.000000
74.270004,64.999840,-39.721489,-0.001552,0.003367,0.085526,289.133728,14.729175,0.855261,-39.721489,294.500488,0.000000
74.630005,64.971169,-39.721489,-0.001548,0.003372,0.085647,289.006195,14.722678,0.856473,-39.721489,294.500488,0.000000
74.990005,64.925377,-39.854931,-0.001556,0.003381,0.085873,288.802490,14.712301,0.858728,-39.854931,294.500488,0.000000
75.350006,65.135017,-39.765972,-0.001552,0.003383,0.085916,289.735016,14.759806,0.859164,-39.765972,294.500488,0.000000
75.710007,65.586708,-39.810452,-0.001552,0.003392,0.086159,291.744263,14.862160,0.861590,-39.810452,294.500488,0.000000
76.070007,65.216560,-39.854931,-0.001556,0.003392,0.086159,290.097748,14.778284,0.861590,-39.854931,294.500488,0.000000
76.430000,65.265724,-39.854931,-0.001539,0.003398,0.086315,290.316437,14.789425,0.863153,-39.854931,294.500488,0.000000
76.790001,65.227364,-39.899414,-0.001561,0.003406,0.086523,290.145813,14.780732,0.865231,-39.899414,294.500488,0.000000
77.150002,65.204277,-39.810452,-0.001552,0.003406,0.086515,290.043121,14.775500,0.865148,-39.810452,294.500488,0.000000
77.510002,65.151405,-39.899414,-0.001535,0.003412,0.086662,289.807922,14.763519,0.866620,-39.899414,294.500488,0.000000
77.870003,64.895210,-39.854931,-0.001535,0.003412,0.086662,288.668304,14.705465,0.866620,-39.854931,294.500488,0.000000
78.230003,64.914940,-39.854931,-0.001535,0.003417,0.086792,288.756073,14.709935,0.867922,-39.854931,294.500488,0.000000
78.590004,65.692451,-39.854931,-0.001531,0.003429,0.087096,292.214630,14.886122,0.870957,-39.854931,294.500488,0.000000
78.950005,65.401268,-39.899414,-0.001522,0.003429,0.087096,290.919373,14.820139,0.870957,-39.899414,294.500488,0.000000
79.310005,65.029640,-39.988377,-0.001526,0.003429,0.087096,289.266296,14.735928,0.870957,-39.988377,294.500488,0.000000
79.670006,64.596565,-39.854931,-0.001526,0.003429,0.087096,287.339874,14.637791,0.870957,-39.854931,294.500488,0.000000
80.030006,66.259575,-39.943893,-0.001509,0.003413,0.086679,294.737305,15.014634,0.866794,-39.943893,294.500488,0.000000
80.390007,65.850349,-39.943893,-0.001522,0.003413,0.086688,292.916992,14.921903,0.866881,-39.943893,294.500488,0.000000
80.750008,65.345039,-39.943893,-0.001513,0.003417,0.086792,290.669250,14.807397,0.867922,-39.943893,294.500488,0.000000
81.110001,64.982719,-39.988377,-0.001505,0.003432,0.087174,289.057587,14.725295,0.871737,-39.988377,294.500488,0.000000
81.470001,65.336464,-39.899414,-0.001496,0.003453,0.087712,290.631104,14.805454,0.877115,-39.899414,294.500488,0.000000
81.830002,64.976021,-39.988377,-0.001505,0.003453,0.087712,289.027771,14.723777,0.877115,-39.988377,294.500488,0.000000
82.190002,64.598793,-40.032856,-0.001513,0.003453,0.087712,287.349792,14.638296,0.877115,-40.032856,294.500488,0.000000
82.550003,66.302773,-39.943893,-0.001505,0.003435,0.087252,294.929474,15.024424,0.872517,-39.943893,294.500488,0.000000
82.910004,65.855934,-40.121819,-0.001496,0.003435,0.087260,292.941833,14.923168,0.872604,-40.121819,294.500488,0.000000
83.270004,65.498085,-40.032856,-0.001487,0.003436,0.087269,291.350037,14.842078,0.872691,-40.032856,294.500488,0.000000
83.630005,65.235924,-40.077335,-0.001492,0.003464,0.087998,290.183868,14.782672,0.879977,-40.077335,294.500488,0.000000
83.990005,65.126076,-40.032856,-0.001483,0.003475,0.088275,289.695251,14.757779,0.882751,-40.032856,294.500488,0.000000
84.350006,65.071709,-40.032856,-0.001492,0.003478,0.088353,289.453430,14.745460,0.883531,-40.032856,294.500488,0.000000
84.710007,64.972282,-40.121819,-0.001487,0.003481,0.088422,289.011139,14.722929,0.884223,-40.121819,294.500488,0.000000
85.070007,65.058678,-40.077335,-0.001475,0.003486,0.088544,289.395447,14.742507,0.885438,-40.077335,294.500488,0.000000
85.430000,65.105965,-40.121819,-0.001492,0.003491,0.088665,289.605804,14.753222,0.886653,-40.121819,294.500488,0.000000
85.790001,64.974144,-40.121819,-0.001479,0.003492,0.088700,289.019440,14.723351,0.887002,-40.121819,294.500488,0.000000
86.150002,64.991280,-40.210781,-0.001483,0.003496,0.088796,289.095642,14.727234,0.887955,-40.210781,294.500488,0.000000
86.510002,65.117516,-40.166298,-0.001487,0.003500,0.088900,289.657166,14.755840,0.888996,-40.166298,294.500488,0.000000
86.870003,65.273170,-40.077335,-0.001475,0.003505,0.089029,290.349548,14.791112,0.890294,-40.077335,294.500488,0.000000
87.230003,65.072456,-40.255260,-0.001470,0.003505,0.089038,289.456757,14.745629,0.890381,-40.255260,294.500488,0.000000
87.590004,65.026649,-40.166298,-0.001483,0.003508,0.089107,289.252991,14.735250,0.891074,-40.166298,294.500488,0.000000
87.950005,65.698036,-40.255260,-0.001470,0.003521,0.089428,292.239471,14.887387,0.894284,-40.255260,294.500488,0.000000
88.310005,65.576653,-40.255260,-0.001457,0.003519,0.089385,291.699524,14.859881,0.893852,-40.255260,294.500488,0.000000
88.670006,65.313377,-40.166298,-0.001462,0.003519,0.089385,290.528412,14.800222,0.893852,-40.166298,294.500488,0.000000
89.030006,65.040428,-40.255260,-0.001475,0.003519,0.089385,289.314270,14.738372,0.893852,-40.255260,294.500488,0.000000
89.390007,64.786842,-40.210781,-0.001475,0.003519,0.089394,288.186279,14.680908,0.893939,-40.210781,294.500488,0.000000
89.750008,64.523201,-40.299740,-0.001470,0.003519,0.089394,287.013519,14.621166,0.893939,-40.299740,294.500488,0.000000
90.110001,66.040993,-40.255260,-0.001475,0.003531,0.089697,293.765015,14.965103,0.896975,-40.255260,294.500488,0.000000
90.470001,65.760979,-40.255260,-0.001466,0.003531,0.089697,292.519440,14.901651,0.896975,-40.255260,294.500488,0.000000
90.830002,65.441109,-40.388702,-0.001457,0.003531,0.089697,291.096588,14.829167,0.896975,-40.388702,294.500488,0.000000
91.190002,65.125710,-40.299740,-0.001466,0.003531,0.089697,289.693634,14.757697,0.896975,-40.299740,294.500488,0.000000
91.550003,64.864677,-40.344223,-0.001457,0.003538,0.089853,288.532501,14.698546,0.898534,-40.344223,294.500488,0.000000
91.910004,64.800255,-40.344223,-0.001457,0.003538,0.089853,288.245941,14.683948,0.898534,-40.344223,294.500488,0.000000
92.270004,64.848656,-40.388702,-0.001444,0.003542,0.089966,288.461212,14.694915,0.899662,-40.388702,294.500488,0.000000
92.630005,64.687050,-40.299740,-0.001444,0.003542,0.089966,287.742371,14.658296,0.899662,-40.299740,294.500488,0.000000
92.990005,65.663414,-40.344223,-0.001449,0.003555,0.090296,292.085449,14.879542,0.902959,-40.344223,294.500488,0.000000
93.350006,65.537178,-40.433186,-0.001444,0.003555,0.090296,291.523926,14.850937,0.902959,-40.433186,294.500488,0.000000
93.710007,65.313759,-40.344223,-0.001440,0.003555,0.090296,290.530121,14.800309,0.902959,-40.344223,294.500488,0.000000
94.070007,65.082146,-40.388702,-0.001436,0.003555,0.090296,289.499847,14.747825,0.902959,-40.388702,294.500488,0.000000
94.430008,64.869148,-40.433186,-0.001440,0.003555,0.090296,288.552368,14.699559,0.902959,-40.433186,294.500488,0.000000
94.790001,64.645714,-40.388702,-0.001444,0.003555,0.090296,287.558502,14.648929,0.902959,-40.388702,294.500488,0.000000
95.150002,64.426765,-40.477665,-0.001436,0.003555,0.090304,286.584564,14.599314,0.903042,-40.477665,294.500488,0.000000
95.510002,64.197014,-40.433186,-0.001440,0.003556,0.090313,285.562592,14.547251,0.903129,-40.433186,294.500488,0.000000
95.870003,66.701591,-40.433186,-0.001440,0.003472,0.088180,296.703491,15.114797,0.881797,-40.433186,294.500488,0.000000
96.230003,66.419701,-40.477665,-0.001436,0.003472,0.088188,295.449585,15.050920,0.881884,-40.477665,294.500488,0.000000
96.590004,66.148979,-40.477665,-0.001431,0.003472,0.088188,294.245361,14.989573,0.881884,-40.477665,294.500488,0.000000
96.950005,65.901360,-40.522148,-0.001427,0.003472,0.088197,293.143890,14.933461,0.881971,-40.522148,294.500488,0.000000
97.310005,65.654472,-40.477665,-0.001423,0.003514,0.089264,292.045685,14.877517,0.892637,-40.477665,294.500488,0.000000
97.670006,65.428825,-40.522148,-0.001418,0.003536,0.089819,291.041962,14.826384,0.898186,-40.522148,294.500488,0.000000
98.030006,65.222145,-40.477665,-0.001401,0.003544,0.090009,290.122589,14.779550,0.900093,-40.477665,294.500488,0.000000
98.390007,65.051598,-40.477665,-0.001401,0.003554,0.090278,289.363953,14.740903,0.902785,-40.477665,294.500488,0.000000
98.750008,65.069481,-40.566628,-0.001418,0.003581,0.090955,289.443512,14.744955,0.909548,-40.566628,294.500488,0.000000
99.110008,65.159599,-40.522148,-0.001410,0.003582,0.090972,289.844360,14.765376,0.909722,-40.522148,294.500488,0.000000
99.470001,65.267586,-40.566628,-0.001401,0.003586,0.091085,290.324707,14.789846,0.910850,-40.566628,294.500488,0.000000
99.830002,65.108955,-40.566628,-0.001414,0.003586,0.091085,289.619110,14.753900,0.910850,-40.566628,294.500488,0.000000
100.190002,64.939156,-40.522148,-0.001406,0.003586,0.091094,288.863800,14.715423,0.910937,-40.522148,294.500488,0.000000
100.550003,64.943245,-40.611107,-0.001393,0.003589,0.091163,288.881989,14.716350,0.911630,-40.611107,294.500488,0.000000
100.910004,65.575539,-40.611107,-0.001418,0.003599,0.091414,291.694550,14.859629,0.914143,-40.611107,294.500488,0.000000
101.270004,65.509254,-40.611107,-0.001397,0.003599,0.091414,291.399719,14.844608,0.914143,-40.611107,294.500488,0.000000
101.630005,65.339073,-40.655590,-0.001401,0.003599,0.091414,290.642700,14.806046,0.914143,-40.655590,294.500488,0.000000
101.990005,65.210243,-40.611107,-0.001414,0.003599,0.091414,290.069641,14.776852,0.914143,-40.611107,294.500488,0.000000
102.350006,65.049736,-40.744553,-0.001397,0.003600,0.091432,289.355682,14.740480,0.914317,-40.744553,294.500488,0.000000
102.710007,64.925743,-40.611107,-0.001406,0.003600,0.091432,288.804138,14.712383,0.914317,-40.611107,294.500488,0.000000
103.070007,65.462334,-40.700069,-0.001393,0.003608,0.091631,291.191010,14.833977,0.916312,-40.700069,294.500488,0.000000
103.430008,65.322319,-40.700069,-0.001406,0.003608,0.091631,290.568176,14.802249,0.916312,-40.700069,294.500488,0.000000
103.790009,65.195717,-40.655590,-0.001406,0.003608,0.091631,290.005035,14.773561,0.916312,-40.655590,294.500488,0.000000
104.150002,65.021812,-40.744553,-0.001401,0.003608,0.091631,289.231476,14.734154,0.916312,-40.744553,294.500488,0.000000
104.510002,64.855736,-40.700069,-0.001397,0.003608,0.091631,288.492706,14.696520,0.916312,-40.700069,294.500488,0.000000
104.870003,64.699715,-40.744553,-0.001401,0.003608,0.091631,287.798706,14.661165,0.916312,-40.744553,294.500488,0.000000
105.230003,66.090157,-40.744553,-0.001401,0.003617,0.091865,293.983704,14.976244,0.918655,-40.744553,294.500488,0.000000
105.590004,65.877159,-40.744553,-0.001388,0.003616,0.091848,293.036224,14.927978,0.918480,-40.744553,294.500488,0.000000
105.950005,65.739372,-40.789032,-0.001397,0.003616,0.091848,292.423340,14.896754,0.918480,-40.789032,294.500488,0.000000
106.310005,65.531960,-40.744553,-0.001397,0.003616,0.091848,291.500702,14.849754,0.918480,-40.744553,294.500488,0.000000
106.670006,65.352104,-40.833511,-0.001388,0.003616,0.091848,290.700684,14.808999,0.918480,-40.833511,294.500488,0.000000
107.030006,65.173378,-40.744553,-0.001401,0.003616,0.091857,289.905670,14.768499,0.918568,-40.744553,294.500488,0.000000
107.390007,65.008034,-40.789032,-0.001401,0.003616,0.091857,289.170166,14.731030,0.918568,-40.789032,294.500488,0.000000
107.750008,65.245979,-40.789032,-0.001397,0.003626,0.092091,290.228607,14.784950,0.920907,-40.789032,294.500488,0.000000
108.110008,65.139854,-40.789032,-0.001393,0.003626,0.092091,289.756531,14.760902,0.920907,-40.789032,294.500488,0.000000
108.470009,65.096657,-40.789032,-0.001397,0.003628,0.092152,289.564392,14.751113,0.921516,-40.789032,294.500488,0.000000
108.830002,65.066124,-40.833511,-0.001393,0.003628,0.092160,289.428589,14.744194,0.921603,-40.833511,294.500488,0.000000
109.190002,65.279121,-40.789032,-0.001388,0.003632,0.092264,290.376038,14.792460,0.922644,-40.789032,294.500488,0.000000
109.550003,65.203911,-40.877995,-0.001397,0.003632,0.092264,290.041473,14.775417,0.922644,-40.877995,294.500488,0.000000
109.910004,65.154015,-40.877995,-0.001406,0.003634,0.092316,289.819519,14.764111,0.923162,-40.877995,294.500488,0.000000
110.270004,65.092567,-40.966957,-0.001397,0.003634,0.092316,289.546204,14.750187,0.923162,-40.966957,294.500488,0.000000
110.630005,65.116402,-40.833511,-0.001406,0.003637,0.092377,289.652222,14.755588,0.923772,-40.833511,294.500488,0.000000
110.990005,65.041557,-40.966957,-0.001384,0.003637,0.092377,289.319305,14.738627,0.923772,-40.966957,294.500488,0.000000
111.350006,64.945473,-40.877995,-0.001393,0.003641,0.092473,288.891876,14.716855,0.924726,-40.877995,294.500488,0.000000
111.710007,65.357323,-40.922474,-0.001388,0.003643,0.092542,290.723877,14.810181,0.925418,-40.922474,294.500488,0.000000
112.070007,65.274651,-40.966957,-0.001393,0.003643,0.092542,290.356140,14.791448,0.925418,-40.966957,294.500488,0.000000
112.430008,65.186409,-40.966957,-0.001367,0.003643,0.092542,289.963623,14.771451,0.925418,-40.966957,294.500488,0.000000
112.790009,65.052345,-41.011436,-0.001375,0.003643,0.092542,289.367279,14.741073,0.925418,-41.011436,294.500488,0.000000
113.150009,64.960747,-40.966957,-0.001388,0.003643,0.092542,288.959839,14.720315,0.925418,-40.966957,294.500488,0.000000
113.510002,65.536430,-41.011436,-0.001388,0.003652,0.092750,291.520599,14.850768,0.927500,-41.011436,294.500488,0.000000
113.870003,65.461952,-41.011436,-0.001384,0.003652,0.092750,291.189301,14.833890,0.927500,-41.011436,294.500488,0.000000
114.230003,65.344292,-41.011436,-0.001375,0.003652,0.092750,290.665924,14.807228,0.927500,-41.011436,1681.640991,0.000000
114.590004,65.132790,-41.011436,-0.001393,0.003644,0.092568,289.725128,14.759300,0.925679,-41.011436,0.092368,0.000000
114.950005,64.899300,-41.055920,-0.001384,0.003624,0.092039,288.686493,14.706392,0.920388,-41.055920,0.091770,0.000000
115.310005,64.727272,-41.055920,-0.001380,0.003608,0.091649,287.921295,14.667409,0.916486,-41.055920,0.091172,0.000000
115.670006,64.543694,-41.100399,-0.001384,0.003585,0.091059,287.104675,14.625810,0.910589,-41.100399,0.090573,0.000000
116.030006,64.409264,-41.100399,-0.001371,0.003564,0.090521,286.506714,14.595347,0.905211,-41.100399,0.089975,0.000000
116.390007,64.310219,-41.100399,-0.001362,0.003545,0.090053,286.066132,14.572904,0.900529,-41.100399,0.089368,0.000000
116.750008,64.124763,-41.144878,-0.001358,0.003513,0.089238,285.241180,14.530879,0.892376,-41.144878,0.088769,0.000000
117.110008,64.017159,-41.144878,-0.001362,0.003492,0.088709,284.762543,14.506495,0.887089,-41.144878,0.088171,0.000000
117.470009,63.901726,-41.144878,-0.001362,0.003473,0.088214,284.249084,14.480338,0.882142,-41.144878,0.087573,0.000000
117.830002,63.754265,-41.100399,-0.001345,0.003447,0.087564,283.593140,14.446922,0.875639,-41.100399,0.086974,0.000000
118.190002,63.301460,-41.189362,-0.001350,0.003424,0.086974,281.578949,14.344316,0.869742,-41.189362,0.086367,0.000000
118.550003,62.641243,-41.189362,-0.001362,0.003403,0.086428,278.642151,14.194709,0.864277,-41.189362,0.085769,0.000000
118.910004,61.829094,-41.189362,-0.001332,0.003385,0.085977,275.029541,14.010674,0.859769,-41.189362,0.085170,0.000000
119.270004,60.613297,-41.189362,-0.001328,0.003362,0.085396,269.621399,13.735169,0.853959,-41.189362,0.084572,0.000000
119.630005,59.341644,-41.189362,-0.001324,0.003340,0.084841,263.964813,13.447009,0.848407,-41.189362,0.083974,0.000000
119.990005,58.006691,-41.189362,-0.001315,0.003318,0.084277,258.026642,13.144504,0.842771,-41.189362,0.083366,0.000000
120.350006,56.412567,-41.233841,-0.001302,0.003294,0.083670,250.935638,12.783271,0.836700,-41.233841,0.082768,0.000000
120.710007,54.440483,-41.233841,-0.001289,0.003271,0.083080,242.163361,12.336390,0.830803,-41.233841,0.082170,0.000000
121.070007,52.700012,-41.278324,-0.001289,0.003251,0.082577,234.421356,11.941994,0.825773,-41.278324,0.081571,0.000000
121.430008,50.262459,-41.278324,-0.001302,0.003224,0.081892,223.578583,11.389636,0.818923,-41.278324,0.080973,0.000000
121.790009,48.576729,-41.233841,-0.001268,0.003205,0.081415,216.080078,11.007645,0.814154,-41.233841,0.080366,0.000000
122.150009,46.556236,-41.278324,-0.001289,0.003187,0.080947,207.092484,10.549793,0.809472,-41.278324,0.079767,0.000000
122.510002,43.561615,-41.322803,-0.001285,0.003155,0.080149,193.771744,9.871203,0.801493,-41.322803,0.079169,0.000000
122.870003,40.979218,-41.367283,-0.001293,0.003132,0.079559,182.284668,9.286023,0.795592,-41.367283,0.078571,0.000000
123.230003,38.801956,-41.233841,-0.001293,0.003113,0.079082,172.599716,8.792648,0.790824,-41.233841,0.077972,0.000000
123.590004,36.627296,-41.322803,-0.001298,0.003094,0.078597,162.926346,8.299864,0.785968,-41.322803,0.077374,0.000000
123.950005,33.841583,-41.278324,-0.001298,0.003066,0.077868,150.534882,7.668612,0.778682,-41.278324,0.076767,0.000000
124.310005,30.763550,-41.367283,-0.001293,0.003039,0.077192,136.843109,6.971120,0.771918,-41.367283,0.076169,0.000000
124.670006,28.275726,-41.322803,-0.001298,0.003015,0.076576,125.776711,6.407371,0.765760,-41.322803,0.075570,0.000000
125.030006,25.902969,-41.367283,-0.001281,0.002994,0.076039,115.222160,5.869697,0.760385,-41.367283,0.074972,0.000000
125.390007,23.673950,-41.367283,-0.001298,0.002967,0.075371,105.306992,5.364594,0.753709,-41.367283,0.074374,0.000000
125.750008,20.996216,-41.367283,-0.001293,0.002949,0.074911,93.395836,4.757811,0.749110,-41.367283,0.073766,0.000000
126.110008,18.171028,-41.322803,-0.001289,0.002922,0.074209,80.828773,4.117614,0.742085,-41.322803,0.073168,0.000000
126.470009,16.270065,-41.411766,-0.001293,0.002901,0.073680,72.372864,3.686850,0.736798,-41.411766,0.072570,0.000000
126.830009,13.307846,-41.411766,-0.001285,0.002875,0.073020,59.196255,3.015601,0.730205,-41.411766,0.071971,0.000000
127.190002,11.336502,-41.456245,-0.001289,0.002856,0.072552,50.427280,2.568888,0.725523,-41.456245,0.071373,0.000000
127.550003,8.185120,-41.367283,-0.001289,0.002824,0.071737,36.409229,1.854775,0.717370,-41.367283,0.070766,0.000000
127.910004,6.764519,-41.456245,-0.001293,0.002809,0.071338,30.090082,1.532862,0.713381,-41.456245,0.070167,0.000000
128.270004,4.798759,-41.456245,-0.001293,0.002789,0.070852,21.345947,1.087415,0.708525,-41.456245,0.069569,0.000000
128.630005,1.785149,-41.411766,-0.001289,0.002755,0.069977,7.940738,0.404520,0.699767,-41.411766,0.068971,0.000000
128.990005,0.164589,-41.500729,-0.001293,0.002736,0.069491,0.732128,0.037296,0.694911,-41.500729,0.068372,0.000000
129.350006,-1.517048,-41.500729,-0.001306,0.002714,0.068936,-6.748166,-0.343768,0.689358,-41.500729,0.067765,0.000000
129.710007,-3.504398,-41.545208,-0.001285,0.002689,0.068294,-15.588343,-0.794108,0.682943,-41.545208,0.067167,0.000000
130.070007,-0.271461,-41.545208,-0.001281,0.002664,0.067661,-1.207521,-0.061514,0.676611,-41.545208,0.066568,0.000000
130.430008,-0.142990,-41.456245,-0.001268,0.002637,0.066967,-0.636052,-0.032402,0.669673,-41.456245,0.065970,0.000000
130.790009,-0.096817,-41.545208,-0.001268,0.002613,0.066378,-0.430664,-0.021939,0.663776,-41.545208,0.065372,0.000000
131.150009,-0.111343,-41.500729,-0.001272,0.002587,0.065710,-0.495280,-0.025231,0.657099,-41.500729,0.064773,0.000000
131.510010,-0.124374,-41.545208,-0.001263,0.002569,0.065250,-0.553245,-0.028184,0.652501,-41.545208,0.064166,0.000000
131.870010,-0.151184,-41.634171,-0.001263,0.002541,0.064539,-0.672500,-0.034259,0.645393,-41.634171,0.063568,0.000000
132.230011,-0.144485,-41.545208,-0.001285,0.002514,0.063854,-0.642703,-0.032741,0.638538,-41.545208,0.062969,0.000000
132.590012,-0.164215,-41.589687,-0.001302,0.002491,0.063264,-0.730465,-0.037212,0.632641,-41.589687,0.062371,0.000000
132.950012,-0.223427,-41.589687,-0.001324,0.002470,0.062727,-0.993852,-0.050629,0.627267,-41.589687,0.061773,0.000000
133.310013,-0.238693,-41.634171,-0.001354,0.002447,0.062146,-1.061761,-0.054089,0.621457,-41.634171,0.061165,0.000000
133.670013,-0.237579,-41.678650,-0.001380,0.002426,0.061625,-1.056806,-0.053836,0.616253,-41.678650,0.060567,0.000000
134.029999,-0.215607,-41.589687,-0.001397,0.002406,0.061122,-0.959066,-0.048857,0.611223,-41.589687,0.059969,0.000000
134.389999,-0.214859,-41.678650,-0.001414,0.002373,0.060272,-0.955741,-0.048688,0.602722,-41.678650,0.059370,0.000000
134.750000,-0.246887,-41.634171,-0.001440,0.002353,0.059761,-1.098209,-0.055945,0.597608,-41.634171,0.058772,0.000000
135.110001,-0.238319,-41.678650,-0.001466,0.002331,0.059197,-1.060098,-0.054004,0.591969,-41.678650,0.058165,0.000000
135.470001,-0.227150,-41.723133,-0.001505,0.002304,0.058512,-1.010414,-0.051473,0.585118,-41.723133,0.057567,0.000000
135.830002,-0.227150,-41.634171,-0.001526,0.002285,0.058035,-1.010414,-0.051473,0.580349,-41.634171,0.056968,0.000000
136.190002,-0.237206,-41.678650,-0.001539,0.002266,0.057549,-1.055143,-0.053752,0.575493,-41.678650,0.056370,0.000000
136.550003,-0.279655,-41.678650,-0.001556,0.002235,0.056769,-1.243970,-0.063371,0.567689,-41.678650,0.055772,0.000000
136.910004,-0.271835,-41.678650,-0.001600,0.002212,0.056196,-1.209184,-0.061599,0.561962,-41.678650,0.055164,0.000000
137.270004,-0.253960,-41.767612,-0.001617,0.002193,0.055693,-1.129669,-0.057548,0.556932,-41.767612,0.054566,0.000000
137.630005,-0.256943,-41.767612,-0.001630,0.002165,0.054991,-1.142938,-0.058224,0.549911,-41.767612,0.053968,0.000000
137.990005,-0.269600,-41.723133,-0.001651,0.002145,0.054479,-1.199240,-0.061092,0.544794,-41.723133,0.053369,0.000000
138.350006,-0.267738,-41.723133,-0.001690,0.002115,0.053716,-1.190960,-0.060670,0.537160,-41.723133,0.052771,0.000000
138.710007,-0.274811,-41.723133,-0.001712,0.002094,0.053179,-1.222420,-0.062273,0.531785,-41.723133,0.052173,0.000000
139.070007,-0.275932,-41.856575,-0.001733,0.002071,0.052606,-1.227408,-0.062527,0.526059,-41.856575,0.051565,0.000000
139.430008,-0.256943,-41.812096,-0.001746,0.002045,0.051956,-1.142938,-0.058224,0.519556,-41.812096,0.050967,0.000000
139.790009,-0.280396,-41.812096,-0.001781,0.002021,0.051331,-1.247262,-0.063539,0.513311,-41.812096,0.050369,0.000000
140.150009,-0.287102,-41.856575,-0.001798,0.001999,0.050768,-1.277092,-0.065058,0.507676,-41.856575,0.049770,0.000000
140.510010,-0.298271,-41.856575,-0.001824,0.001977,0.050204,-1.326777,-0.067589,0.502040,-41.856575,0.049172,0.000000
140.870010,-0.254707,-41.856575,-0.001832,0.001959,0.049770,-1.132995,-0.057718,0.497702,-41.856575,0.048565,0.000000
141.230011,-0.254333,-41.856575,-0.001876,0.001936,0.049181,-1.131332,-0.057633,0.491805,-41.856575,0.047966,0.000000
141.590012,-0.248001,-41.856575,-0.001897,0.001908,0.048461,-1.103164,-0.056198,0.484607,-41.856575,0.047368,0.000000
141.950012,-0.282257,-41.856575,-0.001914,0.001881,0.047784,-1.255542,-0.063960,0.477843,-41.856575,0.046770,0.000000
142.310013,-0.277420,-41.901054,-0.001962,0.001856,0.047151,-1.234026,-0.062864,0.471511,-41.901054,0.046171,0.000000
142.670013,-0.271461,-41.945538,-0.001992,0.001826,0.046388,-1.207521,-0.061514,0.463881,-41.945538,0.045564,0.000000
143.030014,-0.265129,-41.901054,-0.001988,0.001810,0.045980,-1.179353,-0.060079,0.459804,-41.901054,0.044966,0.000000
143.389999,-0.266251,-41.990017,-0.002005,0.001794,0.045564,-1.184342,-0.060333,0.455641,-41.990017,0.044367,0.000000
143.750000,-0.268852,-41.901054,-0.002044,0.001762,0.044766,-1.195915,-0.060923,0.447662,-41.901054,0.043769,0.000000
144.110001,-0.240929,-41.990017,-0.002074,0.001735,0.044081,-1.071704,-0.054595,0.440812,-41.990017,0.043171,0.000000
144.470001,-0.262154,-42.034500,-0.002100,0.001715,0.043561,-1.166118,-0.059405,0.435607,-42.034500,0.042563,0.000000
144.830002,-0.245766,-41.990017,-0.002126,0.001688,0.042884,-1.093220,-0.055691,0.428844,-41.990017,0.041965,0.000000
145.190002,-0.293060,-42.034500,-0.002130,0.001682,0.042711,-1.303597,-0.066408,0.427110,-42.034500,0.041367,0.000000
145.550003,-0.277046,-42.034500,-0.002173,0.001642,0.041705,-1.232363,-0.062780,0.417050,-42.034500,0.040769,0.000000
145.910004,-0.258430,-42.034500,-0.002199,0.001617,0.041072,-1.149556,-0.058561,0.410718,-42.034500,0.040170,0.000000
146.270004,-0.255821,-41.990017,-0.002225,0.001595,0.040526,-1.137950,-0.057970,0.405256,-41.990017,0.039572,0.000000
146.630005,-0.228264,-41.990017,-0.002246,0.001569,0.039841,-1.015368,-0.051725,0.398406,-41.990017,0.038965,0.000000
146.990005,-0.256195,-42.078979,-0.002272,0.001551,0.039389,-1.139613,-0.058055,0.393894,-42.078979,0.038366,0.000000
147.350006,-0.246513,-42.034500,-0.002289,0.001524,0.038704,-1.096546,-0.055861,0.387043,-42.034500,0.037768,0.000000
147.710007,-0.257683,-42.123459,-0.002311,0.001503,0.038184,-1.146230,-0.058392,0.381839,-42.123459,0.037170,0.000000
148.070007,-0.243530,-42.034500,-0.002341,0.001478,0.037542,-1.083277,-0.055185,0.375424,-42.034500,0.036571,0.000000
148.430008,-0.232735,-42.123459,-0.002341,0.001458,0.037031,-1.035256,-0.052738,0.370307,-42.123459,0.035964,0.000000
148.790009,-0.232361,-42.123459,-0.002397,0.001434,0.036415,-1.033593,-0.052654,0.364149,-42.123459,0.035366,0.000000
149.150009,-0.218582,-42.034500,-0.002419,0.001414,0.035903,-0.972302,-0.049531,0.359031,-42.034500,0.034767,0.000000
149.510010,-0.223053,-42.123459,-0.002436,0.001391,0.035331,-0.992189,-0.050545,0.353309,-42.123459,0.034169,0.000000
149.870010,-0.231987,-42.123459,-0.002466,0.001358,0.034481,-1.031930,-0.052569,0.344811,-42.123459,0.033571,0.000000
150.230011,-0.226036,-42.167942,-0.002462,0.001338,0.033987,-1.005459,-0.051221,0.339868,-42.167942,0.032963,0.000000
150.400009,-0.242043,-42.123459,-0.002501,0.001334,0.033891,-1.076659,-0.054848,0.338915,-42.123459,0.033805,0.000000