File: Data/AD Peeled Punched/AD Membrane Peeled Punched Multi_1_08122024_185408.csv
Time (sec),S:Load (lbs),S:HL1 (DIM),S:LVDT (in),S:Position (in),Ch:Position (mm),Ch:Load (N),Ch:Stress (MPa),Ch:Strain (mm/mm),Ch:HL1 (DIM),Set Point (),Cycles ()
0.110000,0.001122,-274.936768,-0.004786,-0.004731,-0.120172,0.004989,0.000254,-1.201715,-274.936768,-0.119972,0.000000
0.600000,-0.037605,-274.936768,-0.004781,-0.004628,-0.117552,-0.167277,-0.008521,-1.175524,-274.936768,-0.116763,0.000000
1.090000,0.030533,-274.981232,-0.004549,-0.004321,-0.109765,0.135817,0.006919,-1.097646,-274.981232,-0.108594,0.000000
1.580000,-0.017502,-275.114685,-0.004230,-0.004004,-0.101691,-0.077852,-0.003966,-1.016907,-275.114685,-0.100425,0.000000
2.070000,0.014153,-275.070190,-0.003889,-0.003686,-0.093617,0.062954,0.003207,-0.936171,-275.070190,-0.092273,0.000000
2.560000,-0.032394,-275.114685,-0.003557,-0.003361,-0.085361,-0.144098,-0.007341,-0.853611,-275.114685,-0.084103,0.000000
3.050000,-0.004471,-275.248138,-0.003225,-0.003034,-0.077070,-0.019887,-0.001013,-0.770703,-275.248138,-0.075934,0.000000
3.540000,0.005211,-275.159149,-0.002902,-0.002717,-0.069022,0.023179,0.001181,-0.690225,-275.159149,-0.067782,0.000000
4.030000,0.061440,-275.248138,-0.002583,-0.002403,-0.061027,0.273297,0.013922,-0.610265,-275.248138,-0.059613,0.000000
4.520000,0.081924,-275.292603,-0.002242,-0.002076,-0.052719,0.364418,0.018564,-0.527187,-275.292603,-0.051461,0.000000
5.010000,0.336250,-275.292603,-0.001888,-0.001746,-0.044341,1.495716,0.076195,-0.443412,-275.292603,-0.043292,0.000000
5.500000,0.598778,-275.426056,-0.001750,-0.000007,-0.000182,2.663496,0.135685,-0.001821,-275.426056,-0.000034,0.000000
5.990000,0.576431,-275.381561,-0.001763,-0.000007,-0.000182,2.564094,0.130621,-0.001821,-275.381561,0.000442,0.000000
6.480000,0.540314,-275.470520,-0.001759,-0.000007,-0.000173,2.403435,0.122437,-0.001733,-275.470520,0.001258,0.000000
6.970000,0.787567,-275.426056,-0.001716,0.000039,0.000980,3.503273,0.178465,0.009803,-275.426056,0.002073,0.000000
7.460001,1.057541,-275.515015,-0.001677,0.000077,0.001951,4.704177,0.239642,0.019515,-275.515015,0.002888,0.000000
7.950000,1.289902,-275.515015,-0.001638,0.000111,0.002819,5.737770,0.292296,0.028186,-275.515015,0.003712,0.000000
8.440001,1.489861,-275.603973,-0.001621,0.000142,0.003608,6.627231,0.337607,0.036078,-275.603973,0.004527,0.000000
8.930000,1.696159,-275.692932,-0.001587,0.000171,0.004345,7.544894,0.384355,0.043451,-275.692932,0.005342,0.000000
9.420000,2.034645,-275.603973,-0.001544,0.000206,0.005238,9.050553,0.461057,0.052383,-275.603973,0.006158,0.000000
9.910001,2.441650,-275.737427,-0.001509,0.000238,0.006054,10.861003,0.553286,0.060536,-275.737427,0.006973,0.000000
10.400001,2.815880,-275.781891,-0.001487,0.000273,0.006947,12.525659,0.638087,0.069468,-275.781891,0.007788,0.000000
10.890000,3.113411,-275.781891,-0.001466,0.000297,0.007536,13.849144,0.705509,0.075365,-275.781891,0.008612,0.000000
11.380000,3.678665,-275.826385,-0.001449,0.000329,0.008369,16.363520,0.833597,0.083688,-275.826385,0.009427,0.000000
11.870001,4.439796,-275.826385,-0.001410,0.000366,0.009306,19.749201,1.006072,0.093055,-275.826385,0.010242,0.000000
12.360001,4.942131,-275.915344,-0.001393,0.000398,0.010103,21.983696,1.119903,0.101034,-275.915344,0.011057,0.000000
12.850000,5.536064,-275.915344,-0.001350,0.000425,0.010806,24.625643,1.254490,0.108059,-275.915344,0.011872,0.000000
13.340001,6.582054,-275.959808,-0.001332,0.000462,0.011725,29.278439,1.491515,0.117252,-275.959808,0.012688,0.000000
13.830001,7.135033,-276.093262,-0.001315,0.000486,0.012349,31.738211,1.616822,0.123494,-276.093262,0.013512,0.000000
14.320001,8.152725,-276.048767,-0.001289,0.000521,0.013243,36.265133,1.847434,0.132426,-276.048767,0.014327,0.000000
14.810000,9.052750,-276.182220,-0.001263,0.000549,0.013954,40.268642,2.051382,0.139538,-276.182220,0.015142,0.000000
15.300001,10.385094,-276.137756,-0.001224,0.000589,0.014960,46.195206,2.353296,0.149598,-276.137756,0.015957,0.000000
15.790001,11.394600,-276.137756,-0.001216,0.000619,0.015732,50.685711,2.582053,0.157315,-276.137756,0.016772,0.000000
16.280001,12.812218,-276.182220,-0.001194,0.000656,0.016660,56.991592,2.903290,0.166596,-276.182220,0.017596,0.000000
16.770000,13.785973,-276.226715,-0.001164,0.000684,0.017362,61.323071,3.123946,0.173621,-276.226715,0.018411,0.000000
17.260000,15.175293,-276.271179,-0.001147,0.000718,0.018238,67.503075,3.438771,0.182379,-276.271179,0.019227,0.000000
17.750000,16.631271,-276.315674,-0.001121,0.000749,0.019027,73.979591,3.768700,0.190270,-276.315674,0.020042,0.000000
18.240002,17.792328,-276.360138,-0.001104,0.000783,0.019885,79.144226,4.031799,0.198855,-276.360138,0.020857,0.000000
18.730001,19.008873,-276.404633,-0.001087,0.000811,0.020605,84.555687,4.307472,0.206053,-276.404633,0.021672,0.000000
19.220001,20.412712,-276.449097,-0.001056,0.000840,0.021343,90.800278,4.625587,0.213426,-276.449097,0.022496,0.000000
19.710001,23.093422,-276.449097,-0.001052,0.000887,0.022522,102.724670,5.233044,0.225220,-276.449097,0.023311,0.000000
20.200001,23.742844,-276.493591,-0.001022,0.000914,0.023216,105.613441,5.380205,0.232158,-276.493591,0.024126,0.000000
20.690001,23.725342,-276.493591,-0.000996,0.000916,0.023259,105.535591,5.376239,0.232593,-276.493591,0.023493,0.000000
21.180000,23.243866,-276.582550,-0.000992,0.000911,0.023147,103.393883,5.267136,0.231465,-276.582550,0.022886,0.000000
21.670000,22.819359,-276.582550,-0.000987,0.000888,0.022548,101.505577,5.170941,0.225481,-276.582550,0.022063,0.000000
22.160002,22.519974,-276.671509,-0.000983,0.000866,0.021984,100.173843,5.103099,0.219842,-276.671509,0.021247,0.000000
22.650002,22.357613,-276.671509,-0.000974,0.000831,0.021108,99.451630,5.066308,0.211084,-276.671509,0.020432,0.000000
23.140001,22.193031,-276.716003,-0.000996,0.000800,0.020319,98.719536,5.029013,0.203192,-276.716003,0.019617,0.000000
23.630001,22.083923,-276.716003,-0.000979,0.000773,0.019634,98.234200,5.004289,0.196341,-276.716003,0.018801,0.000000
24.120001,21.947266,-276.804962,-0.000979,0.000736,0.018697,97.626312,4.973321,0.186974,-276.804962,0.017987,0.000000
24.610001,21.815071,-276.804962,-0.000983,0.000702,0.017822,97.038284,4.943366,0.178216,-276.804962,0.017163,0.000000
25.100000,21.584198,-276.849426,-0.000983,0.000677,0.017197,96.011307,4.891049,0.171974,-276.849426,0.016347,0.000000
25.590002,20.947067,-276.938416,-0.000983,0.000648,0.016460,93.177208,4.746674,0.164601,-276.938416,0.015532,0.000000
26.080002,19.399490,-276.982880,-0.000966,0.000615,0.015627,86.293243,4.395988,0.156275,-276.982880,0.014717,0.000000
26.570002,17.488472,-276.893921,-0.000966,0.000582,0.014795,77.792610,3.962945,0.147952,-276.893921,0.013902,0.000000
27.060001,15.746140,-277.071838,-0.000974,0.000556,0.014110,70.042328,3.568126,0.141101,-277.071838,0.013087,0.000000
27.550001,13.396477,-277.027374,-0.000966,0.000524,0.013304,59.590504,3.035685,0.133035,-277.027374,0.012263,0.000000
28.040001,11.005470,-277.116333,-0.000970,0.000495,0.012584,48.954777,2.493875,0.125836,-277.116333,0.011447,0.000000
28.530001,7.851471,-277.160797,-0.000970,0.000459,0.011656,34.925087,1.779169,0.116556,-277.160797,0.010633,0.000000
29.020000,5.682404,-277.116333,-0.000996,0.000434,0.011014,25.276594,1.287651,0.110140,-277.116333,0.009817,0.000000
29.510002,2.715714,-277.249756,-0.001005,0.000398,0.010121,12.080097,0.615389,0.101208,-277.249756,0.009002,0.000000
30.000002,0.549622,-277.249756,-0.001000,0.000367,0.009332,2.444839,0.124546,0.093317,-277.249756,0.008178,0.000000
30.490002,0.025322,-277.294250,-0.001026,0.000332,0.008430,0.112638,0.005738,0.084297,-277.294250,0.007363,0.000000
30.980001,-0.009308,-277.383209,-0.001052,0.000306,0.007762,-0.041403,-0.002109,0.077617,-277.383209,0.006548,0.000000
31.470001,-0.036118,-277.383209,-0.001108,0.000267,0.006790,-0.160659,-0.008184,0.067905,-277.383209,0.005733,0.000000
31.960001,-0.029045,-277.427704,-0.001138,0.000237,0.006010,-0.129199,-0.006582,0.060100,-277.427704,0.004917,0.000000
32.450001,-0.027184,-277.427704,-0.001173,0.000202,0.005134,-0.120918,-0.006160,0.051342,-277.427704,0.004102,0.000000
32.940002,-0.035004,-277.472168,-0.001203,0.000173,0.004406,-0.155704,-0.007932,0.044056,-277.472168,0.003278,0.000000
33.430000,-0.010796,-277.605621,-0.001250,0.000132,0.003348,-0.048021,-0.002446,0.033477,-277.605621,0.002463,0.000000
33.920002,-0.016380,-277.472168,-0.001281,0.000103,0.002628,-0.072863,-0.003712,0.026279,-277.472168,0.001648,0.000000
34.410000,-0.013031,-277.694580,-0.001341,0.000072,0.001821,-0.057965,-0.002953,0.018213,-277.694580,0.000833,0.000000
34.900002,-0.010056,-277.650085,-0.001337,0.000049,0.001240,-0.044729,-0.002279,0.012403,-277.650085,0.000017,0.000000
35.390003,-0.023460,-277.739044,-0.001397,0.000011,0.000278,-0.104357,-0.005316,0.002778,-277.739044,-0.000798,0.000000
35.880001,-0.027924,-277.739044,-0.001388,0.000009,0.000217,-0.124210,-0.006328,0.002169,-277.739044,-0.000000,0.000000
36.370003,-0.112831,-277.739044,-0.001397,0.000021,0.000529,-0.501898,-0.025568,0.005291,-277.739044,0.000815,0.000000
36.860001,-0.016380,-277.783539,-0.001410,0.000040,0.001015,-0.072863,-0.003712,0.010147,-277.783539,0.001631,0.000000
37.350002,0.022346,-277.828033,-0.001393,0.000075,0.001908,0.099402,0.005064,0.019080,-277.828033,0.002446,0.000000
37.840000,0.026810,-277.872498,-0.001406,0.000111,0.002810,0.119255,0.006075,0.028099,-277.872498,0.003261,0.000000
38.330002,-0.000740,-278.005951,-0.001410,0.000142,0.003616,-0.003292,-0.000168,0.036165,-278.005951,0.004076,0.000000
38.820004,-0.026062,-277.872498,-0.001393,0.000170,0.004328,-0.115930,-0.005906,0.043276,-277.872498,0.004891,0.000000
39.310001,0.026443,-278.005951,-0.001414,0.000199,0.005048,0.117626,0.005992,0.050475,-278.005951,0.005715,0.000000
39.800003,0.004845,-278.050415,-0.001401,0.000236,0.005993,0.021550,0.001098,0.059926,-278.050415,0.006530,0.000000
40.290001,-0.006699,-278.005951,-0.001401,0.000267,0.006790,-0.029797,-0.001518,0.067905,-278.005951,0.007346,0.000000
40.780003,-0.016754,-278.183868,-0.001406,0.000292,0.007424,-0.074526,-0.003797,0.074237,-278.183868,0.008161,0.000000
41.270000,0.007820,-278.094910,-0.001397,0.000318,0.008083,0.034786,0.001772,0.080826,-278.094910,0.008976,0.000000
41.760002,0.031654,-278.183868,-0.001367,0.000350,0.008880,0.140806,0.007173,0.088805,-278.183868,0.009800,0.000000
42.250004,0.015640,-278.228363,-0.001328,0.000385,0.009774,0.069571,0.003544,0.097737,-278.228363,0.010615,0.000000
42.740002,-0.010056,-278.183868,-0.001315,0.000411,0.010450,-0.044729,-0.002279,0.104501,-278.183868,0.011430,0.000000
43.230003,0.013779,-278.317322,-0.001285,0.000445,0.011309,0.061291,0.003122,0.113089,-278.317322,0.012245,0.000000
43.720001,0.035751,-278.317322,-0.001255,0.000471,0.011959,0.159030,0.008101,0.119591,-278.317322,0.013061,0.000000
44.210003,0.054741,-278.361786,-0.001224,0.000510,0.012965,0.243500,0.012404,0.129652,-278.361786,0.013876,0.000000
44.700001,0.037987,-278.406281,-0.001194,0.000540,0.013728,0.168974,0.008608,0.137282,-278.406281,0.014700,0.000000
45.190002,0.080803,-278.450745,-0.001168,0.000566,0.014388,0.359429,0.018310,0.143875,-278.450745,0.015515,0.000000
45.680000,0.235344,-278.450745,-0.001117,0.000601,0.015255,1.046862,0.053330,0.152546,-278.450745,0.016330,0.000000
46.170002,0.900772,-278.495239,-0.001087,0.000639,0.016243,4.006835,0.204118,0.162433,-278.495239,0.017145,0.000000
46.660004,2.507187,-278.539703,-0.001078,0.000673,0.017085,11.152524,0.568137,0.170846,-278.539703,0.017960,0.000000
47.150002,4.889999,-278.628693,-0.001052,0.000705,0.017900,21.751804,1.108090,0.178995,-278.628693,0.018776,0.000000
47.640003,7.060928,-278.584198,-0.001048,0.000729,0.018524,31.408579,1.600029,0.185240,-278.584198,0.019599,0.000000
48.130001,10.566071,-278.673157,-0.001048,0.000770,0.019556,47.000229,2.394306,0.195562,-278.673157,0.020415,0.000000
48.620003,13.027824,-278.673157,-0.001035,0.000799,0.020293,57.950657,2.952147,0.202931,-278.673157,0.021230,0.000000
49.110001,15.819130,-278.717651,-0.001018,0.000832,0.021126,70.367004,3.584666,0.211258,-278.717651,0.022045,0.000000
49.600002,17.824356,-278.762115,-0.001026,0.000857,0.021759,79.286697,4.039057,0.217590,-278.762115,0.022860,0.000000
50.090004,21.938324,-278.762115,-0.001000,0.000903,0.022930,97.586540,4.971295,0.229297,-278.762115,0.023684,0.000000
50.580002,23.756622,-278.895569,-0.000992,0.000926,0.023519,105.674736,5.383327,0.235193,-278.895569,0.024499,0.000000
51.070004,26.180763,-278.851074,-0.000979,0.000956,0.024291,116.457848,5.932646,0.242911,-278.851074,0.025315,0.000000
51.560001,28.413879,-278.940033,-0.000974,0.000987,0.025063,126.391251,6.438677,0.250628,-278.940033,0.026130,0.000000
52.050003,31.332169,-278.984528,-0.000949,0.001032,0.026208,139.372452,7.099971,0.262077,-278.984528,0.026945,0.000000
52.540001,32.293633,-279.073486,-0.000940,0.001055,0.026789,143.649246,7.317842,0.267887,-279.073486,0.027760,0.000000
53.030003,34.594894,-279.028992,-0.000927,0.001091,0.027708,153.885773,7.839315,0.277081,-279.028992,0.028584,0.000000
53.520004,34.804169,-279.073486,-0.000892,0.001098,0.027899,154.816681,7.886737,0.278988,-279.073486,0.028141,0.000000
54.010002,33.999100,-279.162445,-0.000914,0.001095,0.027821,151.235550,7.704306,0.278209,-279.162445,0.027621,0.000000
54.500004,33.514641,-279.162445,-0.000897,0.001079,0.027396,149.080566,7.594526,0.273958,-279.162445,0.026806,0.000000
54.990002,33.156792,-279.162445,-0.000884,0.001046,0.026572,147.488770,7.513436,0.265719,-279.162445,0.025991,0.000000
55.480003,32.905067,-279.295898,-0.000880,0.001015,0.025774,146.369049,7.456395,0.257740,-279.295898,0.025167,0.000000
55.970001,32.659676,-279.295898,-0.000875,0.000979,0.024872,145.277496,7.400788,0.248721,-279.295898,0.024352,0.000000
56.460003,32.526733,-279.340363,-0.000880,0.000964,0.024491,144.686142,7.370663,0.244905,-279.340363,0.023537,0.000000
56.950005,32.340179,-279.340363,-0.000892,0.000922,0.023407,143.856308,7.328390,0.234065,-279.340363,0.022721,0.000000
57.440002,32.201279,-279.384857,-0.000875,0.000892,0.022652,143.238434,7.296914,0.226522,-279.384857,0.021906,0.000000
57.930004,31.955147,-279.473816,-0.000875,0.000867,0.022028,142.143585,7.241139,0.220277,-279.473816,0.021082,0.000000
58.420002,30.688705,-279.473816,-0.000875,0.000830,0.021091,136.510178,6.954160,0.210909,-279.473816,0.020267,0.000000
58.910004,29.119904,-279.518311,-0.000884,0.000800,0.020328,129.531799,6.598664,0.203279,-279.518311,0.019452,0.000000
59.400002,27.797981,-279.607269,-0.000871,0.000779,0.019799,123.651596,6.299113,0.197988,-279.607269,0.018637,0.000000
59.890003,25.258400,-279.562775,-0.000867,0.000741,0.018819,112.354973,5.723635,0.188189,-279.562775,0.017822,0.000000
60.380001,23.418877,-279.651733,-0.000854,0.000718,0.018229,104.172363,5.306793,0.182292,-279.651733,0.017006,0.000000
60.870003,19.857132,-279.651733,-0.000862,0.000680,0.017275,88.328934,4.499690,0.172754,-279.651733,0.016183,0.000000
61.360004,17.199142,-279.785187,-0.000875,0.000654,0.016599,76.505608,3.897382,0.165990,-279.785187,0.015367,0.000000
61.850002,13.654526,-279.740692,-0.000862,0.000619,0.015723,60.738365,3.094160,0.157228,-279.740692,0.014552,0.000000
62.340004,10.009377,-279.785187,-0.000888,0.000582,0.014786,44.523930,2.268157,0.147864,-279.785187,0.013737,0.000000
62.830002,6.891129,-279.829651,-0.000875,0.000550,0.013980,30.653271,1.561552,0.139799,-279.829651,0.012922,0.000000
63.320004,3.998161,-279.829651,-0.000884,0.000521,0.013234,17.784710,0.905996,0.132339,-279.829651,0.012107,0.000000
63.810001,1.213562,-279.918640,-0.000901,0.000488,0.012384,5.398193,0.274997,0.123842,-279.918640,0.011283,0.000000
64.300003,0.037987,-279.918640,-0.000914,0.000453,0.011517,0.168974,0.008608,0.115171,-279.918640,0.010468,0.000000
64.790001,-0.007820,-280.007599,-0.000961,0.000427,0.010858,-0.034786,-0.001772,0.108577,-280.007599,0.009652,0.000000
65.280006,-0.026436,-280.052063,-0.000970,0.000396,0.010060,-0.117593,-0.005990,0.100599,-280.052063,0.008837,0.000000
65.770004,-0.033882,-280.007599,-0.001013,0.000360,0.009141,-0.150715,-0.007678,0.091409,-280.007599,0.008022,0.000000
66.260002,-0.013405,-280.141022,-0.001065,0.000326,0.008291,-0.059628,-0.003038,0.082908,-280.141022,0.007198,0.000000
66.750000,-0.045799,-280.141022,-0.001112,0.000293,0.007441,-0.203725,-0.010378,0.074411,-280.141022,0.006383,0.000000
67.240005,-0.022713,-280.185516,-0.001151,0.000263,0.006686,-0.101031,-0.005147,0.066864,-280.185516,0.005568,0.000000
67.730003,-0.051384,-280.185516,-0.001190,0.000230,0.005845,-0.228567,-0.011644,0.058454,-280.185516,0.004753,0.000000
68.220001,-0.027557,-280.229980,-0.001224,0.000198,0.005021,-0.122581,-0.006245,0.050214,-280.229980,0.003937,0.000000
68.710007,-0.027557,-280.318939,-0.001259,0.000170,0.004319,-0.122581,-0.006245,0.043189,-280.318939,0.003122,0.000000
69.200005,-0.020851,-280.274475,-0.001298,0.000124,0.003140,-0.092750,-0.004725,0.031396,-280.274475,0.002298,0.000000
69.690002,-0.021965,-280.318939,-0.001341,0.000098,0.002480,-0.097705,-0.004977,0.024802,-280.318939,0.001483,0.000000
70.180000,-0.022713,-280.363434,-0.001371,0.000069,0.001743,-0.101031,-0.005147,0.017433,-280.363434,0.000668,0.000000
70.670006,-0.023460,-280.363434,-0.001397,0.000033,0.000850,-0.104357,-0.005316,0.008501,-280.363434,-0.000147,0.000000
71.160004,-0.006699,-280.496887,-0.001431,0.000006,0.000156,-0.029797,-0.001518,0.001563,-280.496887,-0.000919,0.000000
71.650002,-0.001488,-280.452393,-0.001423,0.000008,0.000208,-0.006618,-0.000337,0.002082,-280.452393,0.000208,0.000000
72.140007,0.000748,-280.541351,-0.001436,0.000027,0.000685,0.003326,0.000169,0.006854,-280.541351,0.001032,0.000000
72.630005,-0.007446,-280.541351,-0.001431,0.000047,0.001197,-0.033123,-0.001687,0.011968,-280.541351,0.001847,0.000000
73.120003,-0.008560,-280.585846,-0.001436,0.000090,0.002281,-0.038078,-0.001940,0.022808,-280.585846,0.002663,0.000000
73.610001,-0.011169,-280.719269,-0.001436,0.000116,0.002958,-0.049684,-0.002531,0.029575,-280.719269,0.003478,0.000000
74.100006,0.010803,-280.674805,-0.001444,0.000145,0.003694,0.048055,0.002448,0.036944,-280.674805,0.004293,0.000000
74.590004,0.006332,-280.674805,-0.001436,0.000178,0.004510,0.028168,0.001435,0.045097,-280.674805,0.005108,0.000000
75.080002,0.020111,-280.808258,-0.001427,0.000209,0.005299,0.089459,0.004557,0.052989,-280.808258,0.005932,0.000000
75.570007,0.029045,-280.763763,-0.001449,0.000241,0.006114,0.129199,0.006582,0.061141,-280.763763,0.006747,0.000000
76.060005,-0.005959,-280.852722,-0.001427,0.000273,0.006947,-0.026505,-0.001350,0.069468,-280.852722,0.007562,0.000000
76.550003,-0.016754,-280.897217,-0.001423,0.000298,0.007571,-0.074526,-0.003797,0.075709,-280.897217,0.008377,0.000000
77.040001,0.010056,-280.852722,-0.001397,0.000327,0.008300,0.044729,0.002279,0.082995,-280.852722,0.009193,0.000000
77.530006,0.029419,-280.986176,-0.001362,0.000358,0.009089,0.130862,0.006666,0.090887,-280.986176,0.010008,0.000000
78.020004,0.019363,-280.986176,-0.001354,0.000393,0.009982,0.086133,0.004388,0.099819,-280.986176,0.010832,0.000000
78.510002,-0.011543,-281.075134,-0.001328,0.000422,0.010710,-0.051347,-0.002616,0.107105,-281.075134,0.011647,0.000000
79.000000,0.022713,-281.030640,-0.001281,0.000455,0.011551,0.101031,0.005147,0.115515,-281.030640,0.012462,0.000000
79.490005,0.032768,-281.119598,-0.001272,0.000479,0.012176,0.145760,0.007425,0.121760,-281.119598,0.013277,0.000000
79.980003,0.024208,-281.208588,-0.001233,0.000515,0.013078,0.107683,0.005486,0.130779,-281.208588,0.014093,0.000000
80.470001,-0.005585,-281.164093,-0.001194,0.000547,0.013885,-0.024842,-0.001266,0.138845,-281.164093,0.014916,0.000000
80.960007,0.003349,-281.253052,-0.001168,0.000579,0.014708,0.014898,0.000759,0.147085,-281.253052,0.015732,0.000000
81.450005,0.026443,-281.253052,-0.001138,0.000605,0.015376,0.117626,0.005992,0.153761,-281.253052,0.016547,0.000000
81.940002,0.032394,-281.297546,-0.001099,0.000643,0.016339,0.144098,0.007341,0.163386,-281.297546,0.017362,0.000000
82.430000,0.100540,-281.386505,-0.001052,0.000680,0.017267,0.447225,0.022783,0.172667,-281.386505,0.018177,0.000000
82.920006,0.228264,-281.297546,-0.001009,0.000712,0.018073,1.015368,0.051725,0.180733,-281.297546,0.018992,0.000000
83.410004,0.557068,-281.475464,-0.000987,0.000739,0.018758,2.477962,0.126233,0.187583,-281.475464,0.019816,0.000000
83.900002,2.325096,-281.430969,-0.000953,0.000778,0.019764,10.342545,0.526874,0.197643,-281.430969,0.020631,0.000000
84.390007,4.533264,-281.475464,-0.000944,0.000806,0.020467,20.164967,1.027252,0.204668,-281.475464,0.021447,0.000000
84.880005,7.369621,-281.564423,-0.000940,0.000838,0.021273,32.781712,1.669980,0.212734,-281.564423,0.022262,0.000000
85.370003,10.065971,-281.564423,-0.000944,0.000867,0.022028,44.775677,2.280982,0.220277,-281.564423,0.023077,0.000000
85.860001,14.233940,-281.697876,-0.000931,0.000909,0.023094,63.315727,3.225457,0.230943,-281.697876,0.023892,0.000000
86.350006,16.568710,-281.653381,-0.000923,0.000932,0.023667,73.701302,3.754524,0.236666,-281.653381,0.024716,0.000000
86.840004,19.443802,-281.697876,-0.000923,0.000961,0.024404,86.490349,4.406029,0.244039,-281.697876,0.025531,0.000000
87.330002,23.405472,-281.742340,-0.000905,0.001005,0.025523,104.112740,5.303756,0.255227,-281.742340,0.026347,0.000000
87.820007,26.826088,-281.742340,-0.000914,0.001037,0.026329,119.328400,6.078878,0.263292,-281.742340,0.027162,0.000000
88.310005,29.005951,-281.831299,-0.000923,0.001060,0.026928,129.024918,6.572843,0.269276,-281.831299,0.027977,0.000000
88.800003,32.560249,-281.831299,-0.000884,0.001099,0.027925,144.835220,7.378258,0.279250,-281.831299,0.028801,0.000000
89.290001,35.990547,-281.831299,-0.000892,0.001138,0.028905,160.093948,8.155575,0.289049,-281.831299,0.029616,0.000000
89.780006,38.204674,-281.920258,-0.000867,0.001164,0.029555,169.942871,8.657303,0.295551,-281.920258,0.030431,0.000000
90.270004,39.971954,-281.920258,-0.000862,0.001187,0.030162,177.804138,9.057775,0.301622,-281.920258,0.031246,0.000000
90.760002,42.469826,-282.053711,-0.000841,0.001221,0.031012,188.915222,9.623800,0.310123,-282.053711,0.032061,0.000000
91.250008,43.621201,-282.009216,-0.000849,0.001234,0.031333,194.036789,9.884706,0.313329,-282.009216,0.031550,0.000000
91.740005,42.860817,-282.098206,-0.000832,0.001228,0.031194,190.654434,9.712399,0.311943,-282.098206,0.030977,0.000000
92.230003,42.439293,-282.231628,-0.000828,0.001211,0.030761,188.779404,9.616881,0.307606,-282.231628,0.030162,0.000000
92.720001,42.034523,-282.142670,-0.000819,0.001184,0.030084,186.978897,9.525159,0.300842,-282.142670,0.029347,0.000000
93.210007,41.748169,-282.231628,-0.000819,0.001142,0.029018,185.705124,9.460271,0.290177,-282.231628,0.028532,0.000000
93.700005,41.551186,-282.231628,-0.000815,0.001113,0.028272,184.828903,9.415634,0.282717,-282.231628,0.027708,0.000000
94.190002,41.363876,-282.231628,-0.000828,0.001083,0.027500,183.995712,9.373189,0.274999,-282.231628,0.026893,0.000000
94.680008,41.172104,-282.276123,-0.000811,0.001051,0.026702,183.142670,9.329732,0.267021,-282.276123,0.026078,0.000000
95.170006,41.027252,-282.320587,-0.000828,0.001021,0.025930,182.498337,9.296908,0.259303,-282.320587,0.025262,0.000000
95.660004,40.471306,-282.365082,-0.000811,0.000993,0.025210,180.025360,9.170929,0.252104,-282.365082,0.024447,0.000000
96.150002,39.403336,-282.365082,-0.000802,0.000965,0.024499,175.274796,8.928924,0.244992,-282.365082,0.023632,0.000000
96.640007,38.282127,-282.409546,-0.000806,0.000938,0.023823,170.287415,8.674854,0.238229,-282.409546,0.022808,0.000000
97.130005,36.121246,-282.498535,-0.000811,0.000905,0.022999,160.675323,8.185191,0.229989,-282.498535,0.021993,0.000000
97.620003,33.787216,-282.542999,-0.000806,0.000876,0.022253,150.293045,7.656293,0.222533,-282.542999,0.021178,0.000000
98.110008,30.406822,-282.542999,-0.000793,0.000835,0.021221,135.256302,6.890285,0.212211,-282.542999,0.020363,0.000000
98.600006,28.012093,-282.587494,-0.000811,0.000810,0.020571,124.604012,6.347631,0.205709,-282.587494,0.019547,0.000000
99.090004,24.892731,-282.587494,-0.000798,0.000784,0.019903,110.728394,5.640773,0.199029,-282.587494,0.018732,0.000000
99.580002,21.655319,-282.631958,-0.000811,0.000750,0.019062,96.327667,4.907166,0.190619,-282.631958,0.017908,0.000000
100.070007,19.029350,-282.631958,-0.000806,0.000725,0.018411,84.646774,4.312112,0.184112,-282.631958,0.017093,0.000000
100.560005,15.075127,-282.765411,-0.000811,0.000690,0.017518,67.057510,3.416072,0.175180,-282.765411,0.016278,0.000000
101.050003,11.907730,-282.765411,-0.000815,0.000656,0.016668,52.968227,2.698330,0.166683,-282.765411,0.015463,0.000000
101.540009,8.250282,-282.765411,-0.000828,0.000622,0.015792,36.699089,1.869541,0.157925,-282.765411,0.014648,0.000000
102.030006,4.980858,-282.898834,-0.000824,0.000590,0.014977,22.155962,1.128679,0.149772,-282.898834,0.013824,0.000000
102.520004,1.719986,-282.854370,-0.000832,0.000552,0.014032,7.650880,0.389754,0.140317,-282.854370,0.013009,0.000000
103.010002,0.052132,-282.898834,-0.000845,0.000521,0.013243,0.231893,0.011813,0.132426,-282.898834,0.012193,0.000000
103.500008,-0.051010,-282.987823,-0.000892,0.000489,0.012427,-0.226904,-0.011559,0.124273,-282.987823,0.011378,0.000000
103.990005,-0.045425,-282.987823,-0.000927,0.000454,0.011534,-0.202062,-0.010294,0.115341,-282.987823,0.010563,0.000000
104.480003,-0.024574,-282.987823,-0.000957,0.000429,0.010901,-0.109312,-0.005569,0.109013,-282.987823,0.009748,0.000000
104.970001,-0.035004,-283.076782,-0.001013,0.000393,0.009973,-0.155704,-0.007932,0.099732,-283.076782,0.008924,0.000000
105.460007,-0.035004,-283.121246,-0.001043,0.000363,0.009210,-0.155704,-0.007932,0.092102,-283.121246,0.008109,0.000000
105.950005,-0.033516,-283.121246,-0.001095,0.000327,0.008317,-0.149086,-0.007595,0.083169,-283.121246,0.007293,0.000000
106.440002,-0.039467,-283.210205,-0.001134,0.000295,0.007484,-0.175557,-0.008943,0.074843,-283.210205,0.006478,0.000000
106.930008,-0.030907,-283.165741,-0.001160,0.000267,0.006773,-0.137480,-0.007004,0.067731,-283.165741,0.005663,0.000000
107.420006,-0.043564,-283.210205,-0.001203,0.000231,0.005871,-0.193782,-0.009872,0.058711,-283.210205,0.004848,0.000000
107.910004,-0.030533,-283.299164,-0.001233,0.000198,0.005039,-0.135817,-0.006919,0.050388,-283.299164,0.004024,0.000000
108.400002,-0.035744,-283.299164,-0.001268,0.000170,0.004319,-0.158996,-0.008100,0.043189,-283.299164,0.003209,0.000000
108.890007,-0.038353,-283.432617,-0.001285,0.000131,0.003339,-0.170603,-0.008691,0.033390,-283.432617,0.002394,0.000000
109.380005,-0.020477,-283.432617,-0.001328,0.000100,0.002550,-0.091088,-0.004640,0.025499,-283.432617,0.001579,0.000000
109.870003,-0.035378,-283.388153,-0.001367,0.000069,0.001752,-0.157367,-0.008017,0.017520,-283.388153,0.000763,0.000000
110.360008,-0.015640,-283.566071,-0.001380,0.000061,0.001561,-0.069571,-0.003544,0.015613,-283.566071,-0.000061,0.000000
110.850006,-0.004837,-283.521576,-0.001436,0.000001,0.000017,-0.021516,-0.001096,0.000174,-283.521576,-0.000876,0.000000
111.340004,-0.004471,-283.566071,-0.001449,0.000008,0.000208,-0.019887,-0.001013,0.002082,-283.566071,0.000199,0.000000
111.830002,0.011543,-283.610535,-0.001431,0.000026,0.000668,0.051347,0.002616,0.006680,-283.610535,0.001023,0.000000
112.320007,-0.013031,-283.610535,-0.001449,0.000046,0.001162,-0.057965,-0.002953,0.011623,-283.610535,0.001839,0.000000
112.810005,0.005211,-283.699493,-0.001440,0.000089,0.002272,0.023179,0.001181,0.022725,-283.699493,0.002654,0.000000
113.300003,-0.005959,-283.655029,-0.001444,0.000115,0.002914,-0.026505,-0.001350,0.029140,-283.655029,0.003469,0.000000
113.790009,0.007446,-283.788483,-0.001440,0.000145,0.003686,0.033123,0.001687,0.036857,-283.788483,0.004284,0.000000
114.280006,0.013779,-283.788483,-0.001444,0.000175,0.004449,0.061291,0.003122,0.044491,-283.788483,0.005099,0.000000
114.770004,0.007080,-283.877441,-0.001431,0.000209,0.005299,0.031494,0.001604,0.052989,-283.877441,0.005923,0.000000
115.260002,0.013031,-283.877441,-0.001440,0.000240,0.006097,0.057965,0.002953,0.060967,-283.877441,0.006739,0.000000
115.750008,-0.001488,-283.877441,-0.001418,0.000273,0.006947,-0.006618,-0.000337,0.069468,-283.877441,0.007554,0.000000
116.240005,-0.042450,-283.966400,-0.001414,0.000297,0.007554,-0.188827,-0.009619,0.075535,-283.966400,0.008369,0.000000
116.730003,0.017876,-284.010864,-0.001406,0.000327,0.008308,0.079515,0.004051,0.083082,-284.010864,0.009184,0.000000
117.220009,0.009308,-284.055359,-0.001384,0.000354,0.009002,0.041403,0.002109,0.090020,-284.055359,0.010008,0.000000
117.710007,0.005585,-284.010864,-0.001337,0.000392,0.009964,0.024842,0.001266,0.099645,-284.010864,0.010823,0.000000
118.200005,-0.023460,-284.099823,-0.001337,0.000420,0.010658,-0.104357,-0.005316,0.106583,-284.099823,0.011638,0.000000
118.690002,-0.002235,-284.233276,-0.001285,0.000454,0.011534,-0.009944,-0.000507,0.115341,-284.233276,0.012453,0.000000
119.180008,0.020485,-284.144318,-0.001289,0.000476,0.012098,0.091121,0.004642,0.120980,-284.144318,0.013269,0.000000
119.670006,0.008568,-284.188782,-0.001237,0.000515,0.013069,0.038112,0.001941,0.130692,-284.188782,0.014084,0.000000
120.160004,-0.013031,-284.233276,-0.001194,0.000547,0.013885,-0.057965,-0.002953,0.138845,-284.233276,0.014908,0.000000
120.650009,-0.014153,-284.277771,-0.001168,0.000579,0.014700,-0.062954,-0.003207,0.146998,-284.277771,0.015723,0.000000
121.140007,0.011543,-284.366730,-0.001125,0.000605,0.015367,0.051347,0.002616,0.153674,-284.366730,0.016538,0.000000
121.630005,-0.001488,-284.366730,-0.001108,0.000642,0.016304,-0.006618,-0.000337,0.163042,-284.366730,0.017353,0.000000
122.120003,0.006706,-284.411194,-0.001061,0.000680,0.017267,0.029831,0.001520,0.172667,-284.411194,0.018169,0.000000
122.610008,0.039474,-284.411194,-0.001022,0.000711,0.018065,0.175591,0.008945,0.180645,-284.411194,0.018984,0.000000
123.100006,0.042824,-284.500153,-0.001000,0.000738,0.018741,0.190490,0.009704,0.187409,-284.500153,0.019807,0.000000
123.590004,0.162727,-284.500153,-0.000949,0.000778,0.019764,0.723847,0.036875,0.197643,-284.500153,0.020623,0.000000
124.080009,0.484459,-284.544647,-0.000918,0.000806,0.020467,2.154981,0.109780,0.204668,-284.544647,0.021438,0.000000
124.570007,1.884575,-284.633606,-0.000901,0.000838,0.021282,8.383008,0.427051,0.212817,-284.633606,0.022253,0.000000
125.060005,4.030930,-284.589111,-0.000892,0.000865,0.021975,17.930470,0.913422,0.219755,-284.589111,0.023068,0.000000
125.550003,8.000793,-284.678101,-0.000880,0.000909,0.023077,35.589306,1.813006,0.230769,-284.678101,0.023892,0.000000
126.040009,10.365730,-284.678101,-0.000867,0.000932,0.023667,46.109070,2.348908,0.236666,-284.678101,0.024707,0.000000
126.530006,13.371521,-284.767059,-0.000871,0.000959,0.024369,59.479496,3.030030,0.243690,-284.767059,0.025523,0.000000
127.020004,17.624763,-284.811523,-0.000867,0.001006,0.025540,78.398865,3.993829,0.255401,-284.811523,0.026338,0.000000
127.510010,21.231934,-284.856018,-0.000867,0.001036,0.026321,94.444359,4.811225,0.263205,-284.856018,0.027153,0.000000
128.000000,23.687355,-284.900482,-0.000858,0.001060,0.026928,105.366615,5.367631,0.269276,-284.900482,0.027968,0.000000
128.490005,27.463585,-284.900482,-0.000841,0.001099,0.027925,122.164124,6.223337,0.279250,-284.900482,0.028792,0.000000
128.980011,31.395096,-284.989441,-0.000849,0.001138,0.028896,139.652359,7.114230,0.288962,-284.989441,0.029607,0.000000
129.470001,34.163689,-285.033936,-0.000845,0.001164,0.029555,151.967682,7.741602,0.295551,-285.033936,0.030423,0.000000
129.960007,36.465691,-285.033936,-0.000841,0.001189,0.030206,162.207489,8.263244,0.302057,-285.033936,0.031237,0.000000
130.450012,39.719109,-285.078430,-0.000828,0.001222,0.031038,176.679413,9.000479,0.310380,-285.078430,0.032053,0.000000
130.940002,43.010139,-285.078430,-0.000828,0.001259,0.031966,191.318649,9.746237,0.319661,-285.078430,0.032868,0.000000
131.430008,46.196899,-285.078430,-0.000811,0.001289,0.032738,205.494064,10.468368,0.327378,-285.078430,0.033692,0.000000
131.920013,48.070679,-285.211853,-0.000802,0.001313,0.033354,213.829056,10.892971,0.333536,-285.211853,0.034507,0.000000
132.410004,51.420540,-285.167389,-0.000789,0.001350,0.034299,228.729980,11.652061,0.342991,-285.167389,0.035322,0.000000
132.900009,52.739487,-285.256348,-0.000789,0.001362,0.034585,234.596954,11.950938,0.345852,-285.256348,0.034810,0.000000
133.389999,52.112411,-285.256348,-0.000772,0.001359,0.034516,231.807587,11.808841,0.345156,-285.256348,0.034316,0.000000
133.880005,51.559807,-285.300812,-0.000772,0.001338,0.033978,229.349472,11.683619,0.339781,-285.300812,0.033501,0.000000
134.370010,51.160255,-285.389771,-0.000772,0.001308,0.033223,227.572189,11.593081,0.332234,-285.389771,0.032686,0.000000
134.860001,50.868317,-285.345306,-0.000767,0.001272,0.032313,226.273575,11.526926,0.323132,-285.345306,0.031862,0.000000
135.350006,50.685852,-285.434265,-0.000776,0.001244,0.031593,225.461929,11.485578,0.315933,-285.434265,0.031047,0.000000
135.840012,50.511955,-285.478729,-0.000759,0.001222,0.031029,224.688400,11.446172,0.310293,-285.478729,0.030231,0.000000
136.330002,50.348854,-285.478729,-0.000780,0.001191,0.030249,223.962891,11.409213,0.302489,-285.478729,0.029417,0.000000
136.820007,50.119476,-285.523224,-0.000763,0.001150,0.029217,222.942566,11.357236,0.292171,-285.523224,0.028601,0.000000
137.310013,49.645439,-285.523224,-0.000759,0.001121,0.028471,220.833939,11.249817,0.284711,-285.523224,0.027786,0.000000
137.800003,48.482521,-285.612183,-0.000759,0.001092,0.027725,215.661026,10.986297,0.277255,-285.612183,0.026962,0.000000
138.290009,47.254814,-285.656677,-0.000750,0.001069,0.027153,210.199905,10.708094,0.271528,-285.656677,0.026147,0.000000
138.780014,45.362785,-285.656677,-0.000746,0.001039,0.026390,201.783752,10.279354,0.263898,-285.656677,0.025332,0.000000
139.270004,42.982956,-285.745636,-0.000746,0.001005,0.025523,191.197739,9.740077,0.255227,-285.745636,0.024517,0.000000
139.760010,40.145103,-285.790100,-0.000763,0.000971,0.024656,178.574341,9.097011,0.246556,-285.790100,0.023701,0.000000
140.250000,38.896912,-285.879059,-0.000750,0.000962,0.024447,173.022110,8.814166,0.244474,-285.879059,0.022886,0.000000
140.740005,34.739372,-285.834595,-0.000750,0.000921,0.023398,154.528442,7.872055,0.233978,-285.834595,0.022063,0.000000
141.230011,30.675674,-285.879059,-0.000763,0.000880,0.022357,136.452209,6.951207,0.223574,-285.879059,0.021247,0.000000
141.720001,26.572876,-285.879059,-0.000746,0.000842,0.021377,118.202057,6.021500,0.213775,-285.879059,0.020432,0.000000
142.210007,23.396538,-285.968048,-0.000772,0.000814,0.020666,104.072998,5.301731,0.206663,-285.968048,0.019617,0.000000
142.700012,20.506927,-286.012512,-0.000763,0.000789,0.020033,91.219368,4.646936,0.200331,-286.012512,0.018801,0.000000
143.190002,17.334686,-286.012512,-0.000763,0.000757,0.019227,77.108536,3.928096,0.192265,-286.012512,0.017978,0.000000
143.680008,14.382141,-286.057007,-0.000780,0.000730,0.018550,63.974960,3.259040,0.185501,-286.057007,0.017163,0.000000
144.170013,10.293869,-286.145966,-0.000772,0.000690,0.017527,45.789417,2.332624,0.175267,-286.145966,0.016347,0.000000
144.660004,8.337051,-286.101471,-0.000780,0.000661,0.016798,37.085056,1.889203,0.167985,-286.101471,0.015532,0.000000
145.150009,3.548340,-286.145966,-0.000772,0.000623,0.015836,15.783804,0.804065,0.158356,-286.145966,0.014717,0.000000
145.639999,0.560791,-286.190430,-0.000793,0.000590,0.014977,2.494523,0.127077,0.149772,-286.190430,0.013902,0.000000
146.130005,-0.007446,-286.279388,-0.000806,0.000556,0.014127,-0.033123,-0.001687,0.141271,-286.279388,0.013078,0.000000
146.620010,-0.049522,-286.279388,-0.000845,0.000522,0.013251,-0.220287,-0.011222,0.132513,-286.279388,0.012263,0.000000
147.110001,-0.061066,-286.279388,-0.000892,0.000490,0.012453,-0.271634,-0.013838,0.124534,-286.279388,0.011447,0.000000
147.600006,-0.042076,-286.323883,-0.000927,0.000457,0.011612,-0.187164,-0.009535,0.116124,-286.323883,0.010633,0.000000
148.090012,-0.031647,-286.368378,-0.000961,0.000431,0.010936,-0.140772,-0.007171,0.109357,-286.368378,0.009817,0.000000
148.580002,-0.051758,-286.412842,-0.001022,0.000394,0.010017,-0.230230,-0.011728,0.100167,-286.412842,0.009002,0.000000
149.070007,-0.024574,-286.501801,-0.001048,0.000365,0.009279,-0.109312,-0.005569,0.092794,-286.501801,0.008178,0.000000
149.560013,-0.024948,-286.457336,-0.001095,0.000331,0.008412,-0.110975,-0.005653,0.084123,-286.457336,0.007363,0.000000
150.050003,-0.027924,-286.590759,-0.001125,0.000302,0.007666,-0.124210,-0.006328,0.076663,-286.590759,0.006548,0.000000
150.540009,-0.035004,-286.590759,-0.001160,0.000267,0.006773,-0.155704,-0.007932,0.067731,-286.590759,0.005733,0.000000
151.030014,-0.039101,-286.590759,-0.001207,0.000234,0.005941,-0.173928,-0.008860,0.059408,-286.590759,0.004917,0.000000
151.520004,-0.029785,-286.635254,-0.001237,0.000200,0.005091,-0.132491,-0.006749,0.050907,-286.635254,0.004093,0.000000
152.010010,-0.039101,-286.679718,-0.001268,0.000180,0.004570,-0.173928,-0.008860,0.045703,-286.679718,0.003278,0.000000
152.500000,-0.021225,-286.724213,-0.001289,0.000130,0.003313,-0.094413,-0.004810,0.033129,-286.724213,0.002463,0.000000
152.990005,-0.011169,-286.768677,-0.001345,0.000102,0.002593,-0.049684,-0.002531,0.025930,-286.768677,0.001648,0.000000
153.480011,-0.014153,-286.813171,-0.001371,0.000072,0.001830,-0.062954,-0.003207,0.018300,-286.813171,0.000833,0.000000
153.970001,-0.018242,-286.857666,-0.001367,0.000062,0.001570,-0.081144,-0.004134,0.015700,-286.857666,0.000017,0.000000
154.460007,-0.028297,-286.813171,-0.001427,0.000011,0.000269,-0.125873,-0.006412,0.002691,-286.813171,-0.000806,0.000000
154.950012,-0.002975,-286.991089,-0.001431,0.000008,0.000199,-0.013236,-0.000674,0.001995,-286.991089,0.000017,0.000000
155.440002,0.000748,-286.902130,-0.001436,0.000020,0.000520,0.003326,0.000169,0.005204,-286.902130,0.000833,0.000000
155.930008,-0.005211,-287.035583,-0.001444,0.000040,0.001015,-0.023179,-0.001181,0.010147,-287.035583,0.001657,0.000000
156.420013,0.014526,-286.991089,-0.001444,0.000081,0.002064,0.064617,0.003292,0.020643,-286.991089,0.002472,0.000000
156.910004,0.001122,-287.035583,-0.001449,0.000111,0.002810,0.004989,0.000254,0.028099,-287.035583,0.003287,0.000000
157.400009,-0.007820,-287.080048,-0.001444,0.000142,0.003608,-0.034786,-0.001772,0.036078,-287.080048,0.004102,0.000000
157.890015,0.001488,-287.080048,-0.001431,0.000170,0.004328,0.006618,0.000337,0.043276,-287.080048,0.004917,0.000000
158.380005,0.018250,-287.257996,-0.001440,0.000201,0.005108,0.081178,0.004135,0.051081,-287.257996,0.005741,0.000000
158.870010,-0.000740,-287.213501,-0.001427,0.000236,0.005993,-0.003292,-0.000168,0.059926,-287.213501,0.006557,0.000000
159.360001,-0.008934,-287.257996,-0.001427,0.000268,0.006808,-0.039741,-0.002024,0.068079,-287.257996,0.007371,0.000000
159.850006,-0.010422,-287.346954,-0.001423,0.000292,0.007424,-0.046358,-0.002362,0.074237,-287.346954,0.008187,0.000000
160.340012,-0.001488,-287.346954,-0.001406,0.000319,0.008109,-0.006618,-0.000337,0.081088,-287.346954,0.009002,0.000000
160.830002,0.024208,-287.391418,-0.001384,0.000350,0.008880,0.107683,0.005486,0.088805,-287.391418,0.009817,0.000000
161.320007,0.018250,-287.435913,-0.001337,0.000386,0.009809,0.081178,0.004135,0.098086,-287.435913,0.010641,0.000000
161.810013,-0.008934,-287.435913,-0.001328,0.000412,0.010459,-0.039741,-0.002024,0.104588,-287.435913,0.011456,0.000000
162.300003,0.005211,-287.524872,-0.001306,0.000445,0.011309,0.023179,0.001181,0.113089,-287.524872,0.012271,0.000000
162.790009,0.026070,-287.569336,-0.001268,0.000470,0.011950,0.115964,0.005907,0.119504,-287.569336,0.013087,0.000000
163.280014,0.020111,-287.658325,-0.001246,0.000510,0.012956,0.089459,0.004557,0.129565,-287.658325,0.013902,0.000000
163.770004,-0.018990,-287.613831,-0.001220,0.000539,0.013694,-0.084470,-0.004303,0.136937,-287.613831,0.014717,0.000000
164.260010,-0.011543,-287.658325,-0.001186,0.000566,0.014388,-0.051347,-0.002616,0.143875,-287.658325,0.015541,0.000000
164.750015,0.005585,-287.658325,-0.001155,0.000599,0.015203,0.024842,0.001266,0.152028,-287.658325,0.016356,0.000000
165.240005,0.008194,-287.658325,-0.001121,0.000638,0.016208,0.036449,0.001857,0.162084,-287.658325,0.017171,0.000000
165.730011,0.001122,-287.747284,-0.001069,0.000672,0.017059,0.004989,0.000254,0.170585,-287.747284,0.017987,0.000000
166.220001,0.017128,-287.702789,-0.001035,0.000704,0.017891,0.076189,0.003881,0.178912,-287.702789,0.018801,0.000000
166.710007,0.022346,-287.836243,-0.001022,0.000730,0.018550,0.099402,0.005064,0.185501,-287.836243,0.019625,0.000000
167.200012,0.028671,-287.880707,-0.000974,0.000770,0.019556,0.127536,0.006497,0.195562,-287.880707,0.020441,0.000000
167.690002,0.035378,-287.880707,-0.000927,0.000800,0.020319,0.157367,0.008017,0.203192,-287.880707,0.021256,0.000000
168.180008,0.113571,-287.969666,-0.000901,0.000832,0.021126,0.505190,0.025736,0.211258,-287.969666,0.022071,0.000000
168.670013,0.447594,-287.969666,-0.000862,0.000861,0.021880,1.990996,0.101426,0.218801,-287.969666,0.022886,0.000000
169.160004,2.655014,-288.058624,-0.000845,0.000903,0.022930,11.810092,0.601635,0.229297,-288.058624,0.023701,0.000000
169.650009,4.718704,-288.058624,-0.000819,0.000928,0.023580,20.989845,1.069274,0.235799,-288.058624,0.024525,0.000000
170.140015,7.515221,-288.103119,-0.000836,0.000956,0.024291,33.429371,1.702973,0.242911,-288.103119,0.025341,0.000000
170.630005,10.608147,-288.147614,-0.000832,0.000987,0.025063,47.187393,2.403840,0.250628,-288.147614,0.026156,0.000000
171.120010,15.473564,-288.147614,-0.000824,0.001033,0.026243,68.829849,3.506360,0.262426,-288.147614,0.026971,0.000000
171.610001,17.837013,-288.281036,-0.000819,0.001055,0.026789,79.342995,4.041925,0.267887,-288.281036,0.027786,0.000000
172.100006,21.573402,-288.281036,-0.000811,0.001091,0.027717,95.963287,4.888603,0.277168,-288.281036,0.028601,0.000000
172.590012,25.224136,-288.281036,-0.000815,0.001129,0.028679,112.202560,5.715871,0.286793,-288.281036,0.029425,0.000000
173.080002,28.948608,-288.369995,-0.000793,0.001161,0.029495,128.769836,6.559848,0.294946,-288.369995,0.030240,0.000000
173.570007,31.351898,-288.369995,-0.000806,0.001183,0.030058,139.460205,7.104442,0.300581,-288.369995,0.031055,0.000000
174.060013,35.090149,-288.414490,-0.000793,0.001218,0.030943,156.088776,7.951541,0.309427,-288.414490,0.031871,0.000000
174.550003,38.131317,-288.458954,-0.000785,0.001251,0.031767,169.616577,8.640680,0.317666,-288.458954,0.032686,0.000000
175.040009,42.066917,-288.458954,-0.000789,0.001287,0.032695,187.123001,9.532500,0.326947,-288.458954,0.033510,0.000000
175.530014,44.553246,-288.503448,-0.000780,0.001310,0.033267,198.182739,10.095910,0.332670,-288.503448,0.034325,0.000000
176.020004,48.228569,-288.503448,-0.000767,0.001345,0.034169,214.531387,10.928750,0.341689,-288.503448,0.035140,0.000000
176.510010,51.401176,-288.592407,-0.000789,0.001377,0.034975,228.643845,11.647674,0.349755,-288.592407,0.035955,0.000000
177.000015,53.766113,-288.592407,-0.000750,0.001404,0.035652,239.163620,12.183576,0.356518,-288.592407,0.036771,0.000000
177.490005,57.077255,-288.636902,-0.000759,0.001436,0.036484,253.892319,12.933890,0.364845,-288.636902,0.037586,0.000000
177.980011,60.873962,-288.770325,-0.000746,0.001475,0.037473,270.780914,13.794237,0.374731,-288.770325,0.038409,0.000000
178.470001,63.470139,-288.681366,-0.000742,0.001507,0.038271,282.329285,14.382539,0.382710,-288.681366,0.039225,0.000000
178.960007,66.241333,-288.770325,-0.000733,0.001537,0.039043,294.656158,15.010501,0.390427,-288.770325,0.040031,0.000000
179.450012,65.380783,-288.770325,-0.000711,0.001529,0.038843,290.828247,14.815497,0.388432,-288.770325,0.038913,0.000000
179.940002,64.720566,-288.814819,-0.000720,0.001510,0.038358,287.891449,14.665890,0.383576,-288.814819,0.038097,0.000000
180.430008,64.269257,-288.903778,-0.000711,0.001485,0.037707,285.883942,14.563622,0.377070,-288.903778,0.037282,0.000000
180.920013,63.890182,-288.903778,-0.000716,0.001459,0.037065,284.197723,14.477722,0.370655,-288.903778,0.036458,0.000000
181.410004,63.596756,-288.948273,-0.000707,0.001422,0.036111,282.892487,14.411231,0.361113,-288.948273,0.035643,0.000000
181.900009,63.410187,-288.992737,-0.000720,0.001395,0.035426,282.062592,14.368954,0.354262,-288.992737,0.034828,0.000000
182.390015,63.219162,-288.948273,-0.000698,0.001365,0.034672,281.212891,14.325666,0.346719,-288.948273,0.034013,0.000000
182.880005,63.038933,-289.037231,-0.000694,0.001343,0.034108,280.411163,14.284826,0.341083,-289.037231,0.033198,0.000000
183.370010,62.701569,-289.037231,-0.000720,0.001305,0.033137,278.910492,14.208378,0.331368,-289.037231,0.032382,0.000000
183.860016,61.474602,-289.126190,-0.000690,0.001268,0.032200,273.452698,13.930344,0.322004,-289.126190,0.031558,0.000000
184.350006,60.189171,-289.170654,-0.000681,0.001241,0.031515,267.734802,13.639061,0.315153,-289.170654,0.030743,0.000000
184.840012,58.993484,-289.170654,-0.000694,0.001222,0.031038,262.416138,13.368114,0.310380,-289.170654,0.029928,0.000000
185.330002,57.257111,-289.259613,-0.000681,0.001197,0.030414,254.692352,12.974647,0.304139,-289.259613,0.029113,0.000000
185.820007,53.829048,-289.259613,-0.000698,0.001152,0.029252,239.443558,12.197837,0.292516,-289.259613,0.028298,0.000000
186.310013,51.112221,-289.348572,-0.000698,0.001124,0.028540,227.358521,11.582195,0.285404,-289.348572,0.027474,0.000000
186.800003,47.724747,-289.348572,-0.000686,0.001090,0.027682,212.290283,10.814583,0.276820,-289.348572,0.026659,0.000000
187.290009,45.233948,-289.393066,-0.000690,0.001069,0.027153,201.210648,10.250159,0.271528,-289.393066,0.025844,0.000000
187.780014,41.096886,-289.393066,-0.000694,0.001030,0.026156,182.808075,9.312687,0.261555,-289.393066,0.025028,0.000000
188.270004,37.550789,-289.482025,-0.000703,0.000996,0.025306,167.034256,8.509130,0.253058,-289.482025,0.024213,0.000000
188.760010,33.805832,-289.526520,-0.000698,0.000963,0.024464,150.375854,7.660511,0.244644,-289.526520,0.023398,0.000000
189.250015,30.534912,-289.482025,-0.000703,0.000930,0.023632,135.826080,6.919310,0.236321,-289.482025,0.022574,0.000000
189.740005,27.179840,-289.526520,-0.000720,0.000903,0.022947,120.901970,6.159039,0.229471,-289.526520,0.021759,0.000000
190.230011,23.689964,-289.482025,-0.000694,0.000872,0.022140,105.378227,5.368223,0.221405,-289.482025,0.020944,0.000000
190.720016,19.110527,-289.615479,-0.000724,0.000830,0.021091,85.007874,4.330507,0.210909,-289.615479,0.020128,0.000000
191.210007,16.325180,-289.704437,-0.000720,0.000806,0.020476,72.618027,3.699339,0.204755,-289.704437,0.019313,0.000000
191.700012,13.773689,-289.704437,-0.000737,0.000784,0.019912,61.268429,3.121163,0.199116,-289.704437,0.018498,0.000000
192.190002,9.366661,-289.748901,-0.000720,0.000740,0.018801,41.664989,2.122516,0.188015,-289.748901,0.017674,0.000000
192.680008,6.002274,-289.793396,-0.000724,0.000707,0.017969,26.699446,1.360135,0.179692,-289.793396,0.016859,0.000000
193.170013,2.676239,-289.837891,-0.000729,0.000675,0.017136,11.904506,0.606444,0.171365,-289.837891,0.016044,0.000000
193.660004,0.432701,-289.882355,-0.000729,0.000649,0.016495,1.924751,0.098051,0.164950,-289.882355,0.015229,0.000000
194.150009,-0.040962,-289.837891,-0.000767,0.000616,0.015636,-0.182209,-0.009282,0.156362,-289.837891,0.014414,0.000000
194.640015,-0.051758,-289.926849,-0.000802,0.000577,0.014656,-0.230230,-0.011728,0.146562,-289.926849,0.013590,0.000000
195.130005,-0.045059,-289.926849,-0.000836,0.000542,0.013772,-0.200433,-0.010211,0.137717,-289.926849,0.012774,0.000000
195.620010,-0.047287,-290.015808,-0.000884,0.000509,0.012939,-0.210343,-0.010715,0.129390,-290.015808,0.011959,0.000000
196.110016,-0.050270,-290.015808,-0.000914,0.000482,0.012237,-0.223612,-0.011391,0.122366,-290.015808,0.011144,0.000000
196.600006,-0.036865,-290.060272,-0.000974,0.000448,0.011387,-0.163985,-0.008354,0.113869,-290.060272,0.010329,0.000000
197.090012,-0.037605,-290.104767,-0.001000,0.000416,0.010554,-0.167277,-0.008521,0.105542,-290.104767,0.009514,0.000000
197.580002,-0.038353,-290.149231,-0.001048,0.000380,0.009661,-0.170603,-0.008691,0.096609,-290.149231,0.008690,0.000000
198.070007,-0.037605,-290.193726,-0.001078,0.000358,0.009089,-0.167277,-0.008521,0.090887,-290.193726,0.007874,0.000000
198.560013,-0.026436,-290.193726,-0.001095,0.000323,0.008204,-0.117593,-0.005990,0.082041,-290.193726,0.007059,0.000000
199.050003,-0.044312,-290.238220,-0.001151,0.000285,0.007242,-0.197107,-0.010041,0.072416,-290.238220,0.006244,0.000000
199.540009,-0.025696,-290.327179,-0.001177,0.000252,0.006409,-0.114301,-0.005823,0.064090,-290.327179,0.005429,0.000000
200.030014,-0.051010,-290.282684,-0.001199,0.000223,0.005655,-0.226904,-0.011559,0.056546,-290.282684,0.004614,0.000000
200.520004,-0.053246,-290.371643,-0.001255,0.000188,0.004770,-0.236848,-0.012066,0.047697,-290.371643,0.003790,0.000000
201.010010,-0.049522,-290.416138,-0.001268,0.000160,0.004059,-0.220287,-0.011222,0.040589,-290.416138,0.002975,0.000000
201.500015,-0.030159,-290.460602,-0.001324,0.000118,0.002992,-0.134154,-0.006834,0.029920,-290.460602,0.002160,0.000000
201.990005,-0.039101,-290.505096,-0.001345,0.000093,0.002368,-0.173928,-0.008860,0.023678,-290.505096,0.001344,0.000000
202.480011,-0.032394,-290.594055,-0.001375,0.000061,0.001553,-0.144098,-0.007341,0.015526,-290.594055,0.000529,0.000000
202.970016,-0.021599,-290.638519,-0.001393,0.000030,0.000772,-0.096076,-0.004894,0.007721,-290.638519,-0.000295,0.000000
203.400009,-0.008560,-290.638519,-0.001449,0.000008,0.000208,-0.038078,-0.001940,0.002082,-290.638519,-0.000000,0.000000