File: Data/AD Peeled Punched/AD Membrane Peeled Punched Multi_2_08122024_190210.csv
Time (sec),S:Load (lbs),S:HL1 (DIM),S:LVDT (in),S:Position (in),Ch:Position (mm),Ch:Load (N),Ch:Stress (MPa),Ch:Strain (mm/mm),Ch:HL1 (DIM),Set Point (),Cycles ()
0.110000,-0.067024,-310.743927,-0.007067,-0.005286,-0.134273,-0.298139,-0.015188,-1.342726,-310.743927,-0.134030,0.000000
0.600000,-0.041702,-310.654968,-0.007075,-0.005182,-0.131619,-0.185501,-0.009450,-1.316186,-310.654968,-0.130717,0.000000
1.090000,-0.021599,-310.743927,-0.006791,-0.004871,-0.123718,-0.096076,-0.004894,-1.237184,-310.743927,-0.122565,0.000000
1.580000,-0.059204,-310.788391,-0.006467,-0.004550,-0.115558,-0.263353,-0.013416,-1.155578,-310.788391,-0.114395,0.000000
2.070000,-0.011169,-310.788391,-0.006127,-0.004228,-0.107388,-0.049684,-0.002531,-1.073884,-310.788391,-0.106226,0.000000
2.560000,-0.040962,-310.877380,-0.005795,-0.003909,-0.099297,-0.182209,-0.009282,-0.992971,-310.877380,-0.098075,0.000000
3.050000,-0.001114,-310.877380,-0.005463,-0.003592,-0.091249,-0.004955,-0.000252,-0.912493,-310.877380,-0.089905,0.000000
3.540000,-0.029045,-310.921844,-0.005131,-0.003266,-0.082967,-0.129199,-0.006582,-0.829672,-310.921844,-0.081736,0.000000
4.030000,-0.029419,-310.966339,-0.004807,-0.002941,-0.074702,-0.130862,-0.006666,-0.747025,-310.966339,-0.073584,0.000000
4.520000,-0.030159,-310.966339,-0.004475,-0.002623,-0.066629,-0.134154,-0.006834,-0.666289,-310.966339,-0.065415,0.000000
5.010000,0.024948,-311.010803,-0.004169,-0.002311,-0.058702,0.110975,0.005653,-0.587022,-311.010803,-0.057245,0.000000
5.500000,-0.021599,-310.966339,-0.003824,-0.001983,-0.050360,-0.096076,-0.004894,-0.503595,-310.966339,-0.049093,0.000000
5.990000,0.004471,-311.099762,-0.003479,-0.001646,-0.041800,0.019887,0.001013,-0.418000,-311.099762,-0.040924,0.000000
6.480000,-0.000740,-311.188721,-0.003169,-0.001337,-0.033952,-0.003292,-0.000168,-0.339516,-311.188721,-0.032755,0.000000
6.970000,0.113571,-311.099762,-0.002824,-0.001010,-0.025661,0.505190,0.025736,-0.256612,-311.099762,-0.024603,0.000000
7.460001,0.126984,-311.277710,-0.002505,-0.000692,-0.017570,0.564851,0.028775,-0.175699,-311.277710,-0.016434,0.000000
7.950000,0.215981,-311.188721,-0.002156,-0.000361,-0.009166,0.960729,0.048942,-0.091663,-311.188721,-0.008264,0.000000
8.440001,0.496376,-311.277710,-0.001841,-0.000046,-0.001162,2.207991,0.112480,-0.011620,-311.277710,-0.000112,0.000000
8.930000,0.587234,-311.322174,-0.001742,-0.000011,-0.000286,2.612149,0.133069,-0.002861,-311.322174,-0.000017,0.000000
9.420000,0.554092,-311.366669,-0.001733,-0.000011,-0.000286,2.464726,0.125559,-0.002861,-311.366669,0.000390,0.000000
9.910001,0.490417,-311.366669,-0.001725,-0.000011,-0.000277,2.181486,0.111130,-0.002774,-311.366669,0.001205,0.000000
10.400001,0.799484,-311.366669,-0.001690,0.000038,0.000954,3.556283,0.181166,0.009542,-311.366669,0.002029,0.000000
10.890000,1.037804,-311.455627,-0.001673,0.000081,0.002047,4.616381,0.235170,0.020469,-311.455627,0.002845,0.000000
11.380000,1.112274,-311.500092,-0.001638,0.000104,0.002654,4.947643,0.252045,0.026536,-311.500092,0.003660,0.000000
11.870001,1.445923,-311.455627,-0.001608,0.000146,0.003721,6.431786,0.327651,0.037206,-311.455627,0.004475,0.000000
12.360001,1.672699,-311.500092,-0.001578,0.000174,0.004423,7.440536,0.379039,0.044230,-311.500092,0.005290,0.000000
12.850000,1.881599,-311.544586,-0.001544,0.000206,0.005230,8.369772,0.426377,0.052296,-311.544586,0.006114,0.000000
13.340001,2.050659,-311.633545,-0.001531,0.000232,0.005889,9.121788,0.464686,0.058885,-311.633545,0.006929,0.000000
13.830001,2.560059,-311.633545,-0.001492,0.000267,0.006773,11.387710,0.580118,0.067731,-311.633545,0.007744,0.000000
14.320001,2.832268,-311.633545,-0.001466,0.000292,0.007415,12.598557,0.641801,0.074150,-311.633545,0.008560,0.000000
14.810000,3.527489,-311.811462,-0.001418,0.000336,0.008525,15.691053,0.799340,0.085247,-311.811462,0.009375,0.000000
15.300001,3.985504,-311.766998,-0.001406,0.000364,0.009236,17.728409,0.903128,0.092359,-311.766998,0.010190,0.000000
15.790001,4.810684,-311.766998,-0.001367,0.000402,0.010207,21.398993,1.090117,0.102075,-311.766998,0.011014,0.000000
16.280001,5.152519,-311.811462,-0.001341,0.000423,0.010745,22.919550,1.167578,0.107449,-311.811462,0.011829,0.000000
16.770000,6.303894,-311.811462,-0.001302,0.000464,0.011777,28.041121,1.428483,0.117771,-311.811462,0.012644,0.000000
17.260000,6.920540,-311.944916,-0.001293,0.000490,0.012453,30.784100,1.568217,0.124534,-311.944916,0.013459,0.000000
17.750000,8.061119,-311.900421,-0.001259,0.000526,0.013373,35.857647,1.826676,0.133728,-311.900421,0.014275,0.000000
18.240002,8.755592,-311.989380,-0.001250,0.000551,0.014006,38.946819,1.984046,0.140056,-311.989380,0.015090,0.000000
18.730001,10.375046,-311.989380,-0.001207,0.000593,0.015055,46.150509,2.351019,0.150552,-311.989380,0.015914,0.000000
19.220001,11.324593,-311.989380,-0.001190,0.000623,0.015827,50.374302,2.566189,0.158269,-311.989380,0.016729,0.000000
19.710001,12.707214,-312.122833,-0.001186,0.000657,0.016677,56.524513,2.879496,0.166766,-312.122833,0.017544,0.000000
20.200001,13.504837,-312.078339,-0.001143,0.000681,0.017292,60.072514,3.060240,0.172924,-312.078339,0.018359,0.000000
20.690001,15.388664,-312.122833,-0.001130,0.000722,0.018333,68.452194,3.487121,0.183333,-312.122833,0.019174,0.000000
21.180000,16.492004,-312.122833,-0.001099,0.000750,0.019053,73.360100,3.737142,0.190532,-312.122833,0.019998,0.000000
21.670000,18.087997,-312.167328,-0.001087,0.000784,0.019903,80.459435,4.098799,0.199029,-312.167328,0.020814,0.000000
22.160002,18.998070,-312.300751,-0.001056,0.000807,0.020501,84.507637,4.305024,0.205013,-312.300751,0.021629,0.000000
22.650002,21.413277,-312.256287,-0.001035,0.000852,0.021646,95.251015,4.852318,0.216462,-312.256287,0.022444,0.000000
23.140001,22.307343,-312.345245,-0.001022,0.000876,0.022262,99.228012,5.054916,0.222616,-312.345245,0.023259,0.000000
23.630001,24.018768,-312.300751,-0.001000,0.000908,0.023059,106.840820,5.442731,0.230595,-312.300751,0.024074,0.000000
24.120001,23.538040,-312.300751,-0.000979,0.000905,0.022999,104.702431,5.333796,0.229989,-312.300751,0.023233,0.000000
24.610001,23.067734,-312.434204,-0.000974,0.000898,0.022817,102.610405,5.227223,0.228169,-312.434204,0.022513,0.000000
25.100000,22.708015,-312.389709,-0.000987,0.000875,0.022218,101.010300,5.145710,0.222185,-312.389709,0.021698,0.000000
25.590002,22.455925,-312.434204,-0.000979,0.000844,0.021438,99.888947,5.088585,0.214380,-312.434204,0.020883,0.000000
26.080002,22.317024,-312.478668,-0.000974,0.000817,0.020753,99.271080,5.057110,0.207526,-312.478668,0.020068,0.000000
26.570002,22.147224,-312.523163,-0.000966,0.000782,0.019859,98.515778,5.018633,0.198593,-312.523163,0.019253,0.000000
27.060001,22.026581,-312.567657,-0.000966,0.000752,0.019105,97.979126,4.991295,0.191050,-312.567657,0.018437,0.000000
27.550001,21.928642,-312.523163,-0.000983,0.000728,0.018498,97.543472,4.969101,0.184979,-312.523163,0.017613,0.000000
28.040001,21.761452,-312.612122,-0.000970,0.000691,0.017553,96.799774,4.931216,0.175528,-312.612122,0.016798,0.000000
28.530001,21.514938,-312.701080,-0.000961,0.000661,0.016789,95.703224,4.875355,0.167894,-312.701080,0.015983,0.000000
29.020000,20.481232,-312.745575,-0.000957,0.000629,0.015975,91.105072,4.641114,0.159745,-312.745575,0.015168,0.000000
29.510002,19.355179,-312.745575,-0.000949,0.000602,0.015289,86.096138,4.385946,0.152891,-312.745575,0.014353,0.000000
30.000002,17.543961,-312.834534,-0.000970,0.000573,0.014543,78.039436,3.975518,0.145435,-312.834534,0.013537,0.000000
30.490002,15.615440,-312.834534,-0.000953,0.000545,0.013832,69.460945,3.538509,0.138323,-312.834534,0.012713,0.000000
30.980001,14.846863,-312.834534,-0.000961,0.000527,0.013390,66.042145,3.364347,0.133902,-312.834534,0.011899,0.000000
31.470001,11.188301,-312.834534,-0.000970,0.000491,0.012471,49.768047,2.535305,0.124709,-312.834534,0.011083,0.000000
31.960001,7.688004,-312.878998,-0.000966,0.000449,0.011413,34.197948,1.742127,0.114126,-312.878998,0.010268,0.000000
32.450001,4.720566,-312.923492,-0.000983,0.000415,0.010537,20.998125,1.069695,0.105368,-312.923492,0.009453,0.000000
32.940002,2.409248,-312.967957,-0.001000,0.000386,0.009817,10.716872,0.545943,0.098169,-312.967957,0.008629,0.000000
33.430000,0.920509,-313.012451,-0.001000,0.000367,0.009314,4.094630,0.208590,0.093139,-313.012451,0.007814,0.000000
33.920002,0.043198,-313.056946,-0.001039,0.000319,0.008109,0.192153,0.009789,0.081088,-313.056946,0.006999,0.000000
34.410000,-0.001114,-313.012451,-0.001078,0.000285,0.007241,-0.004955,-0.000252,0.072413,-313.012451,0.006183,0.000000
34.900002,-0.023087,-313.145905,-0.001108,0.000257,0.006530,-0.102694,-0.005231,0.065301,-313.145905,0.005368,0.000000
35.390003,-0.025696,-313.190369,-0.001138,0.000229,0.005811,-0.114301,-0.005823,0.058106,-313.190369,0.004553,0.000000
35.880001,-0.035004,-313.190369,-0.001181,0.000186,0.004735,-0.155704,-0.007932,0.047353,-313.190369,0.003729,0.000000
36.370003,-0.049149,-313.234863,-0.001212,0.000153,0.003894,-0.218624,-0.011137,0.038939,-313.234863,0.002914,0.000000
36.860001,-0.027557,-313.190369,-0.001237,0.000137,0.003478,-0.122581,-0.006245,0.034776,-313.190369,0.002099,0.000000
37.350002,-0.039841,-313.323822,-0.001306,0.000087,0.002212,-0.177220,-0.009028,0.022115,-313.323822,0.001283,0.000000
37.840000,-0.021599,-313.368286,-0.001328,0.000055,0.001405,-0.096076,-0.004894,0.014050,-313.368286,0.000468,0.000000
38.330002,-0.029045,-313.368286,-0.001354,0.000024,0.000607,-0.129199,-0.006582,0.006071,-313.368286,-0.000347,0.000000
38.820004,-0.032768,-313.457275,-0.001397,-0.000000,-0.000000,-0.145760,-0.007425,-0.000000,-313.457275,-0.001162,0.000000
39.310001,-0.012283,-313.368286,-0.001388,0.000003,0.000087,-0.054639,-0.002783,0.000867,-313.368286,0.000208,0.000000
39.800003,-0.061813,-313.457275,-0.001380,0.000029,0.000729,-0.274960,-0.014007,0.007286,-313.457275,0.001023,0.000000
40.290001,0.003349,-313.457275,-0.001384,0.000057,0.001440,0.014898,0.000759,0.014398,-313.457275,0.001839,0.000000
40.780003,0.011543,-313.546234,-0.001388,0.000090,0.002289,0.051347,0.002616,0.022895,-313.546234,0.002654,0.000000
41.270000,0.012291,-313.635193,-0.001375,0.000120,0.003035,0.054673,0.002785,0.030355,-313.635193,0.003469,0.000000
41.760002,0.000748,-313.635193,-0.001380,0.000153,0.003894,0.003326,0.000169,0.038939,-313.635193,0.004284,0.000000
42.250004,-0.009682,-313.679657,-0.001375,0.000180,0.004579,-0.043066,-0.002194,0.045790,-313.679657,0.005108,0.000000
42.740002,0.010803,-313.679657,-0.001380,0.000217,0.005516,0.048055,0.002448,0.055157,-313.679657,0.005923,0.000000
43.230003,-0.015640,-313.768616,-0.001380,0.000238,0.006053,-0.069571,-0.003544,0.060532,-313.768616,0.006738,0.000000
43.720001,-0.038727,-313.768616,-0.001393,0.000267,0.006790,-0.172265,-0.008776,0.067905,-313.768616,0.007554,0.000000
44.210003,0.019363,-313.768616,-0.001384,0.000296,0.007519,0.086133,0.004388,0.075191,-313.768616,0.008369,0.000000
44.700001,0.006706,-313.813110,-0.001367,0.000333,0.008464,0.029831,0.001520,0.084642,-313.813110,0.009193,0.000000
45.190002,-0.018990,-313.857605,-0.001332,0.000360,0.009149,-0.084470,-0.004303,0.091492,-313.857605,0.010008,0.000000
45.680000,-0.010422,-313.902069,-0.001324,0.000392,0.009956,-0.046358,-0.002362,0.099558,-313.902069,0.010823,0.000000
46.170002,0.032768,-313.991028,-0.001276,0.000421,0.010693,0.145760,0.007425,0.106931,-313.991028,0.011638,0.000000
46.660004,0.048035,-313.946564,-0.001237,0.000460,0.011682,0.213669,0.010885,0.116817,-313.946564,0.012453,0.000000
47.150002,0.032394,-314.035522,-0.001220,0.000486,0.012349,0.144098,0.007341,0.123494,-314.035522,0.013269,0.000000
47.640003,0.100914,-314.035522,-0.001194,0.000518,0.013165,0.448888,0.022867,0.131646,-314.035522,0.014092,0.000000
48.130001,0.170174,-314.079987,-0.001151,0.000549,0.013936,0.756970,0.038562,0.139364,-314.079987,0.014908,0.000000
48.620003,0.324341,-314.124481,-0.001125,0.000583,0.014803,1.442740,0.073497,0.148035,-314.124481,0.015723,0.000000
49.110001,0.646065,-314.079987,-0.001095,0.000618,0.015688,2.873840,0.146400,0.156880,-314.079987,0.016538,0.000000
49.600002,1.569176,-314.213440,-0.001074,0.000649,0.016495,6.980042,0.355580,0.164946,-314.213440,0.017353,0.000000
50.090004,3.199799,-314.213440,-0.001052,0.000674,0.017128,14.233415,0.725085,0.171278,-314.213440,0.018168,0.000000
50.580002,5.974716,-314.302399,-0.001043,0.000712,0.018082,26.576864,1.353890,0.180816,-314.302399,0.018992,0.000000
51.070004,8.850174,-314.257904,-0.001022,0.000745,0.018932,39.367538,2.005478,0.189317,-314.257904,0.019807,0.000000
51.560001,11.335022,-314.302399,-0.001022,0.000773,0.019634,50.420696,2.568553,0.196341,-314.302399,0.020623,0.000000
52.050003,13.809059,-314.346893,-0.001005,0.000800,0.020319,61.425762,3.129177,0.203192,-314.346893,0.021438,0.000000
52.540001,17.691048,-314.346893,-0.001009,0.000844,0.021447,78.693710,4.008849,0.214467,-314.346893,0.022253,0.000000
53.030003,20.005341,-314.480316,-0.000987,0.000871,0.022132,88.988197,4.533275,0.221318,-314.480316,0.023077,0.000000
53.520004,22.283142,-314.480316,-0.000987,0.000900,0.022860,99.120369,5.049432,0.228600,-314.480316,0.023892,0.000000
54.010002,24.761650,-314.524811,-0.000974,0.000928,0.023580,110.145317,5.611070,0.235799,-314.524811,0.024707,0.000000
54.500004,28.572510,-314.613770,-0.000953,0.000977,0.024812,127.096870,6.474624,0.248115,-314.613770,0.025523,0.000000
54.990002,29.840813,-314.480316,-0.000931,0.001001,0.025419,132.738571,6.762025,0.254186,-314.480316,0.026338,0.000000
55.480003,32.287300,-314.613770,-0.000927,0.001040,0.026407,143.621078,7.316407,0.264072,-314.613770,0.027153,0.000000
55.970001,33.566772,-314.613770,-0.000892,0.001065,0.027049,149.312454,7.606339,0.270488,-314.613770,0.027977,0.000000
56.460003,34.744957,-314.702728,-0.000884,0.001085,0.027560,154.553284,7.873320,0.275605,-314.702728,0.027716,0.000000
56.950005,33.792427,-314.702728,-0.000880,0.001077,0.027352,150.316223,7.657474,0.273523,-314.702728,0.027135,0.000000
57.440002,33.352661,-314.658234,-0.000871,0.001057,0.026841,148.360046,7.557821,0.268406,-314.658234,0.026321,0.000000
57.930004,32.991455,-314.791687,-0.000862,0.001033,0.026251,146.753326,7.475971,0.262509,-314.791687,0.025505,0.000000
58.420002,32.773994,-314.791687,-0.000858,0.000997,0.025332,145.786011,7.426693,0.253315,-314.791687,0.024690,0.000000
58.910004,32.533813,-314.880646,-0.000867,0.000960,0.024395,144.717636,7.372267,0.243952,-314.880646,0.023875,0.000000
59.400002,32.366615,-314.925140,-0.000862,0.000928,0.023571,143.973892,7.334380,0.235712,-314.925140,0.023051,0.000000
59.890003,32.200165,-314.880646,-0.000867,0.000904,0.022964,143.233490,7.296661,0.229641,-314.880646,0.022236,0.000000
60.380001,32.078400,-314.925140,-0.000871,0.000870,0.022088,142.691849,7.269069,0.220883,-314.925140,0.021421,0.000000
60.870003,31.564522,-314.969604,-0.000849,0.000841,0.021360,140.406006,7.152623,0.213597,-314.969604,0.020605,0.000000
61.360004,30.883087,-315.014099,-0.000845,0.000818,0.020787,137.374832,6.998208,0.207874,-315.014099,0.019790,0.000000
61.850002,28.969833,-315.014099,-0.000849,0.000778,0.019773,128.864258,6.564658,0.197727,-315.014099,0.018975,0.000000
62.340004,27.025307,-315.103058,-0.000841,0.000752,0.019105,120.214569,6.124022,0.191050,-315.103058,0.018151,0.000000
62.830002,25.411812,-315.147552,-0.000845,0.000732,0.018585,113.037384,5.758399,0.185846,-315.147552,0.017336,0.000000
63.320004,22.336761,-315.103058,-0.000845,0.000692,0.017587,99.358879,5.061583,0.175873,-315.103058,0.016521,0.000000
63.810001,20.437660,-315.192017,-0.000862,0.000673,0.017084,90.911255,4.631240,0.170843,-315.192017,0.015705,0.000000
64.300003,17.268028,-315.192017,-0.000858,0.000642,0.016313,76.812027,3.912991,0.163125,-315.192017,0.014890,0.000000
64.790001,14.366501,-315.236511,-0.000854,0.000615,0.015610,63.905388,3.255496,0.156100,-315.236511,0.014067,0.000000
65.280006,9.893196,-315.325470,-0.000880,0.000568,0.014422,44.007133,2.241830,0.144220,-315.325470,0.013251,0.000000
65.770004,6.720207,-315.280975,-0.000888,0.000533,0.013546,29.892975,1.522821,0.135461,-315.280975,0.012436,0.000000
66.260002,4.230896,-315.369934,-0.000880,0.000511,0.012991,18.819965,0.958735,0.129913,-315.369934,0.011621,0.000000
66.750000,0.730225,-315.369934,-0.000905,0.000465,0.011820,3.248201,0.165471,0.118202,-315.369934,0.010805,0.000000
67.240005,0.116928,-315.369934,-0.000923,0.000437,0.011092,0.520122,0.026496,0.110920,-315.369934,0.009991,0.000000
67.730003,0.017876,-315.458893,-0.000961,0.000406,0.010303,0.079515,0.004051,0.103029,-315.458893,0.009167,0.000000
68.220001,-0.001114,-315.503387,-0.000992,0.000379,0.009617,-0.004955,-0.000252,0.096174,-315.503387,0.008351,0.000000
68.710007,-0.034630,-315.503387,-0.001018,0.000349,0.008854,-0.154041,-0.007847,0.088544,-315.503387,0.007536,0.000000
69.200005,-0.044312,-315.547852,-0.001069,0.000310,0.007874,-0.197107,-0.010041,0.078745,-315.547852,0.006721,0.000000
69.690002,-0.038727,-315.592346,-0.001095,0.000276,0.007016,-0.172265,-0.008776,0.070161,-315.592346,0.005906,0.000000
70.180000,-0.037979,-315.681305,-0.001108,0.000263,0.006669,-0.168940,-0.008606,0.066690,-315.681305,0.005091,0.000000
70.670006,-0.039101,-315.681305,-0.001173,0.000206,0.005221,-0.173928,-0.008860,0.052209,-315.681305,0.004267,0.000000
71.160004,-0.042824,-315.725800,-0.001199,0.000167,0.004232,-0.190490,-0.009704,0.042323,-315.725800,0.003451,0.000000
71.650002,0.011917,-315.725800,-0.001216,0.000149,0.003790,0.053010,0.002700,0.037898,-315.725800,0.002637,0.000000
72.140007,-0.059952,-315.770264,-0.001263,0.000113,0.002862,-0.266679,-0.013585,0.028618,-315.770264,0.001821,0.000000
72.630005,-0.029785,-315.814758,-0.001293,0.000074,0.001873,-0.132491,-0.006749,0.018731,-315.814758,0.001006,0.000000
73.120003,-0.036118,-315.814758,-0.001328,0.000047,0.001205,-0.160659,-0.008184,0.012055,-315.814758,0.000182,0.000000
73.610001,-0.036118,-315.903717,-0.001358,0.000015,0.000382,-0.160659,-0.008184,0.003815,-315.903717,-0.000633,0.000000
74.100006,-0.020103,-315.948181,-0.001380,0.000003,0.000069,-0.089425,-0.004556,0.000693,-315.948181,-0.000009,0.000000
74.590004,-0.092720,-315.992676,-0.001384,0.000009,0.000226,-0.412439,-0.021011,0.002256,-315.992676,0.000434,0.000000
75.080002,-0.004471,-315.948181,-0.001375,0.000034,0.000867,-0.019887,-0.001013,0.008671,-315.948181,0.001257,0.000000
75.570007,0.020851,-316.037170,-0.001380,0.000064,0.001622,0.092750,0.004725,0.016218,-316.037170,0.002073,0.000000
76.060005,0.015266,-316.081635,-0.001388,0.000096,0.002446,0.067908,0.003459,0.024458,-316.081635,0.002888,0.000000
76.550003,-0.038353,-316.037170,-0.001393,0.000124,0.003148,-0.170603,-0.008691,0.031479,-316.037170,0.003703,0.000000
77.040001,-0.029045,-316.170593,-0.001384,0.000159,0.004033,-0.129199,-0.006582,0.040328,-316.170593,0.004518,0.000000
77.530006,-0.013405,-316.170593,-0.001380,0.000190,0.004822,-0.059628,-0.003038,0.048220,-316.170593,0.005342,0.000000
78.020004,-0.032394,-316.170593,-0.001384,0.000223,0.005663,-0.144098,-0.007341,0.056630,-316.170593,0.006157,0.000000
78.510002,-0.001114,-316.215088,-0.001384,0.000248,0.006287,-0.004955,-0.000252,0.062875,-316.215088,0.006973,0.000000
79.000000,-0.003723,-316.215088,-0.001384,0.000280,0.007120,-0.016561,-0.000844,0.071201,-316.215088,0.007788,0.000000
79.490005,0.005211,-316.304047,-0.001375,0.000301,0.007658,0.023179,0.001181,0.076576,-316.304047,0.008603,0.000000
79.980003,-0.001862,-316.304047,-0.001341,0.000342,0.008690,-0.008281,-0.000422,0.086897,-316.304047,0.009418,0.000000
80.470001,-0.018616,-316.437500,-0.001332,0.000370,0.009410,-0.082807,-0.004218,0.094096,-316.437500,0.010242,0.000000
80.960007,-0.016014,-316.393005,-0.001276,0.000406,0.010311,-0.071234,-0.003629,0.103112,-316.393005,0.011057,0.000000
81.450005,0.004471,-316.393005,-0.001289,0.000427,0.010849,0.019887,0.001013,0.108490,-316.393005,0.011872,0.000000
81.940002,0.024574,-316.437500,-0.001242,0.000465,0.011812,0.109312,0.005569,0.118115,-316.437500,0.012688,0.000000
82.430000,-0.029419,-316.437500,-0.001207,0.000492,0.012488,-0.130862,-0.006666,0.124883,-316.437500,0.013503,0.000000
82.920006,0.003349,-316.570923,-0.001186,0.000529,0.013425,0.014898,0.000759,0.134246,-316.570923,0.014318,0.000000
83.410004,0.007080,-316.481964,-0.001155,0.000553,0.014049,0.031494,0.001604,0.140492,-316.481964,0.015142,0.000000
83.900002,0.044685,-316.481964,-0.001117,0.000594,0.015081,0.198770,0.010126,0.150813,-316.481964,0.015957,0.000000
84.390007,0.083786,-316.615417,-0.001074,0.000624,0.015862,0.372699,0.018986,0.158617,-316.615417,0.016772,0.000000
84.880005,0.159378,-316.615417,-0.001048,0.000660,0.016764,0.708949,0.036116,0.167637,-316.615417,0.017587,0.000000
85.370003,0.260292,-316.704376,-0.001030,0.000683,0.017353,1.157837,0.058983,0.173534,-316.704376,0.018403,0.000000
85.860001,0.672882,-316.570923,-0.000996,0.000723,0.018359,2.993129,0.152477,0.183594,-316.570923,0.019227,0.000000
86.350006,1.459328,-316.793335,-0.000966,0.000751,0.019070,6.491414,0.330688,0.190702,-316.793335,0.020042,0.000000
86.840004,3.643295,-316.793335,-0.000949,0.000785,0.019946,16.206186,0.825583,0.199464,-316.793335,0.020857,0.000000
87.330002,6.004509,-316.793335,-0.000936,0.000814,0.020666,26.709391,1.360641,0.206659,-316.793335,0.021672,0.000000
87.820007,10.283066,-316.793335,-0.000927,0.000856,0.021750,45.741360,2.330176,0.217499,-316.793335,0.022487,0.000000
88.310005,12.577629,-316.882294,-0.000918,0.000880,0.022357,55.948090,2.850132,0.223570,-316.882294,0.023302,0.000000
88.800003,15.613579,-316.926788,-0.000914,0.000911,0.023129,69.452667,3.538087,0.231291,-316.926788,0.024126,0.000000
89.290001,19.133987,-316.926788,-0.000914,0.000948,0.024092,85.112228,4.335824,0.240916,-316.926788,0.024941,0.000000
89.780006,23.190239,-316.971252,-0.000905,0.000985,0.025020,103.155334,5.254983,0.250197,-316.971252,0.025757,0.000000
90.270004,25.422615,-317.060211,-0.000884,0.001010,0.025653,113.085442,5.760847,0.256525,-317.060211,0.026572,0.000000
90.760002,29.268105,-317.015747,-0.000875,0.001049,0.026641,130.191025,6.632247,0.266411,-317.015747,0.027387,0.000000
91.250008,32.279854,-317.060211,-0.000880,0.001082,0.027483,143.587967,7.314719,0.274825,-317.060211,0.028202,0.000000
91.740005,35.198509,-317.104706,-0.000841,0.001114,0.028289,156.570786,7.976096,0.282891,-317.104706,0.029026,0.000000
92.230003,37.151604,-317.149170,-0.000862,0.001137,0.028870,165.258591,8.418674,0.288700,-317.149170,0.029841,0.000000
92.720001,40.056480,-317.238129,-0.000841,0.001171,0.029737,178.180130,9.076928,0.297372,-317.238129,0.030657,0.000000
93.210007,42.457161,-317.238129,-0.000832,0.001203,0.030561,188.858887,9.620931,0.305611,-317.238129,0.031472,0.000000
93.700005,43.591782,-317.282623,-0.000819,0.001218,0.030934,193.905930,9.878039,0.309339,-317.282623,0.031099,0.000000
94.190002,42.740913,-317.327118,-0.000802,0.001209,0.030708,190.121078,9.685230,0.307084,-317.327118,0.030492,0.000000
94.680008,42.297043,-317.282623,-0.000806,0.001186,0.030136,188.146637,9.584646,0.301361,-317.282623,0.029677,0.000000
95.170006,41.948502,-317.416077,-0.000798,0.001166,0.029624,186.596252,9.505666,0.296244,-317.416077,0.028861,0.000000
95.660004,41.708321,-317.416077,-0.000806,0.001129,0.028688,185.527878,9.451241,0.286880,-317.416077,0.028037,0.000000
96.150002,41.449150,-317.416077,-0.000793,0.001092,0.027734,184.375031,9.392512,0.277338,-317.416077,0.027222,0.000000
96.640007,41.278236,-317.460541,-0.000793,0.001061,0.026953,183.614761,9.353783,0.269534,-317.460541,0.026407,0.000000
97.130005,41.114014,-317.460541,-0.000802,0.001040,0.026407,182.884262,9.316568,0.264072,-317.460541,0.025592,0.000000
97.620003,40.966560,-317.593994,-0.000793,0.001002,0.025453,182.228363,9.283155,0.254530,-317.593994,0.024777,0.000000
98.110008,40.283997,-317.593994,-0.000793,0.000971,0.024655,179.192169,9.128485,0.246552,-317.593994,0.023961,0.000000
98.600006,39.041389,-317.682953,-0.000785,0.000937,0.023797,173.664780,8.846906,0.237968,-317.682953,0.023138,0.000000
99.090004,37.755959,-317.593994,-0.000780,0.000916,0.023268,167.946884,8.555622,0.232676,-317.593994,0.022323,0.000000
99.580002,35.772705,-317.727448,-0.000789,0.000884,0.022452,159.124939,8.106211,0.224524,-317.727448,0.021507,0.000000
100.070007,34.206505,-317.771912,-0.000785,0.000866,0.022002,152.158127,7.751305,0.220016,-317.771912,0.020692,0.000000
100.560005,30.695778,-317.727448,-0.000789,0.000824,0.020926,136.541641,6.955762,0.209263,-317.727448,0.019877,0.000000
101.050003,27.027168,-317.771912,-0.000793,0.000787,0.019981,120.222847,6.124444,0.199808,-317.771912,0.019061,0.000000
101.540009,25.259140,-317.860870,-0.000798,0.000772,0.019617,112.358269,5.723803,0.196167,-317.860870,0.018238,0.000000
102.030006,21.113892,-317.860870,-0.000802,0.000732,0.018585,93.919281,4.784476,0.185846,-317.860870,0.017423,0.000000
102.520004,17.805733,-317.860870,-0.000798,0.000696,0.017683,79.203857,4.034837,0.176827,-317.860870,0.016607,0.000000
103.010002,15.108269,-317.816406,-0.000811,0.000674,0.017128,67.204933,3.423583,0.171278,-317.816406,0.015792,0.000000
103.500008,11.512268,-317.949829,-0.000828,0.000631,0.016018,51.209126,2.608717,0.160177,-317.949829,0.014977,0.000000
103.990005,7.758011,-317.949829,-0.000832,0.000600,0.015237,34.509357,1.757990,0.152372,-317.949829,0.014153,0.000000
104.480003,4.787224,-317.994324,-0.000832,0.000572,0.014517,21.294636,1.084800,0.145173,-317.994324,0.013338,0.000000
104.970001,1.784409,-317.994324,-0.000832,0.000537,0.013633,7.937446,0.404353,0.136328,-317.994324,0.012523,0.000000
105.460007,0.173897,-318.038788,-0.000845,0.000500,0.012688,0.773532,0.039406,0.126877,-318.038788,0.011707,0.000000
105.950005,0.007080,-318.127777,-0.000888,0.000468,0.011899,0.031494,0.001604,0.118986,-318.127777,0.010893,0.000000
106.440002,-0.049896,-318.127777,-0.000936,0.000439,0.011161,-0.221950,-0.011307,0.111613,-318.127777,0.010077,0.000000
106.930008,-0.032394,-318.216736,-0.000966,0.000412,0.010468,-0.144098,-0.007341,0.104675,-318.216736,0.009253,0.000000
107.420006,-0.041328,-318.216736,-0.000983,0.000383,0.009722,-0.183838,-0.009365,0.097215,-318.216736,0.008438,0.000000
107.910004,-0.043938,-318.261200,-0.001048,0.000335,0.008508,-0.195445,-0.009956,0.085077,-318.261200,0.007623,0.000000
108.400002,-0.052132,-318.305695,-0.001048,0.000312,0.007918,-0.231893,-0.011813,0.079180,-318.305695,0.006808,0.000000
108.890007,0.007446,-318.261200,-0.001095,0.000282,0.007155,0.033123,0.001687,0.071546,-318.261200,0.005993,0.000000
109.380005,-0.038353,-318.305695,-0.001117,0.000262,0.006660,-0.170603,-0.008691,0.066603,-318.305695,0.005177,0.000000
109.870003,-0.032394,-318.394653,-0.001151,0.000225,0.005724,-0.144098,-0.007341,0.057239,-318.394653,0.004353,0.000000
110.360008,-0.057716,-318.483612,-0.001207,0.000181,0.004605,-0.256735,-0.013079,0.046051,-318.483612,0.003538,0.000000
110.850006,-0.024948,-318.439117,-0.001220,0.000150,0.003799,-0.110975,-0.005653,0.037985,-318.439117,0.002723,0.000000
111.340004,-0.080429,-318.483612,-0.001242,0.000127,0.003226,-0.357766,-0.018225,0.032262,-318.483612,0.001908,0.000000
111.830002,-0.039467,-318.483612,-0.001298,0.000076,0.001934,-0.175557,-0.008943,0.019341,-318.483612,0.001093,0.000000
112.320007,-0.039841,-318.572571,-0.001324,0.000050,0.001266,-0.177220,-0.009028,0.012660,-318.572571,0.000269,0.000000
112.810005,-0.054367,-318.661530,-0.001362,0.000018,0.000468,-0.241837,-0.012320,0.004682,-318.661530,-0.000546,0.000000
113.300003,-0.021599,-318.706024,-0.001384,0.000002,0.000052,-0.096076,-0.004894,0.000522,-318.706024,-0.000009,0.000000
113.790009,-0.017502,-318.661530,-0.001388,0.000003,0.000069,-0.077852,-0.003966,0.000693,-318.661530,0.000199,0.000000
114.280006,-0.066650,-318.706024,-0.001375,0.000029,0.000729,-0.296476,-0.015103,0.007286,-318.706024,0.001023,0.000000
114.770004,0.012291,-318.706024,-0.001388,0.000056,0.001431,0.054673,0.002785,0.014311,-318.706024,0.001839,0.000000
115.260002,0.008942,-318.706024,-0.001384,0.000090,0.002281,0.039774,0.002026,0.022808,-318.706024,0.002654,0.000000
115.750008,-0.000000,-318.794983,-0.001380,0.000120,0.003035,-0.000000,-0.000000,0.030355,-318.794983,0.003469,0.000000
116.240005,-0.007446,-318.839447,-0.001371,0.000154,0.003903,-0.033123,-0.001687,0.039026,-318.839447,0.004284,0.000000
116.730003,-0.021965,-318.883942,-0.001380,0.000179,0.004553,-0.097705,-0.004977,0.045529,-318.883942,0.005099,0.000000
117.220009,-0.030533,-318.883942,-0.001375,0.000214,0.005437,-0.135817,-0.006919,0.054374,-318.883942,0.005923,0.000000
117.710007,-0.028297,-318.928406,-0.001397,0.000237,0.006019,-0.125873,-0.006412,0.060187,-318.928406,0.006738,0.000000
118.200005,-0.033142,-319.017395,-0.001380,0.000267,0.006782,-0.147423,-0.007510,0.067818,-319.017395,0.007554,0.000000
118.690002,0.008568,-318.972900,-0.001375,0.000295,0.007502,0.038112,0.001941,0.075017,-318.972900,0.008369,0.000000
119.180008,0.013405,-319.061859,-0.001354,0.000333,0.008455,0.059628,0.003038,0.084555,-319.061859,0.009184,0.000000
119.670006,-0.021225,-319.061859,-0.001337,0.000360,0.009149,-0.094413,-0.004810,0.091492,-319.061859,0.009999,0.000000
120.160004,-0.013031,-319.061859,-0.001306,0.000391,0.009930,-0.057965,-0.002953,0.099297,-319.061859,0.010823,0.000000
120.650009,0.012291,-319.150818,-0.001281,0.000421,0.010684,0.054673,0.002785,0.106844,-319.150818,0.011638,0.000000
121.140007,0.000374,-319.150818,-0.001250,0.000459,0.011664,0.001663,0.000085,0.116643,-319.150818,0.012453,0.000000
121.630005,-0.035378,-319.239777,-0.001220,0.000482,0.012237,-0.157367,-0.008017,0.122366,-319.239777,0.013269,0.000000
122.120003,-0.011169,-319.195312,-0.001199,0.000518,0.013156,-0.049684,-0.002531,0.131559,-319.195312,0.014084,0.000000
122.610008,-0.000374,-319.195312,-0.001177,0.000548,0.013928,-0.001663,-0.000085,0.139277,-319.195312,0.014908,0.000000
123.100006,-0.000374,-319.284271,-0.001147,0.000581,0.014769,-0.001663,-0.000085,0.147690,-319.284271,0.015723,0.000000
123.590004,0.001862,-319.284271,-0.001095,0.000616,0.015654,0.008281,0.000422,0.156536,-319.284271,0.016538,0.000000
124.080009,0.018623,-319.373230,-0.001052,0.000648,0.016460,0.082841,0.004220,0.164601,-319.373230,0.017353,0.000000
124.570007,0.064796,-319.373230,-0.001039,0.000674,0.017128,0.288229,0.014683,0.171278,-319.373230,0.018168,0.000000
125.060005,0.137779,-319.417725,-0.001000,0.000714,0.018143,0.612873,0.031221,0.181425,-319.417725,0.018984,0.000000
125.550003,0.259918,-319.506683,-0.000966,0.000746,0.018940,1.156174,0.058898,0.189404,-319.506683,0.019807,0.000000
126.040009,0.514244,-319.417725,-0.000940,0.000774,0.019669,2.287472,0.116529,0.196686,-319.417725,0.020623,0.000000
126.530006,1.066475,-319.551147,-0.000914,0.000800,0.020319,4.743917,0.241667,0.203192,-319.551147,0.021438,0.000000
127.020004,3.849960,-319.551147,-0.000888,0.000848,0.021533,17.125479,0.872413,0.215334,-319.551147,0.022253,0.000000
127.510010,6.023125,-319.551147,-0.000897,0.000873,0.022166,26.792196,1.364860,0.221662,-319.551147,0.023068,0.000000
128.000000,8.727295,-319.595642,-0.000871,0.000901,0.022886,38.820946,1.977633,0.228861,-319.595642,0.023883,0.000000
128.490005,11.746864,-319.640106,-0.000871,0.000930,0.023632,52.252663,2.661877,0.236321,-319.640106,0.024707,0.000000
128.980011,16.663300,-319.684601,-0.000858,0.000977,0.024820,74.122055,3.775958,0.248202,-319.684601,0.025523,0.000000
129.470001,19.151115,-319.684601,-0.000849,0.001001,0.025427,85.188416,4.339705,0.254269,-319.684601,0.026338,0.000000
129.960007,22.779510,-319.773560,-0.000845,0.001039,0.026390,101.328323,5.161911,0.263898,-319.773560,0.027153,0.000000
130.450012,25.661308,-319.773560,-0.000836,0.001066,0.027075,114.147202,5.814936,0.270749,-319.773560,0.027968,0.000000
130.940002,29.783096,-319.773560,-0.000815,0.001105,0.028072,132.481827,6.748946,0.280722,-319.773560,0.028792,0.000000
131.430008,32.002808,-319.862518,-0.000824,0.001128,0.028644,142.355591,7.251940,0.286445,-319.862518,0.029607,0.000000
131.920013,36.051239,-319.907013,-0.000806,0.001167,0.029642,160.363922,8.169328,0.296418,-319.907013,0.030422,0.000000
132.410004,38.705887,-319.907013,-0.000819,0.001195,0.030344,172.172379,8.770880,0.303443,-319.907013,0.031237,0.000000
132.900009,42.310822,-320.040436,-0.000798,0.001232,0.031281,188.207932,9.587770,0.312810,-320.040436,0.032053,0.000000
133.389999,44.757309,-319.951477,-0.000793,0.001261,0.032027,199.090454,10.142151,0.320266,-319.951477,0.032868,0.000000
133.880005,48.058762,-319.995972,-0.000776,0.001293,0.032851,213.776047,10.890271,0.328506,-319.995972,0.033692,0.000000
134.370010,50.470619,-320.040436,-0.000767,0.001320,0.033527,224.504532,11.436806,0.335270,-320.040436,0.034507,0.000000
134.860001,53.023605,-320.040436,-0.000767,0.001346,0.034195,235.860779,12.015321,0.341946,-320.040436,0.034342,0.000000
135.350006,52.223381,-320.129395,-0.000746,0.001344,0.034143,232.301193,11.833987,0.341428,-320.129395,0.033952,0.000000
135.840012,51.678223,-320.129395,-0.000759,0.001320,0.033527,229.876221,11.710453,0.335270,-320.129395,0.033128,0.000000
136.330002,51.243668,-320.173889,-0.000746,0.001292,0.032807,227.943222,11.611981,0.328071,-320.173889,0.032313,0.000000
136.820007,50.965134,-320.173889,-0.000750,0.001260,0.032001,226.704239,11.548864,0.320005,-320.173889,0.031498,0.000000
137.310013,50.724579,-320.218353,-0.000750,0.001227,0.031160,225.634201,11.494354,0.311595,-320.218353,0.030683,0.000000
137.800003,50.517914,-320.351807,-0.000746,0.001197,0.030405,224.714905,11.447523,0.304048,-320.351807,0.029867,0.000000
138.290009,50.389442,-320.351807,-0.000742,0.001173,0.029806,224.143433,11.418410,0.298064,-320.351807,0.029052,0.000000
138.780014,50.204002,-320.396301,-0.000737,0.001144,0.029052,223.318558,11.376390,0.290521,-320.396301,0.028228,0.000000
139.270004,49.583626,-320.351807,-0.000729,0.001106,0.028090,220.558990,11.235810,0.280896,-320.351807,0.027413,0.000000
139.760010,48.610245,-320.440765,-0.000724,0.001077,0.027352,216.229172,11.015239,0.273523,-320.440765,0.026598,0.000000
140.250000,47.286835,-320.529724,-0.000720,0.001048,0.026615,210.342346,10.715350,0.266154,-320.529724,0.025783,0.000000
140.740005,46.044601,-320.485260,-0.000724,0.001031,0.026199,204.816620,10.433856,0.261990,-320.485260,0.024967,0.000000
141.230011,43.131531,-320.574219,-0.000724,0.000990,0.025149,191.858627,9.773745,0.251495,-320.574219,0.024152,0.000000
141.720001,40.508163,-320.574219,-0.000720,0.000958,0.024326,180.189316,9.179281,0.243259,-320.574219,0.023329,0.000000
142.210007,36.991478,-320.618683,-0.000724,0.000923,0.023433,164.546310,8.382389,0.234327,-320.618683,0.022513,0.000000
142.700012,34.654846,-320.707672,-0.000733,0.000900,0.022860,154.152451,7.852901,0.228600,-320.707672,0.021698,0.000000
143.190002,31.008575,-320.663177,-0.000733,0.000868,0.022036,137.933029,7.026644,0.220364,-320.663177,0.020883,0.000000
143.680008,27.547745,-320.796631,-0.000737,0.000831,0.021117,122.538490,6.242408,0.211171,-320.796631,0.020068,0.000000
144.170013,23.142578,-320.752136,-0.000737,0.000793,0.020155,102.943329,5.244183,0.201546,-320.752136,0.019244,0.000000
144.660004,20.804077,-320.841095,-0.000742,0.000775,0.019677,92.541161,4.714271,0.196773,-320.841095,0.018429,0.000000
145.150009,16.725479,-320.796631,-0.000755,0.000732,0.018602,74.398643,3.790048,0.186020,-320.796631,0.017613,0.000000
145.639999,14.269318,-320.841095,-0.000767,0.000712,0.018073,63.473095,3.233474,0.180729,-320.841095,0.016798,0.000000
146.130005,10.396637,-320.930054,-0.000772,0.000674,0.017119,46.246552,2.355912,0.171191,-320.930054,0.015983,0.000000
146.620010,7.046776,-320.885590,-0.000767,0.000643,0.016321,31.345625,1.596822,0.163212,-320.885590,0.015168,0.000000
147.110001,3.579987,-320.974548,-0.000780,0.000607,0.015419,15.924576,0.811237,0.154193,-320.974548,0.014344,0.000000
147.600006,0.809540,-320.930054,-0.000785,0.000576,0.014639,3.601013,0.183444,0.146388,-320.930054,0.013529,0.000000
148.090012,0.172035,-320.974548,-0.000815,0.000542,0.013772,0.765251,0.038984,0.137717,-320.974548,0.012713,0.000000
148.580002,0.043571,-321.152466,-0.000849,0.000512,0.013000,0.193816,0.009873,0.129996,-321.152466,0.011899,0.000000
149.070007,-0.001488,-321.063507,-0.000862,0.000486,0.012349,-0.006618,-0.000337,0.123494,-321.063507,0.011083,0.000000
149.560013,-0.074471,-321.107971,-0.000918,0.000446,0.011326,-0.331261,-0.016875,0.113259,-321.107971,0.010268,0.000000
150.050003,-0.049149,-321.196960,-0.000957,0.000414,0.010519,-0.218624,-0.011137,0.105194,-321.196960,0.009444,0.000000
150.540009,-0.056602,-321.196960,-0.000966,0.000388,0.009860,-0.251780,-0.012826,0.098604,-321.196960,0.008629,0.000000
151.030014,-0.056229,-321.330383,-0.001026,0.000352,0.008950,-0.250117,-0.012742,0.089498,-321.330383,0.007814,0.000000
151.520004,-0.049149,-321.241425,-0.001048,0.000318,0.008065,-0.218624,-0.011137,0.080652,-321.241425,0.006999,0.000000
152.010010,-0.035744,-321.285919,-0.001099,0.000284,0.007224,-0.158996,-0.008100,0.072242,-321.285919,0.006183,0.000000
152.500000,-0.058464,-321.374878,-0.001130,0.000251,0.006374,-0.260061,-0.013248,0.063741,-321.374878,0.005359,0.000000
152.990005,-0.037979,-321.330383,-0.001147,0.000228,0.005802,-0.168940,-0.008606,0.058019,-321.330383,0.004544,0.000000
153.480011,-0.046921,-321.419342,-0.001199,0.000185,0.004709,-0.208714,-0.010632,0.047092,-321.419342,0.003729,0.000000
153.970001,-0.045059,-321.419342,-0.001220,0.000154,0.003903,-0.200433,-0.010211,0.039026,-321.419342,0.002914,0.000000
154.460007,-0.059952,-321.508301,-0.001250,0.000124,0.003148,-0.266679,-0.013585,0.031479,-321.508301,0.002099,0.000000
154.950012,-0.045059,-321.552795,-0.001289,0.000084,0.002142,-0.200433,-0.010211,0.021423,-321.552795,0.001283,0.000000
155.440002,-0.022713,-321.508301,-0.001315,0.000055,0.001405,-0.101031,-0.005147,0.014050,-321.508301,0.000460,0.000000
155.930008,-0.017876,-321.597290,-0.001354,0.000025,0.000642,-0.079515,-0.004051,0.006419,-321.597290,-0.000355,0.000000
156.420013,-0.024948,-321.641754,-0.001375,0.000010,0.000252,-0.110975,-0.005653,0.002517,-321.641754,-0.001171,0.000000
156.910004,-0.012283,-321.686249,-0.001380,0.000003,0.000069,-0.054639,-0.002783,0.000693,-321.686249,0.000026,0.000000
157.400009,-0.033142,-321.730713,-0.001375,0.000023,0.000590,-0.147423,-0.007510,0.005897,-321.730713,0.000841,0.000000
157.890015,-0.018990,-321.686249,-0.001384,0.000050,0.001275,-0.084470,-0.004303,0.012748,-321.686249,0.001656,0.000000
158.380005,-0.003723,-321.819672,-0.001375,0.000082,0.002090,-0.016561,-0.000844,0.020900,-321.819672,0.002472,0.000000
158.870010,-0.042450,-321.775208,-0.001388,0.000111,0.002827,-0.188827,-0.009619,0.028273,-321.775208,0.003296,0.000000
159.360001,-0.012657,-321.819672,-0.001384,0.000146,0.003721,-0.056302,-0.002868,0.037206,-321.819672,0.004111,0.000000
159.850006,-0.021225,-321.819672,-0.001371,0.000174,0.004414,-0.094413,-0.004810,0.044143,-321.819672,0.004926,0.000000
160.340012,-0.006332,-321.908630,-0.001380,0.000208,0.005290,-0.028168,-0.001435,0.052901,-321.908630,0.005741,0.000000
160.830002,-0.004097,-321.997620,-0.001380,0.000232,0.005889,-0.018224,-0.000928,0.058885,-321.997620,0.006556,0.000000
161.320007,-0.023834,-321.997620,-0.001388,0.000260,0.006608,-0.106020,-0.005401,0.066084,-321.997620,0.007371,0.000000
161.810013,-0.018616,-321.997620,-0.001367,0.000290,0.007363,-0.082807,-0.004218,0.073628,-321.997620,0.008195,0.000000
162.300003,-0.000740,-322.086578,-0.001354,0.000327,0.008300,-0.003292,-0.000168,0.082995,-322.086578,0.009011,0.000000
162.790009,-0.027557,-321.997620,-0.001341,0.000354,0.008993,-0.122581,-0.006245,0.089933,-321.997620,0.009826,0.000000
163.280014,-0.023834,-322.175537,-0.001324,0.000386,0.009817,-0.106020,-0.005401,0.098169,-322.175537,0.010641,0.000000
163.770004,-0.004471,-322.131042,-0.001281,0.000417,0.010598,-0.019887,-0.001013,0.105977,-322.131042,0.011456,0.000000
164.260010,0.009308,-322.131042,-0.001281,0.000434,0.011022,0.041403,0.002109,0.110224,-322.131042,0.012280,0.000000
164.750015,0.007820,-322.175537,-0.001237,0.000473,0.012020,0.034786,0.001772,0.120197,-322.175537,0.013095,0.000000
165.240005,-0.018616,-322.220001,-0.001203,0.000508,0.012913,-0.082807,-0.004218,0.129129,-322.220001,0.013910,0.000000
165.730011,-0.014153,-322.308960,-0.001181,0.000542,0.013763,-0.062954,-0.003207,0.137630,-322.308960,0.014726,0.000000
166.220001,0.003349,-322.308960,-0.001143,0.000565,0.014361,0.014898,0.000759,0.143614,-322.308960,0.015541,0.000000
166.710007,0.002609,-322.353455,-0.001112,0.000605,0.015376,0.011607,0.000591,0.153761,-322.353455,0.016356,0.000000
167.200012,-0.011543,-322.353455,-0.001074,0.000637,0.016174,-0.051347,-0.002616,0.161740,-322.353455,0.017180,0.000000
167.690002,0.010056,-322.397919,-0.001022,0.000672,0.017076,0.044729,0.002279,0.170756,-322.397919,0.017995,0.000000
168.180008,0.033890,-322.486908,-0.001000,0.000705,0.017917,0.150749,0.007680,0.179169,-322.486908,0.018810,0.000000
168.670013,0.046921,-322.442413,-0.000979,0.000736,0.018689,0.208714,0.010632,0.186887,-322.442413,0.019625,0.000000
169.160004,0.121765,-322.531372,-0.000944,0.000766,0.019460,0.541638,0.027592,0.194604,-322.531372,0.020441,0.000000
169.650009,0.250610,-322.575867,-0.000923,0.000792,0.020128,1.114771,0.056789,0.201284,-322.575867,0.021256,0.000000
170.140015,0.748466,-322.620331,-0.000875,0.000840,0.021343,3.329345,0.169605,0.213426,-322.620331,0.022080,0.000000
170.630005,1.694672,-322.620331,-0.000858,0.000868,0.022036,7.538276,0.384018,0.220364,-322.620331,0.022895,0.000000
171.120010,3.346512,-322.620331,-0.000841,0.000894,0.022704,14.886028,0.758330,0.227041,-322.620331,0.023710,0.000000
171.610001,6.041000,-322.753784,-0.000828,0.000923,0.023450,26.871712,1.368910,0.234497,-322.753784,0.024525,0.000000
172.100006,10.615227,-322.709290,-0.000811,0.000970,0.024629,47.218887,2.405445,0.246294,-322.709290,0.025340,0.000000
172.590012,13.114586,-322.798248,-0.000806,0.000993,0.025227,58.336590,2.971808,0.252275,-322.798248,0.026164,0.000000
173.080002,16.124474,-322.798248,-0.000802,0.001023,0.025973,71.725243,3.653858,0.259735,-322.798248,0.026979,0.000000
173.570007,19.821762,-322.798248,-0.000798,0.001058,0.026875,88.171600,4.491676,0.268754,-322.798248,0.027795,0.000000
174.060013,24.101433,-322.887238,-0.000793,0.001098,0.027881,107.208527,5.461462,0.278814,-322.887238,0.028610,0.000000
174.550003,26.514786,-322.976196,-0.000802,0.001122,0.028489,117.943657,6.008336,0.284885,-322.976196,0.029425,0.000000
175.040009,30.506615,-322.842743,-0.000789,0.001159,0.029442,135.700195,6.912898,0.294423,-322.842743,0.030240,0.000000
175.530014,33.312439,-322.976196,-0.000767,0.001186,0.030136,148.181122,7.548707,0.301361,-322.976196,0.031064,0.000000
176.020004,37.522484,-322.976196,-0.000776,0.001225,0.031116,166.908340,8.502717,0.311160,-322.976196,0.031879,0.000000
176.510010,39.732140,-323.065155,-0.000767,0.001247,0.031671,176.737381,9.003431,0.316712,-323.065155,0.032694,0.000000
177.000015,43.184784,-323.065155,-0.000755,0.001282,0.032573,192.095520,9.785812,0.325732,-323.065155,0.033510,0.000000
177.490005,46.359627,-323.109619,-0.000759,0.001312,0.033336,206.217926,10.505241,0.333362,-323.109619,0.034325,0.000000
177.980011,50.774475,-323.109619,-0.000733,0.001353,0.034368,225.856140,11.505660,0.343684,-323.109619,0.035140,0.000000
178.470001,53.061584,-323.109619,-0.000755,0.001377,0.034984,236.029709,12.023927,0.349838,-323.109619,0.035964,0.000000
178.960007,56.105362,-323.243073,-0.000716,0.001408,0.035756,249.569107,12.713656,0.357559,-323.243073,0.036779,0.000000
179.450012,59.695404,-323.198578,-0.000720,0.001443,0.036658,265.538422,13.527172,0.366578,-323.198578,0.037594,0.000000
179.940002,62.937279,-323.243073,-0.000707,0.001478,0.037534,279.958984,14.261791,0.375337,-323.243073,0.038409,0.000000
180.430008,64.876968,-323.332031,-0.000698,0.001503,0.038175,288.587158,14.701331,0.381752,-323.332031,0.039225,0.000000
180.920013,65.654480,-323.420990,-0.000694,0.001509,0.038323,292.045715,14.877518,0.383228,-323.420990,0.038565,0.000000
181.410004,64.962234,-323.376526,-0.000690,0.001499,0.038062,288.966461,14.720654,0.380624,-323.376526,0.037837,0.000000
181.900009,64.504593,-323.376526,-0.000681,0.001471,0.037369,286.930756,14.616949,0.373686,-323.376526,0.037022,0.000000
182.390015,64.136322,-323.465485,-0.000694,0.001446,0.036718,285.292603,14.533498,0.367184,-323.465485,0.036207,0.000000
182.880005,63.893524,-323.465485,-0.000673,0.001422,0.036111,284.212585,14.478479,0.361113,-323.465485,0.035391,0.000000
183.370010,63.644409,-323.465485,-0.000686,0.001388,0.035262,283.104462,14.422029,0.352616,-323.465485,0.034568,0.000000
183.860016,63.425827,-323.554443,-0.000668,0.001351,0.034316,282.132172,14.372498,0.343161,-323.554443,0.033753,0.000000
184.350006,63.265717,-323.598907,-0.000677,0.001322,0.033571,281.419952,14.336217,0.335705,-323.598907,0.032937,0.000000
184.840012,63.072449,-323.598907,-0.000681,0.001294,0.032877,280.560272,14.292420,0.328767,-323.598907,0.032122,0.000000
185.330002,62.182106,-323.643402,-0.000673,0.001262,0.032053,276.599823,14.090667,0.320528,-323.643402,0.031307,0.000000
185.820007,60.631920,-323.643402,-0.000664,0.001229,0.031211,269.704254,13.739389,0.312114,-323.643402,0.030483,0.000000
186.310013,59.078011,-323.732361,-0.000655,0.001200,0.030483,262.792114,13.387268,0.304832,-323.732361,0.029668,0.000000
186.800003,57.904289,-323.732361,-0.000651,0.001182,0.030023,257.571136,13.121299,0.300233,-323.732361,0.028853,0.000000
187.290009,55.221718,-323.776855,-0.000660,0.001147,0.029121,245.638474,12.513420,0.291214,-323.776855,0.028037,0.000000
187.780014,52.702621,-323.821320,-0.000660,0.001122,0.028497,234.432968,11.942584,0.284972,-323.821320,0.027222,0.000000
188.270004,48.578224,-323.865814,-0.000673,0.001079,0.027405,216.086731,11.007982,0.274045,-323.865814,0.026407,0.000000
188.760010,45.114418,-323.865814,-0.000660,0.001048,0.026607,200.678955,10.223073,0.266067,-323.865814,0.025583,0.000000
189.250015,42.102669,-323.910278,-0.000677,0.001020,0.025895,187.282028,9.540601,0.258955,-323.910278,0.024768,0.000000
189.740005,38.757645,-323.954773,-0.000673,0.000991,0.025167,172.402618,8.782608,0.251669,-323.954773,0.023953,0.000000
190.230011,34.828743,-323.910278,-0.000677,0.000952,0.024178,154.925980,7.892306,0.241783,-323.910278,0.023138,0.000000
190.720016,31.144119,-324.043732,-0.000686,0.000922,0.023415,138.535965,7.057359,0.234153,-324.043732,0.022323,0.000000
191.210007,29.800598,-324.088196,-0.000681,0.000911,0.023138,132.559677,6.752912,0.231378,-324.088196,0.021507,0.000000
191.700012,24.382202,-324.088196,-0.000698,0.000856,0.021750,108.457451,5.525086,0.217499,-324.088196,0.020683,0.000000
192.190002,20.659599,-324.177185,-0.000698,0.000825,0.020961,91.898491,4.681532,0.209607,-324.177185,0.019868,0.000000
192.680008,16.403008,-324.088196,-0.000698,0.000787,0.019981,72.964218,3.716975,0.199808,-324.088196,0.019053,0.000000
193.170013,14.369484,-324.132690,-0.000716,0.000760,0.019313,63.918655,3.256172,0.193132,-324.132690,0.018238,0.000000
193.660004,10.247322,-324.177185,-0.000716,0.000731,0.018576,45.582367,2.322076,0.185759,-324.177185,0.017423,0.000000
194.150009,6.935814,-324.310608,-0.000729,0.000696,0.017674,30.852041,1.571678,0.176739,-324.310608,0.016599,0.000000
194.640015,3.509239,-324.310608,-0.000733,0.000664,0.016876,15.609876,0.795205,0.168761,-324.310608,0.015783,0.000000
195.130005,1.808243,-324.266144,-0.000733,0.000649,0.016477,8.043466,0.409754,0.164772,-324.266144,0.014969,0.000000
195.620010,0.499352,-324.355103,-0.000750,0.000613,0.015567,2.221226,0.113155,0.155669,-324.355103,0.014153,0.000000
196.110016,0.072243,-324.355103,-0.000789,0.000571,0.014509,0.321352,0.016370,0.145086,-324.355103,0.013338,0.000000
196.600006,-0.002602,-324.488525,-0.000824,0.000542,0.013763,-0.011573,-0.000590,0.137630,-324.488525,0.012523,0.000000
197.090012,-0.035378,-324.399567,-0.000854,0.000511,0.012974,-0.157367,-0.008017,0.129739,-324.399567,0.011699,0.000000
197.580002,-0.064049,-324.533020,-0.000888,0.000471,0.011968,-0.284903,-0.014514,0.119678,-324.533020,0.010884,0.000000
198.070007,-0.069260,-324.533020,-0.000923,0.000439,0.011153,-0.308082,-0.015694,0.111526,-324.533020,0.010069,0.000000
198.560013,-0.038353,-324.444061,-0.000953,0.000410,0.010415,-0.170603,-0.008691,0.104153,-324.444061,0.009253,0.000000
199.050003,-0.046921,-324.577515,-0.000979,0.000382,0.009713,-0.208714,-0.010632,0.097128,-324.577515,0.008438,0.000000
199.540009,-0.043198,-324.666473,-0.001009,0.000348,0.008846,-0.192153,-0.009789,0.088457,-324.666473,0.007623,0.000000
200.030014,-0.045799,-324.666473,-0.001056,0.000312,0.007935,-0.203725,-0.010378,0.079350,-324.666473,0.006799,0.000000
200.520004,-0.017502,-324.755432,-0.001091,0.000281,0.007146,-0.077852,-0.003966,0.071459,-324.755432,0.005984,0.000000
201.010010,-0.048035,-324.710937,-0.001138,0.000241,0.006114,-0.213669,-0.010885,0.061141,-324.710937,0.005169,0.000000
201.500015,-0.041702,-324.755432,-0.001155,0.000227,0.005767,-0.185501,-0.009450,0.057670,-324.755432,0.004353,0.000000
201.990005,-0.064049,-324.710937,-0.001190,0.000182,0.004614,-0.284903,-0.014514,0.046138,-324.710937,0.003538,0.000000
202.480011,-0.044312,-324.844391,-0.001242,0.000149,0.003781,-0.197107,-0.010041,0.037811,-324.844391,0.002715,0.000000
202.970016,-0.036118,-324.799896,-0.001246,0.000132,0.003347,-0.160659,-0.008184,0.033474,-324.799896,0.001899,0.000000
203.460007,-0.035378,-324.799896,-0.001298,0.000079,0.002003,-0.157367,-0.008017,0.020033,-324.799896,0.001084,0.000000
203.950012,-0.047661,-324.888855,-0.001337,0.000050,0.001266,-0.212006,-0.010800,0.012660,-324.888855,0.000269,0.000000
204.440002,-0.038353,-324.933350,-0.001341,0.000020,0.000520,-0.170603,-0.008691,0.005204,-324.933350,-0.000546,0.000000
204.900009,-0.032768,-325.022308,-0.001388,-0.000000,-0.000000,-0.145760,-0.007425,-0.000000,-325.022308,-0.000026,0.000000