File: Data/AD Peeled Punched/AD Peeled Punched with creep_55bar_2_09172024_170949.csv
Time (sec),S:Load (lbs),S:HL1 (DIM),S:LVDT (in),S:Position (in),Ch:Position (mm),Ch:Load (N),Ch:Stress (MPa),Ch:Strain (mm/mm),Ch:HL1 (DIM),Set Point (),Cycles ()
0.110000,-0.080063,-99.904213,-0.006644,-0.004823,-0.122496,-0.356137,-0.018143,-1.224956,-99.904213,-0.122235,0.000000
0.380000,-0.084526,-99.904213,-0.006635,-0.004811,-0.122201,-0.375991,-0.019154,-1.222008,-99.904213,-0.121524,0.000000
0.650000,-0.103149,-99.859734,-0.006622,-0.004657,-0.118298,-0.458832,-0.023374,-1.182983,-99.859734,-0.117015,0.000000
0.920000,-0.142250,-99.948700,-0.006450,-0.004480,-0.113797,-0.632760,-0.032234,-1.137974,-99.948700,-0.112523,0.000000
1.190000,-0.119530,-99.993179,-0.006273,-0.004306,-0.109366,-0.531695,-0.027086,-1.093658,-99.993179,-0.108030,0.000000
1.460000,-0.130707,-99.904213,-0.006079,-0.004124,-0.104761,-0.581413,-0.029619,-1.047609,-99.904213,-0.103521,0.000000
1.730000,-0.187302,-99.904213,-0.005894,-0.003951,-0.100364,-0.833159,-0.042443,-1.003640,-99.904213,-0.099028,0.000000
2.000000,-0.087883,-99.993179,-0.005730,-0.003771,-0.095794,-0.390923,-0.019915,-0.957938,-99.993179,-0.094519,0.000000
2.270000,-0.117294,-99.948700,-0.005553,-0.003596,-0.091336,-0.521751,-0.026579,-0.913362,-99.948700,-0.090027,0.000000
2.540000,-0.102776,-99.993179,-0.005359,-0.003420,-0.086870,-0.457169,-0.023289,-0.868700,-99.993179,-0.085534,0.000000
2.810000,-0.094955,-100.037659,-0.005178,-0.003244,-0.082395,-0.422383,-0.021517,-0.823951,-100.037659,-0.081025,0.000000
3.080000,-0.131447,-99.993179,-0.004993,-0.003065,-0.077842,-0.584705,-0.029786,-0.778422,-99.993179,-0.076533,0.000000
3.350000,-0.105011,-99.904213,-0.004820,-0.002889,-0.073376,-0.467112,-0.023796,-0.733760,-99.904213,-0.072040,0.000000
3.620000,-0.128098,-99.948700,-0.004639,-0.002709,-0.068806,-0.569806,-0.029027,-0.688057,-99.948700,-0.067531,0.000000
3.890000,-0.132935,-99.948700,-0.004475,-0.002539,-0.064487,-0.591322,-0.030123,-0.644869,-99.948700,-0.063039,0.000000
4.160000,-0.096069,-99.993179,-0.004294,-0.002353,-0.059769,-0.427338,-0.021770,-0.597692,-99.993179,-0.058546,0.000000
4.430000,-0.115067,-99.948700,-0.004109,-0.002178,-0.055320,-0.511841,-0.026074,-0.553203,-99.948700,-0.054037,0.000000
4.700000,-0.067398,-100.037659,-0.003932,-0.002001,-0.050819,-0.299802,-0.015273,-0.508194,-100.037659,-0.049545,0.000000
4.970000,-0.069633,-99.948700,-0.003747,-0.001826,-0.046388,-0.309745,-0.015779,-0.463879,-99.948700,-0.045052,0.000000
5.240000,-0.105011,-100.037659,-0.003574,-0.001655,-0.042034,-0.467112,-0.023796,-0.420344,-100.037659,-0.040543,0.000000
5.510000,-0.092720,-99.993179,-0.003393,-0.001472,-0.037395,-0.412439,-0.021011,-0.373948,-99.993179,-0.036051,0.000000
5.780000,-0.132195,-100.082138,-0.003199,-0.001291,-0.032781,-0.588031,-0.029956,-0.327811,-100.082138,-0.031558,0.000000
6.050000,-0.100540,-99.948700,-0.003014,-0.001115,-0.028332,-0.447225,-0.022783,-0.283323,-99.948700,-0.027049,0.000000
6.320000,-0.068886,-99.993179,-0.002837,-0.000938,-0.023831,-0.306419,-0.015610,-0.238314,-99.993179,-0.022557,0.000000
6.590000,-0.074104,-99.993179,-0.002660,-0.000757,-0.019235,-0.329632,-0.016792,-0.192351,-99.993179,-0.018064,0.000000
6.860000,-0.016014,-100.037659,-0.002470,-0.000586,-0.014873,-0.071234,-0.003629,-0.148729,-100.037659,-0.013555,0.000000
7.130000,-0.024208,-99.993179,-0.002298,-0.000407,-0.010346,-0.107683,-0.005486,-0.103460,-99.993179,-0.009063,0.000000
7.400001,0.018990,-100.037659,-0.002117,-0.000236,-0.005993,0.084470,0.004303,-0.059925,-100.037659,-0.004570,0.000000
7.670001,0.080063,-99.993179,-0.001957,-0.000096,-0.002446,0.356137,0.018143,-0.024456,-99.993179,-0.002211,0.000000
7.940001,-0.001862,-100.126617,-0.001944,-0.000000,-0.000000,-0.008281,-0.000422,-0.000000,-100.126617,0.000234,0.000000
8.210000,0.071121,-100.082138,-0.001953,-0.000000,-0.000000,0.316363,0.016116,-0.000000,-100.082138,0.000295,0.000000
8.480000,0.077454,-100.082138,-0.001932,-0.000000,-0.000000,0.344531,0.017551,-0.000000,-100.082138,0.000737,0.000000
8.750000,0.062561,-100.082138,-0.001949,0.000000,0.000009,0.278285,0.014177,0.000087,-100.082138,0.001188,0.000000
9.020000,0.075218,-100.037659,-0.001936,0.000013,0.000338,0.334587,0.017045,0.003382,-100.037659,0.001639,0.000000
9.290001,0.097191,-100.082138,-0.001910,0.000042,0.001058,0.432327,0.022024,0.010580,-100.082138,0.002090,0.000000
9.560000,0.100166,-100.126617,-0.001893,0.000058,0.001466,0.445562,0.022698,0.014656,-100.126617,0.002541,0.000000
9.830001,0.109848,-100.082138,-0.001876,0.000070,0.001786,0.488628,0.024892,0.017865,-100.082138,0.002992,0.000000
10.100000,0.138519,-100.126617,-0.001876,0.000088,0.002246,0.616165,0.031389,0.022461,-100.126617,0.003443,0.000000
10.370001,0.184692,-100.082138,-0.001854,0.000113,0.002862,0.821553,0.041852,0.028618,-100.082138,0.003894,0.000000
10.640000,0.207413,-100.082138,-0.001837,0.000132,0.003365,0.922618,0.047000,0.033648,-100.082138,0.004345,0.000000
10.910001,0.199219,-100.171104,-0.001815,0.000146,0.003712,0.886169,0.045144,0.037117,-100.171104,0.004796,0.000000
11.180000,0.247253,-100.082138,-0.001798,0.000167,0.004241,1.099838,0.056028,0.042407,-100.082138,0.005238,0.000000
11.450001,0.237198,-100.082138,-0.001772,0.000186,0.004718,1.055109,0.053750,0.047177,-100.082138,0.005689,0.000000
11.720000,0.243904,-100.037659,-0.001763,0.000201,0.005108,1.084940,0.055269,0.051080,-100.037659,0.006140,0.000000
11.990001,0.320984,-100.171104,-0.001750,0.000217,0.005524,1.427808,0.072736,0.055242,-100.171104,0.006591,0.000000
12.260000,0.387268,-100.171104,-0.001725,0.000232,0.005888,1.722654,0.087756,0.058885,-100.171104,0.007042,0.000000
12.530001,0.455040,-100.215584,-0.001699,0.000255,0.006478,2.024119,0.103114,0.064782,-100.215584,0.007493,0.000000
12.800000,0.471794,-100.082138,-0.001681,0.000275,0.006972,2.098645,0.106910,0.069725,-100.082138,0.007944,0.000000
13.070001,0.516479,-100.082138,-0.001669,0.000288,0.007319,2.297415,0.117036,0.073194,-100.082138,0.008395,0.000000
13.340001,0.504189,-100.215584,-0.001651,0.000292,0.007406,2.242743,0.114251,0.074061,-100.215584,0.008846,0.000000
13.610001,0.625961,-100.171104,-0.001621,0.000327,0.008299,2.784415,0.141845,0.082993,-100.171104,0.009288,0.000000
13.880001,0.656494,-100.215584,-0.001617,0.000338,0.008577,2.920232,0.148764,0.085769,-100.215584,0.009739,0.000000
14.150001,0.631912,-100.126617,-0.001600,0.000342,0.008690,2.810886,0.143193,0.086896,-100.126617,0.010190,0.000000
14.420001,0.880287,-100.126617,-0.001578,0.000375,0.009513,3.915713,0.199476,0.095135,-100.126617,0.010641,0.000000
14.690001,0.988647,-100.215584,-0.001556,0.000393,0.009982,4.397724,0.224031,0.099818,-100.215584,0.011092,0.000000
14.960001,1.189728,-100.260063,-0.001539,0.000418,0.010624,5.292173,0.269596,0.106235,-100.260063,0.011543,0.000000
15.230000,1.243355,-100.215584,-0.001513,0.000439,0.011153,5.530718,0.281748,0.111525,-100.215584,0.011994,0.000000
15.500001,1.357300,-100.126617,-0.001475,0.000455,0.011560,6.037571,0.307569,0.115601,-100.126617,0.012445,0.000000
15.770000,1.475708,-100.215584,-0.001483,0.000469,0.011916,6.564277,0.334400,0.119157,-100.215584,0.012896,0.000000
16.040001,1.546837,-100.260063,-0.001466,0.000480,0.012185,6.880674,0.350518,0.121845,-100.260063,0.013347,0.000000
16.310001,1.808983,-100.260063,-0.001449,0.000499,0.012670,8.046758,0.409921,0.126702,-100.260063,0.013789,0.000000
16.580000,1.985489,-100.215584,-0.001423,0.000516,0.013112,8.831896,0.449918,0.131125,-100.215584,0.014240,0.000000
16.850000,2.137421,-100.260063,-0.001401,0.000536,0.013624,9.507722,0.484346,0.136241,-100.260063,0.014691,0.000000
17.120001,2.383926,-100.171104,-0.001393,0.000556,0.014110,10.604234,0.540205,0.141098,-100.171104,0.015142,0.000000
17.390001,2.643845,-100.304543,-0.001393,0.000574,0.014569,11.760408,0.599104,0.145694,-100.304543,0.015593,0.000000
17.660002,2.838219,-100.260063,-0.001358,0.000592,0.015038,12.625028,0.643150,0.150377,-100.260063,0.016044,0.000000
17.930000,3.147667,-100.260063,-0.001341,0.000613,0.015567,14.001522,0.713272,0.155667,-100.260063,0.016495,0.000000
18.200001,3.203896,-100.260063,-0.001337,0.000622,0.015792,14.251639,0.726013,0.157922,-100.260063,0.016946,0.000000
18.470001,3.697289,-100.260063,-0.001324,0.000645,0.016382,16.446362,0.837818,0.163819,-100.260063,0.017397,0.000000
18.740002,3.816444,-100.260063,-0.001311,0.000658,0.016711,16.976393,0.864819,0.167114,-100.260063,0.017839,0.000000
19.010000,4.206322,-100.304543,-0.001276,0.000677,0.017206,18.710653,0.953166,0.172058,-100.304543,0.018290,0.000000
19.280001,4.625984,-100.260063,-0.001268,0.000698,0.017726,20.577406,1.048263,0.177261,-100.260063,0.018741,0.000000
19.550001,4.922020,-100.349022,-0.001259,0.000713,0.018116,21.894238,1.115346,0.181163,-100.349022,0.019192,0.000000
19.820002,5.427330,-100.304543,-0.001246,0.000736,0.018689,24.141970,1.229851,0.186887,-100.304543,0.019643,0.000000
20.090000,5.456375,-100.304543,-0.001233,0.000743,0.018880,24.271170,1.236432,0.188795,-100.304543,0.020094,0.000000
20.360001,6.074142,-100.304543,-0.001203,0.000766,0.019461,27.019135,1.376420,0.194605,-100.304543,0.020545,0.000000
20.630001,6.563812,-100.304543,-0.001199,0.000782,0.019859,29.197294,1.487381,0.198595,-100.304543,0.020996,0.000000
20.900002,6.755951,-100.304543,-0.001181,0.000794,0.020172,30.051971,1.530920,0.201717,-100.304543,0.021446,0.000000
21.170000,7.312653,-100.349022,-0.001168,0.000813,0.020657,32.528305,1.657071,0.206573,-100.349022,0.021889,0.000000
21.440001,8.169853,-100.349022,-0.001155,0.000842,0.021386,36.341324,1.851315,0.213858,-100.349022,0.022340,0.000000
21.710001,8.441681,-100.349022,-0.001138,0.000855,0.021707,37.550472,1.912912,0.217067,-100.349022,0.022791,0.000000
21.980001,8.666595,-100.393509,-0.001117,0.000865,0.021975,38.550941,1.963879,0.219755,-100.393509,0.023242,0.000000
22.250002,9.566620,-100.349022,-0.001112,0.000889,0.022574,42.554451,2.167827,0.225739,-100.349022,0.023693,0.000000
22.520000,10.099113,-100.349022,-0.001112,0.000904,0.022964,44.923100,2.288492,0.229641,-100.349022,0.024144,0.000000
22.790001,10.738846,-100.437988,-0.001078,0.000922,0.023406,47.768772,2.433457,0.234064,-100.437988,0.024595,0.000000
23.060001,11.075844,-100.349022,-0.001082,0.000938,0.023823,49.267815,2.509822,0.238227,-100.349022,0.025045,0.000000
23.330002,11.966560,-100.349022,-0.001061,0.000958,0.024334,53.229919,2.711662,0.243344,-100.349022,0.025496,0.000000
23.600000,12.077904,-100.349022,-0.001048,0.000968,0.024595,53.725201,2.736892,0.245945,-100.349022,0.025947,0.000000
23.870001,13.100807,-100.437988,-0.001043,0.000996,0.025288,58.275299,2.968685,0.252883,-100.437988,0.026390,0.000000
24.140001,14.068230,-100.349022,-0.001030,0.001012,0.025713,62.578609,3.187906,0.257132,-100.349022,0.026841,0.000000
24.410002,14.512840,-100.393509,-0.001005,0.001028,0.026121,64.556335,3.288656,0.261208,-100.393509,0.027292,0.000000
24.680000,15.328712,-100.437988,-0.000996,0.001051,0.026693,68.185516,3.473536,0.266932,-100.437988,0.027743,0.000000
24.950001,16.031380,-100.304543,-0.000992,0.001070,0.027170,71.311142,3.632763,0.271702,-100.304543,0.028194,0.000000
25.220001,16.776871,-100.349022,-0.000974,0.001083,0.027517,74.627251,3.801693,0.275171,-100.349022,0.028644,0.000000
25.490002,17.302284,-100.437988,-0.000961,0.001100,0.027951,76.964401,3.920754,0.279507,-100.437988,0.029095,0.000000
25.760002,18.638733,-100.393509,-0.000944,0.001125,0.028584,82.909225,4.223598,0.285838,-100.393509,0.029546,0.000000
26.030001,19.096748,-100.482468,-0.000931,0.001138,0.028913,84.946579,4.327385,0.289133,-100.482468,0.029997,0.000000
26.300001,19.598335,-100.393509,-0.000918,0.001153,0.029295,87.177750,4.441046,0.292949,-100.393509,0.030440,0.000000
26.570002,20.066780,-100.349022,-0.000901,0.001171,0.029755,89.261497,4.547197,0.297545,-100.349022,0.030891,0.000000
26.840002,21.421844,-100.437988,-0.000910,0.001192,0.030275,95.289124,4.854259,0.302748,-100.437988,0.031342,0.000000
27.110001,22.172546,-100.482468,-0.000875,0.001209,0.030717,98.628410,5.024371,0.307171,-100.482468,0.031792,0.000000
27.380001,22.681206,-100.437988,-0.000867,0.001224,0.031081,100.891045,5.139635,0.310814,-100.437988,0.032243,0.000000
27.650002,23.082253,-100.437988,-0.000867,0.001235,0.031359,102.674988,5.230513,0.313589,-100.437988,0.032694,0.000000
27.920002,23.859764,-100.482468,-0.000862,0.001251,0.031784,106.133530,5.406700,0.317838,-100.482468,0.033145,0.000000
28.190001,24.028824,-100.526947,-0.000849,0.001251,0.031766,106.885544,5.445009,0.317665,-100.526947,0.005607,0.000000
28.460001,23.611023,-100.437988,-0.000841,0.001250,0.031749,105.027077,5.350334,0.317491,-100.437988,108.000282,0.000000
28.730001,23.285942,-100.526947,-0.000841,0.001250,0.031758,103.581047,5.276670,0.317578,-100.526947,108.000282,0.000000
29.000002,24.260811,-100.437988,-0.000836,0.001243,0.031576,107.917473,5.497579,0.315757,-100.437988,108.000282,0.000000
29.270000,23.967384,-100.482468,-0.000836,0.001243,0.031576,106.612251,5.431087,0.315757,-100.482468,108.000282,0.000000
29.540001,23.748428,-100.526947,-0.000836,0.001243,0.031576,105.638283,5.381471,0.315757,-100.526947,108.000282,0.000000
29.810001,23.571175,-100.482468,-0.000832,0.001248,0.031706,104.849823,5.341304,0.317058,-100.482468,108.000282,0.000000
30.080002,23.540642,-100.526947,-0.000832,0.001264,0.032105,104.714005,5.334386,0.321047,-100.526947,108.000282,0.000000
30.350002,23.618843,-100.526947,-0.000828,0.001271,0.032295,105.061859,5.352106,0.322955,-100.526947,108.000282,0.000000
30.620001,23.813965,-100.437988,-0.000828,0.001271,0.032287,105.929810,5.396321,0.322868,-100.437988,108.000282,0.000000
30.890001,23.710068,-100.571434,-0.000823,0.001271,0.032287,105.467651,5.372778,0.322868,-100.571434,108.000282,0.000000
31.160002,23.631126,-100.571434,-0.000823,0.001271,0.032295,105.116501,5.354890,0.322955,-100.571434,108.000282,0.000000
31.430002,23.567451,-100.526947,-0.000819,0.001271,0.032295,104.833260,5.340461,0.322955,-100.526947,108.000282,0.000000
31.700001,23.563728,-100.482468,-0.000811,0.001274,0.032348,104.816696,5.339617,0.323475,-100.482468,108.000282,0.000000
31.970001,23.501167,-100.526947,-0.000819,0.001274,0.032348,104.538414,5.325441,0.323475,-100.526947,108.000282,0.000000
32.240002,23.621819,-100.660393,-0.000815,0.001276,0.032417,105.075096,5.352780,0.324169,-100.660393,108.000282,0.000000
32.510002,23.603569,-100.571434,-0.000811,0.001276,0.032417,104.993919,5.348645,0.324169,-100.571434,108.000282,0.000000
32.780003,23.541389,-100.571434,-0.000811,0.001276,0.032417,104.717331,5.334555,0.324169,-100.571434,108.000282,0.000000
33.050003,23.498192,-100.571434,-0.000832,0.001277,0.032426,104.525177,5.324766,0.324256,-100.571434,108.000282,0.000000
33.320000,23.479576,-100.526947,-0.000828,0.001277,0.032434,104.442368,5.320548,0.324342,-100.526947,108.000282,0.000000
33.590000,23.542503,-100.571434,-0.000819,0.001279,0.032495,104.722282,5.334807,0.324950,-100.571434,108.000282,0.000000
33.860001,23.520905,-100.615913,-0.000811,0.001279,0.032495,104.626205,5.329913,0.324950,-100.615913,108.000282,0.000000
34.130001,23.498192,-100.571434,-0.000828,0.001279,0.032495,104.525177,5.324766,0.324950,-100.571434,108.000282,0.000000
34.400002,23.471382,-100.615913,-0.000819,0.001279,0.032495,104.405922,5.318691,0.324950,-100.615913,108.000282,0.000000
34.670002,23.635971,-100.571434,-0.000811,0.001285,0.032634,105.138054,5.355988,0.326337,-100.571434,108.000282,0.000000
34.940002,23.762573,-100.571434,-0.000819,0.001285,0.032634,105.701202,5.384676,0.326337,-100.571434,108.000282,0.000000
35.210003,23.771141,-100.660393,-0.000811,0.001285,0.032634,105.739319,5.386618,0.326337,-100.660393,108.000282,0.000000
35.480003,23.726082,-100.704872,-0.000793,0.001285,0.032634,105.538879,5.376407,0.326337,-100.704872,108.000282,0.000000
35.750000,23.699646,-100.571434,-0.000806,0.001285,0.032634,105.421288,5.370417,0.326337,-100.571434,108.000282,0.000000
36.020000,23.665756,-100.571434,-0.000806,0.001285,0.032634,105.270538,5.362737,0.326337,-100.571434,108.000282,0.000000
36.290001,23.655334,-100.615913,-0.000815,0.001285,0.032634,105.224182,5.360375,0.326337,-100.615913,108.000282,0.000000
36.560001,23.599106,-100.615913,-0.000802,0.001285,0.032642,104.974068,5.347634,0.326424,-100.615913,108.000282,0.000000
36.830002,23.600967,-100.615913,-0.000811,0.001286,0.032677,104.982346,5.348055,0.326771,-100.615913,108.000282,0.000000
37.100002,23.598358,-100.615913,-0.000806,0.001286,0.032677,104.970741,5.347465,0.326771,-100.615913,108.000282,0.000000
37.370003,23.580116,-100.660393,-0.000811,0.001286,0.032677,104.889595,5.343331,0.326771,-100.660393,108.000282,0.000000
37.640003,23.547348,-100.615913,-0.000823,0.001287,0.032686,104.743835,5.335906,0.326857,-100.615913,108.000282,0.000000
37.910004,23.578255,-100.660393,-0.000828,0.001288,0.032712,104.881317,5.342909,0.327118,-100.660393,108.000282,0.000000
38.180000,23.565590,-100.704872,-0.000802,0.001288,0.032712,104.824982,5.340039,0.327118,-100.704872,108.000282,0.000000
38.450001,23.546600,-100.704872,-0.000802,0.001288,0.032712,104.740509,5.335736,0.327118,-100.704872,108.000282,0.000000
38.720001,23.837051,-100.660393,-0.000802,0.001292,0.032824,106.032501,5.401553,0.328245,-100.660393,108.000282,0.000000
38.990002,23.831467,-100.704872,-0.000815,0.001292,0.032824,106.007660,5.400288,0.328245,-100.704872,108.000282,0.000000
39.260002,23.834442,-100.704872,-0.000806,0.001292,0.032824,106.020897,5.400962,0.328245,-100.704872,108.000282,0.000000
39.530003,23.819176,-100.704872,-0.000815,0.001292,0.032824,105.952988,5.397502,0.328245,-100.704872,108.000282,0.000000
39.800003,23.806885,-100.704872,-0.000811,0.001292,0.032824,105.898315,5.394717,0.328245,-100.704872,108.000282,0.000000
40.070004,23.790504,-100.660393,-0.000811,0.001292,0.032824,105.825447,5.391006,0.328245,-100.660393,108.000282,0.000000
40.340000,23.753639,-100.704872,-0.000806,0.001292,0.032824,105.661461,5.382652,0.328245,-100.704872,108.000282,0.000000
40.610001,23.717148,-100.749352,-0.000811,0.001292,0.032824,105.499146,5.374382,0.328245,-100.749352,108.000282,0.000000
40.880001,23.694801,-100.749352,-0.000793,0.001292,0.032824,105.399742,5.369318,0.328245,-100.749352,108.000282,0.000000
41.150002,23.675072,-100.660393,-0.000802,0.001292,0.032824,105.311981,5.364848,0.328245,-100.660393,108.000282,0.000000
41.420002,23.670227,-100.749352,-0.000806,0.001292,0.032824,105.290428,5.363750,0.328245,-100.749352,108.000282,0.000000
41.690002,23.639320,-100.704872,-0.000806,0.001292,0.032824,105.152946,5.356746,0.328245,-100.704872,108.000282,0.000000
41.960003,23.610649,-100.749352,-0.000811,0.001292,0.032824,105.025414,5.350249,0.328245,-100.749352,108.000282,0.000000
42.230003,23.599480,-100.749352,-0.000798,0.001292,0.032824,104.975731,5.347719,0.328245,-100.749352,108.000282,0.000000
42.500004,23.557030,-100.660393,-0.000798,0.001292,0.032824,104.786903,5.338099,0.328245,-100.660393,108.000282,0.000000
42.770000,23.527985,-100.704872,-0.000793,0.001292,0.032824,104.657700,5.331517,0.328245,-100.704872,108.000282,0.000000
43.040001,23.514572,-100.704872,-0.000806,0.001293,0.032833,104.598038,5.328478,0.328332,-100.704872,108.000282,0.000000
43.310001,23.521278,-100.793839,-0.000802,0.001293,0.032851,104.627869,5.329998,0.328505,-100.793839,108.000282,0.000000
43.580002,23.550323,-100.749352,-0.000802,0.001295,0.032885,104.757072,5.336579,0.328852,-100.749352,108.000282,0.000000
43.850002,23.548462,-100.749352,-0.000798,0.001295,0.032885,104.748787,5.336158,0.328852,-100.749352,108.000282,0.000000
44.120003,23.555908,-100.749352,-0.000802,0.001295,0.032885,104.781914,5.337845,0.328852,-100.749352,108.000282,0.000000
44.390003,23.546600,-100.793839,-0.000793,0.001295,0.032885,104.740509,5.335736,0.328852,-100.793839,108.000282,0.000000
44.660004,23.533195,-100.838318,-0.000798,0.001295,0.032885,104.680885,5.332698,0.328852,-100.838318,108.000282,0.000000
44.930000,23.515694,-100.838318,-0.000815,0.001295,0.032885,104.603027,5.328732,0.328852,-100.838318,108.000282,0.000000
45.200001,23.517181,-100.793839,-0.000806,0.001298,0.032981,104.609650,5.329070,0.329806,-100.793839,108.000282,0.000000
45.470001,23.969986,-100.793839,-0.000806,0.001301,0.033041,106.623825,5.431676,0.330413,-100.793839,108.000282,0.000000
45.740002,23.983391,-100.838318,-0.000806,0.001301,0.033041,106.683449,5.434714,0.330413,-100.838318,108.000282,0.000000
46.010002,23.981529,-100.838318,-0.000802,0.001301,0.033041,106.675171,5.434292,0.330413,-100.838318,108.000282,0.000000
46.280003,24.000519,-100.793839,-0.000780,0.001301,0.033041,106.759636,5.438595,0.330413,-100.793839,108.000282,0.000000
46.550003,23.978554,-100.838318,-0.000802,0.001301,0.033041,106.661934,5.433618,0.330413,-100.838318,108.000282,0.000000
46.820004,23.972221,-100.749352,-0.000793,0.001301,0.033041,106.633766,5.432183,0.330413,-100.749352,108.000282,0.000000
47.090004,23.927910,-100.838318,-0.000802,0.001301,0.033041,106.436661,5.422142,0.330413,-100.838318,108.000282,0.000000
47.360001,23.927910,-100.882797,-0.000802,0.001301,0.033041,106.436661,5.422142,0.330413,-100.882797,108.000282,0.000000
47.630001,23.899239,-100.838318,-0.000798,0.001301,0.033041,106.309120,5.415645,0.330413,-100.838318,108.000282,0.000000
47.900002,23.880249,-100.838318,-0.000798,0.001301,0.033041,106.224655,5.411342,0.330413,-100.838318,108.000282,0.000000
48.170002,23.877266,-100.793839,-0.000802,0.001301,0.033041,106.211380,5.410666,0.330413,-100.793839,108.000282,0.000000
48.440002,23.873917,-100.882797,-0.000815,0.001301,0.033041,106.196487,5.409907,0.330413,-100.882797,108.000282,0.000000
48.710003,23.857155,-100.882797,-0.000789,0.001301,0.033041,106.121925,5.406108,0.330413,-100.882797,108.000282,0.000000
48.980003,23.852318,-100.882797,-0.000789,0.001301,0.033041,106.100410,5.405013,0.330413,-100.882797,108.000282,0.000000
49.250004,23.853806,-100.838318,-0.000806,0.001301,0.033041,106.107025,5.405349,0.330413,-100.838318,108.000282,0.000000
49.520000,23.838165,-100.793839,-0.000793,0.001301,0.033041,106.037453,5.401805,0.330413,-100.793839,108.000282,0.000000
49.790001,23.803909,-100.971756,-0.000806,0.001301,0.033041,105.885078,5.394042,0.330413,-100.971756,108.000282,0.000000
50.060001,23.799065,-100.927277,-0.000789,0.001301,0.033041,105.863525,5.392945,0.330413,-100.927277,108.000282,0.000000
50.330002,23.784920,-100.882797,-0.000785,0.001301,0.033041,105.800606,5.389740,0.330413,-100.882797,108.000282,0.000000
50.600002,23.754387,-100.882797,-0.000785,0.001301,0.033041,105.664787,5.382821,0.330413,-100.882797,108.000282,0.000000
50.870003,23.740608,-100.882797,-0.000819,0.001301,0.033041,105.603500,5.379699,0.330413,-100.882797,108.000282,0.000000
51.140003,23.734276,-100.927277,-0.000793,0.001301,0.033041,105.575333,5.378264,0.330413,-100.927277,108.000282,0.000000
51.410004,23.712303,-100.882797,-0.000789,0.001301,0.033041,105.477592,5.373284,0.330413,-100.882797,108.000282,0.000000
51.680004,23.683258,-100.927277,-0.000798,0.001301,0.033041,105.348396,5.366703,0.330413,-100.927277,108.000282,0.000000
51.950001,23.675072,-100.927277,-0.000802,0.001301,0.033041,105.311981,5.364848,0.330413,-100.927277,108.000282,0.000000
52.220001,23.666130,-100.927277,-0.000793,0.001301,0.033041,105.272202,5.362822,0.330413,-100.927277,108.000282,0.000000
52.490002,23.654961,-100.927277,-0.000798,0.001301,0.033041,105.222519,5.360291,0.330413,-100.927277,108.000282,0.000000
52.760002,23.639694,-100.971756,-0.000789,0.001301,0.033041,105.154610,5.356831,0.330413,-100.971756,108.000282,0.000000
53.030003,23.641556,-100.838318,-0.000798,0.001301,0.033041,105.162895,5.357253,0.330413,-100.838318,108.000282,0.000000
53.300003,23.647514,-100.927277,-0.000806,0.001301,0.033041,105.189400,5.358603,0.330413,-100.927277,108.000282,0.000000
53.570004,23.620705,-100.971756,-0.000789,0.001301,0.033050,105.070145,5.352528,0.330500,-100.971756,108.000282,0.000000
53.840004,23.589050,-100.927277,-0.000793,0.001301,0.033050,104.929337,5.345355,0.330500,-100.927277,108.000282,0.000000
54.110004,23.573036,-100.927277,-0.000780,0.001301,0.033050,104.858101,5.341726,0.330500,-100.927277,108.000282,0.000000
54.380001,23.573784,-100.927277,-0.000785,0.001301,0.033050,104.861427,5.341896,0.330500,-100.927277,108.000282,0.000000
54.650002,23.553673,-100.927277,-0.000798,0.001301,0.033050,104.771973,5.337338,0.330500,-100.927277,108.000282,0.000000
54.920002,23.532074,-100.971756,-0.000789,0.001301,0.033050,104.675896,5.332444,0.330500,-100.971756,108.000282,0.000000
55.190002,23.525749,-101.016243,-0.000789,0.001301,0.033050,104.647758,5.331011,0.330500,-101.016243,108.000282,0.000000
55.460003,23.530586,-101.016243,-0.000789,0.001301,0.033050,104.669273,5.332107,0.330500,-101.016243,108.000282,0.000000
55.730003,23.506386,-101.016243,-0.000785,0.001301,0.033050,104.561623,5.326623,0.330500,-101.016243,108.000282,0.000000
56.000004,23.487022,-101.060722,-0.000793,0.001301,0.033050,104.475494,5.322235,0.330500,-101.060722,108.000282,0.000000
56.270004,23.499680,-100.971756,-0.000802,0.001301,0.033050,104.531792,5.325104,0.330500,-100.971756,108.000282,0.000000
56.540001,23.487022,-101.060722,-0.000785,0.001301,0.033050,104.475494,5.322235,0.330500,-101.060722,108.000282,0.000000
56.810001,23.460579,-101.016243,-0.000798,0.001301,0.033050,104.357864,5.316243,0.330500,-101.016243,108.000282,0.000000
57.080002,23.455368,-101.016243,-0.000785,0.001301,0.033050,104.334686,5.315063,0.330500,-101.016243,108.000282,0.000000
57.350002,23.449036,-100.971756,-0.000793,0.001301,0.033050,104.306519,5.313628,0.330500,-100.971756,108.000282,0.000000
57.620003,23.444939,-101.016243,-0.000789,0.001303,0.033093,104.288292,5.312699,0.330933,-101.016243,108.000282,0.000000
57.890003,23.444572,-101.060722,-0.000798,0.001303,0.033093,104.286667,5.312616,0.330933,-101.060722,108.000282,0.000000
58.160004,23.447174,-101.105202,-0.000793,0.001303,0.033093,104.298241,5.313205,0.330933,-101.105202,108.000282,0.000000
58.430004,23.453880,-101.016243,-0.000793,0.001303,0.033093,104.328072,5.314725,0.330933,-101.016243,108.000282,0.000000
58.700005,23.444572,-101.016243,-0.000798,0.001303,0.033093,104.286667,5.312616,0.330933,-101.016243,108.000282,0.000000
58.970001,23.425575,-101.060722,-0.000798,0.001303,0.033093,104.202164,5.308311,0.330933,-101.060722,108.000282,0.000000
59.240002,23.430046,-101.060722,-0.000798,0.001303,0.033093,104.222054,5.309324,0.330933,-101.060722,108.000282,0.000000
59.510002,23.423714,-101.105202,-0.000789,0.001303,0.033093,104.193886,5.307889,0.330933,-101.105202,108.000282,0.000000
59.780003,23.422974,-101.060722,-0.000785,0.001303,0.033093,104.190590,5.307722,0.330933,-101.060722,108.000282,0.000000
60.050003,23.399513,-101.060722,-0.000793,0.001303,0.033093,104.086235,5.302406,0.330933,-101.060722,108.000282,0.000000
60.320004,23.401749,-101.016243,-0.000798,0.001309,0.033241,104.096176,5.302912,0.332408,-101.016243,108.000282,0.000000
60.590004,24.058609,-101.105202,-0.000789,0.001312,0.033327,107.018036,5.451759,0.333275,-101.105202,108.000282,0.000000
60.860004,24.077606,-101.105202,-0.000793,0.001312,0.033327,107.102539,5.456064,0.333275,-101.105202,108.000282,0.000000
61.130001,24.082817,-101.149681,-0.000785,0.001312,0.033327,107.125717,5.457244,0.333275,-101.149681,108.000282,0.000000
61.400002,24.147606,-101.060722,-0.000793,0.001311,0.033293,107.413918,5.471926,0.332928,-101.060722,108.000282,0.000000
61.670002,24.103668,-101.105202,-0.000802,0.001310,0.033275,107.218468,5.461969,0.332754,-101.105202,108.000282,0.000000
61.940002,24.086166,-101.194160,-0.000776,0.001310,0.033275,107.140617,5.458004,0.332754,-101.194160,108.000282,0.000000
62.210003,24.070900,-101.105202,-0.000780,0.001310,0.033275,107.072708,5.454544,0.332754,-101.105202,108.000282,0.000000
62.480003,24.060471,-101.105202,-0.000785,0.001310,0.033275,107.026321,5.452180,0.332754,-101.105202,108.000282,0.000000
62.750004,24.036644,-101.060722,-0.000789,0.001310,0.033275,106.920334,5.446782,0.332754,-101.060722,108.000282,0.000000
63.020004,24.028450,-101.194160,-0.000785,0.001310,0.033275,106.883881,5.444924,0.332754,-101.194160,108.000282,0.000000
63.290005,24.023605,-101.238647,-0.000798,0.001310,0.033275,106.862335,5.443827,0.332754,-101.238647,108.000282,0.000000
63.560001,24.026588,-101.105202,-0.000789,0.001310,0.033275,106.875603,5.444503,0.332754,-101.105202,108.000282,0.000000
63.830002,24.054512,-101.194160,-0.000776,0.001310,0.033275,106.999817,5.450830,0.332754,-101.194160,108.000282,0.000000
64.100006,24.041107,-101.149681,-0.000789,0.001310,0.033275,106.940186,5.447793,0.332754,-101.149681,108.000282,0.000000
64.370003,24.003128,-101.194160,-0.000793,0.001310,0.033275,106.771248,5.439187,0.332754,-101.194160,108.000282,0.000000
64.639999,24.000893,-101.238647,-0.000780,0.001310,0.033275,106.761299,5.438680,0.332754,-101.238647,108.000282,0.000000
64.910004,24.001266,-101.194160,-0.000780,0.001310,0.033275,106.762962,5.438765,0.332754,-101.194160,108.000282,0.000000
65.180000,23.990837,-101.149681,-0.000789,0.001310,0.033275,106.716576,5.436401,0.332754,-101.149681,108.000282,0.000000
65.450005,23.981155,-101.238647,-0.000780,0.001310,0.033275,106.673508,5.434207,0.332754,-101.238647,108.000282,0.000000
65.720001,23.951744,-101.194160,-0.000789,0.001310,0.033275,106.542679,5.427543,0.332754,-101.194160,108.000282,0.000000
65.990005,23.957329,-101.283127,-0.000780,0.001310,0.033275,106.567520,5.428809,0.332754,-101.283127,108.000282,0.000000
66.260002,23.926422,-101.149681,-0.000772,0.001310,0.033275,106.430038,5.421805,0.332754,-101.149681,108.000282,0.000000
66.530006,23.915245,-101.238647,-0.000798,0.001310,0.033275,106.380325,5.419272,0.332754,-101.238647,108.000282,0.000000
66.800003,23.904449,-101.194160,-0.000798,0.001310,0.033275,106.332298,5.416825,0.332754,-101.194160,108.000282,0.000000
67.070000,23.900352,-101.238647,-0.000785,0.001310,0.033275,106.314079,5.415897,0.332754,-101.238647,108.000282,0.000000
67.340004,23.887321,-101.238647,-0.000793,0.001310,0.033275,106.256111,5.412944,0.332754,-101.238647,108.000282,0.000000
67.610001,23.866096,-101.238647,-0.000785,0.001310,0.033275,106.161697,5.408134,0.332754,-101.238647,108.000282,0.000000
67.880005,23.862000,-101.238647,-0.000785,0.001310,0.033275,106.143478,5.407207,0.332754,-101.238647,108.000282,0.000000
68.150002,23.862373,-101.283127,-0.000780,0.001310,0.033275,106.145142,5.407291,0.332754,-101.283127,108.000282,0.000000
68.420006,23.845612,-101.283127,-0.000798,0.001310,0.033284,106.070580,5.403493,0.332841,-101.283127,108.000282,0.000000
68.690002,23.844872,-101.283127,-0.000780,0.001310,0.033284,106.067284,5.403325,0.332841,-101.283127,108.000282,0.000000
68.960007,23.837791,-101.194160,-0.000776,0.001310,0.033284,106.035789,5.401721,0.332841,-101.194160,108.000282,0.000000
69.230003,23.837791,-101.238647,-0.000776,0.001310,0.033284,106.035789,5.401721,0.332841,-101.238647,108.000282,0.000000
69.500000,23.835564,-101.283127,-0.000789,0.001310,0.033284,106.025879,5.401216,0.332841,-101.283127,108.000282,0.000000
69.770004,23.824387,-101.327606,-0.000780,0.001310,0.033284,105.976166,5.398683,0.332841,-101.327606,108.000282,0.000000
70.040001,23.823273,-101.327606,-0.000785,0.001310,0.033284,105.971207,5.398431,0.332841,-101.327606,108.000282,0.000000
70.310005,23.803535,-101.283127,-0.000772,0.001310,0.033284,105.883415,5.393958,0.332841,-101.283127,108.000282,0.000000
70.580002,23.805023,-101.283127,-0.000785,0.001310,0.033284,105.890030,5.394295,0.332841,-101.283127,108.000282,0.000000
70.850006,23.781197,-101.327606,-0.000780,0.001310,0.033284,105.784042,5.388896,0.332841,-101.327606,108.000282,0.000000
71.120003,23.764435,-101.327606,-0.000776,0.001310,0.033284,105.709488,5.385098,0.332841,-101.327606,108.000282,0.000000
71.390007,23.759224,-101.416565,-0.000776,0.001310,0.033284,105.686310,5.383917,0.332841,-101.416565,108.000282,0.000000
71.660004,23.756248,-101.283127,-0.000776,0.001310,0.033284,105.673073,5.383243,0.332841,-101.283127,108.000282,0.000000
71.930000,23.726456,-101.327606,-0.000767,0.001310,0.033284,105.540543,5.376492,0.332841,-101.327606,108.000282,0.000000
72.200005,23.733528,-101.283127,-0.000763,0.001311,0.033293,105.572006,5.378094,0.332928,-101.283127,108.000282,0.000000
72.470001,23.729065,-101.372086,-0.000780,0.001311,0.033293,105.552155,5.377083,0.332928,-101.372086,108.000282,0.000000
72.740005,23.704857,-101.327606,-0.000772,0.001311,0.033293,105.444473,5.371597,0.332928,-101.327606,108.000282,0.000000
73.010002,23.699646,-101.372086,-0.000780,0.001311,0.033293,105.421288,5.370417,0.332928,-101.372086,108.000282,0.000000
73.280006,23.695175,-101.327606,-0.000772,0.001311,0.033293,105.401405,5.369403,0.332928,-101.327606,108.000282,0.000000
73.550003,23.692566,-101.327606,-0.000780,0.001311,0.033293,105.389793,5.368812,0.332928,-101.327606,108.000282,0.000000
73.820000,23.678421,-101.416565,-0.000780,0.001311,0.033301,105.326874,5.365607,0.333015,-101.416565,108.000282,0.000000
74.090004,23.678047,-101.461052,-0.000767,0.001311,0.033301,105.325211,5.365522,0.333015,-101.461052,108.000282,0.000000
74.360001,23.674324,-101.327606,-0.000776,0.001311,0.033301,105.308655,5.364678,0.333015,-101.327606,108.000282,0.000000
74.630005,23.673576,-101.372086,-0.000785,0.001311,0.033301,105.305328,5.364509,0.333015,-101.372086,108.000282,0.000000
74.900002,23.660172,-101.416565,-0.000780,0.001311,0.033301,105.245697,5.361472,0.333015,-101.416565,108.000282,0.000000
75.170006,23.653847,-101.416565,-0.000785,0.001311,0.033301,105.217567,5.360038,0.333015,-101.416565,108.000282,0.000000
75.440002,23.654961,-101.416565,-0.000780,0.001311,0.033301,105.222519,5.360291,0.333015,-101.416565,108.000282,0.000000
75.710007,23.644165,-101.416565,-0.000767,0.001311,0.033301,105.174500,5.357844,0.333015,-101.416565,108.000282,0.000000
75.980003,23.633736,-101.416565,-0.000785,0.001311,0.033310,105.128105,5.355481,0.333101,-101.416565,108.000282,0.000000
76.250000,23.645279,-101.327606,-0.000767,0.001311,0.033310,105.179451,5.358097,0.333101,-101.327606,108.000282,0.000000
76.520004,23.622192,-101.416565,-0.000780,0.001311,0.033310,105.076759,5.352865,0.333101,-101.416565,108.000282,0.000000
76.790001,23.618469,-101.461052,-0.000772,0.001311,0.033310,105.060196,5.352021,0.333101,-101.461052,108.000282,0.000000
77.060005,23.606178,-101.461052,-0.000776,0.001311,0.033310,105.005524,5.349236,0.333101,-101.461052,108.000282,0.000000
77.330002,23.596123,-101.461052,-0.000772,0.001311,0.033310,104.960793,5.346958,0.333101,-101.461052,108.000282,0.000000
77.600006,23.603203,-101.461052,-0.000772,0.001311,0.033310,104.992287,5.348562,0.333101,-101.461052,108.000282,0.000000
77.870003,23.595383,-101.416565,-0.000776,0.001311,0.033310,104.957504,5.346790,0.333101,-101.416565,108.000282,0.000000
78.140007,23.575272,-101.505531,-0.000767,0.001311,0.033310,104.868042,5.342233,0.333101,-101.505531,108.000282,0.000000
78.410004,23.592026,-101.550011,-0.000772,0.001311,0.033310,104.942574,5.346029,0.333101,-101.550011,108.000282,0.000000
78.680000,23.568199,-101.461052,-0.000772,0.001311,0.033310,104.836586,5.340631,0.333101,-101.461052,108.000282,0.000000
78.950005,23.567451,-101.461052,-0.000776,0.001311,0.033310,104.833260,5.340461,0.333101,-101.461052,108.000282,0.000000
79.220001,23.555908,-101.461052,-0.000776,0.001311,0.033310,104.781914,5.337845,0.333101,-101.461052,108.000282,0.000000
79.490005,23.539894,-101.505531,-0.000780,0.001311,0.033310,104.710678,5.334216,0.333101,-101.505531,108.000282,0.000000
79.760002,23.544365,-101.505531,-0.000763,0.001311,0.033310,104.730568,5.335229,0.333101,-101.505531,108.000282,0.000000
80.030006,23.536919,-101.461052,-0.000759,0.001311,0.033310,104.697441,5.333542,0.333101,-101.461052,108.000282,0.000000
80.300003,23.524254,-101.505531,-0.000780,0.001311,0.033310,104.641106,5.330672,0.333101,-101.505531,108.000282,0.000000
80.570007,23.534309,-101.505531,-0.000789,0.001311,0.033310,104.685837,5.332951,0.333101,-101.505531,108.000282,0.000000
80.840004,23.507500,-101.505531,-0.000767,0.001311,0.033310,104.566582,5.326876,0.333101,-101.505531,108.000282,0.000000
81.110001,23.511971,-101.550011,-0.000772,0.001311,0.033310,104.586472,5.327889,0.333101,-101.550011,108.000282,0.000000
81.380005,23.522026,-101.461052,-0.000776,0.001311,0.033310,104.631195,5.330167,0.333101,-101.461052,108.000282,0.000000
81.650002,23.495956,-101.461052,-0.000780,0.001311,0.033310,104.515236,5.324260,0.333101,-101.461052,108.000282,0.000000
81.920006,23.500053,-101.550011,-0.000776,0.001311,0.033310,104.533455,5.325189,0.333101,-101.550011,108.000282,0.000000
82.190002,23.489258,-101.550011,-0.000776,0.001311,0.033310,104.485435,5.322742,0.333101,-101.550011,108.000282,0.000000
82.460007,23.484787,-101.550011,-0.000776,0.001311,0.033310,104.465553,5.321729,0.333101,-101.550011,108.000282,0.000000
82.730003,23.497444,-101.550011,-0.000772,0.001311,0.033310,104.521851,5.324597,0.333101,-101.550011,108.000282,0.000000
83.000008,23.462440,-101.505531,-0.000772,0.001311,0.033310,104.366150,5.316665,0.333101,-101.505531,108.000282,0.000000
83.270004,23.479942,-101.594490,-0.000798,0.001311,0.033310,104.444000,5.320631,0.333101,-101.594490,108.000282,0.000000
83.540001,23.473618,-101.594490,-0.000763,0.001311,0.033310,104.415863,5.319198,0.333101,-101.594490,108.000282,0.000000
83.810005,23.463188,-101.550011,-0.000767,0.001311,0.033310,104.369476,5.316834,0.333101,-101.550011,108.000282,0.000000
84.080002,23.459839,-101.638969,-0.000772,0.001311,0.033310,104.354576,5.316075,0.333101,-101.638969,108.000282,0.000000
84.350006,23.893654,-101.505531,-0.000772,0.001321,0.033544,106.284279,5.414379,0.335443,-101.505531,108.000282,0.000000
84.620003,24.019882,-101.594490,-0.000776,0.001320,0.033527,106.845772,5.442983,0.335269,-101.594490,108.000282,0.000000
84.890007,24.042229,-101.594490,-0.000776,0.001320,0.033527,106.945175,5.448047,0.335269,-101.594490,108.000282,0.000000
85.160004,24.021744,-101.638969,-0.000780,0.001320,0.033527,106.854050,5.443405,0.335269,-101.638969,108.000282,0.000000
85.430000,24.041481,-101.594490,-0.000772,0.001320,0.033527,106.941849,5.447877,0.335269,-101.594490,108.000282,0.000000
85.700005,24.071648,-101.594490,-0.000776,0.001320,0.033527,107.076035,5.454713,0.335269,-101.594490,108.000282,0.000000
85.970001,24.032547,-101.594490,-0.000780,0.001320,0.033527,106.902107,5.445853,0.335269,-101.594490,108.000282,0.000000
86.240005,24.048927,-101.594490,-0.000772,0.001320,0.033527,106.974968,5.449565,0.335269,-101.594490,108.000282,0.000000
86.510002,24.049675,-101.683456,-0.000767,0.001320,0.033527,106.978294,5.449734,0.335269,-101.683456,108.000282,0.000000
86.780006,24.032547,-101.638969,-0.000772,0.001320,0.033527,106.902107,5.445853,0.335269,-101.638969,108.000282,0.000000
87.050003,24.075745,-101.638969,-0.000780,0.001320,0.033527,107.094261,5.455641,0.335269,-101.638969,108.000282,0.000000
87.320007,24.041107,-101.638969,-0.000767,0.001320,0.033527,106.940186,5.447793,0.335269,-101.638969,108.000282,0.000000
87.590004,24.058609,-101.683456,-0.000772,0.001320,0.033527,107.018036,5.451759,0.335269,-101.683456,108.000282,0.000000
87.860001,24.060471,-101.683456,-0.000780,0.001320,0.033527,107.026321,5.452180,0.335269,-101.683456,108.000282,0.000000
88.130005,24.061218,-101.638969,-0.000763,0.001320,0.033527,107.029648,5.452350,0.335269,-101.638969,108.000282,0.000000
88.400002,24.058983,-101.638969,-0.000776,0.001320,0.033527,107.019699,5.451844,0.335269,-101.638969,108.000282,0.000000
88.670006,24.052284,-101.683456,-0.000776,0.001320,0.033527,106.989906,5.450325,0.335269,-101.683456,616.697449,0.000000
88.940002,24.080582,-101.683456,-0.000780,0.001317,0.033449,107.115776,5.456738,0.334489,-101.683456,0.033249,0.000000
89.210007,23.920837,-101.727936,-0.000772,0.001302,0.033076,106.405197,5.420539,0.330760,-101.727936,0.032798,0.000000
89.480003,24.037758,-101.772415,-0.000767,0.001288,0.032703,106.925285,5.447034,0.327031,-101.772415,0.032348,0.000000
89.750008,24.005363,-101.638969,-0.000767,0.001273,0.032339,106.781189,5.439693,0.323388,-101.638969,0.031905,0.000000
90.020004,23.964027,-101.638969,-0.000772,0.001255,0.031888,106.597321,5.430326,0.318879,-101.638969,0.031454,0.000000
90.290001,23.940567,-101.683456,-0.000780,0.001238,0.031454,106.492958,5.425010,0.314543,-101.683456,0.031003,0.000000
90.560005,23.930145,-101.772415,-0.000772,0.001223,0.031064,106.446602,5.422648,0.310640,-101.772415,0.030552,0.000000
90.830002,23.915619,-101.772415,-0.000772,0.001207,0.030656,106.381989,5.419356,0.306564,-101.772415,0.030101,0.000000
91.100006,23.918976,-101.727936,-0.000763,0.001187,0.030153,106.396919,5.420117,0.301534,-101.727936,0.029650,0.000000
91.370003,23.875031,-101.772415,-0.000776,0.001167,0.029650,106.201439,5.410159,0.296504,-101.772415,0.029199,0.000000
91.640007,23.865723,-101.727936,-0.000772,0.001152,0.029269,106.160034,5.408050,0.292689,-101.727936,0.028749,0.000000
91.910004,23.843750,-101.772415,-0.000772,0.001137,0.028870,106.062294,5.403071,0.288699,-101.772415,0.028298,0.000000
92.180008,23.841888,-101.816895,-0.000776,0.001120,0.028436,106.054016,5.402649,0.284363,-101.816895,0.027855,0.000000
92.450005,23.813591,-101.861382,-0.000767,0.001100,0.027942,105.928146,5.396237,0.279420,-101.861382,0.027404,0.000000
92.720001,23.782684,-101.683456,-0.000763,0.001088,0.027630,105.790665,5.389234,0.276298,-101.683456,0.026953,0.000000
92.990005,23.602081,-101.727936,-0.000772,0.001071,0.027214,104.987305,5.348308,0.272135,-101.727936,0.026502,0.000000
93.260002,23.168266,-101.861382,-0.000776,0.001051,0.026702,103.057594,5.250004,0.267019,-101.861382,0.026051,0.000000
93.530006,22.498375,-101.772415,-0.000755,0.001035,0.026286,100.077766,5.098205,0.262856,-101.772415,0.025601,0.000000
93.800003,21.873528,-101.772415,-0.000746,0.001022,0.025956,97.298309,4.956612,0.259561,-101.772415,0.025150,0.000000
94.070007,21.128410,-101.772415,-0.000759,0.001010,0.025644,93.983864,4.787766,0.256439,-101.772415,0.024699,0.000000
94.340004,20.132317,-101.816895,-0.000742,0.000994,0.025236,89.553017,4.562048,0.252363,-101.816895,0.024248,0.000000
94.610008,19.461304,-101.816895,-0.000755,0.000975,0.024768,86.568199,4.409995,0.247680,-101.816895,0.023797,0.000000
94.880005,17.674286,-101.816895,-0.000759,0.000955,0.024256,78.619148,4.005051,0.242563,-101.816895,0.023354,0.000000
95.150002,16.716919,-101.772415,-0.000742,0.000938,0.023823,74.360573,3.788108,0.238227,-101.772415,0.022903,0.000000
95.420006,15.388664,-101.816895,-0.000759,0.000926,0.023528,68.452194,3.487121,0.235278,-101.816895,0.022452,0.000000
95.690002,14.038071,-101.816895,-0.000763,0.000907,0.023034,62.444458,3.181072,0.230335,-101.816895,0.022002,0.000000
95.960007,12.618584,-101.816895,-0.000759,0.000891,0.022643,56.130264,2.859412,0.226433,-101.816895,0.021551,0.000000
96.230003,10.663628,-101.861382,-0.000755,0.000869,0.022080,47.434185,2.416413,0.220796,-101.861382,0.021100,0.000000
96.500008,9.709984,-101.861382,-0.000742,0.000860,0.021837,43.192165,2.200314,0.218367,-101.861382,0.020649,0.000000
96.770004,8.297577,-101.816895,-0.000755,0.000842,0.021377,36.909466,1.880258,0.213771,-101.816895,0.020198,0.000000
97.040001,6.767494,-101.816895,-0.000763,0.000828,0.021030,30.103317,1.533536,0.210302,-101.816895,0.019747,0.000000
97.310005,4.275581,-101.905861,-0.000767,0.000798,0.020276,19.018736,0.968861,0.202757,-101.905861,0.019304,0.000000
97.580002,2.733215,-101.861382,-0.000780,0.000781,0.019825,12.157949,0.619355,0.198248,-101.861382,0.018853,0.000000
97.850006,1.565826,-101.816895,-0.000772,0.000768,0.019504,6.965144,0.354821,0.195039,-101.816895,0.018403,0.000000
98.120003,0.659843,-101.861382,-0.000789,0.000756,0.019209,2.935130,0.149523,0.192091,-101.861382,0.017952,0.000000
98.390007,-0.135918,-101.816895,-0.000811,0.000729,0.018507,-0.604592,-0.030799,0.185066,-101.816895,0.017501,0.000000
98.660004,-0.124001,-101.950340,-0.000836,0.000715,0.018151,-0.551582,-0.028099,0.181510,-101.950340,0.017050,0.000000
98.930008,-0.109108,-101.905861,-0.000845,0.000701,0.017795,-0.485336,-0.024724,0.177955,-101.905861,0.016599,0.000000
99.200005,-0.108360,-101.816895,-0.000888,0.000673,0.017084,-0.482011,-0.024555,0.170843,-101.816895,0.016148,0.000000
99.470001,-0.112457,-101.861382,-0.000905,0.000655,0.016625,-0.500235,-0.025483,0.166247,-101.861382,0.015697,0.000000
99.740005,-0.147461,-101.950340,-0.000927,0.000640,0.016252,-0.655939,-0.033415,0.162518,-101.950340,0.015254,0.000000
100.010002,-0.142990,-101.950340,-0.000957,0.000622,0.015792,-0.636052,-0.032402,0.157922,-101.950340,0.014804,0.000000
100.280006,-0.151932,-101.994820,-0.000979,0.000604,0.015350,-0.675826,-0.034428,0.153499,-101.994820,0.014353,0.000000
100.550003,-0.150436,-101.905861,-0.000992,0.000587,0.014908,-0.669175,-0.034089,0.149076,-101.905861,0.013902,0.000000
100.820007,-0.144478,-101.861382,-0.001013,0.000567,0.014413,-0.642670,-0.032739,0.144133,-101.861382,0.013451,0.000000
101.090004,-0.114693,-101.950340,-0.001035,0.000547,0.013902,-0.510179,-0.025990,0.139016,-101.950340,0.013000,0.000000
101.360008,-0.128471,-101.950340,-0.001061,0.000529,0.013442,-0.571469,-0.029112,0.134420,-101.950340,0.012549,0.000000
101.630005,-0.123627,-101.994820,-0.001069,0.000515,0.013069,-0.549919,-0.028014,0.130691,-101.994820,0.012098,0.000000
101.900002,-0.128098,-101.950340,-0.001104,0.000491,0.012462,-0.569806,-0.029027,0.124620,-101.950340,0.011647,0.000000
102.170006,-0.124748,-101.950340,-0.001117,0.000479,0.012159,-0.554908,-0.028268,0.121585,-101.950340,0.011196,0.000000
102.440002,-0.149696,-101.994820,-0.001125,0.000464,0.011777,-0.665883,-0.033922,0.117769,-101.994820,0.010754,0.000000
102.710007,-0.132568,-101.994820,-0.001147,0.000450,0.011439,-0.589693,-0.030040,0.114387,-101.994820,0.010303,0.000000
102.980003,-0.137405,-101.994820,-0.001155,0.000437,0.011109,-0.611210,-0.031137,0.111092,-101.994820,0.009852,0.000000
103.250008,-0.117294,-101.950340,-0.001181,0.000406,0.010320,-0.521751,-0.026579,0.103200,-101.950340,0.009401,0.000000
103.520004,-0.097191,-101.994820,-0.001207,0.000390,0.009895,-0.432327,-0.022024,0.098950,-101.994820,0.008950,0.000000
103.790009,-0.081924,-101.905861,-0.001237,0.000371,0.009427,-0.364418,-0.018564,0.094267,-101.905861,0.008499,0.000000
104.060005,-0.083412,-101.994820,-0.001259,0.000352,0.008941,-0.371036,-0.018901,0.089411,-101.994820,0.008048,0.000000
104.330002,-0.096069,-101.994820,-0.001263,0.000337,0.008560,-0.427338,-0.021770,0.085595,-101.994820,0.007597,0.000000
104.600006,-0.116554,-102.039299,-0.001276,0.000323,0.008204,-0.518459,-0.026412,0.082040,-102.039299,0.007146,0.000000
104.870003,-0.115433,-102.039299,-0.001302,0.000302,0.007666,-0.513470,-0.026157,0.076663,-102.039299,0.006704,0.000000
105.140007,-0.113205,-101.950340,-0.001319,0.000281,0.007129,-0.503561,-0.025653,0.071286,-101.950340,0.006253,0.000000
105.410004,-0.113571,-101.994820,-0.001350,0.000267,0.006773,-0.505190,-0.025736,0.067730,-101.994820,0.005802,0.000000
105.680008,-0.071869,-102.039299,-0.001354,0.000249,0.006331,-0.319689,-0.016286,0.063307,-102.039299,0.005351,0.000000
105.950005,-0.067398,-102.039299,-0.001367,0.000241,0.006131,-0.299802,-0.015273,0.061313,-102.039299,0.004900,0.000000
106.220009,-0.093094,-101.994820,-0.001380,0.000212,0.005394,-0.414102,-0.021095,0.053941,-101.994820,0.004449,0.000000
106.490005,-0.100914,-101.994820,-0.001406,0.000199,0.005047,-0.448888,-0.022867,0.050473,-101.994820,0.003998,0.000000
106.760002,-0.090858,-102.083786,-0.001423,0.000182,0.004631,-0.404159,-0.020589,0.046310,-102.083786,0.003547,0.000000
107.030006,-0.112083,-102.039299,-0.001453,0.000156,0.003963,-0.498572,-0.025398,0.039632,-102.039299,0.003096,0.000000
107.300003,-0.101662,-102.128265,-0.001466,0.000140,0.003556,-0.452214,-0.023037,0.035556,-102.128265,0.002654,0.000000
107.570007,-0.116554,-102.039299,-0.001475,0.000127,0.003226,-0.518459,-0.026412,0.032261,-102.039299,0.002203,0.000000
107.840004,-0.106873,-102.083786,-0.001505,0.000109,0.002775,-0.475393,-0.024218,0.027751,-102.083786,0.001752,0.000000
108.110008,-0.103523,-102.128265,-0.001513,0.000089,0.002263,-0.460494,-0.023459,0.022635,-102.128265,0.001301,0.000000
108.380005,-0.113945,-102.128265,-0.001531,0.000073,0.001856,-0.506853,-0.025820,0.018559,-102.128265,0.000850,0.000000
108.650002,-0.106499,-102.083786,-0.001544,0.000052,0.001327,-0.473730,-0.024133,0.013269,-102.083786,0.000399,0.000000
108.920006,-0.117294,-102.083786,-0.001574,0.000035,0.000893,-0.521751,-0.026579,0.008932,-102.083786,-0.000052,0.000000
109.190002,-0.096443,-102.128265,-0.001591,0.000015,0.000390,-0.429001,-0.021854,0.003903,-102.128265,-0.000503,0.000000
109.460007,-0.119904,-102.172745,-0.001617,0.000002,0.000061,-0.533358,-0.027171,0.000607,-102.172745,-0.000911,0.000000
109.600006,-0.117294,-102.039299,-0.001617,0.000003,0.000069,-0.521751,-0.026579,0.000694,-102.039299,-0.000017,0.000000