File: Data/AD Peeled Punched/AD Peeled Punched with creep_150bar_1_08142024_220456.csv
Time (sec),S:Load (lbs),S:HL1 (DIM),S:LVDT (in),S:Position (in),Ch:Position (mm),Ch:Load (N),Ch:Stress (MPa),Ch:Strain (mm/mm),Ch:HL1 (DIM),Set Point (),Cycles ()
0.110000,0.001114,-51.642384,-0.002492,-0.002553,-0.064842,0.004955,0.000252,-0.648425,-51.642384,-0.064842,0.000000
0.400000,0.002975,-51.731346,-0.002471,-0.002544,-0.064608,0.013236,0.000674,-0.646083,-51.731346,-0.063906,0.000000
0.690000,0.009308,-51.731346,-0.002466,-0.002378,-0.060402,0.041403,0.002109,-0.604023,-51.731346,-0.059084,0.000000
0.980000,0.029045,-51.686867,-0.002276,-0.002191,-0.055641,0.129199,0.006582,-0.556412,-51.686867,-0.054245,0.000000
1.270000,0.036118,-51.731346,-0.002070,-0.001994,-0.050637,0.160659,0.008184,-0.506373,-51.731346,-0.049423,0.000000
1.560000,0.116547,-51.775826,-0.001897,0.000003,0.000069,0.518425,0.026410,0.000694,-51.775826,0.000269,0.000000
1.850000,0.101280,-51.820309,-0.001897,0.000002,0.000052,0.450517,0.022950,0.000520,-51.820309,0.000269,0.000000
2.140000,0.102028,-51.820309,-0.001897,0.000002,0.000052,0.453843,0.023120,0.000520,-51.820309,0.000399,0.000000
2.430000,0.088623,-51.864788,-0.001910,0.000003,0.000087,0.394215,0.020082,0.000867,-51.864788,0.000885,0.000000
2.720000,0.074471,-51.909271,-0.001880,0.000014,0.000356,0.331261,0.016875,0.003556,-51.909271,0.001370,0.000000
3.010000,0.094582,-51.864788,-0.001880,0.000034,0.000876,0.420720,0.021432,0.008759,-51.864788,0.001856,0.000000
3.300000,0.125114,-51.998230,-0.001871,0.000055,0.001405,0.556537,0.028351,0.014049,-51.998230,0.002333,0.000000
3.590000,0.090485,-51.909271,-0.001841,0.000072,0.001839,0.402496,0.020504,0.018385,-51.909271,0.002818,0.000000
3.880000,0.109474,-51.953751,-0.001828,0.000086,0.002185,0.486965,0.024807,0.021854,-51.953751,0.003304,0.000000
4.170000,0.155647,-51.998230,-0.001807,0.000103,0.002628,0.692354,0.035270,0.026277,-51.998230,0.003790,0.000000
4.460000,0.173523,-51.998230,-0.001789,0.000116,0.002949,0.771869,0.039321,0.029486,-51.998230,0.004267,0.000000
4.750000,0.197357,-52.042713,-0.001755,0.000144,0.003660,0.877889,0.044722,0.036597,-52.042713,0.004752,0.000000
5.040000,0.255074,-52.087193,-0.001746,0.000168,0.004258,1.134624,0.057800,0.042581,-52.087193,0.005238,0.000000
5.330000,0.223793,-52.176155,-0.001742,0.000187,0.004752,0.995481,0.050712,0.047524,-52.176155,0.005724,0.000000
5.620000,0.256935,-52.131676,-0.001703,0.000201,0.005108,1.142905,0.058222,0.051080,-52.131676,0.006201,0.000000
5.910000,0.278534,-52.176155,-0.001707,0.000214,0.005446,1.238981,0.063117,0.054462,-52.176155,0.006686,0.000000
6.200000,0.383171,-52.265118,-0.001664,0.000239,0.006062,1.704430,0.086828,0.060619,-52.265118,0.007172,0.000000
6.490000,0.458389,-52.176155,-0.001651,0.000257,0.006539,2.039017,0.103872,0.065389,-52.176155,0.007658,0.000000
6.780000,0.450943,-52.265118,-0.001638,0.000271,0.006877,2.005895,0.102185,0.068771,-52.265118,0.008135,0.000000
7.070000,0.562653,-52.265118,-0.001613,0.000298,0.007562,2.502804,0.127499,0.075622,-52.265118,0.008620,0.000000
7.360000,0.552971,-52.265118,-0.001595,0.000317,0.008048,2.459737,0.125305,0.080479,-52.265118,0.009106,0.000000
7.650001,0.625954,-52.354080,-0.001578,0.000336,0.008525,2.784381,0.141843,0.085248,-52.354080,0.009583,0.000000
7.940001,0.781982,-52.309597,-0.001556,0.000352,0.008941,3.478431,0.177200,0.089411,-52.309597,0.010068,0.000000
8.230000,0.903374,-52.354080,-0.001548,0.000375,0.009522,4.018407,0.204707,0.095221,-52.354080,0.010554,0.000000
8.520000,1.015831,-52.398560,-0.001513,0.000393,0.009990,4.518642,0.230191,0.099904,-52.398560,0.011040,0.000000
8.810000,1.025513,-52.354080,-0.001505,0.000402,0.010199,4.561708,0.232385,0.101986,-52.354080,0.011517,0.000000
9.100000,1.145790,-52.487522,-0.001487,0.000420,0.010676,5.096729,0.259640,0.106755,-52.487522,0.012002,0.000000
9.390000,1.455971,-52.398560,-0.001453,0.000456,0.011577,6.476481,0.329928,0.115775,-52.398560,0.012488,0.000000
9.680000,1.460815,-52.487522,-0.001453,0.000463,0.011751,6.498032,0.331026,0.117509,-52.487522,0.012974,0.000000
9.970000,1.775467,-52.532001,-0.001427,0.000492,0.012497,7.897671,0.402327,0.124967,-52.532001,0.013451,0.000000
10.260000,2.089005,-52.532001,-0.001410,0.000516,0.013095,9.292356,0.473375,0.130951,-52.532001,0.013936,0.000000
10.550000,2.098312,-52.576485,-0.001401,0.000527,0.013390,9.333759,0.475484,0.133900,-52.576485,0.014422,0.000000
10.840000,2.374992,-52.576485,-0.001380,0.000546,0.013858,10.564494,0.538181,0.138583,-52.576485,0.014908,0.000000
11.130000,2.653526,-52.620964,-0.001367,0.000569,0.014457,11.803474,0.601298,0.144566,-52.620964,0.015385,0.000000
11.420000,2.902267,-52.665447,-0.001337,0.000588,0.014925,12.909930,0.657663,0.149250,-52.665447,0.015870,0.000000
11.710001,3.247459,-52.620964,-0.001319,0.000606,0.015402,14.445421,0.735885,0.154019,-52.620964,0.016356,0.000000
12.000001,3.316719,-52.709927,-0.001311,0.000619,0.015731,14.753503,0.751579,0.157315,-52.709927,0.016842,0.000000
12.290001,3.895760,-52.665447,-0.001289,0.000642,0.016304,17.329205,0.882792,0.163038,-52.665447,0.017318,0.000000
12.580001,4.131844,-52.709927,-0.001285,0.000658,0.016703,18.379358,0.936289,0.167028,-52.709927,0.017804,0.000000
12.870001,4.201103,-52.798889,-0.001255,0.000667,0.016946,18.687441,0.951984,0.169456,-52.798889,0.018290,0.000000
13.160001,4.599541,-52.798889,-0.001237,0.000686,0.017431,20.459780,1.042271,0.174312,-52.798889,0.018767,0.000000
13.450001,5.055328,-52.843369,-0.001237,0.000715,0.018151,22.487225,1.145554,0.181510,-52.843369,0.019252,0.000000
13.740001,5.914391,-52.843369,-0.001212,0.000740,0.018793,26.308523,1.340220,0.187928,-52.843369,0.019738,0.000000
14.030001,6.236122,-52.932331,-0.001203,0.000755,0.019174,27.739656,1.413126,0.191744,-52.932331,0.020224,0.000000
14.320001,6.771591,-52.976814,-0.001177,0.000773,0.019634,30.121542,1.534464,0.196340,-52.976814,0.020701,0.000000
14.610001,7.373344,-52.887852,-0.001164,0.000794,0.020163,32.798275,1.670824,0.201630,-52.887852,0.021186,0.000000
14.900001,7.790771,-52.932331,-0.001160,0.000809,0.020545,34.655083,1.765414,0.205446,-52.932331,0.021672,0.000000
15.190001,8.500885,-52.976814,-0.001143,0.000830,0.021082,37.813824,1.926328,0.210823,-52.976814,0.022158,0.000000
15.480000,9.120888,-53.065773,-0.001125,0.000854,0.021689,40.571735,2.066823,0.216893,-53.065773,0.022635,0.000000
15.770000,9.306702,-53.110256,-0.001117,0.000863,0.021915,41.398277,2.108929,0.219148,-53.110256,0.023120,0.000000
16.060001,10.432014,-53.065773,-0.001087,0.000890,0.022609,46.403919,2.363928,0.226086,-53.065773,0.023606,0.000000
16.350000,10.888916,-53.199219,-0.001099,0.000909,0.023077,48.436317,2.467464,0.230769,-53.199219,0.024092,0.000000
16.640001,11.685417,-53.154736,-0.001074,0.000927,0.023537,51.979332,2.647953,0.235365,-53.154736,0.024569,0.000000
16.930000,12.705719,-53.154736,-0.001056,0.000952,0.024187,56.517860,2.879157,0.241869,-53.154736,0.025054,0.000000
17.220001,13.169693,-53.199219,-0.001039,0.000968,0.024595,58.581718,2.984295,0.245945,-53.199219,0.025540,0.000000
17.510000,12.853920,-53.199219,-0.001022,0.000969,0.024612,57.177094,2.912740,0.246119,-53.199219,0.026025,0.000000
17.800001,14.643913,-53.243698,-0.001018,0.001001,0.025436,65.139381,3.318358,0.254357,-53.243698,0.026502,0.000000
18.090000,15.260193,-53.243698,-0.000992,0.001018,0.025861,67.880730,3.458009,0.258607,-53.243698,0.026988,0.000000
18.380001,16.245865,-53.332661,-0.000992,0.001041,0.026442,72.265213,3.681365,0.264417,-53.332661,0.027474,0.000000
18.670000,16.973854,-53.332661,-0.000970,0.001059,0.026910,75.503471,3.846330,0.269100,-53.332661,0.027951,0.000000
18.960001,17.905151,-53.332661,-0.000966,0.001081,0.027456,79.646088,4.057365,0.274564,-53.332661,0.028436,0.000000
19.250000,18.452911,-53.377140,-0.000957,0.001097,0.027873,82.082649,4.181489,0.278726,-53.377140,0.028922,0.000000
19.540001,19.438210,-53.421623,-0.000936,0.001115,0.028332,86.465477,4.404761,0.283323,-53.421623,0.029408,0.000000
19.830002,20.193756,-53.466103,-0.000923,0.001132,0.028757,89.826317,4.575971,0.287572,-53.466103,0.029885,0.000000
20.120001,21.891029,-53.466103,-0.000914,0.001161,0.029486,97.376160,4.960578,0.294857,-53.466103,0.030370,0.000000
20.410002,22.000877,-53.421623,-0.000897,0.001171,0.029755,97.864792,4.985470,0.297545,-53.421623,0.030856,0.000000
20.700001,23.637825,-53.555065,-0.000892,0.001201,0.030500,105.146294,5.356408,0.305003,-53.555065,0.031342,0.000000
20.990002,24.325600,-53.510586,-0.000871,0.001218,0.030925,108.205673,5.512259,0.309253,-53.510586,0.031819,0.000000
21.280001,25.007416,-53.599545,-0.000854,0.001232,0.031290,111.238541,5.666761,0.312895,-53.599545,0.032304,0.000000
21.570002,26.150223,-53.644028,-0.000854,0.001253,0.031819,116.321999,5.925725,0.318185,-53.644028,0.032790,0.000000
21.860001,26.648834,-53.555065,-0.000849,0.001263,0.032079,118.539932,6.038712,0.320787,-53.555065,0.033275,0.000000
22.150002,27.948036,-53.644028,-0.000836,0.001286,0.032677,124.319077,6.333116,0.326771,-53.644028,0.033752,0.000000
22.440001,29.638985,-53.599545,-0.000819,0.001312,0.033327,131.840790,6.716290,0.333275,-53.599545,0.034238,0.000000
22.730001,30.532677,-53.732990,-0.000806,0.001330,0.033787,135.816132,6.918804,0.337871,-53.732990,0.034724,0.000000
23.020000,31.171295,-53.732990,-0.000802,0.001345,0.034151,138.656845,7.063517,0.341513,-53.732990,0.035209,0.000000
23.310001,32.160316,-53.777470,-0.000785,0.001363,0.034620,143.056229,7.287632,0.346196,-53.777470,0.035686,0.000000
23.600000,32.917725,-53.777470,-0.000780,0.001377,0.034975,146.425354,7.459263,0.349752,-53.777470,0.036172,0.000000
23.890001,34.499191,-53.777470,-0.000767,0.001399,0.035530,153.460068,7.817628,0.355302,-53.777470,0.036658,0.000000
24.180000,35.151955,-53.821949,-0.000776,0.001412,0.035877,156.363708,7.965547,0.358771,-53.821949,0.037135,0.000000
24.470001,37.318794,-53.910912,-0.000763,0.001444,0.036684,166.002289,8.456559,0.366836,-53.910912,0.037620,0.000000
24.760000,38.235947,-53.821949,-0.000729,0.001460,0.037074,170.081985,8.664390,0.370739,-53.821949,0.038106,0.000000
25.050001,39.018677,-53.999874,-0.000737,0.001477,0.037508,173.563736,8.841758,0.375075,-53.999874,0.038592,0.000000
25.340002,39.821510,-53.999874,-0.000720,0.001492,0.037898,177.134918,9.023684,0.378978,-53.999874,0.039069,0.000000
25.630001,40.757278,-53.955395,-0.000716,0.001504,0.038210,181.297424,9.235731,0.382100,-53.955395,0.039554,0.000000
25.920002,43.206001,-53.955395,-0.000724,0.001536,0.039008,192.189896,9.790620,0.390078,-53.955395,0.040040,0.000000
26.210001,43.759720,-53.999874,-0.000707,0.001547,0.039303,194.652954,9.916094,0.393027,-53.999874,0.040525,0.000000
26.500002,45.547478,-54.088837,-0.000707,0.001571,0.039910,202.605301,10.321206,0.399097,-54.088837,0.041002,0.000000
26.790001,46.981117,-54.133316,-0.000690,0.001592,0.040439,208.982452,10.646073,0.404387,-54.133316,0.041488,0.000000
27.080002,47.886353,-54.133316,-0.000677,0.001607,0.040812,213.009140,10.851202,0.408116,-54.133316,0.041974,0.000000
27.370001,49.034004,-54.133316,-0.000686,0.001625,0.041271,218.114151,11.111264,0.412713,-54.133316,0.042459,0.000000
27.660002,49.292061,-54.133316,-0.000655,0.001629,0.041367,219.262039,11.169741,0.413667,-54.133316,0.042936,0.000000
27.950001,52.592018,-54.222279,-0.000651,0.001669,0.042399,233.940979,11.917521,0.423987,-54.222279,0.043422,0.000000
28.240002,53.260803,-54.222279,-0.000651,0.001681,0.042694,236.915878,12.069071,0.426935,-54.222279,0.043908,0.000000
28.530001,55.499130,-54.222279,-0.000638,0.001707,0.043370,246.872467,12.576283,0.433700,-54.222279,0.044393,0.000000
28.820002,56.878777,-54.311241,-0.000647,0.001726,0.043847,253.009430,12.888915,0.438469,-54.311241,0.044870,0.000000
29.110001,57.938171,-54.311241,-0.000634,0.001739,0.044168,257.721863,13.128977,0.441678,-54.311241,0.045356,0.000000
29.400002,59.559853,-54.311241,-0.000617,0.001758,0.044662,264.935455,13.496455,0.446621,-54.311241,0.045842,0.000000
29.690001,61.412407,-54.400204,-0.000621,0.001783,0.045295,273.176025,13.916250,0.452952,-54.400204,0.046319,0.000000
29.980001,62.798752,-54.400204,-0.000629,0.001800,0.045720,279.342804,14.230401,0.457201,-54.400204,0.046804,0.000000
30.270002,63.828728,-54.400204,-0.000604,0.001812,0.046015,283.924347,14.463797,0.460150,-54.400204,0.047290,0.000000
30.560001,66.034660,-54.444683,-0.000599,0.001840,0.046735,293.736847,14.963668,0.467348,-54.444683,0.047775,0.000000
30.850002,65.875298,-54.400204,-0.000604,0.001833,0.046553,293.027954,14.927555,0.465527,-54.400204,0.008194,0.000000
31.140001,65.561378,-54.489166,-0.000599,0.001832,0.046544,291.631592,14.856421,0.465440,-54.489166,294.500488,0.000000
31.430002,65.653725,-54.489166,-0.000586,0.001841,0.046769,292.042358,14.877347,0.467695,-54.489166,294.500488,0.000000
31.720001,65.489510,-54.622608,-0.000586,0.001841,0.046769,291.311890,14.840136,0.467695,-54.622608,294.500488,0.000000
32.010002,65.499947,-54.578129,-0.000586,0.001844,0.046839,291.358307,14.842500,0.468389,-54.578129,294.500488,0.000000
32.300003,65.424721,-54.578129,-0.000582,0.001844,0.046839,291.023682,14.825454,0.468389,-54.578129,294.500488,0.000000
32.590000,65.442970,-54.622608,-0.000591,0.001846,0.046900,291.104858,14.829589,0.468996,-54.622608,294.500488,0.000000
32.880001,65.422493,-54.622608,-0.000578,0.001848,0.046934,291.013794,14.824948,0.469343,-54.622608,294.500488,0.000000
33.170002,65.422112,-54.711571,-0.000569,0.001849,0.046960,291.012085,14.824862,0.469603,-54.711571,294.500488,0.000000
33.460003,65.384499,-54.667088,-0.000586,0.001849,0.046960,290.844788,14.816339,0.469603,-54.667088,294.500488,0.000000
33.750000,65.601601,-54.756050,-0.000578,0.001852,0.047047,291.810486,14.865536,0.470470,-54.756050,294.500488,0.000000
34.040001,65.544624,-54.711571,-0.000591,0.001852,0.047047,291.557037,14.852624,0.470470,-54.711571,294.500488,0.000000
34.330002,65.491371,-54.756050,-0.000586,0.001852,0.047047,291.320160,14.840557,0.470470,-54.756050,294.500488,0.000000
34.620003,65.479088,-54.845013,-0.000591,0.001854,0.047082,291.265533,14.837773,0.470817,-54.845013,294.500488,0.000000
34.910000,65.468285,-54.800533,-0.000569,0.001854,0.047082,291.217468,14.835325,0.470817,-54.800533,294.500488,0.000000
35.200001,65.453773,-54.845013,-0.000573,0.001854,0.047082,291.152924,14.832037,0.470817,-54.845013,294.500488,0.000000
35.490002,65.409081,-54.933975,-0.000578,0.001854,0.047090,290.954132,14.821909,0.470904,-54.933975,294.500488,0.000000
35.780003,65.379662,-54.933975,-0.000569,0.001855,0.047108,290.823273,14.815243,0.471077,-54.933975,294.500488,0.000000
36.070004,65.374077,-55.022938,-0.000586,0.001855,0.047116,290.798431,14.813977,0.471164,-55.022938,294.500488,0.000000
36.360001,65.333870,-55.022938,-0.000582,0.001855,0.047125,290.619568,14.804866,0.471250,-55.022938,294.500488,0.000000
36.650002,65.324547,-54.978455,-0.000582,0.001857,0.047168,290.578094,14.802753,0.471684,-54.978455,294.500488,0.000000
36.940002,65.407585,-55.067417,-0.000582,0.001857,0.047168,290.947479,14.821570,0.471684,-55.067417,294.500488,0.000000
37.230003,65.396416,-55.022938,-0.000556,0.001857,0.047168,290.897797,14.819039,0.471684,-55.022938,294.500488,0.000000
37.520000,65.384499,-55.111897,-0.000582,0.001857,0.047168,290.844788,14.816339,0.471684,-55.111897,294.500488,0.000000
37.810001,65.348015,-55.111897,-0.000578,0.001857,0.047168,290.682495,14.808072,0.471684,-55.111897,294.500488,0.000000
38.100002,65.301460,-55.111897,-0.000573,0.001857,0.047177,290.475403,14.797522,0.471771,-55.111897,294.500488,0.000000
38.390003,65.313011,-55.245342,-0.000582,0.001858,0.047203,290.526794,14.800140,0.472031,-55.245342,294.500488,0.000000
38.680000,65.350624,-55.200859,-0.000565,0.001859,0.047229,290.694092,14.808662,0.472291,-55.200859,294.500488,0.000000
38.970001,65.381905,-55.289822,-0.000582,0.001859,0.047229,290.833252,14.815751,0.472291,-55.289822,294.500488,0.000000
39.260002,65.374458,-55.245342,-0.000565,0.001859,0.047229,290.800110,14.814064,0.472291,-55.245342,294.500488,0.000000
39.550003,65.350624,-55.200859,-0.000573,0.001859,0.047229,290.694092,14.808662,0.472291,-55.200859,294.500488,0.000000
39.840000,65.320457,-55.334305,-0.000573,0.001860,0.047238,290.559906,14.801826,0.472378,-55.334305,294.500488,0.000000
40.130001,65.310036,-55.334305,-0.000573,0.001860,0.047238,290.513550,14.799465,0.472378,-55.334305,294.500488,0.000000
40.420002,65.294014,-55.378784,-0.000565,0.001860,0.047238,290.442291,14.795835,0.472378,-55.378784,294.500488,0.000000
40.710003,65.273918,-55.423264,-0.000565,0.001860,0.047246,290.352875,14.791282,0.472465,-55.423264,294.500488,0.000000
41.000004,65.272423,-55.334305,-0.000565,0.001860,0.047246,290.346252,14.790943,0.472465,-55.334305,294.500488,0.000000
41.290001,65.252693,-55.423264,-0.000573,0.001860,0.047246,290.258484,14.786471,0.472465,-55.423264,294.500488,0.000000
41.580002,65.236671,-55.512226,-0.000569,0.001860,0.047246,290.187195,14.782842,0.472465,-55.512226,294.500488,0.000000
41.870003,65.217308,-55.512226,-0.000582,0.001860,0.047246,290.101074,14.778454,0.472465,-55.512226,294.500488,0.000000
42.160004,65.192360,-55.556709,-0.000565,0.001860,0.047246,289.990112,14.772799,0.472465,-55.556709,294.500488,0.000000
42.450001,65.171135,-55.512226,-0.000569,0.001860,0.047246,289.895691,14.767991,0.472465,-55.512226,294.500488,0.000000
42.740002,65.150276,-55.645668,-0.000591,0.001860,0.047246,289.802917,14.763264,0.472465,-55.645668,294.500488,0.000000
43.030003,65.128319,-55.645668,-0.000582,0.001860,0.047246,289.705231,14.758287,0.472465,-55.645668,294.500488,0.000000
43.320004,65.106346,-55.601189,-0.000582,0.001860,0.047246,289.607483,14.753309,0.472465,-55.601189,294.500488,0.000000
43.610001,65.792259,-55.690151,-0.000578,0.001869,0.047481,292.658600,14.908739,0.474806,-55.690151,294.500488,0.000000
43.900002,65.849220,-55.645668,-0.000573,0.001868,0.047446,292.911957,14.921646,0.474459,-55.645668,294.500488,0.000000
44.190002,65.861137,-55.779114,-0.000578,0.001868,0.047446,292.964966,14.924347,0.474459,-55.779114,294.500488,0.000000
44.480003,65.869713,-55.734631,-0.000560,0.001868,0.047446,293.003113,14.926290,0.474459,-55.734631,294.500488,0.000000
44.770000,65.856300,-55.779114,-0.000565,0.001868,0.047446,292.943451,14.923250,0.474459,-55.779114,294.500488,0.000000
45.060001,65.842903,-55.823593,-0.000578,0.001868,0.047446,292.883850,14.920215,0.474459,-55.823593,294.500488,0.000000
45.350002,65.853325,-55.823593,-0.000573,0.001868,0.047446,292.930206,14.922577,0.474459,-55.823593,294.500488,0.000000
45.640003,65.842155,-55.823593,-0.000565,0.001868,0.047446,292.880524,14.920046,0.474459,-55.823593,294.500488,0.000000
45.930000,65.774376,-55.957035,-0.000560,0.001868,0.047446,292.579041,14.904686,0.474459,-55.957035,294.500488,0.000000
46.220001,65.767311,-55.868076,-0.000565,0.001868,0.047446,292.547607,14.903086,0.474459,-55.868076,294.500488,0.000000
46.510002,65.737511,-55.912556,-0.000565,0.001868,0.047446,292.415039,14.896333,0.474459,-55.912556,294.500488,0.000000
46.800003,65.731178,-55.912556,-0.000573,0.001868,0.047446,292.386871,14.894898,0.474459,-55.912556,294.500488,0.000000
47.090004,65.718529,-56.090481,-0.000569,0.001868,0.047446,292.330627,14.892032,0.474459,-56.090481,294.500488,0.000000
47.380001,65.709221,-55.957035,-0.000552,0.001868,0.047446,292.289215,14.889922,0.474459,-55.957035,294.500488,0.000000
47.670002,65.718147,-56.001518,-0.000565,0.001868,0.047446,292.328918,14.891945,0.474459,-56.001518,294.500488,0.000000
47.960003,65.693199,-56.090481,-0.000573,0.001868,0.047446,292.217957,14.886292,0.474459,-56.090481,294.500488,0.000000
48.250004,65.686134,-56.090481,-0.000560,0.001868,0.047446,292.186523,14.884691,0.474459,-56.090481,294.500488,0.000000
48.540001,65.684639,-56.134960,-0.000569,0.001868,0.047446,292.179871,14.884353,0.474459,-56.134960,294.500488,0.000000
48.830002,65.670113,-56.179440,-0.000569,0.001868,0.047446,292.115265,14.881061,0.474459,-56.179440,294.500488,0.000000
49.120003,65.659691,-56.179440,-0.000569,0.001868,0.047446,292.068878,14.878698,0.474459,-56.179440,294.500488,0.000000
49.410004,65.645912,-56.223923,-0.000586,0.001868,0.047446,292.007599,14.875576,0.474459,-56.223923,294.500488,0.000000
49.700001,65.628777,-56.223923,-0.000560,0.001868,0.047446,291.931366,14.871694,0.474459,-56.223923,294.500488,0.000000
49.990002,65.614632,-56.223923,-0.000565,0.001868,0.047446,291.868469,14.868487,0.474459,-56.223923,294.500488,0.000000
50.280003,65.598991,-56.357365,-0.000556,0.001868,0.047446,291.798889,14.864944,0.474459,-56.357365,294.500488,0.000000
50.570004,65.571815,-56.357365,-0.000573,0.001868,0.047446,291.678009,14.858786,0.474459,-56.357365,294.500488,0.000000
50.860001,65.547981,-56.357365,-0.000565,0.001868,0.047446,291.571991,14.853385,0.474459,-56.357365,294.500488,0.000000
51.150002,65.544624,-56.268402,-0.000556,0.001868,0.047446,291.557037,14.852624,0.474459,-56.268402,294.500488,0.000000
51.440002,65.530846,-56.312885,-0.000552,0.001868,0.047446,291.495758,14.849503,0.474459,-56.312885,294.500488,0.000000
51.730003,65.510002,-56.446327,-0.000578,0.001868,0.047446,291.403046,14.844778,0.474459,-56.446327,294.500488,0.000000
52.020004,65.500313,-56.401848,-0.000565,0.001868,0.047446,291.359955,14.842584,0.474459,-56.401848,294.500488,0.000000
52.310001,65.492500,-56.535290,-0.000560,0.001868,0.047446,291.325195,14.840813,0.474459,-56.535290,294.500488,0.000000
52.600002,65.479454,-56.535290,-0.000569,0.001868,0.047446,291.267151,14.837856,0.474459,-56.535290,294.500488,0.000000
52.890003,65.489891,-56.490807,-0.000569,0.001868,0.047446,291.313599,14.840221,0.474459,-56.490807,294.500488,0.000000
53.180004,65.469414,-56.579769,-0.000565,0.001868,0.047446,291.222504,14.835581,0.474459,-56.579769,294.500488,0.000000
53.470001,65.473137,-56.579769,-0.000560,0.001868,0.047446,291.239044,14.836425,0.474459,-56.579769,294.500488,0.000000
53.760002,65.452278,-56.624252,-0.000569,0.001868,0.047446,291.146271,14.831698,0.474459,-56.624252,294.500488,0.000000
54.050003,65.440361,-56.624252,-0.000556,0.001868,0.047446,291.093262,14.828998,0.474459,-56.624252,294.500488,0.000000
54.340004,65.431801,-56.668732,-0.000578,0.001868,0.047446,291.055176,14.827059,0.474459,-56.668732,294.500488,0.000000
54.630001,65.420631,-56.757694,-0.000560,0.001868,0.047446,291.005493,14.824528,0.474459,-56.757694,294.500488,0.000000
54.920002,65.421364,-56.713211,-0.000548,0.001868,0.047446,291.008759,14.824693,0.474459,-56.713211,294.500488,0.000000
55.210003,65.404243,-56.802174,-0.000565,0.001868,0.047446,290.932617,14.820813,0.474459,-56.802174,294.500488,0.000000
55.500004,65.403130,-56.846657,-0.000569,0.001868,0.047446,290.927643,14.820561,0.474459,-56.846657,294.500488,0.000000
55.790001,65.377434,-56.757694,-0.000560,0.001868,0.047446,290.813354,14.814738,0.474459,-56.757694,294.500488,0.000000
56.080002,65.371468,-56.846657,-0.000560,0.001868,0.047446,290.786804,14.813387,0.474459,-56.846657,294.500488,0.000000
56.370003,65.345406,-56.802174,-0.000552,0.001868,0.047446,290.670868,14.807481,0.474459,-56.802174,294.500488,0.000000
56.660004,65.326408,-56.891136,-0.000573,0.001868,0.047446,290.586365,14.803176,0.474459,-56.891136,294.500488,0.000000
56.950005,65.319710,-56.980099,-0.000556,0.001868,0.047446,290.556580,14.801658,0.474459,-56.980099,294.500488,0.000000
57.240002,65.313011,-56.935616,-0.000565,0.001868,0.047446,290.526794,14.800140,0.474459,-56.935616,294.500488,0.000000
57.530003,65.309654,-57.024578,-0.000556,0.001868,0.047446,290.511841,14.799379,0.474459,-57.024578,294.500488,0.000000
57.820004,65.300728,-56.935616,-0.000560,0.001868,0.047446,290.472137,14.797357,0.474459,-56.935616,294.500488,0.000000
58.110004,65.281364,-57.069061,-0.000565,0.001868,0.047446,290.386017,14.792969,0.474459,-57.069061,294.500488,0.000000
58.400002,65.272057,-57.113541,-0.000578,0.001868,0.047446,290.344604,14.790859,0.474459,-57.113541,294.500488,0.000000
58.690002,65.276894,-57.024578,-0.000560,0.001868,0.047446,290.366119,14.791956,0.474459,-57.024578,294.500488,0.000000
58.980003,65.272423,-57.113541,-0.000569,0.001868,0.047446,290.346252,14.790943,0.474459,-57.113541,294.500488,0.000000
59.270004,65.259010,-57.113541,-0.000565,0.001868,0.047446,290.286591,14.787904,0.474459,-57.113541,294.500488,0.000000
59.560001,65.251945,-57.158024,-0.000573,0.001868,0.047446,290.255157,14.786302,0.474459,-57.158024,294.500488,0.000000
59.850002,65.254173,-57.246983,-0.000552,0.001868,0.047446,290.265045,14.786807,0.474459,-57.246983,294.500488,0.000000
60.140003,65.254173,-57.158024,-0.000560,0.001868,0.047446,290.265045,14.786807,0.474459,-57.158024,294.500488,0.000000
60.430004,65.231453,-57.291466,-0.000569,0.001868,0.047446,290.164001,14.781658,0.474459,-57.291466,294.500488,0.000000
60.720001,65.236671,-57.291466,-0.000582,0.001868,0.047446,290.187195,14.782842,0.474459,-57.291466,294.500488,0.000000
61.010002,65.222145,-57.291466,-0.000565,0.001868,0.047446,290.122589,14.779550,0.474459,-57.291466,294.500488,0.000000
61.300003,65.209114,-57.380428,-0.000573,0.001868,0.047446,290.064636,14.776596,0.474459,-57.380428,294.500488,0.000000
61.590004,65.213219,-57.335945,-0.000560,0.001868,0.047446,290.082886,14.777527,0.474459,-57.335945,294.500488,0.000000
61.880001,65.218056,-57.424908,-0.000578,0.001868,0.047446,290.104401,14.778623,0.474459,-57.424908,294.500488,0.000000
62.170002,65.200554,-57.335945,-0.000560,0.001868,0.047446,290.026550,14.774657,0.474459,-57.335945,294.500488,0.000000
62.460003,65.173744,-57.424908,-0.000560,0.001868,0.047446,289.907288,14.768581,0.474459,-57.424908,294.500488,0.000000
62.750004,65.184547,-57.469387,-0.000552,0.001868,0.047446,289.955353,14.771029,0.474459,-57.469387,294.500488,0.000000
63.040005,65.180443,-57.424908,-0.000565,0.001868,0.047446,289.937103,14.770100,0.474459,-57.424908,294.500488,0.000000
63.330002,65.166298,-57.558350,-0.000569,0.001868,0.047446,289.874176,14.766894,0.474459,-57.558350,294.500488,0.000000
63.620003,65.166664,-57.558350,-0.000560,0.001868,0.047446,289.875793,14.766976,0.474459,-57.558350,294.500488,0.000000
63.910004,65.148048,-57.558350,-0.000569,0.001868,0.047446,289.792999,14.762759,0.474459,-57.558350,294.500488,0.000000
64.200005,65.145073,-57.602833,-0.000560,0.001868,0.047446,289.779755,14.762084,0.474459,-57.602833,294.500488,0.000000
64.490005,65.126457,-57.647312,-0.000556,0.001868,0.047446,289.696960,14.757866,0.474459,-57.647312,294.500488,0.000000
64.780006,65.110069,-57.691795,-0.000556,0.001868,0.047446,289.624054,14.754152,0.474459,-57.691795,294.500488,0.000000
65.070000,65.102242,-57.647312,-0.000569,0.001868,0.047446,289.589233,14.752378,0.474459,-57.647312,294.500488,0.000000
65.360001,65.102989,-57.691795,-0.000573,0.001868,0.047446,289.592560,14.752548,0.474459,-57.691795,294.500488,0.000000
65.650002,65.088844,-57.736275,-0.000560,0.001868,0.047446,289.529633,14.749343,0.474459,-57.736275,294.500488,0.000000
65.940002,65.087730,-57.780754,-0.000573,0.001868,0.047446,289.524689,14.749090,0.474459,-57.780754,294.500488,0.000000
66.230003,65.075813,-57.825237,-0.000578,0.001868,0.047446,289.471680,14.746390,0.474459,-57.825237,294.500488,0.000000
66.520004,65.084007,-57.780754,-0.000565,0.001868,0.047446,289.508118,14.748247,0.474459,-57.780754,294.500488,0.000000
66.810005,65.072456,-57.780754,-0.000573,0.001868,0.047446,289.456757,14.745629,0.474459,-57.780754,294.500488,0.000000
67.100006,65.071709,-57.869717,-0.000560,0.001868,0.047446,289.453430,14.745460,0.474459,-57.869717,294.500488,0.000000
67.389999,65.059425,-57.825237,-0.000569,0.001868,0.047446,289.398773,14.742677,0.474459,-57.825237,294.500488,0.000000
67.680000,65.059425,-57.958679,-0.000560,0.001868,0.047446,289.398773,14.742677,0.474459,-57.958679,294.500488,0.000000
67.970001,65.050484,-57.869717,-0.000569,0.001868,0.047446,289.359009,14.740650,0.474459,-57.869717,294.500488,0.000000
68.260002,65.050484,-57.914200,-0.000565,0.001868,0.047446,289.359009,14.740650,0.474459,-57.914200,294.500488,0.000000
68.550003,65.046761,-58.092121,-0.000560,0.001868,0.047446,289.342438,14.739807,0.474459,-58.092121,294.500488,0.000000
68.840004,65.024422,-57.958679,-0.000565,0.001868,0.047455,289.243073,14.734745,0.474546,-57.958679,294.500488,0.000000
69.130005,65.019951,-58.047642,-0.000565,0.001868,0.047455,289.223175,14.733731,0.474546,-58.047642,294.500488,0.000000
69.420006,65.020332,-58.047642,-0.000552,0.001868,0.047455,289.224884,14.733818,0.474546,-58.047642,294.500488,0.000000
69.710007,65.011391,-58.092121,-0.000573,0.001868,0.047455,289.185120,14.731791,0.474546,-58.092121,294.500488,0.000000
70.000000,65.018471,-58.136604,-0.000556,0.001868,0.047455,289.216614,14.733397,0.474546,-58.136604,294.500488,0.000000
70.290001,65.010277,-58.092121,-0.000560,0.001868,0.047455,289.180145,14.731539,0.474546,-58.092121,294.500488,0.000000
70.580002,65.007286,-58.225563,-0.000565,0.001868,0.047455,289.166840,14.730862,0.474546,-58.225563,294.500488,0.000000
70.870003,65.008415,-58.225563,-0.000560,0.001868,0.047455,289.171875,14.731118,0.474546,-58.225563,294.500488,0.000000
71.160004,66.428261,-58.181084,-0.000560,0.001851,0.047012,295.487671,15.052858,0.470123,-58.181084,294.500488,0.000000
71.450005,66.372780,-58.270046,-0.000565,0.001851,0.047012,295.240875,15.040287,0.470123,-58.270046,294.500488,0.000000
71.740005,66.395866,-58.225563,-0.000552,0.001851,0.047012,295.343567,15.045519,0.470123,-58.225563,294.500488,0.000000
72.030006,66.389915,-58.314526,-0.000556,0.001851,0.047012,295.317108,15.044169,0.470123,-58.314526,294.500488,0.000000
72.320000,66.400337,-58.314526,-0.000578,0.001851,0.047012,295.363464,15.046532,0.470123,-58.314526,294.500488,0.000000
72.610001,66.398842,-58.359009,-0.000560,0.001851,0.047012,295.356812,15.046192,0.470123,-58.359009,294.500488,0.000000
72.900002,66.385445,-58.403488,-0.000556,0.001851,0.047012,295.297211,15.043157,0.470123,-58.403488,294.500488,0.000000
73.190002,66.383949,-58.403488,-0.000548,0.001851,0.047012,295.290558,15.042818,0.470123,-58.403488,294.500488,0.000000
73.480003,66.388420,-58.492451,-0.000565,0.001851,0.047012,295.310455,15.043831,0.470123,-58.492451,294.500488,0.000000
73.770004,66.386925,-58.447971,-0.000565,0.001851,0.047012,295.303802,15.043492,0.470123,-58.447971,294.500488,0.000000
74.060005,66.370171,-58.536930,-0.000548,0.001851,0.047012,295.229279,15.039696,0.470123,-58.536930,294.500488,0.000000
74.350006,66.358253,-58.581413,-0.000539,0.001851,0.047012,295.176239,15.036995,0.470123,-58.581413,294.500488,0.000000
74.640007,66.353416,-58.536930,-0.000543,0.001851,0.047012,295.154724,15.035899,0.470123,-58.536930,294.500488,0.000000
74.930000,66.350075,-58.581413,-0.000560,0.001851,0.047012,295.139862,15.035142,0.470123,-58.581413,294.500488,0.000000
75.220001,66.342613,-58.670376,-0.000543,0.001851,0.047012,295.106689,15.033451,0.470123,-58.670376,294.500488,0.000000
75.510002,66.332939,-58.581413,-0.000543,0.001851,0.047012,295.063660,15.031260,0.470123,-58.581413,294.500488,0.000000
75.800003,66.327721,-58.714855,-0.000560,0.001851,0.047012,295.040436,15.030076,0.470123,-58.714855,294.500488,0.000000
76.090004,66.328102,-58.759335,-0.000556,0.001851,0.047012,295.042145,15.030163,0.470123,-58.759335,294.500488,0.000000
76.380005,66.311714,-58.714855,-0.000560,0.001851,0.047012,294.969238,15.026449,0.470123,-58.714855,294.500488,0.000000
76.670006,66.309471,-58.759335,-0.000548,0.001851,0.047012,294.959259,15.025941,0.470123,-58.759335,294.500488,0.000000
76.960007,66.297569,-58.759335,-0.000552,0.001851,0.047012,294.906311,15.023244,0.470123,-58.759335,294.500488,0.000000
77.250000,66.288246,-58.848297,-0.000552,0.001851,0.047012,294.864838,15.021132,0.470123,-58.848297,294.500488,0.000000
77.540001,66.291985,-58.848297,-0.000548,0.001851,0.047012,294.881470,15.021978,0.470123,-58.848297,294.500488,0.000000
77.830002,66.296822,-58.848297,-0.000552,0.001851,0.047012,294.902985,15.023074,0.470123,-58.848297,294.500488,0.000000
78.120003,66.277458,-58.848297,-0.000556,0.001851,0.047012,294.816864,15.018686,0.470123,-58.848297,294.500488,0.000000
78.410004,66.269264,-58.892780,-0.000552,0.001851,0.047012,294.780396,15.016829,0.470123,-58.892780,294.500488,0.000000
78.700005,66.264427,-58.937260,-0.000556,0.001851,0.047012,294.758881,15.015734,0.470123,-58.937260,294.500488,0.000000
78.990005,66.266289,-58.981743,-0.000552,0.001851,0.047012,294.767181,15.016155,0.470123,-58.981743,294.500488,0.000000
79.280006,66.248787,-59.026222,-0.000569,0.001851,0.047012,294.689331,15.012190,0.470123,-59.026222,294.500488,0.000000
79.570007,66.233894,-58.981743,-0.000548,0.001851,0.047012,294.623077,15.008816,0.470123,-58.981743,294.500488,0.000000
79.860001,66.232399,-58.981743,-0.000552,0.001851,0.047012,294.616425,15.008476,0.470123,-58.981743,294.500488,0.000000
80.150002,66.235374,-59.070702,-0.000560,0.001851,0.047012,294.629669,15.009151,0.470123,-59.070702,294.500488,0.000000
80.440002,66.226433,-59.070702,-0.000552,0.001851,0.047012,294.589874,15.007124,0.470123,-59.070702,294.500488,0.000000
80.730003,66.216011,-59.115185,-0.000560,0.001851,0.047012,294.543518,15.004763,0.470123,-59.115185,294.500488,0.000000
81.020004,66.213402,-59.159664,-0.000565,0.001851,0.047012,294.531921,15.004171,0.470123,-59.159664,294.500488,0.000000
81.310005,66.202614,-59.159664,-0.000556,0.001851,0.047012,294.483948,15.001727,0.470123,-59.159664,294.500488,0.000000
81.600006,66.199623,-59.204147,-0.000543,0.001851,0.047012,294.470642,15.001049,0.470123,-59.204147,294.500488,0.000000
81.890007,66.195534,-59.248627,-0.000552,0.001851,0.047012,294.452454,15.000122,0.470123,-59.248627,294.500488,0.000000
82.180000,66.183983,-59.159664,-0.000548,0.001851,0.047012,294.401062,14.997505,0.470123,-59.159664,294.500488,0.000000
82.470001,66.183983,-59.293106,-0.000548,0.001851,0.047012,294.401062,14.997505,0.470123,-59.293106,294.500488,0.000000
82.760002,66.178032,-59.293106,-0.000548,0.001851,0.047012,294.374603,14.996157,0.470123,-59.293106,294.500488,0.000000
83.050003,66.157173,-59.337589,-0.000565,0.001851,0.047012,294.281799,14.991429,0.470123,-59.337589,294.500488,0.000000
83.340004,66.169472,-59.382069,-0.000560,0.001851,0.047012,294.336517,14.994217,0.470123,-59.382069,294.500488,0.000000
83.630005,66.159782,-59.337589,-0.000539,0.001851,0.047012,294.293396,14.992021,0.470123,-59.337589,294.500488,0.000000
83.920006,66.156807,-59.471031,-0.000565,0.001851,0.047012,294.280182,14.991347,0.470123,-59.471031,294.500488,0.000000
84.210007,66.151222,-59.426552,-0.000548,0.001851,0.047012,294.255341,14.990082,0.470123,-59.426552,294.500488,0.000000
84.500008,66.142281,-59.471031,-0.000565,0.001851,0.047012,294.215546,14.988055,0.470123,-59.471031,294.500488,0.000000
84.790001,66.140800,-59.515514,-0.000548,0.001851,0.047012,294.208984,14.987720,0.470123,-59.515514,294.500488,0.000000
85.080002,66.134087,-59.515514,-0.000560,0.001851,0.047012,294.179108,14.986198,0.470123,-59.515514,294.500488,0.000000
85.370003,66.121056,-59.515514,-0.000565,0.001851,0.047012,294.121155,14.983245,0.470123,-59.515514,294.500488,0.000000
85.660004,66.119194,-59.559994,-0.000543,0.001851,0.047012,294.112854,14.982823,0.470123,-59.559994,294.500488,0.000000
85.950005,66.118446,-59.604473,-0.000560,0.001851,0.047012,294.109528,14.982655,0.470123,-59.604473,294.500488,0.000000
86.240005,66.110634,-59.604473,-0.000548,0.001851,0.047012,294.074799,14.980884,0.470123,-59.604473,294.500488,0.000000
86.530006,66.109138,-59.648956,-0.000548,0.001851,0.047012,294.068146,14.980544,0.470123,-59.648956,294.500488,0.000000
86.820007,66.096489,-59.693436,-0.000556,0.001851,0.047012,294.011871,14.977678,0.470123,-59.693436,294.500488,0.000000
87.110001,66.090523,-59.648956,-0.000552,0.001851,0.047012,293.985321,14.976327,0.470123,-59.648956,294.500488,0.000000
87.400002,66.103188,-59.693436,-0.000556,0.001851,0.047012,294.041656,14.979197,0.470123,-59.693436,294.500488,0.000000
87.690002,66.084190,-59.737919,-0.000556,0.001851,0.047012,293.957153,14.974892,0.470123,-59.737919,294.500488,0.000000
87.980003,66.080467,-59.782398,-0.000556,0.001851,0.047012,293.940613,14.974048,0.470123,-59.782398,294.500488,0.000000
88.270004,66.077492,-59.782398,-0.000556,0.001851,0.047012,293.927368,14.973373,0.470123,-59.782398,294.500488,0.000000
88.560005,66.078606,-59.826878,-0.000539,0.001851,0.047012,293.932312,14.973626,0.470123,-59.826878,294.500488,0.000000
88.850006,66.065575,-59.826878,-0.000530,0.001851,0.047012,293.874359,14.970674,0.470123,-59.826878,294.500488,0.000000
89.140007,66.065208,-59.915840,-0.000539,0.001851,0.047012,293.872711,14.970590,0.470123,-59.915840,294.500488,0.000000
89.430008,66.057381,-59.871361,-0.000535,0.001851,0.047012,293.837891,14.968816,0.470123,-59.871361,294.500488,0.000000
89.720001,66.044716,-59.960323,-0.000543,0.001851,0.047012,293.781555,14.965946,0.470123,-59.960323,294.500488,0.000000
90.010002,66.046959,-59.960323,-0.000539,0.001851,0.047012,293.791534,14.966455,0.470123,-59.960323,294.500488,0.000000
90.300003,66.036537,-60.004803,-0.000552,0.001851,0.047012,293.745178,14.964093,0.470123,-60.004803,294.500488,0.000000
90.590004,66.029457,-60.049282,-0.000556,0.001851,0.047012,293.713684,14.962488,0.470123,-60.049282,294.500488,0.000000
90.880005,66.008598,-60.004803,-0.000548,0.001851,0.047012,293.620911,14.957763,0.470123,-60.004803,294.500488,0.000000
91.170006,65.992958,-60.093765,-0.000543,0.001851,0.047012,293.551331,14.954218,0.470123,-60.093765,1681.640991,0.000000
91.460007,65.951256,-60.138245,-0.000535,0.001851,0.047012,293.365845,14.944768,0.470123,-60.138245,0.046769,0.000000
91.750008,65.990730,-60.049282,-0.000556,0.001842,0.046778,293.541443,14.953713,0.467781,-60.049282,0.046284,0.000000
92.040001,66.049568,-60.182728,-0.000543,0.001819,0.046214,293.803162,14.967046,0.462145,-60.182728,0.045798,0.000000
92.330002,65.985893,-60.138245,-0.000548,0.001802,0.045763,293.519897,14.952618,0.457635,-60.138245,0.045321,0.000000
92.620003,65.954231,-60.182728,-0.000548,0.001784,0.045313,293.379059,14.945443,0.453125,-60.182728,0.044836,0.000000
92.910004,65.973976,-60.227207,-0.000539,0.001769,0.044922,293.466888,14.949917,0.449223,-60.227207,0.044350,0.000000
93.200005,65.922585,-60.316170,-0.000548,0.001745,0.044333,293.238312,14.938271,0.443326,-60.316170,0.043864,0.000000
93.490005,65.902855,-60.316170,-0.000552,0.001730,0.043934,293.150543,14.933801,0.439337,-60.316170,0.043387,0.000000
93.780006,65.913277,-60.271690,-0.000548,0.001717,0.043604,293.196899,14.936162,0.436041,-60.271690,0.042902,0.000000
94.070007,65.835823,-60.405132,-0.000556,0.001692,0.042980,292.852356,14.918611,0.429797,-60.405132,0.042416,0.000000
94.360008,65.789268,-60.316170,-0.000539,0.001674,0.042529,292.645294,14.908062,0.425287,-60.316170,0.041939,0.000000
94.650002,65.649635,-60.316170,-0.000556,0.001660,0.042165,292.024170,14.876420,0.421645,-60.316170,0.041453,0.000000
94.940002,65.016228,-60.449612,-0.000535,0.001640,0.041653,289.206635,14.732888,0.416528,-60.449612,0.040968,0.000000
95.230003,64.288246,-60.449612,-0.000535,0.001621,0.041167,285.968414,14.567925,0.411672,-60.449612,0.040482,0.000000
95.520004,63.450783,-60.494095,-0.000543,0.001603,0.040708,282.243164,14.378153,0.407076,-60.494095,0.040005,0.000000
95.810005,62.813271,-60.494095,-0.000530,0.001591,0.040413,279.407379,14.233691,0.404127,-60.494095,0.039519,0.000000
96.100006,61.489861,-60.494095,-0.000535,0.001566,0.039771,273.520569,13.933802,0.397710,-60.494095,0.039034,0.000000
96.390007,60.313538,-60.538574,-0.000543,0.001547,0.039303,268.288025,13.667243,0.393027,-60.538574,0.038548,0.000000
96.680008,59.393036,-60.538574,-0.000526,0.001535,0.038982,264.193420,13.458653,0.389818,-60.538574,0.038071,0.000000
96.970001,58.055099,-60.627537,-0.000535,0.001519,0.038583,258.241974,13.155474,0.385829,-60.627537,0.037586,0.000000
97.260002,56.574921,-60.583054,-0.000522,0.001498,0.038037,251.657822,12.820060,0.380365,-60.583054,0.037100,0.000000
97.550003,55.209427,-60.627537,-0.000543,0.001481,0.037629,245.583801,12.510635,0.376289,-60.627537,0.036614,0.000000
97.840004,52.969238,-60.627537,-0.000535,0.001462,0.037135,235.618942,12.003001,0.371346,-60.627537,0.036137,0.000000
98.130005,50.644516,-60.672016,-0.000530,0.001438,0.036528,225.278061,11.476211,0.365275,-60.672016,0.035652,0.000000
98.420006,48.528320,-60.716499,-0.000548,0.001418,0.036016,215.864746,10.996675,0.360159,-60.716499,0.035166,0.000000
98.710007,46.931213,-60.805462,-0.000543,0.001403,0.035643,208.760468,10.634765,0.356430,-60.805462,0.034680,0.000000
99.000008,45.660683,-60.716499,-0.000548,0.001395,0.035444,203.108856,10.346858,0.354435,-60.716499,0.034203,0.000000
99.290001,42.847038,-60.894421,-0.000548,0.001369,0.034776,190.593140,9.709278,0.347758,-60.894421,0.033718,0.000000
99.580002,40.876808,-60.805462,-0.000543,0.001351,0.034325,181.829117,9.262817,0.343248,-60.805462,0.033232,0.000000
99.870003,38.666779,-60.849941,-0.000548,0.001329,0.033752,171.998428,8.762017,0.337524,-60.849941,0.032755,0.000000
100.160004,36.229973,-60.938904,-0.000543,0.001305,0.033154,161.158966,8.209829,0.331540,-60.938904,0.032269,0.000000
100.450005,34.134262,-60.894421,-0.000565,0.001289,0.032729,151.836777,7.734934,0.327291,-60.894421,0.031784,0.000000
100.740005,32.747551,-60.983383,-0.000552,0.001274,0.032365,145.668381,7.420701,0.323649,-60.983383,0.031298,0.000000
101.030006,30.960533,-60.938904,-0.000552,0.001263,0.032070,137.719330,7.015757,0.320700,-60.938904,0.030821,0.000000
101.320007,28.653313,-60.983383,-0.000560,0.001242,0.031541,127.456299,6.492933,0.315410,-60.983383,0.030336,0.000000
101.610008,25.888451,-61.027866,-0.000548,0.001217,0.030899,115.157578,5.866406,0.308993,-61.027866,0.029850,0.000000
101.900002,25.055450,-61.027866,-0.000573,0.001210,0.030743,111.452209,5.677646,0.307431,-61.027866,0.029364,0.000000
102.190002,20.932167,-61.072346,-0.000569,0.001171,0.029737,93.110931,4.743297,0.297372,-61.072346,0.028887,0.000000
102.480003,19.265060,-61.116825,-0.000573,0.001156,0.029373,85.695267,4.365525,0.293729,-61.116825,0.028402,0.000000
102.770004,16.630150,-61.027866,-0.000582,0.001132,0.028749,73.974602,3.768446,0.287485,-61.027866,0.027916,0.000000
103.060005,15.399086,-61.161308,-0.000552,0.001124,0.028540,68.498558,3.489483,0.285404,-61.161308,0.027430,0.000000
103.350006,12.864349,-61.072346,-0.000569,0.001100,0.027951,57.223484,2.915103,0.279507,-61.072346,0.026953,0.000000
103.640007,11.248627,-61.250271,-0.000556,0.001086,0.027578,50.036392,2.548975,0.275778,-61.250271,0.026468,0.000000
103.930008,8.621536,-61.294750,-0.000565,0.001058,0.026875,38.350510,1.953668,0.268753,-61.294750,0.025982,0.000000
104.220001,6.506836,-61.250271,-0.000586,0.001038,0.026372,28.943851,1.474470,0.263723,-61.250271,0.025496,0.000000
104.510002,4.839722,-61.339233,-0.000569,0.001023,0.025973,21.528156,1.096697,0.259734,-61.339233,0.025019,0.000000
104.800003,4.140404,-61.294750,-0.000569,0.001017,0.025835,18.417437,0.938229,0.258347,-61.294750,0.024534,0.000000
105.090004,1.174461,-61.339233,-0.000565,0.000981,0.024924,5.224265,0.266137,0.249241,-61.339233,0.024048,0.000000
105.380005,0.043938,-61.339233,-0.000556,0.000967,0.024569,0.195445,0.009956,0.245685,-61.339233,0.023571,0.000000
105.670006,0.016754,-61.339233,-0.000569,0.000955,0.024265,0.074526,0.003797,0.242650,-61.339233,0.023086,0.000000
105.960007,-0.037239,-61.428192,-0.000604,0.000925,0.023484,-0.165648,-0.008438,0.234845,-61.428192,0.022600,0.000000
106.250008,-0.039101,-61.383713,-0.000599,0.000907,0.023042,-0.173928,-0.008860,0.230422,-61.383713,0.022114,0.000000
106.540009,-0.063309,-61.472675,-0.000642,0.000893,0.022678,-0.281611,-0.014346,0.226779,-61.472675,0.021637,0.000000
106.830002,-0.059586,-61.472675,-0.000668,0.000871,0.022114,-0.265050,-0.013502,0.221143,-61.472675,0.021152,0.000000
107.120003,-0.037987,-61.472675,-0.000720,0.000848,0.021551,-0.168974,-0.008608,0.215506,-61.472675,0.020666,0.000000
107.410004,-0.056229,-61.561638,-0.000733,0.000838,0.021282,-0.250117,-0.012742,0.212817,-61.561638,0.020180,0.000000
107.700005,-0.028305,-61.517155,-0.000733,0.000824,0.020917,-0.125907,-0.006414,0.209175,-61.517155,0.019703,0.000000
107.990005,-0.062935,-61.606117,-0.000789,0.000791,0.020094,-0.279948,-0.014261,0.200936,-61.606117,0.019218,0.000000
108.280006,-0.062561,-61.650597,-0.000780,0.000775,0.019695,-0.278285,-0.014177,0.196947,-61.650597,0.018732,0.000000
108.570007,-0.044312,-61.606117,-0.000815,0.000755,0.019183,-0.197107,-0.010041,0.191830,-61.606117,0.018246,0.000000
108.860008,-0.050644,-61.695080,-0.000824,0.000741,0.018827,-0.225275,-0.011476,0.188275,-61.695080,0.017769,0.000000
109.150002,-0.045807,-61.650597,-0.000854,0.000720,0.018290,-0.203759,-0.010380,0.182898,-61.650597,0.017284,0.000000
109.440002,-0.055115,-61.739559,-0.000862,0.000703,0.017856,-0.245163,-0.012489,0.178562,-61.739559,0.016798,0.000000
109.730003,-0.048042,-61.784042,-0.000892,0.000678,0.017232,-0.213703,-0.010887,0.172318,-61.784042,0.016313,0.000000
110.020004,-0.046547,-61.739559,-0.000918,0.000658,0.016703,-0.207051,-0.010548,0.167028,-61.739559,0.015836,0.000000
110.310005,-0.034264,-61.828522,-0.000918,0.000642,0.016304,-0.152412,-0.007764,0.163038,-61.828522,0.015350,0.000000
110.600006,-0.035751,-61.739559,-0.000936,0.000627,0.015931,-0.159030,-0.008101,0.159309,-61.739559,0.014864,0.000000
110.890007,-0.027184,-61.828522,-0.000961,0.000622,0.015792,-0.120918,-0.006160,0.157922,-61.828522,0.014387,0.000000
111.180008,-0.046547,-61.828522,-0.000983,0.000587,0.014908,-0.207051,-0.010548,0.149076,-61.828522,0.013902,0.000000
111.470009,-0.032028,-61.873001,-0.001005,0.000574,0.014569,-0.142469,-0.007258,0.145694,-61.873001,0.013416,0.000000
111.760002,-0.035751,-61.917484,-0.001030,0.000546,0.013858,-0.159030,-0.008101,0.138583,-61.917484,0.012930,0.000000
112.050003,-0.037613,-62.006447,-0.001035,0.000527,0.013381,-0.167311,-0.008523,0.133813,-62.006447,0.012453,0.000000
112.340004,-0.044312,-62.006447,-0.001069,0.000510,0.012948,-0.197107,-0.010041,0.129477,-62.006447,0.011968,0.000000
112.630005,-0.048042,-61.961964,-0.001087,0.000493,0.012531,-0.213703,-0.010887,0.125314,-61.961964,0.011482,0.000000
112.920006,-0.052879,-61.961964,-0.001112,0.000469,0.011916,-0.235219,-0.011983,0.119157,-61.961964,0.010996,0.000000
113.210007,-0.062187,-62.050926,-0.001117,0.000455,0.011560,-0.276622,-0.014092,0.115601,-62.050926,0.010519,0.000000
113.500008,-0.059586,-62.095409,-0.001138,0.000432,0.010970,-0.265050,-0.013502,0.109704,-62.095409,0.010034,0.000000
113.790009,-0.048782,-62.050926,-0.001177,0.000409,0.010381,-0.216995,-0.011054,0.103807,-62.050926,0.009548,0.000000
114.080002,-0.032402,-62.139889,-0.001186,0.000394,0.009999,-0.144131,-0.007342,0.099991,-62.139889,0.009063,0.000000
114.370003,-0.024208,-62.095409,-0.001199,0.000383,0.009730,-0.107683,-0.005486,0.097303,-62.095409,0.008586,0.000000
114.660004,-0.036125,-62.184368,-0.001233,0.000358,0.009089,-0.160693,-0.008186,0.090885,-62.184368,0.008100,0.000000
114.950005,-0.024582,-62.228851,-0.001242,0.000337,0.008560,-0.109346,-0.005570,0.085595,-62.228851,0.007614,0.000000
115.240005,-0.021973,-62.228851,-0.001259,0.000325,0.008265,-0.097739,-0.004979,0.082647,-62.228851,0.007129,0.000000
115.530006,-0.026817,-62.228851,-0.001289,0.000300,0.007623,-0.119289,-0.006077,0.076229,-62.228851,0.006652,0.000000
115.820007,-0.012291,-62.228851,-0.001306,0.000278,0.007059,-0.054673,-0.002785,0.070592,-62.228851,0.006166,0.000000
116.110008,-0.008568,-62.317814,-0.001324,0.000263,0.006669,-0.038112,-0.001941,0.066690,-62.317814,0.005680,0.000000
116.400009,-0.020111,-62.317814,-0.001337,0.000247,0.006261,-0.089459,-0.004557,0.062614,-62.317814,0.005203,0.000000
116.690002,-0.000748,-62.362293,-0.001358,0.000222,0.005637,-0.003326,-0.000169,0.056370,-62.362293,0.004718,0.000000
116.980003,-0.010056,-62.406773,-0.001388,0.000204,0.005177,-0.044729,-0.002279,0.051773,-62.406773,0.004232,0.000000
117.270004,-0.014153,-62.406773,-0.001397,0.000191,0.004848,-0.062954,-0.003207,0.048478,-62.406773,0.003746,0.000000
117.560005,-0.021225,-62.451256,-0.001423,0.000162,0.004119,-0.094413,-0.004810,0.041193,-62.451256,0.003269,0.000000
117.850006,-0.013405,-62.451256,-0.001436,0.000144,0.003668,-0.059628,-0.003038,0.036684,-62.451256,0.002784,0.000000
118.140007,0.018616,-62.451256,-0.001462,0.000126,0.003200,0.082807,0.004218,0.032001,-62.451256,0.002298,0.000000
118.430008,0.020851,-62.540218,-0.001483,0.000108,0.002749,0.092750,0.004725,0.027491,-62.540218,0.001813,0.000000
118.720009,0.013779,-62.495735,-0.001500,0.000089,0.002272,0.061291,0.003122,0.022721,-62.495735,0.001336,0.000000
119.010002,0.005211,-62.540218,-0.001513,0.000068,0.001734,0.023179,0.001181,0.017345,-62.540218,0.000850,0.000000
119.300003,-0.001495,-62.629181,-0.001531,0.000047,0.001197,-0.006652,-0.000339,0.011968,-62.629181,0.000364,0.000000
119.590004,-0.045433,-62.584698,-0.001565,0.000027,0.000676,-0.202096,-0.010295,0.006764,-62.584698,-0.000121,0.000000
119.880005,-0.009315,-62.673660,-0.001574,0.000012,0.000304,-0.041437,-0.002111,0.003035,-62.673660,-0.000598,0.000000
120.170006,-0.014526,-62.673660,-0.001587,0.000002,0.000043,-0.064617,-0.003292,0.000434,-62.673660,-0.001058,0.000000
120.300003,-0.017876,-62.718140,-0.001587,0.000003,0.000078,-0.079515,-0.004051,0.000781,-62.718140,-0.000009,0.000000