File: Data/AD Peeled Punched/AD Peeled Punched with creep_120bar_1_08142024_214052.csv
Time (sec),S:Load (lbs),S:HL1 (DIM),S:LVDT (in),S:Position (in),Ch:Position (mm),Ch:Load (N),Ch:Stress (MPa),Ch:Strain (mm/mm),Ch:HL1 (DIM),Set Point (),Cycles ()
0.110000,-0.066650,-92.742783,-0.005739,-0.005705,-0.144913,-0.296476,-0.015103,-1.449134,-92.742783,-0.144697,0.000000
0.430000,-0.065910,-92.787262,-0.005739,-0.005695,-0.144653,-0.293184,-0.014935,-1.446532,-92.787262,-0.143933,0.000000
0.750000,-0.016754,-92.831741,-0.005678,-0.005507,-0.139883,-0.074526,-0.003797,-1.398835,-92.831741,-0.138591,0.000000
1.070000,-0.051010,-92.742783,-0.005480,-0.005299,-0.134593,-0.226904,-0.011559,-1.345934,-92.742783,-0.133267,0.000000
1.390000,-0.010796,-92.831741,-0.005264,-0.005081,-0.129069,-0.048021,-0.002446,-1.290692,-92.831741,-0.127942,0.000000
1.710000,-0.019363,-92.876228,-0.005053,-0.004880,-0.123953,-0.086133,-0.004388,-1.239526,-92.876228,-0.122600,0.000000
2.030000,-0.055855,-92.876228,-0.004833,-0.004671,-0.118654,-0.248455,-0.012657,-1.186538,-92.876228,-0.117275,0.000000
2.350000,-0.058830,-93.009666,-0.004618,-0.004454,-0.113130,-0.261690,-0.013331,-1.131296,-93.009666,-0.111950,0.000000
2.670000,0.007820,-92.920708,-0.004411,-0.004247,-0.107874,0.034786,0.001772,-1.078742,-92.920708,-0.106608,0.000000
2.990000,-0.026062,-93.009666,-0.004182,-0.004034,-0.102471,-0.115930,-0.005906,-1.024714,-93.009666,-0.101283,0.000000
3.310000,0.018623,-93.009666,-0.003971,-0.003821,-0.097043,0.082841,0.004220,-0.970426,-93.009666,-0.095941,0.000000
3.630000,-0.003349,-93.143112,-0.003760,-0.003619,-0.091935,-0.014898,-0.000759,-0.919346,-93.143112,-0.090616,0.000000
3.950000,-0.031281,-93.143112,-0.003540,-0.003404,-0.086454,-0.139143,-0.007088,-0.864537,-93.143112,-0.085292,0.000000
4.270000,-0.013031,-93.098633,-0.003324,-0.003190,-0.081016,-0.057965,-0.002953,-0.810162,-93.098633,-0.079950,0.000000
4.590000,-0.005211,-93.143112,-0.003113,-0.002990,-0.075943,-0.023179,-0.001181,-0.759430,-93.143112,-0.074625,0.000000
4.910000,0.009682,-93.232071,-0.002889,-0.002775,-0.070497,0.043066,0.002194,-0.704968,-93.232071,-0.069300,0.000000
5.230000,0.063675,-93.321037,-0.002682,-0.002569,-0.065241,0.283240,0.014429,-0.652414,-93.321037,-0.063958,0.000000
5.550000,0.085274,-93.321037,-0.002471,-0.002359,-0.059925,0.379317,0.019323,-0.599253,-93.321037,-0.058633,0.000000
5.870000,0.093094,-93.321037,-0.002315,-0.000002,-0.000043,0.414102,0.021095,-0.000434,-93.321037,0.000182,0.000000
6.190000,0.101662,-93.321037,-0.002311,-0.000002,-0.000043,0.452214,0.023037,-0.000434,-93.321037,0.000182,0.000000
6.510000,0.086395,-93.409996,-0.002324,-0.000002,-0.000043,0.384305,0.019577,-0.000434,-93.409996,0.000538,0.000000
6.830000,0.079689,-93.409996,-0.002328,-0.000002,-0.000043,0.354474,0.018058,-0.000434,-93.409996,0.001075,0.000000
7.150001,0.102402,-93.454475,-0.002294,0.000027,0.000694,0.455506,0.023205,0.006938,-93.454475,0.001604,0.000000
7.470000,0.113205,-93.498962,-0.002294,0.000047,0.001197,0.503561,0.025653,0.011968,-93.498962,0.002142,0.000000
7.790000,0.094582,-93.543442,-0.002255,0.000072,0.001821,0.420720,0.021432,0.018212,-93.543442,0.002671,0.000000
8.110001,0.100540,-93.587921,-0.002233,0.000087,0.002211,0.447225,0.022783,0.022114,-93.587921,0.003209,0.000000
8.430000,0.086021,-93.632401,-0.002225,0.000107,0.002714,0.382642,0.019493,0.027144,-93.632401,0.003738,0.000000
8.750000,0.127724,-93.676880,-0.002212,0.000119,0.003035,0.568143,0.028943,0.030353,-93.676880,0.004275,0.000000
9.070001,0.126984,-93.632401,-0.002169,0.000155,0.003929,0.564851,0.028775,0.039285,-93.632401,0.004804,0.000000
9.390000,0.144112,-93.676880,-0.002151,0.000175,0.004458,0.641041,0.032656,0.044575,-93.676880,0.005342,0.000000
9.710000,0.128098,-93.810326,-0.002126,0.000198,0.005039,0.569806,0.029027,0.050386,-93.810326,0.005871,0.000000
10.030001,0.147461,-93.765846,-0.002126,0.000215,0.005472,0.655939,0.033415,0.054722,-93.765846,0.006409,0.000000
10.350000,0.157890,-93.810326,-0.002091,0.000231,0.005871,0.702331,0.035778,0.058711,-93.810326,0.006938,0.000000
10.670000,0.175392,-93.810326,-0.002078,0.000251,0.006365,0.780183,0.039744,0.063654,-93.810326,0.007475,0.000000
10.990001,0.172035,-93.854805,-0.002070,0.000273,0.006946,0.765251,0.038984,0.069465,-93.854805,0.008004,0.000000
11.310000,0.189911,-93.988251,-0.002031,0.000302,0.007675,0.844766,0.043034,0.076750,-93.988251,0.008542,0.000000
11.630000,0.169807,-94.032730,-0.002001,0.000317,0.008057,0.755341,0.038479,0.080565,-94.032730,0.009071,0.000000
11.950001,0.173897,-93.943771,-0.001988,0.000335,0.008507,0.773532,0.039406,0.085075,-93.943771,0.009609,0.000000
12.270000,0.212997,-94.032730,-0.001983,0.000355,0.009010,0.947460,0.048266,0.090105,-94.032730,0.010138,0.000000
12.590000,0.234222,-94.032730,-0.001940,0.000375,0.009522,1.041873,0.053076,0.095221,-94.032730,0.010676,0.000000
12.910001,0.261406,-94.166176,-0.001936,0.000404,0.010268,1.162792,0.059235,0.102680,-94.166176,0.011205,0.000000
13.230000,0.287102,-94.166176,-0.001893,0.000431,0.010944,1.277092,0.065058,0.109444,-94.166176,0.011742,0.000000
13.550000,0.266251,-94.166176,-0.001867,0.000446,0.011335,1.184342,0.060333,0.113346,-94.166176,0.012271,0.000000
13.870001,0.284492,-94.121689,-0.001854,0.000465,0.011820,1.265486,0.064467,0.118203,-94.121689,0.012809,0.000000
14.190001,0.342209,-94.255135,-0.001832,0.000483,0.012280,1.522221,0.077546,0.122799,-94.255135,0.013338,0.000000
14.510000,0.379448,-94.255135,-0.001815,0.000507,0.012870,1.687869,0.085984,0.128696,-94.255135,0.013876,0.000000
14.830001,0.397697,-94.388580,-0.001807,0.000512,0.013017,1.769047,0.090120,0.130171,-94.388580,0.014405,0.000000
15.150001,0.482971,-94.299614,-0.001755,0.000553,0.014058,2.148363,0.109443,0.140577,-94.299614,0.014942,0.000000
15.470000,0.459137,-94.344101,-0.001746,0.000572,0.014517,2.042343,0.104042,0.145174,-94.344101,0.015471,0.000000
15.790001,0.520576,-94.433060,-0.001738,0.000592,0.015038,2.315640,0.117964,0.150377,-94.433060,0.016009,0.000000
16.110001,0.575317,-94.433060,-0.001725,0.000607,0.015411,2.559139,0.130369,0.154106,-94.433060,0.016538,0.000000
16.430000,0.678841,-94.522018,-0.001686,0.000631,0.016035,3.019634,0.153827,0.160350,-94.522018,0.017076,0.000000
16.750000,0.790176,-94.566505,-0.001656,0.000656,0.016651,3.514880,0.179057,0.166507,-94.566505,0.017605,0.000000
17.070002,0.768578,-94.522018,-0.001651,0.000665,0.016885,3.418804,0.174162,0.168849,-94.522018,0.018142,0.000000
17.390001,0.945084,-94.566505,-0.001621,0.000703,0.017865,4.203942,0.214159,0.178649,-94.566505,0.018671,0.000000
17.710001,1.003548,-94.566505,-0.001608,0.000719,0.018264,4.464003,0.227407,0.182638,-94.566505,0.019209,0.000000
18.030001,1.214310,-94.610985,-0.001578,0.000742,0.018853,5.401519,0.275167,0.188535,-94.610985,0.019738,0.000000
18.350000,1.365868,-94.610985,-0.001539,0.000759,0.019287,6.075683,0.309510,0.192871,-94.610985,0.020276,0.000000
18.670000,1.463051,-94.744423,-0.001539,0.000778,0.019755,6.507975,0.331532,0.197554,-94.744423,0.020805,0.000000
18.990002,1.597481,-94.744423,-0.001526,0.000798,0.020267,7.105949,0.361994,0.202671,-94.744423,0.021342,0.000000
19.310001,1.863358,-94.833389,-0.001505,0.000819,0.020813,8.288629,0.422243,0.208134,-94.833389,0.021871,0.000000
19.630001,2.067787,-94.833389,-0.001479,0.000844,0.021438,9.197977,0.468567,0.214378,-94.833389,0.022409,0.000000
19.950001,2.360474,-94.788910,-0.001475,0.000868,0.022054,10.499911,0.534891,0.220536,-94.788910,0.022938,0.000000
20.270000,2.444252,-94.877869,-0.001444,0.000883,0.022418,10.872576,0.553875,0.224178,-94.877869,0.023476,0.000000
20.590000,2.838600,-94.922348,-0.001423,0.000905,0.022981,12.626724,0.643236,0.229815,-94.922348,0.024005,0.000000
20.910002,2.888123,-94.922348,-0.001414,0.000915,0.023242,12.847011,0.654458,0.232417,-94.922348,0.024542,0.000000
21.230001,3.440353,-94.966827,-0.001388,0.000948,0.024074,15.303456,0.779595,0.240742,-94.966827,0.025071,0.000000
21.550001,3.890175,-95.055794,-0.001358,0.000972,0.024699,17.304361,0.881526,0.246986,-95.055794,0.025609,0.000000
21.870001,4.299416,-95.100273,-0.001345,0.000992,0.025184,19.124756,0.974261,0.251842,-95.100273,0.026138,0.000000
22.190001,4.499748,-95.144753,-0.001328,0.001004,0.025505,20.015881,1.019657,0.255051,-95.144753,0.026676,0.000000
22.510000,5.067619,-95.144753,-0.001306,0.001030,0.026164,22.541897,1.148339,0.261642,-95.144753,0.027205,0.000000
22.830002,5.696182,-95.189232,-0.001289,0.001052,0.026728,25.337885,1.290773,0.267279,-95.189232,0.027743,0.000000
23.150002,6.081589,-95.144753,-0.001263,0.001070,0.027188,27.052258,1.378108,0.271875,-95.144753,0.028272,0.000000
23.470001,6.801758,-95.322678,-0.001259,0.001097,0.027873,30.255730,1.541300,0.278726,-95.322678,0.028809,0.000000
23.790001,7.355103,-95.278198,-0.001263,0.001117,0.028376,32.717129,1.666690,0.283756,-95.278198,0.029338,0.000000
24.110001,7.888344,-95.367157,-0.001237,0.001136,0.028853,35.089108,1.787524,0.288526,-95.367157,0.029876,0.000000
24.430000,8.584679,-95.367157,-0.001207,0.001157,0.029390,38.186558,1.945316,0.293903,-95.367157,0.030405,0.000000
24.750002,9.626205,-95.322678,-0.001194,0.001183,0.030058,42.819500,2.181329,0.300581,-95.322678,0.030943,0.000000
25.070002,10.346375,-95.367157,-0.001177,0.001207,0.030665,46.022972,2.344522,0.306651,-95.367157,0.031472,0.000000
25.390001,10.865089,-95.456123,-0.001168,0.001224,0.031081,48.330330,2.462065,0.310814,-95.456123,0.032009,0.000000
25.710001,11.497749,-95.500603,-0.001147,0.001241,0.031524,51.144543,2.605427,0.315237,-95.500603,0.032538,0.000000
26.030001,12.163551,-95.500603,-0.001130,0.001259,0.031983,54.106178,2.756300,0.319833,-95.500603,0.033076,0.000000
26.350000,13.031174,-95.500603,-0.001138,0.001279,0.032478,57.965557,2.952906,0.324776,-95.500603,0.033605,0.000000
26.670002,14.242134,-95.634048,-0.001112,0.001305,0.033137,63.352177,3.227314,0.331367,-95.634048,0.034143,0.000000
26.990002,15.322014,-95.634048,-0.001082,0.001334,0.033874,68.155724,3.472018,0.338738,-95.634048,0.034672,0.000000
27.310001,15.844078,-95.634048,-0.001074,0.001350,0.034299,70.477982,3.590319,0.342988,-95.634048,0.035209,0.000000
27.630001,16.665901,-95.634048,-0.001052,0.001373,0.034862,74.133629,3.776547,0.348625,-95.634048,0.035738,0.000000
27.950001,17.324257,-95.634048,-0.001039,0.001385,0.035175,77.062141,3.925733,0.351747,-95.634048,0.036276,0.000000
28.270000,17.826591,-95.767487,-0.001026,0.001404,0.035669,79.296638,4.039563,0.356690,-95.767487,0.036805,0.000000
28.590002,19.803886,-95.767487,-0.001022,0.001436,0.036467,88.092087,4.487625,0.364668,-95.767487,0.037343,0.000000
28.910002,20.721413,-95.900932,-0.000996,0.001457,0.037005,92.173447,4.695539,0.370045,-95.900932,0.037872,0.000000
29.230001,21.476585,-95.856453,-0.000970,0.001476,0.037482,95.532623,4.866663,0.374815,-95.856453,0.038409,0.000000
29.550001,22.419800,-95.856453,-0.000970,0.001496,0.038011,99.728249,5.080399,0.380105,-95.856453,0.038938,0.000000
29.870001,23.226738,-95.900932,-0.000970,0.001514,0.038453,103.317688,5.263254,0.384528,-95.900932,0.039476,0.000000
30.190001,24.435829,-95.945412,-0.000966,0.001535,0.038982,108.695999,5.537238,0.389818,-95.945412,0.040005,0.000000
30.510002,25.957344,-96.034370,-0.000927,0.001560,0.039615,115.464035,5.882018,0.396149,-96.034370,0.040543,0.000000
30.830002,27.026054,-96.034370,-0.000923,0.001583,0.040213,120.217896,6.124192,0.402133,-96.034370,0.041072,0.000000
31.150002,27.843781,-95.989891,-0.000910,0.001602,0.040690,123.855324,6.309491,0.406902,-95.989891,0.041609,0.000000
31.470001,28.498413,-96.034370,-0.000905,0.001617,0.041072,126.767273,6.457833,0.410718,-96.034370,0.042139,0.000000
31.790001,29.619621,-96.167816,-0.000901,0.001637,0.041575,131.754654,6.711902,0.415748,-96.167816,0.042676,0.000000
32.110001,31.179123,-96.167816,-0.000871,0.001662,0.042208,138.691666,7.065290,0.422079,-96.167816,0.043205,0.000000
32.430000,32.100746,-96.212296,-0.000862,0.001679,0.042641,142.791245,7.274133,0.426415,-96.212296,0.043743,0.000000
32.750000,33.711250,-96.212296,-0.000845,0.001706,0.043335,149.955124,7.639078,0.433353,-96.212296,0.044272,0.000000
33.070000,34.615746,-96.256775,-0.000849,0.001728,0.043882,153.978531,7.844040,0.438816,-96.256775,0.044810,0.000000
33.390003,35.176537,-96.301262,-0.000819,0.001738,0.044142,156.473053,7.971117,0.441418,-96.301262,0.045339,0.000000
33.710003,36.324188,-96.434700,-0.000802,0.001757,0.044627,161.578064,8.231178,0.446274,-96.434700,0.045876,0.000000
34.030003,38.426231,-96.390221,-0.000806,0.001786,0.045373,170.928421,8.707508,0.453733,-96.390221,0.046405,0.000000
34.350002,39.911255,-96.390221,-0.000802,0.001811,0.046006,177.534134,9.044020,0.460063,-96.390221,0.046943,0.000000
34.670002,41.538895,-96.390221,-0.000780,0.001836,0.046631,184.774231,9.412848,0.466307,-96.390221,0.047472,0.000000
34.990002,42.159637,-96.479179,-0.000772,0.001852,0.047047,187.535431,9.553511,0.470470,-96.479179,0.048010,0.000000
35.310001,43.420120,-96.568146,-0.000750,0.001872,0.047550,193.142334,9.839140,0.475500,-96.568146,0.048539,0.000000
35.630001,44.059113,-96.612625,-0.000755,0.001882,0.047810,195.984726,9.983938,0.478102,-96.612625,0.049076,0.000000
35.950001,46.231529,-96.523666,-0.000737,0.001911,0.048530,205.648117,10.476213,0.485300,-96.523666,0.049605,0.000000
36.270000,47.482330,-96.657104,-0.000724,0.001929,0.049007,211.211960,10.759650,0.490069,-96.657104,0.050143,0.000000
36.590000,49.537453,-96.657104,-0.000729,0.001956,0.049683,220.353592,11.225348,0.496834,-96.657104,0.050672,0.000000
36.910000,50.582336,-96.701584,-0.000720,0.001974,0.050134,225.001465,11.462121,0.501343,-96.701584,0.051210,0.000000
37.230003,51.880424,-96.701584,-0.000707,0.001994,0.050646,230.775650,11.756272,0.506460,-96.701584,0.051739,0.000000
37.550003,52.686234,-96.701584,-0.000694,0.002014,0.051158,234.360077,11.938871,0.511577,-96.701584,0.052276,0.000000
37.870003,52.666870,-96.835030,-0.000686,0.002006,0.050958,234.273941,11.934484,0.509582,-96.835030,0.008962,0.000000
38.190002,52.266571,-96.879509,-0.000686,0.002006,0.050958,232.493317,11.843774,0.509582,-96.879509,235.999924,0.000000
38.510002,51.911331,-96.879509,-0.000677,0.002006,0.050958,230.913132,11.763276,0.509582,-96.879509,235.999924,0.000000
38.830002,53.184471,-96.879509,-0.000651,0.001828,0.046431,236.576340,12.051773,0.464313,-96.879509,235.999924,0.000000
39.150002,52.927910,-96.923996,-0.000664,0.001828,0.046431,235.435104,11.993636,0.464313,-96.923996,235.999924,0.000000
39.470001,52.667618,-96.968475,-0.000655,0.001874,0.047611,234.277267,11.934652,0.476107,-96.968475,235.999924,0.000000
39.790001,52.501915,-97.057434,-0.000668,0.001989,0.050525,233.540176,11.897104,0.505246,-97.057434,235.999924,0.000000
40.110001,52.434883,-97.012955,-0.000651,0.002000,0.050811,233.242004,11.881914,0.508108,-97.012955,235.999924,0.000000
40.430000,52.304184,-97.057434,-0.000651,0.002002,0.050845,232.660629,11.852298,0.508454,-97.057434,235.999924,0.000000
40.750004,52.196564,-97.012955,-0.000664,0.002002,0.050845,232.181915,11.827910,0.508454,-97.012955,235.999924,0.000000
41.070004,52.585693,-97.101913,-0.000655,0.002022,0.051366,233.912842,11.916088,0.513658,-97.101913,235.999924,0.000000
41.390003,52.478828,-97.190880,-0.000664,0.002022,0.051366,233.437485,11.891872,0.513658,-97.190880,235.999924,0.000000
41.710003,52.414032,-97.190880,-0.000660,0.002023,0.051374,233.149261,11.877189,0.513745,-97.190880,235.999924,0.000000
42.030003,52.376427,-97.235359,-0.000660,0.002024,0.051400,232.981979,11.868668,0.514005,-97.235359,235.999924,0.000000
42.350002,52.595009,-97.235359,-0.000660,0.002028,0.051505,233.954285,11.918200,0.515045,-97.235359,235.999924,0.000000
42.670002,52.583466,-97.324318,-0.000655,0.002027,0.051479,233.902939,11.915584,0.514785,-97.324318,235.999924,0.000000
42.990002,52.476967,-97.413284,-0.000664,0.002027,0.051479,233.429214,11.891451,0.514785,-97.413284,235.999924,0.000000
43.310001,52.427437,-97.368805,-0.000651,0.002027,0.051479,233.208893,11.880226,0.514785,-97.368805,235.999924,0.000000
43.630001,52.386475,-97.324318,-0.000664,0.002027,0.051479,233.026672,11.870945,0.514785,-97.324318,235.999924,0.000000
43.950001,52.294502,-97.457764,-0.000673,0.002027,0.051479,232.617569,11.850103,0.514785,-97.457764,235.999924,0.000000
44.270000,52.252052,-97.502243,-0.000655,0.002027,0.051479,232.428741,11.840484,0.514785,-97.502243,235.999924,0.000000
44.590004,52.211464,-97.591209,-0.000664,0.002027,0.051479,232.248184,11.831286,0.514785,-97.591209,235.999924,0.000000
44.910004,52.143318,-97.591209,-0.000664,0.002027,0.051479,231.945068,11.815845,0.514785,-97.591209,235.999924,0.000000
45.230003,52.097145,-97.546722,-0.000647,0.002027,0.051479,231.739670,11.805382,0.514785,-97.546722,235.999924,0.000000
45.550003,52.058792,-97.546722,-0.000664,0.002027,0.051479,231.569077,11.796691,0.514785,-97.546722,235.999924,0.000000
45.870003,53.645096,-97.635689,-0.000651,0.002045,0.051955,238.625305,12.156152,0.519555,-97.635689,235.999924,0.000000
46.190002,53.390762,-97.724648,-0.000638,0.001860,0.047238,237.493973,12.098520,0.472378,-97.724648,235.999924,0.000000
46.510002,53.293579,-97.724648,-0.000638,0.001860,0.047238,237.061676,12.076497,0.472378,-97.724648,235.999924,0.000000
46.830002,53.242187,-97.724648,-0.000634,0.001860,0.047238,236.833084,12.064853,0.472378,-97.724648,235.999924,0.000000
47.150002,53.197502,-97.724648,-0.000655,0.001860,0.047255,236.634308,12.054727,0.472551,-97.724648,235.999924,0.000000
47.470001,53.143509,-97.858093,-0.000660,0.001860,0.047255,236.394135,12.042492,0.472551,-97.858093,235.999924,0.000000
47.790001,53.102921,-97.858093,-0.000638,0.001860,0.047255,236.213593,12.033294,0.472551,-97.858093,235.999924,0.000000
48.110001,53.058235,-97.902573,-0.000638,0.001860,0.047255,236.014816,12.023168,0.472551,-97.902573,235.999924,0.000000
48.430004,53.021004,-97.858093,-0.000647,0.001860,0.047255,235.849197,12.014731,0.472551,-97.858093,235.999924,0.000000
48.750004,52.987488,-97.858093,-0.000638,0.001860,0.047255,235.700119,12.007136,0.472551,-97.858093,235.999924,0.000000
49.070004,52.947639,-97.947052,-0.000642,0.001860,0.047255,235.522858,11.998106,0.472551,-97.947052,235.999924,0.000000
49.390003,52.832581,-98.036018,-0.000629,0.001862,0.047290,235.011063,11.972034,0.472898,-98.036018,235.999924,0.000000
49.710003,52.828110,-98.036018,-0.000634,0.001870,0.047489,234.991165,11.971021,0.474893,-98.036018,235.999924,0.000000
50.030003,52.835556,-98.036018,-0.000634,0.001873,0.047576,235.024292,11.972709,0.475760,-98.036018,235.999924,0.000000
50.350002,52.812843,-98.080498,-0.000638,0.001874,0.047611,234.923264,11.967561,0.476107,-98.080498,235.999924,0.000000
50.670002,52.765182,-98.169456,-0.000651,0.001877,0.047680,234.711258,11.956761,0.476801,-98.169456,235.999924,0.000000
50.990002,52.757362,-98.124977,-0.000655,0.001887,0.047932,234.676468,11.954989,0.479316,-98.124977,235.999924,0.000000
51.310001,52.682144,-98.258423,-0.000638,0.001901,0.048296,234.341888,11.937944,0.482958,-98.258423,235.999924,0.000000
51.630001,52.648628,-98.213943,-0.000634,0.001932,0.049068,234.192795,11.930349,0.490676,-98.213943,235.999924,0.000000
51.950001,52.630753,-98.258423,-0.000642,0.002000,0.050802,234.113281,11.926299,0.508021,-98.258423,235.999924,0.000000
52.270004,52.613251,-98.302902,-0.000642,0.002000,0.050811,234.035431,11.922333,0.508108,-98.302902,235.999924,0.000000
52.590004,52.590164,-98.347382,-0.000647,0.002000,0.050811,233.932739,11.917101,0.508108,-98.347382,235.999924,0.000000
52.910004,52.578995,-98.347382,-0.000634,0.002001,0.050828,233.883057,11.914570,0.508281,-98.347382,235.999924,0.000000
53.230003,52.520157,-98.391861,-0.000642,0.002001,0.050837,233.621323,11.901237,0.508368,-98.391861,235.999924,0.000000
53.550003,52.473610,-98.436348,-0.000664,0.002001,0.050837,233.414276,11.890691,0.508368,-98.436348,235.999924,0.000000
53.870003,52.481056,-98.480827,-0.000651,0.002001,0.050837,233.447403,11.892377,0.508368,-98.480827,235.999924,0.000000
54.190002,52.462814,-98.436348,-0.000638,0.002001,0.050837,233.366257,11.888244,0.508368,-98.436348,235.999924,0.000000
54.510002,52.453506,-98.569786,-0.000651,0.002001,0.050837,233.324844,11.886135,0.508368,-98.569786,235.999924,0.000000
54.830002,52.433769,-98.569786,-0.000638,0.002001,0.050837,233.237061,11.881661,0.508368,-98.569786,235.999924,0.000000
55.150002,52.412544,-98.569786,-0.000647,0.002001,0.050837,233.142639,11.876852,0.508368,-98.569786,235.999924,0.000000
55.470001,52.394295,-98.614265,-0.000638,0.002001,0.050837,233.061462,11.872717,0.508368,-98.614265,235.999924,0.000000
55.790001,52.371208,-98.703232,-0.000647,0.002001,0.050837,232.958771,11.867485,0.508368,-98.703232,235.999924,0.000000
56.110004,52.333603,-98.703232,-0.000634,0.002001,0.050837,232.791489,11.858964,0.508368,-98.703232,235.999924,0.000000
56.430004,52.307907,-98.747711,-0.000638,0.002001,0.050837,232.677185,11.853141,0.508368,-98.747711,235.999924,0.000000
56.750004,52.433769,-98.747711,-0.000629,0.002024,0.051400,233.237061,11.881661,0.514005,-98.747711,235.999924,0.000000
57.070004,52.442329,-98.747711,-0.000655,0.002027,0.051496,233.275131,11.883602,0.514959,-98.747711,235.999924,0.000000
57.390003,52.430786,-98.836670,-0.000647,0.002027,0.051496,233.223785,11.880985,0.514959,-98.836670,235.999924,0.000000
57.710003,52.409561,-98.925636,-0.000642,0.002027,0.051496,233.129364,11.876176,0.514959,-98.925636,235.999924,0.000000
58.030003,52.399879,-98.881157,-0.000642,0.002027,0.051496,233.086304,11.873982,0.514959,-98.881157,235.999924,0.000000
58.350002,52.373444,-98.881157,-0.000642,0.002027,0.051496,232.968719,11.867991,0.514959,-98.881157,235.999924,0.000000
58.670002,52.361153,-98.970116,-0.000651,0.002027,0.051496,232.914032,11.865207,0.514959,-98.970116,235.999924,0.000000
58.990002,52.326523,-98.970116,-0.000638,0.002032,0.051609,232.759995,11.857360,0.516086,-98.970116,235.999924,0.000000
59.310001,52.423340,-99.103561,-0.000642,0.002034,0.051661,233.190659,11.879299,0.516606,-99.103561,235.999924,0.000000
59.630001,52.421852,-99.059074,-0.000638,0.002034,0.051661,233.184052,11.878961,0.516606,-99.059074,235.999924,0.000000
59.950005,52.424835,-99.103561,-0.000642,0.002034,0.051661,233.197311,11.879638,0.516606,-99.103561,235.999924,0.000000
60.270004,52.393181,-99.103561,-0.000634,0.002034,0.051661,233.056503,11.872464,0.516606,-99.103561,235.999924,0.000000
60.590004,52.374565,-99.237000,-0.000655,0.002034,0.051661,232.973694,11.868246,0.516606,-99.237000,235.999924,0.000000
60.910004,52.358925,-99.281487,-0.000647,0.002034,0.051661,232.904129,11.864701,0.516606,-99.281487,235.999924,0.000000
61.230003,52.336952,-99.281487,-0.000629,0.002034,0.051661,232.806396,11.859723,0.516606,-99.281487,235.999924,0.000000
61.550003,52.320564,-99.237000,-0.000634,0.002034,0.051661,232.733490,11.856009,0.516606,-99.237000,235.999924,0.000000
61.870003,52.308281,-99.325966,-0.000638,0.002034,0.051661,232.678848,11.853226,0.516606,-99.325966,235.999924,0.000000
62.190002,52.282959,-99.414925,-0.000642,0.002034,0.051661,232.566223,11.847488,0.516606,-99.414925,235.999924,0.000000
62.510002,52.267319,-99.414925,-0.000642,0.002034,0.051661,232.496643,11.843944,0.516606,-99.414925,235.999924,0.000000
62.830002,52.268066,-99.459404,-0.000621,0.002034,0.051661,232.499969,11.844113,0.516606,-99.459404,235.999924,0.000000
63.150002,52.249069,-99.370445,-0.000647,0.002034,0.051661,232.415466,11.839808,0.516606,-99.370445,235.999924,0.000000
63.470001,52.229706,-99.459404,-0.000647,0.002034,0.051661,232.329330,11.835420,0.516606,-99.459404,235.999924,0.000000
63.790005,52.232689,-99.548370,-0.000655,0.002034,0.051661,232.342606,11.836097,0.516606,-99.548370,235.999924,0.000000
64.110001,52.200294,-99.592850,-0.000660,0.002034,0.051661,232.198502,11.828755,0.516606,-99.592850,235.999924,0.000000
64.430000,52.182045,-99.592850,-0.000647,0.002034,0.051661,232.117325,11.824620,0.516606,-99.592850,235.999924,0.000000
64.750000,52.182793,-99.592850,-0.000647,0.002034,0.051661,232.120651,11.824790,0.516606,-99.592850,235.999924,0.000000
65.070000,53.177399,-99.637329,-0.000625,0.002015,0.051192,236.544876,12.050171,0.511923,-99.637329,235.999924,0.000000
65.389999,53.166969,-99.726295,-0.000647,0.002015,0.051192,236.498489,12.047808,0.511923,-99.726295,235.999924,0.000000
65.710007,53.151329,-99.726295,-0.000638,0.002015,0.051192,236.428925,12.044264,0.511923,-99.726295,235.999924,0.000000
66.030006,53.131966,-99.726295,-0.000638,0.002015,0.051192,236.342789,12.039876,0.511923,-99.726295,235.999924,0.000000
66.350006,53.123772,-99.770775,-0.000634,0.002015,0.051192,236.306335,12.038018,0.511923,-99.770775,235.999924,0.000000
66.670006,53.107018,-99.859734,-0.000634,0.002015,0.051192,236.231812,12.034222,0.511923,-99.859734,235.999924,0.000000
66.990005,53.089142,-99.859734,-0.000638,0.002015,0.051192,236.152298,12.030171,0.511923,-99.859734,235.999924,0.000000
67.310005,53.086166,-99.904213,-0.000647,0.002015,0.051192,236.139069,12.029497,0.511923,-99.904213,235.999924,0.000000
67.630005,53.057861,-99.948700,-0.000625,0.002015,0.051192,236.013153,12.023084,0.511923,-99.948700,235.999924,0.000000
67.950005,53.049675,-99.948700,-0.000651,0.002015,0.051192,235.976746,12.021228,0.511923,-99.948700,235.999924,0.000000
68.270004,53.049675,-100.037659,-0.000638,0.002015,0.051192,235.976746,12.021228,0.511923,-100.037659,235.999924,0.000000
68.590004,53.016533,-99.993179,-0.000634,0.002015,0.051192,235.829315,12.013719,0.511923,-99.993179,235.999924,0.000000
68.910004,53.026215,-100.171104,-0.000629,0.002015,0.051192,235.872375,12.015912,0.511923,-100.171104,235.999924,0.000000
69.230003,52.989723,-100.082138,-0.000629,0.002015,0.051192,235.710068,12.007643,0.511923,-100.082138,235.999924,0.000000
69.550003,52.996796,-100.171104,-0.000634,0.002015,0.051192,235.741516,12.009245,0.511923,-100.171104,235.999924,0.000000
69.870003,52.989349,-100.215584,-0.000629,0.002015,0.051192,235.708405,12.007559,0.511923,-100.215584,235.999924,0.000000
70.190002,52.957695,-100.215584,-0.000642,0.002015,0.051192,235.567596,12.000385,0.511923,-100.215584,235.999924,0.000000
70.510002,52.954346,-100.304543,-0.000634,0.002015,0.051192,235.552689,11.999626,0.511923,-100.304543,235.999924,0.000000
70.830002,52.937218,-100.304543,-0.000642,0.002015,0.051192,235.476501,11.995745,0.511923,-100.304543,235.999924,0.000000
71.150002,52.923065,-100.349022,-0.000625,0.002015,0.051192,235.413559,11.992538,0.511923,-100.349022,235.999924,0.000000
71.470001,52.912636,-100.349022,-0.000651,0.002015,0.051192,235.367157,11.990174,0.511923,-100.349022,235.999924,0.000000
71.790001,52.844872,-100.393509,-0.000638,0.002015,0.051192,235.065735,11.974819,0.511923,-100.393509,235.999924,0.000000
72.110001,52.852684,-100.393509,-0.000642,0.002015,0.051192,235.100479,11.976589,0.511923,-100.393509,235.999924,0.000000
72.430000,52.856781,-100.437988,-0.000634,0.002015,0.051192,235.118698,11.977518,0.511923,-100.437988,235.999924,0.000000
72.750000,52.863861,-100.437988,-0.000634,0.002015,0.051192,235.150192,11.979122,0.511923,-100.437988,235.999924,0.000000
73.070000,52.825134,-100.482468,-0.000629,0.002015,0.051192,234.977936,11.970346,0.511923,-100.482468,235.999924,0.000000
73.390007,52.810608,-100.526947,-0.000629,0.002015,0.051192,234.913315,11.967054,0.511923,-100.526947,235.999924,0.000000
73.710007,52.813217,-100.615913,-0.000629,0.002015,0.051192,234.924927,11.967647,0.511923,-100.615913,235.999924,0.000000
74.030006,52.791992,-100.660393,-0.000634,0.002015,0.051192,234.830505,11.962836,0.511923,-100.660393,235.999924,0.000000
74.350006,52.799812,-100.615913,-0.000647,0.002015,0.051192,234.865295,11.964608,0.511923,-100.615913,235.999924,0.000000
74.670006,52.822525,-100.615913,-0.000647,0.002015,0.051192,234.966324,11.969755,0.511923,-100.615913,235.999924,0.000000
74.990005,52.802414,-100.749352,-0.000634,0.002015,0.051192,234.876862,11.965198,0.511923,-100.749352,235.999924,0.000000
75.310005,52.789757,-100.749352,-0.000638,0.002015,0.051192,234.820572,11.962330,0.511923,-100.749352,235.999924,0.000000
75.630005,52.770767,-100.793839,-0.000621,0.002015,0.051192,234.736099,11.958027,0.511923,-100.793839,235.999924,0.000000
75.950005,52.766296,-100.793839,-0.000629,0.002015,0.051192,234.716202,11.957014,0.511923,-100.793839,235.999924,0.000000
76.270004,52.769279,-100.793839,-0.000634,0.002015,0.051192,234.729477,11.957690,0.511923,-100.793839,235.999924,0.000000
76.590004,52.758476,-100.927277,-0.000642,0.002015,0.051192,234.681427,11.955241,0.511923,-100.927277,235.999924,0.000000
76.910004,52.761086,-100.882797,-0.000629,0.002015,0.051192,234.693024,11.955832,0.511923,-100.882797,235.999924,0.000000
77.230003,52.754005,-100.971756,-0.000642,0.002015,0.051192,234.661530,11.954228,0.511923,-100.971756,235.999924,0.000000
77.550003,52.752518,-100.927277,-0.000612,0.002015,0.051192,234.654922,11.953892,0.511923,-100.927277,235.999924,0.000000
77.870003,52.698151,-101.016243,-0.000638,0.002015,0.051192,234.413086,11.941571,0.511923,-101.016243,235.999924,0.000000
78.190002,52.681023,-101.060722,-0.000625,0.002015,0.051192,234.336899,11.937690,0.511923,-101.060722,235.999924,0.000000
78.510002,52.664268,-101.149681,-0.000629,0.002015,0.051192,234.262360,11.933893,0.511923,-101.149681,235.999924,0.000000
78.830002,52.657936,-101.105202,-0.000629,0.002015,0.051192,234.234192,11.932459,0.511923,-101.105202,235.999924,0.000000
79.150002,52.656075,-101.149681,-0.000647,0.002015,0.051192,234.225922,11.932037,0.511923,-101.149681,235.999924,0.000000
79.470001,52.635963,-101.194160,-0.000634,0.002015,0.051192,234.136459,11.927480,0.511923,-101.194160,235.999924,0.000000
79.790001,52.630379,-101.238647,-0.000625,0.002015,0.051192,234.111618,11.926214,0.511923,-101.238647,235.999924,0.000000
80.110001,52.631874,-101.283127,-0.000629,0.002015,0.051192,234.118271,11.926553,0.511923,-101.283127,235.999924,0.000000
80.430000,52.614372,-101.283127,-0.000629,0.002015,0.051192,234.040421,11.922587,0.511923,-101.283127,235.999924,0.000000
80.750008,52.631126,-101.327606,-0.000647,0.002015,0.051192,234.114944,11.926384,0.511923,-101.327606,235.999924,0.000000
81.070007,52.607292,-101.327606,-0.000638,0.002015,0.051192,234.008926,11.920983,0.511923,-101.327606,235.999924,0.000000
81.390007,52.607292,-101.416565,-0.000638,0.002015,0.051192,234.008926,11.920983,0.511923,-101.416565,235.999924,0.000000
81.710007,52.581970,-101.461052,-0.000625,0.002015,0.051192,233.896286,11.915245,0.511923,-101.461052,235.999924,0.000000
82.030006,52.598358,-101.416565,-0.000629,0.002015,0.051192,233.969177,11.918959,0.511923,-101.416565,235.999924,0.000000
82.350006,52.588303,-101.372086,-0.000629,0.002015,0.051192,233.924454,11.916680,0.511923,-101.372086,235.999924,0.000000
82.670006,52.573784,-101.505531,-0.000638,0.002015,0.051192,233.859863,11.913390,0.511923,-101.505531,235.999924,0.000000
82.990005,52.580856,-101.505531,-0.000625,0.002015,0.051192,233.891327,11.914992,0.511923,-101.505531,235.999924,0.000000
83.310005,52.560379,-101.594490,-0.000642,0.002015,0.051192,233.800247,11.910353,0.511923,-101.594490,235.999924,0.000000
83.630005,52.543991,-101.594490,-0.000629,0.002015,0.051192,233.727341,11.906638,0.511923,-101.594490,235.999924,0.000000
83.950005,52.521652,-101.594490,-0.000634,0.002015,0.051192,233.627975,11.901576,0.511923,-101.594490,235.999924,0.000000
84.270004,52.497818,-101.638969,-0.000642,0.002015,0.051192,233.521957,11.896175,0.511923,-101.638969,235.999924,0.000000
84.590004,52.508987,-101.727936,-0.000629,0.002015,0.051192,233.571640,11.898706,0.511923,-101.727936,235.999924,0.000000
84.910004,52.493721,-101.727936,-0.000638,0.002015,0.051192,233.503738,11.895247,0.511923,-101.727936,235.999924,0.000000
85.230003,52.477333,-101.772415,-0.000647,0.002015,0.051192,233.430832,11.891534,0.511923,-101.772415,235.999924,0.000000
85.550003,52.485527,-101.816895,-0.000638,0.002015,0.051192,233.467285,11.893391,0.511923,-101.816895,235.999924,0.000000
85.870003,52.460205,-101.861382,-0.000634,0.002015,0.051192,233.354645,11.887652,0.511923,-101.861382,235.999924,0.000000
86.190002,52.468773,-101.905861,-0.000647,0.002015,0.051192,233.392761,11.889594,0.511923,-101.905861,235.999924,0.000000
86.510002,52.447922,-101.905861,-0.000638,0.002015,0.051192,233.300003,11.884870,0.511923,-101.905861,235.999924,0.000000
86.830002,52.453506,-101.950340,-0.000625,0.002015,0.051192,233.324844,11.886135,0.511923,-101.950340,235.999924,0.000000
87.150002,52.446060,-102.039299,-0.000629,0.002015,0.051192,233.291733,11.884447,0.511923,-102.039299,235.999924,0.000000
87.470001,52.440842,-102.083786,-0.000634,0.002015,0.051192,233.268509,11.883265,0.511923,-102.083786,235.999924,0.000000
87.790001,52.439354,-102.083786,-0.000629,0.002015,0.051192,233.261902,11.882928,0.511923,-102.083786,235.999924,0.000000
88.110001,52.429298,-102.039299,-0.000647,0.002015,0.051192,233.217163,11.880649,0.511923,-102.039299,235.999924,0.000000
88.430008,52.430786,-102.083786,-0.000634,0.002015,0.051192,233.223785,11.880985,0.511923,-102.083786,235.999924,0.000000
88.750008,52.423714,-102.083786,-0.000634,0.002015,0.051192,233.192322,11.879383,0.511923,-102.083786,235.999924,0.000000
89.070007,52.415154,-102.172745,-0.000629,0.002015,0.051192,233.154251,11.877444,0.511923,-102.172745,235.999924,0.000000
89.390007,52.417755,-102.217224,-0.000629,0.002015,0.051192,233.165817,11.878034,0.511923,-102.217224,235.999924,0.000000
89.710007,52.413658,-102.217224,-0.000642,0.002015,0.051192,233.147598,11.877105,0.511923,-102.217224,235.999924,0.000000
90.030006,52.397278,-102.261703,-0.000634,0.002015,0.051192,233.074738,11.873393,0.511923,-102.261703,235.999924,0.000000
90.350006,52.406586,-102.306190,-0.000638,0.002015,0.051192,233.116135,11.875503,0.511923,-102.306190,235.999924,0.000000
90.670006,52.380150,-102.350670,-0.000629,0.002015,0.051192,232.998550,11.869512,0.511923,-102.350670,235.999924,0.000000
90.990005,52.470634,-102.350670,-0.000625,0.002038,0.051773,233.401031,11.890016,0.517734,-102.350670,235.999924,0.000000
91.310005,52.467651,-102.439629,-0.000634,0.002038,0.051773,233.387772,11.889339,0.517734,-102.439629,235.999924,0.000000
91.630005,52.463928,-102.395149,-0.000634,0.002038,0.051773,233.371201,11.888496,0.517734,-102.395149,235.999924,0.000000
91.950005,52.471008,-102.484108,-0.000642,0.002038,0.051773,233.402695,11.890100,0.517734,-102.484108,235.999924,0.000000
92.270004,52.453506,-102.528595,-0.000629,0.002038,0.051773,233.324844,11.886135,0.517734,-102.528595,235.999924,0.000000
92.590004,52.504517,-102.528595,-0.000638,0.002044,0.051912,233.551758,11.897694,0.519121,-102.528595,235.999924,0.000000
92.910004,52.532074,-102.617554,-0.000621,0.002044,0.051912,233.674332,11.903938,0.519121,-102.617554,235.999924,0.000000
93.230003,52.503777,-102.617554,-0.000642,0.002044,0.051912,233.548462,11.897526,0.519121,-102.617554,235.999924,0.000000
93.550003,52.521278,-102.617554,-0.000634,0.002044,0.051912,233.626312,11.901492,0.519121,-102.617554,235.999924,0.000000
93.870003,52.511223,-102.706512,-0.000634,0.002044,0.051912,233.581589,11.899213,0.519121,-102.706512,235.999924,0.000000
94.190002,52.510849,-102.750999,-0.000642,0.002044,0.051912,233.579926,11.899129,0.519121,-102.750999,235.999924,0.000000
94.510002,52.506012,-102.706512,-0.000638,0.002044,0.051912,233.558411,11.898032,0.519121,-102.706512,235.999924,0.000000
94.830002,52.510475,-102.706512,-0.000629,0.002044,0.051912,233.578262,11.899043,0.519121,-102.706512,235.999924,0.000000
95.150002,52.490372,-102.795479,-0.000647,0.002044,0.051912,233.488831,11.894487,0.519121,-102.795479,235.999924,0.000000
95.470001,52.500420,-102.839958,-0.000629,0.002044,0.051912,233.533524,11.896765,0.519121,-102.839958,235.999924,0.000000
95.790001,52.496330,-102.884438,-0.000660,0.002044,0.051912,233.515335,11.895839,0.519121,-102.884438,235.999924,0.000000
96.110008,52.472122,-102.884438,-0.000638,0.002044,0.051912,233.407654,11.890352,0.519121,-102.884438,235.999924,0.000000
96.430008,52.491486,-102.884438,-0.000638,0.002044,0.051921,233.493790,11.894740,0.519208,-102.884438,235.999924,0.000000
96.750008,52.479942,-102.973404,-0.000638,0.002044,0.051921,233.442444,11.892125,0.519208,-102.973404,235.999924,0.000000
97.070007,52.482925,-103.062363,-0.000625,0.002044,0.051921,233.455719,11.892801,0.519208,-103.062363,235.999924,0.000000
97.390007,52.482925,-103.017883,-0.000621,0.002044,0.051921,233.455719,11.892801,0.519208,-103.017883,235.999924,0.000000
97.710007,52.497818,-103.017883,-0.000638,0.002046,0.051964,233.521957,11.896175,0.519642,-103.017883,235.999924,0.000000
98.030006,52.498558,-103.017883,-0.000642,0.002046,0.051964,233.525253,11.896343,0.519642,-103.017883,1347.594116,0.000000
98.350006,52.509735,-103.195808,-0.000651,0.002040,0.051825,233.574966,11.898876,0.518254,-103.195808,0.051886,0.000000
98.670006,52.426323,-103.195808,-0.000642,0.002031,0.051583,233.203934,11.879974,0.515826,-103.195808,0.051348,0.000000
98.990005,52.357803,-103.195808,-0.000638,0.002013,0.051123,232.899139,11.864448,0.511230,-103.195808,0.050819,0.000000
99.310005,52.355568,-103.240288,-0.000629,0.001997,0.050733,232.889191,11.863941,0.507327,-103.240288,0.050282,0.000000
99.630005,52.326523,-103.240288,-0.000638,0.001980,0.050299,232.759995,11.857360,0.502991,-103.240288,0.049753,0.000000
99.950005,52.315353,-103.329247,-0.000629,0.001956,0.049683,232.710312,11.854829,0.496834,-103.329247,0.049215,0.000000
100.270004,52.322800,-103.373734,-0.000638,0.001935,0.049154,232.743439,11.856516,0.491544,-103.373734,0.048686,0.000000
100.590004,52.314606,-103.373734,-0.000629,0.001915,0.048651,232.706985,11.854659,0.486514,-103.373734,0.048148,0.000000
100.910004,52.338440,-103.418213,-0.000621,0.001898,0.048200,232.813004,11.860060,0.482004,-103.418213,0.047619,0.000000
101.230003,52.300461,-103.418213,-0.000638,0.001869,0.047472,232.644073,11.851454,0.474719,-103.418213,0.047082,0.000000
101.550003,52.300461,-103.462692,-0.000621,0.001859,0.047229,232.644073,11.851454,0.472291,-103.462692,0.046553,0.000000
101.870003,52.169388,-103.507172,-0.000638,0.001837,0.046648,232.061020,11.821753,0.466481,-103.507172,0.046015,0.000000
102.190002,51.656624,-103.507172,-0.000625,0.001814,0.046067,229.780136,11.705558,0.460670,-103.507172,0.045486,0.000000
102.510002,51.039230,-103.507172,-0.000621,0.001795,0.045599,227.033829,11.565655,0.455987,-103.507172,0.044948,0.000000
102.830002,50.246078,-103.551651,-0.000617,0.001775,0.045096,223.505722,11.385924,0.450957,-103.551651,0.044419,0.000000
103.150002,49.229500,-103.640617,-0.000617,0.001755,0.044584,218.983749,11.155564,0.445841,-103.640617,0.043882,0.000000
103.470001,48.355919,-103.685097,-0.000608,0.001739,0.044159,215.097870,10.957607,0.441591,-103.685097,0.043353,0.000000
103.790009,47.163956,-103.729576,-0.000617,0.001723,0.043769,209.795746,10.687505,0.437689,-103.729576,0.042815,0.000000
104.110008,45.490509,-103.685097,-0.000617,0.001697,0.043110,202.351883,10.308297,0.431098,-103.685097,0.042286,0.000000
104.430008,43.966393,-103.774055,-0.000608,0.001678,0.042624,195.572281,9.962927,0.426242,-103.774055,0.041748,0.000000
104.750008,42.338005,-103.818542,-0.000612,0.001659,0.042139,188.328857,9.593929,0.421385,-103.818542,0.041219,0.000000
105.070007,40.589714,-103.818542,-0.000608,0.001639,0.041636,180.552063,9.197761,0.416355,-103.818542,0.040682,0.000000
105.390007,38.826164,-103.818542,-0.000612,0.001625,0.041280,172.707397,8.798135,0.412800,-103.818542,0.040153,0.000000
105.710007,36.344299,-103.818542,-0.000612,0.001598,0.040577,161.667511,8.235736,0.405775,-103.818542,0.039615,0.000000
106.030006,35.455818,-103.996460,-0.000634,0.001584,0.040231,157.715363,8.034404,0.402306,-103.996460,0.039086,0.000000
106.350006,31.563408,-103.996460,-0.000617,0.001554,0.039476,140.401047,7.152370,0.394761,-103.996460,0.038548,0.000000
106.670006,29.978218,-103.996460,-0.000617,0.001542,0.039173,133.349777,6.793161,0.391726,-103.996460,0.038019,0.000000
106.990005,27.672859,-104.040947,-0.000621,0.001522,0.038661,123.095024,6.270760,0.386609,-104.040947,0.037482,0.000000
107.310005,24.691650,-104.040947,-0.000625,0.001493,0.037915,109.833946,5.595208,0.379151,-104.040947,0.036952,0.000000
107.630005,22.454437,-104.085426,-0.000642,0.001474,0.037447,99.882324,5.088248,0.374468,-104.085426,0.036415,0.000000
107.950005,20.306961,-104.129906,-0.000642,0.001454,0.036944,90.329872,4.601623,0.369438,-104.129906,0.035886,0.000000
108.270004,17.688065,-104.085426,-0.000647,0.001429,0.036293,78.680443,4.008173,0.362934,-104.085426,0.035348,0.000000
108.590004,15.775558,-104.174385,-0.000642,0.001412,0.035877,70.173187,3.574793,0.358771,-104.174385,0.034819,0.000000
108.910004,13.097832,-104.263351,-0.000647,0.001387,0.035235,58.262066,2.968011,0.352354,-104.263351,0.034281,0.000000
109.230003,11.940125,-104.352310,-0.000651,0.001379,0.035019,53.112328,2.705671,0.350186,-104.352310,0.033752,0.000000
109.550003,8.781662,-104.263351,-0.000651,0.001349,0.034273,39.062782,1.989953,0.342728,-104.263351,0.033215,0.000000
109.870003,7.350632,-104.307831,-0.000655,0.001335,0.033909,32.697243,1.665677,0.339085,-104.307831,0.032686,0.000000
110.190002,4.297928,-104.307831,-0.000660,0.001304,0.033119,19.118137,0.973924,0.331194,-104.307831,0.032148,0.000000
110.510002,2.256577,-104.352310,-0.000664,0.001286,0.032668,10.037754,0.511348,0.326684,-104.352310,0.031619,0.000000
110.830002,0.184326,-104.396790,-0.000668,0.001265,0.032131,0.819924,0.041769,0.321307,-104.396790,0.031081,0.000000
111.150002,-0.062553,-104.441277,-0.000673,0.001243,0.031584,-0.278251,-0.014175,0.315844,-104.441277,0.030552,0.000000
111.470009,-0.047287,-104.441277,-0.000681,0.001225,0.031125,-0.210343,-0.010715,0.311247,-104.441277,0.030015,0.000000
111.790009,-0.047661,-104.485756,-0.000707,0.001215,0.030873,-0.212006,-0.010800,0.308732,-104.485756,0.029486,0.000000
112.110008,-0.058090,-104.530235,-0.000776,0.001174,0.029824,-0.258398,-0.013163,0.298239,-104.530235,0.028948,0.000000
112.430008,-0.057716,-104.574715,-0.000806,0.001157,0.029382,-0.256735,-0.013079,0.293816,-104.574715,0.028419,0.000000
112.750008,-0.039101,-104.619194,-0.000832,0.001135,0.028827,-0.173928,-0.008860,0.288266,-104.619194,0.027881,0.000000
113.070007,-0.058830,-104.708160,-0.000862,0.001115,0.028324,-0.261690,-0.013331,0.283236,-104.708160,0.027352,0.000000
113.390007,-0.055481,-104.663681,-0.000871,0.001101,0.027968,-0.246792,-0.012572,0.279680,-104.663681,0.026815,0.000000
113.710007,-0.050644,-104.663681,-0.000910,0.001076,0.027335,-0.225275,-0.011476,0.273350,-104.663681,0.026286,0.000000
114.030006,-0.050270,-104.797119,-0.000923,0.001050,0.026676,-0.223612,-0.011391,0.266759,-104.797119,0.025748,0.000000
114.350006,-0.062187,-104.841599,-0.000936,0.001031,0.026190,-0.276622,-0.014092,0.261902,-104.841599,0.025219,0.000000
114.670006,-0.050270,-104.797119,-0.000979,0.001011,0.025687,-0.223612,-0.011391,0.256872,-104.797119,0.024681,0.000000
114.990005,-0.033882,-104.797119,-0.000987,0.000988,0.025106,-0.150715,-0.007678,0.251062,-104.797119,0.024152,0.000000
115.310005,-0.045425,-104.841599,-0.001022,0.000968,0.024595,-0.202062,-0.010294,0.245945,-104.841599,0.023615,0.000000
115.630005,-0.068146,-104.975044,-0.001030,0.000948,0.024092,-0.303127,-0.015442,0.240915,-104.975044,0.023086,0.000000
115.950005,-0.033508,-104.930565,-0.001056,0.000923,0.023450,-0.149052,-0.007593,0.234498,-104.930565,0.022548,0.000000
116.270004,-0.059204,-104.975044,-0.001091,0.000905,0.022999,-0.263353,-0.013416,0.229988,-104.975044,0.022019,0.000000
116.590004,-0.040962,-105.019524,-0.001099,0.000881,0.022366,-0.182209,-0.009282,0.223658,-105.019524,0.021481,0.000000
116.910004,-0.053246,-105.064003,-0.001121,0.000863,0.021932,-0.236848,-0.012066,0.219321,-105.064003,0.020952,0.000000
117.230003,-0.058830,-105.108490,-0.001130,0.000840,0.021342,-0.261690,-0.013331,0.213424,-105.108490,0.020414,0.000000
117.550003,-0.054367,-105.197449,-0.001151,0.000818,0.020787,-0.241837,-0.012320,0.207874,-105.197449,0.019885,0.000000
117.870003,-0.048782,-105.152969,-0.001186,0.000796,0.020224,-0.216995,-0.011054,0.202237,-105.152969,0.019348,0.000000
118.190002,-0.035744,-105.152969,-0.001212,0.000778,0.019773,-0.158996,-0.008100,0.197728,-105.152969,0.018819,0.000000
118.510002,-0.017868,-105.197449,-0.001212,0.000754,0.019157,-0.079481,-0.004049,0.191570,-105.197449,0.018281,0.000000
118.830002,-0.035004,-105.286407,-0.001237,0.000732,0.018602,-0.155704,-0.007932,0.186020,-105.286407,0.017752,0.000000
119.150009,-0.042450,-105.330894,-0.001233,0.000720,0.018281,-0.188827,-0.009619,0.182811,-105.330894,0.017214,0.000000
119.470009,-0.024574,-105.330894,-0.001293,0.000694,0.017622,-0.109312,-0.005569,0.176220,-105.330894,0.016685,0.000000
119.790009,-0.039101,-105.330894,-0.001298,0.000674,0.017110,-0.173928,-0.008860,0.171104,-105.330894,0.016148,0.000000
120.110008,-0.051010,-105.375374,-0.001341,0.000654,0.016616,-0.226904,-0.011559,0.166160,-105.375374,0.015619,0.000000
120.430008,-0.006325,-105.375374,-0.001345,0.000632,0.016044,-0.028134,-0.001433,0.160437,-105.375374,0.015081,0.000000
120.750008,-0.018990,-105.464333,-0.001371,0.000606,0.015402,-0.084470,-0.004303,0.154019,-105.464333,0.014552,0.000000
121.070007,-0.008934,-105.464333,-0.001397,0.000588,0.014942,-0.039741,-0.002024,0.149423,-105.464333,0.014014,0.000000
121.390007,0.002983,-105.553299,-0.001406,0.000577,0.014656,0.013269,0.000676,0.146561,-105.553299,0.013485,0.000000
121.710007,-0.018990,-105.597778,-0.001457,0.000546,0.013867,-0.084470,-0.004303,0.138669,-105.597778,0.012948,0.000000
122.030006,-0.016754,-105.553299,-0.001457,0.000526,0.013355,-0.074526,-0.003797,0.133553,-105.553299,0.012419,0.000000
122.350006,-0.011169,-105.642258,-0.001475,0.000508,0.012913,-0.049684,-0.002531,0.129130,-105.642258,0.011881,0.000000
122.670006,0.012291,-105.642258,-0.001496,0.000490,0.012453,0.054673,0.002785,0.124534,-105.642258,0.011352,0.000000
122.990005,0.006706,-105.642258,-0.001518,0.000465,0.011803,0.029831,0.001520,0.118029,-105.642258,0.010814,0.000000
123.310005,-0.012657,-105.686737,-0.001535,0.000445,0.011309,-0.056302,-0.002868,0.113086,-105.686737,0.010285,0.000000
123.630005,-0.027550,-105.820183,-0.001561,0.000420,0.010676,-0.122547,-0.006243,0.106756,-105.820183,0.009748,0.000000
123.950005,-0.025322,-105.820183,-0.001578,0.000399,0.010129,-0.112638,-0.005738,0.101292,-105.820183,0.009219,0.000000
124.270004,-0.005211,-105.775703,-0.001595,0.000377,0.009574,-0.023179,-0.001181,0.095742,-105.775703,0.008681,0.000000
124.590004,-0.018242,-105.775703,-0.001621,0.000362,0.009193,-0.081144,-0.004134,0.091926,-105.775703,0.008152,0.000000
124.910004,-0.021599,-105.909142,-0.001660,0.000343,0.008724,-0.096076,-0.004894,0.087243,-105.909142,0.007614,0.000000
125.230003,-0.017502,-105.953629,-0.001677,0.000315,0.008004,-0.077852,-0.003966,0.080045,-105.953629,0.007085,0.000000
125.550003,-0.019737,-105.953629,-0.001716,0.000292,0.007423,-0.087796,-0.004473,0.074235,-105.953629,0.006548,0.000000
125.870003,-0.014893,-105.953629,-0.001720,0.000273,0.006946,-0.066245,-0.003375,0.069465,-105.953629,0.006019,0.000000
126.190002,-0.049522,-105.953629,-0.001746,0.000255,0.006487,-0.220287,-0.011222,0.064868,-105.953629,0.005481,0.000000
126.510010,-0.023460,-105.998108,-0.001759,0.000241,0.006114,-0.104357,-0.005316,0.061139,-105.998108,0.004952,0.000000
126.830009,-0.026062,-106.087067,-0.001785,0.000212,0.005394,-0.115930,-0.005906,0.053941,-106.087067,0.004414,0.000000
127.150009,-0.049522,-106.131546,-0.001802,0.000196,0.004987,-0.220287,-0.011222,0.049866,-106.131546,0.003885,0.000000
127.470009,-0.013405,-106.087067,-0.001824,0.000167,0.004241,-0.059628,-0.003038,0.042407,-106.087067,0.003347,0.000000
127.790009,-0.032021,-106.131546,-0.001850,0.000149,0.003772,-0.142435,-0.007256,0.037724,-106.131546,0.002818,0.000000
128.110001,-0.024948,-106.220512,-0.001876,0.000127,0.003217,-0.110975,-0.005653,0.032174,-106.220512,0.002281,0.000000
128.430008,-0.027550,-106.220512,-0.001863,0.000123,0.003122,-0.122547,-0.006243,0.031220,-106.220512,0.001752,0.000000
128.750000,-0.013031,-106.264992,-0.001906,0.000086,0.002177,-0.057965,-0.002953,0.021767,-106.264992,0.001214,0.000000
129.070007,-0.033142,-106.264992,-0.001923,0.000067,0.001691,-0.147423,-0.007510,0.016911,-106.264992,0.000685,0.000000
129.389999,-0.046913,-106.309471,-0.001957,0.000042,0.001058,-0.208680,-0.010631,0.010580,-106.309471,0.000147,0.000000
129.710007,-0.061813,-106.353951,-0.001970,0.000019,0.000477,-0.274960,-0.014007,0.004770,-106.353951,-0.000382,0.000000
130.029999,-0.066650,-106.398437,-0.001992,0.000006,0.000156,-0.296476,-0.015103,0.001561,-106.398437,-0.000919,0.000000
130.100006,-0.025322,-106.398437,-0.001988,0.000003,0.000078,-0.112638,-0.005738,0.000781,-106.398437,-0.000000,0.000000