File: Data/AD Peeled Punched/AD Peeled Punched with creep_80bar_2_09172024_170530.csv
Time (sec),S:Load (lbs),S:HL1 (DIM),S:LVDT (in),S:Position (in),Ch:Position (mm),Ch:Load (N),Ch:Stress (MPa),Ch:Strain (mm/mm),Ch:HL1 (DIM),Set Point (),Cycles ()
0.110000,-0.173157,-92.742783,-0.007217,-0.005472,-0.138990,-0.770240,-0.039238,-1.389903,-92.742783,-0.138695,0.000000
0.380000,-0.117294,-92.698303,-0.007205,-0.005457,-0.138617,-0.521751,-0.026579,-1.386173,-92.698303,-0.137898,0.000000
0.650000,-0.079315,-92.787262,-0.007209,-0.005303,-0.134697,-0.352812,-0.017973,-1.346975,-92.787262,-0.133405,0.000000
0.920000,-0.120277,-92.831741,-0.007028,-0.005126,-0.130197,-0.535021,-0.027255,-1.301966,-92.831741,-0.128896,0.000000
1.190000,-0.098305,-92.831741,-0.006838,-0.004950,-0.125722,-0.437281,-0.022276,-1.257217,-92.831741,-0.124404,0.000000
1.460000,-0.080063,-92.787262,-0.006644,-0.004773,-0.121238,-0.356137,-0.018143,-1.212382,-92.787262,-0.119894,0.000000
1.730000,-0.125114,-92.787262,-0.006467,-0.004597,-0.116755,-0.556537,-0.028351,-1.167546,-92.787262,-0.115402,0.000000
2.000000,-0.093842,-92.787262,-0.006295,-0.004421,-0.112297,-0.417428,-0.021265,-1.122971,-92.787262,-0.110909,0.000000
2.270000,-0.126236,-92.787262,-0.006096,-0.004240,-0.107683,-0.561526,-0.028605,-1.076834,-92.787262,-0.106400,0.000000
2.540000,-0.142250,-92.831741,-0.005915,-0.004070,-0.103382,-0.632760,-0.032234,-1.033820,-92.831741,-0.101908,0.000000
2.810000,-0.084526,-92.787262,-0.005739,-0.003882,-0.098604,-0.375991,-0.019154,-0.986036,-92.787262,-0.097415,0.000000
3.080000,-0.103889,-92.831741,-0.005558,-0.003706,-0.094137,-0.462123,-0.023542,-0.941374,-92.831741,-0.092906,0.000000
3.350000,-0.062561,-92.876228,-0.005381,-0.003532,-0.089714,-0.278285,-0.014177,-0.897145,-92.876228,-0.088414,0.000000
3.620000,-0.078941,-92.831741,-0.005200,-0.003357,-0.085274,-0.351149,-0.017888,-0.852743,-92.831741,-0.083921,0.000000
3.890000,-0.101288,-92.876228,-0.005010,-0.003185,-0.080903,-0.450551,-0.022952,-0.809035,-92.876228,-0.079412,0.000000
4.160000,-0.102402,-92.831741,-0.004838,-0.003001,-0.076220,-0.455506,-0.023205,-0.762205,-92.831741,-0.074920,0.000000
4.430000,-0.149696,-92.831741,-0.004652,-0.002823,-0.071711,-0.665883,-0.033922,-0.717109,-92.831741,-0.070427,0.000000
4.700000,-0.114693,-92.876228,-0.004471,-0.002647,-0.067236,-0.510179,-0.025990,-0.672360,-92.876228,-0.065918,0.000000
4.970000,-0.081924,-92.831741,-0.004294,-0.002471,-0.062770,-0.364418,-0.018564,-0.627698,-92.831741,-0.061426,0.000000
5.240000,-0.090485,-92.876228,-0.004109,-0.002289,-0.058130,-0.402496,-0.020504,-0.581301,-92.876228,-0.056933,0.000000
5.510000,-0.044685,-92.876228,-0.003932,-0.002115,-0.053725,-0.198770,-0.010126,-0.537246,-92.876228,-0.052424,0.000000
5.780000,-0.084900,-92.831741,-0.003747,-0.001938,-0.049224,-0.377654,-0.019239,-0.492237,-92.831741,-0.047932,0.000000
6.050000,-0.102776,-92.920708,-0.003587,-0.001770,-0.044948,-0.457169,-0.023289,-0.449483,-92.920708,-0.043439,0.000000
6.320000,-0.087883,-92.965187,-0.003385,-0.001580,-0.040127,-0.390923,-0.019915,-0.401265,-92.965187,-0.038930,0.000000
6.590000,-0.136658,-92.920708,-0.003199,-0.001408,-0.035764,-0.607884,-0.030967,-0.357644,-92.920708,-0.034438,0.000000
6.860000,-0.090485,-92.965187,-0.003018,-0.001229,-0.031211,-0.402496,-0.020504,-0.312115,-92.965187,-0.029945,0.000000
7.130000,-0.084900,-92.876228,-0.002833,-0.001053,-0.026754,-0.377654,-0.019239,-0.267539,-92.876228,-0.025436,0.000000
7.400001,-0.061440,-92.965187,-0.002652,-0.000874,-0.022201,-0.273297,-0.013922,-0.222010,-92.965187,-0.020943,0.000000
7.670001,-0.034256,-93.009666,-0.002479,-0.000700,-0.017769,-0.152378,-0.007763,-0.177695,-93.009666,-0.016451,0.000000
7.940001,-0.048035,-92.920708,-0.002289,-0.000524,-0.013312,-0.213669,-0.010885,-0.133119,-92.920708,-0.011942,0.000000
8.210000,-0.004845,-92.920708,-0.002104,-0.000346,-0.008776,-0.021550,-0.001098,-0.087763,-92.920708,-0.007449,0.000000
8.480000,0.056969,-92.965187,-0.001919,-0.000163,-0.004137,0.253409,0.012909,-0.041367,-92.965187,-0.002957,0.000000
8.750000,0.026810,-92.920708,-0.001863,-0.000000,-0.000000,0.119255,0.006075,-0.000000,-92.920708,0.000234,0.000000
9.020000,0.010796,-92.920708,-0.001863,-0.000000,-0.000000,0.048021,0.002446,-0.000000,-92.920708,0.000234,0.000000
9.290001,0.077827,-92.920708,-0.001863,-0.000000,-0.000000,0.346194,0.017636,-0.000000,-92.920708,0.000477,0.000000
9.560000,0.080063,-92.965187,-0.001863,0.000000,0.000009,0.356137,0.018143,0.000087,-92.965187,0.000928,0.000000
9.830001,0.060326,-93.054146,-0.001876,0.000000,0.000009,0.268342,0.013670,0.000087,-93.054146,0.001379,0.000000
10.100000,0.151924,-92.965187,-0.001854,0.000030,0.000754,0.675792,0.034427,0.007545,-92.965187,0.001830,0.000000
10.370001,0.173897,-92.965187,-0.001841,0.000050,0.001266,0.773532,0.039406,0.012661,-92.965187,0.002281,0.000000
10.640000,0.188049,-93.009666,-0.001824,0.000067,0.001691,0.836485,0.042613,0.016911,-93.009666,0.002723,0.000000
10.910001,0.220444,-93.054146,-0.001776,0.000083,0.002107,0.980583,0.049953,0.021074,-93.054146,0.003174,0.000000
11.180000,0.229012,-93.009666,-0.001772,0.000101,0.002567,1.018694,0.051895,0.025670,-93.009666,0.003625,0.000000
11.450001,0.299759,-93.009666,-0.001763,0.000121,0.003070,1.333394,0.067926,0.030700,-93.009666,0.004076,0.000000
11.720000,0.278160,-93.054146,-0.001750,0.000126,0.003191,1.237318,0.063032,0.031914,-93.054146,0.004527,0.000000
11.990001,0.433441,-93.054146,-0.001733,0.000157,0.003998,1.928043,0.098219,0.039979,-93.054146,0.004978,0.000000
12.260000,0.455040,-93.054146,-0.001720,0.000175,0.004440,2.024119,0.103114,0.044402,-93.054146,0.005429,0.000000
12.530001,0.484459,-92.920708,-0.001686,0.000188,0.004787,2.154981,0.109780,0.047871,-92.920708,0.005880,0.000000
12.800000,0.597656,-92.965187,-0.001673,0.000208,0.005281,2.658508,0.135431,0.052814,-92.965187,0.006331,0.000000
13.070001,0.596916,-93.054146,-0.001651,0.000224,0.005689,2.655216,0.135263,0.056890,-93.054146,0.006773,0.000000
13.340001,0.657982,-93.009666,-0.001643,0.000240,0.006088,2.926850,0.149101,0.060879,-93.009666,0.007224,0.000000
13.610001,0.695595,-93.098633,-0.001625,0.000250,0.006357,3.094160,0.157624,0.063568,-93.098633,0.007675,0.000000
13.880001,0.907097,-93.098633,-0.001604,0.000278,0.007059,4.034968,0.205551,0.070592,-93.098633,0.008126,0.000000
14.150001,1.045990,-93.054146,-0.001595,0.000296,0.007510,4.652796,0.237025,0.075102,-93.054146,0.008577,0.000000
14.420001,1.116371,-93.054146,-0.001582,0.000311,0.007892,4.965867,0.252973,0.078918,-93.054146,0.009028,0.000000
14.690001,1.117493,-93.098633,-0.001561,0.000320,0.008126,4.970856,0.253227,0.081259,-93.098633,0.009479,0.000000
14.960001,1.353943,-93.143112,-0.001522,0.000354,0.009002,6.022639,0.306808,0.090018,-93.143112,0.009930,0.000000
15.230000,1.450394,-93.098633,-0.001505,0.000370,0.009401,6.451674,0.328664,0.094007,-93.098633,0.010381,0.000000
15.500001,1.609390,-93.098633,-0.001509,0.000384,0.009748,7.158926,0.364693,0.097476,-93.098633,0.010832,0.000000
15.770000,1.809731,-93.143112,-0.001479,0.000399,0.010138,8.050083,0.410091,0.101379,-93.143112,0.011274,0.000000
16.040001,1.963150,-93.187592,-0.001479,0.000417,0.010597,8.732528,0.444856,0.105975,-93.187592,0.011725,0.000000
16.310001,2.196251,-93.187592,-0.001436,0.000440,0.011179,9.769412,0.497678,0.111785,-93.187592,0.012176,0.000000
16.580000,2.184334,-93.098633,-0.001423,0.000446,0.011335,9.716402,0.494977,0.113346,-93.098633,0.012627,0.000000
16.850000,2.546654,-93.054146,-0.001418,0.000472,0.011985,11.328082,0.577080,0.119851,-93.054146,0.013078,0.000000
17.120001,2.792419,-93.187592,-0.001397,0.000494,0.012540,12.421302,0.632771,0.125401,-93.187592,0.013529,0.000000
17.390001,2.981583,-93.232071,-0.001371,0.000508,0.012913,13.262742,0.675636,0.129130,-93.232071,0.013980,0.000000
17.660002,3.152130,-93.187592,-0.001358,0.000524,0.013321,14.021375,0.714283,0.133206,-93.187592,0.014431,0.000000
17.930000,3.671219,-93.143112,-0.001358,0.000547,0.013902,16.330397,0.831910,0.139016,-93.143112,0.014882,0.000000
18.200001,3.896873,-93.232071,-0.001350,0.000562,0.014275,17.334160,0.883044,0.142745,-93.232071,0.015324,0.000000
18.470001,4.210045,-93.143112,-0.001337,0.000581,0.014760,18.727215,0.954010,0.147602,-93.143112,0.015775,0.000000
18.740002,4.485596,-93.232071,-0.001298,0.000597,0.015176,19.952927,1.016451,0.151764,-93.232071,0.016226,0.000000
19.010000,4.788338,-93.232071,-0.001276,0.000616,0.015653,21.299589,1.085053,0.156534,-93.232071,0.016677,0.000000
19.280001,5.424721,-93.232071,-0.001281,0.000638,0.016217,24.130363,1.229259,0.162171,-93.232071,0.017128,0.000000
19.550001,5.450043,-93.187592,-0.001255,0.000647,0.016434,24.243000,1.234997,0.164339,-93.187592,0.017579,0.000000
19.820002,6.036903,-93.187592,-0.001237,0.000666,0.016911,26.853487,1.367982,0.169109,-93.187592,0.018030,0.000000
20.090000,6.031319,-93.232071,-0.001233,0.000673,0.017102,26.828646,1.366716,0.171017,-93.232071,0.018481,0.000000
20.360001,7.009537,-93.276558,-0.001216,0.000703,0.017865,31.179977,1.588384,0.178648,-93.276558,0.018932,0.000000
20.630001,7.253815,-93.187592,-0.001199,0.000718,0.018229,32.266579,1.643738,0.182291,-93.187592,0.019374,0.000000
20.900002,7.652626,-93.187592,-0.001190,0.000734,0.018645,34.040581,1.734110,0.186454,-93.187592,0.019825,0.000000
21.170000,8.128517,-93.187592,-0.001181,0.000751,0.019079,36.157452,1.841948,0.190790,-93.187592,0.020276,0.000000
21.440001,8.949974,-93.276558,-0.001151,0.000777,0.019747,39.811474,2.028093,0.197467,-93.276558,0.020727,0.000000
21.710001,9.378571,-93.276558,-0.001147,0.000792,0.020111,41.717964,2.125214,0.201110,-93.276558,0.021178,0.000000
21.980001,9.950165,-93.276558,-0.001125,0.000808,0.020527,44.260544,2.254740,0.205272,-93.276558,0.021629,0.000000
22.250002,10.454353,-93.232071,-0.001121,0.000824,0.020926,46.503284,2.368990,0.209262,-93.232071,0.022080,0.000000
22.520000,11.022224,-93.276558,-0.001104,0.000842,0.021394,49.029305,2.497672,0.213945,-93.276558,0.022531,0.000000
22.790001,11.664192,-93.232071,-0.001082,0.000863,0.021932,51.884918,2.643144,0.219321,-93.232071,0.022981,0.000000
23.060001,12.192589,-93.321037,-0.001086,0.000878,0.022314,54.235344,2.762880,0.223137,-93.321037,0.023432,0.000000
23.330002,13.094849,-93.276558,-0.001069,0.000898,0.022808,58.248795,2.967335,0.228080,-93.276558,0.023875,0.000000
23.600000,13.795280,-93.232071,-0.001052,0.000915,0.023242,61.364471,3.126055,0.232416,-93.232071,0.024326,0.000000
23.870001,14.370598,-93.232071,-0.001052,0.000932,0.023675,63.923611,3.256424,0.236753,-93.232071,0.024777,0.000000
24.140001,15.145874,-93.321037,-0.001035,0.000952,0.024187,67.372215,3.432104,0.241869,-93.321037,0.025228,0.000000
24.410002,15.730133,-93.321037,-0.001022,0.000968,0.024577,69.971123,3.564499,0.245772,-93.321037,0.025679,0.000000
24.680000,16.486046,-93.365517,-0.001018,0.000987,0.025063,73.333595,3.735791,0.250628,-93.365517,0.026130,0.000000
24.950001,17.036781,-93.321037,-0.000996,0.001000,0.025401,75.783386,3.860590,0.254010,-93.321037,0.026580,0.000000
25.220001,16.617119,-93.276558,-0.000987,0.001001,0.025427,73.916634,3.765493,0.254271,-93.276558,0.027031,0.000000
25.490002,18.889709,-93.365517,-0.000970,0.001040,0.026416,84.025627,4.280469,0.264157,-93.365517,0.027482,0.000000
25.760002,19.341026,-93.365517,-0.000949,0.001056,0.026832,86.033180,4.382740,0.268320,-93.365517,0.027925,0.000000
26.030001,19.811333,-93.409996,-0.000949,0.001069,0.027162,88.125206,4.489312,0.271615,-93.409996,0.028376,0.000000
26.300001,21.095268,-93.276558,-0.000923,0.001094,0.027777,93.836441,4.780256,0.277772,-93.276558,0.028827,0.000000
26.570002,21.162300,-93.321037,-0.000923,0.001102,0.028003,94.134613,4.795446,0.280027,-93.321037,0.029278,0.000000
26.840002,22.391129,-93.365517,-0.000910,0.001126,0.028592,99.600716,5.073902,0.285924,-93.365517,0.029728,0.000000
27.110001,22.769089,-93.454475,-0.000892,0.001139,0.028939,101.281967,5.159549,0.289393,-93.454475,0.030179,0.000000
27.380001,22.931442,-93.409996,-0.000888,0.001144,0.029061,102.004150,5.196339,0.290607,-93.409996,0.030630,0.000000
27.650002,25.182808,-93.365517,-0.000871,0.001178,0.029919,112.018723,5.706506,0.299193,-93.365517,0.031081,0.000000
27.920002,26.022133,-93.409996,-0.000867,0.001198,0.030422,115.752228,5.896699,0.304223,-93.409996,0.031532,0.000000
28.190001,26.889763,-93.365517,-0.000862,0.001217,0.030899,119.611641,6.093307,0.308993,-93.365517,0.031975,0.000000
28.460001,27.778984,-93.409996,-0.000832,0.001235,0.031359,123.567093,6.294808,0.313589,-93.409996,0.032426,0.000000
28.730001,28.304405,-93.409996,-0.000828,0.001250,0.031758,125.904282,6.413870,0.317578,-93.409996,0.032877,0.000000
29.000002,29.094208,-93.365517,-0.000811,0.001268,0.032209,129.417496,6.592842,0.322088,-93.365517,0.033327,0.000000
29.270000,29.853096,-93.454475,-0.000802,0.001279,0.032486,132.793198,6.764808,0.324863,-93.454475,0.033778,0.000000
29.540001,30.970963,-93.498962,-0.000789,0.001298,0.032963,137.765717,7.018120,0.329632,-93.498962,0.034229,0.000000
29.810001,32.348366,-93.365517,-0.000793,0.001324,0.033640,143.892715,7.330245,0.336397,-93.365517,0.034680,0.000000
30.080002,33.469955,-93.409996,-0.000763,0.001342,0.034091,148.881790,7.584400,0.340906,-93.409996,0.035131,0.000000
30.350002,34.236671,-93.409996,-0.000763,0.001359,0.034507,152.292328,7.758141,0.345069,-93.409996,0.035582,0.000000
30.620001,34.836189,-93.409996,-0.000742,0.001373,0.034862,154.959106,7.893993,0.348625,-93.409996,0.036033,0.000000
30.890001,35.967087,-93.409996,-0.000742,0.001386,0.035192,159.989594,8.150258,0.351920,-93.409996,0.035365,0.000000
31.160002,35.183983,-93.498962,-0.000746,0.001381,0.035088,156.506180,7.972805,0.350879,-93.498962,0.006193,0.000000
31.430002,34.767670,-93.454475,-0.000729,0.001380,0.035053,154.654312,7.878467,0.350533,-93.454475,156.999786,0.000000
31.700001,34.441849,-93.498962,-0.000716,0.001380,0.035053,153.205002,7.804635,0.350533,-93.498962,156.999786,0.000000
31.970001,36.204659,-93.454475,-0.000716,0.001351,0.034325,161.046371,8.204093,0.343248,-93.454475,156.999786,0.000000
32.240002,35.580559,-93.409996,-0.000703,0.001188,0.030179,158.270233,8.062670,0.301795,-93.409996,156.999786,0.000000
32.510002,35.283783,-93.498962,-0.000690,0.001189,0.030188,156.950104,7.995420,0.301881,-93.498962,156.999786,0.000000
32.780003,35.049561,-93.454475,-0.000698,0.001190,0.030231,155.908234,7.942344,0.302315,-93.454475,156.999786,0.000000
33.050003,34.863373,-93.498962,-0.000703,0.001249,0.031732,155.080032,7.900153,0.317318,-93.498962,156.999786,0.000000
33.320000,34.693573,-93.454475,-0.000698,0.001271,0.032287,154.324722,7.861676,0.322868,-93.454475,156.999786,0.000000
33.590000,34.627289,-93.498962,-0.000698,0.001381,0.035071,154.029877,7.846656,0.350706,-93.498962,156.999786,0.000000
33.860001,34.603828,-93.543442,-0.000707,0.001391,0.035339,153.925522,7.841340,0.353394,-93.543442,156.999786,0.000000
34.130001,35.061470,-93.543442,-0.000703,0.001400,0.035556,155.961212,7.945043,0.355563,-93.543442,156.999786,0.000000
34.400002,34.972473,-93.587921,-0.000703,0.001400,0.035556,155.565323,7.924876,0.355563,-93.587921,156.999786,0.000000
34.670002,34.868210,-93.498962,-0.000694,0.001400,0.035556,155.101547,7.901249,0.355563,-93.498962,156.999786,0.000000
34.940002,34.803047,-93.498962,-0.000690,0.001400,0.035556,154.811691,7.886483,0.355563,-93.498962,156.999786,0.000000
35.210003,34.699524,-93.543442,-0.000703,0.001400,0.035556,154.351196,7.863025,0.355563,-93.543442,156.999786,0.000000
35.480003,34.638084,-93.543442,-0.000694,0.001400,0.035556,154.077896,7.849102,0.355563,-93.543442,156.999786,0.000000
35.750000,34.538292,-93.543442,-0.000698,0.001400,0.035556,153.634003,7.826489,0.355563,-93.543442,156.999786,0.000000
36.020000,34.488396,-93.498962,-0.000707,0.001400,0.035556,153.412048,7.815182,0.355563,-93.498962,156.999786,0.000000
36.290001,34.423973,-93.498962,-0.000703,0.001400,0.035565,153.125473,7.800584,0.355649,-93.498962,156.999786,0.000000
36.560001,34.334602,-93.498962,-0.000703,0.001400,0.035565,152.727936,7.780332,0.355649,-93.498962,156.999786,0.000000
36.830002,34.297363,-93.587921,-0.000711,0.001401,0.035574,152.562286,7.771894,0.355736,-93.587921,156.999786,0.000000
37.100002,35.619286,-93.632401,-0.000677,0.001359,0.034524,158.442490,8.071445,0.345243,-93.632401,156.999786,0.000000
37.370003,35.558220,-93.587921,-0.000686,0.001359,0.034524,158.170868,8.057608,0.345243,-93.587921,156.999786,0.000000
37.640003,35.439056,-93.498962,-0.000686,0.001359,0.034524,157.640793,8.030605,0.345243,-93.498962,156.999786,0.000000
37.910004,35.367935,-93.543442,-0.000681,0.001359,0.034524,157.324432,8.014488,0.345243,-93.543442,156.999786,0.000000
38.180000,35.301651,-93.632401,-0.000694,0.001359,0.034524,157.029587,7.999469,0.345243,-93.632401,156.999786,0.000000
38.450001,35.224197,-93.721367,-0.000686,0.001359,0.034524,156.685059,7.981917,0.345243,-93.721367,156.999786,0.000000
38.720001,35.168716,-93.587921,-0.000686,0.001359,0.034524,156.438263,7.969345,0.345243,-93.587921,156.999786,0.000000
38.990002,35.048439,-93.587921,-0.000681,0.001360,0.034550,155.903244,7.942090,0.345503,-93.587921,156.999786,0.000000
39.260002,35.075249,-93.587921,-0.000690,0.001361,0.034559,156.022491,7.948165,0.345589,-93.587921,156.999786,0.000000
39.530003,35.026840,-93.676880,-0.000681,0.001366,0.034706,155.807159,7.937195,0.347064,-93.676880,156.999786,0.000000
39.800003,34.931885,-93.676880,-0.000681,0.001371,0.034819,155.384781,7.915678,0.348191,-93.676880,156.999786,0.000000
40.070004,34.868210,-93.632401,-0.000681,0.001371,0.034819,155.101547,7.901249,0.348191,-93.632401,156.999786,0.000000
40.340000,34.848106,-93.587921,-0.000686,0.001371,0.034819,155.012115,7.896694,0.348191,-93.587921,156.999786,0.000000
40.610001,34.823898,-93.632401,-0.000677,0.001382,0.035114,154.904434,7.891208,0.351140,-93.632401,156.999786,0.000000
40.880001,34.750542,-93.632401,-0.000690,0.001388,0.035244,154.578125,7.874586,0.352441,-93.632401,156.999786,0.000000
41.150002,34.699898,-93.632401,-0.000703,0.001391,0.035322,154.352859,7.863109,0.353221,-93.632401,156.999786,0.000000
41.420002,34.690590,-93.632401,-0.000664,0.001391,0.035339,154.311447,7.861000,0.353394,-93.632401,156.999786,0.000000
41.690002,34.695061,-93.632401,-0.000677,0.001402,0.035608,154.331345,7.862013,0.356083,-93.632401,156.999786,0.000000
41.960003,34.665268,-93.632401,-0.000686,0.001403,0.035643,154.198807,7.855262,0.356430,-93.632401,156.999786,0.000000
42.230003,34.627663,-93.676880,-0.000690,0.001403,0.035643,154.031540,7.846741,0.356430,-93.676880,156.999786,0.000000
42.500004,34.572174,-93.765846,-0.000673,0.001403,0.035643,153.784714,7.834167,0.356430,-93.765846,156.999786,0.000000
42.770000,34.655586,-93.721367,-0.000686,0.001409,0.035790,154.155746,7.853068,0.357904,-93.721367,156.999786,0.000000
43.040001,34.620209,-93.676880,-0.000694,0.001409,0.035790,153.998383,7.845052,0.357904,-93.676880,156.999786,0.000000
43.310001,34.613136,-93.676880,-0.000677,0.001409,0.035799,153.966919,7.843449,0.357991,-93.676880,156.999786,0.000000
43.580002,34.574409,-93.721367,-0.000690,0.001409,0.035799,153.794647,7.834673,0.357991,-93.721367,156.999786,0.000000
43.850002,34.558395,-93.721367,-0.000681,0.001410,0.035808,153.723419,7.831044,0.358077,-93.721367,156.999786,0.000000
44.120003,34.991470,-93.765846,-0.000664,0.001419,0.036051,155.649841,7.929180,0.360506,-93.765846,156.999786,0.000000
44.390003,34.999657,-93.721367,-0.000673,0.001417,0.035990,155.686249,7.931036,0.359899,-93.721367,156.999786,0.000000
44.660004,34.998543,-93.721367,-0.000681,0.001417,0.035990,155.681290,7.930783,0.359899,-93.721367,156.999786,0.000000
44.930000,34.985138,-93.765846,-0.000668,0.001417,0.035990,155.621658,7.927745,0.359899,-93.765846,156.999786,0.000000
45.200001,34.933006,-93.765846,-0.000694,0.001417,0.035990,155.389771,7.915932,0.359899,-93.765846,156.999786,0.000000
45.470001,34.904335,-93.765846,-0.000677,0.001417,0.035990,155.262238,7.909435,0.359899,-93.765846,156.999786,0.000000
45.740002,34.892044,-93.765846,-0.000677,0.001417,0.035990,155.207565,7.906650,0.359899,-93.765846,156.999786,0.000000
46.010002,34.865234,-93.721367,-0.000677,0.001417,0.035990,155.088303,7.900575,0.359899,-93.721367,156.999786,0.000000
46.280003,34.863747,-93.721367,-0.000677,0.001417,0.035990,155.081696,7.900238,0.359899,-93.721367,156.999786,0.000000
46.550003,34.844383,-93.810326,-0.000690,0.001417,0.035990,154.995560,7.895850,0.359899,-93.810326,156.999786,0.000000
46.820004,34.826508,-93.810326,-0.000681,0.001417,0.035990,154.916046,7.891799,0.359899,-93.810326,156.999786,0.000000
47.090004,34.798576,-93.765846,-0.000681,0.001417,0.035990,154.791794,7.885470,0.359899,-93.765846,156.999786,0.000000
47.360001,34.759109,-93.765846,-0.000677,0.001417,0.035990,154.616241,7.876527,0.359899,-93.765846,156.999786,0.000000
47.630001,34.722984,-93.765846,-0.000677,0.001417,0.035990,154.455551,7.868340,0.359899,-93.765846,156.999786,0.000000
47.900002,34.718887,-93.810326,-0.000690,0.001417,0.035990,154.437317,7.867412,0.359899,-93.810326,156.999786,0.000000
48.170002,34.686867,-93.765846,-0.000673,0.001417,0.035990,154.294891,7.860156,0.359899,-93.765846,156.999786,0.000000
48.440002,34.674576,-93.765846,-0.000686,0.001417,0.035990,154.240219,7.857371,0.359899,-93.765846,156.999786,0.000000
48.710003,34.665642,-93.765846,-0.000677,0.001417,0.035990,154.200470,7.855347,0.359899,-93.765846,156.999786,0.000000
48.980003,34.647766,-93.810326,-0.000686,0.001417,0.035990,154.120956,7.851296,0.359899,-93.810326,156.999786,0.000000
49.250004,34.637344,-93.854805,-0.000686,0.001417,0.035990,154.074600,7.848934,0.359899,-93.854805,156.999786,0.000000
49.520000,34.605690,-93.854805,-0.000686,0.001417,0.035990,153.933792,7.841762,0.359899,-93.854805,156.999786,0.000000
49.790001,34.578880,-93.854805,-0.000677,0.001417,0.035990,153.814545,7.835686,0.359899,-93.854805,156.999786,0.000000
50.060001,34.531960,-93.810326,-0.000686,0.001417,0.035990,153.605835,7.825054,0.359899,-93.810326,156.999786,0.000000
50.330002,34.525627,-93.854805,-0.000681,0.001417,0.035990,153.577667,7.823619,0.359899,-93.854805,156.999786,0.000000
50.600002,34.512222,-93.854805,-0.000681,0.001417,0.035990,153.518036,7.820581,0.359899,-93.854805,156.999786,0.000000
50.870003,34.515572,-93.854805,-0.000664,0.001417,0.035990,153.532928,7.821340,0.359899,-93.854805,156.999786,0.000000
51.140003,34.481316,-93.854805,-0.000677,0.001417,0.035990,153.380554,7.813578,0.359899,-93.854805,156.999786,0.000000
51.410004,34.459717,-93.943771,-0.000686,0.001417,0.035999,153.284470,7.808683,0.359985,-93.943771,156.999786,0.000000
51.680004,34.438866,-93.810326,-0.000681,0.001417,0.035999,153.191727,7.803958,0.359985,-93.810326,156.999786,0.000000
51.950001,34.416527,-93.899284,-0.000668,0.001417,0.035999,153.092361,7.798896,0.359985,-93.899284,156.999786,0.000000
52.220001,34.402748,-93.988251,-0.000677,0.001417,0.035999,153.031067,7.795774,0.359985,-93.988251,156.999786,0.000000
52.490002,34.382637,-93.943771,-0.000673,0.001417,0.035999,152.941605,7.791217,0.359985,-93.943771,156.999786,0.000000
52.760002,34.359924,-93.899284,-0.000677,0.001417,0.035999,152.840576,7.786070,0.359985,-93.899284,156.999786,0.000000
53.030003,34.331253,-93.854805,-0.000686,0.001417,0.035999,152.713043,7.779573,0.359985,-93.854805,156.999786,0.000000
53.300003,34.319710,-93.943771,-0.000681,0.001417,0.035999,152.661697,7.776958,0.359985,-93.943771,156.999786,0.000000
53.570004,34.299973,-93.943771,-0.000690,0.001417,0.035999,152.573898,7.772485,0.359985,-93.943771,156.999786,0.000000
53.840004,34.301834,-93.899284,-0.000668,0.001417,0.035999,152.582184,7.772907,0.359985,-93.899284,156.999786,0.000000
54.110004,34.288803,-93.988251,-0.000681,0.001417,0.035999,152.524216,7.769954,0.359985,-93.988251,156.999786,0.000000
54.380001,34.273537,-93.943771,-0.000681,0.001417,0.035999,152.456299,7.766494,0.359985,-93.943771,156.999786,0.000000
54.650002,34.256035,-93.943771,-0.000673,0.001417,0.035999,152.378448,7.762528,0.359985,-93.943771,156.999786,0.000000
54.920002,34.226990,-94.032730,-0.000681,0.001417,0.035999,152.249252,7.755947,0.359985,-94.032730,156.999786,0.000000
55.190002,34.214699,-93.988251,-0.000681,0.001417,0.035999,152.194580,7.753162,0.359985,-93.988251,156.999786,0.000000
55.460003,35.882179,-93.943771,-0.000673,0.001339,0.034013,159.611908,8.131019,0.340126,-93.943771,156.999786,0.000000
55.730003,35.745522,-93.943771,-0.000660,0.001249,0.031723,159.004028,8.100051,0.317231,-93.943771,156.999786,0.000000
56.000004,35.722809,-94.032730,-0.000673,0.001238,0.031446,158.902985,8.094904,0.314456,-94.032730,156.999786,0.000000
56.270004,35.677376,-94.032730,-0.000664,0.001238,0.031446,158.700897,8.084609,0.314456,-94.032730,156.999786,0.000000
56.540001,35.643494,-94.032730,-0.000664,0.001238,0.031446,158.550171,8.076931,0.314456,-94.032730,156.999786,0.000000
56.810001,35.623756,-93.943771,-0.000673,0.001238,0.031446,158.462387,8.072459,0.314456,-93.943771,156.999786,0.000000
57.080002,35.608490,-94.032730,-0.000664,0.001238,0.031446,158.394470,8.068999,0.314456,-94.032730,156.999786,0.000000
57.350002,35.597321,-93.988251,-0.000664,0.001238,0.031446,158.344788,8.066468,0.314456,-93.988251,156.999786,0.000000
57.620003,35.607742,-93.988251,-0.000651,0.001238,0.031446,158.391144,8.068830,0.314456,-93.988251,156.999786,0.000000
57.890003,35.593224,-94.032730,-0.000660,0.001238,0.031446,158.326569,8.065539,0.314456,-94.032730,156.999786,0.000000
58.160004,35.539597,-93.988251,-0.000668,0.001238,0.031446,158.088028,8.053388,0.314456,-93.988251,156.999786,0.000000
58.430004,35.551514,-94.032730,-0.000660,0.001238,0.031446,158.141037,8.056088,0.314456,-94.032730,156.999786,0.000000
58.700005,35.497894,-94.032730,-0.000655,0.001238,0.031454,157.902527,8.043938,0.314543,-94.032730,156.999786,0.000000
58.970001,35.485977,-94.121689,-0.000655,0.001238,0.031454,157.849503,8.041237,0.314543,-94.121689,156.999786,0.000000
59.240002,35.417831,-94.077209,-0.000660,0.001239,0.031463,157.546387,8.025795,0.314629,-94.077209,156.999786,0.000000
59.510002,35.450974,-94.032730,-0.000664,0.001239,0.031472,157.693802,8.033305,0.314716,-94.032730,156.999786,0.000000
59.780003,35.434959,-94.032730,-0.000651,0.001239,0.031472,157.622574,8.029676,0.314716,-94.032730,156.999786,0.000000
60.050003,35.420815,-94.077209,-0.000655,0.001239,0.031472,157.559647,8.026471,0.314716,-94.077209,156.999786,0.000000
60.320004,35.403313,-94.077209,-0.000664,0.001239,0.031472,157.481796,8.022505,0.314716,-94.077209,156.999786,0.000000
60.590004,35.384689,-94.077209,-0.000655,0.001239,0.031472,157.398956,8.018285,0.314716,-94.077209,156.999786,0.000000
60.860004,35.391769,-94.077209,-0.000655,0.001239,0.031472,157.430450,8.019890,0.314716,-94.077209,156.999786,0.000000
61.130001,35.357140,-94.032730,-0.000668,0.001239,0.031472,157.276413,8.012042,0.314716,-94.032730,156.999786,0.000000
61.400002,35.341499,-94.121689,-0.000660,0.001239,0.031472,157.206833,8.008498,0.314716,-94.121689,156.999786,0.000000
61.670002,35.337402,-94.166176,-0.000664,0.001239,0.031472,157.188614,8.007570,0.314716,-94.166176,156.999786,0.000000
61.940002,35.314690,-94.121689,-0.000655,0.001239,0.031472,157.087585,8.002423,0.314716,-94.121689,156.999786,0.000000
62.210003,35.286011,-94.121689,-0.000664,0.001239,0.031472,156.960022,7.995924,0.314716,-94.121689,156.999786,0.000000
62.480003,35.276703,-94.121689,-0.000655,0.001239,0.031472,156.918610,7.993815,0.314716,-94.121689,156.999786,0.000000
62.750004,35.271118,-94.121689,-0.000664,0.001239,0.031472,156.893768,7.992549,0.314716,-94.121689,156.999786,0.000000
63.020004,35.248032,-94.121689,-0.000655,0.001239,0.031472,156.791077,7.987318,0.314716,-94.121689,156.999786,0.000000
63.290005,35.235001,-94.121689,-0.000655,0.001239,0.031472,156.733109,7.984365,0.314716,-94.121689,156.999786,0.000000
63.560001,35.229782,-94.121689,-0.000647,0.001239,0.031472,156.709900,7.983183,0.314716,-94.121689,156.999786,0.000000
63.830002,35.210419,-94.121689,-0.000651,0.001239,0.031472,156.623764,7.978795,0.314716,-94.121689,156.999786,0.000000
64.100006,35.185104,-94.121689,-0.000668,0.001239,0.031472,156.511154,7.973059,0.314716,-94.121689,156.999786,0.000000
64.370003,35.180634,-94.166176,-0.000668,0.001239,0.031472,156.491272,7.972045,0.314716,-94.166176,156.999786,0.000000
64.639999,35.170952,-94.166176,-0.000664,0.001239,0.031472,156.448212,7.969851,0.314716,-94.166176,156.999786,0.000000
64.910004,35.150841,-94.166176,-0.000647,0.001239,0.031472,156.358749,7.965294,0.314716,-94.166176,156.999786,0.000000
65.180000,35.076370,-94.210655,-0.000660,0.001240,0.031489,156.027481,7.948419,0.314890,-94.210655,156.999786,0.000000
65.450005,35.127754,-94.255135,-0.000677,0.001240,0.031489,156.256058,7.960063,0.314890,-94.255135,156.999786,0.000000
65.720001,35.040245,-94.166176,-0.000655,0.001240,0.031506,155.866791,7.940233,0.315063,-94.166176,156.999786,0.000000
65.990005,35.113235,-94.166176,-0.000660,0.001241,0.031524,156.191467,7.956773,0.315237,-94.166176,156.999786,0.000000
66.260002,35.065567,-94.166176,-0.000655,0.001241,0.031524,155.979431,7.945971,0.315237,-94.166176,156.999786,0.000000
66.530006,35.062965,-94.166176,-0.000664,0.001241,0.031532,155.967865,7.945382,0.315323,-94.166176,156.999786,0.000000
66.800003,35.095360,-94.255135,-0.000668,0.001242,0.031550,156.111954,7.952722,0.315497,-94.255135,156.999786,0.000000
67.070000,35.032425,-94.255135,-0.000668,0.001242,0.031550,155.832016,7.938461,0.315497,-94.255135,156.999786,0.000000
67.340004,34.989235,-94.255135,-0.000655,0.001243,0.031576,155.639893,7.928674,0.315757,-94.255135,156.999786,0.000000
67.610001,35.041740,-94.210655,-0.000660,0.001243,0.031576,155.873444,7.940572,0.315757,-94.210655,156.999786,0.000000
67.880005,34.995934,-94.166176,-0.000647,0.001243,0.031576,155.669693,7.930192,0.315757,-94.166176,156.999786,0.000000
68.150002,34.996681,-94.210655,-0.000655,0.001250,0.031749,155.673019,7.930361,0.317491,-94.210655,156.999786,0.000000
68.420006,34.992210,-94.210655,-0.000664,0.001251,0.031766,155.653122,7.929348,0.317665,-94.210655,156.999786,0.000000
68.690002,34.947899,-94.255135,-0.000660,0.001252,0.031801,155.456024,7.919307,0.318012,-94.255135,156.999786,0.000000
68.960007,34.952370,-94.255135,-0.000651,0.001260,0.031992,155.475906,7.920320,0.319920,-94.255135,156.999786,0.000000
69.230003,34.933380,-94.255135,-0.000664,0.001260,0.031992,155.391434,7.916017,0.319920,-94.255135,156.999786,0.000000
69.500000,34.928162,-94.255135,-0.000651,0.001260,0.031992,155.368225,7.914834,0.319920,-94.255135,156.999786,0.000000
69.770004,34.926674,-94.210655,-0.000655,0.001268,0.032200,155.361603,7.914497,0.322001,-94.210655,156.999786,0.000000
70.040001,34.897255,-94.299614,-0.000660,0.001268,0.032200,155.230743,7.907831,0.322001,-94.299614,156.999786,0.000000
70.310005,34.877151,-94.255135,-0.000660,0.001268,0.032200,155.141312,7.903275,0.322001,-94.255135,156.999786,0.000000
70.580002,34.869331,-94.210655,-0.000655,0.001268,0.032200,155.106537,7.901504,0.322001,-94.210655,156.999786,0.000000
70.850006,34.867096,-94.299614,-0.000660,0.001268,0.032200,155.096588,7.900997,0.322001,-94.299614,156.999786,0.000000
71.120003,34.872307,-94.255135,-0.000655,0.001268,0.032200,155.119766,7.902177,0.322001,-94.255135,156.999786,0.000000
71.390007,34.861885,-94.299614,-0.000655,0.001268,0.032200,155.073410,7.899816,0.322001,-94.299614,156.999786,0.000000
71.660004,34.852203,-94.299614,-0.000651,0.001268,0.032209,155.030350,7.897623,0.322088,-94.299614,156.999786,0.000000
71.930000,34.845497,-94.255135,-0.000651,0.001270,0.032252,155.000519,7.896103,0.322521,-94.255135,156.999786,0.000000
72.200005,34.828369,-94.299614,-0.000668,0.001270,0.032252,154.924316,7.892221,0.322521,-94.299614,156.999786,0.000000
72.470001,34.820175,-94.299614,-0.000664,0.001271,0.032295,154.887878,7.890365,0.322955,-94.299614,156.999786,0.000000
72.740005,34.797089,-94.344101,-0.000664,0.001271,0.032295,154.785187,7.885133,0.322955,-94.344101,156.999786,0.000000
73.010002,34.784798,-94.299614,-0.000660,0.001271,0.032295,154.730515,7.882348,0.322955,-94.299614,156.999786,0.000000
73.280006,34.777725,-94.299614,-0.000668,0.001271,0.032295,154.699051,7.880745,0.322955,-94.299614,156.999786,0.000000
73.550003,34.757614,-94.344101,-0.000673,0.001271,0.032295,154.609589,7.876188,0.322955,-94.344101,156.999786,0.000000
73.820000,34.754265,-94.344101,-0.000664,0.001359,0.034516,154.594696,7.875429,0.345156,-94.344101,156.999786,0.000000
74.090004,34.743469,-94.388580,-0.000655,0.001403,0.035643,154.546677,7.872983,0.356430,-94.388580,156.999786,0.000000
74.360001,34.738625,-94.344101,-0.000647,0.001403,0.035643,154.525116,7.871885,0.356430,-94.344101,156.999786,0.000000
74.630005,34.723732,-94.344101,-0.000651,0.001403,0.035643,154.458878,7.868510,0.356430,-94.344101,156.999786,0.000000
74.900002,34.717773,-94.344101,-0.000655,0.001403,0.035643,154.432373,7.867160,0.356430,-94.344101,156.999786,0.000000
75.170006,34.706230,-94.388580,-0.000664,0.001403,0.035643,154.381027,7.864544,0.356430,-94.388580,156.999786,0.000000
75.440002,34.691704,-94.344101,-0.000655,0.001403,0.035643,154.316406,7.861252,0.356430,-94.344101,156.999786,0.000000
75.710007,34.694687,-94.388580,-0.000668,0.001403,0.035643,154.329681,7.861928,0.356430,-94.388580,156.999786,0.000000
75.980003,34.682770,-94.344101,-0.000660,0.001403,0.035643,154.276672,7.859228,0.356430,-94.344101,156.999786,0.000000
76.250000,34.683144,-94.388580,-0.000655,0.001403,0.035643,154.278336,7.859313,0.356430,-94.388580,156.999786,0.000000
76.520004,34.672714,-94.433060,-0.000673,0.001403,0.035643,154.231934,7.856949,0.356430,-94.433060,156.999786,0.000000
76.790001,34.677559,-94.433060,-0.000651,0.001403,0.035643,154.253479,7.858047,0.356430,-94.433060,156.999786,0.000000
77.060005,34.667877,-94.433060,-0.000660,0.001403,0.035643,154.210419,7.855853,0.356430,-94.433060,156.999786,0.000000
77.330002,34.663033,-94.388580,-0.000660,0.001403,0.035643,154.188873,7.854755,0.356430,-94.388580,156.999786,0.000000
77.600006,34.672714,-94.388580,-0.000673,0.001410,0.035816,154.231934,7.856949,0.358164,-94.388580,156.999786,0.000000
77.870003,34.710701,-94.477539,-0.000668,0.001422,0.036111,154.400909,7.865557,0.361113,-94.477539,156.999786,0.000000
78.140007,34.703621,-94.477539,-0.000655,0.001422,0.036111,154.369415,7.863953,0.361113,-94.477539,156.999786,0.000000
78.410004,34.692078,-94.433060,-0.000660,0.001422,0.036111,154.318069,7.861337,0.361113,-94.433060,156.999786,0.000000
78.680000,34.672714,-94.433060,-0.000664,0.001422,0.036111,154.231934,7.856949,0.361113,-94.433060,156.999786,0.000000
78.950005,34.706230,-94.388580,-0.000668,0.001425,0.036198,154.381027,7.864544,0.361980,-94.388580,156.999786,0.000000
79.220001,34.702507,-94.522018,-0.000677,0.001425,0.036198,154.364456,7.863700,0.361980,-94.522018,156.999786,0.000000
79.490005,34.701019,-94.522018,-0.000651,0.001425,0.036198,154.357849,7.863363,0.361980,-94.522018,156.999786,0.000000
79.760002,34.685379,-94.433060,-0.000651,0.001425,0.036198,154.288269,7.859819,0.361980,-94.433060,156.999786,0.000000
80.030006,34.677559,-94.522018,-0.000664,0.001425,0.036198,154.253479,7.858047,0.361980,-94.522018,156.999786,0.000000
80.300003,34.670113,-94.522018,-0.000668,0.001425,0.036198,154.220367,7.856359,0.361980,-94.522018,156.999786,0.000000
80.570007,34.698410,-94.477539,-0.000655,0.001428,0.036259,154.346237,7.862772,0.362587,-94.477539,156.999786,0.000000
80.840004,34.687241,-94.477539,-0.000655,0.001428,0.036259,154.296555,7.860241,0.362587,-94.477539,156.999786,0.000000
81.110001,34.682770,-94.522018,-0.000647,0.001428,0.036259,154.276672,7.859228,0.362587,-94.522018,156.999786,0.000000
81.380005,34.678299,-94.477539,-0.000655,0.001428,0.036259,154.256775,7.858215,0.362587,-94.477539,156.999786,0.000000
81.650002,34.677185,-94.522018,-0.000673,0.001428,0.036259,154.251816,7.857963,0.362587,-94.522018,156.999786,0.000000
81.920006,34.685005,-94.522018,-0.000660,0.001428,0.036259,154.286606,7.859735,0.362587,-94.522018,156.999786,0.000000
82.190002,34.670853,-94.566505,-0.000660,0.001428,0.036259,154.223648,7.856528,0.362587,-94.566505,156.999786,0.000000
82.460007,34.644043,-94.522018,-0.000651,0.001428,0.036259,154.104401,7.850452,0.362587,-94.522018,156.999786,0.000000
82.730003,34.634735,-94.522018,-0.000647,0.001428,0.036276,154.063004,7.848343,0.362761,-94.522018,156.999786,0.000000
83.000008,34.649628,-94.522018,-0.000664,0.001428,0.036276,154.129242,7.851718,0.362761,-94.522018,156.999786,0.000000
83.270004,34.635483,-94.566505,-0.000660,0.001429,0.036285,154.066315,7.848513,0.362847,-94.566505,156.999786,0.000000
83.540001,34.641068,-94.610985,-0.000655,0.001429,0.036285,154.091171,7.849778,0.362847,-94.610985,156.999786,0.000000
83.810005,34.621704,-94.566505,-0.000655,0.001429,0.036285,154.005035,7.845390,0.362847,-94.566505,156.999786,0.000000
84.080002,34.643295,-94.522018,-0.000647,0.001432,0.036363,154.101074,7.850283,0.363628,-94.522018,156.999786,0.000000
84.350006,34.690216,-94.522018,-0.000664,0.001432,0.036363,154.309784,7.860915,0.363628,-94.522018,156.999786,0.000000
84.620003,34.691704,-94.610985,-0.000655,0.001432,0.036363,154.316406,7.861252,0.363628,-94.610985,156.999786,0.000000
84.890007,34.696922,-94.610985,-0.000660,0.001432,0.036363,154.339615,7.862435,0.363628,-94.610985,156.999786,0.000000
85.160004,34.682396,-94.566505,-0.000673,0.001432,0.036363,154.275009,7.859143,0.363628,-94.566505,156.999786,0.000000
85.430000,34.682396,-94.566505,-0.000664,0.001432,0.036363,154.275009,7.859143,0.363628,-94.566505,156.999786,0.000000
85.700005,34.690216,-94.610985,-0.000655,0.001432,0.036363,154.309784,7.860915,0.363628,-94.610985,156.999786,0.000000
85.970001,34.687981,-94.610985,-0.000651,0.001432,0.036363,154.299850,7.860409,0.363628,-94.610985,156.999786,0.000000
86.240005,34.687981,-94.610985,-0.000660,0.001432,0.036363,154.299850,7.860409,0.363628,-94.610985,156.999786,0.000000
86.510002,34.690590,-94.655464,-0.000647,0.001432,0.036363,154.311447,7.861000,0.363628,-94.655464,156.999786,0.000000
86.780006,34.685753,-94.610985,-0.000647,0.001432,0.036363,154.289932,7.859904,0.363628,-94.610985,156.999786,0.000000
87.050003,34.683144,-94.655464,-0.000673,0.001432,0.036363,154.278336,7.859313,0.363628,-94.655464,156.999786,0.000000
87.320007,34.676437,-94.655464,-0.000664,0.001432,0.036363,154.248505,7.857793,0.363628,-94.655464,156.999786,0.000000
87.590004,34.660797,-94.699944,-0.000651,0.001432,0.036363,154.178925,7.854249,0.363628,-94.699944,156.999786,0.000000
87.860001,34.673088,-94.610985,-0.000655,0.001432,0.036363,154.233597,7.857034,0.363628,-94.610985,156.999786,0.000000
88.130005,34.671974,-94.655464,-0.000655,0.001432,0.036363,154.228638,7.856782,0.363628,-94.655464,156.999786,0.000000
88.400002,34.657074,-94.655464,-0.000668,0.001432,0.036363,154.162369,7.853405,0.363628,-94.655464,156.999786,0.000000
88.670006,34.648514,-94.699944,-0.000664,0.001432,0.036363,154.124283,7.851466,0.363628,-94.699944,156.999786,0.000000
88.940002,34.658936,-94.699944,-0.000660,0.001432,0.036363,154.170639,7.853827,0.363628,-94.699944,156.999786,0.000000
89.210007,34.640320,-94.655464,-0.000642,0.001432,0.036363,154.087845,7.849608,0.363628,-94.655464,156.999786,0.000000
89.480003,34.631012,-94.655464,-0.000647,0.001432,0.036363,154.046432,7.847499,0.363628,-94.655464,156.999786,0.000000
89.750008,34.630264,-94.655464,-0.000655,0.001432,0.036363,154.043106,7.847330,0.363628,-94.655464,156.999786,0.000000
90.020004,34.623566,-94.699944,-0.000655,0.001432,0.036363,154.013306,7.845812,0.363628,-94.699944,156.999786,0.000000
90.290001,34.614250,-94.744423,-0.000651,0.001432,0.036363,153.971878,7.843701,0.363628,-94.744423,156.999786,0.000000
90.560005,34.634735,-94.788910,-0.000651,0.001432,0.036363,154.063004,7.848343,0.363628,-94.788910,156.999786,0.000000
90.830002,34.612022,-94.610985,-0.000651,0.001432,0.036363,153.961960,7.843196,0.363628,-94.610985,156.999786,0.000000
91.100006,34.596756,-94.699944,-0.000655,0.001432,0.036363,153.894058,7.839737,0.363628,-94.699944,156.999786,0.000000
91.370003,34.586327,-94.744423,-0.000664,0.001432,0.036363,153.847672,7.837374,0.363628,-94.744423,156.999786,0.000000
91.640007,34.587074,-94.699944,-0.000660,0.001424,0.036181,153.850983,7.837543,0.361807,-94.699944,0.036337,0.000000
91.910004,34.537544,-94.744423,-0.000651,0.001421,0.036103,153.630676,7.826319,0.361026,-94.744423,0.035894,0.000000
92.180008,34.556908,-94.699944,-0.000651,0.001410,0.035816,153.716797,7.830707,0.358164,-94.699944,0.035444,0.000000
92.450005,34.543129,-94.655464,-0.000664,0.001394,0.035409,153.655518,7.827585,0.354088,-94.655464,0.034993,0.000000
92.720001,34.516319,-94.744423,-0.000642,0.001377,0.034984,153.536255,7.821510,0.349839,-94.744423,0.034542,0.000000
92.990005,34.501801,-94.833389,-0.000647,0.001368,0.034741,153.471680,7.818220,0.347411,-94.833389,0.034091,0.000000
93.260002,34.476105,-94.744423,-0.000647,0.001347,0.034212,153.357376,7.812397,0.342121,-94.744423,0.033640,0.000000
93.530006,34.473869,-94.699944,-0.000642,0.001326,0.033674,153.347427,7.811891,0.336744,-94.699944,0.033189,0.000000
93.800003,34.431419,-94.744423,-0.000660,0.001312,0.033319,153.158600,7.802271,0.333188,-94.744423,0.032738,0.000000
94.070007,34.458603,-94.788910,-0.000647,0.001293,0.032833,153.279526,7.808431,0.328332,-94.788910,0.032287,0.000000
94.340004,34.444450,-94.833389,-0.000642,0.001278,0.032460,153.216568,7.805224,0.324603,-94.833389,0.031845,0.000000
94.610008,34.412430,-94.833389,-0.000655,0.001260,0.032001,153.074127,7.797968,0.320006,-94.833389,0.031394,0.000000
94.880005,34.416527,-94.744423,-0.000634,0.001242,0.031550,153.092361,7.798896,0.315497,-94.744423,0.030943,0.000000
95.150002,34.372581,-94.744423,-0.000642,0.001231,0.031272,152.896881,7.788939,0.312722,-94.744423,0.030492,0.000000
95.420006,34.269440,-94.833389,-0.000651,0.001207,0.030665,152.438080,7.765566,0.306651,-94.833389,0.030041,0.000000
95.690002,33.944725,-94.788910,-0.000642,0.001190,0.030231,150.993683,7.691985,0.302315,-94.788910,0.029590,0.000000
95.960007,33.548149,-94.833389,-0.000638,0.001179,0.029937,149.229614,7.602119,0.299366,-94.833389,0.029139,0.000000
96.230003,32.823891,-94.788910,-0.000634,0.001162,0.029503,146.007965,7.438000,0.295030,-94.788910,0.028688,0.000000
96.500008,31.977859,-94.833389,-0.000655,0.001144,0.029069,142.244629,7.246287,0.290694,-94.833389,0.028237,0.000000
96.770004,31.075226,-94.877869,-0.000629,0.001127,0.028618,138.229507,7.041747,0.286184,-94.877869,0.027795,0.000000
97.040001,30.260101,-94.922348,-0.000634,0.001116,0.028341,134.603653,6.857037,0.283409,-94.922348,0.027344,0.000000
97.310005,29.327682,-94.877869,-0.000625,0.001102,0.027985,130.456055,6.645748,0.279854,-94.877869,0.026893,0.000000
97.580002,27.603600,-94.833389,-0.000621,0.001075,0.027309,122.786942,6.255065,0.273089,-94.833389,0.026442,0.000000
97.850006,26.378868,-94.833389,-0.000629,0.001061,0.026953,117.339066,5.977537,0.269534,-94.833389,0.025991,0.000000
98.120003,25.028267,-94.833389,-0.000621,0.001046,0.026572,111.331291,5.671486,0.265718,-94.833389,0.025540,0.000000
98.390007,23.534309,-94.877869,-0.000634,0.001028,0.026121,104.685837,5.332951,0.261208,-94.877869,0.025089,0.000000
98.660004,21.896988,-94.922348,-0.000625,0.001008,0.025592,97.402664,4.961928,0.255918,-94.922348,0.024638,0.000000
98.930008,20.317017,-94.966827,-0.000621,0.000992,0.025193,90.374603,4.603902,0.251929,-94.966827,0.024187,0.000000
99.200005,19.177925,-94.922348,-0.000617,0.000984,0.025002,85.307671,4.345780,0.250021,-94.922348,0.023736,0.000000
99.470001,16.468544,-94.922348,-0.000642,0.000955,0.024256,73.255745,3.731825,0.242563,-94.922348,0.023294,0.000000
99.740005,14.611519,-94.922348,-0.000642,0.000938,0.023823,64.995285,3.311017,0.238227,-94.922348,0.022843,0.000000
100.010002,13.113464,-94.966827,-0.000651,0.000925,0.023484,58.331604,2.971554,0.234845,-94.966827,0.022392,0.000000
100.280006,11.619881,-94.966827,-0.000638,0.000911,0.023146,51.687809,2.633103,0.231463,-94.966827,0.021941,0.000000
100.550003,9.586357,-94.922348,-0.000642,0.000890,0.022609,42.642246,2.172300,0.226086,-94.922348,0.021490,0.000000
100.820007,7.436279,-94.922348,-0.000655,0.000869,0.022080,33.078224,1.685085,0.220796,-94.922348,0.021039,0.000000
101.090004,6.208939,-94.966827,-0.000647,0.000858,0.021793,27.618738,1.406965,0.217934,-94.966827,0.020588,0.000000
101.360008,3.871559,-95.011314,-0.000664,0.000832,0.021143,17.221556,0.877308,0.211430,-95.011314,0.020137,0.000000
101.630005,2.954773,-94.966827,-0.000647,0.000825,0.020952,13.143487,0.669561,0.209522,-94.966827,0.019686,0.000000
101.900002,1.493210,-95.011314,-0.000664,0.000806,0.020475,6.642129,0.338366,0.204752,-95.011314,0.019244,0.000000
102.170006,-1.237022,-94.966827,-0.000664,0.000777,0.019729,-5.502551,-0.280313,0.197294,-94.966827,0.018793,0.000000
102.440002,-0.165703,-95.011314,-0.000677,0.000764,0.019417,-0.737083,-0.037549,0.194172,-95.011314,0.018342,0.000000
102.710007,-0.163475,-95.011314,-0.000711,0.000746,0.018940,-0.727173,-0.037044,0.189402,-95.011314,0.017891,0.000000
102.980003,-0.123627,-94.966827,-0.000724,0.000731,0.018567,-0.549919,-0.028014,0.185673,-94.966827,0.017440,0.000000
103.250008,-0.128471,-95.011314,-0.000759,0.000710,0.018038,-0.571469,-0.029112,0.180383,-95.011314,0.016989,0.000000
103.520004,-0.132195,-95.011314,-0.000811,0.000689,0.017492,-0.588031,-0.029956,0.174919,-95.011314,0.016538,0.000000
103.790009,-0.137779,-95.011314,-0.000832,0.000672,0.017076,-0.612873,-0.031221,0.170757,-95.011314,0.016087,0.000000
104.060005,-0.143738,-95.011314,-0.000854,0.000656,0.016668,-0.639378,-0.032571,0.166681,-95.011314,0.015636,0.000000
104.330002,-0.140755,-94.966827,-0.000871,0.000641,0.016286,-0.626108,-0.031895,0.162865,-94.966827,0.015194,0.000000
104.600006,-0.128845,-95.011314,-0.000897,0.000625,0.015879,-0.573132,-0.029197,0.158789,-95.011314,0.014743,0.000000
104.870003,-0.138893,-95.011314,-0.000901,0.000609,0.015463,-0.617827,-0.031474,0.154626,-95.011314,0.014292,0.000000
105.140007,-0.106873,-95.055794,-0.000927,0.000579,0.014708,-0.475393,-0.024218,0.147081,-95.055794,0.013841,0.000000
105.410004,-0.113571,-95.055794,-0.000957,0.000564,0.014335,-0.505190,-0.025736,0.143352,-95.055794,0.013390,0.000000
105.680008,-0.146713,-95.011314,-0.000966,0.000549,0.013936,-0.652613,-0.033246,0.139363,-95.011314,0.012939,0.000000
105.950005,-0.145226,-94.966827,-0.000983,0.000531,0.013477,-0.645995,-0.032909,0.134767,-94.966827,0.012488,0.000000
106.220009,-0.130707,-95.011314,-0.001000,0.000526,0.013373,-0.581413,-0.029619,0.133726,-95.011314,0.012037,0.000000
106.490005,-0.151558,-95.055794,-0.001022,0.000507,0.012887,-0.674163,-0.034344,0.128870,-95.055794,0.011586,0.000000
106.760002,-0.145599,-95.144753,-0.001043,0.000479,0.012167,-0.647658,-0.032993,0.121672,-95.144753,0.011135,0.000000
107.030006,-0.155655,-95.055794,-0.001039,0.000468,0.011898,-0.692388,-0.035272,0.118983,-95.055794,0.010693,0.000000
107.300003,-0.132935,-95.055794,-0.001082,0.000436,0.011074,-0.591322,-0.030123,0.110745,-95.055794,0.010242,0.000000
107.570007,-0.117294,-95.055794,-0.001086,0.000423,0.010754,-0.521751,-0.026579,0.107536,-95.055794,0.009791,0.000000
107.840004,-0.097565,-95.144753,-0.001121,0.000404,0.010259,-0.433989,-0.022108,0.102593,-95.144753,0.009340,0.000000
108.110008,-0.128471,-95.144753,-0.001147,0.000384,0.009765,-0.571469,-0.029112,0.097650,-95.144753,0.008889,0.000000
108.380005,-0.129585,-95.100273,-0.001138,0.000375,0.009522,-0.576424,-0.029364,0.095221,-95.100273,0.008438,0.000000
108.650002,-0.126610,-95.055794,-0.001168,0.000354,0.008984,-0.563189,-0.028690,0.089845,-95.055794,0.007987,0.000000
108.920006,-0.118042,-95.100273,-0.001181,0.000339,0.008612,-0.525077,-0.026749,0.086115,-95.100273,0.007536,0.000000
109.190002,-0.101288,-95.144753,-0.001203,0.000326,0.008291,-0.450551,-0.022952,0.082907,-95.144753,0.007085,0.000000
109.460007,-0.140755,-95.189232,-0.001216,0.000302,0.007675,-0.626108,-0.031895,0.076749,-95.189232,0.006643,0.000000
109.730003,-0.099426,-95.100273,-0.001237,0.000286,0.007276,-0.442270,-0.022530,0.072760,-95.100273,0.006192,0.000000
110.000008,-0.100914,-95.189232,-0.001250,0.000267,0.006773,-0.448888,-0.022867,0.067730,-95.189232,0.005741,0.000000
110.270004,-0.092346,-95.100273,-0.001281,0.000248,0.006287,-0.410776,-0.020926,0.062874,-95.100273,0.005290,0.000000
110.540009,-0.095703,-95.144753,-0.001302,0.000230,0.005836,-0.425709,-0.021687,0.058364,-95.144753,0.004839,0.000000
110.810005,-0.086761,-95.189232,-0.001306,0.000222,0.005628,-0.385934,-0.019660,0.056283,-95.189232,0.004388,0.000000
111.080002,-0.108360,-95.189232,-0.001324,0.000193,0.004891,-0.482011,-0.024555,0.048912,-95.189232,0.003937,0.000000
111.350006,-0.091232,-95.144753,-0.001345,0.000173,0.004406,-0.405822,-0.020674,0.044055,-95.144753,0.003486,0.000000
111.620003,-0.090118,-95.144753,-0.001367,0.000162,0.004111,-0.400867,-0.020421,0.041107,-95.144753,0.003035,0.000000
111.890007,-0.055115,-95.144753,-0.001375,0.000145,0.003694,-0.245163,-0.012489,0.036944,-95.144753,0.002593,0.000000
112.160004,-0.080063,-95.233719,-0.001406,0.000125,0.003165,-0.356137,-0.018143,0.031654,-95.233719,0.002142,0.000000
112.430008,-0.082664,-95.233719,-0.001406,0.000108,0.002749,-0.367710,-0.018732,0.027491,-95.233719,0.001691,0.000000
112.700005,-0.070381,-95.189232,-0.001431,0.000096,0.002446,-0.313071,-0.015949,0.024456,-95.189232,0.001240,0.000000
112.970009,-0.125862,-95.144753,-0.001457,0.000072,0.001839,-0.559863,-0.028521,0.018385,-95.144753,0.000789,0.000000
113.240005,-0.113945,-95.144753,-0.001479,0.000050,0.001275,-0.506853,-0.025820,0.012748,-95.144753,0.000338,0.000000
113.510002,-0.114693,-95.278198,-0.001487,0.000037,0.000945,-0.510179,-0.025990,0.009453,-95.278198,-0.000113,0.000000
113.780006,-0.097931,-95.189232,-0.001513,0.000020,0.000503,-0.435618,-0.022191,0.005030,-95.189232,-0.000564,0.000000
114.050003,-0.089371,-95.144753,-0.001522,0.000008,0.000208,-0.397541,-0.020252,0.002081,-95.144753,-0.001015,0.000000
114.200005,-0.090118,-95.233719,-0.001531,0.000002,0.000052,-0.400867,-0.020421,0.000520,-95.233719,-0.000035,0.000000