File: Data/AD Peeled Punched/AD Peeled Punched with creep_150bar_2_09172024_165630.csv
Time (sec),S:Load (lbs),S:HL1 (DIM),S:LVDT (in),S:Position (in),Ch:Position (mm),Ch:Load (N),Ch:Stress (MPa),Ch:Strain (mm/mm),Ch:HL1 (DIM),Set Point (),Cycles ()
0.110000,-0.085648,-79.265053,-0.007157,-0.002837,-0.072049,-0.380979,-0.019408,-0.720491,-79.265053,-0.072240,0.000000
0.410000,-0.105011,-79.265053,-0.007170,-0.002821,-0.071659,-0.467112,-0.023796,-0.716589,-79.265053,-0.070852,0.000000
0.710000,-0.059952,-79.309532,-0.007157,-0.002636,-0.066950,-0.266679,-0.013585,-0.669498,-79.309532,-0.065857,0.000000
1.010000,-0.051018,-79.265053,-0.006967,-0.002443,-0.062041,-0.226938,-0.011561,-0.620413,-79.265053,-0.060845,0.000000
1.310000,-0.079315,-79.265053,-0.006769,-0.002251,-0.057176,-0.352812,-0.017973,-0.571762,-79.265053,-0.055849,0.000000
1.610000,-0.049896,-79.309532,-0.006571,-0.002049,-0.052042,-0.221950,-0.011307,-0.520422,-79.309532,-0.050854,0.000000
1.910000,-0.085648,-79.309532,-0.006377,-0.001857,-0.047168,-0.380979,-0.019408,-0.471684,-79.309532,-0.045859,0.000000
2.210000,-0.076706,-79.354019,-0.006174,-0.001656,-0.042060,-0.341205,-0.017382,-0.420604,-79.354019,-0.040864,0.000000
2.510000,-0.148209,-79.309532,-0.005971,-0.001463,-0.037169,-0.659265,-0.033585,-0.371693,-79.309532,-0.035868,0.000000
2.810000,-0.066284,-79.309532,-0.005790,-0.001263,-0.032079,-0.294847,-0.015020,-0.320787,-79.309532,-0.030856,0.000000
3.110000,-0.078941,-79.220573,-0.005579,-0.001074,-0.027274,-0.351149,-0.017888,-0.272742,-79.220573,-0.025861,0.000000
3.410000,-0.027557,-79.309532,-0.005385,-0.000875,-0.022227,-0.122581,-0.006245,-0.222270,-79.309532,-0.020865,0.000000
3.710000,-0.057716,-79.354019,-0.005178,-0.000677,-0.017197,-0.256735,-0.013079,-0.171971,-79.354019,-0.015870,0.000000
4.010000,-0.082664,-79.309532,-0.004984,-0.000477,-0.012106,-0.367710,-0.018732,-0.121065,-79.309532,-0.010875,0.000000
4.310000,-0.082298,-79.354019,-0.004794,-0.000286,-0.007276,-0.366081,-0.018649,-0.072760,-79.354019,-0.005880,0.000000
4.610000,-0.129585,-79.354019,-0.004600,-0.000085,-0.002151,-0.576424,-0.029364,-0.021507,-79.354019,-0.000885,0.000000
4.910000,-0.036491,-79.398499,-0.004381,0.000110,0.002792,-0.162322,-0.008269,0.027925,-79.398499,0.004128,0.000000
5.210000,-0.073730,-79.354019,-0.004178,0.000306,0.007762,-0.327969,-0.016708,0.077617,-79.354019,0.009123,0.000000
5.510000,-0.027184,-79.442978,-0.003988,0.000505,0.012818,-0.120918,-0.006160,0.128176,-79.442978,0.014118,0.000000
5.810000,-0.054367,-79.398499,-0.003786,0.000700,0.017769,-0.241837,-0.012320,0.177695,-79.398499,0.019114,0.000000
6.110000,-0.077454,-79.398499,-0.003570,0.000899,0.022834,-0.344531,-0.017551,0.228341,-79.398499,0.024109,0.000000
6.410000,-0.095703,-79.398499,-0.003376,0.001088,0.027647,-0.425709,-0.021687,0.276472,-79.398499,0.029104,0.000000
6.710001,-0.096817,-79.442978,-0.003178,0.001289,0.032738,-0.430664,-0.021939,0.327378,-79.442978,0.034117,0.000000
7.010000,-0.051018,-79.442978,-0.002979,0.001490,0.037846,-0.226938,-0.011561,0.378457,-79.442978,0.039112,0.000000
7.310000,-0.047661,-79.398499,-0.002764,0.001684,0.042763,-0.212006,-0.010800,0.427629,-79.398499,0.044107,0.000000
7.610000,-0.033890,-79.354019,-0.002574,0.001880,0.047749,-0.150749,-0.007680,0.477494,-79.354019,0.049102,0.000000
7.910000,-0.040215,-79.487457,-0.002371,0.002081,0.052849,-0.178883,-0.009113,0.528487,-79.487457,0.054098,0.000000
8.210000,-0.025696,-79.442978,-0.002177,0.002275,0.057783,-0.114301,-0.005823,0.577832,-79.442978,0.059093,0.000000
8.510000,-0.038353,-79.442978,-0.001962,0.002470,0.062744,-0.170603,-0.008691,0.627438,-79.442978,0.064088,0.000000
8.810000,0.150810,-79.487457,-0.001789,-0.000000,-0.000000,0.670837,0.034174,-0.000000,-79.487457,0.000191,0.000000
9.110001,0.116554,-79.442978,-0.001781,-0.000000,-0.000009,0.518459,0.026412,-0.000087,-79.442978,0.000191,0.000000
9.410001,0.118042,-79.487457,-0.001781,-0.000000,-0.000009,0.525077,0.026749,-0.000087,-79.487457,0.000425,0.000000
9.710000,0.110970,-79.531944,-0.001789,-0.000000,-0.000000,0.493617,0.025146,-0.000000,-79.531944,0.000928,0.000000
10.010000,0.097565,-79.487457,-0.001794,0.000013,0.000330,0.433989,0.022108,0.003295,-79.487457,0.001422,0.000000
10.310000,0.160118,-79.442978,-0.001763,0.000037,0.000928,0.712241,0.036283,0.009279,-79.442978,0.001925,0.000000
10.610001,0.170174,-79.531944,-0.001755,0.000047,0.001205,0.756970,0.038562,0.012054,-79.531944,0.002428,0.000000
10.910001,0.202568,-79.487457,-0.001733,0.000072,0.001830,0.901068,0.045903,0.018298,-79.487457,0.002923,0.000000
11.210001,0.221191,-79.487457,-0.001699,0.000095,0.002420,0.983909,0.050123,0.024196,-79.487457,0.003426,0.000000
11.510000,0.258797,-79.576424,-0.001694,0.000107,0.002714,1.151185,0.058644,0.027144,-79.576424,0.003929,0.000000
11.810000,0.313538,-79.531944,-0.001699,0.000126,0.003209,1.394685,0.071049,0.032087,-79.531944,0.004423,0.000000
12.110001,0.481850,-79.576424,-0.001630,0.000154,0.003911,2.143374,0.109189,0.039112,-79.576424,0.004926,0.000000
12.410001,0.541801,-79.531944,-0.001630,0.000176,0.004475,2.410053,0.122774,0.044749,-79.531944,0.005429,0.000000
12.710001,0.532120,-79.531944,-0.001617,0.000187,0.004752,2.366987,0.120580,0.047524,-79.531944,0.005923,0.000000
13.010000,0.671387,-79.531944,-0.001582,0.000219,0.005568,2.986477,0.152138,0.055676,-79.531944,0.006426,0.000000
13.310000,0.745491,-79.531944,-0.001578,0.000233,0.005914,3.316110,0.168931,0.059145,-79.531944,0.006929,0.000000
13.610001,0.835602,-79.620903,-0.001544,0.000252,0.006391,3.716943,0.189350,0.063915,-79.620903,0.007423,0.000000
13.910001,0.989769,-79.531944,-0.001535,0.000269,0.006834,4.402712,0.224285,0.068337,-79.531944,0.007926,0.000000
14.210001,1.138718,-79.576424,-0.001522,0.000289,0.007337,5.065269,0.258037,0.073367,-79.576424,0.008429,0.000000
14.510000,1.277611,-79.531944,-0.001487,0.000310,0.007883,5.683096,0.289511,0.078831,-79.531944,0.008924,0.000000
14.810000,1.464539,-79.576424,-0.001466,0.000330,0.008377,6.514593,0.331869,0.083774,-79.576424,0.009427,0.000000
15.110001,1.402725,-79.620903,-0.001457,0.000338,0.008586,6.239634,0.317862,0.085855,-79.620903,0.009921,0.000000
15.410001,1.706581,-79.576424,-0.001423,0.000370,0.009401,7.591252,0.386717,0.094007,-79.576424,0.010424,0.000000
15.710001,1.950859,-79.620903,-0.001410,0.000390,0.009912,8.677855,0.442071,0.099124,-79.620903,0.010927,0.000000
16.010000,2.133690,-79.576424,-0.001393,0.000409,0.010381,9.491127,0.483501,0.103807,-79.576424,0.011421,0.000000
16.310001,2.362328,-79.620903,-0.001371,0.000425,0.010806,10.508158,0.535311,0.108056,-79.620903,0.011924,0.000000
16.610001,2.715340,-79.620903,-0.001362,0.000447,0.011361,12.078434,0.615305,0.113607,-79.620903,0.012427,0.000000
16.910002,2.777901,-79.576424,-0.001345,0.000461,0.011699,12.356719,0.629481,0.116989,-79.576424,0.012922,0.000000
17.210001,3.119736,-79.620903,-0.001311,0.000485,0.012315,13.877277,0.706942,0.123146,-79.620903,0.013425,0.000000
17.510000,3.241875,-79.709862,-0.001319,0.000497,0.012627,14.420579,0.734619,0.126268,-79.709862,0.013928,0.000000
17.810001,3.802292,-79.709862,-0.001289,0.000525,0.013338,16.913439,0.861612,0.133379,-79.709862,0.014422,0.000000
18.110001,4.122910,-79.709862,-0.001268,0.000544,0.013806,18.339617,0.934265,0.138062,-79.709862,0.014925,0.000000
18.410002,4.666946,-79.665382,-0.001250,0.000568,0.014422,20.759615,1.057545,0.144220,-79.665382,0.015428,0.000000
18.710001,4.679230,-79.665382,-0.001233,0.000575,0.014604,20.814253,1.060329,0.146041,-79.665382,0.015922,0.000000
19.010000,5.490257,-79.620903,-0.001207,0.000606,0.015393,24.421885,1.244110,0.153933,-79.620903,0.016425,0.000000
19.310001,5.944550,-79.709862,-0.001199,0.000626,0.015896,26.442677,1.347054,0.158962,-79.709862,0.016928,0.000000
19.610001,6.262184,-79.665382,-0.001181,0.000642,0.016304,27.855587,1.419031,0.163038,-79.665382,0.017423,0.000000
19.910002,6.879211,-79.665382,-0.001181,0.000663,0.016833,30.600260,1.558852,0.168329,-79.665382,0.017926,0.000000
20.210001,7.404251,-79.754349,-0.001155,0.000683,0.017336,32.935753,1.677827,0.173358,-79.754349,0.018429,0.000000
20.510000,8.042130,-79.709862,-0.001138,0.000702,0.017821,35.773178,1.822373,0.178215,-79.709862,0.018923,0.000000
20.810001,8.557861,-79.754349,-0.001117,0.000721,0.018316,38.067268,1.939239,0.183158,-79.754349,0.019426,0.000000
21.110001,9.177490,-79.754349,-0.001104,0.000740,0.018793,40.823517,2.079649,0.187928,-79.754349,0.019929,0.000000
21.410002,10.089432,-79.754349,-0.001104,0.000764,0.019417,44.880035,2.286298,0.194172,-79.754349,0.020423,0.000000
21.710001,10.540001,-79.709862,-0.001078,0.000779,0.019790,46.884266,2.388398,0.197901,-79.709862,0.020926,0.000000
22.010000,11.199471,-79.754349,-0.001065,0.000799,0.020284,49.817734,2.537836,0.202844,-79.754349,0.021429,0.000000
22.310001,11.645950,-79.754349,-0.001030,0.000813,0.020657,51.803776,2.639010,0.206573,-79.754349,0.021923,0.000000
22.610001,12.861748,-79.798828,-0.001026,0.000841,0.021360,57.211910,2.914514,0.213598,-79.798828,0.022426,0.000000
22.910002,13.352531,-79.754349,-0.001026,0.000858,0.021785,59.395027,3.025727,0.217847,-79.754349,0.022929,0.000000
23.210001,13.559196,-79.798828,-0.001000,0.000872,0.022158,60.314320,3.072558,0.221576,-79.798828,0.023424,0.000000
23.510000,15.108269,-79.798828,-0.000983,0.000899,0.022834,67.204933,3.423583,0.228341,-79.798828,0.023927,0.000000
23.810001,15.934937,-79.843307,-0.000970,0.000921,0.023398,70.882141,3.610908,0.233978,-79.843307,0.024430,0.000000
24.110001,16.142349,-79.798828,-0.000966,0.000934,0.023719,71.804756,3.657909,0.237186,-79.798828,0.024924,0.000000
24.410002,17.679871,-79.887787,-0.000936,0.000958,0.024343,78.643990,4.006316,0.243430,-79.887787,0.025427,0.000000
24.710001,18.607079,-79.843307,-0.000931,0.000981,0.024907,82.768417,4.216424,0.249067,-79.843307,0.025930,0.000000
25.010002,18.538193,-79.887787,-0.000927,0.000987,0.025063,82.461998,4.200815,0.250628,-79.887787,0.026424,0.000000
25.310001,19.555138,-79.843307,-0.000910,0.001012,0.025696,86.985596,4.431258,0.256959,-79.843307,0.026927,0.000000
25.610001,21.207359,-79.843307,-0.000892,0.001036,0.026303,94.335045,4.805656,0.263030,-79.843307,0.027430,0.000000
25.910002,21.878746,-79.887787,-0.000884,0.001053,0.026745,97.321526,4.957795,0.267452,-79.887787,0.027925,0.000000
26.210001,23.131035,-79.887787,-0.000875,0.001078,0.027378,102.891983,5.241568,0.273783,-79.887787,0.028428,0.000000
26.510002,23.877266,-79.887787,-0.000858,0.001097,0.027855,106.211380,5.410666,0.278553,-79.887787,0.028931,0.000000
26.810001,24.533760,-79.887787,-0.000858,0.001111,0.028228,109.131615,5.559430,0.282282,-79.887787,0.029425,0.000000
27.110001,25.511978,-79.843307,-0.000832,0.001131,0.028740,113.482948,5.781097,0.287399,-79.843307,0.029928,0.000000
27.410002,25.999786,-79.932266,-0.000828,0.001146,0.029104,115.652824,5.891636,0.291041,-79.932266,0.030431,0.000000
27.710001,27.573807,-79.887787,-0.000811,0.001167,0.029633,122.654419,6.248314,0.296331,-79.887787,0.030925,0.000000
28.010002,28.625015,-79.843307,-0.000798,0.001187,0.030162,127.330429,6.486521,0.301621,-79.843307,0.031428,0.000000
28.310001,29.957367,-79.976753,-0.000785,0.001212,0.030787,133.257019,6.788436,0.307865,-79.976753,0.031923,0.000000
28.610001,30.610878,-79.932266,-0.000755,0.001227,0.031177,136.163986,6.936524,0.311768,-79.932266,0.032426,0.000000
28.910002,31.371262,-79.976753,-0.000772,0.001243,0.031567,139.546341,7.108829,0.315670,-79.976753,0.032929,0.000000
29.210001,33.122902,-79.932266,-0.000755,0.001271,0.032287,147.338028,7.505757,0.322868,-79.932266,0.033423,0.000000
29.510002,34.660797,-79.932266,-0.000742,0.001295,0.032894,154.178925,7.854249,0.328939,-79.932266,0.033926,0.000000
29.810001,35.198875,-79.932266,-0.000729,0.001309,0.033249,156.572418,7.976179,0.332494,-79.932266,0.034429,0.000000
30.110001,35.692276,-79.932266,-0.000724,0.001326,0.033683,158.767166,8.087986,0.336830,-79.932266,0.034923,0.000000
30.410002,37.299057,-79.976753,-0.000707,0.001352,0.034342,165.914490,8.452087,0.343421,-79.976753,0.035426,0.000000
30.710001,38.558792,-79.976753,-0.000707,0.001370,0.034810,171.518066,8.737547,0.348104,-79.976753,0.035929,0.000000
31.010002,39.772354,-80.021233,-0.000698,0.001388,0.035244,176.916260,9.012544,0.352441,-80.021233,0.036423,0.000000
31.310001,41.115135,-79.976753,-0.000668,0.001410,0.035808,182.889252,9.316822,0.358077,-79.976753,0.036926,0.000000
31.610001,42.720802,-80.021233,-0.000664,0.001434,0.036423,190.031616,9.680673,0.364235,-80.021233,0.037429,0.000000
31.910002,43.392563,-79.976753,-0.000647,0.001446,0.036736,193.019760,9.832896,0.367357,-79.976753,0.037924,0.000000
32.210003,43.487518,-80.065712,-0.000655,0.001452,0.036874,193.442139,9.854412,0.368744,-80.065712,0.038427,0.000000
32.510002,46.119446,-80.065712,-0.000642,0.001485,0.037724,205.149536,10.450816,0.377243,-80.065712,0.038930,0.000000
32.810001,47.145332,-79.976753,-0.000634,0.001505,0.038236,209.712906,10.683285,0.382360,-79.976753,0.039424,0.000000
33.110001,47.586220,-80.021233,-0.000621,0.001512,0.038401,211.674072,10.783192,0.384008,-80.021233,0.039927,0.000000
33.410000,50.250916,-80.021233,-0.000608,0.001546,0.039268,223.527237,11.387020,0.392680,-80.021233,0.040430,0.000000
33.710003,52.000320,-80.065712,-0.000612,0.001571,0.039892,231.308975,11.783441,0.398924,-80.065712,0.040924,0.000000
34.010002,52.494835,-80.065712,-0.000608,0.001581,0.040161,233.508682,11.895499,0.401612,-80.065712,0.041427,0.000000
34.310001,55.497276,-80.065712,-0.000582,0.001616,0.041037,246.864212,12.575863,0.410371,-80.065712,0.041930,0.000000
34.610001,56.192863,-80.110191,-0.000578,0.001630,0.041401,249.958344,12.733485,0.414014,-80.110191,0.042425,0.000000
34.910000,57.586655,-80.065712,-0.000569,0.001649,0.041878,256.158234,13.049323,0.418783,-80.065712,0.042928,0.000000
35.210003,58.816971,-80.065712,-0.000565,0.001664,0.042269,261.630951,13.328116,0.422686,-80.065712,0.043431,0.000000
35.510002,60.328804,-80.021233,-0.000548,0.001684,0.042763,268.355927,13.670702,0.427629,-80.021233,0.043925,0.000000
35.810001,62.375740,-80.065712,-0.000543,0.001708,0.043387,277.461151,14.134544,0.433873,-80.065712,0.044428,0.000000
36.110001,63.567329,-80.110191,-0.000530,0.001726,0.043847,282.761597,14.404563,0.438469,-80.110191,0.044931,0.000000
36.410000,64.498634,-80.110191,-0.000530,0.001737,0.044107,286.904266,14.615600,0.441071,-80.110191,0.045425,0.000000
36.710003,66.125526,-80.154671,-0.000517,0.001748,0.044402,294.141022,14.984259,0.444020,-80.154671,0.007828,0.000000
37.010002,65.677193,-80.110191,-0.000517,0.001747,0.044385,292.146759,14.882665,0.443846,-80.110191,294.500488,0.000000
37.310001,65.282845,-80.154671,-0.000513,0.001748,0.044393,290.392609,14.793304,0.443933,-80.154671,294.500488,0.000000
37.610001,64.972664,-80.110191,-0.000517,0.001748,0.044393,289.012848,14.723016,0.443933,-80.110191,294.500488,0.000000
37.910004,65.749062,-80.199158,-0.000509,0.001762,0.044758,292.466431,14.898951,0.447575,-80.199158,294.500488,0.000000
38.210003,65.502922,-80.110191,-0.000513,0.001762,0.044758,291.371552,14.843175,0.447575,-80.110191,294.500488,0.000000
38.510002,65.288429,-80.199158,-0.000504,0.001762,0.044758,290.417450,14.794570,0.447575,-80.199158,294.500488,0.000000
38.810001,65.157738,-80.243637,-0.000504,0.001762,0.044766,289.836090,14.764955,0.447662,-80.243637,294.500488,0.000000
39.110001,65.028145,-80.154671,-0.000500,0.001763,0.044784,289.259644,14.735588,0.447835,-80.154671,294.500488,0.000000
39.410004,65.774376,-80.199158,-0.000513,0.001772,0.045009,292.579041,14.904686,0.450090,-80.199158,294.500488,0.000000
39.710003,65.727089,-80.243637,-0.000496,0.001772,0.045009,292.368683,14.893970,0.450090,-80.243637,294.500488,0.000000
40.010002,65.578148,-80.199158,-0.000504,0.001772,0.045009,291.706177,14.860221,0.450090,-80.199158,294.500488,0.000000
40.310001,65.519676,-80.199158,-0.000492,0.001772,0.045009,291.446075,14.846972,0.450090,-80.199158,294.500488,0.000000
40.610001,65.448555,-80.243637,-0.000492,0.001772,0.045009,291.129700,14.830854,0.450090,-80.243637,294.500488,0.000000
40.910004,65.340569,-80.243637,-0.000496,0.001772,0.045009,290.649353,14.806384,0.450090,-80.243637,294.500488,0.000000
41.210003,65.270195,-80.199158,-0.000492,0.001772,0.045009,290.336334,14.790438,0.450090,-80.199158,294.500488,0.000000
41.510002,65.209496,-80.243637,-0.000513,0.001772,0.045009,290.066315,14.776683,0.450090,-80.243637,294.500488,0.000000
41.810001,65.110817,-80.243637,-0.000492,0.001772,0.045009,289.627380,14.754322,0.450090,-80.243637,294.500488,0.000000
42.110001,65.045647,-80.243637,-0.000492,0.001772,0.045009,289.337494,14.739554,0.450090,-80.243637,294.500488,0.000000
42.410004,65.012138,-80.243637,-0.000483,0.001772,0.045009,289.188446,14.731961,0.450090,-80.243637,294.500488,0.000000
42.710003,64.943993,-80.332596,-0.000487,0.001772,0.045009,288.885315,14.716518,0.450090,-80.332596,294.500488,0.000000
43.010002,64.871758,-80.332596,-0.000487,0.001772,0.045009,288.563995,14.700150,0.450090,-80.332596,294.500488,0.000000
43.310001,64.815147,-80.243637,-0.000492,0.001772,0.045009,288.312164,14.687323,0.450090,-80.243637,294.500488,0.000000
43.610001,64.764503,-80.332596,-0.000487,0.001772,0.045009,288.086914,14.675847,0.450090,-80.332596,294.500488,0.000000
43.910004,64.720573,-80.288116,-0.000487,0.001772,0.045009,287.891479,14.665891,0.450090,-80.288116,294.500488,0.000000
44.210003,64.674400,-80.288116,-0.000487,0.001772,0.045009,287.686096,14.655428,0.450090,-80.288116,294.500488,0.000000
44.510002,64.630821,-80.288116,-0.000483,0.001772,0.045018,287.492249,14.645554,0.450177,-80.288116,294.500488,0.000000
44.810001,64.590981,-80.288116,-0.000483,0.001772,0.045018,287.315033,14.636525,0.450177,-80.288116,294.500488,0.000000
45.110001,64.553749,-80.332596,-0.000487,0.001772,0.045018,287.149414,14.628089,0.450177,-80.332596,294.500488,0.000000
45.410004,64.496773,-80.332596,-0.000483,0.001772,0.045018,286.895966,14.615177,0.450177,-80.332596,294.500488,0.000000
45.710003,64.466240,-80.288116,-0.000483,0.001772,0.045018,286.760162,14.608258,0.450177,-80.288116,294.500488,0.000000
46.010002,64.436455,-80.421562,-0.000500,0.001773,0.045026,286.627655,14.601510,0.450264,-80.421562,294.500488,0.000000
46.310001,64.412987,-80.332596,-0.000492,0.001773,0.045026,286.523285,14.596191,0.450264,-80.332596,294.500488,0.000000
46.610001,64.374626,-80.288116,-0.000474,0.001773,0.045035,286.352631,14.587500,0.450350,-80.288116,294.500488,0.000000
46.910004,66.779045,-80.332596,-0.000483,0.001655,0.042026,297.048035,15.132348,0.420258,-80.332596,294.500488,0.000000
47.210003,66.698235,-80.421562,-0.000466,0.001648,0.041852,296.688568,15.114037,0.418523,-80.421562,294.500488,0.000000
47.510002,66.668816,-80.466042,-0.000466,0.001648,0.041852,296.557709,15.107370,0.418523,-80.466042,294.500488,0.000000
47.810001,66.629356,-80.421562,-0.000474,0.001648,0.041852,296.382172,15.098429,0.418523,-80.421562,294.500488,0.000000
48.110001,66.582802,-80.377075,-0.000466,0.001648,0.041852,296.175079,15.087878,0.418523,-80.377075,294.500488,0.000000
48.410004,66.513176,-80.377075,-0.000479,0.001648,0.041852,295.865387,15.072101,0.418523,-80.377075,294.500488,0.000000
48.710003,66.487846,-80.421562,-0.000457,0.001648,0.041861,295.752716,15.066360,0.418610,-80.421562,294.500488,0.000000
49.010002,66.439064,-80.421562,-0.000470,0.001648,0.041861,295.535706,15.055307,0.418610,-80.421562,294.500488,0.000000
49.310001,66.420815,-80.332596,-0.000470,0.001648,0.041861,295.454529,15.051172,0.418610,-80.332596,294.500488,0.000000
49.610001,66.385445,-80.377075,-0.000474,0.001648,0.041861,295.297211,15.043157,0.418610,-80.377075,294.500488,0.000000
49.910004,66.365715,-80.421562,-0.000461,0.001648,0.041861,295.209442,15.038686,0.418610,-80.421562,294.500488,0.000000
50.210003,66.320274,-80.421562,-0.000470,0.001648,0.041861,295.007324,15.028389,0.418610,-80.421562,294.500488,0.000000
50.510002,66.284157,-80.466042,-0.000461,0.001648,0.041861,294.846649,15.020205,0.418610,-80.466042,294.500488,0.000000
50.810001,66.261452,-80.466042,-0.000470,0.001648,0.041861,294.745667,15.015059,0.418610,-80.466042,294.500488,0.000000
51.110001,66.220482,-80.466042,-0.000474,0.001648,0.041861,294.563416,15.005776,0.418610,-80.466042,294.500488,0.000000
51.410004,66.182137,-80.466042,-0.000457,0.001648,0.041861,294.392853,14.997087,0.418610,-80.466042,294.500488,0.000000
51.710003,66.169472,-80.466042,-0.000448,0.001648,0.041861,294.336517,14.994217,0.418610,-80.466042,294.500488,0.000000
52.010002,66.121803,-80.466042,-0.000487,0.001648,0.041861,294.124481,14.983415,0.418610,-80.466042,294.500488,0.000000
52.310001,66.102821,-80.510521,-0.000470,0.001648,0.041861,294.040039,14.979114,0.418610,-80.510521,294.500488,0.000000
52.610001,66.081963,-80.555000,-0.000466,0.001648,0.041861,293.947266,14.974386,0.418610,-80.555000,294.500488,0.000000
52.910004,66.050682,-80.510521,-0.000479,0.001648,0.041861,293.808105,14.967299,0.418610,-80.510521,294.500488,0.000000
53.210003,66.013451,-80.466042,-0.000470,0.001648,0.041861,293.642487,14.958861,0.418610,-80.466042,294.500488,0.000000
53.510002,66.007484,-80.421562,-0.000466,0.001648,0.041861,293.615967,14.957510,0.418610,-80.421562,294.500488,0.000000
53.810001,65.992226,-80.466042,-0.000466,0.001648,0.041870,293.548096,14.954052,0.418697,-80.466042,294.500488,0.000000
54.110004,65.938591,-80.555000,-0.000479,0.001648,0.041870,293.309509,14.941898,0.418697,-80.555000,294.500488,0.000000
54.410004,65.863380,-80.510521,-0.000466,0.001649,0.041878,292.974945,14.924855,0.418783,-80.510521,294.500488,0.000000
54.710003,65.829124,-80.510521,-0.000461,0.001649,0.041878,292.822571,14.917092,0.418783,-80.510521,294.500488,0.000000
55.010002,65.848488,-80.510521,-0.000483,0.001649,0.041887,292.908691,14.921480,0.418870,-80.510521,294.500488,0.000000
55.310001,65.813850,-80.599480,-0.000461,0.001649,0.041887,292.754639,14.913632,0.418870,-80.599480,294.500488,0.000000
55.610004,65.865990,-80.555000,-0.000453,0.001649,0.041887,292.986542,14.925447,0.418870,-80.555000,294.500488,0.000000
55.910004,65.842155,-80.555000,-0.000453,0.001649,0.041896,292.880524,14.920046,0.418957,-80.555000,294.500488,0.000000
56.210003,65.822792,-80.555000,-0.000457,0.001649,0.041896,292.794403,14.915658,0.418957,-80.555000,294.500488,0.000000
56.510002,65.774376,-80.599480,-0.000461,0.001649,0.041896,292.579041,14.904686,0.418957,-80.599480,294.500488,0.000000
56.810001,65.772514,-80.555000,-0.000466,0.001650,0.041913,292.570770,14.904265,0.419130,-80.555000,294.500488,0.000000
57.110004,65.749428,-80.599480,-0.000474,0.001650,0.041913,292.468048,14.899034,0.419130,-80.599480,294.500488,0.000000
57.410004,65.757622,-80.555000,-0.000461,0.001650,0.041913,292.504517,14.900890,0.419130,-80.555000,294.500488,0.000000
57.710003,65.672356,-80.643967,-0.000466,0.001653,0.041982,292.125214,14.881569,0.419824,-80.643967,294.500488,0.000000
58.010002,65.652245,-80.599480,-0.000479,0.001678,0.042615,292.035767,14.877011,0.426155,-80.599480,294.500488,0.000000
58.310001,65.636604,-80.599480,-0.000453,0.001680,0.042676,291.966187,14.873467,0.426762,-80.599480,294.500488,0.000000
58.610004,65.630272,-80.599480,-0.000470,0.001698,0.043118,291.938019,14.872032,0.431185,-80.599480,294.500488,0.000000
58.910004,65.593788,-80.599480,-0.000457,0.001714,0.043535,291.775757,14.863765,0.435347,-80.599480,294.500488,0.000000
59.210003,65.589317,-80.599480,-0.000461,0.001714,0.043535,291.755859,14.862752,0.435347,-80.599480,294.500488,0.000000
59.510002,65.580009,-80.643967,-0.000466,0.001714,0.043535,291.714447,14.860642,0.435347,-80.643967,294.500488,0.000000
59.810001,65.562126,-80.643967,-0.000470,0.001714,0.043535,291.634888,14.856590,0.435347,-80.643967,294.500488,0.000000
60.110004,65.543510,-80.643967,-0.000466,0.001714,0.043535,291.552094,14.852372,0.435347,-80.643967,294.500488,0.000000
60.410004,65.541283,-80.688446,-0.000457,0.001714,0.043535,291.542175,14.851867,0.435347,-80.688446,294.500488,0.000000
60.710003,65.516335,-80.688446,-0.000457,0.001714,0.043535,291.431213,14.846213,0.435347,-80.688446,294.500488,0.000000
61.010002,65.506279,-80.643967,-0.000457,0.001714,0.043535,291.386475,14.843935,0.435347,-80.643967,294.500488,0.000000
61.310001,65.502556,-80.599480,-0.000466,0.001715,0.043552,291.369934,14.843092,0.435521,-80.599480,294.500488,0.000000
61.610004,65.483192,-80.643967,-0.000461,0.001745,0.044315,291.283783,14.838703,0.443152,-80.643967,294.500488,0.000000
61.910004,65.473885,-80.643967,-0.000474,0.001745,0.044333,291.242371,14.836595,0.443326,-80.643967,294.500488,0.000000
62.210003,65.454887,-80.688446,-0.000461,0.001745,0.044333,291.157867,14.832290,0.443326,-80.688446,294.500488,0.000000
62.510002,65.420631,-80.688446,-0.000474,0.001745,0.044333,291.005493,14.824528,0.443326,-80.688446,294.500488,0.000000
62.810001,65.412437,-80.732925,-0.000466,0.001749,0.044428,290.969055,14.822670,0.444280,-80.732925,294.500488,0.000000
63.110004,65.402748,-80.688446,-0.000470,0.001749,0.044428,290.925964,14.820475,0.444280,-80.688446,294.500488,0.000000
63.410004,65.379295,-80.643967,-0.000461,0.001749,0.044428,290.821625,14.815161,0.444280,-80.643967,294.500488,0.000000
63.710003,65.352486,-80.688446,-0.000457,0.001749,0.044428,290.702362,14.809085,0.444280,-80.688446,294.500488,0.000000
64.010002,65.343178,-80.688446,-0.000474,0.001749,0.044428,290.660980,14.806976,0.444280,-80.688446,294.500488,0.000000
64.310005,65.334236,-80.732925,-0.000461,0.001749,0.044428,290.621185,14.804950,0.444280,-80.732925,294.500488,0.000000
64.610001,65.320091,-80.777405,-0.000457,0.001749,0.044428,290.558289,14.801744,0.444280,-80.777405,294.500488,0.000000
64.910004,65.306313,-80.777405,-0.000461,0.001749,0.044428,290.496979,14.798622,0.444280,-80.777405,294.500488,0.000000
65.210007,65.301476,-80.777405,-0.000470,0.001749,0.044428,290.475464,14.797526,0.444280,-80.777405,294.500488,0.000000
65.510002,65.297005,-80.777405,-0.000466,0.001754,0.044549,290.455597,14.796514,0.445494,-80.777405,294.500488,0.000000
65.810005,65.323067,-80.732925,-0.000470,0.001765,0.044836,290.571503,14.802419,0.448356,-80.732925,294.500488,0.000000
66.110001,65.328285,-80.777405,-0.000474,0.001765,0.044836,290.594727,14.803600,0.448356,-80.777405,294.500488,0.000000
66.410004,65.321571,-80.777405,-0.000466,0.001765,0.044836,290.564850,14.802079,0.448356,-80.777405,294.500488,0.000000
66.710007,65.307060,-80.821892,-0.000453,0.001765,0.044836,290.500305,14.798792,0.448356,-80.821892,294.500488,0.000000
67.010002,65.311897,-80.777405,-0.000466,0.001770,0.044966,290.521820,14.799888,0.449657,-80.777405,294.500488,0.000000
67.310005,65.305199,-80.777405,-0.000461,0.001770,0.044966,290.492035,14.798369,0.449657,-80.777405,294.500488,0.000000
67.610001,65.326042,-80.821892,-0.000457,0.001774,0.045061,290.584747,14.803092,0.450610,-80.821892,294.500488,0.000000
67.910004,65.313011,-80.777405,-0.000461,0.001774,0.045061,290.526794,14.800140,0.450610,-80.777405,294.500488,0.000000
68.210007,65.309288,-80.866371,-0.000466,0.001774,0.045061,290.510223,14.799295,0.450610,-80.866371,294.500488,0.000000
68.510002,65.294395,-80.821892,-0.000470,0.001774,0.045061,290.443970,14.795921,0.450610,-80.821892,294.500488,0.000000
68.810005,65.280251,-80.777405,-0.000466,0.001774,0.045061,290.381042,14.792717,0.450610,-80.777405,294.500488,0.000000
69.110001,65.269814,-80.866371,-0.000466,0.001774,0.045070,290.334625,14.790351,0.450697,-80.866371,294.500488,0.000000
69.410004,65.262749,-80.910851,-0.000461,0.001774,0.045070,290.303192,14.788750,0.450697,-80.910851,294.500488,0.000000
69.710007,65.254921,-80.866371,-0.000461,0.001774,0.045070,290.268372,14.786977,0.450697,-80.866371,294.500488,0.000000
70.010002,65.326790,-80.910851,-0.000470,0.001781,0.045234,290.588074,14.803262,0.452345,-80.910851,294.500488,0.000000
70.310005,65.304070,-80.866371,-0.000466,0.001781,0.045234,290.487000,14.798114,0.452345,-80.866371,294.500488,0.000000
70.610001,65.300346,-80.866371,-0.000474,0.001783,0.045278,290.470459,14.797271,0.452779,-80.866371,294.500488,0.000000
70.910004,65.298485,-80.910851,-0.000466,0.001783,0.045278,290.462158,14.796848,0.452779,-80.910851,294.500488,0.000000
71.210007,65.305931,-80.910851,-0.000457,0.001783,0.045278,290.495300,14.798535,0.452779,-80.910851,294.500488,0.000000
71.510002,65.305199,-80.866371,-0.000474,0.001783,0.045287,290.492035,14.798369,0.452865,-80.866371,294.500488,0.000000
71.810005,65.283226,-80.955330,-0.000466,0.001783,0.045287,290.394287,14.793390,0.452865,-80.955330,294.500488,0.000000
72.110001,65.265724,-80.910851,-0.000466,0.001783,0.045287,290.316437,14.789425,0.452865,-80.910851,294.500488,0.000000
72.410004,65.276512,-80.910851,-0.000470,0.001783,0.045287,290.364441,14.791869,0.452865,-80.910851,294.500488,0.000000
72.710007,65.266472,-80.910851,-0.000474,0.001783,0.045287,290.319763,14.789594,0.452865,-80.910851,294.500488,0.000000
73.010002,65.257530,-80.910851,-0.000479,0.001783,0.045287,290.279999,14.787567,0.452865,-80.910851,294.500488,0.000000
73.310005,65.238914,-80.999809,-0.000466,0.001783,0.045287,290.197174,14.783349,0.452865,-80.999809,294.500488,0.000000
73.610001,65.241524,-80.955330,-0.000466,0.001783,0.045287,290.208801,14.783940,0.452865,-80.955330,294.500488,0.000000
73.910004,65.230721,-80.955330,-0.000470,0.001783,0.045287,290.160736,14.781493,0.452865,-80.955330,294.500488,0.000000
74.210007,65.225883,-80.955330,-0.000470,0.001783,0.045287,290.139221,14.780396,0.452865,-80.955330,294.500488,0.000000
74.510002,65.223640,-80.910851,-0.000470,0.001783,0.045287,290.129242,14.779888,0.452865,-80.910851,294.500488,0.000000
74.810005,65.200188,-80.999809,-0.000466,0.001783,0.045287,290.024933,14.774573,0.452865,-80.999809,294.500488,0.000000
75.110001,65.186775,-80.955330,-0.000474,0.001783,0.045287,289.965271,14.771534,0.452865,-80.955330,294.500488,0.000000
75.410004,65.177834,-80.955330,-0.000461,0.001783,0.045287,289.925476,14.769507,0.452865,-80.955330,294.500488,0.000000
75.710007,65.161079,-80.999809,-0.000466,0.001783,0.045295,289.850952,14.765712,0.452952,-80.999809,294.500488,0.000000
76.010002,65.203529,-80.999809,-0.000470,0.001786,0.045373,290.039795,14.775331,0.453732,-80.999809,294.500488,0.000000
76.310005,65.221779,-80.955330,-0.000466,0.001786,0.045373,290.120972,14.779467,0.453732,-80.955330,294.500488,0.000000
76.610001,65.215828,-81.044296,-0.000470,0.001786,0.045373,290.094482,14.778117,0.453732,-81.044296,294.500488,0.000000
76.910004,65.220299,-80.999809,-0.000461,0.001786,0.045373,290.114380,14.779131,0.453732,-80.999809,294.500488,0.000000
77.210007,65.225136,-80.999809,-0.000457,0.001786,0.045373,290.135895,14.780228,0.453732,-80.999809,294.500488,0.000000
77.510002,65.218056,-80.999809,-0.000470,0.001786,0.045373,290.104401,14.778623,0.453732,-80.999809,294.500488,0.000000
77.810005,65.204659,-80.999809,-0.000461,0.001786,0.045373,290.044800,14.775586,0.453732,-80.999809,294.500488,0.000000
78.110001,65.202797,-81.044296,-0.000461,0.001786,0.045373,290.036530,14.775166,0.453732,-81.044296,294.500488,0.000000
78.410004,65.196083,-81.044296,-0.000466,0.001786,0.045373,290.006653,14.773643,0.453732,-81.044296,294.500488,0.000000
78.710007,65.188271,-81.044296,-0.000466,0.001786,0.045373,289.971924,14.771873,0.453732,-81.044296,294.500488,0.000000
79.010002,65.169655,-80.999809,-0.000461,0.001786,0.045373,289.889099,14.767654,0.453732,-80.999809,294.500488,0.000000
79.310005,65.199806,-81.088776,-0.000470,0.001788,0.045408,290.023224,14.774487,0.454079,-81.088776,294.500488,0.000000
79.610001,65.219170,-81.044296,-0.000461,0.001788,0.045408,290.109344,14.778874,0.454079,-81.044296,294.500488,0.000000
79.910004,65.219917,-81.044296,-0.000470,0.001788,0.045408,290.112671,14.779044,0.454079,-81.044296,294.500488,0.000000
80.210007,65.206139,-81.044296,-0.000461,0.001788,0.045408,290.051392,14.775923,0.454079,-81.044296,294.500488,0.000000
80.510002,65.188271,-81.133255,-0.000474,0.001788,0.045408,289.971924,14.771873,0.454079,-81.133255,294.500488,0.000000
80.810005,65.201668,-81.133255,-0.000457,0.001788,0.045408,290.031494,14.774909,0.454079,-81.133255,294.500488,0.000000
81.110001,65.198326,-81.088776,-0.000461,0.001788,0.045408,290.016632,14.774152,0.454079,-81.088776,294.500488,0.000000
81.410004,65.186409,-81.133255,-0.000470,0.001788,0.045408,289.963623,14.771451,0.454079,-81.133255,294.500488,0.000000
81.710007,65.191994,-81.088776,-0.000466,0.001788,0.045408,289.988464,14.772717,0.454079,-81.088776,294.500488,0.000000
82.010002,65.179329,-81.133255,-0.000461,0.001788,0.045408,289.932129,14.769847,0.454079,-81.133255,294.500488,0.000000
82.310005,65.168526,-81.088776,-0.000470,0.001788,0.045408,289.884094,14.767399,0.454079,-81.088776,294.500488,0.000000
82.610001,65.165184,-81.177734,-0.000466,0.001788,0.045408,289.869202,14.766642,0.454079,-81.177734,294.500488,0.000000
82.910004,65.157738,-81.133255,-0.000453,0.001788,0.045408,289.836090,14.764955,0.454079,-81.133255,294.500488,0.000000
83.210007,65.153267,-81.133255,-0.000479,0.001788,0.045408,289.816193,14.763942,0.454079,-81.133255,294.500488,0.000000
83.510002,65.148430,-81.044296,-0.000461,0.001788,0.045408,289.794678,14.762845,0.454079,-81.044296,294.500488,0.000000
83.810005,65.134270,-81.177734,-0.000457,0.001788,0.045408,289.731689,14.759637,0.454079,-81.177734,294.500488,0.000000
84.110001,65.137627,-81.177734,-0.000457,0.001788,0.045408,289.746643,14.760398,0.454079,-81.177734,294.500488,0.000000
84.410004,65.119011,-81.222214,-0.000457,0.001788,0.045408,289.663818,14.756179,0.454079,-81.222214,294.500488,0.000000
84.710007,65.110069,-81.222214,-0.000479,0.001788,0.045408,289.624054,14.754152,0.454079,-81.222214,294.500488,0.000000
85.010002,65.114159,-81.266701,-0.000466,0.001789,0.045451,289.642242,14.755079,0.454513,-81.266701,294.500488,0.000000
85.310005,65.138374,-81.133255,-0.000470,0.001789,0.045451,289.749969,14.760567,0.454513,-81.133255,294.500488,0.000000
85.610001,65.139107,-81.133255,-0.000461,0.001789,0.045451,289.753204,14.760733,0.454513,-81.133255,294.500488,0.000000
85.910004,65.205391,-81.133255,-0.000474,0.001791,0.045495,290.048065,14.775753,0.454947,-81.133255,294.500488,0.000000
86.210007,65.223640,-81.222214,-0.000474,0.001791,0.045495,290.129242,14.779888,0.454947,-81.222214,294.500488,0.000000
86.510002,65.247841,-81.222214,-0.000453,0.001791,0.045495,290.236877,14.785373,0.454947,-81.222214,294.500488,0.000000
86.810005,65.253426,-81.222214,-0.000453,0.001791,0.045495,290.261719,14.786638,0.454947,-81.222214,294.500488,0.000000
87.110001,65.241890,-81.266701,-0.000466,0.001791,0.045495,290.210419,14.784024,0.454947,-81.266701,294.500488,0.000000
87.410004,65.248970,-81.222214,-0.000461,0.001791,0.045495,290.241913,14.785628,0.454947,-81.222214,294.500488,0.000000
87.710007,65.243385,-81.222214,-0.000470,0.001791,0.045495,290.217072,14.784363,0.454947,-81.222214,294.500488,0.000000
88.010002,65.251564,-81.222214,-0.000461,0.001791,0.045495,290.253448,14.786216,0.454947,-81.222214,294.500488,0.000000
88.310005,65.235191,-81.266701,-0.000466,0.001791,0.045495,290.180634,14.782506,0.454947,-81.266701,294.500488,0.000000
88.610001,65.246727,-81.311180,-0.000453,0.001791,0.045495,290.231934,14.785120,0.454947,-81.311180,294.500488,0.000000
88.910004,65.244118,-81.311180,-0.000457,0.001791,0.045495,290.220337,14.784528,0.454947,-81.311180,294.500488,0.000000
89.210007,65.243752,-81.311180,-0.000461,0.001791,0.045495,290.218689,14.784445,0.454947,-81.311180,294.500488,0.000000
89.510002,65.242638,-81.266701,-0.000466,0.001791,0.045495,290.213745,14.784193,0.454947,-81.266701,294.500488,0.000000
89.810005,65.231834,-81.355659,-0.000466,0.001791,0.045495,290.165680,14.781745,0.454947,-81.355659,294.500488,0.000000
90.110001,65.217308,-81.311180,-0.000461,0.001791,0.045495,290.101074,14.778454,0.454947,-81.311180,294.500488,0.000000
90.410004,65.218803,-81.311180,-0.000470,0.001791,0.045495,290.107727,14.778792,0.454947,-81.311180,294.500488,0.000000
90.710007,65.219917,-81.311180,-0.000461,0.001791,0.045495,290.112671,14.779044,0.454947,-81.311180,294.500488,0.000000
91.010002,65.223274,-81.400139,-0.000457,0.001791,0.045495,290.127625,14.779805,0.454947,-81.400139,294.500488,0.000000
91.310005,65.212105,-81.355659,-0.000461,0.001791,0.045495,290.077942,14.777274,0.454947,-81.355659,294.500488,0.000000
91.610001,65.210243,-81.311180,-0.000470,0.001791,0.045495,290.069641,14.776852,0.454947,-81.311180,294.500488,0.000000
91.910004,65.202049,-81.355659,-0.000470,0.001791,0.045495,290.033203,14.774996,0.454947,-81.355659,294.500488,0.000000
92.210007,65.209862,-81.311180,-0.000457,0.001791,0.045495,290.067963,14.776766,0.454947,-81.311180,294.500488,0.000000
92.510002,65.189018,-81.355659,-0.000461,0.001791,0.045495,289.975250,14.772042,0.454947,-81.355659,294.500488,0.000000
92.810005,65.171883,-81.355659,-0.000457,0.001791,0.045495,289.899017,14.768160,0.454947,-81.355659,294.500488,0.000000
93.110001,65.167412,-81.400139,-0.000466,0.001791,0.045495,289.879120,14.767146,0.454947,-81.400139,294.500488,0.000000
93.410004,65.173378,-81.444618,-0.000470,0.001791,0.045495,289.905670,14.768499,0.454947,-81.444618,294.500488,0.000000
93.710007,65.169655,-81.355659,-0.000453,0.001791,0.045495,289.889099,14.767654,0.454947,-81.355659,294.500488,0.000000
94.010002,65.159218,-81.355659,-0.000461,0.001791,0.045495,289.842682,14.765290,0.454947,-81.355659,294.500488,0.000000
94.310005,65.146935,-81.400139,-0.000479,0.001791,0.045495,289.788025,14.762506,0.454947,-81.400139,294.500488,0.000000
94.610008,65.149544,-81.444618,-0.000457,0.001791,0.045495,289.799652,14.763098,0.454947,-81.444618,294.500488,0.000000
94.910004,65.145073,-81.444618,-0.000470,0.001791,0.045495,289.779755,14.762084,0.454947,-81.444618,294.500488,0.000000
95.210007,65.136131,-81.444618,-0.000470,0.001791,0.045495,289.739990,14.760058,0.454947,-81.444618,294.500488,0.000000
95.510002,65.122734,-81.489105,-0.000466,0.001791,0.045495,289.680389,14.757022,0.454947,-81.489105,294.500488,0.000000
95.810005,65.110817,-81.489105,-0.000474,0.001791,0.045495,289.627380,14.754322,0.454947,-81.489105,294.500488,0.000000
96.110008,65.127205,-81.444618,-0.000453,0.001791,0.045495,289.700287,14.758035,0.454947,-81.444618,294.500488,0.000000
96.410004,65.115654,-81.489105,-0.000466,0.001791,0.045495,289.648895,14.755418,0.454947,-81.489105,294.500488,0.000000
96.710007,65.110435,-81.444618,-0.000466,0.001791,0.045495,289.625671,14.754235,0.454947,-81.444618,294.500488,0.000000
97.010002,65.094429,-81.489105,-0.000466,0.001791,0.045495,289.554474,14.750608,0.454947,-81.489105,294.500488,0.000000
97.310005,65.098518,-81.489105,-0.000466,0.001791,0.045495,289.572662,14.751535,0.454947,-81.489105,1681.640991,0.000000
97.610008,65.072838,-81.533585,-0.000470,0.001783,0.045295,289.458435,14.745716,0.452952,-81.533585,0.045096,0.000000
97.910004,65.022560,-81.533585,-0.000470,0.001768,0.044914,289.234802,14.734323,0.449136,-81.533585,0.044593,0.000000
98.210007,64.980476,-81.489105,-0.000466,0.001754,0.044541,289.047607,14.724787,0.445407,-81.489105,0.044098,0.000000
98.510002,64.923515,-81.489105,-0.000461,0.001738,0.044142,288.794220,14.711879,0.441418,-81.489105,0.043595,0.000000
98.810005,64.919792,-81.533585,-0.000453,0.001711,0.043465,288.777649,14.711036,0.434654,-81.533585,0.043092,0.000000
99.110008,64.929100,-81.533585,-0.000453,0.001694,0.043023,288.819061,14.713144,0.430231,-81.533585,0.042598,0.000000
99.410004,64.886269,-81.533585,-0.000466,0.001675,0.042546,288.628540,14.703439,0.425461,-81.533585,0.042095,0.000000
99.710007,64.888878,-81.533585,-0.000453,0.001658,0.042121,288.640137,14.704030,0.421212,-81.533585,0.041601,0.000000
100.010002,64.859093,-81.533585,-0.000457,0.001640,0.041644,288.507660,14.697281,0.416442,-81.533585,0.041098,0.000000
100.310005,64.874733,-81.578064,-0.000453,0.001622,0.041211,288.577240,14.700825,0.412106,-81.578064,0.040595,0.000000
100.610008,64.777534,-81.533585,-0.000457,0.001600,0.040630,288.144867,14.678799,0.406295,-81.533585,0.040101,0.000000
100.910004,64.760033,-81.533585,-0.000466,0.001579,0.040118,288.067017,14.674833,0.401179,-81.533585,0.039598,0.000000
101.210007,64.516136,-81.533585,-0.000466,0.001562,0.039676,286.982117,14.619566,0.396756,-81.533585,0.039095,0.000000
101.510002,64.036140,-81.622543,-0.000440,0.001547,0.039303,284.846985,14.510797,0.393027,-81.622543,0.038600,0.000000
101.810005,63.327522,-81.622543,-0.000453,0.001530,0.038860,281.694885,14.350223,0.388604,-81.622543,0.038097,0.000000
102.110008,62.548515,-81.578064,-0.000448,0.001511,0.038383,278.229706,14.173697,0.383834,-81.578064,0.037594,0.000000
102.410004,61.450394,-81.622543,-0.000444,0.001494,0.037941,273.345001,13.924858,0.379411,-81.622543,0.037100,0.000000
102.710007,60.075218,-81.622543,-0.000440,0.001470,0.037325,267.227905,13.613239,0.373254,-81.622543,0.036597,0.000000
103.010002,58.755157,-81.667023,-0.000457,0.001450,0.036840,261.355988,13.314109,0.368397,-81.667023,0.036094,0.000000
103.310005,57.620544,-81.667023,-0.000444,0.001435,0.036441,256.308990,13.057002,0.364408,-81.667023,0.035600,0.000000
103.610008,56.164940,-81.622543,-0.000435,0.001419,0.036042,249.834137,12.727158,0.360419,-81.622543,0.035097,0.000000
103.910004,54.917862,-81.711510,-0.000444,0.001402,0.035600,244.286850,12.444565,0.355996,-81.711510,0.034594,0.000000
104.210007,53.134941,-81.622543,-0.000440,0.001383,0.035123,236.356018,12.040549,0.351226,-81.622543,0.034099,0.000000
104.510002,51.061203,-81.622543,-0.000431,0.001362,0.034585,227.131577,11.570634,0.345850,-81.622543,0.033596,0.000000
104.810005,49.433189,-81.667023,-0.000427,0.001347,0.034212,219.889801,11.201720,0.342121,-81.667023,0.033093,0.000000
105.110008,46.707047,-81.667023,-0.000427,0.001321,0.033562,207.763321,10.583968,0.335616,-81.667023,0.032599,0.000000
105.410004,44.704430,-81.622543,-0.000418,0.001304,0.033128,198.855240,10.130168,0.331280,-81.622543,0.032096,0.000000
105.710007,42.895821,-81.667023,-0.000427,0.001290,0.032764,190.810135,9.720331,0.327638,-81.667023,0.031593,0.000000
106.010002,40.661209,-81.667023,-0.000427,0.001269,0.032235,180.870087,9.213962,0.322348,-81.667023,0.031099,0.000000
106.310005,38.286591,-81.711510,-0.000431,0.001249,0.031723,170.307266,8.675866,0.317231,-81.711510,0.030596,0.000000
106.610008,36.078049,-81.711510,-0.000427,0.001225,0.031107,160.483170,8.175403,0.311074,-81.711510,0.030093,0.000000
106.910004,34.138733,-81.711510,-0.000431,0.001209,0.030708,151.856674,7.735947,0.307085,-81.711510,0.029598,0.000000
107.210007,31.342216,-81.755989,-0.000431,0.001184,0.030084,139.417145,7.102248,0.300841,-81.755989,0.029095,0.000000
107.510002,28.907272,-81.755989,-0.000431,0.001162,0.029503,128.585968,6.550481,0.295030,-81.755989,0.028592,0.000000
107.810005,27.216705,-81.755989,-0.000444,0.001150,0.029208,121.065948,6.167394,0.292082,-81.755989,0.028098,0.000000
108.110008,24.643982,-81.800468,-0.000440,0.001126,0.028592,109.621910,5.584406,0.285924,-81.800468,0.027595,0.000000
108.410004,22.921761,-81.800468,-0.000444,0.001112,0.028237,101.961082,5.194145,0.282369,-81.800468,0.027092,0.000000
108.710007,21.038300,-81.800468,-0.000435,0.001089,0.027673,93.583031,4.767347,0.276732,-81.800468,0.026598,0.000000
109.010002,17.664230,-81.755989,-0.000431,0.001064,0.027023,78.574417,4.002772,0.270228,-81.755989,0.026095,0.000000
109.310005,15.958023,-81.755989,-0.000440,0.001046,0.026580,70.984833,3.616140,0.265805,-81.755989,0.025592,0.000000
109.610008,13.718575,-81.755989,-0.000444,0.001029,0.026147,61.023266,3.108673,0.261469,-81.755989,0.025098,0.000000
109.910004,11.138405,-81.755989,-0.000444,0.001006,0.025557,49.546101,2.523999,0.255571,-81.755989,0.024595,0.000000
110.210007,9.599388,-81.844948,-0.000440,0.000988,0.025089,42.700211,2.175252,0.250888,-81.844948,0.024092,0.000000
110.510002,7.301849,-81.800468,-0.000453,0.000971,0.024655,32.480247,1.654623,0.246552,-81.800468,0.023597,0.000000
110.810005,5.201302,-81.889427,-0.000444,0.000950,0.024118,23.136545,1.178632,0.241175,-81.889427,0.023094,0.000000
111.110008,2.939880,-81.844948,-0.000444,0.000929,0.023597,13.077241,0.666186,0.235972,-81.844948,0.022591,0.000000
111.410004,0.865768,-81.844948,-0.000444,0.000909,0.023086,3.851130,0.196186,0.230855,-81.844948,0.022097,0.000000
111.710007,-0.942474,-81.844948,-0.000457,0.000888,0.022557,-4.192335,-0.213568,0.225565,-81.844948,0.021594,0.000000
112.010002,-0.291199,-81.844948,-0.000470,0.000867,0.022019,-1.295317,-0.065987,0.220189,-81.844948,0.021091,0.000000
112.310005,-0.246140,-81.889427,-0.000474,0.000852,0.021646,-1.094883,-0.055776,0.216460,-81.889427,0.020597,0.000000
112.610008,-0.210762,-81.844948,-0.000487,0.000829,0.021056,-0.937516,-0.047759,0.210562,-81.844948,0.020094,0.000000
112.910004,-0.184326,-81.889427,-0.000526,0.000810,0.020571,-0.819924,-0.041769,0.205706,-81.889427,0.019599,0.000000
113.210007,-0.188049,-81.889427,-0.000530,0.000793,0.020137,-0.836485,-0.042613,0.201370,-81.889427,0.019096,0.000000
113.510002,-0.133682,-81.889427,-0.000552,0.000773,0.019643,-0.594648,-0.030293,0.196427,-81.889427,0.018593,0.000000
113.810005,-0.147087,-81.889427,-0.000586,0.000751,0.019079,-0.654276,-0.033330,0.190790,-81.889427,0.018099,0.000000
114.110008,-0.144112,-81.889427,-0.000599,0.000729,0.018515,-0.641041,-0.032656,0.185153,-81.889427,0.017596,0.000000
114.410004,-0.128845,-81.933914,-0.000621,0.000710,0.018038,-0.573132,-0.029197,0.180383,-81.933914,0.017093,0.000000
114.710007,-0.167198,-81.889427,-0.000638,0.000693,0.017605,-0.743735,-0.037888,0.176047,-81.889427,0.016599,0.000000
115.010002,-0.163101,-81.933914,-0.000660,0.000674,0.017128,-0.725510,-0.036959,0.171277,-81.933914,0.016096,0.000000
115.310005,-0.137032,-81.933914,-0.000686,0.000662,0.016824,-0.609547,-0.031052,0.168242,-81.933914,0.015593,0.000000
115.610008,-0.139267,-81.889427,-0.000698,0.000633,0.016087,-0.619490,-0.031558,0.160870,-81.889427,0.015098,0.000000
115.910004,-0.142250,-81.933914,-0.000716,0.000613,0.015567,-0.632760,-0.032234,0.155667,-81.933914,0.014595,0.000000
116.210007,-0.127724,-81.933914,-0.000737,0.000599,0.015211,-0.568143,-0.028943,0.152111,-81.933914,0.014092,0.000000
116.510002,-0.123627,-81.978394,-0.000776,0.000571,0.014491,-0.549919,-0.028014,0.144913,-81.978394,0.013598,0.000000
116.810005,-0.119904,-81.889427,-0.000793,0.000552,0.014014,-0.533358,-0.027171,0.140144,-81.889427,0.013095,0.000000
117.110008,-0.139641,-81.978394,-0.000798,0.000536,0.013624,-0.621153,-0.031643,0.136241,-81.978394,0.012592,0.000000
117.410004,-0.130707,-81.933914,-0.000815,0.000517,0.013138,-0.581413,-0.029619,0.131385,-81.933914,0.012098,0.000000
117.710007,-0.124001,-81.978394,-0.000841,0.000500,0.012696,-0.551582,-0.028099,0.126962,-81.978394,0.011595,0.000000
118.010002,-0.116554,-82.022873,-0.000867,0.000482,0.012254,-0.518459,-0.026412,0.122539,-82.022873,0.011092,0.000000
118.310005,-0.112083,-81.978394,-0.000880,0.000452,0.011491,-0.498572,-0.025398,0.114907,-81.978394,0.010597,0.000000
118.610008,-0.100166,-81.978394,-0.000918,0.000432,0.010979,-0.445562,-0.022698,0.109791,-81.978394,0.010095,0.000000
118.910004,-0.122887,-82.067352,-0.000931,0.000414,0.010528,-0.546627,-0.027847,0.105281,-82.067352,0.009592,0.000000
119.210007,-0.122513,-82.022873,-0.000944,0.000402,0.010199,-0.544964,-0.027762,0.101986,-82.022873,0.009097,0.000000
119.510002,-0.130333,-82.022873,-0.000961,0.000376,0.009557,-0.579750,-0.029534,0.095568,-82.022873,0.008594,0.000000
119.810005,-0.140015,-82.067352,-0.000983,0.000361,0.009158,-0.622816,-0.031728,0.091579,-82.067352,0.008091,0.000000
120.110008,-0.140015,-82.067352,-0.001013,0.000338,0.008594,-0.622816,-0.031728,0.085942,-82.067352,0.007597,0.000000
120.410004,-0.114319,-82.022873,-0.001043,0.000312,0.007926,-0.508516,-0.025905,0.079264,-82.022873,0.007094,0.000000
120.710007,-0.110222,-82.067352,-0.001056,0.000295,0.007493,-0.490291,-0.024977,0.074928,-82.067352,0.006591,0.000000
121.010002,-0.118790,-82.067352,-0.001069,0.000271,0.006877,-0.528403,-0.026918,0.068771,-82.067352,0.006097,0.000000
121.310005,-0.095703,-82.022873,-0.001099,0.000256,0.006504,-0.425709,-0.021687,0.065042,-82.022873,0.005594,0.000000
121.610008,-0.110222,-82.111839,-0.001125,0.000237,0.006010,-0.490291,-0.024977,0.060099,-82.111839,0.005091,0.000000
121.910004,-0.126610,-82.067352,-0.001130,0.000222,0.005628,-0.563189,-0.028690,0.056283,-82.067352,0.004596,0.000000
122.210007,-0.095703,-82.067352,-0.001168,0.000195,0.004952,-0.425709,-0.021687,0.049519,-82.067352,0.004093,0.000000
122.510002,-0.102402,-82.111839,-0.001186,0.000176,0.004466,-0.455506,-0.023205,0.044662,-82.111839,0.003590,0.000000
122.810005,-0.074104,-82.111839,-0.001199,0.000156,0.003972,-0.329632,-0.016792,0.039719,-82.111839,0.003096,0.000000
123.110008,-0.075218,-82.111839,-0.001224,0.000138,0.003495,-0.334587,-0.017045,0.034949,-82.111839,0.002593,0.000000
123.410004,-0.081551,-82.111839,-0.001237,0.000117,0.002966,-0.362755,-0.018480,0.029659,-82.111839,0.002090,0.000000
123.710007,-0.081551,-82.067352,-0.001259,0.000098,0.002489,-0.362755,-0.018480,0.024889,-82.067352,0.001596,0.000000
124.010002,-0.093842,-82.156319,-0.001281,0.000083,0.002099,-0.417428,-0.021265,0.020987,-82.156319,0.001093,0.000000
124.310005,-0.106125,-82.156319,-0.001315,0.000056,0.001414,-0.472067,-0.024048,0.014136,-82.156319,0.000590,0.000000
124.610008,-0.083412,-82.111839,-0.001306,0.000039,0.000980,-0.371036,-0.018901,0.009800,-82.111839,0.000095,0.000000
124.910004,-0.046173,-82.156319,-0.001358,0.000020,0.000520,-0.205388,-0.010463,0.005203,-82.156319,-0.000408,0.000000
125.210007,-0.061073,-82.156319,-0.001371,0.000001,0.000035,-0.271668,-0.013839,0.000347,-82.156319,-0.000911,0.000000
125.400009,-0.093094,-82.111839,-0.001358,0.000003,0.000087,-0.414102,-0.021095,0.000867,-82.111839,-0.000000,0.000000