File: Data/AD Peeled Punched/AD Peeled Punched with creep_100bar_1_08142024_211902.csv
Time (sec),S:Load (lbs),S:HL1 (DIM),S:LVDT (in),S:Position (in),Ch:Position (mm),Ch:Load (N),Ch:Stress (MPa),Ch:Strain (mm/mm),Ch:HL1 (DIM),Set Point (),Cycles ()
0.110000,0.010056,-253.897263,-0.007778,-0.005647,-0.143430,0.044729,0.002279,-1.434304,-253.897263,-0.143430,0.000000
0.410000,-0.016754,-253.897263,-0.007787,-0.005614,-0.142607,-0.074526,-0.003797,-1.426066,-253.897263,-0.142112,0.000000
0.710000,-0.019363,-253.986237,-0.007748,-0.005454,-0.138531,-0.086133,-0.004388,-1.385306,-253.986237,-0.137117,0.000000
1.010000,-0.015640,-253.941757,-0.007524,-0.005247,-0.133275,-0.069571,-0.003544,-1.332752,-253.941757,-0.132122,0.000000
1.310000,0.019363,-253.986237,-0.007325,-0.005054,-0.128384,0.086133,0.004388,-1.283841,-253.986237,-0.127109,0.000000
1.610000,0.000374,-254.030716,-0.007114,-0.004852,-0.123233,0.001663,0.000085,-1.232328,-254.030716,-0.122114,0.000000
1.910000,0.047295,-254.075195,-0.006911,-0.004661,-0.118394,0.210377,0.010717,-1.183937,-254.075195,-0.117119,0.000000
2.210000,0.021973,-254.030716,-0.006722,-0.004457,-0.113208,0.097739,0.004979,-1.132076,-254.030716,-0.112124,0.000000
2.510000,0.000748,-254.075195,-0.006510,-0.004269,-0.108438,0.003326,0.000169,-1.084379,-254.075195,-0.107128,0.000000
2.810000,-0.016014,-254.075195,-0.006303,-0.004069,-0.103356,-0.071234,-0.003629,-1.033560,-254.075195,-0.102133,0.000000
3.110000,-0.020111,-254.208633,-0.006118,-0.003876,-0.098447,-0.089459,-0.004557,-0.984474,-254.208633,-0.097121,0.000000
3.410000,-0.007446,-254.253113,-0.005894,-0.003673,-0.093287,-0.033123,-0.001687,-0.932875,-254.253113,-0.092125,0.000000
3.710000,0.029045,-254.297592,-0.005700,-0.003474,-0.088249,0.129199,0.006582,-0.882489,-254.297592,-0.087130,0.000000
4.010000,0.020851,-254.208633,-0.005501,-0.003277,-0.083245,0.092750,0.004725,-0.832450,-254.208633,-0.082135,0.000000
4.310000,0.029045,-254.208633,-0.005286,-0.003087,-0.078397,0.129199,0.006582,-0.783972,-254.208633,-0.077140,0.000000
4.610000,-0.007820,-254.342072,-0.005092,-0.002894,-0.073506,-0.034786,-0.001772,-0.735060,-254.342072,-0.072144,0.000000
4.910000,-0.024574,-254.386566,-0.004902,-0.002691,-0.068355,-0.109312,-0.005569,-0.683547,-254.386566,-0.067149,0.000000
5.210000,0.022339,-254.431046,-0.004682,-0.002496,-0.063403,0.099368,0.005062,-0.634029,-254.431046,-0.062137,0.000000
5.510000,-0.028297,-254.386566,-0.004484,-0.002295,-0.058295,-0.125873,-0.006412,-0.582949,-254.386566,-0.057141,0.000000
5.810000,0.041702,-254.431046,-0.004299,-0.002101,-0.053378,0.185501,0.009450,-0.533777,-254.431046,-0.052146,0.000000
6.110000,0.021225,-254.431046,-0.004083,-0.001899,-0.048235,0.094413,0.004810,-0.482351,-254.431046,-0.047151,0.000000
6.410000,0.045425,-254.475525,-0.003880,-0.001706,-0.043335,0.202062,0.010294,-0.433353,-254.475525,-0.042156,0.000000
6.710001,0.032394,-254.520004,-0.003691,-0.001509,-0.038340,0.144098,0.007341,-0.383400,-254.520004,-0.037161,0.000000
7.010000,0.030907,-254.564484,-0.003484,-0.001313,-0.033354,0.137480,0.007004,-0.333535,-254.564484,-0.032148,0.000000
7.310000,0.023087,-254.564484,-0.003281,-0.001118,-0.028393,0.102694,0.005231,-0.283930,-254.564484,-0.027153,0.000000
7.610000,-0.018616,-254.608963,-0.003065,-0.000914,-0.023207,-0.082807,-0.004218,-0.232070,-254.608963,-0.022158,0.000000
7.910000,0.076706,-254.697922,-0.002867,-0.000722,-0.018342,0.341205,0.017382,-0.183418,-254.697922,-0.017162,0.000000
8.210000,0.032768,-254.697922,-0.002686,-0.000521,-0.013243,0.145760,0.007425,-0.132425,-254.697922,-0.012167,0.000000
8.510000,0.084526,-254.786880,-0.002483,-0.000334,-0.008481,0.375991,0.019154,-0.084815,-254.786880,-0.007172,0.000000
8.810000,0.071121,-254.697922,-0.002289,-0.000132,-0.003347,0.316363,0.016116,-0.033475,-254.697922,-0.002159,0.000000
9.110001,0.126976,-254.742401,-0.002121,-0.000000,-0.000000,0.564817,0.028773,-0.000000,-254.742401,0.000251,0.000000
9.410001,0.111336,-254.831375,-0.002121,-0.000000,-0.000000,0.495246,0.025229,-0.000000,-254.831375,0.000251,0.000000
9.710000,0.145973,-254.875854,-0.002100,-0.000000,-0.000000,0.649321,0.033078,-0.000000,-254.875854,0.000451,0.000000
10.010000,0.113571,-254.875854,-0.002108,0.000000,0.000009,0.505190,0.025736,0.000087,-254.875854,0.000945,0.000000
10.310000,0.098305,-254.920334,-0.002108,0.000000,0.000009,0.437281,0.022276,0.000087,-254.920334,0.001448,0.000000
10.610001,0.125862,-254.875854,-0.002091,0.000036,0.000919,0.559863,0.028521,0.009193,-254.875854,0.001951,0.000000
10.910001,0.118790,-255.009293,-0.002057,0.000054,0.001379,0.528403,0.026918,0.013789,-255.009293,0.002446,0.000000
11.210001,0.154907,-255.009293,-0.002061,0.000081,0.002047,0.689062,0.035102,0.020466,-255.009293,0.002949,0.000000
11.510000,0.126236,-255.009293,-0.002026,0.000098,0.002498,0.561526,0.028605,0.024976,-255.009293,0.003452,0.000000
11.810000,0.140015,-255.098251,-0.002022,0.000116,0.002940,0.622816,0.031728,0.029399,-255.098251,0.003946,0.000000
12.110001,0.163475,-255.098251,-0.002005,0.000132,0.003365,0.727173,0.037044,0.033648,-255.098251,0.004449,0.000000
12.410001,0.205551,-255.053772,-0.001975,0.000154,0.003911,0.914337,0.046579,0.039112,-255.053772,0.004943,0.000000
12.710001,0.227890,-255.187210,-0.001970,0.000172,0.004362,1.013705,0.051641,0.043621,-255.187210,0.005446,0.000000
13.010000,0.259544,-255.187210,-0.001944,0.000200,0.005082,1.154511,0.058814,0.050819,-255.187210,0.005949,0.000000
13.310000,0.295288,-255.231705,-0.001914,0.000219,0.005550,1.313507,0.066913,0.055502,-255.231705,0.006443,0.000000
13.610001,0.303108,-255.231705,-0.001910,0.000236,0.006001,1.348293,0.068685,0.060012,-255.231705,0.006946,0.000000
13.910001,0.326195,-255.320663,-0.001880,0.000254,0.006443,1.450987,0.073917,0.064435,-255.320663,0.007449,0.000000
14.210001,0.399185,-255.320663,-0.001858,0.000272,0.006920,1.775664,0.090457,0.069205,-255.320663,0.007944,0.000000
14.510000,0.452057,-255.365143,-0.001837,0.000291,0.007389,2.010849,0.102438,0.073888,-255.365143,0.008447,0.000000
14.810000,0.479240,-255.365143,-0.001811,0.000306,0.007770,2.131768,0.108597,0.077703,-255.365143,0.008950,0.000000
15.110001,0.588348,-255.409622,-0.001781,0.000336,0.008533,2.617104,0.133322,0.085335,-255.409622,0.009444,0.000000
15.410001,0.610321,-255.409622,-0.001781,0.000356,0.009045,2.714844,0.138301,0.090452,-255.409622,0.009947,0.000000
15.710001,0.654633,-255.498581,-0.001768,0.000371,0.009435,2.911951,0.148342,0.094354,-255.498581,0.010450,0.000000
16.010000,0.764107,-255.498581,-0.001738,0.000389,0.009878,3.398916,0.173149,0.098777,-255.498581,0.010944,0.000000
16.310001,0.833000,-255.543060,-0.001716,0.000409,0.010389,3.705370,0.188761,0.103894,-255.543060,0.011447,0.000000
16.610001,1.017693,-255.543060,-0.001712,0.000433,0.010988,4.526923,0.230612,0.109877,-255.543060,0.011950,0.000000
16.910002,1.180046,-255.587540,-0.001673,0.000456,0.011577,5.249107,0.267402,0.115775,-255.587540,0.012445,0.000000
17.210001,1.261971,-255.632019,-0.001664,0.000477,0.012106,5.613525,0.285967,0.121065,-255.632019,0.012948,0.000000
17.510000,1.383362,-255.632019,-0.001638,0.000493,0.012523,6.153501,0.313474,0.125227,-255.632019,0.013451,0.000000
17.810001,1.614235,-255.720993,-0.001643,0.000515,0.013086,7.180476,0.365791,0.130864,-255.720993,0.013945,0.000000
18.110001,1.747169,-255.720993,-0.001621,0.000531,0.013494,7.771798,0.395914,0.134940,-255.720993,0.014448,0.000000
18.410002,1.992561,-255.720993,-0.001587,0.000550,0.013962,8.863356,0.451521,0.139623,-255.720993,0.014951,0.000000
18.710001,2.249878,-255.765472,-0.001565,0.000574,0.014578,10.007957,0.509830,0.145781,-255.765472,0.015445,0.000000
19.010000,2.243172,-255.809952,-0.001569,0.000581,0.014760,9.978126,0.508310,0.147602,-255.809952,0.015948,0.000000
19.310001,2.674377,-255.898911,-0.001535,0.000614,0.015584,11.896225,0.606023,0.155840,-255.898911,0.016451,0.000000
19.610001,2.851997,-255.854431,-0.001513,0.000630,0.015992,12.686318,0.646272,0.159916,-255.854431,0.016946,0.000000
19.910002,3.352097,-255.854431,-0.001505,0.000653,0.016581,14.910871,0.759596,0.165814,-255.854431,0.017449,0.000000
20.210001,3.607170,-255.943390,-0.001479,0.000669,0.016998,16.045494,0.817396,0.169976,-255.943390,0.017952,0.000000
20.510000,3.881607,-255.987869,-0.001470,0.000687,0.017457,17.266251,0.879585,0.174572,-255.987869,0.018446,0.000000
20.810001,4.347076,-255.987869,-0.001453,0.000711,0.018047,19.336761,0.985062,0.180470,-255.987869,0.018949,0.000000
21.110001,4.796158,-256.076843,-0.001427,0.000732,0.018593,21.334375,1.086825,0.185933,-256.076843,0.019452,0.000000
21.410002,5.157730,-256.076843,-0.001406,0.000750,0.019044,22.942730,1.168758,0.190443,-256.076843,0.019946,0.000000
21.710001,5.655594,-256.076843,-0.001401,0.000770,0.019547,25.157337,1.281576,0.195473,-256.076843,0.020449,0.000000
22.010000,6.091270,-256.076843,-0.001371,0.000787,0.019990,27.095324,1.380302,0.199896,-256.076843,0.020952,0.000000
22.310001,6.588387,-256.210266,-0.001375,0.000805,0.020458,29.306606,1.492950,0.204578,-256.210266,0.021446,0.000000
22.610001,7.424736,-256.210266,-0.001345,0.000831,0.021117,33.026875,1.682469,0.211169,-256.210266,0.021949,0.000000
22.910002,7.815353,-256.210266,-0.001328,0.000850,0.021585,34.764427,1.770984,0.215852,-256.210266,0.022452,0.000000
23.210001,8.372421,-256.254761,-0.001324,0.000869,0.022071,37.242390,1.897218,0.220709,-256.254761,0.022947,0.000000
23.510000,8.999123,-256.299225,-0.001306,0.000887,0.022531,40.030098,2.039230,0.225305,-256.299225,0.023450,0.000000
23.810001,9.608696,-256.299225,-0.001298,0.000908,0.023068,42.741615,2.177362,0.230682,-256.299225,0.023953,0.000000
24.110001,10.088684,-256.388214,-0.001268,0.000922,0.023406,44.876709,2.286128,0.234064,-256.388214,0.024447,0.000000
24.410002,10.637939,-256.343719,-0.001263,0.000937,0.023788,47.319920,2.410592,0.237880,-256.343719,0.024950,0.000000
24.710001,11.872353,-256.388214,-0.001255,0.000967,0.024560,52.810863,2.690314,0.245598,-256.388214,0.025453,0.000000
25.010002,12.574272,-256.388214,-0.001224,0.000988,0.025098,55.933155,2.849371,0.250975,-256.388214,0.025947,0.000000
25.310001,13.071388,-256.477173,-0.001220,0.001003,0.025470,58.144440,2.962019,0.254704,-256.477173,0.026450,0.000000
25.610001,13.969177,-256.477173,-0.001203,0.001026,0.026051,62.138004,3.165461,0.260515,-256.477173,0.026945,0.000000
25.910002,14.676315,-256.521637,-0.001186,0.001041,0.026442,65.283508,3.325701,0.264417,-256.521637,0.027448,0.000000
26.210001,15.382332,-256.566132,-0.001181,0.001059,0.026910,68.424026,3.485686,0.269100,-256.566132,0.027951,0.000000
26.510002,16.335983,-256.610596,-0.001173,0.001080,0.027422,72.666084,3.701787,0.274217,-256.610596,0.028445,0.000000
26.810001,17.086311,-256.566132,-0.001138,0.001100,0.027951,76.003708,3.871814,0.279507,-256.566132,0.028948,0.000000
27.110001,18.039955,-256.610596,-0.001134,0.001121,0.028480,80.245728,4.087913,0.284797,-256.610596,0.029451,0.000000
27.410002,19.076271,-256.655090,-0.001121,0.001147,0.029121,84.855492,4.322745,0.291214,-256.655090,0.029945,0.000000
27.710001,19.766273,-256.699554,-0.001108,0.001163,0.029538,87.924774,4.479102,0.295377,-256.699554,0.030448,0.000000
28.010002,20.026566,-256.744049,-0.001112,0.001175,0.029841,89.082611,4.538085,0.298412,-256.744049,0.030951,0.000000
28.310001,21.716019,-256.744049,-0.001078,0.001204,0.030587,96.597679,4.920920,0.305871,-256.744049,0.031446,0.000000
28.610001,22.588860,-256.833008,-0.001074,0.001223,0.031055,100.480263,5.118709,0.310553,-256.833008,0.031949,0.000000
28.910002,23.328392,-256.788544,-0.001048,0.001242,0.031558,103.769867,5.286289,0.315583,-256.788544,0.032452,0.000000
29.210001,24.063828,-256.833008,-0.001039,0.001259,0.031975,107.041252,5.452941,0.319746,-256.833008,0.032946,0.000000
29.510002,25.228233,-256.877502,-0.001018,0.001279,0.032486,112.220787,5.716799,0.324863,-256.877502,0.033449,0.000000
29.810001,25.695930,-256.921967,-0.001026,0.001293,0.032842,114.301208,5.822781,0.328418,-256.921967,0.033952,0.000000
30.110001,26.899445,-256.833008,-0.001000,0.001313,0.033345,119.654709,6.095501,0.333448,-256.833008,0.034446,0.000000
30.410002,28.402710,-256.966461,-0.000992,0.001339,0.034013,126.341560,6.436146,0.340126,-256.966461,0.034949,0.000000
30.710001,29.277786,-257.010925,-0.000979,0.001359,0.034507,130.234100,6.634441,0.345069,-257.010925,0.035452,0.000000
31.010002,30.124557,-257.055420,-0.000949,0.001378,0.035001,134.000717,6.826322,0.350012,-257.055420,0.035946,0.000000
31.310001,30.496933,-257.010925,-0.000944,0.001391,0.035331,135.657135,6.910704,0.353308,-257.010925,0.036449,0.000000
31.610001,31.549255,-257.099884,-0.000944,0.001409,0.035782,140.338104,7.149164,0.357817,-257.099884,0.036952,0.000000
31.910002,33.099068,-257.055420,-0.000949,0.001433,0.036397,147.232010,7.500356,0.363975,-257.055420,0.037447,0.000000
32.210003,34.130173,-257.144379,-0.000914,0.001452,0.036892,151.818588,7.734007,0.368918,-257.144379,0.037950,0.000000
32.510002,35.664719,-257.188873,-0.000905,0.001477,0.037525,158.644592,8.081741,0.375248,-257.188873,0.038453,0.000000
32.810001,36.478348,-257.188873,-0.000884,0.001494,0.037958,162.263794,8.266111,0.379585,-257.188873,0.038947,0.000000
33.110001,37.411514,-257.233337,-0.000888,0.001513,0.038427,166.414734,8.477571,0.384268,-257.233337,0.039450,0.000000
33.410000,38.115669,-257.277832,-0.000884,0.001527,0.038782,169.546967,8.637135,0.387823,-257.277832,0.039953,0.000000
33.710003,39.680756,-257.322296,-0.000867,0.001551,0.039407,176.508820,8.991788,0.394067,-257.322296,0.040447,0.000000
34.010002,40.902512,-257.322296,-0.000849,0.001569,0.039858,181.943451,9.268641,0.398577,-257.322296,0.040950,0.000000
34.310001,42.355133,-257.322296,-0.000849,0.001594,0.040499,188.405045,9.597810,0.404994,-257.322296,0.041453,0.000000
34.610001,43.901596,-257.411255,-0.000823,0.001616,0.041046,195.284058,9.948244,0.410458,-257.411255,0.041948,0.000000
34.910000,43.699028,-257.411255,-0.000815,0.001614,0.041002,194.382980,9.902341,0.410024,-257.411255,0.007219,0.000000
35.210003,43.095039,-257.500214,-0.000815,0.001615,0.041011,191.696304,9.765476,0.410111,-257.500214,195.999619,0.000000
35.510002,43.820793,-257.411255,-0.000806,0.001417,0.035990,194.924622,9.929934,0.359899,-257.411255,195.999619,0.000000
35.810001,43.458473,-257.500214,-0.000802,0.001514,0.038453,193.312943,9.847831,0.384528,-257.500214,195.999619,0.000000
36.110001,43.540024,-257.544708,-0.000793,0.001624,0.041245,193.675705,9.866311,0.412452,-257.544708,195.999619,0.000000
36.410000,43.459961,-257.589172,-0.000806,0.001629,0.041375,193.319565,9.848167,0.413753,-257.589172,195.999619,0.000000
36.710003,43.486397,-257.589172,-0.000798,0.001632,0.041445,193.437149,9.854158,0.414447,-257.589172,195.999619,0.000000
37.010002,43.465546,-257.633667,-0.000798,0.001633,0.041488,193.344406,9.849433,0.414881,-257.633667,195.999619,0.000000
37.310001,43.440971,-257.678162,-0.000802,0.001635,0.041523,193.235092,9.843865,0.415228,-257.678162,195.999619,0.000000
37.610001,43.468155,-257.722626,-0.000798,0.001639,0.041618,193.356003,9.850025,0.416182,-257.722626,195.999619,0.000000
37.910004,43.553802,-257.722626,-0.000806,0.001639,0.041618,193.736984,9.869432,0.416182,-257.722626,195.999619,0.000000
38.210003,43.463684,-257.722626,-0.000798,0.001639,0.041618,193.336121,9.849011,0.416182,-257.722626,195.999619,0.000000
38.510002,43.387352,-257.811584,-0.000806,0.001639,0.041627,192.996582,9.831715,0.416268,-257.811584,195.999619,0.000000
38.810001,43.537415,-257.767120,-0.000793,0.001642,0.041714,193.664093,9.865719,0.417136,-257.767120,195.999619,0.000000
39.110001,43.495338,-257.856079,-0.000780,0.001642,0.041714,193.476929,9.856185,0.417136,-257.856079,195.999619,0.000000
39.410004,43.449165,-257.811584,-0.000802,0.001642,0.041714,193.271545,9.845721,0.417136,-257.811584,195.999619,0.000000
39.710003,43.397400,-257.900543,-0.000793,0.001643,0.041722,193.041275,9.833992,0.417222,-257.900543,195.999619,0.000000
40.010002,43.349739,-257.945038,-0.000789,0.001643,0.041731,192.829269,9.823191,0.417309,-257.945038,195.999619,0.000000
40.310001,43.634605,-257.989502,-0.000798,0.001647,0.041835,194.096420,9.887743,0.418350,-257.989502,195.999619,0.000000
40.610001,43.617477,-257.989502,-0.000793,0.001647,0.041835,194.020233,9.883862,0.418350,-257.989502,195.999619,0.000000
40.910004,43.568695,-258.033997,-0.000789,0.001647,0.041835,193.803238,9.872808,0.418350,-258.033997,195.999619,0.000000
41.210003,43.509491,-258.078491,-0.000785,0.001647,0.041835,193.539886,9.859392,0.418350,-258.078491,195.999619,0.000000
41.510002,43.461082,-258.078491,-0.000776,0.001647,0.041835,193.324554,9.848422,0.418350,-258.078491,195.999619,0.000000
41.810001,43.445068,-258.078491,-0.000798,0.001647,0.041835,193.253311,9.844793,0.418350,-258.078491,195.999619,0.000000
42.110001,43.389587,-258.078491,-0.000780,0.001647,0.041835,193.006531,9.832221,0.418350,-258.078491,195.999619,0.000000
42.410004,43.635719,-258.167450,-0.000776,0.001653,0.041974,194.101379,9.887996,0.419737,-258.167450,195.999619,0.000000
42.710003,43.692322,-258.211914,-0.000798,0.001652,0.041965,194.353149,9.900822,0.419650,-258.211914,195.999619,0.000000
43.010002,43.689346,-258.211914,-0.000785,0.001652,0.041965,194.339920,9.900147,0.419650,-258.211914,195.999619,0.000000
43.310001,43.648758,-258.300873,-0.000780,0.001652,0.041965,194.159378,9.890950,0.419650,-258.300873,195.999619,0.000000
43.610001,43.647636,-258.300873,-0.000776,0.001652,0.041965,194.154388,9.890697,0.419650,-258.300873,195.999619,0.000000
43.910004,43.618591,-258.300873,-0.000780,0.001652,0.041965,194.025177,9.884114,0.419650,-258.300873,195.999619,0.000000
44.210003,43.570183,-258.389832,-0.000789,0.001652,0.041965,193.809860,9.873145,0.419650,-258.389832,195.999619,0.000000
44.510002,43.537041,-258.345367,-0.000798,0.001652,0.041965,193.662430,9.865634,0.419650,-258.345367,195.999619,0.000000
44.810001,43.497200,-258.434326,-0.000806,0.001652,0.041965,193.485214,9.856606,0.419650,-258.434326,195.999619,0.000000
45.110001,43.458473,-258.478821,-0.000776,0.001653,0.041974,193.312943,9.847831,0.419737,-258.478821,195.999619,0.000000
45.410004,43.434639,-258.478821,-0.000785,0.001653,0.041974,193.206924,9.842430,0.419737,-258.478821,195.999619,0.000000
45.710003,43.414162,-258.478821,-0.000785,0.001655,0.042026,193.115829,9.837790,0.420258,-258.478821,195.999619,0.000000
46.010002,43.465172,-258.567780,-0.000789,0.001655,0.042026,193.342743,9.849349,0.420258,-258.567780,195.999619,0.000000
46.310001,43.471130,-258.523285,-0.000780,0.001655,0.042026,193.369247,9.850698,0.420258,-258.523285,195.999619,0.000000
46.610001,43.444321,-258.612244,-0.000785,0.001655,0.042026,193.249985,9.844625,0.420258,-258.612244,195.999619,0.000000
46.910004,43.449165,-258.612244,-0.000785,0.001655,0.042026,193.271545,9.845721,0.420258,-258.612244,195.999619,0.000000
47.210003,43.423096,-258.612244,-0.000785,0.001655,0.042026,193.155579,9.839814,0.420258,-258.612244,195.999619,0.000000
47.510002,43.561623,-258.701202,-0.000767,0.001660,0.042156,193.771774,9.871204,0.421558,-258.701202,195.999619,0.000000
47.810001,43.771263,-258.656738,-0.000776,0.001659,0.042147,194.704300,9.918711,0.421472,-258.656738,195.999619,0.000000
48.110001,43.766052,-258.790161,-0.000772,0.001659,0.042147,194.681122,9.917529,0.421472,-258.790161,195.999619,0.000000
48.410004,43.763817,-258.745697,-0.000785,0.001659,0.042147,194.671173,9.917023,0.421472,-258.745697,195.999619,0.000000
48.710003,43.763817,-258.790161,-0.000772,0.001659,0.042147,194.671173,9.917023,0.421472,-258.790161,195.999619,0.000000
49.010002,43.748924,-258.834656,-0.000793,0.001659,0.042147,194.604935,9.913649,0.421472,-258.834656,195.999619,0.000000
49.310001,43.701256,-258.879150,-0.000780,0.001659,0.042147,194.392899,9.902846,0.421472,-258.879150,195.999619,0.000000
49.610001,43.685623,-258.923615,-0.000780,0.001659,0.042147,194.323364,9.899303,0.421472,-258.923615,195.999619,0.000000
49.910004,43.657318,-258.879150,-0.000780,0.001659,0.042147,194.197449,9.892890,0.421472,-258.879150,195.999619,0.000000
50.210003,43.652847,-258.968109,-0.000785,0.001659,0.042147,194.177567,9.891876,0.421472,-258.968109,195.999619,0.000000
50.510002,43.636841,-259.012573,-0.000780,0.001659,0.042147,194.106369,9.888249,0.421472,-259.012573,195.999619,0.000000
50.810001,43.624550,-259.012573,-0.000772,0.001659,0.042147,194.051697,9.885465,0.421472,-259.012573,195.999619,0.000000
51.110001,43.608910,-259.057068,-0.000776,0.001659,0.042147,193.982117,9.881920,0.421472,-259.057068,195.999619,0.000000
51.410004,43.583588,-259.101532,-0.000767,0.001660,0.042156,193.869476,9.876183,0.421558,-259.101532,195.999619,0.000000
51.710003,43.578751,-259.146027,-0.000776,0.001660,0.042156,193.847961,9.875086,0.421558,-259.146027,195.999619,0.000000
52.010002,43.535553,-259.146027,-0.000772,0.001660,0.042156,193.655807,9.865297,0.421558,-259.146027,195.999619,0.000000
52.310001,43.535553,-259.101532,-0.000793,0.001660,0.042165,193.655807,9.865297,0.421645,-259.101532,195.999619,0.000000
52.610001,43.502411,-259.234985,-0.000776,0.001660,0.042165,193.508392,9.857787,0.421645,-259.234985,195.999619,0.000000
52.910004,43.487144,-259.234985,-0.000772,0.001660,0.042165,193.440475,9.854328,0.421645,-259.234985,195.999619,0.000000
53.210003,43.478584,-259.323944,-0.000776,0.001660,0.042173,193.402405,9.852388,0.421732,-259.323944,195.999619,0.000000
53.510002,43.464058,-259.323944,-0.000767,0.001660,0.042173,193.337784,9.849096,0.421732,-259.323944,195.999619,0.000000
53.810001,43.457359,-259.323944,-0.000776,0.001660,0.042173,193.307983,9.847578,0.421732,-259.323944,195.999619,0.000000
54.110004,43.433899,-259.368439,-0.000776,0.001661,0.042182,193.203629,9.842262,0.421819,-259.368439,195.999619,0.000000
54.410004,43.443947,-259.457397,-0.000772,0.001661,0.042182,193.248322,9.844539,0.421819,-259.457397,195.999619,0.000000
54.710003,43.442833,-259.412903,-0.000785,0.001661,0.042182,193.243378,9.844286,0.421819,-259.412903,195.999619,0.000000
55.010002,43.428314,-259.457397,-0.000780,0.001661,0.042182,193.178787,9.840997,0.421819,-259.457397,195.999619,0.000000
55.310001,43.415649,-259.501862,-0.000780,0.001661,0.042182,193.122452,9.838127,0.421819,-259.501862,195.999619,0.000000
55.610004,43.402245,-259.590820,-0.000776,0.001661,0.042182,193.062820,9.835089,0.421819,-259.590820,195.999619,0.000000
55.910004,43.405220,-259.590820,-0.000780,0.001661,0.042191,193.076065,9.835764,0.421905,-259.590820,195.999619,0.000000
56.210003,43.386230,-259.590820,-0.000789,0.001661,0.042191,192.991592,9.831461,0.421905,-259.590820,195.999619,0.000000
56.510002,43.643166,-259.590820,-0.000767,0.001666,0.042312,194.134491,9.889683,0.423119,-259.590820,195.999619,0.000000
56.810001,43.683388,-259.635315,-0.000776,0.001666,0.042312,194.313416,9.898797,0.423119,-259.635315,195.999619,0.000000
57.110004,43.705727,-259.679779,-0.000767,0.001666,0.042312,194.412781,9.903859,0.423119,-259.679779,195.999619,0.000000
57.410004,43.695671,-259.679779,-0.000772,0.001666,0.042312,194.368057,9.901580,0.423119,-259.679779,195.999619,0.000000
57.710003,43.709450,-259.724274,-0.000763,0.001665,0.042303,194.429337,9.904703,0.423033,-259.724274,195.999619,0.000000
58.010002,43.708336,-259.813232,-0.000776,0.001665,0.042303,194.424393,9.904450,0.423033,-259.813232,195.999619,0.000000
58.310001,43.700516,-259.813232,-0.000772,0.001665,0.042303,194.389603,9.902678,0.423033,-259.813232,195.999619,0.000000
58.610004,43.701256,-259.813232,-0.000780,0.001665,0.042303,194.392899,9.902846,0.423033,-259.813232,195.999619,0.000000
58.910004,43.689346,-259.902191,-0.000763,0.001665,0.042303,194.339920,9.900147,0.423033,-259.902191,195.999619,0.000000
59.210003,43.677429,-259.946686,-0.000755,0.001665,0.042303,194.286911,9.897447,0.423033,-259.946686,195.999619,0.000000
59.510002,43.661041,-259.902191,-0.000767,0.001665,0.042303,194.214005,9.893733,0.423033,-259.902191,195.999619,0.000000
59.810001,43.659554,-259.946686,-0.000776,0.001665,0.042303,194.207397,9.893396,0.423033,-259.946686,195.999619,0.000000
60.110004,43.640564,-259.946686,-0.000780,0.001665,0.042303,194.122925,9.889092,0.423033,-259.946686,195.999619,0.000000
60.410004,43.644287,-260.080109,-0.000767,0.001665,0.042303,194.139481,9.889937,0.423033,-260.080109,195.999619,0.000000
60.710003,43.638329,-260.035645,-0.000772,0.001665,0.042303,194.112976,9.888586,0.423033,-260.035645,195.999619,0.000000
61.010002,43.626038,-260.080109,-0.000785,0.001665,0.042303,194.058304,9.885801,0.423033,-260.080109,195.999619,0.000000
61.310001,43.618965,-260.080109,-0.000759,0.001665,0.042303,194.026840,9.884199,0.423033,-260.080109,195.999619,0.000000
61.610004,43.601089,-260.124603,-0.000776,0.001665,0.042303,193.947327,9.880148,0.423033,-260.124603,195.999619,0.000000
61.910004,43.602211,-260.124603,-0.000772,0.001665,0.042303,193.952316,9.880403,0.423033,-260.124603,195.999619,0.000000
62.210003,43.594391,-260.213562,-0.000776,0.001665,0.042303,193.917542,9.878630,0.423033,-260.213562,195.999619,0.000000
62.510002,43.569809,-260.213562,-0.000776,0.001665,0.042303,193.808197,9.873059,0.423033,-260.213562,195.999619,0.000000
62.810001,43.586571,-260.258057,-0.000767,0.001665,0.042303,193.882751,9.876858,0.423033,-260.258057,195.999619,0.000000
63.110004,43.531456,-260.302521,-0.000767,0.001666,0.042312,193.637589,9.864368,0.423119,-260.302521,195.999619,0.000000
63.410004,43.518425,-260.302521,-0.000776,0.001666,0.042312,193.579620,9.861417,0.423119,-260.302521,195.999619,0.000000
63.710003,43.503532,-260.391479,-0.000776,0.001666,0.042312,193.513382,9.858041,0.423119,-260.391479,195.999619,0.000000
64.010002,43.491615,-260.391479,-0.000780,0.001666,0.042312,193.460373,9.855341,0.423119,-260.391479,195.999619,0.000000
64.310005,43.504272,-260.391479,-0.000763,0.001666,0.042312,193.516663,9.858209,0.423119,-260.391479,195.999619,0.000000
64.610001,43.470016,-260.435974,-0.000763,0.001666,0.042312,193.364288,9.850446,0.423119,-260.435974,195.999619,0.000000
64.910004,43.471504,-260.435974,-0.000785,0.001666,0.042312,193.370911,9.850784,0.423119,-260.435974,195.999619,0.000000
65.210007,43.452888,-260.524933,-0.000780,0.001666,0.042321,193.288101,9.846565,0.423206,-260.524933,195.999619,0.000000
65.510002,43.452888,-260.569397,-0.000767,0.001667,0.042347,193.288101,9.846565,0.423466,-260.569397,195.999619,0.000000
65.810005,43.466293,-260.524933,-0.000767,0.001667,0.042347,193.347733,9.849603,0.423466,-260.524933,195.999619,0.000000
66.110001,43.472992,-260.569397,-0.000767,0.001667,0.042347,193.377533,9.851121,0.423466,-260.569397,195.999619,0.000000
66.410004,43.473366,-260.613892,-0.000767,0.001667,0.042347,193.379196,9.851205,0.423466,-260.613892,195.999619,0.000000
66.710007,43.478584,-260.569397,-0.000772,0.001667,0.042347,193.402405,9.852388,0.423466,-260.569397,195.999619,0.000000
67.010002,43.463310,-260.658386,-0.000780,0.001667,0.042347,193.334457,9.848927,0.423466,-260.658386,195.999619,0.000000
67.310005,43.466293,-260.702850,-0.000763,0.001667,0.042347,193.347733,9.849603,0.423466,-260.702850,195.999619,0.000000
67.610001,43.457359,-260.702850,-0.000776,0.001667,0.042347,193.307983,9.847578,0.423466,-260.702850,195.999619,0.000000
67.910004,43.453262,-260.747345,-0.000767,0.001667,0.042347,193.289764,9.846650,0.423466,-260.747345,195.999619,0.000000
68.210007,43.455490,-260.747345,-0.000763,0.001667,0.042347,193.299667,9.847156,0.423466,-260.747345,195.999619,0.000000
68.510002,43.435013,-260.747345,-0.000763,0.001667,0.042347,193.208588,9.842514,0.423466,-260.747345,195.999619,0.000000
68.810005,43.424217,-260.791809,-0.000785,0.001667,0.042347,193.160568,9.840069,0.423466,-260.791809,195.999619,0.000000
69.110001,43.432777,-260.836304,-0.000763,0.001667,0.042347,193.198639,9.842008,0.423466,-260.836304,195.999619,0.000000
69.410004,43.418633,-260.880768,-0.000759,0.001667,0.042347,193.135727,9.838803,0.423466,-260.880768,195.999619,0.000000
69.710007,43.429054,-260.880768,-0.000759,0.001669,0.042390,193.182083,9.841165,0.423900,-260.880768,195.999619,0.000000
70.010002,43.439110,-260.925262,-0.000755,0.001669,0.042390,193.226807,9.843443,0.423900,-260.925262,195.999619,0.000000
70.310005,43.454376,-261.014221,-0.000763,0.001669,0.042390,193.294724,9.846903,0.423900,-261.014221,195.999619,0.000000
70.610001,43.452141,-261.014221,-0.000759,0.001669,0.042390,193.284775,9.846396,0.423900,-261.014221,195.999619,0.000000
70.910004,43.448044,-261.058716,-0.000767,0.001669,0.042390,193.266556,9.845468,0.423900,-261.058716,195.999619,0.000000
71.210007,43.451401,-261.014221,-0.000759,0.001669,0.042390,193.281479,9.846229,0.423900,-261.014221,195.999619,0.000000
71.510002,43.441719,-261.103180,-0.000767,0.001669,0.042390,193.238419,9.844034,0.423900,-261.103180,195.999619,0.000000
71.810005,43.450279,-261.103180,-0.000763,0.001669,0.042390,193.276489,9.845974,0.423900,-261.103180,195.999619,0.000000
72.110001,43.441719,-261.147675,-0.000759,0.001669,0.042390,193.238419,9.844034,0.423900,-261.147675,195.999619,0.000000
72.410004,43.417885,-261.192139,-0.000759,0.001669,0.042390,193.132401,9.838634,0.423900,-261.192139,195.999619,0.000000
72.710007,43.440598,-261.192139,-0.000755,0.001669,0.042390,193.233429,9.843780,0.423900,-261.192139,195.999619,0.000000
73.010002,43.435760,-261.236633,-0.000759,0.001669,0.042390,193.211914,9.842684,0.423900,-261.236633,195.999619,0.000000
73.310005,43.416397,-261.192139,-0.000772,0.001669,0.042390,193.125778,9.838297,0.423900,-261.192139,195.999619,0.000000
73.610001,43.407829,-261.236633,-0.000746,0.001669,0.042390,193.087662,9.836354,0.423900,-261.236633,195.999619,0.000000
73.910004,43.423843,-261.281097,-0.000746,0.001670,0.042407,193.158905,9.839983,0.424073,-261.281097,195.999619,0.000000
74.210007,43.435760,-261.370056,-0.000755,0.001670,0.042407,193.211914,9.842684,0.424073,-261.370056,195.999619,0.000000
74.510002,43.423096,-261.325592,-0.000767,0.001670,0.042407,193.155579,9.839814,0.424073,-261.325592,195.999619,0.000000
74.810005,43.421234,-261.370056,-0.000759,0.001670,0.042407,193.147293,9.839393,0.424073,-261.370056,195.999619,0.000000
75.110001,43.421608,-261.414551,-0.000772,0.001670,0.042407,193.148956,9.839477,0.424073,-261.414551,195.999619,0.000000
75.410004,43.432404,-261.459045,-0.000750,0.001670,0.042407,193.196976,9.841924,0.424073,-261.459045,195.999619,0.000000
75.710007,43.435013,-261.459045,-0.000755,0.001670,0.042407,193.208588,9.842514,0.424073,-261.459045,195.999619,0.000000
76.010002,43.432777,-261.459045,-0.000767,0.001670,0.042407,193.198639,9.842008,0.424073,-261.459045,195.999619,0.000000
76.310005,43.411926,-261.548004,-0.000772,0.001670,0.042407,193.105896,9.837283,0.424073,-261.548004,195.999619,0.000000
76.610001,43.400383,-261.592468,-0.000772,0.001670,0.042407,193.054550,9.834667,0.424073,-261.592468,195.999619,0.000000
76.910004,43.403358,-261.592468,-0.000763,0.001670,0.042407,193.067780,9.835341,0.424073,-261.592468,195.999619,0.000000
77.210007,43.407082,-261.592468,-0.000776,0.001670,0.042416,193.084335,9.836185,0.424160,-261.592468,195.999619,0.000000
77.510002,43.398521,-261.681427,-0.000759,0.001670,0.042416,193.046265,9.834246,0.424160,-261.681427,195.999619,0.000000
77.810005,43.383995,-261.725922,-0.000767,0.001670,0.042425,192.981644,9.830954,0.424247,-261.725922,195.999619,0.000000
78.110001,43.378784,-261.636963,-0.000759,0.001670,0.042425,192.958466,9.829773,0.424247,-261.636963,195.999619,0.000000
78.410004,43.381393,-261.770386,-0.000755,0.001670,0.042425,192.970078,9.830364,0.424247,-261.770386,195.999619,0.000000
78.710007,43.382507,-261.725922,-0.000759,0.001670,0.042425,192.975037,9.830617,0.424247,-261.725922,195.999619,0.000000
79.010002,43.381393,-261.725922,-0.000767,0.001670,0.042425,192.970078,9.830364,0.424247,-261.725922,195.999619,0.000000
79.310005,43.375435,-261.770386,-0.000759,0.001670,0.042425,192.943573,9.829014,0.424247,-261.770386,195.999619,0.000000
79.610001,43.381020,-261.770386,-0.000767,0.001670,0.042425,192.968414,9.830279,0.424247,-261.770386,195.999619,0.000000
79.910004,43.361656,-261.814880,-0.000767,0.001670,0.042425,192.882278,9.825891,0.424247,-261.814880,195.999619,0.000000
80.210007,43.349739,-261.948334,-0.000763,0.001670,0.042425,192.829269,9.823191,0.424247,-261.948334,195.999619,0.000000
80.510002,43.338196,-261.948334,-0.000759,0.001670,0.042425,192.777924,9.820576,0.424247,-261.948334,195.999619,0.000000
80.810005,43.331123,-261.903839,-0.000763,0.001670,0.042425,192.746460,9.818973,0.424247,-261.903839,195.999619,0.000000
81.110001,43.367989,-261.948334,-0.000759,0.001671,0.042451,192.910446,9.827327,0.424507,-261.948334,195.999619,0.000000
81.410004,43.381393,-261.948334,-0.000776,0.001671,0.042451,192.970078,9.830364,0.424507,-261.948334,195.999619,0.000000
81.710007,43.366493,-261.992798,-0.000763,0.001671,0.042451,192.903793,9.826987,0.424507,-261.992798,195.999619,0.000000
82.010002,43.364265,-262.037292,-0.000755,0.001671,0.042451,192.893890,9.826483,0.424507,-262.037292,195.999619,0.000000
82.310005,43.370224,-262.081757,-0.000750,0.001671,0.042451,192.920395,9.827833,0.424507,-262.081757,195.999619,0.000000
82.610001,43.373573,-262.126251,-0.000759,0.001671,0.042451,192.935287,9.828592,0.424507,-262.126251,195.999619,0.000000
82.910004,43.382881,-262.170715,-0.000776,0.001671,0.042451,192.976700,9.830702,0.424507,-262.170715,195.999619,0.000000
83.210007,43.372826,-262.126251,-0.000763,0.001671,0.042451,192.931961,9.828423,0.424507,-262.126251,195.999619,0.000000
83.510002,43.362404,-262.215210,-0.000759,0.001671,0.042451,192.885605,9.826061,0.424507,-262.215210,195.999619,0.000000
83.810005,43.354584,-262.259674,-0.000755,0.001671,0.042451,192.850815,9.824289,0.424507,-262.259674,195.999619,0.000000
84.110001,43.353836,-262.259674,-0.000755,0.001671,0.042451,192.847488,9.824120,0.424507,-262.259674,195.999619,0.000000
84.410004,43.336334,-262.259674,-0.000746,0.001671,0.042451,192.769638,9.820153,0.424507,-262.259674,195.999619,0.000000
84.710007,43.333725,-262.348663,-0.000763,0.001671,0.042451,192.758041,9.819562,0.424507,-262.348663,195.999619,0.000000
85.010002,43.345268,-262.348663,-0.000759,0.001671,0.042451,192.809387,9.822178,0.424507,-262.348663,195.999619,0.000000
85.310005,43.338570,-262.348663,-0.000746,0.001671,0.042451,192.779587,9.820660,0.424507,-262.348663,195.999619,0.000000
85.610001,43.322182,-262.393127,-0.000763,0.001671,0.042451,192.706696,9.816947,0.424507,-262.393127,195.999619,0.000000
85.910004,43.309525,-262.437622,-0.000772,0.001671,0.042451,192.650391,9.814079,0.424507,-262.437622,195.999619,0.000000
86.210007,43.302452,-262.482086,-0.000767,0.001671,0.042451,192.618927,9.812475,0.424507,-262.482086,195.999619,0.000000
86.510002,43.316223,-262.482086,-0.000767,0.001671,0.042451,192.680191,9.815597,0.424507,-262.482086,195.999619,0.000000
86.810005,43.297607,-262.482086,-0.000763,0.001671,0.042451,192.597382,9.811378,0.424507,-262.482086,195.999619,0.000000
87.110001,43.308037,-262.526581,-0.000763,0.001671,0.042451,192.643768,9.813741,0.424507,-262.526581,195.999619,0.000000
87.410004,43.290161,-262.571045,-0.000763,0.001671,0.042451,192.564255,9.809690,0.424507,-262.571045,195.999619,0.000000
87.710007,43.287178,-262.615540,-0.000759,0.001671,0.042451,192.550980,9.809015,0.424507,-262.615540,195.999619,0.000000
88.010002,43.287178,-262.615540,-0.000763,0.001671,0.042451,192.550980,9.809015,0.424507,-262.615540,195.999619,0.000000
88.310005,43.278992,-262.704498,-0.000772,0.001671,0.042451,192.514572,9.807159,0.424507,-262.704498,195.999619,0.000000
88.610001,43.277870,-262.704498,-0.000750,0.001671,0.042451,192.509583,9.806905,0.424507,-262.704498,195.999619,0.000000
88.910004,43.273033,-262.704498,-0.000759,0.001671,0.042451,192.488068,9.805809,0.424507,-262.704498,195.999619,0.000000
89.210007,43.418633,-262.704498,-0.000759,0.001677,0.042589,193.135727,9.838803,0.425894,-262.704498,195.999619,0.000000
89.510002,43.541138,-262.837952,-0.000742,0.001675,0.042546,193.680649,9.866563,0.425461,-262.837952,195.999619,0.000000
89.810005,43.572418,-262.793457,-0.000763,0.001675,0.042546,193.819794,9.873652,0.425461,-262.793457,195.999619,0.000000
90.110001,43.578751,-262.837952,-0.000763,0.001675,0.042546,193.847961,9.875086,0.425461,-262.837952,195.999619,0.000000
90.410004,43.577263,-262.837952,-0.000772,0.001675,0.042546,193.841339,9.874749,0.425461,-262.837952,195.999619,0.000000
90.710007,43.576889,-262.926910,-0.000767,0.001675,0.042546,193.839676,9.874664,0.425461,-262.926910,195.999619,0.000000
91.010002,43.580612,-262.971375,-0.000776,0.001675,0.042546,193.856247,9.875508,0.425461,-262.971375,195.999619,0.000000
91.310005,43.568695,-262.971375,-0.000767,0.001675,0.042546,193.803238,9.872808,0.425461,-262.971375,195.999619,0.000000
91.610001,43.576141,-262.926910,-0.000772,0.001675,0.042546,193.836365,9.874495,0.425461,-262.926910,195.999619,0.000000
91.910004,43.571304,-263.015869,-0.000763,0.001675,0.042546,193.814835,9.873399,0.425461,-263.015869,195.999619,0.000000
92.210007,43.585083,-263.104828,-0.000746,0.001675,0.042546,193.876129,9.876521,0.425461,-263.104828,195.999619,0.000000
92.510002,43.565720,-263.015869,-0.000772,0.001675,0.042546,193.789993,9.872133,0.425461,-263.015869,195.999619,0.000000
92.810005,43.578751,-263.149292,-0.000763,0.001675,0.042546,193.847961,9.875086,0.425461,-263.149292,195.999619,0.000000
93.110001,43.578377,-263.149292,-0.000772,0.001675,0.042546,193.846298,9.875001,0.425461,-263.149292,195.999619,0.000000
93.410004,43.576889,-263.149292,-0.000750,0.001675,0.042546,193.839676,9.874664,0.425461,-263.149292,195.999619,0.000000
93.710007,43.561623,-263.238281,-0.000759,0.001675,0.042546,193.771774,9.871204,0.425461,-263.238281,195.999619,0.000000
94.010002,43.570557,-263.282745,-0.000767,0.001675,0.042546,193.811508,9.873229,0.425461,-263.282745,195.999619,0.000000
94.310005,43.575768,-263.327240,-0.000763,0.001675,0.042546,193.834702,9.874411,0.425461,-263.327240,195.999619,0.000000
94.610008,43.556404,-263.282745,-0.000759,0.001675,0.042546,193.748566,9.870022,0.425461,-263.282745,195.999619,0.000000
94.910004,43.557152,-263.371704,-0.000772,0.001675,0.042546,193.751892,9.870192,0.425461,-263.371704,195.999619,0.000000
95.210007,43.554916,-263.416199,-0.000755,0.001675,0.042546,193.741943,9.869685,0.425461,-263.416199,1119.186523,0.000000
95.510002,43.538902,-263.371704,-0.000759,0.001671,0.042451,193.670715,9.866056,0.424507,-263.371704,0.042425,0.000000
95.810005,43.453629,-263.416199,-0.000763,0.001661,0.042191,193.291397,9.846733,0.421905,-263.416199,0.041922,0.000000
96.110008,43.486397,-263.460663,-0.000763,0.001646,0.041818,193.437149,9.854158,0.418176,-263.460663,0.041419,0.000000
96.410004,43.449905,-263.505157,-0.000763,0.001631,0.041419,193.274826,9.845890,0.414187,-263.505157,0.040924,0.000000
96.710007,43.467781,-263.505157,-0.000755,0.001607,0.040829,193.354340,9.849939,0.408290,-263.505157,0.040421,0.000000
97.010002,43.419746,-263.505157,-0.000737,0.001587,0.040300,193.140671,9.839055,0.403000,-263.505157,0.039918,0.000000
97.310005,43.417885,-263.638611,-0.000750,0.001566,0.039788,193.132401,9.838634,0.397883,-263.638611,0.039424,0.000000
97.610008,43.426819,-263.549622,-0.000759,0.001557,0.039537,193.172134,9.840658,0.395368,-263.549622,0.038921,0.000000
97.910004,43.401497,-263.594116,-0.000746,0.001540,0.039112,193.059494,9.834919,0.391119,-263.594116,0.038418,0.000000
98.210007,43.366867,-263.638611,-0.000750,0.001515,0.038470,192.905457,9.827073,0.384701,-263.638611,0.037924,0.000000
98.510002,43.331497,-263.638611,-0.000772,0.001494,0.037950,192.748123,9.819057,0.379498,-263.638611,0.037421,0.000000
98.810005,43.314362,-263.683075,-0.000746,0.001472,0.037386,192.671906,9.815175,0.373861,-263.683075,0.036918,0.000000
99.110008,43.296120,-263.772034,-0.000737,0.001453,0.036918,192.590759,9.811041,0.369178,-263.772034,0.036423,0.000000
99.410004,43.043648,-263.860992,-0.000772,0.001436,0.036467,191.467712,9.753830,0.364668,-263.860992,0.035920,0.000000
99.710007,42.838097,-263.816528,-0.000755,0.001420,0.036068,190.553375,9.707252,0.360679,-263.816528,0.035417,0.000000
100.010002,42.004730,-263.860992,-0.000746,0.001404,0.035669,186.846375,9.518408,0.356690,-263.860992,0.034923,0.000000
100.310005,41.112526,-263.860992,-0.000742,0.001382,0.035114,182.877655,9.316232,0.351140,-263.860992,0.034420,0.000000
100.610008,40.557320,-263.860992,-0.000746,0.001376,0.034958,180.407974,9.190420,0.349579,-263.860992,0.033917,0.000000
100.910004,38.928192,-263.949951,-0.000746,0.001348,0.034229,173.161240,8.821255,0.342294,-263.949951,0.033423,0.000000
101.210007,37.633080,-263.994446,-0.000742,0.001328,0.033726,167.400299,8.527778,0.337264,-263.994446,0.032920,0.000000
101.510002,36.102631,-263.949951,-0.000759,0.001308,0.033232,160.592514,8.180973,0.332321,-263.949951,0.032417,0.000000
101.810005,34.626541,-264.083405,-0.000742,0.001292,0.032807,154.026550,7.846487,0.328071,-264.083405,0.031923,0.000000
102.110008,33.234985,-264.083405,-0.000755,0.001275,0.032374,147.836594,7.531156,0.323735,-264.083405,0.031420,0.000000
102.410004,31.126617,-264.127899,-0.000759,0.001254,0.031845,138.458115,7.053392,0.318445,-264.127899,0.030917,0.000000
102.710007,30.386337,-264.127899,-0.000763,0.001249,0.031714,135.165176,6.885642,0.317144,-264.127899,0.030422,0.000000
103.010002,27.905594,-264.127899,-0.000750,0.001224,0.031081,124.130280,6.323498,0.310814,-264.127899,0.029919,0.000000
103.310005,25.303825,-264.127899,-0.000759,0.001197,0.030405,112.557037,5.733929,0.304049,-264.127899,0.029416,0.000000
103.610008,23.360786,-264.127899,-0.000755,0.001178,0.029928,103.913971,5.293630,0.299280,-264.127899,0.028922,0.000000
103.910004,21.544724,-264.261322,-0.000750,0.001162,0.029512,95.835716,4.882104,0.295117,-264.261322,0.028419,0.000000
104.210007,20.377708,-264.261322,-0.000755,0.001155,0.029347,90.644577,4.617655,0.293469,-264.261322,0.027916,0.000000
104.510002,17.206589,-264.261322,-0.000767,0.001125,0.028566,76.538727,3.899069,0.285664,-264.261322,0.027422,0.000000
104.810005,14.833084,-264.305817,-0.000763,0.001101,0.027968,65.980850,3.361225,0.279680,-264.305817,0.026919,0.000000
105.110008,12.312866,-264.305817,-0.000763,0.001077,0.027352,54.770363,2.790135,0.273523,-264.305817,0.026416,0.000000
105.410004,10.640167,-264.305817,-0.000763,0.001060,0.026927,47.329826,2.411096,0.269274,-264.305817,0.025921,0.000000
105.710007,9.011040,-264.350281,-0.000763,0.001047,0.026606,40.083107,2.041931,0.266065,-264.350281,0.025418,0.000000
106.010002,6.503113,-264.394775,-0.000772,0.001020,0.025913,28.927290,1.473626,0.259127,-264.394775,0.024915,0.000000
106.310005,4.637154,-264.439240,-0.000780,0.001005,0.025531,20.627090,1.050794,0.255311,-264.439240,0.024421,0.000000
106.610008,2.997223,-264.439240,-0.000780,0.000989,0.025115,13.332314,0.679180,0.251149,-264.439240,0.023918,0.000000
106.910004,0.352638,-264.483734,-0.000785,0.000960,0.024386,1.568613,0.079909,0.243864,-264.483734,0.023415,0.000000
107.210007,-1.197178,-264.572693,-0.000776,0.000940,0.023875,-5.325313,-0.271284,0.238747,-264.572693,0.022921,0.000000
107.510002,-0.062561,-264.528229,-0.000806,0.000924,0.023467,-0.278285,-0.014177,0.234671,-264.528229,0.022418,0.000000
107.810005,-0.020851,-264.572693,-0.000828,0.000905,0.022981,-0.092750,-0.004725,0.229815,-264.572693,0.021915,0.000000
108.110008,0.005959,-264.617187,-0.000880,0.000885,0.022478,0.026505,0.001350,0.224785,-264.617187,0.021420,0.000000
108.410004,0.010429,-264.617187,-0.000931,0.000860,0.021854,0.046392,0.002363,0.218541,-264.617187,0.020917,0.000000
108.710007,0.002235,-264.661652,-0.000940,0.000840,0.021325,0.009944,0.000507,0.213251,-264.661652,0.020423,0.000000
109.010002,-0.001488,-264.706146,-0.000974,0.000818,0.020770,-0.006618,-0.000337,0.207700,-264.706146,0.019920,0.000000
109.310005,0.010796,-264.661652,-0.000983,0.000800,0.020319,0.048021,0.002446,0.203191,-264.661652,0.019417,0.000000
109.610008,0.012291,-264.706146,-0.001026,0.000784,0.019903,0.054673,0.002785,0.199028,-264.706146,0.018923,0.000000
109.910004,0.008568,-264.750610,-0.001026,0.000764,0.019409,0.038112,0.001941,0.194085,-264.750610,0.018420,0.000000
110.210007,0.005959,-264.839569,-0.001039,0.000753,0.019131,0.026505,0.001350,0.191310,-264.839569,0.017917,0.000000
110.510002,-0.000374,-264.839569,-0.001069,0.000726,0.018446,-0.001663,-0.000085,0.184459,-264.839569,0.017423,0.000000
110.810005,-0.003349,-264.839569,-0.001087,0.000698,0.017726,-0.014898,-0.000759,0.177261,-264.839569,0.016920,0.000000
111.110008,0.007072,-264.928558,-0.001112,0.000683,0.017345,0.031460,0.001603,0.173445,-264.928558,0.016417,0.000000
111.410004,0.012291,-264.839569,-0.001147,0.000661,0.016781,0.054673,0.002785,0.167808,-264.839569,0.015922,0.000000
111.710007,0.006332,-264.928558,-0.001143,0.000644,0.016347,0.028168,0.001435,0.163472,-264.928558,0.015419,0.000000
112.010002,-0.008934,-265.017517,-0.001164,0.000643,0.016330,-0.039741,-0.002024,0.163299,-265.017517,0.014916,0.000000
112.310005,-0.002235,-265.017517,-0.001177,0.000612,0.015541,-0.009944,-0.000507,0.155407,-265.017517,0.014422,0.000000
112.610008,-0.003723,-265.017517,-0.001220,0.000580,0.014734,-0.016561,-0.000844,0.147342,-265.017517,0.013919,0.000000
112.910004,-0.009682,-265.061981,-0.001242,0.000560,0.014231,-0.043066,-0.002194,0.142312,-265.061981,0.013416,0.000000
113.210007,0.026810,-265.106476,-0.001255,0.000548,0.013919,0.119255,0.006075,0.139190,-265.106476,0.012922,0.000000
113.510002,0.018250,-265.150940,-0.001289,0.000524,0.013312,0.081178,0.004135,0.133119,-265.150940,0.012419,0.000000
113.810005,0.026810,-265.150940,-0.001302,0.000505,0.012826,0.119255,0.006075,0.128263,-265.150940,0.011916,0.000000
114.110008,0.010429,-265.150940,-0.001328,0.000488,0.012393,0.046392,0.002363,0.123927,-265.150940,0.011421,0.000000
114.410004,0.026436,-265.150940,-0.001337,0.000467,0.011872,0.117593,0.005990,0.118723,-265.150940,0.010918,0.000000
114.710007,0.016754,-265.284393,-0.001350,0.000444,0.011265,0.074526,0.003797,0.112653,-265.284393,0.010415,0.000000
115.010002,0.047661,-265.239899,-0.001384,0.000427,0.010840,0.212006,0.010800,0.108403,-265.239899,0.009921,0.000000
115.310005,0.021973,-265.239899,-0.001393,0.000410,0.010424,0.097739,0.004979,0.104240,-265.239899,0.009418,0.000000
115.610008,0.029793,-265.328888,-0.001406,0.000393,0.009973,0.132525,0.006751,0.099731,-265.328888,0.008915,0.000000
115.910004,0.041336,-265.328888,-0.001427,0.000372,0.009444,0.183872,0.009367,0.094441,-265.328888,0.008421,0.000000
116.210007,0.018250,-265.328888,-0.001453,0.000350,0.008880,0.081178,0.004135,0.088804,-265.328888,0.007918,0.000000
116.510002,0.020477,-265.417847,-0.001462,0.000325,0.008265,0.091088,0.004640,0.082647,-265.417847,0.007415,0.000000
116.810005,0.014893,-265.417847,-0.001500,0.000306,0.007770,0.066245,0.003375,0.077703,-265.417847,0.006920,0.000000
117.110008,0.060699,-265.462311,-0.001526,0.000286,0.007259,0.270005,0.013755,0.072587,-265.462311,0.006417,0.000000
117.410004,0.058838,-265.462311,-0.001539,0.000270,0.006851,0.261724,0.013333,0.068511,-265.462311,0.005914,0.000000
117.710007,0.052132,-265.551270,-0.001552,0.000252,0.006409,0.231893,0.011813,0.064088,-265.551270,0.005420,0.000000
118.010002,0.043938,-265.551270,-0.001574,0.000233,0.005906,0.195445,0.009956,0.059058,-265.551270,0.004917,0.000000
118.310005,0.018616,-265.595764,-0.001604,0.000208,0.005273,0.082807,0.004218,0.052727,-265.595764,0.004414,0.000000
118.610008,-0.005585,-265.595764,-0.001634,0.000186,0.004735,-0.024842,-0.001266,0.047350,-265.595764,0.003920,0.000000
118.910004,0.031281,-265.640228,-0.001651,0.000165,0.004197,0.139143,0.007088,0.041974,-265.640228,0.003417,0.000000
119.210007,0.040588,-265.640228,-0.001656,0.000149,0.003781,0.180546,0.009197,0.037811,-265.640228,0.002914,0.000000
119.510002,0.033142,-265.684723,-0.001699,0.000134,0.003408,0.147423,0.007510,0.034082,-265.684723,0.002420,0.000000
119.810005,0.048035,-265.684723,-0.001686,0.000119,0.003035,0.213669,0.010885,0.030353,-265.684723,0.001917,0.000000
120.110008,0.039841,-265.684723,-0.001712,0.000094,0.002385,0.177220,0.009028,0.023849,-265.684723,0.001414,0.000000
120.410004,0.018616,-265.773682,-0.001763,0.000068,0.001726,0.082807,0.004218,0.017258,-265.773682,0.000919,0.000000
120.710007,0.034256,-265.773682,-0.001781,0.000051,0.001301,0.152378,0.007763,0.013008,-265.773682,0.000416,0.000000
121.010002,0.008934,-265.818176,-0.001785,0.000030,0.000754,0.039741,0.002024,0.007545,-265.818176,-0.000087,0.000000
121.310005,0.025696,-265.862640,-0.001815,0.000013,0.000338,0.114301,0.005823,0.003382,-265.862640,-0.000581,0.000000
121.610008,0.009682,-265.907135,-0.001824,0.000001,0.000035,0.043066,0.002194,0.000347,-265.907135,-0.001084,0.000000
121.800003,0.020111,-265.818176,-0.001824,0.000003,0.000078,0.089459,0.004557,0.000781,-265.818176,-0.000000,0.000000