File: Data/AD Peeled Punched/AD Peeled Punched with creep_80bar_1_08142024_210957.csv
Time (sec),S:Load (lbs),S:HL1 (DIM),S:LVDT (in),S:Position (in),Ch:Position (mm),Ch:Load (N),Ch:Stress (MPa),Ch:Strain (mm/mm),Ch:HL1 (DIM),Set Point (),Cycles ()
0.110000,-0.000748,-195.093445,-0.005394,-0.005350,-0.135894,-0.003326,-0.000169,-1.358943,-195.093445,-0.135703,0.000000
0.390000,-0.022713,-195.004486,-0.005389,-0.005324,-0.135227,-0.101031,-0.005147,-1.352265,-195.004486,-0.134750,0.000000
0.670000,-0.006706,-195.093445,-0.005355,-0.005167,-0.131246,-0.029831,-0.001520,-1.312459,-195.093445,-0.130084,0.000000
0.950000,0.002975,-195.093445,-0.005178,-0.004986,-0.126650,0.013236,0.000674,-1.266496,-195.093445,-0.125418,0.000000
1.230000,-0.024208,-195.137939,-0.004984,-0.004804,-0.122019,-0.107683,-0.005486,-1.220186,-195.137939,-0.120770,0.000000
1.510000,-0.013031,-195.226898,-0.004803,-0.004622,-0.117396,-0.057965,-0.002953,-1.173963,-195.226898,-0.116104,0.000000
1.790000,-0.083038,-195.226898,-0.004609,-0.004430,-0.112514,-0.369373,-0.018817,-1.125139,-195.226898,-0.111438,0.000000
2.070000,-0.004097,-195.315857,-0.004419,-0.004253,-0.108030,-0.018224,-0.000928,-1.080303,-195.315857,-0.106773,0.000000
2.350000,0.001114,-195.271378,-0.004225,-0.004065,-0.103261,0.004955,0.000252,-1.032606,-195.271378,-0.102107,0.000000
2.630000,0.005959,-195.404816,-0.004049,-0.003878,-0.098508,0.026505,0.001350,-0.985082,-195.404816,-0.097441,0.000000
2.910000,0.014153,-195.449295,-0.003854,-0.003693,-0.093808,0.062954,0.003207,-0.938078,-195.449295,-0.092776,0.000000
3.190000,-0.011917,-195.538254,-0.003665,-0.003514,-0.089255,-0.053010,-0.002700,-0.892549,-195.538254,-0.088110,0.000000
3.470000,0.004837,-195.449295,-0.003501,-0.003335,-0.084702,0.021516,0.001096,-0.847019,-195.449295,-0.083444,0.000000
3.750000,-0.043571,-195.449295,-0.003298,-0.003147,-0.079932,-0.193816,-0.009873,-0.799322,-195.449295,-0.078779,0.000000
4.030000,0.029045,-195.493774,-0.003104,-0.002967,-0.075371,0.129199,0.006582,-0.753706,-195.493774,-0.074113,0.000000
4.310000,0.014519,-195.627228,-0.002928,-0.002779,-0.070575,0.064583,0.003290,-0.705748,-195.627228,-0.069447,0.000000
4.590000,0.044685,-195.627228,-0.002751,-0.002596,-0.065935,0.198770,0.010126,-0.659352,-195.627228,-0.064782,0.000000
4.870000,0.073730,-195.627228,-0.002561,-0.002410,-0.061217,0.327969,0.016708,-0.612175,-195.627228,-0.060116,0.000000
5.150000,0.070007,-195.671707,-0.002358,-0.002227,-0.056569,0.311408,0.015864,-0.565691,-195.671707,-0.055450,0.000000
5.430000,0.106499,-195.716187,-0.002156,-0.002043,-0.051886,0.473730,0.024133,-0.518861,-195.716187,-0.050785,0.000000
5.710000,0.053246,-195.760666,-0.002091,-0.000000,-0.000000,0.236848,0.012066,-0.000000,-195.760666,0.000225,0.000000
5.990000,0.045425,-195.805145,-0.002082,-0.000000,-0.000000,0.202062,0.010294,-0.000000,-195.805145,0.000225,0.000000
6.270000,0.074104,-195.805145,-0.002100,-0.000000,-0.000000,0.329632,0.016792,-0.000000,-195.805145,0.000538,0.000000
6.550000,0.087883,-195.805145,-0.002091,-0.000000,-0.000000,0.390923,0.019915,-0.000000,-195.805145,0.001006,0.000000
6.830000,0.075966,-195.894104,-0.002091,0.000000,0.000009,0.337913,0.017214,0.000087,-195.894104,0.001474,0.000000
7.110000,0.132195,-195.938583,-0.002082,0.000036,0.000902,0.588031,0.029956,0.009019,-195.938583,0.001943,0.000000
7.390000,0.123627,-195.983063,-0.002035,0.000054,0.001379,0.549919,0.028014,0.013789,-195.983063,0.002411,0.000000
7.670001,0.142242,-196.027557,-0.002026,0.000081,0.002047,0.632726,0.032233,0.020467,-196.027557,0.002879,0.000000
7.950000,0.137032,-195.983063,-0.002018,0.000095,0.002420,0.609547,0.031052,0.024196,-195.983063,0.003339,0.000000
8.230000,0.147461,-196.072037,-0.001992,0.000112,0.002845,0.655939,0.033415,0.028445,-196.072037,0.003807,0.000000
8.510000,0.150436,-196.072037,-0.001975,0.000127,0.003217,0.669175,0.034089,0.032174,-196.072037,0.004275,0.000000
8.790000,0.198471,-196.160995,-0.001962,0.000142,0.003616,0.882843,0.044974,0.036163,-196.160995,0.004744,0.000000
9.070001,0.242043,-196.160995,-0.001953,0.000166,0.004215,1.076659,0.054848,0.042147,-196.160995,0.005212,0.000000
9.350000,0.233475,-196.160995,-0.001923,0.000185,0.004700,1.038548,0.052906,0.047004,-196.160995,0.005672,0.000000
9.630000,0.265503,-196.249954,-0.001888,0.000212,0.005377,1.181016,0.060164,0.053768,-196.249954,0.006140,0.000000
9.910001,0.258423,-196.294434,-0.001867,0.000227,0.005776,1.149522,0.058559,0.057757,-196.294434,0.006608,0.000000
10.190001,0.265129,-196.383392,-0.001850,0.000241,0.006114,1.179353,0.060079,0.061139,-196.383392,0.007077,0.000000
10.470000,0.342957,-196.338913,-0.001841,0.000261,0.006634,1.525547,0.077715,0.066343,-196.338913,0.007545,0.000000
10.750001,0.401047,-196.338913,-0.001837,0.000276,0.006999,1.783945,0.090878,0.069985,-196.338913,0.008004,0.000000
11.030001,0.444237,-196.338913,-0.001807,0.000294,0.007467,1.976064,0.100665,0.074668,-196.338913,0.008473,0.000000
11.310000,0.435303,-196.472366,-0.001789,0.000312,0.007926,1.936323,0.098641,0.079264,-196.472366,0.008941,0.000000
11.590000,0.509407,-196.516846,-0.001776,0.000336,0.008534,2.265956,0.115433,0.085335,-196.516846,0.009409,0.000000
11.870001,0.535469,-196.605804,-0.001763,0.000353,0.008976,2.381885,0.121339,0.089758,-196.605804,0.009878,0.000000
12.150001,0.588348,-196.561325,-0.001720,0.000370,0.009401,2.617104,0.133322,0.094007,-196.561325,0.010346,0.000000
12.430000,0.700432,-196.561325,-0.001720,0.000389,0.009869,3.115676,0.158720,0.098690,-196.561325,0.010806,0.000000
12.710001,0.749214,-196.605804,-0.001699,0.000405,0.010294,3.332671,0.169774,0.102940,-196.605804,0.011274,0.000000
12.990001,0.874329,-196.650284,-0.001699,0.000423,0.010754,3.889208,0.198126,0.107536,-196.650284,0.011742,0.000000
13.270000,0.945084,-196.739243,-0.001664,0.000448,0.011369,4.203942,0.214159,0.113693,-196.739243,0.012211,0.000000
13.550000,1.021416,-196.739243,-0.001647,0.000463,0.011760,4.543484,0.231456,0.117596,-196.739243,0.012679,0.000000
13.830001,1.120842,-196.783722,-0.001630,0.000483,0.012280,4.985754,0.253986,0.122799,-196.783722,0.013138,0.000000
14.110001,1.218773,-196.783722,-0.001608,0.000499,0.012670,5.421372,0.276178,0.126702,-196.783722,0.013607,0.000000
14.390000,1.412407,-196.828201,-0.001595,0.000520,0.013208,6.282700,0.320056,0.132079,-196.828201,0.014075,0.000000
14.670001,1.477577,-196.961655,-0.001574,0.000533,0.013529,6.572592,0.334824,0.135287,-196.961655,0.014543,0.000000
14.950001,1.655197,-196.917175,-0.001561,0.000550,0.013962,7.362685,0.375073,0.139623,-196.917175,0.015012,0.000000
15.230000,1.931870,-196.917175,-0.001535,0.000575,0.014595,8.593385,0.437768,0.145954,-196.917175,0.015480,0.000000
15.510001,1.887558,-196.961655,-0.001518,0.000582,0.014778,8.396277,0.427727,0.147775,-196.961655,0.015940,0.000000
15.790001,2.251366,-197.006134,-0.001496,0.000611,0.015523,10.014575,0.510167,0.155233,-197.006134,0.016408,0.000000
16.070002,2.400314,-197.095093,-0.001487,0.000627,0.015922,10.677132,0.543919,0.159223,-197.095093,0.016876,0.000000
16.350000,2.730606,-197.050613,-0.001483,0.000647,0.016443,12.146342,0.618764,0.164426,-197.050613,0.017345,0.000000
16.630001,2.871735,-197.050613,-0.001462,0.000662,0.016824,12.774114,0.650744,0.168242,-197.050613,0.017813,0.000000
16.910002,3.149155,-197.139572,-0.001440,0.000679,0.017240,14.008140,0.713609,0.172405,-197.139572,0.018272,0.000000
17.190001,3.521156,-197.139572,-0.001414,0.000701,0.017804,15.662886,0.797905,0.178041,-197.139572,0.018741,0.000000
17.470001,3.831711,-197.228531,-0.001401,0.000719,0.018272,17.044300,0.868278,0.182724,-197.228531,0.019209,0.000000
17.750000,4.183235,-197.317505,-0.001401,0.000741,0.018819,18.607960,0.947935,0.188188,-197.317505,0.019677,0.000000
18.030001,4.471817,-197.273026,-0.001384,0.000757,0.019235,19.891636,1.013328,0.192351,-197.273026,0.020146,0.000000
18.310001,4.849777,-197.317505,-0.001362,0.000774,0.019669,21.572887,1.098975,0.196687,-197.317505,0.020614,0.000000
18.590000,5.317482,-197.361984,-0.001358,0.000793,0.020137,23.653341,1.204959,0.201370,-197.361984,0.021074,0.000000
18.870001,5.531593,-197.450943,-0.001332,0.000806,0.020484,24.605757,1.253477,0.204839,-197.450943,0.021542,0.000000
19.150002,6.406670,-197.539902,-0.001324,0.000835,0.021204,28.498289,1.451772,0.212037,-197.539902,0.022010,0.000000
19.430000,6.725044,-197.450943,-0.001319,0.000852,0.021637,29.914492,1.523917,0.216373,-197.450943,0.022478,0.000000
19.710001,7.154388,-197.450943,-0.001285,0.000869,0.022080,31.824308,1.621208,0.220796,-197.450943,0.022947,0.000000
19.990002,7.680923,-197.584381,-0.001276,0.000886,0.022505,34.166454,1.740522,0.225045,-197.584381,0.023406,0.000000
20.270000,8.207092,-197.584381,-0.001268,0.000904,0.022973,36.506969,1.859754,0.229728,-197.584381,0.023875,0.000000
20.550001,8.576485,-197.584381,-0.001250,0.000918,0.023328,38.150108,1.943459,0.233284,-197.584381,0.024343,0.000000
20.830002,9.176376,-197.628860,-0.001224,0.000935,0.023745,40.818562,2.079396,0.237446,-197.628860,0.024811,0.000000
21.110001,10.205238,-197.673340,-0.001212,0.000960,0.024395,45.395168,2.312540,0.243951,-197.673340,0.025280,0.000000
21.390001,10.480423,-197.717834,-0.001207,0.000976,0.024785,46.619251,2.374898,0.247853,-197.717834,0.025739,0.000000
21.670000,11.320496,-197.762314,-0.001190,0.000997,0.025332,50.356079,2.565261,0.253317,-197.762314,0.026208,0.000000
21.950001,12.045876,-197.806793,-0.001164,0.001016,0.025809,53.582729,2.729635,0.258086,-197.806793,0.026676,0.000000
22.230001,12.614120,-197.851273,-0.001168,0.001034,0.026268,56.110409,2.858401,0.262683,-197.851273,0.027144,0.000000
22.510000,12.951111,-197.851273,-0.001138,0.001044,0.026528,57.609417,2.934764,0.265284,-197.851273,0.027612,0.000000
22.790001,14.134140,-197.851273,-0.001143,0.001072,0.027222,62.871796,3.202842,0.272222,-197.851273,0.028081,0.000000
23.070002,14.883728,-197.984711,-0.001112,0.001089,0.027673,66.206131,3.372701,0.276732,-197.984711,0.028540,0.000000
23.350000,15.193916,-198.029190,-0.001104,0.001103,0.028020,67.585915,3.442991,0.280201,-198.029190,0.029009,0.000000
23.630001,16.092079,-197.984711,-0.001091,0.001122,0.028506,71.581146,3.646517,0.285057,-197.984711,0.029477,0.000000
23.910002,17.243454,-198.029190,-0.001087,0.001146,0.029104,76.702713,3.907423,0.291041,-198.029190,0.029945,0.000000
24.190001,17.724556,-198.029190,-0.001056,0.001160,0.029468,78.842766,4.016442,0.294683,-198.029190,0.030414,0.000000
24.470001,18.134911,-198.162643,-0.001056,0.001172,0.029772,80.668114,4.109430,0.297719,-198.162643,0.030873,0.000000
24.750002,19.687706,-198.162643,-0.001048,0.001200,0.030492,87.575287,4.461298,0.304917,-198.162643,0.031342,0.000000
25.030001,20.395210,-198.207123,-0.001039,0.001218,0.030934,90.722427,4.621621,0.309339,-198.207123,0.031810,0.000000
25.310001,20.909828,-198.251602,-0.001026,0.001233,0.031316,93.011559,4.738235,0.313155,-198.251602,0.032278,0.000000
25.590002,21.822517,-198.207123,-0.001000,0.001251,0.031784,97.071404,4.945053,0.317838,-198.207123,0.032746,0.000000
25.870001,22.809303,-198.251602,-0.001000,0.001271,0.032278,101.460846,5.168662,0.322781,-198.251602,0.033215,0.000000
26.150002,23.265457,-198.340561,-0.000983,0.001283,0.032590,103.489922,5.272028,0.325903,-198.340561,0.033674,0.000000
26.430000,24.008713,-198.340561,-0.000974,0.001300,0.033015,106.796089,5.440452,0.330153,-198.340561,0.034143,0.000000
26.710001,25.193977,-198.340561,-0.000949,0.001322,0.033588,112.068405,5.709037,0.335877,-198.340561,0.034611,0.000000
26.990002,26.814911,-198.385040,-0.000944,0.001347,0.034203,119.278679,6.076346,0.342034,-198.385040,0.035079,0.000000
27.270000,27.422997,-198.429520,-0.000949,0.001365,0.034663,121.983582,6.214140,0.346630,-198.429520,0.035548,0.000000
27.550001,28.020279,-198.607452,-0.000936,0.001378,0.035010,124.640427,6.349486,0.350099,-198.607452,0.036007,0.000000
27.830002,28.962761,-198.607452,-0.000923,0.001396,0.035470,128.832794,6.563056,0.354695,-198.607452,0.036476,0.000000
28.110001,29.814743,-198.562973,-0.000918,0.001410,0.035825,132.622604,6.756117,0.358251,-198.562973,0.036944,0.000000
28.390001,30.771370,-198.562973,-0.000901,0.001430,0.036328,136.877884,6.972892,0.363281,-198.562973,0.037412,0.000000
28.670002,31.933174,-198.607452,-0.000888,0.001449,0.036814,142.045853,7.236161,0.368137,-198.607452,0.037880,0.000000
28.950001,33.701195,-198.696411,-0.000884,0.001475,0.037473,149.910400,7.636800,0.374728,-198.696411,0.038340,0.000000
29.230001,34.162193,-198.740891,-0.000871,0.001490,0.037846,151.961029,7.741263,0.378457,-198.740891,0.038808,0.000000
29.510002,35.045464,-198.740891,-0.000867,0.001506,0.038253,155.890015,7.941416,0.382533,-198.740891,0.039277,0.000000
29.790001,34.826881,-198.785370,-0.000849,0.001502,0.038141,154.917709,7.891884,0.381406,-198.785370,0.038375,0.000000
30.070002,34.937477,-198.785370,-0.000841,0.001516,0.038505,155.409653,7.916945,0.385048,-198.785370,156.999786,0.000000
30.350002,34.698036,-198.874329,-0.000845,0.001513,0.038427,154.344574,7.862687,0.384268,-198.874329,156.999786,0.000000
30.630001,34.448547,-198.874329,-0.000823,0.001513,0.038427,153.234787,7.806152,0.384268,-198.874329,156.999786,0.000000
30.910002,35.352669,-198.918808,-0.000845,0.001517,0.038522,157.256531,8.011029,0.385222,-198.918808,156.999786,0.000000
31.190001,35.050301,-198.963287,-0.000828,0.001516,0.038505,155.911530,7.942512,0.385048,-198.963287,156.999786,0.000000
31.470001,34.865608,-198.918808,-0.000819,0.001516,0.038505,155.089966,7.900660,0.385048,-198.918808,156.999786,0.000000
31.750002,34.677933,-199.052261,-0.000823,0.001516,0.038513,154.255142,7.858132,0.385135,-199.052261,156.999786,0.000000
32.030003,34.515205,-199.096741,-0.000823,0.001516,0.038513,153.531296,7.821258,0.385135,-199.096741,156.999786,0.000000
32.310001,34.372955,-199.096741,-0.000823,0.001516,0.038513,152.898544,7.789023,0.385135,-199.096741,156.999786,0.000000
32.590000,35.404800,-199.141220,-0.000815,0.001504,0.038201,157.488419,8.022842,0.382013,-199.141220,156.999786,0.000000
32.870003,35.265533,-199.096741,-0.000815,0.001504,0.038201,156.868927,7.991284,0.382013,-199.096741,156.999786,0.000000
33.150002,35.148605,-199.274658,-0.000815,0.001504,0.038201,156.348801,7.964788,0.382013,-199.274658,156.999786,0.000000
33.430000,34.992958,-199.230179,-0.000819,0.001504,0.038210,155.656448,7.929518,0.382100,-199.230179,156.999786,0.000000
33.710003,34.895767,-199.274658,-0.000815,0.001504,0.038210,155.224121,7.907494,0.382100,-199.274658,156.999786,0.000000
33.990002,34.836929,-199.319138,-0.000811,0.001504,0.038210,154.962402,7.894161,0.382100,-199.319138,156.999786,0.000000
34.270000,34.711815,-199.363617,-0.000811,0.001506,0.038245,154.405869,7.865810,0.382447,-199.363617,156.999786,0.000000
34.550003,34.681282,-199.452591,-0.000802,0.001519,0.038583,154.270050,7.858891,0.385829,-199.452591,156.999786,0.000000
34.830002,34.643303,-199.497070,-0.000811,0.001522,0.038661,154.101105,7.850285,0.386609,-199.497070,156.999786,0.000000
35.110001,34.710327,-199.452591,-0.000802,0.001530,0.038869,154.399246,7.865473,0.388691,-199.452591,156.999786,0.000000
35.390003,34.717773,-199.541550,-0.000811,0.001532,0.038912,154.432373,7.867160,0.389124,-199.541550,156.999786,0.000000
35.670002,34.725594,-199.497070,-0.000802,0.001532,0.038921,154.467148,7.868932,0.389211,-199.497070,156.999786,0.000000
35.950001,34.696175,-199.586029,-0.000815,0.001533,0.038930,154.336288,7.862266,0.389298,-199.586029,156.999786,0.000000
36.230003,34.680161,-199.541550,-0.000802,0.001533,0.038930,154.265060,7.858636,0.389298,-199.541550,156.999786,0.000000
36.510002,34.640320,-199.674988,-0.000823,0.001533,0.038930,154.087845,7.849608,0.389298,-199.674988,156.999786,0.000000
36.790001,34.591164,-199.674988,-0.000802,0.001533,0.038930,153.869186,7.838470,0.389298,-199.674988,156.999786,0.000000
37.070004,34.559517,-199.630508,-0.000815,0.001533,0.038930,153.728409,7.831299,0.389298,-199.630508,156.999786,0.000000
37.350002,34.525627,-199.719467,-0.000823,0.001533,0.038930,153.577667,7.823619,0.389298,-199.719467,156.999786,0.000000
37.630001,34.486900,-199.808426,-0.000819,0.001533,0.038930,153.405396,7.814843,0.389298,-199.808426,156.999786,0.000000
37.910004,34.442215,-199.852921,-0.000819,0.001533,0.038930,153.206619,7.804718,0.389298,-199.852921,156.999786,0.000000
38.190002,35.157921,-199.808426,-0.000798,0.001537,0.039043,156.390244,7.966899,0.390425,-199.808426,156.999786,0.000000
38.470001,35.079720,-199.852921,-0.000815,0.001537,0.039043,156.042389,7.949178,0.390425,-199.852921,156.999786,0.000000
38.750000,35.026474,-199.897400,-0.000806,0.001537,0.039043,155.805542,7.937112,0.390425,-199.897400,156.999786,0.000000
39.030003,34.994072,-199.986359,-0.000789,0.001537,0.039043,155.661407,7.929770,0.390425,-199.986359,156.999786,0.000000
39.310001,35.003014,-199.986359,-0.000811,0.001537,0.039043,155.701187,7.931796,0.390425,-199.986359,156.999786,0.000000
39.590000,34.888321,-200.030838,-0.000802,0.001537,0.039043,155.191010,7.905807,0.390425,-200.030838,156.999786,0.000000
39.870003,34.881615,-200.075317,-0.000793,0.001537,0.039043,155.161179,7.904287,0.390425,-200.075317,156.999786,0.000000
40.150002,34.855553,-200.030838,-0.000789,0.001537,0.039043,155.045242,7.898381,0.390425,-200.030838,156.999786,0.000000
40.430000,34.833206,-200.164276,-0.000789,0.001537,0.039043,154.945847,7.893318,0.390425,-200.164276,156.999786,0.000000
40.710003,34.773254,-200.164276,-0.000828,0.001537,0.039043,154.679153,7.879732,0.390425,-200.164276,156.999786,0.000000
40.990002,34.731178,-200.164276,-0.000806,0.001537,0.039043,154.492004,7.870197,0.390425,-200.164276,156.999786,0.000000
41.270000,34.701393,-200.208755,-0.000802,0.001537,0.039043,154.359512,7.863448,0.390425,-200.208755,156.999786,0.000000
41.550003,34.687614,-200.253235,-0.000785,0.001537,0.039043,154.298218,7.860326,0.390425,-200.253235,156.999786,0.000000
41.830002,34.654472,-200.253235,-0.000798,0.001537,0.039043,154.150787,7.852816,0.390425,-200.253235,156.999786,0.000000
42.110001,34.620956,-200.253235,-0.000806,0.001537,0.039043,154.001709,7.845221,0.390425,-200.253235,156.999786,0.000000
42.390003,34.593399,-200.342209,-0.000789,0.001537,0.039043,153.879120,7.838976,0.390425,-200.342209,156.999786,0.000000
42.670002,34.567711,-200.386688,-0.000789,0.001537,0.039043,153.764862,7.833155,0.390425,-200.386688,156.999786,0.000000
42.950001,34.533447,-200.431168,-0.000793,0.001537,0.039043,153.612442,7.825391,0.390425,-200.431168,156.999786,0.000000
43.230003,34.503288,-200.520126,-0.000806,0.001537,0.039043,153.478287,7.818557,0.390425,-200.520126,156.999786,0.000000
43.510002,34.486900,-200.564606,-0.000819,0.001537,0.039043,153.405396,7.814843,0.390425,-200.564606,156.999786,0.000000
43.790001,34.470894,-200.564606,-0.000798,0.001537,0.039043,153.334198,7.811216,0.390425,-200.564606,156.999786,0.000000
44.070004,34.457115,-200.564606,-0.000798,0.001537,0.039043,153.272903,7.808094,0.390425,-200.564606,156.999786,0.000000
44.350002,34.413918,-200.564606,-0.000806,0.001537,0.039051,153.080750,7.798305,0.390512,-200.564606,156.999786,0.000000
44.630001,34.373329,-200.698044,-0.000806,0.001537,0.039051,152.900208,7.789108,0.390512,-200.698044,156.999786,0.000000
44.910004,34.343910,-200.698044,-0.000815,0.001537,0.039051,152.769348,7.782442,0.390512,-200.698044,156.999786,0.000000
45.190002,34.358437,-200.742538,-0.000802,0.001538,0.039060,152.833954,7.785733,0.390599,-200.742538,156.999786,0.000000
45.470001,34.352852,-200.742538,-0.000806,0.001538,0.039060,152.809113,7.784468,0.390599,-200.742538,156.999786,0.000000
45.750004,35.457680,-200.787018,-0.000793,0.001520,0.038609,157.723633,8.034825,0.386089,-200.787018,156.999786,0.000000
46.030003,35.424538,-200.920456,-0.000785,0.001520,0.038609,157.576218,8.027315,0.386089,-200.920456,156.999786,0.000000
46.310001,35.417465,-200.920456,-0.000793,0.001520,0.038609,157.544754,8.025712,0.386089,-200.920456,156.999786,0.000000
46.590004,35.420441,-200.964935,-0.000789,0.001520,0.038609,157.557983,8.026387,0.386089,-200.964935,156.999786,0.000000
46.870003,35.393257,-200.964935,-0.000802,0.001520,0.038609,157.437073,8.020226,0.386089,-200.964935,156.999786,0.000000
47.150002,35.354904,-200.964935,-0.000793,0.001520,0.038609,157.266464,8.011536,0.386089,-200.964935,156.999786,0.000000
47.430004,35.335541,-200.964935,-0.000789,0.001520,0.038609,157.180328,8.007148,0.386089,-200.964935,156.999786,0.000000
47.710003,35.316551,-201.053894,-0.000798,0.001520,0.038609,157.095871,8.002845,0.386089,-201.053894,156.999786,0.000000
47.990002,35.300163,-201.098373,-0.000785,0.001520,0.038609,157.022964,7.999131,0.386089,-201.098373,156.999786,0.000000
48.270000,35.268509,-201.142868,-0.000785,0.001520,0.038609,156.882156,7.991959,0.386089,-201.142868,156.999786,0.000000
48.550003,35.257713,-201.098373,-0.000793,0.001520,0.038609,156.834137,7.989512,0.386089,-201.098373,156.999786,0.000000
48.830002,35.234253,-201.187347,-0.000789,0.001520,0.038609,156.729782,7.984196,0.386089,-201.187347,156.999786,0.000000
49.110001,35.211540,-201.276306,-0.000802,0.001520,0.038609,156.628754,7.979049,0.386089,-201.276306,156.999786,0.000000
49.390003,35.192177,-201.276306,-0.000793,0.001520,0.038609,156.542618,7.974661,0.386089,-201.276306,156.999786,0.000000
49.670002,35.158287,-201.320786,-0.000789,0.001520,0.038609,156.391876,7.966981,0.386089,-201.320786,156.999786,0.000000
49.950001,35.148605,-201.365265,-0.000798,0.001520,0.038609,156.348801,7.964788,0.386089,-201.365265,156.999786,0.000000
50.230003,35.137810,-201.320786,-0.000793,0.001520,0.038609,156.300781,7.962341,0.386089,-201.320786,156.999786,0.000000
50.510002,35.104668,-201.454224,-0.000793,0.001520,0.038609,156.153366,7.954832,0.386089,-201.454224,156.999786,0.000000
50.790001,35.032425,-201.454224,-0.000776,0.001520,0.038609,155.832016,7.938461,0.386089,-201.454224,156.999786,0.000000
51.070004,35.078606,-201.498703,-0.000789,0.001520,0.038609,156.037430,7.948926,0.386089,-201.498703,156.999786,0.000000
51.350002,35.060356,-201.454224,-0.000789,0.001520,0.038609,155.956253,7.944790,0.386089,-201.454224,156.999786,0.000000
51.630001,35.037270,-201.498703,-0.000785,0.001520,0.038609,155.853561,7.939559,0.386089,-201.498703,156.999786,0.000000
51.910004,35.017532,-201.587677,-0.000793,0.001520,0.038609,155.765762,7.935086,0.386089,-201.587677,156.999786,0.000000
52.190002,34.988487,-201.587677,-0.000793,0.001520,0.038609,155.636566,7.928504,0.386089,-201.587677,156.999786,0.000000
52.470001,35.013809,-201.676636,-0.000793,0.001520,0.038609,155.749207,7.934242,0.386089,-201.676636,156.999786,0.000000
52.750004,35.001892,-201.632156,-0.000785,0.001520,0.038609,155.696198,7.931542,0.386089,-201.632156,156.999786,0.000000
53.030003,34.975830,-201.676636,-0.000806,0.001520,0.038609,155.580261,7.925637,0.386089,-201.676636,156.999786,0.000000
53.310001,34.894653,-201.810074,-0.000798,0.001520,0.038609,155.219177,7.907241,0.386089,-201.810074,156.999786,0.000000
53.590004,34.884224,-201.810074,-0.000789,0.001520,0.038618,155.172775,7.904878,0.386176,-201.810074,156.999786,0.000000
53.870003,34.877525,-201.854553,-0.000793,0.001520,0.038618,155.142975,7.903360,0.386176,-201.854553,156.999786,0.000000
54.150002,34.875656,-201.854553,-0.000789,0.001520,0.038618,155.134674,7.902936,0.386176,-201.854553,156.999786,0.000000
54.430004,34.874916,-201.810074,-0.000776,0.001520,0.038618,155.131378,7.902769,0.386176,-201.810074,156.999786,0.000000
54.710003,34.848106,-201.899033,-0.000793,0.001520,0.038618,155.012115,7.896694,0.386176,-201.899033,156.999786,0.000000
54.990002,34.845497,-202.032486,-0.000780,0.001520,0.038618,155.000519,7.896103,0.386176,-202.032486,156.999786,0.000000
55.270004,34.835815,-202.076965,-0.000789,0.001520,0.038618,154.957443,7.893909,0.386176,-202.076965,156.999786,0.000000
55.550003,34.817940,-202.032486,-0.000789,0.001520,0.038618,154.877930,7.889858,0.386176,-202.032486,156.999786,0.000000
55.830002,34.818687,-201.987991,-0.000789,0.001520,0.038618,154.881256,7.890028,0.386176,-201.987991,156.999786,0.000000
56.110004,34.799698,-202.076965,-0.000785,0.001520,0.038618,154.796783,7.885724,0.386176,-202.076965,156.999786,0.000000
56.390003,34.753151,-202.121445,-0.000785,0.001520,0.038618,154.589737,7.875176,0.386176,-202.121445,156.999786,0.000000
56.670002,34.747192,-202.165924,-0.000785,0.001520,0.038618,154.563232,7.873827,0.386176,-202.165924,156.999786,0.000000
56.950005,34.731926,-202.165924,-0.000785,0.001520,0.038618,154.495316,7.870367,0.386176,-202.165924,156.999786,0.000000
57.230003,34.718887,-202.210403,-0.000789,0.001520,0.038618,154.437317,7.867412,0.386176,-202.210403,156.999786,0.000000
57.510002,34.795975,-202.299362,-0.000793,0.001538,0.039077,154.780228,7.884881,0.390772,-202.299362,156.999786,0.000000
57.790001,34.794479,-202.299362,-0.000811,0.001538,0.039077,154.773575,7.884542,0.390772,-202.299362,156.999786,0.000000
58.070004,34.780334,-202.432816,-0.000793,0.001538,0.039077,154.710648,7.881337,0.390772,-202.432816,156.999786,0.000000
58.350002,34.762833,-202.388321,-0.000798,0.001539,0.039086,154.632797,7.877370,0.390859,-202.388321,156.999786,0.000000
58.630001,34.735649,-202.432816,-0.000789,0.001539,0.039086,154.511887,7.871211,0.390859,-202.432816,156.999786,0.000000
58.910004,34.728203,-202.432816,-0.000780,0.001539,0.039086,154.478760,7.869524,0.390859,-202.432816,156.999786,0.000000
59.190002,34.728943,-202.521774,-0.000789,0.001541,0.039129,154.482056,7.869691,0.391292,-202.521774,156.999786,0.000000
59.470001,34.709579,-202.610733,-0.000798,0.001541,0.039129,154.395920,7.865304,0.391292,-202.610733,156.999786,0.000000
59.750004,34.701019,-202.521774,-0.000789,0.001541,0.039129,154.357849,7.863363,0.391292,-202.521774,156.999786,0.000000
60.030003,34.707344,-202.521774,-0.000780,0.001541,0.039129,154.385971,7.864797,0.391292,-202.521774,156.999786,0.000000
60.310001,34.690590,-202.566254,-0.000798,0.001541,0.039129,154.311447,7.861000,0.391292,-202.566254,156.999786,0.000000
60.590004,34.688354,-202.699692,-0.000802,0.001541,0.039129,154.301514,7.860494,0.391292,-202.699692,156.999786,0.000000
60.870003,34.666016,-202.744171,-0.000776,0.001541,0.039129,154.202133,7.855432,0.391292,-202.744171,156.999786,0.000000
61.150002,34.664528,-202.699692,-0.000793,0.001541,0.039129,154.195526,7.855094,0.391292,-202.699692,156.999786,0.000000
61.430004,34.655586,-202.699692,-0.000789,0.001541,0.039129,154.155746,7.853068,0.391292,-202.699692,156.999786,0.000000
61.710003,34.647026,-202.744171,-0.000806,0.001541,0.039129,154.117676,7.851128,0.391292,-202.744171,156.999786,0.000000
61.990002,34.642181,-202.877625,-0.000793,0.001541,0.039129,154.096115,7.850031,0.391292,-202.877625,156.999786,0.000000
62.270004,34.623566,-202.877625,-0.000802,0.001541,0.039129,154.013306,7.845812,0.391292,-202.877625,156.999786,0.000000
62.550003,34.635483,-202.922104,-0.000789,0.001541,0.039129,154.066315,7.848513,0.391292,-202.922104,156.999786,0.000000
62.830002,34.596382,-202.922104,-0.000780,0.001541,0.039129,153.892395,7.839652,0.391292,-202.922104,156.999786,0.000000
63.110004,34.586700,-202.922104,-0.000785,0.001541,0.039129,153.849335,7.837459,0.391292,-202.922104,156.999786,0.000000
63.390003,34.567337,-203.055542,-0.000798,0.001541,0.039129,153.763199,7.833070,0.391292,-203.055542,156.999786,0.000000
63.670002,34.562492,-203.055542,-0.000785,0.001541,0.039129,153.741638,7.831973,0.391292,-203.055542,156.999786,0.000000
63.950005,34.553185,-203.055542,-0.000802,0.001541,0.039129,153.700241,7.829864,0.391292,-203.055542,156.999786,0.000000
64.230003,34.539032,-203.011063,-0.000780,0.001541,0.039129,153.637283,7.826656,0.391292,-203.011063,156.999786,0.000000
64.510002,34.520790,-203.100021,-0.000780,0.001541,0.039129,153.556137,7.822523,0.391292,-203.100021,156.999786,0.000000
64.790001,34.530472,-203.188980,-0.000789,0.001541,0.039129,153.599213,7.824717,0.391292,-203.188980,156.999786,0.000000
65.070000,34.505150,-203.277939,-0.000767,0.001541,0.039138,153.486572,7.818979,0.391379,-203.277939,156.999786,0.000000
65.350006,34.505524,-203.233459,-0.000793,0.001541,0.039138,153.488235,7.819063,0.391379,-203.233459,156.999786,0.000000
65.630005,34.491371,-203.233459,-0.000785,0.001541,0.039138,153.425278,7.815856,0.391379,-203.233459,156.999786,0.000000
65.910004,34.469772,-203.277939,-0.000789,0.001541,0.039138,153.329208,7.810962,0.391379,-203.277939,156.999786,0.000000
66.190002,34.464188,-203.366913,-0.000780,0.001541,0.039138,153.304367,7.809697,0.391379,-203.366913,156.999786,0.000000
66.470001,34.467911,-203.411392,-0.000789,0.001541,0.039138,153.320923,7.810540,0.391379,-203.411392,156.999786,0.000000
66.750000,34.467171,-203.411392,-0.000780,0.001541,0.039138,153.317627,7.810372,0.391379,-203.411392,156.999786,0.000000
67.030006,35.189941,-203.411392,-0.000767,0.001550,0.039381,156.532684,7.974155,0.393807,-203.411392,156.999786,0.000000
67.310005,35.180634,-203.455872,-0.000772,0.001550,0.039372,156.491272,7.972045,0.393721,-203.455872,156.999786,0.000000
67.590004,35.169090,-203.500351,-0.000789,0.001550,0.039363,156.439926,7.969430,0.393634,-203.500351,156.999786,0.000000
67.870003,35.162018,-203.589310,-0.000785,0.001550,0.039363,156.408463,7.967827,0.393634,-203.589310,156.999786,0.000000
68.150002,35.166107,-203.589310,-0.000798,0.001550,0.039363,156.426651,7.968754,0.393634,-203.589310,156.999786,0.000000
68.430000,35.149727,-203.589310,-0.000772,0.001550,0.039363,156.353790,7.965042,0.393634,-203.589310,156.999786,0.000000
68.710007,35.087914,-203.678268,-0.000776,0.001550,0.039363,156.078827,7.951035,0.393634,-203.678268,156.999786,0.000000
68.990005,35.080467,-203.722763,-0.000772,0.001550,0.039363,156.045715,7.949347,0.393634,-203.722763,156.999786,0.000000
69.270004,35.093498,-203.722763,-0.000789,0.001550,0.039363,156.103683,7.952301,0.393634,-203.722763,156.999786,0.000000
69.550003,35.091263,-203.722763,-0.000798,0.001550,0.039363,156.093735,7.951794,0.393634,-203.722763,156.999786,0.000000
69.830002,35.086052,-203.767242,-0.000785,0.001550,0.039363,156.070557,7.950613,0.393634,-203.767242,156.999786,0.000000
70.110001,35.055145,-203.811722,-0.000772,0.001550,0.039363,155.933075,7.943610,0.393634,-203.811722,156.999786,0.000000
70.390007,35.085678,-203.900681,-0.000780,0.001550,0.039363,156.068893,7.950528,0.393634,-203.900681,156.999786,0.000000
70.670006,35.058121,-203.945160,-0.000785,0.001550,0.039363,155.946304,7.944283,0.393634,-203.945160,156.999786,0.000000
70.950005,35.059608,-204.034119,-0.000802,0.001550,0.039363,155.952927,7.944621,0.393634,-204.034119,156.999786,0.000000
71.230003,35.066689,-203.945160,-0.000780,0.001550,0.039363,155.984421,7.946225,0.393634,-203.945160,156.999786,0.000000
71.510002,35.057747,-204.034119,-0.000772,0.001550,0.039363,155.944641,7.944199,0.393634,-204.034119,156.999786,0.000000
71.790001,35.045090,-204.078598,-0.000785,0.001550,0.039363,155.888351,7.941331,0.393634,-204.078598,156.999786,0.000000
72.070000,35.038017,-204.123077,-0.000785,0.001550,0.039363,155.856888,7.939728,0.393634,-204.123077,156.999786,0.000000
72.350006,35.055519,-204.078598,-0.000785,0.001550,0.039363,155.934738,7.943695,0.393634,-204.078598,156.999786,0.000000
72.630005,35.025726,-204.123077,-0.000798,0.001550,0.039363,155.802216,7.936943,0.393634,-204.123077,156.999786,0.000000
72.910004,35.013435,-204.123077,-0.000776,0.001550,0.039363,155.747543,7.934158,0.393634,-204.123077,156.999786,0.000000
73.190002,35.017159,-204.212051,-0.000785,0.001550,0.039363,155.764099,7.935001,0.393634,-204.212051,156.999786,0.000000
73.470001,35.005249,-204.301010,-0.000798,0.001550,0.039363,155.711121,7.932303,0.393634,-204.301010,156.999786,0.000000
73.750000,35.005249,-204.301010,-0.000793,0.001550,0.039363,155.711121,7.932303,0.393634,-204.301010,156.999786,0.000000
74.030006,34.990723,-204.301010,-0.000785,0.001550,0.039363,155.646515,7.929011,0.393634,-204.301010,156.999786,0.000000
74.310005,34.985138,-204.345490,-0.000776,0.001550,0.039363,155.621658,7.927745,0.393634,-204.345490,156.999786,0.000000
74.590004,35.003754,-204.434448,-0.000780,0.001550,0.039363,155.704468,7.931964,0.393634,-204.434448,156.999786,0.000000
74.870003,34.930771,-204.478928,-0.000789,0.001550,0.039363,155.379822,7.915426,0.393634,-204.478928,156.999786,0.000000
75.150002,34.931519,-204.434448,-0.000798,0.001550,0.039363,155.383148,7.915596,0.393634,-204.434448,156.999786,0.000000
75.430000,34.934120,-204.478928,-0.000785,0.001550,0.039363,155.394730,7.916184,0.393634,-204.478928,156.999786,0.000000
75.710007,34.920341,-204.523407,-0.000789,0.001550,0.039363,155.333435,7.913063,0.393634,-204.523407,156.999786,0.000000
75.990005,34.909546,-204.478928,-0.000776,0.001550,0.039363,155.285416,7.910616,0.393634,-204.478928,156.999786,0.000000
76.270004,34.904701,-204.567886,-0.000776,0.001550,0.039363,155.263870,7.909518,0.393634,-204.567886,156.999786,0.000000
76.550003,34.896515,-204.612381,-0.000798,0.001550,0.039363,155.227448,7.907663,0.393634,-204.612381,156.999786,0.000000
76.830002,34.888321,-204.656860,-0.000780,0.001550,0.039363,155.191010,7.905807,0.393634,-204.656860,156.999786,0.000000
77.110001,34.875656,-204.612381,-0.000772,0.001550,0.039363,155.134674,7.902936,0.393634,-204.612381,156.999786,0.000000
77.390007,34.865608,-204.745819,-0.000789,0.001550,0.039363,155.089966,7.900660,0.393634,-204.745819,156.999786,0.000000
77.670006,34.878639,-204.745819,-0.000793,0.001550,0.039363,155.147934,7.903613,0.393634,-204.745819,156.999786,0.000000
77.950005,34.865974,-204.790298,-0.000789,0.001550,0.039363,155.091599,7.900743,0.393634,-204.790298,156.999786,0.000000
78.230003,34.863373,-204.834778,-0.000785,0.001550,0.039363,155.080032,7.900153,0.393634,-204.834778,156.999786,0.000000
78.510002,34.851082,-204.834778,-0.000780,0.001550,0.039363,155.025360,7.897368,0.393634,-204.834778,156.999786,0.000000
78.790001,34.854065,-204.879257,-0.000798,0.001550,0.039363,155.038620,7.898044,0.393634,-204.879257,156.999786,0.000000
79.070007,34.849220,-204.968216,-0.000793,0.001550,0.039363,155.017075,7.896946,0.393634,-204.968216,156.999786,0.000000
79.350006,34.840286,-204.923737,-0.000789,0.001550,0.039363,154.977341,7.894921,0.393634,-204.923737,156.999786,0.000000
79.630005,34.833206,-204.968216,-0.000772,0.001550,0.039363,154.945847,7.893318,0.393634,-204.968216,156.999786,0.000000
79.910004,34.834702,-205.012711,-0.000785,0.001550,0.039363,154.952484,7.893656,0.393634,-205.012711,156.999786,0.000000
80.190002,34.825760,-205.146149,-0.000798,0.001550,0.039363,154.912720,7.891630,0.393634,-205.146149,156.999786,0.000000
80.470001,34.826881,-205.146149,-0.000785,0.001550,0.039363,154.917709,7.891884,0.393634,-205.146149,156.999786,0.000000
80.750008,34.826134,-205.146149,-0.000802,0.001550,0.039363,154.914383,7.891715,0.393634,-205.146149,156.999786,0.000000
81.030006,34.804161,-205.146149,-0.000785,0.001550,0.039363,154.816635,7.886735,0.393634,-205.146149,156.999786,0.000000
81.310005,34.797462,-205.190628,-0.000763,0.001550,0.039363,154.786850,7.885218,0.393634,-205.190628,156.999786,0.000000
81.590004,34.778473,-205.324066,-0.000789,0.001550,0.039363,154.702377,7.880915,0.393634,-205.324066,156.999786,0.000000
81.870003,34.760971,-205.279587,-0.000776,0.001550,0.039363,154.624527,7.876948,0.393634,-205.279587,156.999786,0.000000
82.150002,34.746071,-205.324066,-0.000776,0.001550,0.039363,154.558243,7.873572,0.393634,-205.324066,156.999786,0.000000
82.430000,34.743469,-205.368546,-0.000789,0.001550,0.039363,154.546677,7.872983,0.393634,-205.368546,156.999786,0.000000
82.710007,34.746071,-205.413025,-0.000776,0.001550,0.039363,154.558243,7.873572,0.393634,-205.413025,156.999786,0.000000
82.990005,34.739746,-205.457520,-0.000776,0.001550,0.039363,154.530106,7.872139,0.393634,-205.457520,156.999786,0.000000
83.270004,34.730438,-205.501999,-0.000785,0.001550,0.039363,154.488708,7.870030,0.393634,-205.501999,156.999786,0.000000
83.550003,34.715164,-205.457520,-0.000776,0.001550,0.039363,154.420761,7.866569,0.393634,-205.457520,156.999786,0.000000
83.830002,34.718147,-205.546478,-0.000789,0.001550,0.039363,154.434036,7.867245,0.393634,-205.546478,156.999786,0.000000
84.110001,34.702133,-205.546478,-0.000776,0.001550,0.039363,154.362793,7.863616,0.393634,-205.546478,156.999786,0.000000
84.390007,34.703621,-205.635437,-0.000785,0.001550,0.039363,154.369415,7.863953,0.393634,-205.635437,156.999786,0.000000
84.670006,34.703255,-205.679916,-0.000785,0.001550,0.039363,154.367783,7.863870,0.393634,-205.679916,156.999786,0.000000
84.950005,34.700272,-205.635437,-0.000780,0.001550,0.039363,154.354523,7.863194,0.393634,-205.635437,156.999786,0.000000
85.230003,34.692078,-205.724396,-0.000780,0.001550,0.039363,154.318069,7.861337,0.393634,-205.724396,156.999786,0.000000
85.510002,34.685379,-205.724396,-0.000776,0.001550,0.039363,154.288269,7.859819,0.393634,-205.724396,156.999786,0.000000
85.790001,34.674950,-205.813354,-0.000789,0.001550,0.039363,154.241882,7.857456,0.393634,-205.813354,156.999786,0.000000
86.070007,34.676071,-205.768875,-0.000785,0.001550,0.039363,154.246872,7.857710,0.393634,-205.768875,156.999786,0.000000
86.350006,34.678299,-205.768875,-0.000789,0.001550,0.039363,154.256775,7.858215,0.393634,-205.768875,156.999786,0.000000
86.630005,34.666389,-205.857849,-0.000776,0.001550,0.039363,154.203796,7.855516,0.393634,-205.857849,156.999786,0.000000
86.910004,34.664528,-205.857849,-0.000789,0.001550,0.039363,154.195526,7.855094,0.393634,-205.857849,156.999786,0.000000
87.190002,34.659683,-205.946808,-0.000763,0.001550,0.039363,154.173965,7.853997,0.393634,-205.946808,156.999786,0.000000
87.470001,34.655960,-206.035767,-0.000793,0.001550,0.039363,154.157410,7.853153,0.393634,-206.035767,156.999786,0.000000
87.750008,34.654846,-205.991287,-0.000798,0.001550,0.039363,154.152451,7.852901,0.393634,-205.991287,156.999786,0.000000
88.030006,34.645531,-206.035767,-0.000780,0.001550,0.039363,154.111023,7.850790,0.393634,-206.035767,156.999786,0.000000
88.310005,34.640694,-206.080246,-0.000776,0.001550,0.039363,154.089508,7.849693,0.393634,-206.080246,156.999786,0.000000
88.590004,34.642181,-206.124725,-0.000798,0.001550,0.039363,154.096115,7.850031,0.393634,-206.124725,156.999786,0.000000
88.870003,34.624306,-206.169205,-0.000776,0.001550,0.039363,154.016602,7.845980,0.393634,-206.169205,156.999786,0.000000
89.150002,34.619469,-206.169205,-0.000793,0.001550,0.039363,153.995087,7.844883,0.393634,-206.169205,156.999786,0.000000
89.430008,34.617981,-206.169205,-0.000780,0.001550,0.039363,153.988464,7.844547,0.393634,-206.169205,156.999786,0.000000
89.710007,34.620583,-206.258163,-0.000789,0.001550,0.039363,154.000046,7.845136,0.393634,-206.258163,156.999786,0.000000
89.990005,34.601967,-206.347137,-0.000780,0.001550,0.039363,153.917236,7.840918,0.393634,-206.347137,156.999786,0.000000
90.270004,34.593399,-206.391617,-0.000789,0.001550,0.039363,153.879120,7.838976,0.393634,-206.391617,896.491760,0.000000
90.550003,34.547974,-206.347137,-0.000793,0.001546,0.039277,153.677063,7.828683,0.392767,-206.347137,0.039077,0.000000
90.830002,34.544624,-206.391617,-0.000776,0.001535,0.038982,153.662170,7.827924,0.389818,-206.391617,0.038609,0.000000
91.110001,34.489136,-206.436096,-0.000763,0.001520,0.038609,153.415344,7.815350,0.386089,-206.436096,0.038141,0.000000
91.390007,34.477966,-206.480576,-0.000789,0.001503,0.038184,153.365646,7.812819,0.381839,-206.480576,0.037672,0.000000
91.670006,34.471260,-206.480576,-0.000776,0.001483,0.037672,153.335815,7.811299,0.376723,-206.480576,0.037204,0.000000
91.950005,34.474617,-206.525055,-0.000789,0.001462,0.037126,153.350754,7.812060,0.371259,-206.525055,0.036744,0.000000
92.230003,34.438126,-206.569534,-0.000772,0.001447,0.036744,153.188431,7.803791,0.367444,-206.569534,0.036276,0.000000
92.510002,34.430305,-206.614014,-0.000780,0.001428,0.036276,153.153641,7.802019,0.362761,-206.614014,0.035808,0.000000
92.790001,34.448174,-206.658493,-0.000772,0.001417,0.035981,153.233124,7.806067,0.359812,-206.658493,0.035339,0.000000
93.070007,34.417641,-206.702972,-0.000767,0.001395,0.035435,153.097305,7.799149,0.354348,-206.702972,0.034871,0.000000
93.350006,34.383385,-206.702972,-0.000772,0.001376,0.034958,152.944931,7.791386,0.349579,-206.702972,0.034412,0.000000
93.630005,34.388222,-206.702972,-0.000759,0.001365,0.034663,152.966446,7.792483,0.346630,-206.702972,0.033943,0.000000
93.910004,34.358063,-206.747467,-0.000772,0.001344,0.034134,152.832291,7.785648,0.341340,-206.747467,0.033475,0.000000
94.190002,34.211349,-206.836426,-0.000759,0.001327,0.033709,152.179687,7.752403,0.337091,-206.836426,0.033007,0.000000
94.470001,33.725029,-206.880905,-0.000772,0.001307,0.033206,150.016418,7.642201,0.332061,-206.880905,0.032538,0.000000
94.750008,33.099442,-206.836426,-0.000759,0.001288,0.032720,147.233673,7.500441,0.327204,-206.836426,0.032070,0.000000
95.030006,32.323418,-206.880905,-0.000767,0.001274,0.032348,143.781738,7.324591,0.323475,-206.880905,0.031610,0.000000
95.310005,31.506058,-206.969864,-0.000763,0.001255,0.031888,140.145950,7.139375,0.318879,-206.969864,0.031142,0.000000
95.590004,30.605293,-207.014343,-0.000776,0.001242,0.031558,136.139145,6.935258,0.315583,-207.014343,0.030674,0.000000
95.870003,29.817726,-207.014343,-0.000759,0.001228,0.031203,132.635864,6.756793,0.312028,-207.014343,0.030205,0.000000
96.150002,28.347969,-207.058823,-0.000763,0.001208,0.030682,126.098061,6.423742,0.306824,-207.058823,0.029737,0.000000
96.430008,26.943008,-207.014343,-0.000763,0.001192,0.030266,119.848488,6.105373,0.302662,-207.014343,0.029278,0.000000
96.710007,25.560760,-207.103302,-0.000759,0.001175,0.029841,113.699944,5.792151,0.298412,-207.103302,0.028809,0.000000
96.990005,24.085426,-207.103302,-0.000767,0.001158,0.029425,107.137329,5.457836,0.294250,-207.103302,0.028341,0.000000
97.270004,23.912270,-207.192276,-0.000767,0.001158,0.029425,106.367088,5.418598,0.294250,-207.192276,0.027873,0.000000
97.550003,20.746361,-207.192276,-0.000767,0.001123,0.028532,92.284424,4.701192,0.285317,-207.192276,0.027404,0.000000
97.830002,19.354805,-207.192276,-0.000759,0.001110,0.028194,86.094475,4.385861,0.281935,-207.192276,0.026936,0.000000
98.110008,16.243256,-207.236755,-0.000763,0.001078,0.027378,72.253609,3.680774,0.273783,-207.236755,0.026476,0.000000
98.390007,14.675941,-207.281235,-0.000776,0.001065,0.027049,65.281845,3.325616,0.270488,-207.281235,0.026008,0.000000
98.670006,12.824135,-207.370193,-0.000767,0.001046,0.026580,57.044601,2.905991,0.265805,-207.370193,0.025540,0.000000
98.950005,11.066910,-207.325714,-0.000763,0.001029,0.026147,49.228073,2.507797,0.261469,-207.325714,0.025071,0.000000
99.230003,8.716492,-207.370193,-0.000776,0.001007,0.025566,38.772892,1.975185,0.255658,-207.370193,0.024603,0.000000
99.510002,7.785934,-207.459152,-0.000776,0.000999,0.025375,34.633568,1.764318,0.253750,-207.459152,0.024144,0.000000
99.790009,5.422859,-207.503632,-0.000767,0.000974,0.024733,24.122082,1.228837,0.247333,-207.503632,0.023675,0.000000
100.070007,3.443703,-207.503632,-0.000776,0.000951,0.024161,15.318355,0.780354,0.241609,-207.503632,0.023207,0.000000
100.350006,1.905060,-207.459152,-0.000789,0.000937,0.023788,8.474130,0.431693,0.237880,-207.459152,0.022739,0.000000
100.630005,0.559303,-207.592606,-0.000785,0.000921,0.023389,2.487905,0.126740,0.233891,-207.592606,0.022270,0.000000
100.910004,-0.565262,-207.637085,-0.000780,0.000905,0.022990,-2.514410,-0.128090,0.229902,-207.637085,0.021802,0.000000
101.190002,0.016754,-207.681564,-0.000802,0.000889,0.022591,0.074526,0.003797,0.225912,-207.681564,0.021342,0.000000
101.470001,-0.031281,-207.681564,-0.000841,0.000859,0.021828,-0.139143,-0.007088,0.218281,-207.681564,0.020874,0.000000
101.750008,-0.010796,-207.726044,-0.000880,0.000838,0.021290,-0.048021,-0.002446,0.212904,-207.726044,0.020406,0.000000
102.030006,-0.023460,-207.770523,-0.000923,0.000818,0.020779,-0.104357,-0.005316,0.207787,-207.770523,0.019938,0.000000
102.310005,-0.016388,-207.770523,-0.000944,0.000804,0.020432,-0.072897,-0.003714,0.204318,-207.770523,0.019469,0.000000
102.590004,-0.007820,-207.815002,-0.000961,0.000787,0.019998,-0.034786,-0.001772,0.199982,-207.815002,0.019010,0.000000
102.870003,-0.023834,-207.815002,-0.001000,0.000768,0.019495,-0.106020,-0.005401,0.194952,-207.815002,0.018541,0.000000
103.150002,-0.017876,-207.815002,-0.001018,0.000760,0.019304,-0.079515,-0.004051,0.193044,-207.815002,0.018073,0.000000
103.430008,-0.017128,-207.859482,-0.001018,0.000738,0.018741,-0.076189,-0.003881,0.187408,-207.859482,0.017605,0.000000
103.710007,-0.029419,-207.992920,-0.001056,0.000707,0.017969,-0.130862,-0.006666,0.179689,-207.992920,0.017136,0.000000
103.990005,-0.020111,-208.037415,-0.001078,0.000689,0.017501,-0.089459,-0.004557,0.175006,-208.037415,0.016677,0.000000
104.270004,-0.029045,-208.037415,-0.001099,0.000671,0.017050,-0.129199,-0.006582,0.170497,-208.037415,0.016208,0.000000
104.550003,0.004471,-208.037415,-0.001095,0.000656,0.016651,0.019887,0.001013,0.166507,-208.037415,0.015740,0.000000
104.830002,-0.008568,-208.037415,-0.001095,0.000656,0.016651,-0.038112,-0.001941,0.166507,-208.037415,0.015272,0.000000
105.110008,-0.017128,-208.170853,-0.001134,0.000628,0.015948,-0.076189,-0.003881,0.159483,-208.170853,0.014804,0.000000
105.390007,-0.013405,-208.170853,-0.001160,0.000611,0.015523,-0.059628,-0.003038,0.155233,-208.170853,0.014335,0.000000
105.670006,-0.014893,-208.170853,-0.001181,0.000579,0.014708,-0.066245,-0.003375,0.147081,-208.170853,0.013876,0.000000
105.950005,-0.040215,-208.215332,-0.001207,0.000560,0.014231,-0.178883,-0.009113,0.142312,-208.215332,0.013407,0.000000
106.230003,-0.006332,-208.215332,-0.001216,0.000547,0.013902,-0.028168,-0.001435,0.139016,-208.215332,0.012939,0.000000
106.510002,0.001488,-208.348770,-0.001246,0.000527,0.013390,0.006618,0.000337,0.133900,-208.348770,0.012471,0.000000
106.790009,-0.016754,-208.348770,-0.001259,0.000510,0.012965,-0.074526,-0.003797,0.129650,-208.348770,0.012002,0.000000
107.070007,-0.024948,-208.393250,-0.001281,0.000495,0.012566,-0.110975,-0.005653,0.125661,-208.393250,0.011543,0.000000
107.350006,-0.026810,-208.393250,-0.001298,0.000478,0.012141,-0.119255,-0.006075,0.121412,-208.393250,0.011074,0.000000
107.630005,-0.016388,-208.437744,-0.001311,0.000457,0.011603,-0.072897,-0.003714,0.116035,-208.437744,0.010606,0.000000
107.910004,0.006332,-208.526703,-0.001345,0.000434,0.011014,0.028168,0.001435,0.110138,-208.526703,0.010138,0.000000
108.190002,0.009308,-208.482224,-0.001362,0.000414,0.010511,0.041403,0.002109,0.105108,-208.482224,0.009670,0.000000
108.470009,0.016380,-208.526703,-0.001380,0.000413,0.010493,0.072863,0.003712,0.104934,-208.526703,0.009201,0.000000
108.750008,-0.009308,-208.526703,-0.001380,0.000394,0.009999,-0.041403,-0.002109,0.099991,-208.526703,0.008742,0.000000
109.030006,0.009308,-208.660141,-0.001393,0.000394,0.009999,0.041403,0.002109,0.099991,-208.660141,0.008273,0.000000
109.310005,0.016754,-208.749100,-0.001436,0.000355,0.009010,0.074526,0.003797,0.090105,-208.749100,0.007805,0.000000
109.590004,-0.005211,-208.660141,-0.001449,0.000321,0.008161,-0.023179,-0.001181,0.081606,-208.660141,0.007337,0.000000
109.870003,0.001862,-208.704620,-0.001492,0.000305,0.007736,0.008281,0.000422,0.077357,-208.704620,0.006868,0.000000
110.150002,0.033882,-208.704620,-0.001483,0.000286,0.007267,0.150715,0.007678,0.072674,-208.704620,0.006409,0.000000
110.430008,0.041702,-208.793579,-0.001500,0.000277,0.007033,0.185501,0.009450,0.070332,-208.793579,0.005940,0.000000
110.710007,0.026436,-208.882553,-0.001509,0.000251,0.006374,0.117593,0.005990,0.063741,-208.882553,0.005472,0.000000
110.990005,0.031654,-208.882553,-0.001539,0.000231,0.005880,0.140806,0.007173,0.058798,-208.882553,0.005004,0.000000
111.270004,0.030907,-208.882553,-0.001561,0.000212,0.005377,0.137480,0.007004,0.053768,-208.882553,0.004536,0.000000
111.550003,-0.016388,-208.882553,-0.001587,0.000191,0.004856,-0.072897,-0.003714,0.048565,-208.882553,0.004076,0.000000
111.830002,0.001488,-208.927032,-0.001582,0.000177,0.004484,0.006618,0.000337,0.044836,-208.927032,0.003608,0.000000
112.110008,0.009308,-208.971512,-0.001613,0.000160,0.004067,0.041403,0.002109,0.040673,-208.971512,0.003139,0.000000
112.390007,0.006332,-209.060471,-0.001647,0.000141,0.003590,0.028168,0.001435,0.035903,-209.060471,0.002671,0.000000
112.670006,0.027557,-208.971512,-0.001643,0.000133,0.003391,0.122581,0.006245,0.033909,-208.971512,0.002203,0.000000
112.950005,0.023460,-209.060471,-0.001686,0.000104,0.002654,0.104357,0.005316,0.026537,-209.060471,0.001734,0.000000
113.230003,-0.002975,-209.149429,-0.001703,0.000085,0.002159,-0.013236,-0.000674,0.021594,-209.149429,0.001275,0.000000
113.510002,-0.020851,-209.193909,-0.001712,0.000063,0.001604,-0.092750,-0.004725,0.016044,-209.193909,0.000807,0.000000
113.790009,0.012657,-209.193909,-0.001729,0.000049,0.001240,0.056302,0.002868,0.012401,-209.193909,0.000338,0.000000
114.070007,-0.001488,-209.149429,-0.001759,0.000029,0.000737,-0.006618,-0.000337,0.007371,-209.149429,-0.000130,0.000000
114.350006,-0.020111,-209.238388,-0.001772,0.000016,0.000416,-0.089459,-0.004557,0.004163,-209.238388,-0.000598,0.000000
114.630005,-0.002975,-209.327362,-0.001789,0.000004,0.000113,-0.013236,-0.000674,0.001127,-209.327362,-0.001058,0.000000
114.900009,-0.001488,-209.327362,-0.001794,0.000002,0.000043,-0.006618,-0.000337,0.000434,-209.327362,-0.000035,0.000000