File: Data/AD Peeled Punched/AD Peeled Punched with creep_55bar_1_08142024_205153.csv
Time (sec),S:Load (lbs),S:HL1 (DIM),S:LVDT (in),S:Position (in),Ch:Position (mm),Ch:Load (N),Ch:Stress (MPa),Ch:Strain (mm/mm),Ch:HL1 (DIM),Set Point (),Cycles ()
0.110000,-0.069260,-1296.619751,-0.005652,-0.003594,-0.091284,-0.308082,-0.015694,-0.912842,-1296.619751,-0.090989,0.000000
0.530000,0.069260,-1296.575195,-0.005622,-0.003528,-0.089602,0.308082,0.015694,-0.896018,-1296.575195,-0.088821,0.000000
0.950000,0.067398,-1296.575195,-0.005467,-0.003270,-0.083054,0.299802,0.015273,-0.830542,-1296.575195,-0.081814,0.000000
1.370000,0.043571,-1296.619751,-0.005161,-0.002990,-0.075943,0.193816,0.009873,-0.759430,-1296.619751,-0.074824,0.000000
1.790000,0.011169,-1296.708740,-0.004889,-0.002722,-0.069127,0.049684,0.002531,-0.691266,-1296.708740,-0.067834,0.000000
2.210000,0.001862,-1296.664185,-0.004605,-0.002447,-0.062163,0.008281,0.000422,-0.621627,-1296.664185,-0.060827,0.000000
2.630000,-0.031281,-1296.619751,-0.004437,-0.000000,-0.000000,-0.139143,-0.007088,-0.000000,-1296.619751,0.000234,0.000000
3.050000,0.023834,-1296.619751,-0.004415,-0.000000,-0.000000,0.106020,0.005401,-0.000000,-1296.619751,0.000304,0.000000
3.470000,0.082672,-1296.797607,-0.004428,-0.000000,-0.000000,0.367744,0.018734,-0.000000,-1296.797607,0.001006,0.000000
3.890000,0.075592,-1296.619751,-0.004411,0.000027,0.000676,0.336250,0.017129,0.006764,-1296.619751,0.001700,0.000000
4.310000,0.074104,-1296.619751,-0.004393,0.000046,0.001162,0.329632,0.016792,0.011621,-1296.619751,0.002402,0.000000
4.730000,0.081177,-1296.664185,-0.004368,0.000078,0.001986,0.361092,0.018395,0.019859,-1296.664185,0.003105,0.000000
5.150000,0.076714,-1296.708740,-0.004329,0.000110,0.002792,0.341239,0.017384,0.027925,-1296.708740,0.003807,0.000000
5.570000,0.102776,-1296.708740,-0.004294,0.000140,0.003556,0.457169,0.023289,0.035556,-1296.708740,0.004501,0.000000
5.990000,0.094955,-1296.708740,-0.004277,0.000156,0.003955,0.422383,0.021517,0.039546,-1296.708740,0.005203,0.000000
6.410000,0.066284,-1296.664185,-0.004243,0.000192,0.004882,0.294847,0.015020,0.048825,-1296.664185,0.005906,0.000000
6.830000,0.063675,-1296.619751,-0.004221,0.000221,0.005602,0.283240,0.014429,0.056023,-1296.619751,0.006600,0.000000
7.250000,0.084900,-1296.708740,-0.004199,0.000242,0.006157,0.377654,0.019239,0.061573,-1296.708740,0.007302,0.000000
7.670001,0.110222,-1296.708740,-0.004165,0.000280,0.007103,0.490291,0.024977,0.071026,-1296.708740,0.008004,0.000000
8.090000,0.113945,-1296.753174,-0.004126,0.000306,0.007770,0.506853,0.025820,0.077703,-1296.753174,0.008707,0.000000
8.510000,0.065910,-1296.664185,-0.004096,0.000331,0.008395,0.293184,0.014935,0.083947,-1296.664185,0.009401,0.000000
8.930000,0.106125,-1296.619751,-0.004083,0.000362,0.009184,0.472067,0.024048,0.091839,-1296.619751,0.010103,0.000000
9.350000,0.105759,-1296.708740,-0.004057,0.000380,0.009652,0.470438,0.023965,0.096522,-1296.708740,0.010806,0.000000
9.770000,0.117668,-1296.753174,-0.004018,0.000421,0.010702,0.523414,0.026664,0.107016,-1296.753174,0.011508,0.000000
10.190001,0.089371,-1296.753174,-0.003997,0.000446,0.011317,0.397541,0.020252,0.113173,-1296.753174,0.012202,0.000000
10.610001,0.073730,-1296.708740,-0.003949,0.000466,0.011829,0.327969,0.016708,0.118290,-1296.708740,0.012904,0.000000
11.030001,0.094955,-1296.708740,-0.003954,0.000491,0.012479,0.422383,0.021517,0.124794,-1296.708740,0.013607,0.000000
11.450001,0.103149,-1296.708740,-0.003919,0.000518,0.013164,0.458832,0.023374,0.131645,-1296.708740,0.014301,0.000000
11.870001,0.131447,-1296.753174,-0.003872,0.000555,0.014101,0.584705,0.029786,0.141011,-1296.753174,0.015003,0.000000
12.290001,0.101288,-1296.797607,-0.003846,0.000582,0.014795,0.450551,0.022952,0.147949,-1296.797607,0.015705,0.000000
12.710001,0.107986,-1296.797607,-0.003811,0.000609,0.015480,0.480348,0.024470,0.154800,-1296.797607,0.016408,0.000000
13.130001,0.106873,-1296.797607,-0.003794,0.000626,0.015905,0.475393,0.024218,0.159049,-1296.797607,0.017102,0.000000
13.550000,0.114693,-1296.753174,-0.003768,0.000663,0.016842,0.510179,0.025990,0.168415,-1296.753174,0.017804,0.000000
13.970000,0.109108,-1296.797607,-0.003747,0.000688,0.017483,0.485336,0.024724,0.174833,-1296.797607,0.018507,0.000000
14.390000,0.064423,-1296.753174,-0.003708,0.000717,0.018203,0.286566,0.014598,0.182031,-1296.753174,0.019200,0.000000
14.810000,0.105759,-1296.708740,-0.003682,0.000745,0.018932,0.470438,0.023965,0.189315,-1296.708740,0.019903,0.000000
15.230000,0.108360,-1296.708740,-0.003678,0.000773,0.019625,0.482011,0.024555,0.196253,-1296.708740,0.020605,0.000000
15.650001,0.096443,-1296.753174,-0.003639,0.000805,0.020458,0.429001,0.021854,0.204579,-1296.753174,0.021308,0.000000
16.070002,0.099052,-1296.842163,-0.003604,0.000829,0.021048,0.440607,0.022446,0.210476,-1296.842163,0.022002,0.000000
16.490002,0.075218,-1296.842163,-0.003574,0.000850,0.021603,0.334587,0.017045,0.216026,-1296.842163,0.022704,0.000000
16.910002,0.103523,-1296.797607,-0.003527,0.000881,0.022374,0.460494,0.023459,0.223744,-1296.797607,0.023406,0.000000
17.330000,0.095329,-1296.753174,-0.003518,0.000918,0.023311,0.424046,0.021602,0.233110,-1296.753174,0.024109,0.000000
17.750000,0.099052,-1296.797607,-0.003471,0.000945,0.023996,0.440607,0.022446,0.239961,-1296.797607,0.024803,0.000000
18.170000,0.063675,-1296.842163,-0.003462,0.000963,0.024464,0.283240,0.014429,0.244644,-1296.842163,0.025505,0.000000
18.590000,0.123627,-1296.797607,-0.003441,0.000997,0.025323,0.549919,0.028014,0.253230,-1296.797607,0.026208,0.000000
19.010000,0.131821,-1296.797607,-0.003397,0.001023,0.025982,0.586368,0.029871,0.259821,-1296.797607,0.026901,0.000000
19.430000,0.117302,-1296.797607,-0.003363,0.001059,0.026901,0.521785,0.026581,0.269013,-1296.797607,0.027604,0.000000
19.850000,0.072243,-1296.842163,-0.003341,0.001080,0.027422,0.321352,0.016370,0.274217,-1296.842163,0.028306,0.000000
20.270000,0.069260,-1296.886597,-0.003307,0.001103,0.028011,0.308082,0.015694,0.280114,-1296.886597,0.029009,0.000000
20.690001,0.121025,-1296.797607,-0.003272,0.001136,0.028844,0.538346,0.027425,0.288439,-1296.797607,0.029702,0.000000
21.110001,0.113945,-1296.797607,-0.003260,0.001161,0.029494,0.506853,0.025820,0.294944,-1296.797607,0.030405,0.000000
21.530001,0.103149,-1296.842163,-0.003225,0.001182,0.030032,0.458832,0.023374,0.300320,-1296.842163,0.031107,0.000000
21.950001,0.075218,-1296.797607,-0.003221,0.001215,0.030856,0.334587,0.017045,0.308559,-1296.797607,0.031801,0.000000
22.370001,0.070007,-1296.886597,-0.003178,0.001232,0.031298,0.311408,0.015864,0.312982,-1296.886597,0.032504,0.000000
22.790001,0.110596,-1296.753174,-0.003143,0.001257,0.031923,0.491954,0.025061,0.319226,-1296.753174,0.033206,0.000000
23.210001,0.109482,-1296.886597,-0.003109,0.001303,0.033085,0.486999,0.024809,0.330847,-1296.886597,0.033909,0.000000
23.630001,0.116180,-1296.842163,-0.003096,0.001330,0.033787,0.516796,0.026327,0.337871,-1296.842163,0.034602,0.000000
24.050001,0.100914,-1296.886597,-0.003070,0.001352,0.034342,0.448888,0.022867,0.343421,-1296.886597,0.035305,0.000000
24.470001,0.147461,-1296.886597,-0.003031,0.001385,0.035183,0.655939,0.033415,0.351834,-1296.886597,0.036007,0.000000
24.890001,0.179855,-1296.797607,-0.003001,0.001410,0.035825,0.800037,0.040756,0.358251,-1296.797607,0.036710,0.000000
25.310001,0.157890,-1296.753174,-0.002992,0.001430,0.036328,0.702331,0.035778,0.363281,-1296.753174,0.037403,0.000000
25.730001,0.150810,-1296.886597,-0.002958,0.001449,0.036796,0.670837,0.034174,0.367964,-1296.886597,0.038106,0.000000
26.150002,0.160866,-1296.842163,-0.002936,0.001483,0.037672,0.715567,0.036453,0.376723,-1296.842163,0.038808,0.000000
26.570002,0.175758,-1296.842163,-0.002884,0.001510,0.038366,0.781812,0.039827,0.383661,-1296.842163,0.039502,0.000000
26.990002,0.176880,-1296.797607,-0.002863,0.001546,0.039259,0.786801,0.040082,0.392593,-1296.797607,0.040205,0.000000
27.410002,0.180977,-1296.842163,-0.002846,0.001567,0.039797,0.805025,0.041010,0.397970,-1296.842163,0.040907,0.000000
27.830002,0.141876,-1296.886597,-0.002811,0.001598,0.040586,0.631097,0.032150,0.405862,-1296.886597,0.041609,0.000000
28.250002,0.172035,-1296.886597,-0.002772,0.001628,0.041349,0.765251,0.038984,0.413493,-1296.886597,0.042303,0.000000
28.670002,0.180977,-1296.886597,-0.002755,0.001644,0.041766,0.805025,0.041010,0.417656,-1296.886597,0.043006,0.000000
29.090002,0.227150,-1296.797607,-0.002725,0.001686,0.042832,1.010414,0.051473,0.428323,-1296.797607,0.043708,0.000000
29.510002,0.202202,-1296.886597,-0.002708,0.001708,0.043379,0.899439,0.045820,0.433786,-1296.886597,0.044402,0.000000
29.930002,0.170547,-1296.931030,-0.002677,0.001733,0.044029,0.758633,0.038647,0.440291,-1296.931030,0.045104,0.000000
30.350002,0.219330,-1296.886597,-0.002626,0.001766,0.044862,0.975628,0.049701,0.448616,-1296.886597,0.045807,0.000000
30.770002,0.236458,-1296.975586,-0.002613,0.001788,0.045425,1.051817,0.053582,0.454253,-1296.975586,0.046509,0.000000
31.190001,0.258430,-1296.842163,-0.002587,0.001825,0.046362,1.149556,0.058561,0.463619,-1296.842163,0.047203,0.000000
31.610001,0.215233,-1296.931030,-0.002548,0.001850,0.046986,0.957404,0.048772,0.469863,-1296.931030,0.047906,0.000000
32.030003,0.236084,-1296.931030,-0.002522,0.001878,0.047697,1.050154,0.053497,0.476974,-1296.931030,0.048608,0.000000
32.450001,0.241669,-1296.886597,-0.002509,0.001900,0.048252,1.074996,0.054763,0.482524,-1296.886597,0.049310,0.000000
32.870003,0.272949,-1296.886597,-0.002458,0.001935,0.049154,1.214139,0.061851,0.491544,-1296.886597,0.050004,0.000000
33.290001,0.273323,-1296.886597,-0.002436,0.001958,0.049735,1.215802,0.061936,0.497354,-1296.886597,0.050707,0.000000
33.710003,0.266991,-1296.931030,-0.002414,0.001987,0.050464,1.187634,0.060501,0.504639,-1296.931030,0.051409,0.000000
34.130001,0.296410,-1297.020020,-0.002406,0.002015,0.051175,1.318496,0.067167,0.511750,-1297.020020,0.052103,0.000000
34.550003,0.291199,-1296.931030,-0.002363,0.002034,0.051669,1.295317,0.065987,0.516693,-1296.931030,0.052805,0.000000
34.970001,0.321732,-1296.931030,-0.002333,0.002070,0.052571,1.431134,0.072905,0.525712,-1296.931030,0.053508,0.000000
35.390003,0.301254,-1296.975586,-0.002302,0.002099,0.053308,1.340046,0.068265,0.533084,-1296.975586,0.054210,0.000000
35.810001,0.314285,-1296.931030,-0.002281,0.002123,0.053915,1.398011,0.071218,0.539154,-1296.931030,0.054904,0.000000
36.230003,0.313164,-1296.975586,-0.002246,0.002150,0.054609,1.393022,0.070964,0.546092,-1296.975586,0.055607,0.000000
36.650002,0.365669,-1296.975586,-0.002207,0.002183,0.055450,1.626578,0.082862,0.554504,-1296.975586,0.056309,0.000000
37.070004,0.363434,-1296.975586,-0.002186,0.002210,0.056144,1.616634,0.082355,0.561442,-1296.975586,0.057003,0.000000
37.490002,0.358597,-1296.931030,-0.002169,0.002234,0.056751,1.595118,0.081259,0.567513,-1296.931030,0.057705,0.000000
37.910004,0.403282,-1297.064575,-0.002139,0.002261,0.057419,1.793889,0.091385,0.574190,-1297.064575,0.058408,0.000000
38.330002,0.442009,-1296.975586,-0.002113,0.002290,0.058174,1.966154,0.100161,0.581735,-1296.975586,0.059110,0.000000
38.750000,0.470306,-1296.975586,-0.002074,0.002324,0.059032,2.092027,0.106573,0.590321,-1296.975586,0.059804,0.000000
39.170002,0.506798,-1296.886597,-0.002057,0.002346,0.059596,2.254349,0.114842,0.595958,-1296.886597,0.060506,0.000000
39.590000,0.475891,-1297.020020,-0.002031,0.002370,0.060203,2.116869,0.107838,0.602028,-1297.020020,0.061209,0.000000
40.010002,0.582764,-1297.020020,-0.001996,0.002401,0.060992,2.592262,0.132056,0.609920,-1297.020020,0.061911,0.000000
40.430000,0.623726,-1296.975586,-0.001970,0.002432,0.061772,2.774471,0.141338,0.617725,-1296.975586,0.062605,0.000000
40.850002,0.682930,-1296.931030,-0.001944,0.002464,0.062596,3.037824,0.154754,0.625964,-1296.931030,0.063307,0.000000
41.270000,0.666550,-1296.931030,-0.001914,0.002485,0.063125,2.964961,0.151042,0.631254,-1296.931030,0.064010,0.000000
41.690002,0.784218,-1296.975586,-0.001880,0.002511,0.063776,3.488375,0.177706,0.637758,-1296.975586,0.064704,0.000000
42.110001,0.880661,-1297.020020,-0.001867,0.002539,0.064496,3.917376,0.199561,0.644956,-1297.020020,0.065406,0.000000
42.530003,0.940239,-1296.975586,-0.001832,0.002564,0.065129,4.182392,0.213061,0.651286,-1296.975586,0.066109,0.000000
42.950001,0.978966,-1296.931030,-0.001815,0.002590,0.065779,4.354657,0.221837,0.657791,-1296.931030,0.066811,0.000000
43.370003,1.092918,-1296.975586,-0.001763,0.002616,0.066456,4.861544,0.247659,0.664555,-1296.975586,0.067505,0.000000
43.790001,1.312614,-1297.064575,-0.001755,0.002645,0.067184,5.838800,0.297443,0.671840,-1297.064575,0.068207,0.000000
44.210003,1.367729,-1297.064575,-0.001733,0.002662,0.067626,6.083963,0.309932,0.676263,-1297.064575,0.068910,0.000000
44.630001,1.697647,-1297.064575,-0.001677,0.002710,0.068823,7.551511,0.384692,0.688230,-1297.064575,0.069604,0.000000
45.050003,1.755363,-1297.020020,-0.001660,0.002731,0.069361,7.808247,0.397771,0.693607,-1297.020020,0.070306,0.000000
45.470001,1.986610,-1296.975586,-0.001647,0.002757,0.070020,8.836884,0.450172,0.700198,-1296.975586,0.071008,0.000000
45.890003,2.317650,-1297.020020,-0.001625,0.002787,0.070800,10.309422,0.525187,0.708003,-1297.020020,0.071711,0.000000
46.310001,2.551125,-1297.064575,-0.001591,0.002814,0.071485,11.347969,0.578093,0.714854,-1297.064575,0.072405,0.000000
46.730003,2.814766,-1297.064575,-0.001556,0.002838,0.072075,12.520704,0.637835,0.720751,-1297.064575,0.073107,0.000000
47.150002,3.102982,-1296.975586,-0.001556,0.002863,0.072726,13.802752,0.703146,0.727256,-1296.975586,0.073810,0.000000
47.570004,3.480942,-1297.064575,-0.001522,0.002892,0.073445,15.484002,0.788793,0.734453,-1297.064575,0.074512,0.000000
47.990002,3.814957,-1297.020020,-0.001492,0.002924,0.074278,16.969774,0.864482,0.742779,-1297.020020,0.075206,0.000000
48.410004,4.313568,-1297.064575,-0.001466,0.002950,0.074920,19.187710,0.977468,0.749196,-1297.064575,0.075908,0.000000
48.830002,4.799507,-1297.064575,-0.001449,0.002977,0.075622,21.349274,1.087584,0.756221,-1297.064575,0.076611,0.000000
49.250004,5.225876,-1296.975586,-0.001410,0.003001,0.076220,23.245857,1.184200,0.762205,-1296.975586,0.077305,0.000000
49.670002,5.902481,-1297.064575,-0.001388,0.003031,0.076992,26.255547,1.337521,0.769923,-1297.064575,0.078007,0.000000
50.090004,6.689301,-1297.064575,-0.001397,0.003061,0.077738,29.755495,1.515817,0.777381,-1297.064575,0.078709,0.000000
50.510002,7.381912,-1297.064575,-0.001354,0.003093,0.078553,32.836384,1.672765,0.785533,-1297.064575,0.079412,0.000000
50.930004,7.814613,-1297.064575,-0.001341,0.003115,0.079117,34.761135,1.770817,0.791170,-1297.064575,0.080106,0.000000
51.350002,8.566055,-1297.020020,-0.001337,0.003138,0.079707,38.103718,1.941096,0.797067,-1297.020020,0.080808,0.000000
51.770004,9.623222,-1297.020020,-0.001298,0.003170,0.080531,42.806232,2.180653,0.805306,-1297.020020,0.081511,0.000000
52.190002,10.196304,-1297.064575,-0.001302,0.003191,0.081051,45.355427,2.310516,0.810509,-1297.064575,0.082213,0.000000
52.610001,11.460884,-1297.020020,-0.001246,0.003227,0.081962,50.980560,2.597073,0.819615,-1297.020020,0.082907,0.000000
53.030003,12.471870,-1297.064575,-0.001246,0.003257,0.082716,55.477650,2.826166,0.827160,-1297.064575,0.083609,0.000000
53.450001,13.495522,-1297.064575,-0.001199,0.003284,0.083418,60.031078,3.058129,0.834184,-1297.064575,0.084312,0.000000
53.870003,14.044777,-1297.064575,-0.001199,0.003303,0.083904,62.474289,3.182592,0.839041,-1297.064575,0.085005,0.000000
54.290001,15.928238,-1296.975586,-0.001181,0.003343,0.084901,70.852341,3.609390,0.849014,-1296.975586,0.085708,0.000000
54.710003,16.505409,-1297.020020,-0.001155,0.003363,0.085430,73.419724,3.740179,0.854304,-1297.020020,0.086410,0.000000
55.130001,17.586784,-1297.064575,-0.001130,0.003390,0.086098,78.229927,3.985222,0.860982,-1297.064575,0.087113,0.000000
55.550003,18.998817,-1297.020020,-0.001125,0.003419,0.086844,84.510963,4.305194,0.868440,-1297.020020,0.087807,0.000000
55.970001,19.863464,-1297.064575,-0.001108,0.003441,0.087390,88.357101,4.501125,0.873903,-1297.064575,0.088509,0.000000
56.390003,21.524620,-1297.153442,-0.001065,0.003477,0.088310,95.746292,4.877549,0.883096,-1297.153442,0.089212,0.000000
56.810001,22.696846,-1297.109009,-0.001056,0.003503,0.088977,100.960617,5.143179,0.889774,-1297.109009,0.089905,0.000000
57.230003,23.920837,-1297.064575,-0.001056,0.003530,0.089671,106.405197,5.420539,0.896711,-1297.064575,0.090608,0.000000
57.650002,23.767418,-1297.064575,-0.001039,0.003531,0.089688,105.722755,5.385774,0.896885,-1297.064575,0.015749,0.000000
58.070004,24.082443,-1297.109009,-0.001043,0.003539,0.089888,107.124054,5.457160,0.898879,-1297.109009,108.000320,0.000000
58.490002,23.615494,-1297.109009,-0.001009,0.003539,0.089888,105.046959,5.351347,0.898879,-1297.109009,108.000320,0.000000
58.910004,23.275513,-1297.064575,-0.001018,0.003539,0.089888,103.534653,5.274307,0.898879,-1297.064575,108.000320,0.000000
59.330002,24.703934,-1297.109009,-0.001000,0.003438,0.087321,109.888588,5.597991,0.873210,-1297.109009,108.000320,0.000000
59.750004,24.358002,-1297.109009,-0.001000,0.003438,0.087321,108.349800,5.519602,0.873210,-1297.109009,108.000320,0.000000
60.170002,24.139793,-1297.153442,-0.001009,0.003438,0.087321,107.379166,5.470155,0.873210,-1297.153442,108.000320,0.000000
60.590004,23.919350,-1297.197998,-0.001000,0.003441,0.087408,106.398582,5.420202,0.874077,-1297.197998,108.000320,0.000000
61.010002,23.786781,-1297.064575,-0.000992,0.003531,0.089688,105.808891,5.390162,0.896885,-1297.064575,108.000320,0.000000
61.430004,23.664268,-1297.153442,-0.001005,0.003545,0.090035,105.263924,5.362400,0.900354,-1297.153442,108.000320,0.000000
61.850002,23.621452,-1297.109009,-0.001000,0.003549,0.090157,105.073471,5.352698,0.901568,-1297.109009,108.000320,0.000000
62.270004,23.491119,-1297.242432,-0.001000,0.003550,0.090174,104.493721,5.323164,0.901741,-1297.242432,108.000320,0.000000
62.690002,23.644539,-1297.153442,-0.001000,0.003555,0.090304,105.176163,5.357929,0.903042,-1297.153442,108.000320,0.000000
63.110004,23.592773,-1297.109009,-0.001009,0.003555,0.090304,104.945900,5.346199,0.903042,-1297.109009,108.000320,0.000000
63.530003,23.508621,-1297.153442,-0.000996,0.003555,0.090304,104.571571,5.327130,0.903042,-1297.153442,108.000320,0.000000
63.950005,23.692947,-1297.109009,-0.001000,0.003559,0.090408,105.391495,5.368898,0.904083,-1297.109009,108.000320,0.000000
64.370003,23.671349,-1297.197998,-0.000996,0.003559,0.090408,105.295418,5.364005,0.904083,-1297.197998,108.000320,0.000000
64.790001,23.632248,-1297.153442,-0.000996,0.003559,0.090408,105.121490,5.355144,0.904083,-1297.153442,108.000320,0.000000
65.210007,23.585701,-1297.153442,-0.000996,0.003560,0.090417,104.914436,5.344596,0.904170,-1297.153442,108.000320,0.000000
65.630005,23.666138,-1297.197998,-0.000996,0.003562,0.090486,105.272240,5.362823,0.904863,-1297.197998,108.000320,0.000000
66.050003,23.663155,-1297.109009,-0.000983,0.003562,0.090486,105.258972,5.362147,0.904863,-1297.109009,108.000320,0.000000
66.470001,23.628525,-1297.197998,-0.000983,0.003562,0.090486,105.104927,5.354300,0.904863,-1297.197998,108.000320,0.000000
66.889999,23.580116,-1297.109009,-0.000987,0.003562,0.090486,104.889595,5.343331,0.904863,-1297.109009,108.000320,0.000000
67.310005,23.772629,-1297.109009,-0.000996,0.003568,0.090616,105.745934,5.386955,0.906164,-1297.109009,108.000320,0.000000
67.730003,23.843010,-1297.153442,-0.000987,0.003567,0.090608,106.059006,5.402903,0.906078,-1297.153442,108.000320,0.000000
68.150002,23.817688,-1297.153442,-0.000992,0.003567,0.090608,105.946365,5.397165,0.906078,-1297.153442,108.000320,0.000000
68.570000,23.781197,-1297.197998,-0.000983,0.003567,0.090608,105.784042,5.388896,0.906078,-1297.197998,108.000320,0.000000
68.990005,23.752151,-1297.109009,-0.000974,0.003567,0.090608,105.654846,5.382314,0.906078,-1297.109009,108.000320,0.000000
69.410004,23.714912,-1297.109009,-0.000983,0.003567,0.090608,105.489197,5.373876,0.906078,-1297.109009,108.000320,0.000000
69.830002,23.688477,-1297.153442,-0.000992,0.003567,0.090608,105.371605,5.367886,0.906078,-1297.153442,108.000320,0.000000
70.250000,23.662407,-1297.153442,-0.000987,0.003567,0.090608,105.255646,5.361978,0.906078,-1297.153442,108.000320,0.000000
70.670006,23.621078,-1297.153442,-0.000987,0.003568,0.090616,105.071808,5.352613,0.906164,-1297.153442,108.000320,0.000000
71.090004,23.597618,-1297.197998,-0.000983,0.003568,0.090616,104.967445,5.347297,0.906164,-1297.197998,108.000320,0.000000
71.510002,23.576019,-1297.197998,-0.000974,0.003568,0.090616,104.871368,5.342402,0.906164,-1297.197998,108.000320,0.000000
71.930000,23.578629,-1297.153442,-0.000987,0.003569,0.090651,104.882980,5.342993,0.906511,-1297.153442,108.000320,0.000000
72.350006,23.551445,-1297.153442,-0.000979,0.003569,0.090660,104.762062,5.336833,0.906598,-1297.153442,108.000320,0.000000
72.770004,23.666138,-1297.197998,-0.000974,0.003572,0.090720,105.272240,5.362823,0.907205,-1297.197998,108.000320,0.000000
73.190002,23.704117,-1297.153442,-0.000992,0.003572,0.090720,105.441177,5.371430,0.907205,-1297.153442,108.000320,0.000000
73.610001,23.699272,-1297.197998,-0.000979,0.003572,0.090720,105.419624,5.370332,0.907205,-1297.197998,108.000320,0.000000
74.030006,23.680656,-1297.197998,-0.000996,0.003572,0.090720,105.336823,5.366113,0.907205,-1297.197998,108.000320,0.000000
74.450005,23.660545,-1297.242432,-0.000974,0.003572,0.090720,105.247360,5.361556,0.907205,-1297.242432,108.000320,0.000000
74.870003,23.657196,-1297.153442,-0.000996,0.003572,0.090720,105.232460,5.360797,0.907205,-1297.153442,108.000320,0.000000
75.290001,23.669113,-1297.197998,-0.000987,0.003573,0.090746,105.285477,5.363498,0.907465,-1297.197998,108.000320,0.000000
75.710007,23.659058,-1297.197998,-0.000987,0.003573,0.090746,105.240746,5.361219,0.907465,-1297.197998,108.000320,0.000000
76.130005,23.648636,-1297.331421,-0.000979,0.003573,0.090746,105.194389,5.358858,0.907465,-1297.331421,108.000320,0.000000
76.550003,23.641182,-1297.242432,-0.000983,0.003573,0.090746,105.161232,5.357169,0.907465,-1297.242432,108.000320,0.000000
76.970001,23.629272,-1297.197998,-0.000987,0.003573,0.090746,105.108253,5.354470,0.907465,-1297.197998,108.000320,0.000000
77.390007,23.996803,-1297.242432,-0.000979,0.003578,0.090885,106.743111,5.437753,0.908853,-1297.242432,108.000320,0.000000
77.810005,23.979301,-1297.242432,-0.000979,0.003578,0.090885,106.665260,5.433787,0.908853,-1297.242432,108.000320,0.000000
78.230003,23.996056,-1297.331421,-0.000979,0.003578,0.090885,106.739784,5.437584,0.908853,-1297.331421,108.000320,0.000000
78.650002,23.986000,-1297.197998,-0.000983,0.003578,0.090885,106.695061,5.435306,0.908853,-1297.197998,108.000320,0.000000
79.070007,23.994568,-1297.286987,-0.000974,0.003578,0.090885,106.733170,5.437247,0.908853,-1297.286987,108.000320,0.000000
79.490005,23.974083,-1297.242432,-0.000987,0.003578,0.090885,106.642044,5.432605,0.908853,-1297.242432,108.000320,0.000000
79.910004,23.955841,-1297.286987,-0.000966,0.003578,0.090885,106.560905,5.428471,0.908853,-1297.286987,108.000320,0.000000
80.330002,23.923073,-1297.286987,-0.000970,0.003578,0.090885,106.415146,5.421046,0.908853,-1297.286987,108.000320,0.000000
80.750008,23.893654,-1297.331421,-0.000974,0.003578,0.090885,106.284279,5.414379,0.908853,-1297.331421,108.000320,0.000000
81.170006,23.876900,-1297.242432,-0.000970,0.003578,0.090885,106.209755,5.410583,0.908853,-1297.242432,108.000320,0.000000
81.590004,23.875778,-1297.242432,-0.000957,0.003578,0.090885,106.204765,5.410328,0.908853,-1297.242432,108.000320,0.000000
82.010002,23.862373,-1297.331421,-0.000961,0.003578,0.090885,106.145142,5.407291,0.908853,-1297.331421,108.000320,0.000000
82.430000,23.843758,-1297.331421,-0.000953,0.003578,0.090885,106.062332,5.403072,0.908853,-1297.331421,108.000320,0.000000
82.850006,23.836678,-1297.286987,-0.000957,0.003578,0.090885,106.030838,5.401468,0.908853,-1297.286987,108.000320,0.000000
83.270004,23.810989,-1297.197998,-0.000974,0.003579,0.090894,105.916573,5.395647,0.908939,-1297.197998,108.000320,0.000000
83.690002,23.806892,-1297.286987,-0.000966,0.003579,0.090894,105.898346,5.394719,0.908939,-1297.286987,108.000320,0.000000
84.110001,23.786781,-1297.331421,-0.000961,0.003579,0.090894,105.808891,5.390162,0.908939,-1297.331421,108.000320,0.000000
84.530006,23.749176,-1297.286987,-0.000961,0.003579,0.090894,105.641609,5.381640,0.908939,-1297.286987,108.000320,0.000000
84.950005,23.741356,-1297.286987,-0.000949,0.003579,0.090894,105.606827,5.379868,0.908939,-1297.286987,108.000320,0.000000
85.370003,23.730553,-1297.331421,-0.000953,0.003579,0.090894,105.558769,5.377420,0.908939,-1297.331421,108.000320,0.000000
85.790001,23.696671,-1297.286987,-0.000966,0.003579,0.090903,105.408058,5.369742,0.909026,-1297.286987,108.000320,0.000000
86.210007,23.688103,-1297.286987,-0.000953,0.003579,0.090903,105.369942,5.367801,0.909026,-1297.286987,108.000320,0.000000
86.630005,23.681770,-1297.331421,-0.000944,0.003579,0.090903,105.341774,5.366366,0.909026,-1297.331421,108.000320,0.000000
87.050003,23.662781,-1297.286987,-0.000957,0.003579,0.090903,105.257309,5.362062,0.909026,-1297.286987,108.000320,0.000000
87.470001,23.663902,-1297.286987,-0.000961,0.003579,0.090903,105.262291,5.362317,0.909026,-1297.286987,108.000320,0.000000
87.890007,23.651985,-1297.286987,-0.000966,0.003579,0.090903,105.209282,5.359616,0.909026,-1297.286987,108.000320,0.000000
88.310005,23.634857,-1297.286987,-0.000970,0.003579,0.090903,105.133095,5.355735,0.909026,-1297.286987,108.000320,0.000000
88.730003,23.613998,-1297.286987,-0.000966,0.003579,0.090903,105.040314,5.351008,0.909026,-1297.286987,108.000320,0.000000
89.150002,23.606178,-1297.331421,-0.000970,0.003579,0.090903,105.005524,5.349236,0.909026,-1297.331421,108.000320,0.000000
89.570007,23.592407,-1297.331421,-0.000966,0.003579,0.090903,104.944267,5.346116,0.909026,-1297.331421,108.000320,0.000000
89.990005,23.567825,-1297.331421,-0.000961,0.003579,0.090911,104.834923,5.340546,0.909113,-1297.331421,108.000320,0.000000
90.410004,23.567451,-1297.331421,-0.000979,0.003579,0.090911,104.833260,5.340461,0.909113,-1297.331421,108.000320,0.000000
90.830002,23.547348,-1297.331421,-0.000957,0.003580,0.090920,104.743835,5.335906,0.909199,-1297.331421,108.000320,0.000000
91.250008,23.991219,-1297.331421,-0.000961,0.003586,0.091085,106.718269,5.436488,0.910847,-1297.331421,108.000320,0.000000
91.670006,24.009087,-1297.286987,-0.000974,0.003586,0.091085,106.797752,5.440537,0.910847,-1297.286987,108.000320,0.000000
92.090004,24.031059,-1297.331421,-0.000961,0.003586,0.091085,106.895493,5.445516,0.910847,-1297.331421,108.000320,0.000000
92.510002,24.030312,-1297.375854,-0.000957,0.003586,0.091085,106.892166,5.445347,0.910847,-1297.375854,108.000320,0.000000
92.930008,24.035896,-1297.420410,-0.000957,0.003586,0.091085,106.917007,5.446612,0.910847,-1297.420410,108.000320,0.000000
93.350006,24.029198,-1297.331421,-0.000953,0.003586,0.091085,106.887207,5.445094,0.910847,-1297.331421,108.000320,0.000000
93.770004,24.004250,-1297.375854,-0.000957,0.003586,0.091085,106.776237,5.439441,0.910847,-1297.375854,108.000320,0.000000
94.190002,23.995308,-1297.375854,-0.000953,0.003586,0.091085,106.736458,5.437414,0.910847,-1297.375854,108.000320,0.000000
94.610008,23.991585,-1297.375854,-0.000949,0.003586,0.091085,106.719902,5.436571,0.910847,-1297.375854,108.000320,0.000000
95.030006,23.984512,-1297.286987,-0.000957,0.003586,0.091085,106.688438,5.434968,0.910847,-1297.286987,108.000320,0.000000
95.450005,23.984138,-1297.331421,-0.000970,0.003586,0.091085,106.686775,5.434883,0.910847,-1297.331421,108.000320,0.000000
95.870003,23.967010,-1297.331421,-0.000966,0.003586,0.091085,106.610588,5.431002,0.910847,-1297.331421,108.000320,0.000000
96.290001,23.971107,-1297.420410,-0.000970,0.003586,0.091085,106.628815,5.431931,0.910847,-1297.420410,108.000320,0.000000
96.710007,23.939827,-1297.331421,-0.000957,0.003586,0.091085,106.489670,5.424842,0.910847,-1297.331421,108.000320,0.000000
97.130005,23.912643,-1297.331421,-0.000970,0.003586,0.091085,106.368752,5.418683,0.910847,-1297.331421,108.000320,0.000000
97.550003,23.919716,-1297.375854,-0.000953,0.003586,0.091085,106.400208,5.420285,0.910847,-1297.375854,108.000320,0.000000
97.970001,23.894768,-1297.420410,-0.000970,0.003586,0.091085,106.289238,5.414632,0.910847,-1297.420410,108.000320,0.000000
98.390007,23.892906,-1297.420410,-0.000949,0.003586,0.091085,106.280952,5.414210,0.910847,-1297.420410,108.000320,0.000000
98.810005,23.881363,-1297.331421,-0.000961,0.003586,0.091085,106.229607,5.411594,0.910847,-1297.331421,108.000320,0.000000
99.230003,23.875038,-1297.331421,-0.000957,0.003586,0.091085,106.201477,5.410161,0.910847,-1297.331421,108.000320,0.000000
99.650002,23.859398,-1297.375854,-0.000974,0.003586,0.091085,106.131905,5.406617,0.910847,-1297.375854,108.000320,0.000000
100.070007,23.859764,-1297.420410,-0.000957,0.003586,0.091085,106.133530,5.406700,0.910847,-1297.420410,108.000320,0.000000
100.490005,23.840401,-1297.420410,-0.000957,0.003586,0.091085,106.047401,5.402312,0.910847,-1297.420410,108.000320,0.000000
100.910004,23.845245,-1297.420410,-0.000970,0.003586,0.091085,106.068947,5.403410,0.910847,-1297.420410,108.000320,0.000000
101.330002,23.837051,-1297.331421,-0.000970,0.003586,0.091085,106.032501,5.401553,0.910847,-1297.331421,108.000320,0.000000
101.750008,23.812851,-1297.464844,-0.000949,0.003586,0.091085,105.924850,5.396069,0.910847,-1297.464844,108.000320,0.000000
102.170006,23.819176,-1297.464844,-0.000953,0.003586,0.091085,105.952988,5.397502,0.910847,-1297.464844,108.000320,0.000000
102.590004,23.818810,-1297.420410,-0.000949,0.003586,0.091085,105.951355,5.397419,0.910847,-1297.420410,108.000320,0.000000
103.010002,23.808006,-1297.420410,-0.000966,0.003586,0.091085,105.903297,5.394971,0.910847,-1297.420410,108.000320,0.000000
103.430008,23.789017,-1297.420410,-0.000957,0.003586,0.091085,105.818832,5.390668,0.910847,-1297.420410,108.000320,0.000000
103.850006,23.786781,-1297.420410,-0.000974,0.003586,0.091085,105.808891,5.390162,0.910847,-1297.420410,108.000320,0.000000
104.270004,23.763695,-1297.420410,-0.000957,0.003586,0.091085,105.706192,5.384930,0.910847,-1297.420410,108.000320,0.000000
104.690002,23.743958,-1297.375854,-0.000957,0.003586,0.091085,105.618401,5.380458,0.910847,-1297.375854,108.000320,0.000000
105.110008,23.735397,-1297.375854,-0.000961,0.003586,0.091085,105.580322,5.378518,0.910847,-1297.375854,108.000320,0.000000
105.530006,23.732788,-1297.464844,-0.000966,0.003586,0.091085,105.568710,5.377927,0.910847,-1297.464844,108.000320,0.000000
105.950005,23.732040,-1297.464844,-0.000957,0.003586,0.091085,105.565392,5.377758,0.910847,-1297.464844,108.000320,0.000000
106.370003,23.721245,-1297.420410,-0.000970,0.003586,0.091085,105.517365,5.375311,0.910847,-1297.420410,108.000320,0.000000
106.790009,23.698158,-1297.331421,-0.000961,0.003586,0.091085,105.414673,5.370080,0.910847,-1297.331421,108.000320,0.000000
107.210007,23.694435,-1297.420410,-0.000970,0.003586,0.091085,105.398109,5.369236,0.910847,-1297.420410,108.000320,0.000000
107.630005,23.685867,-1297.464844,-0.000966,0.003586,0.091085,105.360001,5.367294,0.910847,-1297.464844,108.000320,0.000000
108.050003,23.697044,-1297.464844,-0.000953,0.003586,0.091085,105.409721,5.369827,0.910847,-1297.464844,108.000320,0.000000
108.470009,23.678795,-1297.464844,-0.000970,0.003586,0.091085,105.328537,5.365692,0.910847,-1297.464844,108.000320,0.000000
108.890007,23.663155,-1297.420410,-0.000957,0.003586,0.091085,105.258972,5.362147,0.910847,-1297.420410,108.000320,0.000000
109.310005,23.654587,-1297.420410,-0.000970,0.003586,0.091085,105.220856,5.360206,0.910847,-1297.420410,108.000320,0.000000
109.730003,23.655334,-1297.375854,-0.000961,0.003586,0.091085,105.224182,5.360375,0.910847,-1297.375854,108.000320,0.000000
110.150002,23.644165,-1297.464844,-0.000953,0.003586,0.091085,105.174500,5.357844,0.910847,-1297.464844,108.000320,0.000000
110.570007,23.635597,-1297.420410,-0.000957,0.003586,0.091085,105.136391,5.355903,0.910847,-1297.420410,108.000320,0.000000
110.990005,23.636719,-1297.464844,-0.000966,0.003586,0.091093,105.141373,5.356157,0.910934,-1297.464844,108.000320,0.000000
111.410004,23.631874,-1297.509399,-0.000970,0.003586,0.091093,105.119827,5.355059,0.910934,-1297.509399,108.000320,0.000000
111.830002,23.618843,-1297.420410,-0.000961,0.003586,0.091093,105.061859,5.352106,0.910934,-1297.420410,108.000320,0.000000
112.250008,23.607300,-1297.464844,-0.000974,0.003586,0.091093,105.010513,5.349491,0.910934,-1297.464844,108.000320,0.000000
112.670006,23.602455,-1297.420410,-0.000944,0.003586,0.091093,104.988960,5.348393,0.910934,-1297.420410,108.000320,0.000000
113.090004,23.587189,-1297.375854,-0.000961,0.003586,0.091093,104.921059,5.344934,0.910934,-1297.375854,108.000320,0.000000
113.510002,23.574532,-1297.375854,-0.000970,0.003586,0.091093,104.864754,5.342065,0.910934,-1297.375854,108.000320,0.000000
113.930008,23.562988,-1297.509399,-0.000966,0.003586,0.091093,104.813408,5.339449,0.910934,-1297.509399,108.000320,0.000000
114.350006,23.549210,-1297.420410,-0.000970,0.003586,0.091093,104.752113,5.336327,0.910934,-1297.420410,108.000320,0.000000
114.770004,23.545113,-1297.420410,-0.000953,0.003586,0.091093,104.733894,5.335399,0.910934,-1297.420410,108.000320,0.000000
115.190002,23.534683,-1297.420410,-0.000966,0.003586,0.091093,104.687500,5.333035,0.910934,-1297.420410,108.000320,0.000000
115.610008,23.518677,-1297.420410,-0.000953,0.003586,0.091093,104.616302,5.329409,0.910934,-1297.420410,108.000320,0.000000
116.030006,23.519417,-1297.509399,-0.000961,0.003586,0.091093,104.619591,5.329576,0.910934,-1297.509399,108.000320,0.000000
116.450005,23.516441,-1297.464844,-0.000966,0.003586,0.091093,104.606354,5.328902,0.910934,-1297.464844,108.000320,0.000000
116.870003,23.506012,-1297.420410,-0.000949,0.003586,0.091093,104.559967,5.326539,0.910934,-1297.420410,108.000320,0.000000
117.290009,23.494469,-1297.464844,-0.000957,0.003586,0.091093,104.508614,5.323923,0.910934,-1297.464844,108.000320,0.000000
117.710007,23.491119,-1297.464844,-0.000961,0.003586,0.091093,104.493721,5.323164,0.910934,-1297.464844,108.000320,0.000000
118.130005,23.485161,-1297.509399,-0.000974,0.003586,0.091093,104.467216,5.321814,0.910934,-1297.509399,616.697632,0.000000
118.550003,23.329140,-1297.509399,-0.000970,0.003576,0.090833,103.773193,5.286458,0.908332,-1297.509399,0.090608,0.000000
118.970009,23.414040,-1297.464844,-0.000957,0.003559,0.090408,104.150848,5.305697,0.904083,-1297.464844,0.089914,0.000000
119.390007,23.425209,-1297.464844,-0.000949,0.003537,0.089827,104.200531,5.308228,0.898272,-1297.464844,0.089212,0.000000
119.810005,23.407707,-1297.464844,-0.000953,0.003508,0.089107,104.122681,5.304262,0.891074,-1297.464844,0.088509,0.000000
120.230003,23.379776,-1297.553833,-0.000949,0.003481,0.088414,103.998436,5.297933,0.884137,-1297.553833,0.087807,0.000000
120.650009,23.318710,-1297.509399,-0.000944,0.003450,0.087642,103.726807,5.284095,0.876418,-1297.509399,0.087113,0.000000
121.070007,23.328018,-1297.464844,-0.000944,0.003422,0.086913,103.768204,5.286204,0.869134,-1297.464844,0.086410,0.000000
121.490005,23.280731,-1297.509399,-0.000949,0.003399,0.086324,103.557861,5.275489,0.863236,-1297.509399,0.085708,0.000000
121.910004,23.258385,-1297.464844,-0.000961,0.003380,0.085847,103.458466,5.270425,0.858467,-1297.464844,0.085014,0.000000
122.330009,22.926971,-1297.509399,-0.000961,0.003345,0.084953,101.984261,5.195326,0.849534,-1297.509399,0.084312,0.000000
122.750008,22.245529,-1297.509399,-0.000940,0.003322,0.084372,98.953056,5.040909,0.843724,-1297.509399,0.083609,0.000000
123.170006,21.612869,-1297.464844,-0.000944,0.003308,0.084026,96.138847,4.897546,0.840255,-1297.464844,0.082907,0.000000
123.590004,19.879478,-1297.464844,-0.000936,0.003276,0.083219,88.428337,4.504754,0.832190,-1297.464844,0.082213,0.000000
124.010002,18.922852,-1297.553833,-0.000957,0.003262,0.082863,84.173050,4.287979,0.828634,-1297.553833,0.081511,0.000000
124.430008,16.115913,-1297.509399,-0.000936,0.003220,0.081779,71.687164,3.651918,0.817794,-1297.509399,0.080808,0.000000
124.850006,14.240273,-1297.420410,-0.000949,0.003196,0.081190,63.343895,3.226892,0.811897,-1297.420410,0.080106,0.000000
125.270004,12.019814,-1297.553833,-0.000936,0.003169,0.080505,53.466801,2.723729,0.805046,-1297.553833,0.079412,0.000000
125.690002,10.465157,-1297.553833,-0.000957,0.003145,0.079871,46.551342,2.371438,0.798715,-1297.553833,0.078709,0.000000
126.110008,7.088486,-1297.553833,-0.000953,0.003116,0.079143,31.531158,1.606274,0.791430,-1297.553833,0.078007,0.000000
126.530006,4.175789,-1297.509399,-0.000961,0.003082,0.078284,18.574837,0.946247,0.782845,-1297.509399,0.077313,0.000000
126.950005,2.507927,-1297.509399,-0.000961,0.003062,0.077773,11.155816,0.568304,0.777728,-1297.509399,0.076611,0.000000
127.370003,0.576805,-1297.509399,-0.000974,0.003038,0.077157,2.565757,0.130706,0.771571,-1297.509399,0.075908,0.000000
127.790009,0.139641,-1297.553833,-0.000987,0.003003,0.076264,0.621153,0.031643,0.762638,-1297.553833,0.075206,0.000000
128.210007,0.065170,-1297.464844,-0.001026,0.002974,0.075544,0.289892,0.014768,0.755440,-1297.464844,0.074512,0.000000
128.630005,0.059952,-1297.553833,-0.001061,0.002944,0.074790,0.266679,0.013585,0.747895,-1297.553833,0.073810,0.000000
129.050003,0.042824,-1297.509399,-0.001104,0.002919,0.074139,0.190490,0.009704,0.741391,-1297.509399,0.073107,0.000000
129.470001,0.044312,-1297.509399,-0.001121,0.002909,0.073896,0.197107,0.010041,0.738963,-1297.509399,0.072413,0.000000
129.889999,0.013039,-1297.509399,-0.001181,0.002876,0.073055,0.057999,0.002955,0.730551,-1297.509399,0.071711,0.000000
130.310013,0.016388,-1297.598267,-0.001237,0.002830,0.071893,0.072897,0.003714,0.718930,-1297.598267,0.071008,0.000000
130.730011,0.017128,-1297.553833,-0.001255,0.002807,0.071295,0.076189,0.003881,0.712946,-1297.553833,0.070306,0.000000
131.150009,0.039474,-1297.464844,-0.001250,0.002797,0.071052,0.175591,0.008945,0.710518,-1297.464844,0.069612,0.000000
131.570007,0.016014,-1297.509399,-0.001285,0.002754,0.069959,0.071234,0.003629,0.699591,-1297.509399,0.068910,0.000000
131.990005,0.027557,-1297.553833,-0.001337,0.002728,0.069300,0.122581,0.006245,0.693000,-1297.553833,0.068207,0.000000
132.410004,0.037613,-1297.598267,-0.001358,0.002694,0.068424,0.167311,0.008523,0.684241,-1297.598267,0.067505,0.000000
132.830002,0.071869,-1297.598267,-0.001401,0.002667,0.067748,0.319689,0.016286,0.677477,-1297.598267,0.066811,0.000000
133.250000,0.053993,-1297.509399,-0.001414,0.002641,0.067071,0.240174,0.012235,0.670712,-1297.509399,0.066109,0.000000
133.670013,0.029793,-1297.553833,-0.001444,0.002619,0.066516,0.132525,0.006751,0.665162,-1297.553833,0.065406,0.000000
134.090012,0.032402,-1297.509399,-0.001470,0.002584,0.065623,0.144131,0.007342,0.656230,-1297.509399,0.064712,0.000000
134.510010,0.057716,-1297.598267,-0.001509,0.002559,0.064990,0.256735,0.013079,0.649899,-1297.598267,0.064010,0.000000
134.930008,0.049896,-1297.553833,-0.001526,0.002534,0.064357,0.221950,0.011307,0.643568,-1297.553833,0.063307,0.000000
135.350006,0.057350,-1297.553833,-0.001569,0.002498,0.063438,0.255106,0.012996,0.634376,-1297.553833,0.062605,0.000000
135.770004,0.042084,-1297.598267,-0.001587,0.002476,0.062883,0.187198,0.009536,0.628825,-1297.598267,0.061911,0.000000
136.190002,0.030167,-1297.598267,-0.001625,0.002445,0.062102,0.134188,0.006836,0.621020,-1297.598267,0.061209,0.000000
136.610001,0.039101,-1297.598267,-0.001647,0.002417,0.061400,0.173928,0.008860,0.613996,-1297.598267,0.060506,0.000000
137.030014,0.034630,-1297.553833,-0.001660,0.002398,0.060905,0.154041,0.007847,0.609053,-1297.553833,0.059813,0.000000
137.450012,0.052132,-1297.553833,-0.001712,0.002361,0.059969,0.231893,0.011813,0.599687,-1297.553833,0.059110,0.000000
137.870010,0.039101,-1297.598267,-0.001716,0.002352,0.059743,0.173928,0.008860,0.597432,-1297.598267,0.058408,0.000000
138.290009,0.034264,-1297.553833,-0.001763,0.002310,0.058668,0.152412,0.007764,0.586678,-1297.553833,0.057705,0.000000
138.710007,0.012291,-1297.598267,-0.001785,0.002286,0.058069,0.054673,0.002785,0.580694,-1297.598267,0.057011,0.000000
139.130005,0.038353,-1297.553833,-0.001802,0.002281,0.057931,0.170603,0.008691,0.579307,-1297.553833,0.056309,0.000000
139.550003,0.035004,-1297.598267,-0.001850,0.002234,0.056751,0.155704,0.007932,0.567513,-1297.598267,0.055607,0.000000
139.970001,0.032402,-1297.598267,-0.001888,0.002199,0.055867,0.144131,0.007342,0.558667,-1297.598267,0.054904,0.000000
140.389999,0.035751,-1297.598267,-0.001897,0.002179,0.055355,0.159030,0.008101,0.553550,-1297.598267,0.054210,0.000000
140.810013,0.020851,-1297.598267,-0.001910,0.002161,0.054895,0.092750,0.004725,0.548954,-1297.598267,0.053508,0.000000
141.230011,0.029045,-1297.598267,-0.001962,0.002119,0.053811,0.129199,0.006582,0.538114,-1297.598267,0.052805,0.000000
141.650009,0.025322,-1297.553833,-0.001988,0.002090,0.053074,0.112638,0.005738,0.530742,-1297.553833,0.052112,0.000000
142.070007,0.007820,-1297.553833,-0.002026,0.002062,0.052372,0.034786,0.001772,0.523718,-1297.553833,0.051409,0.000000
142.490005,0.002983,-1297.642822,-0.002035,0.002033,0.051635,0.013269,0.000676,0.516346,-1297.642822,0.050707,0.000000
142.910004,0.004097,-1297.598267,-0.002070,0.002028,0.051522,0.018224,0.000928,0.515219,-1297.598267,0.050004,0.000000
143.330002,0.007446,-1297.553833,-0.002095,0.001983,0.050377,0.033123,0.001687,0.503771,-1297.553833,0.049310,0.000000
143.750000,-0.005959,-1297.598267,-0.002139,0.001953,0.049597,-0.026505,-0.001350,0.495966,-1297.598267,0.048608,0.000000
144.170013,-0.010422,-1297.598267,-0.002160,0.001926,0.048912,-0.046358,-0.002362,0.489115,-1297.598267,0.047906,0.000000
144.590012,-0.009308,-1297.642822,-0.002160,0.001910,0.048513,-0.041403,-0.002109,0.485126,-1297.642822,0.047212,0.000000
145.010010,0.020485,-1297.509399,-0.002216,0.001868,0.047437,0.091121,0.004642,0.474372,-1297.509399,0.046509,0.000000
145.430008,-0.006325,-1297.598267,-0.002238,0.001842,0.046796,-0.028134,-0.001433,0.467955,-1297.598267,0.045807,0.000000
145.850006,-0.020477,-1297.598267,-0.002276,0.001814,0.046076,-0.091088,-0.004640,0.460757,-1297.598267,0.045104,0.000000
146.270004,-0.001488,-1297.642822,-0.002307,0.001790,0.045469,-0.006618,-0.000337,0.454687,-1297.642822,0.044411,0.000000
146.690002,0.000374,-1297.642822,-0.002328,0.001772,0.045009,0.001663,0.000085,0.450090,-1297.642822,0.043708,0.000000
147.110001,0.007820,-1297.598267,-0.002350,0.001738,0.044142,0.034786,0.001772,0.441418,-1297.598267,0.043006,0.000000
147.530014,-0.000740,-1297.553833,-0.002389,0.001706,0.043335,-0.003292,-0.000168,0.433353,-1297.553833,0.042303,0.000000
147.950012,0.001495,-1297.553833,-0.002436,0.001676,0.042563,0.006652,0.000339,0.425634,-1297.553833,0.041609,0.000000
148.370010,0.027557,-1297.598267,-0.002436,0.001654,0.042000,0.122581,0.006245,0.419997,-1297.598267,0.040907,0.000000
148.790009,0.025696,-1297.642822,-0.002453,0.001638,0.041601,0.114301,0.005823,0.416008,-1297.642822,0.040205,0.000000
149.210007,0.016388,-1297.642822,-0.002496,0.001600,0.040638,0.072897,0.003714,0.406382,-1297.642822,0.039511,0.000000
149.630005,0.026810,-1297.598267,-0.002518,0.001564,0.039728,0.119255,0.006075,0.397276,-1297.598267,0.038808,0.000000
150.050003,-0.011543,-1297.553833,-0.002557,0.001540,0.039121,-0.051347,-0.002616,0.391206,-1297.553833,0.038106,0.000000
150.470001,0.003357,-1297.598267,-0.002583,0.001515,0.038479,0.014932,0.000761,0.384788,-1297.598267,0.037403,0.000000
150.890015,-0.013405,-1297.642822,-0.002604,0.001486,0.037750,-0.059628,-0.003038,0.377503,-1297.642822,0.036710,0.000000
151.310013,-0.001862,-1297.642822,-0.002647,0.001458,0.037039,-0.008281,-0.000422,0.370392,-1297.642822,0.036007,0.000000
151.730011,0.008942,-1297.642822,-0.002669,0.001425,0.036189,0.039774,0.002026,0.361893,-1297.642822,0.035305,0.000000
152.150009,0.007820,-1297.598267,-0.002682,0.001406,0.035712,0.034786,0.001772,0.357124,-1297.598267,0.034611,0.000000
152.570007,0.012665,-1297.687256,-0.002721,0.001380,0.035045,0.056336,0.002870,0.350446,-1297.687256,0.033909,0.000000
152.990005,0.007820,-1297.687256,-0.002746,0.001356,0.034446,0.034786,0.001772,0.344462,-1297.687256,0.033206,0.000000
153.410004,0.027931,-1297.598267,-0.002772,0.001316,0.033423,0.124244,0.006329,0.334229,-1297.598267,0.032504,0.000000
153.830002,0.027184,-1297.598267,-0.002820,0.001290,0.032755,0.120918,0.006160,0.327551,-1297.598267,0.031810,0.000000
154.250000,0.038727,-1297.642822,-0.002828,0.001275,0.032374,0.172265,0.008776,0.323735,-1297.642822,0.031107,0.000000
154.670013,0.036865,-1297.642822,-0.002863,0.001238,0.031446,0.163985,0.008354,0.314456,-1297.642822,0.030405,0.000000
155.090012,0.051392,-1297.598267,-0.002867,0.001214,0.030839,0.228601,0.011646,0.308386,-1297.598267,0.029702,0.000000
155.510010,0.022346,-1297.598267,-0.002910,0.001176,0.029859,0.099402,0.005064,0.298586,-1297.598267,0.029009,0.000000
155.930008,0.056602,-1297.553833,-0.002949,0.001153,0.029295,0.251780,0.012826,0.292949,-1297.553833,0.028306,0.000000
156.350006,0.056602,-1297.642822,-0.002953,0.001129,0.028670,0.251780,0.012826,0.286705,-1297.642822,0.027604,0.000000
156.770004,0.058464,-1297.687256,-0.003009,0.001094,0.027777,0.260061,0.013248,0.277772,-1297.687256,0.026910,0.000000
157.190002,0.040962,-1297.687256,-0.003018,0.001067,0.027109,0.182209,0.009282,0.271095,-1297.687256,0.026208,0.000000
157.610001,0.019363,-1297.598267,-0.003057,0.001039,0.026381,0.086133,0.004388,0.263810,-1297.598267,0.025505,0.000000
158.030014,0.036491,-1297.642822,-0.003078,0.001014,0.025748,0.162322,0.008269,0.257479,-1297.642822,0.024803,0.000000
158.450012,0.021225,-1297.642822,-0.003104,0.000990,0.025150,0.094413,0.004810,0.251496,-1297.642822,0.024109,0.000000
158.870010,0.035751,-1297.642822,-0.003147,0.000960,0.024378,0.159030,0.008101,0.243777,-1297.642822,0.023406,0.000000
159.290009,0.038727,-1297.642822,-0.003173,0.000929,0.023597,0.172265,0.008776,0.235972,-1297.642822,0.022704,0.000000
159.710007,0.011543,-1297.598267,-0.003208,0.000905,0.022981,0.051347,0.002616,0.229815,-1297.598267,0.022010,0.000000
160.130005,0.014900,-1297.642822,-0.003238,0.000881,0.022374,0.066279,0.003376,0.223744,-1297.642822,0.021308,0.000000
160.550003,-0.003723,-1297.687256,-0.003272,0.000850,0.021594,-0.016561,-0.000844,0.215939,-1297.687256,0.020605,0.000000
160.970001,0.016014,-1297.687256,-0.003294,0.000827,0.021004,0.071234,0.003629,0.210042,-1297.687256,0.019903,0.000000
161.390015,0.023460,-1297.642822,-0.003320,0.000793,0.020154,0.104357,0.005316,0.201543,-1297.642822,0.019209,0.000000
161.810013,0.021599,-1297.553833,-0.003333,0.000765,0.019443,0.096076,0.004894,0.194432,-1297.553833,0.018507,0.000000
162.230011,0.017502,-1297.598267,-0.003359,0.000741,0.018827,0.077852,0.003966,0.188275,-1297.598267,0.017804,0.000000
162.650009,0.040962,-1297.598267,-0.003415,0.000710,0.018038,0.182209,0.009282,0.180383,-1297.598267,0.017102,0.000000
163.070007,0.026443,-1297.642822,-0.003428,0.000690,0.017518,0.117626,0.005992,0.175180,-1297.642822,0.016408,0.000000
163.490005,0.013405,-1297.598267,-0.003466,0.000655,0.016633,0.059628,0.003038,0.166334,-1297.598267,0.015705,0.000000
163.910004,0.000374,-1297.642822,-0.003479,0.000630,0.016000,0.001663,0.000085,0.160003,-1297.642822,0.015003,0.000000
164.330002,0.003723,-1297.642822,-0.003518,0.000601,0.015263,0.016561,0.000844,0.152632,-1297.642822,0.014309,0.000000
164.750015,-0.006325,-1297.642822,-0.003548,0.000586,0.014890,-0.028134,-0.001433,0.148903,-1297.642822,0.013607,0.000000
165.170013,-0.002602,-1297.687256,-0.003570,0.000545,0.013850,-0.011573,-0.000590,0.138496,-1297.687256,0.012904,0.000000
165.590012,-0.016754,-1297.642822,-0.003574,0.000521,0.013243,-0.074526,-0.003797,0.132425,-1297.642822,0.012202,0.000000
166.010010,-0.010056,-1297.642822,-0.003622,0.000491,0.012471,-0.044729,-0.002279,0.124707,-1297.642822,0.011508,0.000000
166.430008,-0.007820,-1297.642822,-0.003660,0.000465,0.011820,-0.034786,-0.001772,0.118203,-1297.642822,0.010806,0.000000
166.850006,0.002609,-1297.642822,-0.003660,0.000454,0.011525,0.011607,0.000591,0.115254,-1297.642822,0.010103,0.000000
167.270004,-0.014893,-1297.642822,-0.003712,0.000408,0.010372,-0.066245,-0.003375,0.103720,-1297.642822,0.009401,0.000000
167.690002,-0.007446,-1297.642822,-0.003734,0.000387,0.009826,-0.033123,-0.001687,0.098257,-1297.642822,0.008707,0.000000
168.110001,0.000748,-1297.642822,-0.003755,0.000356,0.009045,0.003326,0.000169,0.090452,-1297.642822,0.008004,0.000000
168.530014,-0.007820,-1297.642822,-0.003794,0.000334,0.008481,-0.034786,-0.001772,0.084815,-1297.642822,0.007302,0.000000
168.950012,-0.018616,-1297.731689,-0.003816,0.000298,0.007562,-0.082807,-0.004218,0.075622,-1297.731689,0.006608,0.000000
169.370010,-0.019363,-1297.687256,-0.003850,0.000273,0.006929,-0.086133,-0.004388,0.069291,-1297.687256,0.005906,0.000000
169.790009,0.002609,-1297.687256,-0.003867,0.000245,0.006218,0.011607,0.000591,0.062180,-1297.687256,0.005203,0.000000
170.210007,0.004097,-1297.731689,-0.003898,0.000221,0.005611,0.018224,0.000928,0.056110,-1297.731689,0.004501,0.000000
170.630005,-0.009682,-1297.687256,-0.003923,0.000193,0.004909,-0.043066,-0.002194,0.049085,-1297.687256,0.003807,0.000000
171.050003,0.022346,-1297.642822,-0.003962,0.000157,0.003989,0.099402,0.005064,0.039892,-1297.642822,0.003105,0.000000
171.470001,0.010803,-1297.731689,-0.003984,0.000129,0.003287,0.048055,0.002448,0.032868,-1297.731689,0.002402,0.000000
171.890015,0.009308,-1297.731689,-0.004010,0.000116,0.002957,0.041403,0.002109,0.029572,-1297.731689,0.001708,0.000000
172.310013,-0.009308,-1297.687256,-0.004023,0.000088,0.002229,-0.041403,-0.002109,0.022288,-1297.687256,0.001006,0.000000
172.730011,-0.013031,-1297.687256,-0.004066,0.000046,0.001162,-0.057965,-0.002953,0.011621,-1297.687256,0.000304,0.000000
173.150009,-0.002975,-1297.687256,-0.004109,0.000019,0.000494,-0.013236,-0.000674,0.004943,-1297.687256,-0.000399,0.000000
173.570007,0.002235,-1297.687256,-0.004122,0.000002,0.000043,0.009944,0.000507,0.000434,-1297.687256,-0.001093,0.000000
173.900009,0.026443,-1297.687256,-0.004126,-0.000000,-0.000009,0.117626,0.005992,-0.000087,-1297.687256,-0.000035,0.000000