File: Data/compression 7/AutoHeating-12-7-1-2-240320_03202024_203323.csv
Time (sec),S:Load (lbs),S:HL1 (DIM),S:LVDT (in),S:Position (in),Ch:Position (mm),Ch:Load (N),Ch:Stress (MPa),Ch:Strain (mm/mm),Ch:HL1 (DIM),Set Point (),Cycles ()
0.010000,-0.011917,-580.254028,0.000026,-0.000000,-0.000000,-0.053010,-0.002700,-0.000000,-580.254028,0.000277,0.000000
0.280000,-0.004471,-580.298462,0.000022,-0.000000,-0.000000,-0.019887,-0.001013,-0.000000,-580.298462,0.000277,0.000000
0.550000,0.031281,-580.298462,0.000013,0.000116,0.002948,0.139143,0.007088,0.029484,-580.298462,0.003833,0.000000
0.820000,0.026810,-580.298462,0.000138,0.000287,0.007293,0.119255,0.006075,0.072935,-580.298462,0.008325,0.000000
1.090000,-0.015266,-580.254028,0.000310,0.000462,0.011734,-0.067908,-0.003459,0.117336,-580.254028,0.012818,0.000000
1.360000,0.038727,-580.298462,0.000474,0.000637,0.016174,0.172265,0.008776,0.161736,-580.298462,0.017327,0.000000
1.630000,0.017128,-580.387451,0.000664,0.000822,0.020891,0.076189,0.003881,0.208915,-580.387451,0.021820,0.000000
1.900000,0.011917,-580.298462,0.000836,0.000997,0.025332,0.053010,0.002700,0.253315,-580.298462,0.026311,0.000000
2.170000,0.054741,-580.387451,0.001000,0.001163,0.029546,0.243500,0.012404,0.295464,-580.387451,0.030821,0.000000
2.440000,0.027931,-580.387451,0.001194,0.001348,0.034238,0.124244,0.006329,0.342382,-580.387451,0.035313,0.000000
2.710000,0.052132,-580.387451,0.001362,0.001522,0.038661,0.231893,0.011813,0.386608,-580.387451,0.039806,0.000000
2.980000,0.049896,-580.387451,0.001569,0.001709,0.043396,0.221950,0.011307,0.433961,-580.387451,0.044315,0.000000
3.250000,0.018990,-580.387451,0.001738,0.001874,0.047611,0.084470,0.004303,0.476106,-580.387451,0.048807,0.000000
3.520000,0.042824,-580.342957,0.001893,0.002051,0.052085,0.190490,0.009704,0.520855,-580.342957,0.053300,0.000000
3.790000,-0.012291,-580.387451,0.002082,0.002235,0.056760,-0.054673,-0.002785,0.567598,-580.387451,0.057809,0.000000
4.060000,0.044312,-580.431946,0.002268,0.002414,0.061304,0.197107,0.010041,0.613043,-580.431946,0.062302,0.000000
4.330000,0.069633,-580.431946,0.002427,0.002589,0.065762,0.309745,0.015779,0.657618,-580.431946,0.066794,0.000000
4.600000,0.033142,-580.431946,0.002608,0.002766,0.070254,0.147423,0.007510,0.702541,-580.431946,0.071303,0.000000
4.870000,0.067398,-580.387451,0.002807,0.002936,0.074581,0.299802,0.015273,0.745814,-580.387451,0.075796,0.000000
5.140000,0.019737,-580.387451,0.002966,0.003119,0.079230,0.087796,0.004473,0.792296,-580.387451,0.080288,0.000000
5.410000,0.044685,-580.476440,0.003147,0.003297,0.083739,0.198770,0.010126,0.837393,-580.476440,0.084797,0.000000
5.680000,0.031654,-580.431946,0.003341,0.003472,0.088197,0.140806,0.007173,0.881968,-580.431946,0.089289,0.000000
5.950000,-0.006706,-580.431946,0.003531,0.003653,0.092776,-0.029831,-0.001520,0.927757,-580.431946,0.093782,0.000000
6.220000,0.065536,-580.431946,0.003704,0.003821,0.097060,0.291521,0.014851,0.970598,-580.431946,0.098291,0.000000
6.490000,0.044685,-580.476440,0.003885,0.004006,0.101743,0.198770,0.010126,1.017429,-580.476440,0.102784,0.000000
6.760000,0.040588,-580.476440,0.004061,0.004185,0.106287,0.180546,0.009197,1.062870,-580.476440,0.107276,0.000000
7.030000,0.051018,-580.520874,0.004225,0.004353,0.110562,0.226938,0.011561,1.105625,-580.520874,0.111785,0.000000
7.300000,0.042076,-580.476440,0.004411,0.004532,0.115124,0.187164,0.009535,1.151240,-580.476440,0.116278,0.000000
7.570000,0.065910,-580.520874,0.004600,0.004709,0.119608,0.293184,0.014935,1.196076,-580.520874,0.120770,0.000000
7.840000,0.033142,-580.476440,0.004769,0.004895,0.124325,0.147423,0.007510,1.243255,-580.476440,0.125279,0.000000
8.110001,0.060699,-580.476440,0.004928,0.005066,0.128679,0.270005,0.013755,1.286789,-580.476440,0.129772,0.000000
8.380000,0.075218,-580.565369,0.005083,0.005239,0.133067,0.334587,0.017045,1.330671,-580.565369,0.134264,0.000000
8.650001,0.053246,-580.520874,0.005295,0.005419,0.137646,0.236848,0.012066,1.376460,-580.520874,0.138774,0.000000
8.920000,0.071869,-580.520874,0.005467,0.005592,0.142043,0.319689,0.016286,1.420429,-580.520874,0.143265,0.000000
9.190001,0.090111,-580.565369,0.005631,0.005777,0.146726,0.400833,0.020419,1.467260,-580.565369,0.147775,0.000000
9.460000,0.265129,-580.609863,0.005808,0.005950,0.151123,1.179353,0.060079,1.511225,-580.609863,0.152267,0.000000
9.730000,0.657608,-580.654358,0.005902,-0.000003,-0.000069,2.925187,0.149016,-0.000693,-580.654358,0.000121,0.000000
10.000000,0.610321,-580.565369,0.005894,-0.000003,-0.000078,2.714844,0.138301,-0.000780,-580.565369,0.000121,0.000000
10.270000,0.613670,-580.565369,0.005907,-0.000003,-0.000087,2.729742,0.139060,-0.000867,-580.565369,0.000347,0.000000
10.540001,0.590210,-580.520874,0.005907,-0.000003,-0.000078,2.625385,0.133743,-0.000780,-580.520874,0.000798,0.000000
10.810000,0.588722,-580.609863,0.005911,0.000013,0.000338,2.618767,0.133406,0.003380,-580.609863,0.001249,0.000000
11.080001,0.818848,-580.654358,0.005920,0.000031,0.000798,3.642416,0.185554,0.007979,-580.654358,0.001691,0.000000
11.350000,1.043762,-580.565369,0.005924,0.000052,0.001327,4.642886,0.236520,0.013270,-580.565369,0.002142,0.000000
11.620001,1.122704,-580.654358,0.005946,0.000067,0.001709,4.994035,0.254408,0.017085,-580.654358,0.002593,0.000000
11.890000,1.212448,-580.609863,0.005954,0.000081,0.002046,5.393239,0.274745,0.020465,-580.609863,0.003044,0.000000
12.160001,1.446297,-580.698792,0.005989,0.000107,0.002715,6.433449,0.327736,0.027145,-580.698792,0.003495,0.000000
12.430000,1.547211,-580.654358,0.006002,0.000123,0.003113,6.882337,0.350603,0.031135,-580.654358,0.003946,0.000000
12.700001,1.687592,-580.654358,0.006002,0.000140,0.003547,7.506782,0.382414,0.035468,-580.654358,0.004397,0.000000
12.970000,1.784409,-580.565369,0.006023,0.000153,0.003876,7.937446,0.404353,0.038765,-580.565369,0.004848,0.000000
13.240001,2.037994,-580.654358,0.006028,0.000175,0.004440,9.065452,0.461816,0.044401,-580.654358,0.005299,0.000000
13.510000,2.163857,-580.698792,0.006062,0.000192,0.004865,9.625315,0.490337,0.048651,-580.698792,0.005741,0.000000
13.780001,2.280411,-580.654358,0.006075,0.000207,0.005247,10.143774,0.516748,0.052466,-580.654358,0.006192,0.000000
14.050000,2.490799,-580.609863,0.006084,0.000225,0.005724,11.079627,0.564423,0.057235,-580.609863,0.006643,0.000000
14.320001,2.694489,-580.654358,0.006114,0.000250,0.006339,11.985683,0.610580,0.063393,-580.654358,0.007094,0.000000
14.590001,2.671402,-580.654358,0.006118,0.000262,0.006652,11.882990,0.605348,0.066516,-580.654358,0.007545,0.000000
14.860001,2.870247,-580.743286,0.006140,0.000281,0.007137,12.767496,0.650407,0.071372,-580.743286,0.007996,0.000000
15.130001,2.991264,-580.743286,0.006161,0.000294,0.007467,13.305808,0.677830,0.074668,-580.743286,0.008447,0.000000
15.400001,3.221764,-580.698792,0.006170,0.000313,0.007961,14.331120,0.730062,0.079611,-580.698792,0.008898,0.000000
15.670001,3.365501,-580.743286,0.006191,0.000332,0.008429,14.970498,0.762634,0.084293,-580.743286,0.009349,0.000000
15.940001,3.371834,-580.743286,0.006196,0.000345,0.008759,14.998666,0.764068,0.087590,-580.743286,0.009799,0.000000
16.210001,3.771019,-580.743286,0.006217,0.000373,0.009479,16.774330,0.854525,0.094789,-580.743286,0.010242,0.000000
16.480001,3.797455,-580.698792,0.006243,0.000390,0.009912,16.891922,0.860516,0.099123,-580.698792,0.010693,0.000000
16.750000,3.950874,-580.743286,0.006273,0.000407,0.010346,17.574368,0.895281,0.103460,-580.743286,0.011144,0.000000
17.020000,4.055511,-580.743286,0.006273,0.000421,0.010701,18.039816,0.918992,0.107014,-580.743286,0.011595,0.000000
17.290001,4.226051,-580.743286,0.006282,0.000437,0.011092,18.798414,0.957637,0.110916,-580.743286,0.012046,0.000000
17.560001,4.388412,-580.743286,0.006299,0.000453,0.011517,19.520634,0.994428,0.115167,-580.743286,0.012497,0.000000
17.830000,4.476662,-580.787781,0.006321,0.000468,0.011881,19.913185,1.014426,0.118808,-580.787781,0.012948,0.000000
18.100000,4.835625,-580.698792,0.006329,0.000496,0.012609,21.509933,1.095768,0.126094,-580.698792,0.013399,0.000000
18.370001,4.898560,-580.743286,0.006329,0.000513,0.013034,21.789881,1.110029,0.130344,-580.743286,0.013850,0.000000
18.640001,4.873611,-580.787781,0.006342,0.000528,0.013399,21.678907,1.104376,0.133985,-580.787781,0.014292,0.000000
18.910002,5.142090,-580.787781,0.006372,0.000547,0.013902,22.873158,1.165214,0.139015,-580.787781,0.014743,0.000000
19.180000,5.314499,-580.787781,0.006407,0.000566,0.014378,23.640072,1.204283,0.143784,-580.787781,0.015194,0.000000
19.450001,5.345032,-580.743286,0.006403,0.000580,0.014734,23.775888,1.211202,0.147342,-580.743286,0.015645,0.000000
19.720001,5.362160,-580.787781,0.006424,0.000590,0.014986,23.852077,1.215083,0.149855,-580.787781,0.016096,0.000000
19.990002,5.843269,-580.787781,0.006428,0.000617,0.015679,25.992161,1.324104,0.156793,-580.787781,0.016547,0.000000
20.260000,5.935989,-580.787781,0.006446,0.000635,0.016122,26.404600,1.345114,0.161218,-580.787781,0.016998,0.000000
20.530001,5.956467,-580.787781,0.006467,0.000652,0.016564,26.495687,1.349755,0.165638,-580.787781,0.017448,0.000000
20.800001,6.057381,-580.876770,0.006467,0.000667,0.016946,26.944574,1.372622,0.169457,-580.876770,0.017900,0.000000
21.070002,6.327728,-580.832275,0.006493,0.000689,0.017509,28.147141,1.433884,0.175093,-580.832275,0.018342,0.000000
21.340000,6.378738,-580.832275,0.006510,0.000704,0.017891,28.374046,1.445443,0.178908,-580.832275,0.018793,0.000000
21.610001,6.361610,-580.876770,0.006519,0.000716,0.018177,28.297857,1.441561,0.181770,-580.876770,0.019244,0.000000
21.880001,6.709778,-580.876770,0.006545,0.000740,0.018793,29.846582,1.520457,0.187928,-580.876770,0.019695,0.000000
22.150002,6.805855,-580.876770,0.006549,0.000758,0.019252,30.273954,1.542229,0.192522,-580.876770,0.020145,0.000000
22.420002,6.881813,-580.832275,0.006549,0.000774,0.019660,30.611834,1.559441,0.196599,-580.832275,0.020597,0.000000
22.690001,7.079170,-580.921204,0.006571,0.000795,0.020189,31.489721,1.604163,0.201890,-580.921204,0.021047,0.000000
22.960001,7.288071,-580.876770,0.006601,0.000815,0.020701,32.418957,1.651500,0.207007,-580.876770,0.021499,0.000000
23.230001,7.329033,-580.876770,0.006597,0.000831,0.021117,32.601166,1.660783,0.211171,-580.876770,0.021949,0.000000
23.500002,7.281746,-580.832275,0.006614,0.000844,0.021429,32.390823,1.650067,0.214289,-580.832275,0.022401,0.000000
23.770000,7.701035,-580.921204,0.006640,0.000867,0.022010,34.255913,1.745079,0.220103,-580.921204,0.022843,0.000000
24.040001,7.710342,-580.832275,0.006640,0.000882,0.022392,34.297318,1.747189,0.223918,-580.832275,0.023294,0.000000
24.310001,7.861526,-580.921204,0.006666,0.000901,0.022877,34.969818,1.781447,0.228774,-580.921204,0.023745,0.000000
24.580002,8.017921,-580.965698,0.006687,0.000920,0.023372,35.665497,1.816887,0.233717,-580.965698,0.024196,0.000000
24.850000,8.020157,-580.876770,0.006704,0.000932,0.023675,35.675438,1.817394,0.236753,-580.876770,0.024646,0.000000
25.120001,8.144157,-580.921204,0.006704,0.000951,0.024152,36.227020,1.845492,0.241522,-580.921204,0.025098,0.000000
25.390001,8.026115,-580.965698,0.006700,0.000960,0.024378,35.701946,1.818744,0.243778,-580.965698,0.025548,0.000000
25.660002,8.226082,-580.921204,0.006713,0.000978,0.024829,36.591438,1.864057,0.248285,-580.921204,0.025999,0.000000
25.930000,8.729897,-580.921204,0.006735,0.001005,0.025522,38.832520,1.978223,0.255223,-580.921204,0.026450,0.000000
26.200001,8.774956,-580.832275,0.006756,0.001021,0.025930,39.032951,1.988433,0.259299,-580.832275,0.026892,0.000000
26.470001,8.856133,-580.876770,0.006778,0.001039,0.026398,39.394043,2.006828,0.263981,-580.876770,0.027344,0.000000
26.740002,8.979019,-580.965698,0.006773,0.001058,0.026867,39.940674,2.034675,0.268667,-580.965698,0.027794,0.000000
27.010002,9.108604,-580.965698,0.006791,0.001077,0.027344,40.517097,2.064039,0.273436,-580.965698,0.028246,0.000000
27.280001,9.081421,-580.921204,0.006812,0.001091,0.027708,40.396179,2.057879,0.277077,-580.921204,0.028696,0.000000
27.550001,9.162224,-580.921204,0.006825,0.001103,0.028020,40.755608,2.076190,0.280200,-580.921204,0.029147,0.000000
27.820002,9.730835,-580.876770,0.006825,0.001133,0.028775,43.284916,2.205039,0.287747,-580.876770,0.029598,0.000000
28.090002,9.620613,-581.010193,0.006838,0.001147,0.029130,42.794624,2.180062,0.291301,-581.010193,0.030049,0.000000
28.360001,9.717804,-581.010193,0.006842,0.001165,0.029598,43.226952,2.202086,0.295983,-581.010193,0.030500,0.000000
28.630001,9.768074,-580.965698,0.006890,0.001181,0.029988,43.450562,2.213477,0.299885,-580.965698,0.030943,0.000000
28.900002,9.860794,-580.965698,0.006877,0.001197,0.030396,43.863003,2.234488,0.303961,-580.965698,0.031393,0.000000
29.170002,9.959473,-580.965698,0.006885,0.001212,0.030795,44.301949,2.256849,0.307950,-580.965698,0.031845,0.000000
29.440001,10.509842,-581.010193,0.006907,0.001240,0.031489,46.750111,2.381564,0.314888,-581.010193,0.032295,0.000000
29.710001,10.696030,-581.099121,0.006920,0.001261,0.032027,47.578316,2.423755,0.320266,-581.099121,0.032747,0.000000
29.980001,10.499786,-581.010193,0.006954,0.001273,0.032330,46.705383,2.379286,0.323302,-581.010193,0.033197,0.000000
30.250002,10.548195,-581.010193,0.006954,0.001290,0.032764,46.920715,2.390255,0.327636,-581.010193,0.033648,0.000000
30.520002,10.607399,-581.054687,0.006963,0.001304,0.033128,47.184067,2.403671,0.331280,-581.054687,0.034099,0.000000
30.790001,10.870667,-581.054687,0.006963,0.001324,0.033640,48.355141,2.463328,0.336398,-581.054687,0.034550,0.000000
31.060001,10.984612,-581.010193,0.006989,0.001340,0.034039,48.861992,2.489148,0.340387,-581.010193,0.035001,0.000000
31.330002,11.149948,-580.965698,0.006993,0.001358,0.034489,49.597446,2.526614,0.344895,-580.965698,0.035444,0.000000
31.600002,11.532372,-581.054687,0.007011,0.001382,0.035105,51.298550,2.613273,0.351053,-581.054687,0.035894,0.000000
31.870001,11.479126,-581.054687,0.007036,0.001397,0.035478,51.061703,2.601207,0.354781,-581.054687,0.036345,0.000000
32.140003,11.429230,-581.099121,0.007036,0.001414,0.035912,50.839752,2.589900,0.359118,-581.099121,0.036796,0.000000
32.410000,11.351402,-581.143616,0.007045,0.001425,0.036189,50.493561,2.572264,0.361893,-581.143616,0.037247,0.000000
32.680000,11.991508,-581.099121,0.007071,0.001451,0.036857,53.340893,2.717314,0.368569,-581.099121,0.037698,0.000000
32.950001,11.913315,-581.010193,0.007080,0.001463,0.037152,52.993073,2.699596,0.371518,-581.010193,0.038149,0.000000
33.220001,11.824684,-581.010193,0.007088,0.001477,0.037525,52.598824,2.679512,0.375250,-581.010193,0.038600,0.000000
33.490002,12.544113,-581.099121,0.007092,0.001506,0.038253,55.799004,2.842537,0.382532,-581.099121,0.039051,0.000000
33.760002,12.416756,-581.143616,0.007114,0.001522,0.038652,55.232487,2.813677,0.386521,-581.143616,0.039493,0.000000
34.030003,12.421974,-581.143616,0.007144,0.001539,0.039086,55.255699,2.814860,0.390859,-581.143616,0.039944,0.000000
34.300003,12.359413,-581.099121,0.007136,0.001551,0.039389,54.977417,2.800683,0.393894,-581.099121,0.040395,0.000000
34.570004,12.779449,-581.099121,0.007131,0.001573,0.039953,56.845829,2.895865,0.399530,-581.099121,0.040846,0.000000
34.840000,12.878502,-581.099121,0.007157,0.001587,0.040309,57.286438,2.918310,0.403088,-581.099121,0.041297,0.000000
35.110001,12.976433,-581.143616,0.007174,0.001605,0.040777,57.722057,2.940502,0.407769,-581.143616,0.041748,0.000000
35.380001,13.118309,-581.099121,0.007170,0.001625,0.041263,58.353153,2.972651,0.412625,-581.099121,0.042199,0.000000
35.650002,13.628090,-581.143616,0.007192,0.001649,0.041878,60.620773,3.088169,0.418783,-581.143616,0.042650,0.000000
35.920002,13.318275,-581.188110,0.007200,0.001663,0.042251,59.242649,3.017964,0.422512,-581.188110,0.043101,0.000000
36.190002,13.389397,-581.188110,0.007226,0.001679,0.042659,59.559010,3.034081,0.426588,-581.188110,0.043543,0.000000
36.460003,13.348061,-581.188110,0.007235,0.001693,0.042997,59.375137,3.024714,0.429972,-581.188110,0.043994,0.000000
36.730003,13.699951,-581.143616,0.007239,0.001715,0.043561,60.940426,3.104453,0.435607,-581.143616,0.044445,0.000000
37.000000,13.790817,-581.099121,0.007248,0.001731,0.043960,61.344620,3.125044,0.439597,-581.099121,0.044896,0.000000
37.270000,13.821724,-581.188110,0.007248,0.001748,0.044410,61.482098,3.132047,0.444104,-581.188110,0.045347,0.000000
37.540001,14.462944,-581.188110,0.007261,0.001773,0.045026,64.334389,3.277350,0.450262,-581.188110,0.045798,0.000000
37.810001,14.328148,-581.232605,0.007286,0.001790,0.045469,63.734783,3.246805,0.454687,-581.232605,0.046249,0.000000
38.080002,14.317345,-581.188110,0.007308,0.001806,0.045876,63.686729,3.244357,0.458763,-581.188110,0.046700,0.000000
38.350002,14.283836,-581.188110,0.007312,0.001820,0.046240,63.537678,3.236764,0.462404,-581.188110,0.047151,0.000000
38.620003,14.303940,-581.232605,0.007304,0.001836,0.046639,63.627102,3.241319,0.466394,-581.232605,0.047602,0.000000
38.890003,14.462204,-581.232605,0.007325,0.001853,0.047064,64.331093,3.277182,0.470644,-581.232605,0.048044,0.000000
39.160004,14.809250,-581.188110,0.007338,0.001874,0.047602,65.874832,3.355824,0.476019,-581.188110,0.048495,0.000000
39.430000,15.251259,-581.232605,0.007364,0.001895,0.048140,67.840988,3.455985,0.481397,-581.232605,0.048946,0.000000
39.700001,15.229660,-581.188110,0.007364,0.001912,0.048573,67.744911,3.451090,0.485734,-581.188110,0.049397,0.000000
39.970001,15.031555,-581.232605,0.007373,0.001928,0.048964,66.863693,3.406199,0.489637,-581.232605,0.049848,0.000000
40.240002,15.271736,-581.277039,0.007373,0.001945,0.049406,67.932076,3.460625,0.494057,-581.277039,0.050299,0.000000
40.510002,15.491814,-581.321533,0.007394,0.001965,0.049900,68.911026,3.510495,0.499001,-581.321533,0.050750,0.000000
40.780003,15.373024,-581.232605,0.007412,0.001979,0.050265,68.382629,3.483577,0.502645,-581.232605,0.051201,0.000000
41.050003,15.184601,-581.232605,0.007424,0.001992,0.050585,67.544479,3.440880,0.505851,-581.232605,0.051652,0.000000
41.320004,15.907753,-581.321533,0.007416,0.002016,0.051210,70.761223,3.604748,0.512096,-581.321533,0.052094,0.000000
41.590000,15.967331,-581.366028,0.007437,0.002033,0.051643,71.026237,3.618249,0.516434,-581.366028,0.052545,0.000000
41.860001,15.943123,-581.277039,0.007450,0.002051,0.052085,70.918556,3.612763,0.520855,-581.277039,0.052996,0.000000
42.130001,15.976265,-581.277039,0.007476,0.002067,0.052502,71.065979,3.620274,0.525018,-581.277039,0.053447,0.000000
42.400002,16.382156,-581.277039,0.007480,0.002089,0.053057,72.871468,3.712250,0.530567,-581.277039,0.053898,0.000000
42.670002,16.262993,-581.277039,0.007493,0.002104,0.053430,72.341408,3.685247,0.534298,-581.277039,0.054349,0.000000
42.940002,16.176605,-581.321533,0.007498,0.002119,0.053811,71.957130,3.665671,0.538114,-581.321533,0.054800,0.000000
43.210003,16.490143,-581.321533,0.007511,0.002138,0.054306,73.351822,3.736720,0.543057,-581.321533,0.055251,0.000000
43.480003,16.594780,-581.366028,0.007524,0.002156,0.054765,73.817268,3.760431,0.547652,-581.366028,0.055702,0.000000
43.750004,16.678932,-581.410522,0.007537,0.002173,0.055199,74.191597,3.779500,0.551989,-581.410522,0.056153,0.000000
44.020000,16.959702,-581.366028,0.007545,0.002194,0.055736,75.440521,3.843123,0.557364,-581.366028,0.056595,0.000000
44.290001,17.174934,-581.410522,0.007558,0.002214,0.056239,76.397926,3.891896,0.562394,-581.410522,0.057046,0.000000
44.560001,17.177544,-581.366028,0.007575,0.002230,0.056647,76.409531,3.892487,0.566470,-581.366028,0.057497,0.000000
44.830002,16.845383,-581.366028,0.007575,0.002241,0.056933,74.932007,3.817218,0.569331,-581.366028,0.057948,0.000000
45.100002,17.452354,-581.366028,0.007601,0.002264,0.057506,77.631950,3.954760,0.575058,-581.366028,0.058399,0.000000
45.370003,17.348831,-581.410522,0.007610,0.002281,0.057930,77.171455,3.931301,0.579305,-581.410522,0.058850,0.000000
45.640003,17.580818,-581.455017,0.007614,0.002300,0.058408,78.203384,3.983870,0.584077,-581.455017,0.059301,0.000000
45.910004,17.764397,-581.410522,0.007640,0.002319,0.058902,79.019981,4.025470,0.589020,-581.410522,0.059752,0.000000
46.180000,17.496292,-581.410522,0.007631,0.002331,0.059197,77.827393,3.964716,0.591969,-581.410522,0.060203,0.000000
46.450001,17.679497,-581.366028,0.007657,0.002350,0.059691,78.642326,4.006231,0.596912,-581.366028,0.060645,0.000000
46.720001,17.245682,-581.455017,0.007653,0.002359,0.059908,76.712624,3.907927,0.599081,-581.455017,0.061096,0.000000
46.990002,17.503738,-581.455017,0.007662,0.002378,0.060411,77.860519,3.966404,0.604107,-581.455017,0.061547,0.000000
47.260002,18.386635,-581.455017,0.007683,0.002404,0.061053,81.787834,4.166471,0.610526,-581.455017,0.061998,0.000000
47.530003,18.340836,-581.366028,0.007713,0.002420,0.061478,81.584114,4.156093,0.614777,-581.366028,0.062449,0.000000
47.800003,18.372856,-581.410522,0.007713,0.002438,0.061928,81.726547,4.163349,0.619285,-581.410522,0.062900,0.000000
48.070004,18.430946,-581.499451,0.007713,0.002456,0.062388,81.984947,4.176512,0.623883,-581.499451,0.063351,0.000000
48.340004,18.669640,-581.455017,0.007731,0.002475,0.062874,83.046707,4.230601,0.628739,-581.455017,0.063802,0.000000
48.610001,18.494995,-581.499451,0.007739,0.002491,0.063264,82.269844,4.191026,0.632641,-581.499451,0.064253,0.000000
48.880001,18.341576,-581.455017,0.007765,0.002502,0.063550,81.587402,4.156260,0.635503,-581.455017,0.064695,0.000000
49.150002,19.269157,-581.499451,0.007756,0.002532,0.064313,85.713493,4.366454,0.643133,-581.499451,0.065146,0.000000
49.420002,18.948914,-581.543945,0.007769,0.002546,0.064669,84.288979,4.293885,0.646691,-581.543945,0.065597,0.000000
49.690002,19.066589,-581.543945,0.007778,0.002565,0.065146,84.812424,4.320551,0.651460,-581.543945,0.066048,0.000000
49.960003,18.926201,-581.543945,0.007787,0.002579,0.065510,84.187943,4.288738,0.655101,-581.543945,0.066499,0.000000
50.230003,19.013336,-581.499451,0.007804,0.002598,0.065987,84.575546,4.308484,0.659870,-581.499451,0.066950,0.000000
50.500004,18.436905,-581.499451,0.007800,0.002610,0.066299,82.011452,4.177862,0.662992,-581.499451,0.067401,0.000000
50.770004,19.709671,-581.543945,0.007817,0.002638,0.067010,87.672997,4.466275,0.670104,-581.543945,0.067852,0.000000
51.040001,20.073853,-581.588440,0.007838,0.002659,0.067548,89.292953,4.548800,0.675483,-581.588440,0.068303,0.000000
51.310001,19.564079,-581.499451,0.007851,0.002673,0.067886,87.025368,4.433284,0.678863,-581.499451,0.068754,0.000000
51.580002,19.424065,-581.499451,0.007856,0.002688,0.068285,86.402557,4.401556,0.682852,-581.499451,0.069196,0.000000
51.850002,19.339905,-581.499451,0.007860,0.002705,0.068719,86.028191,4.382485,0.687189,-581.499451,0.069647,0.000000
52.120003,19.578224,-581.588440,0.007881,0.002723,0.069153,87.088287,4.436489,0.691527,-581.588440,0.070098,0.000000
52.390003,19.572639,-581.588440,0.007890,0.002740,0.069586,87.063446,4.435224,0.695861,-581.588440,0.070549,0.000000
52.660004,19.633713,-581.632935,0.007886,0.002756,0.069994,87.335114,4.449063,0.699937,-581.632935,0.071000,0.000000
52.930004,20.156151,-581.588440,0.007912,0.002782,0.070653,89.659035,4.567449,0.706530,-581.588440,0.071451,0.000000
53.200001,19.959908,-581.543945,0.007916,0.002796,0.071017,88.786102,4.522979,0.710171,-581.543945,0.071902,0.000000
53.470001,19.827713,-581.588440,0.007938,0.002814,0.071477,88.198074,4.493024,0.714766,-581.588440,0.072352,0.000000
53.740002,19.369324,-581.677368,0.007946,0.002827,0.071806,86.159058,4.389152,0.718063,-581.677368,0.072804,0.000000
54.010002,19.828835,-581.588440,0.007942,0.002850,0.072396,88.203064,4.493278,0.723960,-581.588440,0.073246,0.000000
54.280003,19.802025,-581.632935,0.007955,0.002861,0.072673,88.083809,4.487203,0.726734,-581.632935,0.073697,0.000000
54.550003,19.631104,-581.588440,0.007950,0.002879,0.073116,87.323509,4.448472,0.731158,-581.588440,0.074148,0.000000
54.820004,20.522934,-581.632935,0.007976,0.002904,0.073766,91.290573,4.650563,0.737661,-581.632935,0.074599,0.000000
55.090004,20.322975,-581.677368,0.007981,0.002921,0.074200,90.401108,4.605252,0.741998,-581.677368,0.075050,0.000000
55.360004,20.127106,-581.632935,0.008011,0.002938,0.074625,89.529839,4.560867,0.746249,-581.632935,0.075501,0.000000
55.630001,19.736115,-581.588440,0.008006,0.002949,0.074911,87.790619,4.472268,0.749110,-581.588440,0.075951,0.000000
55.900002,20.229881,-581.588440,0.008015,0.002972,0.075483,89.987007,4.584157,0.754833,-581.588440,0.076403,0.000000
56.170002,20.136040,-581.677368,0.008015,0.002987,0.075874,89.569580,4.562892,0.758735,-581.677368,0.076853,0.000000
56.440002,20.079437,-581.677368,0.008037,0.003004,0.076299,89.317795,4.550066,0.762986,-581.677368,0.077296,0.000000
56.710003,20.417183,-581.677368,0.008050,0.003024,0.076819,90.820168,4.626600,0.768190,-581.677368,0.077747,0.000000
56.980003,20.849503,-581.632935,0.008063,0.003048,0.077409,92.743217,4.724565,0.774087,-581.632935,0.078198,0.000000
57.250004,20.260788,-581.677368,0.008063,0.003062,0.077764,90.124489,4.591160,0.777641,-581.677368,0.078649,0.000000
57.520004,20.252968,-581.677368,0.008080,0.003078,0.078180,90.089699,4.589388,0.781804,-581.677368,0.079100,0.000000
57.790001,20.170670,-581.721863,0.008084,0.003095,0.078614,89.723618,4.570739,0.786138,-581.721863,0.079551,0.000000
58.060001,20.280518,-581.632935,0.008093,0.003111,0.079030,90.212250,4.595631,0.790301,-581.632935,0.080002,0.000000
58.330002,20.451439,-581.721863,0.008101,0.003129,0.079481,90.972542,4.634362,0.794813,-581.721863,0.080452,0.000000
58.600002,20.372871,-581.766357,0.008110,0.003148,0.079958,90.623055,4.616559,0.799582,-581.766357,0.080903,0.000000
58.870003,21.194321,-581.721863,0.008119,0.003172,0.080574,94.277046,4.802702,0.805740,-581.721863,0.081354,0.000000
59.140003,20.884140,-581.766357,0.008149,0.003189,0.080990,92.897293,4.732414,0.809903,-581.766357,0.081796,0.000000
59.410004,20.730721,-581.677368,0.008149,0.003205,0.081398,92.214851,4.697649,0.813976,-581.677368,0.082248,0.000000
59.680004,20.525917,-581.677368,0.008157,0.003219,0.081771,91.303841,4.651239,0.817708,-581.677368,0.082698,0.000000
59.950005,20.445480,-581.766357,0.008179,0.003236,0.082195,90.946037,4.633012,0.821954,-581.766357,0.083150,0.000000
60.220001,20.497612,-581.810852,0.008179,0.003251,0.082569,91.177933,4.644825,0.825686,-581.810852,0.083600,0.000000
60.490002,20.996590,-581.810852,0.008196,0.003273,0.083132,93.397499,4.757895,0.831322,-581.810852,0.084052,0.000000
60.760002,21.524986,-581.766357,0.008201,0.003295,0.083687,95.747917,4.877632,0.836871,-581.766357,0.084502,0.000000
61.030003,21.317581,-581.766357,0.008205,0.003313,0.084138,94.825340,4.830633,0.841382,-581.766357,0.084953,0.000000
61.300003,21.040909,-581.810852,0.008218,0.003327,0.084511,93.594635,4.767938,0.845110,-581.810852,0.085404,0.000000
61.570004,21.216293,-581.899780,0.008222,0.003344,0.084936,94.374786,4.807681,0.849361,-581.899780,0.085847,0.000000
61.840004,21.458336,-581.810852,0.008235,0.003363,0.085430,95.451447,4.862528,0.854304,-581.810852,0.086297,0.000000
62.110004,21.285927,-581.721863,0.008248,0.003378,0.085812,94.684532,4.823460,0.858119,-581.721863,0.086749,0.000000
62.380001,21.050591,-581.721863,0.008235,0.003393,0.086185,93.637703,4.770132,0.861847,-581.721863,0.087199,0.000000
62.650002,21.886932,-581.855347,0.008252,0.003416,0.086757,97.357941,4.959650,0.867574,-581.855347,0.087651,0.000000
62.920002,21.911514,-581.855347,0.008269,0.003433,0.087199,97.467285,4.965220,0.871994,-581.855347,0.088101,0.000000
63.190002,21.951355,-581.810852,0.008269,0.003450,0.087642,97.644501,4.974248,0.876419,-581.810852,0.088553,0.000000
63.460003,21.778946,-581.810852,0.008300,0.003464,0.087989,96.877586,4.935180,0.879886,-581.810852,0.089003,0.000000
63.730003,22.283142,-581.899780,0.008291,0.003486,0.088553,99.120369,5.049432,0.885525,-581.899780,0.089454,0.000000
64.000000,22.243294,-581.855347,0.008304,0.003502,0.088943,98.943115,5.040402,0.889428,-581.855347,0.089897,0.000000
64.270004,22.101791,-581.944275,0.008321,0.003517,0.089333,98.313675,5.008337,0.893330,-581.944275,0.090348,0.000000
64.540001,22.673012,-581.899780,0.008317,0.003538,0.089870,100.854591,5.137778,0.898704,-581.899780,0.090798,0.000000
64.810005,22.928833,-581.855347,0.008351,0.003557,0.090348,101.992546,5.195748,0.903477,-581.855347,0.091249,0.000000
65.080002,22.911705,-581.855347,0.008351,0.003572,0.090738,101.916351,5.191866,0.907379,-581.855347,0.091700,0.000000
65.350006,23.425209,-581.944275,0.008351,0.003594,0.091293,104.200531,5.308228,0.912928,-581.944275,0.092151,0.000000
65.620003,23.723106,-581.944275,0.008369,0.003613,0.091778,105.525650,5.375733,0.917784,-581.944275,0.092602,0.000000
65.889999,23.783798,-581.899780,0.008382,0.003629,0.092169,105.795616,5.389486,0.921686,-581.899780,0.093053,0.000000
66.160004,23.476593,-581.899780,0.008395,0.003641,0.092481,104.429100,5.319872,0.924809,-581.899780,0.093504,0.000000
66.430000,24.461891,-581.899780,0.008390,0.003664,0.093062,108.811928,5.543144,0.930619,-581.899780,0.093955,0.000000
66.700005,24.495781,-581.944275,0.008395,0.003681,0.093487,108.962677,5.550823,0.934869,-581.944275,0.094398,0.000000
66.970001,24.909111,-581.988770,0.008429,0.003698,0.093938,110.801262,5.644485,0.939377,-581.988770,0.094848,0.000000
67.240005,25.376442,-581.988770,0.008442,0.003718,0.094449,112.880051,5.750384,0.944494,-581.988770,0.095299,0.000000
67.510002,25.261749,-581.855347,0.008451,0.003730,0.094744,112.369873,5.724394,0.947442,-581.855347,0.095750,0.000000
67.780006,25.738388,-581.899780,0.008451,0.003749,0.095222,114.490067,5.832402,0.952215,-581.899780,0.096201,0.000000
68.050003,25.469162,-582.033264,0.008455,0.003759,0.095482,113.292488,5.771395,0.954815,-582.033264,0.096652,0.000000
68.320000,26.125648,-581.944275,0.008451,0.003783,0.096080,116.212692,5.920157,0.960799,-581.944275,0.097103,0.000000
68.590004,27.402519,-581.988770,0.008485,0.003803,0.096600,121.892494,6.209500,0.966004,-581.988770,0.097554,0.000000
68.860001,27.730576,-581.988770,0.008481,0.003820,0.097016,123.351761,6.283838,0.970163,-581.988770,0.098005,0.000000
69.130005,28.266792,-581.988770,0.008511,0.003838,0.097476,125.736969,6.405346,0.974762,-581.988770,0.098447,0.000000
69.400002,28.915840,-581.988770,0.008520,0.003860,0.098040,128.624084,6.552423,0.980398,-581.988770,0.098899,0.000000
69.670006,29.374229,-582.033264,0.008520,0.003874,0.098404,130.663101,6.656296,0.984042,-582.033264,0.099349,0.000000
69.940002,29.844162,-581.988770,0.008550,0.003891,0.098829,132.753464,6.762784,0.988289,-581.988770,0.099800,0.000000
70.210007,29.884377,-582.033264,0.008541,0.003900,0.099072,132.932343,6.771896,0.990719,-582.033264,0.100251,0.000000
70.480003,31.443878,-581.988770,0.008537,0.003931,0.099844,139.869354,7.125285,0.998436,-581.988770,0.100702,0.000000
70.750000,31.760017,-582.077698,0.008558,0.003945,0.100208,141.275620,7.196923,1.002077,-582.077698,0.101153,0.000000
71.020004,32.398262,-582.033264,0.008580,0.003964,0.100685,144.114670,7.341551,1.006850,-582.033264,0.101604,0.000000
71.290001,32.918846,-582.033264,0.008584,0.003978,0.101032,146.430344,7.459517,1.010317,-582.033264,0.102055,0.000000
71.560005,33.697098,-582.077698,0.008597,0.003997,0.101526,149.892181,7.635871,1.015260,-582.077698,0.102497,0.000000
71.830002,34.055695,-582.033264,0.008601,0.004011,0.101873,151.487289,7.717131,1.018731,-582.033264,0.102948,0.000000
72.100006,35.690781,-582.077698,0.008619,0.004039,0.102584,158.760529,8.087646,1.025839,-582.077698,0.103399,0.000000
72.370003,36.781464,-582.122192,0.008632,0.004058,0.103079,163.612122,8.334799,1.030786,-582.122192,0.103850,0.000000
72.640007,36.937111,-582.033264,0.008649,0.004072,0.103417,164.304474,8.370070,1.034166,-582.033264,0.104301,0.000000
72.910004,37.461784,-582.033264,0.008653,0.004087,0.103807,166.638336,8.488962,1.038068,-582.033264,0.104752,0.000000
73.180000,38.070244,-582.077698,0.008640,0.004105,0.104258,169.344910,8.626841,1.042580,-582.077698,0.105203,0.000000
73.450005,39.038040,-582.077698,0.008675,0.004122,0.104700,173.649872,8.846147,1.047000,-582.077698,0.105654,0.000000
73.720001,39.858376,-582.122192,0.008688,0.004138,0.105116,177.298904,9.032037,1.051164,-582.122192,0.106105,0.000000
73.990005,40.659348,-582.077698,0.008692,0.004155,0.105541,180.861816,9.213540,1.055414,-582.077698,0.106556,0.000000
74.260002,42.166344,-582.077698,0.008709,0.004181,0.106192,187.565262,9.555030,1.061917,-582.077698,0.106998,0.000000
74.530006,42.871613,-582.122192,0.008709,0.004195,0.106564,190.702454,9.714847,1.065645,-582.122192,0.107449,0.000000
74.800003,43.581352,-582.077698,0.008705,0.004213,0.106998,193.859543,9.875676,1.069982,-582.077698,0.107900,0.000000
75.070007,43.883347,-582.122192,0.008735,0.004222,0.107250,195.202881,9.944108,1.072499,-582.122192,0.108351,0.000000
75.340004,45.609299,-582.077698,0.008761,0.004249,0.107918,202.880295,10.335216,1.079176,-582.077698,0.108802,0.000000
75.610001,46.485863,-582.077698,0.008761,0.004263,0.108273,206.779449,10.533847,1.082730,-582.077698,0.109253,0.000000
75.880005,46.748756,-582.166687,0.008752,0.004275,0.108577,207.948853,10.593420,1.085765,-582.166687,0.109704,0.000000
76.150002,48.935326,-582.211182,0.008774,0.004303,0.109296,217.675201,11.088903,1.092964,-582.211182,0.110155,0.000000
76.420006,49.875565,-582.166687,0.008783,0.004320,0.109730,221.857590,11.301965,1.097302,-582.166687,0.110606,0.000000
76.690002,50.533546,-582.166687,0.008791,0.004336,0.110129,224.784439,11.451066,1.101291,-582.166687,0.111048,0.000000
76.960007,51.255951,-582.166687,0.008791,0.004348,0.110441,227.997864,11.614765,1.104410,-582.166687,0.111499,0.000000
77.230003,52.700760,-582.166687,0.008791,0.004370,0.111005,234.424683,11.942163,1.110049,-582.166687,0.111950,0.000000
77.500000,53.944481,-582.255676,0.008795,0.004389,0.111473,239.957031,12.223994,1.114731,-582.255676,0.112401,0.000000
77.770004,54.663902,-582.211182,0.008839,0.004403,0.111829,243.157181,12.387017,1.118289,-582.211182,0.112852,0.000000
78.040001,56.030884,-582.166687,0.008834,0.004424,0.112366,249.237823,12.696780,1.123663,-582.166687,0.113303,0.000000
78.310005,57.933708,-582.166687,0.008830,0.004446,0.112922,257.701996,13.127966,1.129216,-582.166687,0.113754,0.000000
78.580002,58.488541,-582.255676,0.008834,0.004459,0.113251,260.170013,13.253693,1.132509,-582.255676,0.114205,0.000000
78.850006,59.518150,-582.255676,0.008856,0.004476,0.113702,264.749969,13.487006,1.137020,-582.255676,0.114656,0.000000
79.120003,60.567871,-582.255676,0.008856,0.004489,0.114031,269.419342,13.724875,1.140313,-582.255676,0.115107,0.000000
79.390007,62.001877,-582.211182,0.008873,0.004510,0.114552,275.798126,14.049827,1.145517,-582.211182,0.115549,0.000000
79.660004,63.314857,-582.211182,0.008877,0.004528,0.115003,281.638550,14.347352,1.150029,-582.211182,0.116000,0.000000
79.930000,64.071144,-582.211182,0.008886,0.004544,0.115428,285.002686,14.518728,1.154276,-582.211182,0.116451,0.000000
80.200005,66.568657,-582.300110,0.008886,0.004569,0.116052,296.112183,15.084673,1.160521,-582.300110,0.116902,0.000000
80.470001,67.318977,-582.300110,0.008925,0.004573,0.116156,299.449768,15.254698,1.161562,-582.300110,0.116347,0.000000
80.740005,66.642006,-582.300110,0.008903,0.004572,0.116139,296.438446,15.101295,1.161387,-582.300110,0.116347,0.000000
81.010002,66.059242,-582.300110,0.008925,0.004572,0.116130,293.846191,14.969238,1.161300,-582.300110,0.116139,0.000000
81.280006,65.570702,-582.344604,0.008916,0.004572,0.116130,291.673035,14.858533,1.161300,-582.344604,0.116139,0.000000
81.550003,65.116402,-582.300110,0.008916,0.004572,0.116121,289.652222,14.755588,1.161213,-582.300110,0.116139,0.000000
81.820007,64.729500,-582.300110,0.008933,0.004572,0.116121,287.931183,14.667914,1.161213,-582.300110,0.116139,0.000000
82.090004,64.377617,-582.344604,0.008929,0.004572,0.116121,286.365936,14.588177,1.161213,-582.344604,0.116139,0.000000
82.360001,64.046196,-582.344604,0.008938,0.004572,0.116121,284.891693,14.513075,1.161213,-582.344604,0.116139,0.000000
82.630005,63.773628,-582.300110,0.008925,0.004572,0.116121,283.679260,14.451311,1.161213,-582.300110,0.116139,0.000000
82.900002,63.507011,-582.344604,0.008921,0.004572,0.116121,282.493286,14.390894,1.161213,-582.344604,0.116139,0.000000
83.170006,63.270180,-582.344604,0.008942,0.004572,0.116121,281.439819,14.337227,1.161213,-582.344604,0.116139,0.000000
83.440002,63.053825,-582.300110,0.008946,0.004572,0.116121,280.477417,14.288201,1.161213,-582.300110,0.116139,0.000000
83.710007,62.852379,-582.344604,0.008946,0.004571,0.116113,279.581329,14.242553,1.161126,-582.344604,0.116139,0.000000
83.980003,62.665817,-582.389099,0.008933,0.004571,0.116113,278.751465,14.200277,1.161126,-582.389099,0.116139,0.000000
84.250008,62.475533,-582.389099,0.008938,0.004571,0.116113,277.905060,14.157158,1.161126,-582.389099,0.116139,0.000000
84.520004,62.308342,-582.389099,0.008951,0.004571,0.116113,277.161346,14.119271,1.161126,-582.389099,0.116139,0.000000
84.790001,62.153435,-582.300110,0.008938,0.004571,0.116113,276.472290,14.084169,1.161126,-582.300110,0.116139,0.000000
85.060005,62.011185,-582.389099,0.008951,0.004571,0.116113,275.839539,14.051935,1.161126,-582.389099,0.116139,0.000000
85.330002,61.863358,-582.389099,0.008929,0.004571,0.116113,275.181946,14.018437,1.161126,-582.389099,0.116139,0.000000
85.600006,61.752762,-582.389099,0.008938,0.004571,0.116113,274.690002,13.993376,1.161126,-582.389099,0.116139,0.000000
85.870003,61.624290,-582.478027,0.008946,0.004571,0.116113,274.118530,13.964263,1.161126,-582.478027,0.116139,0.000000
86.140007,61.517792,-582.344604,0.008942,0.004571,0.116113,273.644806,13.940131,1.161126,-582.344604,0.116139,0.000000
86.410004,61.393051,-582.389099,0.008964,0.004571,0.116113,273.089935,13.911864,1.161126,-582.389099,0.116139,0.000000
86.680000,61.278732,-582.478027,0.008946,0.004571,0.116113,272.581421,13.885960,1.161126,-582.478027,0.116139,0.000000
86.950005,61.173347,-582.478027,0.008955,0.004571,0.116113,272.112640,13.862079,1.161126,-582.478027,0.116139,0.000000
87.220001,61.077644,-582.433594,0.008938,0.004571,0.116113,271.686920,13.840392,1.161126,-582.433594,0.116139,0.000000
87.490005,60.986786,-582.389099,0.008951,0.004571,0.116113,271.282776,13.819803,1.161126,-582.389099,0.116139,0.000000
87.760002,60.908966,-582.433594,0.008946,0.004571,0.116113,270.936615,13.802169,1.161126,-582.433594,0.116139,0.000000
88.030006,60.826668,-582.522522,0.008946,0.004571,0.116113,270.570526,13.783521,1.161126,-582.522522,0.116139,0.000000
88.300003,60.746239,-582.478027,0.008942,0.004571,0.116113,270.212769,13.765294,1.161126,-582.478027,0.116139,0.000000
88.570007,60.662827,-582.478027,0.008942,0.004571,0.116113,269.841736,13.746393,1.161126,-582.478027,0.116139,0.000000
88.840004,60.580162,-582.522522,0.008959,0.004571,0.116113,269.474030,13.727661,1.161126,-582.522522,0.116139,0.000000
89.110001,60.500473,-582.478027,0.008959,0.004571,0.116113,269.119537,13.709603,1.161126,-582.478027,0.116139,0.000000
89.380005,60.438286,-582.478027,0.008955,0.004571,0.116113,268.842926,13.695512,1.161126,-582.478027,0.116139,0.000000
89.650002,60.358223,-582.522522,0.008933,0.004571,0.116113,268.486786,13.677369,1.161126,-582.522522,0.116139,0.000000
89.920006,60.310936,-582.567017,0.008955,0.004571,0.116113,268.276428,13.666653,1.161126,-582.567017,0.116139,0.000000
90.190002,60.237579,-582.567017,0.008959,0.004571,0.116113,267.950134,13.650030,1.161126,-582.567017,0.116139,0.000000
90.460007,60.177994,-582.522522,0.008938,0.004571,0.116113,267.685089,13.636528,1.161126,-582.522522,0.116139,0.000000
90.730003,60.111343,-582.478027,0.008959,0.004571,0.116113,267.388611,13.621426,1.161126,-582.478027,0.116139,0.000000
91.000008,60.052505,-582.567017,0.008946,0.004571,0.116113,267.126892,13.608092,1.161126,-582.567017,0.116139,0.000000
91.270004,59.990692,-582.611511,0.008964,0.004571,0.116113,266.851929,13.594085,1.161126,-582.611511,0.116139,0.000000
91.540001,59.930740,-582.611511,0.008959,0.004571,0.116113,266.585236,13.580500,1.161126,-582.611511,0.116139,0.000000
91.810005,59.873772,-582.567017,0.008955,0.004571,0.116113,266.331848,13.567590,1.161126,-582.567017,0.116139,0.000000
92.080002,59.831314,-582.567017,0.008955,0.004571,0.116113,266.142975,13.557970,1.161126,-582.567017,0.116139,0.000000
92.350006,59.783279,-582.611511,0.008964,0.004571,0.116113,265.929321,13.547085,1.161126,-582.611511,0.116139,0.000000
92.620003,59.740089,-582.611511,0.008955,0.004571,0.116113,265.737183,13.537297,1.161126,-582.611511,0.116139,0.000000
92.890007,59.683487,-582.567017,0.008951,0.004571,0.116113,265.485413,13.524471,1.161126,-582.567017,0.116139,0.000000
93.160004,59.633591,-582.567017,0.008968,0.004571,0.116113,265.263458,13.513165,1.161126,-582.567017,0.116139,0.000000
93.430008,59.580711,-582.567017,0.008959,0.004571,0.116113,265.028229,13.501183,1.161126,-582.567017,0.116139,0.000000
93.700005,59.534538,-582.611511,0.008946,0.004571,0.116113,264.822845,13.490719,1.161126,-582.611511,0.116139,0.000000
93.970001,59.485756,-582.611511,0.008951,0.004571,0.116113,264.605865,13.479665,1.161126,-582.611511,0.116139,0.000000
94.240005,59.454102,-582.611511,0.008959,0.004571,0.116113,264.465057,13.472492,1.161126,-582.611511,0.116139,0.000000
94.510002,59.420593,-582.567017,0.008959,0.004571,0.116113,264.316010,13.464899,1.161126,-582.567017,0.116139,0.000000
94.780006,59.379631,-582.611511,0.008946,0.004571,0.116113,264.133789,13.455617,1.161126,-582.611511,0.116139,0.000000
95.050003,59.334946,-582.656006,0.008946,0.004571,0.116113,263.935028,13.445491,1.161126,-582.656006,0.116139,0.000000
95.320007,59.304039,-582.700439,0.008968,0.004571,0.116113,263.797546,13.438487,1.161126,-582.700439,0.116139,0.000000
95.590004,59.269783,-582.744934,0.008951,0.004571,0.116113,263.645172,13.430725,1.161126,-582.744934,0.116139,0.000000
95.860008,59.225838,-582.656006,0.008951,0.004571,0.116113,263.449677,13.420767,1.161126,-582.656006,0.116139,0.000000
96.130005,59.195679,-582.700439,0.008951,0.004571,0.116113,263.315521,13.413933,1.161126,-582.700439,0.116139,0.000000
96.400002,59.132378,-582.656006,0.008964,0.004571,0.116113,263.033966,13.399588,1.161126,-582.656006,0.116139,0.000000
96.670006,59.098114,-582.700439,0.008972,0.004571,0.116113,262.881531,13.391824,1.161126,-582.700439,0.116139,0.000000
96.940002,59.083969,-582.700439,0.008959,0.004571,0.116113,262.818634,13.388618,1.161126,-582.700439,0.116139,0.000000
97.210007,59.060509,-582.744934,0.008955,0.004571,0.116113,262.714264,13.383302,1.161126,-582.744934,0.116139,0.000000
97.480003,59.016563,-582.700439,0.008964,0.004571,0.116113,262.518799,13.373344,1.161126,-582.700439,0.116139,0.000000
97.750008,58.986404,-582.744934,0.008959,0.004571,0.116113,262.384644,13.366510,1.161126,-582.744934,0.116139,0.000000
98.020004,58.946564,-582.744934,0.008955,0.004571,0.116113,262.207397,13.357482,1.161126,-582.744934,0.116139,0.000000
98.290001,58.914162,-582.744934,0.008964,0.004571,0.116113,262.063293,13.350140,1.161126,-582.744934,0.116139,0.000000
98.560005,58.901131,-582.700439,0.008959,0.004571,0.116113,262.005310,13.347187,1.161126,-582.700439,0.116139,0.000000
98.830002,58.858307,-582.744934,0.008955,0.004571,0.116113,261.814819,13.337482,1.161126,-582.744934,0.116139,0.000000
99.100006,58.820328,-582.744934,0.008951,0.004571,0.116113,261.645874,13.328877,1.161126,-582.744934,0.116139,0.000000
99.370003,58.794632,-582.789429,0.008951,0.004571,0.116113,261.531586,13.323054,1.161126,-582.789429,0.116139,0.000000
99.640007,58.765213,-582.789429,0.008959,0.004571,0.116113,261.400726,13.316388,1.161126,-582.789429,0.116139,0.000000
99.910004,58.745110,-582.744934,0.008977,0.004571,0.116113,261.311310,13.311832,1.161126,-582.744934,0.116139,0.000000
100.180008,58.720528,-582.744934,0.008955,0.004571,0.116113,261.201965,13.306262,1.161126,-582.744934,0.116139,0.000000
100.450005,58.675476,-582.789429,0.008977,0.004571,0.116113,261.001556,13.296053,1.161126,-582.789429,0.116139,0.000000
100.720001,58.653130,-582.789429,0.008955,0.004571,0.116113,260.902161,13.290989,1.161126,-582.789429,0.116139,0.000000
100.990005,58.647171,-582.789429,0.008968,0.004571,0.116113,260.875641,13.289639,1.161126,-582.789429,0.116139,0.000000
101.260002,58.603981,-582.744934,0.008968,0.004571,0.116113,260.683533,13.279852,1.161126,-582.744934,0.116139,0.000000
101.530006,58.564133,-582.789429,0.008968,0.004571,0.116113,260.506287,13.270823,1.161126,-582.789429,0.116139,0.000000
101.800003,58.535461,-582.789429,0.008977,0.004571,0.116113,260.378723,13.264325,1.161126,-582.789429,0.116139,0.000000
102.070007,58.517212,-582.878357,0.008946,0.004571,0.116113,260.297546,13.260190,1.161126,-582.878357,0.116139,0.000000
102.340004,58.490028,-582.833923,0.008955,0.004571,0.116113,260.176636,13.254030,1.161126,-582.833923,0.116139,0.000000
102.610008,58.473274,-582.789429,0.008964,0.004571,0.116113,260.102112,13.250234,1.161126,-582.789429,0.116139,0.000000
102.880005,58.435669,-582.833923,0.008951,0.004571,0.116113,259.934845,13.241712,1.161126,-582.833923,0.116139,0.000000
103.150002,58.421516,-582.789429,0.008946,0.004571,0.116113,259.871887,13.238505,1.161126,-582.789429,0.116139,0.000000
103.420006,58.412575,-582.878357,0.008951,0.004571,0.116113,259.832123,13.236479,1.161126,-582.878357,0.116139,0.000000
103.690002,58.389862,-582.878357,0.008959,0.004571,0.116113,259.731079,13.231333,1.161126,-582.878357,0.116139,0.000000
103.960007,58.360077,-582.789429,0.008964,0.004571,0.116113,259.598602,13.224583,1.161126,-582.789429,0.116139,0.000000
104.230003,58.326561,-582.833923,0.008972,0.004571,0.116113,259.449493,13.216988,1.161126,-582.833923,0.116139,0.000000
104.500008,58.300865,-582.833923,0.008964,0.004571,0.116113,259.335205,13.211164,1.161126,-582.833923,0.116139,0.000000
104.770004,58.272942,-582.878357,0.008951,0.004571,0.116113,259.210999,13.204837,1.161126,-582.878357,0.116139,0.000000
105.040009,58.243149,-582.878357,0.008968,0.004571,0.116113,259.078461,13.198086,1.161126,-582.878357,0.116139,0.000000
105.310005,58.237564,-582.967346,0.008964,0.004571,0.116113,259.053619,13.196820,1.161126,-582.967346,0.116139,0.000000
105.580002,58.218575,-582.878357,0.008968,0.004571,0.116113,258.969147,13.192517,1.161126,-582.878357,0.116139,0.000000
105.850006,58.203308,-582.878357,0.008951,0.004571,0.116113,258.901245,13.189057,1.161126,-582.878357,0.116139,0.000000
106.120003,58.176865,-582.878357,0.008968,0.004571,0.116113,258.783630,13.183066,1.161126,-582.878357,0.116139,0.000000
106.390007,58.147820,-582.967346,0.008951,0.004571,0.116113,258.654419,13.176484,1.161126,-582.967346,0.116139,0.000000
106.660004,58.134415,-582.967346,0.008964,0.004571,0.116113,258.594788,13.173447,1.161126,-582.967346,0.116139,0.000000
106.930008,58.122131,-582.922852,0.008955,0.004571,0.116113,258.540161,13.170663,1.161126,-582.922852,0.116139,0.000000
107.200005,58.105743,-582.922852,0.008968,0.004571,0.116113,258.467255,13.166950,1.161126,-582.922852,0.116139,0.000000
107.470009,58.069252,-582.878357,0.008959,0.004571,0.116113,258.304932,13.158680,1.161126,-582.878357,0.116139,0.000000
107.740005,58.060310,-583.011841,0.008964,0.004571,0.116113,258.265167,13.156654,1.161126,-583.011841,0.116139,0.000000
108.010002,58.026054,-582.967346,0.008977,0.004571,0.116113,258.112793,13.148892,1.161126,-582.967346,0.116139,0.000000
108.280006,58.010788,-582.922852,0.008964,0.004571,0.116113,258.044861,13.145432,1.161126,-582.922852,0.116139,0.000000
108.550003,58.005203,-582.922852,0.008977,0.004571,0.116113,258.020020,13.144167,1.161126,-582.922852,0.116139,0.000000
108.820007,57.991051,-582.922852,0.008972,0.004571,0.116113,257.957062,13.140961,1.161126,-582.922852,0.116139,0.000000
109.090004,57.969826,-583.011841,0.008959,0.004571,0.116113,257.862671,13.136150,1.161126,-583.011841,0.116139,0.000000
109.360008,57.959030,-582.922852,0.008964,0.004571,0.116113,257.814636,13.133704,1.161126,-582.922852,0.116139,0.000000
109.630005,57.942268,-582.922852,0.008964,0.004571,0.116113,257.740082,13.129906,1.161126,-582.922852,0.116139,0.000000
109.900002,57.906898,-582.922852,0.008977,0.004571,0.116113,257.582764,13.121891,1.161126,-582.922852,0.116139,0.000000
110.170006,57.902802,-582.922852,0.008964,0.004571,0.116113,257.564514,13.120962,1.161126,-582.922852,0.116139,0.000000
110.440002,57.871895,-582.967346,0.008964,0.004571,0.116113,257.427032,13.113959,1.161126,-582.967346,0.116139,0.000000
110.710007,57.844711,-582.922852,0.008977,0.004571,0.116113,257.306122,13.107799,1.161126,-582.922852,0.116139,0.000000
110.800003,57.867424,-582.922852,0.008946,0.004571,0.116113,257.407166,13.112947,1.161126,-582.922852,0.116139,0.000000