File: Data/compression 7/AutoHeating-12-7-1-1-240320_03202024_202947.csv
Time (sec),S:Load (lbs),S:HL1 (DIM),S:LVDT (in),S:Position (in),Ch:Position (mm),Ch:Load (N),Ch:Stress (MPa),Ch:Strain (mm/mm),Ch:HL1 (DIM),Set Point (),Cycles ()
0.010000,-0.006706,-575.227661,-0.000013,-0.000000,-0.000000,-0.029831,-0.001520,-0.000000,-575.227661,0.000191,0.000000
0.270000,-0.009308,-575.227661,0.000026,-0.000000,-0.000000,-0.041403,-0.002109,-0.000000,-575.227661,0.000191,0.000000
0.530000,0.026062,-575.272156,0.000060,0.000084,0.002125,0.115930,0.005906,0.021248,-575.272156,0.003382,0.000000
0.790000,-0.004097,-575.272156,0.000246,0.000262,0.006660,-0.018224,-0.000928,0.066603,-575.272156,0.007719,0.000000
1.050000,-0.007446,-575.183167,0.000435,0.000431,0.010953,-0.033123,-0.001687,0.109531,-575.183167,0.012037,0.000000
1.310000,0.004837,-575.227661,0.000573,0.000595,0.015124,0.021516,0.001096,0.151244,-575.227661,0.016373,0.000000
1.570000,-0.040215,-575.272156,0.000759,0.000775,0.019695,-0.178883,-0.009113,0.196947,-575.272156,0.020709,0.000000
1.830000,-0.016754,-575.227661,0.000923,0.000941,0.023892,-0.074526,-0.003797,0.238921,-575.227661,0.025028,0.000000
2.090000,-0.021599,-575.316650,0.001108,0.001110,0.028194,-0.096076,-0.004894,0.281937,-575.316650,0.029364,0.000000
2.350000,-0.014893,-575.227661,0.001259,0.001284,0.032608,-0.066245,-0.003375,0.326080,-575.227661,0.033701,0.000000
2.610000,-0.006332,-575.316650,0.001436,0.001456,0.036979,-0.028168,-0.001435,0.369788,-575.316650,0.038037,0.000000
2.870000,0.027931,-575.272156,0.001591,0.001621,0.041168,0.124244,0.006329,0.411675,-575.272156,0.042356,0.000000
3.130000,-0.001114,-575.316650,0.001789,0.001794,0.045573,-0.004955,-0.000252,0.455728,-575.316650,0.046692,0.000000
3.390000,-0.016754,-575.316650,0.001953,0.001967,0.049952,-0.074526,-0.003797,0.499523,-575.316650,0.051028,0.000000
3.650000,0.005211,-575.272156,0.002134,0.002133,0.054185,0.023179,0.001181,0.541846,-575.272156,0.055364,0.000000
3.910000,-0.058090,-575.272156,0.002311,0.002307,0.058607,-0.258398,-0.013163,0.586072,-575.272156,0.059682,0.000000
4.170000,-0.014526,-575.316650,0.002471,0.002479,0.062978,-0.064617,-0.003292,0.629780,-575.316650,0.064019,0.000000
4.430000,0.005585,-575.316650,0.002634,0.002643,0.067124,0.024842,0.001266,0.671236,-575.316650,0.068355,0.000000
4.690000,-0.018250,-575.361084,0.002824,0.002820,0.071633,-0.081178,-0.004135,0.716329,-575.361084,0.072691,0.000000
4.950000,0.011169,-575.316650,0.002997,0.002992,0.075995,0.049684,0.002531,0.759950,-575.316650,0.077010,0.000000
5.210000,0.018250,-575.361084,0.003152,0.003159,0.080227,0.081178,0.004135,0.802273,-575.361084,0.081346,0.000000
5.470000,-0.018250,-575.361084,0.003337,0.003333,0.084650,-0.081178,-0.004135,0.846499,-575.361084,0.085682,0.000000
5.730000,0.010056,-575.361084,0.003527,0.003500,0.088900,0.044729,0.002279,0.888996,-575.361084,0.090018,0.000000
5.990000,0.004471,-575.405579,0.003673,0.003678,0.093426,0.019887,0.001013,0.934263,-575.405579,0.094337,0.000000
6.250000,-0.056976,-575.361084,0.003859,0.003846,0.097684,-0.253443,-0.012911,0.976844,-575.361084,0.098673,0.000000
6.510000,0.019737,-575.361084,0.004027,0.004009,0.101830,0.087796,0.004473,1.018299,-575.361084,0.103009,0.000000
6.770000,0.032021,-575.361084,0.004204,0.004186,0.106314,0.142435,0.007256,1.063135,-575.361084,0.107328,0.000000
7.030000,-0.005585,-575.316650,0.004359,0.004347,0.110424,-0.024842,-0.001266,1.104239,-575.316650,0.111664,0.000000
7.290000,0.014519,-575.405579,0.004531,0.004523,0.114881,0.064583,0.003290,1.148814,-575.405579,0.116000,0.000000
7.550000,0.030159,-575.405579,0.004695,0.004690,0.119122,0.134154,0.006834,1.191224,-575.405579,0.120337,0.000000
7.810000,-0.018990,-575.494568,0.004889,0.004866,0.123597,-0.084470,-0.004303,1.235973,-575.494568,0.124655,0.000000
8.070001,0.014153,-575.405579,0.005057,0.005034,0.127873,0.062954,0.003207,1.278727,-575.405579,0.128991,0.000000
8.330000,0.011169,-575.405579,0.005243,0.005214,0.132434,0.049684,0.002531,1.324342,-575.405579,0.133327,0.000000
8.590000,-0.024208,-575.405579,0.005381,0.005379,0.136632,-0.107683,-0.005486,1.366317,-575.405579,0.137663,0.000000
8.850000,0.064789,-575.361084,0.005545,0.005544,0.140812,0.288195,0.014681,1.408117,-575.361084,0.141982,0.000000
9.110001,0.048782,-575.494568,0.005717,0.005719,0.145269,0.216995,0.011054,1.452692,-575.494568,0.146318,0.000000
9.370001,0.012657,-575.450073,0.005898,0.005890,0.149614,0.056302,0.002868,1.496139,-575.450073,0.150655,0.000000
9.630000,0.046921,-575.405579,0.006066,0.006055,0.153785,0.208714,0.010632,1.537852,-575.405579,0.154991,0.000000
9.890000,0.052132,-575.450073,0.006243,0.006235,0.158364,0.231893,0.011813,1.583642,-575.450073,0.159310,0.000000
10.150001,0.078941,-575.405579,0.006398,0.006398,0.162501,0.351149,0.017888,1.625011,-575.405579,0.163646,0.000000
10.410001,0.336624,-575.494568,0.006575,0.006569,0.166863,1.497379,0.076280,1.668632,-575.494568,0.167982,0.000000
10.670000,0.574944,-575.494568,0.006709,-0.000010,-0.000252,2.557477,0.130284,-0.002517,-575.494568,-0.000026,0.000000
10.930000,0.511269,-575.450073,0.006709,-0.000010,-0.000252,2.274236,0.115855,-0.002517,-575.450073,-0.000026,0.000000
11.190001,0.505684,-575.450073,0.006713,-0.000010,-0.000252,2.249394,0.114590,-0.002517,-575.450073,0.000078,0.000000
11.450001,0.497490,-575.405579,0.006709,-0.000010,-0.000252,2.212946,0.112733,-0.002517,-575.405579,0.000512,0.000000
11.710001,0.573456,-575.494568,0.006717,0.000002,0.000052,2.550859,0.129947,0.000519,-575.494568,0.000945,0.000000
11.970000,0.646812,-575.494568,0.006713,0.000021,0.000529,2.877165,0.146570,0.005287,-575.494568,0.001379,0.000000
12.230000,0.741020,-575.450073,0.006769,0.000042,0.001058,3.296222,0.167918,0.010579,-575.450073,0.001813,0.000000
12.490001,0.728363,-575.494568,0.006847,0.000056,0.001422,3.239921,0.165049,0.014220,-575.494568,0.002246,0.000000
12.750001,0.818100,-575.494568,0.006851,0.000075,0.001908,3.639091,0.185384,0.019080,-575.494568,0.002680,0.000000
13.010000,0.874329,-575.494568,0.006847,0.000086,0.002177,3.889208,0.198126,0.021767,-575.494568,0.003105,0.000000
13.270000,1.023277,-575.494568,0.006847,0.000104,0.002645,4.551764,0.231878,0.026449,-575.494568,0.003538,0.000000
13.530001,1.038544,-575.450073,0.006847,0.000116,0.002940,4.619673,0.235337,0.029397,-575.450073,0.003972,0.000000
13.790001,1.130524,-575.494568,0.006842,0.000128,0.003261,5.028821,0.256180,0.032607,-575.494568,0.004405,0.000000
14.050000,1.291016,-575.494568,0.006873,0.000158,0.004006,5.742724,0.292548,0.040063,-575.494568,0.004839,0.000000
14.310000,1.349480,-575.583496,0.006881,0.000172,0.004371,6.002785,0.305796,0.043708,-575.583496,0.005273,0.000000
14.570001,1.437729,-575.583496,0.006894,0.000193,0.004891,6.395338,0.325794,0.048912,-575.583496,0.005706,0.000000
14.830001,1.520027,-575.494568,0.006911,0.000208,0.005273,6.761418,0.344443,0.052727,-575.494568,0.006140,0.000000
15.090001,1.661896,-575.539001,0.006911,0.000227,0.005767,7.392481,0.376591,0.057670,-575.539001,0.006574,0.000000
15.350000,1.737114,-575.494568,0.006920,0.000241,0.006131,7.727069,0.393636,0.061312,-575.494568,0.007007,0.000000
15.610001,1.786644,-575.583496,0.006929,0.000251,0.006365,7.947389,0.404859,0.063654,-575.583496,0.007441,0.000000
15.870001,1.994057,-575.539001,0.006954,0.000277,0.007042,8.870008,0.451860,0.070418,-575.539001,0.007874,0.000000
16.130001,2.037994,-575.583496,0.006967,0.000293,0.007441,9.065452,0.461816,0.074407,-575.583496,0.008308,0.000000
16.390001,2.120285,-575.627991,0.006993,0.000309,0.007857,9.431499,0.480463,0.078571,-575.627991,0.008742,0.000000
16.650002,2.246521,-575.627991,0.007011,0.000328,0.008325,9.993025,0.509069,0.083253,-575.627991,0.009175,0.000000
16.910002,2.373505,-575.627991,0.007036,0.000345,0.008759,10.557876,0.537844,0.087590,-575.627991,0.009609,0.000000
17.170000,2.444626,-575.583496,0.007028,0.000358,0.009106,10.874239,0.553960,0.091057,-575.583496,0.010042,0.000000
17.430000,2.533623,-575.627991,0.007054,0.000372,0.009453,11.270117,0.574127,0.094528,-575.627991,0.010476,0.000000
17.690001,2.763000,-575.627991,0.007062,0.000394,0.010008,12.290440,0.626105,0.100076,-575.627991,0.010910,0.000000
17.950001,2.875832,-575.627991,0.007075,0.000413,0.010502,12.792337,0.651673,0.105019,-575.627991,0.011343,0.000000
18.210001,2.918655,-575.583496,0.007092,0.000430,0.010918,12.982827,0.661377,0.109183,-575.583496,0.011777,0.000000
18.470001,2.919769,-575.672485,0.007114,0.000440,0.011178,12.987782,0.661629,0.111783,-575.672485,0.012210,0.000000
18.730001,3.192352,-575.627991,0.007136,0.000464,0.011794,14.200293,0.723397,0.117941,-575.627991,0.012644,0.000000
18.990002,3.307785,-575.672485,0.007153,0.000480,0.012202,14.713762,0.749555,0.122017,-575.672485,0.013078,0.000000
19.250000,3.393799,-575.627991,0.007166,0.000495,0.012566,15.096371,0.769046,0.125659,-575.627991,0.013511,0.000000
19.510000,3.505516,-575.627991,0.007166,0.000511,0.012991,15.593314,0.794361,0.129909,-575.627991,0.013945,0.000000
19.770000,3.800804,-575.672485,0.007187,0.000536,0.013607,16.906820,0.861275,0.136067,-575.672485,0.014378,0.000000
20.030001,3.858894,-575.627991,0.007222,0.000550,0.013980,17.165220,0.874438,0.139795,-575.627991,0.014812,0.000000
20.290001,3.954597,-575.761414,0.007222,0.000567,0.014413,17.590929,0.896125,0.144133,-575.761414,0.015246,0.000000
20.550001,4.068169,-575.627991,0.007256,0.000584,0.014830,18.096117,0.921860,0.148296,-575.627991,0.015679,0.000000
20.810001,4.175415,-575.716980,0.007239,0.000597,0.015176,18.573174,0.946163,0.151763,-575.716980,0.016113,0.000000
21.070002,4.376495,-575.672485,0.007265,0.000617,0.015679,19.467623,0.991728,0.156793,-575.672485,0.016546,0.000000
21.330002,4.389526,-575.672485,0.007274,0.000629,0.015974,19.525589,0.994681,0.159741,-575.672485,0.016980,0.000000
21.590000,4.466980,-575.761414,0.007295,0.000639,0.016243,19.870119,1.012232,0.162429,-575.761414,0.017414,0.000000
21.850000,4.900047,-575.716980,0.007317,0.000669,0.016980,21.796499,1.110367,0.169802,-575.716980,0.017847,0.000000
22.110001,4.937660,-575.716980,0.007338,0.000682,0.017327,21.963810,1.118890,0.173272,-575.716980,0.018272,0.000000
22.370001,5.100754,-575.627991,0.007347,0.000703,0.017856,22.689285,1.155847,0.178560,-575.627991,0.018706,0.000000
22.630001,5.172256,-575.761414,0.007364,0.000718,0.018246,23.007345,1.172050,0.182462,-575.761414,0.019139,0.000000
22.890001,5.269814,-575.761414,0.007381,0.000734,0.018645,23.441301,1.194157,0.186451,-575.761414,0.019573,0.000000
23.150002,5.408340,-575.716980,0.007394,0.000749,0.019027,24.057499,1.225548,0.190267,-575.716980,0.020007,0.000000
23.410002,5.477600,-575.716980,0.007416,0.000763,0.019382,24.365582,1.241242,0.193824,-575.716980,0.020440,0.000000
23.670002,5.732674,-575.761414,0.007429,0.000782,0.019859,25.500206,1.299042,0.198593,-575.761414,0.020874,0.000000
23.930000,5.949394,-575.761414,0.007455,0.000804,0.020414,26.464228,1.348152,0.204142,-575.761414,0.021308,0.000000
24.190001,6.016052,-575.761414,0.007455,0.000821,0.020857,26.760736,1.363257,0.208567,-575.761414,0.021741,0.000000
24.450001,6.115845,-575.761414,0.007480,0.000837,0.021264,27.204636,1.385870,0.212643,-575.761414,0.022175,0.000000
24.710001,6.266281,-575.805908,0.007498,0.000856,0.021732,27.873810,1.419960,0.217325,-575.805908,0.022608,0.000000
24.970001,6.250641,-575.761414,0.007511,0.000866,0.021993,27.804239,1.416415,0.219929,-575.761414,0.023042,0.000000
25.230001,6.388046,-575.761414,0.007524,0.000883,0.022435,28.415449,1.447552,0.224350,-575.761414,0.023476,0.000000
25.490002,6.859100,-575.850403,0.007549,0.000909,0.023086,30.510801,1.554294,0.230856,-575.850403,0.023909,0.000000
25.750002,6.960388,-575.761414,0.007567,0.000928,0.023571,30.961353,1.577246,0.235712,-575.761414,0.024343,0.000000
26.010002,6.930595,-575.850403,0.007580,0.000943,0.023961,30.828829,1.570495,0.239614,-575.850403,0.024777,0.000000
26.270000,7.012894,-575.850403,0.007588,0.000958,0.024343,31.194908,1.589144,0.243429,-575.850403,0.025210,0.000000
26.530001,7.089600,-575.716980,0.007618,0.000974,0.024733,31.536114,1.606526,0.247332,-575.716980,0.025644,0.000000
26.790001,7.310791,-575.850403,0.007618,0.000992,0.025201,32.520023,1.656649,0.252013,-575.850403,0.026078,0.000000
27.050001,7.325684,-575.850403,0.007640,0.001006,0.025540,32.586269,1.660024,0.255397,-575.850403,0.026511,0.000000
27.310001,7.581505,-575.850403,0.007644,0.001026,0.026060,33.724216,1.717993,0.260601,-575.850403,0.026945,0.000000
27.570002,7.943077,-575.850403,0.007670,0.001049,0.026650,35.332573,1.799927,0.266498,-575.850403,0.027378,0.000000
27.830002,7.784447,-575.805908,0.007696,0.001061,0.026962,34.626949,1.763981,0.269621,-575.805908,0.027812,0.000000
28.090002,7.934509,-575.850403,0.007687,0.001078,0.027387,35.294460,1.797986,0.273867,-575.850403,0.028246,0.000000
28.350002,7.982552,-575.850403,0.007718,0.001093,0.027760,35.508163,1.808872,0.277599,-575.850403,0.028679,0.000000
28.610001,8.313217,-575.894897,0.007726,0.001113,0.028280,36.979038,1.883802,0.282800,-575.894897,0.029113,0.000000
28.870001,8.316193,-575.850403,0.007739,0.001128,0.028662,36.992271,1.884476,0.286619,-575.850403,0.029546,0.000000
29.130001,8.209694,-575.894897,0.007765,0.001140,0.028948,36.518543,1.860343,0.289480,-575.894897,0.029980,0.000000
29.390001,8.861717,-575.939331,0.007769,0.001168,0.029668,39.418888,2.008094,0.296675,-575.939331,0.030414,0.000000
29.650002,8.871025,-575.894897,0.007804,0.001184,0.030084,39.460289,2.010203,0.300839,-575.894897,0.030847,0.000000
29.910002,8.691917,-575.939331,0.007808,0.001195,0.030353,38.663578,1.969617,0.303530,-575.939331,0.031281,0.000000
30.170002,8.980133,-575.939331,0.007830,0.001216,0.030882,39.945625,2.034927,0.308817,-575.939331,0.031714,0.000000
30.430002,8.872894,-575.939331,0.007847,0.001229,0.031211,39.468605,2.010627,0.312114,-575.939331,0.032148,0.000000
30.690001,9.271332,-575.939331,0.007847,0.001246,0.031653,41.240944,2.100914,0.316535,-575.939331,0.032582,0.000000
30.950001,9.346924,-575.850403,0.007881,0.001262,0.032061,41.577194,2.118043,0.320611,-575.850403,0.033007,0.000000
31.210001,9.444481,-575.983826,0.007886,0.001281,0.032530,42.011150,2.140150,0.325297,-575.983826,0.033440,0.000000
31.470001,9.927818,-575.894897,0.007916,0.001306,0.033180,44.161140,2.249676,0.331799,-575.894897,0.033874,0.000000
31.730001,9.819458,-575.983826,0.007916,0.001320,0.033536,43.679131,2.225121,0.335357,-575.983826,0.034307,0.000000
31.990002,9.912926,-576.028320,0.007938,0.001338,0.033986,44.094894,2.246301,0.339865,-576.028320,0.034741,0.000000
32.250000,9.814247,-575.939331,0.007963,0.001348,0.034238,43.655952,2.223940,0.342378,-575.939331,0.035175,0.000000
32.510002,10.129646,-575.939331,0.007972,0.001369,0.034776,45.058918,2.295411,0.347756,-575.939331,0.035608,0.000000
32.770000,10.260353,-575.983826,0.007976,0.001386,0.035192,45.640331,2.325029,0.351920,-575.983826,0.036042,0.000000
33.030003,10.258118,-575.983826,0.008002,0.001398,0.035513,45.630386,2.324523,0.355129,-575.983826,0.036475,0.000000
33.290001,10.768265,-576.028320,0.007998,0.001424,0.036172,47.899635,2.440124,0.361719,-576.028320,0.036909,0.000000
33.550003,10.841255,-575.983826,0.008058,0.001441,0.036597,48.224312,2.456664,0.365969,-575.983826,0.037343,0.000000
33.810001,10.719856,-575.983826,0.008050,0.001455,0.036952,47.684303,2.429154,0.369523,-575.983826,0.037776,0.000000
34.070004,10.885567,-576.028320,0.008084,0.001473,0.037412,48.421417,2.466705,0.374122,-576.028320,0.038210,0.000000
34.330002,10.825981,-576.072815,0.008101,0.001485,0.037716,48.156368,2.453202,0.377157,-576.072815,0.038643,0.000000
34.590000,11.118668,-575.983826,0.008114,0.001505,0.038218,49.458305,2.519526,0.382184,-575.983826,0.039077,0.000000
34.850002,11.019615,-576.028320,0.008119,0.001514,0.038461,49.017696,2.497081,0.384613,-576.028320,0.039511,0.000000
35.110001,11.311928,-576.072815,0.008127,0.001535,0.038982,50.317966,2.563319,0.389818,-576.072815,0.039944,0.000000
35.370003,11.744255,-576.072815,0.008140,0.001556,0.039511,52.241055,2.661286,0.395105,-576.072815,0.040378,0.000000
35.630001,11.720047,-576.072815,0.008170,0.001571,0.039892,52.133373,2.655801,0.398924,-576.072815,0.040811,0.000000
35.890003,11.823196,-576.117249,0.008183,0.001588,0.040326,52.592205,2.679175,0.403258,-576.117249,0.041245,0.000000
36.150002,11.853363,-576.072815,0.008188,0.001604,0.040733,52.726391,2.686011,0.407334,-576.072815,0.041679,0.000000
36.410000,12.230942,-576.072815,0.008209,0.001626,0.041289,54.405945,2.771571,0.412887,-576.072815,0.042112,0.000000
36.670002,12.225357,-576.072815,0.008231,0.001641,0.041679,54.381104,2.770306,0.416789,-576.072815,0.042546,0.000000
36.930000,12.009010,-576.161743,0.008252,0.001651,0.041930,53.418747,2.721281,0.419302,-576.161743,0.042980,0.000000
37.190002,12.655075,-576.072815,0.008261,0.001676,0.042572,56.292587,2.867681,0.425721,-576.072815,0.043413,0.000000
37.450001,12.636086,-576.117249,0.008265,0.001691,0.042962,56.208115,2.863378,0.429623,-576.117249,0.043847,0.000000
37.710003,12.718384,-576.117249,0.008291,0.001708,0.043387,56.574196,2.882027,0.433874,-576.117249,0.044281,0.000000
37.970001,12.910522,-576.161743,0.008313,0.001727,0.043864,57.428871,2.925566,0.438643,-576.161743,0.044714,0.000000
38.230003,13.055008,-576.161743,0.008308,0.001744,0.044306,58.071575,2.958307,0.443064,-576.161743,0.045148,0.000000
38.490002,13.015533,-576.161743,0.008334,0.001759,0.044688,57.895985,2.949362,0.446879,-576.161743,0.045581,0.000000
38.750000,12.964890,-576.117249,0.008343,0.001774,0.045052,57.670708,2.937886,0.450524,-576.117249,0.046015,0.000000
39.010002,13.357742,-576.206238,0.008373,0.001792,0.045529,59.418205,3.026908,0.455293,-576.206238,0.046449,0.000000
39.270000,13.567017,-576.161743,0.008386,0.001811,0.046006,60.349102,3.074330,0.460062,-576.161743,0.046882,0.000000
39.530003,13.536858,-576.206238,0.008395,0.001827,0.046405,60.214951,3.067496,0.464051,-576.206238,0.047316,0.000000
39.790001,13.404289,-576.161743,0.008395,0.001839,0.046717,59.625256,3.037455,0.467173,-576.161743,0.047749,0.000000
40.050003,13.918541,-576.161743,0.008429,0.001862,0.047290,61.912762,3.153986,0.472896,-576.161743,0.048174,0.000000
40.310001,14.035835,-576.161743,0.008451,0.001879,0.047715,62.434513,3.180566,0.477147,-576.161743,0.048608,0.000000
40.570004,14.006042,-576.206238,0.008455,0.001894,0.048096,62.301987,3.173815,0.480962,-576.206238,0.049042,0.000000
40.830002,13.932686,-576.206238,0.008468,0.001908,0.048452,61.975681,3.157192,0.484520,-576.206238,0.049475,0.000000
41.090000,14.615616,-576.206238,0.008472,0.001934,0.049111,65.013504,3.311946,0.491109,-576.206238,0.049909,0.000000
41.350002,14.630516,-576.250732,0.008515,0.001949,0.049510,65.079788,3.315322,0.495098,-576.250732,0.050343,0.000000
41.610001,14.658440,-576.250732,0.008507,0.001966,0.049944,65.203995,3.321650,0.499436,-576.250732,0.050776,0.000000
41.870003,14.716904,-576.206238,0.008537,0.001984,0.050403,65.464058,3.334898,0.504031,-576.206238,0.051210,0.000000
42.130001,14.537422,-576.250732,0.008541,0.001997,0.050715,64.665680,3.294227,0.507153,-576.250732,0.051643,0.000000
42.390003,14.755630,-576.250732,0.008576,0.002015,0.051184,65.636322,3.343674,0.511835,-576.250732,0.052077,0.000000
42.650002,14.650620,-576.250732,0.008584,0.002028,0.051504,65.169212,3.319878,0.515045,-576.250732,0.052510,0.000000
42.910004,14.560135,-576.295227,0.008576,0.002038,0.051764,64.766716,3.299374,0.517645,-576.295227,0.052944,0.000000
43.170002,15.469467,-576.295227,0.008597,0.002067,0.052493,68.811630,3.505431,0.524931,-576.295227,0.053378,0.000000
43.430000,15.407280,-576.339661,0.008623,0.002081,0.052866,68.535004,3.491340,0.528659,-576.339661,0.053811,0.000000
43.690002,15.583412,-576.295227,0.008636,0.002100,0.053351,69.318481,3.531252,0.533515,-576.295227,0.054245,0.000000
43.950001,15.438187,-576.295227,0.008658,0.002116,0.053742,68.672485,3.498343,0.537417,-576.295227,0.054678,0.000000
44.210003,15.453087,-576.206238,0.008675,0.002130,0.054098,68.738762,3.501719,0.540975,-576.206238,0.055112,0.000000
44.470001,15.650818,-576.295227,0.008675,0.002147,0.054540,69.618317,3.546526,0.545396,-576.295227,0.055546,0.000000
44.730003,15.613953,-576.339661,0.008692,0.002162,0.054904,69.454330,3.538172,0.549041,-576.339661,0.055979,0.000000
44.990002,16.009781,-576.295227,0.008688,0.002181,0.055390,71.215065,3.627868,0.553897,-576.295227,0.056413,0.000000
45.250004,16.395187,-576.339661,0.008739,0.002203,0.055953,72.929436,3.715203,0.559532,-576.339661,0.056846,0.000000
45.510002,16.388115,-576.339661,0.008744,0.002220,0.056378,72.897980,3.713600,0.563783,-576.339661,0.057280,0.000000
45.770000,16.400024,-576.339661,0.008761,0.002236,0.056795,72.950951,3.716299,0.567946,-576.339661,0.057714,0.000000
46.030003,16.276024,-576.428650,0.008752,0.002250,0.057141,72.399368,3.688200,0.571413,-576.428650,0.058147,0.000000
46.290001,16.212349,-576.384155,0.008778,0.002264,0.057497,72.116127,3.673771,0.574971,-576.384155,0.058581,0.000000
46.550003,16.172508,-576.384155,0.008808,0.002278,0.057852,71.938911,3.664743,0.578525,-576.384155,0.059014,0.000000
46.810001,17.215149,-576.384155,0.008800,0.002308,0.058624,76.576805,3.901008,0.586242,-576.384155,0.059448,0.000000
47.070004,17.152222,-576.384155,0.008843,0.002326,0.059084,76.296890,3.886749,0.590841,-576.384155,0.059882,0.000000
47.330002,17.019279,-576.428650,0.008843,0.002343,0.059500,75.705536,3.856624,0.595004,-576.428650,0.060315,0.000000
47.590004,16.806290,-576.428650,0.008864,0.002357,0.059856,74.758110,3.808360,0.598558,-576.428650,0.060749,0.000000
47.850002,16.822670,-576.428650,0.008869,0.002373,0.060272,74.830971,3.812072,0.602722,-576.428650,0.061183,0.000000
48.110001,16.920601,-576.428650,0.008882,0.002390,0.060714,75.266594,3.834263,0.607143,-576.428650,0.061616,0.000000
48.370003,16.859161,-576.384155,0.008903,0.002403,0.061027,74.993294,3.820341,0.610265,-576.384155,0.062050,0.000000
48.630001,17.206589,-576.428650,0.008916,0.002424,0.061582,76.538727,3.899069,0.615818,-576.428650,0.062484,0.000000
48.890003,17.915955,-576.384155,0.008933,0.002448,0.062188,79.694145,4.059813,0.621885,-576.384155,0.062917,0.000000
49.150002,17.486237,-576.473145,0.008946,0.002463,0.062553,77.782661,3.962438,0.625530,-576.473145,0.063342,0.000000
49.410004,17.406181,-576.473145,0.008968,0.002477,0.062908,77.426559,3.944297,0.629084,-576.473145,0.063776,0.000000
49.670002,17.257599,-576.384155,0.008985,0.002491,0.063264,76.765633,3.910628,0.632641,-576.384155,0.064209,0.000000
49.930004,17.705940,-576.517578,0.008990,0.002512,0.063802,78.759956,4.012223,0.638016,-576.517578,0.064643,0.000000
50.190002,17.551773,-576.428650,0.008981,0.002527,0.064183,78.074188,3.977289,0.641831,-576.428650,0.065076,0.000000
50.450001,17.152222,-576.473145,0.009007,0.002537,0.064435,76.296890,3.886749,0.644348,-576.473145,0.065510,0.000000
50.710003,18.353867,-576.517578,0.009015,0.002566,0.065180,81.642075,4.159045,0.651804,-576.517578,0.065944,0.000000
50.970001,18.261147,-576.428650,0.009054,0.002583,0.065597,81.229637,4.138035,0.655968,-576.428650,0.066377,0.000000
51.230003,17.810944,-576.473145,0.009058,0.002595,0.065918,79.227036,4.036017,0.659177,-576.473145,0.066811,0.000000
51.490002,18.070862,-576.428650,0.009058,0.002614,0.066403,80.383209,4.094916,0.664033,-576.428650,0.067245,0.000000
51.750004,17.487358,-576.473145,0.009093,0.002623,0.066629,77.787651,3.962692,0.666289,-576.473145,0.067678,0.000000
52.010002,18.109589,-576.473145,0.009102,0.002647,0.067245,80.555473,4.103691,0.672447,-576.473145,0.068112,0.000000
52.270004,18.294655,-576.517578,0.009110,0.002661,0.067583,81.378693,4.145628,0.675827,-576.517578,0.068546,0.000000
52.530003,18.363922,-576.562073,0.009119,0.002678,0.068034,81.686806,4.161324,0.680339,-576.562073,0.068979,0.000000
52.790001,19.208458,-576.517578,0.009127,0.002705,0.068702,85.443489,4.352699,0.687015,-576.517578,0.069413,0.000000
53.050003,18.759377,-576.562073,0.009153,0.002718,0.069031,83.445877,4.250936,0.690312,-576.562073,0.069846,0.000000
53.310001,18.790657,-576.562073,0.009158,0.002736,0.069482,83.585014,4.258024,0.694820,-576.562073,0.070280,0.000000
53.570004,18.505424,-576.562073,0.009166,0.002746,0.069759,82.316238,4.193389,0.697594,-576.562073,0.070714,0.000000
53.830002,18.740387,-576.562073,0.009175,0.002765,0.070219,83.361404,4.246632,0.702193,-576.562073,0.071147,0.000000
54.090004,18.833855,-576.562073,0.009196,0.002780,0.070609,83.777168,4.267813,0.706095,-576.562073,0.071581,0.000000
54.350002,18.845772,-576.562073,0.009214,0.002794,0.070965,83.830177,4.270513,0.709649,-576.562073,0.072014,0.000000
54.610004,19.628868,-576.562073,0.009240,0.002822,0.071667,87.313568,4.447965,0.716674,-576.562073,0.072448,0.000000
54.870003,19.955811,-576.562073,0.009240,0.002840,0.072127,88.767876,4.522051,0.721272,-576.562073,0.072882,0.000000
55.130001,19.643761,-576.562073,0.009261,0.002853,0.072465,87.379814,4.451340,0.724652,-576.562073,0.073315,0.000000
55.390003,19.798302,-576.562073,0.009261,0.002871,0.072925,88.067245,4.486360,0.729251,-576.562073,0.073749,0.000000
55.650002,19.517159,-576.606567,0.009287,0.002883,0.073220,86.816658,4.422651,0.732199,-576.606567,0.074182,0.000000
55.910004,19.834419,-576.562073,0.009300,0.002900,0.073653,88.227905,4.494544,0.736533,-576.562073,0.074616,0.000000
56.170002,19.833305,-576.606567,0.009304,0.002913,0.073983,88.222946,4.494291,0.739830,-576.606567,0.075050,0.000000
56.430004,20.047417,-576.651062,0.009304,0.002932,0.074469,89.175362,4.542809,0.744686,-576.651062,0.075483,0.000000
56.690002,20.841690,-576.651062,0.009326,0.002954,0.075023,92.708466,4.722795,0.750234,-576.651062,0.075917,0.000000
56.950005,20.896423,-576.695557,0.009334,0.002970,0.075431,92.951935,4.735198,0.754311,-576.695557,0.076350,0.000000
57.210003,20.909088,-576.606567,0.009347,0.002985,0.075830,93.008270,4.738067,0.758300,-576.606567,0.076784,0.000000
57.470001,20.991753,-576.606567,0.009373,0.003002,0.076255,93.375977,4.756799,0.762550,-576.606567,0.077218,0.000000
57.730003,21.629997,-576.651062,0.009369,0.003024,0.076819,96.215034,4.901427,0.768186,-576.651062,0.077651,0.000000
57.990002,21.456474,-576.606567,0.009382,0.003039,0.077192,95.443161,4.862107,0.771918,-576.606567,0.078085,0.000000
58.250004,21.165649,-576.695557,0.009408,0.003049,0.077434,94.149513,4.796205,0.774344,-576.695557,0.078510,0.000000
58.510002,22.091370,-576.651062,0.009403,0.003074,0.078085,98.267319,5.005976,0.780850,-576.651062,0.078943,0.000000
58.770004,22.067162,-576.651062,0.009421,0.003090,0.078493,98.159637,5.000490,0.784927,-576.651062,0.079377,0.000000
59.030003,22.442146,-576.651062,0.009429,0.003107,0.078909,99.827652,5.085463,0.789086,-576.651062,0.079811,0.000000
59.290001,22.547897,-576.562073,0.009451,0.003124,0.079342,100.298058,5.109427,0.793424,-576.562073,0.080244,0.000000
59.550003,22.801109,-576.695557,0.009477,0.003142,0.079819,101.424400,5.166805,0.798193,-576.695557,0.080678,0.000000
59.810001,22.820847,-576.695557,0.009477,0.003156,0.080158,101.512192,5.171278,0.801576,-576.695557,0.081111,0.000000
60.070004,22.805580,-576.695557,0.009507,0.003171,0.080548,101.444290,5.167818,0.805479,-576.695557,0.081545,0.000000
60.330002,23.481064,-576.739990,0.009494,0.003191,0.081051,104.448990,5.320885,0.810509,-576.739990,0.081979,0.000000
60.590004,23.845245,-576.651062,0.009524,0.003210,0.081545,106.068947,5.403410,0.815452,-576.651062,0.082412,0.000000
60.850002,23.797951,-576.695557,0.009524,0.003227,0.081970,105.858574,5.392693,0.819702,-576.695557,0.082846,0.000000
61.110004,23.590538,-576.739990,0.009546,0.003238,0.082239,104.935951,5.345693,0.822390,-576.739990,0.083279,0.000000
61.370003,24.428375,-576.695557,0.009546,0.003261,0.082837,108.662842,5.535549,0.828373,-576.695557,0.083713,0.000000
61.630001,24.613823,-576.784485,0.009567,0.003277,0.083236,109.487755,5.577572,0.832363,-576.784485,0.084147,0.000000
61.890003,24.684196,-576.695557,0.009576,0.003292,0.083626,109.800789,5.593519,0.836265,-576.695557,0.084580,0.000000
62.150002,24.600410,-576.784485,0.009593,0.003307,0.083991,109.428093,5.574533,0.839906,-576.784485,0.085014,0.000000
62.410004,25.692581,-576.739990,0.009602,0.003333,0.084650,114.286308,5.822022,0.846499,-576.739990,0.085448,0.000000
62.670002,25.832222,-576.784485,0.009623,0.003348,0.085040,114.907463,5.853665,0.850402,-576.784485,0.085881,0.000000
62.930004,25.976700,-576.784485,0.009628,0.003365,0.085465,115.550133,5.886404,0.854648,-576.784485,0.086315,0.000000
63.190002,26.194916,-576.784485,0.009649,0.003383,0.085925,116.520805,5.935853,0.859247,-576.784485,0.086749,0.000000
63.450005,26.048569,-576.828979,0.009653,0.003394,0.086220,115.869820,5.902690,0.862195,-576.828979,0.087182,0.000000
63.710003,26.474190,-576.739990,0.009671,0.003414,0.086705,117.763077,5.999137,0.867051,-576.739990,0.087616,0.000000
63.970001,26.398598,-576.784485,0.009692,0.003426,0.087026,117.426826,5.982008,0.870261,-576.784485,0.088049,0.000000
64.230003,26.833900,-576.784485,0.009679,0.003445,0.087512,119.363152,6.080648,0.875117,-576.784485,0.088483,0.000000
64.490005,27.646049,-576.784485,0.009697,0.003464,0.087997,122.975769,6.264684,0.879973,-576.784485,0.088917,0.000000
64.750000,27.854950,-576.828979,0.009722,0.003481,0.088422,123.905006,6.312022,0.884223,-576.828979,0.089350,0.000000
65.010002,28.264183,-576.784485,0.009727,0.003498,0.088856,125.725365,6.404756,0.888557,-576.784485,0.089784,0.000000
65.270004,28.533043,-576.828979,0.009748,0.003515,0.089289,126.921310,6.465680,0.892895,-576.828979,0.090218,0.000000
65.530006,28.726677,-576.828979,0.009748,0.003532,0.089723,127.782639,6.509558,0.897232,-576.828979,0.090651,0.000000
65.790001,29.139633,-576.828979,0.009757,0.003549,0.090148,129.619568,6.603135,0.901479,-576.828979,0.091085,0.000000
66.050003,28.992920,-576.828979,0.009774,0.003559,0.090408,128.966949,6.569890,0.904083,-576.828979,0.091518,0.000000
66.310005,29.734314,-576.784485,0.009796,0.003579,0.090911,132.264832,6.737892,0.909113,-576.784485,0.091952,0.000000
66.570000,30.520767,-576.873474,0.009791,0.003601,0.091457,135.763153,6.916105,0.914574,-576.873474,0.092386,0.000000
66.830002,30.836906,-576.828979,0.009826,0.003618,0.091891,137.169403,6.987743,0.918912,-576.828979,0.092819,0.000000
67.090004,30.862976,-576.873474,0.009826,0.003632,0.092264,137.285370,6.993650,0.922640,-576.873474,0.093244,0.000000
67.350006,31.652031,-576.828979,0.009822,0.003652,0.092767,140.795273,7.172453,0.927670,-576.828979,0.093678,0.000000
67.610001,31.659851,-576.828979,0.009830,0.003662,0.093019,140.830048,7.174225,0.930187,-576.828979,0.094111,0.000000
67.870003,31.885139,-576.873474,0.009860,0.003676,0.093374,141.832184,7.225276,0.933741,-576.873474,0.094545,0.000000
68.130005,33.540703,-576.917908,0.009860,0.003707,0.094146,149.196503,7.600432,0.941459,-576.917908,0.094979,0.000000
68.390007,34.158844,-576.917908,0.009865,0.003725,0.094623,151.946121,7.740505,0.946228,-576.917908,0.095412,0.000000
68.650002,34.352852,-576.962402,0.009891,0.003741,0.095022,152.809113,7.784468,0.950217,-576.962402,0.095846,0.000000
68.910004,34.511848,-576.917908,0.009908,0.003755,0.095369,153.516373,7.820497,0.953688,-576.917908,0.096279,0.000000
69.170006,34.878265,-576.917908,0.009916,0.003771,0.095785,155.146271,7.903528,0.957851,-576.917908,0.096713,0.000000
69.430000,35.587639,-576.962402,0.009908,0.003789,0.096245,158.301727,8.064274,0.962446,-576.962402,0.097147,0.000000
69.690002,35.735840,-576.917908,0.009938,0.003801,0.096548,158.960953,8.097857,0.965481,-576.917908,0.097580,0.000000
69.950005,36.628418,-576.962402,0.009938,0.003824,0.097120,162.931335,8.300118,0.971204,-576.962402,0.098014,0.000000
70.210007,38.041573,-576.917908,0.009942,0.003846,0.097693,169.217361,8.620344,0.976931,-576.917908,0.098447,0.000000
70.470001,38.272438,-576.917908,0.009960,0.003861,0.098057,170.244308,8.672658,0.980572,-576.917908,0.098881,0.000000
70.730003,38.795624,-576.962402,0.009977,0.003876,0.098439,172.571548,8.791214,0.984387,-576.962402,0.099315,0.000000
70.990005,39.190338,-576.917908,0.009985,0.003890,0.098803,174.327332,8.880657,0.988028,-576.917908,0.099748,0.000000
71.250000,40.130577,-577.006897,0.009977,0.003910,0.099323,178.509720,9.093719,0.993232,-577.006897,0.100182,0.000000
71.510002,40.682060,-576.962402,0.010003,0.003927,0.099740,180.962845,9.218687,0.997396,-576.962402,0.100615,0.000000
71.770004,40.890961,-576.962402,0.010016,0.003937,0.100000,181.892075,9.266025,0.999996,-576.962402,0.101049,0.000000
72.030006,42.596428,-577.051392,0.010011,0.003963,0.100668,189.478378,9.652489,1.006676,-577.051392,0.101482,0.000000
72.290001,43.529594,-576.962402,0.010042,0.003980,0.101092,193.629303,9.863947,1.010923,-576.962402,0.101916,0.000000
72.550003,43.769775,-577.095886,0.010037,0.003993,0.101413,194.697678,9.918372,1.014132,-577.095886,0.102350,0.000000
72.810005,44.898437,-576.962402,0.010059,0.004013,0.101925,199.718231,10.174131,1.019250,-576.962402,0.102783,0.000000
73.070000,44.867531,-576.962402,0.010076,0.004023,0.102185,199.580750,10.167128,1.021850,-576.962402,0.103217,0.000000
73.330002,46.600922,-577.095886,0.010085,0.004046,0.102766,207.291260,10.559919,1.027663,-577.095886,0.103651,0.000000
73.590004,47.219063,-576.917908,0.010093,0.004059,0.103104,210.040878,10.699992,1.031043,-576.917908,0.104084,0.000000
73.850006,48.047218,-577.051392,0.010093,0.004077,0.103547,213.724701,10.887655,1.035468,-577.051392,0.104518,0.000000
74.110001,49.764603,-576.962402,0.010111,0.004103,0.104206,221.364014,11.276820,1.042057,-576.962402,0.104952,0.000000
74.370003,50.571907,-577.051392,0.010115,0.004116,0.104544,224.955078,11.459758,1.045441,-577.051392,0.105385,0.000000
74.630005,51.244781,-577.051392,0.010111,0.004133,0.104977,227.948166,11.612234,1.049775,-577.051392,0.105819,0.000000
74.890007,52.091187,-577.051392,0.010119,0.004145,0.105281,231.713165,11.804031,1.052810,-577.051392,0.106252,0.000000
75.150002,53.058235,-577.051392,0.010141,0.004162,0.105723,236.014816,12.023168,1.057235,-577.051392,0.106686,0.000000
75.410004,54.038689,-577.051392,0.010149,0.004177,0.106088,240.376099,12.245342,1.060876,-577.051392,0.107120,0.000000
75.670006,54.883232,-577.051392,0.010158,0.004192,0.106469,244.132812,12.436718,1.064691,-577.051392,0.107553,0.000000
75.930000,56.605453,-577.095886,0.010162,0.004218,0.107137,251.793640,12.826979,1.071371,-577.095886,0.107987,0.000000
76.190002,58.268845,-577.051392,0.010179,0.004237,0.107623,259.192780,13.203909,1.076227,-577.051392,0.108412,0.000000
76.450005,58.991615,-577.184814,0.010179,0.004251,0.107987,262.407806,13.367691,1.079868,-577.184814,0.108845,0.000000
76.710007,60.096443,-577.051392,0.010188,0.004268,0.108403,267.322327,13.618049,1.084032,-577.051392,0.109279,0.000000
76.970001,60.783470,-577.140320,0.010192,0.004280,0.108715,270.378387,13.773731,1.087154,-577.140320,0.109713,0.000000
77.230003,62.039856,-577.095886,0.010197,0.004298,0.109166,275.967072,14.058432,1.091662,-577.095886,0.110146,0.000000
77.490005,63.039307,-577.051392,0.010236,0.004311,0.109505,280.412842,14.284911,1.095046,-577.051392,0.110580,0.000000
77.750000,63.911407,-577.095886,0.010218,0.004326,0.109886,284.292145,14.482532,1.098861,-577.095886,0.111014,0.000000
78.010002,65.926682,-577.051392,0.010227,0.004350,0.110493,293.256531,14.939199,1.104932,-577.051392,0.111447,0.000000
78.270004,67.361435,-577.095886,0.010240,0.004367,0.110910,299.638641,15.264319,1.109095,-577.095886,0.111881,0.000000
78.530006,67.005814,-577.184814,0.010231,0.004361,0.110771,298.056732,15.183735,1.107706,-577.184814,0.110987,0.000000
78.790001,66.445404,-577.140320,0.010257,0.004360,0.110753,295.563904,15.056744,1.107532,-577.140320,0.110771,0.000000
79.050003,65.922211,-577.229309,0.010257,0.004359,0.110719,293.236633,14.938187,1.107188,-577.229309,0.110771,0.000000
79.310005,65.505157,-577.095886,0.010244,0.004358,0.110701,291.381500,14.843681,1.107014,-577.095886,0.110771,0.000000
79.570007,65.098526,-577.184814,0.010266,0.004358,0.110701,289.572693,14.751537,1.107014,-577.184814,0.110771,0.000000
79.830002,64.747757,-577.184814,0.010266,0.004358,0.110693,288.012421,14.672051,1.106927,-577.184814,0.110771,0.000000
80.090004,64.436447,-577.140320,0.010257,0.004358,0.110693,286.627625,14.601508,1.106927,-577.140320,0.110771,0.000000
80.350006,64.181366,-577.229309,0.010270,0.004358,0.110684,285.492981,14.543705,1.106840,-577.229309,0.110771,0.000000
80.610001,63.909912,-577.184814,0.010274,0.004358,0.110684,284.285492,14.482193,1.106840,-577.184814,0.110771,0.000000
80.870003,63.692078,-577.184814,0.010266,0.004358,0.110684,283.316498,14.432831,1.106840,-577.184814,0.110771,0.000000
81.130005,63.446304,-577.184814,0.010279,0.004358,0.110684,282.223267,14.377138,1.106840,-577.184814,0.110771,0.000000
81.390007,63.276505,-577.184814,0.010279,0.004358,0.110684,281.467957,14.338661,1.106840,-577.184814,0.110771,0.000000
81.650002,63.100372,-577.229309,0.010283,0.004358,0.110684,280.684479,14.298748,1.106840,-577.229309,0.110771,0.000000
81.910004,62.914932,-577.184814,0.010274,0.004358,0.110684,279.859589,14.256727,1.106840,-577.184814,0.110771,0.000000
82.170006,62.747742,-577.229309,0.010279,0.004358,0.110684,279.115906,14.218841,1.106840,-577.229309,0.110771,0.000000
82.430000,62.617035,-577.229309,0.010279,0.004357,0.110675,278.534485,14.189223,1.106753,-577.229309,0.110771,0.000000
82.690002,62.488564,-577.184814,0.010287,0.004357,0.110675,277.963013,14.160111,1.106753,-577.184814,0.110771,0.000000
82.950005,62.342598,-577.184814,0.010279,0.004357,0.110675,277.313721,14.127035,1.106753,-577.184814,0.110771,0.000000
83.210007,62.207802,-577.229309,0.010279,0.004357,0.110675,276.714111,14.096490,1.106753,-577.229309,0.110771,0.000000
83.470001,62.100182,-577.273804,0.010292,0.004357,0.110675,276.235413,14.072103,1.106753,-577.273804,0.110771,0.000000
83.730003,61.996292,-577.273804,0.010283,0.004357,0.110675,275.773285,14.048561,1.106753,-577.273804,0.110771,0.000000
83.990005,61.869682,-577.229309,0.010283,0.004357,0.110675,275.210083,14.019871,1.106753,-577.229309,0.110771,0.000000
84.250008,61.787018,-577.273804,0.010292,0.004357,0.110675,274.842377,14.001138,1.106753,-577.273804,0.110771,0.000000
84.510002,61.679771,-577.184814,0.010292,0.004357,0.110675,274.365326,13.976836,1.106753,-577.184814,0.110771,0.000000
84.770004,61.620567,-577.318237,0.010287,0.004357,0.110675,274.101959,13.963420,1.106753,-577.318237,0.110771,0.000000
85.030006,61.510345,-577.318237,0.010283,0.004357,0.110675,273.611694,13.938443,1.106753,-577.318237,0.110771,0.000000
85.290001,61.420975,-577.273804,0.010287,0.004357,0.110675,273.214142,13.918191,1.106753,-577.273804,0.110771,0.000000
85.550003,61.351341,-577.318237,0.010292,0.004357,0.110675,272.904388,13.902413,1.106753,-577.318237,0.110771,0.000000
85.810005,61.267929,-577.273804,0.010283,0.004357,0.110675,272.533356,13.883511,1.106753,-577.273804,0.110771,0.000000
86.070007,61.191597,-577.318237,0.010292,0.004357,0.110675,272.193817,13.866214,1.106753,-577.318237,0.110771,0.000000
86.330002,61.118980,-577.362732,0.010287,0.004357,0.110675,271.870789,13.849759,1.106753,-577.362732,0.110771,0.000000
86.590004,61.054192,-577.273804,0.010305,0.004357,0.110675,271.582611,13.835077,1.106753,-577.273804,0.110771,0.000000
86.850006,60.984924,-577.362732,0.010296,0.004357,0.110675,271.274506,13.819381,1.106753,-577.362732,0.110771,0.000000
87.110001,60.915665,-577.318237,0.010283,0.004357,0.110675,270.966400,13.803687,1.106753,-577.318237,0.110771,0.000000
87.370003,60.850128,-577.362732,0.010292,0.004357,0.110675,270.674896,13.788836,1.106753,-577.362732,0.110771,0.000000
87.630005,60.791290,-577.407227,0.010296,0.004357,0.110675,270.413177,13.775503,1.106753,-577.407227,0.110771,0.000000
87.890007,60.729851,-577.318237,0.010292,0.004357,0.110675,270.139862,13.761580,1.106753,-577.318237,0.110771,0.000000
88.150002,60.681068,-577.362732,0.010279,0.004357,0.110675,269.922882,13.750526,1.106753,-577.362732,0.110771,0.000000
88.410004,60.599152,-577.362732,0.010287,0.004357,0.110675,269.558502,13.731964,1.106753,-577.362732,0.110771,0.000000
88.670006,60.563400,-577.362732,0.010287,0.004357,0.110675,269.399445,13.723863,1.106753,-577.362732,0.110771,0.000000
88.930008,60.507919,-577.407227,0.010292,0.004357,0.110675,269.152679,13.711290,1.106753,-577.407227,0.110771,0.000000
89.190002,60.469566,-577.407227,0.010300,0.004357,0.110675,268.982056,13.702600,1.106753,-577.407227,0.110771,0.000000
89.450005,60.410355,-577.407227,0.010274,0.004357,0.110675,268.718689,13.689182,1.106753,-577.407227,0.110771,0.000000
89.710007,60.360832,-577.362732,0.010287,0.004357,0.110675,268.498383,13.677960,1.106753,-577.362732,0.110771,0.000000
89.970001,60.315025,-577.362732,0.010296,0.004357,0.110675,268.294647,13.667580,1.106753,-577.362732,0.110771,0.000000
90.230003,60.267365,-577.451721,0.010279,0.004357,0.110675,268.082611,13.656780,1.106753,-577.451721,0.110771,0.000000
90.490005,60.240929,-577.362732,0.010292,0.004357,0.110675,267.965027,13.650789,1.106753,-577.362732,0.110771,0.000000
90.750008,60.163475,-577.451721,0.010300,0.004357,0.110675,267.620514,13.633238,1.106753,-577.451721,0.110771,0.000000
91.010002,60.129219,-577.407227,0.010279,0.004357,0.110675,267.468140,13.625476,1.106753,-577.407227,0.110771,0.000000
91.270004,60.096077,-577.407227,0.010287,0.004357,0.110675,267.320709,13.617966,1.106753,-577.407227,0.110771,0.000000
91.530006,60.051765,-577.407227,0.010292,0.004357,0.110675,267.123596,13.607924,1.106753,-577.407227,0.110771,0.000000
91.790001,60.006706,-577.407227,0.010296,0.004357,0.110675,266.923157,13.597714,1.106753,-577.407227,0.110771,0.000000
92.050003,59.963509,-577.451721,0.010300,0.004357,0.110675,266.731018,13.587925,1.106753,-577.451721,0.110771,0.000000
92.310005,59.925529,-577.451721,0.010296,0.004357,0.110675,266.562073,13.579319,1.106753,-577.451721,0.110771,0.000000
92.570007,59.895363,-577.451721,0.010305,0.004357,0.110675,266.427887,13.572484,1.106753,-577.451721,0.110771,0.000000
92.830002,59.833176,-577.451721,0.010292,0.004357,0.110675,266.151245,13.558392,1.106753,-577.451721,0.110771,0.000000
93.090004,59.802643,-577.362732,0.010309,0.004357,0.110675,266.015442,13.551473,1.106753,-577.362732,0.110771,0.000000
93.350006,59.772858,-577.496216,0.010283,0.004357,0.110675,265.882965,13.544724,1.106753,-577.496216,0.110771,0.000000
93.610008,59.743439,-577.496216,0.010296,0.004357,0.110675,265.752075,13.538056,1.106753,-577.496216,0.110771,0.000000
93.870003,59.694283,-577.585144,0.010296,0.004357,0.110675,265.533417,13.526918,1.106753,-577.585144,0.110771,0.000000
94.130005,59.654068,-577.540649,0.010305,0.004357,0.110675,265.354553,13.517805,1.106753,-577.540649,0.110771,0.000000
94.390007,59.641037,-577.540649,0.010305,0.004357,0.110675,265.296570,13.514852,1.106753,-577.540649,0.110771,0.000000
94.650002,59.611618,-577.540649,0.010296,0.004357,0.110675,265.165710,13.508185,1.106753,-577.540649,0.110771,0.000000
94.910004,59.565071,-577.496216,0.010309,0.004357,0.110675,264.958679,13.497639,1.106753,-577.496216,0.110771,0.000000
95.170006,59.533051,-577.540649,0.010305,0.004357,0.110675,264.816223,13.490382,1.106753,-577.540649,0.110771,0.000000
95.430008,59.514053,-577.585144,0.010300,0.004357,0.110675,264.731720,13.486077,1.106753,-577.585144,0.110771,0.000000
95.690002,59.476074,-577.496216,0.010300,0.004357,0.110675,264.562805,13.477470,1.106753,-577.496216,0.110771,0.000000
95.950005,59.444420,-577.629639,0.010292,0.004357,0.110675,264.421997,13.470298,1.106753,-577.629639,0.110771,0.000000
96.210007,59.418358,-577.540649,0.010292,0.004357,0.110675,264.306061,13.464393,1.106753,-577.540649,0.110771,0.000000
96.470001,59.394897,-577.585144,0.010292,0.004357,0.110675,264.201691,13.459076,1.106753,-577.585144,0.110771,0.000000
96.730003,59.362503,-577.585144,0.010300,0.004357,0.110675,264.057587,13.451735,1.106753,-577.585144,0.110771,0.000000
96.990005,59.329361,-577.540649,0.010296,0.004357,0.110675,263.910187,13.444225,1.106753,-577.540649,0.110771,0.000000
97.250008,59.296593,-577.629639,0.010300,0.004357,0.110675,263.764404,13.436800,1.106753,-577.629639,0.110771,0.000000
97.510002,59.276108,-577.585144,0.010305,0.004357,0.110675,263.673309,13.432158,1.106753,-577.585144,0.110771,0.000000
97.770004,59.254883,-577.585144,0.010309,0.004357,0.110675,263.578888,13.427348,1.106753,-577.585144,0.110771,0.000000
98.030006,59.228821,-577.585144,0.010292,0.004357,0.110675,263.462952,13.421442,1.106753,-577.585144,0.110771,0.000000
98.290001,59.187859,-577.585144,0.010292,0.004357,0.110675,263.280731,13.412161,1.106753,-577.585144,0.110771,0.000000
98.550003,59.151367,-577.585144,0.010300,0.004357,0.110675,263.118408,13.403891,1.106753,-577.585144,0.110771,0.000000
98.810005,59.150993,-577.585144,0.010305,0.004357,0.110675,263.116760,13.403807,1.106753,-577.585144,0.110771,0.000000
99.070007,59.121948,-577.585144,0.010305,0.004357,0.110675,262.987549,13.397224,1.106753,-577.585144,0.110771,0.000000
99.330002,59.085831,-577.674133,0.010305,0.004357,0.110675,262.826904,13.389041,1.106753,-577.674133,0.110771,0.000000
99.590004,59.068329,-577.629639,0.010296,0.004357,0.110675,262.749054,13.385075,1.106753,-577.629639,0.110771,0.000000
99.850006,59.043747,-577.629639,0.010296,0.004357,0.110675,262.639709,13.379505,1.106753,-577.629639,0.110771,0.000000
100.110008,59.027367,-577.674133,0.010313,0.004357,0.110675,262.566833,13.375793,1.106753,-577.674133,0.110771,0.000000
100.370003,58.984169,-577.674133,0.010300,0.004357,0.110675,262.374695,13.366004,1.106753,-577.674133,0.110771,0.000000
100.630005,58.965553,-577.718567,0.010300,0.004357,0.110675,262.291870,13.361785,1.106753,-577.718567,0.110771,0.000000
100.890007,58.953636,-577.674133,0.010300,0.004357,0.110675,262.238861,13.359084,1.106753,-577.674133,0.110771,0.000000
101.150002,58.944702,-577.674133,0.010309,0.004357,0.110675,262.199127,13.357060,1.106753,-577.674133,0.110771,0.000000
101.410004,58.907089,-577.629639,0.010296,0.004357,0.110675,262.031830,13.348537,1.106753,-577.629639,0.110771,0.000000
101.670006,58.887726,-577.674133,0.010305,0.004357,0.110675,261.945679,13.344150,1.106753,-577.674133,0.110771,0.000000
101.930008,58.865013,-577.674133,0.010296,0.004357,0.110675,261.844666,13.339003,1.106753,-577.674133,0.110771,0.000000
102.190002,58.856071,-577.629639,0.010287,0.004357,0.110675,261.804871,13.336976,1.106753,-577.629639,0.110771,0.000000
102.450005,58.823303,-577.629639,0.010296,0.004357,0.110675,261.659119,13.329551,1.106753,-577.629639,0.110771,0.000000
102.710007,58.807663,-577.674133,0.010292,0.004357,0.110675,261.589539,13.326007,1.106753,-577.674133,0.110771,0.000000
102.970001,58.782715,-577.674133,0.010296,0.004357,0.110675,261.478577,13.320354,1.106753,-577.674133,0.110771,0.000000
103.230003,58.762611,-577.763062,0.010296,0.004357,0.110675,261.389160,13.315798,1.106753,-577.763062,0.110771,0.000000
103.490005,58.760002,-577.718567,0.010296,0.004357,0.110675,261.377533,13.315207,1.106753,-577.718567,0.110771,0.000000
103.750008,58.727974,-577.807556,0.010305,0.004357,0.110675,261.235077,13.307949,1.106753,-577.807556,0.110771,0.000000
104.010002,58.699677,-577.718567,0.010305,0.004357,0.110675,261.109192,13.301537,1.106753,-577.718567,0.110771,0.000000
104.270004,58.698936,-577.718567,0.010317,0.004357,0.110675,261.105896,13.301370,1.106753,-577.718567,0.110771,0.000000
104.530006,58.669891,-577.763062,0.010300,0.004357,0.110675,260.976715,13.294787,1.106753,-577.763062,0.110771,0.000000
104.790009,58.648293,-577.718567,0.010305,0.004357,0.110675,260.880646,13.289893,1.106753,-577.718567,0.110771,0.000000
105.050003,58.628929,-577.763062,0.010305,0.004357,0.110675,260.794495,13.285505,1.106753,-577.763062,0.110771,0.000000
105.310005,58.614403,-577.763062,0.010300,0.004357,0.110675,260.729889,13.282213,1.106753,-577.763062,0.110771,0.000000
105.570007,58.611053,-577.763062,0.010313,0.004357,0.110675,260.714996,13.281454,1.106753,-577.763062,0.110771,0.000000
105.830002,58.575676,-577.807556,0.010296,0.004357,0.110675,260.557617,13.273437,1.106753,-577.807556,0.110771,0.000000
106.090004,58.556686,-577.807556,0.010317,0.004357,0.110675,260.473145,13.269135,1.106753,-577.807556,0.110771,0.000000
106.350006,58.554451,-577.763062,0.010305,0.004357,0.110675,260.463196,13.268628,1.106753,-577.763062,0.110771,0.000000
106.610008,58.533226,-577.763062,0.010309,0.004357,0.110675,260.368805,13.263819,1.106753,-577.763062,0.110771,0.000000
106.870003,58.519821,-577.807556,0.010309,0.004357,0.110675,260.309174,13.260781,1.106753,-577.807556,0.110771,0.000000
107.130005,58.500458,-577.852051,0.010309,0.004357,0.110675,260.223022,13.256393,1.106753,-577.852051,0.110771,0.000000
107.390007,58.483704,-577.763062,0.010305,0.004357,0.110675,260.148499,13.252597,1.106753,-577.763062,0.110771,0.000000
107.650002,58.471039,-577.852051,0.010305,0.004357,0.110675,260.092163,13.249727,1.106753,-577.852051,0.110771,0.000000
107.910004,58.462845,-577.807556,0.010305,0.004357,0.110675,260.055725,13.247869,1.106753,-577.807556,0.110771,0.000000
108.170006,58.450188,-577.763062,0.010300,0.004357,0.110675,259.999420,13.245002,1.106753,-577.763062,0.110771,0.000000
108.430008,58.430824,-577.852051,0.010305,0.004357,0.110675,259.913300,13.240614,1.106753,-577.852051,0.110771,0.000000
108.690002,58.420029,-577.807556,0.010300,0.004357,0.110675,259.865265,13.238168,1.106753,-577.807556,0.110771,0.000000
108.700005,58.413696,-577.896545,0.010296,0.004357,0.110675,259.837097,13.236733,1.106753,-577.896545,0.110771,0.000000