File: Data/compression 7/AutoHeating-12-7-1-4-240320_03202024_203910.csv
Time (sec),S:Load (lbs),S:HL1 (DIM),S:LVDT (in),S:Position (in),Ch:Position (mm),Ch:Load (N),Ch:Stress (MPa),Ch:Strain (mm/mm),Ch:HL1 (DIM),Set Point (),Cycles ()
0.010000,-0.003349,-588.394043,-0.000004,-0.000000,-0.000000,-0.014898,-0.000759,-0.000000,-588.394043,0.000156,0.000000
0.290000,0.002235,-588.438477,0.000017,-0.000000,-0.000000,0.009944,0.000507,-0.000000,-588.438477,0.000156,0.000000
0.570000,0.010422,-588.349548,0.000009,0.000132,0.003356,0.046358,0.002362,0.033564,-588.349548,0.004059,0.000000
0.850000,-0.042450,-588.394043,0.000155,0.000303,0.007701,-0.188827,-0.009619,0.077011,-588.394043,0.008725,0.000000
1.130000,0.007446,-588.438477,0.000328,0.000480,0.012193,0.033123,0.001687,0.121934,-588.438477,0.013390,0.000000
1.410000,-0.047661,-588.482971,0.000509,0.000673,0.017093,-0.212006,-0.010800,0.170933,-588.482971,0.018056,0.000000
1.690000,0.021973,-588.349548,0.000694,0.000854,0.021689,0.097739,0.004979,0.216893,-588.349548,0.022721,0.000000
1.970000,0.015640,-588.349548,0.000897,0.001036,0.026312,0.069571,0.003544,0.263118,-588.349548,0.027387,0.000000
2.250000,-0.007446,-588.394043,0.001086,0.001222,0.031029,-0.033123,-0.001687,0.310293,-588.394043,0.032053,0.000000
2.530000,0.008194,-588.482971,0.001268,0.001406,0.035704,0.036449,0.001857,0.357037,-588.482971,0.036718,0.000000
2.810000,-0.017502,-588.438477,0.001436,0.001589,0.040352,-0.077852,-0.003966,0.403523,-588.438477,0.041384,0.000000
3.090000,-0.020485,-588.482971,0.001630,0.001767,0.044870,-0.091121,-0.004642,0.448703,-588.482971,0.046050,0.000000
3.370000,-0.067024,-588.482971,0.001819,0.001956,0.049684,-0.298139,-0.015188,0.496836,-588.482971,0.050715,0.000000
3.650000,0.043198,-588.482971,0.001983,0.002132,0.054141,0.192153,0.009789,0.541410,-588.482971,0.055381,0.000000
3.930000,-0.012665,-588.438477,0.002186,0.002324,0.059041,-0.056336,-0.002870,0.590410,-588.438477,0.060030,0.000000
4.210000,0.010796,-588.482971,0.002371,0.002502,0.063559,0.048021,0.002446,0.635590,-588.482971,0.064695,0.000000
4.490000,0.022713,-588.571960,0.002552,0.002691,0.068355,0.101031,0.005147,0.683548,-588.571960,0.069361,0.000000
4.770000,0.002975,-588.438477,0.002733,0.002872,0.072951,0.013236,0.000674,0.729512,-588.438477,0.074026,0.000000
5.050000,0.001862,-588.527466,0.002932,0.003062,0.077764,0.008281,0.000422,0.777645,-588.527466,0.078692,0.000000
5.330000,-0.018623,-588.482971,0.003130,0.003238,0.082256,-0.082841,-0.004220,0.822564,-588.482971,0.083358,0.000000
5.610000,-0.010803,-588.571960,0.003290,0.003421,0.086896,-0.048055,-0.002448,0.868963,-588.571960,0.088023,0.000000
5.890000,-0.015640,-588.616455,0.003488,0.003609,0.091675,-0.069571,-0.003544,0.916747,-588.616455,0.092689,0.000000
6.170000,0.049896,-588.527466,0.003665,0.003787,0.096193,0.221950,0.011307,0.961927,-588.527466,0.097355,0.000000
6.450000,-0.000374,-588.482971,0.003863,0.003974,0.100945,-0.001663,-0.000085,1.009450,-588.482971,0.102021,0.000000
6.730000,0.013031,-588.527466,0.004057,0.004155,0.105533,0.057965,0.002953,1.055327,-588.527466,0.106686,0.000000
7.010000,-0.004471,-588.660889,0.004234,0.004345,0.110372,-0.019887,-0.001013,1.103721,-588.660889,0.111352,0.000000
7.290000,-0.007446,-588.616455,0.004406,0.004527,0.114977,-0.033123,-0.001687,1.149768,-588.616455,0.116018,0.000000
7.570000,-0.011543,-588.616455,0.004626,0.004715,0.119755,-0.051347,-0.002616,1.197552,-588.616455,0.120683,0.000000
7.850000,-0.011543,-588.527466,0.004799,0.004893,0.124274,-0.051347,-0.002616,1.242736,-588.527466,0.125349,0.000000
8.130000,0.028671,-588.571960,0.004988,0.005075,0.128896,0.127536,0.006497,1.288957,-588.571960,0.130015,0.000000
8.410001,0.001488,-588.660889,0.005165,0.005259,0.133587,0.006618,0.000337,1.335875,-588.660889,0.134680,0.000000
8.690001,0.024948,-588.616455,0.005355,0.005435,0.138045,0.110975,0.005653,1.380450,-588.616455,0.139346,0.000000
8.970000,-0.021225,-588.616455,0.005536,0.005629,0.142980,-0.094413,-0.004810,1.429797,-588.616455,0.144011,0.000000
9.250000,0.013405,-588.571960,0.005730,0.005807,0.147489,0.059628,0.003038,1.474890,-588.571960,0.148660,0.000000
9.530001,-0.009682,-588.571960,0.005928,0.006000,0.152398,-0.043066,-0.002194,1.523977,-588.571960,0.153326,0.000000
9.810000,-0.011169,-588.660889,0.006105,0.006178,0.156916,-0.049684,-0.002531,1.569161,-588.660889,0.157991,0.000000
10.090000,0.033516,-588.660889,0.006291,0.006367,0.161720,0.149086,0.007595,1.617202,-588.660889,0.162657,0.000000
10.370001,0.002235,-588.660889,0.006472,0.006545,0.166239,0.009944,0.000507,1.662386,-588.660889,0.167323,0.000000
10.650001,0.027184,-588.660889,0.006644,0.006725,0.170818,0.120918,0.006160,1.708176,-588.660889,0.171988,0.000000
10.930000,0.005585,-588.571960,0.006860,0.006915,0.175639,0.024842,0.001266,1.756392,-588.571960,0.176654,0.000000
11.210001,0.021599,-588.705383,0.007032,0.007089,0.180071,0.096076,0.004894,1.800709,-588.705383,0.181320,0.000000
11.490001,-0.044312,-588.660889,0.007200,0.007281,0.184945,-0.197107,-0.010041,1.849447,-588.660889,0.185985,0.000000
11.770000,0.007446,-588.749878,0.007394,0.007462,0.189532,0.033123,0.001687,1.895324,-588.749878,0.190651,0.000000
12.050000,-0.006706,-588.705383,0.007593,0.007654,0.194406,-0.029831,-0.001520,1.944062,-588.705383,0.195317,0.000000
12.330001,0.014893,-588.749878,0.007778,0.007834,0.198994,0.066245,0.003375,1.989939,-588.749878,0.199982,0.000000
12.610001,0.030159,-588.749878,0.007955,0.008017,0.203642,0.134154,0.006834,2.036421,-588.749878,0.204648,0.000000
12.890000,0.037979,-588.705383,0.008153,0.008197,0.208212,0.168940,0.008606,2.082124,-588.705383,0.209314,0.000000
13.170001,0.398064,-588.794373,0.008317,0.008375,0.212713,1.770676,0.090203,2.127134,-588.794373,0.213979,0.000000
13.450001,0.556320,-588.794373,0.008377,-0.000000,-0.000000,2.474636,0.126064,-0.000000,-588.794373,0.000234,0.000000
13.730000,0.522812,-588.705383,0.008382,-0.000000,-0.000000,2.325583,0.118471,-0.000000,-588.705383,0.000234,0.000000
14.010000,0.602127,-588.749878,0.008395,0.000000,0.000008,2.678395,0.136444,0.000083,-588.749878,0.000633,0.000000
14.290001,0.580528,-588.838806,0.008386,0.000000,0.000008,2.582319,0.131550,0.000083,-588.838806,0.001093,0.000000
14.570001,0.847519,-588.749878,0.008395,0.000032,0.000806,3.769953,0.192051,0.008062,-588.749878,0.001561,0.000000
14.850000,0.946945,-588.749878,0.008407,0.000044,0.001110,4.212223,0.214581,0.011097,-588.749878,0.002029,0.000000
15.130001,1.037804,-588.749878,0.008433,0.000056,0.001431,4.616381,0.235170,0.014307,-588.749878,0.002497,0.000000
15.410001,1.283195,-588.794373,0.008451,0.000090,0.002281,5.707939,0.290776,0.022808,-588.794373,0.002966,0.000000
15.690001,1.327507,-588.883301,0.008468,0.000102,0.002584,5.905046,0.300817,0.025843,-588.883301,0.003425,0.000000
15.970001,1.451881,-588.794373,0.008476,0.000119,0.003018,6.458291,0.329001,0.030177,-588.794373,0.003894,0.000000
16.250000,1.564705,-588.838806,0.008502,0.000135,0.003417,6.960155,0.354567,0.034166,-588.838806,0.004362,0.000000
16.530001,1.804886,-588.794373,0.008515,0.000156,0.003963,8.028533,0.408993,0.039632,-588.794373,0.004830,0.000000
16.810001,1.894630,-588.794373,0.008532,0.000171,0.004353,8.427737,0.429329,0.043534,-588.794373,0.005298,0.000000
17.090000,2.096458,-588.749878,0.008532,0.000188,0.004787,9.325513,0.475064,0.047868,-588.749878,0.005758,0.000000
17.370001,2.300888,-588.838806,0.008563,0.000212,0.005385,10.234861,0.521389,0.053851,-588.838806,0.006227,0.000000
17.650002,2.424515,-588.838806,0.008576,0.000229,0.005810,10.784781,0.549403,0.058102,-588.838806,0.006695,0.000000
17.930000,2.544792,-588.794373,0.008597,0.000246,0.006244,11.319801,0.576658,0.062439,-588.794373,0.007163,0.000000
18.210001,2.689644,-588.838806,0.008601,0.000265,0.006738,11.964133,0.609482,0.067382,-588.838806,0.007631,0.000000
18.490002,3.008766,-588.838806,0.008632,0.000285,0.007233,13.383660,0.681796,0.072326,-588.838806,0.008100,0.000000
18.770000,3.124207,-588.838806,0.008645,0.000301,0.007649,13.897164,0.707955,0.076489,-588.838806,0.008559,0.000000
19.050001,3.125694,-588.883301,0.008658,0.000312,0.007935,13.903783,0.708292,0.079350,-588.883301,0.009028,0.000000
19.330002,3.612755,-588.838806,0.008688,0.000343,0.008715,16.070335,0.818662,0.087155,-588.838806,0.009496,0.000000
19.610001,3.671593,-588.838806,0.008705,0.000361,0.009175,16.332060,0.831995,0.091750,-588.838806,0.009964,0.000000
19.890001,3.769150,-588.927795,0.008718,0.000377,0.009565,16.766016,0.854102,0.095652,-588.927795,0.010433,0.000000
20.170000,3.946030,-588.927795,0.008727,0.000392,0.009947,17.552816,0.894183,0.099471,-588.927795,0.010892,0.000000
20.450001,4.199989,-588.883301,0.008744,0.000411,0.010441,18.682486,0.951731,0.104414,-588.883301,0.011360,0.000000
20.730001,4.349312,-588.883301,0.008770,0.000427,0.010849,19.346704,0.985568,0.108486,-588.883301,0.011829,0.000000
21.010000,4.532890,-588.883301,0.008791,0.000445,0.011300,20.163303,1.027168,0.112998,-588.883301,0.012297,0.000000
21.290001,4.887016,-588.883301,0.008795,0.000473,0.012002,21.738535,1.107414,0.120023,-588.883301,0.012765,0.000000
21.570002,4.929840,-588.927795,0.008830,0.000488,0.012401,21.929024,1.117118,0.124012,-588.927795,0.013234,0.000000
21.850000,5.017349,-588.927795,0.008830,0.000506,0.012843,22.318285,1.136948,0.128433,-588.927795,0.013693,0.000000
22.130001,5.231461,-588.883301,0.008852,0.000522,0.013251,23.270699,1.185466,0.132509,-588.883301,0.014162,0.000000
22.410002,5.482811,-588.883301,0.008873,0.000541,0.013745,24.388762,1.242423,0.137452,-588.883301,0.014630,0.000000
22.690001,5.573669,-588.972290,0.008877,0.000557,0.014144,24.792919,1.263012,0.141442,-588.972290,0.015098,0.000000
22.970001,5.629524,-588.927795,0.008890,0.000568,0.014439,25.041374,1.275668,0.144390,-588.927795,0.015567,0.000000
23.250002,6.166862,-588.972290,0.008916,0.000601,0.015263,27.431574,1.397431,0.152630,-588.972290,0.016026,0.000000
23.530001,6.239098,-588.927795,0.008942,0.000620,0.015757,27.752892,1.413800,0.157573,-588.927795,0.016495,0.000000
23.810001,6.310226,-588.972290,0.008968,0.000638,0.016217,28.069288,1.429918,0.162168,-588.972290,0.016963,0.000000
24.090002,6.389542,-588.972290,0.008981,0.000652,0.016573,28.422100,1.447891,0.165725,-588.972290,0.017431,0.000000
24.370001,6.580566,-588.972290,0.008994,0.000669,0.016998,29.271822,1.491178,0.169976,-588.972290,0.017900,0.000000
24.650002,6.719833,-588.972290,0.008994,0.000685,0.017397,29.891312,1.522736,0.173965,-588.972290,0.018359,0.000000
24.930000,6.843834,-588.927795,0.009020,0.000698,0.017726,30.442894,1.550835,0.177258,-588.927795,0.018827,0.000000
25.210001,7.348770,-588.972290,0.009037,0.000729,0.018506,32.688961,1.665255,0.185062,-588.972290,0.019296,0.000000
25.490002,7.396805,-588.972290,0.009063,0.000747,0.018984,32.902630,1.676140,0.189835,-588.972290,0.019764,0.000000
25.770000,7.369995,-588.972290,0.009071,0.000764,0.019399,32.783375,1.670065,0.193995,-588.972290,0.020232,0.000000
26.050001,7.486176,-589.061218,0.009067,0.000780,0.019807,33.300171,1.696392,0.198071,-589.061218,0.020700,0.000000
26.330002,7.823174,-588.972290,0.009097,0.000802,0.020362,34.799213,1.772756,0.203624,-588.972290,0.021160,0.000000
26.610001,7.879028,-589.016724,0.009123,0.000816,0.020735,35.047668,1.785413,0.207352,-589.016724,0.021628,0.000000
26.890001,8.003029,-589.016724,0.009136,0.000833,0.021160,35.599251,1.813512,0.211602,-589.016724,0.022097,0.000000
27.170002,8.375771,-589.016724,0.009140,0.000857,0.021776,37.257290,1.897977,0.217760,-589.016724,0.022565,0.000000
27.450001,8.415245,-589.061218,0.009153,0.000875,0.022227,37.432880,1.906922,0.222268,-589.061218,0.023033,0.000000
27.730001,8.464767,-589.105713,0.009166,0.000893,0.022678,37.653168,1.918144,0.226780,-589.105713,0.023493,0.000000
28.010002,8.532913,-589.016724,0.009192,0.000908,0.023059,37.956295,1.933586,0.230595,-589.016724,0.023961,0.000000
28.290001,8.822617,-589.016724,0.009218,0.000927,0.023554,39.244957,1.999233,0.235538,-589.016724,0.024430,0.000000
28.570002,8.882202,-589.105713,0.009205,0.000944,0.023978,39.510010,2.012736,0.239784,-589.105713,0.024898,0.000000
28.850002,9.082161,-589.016724,0.009235,0.000963,0.024473,40.399471,2.058047,0.244728,-589.016724,0.025366,0.000000
29.130001,9.387138,-589.061218,0.009257,0.000986,0.025045,41.756077,2.127156,0.250454,-589.061218,0.025835,0.000000
29.410002,9.359581,-589.105713,0.009265,0.001003,0.025479,41.633495,2.120911,0.254788,-589.105713,0.026294,0.000000
29.690001,9.374100,-589.105713,0.009287,0.001016,0.025817,41.698078,2.124201,0.258171,-589.105713,0.026762,0.000000
29.970001,9.682053,-589.105713,0.009304,0.001040,0.026416,43.067921,2.193985,0.264155,-589.105713,0.027231,0.000000
30.250002,9.763977,-589.150208,0.009313,0.001058,0.026866,43.432339,2.212549,0.268663,-589.150208,0.027699,0.000000
30.530001,9.625084,-589.105713,0.009334,0.001068,0.027118,42.814510,2.181075,0.271180,-589.105713,0.028167,0.000000
30.810001,9.693230,-589.150208,0.009343,0.001081,0.027465,43.117638,2.196517,0.274647,-589.150208,0.028627,0.000000
31.090002,10.379883,-589.150208,0.009365,0.001114,0.028306,46.172024,2.352115,0.283061,-589.150208,0.029095,0.000000
31.370001,10.247314,-589.194702,0.009390,0.001128,0.028653,45.582333,2.322075,0.286528,-589.194702,0.029563,0.000000
31.650002,10.324394,-589.105713,0.009399,0.001150,0.029208,45.925198,2.339541,0.292080,-589.105713,0.030032,0.000000
31.930002,10.567558,-589.150208,0.009408,0.001166,0.029624,47.006847,2.394643,0.296244,-589.150208,0.030500,0.000000
32.210003,10.594742,-589.105713,0.009421,0.001183,0.030040,47.127766,2.400803,0.300403,-589.105713,0.030960,0.000000
32.490002,10.522499,-589.105713,0.009451,0.001196,0.030370,46.806412,2.384432,0.303700,-589.105713,0.031428,0.000000
32.770000,10.606659,-589.239136,0.009438,0.001210,0.030734,47.180775,2.403503,0.307345,-589.239136,0.031896,0.000000
33.050003,11.228516,-589.150208,0.009459,0.001239,0.031480,49.946934,2.544418,0.314801,-589.150208,0.032365,0.000000
33.330002,11.280647,-589.194702,0.009468,0.001259,0.031983,50.178825,2.556231,0.319831,-589.194702,0.032833,0.000000
33.610001,11.222931,-589.194702,0.009494,0.001276,0.032417,49.922089,2.543153,0.324169,-589.194702,0.033301,0.000000
33.890003,11.455666,-589.105713,0.009511,0.001297,0.032946,50.957344,2.595891,0.329456,-589.105713,0.033761,0.000000
34.170002,11.490669,-589.194702,0.009528,0.001314,0.033379,51.113049,2.603823,0.333794,-589.194702,0.034229,0.000000
34.450001,11.532745,-589.283630,0.009524,0.001330,0.033770,51.300213,2.613358,0.337696,-589.283630,0.034698,0.000000
34.730003,11.390869,-589.194702,0.009541,0.001344,0.034142,50.669117,2.581208,0.341424,-589.194702,0.035166,0.000000
35.010002,12.025024,-589.239136,0.009572,0.001370,0.034810,53.489979,2.724910,0.348104,-589.239136,0.035634,0.000000
35.290001,11.873093,-589.239136,0.009593,0.001386,0.035201,52.814156,2.690481,0.352007,-589.239136,0.036094,0.000000
35.570004,12.003799,-589.239136,0.009593,0.001404,0.035669,53.395565,2.720100,0.356688,-589.239136,0.036562,0.000000
35.850002,12.195198,-589.283630,0.009615,0.001425,0.036198,54.246952,2.763472,0.361980,-589.283630,0.037030,0.000000
36.130001,12.042526,-589.150208,0.009628,0.001437,0.036493,53.567833,2.728875,0.364928,-589.150208,0.037498,0.000000
36.410000,12.175835,-589.239136,0.009623,0.001455,0.036961,54.160816,2.759084,0.369610,-589.239136,0.037967,0.000000
36.690002,12.779076,-589.194702,0.009649,0.001482,0.037655,56.844166,2.895780,0.376548,-589.194702,0.038435,0.000000
36.970001,12.711304,-589.283630,0.009671,0.001499,0.038062,56.542702,2.880423,0.380624,-589.283630,0.038895,0.000000
37.250000,12.635338,-589.239136,0.009675,0.001515,0.038487,56.204788,2.863209,0.384875,-589.239136,0.039363,0.000000
37.530003,12.587677,-589.283630,0.009684,0.001529,0.038843,55.992783,2.852408,0.388429,-589.283630,0.039831,0.000000
37.810001,12.846107,-589.239136,0.009710,0.001551,0.039389,57.142342,2.910969,0.393890,-589.239136,0.040300,0.000000
38.090000,12.888924,-589.239136,0.009731,0.001566,0.039788,57.332794,2.920672,0.397880,-589.239136,0.040768,0.000000
38.370003,13.141769,-589.283630,0.009731,0.001587,0.040300,58.457508,2.977968,0.402997,-589.283630,0.041228,0.000000
38.650002,13.453072,-589.283630,0.009766,0.001609,0.040872,59.842251,3.048510,0.408723,-589.283630,0.041696,0.000000
38.930000,13.464989,-589.283630,0.009757,0.001627,0.041332,59.895260,3.051210,0.413318,-589.283630,0.042164,0.000000
39.210003,13.406898,-589.283630,0.009787,0.001644,0.041748,59.636864,3.038047,0.417481,-589.283630,0.042633,0.000000
39.490002,13.303375,-589.283630,0.009787,0.001658,0.042121,59.176369,3.014588,0.421210,-589.283630,0.043101,0.000000
39.770000,13.672768,-589.328125,0.009804,0.001682,0.042728,60.819508,3.098293,0.427281,-589.328125,0.043561,0.000000
40.050003,13.714104,-589.328125,0.009822,0.001697,0.043110,61.003380,3.107660,0.431096,-589.328125,0.044029,0.000000
40.330002,13.438545,-589.283630,0.009813,0.001709,0.043404,59.777634,3.045218,0.434044,-589.283630,0.044497,0.000000
40.610001,14.345650,-589.328125,0.009865,0.001740,0.044202,63.812637,3.250771,0.442023,-589.328125,0.044965,0.000000
40.890003,14.145683,-589.372620,0.009860,0.001756,0.044592,62.923141,3.205458,0.445925,-589.372620,0.045434,0.000000
41.170002,14.120361,-589.372620,0.009873,0.001773,0.045026,62.810505,3.199720,0.450262,-589.372620,0.045902,0.000000
41.450001,14.038811,-589.372620,0.009886,0.001787,0.045399,62.447750,3.181240,0.453991,-589.372620,0.046362,0.000000
41.730003,14.356071,-589.328125,0.009899,0.001807,0.045902,63.858994,3.253132,0.459021,-589.328125,0.046830,0.000000
42.010002,14.475235,-589.372620,0.009912,0.001825,0.046362,64.389061,3.280135,0.463616,-589.372620,0.047298,0.000000
42.290001,14.522522,-589.417053,0.009921,0.001842,0.046778,64.599403,3.290851,0.467779,-589.417053,0.047767,0.000000
42.570004,14.935486,-589.372620,0.009938,0.001868,0.047454,66.436356,3.384429,0.474543,-589.372620,0.048235,0.000000
42.850002,14.874046,-589.461548,0.009947,0.001886,0.047905,66.163063,3.370507,0.479054,-589.461548,0.048695,0.000000
43.130001,14.715790,-589.372620,0.009968,0.001900,0.048270,65.459099,3.334646,0.482695,-589.372620,0.049163,0.000000
43.410004,14.693817,-589.372620,0.009973,0.001918,0.048721,65.361366,3.329667,0.487207,-589.372620,0.049631,0.000000
43.690002,15.025230,-589.372620,0.009985,0.001938,0.049224,66.835564,3.404766,0.492237,-589.372620,0.050100,0.000000
43.970001,14.949638,-589.417053,0.009998,0.001954,0.049631,66.499313,3.387636,0.496313,-589.417053,0.050568,0.000000
44.250004,14.895271,-589.461548,0.010016,0.001965,0.049917,66.257477,3.375317,0.499175,-589.461548,0.051036,0.000000
44.530003,15.826202,-589.461548,0.010033,0.001998,0.050758,70.398460,3.586269,0.507585,-589.461548,0.051496,0.000000
44.810001,15.774071,-589.417053,0.010042,0.002017,0.051244,70.166573,3.574455,0.512441,-589.417053,0.051964,0.000000
45.090004,15.562561,-589.372620,0.010059,0.002034,0.051669,69.225731,3.526527,0.516691,-589.372620,0.052432,0.000000
45.370003,15.513039,-589.461548,0.010080,0.002049,0.052042,69.005440,3.515305,0.520419,-589.461548,0.052901,0.000000
45.650002,15.569267,-589.461548,0.010080,0.002065,0.052450,69.255562,3.528047,0.524496,-589.461548,0.053369,0.000000
45.930000,15.488091,-589.461548,0.010085,0.002081,0.052857,68.894470,3.509652,0.528572,-589.461548,0.053828,0.000000
46.210003,15.642624,-589.461548,0.010098,0.002097,0.053256,69.581863,3.544669,0.532561,-589.461548,0.054297,0.000000
46.490002,16.410828,-589.461548,0.010123,0.002125,0.053985,72.999008,3.718747,0.539847,-589.461548,0.054765,0.000000
46.770000,16.272675,-589.506042,0.010123,0.002142,0.054418,72.384468,3.687441,0.544181,-589.506042,0.055233,0.000000
47.050003,16.051857,-589.506042,0.010149,0.002156,0.054756,71.402229,3.637403,0.547565,-589.506042,0.055702,0.000000
47.330002,16.055580,-589.550537,0.010141,0.002172,0.055173,71.418785,3.638247,0.551728,-589.550537,0.056170,0.000000
47.610001,16.505783,-589.506042,0.010149,0.002197,0.055814,73.421387,3.740264,0.558143,-589.506042,0.056630,0.000000
47.890003,16.464821,-589.506042,0.010184,0.002214,0.056239,73.239182,3.730982,0.562394,-589.506042,0.057098,0.000000
48.170002,16.388107,-589.506042,0.010184,0.002230,0.056630,72.897942,3.713598,0.566296,-589.506042,0.057566,0.000000
48.450001,16.861397,-589.506042,0.010201,0.002253,0.057228,75.003242,3.820847,0.572280,-589.506042,0.058035,0.000000
48.730003,16.815224,-589.639465,0.010210,0.002272,0.057696,74.797852,3.810384,0.576962,-589.639465,0.058503,0.000000
49.010002,16.554558,-589.506042,0.010223,0.002284,0.058017,73.638351,3.751316,0.580171,-589.506042,0.058963,0.000000
49.290001,16.692337,-589.550537,0.010240,0.002302,0.058477,74.251221,3.782538,0.584770,-589.550537,0.059431,0.000000
49.570004,16.964546,-589.550537,0.010257,0.002325,0.059067,75.462067,3.844221,0.590667,-589.550537,0.059899,0.000000
49.850002,16.773514,-589.595032,0.010266,0.002338,0.059396,74.612312,3.800933,0.593960,-589.595032,0.060368,0.000000
50.130001,16.678558,-589.639465,0.010261,0.002354,0.059786,74.189934,3.779415,0.597862,-589.639465,0.060836,0.000000
50.410004,17.358513,-589.550537,0.010270,0.002381,0.060480,77.214523,3.933495,0.604800,-589.550537,0.061295,0.000000
50.690002,17.150360,-589.595032,0.010296,0.002396,0.060853,76.288612,3.886327,0.608532,-589.595032,0.061764,0.000000
50.970001,17.209190,-589.595032,0.010309,0.002415,0.061330,76.550301,3.899658,0.613301,-589.595032,0.062232,0.000000
51.250004,17.464638,-589.639465,0.010322,0.002436,0.061876,77.686592,3.957544,0.618762,-589.639465,0.062700,0.000000
51.530003,17.437454,-589.595032,0.010330,0.002454,0.062327,77.565674,3.951384,0.623274,-589.595032,0.063168,0.000000
51.810001,17.067322,-589.639465,0.010317,0.002466,0.062648,75.919235,3.867510,0.626483,-589.639465,0.063637,0.000000
52.090004,16.944435,-589.550537,0.010356,0.002479,0.062978,75.372612,3.839664,0.629776,-589.550537,0.064096,0.000000
52.370003,17.940163,-589.639465,0.010352,0.002512,0.063802,79.801826,4.065299,0.638016,-589.639465,0.064565,0.000000
52.650002,17.544701,-589.683960,0.010369,0.002526,0.064157,78.042725,3.975686,0.641570,-589.683960,0.065033,0.000000
52.930004,17.376389,-589.683960,0.010382,0.002542,0.064565,77.294037,3.937546,0.645646,-589.683960,0.065501,0.000000
53.210003,17.533897,-589.683960,0.010378,0.002564,0.065129,77.994675,3.973238,0.651286,-589.683960,0.065970,0.000000
53.490002,17.329094,-589.639465,0.010399,0.002580,0.065528,77.083656,3.926829,0.655275,-589.639465,0.066429,0.000000
53.770004,17.215523,-589.683960,0.010412,0.002593,0.065865,76.578468,3.901093,0.658655,-589.683960,0.066898,0.000000
54.050003,17.119820,-589.639465,0.010417,0.002608,0.066239,76.152763,3.879407,0.662387,-589.639465,0.067366,0.000000
54.330002,17.850792,-589.728455,0.010430,0.002635,0.066941,79.404289,4.045047,0.669408,-589.728455,0.067834,0.000000
54.610004,17.869408,-589.683960,0.010430,0.002655,0.067427,79.487099,4.049265,0.674268,-589.683960,0.068303,0.000000
54.890003,17.584175,-589.772949,0.010451,0.002670,0.067826,78.218315,3.984631,0.678257,-589.772949,0.068771,0.000000
55.170002,17.826584,-589.728455,0.010460,0.002694,0.068424,79.296608,4.039562,0.684241,-589.728455,0.069230,0.000000
55.450001,17.614334,-589.728455,0.010468,0.002710,0.068823,78.352470,3.991465,0.688230,-589.728455,0.069699,0.000000
55.730003,17.442673,-589.772949,0.010490,0.002727,0.069256,77.588882,3.952566,0.692564,-589.772949,0.070167,0.000000
56.010002,17.082954,-589.817383,0.010490,0.002736,0.069482,75.988777,3.871053,0.694820,-589.817383,0.070635,0.000000
56.290001,17.990433,-589.728455,0.010511,0.002767,0.070271,80.025444,4.076690,0.702711,-589.728455,0.071104,0.000000
56.570004,17.717484,-589.728455,0.010520,0.002782,0.070670,78.811302,4.014839,0.706700,-589.728455,0.071563,0.000000
56.850002,17.659019,-589.772949,0.010533,0.002801,0.071156,78.551239,4.001591,0.711556,-589.772949,0.072031,0.000000
57.130001,17.664604,-589.861877,0.010546,0.002821,0.071650,78.576080,4.002856,0.716500,-589.861877,0.072500,0.000000
57.410004,17.385696,-589.817383,0.010555,0.002834,0.071988,77.335442,3.939655,0.719883,-589.817383,0.072968,0.000000
57.690002,17.149612,-589.772949,0.010546,0.002851,0.072405,76.285286,3.886158,0.724047,-589.772949,0.073436,0.000000
57.970001,17.992661,-589.772949,0.010572,0.002879,0.073115,80.035355,4.077195,0.731155,-589.772949,0.073896,0.000000
58.250004,17.898827,-589.861877,0.010602,0.002897,0.073584,79.617958,4.055932,0.735840,-589.861877,0.074364,0.000000
58.530003,17.558853,-589.817383,0.010598,0.002913,0.073983,78.105682,3.978893,0.739830,-589.817383,0.074833,0.000000
58.810001,17.157433,-589.861877,0.010606,0.002926,0.074321,76.320068,3.887930,0.743210,-589.861877,0.075301,0.000000
59.090004,17.364098,-589.728455,0.010615,0.002946,0.074833,77.239365,3.934761,0.748327,-589.728455,0.075769,0.000000
59.370003,17.311966,-589.772949,0.010632,0.002962,0.075232,77.007469,3.922947,0.752316,-589.772949,0.076238,0.000000
59.650002,17.192062,-589.817383,0.010645,0.002980,0.075691,76.474113,3.895777,0.756915,-589.817383,0.076697,0.000000
59.930004,17.743172,-589.817383,0.010662,0.003004,0.076289,78.925568,4.020660,0.762895,-589.817383,0.077166,0.000000
60.210003,18.026924,-589.906372,0.010658,0.003025,0.076845,80.187767,4.084960,0.768447,-589.906372,0.077634,0.000000
60.490002,17.651573,-589.861877,0.010675,0.003042,0.077270,78.518120,3.999904,0.772698,-589.861877,0.078102,0.000000
60.770004,17.403946,-589.817383,0.010675,0.003056,0.077634,77.416618,3.943791,0.776339,-589.817383,0.078571,0.000000
61.050003,17.534645,-589.861877,0.010684,0.003077,0.078146,77.997993,3.973407,0.781456,-589.861877,0.079030,0.000000
61.330002,17.275101,-589.861877,0.010705,0.003089,0.078458,76.843483,3.914594,0.784578,-589.861877,0.079498,0.000000
61.610004,17.229301,-589.906372,0.010718,0.003106,0.078891,76.639763,3.904216,0.788912,-589.906372,0.079967,0.000000
61.890003,18.524040,-589.861877,0.010723,0.003138,0.079698,82.399048,4.197608,0.796978,-589.861877,0.080435,0.000000
62.170002,18.128204,-589.861877,0.010736,0.003152,0.080071,80.638283,4.107910,0.800706,-589.861877,0.080903,0.000000
62.450005,17.882812,-589.906372,0.010757,0.003170,0.080513,79.546722,4.052303,0.805130,-589.906372,0.081371,0.000000
62.730003,17.702957,-589.906372,0.010766,0.003185,0.080895,78.746689,4.011548,0.808946,-589.906372,0.081831,0.000000
63.010002,17.859352,-589.950867,0.010774,0.003204,0.081389,79.442368,4.046987,0.813889,-589.950867,0.082300,0.000000
63.290005,18.081291,-589.906372,0.010774,0.003223,0.081866,80.429604,4.097279,0.818658,-589.906372,0.082768,0.000000
63.570004,18.018356,-589.861877,0.010792,0.003238,0.082239,80.149651,4.083018,0.822390,-589.861877,0.083236,0.000000
63.850002,18.640221,-589.906372,0.010805,0.003262,0.082854,82.915840,4.223934,0.828544,-589.906372,0.083704,0.000000
64.130005,18.614525,-589.950867,0.010826,0.003281,0.083332,82.801544,4.218112,0.833317,-589.950867,0.084164,0.000000
64.410004,18.334129,-589.906372,0.010826,0.003297,0.083739,81.554283,4.154573,0.837393,-589.906372,0.084633,0.000000
64.690002,18.295776,-589.995361,0.010822,0.003312,0.084121,81.383675,4.145882,0.841208,-589.995361,0.085101,0.000000
64.970001,18.153526,-589.950867,0.010861,0.003330,0.084589,80.750916,4.113648,0.845890,-589.950867,0.085569,0.000000
65.250000,18.643196,-589.950867,0.010861,0.003347,0.085014,82.929077,4.224608,0.850140,-589.950867,0.086037,0.000000
65.530006,18.701660,-589.995361,0.010887,0.003364,0.085439,83.189140,4.237856,0.854387,-589.995361,0.086497,0.000000
65.810005,19.732758,-590.039795,0.010882,0.003393,0.086193,87.775688,4.471507,0.861934,-590.039795,0.086965,0.000000
66.090004,19.777443,-589.906372,0.010895,0.003412,0.086670,87.974457,4.481633,0.866703,-589.906372,0.087433,0.000000
66.370003,19.447525,-589.995361,0.010908,0.003426,0.087026,86.506912,4.406872,0.870261,-589.995361,0.087902,0.000000
66.650002,19.563332,-589.906372,0.010925,0.003446,0.087520,87.022049,4.433114,0.875204,-589.906372,0.088370,0.000000
66.930000,19.510452,-589.995361,0.010934,0.003460,0.087885,86.786827,4.421132,0.878845,-589.995361,0.088838,0.000000
67.210007,19.816917,-590.039795,0.010934,0.003477,0.088327,88.150055,4.490578,0.883266,-590.039795,0.089298,0.000000
67.490005,19.940544,-589.995361,0.010960,0.003494,0.088752,88.699974,4.518592,0.887516,-589.995361,0.089766,0.000000
67.770004,20.935150,-589.950867,0.010977,0.003523,0.089472,93.124199,4.743973,0.894715,-589.950867,0.090235,0.000000
68.050003,21.006645,-589.995361,0.010986,0.003538,0.089862,93.442223,4.760174,0.898617,-589.995361,0.090703,0.000000
68.330002,20.995102,-589.995361,0.011003,0.003553,0.090252,93.390877,4.757558,0.902520,-589.995361,0.091171,0.000000
68.610001,21.156715,-590.039795,0.010990,0.003571,0.090694,94.109772,4.794180,0.906944,-590.039795,0.091631,0.000000
68.890007,21.834435,-589.995361,0.011020,0.003593,0.091267,97.124413,4.947753,0.912667,-589.995361,0.092099,0.000000
69.170006,21.990082,-589.995361,0.011012,0.003611,0.091709,97.816772,4.983024,0.917088,-589.995361,0.092568,0.000000
69.450005,21.680267,-589.995361,0.011029,0.003622,0.092004,96.438644,4.912819,0.920036,-589.995361,0.093036,0.000000
69.730003,22.776161,-590.084290,0.011042,0.003648,0.092672,101.313423,5.161152,0.926716,-590.084290,0.093504,0.000000
70.010002,23.091560,-590.084290,0.011046,0.003666,0.093105,102.716393,5.232622,0.931050,-590.084290,0.093973,0.000000
70.290001,23.147041,-590.039795,0.011059,0.003682,0.093513,102.963181,5.245194,0.935126,-590.039795,0.094432,0.000000
70.570000,23.393555,-590.039795,0.011076,0.003698,0.093929,104.059731,5.301055,0.939290,-590.039795,0.094900,0.000000
70.850006,24.076859,-590.039795,0.011089,0.003720,0.094476,107.099213,5.455894,0.944755,-590.039795,0.095369,0.000000
71.130005,24.350182,-590.128784,0.011115,0.003736,0.094891,108.315018,5.517830,0.948915,-590.128784,0.095837,0.000000
71.410004,24.740051,-590.128784,0.011115,0.003754,0.095343,110.049248,5.606176,0.953426,-590.128784,0.096305,0.000000
71.690002,25.606934,-590.128784,0.011128,0.003776,0.095906,113.905327,5.802614,0.959062,-590.128784,0.096765,0.000000
71.970001,25.874672,-590.128784,0.011141,0.003792,0.096323,115.096291,5.863285,0.963225,-590.128784,0.097233,0.000000
72.250000,26.078735,-590.084290,0.011150,0.003809,0.096756,116.004005,5.909526,0.967563,-590.084290,0.097701,0.000000
72.530006,26.759804,-590.128784,0.011180,0.003830,0.097276,119.033554,6.063859,0.972763,-590.128784,0.098170,0.000000
72.810005,27.397675,-590.128784,0.011163,0.003850,0.097779,121.870941,6.208402,0.977794,-590.128784,0.098638,0.000000
73.090004,27.553329,-590.128784,0.011184,0.003863,0.098109,122.563332,6.243674,0.981090,-590.128784,0.099098,0.000000
73.370003,27.776375,-590.084290,0.011201,0.003878,0.098508,123.555489,6.294217,0.985079,-590.084290,0.099566,0.000000
73.650002,29.408112,-590.217712,0.011214,0.003906,0.099219,130.813812,6.663973,0.992191,-590.217712,0.100034,0.000000
73.930000,29.499344,-590.217712,0.011223,0.003920,0.099575,131.219635,6.684647,0.995745,-590.217712,0.100503,0.000000
74.210007,30.122322,-590.173279,0.011244,0.003939,0.100060,133.990784,6.825816,1.000601,-590.173279,0.100971,0.000000
74.490005,30.465652,-590.217712,0.011240,0.003956,0.100476,135.517990,6.903615,1.004765,-590.217712,0.101439,0.000000
74.770004,31.177628,-590.173279,0.011266,0.003974,0.100945,138.685013,7.064951,1.009450,-590.173279,0.101899,0.000000
75.050003,31.603249,-590.173279,0.011249,0.003990,0.101344,140.578278,7.161398,1.013440,-590.173279,0.102367,0.000000
75.330002,31.796509,-590.217712,0.011283,0.004004,0.101708,141.437943,7.205192,1.017081,-590.217712,0.102836,0.000000
75.610001,33.335152,-590.262207,0.011292,0.004031,0.102376,148.282166,7.553854,1.023757,-590.262207,0.103304,0.000000
75.890007,34.100006,-590.173279,0.011296,0.004049,0.102853,151.684402,7.727171,1.028526,-590.173279,0.103772,0.000000
76.170006,34.673088,-590.217712,0.011305,0.004067,0.103312,154.233597,7.857034,1.033125,-590.217712,0.104232,0.000000
76.450005,35.541832,-590.173279,0.011326,0.004089,0.103850,158.097961,8.053894,1.038499,-590.173279,0.104700,0.000000
76.730003,36.066879,-590.217712,0.011348,0.004105,0.104258,160.433487,8.172872,1.042576,-590.217712,0.105168,0.000000
77.010002,36.412071,-590.262207,0.011331,0.004119,0.104613,161.968979,8.251093,1.046134,-590.262207,0.105636,0.000000
77.290001,36.896149,-590.262207,0.011348,0.004134,0.105004,164.122269,8.360786,1.050036,-590.262207,0.106105,0.000000
77.570007,38.546509,-590.262207,0.011369,0.004162,0.105715,171.463440,8.734764,1.057148,-590.262207,0.106573,0.000000
77.850006,39.394402,-590.217712,0.011357,0.004179,0.106157,175.235046,8.926899,1.061568,-590.217712,0.107033,0.000000
78.130005,39.914978,-590.173279,0.011369,0.004196,0.106573,177.550690,9.044863,1.065732,-590.173279,0.107501,0.000000
78.410004,40.960968,-590.262207,0.011395,0.004217,0.107111,182.203491,9.281888,1.071110,-590.262207,0.107969,0.000000
78.690002,41.560486,-590.351196,0.011395,0.004232,0.107493,184.870270,9.417741,1.074925,-590.351196,0.108438,0.000000
78.970001,41.982391,-590.262207,0.011421,0.004243,0.107770,186.747009,9.513346,1.077700,-590.262207,0.108906,0.000000
79.250000,43.593643,-590.217712,0.011413,0.004271,0.108472,193.914215,9.878460,1.084724,-590.217712,0.109366,0.000000
79.530006,45.089462,-590.306702,0.011438,0.004293,0.109036,200.567947,10.217419,1.090360,-590.306702,0.109834,0.000000
79.810005,45.632385,-590.395691,0.011443,0.004309,0.109452,202.982986,10.340446,1.094524,-590.395691,0.110302,0.000000
80.090004,46.274727,-590.395691,0.011447,0.004323,0.109816,205.840271,10.486003,1.098165,-590.395691,0.110771,0.000000
80.370003,46.672043,-590.306702,0.011482,0.004336,0.110137,207.607620,10.576036,1.101374,-590.306702,0.111239,0.000000
80.650002,48.111267,-590.306702,0.011477,0.004359,0.110710,214.009598,10.902169,1.107097,-590.306702,0.111707,0.000000
80.930000,48.826591,-590.351196,0.011477,0.004372,0.111048,217.191528,11.064263,1.110481,-590.351196,0.112167,0.000000
81.210007,50.427422,-590.395691,0.011499,0.004398,0.111698,224.312378,11.427017,1.116983,-590.395691,0.112635,0.000000
81.490005,52.106079,-590.351196,0.011499,0.004421,0.112297,231.779419,11.807405,1.122967,-590.351196,0.113103,0.000000
81.770004,52.790871,-590.306702,0.011512,0.004437,0.112704,234.825516,11.962583,1.127043,-590.306702,0.113572,0.000000
82.050003,53.553864,-590.351196,0.011507,0.004451,0.113060,238.219482,12.135479,1.130601,-590.351196,0.114040,0.000000
82.330002,54.436386,-590.351196,0.011546,0.004469,0.113511,242.145142,12.335462,1.135109,-590.351196,0.114500,0.000000
82.610001,55.689789,-590.351196,0.011546,0.004487,0.113962,247.720551,12.619486,1.139621,-590.351196,0.114968,0.000000
82.890007,56.627800,-590.351196,0.011538,0.004503,0.114370,251.893036,12.832043,1.143697,-590.351196,0.115436,0.000000
83.170006,58.160851,-590.440125,0.011551,0.004527,0.114985,258.712372,13.179438,1.149851,-590.440125,0.115904,0.000000
83.450005,59.734497,-590.395691,0.011568,0.004547,0.115506,265.712311,13.536030,1.155055,-590.395691,0.116373,0.000000
83.730003,60.771927,-590.395691,0.011563,0.004565,0.115948,270.327026,13.771115,1.159480,-590.395691,0.116833,0.000000
84.010002,61.827980,-590.395691,0.011581,0.004582,0.116373,275.024597,14.010421,1.163727,-590.395691,0.117301,0.000000
84.290001,62.434570,-590.440125,0.011585,0.004596,0.116746,277.722839,14.147876,1.167458,-590.440125,0.117769,0.000000
84.570007,64.120674,-590.440125,0.011594,0.004617,0.117275,285.222992,14.529952,1.172746,-590.440125,0.118237,0.000000
84.850006,64.803612,-590.440125,0.011602,0.004628,0.117544,288.260864,14.684708,1.175437,-590.440125,0.118706,0.000000
85.130005,66.933952,-590.440125,0.011607,0.004656,0.118263,297.737091,15.167451,1.182632,-590.440125,0.119174,0.000000
85.410004,66.952568,-590.484619,0.011607,0.004653,0.118194,297.819885,15.171669,1.181939,-590.484619,0.118411,0.000000
85.690002,66.310966,-590.484619,0.011615,0.004653,0.118185,294.965912,15.026279,1.181852,-590.484619,0.118194,0.000000
85.970001,65.724861,-590.529114,0.011607,0.004653,0.118177,292.358795,14.893466,1.181765,-590.529114,0.118194,0.000000
86.250008,65.197197,-590.484619,0.011632,0.004652,0.118168,290.011627,14.773896,1.181678,-590.484619,0.118194,0.000000
86.530006,64.767479,-590.440125,0.011641,0.004652,0.118168,288.100128,14.676520,1.181678,-590.440125,0.118194,0.000000
86.810005,64.370903,-590.484619,0.011632,0.004652,0.118168,286.336090,14.586655,1.181678,-590.484619,0.118194,0.000000
87.090004,64.012688,-590.529114,0.011641,0.004652,0.118159,284.742645,14.505482,1.181595,-590.529114,0.118194,0.000000
87.370003,63.693932,-590.484619,0.011645,0.004652,0.118159,283.324768,14.433251,1.181595,-590.484619,0.118194,0.000000
87.650002,63.403114,-590.484619,0.011632,0.004652,0.118159,282.031128,14.367352,1.181595,-590.484619,0.118194,0.000000
87.930008,63.132393,-590.484619,0.011650,0.004652,0.118159,280.826904,14.306005,1.181595,-590.484619,0.118194,0.000000
88.210007,62.900414,-590.529114,0.011645,0.004652,0.118159,279.795013,14.253437,1.181595,-590.529114,0.118194,0.000000
88.490005,62.671028,-590.529114,0.011663,0.004652,0.118159,278.774658,14.201458,1.181595,-590.529114,0.118194,0.000000
88.770004,62.455429,-590.529114,0.011650,0.004652,0.118159,277.815613,14.152602,1.181595,-590.529114,0.118194,0.000000
89.050003,62.253975,-590.529114,0.011645,0.004652,0.118159,276.919525,14.106953,1.181595,-590.529114,0.118194,0.000000
89.330002,62.082680,-590.529114,0.011654,0.004652,0.118151,276.157562,14.068136,1.181508,-590.529114,0.118194,0.000000
89.610001,61.903198,-590.618042,0.011641,0.004652,0.118151,275.359192,14.027466,1.181508,-590.618042,0.118194,0.000000
89.890007,61.738609,-590.618042,0.011658,0.004652,0.118151,274.627045,13.990169,1.181508,-590.618042,0.118194,0.000000
90.170006,61.586678,-590.529114,0.011645,0.004652,0.118151,273.951233,13.955741,1.181508,-590.529114,0.118194,0.000000
90.450005,61.447044,-590.529114,0.011650,0.004652,0.118151,273.330109,13.924100,1.181508,-590.529114,0.118194,0.000000
90.730003,61.298836,-590.573608,0.011650,0.004652,0.118151,272.670837,13.890515,1.181508,-590.573608,0.118194,0.000000
91.010002,61.178558,-590.573608,0.011671,0.004652,0.118151,272.135834,13.863259,1.181508,-590.573608,0.118194,0.000000
91.290001,61.061264,-590.662537,0.011658,0.004652,0.118151,271.614075,13.836679,1.181508,-590.662537,0.118194,0.000000
91.570007,60.930557,-590.662537,0.011658,0.004652,0.118151,271.032654,13.807061,1.181508,-590.662537,0.118194,0.000000
91.850006,60.827782,-590.618042,0.011645,0.004652,0.118151,270.575500,13.783772,1.181508,-590.618042,0.118194,0.000000
92.130005,60.715698,-590.618042,0.011663,0.004652,0.118151,270.076904,13.758374,1.181508,-590.618042,0.118194,0.000000
92.410004,60.614044,-590.662537,0.011667,0.004652,0.118151,269.624725,13.735338,1.181508,-590.662537,0.118194,0.000000
92.690002,60.516853,-590.707031,0.011650,0.004652,0.118151,269.192413,13.713315,1.181508,-590.707031,0.118194,0.000000
92.970001,60.419662,-590.618042,0.011650,0.004652,0.118151,268.760071,13.691291,1.181508,-590.618042,0.118194,0.000000
93.250008,60.330299,-590.573608,0.011645,0.004652,0.118151,268.362579,13.671041,1.181508,-590.573608,0.118194,0.000000
93.530006,60.240929,-590.618042,0.011663,0.004652,0.118151,267.965027,13.650789,1.181508,-590.618042,0.118194,0.000000
93.810005,60.153793,-590.707031,0.011658,0.004652,0.118151,267.577423,13.631044,1.181508,-590.707031,0.118194,0.000000
94.090004,60.076340,-590.618042,0.011671,0.004652,0.118151,267.232910,13.613494,1.181508,-590.618042,0.118194,0.000000
94.370003,59.994041,-590.662537,0.011667,0.004652,0.118151,266.866821,13.594844,1.181508,-590.662537,0.118194,0.000000
94.650002,59.919945,-590.707031,0.011663,0.004652,0.118151,266.537231,13.578053,1.181508,-590.707031,0.118194,0.000000
94.930008,59.846214,-590.618042,0.011676,0.004652,0.118151,266.209259,13.561346,1.181508,-590.618042,0.118194,0.000000
95.210007,59.768013,-590.662537,0.011676,0.004652,0.118151,265.861389,13.543625,1.181508,-590.662537,0.118194,0.000000
95.490005,59.709175,-590.707031,0.011680,0.004652,0.118151,265.599670,13.530293,1.181508,-590.707031,0.118194,0.000000
95.770004,59.639915,-590.662537,0.011658,0.004652,0.118151,265.291595,13.514598,1.181508,-590.662537,0.118194,0.000000
96.050003,59.585182,-590.662537,0.011658,0.004652,0.118151,265.048126,13.502194,1.181508,-590.662537,0.118194,0.000000
96.330002,59.528580,-590.707031,0.011667,0.004652,0.118151,264.796356,13.489368,1.181508,-590.707031,0.118194,0.000000
96.610008,59.468628,-590.707031,0.011667,0.004652,0.118151,264.529663,13.475784,1.181508,-590.707031,0.118194,0.000000
96.890007,59.419098,-590.707031,0.011671,0.004652,0.118151,264.309357,13.464561,1.181508,-590.707031,0.118194,0.000000
97.170006,59.342766,-590.707031,0.011650,0.004652,0.118151,263.969818,13.447263,1.181508,-590.707031,0.118194,0.000000
97.450005,59.291374,-590.751526,0.011680,0.004652,0.118151,263.741211,13.435617,1.181508,-590.751526,0.118194,0.000000
97.730003,59.244827,-590.751526,0.011671,0.004652,0.118151,263.534149,13.425070,1.181508,-590.751526,0.118194,0.000000
98.010002,59.198654,-590.751526,0.011663,0.004652,0.118151,263.328766,13.414606,1.181508,-590.751526,0.118194,0.000000
98.290001,59.152107,-590.751526,0.011667,0.004652,0.118151,263.121704,13.404059,1.181508,-590.751526,0.118194,0.000000
98.570007,59.081734,-590.796021,0.011667,0.004652,0.118151,262.808685,13.388112,1.181508,-590.796021,0.118194,0.000000
98.850006,59.031464,-590.796021,0.011663,0.004652,0.118151,262.585052,13.376721,1.181508,-590.796021,0.118194,0.000000
99.130005,58.983421,-590.796021,0.011667,0.004652,0.118151,262.371368,13.365834,1.181508,-590.796021,0.118194,0.000000
99.410004,58.940971,-590.707031,0.011663,0.004652,0.118151,262.182526,13.356215,1.181508,-590.707031,0.118194,0.000000
99.690002,58.892937,-590.751526,0.011676,0.004652,0.118151,261.968872,13.345330,1.181508,-590.751526,0.118194,0.000000
99.970001,58.841553,-590.884949,0.011680,0.004652,0.118151,261.740295,13.333687,1.181508,-590.884949,0.118194,0.000000
100.250008,58.797981,-590.796021,0.011667,0.004652,0.118151,261.546478,13.323813,1.181508,-590.796021,0.118194,0.000000
100.530006,58.754044,-590.796021,0.011667,0.004652,0.118151,261.351044,13.313857,1.181508,-590.796021,0.118194,0.000000
100.810005,58.714203,-590.796021,0.011671,0.004652,0.118151,261.173828,13.304829,1.181508,-590.796021,0.118194,0.000000
101.090004,58.660202,-590.796021,0.011684,0.004652,0.118151,260.933624,13.292592,1.181508,-590.796021,0.118194,0.000000
101.370003,58.633766,-590.840454,0.011676,0.004652,0.118151,260.816010,13.286602,1.181508,-590.840454,0.118194,0.000000
101.650002,58.586105,-590.840454,0.011676,0.004652,0.118151,260.604004,13.275801,1.181508,-590.840454,0.118194,0.000000
101.930008,58.554077,-590.796021,0.011671,0.004652,0.118151,260.461548,13.268544,1.181508,-590.796021,0.118194,0.000000
102.210007,58.511627,-590.840454,0.011680,0.004652,0.118151,260.272705,13.258924,1.181508,-590.840454,0.118194,0.000000
102.490005,58.476624,-590.840454,0.011680,0.004652,0.118151,260.117004,13.250993,1.181508,-590.840454,0.118194,0.000000
102.770004,58.427475,-590.884949,0.011680,0.004652,0.118151,259.898376,13.239855,1.181508,-590.884949,0.118194,0.000000
103.050003,58.401031,-590.929443,0.011663,0.004652,0.118151,259.780762,13.233863,1.181508,-590.929443,0.118194,0.000000
103.330002,58.360077,-590.840454,0.011671,0.004652,0.118151,259.598602,13.224583,1.181508,-590.840454,0.118194,0.000000
103.610008,58.322464,-590.884949,0.011680,0.004652,0.118151,259.431274,13.216060,1.181508,-590.884949,0.118194,0.000000
103.890007,58.294167,-590.884949,0.011676,0.004652,0.118151,259.305389,13.209646,1.181508,-590.884949,0.118194,0.000000
104.170006,58.258041,-590.929443,0.011684,0.004652,0.118151,259.144714,13.201461,1.181508,-590.929443,0.118194,0.000000
104.450005,58.232719,-590.973938,0.011667,0.004652,0.118151,259.032074,13.195724,1.181508,-590.973938,0.118194,0.000000
104.730003,58.199577,-590.884949,0.011684,0.004652,0.118151,258.884644,13.188212,1.181508,-590.884949,0.118194,0.000000
105.010002,58.170166,-590.840454,0.011676,0.004652,0.118151,258.753815,13.181548,1.181508,-590.840454,0.118194,0.000000
105.290009,58.146706,-590.884949,0.011684,0.004652,0.118151,258.649475,13.176231,1.181508,-590.884949,0.118194,0.000000
105.570007,58.111328,-590.884949,0.011676,0.004652,0.118151,258.492096,13.168216,1.181508,-590.884949,0.118194,0.000000
105.850006,58.081535,-590.973938,0.011671,0.004652,0.118151,258.359558,13.161464,1.181508,-590.973938,0.118194,0.000000
106.130005,58.047653,-590.929443,0.011680,0.004652,0.118151,258.208862,13.153787,1.181508,-590.929443,0.118194,0.000000
106.410004,58.032013,-590.929443,0.011671,0.004652,0.118151,258.139282,13.150242,1.181508,-590.929443,0.118194,0.000000
106.690002,57.990677,-590.973938,0.011676,0.004652,0.118151,257.955414,13.140875,1.181508,-590.973938,0.118194,0.000000
106.970009,57.972435,-591.018372,0.011676,0.004652,0.118151,257.874268,13.136742,1.181508,-591.018372,0.118194,0.000000
107.250008,57.939667,-590.973938,0.011684,0.004652,0.118151,257.728516,13.129316,1.181508,-590.973938,0.118194,0.000000
107.530006,57.906525,-590.973938,0.011689,0.004652,0.118151,257.581085,13.121806,1.181508,-590.973938,0.118194,0.000000
107.810005,57.881950,-590.973938,0.011676,0.004652,0.118151,257.471771,13.116237,1.181508,-590.973938,0.118194,0.000000
108.090004,57.846947,-590.929443,0.011689,0.004652,0.118151,257.316071,13.108305,1.181508,-590.929443,0.118194,0.000000
108.370003,57.824600,-590.973938,0.011689,0.004652,0.118151,257.216675,13.103241,1.181508,-590.973938,0.118194,0.000000
108.650002,57.806725,-591.018372,0.011689,0.004652,0.118151,257.137146,13.099191,1.181508,-591.018372,0.118194,0.000000
108.930008,57.763908,-590.929443,0.011671,0.004652,0.118151,256.946686,13.089488,1.181508,-590.929443,0.118194,0.000000
109.210007,57.744545,-591.018372,0.011680,0.004652,0.118151,256.860565,13.085101,1.181508,-591.018372,0.118194,0.000000
109.490005,57.727409,-591.018372,0.011676,0.004652,0.118151,256.784332,13.081218,1.181508,-591.018372,0.118194,0.000000
109.770004,57.694641,-591.018372,0.011680,0.004652,0.118151,256.638580,13.073792,1.181508,-591.018372,0.118194,0.000000
110.050003,57.676399,-590.973938,0.011676,0.004652,0.118151,256.557434,13.069658,1.181508,-590.973938,0.118194,0.000000
110.330002,57.657036,-591.107361,0.011680,0.004652,0.118151,256.471313,13.065270,1.181508,-591.107361,0.118194,0.000000
110.610008,57.634315,-590.973938,0.011680,0.004652,0.118151,256.370239,13.060122,1.181508,-590.973938,0.118194,0.000000
110.890007,57.598198,-590.973938,0.011684,0.004652,0.118151,256.209595,13.051938,1.181508,-590.973938,0.118194,0.000000
111.170006,57.581444,-591.018372,0.011689,0.004652,0.118151,256.135040,13.048141,1.181508,-591.018372,0.118194,0.000000
111.450005,57.556870,-591.107361,0.011684,0.004652,0.118151,256.025757,13.042573,1.181508,-591.107361,0.118194,0.000000
111.730003,57.543457,-591.062866,0.011671,0.004652,0.118151,255.966080,13.039534,1.181508,-591.062866,0.118194,0.000000
112.010002,57.511810,-591.018372,0.011684,0.004652,0.118151,255.825302,13.032363,1.181508,-591.018372,0.118194,0.000000
112.290009,57.478668,-591.018372,0.011671,0.004652,0.118151,255.677887,13.024852,1.181508,-591.018372,0.118194,0.000000
112.570007,57.464890,-591.062866,0.011689,0.004652,0.118151,255.616592,13.021729,1.181508,-591.062866,0.118194,0.000000
112.850006,57.433609,-591.062866,0.011684,0.004652,0.118151,255.477448,13.014642,1.181508,-591.062866,0.118194,0.000000
113.130005,57.413132,-591.107361,0.011689,0.004652,0.118151,255.386368,13.010001,1.181508,-591.107361,0.118194,0.000000
113.410004,57.395630,-591.062866,0.011680,0.004652,0.118151,255.308517,13.006036,1.181508,-591.062866,0.118194,0.000000
113.690002,57.374779,-591.062866,0.011689,0.004652,0.118151,255.215759,13.001310,1.181508,-591.062866,0.118194,0.000000
113.970009,57.360252,-591.107361,0.011693,0.004652,0.118151,255.151138,12.998019,1.181508,-591.107361,0.118194,0.000000
114.250008,57.341637,-591.196350,0.011684,0.004652,0.118151,255.068344,12.993801,1.181508,-591.196350,0.118194,0.000000
114.530006,57.318176,-591.151855,0.011689,0.004652,0.118151,254.963989,12.988484,1.181508,-591.151855,0.118194,0.000000
114.810005,57.298065,-591.107361,0.011689,0.004652,0.118151,254.874527,12.983928,1.181508,-591.107361,0.118194,0.000000
115.090004,57.273491,-591.107361,0.011680,0.004652,0.118151,254.765213,12.978358,1.181508,-591.107361,0.118194,0.000000
115.370003,57.260826,-591.107361,0.011676,0.004652,0.118151,254.708878,12.975489,1.181508,-591.107361,0.118194,0.000000
115.650009,57.233650,-591.107361,0.011676,0.004652,0.118151,254.587997,12.969330,1.181508,-591.107361,0.118194,0.000000
115.700005,57.231041,-591.196350,0.011676,0.004652,0.118151,254.576385,12.968740,1.181508,-591.196350,0.118194,0.000000