File: Data/compression 7/AutoHeating-12-7-2-2-240320_03202024_204706.csv
Time (sec),S:Load (lbs),S:HL1 (DIM),S:LVDT (in),S:Position (in),Ch:Position (mm),Ch:Load (N),Ch:Stress (MPa),Ch:Strain (mm/mm),Ch:HL1 (DIM),Set Point (),Cycles ()
0.010000,0.004097,-599.158386,-0.000017,-0.000000,-0.000000,0.018224,0.000928,-0.000000,-599.158386,0.000199,0.000000
0.260000,0.004471,-599.202881,0.000000,-0.000000,-0.000000,0.019887,0.001013,-0.000000,-599.202881,0.000199,0.000000
0.510000,0.021599,-599.202881,0.000009,0.000097,0.002455,0.096076,0.004894,0.024545,-599.202881,0.003131,0.000000
0.760000,-0.018990,-599.202881,0.000069,0.000247,0.006261,-0.084470,-0.004303,0.062614,-599.202881,0.007293,0.000000
1.010000,-0.000374,-599.202881,0.000229,0.000411,0.010450,-0.001663,-0.000085,0.104501,-599.202881,0.011456,0.000000
1.260000,0.018242,-599.202881,0.000392,0.000565,0.014353,0.081144,0.004134,0.143527,-599.202881,0.015636,0.000000
1.510000,-0.020111,-599.202881,0.000582,0.000741,0.018819,-0.089459,-0.004557,0.188189,-599.202881,0.019799,0.000000
1.760000,-0.019363,-599.158386,0.000742,0.000904,0.022964,-0.086133,-0.004388,0.229641,-599.158386,0.023961,0.000000
2.010000,0.029045,-599.158386,0.000897,0.001066,0.027066,0.129199,0.006582,0.270662,-599.158386,0.028124,0.000000
2.260000,0.036865,-599.202881,0.001056,0.001228,0.031194,0.163985,0.008354,0.311943,-599.202881,0.032287,0.000000
2.510000,-0.008194,-599.202881,0.001246,0.001392,0.035366,-0.036449,-0.001857,0.353657,-599.202881,0.036450,0.000000
2.760000,0.027924,-599.158386,0.001406,0.001561,0.039641,0.124210,0.006328,0.396411,-599.158386,0.040612,0.000000
3.010000,0.007072,-599.202881,0.001565,0.001714,0.043526,0.031460,0.001603,0.435263,-599.202881,0.044792,0.000000
3.260000,0.000740,-599.158386,0.001755,0.001887,0.047923,0.003292,0.000168,0.479232,-599.158386,0.048955,0.000000
3.510000,-0.025696,-599.247375,0.001884,0.002048,0.052016,-0.114301,-0.005823,0.520162,-599.247375,0.053118,0.000000
3.760000,0.010056,-599.202881,0.002070,0.002211,0.056170,0.044729,0.002279,0.561705,-599.202881,0.057280,0.000000
4.010000,0.027557,-599.247375,0.002233,0.002382,0.060515,0.122581,0.006245,0.605152,-599.247375,0.061443,0.000000
4.260000,-0.017876,-599.247375,0.002410,0.002543,0.064600,-0.079515,-0.004051,0.645998,-599.247375,0.065606,0.000000
4.510000,0.025696,-599.202881,0.002570,0.002709,0.068814,0.114301,0.005823,0.688143,-599.202881,0.069768,0.000000
4.760000,0.016014,-599.247375,0.002712,0.002858,0.072595,0.071234,0.003629,0.725954,-599.247375,0.073931,0.000000
5.010000,0.007446,-599.247375,0.002897,0.003033,0.077036,0.033123,0.001687,0.770359,-599.247375,0.078111,0.000000
5.260000,0.007820,-599.247375,0.003070,0.003195,0.081147,0.034786,0.001772,0.811466,-599.247375,0.082274,0.000000
5.510000,0.027184,-599.247375,0.003238,0.003355,0.085205,0.120918,0.006160,0.852052,-599.247375,0.086436,0.000000
5.760000,-0.002609,-599.291870,0.003393,0.003529,0.089637,-0.011607,-0.000591,0.896365,-599.291870,0.090599,0.000000
6.010000,-0.045799,-599.247375,0.003557,0.003692,0.093782,-0.203725,-0.010378,0.937818,-599.247375,0.094762,0.000000
6.260000,0.016014,-599.247375,0.003725,0.003856,0.097945,0.071234,0.003629,0.979448,-599.247375,0.098925,0.000000
6.510000,0.045425,-599.291870,0.003876,0.004014,0.101951,0.202062,0.010294,1.019511,-599.291870,0.103087,0.000000
6.760000,0.004097,-599.291870,0.004044,0.004178,0.106114,0.018224,0.000928,1.061137,-599.291870,0.107250,0.000000
7.010000,0.020103,-599.291870,0.004212,0.004347,0.110415,0.089425,0.004556,1.104152,-599.291870,0.111430,0.000000
7.260000,0.029045,-599.247375,0.004381,0.004501,0.114335,0.129199,0.006582,1.143352,-599.247375,0.115593,0.000000
7.510000,0.032394,-599.247375,0.004544,0.004673,0.118697,0.144098,0.007341,1.186973,-599.247375,0.119755,0.000000
7.760000,0.043198,-599.336365,0.004721,0.004838,0.122877,0.192153,0.009789,1.228774,-599.336365,0.123918,0.000000
8.010000,0.777885,-599.291870,0.004872,-0.000003,-0.000078,3.460207,0.176271,-0.000783,-599.291870,0.000026,0.000000
8.260000,0.659096,-599.291870,0.004872,-0.000006,-0.000156,2.931804,0.149353,-0.001563,-599.291870,0.000026,0.000000
8.510000,0.564888,-599.336365,0.004872,-0.000006,-0.000165,2.512747,0.128005,-0.001650,-599.336365,0.000061,0.000000
8.760000,0.586113,-599.336365,0.004872,-0.000006,-0.000165,2.607161,0.132815,-0.001650,-599.336365,0.000477,0.000000
9.010000,0.649414,-599.336365,0.004868,0.000002,0.000052,2.888738,0.147159,0.000519,-599.336365,0.000893,0.000000
9.260000,0.799484,-599.291870,0.004876,0.000016,0.000399,3.556283,0.181166,0.003989,-599.291870,0.001310,0.000000
9.510000,0.950668,-599.247375,0.004907,0.000035,0.000893,4.228784,0.215425,0.008932,-599.247375,0.001726,0.000000
9.760000,1.156212,-599.336365,0.004932,0.000055,0.001396,5.143087,0.262001,0.013962,-599.336365,0.002142,0.000000
10.010000,1.238884,-599.336365,0.004950,0.000070,0.001769,5.510831,0.280735,0.017691,-599.336365,0.002558,0.000000
10.260000,1.315216,-599.380798,0.004932,0.000084,0.002142,5.850373,0.298032,0.021419,-599.380798,0.002975,0.000000
10.510000,1.487999,-599.380798,0.004950,0.000103,0.002619,6.618950,0.337185,0.026188,-599.380798,0.003391,0.000000
10.760000,1.561356,-599.425293,0.004975,0.000113,0.002862,6.945257,0.353808,0.028618,-599.425293,0.003807,0.000000
11.010000,1.842499,-599.380798,0.005001,0.000133,0.003391,8.195844,0.417516,0.033909,-599.380798,0.004232,0.000000
11.260000,1.937080,-599.380798,0.005006,0.000145,0.003694,8.616564,0.438949,0.036944,-599.380798,0.004648,0.000000
11.510000,2.143005,-599.380798,0.005019,0.000166,0.004223,9.532564,0.485612,0.042232,-599.380798,0.005065,0.000000
11.760000,2.298653,-599.425293,0.005049,0.000186,0.004726,10.224917,0.520882,0.047262,-599.425293,0.005481,0.000000
12.010000,2.420418,-599.336365,0.005044,0.000202,0.005125,10.766556,0.548474,0.051251,-599.336365,0.005897,0.000000
12.260000,2.547401,-599.380798,0.005079,0.000218,0.005541,11.331408,0.577249,0.055415,-599.380798,0.006313,0.000000
12.510000,2.653900,-599.380798,0.005079,0.000231,0.005862,11.805138,0.601382,0.058624,-599.380798,0.006730,0.000000
12.760000,2.873222,-599.336365,0.005109,0.000250,0.006357,12.780731,0.651082,0.063567,-599.336365,0.007146,0.000000
13.010000,2.997597,-599.425293,0.005113,0.000266,0.006747,13.333976,0.679265,0.067470,-599.425293,0.007562,0.000000
13.260000,3.076164,-599.380798,0.005118,0.000276,0.007016,13.683462,0.697069,0.070157,-599.380798,0.007978,0.000000
13.510000,3.228470,-599.380798,0.005139,0.000294,0.007458,14.360951,0.731582,0.074581,-599.380798,0.008395,0.000000
13.760000,3.517059,-599.425293,0.005157,0.000316,0.008030,15.644661,0.796977,0.080304,-599.425293,0.008811,0.000000
14.010000,3.559883,-599.425293,0.005170,0.000331,0.008403,15.835151,0.806681,0.084032,-599.425293,0.009227,0.000000
14.260000,3.707336,-599.425293,0.005182,0.000348,0.008846,16.491056,0.840094,0.088457,-599.425293,0.009644,0.000000
14.510000,3.764687,-599.425293,0.005204,0.000360,0.009141,16.746162,0.853090,0.091405,-599.425293,0.010060,0.000000
14.760000,4.006355,-599.469788,0.005213,0.000379,0.009626,17.821157,0.907853,0.096261,-599.469788,0.010476,0.000000
15.010001,4.152321,-599.425293,0.005243,0.000394,0.010016,18.470446,0.940929,0.100163,-599.425293,0.010892,0.000000
15.260001,4.213020,-599.425293,0.005251,0.000407,0.010346,18.740450,0.954684,0.103460,-599.425293,0.011309,0.000000
15.510001,4.438309,-599.558716,0.005269,0.000425,0.010805,19.742582,1.005735,0.108055,-599.558716,0.011725,0.000000
15.760001,4.674393,-599.469788,0.005282,0.000446,0.011335,20.792738,1.059232,0.113346,-599.469788,0.012141,0.000000
16.010000,4.691521,-599.514282,0.005303,0.000461,0.011707,20.868927,1.063114,0.117074,-599.514282,0.012566,0.000000
16.260000,4.802856,-599.469788,0.005320,0.000476,0.012098,21.364172,1.088343,0.120977,-599.469788,0.012982,0.000000
16.510000,4.996864,-599.469788,0.005320,0.000496,0.012592,22.227163,1.132306,0.125920,-599.469788,0.013399,0.000000
16.760000,5.194595,-599.469788,0.005346,0.000514,0.013043,23.106714,1.177112,0.130431,-599.469788,0.013815,0.000000
17.010000,5.178581,-599.469788,0.005351,0.000524,0.013303,23.035480,1.173483,0.133031,-599.469788,0.014231,0.000000
17.260000,5.286568,-599.514282,0.005368,0.000538,0.013659,23.515827,1.197953,0.136586,-599.514282,0.014647,0.000000
17.510000,5.661919,-599.514282,0.005394,0.000562,0.014283,25.185472,1.283009,0.142831,-599.514282,0.015064,0.000000
17.760000,5.668625,-599.469788,0.005402,0.000576,0.014621,25.215303,1.284529,0.146214,-599.469788,0.015480,0.000000
18.010000,5.740494,-599.469788,0.005407,0.000592,0.015029,25.534992,1.300815,0.150291,-599.469788,0.015896,0.000000
18.260000,5.941574,-599.514282,0.005441,0.000608,0.015437,26.429441,1.346380,0.154367,-599.514282,0.016313,0.000000
18.510000,6.102066,-599.558716,0.005450,0.000623,0.015835,27.143345,1.382748,0.158352,-599.558716,0.016729,0.000000
18.760000,6.258087,-599.558716,0.005471,0.000643,0.016321,27.837362,1.418103,0.163212,-599.558716,0.017145,0.000000
19.010000,6.130363,-599.514282,0.005480,0.000649,0.016486,27.269218,1.389160,0.164859,-599.514282,0.017561,0.000000
19.260000,6.297935,-599.558716,0.005497,0.000664,0.016867,28.014616,1.427133,0.168674,-599.558716,0.017977,0.000000
19.510000,6.780899,-599.603210,0.005501,0.000690,0.017526,30.162945,1.536574,0.175263,-599.603210,0.018394,0.000000
19.760000,6.684082,-599.558716,0.005523,0.000701,0.017813,29.732283,1.514635,0.178129,-599.558716,0.018810,0.000000
20.010000,6.948845,-599.603210,0.005549,0.000725,0.018411,30.910006,1.574631,0.184112,-599.603210,0.019226,0.000000
20.260000,7.075073,-599.558716,0.005558,0.000741,0.018819,31.471498,1.603235,0.188189,-599.558716,0.019642,0.000000
20.510000,7.168167,-599.603210,0.005592,0.000757,0.019235,31.885599,1.624330,0.192348,-599.603210,0.020059,0.000000
20.760000,7.257164,-599.603210,0.005583,0.000772,0.019608,32.281479,1.644497,0.196080,-599.603210,0.020475,0.000000
21.010000,7.352867,-599.558716,0.005601,0.000787,0.019990,32.707188,1.666183,0.199895,-599.558716,0.020891,0.000000
21.260000,7.229980,-599.647705,0.005605,0.000793,0.020154,32.160561,1.638337,0.201542,-599.647705,0.021316,0.000000
21.510000,7.787048,-599.647705,0.005635,0.000824,0.020917,34.638519,1.764570,0.209172,-599.647705,0.021732,0.000000
21.760000,7.809395,-599.647705,0.005644,0.000836,0.021238,34.737923,1.769634,0.212382,-599.647705,0.022149,0.000000
22.010000,8.006752,-599.558716,0.005665,0.000858,0.021785,35.615810,1.814356,0.217847,-599.558716,0.022565,0.000000
22.260000,8.011589,-599.647705,0.005696,0.000871,0.022131,35.637329,1.815452,0.221314,-599.647705,0.022982,0.000000
22.510000,8.093140,-599.603210,0.005708,0.000885,0.022478,36.000084,1.833932,0.224785,-599.603210,0.023397,0.000000
22.760000,8.091652,-599.647705,0.005730,0.000897,0.022782,35.993465,1.833595,0.227820,-599.647705,0.023814,0.000000
23.010000,8.193314,-599.692200,0.005713,0.000910,0.023120,36.445679,1.856631,0.231200,-599.692200,0.024230,0.000000
23.260000,8.834534,-599.647705,0.005734,0.000940,0.023875,39.297970,2.001934,0.238747,-599.647705,0.024646,0.000000
23.510000,8.818527,-599.647705,0.005777,0.000955,0.024265,39.226768,1.998307,0.242650,-599.647705,0.025063,0.000000
23.760000,8.781662,-599.692200,0.005799,0.000970,0.024638,39.062782,1.989953,0.246378,-599.692200,0.025479,0.000000
24.010000,8.840492,-599.647705,0.005790,0.000984,0.024993,39.324474,2.003284,0.249932,-599.647705,0.025895,0.000000
24.260000,8.940659,-599.647705,0.005816,0.000999,0.025375,39.770035,2.025982,0.253751,-599.647705,0.026311,0.000000
24.510000,9.181961,-599.692200,0.005812,0.001017,0.025835,40.843403,2.080662,0.258346,-599.692200,0.026728,0.000000
24.760000,9.206535,-599.692200,0.005842,0.001031,0.026199,40.952713,2.086231,0.261987,-599.692200,0.027144,0.000000
25.010002,9.293671,-599.692200,0.005859,0.001044,0.026520,41.340313,2.105976,0.265196,-599.692200,0.027560,0.000000
25.260002,9.725250,-599.692200,0.005877,0.001069,0.027153,43.260075,2.203773,0.271528,-599.692200,0.027976,0.000000
25.510002,9.716316,-599.736633,0.005877,0.001083,0.027500,43.220333,2.201749,0.274995,-599.736633,0.028393,0.000000
25.760002,9.825790,-599.692200,0.005902,0.001099,0.027925,43.707298,2.226556,0.279246,-599.692200,0.028809,0.000000
26.010002,9.885368,-599.692200,0.005924,0.001115,0.028315,43.972313,2.240057,0.283148,-599.692200,0.029225,0.000000
26.260002,10.062996,-599.736633,0.005933,0.001133,0.028774,44.762440,2.280308,0.287743,-599.736633,0.029650,0.000000
26.510002,10.153107,-599.736633,0.005941,0.001148,0.029165,45.163273,2.300727,0.291645,-599.736633,0.030066,0.000000
26.760002,10.192947,-599.781128,0.005959,0.001161,0.029494,45.340496,2.309755,0.294942,-599.781128,0.030483,0.000000
27.010002,10.276360,-599.736633,0.005967,0.001178,0.029911,45.711529,2.328656,0.299105,-599.736633,0.030899,0.000000
27.260002,10.739220,-599.736633,0.006006,0.001199,0.030448,47.770435,2.433542,0.304483,-599.736633,0.031315,0.000000
27.510002,10.789864,-599.781128,0.006015,0.001216,0.030890,47.995708,2.445018,0.308904,-599.781128,0.031732,0.000000
27.760002,10.812950,-599.781128,0.006023,0.001230,0.031237,48.098404,2.450249,0.312375,-599.781128,0.032148,0.000000
28.010002,10.879234,-599.825623,0.006045,0.001246,0.031653,48.393250,2.465270,0.316535,-599.825623,0.032564,0.000000
28.260002,11.147713,-599.781128,0.006058,0.001263,0.032078,49.587502,2.526108,0.320785,-599.781128,0.032980,0.000000
28.510002,11.250488,-599.692200,0.006075,0.001279,0.032486,50.044670,2.549397,0.324861,-599.692200,0.033397,0.000000
28.760002,11.196121,-599.692200,0.006101,0.001290,0.032772,49.802834,2.537077,0.327723,-599.692200,0.033813,0.000000
29.010002,11.383057,-599.781128,0.006105,0.001309,0.033249,50.634365,2.579437,0.332492,-599.781128,0.034229,0.000000
29.260002,11.982574,-599.825623,0.006135,0.001334,0.033891,53.301155,2.715290,0.338911,-599.825623,0.034645,0.000000
29.510002,11.918526,-599.870117,0.006131,0.001347,0.034221,53.016251,2.700776,0.342207,-599.870117,0.035062,0.000000
29.760002,12.108063,-599.825623,0.006153,0.001366,0.034689,53.859352,2.743726,0.346889,-599.825623,0.035478,0.000000
30.010002,11.941986,-599.781128,0.006174,0.001377,0.034975,53.120605,2.706093,0.349751,-599.781128,0.035894,0.000000
30.260002,12.209351,-599.781128,0.006174,0.001395,0.035443,54.309902,2.766678,0.354433,-599.781128,0.036311,0.000000
30.510002,12.338562,-599.825623,0.006187,0.001411,0.035833,54.884666,2.795958,0.358335,-599.825623,0.036727,0.000000
30.760002,12.183281,-599.870117,0.006200,0.001420,0.036076,54.193939,2.760771,0.360765,-599.870117,0.037143,0.000000
31.010002,12.786896,-599.870117,0.006209,0.001445,0.036710,56.878952,2.897552,0.367097,-599.870117,0.037559,0.000000
31.260002,13.006966,-599.781128,0.006247,0.001464,0.037195,57.857872,2.947421,0.371953,-599.781128,0.037984,0.000000
31.510002,12.975693,-599.870117,0.006260,0.001480,0.037594,57.718765,2.940334,0.375942,-599.870117,0.038401,0.000000
31.760002,13.122780,-599.870117,0.006282,0.001497,0.038036,58.373039,2.973664,0.380363,-599.870117,0.038817,0.000000
32.010002,12.984253,-599.870117,0.006286,0.001509,0.038331,57.756840,2.942274,0.383311,-599.870117,0.039233,0.000000
32.260002,13.247520,-599.914612,0.006291,0.001527,0.038791,58.927914,3.001931,0.387910,-599.914612,0.039649,0.000000
32.510002,13.301888,-599.870117,0.006303,0.001542,0.039155,59.169750,3.014251,0.391551,-599.870117,0.040066,0.000000
32.760002,13.378227,-599.870117,0.006334,0.001554,0.039476,59.509327,3.031550,0.394761,-599.870117,0.040482,0.000000
33.010002,14.144569,-599.959045,0.006342,0.001581,0.040152,62.918186,3.205205,0.401524,-599.959045,0.040898,0.000000
33.260002,13.951675,-599.870117,0.006351,0.001593,0.040473,62.060150,3.161495,0.404734,-599.870117,0.041314,0.000000
33.510002,14.030991,-599.870117,0.006377,0.001609,0.040881,62.412964,3.179468,0.408810,-599.870117,0.041731,0.000000
33.760002,14.161324,-599.870117,0.006398,0.001626,0.041306,62.992714,3.209002,0.413057,-599.870117,0.042147,0.000000
34.010002,14.176964,-599.914612,0.006390,0.001640,0.041661,63.062286,3.212546,0.416615,-599.914612,0.042563,0.000000
34.260002,14.592529,-599.959045,0.006420,0.001661,0.042199,64.910812,3.306715,0.421989,-599.959045,0.042980,0.000000
34.510002,14.474487,-599.959045,0.006428,0.001672,0.042477,64.385735,3.279966,0.424767,-599.959045,0.043396,0.000000
34.760002,14.693817,-600.048035,0.006454,0.001688,0.042867,65.361366,3.329667,0.428670,-600.048035,0.043812,0.000000
35.010002,15.151459,-599.959045,0.006459,0.001711,0.043448,67.397057,3.433370,0.434479,-599.959045,0.044228,0.000000
35.260002,15.257957,-599.914612,0.006485,0.001727,0.043856,67.870781,3.457503,0.438556,-599.914612,0.044645,0.000000
35.510002,15.191307,-600.003540,0.006497,0.001741,0.044220,67.574310,3.442400,0.442197,-600.003540,0.045061,0.000000
35.760002,15.282166,-600.003540,0.006506,0.001756,0.044592,67.978470,3.462988,0.445925,-600.003540,0.045477,0.000000
36.010002,15.600174,-599.959045,0.006523,0.001774,0.045061,69.393036,3.535050,0.450611,-599.959045,0.045893,0.000000
36.260002,15.674271,-599.959045,0.006554,0.001789,0.045434,69.722641,3.551840,0.454339,-599.959045,0.046310,0.000000
36.510002,15.733482,-600.003540,0.006541,0.001803,0.045807,69.986023,3.565258,0.458067,-600.003540,0.046735,0.000000
36.760002,16.046646,-600.003540,0.006579,0.001821,0.046258,71.379044,3.636222,0.462579,-600.003540,0.047151,0.000000
37.010002,16.370979,-600.003540,0.006584,0.001840,0.046735,72.821754,3.709717,0.467347,-600.003540,0.047567,0.000000
37.260002,16.229477,-600.003540,0.006605,0.001853,0.047073,72.192322,3.677652,0.470727,-600.003540,0.047983,0.000000
37.510002,16.346405,-600.003540,0.006605,0.001868,0.047455,72.712440,3.704148,0.474546,-600.003540,0.048400,0.000000
37.760002,16.577652,-600.003540,0.006631,0.001886,0.047905,73.741081,3.756550,0.479054,-600.003540,0.048816,0.000000
38.010002,16.931778,-600.003540,0.006661,0.001906,0.048417,75.316307,3.836796,0.484171,-600.003540,0.049232,0.000000
38.260002,16.923958,-600.048035,0.006674,0.001920,0.048773,75.281525,3.835024,0.487725,-600.048035,0.049649,0.000000
38.510002,16.703880,-600.048035,0.006674,0.001931,0.049050,74.302574,3.785153,0.490503,-600.048035,0.050065,0.000000
38.760002,17.512306,-600.048035,0.006687,0.001954,0.049640,77.898628,3.968345,0.496400,-600.048035,0.050481,0.000000
39.010002,17.521614,-600.048035,0.006700,0.001970,0.050030,77.940033,3.970455,0.500303,-600.048035,0.050897,0.000000
39.260002,17.444160,-600.092529,0.006713,0.001984,0.050386,77.595505,3.952903,0.503857,-600.092529,0.051314,0.000000
39.510002,17.478043,-600.092529,0.006730,0.002002,0.050845,77.746216,3.960581,0.508451,-600.092529,0.051730,0.000000
39.760002,17.489220,-600.048035,0.006748,0.002015,0.051192,77.795937,3.963114,0.511922,-600.048035,0.052146,0.000000
40.010002,18.063042,-600.092529,0.006756,0.002035,0.051695,80.348419,4.093144,0.516952,-600.092529,0.052562,0.000000
40.260002,17.894356,-600.092529,0.006765,0.002047,0.051999,79.598068,4.054919,0.519988,-600.092529,0.052979,0.000000
40.510002,17.432991,-600.136963,0.006778,0.002056,0.052224,77.545815,3.950372,0.522244,-600.136963,0.053395,0.000000
40.760002,18.782097,-600.048035,0.006795,0.002084,0.052927,83.546936,4.256084,0.529268,-600.048035,0.053811,0.000000
41.010002,18.716187,-600.092529,0.006795,0.002099,0.053308,83.253754,4.241148,0.533084,-600.092529,0.054227,0.000000
41.260002,18.881142,-600.092529,0.006812,0.002116,0.053750,83.987511,4.278528,0.537504,-600.092529,0.054644,0.000000
41.510002,19.164894,-600.048035,0.006847,0.002135,0.054219,85.249710,4.342827,0.542190,-600.048035,0.055069,0.000000
41.760002,19.237129,-600.181458,0.006842,0.002151,0.054626,85.571022,4.359196,0.546263,-600.181458,0.055485,0.000000
42.010002,19.224098,-600.048035,0.006860,0.002166,0.055008,85.513062,4.356243,0.550081,-600.048035,0.055901,0.000000
42.260002,19.291870,-600.136963,0.006868,0.002182,0.055416,85.814522,4.371600,0.554158,-600.136963,0.056317,0.000000
42.510002,19.066216,-600.136963,0.006894,0.002192,0.055667,84.810760,4.320467,0.556671,-600.136963,0.056734,0.000000
42.760002,19.773346,-600.092529,0.006911,0.002215,0.056265,87.956238,4.480704,0.562655,-600.092529,0.057150,0.000000
43.010002,20.189293,-600.136963,0.006907,0.002235,0.056760,89.806458,4.574959,0.567598,-600.136963,0.057566,0.000000
43.260002,20.060074,-600.136963,0.006924,0.002249,0.057133,89.231667,4.545678,0.571326,-600.136963,0.057983,0.000000
43.510002,20.160988,-600.092529,0.006942,0.002265,0.057523,89.680550,4.568545,0.575228,-600.092529,0.058399,0.000000
43.760002,20.290199,-600.136963,0.006959,0.002280,0.057922,90.255318,4.597825,0.579218,-600.136963,0.058815,0.000000
44.010002,20.203064,-600.181458,0.006963,0.002294,0.058260,89.867714,4.578080,0.582601,-600.181458,0.059231,0.000000
44.260002,20.270470,-600.136963,0.006976,0.002307,0.058607,90.167549,4.593354,0.586068,-600.136963,0.059648,0.000000
44.510002,21.015953,-600.181458,0.006972,0.002333,0.059249,93.483627,4.762283,0.592487,-600.181458,0.060064,0.000000
44.760002,21.403595,-600.136963,0.007006,0.002350,0.059700,95.207947,4.850124,0.596995,-600.136963,0.060480,0.000000
45.010002,21.153732,-600.181458,0.007011,0.002364,0.060047,94.096504,4.793504,0.600466,-600.181458,0.060896,0.000000
45.260002,21.231186,-600.136963,0.007032,0.002379,0.060437,94.441032,4.811056,0.604368,-600.136963,0.061313,0.000000
45.510002,20.918770,-600.181458,0.007041,0.002392,0.060758,93.051338,4.740261,0.607578,-600.181458,0.061729,0.000000
45.760002,21.436737,-600.136963,0.007045,0.002411,0.061243,95.355370,4.857634,0.612434,-600.136963,0.062145,0.000000
46.010002,21.315346,-600.225952,0.007062,0.002425,0.061599,94.815392,4.830126,0.615988,-600.225952,0.062562,0.000000
46.260002,21.171982,-600.136963,0.007054,0.002438,0.061928,94.177681,4.797639,0.619285,-600.136963,0.062978,0.000000
46.510002,21.830338,-600.270447,0.007075,0.002461,0.062501,97.106194,4.946825,0.625007,-600.270447,0.063403,0.000000
46.760002,22.200470,-600.314941,0.007084,0.002478,0.062952,98.752625,5.030698,0.629519,-600.314941,0.063819,0.000000
47.010002,22.088387,-600.270447,0.007110,0.002495,0.063377,98.254051,5.005300,0.633769,-600.270447,0.064235,0.000000
47.260002,22.047424,-600.225952,0.007118,0.002509,0.063724,98.071838,4.996018,0.637236,-600.225952,0.064652,0.000000
47.510002,21.803154,-600.225952,0.007123,0.002523,0.064096,96.985275,4.940665,0.640964,-600.225952,0.065068,0.000000
47.760002,22.205688,-600.225952,0.007140,0.002542,0.064573,98.775833,5.031881,0.645733,-600.225952,0.065484,0.000000
48.010002,22.076469,-600.314941,0.007144,0.002557,0.064938,98.201042,5.002599,0.649378,-600.314941,0.065900,0.000000
48.260002,21.596115,-600.225952,0.007136,0.002568,0.065224,96.064316,4.893750,0.652240,-600.225952,0.066317,0.000000
48.510002,22.880424,-600.225952,0.007179,0.002596,0.065935,101.777214,5.184779,0.659351,-600.225952,0.066733,0.000000
48.760002,22.523323,-600.314941,0.007174,0.002609,0.066264,100.188744,5.103858,0.662644,-600.314941,0.067149,0.000000
49.010002,22.323730,-600.225952,0.007187,0.002626,0.066689,99.300911,5.058630,0.666895,-600.225952,0.067565,0.000000
49.260002,22.323730,-600.314941,0.007196,0.002641,0.067080,99.300911,5.058630,0.670797,-600.314941,0.067982,0.000000
49.510002,22.030296,-600.314941,0.007192,0.002654,0.067409,97.995651,4.992136,0.674094,-600.314941,0.068398,0.000000
49.760002,22.327827,-600.270447,0.007205,0.002673,0.067886,99.319138,5.059558,0.678863,-600.270447,0.068814,0.000000
50.010002,21.995667,-600.359375,0.007217,0.002686,0.068216,97.841614,4.984289,0.682159,-600.359375,0.069231,0.000000
50.260002,21.878372,-600.270447,0.007235,0.002699,0.068554,97.319862,4.957710,0.685539,-600.270447,0.069647,0.000000
50.510002,22.834625,-600.359375,0.007226,0.002726,0.069248,101.573486,5.174400,0.692477,-600.359375,0.070063,0.000000
50.760002,22.496880,-600.314941,0.007252,0.002740,0.069595,100.071121,5.097866,0.695948,-600.314941,0.070479,0.000000
51.010002,22.258934,-600.359375,0.007265,0.002754,0.069959,99.012680,5.043946,0.699589,-600.359375,0.070896,0.000000
51.260002,22.193771,-600.314941,0.007252,0.002769,0.070340,98.722824,5.029181,0.703404,-600.314941,0.071312,0.000000
51.510002,22.294685,-600.359375,0.007256,0.002788,0.070818,99.171715,5.052048,0.708177,-600.359375,0.071728,0.000000
51.760002,22.336388,-600.359375,0.007269,0.002802,0.071182,99.357216,5.061498,0.711818,-600.359375,0.072153,0.000000
52.010002,22.185577,-600.359375,0.007286,0.002816,0.071537,98.686378,5.027324,0.715372,-600.359375,0.072569,0.000000
52.260002,22.764618,-600.403870,0.007286,0.002839,0.072110,101.262077,5.158536,0.721098,-600.403870,0.072986,0.000000
52.510002,23.324669,-600.359375,0.007291,0.002859,0.072630,103.753311,5.285445,0.726299,-600.359375,0.073402,0.000000
52.760002,23.079643,-600.403870,0.007321,0.002873,0.072986,102.663383,5.229922,0.729856,-600.403870,0.073818,0.000000
53.010002,23.116135,-600.359375,0.007312,0.002892,0.073454,102.825699,5.238191,0.734538,-600.359375,0.074234,0.000000
53.260002,23.000702,-600.448364,0.007325,0.002906,0.073801,102.312233,5.212034,0.738009,-600.448364,0.074651,0.000000
53.510002,22.748230,-600.359375,0.007325,0.002918,0.074121,101.189178,5.154822,0.741215,-600.359375,0.075067,0.000000
53.760002,23.081505,-600.403870,0.007351,0.002934,0.074529,102.671661,5.230343,0.745291,-600.403870,0.075483,0.000000
54.010002,22.961601,-600.448364,0.007338,0.002948,0.074885,102.138306,5.203173,0.748849,-600.448364,0.075900,0.000000
54.260002,23.742096,-600.403870,0.007360,0.002971,0.075475,105.610115,5.380035,0.754746,-600.403870,0.076316,0.000000
54.510002,24.163994,-600.448364,0.007373,0.002989,0.075925,107.486816,5.475639,0.759254,-600.448364,0.076732,0.000000
54.760002,24.103668,-600.403870,0.007373,0.003004,0.076307,107.218468,5.461969,0.763073,-600.403870,0.077148,0.000000
55.010002,24.325974,-600.448364,0.007390,0.003021,0.076741,108.207336,5.512344,0.767406,-600.448364,0.077565,0.000000
55.260002,24.183731,-600.403870,0.007381,0.003034,0.077062,107.574608,5.480112,0.770616,-600.403870,0.077981,0.000000
55.510002,24.620895,-600.492859,0.007403,0.003053,0.077538,109.519211,5.579175,0.775385,-600.492859,0.078397,0.000000
55.760002,24.737076,-600.537292,0.007411,0.003067,0.077894,110.036011,5.605502,0.778943,-600.537292,0.078813,0.000000
56.010002,24.901665,-600.403870,0.007437,0.003083,0.078319,110.768135,5.642798,0.783189,-600.403870,0.079230,0.000000
56.260002,25.080399,-600.492859,0.007429,0.003098,0.078683,111.563187,5.683300,0.786834,-600.492859,0.079646,0.000000
56.510002,25.707108,-600.448364,0.007437,0.003120,0.079247,114.350929,5.825314,0.792470,-600.448364,0.080062,0.000000
56.760002,25.986008,-600.492859,0.007450,0.003135,0.079637,115.591537,5.888514,0.796372,-600.492859,0.080487,0.000000
57.010002,25.906693,-600.537292,0.007459,0.003150,0.080010,115.238724,5.870541,0.800100,-600.537292,0.080903,0.000000
57.260002,25.856056,-600.492859,0.007463,0.003166,0.080409,115.013481,5.859066,0.804090,-600.492859,0.081320,0.000000
57.510002,26.428391,-600.448364,0.007476,0.003183,0.080851,117.559349,5.988759,0.808514,-600.448364,0.081736,0.000000
57.760002,26.479408,-600.537292,0.007476,0.003197,0.081198,117.786293,6.000319,0.811981,-600.537292,0.082152,0.000000
58.010002,26.512543,-600.492859,0.007493,0.003208,0.081484,117.933678,6.007828,0.814842,-600.492859,0.082569,0.000000
58.260002,27.393578,-600.492859,0.007506,0.003232,0.082100,121.852722,6.207474,0.821001,-600.492859,0.082985,0.000000
58.510002,27.705627,-600.537292,0.007502,0.003249,0.082516,123.240784,6.278185,0.825164,-600.537292,0.083401,0.000000
58.760002,27.654984,-600.537292,0.007515,0.003264,0.082898,123.015511,6.266709,0.828979,-600.537292,0.083817,0.000000
59.010002,28.216896,-600.537292,0.007537,0.003282,0.083366,125.515022,6.394040,0.833665,-600.537292,0.084234,0.000000
59.260002,28.654060,-600.537292,0.007524,0.003301,0.083835,127.459625,6.493103,0.838347,-600.537292,0.084650,0.000000
59.510002,28.820137,-600.537292,0.007549,0.003316,0.084225,128.198380,6.530736,0.842249,-600.537292,0.085066,0.000000
59.760002,28.296951,-600.581787,0.007558,0.003323,0.084398,125.871124,6.412181,0.843982,-600.581787,0.085482,0.000000
60.010002,29.262520,-600.537292,0.007558,0.003349,0.085058,130.166183,6.630982,0.850576,-600.537292,0.085899,0.000000
60.260002,29.795006,-600.581787,0.007567,0.003366,0.085491,132.534805,6.751645,0.854909,-600.581787,0.086315,0.000000
60.510002,29.938004,-600.537292,0.007588,0.003381,0.085872,133.170883,6.784049,0.858725,-600.537292,0.086731,0.000000
60.760002,30.038170,-600.537292,0.007601,0.003395,0.086246,133.616455,6.806747,0.862456,-600.537292,0.087148,0.000000
61.010002,30.219887,-600.626282,0.007597,0.003411,0.086636,134.424774,6.847924,0.866359,-600.626282,0.087564,0.000000
61.260002,30.695404,-600.537292,0.007614,0.003429,0.087095,136.539978,6.955678,0.870954,-600.537292,0.087980,0.000000
61.510002,30.971336,-600.581787,0.007627,0.003444,0.087486,137.767380,7.018205,0.874856,-600.581787,0.088396,0.000000
61.760002,30.411659,-600.537292,0.007631,0.003450,0.087624,135.277817,6.891381,0.876245,-600.537292,0.088821,0.000000
62.010002,30.550552,-600.581787,0.007657,0.003464,0.087997,135.895645,6.922854,0.879973,-600.581787,0.089237,0.000000
62.260002,32.174469,-600.537292,0.007662,0.003494,0.088743,143.119186,7.290839,0.887429,-600.537292,0.089654,0.000000
62.510002,32.404221,-600.626282,0.007662,0.003509,0.089116,144.141174,7.342902,0.891161,-600.626282,0.090070,0.000000
62.760002,32.682014,-600.626282,0.007679,0.003526,0.089549,145.376862,7.405850,0.895495,-600.626282,0.090486,0.000000
63.010002,33.246155,-600.581787,0.007696,0.003544,0.090027,147.886276,7.533686,0.900268,-600.581787,0.090903,0.000000
63.260002,33.599541,-600.626282,0.007687,0.003562,0.090478,149.458221,7.613765,0.904775,-600.626282,0.091319,0.000000
63.510002,33.461388,-600.581787,0.007705,0.003573,0.090764,148.843689,7.582459,0.907637,-600.581787,0.091735,0.000000
63.760002,33.616295,-600.626282,0.007722,0.003586,0.091076,149.532745,7.617561,0.910759,-600.626282,0.092151,0.000000
64.010002,34.431419,-600.670776,0.007705,0.003609,0.091657,153.158600,7.802271,0.916569,-600.670776,0.092568,0.000000
64.260002,35.084190,-600.626282,0.007752,0.003626,0.092099,156.062271,7.950191,0.920994,-600.626282,0.092984,0.000000
64.510002,35.212654,-600.670776,0.007748,0.003641,0.092481,156.633713,7.979301,0.924809,-600.670776,0.093400,0.000000
64.760002,35.716476,-600.670776,0.007748,0.003656,0.092871,158.874817,8.093470,0.928711,-600.670776,0.093816,0.000000
65.010002,36.282486,-600.670776,0.007774,0.003675,0.093357,161.392563,8.221729,0.933567,-600.670776,0.094233,0.000000
65.260002,36.301476,-600.715271,0.007782,0.003689,0.093695,161.477020,8.226032,0.936951,-600.715271,0.094649,0.000000
65.510002,36.499207,-600.670776,0.007778,0.003700,0.093981,162.356583,8.270839,0.939812,-600.670776,0.095065,0.000000
65.760002,36.918121,-600.715271,0.007791,0.003716,0.094389,164.220001,8.365767,0.943888,-600.715271,0.095482,0.000000
66.010002,38.839561,-600.626282,0.007808,0.003746,0.095152,172.766998,8.801170,0.951519,-600.626282,0.095898,0.000000
66.260002,38.753174,-600.715271,0.007812,0.003758,0.095447,172.382721,8.781594,0.954467,-600.715271,0.096314,0.000000
66.510002,39.138954,-600.715271,0.007830,0.003774,0.095863,174.098770,8.869014,0.958631,-600.715271,0.096730,0.000000
66.760002,39.371315,-600.759705,0.007834,0.003785,0.096140,175.132355,8.921667,0.961405,-600.759705,0.097147,0.000000
67.010002,40.032646,-600.715271,0.007847,0.003804,0.096617,178.074097,9.071527,0.966174,-600.715271,0.097572,0.000000
67.260002,40.545029,-600.759705,0.007856,0.003819,0.097008,180.353302,9.187634,0.970076,-600.759705,0.097988,0.000000
67.510002,41.102844,-600.759705,0.007869,0.003833,0.097355,182.834579,9.314037,0.973547,-600.759705,0.098404,0.000000
67.760002,41.936211,-600.715271,0.007864,0.003853,0.097866,186.541580,9.502881,0.978664,-600.715271,0.098820,0.000000
68.010002,42.977364,-600.759705,0.007886,0.003873,0.098378,191.172867,9.738810,0.983781,-600.759705,0.099237,0.000000
68.260002,43.110680,-600.759705,0.007894,0.003884,0.098647,191.765884,9.769020,0.986469,-600.759705,0.099653,0.000000
68.510002,44.233749,-600.759705,0.007894,0.003906,0.099219,196.761551,10.023511,0.992191,-600.759705,0.100069,0.000000
68.760002,44.642616,-600.759705,0.007920,0.003918,0.099514,198.580276,10.116161,0.995140,-600.759705,0.100485,0.000000
69.010002,45.672600,-600.715271,0.007916,0.003938,0.100017,203.161865,10.349559,1.000170,-600.715271,0.100902,0.000000
69.260002,45.999542,-600.848694,0.007946,0.003950,0.100329,204.616180,10.423645,1.003292,-600.848694,0.101318,0.000000
69.510002,46.153328,-600.715271,0.007942,0.003960,0.100572,205.300262,10.458494,1.005722,-600.715271,0.101734,0.000000
69.760002,47.617500,-600.759705,0.007955,0.003987,0.101257,211.813217,10.790279,1.012573,-600.759705,0.102151,0.000000
70.010002,48.886169,-600.848694,0.007963,0.004004,0.101708,217.456543,11.077764,1.017081,-600.848694,0.102566,0.000000
70.260002,49.639107,-600.759705,0.007972,0.004019,0.102090,220.805771,11.248383,1.020896,-600.759705,0.102983,0.000000
70.510002,50.419601,-600.804199,0.007968,0.004037,0.102532,224.277588,11.425244,1.025321,-600.804199,0.103399,0.000000
70.760002,50.667976,-600.804199,0.007989,0.004047,0.102783,225.382416,11.481527,1.027834,-600.804199,0.103816,0.000000
71.010002,51.867386,-600.848694,0.007998,0.004069,0.103347,230.717651,11.753318,1.033473,-600.848694,0.104232,0.000000
71.260002,52.552177,-600.848694,0.008006,0.004080,0.103625,233.763763,11.908493,1.036247,-600.848694,0.104648,0.000000
71.510002,53.143135,-600.804199,0.008011,0.004094,0.103980,236.392471,12.042406,1.039801,-600.804199,0.105064,0.000000
71.760002,54.913391,-600.848694,0.008024,0.004118,0.104605,244.266968,12.443552,1.046047,-600.848694,0.105480,0.000000
72.010002,56.080040,-600.804199,0.008037,0.004135,0.105030,249.456482,12.707919,1.050297,-600.804199,0.105906,0.000000
72.260002,56.436394,-600.893188,0.008045,0.004146,0.105307,251.041611,12.788670,1.053071,-600.893188,0.106322,0.000000
72.510002,57.615326,-600.893188,0.008045,0.004164,0.105767,256.285767,13.055820,1.057666,-600.893188,0.106738,0.000000
72.760002,58.440506,-600.893188,0.008045,0.004179,0.106140,259.956360,13.242808,1.061398,-600.893188,0.107154,0.000000
73.010002,59.608269,-600.848694,0.008050,0.004196,0.106582,265.150818,13.507426,1.065819,-600.848694,0.107570,0.000000
73.260002,60.482597,-600.893188,0.008067,0.004210,0.106938,269.040039,13.705552,1.069377,-600.893188,0.107987,0.000000
73.510002,61.098129,-600.848694,0.008088,0.004223,0.107276,271.778046,13.845034,1.072757,-600.848694,0.108403,0.000000
73.760002,63.269432,-600.848694,0.008080,0.004250,0.107961,281.436493,14.337058,1.079607,-600.848694,0.108820,0.000000
74.010002,64.556358,-600.893188,0.008106,0.004267,0.108386,287.161011,14.628679,1.083858,-600.893188,0.109235,0.000000
74.260002,65.384514,-600.848694,0.008101,0.004281,0.108732,290.844849,14.816342,1.087325,-600.848694,0.109652,0.000000
74.510002,66.620415,-600.893188,0.008106,0.004297,0.109149,296.342407,15.096402,1.091488,-600.893188,0.110068,0.000000
74.760002,67.222542,-600.893188,0.008114,0.004307,0.109409,299.020813,15.232845,1.094092,-600.893188,0.110484,0.000000
75.010002,67.089973,-600.893188,0.008114,0.004303,0.109288,298.431122,15.202805,1.092877,-600.893188,0.109539,0.000000
75.260002,66.453209,-600.893188,0.008132,0.004301,0.109235,295.598633,15.058513,1.092355,-600.893188,0.109288,0.000000
75.510002,65.909187,-600.893188,0.008123,0.004299,0.109201,293.178711,14.935235,1.092010,-600.893188,0.109288,0.000000
75.760002,65.450050,-600.893188,0.008127,0.004299,0.109192,291.136353,14.831194,1.091923,-600.893188,0.109288,0.000000
76.010002,65.012886,-600.893188,0.008140,0.004299,0.109184,289.191772,14.732131,1.091836,-600.893188,0.109288,0.000000
76.260002,64.632683,-600.937622,0.008140,0.004299,0.109184,287.500519,14.645975,1.091836,-600.937622,0.109288,0.000000
76.510002,64.297173,-600.937622,0.008136,0.004298,0.109175,286.008118,14.569948,1.091749,-600.937622,0.109288,0.000000
76.760002,63.960182,-600.848694,0.008149,0.004298,0.109175,284.509094,14.493585,1.091749,-600.848694,0.109288,0.000000
77.010002,63.693199,-600.937622,0.008140,0.004298,0.109175,283.321503,14.433085,1.091749,-600.937622,0.109288,0.000000
77.260002,63.419121,-600.893188,0.008149,0.004298,0.109175,282.102325,14.370978,1.091749,-600.893188,0.109288,0.000000
77.510002,63.187141,-600.982117,0.008153,0.004298,0.109175,281.070435,14.318411,1.091749,-600.982117,0.109288,0.000000
77.760002,62.959618,-600.893188,0.008132,0.004298,0.109166,280.058380,14.266853,1.091662,-600.893188,0.109288,0.000000
78.010002,62.746994,-600.937622,0.008136,0.004298,0.109166,279.112579,14.218672,1.091662,-600.937622,0.109288,0.000000
78.260002,62.549263,-600.937622,0.008157,0.004298,0.109166,278.233032,14.173865,1.091662,-600.937622,0.109288,0.000000
78.510002,62.367172,-600.982117,0.008157,0.004298,0.109166,277.423035,14.132604,1.091662,-600.982117,0.109288,0.000000
78.760002,62.204819,-600.982117,0.008140,0.004298,0.109166,276.700867,14.095813,1.091662,-600.982117,0.109288,0.000000
79.010002,62.036507,-601.026611,0.008144,0.004298,0.109166,275.952148,14.057673,1.091662,-601.026611,0.109288,0.000000
79.260002,61.872665,-600.982117,0.008140,0.004298,0.109166,275.223358,14.020547,1.091662,-600.982117,0.109288,0.000000
79.510002,61.741219,-600.982117,0.008140,0.004298,0.109166,274.638672,13.990761,1.091662,-600.982117,0.109288,0.000000
79.760002,61.617958,-601.026611,0.008153,0.004298,0.109166,274.090363,13.962829,1.091662,-601.026611,0.109288,0.000000
80.010002,61.464912,-601.026611,0.008153,0.004298,0.109166,273.409576,13.928148,1.091662,-601.026611,0.109288,0.000000
80.260002,61.353577,-601.026611,0.008162,0.004298,0.109166,272.914337,13.902920,1.091662,-601.026611,0.109288,0.000000
80.510002,61.235535,-601.026611,0.008144,0.004298,0.109166,272.389252,13.876170,1.091662,-601.026611,0.109288,0.000000
80.760002,61.124191,-601.071106,0.008149,0.004298,0.109166,271.893982,13.850940,1.091662,-601.071106,0.109288,0.000000
81.010002,61.028496,-601.071106,0.008153,0.004298,0.109166,271.468292,13.829255,1.091662,-601.071106,0.109288,0.000000
81.260002,60.907104,-601.071106,0.008162,0.004298,0.109166,270.928345,13.801747,1.091662,-601.071106,0.109288,0.000000
81.510002,60.823318,-600.982117,0.008144,0.004298,0.109166,270.555634,13.782762,1.091662,-600.982117,0.109288,0.000000
81.760002,60.717934,-601.026611,0.008157,0.004298,0.109166,270.086853,13.758881,1.091662,-601.026611,0.109288,0.000000
82.010002,60.626701,-601.071106,0.008153,0.004298,0.109166,269.681030,13.738208,1.091662,-601.071106,0.109288,0.000000
82.260002,60.552971,-601.071106,0.008166,0.004298,0.109166,269.353058,13.721499,1.091662,-601.071106,0.109288,0.000000
82.510002,60.447594,-601.026611,0.008157,0.004298,0.109166,268.884338,13.697620,1.091662,-601.026611,0.109288,0.000000
82.760002,60.383919,-601.026611,0.008166,0.004298,0.109166,268.601074,13.683191,1.091662,-601.026611,0.109288,0.000000
83.010002,60.279655,-601.071106,0.008170,0.004298,0.109166,268.137299,13.659566,1.091662,-601.071106,0.109288,0.000000
83.260002,60.209648,-601.026611,0.008157,0.004298,0.109166,267.825897,13.643701,1.091662,-601.026611,0.109288,0.000000
83.510002,60.109108,-601.071106,0.008162,0.004298,0.109166,267.378662,13.620918,1.091662,-601.071106,0.109288,0.000000
83.760002,60.036125,-601.160034,0.008166,0.004298,0.109166,267.054016,13.604381,1.091662,-601.160034,0.109288,0.000000
84.010002,59.974678,-601.160034,0.008153,0.004298,0.109166,266.780701,13.590456,1.091662,-601.160034,0.109288,0.000000
84.260002,59.894989,-601.071106,0.008170,0.004298,0.109158,266.426208,13.572398,1.091575,-601.071106,0.109288,0.000000
84.510002,59.836533,-601.160034,0.008175,0.004298,0.109158,266.166199,13.559152,1.091575,-601.160034,0.109288,0.000000
84.760002,59.770996,-601.160034,0.008157,0.004298,0.109158,265.874664,13.544301,1.091575,-601.160034,0.109288,0.000000
85.010002,59.680878,-601.160034,0.008157,0.004298,0.109158,265.473816,13.523881,1.091575,-601.160034,0.109288,0.000000
85.260002,59.658539,-601.160034,0.008162,0.004298,0.109158,265.374420,13.518818,1.091575,-601.160034,0.109288,0.000000
85.510002,59.587044,-601.071106,0.008157,0.004298,0.109158,265.056396,13.502617,1.091575,-601.071106,0.109288,0.000000
85.760002,59.539375,-601.160034,0.008166,0.004298,0.109158,264.844360,13.491816,1.091575,-601.160034,0.109288,0.000000
86.010002,59.480545,-601.115601,0.008166,0.004298,0.109158,264.582672,13.478484,1.091575,-601.115601,0.109288,0.000000
86.260002,59.417236,-601.115601,0.008170,0.004298,0.109158,264.301056,13.464138,1.091575,-601.115601,0.109288,0.000000
86.510002,59.395271,-601.160034,0.008157,0.004298,0.109158,264.203369,13.459161,1.091575,-601.160034,0.109288,0.000000
86.760002,59.319679,-601.115601,0.008166,0.004298,0.109158,263.867126,13.442031,1.091575,-601.115601,0.109288,0.000000
87.010002,59.275734,-601.115601,0.008170,0.004298,0.109158,263.671631,13.432074,1.091575,-601.115601,0.109288,0.000000
87.260002,59.216530,-601.204529,0.008162,0.004298,0.109158,263.408295,13.418657,1.091575,-601.204529,0.109288,0.000000
87.510002,59.164398,-601.160034,0.008166,0.004298,0.109158,263.176392,13.406844,1.091575,-601.160034,0.109288,0.000000
87.760002,59.139076,-601.204529,0.008170,0.004298,0.109158,263.063751,13.401106,1.091575,-601.204529,0.109288,0.000000
88.010002,59.073540,-601.204529,0.008157,0.004298,0.109158,262.772217,13.386255,1.091575,-601.204529,0.109288,0.000000
88.260002,59.022896,-601.160034,0.008162,0.004298,0.109158,262.546967,13.374780,1.091575,-601.160034,0.109288,0.000000
88.510002,58.987518,-601.204529,0.008166,0.004298,0.109158,262.389587,13.366762,1.091575,-601.204529,0.109288,0.000000
88.760002,58.933899,-601.249023,0.008166,0.004298,0.109158,262.151062,13.354612,1.091575,-601.249023,0.109288,0.000000
89.010002,58.910065,-601.249023,0.008157,0.004298,0.109158,262.045044,13.349212,1.091575,-601.249023,0.109288,0.000000
89.260002,58.839317,-601.160034,0.008157,0.004298,0.109158,261.730347,13.333180,1.091575,-601.160034,0.109288,0.000000
89.510002,58.809525,-601.160034,0.008157,0.004298,0.109158,261.597839,13.326428,1.091575,-601.160034,0.109288,0.000000
89.760002,58.781601,-601.249023,0.008157,0.004298,0.109158,261.473633,13.320101,1.091575,-601.249023,0.109288,0.000000
90.010002,58.731331,-601.293518,0.008175,0.004298,0.109158,261.250000,13.308709,1.091575,-601.293518,0.109288,0.000000
90.260002,58.701164,-601.249023,0.008166,0.004298,0.109158,261.115814,13.301874,1.091575,-601.249023,0.109288,0.000000
90.510002,58.649406,-601.249023,0.008166,0.004298,0.109158,260.885590,13.290146,1.091575,-601.249023,0.109288,0.000000
90.760002,58.628929,-601.249023,0.008170,0.004298,0.109158,260.794495,13.285505,1.091575,-601.249023,0.109288,0.000000
91.010002,58.599136,-601.249023,0.008170,0.004298,0.109158,260.661987,13.278754,1.091575,-601.249023,0.109288,0.000000
91.260002,58.544769,-601.293518,0.008157,0.004298,0.109158,260.420135,13.266434,1.091575,-601.293518,0.109288,0.000000
91.510002,58.525032,-601.293518,0.008170,0.004298,0.109158,260.332336,13.261962,1.091575,-601.293518,0.109288,0.000000
91.760002,58.465454,-601.293518,0.008170,0.004298,0.109158,260.067322,13.248462,1.091575,-601.293518,0.109288,0.000000
92.010002,58.453911,-601.293518,0.008149,0.004298,0.109158,260.015991,13.245846,1.091575,-601.293518,0.109288,0.000000
92.260002,58.402893,-601.293518,0.008175,0.004298,0.109158,259.789032,13.234284,1.091575,-601.293518,0.109288,0.000000
92.510002,58.385025,-601.337952,0.008166,0.004298,0.109158,259.709564,13.230235,1.091575,-601.337952,0.109288,0.000000
92.760002,58.369011,-601.337952,0.008162,0.004298,0.109158,259.638336,13.226607,1.091575,-601.337952,0.109288,0.000000
93.010002,58.321350,-601.337952,0.008166,0.004298,0.109158,259.426331,13.215807,1.091575,-601.337952,0.109288,0.000000
93.260002,58.309059,-601.337952,0.008153,0.004298,0.109158,259.371643,13.213022,1.091575,-601.337952,0.109288,0.000000
93.510002,58.270706,-601.337952,0.008170,0.004298,0.109158,259.201050,13.204330,1.091575,-601.337952,0.109288,0.000000
93.760002,58.232719,-601.382446,0.008166,0.004298,0.109158,259.032074,13.195724,1.091575,-601.382446,0.109288,0.000000
94.010002,58.214478,-601.337952,0.008170,0.004298,0.109158,258.950928,13.191588,1.091575,-601.337952,0.109288,0.000000
94.260002,58.182076,-601.337952,0.008157,0.004298,0.109158,258.806793,13.184247,1.091575,-601.337952,0.109288,0.000000
94.510002,58.163460,-601.382446,0.008157,0.004298,0.109158,258.723999,13.180028,1.091575,-601.382446,0.109288,0.000000
94.760002,58.140747,-601.382446,0.008170,0.004298,0.109158,258.622955,13.174882,1.091575,-601.382446,0.109288,0.000000
95.010002,58.100159,-601.337952,0.008179,0.004298,0.109158,258.442413,13.165685,1.091575,-601.337952,0.109288,0.000000
95.260002,58.089355,-601.382446,0.008153,0.004298,0.109158,258.394348,13.163236,1.091575,-601.382446,0.109288,0.000000
95.510002,58.048401,-601.337952,0.008162,0.004298,0.109158,258.212189,13.153956,1.091575,-601.337952,0.109288,0.000000
95.760002,58.037971,-601.382446,0.008170,0.004298,0.109158,258.165802,13.151592,1.091575,-601.382446,0.109288,0.000000
96.010002,58.010414,-601.382446,0.008175,0.004298,0.109158,258.043213,13.145348,1.091575,-601.382446,0.109288,0.000000
96.260002,57.984352,-601.426941,0.008162,0.004298,0.109158,257.927277,13.139442,1.091575,-601.426941,0.109288,0.000000
96.510002,57.968338,-601.382446,0.008153,0.004298,0.109158,257.856049,13.135813,1.091575,-601.382446,0.109288,0.000000
96.760002,57.926628,-601.426941,0.008170,0.004298,0.109158,257.670502,13.126362,1.091575,-601.426941,0.109288,0.000000
97.010002,57.928490,-601.426941,0.008175,0.004298,0.109158,257.678802,13.126783,1.091575,-601.426941,0.109288,0.000000
97.260002,57.889023,-601.426941,0.008175,0.004298,0.109158,257.503235,13.117841,1.091575,-601.426941,0.109288,0.000000
97.510002,57.867050,-601.471436,0.008157,0.004298,0.109158,257.405487,13.112861,1.091575,-601.471436,0.109288,0.000000
97.760002,57.858116,-601.426941,0.008162,0.004298,0.109158,257.365753,13.110836,1.091575,-601.426941,0.109288,0.000000
98.010002,57.817902,-601.426941,0.008175,0.004298,0.109158,257.186859,13.101724,1.091575,-601.426941,0.109288,0.000000
98.260002,57.793694,-601.471436,0.008179,0.004298,0.109158,257.079193,13.096238,1.091575,-601.471436,0.109288,0.000000
98.510002,57.769119,-601.471436,0.008175,0.004298,0.109158,256.969879,13.090670,1.091575,-601.471436,0.109288,0.000000
98.760002,57.761299,-601.426941,0.008179,0.004298,0.109158,256.935089,13.088898,1.091575,-601.426941,0.109288,0.000000
99.010002,57.737839,-601.426941,0.008170,0.004298,0.109158,256.830719,13.083581,1.091575,-601.426941,0.109288,0.000000
99.260002,57.709908,-601.471436,0.008179,0.004298,0.109158,256.706482,13.077251,1.091575,-601.471436,0.109288,0.000000
99.510002,57.690544,-601.471436,0.008162,0.004298,0.109158,256.620361,13.072865,1.091575,-601.471436,0.109288,0.000000
99.760002,57.667458,-601.471436,0.008183,0.004298,0.109158,256.517670,13.067632,1.091575,-601.471436,0.109288,0.000000
100.010002,57.656662,-601.471436,0.008179,0.004298,0.109158,256.469635,13.065187,1.091575,-601.471436,0.109288,0.000000
100.260002,57.629478,-601.560364,0.008170,0.004298,0.109158,256.348724,13.059027,1.091575,-601.560364,0.109288,0.000000
100.510002,57.592239,-601.515930,0.008166,0.004298,0.109158,256.183075,13.050589,1.091575,-601.515930,0.109288,0.000000
100.760002,57.590752,-601.560364,0.008175,0.004298,0.109158,256.176453,13.050251,1.091575,-601.560364,0.109288,0.000000
101.010002,57.556122,-601.471436,0.008157,0.004298,0.109158,256.022430,13.042403,1.091575,-601.471436,0.109288,0.000000
101.260002,57.543457,-601.560364,0.008157,0.004298,0.109158,255.966080,13.039534,1.091575,-601.560364,0.109288,0.000000
101.510002,57.523727,-601.560364,0.008166,0.004298,0.109158,255.878326,13.035064,1.091575,-601.560364,0.109288,0.000000
101.760002,57.497658,-601.560364,0.008157,0.004298,0.109158,255.762360,13.029155,1.091575,-601.560364,0.109288,0.000000
102.010002,57.488350,-601.515930,0.008170,0.004298,0.109158,255.720947,13.027046,1.091575,-601.515930,0.109288,0.000000
102.260002,57.451111,-601.560364,0.008175,0.004298,0.109158,255.555298,13.018608,1.091575,-601.560364,0.109288,0.000000
102.510002,57.439568,-601.560364,0.008179,0.004298,0.109158,255.503952,13.015992,1.091575,-601.560364,0.109288,0.000000
102.760002,57.433609,-601.560364,0.008157,0.004298,0.109158,255.477448,13.014642,1.091575,-601.560364,0.109288,0.000000
103.010002,57.386688,-601.560364,0.008170,0.004298,0.109158,255.268738,13.004010,1.091575,-601.560364,0.109288,0.000000
103.260002,57.392647,-601.604858,0.008170,0.004298,0.109158,255.295242,13.005360,1.091575,-601.604858,0.109288,0.000000
103.510002,57.338654,-601.560364,0.008166,0.004298,0.109158,255.055069,12.993125,1.091575,-601.560364,0.109288,0.000000
103.760002,57.340515,-601.560364,0.008183,0.004298,0.109158,255.063354,12.993546,1.091575,-601.560364,0.109288,0.000000
104.010002,57.318176,-601.604858,0.008157,0.004298,0.109158,254.963989,12.988484,1.091575,-601.604858,0.109288,0.000000
104.260002,57.285408,-601.649353,0.008170,0.004298,0.109158,254.818222,12.981058,1.091575,-601.649353,0.109288,0.000000
104.510002,57.288010,-601.649353,0.008179,0.004298,0.109158,254.829788,12.981648,1.091575,-601.649353,0.109288,0.000000
104.760002,57.234016,-601.649353,0.008170,0.004298,0.109158,254.589615,12.969414,1.091575,-601.649353,0.109288,0.000000
105.010002,57.238861,-601.649353,0.008170,0.004298,0.109158,254.611176,12.970511,1.091575,-601.649353,0.109288,0.000000
105.260002,57.215775,-601.649353,0.008170,0.004298,0.109158,254.508469,12.965280,1.091575,-601.649353,0.109288,0.000000
105.300003,57.193802,-601.649353,0.008170,0.004298,0.109158,254.410736,12.960300,1.091575,-601.649353,0.109288,0.000000