File: Data/compression 7/AutoHeating-12-7-2-4-240320_03202024_205221.csv
Time (sec),S:Load (lbs),S:HL1 (DIM),S:LVDT (in),S:Position (in),Ch:Position (mm),Ch:Load (N),Ch:Stress (MPa),Ch:Strain (mm/mm),Ch:HL1 (DIM),Set Point (),Cycles ()
0.010000,0.013405,-606.230896,0.000000,-0.000000,-0.000000,0.059628,0.003038,-0.000000,-606.230896,0.000199,0.000000
0.260000,-0.001862,-606.319824,0.000013,-0.000000,-0.000000,-0.008281,-0.000422,-0.000000,-606.319824,0.000199,0.000000
0.510000,-0.000748,-606.275391,0.000004,0.000082,0.002073,-0.003326,-0.000169,0.020726,-606.275391,0.002766,0.000000
0.760000,-0.017502,-606.230896,0.000099,0.000231,0.005871,-0.077852,-0.003966,0.058711,-606.230896,0.006946,0.000000
1.010000,-0.004471,-606.275391,0.000263,0.000394,0.009999,-0.019887,-0.001013,0.099989,-606.275391,0.011109,0.000000
1.260000,-0.016762,-606.319824,0.000418,0.000555,0.014092,-0.074560,-0.003798,0.140923,-606.319824,0.015272,0.000000
1.510000,-0.058090,-606.319824,0.000599,0.000723,0.018376,-0.258398,-0.013163,0.183764,-606.319824,0.019434,0.000000
1.760000,-0.003349,-606.364319,0.000746,0.000886,0.022513,-0.014898,-0.000759,0.225129,-606.364319,0.023597,0.000000
2.010000,0.037605,-606.275391,0.000931,0.001044,0.026511,0.167277,0.008521,0.265109,-606.275391,0.027760,0.000000
2.260000,0.017128,-606.408813,0.001095,0.001215,0.030873,0.076189,0.003881,0.308730,-606.408813,0.031923,0.000000
2.510000,0.016014,-606.364319,0.001259,0.001380,0.035044,0.071234,0.003629,0.350443,-606.364319,0.036103,0.000000
2.760000,0.020477,-606.364319,0.001414,0.001536,0.039016,0.091088,0.004640,0.390162,-606.364319,0.040265,0.000000
3.010000,-0.001488,-606.364319,0.001587,0.001710,0.043439,-0.006618,-0.000337,0.434392,-606.364319,0.044428,0.000000
3.260000,-0.050644,-606.364319,0.001755,0.001873,0.047567,-0.225275,-0.011476,0.475670,-606.364319,0.048590,0.000000
3.510000,0.000740,-606.364319,0.001927,0.002033,0.051626,0.003292,0.000168,0.516260,-606.364319,0.052753,0.000000
3.760000,0.028671,-606.408813,0.002074,0.002194,0.055719,0.127536,0.006497,0.557190,-606.408813,0.056916,0.000000
4.010000,0.000374,-606.408813,0.002264,0.002366,0.060090,0.001663,0.000085,0.600897,-606.408813,0.061078,0.000000
4.260000,0.007820,-606.408813,0.002414,0.002527,0.064183,0.034786,0.001772,0.641831,-606.408813,0.065241,0.000000
4.510000,0.035004,-606.408813,0.002587,0.002682,0.068121,0.155704,0.007932,0.681205,-606.408813,0.069421,0.000000
4.760000,0.031281,-606.408813,0.002759,0.002853,0.072465,0.139143,0.007088,0.724652,-606.408813,0.073584,0.000000
5.010000,-0.000000,-606.364319,0.002923,0.003017,0.076637,-0.000000,-0.000000,0.766366,-606.364319,0.077747,0.000000
5.260000,0.022713,-606.408813,0.003083,0.003181,0.080790,0.101031,0.005147,0.807905,-606.408813,0.081909,0.000000
5.510000,0.010056,-606.364319,0.003242,0.003342,0.084884,0.044729,0.002279,0.848838,-606.364319,0.086072,0.000000
5.760000,-0.024582,-606.453308,0.003406,0.003514,0.089263,-0.109346,-0.005570,0.892633,-606.453308,0.090235,0.000000
6.010000,0.008934,-606.364319,0.003570,0.003673,0.093296,0.039741,0.002024,0.932961,-606.364319,0.094397,0.000000
6.260000,0.044312,-606.408813,0.003738,0.003836,0.097424,0.197107,0.010041,0.974240,-606.408813,0.098560,0.000000
6.510000,0.041328,-606.497742,0.003923,0.004004,0.101699,0.183838,0.009365,1.016994,-606.497742,0.102740,0.000000
6.760000,0.025696,-606.497742,0.004074,0.004163,0.105749,0.114301,0.005823,1.057492,-606.497742,0.106903,0.000000
7.010000,0.024200,-606.497742,0.004247,0.004328,0.109921,0.107649,0.005484,1.099205,-606.497742,0.111065,0.000000
7.260000,0.019363,-606.453308,0.004406,0.004491,0.114084,0.086133,0.004388,1.140836,-606.453308,0.115228,0.000000
7.510000,0.016754,-606.497742,0.004562,0.004659,0.118342,0.074526,0.003797,1.183416,-606.497742,0.119391,0.000000
7.760000,0.738037,-606.453308,0.004730,0.004816,0.122322,3.282953,0.167242,1.223221,-606.453308,0.123432,0.000000
8.010000,0.574944,-606.497742,0.004738,-0.000000,-0.000000,2.557477,0.130284,-0.000000,-606.497742,0.000217,0.000000
8.260000,0.535095,-606.453308,0.004721,-0.000000,-0.000009,2.380222,0.121254,-0.000087,-606.453308,0.000217,0.000000
8.510000,0.607338,-606.497742,0.004743,-0.000000,-0.000000,2.701574,0.137625,-0.000000,-606.497742,0.000616,0.000000
8.760000,0.571587,-606.497742,0.004743,-0.000000,-0.000000,2.542544,0.129523,-0.000000,-606.497742,0.001032,0.000000
9.010000,0.828903,-606.497742,0.004751,0.000022,0.000555,3.687145,0.187832,0.005552,-606.497742,0.001448,0.000000
9.260000,0.991623,-606.497742,0.004747,0.000038,0.000963,4.410959,0.224705,0.009629,-606.497742,0.001864,0.000000
9.510000,1.137222,-606.497742,0.004773,0.000056,0.001431,5.058618,0.257698,0.014311,-606.497742,0.002281,0.000000
9.760000,1.316704,-606.497742,0.004799,0.000077,0.001951,5.856991,0.298369,0.019515,-606.497742,0.002697,0.000000
10.010000,1.419113,-606.497742,0.004799,0.000093,0.002359,6.312531,0.321576,0.023591,-606.497742,0.003113,0.000000
10.260000,1.493210,-606.542236,0.004820,0.000106,0.002697,6.642129,0.338366,0.026971,-606.542236,0.003530,0.000000
10.510000,1.682007,-606.542236,0.004855,0.000124,0.003148,7.481940,0.381148,0.031483,-606.542236,0.003946,0.000000
10.760000,1.841751,-606.497742,0.004842,0.000138,0.003504,8.192518,0.417347,0.035037,-606.497742,0.004371,0.000000
11.010000,2.026825,-606.586731,0.004872,0.000152,0.003859,9.015768,0.459285,0.038591,-606.586731,0.004787,0.000000
11.260000,2.154915,-606.542236,0.004872,0.000165,0.004189,9.585540,0.488311,0.041887,-606.542236,0.005203,0.000000
11.510000,2.393234,-606.586731,0.004894,0.000186,0.004735,10.645638,0.542315,0.047353,-606.586731,0.005620,0.000000
11.760000,2.539948,-606.542236,0.004902,0.000207,0.005247,11.298251,0.575560,0.052466,-606.542236,0.006036,0.000000
12.010000,2.682945,-606.542236,0.004932,0.000224,0.005680,11.934337,0.607964,0.056804,-606.542236,0.006452,0.000000
12.260000,2.841942,-606.631226,0.004928,0.000240,0.006097,12.641588,0.643993,0.060967,-606.631226,0.006868,0.000000
12.510000,2.900780,-606.586731,0.004945,0.000251,0.006383,12.903313,0.657326,0.063828,-606.586731,0.007285,0.000000
12.760000,3.128670,-606.586731,0.004963,0.000270,0.006860,13.917018,0.708967,0.068597,-606.586731,0.007701,0.000000
13.010000,3.305550,-606.542236,0.004971,0.000286,0.007276,14.703819,0.749048,0.072761,-606.542236,0.008117,0.000000
13.260000,3.264587,-606.542236,0.004984,0.000292,0.007406,14.521610,0.739766,0.074063,-606.542236,0.008533,0.000000
13.510000,3.590416,-606.586731,0.005006,0.000314,0.007987,15.970968,0.813600,0.079873,-606.586731,0.008950,0.000000
13.760000,3.795593,-606.631226,0.005023,0.000336,0.008533,16.883642,0.860094,0.085334,-606.631226,0.009366,0.000000
14.010000,3.903954,-606.586731,0.005036,0.000354,0.008985,17.365652,0.884649,0.089846,-606.586731,0.009782,0.000000
14.260000,4.020500,-606.631226,0.005057,0.000368,0.009357,17.884077,0.911058,0.093574,-606.631226,0.010199,0.000000
14.510000,4.135193,-606.586731,0.005062,0.000381,0.009687,18.394257,0.937048,0.096871,-606.586731,0.010615,0.000000
14.760000,4.388779,-606.631226,0.005083,0.000402,0.010199,19.522263,0.994511,0.101988,-606.631226,0.011031,0.000000
15.010001,4.465118,-606.631226,0.005101,0.000414,0.010528,19.861839,1.011810,0.105281,-606.631226,0.011447,0.000000
15.260001,4.624863,-606.631226,0.005109,0.000431,0.010944,20.572416,1.048009,0.109444,-606.631226,0.011864,0.000000
15.510001,4.895950,-606.631226,0.005139,0.000453,0.011508,21.778275,1.109438,0.115084,-606.631226,0.012280,0.000000
15.760001,4.956276,-606.675720,0.005144,0.000468,0.011899,22.046616,1.123108,0.118986,-606.675720,0.012696,0.000000
16.010000,4.993889,-606.675720,0.005148,0.000483,0.012271,22.213926,1.131631,0.122714,-606.675720,0.013121,0.000000
16.260000,5.175232,-606.631226,0.005152,0.000498,0.012662,23.020582,1.172724,0.126616,-606.631226,0.013537,0.000000
16.510000,5.442970,-606.675720,0.005200,0.000519,0.013191,24.211540,1.233395,0.131907,-606.675720,0.013954,0.000000
16.760000,5.538292,-606.720154,0.005204,0.000535,0.013581,24.635553,1.254995,0.135810,-606.720154,0.014370,0.000000
17.010000,5.463448,-606.675720,0.005217,0.000543,0.013789,24.302629,1.238035,0.137891,-606.675720,0.014786,0.000000
17.260000,5.857414,-606.675720,0.005234,0.000565,0.014353,26.055080,1.327309,0.143527,-606.675720,0.015202,0.000000
17.510000,6.013817,-606.675720,0.005251,0.000584,0.014830,26.750793,1.362750,0.148296,-606.675720,0.015619,0.000000
17.760000,5.983650,-606.720154,0.005260,0.000596,0.015142,26.616606,1.355914,0.151419,-606.720154,0.016035,0.000000
18.010000,6.156807,-606.675720,0.005282,0.000613,0.015558,27.386845,1.395152,0.155582,-606.675720,0.016451,0.000000
18.260000,6.242447,-606.720154,0.005295,0.000626,0.015896,27.767790,1.414559,0.158962,-606.720154,0.016868,0.000000
18.510000,6.420441,-606.764648,0.005299,0.000643,0.016339,28.559547,1.454893,0.163386,-606.764648,0.017284,0.000000
18.760000,6.517258,-606.720154,0.005312,0.000659,0.016729,28.990210,1.476832,0.167289,-606.720154,0.017700,0.000000
19.010000,6.472946,-606.720154,0.005338,0.000670,0.017015,28.793102,1.466791,0.170150,-606.720154,0.018116,0.000000
19.260000,6.881439,-606.720154,0.005329,0.000694,0.017622,30.610170,1.559356,0.176221,-606.720154,0.018533,0.000000
19.510000,7.119385,-606.809143,0.005351,0.000713,0.018099,31.668606,1.613276,0.180990,-606.809143,0.018949,0.000000
19.760000,7.145081,-606.764648,0.005372,0.000729,0.018515,31.782906,1.619098,0.185153,-606.764648,0.019365,0.000000
20.010000,7.187904,-606.764648,0.005385,0.000744,0.018897,31.973396,1.628802,0.188968,-606.764648,0.019781,0.000000
20.260000,7.253815,-606.764648,0.005398,0.000760,0.019313,32.266579,1.643738,0.193132,-606.764648,0.020198,0.000000
20.510000,7.463829,-606.720154,0.005420,0.000779,0.019790,33.200771,1.691328,0.197901,-606.720154,0.020614,0.000000
20.760000,7.495483,-606.809143,0.005433,0.000793,0.020137,33.341576,1.698501,0.201372,-606.809143,0.021030,0.000000
21.010000,7.530113,-606.764648,0.005433,0.000806,0.020466,33.495617,1.706348,0.204664,-606.764648,0.021455,0.000000
21.260000,7.795616,-606.809143,0.005450,0.000825,0.020952,34.676632,1.766512,0.209524,-606.809143,0.021871,0.000000
21.510000,7.948288,-606.809143,0.005480,0.000842,0.021386,35.355751,1.801108,0.213858,-606.809143,0.022288,0.000000
21.760000,7.982544,-606.809143,0.005489,0.000857,0.021759,35.508129,1.808870,0.217586,-606.809143,0.022704,0.000000
22.010000,8.131126,-606.809143,0.005497,0.000875,0.022227,36.169056,1.842540,0.222272,-606.809143,0.023120,0.000000
22.260000,8.058884,-606.853638,0.005497,0.000888,0.022565,35.847706,1.826169,0.225652,-606.853638,0.023537,0.000000
22.510000,8.271881,-606.853638,0.005519,0.000907,0.023034,36.795166,1.874435,0.230337,-606.853638,0.023953,0.000000
22.760000,8.251396,-606.764648,0.005532,0.000919,0.023337,36.704044,1.869793,0.233373,-606.764648,0.024369,0.000000
23.010000,8.401840,-606.809143,0.005536,0.000935,0.023745,37.373253,1.903884,0.237449,-606.809143,0.024785,0.000000
23.260000,8.921669,-606.853638,0.005558,0.000963,0.024456,39.685566,2.021679,0.244557,-606.853638,0.025202,0.000000
23.510000,8.741440,-606.853638,0.005566,0.000975,0.024759,38.883865,1.980839,0.247593,-606.853638,0.025618,0.000000
23.760000,8.729156,-606.853638,0.005596,0.000989,0.025124,38.829227,1.978055,0.251238,-606.853638,0.026034,0.000000
24.010000,8.767509,-606.809143,0.005596,0.001005,0.025531,38.999828,1.986746,0.255314,-606.809143,0.026450,0.000000
24.260000,8.884804,-606.853638,0.005609,0.001021,0.025939,39.521580,2.013325,0.259386,-606.853638,0.026867,0.000000
24.510000,9.021095,-606.853638,0.005614,0.001037,0.026338,40.127834,2.044209,0.263376,-606.853638,0.027283,0.000000
24.760000,9.109718,-606.853638,0.005635,0.001053,0.026745,40.522053,2.064292,0.267452,-606.853638,0.027699,0.000000
25.010002,9.091103,-606.853638,0.005648,0.001065,0.027040,40.439243,2.060073,0.270400,-606.853638,0.028116,0.000000
25.260002,9.651894,-606.853638,0.005661,0.001093,0.027769,42.933765,2.187150,0.277686,-606.853638,0.028532,0.000000
25.510002,9.471664,-606.853638,0.005670,0.001104,0.028046,42.132069,2.146310,0.280461,-606.853638,0.028948,0.000000
25.760002,9.409851,-606.853638,0.005678,0.001120,0.028436,41.857109,2.132303,0.284363,-606.853638,0.029364,0.000000
26.010002,9.371498,-606.898071,0.005687,0.001131,0.028740,41.686504,2.123612,0.287398,-606.898071,0.029789,0.000000
26.260002,9.736046,-606.853638,0.005713,0.001154,0.029304,43.308094,2.206219,0.293038,-606.853638,0.030206,0.000000
26.510002,9.890587,-606.898071,0.005721,0.001170,0.029720,43.995529,2.241239,0.297198,-606.898071,0.030622,0.000000
26.760002,9.688011,-606.853638,0.005721,0.001179,0.029937,43.094425,2.195335,0.299366,-606.853638,0.031038,0.000000
27.010002,10.219391,-606.898071,0.005721,0.001206,0.030622,45.458122,2.315747,0.306217,-606.898071,0.031454,0.000000
27.260002,10.274124,-606.853638,0.005760,0.001223,0.031055,45.701588,2.328150,0.310554,-606.853638,0.031871,0.000000
27.510002,10.286041,-606.898071,0.005764,0.001239,0.031463,45.754597,2.330850,0.314631,-606.898071,0.032287,0.000000
27.760002,10.228325,-606.942566,0.005782,0.001254,0.031853,45.497860,2.317772,0.318533,-606.942566,0.032703,0.000000
28.010002,10.212685,-606.942566,0.005786,0.001268,0.032200,45.428291,2.314227,0.322000,-606.942566,0.033119,0.000000
28.260002,10.478935,-606.898071,0.005799,0.001285,0.032642,46.612633,2.374561,0.326424,-606.898071,0.033536,0.000000
28.510002,10.509094,-606.942566,0.005816,0.001299,0.033007,46.746784,2.381395,0.330066,-606.942566,0.033952,0.000000
28.760002,10.506859,-606.898071,0.005825,0.001313,0.033362,46.736843,2.380888,0.333623,-606.898071,0.034368,0.000000
29.010002,10.832314,-606.898071,0.005838,0.001333,0.033865,48.184536,2.454637,0.338653,-606.898071,0.034785,0.000000
29.260002,11.076965,-606.987061,0.005838,0.001355,0.034420,49.272804,2.510076,0.344202,-606.987061,0.035201,0.000000
29.510002,10.883331,-606.898071,0.005859,0.001367,0.034715,48.411476,2.466198,0.347151,-606.898071,0.035617,0.000000
29.760002,10.990570,-606.942566,0.005859,0.001384,0.035149,48.888496,2.490499,0.351488,-606.942566,0.036033,0.000000
30.010002,10.875877,-606.942566,0.005877,0.001396,0.035470,48.378319,2.464509,0.354698,-606.942566,0.036450,0.000000
30.260002,11.189415,-606.987061,0.005877,0.001416,0.035955,49.773003,2.535558,0.359554,-606.987061,0.036866,0.000000
30.510002,11.168938,-606.987061,0.005902,0.001430,0.036328,49.681915,2.530918,0.363282,-606.987061,0.037282,0.000000
30.760002,11.209526,-606.942566,0.005924,0.001443,0.036658,49.862461,2.540115,0.366578,-606.942566,0.037698,0.000000
31.010002,11.678345,-606.987061,0.005907,0.001469,0.037317,51.947872,2.646351,0.373168,-606.987061,0.038115,0.000000
31.260002,11.737549,-606.987061,0.005933,0.001486,0.037733,52.211224,2.659767,0.377331,-606.987061,0.038540,0.000000
31.510002,11.661591,-606.987061,0.005959,0.001501,0.038123,51.873344,2.642554,0.381234,-606.987061,0.038956,0.000000
31.760002,11.681694,-606.987061,0.005963,0.001517,0.038531,51.962769,2.647110,0.385310,-606.987061,0.039372,0.000000
32.010002,11.613182,-606.987061,0.005967,0.001531,0.038886,51.658012,2.631585,0.388864,-606.987061,0.039788,0.000000
32.260002,11.784096,-607.031555,0.005971,0.001547,0.039294,52.418278,2.670314,0.392940,-607.031555,0.040205,0.000000
32.510002,11.813889,-606.987061,0.005984,0.001561,0.039641,52.550800,2.677065,0.396411,-606.987061,0.040621,0.000000
32.760002,12.165031,-606.987061,0.005997,0.001581,0.040170,54.112762,2.756635,0.401698,-606.987061,0.041037,0.000000
33.010002,12.443939,-606.942566,0.006019,0.001601,0.040673,55.353405,2.819837,0.406729,-606.942566,0.041453,0.000000
33.260002,12.259621,-606.987061,0.006010,0.001615,0.041029,54.533516,2.778070,0.410286,-606.987061,0.041870,0.000000
33.510002,12.270790,-607.031555,0.006032,0.001630,0.041393,54.583199,2.780601,0.413927,-607.031555,0.042286,0.000000
33.760002,12.281212,-607.076050,0.006040,0.001646,0.041818,54.629559,2.782963,0.418178,-607.076050,0.042702,0.000000
34.010002,12.491608,-607.076050,0.006045,0.001663,0.042243,55.565445,2.830639,0.422428,-607.076050,0.043119,0.000000
34.260002,12.661407,-607.076050,0.006058,0.001682,0.042728,56.320755,2.869116,0.427284,-607.076050,0.043535,0.000000
34.510002,12.381012,-607.031555,0.006062,0.001690,0.042919,55.073490,2.805577,0.429192,-607.031555,0.043951,0.000000
34.760002,12.735878,-607.031555,0.006079,0.001712,0.043491,56.652016,2.885991,0.434915,-607.031555,0.044367,0.000000
35.010002,13.060959,-607.031555,0.006092,0.001732,0.043986,58.098045,2.959656,0.439858,-607.031555,0.044784,0.000000
35.260002,12.980156,-607.120483,0.006092,0.001747,0.044385,57.738617,2.941345,0.443847,-607.120483,0.045200,0.000000
35.510002,12.924675,-607.076050,0.006118,0.001763,0.044775,57.491825,2.928773,0.447749,-607.076050,0.045616,0.000000
35.760002,12.923187,-607.031555,0.006122,0.001776,0.045105,57.485207,2.928436,0.451046,-607.031555,0.046032,0.000000
36.010002,13.189804,-607.120483,0.006118,0.001795,0.045599,58.671177,2.988853,0.455989,-607.120483,0.046449,0.000000
36.260002,13.213264,-607.076050,0.006140,0.001811,0.045998,58.775536,2.994169,0.459978,-607.076050,0.046874,0.000000
36.510002,13.167458,-607.164978,0.006144,0.001826,0.046379,58.571777,2.983788,0.463793,-607.164978,0.047290,0.000000
36.760002,13.427376,-607.120483,0.006165,0.001844,0.046839,59.727951,3.042687,0.468388,-607.120483,0.047706,0.000000
37.010002,13.500359,-607.120483,0.006170,0.001861,0.047281,60.052593,3.059225,0.472813,-607.120483,0.048122,0.000000
37.260002,13.471313,-607.120483,0.006187,0.001877,0.047680,59.923393,3.052643,0.476802,-607.120483,0.048539,0.000000
37.510002,13.374870,-607.164978,0.006191,0.001890,0.048001,59.494396,3.030789,0.480012,-607.164978,0.048955,0.000000
37.760002,13.476158,-607.164978,0.006196,0.001911,0.048530,59.944946,3.053741,0.485299,-607.164978,0.049371,0.000000
38.010002,13.730492,-607.164978,0.006204,0.001928,0.048964,61.076279,3.111374,0.489637,-607.164978,0.049788,0.000000
38.260002,13.481369,-607.120483,0.006226,0.001938,0.049224,59.968124,3.054922,0.492237,-607.120483,0.050204,0.000000
38.510002,13.584892,-607.164978,0.006217,0.001953,0.049614,60.428619,3.078381,0.496139,-607.164978,0.050620,0.000000
38.760002,14.109940,-607.164978,0.006234,0.001978,0.050247,62.764145,3.197358,0.502471,-607.164978,0.051036,0.000000
39.010002,13.860443,-607.164978,0.006252,0.001991,0.050559,61.654331,3.140821,0.505594,-607.164978,0.051453,0.000000
39.260002,13.630692,-607.209473,0.006247,0.002003,0.050880,60.632343,3.088759,0.508803,-607.209473,0.051869,0.000000
39.510002,13.930824,-607.164978,0.006269,0.002023,0.051392,61.967400,3.156770,0.513921,-607.164978,0.052285,0.000000
39.760002,14.038071,-607.209473,0.006256,0.002039,0.051791,62.444458,3.181072,0.517910,-607.209473,0.052701,0.000000
40.010002,14.048866,-607.164978,0.006265,0.002054,0.052173,62.492477,3.183519,0.521725,-607.164978,0.053118,0.000000
40.260002,13.790810,-607.164978,0.006282,0.002065,0.052459,61.344585,3.125042,0.524586,-607.164978,0.053534,0.000000
40.510002,14.035835,-607.209473,0.006282,0.002082,0.052884,62.434513,3.180566,0.528837,-607.209473,0.053950,0.000000
40.760002,14.518799,-607.209473,0.006303,0.002106,0.053490,64.582840,3.290007,0.534904,-607.209473,0.054367,0.000000
41.010002,14.421242,-607.209473,0.006321,0.002124,0.053942,64.148888,3.267900,0.539416,-607.209473,0.054783,0.000000
41.260002,14.337082,-607.209473,0.006303,0.002139,0.054340,63.774525,3.248829,0.543405,-607.209473,0.055208,0.000000
41.510002,14.161324,-607.209473,0.006303,0.002153,0.054678,62.992714,3.209002,0.546785,-607.209473,0.055624,0.000000
41.760002,14.440971,-607.253967,0.006316,0.002172,0.055173,64.236649,3.272371,0.551732,-607.253967,0.056040,0.000000
42.010002,14.287186,-607.298401,0.006342,0.002187,0.055555,63.552574,3.237523,0.555547,-607.298401,0.056457,0.000000
42.260002,14.204147,-607.209473,0.006342,0.002201,0.055910,63.183205,3.218706,0.559101,-607.209473,0.056873,0.000000
42.510002,14.276016,-607.253967,0.006359,0.002219,0.056361,63.502892,3.234992,0.563613,-607.253967,0.057289,0.000000
42.760002,14.559013,-607.253967,0.006355,0.002238,0.056838,64.761726,3.299120,0.568381,-607.253967,0.057705,0.000000
43.010002,14.541519,-607.253967,0.006368,0.002252,0.057211,64.683907,3.295155,0.572110,-607.253967,0.058122,0.000000
43.260002,14.449913,-607.298401,0.006372,0.002270,0.057653,64.276421,3.274397,0.576534,-607.298401,0.058538,0.000000
43.510002,14.360168,-607.209473,0.006372,0.002283,0.058000,63.877220,3.254061,0.580001,-607.209473,0.058954,0.000000
43.760002,14.580246,-607.298401,0.006390,0.002302,0.058460,64.856171,3.303931,0.584596,-607.298401,0.059370,0.000000
44.010002,14.301704,-607.253967,0.006390,0.002315,0.058789,63.617157,3.240813,0.587893,-607.253967,0.059787,0.000000
44.260002,14.136749,-607.298401,0.006403,0.002326,0.059075,62.883400,3.203433,0.590754,-607.298401,0.060203,0.000000
44.510002,15.133591,-607.342896,0.006398,0.002356,0.059839,67.317574,3.429321,0.598388,-607.342896,0.060619,0.000000
44.760002,14.872925,-607.298401,0.006416,0.002371,0.060229,66.158073,3.370253,0.602290,-607.298401,0.061036,0.000000
45.010002,14.448792,-607.342896,0.006424,0.002385,0.060584,64.271431,3.274143,0.605844,-607.342896,0.061452,0.000000
45.260002,14.302826,-607.342896,0.006437,0.002399,0.060932,63.622147,3.241066,0.609315,-607.342896,0.061868,0.000000
45.510002,14.224251,-607.342896,0.006428,0.002413,0.061296,63.272629,3.223261,0.612956,-607.342896,0.062284,0.000000
45.760002,14.500183,-607.342896,0.006433,0.002432,0.061764,64.500038,3.285789,0.617638,-607.342896,0.062701,0.000000
46.010002,14.288300,-607.342896,0.006446,0.002444,0.062067,63.557529,3.237775,0.620674,-607.342896,0.063117,0.000000
46.260002,14.389214,-607.342896,0.006454,0.002459,0.062466,64.006416,3.260642,0.624663,-607.342896,0.063533,0.000000
46.510002,14.970863,-607.342896,0.006467,0.002485,0.063126,66.593727,3.392446,0.631256,-607.342896,0.063958,0.000000
46.760002,14.829735,-607.342896,0.006472,0.002501,0.063525,65.965958,3.360466,0.635245,-607.342896,0.064374,0.000000
47.010002,14.607422,-607.387390,0.006489,0.002516,0.063906,64.977058,3.310089,0.639061,-607.387390,0.064791,0.000000
47.260002,14.321815,-607.342896,0.006489,0.002529,0.064235,63.706615,3.245370,0.642353,-607.342896,0.065207,0.000000
47.510002,14.289795,-607.387390,0.006493,0.002544,0.064617,63.564182,3.238114,0.646172,-607.387390,0.065623,0.000000
47.760002,14.537422,-607.431885,0.006493,0.002561,0.065059,64.665680,3.294227,0.650593,-607.431885,0.066039,0.000000
48.010002,14.481194,-607.431885,0.006506,0.002576,0.065441,64.415565,3.281486,0.654408,-607.431885,0.066456,0.000000
48.260002,14.136749,-607.387390,0.006493,0.002589,0.065762,62.883400,3.203433,0.657618,-607.387390,0.066872,0.000000
48.510002,15.070656,-607.387390,0.006519,0.002615,0.066429,67.037628,3.415059,0.664294,-607.387390,0.067288,0.000000
48.760002,14.879257,-607.431885,0.006510,0.002633,0.066872,66.186241,3.371688,0.668719,-607.431885,0.067705,0.000000
49.010002,14.643173,-607.387390,0.006515,0.002646,0.067219,65.136086,3.318190,0.672186,-607.387390,0.068121,0.000000
49.260002,14.426826,-607.476318,0.006532,0.002660,0.067566,64.173729,3.269166,0.675657,-607.476318,0.068537,0.000000
49.510002,14.695305,-607.431885,0.006528,0.002680,0.068069,65.367981,3.330004,0.680687,-607.431885,0.068953,0.000000
49.760002,14.675194,-607.476318,0.006554,0.002695,0.068441,65.278519,3.325446,0.684415,-607.476318,0.069370,0.000000
50.010002,14.260750,-607.431885,0.006541,0.002703,0.068650,63.434982,3.231532,0.686497,-607.431885,0.069786,0.000000
50.260002,14.340805,-607.520813,0.006558,0.002718,0.069040,63.791088,3.249673,0.690399,-607.520813,0.070202,0.000000
50.510002,15.426643,-607.387390,0.006549,0.002749,0.069820,68.621140,3.495728,0.698203,-607.387390,0.070618,0.000000
50.760002,15.131729,-607.476318,0.006562,0.002764,0.070202,67.309296,3.428899,0.702019,-607.476318,0.071035,0.000000
51.010002,14.652107,-607.431885,0.006571,0.002776,0.070514,65.175827,3.320215,0.705141,-607.431885,0.071451,0.000000
51.260002,14.623062,-607.431885,0.006579,0.002790,0.070870,65.046631,3.313633,0.708699,-607.431885,0.071867,0.000000
51.510002,15.002510,-607.520813,0.006575,0.002808,0.071329,66.734497,3.399617,0.713294,-607.520813,0.072292,0.000000
51.760002,14.975700,-607.476318,0.006579,0.002823,0.071711,66.615242,3.393542,0.717109,-607.476318,0.072708,0.000000
52.010002,14.884842,-607.476318,0.006588,0.002837,0.072067,66.211082,3.372953,0.720667,-607.476318,0.073125,0.000000
52.260002,15.394997,-607.476318,0.006588,0.002859,0.072613,68.480362,3.488556,0.726128,-607.476318,0.073541,0.000000
52.510002,15.678741,-607.520813,0.006588,0.002880,0.073159,69.742523,3.552854,0.731594,-607.520813,0.073957,0.000000
52.760002,15.508568,-607.520813,0.006610,0.002896,0.073567,68.985558,3.514292,0.735670,-607.520813,0.074373,0.000000
53.010002,15.400581,-607.520813,0.006610,0.002912,0.073966,68.505211,3.489822,0.739659,-607.520813,0.074790,0.000000
53.260002,15.196518,-607.520813,0.006622,0.002925,0.074304,67.597488,3.443580,0.743039,-607.520813,0.075206,0.000000
53.510002,15.227051,-607.520813,0.006614,0.002940,0.074677,67.733307,3.450499,0.746767,-607.520813,0.075622,0.000000
53.760002,15.223328,-607.476318,0.006631,0.002953,0.075006,67.716743,3.449655,0.750064,-607.476318,0.076039,0.000000
54.010002,15.453827,-607.565308,0.006644,0.002969,0.075414,68.742058,3.501887,0.754140,-607.565308,0.076455,0.000000
54.260002,16.370239,-607.520813,0.006635,0.002997,0.076125,72.818459,3.709549,0.761252,-607.520813,0.076871,0.000000
54.510002,16.165428,-607.520813,0.006666,0.003011,0.076472,71.907417,3.663138,0.764719,-607.520813,0.077287,0.000000
54.760002,16.217934,-607.476318,0.006661,0.003027,0.076897,72.140968,3.675036,0.768970,-607.476318,0.077704,0.000000
55.010002,16.107338,-607.565308,0.006661,0.003041,0.077253,71.649017,3.649975,0.772527,-607.565308,0.078120,0.000000
55.260002,16.171387,-607.609802,0.006687,0.003057,0.077643,71.933922,3.664489,0.776430,-607.609802,0.078536,0.000000
55.510002,16.588821,-607.565308,0.006696,0.003076,0.078129,73.790764,3.759081,0.781286,-607.565308,0.078952,0.000000
55.760002,16.365395,-607.565308,0.006696,0.003086,0.078380,72.796913,3.708452,0.783799,-607.565308,0.079368,0.000000
56.010002,16.622704,-607.609802,0.006717,0.003104,0.078848,73.941475,3.766758,0.788481,-607.609802,0.079785,0.000000
56.260002,17.213661,-607.565308,0.006713,0.003124,0.079360,76.570190,3.900671,0.793598,-607.565308,0.080201,0.000000
56.510002,17.522728,-607.654297,0.006726,0.003143,0.079828,77.944984,3.970707,0.798284,-607.654297,0.080626,0.000000
56.760002,17.448257,-607.609802,0.006722,0.003156,0.080166,77.613724,3.953831,0.801663,-607.609802,0.081042,0.000000
57.010002,17.466873,-607.565308,0.006735,0.003172,0.080557,77.696533,3.958050,0.805566,-607.565308,0.081459,0.000000
57.260002,18.173264,-607.654297,0.006739,0.003191,0.081051,80.838715,4.118121,0.810509,-607.654297,0.081875,0.000000
57.510002,18.256676,-607.654297,0.006756,0.003204,0.081389,81.209747,4.137022,0.813892,-607.654297,0.082291,0.000000
57.760002,18.435783,-607.609802,0.006756,0.003219,0.081753,82.006462,4.177608,0.817534,-607.609802,0.082708,0.000000
58.010002,19.021904,-607.609802,0.006765,0.003238,0.082256,84.613655,4.310425,0.822564,-607.609802,0.083124,0.000000
58.260002,19.370811,-607.609802,0.006778,0.003255,0.082681,86.165672,4.389489,0.826814,-607.609802,0.083540,0.000000
58.510002,19.507477,-607.609802,0.006782,0.003271,0.083072,86.773590,4.420457,0.830716,-607.609802,0.083956,0.000000
58.760002,19.668709,-607.654297,0.006799,0.003286,0.083471,87.490784,4.456993,0.834706,-607.654297,0.084372,0.000000
59.010002,20.066780,-607.654297,0.006799,0.003302,0.083861,89.261497,4.547197,0.838608,-607.654297,0.084789,0.000000
59.260002,20.690498,-607.654297,0.006804,0.003322,0.084372,92.035934,4.688534,0.843725,-607.654297,0.085205,0.000000
59.510002,20.891586,-607.698730,0.006825,0.003336,0.084745,92.930420,4.734101,0.847453,-607.698730,0.085621,0.000000
59.760002,20.476761,-607.654297,0.006829,0.003342,0.084876,91.085182,4.640100,0.848755,-607.654297,0.086037,0.000000
60.010002,22.106262,-607.654297,0.006838,0.003373,0.085673,98.333565,5.009350,0.856734,-607.654297,0.086454,0.000000
60.260002,22.146103,-607.654297,0.006842,0.003385,0.085986,98.510788,5.018379,0.859856,-607.654297,0.086870,0.000000
60.510002,22.302872,-607.698730,0.006855,0.003400,0.086350,99.208130,5.053903,0.863497,-607.698730,0.087286,0.000000
60.760002,22.667053,-607.698730,0.006851,0.003414,0.086705,100.828087,5.136428,0.867051,-607.698730,0.087702,0.000000
61.010002,23.177948,-607.698730,0.006873,0.003431,0.087156,103.100662,5.252198,0.871563,-607.698730,0.088119,0.000000
61.260002,23.799065,-607.698730,0.006877,0.003448,0.087590,105.863525,5.392945,0.875900,-607.698730,0.088535,0.000000
61.510002,23.994560,-607.743225,0.006890,0.003463,0.087963,106.733131,5.437245,0.879629,-607.743225,0.088951,0.000000
61.760002,23.855293,-607.698730,0.006894,0.003472,0.088197,106.113647,5.405687,0.881968,-607.698730,0.089377,0.000000
62.010002,25.294884,-607.743225,0.006903,0.003499,0.088882,112.517265,5.731903,0.888822,-607.743225,0.089792,0.000000
62.260002,25.746201,-607.743225,0.006924,0.003515,0.089272,114.524818,5.834172,0.892724,-607.743225,0.090209,0.000000
62.510002,26.180389,-607.698730,0.006933,0.003531,0.089697,116.456192,5.932561,0.896971,-607.698730,0.090625,0.000000
62.760002,26.622765,-607.698730,0.006937,0.003546,0.090070,118.423973,6.032805,0.900703,-607.698730,0.091041,0.000000
63.010002,27.578278,-607.698730,0.006959,0.003567,0.090608,122.674309,6.249327,0.906077,-607.698730,0.091458,0.000000
63.260002,28.020653,-607.743225,0.006950,0.003583,0.090998,124.642090,6.349571,0.909980,-607.743225,0.091874,0.000000
63.510002,28.259720,-607.787720,0.006967,0.003597,0.091354,125.705513,6.403744,0.913537,-607.787720,0.092290,0.000000
63.760002,28.404572,-607.698730,0.006980,0.003609,0.091657,126.349846,6.436568,0.916573,-607.698730,0.092706,0.000000
64.010002,29.370880,-607.698730,0.006980,0.003627,0.092125,130.648193,6.655537,0.921255,-607.698730,0.093123,0.000000
64.260002,29.986038,-607.787720,0.006989,0.003645,0.092576,133.384567,6.794933,0.925763,-607.787720,0.093539,0.000000
64.510002,30.451500,-607.832214,0.006993,0.003660,0.092958,135.455032,6.900408,0.929582,-607.832214,0.093955,0.000000
64.760002,31.083046,-607.787720,0.007006,0.003675,0.093340,138.264297,7.043519,0.933397,-607.787720,0.094371,0.000000
65.010002,31.931313,-607.787720,0.007019,0.003693,0.093799,142.037567,7.235739,0.937992,-607.787720,0.094788,0.000000
65.260002,32.724464,-607.787720,0.007028,0.003711,0.094250,145.565689,7.415470,0.942503,-607.787720,0.095204,0.000000
65.510002,32.797073,-607.832214,0.007032,0.003722,0.094528,145.888672,7.431923,0.945278,-607.832214,0.095620,0.000000
65.760002,33.706039,-607.876648,0.007036,0.003740,0.095005,149.931946,7.637897,0.950046,-607.876648,0.096037,0.000000
66.010002,35.660248,-607.832214,0.007058,0.003767,0.095672,158.624710,8.080728,0.956723,-607.832214,0.096453,0.000000
66.260002,35.944366,-607.787720,0.007058,0.003778,0.095967,159.888535,8.145110,0.959671,-607.787720,0.096869,0.000000
66.510002,36.666771,-607.787720,0.007075,0.003795,0.096392,163.101944,8.308809,0.963922,-607.787720,0.097285,0.000000
66.760002,36.740875,-607.832214,0.007084,0.003808,0.096713,163.431580,8.325602,0.967131,-607.832214,0.097710,0.000000
67.010002,37.881447,-607.876648,0.007080,0.003826,0.097181,168.505096,8.584059,0.971813,-607.876648,0.098127,0.000000
67.260002,38.218445,-607.876648,0.007105,0.003838,0.097476,170.004135,8.660423,0.974762,-607.876648,0.098543,0.000000
67.510002,39.157944,-607.965637,0.007101,0.003853,0.097875,174.183228,8.873317,0.978751,-607.965637,0.098959,0.000000
67.760002,40.325333,-607.965637,0.007127,0.003875,0.098430,179.376038,9.137851,0.984304,-607.965637,0.099375,0.000000
68.010002,41.961533,-607.832214,0.007118,0.003896,0.098968,186.654221,9.508619,0.989678,-607.832214,0.099792,0.000000
68.260002,42.420296,-607.876648,0.007140,0.003910,0.099306,188.694901,9.612576,0.993062,-607.876648,0.100208,0.000000
68.510002,43.163925,-607.921143,0.007136,0.003924,0.099679,192.002731,9.781085,0.996790,-607.921143,0.100624,0.000000
68.760002,43.658806,-607.921143,0.007148,0.003937,0.100009,194.204071,9.893227,1.000087,-607.921143,0.101040,0.000000
69.010002,44.932693,-607.921143,0.007153,0.003957,0.100503,199.870605,10.181893,1.005030,-607.921143,0.101457,0.000000
69.260002,45.435028,-607.921143,0.007166,0.003969,0.100824,202.105103,10.295725,1.008239,-607.921143,0.101873,0.000000
69.510002,45.994331,-607.921143,0.007161,0.003981,0.101119,204.593002,10.422464,1.011188,-607.921143,0.102289,0.000000
69.760002,48.109032,-607.921143,0.007179,0.004010,0.101864,213.999664,10.901663,1.018644,-607.921143,0.102706,0.000000
70.010002,49.013153,-607.965637,0.007187,0.004024,0.102211,218.021393,11.106539,1.022115,-607.965637,0.103122,0.000000
70.260002,49.740768,-607.965637,0.007205,0.004038,0.102558,221.257996,11.271420,1.025582,-607.965637,0.103538,0.000000
70.510002,50.940178,-607.921143,0.007192,0.004057,0.103044,226.593231,11.543210,1.030438,-607.921143,0.103954,0.000000
70.760002,51.741150,-608.010132,0.007217,0.004072,0.103417,230.156128,11.724712,1.034166,-608.010132,0.104371,0.000000
71.010002,52.927162,-607.965637,0.007217,0.004089,0.103850,235.431778,11.993466,1.038503,-607.965637,0.104787,0.000000
71.260002,53.589607,-608.010132,0.007230,0.004101,0.104163,238.378479,12.143579,1.041626,-608.010132,0.105203,0.000000
71.510002,54.414040,-607.965637,0.007235,0.004115,0.104518,242.045731,12.330398,1.045180,-607.965637,0.105619,0.000000
71.760002,55.843948,-607.921143,0.007248,0.004136,0.105065,248.406296,12.654419,1.050645,-607.921143,0.106044,0.000000
72.010002,57.424301,-608.010132,0.007235,0.004156,0.105559,255.436050,13.012532,1.055588,-608.010132,0.106461,0.000000
72.260002,57.904663,-607.965637,0.007248,0.004166,0.105819,257.572815,13.121385,1.058189,-607.965637,0.106877,0.000000
72.510002,59.320419,-608.010132,0.007256,0.004185,0.106296,263.870392,13.442200,1.062961,-608.010132,0.107293,0.000000
72.760002,60.230125,-608.010132,0.007282,0.004200,0.106686,267.916992,13.648342,1.066864,-608.010132,0.107709,0.000000
73.010002,61.604179,-608.010132,0.007278,0.004218,0.107128,274.029083,13.959707,1.071284,-608.010132,0.108126,0.000000
73.260002,62.472183,-607.965637,0.007282,0.004231,0.107467,277.890137,14.156399,1.074668,-607.965637,0.108542,0.000000
73.510002,63.427322,-608.010132,0.007291,0.004246,0.107857,282.138824,14.372836,1.078570,-608.010132,0.108958,0.000000
73.760002,65.787415,-608.054626,0.007291,0.004271,0.108473,292.637024,14.907641,1.084728,-608.054626,0.109375,0.000000
74.010002,67.063538,-608.054626,0.007286,0.004288,0.108924,298.313507,15.196815,1.089236,-608.054626,0.109791,0.000000
74.260002,67.088486,-607.965637,0.007308,0.004284,0.108820,298.424500,15.202468,1.088195,-607.965637,0.109036,0.000000
74.510002,66.533279,-608.054626,0.007304,0.004284,0.108820,295.954803,15.076656,1.088195,-608.054626,0.108820,0.000000
74.760002,66.034668,-608.054626,0.007317,0.004284,0.108802,293.736877,14.963670,1.088021,-608.054626,0.108820,0.000000
75.010002,65.586700,-608.054626,0.007321,0.004283,0.108793,291.744202,14.862159,1.087934,-608.054626,0.108820,0.000000
75.260002,65.188263,-608.010132,0.007325,0.004283,0.108793,289.971863,14.771872,1.087934,-608.010132,0.108820,0.000000
75.510002,64.847549,-608.054626,0.007334,0.004283,0.108793,288.456299,14.694664,1.087934,-608.054626,0.108820,0.000000
75.760002,64.527679,-608.054626,0.007338,0.004283,0.108785,287.033447,14.622181,1.087851,-608.054626,0.108820,0.000000
76.010002,64.232758,-608.143555,0.007338,0.004283,0.108785,285.721588,14.555350,1.087851,-608.143555,0.108820,0.000000
76.260002,63.983643,-608.099060,0.007355,0.004283,0.108785,284.613464,14.498901,1.087851,-608.099060,0.108820,0.000000
76.510002,63.747925,-608.143555,0.007325,0.004283,0.108785,283.564941,14.445486,1.087851,-608.143555,0.108820,0.000000
76.760002,63.513336,-608.143555,0.007338,0.004283,0.108785,282.521423,14.392327,1.087851,-608.143555,0.108820,0.000000
77.010002,63.325653,-608.099060,0.007338,0.004283,0.108785,281.686584,14.349798,1.087851,-608.099060,0.108820,0.000000
77.260002,63.126816,-608.099060,0.007330,0.004283,0.108785,280.802094,14.304741,1.087851,-608.099060,0.108820,0.000000
77.510002,62.943604,-608.099060,0.007343,0.004283,0.108785,279.987122,14.263225,1.087851,-608.099060,0.108820,0.000000
77.760002,62.784233,-608.143555,0.007343,0.004283,0.108785,279.278229,14.227111,1.087851,-608.143555,0.108820,0.000000
78.010002,62.636398,-608.143555,0.007338,0.004283,0.108785,278.620605,14.193610,1.087851,-608.143555,0.108820,0.000000
78.260002,62.482239,-608.099060,0.007338,0.004283,0.108785,277.934875,14.158677,1.087851,-608.099060,0.108820,0.000000
78.510002,62.345200,-608.143555,0.007355,0.004283,0.108785,277.325287,14.127624,1.087851,-608.143555,0.108820,0.000000
78.760002,62.213387,-608.188049,0.007351,0.004283,0.108785,276.738953,14.097755,1.087851,-608.188049,0.108820,0.000000
79.010002,62.100929,-608.099060,0.007355,0.004283,0.108785,276.238739,14.072272,1.087851,-608.099060,0.108820,0.000000
79.260002,61.988098,-608.188049,0.007351,0.004283,0.108785,275.736847,14.046703,1.087851,-608.188049,0.108820,0.000000
79.510002,61.874153,-608.143555,0.007338,0.004283,0.108785,275.229980,14.020884,1.087851,-608.143555,0.108820,0.000000
79.760002,61.755737,-608.188049,0.007347,0.004283,0.108785,274.703247,13.994050,1.087851,-608.188049,0.108820,0.000000
80.010002,61.669350,-608.232544,0.007351,0.004283,0.108785,274.318970,13.974475,1.087851,-608.232544,0.108820,0.000000
80.260002,61.544601,-608.143555,0.007355,0.004283,0.108785,273.764069,13.946206,1.087851,-608.143555,0.108820,0.000000
80.510002,61.463051,-608.188049,0.007347,0.004283,0.108785,273.401306,13.927727,1.087851,-608.188049,0.108820,0.000000
80.760002,61.386345,-608.188049,0.007351,0.004283,0.108785,273.060089,13.910345,1.087851,-608.188049,0.108820,0.000000
81.010002,61.303680,-608.143555,0.007351,0.004283,0.108785,272.692383,13.891612,1.087851,-608.143555,0.108820,0.000000
81.260002,61.217285,-608.232544,0.007355,0.004283,0.108785,272.308075,13.872035,1.087851,-608.232544,0.108820,0.000000
81.510002,61.146164,-608.276978,0.007351,0.004283,0.108785,271.991730,13.855919,1.087851,-608.276978,0.108820,0.000000
81.760002,61.062004,-608.232544,0.007364,0.004283,0.108785,271.617371,13.836848,1.087851,-608.232544,0.108820,0.000000
82.010002,60.992371,-608.232544,0.007355,0.004283,0.108785,271.307617,13.821069,1.087851,-608.232544,0.108820,0.000000
82.260002,60.910080,-608.232544,0.007368,0.004283,0.108785,270.941559,13.802422,1.087851,-608.232544,0.108820,0.000000
82.510002,60.845284,-608.276978,0.007355,0.004283,0.108785,270.653351,13.787738,1.087851,-608.276978,0.108820,0.000000
82.760002,60.784218,-608.232544,0.007351,0.004283,0.108785,270.381714,13.773901,1.087851,-608.232544,0.108820,0.000000
83.010002,60.706764,-608.276978,0.007364,0.004283,0.108785,270.037170,13.756350,1.087851,-608.276978,0.108820,0.000000
83.260002,60.659103,-608.321472,0.007355,0.004283,0.108785,269.825165,13.745549,1.087851,-608.321472,0.108820,0.000000
83.510002,60.585373,-608.276978,0.007368,0.004283,0.108785,269.497192,13.728842,1.087851,-608.276978,0.108820,0.000000
83.760002,60.536217,-608.276978,0.007355,0.004283,0.108785,269.278534,13.717703,1.087851,-608.276978,0.108820,0.000000
84.010002,60.461746,-608.232544,0.007347,0.004283,0.108785,268.947266,13.700828,1.087851,-608.232544,0.108820,0.000000
84.260002,60.414078,-608.276978,0.007360,0.004283,0.108785,268.735229,13.690025,1.087851,-608.276978,0.108820,0.000000
84.510002,60.353386,-608.276978,0.007360,0.004283,0.108785,268.465271,13.676272,1.087851,-608.276978,0.108820,0.000000
84.760002,60.306839,-608.276978,0.007360,0.004283,0.108785,268.258209,13.665725,1.087851,-608.276978,0.108820,0.000000
85.010002,60.259171,-608.321472,0.007355,0.004283,0.108785,268.046173,13.654922,1.087851,-608.321472,0.108820,0.000000
85.260002,60.205551,-608.321472,0.007364,0.004283,0.108785,267.807678,13.642774,1.087851,-608.321472,0.108820,0.000000
85.510002,60.147835,-608.321472,0.007355,0.004283,0.108785,267.550934,13.629694,1.087851,-608.321472,0.108820,0.000000
85.760002,60.112831,-608.321472,0.007360,0.004283,0.108785,267.395233,13.621762,1.087851,-608.321472,0.108820,0.000000
86.010002,60.060699,-608.321472,0.007351,0.004283,0.108785,267.163330,13.609949,1.087851,-608.321472,0.108820,0.000000
86.260002,60.017128,-608.276978,0.007351,0.004283,0.108785,266.969513,13.600076,1.087851,-608.276978,0.108820,0.000000
86.510002,59.964256,-608.365967,0.007351,0.004283,0.108785,266.734344,13.588095,1.087851,-608.365967,0.108820,0.000000
86.760002,59.941910,-608.321472,0.007364,0.004283,0.108785,266.634918,13.583031,1.087851,-608.321472,0.108820,0.000000
87.010002,59.881958,-608.365967,0.007351,0.004283,0.108785,266.368256,13.569446,1.087851,-608.365967,0.108820,0.000000
87.260002,59.845840,-608.321472,0.007355,0.004283,0.108785,266.207581,13.561262,1.087851,-608.321472,0.108820,0.000000
87.510002,59.807114,-608.410461,0.007373,0.004283,0.108785,266.035339,13.552485,1.087851,-608.410461,0.108820,0.000000
87.760002,59.770248,-608.454956,0.007360,0.004283,0.108785,265.871338,13.544131,1.087851,-608.454956,0.108820,0.000000
88.010002,59.721092,-608.365967,0.007360,0.004283,0.108785,265.652679,13.532992,1.087851,-608.365967,0.108820,0.000000
88.260002,59.685722,-608.410461,0.007368,0.004283,0.108785,265.495361,13.524978,1.087851,-608.410461,0.108820,0.000000
88.510002,59.664864,-608.365967,0.007355,0.004283,0.108785,265.402557,13.520251,1.087851,-608.365967,0.108820,0.000000
88.760002,59.608269,-608.410461,0.007364,0.004283,0.108785,265.150818,13.507426,1.087851,-608.410461,0.108820,0.000000
89.010002,59.581085,-608.365967,0.007355,0.004283,0.108785,265.029907,13.501267,1.087851,-608.365967,0.108820,0.000000
89.260002,59.541237,-608.454956,0.007368,0.004283,0.108785,264.852661,13.492237,1.087851,-608.454956,0.108820,0.000000
89.510002,59.517403,-608.321472,0.007368,0.004283,0.108785,264.746643,13.486836,1.087851,-608.321472,0.108820,0.000000
89.760002,59.464157,-608.454956,0.007360,0.004283,0.108785,264.509796,13.474771,1.087851,-608.454956,0.108820,0.000000
90.010002,59.439583,-608.410461,0.007368,0.004283,0.108785,264.400482,13.469202,1.087851,-608.410461,0.108820,0.000000
90.260002,59.404205,-608.410461,0.007364,0.004283,0.108785,264.243103,13.461185,1.087851,-608.410461,0.108820,0.000000
90.510002,59.371063,-608.410461,0.007355,0.004283,0.108785,264.095673,13.453675,1.087851,-608.410461,0.108820,0.000000
90.760002,59.335686,-608.499390,0.007351,0.004283,0.108785,263.938324,13.445658,1.087851,-608.499390,0.108820,0.000000
91.010002,59.303291,-608.410461,0.007355,0.004283,0.108785,263.794220,13.438318,1.087851,-608.410461,0.108820,0.000000
91.260002,59.271637,-608.454956,0.007347,0.004283,0.108785,263.653412,13.431145,1.087851,-608.454956,0.108820,0.000000
91.510002,59.247437,-608.365967,0.007355,0.004283,0.108785,263.545746,13.425661,1.087851,-608.365967,0.108820,0.000000
91.760002,59.204613,-608.454956,0.007355,0.004283,0.108785,263.355255,13.415957,1.087851,-608.454956,0.108820,0.000000
92.010002,59.191956,-608.454956,0.007351,0.004283,0.108785,263.298981,13.413089,1.087851,-608.454956,0.108820,0.000000
92.260002,59.153595,-608.454956,0.007360,0.004283,0.108785,263.128326,13.404396,1.087851,-608.454956,0.108820,0.000000
92.510002,59.123810,-608.499390,0.007360,0.004283,0.108785,262.995850,13.397647,1.087851,-608.499390,0.108820,0.000000
92.760002,59.102959,-608.410461,0.007368,0.004283,0.108785,262.903076,13.392921,1.087851,-608.410461,0.108820,0.000000
93.010002,59.072418,-608.499390,0.007360,0.004283,0.108785,262.767242,13.386002,1.087851,-608.499390,0.108820,0.000000
93.260002,59.041512,-608.454956,0.007373,0.004283,0.108785,262.629761,13.378998,1.087851,-608.454956,0.108820,0.000000
93.510002,59.008743,-608.454956,0.007368,0.004283,0.108785,262.484009,13.371572,1.087851,-608.454956,0.108820,0.000000
93.760002,59.001671,-608.499390,0.007364,0.004283,0.108785,262.452545,13.369969,1.087851,-608.499390,0.108820,0.000000
94.010002,58.985283,-608.499390,0.007364,0.004283,0.108785,262.379639,13.366256,1.087851,-608.499390,0.108820,0.000000
94.260002,58.956612,-608.410461,0.007373,0.004283,0.108785,262.252106,13.359759,1.087851,-608.410461,0.108820,0.000000
94.510002,58.937622,-608.543884,0.007351,0.004283,0.108785,262.167633,13.355456,1.087851,-608.543884,0.108820,0.000000
94.760002,58.901131,-608.543884,0.007360,0.004283,0.108785,262.005310,13.347187,1.087851,-608.543884,0.108820,0.000000
95.010002,58.887726,-608.499390,0.007364,0.004283,0.108785,261.945679,13.344150,1.087851,-608.499390,0.108820,0.000000
95.260002,58.854958,-608.543884,0.007360,0.004283,0.108785,261.799927,13.336724,1.087851,-608.543884,0.108820,0.000000
95.510002,58.841919,-608.588379,0.007360,0.004283,0.108785,261.741913,13.333770,1.087851,-608.588379,0.108820,0.000000
95.760002,58.808411,-608.543884,0.007377,0.004283,0.108785,261.592865,13.326177,1.087851,-608.543884,0.108820,0.000000
96.010002,58.791283,-608.588379,0.007373,0.004283,0.108785,261.516693,13.322295,1.087851,-608.588379,0.108820,0.000000
96.260002,58.768562,-608.588379,0.007368,0.004283,0.108785,261.415619,13.317147,1.087851,-608.588379,0.108820,0.000000
96.510002,58.752922,-608.499390,0.007364,0.004283,0.108785,261.346039,13.313602,1.087851,-608.499390,0.108820,0.000000
96.760002,58.728348,-608.588379,0.007386,0.004283,0.108785,261.236725,13.308034,1.087851,-608.588379,0.108820,0.000000
97.010002,58.695206,-608.543884,0.007364,0.004283,0.108785,261.089325,13.300524,1.087851,-608.543884,0.108820,0.000000
97.260002,58.676964,-608.543884,0.007360,0.004283,0.108785,261.008179,13.296390,1.087851,-608.543884,0.108820,0.000000
97.510002,58.640472,-608.543884,0.007364,0.004283,0.108785,260.845856,13.288121,1.087851,-608.543884,0.108820,0.000000
97.760002,58.602486,-608.588379,0.007360,0.004283,0.108785,260.676880,13.279513,1.087851,-608.588379,0.108820,0.000000
98.010002,58.570465,-608.632874,0.007373,0.004283,0.108785,260.534454,13.272257,1.087851,-608.632874,0.108820,0.000000
98.260002,58.541420,-608.632874,0.007368,0.004283,0.108785,260.405243,13.265675,1.087851,-608.632874,0.108820,0.000000
98.510002,58.521309,-608.588379,0.007351,0.004283,0.108785,260.315796,13.261119,1.087851,-608.588379,0.108820,0.000000
98.760002,58.488541,-608.632874,0.007373,0.004283,0.108785,260.170013,13.253693,1.087851,-608.632874,0.108820,0.000000
99.010002,58.458748,-608.588379,0.007364,0.004283,0.108785,260.037506,13.246942,1.087851,-608.588379,0.108820,0.000000
99.260002,58.438271,-608.588379,0.007377,0.004283,0.108785,259.946411,13.242302,1.087851,-608.588379,0.108820,0.000000
99.510002,58.420395,-608.632874,0.007368,0.004283,0.108785,259.866882,13.238251,1.087851,-608.632874,0.108820,0.000000
99.760002,58.394333,-608.632874,0.007368,0.004283,0.108785,259.750977,13.232346,1.087851,-608.632874,0.108820,0.000000
100.010002,58.377571,-608.632874,0.007373,0.004283,0.108785,259.676392,13.228547,1.087851,-608.632874,0.108820,0.000000
100.260002,58.343315,-608.632874,0.007368,0.004283,0.108785,259.524017,13.220784,1.087851,-608.632874,0.108820,0.000000
100.510002,58.337357,-608.632874,0.007368,0.004283,0.108785,259.497528,13.219434,1.087851,-608.632874,0.108820,0.000000
100.760002,58.320976,-608.632874,0.007381,0.004283,0.108785,259.424652,13.215722,1.087851,-608.632874,0.108820,0.000000
101.010002,58.293419,-608.632874,0.007368,0.004283,0.108785,259.302063,13.209477,1.087851,-608.632874,0.108820,0.000000
101.260002,58.269211,-608.677307,0.007364,0.004283,0.108785,259.194397,13.203992,1.087851,-608.677307,0.108820,0.000000
101.510002,58.246872,-608.677307,0.007368,0.004283,0.108785,259.095032,13.198930,1.087851,-608.677307,0.108820,0.000000
101.760002,58.238304,-608.677307,0.007368,0.004283,0.108785,259.056915,13.196989,1.087851,-608.677307,0.108820,0.000000
102.010002,58.218941,-608.677307,0.007377,0.004283,0.108785,258.970795,13.192600,1.087851,-608.677307,0.108820,0.000000
102.260002,58.187294,-608.677307,0.007377,0.004283,0.108785,258.830017,13.185429,1.087851,-608.677307,0.108820,0.000000
102.510002,58.181335,-608.677307,0.007373,0.004283,0.108785,258.803497,13.184079,1.087851,-608.677307,0.108820,0.000000
102.760002,58.146332,-608.677307,0.007368,0.004283,0.108785,258.647797,13.176147,1.087851,-608.677307,0.108820,0.000000
103.010002,58.130318,-608.721802,0.007364,0.004283,0.108785,258.576569,13.172519,1.087851,-608.721802,0.108820,0.000000
103.260002,58.101273,-608.766296,0.007373,0.004283,0.108785,258.447357,13.165936,1.087851,-608.766296,0.108820,0.000000
103.510002,58.079674,-608.721802,0.007373,0.004283,0.108785,258.351288,13.161042,1.087851,-608.721802,0.108820,0.000000
103.760002,58.061806,-608.766296,0.007364,0.004283,0.108785,258.271820,13.156994,1.087851,-608.766296,0.108820,0.000000
104.010002,58.040207,-608.721802,0.007360,0.004283,0.108785,258.175720,13.152099,1.087851,-608.721802,0.108820,0.000000
104.260002,58.014137,-608.766296,0.007360,0.004283,0.108785,258.059784,13.146192,1.087851,-608.766296,0.108820,0.000000
104.500008,57.993660,-608.766296,0.007373,0.004283,0.108785,257.968689,13.141551,1.087851,-608.766296,0.108820,0.000000