File: Data/compression 7/AutoHeating-12-7-2-1-240320_03202024_204415.csv
Time (sec),S:Load (lbs),S:HL1 (DIM),S:LVDT (in),S:Position (in),Ch:Position (mm),Ch:Load (N),Ch:Stress (MPa),Ch:Strain (mm/mm),Ch:HL1 (DIM),Set Point (),Cycles ()
0.010000,0.001488,-595.244080,0.000004,-0.000000,-0.000000,0.006618,0.000337,-0.000000,-595.244080,0.000208,0.000000
0.260000,-0.001122,-595.244080,-0.000004,-0.000000,-0.000000,-0.004989,-0.000254,-0.000000,-595.244080,0.000208,0.000000
0.510000,0.023460,-595.199585,-0.000013,0.000097,0.002454,0.104357,0.005316,0.024541,-595.199585,0.003122,0.000000
0.760000,0.023827,-595.288574,0.000078,0.000246,0.006244,0.105986,0.005399,0.062439,-595.288574,0.007285,0.000000
1.010000,-0.001495,-595.288574,0.000207,0.000407,0.010346,-0.006652,-0.000339,0.103460,-595.288574,0.011465,0.000000
1.260000,-0.034630,-595.288574,0.000392,0.000573,0.014561,-0.154041,-0.007847,0.145609,-595.288574,0.015627,0.000000
1.510000,0.004837,-595.244080,0.000582,0.000734,0.018654,0.021516,0.001096,0.186542,-595.244080,0.019790,0.000000
1.760000,0.034630,-595.244080,0.000724,0.000896,0.022747,0.154041,0.007847,0.227472,-595.244080,0.023953,0.000000
2.010000,0.033142,-595.244080,0.000888,0.001069,0.027153,0.147423,0.007510,0.271528,-595.244080,0.028115,0.000000
2.260000,-0.010056,-595.244080,0.001052,0.001227,0.031168,-0.044729,-0.002279,0.311682,-595.244080,0.032278,0.000000
2.510000,0.012283,-595.199585,0.001246,0.001391,0.035340,0.054639,0.002783,0.353396,-595.199585,0.036441,0.000000
2.760000,0.027924,-595.244080,0.001388,0.001545,0.039242,0.124210,0.006328,0.392422,-595.244080,0.040604,0.000000
3.010000,-0.002235,-595.244080,0.001556,0.001719,0.043674,-0.009944,-0.000507,0.436735,-595.244080,0.044784,0.000000
3.260000,0.015266,-595.244080,0.001720,0.001884,0.047862,0.067908,0.003459,0.478623,-595.244080,0.048946,0.000000
3.510000,0.007446,-595.288574,0.001893,0.002038,0.051756,0.033123,0.001687,0.517562,-595.288574,0.053109,0.000000
3.760000,0.002228,-595.288574,0.002078,0.002216,0.056292,0.009910,0.000505,0.562916,-595.288574,0.057272,0.000000
4.010000,-0.023460,-595.288574,0.002225,0.002378,0.060402,-0.104357,-0.005316,0.604024,-595.288574,0.061434,0.000000
4.260000,0.021965,-595.333069,0.002397,0.002541,0.064530,0.097705,0.004977,0.645302,-595.333069,0.065597,0.000000
4.510000,0.029785,-595.333069,0.002574,0.002703,0.068667,0.132491,0.006749,0.686671,-595.333069,0.069760,0.000000
4.760000,0.009682,-595.333069,0.002734,0.002867,0.072812,0.043066,0.002194,0.728123,-595.333069,0.073940,0.000000
5.010000,0.017128,-595.333069,0.002897,0.003035,0.077088,0.076189,0.003881,0.770877,-595.333069,0.078102,0.000000
5.260000,0.018990,-595.288574,0.003057,0.003189,0.080999,0.084470,0.004303,0.809990,-595.288574,0.082265,0.000000
5.510000,-0.004845,-595.333069,0.003238,0.003363,0.085430,-0.021550,-0.001098,0.854304,-595.333069,0.086428,0.000000
5.760000,-0.023460,-595.333069,0.003389,0.003523,0.089472,-0.104357,-0.005316,0.894719,-595.333069,0.090590,0.000000
6.010000,0.019730,-595.333069,0.003561,0.003685,0.093591,0.087762,0.004471,0.935910,-595.333069,0.094753,0.000000
6.260000,0.026810,-595.377502,0.003742,0.003856,0.097936,0.119255,0.006075,0.979357,-595.377502,0.098916,0.000000
6.510000,-0.013039,-595.377502,0.003889,0.004017,0.102029,-0.057999,-0.002955,1.020290,-595.377502,0.103079,0.000000
6.760000,0.025322,-595.333069,0.004053,0.004182,0.106235,0.112638,0.005738,1.062352,-595.333069,0.107259,0.000000
7.010000,0.016754,-595.377502,0.004217,0.004333,0.110060,0.074526,0.003797,1.100598,-595.377502,0.111421,0.000000
7.260000,0.023087,-595.377502,0.004393,0.004507,0.114482,0.102694,0.005231,1.144825,-595.377502,0.115584,0.000000
7.510000,0.003349,-595.377502,0.004562,0.004669,0.118593,0.014898,0.000759,1.185933,-595.377502,0.119747,0.000000
7.760000,0.031273,-595.377502,0.004717,0.004831,0.122695,0.139109,0.007087,1.226953,-595.377502,0.123909,0.000000
8.010000,0.002975,-595.421997,0.004881,0.005002,0.127057,0.013236,0.000674,1.270574,-595.421997,0.128072,0.000000
8.260000,-0.030907,-595.377502,0.005049,0.005167,0.131246,-0.137480,-0.007004,1.312461,-595.377502,0.132235,0.000000
8.510000,0.012283,-595.421997,0.005230,0.005331,0.135400,0.054639,0.002783,1.354001,-595.421997,0.136397,0.000000
8.760000,0.039841,-595.466492,0.005381,0.005490,0.139459,0.177220,0.009028,1.394586,-595.466492,0.140577,0.000000
9.010000,0.017128,-595.377502,0.005545,0.005651,0.143543,0.076189,0.003881,1.435433,-595.377502,0.144740,0.000000
9.260000,0.032768,-595.421997,0.005726,0.005819,0.147801,0.145760,0.007425,1.478013,-595.421997,0.148903,0.000000
9.510000,0.026436,-595.421997,0.005877,0.005976,0.151799,0.117593,0.005990,1.517993,-595.421997,0.153065,0.000000
9.760000,0.015640,-595.421997,0.006058,0.006150,0.156214,0.069571,0.003544,1.562136,-595.421997,0.157228,0.000000
10.010000,-0.032402,-595.421997,0.006213,0.006312,0.160333,-0.144131,-0.007342,1.603327,-595.421997,0.161391,0.000000
10.260000,0.029785,-595.421997,0.006381,0.006473,0.164417,0.132491,0.006749,1.644174,-595.421997,0.165554,0.000000
10.510000,0.278160,-595.510986,0.006549,0.006637,0.168580,1.237318,0.063032,1.685800,-595.510986,0.169734,0.000000
10.760000,0.650902,-595.466492,0.006622,-0.000000,-0.000000,2.895356,0.147496,-0.000000,-595.466492,0.000208,0.000000
11.010000,0.550735,-595.421997,0.006653,-0.000000,-0.000009,2.449794,0.124798,-0.000087,-595.421997,0.000208,0.000000
11.260000,0.589462,-595.466492,0.006644,-0.000000,-0.000009,2.622059,0.133574,-0.000087,-595.466492,0.000364,0.000000
11.510000,0.564888,-595.421997,0.006622,-0.000000,-0.000000,2.512747,0.128005,-0.000000,-595.421997,0.000780,0.000000
11.760000,0.573448,-595.421997,0.006644,-0.000000,-0.000000,2.550825,0.129945,-0.000000,-595.421997,0.001197,0.000000
12.010000,0.854965,-595.510986,0.006653,0.000031,0.000789,3.803075,0.193738,0.007892,-595.510986,0.001613,0.000000
12.260000,0.956993,-595.421997,0.006679,0.000049,0.001240,4.256918,0.216858,0.012399,-595.421997,0.002029,0.000000
12.510000,1.064240,-595.466492,0.006679,0.000064,0.001630,4.733974,0.241160,0.016302,-595.466492,0.002445,0.000000
12.760000,1.151749,-595.555481,0.006713,0.000081,0.002064,5.123234,0.260990,0.020639,-595.555481,0.002862,0.000000
13.010000,1.275375,-595.466492,0.006726,0.000096,0.002445,5.673153,0.289004,0.024454,-595.466492,0.003278,0.000000
13.260000,1.391182,-595.510986,0.006726,0.000110,0.002801,6.188286,0.315246,0.028008,-595.510986,0.003694,0.000000
13.510000,1.567314,-595.510986,0.006735,0.000129,0.003287,6.971762,0.355158,0.032868,-595.510986,0.004110,0.000000
13.760000,1.644768,-595.510986,0.006756,0.000143,0.003625,7.316292,0.372710,0.036248,-595.510986,0.004527,0.000000
14.010000,1.827972,-595.510986,0.006773,0.000159,0.004041,8.131227,0.414224,0.040411,-595.510986,0.004943,0.000000
14.260000,1.948624,-595.510986,0.006782,0.000177,0.004501,8.667911,0.441564,0.045006,-595.510986,0.005359,0.000000
14.510000,2.088264,-595.555481,0.006817,0.000193,0.004891,9.289064,0.473208,0.048908,-595.555481,0.005776,0.000000
14.760000,2.150452,-595.644409,0.006821,0.000209,0.005307,9.565687,0.487299,0.053072,-595.644409,0.006200,0.000000
15.010001,2.319130,-595.466492,0.006825,0.000224,0.005697,10.316005,0.525522,0.056974,-595.466492,0.006617,0.000000
15.260001,2.515747,-595.555481,0.006847,0.000246,0.006253,11.190602,0.570076,0.062526,-595.555481,0.007033,0.000000
15.510001,2.632301,-595.599915,0.006868,0.000262,0.006660,11.709061,0.596488,0.066603,-595.599915,0.007449,0.000000
15.760001,2.653152,-595.555481,0.006868,0.000270,0.006868,11.801811,0.601213,0.068684,-595.555481,0.007865,0.000000
16.010000,2.907478,-595.644409,0.006911,0.000291,0.007388,12.933109,0.658844,0.073885,-595.644409,0.008282,0.000000
16.260000,3.091431,-595.599915,0.006916,0.000311,0.007909,13.751370,0.700528,0.079089,-595.599915,0.008698,0.000000
16.510000,3.132019,-595.599915,0.006929,0.000324,0.008221,13.931916,0.709726,0.082212,-595.599915,0.009114,0.000000
16.760000,3.278366,-595.599915,0.006950,0.000340,0.008638,14.582901,0.742888,0.086375,-595.599915,0.009531,0.000000
17.010000,3.341667,-595.599915,0.006963,0.000353,0.008975,14.864478,0.757233,0.089755,-595.599915,0.009947,0.000000
17.260000,3.549080,-595.599915,0.006972,0.000372,0.009444,15.787096,0.804233,0.094441,-595.599915,0.010363,0.000000
17.510000,3.674568,-595.599915,0.006985,0.000389,0.009886,16.345295,0.832669,0.098861,-595.599915,0.010779,0.000000
17.760000,3.609032,-595.599915,0.007002,0.000396,0.010068,16.053774,0.817818,0.100682,-595.599915,0.011196,0.000000
18.010000,3.798195,-595.599915,0.007015,0.000411,0.010450,16.895214,0.860683,0.104501,-595.599915,0.011612,0.000000
18.260000,4.180626,-595.644409,0.007054,0.000440,0.011170,18.596354,0.947343,0.111696,-595.644409,0.012028,0.000000
18.510000,4.171684,-595.688904,0.007054,0.000454,0.011543,18.556578,0.945317,0.115428,-595.688904,0.012444,0.000000
18.760000,4.363083,-595.688904,0.007084,0.000472,0.011976,19.407963,0.988689,0.119762,-595.688904,0.012861,0.000000
19.010000,4.411865,-595.644409,0.007092,0.000487,0.012358,19.624956,0.999743,0.123577,-595.644409,0.013277,0.000000
19.260000,4.574966,-595.599915,0.007110,0.000505,0.012835,20.350468,1.036702,0.128350,-595.599915,0.013693,0.000000
19.510000,4.663216,-595.688904,0.007127,0.000520,0.013208,20.743019,1.056700,0.132078,-595.688904,0.014110,0.000000
19.760000,4.769341,-595.599915,0.007136,0.000533,0.013546,21.215086,1.080748,0.135458,-595.599915,0.014534,0.000000
20.010000,5.015106,-595.644409,0.007153,0.000554,0.014075,22.308306,1.136439,0.140749,-595.644409,0.014951,0.000000
20.260000,5.158844,-595.688904,0.007179,0.000571,0.014500,22.947683,1.169011,0.144999,-595.688904,0.015367,0.000000
20.510000,5.151772,-595.688904,0.007183,0.000585,0.014864,22.916224,1.167408,0.148640,-595.688904,0.015783,0.000000
20.760000,5.329765,-595.688904,0.007209,0.000603,0.015324,23.707981,1.207742,0.153239,-595.688904,0.016200,0.000000
21.010000,5.387482,-595.688904,0.007209,0.000617,0.015679,23.964716,1.220821,0.156793,-595.688904,0.016616,0.000000
21.260000,5.474617,-595.644409,0.007230,0.000633,0.016078,24.352312,1.240566,0.160782,-595.644409,0.017032,0.000000
21.510000,5.599365,-595.733398,0.007261,0.000647,0.016425,24.907221,1.268834,0.164249,-595.733398,0.017448,0.000000
21.760000,5.674210,-595.777832,0.007269,0.000659,0.016746,25.240145,1.285794,0.167459,-595.777832,0.017865,0.000000
22.010000,6.178398,-595.777832,0.007291,0.000691,0.017544,27.482887,1.400045,0.175437,-595.777832,0.018281,0.000000
22.260000,6.021629,-595.733398,0.007308,0.000701,0.017812,26.785545,1.364521,0.178125,-595.733398,0.018697,0.000000
22.510000,6.077492,-595.733398,0.007325,0.000717,0.018203,27.034033,1.377179,0.182031,-595.733398,0.019113,0.000000
22.760000,6.168716,-595.822327,0.007330,0.000731,0.018576,27.439821,1.397851,0.185759,-595.822327,0.019530,0.000000
23.010000,6.347458,-595.777832,0.007360,0.000749,0.019027,28.234903,1.438355,0.190267,-595.777832,0.019946,0.000000
23.260000,6.445023,-595.688904,0.007377,0.000763,0.019382,28.668892,1.460463,0.193824,-595.688904,0.020362,0.000000
23.510000,6.573860,-595.777832,0.007373,0.000780,0.019816,29.241991,1.489658,0.198158,-595.777832,0.020779,0.000000
23.760000,6.620407,-595.777832,0.007386,0.000796,0.020206,29.449041,1.500206,0.202060,-595.777832,0.021195,0.000000
24.010000,6.988686,-595.822327,0.007420,0.000819,0.020796,31.087227,1.583659,0.207957,-595.822327,0.021611,0.000000
24.260000,6.948837,-595.822327,0.007429,0.000833,0.021152,30.909971,1.574629,0.211515,-595.822327,0.022027,0.000000
24.510000,6.953308,-595.777832,0.007437,0.000848,0.021542,30.929859,1.575642,0.215417,-595.777832,0.022444,0.000000
24.760000,7.043419,-595.822327,0.007442,0.000863,0.021932,31.330692,1.596061,0.219320,-595.822327,0.022860,0.000000
25.010002,7.380051,-595.822327,0.007476,0.000883,0.022435,32.828106,1.672343,0.224350,-595.822327,0.023285,0.000000
25.260002,7.405739,-595.866821,0.007493,0.000896,0.022765,32.942371,1.678164,0.227646,-595.866821,0.023701,0.000000
25.510002,7.362915,-595.822327,0.007506,0.000908,0.023051,32.751881,1.668460,0.230508,-595.822327,0.024117,0.000000
25.760002,7.741623,-595.866821,0.007537,0.000932,0.023684,34.436459,1.754277,0.236836,-595.866821,0.024534,0.000000
26.010002,7.868225,-595.911316,0.007545,0.000950,0.024126,34.999615,1.782965,0.241261,-595.911316,0.024950,0.000000
26.260002,7.863762,-595.822327,0.007575,0.000964,0.024490,34.979759,1.781954,0.244902,-595.822327,0.025366,0.000000
26.510002,7.987762,-595.822327,0.007571,0.000983,0.024959,35.531342,1.810053,0.249587,-595.822327,0.025782,0.000000
26.760002,7.930038,-596.000244,0.007588,0.000994,0.025254,35.274574,1.796972,0.252536,-596.000244,0.026199,0.000000
27.010002,8.212669,-595.911316,0.007601,0.001014,0.025748,36.531776,1.861017,0.257479,-595.911316,0.026615,0.000000
27.260002,8.328110,-595.866821,0.007636,0.001030,0.026164,37.045280,1.887177,0.261642,-595.866821,0.027031,0.000000
27.510002,8.324753,-595.911316,0.007644,0.001043,0.026485,37.030350,1.886416,0.264848,-595.911316,0.027448,0.000000
27.760002,8.653564,-595.866821,0.007657,0.001063,0.026988,38.492977,1.960926,0.269878,-595.866821,0.027864,0.000000
28.010002,8.825966,-595.911316,0.007692,0.001082,0.027482,39.259857,1.999992,0.274821,-595.911316,0.028280,0.000000
28.260002,8.695267,-595.911316,0.007709,0.001094,0.027777,38.678478,1.970376,0.277770,-595.911316,0.028696,0.000000
28.510002,8.833786,-595.911316,0.007726,0.001111,0.028228,39.294643,2.001765,0.282281,-595.911316,0.029113,0.000000
28.760002,8.891876,-595.911316,0.007731,0.001127,0.028636,39.553040,2.014928,0.286358,-595.911316,0.029529,0.000000
29.010002,9.098175,-595.911316,0.007756,0.001144,0.029069,40.470703,2.061676,0.290691,-595.911316,0.029945,0.000000
29.260002,9.161850,-595.911316,0.007765,0.001159,0.029434,40.753944,2.076105,0.294336,-595.911316,0.030361,0.000000
29.510002,9.111206,-596.000244,0.007774,0.001170,0.029728,40.528667,2.064629,0.297285,-596.000244,0.030778,0.000000
29.760002,9.635880,-595.955811,0.007800,0.001197,0.030414,42.862534,2.183522,0.304135,-595.955811,0.031194,0.000000
30.010002,9.677216,-595.955811,0.007817,0.001213,0.030804,43.046406,2.192888,0.308037,-595.955811,0.031619,0.000000
30.260002,9.665298,-595.955811,0.007851,0.001229,0.031220,42.993393,2.190188,0.312201,-595.955811,0.032035,0.000000
30.510002,9.743492,-596.044739,0.007869,0.001246,0.031653,43.341217,2.207907,0.316535,-596.044739,0.032451,0.000000
30.760002,9.708488,-595.955811,0.007886,0.001259,0.031983,43.185513,2.199975,0.319831,-595.955811,0.032868,0.000000
31.010002,9.918510,-596.000244,0.007899,0.001277,0.032426,44.119740,2.247567,0.324256,-596.000244,0.033284,0.000000
31.260002,9.919624,-596.000244,0.007912,0.001289,0.032729,44.124691,2.247819,0.327291,-596.000244,0.033700,0.000000
31.510002,10.357162,-596.044739,0.007933,0.001309,0.033249,46.070961,2.346967,0.332492,-596.044739,0.034117,0.000000
31.760002,10.550797,-595.955811,0.007946,0.001329,0.033752,46.932285,2.390845,0.337522,-595.955811,0.034533,0.000000
32.010002,10.560104,-596.000244,0.007963,0.001345,0.034151,46.973690,2.392954,0.341511,-596.000244,0.034949,0.000000
32.260002,10.618195,-596.044739,0.007985,0.001361,0.034576,47.232090,2.406117,0.345762,-596.044739,0.035365,0.000000
32.510002,10.606651,-596.044739,0.007994,0.001374,0.034888,47.180740,2.403502,0.348884,-596.044739,0.035782,0.000000
32.760002,10.911255,-596.089233,0.008032,0.001394,0.035417,48.535686,2.472526,0.354172,-596.089233,0.036198,0.000000
33.010002,10.996155,-596.000244,0.008032,0.001409,0.035799,48.913338,2.491764,0.357991,-596.000244,0.036614,0.000000
33.260002,10.775711,-596.089233,0.008054,0.001419,0.036042,47.932758,2.441811,0.360417,-596.089233,0.037030,0.000000
33.510002,11.053131,-596.089233,0.008067,0.001438,0.036527,49.166782,2.504675,0.365273,-596.089233,0.037447,0.000000
33.760002,11.485825,-596.133728,0.008084,0.001460,0.037074,51.091499,2.602725,0.370738,-596.133728,0.037863,0.000000
34.010002,11.403900,-596.044739,0.008114,0.001474,0.037438,50.727081,2.584161,0.374379,-596.044739,0.038279,0.000000
34.260002,11.508537,-596.044739,0.008123,0.001491,0.037863,51.192532,2.607872,0.378630,-596.044739,0.038696,0.000000
34.510002,11.449707,-596.089233,0.008157,0.001503,0.038184,50.930840,2.594541,0.381839,-596.089233,0.039112,0.000000
34.760002,11.772926,-596.044739,0.008170,0.001523,0.038678,52.368591,2.667783,0.386782,-596.044739,0.039528,0.000000
35.010002,11.833618,-596.178162,0.008201,0.001538,0.039077,52.638561,2.681536,0.390771,-596.178162,0.039953,0.000000
35.260002,11.760635,-596.089233,0.008209,0.001552,0.039415,52.313919,2.664998,0.394151,-596.089233,0.040369,0.000000
35.510002,12.057419,-596.089233,0.008218,0.001570,0.039875,53.634079,2.732250,0.398750,-596.089233,0.040786,0.000000
35.760002,12.274513,-596.133728,0.008239,0.001588,0.040334,54.599762,2.781445,0.403345,-596.133728,0.041202,0.000000
36.010002,12.373192,-596.133728,0.008252,0.001605,0.040760,55.038708,2.803805,0.407595,-596.133728,0.041618,0.000000
36.260002,12.322548,-596.178162,0.008282,0.001618,0.041106,54.813431,2.792329,0.411062,-596.178162,0.042034,0.000000
36.510002,12.620819,-596.133728,0.008287,0.001637,0.041592,56.140205,2.859919,0.415918,-596.133728,0.042451,0.000000
36.760002,12.761948,-596.178162,0.008321,0.001655,0.042043,56.767979,2.891899,0.420430,-596.178162,0.042867,0.000000
37.010002,12.645020,-596.178162,0.008326,0.001668,0.042355,56.247856,2.865402,0.423552,-596.178162,0.043283,0.000000
37.260002,12.677422,-596.178162,0.008347,0.001681,0.042693,56.391987,2.872745,0.426932,-596.178162,0.043699,0.000000
37.510002,13.283638,-596.178162,0.008377,0.001706,0.043335,59.088573,3.010115,0.433352,-596.178162,0.044116,0.000000
37.760002,13.115700,-596.222656,0.008382,0.001720,0.043682,58.341545,2.972060,0.436819,-596.222656,0.044532,0.000000
38.010002,13.179001,-596.133728,0.008403,0.001735,0.044072,58.623123,2.986404,0.440721,-596.133728,0.044948,0.000000
38.260002,13.195389,-596.222656,0.008433,0.001749,0.044428,58.696022,2.990118,0.444279,-596.222656,0.045364,0.000000
38.510002,13.400940,-596.222656,0.008442,0.001767,0.044870,59.610359,3.036696,0.448699,-596.222656,0.045781,0.000000
38.760002,13.493286,-596.178162,0.008472,0.001784,0.045312,60.021133,3.057622,0.453124,-596.178162,0.046197,0.000000
39.010002,13.257576,-596.222656,0.008481,0.001793,0.045547,58.972645,3.004210,0.455467,-596.222656,0.046613,0.000000
39.260002,13.362579,-596.178162,0.008498,0.001807,0.045893,59.439720,3.028004,0.458934,-596.178162,0.047030,0.000000
39.510002,14.171379,-596.222656,0.008524,0.001834,0.046587,63.037441,3.211281,0.465871,-596.222656,0.047446,0.000000
39.760002,14.054451,-596.178162,0.008532,0.001847,0.046917,62.517319,3.184784,0.469168,-596.178162,0.047862,0.000000
40.010002,14.196701,-596.222656,0.008554,0.001867,0.047429,63.150082,3.217019,0.474285,-596.222656,0.048278,0.000000
40.260002,14.267448,-596.222656,0.008580,0.001881,0.047784,63.464779,3.233050,0.477839,-596.222656,0.048703,0.000000
40.510002,14.447678,-596.178162,0.008601,0.001899,0.048244,64.266479,3.273890,0.482438,-596.178162,0.049120,0.000000
40.760002,14.424965,-596.267151,0.008632,0.001915,0.048643,64.165451,3.268744,0.486427,-596.267151,0.049536,0.000000
41.010002,14.439484,-596.267151,0.008640,0.001930,0.049016,64.230034,3.272034,0.490155,-596.267151,0.049952,0.000000
41.260002,14.100624,-596.267151,0.008666,0.001940,0.049284,62.722710,3.195247,0.492843,-596.267151,0.050368,0.000000
41.510002,14.942184,-596.222656,0.008688,0.001966,0.049943,66.466156,3.385947,0.499432,-596.222656,0.050785,0.000000
41.760002,14.945908,-596.267151,0.008688,0.001980,0.050282,66.482719,3.386791,0.502816,-596.267151,0.051201,0.000000
42.010002,15.136192,-596.311646,0.008727,0.001999,0.050767,67.329147,3.429910,0.507672,-596.311646,0.051617,0.000000
42.260002,15.049805,-596.311646,0.008727,0.002012,0.051114,66.944878,3.410335,0.511142,-596.311646,0.052033,0.000000
42.510002,15.066933,-596.356140,0.008752,0.002027,0.051487,67.021065,3.414216,0.514871,-596.356140,0.052450,0.000000
42.760002,15.194283,-596.356140,0.008774,0.002043,0.051895,67.587547,3.443074,0.518947,-596.356140,0.052866,0.000000
43.010002,15.286263,-596.311646,0.008800,0.002057,0.052259,67.996689,3.463917,0.522588,-596.311646,0.053282,0.000000
43.260002,15.943123,-596.311646,0.008813,0.002082,0.052892,70.918556,3.612763,0.528920,-596.311646,0.053699,0.000000
43.510002,15.936424,-596.311646,0.008847,0.002098,0.053300,70.888756,3.611245,0.532996,-596.311646,0.054115,0.000000
43.760002,15.794922,-596.267151,0.008860,0.002114,0.053699,70.259323,3.579180,0.536986,-596.267151,0.054531,0.000000
44.010002,15.668686,-596.311646,0.008886,0.002126,0.054011,69.697800,3.550575,0.540108,-596.311646,0.054947,0.000000
44.260002,15.729012,-596.400574,0.008903,0.002142,0.054418,69.966141,3.564245,0.544181,-596.400574,0.055364,0.000000
44.510002,15.950569,-596.356140,0.008908,0.002158,0.054826,70.951675,3.614451,0.548257,-596.356140,0.055780,0.000000
44.760002,15.947968,-596.311646,0.008938,0.002173,0.055190,70.940102,3.613861,0.551902,-596.311646,0.056196,0.000000
45.010002,16.045525,-596.356140,0.008959,0.002187,0.055546,71.374062,3.635968,0.555456,-596.356140,0.056612,0.000000
45.260002,16.801071,-596.356140,0.008972,0.002213,0.056222,74.734894,3.807177,0.562220,-596.356140,0.057037,0.000000
45.510002,16.620094,-596.356140,0.009002,0.002227,0.056560,73.929871,3.766167,0.565603,-596.356140,0.057454,0.000000
45.760002,16.676323,-596.356140,0.009033,0.002243,0.056977,74.179993,3.778909,0.569767,-596.356140,0.057870,0.000000
46.010002,16.503548,-596.356140,0.009037,0.002257,0.057332,73.411446,3.739757,0.573321,-596.356140,0.058286,0.000000
46.260002,16.591423,-596.400574,0.009080,0.002274,0.057766,73.802338,3.759670,0.577658,-596.400574,0.058702,0.000000
46.510002,16.785805,-596.356140,0.009076,0.002289,0.058147,74.666992,3.803718,0.581473,-596.356140,0.059119,0.000000
46.760002,16.837563,-596.400574,0.009102,0.002304,0.058529,74.897217,3.815446,0.585289,-596.400574,0.059535,0.000000
47.010002,16.968636,-596.356140,0.009115,0.002322,0.058980,75.480263,3.845148,0.589800,-596.356140,0.059951,0.000000
47.260002,17.541718,-596.445068,0.009158,0.002342,0.059491,78.029457,3.975010,0.594914,-596.445068,0.060368,0.000000
47.510002,17.553261,-596.356140,0.009175,0.002360,0.059951,78.080803,3.977626,0.599512,-596.356140,0.060784,0.000000
47.760002,17.512299,-596.400574,0.009184,0.002377,0.060368,77.898598,3.968343,0.603676,-596.400574,0.061200,0.000000
48.010002,17.458679,-596.400574,0.009218,0.002390,0.060697,77.660080,3.956193,0.606968,-596.400574,0.061616,0.000000
48.260002,17.692528,-596.400574,0.009235,0.002407,0.061139,78.700294,4.009184,0.611393,-596.400574,0.062033,0.000000
48.510002,17.846321,-596.400574,0.009248,0.002424,0.061581,79.384399,4.044034,0.615814,-596.400574,0.062449,0.000000
48.760002,17.343987,-596.445068,0.009270,0.002433,0.061798,77.149902,3.930203,0.617983,-596.445068,0.062865,0.000000
49.010002,17.436707,-596.489563,0.009278,0.002449,0.062197,77.562347,3.951214,0.621972,-596.489563,0.063281,0.000000
49.260002,18.681923,-596.400574,0.009300,0.002477,0.062917,83.101341,4.233384,0.629171,-596.400574,0.063698,0.000000
49.510002,18.482704,-596.400574,0.009330,0.002490,0.063255,82.215172,4.188241,0.632554,-596.400574,0.064114,0.000000
49.760002,18.600746,-596.445068,0.009352,0.002508,0.063706,82.740250,4.214989,0.637062,-596.445068,0.064530,0.000000
50.010002,18.328545,-596.445068,0.009369,0.002520,0.064010,81.529442,4.153307,0.640098,-596.445068,0.064947,0.000000
50.260002,18.528503,-596.489563,0.009399,0.002536,0.064409,82.418900,4.198619,0.644087,-596.489563,0.065371,0.000000
50.510002,18.562767,-596.445068,0.009408,0.002553,0.064842,82.571312,4.206383,0.648424,-596.445068,0.065788,0.000000
50.760002,18.585854,-596.489563,0.009429,0.002565,0.065154,82.674004,4.211615,0.651543,-596.489563,0.066204,0.000000
51.010002,19.139572,-596.489563,0.009451,0.002588,0.065727,85.137070,4.337089,0.657270,-596.489563,0.066620,0.000000
51.260002,19.506729,-596.489563,0.009477,0.002608,0.066239,86.770264,4.420288,0.662387,-596.489563,0.067037,0.000000
51.510002,19.383842,-596.534058,0.009490,0.002624,0.066655,86.223640,4.392442,0.666547,-596.534058,0.067453,0.000000
51.760002,19.430023,-596.489563,0.009524,0.002641,0.067071,86.429062,4.402906,0.670710,-596.489563,0.067869,0.000000
52.010002,19.141060,-596.534058,0.009537,0.002653,0.067383,85.143684,4.337426,0.673832,-596.534058,0.068285,0.000000
52.260002,19.182396,-596.489563,0.009550,0.002668,0.067765,85.327560,4.346793,0.677648,-596.489563,0.068702,0.000000
52.510002,19.190956,-596.489563,0.009580,0.002684,0.068164,85.365639,4.348733,0.681637,-596.489563,0.069118,0.000000
52.760002,19.297829,-596.489563,0.009597,0.002697,0.068502,85.841026,4.372951,0.685021,-596.489563,0.069534,0.000000
53.010002,20.253334,-596.489563,0.009636,0.002724,0.069178,90.091331,4.589471,0.691784,-596.489563,0.069950,0.000000
53.260002,20.026932,-596.578491,0.009636,0.002738,0.069534,89.084244,4.538168,0.695338,-596.578491,0.070366,0.000000
53.510002,20.003845,-596.534058,0.009666,0.002753,0.069933,88.981544,4.532936,0.699327,-596.534058,0.070783,0.000000
53.760002,20.036987,-596.489563,0.009684,0.002770,0.070349,89.128967,4.540446,0.703491,-596.489563,0.071199,0.000000
54.010002,19.953575,-596.534058,0.009710,0.002785,0.070748,88.757935,4.521544,0.707480,-596.534058,0.071616,0.000000
54.260002,20.276794,-596.534058,0.009735,0.002803,0.071208,90.195686,4.594788,0.712079,-596.534058,0.072031,0.000000
54.510002,20.142738,-596.534058,0.009748,0.002815,0.071511,89.599373,4.564410,0.715114,-596.534058,0.072448,0.000000
54.760002,20.245140,-596.534058,0.009748,0.002832,0.071936,90.054878,4.587614,0.719361,-596.534058,0.072864,0.000000
55.010002,20.867752,-596.578491,0.009779,0.002855,0.072509,92.824394,4.728701,0.725087,-596.578491,0.073280,0.000000
55.260002,20.871475,-596.445068,0.009813,0.002870,0.072899,92.840958,4.729544,0.728990,-596.445068,0.073697,0.000000
55.510002,20.605972,-596.489563,0.009835,0.002883,0.073228,91.659943,4.669380,0.732283,-596.489563,0.074121,0.000000
55.760002,20.629807,-596.622986,0.009839,0.002899,0.073636,91.765961,4.674781,0.736359,-596.622986,0.074538,0.000000
56.010002,21.048721,-596.534058,0.009865,0.002918,0.074121,93.629387,4.769709,0.741215,-596.534058,0.074954,0.000000
56.260002,20.989517,-596.622986,0.009886,0.002931,0.074460,93.366035,4.756292,0.744599,-596.622986,0.075371,0.000000
56.510002,21.052078,-596.534058,0.009904,0.002947,0.074841,93.644318,4.770469,0.748414,-596.534058,0.075787,0.000000
56.760002,21.285553,-596.534058,0.009916,0.002965,0.075301,94.682869,4.823375,0.753009,-596.534058,0.076203,0.000000
57.010002,21.439713,-596.578491,0.009938,0.002981,0.075717,95.368607,4.858308,0.757172,-596.578491,0.076619,0.000000
57.260002,21.556641,-596.667480,0.009960,0.002998,0.076142,95.888725,4.884805,0.761422,-596.667480,0.077035,0.000000
57.510002,21.351837,-596.622986,0.009981,0.003011,0.076472,94.977715,4.838395,0.764719,-596.622986,0.077452,0.000000
57.760002,21.726440,-596.622986,0.010011,0.003029,0.076931,96.644035,4.923282,0.769314,-596.622986,0.077868,0.000000
58.010002,22.104027,-596.622986,0.010029,0.003049,0.077434,98.323624,5.008844,0.774344,-596.622986,0.078284,0.000000
58.260002,22.144989,-596.622986,0.010059,0.003063,0.077807,98.505829,5.018126,0.778072,-596.622986,0.078700,0.000000
58.510002,22.001251,-596.667480,0.010059,0.003077,0.078163,97.866455,4.985555,0.781630,-596.667480,0.079117,0.000000
58.760002,22.750092,-596.578491,0.010089,0.003100,0.078735,101.197464,5.155244,0.787353,-596.578491,0.079533,0.000000
59.010002,22.700195,-596.622986,0.010106,0.003113,0.079065,100.975510,5.143938,0.790649,-596.622986,0.079949,0.000000
59.260002,22.567627,-596.622986,0.010128,0.003127,0.079438,100.385818,5.113897,0.794378,-596.622986,0.080366,0.000000
59.510002,22.807442,-596.667480,0.010145,0.003147,0.079923,101.452568,5.168241,0.799234,-596.667480,0.080782,0.000000
59.760002,22.909096,-596.622986,0.010171,0.003161,0.080287,101.904747,5.191276,0.802875,-596.622986,0.081198,0.000000
60.010002,23.363388,-596.622986,0.010184,0.003179,0.080747,103.925537,5.294219,0.807473,-596.622986,0.081614,0.000000
60.260002,23.302322,-596.622986,0.010192,0.003191,0.081042,103.653908,5.280382,0.810422,-596.622986,0.082031,0.000000
60.510002,22.939629,-596.667480,0.010205,0.003202,0.081320,102.040565,5.198194,0.813196,-596.667480,0.082456,0.000000
60.760002,24.396355,-596.622986,0.010218,0.003228,0.081996,108.520409,5.528293,0.819960,-596.622986,0.082872,0.000000
61.010002,24.434708,-596.667480,0.010227,0.003243,0.082360,108.691010,5.536983,0.823605,-596.667480,0.083288,0.000000
61.260002,24.578072,-596.711975,0.010279,0.003260,0.082803,109.328720,5.569471,0.828025,-596.711975,0.083704,0.000000
61.510002,24.886024,-596.756470,0.010266,0.003276,0.083210,110.698563,5.639254,0.832102,-596.756470,0.084121,0.000000
61.760002,25.313133,-596.711975,0.010300,0.003294,0.083678,112.598442,5.736038,0.836784,-596.711975,0.084537,0.000000
62.010002,25.522781,-596.667480,0.010330,0.003310,0.084077,113.530998,5.783545,0.840773,-596.667480,0.084953,0.000000
62.260002,25.507881,-596.667480,0.010335,0.003325,0.084450,113.464722,5.780169,0.844501,-596.667480,0.085369,0.000000
62.510002,25.371971,-596.711975,0.010343,0.003335,0.084702,112.860161,5.749371,0.847018,-596.711975,0.085786,0.000000
62.760002,26.583664,-596.711975,0.010365,0.003358,0.085300,118.250046,6.023944,0.853002,-596.711975,0.086202,0.000000
63.010002,26.704315,-596.756470,0.010374,0.003374,0.085690,118.786728,6.051284,0.856904,-596.756470,0.086618,0.000000
63.260002,27.099777,-596.756470,0.010408,0.003390,0.086115,120.545830,6.140897,0.861154,-596.756470,0.087035,0.000000
63.510002,27.276649,-596.711975,0.010404,0.003404,0.086471,121.332596,6.180977,0.864708,-596.711975,0.087451,0.000000
63.760002,27.933144,-596.800903,0.010421,0.003422,0.086922,124.252831,6.329741,0.869220,-596.800903,0.087867,0.000000
64.010002,28.060493,-596.667480,0.010455,0.003434,0.087234,124.819305,6.358599,0.872343,-596.667480,0.088283,0.000000
64.260002,28.468987,-596.711975,0.010451,0.003451,0.087668,126.636375,6.451164,0.876676,-596.711975,0.088700,0.000000
64.510002,29.601746,-596.711975,0.010473,0.003475,0.088257,131.675140,6.707851,0.882573,-596.711975,0.089116,0.000000
64.760002,30.531563,-596.756470,0.010503,0.003493,0.088734,135.811172,6.918551,0.887342,-596.756470,0.089532,0.000000
65.010002,30.583321,-596.756470,0.010507,0.003505,0.089038,136.041397,6.930279,0.890378,-596.756470,0.089948,0.000000
65.260002,31.058464,-596.756470,0.010516,0.003522,0.089454,138.154953,7.037949,0.894541,-596.756470,0.090365,0.000000
65.510002,31.182465,-596.800903,0.010529,0.003535,0.089792,138.706528,7.066048,0.897925,-596.800903,0.090790,0.000000
65.760002,32.222878,-596.756470,0.010542,0.003555,0.090295,143.334518,7.301808,0.902955,-596.756470,0.091206,0.000000
66.010002,32.394913,-596.711975,0.010563,0.003568,0.090625,144.099762,7.340792,0.906248,-596.711975,0.091622,0.000000
66.260002,33.221954,-596.800903,0.010563,0.003585,0.091059,147.778641,7.528202,0.910585,-596.800903,0.092038,0.000000
66.510002,33.971535,-596.800903,0.010580,0.003603,0.091510,151.112930,7.698060,0.915097,-596.800903,0.092455,0.000000
66.760002,35.048439,-596.845398,0.010602,0.003622,0.091995,155.903244,7.942090,0.919953,-596.845398,0.092871,0.000000
67.010002,35.535873,-596.800903,0.010611,0.003639,0.092420,158.071457,8.052544,0.924199,-596.800903,0.093287,0.000000
67.260002,36.074699,-596.800903,0.010615,0.003651,0.092741,160.468277,8.174644,0.927409,-596.800903,0.093703,0.000000
67.510002,36.371101,-596.800903,0.010637,0.003665,0.093097,161.786743,8.241810,0.930967,-596.800903,0.094120,0.000000
67.760002,37.589882,-596.800903,0.010637,0.003685,0.093608,167.208145,8.517989,0.936080,-596.800903,0.094536,0.000000
68.010002,38.053482,-596.889893,0.010649,0.003700,0.093981,169.270340,8.623042,0.939812,-596.889893,0.094952,0.000000
68.260002,38.451920,-596.800903,0.010675,0.003712,0.094285,171.042679,8.713329,0.942848,-596.800903,0.095369,0.000000
68.510002,40.360329,-596.889893,0.010675,0.003739,0.094961,179.531708,9.145782,0.949611,-596.889893,0.095785,0.000000
68.760002,40.998207,-596.800903,0.010688,0.003752,0.095308,182.369141,9.290326,0.953078,-596.800903,0.096201,0.000000
69.010002,41.712418,-596.934387,0.010701,0.003768,0.095707,185.546097,9.452168,0.957067,-596.934387,0.096617,0.000000
69.260002,42.524559,-596.845398,0.010714,0.003784,0.096114,189.158691,9.636203,0.961144,-596.845398,0.097034,0.000000
69.510002,43.186638,-596.934387,0.010723,0.003799,0.096505,192.103760,9.786232,0.965046,-596.934387,0.097450,0.000000
69.760002,44.345459,-596.889893,0.010731,0.003817,0.096956,197.258453,10.048825,0.969558,-596.889893,0.097866,0.000000
70.010002,44.839973,-596.889893,0.010736,0.003828,0.097224,199.458160,10.160883,0.972245,-596.889893,0.098282,0.000000
70.260002,45.573174,-596.934387,0.010749,0.003842,0.097597,202.719604,10.327028,0.975973,-596.934387,0.098699,0.000000
70.510002,47.319969,-596.889893,0.010762,0.003869,0.098274,210.489731,10.722858,0.982740,-596.889893,0.099115,0.000000
70.760002,48.307503,-596.889893,0.010770,0.003883,0.098629,214.882507,10.946636,0.986294,-596.889893,0.099540,0.000000
71.010002,48.815048,-596.889893,0.010770,0.003896,0.098968,217.140182,11.061648,0.989678,-596.889893,0.099956,0.000000
71.260002,50.165268,-596.934387,0.010770,0.003915,0.099436,223.146255,11.367612,0.994360,-596.934387,0.100372,0.000000
71.510002,50.922302,-596.978821,0.010796,0.003929,0.099800,226.513718,11.539159,0.998001,-596.978821,0.100789,0.000000
71.760002,52.050591,-596.934387,0.010787,0.003944,0.100173,231.532593,11.794832,1.001729,-596.934387,0.101205,0.000000
72.010002,52.926041,-596.889893,0.010805,0.003959,0.100546,235.426788,11.993212,1.005461,-596.889893,0.101621,0.000000
72.260002,53.673393,-596.889893,0.010800,0.003974,0.100936,238.751175,12.162564,1.009363,-596.889893,0.102038,0.000000
72.510002,56.109825,-596.934387,0.010822,0.004000,0.101604,249.588974,12.714668,1.016040,-596.934387,0.102454,0.000000
72.760002,57.253006,-596.934387,0.010839,0.004017,0.102020,254.674088,12.973717,1.020203,-596.934387,0.102870,0.000000
73.010002,58.237564,-596.978821,0.010839,0.004033,0.102428,259.053619,13.196820,1.024280,-596.978821,0.103286,0.000000
73.260002,59.320793,-596.978821,0.010831,0.004047,0.102783,263.872070,13.442284,1.027834,-596.978821,0.103703,0.000000
73.510002,60.112457,-596.934387,0.010848,0.004060,0.103113,267.393555,13.621677,1.031130,-596.934387,0.104119,0.000000
73.760002,61.562477,-596.978821,0.010865,0.004077,0.103564,273.843567,13.950256,1.035638,-596.978821,0.104535,0.000000
74.010002,62.399567,-597.023315,0.010852,0.004089,0.103850,277.567139,14.139944,1.038499,-597.023315,0.104951,0.000000
74.260002,63.823151,-597.023315,0.010869,0.004108,0.104353,283.899567,14.462533,1.043530,-597.023315,0.105368,0.000000
74.510002,65.756500,-596.978821,0.010878,0.004131,0.104917,292.499512,14.900637,1.049169,-596.978821,0.105784,0.000000
74.760002,66.728394,-596.978821,0.010878,0.004144,0.105264,296.822723,15.120871,1.052636,-596.978821,0.106200,0.000000
75.010002,67.311539,-597.023315,0.010878,0.004146,0.105307,299.416687,15.253013,1.053071,-597.023315,0.105541,0.000000
75.260002,66.742554,-597.023315,0.010900,0.004146,0.105307,296.885712,15.124079,1.053071,-597.023315,0.105541,0.000000
75.510002,66.334061,-596.978821,0.010895,0.004144,0.105264,295.068634,15.031513,1.052636,-596.978821,0.105307,0.000000
75.760002,65.889450,-597.067810,0.010900,0.004144,0.105246,293.090912,14.930763,1.052462,-597.067810,0.105307,0.000000
76.010002,65.516327,-597.112305,0.010904,0.004143,0.105229,291.431183,14.846212,1.052292,-597.112305,0.105307,0.000000
76.260002,65.152893,-597.023315,0.010900,0.004143,0.105229,289.814545,14.763856,1.052292,-597.023315,0.105307,0.000000
76.510002,64.834518,-597.023315,0.010895,0.004143,0.105220,288.398346,14.691712,1.052205,-597.023315,0.105307,0.000000
76.760002,64.561569,-597.067810,0.010908,0.004143,0.105220,287.184204,14.629861,1.052205,-597.067810,0.105307,0.000000
77.010002,64.286758,-597.023315,0.010921,0.004143,0.105220,285.961792,14.567587,1.052205,-597.023315,0.105307,0.000000
77.260002,64.053268,-597.067810,0.010904,0.004142,0.105212,284.923157,14.514678,1.052118,-597.067810,0.105307,0.000000
77.510002,63.846603,-597.023315,0.010917,0.004142,0.105212,284.003876,14.467848,1.052118,-597.023315,0.105307,0.000000
77.760002,63.642548,-597.112305,0.010917,0.004142,0.105212,283.096191,14.421608,1.052118,-597.112305,0.105307,0.000000
78.010002,63.474228,-597.067810,0.010912,0.004142,0.105212,282.347473,14.383466,1.052118,-597.067810,0.105307,0.000000
78.260002,63.281723,-597.067810,0.010925,0.004142,0.105212,281.491150,14.339844,1.052118,-597.067810,0.105307,0.000000
78.510002,63.116760,-597.023315,0.010912,0.004142,0.105212,280.757385,14.302463,1.052118,-597.023315,0.105307,0.000000
78.760002,62.969673,-597.112305,0.010921,0.004142,0.105212,280.103088,14.269132,1.052118,-597.112305,0.105307,0.000000
79.010002,62.815506,-597.112305,0.010921,0.004142,0.105203,279.417328,14.234198,1.052030,-597.112305,0.105307,0.000000
79.260002,62.687042,-597.067810,0.010921,0.004142,0.105203,278.845886,14.205087,1.052030,-597.067810,0.105307,0.000000
79.510002,62.565277,-597.112305,0.010917,0.004142,0.105203,278.304260,14.177494,1.052030,-597.112305,0.105307,0.000000
79.760002,62.435692,-597.156738,0.010917,0.004142,0.105203,277.727814,14.148130,1.052030,-597.156738,0.105307,0.000000
80.010002,62.332916,-597.067810,0.010912,0.004142,0.105203,277.270660,14.124841,1.052030,-597.067810,0.105307,0.000000
80.260002,62.223061,-597.156738,0.010934,0.004142,0.105203,276.781982,14.099947,1.052030,-597.156738,0.105307,0.000000
80.510002,62.106880,-597.156738,0.010930,0.004142,0.105203,276.265198,14.073620,1.052030,-597.156738,0.105307,0.000000
80.760002,62.020493,-597.201233,0.010934,0.004142,0.105203,275.880920,14.054045,1.052030,-597.201233,0.105307,0.000000
81.010002,61.921440,-597.156738,0.010917,0.004142,0.105203,275.440308,14.031599,1.052030,-597.156738,0.105307,0.000000
81.260002,61.826859,-597.156738,0.010917,0.004142,0.105203,275.019592,14.010166,1.052030,-597.156738,0.105307,0.000000
81.510002,61.757225,-597.112305,0.010921,0.004142,0.105203,274.709869,13.994388,1.052030,-597.112305,0.105307,0.000000
81.760002,61.653336,-597.156738,0.010934,0.004142,0.105203,274.247742,13.970845,1.052030,-597.156738,0.105307,0.000000
82.010002,61.581093,-597.201233,0.010930,0.004142,0.105203,273.926392,13.954475,1.052030,-597.201233,0.105307,0.000000
82.260002,61.503265,-597.201233,0.010938,0.004142,0.105203,273.580200,13.936839,1.052030,-597.201233,0.105307,0.000000
82.510002,61.422462,-597.112305,0.010938,0.004142,0.105203,273.220764,13.918530,1.052030,-597.112305,0.105307,0.000000
82.760002,61.363998,-597.201233,0.010930,0.004142,0.105203,272.960693,13.905281,1.052030,-597.201233,0.105307,0.000000
83.010002,61.276863,-597.201233,0.010934,0.004142,0.105203,272.573090,13.885535,1.052030,-597.201233,0.105307,0.000000
83.260002,61.231064,-597.156738,0.010934,0.004142,0.105203,272.369385,13.875157,1.052030,-597.156738,0.105307,0.000000
83.510002,61.155472,-597.245728,0.010930,0.004142,0.105203,272.033112,13.858027,1.052030,-597.245728,0.105307,0.000000
83.760002,61.084724,-597.245728,0.010938,0.004142,0.105203,271.718414,13.841996,1.052030,-597.245728,0.105307,0.000000
84.010002,61.028862,-597.245728,0.010925,0.004142,0.105203,271.469940,13.829337,1.052030,-597.245728,0.105307,0.000000
84.260002,60.964447,-597.156738,0.010930,0.004142,0.105203,271.183411,13.814741,1.052030,-597.156738,0.105307,0.000000
84.510002,60.893692,-597.245728,0.010934,0.004142,0.105203,270.868683,13.798708,1.052030,-597.245728,0.105307,0.000000
84.760002,60.843796,-597.201233,0.010938,0.004142,0.105203,270.646729,13.787401,1.052030,-597.201233,0.105307,0.000000
85.010002,60.800232,-597.201233,0.010938,0.004142,0.105203,270.452942,13.777530,1.052030,-597.201233,0.105307,0.000000
85.260002,60.738785,-597.290222,0.010943,0.004142,0.105203,270.179596,13.763605,1.052030,-597.290222,0.105307,0.000000
85.510002,60.686653,-597.201233,0.010930,0.004142,0.105203,269.947723,13.751792,1.052030,-597.201233,0.105307,0.000000
85.760002,60.645325,-597.245728,0.010921,0.004142,0.105203,269.763885,13.742427,1.052030,-597.245728,0.105307,0.000000
86.010002,60.585739,-597.201233,0.010938,0.004142,0.105203,269.498840,13.728925,1.052030,-597.201233,0.105307,0.000000
86.260002,60.537331,-597.245728,0.010921,0.004142,0.105203,269.283508,13.717956,1.052030,-597.245728,0.105307,0.000000
86.510002,60.478500,-597.290222,0.010930,0.004142,0.105194,269.021820,13.704624,1.051943,-597.290222,0.105307,0.000000
86.760002,60.440887,-597.290222,0.010938,0.004142,0.105194,268.854492,13.696101,1.051943,-597.290222,0.105307,0.000000
87.010002,60.409981,-597.290222,0.010938,0.004142,0.105194,268.717010,13.689097,1.051943,-597.290222,0.105307,0.000000
87.260002,60.344070,-597.290222,0.010938,0.004142,0.105194,268.423828,13.674162,1.051943,-597.290222,0.105307,0.000000
87.510002,60.308693,-597.290222,0.010925,0.004142,0.105194,268.266479,13.666144,1.051943,-597.290222,0.105307,0.000000
87.760002,60.283379,-597.334717,0.010943,0.004142,0.105194,268.153870,13.660409,1.051943,-597.334717,0.105307,0.000000
88.010002,60.230873,-597.290222,0.010930,0.004142,0.105194,267.920319,13.648511,1.051943,-597.290222,0.105307,0.000000
88.260002,60.197731,-597.379150,0.010938,0.004142,0.105194,267.772888,13.641001,1.051943,-597.379150,0.105307,0.000000
88.510002,60.161980,-597.290222,0.010943,0.004142,0.105194,267.613861,13.632899,1.051943,-597.290222,0.105307,0.000000
88.760002,60.123627,-597.290222,0.010925,0.004142,0.105194,267.443237,13.624208,1.051943,-597.290222,0.105307,0.000000
89.010002,60.088997,-597.245728,0.010943,0.004142,0.105194,267.289215,13.616362,1.051943,-597.245728,0.105307,0.000000
89.260002,60.062187,-597.290222,0.010921,0.004142,0.105194,267.169952,13.610286,1.051943,-597.290222,0.105307,0.000000
89.510002,60.009682,-597.379150,0.010947,0.004142,0.105194,266.936401,13.598388,1.051943,-597.379150,0.105307,0.000000
89.760002,59.995529,-597.290222,0.010938,0.004142,0.105194,266.873444,13.595181,1.051943,-597.290222,0.105307,0.000000
90.010002,59.951591,-597.290222,0.010934,0.004142,0.105194,266.678009,13.585225,1.051943,-597.290222,0.105307,0.000000
90.260002,59.935577,-597.334717,0.010934,0.004142,0.105194,266.606750,13.581595,1.051943,-597.334717,0.105307,0.000000
90.510002,59.906532,-597.334717,0.010943,0.004142,0.105194,266.477570,13.575015,1.051943,-597.334717,0.105307,0.000000
90.760002,59.851799,-597.379150,0.010943,0.004142,0.105194,266.234100,13.562612,1.051943,-597.379150,0.105307,0.000000
91.010002,59.830940,-597.334717,0.010943,0.004142,0.105194,266.141327,13.557884,1.051943,-597.334717,0.105307,0.000000
91.260002,59.805252,-597.334717,0.010943,0.004142,0.105194,266.027039,13.552064,1.051943,-597.334717,0.105307,0.000000
91.510002,59.769127,-597.379150,0.010951,0.004142,0.105194,265.866364,13.543878,1.051943,-597.379150,0.105307,0.000000
91.760002,59.747902,-597.379150,0.010938,0.004142,0.105194,265.771942,13.539068,1.051943,-597.379150,0.105307,0.000000
92.010002,59.722206,-597.379150,0.010947,0.004142,0.105194,265.657654,13.533245,1.051943,-597.379150,0.105307,0.000000
92.260002,59.671936,-597.379150,0.010947,0.004142,0.105194,265.434021,13.521854,1.051943,-597.379150,0.105307,0.000000
92.510002,59.663002,-597.423645,0.010938,0.004142,0.105194,265.394287,13.519830,1.051943,-597.423645,0.105307,0.000000
92.760002,59.633957,-597.379150,0.010934,0.004142,0.105194,265.265076,13.513247,1.051943,-597.379150,0.105307,0.000000
93.010002,59.609383,-597.379150,0.010934,0.004142,0.105194,265.155762,13.507679,1.051943,-597.379150,0.105307,0.000000
93.260002,59.576241,-597.423645,0.010934,0.004142,0.105194,265.008362,13.500170,1.051943,-597.423645,0.105307,0.000000
93.510002,59.553154,-597.468140,0.010934,0.004142,0.105194,264.905670,13.494938,1.051943,-597.468140,0.105307,0.000000
93.760002,59.528946,-597.379150,0.010943,0.004142,0.105194,264.797974,13.489451,1.051943,-597.379150,0.105307,0.000000
94.010002,59.514427,-597.379150,0.010947,0.004142,0.105194,264.733398,13.486161,1.051943,-597.379150,0.105307,0.000000
94.260002,59.482033,-597.468140,0.010943,0.004142,0.105194,264.589294,13.478822,1.051943,-597.468140,0.105307,0.000000
94.510002,59.452988,-597.423645,0.010938,0.004142,0.105194,264.460083,13.472239,1.051943,-597.423645,0.105307,0.000000
94.760002,59.432503,-597.423645,0.010938,0.004142,0.105194,264.368988,13.467598,1.051943,-597.423645,0.105307,0.000000
95.010002,59.407181,-597.423645,0.010947,0.004142,0.105194,264.256348,13.461860,1.051943,-597.423645,0.105307,0.000000
95.260002,59.387444,-597.423645,0.010947,0.004142,0.105194,264.168549,13.457387,1.051943,-597.423645,0.105307,0.000000
95.510002,59.354309,-597.512634,0.010943,0.004142,0.105194,264.021149,13.449879,1.051943,-597.512634,0.105307,0.000000
95.760002,59.344627,-597.468140,0.010938,0.004142,0.105194,263.978088,13.447684,1.051943,-597.468140,0.105307,0.000000
96.010002,59.328987,-597.468140,0.010956,0.004142,0.105194,263.908508,13.444140,1.051943,-597.468140,0.105307,0.000000
96.260002,59.297707,-597.512634,0.010947,0.004142,0.105194,263.769379,13.437053,1.051943,-597.512634,0.105307,0.000000
96.510002,59.280579,-597.512634,0.010930,0.004142,0.105194,263.693176,13.433170,1.051943,-597.512634,0.105307,0.000000
96.760002,59.254135,-597.512634,0.010947,0.004142,0.105194,263.575562,13.427179,1.051943,-597.512634,0.105307,0.000000
97.010002,59.247437,-597.512634,0.010951,0.004142,0.105194,263.545746,13.425661,1.051943,-597.512634,0.105307,0.000000
97.260002,59.222855,-597.512634,0.010947,0.004142,0.105194,263.436401,13.420091,1.051943,-597.512634,0.105307,0.000000
97.510002,59.185623,-597.512634,0.010947,0.004142,0.105194,263.270813,13.411654,1.051943,-597.512634,0.105307,0.000000
97.760002,59.185997,-597.601562,0.010934,0.004142,0.105194,263.272461,13.411738,1.051943,-597.601562,0.105307,0.000000
98.010002,59.147270,-597.557068,0.010930,0.004142,0.105194,263.100189,13.402964,1.051943,-597.557068,0.105307,0.000000
98.260002,59.128273,-597.512634,0.010938,0.004142,0.105194,263.015686,13.398659,1.051943,-597.512634,0.105307,0.000000
98.510002,59.129768,-597.557068,0.010947,0.004142,0.105194,263.022339,13.398997,1.051943,-597.557068,0.105307,0.000000
98.760002,59.094391,-597.557068,0.010943,0.004142,0.105194,262.864990,13.390981,1.051943,-597.557068,0.105307,0.000000
99.010002,59.086197,-597.557068,0.010938,0.004142,0.105194,262.828522,13.389123,1.051943,-597.557068,0.105307,0.000000
99.260002,59.072044,-597.601562,0.010943,0.004142,0.105194,262.765564,13.385917,1.051943,-597.601562,0.105307,0.000000
99.510002,59.036301,-597.557068,0.010947,0.004142,0.105194,262.606567,13.377817,1.051943,-597.557068,0.105307,0.000000
99.760002,59.033691,-597.557068,0.010956,0.004142,0.105194,262.594971,13.377226,1.051943,-597.557068,0.105307,0.000000
100.010002,59.014702,-597.601562,0.010934,0.004142,0.105194,262.510498,13.372923,1.051943,-597.601562,0.105307,0.000000
100.260002,58.994965,-597.601562,0.010947,0.004142,0.105194,262.422699,13.368450,1.051943,-597.601562,0.105307,0.000000
100.510002,58.966667,-597.601562,0.010930,0.004142,0.105194,262.296844,13.362038,1.051943,-597.601562,0.105307,0.000000
100.760002,58.946930,-597.601562,0.010947,0.004142,0.105194,262.209045,13.357565,1.051943,-597.601562,0.105307,0.000000
101.010002,58.951401,-597.690552,0.010938,0.004142,0.105194,262.228912,13.358578,1.051943,-597.690552,0.105307,0.000000
101.260002,58.909317,-597.646057,0.010947,0.004142,0.105194,262.041718,13.349042,1.051943,-597.646057,0.105307,0.000000
101.510002,58.924217,-597.601562,0.010956,0.004142,0.105194,262.108002,13.352418,1.051943,-597.601562,0.105307,0.000000
101.760002,58.886604,-597.601562,0.010938,0.004142,0.105194,261.940704,13.343896,1.051943,-597.601562,0.105307,0.000000
102.010002,58.882507,-597.646057,0.010943,0.004142,0.105194,261.922485,13.342967,1.051943,-597.646057,0.105307,0.000000
102.260002,58.868362,-597.557068,0.010938,0.004142,0.105194,261.859558,13.339761,1.051943,-597.557068,0.105307,0.000000
102.510002,58.842667,-597.646057,0.010947,0.004142,0.105194,261.745239,13.333940,1.051943,-597.646057,0.105307,0.000000
102.760002,58.834099,-597.601562,0.010960,0.004142,0.105194,261.707153,13.331998,1.051943,-597.601562,0.105307,0.000000
103.010002,58.816231,-597.601562,0.010934,0.004142,0.105194,261.627655,13.327949,1.051943,-597.601562,0.105307,0.000000
103.260002,58.799095,-597.646057,0.010943,0.004142,0.105194,261.551453,13.324065,1.051943,-597.646057,0.105307,0.000000
103.510002,58.783829,-597.601562,0.010951,0.004142,0.105194,261.483521,13.320606,1.051943,-597.601562,0.105307,0.000000
103.760002,58.749947,-597.646057,0.010943,0.004142,0.105194,261.332825,13.312928,1.051943,-597.646057,0.105307,0.000000
104.010002,58.756279,-597.646057,0.010930,0.004142,0.105194,261.360992,13.314363,1.051943,-597.646057,0.105307,0.000000
104.260002,58.734306,-597.690552,0.010934,0.004142,0.105194,261.263245,13.309384,1.051943,-597.690552,0.105307,0.000000
104.510002,58.706009,-597.690552,0.010947,0.004142,0.105194,261.137360,13.302972,1.051943,-597.690552,0.105307,0.000000
104.760002,58.708611,-597.690552,0.010938,0.004142,0.105194,261.148956,13.303561,1.051943,-597.690552,0.105307,0.000000
105.010002,58.681053,-597.690552,0.010947,0.004142,0.105194,261.026367,13.297317,1.051943,-597.690552,0.105307,0.000000
105.260002,58.684784,-597.690552,0.010947,0.004142,0.105194,261.042969,13.298162,1.051943,-597.690552,0.105307,0.000000
105.400002,58.673233,-597.690552,0.010943,0.004142,0.105194,260.991577,13.295545,1.051943,-597.690552,0.105307,0.000000