File: Data/compression 7/AutoHeating-12-7-1-3-240320_03202024_203606.csv
Time (sec),S:Load (lbs),S:HL1 (DIM),S:LVDT (in),S:Position (in),Ch:Position (mm),Ch:Load (N),Ch:Stress (MPa),Ch:Strain (mm/mm),Ch:HL1 (DIM),Set Point (),Cycles ()
0.010000,0.011169,-584.212830,-0.000022,-0.000000,-0.000000,0.049684,0.002531,-0.000000,-584.212830,0.000208,0.000000
0.280000,0.001488,-584.168335,-0.000009,-0.000000,-0.000009,0.006618,0.000337,-0.000087,-584.168335,0.000208,0.000000
0.550000,0.016754,-584.123840,0.000013,0.000116,0.002957,0.074526,0.003797,0.029571,-584.123840,0.003816,0.000000
0.820000,0.011917,-584.123840,0.000142,0.000277,0.007042,0.053010,0.002700,0.070418,-584.123840,0.008308,0.000000
1.090000,-0.024574,-584.212830,0.000319,0.000463,0.011768,-0.109312,-0.005569,0.117684,-584.212830,0.012818,0.000000
1.360000,0.015266,-584.168335,0.000500,0.000637,0.016191,0.067908,0.003459,0.161910,-584.168335,0.017310,0.000000
1.630000,-0.008568,-584.212830,0.000681,0.000820,0.020822,-0.038112,-0.001941,0.208222,-584.212830,0.021802,0.000000
1.900000,-0.045799,-584.168335,0.000858,0.000990,0.025149,-0.203725,-0.010378,0.251495,-584.168335,0.026311,0.000000
2.170000,0.032021,-584.168335,0.001048,0.001165,0.029590,0.142435,0.007256,0.295896,-584.168335,0.030804,0.000000
2.440000,-0.015640,-584.212830,0.001216,0.001348,0.034238,-0.069571,-0.003544,0.342382,-584.212830,0.035296,0.000000
2.710000,0.004837,-584.212830,0.001401,0.001527,0.038774,0.021516,0.001096,0.387736,-584.212830,0.039806,0.000000
2.980000,0.016380,-584.257263,0.001561,0.001699,0.043162,0.072863,0.003712,0.431618,-584.257263,0.044298,0.000000
3.250000,-0.002983,-584.257263,0.001755,0.001880,0.047741,-0.013269,-0.000676,0.477408,-584.257263,0.048790,0.000000
3.520000,0.021599,-584.123840,0.001944,0.002052,0.052129,0.096076,0.004894,0.521290,-584.123840,0.053300,0.000000
3.790000,-0.047668,-584.212830,0.002126,0.002235,0.056777,-0.212040,-0.010802,0.567772,-584.212830,0.057792,0.000000
4.060000,0.002602,-584.257263,0.002289,0.002408,0.061157,0.011573,0.000590,0.611567,-584.257263,0.062284,0.000000
4.330000,0.018242,-584.257263,0.002483,0.002593,0.065857,0.081144,0.004134,0.658572,-584.257263,0.066794,0.000000
4.600000,-0.002609,-584.212830,0.002647,0.002764,0.070202,-0.011607,-0.000591,0.702019,-584.212830,0.071286,0.000000
4.870000,0.036491,-584.168335,0.002837,0.002935,0.074538,0.162322,0.008269,0.745378,-584.168335,0.075796,0.000000
5.140000,0.016014,-584.212830,0.003027,0.003118,0.079186,0.071234,0.003629,0.791864,-584.212830,0.080288,0.000000
5.410000,-0.002983,-584.346252,0.003178,0.003294,0.083670,-0.013269,-0.000676,0.836700,-584.346252,0.084780,0.000000
5.680000,-0.002235,-584.257263,0.003372,0.003474,0.088240,-0.009944,-0.000507,0.882403,-584.257263,0.089289,0.000000
5.950000,-0.039101,-584.212830,0.003570,0.003647,0.092646,-0.173928,-0.008860,0.926455,-584.212830,0.093782,0.000000
6.220000,0.008194,-584.212830,0.003747,0.003820,0.097034,0.036449,0.001857,0.970337,-584.212830,0.098274,0.000000
6.490000,0.016014,-584.257263,0.003911,0.004008,0.101812,0.071234,0.003629,1.018122,-584.257263,0.102783,0.000000
6.760000,0.004097,-584.301758,0.004092,0.004182,0.106218,0.018224,0.000928,1.062178,-584.301758,0.107276,0.000000
7.030000,0.024948,-584.257263,0.004277,0.004360,0.110736,0.110975,0.005653,1.107362,-584.257263,0.111768,0.000000
7.300000,-0.000374,-584.301758,0.004449,0.004536,0.115202,-0.001663,-0.000085,1.152024,-584.301758,0.116278,0.000000
7.570000,0.010056,-584.301758,0.004622,0.004703,0.119460,0.044729,0.002279,1.194604,-584.301758,0.120770,0.000000
7.840000,0.004471,-584.257263,0.004820,0.004892,0.124247,0.019887,0.001013,1.242475,-584.257263,0.125262,0.000000
8.110001,-0.006706,-584.346252,0.004997,0.005064,0.128627,-0.029831,-0.001520,1.286270,-584.346252,0.129772,0.000000
8.380000,-0.007080,-584.346252,0.005174,0.005237,0.133032,-0.031494,-0.001604,1.330323,-584.346252,0.134264,0.000000
8.650001,0.001862,-584.257263,0.005351,0.005420,0.137672,0.008281,0.000422,1.376722,-584.257263,0.138756,0.000000
8.920000,0.018242,-584.301758,0.005532,0.005597,0.142156,0.081144,0.004134,1.421557,-584.301758,0.143265,0.000000
9.190001,0.043564,-584.301758,0.005734,0.005775,0.146691,0.193782,0.009872,1.466912,-584.301758,0.147758,0.000000
9.460000,0.018616,-584.390747,0.005894,0.005952,0.151183,0.082807,0.004218,1.511835,-584.390747,0.152250,0.000000
9.730000,0.029045,-584.346252,0.006062,0.006124,0.155554,0.129199,0.006582,1.555543,-584.346252,0.156760,0.000000
10.000000,-0.014893,-584.301758,0.006252,0.006307,0.160194,-0.066245,-0.003375,1.601938,-584.301758,0.161252,0.000000
10.270000,0.013779,-584.390747,0.006424,0.006483,0.164677,0.061291,0.003122,1.646774,-584.390747,0.165744,0.000000
10.540001,0.004097,-584.346252,0.006601,0.006664,0.169256,0.018224,0.000928,1.692563,-584.346252,0.170254,0.000000
10.810000,0.010796,-584.435242,0.006786,0.006838,0.173688,0.048021,0.002446,1.736881,-584.435242,0.174746,0.000000
11.080001,0.068146,-584.479675,0.006937,0.007008,0.178007,0.303127,0.015442,1.780066,-584.479675,0.179238,0.000000
11.350000,0.020851,-584.346252,0.007136,0.007188,0.182586,0.092750,0.004725,1.825856,-584.346252,0.183748,0.000000
11.620001,0.124001,-584.390747,0.007317,0.007367,0.187130,0.551582,0.028099,1.871297,-584.390747,0.188240,0.000000
11.890000,0.725006,-584.390747,0.007463,0.007502,0.190547,3.224988,0.164289,1.905468,-584.390747,0.190746,0.000000
12.160001,0.640480,-584.390747,0.007468,-0.000000,-0.000000,2.848998,0.145135,-0.000000,-584.390747,0.000217,0.000000
12.430000,0.602501,-584.390747,0.007468,-0.000000,-0.000000,2.680058,0.136529,-0.000000,-584.390747,0.000286,0.000000
12.700001,0.592819,-584.435242,0.007476,-0.000000,-0.000000,2.636992,0.134335,-0.000000,-584.435242,0.000737,0.000000
12.970000,0.593559,-584.435242,0.007459,-0.000000,-0.000000,2.640284,0.134502,-0.000000,-584.435242,0.001188,0.000000
13.240001,0.951408,-584.479675,0.007485,0.000040,0.001015,4.232076,0.215592,0.010147,-584.479675,0.001639,0.000000
13.510000,1.003914,-584.435242,0.007515,0.000051,0.001283,4.465632,0.227490,0.012835,-584.435242,0.002090,0.000000
13.780001,1.126427,-584.390747,0.007511,0.000066,0.001665,5.010596,0.255252,0.016654,-584.390747,0.002541,0.000000
14.050000,1.284309,-584.479675,0.007541,0.000083,0.002099,5.712893,0.291029,0.020987,-584.479675,0.002992,0.000000
14.320001,1.433258,-584.479675,0.007541,0.000099,0.002506,6.375450,0.324781,0.025064,-584.479675,0.003443,0.000000
14.590001,1.598969,-584.524170,0.007562,0.000118,0.003001,7.112567,0.362331,0.030007,-584.524170,0.003894,0.000000
14.860001,1.706207,-584.524170,0.007580,0.000130,0.003304,7.589589,0.386632,0.033042,-584.524170,0.004345,0.000000
15.130001,1.965752,-584.479675,0.007593,0.000155,0.003946,8.744100,0.445446,0.039461,-584.479675,0.004787,0.000000
15.400001,2.126617,-584.524170,0.007618,0.000174,0.004423,9.459667,0.481898,0.044230,-584.524170,0.005238,0.000000
15.670001,2.268494,-584.479675,0.007618,0.000190,0.004822,10.090764,0.514048,0.048220,-584.479675,0.005689,0.000000
15.940001,2.404411,-584.568665,0.007649,0.000207,0.005264,10.695355,0.544847,0.052640,-584.568665,0.006140,0.000000
16.210001,2.517235,-584.524170,0.007670,0.000221,0.005611,11.197220,0.570414,0.056111,-584.524170,0.006591,0.000000
16.480001,2.767845,-584.524170,0.007679,0.000243,0.006166,12.311990,0.627203,0.061660,-584.524170,0.007042,0.000000
16.750000,2.860939,-584.524170,0.007679,0.000255,0.006487,12.726092,0.648298,0.064869,-584.524170,0.007493,0.000000
17.020000,3.178940,-584.568665,0.007705,0.000278,0.007068,14.140631,0.720358,0.070679,-584.568665,0.007944,0.000000
17.290001,3.308159,-584.568665,0.007726,0.000297,0.007554,14.715425,0.749640,0.075535,-584.568665,0.008395,0.000000
17.560001,3.447792,-584.568665,0.007748,0.000316,0.008022,15.336545,0.781281,0.080221,-584.568665,0.008837,0.000000
17.830000,3.503654,-584.479675,0.007761,0.000328,0.008326,15.585033,0.793939,0.083256,-584.479675,0.009288,0.000000
18.100000,3.736015,-584.568665,0.007761,0.000348,0.008846,16.618626,0.846593,0.088457,-584.568665,0.009739,0.000000
18.370001,4.009331,-584.524170,0.007795,0.000367,0.009331,17.834394,0.908527,0.093313,-584.524170,0.010190,0.000000
18.640001,4.043221,-584.568665,0.007812,0.000380,0.009644,17.985144,0.916207,0.096435,-584.568665,0.010641,0.000000
18.910002,4.282654,-584.568665,0.007817,0.000402,0.010207,19.050196,0.970463,0.102075,-584.568665,0.011092,0.000000
19.180000,4.523582,-584.568665,0.007838,0.000422,0.010728,20.121901,1.025058,0.107275,-584.568665,0.011543,0.000000
19.450001,4.639389,-584.568665,0.007860,0.000441,0.011196,20.637033,1.051301,0.111961,-584.568665,0.011994,0.000000
19.720001,4.694122,-584.568665,0.007873,0.000458,0.011621,20.880499,1.063703,0.116208,-584.568665,0.012445,0.000000
19.990002,4.815147,-584.613159,0.007903,0.000472,0.011985,21.418846,1.091128,0.119852,-584.613159,0.012887,0.000000
20.260000,5.010643,-584.613159,0.007899,0.000490,0.012436,22.288454,1.135428,0.124360,-584.613159,0.013338,0.000000
20.530001,5.153633,-584.568665,0.007920,0.000504,0.012792,22.924505,1.167830,0.127918,-584.568665,0.013789,0.000000
20.800001,5.260880,-584.568665,0.007933,0.000519,0.013182,23.401562,1.192132,0.131820,-584.568665,0.014240,0.000000
21.070002,5.731552,-584.702087,0.007959,0.000549,0.013936,25.495216,1.298788,0.139364,-584.702087,0.014691,0.000000
21.340000,5.754646,-584.702087,0.007972,0.000566,0.014370,25.597944,1.304022,0.143701,-584.702087,0.015142,0.000000
21.610001,5.770653,-584.657593,0.007989,0.000581,0.014760,25.669146,1.307649,0.147603,-584.657593,0.015593,0.000000
21.880001,5.950142,-584.657593,0.008011,0.000599,0.015202,26.467552,1.348321,0.152024,-584.657593,0.016044,0.000000
22.150002,6.049561,-584.657593,0.008019,0.000613,0.015567,26.909790,1.370850,0.155669,-584.657593,0.016495,0.000000
22.420002,6.257347,-584.657593,0.008028,0.000630,0.016009,27.834070,1.417935,0.160090,-584.657593,0.016946,0.000000
22.690001,6.374641,-584.702087,0.008032,0.000646,0.016399,28.355822,1.444514,0.163992,-584.702087,0.017388,0.000000
22.960001,6.814789,-584.657593,0.008058,0.000673,0.017084,30.313694,1.544253,0.170843,-584.657593,0.017839,0.000000
23.230001,6.756325,-584.657593,0.008093,0.000687,0.017440,30.053633,1.531005,0.174400,-584.657593,0.018290,0.000000
23.500002,6.830055,-584.613159,0.008097,0.000703,0.017865,30.381603,1.547713,0.178651,-584.613159,0.018741,0.000000
23.770000,6.993896,-584.746582,0.008114,0.000721,0.018325,31.110405,1.584840,0.183246,-584.746582,0.019192,0.000000
24.040001,7.194611,-584.746582,0.008136,0.000742,0.018845,32.003227,1.630322,0.188450,-584.746582,0.019643,0.000000
24.310001,7.337601,-584.657593,0.008140,0.000758,0.019261,32.639278,1.662724,0.192613,-584.657593,0.020094,0.000000
24.580002,7.284348,-584.702087,0.008144,0.000769,0.019530,32.402397,1.650657,0.195301,-584.702087,0.020545,0.000000
24.850000,7.662682,-584.746582,0.008166,0.000792,0.020120,34.085312,1.736388,0.201197,-584.746582,0.020996,0.000000
25.120001,7.744232,-584.746582,0.008175,0.000811,0.020597,34.448067,1.754868,0.205966,-584.746582,0.021438,0.000000
25.390001,7.877541,-584.746582,0.008196,0.000830,0.021082,35.041050,1.785076,0.210822,-584.746582,0.021889,0.000000
25.660002,7.916634,-584.746582,0.008226,0.000845,0.021455,35.214947,1.793935,0.214554,-584.746582,0.022340,0.000000
25.930000,8.117348,-584.702087,0.008231,0.000864,0.021950,36.107765,1.839417,0.219497,-584.702087,0.022791,0.000000
26.200001,8.173576,-584.791077,0.008244,0.000878,0.022296,36.357883,1.852159,0.222964,-584.791077,0.023242,0.000000
26.470001,8.203735,-584.791077,0.008252,0.000894,0.022704,36.492039,1.858993,0.227041,-584.791077,0.023693,0.000000
26.740002,8.538498,-584.791077,0.008269,0.000915,0.023242,37.981136,1.934851,0.232419,-584.791077,0.024144,0.000000
27.010002,8.710907,-584.746582,0.008291,0.000934,0.023728,38.748051,1.973920,0.237275,-584.746582,0.024595,0.000000
27.280001,8.698616,-584.791077,0.008300,0.000951,0.024161,38.693378,1.971135,0.241609,-584.791077,0.025045,0.000000
27.550001,8.720215,-584.791077,0.008304,0.000967,0.024551,38.789452,1.976029,0.245511,-584.791077,0.025488,0.000000
27.820002,9.044556,-584.835571,0.008334,0.000989,0.025124,40.232193,2.049526,0.251238,-584.835571,0.025939,0.000000
28.090002,9.091843,-584.835571,0.008347,0.001006,0.025557,40.442535,2.060241,0.255571,-584.835571,0.026390,0.000000
28.360001,8.963379,-584.791077,0.008360,0.001016,0.025800,39.871101,2.031131,0.258001,-584.791077,0.026841,0.000000
28.630001,9.353996,-584.791077,0.008382,0.001040,0.026425,41.608654,2.119646,0.264246,-584.791077,0.027292,0.000000
28.900002,9.537575,-584.835571,0.008377,0.001058,0.026875,42.425251,2.161245,0.268754,-584.835571,0.027743,0.000000
29.170002,9.501083,-584.880005,0.008386,0.001074,0.027274,42.262928,2.152976,0.272743,-584.880005,0.028194,0.000000
29.440001,9.646309,-584.924500,0.008416,0.001092,0.027743,42.908924,2.185885,0.277425,-584.924500,0.028644,0.000000
29.710001,9.800842,-584.746582,0.008433,0.001111,0.028220,43.596325,2.220903,0.282198,-584.746582,0.029096,0.000000
29.980001,9.953140,-584.880005,0.008442,0.001129,0.028671,44.273781,2.255414,0.286706,-584.880005,0.029546,0.000000
30.250002,9.873825,-584.880005,0.008451,0.001141,0.028983,43.920967,2.237441,0.289828,-584.880005,0.029989,0.000000
30.520002,9.894310,-584.835571,0.008464,0.001155,0.029347,44.012089,2.242083,0.293469,-584.835571,0.030440,0.000000
30.790001,10.465530,-584.880005,0.008476,0.001181,0.029998,46.553005,2.371523,0.299976,-584.880005,0.030891,0.000000
31.060001,10.242851,-584.880005,0.008498,0.001192,0.030284,45.562477,2.321063,0.302837,-584.880005,0.031342,0.000000
31.330002,10.548195,-584.880005,0.008515,0.001215,0.030856,46.920715,2.390255,0.308560,-584.880005,0.031793,0.000000
31.600002,10.636818,-584.924500,0.008511,0.001234,0.031350,47.314930,2.410337,0.313503,-584.924500,0.032244,0.000000
31.870001,10.685226,-584.924500,0.008554,0.001252,0.031810,47.530262,2.421307,0.318098,-584.924500,0.032695,0.000000
32.140003,10.662888,-584.924500,0.008550,0.001266,0.032166,47.430893,2.416245,0.321656,-584.924500,0.033145,0.000000
32.410000,10.786514,-584.924500,0.008563,0.001282,0.032556,47.980812,2.444259,0.325558,-584.924500,0.033596,0.000000
32.680000,11.044937,-584.835571,0.008571,0.001302,0.033059,49.130333,2.502819,0.330588,-584.835571,0.034039,0.000000
32.950001,11.250114,-584.924500,0.008584,0.001322,0.033579,50.043007,2.549312,0.335792,-584.924500,0.034490,0.000000
33.220001,11.276550,-584.880005,0.008606,0.001340,0.034047,50.160603,2.555303,0.340474,-584.880005,0.034941,0.000000
33.490002,11.444870,-584.924500,0.008614,0.001360,0.034542,50.909325,2.593445,0.345417,-584.924500,0.035391,0.000000
33.760002,11.371880,-584.924500,0.008632,0.001374,0.034897,50.584648,2.576905,0.348971,-584.924500,0.035843,0.000000
34.030003,11.362198,-584.880005,0.008627,0.001388,0.035244,50.541580,2.574711,0.352442,-584.880005,0.036293,0.000000
34.300003,11.692123,-584.968994,0.008649,0.001406,0.035721,52.009163,2.649473,0.357211,-584.968994,0.036745,0.000000
34.570004,12.270416,-585.013489,0.008662,0.001435,0.036458,54.581539,2.780516,0.364584,-585.013489,0.037195,0.000000
34.840000,12.042900,-584.968994,0.008675,0.001449,0.036814,53.569496,2.728960,0.368138,-584.968994,0.037646,0.000000
35.110001,11.994492,-584.968994,0.008696,0.001466,0.037230,53.354164,2.717991,0.372301,-584.968994,0.038089,0.000000
35.380001,11.993370,-584.968994,0.008714,0.001481,0.037620,53.349174,2.717736,0.376203,-584.968994,0.038540,0.000000
35.650002,12.108063,-585.013489,0.008714,0.001499,0.038063,53.859352,2.743726,0.380628,-585.013489,0.038990,0.000000
35.920002,12.275627,-585.057922,0.008722,0.001517,0.038522,54.604717,2.781697,0.385223,-585.057922,0.039442,0.000000
36.190002,12.355690,-585.057922,0.008744,0.001534,0.038965,54.960854,2.799839,0.389647,-585.057922,0.039892,0.000000
36.460003,12.718750,-585.013489,0.008761,0.001556,0.039520,56.575825,2.882110,0.395196,-585.013489,0.040344,0.000000
36.730003,12.793602,-585.057922,0.008770,0.001574,0.039979,56.908783,2.899072,0.399791,-585.057922,0.040794,0.000000
37.000000,12.745193,-585.102417,0.008774,0.001591,0.040413,56.693451,2.888102,0.404128,-585.102417,0.041246,0.000000
37.270000,12.833443,-585.102417,0.008795,0.001606,0.040803,57.086002,2.908100,0.408031,-585.102417,0.041696,0.000000
37.540001,12.780197,-585.013489,0.008813,0.001621,0.041185,56.849155,2.896034,0.411846,-585.013489,0.042147,0.000000
37.810001,13.025215,-585.057922,0.008813,0.001643,0.041722,57.939049,2.951556,0.417224,-585.057922,0.042590,0.000000
38.080002,12.991699,-585.057922,0.008817,0.001654,0.042009,57.789963,2.943961,0.420085,-585.057922,0.043041,0.000000
38.350002,13.444504,-585.102417,0.008839,0.001679,0.042642,59.804138,3.046568,0.426418,-585.102417,0.043491,0.000000
38.620003,13.567764,-585.102417,0.008843,0.001697,0.043093,60.352428,3.074499,0.430925,-585.102417,0.043942,0.000000
38.890003,13.597923,-585.013489,0.008873,0.001715,0.043552,60.486584,3.081334,0.435520,-585.013489,0.044393,0.000000
39.160004,13.356628,-585.057922,0.008864,0.001727,0.043864,59.413250,3.026655,0.438643,-585.057922,0.044844,0.000000
39.430000,13.516747,-585.102417,0.008869,0.001746,0.044341,60.125492,3.062939,0.443412,-585.102417,0.045295,0.000000
39.700001,13.955399,-585.102417,0.008899,0.001768,0.044905,62.076714,3.162338,0.449051,-585.102417,0.045746,0.000000
39.970001,13.750969,-585.102417,0.008912,0.001778,0.045174,61.167366,3.116014,0.451739,-585.102417,0.046197,0.000000
40.240002,14.118126,-585.102417,0.008921,0.001802,0.045764,62.800560,3.199213,0.457635,-585.102417,0.046639,0.000000
40.510002,14.503906,-585.146912,0.008933,0.001825,0.046353,64.516594,3.286632,0.463532,-585.146912,0.047091,0.000000
40.780003,14.324425,-585.102417,0.008946,0.001840,0.046726,63.718224,3.245961,0.467260,-585.102417,0.047541,0.000000
41.050003,14.321068,-585.191406,0.008959,0.001857,0.047177,63.703293,3.245200,0.471772,-585.191406,0.047992,0.000000
41.320004,14.236168,-585.102417,0.008977,0.001872,0.047559,63.325638,3.225962,0.475587,-585.102417,0.048443,0.000000
41.590000,14.497574,-585.057922,0.008981,0.001891,0.048027,64.488426,3.285197,0.480269,-585.057922,0.048894,0.000000
41.860001,14.317345,-585.146912,0.008985,0.001902,0.048322,63.686729,3.244357,0.483218,-585.146912,0.049345,0.000000
42.130001,14.390701,-585.191406,0.009011,0.001917,0.048704,64.013039,3.260979,0.487036,-585.191406,0.049796,0.000000
42.400002,15.269875,-585.146912,0.009007,0.001949,0.049502,67.923798,3.460203,0.495015,-585.146912,0.050247,0.000000
42.670002,15.164124,-585.191406,0.009037,0.001966,0.049944,67.453392,3.436239,0.499436,-585.191406,0.050698,0.000000
42.940002,14.966019,-585.191406,0.009037,0.001982,0.050334,66.572174,3.391348,0.503338,-585.191406,0.051140,0.000000
43.210003,14.929153,-585.146912,0.009050,0.001998,0.050750,66.408188,3.382994,0.507501,-585.146912,0.051592,0.000000
43.480003,14.973839,-585.191406,0.009058,0.002013,0.051132,66.606964,3.393121,0.511317,-585.191406,0.052042,0.000000
43.750004,15.110870,-585.191406,0.009067,0.002032,0.051609,67.216507,3.424172,0.516086,-585.191406,0.052493,0.000000
44.020000,15.076241,-585.191406,0.009076,0.002044,0.051930,67.062469,3.416325,0.519295,-585.191406,0.052944,0.000000
44.290001,15.748749,-585.146912,0.009093,0.002072,0.052641,70.053932,3.568717,0.526407,-585.146912,0.053395,0.000000
44.560001,15.557350,-585.191406,0.009097,0.002088,0.053040,69.202553,3.525346,0.530396,-585.191406,0.053846,0.000000
44.830002,15.457550,-585.235901,0.009110,0.002103,0.053412,68.758614,3.502731,0.534124,-585.235901,0.054297,0.000000
45.100002,15.530907,-585.191406,0.009127,0.002121,0.053864,69.084923,3.519354,0.538636,-585.191406,0.054748,0.000000
45.370003,15.797157,-585.235901,0.009132,0.002141,0.054384,70.269264,3.579687,0.543836,-585.235901,0.055190,0.000000
45.640003,15.873123,-585.191406,0.009153,0.002158,0.054817,70.607178,3.596901,0.548174,-585.191406,0.055641,0.000000
45.910004,15.510429,-585.235901,0.009153,0.002168,0.055078,68.993835,3.514714,0.550778,-585.235901,0.056092,0.000000
46.180000,16.041801,-585.280334,0.009153,0.002192,0.055667,71.357498,3.635124,0.556675,-585.280334,0.056543,0.000000
46.450001,16.214584,-585.235901,0.009149,0.002212,0.056188,72.126076,3.674277,0.561875,-585.235901,0.056994,0.000000
46.720001,16.232460,-585.235901,0.009188,0.002229,0.056621,72.205589,3.678328,0.566213,-585.235901,0.057445,0.000000
46.990002,16.190750,-585.235901,0.009192,0.002245,0.057029,72.020050,3.668876,0.570289,-585.235901,0.057896,0.000000
47.260002,16.403748,-585.235901,0.009201,0.002264,0.057515,72.967514,3.717142,0.575145,-585.235901,0.058347,0.000000
47.530003,16.251076,-585.280334,0.009214,0.002280,0.057913,72.288399,3.682546,0.579134,-585.280334,0.058798,0.000000
47.800003,16.281982,-585.280334,0.009222,0.002295,0.058286,72.425873,3.689550,0.582862,-585.280334,0.059240,0.000000
48.070004,16.597015,-585.280334,0.009244,0.002315,0.058789,73.827209,3.760937,0.587893,-585.280334,0.059691,0.000000
48.340004,16.705376,-585.280334,0.009257,0.002332,0.059240,74.309219,3.785492,0.592404,-585.280334,0.060142,0.000000
48.610001,16.658081,-585.235901,0.009257,0.002350,0.059700,74.098846,3.774775,0.596999,-585.235901,0.060593,0.000000
48.880001,16.634247,-585.369324,0.009257,0.002368,0.060151,73.992828,3.769374,0.601507,-585.369324,0.061044,0.000000
49.150002,16.885231,-585.369324,0.009270,0.002387,0.060637,75.109261,3.826248,0.606367,-585.369324,0.061495,0.000000
49.420002,16.867729,-585.324829,0.009287,0.002405,0.061087,75.031410,3.822282,0.610874,-585.324829,0.061946,0.000000
49.690002,16.440987,-585.324829,0.009291,0.002416,0.061365,73.133163,3.725581,0.613649,-585.324829,0.062397,0.000000
49.960003,16.894913,-585.324829,0.009304,0.002438,0.061938,75.152328,3.828442,0.619375,-585.324829,0.062848,0.000000
50.230003,17.132111,-585.369324,0.009322,0.002457,0.062414,76.207436,3.882192,0.624144,-585.369324,0.063299,0.000000
50.500004,17.042366,-585.369324,0.009313,0.002474,0.062831,75.808228,3.861855,0.628308,-585.369324,0.063741,0.000000
50.770004,17.005135,-585.324829,0.009330,0.002494,0.063351,75.642616,3.853419,0.633508,-585.324829,0.064192,0.000000
51.040001,17.094498,-585.369324,0.009343,0.002512,0.063811,76.040123,3.873669,0.638107,-585.369324,0.064643,0.000000
51.310001,17.095619,-585.369324,0.009352,0.002527,0.064192,76.045113,3.873923,0.641922,-585.369324,0.065094,0.000000
51.580002,16.762344,-585.369324,0.009360,0.002539,0.064496,74.562630,3.798401,0.644957,-585.369324,0.065545,0.000000
51.850002,16.760857,-585.369324,0.009382,0.002553,0.064851,74.556015,3.798064,0.648511,-585.369324,0.065996,0.000000
52.120003,17.537254,-585.413818,0.009369,0.002579,0.065502,78.009605,3.973999,0.655018,-585.413818,0.066447,0.000000
52.390003,17.334679,-585.413818,0.009382,0.002596,0.065944,77.108505,3.928094,0.659438,-585.413818,0.066898,0.000000
52.660004,17.384949,-585.458252,0.009403,0.002615,0.066412,77.332115,3.939486,0.664124,-585.458252,0.067349,0.000000
52.930004,17.355904,-585.413818,0.009399,0.002633,0.066872,77.202911,3.932904,0.668719,-585.413818,0.067791,0.000000
53.200001,17.324257,-585.369324,0.009425,0.002652,0.067358,77.062141,3.925733,0.673575,-585.369324,0.068242,0.000000
53.470001,17.151848,-585.369324,0.009425,0.002665,0.067696,76.295227,3.886664,0.676959,-585.369324,0.068693,0.000000
53.740002,17.090034,-585.324829,0.009425,0.002680,0.068077,76.020271,3.872657,0.680774,-585.324829,0.069144,0.000000
54.010002,17.354042,-585.458252,0.009425,0.002700,0.068589,77.194633,3.932482,0.685891,-585.458252,0.069595,0.000000
54.280003,17.552147,-585.458252,0.009451,0.002721,0.069109,78.075851,3.977373,0.691092,-585.458252,0.070046,0.000000
54.550003,17.543579,-585.369324,0.009459,0.002740,0.069595,78.037735,3.975432,0.695951,-585.369324,0.070497,0.000000
54.820004,17.624016,-585.458252,0.009472,0.002759,0.070081,78.395538,3.993659,0.700807,-585.458252,0.070948,0.000000
55.090004,17.325745,-585.413818,0.009468,0.002772,0.070419,77.068764,3.926070,0.704187,-585.413818,0.071399,0.000000
55.360004,17.137695,-585.502747,0.009477,0.002786,0.070775,76.232277,3.883457,0.707745,-585.502747,0.071841,0.000000
55.630001,17.405807,-585.502747,0.009494,0.002805,0.071251,77.424896,3.944212,0.712514,-585.502747,0.072292,0.000000
55.900002,18.279762,-585.458252,0.009494,0.002835,0.072006,81.312447,4.142253,0.720057,-585.458252,0.072743,0.000000
56.170002,17.732750,-585.502747,0.009520,0.002849,0.072370,78.879211,4.018299,0.723702,-585.502747,0.073194,0.000000
56.440002,17.517517,-585.502747,0.009498,0.002866,0.072786,77.921806,3.969526,0.727862,-585.502747,0.073645,0.000000
56.710003,17.274361,-585.591736,0.009528,0.002880,0.073142,76.840195,3.914426,0.731420,-585.591736,0.074096,0.000000
56.980003,17.136581,-585.458252,0.009541,0.002894,0.073506,76.227318,3.883205,0.735061,-585.458252,0.074547,0.000000
57.250004,17.462036,-585.502747,0.009528,0.002914,0.074009,77.675018,3.956954,0.740091,-585.502747,0.074998,0.000000
57.520004,17.563690,-585.502747,0.009533,0.002934,0.074512,78.127197,3.979989,0.745121,-585.502747,0.075449,0.000000
57.790001,17.890259,-585.547241,0.009541,0.002952,0.074989,79.579849,4.053991,0.749890,-585.547241,0.075900,0.000000
58.060001,18.060432,-585.636230,0.009550,0.002973,0.075527,80.336815,4.092552,0.755268,-585.636230,0.076342,0.000000
58.330002,17.927124,-585.502747,0.009567,0.002990,0.075952,79.743828,4.062345,0.759519,-585.502747,0.076793,0.000000
58.600002,17.678757,-585.458252,0.009567,0.003004,0.076307,78.639038,4.006063,0.763073,-585.458252,0.077244,0.000000
58.870003,17.412132,-585.547241,0.009572,0.003019,0.076671,77.453033,3.945646,0.766714,-585.547241,0.077695,0.000000
59.140003,17.743919,-585.591736,0.009576,0.003041,0.077253,78.928894,4.020830,0.772527,-585.591736,0.078146,0.000000
59.410004,17.648216,-585.636230,0.009580,0.003052,0.077530,78.503189,3.999143,0.775302,-585.636230,0.078597,0.000000
59.680004,18.248856,-585.547241,0.009606,0.003078,0.078172,81.174965,4.135250,0.781717,-585.547241,0.079048,0.000000
59.950005,18.302475,-585.502747,0.009606,0.003095,0.078614,81.413475,4.147400,0.786142,-585.502747,0.079499,0.000000
60.220001,18.263382,-585.547241,0.009606,0.003113,0.079065,81.239578,4.138541,0.790649,-585.547241,0.079949,0.000000
60.490002,17.842224,-585.547241,0.009610,0.003127,0.079438,79.366180,4.043106,0.794381,-585.547241,0.080392,0.000000
60.760002,17.870155,-585.591736,0.009606,0.003145,0.079871,79.490417,4.049435,0.798715,-585.591736,0.080843,0.000000
61.030003,18.388496,-585.591736,0.009632,0.003164,0.080357,81.796120,4.166893,0.803571,-585.591736,0.081294,0.000000
61.300003,18.072723,-585.591736,0.009645,0.003177,0.080687,80.391487,4.095337,0.806868,-585.591736,0.081745,0.000000
61.570004,18.491646,-585.547241,0.009641,0.003199,0.081259,82.254951,4.190267,0.812590,-585.547241,0.082196,0.000000
61.840004,19.015945,-585.591736,0.009649,0.003223,0.081866,84.587151,4.309075,0.818661,-585.591736,0.082647,0.000000
62.110004,18.681183,-585.636230,0.009658,0.003237,0.082231,83.098053,4.233216,0.822306,-585.636230,0.083098,0.000000
62.380001,18.438019,-585.547241,0.009662,0.003253,0.082638,82.016403,4.178115,0.826379,-585.547241,0.083549,0.000000
62.650002,18.274925,-585.547241,0.009679,0.003267,0.082976,81.290924,4.141157,0.829763,-585.547241,0.084000,0.000000
62.920002,18.494621,-585.680664,0.009671,0.003288,0.083505,82.268181,4.190941,0.835054,-585.680664,0.084442,0.000000
63.190002,18.447701,-585.725159,0.009688,0.003301,0.083835,82.059471,4.180308,0.838347,-585.725159,0.084893,0.000000
63.460003,18.496483,-585.680664,0.009692,0.003317,0.084242,82.276466,4.191363,0.842423,-585.680664,0.085344,0.000000
63.730003,19.828835,-585.636230,0.009710,0.003348,0.085049,88.203064,4.493278,0.850489,-585.636230,0.085795,0.000000
64.000000,19.447151,-585.636230,0.009718,0.003365,0.085474,86.505249,4.406787,0.854739,-585.636230,0.086246,0.000000
64.270004,19.115738,-585.680664,0.009722,0.003380,0.085847,85.031052,4.331688,0.858467,-585.680664,0.086697,0.000000
64.540001,18.890083,-585.769653,0.009727,0.003394,0.086211,84.027290,4.280554,0.862108,-585.769653,0.087148,0.000000
64.810005,18.972374,-585.680664,0.009731,0.003412,0.086653,84.393333,4.299201,0.866533,-585.680664,0.087599,0.000000
65.080002,19.092278,-585.680664,0.009731,0.003428,0.087078,84.926689,4.326372,0.870783,-585.680664,0.088050,0.000000
65.350006,19.190216,-585.680664,0.009744,0.003443,0.087451,85.362343,4.348565,0.874511,-585.680664,0.088500,0.000000
65.620003,20.234718,-585.725159,0.009757,0.003471,0.088171,90.008522,4.585253,0.881710,-585.725159,0.088943,0.000000
65.889999,19.965118,-585.814148,0.009748,0.003488,0.088587,88.809280,4.524161,0.885874,-585.814148,0.089394,0.000000
66.160004,19.810585,-585.769653,0.009774,0.003501,0.088934,88.121880,4.489143,0.889341,-585.769653,0.089845,0.000000
66.430000,19.822502,-585.725159,0.009787,0.003518,0.089368,88.174896,4.491843,0.893678,-585.725159,0.090295,0.000000
66.700005,20.356483,-585.725159,0.009791,0.003540,0.089905,90.550163,4.612845,0.899053,-585.725159,0.090747,0.000000
66.970001,20.563148,-585.769653,0.009800,0.003557,0.090348,91.469452,4.659676,0.903477,-585.769653,0.091197,0.000000
67.240005,20.078697,-585.769653,0.009800,0.003567,0.090599,89.314507,4.549898,0.905990,-585.769653,0.091649,0.000000
67.510002,20.788811,-585.769653,0.009804,0.003590,0.091189,92.473251,4.710812,0.911887,-585.769653,0.092099,0.000000
67.780006,21.317207,-585.725159,0.009813,0.003611,0.091727,94.823677,4.830548,0.917266,-585.725159,0.092551,0.000000
68.050003,21.540253,-585.769653,0.009830,0.003629,0.092169,95.815826,4.881091,0.921690,-585.769653,0.092993,0.000000
68.320000,21.442696,-585.814148,0.009830,0.003644,0.092551,95.381874,4.858984,0.925505,-585.814148,0.093444,0.000000
68.590004,22.036629,-585.769653,0.009848,0.003663,0.093045,98.023819,4.993571,0.930448,-585.769653,0.093895,0.000000
68.860001,21.991570,-585.725159,0.009860,0.003678,0.093426,97.823387,4.983361,0.934263,-585.725159,0.094346,0.000000
69.130005,22.368416,-585.725159,0.009856,0.003693,0.093808,99.499680,5.068756,0.938079,-585.725159,0.094796,0.000000
69.400002,22.994743,-585.769653,0.009873,0.003713,0.094311,102.285728,5.210683,0.943109,-585.769653,0.095248,0.000000
69.670006,23.403984,-585.769653,0.009878,0.003731,0.094779,104.106117,5.303419,0.947791,-585.769653,0.095698,0.000000
69.940002,23.659058,-585.858582,0.009891,0.003750,0.095239,105.240746,5.361219,0.952389,-585.858582,0.096150,0.000000
70.210007,24.038872,-585.814148,0.009908,0.003767,0.095681,106.930244,5.447286,0.956810,-585.814148,0.096600,0.000000
70.480003,24.785484,-585.858582,0.009912,0.003790,0.096254,110.251343,5.616471,0.962537,-585.858582,0.097051,0.000000
70.750000,24.912834,-585.858582,0.009904,0.003804,0.096609,110.817818,5.645329,0.966091,-585.858582,0.097494,0.000000
71.020004,24.831657,-585.903076,0.009925,0.003814,0.096886,110.456726,5.626934,0.968865,-585.903076,0.097945,0.000000
71.290001,25.926056,-585.858582,0.009929,0.003838,0.097494,115.324860,5.874928,0.974936,-585.858582,0.098396,0.000000
71.560005,26.483498,-585.858582,0.009955,0.003857,0.097962,117.804482,6.001246,0.979618,-585.858582,0.098846,0.000000
71.830002,26.778419,-585.814148,0.009960,0.003872,0.098352,119.116356,6.068077,0.983520,-585.814148,0.099297,0.000000
72.100006,27.146324,-585.814148,0.009960,0.003890,0.098803,120.752884,6.151445,0.988032,-585.814148,0.099748,0.000000
72.370003,27.949905,-585.858582,0.009973,0.003911,0.099332,124.327385,6.333539,0.993323,-585.858582,0.100199,0.000000
72.640007,28.183006,-585.858582,0.009985,0.003926,0.099731,125.364273,6.386361,0.997312,-585.858582,0.100650,0.000000
72.910004,28.547562,-585.903076,0.009990,0.003938,0.100026,126.985893,6.468970,1.000261,-585.903076,0.101101,0.000000
73.180000,28.840248,-585.858582,0.010007,0.003953,0.100408,128.287827,6.535294,1.004076,-585.858582,0.101543,0.000000
73.450005,30.313721,-585.903076,0.010007,0.003979,0.101075,134.842163,6.869187,1.010752,-585.903076,0.101995,0.000000
73.720001,30.587418,-585.947571,0.010020,0.003994,0.101457,136.059631,6.931208,1.014568,-585.947571,0.102445,0.000000
73.990005,31.408501,-585.947571,0.010020,0.004014,0.101960,139.711990,7.117268,1.019598,-585.947571,0.102897,0.000000
74.260002,32.003181,-585.947571,0.010059,0.004032,0.102420,142.357254,7.252025,1.024196,-585.947571,0.103347,0.000000
74.530006,32.545349,-585.903076,0.010046,0.004050,0.102870,144.768936,7.374882,1.028704,-585.903076,0.103798,0.000000
74.800003,33.100189,-585.903076,0.010054,0.004064,0.103217,147.237000,7.500610,1.032175,-585.903076,0.104249,0.000000
75.070007,33.539589,-585.992065,0.010072,0.004079,0.103599,149.191544,7.600180,1.035990,-585.992065,0.104700,0.000000
75.340004,34.486526,-585.947571,0.010098,0.004099,0.104119,153.403732,7.814759,1.041191,-585.947571,0.105151,0.000000
75.610001,35.433846,-585.947571,0.010089,0.004119,0.104622,157.617615,8.029424,1.046221,-585.947571,0.105594,0.000000
75.880005,36.180450,-585.992065,0.010102,0.004138,0.105108,160.938675,8.198607,1.051077,-585.992065,0.106044,0.000000
76.150002,37.105049,-585.903076,0.010111,0.004158,0.105602,165.051498,8.408124,1.056024,-585.903076,0.106496,0.000000
76.420006,37.578339,-585.992065,0.010123,0.004171,0.105932,167.156799,8.515373,1.059316,-585.992065,0.106946,0.000000
76.690002,37.961136,-585.947571,0.010132,0.004185,0.106296,168.859573,8.602117,1.062961,-585.947571,0.107397,0.000000
76.960007,38.872704,-585.947571,0.010154,0.004203,0.106764,172.914429,8.808681,1.067643,-585.947571,0.107848,0.000000
77.230003,41.064865,-585.903076,0.010158,0.004233,0.107527,182.665649,9.305431,1.075274,-585.903076,0.108299,0.000000
77.500000,41.462181,-586.036560,0.010162,0.004247,0.107874,184.432999,9.395464,1.078744,-586.036560,0.108750,0.000000
77.770004,42.153305,-585.992065,0.010171,0.004264,0.108317,187.507263,9.552075,1.083165,-585.992065,0.109201,0.000000
78.040001,42.597916,-585.992065,0.010171,0.004277,0.108637,189.484985,9.652825,1.086375,-585.992065,0.109652,0.000000
78.310005,43.272285,-585.947571,0.010179,0.004291,0.109002,192.484741,9.805639,1.090016,-585.947571,0.110094,0.000000
78.580002,44.484734,-585.947571,0.010197,0.004312,0.109531,197.877975,10.080385,1.095307,-585.947571,0.110545,0.000000
78.850006,45.106216,-585.947571,0.010210,0.004330,0.109973,200.642471,10.221215,1.099732,-585.947571,0.110996,0.000000
79.120003,46.691040,-586.036560,0.010210,0.004350,0.110493,207.692123,10.580340,1.104932,-586.036560,0.111447,0.000000
79.390007,47.890076,-585.992065,0.010223,0.004371,0.111031,213.025696,10.852047,1.110310,-585.992065,0.111898,0.000000
79.660004,48.815422,-585.992065,0.010244,0.004388,0.111465,217.141846,11.061732,1.114648,-585.992065,0.112349,0.000000
79.930000,49.409729,-586.036560,0.010240,0.004402,0.111803,219.785446,11.196404,1.118028,-586.036560,0.112800,0.000000
80.200005,49.974991,-586.036560,0.010244,0.004416,0.112167,222.299866,11.324495,1.121673,-586.036560,0.113251,0.000000
80.470001,51.295052,-586.080994,0.010261,0.004438,0.112713,228.171783,11.623625,1.127134,-586.080994,0.113702,0.000000
80.740005,52.267311,-585.992065,0.010270,0.004451,0.113052,232.496613,11.843942,1.130518,-585.992065,0.114144,0.000000
81.010002,53.775421,-586.036560,0.010274,0.004473,0.113624,239.205017,12.185684,1.136241,-586.036560,0.114595,0.000000
81.280006,55.239594,-586.036560,0.010292,0.004495,0.114162,245.717987,12.517471,1.141615,-586.036560,0.115046,0.000000
81.550003,56.196960,-586.080994,0.010292,0.004511,0.114578,249.976562,12.734413,1.145779,-586.080994,0.115497,0.000000
81.820007,56.854202,-586.080994,0.010296,0.004525,0.114942,252.900116,12.883347,1.149423,-586.080994,0.115948,0.000000
82.090004,57.547928,-586.080994,0.010317,0.004541,0.115333,255.985962,13.040546,1.153326,-586.080994,0.116399,0.000000
82.360001,59.538261,-586.080994,0.010313,0.004563,0.115896,264.839417,13.491563,1.158961,-586.080994,0.116850,0.000000
82.630005,60.290825,-586.080994,0.010322,0.004575,0.116217,268.186981,13.662097,1.162171,-586.080994,0.117301,0.000000
82.900002,61.816437,-586.125488,0.010317,0.004598,0.116781,274.973236,14.007805,1.167807,-586.125488,0.117752,0.000000
83.170006,63.385246,-586.125488,0.010330,0.004620,0.117336,281.951660,14.363302,1.173359,-586.125488,0.118194,0.000000
83.440002,64.679604,-586.080994,0.010352,0.004635,0.117735,287.709259,14.656608,1.177348,-586.080994,0.118645,0.000000
83.710007,65.479088,-586.080994,0.010339,0.004651,0.118134,291.265533,14.837773,1.181338,-586.080994,0.119096,0.000000
83.980003,66.508705,-586.125488,0.010361,0.004665,0.118489,295.845490,15.071088,1.184892,-586.125488,0.119547,0.000000
84.250008,67.380058,-586.125488,0.010378,0.004668,0.118576,299.721466,15.268539,1.185758,-586.125488,0.118836,0.000000
84.520004,66.732124,-586.169983,0.010361,0.004668,0.118576,296.839325,15.121716,1.185758,-586.169983,0.118836,0.000000
84.790001,66.138191,-586.169983,0.010382,0.004666,0.118507,294.197357,14.987128,1.185066,-586.169983,0.118576,0.000000
85.060005,65.645546,-586.080994,0.010382,0.004665,0.118489,292.005981,14.875493,1.184892,-586.080994,0.118576,0.000000
85.330002,65.210243,-586.169983,0.010382,0.004665,0.118480,290.069641,14.776852,1.184805,-586.169983,0.118576,0.000000
85.600006,64.834892,-586.169983,0.010382,0.004664,0.118472,288.399994,14.691796,1.184718,-586.169983,0.118576,0.000000
85.870003,64.478905,-586.214478,0.010386,0.004664,0.118472,286.816498,14.611128,1.184718,-586.214478,0.118576,0.000000
86.140007,64.163124,-586.125488,0.010395,0.004664,0.118463,285.411835,14.539572,1.184631,-586.125488,0.118576,0.000000
86.410004,63.881233,-586.169983,0.010399,0.004664,0.118463,284.157928,14.475694,1.184631,-586.169983,0.118576,0.000000
86.680000,63.617973,-586.169983,0.010399,0.004664,0.118463,282.986877,14.416039,1.184631,-586.169983,0.118576,0.000000
86.950005,63.384499,-586.258911,0.010386,0.004664,0.118463,281.948334,14.363132,1.184631,-586.258911,0.118576,0.000000
87.220001,63.165916,-586.258911,0.010408,0.004664,0.118463,280.976044,14.313601,1.184631,-586.258911,0.118576,0.000000
87.490005,62.967812,-586.214478,0.010408,0.004664,0.118463,280.094818,14.268710,1.184631,-586.214478,0.118576,0.000000
87.760002,62.777527,-586.169983,0.010404,0.004664,0.118454,279.248383,14.225591,1.184543,-586.169983,0.118576,0.000000
88.030006,62.585754,-586.258911,0.010382,0.004664,0.118454,278.395325,14.182135,1.184543,-586.258911,0.118576,0.000000
88.300003,62.435692,-586.214478,0.010399,0.004664,0.118454,277.727814,14.148130,1.184543,-586.214478,0.118576,0.000000
88.570007,62.267746,-586.258911,0.010386,0.004664,0.118454,276.980774,14.110073,1.184543,-586.258911,0.118576,0.000000
88.840004,62.119919,-586.258911,0.010404,0.004664,0.118454,276.323212,14.076575,1.184543,-586.258911,0.118576,0.000000
89.110001,61.982140,-586.258911,0.010404,0.004664,0.118454,275.710327,14.045354,1.184543,-586.258911,0.118576,0.000000
89.380005,61.843987,-586.214478,0.010399,0.004664,0.118454,275.095795,14.014048,1.184543,-586.214478,0.118576,0.000000
89.650002,61.729301,-586.258911,0.010395,0.004664,0.118454,274.585632,13.988060,1.184543,-586.258911,0.118576,0.000000
89.920006,61.605675,-586.303406,0.010399,0.004664,0.118454,274.035736,13.960046,1.184543,-586.303406,0.118576,0.000000
90.190002,61.490608,-586.303406,0.010399,0.004664,0.118454,273.523895,13.933970,1.184543,-586.303406,0.118576,0.000000
90.460007,61.393791,-586.214478,0.010417,0.004664,0.118454,273.093231,13.912031,1.184543,-586.214478,0.118576,0.000000
90.730003,61.280960,-586.303406,0.010404,0.004664,0.118454,272.591339,13.886464,1.184543,-586.303406,0.118576,0.000000
91.000008,61.181168,-586.347900,0.010412,0.004664,0.118454,272.147430,13.863851,1.184543,-586.347900,0.118576,0.000000
91.270004,61.093658,-586.258911,0.010412,0.004664,0.118454,271.758179,13.844021,1.184543,-586.258911,0.118576,0.000000
91.540001,60.983810,-586.258911,0.010391,0.004664,0.118454,271.269531,13.819129,1.184543,-586.258911,0.118576,0.000000
91.810005,60.904869,-586.347900,0.010391,0.004664,0.118454,270.918396,13.801241,1.184543,-586.347900,0.118576,0.000000
92.080002,60.816986,-586.347900,0.010404,0.004664,0.118454,270.527466,13.781326,1.184543,-586.347900,0.118576,0.000000
92.350006,60.724266,-586.392395,0.010404,0.004664,0.118454,270.115021,13.760315,1.184543,-586.392395,0.118576,0.000000
92.620003,60.654259,-586.347900,0.010404,0.004664,0.118454,269.803619,13.744452,1.184543,-586.347900,0.118576,0.000000
92.890007,60.583138,-586.347900,0.010408,0.004664,0.118454,269.487244,13.728335,1.184543,-586.347900,0.118576,0.000000
93.160004,60.503448,-586.303406,0.010417,0.004664,0.118454,269.132782,13.710278,1.184543,-586.303406,0.118576,0.000000
93.430008,60.434189,-586.392395,0.010412,0.004664,0.118454,268.824707,13.694583,1.184543,-586.392395,0.118576,0.000000
93.700005,60.348915,-586.392395,0.010412,0.004664,0.118454,268.445374,13.675260,1.184543,-586.392395,0.118576,0.000000
93.970001,60.285240,-586.392395,0.010421,0.004664,0.118454,268.162140,13.660831,1.184543,-586.392395,0.118576,0.000000
94.240005,60.220444,-586.347900,0.010421,0.004664,0.118454,267.873901,13.646148,1.184543,-586.347900,0.118576,0.000000
94.510002,60.162354,-586.347900,0.010408,0.004664,0.118454,267.615509,13.632984,1.184543,-586.347900,0.118576,0.000000
94.780006,60.099800,-586.392395,0.010417,0.004664,0.118454,267.337250,13.618810,1.184543,-586.392395,0.118576,0.000000
95.050003,60.043571,-586.436829,0.010417,0.004663,0.118446,267.087158,13.606069,1.184456,-586.436829,0.118576,0.000000
95.320007,59.974678,-586.436829,0.010421,0.004663,0.118446,266.780701,13.590456,1.184456,-586.436829,0.118576,0.000000
95.590004,59.911377,-586.392395,0.010412,0.004663,0.118446,266.499115,13.576112,1.184456,-586.392395,0.118576,0.000000
95.860008,59.856262,-586.436829,0.010417,0.004663,0.118446,266.253937,13.563623,1.184456,-586.436829,0.118576,0.000000
96.130005,59.793709,-586.436829,0.010412,0.004663,0.118446,265.975708,13.549448,1.184456,-586.436829,0.118576,0.000000
96.400002,59.748276,-586.481323,0.010404,0.004663,0.118446,265.773590,13.539153,1.184456,-586.481323,0.118576,0.000000
96.670006,59.693542,-586.392395,0.010425,0.004663,0.118446,265.530151,13.526751,1.184456,-586.392395,0.118576,0.000000
96.940002,59.638054,-586.436829,0.010417,0.004663,0.118446,265.283325,13.514176,1.184456,-586.436829,0.118576,0.000000
97.210007,59.597092,-586.436829,0.010417,0.004663,0.118446,265.101105,13.504894,1.184456,-586.436829,0.118576,0.000000
97.480003,59.547943,-586.481323,0.010412,0.004663,0.118446,264.882477,13.493756,1.184456,-586.481323,0.118576,0.000000
97.750008,59.488731,-586.525818,0.010421,0.004663,0.118446,264.619080,13.480340,1.184456,-586.525818,0.118576,0.000000
98.020004,59.458572,-586.525818,0.010425,0.004663,0.118446,264.484924,13.473505,1.184456,-586.525818,0.118576,0.000000
98.290001,59.410164,-586.481323,0.010404,0.004663,0.118446,264.269592,13.462536,1.184456,-586.481323,0.118576,0.000000
98.560005,59.366966,-586.481323,0.010408,0.004663,0.118446,264.077454,13.452746,1.184456,-586.481323,0.118576,0.000000
98.830002,59.320793,-586.481323,0.010408,0.004663,0.118446,263.872070,13.442284,1.184456,-586.481323,0.118576,0.000000
99.100006,59.278343,-586.525818,0.010408,0.004663,0.118446,263.683228,13.432664,1.184456,-586.525818,0.118576,0.000000
99.370003,59.235146,-586.525818,0.010438,0.004663,0.118446,263.491089,13.422876,1.184456,-586.525818,0.118576,0.000000
99.640007,59.213921,-586.570312,0.010417,0.004663,0.118446,263.396667,13.418066,1.184456,-586.570312,0.118576,0.000000
99.910004,59.159927,-586.525818,0.010404,0.004663,0.118446,263.156494,13.405831,1.184456,-586.525818,0.118576,0.000000
100.180008,59.128281,-586.570312,0.010421,0.004663,0.118446,263.015717,13.398660,1.184456,-586.570312,0.118576,0.000000
100.450005,59.097000,-586.570312,0.010404,0.004663,0.118446,262.876587,13.391572,1.184456,-586.570312,0.118576,0.000000
100.720001,59.056412,-586.614807,0.010412,0.004663,0.118446,262.696045,13.382375,1.184456,-586.614807,0.118576,0.000000
100.990005,59.001297,-586.525818,0.010421,0.004663,0.118446,262.450867,13.369885,1.184456,-586.525818,0.118576,0.000000
101.260002,58.977097,-586.525818,0.010421,0.004663,0.118446,262.343231,13.364401,1.184456,-586.525818,0.118576,0.000000
101.530006,58.921982,-586.570312,0.010421,0.004663,0.118446,262.098053,13.351912,1.184456,-586.570312,0.118576,0.000000
101.800003,58.901131,-586.570312,0.010417,0.004663,0.118446,262.005310,13.347187,1.184456,-586.570312,0.118576,0.000000
102.070007,58.885864,-586.614807,0.010430,0.004663,0.118446,261.937408,13.343727,1.184456,-586.614807,0.118576,0.000000
102.340004,58.835968,-586.570312,0.010425,0.004663,0.118446,261.715454,13.332421,1.184456,-586.570312,0.118576,0.000000
102.610008,58.805061,-586.659241,0.010412,0.004663,0.118446,261.577972,13.325418,1.184456,-586.659241,0.118576,0.000000
102.880005,58.773407,-586.659241,0.010421,0.004663,0.118446,261.437164,13.318245,1.184456,-586.659241,0.118576,0.000000
103.150002,58.738777,-586.659241,0.010412,0.004663,0.118446,261.283142,13.310397,1.184456,-586.659241,0.118576,0.000000
103.420006,58.712334,-586.614807,0.010430,0.004663,0.118446,261.165497,13.304405,1.184456,-586.614807,0.118576,0.000000
103.690002,58.687019,-586.659241,0.010417,0.004663,0.118446,261.052887,13.298669,1.184456,-586.659241,0.118576,0.000000
103.960007,58.638977,-586.659241,0.010417,0.004663,0.118446,260.839203,13.287782,1.184456,-586.659241,0.118576,0.000000
104.230003,58.610306,-586.614807,0.010430,0.004663,0.118446,260.711670,13.281285,1.184456,-586.614807,0.118576,0.000000
104.500008,58.578285,-586.659241,0.010421,0.004663,0.118446,260.569214,13.274029,1.184456,-586.659241,0.118576,0.000000
104.770004,58.553337,-586.659241,0.010412,0.004663,0.118446,260.458252,13.268375,1.184456,-586.659241,0.118576,0.000000
105.040009,58.525032,-586.614807,0.010425,0.004663,0.118446,260.332336,13.261962,1.184456,-586.614807,0.118576,0.000000
105.310005,58.515724,-586.659241,0.010430,0.004663,0.118446,260.290955,13.259853,1.184456,-586.659241,0.118576,0.000000
105.580002,58.469925,-586.748230,0.010421,0.004663,0.118446,260.087219,13.249475,1.184456,-586.748230,0.118576,0.000000
105.850006,58.440880,-586.703735,0.010430,0.004663,0.118446,259.958008,13.242892,1.184456,-586.703735,0.118576,0.000000
106.120003,58.418533,-586.703735,0.010421,0.004663,0.118446,259.858612,13.237829,1.184456,-586.703735,0.118576,0.000000
106.390007,58.375343,-586.659241,0.010412,0.004663,0.118446,259.666504,13.228043,1.184456,-586.659241,0.118576,0.000000
106.660004,58.343315,-586.659241,0.010421,0.004663,0.118446,259.524017,13.220784,1.184456,-586.659241,0.118576,0.000000
106.930008,58.330658,-586.703735,0.010417,0.004663,0.118446,259.467712,13.217916,1.184456,-586.703735,0.118576,0.000000
107.200005,58.300117,-586.703735,0.010425,0.004663,0.118446,259.331879,13.210996,1.184456,-586.703735,0.118576,0.000000
107.470009,58.279640,-586.659241,0.010425,0.004663,0.118446,259.240784,13.206355,1.184456,-586.659241,0.118576,0.000000
107.740005,58.281502,-586.703735,0.010421,0.004663,0.118446,259.249054,13.206777,1.184456,-586.703735,0.118576,0.000000
108.010002,58.226021,-586.703735,0.010434,0.004663,0.118446,259.002289,13.194205,1.184456,-586.703735,0.118576,0.000000
108.280006,58.207397,-586.748230,0.010434,0.004663,0.118446,258.919434,13.189984,1.184456,-586.748230,0.118576,0.000000
108.550003,58.188408,-586.792725,0.010434,0.004663,0.118446,258.834961,13.185681,1.184456,-586.792725,0.118576,0.000000
108.820007,58.156013,-586.792725,0.010425,0.004663,0.118446,258.690857,13.178341,1.184456,-586.792725,0.118576,0.000000
109.090004,58.130692,-586.792725,0.010417,0.004663,0.118446,258.578217,13.172604,1.184456,-586.792725,0.118576,0.000000
109.360008,58.103134,-586.792725,0.010434,0.004663,0.118446,258.455658,13.166358,1.184456,-586.792725,0.118576,0.000000
109.630005,58.080421,-586.792725,0.010430,0.004663,0.118446,258.354614,13.161212,1.184456,-586.792725,0.118576,0.000000
109.900002,58.069626,-586.748230,0.010434,0.004663,0.118446,258.306610,13.158766,1.184456,-586.748230,0.118576,0.000000
110.170006,58.051376,-586.792725,0.010421,0.004663,0.118446,258.225433,13.154630,1.184456,-586.792725,0.118576,0.000000
110.440002,58.012276,-586.792725,0.010425,0.004663,0.118446,258.051483,13.145769,1.184456,-586.792725,0.118576,0.000000
110.710007,57.997383,-586.881653,0.010425,0.004663,0.118446,257.985260,13.142395,1.184456,-586.881653,0.118576,0.000000
110.980003,57.969078,-586.792725,0.010434,0.004663,0.118446,257.859344,13.135981,1.184456,-586.792725,0.118576,0.000000
111.250008,57.943390,-586.748230,0.010434,0.004663,0.118446,257.745056,13.130159,1.184456,-586.748230,0.118576,0.000000
111.520004,57.911362,-586.881653,0.010430,0.004663,0.118446,257.602600,13.122903,1.184456,-586.881653,0.118576,0.000000
111.790009,57.888275,-586.792725,0.010434,0.004663,0.118446,257.499908,13.117671,1.184456,-586.792725,0.118576,0.000000
112.060005,57.862953,-586.926147,0.010430,0.004663,0.118446,257.387268,13.111933,1.184456,-586.926147,0.118576,0.000000
112.330002,57.855507,-586.837158,0.010434,0.004663,0.118446,257.354156,13.110246,1.184456,-586.837158,0.118576,0.000000
112.600006,57.839493,-586.881653,0.010425,0.004663,0.118446,257.282928,13.106617,1.184456,-586.881653,0.118576,0.000000
112.870003,57.807098,-586.837158,0.010417,0.004663,0.118446,257.138824,13.099276,1.184456,-586.837158,0.118576,0.000000
113.140007,57.787361,-586.881653,0.010430,0.004663,0.118446,257.051025,13.094803,1.184456,-586.881653,0.118576,0.000000
113.410004,57.772469,-586.926147,0.010412,0.004663,0.118446,256.984772,13.091429,1.184456,-586.926147,0.118576,0.000000
113.680008,57.738953,-586.837158,0.010421,0.004663,0.118446,256.835693,13.083834,1.184456,-586.837158,0.118576,0.000000
113.950005,57.719589,-586.837158,0.010430,0.004663,0.118446,256.749542,13.079446,1.184456,-586.837158,0.118576,0.000000
114.220009,57.701721,-586.881653,0.010430,0.004663,0.118446,256.670074,13.075397,1.184456,-586.881653,0.118576,0.000000
114.490005,57.700226,-586.970642,0.010408,0.004663,0.118446,256.663422,13.075058,1.184456,-586.970642,0.118576,0.000000
114.600006,57.689056,-586.881653,0.010417,0.004663,0.118446,256.613739,13.072527,1.184456,-586.881653,0.118576,0.000000