File: Data/compression 7/AutoHeating-12-7-2-3-240320_03202024_204950.csv
Time (sec),S:Load (lbs),S:HL1 (DIM),S:LVDT (in),S:Position (in),Ch:Position (mm),Ch:Load (N),Ch:Stress (MPa),Ch:Strain (mm/mm),Ch:HL1 (DIM),Set Point (),Cycles ()
0.010000,0.011917,-602.894836,-0.000009,-0.000000,-0.000000,0.053010,0.002700,-0.000000,-602.894836,0.000191,0.000000
0.260000,0.014519,-602.939270,-0.000009,-0.000000,-0.000000,0.064583,0.003290,-0.000000,-602.939270,0.000191,0.000000
0.510000,0.013779,-602.983765,0.000004,0.000091,0.002324,0.061291,0.003122,0.023239,-602.983765,0.003122,0.000000
0.760000,0.031654,-602.983765,0.000078,0.000242,0.006140,0.140806,0.007173,0.061399,-602.983765,0.007285,0.000000
1.010000,0.004471,-602.939270,0.000259,0.000413,0.010485,0.019887,0.001013,0.104845,-602.939270,0.011447,0.000000
1.260000,-0.017502,-602.939270,0.000423,0.000575,0.014595,-0.077852,-0.003966,0.145953,-602.939270,0.015610,0.000000
1.510000,0.027557,-602.894836,0.000608,0.000734,0.018654,0.122581,0.006245,0.186539,-602.894836,0.019790,0.000000
1.760000,-0.007446,-602.983765,0.000750,0.000906,0.023007,-0.033123,-0.001687,0.230072,-602.983765,0.023953,0.000000
2.010000,-0.005959,-602.983765,0.000927,0.001067,0.027109,-0.026505,-0.001350,0.271093,-602.983765,0.028115,0.000000
2.260000,0.023834,-602.939270,0.001095,0.001232,0.031298,0.106020,0.005401,0.312981,-602.939270,0.032278,0.000000
2.510000,0.032021,-602.983765,0.001250,0.001387,0.035218,0.142435,0.007256,0.352181,-602.983765,0.036441,0.000000
2.760000,0.024200,-602.983765,0.001427,0.001557,0.039554,0.107649,0.005484,0.395540,-602.983765,0.040604,0.000000
3.010000,0.001488,-602.983765,0.001582,0.001722,0.043751,0.006618,0.000337,0.437515,-602.983765,0.044766,0.000000
3.260000,0.034630,-602.939270,0.001742,0.001878,0.047689,0.154041,0.007847,0.476885,-602.939270,0.048946,0.000000
3.510000,0.005585,-602.939270,0.001923,0.002052,0.052129,0.024842,0.001266,0.521290,-602.939270,0.053109,0.000000
3.760000,-0.048409,-603.028259,0.002091,0.002213,0.056214,-0.215332,-0.010970,0.562136,-603.028259,0.057272,0.000000
4.010000,0.021599,-603.028259,0.002242,0.002377,0.060368,0.096076,0.004894,0.603676,-603.028259,0.061434,0.000000
4.260000,0.035751,-603.028259,0.002410,0.002539,0.064495,0.159030,0.008101,0.644954,-603.028259,0.065597,0.000000
4.510000,-0.005211,-602.983765,0.002561,0.002703,0.068650,-0.023179,-0.001181,0.686497,-602.983765,0.069759,0.000000
4.760000,0.030907,-602.983765,0.002751,0.002866,0.072804,0.137480,0.007004,0.728036,-602.983765,0.073922,0.000000
5.010000,0.053619,-603.028259,0.002897,0.003028,0.076914,0.238511,0.012150,0.769140,-603.028259,0.078085,0.000000
5.260000,0.026810,-603.028259,0.003096,0.003202,0.081337,0.119255,0.006075,0.813370,-603.028259,0.082265,0.000000
5.510000,-0.013779,-603.028259,0.003247,0.003361,0.085361,-0.061291,-0.003122,0.853611,-603.028259,0.086428,0.000000
5.760000,0.146713,-602.983765,0.003402,0.003524,0.089506,0.652613,0.033246,0.895063,-602.983765,0.090590,0.000000
6.010000,0.614418,-603.028259,0.003523,-0.000001,-0.000017,2.733068,0.139229,-0.000170,-603.028259,0.000199,0.000000
6.260000,0.545151,-603.072754,0.003510,-0.000001,-0.000017,2.424952,0.123533,-0.000170,-603.072754,0.000199,0.000000
6.510000,0.574944,-603.072754,0.003514,-0.000001,-0.000017,2.557477,0.130284,-0.000170,-603.072754,0.000260,0.000000
6.760000,0.596169,-603.072754,0.003523,-0.000001,-0.000017,2.651890,0.135094,-0.000170,-603.072754,0.000685,0.000000
7.010000,0.568611,-603.072754,0.003523,0.000008,0.000191,2.529309,0.128849,0.001908,-603.072754,0.001101,0.000000
7.260000,0.845284,-603.072754,0.003544,0.000024,0.000598,3.760009,0.191544,0.005984,-603.072754,0.001518,0.000000
7.510000,1.018066,-603.117187,0.003561,0.000040,0.001015,4.528585,0.230697,0.010147,-603.117187,0.001934,0.000000
7.760000,1.169250,-603.072754,0.003553,0.000062,0.001570,5.201086,0.264956,0.015700,-603.072754,0.002350,0.000000
8.010000,1.316338,-603.072754,0.003583,0.000079,0.002012,5.855362,0.298286,0.020121,-603.072754,0.002767,0.000000
8.260000,1.447037,-603.072754,0.003591,0.000095,0.002420,6.436741,0.327903,0.024197,-603.072754,0.003183,0.000000
8.510000,1.551674,-603.072754,0.003609,0.000111,0.002827,6.902190,0.351614,0.028273,-603.072754,0.003599,0.000000
8.760000,1.692802,-603.161682,0.003617,0.000126,0.003209,7.529961,0.383595,0.032088,-603.161682,0.004015,0.000000
9.010000,1.893143,-603.161682,0.003639,0.000141,0.003582,8.421120,0.428992,0.035816,-603.161682,0.004432,0.000000
9.260000,2.031288,-603.117187,0.003660,0.000156,0.003972,9.035621,0.460296,0.039719,-603.117187,0.004848,0.000000
9.510000,2.117310,-603.206177,0.003652,0.000168,0.004267,9.418263,0.479789,0.042671,-603.206177,0.005264,0.000000
9.760000,2.404411,-603.117187,0.003686,0.000193,0.004900,10.695355,0.544847,0.048999,-603.117187,0.005680,0.000000
10.010000,2.523941,-603.117187,0.003699,0.000210,0.005325,11.227051,0.571933,0.053250,-603.117187,0.006097,0.000000
10.260000,2.636024,-603.117187,0.003699,0.000225,0.005715,11.725622,0.597332,0.057152,-603.117187,0.006513,0.000000
10.510000,2.814766,-603.117187,0.003725,0.000242,0.006149,12.520704,0.637835,0.061489,-603.117187,0.006929,0.000000
10.760000,2.891846,-603.161682,0.003742,0.000254,0.006461,12.863572,0.655302,0.064608,-603.161682,0.007346,0.000000
11.010000,3.100372,-603.161682,0.003747,0.000272,0.006903,13.791144,0.702554,0.069033,-603.161682,0.007762,0.000000
11.260000,3.262352,-603.161682,0.003764,0.000289,0.007328,14.511666,0.739260,0.073283,-603.161682,0.008178,0.000000
11.510000,3.307785,-603.117187,0.003773,0.000298,0.007571,14.713762,0.749555,0.075709,-603.117187,0.008594,0.000000
11.760000,3.607170,-603.161682,0.003803,0.000321,0.008144,16.045494,0.817396,0.081436,-603.161682,0.009019,0.000000
12.010000,3.737129,-603.206177,0.003820,0.000338,0.008594,16.623581,0.846846,0.085944,-603.206177,0.009436,0.000000
12.260000,3.851448,-603.161682,0.003833,0.000355,0.009019,17.132097,0.872751,0.090194,-603.161682,0.009852,0.000000
12.510000,3.997421,-603.161682,0.003842,0.000370,0.009401,17.781418,0.905829,0.094009,-603.161682,0.010268,0.000000
12.760000,4.098701,-603.206177,0.003854,0.000385,0.009782,18.231936,0.928779,0.097824,-603.206177,0.010684,0.000000
13.010000,4.385056,-603.161682,0.003867,0.000405,0.010277,19.505701,0.993668,0.102767,-603.161682,0.011101,0.000000
13.260000,4.427879,-603.250671,0.003893,0.000418,0.010615,19.696192,1.003372,0.106151,-603.250671,0.011517,0.000000
13.510000,4.510178,-603.206177,0.003911,0.000428,0.010884,20.062271,1.022021,0.108838,-603.206177,0.011933,0.000000
13.760000,4.882545,-603.161682,0.003932,0.000454,0.011543,21.718647,1.106401,0.115428,-603.161682,0.012349,0.000000
14.010000,4.943993,-603.206177,0.003945,0.000469,0.011925,21.991978,1.120325,0.119247,-603.206177,0.012766,0.000000
14.260000,5.057938,-603.206177,0.003954,0.000484,0.012289,22.498831,1.146145,0.122888,-603.206177,0.013182,0.000000
14.510000,5.197945,-603.206177,0.003971,0.000501,0.012723,23.121613,1.177871,0.127225,-603.206177,0.013598,0.000000
14.760000,5.489517,-603.206177,0.003988,0.000521,0.013225,24.418592,1.243942,0.132252,-603.206177,0.014015,0.000000
15.010001,5.597878,-603.250671,0.003988,0.000536,0.013624,24.900602,1.268497,0.136241,-603.250671,0.014431,0.000000
15.260001,5.447433,-603.250671,0.004018,0.000543,0.013780,24.231394,1.234406,0.137804,-603.250671,0.014847,0.000000
15.510001,5.927795,-603.250671,0.004023,0.000568,0.014431,26.368151,1.343258,0.144307,-603.250671,0.015263,0.000000
15.760001,6.076744,-603.206177,0.004040,0.000585,0.014864,27.030708,1.377010,0.148644,-603.206177,0.015680,0.000000
16.010000,6.011581,-603.250671,0.004053,0.000596,0.015133,26.740850,1.362244,0.151331,-603.250671,0.016096,0.000000
16.260000,6.275963,-603.250671,0.004074,0.000614,0.015593,27.916878,1.422154,0.155930,-603.250671,0.016512,0.000000
16.510000,6.311714,-603.339600,0.004087,0.000628,0.015940,28.075907,1.430255,0.159397,-603.339600,0.016928,0.000000
16.760000,6.563438,-603.250671,0.004096,0.000647,0.016443,29.195633,1.487296,0.164427,-603.250671,0.017345,0.000000
17.010000,6.788353,-603.339600,0.004122,0.000665,0.016894,30.196102,1.538263,0.168939,-603.339600,0.017770,0.000000
17.260000,6.582054,-603.339600,0.004126,0.000671,0.017041,29.278439,1.491515,0.170411,-603.339600,0.018186,0.000000
17.510000,6.771965,-603.339600,0.004118,0.000686,0.017431,30.123205,1.534549,0.174313,-603.339600,0.018602,0.000000
17.760000,7.317490,-603.250671,0.004165,0.000715,0.018151,32.549820,1.658167,0.181512,-603.250671,0.019018,0.000000
18.010000,7.346535,-603.339600,0.004178,0.000730,0.018541,32.679020,1.664749,0.185414,-603.339600,0.019435,0.000000
18.260000,7.423248,-603.339600,0.004195,0.000745,0.018923,33.020256,1.682132,0.189230,-603.339600,0.019851,0.000000
18.510000,7.666779,-603.339600,0.004217,0.000766,0.019461,34.103535,1.737317,0.194608,-603.339600,0.020267,0.000000
18.760000,7.753166,-603.339600,0.004225,0.000781,0.019834,34.487804,1.756893,0.198336,-603.339600,0.020683,0.000000
19.010000,7.755775,-603.384094,0.004234,0.000793,0.020155,34.499413,1.757484,0.201546,-603.384094,0.021100,0.000000
19.260000,7.826523,-603.384094,0.004243,0.000807,0.020501,34.814114,1.773515,0.205013,-603.384094,0.021516,0.000000
19.510000,8.194054,-603.295166,0.004260,0.000827,0.021013,36.448971,1.856799,0.210130,-603.295166,0.021932,0.000000
19.760000,8.395882,-603.384094,0.004273,0.000847,0.021525,37.346748,1.902534,0.215247,-603.384094,0.022349,0.000000
20.010000,8.337044,-603.339600,0.004290,0.000859,0.021828,37.085022,1.889201,0.218282,-603.339600,0.022765,0.000000
20.260000,8.553024,-603.339600,0.004303,0.000878,0.022314,38.045753,1.938143,0.223138,-603.339600,0.023181,0.000000
20.510000,8.653938,-603.428589,0.004329,0.000896,0.022765,38.494640,1.961010,0.227650,-603.428589,0.023597,0.000000
20.760000,8.727669,-603.384094,0.004342,0.000909,0.023094,38.822609,1.977718,0.230943,-603.384094,0.024014,0.000000
21.010000,8.675537,-603.339600,0.004346,0.000920,0.023380,38.590717,1.965905,0.233804,-603.339600,0.024430,0.000000
21.260000,8.887039,-603.384094,0.004359,0.000936,0.023771,39.531525,2.013832,0.237707,-603.384094,0.024846,0.000000
21.510000,9.517471,-603.295166,0.004368,0.000966,0.024543,42.335827,2.156690,0.245428,-603.295166,0.025262,0.000000
21.760000,9.331657,-603.517517,0.004402,0.000977,0.024820,41.509285,2.114584,0.248202,-603.517517,0.025679,0.000000
22.010000,9.389374,-603.428589,0.004411,0.000994,0.025254,41.766022,2.127663,0.252540,-603.428589,0.026104,0.000000
22.260000,9.424744,-603.428589,0.004441,0.001007,0.025566,41.923355,2.135678,0.255658,-603.428589,0.026520,0.000000
22.510000,9.428101,-603.428589,0.004432,0.001017,0.025844,41.938286,2.136438,0.258436,-603.428589,0.026936,0.000000
22.760000,9.813873,-603.473083,0.004445,0.001040,0.026425,43.654289,2.223855,0.264246,-603.473083,0.027352,0.000000
23.010000,9.912186,-603.428589,0.004462,0.001054,0.026771,44.091602,2.246133,0.267713,-603.428589,0.027769,0.000000
23.260000,9.870850,-603.473083,0.004484,0.001066,0.027084,43.907730,2.236767,0.270836,-603.473083,0.028185,0.000000
23.510000,10.469254,-603.473083,0.004488,0.001094,0.027786,46.569565,2.372367,0.277860,-603.473083,0.028601,0.000000
23.760000,10.424568,-603.517517,0.004497,0.001110,0.028194,46.370796,2.362241,0.281937,-603.517517,0.029018,0.000000
24.010000,10.410416,-603.473083,0.004518,0.001124,0.028558,46.307842,2.359034,0.285578,-603.473083,0.029434,0.000000
24.260000,10.609634,-603.517517,0.004531,0.001139,0.028939,47.194012,2.404177,0.289393,-603.517517,0.029850,0.000000
24.510000,10.884071,-603.473083,0.004540,0.001159,0.029434,48.414768,2.466366,0.294336,-603.473083,0.030266,0.000000
24.760000,10.792847,-603.473083,0.004566,0.001170,0.029720,48.008980,2.445694,0.297201,-603.473083,0.030683,0.000000
25.010002,10.728798,-603.384094,0.004579,0.001181,0.030006,47.724075,2.431180,0.300063,-603.384094,0.031099,0.000000
25.260002,11.382683,-603.473083,0.004587,0.001209,0.030717,50.632702,2.579353,0.307175,-603.473083,0.031515,0.000000
25.510002,11.529770,-603.473083,0.004613,0.001227,0.031160,51.286980,2.612683,0.311595,-603.473083,0.031931,0.000000
25.760002,11.470932,-603.562012,0.004618,0.001241,0.031524,51.025253,2.599350,0.315236,-603.562012,0.032348,0.000000
26.010002,11.558441,-603.517517,0.004635,0.001258,0.031949,51.414513,2.619180,0.319487,-603.517517,0.032764,0.000000
26.260002,11.343208,-603.517517,0.004635,0.001267,0.032174,50.457111,2.570408,0.321743,-603.517517,0.033180,0.000000
26.510002,11.740906,-603.562012,0.004652,0.001286,0.032669,52.226158,2.660527,0.326686,-603.562012,0.033597,0.000000
26.760002,11.979591,-603.517517,0.004669,0.001304,0.033119,53.287884,2.714614,0.331193,-603.517517,0.034013,0.000000
27.010002,12.037315,-603.606506,0.004682,0.001318,0.033484,53.544655,2.727695,0.334838,-603.606506,0.034438,0.000000
27.260002,12.322922,-603.606506,0.004695,0.001337,0.033961,54.815094,2.792414,0.339607,-603.606506,0.034854,0.000000
27.510002,12.552673,-603.562012,0.004712,0.001356,0.034446,55.837078,2.844476,0.344463,-603.562012,0.035270,0.000000
27.760002,12.378036,-603.562012,0.004730,0.001368,0.034750,55.060257,2.804903,0.347499,-603.562012,0.035687,0.000000
28.010002,12.597359,-603.517517,0.004738,0.001387,0.035235,56.035851,2.854602,0.352355,-603.517517,0.036103,0.000000
28.260002,12.580231,-603.562012,0.004743,0.001400,0.035556,55.959660,2.850721,0.355564,-603.562012,0.036519,0.000000
28.510002,12.875153,-603.562012,0.004764,0.001418,0.036025,57.271538,2.917552,0.360246,-603.562012,0.036935,0.000000
28.760002,12.748917,-603.562012,0.004781,0.001430,0.036328,56.710014,2.888946,0.363282,-603.562012,0.037352,0.000000
29.010002,12.906059,-603.562012,0.004773,0.001446,0.036736,57.409019,2.924555,0.367358,-603.562012,0.037768,0.000000
29.260002,13.559944,-603.606506,0.004794,0.001472,0.037386,60.317642,3.072727,0.373864,-603.606506,0.038184,0.000000
29.510002,13.572601,-603.606506,0.004807,0.001489,0.037811,60.373947,3.075596,0.378111,-603.606506,0.038600,0.000000
29.760002,13.522705,-603.651001,0.004825,0.001503,0.038167,60.151997,3.064289,0.381669,-603.651001,0.039017,0.000000
30.010002,13.616173,-603.651001,0.004846,0.001521,0.038626,60.567760,3.085469,0.386264,-603.651001,0.039433,0.000000
30.260002,13.540581,-603.695496,0.004850,0.001533,0.038947,60.231510,3.068340,0.389473,-603.695496,0.039849,0.000000
30.510002,13.862312,-603.651001,0.004863,0.001551,0.039389,61.662643,3.141245,0.393894,-603.651001,0.040266,0.000000
30.760002,13.870132,-603.651001,0.004863,0.001564,0.039719,61.697430,3.143017,0.397191,-603.651001,0.040682,0.000000
31.010002,14.268196,-603.695496,0.004868,0.001585,0.040248,63.468105,3.233219,0.402482,-603.695496,0.041098,0.000000
31.260002,14.614128,-603.651001,0.004885,0.001605,0.040769,65.006889,3.311609,0.407686,-603.651001,0.041514,0.000000
31.510002,14.528114,-603.651001,0.004907,0.001621,0.041168,64.624283,3.292118,0.411675,-603.651001,0.041931,0.000000
31.760002,14.586945,-603.651001,0.004915,0.001637,0.041575,64.885971,3.305449,0.415748,-603.651001,0.042347,0.000000
32.010002,14.611153,-603.695496,0.004924,0.001650,0.041904,64.993652,3.310935,0.419045,-603.695496,0.042763,0.000000
32.260002,14.717278,-603.695496,0.004954,0.001666,0.042321,65.465721,3.334983,0.423208,-603.695496,0.043188,0.000000
32.510002,15.010704,-603.606506,0.004950,0.001685,0.042789,66.770943,3.401474,0.427890,-603.606506,0.043604,0.000000
32.760002,14.848351,-603.651001,0.004963,0.001696,0.043084,66.048759,3.364684,0.430838,-603.651001,0.044021,0.000000
33.010002,15.051666,-603.695496,0.004993,0.001713,0.043518,66.953156,3.410756,0.435176,-603.695496,0.044437,0.000000
33.260002,15.527557,-603.739929,0.004984,0.001734,0.044038,69.070023,3.518595,0.440380,-603.739929,0.044853,0.000000
33.510002,15.592728,-603.695496,0.005006,0.001752,0.044489,69.359917,3.533363,0.444888,-603.695496,0.045269,0.000000
33.760002,15.588997,-603.695496,0.005019,0.001766,0.044845,69.343323,3.532517,0.448446,-603.695496,0.045686,0.000000
34.010002,15.615067,-603.695496,0.005019,0.001780,0.045217,69.459282,3.538425,0.452174,-603.695496,0.046102,0.000000
34.260002,16.106224,-603.739929,0.005032,0.001801,0.045738,71.644066,3.649723,0.457378,-603.739929,0.046518,0.000000
34.510002,15.895836,-603.695496,0.005044,0.001813,0.046050,70.708206,3.602048,0.460497,-603.695496,0.046935,0.000000
34.760002,15.970306,-603.739929,0.005053,0.001827,0.046397,71.039474,3.618923,0.463968,-603.739929,0.047351,0.000000
35.010002,16.245117,-603.739929,0.005075,0.001845,0.046856,72.261887,3.681196,0.468562,-603.739929,0.047767,0.000000
35.260002,16.424980,-603.695496,0.005096,0.001862,0.047299,73.061958,3.721954,0.472987,-603.695496,0.048183,0.000000
35.510002,16.515465,-603.695496,0.005092,0.001878,0.047706,73.464455,3.742458,0.477063,-603.695496,0.048600,0.000000
35.760002,16.415665,-603.739929,0.005109,0.001893,0.048070,73.020523,3.719843,0.480704,-603.739929,0.049016,0.000000
36.010002,16.936615,-603.784424,0.005118,0.001913,0.048600,75.337830,3.837892,0.485996,-603.784424,0.049432,0.000000
36.260002,17.052422,-603.739929,0.005148,0.001930,0.049016,75.852959,3.864134,0.490159,-603.739929,0.049848,0.000000
36.510002,16.812241,-603.784424,0.005139,0.001941,0.049302,74.784584,3.809708,0.493020,-603.784424,0.050265,0.000000
36.760002,16.626801,-603.739929,0.005139,0.001952,0.049588,73.959702,3.767687,0.495882,-603.739929,0.050681,0.000000
37.010002,17.279572,-603.739929,0.005165,0.001977,0.050221,76.863373,3.915607,0.502210,-603.739929,0.051097,0.000000
37.260002,17.191322,-603.784424,0.005161,0.001989,0.050516,76.470818,3.895609,0.505162,-603.784424,0.051522,0.000000
37.510002,17.395378,-603.784424,0.005178,0.002009,0.051028,77.378510,3.941849,0.510276,-603.784424,0.051938,0.000000
37.760002,17.673912,-603.784424,0.005204,0.002025,0.051427,78.617485,4.004966,0.514265,-603.784424,0.052355,0.000000
38.010002,17.760307,-603.784424,0.005191,0.002041,0.051834,79.001793,4.024543,0.518341,-603.784424,0.052771,0.000000
38.260002,17.822121,-603.828918,0.005217,0.002057,0.052250,79.276749,4.038550,0.522505,-603.828918,0.053187,0.000000
38.510002,17.472458,-603.828918,0.005230,0.002067,0.052493,77.721375,3.959316,0.524935,-603.828918,0.053603,0.000000
38.760002,17.710777,-603.873413,0.005243,0.002082,0.052884,78.781471,4.013319,0.528837,-603.873413,0.054020,0.000000
39.010002,18.522179,-603.828918,0.005230,0.002108,0.053551,82.390762,4.197186,0.535513,-603.828918,0.054436,0.000000
39.260002,18.650650,-603.828918,0.005251,0.002126,0.053994,82.962234,4.226298,0.539938,-603.828918,0.054852,0.000000
39.510002,18.411957,-603.917847,0.005269,0.002139,0.054340,81.900475,4.172209,0.543405,-603.917847,0.055269,0.000000
39.760002,18.707619,-603.828918,0.005286,0.002158,0.054817,83.215645,4.239207,0.548174,-603.828918,0.055685,0.000000
40.010002,18.715065,-603.828918,0.005290,0.002173,0.055182,83.248764,4.240894,0.551819,-603.828918,0.056101,0.000000
40.260002,18.724007,-603.784424,0.005316,0.002190,0.055615,83.288544,4.242920,0.556152,-603.784424,0.056517,0.000000
40.510002,18.718788,-603.828918,0.005299,0.002205,0.055997,83.265327,4.241738,0.559968,-603.828918,0.056934,0.000000
40.760002,18.179222,-603.873413,0.005303,0.002213,0.056222,80.865219,4.119471,0.562223,-603.873413,0.057350,0.000000
41.010002,19.141434,-603.873413,0.005320,0.002240,0.056890,85.145348,4.337511,0.568900,-603.873413,0.057766,0.000000
41.260002,19.304909,-603.828918,0.005333,0.002255,0.057289,85.872520,4.374555,0.572889,-603.828918,0.058182,0.000000
41.510002,19.332832,-603.828918,0.005355,0.002274,0.057757,85.996735,4.380882,0.577575,-603.828918,0.058598,0.000000
41.760002,19.266182,-603.917847,0.005338,0.002288,0.058113,85.700256,4.365779,0.581129,-603.917847,0.059015,0.000000
42.010002,19.251656,-603.917847,0.005351,0.002304,0.058512,85.635643,4.362488,0.585118,-603.917847,0.059431,0.000000
42.260002,19.135849,-603.917847,0.005364,0.002317,0.058850,85.120506,4.336245,0.588502,-603.917847,0.059856,0.000000
42.510002,19.131378,-603.828918,0.005381,0.002332,0.059223,85.100624,4.335232,0.592230,-603.828918,0.060272,0.000000
42.760002,20.023582,-603.917847,0.005368,0.002357,0.059865,89.069344,4.537409,0.598649,-603.917847,0.060689,0.000000
43.010002,19.923042,-603.873413,0.005385,0.002373,0.060264,88.622116,4.514626,0.602639,-603.873413,0.061105,0.000000
43.260002,19.674675,-603.873413,0.005398,0.002387,0.060637,87.517326,4.458345,0.606367,-603.873413,0.061521,0.000000
43.510002,19.471359,-603.962341,0.005415,0.002402,0.061009,86.612930,4.412273,0.610095,-603.962341,0.061938,0.000000
43.760002,19.376030,-603.917847,0.005420,0.002416,0.061365,86.188889,4.390671,0.613649,-603.917847,0.062354,0.000000
44.010002,19.667221,-603.917847,0.005415,0.002435,0.061851,87.484169,4.456656,0.618509,-603.917847,0.062770,0.000000
44.260002,19.295967,-603.962341,0.005428,0.002445,0.062111,85.832748,4.372529,0.621109,-603.962341,0.063186,0.000000
44.510002,19.498543,-604.006836,0.005424,0.002462,0.062536,86.733849,4.418433,0.625359,-604.006836,0.063603,0.000000
44.760002,20.281639,-603.917847,0.005441,0.002489,0.063221,90.217239,4.595885,0.632210,-603.917847,0.064019,0.000000
45.010002,20.011665,-603.962341,0.005450,0.002502,0.063550,89.016335,4.534708,0.635503,-603.962341,0.064435,0.000000
45.260002,19.810211,-603.917847,0.005458,0.002517,0.063932,88.120224,4.489058,0.639322,-603.917847,0.064851,0.000000
45.510002,19.739464,-603.917847,0.005476,0.002534,0.064366,87.805519,4.473026,0.643655,-603.917847,0.065267,0.000000
45.760002,19.774094,-603.917847,0.005467,0.002551,0.064808,87.959564,4.480874,0.648080,-603.917847,0.065684,0.000000
46.010002,19.873894,-603.962341,0.005480,0.002568,0.065216,88.403496,4.503489,0.652156,-603.962341,0.066100,0.000000
46.260002,19.494072,-604.006836,0.005480,0.002577,0.065458,86.713966,4.417420,0.654582,-604.006836,0.066516,0.000000
46.510002,19.441940,-603.917847,0.005476,0.002595,0.065909,86.482071,4.405606,0.659094,-603.917847,0.066932,0.000000
46.760002,20.394470,-603.962341,0.005493,0.002620,0.066542,90.719131,4.621453,0.665422,-603.962341,0.067349,0.000000
47.010002,20.316643,-604.006836,0.005501,0.002635,0.066932,90.372940,4.603817,0.669325,-604.006836,0.067765,0.000000
47.260002,19.879478,-604.006836,0.005497,0.002648,0.067271,88.428337,4.504754,0.672708,-604.006836,0.068181,0.000000
47.510002,19.733879,-604.051331,0.005514,0.002663,0.067644,87.780678,4.471761,0.676436,-604.051331,0.068607,0.000000
47.760002,20.105507,-604.006836,0.005510,0.002682,0.068121,89.433762,4.555973,0.681209,-604.006836,0.069022,0.000000
48.010002,20.042572,-603.962341,0.005519,0.002698,0.068520,89.153816,4.541712,0.685198,-603.962341,0.069439,0.000000
48.260002,19.698128,-604.095825,0.005527,0.002710,0.068823,87.621651,4.463659,0.688230,-604.095825,0.069855,0.000000
48.510002,19.706322,-604.006836,0.005532,0.002726,0.069248,87.658096,4.465517,0.692481,-604.006836,0.070271,0.000000
48.760002,20.970154,-604.051331,0.005545,0.002752,0.069907,93.279900,4.751905,0.699074,-604.051331,0.070688,0.000000
49.010002,20.630180,-603.962341,0.005558,0.002765,0.070228,91.767624,4.674866,0.702280,-603.962341,0.071104,0.000000
49.260002,20.712845,-604.051331,0.005553,0.002783,0.070679,92.135338,4.693598,0.706791,-604.051331,0.071520,0.000000
49.510002,20.317017,-604.051331,0.005562,0.002795,0.070991,90.374603,4.603902,0.709914,-604.051331,0.071936,0.000000
49.760002,20.745239,-604.006836,0.005558,0.002814,0.071486,92.279434,4.700938,0.714857,-604.006836,0.072353,0.000000
50.010002,20.464470,-604.095825,0.005575,0.002825,0.071763,91.030510,4.637315,0.717631,-604.095825,0.072769,0.000000
50.260002,20.462242,-604.006836,0.005570,0.002842,0.072188,91.020599,4.636810,0.721882,-604.006836,0.073185,0.000000
50.510002,21.147774,-604.095825,0.005588,0.002864,0.072752,94.069992,4.792154,0.727517,-604.095825,0.073601,0.000000
50.760002,21.427055,-604.095825,0.005596,0.002883,0.073237,95.312302,4.855440,0.732373,-604.095825,0.074018,0.000000
51.010002,21.271774,-604.051331,0.005575,0.002898,0.073619,94.621574,4.820253,0.736189,-604.051331,0.074434,0.000000
51.260002,21.277733,-604.140259,0.005605,0.002915,0.074035,94.648087,4.821603,0.740352,-604.140259,0.074850,0.000000
51.510002,21.020050,-604.051331,0.005605,0.002927,0.074347,93.501854,4.763212,0.743474,-604.051331,0.075267,0.000000
51.760002,21.348862,-604.095825,0.005618,0.002945,0.074816,94.964478,4.837721,0.748156,-604.095825,0.075683,0.000000
52.010002,21.323166,-604.095825,0.005605,0.002960,0.075171,94.850182,4.831898,0.751714,-604.095825,0.076099,0.000000
52.260002,21.192093,-604.140259,0.005618,0.002972,0.075501,94.267136,4.802197,0.755007,-604.140259,0.076515,0.000000
52.510002,22.310326,-604.140259,0.005635,0.003000,0.076194,99.241287,5.055592,0.761945,-604.140259,0.076940,0.000000
52.760002,21.973328,-604.140259,0.005644,0.003012,0.076515,97.742241,4.979228,0.765154,-604.140259,0.077357,0.000000
53.010002,22.085037,-604.184753,0.005644,0.003028,0.076914,98.239151,5.004541,0.769144,-604.184753,0.077773,0.000000
53.260002,22.060089,-604.140259,0.005652,0.003045,0.077339,98.128174,4.998888,0.773394,-604.140259,0.078189,0.000000
53.510002,22.365807,-604.140259,0.005648,0.003063,0.077790,99.488075,5.068164,0.777902,-604.140259,0.078605,0.000000
53.760002,22.457413,-604.184753,0.005657,0.003079,0.078207,99.895561,5.088922,0.782065,-604.184753,0.079022,0.000000
54.010002,22.218346,-604.184753,0.005670,0.003089,0.078467,98.832138,5.034749,0.784666,-604.184753,0.079438,0.000000
54.260002,22.400810,-604.184753,0.005661,0.003107,0.078918,99.643784,5.076096,0.789177,-604.184753,0.079854,0.000000
54.510002,23.105713,-604.140259,0.005665,0.003129,0.079481,102.779343,5.235829,0.794813,-604.140259,0.080270,0.000000
54.760002,23.221146,-604.184753,0.005674,0.003145,0.079871,103.292816,5.261987,0.798715,-604.184753,0.080687,0.000000
55.010002,22.988045,-604.184753,0.005687,0.003157,0.080192,102.255928,5.209165,0.801925,-604.184753,0.081103,0.000000
55.260002,23.120979,-604.140259,0.005678,0.003174,0.080626,102.847252,5.239289,0.806262,-604.140259,0.081519,0.000000
55.510002,23.675812,-604.184753,0.005687,0.003193,0.081112,105.315269,5.365016,0.811118,-604.184753,0.081936,0.000000
55.760002,23.517555,-604.140259,0.005696,0.003205,0.081415,104.611313,5.329154,0.814154,-604.140259,0.082352,0.000000
56.010002,23.629265,-604.184753,0.005713,0.003222,0.081840,105.108223,5.354468,0.818404,-604.184753,0.082768,0.000000
56.260002,24.087288,-604.229248,0.005713,0.003240,0.082300,107.145607,5.458258,0.822999,-604.229248,0.083184,0.000000
56.510002,24.376244,-604.273743,0.005717,0.003258,0.082751,108.430946,5.523736,0.827507,-604.273743,0.083601,0.000000
56.760002,24.295815,-604.229248,0.005734,0.003271,0.083080,108.073181,5.505510,0.830803,-604.229248,0.084017,0.000000
57.010002,24.411995,-604.229248,0.005717,0.003289,0.083531,108.589973,5.531837,0.835315,-604.229248,0.084433,0.000000
57.260002,24.683823,-604.229248,0.005734,0.003303,0.083896,109.799126,5.593434,0.838956,-604.229248,0.084849,0.000000
57.510002,25.221161,-604.229248,0.005739,0.003323,0.084416,112.189323,5.715197,0.844160,-604.229248,0.085274,0.000000
57.760002,25.260628,-604.140259,0.005734,0.003337,0.084763,112.364883,5.724140,0.847627,-604.140259,0.085691,0.000000
58.010002,25.053963,-604.184753,0.005747,0.003353,0.085170,111.445595,5.677309,0.851704,-604.184753,0.086107,0.000000
58.260002,26.084320,-604.273743,0.005760,0.003373,0.085673,116.028854,5.910791,0.856734,-604.273743,0.086523,0.000000
58.510002,26.090279,-604.229248,0.005764,0.003386,0.086012,116.055359,5.912142,0.860117,-604.229248,0.086939,0.000000
58.760002,25.851212,-604.273743,0.005777,0.003398,0.086315,114.991936,5.857968,0.863153,-604.273743,0.087356,0.000000
59.010002,26.350937,-604.273743,0.005782,0.003418,0.086810,117.214821,5.971208,0.868096,-604.273743,0.087772,0.000000
59.260002,26.912102,-604.229248,0.005786,0.003438,0.087313,119.711006,6.098370,0.873126,-604.229248,0.088188,0.000000
59.510002,27.412941,-604.318176,0.005777,0.003454,0.087720,121.938850,6.211861,0.877199,-604.318176,0.088605,0.000000
59.760002,27.297508,-604.318176,0.005782,0.003464,0.087998,121.425385,6.185704,0.879977,-604.318176,0.089021,0.000000
60.010002,26.987320,-604.318176,0.005799,0.003477,0.088327,120.045593,6.115414,0.883270,-604.318176,0.089437,0.000000
60.260002,28.601555,-604.273743,0.005803,0.003503,0.088969,127.226067,6.481205,0.889689,-604.273743,0.089853,0.000000
60.510002,28.792953,-604.273743,0.005812,0.003517,0.089342,128.077454,6.524577,0.893417,-604.273743,0.090270,0.000000
60.760002,29.000366,-604.362671,0.005816,0.003534,0.089767,129.000076,6.571577,0.897667,-604.362671,0.090686,0.000000
61.010002,29.291931,-604.318176,0.005838,0.003550,0.090166,130.297012,6.637646,0.901657,-604.318176,0.091102,0.000000
61.260002,30.013596,-604.362671,0.005855,0.003568,0.090634,133.507141,6.801178,0.906339,-604.362671,0.091518,0.000000
61.510002,30.291382,-604.318176,0.005846,0.003584,0.091024,134.742798,6.864125,0.910241,-604.318176,0.091935,0.000000
61.760002,30.510712,-604.318176,0.005855,0.003599,0.091423,135.718430,6.913826,0.914230,-604.318176,0.092351,0.000000
62.010002,30.505127,-604.318176,0.005864,0.003609,0.091657,135.693588,6.912560,0.916573,-604.318176,0.092767,0.000000
62.260002,31.396210,-604.362671,0.005864,0.003629,0.092186,139.657318,7.114483,0.921864,-604.362671,0.093184,0.000000
62.510002,32.573654,-604.318176,0.005859,0.003652,0.092750,144.894852,7.381295,0.927500,-604.318176,0.093600,0.000000
62.760002,32.628761,-604.362671,0.005885,0.003665,0.093080,145.139984,7.393783,0.930797,-604.362671,0.094025,0.000000
63.010002,33.030556,-604.318176,0.005894,0.003681,0.093487,146.927246,7.484831,0.934869,-604.318176,0.094441,0.000000
63.260002,33.877327,-604.407166,0.005902,0.003699,0.093955,150.693878,7.676712,0.939555,-604.407166,0.094857,0.000000
63.510002,33.943611,-604.362671,0.005911,0.003709,0.094207,150.988724,7.691732,0.942068,-604.362671,0.095274,0.000000
63.760002,34.501427,-604.362671,0.005924,0.003724,0.094597,153.470016,7.818135,0.945970,-604.362671,0.095690,0.000000
64.010002,34.954231,-604.362671,0.005924,0.003744,0.095100,155.484192,7.920742,0.951000,-604.362671,0.096106,0.000000
64.260002,36.926689,-604.496155,0.005928,0.003769,0.095725,164.258118,8.367707,0.957245,-604.496155,0.096522,0.000000
64.510002,37.326241,-604.362671,0.005950,0.003783,0.096080,166.035416,8.458247,0.960799,-604.362671,0.096939,0.000000
64.760002,37.706436,-604.407166,0.005941,0.003797,0.096436,167.726608,8.544400,0.964357,-604.407166,0.097355,0.000000
65.010002,37.986084,-604.407166,0.005950,0.003809,0.096748,168.970535,8.607769,0.967480,-604.407166,0.097771,0.000000
65.260002,38.999687,-604.362671,0.005959,0.003828,0.097242,173.479279,8.837455,0.972423,-604.362671,0.098187,0.000000
65.510002,39.380997,-604.407166,0.005959,0.003842,0.097580,175.175415,8.923862,0.975803,-604.407166,0.098604,0.000000
65.760002,39.967110,-604.318176,0.005976,0.003859,0.098014,177.782578,9.056677,0.980140,-604.318176,0.099020,0.000000
66.010002,41.397018,-604.407166,0.005984,0.003880,0.098543,184.143127,9.380698,0.985431,-604.407166,0.099436,0.000000
66.260002,42.557701,-604.451660,0.006002,0.003897,0.098994,189.306107,9.643713,0.989939,-604.451660,0.099852,0.000000
66.510002,43.068970,-604.407166,0.006006,0.003911,0.099341,191.580353,9.759567,0.993410,-604.407166,0.100269,0.000000
66.760002,43.744080,-604.451660,0.006019,0.003926,0.099723,194.583389,9.912550,0.997225,-604.451660,0.100685,0.000000
67.010002,44.303383,-604.496155,0.006015,0.003941,0.100113,197.071289,10.039289,1.001127,-604.496155,0.101101,0.000000
67.260002,45.617485,-604.407166,0.006023,0.003962,0.100642,202.916702,10.337070,1.006419,-604.407166,0.101518,0.000000
67.510002,46.153702,-604.451660,0.006023,0.003975,0.100971,205.301926,10.458578,1.009712,-604.451660,0.101934,0.000000
67.760002,46.188332,-604.451660,0.006040,0.003982,0.101145,205.455963,10.466426,1.011445,-604.451660,0.102359,0.000000
68.010002,48.622162,-604.496155,0.006058,0.004013,0.101942,216.282181,11.017939,1.019424,-604.496155,0.102775,0.000000
68.260002,49.547134,-604.451660,0.006049,0.004030,0.102359,220.396667,11.227542,1.023587,-604.451660,0.103191,0.000000
68.510002,50.035316,-604.451660,0.006071,0.004043,0.102680,222.568207,11.338164,1.026797,-604.451660,0.103608,0.000000
68.760002,51.012421,-604.540588,0.006071,0.004058,0.103061,226.914581,11.559580,1.030612,-604.540588,0.104024,0.000000
69.010002,51.880051,-604.540588,0.006075,0.004074,0.103478,230.773987,11.756187,1.034775,-604.540588,0.104440,0.000000
69.260002,52.892899,-604.540588,0.006088,0.004089,0.103868,235.279358,11.985703,1.038677,-604.540588,0.104856,0.000000
69.510002,53.527054,-604.496155,0.006092,0.004101,0.104171,238.100220,12.129404,1.041713,-604.496155,0.105273,0.000000
69.760002,54.419998,-604.540588,0.006088,0.004116,0.104553,242.072235,12.331748,1.045528,-604.540588,0.105689,0.000000
70.010002,56.115410,-604.496155,0.006114,0.004142,0.105195,249.613815,12.715934,1.051947,-604.496155,0.106105,0.000000
70.260002,57.439568,-604.540588,0.006118,0.004158,0.105620,255.503952,13.015992,1.056198,-604.540588,0.106521,0.000000
70.510002,58.102020,-604.496155,0.006131,0.004171,0.105932,258.450684,13.166105,1.059316,-604.496155,0.106938,0.000000
70.760002,59.218765,-604.496155,0.006118,0.004187,0.106357,263.418213,13.419164,1.063567,-604.496155,0.107354,0.000000
71.010002,60.007446,-604.496155,0.006140,0.004202,0.106721,266.926453,13.597881,1.067208,-604.496155,0.107770,0.000000
71.260002,61.393051,-604.540588,0.006144,0.004219,0.107155,273.089935,13.911864,1.071545,-604.540588,0.108187,0.000000
71.510002,61.985489,-604.540588,0.006135,0.004232,0.107502,275.725220,14.046113,1.075016,-604.540588,0.108603,0.000000
71.760002,63.905441,-604.540588,0.006148,0.004253,0.108022,284.265594,14.481180,1.080217,-604.540588,0.109019,0.000000
72.010002,65.704376,-604.540588,0.006161,0.004274,0.108559,292.267670,14.888824,1.085595,-604.540588,0.109435,0.000000
72.260002,67.101517,-604.540588,0.006174,0.004291,0.108993,298.482452,15.205421,1.089932,-604.540588,0.109852,0.000000
72.510002,67.240036,-604.629578,0.006174,0.004289,0.108950,299.098633,15.236810,1.089497,-604.629578,0.109167,0.000000
72.760002,66.620407,-604.585083,0.006174,0.004289,0.108950,296.342377,15.096399,1.089497,-604.585083,0.108950,0.000000
73.010002,66.103928,-604.585083,0.006178,0.004289,0.108932,294.044952,14.979364,1.089323,-604.585083,0.108950,0.000000
73.260002,65.598999,-604.540588,0.006204,0.004289,0.108932,291.798920,14.864945,1.089323,-604.540588,0.108950,0.000000
73.510002,65.188263,-604.629578,0.006187,0.004288,0.108924,289.971863,14.771872,1.089236,-604.629578,0.108950,0.000000
73.760002,64.806961,-604.585083,0.006200,0.004288,0.108924,288.275757,14.685467,1.089236,-604.585083,0.108950,0.000000
74.010002,64.470337,-604.629578,0.006204,0.004288,0.108924,286.778381,14.609187,1.089236,-604.629578,0.108950,0.000000
74.260002,64.159027,-604.585083,0.006200,0.004288,0.108915,285.393616,14.538644,1.089149,-604.585083,0.108950,0.000000
74.510002,63.856659,-604.629578,0.006209,0.004288,0.108915,284.048615,14.470125,1.089149,-604.629578,0.108950,0.000000
74.760002,63.620575,-604.629578,0.006204,0.004288,0.108915,282.998444,14.416628,1.089149,-604.629578,0.108950,0.000000
75.010002,63.360657,-604.629578,0.006209,0.004288,0.108915,281.842285,14.357730,1.089149,-604.629578,0.108950,0.000000
75.260002,63.151398,-604.629578,0.006200,0.004288,0.108915,280.911438,14.310311,1.089149,-604.629578,0.108950,0.000000
75.510002,62.943604,-604.629578,0.006200,0.004288,0.108915,279.987122,14.263225,1.089149,-604.629578,0.108950,0.000000
75.760002,62.746246,-604.629578,0.006204,0.004288,0.108915,279.109253,14.218503,1.089149,-604.629578,0.108950,0.000000
76.010002,62.581657,-604.674072,0.006200,0.004288,0.108915,278.377106,14.181207,1.089149,-604.674072,0.108950,0.000000
76.260002,62.391380,-604.629578,0.006217,0.004288,0.108915,277.530731,14.138088,1.089149,-604.629578,0.108950,0.000000
76.510002,62.260300,-604.718506,0.006213,0.004288,0.108915,276.947632,14.108386,1.089149,-604.718506,0.108950,0.000000
76.760002,62.083054,-604.674072,0.006209,0.004288,0.108915,276.159210,14.068221,1.089149,-604.674072,0.108950,0.000000
77.010002,61.948997,-604.674072,0.006222,0.004288,0.108915,275.562897,14.037843,1.089149,-604.674072,0.108950,0.000000
77.260002,61.823135,-604.674072,0.006213,0.004288,0.108915,275.003052,14.009322,1.089149,-604.674072,0.108950,0.000000
77.510002,61.672699,-604.674072,0.006217,0.004288,0.108915,274.333862,13.975234,1.089149,-604.674072,0.108950,0.000000
77.760002,61.581093,-604.674072,0.006209,0.004288,0.108915,273.926392,13.954475,1.089149,-604.674072,0.108950,0.000000
78.010002,61.446671,-604.763000,0.006209,0.004288,0.108915,273.328430,13.924014,1.089149,-604.763000,0.108950,0.000000
78.260002,61.365120,-604.718506,0.006217,0.004288,0.108915,272.965698,13.905535,1.089149,-604.718506,0.108950,0.000000
78.510002,61.246330,-604.763000,0.006222,0.004288,0.108915,272.437286,13.878616,1.089149,-604.763000,0.108950,0.000000
78.760002,61.120468,-604.674072,0.006234,0.004288,0.108915,271.877411,13.850096,1.089149,-604.674072,0.108950,0.000000
79.010002,61.043015,-604.763000,0.006222,0.004288,0.108915,271.532898,13.832544,1.089149,-604.763000,0.108950,0.000000
79.260002,60.936516,-604.718506,0.006230,0.004288,0.108915,271.059174,13.808412,1.089149,-604.718506,0.108950,0.000000
79.510002,60.855339,-604.718506,0.006222,0.004288,0.108915,270.698059,13.790017,1.089149,-604.718506,0.108950,0.000000
79.760002,60.765228,-604.763000,0.006226,0.004288,0.108906,270.297241,13.769598,1.089062,-604.763000,0.108950,0.000000
80.010002,60.660965,-604.763000,0.006230,0.004288,0.108906,269.833435,13.745971,1.089062,-604.763000,0.108950,0.000000
80.260002,60.603249,-604.763000,0.006222,0.004288,0.108906,269.576721,13.732893,1.089062,-604.763000,0.108950,0.000000
80.510002,60.512016,-604.763000,0.006234,0.004288,0.108906,269.170898,13.712218,1.089062,-604.763000,0.108950,0.000000
80.760002,60.453552,-604.763000,0.006217,0.004288,0.108906,268.910828,13.698971,1.089062,-604.763000,0.108950,0.000000
81.010002,60.368279,-604.718506,0.006230,0.004288,0.108906,268.531525,13.679647,1.089062,-604.718506,0.108950,0.000000
81.260002,60.294922,-604.763000,0.006230,0.004288,0.108906,268.205200,13.663024,1.089062,-604.763000,0.108950,0.000000
81.510002,60.249123,-604.763000,0.006226,0.004288,0.108906,268.001495,13.652646,1.089062,-604.763000,0.108950,0.000000
81.760002,60.157890,-604.807495,0.006226,0.004288,0.108906,267.595673,13.631972,1.089062,-604.807495,0.108950,0.000000
82.010002,60.102776,-604.851990,0.006226,0.004288,0.108906,267.350494,13.619483,1.089062,-604.851990,0.108950,0.000000
82.260002,60.059212,-604.763000,0.006230,0.004288,0.108906,267.156708,13.609612,1.089062,-604.763000,0.108950,0.000000
82.510002,59.974678,-604.763000,0.006234,0.004288,0.108906,266.780701,13.590456,1.089062,-604.763000,0.108950,0.000000
82.760002,59.951591,-604.851990,0.006239,0.004288,0.108906,266.678009,13.585225,1.089062,-604.851990,0.108950,0.000000
83.010002,59.878609,-604.807495,0.006239,0.004288,0.108906,266.353363,13.568687,1.089062,-604.807495,0.108950,0.000000
83.260002,59.819405,-604.807495,0.006230,0.004288,0.108906,266.089996,13.555271,1.089062,-604.807495,0.108950,0.000000
83.510002,59.780304,-604.763000,0.006226,0.004288,0.108906,265.916077,13.546411,1.089062,-604.763000,0.108950,0.000000
83.760002,59.710297,-604.851990,0.006234,0.004288,0.108906,265.604675,13.530547,1.089062,-604.851990,0.108950,0.000000
84.010002,59.673431,-604.807495,0.006234,0.004288,0.108906,265.440674,13.522193,1.089062,-604.807495,0.108950,0.000000
84.260002,59.616829,-604.807495,0.006239,0.004288,0.108906,265.188904,13.509367,1.089062,-604.807495,0.108950,0.000000
84.510002,59.569916,-604.851990,0.006226,0.004288,0.108906,264.980225,13.498736,1.089062,-604.851990,0.108950,0.000000
84.760002,59.525597,-604.851990,0.006230,0.004288,0.108906,264.783081,13.488692,1.089062,-604.851990,0.108950,0.000000
85.010002,59.461182,-604.851990,0.006213,0.004288,0.108906,264.496552,13.474096,1.089062,-604.851990,0.108950,0.000000
85.260002,59.428040,-604.896423,0.006243,0.004288,0.108906,264.349121,13.466587,1.089062,-604.896423,0.108950,0.000000
85.510002,59.401596,-604.896423,0.006234,0.004288,0.108906,264.231506,13.460594,1.089062,-604.896423,0.108950,0.000000
85.760002,59.336433,-604.896423,0.006243,0.004288,0.108906,263.941650,13.445827,1.089062,-604.896423,0.108950,0.000000
86.010002,59.315956,-604.940918,0.006230,0.004288,0.108906,263.850555,13.441188,1.089062,-604.940918,0.108950,0.000000
86.260002,59.251534,-604.851990,0.006234,0.004288,0.108906,263.563995,13.426590,1.089062,-604.851990,0.108950,0.000000
86.510002,59.230309,-604.896423,0.006243,0.004288,0.108906,263.469574,13.421781,1.089062,-604.896423,0.108950,0.000000
86.760002,59.177803,-604.896423,0.006226,0.004288,0.108906,263.236023,13.409882,1.089062,-604.896423,0.108950,0.000000
87.010002,59.136841,-604.940918,0.006243,0.004288,0.108906,263.053802,13.400599,1.089062,-604.940918,0.108950,0.000000
87.260002,59.123436,-604.940918,0.006247,0.004288,0.108906,262.994171,13.397562,1.089062,-604.940918,0.108950,0.000000
87.510002,59.079124,-604.940918,0.006234,0.004288,0.108906,262.797058,13.387521,1.089062,-604.940918,0.108950,0.000000
87.760002,59.041885,-604.896423,0.006234,0.004288,0.108906,262.631409,13.379083,1.089062,-604.896423,0.108950,0.000000
88.010002,59.009117,-604.940918,0.006230,0.004288,0.108906,262.485657,13.371657,1.089062,-604.940918,0.108950,0.000000
88.260002,58.962570,-604.940918,0.006239,0.004288,0.108906,262.278625,13.361109,1.089062,-604.940918,0.108950,0.000000
88.510002,58.947678,-604.940918,0.006243,0.004288,0.108906,262.212372,13.357735,1.089062,-604.940918,0.108950,0.000000
88.760002,58.911560,-604.940918,0.006226,0.004288,0.108906,262.051697,13.349550,1.089062,-604.940918,0.108950,0.000000
89.010002,58.858307,-604.985413,0.006230,0.004288,0.108906,261.814819,13.337482,1.089062,-604.985413,0.108950,0.000000
89.260002,58.847885,-604.940918,0.006230,0.004288,0.108906,261.768463,13.335121,1.089062,-604.940918,0.108950,0.000000
89.510002,58.806175,-604.940918,0.006234,0.004288,0.108906,261.582947,13.325669,1.089062,-604.940918,0.108950,0.000000
89.760002,58.788300,-604.985413,0.006230,0.004288,0.108906,261.503418,13.321619,1.089062,-604.985413,0.108950,0.000000
90.010002,58.755157,-604.985413,0.006247,0.004288,0.108906,261.355988,13.314109,1.089062,-604.985413,0.108950,0.000000
90.260002,58.704887,-604.985413,0.006234,0.004288,0.108906,261.132385,13.302718,1.089062,-604.985413,0.108950,0.000000
90.510002,58.684784,-604.985413,0.006234,0.004288,0.108906,261.042969,13.298162,1.089062,-604.985413,0.108950,0.000000
90.760002,58.656479,-604.985413,0.006222,0.004288,0.108906,260.917053,13.291748,1.089062,-604.985413,0.108950,0.000000
91.010002,58.619987,-605.029907,0.006239,0.004288,0.108906,260.754730,13.283479,1.089062,-605.029907,0.108950,0.000000
91.260002,58.606209,-605.074402,0.006226,0.004288,0.108906,260.693451,13.280356,1.089062,-605.074402,0.108950,0.000000
91.510002,58.573074,-605.074402,0.006243,0.004288,0.108906,260.546051,13.272849,1.089062,-605.074402,0.108950,0.000000
91.760002,58.533600,-605.074402,0.006230,0.004288,0.108906,260.370453,13.263903,1.089062,-605.074402,0.108950,0.000000
92.010002,58.517586,-605.074402,0.006239,0.004288,0.108906,260.299225,13.260274,1.089062,-605.074402,0.108950,0.000000
92.260002,58.481842,-605.029907,0.006239,0.004288,0.108906,260.140228,13.252174,1.089062,-605.029907,0.108950,0.000000
92.510002,58.471039,-605.074402,0.006234,0.004288,0.108906,260.092163,13.249727,1.089062,-605.074402,0.108950,0.000000
92.760002,58.428589,-605.029907,0.006239,0.004288,0.108906,259.903351,13.240108,1.089062,-605.029907,0.108950,0.000000
93.010002,58.405502,-605.163330,0.006234,0.004288,0.108906,259.800659,13.234876,1.089062,-605.163330,0.108950,0.000000
93.260002,58.393219,-605.118835,0.006226,0.004288,0.108906,259.746002,13.232093,1.089062,-605.118835,0.108950,0.000000
93.510002,58.348534,-605.074402,0.006234,0.004288,0.108906,259.547241,13.221967,1.089062,-605.074402,0.108950,0.000000
93.760002,58.342941,-605.118835,0.006243,0.004288,0.108906,259.522369,13.220699,1.089062,-605.118835,0.108950,0.000000
94.010002,58.299751,-605.029907,0.006239,0.004288,0.108906,259.330231,13.210912,1.089062,-605.029907,0.108950,0.000000
94.260002,58.291931,-605.163330,0.006234,0.004288,0.108906,259.295471,13.209140,1.089062,-605.163330,0.108950,0.000000
94.510002,58.275543,-605.163330,0.006234,0.004288,0.108906,259.222565,13.205427,1.089062,-605.163330,0.108950,0.000000
94.760002,58.238678,-605.163330,0.006243,0.004288,0.108906,259.058563,13.197073,1.089062,-605.163330,0.108950,0.000000
95.010002,58.230858,-605.163330,0.006243,0.004288,0.108906,259.023804,13.195301,1.089062,-605.163330,0.108950,0.000000
95.260002,58.193253,-605.207825,0.006247,0.004288,0.108906,258.856506,13.186780,1.089062,-605.207825,0.108950,0.000000
95.510002,58.173889,-605.074402,0.006243,0.004288,0.108906,258.770386,13.182391,1.089062,-605.074402,0.108950,0.000000
95.760002,58.165321,-605.163330,0.006239,0.004288,0.108906,258.732269,13.180450,1.089062,-605.163330,0.108950,0.000000
96.010002,58.121010,-605.163330,0.006234,0.004288,0.108906,258.535156,13.170409,1.089062,-605.163330,0.108950,0.000000
96.260002,58.116539,-605.163330,0.006252,0.004288,0.108906,258.515289,13.169395,1.089062,-605.163330,0.108950,0.000000
96.510002,58.087868,-605.163330,0.006234,0.004288,0.108906,258.387726,13.162899,1.089062,-605.163330,0.108950,0.000000
96.760002,58.062546,-605.207825,0.006247,0.004288,0.108906,258.275116,13.157161,1.089062,-605.207825,0.108950,0.000000
97.010002,58.053612,-605.207825,0.006247,0.004288,0.108906,258.235352,13.155136,1.089062,-605.207825,0.108950,0.000000
97.260002,58.017860,-605.207825,0.006230,0.004288,0.108906,258.076324,13.147035,1.089062,-605.207825,0.108950,0.000000
97.510002,58.003342,-605.207825,0.006247,0.004288,0.108906,258.011749,13.143744,1.089062,-605.207825,0.108950,0.000000
97.760002,57.977646,-605.207825,0.006252,0.004288,0.108906,257.897461,13.137922,1.089062,-605.207825,0.108950,0.000000
98.010002,57.963867,-605.118835,0.006230,0.004288,0.108906,257.836151,13.134800,1.089062,-605.118835,0.108950,0.000000
98.260002,57.945999,-605.163330,0.006239,0.004288,0.108906,257.756683,13.130751,1.089062,-605.163330,0.108950,0.000000
98.510002,57.921417,-605.207825,0.006239,0.004288,0.108906,257.647339,13.125181,1.089062,-605.207825,0.108950,0.000000
98.760002,57.903549,-605.252319,0.006247,0.004288,0.108906,257.567841,13.121132,1.089062,-605.252319,0.108950,0.000000
99.010002,57.871895,-605.252319,0.006243,0.004288,0.108906,257.427032,13.113959,1.089062,-605.252319,0.108950,0.000000
99.260002,57.865189,-605.252319,0.006243,0.004288,0.108906,257.397217,13.112439,1.089062,-605.252319,0.108950,0.000000
99.510002,57.843224,-605.252319,0.006247,0.004288,0.108906,257.299500,13.107462,1.089062,-605.252319,0.108950,0.000000
99.760002,57.800774,-605.296753,0.006239,0.004288,0.108906,257.110687,13.097842,1.089062,-605.296753,0.108950,0.000000
100.010002,57.808960,-605.296753,0.006247,0.004288,0.108906,257.147095,13.099697,1.089062,-605.296753,0.108950,0.000000
100.260002,57.785873,-605.252319,0.006239,0.004288,0.108906,257.044403,13.094466,1.089062,-605.252319,0.108950,0.000000
100.510002,57.767632,-605.296753,0.006230,0.004288,0.108906,256.963257,13.090333,1.089062,-605.296753,0.108950,0.000000
100.760002,57.744171,-605.296753,0.006239,0.004288,0.108906,256.858887,13.085016,1.089062,-605.296753,0.108950,0.000000
101.010002,57.724434,-605.296753,0.006234,0.004288,0.108906,256.771118,13.080544,1.089062,-605.296753,0.108950,0.000000
101.260002,57.727783,-605.252319,0.006247,0.004288,0.108906,256.786011,13.081303,1.089062,-605.252319,0.108950,0.000000
101.510002,57.681610,-605.341248,0.006239,0.004288,0.108906,256.580627,13.070840,1.089062,-605.341248,0.108950,0.000000
101.760002,57.683098,-605.341248,0.006243,0.004288,0.108906,256.587219,13.071177,1.089062,-605.341248,0.108950,0.000000
102.010002,57.658524,-605.296753,0.006247,0.004288,0.108906,256.477936,13.065609,1.089062,-605.296753,0.108950,0.000000
102.260002,57.636185,-605.252319,0.006252,0.004288,0.108906,256.378540,13.060547,1.089062,-605.252319,0.108950,0.000000
102.510002,57.644005,-605.341248,0.006234,0.004288,0.108906,256.413330,13.062319,1.089062,-605.341248,0.108950,0.000000
102.760002,57.599693,-605.385742,0.006239,0.004288,0.108906,256.216217,13.052277,1.089062,-605.385742,0.108950,0.000000
102.900002,57.601921,-605.252319,0.006247,0.004288,0.108906,256.226135,13.052782,1.089062,-605.252319,0.108950,0.000000