File: Data/compression 32/AutoNoHeating-17-32-reverse-1-3_11142024_161302.csv
Time (sec),S:Load (lbs),S:HL1 (DIM),S:LVDT (in),S:Position (in),Ch:Position (mm),Ch:Load (N),Ch:Stress (MPa),Ch:Strain (mm/mm),Ch:HL1 (DIM),Set Point (),Cycles ()
0.110000,-0.041710,-201.009415,-0.013142,-0.007760,-0.197095,-0.185535,-0.009452,-1.970946,-201.009415,-0.196886,0.000000
0.490000,-0.015640,-201.053894,-0.013146,-0.007698,-0.195541,-0.069571,-0.003544,-1.955413,-201.053894,-0.194925,0.000000
0.870000,-0.028297,-201.053894,-0.013008,-0.007466,-0.189644,-0.125873,-0.006412,-1.896444,-201.053894,-0.188612,0.000000
1.250000,-0.026436,-201.098373,-0.012749,-0.007220,-0.183392,-0.117593,-0.005990,-1.833918,-201.098373,-0.182282,0.000000
1.630000,-0.007072,-201.187347,-0.012508,-0.006973,-0.177104,-0.031460,-0.001603,-1.771043,-201.187347,-0.175951,0.000000
2.010000,-0.040962,-201.142868,-0.012227,-0.006720,-0.170696,-0.182209,-0.009282,-1.706957,-201.142868,-0.169621,0.000000
2.390000,-0.097939,-201.231827,-0.011986,-0.006471,-0.164364,-0.435652,-0.022193,-1.643644,-201.231827,-0.163289,0.000000
2.770000,-0.083038,-201.187347,-0.011723,-0.006223,-0.158069,-0.369373,-0.018817,-1.580693,-201.187347,-0.156958,0.000000
3.150000,-0.021973,-201.187347,-0.011447,-0.005974,-0.151729,-0.097739,-0.004979,-1.517289,-201.187347,-0.150628,0.000000
3.530000,-0.018250,-201.276306,-0.011214,-0.005722,-0.145338,-0.081178,-0.004135,-1.453385,-201.276306,-0.144297,0.000000
3.910000,-0.025696,-201.320786,-0.010969,-0.005472,-0.138998,-0.114301,-0.005823,-1.389980,-201.320786,-0.137967,0.000000
4.290000,-0.037979,-201.365265,-0.010736,-0.005222,-0.132650,-0.168940,-0.008606,-1.326500,-201.365265,-0.131636,0.000000
4.670000,-0.035751,-201.409744,-0.010468,-0.004970,-0.126250,-0.159030,-0.008101,-1.262505,-201.409744,-0.125304,0.000000
5.050000,0.007446,-201.365265,-0.010214,-0.004727,-0.120058,0.033123,0.001687,-1.200584,-201.365265,-0.118974,0.000000
5.430000,0.033882,-201.454224,-0.009968,-0.004476,-0.113692,0.150715,0.007678,-1.136922,-201.454224,-0.112643,0.000000
5.810000,0.021599,-201.454224,-0.009727,-0.004235,-0.107562,0.096076,0.004894,-1.075622,-201.454224,-0.106313,0.000000
6.190000,-0.004097,-201.454224,-0.009459,-0.003987,-0.101282,-0.018224,-0.000928,-1.012823,-201.454224,-0.099982,0.000000
6.570000,-0.014893,-201.454224,-0.009201,-0.003737,-0.094927,-0.066245,-0.003375,-0.949267,-201.454224,-0.093652,0.000000
6.950000,0.010422,-201.543182,-0.008977,-0.003489,-0.088621,0.046358,0.002362,-0.886210,-201.543182,-0.087321,0.000000
7.330000,0.026436,-201.587677,-0.008696,-0.003237,-0.082222,0.117593,0.005990,-0.822215,-201.587677,-0.080989,0.000000
7.710001,0.057716,-201.632156,-0.008438,-0.002987,-0.075864,0.256735,0.013079,-0.758644,-201.632156,-0.074659,0.000000
8.090000,0.039467,-201.587677,-0.008179,-0.002734,-0.069438,0.175557,0.008943,-0.694377,-201.587677,-0.068328,0.000000
8.470000,0.026436,-201.587677,-0.007925,-0.002483,-0.063073,0.117593,0.005990,-0.630730,-201.587677,-0.061998,0.000000
8.850000,-0.022346,-201.676636,-0.007683,-0.002233,-0.056725,-0.099402,-0.005064,-0.567250,-201.676636,-0.055667,0.000000
9.230000,0.005211,-201.676636,-0.007411,-0.001986,-0.050447,0.023179,0.001181,-0.504466,-201.676636,-0.049335,0.000000
9.610001,0.037239,-201.721115,-0.007153,-0.001735,-0.044071,0.165648,0.008438,-0.440713,-201.721115,-0.043005,0.000000
9.990001,0.026062,-201.721115,-0.006894,-0.001485,-0.037716,0.115930,0.005906,-0.377157,-201.721115,-0.036674,0.000000
10.370001,-0.001488,-201.765594,-0.006640,-0.001241,-0.031531,-0.006618,-0.000337,-0.315312,-201.765594,-0.030344,0.000000
10.750001,-0.019363,-201.943512,-0.006381,-0.000990,-0.025157,-0.086133,-0.004388,-0.251574,-201.943512,-0.024013,0.000000
11.130000,-0.054741,-201.899033,-0.006131,-0.000743,-0.018862,-0.243500,-0.012404,-0.188624,-201.899033,-0.017682,0.000000
11.510000,0.020851,-201.854553,-0.005877,-0.000492,-0.012487,0.092750,0.004725,-0.124871,-201.854553,-0.011352,0.000000
11.890000,0.011917,-201.854553,-0.005618,-0.000242,-0.006148,0.053010,0.002700,-0.061482,-201.854553,-0.005020,0.000000
12.270000,0.048409,-201.943512,-0.005364,0.000006,0.000165,0.215332,0.010970,0.001650,-201.943512,0.001310,0.000000
12.650001,0.152672,-202.032486,-0.005182,-0.000000,-0.000000,0.679118,0.034596,-0.000000,-202.032486,0.000207,0.000000
13.030001,0.124741,-202.032486,-0.005187,-0.000000,-0.000009,0.554874,0.028267,-0.000091,-202.032486,0.000207,0.000000
13.410001,0.124374,-201.987991,-0.005191,0.000002,0.000042,0.553245,0.028184,0.000424,-201.987991,0.000789,0.000000
13.790001,0.192886,-201.943512,-0.005182,0.000019,0.000477,0.858001,0.043709,0.004769,-201.943512,0.001422,0.000000
14.170001,0.288589,-202.032486,-0.005148,0.000036,0.000919,1.283710,0.065395,0.009190,-202.032486,0.002054,0.000000
14.550001,0.479988,-202.165924,-0.005135,0.000070,0.001768,2.135094,0.108767,0.017683,-202.165924,0.002687,0.000000
14.930000,0.637131,-202.121445,-0.005105,0.000095,0.002410,2.834099,0.144376,0.024102,-202.121445,0.003322,0.000000
15.310000,0.896301,-202.121445,-0.005101,0.000121,0.003078,3.986947,0.203105,0.030779,-202.121445,0.003954,0.000000
15.690001,1.190475,-202.121445,-0.005066,0.000147,0.003738,5.295499,0.269766,0.037380,-202.121445,0.004587,0.000000
16.070002,1.381126,-202.210403,-0.005057,0.000164,0.004171,6.143557,0.312968,0.041710,-202.210403,0.005220,0.000000
16.450001,1.800423,-202.210403,-0.005023,0.000197,0.004995,8.008680,0.407982,0.049945,-202.210403,0.005853,0.000000
16.830000,2.069275,-202.299362,-0.005014,0.000220,0.005576,9.204595,0.468904,0.055759,-202.299362,0.006495,0.000000
17.210001,2.429726,-202.254883,-0.004988,0.000243,0.006183,10.807960,0.550584,0.061830,-202.254883,0.007128,0.000000
17.590000,2.764862,-202.254883,-0.004945,0.000266,0.006764,12.298720,0.626527,0.067644,-202.254883,0.007761,0.000000
17.970001,3.231445,-202.299362,-0.004945,0.000289,0.007353,14.374187,0.732256,0.073533,-202.299362,0.008395,0.000000
18.350000,3.727448,-202.388321,-0.004911,0.000319,0.008109,16.580515,0.844652,0.081088,-202.388321,0.009028,0.000000
18.730001,4.134079,-202.388321,-0.004898,0.000346,0.008793,18.389301,0.936796,0.087931,-202.388321,0.009661,0.000000
19.110001,4.518364,-202.477295,-0.004863,0.000370,0.009391,20.098686,1.023876,0.093911,-202.477295,0.010293,0.000000
19.490002,5.024422,-202.477295,-0.004850,0.000394,0.009998,22.349745,1.138550,0.099982,-202.477295,0.010926,0.000000
19.870001,5.439613,-202.477295,-0.004838,0.000416,0.010563,24.196609,1.232634,0.105629,-202.477295,0.011559,0.000000
20.250002,6.099831,-202.566254,-0.004799,0.000449,0.011403,27.133402,1.382241,0.114031,-202.566254,0.012193,0.000000
20.630001,6.326607,-202.521774,-0.004777,0.000471,0.011975,28.142153,1.433630,0.119754,-202.521774,0.012826,0.000000
21.010000,6.576096,-202.521774,-0.004756,0.000490,0.012445,29.251934,1.490165,0.124447,-202.521774,0.013459,0.000000
21.390001,6.969696,-202.566254,-0.004725,0.000513,0.013025,31.002756,1.579356,0.130246,-202.566254,0.014092,0.000000
21.770000,7.542778,-202.655212,-0.004721,0.000539,0.013701,33.551952,1.709218,0.137013,-202.655212,0.014725,0.000000
22.150002,8.053299,-202.655212,-0.004691,0.000570,0.014490,35.822865,1.824904,0.144901,-202.655212,0.015358,0.000000
22.530001,8.371307,-202.655212,-0.004661,0.000596,0.015141,37.237434,1.896965,0.151411,-202.655212,0.015990,0.000000
22.910002,8.568291,-202.655212,-0.004635,0.000616,0.015636,38.113659,1.941602,0.156362,-202.655212,0.016625,0.000000
23.290001,9.006943,-202.699692,-0.004613,0.000642,0.016311,40.064884,2.041003,0.163114,-202.699692,0.017258,0.000000
23.670002,9.374100,-202.744171,-0.004596,0.000665,0.016884,41.698078,2.124201,0.168837,-202.744171,0.017890,0.000000
24.050001,9.845154,-202.788651,-0.004579,0.000690,0.017526,43.793430,2.230944,0.175256,-202.788651,0.018523,0.000000
24.430000,10.186249,-202.788651,-0.004544,0.000719,0.018272,45.310696,2.308237,0.182720,-202.788651,0.019156,0.000000
24.810001,10.392540,-202.833130,-0.004523,0.000740,0.018793,46.228325,2.354983,0.187928,-202.833130,0.019789,0.000000
25.190001,10.713898,-202.877625,-0.004484,0.000768,0.019495,47.657799,2.427804,0.194952,-202.877625,0.020423,0.000000
25.570002,10.870293,-202.922104,-0.004471,0.000789,0.020049,48.353477,2.463243,0.200493,-202.922104,0.021056,0.000000
25.950001,10.925407,-202.922104,-0.004458,0.000804,0.020423,48.598640,2.475733,0.204233,-202.922104,0.021689,0.000000
26.330002,11.699570,-203.011063,-0.004432,0.000842,0.021385,52.042286,2.651160,0.213847,-203.011063,0.022322,0.000000
26.710001,11.844795,-203.011063,-0.004381,0.000865,0.021975,52.688282,2.684069,0.219751,-203.011063,0.022955,0.000000
27.090002,12.198921,-203.011063,-0.004363,0.000893,0.022678,54.263512,2.764315,0.226776,-203.011063,0.023587,0.000000
27.470001,12.326271,-203.055542,-0.004329,0.000914,0.023206,54.829990,2.793173,0.232059,-203.055542,0.024222,0.000000
27.850000,12.929146,-203.100021,-0.004316,0.000947,0.024057,57.511711,2.929786,0.240568,-203.100021,0.024862,0.000000
28.230001,12.998405,-203.100021,-0.004294,0.000969,0.024603,57.819794,2.945481,0.246033,-203.100021,0.025497,0.000000
28.610001,12.959679,-203.144501,-0.004260,0.000993,0.025210,57.647530,2.936705,0.252104,-203.144501,0.026129,0.000000
28.990002,13.319016,-203.188980,-0.004238,0.001020,0.025913,59.245941,3.018132,0.259129,-203.188980,0.026762,0.000000
29.370001,13.359978,-203.233459,-0.004217,0.001039,0.026381,59.428150,3.027414,0.263807,-203.233459,0.027395,0.000000
29.750002,13.295189,-203.277939,-0.004186,0.001055,0.026806,59.139954,3.012733,0.268061,-203.277939,0.028028,0.000000
30.130001,13.943489,-203.233459,-0.004139,0.001091,0.027707,62.023739,3.159640,0.277069,-203.233459,0.028661,0.000000
30.510002,14.043655,-203.322433,-0.004109,0.001116,0.028349,62.469299,3.182338,0.283489,-203.322433,0.029295,0.000000
30.890001,14.251434,-203.277939,-0.004079,0.001144,0.029060,63.393547,3.229421,0.290604,-203.277939,0.029928,0.000000
31.270002,14.211220,-203.366913,-0.004053,0.001163,0.029537,63.214664,3.220308,0.295373,-203.366913,0.030561,0.000000
31.650002,14.153503,-203.411392,-0.004018,0.001179,0.029954,62.957928,3.207230,0.299537,-203.411392,0.031194,0.000000
32.030003,15.020012,-203.411392,-0.003992,0.001220,0.030994,66.812347,3.403583,0.309937,-203.411392,0.031826,0.000000
32.410000,14.699776,-203.411392,-0.003954,0.001239,0.031480,65.387871,3.331017,0.314797,-203.411392,0.032459,0.000000
32.790001,14.851334,-203.411392,-0.003923,0.001266,0.032156,66.062035,3.365360,0.321565,-203.411392,0.033092,0.000000
33.170002,15.129120,-203.455872,-0.003893,0.001292,0.032806,67.297684,3.428308,0.328060,-203.455872,0.033726,0.000000
33.550003,14.930649,-203.500351,-0.003872,0.001306,0.033180,66.414841,3.383333,0.331799,-203.500351,0.034359,0.000000
33.930000,15.601662,-203.544830,-0.003837,0.001342,0.034082,69.399658,3.535387,0.340822,-203.544830,0.034992,0.000000
34.310001,15.459045,-203.544830,-0.003798,0.001365,0.034680,68.765266,3.503070,0.346802,-203.544830,0.035625,0.000000
34.690002,15.408775,-203.544830,-0.003786,0.001387,0.035234,68.541656,3.491678,0.352343,-203.544830,0.036258,0.000000
35.070004,15.737579,-203.633789,-0.003738,0.001416,0.035964,70.004250,3.566186,0.359641,-203.633789,0.036891,0.000000
35.450001,15.525696,-203.633789,-0.003717,0.001434,0.036414,69.061745,3.518173,0.364137,-203.633789,0.037525,0.000000
35.830002,15.904396,-203.722763,-0.003669,0.001464,0.037186,70.746284,3.603988,0.371858,-203.722763,0.038158,0.000000
36.210003,16.073830,-203.678268,-0.003639,0.001490,0.037853,71.499962,3.642382,0.378535,-203.678268,0.038791,0.000000
36.590000,16.017227,-203.722763,-0.003600,0.001514,0.038461,71.248184,3.629555,0.384606,-203.722763,0.039423,0.000000
36.970001,16.213844,-203.767242,-0.003570,0.001541,0.039137,72.122780,3.674110,0.391373,-203.767242,0.040056,0.000000
37.350002,16.110321,-203.767242,-0.003544,0.001561,0.039640,71.662285,3.650651,0.396400,-203.767242,0.040689,0.000000
37.730003,16.478600,-203.811722,-0.003527,0.001591,0.040421,73.300468,3.734104,0.404212,-203.811722,0.041323,0.000000
38.110001,16.486420,-203.767242,-0.003492,0.001615,0.041028,73.335258,3.735876,0.410283,-203.767242,0.041956,0.000000
38.490002,16.449928,-203.900681,-0.003458,0.001638,0.041617,73.172935,3.727607,0.416172,-203.900681,0.042598,0.000000
38.870003,16.580254,-203.900681,-0.003423,0.001661,0.042189,73.752655,3.757139,0.421895,-203.900681,0.043231,0.000000
39.250000,16.871078,-203.900681,-0.003393,0.001687,0.042857,75.046303,3.823041,0.428571,-203.900681,0.043864,0.000000
39.630001,17.290001,-203.945160,-0.003367,0.001717,0.043613,76.909767,3.917970,0.436126,-203.945160,0.044497,0.000000
40.010002,17.315689,-203.989639,-0.003333,0.001744,0.044297,77.024033,3.923791,0.442969,-203.989639,0.045130,0.000000
40.390003,17.184242,-203.989639,-0.003303,0.001765,0.044827,76.439323,3.894005,0.448268,-203.989639,0.045762,0.000000
40.770000,17.535767,-204.034119,-0.003264,0.001793,0.045537,78.002983,3.973661,0.455368,-204.034119,0.046397,0.000000
41.150002,17.511185,-204.034119,-0.003242,0.001814,0.046076,77.893639,3.968091,0.460758,-204.034119,0.047030,0.000000
41.530003,17.622902,-204.123077,-0.003229,0.001839,0.046700,78.390579,3.993407,0.466995,-204.123077,0.047662,0.000000
41.910004,17.886536,-204.123077,-0.003186,0.001868,0.047437,79.563286,4.053147,0.474368,-204.123077,0.048295,0.000000
42.290001,17.809830,-204.123077,-0.003152,0.001888,0.047965,79.222076,4.035765,0.479652,-204.123077,0.048928,0.000000
42.670002,17.823982,-204.167572,-0.003113,0.001910,0.048504,79.285034,4.038972,0.485042,-204.167572,0.049561,0.000000
43.050003,18.255562,-204.212051,-0.003087,0.001937,0.049205,81.204796,4.136769,0.492051,-204.212051,0.050195,0.000000
43.430000,17.889519,-204.301010,-0.003065,0.001950,0.049535,79.576553,4.053823,0.495352,-204.301010,0.050828,0.000000
43.810001,18.890083,-204.256531,-0.003027,0.001993,0.050628,84.027290,4.280554,0.506283,-204.256531,0.051461,0.000000
44.190002,18.589577,-204.256531,-0.003009,0.002014,0.051149,82.690567,4.212458,0.511491,-204.256531,0.052094,0.000000
44.570004,18.791779,-204.345490,-0.002979,0.002037,0.051738,83.590004,4.258278,0.517380,-204.345490,0.052727,0.000000
44.950001,18.939980,-204.301010,-0.002932,0.002061,0.052354,84.249237,4.291861,0.523542,-204.301010,0.053359,0.000000
45.330002,19.393898,-204.389969,-0.002923,0.002087,0.053022,86.268364,4.394720,0.530218,-204.389969,0.053992,0.000000
45.710003,19.330971,-204.478928,-0.002893,0.002108,0.053550,85.988449,4.380461,0.535502,-204.478928,0.054627,0.000000
46.090004,19.814308,-204.434448,-0.002859,0.002138,0.054297,88.138443,4.489986,0.542966,-204.434448,0.055259,0.000000
46.470001,19.987465,-204.478928,-0.002833,0.002164,0.054973,88.908684,4.529224,0.549733,-204.478928,0.055892,0.000000
46.850002,20.004593,-204.523407,-0.002798,0.002187,0.055546,88.984871,4.533105,0.555456,-204.523407,0.056525,0.000000
47.230003,19.844841,-204.523407,-0.002768,0.002205,0.056004,88.274261,4.496905,0.560043,-204.523407,0.057158,0.000000
47.610001,20.516602,-204.567886,-0.002746,0.002239,0.056863,91.262405,4.649128,0.568627,-204.567886,0.057791,0.000000
47.990002,20.898659,-204.567886,-0.002721,0.002263,0.057488,92.961876,4.735704,0.574880,-204.567886,0.058425,0.000000
48.370003,21.192459,-204.612381,-0.002699,0.002289,0.058130,94.268768,4.802280,0.581299,-204.612381,0.059058,0.000000
48.750004,21.099739,-204.656860,-0.002652,0.002311,0.058693,93.856323,4.781270,0.586931,-204.656860,0.059691,0.000000
49.130001,21.497437,-204.701340,-0.002639,0.002339,0.059421,95.625374,4.871389,0.594213,-204.701340,0.060324,0.000000
49.510002,21.858635,-204.745819,-0.002604,0.002366,0.060098,97.232063,4.953238,0.600981,-204.745819,0.060966,0.000000
49.890003,21.865707,-204.745819,-0.002574,0.002388,0.060654,97.263527,4.954840,0.606537,-204.745819,0.061598,0.000000
50.270004,22.245529,-204.701340,-0.002544,0.002414,0.061312,98.953056,5.040909,0.613123,-204.701340,0.062231,0.000000
50.650002,22.394104,-204.790298,-0.002531,0.002436,0.061875,99.613953,5.074577,0.618755,-204.790298,0.062864,0.000000
51.030003,22.165466,-204.834778,-0.002496,0.002452,0.062284,98.596916,5.022767,0.622842,-204.834778,0.063498,0.000000
51.410004,23.262848,-204.923737,-0.002466,0.002488,0.063203,103.478317,5.271437,0.632032,-204.923737,0.064131,0.000000
51.790001,23.376801,-204.790298,-0.002445,0.002512,0.063810,103.985199,5.297259,0.638103,-204.790298,0.064764,0.000000
52.170002,23.890297,-204.879257,-0.002406,0.002541,0.064548,106.269348,5.413619,0.645476,-204.879257,0.065397,0.000000
52.550003,23.823273,-204.879257,-0.002380,0.002561,0.065059,105.971207,5.398431,0.650593,-204.879257,0.066030,0.000000
52.930004,23.629639,-205.012711,-0.002363,0.002577,0.065457,105.109886,5.354553,0.654575,-205.012711,0.066663,0.000000
53.310001,25.179077,-205.012711,-0.002354,0.002617,0.066481,112.002129,5.705661,0.664809,-205.012711,0.067297,0.000000
53.690002,25.004807,-205.012711,-0.002324,0.002637,0.066976,111.226936,5.666170,0.669760,-205.012711,0.067930,0.000000
54.070004,24.692764,-205.012711,-0.002281,0.002652,0.067365,109.838898,5.595460,0.673651,-205.012711,0.068563,0.000000
54.450001,25.542519,-205.057190,-0.002268,0.002683,0.068155,113.618797,5.788018,0.681554,-205.057190,0.069195,0.000000
54.830002,25.760727,-205.146149,-0.002233,0.002705,0.068700,114.589439,5.837464,0.687004,-205.146149,0.069828,0.000000
55.210003,26.971306,-205.190628,-0.002207,0.002739,0.069577,119.974358,6.111785,0.695770,-205.190628,0.070461,0.000000
55.590004,27.106850,-205.146149,-0.002199,0.002763,0.070175,120.577286,6.142500,0.701750,-205.146149,0.071094,0.000000
55.970001,27.048019,-205.190628,-0.002177,0.002782,0.070670,120.315598,6.129169,0.706700,-205.190628,0.071728,0.000000
56.350002,27.798721,-205.190628,-0.002143,0.002813,0.071459,123.654892,6.299280,0.714588,-205.190628,0.072361,0.000000
56.730003,27.821808,-205.279587,-0.002147,0.002831,0.071910,123.757584,6.304512,0.719100,-205.279587,0.072994,0.000000
57.110004,28.854767,-205.324066,-0.002087,0.002860,0.072656,128.352417,6.538584,0.726564,-205.324066,0.073627,0.000000
57.490002,29.382050,-205.324066,-0.002070,0.002888,0.073366,130.697891,6.658068,0.733664,-205.324066,0.074260,0.000000
57.870003,29.513870,-205.279587,-0.002048,0.002911,0.073939,131.284256,6.687938,0.739387,-205.279587,0.074892,0.000000
58.250004,29.969650,-205.324066,-0.002031,0.002937,0.074599,133.311661,6.791220,0.745988,-205.324066,0.075527,0.000000
58.630001,30.346863,-205.368546,-0.001988,0.002958,0.075136,134.989594,6.876698,0.751362,-205.368546,0.076160,0.000000
59.010002,31.118790,-205.457520,-0.001970,0.002986,0.075848,138.423294,7.051619,0.758478,-205.457520,0.076792,0.000000
59.390003,31.726501,-205.501999,-0.001962,0.003014,0.076550,141.126526,7.189328,0.765503,-205.501999,0.077425,0.000000
59.770004,31.970779,-205.501999,-0.001936,0.003036,0.077113,142.213135,7.244682,0.771134,-205.501999,0.078058,0.000000
60.150002,32.474976,-205.501999,-0.001923,0.003059,0.077702,144.455902,7.358935,0.777024,-205.501999,0.078691,0.000000
60.530003,33.069656,-205.546478,-0.001884,0.003085,0.078362,147.101181,7.493691,0.783625,-205.546478,0.079333,0.000000
60.910004,34.186028,-205.590958,-0.001880,0.003113,0.079082,152.067047,7.746665,0.790816,-205.590958,0.079966,0.000000
61.290005,34.371468,-205.679916,-0.001854,0.003134,0.079611,152.891922,7.788686,0.796115,-205.679916,0.080600,0.000000
61.670002,35.181007,-205.679916,-0.001815,0.003162,0.080314,156.492935,7.972130,0.803140,-205.679916,0.081233,0.000000
62.050003,35.696739,-205.679916,-0.001794,0.003187,0.080938,158.787033,8.088997,0.809377,-205.679916,0.081866,0.000000
62.430004,35.723175,-205.724396,-0.001772,0.003201,0.081303,158.904617,8.094988,0.813026,-205.724396,0.082499,0.000000
62.810001,35.928726,-205.768875,-0.001755,0.003222,0.081848,159.818954,8.141565,0.818476,-205.768875,0.083131,0.000000
63.190002,37.844955,-205.768875,-0.001742,0.003258,0.082750,168.342773,8.575789,0.827499,-205.768875,0.083764,0.000000
63.570004,38.613907,-205.813354,-0.001725,0.003285,0.083427,171.763229,8.750036,0.834267,-205.813354,0.084399,0.000000
63.950005,39.150864,-205.768875,-0.001703,0.003307,0.083999,174.151733,8.871713,0.839989,-205.768875,0.085031,0.000000
64.330002,39.822998,-205.813354,-0.001664,0.003329,0.084555,177.141541,9.024020,0.845546,-205.813354,0.085664,0.000000
64.710007,39.959663,-205.902328,-0.001651,0.003345,0.084962,177.749466,9.054989,0.849618,-205.902328,0.086297,0.000000
65.090004,42.198364,-205.902328,-0.001630,0.003386,0.085994,187.707703,9.562286,0.859943,-205.902328,0.086930,0.000000
65.470001,42.700325,-205.902328,-0.001621,0.003409,0.086600,189.940536,9.676032,0.865999,-205.902328,0.087563,0.000000
65.850006,43.122223,-205.902328,-0.001591,0.003428,0.087069,191.817230,9.771635,0.870692,-205.902328,0.088196,0.000000
66.230003,44.316788,-205.946808,-0.001582,0.003455,0.087763,197.130920,10.042328,0.877626,-205.946808,0.088830,0.000000
66.610001,44.640755,-205.991287,-0.001556,0.003475,0.088265,198.571991,10.115740,0.882653,-205.991287,0.089463,0.000000
66.990005,46.174561,-206.080246,-0.001539,0.003505,0.089037,205.394699,10.463305,0.890374,-206.080246,0.090096,0.000000
67.370003,47.429077,-206.035767,-0.001522,0.003534,0.089775,210.975067,10.747582,0.897747,-206.035767,0.090728,0.000000
67.750000,48.568909,-205.991287,-0.001496,0.003559,0.090391,216.045303,11.005872,0.903909,-205.991287,0.091361,0.000000
68.130005,49.066399,-206.080246,-0.001492,0.003581,0.090963,218.258240,11.118605,0.909631,-206.080246,0.091994,0.000000
68.510002,49.305092,-206.124725,-0.001453,0.003594,0.091292,219.320007,11.172693,0.912917,-206.124725,0.092628,0.000000
68.890007,51.405273,-206.169205,-0.001462,0.003632,0.092264,228.662079,11.648602,0.922636,-206.169205,0.093261,0.000000
69.270004,52.727570,-206.258163,-0.001436,0.003660,0.092975,234.543945,11.948238,0.929752,-206.258163,0.093894,0.000000
69.650002,54.162689,-206.213684,-0.001410,0.003687,0.093643,240.927673,12.273441,0.936428,-206.213684,0.094527,0.000000
70.030006,54.926430,-206.213684,-0.001401,0.003708,0.094180,244.324966,12.446507,0.941803,-206.213684,0.095160,0.000000
70.410004,55.282043,-206.258163,-0.001384,0.003726,0.094631,245.906815,12.527090,0.946315,-206.258163,0.095793,0.000000
70.790001,57.258598,-206.302658,-0.001358,0.003759,0.095481,254.698959,12.974984,0.954808,-206.302658,0.096427,0.000000
71.170006,58.520195,-206.347137,-0.001358,0.003783,0.096088,260.310822,13.260866,0.960879,-206.347137,0.097060,0.000000
71.550003,59.561348,-206.302658,-0.001341,0.003810,0.096781,264.942108,13.496794,0.967813,-206.302658,0.097702,0.000000
71.930000,61.121590,-206.391617,-0.001328,0.003834,0.097381,271.882416,13.850350,0.973808,-206.391617,0.098335,0.000000
72.310005,61.600082,-206.391617,-0.001311,0.003850,0.097779,274.010864,13.958778,0.977790,-206.391617,0.098967,0.000000
72.690002,63.634735,-206.480576,-0.001306,0.003883,0.098630,283.061432,14.419837,0.986298,-206.480576,0.099600,0.000000
73.070000,65.363647,-206.480576,-0.001285,0.003910,0.099314,290.752014,14.811614,0.993141,-206.480576,0.100233,0.000000
73.450005,66.435715,-206.480576,-0.001268,0.003924,0.099679,295.520813,15.054548,0.996790,-206.480576,0.099895,0.000000
73.830002,65.105225,-206.480576,-0.001259,0.003931,0.099842,289.602509,14.753055,0.998425,-206.480576,294.500458,0.000000
74.210007,65.507019,-206.525055,-0.001242,0.003944,0.100173,291.389771,14.844102,1.001725,-206.525055,294.500458,0.000000
74.590004,65.377426,-206.569534,-0.001233,0.003953,0.100398,290.813324,14.814736,1.003981,-206.569534,294.500458,0.000000
74.970001,65.220291,-206.614014,-0.001242,0.003958,0.100528,290.114349,14.779129,1.005283,-206.614014,294.500458,0.000000
75.350006,65.125336,-206.614014,-0.001224,0.003964,0.100684,289.691956,14.757612,1.006843,-206.614014,294.500458,0.000000
75.730003,65.243011,-206.614014,-0.001216,0.003970,0.100849,290.215424,14.784278,1.008493,-206.614014,294.500458,0.000000
76.110001,65.017715,-206.747467,-0.001203,0.003975,0.100954,289.213257,14.733225,1.009537,-206.747467,294.500458,0.000000
76.490005,65.265350,-206.791946,-0.001194,0.003983,0.101161,290.314789,14.789339,1.011612,-206.791946,294.500458,0.000000
76.870003,64.856110,-206.747467,-0.001194,0.003983,0.101161,288.494385,14.696605,1.011612,-206.747467,294.500458,0.000000
77.250000,66.549286,-206.791946,-0.001181,0.003937,0.100008,296.026001,15.080283,1.000075,-206.791946,294.500458,0.000000
77.630005,65.992966,-206.836426,-0.001181,0.003938,0.100017,293.551361,14.954220,1.000166,-206.836426,294.500458,0.000000
78.010002,65.531601,-206.836426,-0.001168,0.003957,0.100512,291.499115,14.849672,1.005117,-206.836426,294.500458,0.000000
78.390007,65.165558,-206.880905,-0.001155,0.003975,0.100954,289.870880,14.766726,1.009537,-206.880905,294.500458,0.000000
78.770004,66.073029,-206.925385,-0.001164,0.004012,0.101915,293.907501,14.972362,1.019151,-206.925385,294.500458,0.000000
79.150002,65.766556,-206.969864,-0.001186,0.004003,0.101673,292.544250,14.902914,1.016729,-206.969864,294.500458,0.000000
79.530006,65.364395,-206.969864,-0.001181,0.004003,0.101682,290.755341,14.811783,1.016820,-206.969864,294.500458,0.000000
79.910004,65.385254,-206.925385,-0.001168,0.004011,0.101882,290.848145,14.816510,1.018818,-206.925385,294.500458,0.000000
80.290001,65.313019,-207.014343,-0.001164,0.004014,0.101950,290.526825,14.800141,1.019499,-207.014343,294.500458,0.000000
80.670006,65.240768,-207.014343,-0.001164,0.004017,0.102020,290.205444,14.783769,1.020196,-207.014343,294.500458,0.000000
81.050003,65.224014,-207.058823,-0.001168,0.004021,0.102124,290.130920,14.779973,1.021240,-207.058823,294.500458,0.000000
81.430000,65.236679,-207.103302,-0.001164,0.004023,0.102176,290.187256,14.782843,1.021755,-207.103302,294.500458,0.000000
81.810005,65.255661,-207.058823,-0.001160,0.004025,0.102228,290.271667,14.787145,1.022285,-207.058823,294.500458,0.000000
82.190002,65.640701,-207.192276,-0.001160,0.004032,0.102401,291.984436,14.874395,1.024011,-207.192276,294.500458,0.000000
82.570007,65.516327,-207.192276,-0.001143,0.004032,0.102401,291.431183,14.846212,1.024011,-207.192276,294.500458,0.000000
82.950005,65.327164,-207.192276,-0.001147,0.004032,0.102410,290.589752,14.803347,1.024102,-207.192276,294.500458,0.000000
83.330002,65.187897,-207.192276,-0.001147,0.004033,0.102436,289.970245,14.771788,1.024359,-207.192276,294.500458,0.000000
83.710007,65.208008,-207.192276,-0.001143,0.004035,0.102496,290.059692,14.776345,1.024965,-207.192276,294.500458,0.000000
84.090004,65.247101,-207.281235,-0.001151,0.004038,0.102557,290.233612,14.785204,1.025570,-207.281235,294.500458,0.000000
84.470001,65.140976,-207.325714,-0.001143,0.004038,0.102566,289.761536,14.761156,1.025661,-207.325714,294.500458,0.000000
84.850006,65.394196,-207.370193,-0.001138,0.004043,0.102687,290.887909,14.818537,1.026872,-207.370193,294.500458,0.000000
85.230003,65.295883,-207.414673,-0.001155,0.004043,0.102687,290.450592,14.796259,1.026872,-207.414673,294.500458,0.000000
85.610001,65.172256,-207.414673,-0.001147,0.004043,0.102687,289.900665,14.768245,1.026872,-207.414673,294.500458,0.000000
85.990005,65.043045,-207.370193,-0.001125,0.004043,0.102696,289.325928,14.738965,1.026963,-207.370193,294.500458,0.000000
86.370003,65.566605,-207.459152,-0.001143,0.004051,0.102887,291.654816,14.857605,1.028871,-207.459152,294.500458,0.000000
86.750008,65.482437,-207.548111,-0.001151,0.004051,0.102887,291.280426,14.838532,1.028871,-207.548111,294.500458,0.000000
87.130005,65.343552,-207.459152,-0.001130,0.004051,0.102887,290.662628,14.807060,1.028871,-207.459152,294.500458,0.000000
87.510002,65.253433,-207.503632,-0.001125,0.004051,0.102887,290.261780,14.786639,1.028871,-207.503632,294.500458,0.000000
87.890007,65.208008,-207.548111,-0.001134,0.004056,0.103026,290.059692,14.776345,1.030264,-207.548111,294.500458,0.000000
88.270004,65.544998,-207.681564,-0.001138,0.004057,0.103052,291.558716,14.852709,1.030521,-207.681564,294.500458,0.000000
88.650002,65.472763,-207.637085,-0.001134,0.004057,0.103052,291.237396,14.836340,1.030521,-207.637085,294.500458,0.000000
89.030006,65.348007,-207.592606,-0.001130,0.004057,0.103052,290.682465,14.808070,1.030521,-207.592606,294.500458,0.000000
89.410004,65.269821,-207.637085,-0.001130,0.004057,0.103052,290.334656,14.790353,1.030521,-207.637085,294.500458,0.000000
89.790001,65.165924,-207.726044,-0.001121,0.004057,0.103052,289.872498,14.766809,1.030521,-207.726044,294.500458,0.000000
90.170006,65.050110,-207.726044,-0.001121,0.004057,0.103052,289.357330,14.740566,1.030521,-207.726044,294.500458,0.000000
90.550003,65.947159,-207.770523,-0.001130,0.004068,0.103320,293.347626,14.943840,1.033201,-207.770523,294.500458,0.000000
90.930008,65.882004,-207.726044,-0.001121,0.004067,0.103312,293.057800,14.929075,1.033125,-207.726044,294.500458,0.000000
91.310005,65.797470,-207.815002,-0.001130,0.004067,0.103312,292.681763,14.909920,1.033125,-207.815002,294.500458,0.000000
91.690002,65.673096,-207.815002,-0.001130,0.004067,0.103312,292.128510,14.881736,1.033125,-207.815002,294.500458,0.000000
92.070007,65.589310,-207.903961,-0.001121,0.004067,0.103312,291.755829,14.862750,1.033125,-207.903961,294.500458,0.000000
92.450005,65.524139,-207.948441,-0.001117,0.004067,0.103312,291.465942,14.847982,1.033125,-207.948441,294.500458,0.000000
92.830002,65.417648,-207.903961,-0.001125,0.004067,0.103312,290.992218,14.823851,1.033125,-207.903961,294.500458,0.000000
93.210007,65.305191,-207.948441,-0.001121,0.004067,0.103312,290.492004,14.798368,1.033125,-207.948441,294.500458,0.000000
93.590004,65.253433,-207.948441,-0.001130,0.004067,0.103312,290.261780,14.786639,1.033125,-207.948441,294.500458,0.000000
93.970001,65.153259,-207.992920,-0.001117,0.004067,0.103312,289.816162,14.763940,1.033125,-207.992920,294.500458,0.000000
94.350006,65.052353,-208.081894,-0.001117,0.004067,0.103312,289.367310,14.741074,1.033125,-208.081894,294.500458,0.000000
94.730003,64.990906,-208.037415,-0.001125,0.004067,0.103312,289.093994,14.727150,1.033125,-208.037415,294.500458,0.000000
95.110008,64.907501,-208.081894,-0.001121,0.004067,0.103312,288.722992,14.708250,1.033125,-208.081894,294.500458,0.000000
95.490005,64.803238,-208.126373,-0.001117,0.004067,0.103312,288.259186,14.684624,1.033125,-208.126373,294.500458,0.000000
95.870003,64.739929,-208.170853,-0.001108,0.004067,0.103312,287.977600,14.670278,1.033125,-208.170853,294.500458,0.000000
96.250008,66.382462,-208.259811,-0.001117,0.004073,0.103443,295.283936,15.042481,1.034427,-208.259811,294.500458,0.000000
96.630005,66.249908,-208.259811,-0.001104,0.004073,0.103443,294.694305,15.012444,1.034427,-208.259811,294.500458,0.000000
97.010002,66.148987,-208.259811,-0.001117,0.004073,0.103443,294.245392,14.989574,1.034427,-208.259811,294.500458,0.000000
97.390007,66.049942,-208.304291,-0.001104,0.004073,0.103443,293.804810,14.967131,1.034427,-208.304291,294.500458,0.000000
97.770004,66.026855,-208.259811,-0.001104,0.004073,0.103443,293.702118,14.961899,1.034427,-208.259811,294.500458,0.000000
98.150002,65.928177,-208.393250,-0.001099,0.004073,0.103443,293.263184,14.939538,1.034427,-208.393250,294.500458,0.000000
98.530006,65.852585,-208.348770,-0.001112,0.004073,0.103443,292.926941,14.922409,1.034427,-208.348770,294.500458,0.000000
98.910004,65.743103,-208.393250,-0.001099,0.004073,0.103443,292.439941,14.897600,1.034427,-208.393250,294.500458,0.000000
99.290001,65.660065,-208.437744,-0.001117,0.004073,0.103443,292.070557,14.878783,1.034427,-208.437744,294.500458,0.000000
99.670006,65.579254,-208.482224,-0.001095,0.004073,0.103443,291.711090,14.860472,1.034427,-208.482224,294.500458,0.000000
100.050003,65.544632,-208.482224,-0.001104,0.004073,0.103443,291.557098,14.852626,1.034427,-208.482224,294.500458,0.000000
100.430008,65.433289,-208.526703,-0.001095,0.004073,0.103443,291.061798,14.827395,1.034427,-208.526703,294.500458,0.000000
100.810005,65.347275,-208.571182,-0.001104,0.004073,0.103443,290.679199,14.807904,1.034427,-208.571182,294.500458,0.000000
101.190002,65.282471,-208.482224,-0.001099,0.004073,0.103443,290.390930,14.793220,1.034427,-208.482224,294.500458,0.000000
101.570007,65.224380,-208.615662,-0.001095,0.004073,0.103443,290.132538,14.780056,1.034427,-208.615662,294.500458,0.000000
101.950005,65.171509,-208.704620,-0.001099,0.004073,0.103443,289.897339,14.768075,1.034427,-208.704620,294.500458,0.000000
102.330002,65.232574,-208.615662,-0.001108,0.004088,0.103841,290.168976,14.781913,1.038409,-208.615662,294.500458,0.000000
102.710007,65.611282,-208.660141,-0.001117,0.004089,0.103850,291.853546,14.867729,1.038499,-208.660141,294.500458,0.000000
103.090004,65.604202,-208.704620,-0.001108,0.004089,0.103850,291.822052,14.866125,1.038499,-208.704620,294.500458,0.000000
103.470001,65.545746,-208.704620,-0.001108,0.004089,0.103850,291.562042,14.852879,1.038499,-208.704620,294.500458,0.000000
103.850006,65.527878,-208.838058,-0.001087,0.004089,0.103850,291.482544,14.848829,1.038499,-208.838058,294.500458,0.000000
104.230003,65.476105,-208.882553,-0.001099,0.004089,0.103850,291.252258,14.837097,1.038499,-208.882553,294.500458,0.000000
104.610008,65.435150,-208.793579,-0.001121,0.004089,0.103850,291.070099,14.827816,1.038499,-208.793579,294.500458,0.000000
104.990005,65.365143,-208.793579,-0.001099,0.004089,0.103850,290.758667,14.811953,1.038499,-208.793579,294.500458,0.000000
105.370003,65.345779,-208.882553,-0.001112,0.004089,0.103859,290.672546,14.807566,1.038590,-208.882553,294.500458,0.000000
105.750008,65.305557,-208.882553,-0.001091,0.004089,0.103859,290.493622,14.798450,1.038590,-208.882553,294.500458,0.000000
106.130005,65.264969,-208.971512,-0.001104,0.004089,0.103859,290.313080,14.789253,1.038590,-208.971512,294.500458,0.000000
106.510002,65.240768,-209.015991,-0.001104,0.004090,0.103876,290.205444,14.783769,1.038757,-209.015991,294.500458,0.000000
106.890007,65.221039,-208.927032,-0.001104,0.004090,0.103876,290.117676,14.779299,1.038757,-208.927032,294.500458,0.000000
107.270004,65.163696,-208.971512,-0.001087,0.004090,0.103894,289.862610,14.766305,1.038939,-208.971512,294.500458,0.000000
107.650002,65.142838,-209.060471,-0.001087,0.004090,0.103894,289.769806,14.761578,1.038939,-209.060471,294.500458,0.000000
108.030006,65.144699,-209.104950,-0.001099,0.004091,0.103901,289.778107,14.762000,1.039014,-209.104950,294.500458,0.000000
108.410004,65.084000,-209.104950,-0.001095,0.004091,0.103911,289.508087,14.748245,1.039105,-209.104950,294.500458,0.000000
108.790009,65.069473,-209.104950,-0.001095,0.004091,0.103911,289.443481,14.744953,1.039105,-209.104950,294.500458,0.000000
109.170006,65.021820,-209.104950,-0.001091,0.004091,0.103911,289.231506,14.734156,1.039105,-209.104950,294.500458,0.000000
109.550003,65.027405,-209.193909,-0.001099,0.004092,0.103936,289.256348,14.735421,1.039362,-209.193909,294.500458,0.000000
109.930008,65.720383,-209.193909,-0.001099,0.004102,0.104188,292.338867,14.892451,1.041876,-209.193909,294.500458,0.000000
110.310005,65.800827,-209.238388,-0.001104,0.004101,0.104171,292.696686,14.910681,1.041709,-209.238388,294.500458,0.000000
110.690002,65.813858,-209.193909,-0.001104,0.004101,0.104171,292.754669,14.913633,1.041709,-209.193909,294.500458,0.000000
111.070007,65.771027,-209.238388,-0.001082,0.004101,0.104171,292.564148,14.903927,1.041709,-209.238388,294.500458,0.000000
111.450005,65.762833,-209.371841,-0.001082,0.004101,0.104171,292.527679,14.902071,1.041709,-209.371841,294.500458,0.000000
111.830002,65.740875,-209.371841,-0.001104,0.004101,0.104171,292.430023,14.897096,1.041709,-209.371841,294.500458,0.000000
112.210007,65.674591,-209.327362,-0.001104,0.004101,0.104171,292.135162,14.882075,1.041709,-209.327362,294.500458,0.000000
112.590004,65.650009,-209.327362,-0.001095,0.004101,0.104171,292.025818,14.876505,1.041709,-209.327362,294.500458,0.000000
112.970009,65.606064,-209.416321,-0.001087,0.004101,0.104171,291.830353,14.866547,1.041709,-209.416321,294.500458,0.000000
113.350006,65.596390,-209.460800,-0.001091,0.004101,0.104171,291.787323,14.864354,1.041709,-209.460800,294.500458,0.000000
113.730003,65.559143,-209.549759,-0.001095,0.004101,0.104171,291.621643,14.855914,1.041709,-209.549759,294.500458,0.000000
114.110008,65.533081,-209.505280,-0.001104,0.004101,0.104171,291.505707,14.850009,1.041709,-209.505280,294.500458,0.000000
114.490005,65.504791,-209.460800,-0.001082,0.004101,0.104171,291.379852,14.843598,1.041709,-209.460800,294.500458,0.000000
114.870003,65.447815,-209.505280,-0.001099,0.004101,0.104171,291.126434,14.830687,1.041709,-209.505280,294.500458,0.000000
115.250008,65.403503,-209.549759,-0.001091,0.004101,0.104171,290.929321,14.820645,1.041709,-209.549759,294.500458,0.000000
115.630005,65.348755,-209.638718,-0.001095,0.004101,0.104171,290.685791,14.808240,1.041709,-209.638718,294.500458,0.000000
116.010002,65.327530,-209.638718,-0.001099,0.004101,0.104171,290.591370,14.803431,1.041709,-209.638718,294.500458,0.000000
116.390007,65.281357,-209.594238,-0.001091,0.004101,0.104171,290.385986,14.792967,1.041709,-209.594238,294.500458,0.000000
116.770004,65.283966,-209.727692,-0.001099,0.004102,0.104180,290.397583,14.793558,1.041800,-209.727692,294.500458,0.000000
117.150009,65.241882,-209.727692,-0.001087,0.004102,0.104180,290.210388,14.784021,1.041800,-209.727692,294.500458,0.000000
117.530006,65.203903,-209.772171,-0.001095,0.004102,0.104180,290.041443,14.775416,1.041800,-209.772171,294.500458,0.000000
117.910004,65.170013,-209.816650,-0.001099,0.004102,0.104188,289.890686,14.767735,1.041876,-209.816650,294.500458,0.000000
118.290009,65.111557,-209.683197,-0.001091,0.004102,0.104188,289.630676,14.754489,1.041876,-209.683197,294.500458,0.000000
118.670006,65.082520,-209.816650,-0.001095,0.004102,0.104188,289.501495,14.747910,1.041876,-209.816650,294.500458,0.000000
119.050003,65.047134,-209.861130,-0.001091,0.004102,0.104188,289.344116,14.739891,1.041876,-209.861130,294.500458,0.000000
119.430008,65.004318,-209.905609,-0.001104,0.004102,0.104188,289.153656,14.730189,1.041876,-209.905609,294.500458,0.000000
119.810005,64.994263,-209.905609,-0.001099,0.004102,0.104197,289.108917,14.727910,1.041966,-209.905609,294.500458,0.000000
120.190002,64.961487,-209.905609,-0.001099,0.004103,0.104206,288.963135,14.720484,1.042057,-209.905609,294.500458,0.000000
120.570007,64.935059,-209.905609,-0.001095,0.004103,0.104206,288.845581,14.714494,1.042057,-209.905609,294.500458,0.000000
120.950005,64.976395,-210.039047,-0.001095,0.004104,0.104248,289.029449,14.723862,1.042481,-210.039047,294.500458,0.000000
121.330009,64.991287,-209.994568,-0.001087,0.004104,0.104248,289.095673,14.727236,1.042481,-209.994568,294.500458,0.000000
121.710007,64.967819,-209.994568,-0.001099,0.004104,0.104248,288.991302,14.721919,1.042481,-209.994568,294.500458,0.000000
122.090004,64.961868,-210.039047,-0.001095,0.004105,0.104257,288.964813,14.720570,1.042572,-210.039047,294.500458,0.000000
122.470009,64.924622,-210.128006,-0.001082,0.004105,0.104257,288.799133,14.712130,1.042572,-210.128006,294.500458,0.000000
122.850006,64.920532,-210.128006,-0.001082,0.004105,0.104257,288.780945,14.711203,1.042572,-210.128006,294.500458,0.000000
123.230003,64.890366,-210.216980,-0.001087,0.004105,0.104257,288.646759,14.704368,1.042572,-210.216980,294.500458,0.000000
123.610008,64.872498,-210.216980,-0.001078,0.004106,0.104283,288.567291,14.700318,1.042829,-210.216980,294.500458,0.000000
123.990005,64.948837,-210.216980,-0.001087,0.004107,0.104309,288.906860,14.717617,1.043087,-210.216980,294.500458,0.000000
124.370003,64.933929,-210.261459,-0.001087,0.004107,0.104309,288.840546,14.714238,1.043087,-210.261459,294.500458,0.000000
124.750008,64.945480,-210.305939,-0.001095,0.004107,0.104309,288.891937,14.716857,1.043087,-210.305939,294.500458,0.000000
125.130005,64.908615,-210.305939,-0.001095,0.004107,0.104309,288.727936,14.708503,1.043087,-210.305939,294.500458,0.000000
125.510010,64.899673,-210.261459,-0.001082,0.004107,0.104309,288.688171,14.706476,1.043087,-210.261459,294.500458,0.000000
125.890007,64.870255,-210.305939,-0.001095,0.004107,0.104309,288.557312,14.699810,1.043087,-210.305939,294.500458,0.000000
126.270004,64.866165,-210.394897,-0.001091,0.004107,0.104309,288.539124,14.698883,1.043087,-210.394897,294.500458,0.000000
126.650009,64.812546,-210.439377,-0.001069,0.004107,0.104309,288.300598,14.686732,1.043087,-210.439377,294.500458,0.000000
127.030006,64.816269,-210.439377,-0.001091,0.004107,0.104309,288.317169,14.687577,1.043087,-210.439377,294.500458,0.000000
127.410004,64.784988,-210.439377,-0.001095,0.004107,0.104309,288.178009,14.680489,1.043087,-210.439377,294.500458,0.000000
127.790009,64.774933,-210.483856,-0.001091,0.004107,0.104309,288.133301,14.678209,1.043087,-210.483856,294.500458,0.000000
128.170013,64.741043,-210.528336,-0.001082,0.004107,0.104309,287.982544,14.670530,1.043087,-210.528336,294.500458,0.000000
128.550003,64.741425,-210.528336,-0.001087,0.004107,0.104309,287.984253,14.670616,1.043087,-210.528336,294.500458,0.000000
128.930008,66.067062,-210.572815,-0.001087,0.004118,0.104604,293.880981,14.971010,1.046039,-210.572815,294.500458,0.000000
129.310013,66.043610,-210.572815,-0.001091,0.004118,0.104596,293.776642,14.965695,1.045963,-210.572815,294.500458,0.000000
129.690002,65.996323,-210.572815,-0.001082,0.004118,0.104587,293.566315,14.954981,1.045872,-210.572815,294.500458,0.000000
130.070007,65.930405,-210.617310,-0.001082,0.004118,0.104587,293.273102,14.940042,1.045872,-210.617310,294.500458,0.000000
130.450012,65.890564,-210.706268,-0.001091,0.004118,0.104587,293.095856,14.931015,1.045872,-210.706268,294.500458,0.000000
130.830002,65.856308,-210.661789,-0.001082,0.004118,0.104587,292.943481,14.923252,1.045872,-210.661789,294.500458,0.000000
131.210007,65.877533,-210.795227,-0.001091,0.004118,0.104587,293.037903,14.928062,1.045872,-210.795227,294.500458,0.000000
131.590012,65.848114,-210.706268,-0.001087,0.004118,0.104587,292.907043,14.921396,1.045872,-210.706268,294.500458,0.000000
131.970001,65.811615,-210.884186,-0.001091,0.004118,0.104587,292.744690,14.913126,1.045872,-210.884186,294.500458,0.000000
132.350006,65.783325,-210.839706,-0.001078,0.004118,0.104587,292.618835,14.906714,1.045872,-210.839706,294.500458,0.000000
132.730011,65.755020,-210.839706,-0.001074,0.004118,0.104587,292.492950,14.900300,1.045872,-210.839706,294.500458,0.000000
133.110001,65.757248,-210.839706,-0.001074,0.004118,0.104587,292.502838,14.900805,1.045872,-210.839706,294.500458,0.000000
133.490005,65.682037,-210.884186,-0.001078,0.004118,0.104587,292.168304,14.883762,1.045872,-210.884186,294.500458,0.000000
133.870010,65.667511,-210.973145,-0.001082,0.004118,0.104587,292.103668,14.880470,1.045872,-210.973145,1681.640747,0.000000
134.250000,65.649643,-210.928665,-0.001078,0.004118,0.104587,292.024200,14.876421,1.045872,-210.928665,0.104404,0.000000
134.630005,65.613144,-210.973145,-0.001074,0.004100,0.104136,291.861847,14.868151,1.041361,-210.973145,0.103771,0.000000
135.010010,65.505157,-210.928665,-0.001074,0.004078,0.103573,291.381500,14.843681,1.035729,-210.928665,0.103138,0.000000
135.389999,65.446320,-211.062119,-0.001065,0.004053,0.102939,291.119781,14.830348,1.029385,-211.062119,0.102506,0.000000
135.770004,65.401260,-211.106598,-0.001061,0.004034,0.102471,290.919342,14.820137,1.024707,-211.106598,0.101873,0.000000
136.150009,65.342422,-211.106598,-0.001052,0.004018,0.102045,290.657623,14.806805,1.020453,-211.106598,0.101240,0.000000
136.530014,65.350250,-211.106598,-0.001065,0.003986,0.101247,290.692444,14.808578,1.012475,-211.106598,0.100607,0.000000
136.910004,65.280609,-211.106598,-0.001048,0.003955,0.100450,290.382660,14.792797,1.004496,-211.106598,0.099973,0.000000
137.290009,65.217316,-211.195557,-0.001065,0.003931,0.099852,290.101105,14.778456,0.998516,-211.195557,0.099340,0.000000
137.670013,65.172256,-211.195557,-0.001069,0.003910,0.099305,289.900665,14.768245,0.993050,-211.195557,0.098707,0.000000
138.050003,65.084747,-211.240036,-0.001056,0.003892,0.098846,289.511414,14.748415,0.988463,-211.240036,0.098074,0.000000
138.430008,64.786850,-211.240036,-0.001052,0.003867,0.098213,288.186310,14.680909,0.982135,-211.240036,0.097441,0.000000
138.810013,63.906189,-211.328995,-0.001026,0.003836,0.097432,284.268921,14.481350,0.974323,-211.328995,0.096809,0.000000
139.190002,63.140213,-211.284515,-0.001022,0.003817,0.096964,280.861694,14.307777,0.969645,-211.284515,0.096174,0.000000
139.570007,62.026451,-211.373474,-0.001026,0.003797,0.096453,275.907440,14.055394,0.964527,-211.373474,0.095541,0.000000
139.950012,60.424507,-211.373474,-0.001039,0.003771,0.095793,268.781647,13.692389,0.957927,-211.373474,0.094909,0.000000
140.330002,58.667282,-211.373474,-0.001030,0.003750,0.095255,260.965118,13.294196,0.952552,-211.373474,0.094267,0.000000
140.710007,56.943199,-211.373474,-0.001035,0.003728,0.094701,253.296005,12.903514,0.947011,-211.373474,0.093634,0.000000
141.090012,54.059547,-211.373474,-0.001013,0.003698,0.093938,240.468872,12.250069,0.939381,-211.373474,0.093001,0.000000
141.470001,52.172729,-211.551407,-0.001030,0.003681,0.093504,232.075897,11.822510,0.935036,-211.551407,0.092368,0.000000
141.850006,48.923782,-211.506927,-0.001026,0.003652,0.092750,217.623856,11.086287,0.927496,-211.506927,0.091735,0.000000
142.230011,46.444153,-211.506927,-0.001026,0.003627,0.092133,206.593903,10.524396,0.921334,-211.506927,0.091101,0.000000
142.610001,43.720619,-211.551407,-0.001039,0.003601,0.091475,194.479034,9.907233,0.914749,-211.551407,0.090468,0.000000
142.990005,40.828781,-211.595886,-0.001022,0.003576,0.090824,181.615494,9.251934,0.908239,-211.595886,0.089835,0.000000
143.370010,38.473892,-211.684845,-0.001035,0.003553,0.090235,171.140427,8.718308,0.902349,-211.684845,0.089202,0.000000
143.750000,35.777176,-211.640366,-0.001022,0.003530,0.089670,159.144821,8.107224,0.896702,-211.640366,0.088570,0.000000
144.130005,32.887192,-211.640366,-0.001018,0.003501,0.088916,146.289536,7.452344,0.889163,-211.640366,0.087937,0.000000
144.510010,30.594124,-211.729324,-0.001018,0.003481,0.088414,136.089462,6.932727,0.884136,-211.729324,0.087302,0.000000
144.889999,27.395439,-211.773804,-0.001018,0.003450,0.087642,121.861000,6.207895,0.876415,-211.773804,0.086670,0.000000
145.270004,25.016724,-211.773804,-0.001022,0.003426,0.087025,111.279945,5.668871,0.870253,-211.773804,0.086037,0.000000
145.650009,22.010567,-211.773804,-0.001030,0.003400,0.086349,97.907890,4.987666,0.863486,-211.773804,0.085404,0.000000
146.030014,20.025444,-211.818283,-0.001009,0.003383,0.085916,89.077621,4.537830,0.859156,-211.818283,0.084771,0.000000
146.410004,17.122055,-211.818283,-0.001005,0.003355,0.085213,76.162704,3.879913,0.852131,-211.818283,0.084138,0.000000
146.790009,14.164299,-211.907257,-0.001022,0.003327,0.084502,63.005947,3.209676,0.845016,-211.907257,0.083505,0.000000
147.170013,11.745743,-211.951736,-0.001026,0.003302,0.083869,52.247673,2.661623,0.838687,-211.951736,0.082871,0.000000
147.550003,9.094452,-211.907257,-0.001022,0.003277,0.083245,40.454144,2.060832,0.832450,-211.907257,0.082238,0.000000
147.930008,6.493805,-211.951736,-0.001026,0.003252,0.082612,28.885887,1.471517,0.826121,-211.951736,0.081605,0.000000
148.310013,3.760216,-211.907257,-0.001013,0.003227,0.081961,16.726274,0.852077,0.819611,-211.907257,0.080973,0.000000
148.690002,1.262344,-212.085175,-0.001030,0.003202,0.081319,5.615188,0.286051,0.813192,-212.085175,0.080340,0.000000
149.070007,-0.981575,-212.085175,-0.001035,0.003178,0.080721,-4.366264,-0.222428,0.807212,-212.085175,0.079707,0.000000
149.450012,-2.308712,-212.085175,-0.001039,0.003159,0.080235,-10.269664,-0.523162,0.802352,-212.085175,0.079073,0.000000
149.830002,-0.005211,-212.040695,-0.001087,0.003131,0.079533,-0.023179,-0.001181,0.795328,-212.040695,0.078440,0.000000
150.210007,-0.021225,-212.085175,-0.001117,0.003103,0.078814,-0.094413,-0.004810,0.788136,-212.085175,0.077807,0.000000
150.590012,0.011169,-212.218613,-0.001134,0.003086,0.078388,0.049684,0.002531,0.783882,-212.218613,0.077174,0.000000
150.970001,0.007072,-212.218613,-0.001164,0.003061,0.077737,0.031460,0.001603,0.777372,-212.218613,0.076532,0.000000
151.350006,-0.053253,-212.174133,-0.001194,0.003028,0.076914,-0.236882,-0.012067,0.769136,-212.174133,0.075899,0.000000
151.730011,-0.019737,-212.174133,-0.001207,0.003006,0.076358,-0.087796,-0.004473,0.763580,-212.174133,0.075266,0.000000
152.110001,-0.069260,-212.263092,-0.001224,0.002977,0.075622,-0.308082,-0.015694,0.756222,-212.263092,0.074634,0.000000
152.490005,-0.060326,-212.307587,-0.001263,0.002951,0.074962,-0.268342,-0.013670,0.749621,-212.307587,0.073999,0.000000
152.870010,-0.099426,-212.396545,-0.001272,0.002930,0.074425,-0.442270,-0.022530,0.744247,-212.396545,0.073366,0.000000
153.250000,-0.058464,-212.352066,-0.001311,0.002909,0.073887,-0.260061,-0.013248,0.738872,-212.352066,0.072734,0.000000
153.630005,-0.108734,-212.352066,-0.001354,0.002878,0.073089,-0.483674,-0.024640,0.730893,-212.352066,0.072101,0.000000
154.010010,-0.083412,-212.396545,-0.001367,0.002857,0.072569,-0.371036,-0.018901,0.725685,-212.396545,0.071468,0.000000
154.390015,-0.116928,-212.485504,-0.001436,0.002820,0.071624,-0.520122,-0.026496,0.716238,-212.485504,0.070835,0.000000
154.770004,-0.093468,-212.485504,-0.001449,0.002800,0.071129,-0.415765,-0.021180,0.711288,-212.485504,0.070201,0.000000
155.150009,-0.099800,-212.441025,-0.001466,0.002782,0.070652,-0.443933,-0.022615,0.706519,-212.441025,0.069568,0.000000
155.530014,-0.109482,-212.441025,-0.001509,0.002757,0.070019,-0.486999,-0.024809,0.700190,-212.441025,0.068935,0.000000
155.910004,-0.113571,-212.485504,-0.001518,0.002733,0.069430,-0.505190,-0.025736,0.694301,-212.485504,0.068302,0.000000
156.290009,-0.131821,-212.574463,-0.001565,0.002710,0.068840,-0.586368,-0.029871,0.688397,-212.574463,0.067669,0.000000
156.670013,-0.140755,-212.618942,-0.001600,0.002680,0.068060,-0.626108,-0.031895,0.680600,-212.618942,0.067037,0.000000
156.800003,-0.079689,-212.618942,-0.001582,0.002679,0.068042,-0.354474,-0.018058,0.680418,-212.618942,0.067903,0.000000